File: Force_trajectories/161226_1/Specimen_RawData_2.csv
End date,"12/26/2016"
Specimen label,"15DT_23"
Maximum Load,"0.28588",N

Time,Extension,Load
(s),(mm),(N)
"0.00000","0.00000","-0.00035"
"0.27600","0.02212","0.00044"
"0.55200","0.04622","0.00033"
"0.82800","0.06924","-0.00009"
"1.10400","0.09220","0.00009"
"1.38000","0.11527","-0.00015"
"1.65600","0.13817","0.00018"
"1.93200","0.16119","0.00044"
"2.20800","0.18415","-0.00037"
"2.48400","0.20717","-0.00050"
"2.76000","0.23019","-0.00008"
"3.03600","0.25321","0.00025"
"3.31200","0.27617","0.00039"
"3.58800","0.29925","-0.00075"
"3.86400","0.32215","-0.00022"
"4.14000","0.34522","-0.00037"
"4.41600","0.36812","-0.00047"
"4.69200","0.39120","-0.00030"
"4.96800","0.41410","-0.00018"
"5.24400","0.43718","0.00002"
"5.52000","0.46014","0.00040"
"5.79600","0.48322","0.00036"
"6.07200","0.50618","-0.00012"
"6.34800","0.52926","0.00067"
"6.62400","0.55222","0.00044"
"6.90000","0.57524","0.00118"
"7.17600","0.59819","0.00068"
"7.45200","0.62115","0.00111"
"7.72800","0.64417","0.00144"
"8.00400","0.66713","0.00148"
"8.28000","0.69021","0.00197"
"8.55600","0.71317","0.00211"
"8.83200","0.73625","0.00207"
"9.10800","0.75921","0.00170"
"9.38400","0.78223","0.00189"
"9.66000","0.80519","0.00201"
"9.93600","0.82820","0.00192"
"10.21200","0.85116","0.00233"
"10.48800","0.87424","0.00210"
"10.76400","0.89714","0.00175"
"11.04000","0.92022","0.00222"
"11.31600","0.94318","0.00187"
"11.59200","0.96620","0.00220"
"11.86800","0.98916","0.00205"
"12.14400","1.01218","0.00232"
"12.42000","1.03508","0.00242"
"12.69600","1.05821","0.00260"
"12.97200","1.08117","0.00199"
"13.24800","1.10425","0.00220"
"13.52400","1.12721","0.00281"
"13.80000","1.15023","0.00246"
"14.07600","1.17319","0.00257"
"14.35200","1.19621","0.00303"
"14.62800","1.21911","0.00207"
"14.90400","1.24219","0.00322"
"15.18000","1.26515","0.00274"
"15.45600","1.28817","0.00297"
"15.73200","1.31112","0.00294"
"16.00800","1.33420","0.00265"
"16.28400","1.35716","0.00258"
"16.56000","1.38024","0.00246"
"16.83600","1.40326","0.00294"
"17.11200","1.42622","0.00223"
"17.38800","1.44918","0.00329"
"17.66400","1.47220","0.00270"
"17.94000","1.49522","0.00293"
"18.21600","1.51818","0.00312"
"18.49200","1.54119","0.00311"
"18.76800","1.56415","0.00311"
"19.04400","1.58723","0.00289"
"19.32000","1.61013","0.00335"
"19.59600","1.63321","0.00293"
"19.87200","1.65617","0.00267"
"20.14800","1.67925","0.00299"
"20.42400","1.70215","0.00345"
"20.70000","1.72529","0.00290"
"20.97600","1.74819","0.00291"
"21.25200","1.77126","0.00231"
"21.52800","1.79416","0.00279"
"21.80400","1.81718","0.00290"
"22.08000","1.84014","0.00292"
"22.35600","1.86322","0.00277"
"22.63200","1.88618","0.00309"
"22.90800","1.90926","0.00273"
"23.18400","1.93216","0.00270"
"23.46000","1.95524","0.00339"
"23.73600","1.97820","0.00342"
"24.01200","2.00128","0.00330"
"24.28800","2.02417","0.00297"
"24.56400","2.04725","0.00266"
"24.84000","2.07015","0.00287"
"25.11600","2.09323","0.00292"
"25.39200","2.11619","0.00273"
"25.66800","2.13915","0.00275"
"25.94400","2.16217","0.00299"
"26.22000","2.18519","0.00261"
"26.49600","2.20821","0.00286"
"26.77200","2.23123","0.00308"
"27.04800","2.25418","0.00329"
"27.32400","2.27720","0.00276"
"27.60000","2.30022","0.00279"
"27.87600","2.32318","0.00249"
"28.15200","2.34620","0.00243"
"28.42800","2.36922","0.00274"
"28.70400","2.39224","0.00291"
"28.98000","2.41520","0.00262"
"29.25600","2.43822","0.00243"
"29.53200","2.46118","0.00302"
"29.80800","2.48420","0.00278"
"30.08400","2.50715","0.00242"
"30.36000","2.53023","0.00253"
"30.63600","2.55319","0.00309"
"30.91200","2.57627","0.00308"
"31.18800","2.59923","0.00268"
"31.46400","2.62225","0.00300"
"31.74000","2.64515","0.00255"
"32.01600","2.66823","0.00325"
"32.29200","2.69119","0.00373"
"32.56800","2.71421","0.00303"
"32.84400","2.73710","0.00267"
"33.12000","2.76012","0.00264"
"33.39600","2.78308","0.00326"
"33.67200","2.80616","0.00299"
"33.94800","2.82912","0.00331"
"34.22400","2.85220","0.00211"
"34.50000","2.87516","0.00237"
"34.77600","2.89824","0.00217"
"35.05200","2.92120","0.00218"
"35.32800","2.94422","0.00268"
"35.60400","2.96718","0.00261"
"35.88000","2.99019","0.00271"
"36.15600","3.01315","0.00254"
"36.43200","3.03623","0.00301"
"36.70800","3.05919","0.00303"
"36.98400","3.08221","0.00304"
"37.26000","3.10517","0.00219"
"37.53600","3.12819","0.00265"
"37.81200","3.15121","0.00287"
"38.08800","3.17423","0.00310"
"38.36400","3.19719","0.00309"
"38.64000","3.22020","0.00306"
"38.91600","3.24322","0.00274"
"39.19200","3.26624","0.00302"
"39.46800","3.28920","0.00261"
"39.74400","3.31222","0.00320"
"40.02000","3.33518","0.00245"
"40.29600","3.35820","0.00270"
"40.57200","3.38116","0.00374"
"40.84800","3.40412","0.00326"
"41.12400","3.42720","0.00317"
"41.40000","3.45016","0.00272"
"41.67600","3.47323","0.00262"
"41.95200","3.49619","0.00274"
"42.22800","3.51927","0.00250"
"42.50400","3.54223","0.00288"
"42.78000","3.56525","0.00190"
"43.05600","3.58821","0.00211"
"43.33200","3.61117","0.00235"
"43.60800","3.63419","0.00253"
"43.88400","3.65721","0.00240"
"44.16000","3.68011","0.00230"
"44.43600","3.70318","0.00231"
"44.71200","3.72614","0.00239"
"44.98800","3.74916","0.00239"
"45.26400","3.77218","0.00209"
"45.54000","3.79526","0.00276"
"45.81600","3.81816","0.00216"
"46.09200","3.84118","0.00241"
"46.36800","3.86414","0.00204"
"46.64400","3.88722","0.00295"
"46.92000","3.91018","0.00215"
"47.19600","3.93325","0.00234"
"47.47200","3.95615","0.00268"
"47.74800","3.97923","0.00197"
"48.02400","4.00213","0.00231"
"48.30000","4.02515","0.00267"
"48.57600","4.04817","0.00243"
"48.85200","4.07119","0.00288"
"49.12800","4.09421","0.00275"
"49.40400","4.11723","0.00224"
"49.68000","4.14019","0.00220"
"49.95600","4.16320","0.00299"
"50.23200","4.18616","0.00274"
"50.50800","4.20912","0.00280"
"50.78400","4.23220","0.00260"
"51.06000","4.25516","0.00285"
"51.33600","4.27818","0.00284"
"51.61200","4.30120","0.00265"
"51.88800","4.32422","0.00268"
"52.16400","4.34718","0.00256"
"52.44000","4.37026","0.00273"
"52.71600","4.39322","0.00266"
"52.99200","4.41623","0.00311"
"53.26800","4.43919","0.00211"
"53.54400","4.46221","0.00286"
"53.82000","4.48517","0.00261"
"54.09600","4.50819","0.00283"
"54.37200","4.53115","0.00304"
"54.64800","4.55417","0.00233"
"54.92400","4.57719","0.00319"
"55.20000","4.60027","0.00269"
"55.47600","4.62311","0.00338"
"55.75200","4.64618","0.00328"
"56.02800","4.66914","0.00354"
"56.30400","4.69222","0.00330"
"56.58000","4.71518","0.00327"
"56.85600","4.73826","0.00300"
"57.13200","4.76122","0.00303"
"57.40800","4.78424","0.00343"
"57.68400","4.80714","0.00341"
"57.96000","4.83022","0.00314"
"58.23600","4.85318","0.00322"
"58.51200","4.87619","0.00326"
"58.78800","4.89915","0.00339"
"59.06400","4.92223","0.00359"
"59.34000","4.94519","0.00364"
"59.61600","4.96821","0.00352"
"59.89200","4.99123","0.00423"
"60.16800","5.01419","0.00403"
"60.44400","5.03721","0.00310"
"60.72000","5.06023","0.00346"
"60.99600","5.08319","0.00376"
"61.27200","5.10615","0.00372"
"61.54800","5.12916","0.00389"
"61.82400","5.15212","0.00409"
"62.10000","5.17520","0.00402"
"62.37600","5.19816","0.00384"
"62.65200","5.22124","0.00390"
"62.92800","5.24414","0.00392"
"63.20400","5.26722","0.00430"
"63.48000","5.29018","0.00442"
"63.75600","5.31326","0.00418"
"64.03200","5.33616","0.00405"
"64.30800","5.35923","0.00397"
"64.58400","5.38213","0.00383"
"64.86000","5.40521","0.00439"
"65.13600","5.42817","0.00450"
"65.41200","5.45125","0.00423"
"65.68800","5.47415","0.00444"
"65.96400","5.49717","0.00445"
"66.24000","5.52013","0.00423"
"66.51600","5.54321","0.00391"
"66.79200","5.56617","0.00477"
"67.06800","5.58924","0.00489"
"67.34400","5.61220","0.00465"
"67.62000","5.63522","0.00503"
"67.89600","5.65818","0.00416"
"68.17200","5.68120","0.00436"
"68.44800","5.70416","0.00412"
"68.72400","5.72718","0.00450"
"69.00000","5.75014","0.00453"
"69.27600","5.77322","0.00437"
"69.55200","5.79618","0.00432"
"69.82800","5.81914","0.00492"
"70.10400","5.84215","0.00454"
"70.38000","5.86517","0.00461"
"70.65600","5.88819","0.00432"
"70.93200","5.91121","0.00508"
"71.20800","5.93423","0.00475"
"71.48400","5.95725","0.00465"
"71.76000","5.98021","0.00442"
"72.03600","6.00317","0.00447"
"72.31200","6.02619","0.00499"
"72.58800","6.04915","0.00456"
"72.86400","6.07223","0.00497"
"73.14000","6.09518","0.00483"
"73.41600","6.11820","0.00495"
"73.69200","6.14116","0.00519"
"73.96800","6.16424","0.00478"
"74.24400","6.18714","0.00464"
"74.52000","6.21022","0.00444"
"74.79600","6.23318","0.00474"
"75.07200","6.25626","0.00492"
"75.34800","6.27922","0.00504"
"75.62400","6.30218","0.00546"
"75.90000","6.32514","0.00572"
"76.17600","6.34821","0.00516"
"76.45200","6.37111","0.00545"
"76.72800","6.39419","0.00564"
"77.00400","6.41715","0.00549"
"77.28000","6.44017","0.00560"
"77.55600","6.46319","0.00543"
"77.83200","6.48627","0.00553"
"78.10800","6.50917","0.00514"
"78.38400","6.53225","0.00524"
"78.66000","6.55520","0.00586"
"78.93600","6.57816","0.00591"
"79.21200","6.60112","0.00603"
"79.48800","6.62420","0.00583"
"79.76400","6.64716","0.00585"
"80.04000","6.67024","0.00594"
"80.31600","6.69320","0.00570"
"80.59200","6.71616","0.00563"
"80.86800","6.73918","0.00564"
"81.14400","6.76220","0.00602"
"81.42000","6.78522","0.00618"
"81.69600","6.80823","0.00608"
"81.97200","6.83119","0.00630"
"82.24800","6.85421","0.00625"
"82.52400","6.87717","0.00571"
"82.80000","6.90019","0.00539"
"83.07600","6.92321","0.00583"
"83.35200","6.94617","0.00621"
"83.62800","6.96925","0.00637"
"83.90400","6.99221","0.00621"
"84.18000","7.01517","0.00571"
"84.45600","7.03813","0.00581"
"84.73200","7.06120","0.00646"
"85.00800","7.08416","0.00666"
"85.28400","7.10724","0.00630"
"85.56000","7.13020","0.00634"
"85.83600","7.15322","0.00683"
"86.11200","7.17618","0.00711"
"86.38800","7.19920","0.00663"
"86.66400","7.22216","0.00665"
"86.94000","7.24518","0.00686"
"87.21600","7.26814","0.00671"
"87.49200","7.29121","0.00729"
"87.76800","7.31417","0.00712"
"88.04400","7.33719","0.00766"
"88.32000","7.36015","0.00750"
"88.59600","7.38323","0.00754"
"88.87200","7.40619","0.00805"
"89.14800","7.42921","0.00831"
"89.42400","7.45223","0.00780"
"89.70000","7.47525","0.00791"
"89.97600","7.49815","0.00802"
"90.25200","7.52122","0.00815"
"90.52800","7.54412","0.00825"
"90.80400","7.56726","0.00819"
"91.08000","7.59016","0.00840"
"91.35600","7.61324","0.00820"
"91.63200","7.63614","0.00841"
"91.90800","7.65916","0.00779"
"92.18400","7.68218","0.00813"
"92.46000","7.70526","0.00816"
"92.73600","7.72822","0.00833"
"93.01200","7.75124","0.00864"
"93.28800","7.77419","0.00897"
"93.56400","7.79721","0.00844"
"93.84000","7.82017","0.00632"
"94.11600","7.84313","0.00660"
"94.39200","7.86621","0.00753"
"94.66800","7.88917","0.00749"
"94.94400","7.91225","0.00784"
"95.22000","7.93521","0.00814"
"95.49600","7.95823","0.00816"
"95.77200","7.98118","0.00840"
"96.04800","8.00426","0.00846"
"96.32400","8.02716","0.00919"
"96.60000","8.05018","0.00914"
"96.87600","8.07314","0.00925"
"97.15200","8.09622","0.00940"
"97.42800","8.11912","0.00990"
"97.70400","8.14220","0.00945"
"97.98000","8.16510","0.00851"
"98.25600","8.18818","0.00875"
"98.53200","8.21114","0.00906"
"98.80800","8.23421","0.00880"
"99.08400","8.25711","0.00939"
"99.36000","8.28025","0.00960"
"99.63600","8.30321","0.00951"
"99.91200","8.32623","0.00959"
"100.18800","8.34919","0.01000"
"100.46400","8.37221","0.00959"
"100.74000","8.39517","0.00791"
"101.01600","8.41819","0.00873"
"101.29200","8.44115","0.00857"
"101.56800","8.46422","0.00865"
"101.84400","8.48712","0.00913"
"102.12000","8.51020","0.00933"
"102.39600","8.53316","0.00905"
"102.67200","8.55618","0.00971"
"102.94800","8.57914","0.00909"
"103.22400","8.60222","0.00979"
"103.50000","8.62524","0.00976"
"103.77600","8.64826","0.00999"
"104.05200","8.67122","0.01010"
"104.32800","8.69418","0.01004"
"104.60400","8.71719","0.01030"
"104.88000","8.74009","0.01006"
"105.15600","8.76317","0.00996"
"105.43200","8.78613","0.01009"
"105.70800","8.80921","0.01025"
"105.98400","8.83217","0.00953"
"106.26000","8.85519","0.00997"
"106.53600","8.87815","0.01004"
"106.81200","8.90123","0.01034"
"107.08800","8.92419","0.01013"
"107.36400","8.94726","0.01060"
"107.64000","8.97016","0.01092"
"107.91600","8.99324","0.01091"
"108.19200","9.01614","0.01051"
"108.46800","9.03922","0.01071"
"108.74400","9.06212","0.01101"
"109.02000","9.08520","0.01139"
"109.29600","9.10810","0.01105"
"109.57200","9.13124","0.01146"
"109.84800","9.15420","0.01133"
"110.12400","9.17722","0.01169"
"110.40000","9.20017","0.01187"
"110.67600","9.22319","0.01210"
"110.95200","9.24621","0.01240"
"111.22800","9.26923","0.01111"
"111.50400","9.29213","0.01161"
"111.78000","9.31521","0.01209"
"112.05600","9.33817","0.01241"
"112.33200","9.36119","0.01262"
"112.60800","9.38421","0.01251"
"112.88400","9.40717","0.01240"
"113.16000","9.43012","0.01273"
"113.43600","9.45320","0.01321"
"113.71200","9.47622","0.01345"
"113.98800","9.49924","0.01350"
"114.26400","9.52226","0.01402"
"114.54000","9.54522","0.01429"
"114.81600","9.56824","0.01159"
"115.09200","9.59114","0.01181"
"115.36800","9.61422","0.01261"
"115.64400","9.63718","0.01256"
"115.92000","9.66026","0.01314"
"116.19600","9.68315","0.01337"
"116.47200","9.70623","0.01367"
"116.74800","9.72913","0.01446"
"117.02400","9.75221","0.01482"
"117.30000","9.77511","0.01458"
"117.57600","9.79819","0.01543"
"117.85200","9.82115","0.01552"
"118.12800","9.84429","0.01590"
"118.40400","9.86719","0.01657"
"118.68000","9.89026","0.01717"
"118.95600","9.91316","0.01735"
"119.23200","9.93618","0.01651"
"119.50800","9.95914","0.01686"
"119.78400","9.98222","0.01545"
"120.06000","10.00518","0.01556"
"120.33600","10.02820","0.01581"
"120.61200","10.05122","0.01666"
"120.88800","10.07424","0.01762"
"121.16400","10.09720","0.01797"
"121.44000","10.12022","0.01810"
"121.71600","10.14323","0.01929"
"121.99200","10.16625","0.01980"
"122.26800","10.18915","0.02035"
"122.54400","10.21217","0.02133"
"122.82000","10.23519","0.02271"
"123.09600","10.25821","0.02308"
"123.37200","10.28123","0.02353"
"123.64800","10.30419","0.02424"
"123.92400","10.32721","0.02476"
"124.20000","10.35023","0.02568"
"124.47600","10.37324","0.02563"
"124.75200","10.39620","0.02667"
"125.02800","10.41922","0.02768"
"125.30400","10.44218","0.02857"
"125.58000","10.46520","0.03015"
"125.85600","10.48816","0.03104"
"126.13200","10.51124","0.03210"
"126.40800","10.53414","0.03284"
"126.68400","10.55722","0.03389"
"126.96000","10.58018","0.03483"
"127.23600","10.60320","0.03663"
"127.51200","10.62615","0.03802"
"127.78800","10.64917","0.03948"
"128.06400","10.67219","0.04075"
"128.34000","10.69521","0.04175"
"128.61600","10.71817","0.04316"
"128.89200","10.74125","0.04390"
"129.16800","10.76421","0.04541"
"129.44400","10.78723","0.04636"
"129.72000","10.81013","0.04717"
"129.99600","10.83315","0.04740"
"130.27200","10.85610","0.04875"
"130.54800","10.87918","0.04982"
"130.82400","10.90214","0.05144"
"131.10000","10.92522","0.05217"
"131.37600","10.94818","0.05331"
"131.65200","10.97126","0.05335"
"131.92800","10.99422","0.05204"
"132.20400","11.01718","0.05087"
"132.48000","11.04014","0.01077"
"132.75600","11.06322","0.01125"
"133.03200","11.08617","0.01104"
"133.30800","11.10925","0.01084"
"133.58400","11.13215","0.01096"
"133.86000","11.15517","0.01210"
"134.13600","11.17813","0.01186"
"134.41200","11.20115","0.01300"
"134.68800","11.22417","0.01273"
"134.96400","11.24719","0.01307"
"135.24000","11.27021","0.01376"
"135.51600","11.29317","0.01407"
"135.79200","11.31625","0.01426"
"136.06800","11.33926","0.01479"
"136.34400","11.36222","0.01532"
"136.62000","11.38518","0.01542"
"136.89600","11.40820","0.01617"
"137.17200","11.43116","0.01609"
"137.44800","11.45418","0.01668"
"137.72400","11.47714","0.01702"
"138.00000","11.50022","0.01761"
"138.27600","11.52318","0.01864"
"138.55200","11.54620","0.01841"
"138.82800","11.56916","0.01965"
"139.10400","11.59223","0.01959"
"139.38000","11.61519","0.02005"
"139.65600","11.63827","0.02030"
"139.93200","11.66117","0.02091"
"140.20800","11.68419","0.02116"
"140.48400","11.70715","0.02196"
"140.76000","11.73023","0.02226"
"141.03600","11.75313","0.02284"
"141.31200","11.77621","0.02373"
"141.58800","11.79911","0.02444"
"141.86400","11.82224","0.02410"
"142.14000","11.84508","0.02517"
"142.41600","11.86822","0.02601"
"142.69200","11.89118","0.02664"
"142.96800","11.91420","0.02650"
"143.24400","11.93716","0.02692"
"143.52000","11.96024","0.02780"
"143.79600","11.98320","0.02852"
"144.07200","12.00622","0.02885"
"144.34800","12.02918","0.02949"
"144.62400","12.05219","0.02997"
"144.90000","12.07515","0.03007"
"145.17600","12.09817","0.03117"
"145.45200","12.12119","0.03096"
"145.72800","12.14421","0.03217"
"146.00400","12.16723","0.03253"
"146.28000","12.19019","0.03407"
"146.55600","12.21321","0.03423"
"146.83200","12.23623","0.03508"
"147.10800","12.25925","0.03589"
"147.38400","12.28215","0.03681"
"147.66000","12.30522","0.03766"
"147.93600","12.32818","0.03821"
"148.21200","12.35120","0.03932"
"148.48800","12.37416","0.04033"
"148.76400","12.39718","0.04080"
"149.04000","12.42014","0.04190"
"149.31600","12.44322","0.04119"
"149.59200","12.46612","0.04237"
"149.86800","12.48920","0.04228"
"150.14400","12.51216","0.04380"
"150.42000","12.53529","0.04443"
"150.69600","12.55813","0.04437"
"150.97200","12.58121","0.04534"
"151.24800","12.60417","0.04564"
"151.52400","12.62725","0.04682"
"151.80000","12.65015","0.04759"
"152.07600","12.67329","0.04799"
"152.35200","12.69619","0.04894"
"152.62800","12.71927","0.04913"
"152.90400","12.74217","0.05005"
"153.18000","12.76525","0.05125"
"153.45600","12.78820","0.05223"
"153.73200","12.81122","0.05292"
"154.00800","12.83424","0.05340"
"154.28400","12.85726","0.05438"
"154.56000","12.88022","0.05509"
"154.83600","12.90324","0.05533"
"155.11200","12.92620","0.05599"
"155.38800","12.94922","0.05709"
"155.66400","12.97218","0.05724"
"155.94000","12.99520","0.05806"
"156.21600","13.01815","0.05591"
"156.49200","13.04117","0.05742"
"156.76800","13.06425","0.05847"
"157.04400","13.08721","0.05817"
"157.32000","13.11023","0.06002"
"157.59600","13.13325","0.05962"
"157.87200","13.15627","0.06176"
"158.14800","13.17917","0.06244"
"158.42400","13.20219","0.06329"
"158.70000","13.22515","0.06402"
"158.97600","13.24817","0.06577"
"159.25200","13.27112","0.06616"
"159.52800","13.29426","0.06818"
"159.80400","13.31722","0.06814"
"160.08000","13.34024","0.07034"
"160.35600","13.36314","0.07145"
"160.63200","13.38622","0.07220"
"160.90800","13.40912","0.07400"
"161.18400","13.43220","0.07568"
"161.46000","13.45516","0.07730"
"161.73600","13.47824","0.07916"
"162.01200","13.50119","0.08052"
"162.28800","13.52415","0.08150"
"162.56400","13.54711","0.08318"
"162.84000","13.57019","0.08377"
"163.11600","13.59315","0.08558"
"163.39200","13.61623","0.08688"
"163.66800","13.63919","0.08847"
"163.94400","13.66221","0.08940"
"164.22000","13.68517","0.09039"
"164.49600","13.70819","0.09170"
"164.77200","13.73120","0.09238"
"165.04800","13.75422","0.09329"
"165.32400","13.77724","0.09405"
"165.60000","13.80026","0.09497"
"165.87600","13.82322","0.09555"
"166.15200","13.84618","0.09644"
"166.42800","13.86920","0.09707"
"166.70400","13.89216","0.09752"
"166.98000","13.91524","0.09843"
"167.25600","13.93826","0.09872"
"167.53200","13.96122","0.09954"
"167.80800","13.98423","0.09976"
"168.08400","14.00725","0.10041"
"168.36000","14.03015","0.10060"
"168.63600","14.05317","0.10128"
"168.91200","14.07613","0.10198"
"169.18800","14.09921","0.10213"
"169.46400","14.12217","0.10263"
"169.74000","14.14525","0.10309"
"170.01600","14.16815","0.10373"
"170.29200","14.19117","0.10402"
"170.56800","14.21412","0.10505"
"170.84400","14.23714","0.10580"
"171.12000","14.26016","0.10598"
"171.39600","14.28318","0.10662"
"171.67200","14.30620","0.10763"
"171.94800","14.32922","0.10870"
"172.22400","14.35218","0.10944"
"172.50000","14.37526","0.11041"
"172.77600","14.39816","0.11178"
"173.05200","14.42118","0.11274"
"173.32800","14.44408","0.11376"
"173.60400","14.46715","0.11524"
"173.88000","14.49011","0.11657"
"174.15600","14.51319","0.11807"
"174.43200","14.53615","0.12008"
"174.70800","14.55923","0.12139"
"174.98400","14.58219","0.12297"
"175.26000","14.60521","0.12579"
"175.53600","14.62823","0.12698"
"175.81200","14.65125","0.12925"
"176.08800","14.67421","0.13136"
"176.36400","14.69722","0.13323"
"176.64000","14.72018","0.13661"
"176.91600","14.74320","0.13896"
"177.19200","14.76616","0.14156"
"177.46800","14.78918","0.14295"
"177.74400","14.81220","0.14649"
"178.02000","14.83516","0.14761"
"178.29600","14.85824","0.15011"
"178.57200","14.88120","0.15152"
"178.84800","14.90422","0.15337"
"179.12400","14.92723","0.15563"
"179.40000","14.95019","0.15523"
"179.67600","14.97321","0.15650"
"179.95200","14.99623","0.15764"
"180.22800","15.01919","0.15889"
"180.50400","15.04221","0.15968"
"180.78000","15.06517","0.16041"
"181.05600","15.08819","0.16168"
"181.33200","15.11115","0.16357"
"181.60800","15.13417","0.16450"
"181.88400","15.15719","0.16634"
"182.16000","15.18020","0.16750"
"182.43600","15.20316","0.16863"
"182.71200","15.22624","0.16965"
"182.98800","15.24920","0.17143"
"183.26400","15.27222","0.17260"
"183.54000","15.29512","0.17478"
"183.81600","15.31820","0.17616"
"184.09200","15.34116","0.17747"
"184.36800","15.36424","0.17977"
"184.64400","15.38714","0.18140"
"184.92000","15.41021","0.18400"
"185.19600","15.43311","0.18603"
"185.47200","15.45625","0.18765"
"185.74800","15.47915","0.18976"
"186.02400","15.50223","0.19096"
"186.30000","15.52519","0.19225"
"186.57600","15.54827","0.19455"
"186.85200","15.57117","0.19614"
"187.12800","15.59425","0.19716"
"187.40400","15.61721","0.19860"
"187.68000","15.64022","0.20068"
"187.95600","15.66318","0.20116"
"188.23200","15.68620","0.20279"
"188.50800","15.70922","0.20363"
"188.78400","15.73218","0.20484"
"189.06000","15.75520","0.20584"
"189.33600","15.77816","0.20716"
"189.61200","15.80118","0.20776"
"189.88800","15.82420","0.20890"
"190.16400","15.84727","0.21044"
"190.44000","15.87017","0.21070"
"190.71600","15.89319","0.21191"
"190.99200","15.91615","0.21289"
"191.26800","15.93923","0.21392"
"191.54400","15.96213","0.21518"
"191.82000","15.98521","0.21674"
"192.09600","16.00817","0.21798"
"192.37200","16.03119","0.21978"
"192.64800","16.05415","0.22185"
"192.92400","16.07723","0.22398"
"193.20000","16.10019","0.22547"
"193.47600","16.12320","0.22701"
"193.75200","16.14616","0.22876"
"194.02800","16.16924","0.23061"
"194.30400","16.19220","0.23121"
"194.58000","16.21522","0.23301"
"194.85600","16.23812","0.23512"
"195.13200","16.26120","0.23681"
"195.40800","16.28416","0.23846"
"195.68400","16.30724","0.24064"
"195.96000","16.33020","0.24298"
"196.23600","16.35321","0.24440"
"196.51200","16.37617","0.24610"
"196.78800","16.39919","0.24745"
"197.06400","16.42215","0.24867"
"197.34000","16.44517","0.25101"
"197.61600","16.46819","0.25217"
"197.89200","16.49121","0.25377"
"198.16800","16.51417","0.25542"
"198.44400","16.53719","0.25667"
"198.72000","16.56015","0.25813"
"198.99600","16.58311","0.25976"
"199.27200","16.60618","0.26098"
"199.54800","16.62920","0.26261"
"199.82400","16.65222","0.26415"
"200.10000","16.67518","0.26618"
"200.37600","16.69820","0.26847"
"200.65200","16.72122","0.27077"
"200.92800","16.74424","0.27216"
"201.20400","16.76720","0.27542"
"201.48000","16.79022","0.27747"
"201.75600","16.81318","0.27995"
"202.03200","16.83619","0.28307"
"202.30800","16.85915","0.28557"
"202.58400","16.88223","0.19728"
"202.86000","16.90513","0.08555"
"203.13600","16.92821","0.08495"
"203.41200","16.95117","0.09110"
"203.68800","16.97425","0.08518"
"203.96400","16.99715","0.08716"
"204.24000","17.02029","0.08565"
"204.51600","17.04313","0.08741"
"204.79200","17.06620","0.08834"
"205.06800","17.08916","0.08869"
"205.34400","17.11218","0.08901"
"205.62000","17.13514","0.09081"
"205.89600","17.15816","0.08647"
"206.17200","17.18112","0.09264"
"206.44800","17.20420","0.08640"
"206.72400","17.22710","0.09411"
"207.00000","17.25018","0.08824"
"207.27600","17.27314","0.09322"
"207.55200","17.29622","0.09017"
"207.82800","17.31923","0.09358"
"208.10400","17.34225","0.09218"
"208.38000","17.36521","0.09493"
"208.65600","17.38823","0.09212"
"208.93200","17.41119","0.09641"
"209.20800","17.43421","0.09138"
"209.48400","17.45717","0.09760"
"209.76000","17.48019","0.09217"
"210.03600","17.50321","0.09756"
"210.31200","17.52623","0.09400"
"210.58800","17.54924","0.09723"
"210.86400","17.57220","0.09530"
"211.14000","17.59522","0.09712"
"211.41600","17.61818","0.09554"
"211.69200","17.64120","0.09776"
"211.96800","17.66416","0.09492"
"212.24400","17.68718","0.09819"
"212.52000","17.71020","0.09598"
"212.79600","17.73322","0.09785"
"213.07200","17.75618","0.09714"
"213.34800","17.77920","0.09695"
"213.62400","17.80215","0.09846"
"213.90000","17.82517","0.09773"
"214.17600","17.84819","0.09865"
"214.45200","17.87121","0.09785"
"214.72800","17.89417","0.09916"
"215.00400","17.91725","0.09906"
"215.28000","17.94021","0.10051"
"215.55600","17.96323","0.09877"
"215.83200","17.98619","0.10104"
"216.10800","18.00920","0.09852"
"216.38400","18.03217","0.10165"
"216.66000","18.05524","0.09963"
"216.93600","18.07820","0.10140"
"217.21200","18.10122","0.10052"
"217.48800","18.12412","0.10182"
"217.76400","18.14720","0.10103"
"218.04000","18.17022","0.10175"
"218.31600","18.19318","0.10095"
"218.59200","18.21626","0.10184"
"218.86800","18.23927","0.10200"
"219.14400","18.26224","0.10171"
"219.42000","18.28519","0.10272"
"219.69600","18.30821","0.10139"
"219.97200","18.33117","0.10366"
"220.24800","18.35419","0.10191"
"220.52400","18.37721","0.10373"
"220.80000","18.40017","0.10290"
"221.07600","18.42319","0.10424"
"221.35200","18.44621","0.10303"
"221.62800","18.46922","0.10476"
"221.90400","18.49218","0.10338"
"222.18000","18.51521","0.10489"
"222.45600","18.53822","0.10404"
"222.73200","18.56118","0.10412"
"223.00800","18.58426","0.10466"
"223.28400","18.60722","0.10443"
"223.56000","18.63024","0.10544"
"223.83600","18.65320","0.10472"
"224.11200","18.67628","0.10631"
"224.38800","18.69918","0.10538"
"224.66400","18.72219","0.10670"
"224.94000","18.74515","0.10541"
"225.21600","18.76818","0.10796"
"225.49200","18.79113","0.10589"
"225.76800","18.81421","0.10735"
"226.04400","18.83717","0.10736"
"226.32000","18.86025","0.10703"
"226.59600","18.88315","0.10854"
"226.87200","18.90623","0.10750"
"227.14800","18.92913","0.10921"
"227.42400","18.95221","0.10847"
"227.70000","18.97516","0.11041"
"227.97600","18.99818","0.10803"
"228.25200","19.02114","0.11093"
"228.52800","19.04422","0.10894"
"228.80400","19.06718","0.11030"
"229.08000","19.09020","0.11042"
"229.35600","19.11316","0.11021"
"229.63200","19.13624","0.11222"
"229.90800","19.15920","0.11117"
"230.18400","19.18222","0.11371"
"230.46000","19.20518","0.11156"
"230.73600","19.22819","0.11525"
"231.01200","19.25115","0.11233"
"231.28800","19.27417","0.11527"
"231.56400","19.29719","0.11366"
"231.84000","19.32021","0.11394"
"232.11600","19.34317","0.11570"
"232.39200","19.36619","0.11435"
"232.66800","19.38915","0.11698"
"232.94400","19.41217","0.11552"
"233.22000","19.43519","0.11867"
"233.49600","19.45815","0.11592"
"233.77200","19.48122","0.11928"
"234.04800","19.50418","0.11685"
"234.32400","19.52720","0.11856"
"234.60000","19.55010","0.11951"
"234.87600","19.57318","0.11831"
"235.15200","19.59614","0.12107"
"235.42800","19.61922","0.11880"
"235.70400","19.64218","0.12234"
"235.98000","19.66520","0.11994"
"236.25600","19.68816","0.12290"
"236.53200","19.71123","0.12127"
"236.80800","19.73413","0.12296"
"237.08400","19.75721","0.12336"
"237.36000","19.78017","0.12204"
"237.63600","19.80325","0.12678"
"237.91200","19.82615","0.12305"
"238.18800","19.84923","0.12645"
"238.46400","19.87213","0.12502"
"238.74000","19.89521","0.12670"
"239.01600","19.91817","0.12643"
"239.29200","19.94124","0.12732"
"239.56800","19.96414","0.12937"
"239.84400","19.98716","0.12711"
"240.12000","20.01018","0.13153"
"240.39600","20.03326","0.12793"
"240.67200","20.05616","0.13149"
"240.94800","20.07918","0.13022"
"241.22400","20.10220","0.13124"
"241.50000","20.12522","0.13332"
"241.77600","20.14824","0.13166"
"242.05200","20.17113","0.13553"
"242.32800","20.19415","0.13339"
"242.60400","20.21717","0.13636"
"242.88000","20.24019","0.13438"
"243.15600","20.26315","0.13659"
"243.43200","20.28623","0.13701"
"243.70800","20.30919","0.13547"
"243.98400","20.33227","0.13983"
"244.26000","20.35517","0.13778"
"244.53600","20.37825","0.14197"
"244.81200","20.40121","0.14017"
"245.08800","20.42417","0.14209"
"245.36400","20.44712","0.14209"
"245.64000","20.47020","0.14186"
"245.91600","20.49316","0.14537"
"246.19200","20.51618","0.14209"
"246.46800","20.53920","0.14582"
"246.74400","20.56222","0.14471"
"247.02000","20.58512","0.14564"
"247.29600","20.60826","0.14582"
"247.57200","20.63116","0.14572"
"247.84800","20.65424","0.14772"
"248.12400","20.67719","0.14535"
"248.40000","20.70021","0.14879"
"248.67600","20.72317","0.14709"
"248.95200","20.74619","0.14874"
"249.22800","20.76915","0.14997"
"249.50400","20.79217","0.14802"
"249.78000","20.81513","0.15106"
"250.05600","20.83821","0.14927"
"250.33200","20.86111","0.15118"
"250.60800","20.88418","0.15034"
"250.88400","20.90720","0.15206"
"251.16000","20.93022","0.15232"
"251.43600","20.95318","0.15177"
"251.71200","20.97626","0.15421"
"251.98800","20.99922","0.15238"
"252.26400","21.02218","0.15366"
"252.54000","21.04520","0.15409"
"252.81600","21.06821","0.15358"
"253.09200","21.09124","0.15590"
"253.36800","21.11420","0.15428"
"253.64400","21.13721","0.15628"
"253.92000","21.16017","0.15501"
"254.19600","21.18319","0.15665"
"254.47200","21.20621","0.15683"
"254.74800","21.22923","0.15695"
"255.02400","21.25213","0.15788"
"255.30000","21.27527","0.15717"
"255.57600","21.29817","0.15909"
"255.85200","21.32119","0.15810"
"256.12800","21.34414","0.15895"
"256.40400","21.36722","0.15973"
"256.68000","21.39018","0.15899"
"256.95600","21.41320","0.16054"
"257.23200","21.43616","0.15951"
"257.50800","21.45924","0.16058"
"257.78400","21.48214","0.16100"
"258.06000","21.50522","0.16069"
"258.33600","21.52812","0.16176"
"258.61200","21.55125","0.16072"
"258.88800","21.57422","0.16221"
"259.16400","21.59723","0.16187"
"259.44000","21.62013","0.16173"
"259.71600","21.64315","0.16295"
"259.99200","21.66611","0.16197"
"260.26800","21.68919","0.16311"
"260.54400","21.71215","0.16281"
"260.82000","21.73523","0.16390"
"261.09600","21.75819","0.16414"
"261.37200","21.78121","0.16382"
"261.64800","21.80416","0.16466"
"261.92400","21.82724","0.16407"
"262.20000","21.85020","0.16499"
"262.47600","21.87322","0.16461"
"262.75200","21.89624","0.16482"
"263.02800","21.91920","0.16568"
"263.30400","21.94216","0.16506"
"263.58000","21.96512","0.16689"
"263.85600","21.98820","0.16610"
"264.13200","22.01122","0.16651"
"264.40800","22.03418","0.16748"
"264.68400","22.05719","0.16672"
"264.96000","22.08022","0.16796"
"265.23600","22.10324","0.16740"
"265.51200","22.12619","0.16749"
"265.78800","22.14915","0.16851"
"266.06400","22.17223","0.16794"
"266.34000","22.19519","0.16939"
"266.61600","22.21821","0.16850"
"266.89200","22.24117","0.16960"
"267.16800","22.26419","0.17018"
"267.44400","22.28720","0.16984"
"267.72000","22.31017","0.17044"
"267.99600","22.33318","0.16998"
"268.27200","22.35620","0.17128"
"268.54800","22.37916","0.17095"
"268.82400","22.40218","0.17131"
"269.10000","22.42514","0.17259"
"269.37600","22.44816","0.17159"
"269.65200","22.47112","0.17264"
"269.92800","22.49420","0.17266"
"270.20400","22.51716","0.17281"
"270.48000","22.54018","0.17334"
"270.75600","22.56314","0.17357"
"271.03200","22.58615","0.17484"
"271.30800","22.60911","0.17464"
"271.58400","22.63219","0.17452"
"271.86000","22.65515","0.17578"
"272.13600","22.67823","0.17531"
"272.41200","22.70119","0.17629"
"272.68800","22.72427","0.17686"
"272.96400","22.74717","0.17638"
"273.24000","22.77024","0.17730"
"273.51600","22.79321","0.17643"
"273.79200","22.81622","0.17852"
"274.06800","22.83918","0.17802"
"274.34400","22.86220","0.17834"
"274.62000","22.88522","0.17918"
"274.89600","22.90818","0.17892"
"275.17200","22.93120","0.17991"
"275.44800","22.95422","0.18034"
"275.72400","22.97718","0.18022"
"276.00000","23.00020","0.18195"
"276.27600","23.02327","0.18117"
"276.55200","23.04618","0.18228"
"276.82800","23.06925","0.18190"
"277.10400","23.09215","0.18224"
"277.38000","23.11523","0.18378"
"277.65600","23.13813","0.18360"
"277.93200","23.16115","0.18463"
"278.20800","23.18411","0.18433"
"278.48400","23.20719","0.18509"
"278.76000","23.23009","0.18551"
"279.03600","23.25317","0.18480"
"279.31200","23.27613","0.18621"
"279.58800","23.29926","0.18615"
"279.86400","23.32216","0.18669"
"280.14000","23.34524","0.18758"
"280.41600","23.36820","0.18787"
"280.69200","23.39122","0.18822"
"280.96800","23.41418","0.18872"
"281.24400","23.43726","0.18903"
"281.52000","23.46016","0.18977"
"281.79600","23.48318","0.18931"
"282.07200","23.50613","0.18942"
"282.34800","23.52927","0.19126"
"282.62400","23.55217","0.19011"
"282.90000","23.57519","0.19128"
"283.17600","23.59821","0.19176"
"283.45200","23.62123","0.19258"
"283.72800","23.64413","0.19250"
"284.00400","23.66721","0.19272"
"284.28000","23.69023","0.19362"
"284.55600","23.71325","0.19354"
"284.83200","23.73621","0.19322"
"285.10800","23.75922","0.19413"
"285.38400","23.78218","0.19399"
"285.66000","23.80514","0.19494"
"285.93600","23.82816","0.19548"
"286.21200","23.85118","0.19589"
"286.48800","23.87426","0.19686"
"286.76400","23.89722","0.19706"
"287.04000","23.92030","0.19792"
"287.31600","23.94320","0.19788"
"287.59200","23.96627","0.19799"
"287.86800","23.98917","0.19878"
"288.14400","24.01220","0.19928"
"288.42000","24.03515","0.19937"
"288.69600","24.05823","0.19989"
"288.97200","24.08113","0.19981"
"289.24800","24.10415","0.20049"
"289.52400","24.12711","0.20105"
"289.80000","24.15019","0.20098"
"290.07600","24.17315","0.20181"
"290.35200","24.19623","0.20150"
"290.62800","24.21918","0.20203"
"290.90400","24.24226","0.20311"
"291.18000","24.26516","0.20308"
"291.45600","24.28818","0.20387"
"291.73200","24.31114","0.20395"
"292.00800","24.33422","0.20399"
"292.28400","24.35718","0.20440"
"292.56000","24.38020","0.20481"
"292.83600","24.40316","0.20513"
"293.11200","24.42624","0.20554"
"293.38800","24.44914","0.20558"
"293.66400","24.47216","0.20632"
"293.94000","24.49517","0.20614"
"294.21600","24.51819","0.20652"
"294.49200","24.54115","0.20678"
"294.76800","24.56423","0.20702"
"295.04400","24.58725","0.20711"
"295.32000","24.61021","0.20777"
"295.59600","24.63317","0.20783"
"295.87200","24.65613","0.20824"
"296.14800","24.67921","0.20824"
"296.42400","24.70217","0.20853"
"296.70000","24.72524","0.20886"
"296.97600","24.74820","0.20903"
"297.25200","24.77122","0.20929"
"297.52800","24.79418","0.20977"
"297.80400","24.81720","0.20974"
"298.08000","24.84016","0.21020"
"298.35600","24.86318","0.21011"
"298.63200","24.88620","0.21054"
"298.90800","24.90922","0.21112"
"299.18400","24.93218","0.21141"
"299.46000","24.95520","0.21179"
"299.73600","24.97809","0.21201"
"300.01200","25.00117","0.21220"
"300.28800","25.02413","0.21225"
"300.56400","25.04721","0.21249"
"300.84000","25.07017","0.21235"
"301.11600","25.09319","0.21302"
"301.39200","25.11615","0.21304"
"301.66800","25.13923","0.21341"
"301.94400","25.16213","0.21361"
"302.22000","25.18521","0.21379"
"302.49600","25.20816","0.21417"
"302.77200","25.23118","0.21462"
"303.04800","25.25414","0.21453"
"303.32400","25.27722","0.21482"
"303.60000","25.30012","0.21535"
"303.87600","25.32320","0.21532"
"304.15200","25.34622","0.21588"
"304.42800","25.36918","0.21577"
"304.70400","25.39219","0.21634"
"304.98000","25.41527","0.21696"
"305.25600","25.43824","0.21655"
"305.53200","25.46119","0.21709"
"305.80800","25.48421","0.21724"
"306.08400","25.50717","0.21746"
"306.36000","25.53019","0.21780"
"306.63600","25.55315","0.21808"
"306.91200","25.57617","0.21816"
"307.18800","25.59913","0.21835"
"307.46400","25.62221","0.21785"
"307.74000","25.64517","0.21375"
"308.01600","25.66825","0.21121"
"308.29200","25.69120","-0.00358"
"308.56800","25.71422","-0.00641"
"308.84400","25.73712","-0.00031"
"309.12000","25.76020","-0.00049"
"309.39600","25.78316","-0.00133"
"309.67200","25.80624","-0.00099"
"309.94800","25.82920","0.00051"
"310.22400","25.85222","-0.00104"
"310.50000","25.87518","-0.00065"
"310.77600","25.89820","-0.00122"
"311.05200","25.92115","-0.00058"
"311.32800","25.94417","0.00100"
"311.60400","25.96713","-0.00119"
"311.88000","25.99027","-0.00133"
"312.15600","26.01317","-0.00106"
"312.43200","26.03619","0.00056"
"312.70800","26.05921","-0.00048"
"312.98400","26.08223","-0.00140"
"313.26000","26.10513","-0.00121"
"313.53600","26.12821","-0.00081"
"313.81200","26.15117","0.00011"
"314.08800","26.17418","-0.00099"
"314.36400","26.19708","-0.00084"
"314.64000","26.22022","-0.00097"
"314.91600","26.24318","0.00003"
"315.19200","26.26620","0.00013"
"315.46800","26.28916","-0.00080"
"315.74400","26.31224","-0.00144"
"316.02000","26.33520","-0.00099"
"316.29600","26.35827","0.00053"
"316.57200","26.38124","-0.00116"
"316.84800","26.40419","-0.00108"
"317.12400","26.42715","-0.00102"
"317.40000","26.45017","0.00003"
"317.67600","26.47319","-0.00055"
"317.95200","26.49615","-0.00055"
"318.22800","26.51923","-0.00112"
"318.50400","26.54219","-0.00078"
"318.78000","26.56521","0.00064"
"319.05600","26.58817","-0.00026"
"319.33200","26.61130","-0.00136"
"319.60800","26.63415","-0.00072"
"319.88400","26.65722","-0.00037"
"320.16000","26.68018","0.00016"
"320.43600","26.70320","-0.00103"
"320.71200","26.72616","-0.00095"
"320.98800","26.74924","-0.00056"
"321.26400","26.77220","0.00031"
"321.54000","26.79522","-0.00140"
"321.81600","26.81812","-0.00109"
"322.09200","26.84120","-0.00087"
"322.36800","26.86416","-0.00070"
"322.64400","26.88723","0.00009"
"322.92000","26.91013","-0.00139"
"323.19600","26.93327","-0.00125"
"323.47200","26.95617","-0.00058"
"323.74800","26.97925","0.00059"
"324.02400","27.00215","-0.00041"
"324.30000","27.02523","-0.00044"
"324.57600","27.04819","-0.00072"
"324.85200","27.07127","-0.00066"
"325.12800","27.09422","0.00048"
"325.40400","27.11724","-0.00046"
"325.68000","27.14020","-0.00098"
"325.95600","27.16322","-0.00064"
"326.23200","27.18618","0.00052"
"326.50800","27.20920","0.00014"
"326.78400","27.23216","-0.00099"
"327.06000","27.25524","-0.00113"
"327.33600","27.27820","0.00022"
"327.61200","27.30122","-0.00011"
"327.88800","27.32417","-0.00068"
"328.16400","27.34713","-0.00104"
"328.44000","27.37016","-0.00109"
"328.71600","27.39317","0.00103"
"328.99200","27.41619","0.00025"
"329.26800","27.43915","-0.00049"
"329.54400","27.46223","-0.00042"
"329.82000","27.48519","0.00061"
"330.09600","27.50827","0.00002"
"330.37200","27.53117","-0.00103"
"330.64800","27.55425","-0.00066"
"330.92400","27.57721","0.00011"
"331.20000","27.60023","0.00023"
"331.47600","27.62312","-0.00040"
"331.75200","27.64620","-0.00144"
"332.02800","27.66916","-0.00048"
"332.30400","27.69218","0.00077"
"332.58000","27.71514","0.00007"
"332.85600","27.73822","-0.00084"
"333.13200","27.76112","-0.00040"
"333.40800","27.78426","0.00037"
"333.68400","27.80716","0.00082"
"333.96000","27.83024","-0.00027"
"334.23600","27.85313","-0.00016"
"334.51200","27.87621","0.00074"
"334.78800","27.89911","0.00071"
"335.06400","27.92219","-0.00030"
"335.34000","27.94515","-0.00055"
"335.61600","27.96817","0.00072"
"335.89200","27.99119","0.00096"
"336.16800","28.01421","-0.00033"
"336.44400","28.03717","-0.00021"
"336.72000","28.06019","0.00063"
"336.99600","28.08315","0.00085"
"337.27200","28.10622","0.00001"
"337.54800","28.12918","-0.00051"
"337.82400","28.15220","0.00026"
"338.10000","28.17522","0.00136"
"338.37600","28.19824","0.00003"
"338.65200","28.22126","-0.00042"
"338.92800","28.24416","0.00069"
"339.20400","28.26718","0.00057"
"339.48000","28.29020","0.00078"
"339.75600","28.31321","-0.00029"
"340.03200","28.33617","0.00027"
"340.30800","28.35925","0.00092"
"340.58400","28.38221","0.00079"
"340.86000","28.40523","0.00017"
"341.13600","28.42813","0.00001"
"341.41200","28.45121","0.00089"
"341.68800","28.47417","0.00092"
"341.96400","28.49725","-0.00029"
"342.24000","28.52015","0.00016"
"342.51600","28.54317","0.00051"
"342.79200","28.56612","0.00099"
"343.06800","28.58914","0.00081"
"343.34400","28.61216","0.00080"
"343.62000","28.63518","0.00088"
"343.89600","28.65814","0.00105"
"344.17200","28.68122","0.00042"
"344.44800","28.70418","0.00090"
"344.72400","28.72726","0.00075"
"345.00000","28.75022","0.00119"
"345.27600","28.77323","0.00090"
"345.55200","28.79614","0.00080"
"345.82800","28.81921","0.00076"
"346.10400","28.84217","0.00128"
"346.38000","28.86519","0.00099"
"346.65600","28.88815","0.00123"
"346.93200","28.91123","0.00150"
"347.20800","28.93419","0.00137"
"347.48400","28.95715","0.00143"
"347.76000","28.98017","0.00136"
"348.03600","29.00325","0.00161"
"348.31200","29.02621","0.00165"
"348.58800","29.04928","0.00168"
"348.86400","29.07224","0.00164"
"349.14000","29.09520","0.00149"
"349.41600","29.11816","0.00101"
"349.69200","29.14118","0.00151"
"349.96800","29.16420","0.00105"
"350.24400","29.18716","0.00141"
"350.52000","29.21018","0.00184"
"350.79600","29.23319","0.00128"
"351.07200","29.25621","0.00137"
"351.34800","29.27924","0.00138"
"351.62400","29.30225","0.00100"
"351.90000","29.32515","0.00153"
"352.17600","29.34823","0.00157"
"352.45200","29.37119","0.00115"
"352.72800","29.39421","0.00149"
"353.00400","29.41717","0.00149"
"353.28000","29.44025","0.00173"
"353.55600","29.46321","0.00116"
"353.83200","29.48622","0.00188"
"354.10800","29.50912","0.00175"
"354.38400","29.53220","0.00144"
"354.66000","29.55516","0.00214"
"354.93600","29.57824","0.00182"
"355.21200","29.60114","0.00189"
"355.48800","29.62422","0.00273"
"355.76400","29.64718","0.00254"
"356.04000","29.67020","0.00283"
"356.31600","29.69316","0.00274"
"356.59200","29.71623","0.00301"
"356.86800","29.73919","0.00280"
"357.14400","29.76221","0.00332"
"357.42000","29.78518","0.00260"
"357.69600","29.80819","0.00329"
"357.97200","29.83115","0.00338"
"358.24800","29.85417","0.00358"
"358.52400","29.87719","0.00334"
"358.80000","29.90021","0.00375"
"359.07600","29.92323","0.00378"
"359.35200","29.94625","0.00354"
"359.62800","29.96921","0.00419"
"359.90400","29.99216","0.00469"
"360.18000","30.01518","0.00437"
"360.45600","30.03814","0.00466"
"360.73200","30.06122","0.00511"
"361.00800","30.08418","0.00490"
"361.28400","30.10720","0.00491"
"361.56000","30.13022","0.00495"
"361.83600","30.15318","0.00496"
"362.11200","30.17620","0.00534"
"362.38800","30.19921","0.00523"
"362.66400","30.22212","0.00525"
"362.94000","30.24525","0.00540"
"363.21600","30.26822","0.00506"
"363.49200","30.29123","0.00620"
"363.76800","30.31413","0.00608"
"364.04400","30.33715","0.00638"
"364.32000","30.36011","0.00661"
"364.59600","30.38319","0.00697"
"364.87200","30.40609","0.00722"
"365.14800","30.42923","0.00706"
"365.42400","30.45213","0.00757"
"365.70000","30.47526","0.00752"
"365.97600","30.49816","0.00767"
"366.25200","30.52124","0.00757"
"366.52800","30.54420","0.00783"
"366.80400","30.56728","0.00769"
"367.08000","30.59018","0.00802"
"367.35600","30.61326","0.00805"
"367.63200","30.63616","0.00846"
"367.90800","30.65924","0.00810"
"368.18400","30.68213","0.00851"
"368.46000","30.70521","0.00876"
"368.73600","30.72817","0.00885"
"369.01200","30.75119","0.00902"
"369.28800","30.77421","0.00891"
"369.56400","30.79723","0.00867"
"369.84000","30.82019","0.00881"
"370.11600","30.84321","0.00779"
"370.39200","30.86617","0.00714"
"370.66800","30.88925","0.00709"
"370.94400","30.91221","0.00668"
"371.22000","30.93517","0.00679"
"371.49600","30.95819","0.00651"
"371.77200","30.98114","0.00711"
"372.04800","31.00416","0.00689"
"372.32400","31.02712","0.00728"
"372.60000","31.05020","0.00762"
"372.87600","31.07316","0.00753"
"373.15200","31.09624","0.00781"
"373.42800","31.11920","0.00755"
"373.70400","31.14222","0.00702"
"373.98000","31.16517","0.00761"
"374.25600","31.18825","0.00752"
"374.53200","31.21115","0.00820"
"374.80800","31.23423","0.00745"
"375.08400","31.25713","0.00759"
"375.36000","31.28021","0.00642"
"375.63600","31.30317","0.00589"
"375.91200","31.32619","0.00541"
"376.18800","31.34914","0.00382"
"376.46400","31.37222","0.00526"
"376.74000","31.39519","0.00567"
"377.01600","31.41826","0.00467"
"377.29200","31.44122","0.00471"
"377.56800","31.46418","0.00588"
"377.84400","31.48714","0.00587"
"378.12000","31.51016","0.00527"
"378.39600","31.53312","0.00532"
"378.67200","31.55620","0.00601"
"378.94800","31.57915","0.00547"
"379.22400","31.60217","0.00554"
"379.50000","31.62513","0.00580"
"379.77600","31.64816","0.00583"
"380.05200","31.67123","0.00572"
"380.32800","31.69419","0.00590"
"380.60400","31.71721","0.00638"
"380.88000","31.74023","0.00671"
"381.15600","31.76325","0.00680"
"381.43200","31.78621","0.00651"
"381.70800","31.80923","0.00640"
"381.98400","31.83218","0.00704"
"382.26000","31.85520","0.00675"
"382.53600","31.87816","0.00746"
"382.81200","31.90118","0.00708"
"383.08800","31.92420","0.00697"
"383.36400","31.94722","0.00710"
"383.64000","31.97012","0.00730"
"383.91600","31.99320","0.00692"
"384.19200","32.01610","0.00682"
"384.46800","32.03924","0.00700"
"384.74400","32.06219","0.00639"
"385.02000","32.08521","0.00649"
"385.29600","32.10817","0.00653"
"385.57200","32.13120","0.00674"
"385.84800","32.15416","0.00612"
"386.12400","32.17717","0.00626"
"386.40000","32.20013","0.00561"
"386.67600","32.22321","0.00517"
"386.95200","32.24617","0.00370"
"387.22800","32.26925","0.00209"
"387.50400","32.29214","0.00210"
"387.78000","32.31522","0.00206"
"388.05600","32.33818","0.00137"
"388.33200","32.36127","0.00146"
"388.60800","32.38422","0.00113"
"388.88400","32.40724","0.00089"
"389.16000","32.43020","0.00079"
"389.43600","32.45322","0.00172"
"389.71200","32.47618","0.00163"
"389.98800","32.49920","0.00112"
"390.26400","32.52216","0.00103"
"390.54000","32.54517","0.00157"
"390.81600","32.56820","0.00115"
"391.09200","32.59121","0.00053"
"391.36800","32.61423","0.00117"
"391.64400","32.63725","0.00092"
"391.92000","32.66021","0.00147"
"392.19600","32.68323","0.00086"
"392.47200","32.70619","0.00134"
"392.74800","32.72915","0.00148"
"393.02400","32.75217","0.00113"
"393.30000","32.77518","0.00186"
"393.57600","32.79821","0.00155"
"393.85200","32.82116","0.00175"
"394.12800","32.84418","0.00167"
"394.40400","32.86720","0.00164"
"394.68000","32.89022","0.00218"
"394.95600","32.91318","0.00168"
"395.23200","32.93620","0.00157"
"395.50800","32.95922","0.00203"
"395.78400","32.98224","0.00212"
"396.06000","33.00520","0.00201"
"396.33600","33.02821","0.00215"
"396.61200","33.05111","0.00213"
"396.88800","33.07419","0.00216"
"397.16400","33.09715","0.00180"
"397.44000","33.12024","0.00254"
"397.71600","33.14313","0.00231"
"397.99200","33.16621","0.00192"
"398.26800","33.18911","0.00260"
"398.54400","33.21219","0.00223"
"398.82000","33.23515","0.00213"
"399.09600","33.25822","0.00170"
"399.37200","33.28119","0.00213"
"399.64800","33.30426","0.00131"
"399.92400","33.32716","0.00170"
"400.20000","33.35018","0.00161"
"400.47600","33.37314","0.00198"
"400.75200","33.39616","0.00151"
"401.02800","33.41918","0.00152"
"401.30400","33.44220","0.00194"
"401.58000","33.46516","0.00205"
"401.85600","33.48824","0.00173"
"402.13200","33.51120","0.00212"
"402.40800","33.53421","0.00188"
"402.68400","33.55717","0.00229"
"402.96000","33.58019","0.00190"
"403.23600","33.60321","0.00204"
"403.51200","33.62617","0.00227"
"403.78800","33.64919","0.00205"
"404.06400","33.67221","0.00256"
"404.34000","33.69523","0.00288"
"404.61600","33.71819","0.00269"
"404.89200","33.74121","0.00310"
"405.16800","33.76416","0.00352"
"405.44400","33.78724","0.00322"
"405.72000","33.81020","0.00348"
"405.99600","33.83322","0.00319"
"406.27200","33.85612","0.00326"
"406.54800","33.87920","0.00352"
"406.82400","33.90210","0.00363"
"407.10000","33.92518","0.00089"
"407.37600","33.94814","0.00110"
"407.65200","33.97122","0.00131"
"407.92800","33.99412","-0.00002"
"408.20400","34.01719","0.00143"
"408.48000","34.04009","0.00100"
"408.75600","34.06323","0.00118"
"409.03200","34.08613","0.00085"
"409.30800","34.10921","0.00131"
"409.58400","34.13223","0.00093"
"409.86000","34.15525","0.00079"
"410.13600","34.17821","0.00055"
"410.41200","34.20123","0.00103"
"410.68800","34.22419","0.00048"
"410.96400","34.24715","0.00021"
"411.24000","34.27016","0.00054"
"411.51600","34.29318","0.00086"
"411.79200","34.31620","0.00047"
"411.87800","34.32338","0.00056"