File: Force_trajectories/161226_1/Specimen_RawData_6.csv
End date,"12/26/2016"
Specimen label,"22AG_78"
Maximum Load,"0.48193",N

Time,Extension,Load
(s),(mm),(N)
"0.00000","0.00000","0.00007"
"0.34200","0.02840","0.00034"
"0.68400","0.05716","0.00082"
"1.02600","0.08556","0.00078"
"1.36800","0.11408","0.00079"
"1.71000","0.14266","0.00123"
"2.05200","0.17112","0.00092"
"2.39400","0.19970","0.00137"
"2.73600","0.22816","0.00145"
"3.07800","0.25656","0.00138"
"3.42000","0.28520","0.00162"
"3.76200","0.31360","0.00162"
"4.10400","0.34206","0.00187"
"4.44600","0.37064","0.00259"
"4.78800","0.39910","0.00221"
"5.13000","0.42761","0.00213"
"5.47200","0.45613","0.00222"
"5.81400","0.48453","0.00220"
"6.15600","0.51317","0.00318"
"6.49800","0.54163","0.00255"
"6.84000","0.57009","0.00270"
"7.18200","0.59867","0.00294"
"7.52400","0.62713","0.00289"
"7.86600","0.65565","0.00270"
"8.20800","0.68411","0.00343"
"8.55000","0.71257","0.00335"
"8.89200","0.74115","0.00298"
"9.23400","0.76961","0.00381"
"9.57600","0.79807","0.00384"
"9.91800","0.82659","0.00378"
"10.26000","0.85511","0.00423"
"10.60200","0.88363","0.00370"
"10.94400","0.91209","0.00427"
"11.28600","0.94067","0.00375"
"11.62800","0.96907","0.00355"
"11.97000","0.99765","0.00380"
"12.31200","1.02611","0.00434"
"12.65400","1.05463","0.00412"
"12.99600","1.08309","0.00470"
"13.33800","1.11161","0.00450"
"13.68000","1.14007","0.00447"
"14.02200","1.16865","0.00432"
"14.36400","1.19705","0.00460"
"14.70600","1.22563","0.00441"
"15.04800","1.25415","0.00493"
"15.39000","1.28261","0.00484"
"15.73200","1.31112","0.00469"
"16.07400","1.33964","0.00475"
"16.41600","1.36810","0.00402"
"16.75800","1.39662","0.00435"
"17.10000","1.42508","0.00459"
"17.44200","1.45360","0.00395"
"17.78400","1.48218","0.00435"
"18.12600","1.51058","0.00400"
"18.46800","1.53910","0.00452"
"18.81000","1.56762","0.00483"
"19.15200","1.59608","0.00494"
"19.49400","1.62466","0.00455"
"19.83600","1.65312","0.00429"
"20.17800","1.68158","0.00407"
"20.52000","1.71016","0.00448"
"20.86200","1.73856","0.00406"
"21.20400","1.76714","0.00408"
"21.54600","1.79566","0.00434"
"21.88800","1.82406","0.00442"
"22.23000","1.85264","0.00451"
"22.57200","1.88110","0.00493"
"22.91400","1.90962","0.00492"
"23.25600","1.93814","0.00466"
"23.59800","1.96654","0.00468"
"23.94000","1.99512","0.00496"
"24.28200","2.02358","0.00490"
"24.62400","2.05204","0.00507"
"24.96600","2.08062","0.00533"
"25.30800","2.10914","0.00497"
"25.65000","2.13760","0.00533"
"25.99200","2.16612","0.00540"
"26.33400","2.19457","0.00572"
"26.67600","2.22309","0.00546"
"27.01800","2.25161","0.00547"
"27.36000","2.28007","0.00551"
"27.70200","2.30865","0.00577"
"28.04400","2.33711","0.00589"
"28.38600","2.36557","0.00617"
"28.72800","2.39409","0.00600"
"29.07000","2.42261","0.00616"
"29.41200","2.45107","0.00602"
"29.75400","2.47965","0.00627"
"30.09600","2.50811","0.00632"
"30.43800","2.53657","0.00688"
"30.78000","2.56515","0.00680"
"31.12200","2.59361","0.00638"
"31.46400","2.62207","0.00649"
"31.80600","2.65065","0.00680"
"32.14800","2.67905","0.00641"
"32.49000","2.70763","0.00656"
"32.83200","2.73615","0.00647"
"33.17400","2.76455","0.00710"
"33.51600","2.79313","0.00703"
"33.85800","2.82159","0.00702"
"34.20000","2.85011","0.00735"
"34.54200","2.87863","0.00674"
"34.88400","2.90709","0.00709"
"35.22600","2.93555","0.00689"
"35.56800","2.96419","0.00695"
"35.91000","2.99259","0.00717"
"36.25200","3.02111","0.00727"
"36.59400","3.04963","0.00731"
"36.93600","3.07802","0.00765"
"37.27800","3.10666","0.00741"
"37.62000","3.13512","0.00747"
"37.96200","3.16358","0.00759"
"38.30400","3.19216","0.00793"
"38.64600","3.22056","0.00762"
"38.98800","3.24914","0.00766"
"39.33000","3.27766","0.00802"
"39.67200","3.30606","0.00796"
"40.01400","3.33464","0.00834"
"40.35600","3.36316","0.00826"
"40.69800","3.39162","0.00843"
"41.04000","3.42014","0.00847"
"41.38200","3.44854","0.00832"
"41.72400","3.47706","0.00893"
"42.06600","3.50564","0.00842"
"42.40800","3.53404","0.00876"
"42.75000","3.56268","0.00878"
"43.09200","3.59114","0.00888"
"43.43400","3.61960","0.00908"
"43.77600","3.64812","0.00912"
"44.11800","3.67658","0.00907"
"44.46000","3.70510","0.00959"
"44.80200","3.73362","0.00964"
"45.14400","3.76214","0.00955"
"45.48600","3.79060","0.00972"
"45.82800","3.81912","0.00961"
"46.17000","3.84764","0.00989"
"46.51200","3.87610","0.00977"
"46.85400","3.90462","0.01026"
"47.19600","3.93307","0.01016"
"47.53800","3.96159","0.01051"
"47.88000","3.99011","0.01053"
"48.22200","4.01857","0.01062"
"48.56400","4.04715","0.01073"
"48.90600","4.07561","0.01062"
"49.24800","4.10413","0.01085"
"49.59000","4.13259","0.01103"
"49.93200","4.16111","0.01107"
"50.27400","4.18957","0.01153"
"50.61600","4.21815","0.01151"
"50.95800","4.24661","0.01154"
"51.30000","4.27507","0.01183"
"51.64200","4.30365","0.01229"
"51.98400","4.33211","0.01205"
"52.32600","4.36063","0.01218"
"52.66800","4.38909","0.01265"
"53.01000","4.41761","0.01298"
"53.35200","4.44613","0.01314"
"53.69400","4.47459","0.01346"
"54.03600","4.50311","0.01397"
"54.37800","4.53169","0.01407"
"54.72000","4.56003","0.01430"
"55.06200","4.58867","0.01431"
"55.40400","4.61713","0.01455"
"55.74600","4.64559","0.01439"
"56.08800","4.67417","0.01501"
"56.43000","4.70263","0.01556"
"56.77200","4.73109","0.01539"
"57.11400","4.75961","0.01582"
"57.45600","4.78807","0.01593"
"57.79800","4.81664","0.01648"
"58.14000","4.84510","0.01726"
"58.48200","4.87356","0.01727"
"58.82400","4.90214","0.01760"
"59.16600","4.93060","0.01821"
"59.50800","4.95912","0.01872"
"59.85000","4.98764","0.01908"
"60.19200","5.01604","0.01938"
"60.53400","5.04462","0.01987"
"60.87600","5.07314","0.01990"
"61.21800","5.10160","0.02021"
"61.56000","5.13012","0.01980"
"61.90200","5.15858","0.02123"
"62.24400","5.18710","0.02123"
"62.58600","5.21562","0.02176"
"62.92800","5.24408","0.02262"
"63.27000","5.27260","0.02218"
"63.61200","5.30112","0.02304"
"63.95400","5.32958","0.02310"
"64.29600","5.35810","0.02389"
"64.63800","5.38662","0.02373"
"64.98000","5.41514","0.02419"
"65.32200","5.44366","0.02515"
"65.66400","5.47212","0.02550"
"66.00600","5.50058","0.02618"
"66.34800","5.52916","0.02660"
"66.69000","5.55762","0.02648"
"67.03200","5.58608","0.02668"
"67.37400","5.61460","0.02753"
"67.71600","5.64312","0.02768"
"68.05800","5.67164","0.02829"
"68.40000","5.70015","0.02829"
"68.74200","5.72855","0.02924"
"69.08400","5.75713","0.02981"
"69.42600","5.78565","0.03008"
"69.76800","5.81405","0.03078"
"70.11000","5.84257","0.03088"
"70.45200","5.87109","0.03178"
"70.79400","5.89955","0.03220"
"71.13600","5.92813","0.03331"
"71.47800","5.95659","0.03360"
"71.82000","5.98505","0.03436"
"72.16200","6.01363","0.03474"
"72.50400","6.04209","0.03446"
"72.84600","6.07061","0.03627"
"73.18800","6.09913","0.03708"
"73.53000","6.12759","0.03681"
"73.87200","6.15617","0.03810"
"74.21400","6.18463","0.03854"
"74.55600","6.21309","0.03868"
"74.89800","6.24161","0.03933"
"75.24000","6.27001","0.04008"
"75.58200","6.29865","0.04009"
"75.92400","6.32711","0.04029"
"76.26600","6.35557","0.04144"
"76.60800","6.38415","0.04140"
"76.95000","6.41261","0.04247"
"77.29200","6.44113","0.04306"
"77.63400","6.46965","0.04377"
"77.97600","6.49811","0.04471"
"78.31800","6.52663","0.04528"
"78.66000","6.55514","0.04592"
"79.00200","6.58354","0.04687"
"79.34400","6.61212","0.04709"
"79.68600","6.64058","0.04799"
"80.02800","6.66904","0.04925"
"80.37000","6.69756","0.04972"
"80.71200","6.72614","0.04954"
"81.05400","6.75460","0.05003"
"81.39600","6.78312","0.05105"
"81.73800","6.81164","0.05172"
"82.08000","6.84010","0.05252"
"82.42200","6.86862","0.05284"
"82.76400","6.89708","0.05341"
"83.10600","6.92560","0.05412"
"83.44800","6.95412","0.05478"
"83.79000","6.98264","0.05491"
"84.13200","7.01116","0.05491"
"84.47400","7.03962","0.05604"
"84.81600","7.06808","0.05653"
"85.15800","7.09666","0.05711"
"85.50000","7.12512","0.05833"
"85.84200","7.15364","0.05930"
"86.18400","7.18216","0.06008"
"86.52600","7.21062","0.06106"
"86.86800","7.23908","0.06246"
"87.21000","7.26766","0.06358"
"87.55200","7.29606","0.06394"
"87.89400","7.32464","0.06398"
"88.23600","7.35316","0.06506"
"88.57800","7.38156","0.06626"
"88.92000","7.41014","0.06720"
"89.26200","7.43859","0.06807"
"89.60400","7.46712","0.06907"
"89.94600","7.49563","0.06982"
"90.28800","7.52403","0.07177"
"90.63000","7.55261","0.07269"
"90.97200","7.58119","0.07455"
"91.31400","7.60953","0.07552"
"91.65600","7.63817","0.07614"
"91.99800","7.66663","0.07746"
"92.34000","7.69509","0.07911"
"92.68200","7.72361","0.08006"
"93.02400","7.75207","0.08240"
"93.36600","7.78059","0.08387"
"93.70800","7.80917","0.08424"
"94.05000","7.83751","0.08457"
"94.39200","7.86609","0.08628"
"94.73400","7.89467","0.08805"
"95.07600","7.92307","0.08895"
"95.41800","7.95159","0.08970"
"95.76000","7.98005","0.09054"
"96.10200","8.00863","0.09077"
"96.44400","8.03715","0.09157"
"96.78600","8.06567","0.09247"
"97.12800","8.09413","0.09314"
"97.47000","8.12265","0.09384"
"97.81200","8.15105","0.09423"
"98.15400","8.17969","0.09485"
"98.49600","8.20815","0.09558"
"98.83800","8.23655","0.09598"
"99.18000","8.26513","0.09465"
"99.52200","8.29358","0.09467"
"99.86400","8.32210","0.09519"
"100.20600","8.35063","0.09543"
"100.54800","8.37908","0.09638"
"100.89000","8.40760","0.09685"
"101.23200","8.43612","0.09741"
"101.57400","8.46464","0.09795"
"101.91600","8.49310","0.09862"
"102.25800","8.52162","0.09913"
"102.60000","8.55008","0.09983"
"102.94200","8.57860","0.10022"
"103.28400","8.60712","0.10041"
"103.62600","8.63558","0.10065"
"103.96800","8.66410","0.10122"
"104.31000","8.69262","0.10132"
"104.65200","8.72108","0.10246"
"104.99400","8.74966","0.10304"
"105.33600","8.77806","0.10414"
"105.67800","8.80658","0.10515"
"106.02000","8.83516","0.10659"
"106.36200","8.86362","0.10741"
"106.70400","8.89214","0.10846"
"107.04600","8.92066","0.10980"
"107.38800","8.94906","0.11041"
"107.73000","8.97770","0.11129"
"108.07200","9.00610","0.11227"
"108.41400","9.03456","0.11358"
"108.75600","9.06314","0.11442"
"109.09800","9.09154","0.11663"
"109.44000","9.12018","0.11867"
"109.78200","9.14864","0.11982"
"110.12400","9.17710","0.12024"
"110.46600","9.20568","0.12322"
"110.80800","9.23407","0.12619"
"111.15000","9.26259","0.12813"
"111.49200","9.29111","0.12982"
"111.83400","9.31957","0.13296"
"112.17600","9.34815","0.13597"
"112.51800","9.37667","0.13636"
"112.86000","9.40507","0.13780"
"113.20200","9.43359","0.13936"
"113.54400","9.46211","0.14020"
"113.88600","9.49051","0.14216"
"114.22800","9.51915","0.14470"
"114.57000","9.54761","0.14689"
"114.91200","9.57607","0.14820"
"115.25400","9.60459","0.14913"
"115.59600","9.63305","0.15052"
"115.93800","9.66163","0.15156"
"116.28000","9.69015","0.15322"
"116.62200","9.71861","0.15536"
"116.96400","9.74713","0.15731"
"117.30600","9.77559","0.15994"
"117.64800","9.80405","0.16169"
"117.99000","9.83269","0.16288"
"118.33200","9.86109","0.16451"
"118.67400","9.88961","0.16617"
"119.01600","9.91807","0.16736"
"119.35800","9.94659","0.16832"
"119.70000","9.97511","0.16956"
"120.04200","10.00363","0.17073"
"120.38400","10.03215","0.17158"
"120.72600","10.06066","0.17284"
"121.06800","10.08913","0.17452"
"121.41000","10.11759","0.17493"
"121.75200","10.14610","0.17702"
"122.09400","10.17462","0.17786"
"122.43600","10.20308","0.17973"
"122.77800","10.23160","0.18083"
"123.12000","10.26012","0.18324"
"123.46200","10.28858","0.18367"
"123.80400","10.31716","0.18519"
"124.14600","10.34550","0.18652"
"124.48800","10.37414","0.18809"
"124.83000","10.40266","0.18900"
"125.17200","10.43112","0.19011"
"125.51400","10.45964","0.19165"
"125.85600","10.48804","0.19311"
"126.19800","10.51656","0.19373"
"126.54000","10.54514","0.19526"
"126.88200","10.57360","0.19672"
"127.22400","10.60212","0.19784"
"127.56600","10.63070","0.19905"
"127.90800","10.65904","0.20025"
"128.25000","10.68762","0.20084"
"128.59200","10.71614","0.20194"
"128.93400","10.74460","0.20291"
"129.27600","10.77312","0.20361"
"129.61800","10.80164","0.20426"
"129.96000","10.83010","0.20520"
"130.30200","10.85862","0.20624"
"130.64400","10.88708","0.20689"
"130.98600","10.91566","0.20772"
"131.32800","10.94412","0.20867"
"131.67000","10.97257","0.20914"
"132.01200","11.00115","0.20999"
"132.35400","11.02962","0.21090"
"132.69600","11.05807","0.21175"
"133.03800","11.08665","0.21279"
"133.38000","11.11511","0.21390"
"133.72200","11.14363","0.21515"
"134.06400","11.17209","0.21573"
"134.40600","11.20055","0.21800"
"134.74800","11.22913","0.21926"
"135.09000","11.25765","0.22025"
"135.43200","11.28611","0.22128"
"135.77400","11.31463","0.22301"
"136.11600","11.34309","0.22457"
"136.45800","11.37161","0.22520"
"136.80000","11.40013","0.22697"
"137.14200","11.42859","0.22784"
"137.48400","11.45711","0.22896"
"137.82600","11.48563","0.23080"
"138.16800","11.51409","0.23215"
"138.51000","11.54261","0.23339"
"138.85200","11.57113","0.23562"
"139.19400","11.59959","0.23604"
"139.53600","11.62811","0.23685"
"139.87800","11.65669","0.23985"
"140.22000","11.68509","0.24091"
"140.56200","11.71361","0.24430"
"140.90400","11.74207","0.24626"
"141.24600","11.77065","0.24557"
"141.58800","11.79917","0.24738"
"141.93000","11.82757","0.24895"
"142.27200","11.85609","0.25100"
"142.61400","11.88461","0.25313"
"142.95600","11.91306","0.25551"
"143.29800","11.94164","0.25673"
"143.64000","11.97010","0.25902"
"143.98200","11.99856","0.26096"
"144.32400","12.02714","0.26283"
"144.66600","12.05560","0.26568"
"145.00800","12.08406","0.26800"
"145.35000","12.11270","0.27063"
"145.69200","12.14104","0.27266"
"146.03400","12.16962","0.27665"
"146.37600","12.19814","0.28006"
"146.71800","12.22654","0.28390"
"147.06000","12.25512","0.28663"
"147.40200","12.28358","0.29021"
"147.74400","12.31210","0.29364"
"148.08600","12.34062","0.29506"
"148.42800","12.36908","0.29796"
"148.77000","12.39766","0.29992"
"149.11200","12.42618","0.30207"
"149.45400","12.45452","0.30432"
"149.79600","12.48310","0.30587"
"150.13800","12.51168","0.30765"
"150.48000","12.54008","0.30872"
"150.82200","12.56860","0.31030"
"151.16400","12.59712","0.31066"
"151.50600","12.62558","0.31164"
"151.84800","12.65410","0.31272"
"152.19000","12.68262","0.31306"
"152.53200","12.71114","0.31379"
"152.87400","12.73960","0.31427"
"153.21600","12.76812","0.31467"
"153.55800","12.79663","0.31521"
"153.90000","12.82515","0.31559"
"154.24200","12.85355","0.31608"
"154.58400","12.88213","0.31662"
"154.92600","12.91065","0.31697"
"155.26800","12.93911","0.31776"
"155.61000","12.96757","0.31843"
"155.95200","12.99615","0.31954"
"156.29400","13.02461","0.32048"
"156.63600","13.05307","0.32136"
"156.97800","13.08153","0.32323"
"157.32000","13.11011","0.32499"
"157.66200","13.13869","0.32739"
"158.00400","13.16703","0.32889"
"158.34600","13.19561","0.33200"
"158.68800","13.22413","0.33524"
"159.03000","13.25265","0.33825"
"159.37200","13.28111","0.34176"
"159.71400","13.30957","0.34490"
"160.05600","13.33809","0.34873"
"160.39800","13.36667","0.35107"
"160.74000","13.39507","0.35416"
"161.08200","13.42365","0.35690"
"161.42400","13.45211","0.35930"
"161.76600","13.48063","0.36220"
"162.10800","13.50915","0.36521"
"162.45000","13.53761","0.36767"
"162.79200","13.56612","0.36957"
"163.13400","13.59465","0.37239"
"163.47600","13.62311","0.37474"
"163.81800","13.65162","0.37723"
"164.16000","13.68015","0.37934"
"164.50200","13.70854","0.38126"
"164.84400","13.73712","0.38362"
"165.18600","13.76564","0.38603"
"165.52800","13.79410","0.38819"
"165.87000","13.82268","0.39112"
"166.21200","13.85108","0.39269"
"166.55400","13.87960","0.39460"
"166.89600","13.90812","0.39644"
"167.23800","13.93658","0.39767"
"167.58000","13.96522","0.40009"
"167.92200","13.99368","0.40177"
"168.26400","14.02208","0.40395"
"168.60600","14.05066","0.40329"
"168.94800","14.07906","0.40543"
"169.29000","14.10758","0.40650"
"169.63200","14.13610","0.40829"
"169.97400","14.16456","0.40977"
"170.31600","14.19314","0.41142"
"170.65800","14.22160","0.41271"
"171.00000","14.25006","0.41476"
"171.34200","14.27864","0.41762"
"171.68400","14.30710","0.42075"
"172.02600","14.33562","0.42404"
"172.36800","14.36414","0.42587"
"172.71000","14.39266","0.42738"
"173.05200","14.42112","0.42909"
"173.39400","14.44964","0.43163"
"173.73600","14.47815","0.43511"
"174.07800","14.50656","0.43681"
"174.42000","14.53513","0.43804"
"174.76200","14.56359","0.44054"
"175.10400","14.59211","0.44258"
"175.44600","14.62063","0.44649"
"175.78800","14.64903","0.44955"
"176.13000","14.67761","0.45163"
"176.47200","14.70613","0.43673"
"176.81400","14.73459","0.43925"
"177.15600","14.76311","0.44280"
"177.49800","14.79157","0.44619"
"177.84000","14.82009","0.44966"
"178.18200","14.84867","0.45270"
"178.52400","14.87707","0.45484"
"178.86600","14.90559","0.45694"
"179.20800","14.93417","0.45873"
"179.55000","14.96251","0.46130"
"179.89200","14.99115","0.46249"
"180.23400","15.01967","0.46430"
"180.57600","15.04813","0.46613"
"180.91800","15.07671","0.46904"
"181.26000","15.10505","0.47255"
"181.60200","15.13357","0.47585"
"181.94400","15.16215","0.47915"
"182.28600","15.19055","0.24060"
"182.62800","15.21913","0.23319"
"182.97000","15.24765","0.23350"
"183.31200","15.27605","0.23189"
"183.65400","15.30463","0.23195"
"183.99600","15.33309","0.23390"
"184.33800","15.36161","0.23228"
"184.68000","15.39018","0.23302"
"185.02200","15.41852","0.23678"
"185.36400","15.44710","0.23369"
"185.70600","15.47562","0.23857"
"186.04800","15.50402","0.23928"
"186.39000","15.53266","0.24007"
"186.73200","15.56112","0.24407"
"187.07400","15.58958","0.24327"
"187.41600","15.61816","0.24509"
"187.75800","15.64662","0.24776"
"188.10000","15.67508","0.24720"
"188.44200","15.70360","0.24914"
"188.78400","15.73212","0.24982"
"189.12600","15.76064","0.25135"
"189.46800","15.78910","0.25424"
"189.81000","15.81756","0.25417"
"190.15200","15.84608","0.25649"
"190.49400","15.87460","0.25843"
"190.83600","15.90312","0.25973"
"191.17800","15.93164","0.26298"
"191.52000","15.96010","0.26404"
"191.86200","15.98862","0.26846"
"192.20400","16.01708","0.27147"
"192.54600","16.04560","0.27526"
"192.88800","16.07412","0.27968"
"193.23000","16.10264","0.28266"
"193.57200","16.13104","0.28674"
"193.91400","16.15962","0.28836"
"194.25600","16.18814","0.29248"
"194.59800","16.21654","0.29353"
"194.94000","16.24517","0.29465"
"195.28200","16.27357","0.29698"
"195.62400","16.30209","0.29850"
"195.96600","16.33068","0.30113"
"196.30800","16.35913","0.30481"
"196.65000","16.38759","0.30777"
"196.99200","16.41617","0.30943"
"197.33400","16.44457","0.31155"
"197.67600","16.47309","0.31322"
"198.01800","16.50161","0.31442"
"198.36000","16.53007","0.31505"
"198.70200","16.55859","0.31542"
"199.04400","16.58711","0.31584"
"199.38600","16.61557","0.31616"
"199.72800","16.64415","0.31657"
"200.07000","16.67255","0.31769"
"200.41200","16.70113","0.31917"
"200.75400","16.72965","0.32023"
"201.09600","16.75805","0.32250"
"201.43800","16.78663","0.32455"
"201.78000","16.81515","0.32661"
"202.12200","16.84361","0.32815"
"202.46400","16.87213","0.32977"
"202.80600","16.90059","0.33248"
"203.14800","16.92905","0.33685"
"203.49000","16.95763","0.34116"
"203.83200","16.98609","0.34566"
"204.17400","17.01467","0.34793"
"204.51600","17.04313","0.31334"
"204.85800","17.07159","0.31129"
"205.20000","17.10011","0.31400"
"205.54200","17.12862","0.31377"
"205.88400","17.15714","0.31430"
"206.22600","17.18560","0.31602"
"206.56800","17.21412","0.31612"
"206.91000","17.24258","0.31897"
"207.25200","17.27110","0.31928"
"207.59400","17.29956","0.32202"
"207.93600","17.32808","0.32104"
"208.27800","17.35660","0.32242"
"208.62000","17.38512","0.32364"
"208.96200","17.41364","0.32516"
"209.30400","17.44216","0.32935"
"209.64600","17.47062","0.33331"
"209.98800","17.49914","0.34105"
"210.33000","17.52760","0.34102"
"210.67200","17.55612","0.34419"
"211.01400","17.58464","0.34240"
"211.35600","17.61310","0.34571"
"211.69800","17.64162","0.34777"
"212.04000","17.67014","0.35338"
"212.38200","17.69854","0.35707"
"212.72400","17.72712","0.36162"
"213.06600","17.75564","0.36180"
"213.40800","17.78410","0.36277"
"213.75000","17.81256","0.36507"
"214.09200","17.84108","0.36724"
"214.43400","17.86966","0.37073"
"214.77600","17.89818","0.37281"
"215.11800","17.92657","0.37356"
"215.46000","17.95510","0.37100"
"215.80200","17.98368","0.02369"
"216.14400","18.01208","0.02789"
"216.48600","18.04066","0.01804"
"216.82800","18.06911","0.01858"
"217.17000","18.09757","0.03154"
"217.51200","18.12615","0.02565"
"217.85400","18.15455","0.02343"
"218.19600","18.18307","0.03417"
"218.53800","18.21159","0.03798"
"218.88000","18.24005","0.02953"
"219.22200","18.26863","0.03318"
"219.56400","18.29715","0.04486"
"219.90600","18.32561","0.03997"
"220.24800","18.35413","0.03610"
"220.59000","18.38259","0.04198"
"220.93200","18.41111","0.04748"
"221.27400","18.43963","0.04347"
"221.61600","18.46803","0.04232"
"221.95800","18.49667","0.04923"
"222.30000","18.52513","0.05298"
"222.64200","18.55353","0.04911"
"222.98400","18.58217","0.04864"
"223.32600","18.61063","0.05468"
"223.66800","18.63909","0.05752"
"224.01000","18.66761","0.05457"
"224.35200","18.69607","0.05311"
"224.69400","18.72459","0.05762"
"225.03600","18.75311","0.06212"
"225.37800","18.78163","0.05977"
"225.72000","18.81009","0.05802"
"226.06200","18.83867","0.06092"
"226.40400","18.86707","0.06570"
"226.74600","18.89565","0.06534"
"227.08800","18.92416","0.06162"
"227.43000","18.95257","0.06295"
"227.77200","18.98114","0.06832"
"228.11400","19.00960","0.07138"
"228.45600","19.03806","0.06958"
"228.79800","19.06658","0.06858"
"229.14000","19.09510","0.07110"
"229.48200","19.12362","0.07739"
"229.82400","19.15214","0.08004"
"230.16600","19.18060","0.07704"
"230.50800","19.20918","0.07792"
"230.85000","19.23764","0.08190"
"231.19200","19.26604","0.08626"
"231.53400","19.29462","0.08718"
"231.87600","19.32308","0.08666"
"232.21800","19.35160","0.08719"
"232.56000","19.38012","0.08940"
"232.90200","19.40858","0.09174"
"233.24400","19.43704","0.09357"
"233.58600","19.46562","0.09280"
"233.92800","19.49408","0.09290"
"234.27000","19.52266","0.09414"
"234.61200","19.55118","0.09579"
"234.95400","19.57958","0.09677"
"235.29600","19.60816","0.09720"
"235.63800","19.63662","0.09677"
"235.98000","19.66508","0.09669"
"236.32200","19.69371","0.09788"
"236.66400","19.72206","0.09961"
"237.00600","19.75064","0.10036"
"237.34800","19.77915","0.10093"
"237.69000","19.80755","0.10067"
"238.03200","19.83619","0.10145"
"238.37400","19.86465","0.10280"
"238.71600","19.89305","0.10380"
"239.05800","19.92163","0.10618"
"239.40000","19.95009","0.10676"
"239.74200","19.97861","0.10740"
"240.08400","20.00713","0.10339"
"240.42600","20.03553","0.10441"
"240.76800","20.06411","0.10725"
"241.11000","20.09263","0.10962"
"241.45200","20.12103","0.10995"
"241.79400","20.14961","0.11083"
"242.13600","20.17813","0.11182"
"242.47800","20.20659","0.11487"
"242.82000","20.23511","0.11660"
"243.16200","20.26363","0.12016"
"243.50400","20.29209","0.12370"
"243.84600","20.32061","0.12750"
"244.18800","20.34907","0.12918"
"244.53000","20.37765","0.13163"
"244.87200","20.40617","0.13593"
"245.21400","20.43457","0.13836"
"245.55600","20.46309","0.14153"
"245.89800","20.49155","0.14519"
"246.24000","20.52007","0.14830"
"246.58200","20.54865","0.15111"
"246.92400","20.57711","0.15362"
"247.26600","20.60563","0.15560"
"247.60800","20.63414","0.15712"
"247.95000","20.66260","0.15991"
"248.29200","20.69112","0.16138"
"248.63400","20.71964","0.16418"
"248.97600","20.74810","0.16572"
"249.31800","20.77662","0.16795"
"249.66000","20.80514","0.17059"
"250.00200","20.83360","0.17331"
"250.34400","20.86212","0.17477"
"250.68600","20.89058","0.17838"
"251.02800","20.91904","0.18140"
"251.37000","20.94768","0.18370"
"251.71200","20.97608","0.18563"
"252.05400","21.00460","0.18805"
"252.39600","21.03318","0.19003"
"252.73800","21.06158","0.19246"
"253.08000","21.09016","0.19467"
"253.42200","21.11862","0.19697"
"253.76400","21.14702","0.19976"
"254.10600","21.17566","0.19938"
"254.44800","21.20406","0.20175"
"254.79000","21.23258","0.20267"
"255.13200","21.26116","0.20488"
"255.47400","21.28956","0.20618"
"255.81600","21.31814","0.20787"
"256.15800","21.34666","0.20968"
"256.50000","21.37506","0.21145"
"256.84200","21.40369","0.21318"
"257.18400","21.43210","0.21610"
"257.52600","21.46062","0.21814"
"257.86800","21.48913","0.22173"
"258.21000","21.51760","0.22411"
"258.55200","21.54611","0.22621"
"258.89400","21.57463","0.22882"
"259.23600","21.60303","0.23199"
"259.57800","21.63161","0.23498"
"259.92000","21.66013","0.23895"
"260.26200","21.68859","0.24194"
"260.60400","21.71711","0.24573"
"260.94600","21.74563","0.24812"
"261.28800","21.77409","0.25193"
"261.63000","21.80261","0.25522"
"261.97200","21.83107","0.25718"
"262.31400","21.85959","0.26045"
"262.65600","21.88817","0.26439"
"262.99800","21.91663","0.26936"
"263.34000","21.94515","0.27413"
"263.68200","21.97355","0.27939"
"264.02400","22.00207","0.28445"
"264.36600","22.03059","0.28924"
"264.70800","22.05911","0.29106"
"265.05000","22.08763","0.29587"
"265.39200","22.11609","0.30042"
"265.73400","22.14467","0.30426"
"266.07600","22.17313","0.30752"
"266.41800","22.20159","0.31060"
"266.76000","22.23011","0.31256"
"267.10200","22.25863","0.31349"
"267.44400","22.28715","0.31479"
"267.78600","22.31561","0.31506"
"268.12800","22.34413","0.30764"
"268.47000","22.37259","0.31241"
"268.81200","22.40105","0.31453"
"269.15400","22.42962","0.31617"
"269.49600","22.45808","0.31848"
"269.83800","22.48660","0.32156"
"270.18000","22.51518","0.32424"
"270.52200","22.54358","0.32773"
"270.86400","22.57210","0.21345"
"271.20600","22.60062","0.20923"
"271.54800","22.62908","0.21967"
"271.89000","22.65760","0.22605"
"272.23200","22.68606","0.22364"
"272.57400","22.71458","0.23108"
"272.91600","22.74316","0.24451"
"273.25800","22.77156","0.24975"
"273.60000","22.80014","0.25345"
"273.94200","22.82860","0.26337"
"274.28400","22.85700","0.27770"
"274.62600","22.88570","0.28513"
"274.96800","22.91416","0.29856"
"275.31000","22.94262","0.30589"
"275.65200","22.97114","0.30571"
"275.99400","22.99960","0.30836"
"276.33600","23.02812","0.30761"
"276.67800","23.05658","0.30700"
"277.02000","23.08504","0.31089"
"277.36200","23.11368","0.31116"
"277.70400","23.14214","0.31404"
"278.04600","23.17054","0.31630"
"278.38800","23.19912","0.32007"
"278.73000","23.22758","0.32920"
"279.07200","23.25610","0.33499"
"279.41400","23.28461","0.34097"
"279.75600","23.31307","0.34113"
"280.09800","23.34166","0.34145"
"280.44000","23.37012","0.30828"
"280.78200","23.39857","0.31005"
"281.12400","23.42710","0.31353"
"281.46600","23.45561","0.31548"
"281.80800","23.48407","0.31753"
"282.15000","23.51265","0.32222"
"282.49200","23.54111","0.32475"
"282.83400","23.56957","0.32893"
"283.17600","23.59815","0.32749"
"283.51800","23.62661","0.32290"
"283.86000","23.65513","0.32528"
"284.20200","23.68365","0.32882"
"284.54400","23.71211","0.33920"
"284.88600","23.74057","0.34785"
"285.22800","23.76915","0.35574"
"285.57000","23.79761","0.35994"
"285.91200","23.82613","0.36254"
"286.25400","23.85465","0.36483"
"286.59600","23.88311","0.36837"
"286.93800","23.91163","0.37294"
"287.28000","23.94009","0.37749"
"287.62200","23.96861","0.37853"
"287.96400","23.99719","0.37764"
"288.30600","24.02559","0.36246"
"288.64800","24.05411","0.24072"
"288.99000","24.08269","0.21302"
"289.33200","24.11103","0.20884"
"289.67400","24.13967","0.21064"
"290.01600","24.16806","0.21687"
"290.35800","24.19658","0.22541"
"290.70000","24.22516","0.23261"
"291.04200","24.25362","0.23768"
"291.38400","24.28214","0.24979"
"291.72600","24.31066","0.25888"
"292.06800","24.33906","0.25835"
"292.41000","24.36758","0.26939"
"292.75200","24.39610","0.27444"
"293.09400","24.42456","0.21237"
"293.43600","24.45314","0.21784"
"293.77800","24.48160","0.17724"
"294.12000","24.51012","0.17962"
"294.46200","24.53864","0.18235"
"294.80400","24.56710","0.19059"
"295.14600","24.59568","0.19811"
"295.48800","24.62408","0.20197"
"295.83000","24.65254","0.20486"
"296.17200","24.68118","0.20770"
"296.51400","24.70964","0.16003"
"296.85600","24.73810","0.16300"
"297.19800","24.76662","0.16936"
"297.54000","24.79508","0.17598"
"297.88200","24.82360","0.17847"
"298.22400","24.85212","0.18242"
"298.56600","24.88058","0.18841"
"298.90800","24.90910","0.19423"
"299.25000","24.93761","0.19801"
"299.59200","24.96608","0.20069"
"299.93400","24.99466","0.19731"
"300.27600","25.02311","0.20137"
"300.61800","25.05157","0.20329"
"300.96000","25.08010","0.13481"
"301.30200","25.10867","0.14260"
"301.64400","25.13713","0.14936"
"301.98600","25.16566","0.15224"
"302.32800","25.19411","0.14817"
"302.67000","25.22257","0.10489"
"303.01200","25.25115","0.07506"
"303.35400","25.27955","0.08262"
"303.69600","25.30819","0.06764"
"304.03800","25.33665","0.06757"
"304.38000","25.36505","0.08189"
"304.72200","25.39363","0.07298"
"305.06400","25.42215","0.07670"
"305.40600","25.45055","0.08822"
"305.74800","25.47919","0.08613"
"306.09000","25.50759","0.08624"
"306.43200","25.53605","0.08941"
"306.77400","25.56463","0.09317"
"307.11600","25.59303","0.09145"
"307.45800","25.62161","0.03910"
"307.80000","25.65013","0.03662"
"308.14200","25.67859","0.02953"
"308.48400","25.70717","0.03734"
"308.82600","25.73563","0.04426"
"309.16800","25.76415","0.03473"
"309.51000","25.79267","0.04398"
"309.85200","25.82107","0.03699"
"310.19400","25.84958","0.04440"
"310.53600","25.87817","0.04653"
"310.87800","25.90656","0.04875"
"311.22000","25.93508","0.05609"
"311.56200","25.96361","0.03864"
"311.90400","25.99207","0.04612"
"312.24600","26.02064","0.04728"
"312.58800","26.04910","0.04489"
"312.93000","26.07763","0.04833"
"313.27200","26.10608","0.04761"
"313.61400","26.13454","0.05158"
"313.95600","26.16312","0.05371"
"314.29800","26.19164","0.05226"
"314.64000","26.22010","0.05437"
"314.98200","26.24862","0.05392"
"315.32400","26.27714","0.05540"
"315.66600","26.30560","0.06080"
"316.00800","26.33418","0.05879"
"316.35000","26.36258","0.05953"
"316.69200","26.39110","0.06315"
"317.03400","26.41962","0.06242"
"317.37600","26.44814","0.06403"
"317.71800","26.47666","0.06703"
"318.06000","26.50512","0.06743"
"318.40200","26.53358","0.06819"
"318.74400","26.56216","0.07117"
"319.08600","26.59068","0.07355"
"319.42800","26.61908","0.07405"
"319.77000","26.64760","0.07714"
"320.11200","26.67612","0.07909"
"320.45400","26.70458","0.07974"
"320.79600","26.73310","0.08198"
"321.13800","26.76162","0.08367"
"321.48000","26.79008","0.08450"
"321.82200","26.81865","0.08564"
"322.16400","26.84706","0.08705"
"322.50600","26.87563","0.08816"
"322.84800","26.90415","0.08942"
"323.19000","26.93262","0.09123"
"323.53200","26.96113","0.09219"
"323.87400","26.98953","0.09279"
"324.21600","27.01811","0.09421"
"324.55800","27.04663","0.09502"
"324.90000","27.07509","0.09570"
"325.24200","27.10361","0.09622"
"325.58400","27.13213","0.09710"
"325.92600","27.16053","0.09779"
"326.26800","27.18911","0.09846"
"326.61000","27.21763","0.09886"
"326.95200","27.24615","0.09971"
"327.29400","27.27467","0.10037"
"327.63600","27.30307","0.09843"
"327.97800","27.33159","0.09941"
"328.32000","27.36011","0.10024"
"328.66200","27.38857","0.10090"
"329.00400","27.41715","0.10170"
"329.34600","27.44567","0.00110"
"329.68800","27.47407","0.00494"
"330.03000","27.50265","-0.00264"
"330.37200","27.53111","0.00953"
"330.71400","27.55963","-0.00287"
"331.05600","27.58809","0.01441"
"331.39800","27.61661","-0.00290"
"331.74000","27.64513","0.00961"
"332.08200","27.67365","-0.00081"
"332.42400","27.70205","0.00780"
"332.76600","27.73062","-0.00049"
"333.10800","27.75908","0.00722"
"333.45000","27.78760","-0.00027"
"333.79200","27.81618","0.00628"
"334.13400","27.84459","0.00493"
"334.47600","27.87310","0.00561"
"334.81800","27.90162","0.00432"
"335.16000","27.93008","0.00515"
"335.50200","27.95860","0.00691"
"335.84400","27.98706","0.00382"
"336.18600","28.01558","0.00650"
"336.52800","28.04410","0.00581"
"336.87000","28.07262","0.00626"
"337.21200","28.10114","0.00591"
"337.55400","28.12966","0.00590"
"337.89600","28.15812","0.00771"
"338.23800","28.18658","0.00681"
"338.58000","28.21510","0.00599"
"338.92200","28.24362","0.00698"
"339.26400","28.27208","0.00672"
"339.60600","28.30066","0.00726"
"339.94800","28.32906","0.00671"
"340.29000","28.35764","0.00724"
"340.63200","28.38616","0.00819"
"340.97400","28.41456","0.00769"
"341.31600","28.44314","0.00786"
"341.65800","28.47166","0.00812"
"342.00000","28.50006","0.00895"
"342.34200","28.52864","0.00882"
"342.68400","28.55710","0.00879"
"343.02600","28.58556","0.00883"
"343.36800","28.61413","0.00895"
"343.71000","28.64260","0.00961"
"344.05200","28.67112","0.00990"
"344.39400","28.69969","0.00991"
"344.73600","28.72810","0.01013"
"345.07800","28.75667","0.01043"
"345.42000","28.78507","0.01074"
"345.76200","28.81359","0.01123"
"346.10400","28.84217","0.01130"
"346.44600","28.87057","0.01150"
"346.78800","28.89915","0.01183"
"347.13000","28.92761","0.01192"
"347.47200","28.95607","0.01265"
"347.81400","28.98459","0.01267"
"348.15600","29.01311","0.01330"
"348.49800","29.04157","0.01366"
"348.84000","29.07015","0.01363"
"349.18200","29.09855","0.01432"
"349.52400","29.12707","0.01419"
"349.86600","29.15559","0.01521"
"350.20800","29.18405","0.01547"
"350.55000","29.21269","0.01601"
"350.89200","29.24109","0.01590"
"351.23400","29.26955","0.01650"
"351.57600","29.29813","0.01651"
"351.91800","29.32659","0.01716"
"352.26000","29.35511","0.01733"
"352.60200","29.38363","0.01750"
"352.94400","29.41209","0.01809"
"353.28600","29.44061","0.01858"
"353.62800","29.46913","0.01910"
"353.97000","29.49758","0.01939"
"354.31200","29.52604","0.02007"
"354.65400","29.55463","0.02054"
"354.99600","29.58309","0.02116"
"355.33800","29.61166","0.02149"
"355.68000","29.64018","0.02191"
"356.02200","29.66858","0.02207"
"356.36400","29.69710","0.02322"
"356.70600","29.72562","0.02324"
"357.04800","29.75408","0.02393"
"357.39000","29.78260","0.02406"
"357.73200","29.81112","0.02456"
"358.07400","29.83958","0.02533"
"358.41600","29.86816","0.02548"
"358.75800","29.89662","0.02581"
"359.10000","29.92514","0.02681"
"359.44200","29.95360","0.02697"
"359.78400","29.98206","0.02797"
"360.12600","30.01064","0.02805"
"360.46800","30.03910","0.02874"
"360.81000","30.06762","0.02988"
"361.15200","30.09614","0.03074"
"361.49400","30.12454","0.03161"
"361.83600","30.15312","0.03172"
"362.17800","30.18170","0.03313"
"362.52000","30.21010","0.03265"
"362.86200","30.23862","0.03455"
"363.20400","30.26708","0.03521"
"363.54600","30.29560","0.03626"
"363.88800","30.32411","0.03726"
"364.23000","30.35264","0.03839"
"364.57200","30.38109","0.03916"
"364.91400","30.40968","0.03933"
"365.25600","30.43808","0.04071"
"365.59800","30.46665","0.04055"
"365.94000","30.49512","0.04135"
"366.28200","30.52358","0.04202"
"366.62400","30.55215","0.04267"
"366.96600","30.58055","0.04280"
"367.30800","30.60907","0.04349"
"367.65000","30.63765","0.04403"
"367.99200","30.66611","0.04443"
"368.33400","30.69457","0.04488"
"368.67600","30.72309","0.04563"
"369.01800","30.75149","0.04598"
"369.36000","30.78013","0.04637"
"369.70200","30.80865","0.04701"
"370.04400","30.83717","0.04781"
"370.38600","30.86563","0.04828"
"370.72800","30.89409","0.04879"
"371.07000","30.92261","0.04907"
"371.41200","30.95107","0.04990"
"371.75400","30.97959","0.05044"
"372.09600","31.00811","0.05136"
"372.43800","31.03663","0.05154"
"372.78000","31.06509","0.05197"
"373.12200","31.09361","0.05242"
"373.46400","31.12213","0.05333"
"373.80600","31.15059","0.05386"
"374.14800","31.17911","0.05410"
"374.49000","31.20762","0.05429"
"374.83200","31.23608","0.05462"
"375.17400","31.26460","0.05571"
"375.51600","31.29312","0.05582"
"375.85800","31.32164","0.05635"
"376.20000","31.35016","0.05636"
"376.54200","31.37856","0.05715"
"376.88400","31.40708","0.05746"
"377.22600","31.43566","0.05793"
"377.56800","31.46406","0.05874"
"377.91000","31.49264","0.05978"
"378.25200","31.52110","0.05974"
"378.59400","31.54956","0.06066"
"378.93600","31.57814","0.06155"
"379.27800","31.60660","0.06145"
"379.62000","31.63506","0.06204"
"379.96200","31.66364","0.06292"
"380.30400","31.69210","0.06282"
"380.64600","31.72062","0.06319"
"380.98800","31.74914","0.06363"
"381.33000","31.77754","0.06471"
"381.67200","31.80612","0.06561"
"382.01400","31.83464","0.06645"
"382.35600","31.86310","0.06693"
"382.69800","31.89168","0.06749"
"383.04000","31.92007","0.06783"
"383.38200","31.94866","0.06932"
"383.72400","31.97712","0.06925"
"384.06600","32.00557","0.06961"
"384.40800","32.03416","0.06988"
"384.75000","32.06261","0.07063"
"385.09200","32.09107","0.07170"
"385.43400","32.11966","0.07227"
"385.77600","32.14806","0.07295"
"386.11800","32.17657","0.07339"
"386.46000","32.20509","0.07419"
"386.80200","32.23355","0.07461"
"387.14400","32.26213","0.07625"
"387.48600","32.29065","0.07758"
"387.82800","32.31911","0.07699"
"388.17000","32.34763","0.07861"
"388.51200","32.37609","0.07886"
"388.85400","32.40455","0.07996"
"389.19600","32.43313","0.08004"
"389.53800","32.46159","0.08140"
"389.88000","32.49011","0.08194"
"390.22200","32.51857","0.08303"
"390.56400","32.54715","0.08335"
"390.90600","32.57561","0.08435"
"391.24800","32.60413","0.08424"
"391.59000","32.63259","0.08565"
"391.93200","32.66111","0.08589"
"392.27400","32.68963","0.08663"
"392.61600","32.71803","0.08700"
"392.95800","32.74667","0.08774"
"393.30000","32.77518","0.08806"
"393.64200","32.80359","0.08819"
"393.98400","32.83210","0.08879"
"394.32600","32.86057","0.08949"
"394.66800","32.88909","0.09021"
"395.01000","32.91766","0.09051"
"395.35200","32.94613","0.09066"
"395.69400","32.97459","0.09169"
"396.03600","33.00310","0.09163"
"396.37800","33.03156","0.09248"
"396.72000","33.06015","0.09266"
"397.06200","33.08860","0.09309"
"397.40400","33.11706","0.09330"
"397.74600","33.14565","0.09326"
"398.08800","33.17410","0.09403"
"398.43000","33.20262","0.09329"
"398.77200","33.23114","0.00800"
"399.11400","33.25954","-0.00171"
"399.45600","33.28818","0.00463"
"399.79800","33.31664","-0.00128"
"400.14000","33.34504","0.00207"
"400.48200","33.37362","0.00297"
"400.82400","33.40214","0.00038"
"401.16600","33.43060","0.00336"
"401.50800","33.45912","0.00143"
"401.85000","33.48752","0.00171"
"402.19200","33.51616","0.00361"
"402.53400","33.54462","0.00126"
"402.87600","33.57307","0.00279"
"403.21800","33.60166","0.00305"
"403.56000","33.63012","0.00252"
"403.90200","33.65864","0.00273"
"404.24400","33.68716","0.00099"
"404.58600","33.71562","0.00305"
"404.92800","33.74413","0.00164"
"405.27000","33.77259","0.00226"
"405.61200","33.80106","0.00279"
"405.95400","33.82963","0.00208"
"406.29600","33.85809","0.00389"
"406.63800","33.88662","0.00180"
"406.98000","33.91513","0.00197"
"407.32200","33.94359","0.00144"
"407.66400","33.97211","0.00260"
"408.00600","34.00063","0.00687"
"408.34800","34.02909","0.00116"
"408.69000","34.05761","-0.00227"
"409.03200","34.08613","0.00197"
"409.37400","34.11459","-0.00122"
"409.71600","34.14311","0.00639"
"410.05800","34.17157","-0.00139"
"410.40000","34.20003","0.00414"
"410.74200","34.22861","0.00275"
"411.08400","34.25713","0.00144"
"411.42600","34.28559","0.00461"
"411.76800","34.31411","0.00168"
"412.11000","34.34257","0.00367"
"412.45200","34.37109","0.00253"
"412.79400","34.39967","0.00401"
"413.13600","34.42807","0.00350"
"413.47800","34.45659","0.00258"
"413.82000","34.48517","0.00461"
"414.16200","34.51357","0.00264"
"414.50400","34.54215","0.00322"
"414.84600","34.57061","0.00469"
"415.18800","34.59907","0.00307"
"415.53000","34.62765","0.00398"
"415.87200","34.65611","0.00429"
"416.21400","34.68462","0.00437"
"416.55600","34.71315","0.00380"
"416.89800","34.74148","0.00429"
"417.24000","34.77012","0.00447"
"417.58200","34.79865","0.00471"
"417.92400","34.82704","0.00438"
"418.26600","34.85562","0.00461"
"418.60800","34.88414","0.00507"
"418.95000","34.91260","0.00492"
"419.29200","34.94112","0.00536"
"419.63400","34.96958","0.00499"
"419.97600","34.99810","0.00487"
"420.31800","35.02656","0.00544"
"420.66000","35.05502","0.00537"
"421.00200","35.08366","0.00559"
"421.34400","35.11212","0.00571"
"421.68600","35.14058","0.00560"
"422.02800","35.16916","0.00610"
"422.37000","35.19762","0.00583"
"422.71200","35.22608","0.00643"
"423.05400","35.25460","0.00596"
"423.39600","35.28312","0.00627"
"423.73800","35.31164","0.00657"
"424.08000","35.34016","0.00663"
"424.42200","35.36862","0.00675"
"424.76400","35.39708","0.00746"
"425.10600","35.42559","0.00725"
"425.44800","35.45406","0.00732"
"425.79000","35.48264","0.00767"
"426.13200","35.51115","0.00794"
"426.47400","35.53962","0.00769"
"426.81600","35.56814","0.00745"
"427.15800","35.59660","0.00776"
"427.50000","35.62511","0.00840"
"427.84200","35.65364","0.00848"
"428.18400","35.68209","0.00837"
"428.52600","35.71061","0.00856"
"428.86800","35.73914","0.00869"
"429.21000","35.76759","0.00853"
"429.55200","35.79611","0.00914"
"429.89400","35.82463","0.00918"
"430.23600","35.85309","0.00934"
"430.57800","35.88161","0.00967"
"430.92000","35.91013","0.00982"
"431.26200","35.93853","0.01016"
"431.60400","35.96717","0.01030"
"431.94600","35.99557","0.01033"
"432.28800","36.02409","0.01028"
"432.63000","36.05261","0.01101"
"432.97200","36.08107","0.01107"
"433.31400","36.10965","0.01124"
"433.65600","36.13811","0.01156"
"433.99800","36.16657","0.01162"
"434.34000","36.19515","0.01160"
"434.68200","36.22355","0.01231"
"435.02400","36.25207","0.01237"
"435.36600","36.28065","0.01262"
"435.70800","36.30905","0.01282"
"436.05000","36.33762","0.01317"
"436.39200","36.36621","0.01316"
"436.73400","36.39461","0.01379"
"437.07600","36.42318","0.01443"
"437.41800","36.45158","0.01469"
"437.76000","36.48011","0.01505"
"438.10200","36.50863","0.01564"
"438.44400","36.53703","0.01584"
"438.78600","36.56561","0.01593"
"439.12800","36.59412","0.01662"
"439.47000","36.62259","0.01660"
"439.81200","36.65105","0.01749"
"440.15400","36.67962","0.01820"
"440.49600","36.70808","0.01828"
"440.83800","36.73666","0.01933"
"441.18000","36.76512","0.01989"
"441.52200","36.79364","0.02053"
"441.86400","36.82210","0.02104"
"442.20600","36.85056","0.02138"
"442.54800","36.87914","0.02223"
"442.89000","36.90766","0.02336"
"443.23200","36.93606","0.02379"
"443.57400","36.96458","0.02406"
"443.91600","36.99310","0.02505"
"444.25800","37.02162","0.02538"
"444.60000","37.05014","0.02665"
"444.94200","37.07860","0.02662"
"445.28400","37.10706","0.02763"
"445.62600","37.13558","0.02871"
"445.96800","37.16410","0.02869"
"446.31000","37.19262","0.03020"
"446.65200","37.22120","0.03125"
"446.99400","37.24960","0.03182"
"447.33600","37.27811","0.03293"
"447.67800","37.30664","0.03361"
"448.02000","37.33509","0.03512"
"448.36200","37.36361","0.03560"
"448.70400","37.39207","0.03674"
"449.04600","37.42053","0.03698"
"449.38800","37.44917","0.03941"
"449.73000","37.47757","0.03926"
"450.07200","37.50609","0.04020"
"450.41400","37.53467","0.04185"
"450.75600","37.56308","0.04206"
"451.09800","37.59165","0.04316"
"451.44000","37.62011","0.04404"
"451.78200","37.64857","0.04416"
"452.12400","37.67715","0.04528"
"452.46600","37.70561","0.04561"
"452.80800","37.73413","0.04674"
"453.15000","37.76265","0.04735"
"453.49200","37.79105","0.04816"
"453.83400","37.81963","0.04874"
"454.17600","37.84809","0.03151"
"454.51800","37.87655","0.02901"
"454.86000","37.90519","0.02986"
"455.20200","37.93359","0.03054"
"455.54400","37.96211","0.03123"
"455.88600","37.99063","0.03165"
"456.22800","38.01909","0.03173"
"456.57000","38.04767","0.03457"
"456.91200","38.07619","0.03442"
"457.25400","38.10459","0.03489"
"457.59600","38.13311","0.03588"
"457.93800","38.16163","0.03677"
"458.28000","38.19003","0.03846"
"458.62200","38.21861","0.03835"
"458.96400","38.24713","0.03881"
"459.30600","38.27559","0.03983"
"459.64800","38.30410","0.04031"
"459.99000","38.33256","0.04179"
"460.33200","38.36115","0.04214"
"460.67400","38.38960","0.04280"
"461.01600","38.41806","0.04337"
"461.35800","38.44658","0.04407"
"461.70000","38.47511","0.04482"
"462.04200","38.50362","0.04534"
"462.38400","38.53214","0.04560"
"462.72600","38.56060","0.04625"
"463.06800","38.58906","0.04741"
"463.41000","38.61758","0.04810"
"463.75200","38.64610","0.04887"
"464.09400","38.67462","0.04937"
"464.43600","38.70314","0.04980"
"464.77800","38.73160","0.05048"
"465.12000","38.76012","0.05079"
"465.46200","38.78864","0.05175"
"465.80400","38.81710","0.05220"
"466.14600","38.84562","0.05284"
"466.48800","38.87414","0.05334"
"466.83000","38.90260","0.05435"
"467.17200","38.93118","0.05445"
"467.51400","38.95964","0.05547"
"467.85600","38.98804","0.05618"
"468.19800","39.01667","0.05694"
"468.54000","39.04502","0.05709"
"468.88200","39.07366","0.05731"
"469.22400","39.10212","0.05844"
"469.56600","39.13058","0.05919"
"469.90800","39.15916","0.05976"
"470.25000","39.18755","0.06027"
"470.59200","39.21608","0.06128"
"470.93400","39.24465","0.06307"
"471.27600","39.27305","0.06369"
"471.61800","39.30163","0.06448"
"471.96000","39.33015","0.06623"
"472.30200","39.35855","0.06682"
"472.64400","39.38713","0.06815"
"472.98600","39.41559","0.06841"
"473.32800","39.44405","0.06893"
"473.67000","39.47269","0.07022"
"474.01200","39.50109","0.07134"
"474.35400","39.52961","0.07183"
"474.69600","39.55813","0.07242"
"475.03800","39.58659","0.07346"
"475.38000","39.61517","0.07430"
"475.72200","39.64363","0.07582"
"476.06400","39.67203","0.07635"
"476.40600","39.70061","0.07590"
"476.74800","39.72913","0.07747"
"477.09000","39.75759","0.07862"
"477.43200","39.78610","0.07954"
"477.77400","39.81456","0.08056"
"478.11600","39.84308","0.08214"
"478.45800","39.87160","0.08295"
"478.80000","39.90013","0.08356"
"479.14200","39.92865","0.08444"
"479.48400","39.95711","0.08553"
"479.82600","39.98557","0.08633"
"480.16800","40.01414","0.08792"
"480.51000","40.04261","0.08795"
"480.85200","40.07107","0.08961"
"481.19400","40.09964","0.09078"
"481.53600","40.12811","0.09101"
"481.87800","40.15662","0.09181"
"482.22000","40.18514","0.09296"
"482.56200","40.21360","0.09348"
"482.90400","40.24206","0.09401"
"483.24600","40.27064","0.09458"
"483.58800","40.29910","0.09512"
"483.93000","40.32763","0.09566"
"484.27200","40.35614","0.09612"
"484.61400","40.38460","0.09662"
"484.95600","40.41312","0.09675"
"485.29800","40.44164","0.09715"
"485.64000","40.47010","0.09750"
"485.98200","40.49868","0.09770"
"486.32400","40.52708","0.09824"
"486.66600","40.55560","0.09873"
"487.00800","40.58412","0.09858"
"487.35000","40.61258","0.02673"
"487.69200","40.64116","0.02490"
"488.03400","40.66962","0.02265"
"488.37600","40.69807","0.02315"
"488.71800","40.72659","0.02309"
"489.06000","40.75505","0.02490"
"489.40200","40.78358","0.02505"
"489.74400","40.81216","0.01433"
"490.08600","40.84055","0.00796"
"490.42800","40.86914","0.00845"
"490.77000","40.89766","0.00910"
"491.11200","40.92606","0.00906"
"491.45400","40.95464","0.01135"
"491.79600","40.98304","0.00878"
"492.13800","41.01155","0.01033"
"492.48000","41.04013","0.00988"
"492.82200","41.06859","0.00941"
"493.16400","41.09717","0.01203"
"493.50600","41.12563","0.00981"
"493.84800","41.15403","0.01256"
"494.19000","41.18267","0.01121"
"494.53200","41.21107","0.01216"
"494.87400","41.23959","0.01192"
"495.21600","41.26811","0.01243"
"495.55800","41.29657","0.01374"
"495.90000","41.32509","0.01261"
"496.24200","41.35361","0.01493"
"496.58400","41.38207","0.01362"
"496.92600","41.41059","0.01554"
"497.26800","41.43911","0.01481"
"497.61000","41.46757","0.01624"
"497.95200","41.49615","0.01596"
"498.29400","41.52460","0.01694"
"498.63600","41.55307","0.01606"
"498.97800","41.58158","0.01692"
"499.32000","41.61011","-0.00030"
"499.66200","41.63857","-0.00216"
"500.00400","41.66709","-0.00158"
"500.34600","41.69567","-0.00308"
"500.68800","41.72412","-0.00211"
"501.03000","41.75265","-0.00146"
"501.37200","41.78104","-0.00203"
"501.71400","41.80963","-0.00344"
"502.05600","41.83814","-0.00229"
"502.39800","41.86654","-0.00186"
"502.74000","41.89512","-0.00214"
"503.08200","41.92364","-0.00255"
"503.42400","41.95210","-0.00169"
"503.76600","41.98063","-0.00217"
"504.10800","42.00908","-0.00250"
"504.37600","42.03144","-0.00253"