File: Force_trajectories/161226_1/Specimen_RawData_1.csv
End date,"12/26/2016"
Specimen label,"15DT_27"
Maximum Load,"0.05819",N

Time,Extension,Load
(s),(mm),(N)
"0.00000","0.00000","-0.00011"
"0.27600","0.02212","-0.00017"
"0.55200","0.04628","-0.00004"
"0.82800","0.06918","0.00069"
"1.10400","0.09220","-0.00052"
"1.38000","0.11521","-0.00014"
"1.65600","0.13817","-0.00004"
"1.93200","0.16113","-0.00046"
"2.20800","0.18421","0.00042"
"2.48400","0.20717","-0.00009"
"2.76000","0.23025","0.00001"
"3.03600","0.25315","-0.00017"
"3.31200","0.27623","0.00004"
"3.58800","0.29919","-0.00023"
"3.86400","0.32221","0.00001"
"4.14000","0.34516","0.00028"
"4.41600","0.36818","-0.00044"
"4.69200","0.39114","0.00010"
"4.96800","0.41416","0.00007"
"5.24400","0.43712","-0.00015"
"5.52000","0.46020","-0.00012"
"5.79600","0.48310","-0.00001"
"6.07200","0.50618","-0.00027"
"6.34800","0.52914","-0.00070"
"6.62400","0.55222","-0.00048"
"6.90000","0.57518","-0.00034"
"7.17600","0.59819","-0.00064"
"7.45200","0.62109","-0.00086"
"7.72800","0.64423","-0.00042"
"8.00400","0.66713","-0.00018"
"8.28000","0.69021","-0.00012"
"8.55600","0.71317","-0.00051"
"8.83200","0.73619","-0.00076"
"9.10800","0.75909","-0.00050"
"9.38400","0.78223","-0.00016"
"9.66000","0.80513","-0.00075"
"9.93600","0.82826","-0.00036"
"10.21200","0.85122","-0.00049"
"10.48800","0.87424","-0.00017"
"10.76400","0.89720","-0.00042"
"11.04000","0.92016","-0.00080"
"11.31600","0.94318","-0.00121"
"11.59200","0.96614","-0.00049"
"11.86800","0.98916","-0.00059"
"12.14400","1.01218","-0.00020"
"12.42000","1.03520","-0.00069"
"12.69600","1.05816","-0.00026"
"12.97200","1.08117","-0.00047"
"13.24800","1.10419","-0.00068"
"13.52400","1.12721","-0.00055"
"13.80000","1.15017","-0.00093"
"14.07600","1.17325","-0.00054"
"14.35200","1.19615","-0.00057"
"14.62800","1.21923","-0.00068"
"14.90400","1.24219","-0.00081"
"15.18000","1.26521","-0.00035"
"15.45600","1.28817","-0.00061"
"15.73200","1.31118","-0.00120"
"16.00800","1.33414","-0.00128"
"16.28400","1.35722","-0.00015"
"16.56000","1.38018","-0.00066"
"16.83600","1.40320","-0.00114"
"17.11200","1.42616","-0.00108"
"17.38800","1.44924","-0.00087"
"17.66400","1.47220","-0.00105"
"17.94000","1.49522","-0.00067"
"18.21600","1.51812","-0.00048"
"18.49200","1.54119","-0.00067"
"18.76800","1.56415","-0.00131"
"19.04400","1.58711","-0.00057"
"19.32000","1.61013","-0.00081"
"19.59600","1.63321","-0.00071"
"19.87200","1.65617","-0.00011"
"20.14800","1.67913","-0.00031"
"20.42400","1.70215","-0.00076"
"20.70000","1.72517","-0.00089"
"20.97600","1.74825","-0.00085"
"21.25200","1.77121","-0.00046"
"21.52800","1.79422","-0.00073"
"21.80400","1.81712","-0.00082"
"22.08000","1.84020","-0.00016"
"22.35600","1.86316","-0.00050"
"22.63200","1.88624","-0.00030"
"22.90800","1.90920","-0.00046"
"23.18400","1.93222","-0.00022"
"23.46000","1.95518","-0.00039"
"23.73600","1.97826","-0.00017"
"24.01200","2.00116","-0.00081"
"24.28800","2.02417","-0.00039"
"24.56400","2.04719","-0.00057"
"24.84000","2.07027","-0.00043"
"25.11600","2.09317","-0.00047"
"25.39200","2.11619","-0.00062"
"25.66800","2.13915","-0.00038"
"25.94400","2.16217","-0.00059"
"26.22000","2.18513","-0.00126"
"26.49600","2.20815","0.00010"
"26.77200","2.23111","-0.00074"
"27.04800","2.25418","-0.00078"
"27.32400","2.27714","-0.00115"
"27.60000","2.30022","-0.00059"
"27.87600","2.32312","-0.00074"
"28.15200","2.34620","-0.00057"
"28.42800","2.36916","-0.00080"
"28.70400","2.39218","-0.00042"
"28.98000","2.41514","-0.00019"
"29.25600","2.43822","-0.00101"
"29.53200","2.46112","-0.00058"
"29.80800","2.48420","-0.00062"
"30.08400","2.50715","-0.00094"
"30.36000","2.53023","-0.00017"
"30.63600","2.55313","-0.00054"
"30.91200","2.57615","-0.00081"
"31.18800","2.59917","-0.00044"
"31.46400","2.62219","-0.00013"
"31.74000","2.64521","-0.00014"
"32.01600","2.66817","-0.00142"
"32.29200","2.69125","-0.00082"
"32.56800","2.71421","0.00013"
"32.84400","2.73716","-0.00102"
"33.12000","2.76012","-0.00080"
"33.39600","2.78314","-0.00056"
"33.67200","2.80616","-0.00095"
"33.94800","2.82918","-0.00056"
"34.22400","2.85214","-0.00109"
"34.50000","2.87516","-0.00048"
"34.77600","2.89812","-0.00130"
"35.05200","2.92120","-0.00045"
"35.32800","2.94416","-0.00109"
"35.60400","2.96718","-0.00042"
"35.88000","2.99019","-0.00100"
"36.15600","3.01321","-0.00109"
"36.43200","3.03617","-0.00068"
"36.70800","3.05919","-0.00083"
"36.98400","3.08215","-0.00098"
"37.26000","3.10517","-0.00097"
"37.53600","3.12813","-0.00069"
"37.81200","3.15121","-0.00077"
"38.08800","3.17417","-0.00071"
"38.36400","3.19719","-0.00066"
"38.64000","3.22014","-0.00086"
"38.91600","3.24322","-0.00054"
"39.19200","3.26618","-0.00082"
"39.46800","3.28920","-0.00082"
"39.74400","3.31210","-0.00074"
"40.02000","3.33524","-0.00105"
"40.29600","3.35808","-0.00057"
"40.57200","3.38122","-0.00030"
"40.84800","3.40412","-0.00065"
"41.12400","3.42720","-0.00035"
"41.40000","3.45010","-0.00057"
"41.67600","3.47323","-0.00089"
"41.95200","3.49619","-0.00128"
"42.22800","3.51921","-0.00099"
"42.50400","3.54217","-0.00087"
"42.78000","3.56519","-0.00112"
"43.05600","3.58815","-0.00128"
"43.33200","3.61117","-0.00089"
"43.60800","3.63419","-0.00039"
"43.88400","3.65721","-0.00108"
"44.16000","3.68022","-0.00117"
"44.43600","3.70318","-0.00096"
"44.71200","3.72614","-0.00081"
"44.98800","3.74916","-0.00083"
"45.26400","3.77218","-0.00097"
"45.54000","3.79520","-0.00060"
"45.81600","3.81822","-0.00069"
"46.09200","3.84118","-0.00078"
"46.36800","3.86426","-0.00087"
"46.64400","3.88722","-0.00072"
"46.92000","3.91018","-0.00108"
"47.19600","3.93314","-0.00123"
"47.47200","3.95615","-0.00082"
"47.74800","3.97911","-0.00129"
"48.02400","4.00213","-0.00141"
"48.30000","4.02515","-0.00162"
"48.57600","4.04823","-0.00123"
"48.85200","4.07113","-0.00103"
"49.12800","4.09421","-0.00078"
"49.40400","4.11711","-0.00085"
"49.68000","4.14025","-0.00082"
"49.95600","4.16315","-0.00125"
"50.23200","4.18622","-0.00141"
"50.50800","4.20912","-0.00131"
"50.78400","4.23226","-0.00147"
"51.06000","4.25516","-0.00141"
"51.33600","4.27824","-0.00114"
"51.61200","4.30114","-0.00149"
"51.88800","4.32422","-0.00115"
"52.16400","4.34712","-0.00080"
"52.44000","4.37020","-0.00070"
"52.71600","4.39316","-0.00092"
"52.99200","4.41617","-0.00073"
"53.26800","4.43919","-0.00046"
"53.54400","4.46221","-0.00097"
"53.82000","4.48517","-0.00141"
"54.09600","4.50819","-0.00081"
"54.37200","4.53121","-0.00169"
"54.64800","4.55411","-0.00089"
"54.92400","4.57719","-0.00159"
"55.20000","4.60015","-0.00095"
"55.47600","4.62317","-0.00124"
"55.75200","4.64613","-0.00103"
"56.02800","4.66920","-0.00057"
"56.30400","4.69216","-0.00105"
"56.58000","4.71524","-0.00100"
"56.85600","4.73814","-0.00060"
"57.13200","4.76128","-0.00102"
"57.40800","4.78418","-0.00082"
"57.68400","4.80720","-0.00080"
"57.96000","4.83016","-0.00062"
"58.23600","4.85324","-0.00086"
"58.51200","4.87614","-0.00078"
"58.78800","4.89915","-0.00024"
"59.06400","4.92211","-0.00087"
"59.34000","4.94519","-0.00094"
"59.61600","4.96809","-0.00046"
"59.89200","4.99123","-0.00043"
"60.16800","5.01413","-0.00051"
"60.44400","5.03721","-0.00072"
"60.72000","5.06017","-0.00055"
"60.99600","5.08325","-0.00119"
"61.27200","5.10620","-0.00113"
"61.54800","5.12922","-0.00069"
"61.82400","5.15212","-0.00095"
"62.10000","5.17514","-0.00125"
"62.37600","5.19816","-0.00126"
"62.65200","5.22118","-0.00061"
"62.92800","5.24414","-0.00115"
"63.20400","5.26716","-0.00060"
"63.48000","5.29012","-0.00053"
"63.75600","5.31314","-0.00101"
"64.03200","5.33616","-0.00122"
"64.30800","5.35918","-0.00085"
"64.58400","5.38219","-0.00060"
"64.86000","5.40521","-0.00114"
"65.13600","5.42823","-0.00093"
"65.41200","5.45113","-0.00094"
"65.68800","5.47421","-0.00127"
"65.96400","5.49717","-0.00114"
"66.24000","5.52019","-0.00081"
"66.51600","5.54315","-0.00098"
"66.79200","5.56623","-0.00172"
"67.06800","5.58919","-0.00070"
"67.34400","5.61220","-0.00139"
"67.62000","5.63516","-0.00129"
"67.89600","5.65818","-0.00102"
"68.17200","5.68114","-0.00073"
"68.44800","5.70422","-0.00100"
"68.72400","5.72712","-0.00077"
"69.00000","5.75014","-0.00146"
"69.27600","5.77316","-0.00067"
"69.55200","5.79618","-0.00116"
"69.82800","5.81914","-0.00172"
"70.10400","5.84215","-0.00132"
"70.38000","5.86517","-0.00120"
"70.65600","5.88819","-0.00107"
"70.93200","5.91115","-0.00092"
"71.20800","5.93417","-0.00132"
"71.48400","5.95713","-0.00105"
"71.76000","5.98015","-0.00086"
"72.03600","6.00323","-0.00069"
"72.31200","6.02625","-0.00139"
"72.58800","6.04915","-0.00083"
"72.86400","6.07217","-0.00118"
"73.14000","6.09512","-0.00122"
"73.41600","6.11814","-0.00129"
"73.69200","6.14116","-0.00111"
"73.96800","6.16418","-0.00158"
"74.24400","6.18714","-0.00098"
"74.52000","6.21022","-0.00086"
"74.79600","6.23318","-0.00150"
"75.07200","6.25620","-0.00110"
"75.34800","6.27922","-0.00063"
"75.62400","6.30218","-0.00084"
"75.90000","6.32519","-0.00102"
"76.17600","6.34815","-0.00101"
"76.45200","6.37111","-0.00058"
"76.72800","6.39413","-0.00078"
"77.00400","6.41721","-0.00113"
"77.28000","6.44017","-0.00116"
"77.55600","6.46319","-0.00101"
"77.83200","6.48615","-0.00126"
"78.10800","6.50917","-0.00081"
"78.38400","6.53213","-0.00123"
"78.66000","6.55520","-0.00091"
"78.93600","6.57816","-0.00122"
"79.21200","6.60118","-0.00121"
"79.48800","6.62420","-0.00110"
"79.76400","6.64716","-0.00153"
"80.04000","6.67012","-0.00086"
"80.31600","6.69314","-0.00124"
"80.59200","6.71610","-0.00127"
"80.86800","6.73918","-0.00074"
"81.14400","6.76220","-0.00059"
"81.42000","6.78516","-0.00061"
"81.69600","6.80811","-0.00079"
"81.97200","6.83125","-0.00063"
"82.24800","6.85421","-0.00112"
"82.52400","6.87723","-0.00114"
"82.80000","6.90019","-0.00102"
"83.07600","6.92321","-0.00069"
"83.35200","6.94617","-0.00167"
"83.62800","6.96919","-0.00161"
"83.90400","6.99209","-0.00082"
"84.18000","7.01517","-0.00090"
"84.45600","7.03813","-0.00089"
"84.73200","7.06120","-0.00009"
"85.00800","7.08416","-0.00090"
"85.28400","7.10724","-0.00118"
"85.56000","7.13014","-0.00116"
"85.83600","7.15316","-0.00070"
"86.11200","7.17618","-0.00076"
"86.38800","7.19920","-0.00085"
"86.66400","7.22222","-0.00099"
"86.94000","7.24518","-0.00117"
"87.21600","7.26820","-0.00080"
"87.49200","7.29121","-0.00077"
"87.76800","7.31417","-0.00095"
"88.04400","7.33713","-0.00090"
"88.32000","7.36021","-0.00077"
"88.59600","7.38317","-0.00036"
"88.87200","7.40619","-0.00131"
"89.14800","7.42921","-0.00096"
"89.42400","7.45229","-0.00081"
"89.70000","7.47519","-0.00087"
"89.97600","7.49821","-0.00076"
"90.25200","7.52116","-0.00074"
"90.52800","7.54418","-0.00083"
"90.80400","7.56708","-0.00105"
"91.08000","7.59016","-0.00025"
"91.35600","7.61312","-0.00144"
"91.63200","7.63620","-0.00040"
"91.90800","7.65910","-0.00095"
"92.18400","7.68218","-0.00065"
"92.46000","7.70514","-0.00080"
"92.73600","7.72822","-0.00055"
"93.01200","7.75117","-0.00094"
"93.28800","7.77425","-0.00028"
"93.56400","7.79715","-0.00052"
"93.84000","7.82023","-0.00089"
"94.11600","7.84313","-0.00092"
"94.39200","7.86621","-0.00032"
"94.66800","7.88917","-0.00139"
"94.94400","7.91219","-0.00075"
"95.22000","7.93515","-0.00130"
"95.49600","7.95817","-0.00060"
"95.77200","7.98118","-0.00114"
"96.04800","8.00420","-0.00099"
"96.32400","8.02716","-0.00103"
"96.60000","8.05018","-0.00102"
"96.87600","8.07320","-0.00102"
"97.15200","8.09622","-0.00104"
"97.42800","8.11918","-0.00069"
"97.70400","8.14214","-0.00050"
"97.98000","8.16516","-0.00068"
"98.25600","8.18812","-0.00055"
"98.53200","8.21114","-0.00069"
"98.80800","8.23409","-0.00077"
"99.08400","8.25723","-0.00226"
"99.36000","8.28019","-0.00161"
"99.63600","8.30321","-0.00158"
"99.91200","8.32611","-0.00173"
"100.18800","8.34919","-0.00121"
"100.46400","8.37215","-0.00131"
"100.74000","8.39523","-0.00138"
"101.01600","8.41813","-0.00085"
"101.29200","8.44121","-0.00180"
"101.56800","8.46416","-0.00107"
"101.84400","8.48718","-0.00123"
"102.12000","8.51014","-0.00193"
"102.39600","8.53316","-0.00147"
"102.67200","8.55612","-0.00152"
"102.94800","8.57920","-0.00138"
"103.22400","8.60216","-0.00140"
"103.50000","8.62524","-0.00139"
"103.77600","8.64814","-0.00104"
"104.05200","8.67122","-0.00180"
"104.32800","8.69418","-0.00150"
"104.60400","8.71719","-0.00098"
"104.88000","8.74015","-0.00124"
"105.15600","8.76317","-0.00088"
"105.43200","8.78619","-0.00084"
"105.70800","8.80921","-0.00128"
"105.98400","8.83217","-0.00074"
"106.26000","8.85513","-0.00144"
"106.53600","8.87815","-0.00130"
"106.81200","8.90117","-0.00171"
"107.08800","8.92419","-0.00114"
"107.36400","8.94720","-0.00126"
"107.64000","8.97016","-0.00140"
"107.91600","8.99318","-0.00168"
"108.19200","9.01620","-0.00185"
"108.46800","9.03916","-0.00166"
"108.74400","9.06218","-0.00079"
"109.02000","9.08514","-0.00091"
"109.29600","9.10822","-0.00118"
"109.57200","9.13112","-0.00094"
"109.84800","9.15426","-0.00112"
"110.12400","9.17715","-0.00127"
"110.40000","9.20023","-0.00115"
"110.67600","9.22313","-0.00144"
"110.95200","9.24627","-0.00118"
"111.22800","9.26911","-0.00077"
"111.50400","9.29219","-0.00131"
"111.78000","9.31515","-0.00088"
"112.05600","9.33823","-0.00074"
"112.33200","9.36113","-0.00078"
"112.60800","9.38415","-0.00098"
"112.88400","9.40711","-0.00142"
"113.16000","9.43019","-0.00086"
"113.43600","9.45314","-0.00099"
"113.71200","9.47616","-0.00112"
"113.98800","9.49912","-0.00111"
"114.26400","9.52220","-0.00070"
"114.54000","9.54522","-0.00088"
"114.81600","9.56818","-0.00114"
"115.09200","9.59120","-0.00086"
"115.36800","9.61422","-0.00095"
"115.64400","9.63718","-0.00102"
"115.92000","9.66019","-0.00049"
"116.19600","9.68315","-0.00068"
"116.47200","9.70617","-0.00121"
"116.74800","9.72913","-0.00057"
"117.02400","9.75215","-0.00039"
"117.30000","9.77517","-0.00108"
"117.57600","9.79819","-0.00063"
"117.85200","9.82121","-0.00036"
"118.12800","9.84423","-0.00017"
"118.40400","9.86725","-0.00067"
"118.68000","9.89020","-0.00092"
"118.95600","9.91323","-0.00091"
"119.23200","9.93618","-0.00053"
"119.50800","9.95914","-0.00068"
"119.78400","9.98216","-0.00112"
"120.06000","10.00518","-0.00065"
"120.33600","10.02820","-0.00086"
"120.61200","10.05122","-0.00097"
"120.88800","10.07418","-0.00071"
"121.16400","10.09720","-0.00052"
"121.44000","10.12016","-0.00079"
"121.71600","10.14323","-0.00085"
"121.99200","10.16619","-0.00090"
"122.26800","10.18921","-0.00091"
"122.54400","10.21217","-0.00060"
"122.82000","10.23519","-0.00080"
"123.09600","10.25815","-0.00076"
"123.37200","10.28123","-0.00087"
"123.64800","10.30413","-0.00053"
"123.92400","10.32715","-0.00052"
"124.20000","10.35017","-0.00048"
"124.47600","10.37318","-0.00051"
"124.75200","10.39614","-0.00013"
"125.02800","10.41922","-0.00042"
"125.30400","10.44218","-0.00050"
"125.58000","10.46520","-0.00061"
"125.85600","10.48816","0.00017"
"126.13200","10.51124","-0.00091"
"126.40800","10.53414","-0.00033"
"126.68400","10.55722","0.00007"
"126.96000","10.58018","-0.00019"
"127.23600","10.60320","-0.00012"
"127.51200","10.62615","-0.00059"
"127.78800","10.64917","-0.00048"
"128.06400","10.67213","-0.00041"
"128.34000","10.69521","-0.00028"
"128.61600","10.71817","-0.00083"
"128.89200","10.74119","-0.00048"
"129.16800","10.76415","-0.00017"
"129.44400","10.78723","-0.00036"
"129.72000","10.81019","-0.00077"
"129.99600","10.83315","-0.00015"
"130.27200","10.85617","-0.00024"
"130.54800","10.87912","-0.00018"
"130.82400","10.90220","-0.00023"
"131.10000","10.92516","-0.00039"
"131.37600","10.94818","0.00006"
"131.65200","10.97114","-0.00023"
"131.92800","10.99422","-0.00052"
"132.20400","11.01712","0.00039"
"132.48000","11.04020","0.00013"
"132.75600","11.06316","-0.00012"
"133.03200","11.08624","-0.00021"
"133.30800","11.10919","-0.00025"
"133.58400","11.13221","0.00000"
"133.86000","11.15511","-0.00002"
"134.13600","11.17819","-0.00001"
"134.41200","11.20109","0.00003"
"134.68800","11.22417","-0.00018"
"134.96400","11.24707","0.00010"
"135.24000","11.27021","0.00049"
"135.51600","11.29311","0.00072"
"135.79200","11.31618","0.00020"
"136.06800","11.33914","0.00008"
"136.34400","11.36222","0.00021"
"136.62000","11.38512","0.00002"
"136.89600","11.40820","0.00052"
"137.17200","11.43116","-0.00031"
"137.44800","11.45424","0.00026"
"137.72400","11.47714","0.00019"
"138.00000","11.50022","0.00021"
"138.27600","11.52318","0.00026"
"138.55200","11.54620","0.00028"
"138.82800","11.56916","-0.00044"
"139.10400","11.59217","0.00042"
"139.38000","11.61519","0.00001"
"139.65600","11.63821","-0.00029"
"139.93200","11.66123","-0.00066"
"140.20800","11.68419","-0.00062"
"140.48400","11.70721","-0.00011"
"140.76000","11.73017","-0.00011"
"141.03600","11.75319","-0.00002"
"141.31200","11.77615","-0.00041"
"141.58800","11.79917","0.00011"
"141.86400","11.82212","0.00000"
"142.14000","11.84520","0.00025"
"142.41600","11.86816","-0.00021"
"142.69200","11.89118","0.00033"
"142.96800","11.91408","-0.00017"
"143.24400","11.93722","0.00021"
"143.52000","11.96012","0.00008"
"143.79600","11.98326","0.00023"
"144.07200","12.00616","0.00036"
"144.34800","12.02924","0.00021"
"144.62400","12.05213","0.00025"
"144.90000","12.07515","0.00061"
"145.17600","12.09811","0.00055"
"145.45200","12.12119","0.00085"
"145.72800","12.14409","0.00038"
"146.00400","12.16723","0.00098"
"146.28000","12.19019","0.00057"
"146.55600","12.21321","0.00077"
"146.83200","12.23617","0.00055"
"147.10800","12.25925","0.00057"
"147.38400","12.28221","0.00093"
"147.66000","12.30522","0.00020"
"147.93600","12.32812","0.00100"
"148.21200","12.35120","0.00104"
"148.48800","12.37416","0.00024"
"148.76400","12.39718","0.00119"
"149.04000","12.42014","0.00061"
"149.31600","12.44316","0.00080"
"149.59200","12.46612","0.00099"
"149.86800","12.48914","0.00134"
"150.14400","12.51216","0.00040"
"150.42000","12.53517","0.00049"
"150.69600","12.55825","0.00107"
"150.97200","12.58121","0.00088"
"151.24800","12.60423","0.00196"
"151.52400","12.62719","0.00109"
"151.80000","12.65021","0.00155"
"152.07600","12.67317","0.00160"
"152.35200","12.69619","0.00119"
"152.62800","12.71915","0.00116"
"152.90400","12.74229","0.00099"
"153.18000","12.76519","0.00180"
"153.45600","12.78820","0.00149"
"153.73200","12.81116","0.00186"
"154.00800","12.83418","0.00203"
"154.28400","12.85720","0.00185"
"154.56000","12.88022","0.00211"
"154.83600","12.90318","0.00220"
"155.11200","12.92620","0.00236"
"155.38800","12.94916","0.00216"
"155.66400","12.97218","0.00232"
"155.94000","12.99508","0.00234"
"156.21600","13.01815","0.00226"
"156.49200","13.04111","0.00246"
"156.76800","13.06419","0.00277"
"157.04400","13.08715","0.00294"
"157.32000","13.11023","0.00317"
"157.59600","13.13319","0.00333"
"157.87200","13.15621","0.00303"
"158.14800","13.17917","0.00375"
"158.42400","13.20225","0.00396"
"158.70000","13.22521","0.00393"
"158.97600","13.24822","0.00395"
"159.25200","13.27118","0.00377"
"159.52800","13.29420","0.00419"
"159.80400","13.31716","0.00434"
"160.08000","13.34018","0.00458"
"160.35600","13.36320","0.00468"
"160.63200","13.38622","0.00528"
"160.90800","13.40918","0.00538"
"161.18400","13.43220","0.00501"
"161.46000","13.45528","0.00527"
"161.73600","13.47824","0.00571"
"162.01200","13.50119","0.00566"
"162.28800","13.52409","0.00595"
"162.56400","13.54717","0.00639"
"162.84000","13.57013","0.00642"
"163.11600","13.59321","0.00653"
"163.39200","13.61617","0.00688"
"163.66800","13.63919","0.00698"
"163.94400","13.66215","0.00716"
"164.22000","13.68517","0.00744"
"164.49600","13.70813","0.00765"
"164.77200","13.73114","0.00775"
"165.04800","13.75416","0.00813"
"165.32400","13.77724","0.00837"
"165.60000","13.80020","0.00835"
"165.87600","13.82322","0.00854"
"166.15200","13.84612","0.00532"
"166.42800","13.86914","-0.00089"
"166.70400","13.89210","0.00041"
"166.98000","13.91518","-0.00033"
"167.25600","13.93808","-0.00133"
"167.53200","13.96115","-0.00146"
"167.80800","13.98411","-0.00021"
"168.08400","14.00719","-0.00018"
"168.36000","14.03015","-0.00094"
"168.63600","14.05317","-0.00085"
"168.91200","14.07613","-0.00061"
"169.18800","14.09927","0.00005"
"169.46400","14.12217","-0.00115"
"169.74000","14.14519","-0.00052"
"170.01600","14.16815","-0.00051"
"170.29200","14.19117","-0.00037"
"170.56800","14.21412","-0.00067"
"170.84400","14.23720","-0.00087"
"171.12000","14.26016","-0.00118"
"171.39600","14.28318","0.00002"
"171.67200","14.30614","-0.00089"
"171.94800","14.32922","-0.00070"
"172.22400","14.35218","-0.00059"
"172.50000","14.37520","-0.00074"
"172.77600","14.39822","-0.00080"
"173.05200","14.42118","-0.00055"
"173.32800","14.44419","-0.00086"
"173.60400","14.46715","-0.00005"
"173.88000","14.49017","-0.00108"
"174.15600","14.51319","-0.00099"
"174.43200","14.53621","-0.00055"
"174.70800","14.55917","-0.00065"
"174.98400","14.58219","-0.00039"
"175.26000","14.60509","-0.00080"
"175.53600","14.62823","-0.00015"
"175.81200","14.65119","-0.00057"
"176.08800","14.67421","-0.00055"
"176.36400","14.69716","-0.00078"
"176.64000","14.72018","-0.00034"
"176.91600","14.74314","-0.00034"
"177.19200","14.76616","-0.00057"
"177.46800","14.78912","0.00000"
"177.74400","14.81220","-0.00064"
"178.02000","14.83516","0.00005"
"178.29600","14.85818","-0.00016"
"178.57200","14.88114","-0.00064"
"178.84800","14.90422","-0.00025"
"179.12400","14.92717","-0.00036"
"179.40000","14.95025","0.00035"
"179.67600","14.97321","-0.00074"
"179.95200","14.99623","-0.00017"
"180.22800","15.01913","0.00020"
"180.50400","15.04221","-0.00068"
"180.78000","15.06511","-0.00043"
"181.05600","15.08819","-0.00059"
"181.33200","15.11115","0.00028"
"181.60800","15.13417","-0.00018"
"181.88400","15.15719","-0.00031"
"182.16000","15.18014","-0.00036"
"182.43600","15.20316","0.00010"
"182.71200","15.22618","-0.00051"
"182.98800","15.24920","-0.00005"
"183.26400","15.27222","-0.00011"
"183.54000","15.29524","0.00011"
"183.81600","15.31814","-0.00015"
"184.09200","15.34116","-0.00055"
"184.36800","15.36418","0.00014"
"184.64400","15.38720","0.00003"
"184.92000","15.41010","0.00005"
"185.19600","15.43323","-0.00051"
"185.47200","15.45619","-0.00050"
"185.74800","15.47921","-0.00034"
"186.02400","15.50211","0.00014"
"186.30000","15.52519","-0.00031"
"186.57600","15.54815","-0.00041"
"186.85200","15.57129","-0.00011"
"187.12800","15.59419","-0.00062"
"187.40400","15.61727","-0.00024"
"187.68000","15.64010","-0.00001"
"187.95600","15.66318","-0.00050"
"188.23200","15.68608","-0.00020"
"188.50800","15.70922","-0.00024"
"188.78400","15.73212","0.00011"
"189.06000","15.75526","0.00007"
"189.33600","15.77816","-0.00042"
"189.61200","15.80124","-0.00048"
"189.88800","15.82420","0.00015"
"190.16400","15.84727","-0.00065"
"190.44000","15.87017","0.00029"
"190.71600","15.89325","-0.00011"
"190.99200","15.91621","0.00004"
"191.26800","15.93917","-0.00037"
"191.54400","15.96219","0.00003"
"191.82000","15.98515","0.00031"
"192.09600","16.00817","0.00037"
"192.37200","16.03113","-0.00066"
"192.64800","16.05415","0.00018"
"192.92400","16.07717","-0.00007"
"193.20000","16.10019","0.00008"
"193.47600","16.12314","-0.00009"
"193.75200","16.14622","0.00010"
"194.02800","16.16924","0.00054"
"194.30400","16.19226","-0.00021"
"194.58000","16.21516","0.00022"
"194.85600","16.23824","0.00024"
"195.13200","16.26114","0.00057"
"195.40800","16.28422","0.00053"
"195.68400","16.30712","-0.00009"
"195.96000","16.33020","-0.00001"
"196.23600","16.35316","0.00024"
"196.51200","16.37623","0.00033"
"196.78800","16.39919","-0.00023"
"197.06400","16.42221","-0.00001"
"197.34000","16.44517","-0.00014"
"197.61600","16.46825","-0.00029"
"197.89200","16.49115","0.00022"
"198.16800","16.51417","0.00045"
"198.44400","16.53713","-0.00043"
"198.72000","16.56021","-0.00030"
"198.99600","16.58305","-0.00034"
"199.27200","16.60618","0.00022"
"199.54800","16.62914","-0.00015"
"199.82400","16.65222","-0.00041"
"200.10000","16.67512","0.00017"
"200.37600","16.69820","-0.00055"
"200.65200","16.72110","-0.00042"
"200.92800","16.74412","0.00071"
"201.20400","16.76714","-0.00022"
"201.48000","16.79022","0.00018"
"201.75600","16.81324","0.00002"
"202.03200","16.83625","0.00035"
"202.30800","16.85915","0.00029"
"202.58400","16.88217","0.00057"
"202.86000","16.90513","0.00048"
"203.13600","16.92815","0.00016"
"203.41200","16.95117","0.00009"
"203.68800","16.97419","0.00034"
"203.96400","16.99721","0.00056"
"204.24000","17.02017","0.00007"
"204.51600","17.04325","0.00004"
"204.79200","17.06620","0.00039"
"205.06800","17.08922","0.00043"
"205.34400","17.11218","0.00021"
"205.62000","17.13514","0.00007"
"205.89600","17.15816","-0.00040"
"206.17200","17.18118","-0.00021"
"206.44800","17.20420","0.00016"
"206.72400","17.22716","0.00037"
"207.00000","17.25018","0.00036"
"207.27600","17.27314","0.00050"
"207.55200","17.29609","-0.00022"
"207.82800","17.31917","-0.00019"
"208.10400","17.34213","0.00019"
"208.38000","17.36521","-0.00014"
"208.65600","17.38817","0.00037"
"208.93200","17.41119","-0.00003"
"209.20800","17.43415","0.00065"
"209.48400","17.45717","0.00068"
"209.76000","17.48013","0.00040"
"210.03600","17.50321","0.00046"
"210.31200","17.52617","-0.00007"
"210.58800","17.54918","0.00033"
"210.86400","17.57214","0.00081"
"211.14000","17.59522","0.00055"
"211.41600","17.61818","0.00081"
"211.69200","17.64120","0.00065"
"211.96800","17.66416","0.00007"
"212.24400","17.68724","0.00103"
"212.52000","17.71020","0.00086"
"212.79600","17.73322","0.00096"
"213.07200","17.75618","0.00039"
"213.34800","17.77913","0.00031"
"213.62400","17.80215","0.00069"
"213.90000","17.82517","0.00048"
"214.17600","17.84819","0.00042"
"214.45200","17.87121","0.00070"
"214.72800","17.89417","0.00072"
"215.00400","17.91719","0.00046"
"215.28000","17.94021","0.00046"
"215.55600","17.96323","0.00030"
"215.83200","17.98625","0.00080"
"216.10800","18.00920","0.00041"
"216.38400","18.03222","0.00080"
"216.66000","18.05518","0.00125"
"216.93600","18.07820","0.00073"
"217.21200","18.10116","0.00071"
"217.48800","18.12418","0.00142"
"217.76400","18.14720","0.00076"
"218.04000","18.17022","0.00108"
"218.31600","18.19312","0.00078"
"218.59200","18.21620","0.00056"
"218.86800","18.23915","0.00085"
"219.14400","18.26224","0.00089"
"219.42000","18.28519","0.00063"
"219.69600","18.30821","0.00056"
"219.97200","18.33111","0.00117"
"220.24800","18.35419","0.00141"
"220.52400","18.37709","0.00089"
"220.80000","18.40017","0.00048"
"221.07600","18.42313","0.00104"
"221.35200","18.44621","0.00107"
"221.62800","18.46911","0.00097"
"221.90400","18.49224","0.00100"
"222.18000","18.51514","0.00072"
"222.45600","18.53822","0.00070"
"222.73200","18.56118","0.00154"
"223.00800","18.58426","0.00142"
"223.28400","18.60716","0.00098"
"223.56000","18.63024","0.00093"
"223.83600","18.65314","0.00087"
"224.11200","18.67616","0.00133"
"224.38800","18.69918","0.00122"
"224.66400","18.72214","0.00151"
"224.94000","18.74515","-0.00003"
"225.21600","18.76823","0.00038"
"225.49200","18.79125","0.00083"
"225.76800","18.81421","0.00062"
"226.04400","18.83723","0.00021"
"226.32000","18.86019","0.00009"
"226.59600","18.88321","0.00075"
"226.87200","18.90617","0.00071"
"227.14800","18.92925","0.00025"
"227.42400","18.95215","0.00033"
"227.70000","18.97516","0.00045"
"227.97600","18.99812","0.00084"
"228.25200","19.02120","0.00080"
"228.52800","19.04416","0.00050"
"228.80400","19.06718","0.00043"
"229.08000","19.09014","0.00072"
"229.35600","19.11316","0.00094"
"229.63200","19.13612","0.00097"
"229.90800","19.15920","0.00119"
"230.18400","19.18216","0.00113"
"230.46000","19.20523","0.00074"
"230.73600","19.22813","0.00098"
"231.01200","19.25115","0.00131"
"231.28800","19.27411","0.00100"
"231.56400","19.29719","0.00122"
"231.84000","19.32009","0.00142"
"232.11600","19.34323","0.00103"
"232.39200","19.36613","0.00158"
"232.66800","19.38921","0.00069"
"232.94400","19.41217","0.00116"
"233.22000","19.43525","0.00137"
"233.49600","19.45820","0.00075"
"233.77200","19.48122","0.00089"
"234.04800","19.50418","0.00104"
"234.32400","19.52720","0.00102"
"234.60000","19.55016","0.00083"
"234.87600","19.57318","0.00121"
"235.15200","19.59614","0.00103"
"235.42800","19.61910","0.00119"
"235.70400","19.64218","0.00159"
"235.98000","19.66514","0.00147"
"236.25600","19.68816","0.00161"
"236.53200","19.71117","0.00200"
"236.80800","19.73419","0.00165"
"237.08400","19.75715","0.00212"
"237.36000","19.78023","0.00201"
"237.63600","19.80319","0.00156"
"237.91200","19.82621","0.00193"
"238.18800","19.84917","0.00230"
"238.46400","19.87219","0.00224"
"238.74000","19.89508","0.00221"
"239.01600","19.91817","0.00188"
"239.29200","19.94113","0.00262"
"239.56800","19.96414","0.00230"
"239.84400","19.98716","0.00268"
"240.12000","20.01024","0.00299"
"240.39600","20.03320","0.00310"
"240.67200","20.05622","0.00341"
"240.94800","20.07918","0.00337"
"241.22400","20.10220","0.00366"
"241.50000","20.12516","0.00383"
"241.77600","20.14818","0.00373"
"242.05200","20.17113","0.00421"
"242.32800","20.19421","0.00427"
"242.60400","20.21711","0.00447"
"242.88000","20.24019","0.00512"
"243.15600","20.26315","0.00497"
"243.43200","20.28617","0.00505"
"243.70800","20.30919","0.00512"
"243.98400","20.33215","0.00509"
"244.26000","20.35517","0.00553"
"244.53600","20.37819","0.00530"
"244.81200","20.40121","0.00610"
"245.08800","20.42422","0.00602"
"245.36400","20.44718","0.00593"
"245.64000","20.47020","0.00690"
"245.91600","20.49316","0.00661"
"246.19200","20.51618","0.00652"
"246.46800","20.53920","0.00695"
"246.74400","20.56222","0.00718"
"247.02000","20.58518","0.00767"
"247.29600","20.60820","0.00796"
"247.57200","20.63122","0.00796"
"247.84800","20.65424","0.00823"
"248.12400","20.67725","0.00821"
"248.40000","20.70015","0.00884"
"248.67600","20.72317","0.00898"
"248.95200","20.74613","0.00905"
"249.22800","20.76921","0.00959"
"249.50400","20.79217","0.00993"
"249.78000","20.81519","0.01039"
"250.05600","20.83821","0.01047"
"250.33200","20.86116","0.01090"
"250.60800","20.88413","0.01114"
"250.88400","20.90720","0.01157"
"251.16000","20.93016","0.01179"
"251.43600","20.95318","0.01220"
"251.71200","20.97614","0.01277"
"251.98800","20.99922","0.01325"
"252.26400","21.02212","0.01334"
"252.54000","21.04520","0.01405"
"252.81600","21.06810","0.01482"
"253.09200","21.09118","0.01513"
"253.36800","21.11414","0.01591"
"253.64400","21.13721","0.01620"
"253.92000","21.16017","0.01688"
"254.19600","21.18319","0.01738"
"254.47200","21.20615","0.01773"
"254.74800","21.22923","0.01870"
"255.02400","21.25219","0.01945"
"255.30000","21.27527","0.02019"
"255.57600","21.29823","0.02072"
"255.85200","21.32125","0.02135"
"256.12800","21.34420","0.02220"
"256.40400","21.36717","0.02312"
"256.68000","21.39013","0.02360"
"256.95600","21.41314","0.02431"
"257.23200","21.43616","0.02466"
"257.50800","21.45918","0.02500"
"257.78400","21.48220","0.02582"
"258.06000","21.50516","0.02655"
"258.33600","21.52818","0.02746"
"258.61200","21.55120","0.02846"
"258.88800","21.57422","0.02969"
"259.16400","21.59718","0.02905"
"259.44000","21.62025","0.02999"
"259.71600","21.64315","0.03029"
"259.99200","21.66617","0.03135"
"260.26800","21.68913","0.03263"
"260.54400","21.71215","0.03371"
"260.82000","21.73517","0.03524"
"261.09600","21.75819","0.03593"
"261.37200","21.78115","0.03717"
"261.64800","21.80416","0.03772"
"261.92400","21.82718","0.03786"
"262.20000","21.85020","0.03949"
"262.47600","21.87317","0.04110"
"262.75200","21.89624","0.04137"
"263.02800","21.91914","0.04098"
"263.30400","21.94216","0.04112"
"263.58000","21.96512","0.04318"
"263.85600","21.98820","0.04353"
"264.13200","22.01110","0.04465"
"264.40800","22.03418","0.04547"
"264.68400","22.05708","0.04659"
"264.96000","22.08022","0.04713"
"265.23600","22.10311","0.04870"
"265.51200","22.12619","0.04873"
"265.78800","22.14915","0.04958"
"266.06400","22.17223","0.05015"
"266.34000","22.19519","0.05056"
"266.61600","22.21821","0.05185"
"266.89200","22.24117","0.05247"
"267.16800","22.26419","0.05269"
"267.44400","22.28715","0.05334"
"267.72000","22.31017","0.05406"
"267.99600","22.33318","0.05428"
"268.27200","22.35620","0.05484"
"268.54800","22.37922","0.05632"
"268.82400","22.40218","0.05626"
"269.10000","22.42520","0.05718"
"269.37600","22.44816","0.05802"
"269.65200","22.47118","-0.00576"
"269.92800","22.49414","-0.00076"
"270.20400","22.51722","-0.00087"
"270.48000","22.54012","-0.00089"
"270.75600","22.56319","-0.00094"
"271.03200","22.58609","-0.00034"
"271.30800","22.60917","-0.00088"
"271.58400","22.63213","-0.00023"
"271.86000","22.65515","-0.00029"
"272.13600","22.67811","-0.00015"
"272.41200","22.70119","0.00031"
"272.68800","22.72409","-0.00030"
"272.96400","22.74723","0.00012"
"273.24000","22.77013","0.00019"
"273.51600","22.79326","0.00008"
"273.79200","22.81616","0.00054"
"274.06800","22.83918","0.00004"
"274.34400","22.86214","0.00042"
"274.62000","22.88522","0.00024"
"274.89600","22.90812","-0.00019"
"275.17200","22.93120","0.00019"
"275.44800","22.95410","-0.00018"
"275.72400","22.97724","-0.00032"
"276.00000","23.00014","-0.00027"
"276.27600","23.02322","0.00039"
"276.55200","23.04618","0.00022"
"276.82800","23.06925","0.00088"
"277.10400","23.09215","0.00042"
"277.38000","23.11517","0.00016"
"277.65600","23.13813","0.00058"
"277.93200","23.16121","0.00041"
"278.20800","23.18417","0.00049"
"278.48400","23.20719","0.00065"
"278.76000","23.23021","0.00075"
"279.03600","23.25317","0.00060"
"279.31200","23.27618","0.00097"
"279.58800","23.29914","0.00076"
"279.86400","23.32216","0.00065"
"280.14000","23.34518","0.00066"
"280.41600","23.36826","0.00081"
"280.69200","23.39116","0.00104"
"280.96800","23.41424","0.00031"
"281.24400","23.43720","0.00068"
"281.52000","23.46022","0.00124"
"281.79600","23.48312","0.00044"
"282.07200","23.50620","0.00088"
"282.34800","23.52916","0.00117"
"282.62400","23.55217","0.00053"
"282.90000","23.57507","0.00075"
"283.17600","23.59821","0.00082"
"283.45200","23.62117","0.00094"
"283.72800","23.64425","0.00100"
"284.00400","23.66715","0.00105"
"284.28000","23.69023","0.00073"
"284.55600","23.71313","0.00098"
"284.83200","23.73621","0.00098"
"285.10800","23.75910","0.00077"
"285.38400","23.78218","0.00087"
"285.66000","23.80514","0.00148"
"285.93600","23.82816","0.00043"
"286.21200","23.85118","0.00109"
"286.48800","23.87426","0.00144"
"286.76400","23.89716","0.00100"
"287.04000","23.92018","0.00078"
"287.31600","23.94314","0.00084"
"287.59200","23.96622","0.00134"
"287.86800","23.98923","0.00108"
"288.14400","24.01225","0.00118"
"288.42000","24.03521","0.00162"
"288.69600","24.05823","0.00100"
"288.97200","24.08119","0.00118"
"289.24800","24.10415","0.00097"
"289.52400","24.12717","0.00146"
"289.80000","24.15019","0.00143"
"290.07600","24.17315","0.00160"
"290.35200","24.19617","0.00174"
"290.62800","24.21925","0.00142"
"290.90400","24.24220","0.00102"
"291.18000","24.26522","0.00145"
"291.45600","24.28818","0.00137"
"291.73200","24.31120","0.00131"
"292.00800","24.33416","0.00190"
"292.28400","24.35718","0.00194"
"292.56000","24.38014","0.00127"
"292.83600","24.40316","0.00136"
"293.11200","24.42618","0.00129"
"293.38800","24.44919","0.00118"
"293.66400","24.47216","0.00170"
"293.94000","24.49517","0.00154"
"294.21600","24.51813","0.00137"
"294.49200","24.54121","0.00168"
"294.76800","24.56417","0.00187"
"295.04400","24.58725","0.00199"
"295.32000","24.61015","0.00121"
"295.59600","24.63317","0.00213"
"295.87200","24.65613","0.00161"
"296.14800","24.67921","0.00141"
"296.42400","24.70210","0.00207"
"296.70000","24.72518","0.00159"
"296.97600","24.74814","0.00200"
"297.25200","24.77122","0.00162"
"297.52800","24.79418","0.00232"
"297.80400","24.81720","0.00196"
"298.08000","24.84016","0.00162"
"298.35600","24.86324","0.00216"
"298.63200","24.88620","0.00185"
"298.90800","24.90922","0.00157"
"299.18400","24.93218","0.00172"
"299.46000","24.95520","0.00221"
"299.73600","24.97816","0.00143"
"300.01200","25.00117","0.00222"
"300.28800","25.02419","0.00204"
"300.56400","25.04715","0.00179"
"300.84000","25.07017","0.00172"
"301.11600","25.09319","0.00150"
"301.39200","25.11621","0.00139"
"301.66800","25.13917","0.00199"
"301.94400","25.16225","0.00224"
"302.22000","25.18521","0.00172"
"302.49600","25.20822","0.00177"
"302.77200","25.23112","0.00197"
"303.04800","25.25414","0.00212"
"303.32400","25.27710","0.00180"
"303.60000","25.30018","0.00251"
"303.87600","25.32314","0.00235"
"304.15200","25.34616","0.00215"
"304.42800","25.36912","0.00203"
"304.70400","25.39219","0.00190"
"304.98000","25.41522","0.00174"
"305.25600","25.43817","0.00195"
"305.53200","25.46113","0.00210"
"305.80800","25.48421","0.00178"
"306.08400","25.50717","0.00181"
"306.36000","25.53019","0.00218"
"306.63600","25.55309","0.00172"
"306.91200","25.57623","0.00089"
"307.18800","25.59913","0.00158"
"307.46400","25.62221","0.00108"
"307.74000","25.64511","0.00059"
"308.01600","25.66818","0.00094"
"308.29200","25.69114","0.00132"
"308.56800","25.71416","-0.00008"
"308.84400","25.73712","-0.00030"
"309.12000","25.76020","-0.00091"
"309.39600","25.78316","-0.00080"
"309.67200","25.80624","-0.00038"
"309.94800","25.82920","-0.00039"
"310.22400","25.85216","-0.00078"
"310.50000","25.87518","-0.00023"
"310.77600","25.89813","-0.00041"
"311.05200","25.92121","-0.00054"
"311.32800","25.94417","0.00013"
"311.60400","25.96719","0.00005"
"311.88000","25.99015","-0.00002"
"312.15600","26.01323","-0.00045"
"312.43200","26.03619","-0.00021"
"312.70800","26.05921","0.00006"
"312.98400","26.08211","0.00027"
"313.26000","26.10519","0.00006"
"313.53600","26.12815","-0.00023"
"313.81200","26.15117","-0.00017"
"314.08800","26.17412","0.00059"
"314.36400","26.19720","0.00034"
"314.64000","26.22016","0.00006"
"314.91600","26.24318","-0.00005"
"315.19200","26.26614","0.00049"
"315.46800","26.28916","0.00029"
"315.74400","26.31212","0.00035"
"316.02000","26.33520","0.00018"
"316.29600","26.35816","0.00072"
"316.57200","26.38129","-0.00001"
"316.84800","26.40419","0.00016"
"317.12400","26.42721","0.00025"
"317.40000","26.45011","0.00053"
"317.67600","26.47319","0.00038"
"317.95200","26.49609","0.00033"
"318.22800","26.51923","0.00035"
"318.50400","26.54219","0.00007"
"318.78000","26.56527","0.00090"
"319.05600","26.58817","0.00035"
"319.33200","26.61125","0.00059"
"319.60800","26.63415","0.00088"
"319.88400","26.65722","0.00073"
"320.16000","26.68024","0.00086"
"320.43600","26.70320","0.00107"
"320.71200","26.72616","0.00078"
"320.98800","26.74918","0.00035"
"321.26400","26.77214","0.00106"
"321.54000","26.79510","0.00094"
"321.81600","26.81818","0.00104"
"322.09200","26.84120","0.00112"
"322.36800","26.86421","0.00055"
"322.64400","26.88717","0.00110"
"322.92000","26.91019","0.00131"
"323.19600","26.93321","0.00142"
"323.47200","26.95623","0.00103"
"323.74800","26.97919","0.00095"
"324.02400","27.00227","0.00138"
"324.30000","27.02517","0.00124"
"324.57600","27.04825","0.00094"
"324.85200","27.07115","0.00132"
"325.12800","27.09417","0.00151"
"325.40400","27.11712","0.00084"
"325.68000","27.14020","0.00147"
"325.95600","27.16316","0.00079"
"326.23200","27.18618","0.00115"
"326.50800","27.20914","0.00061"
"326.78400","27.23222","0.00110"
"327.06000","27.25518","0.00145"
"327.33600","27.27826","0.00138"
"327.61200","27.30116","0.00070"
"327.88800","27.32417","0.00146"
"328.16400","27.34713","0.00103"
"328.44000","27.37016","0.00135"
"328.71600","27.39311","0.00120"
"328.99200","27.41613","0.00105"
"329.26800","27.43915","0.00082"
"329.54400","27.46223","0.00100"
"329.82000","27.48519","0.00167"
"330.09600","27.50815","0.00097"
"330.37200","27.53117","0.00120"
"330.64800","27.55419","0.00144"
"330.92400","27.57721","0.00159"
"331.20000","27.60023","0.00152"
"331.47600","27.62324","0.00147"
"331.75200","27.64620","0.00145"
"332.02800","27.66922","0.00176"
"332.30400","27.69218","0.00139"
"332.58000","27.71514","0.00151"
"332.85600","27.73816","0.00159"
"333.13200","27.76118","0.00172"
"333.40800","27.78419","0.00066"
"333.68400","27.80721","0.00136"
"333.96000","27.83017","0.00151"
"334.23600","27.85320","0.00114"
"334.51200","27.87615","0.00153"
"334.78800","27.89923","0.00138"
"335.06400","27.92213","0.00059"
"335.34000","27.94521","0.00083"
"335.61600","27.96817","0.00136"
"335.89200","27.99119","0.00066"
"336.16800","28.01414","0.00063"
"336.44400","28.03711","0.00174"
"336.72000","28.06013","0.00101"
"336.99600","28.08315","0.00135"
"337.27200","28.10610","0.00122"
"337.54800","28.12918","0.00130"
"337.82400","28.15214","0.00130"
"338.10000","28.17522","0.00120"
"338.37600","28.19818","0.00150"
"338.65200","28.22120","0.00098"
"338.92800","28.24416","0.00127"
"339.20400","28.26718","0.00136"
"339.48000","28.29013","0.00090"
"339.75600","28.31316","0.00112"
"340.03200","28.33617","0.00125"
"340.30800","28.35919","0.00131"
"340.58400","28.38215","0.00132"
"340.86000","28.40517","0.00131"
"341.13600","28.42819","0.00133"
"341.41200","28.45121","0.00153"
"341.68800","28.47417","0.00108"
"341.96400","28.49718","0.00078"
"342.24000","28.52021","0.00121"
"342.51600","28.54317","0.00134"
"342.79200","28.56612","0.00104"
"343.06800","28.58914","0.00160"
"343.34400","28.61222","0.00106"
"343.62000","28.63518","0.00164"
"343.89600","28.65820","0.00136"
"344.17200","28.68116","0.00112"
"344.44800","28.70418","0.00158"
"344.72400","28.72714","0.00117"
"345.00000","28.75022","0.00181"
"345.27600","28.77317","0.00122"
"345.55200","28.79620","0.00134"
"345.82800","28.81921","0.00111"
"346.10400","28.84223","0.00141"
"346.38000","28.86513","0.00085"
"346.65600","28.88815","0.00045"
"346.93200","28.91117","0.00046"
"347.20800","28.93419","-0.00006"
"347.48400","28.95715","0.00032"
"347.76000","28.98017","0.00010"
"348.03600","29.00313","0.00011"
"348.31200","29.02621","-0.00007"
"348.58800","29.04916","0.00018"
"348.86400","29.07224","0.00041"
"349.14000","29.09514","-0.00011"
"349.41600","29.11822","0.00017"
"349.69200","29.14112","0.00056"
"349.96800","29.16420","0.00052"
"350.24400","29.18716","0.00037"
"350.52000","29.21024","0.00043"
"350.79600","29.23319","0.00088"
"351.07200","29.25621","0.00033"
"351.34800","29.27911","0.00047"
"351.62400","29.30219","0.00078"
"351.90000","29.32515","0.00050"
"352.17600","29.34823","0.00074"
"352.45200","29.37119","0.00060"
"352.72800","29.39421","0.00046"
"353.00400","29.41723","0.00097"
"353.28000","29.44019","0.00118"
"353.55600","29.46315","-0.00017"
"353.83200","29.48610","0.00066"
"354.10800","29.50918","0.00056"
"354.38400","29.53214","0.00028"
"354.66000","29.55522","0.00094"
"354.93600","29.57818","0.00070"
"355.21200","29.60126","0.00066"
"355.48800","29.62422","0.00093"
"355.76400","29.64724","0.00051"
"356.04000","29.67020","0.00073"
"356.31600","29.69328","0.00095"
"356.59200","29.71618","0.00050"
"356.86800","29.73925","-0.00007"
"357.14400","29.76215","0.00087"
"357.42000","29.78518","0.00068"
"357.69600","29.80813","0.00046"
"357.97200","29.83121","0.00071"
"358.24800","29.85417","0.00048"
"358.52400","29.87719","0.00071"
"358.80000","29.90015","0.00055"
"359.07600","29.92317","0.00098"
"359.35200","29.94613","0.00031"
"359.62800","29.96926","0.00083"
"359.90400","29.99216","0.00055"
"360.18000","30.01518","0.00082"
"360.45600","30.03814","0.00064"
"360.73200","30.06122","0.00076"
"361.00800","30.08412","0.00091"
"361.28400","30.10720","0.00046"
"361.56000","30.13016","0.00067"
"361.83600","30.15324","0.00031"
"362.11200","30.17620","0.00046"
"362.38800","30.19921","0.00075"
"362.66400","30.22223","0.00038"
"362.94000","30.24525","0.00052"
"363.21600","30.26822","0.00092"
"363.49200","30.29117","0.00013"
"363.76800","30.31413","0.00041"
"364.04400","30.33715","0.00068"
"364.32000","30.36017","0.00100"
"364.59600","30.38313","0.00103"
"364.87200","30.40615","0.00072"
"365.14800","30.42911","0.00065"
"365.42400","30.45218","0.00063"
"365.70000","30.47515","0.00093"
"365.97600","30.49822","0.00085"
"366.25200","30.52118","0.00116"
"366.52800","30.54420","0.00046"
"366.80400","30.56716","0.00083"
"367.08000","30.59024","0.00022"
"367.35600","30.61320","0.00074"
"367.63200","30.63622","0.00070"
"367.90800","30.65912","0.00097"
"368.18400","30.68220","0.00084"
"368.46000","30.70516","0.00070"
"368.73600","30.72817","0.00091"
"369.01200","30.75113","0.00096"
"369.28800","30.77415","0.00100"
"369.56400","30.79717","0.00076"
"369.84000","30.82019","0.00122"
"370.11600","30.84315","0.00132"
"370.39200","30.86623","0.00145"
"370.66800","30.88919","0.00121"
"370.94400","30.91227","0.00124"
"371.22000","30.93511","0.00131"
"371.49600","30.95819","0.00098"
"371.77200","30.98114","0.00122"
"372.04800","31.00416","0.00146"
"372.32400","31.02712","0.00102"
"372.60000","31.05020","0.00098"
"372.87600","31.07316","0.00141"
"373.15200","31.09612","0.00124"
"373.42800","31.11914","0.00093"
"373.70400","31.14216","0.00162"
"373.98000","31.16517","0.00146"
"374.25600","31.18825","0.00184"
"374.53200","31.21121","0.00111"
"374.80800","31.23423","0.00157"
"375.08400","31.25719","0.00155"
"375.36000","31.28015","0.00157"
"375.63600","31.30317","0.00211"
"375.91200","31.32619","0.00206"
"376.18800","31.34921","0.00242"
"376.46400","31.37216","0.00205"
"376.74000","31.39519","0.00230"
"377.01600","31.41821","0.00196"
"377.29200","31.44122","0.00202"
"377.56800","31.46418","0.00175"
"377.84400","31.48720","0.00196"
"378.12000","31.51016","0.00184"
"378.39600","31.53324","0.00189"
"378.67200","31.55614","0.00231"
"378.94800","31.57915","0.00193"
"379.22400","31.60217","0.00203"
"379.50000","31.62513","0.00228"
"379.77600","31.64810","0.00221"
"380.05200","31.67117","0.00190"
"380.32800","31.69413","0.00218"
"380.60400","31.71721","0.00206"
"380.88000","31.74017","0.00200"
"381.15600","31.76325","0.00200"
"381.43200","31.78615","0.00199"
"381.70800","31.80923","0.00221"
"381.98400","31.83212","0.00239"
"382.26000","31.85520","0.00217"
"382.53600","31.87816","0.00232"
"382.81200","31.90118","0.00228"
"383.08800","31.92414","0.00312"
"383.36400","31.94722","0.00207"
"383.64000","31.97018","0.00305"
"383.91600","31.99320","0.00286"
"384.19200","32.01616","0.00281"
"384.46800","32.03924","0.00261"
"384.74400","32.06219","0.00247"
"385.02000","32.08521","0.00252"
"385.29600","32.10823","0.00275"
"385.57200","32.13120","0.00290"
"385.84800","32.15416","0.00295"
"386.12400","32.17711","0.00256"
"386.40000","32.20019","0.00278"
"386.67600","32.22321","0.00288"
"386.95200","32.24623","0.00234"
"387.22800","32.26919","0.00270"
"387.50400","32.29221","0.00296"
"387.78000","32.31517","0.00311"
"388.05600","32.33818","0.00310"
"388.33200","32.36120","0.00236"
"388.60800","32.38428","0.00172"
"388.88400","32.40724","-0.00119"
"389.16000","32.43026","-0.00100"
"389.43600","32.45316","-0.00108"
"389.71200","32.47618","-0.00156"
"389.98800","32.49914","-0.00073"
"390.26400","32.52216","-0.00145"
"390.54000","32.54512","-0.00075"
"390.81600","32.56820","-0.00099"
"391.09200","32.59121","-0.00070"
"391.36800","32.61423","-0.00074"
"391.64400","32.63713","-0.00080"
"391.92000","32.66021","-0.00114"
"392.19600","32.68311","-0.00137"
"392.47200","32.70619","-0.00011"
"392.74800","32.72915","-0.00100"
"393.02400","32.75223","-0.00086"
"393.30000","32.77513","-0.00119"
"393.57600","32.79821","-0.00088"
"393.85200","32.82110","-0.00059"
"394.12800","32.84418","-0.00115"
"394.40400","32.86714","-0.00096"
"394.68000","32.89022","-0.00136"
"394.95600","32.91312","-0.00153"
"395.23200","32.93620","-0.00182"
"395.50800","32.95922","-0.00200"
"395.78400","32.98224","-0.00231"
"396.06000","33.00520","-0.00266"
"396.33600","33.02821","-0.00199"
"396.61200","33.05117","-0.00167"
"396.88800","33.07413","-0.00275"
"397.16400","33.09715","-0.00184"
"397.44000","33.12017","-0.00103"
"397.71600","33.14313","-0.00181"
"397.99200","33.16615","-0.00207"
"398.26800","33.18923","-0.00184"
"398.54400","33.21219","-0.00193"
"398.82000","33.23521","-0.00165"
"399.09600","33.25817","-0.00209"
"399.37200","33.28125","-0.00202"
"399.64800","33.30414","-0.00189"
"399.92400","33.32716","-0.00172"
"400.20000","33.35012","-0.00169"
"400.47600","33.37320","-0.00129"
"400.75200","33.39610","-0.00180"
"401.02800","33.41912","-0.00222"
"401.30400","33.44214","-0.00188"
"401.58000","33.46516","-0.00148"
"401.85600","33.48812","-0.00138"
"402.13200","33.51120","-0.00132"
"402.40800","33.53410","-0.00227"
"402.68400","33.55723","-0.00180"
"402.96000","33.58019","-0.00148"
"403.23600","33.60321","-0.00145"
"403.51200","33.62617","-0.00176"
"403.78800","33.64919","-0.00194"
"404.06400","33.67215","-0.00128"
"404.34000","33.69517","-0.00164"
"404.61600","33.71813","-0.00218"
"404.89200","33.74115","-0.00159"
"405.16800","33.76411","-0.00168"
"405.44400","33.78718","-0.00136"
"405.72000","33.81020","-0.00160"
"405.99600","33.83322","-0.00185"
"406.27200","33.85618","-0.00180"
"406.54800","33.87920","-0.00152"
"406.73800","33.89499","-0.00179"