File: Force_trajectories/161226_1/Specimen_RawData_5.csv
End date,"12/26/2016"
Specimen label,"22AG_78"
Maximum Load,"0.26632",N

Time,Extension,Load
(s),(mm),(N)
"0.00000","0.00000","-0.00080"
"0.19200","0.01208","-0.00023"
"0.38400","0.03205","0.00018"
"0.57600","0.04819","0.00019"
"0.76800","0.06409","0.00104"
"0.96000","0.08018","0.00092"
"1.15200","0.09620","0.00126"
"1.34400","0.11211","0.00100"
"1.53600","0.12819","0.00187"
"1.72800","0.14409","0.00196"
"1.92000","0.16018","0.00133"
"2.11200","0.17614","0.00190"
"2.30400","0.19210","0.00154"
"2.49600","0.20819","0.00222"
"2.68800","0.22421","0.00257"
"2.88000","0.24011","0.00237"
"3.07200","0.25614","0.00228"
"3.26400","0.27216","0.00260"
"3.45600","0.28813","0.00292"
"3.64800","0.30421","0.00281"
"3.84000","0.32011","0.00291"
"4.03200","0.33608","0.00275"
"4.22400","0.35216","0.00250"
"4.41600","0.36812","0.00298"
"4.60800","0.38409","0.00298"
"4.80000","0.40017","0.00269"
"4.99200","0.41614","0.00289"
"5.18400","0.43210","0.00262"
"5.37600","0.44818","0.00264"
"5.56800","0.46409","0.00301"
"5.76000","0.48011","0.00270"
"5.95200","0.49613","0.00330"
"6.14400","0.51204","0.00288"
"6.33600","0.52812","0.00367"
"6.52800","0.54414","0.00328"
"6.72000","0.56011","0.00323"
"6.91200","0.57613","0.00315"
"7.10400","0.59216","0.00380"
"7.29600","0.60806","0.00374"
"7.48800","0.62414","0.00364"
"7.68000","0.64017","0.00399"
"7.87200","0.65613","0.00420"
"8.06400","0.67209","0.00463"
"8.25600","0.68812","0.00409"
"8.44800","0.70408","0.00465"
"8.64000","0.72016","0.00432"
"8.83200","0.73613","0.00411"
"9.02400","0.75215","0.00439"
"9.21600","0.76818","0.00427"
"9.40800","0.78408","0.00464"
"9.60000","0.80010","0.00416"
"9.79200","0.81619","0.00417"
"9.98400","0.83215","0.00424"
"10.17600","0.84811","0.00487"
"10.36800","0.86408","0.00480"
"10.56000","0.88010","0.00497"
"10.75200","0.89613","0.00491"
"10.94400","0.91215","0.00480"
"11.13600","0.92811","0.00483"
"11.32800","0.94414","0.00511"
"11.52000","0.96004","0.00451"
"11.71200","0.97618","0.00467"
"11.90400","0.99215","0.00526"
"12.09600","1.00811","0.00510"
"12.28800","1.02419","0.00487"
"12.48000","1.04010","0.00498"
"12.67200","1.05612","0.00578"
"12.86400","1.07215","0.00526"
"13.05600","1.08811","0.00500"
"13.24800","1.10413","0.00512"
"13.44000","1.12016","0.00510"
"13.63200","1.13612","0.00545"
"13.82400","1.15214","0.00611"
"14.01600","1.16817","0.00529"
"14.20800","1.18413","0.00550"
"14.40000","1.20010","0.00563"
"14.59200","1.21612","0.00549"
"14.78400","1.23202","0.00531"
"14.97600","1.24817","0.00546"
"15.16800","1.26419","0.00637"
"15.36000","1.28009","0.00604"
"15.55200","1.29618","0.00637"
"15.74400","1.31214","0.00661"
"15.93600","1.32810","0.00622"
"16.12800","1.34419","0.00632"
"16.32000","1.36009","0.00526"
"16.51200","1.37612","0.00452"
"16.70400","1.39214","0.00440"
"16.89600","1.40810","0.00418"
"17.08800","1.42413","0.00456"
"17.28000","1.44015","0.00445"
"17.47200","1.45611","0.00461"
"17.66400","1.47214","0.00390"
"17.85600","1.48816","0.00456"
"18.04800","1.50413","0.00415"
"18.24000","1.52015","0.00402"
"18.43200","1.53617","0.00440"
"18.62400","1.55208","0.00392"
"18.81600","1.56810","0.00364"
"19.00800","1.58412","0.00397"
"19.20000","1.60015","0.00383"
"19.39200","1.61617","0.00405"
"19.58400","1.63213","0.00450"
"19.77600","1.64816","0.00429"
"19.96800","1.66412","0.00483"
"20.16000","1.68009","0.00485"
"20.35200","1.69617","0.00481"
"20.54400","1.71213","0.00471"
"20.73600","1.72810","0.00515"
"20.92800","1.74412","0.00514"
"21.12000","1.76008","0.00479"
"21.31200","1.77611","0.00509"
"21.50400","1.79219","0.00514"
"21.69600","1.80816","0.00485"
"21.88800","1.82412","0.00515"
"22.08000","1.84020","0.00497"
"22.27200","1.85611","0.00493"
"22.46400","1.87213","0.00542"
"22.65600","1.88815","0.00512"
"22.84800","1.90406","0.00473"
"23.04000","1.92014","0.00518"
"23.23200","1.93616","0.00503"
"23.42400","1.95207","0.00542"
"23.61600","1.96815","0.00516"
"23.80800","1.98412","0.00533"
"24.00000","2.00008","0.00602"
"24.19200","2.01616","0.00550"
"24.38400","2.03213","0.00534"
"24.57600","2.04815","0.00564"
"24.76800","2.06417","0.00602"
"24.96000","2.08008","0.00539"
"25.15200","2.09616","0.00588"
"25.34400","2.11213","0.00603"
"25.53600","2.12809","0.00606"
"25.72800","2.14411","0.00589"
"25.92000","2.16014","0.00572"
"26.11200","2.17610","0.00641"
"26.30400","2.19212","0.00573"
"26.49600","2.20815","0.00654"
"26.68800","2.22411","0.00617"
"26.88000","2.24013","0.00613"
"27.07200","2.25610","0.00640"
"27.26400","2.27212","0.00649"
"27.45600","2.28815","0.00596"
"27.64800","2.30405","0.00616"
"27.84000","2.32013","0.00642"
"28.03200","2.33622","0.00678"
"28.22400","2.35206","0.00598"
"28.41600","2.36820","0.00676"
"28.60800","2.38417","0.00649"
"28.80000","2.40001","0.00627"
"28.99200","2.41615","0.00655"
"29.18400","2.43212","0.00650"
"29.37600","2.44808","0.00676"
"29.56800","2.46417","0.00687"
"29.76000","2.48007","0.00653"
"29.95200","2.49609","0.00652"
"30.14400","2.51218","0.00703"
"30.33600","2.52814","0.00692"
"30.52800","2.54416","0.00683"
"30.72000","2.56019","0.00735"
"30.91200","2.57609","0.00716"
"31.10400","2.59218","0.00748"
"31.29600","2.60814","0.00685"
"31.48800","2.62410","0.00671"
"31.68000","2.64013","0.00728"
"31.87200","2.65609","0.00681"
"32.06400","2.67211","0.00769"
"32.25600","2.68814","0.00711"
"32.44800","2.70410","0.00768"
"32.64000","2.72018","0.00780"
"32.83200","2.73615","0.00770"
"33.02400","2.75211","0.00759"
"33.21600","2.76814","0.00742"
"33.40800","2.78416","0.00745"
"33.60000","2.80012","0.00749"
"33.79200","2.81615","0.00766"
"33.98400","2.83211","0.00782"
"34.17600","2.84807","0.00737"
"34.36800","2.86416","0.00812"
"34.56000","2.88012","0.00783"
"34.75200","2.89615","0.00832"
"34.94400","2.91217","0.00783"
"35.13600","2.92813","0.00811"
"35.32800","2.94416","0.00806"
"35.52000","2.96018","0.00842"
"35.71200","2.97608","0.00798"
"35.90400","2.99217","0.00828"
"36.09600","3.00819","0.00799"
"36.28800","3.02403","0.00815"
"36.48000","3.04018","0.00825"
"36.67200","3.05614","0.00815"
"36.86400","3.07205","0.00848"
"37.05600","3.08813","0.00842"
"37.24800","3.10409","0.00843"
"37.44000","3.12006","0.00836"
"37.63200","3.13620","0.00860"
"37.82400","3.15210","0.00895"
"38.01600","3.16807","0.00903"
"38.20800","3.18415","0.00898"
"38.40000","3.20006","0.00881"
"38.59200","3.21614","0.00849"
"38.78400","3.23216","0.00906"
"38.97600","3.24813","0.00850"
"39.16800","3.26415","0.00895"
"39.36000","3.28017","0.00896"
"39.55200","3.29608","0.00905"
"39.74400","3.31210","0.00876"
"39.93600","3.32818","0.00913"
"40.12800","3.34415","0.00917"
"40.32000","3.36011","0.00906"
"40.51200","3.37614","0.00939"
"40.70400","3.39216","0.00955"
"40.89600","3.40812","0.00924"
"41.08800","3.42415","0.00949"
"41.28000","3.44017","0.00946"
"41.47200","3.45607","0.00932"
"41.66400","3.47210","0.00947"
"41.85600","3.48812","0.00953"
"42.04800","3.50415","0.00965"
"42.24000","3.52011","0.00930"
"42.43200","3.53613","0.00964"
"42.62400","3.55210","0.00978"
"42.81600","3.56806","0.00916"
"43.00800","3.58414","0.00957"
"43.20000","3.60011","0.00966"
"43.39200","3.61613","0.00973"
"43.58400","3.63215","0.01012"
"43.77600","3.64806","0.00972"
"43.96800","3.66420","0.01011"
"44.16000","3.68017","0.01013"
"44.35200","3.69607","0.00997"
"44.54400","3.71221","0.01004"
"44.73600","3.72812","0.01020"
"44.92800","3.74402","0.00984"
"45.12000","3.76016","0.00980"
"45.31200","3.77619","0.01032"
"45.50400","3.79209","0.01064"
"45.69600","3.80823","0.01025"
"45.88800","3.82414","0.00995"
"46.08000","3.84010","0.01012"
"46.27200","3.85619","0.01036"
"46.46400","3.87215","0.01050"
"46.65600","3.88811","0.01070"
"46.84800","3.90414","0.01076"
"47.04000","3.92004","0.01045"
"47.23200","3.93612","0.01054"
"47.42400","3.95221","0.01080"
"47.61600","3.96805","0.01040"
"47.80800","3.98414","0.01064"
"48.00000","4.00016","0.01069"
"48.19200","4.01612","0.01098"
"48.38400","4.03215","0.01096"
"48.57600","4.04811","0.01085"
"48.76800","4.06413","0.01119"
"48.96000","4.08016","0.01090"
"49.15200","4.09612","0.01120"
"49.34400","4.11214","0.01126"
"49.53600","4.12811","0.01105"
"49.72800","4.14413","0.01129"
"49.92000","4.16016","0.01132"
"50.11200","4.17612","0.01151"
"50.30400","4.19208","0.01159"
"50.49600","4.20817","0.01163"
"50.68800","4.22413","0.01132"
"50.88000","4.24015","0.01144"
"51.07200","4.25612","0.01146"
"51.26400","4.27214","0.01169"
"51.45600","4.28811","0.01113"
"51.64800","4.30413","0.01182"
"51.84000","4.32009","0.01196"
"52.03200","4.33612","0.01182"
"52.22400","4.35214","0.01176"
"52.41600","4.36810","0.01188"
"52.60800","4.38419","0.01180"
"52.80000","4.40015","0.01183"
"52.99200","4.41606","0.01179"
"53.18400","4.43214","0.01169"
"53.37600","4.44810","0.01174"
"53.56800","4.46413","0.01186"
"53.76000","4.48015","0.01210"
"53.95200","4.49611","0.01209"
"54.14400","4.51208","0.01193"
"54.33600","4.52816","0.01197"
"54.52800","4.54412","0.01217"
"54.72000","4.56015","0.01194"
"54.91200","4.57617","0.01210"
"55.10400","4.59208","0.01207"
"55.29600","4.60816","0.01252"
"55.48800","4.62412","0.01227"
"55.68000","4.64009","0.01235"
"55.87200","4.65617","0.01248"
"56.06400","4.67213","0.01276"
"56.25600","4.68810","0.01275"
"56.44800","4.70418","0.01244"
"56.64000","4.72008","0.01259"
"56.83200","4.73611","0.01262"
"57.02400","4.75213","0.01283"
"57.21600","4.76810","0.01272"
"57.40800","4.78412","0.01260"
"57.60000","4.80014","0.01267"
"57.79200","4.81611","0.01310"
"57.98400","4.83213","0.01303"
"58.17600","4.84809","0.01299"
"58.36800","4.86412","0.01308"
"58.56000","4.88014","0.01295"
"58.75200","4.89616","0.01305"
"58.94400","4.91207","0.01337"
"59.13600","4.92815","0.01299"
"59.32800","4.94412","0.01340"
"59.52000","4.96008","0.01318"
"59.71200","4.97610","0.01304"
"59.90400","4.99213","0.01337"
"60.09600","5.00815","0.01256"
"60.28800","5.02411","0.01258"
"60.48000","5.04014","0.01273"
"60.67200","5.05616","0.01252"
"60.86400","5.07213","0.01251"
"61.05600","5.08809","0.01261"
"61.24800","5.10417","0.01266"
"61.44000","5.12014","0.01287"
"61.63200","5.13610","0.01292"
"61.82400","5.15218","0.01286"
"62.01600","5.16809","0.01264"
"62.20800","5.18411","0.01284"
"62.40000","5.20014","0.01288"
"62.59200","5.21610","0.01293"
"62.78400","5.23218","0.01290"
"62.97600","5.24815","0.01292"
"63.16800","5.26411","0.01266"
"63.36000","5.28013","0.01319"
"63.55200","5.29616","0.01305"
"63.74400","5.31206","0.01323"
"63.93600","5.32814","0.01319"
"64.12800","5.34411","0.01339"
"64.32000","5.36013","0.01358"
"64.51200","5.37616","0.01343"
"64.70400","5.39212","0.01335"
"64.89600","5.40808","0.01333"
"65.08800","5.42417","0.01378"
"65.28000","5.44013","0.01392"
"65.47200","5.45609","0.01378"
"65.66400","5.47212","0.01369"
"65.85600","5.48808","0.01384"
"66.04800","5.50416","0.01305"
"66.24000","5.52013","0.01294"
"66.43200","5.53609","0.01319"
"66.62400","5.55218","0.01324"
"66.81600","5.56814","0.01292"
"67.00800","5.58410","0.01361"
"67.20000","5.60013","0.01302"
"67.39200","5.61615","0.01316"
"67.58400","5.63211","0.01345"
"67.77600","5.64814","0.01322"
"67.96800","5.66410","0.01342"
"68.16000","5.68007","0.01299"
"68.35200","5.69615","0.01282"
"68.54400","5.71205","0.01311"
"68.73600","5.72814","0.01311"
"68.92800","5.74416","0.01322"
"69.12000","5.76012","0.01311"
"69.31200","5.77615","0.01346"
"69.50400","5.79217","0.01342"
"69.69600","5.80807","0.01374"
"69.88800","5.82410","0.01331"
"70.08000","5.84012","0.01342"
"70.27200","5.85615","0.01346"
"70.46400","5.87211","0.01368"
"70.65600","5.88813","0.01349"
"70.84800","5.90410","0.01365"
"71.04000","5.92018","0.01359"
"71.23200","5.93608","0.01380"
"71.42400","5.95217","0.01407"
"71.61600","5.96813","0.01387"
"71.80800","5.98410","0.01394"
"72.00000","6.00018","0.01388"
"72.19200","6.01614","0.01411"
"72.38400","6.03211","0.01422"
"72.57600","6.04813","0.01438"
"72.76800","6.06409","0.01408"
"72.96000","6.08012","0.01454"
"73.15200","6.09614","0.01434"
"73.34400","6.11210","0.01450"
"73.53600","6.12813","0.01444"
"73.72800","6.14415","0.01455"
"73.92000","6.16012","0.01447"
"74.11200","6.17614","0.01452"
"74.30400","6.19216","0.01476"
"74.49600","6.20807","0.01462"
"74.68800","6.22415","0.01459"
"74.88000","6.24017","0.01502"
"75.07200","6.25602","0.01469"
"75.26400","6.27216","0.01516"
"75.45600","6.28812","0.01511"
"75.64800","6.30409","0.01501"
"75.84000","6.32017","0.01488"
"76.03200","6.33608","0.01483"
"76.22400","6.35210","0.01497"
"76.41600","6.36818","0.01505"
"76.60800","6.38415","0.01499"
"76.80000","6.40011","0.01522"
"76.99200","6.41613","0.01544"
"77.18400","6.43210","0.01530"
"77.37600","6.44812","0.01553"
"77.56800","6.46415","0.01543"
"77.76000","6.48005","0.01581"
"77.95200","6.49613","0.01564"
"78.14400","6.51216","0.01557"
"78.33600","6.52812","0.01544"
"78.52800","6.54414","0.01581"
"78.72000","6.56011","0.01566"
"78.91200","6.57619","0.01571"
"79.10400","6.59215","0.01642"
"79.29600","6.60806","0.01600"
"79.48800","6.62414","0.01607"
"79.68000","6.64017","0.01591"
"79.87200","6.65607","0.01588"
"80.06400","6.67215","0.01619"
"80.25600","6.68818","0.01617"
"80.44800","6.70408","0.01618"
"80.64000","6.72016","0.01642"
"80.83200","6.73613","0.01657"
"81.02400","6.75209","0.01619"
"81.21600","6.76812","0.01660"
"81.40800","6.78408","0.01665"
"81.60000","6.80010","0.01655"
"81.79200","6.81619","0.01696"
"81.98400","6.83209","0.01660"
"82.17600","6.84817","0.01672"
"82.36800","6.86414","0.01689"
"82.56000","6.88010","0.01679"
"82.75200","6.89612","0.01680"
"82.94400","6.91215","0.01687"
"83.13600","6.92811","0.01727"
"83.32800","6.94408","0.01701"
"83.52000","6.96010","0.01726"
"83.71200","6.97612","0.01720"
"83.90400","6.99215","0.01744"
"84.09600","7.00811","0.01757"
"84.28800","7.02413","0.01750"
"84.48000","7.04010","0.01770"
"84.67200","7.05612","0.01768"
"84.86400","7.07214","0.01787"
"85.05600","7.08817","0.01792"
"85.24800","7.10407","0.01793"
"85.44000","7.12022","0.01801"
"85.63200","7.13606","0.01779"
"85.82400","7.15208","0.01827"
"86.01600","7.16817","0.01799"
"86.20800","7.18407","0.01814"
"86.40000","7.20009","0.01833"
"86.59200","7.21612","0.01852"
"86.78400","7.23208","0.01859"
"86.97600","7.24817","0.01835"
"87.16800","7.26419","0.01850"
"87.36000","7.28009","0.01836"
"87.55200","7.29612","0.01747"
"87.74400","7.31214","0.01752"
"87.93600","7.32804","0.01732"
"88.12800","7.34413","0.01788"
"88.32000","7.36021","0.01780"
"88.51200","7.37606","0.01811"
"88.70400","7.39220","0.01811"
"88.89600","7.40816","0.01816"
"89.08800","7.42407","0.01820"
"89.28000","7.44015","0.01792"
"89.47200","7.45617","0.01796"
"89.66400","7.47214","0.01864"
"89.85600","7.48816","0.01858"
"90.04800","7.50412","0.01863"
"90.24000","7.52015","0.01901"
"90.43200","7.53617","0.01896"
"90.62400","7.55208","0.01906"
"90.81600","7.56810","0.01920"
"91.00800","7.58418","0.01922"
"91.20000","7.60015","0.01942"
"91.39200","7.61611","0.01950"
"91.58400","7.63213","0.01990"
"91.77600","7.64810","0.01961"
"91.96800","7.66412","0.01984"
"92.16000","7.68015","0.01993"
"92.35200","7.69617","0.01967"
"92.54400","7.71213","0.01997"
"92.73600","7.72810","0.01981"
"92.92800","7.74412","0.02020"
"93.12000","7.76014","0.01999"
"93.31200","7.77611","0.02018"
"93.50400","7.79219","0.02065"
"93.69600","7.80816","0.02011"
"93.88800","7.82412","0.02054"
"94.08000","7.84014","0.02101"
"94.27200","7.85611","0.02110"
"94.46400","7.87213","0.02128"
"94.65600","7.88815","0.02115"
"94.84800","7.90406","0.02123"
"95.04000","7.92014","0.02130"
"95.23200","7.93610","0.02191"
"95.42400","7.95207","0.02180"
"95.61600","7.96815","0.02170"
"95.80800","7.98411","0.02160"
"96.00000","8.00008","0.02186"
"96.19200","8.01616","0.02220"
"96.38400","8.03213","0.02178"
"96.57600","8.04803","0.02136"
"96.76800","8.06417","0.02134"
"96.96000","8.08014","0.02142"
"97.15200","8.09610","0.02143"
"97.34400","8.11218","0.02143"
"97.53600","8.12815","0.02212"
"97.72800","8.14411","0.02227"
"97.92000","8.16013","0.02201"
"98.11200","8.17610","0.02226"
"98.30400","8.19212","0.02243"
"98.49600","8.20821","0.02276"
"98.68800","8.22405","0.02244"
"98.88000","8.24007","0.02272"
"99.07200","8.25622","0.02263"
"99.26400","8.27206","0.02307"
"99.45600","8.28814","0.02292"
"99.64800","8.30417","0.02355"
"99.84000","8.32013","0.02325"
"100.03200","8.33616","0.02345"
"100.22400","8.35218","0.02353"
"100.41600","8.36808","0.02335"
"100.60800","8.38411","0.02352"
"100.80000","8.40007","0.02391"
"100.99200","8.41609","0.02394"
"101.18400","8.43212","0.02445"
"101.37600","8.44808","0.02442"
"101.56800","8.46416","0.02481"
"101.76000","8.48013","0.02461"
"101.95200","8.49609","0.02518"
"102.14400","8.51218","0.02496"
"102.33600","8.52814","0.02540"
"102.52800","8.54416","0.02534"
"102.72000","8.56013","0.02486"
"102.91200","8.57609","0.02567"
"103.10400","8.59211","0.02589"
"103.29600","8.60814","0.02620"
"103.48800","8.62410","0.02576"
"103.68000","8.64013","0.02599"
"103.87200","8.65615","0.02638"
"104.06400","8.67205","0.02660"
"104.25600","8.68820","0.02695"
"104.44800","8.70416","0.02668"
"104.64000","8.72012","0.02731"
"104.83200","8.73621","0.02750"
"105.02400","8.75211","0.02774"
"105.21600","8.76807","0.02733"
"105.40800","8.78416","0.02769"
"105.60000","8.80012","0.02836"
"105.79200","8.81609","0.02778"
"105.98400","8.83211","0.02765"
"106.17600","8.84813","0.02843"
"106.36800","8.86416","0.02857"
"106.56000","8.88012","0.02883"
"106.75200","8.89608","0.02945"
"106.94400","8.91211","0.02919"
"107.13600","8.92813","0.02960"
"107.32800","8.94410","0.02970"
"107.52000","8.96012","0.03009"
"107.71200","8.97614","0.03022"
"107.90400","8.99205","0.03064"
"108.09600","9.00813","0.03013"
"108.28800","9.02415","0.03057"
"108.48000","9.04006","0.03092"
"108.67200","9.05620","0.03139"
"108.86400","9.07211","0.03058"
"109.05600","9.08813","0.03144"
"109.24800","9.10421","0.03120"
"109.44000","9.12012","0.03191"
"109.63200","9.13614","0.03193"
"109.82400","9.15216","0.03208"
"110.01600","9.16813","0.03250"
"110.20800","9.18415","0.03295"
"110.40000","9.20017","0.03307"
"110.59200","9.21608","0.03232"
"110.78400","9.23210","0.03364"
"110.97600","9.24813","0.03363"
"111.16800","9.26415","0.03409"
"111.36000","9.28011","0.03369"
"111.55200","9.29614","0.03422"
"111.74400","9.31216","0.03515"
"111.93600","9.32812","0.03516"
"112.12800","9.34415","0.03531"
"112.32000","9.36011","0.03581"
"112.51200","9.37613","0.03575"
"112.70400","9.39210","0.03613"
"112.89600","9.40818","0.03695"
"113.08800","9.42415","0.03654"
"113.28000","9.44011","0.03659"
"113.47200","9.45613","0.03830"
"113.66400","9.47210","0.03830"
"113.85600","9.48812","0.03873"
"114.04800","9.50408","0.03901"
"114.24000","9.52011","0.03961"
"114.43200","9.53613","0.03972"
"114.62400","9.55222","0.04057"
"114.81600","9.56812","0.04040"
"115.00800","9.58414","0.04106"
"115.20000","9.60017","0.04143"
"115.39200","9.61607","0.04139"
"115.58400","9.63215","0.04194"
"115.77600","9.64812","0.04301"
"115.96800","9.66408","0.04319"
"116.16000","9.68017","0.04379"
"116.35200","9.69607","0.04445"
"116.54400","9.71209","0.04461"
"116.73600","9.72818","0.04493"
"116.92800","9.74408","0.04572"
"117.12000","9.76010","0.04559"
"117.31200","9.77619","0.04617"
"117.50400","9.79215","0.04667"
"117.69600","9.80811","0.04707"
"117.88800","9.82420","0.04754"
"118.08000","9.84010","0.04765"
"118.27200","9.85612","0.04833"
"118.46400","9.87215","0.04887"
"118.65600","9.88811","0.04899"
"118.84800","9.90414","0.04913"
"119.04000","9.92016","0.04998"
"119.23200","9.93606","0.05019"
"119.42400","9.95215","0.05130"
"119.61600","9.96817","0.05088"
"119.80800","9.98413","0.05120"
"120.00000","10.00016","0.05137"
"120.19200","10.01612","0.05203"
"120.38400","10.03209","0.05226"
"120.57600","10.04817","0.05204"
"120.76800","10.06407","0.05317"
"120.96000","10.08010","0.05267"
"121.15200","10.09612","0.05291"
"121.34400","10.11208","0.05333"
"121.53600","10.12811","0.05382"
"121.72800","10.14419","0.05401"
"121.92000","10.16010","0.05435"
"122.11200","10.17612","0.05480"
"122.30400","10.19208","0.05551"
"122.49600","10.20811","0.05575"
"122.68800","10.22419","0.05550"
"122.88000","10.24009","0.05627"
"123.07200","10.25612","0.05696"
"123.26400","10.27214","0.05685"
"123.45600","10.28810","0.05690"
"123.64800","10.30419","0.05694"
"123.84000","10.32015","0.05727"
"124.03200","10.33612","0.05799"
"124.22400","10.35220","0.05821"
"124.41600","10.36810","0.05822"
"124.60800","10.38413","0.05847"
"124.80000","10.40009","0.05901"
"124.99200","10.41611","0.05936"
"125.18400","10.43214","0.05917"
"125.37600","10.44816","0.05981"
"125.56800","10.46413","0.06009"
"125.76000","10.48015","0.06041"
"125.95200","10.49617","0.06078"
"126.14400","10.51208","0.06062"
"126.33600","10.52810","0.06085"
"126.52800","10.54418","0.06144"
"126.72000","10.56003","0.06174"
"126.91200","10.57617","0.06176"
"127.10400","10.59213","0.06274"
"127.29600","10.60810","0.06261"
"127.48800","10.62412","0.06294"
"127.68000","10.64015","0.06393"
"127.87200","10.65611","0.06450"
"128.06400","10.67219","0.06437"
"128.25600","10.68810","0.06503"
"128.44800","10.70412","0.06563"
"128.64000","10.72014","0.06541"
"128.83200","10.73611","0.06679"
"129.02400","10.75213","0.06663"
"129.21600","10.76816","0.06752"
"129.40800","10.78412","0.06786"
"129.60000","10.80014","0.06814"
"129.79200","10.81611","0.06928"
"129.98400","10.83213","0.06923"
"130.17600","10.84815","0.06944"
"130.36800","10.86412","0.06941"
"130.56000","10.88014","0.06998"
"130.75200","10.89616","0.07110"
"130.94400","10.91213","0.07172"
"131.13600","10.92815","0.07212"
"131.33000","10.94435","0.07240"
"131.52200","10.96026","0.07345"
"131.71400","10.97634","0.07369"
"131.90600","10.99231","0.07406"
"132.09800","11.00827","0.07457"
"132.29000","11.02429","0.07541"
"132.48200","11.04032","0.07548"
"132.67400","11.05634","0.07680"
"132.86600","11.07230","0.07657"
"133.05800","11.08827","0.07722"
"133.25000","11.10429","0.07754"
"133.44200","11.12032","0.07814"
"133.63400","11.13628","0.07916"
"133.82600","11.15224","0.07973"
"134.01800","11.16833","0.08030"
"134.21000","11.18423","0.08081"
"134.40200","11.20031","0.08103"
"134.59400","11.21634","0.08195"
"134.78600","11.23230","0.08236"
"134.97800","11.24826","0.08297"
"135.17000","11.26429","0.08346"
"135.36200","11.28025","0.08449"
"135.55400","11.29628","0.08506"
"135.74600","11.31230","0.08550"
"135.93800","11.32826","0.08620"
"136.13000","11.34429","0.08697"
"136.32200","11.36025","0.08676"
"136.51400","11.37633","0.08743"
"136.70600","11.39230","0.08775"
"136.89800","11.40826","0.08761"
"137.09000","11.42434","0.08865"
"137.28200","11.44025","0.08860"
"137.47400","11.45621","0.09033"
"137.66600","11.47236","0.08991"
"137.85800","11.48826","0.09105"
"138.05000","11.50428","0.09169"
"138.24200","11.52031","0.09208"
"138.43400","11.53627","0.09254"
"138.62600","11.55229","0.09317"
"138.81800","11.56832","0.09391"
"139.01000","11.58428","0.09417"
"139.20200","11.60031","0.09493"
"139.39400","11.61633","0.09544"
"139.58600","11.63229","0.09559"
"139.77800","11.64832","0.09585"
"139.97000","11.66434","0.09640"
"140.16200","11.68024","0.09700"
"140.35400","11.69633","0.09750"
"140.54600","11.71235","0.09772"
"140.73800","11.72826","0.09839"
"140.93000","11.74434","0.09878"
"141.12200","11.76030","0.09894"
"141.31400","11.77627","0.09954"
"141.50600","11.79229","0.09957"
"141.69800","11.80825","0.09985"
"141.89000","11.82422","0.10049"
"142.08200","11.84036","0.10091"
"142.27400","11.85626","0.10151"
"142.46600","11.87229","0.10188"
"142.65800","11.88831","0.10271"
"142.85000","11.90428","0.10274"
"143.04200","11.92036","0.10327"
"143.23400","11.93632","0.10326"
"143.42600","11.95229","0.10313"
"143.61800","11.96831","0.10381"
"143.81000","11.98427","0.10358"
"144.00200","12.00030","0.10389"
"144.19400","12.01626","0.10398"
"144.38600","12.03229","0.10414"
"144.57800","12.04831","0.10458"
"144.77000","12.06427","0.10442"
"144.96200","12.08030","0.10484"
"145.15400","12.09632","0.10505"
"145.34600","12.11234","0.10530"
"145.53800","12.12831","0.10572"
"145.73000","12.14439","0.10603"
"145.92200","12.16023","0.10644"
"146.11400","12.17626","0.10677"
"146.30600","12.19228","0.10685"
"146.49800","12.20825","0.10706"
"146.69000","12.22427","0.10742"
"146.88200","12.24029","0.10782"
"147.07400","12.25626","0.10794"
"147.26600","12.27234","0.10882"
"147.45800","12.28836","0.10904"
"147.65000","12.30427","0.10955"
"147.84200","12.32035","0.10999"
"148.03400","12.33631","0.11045"
"148.22600","12.35222","0.11057"
"148.41800","12.36836","0.11102"
"148.61000","12.38433","0.11196"
"148.80200","12.40023","0.11212"
"148.99400","12.41637","0.11232"
"149.18600","12.43234","0.11251"
"149.37800","12.44824","0.11220"
"149.57000","12.46432","0.11309"
"149.76200","12.48029","0.11324"
"149.95400","12.49625","0.11370"
"150.14600","12.51234","0.11358"
"150.33800","12.52824","0.11431"
"150.53000","12.54426","0.11502"
"150.72200","12.56035","0.11479"
"150.91400","12.57625","0.11534"
"151.10600","12.59233","0.11542"
"151.29800","12.60830","0.11686"
"151.49000","12.62426","0.11747"
"151.68200","12.64028","0.11810"
"151.87400","12.65631","0.11791"
"152.06600","12.67227","0.11855"
"152.25800","12.68830","0.11797"
"152.45200","12.70444","0.11841"
"152.64400","12.72046","0.11842"
"152.83600","12.73649","0.11901"
"153.02800","12.75245","0.12045"
"153.22000","12.76847","0.12132"
"153.41200","12.78450","0.11832"
"153.60400","12.80046","0.11799"
"153.79600","12.81648","0.11865"
"153.98800","12.83245","0.11860"
"154.18000","12.84847","0.11978"
"154.37200","12.86449","0.12056"
"154.56400","12.88040","0.12086"
"154.75600","12.89642","0.12153"
"154.94800","12.91245","0.12163"
"155.14000","12.92841","0.12232"
"155.33200","12.94443","0.12269"
"155.52400","12.96046","0.12337"
"155.71600","12.97642","0.12303"
"155.90800","12.99250","0.12338"
"156.10000","13.00853","0.11333"
"156.29200","13.02443","0.11313"
"156.48400","13.04052","0.11297"
"156.67600","13.05642","0.11351"
"156.86800","13.07238","0.11357"
"157.06000","13.08853","0.11451"
"157.25200","13.10449","0.11454"
"157.44400","13.12045","0.11582"
"157.63600","13.13648","0.11615"
"157.82800","13.15244","0.11623"
"158.02000","13.16847","0.11750"
"158.21200","13.18449","0.11786"
"158.40400","13.20045","0.11860"
"158.59600","13.21648","0.11908"
"158.78800","13.23244","0.11945"
"158.98000","13.24840","0.12023"
"159.17200","13.26443","0.12037"
"159.36400","13.28045","0.12165"
"159.55600","13.29635","0.12214"
"159.74800","13.31250","0.12320"
"159.94000","13.32846","0.12328"
"160.13200","13.34443","0.12383"
"160.32400","13.36051","0.12483"
"160.51600","13.37647","0.12578"
"160.70800","13.39244","0.12620"
"160.90000","13.40846","0.12749"
"161.09200","13.42442","0.12811"
"161.28400","13.44045","0.12924"
"161.47600","13.45647","0.12975"
"161.66800","13.47244","0.13093"
"161.86000","13.48846","0.13125"
"162.05200","13.50448","0.13256"
"162.24400","13.52045","0.13317"
"162.43600","13.53653","0.13379"
"162.62800","13.55249","0.13525"
"162.82000","13.56846","0.13598"
"163.01200","13.58448","0.13758"
"163.20400","13.60044","0.13824"
"163.39600","13.61641","0.13940"
"163.58800","13.63249","0.14000"
"163.78000","13.64846","0.13378"
"163.97200","13.66442","0.13428"
"164.16400","13.68050","0.13429"
"164.35600","13.69641","0.13474"
"164.54800","13.71249","0.13619"
"164.74000","13.72845","0.13583"
"164.93200","13.74442","0.13691"
"165.12400","13.76044","0.13764"
"165.31600","13.77640","0.13873"
"165.50800","13.79249","0.13921"
"165.70000","13.80845","0.14042"
"165.89200","13.82442","0.14096"
"166.08400","13.84050","0.14251"
"166.27600","13.85646","0.14411"
"166.46800","13.87249","0.14473"
"166.66000","13.88851","0.14629"
"166.85200","13.90447","0.14697"
"167.04400","13.92044","0.14825"
"167.23600","13.93652","0.14919"
"167.42800","13.95249","0.15007"
"167.62000","13.96839","0.15080"
"167.81200","13.98447","0.15136"
"168.00400","14.00050","0.15282"
"168.19600","14.01640","0.15334"
"168.38800","14.03254","0.15422"
"168.58000","14.04845","0.15515"
"168.77200","14.06447","0.15664"
"168.96400","14.08049","0.15698"
"169.15600","14.09646","0.15868"
"169.34800","14.11242","0.15932"
"169.54000","14.12857","0.15982"
"169.73200","14.14435","0.15898"
"169.92400","14.16049","0.16092"
"170.11600","14.17646","0.16115"
"170.30800","14.19242","0.16187"
"170.50000","14.20844","0.16238"
"170.69200","14.22447","0.16292"
"170.88400","14.24037","0.16308"
"171.07600","14.25651","0.16405"
"171.26800","14.27248","0.16417"
"171.46000","14.28844","0.16493"
"171.65200","14.30447","0.16579"
"171.84400","14.32043","0.16655"
"172.03600","14.33645","0.16679"
"172.22800","14.35248","0.16751"
"172.42000","14.36844","0.16812"
"172.61200","14.38441","0.16867"
"172.80400","14.40049","0.16913"
"172.99600","14.41645","0.17007"
"173.18800","14.43248","0.17163"
"173.38000","14.44850","0.17191"
"173.57200","14.46446","0.17258"
"173.76400","14.48049","0.17352"
"173.95600","14.49645","0.17433"
"174.14800","14.51241","0.17454"
"174.34000","14.52850","0.17554"
"174.53200","14.54446","0.17549"
"174.72400","14.56048","0.17674"
"174.91600","14.57645","0.17723"
"175.10800","14.59241","0.17812"
"175.30000","14.60850","0.17871"
"175.49200","14.62446","0.17997"
"175.68400","14.64042","0.18044"
"175.87600","14.65651","0.18077"
"176.06800","14.67241","0.18191"
"176.26000","14.68844","0.18260"
"176.45200","14.70446","0.18241"
"176.64400","14.72042","0.18356"
"176.83600","14.73645","0.18498"
"177.02800","14.75247","0.18570"
"177.22000","14.76843","0.18667"
"177.41200","14.78446","0.18726"
"177.60400","14.80048","0.18863"
"177.79600","14.81644","0.18952"
"177.98800","14.83247","0.19009"
"178.18000","14.84849","0.19093"
"178.37200","14.86434","0.19140"
"178.56400","14.88054","0.19204"
"178.75600","14.89644","0.19278"
"178.94800","14.91241","0.19319"
"179.14000","14.92849","0.19497"
"179.33200","14.94445","0.19516"
"179.52400","14.96048","0.19619"
"179.71600","14.97644","0.19749"
"179.90800","14.99246","0.19827"
"180.10000","15.00849","0.19866"
"180.29200","15.02451","0.20014"
"180.48400","15.04042","0.20051"
"180.67600","15.05644","0.20180"
"180.86800","15.07246","0.20252"
"181.06000","15.08843","0.20315"
"181.25200","15.10445","0.20506"
"181.44400","15.12053","0.20602"
"181.63600","15.13644","0.20721"
"181.82800","15.15246","0.20788"
"182.02000","15.16849","0.20867"
"182.21200","15.18445","0.20945"
"182.40400","15.20047","0.21016"
"182.59600","15.21650","0.21076"
"182.78800","15.23246","0.21078"
"182.98000","15.24848","0.21132"
"183.17200","15.26445","0.21157"
"183.36400","15.28047","0.21169"
"183.55600","15.29644","0.21254"
"183.74800","15.31240","0.21271"
"183.94000","15.32854","0.21286"
"184.13200","15.34445","0.21336"
"184.32400","15.36047","0.21366"
"184.51600","15.37643","0.21394"
"184.70800","15.39240","0.21439"
"184.90000","15.40842","0.21468"
"185.09200","15.42444","0.21549"
"185.28400","15.44041","0.21549"
"185.47600","15.45649","0.21592"
"185.66800","15.47251","0.21656"
"185.86000","15.48848","0.21685"
"186.05200","15.50444","0.21717"
"186.24400","15.52047","0.21803"
"186.43600","15.53643","0.21802"
"186.62800","15.55245","0.21883"
"186.82000","15.56848","0.21965"
"187.01200","15.58438","0.21972"
"187.20400","15.60046","0.22053"
"187.39600","15.61649","0.22152"
"187.58800","15.63245","0.22185"
"187.78000","15.64847","0.22283"
"187.97200","15.66444","0.22317"
"188.16400","15.68046","0.22460"
"188.35600","15.69649","0.22527"
"188.54800","15.71245","0.22588"
"188.74000","15.72847","0.22723"
"188.93200","15.74450","0.22744"
"189.12400","15.76040","0.22846"
"189.31600","15.77649","0.22933"
"189.50800","15.79245","0.23019"
"189.70000","15.80841","0.23111"
"189.89200","15.82450","0.23231"
"190.08400","15.84046","0.23287"
"190.27600","15.85642","0.23355"
"190.46800","15.87251","0.23361"
"190.66000","15.88841","0.23424"
"190.85200","15.90449","0.23507"
"191.04400","15.92046","0.23560"
"191.23600","15.93642","0.23668"
"191.42800","15.95251","0.23702"
"191.62000","15.96853","0.23754"
"191.81200","15.98437","0.23635"
"192.00400","16.00051","0.23805"
"192.19600","16.01648","0.23901"
"192.38800","16.03238","0.23978"
"192.58000","16.04847","0.24161"
"192.77200","16.06449","0.24236"
"192.96400","16.08039","0.24338"
"193.15600","16.09648","0.24495"
"193.34800","16.11238","0.24570"
"193.54000","16.12847","0.24663"
"193.73200","16.14449","0.24783"
"193.92400","16.16045","0.24830"
"194.11600","16.17648","0.24928"
"194.30800","16.19250","0.24955"
"194.50000","16.20846","0.25052"
"194.69200","16.22449","0.25121"
"194.88400","16.24051","0.25238"
"195.07600","16.25647","0.25371"
"195.26800","16.27244","0.25487"
"195.46000","16.28846","0.25575"
"195.65200","16.30449","0.25661"
"195.84400","16.32045","0.25718"
"196.03600","16.33647","0.25808"
"196.22800","16.35244","0.25960"
"196.42000","16.36846","0.26060"
"196.61200","16.38448","0.26103"
"196.80400","16.40051","0.26216"
"196.99600","16.41647","0.25646"
"197.18800","16.43237","0.24592"
"197.38000","16.44852","0.12399"
"197.57200","16.46442","0.11401"
"197.76400","16.48039","0.11390"
"197.95600","16.49653","0.11368"
"198.14800","16.51243","0.11341"
"198.34000","16.52846","0.11679"
"198.53200","16.54448","0.11600"
"198.72400","16.56044","0.11933"
"198.91600","16.57647","0.11831"
"199.10800","16.59249","0.12196"
"199.30000","16.60840","0.11962"
"199.49200","16.62454","0.12506"
"199.68400","16.64044","0.12181"
"199.87600","16.65641","0.12794"
"200.06800","16.67249","0.12597"
"200.26000","16.68846","0.13288"
"200.45200","16.70442","0.13120"
"200.64400","16.72050","0.13741"
"200.83600","16.73652","0.13234"
"201.02800","16.75237","0.13861"
"201.22000","16.76851","0.13891"
"201.41200","16.78448","0.14308"
"201.60400","16.80038","0.14604"
"201.79600","16.81652","0.14748"
"201.98800","16.83243","0.14890"
"202.18000","16.84845","0.15097"
"202.37200","16.86448","0.15159"
"202.56400","16.88044","0.15179"
"202.75600","16.89646","0.15501"
"202.94800","16.91249","0.15430"
"203.14000","16.92839","0.15681"
"203.33200","16.94447","0.15701"
"203.52400","16.96050","0.15965"
"203.71600","16.97640","0.15867"
"203.90800","16.99248","0.16257"
"204.10000","17.00845","0.16158"
"204.29200","17.02441","0.16362"
"204.48400","17.04049","0.16313"
"204.67600","17.05646","0.16540"
"204.86800","17.07248","0.16433"
"205.06000","17.08845","0.16710"
"205.25200","17.10447","0.16593"
"205.44400","17.12049","0.04420"
"205.63600","17.13646","0.04831"
"205.82800","17.15248","0.04074"
"206.02000","17.16850","0.04650"
"206.21200","17.18441","0.04536"
"206.40400","17.20043","0.04737"
"206.59600","17.21651","0.04827"
"206.78800","17.23242","0.04827"
"206.98000","17.24850","0.04885"
"207.17200","17.26447","0.05032"
"207.36400","17.28043","0.04900"
"207.55600","17.29645","0.05158"
"207.74800","17.31254","0.05071"
"207.94000","17.32844","0.05184"
"208.13200","17.34452","0.05323"
"208.32400","17.36049","0.05229"
"208.51600","17.37639","0.05348"
"208.70800","17.39254","0.05422"
"208.90000","17.40844","0.05333"
"209.09200","17.42447","0.05568"
"209.28400","17.44055","0.05444"
"209.47600","17.45645","0.05567"
"209.66800","17.47241","0.05621"
"209.86000","17.48856","0.05669"
"210.05200","17.50440","0.05800"
"210.24400","17.52043","0.05759"
"210.43600","17.53651","0.05860"
"210.62800","17.55241","0.05959"
"210.82000","17.56844","0.05845"
"211.01200","17.58452","0.06034"
"211.20400","17.60042","0.05962"
"211.39600","17.61651","0.06050"
"211.58800","17.63247","0.06127"
"211.78000","17.64843","0.06036"
"211.97200","17.66446","0.06203"
"212.16400","17.68048","0.06139"
"212.35600","17.69645","0.06202"
"212.54800","17.71247","0.06326"
"212.74000","17.72843","0.06192"
"212.93200","17.74446","0.06434"
"213.12400","17.76054","0.06403"
"213.31600","17.77645","0.06529"
"213.50800","17.79247","0.06662"
"213.70000","17.80849","0.06613"
"213.89200","17.82446","0.06855"
"214.08400","17.84048","0.06726"
"214.27600","17.85644","0.06865"
"214.46800","17.87241","0.06987"
"214.66000","17.88843","0.06923"
"214.85200","17.90446","0.07185"
"215.04400","17.92042","0.07100"
"215.23600","17.93650","0.07289"
"215.42800","17.95240","0.07271"
"215.62000","17.96843","0.07304"
"215.81200","17.98451","0.07464"
"216.00400","18.00042","0.07379"
"216.19600","18.01650","0.07480"
"216.38800","18.03246","0.07556"
"216.58000","18.04843","0.07533"
"216.77200","18.06451","0.07736"
"216.96400","18.08042","0.07626"
"217.15600","18.09644","0.07935"
"217.34800","18.11246","0.07849"
"217.54000","18.12843","0.07918"
"217.73200","18.14445","0.08144"
"217.92400","18.16053","0.07977"
"218.11600","18.17644","0.08246"
"218.30800","18.19246","0.08199"
"218.50000","18.20848","0.08344"
"218.69200","18.22445","0.08459"
"218.88400","18.24047","0.08395"
"219.07600","18.25649","0.08586"
"219.26800","18.27240","0.08564"
"219.46000","18.28848","0.08702"
"219.65200","18.30445","0.08727"
"219.84400","18.32047","0.08791"
"220.03600","18.33655","0.08953"
"220.22800","18.35246","0.08875"
"220.42000","18.36842","0.09099"
"220.61200","18.38450","0.08993"
"220.80400","18.40041","0.09167"
"220.99600","18.41643","0.09145"
"221.18800","18.43251","0.09180"
"221.38000","18.44836","0.09358"
"221.57200","18.46450","0.09299"
"221.76400","18.48053","0.09418"
"221.95600","18.49643","0.09409"
"222.14800","18.51251","0.09488"
"222.34000","18.52848","0.09558"
"222.53200","18.54438","0.09584"
"222.72400","18.56046","0.09727"
"222.91600","18.57649","0.09640"
"223.10800","18.59245","0.09801"
"223.30000","18.60847","0.09774"
"223.49200","18.62438","0.09849"
"223.68400","18.64046","0.09882"
"223.87600","18.65649","0.09867"
"224.06800","18.67245","0.09949"
"224.26000","18.68847","0.09884"
"224.45200","18.70450","0.09984"
"224.64400","18.72046","0.10023"
"224.83600","18.73648","0.10051"
"225.02800","18.75245","0.10093"
"225.22000","18.76847","0.10056"
"225.41200","18.78444","0.10169"
"225.60400","18.80040","0.10139"
"225.79600","18.81643","0.10203"
"225.98800","18.83251","0.10193"
"226.18000","18.84841","0.10248"
"226.37200","18.86449","0.10289"
"226.56400","18.88052","0.10284"
"226.75600","18.89642","0.10335"
"226.94800","18.91251","0.10317"
"227.14000","18.92847","0.10415"
"227.33200","18.94443","0.10365"
"227.52400","18.96052","0.10451"
"227.71600","18.97642","0.10438"
"227.90800","18.99244","0.10478"
"228.10000","19.00847","0.10507"
"228.29200","19.02443","0.10501"
"228.48400","19.04046","0.10564"
"228.67600","19.05648","0.10548"
"228.86800","19.07244","0.10500"
"229.06000","19.08847","0.10456"
"229.25200","19.10449","0.10521"
"229.44400","19.12039","0.10550"
"229.63600","19.13648","0.10566"
"229.82800","19.15250","0.10588"
"230.02000","19.16841","0.10575"
"230.21200","19.18455","0.10633"
"230.40400","19.20045","0.10645"
"230.59600","19.21642","0.10696"
"230.78800","19.23250","0.10705"
"230.98000","19.24846","0.10780"
"231.17200","19.26449","0.10805"
"231.36400","19.28045","0.10773"
"231.55600","19.29642","0.10853"
"231.74800","19.31244","0.10853"
"231.94000","19.32846","0.10912"
"232.13200","19.34443","0.10891"
"232.32400","19.36051","0.10956"
"232.51600","19.37647","0.10918"
"232.70800","19.39250","0.10990"
"232.90000","19.40852","0.11049"
"233.09200","19.42454","0.11067"
"233.28400","19.44039","0.11169"
"233.47600","19.45647","0.11187"
"233.66800","19.47249","0.11321"
"233.86000","19.48846","0.11326"
"234.05200","19.50442","0.11447"
"234.24400","19.52044","0.11533"
"234.43600","19.53647","0.11573"
"234.62800","19.55249","0.11695"
"234.82000","19.56846","0.11709"
"235.01200","19.58454","0.11871"
"235.20400","19.60044","0.11847"
"235.39600","19.61641","0.12028"
"235.58800","19.63249","0.11999"
"235.78000","19.64839","0.12210"
"235.97200","19.66442","0.12157"
"236.16400","19.68050","0.12244"
"236.35600","19.69641","0.12321"
"236.54800","19.71243","0.12434"
"236.74000","19.72845","0.12485"
"236.93200","19.74448","0.12468"
"237.12400","19.76050","0.12641"
"237.31600","19.77653","0.12641"
"237.50800","19.79243","0.12783"
"237.70000","19.80851","0.12840"
"237.89200","19.82447","0.13046"
"238.08400","19.84038","0.13095"
"238.27600","19.85652","0.13316"
"238.46800","19.87243","0.13446"
"238.66000","19.88839","0.13670"
"238.85200","19.90453","0.13751"
"239.04400","19.92050","0.13902"
"239.23600","19.93646","0.14024"
"239.42800","19.95249","0.14129"
"239.62000","19.96845","0.14251"
"239.81200","19.98447","0.14328"
"240.00400","20.00050","0.14461"
"240.19600","20.01646","0.14574"
"240.38800","20.03248","0.14702"
"240.58000","20.04845","0.14706"
"240.77200","20.06441","0.14902"
"240.96400","20.08049","0.14973"
"241.15600","20.09646","0.15100"
"241.34800","20.11236","0.15127"
"241.54000","20.12851","0.15251"
"241.73200","20.14447","0.15294"
"241.92400","20.16043","0.15506"
"242.11600","20.17645","0.15519"
"242.30800","20.19242","0.15673"
"242.50000","20.20844","0.15725"
"242.69200","20.22447","0.15772"
"242.88400","20.24043","0.15903"
"243.07600","20.25645","0.15943"
"243.26800","20.27254","0.16114"
"243.46000","20.28838","0.16111"
"243.65200","20.30453","0.16232"
"243.84400","20.32049","0.16238"
"244.03600","20.33639","0.16423"
"244.22800","20.35248","0.16384"
"244.42000","20.36844","0.16501"
"244.61200","20.38441","0.16495"
"244.80400","20.40049","0.16619"
"244.99600","20.41645","0.16655"
"245.18800","20.43242","0.16737"
"245.38000","20.44850","0.16781"
"245.57200","20.46446","0.16872"
"245.76400","20.48048","0.16967"
"245.95600","20.49645","0.17007"
"246.14800","20.51247","0.16998"
"246.34000","20.52844","0.17167"
"246.53200","20.54446","0.17169"
"246.72400","20.56042","0.17320"
"246.91600","20.57645","0.17421"
"247.10800","20.59241","0.17500"
"247.30000","20.60844","0.17564"
"247.49200","20.62446","0.17708"
"247.68400","20.64048","0.17726"
"247.87600","20.65645","0.17866"
"248.06800","20.67247","0.17858"
"248.26000","20.68849","0.18031"
"248.45200","20.70452","0.18069"
"248.64400","20.72048","0.18156"
"248.83600","20.73644","0.18220"
"249.02800","20.75253","0.18358"
"249.22000","20.76843","0.18483"
"249.41200","20.78440","0.18542"
"249.60400","20.80054","0.18606"
"249.79600","20.81644","0.18741"
"249.98800","20.83247","0.18734"
"250.18000","20.84855","0.18857"
"250.37200","20.86445","0.18909"
"250.56400","20.88048","0.19034"
"250.75600","20.89650","0.19126"
"250.94800","20.91240","0.19270"
"251.14000","20.92843","0.19294"
"251.33200","20.94445","0.19413"
"251.52400","20.96042","0.19497"
"251.71600","20.97650","0.19573"
"251.90800","20.99246","0.19652"
"252.10000","21.00843","0.19715"
"252.29200","21.02451","0.19814"
"252.48400","21.04048","0.19967"
"252.67600","21.05644","0.19938"
"252.86800","21.07246","0.20074"
"253.06000","21.08842","0.20166"
"253.25200","21.10439","0.20259"
"253.44400","21.12041","0.20319"
"253.63600","21.13638","0.20487"
"253.82800","21.15240","0.20503"
"254.02000","21.16849","0.20578"
"254.21200","21.18439","0.20545"
"254.40400","21.20047","0.20650"
"254.59600","21.21650","0.20763"
"254.78800","21.23246","0.20846"
"254.98000","21.24848","0.20906"
"255.17200","21.26451","0.20955"
"255.36400","21.28047","0.21012"
"255.55600","21.29643","0.21051"
"255.74800","21.31246","0.21083"
"255.94000","21.32848","0.21147"
"256.13200","21.34451","0.21179"
"256.32400","21.36047","0.21225"
"256.51600","21.37643","0.21257"
"256.70800","21.39245","0.21295"
"256.90000","21.40842","0.21335"
"257.09200","21.42450","0.21405"
"257.28400","21.44047","0.21431"
"257.47600","21.45643","0.21497"
"257.66800","21.47251","0.21593"
"257.86000","21.48836","0.21654"
"258.05200","21.50444","0.21707"
"258.24400","21.52046","0.21738"
"258.43600","21.53637","0.21770"
"258.62800","21.55251","0.21806"
"258.82000","21.56848","0.21834"
"259.01200","21.58444","0.21893"
"259.20400","21.60046","0.21969"
"259.39600","21.61649","0.22008"
"259.58800","21.63239","0.22087"
"259.78000","21.64847","0.22161"
"259.97200","21.66444","0.22202"
"260.16400","21.68040","0.22270"
"260.35600","21.69654","0.22352"
"260.54800","21.71251","0.22362"
"260.74000","21.72841","0.22490"
"260.93200","21.74450","0.22578"
"261.12400","21.76046","0.22732"
"261.31600","21.77642","0.22697"
"261.50800","21.79251","0.22806"
"261.70000","21.80841","0.22928"
"261.89200","21.82444","0.22951"
"262.08400","21.84052","0.23025"
"262.27600","21.85642","0.23122"
"262.46800","21.87245","0.23134"
"262.66000","21.88853","0.23292"
"262.85200","21.90443","0.23341"
"263.04400","21.92052","0.23348"
"263.23600","21.93648","0.23432"
"263.42800","21.95244","0.23540"
"263.62000","21.96841","0.23623"
"263.81200","21.98443","0.23607"
"264.00400","22.00039","0.23776"
"264.19600","22.01648","0.23773"
"264.38800","22.03244","0.23866"
"264.58000","22.04847","0.23890"
"264.77200","22.06449","0.23966"
"264.96400","22.08046","0.24089"
"265.15600","22.09648","0.24181"
"265.34800","22.11244","0.24272"
"265.54000","22.12846","0.24303"
"265.73200","22.14449","0.24415"
"265.92400","22.16045","0.24475"
"266.11600","22.17648","0.24566"
"266.30800","22.19244","0.24609"
"266.50000","22.20840","0.24661"
"266.69200","22.22443","0.24741"
"266.88400","22.24045","0.24851"
"267.07600","22.25641","0.24887"
"267.26800","22.27244","0.24986"
"267.46000","22.28852","0.24974"
"267.65200","22.30443","0.25068"
"267.84400","22.32051","0.25056"
"268.03600","22.33647","0.25182"
"268.22800","22.35243","0.25191"
"268.42000","22.36852","0.25280"
"268.61200","22.38442","0.25293"
"268.80400","22.40039","0.25372"
"268.99600","22.41647","0.25363"
"269.18800","22.43243","0.25365"
"269.38000","22.44846","0.25441"
"269.57200","22.46448","0.25347"
"269.76400","22.48045","0.25432"
"269.95600","22.49647","0.25401"
"270.14800","22.51249","0.25428"
"270.34000","22.52840","0.25370"
"270.53200","22.54448","0.25505"
"270.72400","22.56050","0.25491"
"270.91600","22.57635","0.25579"
"271.10800","22.59249","0.25592"
"271.30000","22.60851","0.25620"
"271.49200","22.62436","0.25726"
"271.68400","22.64056","0.25677"
"271.87600","22.65647","0.25778"
"272.06800","22.67243","0.25769"
"272.26000","22.68851","0.25859"
"272.45200","22.70442","0.25951"
"272.64400","22.72050","0.25959"
"272.83600","22.73646","0.26070"
"273.02800","22.75243","0.26092"
"273.22000","22.76845","0.26178"
"273.41200","22.78454","0.26200"
"273.60400","22.80038","0.26235"
"273.79600","22.81646","0.26254"
"273.98800","22.83249","0.26301"
"274.18000","22.84839","0.26281"
"274.37200","22.86447","0.26366"
"274.56400","22.88050","0.26354"
"274.75600","22.89640","0.26377"
"274.94800","22.91243","0.26415"
"275.14000","22.92845","0.26390"
"275.33200","22.94447","0.26417"
"275.52400","22.96049","0.26369"
"275.71600","22.97646","0.26430"
"275.90800","22.99249","0.26468"
"276.10000","23.00851","0.26503"
"276.29200","23.02441","0.26490"
"276.48400","23.04049","0.26521"
"276.67600","23.05646","0.26510"
"276.86800","23.07242","0.26555"
"277.06000","23.08845","0.26541"
"277.25200","23.10441","0.26552"
"277.44400","23.12049","0.26549"
"277.63600","23.13651","0.26547"
"277.82800","23.15242","0.26529"
"278.02000","23.16850","0.26498"
"278.21200","23.18447","0.26497"
"278.40400","23.20043","0.26403"
"278.59600","23.21651","0.00562"
"278.78800","23.23248","0.00213"
"278.98000","23.24838","-0.00193"
"279.17200","23.26453","-0.00091"
"279.36400","23.28043","0.00133"
"279.55600","23.29639","0.00190"
"279.74800","23.31248","0.00272"
"279.94000","23.32850","0.00248"
"280.13200","23.34440","0.00215"
"280.32400","23.36043","0.00272"
"280.51600","23.37645","0.00267"
"280.70800","23.39248","0.00306"
"280.90000","23.40850","0.00273"
"281.09200","23.42440","0.00194"
"281.28400","23.44049","0.00252"
"281.47600","23.45651","0.00243"
"281.66800","23.47241","0.00215"
"281.82800","23.48581","0.00272"