File: Force_trajectories/161226_1/Specimen_RawData_3.csv
End date,"12/26/2016"
Specimen label,"10AT_64"
Maximum Load,"0.01466",N

Time,Extension,Load
(s),(mm),(N)
"0.00000","0.00000","-0.00008"
"0.09000","0.00305","0.00014"
"0.18000","0.01178","-0.00025"
"0.27000","0.02152","-0.00050"
"0.36000","0.03007","0.00021"
"0.45000","0.03785","-0.00020"
"0.54000","0.04526","-0.00032"
"0.63000","0.05273","-0.00050"
"0.72000","0.06015","-0.00053"
"0.81000","0.06768","-0.00010"
"0.90000","0.07522","-0.00008"
"0.99000","0.08275","-0.00007"
"1.08000","0.09028","-0.00015"
"1.17000","0.09770","0.00006"
"1.26000","0.10517","0.00032"
"1.35000","0.11264","0.00017"
"1.44000","0.12018","0.00033"
"1.53000","0.12771","0.00001"
"1.62000","0.13524","0.00025"
"1.71000","0.14272","-0.00015"
"1.80000","0.15013","0.00024"
"1.89000","0.15772","-0.00014"
"1.98000","0.16520","-0.00016"
"2.07000","0.17267","-0.00031"
"2.16000","0.18027","-0.00045"
"2.25000","0.18768","-0.00016"
"2.34000","0.19515","0.00051"
"2.43000","0.20269","0.00026"
"2.52000","0.21016","-0.00012"
"2.61000","0.21775","-0.00024"
"2.70000","0.22523","-0.00003"
"2.79000","0.23270","-0.00003"
"2.88000","0.24017","0.00010"
"2.97000","0.24765","-0.00001"
"3.06000","0.25518","-0.00038"
"3.15000","0.26272","0.00013"
"3.24000","0.27019","-0.00034"
"3.33000","0.27766","-0.00021"
"3.42000","0.28514","-0.00037"
"3.51000","0.29267","-0.00021"
"3.60000","0.30020","0.00000"
"3.69000","0.30768","-0.00004"
"3.78000","0.31521","-0.00041"
"3.87000","0.32274","-0.00022"
"3.96000","0.33016","-0.00084"
"4.05000","0.33769","-0.00033"
"4.14000","0.34522","-0.00059"
"4.23000","0.35270","0.00011"
"4.32000","0.36023","0.00026"
"4.41000","0.36765","-0.00046"
"4.50000","0.37512","-0.00055"
"4.59000","0.38265","-0.00044"
"4.68000","0.39025","-0.00022"
"4.77000","0.39772","-0.00077"
"4.86000","0.40519","-0.00041"
"4.95000","0.41267","-0.00086"
"5.04000","0.42020","0.00001"
"5.13000","0.42767","-0.00033"
"5.22000","0.43515","-0.00033"
"5.31000","0.44268","-0.00066"
"5.40000","0.45016","-0.00061"
"5.49000","0.45769","-0.00066"
"5.58000","0.46516","-0.00035"
"5.67000","0.47264","0.00006"
"5.76000","0.48023","-0.00065"
"5.85000","0.48770","-0.00050"
"5.94000","0.49524","-0.00088"
"6.03000","0.50271","-0.00020"
"6.12000","0.51018","-0.00042"
"6.21000","0.51766","-0.00026"
"6.30000","0.52519","-0.00069"
"6.39000","0.53266","-0.00051"
"6.48000","0.54020","-0.00047"
"6.57000","0.54767","-0.00052"
"6.66000","0.55515","-0.00059"
"6.75000","0.56274","-0.00042"
"6.84000","0.57021","-0.00043"
"6.93000","0.57769","-0.00036"
"7.02000","0.58522","-0.00078"
"7.11000","0.59269","-0.00059"
"7.20000","0.60017","-0.00063"
"7.29000","0.60764","-0.00054"
"7.38000","0.61523","-0.00011"
"7.47000","0.62277","-0.00022"
"7.56000","0.63018","-0.00039"
"7.65000","0.63772","-0.00041"
"7.74000","0.64519","-0.00067"
"7.83000","0.65260","-0.00045"
"7.92000","0.66026","-0.00034"
"8.01000","0.66773","-0.00028"
"8.10000","0.67520","-0.00016"
"8.19000","0.68274","-0.00019"
"8.28000","0.69021","-0.00033"
"8.37000","0.69768","-0.00032"
"8.46000","0.70516","-0.00085"
"8.55000","0.71275","-0.00019"
"8.64000","0.72022","-0.00068"
"8.73000","0.72770","-0.00053"
"8.82000","0.73517","-0.00058"
"8.91000","0.74265","-0.00060"
"9.00000","0.75018","-0.00060"
"9.09000","0.75771","-0.00029"
"9.18000","0.76525","-0.00030"
"9.27000","0.77266","0.00006"
"9.36000","0.78013","-0.00051"
"9.45000","0.78767","-0.00030"
"9.54000","0.79520","-0.00026"
"9.63000","0.80273","0.00005"
"9.72000","0.81021","-0.00060"
"9.81000","0.81768","-0.00014"
"9.90000","0.82516","-0.00059"
"9.99000","0.83263","-0.00041"
"10.08000","0.84022","-0.00053"
"10.17000","0.84770","-0.00016"
"10.26000","0.85523","-0.00047"
"10.35000","0.86276","-0.00063"
"10.44000","0.87012","-0.00046"
"10.53000","0.87765","-0.00039"
"10.62000","0.88524","-0.00041"
"10.71000","0.89266","-0.00045"
"10.80000","0.90025","-0.00001"
"10.89000","0.90766","-0.00040"
"10.98000","0.91508","-0.00065"
"11.07000","0.92267","-0.00010"
"11.16000","0.93021","-0.00049"
"11.25000","0.93768","-0.00073"
"11.34000","0.94527","-0.00060"
"11.43000","0.95269","-0.00049"
"11.52000","0.96022","0.00052"
"11.61000","0.96769","-0.00010"
"11.70000","0.97517","-0.00053"
"11.79000","0.98270","-0.00028"
"11.88000","0.99023","-0.00043"
"11.97000","0.99771","-0.00002"
"12.06000","1.00518","-0.00032"
"12.15000","1.01272","-0.00067"
"12.24000","1.02025","-0.00031"
"12.33000","1.02772","-0.00031"
"12.42000","1.03520","0.00005"
"12.51000","1.04273","-0.00030"
"12.60000","1.05020","-0.00061"
"12.69000","1.05774","-0.00026"
"12.78000","1.06527","-0.00048"
"12.87000","1.07268","-0.00066"
"12.96000","1.08016","-0.00028"
"13.05000","1.08769","-0.00030"
"13.14000","1.09516","0.00043"
"13.23000","1.10264","-0.00051"
"13.32000","1.11023","0.00012"
"13.41000","1.11771","0.00016"
"13.50000","1.12518","-0.00015"
"13.59000","1.13265","0.00008"
"13.68000","1.14019","-0.00019"
"13.77000","1.14772","0.00006"
"13.86000","1.15519","-0.00034"
"13.95000","1.16273","0.00007"
"14.04000","1.17026","-0.00014"
"14.13000","1.17767","0.00031"
"14.22000","1.18515","-0.00010"
"14.31000","1.19268","0.00004"
"14.40000","1.20022","-0.00008"
"14.49000","1.20775","-0.00019"
"14.58000","1.21522","-0.00020"
"14.67000","1.22270","-0.00007"
"14.76000","1.23017","0.00002"
"14.85000","1.23764","0.00003"
"14.94000","1.24524","0.00000"
"15.03000","1.25271","-0.00007"
"15.12000","1.26018","-0.00023"
"15.21000","1.26766","-0.00061"
"15.30000","1.27507","0.00020"
"15.39000","1.28266","0.00012"
"15.48000","1.29020","-0.00054"
"15.57000","1.29767","-0.00003"
"15.66000","1.30521","0.00006"
"15.75000","1.31268","-0.00020"
"15.84000","1.32009","-0.00032"
"15.93000","1.32769","-0.00010"
"16.02000","1.33522","-0.00034"
"16.11000","1.34269","-0.00022"
"16.20000","1.35023","0.00012"
"16.29000","1.35770","-0.00027"
"16.38000","1.36517","0.00010"
"16.47000","1.37271","-0.00038"
"16.56000","1.38024","-0.00015"
"16.65000","1.38771","0.00010"
"16.74000","1.39519","-0.00031"
"16.83000","1.40272","-0.00019"
"16.92000","1.41020","-0.00001"
"17.01000","1.41767","-0.00018"
"17.10000","1.42526","-0.00009"
"17.19000","1.43268","-0.00024"
"17.28000","1.44021","-0.00040"
"17.37000","1.44768","-0.00036"
"17.46000","1.45510","0.00007"
"17.55000","1.46269","0.00043"
"17.64000","1.47022","0.00027"
"17.73000","1.47770","0.00026"
"17.82000","1.48523","0.00011"
"17.91000","1.49271","0.00040"
"18.00000","1.50012","0.00009"
"18.09000","1.50771","0.00023"
"18.18000","1.51525","-0.00058"
"18.27000","1.52272","-0.00011"
"18.36000","1.53025","0.00009"
"18.45000","1.53767","-0.00016"
"18.54000","1.54514","0.00029"
"18.63000","1.55267","-0.00020"
"18.72000","1.56021","-0.00025"
"18.81000","1.56774","-0.00041"
"18.90000","1.57522","-0.00038"
"18.99000","1.58269","-0.00005"
"19.08000","1.59016","-0.00023"
"19.17000","1.59764","-0.00030"
"19.26000","1.60523","-0.00063"
"19.35000","1.61270","0.00007"
"19.44000","1.62018","-0.00004"
"19.53000","1.62771","-0.00005"
"19.62000","1.63512","-0.00002"
"19.71000","1.64266","0.00003"
"19.80000","1.65025","0.00021"
"19.89000","1.65772","-0.00040"
"19.98000","1.66520","-0.00013"
"20.07000","1.67267","0.00022"
"20.16000","1.68015","0.00012"
"20.25000","1.68768","0.00026"
"20.34000","1.69521","0.00014"
"20.43000","1.70263","-0.00002"
"20.52000","1.71022","0.00010"
"20.61000","1.71769","-0.00003"
"20.70000","1.72517","0.00024"
"20.79000","1.73270","0.00006"
"20.88000","1.74017","-0.00011"
"20.97000","1.74777","0.00002"
"21.06000","1.75518","0.00005"
"21.15000","1.76266","-0.00012"
"21.24000","1.77019","0.00018"
"21.33000","1.77772","0.00013"
"21.42000","1.78520","0.00029"
"21.51000","1.79267","0.00009"
"21.60000","1.80020","-0.00011"
"21.69000","1.80768","-0.00037"
"21.78000","1.81515","-0.00048"
"21.87000","1.82268","-0.00018"
"21.96000","1.83022","-0.00023"
"22.05000","1.83769","0.00031"
"22.14000","1.84516","0.00012"
"22.23000","1.85270","-0.00046"
"22.32000","1.86017","0.00008"
"22.41000","1.86771","0.00035"
"22.50000","1.87524","-0.00028"
"22.59000","1.88271","0.00021"
"22.68000","1.89025","0.00017"
"22.77000","1.89760","0.00000"
"22.86000","1.90519","0.00051"
"22.95000","1.91273","0.00028"
"23.04000","1.92020","0.00018"
"23.13000","1.92773","0.00027"
"23.22000","1.93515","-0.00031"
"23.31000","1.94262","-0.00001"
"23.40000","1.95016","0.00000"
"23.49000","1.95775","0.00010"
"23.58000","1.96522","-0.00009"
"23.67000","1.97270","-0.00034"
"23.76000","1.98017","0.00013"
"23.85000","1.98764","-0.00032"
"23.94000","1.99512","-0.00022"
"24.03000","2.00271","-0.00018"
"24.12000","2.01024","-0.00019"
"24.21000","2.01772","-0.00054"
"24.30000","2.02525","-0.00009"
"24.39000","2.03266","-0.00016"
"24.48000","2.04014","-0.00023"
"24.57000","2.04767","0.00012"
"24.66000","2.05521","0.00005"
"24.75000","2.06274","-0.00001"
"24.84000","2.07021","-0.00039"
"24.93000","2.07763","0.00017"
"25.02000","2.08516","0.00021"
"25.11000","2.09269","0.00025"
"25.20000","2.10023","0.00040"
"25.29000","2.10770","-0.00009"
"25.38000","2.11517","-0.00022"
"25.47000","2.12271","-0.00023"
"25.56000","2.13018","0.00026"
"25.65000","2.13766","0.00007"
"25.74000","2.14519","0.00021"
"25.83000","2.15272","0.00003"
"25.92000","2.16014","0.00022"
"26.01000","2.16767","0.00007"
"26.10000","2.17520","-0.00049"
"26.19000","2.18268","0.00005"
"26.28000","2.19021","0.00025"
"26.37000","2.19774","0.00063"
"26.46000","2.20522","0.00015"
"26.55000","2.21269","0.00029"
"26.64000","2.22016","0.00059"
"26.73000","2.22770","0.00038"
"26.82000","2.23523","-0.00074"
"26.91000","2.24271","0.00004"
"27.00000","2.25024","0.00005"
"27.09000","2.25765","0.00036"
"27.18000","2.26519","-0.00021"
"27.27000","2.27272","0.00009"
"27.36000","2.28019","0.00016"
"27.45000","2.28773","-0.00006"
"27.54000","2.29520","0.00021"
"27.63000","2.30267","-0.00005"
"27.72000","2.31015","-0.00027"
"27.81000","2.31768","-0.00027"
"27.90000","2.32516","0.00007"
"27.99000","2.33269","0.00032"
"28.08000","2.34016","0.00031"
"28.17000","2.34764","0.00007"
"28.26000","2.35517","0.00007"
"28.35000","2.36270","-0.00019"
"28.44000","2.37024","0.00027"
"28.53000","2.37771","-0.00034"
"28.62000","2.38518","0.00013"
"28.71000","2.39272","0.00007"
"28.80000","2.40013","0.00003"
"28.89000","2.40772","-0.00027"
"28.98000","2.41520","0.00006"
"29.07000","2.42273","-0.00013"
"29.16000","2.43021","0.00028"
"29.25000","2.43768","-0.00022"
"29.34000","2.44521","0.00001"
"29.43000","2.45269","0.00063"
"29.52000","2.46022","0.00036"
"29.61000","2.46769","0.00005"
"29.70000","2.47523","-0.00037"
"29.79000","2.48270","0.00014"
"29.88000","2.49017","0.00013"
"29.97000","2.49771","0.00028"
"30.06000","2.50518","-0.00009"
"30.15000","2.51272","0.00014"
"30.24000","2.52013","-0.00013"
"30.33000","2.52766","-0.00043"
"30.42000","2.53520","0.00009"
"30.51000","2.54267","0.00015"
"30.60000","2.55020","-0.00029"
"30.69000","2.55774","0.00010"
"30.78000","2.56515","-0.00005"
"30.87000","2.57268","0.00016"
"30.96000","2.58016","-0.00004"
"31.05000","2.58769","0.00054"
"31.14000","2.59528","0.00010"
"31.23000","2.60276","0.00080"
"31.32000","2.61023","0.00012"
"31.41000","2.61765","0.00030"
"31.50000","2.62518","-0.00014"
"31.59000","2.63277","-0.00004"
"31.68000","2.64019","0.00031"
"31.77000","2.64772","-0.00036"
"31.86000","2.65525","-0.00021"
"31.95000","2.66267","-0.00029"
"32.04000","2.67020","0.00063"
"32.13000","2.67773","-0.00029"
"32.22000","2.68521","-0.00033"
"32.31000","2.69274","-0.00023"
"32.40000","2.70016","0.00058"
"32.49000","2.70769","0.00023"
"32.58000","2.71522","0.00012"
"32.67000","2.72270","0.00039"
"32.76000","2.73023","-0.00027"
"32.85000","2.73776","-0.00037"
"32.94000","2.74524","0.00010"
"33.03000","2.75271","0.00008"
"33.12000","2.76018","-0.00008"
"33.21000","2.76772","0.00030"
"33.30000","2.77525","0.00039"
"33.39000","2.78272","-0.00003"
"33.48000","2.79020","0.00017"
"33.57000","2.79767","0.00020"
"33.66000","2.80515","-0.00004"
"33.75000","2.81274","0.00061"
"33.84000","2.82021","0.00092"
"33.93000","2.82769","0.00031"
"34.02000","2.83522","0.00066"
"34.11000","2.84263","-0.00030"
"34.20000","2.85017","0.00014"
"34.29000","2.85770","0.00031"
"34.38000","2.86517","0.00030"
"34.47000","2.87271","0.00040"
"34.56000","2.88018","0.00018"
"34.65000","2.88766","0.00046"
"34.74000","2.89519","-0.00009"
"34.83000","2.90266","0.00048"
"34.92000","2.91020","0.00048"
"35.01000","2.91779","0.00032"
"35.10000","2.92520","0.00083"
"35.19000","2.93268","0.00052"
"35.28000","2.94015","0.00035"
"35.37000","2.94768","0.00039"
"35.46000","2.95528","0.00063"
"35.55000","2.96275","0.00037"
"35.64000","2.97016","0.00031"
"35.73000","2.97770","-0.00011"
"35.82000","2.98517","0.00051"
"35.91000","2.99265","0.00054"
"36.00000","3.00018","0.00077"
"36.09000","3.00771","0.00075"
"36.18000","3.01519","0.00011"
"36.27000","3.02260","0.00082"
"36.36000","3.03013","0.00066"
"36.45000","3.03773","0.00027"
"36.54000","3.04520","0.00078"
"36.63000","3.05267","0.00054"
"36.72000","3.06021","0.00045"
"36.81000","3.06768","0.00036"
"36.90000","3.07516","0.00034"
"36.99000","3.08269","0.00052"
"37.08000","3.09016","0.00075"
"37.17000","3.09770","0.00056"
"37.26000","3.10523","0.00038"
"37.35000","3.11264","0.00038"
"37.44000","3.12018","0.00078"
"37.53000","3.12771","0.00033"
"37.62000","3.13524","0.00051"
"37.71000","3.14272","0.00049"
"37.80000","3.15019","0.00020"
"37.89000","3.15772","0.00082"
"37.98000","3.16520","0.00044"
"38.07000","3.17273","-0.00007"
"38.16000","3.18027","0.00066"
"38.25000","3.18768","0.00044"
"38.34000","3.19521","0.00085"
"38.43000","3.20263","0.00037"
"38.52000","3.21010","0.00023"
"38.61000","3.21775","0.00069"
"38.70000","3.22517","0.00054"
"38.79000","3.23270","0.00073"
"38.88000","3.24017","0.00026"
"38.97000","3.24765","0.00012"
"39.06000","3.25524","-0.00006"
"39.15000","3.26271","0.00096"
"39.24000","3.27019","0.00006"
"39.33000","3.27772","0.00015"
"39.42000","3.28514","0.00067"
"39.51000","3.29267","0.00057"
"39.60000","3.30020","0.00092"
"39.69000","3.30768","0.00050"
"39.78000","3.31521","0.00032"
"39.87000","3.32274","0.00081"
"39.96000","3.33016","0.00038"
"40.05000","3.33769","0.00013"
"40.14000","3.34516","-0.00005"
"40.23000","3.35276","0.00079"
"40.32000","3.36023","0.00044"
"40.41000","3.36771","0.00042"
"40.50000","3.37518","0.00047"
"40.59000","3.38265","0.00031"
"40.68000","3.39019","0.00022"
"40.77000","3.39772","0.00083"
"40.86000","3.40519","0.00079"
"40.95000","3.41267","0.00111"
"41.04000","3.42014","0.00072"
"41.13000","3.42761","0.00053"
"41.22000","3.43515","0.00058"
"41.31000","3.44274","0.00019"
"41.40000","3.45021","0.00025"
"41.49000","3.45775","0.00070"
"41.58000","3.46516","0.00089"
"41.67000","3.47264","0.00075"
"41.76000","3.48023","0.00036"
"41.85000","3.48776","0.00059"
"41.94000","3.49518","0.00030"
"42.03000","3.50271","0.00050"
"42.12000","3.51018","0.00052"
"42.21000","3.51766","0.00075"
"42.30000","3.52519","0.00066"
"42.39000","3.53272","0.00058"
"42.48000","3.54020","0.00089"
"42.57000","3.54767","0.00045"
"42.66000","3.55515","0.00111"
"42.75000","3.56262","0.00036"
"42.84000","3.57015","0.00070"
"42.93000","3.57775","0.00066"
"43.02000","3.58522","0.00112"
"43.11000","3.59269","0.00022"
"43.20000","3.60017","0.00039"
"43.29000","3.60764","0.00052"
"43.38000","3.61517","0.00064"
"43.47000","3.62271","0.00095"
"43.56000","3.63018","0.00066"
"43.65000","3.63771","0.00083"
"43.74000","3.64519","0.00057"
"43.83000","3.65266","0.00059"
"43.92000","3.66020","0.00070"
"44.01000","3.66767","0.00107"
"44.10000","3.67520","0.00082"
"44.19000","3.68274","0.00083"
"44.28000","3.69015","0.00109"
"44.37000","3.69762","0.00104"
"44.46000","3.70516","0.00046"
"44.55000","3.71275","0.00070"
"44.64000","3.72022","0.00068"
"44.73000","3.72770","0.00080"
"44.82000","3.73517","0.00111"
"44.91000","3.74265","0.00120"
"45.00000","3.75018","0.00104"
"45.09000","3.75771","0.00104"
"45.18000","3.76519","0.00073"
"45.27000","3.77272","0.00084"
"45.36000","3.78019","0.00124"
"45.45000","3.78761","0.00064"
"45.54000","3.79520","0.00090"
"45.63000","3.80279","0.00085"
"45.72000","3.81021","0.00085"
"45.81000","3.81774","0.00135"
"45.90000","3.82521","0.00149"
"45.99000","3.83269","0.00092"
"46.08000","3.84022","0.00096"
"46.17000","3.84770","0.00109"
"46.26000","3.85523","0.00124"
"46.35000","3.86270","0.00050"
"46.44000","3.87018","0.00090"
"46.53000","3.87771","0.00103"
"46.62000","3.88518","0.00165"
"46.71000","3.89272","0.00102"
"46.80000","3.90025","0.00130"
"46.89000","3.90766","0.00148"
"46.98000","3.91514","0.00098"
"47.07000","3.92267","0.00099"
"47.16000","3.93015","0.00125"
"47.25000","3.93774","0.00139"
"47.34000","3.94521","0.00154"
"47.43000","3.95263","0.00171"
"47.52000","3.96016","0.00109"
"47.61000","3.96763","0.00115"
"47.70000","3.97517","0.00145"
"47.79000","3.98276","0.00158"
"47.88000","3.99023","0.00148"
"47.97000","3.99771","0.00113"
"48.06000","4.00524","0.00097"
"48.15000","4.01265","0.00114"
"48.24000","4.02019","0.00160"
"48.33000","4.02772","0.00102"
"48.42000","4.03520","0.00152"
"48.51000","4.04273","0.00154"
"48.60000","4.05020","0.00101"
"48.69000","4.05768","0.00096"
"48.78000","4.06521","0.00149"
"48.87000","4.07268","0.00143"
"48.96000","4.08022","0.00125"
"49.05000","4.08769","0.00121"
"49.14000","4.09510","0.00137"
"49.23000","4.10270","0.00156"
"49.32000","4.11017","0.00118"
"49.41000","4.11770","0.00108"
"49.50000","4.12524","0.00177"
"49.59000","4.13271","0.00157"
"49.68000","4.14013","0.00131"
"49.77000","4.14760","0.00129"
"49.86000","4.15519","0.00136"
"49.95000","4.16273","0.00124"
"50.04000","4.17026","0.00198"
"50.13000","4.17773","0.00104"
"50.22000","4.18521","0.00171"
"50.31000","4.19262","0.00148"
"50.40000","4.20021","0.00083"
"50.49000","4.20775","0.00174"
"50.58000","4.21522","0.00135"
"50.67000","4.22276","0.00186"
"50.76000","4.23017","0.00212"
"50.85000","4.23758","0.00129"
"50.94000","4.24524","0.00201"
"51.03000","4.25271","0.00162"
"51.12000","4.26024","0.00187"
"51.21000","4.26772","0.00235"
"51.30000","4.27513","0.00151"
"51.39000","4.28266","0.00207"
"51.48000","4.29014","0.00166"
"51.57000","4.29773","0.00190"
"51.66000","4.30526","0.00187"
"51.75000","4.31268","0.00204"
"51.84000","4.32015","0.00166"
"51.93000","4.32769","0.00180"
"52.02000","4.33516","0.00194"
"52.11000","4.34269","0.00165"
"52.20000","4.35023","0.00197"
"52.29000","4.35770","0.00143"
"52.38000","4.36511","0.00171"
"52.47000","4.37265","0.00139"
"52.56000","4.38018","0.00169"
"52.65000","4.38771","0.00185"
"52.74000","4.39525","0.00187"
"52.83000","4.40272","0.00200"
"52.92000","4.41020","0.00175"
"53.01000","4.41767","0.00172"
"53.10000","4.42520","0.00185"
"53.19000","4.43268","0.00201"
"53.28000","4.44027","0.00153"
"53.37000","4.44774","0.00159"
"53.46000","4.45522","0.00175"
"53.55000","4.46263","0.00171"
"53.64000","4.47016","0.00223"
"53.73000","4.47770","0.00152"
"53.82000","4.48523","0.00191"
"53.91000","4.49265","0.00187"
"54.00000","4.50018","0.00177"
"54.09000","4.50765","0.00170"
"54.18000","4.51519","0.00215"
"54.27000","4.52272","0.00170"
"54.36000","4.53019","0.00216"
"54.45000","4.53767","0.00178"
"54.54000","4.54520","0.00217"
"54.63000","4.55261","0.00203"
"54.72000","4.56021","0.00186"
"54.81000","4.56774","0.00225"
"54.90000","4.57521","0.00226"
"54.99000","4.58269","0.00224"
"55.08000","4.59016","0.00219"
"55.17000","4.59764","0.00224"
"55.26000","4.60523","0.00179"
"55.35000","4.61264","0.00243"
"55.44000","4.62018","0.00210"
"55.53000","4.62771","0.00190"
"55.62000","4.63518","0.00215"
"55.71000","4.64266","0.00234"
"55.80000","4.65019","0.00213"
"55.89000","4.65772","0.00234"
"55.98000","4.66520","0.00217"
"56.07000","4.67267","0.00199"
"56.16000","4.68015","0.00212"
"56.25000","4.68768","0.00234"
"56.34000","4.69521","0.00224"
"56.43000","4.70275","0.00201"
"56.52000","4.71022","0.00247"
"56.61000","4.71763","0.00265"
"56.70000","4.72517","0.00257"
"56.79000","4.73270","0.00249"
"56.88000","4.74017","0.00232"
"56.97000","4.74777","0.00257"
"57.06000","4.75524","0.00209"
"57.15000","4.76271","0.00311"
"57.24000","4.77013","0.00257"
"57.33000","4.77772","0.00242"
"57.42000","4.78520","0.00282"
"57.51000","4.79267","0.00224"
"57.60000","4.80026","0.00287"
"57.69000","4.80768","0.00242"
"57.78000","4.81515","0.00260"
"57.87000","4.82268","0.00237"
"57.96000","4.83022","0.00294"
"58.05000","4.83775","0.00238"
"58.14000","4.84522","0.00234"
"58.23000","4.85270","0.00271"
"58.32000","4.86017","0.00321"
"58.41000","4.86770","0.00278"
"58.50000","4.87518","0.00285"
"58.59000","4.88271","0.00303"
"58.68000","4.89025","0.00266"
"58.77000","4.89766","0.00297"
"58.86000","4.90513","0.00296"
"58.95000","4.91267","0.00285"
"59.04000","4.92020","0.00285"
"59.13000","4.92773","0.00285"
"59.22000","4.93521","0.00294"
"59.31000","4.94268","0.00331"
"59.40000","4.95021","0.00254"
"59.49000","4.95763","0.00291"
"59.58000","4.96522","0.00326"
"59.67000","4.97276","0.00348"
"59.76000","4.98023","0.00265"
"59.85000","4.98770","0.00322"
"59.94000","4.99518","0.00342"
"60.03000","5.00265","0.00296"
"60.12000","5.01024","0.00263"
"60.21000","5.01772","0.00310"
"60.30000","5.02519","0.00340"
"60.39000","5.03266","0.00335"
"60.48000","5.04014","0.00327"
"60.57000","5.04773","0.00357"
"60.66000","5.05520","0.00303"
"60.75000","5.06274","0.00332"
"60.84000","5.07027","0.00329"
"60.93000","5.07769","0.00302"
"61.02000","5.08516","0.00386"
"61.11000","5.09263","0.00398"
"61.20000","5.10023","0.00315"
"61.29000","5.10770","0.00411"
"61.38000","5.11523","0.00380"
"61.47000","5.12271","0.00348"
"61.56000","5.13012","0.00367"
"61.65000","5.13765","0.00379"
"61.74000","5.14519","0.00403"
"61.83000","5.15272","0.00359"
"61.92000","5.16020","0.00370"
"62.01000","5.16773","0.00402"
"62.10000","5.17514","0.00370"
"62.19000","5.18268","0.00402"
"62.28000","5.19021","0.00344"
"62.37000","5.19768","0.00434"
"62.46000","5.20528","0.00379"
"62.55000","5.21269","0.00384"
"62.64000","5.22016","0.00430"
"62.73000","5.22770","0.00364"
"62.82000","5.23523","0.00375"
"62.91000","5.24270","0.00422"
"63.00000","5.25024","0.00426"
"63.09000","5.25771","0.00371"
"63.18000","5.26519","0.00439"
"63.27000","5.27272","0.00460"
"63.36000","5.28019","0.00446"
"63.45000","5.28773","0.00460"
"63.54000","5.29520","0.00427"
"63.63000","5.30267","0.00435"
"63.72000","5.31021","0.00430"
"63.81000","5.31762","0.00436"
"63.90000","5.32521","0.00484"
"63.99000","5.33275","0.00475"
"64.08000","5.34016","0.00409"
"64.17000","5.34770","0.00462"
"64.26000","5.35511","0.00408"
"64.35000","5.36264","0.00453"
"64.44000","5.37024","0.00486"
"64.53000","5.37765","0.00421"
"64.62000","5.38512","0.00518"
"64.71000","5.39272","0.00449"
"64.80000","5.40013","0.00440"
"64.89000","5.40766","0.00501"
"64.98000","5.41520","0.00348"
"65.07000","5.42273","0.00262"
"65.16000","5.43015","0.00249"
"65.25000","5.43768","0.00247"
"65.34000","5.44515","0.00301"
"65.43000","5.45269","0.00328"
"65.52000","5.46022","0.00227"
"65.61000","5.46769","0.00283"
"65.70000","5.47523","0.00294"
"65.79000","5.48264","0.00339"
"65.88000","5.49011","0.00286"
"65.97000","5.49771","0.00280"
"66.06000","5.50524","0.00327"
"66.15000","5.51271","0.00267"
"66.24000","5.52019","0.00320"
"66.33000","5.52766","0.00294"
"66.42000","5.53514","0.00334"
"66.51000","5.54267","0.00334"
"66.60000","5.55026","0.00313"
"66.69000","5.55768","0.00268"
"66.78000","5.56515","0.00314"
"66.87000","5.57268","0.00305"
"66.96000","5.58010","0.00308"
"67.05000","5.58769","0.00360"
"67.14000","5.59522","0.00376"
"67.23000","5.60270","0.00330"
"67.32000","5.61023","0.00336"
"67.41000","5.61765","0.00348"
"67.50000","5.62512","0.00362"
"67.59000","5.63271","0.00330"
"67.68000","5.64025","0.00378"
"67.77000","5.64778","0.00348"
"67.86000","5.65519","0.00398"
"67.95000","5.66267","0.00377"
"68.04000","5.67014","0.00325"
"68.13000","5.67767","0.00344"
"68.22000","5.68527","0.00372"
"68.31000","5.69274","0.00390"
"68.40000","5.70021","0.00358"
"68.49000","5.70769","0.00352"
"68.58000","5.71522","0.00373"
"68.67000","5.72270","0.00373"
"68.76000","5.73023","0.00388"
"68.85000","5.73770","0.00378"
"68.94000","5.74518","0.00362"
"69.03000","5.75265","0.00411"
"69.12000","5.76012","0.00356"
"69.21000","5.76766","0.00345"
"69.30000","5.77519","0.00341"
"69.39000","5.78272","0.00336"
"69.48000","5.79020","0.00382"
"69.57000","5.79767","0.00394"
"69.66000","5.80515","0.00435"
"69.75000","5.81268","0.00403"
"69.84000","5.82021","0.00367"
"69.93000","5.82775","0.00420"
"70.02000","5.83522","0.00401"
"70.11000","5.84263","0.00407"
"70.20000","5.85017","0.00438"
"70.29000","5.85770","0.00390"
"70.38000","5.86517","0.00494"
"70.47000","5.87277","0.00428"
"70.56000","5.88018","0.00443"
"70.65000","5.88765","0.00425"
"70.74000","5.89519","0.00423"
"70.83000","5.90272","0.00440"
"70.92000","5.91020","0.00426"
"71.01000","5.91773","0.00436"
"71.10000","5.92520","0.00428"
"71.19000","5.93268","0.00407"
"71.28000","5.94015","0.00405"
"71.37000","5.94768","0.00407"
"71.46000","5.95528","0.00397"
"71.55000","5.96269","0.00313"
"71.64000","5.97022","0.00336"
"71.73000","5.97770","0.00356"
"71.82000","5.98517","0.00394"
"71.91000","5.99265","0.00391"
"72.00000","6.00024","0.00368"
"72.09000","6.00771","0.00379"
"72.18000","6.01525","0.00397"
"72.27000","6.02266","0.00431"
"72.36000","6.03013","0.00398"
"72.45000","6.03767","0.00434"
"72.54000","6.04520","0.00373"
"72.63000","6.05267","0.00414"
"72.72000","6.06021","0.00436"
"72.81000","6.06768","0.00400"
"72.90000","6.07515","0.00461"
"72.99000","6.08269","0.00428"
"73.08000","6.09022","0.00461"
"73.17000","6.09769","0.00392"
"73.26000","6.10517","0.00423"
"73.35000","6.11264","0.00427"
"73.44000","6.12018","0.00403"
"73.53000","6.12771","0.00439"
"73.62000","6.13524","0.00413"
"73.71000","6.14272","0.00461"
"73.80000","6.15019","0.00458"
"73.89000","6.15766","0.00481"
"73.98000","6.16514","0.00491"
"74.07000","6.17273","0.00462"
"74.16000","6.18020","0.00495"
"74.25000","6.18768","0.00480"
"74.34000","6.19521","0.00531"
"74.43000","6.20263","0.00506"
"74.52000","6.21016","0.00499"
"74.61000","6.21769","0.00567"
"74.70000","6.22517","0.00525"
"74.79000","6.23270","0.00486"
"74.88000","6.24023","0.00523"
"74.97000","6.24765","0.00480"
"75.06000","6.25518","0.00562"
"75.15000","6.26271","0.00525"
"75.24000","6.27025","0.00525"
"75.33000","6.27772","0.00565"
"75.42000","6.28514","0.00496"
"75.51000","6.29267","0.00591"
"75.60000","6.30014","0.00535"
"75.69000","6.30768","0.00522"
"75.78000","6.31527","0.00066"
"75.87000","6.32274","0.00114"
"75.96000","6.33022","0.00105"
"76.05000","6.33769","0.00186"
"76.14000","6.34510","0.00138"
"76.23000","6.35270","0.00092"
"76.32000","6.36023","0.00122"
"76.41000","6.36770","0.00102"
"76.50000","6.37524","0.00158"
"76.59000","6.38265","0.00171"
"76.68000","6.39013","0.00109"
"76.77000","6.39772","0.00131"
"76.86000","6.40525","0.00106"
"76.95000","6.41273","0.00134"
"77.04000","6.42020","0.00118"
"77.13000","6.42767","0.00113"
"77.22000","6.43521","0.00168"
"77.31000","6.44268","0.00146"
"77.40000","6.45021","0.00065"
"77.49000","6.45775","0.00160"
"77.58000","6.46516","0.00111"
"77.67000","6.47264","0.00187"
"77.76000","6.48017","0.00152"
"77.85000","6.48764","0.00139"
"77.94000","6.49524","0.00123"
"78.03000","6.50277","0.00185"
"78.12000","6.51018","0.00175"
"78.21000","6.51766","0.00183"
"78.30000","6.52519","0.00133"
"78.39000","6.53266","0.00165"
"78.48000","6.54026","0.00106"
"78.57000","6.54773","0.00123"
"78.66000","6.55520","0.00184"
"78.75000","6.56268","0.00126"
"78.84000","6.57021","0.00091"
"78.93000","6.57775","0.00136"
"79.02000","6.58516","0.00159"
"79.11000","6.59275","0.00193"
"79.20000","6.60023","0.00159"
"79.29000","6.60764","0.00159"
"79.38000","6.61517","0.00183"
"79.47000","6.62265","0.00128"
"79.56000","6.63012","0.00129"
"79.65000","6.63771","0.00144"
"79.74000","6.64513","0.00157"
"79.83000","6.65260","0.00180"
"79.92000","6.66019","0.00168"
"80.01000","6.66767","0.00146"
"80.10000","6.67520","0.00153"
"80.19000","6.68268","0.00134"
"80.28000","6.69021","0.00176"
"80.37000","6.69768","0.00165"
"80.46000","6.70516","0.00205"
"80.55000","6.71269","0.00120"
"80.64000","6.72022","0.00190"
"80.73000","6.72770","0.00185"
"80.82000","6.73517","0.00115"
"80.91000","6.74271","0.00202"
"81.00000","6.75018","0.00125"
"81.09000","6.75771","0.00185"
"81.18000","6.76519","0.00202"
"81.27000","6.77272","0.00219"
"81.36000","6.78025","0.00216"
"81.45000","6.78767","0.00181"
"81.54000","6.79520","0.00211"
"81.63000","6.80267","0.00174"
"81.72000","6.81021","0.00180"
"81.81000","6.81774","0.00207"
"81.90000","6.82516","0.00202"
"81.99000","6.83263","0.00178"
"82.08000","6.84022","0.00183"
"82.17000","6.84770","0.00241"
"82.26000","6.85517","0.00213"
"82.35000","6.86270","0.00201"
"82.44000","6.87018","0.00190"
"82.53000","6.87765","0.00191"
"82.62000","6.88512","0.00239"
"82.71000","6.89272","0.00169"
"82.80000","6.90019","0.00201"
"82.89000","6.90772","0.00163"
"82.98000","6.91520","0.00119"
"83.07000","6.92267","0.00223"
"83.16000","6.93015","0.00171"
"83.25000","6.93774","0.00238"
"83.34000","6.94521","0.00251"
"83.43000","6.95275","0.00253"
"83.52000","6.96028","0.00211"
"83.61000","6.96769","0.00165"
"83.70000","6.97517","0.00201"
"83.79000","6.98276","0.00197"
"83.88000","6.99017","0.00165"
"83.97000","6.99771","0.00182"
"84.06000","7.00518","0.00211"
"84.15000","7.01259","0.00142"
"84.24000","7.02019","0.00197"
"84.33000","7.02772","0.00206"
"84.42000","7.03519","0.00169"
"84.51000","7.04273","0.00196"
"84.60000","7.05020","0.00191"
"84.69000","7.05768","0.00155"
"84.78000","7.06515","0.00157"
"84.87000","7.07274","0.00208"
"84.96000","7.08022","0.00204"
"85.05000","7.08769","0.00164"
"85.14000","7.09522","0.00212"
"85.23000","7.10264","0.00242"
"85.32000","7.11011","0.00201"
"85.41000","7.11770","0.00212"
"85.50000","7.12524","0.00206"
"85.59000","7.13271","0.00170"
"85.68000","7.14019","0.00191"
"85.77000","7.14766","0.00238"
"85.86000","7.15513","0.00228"
"85.95000","7.16267","0.00188"
"86.04000","7.17020","0.00234"
"86.13000","7.17773","0.00133"
"86.22000","7.18521","0.00240"
"86.31000","7.19268","0.00247"
"86.40000","7.20021","0.00254"
"86.49000","7.20769","0.00241"
"86.58000","7.21522","0.00258"
"86.67000","7.22276","0.00245"
"86.76000","7.23017","0.00235"
"86.85000","7.23770","0.00206"
"86.94000","7.24518","0.00235"
"87.03000","7.25265","0.00245"
"87.12000","7.26018","0.00207"
"87.21000","7.26766","0.00227"
"87.30000","7.27519","0.00266"
"87.39000","7.28266","0.00204"
"87.48000","7.29014","0.00222"
"87.57000","7.29767","0.00278"
"87.66000","7.30526","0.00253"
"87.75000","7.31268","0.00246"
"87.84000","7.32021","0.00309"
"87.93000","7.32763","0.00305"
"88.02000","7.33516","0.00243"
"88.11000","7.34275","0.00259"
"88.20000","7.35017","0.00320"
"88.29000","7.35770","0.00242"
"88.38000","7.36523","0.00263"
"88.47000","7.37265","0.00270"
"88.56000","7.38018","0.00285"
"88.65000","7.38771","0.00311"
"88.74000","7.39519","0.00269"
"88.83000","7.40272","0.00230"
"88.92000","7.41020","0.00287"
"89.01000","7.41767","0.00277"
"89.10000","7.42520","0.00268"
"89.19000","7.43274","0.00285"
"89.28000","7.44021","0.00262"
"89.37000","7.44768","0.00267"
"89.46000","7.45516","0.00259"
"89.55000","7.46269","0.00313"
"89.64000","7.47016","0.00247"
"89.73000","7.47770","0.00256"
"89.82000","7.48523","0.00273"
"89.91000","7.49270","0.00256"
"90.00000","7.50018","0.00285"
"90.09000","7.50765","0.00311"
"90.18000","7.51524","0.00276"
"90.27000","7.52272","0.00309"
"90.36000","7.53025","0.00319"
"90.45000","7.53773","0.00285"
"90.54000","7.54520","0.00297"
"90.63000","7.55261","0.00330"
"90.72000","7.56021","0.00323"
"90.81000","7.56774","0.00315"
"90.90000","7.57521","0.00312"
"90.99000","7.58275","0.00314"
"91.08000","7.59016","0.00335"
"91.17000","7.59769","0.00320"
"91.26000","7.60523","0.00356"
"91.35000","7.61270","0.00300"
"91.44000","7.62018","0.00361"
"91.53000","7.62771","0.00317"
"91.62000","7.63518","0.00358"
"91.71000","7.64266","0.00355"
"91.80000","7.65019","0.00336"
"91.89000","7.65772","0.00358"
"91.98000","7.66526","0.00359"
"92.07000","7.67267","0.00309"
"92.16000","7.68015","0.00341"
"92.25000","7.68762","0.00363"
"92.34000","7.69515","0.00346"
"92.43000","7.70275","0.00337"
"92.52000","7.71016","0.00385"
"92.61000","7.71763","0.00384"
"92.70000","7.72517","0.00373"
"92.79000","7.73258","0.00393"
"92.88000","7.74023","0.00350"
"92.97000","7.74777","0.00357"
"93.06000","7.75524","0.00381"
"93.15000","7.76277","0.00387"
"93.24000","7.77019","0.00415"
"93.33000","7.77760","0.00450"
"93.42000","7.78520","0.00387"
"93.51000","7.79273","0.00412"
"93.60000","7.80020","0.00393"
"93.69000","7.80774","0.00427"
"93.78000","7.81521","0.00405"
"93.87000","7.82262","0.00446"
"93.96000","7.83022","0.00411"
"94.05000","7.83775","0.00425"
"94.14000","7.84522","0.00375"
"94.23000","7.85270","0.00450"
"94.32000","7.86017","0.00458"
"94.41000","7.86764","0.00476"
"94.50000","7.87518","0.00460"
"94.59000","7.88277","0.00447"
"94.68000","7.89024","0.00502"
"94.77000","7.89766","0.00468"
"94.86000","7.90519","0.00424"
"94.95000","7.91261","0.00509"
"95.04000","7.92014","0.00469"
"95.13000","7.92773","0.00512"
"95.22000","7.93521","0.00507"
"95.31000","7.94274","0.00509"
"95.40000","7.95015","0.00508"
"95.49000","7.95763","0.00541"
"95.58000","7.96522","0.00494"
"95.67000","7.97269","0.00490"
"95.76000","7.98017","0.00493"
"95.85000","7.98776","0.00498"
"95.94000","7.99518","0.00540"
"96.03000","8.00271","0.00492"
"96.12000","8.01018","0.00513"
"96.21000","8.01772","0.00502"
"96.30000","8.02525","0.00520"
"96.39000","8.03272","0.00505"
"96.48000","8.04020","0.00516"
"96.57000","8.04767","0.00504"
"96.66000","8.05520","0.00558"
"96.75000","8.06274","0.00544"
"96.84000","8.07021","0.00568"
"96.93000","8.07769","0.00493"
"97.02000","8.08516","0.00498"
"97.11000","8.09263","0.00539"
"97.20000","8.10017","0.00521"
"97.29000","8.10770","0.00586"
"97.38000","8.11523","0.00557"
"97.47000","8.12271","0.00594"
"97.56000","8.13018","0.00564"
"97.65000","8.13765","0.00602"
"97.74000","8.14513","0.00579"
"97.83000","8.15272","0.00642"
"97.92000","8.16020","0.00553"
"98.01000","8.16767","0.00575"
"98.10000","8.17514","0.00597"
"98.19000","8.18262","0.00577"
"98.28000","8.19015","0.00600"
"98.37000","8.19768","0.00579"
"98.46000","8.20522","0.00561"
"98.55000","8.21269","0.00611"
"98.64000","8.22016","0.00619"
"98.73000","8.22770","0.00590"
"98.82000","8.23517","0.00570"
"98.91000","8.24276","0.00609"
"99.00000","8.25024","0.00600"
"99.09000","8.25765","0.00605"
"99.18000","8.26519","0.00587"
"99.27000","8.27266","0.00632"
"99.36000","8.28013","0.00598"
"99.45000","8.28773","0.00646"
"99.54000","8.29520","0.00588"
"99.63000","8.30261","0.00635"
"99.72000","8.31021","0.00650"
"99.81000","8.31762","0.00692"
"99.90000","8.32515","0.00657"
"99.99000","8.33269","0.00652"
"100.08000","8.34022","0.00674"
"100.17000","8.34769","0.00637"
"100.26000","8.35511","0.00697"
"100.35000","8.36264","0.00705"
"100.44000","8.37024","0.00684"
"100.53000","8.37771","0.00704"
"100.62000","8.38518","0.00715"
"100.71000","8.39272","0.00701"
"100.80000","8.40019","0.00696"
"100.89000","8.40766","0.00706"
"100.98000","8.41520","0.00719"
"101.07000","8.42273","0.00729"
"101.16000","8.43020","0.00732"
"101.25000","8.43768","0.00712"
"101.34000","8.44515","0.00762"
"101.43000","8.45269","0.00739"
"101.52000","8.46022","0.00761"
"101.61000","8.46769","0.00758"
"101.70000","8.47523","0.00713"
"101.79000","8.48270","0.00716"
"101.88000","8.49017","0.00744"
"101.97000","8.49765","0.00790"
"102.06000","8.50524","0.00807"
"102.15000","8.51271","0.00810"
"102.24000","8.52019","0.00803"
"102.33000","8.52772","0.00807"
"102.42000","8.53514","0.00738"
"102.51000","8.54261","0.00669"
"102.60000","8.55020","0.00723"
"102.69000","8.55774","0.00663"
"102.78000","8.56527","0.00203"
"102.87000","8.57268","0.00097"
"102.96000","8.58016","0.00417"
"103.05000","8.58769","0.00431"
"103.14000","8.59516","0.00158"
"103.23000","8.60270","0.00115"
"103.32000","8.61023","0.00141"
"103.41000","8.61765","0.00277"
"103.50000","8.62512","0.00272"
"103.59000","8.63271","0.00179"
"103.68000","8.64019","0.00093"
"103.77000","8.64772","0.00142"
"103.86000","8.65519","0.00222"
"103.95000","8.66267","0.00258"
"104.04000","8.67020","0.00292"
"104.13000","8.67761","0.00150"
"104.22000","8.68521","0.00139"
"104.31000","8.69274","0.00228"
"104.40000","8.70021","0.00224"
"104.49000","8.70769","0.00260"
"104.58000","8.71516","0.00158"
"104.67000","8.72264","0.00163"
"104.76000","8.73023","0.00195"
"104.85000","8.73770","0.00288"
"104.94000","8.74524","0.00259"
"105.03000","8.75271","0.00202"
"105.12000","8.76018","0.00184"
"105.21000","8.76766","0.00240"
"105.30000","8.77519","0.00274"
"105.39000","8.78266","0.00220"
"105.48000","8.79020","0.00188"
"105.57000","8.79767","0.00179"
"105.66000","8.80514","0.00201"
"105.75000","8.81268","0.00306"
"105.84000","8.82021","0.00309"
"105.93000","8.82775","0.00267"
"106.02000","8.83522","0.00251"
"106.11000","8.84269","0.00224"
"106.20000","8.85023","0.00282"
"106.29000","8.85764","0.00307"
"106.38000","8.86517","0.00239"
"106.47000","8.87277","0.00212"
"106.56000","8.88018","0.00254"
"106.65000","8.88771","0.00317"
"106.74000","8.89519","0.00342"
"106.83000","8.90266","0.00264"
"106.92000","8.91020","0.00241"
"107.01000","8.91773","0.00266"
"107.10000","8.92520","0.00335"
"107.19000","8.93274","0.00292"
"107.28000","8.94021","0.00255"
"107.37000","8.94768","0.00248"
"107.46000","8.95522","0.00270"
"107.55000","8.96269","0.00357"
"107.64000","8.97022","0.00348"
"107.73000","8.97764","0.00301"
"107.82000","8.98517","0.00312"
"107.91000","8.99270","0.00349"
"108.00000","9.00018","0.00372"
"108.09000","9.00771","0.00368"
"108.18000","9.01525","0.00253"
"108.27000","9.02266","0.00305"
"108.36000","9.03019","0.00347"
"108.45000","9.03767","0.00365"
"108.54000","9.04520","0.00373"
"108.63000","9.05279","0.00257"
"108.72000","9.06021","0.00327"
"108.81000","9.06762","0.00348"
"108.90000","9.07515","0.00361"
"108.99000","9.08275","0.00333"
"109.08000","9.09022","0.00290"
"109.17000","9.09770","0.00337"
"109.26000","9.10523","0.00403"
"109.35000","9.11270","0.00385"
"109.44000","9.12018","0.00360"
"109.53000","9.12771","0.00325"
"109.62000","9.13524","0.00355"
"109.71000","9.14272","0.00442"
"109.80000","9.15019","0.00412"
"109.89000","9.15766","0.00343"
"109.98000","9.16514","0.00319"
"110.07000","9.17273","0.00431"
"110.16000","9.18021","0.00469"
"110.25000","9.18768","0.00415"
"110.34000","9.19521","0.00394"
"110.43000","9.20269","0.00387"
"110.52000","9.21016","0.00435"
"110.61000","9.21769","0.00440"
"110.70000","9.22523","0.00483"
"110.79000","9.23276","0.00431"
"110.88000","9.24023","0.00427"
"110.97000","9.24771","0.00455"
"111.06000","9.25518","0.00462"
"111.15000","9.26265","0.00442"
"111.24000","9.27025","0.00438"
"111.33000","9.27772","0.00442"
"111.42000","9.28519","0.00520"
"111.51000","9.29273","0.00492"
"111.60000","9.30014","0.00439"
"111.69000","9.30774","0.00460"
"111.78000","9.31527","0.00469"
"111.87000","9.32274","0.00517"
"111.96000","9.33022","0.00518"
"112.05000","9.33769","0.00477"
"112.14000","9.34510","0.00458"
"112.23000","9.35270","0.00482"
"112.32000","9.36017","0.00495"
"112.41000","9.36770","0.00514"
"112.50000","9.37524","0.00519"
"112.59000","9.38265","0.00518"
"112.68000","9.39013","0.00565"
"112.77000","9.39766","0.00536"
"112.86000","9.40519","0.00540"
"112.95000","9.41273","0.00530"
"113.04000","9.42020","0.00507"
"113.13000","9.42767","0.00544"
"113.22000","9.43515","0.00560"
"113.31000","9.44268","0.00537"
"113.40000","9.45021","0.00541"
"113.49000","9.45775","0.00520"
"113.58000","9.46528","0.00560"
"113.67000","9.47270","0.00583"
"113.76000","9.48017","0.00570"
"113.85000","9.48764","0.00561"
"113.94000","9.49524","0.00568"
"114.03000","9.50265","0.00588"
"114.12000","9.51018","0.00600"
"114.21000","9.51766","0.00540"
"114.30000","9.52513","0.00591"
"114.39000","9.53266","0.00569"
"114.48000","9.54026","0.00554"
"114.57000","9.54767","0.00566"
"114.66000","9.55520","0.00576"
"114.75000","9.56274","0.00582"
"114.84000","9.57015","0.00560"
"114.93000","9.57769","0.00574"
"115.02000","9.58522","0.00645"
"115.11000","9.59269","0.00631"
"115.20000","9.60023","0.00613"
"115.29000","9.60764","0.00639"
"115.38000","9.61517","0.00656"
"115.47000","9.62265","0.00602"
"115.56000","9.63024","0.00634"
"115.65000","9.63771","0.00702"
"115.74000","9.64519","0.00670"
"115.83000","9.65272","0.00650"
"115.92000","9.66014","0.00622"
"116.01000","9.66767","0.00666"
"116.10000","9.67526","0.00671"
"116.19000","9.68268","0.00656"
"116.28000","9.69015","0.00641"
"116.37000","9.69768","0.00685"
"116.46000","9.70510","0.00714"
"116.55000","9.71263","0.00716"
"116.64000","9.72022","0.00713"
"116.73000","9.72770","0.00719"
"116.82000","9.73523","0.00746"
"116.91000","9.74264","0.00707"
"117.00000","9.75018","0.00713"
"117.09000","9.75771","0.00763"
"117.18000","9.76519","0.00749"
"117.27000","9.77266","0.00743"
"117.36000","9.78019","0.00728"
"117.45000","9.78767","0.00756"
"117.54000","9.79520","0.00785"
"117.63000","9.80267","0.00759"
"117.72000","9.81021","0.00782"
"117.81000","9.81774","0.00755"
"117.90000","9.82521","0.00723"
"117.99000","9.83269","0.00812"
"118.08000","9.84016","0.00805"
"118.17000","9.84769","0.00760"
"118.26000","9.85523","0.00758"
"118.35000","9.86270","0.00769"
"118.44000","9.87018","0.00835"
"118.53000","9.87771","0.00850"
"118.62000","9.88512","0.00810"
"118.71000","9.89266","0.00839"
"118.80000","9.90019","0.00838"
"118.89000","9.90772","0.00841"
"118.98000","9.91526","0.00835"
"119.07000","9.92267","0.00841"
"119.16000","9.93014","0.00829"
"119.25000","9.93774","0.00865"
"119.34000","9.94521","0.00828"
"119.43000","9.95275","0.00886"
"119.52000","9.96022","0.00883"
"119.61000","9.96769","0.00873"
"119.70000","9.97517","0.00861"
"119.79000","9.98264","0.00922"
"119.88000","9.99023","0.00902"
"119.97000","9.99777","0.00874"
"120.06000","10.00518","0.00887"
"120.15000","10.01265","0.00895"
"120.24000","10.02019","0.00902"
"120.33000","10.02766","0.00915"
"120.42000","10.03525","0.00966"
"120.51000","10.04273","0.00936"
"120.60000","10.05020","0.00959"
"120.69000","10.05767","0.00930"
"120.78000","10.06509","0.00938"
"120.87000","10.07268","0.00938"
"120.96000","10.08022","0.00974"
"121.05000","10.08775","0.00994"
"121.14000","10.09522","0.00972"
"121.23000","10.10270","0.01000"
"121.32000","10.11011","0.01009"
"121.41000","10.11770","0.00996"
"121.50000","10.12518","0.01032"
"121.59000","10.13271","0.01036"
"121.68000","10.14024","0.01009"
"121.77000","10.14766","0.01016"
"121.86000","10.15513","0.01053"
"121.95000","10.16267","0.01059"
"122.04000","10.17020","0.01056"
"122.13000","10.17767","0.01060"
"122.22000","10.18521","0.01112"
"122.31000","10.19268","0.01069"
"122.40000","10.20015","0.01087"
"122.49000","10.20769","0.01125"
"122.58000","10.21522","0.01115"
"122.67000","10.22269","0.01134"
"122.76000","10.23017","0.01164"
"122.85000","10.23764","0.01153"
"122.94000","10.24512","0.01152"
"123.03000","10.25265","0.01150"
"123.12000","10.26024","0.01183"
"123.21000","10.26766","0.01173"
"123.30000","10.27519","0.01188"
"123.39000","10.28272","0.01224"
"123.48000","10.29014","0.01223"
"123.57000","10.29773","0.01206"
"123.66000","10.30520","0.01213"
"123.75000","10.31268","0.01240"
"123.84000","10.32021","0.01274"
"123.93000","10.32769","0.01256"
"124.02000","10.33516","0.01270"
"124.11000","10.34269","0.01302"
"124.20000","10.35017","0.01306"
"124.29000","10.35776","0.01317"
"124.38000","10.36523","0.01327"
"124.47000","10.37271","0.01335"
"124.56000","10.38018","0.01355"
"124.65000","10.38771","0.01352"
"124.74000","10.39525","0.01366"
"124.83000","10.40272","0.01381"
"124.92000","10.41019","0.01394"
"125.01000","10.41767","0.01418"
"125.10000","10.42514","0.01420"
"125.19000","10.43268","0.01443"
"125.28000","10.44027","0.01426"
"125.37000","10.44768","0.01411"
"125.46000","10.45516","0.01351"
"125.55000","10.46269","0.01219"
"125.64000","10.47016","0.00890"
"125.73000","10.47770","0.00572"
"125.82000","10.48517","-0.00027"
"125.91000","10.49270","-0.00078"
"126.00000","10.50018","-0.00099"
"126.09000","10.50765","-0.00069"
"126.18000","10.51513","-0.00011"
"126.27000","10.52272","-0.00086"
"126.36000","10.53025","-0.00030"
"126.45000","10.53772","-0.00120"
"126.54000","10.54520","-0.00088"
"126.63000","10.55267","-0.00141"
"126.72000","10.56021","-0.00151"
"126.81000","10.56774","-0.00125"
"126.90000","10.57521","-0.00133"
"126.99000","10.58275","-0.00158"
"127.08000","10.59016","-0.00164"
"127.17000","10.59764","-0.00115"
"127.26000","10.60517","-0.00145"
"127.35000","10.61270","-0.00107"
"127.44000","10.62024","-0.00088"
"127.53000","10.62771","-0.00080"
"127.62000","10.63524","-0.00036"
"127.71000","10.64272","-0.00042"
"127.80000","10.65007","-0.00066"
"127.89000","10.65772","-0.00093"
"127.98000","10.66526","-0.00134"
"128.07000","10.67267","-0.00099"
"128.16000","10.68026","-0.00139"
"128.25000","10.68768","-0.00153"
"128.34000","10.69509","-0.00195"
"128.43000","10.70275","-0.00121"
"128.52000","10.71022","-0.00160"
"128.61000","10.71775","-0.00133"
"128.70000","10.72523","-0.00129"
"128.79000","10.73270","-0.00108"
"128.88000","10.74017","-0.00046"
"128.97000","10.74765","-0.00082"
"129.06000","10.75518","-0.00105"
"129.15000","10.76277","-0.00131"
"129.24000","10.77013","-0.00095"
"129.33000","10.77760","-0.00145"
"129.42000","10.78514","-0.00115"
"129.51000","10.79267","-0.00119"
"129.60000","10.80020","-0.00087"
"129.69000","10.80774","-0.00147"
"129.78000","10.81521","-0.00170"
"129.87000","10.82268","-0.00120"
"129.96000","10.83016","-0.00170"
"130.05000","10.83769","-0.00134"
"130.14000","10.84522","-0.00101"
"130.23000","10.85276","-0.00031"
"130.32000","10.86017","-0.00082"
"130.41000","10.86770","-0.00103"
"130.49800","10.87500","-0.00101"