File: Force_trajectories/161226_1/Specimen_RawData_4.csv
End date,"12/26/2016"
Specimen label,"10AT_60"
Maximum Load,"0.01895",N

Time,Extension,Load
(s),(mm),(N)
"0.00000","0.00000","0.00006"
"0.07800","0.00221","-0.00002"
"0.15600","0.00903","0.00006"
"0.23400","0.01770","0.00015"
"0.31200","0.02565","0.00005"
"0.39000","0.03270","0.00015"
"0.46800","0.03928","0.00010"
"0.54600","0.04580","0.00000"
"0.62400","0.05226","0.00051"
"0.70200","0.05871","0.00031"
"0.78000","0.06523","0.00037"
"0.85800","0.07169","0.00024"
"0.93600","0.07814","0.00024"
"1.01400","0.08466","0.00025"
"1.09200","0.09124","0.00023"
"1.17000","0.09770","0.00034"
"1.24800","0.10421","0.00056"
"1.32600","0.11067","0.00062"
"1.40400","0.11719","0.00052"
"1.48200","0.12370","0.00050"
"1.56000","0.13022","0.00046"
"1.63800","0.13668","0.00096"
"1.71600","0.14320","0.00053"
"1.79400","0.14971","0.00027"
"1.87200","0.15623","0.00075"
"1.95000","0.16263","0.00066"
"2.02800","0.16914","0.00082"
"2.10600","0.17566","0.00030"
"2.18400","0.18218","0.00073"
"2.26200","0.18870","0.00065"
"2.34000","0.19521","0.00044"
"2.41800","0.20173","0.00035"
"2.49600","0.20819","0.00059"
"2.57400","0.21470","0.00072"
"2.65200","0.22122","0.00048"
"2.73000","0.22780","0.00046"
"2.80800","0.23420","0.00090"
"2.88600","0.24071","0.00053"
"2.96400","0.24717","0.00108"
"3.04200","0.25363","0.00024"
"3.12000","0.26014","0.00079"
"3.19800","0.26672","0.00032"
"3.27600","0.27324","0.00058"
"3.35400","0.27970","0.00092"
"3.43200","0.28627","0.00022"
"3.51000","0.29273","0.00042"
"3.58800","0.29919","0.00074"
"3.66600","0.30564","0.00050"
"3.74400","0.31222","0.00029"
"3.82200","0.31874","0.00053"
"3.90000","0.32520","0.00011"
"3.97800","0.33171","0.00079"
"4.05600","0.33817","0.00032"
"4.13400","0.34469","0.00066"
"4.21200","0.35114","0.00041"
"4.29000","0.35772","0.00067"
"4.36800","0.36424","0.00045"
"4.44600","0.37075","0.00043"
"4.52400","0.37721","0.00024"
"4.60200","0.38373","0.00045"
"4.68000","0.39019","0.00080"
"4.75800","0.39664","0.00046"
"4.83600","0.40322","0.00070"
"4.91400","0.40974","0.00037"
"4.99200","0.41625","0.00053"
"5.07000","0.42271","0.00057"
"5.14800","0.42917","0.00024"
"5.22600","0.43563","0.00049"
"5.30400","0.44214","0.00064"
"5.38200","0.44866","0.00049"
"5.46000","0.45524","0.00019"
"5.53800","0.46175","0.00070"
"5.61600","0.46821","0.00057"
"5.69400","0.47467","0.00060"
"5.77200","0.48113","0.00044"
"5.85000","0.48770","0.00025"
"5.92800","0.49422","0.00043"
"6.00600","0.50080","0.00102"
"6.08400","0.50725","0.00057"
"6.16200","0.51377","0.00038"
"6.24000","0.52017","0.00067"
"6.31800","0.52669","0.00027"
"6.39600","0.53314","0.00046"
"6.47400","0.53972","0.00105"
"6.55200","0.54618","0.00034"
"6.63000","0.55275","0.00099"
"6.70800","0.55921","0.00095"
"6.78600","0.56573","0.00052"
"6.86400","0.57213","0.00082"
"6.94200","0.57864","0.00055"
"7.02000","0.58522","0.00030"
"7.09800","0.59168","0.00078"
"7.17600","0.59825","0.00085"
"7.25400","0.60465","0.00079"
"7.33200","0.61117","0.00048"
"7.41000","0.61763","0.00028"
"7.48800","0.62414","0.00083"
"7.56600","0.63072","0.00132"
"7.64400","0.63724","0.00091"
"7.72200","0.64375","0.00092"
"7.80000","0.65021","0.00101"
"7.87800","0.65673","0.00055"
"7.95600","0.66313","0.00116"
"8.03400","0.66970","0.00027"
"8.11200","0.67622","0.00127"
"8.19000","0.68274","0.00097"
"8.26800","0.68919","0.00054"
"8.34600","0.69571","0.00069"
"8.42400","0.70223","0.00096"
"8.50200","0.70869","0.00106"
"8.58000","0.71526","0.00133"
"8.65800","0.72178","0.00080"
"8.73600","0.72824","0.00142"
"8.81400","0.73475","0.00133"
"8.89200","0.74121","0.00049"
"8.97000","0.74773","0.00125"
"9.04800","0.75419","0.00100"
"9.12600","0.76070","0.00124"
"9.20400","0.76728","0.00137"
"9.28200","0.77368","0.00096"
"9.36000","0.78019","0.00120"
"9.43800","0.78665","0.00085"
"9.51600","0.79317","0.00140"
"9.59400","0.79969","0.00053"
"9.67200","0.80614","0.00102"
"9.75000","0.81278","0.00033"
"9.82800","0.81924","0.00103"
"9.90600","0.82569","0.00089"
"9.98400","0.83215","0.00049"
"10.06200","0.83867","0.00049"
"10.14000","0.84518","0.00070"
"10.21800","0.85170","0.00038"
"10.29600","0.85822","0.00033"
"10.37400","0.86474","0.00064"
"10.45200","0.87119","0.00078"
"10.53000","0.87771","0.00044"
"10.60800","0.88417","0.00036"
"10.68600","0.89068","0.00017"
"10.76400","0.89726","0.00022"
"10.84200","0.90372","0.00045"
"10.92000","0.91024","0.00092"
"10.99800","0.91669","0.00072"
"11.07600","0.92321","0.00037"
"11.15400","0.92967","0.00065"
"11.23200","0.93618","0.00065"
"11.31000","0.94276","0.00075"
"11.38800","0.94922","0.00085"
"11.46600","0.95574","0.00063"
"11.54400","0.96219","0.00065"
"11.62200","0.96865","0.00069"
"11.70000","0.97511","0.00055"
"11.77800","0.98168","0.00078"
"11.85600","0.98820","0.00047"
"11.93400","0.99472","0.00059"
"12.01200","1.00124","0.00038"
"12.09000","1.00769","0.00091"
"12.16800","1.01415","0.00035"
"12.24600","1.02061","0.00042"
"12.32400","1.02718","0.00049"
"12.40200","1.03370","0.00081"
"12.48000","1.04022","0.00028"
"12.55800","1.04674","0.00061"
"12.63600","1.05319","0.00044"
"12.71400","1.05971","0.00076"
"12.79200","1.06611","0.00096"
"12.87000","1.07268","0.00053"
"12.94800","1.07920","0.00036"
"13.02600","1.08572","0.00084"
"13.10400","1.09224","0.00030"
"13.18200","1.09875","0.00097"
"13.26000","1.10521","0.00071"
"13.33800","1.11167","0.00053"
"13.41600","1.11812","0.00098"
"13.49400","1.12476","0.00065"
"13.57200","1.13116","0.00045"
"13.65000","1.13768","0.00084"
"13.72800","1.14419","0.00052"
"13.80600","1.15065","0.00056"
"13.88400","1.15717","0.00000"
"13.96200","1.16368","0.00047"
"14.04000","1.17020","0.00084"
"14.11800","1.17672","0.00095"
"14.19600","1.18323","0.00092"
"14.27400","1.18969","0.00054"
"14.35200","1.19621","0.00032"
"14.43000","1.20261","0.00068"
"14.50800","1.20924","0.00091"
"14.58600","1.21576","0.00116"
"14.66400","1.22222","0.00119"
"14.74200","1.22873","0.00105"
"14.82000","1.23519","0.00076"
"14.89800","1.24171","0.00102"
"14.97600","1.24817","0.00097"
"15.05400","1.25474","0.00083"
"15.13200","1.26120","0.00065"
"15.21000","1.26778","0.00060"
"15.28800","1.27423","0.00102"
"15.36600","1.28075","0.00033"
"15.44400","1.28715","0.00058"
"15.52200","1.29367","0.00073"
"15.60000","1.30018","0.00068"
"15.67800","1.30670","0.00084"
"15.75600","1.31322","0.00074"
"15.83400","1.31967","0.00080"
"15.91200","1.32619","0.00130"
"15.99000","1.33265","0.00123"
"16.06800","1.33923","0.00046"
"16.14600","1.34568","0.00098"
"16.22400","1.35226","0.00075"
"16.30200","1.35872","0.00075"
"16.38000","1.36523","0.00089"
"16.45800","1.37169","0.00054"
"16.53600","1.37821","0.00063"
"16.61400","1.38473","0.00048"
"16.69200","1.39124","0.00068"
"16.77000","1.39776","0.00079"
"16.84800","1.40416","0.00077"
"16.92600","1.41073","0.00112"
"17.00400","1.41719","0.00057"
"17.08200","1.42371","0.00088"
"17.16000","1.43017","0.00095"
"17.23800","1.43668","0.00070"
"17.31600","1.44320","0.00088"
"17.39400","1.44972","0.00065"
"17.47200","1.45617","0.00051"
"17.55000","1.46269","0.00139"
"17.62800","1.46915","0.00096"
"17.70600","1.47567","0.00081"
"17.78400","1.48218","0.00128"
"17.86200","1.48870","0.00114"
"17.94000","1.49516","0.00038"
"18.01800","1.50167","0.00058"
"18.09600","1.50813","0.00084"
"18.17400","1.51465","0.00080"
"18.25200","1.52117","0.00075"
"18.33000","1.52774","0.00099"
"18.40800","1.53420","0.00124"
"18.48600","1.54072","0.00051"
"18.56400","1.54717","0.00092"
"18.64200","1.55369","0.00090"
"18.72000","1.56015","0.00089"
"18.79800","1.56673","0.00110"
"18.87600","1.57318","0.00078"
"18.95400","1.57976","0.00063"
"19.03200","1.58622","0.00098"
"19.11000","1.59267","0.00092"
"19.18800","1.59913","0.00078"
"19.26600","1.60571","0.00117"
"19.34400","1.61222","0.00060"
"19.42200","1.61868","0.00098"
"19.50000","1.62526","0.00063"
"19.57800","1.63172","0.00090"
"19.65600","1.63823","0.00106"
"19.73400","1.64463","0.00096"
"19.81200","1.65121","0.00090"
"19.89000","1.65772","0.00115"
"19.96800","1.66424","0.00106"
"20.04600","1.67070","0.00098"
"20.12400","1.67716","0.00080"
"20.20200","1.68367","0.00098"
"20.28000","1.69013","0.00100"
"20.35800","1.69665","0.00075"
"20.43600","1.70322","0.00136"
"20.51400","1.70974","0.00105"
"20.59200","1.71626","0.00107"
"20.67000","1.72278","0.00106"
"20.74800","1.72917","0.00104"
"20.82600","1.73569","0.00087"
"20.90400","1.74215","0.00085"
"20.98200","1.74872","0.00057"
"21.06000","1.75524","0.00103"
"21.13800","1.76176","0.00067"
"21.21600","1.76822","0.00043"
"21.29400","1.77467","0.00092"
"21.37200","1.78119","0.00095"
"21.45000","1.78765","0.00125"
"21.52800","1.79422","0.00097"
"21.60600","1.80074","0.00059"
"21.68400","1.80720","0.00065"
"21.76200","1.81372","0.00120"
"21.84000","1.82017","0.00094"
"21.91800","1.82669","0.00078"
"21.99600","1.83321","0.00045"
"22.07400","1.83966","0.00098"
"22.15200","1.84618","0.00111"
"22.23000","1.85276","0.00066"
"22.30800","1.85916","0.00088"
"22.38600","1.86567","0.00082"
"22.46400","1.87213","0.00098"
"22.54200","1.87871","0.00101"
"22.62000","1.88522","0.00082"
"22.69800","1.89174","0.00090"
"22.77600","1.89826","0.00093"
"22.85400","1.90472","0.00162"
"22.93200","1.91117","0.00062"
"23.01000","1.91763","0.00043"
"23.08800","1.92421","0.00070"
"23.16600","1.93072","0.00090"
"23.24400","1.93724","0.00072"
"23.32200","1.94370","0.00085"
"23.40000","1.95022","0.00119"
"23.47800","1.95667","0.00064"
"23.55600","1.96319","0.00119"
"23.63400","1.96971","0.00105"
"23.71200","1.97622","0.00090"
"23.79000","1.98274","0.00122"
"23.86800","1.98926","0.00106"
"23.94600","1.99571","0.00094"
"24.02400","2.00217","0.00096"
"24.10200","2.00869","0.00070"
"24.18000","2.01521","0.00060"
"24.25800","2.02166","0.00075"
"24.33600","2.02818","0.00102"
"24.41400","2.03470","0.00119"
"24.49200","2.04115","0.00039"
"24.57000","2.04761","0.00132"
"24.64800","2.05413","0.00107"
"24.72600","2.06071","0.00078"
"24.80400","2.06728","0.00153"
"24.88200","2.07368","0.00100"
"24.96000","2.08026","0.00110"
"25.03800","2.08671","0.00086"
"25.11600","2.09317","0.00124"
"25.19400","2.09963","0.00048"
"25.27200","2.10621","0.00070"
"25.35000","2.11272","0.00129"
"25.42800","2.11924","0.00081"
"25.50600","2.12570","0.00140"
"25.58400","2.13221","0.00162"
"25.66200","2.13867","0.00079"
"25.74000","2.14519","0.00122"
"25.81800","2.15171","0.00094"
"25.89600","2.15822","0.00154"
"25.97400","2.16468","0.00096"
"26.05200","2.17120","0.00144"
"26.13000","2.17771","0.00092"
"26.20800","2.18417","0.00099"
"26.28600","2.19069","0.00078"
"26.36400","2.19721","0.00149"
"26.44200","2.20372","0.00083"
"26.52000","2.21018","0.00129"
"26.59800","2.21664","0.00110"
"26.67600","2.22321","0.00137"
"26.75400","2.22961","0.00126"
"26.83200","2.23619","0.00114"
"26.91000","2.24265","0.00095"
"26.98800","2.24922","0.00111"
"27.06600","2.25568","0.00103"
"27.14400","2.26220","0.00108"
"27.22200","2.26865","0.00109"
"27.30000","2.27517","0.00120"
"27.37800","2.28169","0.00095"
"27.45600","2.28821","0.00103"
"27.53400","2.29472","0.00125"
"27.61200","2.30124","0.00130"
"27.69000","2.30776","0.00074"
"27.76800","2.31415","0.00123"
"27.84600","2.32067","0.00058"
"27.92400","2.32719","0.00099"
"28.00200","2.33377","0.00079"
"28.08000","2.34016","0.00089"
"28.15800","2.34674","0.00061"
"28.23600","2.35320","0.00116"
"28.31400","2.35965","0.00111"
"28.39200","2.36617","0.00110"
"28.47000","2.37269","0.00076"
"28.54800","2.37926","0.00123"
"28.62600","2.38566","0.00130"
"28.70400","2.39224","0.00129"
"28.78200","2.39870","0.00089"
"28.86000","2.40521","0.00113"
"28.93800","2.41161","0.00094"
"29.01600","2.41819","0.00108"
"29.09400","2.42470","0.00156"
"29.17200","2.43122","0.00120"
"29.25000","2.43774","0.00151"
"29.32800","2.44420","0.00152"
"29.40600","2.45071","0.00140"
"29.48400","2.45717","0.00093"
"29.56200","2.46369","0.00151"
"29.64000","2.47026","0.00174"
"29.71800","2.47672","0.00128"
"29.79600","2.48324","0.00135"
"29.87400","2.48970","0.00107"
"29.95200","2.49615","0.00161"
"30.03000","2.50261","0.00144"
"30.10800","2.50925","0.00123"
"30.18600","2.51576","0.00192"
"30.26400","2.52228","0.00119"
"30.34200","2.52868","0.00101"
"30.42000","2.53526","0.00154"
"30.49800","2.54165","0.00120"
"30.57600","2.54817","0.00160"
"30.65400","2.55463","0.00088"
"30.73200","2.56120","0.00151"
"30.81000","2.56772","0.00094"
"30.88800","2.57418","0.00099"
"30.96600","2.58070","0.00165"
"31.04400","2.58715","0.00125"
"31.12200","2.59367","0.00113"
"31.20000","2.60019","0.00116"
"31.27800","2.60676","0.00104"
"31.35600","2.61322","0.00166"
"31.43400","2.61980","0.00126"
"31.51200","2.62620","0.00068"
"31.59000","2.63265","0.00089"
"31.66800","2.63917","0.00112"
"31.74600","2.64569","0.00159"
"31.82400","2.65226","0.00093"
"31.90200","2.65872","0.00165"
"31.98000","2.66524","0.00114"
"32.05800","2.67164","0.00118"
"32.13600","2.67821","0.00139"
"32.21400","2.68467","0.00155"
"32.29200","2.69119","0.00155"
"32.37000","2.69764","0.00146"
"32.44800","2.70422","0.00114"
"32.52600","2.71068","0.00129"
"32.60400","2.71714","0.00104"
"32.68200","2.72365","0.00118"
"32.76000","2.73017","0.00098"
"32.83800","2.73675","0.00170"
"32.91600","2.74320","0.00168"
"32.99400","2.74972","0.00101"
"33.07200","2.75624","0.00092"
"33.15000","2.76270","0.00172"
"33.22800","2.76915","0.00090"
"33.30600","2.77567","0.00130"
"33.38400","2.78225","0.00147"
"33.46200","2.78870","0.00127"
"33.54000","2.79522","0.00082"
"33.61800","2.80174","0.00138"
"33.69600","2.80819","0.00101"
"33.77400","2.81471","0.00115"
"33.85200","2.82123","0.00123"
"33.93000","2.82775","0.00126"
"34.00800","2.83426","0.00143"
"34.08600","2.84072","0.00131"
"34.16400","2.84724","0.00127"
"34.24200","2.85369","0.00096"
"34.32000","2.86021","0.00119"
"34.39800","2.86673","0.00064"
"34.47600","2.87319","0.00126"
"34.55400","2.87976","0.00129"
"34.63200","2.88622","0.00114"
"34.71000","2.89274","0.00101"
"34.78800","2.89919","0.00099"
"34.86600","2.90571","0.00151"
"34.94400","2.91217","0.00136"
"35.02200","2.91875","0.00128"
"35.10000","2.92514","0.00150"
"35.17800","2.93172","0.00060"
"35.25600","2.93818","0.00095"
"35.33400","2.94463","0.00133"
"35.41200","2.95121","0.00097"
"35.49000","2.95773","0.00118"
"35.56800","2.96425","0.00134"
"35.64600","2.97070","0.00113"
"35.72400","2.97722","0.00134"
"35.80200","2.98368","0.00158"
"35.88000","2.99019","0.00117"
"35.95800","2.99665","0.00070"
"36.03600","3.00323","0.00153"
"36.11400","3.00969","0.00107"
"36.19200","3.01620","0.00109"
"36.27000","3.02272","0.00143"
"36.34800","3.02918","0.00157"
"36.42600","3.03569","0.00143"
"36.50400","3.04215","0.00114"
"36.58200","3.04879","0.00132"
"36.66000","3.05519","0.00118"
"36.73800","3.06176","0.00195"
"36.81600","3.06822","0.00162"
"36.89400","3.07474","0.00102"
"36.97200","3.08119","0.00127"
"37.05000","3.08771","0.00130"
"37.12800","3.09423","0.00144"
"37.20600","3.10075","0.00115"
"37.28400","3.10720","0.00097"
"37.36200","3.11372","0.00132"
"37.44000","3.12018","0.00137"
"37.51800","3.12663","0.00111"
"37.59600","3.13315","0.00106"
"37.67400","3.13967","0.00113"
"37.75200","3.14618","0.00118"
"37.83000","3.15270","0.00116"
"37.90800","3.15922","0.00130"
"37.98600","3.16568","0.00167"
"38.06400","3.17213","0.00118"
"38.14200","3.17871","0.00183"
"38.22000","3.18523","0.00095"
"38.29800","3.19174","0.00097"
"38.37600","3.19820","0.00105"
"38.45400","3.20472","0.00138"
"38.53200","3.21118","0.00147"
"38.61000","3.21763","0.00141"
"38.68800","3.22415","0.00106"
"38.76600","3.23073","0.00102"
"38.84400","3.23718","0.00126"
"38.92200","3.24370","0.00126"
"39.00000","3.25022","0.00113"
"39.07800","3.25668","0.00121"
"39.15600","3.26319","0.00140"
"39.23400","3.26965","0.00116"
"39.31200","3.27623","0.00131"
"39.39000","3.28268","0.00099"
"39.46800","3.28920","0.00182"
"39.54600","3.29566","0.00144"
"39.62400","3.30212","0.00164"
"39.70200","3.30863","0.00116"
"39.78000","3.31515","0.00149"
"39.85800","3.32173","0.00158"
"39.93600","3.32818","0.00186"
"40.01400","3.33476","0.00146"
"40.09200","3.34116","0.00119"
"40.17000","3.34768","0.00162"
"40.24800","3.35413","0.00187"
"40.32600","3.36071","0.00120"
"40.40400","3.36723","0.00150"
"40.48200","3.37374","0.00140"
"40.56000","3.38020","0.00237"
"40.63800","3.38666","0.00165"
"40.71600","3.39318","0.00163"
"40.79400","3.39969","0.00119"
"40.87200","3.40615","0.00142"
"40.95000","3.41273","0.00188"
"41.02800","3.41924","0.00181"
"41.10600","3.42576","0.00153"
"41.18400","3.43216","0.00193"
"41.26200","3.43868","0.00189"
"41.34000","3.44519","0.00114"
"41.41800","3.45171","0.00148"
"41.49600","3.45823","0.00153"
"41.57400","3.46474","0.00156"
"41.65200","3.47120","0.00146"
"41.73000","3.47772","0.00175"
"41.80800","3.48418","0.00214"
"41.88600","3.49069","0.00135"
"41.96400","3.49721","0.00189"
"42.04200","3.50379","0.00186"
"42.12000","3.51018","0.00190"
"42.19800","3.51676","0.00162"
"42.27600","3.52322","0.00155"
"42.35400","3.52968","0.00131"
"42.43200","3.53619","0.00141"
"42.51000","3.54271","0.00170"
"42.58800","3.54923","0.00132"
"42.66600","3.55574","0.00166"
"42.74400","3.56220","0.00153"
"42.82200","3.56866","0.00199"
"42.90000","3.57518","0.00155"
"42.97800","3.58169","0.00176"
"43.05600","3.58821","0.00102"
"43.13400","3.59467","0.00165"
"43.21200","3.60124","0.00167"
"43.29000","3.60770","0.00180"
"43.36800","3.61416","0.00163"
"43.44600","3.62067","0.00177"
"43.52400","3.62719","0.00174"
"43.60200","3.63377","0.00131"
"43.68000","3.64017","0.00154"
"43.75800","3.64674","0.00170"
"43.83600","3.65314","0.00162"
"43.91400","3.65966","0.00153"
"43.99200","3.66612","0.00235"
"44.07000","3.67269","0.00173"
"44.14800","3.67921","0.00141"
"44.22600","3.68573","0.00190"
"44.30400","3.69224","0.00145"
"44.38200","3.69870","0.00151"
"44.46000","3.70522","0.00229"
"44.53800","3.71167","0.00145"
"44.61600","3.71819","0.00184"
"44.69400","3.72471","0.00166"
"44.77200","3.73123","0.00210"
"44.85000","3.73768","0.00169"
"44.92800","3.74420","0.00167"
"45.00600","3.75066","0.00164"
"45.08400","3.75717","0.00133"
"45.16200","3.76369","0.00174"
"45.24000","3.77021","0.00130"
"45.31800","3.77673","0.00162"
"45.39600","3.78318","0.00184"
"45.47400","3.78970","0.00221"
"45.55200","3.79610","0.00187"
"45.63000","3.80267","0.00190"
"45.70800","3.80919","0.00164"
"45.78600","3.81577","0.00178"
"45.86400","3.82217","0.00190"
"45.94200","3.82868","0.00185"
"46.02000","3.83520","0.00176"
"46.09800","3.84166","0.00191"
"46.17600","3.84817","0.00172"
"46.25400","3.85469","0.00137"
"46.33200","3.86127","0.00209"
"46.41000","3.86773","0.00176"
"46.48800","3.87424","0.00134"
"46.56600","3.88070","0.00131"
"46.64400","3.88716","0.00166"
"46.72200","3.89367","0.00209"
"46.80000","3.90019","0.00182"
"46.87800","3.90671","0.00154"
"46.95600","3.91322","0.00221"
"47.03400","3.91974","0.00169"
"47.11200","3.92620","0.00193"
"47.19000","3.93272","0.00191"
"47.26800","3.93911","0.00211"
"47.34600","3.94575","0.00189"
"47.42400","3.95221","0.00194"
"47.50200","3.95872","0.00205"
"47.58000","3.96518","0.00173"
"47.65800","3.97170","0.00186"
"47.73600","3.97816","0.00228"
"47.81400","3.98467","0.00203"
"47.89200","3.99119","0.00223"
"47.97000","3.99771","0.00167"
"48.04800","4.00428","0.00207"
"48.12600","4.01068","0.00219"
"48.20400","4.01720","0.00232"
"48.28200","4.02366","0.00254"
"48.36000","4.03017","0.00234"
"48.43800","4.03669","0.00187"
"48.51600","4.04321","0.00241"
"48.59400","4.04972","0.00202"
"48.67200","4.05618","0.00191"
"48.75000","4.06270","0.00202"
"48.82800","4.06916","0.00194"
"48.90600","4.07567","0.00197"
"48.98400","4.08219","0.00217"
"49.06200","4.08871","0.00199"
"49.14000","4.09522","0.00197"
"49.21800","4.10174","0.00181"
"49.29600","4.10820","0.00199"
"49.37400","4.11472","0.00221"
"49.45200","4.12117","0.00192"
"49.53000","4.12775","0.00216"
"49.60800","4.13427","0.00197"
"49.68600","4.14078","0.00180"
"49.76400","4.14724","0.00208"
"49.84200","4.15370","0.00232"
"49.92000","4.16016","0.00188"
"49.99800","4.16667","0.00240"
"50.07600","4.17319","0.00230"
"50.15400","4.17965","0.00199"
"50.23200","4.18622","0.00184"
"50.31000","4.19268","0.00235"
"50.38800","4.19914","0.00260"
"50.46600","4.20560","0.00209"
"50.54400","4.21217","0.00253"
"50.62200","4.21875","0.00203"
"50.70000","4.22521","0.00257"
"50.77800","4.23172","0.00199"
"50.85600","4.23818","0.00248"
"50.93400","4.24476","0.00249"
"51.01200","4.25116","0.00169"
"51.09000","4.25773","0.00219"
"51.16800","4.26419","0.00261"
"51.24600","4.27071","0.00226"
"51.32400","4.27722","0.00247"
"51.40200","4.28368","0.00246"
"51.48000","4.29020","0.00232"
"51.55800","4.29666","0.00241"
"51.63600","4.30323","0.00257"
"51.71400","4.30975","0.00227"
"51.79200","4.31627","0.00205"
"51.87000","4.32272","0.00249"
"51.94800","4.32924","0.00276"
"52.02600","4.33570","0.00276"
"52.10400","4.34221","0.00215"
"52.18200","4.34873","0.00212"
"52.26000","4.35525","0.00212"
"52.33800","4.36171","0.00251"
"52.41600","4.36822","0.00245"
"52.49400","4.37468","0.00213"
"52.57200","4.38120","0.00211"
"52.65000","4.38771","0.00208"
"52.72800","4.39417","0.00206"
"52.80600","4.40075","0.00240"
"52.88400","4.40721","0.00214"
"52.96200","4.41372","0.00212"
"53.04000","4.42018","0.00210"
"53.11800","4.42670","0.00241"
"53.19600","4.43315","0.00209"
"53.27400","4.43967","0.00242"
"53.35200","4.44625","0.00222"
"53.43000","4.45271","0.00228"
"53.50800","4.45922","0.00218"
"53.58600","4.46568","0.00237"
"53.66400","4.47214","0.00251"
"53.74200","4.47871","0.00234"
"53.82000","4.48523","0.00273"
"53.89800","4.49169","0.00218"
"53.97600","4.49821","0.00222"
"54.05400","4.50472","0.00232"
"54.13200","4.51118","0.00232"
"54.21000","4.51764","0.00271"
"54.28800","4.52421","0.00223"
"54.36600","4.53073","0.00281"
"54.44400","4.53725","0.00244"
"54.52200","4.54377","0.00265"
"54.60000","4.55022","0.00216"
"54.67800","4.55668","0.00223"
"54.75600","4.56314","0.00250"
"54.83400","4.56971","0.00226"
"54.91200","4.57623","0.00207"
"54.99000","4.58275","0.00253"
"55.06800","4.58927","0.00264"
"55.14600","4.59566","0.00227"
"55.22400","4.60218","0.00250"
"55.30200","4.60864","0.00272"
"55.38000","4.61521","0.00217"
"55.45800","4.62173","0.00182"
"55.53600","4.62825","0.00270"
"55.61400","4.63471","0.00204"
"55.69200","4.64122","0.00248"
"55.77000","4.64768","0.00198"
"55.84800","4.65414","0.00217"
"55.92600","4.66065","0.00221"
"56.00400","4.66723","0.00214"
"56.08200","4.67375","0.00231"
"56.16000","4.68021","0.00273"
"56.23800","4.68672","0.00217"
"56.31600","4.69318","0.00192"
"56.39400","4.69970","0.00286"
"56.47200","4.70615","0.00257"
"56.55000","4.71273","0.00226"
"56.62800","4.71919","0.00272"
"56.70600","4.72570","0.00271"
"56.78400","4.73216","0.00191"
"56.86200","4.73868","0.00268"
"56.94000","4.74520","0.00270"
"57.01800","4.75171","0.00268"
"57.09600","4.75829","0.00256"
"57.17400","4.76475","0.00275"
"57.25200","4.77126","0.00262"
"57.33000","4.77766","0.00245"
"57.40800","4.78418","0.00231"
"57.48600","4.79064","0.00239"
"57.56400","4.79721","0.00240"
"57.64200","4.80373","0.00276"
"57.72000","4.81025","0.00233"
"57.79800","4.81670","0.00268"
"57.87600","4.82322","0.00295"
"57.95400","4.82962","0.00238"
"58.03200","4.83614","0.00240"
"58.11000","4.84271","0.00283"
"58.18800","4.84917","0.00297"
"58.26600","4.85575","0.00290"
"58.34400","4.86220","0.00258"
"58.42200","4.86872","0.00291"
"58.50000","4.87518","0.00262"
"58.57800","4.88170","0.00305"
"58.65600","4.88821","0.00288"
"58.73400","4.89467","0.00236"
"58.81200","4.90125","0.00252"
"58.89000","4.90770","0.00282"
"58.96800","4.91422","0.00204"
"59.04600","4.92062","0.00283"
"59.12400","4.92720","0.00245"
"59.20200","4.93371","0.00283"
"59.28000","4.94023","0.00292"
"59.35800","4.94675","0.00206"
"59.43600","4.95320","0.00267"
"59.51400","4.95972","0.00290"
"59.59200","4.96618","0.00243"
"59.67000","4.97269","0.00258"
"59.74800","4.97921","0.00266"
"59.82600","4.98573","0.00282"
"59.90400","4.99219","0.00259"
"59.98200","4.99876","0.00276"
"60.06000","5.00516","0.00311"
"60.13800","5.01168","0.00218"
"60.21600","5.01814","0.00256"
"60.29400","5.02471","0.00299"
"60.37200","5.03123","0.00272"
"60.45000","5.03775","0.00328"
"60.52800","5.04420","0.00215"
"60.60600","5.05066","0.00273"
"60.68400","5.05718","0.00318"
"60.76200","5.06364","0.00263"
"60.84000","5.07027","0.00288"
"60.91800","5.07667","0.00299"
"60.99600","5.08319","0.00307"
"61.07400","5.08964","0.00267"
"61.15200","5.09616","0.00301"
"61.23000","5.10268","0.00277"
"61.30800","5.10914","0.00297"
"61.38600","5.11571","0.00289"
"61.46400","5.12223","0.00293"
"61.54200","5.12869","0.00287"
"61.62000","5.13520","0.00287"
"61.69800","5.14166","0.00276"
"61.77600","5.14818","0.00262"
"61.85400","5.15469","0.00302"
"61.93200","5.16121","0.00292"
"62.01000","5.16773","0.00291"
"62.08800","5.17425","0.00341"
"62.16600","5.18064","0.00300"
"62.24400","5.18716","0.00324"
"62.32200","5.19368","0.00347"
"62.40000","5.20025","0.00288"
"62.47800","5.20671","0.00290"
"62.55600","5.21329","0.00312"
"62.63400","5.21975","0.00268"
"62.71200","5.22620","0.00289"
"62.79000","5.23260","0.00331"
"62.86800","5.23918","0.00280"
"62.94600","5.24569","0.00315"
"63.02400","5.25221","0.00293"
"63.10200","5.25873","0.00361"
"63.18000","5.26519","0.00322"
"63.25800","5.27164","0.00317"
"63.33600","5.27810","0.00325"
"63.41400","5.28468","0.00318"
"63.49200","5.29119","0.00304"
"63.57000","5.29777","0.00349"
"63.64800","5.30417","0.00333"
"63.72600","5.31075","0.00387"
"63.80400","5.31714","0.00304"
"63.88200","5.32366","0.00365"
"63.96000","5.33018","0.00395"
"64.03800","5.33675","0.00322"
"64.11600","5.34327","0.00334"
"64.19400","5.34973","0.00312"
"64.27200","5.35625","0.00340"
"64.35000","5.36270","0.00387"
"64.42800","5.36916","0.00335"
"64.50600","5.37568","0.00348"
"64.58400","5.38225","0.00328"
"64.66200","5.38871","0.00334"
"64.74000","5.39523","0.00305"
"64.81800","5.40169","0.00365"
"64.89600","5.40820","0.00373"
"64.97400","5.41472","0.00352"
"65.05200","5.42124","0.00379"
"65.13000","5.42775","0.00343"
"65.20800","5.43421","0.00318"
"65.28600","5.44073","0.00348"
"65.36400","5.44719","0.00378"
"65.44200","5.45364","0.00309"
"65.52000","5.46016","0.00366"
"65.59800","5.46668","0.00319"
"65.67600","5.47319","0.00310"
"65.75400","5.47971","0.00353"
"65.83200","5.48623","0.00283"
"65.91000","5.49274","0.00311"
"65.98800","5.49920","0.00343"
"66.06600","5.50566","0.00319"
"66.14400","5.51218","0.00308"
"66.22200","5.51869","0.00371"
"66.30000","5.52527","0.00345"
"66.37800","5.53173","0.00309"
"66.45600","5.53824","0.00321"
"66.53400","5.54464","0.00396"
"66.61200","5.55116","0.00361"
"66.69000","5.55768","0.00356"
"66.76800","5.56419","0.00370"
"66.84600","5.57077","0.00358"
"66.92400","5.57723","0.00394"
"67.00200","5.58374","0.00322"
"67.08000","5.59020","0.00336"
"67.15800","5.59672","0.00372"
"67.23600","5.60324","0.00316"
"67.31400","5.60975","0.00405"
"67.39200","5.61621","0.00335"
"67.47000","5.62273","0.00375"
"67.54800","5.62918","0.00354"
"67.62600","5.63564","0.00336"
"67.70400","5.64216","0.00394"
"67.78200","5.64868","0.00415"
"67.86000","5.65525","0.00348"
"67.93800","5.66171","0.00327"
"68.01600","5.66823","0.00405"
"68.09400","5.67468","0.00386"
"68.17200","5.68120","0.00378"
"68.25000","5.68766","0.00363"
"68.32800","5.69418","0.00401"
"68.40600","5.70075","0.00390"
"68.48400","5.70721","0.00345"
"68.56200","5.71373","0.00337"
"68.64000","5.72012","0.00392"
"68.71800","5.72670","0.00390"
"68.79600","5.73316","0.00425"
"68.87400","5.73974","0.00401"
"68.95200","5.74619","0.00393"
"69.03000","5.75271","0.00396"
"69.10800","5.75923","0.00395"
"69.18600","5.76568","0.00404"
"69.26400","5.77220","0.00415"
"69.34200","5.77872","0.00397"
"69.42000","5.78524","0.00411"
"69.49800","5.79169","0.00402"
"69.57600","5.79821","0.00390"
"69.65400","5.80473","0.00394"
"69.73200","5.81118","0.00399"
"69.81000","5.81770","0.00398"
"69.88800","5.82422","0.00401"
"69.96600","5.83074","0.00408"
"70.04400","5.83725","0.00375"
"70.12200","5.84371","0.00404"
"70.20000","5.85017","0.00406"
"70.27800","5.85668","0.00377"
"70.35600","5.86314","0.00433"
"70.43400","5.86972","0.00441"
"70.51200","5.87624","0.00444"
"70.59000","5.88275","0.00440"
"70.66800","5.88921","0.00490"
"70.74600","5.89573","0.00392"
"70.82400","5.90212","0.00440"
"70.90200","5.90864","0.00451"
"70.98000","5.91516","0.00429"
"71.05800","5.92173","0.00458"
"71.13600","5.92819","0.00475"
"71.21400","5.93471","0.00419"
"71.29200","5.94123","0.00473"
"71.37000","5.94768","0.00402"
"71.44800","5.95414","0.00507"
"71.52600","5.96066","0.00439"
"71.60400","5.96729","0.00465"
"71.68200","5.97369","0.00436"
"71.76000","5.98021","0.00488"
"71.83800","5.98667","0.00504"
"71.91600","5.99318","0.00483"
"71.99400","5.99964","0.00474"
"72.07200","6.00616","0.00486"
"72.15000","6.01273","0.00480"
"72.22800","6.01919","0.00488"
"72.30600","6.02577","0.00507"
"72.38400","6.03217","0.00507"
"72.46200","6.03868","0.00509"
"72.54000","6.04514","0.00484"
"72.61800","6.05172","0.00482"
"72.69600","6.05817","0.00439"
"72.77400","6.06475","0.00536"
"72.85200","6.07121","0.00435"
"72.93000","6.07773","0.00494"
"73.00800","6.08418","0.00521"
"73.08600","6.09064","0.00484"
"73.16400","6.09722","0.00471"
"73.24200","6.10373","0.00501"
"73.32000","6.11025","0.00514"
"73.39800","6.11671","0.00483"
"73.47600","6.12323","0.00524"
"73.55400","6.12962","0.00508"
"73.63200","6.13620","0.00516"
"73.71000","6.14272","0.00500"
"73.78800","6.14923","0.00518"
"73.86600","6.15575","0.00526"
"73.94400","6.16221","0.00564"
"74.02200","6.16873","0.00532"
"74.10000","6.17512","0.00562"
"74.17800","6.18170","0.00516"
"74.25600","6.18816","0.00554"
"74.33400","6.19473","0.00550"
"74.41200","6.20125","0.00525"
"74.49000","6.20771","0.00582"
"74.56800","6.21417","0.00581"
"74.64600","6.22062","0.00520"
"74.72400","6.22720","0.00586"
"74.80200","6.23372","0.00619"
"74.88000","6.24023","0.00555"
"74.95800","6.24675","0.00590"
"75.03600","6.25321","0.00582"
"75.11400","6.25967","0.00560"
"75.19200","6.26618","0.00557"
"75.27000","6.27270","0.00604"
"75.34800","6.27922","0.00584"
"75.42600","6.28573","0.00555"
"75.50400","6.29225","0.00577"
"75.58200","6.29871","0.00543"
"75.66000","6.30517","0.00612"
"75.73800","6.31168","0.00598"
"75.81600","6.31820","0.00607"
"75.89400","6.32472","0.00559"
"75.97200","6.33117","0.00597"
"76.05000","6.33775","0.00554"
"76.12800","6.34415","0.00592"
"76.20600","6.35067","0.00593"
"76.28400","6.35712","0.00585"
"76.36200","6.36370","0.00596"
"76.44000","6.37022","0.00581"
"76.51800","6.37667","0.00617"
"76.59600","6.38319","0.00565"
"76.67400","6.38971","0.00587"
"76.75200","6.39622","0.00594"
"76.83000","6.40262","0.00597"
"76.90800","6.40920","0.00623"
"76.98600","6.41572","0.00592"
"77.06400","6.42217","0.00611"
"77.14200","6.42869","0.00596"
"77.22000","6.43521","0.00602"
"77.29800","6.44172","0.00619"
"77.37600","6.44818","0.00601"
"77.45400","6.45470","0.00613"
"77.53200","6.46122","0.00633"
"77.61000","6.46773","0.00624"
"77.68800","6.47425","0.00622"
"77.76600","6.48077","0.00634"
"77.84400","6.48716","0.00624"
"77.92200","6.49368","0.00616"
"78.00000","6.50020","0.00626"
"78.07800","6.50678","0.00582"
"78.15600","6.51317","0.00624"
"78.23400","6.51969","0.00613"
"78.31200","6.52621","0.00632"
"78.39000","6.53266","0.00636"
"78.46800","6.53918","0.00620"
"78.54600","6.54576","0.00632"
"78.62400","6.55222","0.00653"
"78.70200","6.55873","0.00637"
"78.78000","6.56519","0.00640"
"78.85800","6.57165","0.00668"
"78.93600","6.57822","0.00627"
"79.01400","6.58468","0.00658"
"79.09200","6.59120","0.00660"
"79.17000","6.59771","0.00676"
"79.24800","6.60423","0.00658"
"79.32600","6.61075","0.00638"
"79.40400","6.61715","0.00674"
"79.48200","6.62366","0.00663"
"79.56000","6.63018","0.00642"
"79.63800","6.63676","0.00673"
"79.71600","6.64321","0.00663"
"79.79400","6.64973","0.00628"
"79.87200","6.65619","0.00685"
"79.95000","6.66271","0.00678"
"80.02800","6.66916","0.00663"
"80.10600","6.67568","0.00693"
"80.18400","6.68226","0.00667"
"80.26200","6.68871","0.00684"
"80.34000","6.69523","0.00668"
"80.41800","6.70169","0.00689"
"80.49600","6.70821","0.00708"
"80.57400","6.71460","0.00678"
"80.65200","6.72124","0.00662"
"80.73000","6.72770","0.00701"
"80.80800","6.73421","0.00740"
"80.88600","6.74073","0.00746"
"80.96400","6.74725","0.00699"
"81.04200","6.75371","0.00714"
"81.12000","6.76016","0.00759"
"81.19800","6.76668","0.00734"
"81.27600","6.77326","0.00701"
"81.35400","6.77971","0.00755"
"81.43200","6.78617","0.00738"
"81.51000","6.79275","0.00741"
"81.58800","6.79915","0.00745"
"81.66600","6.80560","0.00745"
"81.74400","6.81218","0.00709"
"81.82200","6.81876","0.00719"
"81.90000","6.82527","0.00739"
"81.97800","6.83173","0.00767"
"82.05600","6.83825","0.00746"
"82.13400","6.84471","0.00724"
"82.21200","6.85116","0.00717"
"82.29000","6.85768","0.00705"
"82.36800","6.86420","0.00734"
"82.44600","6.87077","0.00758"
"82.52400","6.87723","0.00772"
"82.60200","6.88369","0.00753"
"82.68000","6.89021","0.00751"
"82.75800","6.89666","0.00725"
"82.83600","6.90318","0.00726"
"82.91400","6.90970","0.00782"
"82.99200","6.91621","0.00756"
"83.07000","6.92273","0.00768"
"83.14800","6.92919","0.00735"
"83.22600","6.93571","0.00761"
"83.30400","6.94210","0.00766"
"83.38200","6.94868","0.00765"
"83.46000","6.95520","0.00792"
"83.53800","6.96171","0.00767"
"83.61600","6.96817","0.00794"
"83.69400","6.97469","0.00793"
"83.77200","6.98121","0.00790"
"83.85000","6.98760","0.00813"
"83.92800","6.99418","0.00789"
"84.00600","7.00070","0.00791"
"84.08400","7.00727","0.00811"
"84.16200","7.01367","0.00798"
"84.24000","7.02019","0.00800"
"84.31800","7.02665","0.00822"
"84.39600","7.03322","0.00826"
"84.47400","7.03974","0.00816"
"84.55200","7.04620","0.00868"
"84.63000","7.05271","0.00865"
"84.70800","7.05923","0.00821"
"84.78600","7.06575","0.00849"
"84.86400","7.07214","0.00830"
"84.94200","7.07872","0.00853"
"85.02000","7.08524","0.00855"
"85.09800","7.09176","0.00865"
"85.17600","7.09821","0.00842"
"85.25400","7.10473","0.00885"
"85.33200","7.11119","0.00893"
"85.41000","7.11770","0.00891"
"85.48800","7.12416","0.00891"
"85.56600","7.13068","0.00880"
"85.64400","7.13726","0.00914"
"85.72200","7.14371","0.00919"
"85.80000","7.15023","0.00918"
"85.87800","7.15669","0.00924"
"85.95600","7.16320","0.00907"
"86.03400","7.16966","0.00928"
"86.11200","7.17618","0.00931"
"86.19000","7.18264","0.00947"
"86.26800","7.18921","0.00910"
"86.34600","7.19567","0.00935"
"86.42400","7.20219","0.00926"
"86.50200","7.20864","0.00930"
"86.58000","7.21522","0.00930"
"86.65800","7.22168","0.00952"
"86.73600","7.22820","0.00916"
"86.81400","7.23471","0.00952"
"86.89200","7.24117","0.00937"
"86.97000","7.24769","0.00937"
"87.04800","7.25415","0.00976"
"87.12600","7.26072","0.00982"
"87.20400","7.26724","0.00959"
"87.28200","7.27370","0.00958"
"87.36000","7.28021","0.00970"
"87.43800","7.28667","0.01005"
"87.51600","7.29319","0.00977"
"87.59400","7.29964","0.01001"
"87.67200","7.30622","0.01036"
"87.75000","7.31268","0.01013"
"87.82800","7.31920","0.00985"
"87.90600","7.32571","0.01026"
"87.98400","7.33223","0.01012"
"88.06200","7.33869","0.00983"
"88.14000","7.34514","0.01012"
"88.21800","7.35172","0.01022"
"88.29600","7.35818","0.01022"
"88.37400","7.36476","0.01059"
"88.45200","7.37121","0.01013"
"88.53000","7.37773","0.01042"
"88.60800","7.38413","0.01033"
"88.68600","7.39070","0.01043"
"88.76400","7.39722","0.01027"
"88.84200","7.40374","0.01057"
"88.92000","7.41020","0.01078"
"88.99800","7.41665","0.01060"
"89.07600","7.42317","0.01077"
"89.15400","7.42963","0.01053"
"89.23200","7.43614","0.01067"
"89.31000","7.44272","0.01095"
"89.38800","7.44930","0.01101"
"89.46600","7.45570","0.01115"
"89.54400","7.46227","0.01100"
"89.62200","7.46867","0.01119"
"89.70000","7.47513","0.01111"
"89.77800","7.48164","0.01134"
"89.85600","7.48822","0.01108"
"89.93400","7.49474","0.01103"
"90.01200","7.50125","0.01142"
"90.09000","7.50771","0.01129"
"90.16800","7.51423","0.01132"
"90.24600","7.52063","0.01162"
"90.32400","7.52720","0.01117"
"90.40200","7.53372","0.01168"
"90.48000","7.54030","0.01174"
"90.55800","7.54669","0.01162"
"90.63600","7.55321","0.01148"
"90.71400","7.55967","0.01193"
"90.79200","7.56619","0.01168"
"90.87000","7.57264","0.01178"
"90.94800","7.57916","0.01146"
"91.02600","7.58574","0.01205"
"91.10400","7.59225","0.01189"
"91.18200","7.59865","0.01201"
"91.26000","7.60523","0.01220"
"91.33800","7.61163","0.01223"
"91.41600","7.61820","0.01245"
"91.49400","7.62466","0.01209"
"91.57200","7.63124","0.01214"
"91.65000","7.63775","0.01233"
"91.72800","7.64421","0.01249"
"91.80600","7.65073","0.01225"
"91.88400","7.65713","0.01272"
"91.96200","7.66376","0.01262"
"92.04000","7.67022","0.01256"
"92.11800","7.67674","0.01282"
"92.19600","7.68319","0.01267"
"92.27400","7.68971","0.01273"
"92.35200","7.69617","0.01288"
"92.43000","7.70269","0.01292"
"92.50800","7.70914","0.01295"
"92.58600","7.71572","0.01298"
"92.66400","7.72224","0.01328"
"92.74200","7.72869","0.01327"
"92.82000","7.73521","0.01328"
"92.89800","7.74167","0.01331"
"92.97600","7.74819","0.01316"
"93.05400","7.75470","0.01337"
"93.13200","7.76128","0.01345"
"93.21000","7.76768","0.01328"
"93.28800","7.77425","0.01363"
"93.36600","7.78065","0.01361"
"93.44400","7.78717","0.01372"
"93.52200","7.79363","0.01387"
"93.60000","7.80020","0.01370"
"93.67800","7.80672","0.01405"
"93.75600","7.81318","0.01353"
"93.83400","7.81969","0.01420"
"93.91200","7.82621","0.01392"
"93.99000","7.83267","0.01366"
"94.06800","7.83919","0.01378"
"94.14600","7.84570","0.01384"
"94.22400","7.85222","0.01389"
"94.30200","7.85868","0.01400"
"94.38000","7.86519","0.01409"
"94.45800","7.87171","0.01416"
"94.53600","7.87817","0.01459"
"94.61400","7.88463","0.01442"
"94.69200","7.89120","0.01435"
"94.77000","7.89772","0.01458"
"94.84800","7.90424","0.01444"
"94.92600","7.91069","0.01494"
"95.00400","7.91721","0.01502"
"95.08200","7.92367","0.01498"
"95.16000","7.93018","0.01550"
"95.23800","7.93670","0.01521"
"95.31600","7.94322","0.01526"
"95.39400","7.94974","0.01556"
"95.47200","7.95619","0.01555"
"95.55000","7.96271","0.01563"
"95.62800","7.96917","0.01568"
"95.70600","7.97568","0.01592"
"95.78400","7.98220","0.01600"
"95.86200","7.98878","0.01584"
"95.94000","7.99524","0.01578"
"96.01800","8.00169","0.01619"
"96.09600","8.00821","0.01625"
"96.17400","8.01461","0.01658"
"96.25200","8.02118","0.01643"
"96.33000","8.02770","0.01649"
"96.40800","8.03422","0.01664"
"96.48600","8.04074","0.01687"
"96.56400","8.04719","0.01690"
"96.64200","8.05365","0.01682"
"96.72000","8.06017","0.01702"
"96.79800","8.06668","0.01689"
"96.87600","8.07326","0.01694"
"96.95400","8.07972","0.01737"
"97.03200","8.08618","0.01770"
"97.11000","8.09275","0.01791"
"97.18800","8.09921","0.01775"
"97.26600","8.10567","0.01793"
"97.34400","8.11218","0.01788"
"97.42200","8.11876","0.01803"
"97.50000","8.12522","0.01778"
"97.57800","8.13173","0.01773"
"97.65600","8.13819","0.01822"
"97.73400","8.14465","0.01884"
"97.81200","8.15117","0.01801"
"97.89000","8.15768","0.01823"
"97.96800","8.16426","0.01854"
"98.04600","8.17072","0.01868"
"98.12400","8.17723","0.01843"
"98.20200","8.18369","0.01822"
"98.28000","8.19015","0.01284"
"98.35800","8.19667","0.01126"
"98.43600","8.20324","0.01124"
"98.51400","8.20970","0.01071"
"98.59200","8.21622","0.01120"
"98.67000","8.22268","0.01099"
"98.74800","8.22919","0.01144"
"98.82600","8.23565","0.01226"
"98.90400","8.24211","0.01213"
"98.98200","8.24868","0.01183"
"99.06000","8.25526","0.01070"
"99.13800","8.26178","0.01111"
"99.21600","8.26823","0.01126"
"99.29400","8.27475","0.01271"
"99.37200","8.28121","0.01265"
"99.45000","8.28773","0.01212"
"99.52800","8.29418","0.01163"
"99.60600","8.30076","0.01174"
"99.68400","8.30722","0.01176"
"99.76200","8.31373","0.01203"
"99.84000","8.32019","0.01260"
"99.91800","8.32665","0.01257"
"99.99600","8.33323","0.01266"
"100.07400","8.33968","0.01282"
"100.15200","8.34626","0.01226"
"100.23000","8.35272","0.01240"
"100.30800","8.35929","0.01234"
"100.38600","8.36569","0.01297"
"100.46400","8.37215","0.01322"
"100.54200","8.37867","0.01293"
"100.62000","8.38524","0.01289"
"100.69800","8.39176","0.01246"
"100.77600","8.39822","0.01265"
"100.85400","8.40473","0.01278"
"100.93200","8.41119","0.01353"
"101.01000","8.41771","0.01367"
"101.08800","8.42417","0.01343"
"101.16600","8.43074","0.01346"
"101.24400","8.43720","0.01300"
"101.32200","8.44372","0.01296"
"101.40000","8.45017","0.01352"
"101.47800","8.45669","0.01374"
"101.55600","8.46315","0.01337"
"101.63400","8.46967","0.01327"
"101.71200","8.47618","0.01293"
"101.79000","8.48264","0.01308"
"101.86800","8.48922","0.01272"
"101.94600","8.49573","0.01288"
"102.02400","8.50219","0.01310"
"102.10200","8.50859","0.01360"
"102.18000","8.51522","0.01376"
"102.25800","8.52168","0.01302"
"102.33600","8.52826","0.01293"
"102.41400","8.53472","0.01245"
"102.49200","8.54117","0.01267"
"102.57000","8.54775","0.01347"
"102.64800","8.55415","0.01106"
"102.72600","8.56073","0.01106"
"102.80400","8.56724","0.01122"
"102.88200","8.57376","0.01200"
"102.96000","8.58022","0.01090"
"103.03800","8.58673","0.01056"
"103.11600","8.59319","0.01015"
"103.19400","8.59971","0.01053"
"103.27200","8.60623","0.01172"
"103.35000","8.61274","0.01211"
"103.42800","8.61926","0.01212"
"103.50600","8.62572","0.01112"
"103.58400","8.63223","0.01064"
"103.66200","8.63869","0.01110"
"103.74000","8.64521","0.01181"
"103.81800","8.65172","0.01201"
"103.89600","8.65830","0.01283"
"103.97400","8.66470","0.01213"
"104.05200","8.67122","0.01098"
"104.13000","8.67767","0.01102"
"104.20800","8.68419","0.01159"
"104.28600","8.69065","0.01229"
"104.36400","8.69717","0.01295"
"104.44200","8.70374","0.01275"
"104.52000","8.71020","0.01259"
"104.59800","8.71672","0.01166"
"104.67600","8.72311","0.01177"
"104.75400","8.72975","0.01233"
"104.83200","8.73615","0.01312"
"104.91000","8.74267","0.01324"
"104.98800","8.74924","0.01304"
"105.06600","8.75570","0.01229"
"105.14400","8.76222","0.01212"
"105.22200","8.76867","0.01281"
"105.30000","8.77519","0.01259"
"105.37800","8.78171","0.01333"
"105.45600","8.78822","0.01341"
"105.53400","8.79474","0.01329"
"105.61200","8.80120","0.01283"
"105.69000","8.80778","0.01297"
"105.76800","8.81417","0.01297"
"105.84600","8.82069","0.01323"
"105.92400","8.82721","0.01347"
"106.00200","8.83372","0.01305"
"106.08000","8.84024","0.00167"
"106.15800","8.84670","0.00187"
"106.23600","8.85316","0.00308"
"106.31400","8.85967","0.00298"
"106.39200","8.86613","0.00424"
"106.47000","8.87271","0.00175"
"106.54800","8.87922","0.00105"
"106.62600","8.88574","0.00020"
"106.70400","8.89220","0.00033"
"106.78200","8.89878","0.00020"
"106.86000","8.90517","0.00161"
"106.93800","8.91169","0.00103"
"107.01600","8.91821","0.00180"
"107.09400","8.92472","0.00206"
"107.17200","8.93124","0.00142"
"107.25000","8.93776","0.00110"
"107.32800","8.94421","0.00026"
"107.40600","8.95061","0.00141"
"107.48400","8.95713","0.00065"
"107.56200","8.96365","0.00185"
"107.64000","8.97022","0.00158"
"107.71800","8.97668","0.00197"
"107.79600","8.98320","0.00076"
"107.87400","8.98971","0.00096"
"107.95200","8.99617","0.00109"
"108.03000","9.00269","0.00130"
"108.10800","9.00921","0.00079"
"108.18600","9.01572","0.00138"
"108.26400","9.02224","0.00147"
"108.34200","9.02876","0.00136"
"108.42000","9.03516","0.00110"
"108.49800","9.04167","0.00124"
"108.57600","9.04813","0.00132"
"108.65400","9.05471","0.00127"
"108.73200","9.06122","0.00100"
"108.81000","9.06768","0.00106"
"108.88800","9.07426","0.00153"
"108.96600","9.08066","0.00150"
"109.04400","9.08717","0.00148"
"109.12200","9.09363","0.00158"
"109.20000","9.10021","0.00157"
"109.27800","9.10672","0.00088"
"109.35600","9.11324","0.00126"
"109.43400","9.11970","0.00115"
"109.51200","9.12621","0.00110"
"109.59000","9.13267","0.00128"
"109.66800","9.13919","0.00133"
"109.74600","9.14571","0.00165"
"109.82400","9.15222","0.00099"
"109.90200","9.15874","0.00169"
"109.98000","9.16526","0.00133"
"110.05800","9.17171","0.00175"
"110.13600","9.17817","0.00163"
"110.21400","9.18469","0.00226"
"110.29200","9.19121","0.00153"
"110.37000","9.19772","0.00132"
"110.44800","9.20418","0.00147"
"110.52600","9.21070","0.00163"
"110.60400","9.21721","0.00197"
"110.68200","9.22367","0.00128"
"110.76000","9.23019","0.00214"
"110.83800","9.23671","0.00147"
"110.91600","9.24322","0.00127"
"110.99400","9.24974","0.00132"
"111.07200","9.25620","0.00152"
"111.15000","9.26271","0.00199"
"111.22800","9.26917","0.00183"
"111.30600","9.27569","0.00151"
"111.38400","9.28221","0.00167"
"111.46200","9.28872","0.00174"
"111.54000","9.29518","0.00105"
"111.61800","9.30170","0.00169"
"111.69600","9.30815","0.00135"
"111.77400","9.31467","0.00171"
"111.85200","9.32113","0.00142"
"111.93000","9.32776","0.00132"
"112.00800","9.33422","0.00165"
"112.08600","9.34074","0.00153"
"112.16400","9.34720","0.00177"
"112.24200","9.35371","0.00175"
"112.32000","9.36017","0.00137"
"112.39800","9.36669","0.00191"
"112.47600","9.37327","0.00210"
"112.55400","9.37972","0.00141"
"112.63200","9.38624","0.00136"
"112.71000","9.39264","0.00160"
"112.78800","9.39921","0.00164"
"112.86600","9.40561","0.00215"
"112.94400","9.41219","0.00193"
"113.02200","9.41870","0.00177"
"113.10000","9.42522","0.00165"
"113.17800","9.43174","0.00158"
"113.25600","9.43820","0.00148"
"113.33400","9.44471","0.00165"
"113.41200","9.45117","0.00157"
"113.49000","9.45775","0.00136"
"113.56800","9.46420","0.00171"
"113.64600","9.47072","0.00195"
"113.72400","9.47724","0.00168"
"113.80200","9.48370","0.00200"
"113.88000","9.49015","0.00171"
"113.95800","9.49667","0.00171"
"114.03600","9.50319","0.00166"
"114.11400","9.50976","0.00228"
"114.19200","9.51622","0.00151"
"114.27000","9.52268","0.00216"
"114.34800","9.52926","0.00177"
"114.35800","9.53003","0.00179"