File: Force_trajectories/161226_1/Specimen_RawData_9.csv
End date,"12/26/2016"
Specimen label,"13AT_2"
Maximum Load,"0.10271",N

Time,Extension,Load
(s),(mm),(N)
"0.00000","0.00000","0.00010"
"0.28200","0.02272","0.00002"
"0.56400","0.04723","0.00073"
"0.84600","0.07067","0.00004"
"1.12800","0.09417","0.00007"
"1.41000","0.11761","0.00080"
"1.69200","0.14116","0.00055"
"1.97400","0.16466","0.00057"
"2.25600","0.18816","0.00097"
"2.53800","0.21171","0.00059"
"2.82000","0.23521","0.00088"
"3.10200","0.25871","0.00062"
"3.38400","0.28215","0.00065"
"3.66600","0.30576","0.00089"
"3.94800","0.32908","0.00071"
"4.23000","0.35264","0.00024"
"4.51200","0.37614","0.00106"
"4.79400","0.39975","0.00099"
"5.07600","0.42319","0.00047"
"5.35800","0.44669","0.00081"
"5.64000","0.47013","0.00068"
"5.92200","0.49368","0.00094"
"6.20400","0.51706","0.00068"
"6.48600","0.54068","0.00100"
"6.76800","0.56411","0.00107"
"7.05000","0.58767","0.00086"
"7.33200","0.61111","0.00111"
"7.61400","0.63467","0.00088"
"7.89600","0.65816","0.00151"
"8.17800","0.68166","0.00084"
"8.46000","0.70516","0.00118"
"8.74200","0.72866","0.00141"
"9.02400","0.75215","0.00096"
"9.30600","0.77565","0.00144"
"9.58800","0.79915","0.00121"
"9.87000","0.82264","0.00109"
"10.15200","0.84614","0.00089"
"10.43400","0.86964","0.00091"
"10.71600","0.89320","0.00060"
"10.99800","0.91669","0.00054"
"11.28000","0.94025","-0.00004"
"11.56200","0.96369","0.00085"
"11.84400","0.98718","0.00012"
"12.12600","1.01068","0.00061"
"12.40800","1.03424","0.00045"
"12.69000","1.05774","0.00078"
"12.97200","1.08117","0.00045"
"13.25400","1.10467","0.00103"
"13.53600","1.12817","0.00084"
"13.81800","1.15161","0.00079"
"14.10000","1.17516","0.00116"
"14.38200","1.19866","0.00116"
"14.66400","1.22210","0.00081"
"14.94600","1.24571","0.00045"
"15.22800","1.26915","0.00054"
"15.51000","1.29265","0.00066"
"15.79200","1.31609","0.00044"
"16.07400","1.33964","0.00094"
"16.35600","1.36308","0.00063"
"16.63800","1.38664","0.00090"
"16.92000","1.41014","0.00070"
"17.20200","1.43369","0.00071"
"17.48400","1.45719","0.00085"
"17.76600","1.48069","0.00095"
"18.04800","1.50413","0.00051"
"18.33000","1.52768","0.00044"
"18.61200","1.55118","0.00086"
"18.89400","1.57468","0.00059"
"19.17600","1.59817","0.00042"
"19.45800","1.62173","0.00043"
"19.74000","1.64523","0.00079"
"20.02200","1.66873","0.00049"
"20.30400","1.69222","0.00087"
"20.58600","1.71566","0.00108"
"20.86800","1.73922","0.00085"
"21.15000","1.76266","0.00091"
"21.43200","1.78615","0.00029"
"21.71400","1.80965","0.00095"
"21.99600","1.83321","0.00112"
"22.27800","1.85658","0.00090"
"22.56000","1.88020","0.00110"
"22.84200","1.90358","0.00091"
"23.12400","1.92726","0.00077"
"23.40600","1.95063","0.00060"
"23.68800","1.97419","0.00125"
"23.97000","1.99763","0.00149"
"24.25200","2.02119","0.00106"
"24.53400","2.04468","0.00105"
"24.81600","2.06818","0.00099"
"25.09800","2.09168","0.00172"
"25.38000","2.11517","0.00151"
"25.66200","2.13867","0.00110"
"25.94400","2.16217","0.00084"
"26.22600","2.18567","0.00115"
"26.50800","2.20916","0.00135"
"26.79000","2.23272","0.00152"
"27.07200","2.25616","0.00133"
"27.35400","2.27972","0.00115"
"27.63600","2.30315","0.00123"
"27.91800","2.32671","0.00079"
"28.20000","2.35015","0.00096"
"28.48200","2.37370","0.00185"
"28.76400","2.39714","0.00092"
"29.04600","2.42070","0.00153"
"29.32800","2.44414","0.00199"
"29.61000","2.46769","0.00099"
"29.89200","2.49113","0.00130"
"30.17400","2.51469","0.00111"
"30.45600","2.53813","0.00103"
"30.73800","2.56168","0.00095"
"31.02000","2.58512","0.00118"
"31.30200","2.60862","0.00198"
"31.58400","2.63217","0.00134"
"31.86600","2.65567","0.00168"
"32.14800","2.67917","0.00170"
"32.43000","2.70267","0.00197"
"32.71200","2.72622","0.00151"
"32.99400","2.74966","0.00147"
"33.27600","2.77316","0.00173"
"33.55800","2.79666","0.00167"
"33.84000","2.82021","0.00189"
"34.12200","2.84365","0.00151"
"34.40400","2.86721","0.00198"
"34.68600","2.89064","0.00203"
"34.96800","2.91420","0.00125"
"35.25000","2.93770","0.00158"
"35.53200","2.96120","0.00182"
"35.81400","2.98469","0.00197"
"36.09600","3.00825","0.00198"
"36.37800","3.03169","0.00207"
"36.66000","3.05519","0.00180"
"36.94200","3.07868","0.00157"
"37.22400","3.10218","0.00160"
"37.50600","3.12574","0.00124"
"37.78800","3.14917","0.00168"
"38.07000","3.17273","0.00116"
"38.35200","3.19617","0.00139"
"38.63400","3.21973","0.00205"
"38.91600","3.24316","0.00177"
"39.19800","3.26666","0.00172"
"39.48000","3.29010","0.00226"
"39.76200","3.31366","0.00157"
"40.04400","3.33709","0.00163"
"40.32600","3.36071","0.00160"
"40.60800","3.38415","0.00214"
"40.89000","3.40770","0.00200"
"41.17200","3.43114","0.00191"
"41.45400","3.45476","0.00137"
"41.73600","3.47814","0.00167"
"42.01800","3.50169","0.00165"
"42.30000","3.52513","0.00181"
"42.58200","3.54869","0.00197"
"42.86400","3.57219","0.00144"
"43.14600","3.59568","0.00156"
"43.42800","3.61918","0.00185"
"43.71000","3.64268","0.00142"
"43.99200","3.66623","0.00253"
"44.27400","3.68967","0.00169"
"44.55600","3.71323","0.00181"
"44.83800","3.73667","0.00163"
"45.12000","3.76022","0.00246"
"45.40200","3.78366","0.00203"
"45.68400","3.80716","0.00225"
"45.96600","3.83060","0.00285"
"46.24800","3.85421","0.00239"
"46.53000","3.87765","0.00220"
"46.81200","3.90121","0.00237"
"47.09400","3.92464","0.00232"
"47.37600","3.94814","0.00251"
"47.65800","3.97158","0.00239"
"47.94000","3.99520","0.00159"
"48.22200","4.01863","0.00217"
"48.50400","4.04213","0.00234"
"48.78600","4.06569","0.00209"
"49.06800","4.08919","0.00192"
"49.35000","4.11274","0.00215"
"49.63200","4.13618","0.00208"
"49.91400","4.15974","0.00182"
"50.19600","4.18317","0.00197"
"50.47800","4.20667","0.00204"
"50.76000","4.23011","0.00194"
"51.04200","4.25373","0.00167"
"51.32400","4.27716","0.00173"
"51.60600","4.30072","0.00168"
"51.88800","4.32416","0.00212"
"52.17000","4.34772","0.00233"
"52.45200","4.37115","0.00178"
"52.73400","4.39471","0.00206"
"53.01600","4.41815","0.00189"
"53.29800","4.44165","0.00234"
"53.58000","4.46514","0.00188"
"53.86200","4.48870","0.00273"
"54.14400","4.51220","0.00189"
"54.42600","4.53569","0.00202"
"54.70800","4.55919","0.00229"
"54.99000","4.58263","0.00228"
"55.27200","4.60619","0.00226"
"55.55400","4.62962","0.00189"
"55.83600","4.65318","0.00215"
"56.11800","4.67662","0.00262"
"56.40000","4.70017","0.00269"
"56.68200","4.72361","0.00234"
"56.96400","4.74717","0.00221"
"57.24600","4.77067","0.00272"
"57.52800","4.79422","0.00251"
"57.81000","4.81760","0.00264"
"58.09200","4.84122","0.00268"
"58.37400","4.86460","0.00273"
"58.65600","4.88821","0.00229"
"58.93800","4.91165","0.00257"
"59.22000","4.93521","0.00271"
"59.50200","4.95870","0.00227"
"59.78400","4.98226","0.00274"
"60.06600","5.00564","0.00219"
"60.34800","5.02920","0.00282"
"60.63000","5.05269","0.00234"
"60.91200","5.07619","0.00253"
"61.19400","5.09969","0.00232"
"61.47600","5.12319","0.00247"
"61.75800","5.14668","0.00281"
"62.04000","5.17018","0.00256"
"62.32200","5.19368","0.00254"
"62.60400","5.21712","0.00235"
"62.88600","5.24067","0.00286"
"63.16800","5.26411","0.00246"
"63.45000","5.28767","0.00312"
"63.73200","5.31110","0.00257"
"64.01400","5.33466","0.00269"
"64.29600","5.35810","0.00269"
"64.57800","5.38172","0.00245"
"64.86000","5.40509","0.00237"
"65.14200","5.42871","0.00292"
"65.42400","5.45215","0.00272"
"65.70600","5.47570","0.00234"
"65.98800","5.49914","0.00248"
"66.27000","5.52270","0.00288"
"66.55200","5.54614","0.00248"
"66.83400","5.56969","0.00275"
"67.11600","5.59319","0.00267"
"67.39800","5.61669","0.00247"
"67.68000","5.64019","0.00318"
"67.96200","5.66362","0.00303"
"68.24400","5.68724","0.00296"
"68.52600","5.71068","0.00241"
"68.80800","5.73417","0.00255"
"69.09000","5.75761","0.00314"
"69.37200","5.78117","0.00255"
"69.65400","5.80467","0.00257"
"69.93600","5.82816","0.00241"
"70.21800","5.85166","0.00285"
"70.50000","5.87516","0.00317"
"70.78200","5.89860","0.00295"
"71.06400","5.92221","0.00251"
"71.34600","5.94565","0.00260"
"71.62800","5.96921","0.00285"
"71.91000","5.99265","0.00230"
"72.19200","6.01614","0.00254"
"72.47400","6.03970","0.00307"
"72.75600","6.06320","0.00324"
"73.03800","6.08669","0.00234"
"73.32000","6.11013","0.00300"
"73.60200","6.13369","0.00325"
"73.88400","6.15713","0.00324"
"74.16600","6.18068","0.00298"
"74.44800","6.20418","0.00293"
"74.73000","6.22768","0.00275"
"75.01200","6.25112","0.00238"
"75.29400","6.27467","0.00301"
"75.57600","6.29811","0.00305"
"75.85800","6.32173","0.00330"
"76.14000","6.34516","0.00279"
"76.42200","6.36872","0.00265"
"76.70400","6.39216","0.00341"
"76.98600","6.41572","0.00286"
"77.26800","6.43921","0.00298"
"77.55000","6.46271","0.00349"
"77.83200","6.48615","0.00297"
"78.11400","6.50964","0.00251"
"78.39600","6.53320","0.00349"
"78.67800","6.55664","0.00274"
"78.96000","6.58020","0.00292"
"79.24200","6.60363","0.00337"
"79.52400","6.62719","0.00320"
"79.80600","6.65063","0.00265"
"80.08800","6.67419","0.00336"
"80.37000","6.69756","0.00298"
"80.65200","6.72118","0.00323"
"80.93400","6.74462","0.00299"
"81.21600","6.76818","0.00313"
"81.49800","6.79161","0.00316"
"81.78000","6.81523","0.00336"
"82.06200","6.83861","0.00280"
"82.34400","6.86222","0.00330"
"82.62600","6.88560","0.00341"
"82.90800","6.90916","0.00319"
"83.19000","6.93266","0.00290"
"83.47200","6.95621","0.00298"
"83.75400","6.97971","0.00354"
"84.03600","7.00321","0.00319"
"84.31800","7.02671","0.00343"
"84.60000","7.05020","0.00344"
"84.88200","7.07376","0.00300"
"85.16400","7.09714","0.00312"
"85.44600","7.12069","0.00314"
"85.72800","7.14413","0.00290"
"86.01000","7.16769","0.00280"
"86.29200","7.19113","0.00318"
"86.57400","7.21468","0.00328"
"86.85600","7.23812","0.00313"
"87.13800","7.26168","0.00297"
"87.42000","7.28512","0.00317"
"87.70200","7.30873","0.00302"
"87.98400","7.33211","0.00340"
"88.26600","7.35567","0.00279"
"88.54800","7.37916","0.00244"
"88.83000","7.40266","0.00336"
"89.11200","7.42616","0.00275"
"89.39400","7.44972","0.00290"
"89.67600","7.47315","0.00349"
"89.95800","7.49665","0.00271"
"90.24000","7.52021","0.00296"
"90.52200","7.54371","0.00334"
"90.80400","7.56720","0.00310"
"91.08600","7.59064","0.00307"
"91.36800","7.61420","0.00283"
"91.65000","7.63763","0.00284"
"91.93200","7.66119","0.00280"
"92.21400","7.68463","0.00285"
"92.49600","7.70825","0.00332"
"92.77800","7.73168","0.00337"
"93.06000","7.75518","0.00280"
"93.34200","7.77862","0.00319"
"93.62400","7.80218","0.00272"
"93.90600","7.82567","0.00269"
"94.18800","7.84917","0.00290"
"94.47000","7.87267","0.00347"
"94.75200","7.89616","0.00281"
"95.03400","7.91966","0.00262"
"95.31600","7.94316","0.00325"
"95.59800","7.96666","0.00318"
"95.88000","7.99009","0.00312"
"96.16200","8.01365","0.00348"
"96.44400","8.03709","0.00331"
"96.72600","8.06065","0.00323"
"97.00800","8.08414","0.00296"
"97.29000","8.10770","0.00290"
"97.57200","8.13114","0.00308"
"97.85400","8.15469","0.00326"
"98.13600","8.17813","0.00340"
"98.41800","8.20169","0.00325"
"98.70000","8.22513","0.00298"
"98.98200","8.24874","0.00352"
"99.26400","8.27212","0.00353"
"99.54600","8.29574","0.00304"
"99.82800","8.31917","0.00332"
"100.11000","8.34273","0.00335"
"100.39200","8.36617","0.00364"
"100.67400","8.38973","0.00340"
"100.95600","8.41317","0.00313"
"101.23800","8.43666","0.00291"
"101.52000","8.46016","0.00279"
"101.80200","8.48372","0.00288"
"102.08400","8.50721","0.00275"
"102.36600","8.53065","0.00260"
"102.64800","8.55421","0.00270"
"102.93000","8.57771","0.00277"
"103.21200","8.60120","0.00313"
"103.49400","8.62464","0.00307"
"103.77600","8.64820","0.00346"
"104.05800","8.67163","0.00311"
"104.34000","8.69513","0.00264"
"104.62200","8.71863","0.00347"
"104.90400","8.74219","0.00318"
"105.18600","8.76562","0.00325"
"105.46800","8.78918","0.00313"
"105.75000","8.81262","0.00296"
"106.03200","8.83617","0.00318"
"106.31400","8.85967","0.00292"
"106.59600","8.88317","0.00277"
"106.87800","8.90667","0.00309"
"107.16000","8.93022","0.00337"
"107.44200","8.95366","0.00314"
"107.72400","8.97716","0.00307"
"108.00600","9.00072","0.00311"
"108.28800","9.02421","0.00352"
"108.57000","9.04771","0.00317"
"108.85200","9.07115","0.00324"
"109.13400","9.09471","0.00311"
"109.41600","9.11814","0.00299"
"109.69800","9.14176","0.00321"
"109.98000","9.16520","0.00306"
"110.26200","9.18869","0.00356"
"110.54400","9.21213","0.00309"
"110.82600","9.23569","0.00331"
"111.10800","9.25913","0.00312"
"111.39000","9.28268","0.00326"
"111.67200","9.30612","0.00334"
"111.95400","9.32962","0.00320"
"112.23600","9.35312","0.00297"
"112.51800","9.37667","0.00334"
"112.80000","9.40017","0.00308"
"113.08200","9.42367","0.00339"
"113.36400","9.44716","0.00324"
"113.64600","9.47066","0.00324"
"113.92800","9.49416","0.00337"
"114.21000","9.51766","0.00343"
"114.49200","9.54121","0.00317"
"114.77400","9.56471","0.00292"
"115.05600","9.58821","0.00341"
"115.33800","9.61165","0.00332"
"115.62000","9.63520","0.00306"
"115.90200","9.65864","0.00316"
"116.18400","9.68220","0.00291"
"116.46600","9.70564","0.00306"
"116.74800","9.72925","0.00337"
"117.03000","9.75263","0.00354"
"117.31200","9.77625","0.00329"
"117.59400","9.79968","0.00319"
"117.87600","9.82318","0.00348"
"118.15800","9.84662","0.00347"
"118.44000","9.87018","0.00346"
"118.72200","9.89367","0.00342"
"119.00400","9.91717","0.00399"
"119.28600","9.94067","0.00310"
"119.56800","9.96417","0.00358"
"119.85000","9.98766","0.00363"
"120.13200","10.01116","0.00361"
"120.41400","10.03466","0.00339"
"120.69600","10.05815","0.00363"
"120.97800","10.08165","0.00394"
"121.26000","10.10515","0.00372"
"121.54200","10.12865","0.00379"
"121.82400","10.15214","0.00306"
"122.10600","10.17570","0.00328"
"122.38800","10.19914","0.00366"
"122.67000","10.22269","0.00375"
"122.95200","10.24613","0.00360"
"123.23400","10.26969","0.00351"
"123.51600","10.29319","0.00319"
"123.79800","10.31668","0.00382"
"124.08000","10.34018","0.00333"
"124.36200","10.36374","0.00386"
"124.64400","10.38718","0.00342"
"124.92600","10.41073","0.00367"
"125.20800","10.43423","0.00364"
"125.49000","10.45767","0.00346"
"125.77200","10.48116","0.00379"
"126.05400","10.50466","0.00338"
"126.33600","10.52816","0.00324"
"126.61800","10.55166","0.00397"
"126.90000","10.57521","0.00390"
"127.18200","10.59865","0.00349"
"127.46400","10.62221","0.00340"
"127.74600","10.64565","0.00352"
"128.02800","10.66914","0.00349"
"128.31000","10.69258","0.00369"
"128.59200","10.71614","0.00329"
"128.87400","10.73958","0.00349"
"129.15600","10.76319","0.00330"
"129.43800","10.78669","0.00373"
"129.72000","10.81025","0.00324"
"130.00200","10.83368","0.00376"
"130.28400","10.85718","0.00336"
"130.56600","10.88062","0.00309"
"130.84800","10.90418","0.00307"
"131.13000","10.92767","0.00292"
"131.41200","10.95117","0.00314"
"131.69400","10.97473","0.00319"
"131.97600","10.99817","0.00282"
"132.25800","11.02172","0.00366"
"132.54000","11.04510","0.00286"
"132.82200","11.06872","0.00354"
"133.10400","11.09209","0.00303"
"133.38600","11.11571","0.00321"
"133.66800","11.13915","0.00334"
"133.95000","11.16277","0.00375"
"134.23200","11.18614","0.00339"
"134.51400","11.20970","0.00316"
"134.79600","11.23314","0.00356"
"135.07800","11.25670","0.00314"
"135.36000","11.28013","0.00283"
"135.64200","11.30369","0.00323"
"135.92400","11.32713","0.00317"
"136.20600","11.35069","0.00309"
"136.48800","11.37412","0.00335"
"136.77000","11.39768","0.00309"
"137.05200","11.42118","0.00315"
"137.33400","11.44461","0.00304"
"137.61600","11.46817","0.00322"
"137.89800","11.49167","0.00356"
"138.18000","11.51523","0.00356"
"138.46200","11.53866","0.00347"
"138.74400","11.56222","0.00350"
"139.02600","11.58560","0.00322"
"139.30800","11.60915","0.00342"
"139.59000","11.63265","0.00335"
"139.87200","11.65621","0.00345"
"140.15400","11.67971","0.00303"
"140.43600","11.70326","0.00328"
"140.71800","11.72664","0.00324"
"141.00000","11.75020","0.00341"
"141.28200","11.77364","0.00315"
"141.56400","11.79725","0.00320"
"141.84600","11.82069","0.00348"
"142.12800","11.84419","0.00386"
"142.41000","11.86768","0.00313"
"142.69200","11.89118","0.00335"
"142.97400","11.91468","0.00358"
"143.25600","11.93818","0.00334"
"143.53800","11.96167","0.00330"
"143.82000","11.98511","0.00307"
"144.10200","12.00867","0.00320"
"144.38400","12.03211","0.00318"
"144.66600","12.05566","0.00366"
"144.94800","12.07910","0.00390"
"145.23000","12.10266","0.00331"
"145.51200","12.12609","0.00297"
"145.79400","12.14965","0.00350"
"146.07600","12.17309","0.00357"
"146.35800","12.19671","0.00339"
"146.64000","12.22014","0.00362"
"146.92200","12.24370","0.00320"
"147.20400","12.26714","0.00376"
"147.48600","12.29064","0.00336"
"147.76800","12.31413","0.00358"
"148.05000","12.33769","0.00308"
"148.33200","12.36119","0.00316"
"148.61400","12.38474","0.00316"
"148.89600","12.40824","0.00358"
"149.17800","12.43168","0.00282"
"149.46000","12.45524","0.00338"
"149.74200","12.47867","0.00344"
"150.02400","12.50223","0.00337"
"150.30600","12.52567","0.00368"
"150.58800","12.54917","0.00325"
"150.87000","12.57266","0.00343"
"151.15200","12.59622","0.00342"
"151.43400","12.61960","0.00363"
"151.71600","12.64321","0.00341"
"151.99800","12.66659","0.00361"
"152.28000","12.69021","0.00358"
"152.56200","12.71359","0.00362"
"152.84400","12.73720","0.00340"
"153.12600","12.76064","0.00325"
"153.40800","12.78420","0.00373"
"153.69000","12.80764","0.00361"
"153.97200","12.83119","0.00324"
"154.25400","12.85469","0.00340"
"154.53600","12.87819","0.00346"
"154.81800","12.90168","0.00343"
"155.10000","12.92518","0.00357"
"155.38200","12.94868","0.00369"
"155.66400","12.97218","0.00333"
"155.94600","12.99573","0.00353"
"156.22800","13.01917","0.00341"
"156.51000","13.04273","0.00379"
"156.79200","13.06617","0.00333"
"157.07400","13.08972","0.00316"
"157.35600","13.11316","0.00330"
"157.63800","13.13672","0.00386"
"157.92000","13.16016","0.00376"
"158.20200","13.18371","0.00376"
"158.48400","13.20715","0.00432"
"158.76600","13.23071","0.00389"
"159.04800","13.25420","0.00367"
"159.33000","13.27770","0.00340"
"159.61200","13.30120","0.00387"
"159.89400","13.32464","0.00340"
"160.17600","13.34813","0.00336"
"160.45800","13.37163","0.00337"
"160.74000","13.39519","0.00381"
"161.02200","13.41862","0.00360"
"161.30400","13.44218","0.00383"
"161.58600","13.46568","0.00391"
"161.86800","13.48924","0.00354"
"162.15000","13.51267","0.00381"
"162.43200","13.53617","0.00354"
"162.71400","13.55961","0.00340"
"162.99600","13.58317","0.00320"
"163.27800","13.60666","0.00381"
"163.56000","13.63022","0.00360"
"163.84200","13.65366","0.00361"
"164.12400","13.67722","0.00374"
"164.40600","13.70065","0.00385"
"164.68800","13.72415","0.00391"
"164.97000","13.74771","0.00317"
"165.25200","13.77114","0.00392"
"165.53400","13.79470","0.00336"
"165.81600","13.81820","0.00353"
"166.09800","13.84170","0.00351"
"166.38000","13.86519","0.00359"
"166.66200","13.88875","0.00383"
"166.94400","13.91213","0.00375"
"167.22600","13.93569","0.00391"
"167.50800","13.95918","0.00394"
"167.79000","13.98268","0.00372"
"168.07200","14.00612","0.00448"
"168.35400","14.02967","0.00369"
"168.63600","14.05311","0.00429"
"168.91800","14.07667","0.00374"
"169.20000","14.10011","0.00344"
"169.48200","14.12372","0.00380"
"169.76400","14.14710","0.00347"
"170.04600","14.17072","0.00374"
"170.32800","14.19415","0.00402"
"170.61000","14.21771","0.00371"
"170.89200","14.24115","0.00396"
"171.17400","14.26471","0.00379"
"171.45600","14.28815","0.00352"
"171.73800","14.31164","0.00371"
"172.02000","14.33520","0.00377"
"172.30200","14.35864","0.00378"
"172.58400","14.38219","0.00433"
"172.86600","14.40569","0.00383"
"173.14800","14.42925","0.00397"
"173.43000","14.45263","0.00406"
"173.71200","14.47618","0.00392"
"173.99400","14.49968","0.00376"
"174.27600","14.52324","0.00389"
"174.55800","14.54661","0.00389"
"174.84000","14.57017","0.00381"
"175.12200","14.59361","0.00397"
"175.40400","14.61722","0.00363"
"175.68600","14.64060","0.00410"
"175.96800","14.66422","0.00420"
"176.25000","14.68766","0.00399"
"176.53200","14.71115","0.00394"
"176.81400","14.73459","0.00403"
"177.09600","14.75815","0.00426"
"177.37800","14.78159","0.00358"
"177.66000","14.80514","0.00406"
"177.94200","14.82864","0.00360"
"178.22400","14.85214","0.00401"
"178.50600","14.87570","0.00374"
"178.78800","14.89919","0.00393"
"179.07000","14.92275","0.00366"
"179.35200","14.94619","0.00392"
"179.63400","14.96969","0.00389"
"179.91600","14.99312","0.00386"
"180.19800","15.01668","0.00354"
"180.48000","15.04018","0.00361"
"180.76200","15.06367","0.00391"
"181.04400","15.08717","0.00390"
"181.32600","15.11073","0.00408"
"181.60800","15.13417","0.00417"
"181.89000","15.15766","0.00410"
"182.17200","15.18116","0.00384"
"182.45400","15.20466","0.00424"
"182.73600","15.22816","0.00379"
"183.01800","15.25165","0.00389"
"183.30000","15.27521","0.00382"
"183.58200","15.29871","0.00422"
"183.86400","15.32220","0.00391"
"184.14600","15.34564","0.00445"
"184.42800","15.36920","0.00411"
"184.71000","15.39264","0.00452"
"184.99200","15.41619","0.00417"
"185.27400","15.43963","0.00415"
"185.55600","15.46319","0.00417"
"185.83800","15.48668","0.00411"
"186.12000","15.51018","0.00468"
"186.40200","15.53362","0.00461"
"186.68400","15.55724","0.00471"
"186.96600","15.58067","0.00457"
"187.24800","15.60423","0.00421"
"187.53000","15.62761","0.00462"
"187.81200","15.65123","0.00478"
"188.09400","15.67466","0.00436"
"188.37600","15.69816","0.00426"
"188.65800","15.72166","0.00444"
"188.94000","15.74522","0.00449"
"189.22200","15.76865","0.00487"
"189.50400","15.79221","0.00461"
"189.78600","15.81571","0.00481"
"190.06800","15.83920","0.00470"
"190.35000","15.86270","0.00440"
"190.63200","15.88614","0.00440"
"190.91400","15.90970","0.00438"
"191.19600","15.93319","0.00419"
"191.47800","15.95675","0.00422"
"191.76000","15.98013","0.00456"
"192.04200","16.00368","0.00457"
"192.32400","16.02712","0.00470"
"192.60600","16.05068","0.00489"
"192.88800","16.07406","0.00445"
"193.17000","16.09767","0.00492"
"193.45200","16.12111","0.00461"
"193.73400","16.14473","0.00480"
"194.01600","16.16811","0.00490"
"194.29800","16.19166","0.00485"
"194.58000","16.21516","0.00489"
"194.86200","16.23866","0.00511"
"195.14400","16.26209","0.00481"
"195.42600","16.28565","0.00458"
"195.70800","16.30915","0.00527"
"195.99000","16.33265","0.00499"
"196.27200","16.35620","0.00524"
"196.55400","16.37964","0.00490"
"196.83600","16.40320","0.00525"
"197.11800","16.42664","0.00529"
"197.40000","16.45019","0.00524"
"197.68200","16.47363","0.00496"
"197.96400","16.49719","0.00532"
"198.24600","16.52062","0.00501"
"198.52800","16.54424","0.00525"
"198.81000","16.56768","0.00507"
"199.09200","16.59118","0.00508"
"199.37400","16.61467","0.00518"
"199.65600","16.63817","0.00544"
"199.93800","16.66167","0.00488"
"200.22000","16.68522","0.00499"
"200.50200","16.70872","0.00473"
"200.78400","16.73216","0.00492"
"201.06600","16.75566","0.00527"
"201.34800","16.77909","0.00510"
"201.63000","16.80271","0.00490"
"201.91200","16.82621","0.00515"
"202.19400","16.84977","0.00518"
"202.47600","16.87314","0.00553"
"202.75800","16.89670","0.00508"
"203.04000","16.92014","0.00515"
"203.32200","16.94370","0.00533"
"203.60400","16.96713","0.00562"
"203.88600","16.99069","0.00569"
"204.16800","17.01413","0.00526"
"204.45000","17.03768","0.00581"
"204.73200","17.06112","0.00586"
"205.01400","17.08474","0.00588"
"205.29600","17.10818","0.00575"
"205.57800","17.13167","0.00545"
"205.86000","17.15517","0.00540"
"206.14200","17.17873","0.00505"
"206.42400","17.20217","0.00502"
"206.70600","17.22572","0.00541"
"206.98800","17.24916","0.00571"
"207.27000","17.27266","0.00531"
"207.55200","17.29622","0.00532"
"207.83400","17.31965","0.00525"
"208.11600","17.34321","0.00527"
"208.39800","17.36665","0.00538"
"208.68000","17.39021","0.00472"
"208.96200","17.41364","0.00496"
"209.24400","17.43714","0.00509"
"209.52600","17.46058","0.00494"
"209.80800","17.48413","0.00532"
"210.09000","17.50757","0.00512"
"210.37200","17.53119","0.00510"
"210.65400","17.55457","0.00488"
"210.93600","17.57824","0.00581"
"211.21800","17.60162","0.00531"
"211.50000","17.62524","0.00542"
"211.78200","17.64861","0.00535"
"212.06400","17.67217","0.00551"
"212.34600","17.69567","0.00564"
"212.62800","17.71923","0.00586"
"212.91000","17.74272","0.00563"
"213.19200","17.76616","0.00532"
"213.47400","17.78972","0.00579"
"213.75600","17.81322","0.00572"
"214.03800","17.83671","0.00577"
"214.32000","17.86015","0.00561"
"214.60200","17.88371","0.00509"
"214.88400","17.90720","0.00536"
"215.16600","17.93070","0.00580"
"215.44800","17.95420","0.00552"
"215.73000","17.97770","0.00571"
"216.01200","18.00113","0.00559"
"216.29400","18.02469","0.00579"
"216.57600","18.04813","0.00533"
"216.85800","18.07174","0.00463"
"217.14000","18.09518","0.00514"
"217.42200","18.11868","0.00461"
"217.70400","18.14212","0.00510"
"217.98600","18.16567","0.00503"
"218.26800","18.18917","0.00504"
"218.55000","18.21267","0.00550"
"218.83200","18.23623","0.00535"
"219.11400","18.25972","0.00565"
"219.39600","18.28322","0.00585"
"219.67800","18.30666","0.00503"
"219.96000","18.33022","0.00553"
"220.24200","18.35365","0.00544"
"220.52400","18.37721","0.00524"
"220.80600","18.40059","0.00572"
"221.08800","18.42420","0.00531"
"221.37000","18.44764","0.00562"
"221.65200","18.47120","0.00519"
"221.93400","18.49464","0.00545"
"222.21600","18.51819","0.00567"
"222.49800","18.54163","0.00563"
"222.78000","18.56519","0.00611"
"223.06200","18.58869","0.00582"
"223.34400","18.61224","0.00564"
"223.62600","18.63568","0.00551"
"223.90800","18.65918","0.00593"
"224.19000","18.68268","0.00564"
"224.47200","18.70617","0.00555"
"224.75400","18.72967","0.00576"
"225.03600","18.75311","0.00527"
"225.31800","18.77666","0.00599"
"225.60000","18.80010","0.00539"
"225.88200","18.82366","0.00547"
"226.16400","18.84716","0.00531"
"226.44600","18.87071","0.00558"
"226.72800","18.89415","0.00552"
"227.01000","18.91771","0.00543"
"227.29200","18.94109","0.00568"
"227.57400","18.96470","0.00584"
"227.85600","18.98814","0.00557"
"228.13800","19.01176","0.00604"
"228.42000","19.03514","0.00606"
"228.70200","19.05869","0.00586"
"228.98400","19.08219","0.00603"
"229.26600","19.10569","0.00544"
"229.54800","19.12918","0.00607"
"229.83000","19.15268","0.00588"
"230.11200","19.17618","0.00603"
"230.39400","19.19973","0.00567"
"230.67600","19.22317","0.00561"
"230.95800","19.24667","0.00541"
"231.24000","19.27017","0.00554"
"231.52200","19.29366","0.00575"
"231.80400","19.31722","0.00541"
"232.08600","19.34066","0.00544"
"232.36800","19.36422","0.00521"
"232.65000","19.38765","0.00535"
"232.93200","19.41121","0.00520"
"233.21400","19.43465","0.00553"
"233.49600","19.45815","0.00534"
"233.77800","19.48158","0.00489"
"234.06000","19.50520","0.00508"
"234.34200","19.52864","0.00556"
"234.62400","19.55219","0.00491"
"234.90600","19.57563","0.00546"
"235.18800","19.59919","0.00537"
"235.47000","19.62268","0.00545"
"235.75200","19.64618","0.00497"
"236.03400","19.66968","0.00562"
"236.31600","19.69318","0.00546"
"236.59800","19.71667","0.00558"
"236.88000","19.74017","0.00579"
"237.16200","19.76367","0.00556"
"237.44400","19.78717","0.00572"
"237.72600","19.81072","0.00583"
"238.00800","19.83416","0.00621"
"238.29000","19.85772","0.00614"
"238.57200","19.88116","0.00641"
"238.85400","19.90471","0.00635"
"239.13600","19.92815","0.00675"
"239.41800","19.95171","0.00634"
"239.70000","19.97515","0.00671"
"239.98200","19.99870","0.00692"
"240.26400","20.02214","0.00661"
"240.54600","20.04570","0.00696"
"240.82800","20.06913","0.00669"
"241.11000","20.09269","0.00717"
"241.39200","20.11613","0.00683"
"241.67400","20.13963","0.00677"
"241.95600","20.16312","0.00679"
"242.23800","20.18662","0.00718"
"242.52000","20.21018","0.00716"
"242.80200","20.23362","0.00732"
"243.08400","20.25717","0.00702"
"243.36600","20.28067","0.00737"
"243.64800","20.30423","0.00631"
"243.93000","20.32766","0.00653"
"244.21200","20.35116","0.00629"
"244.49400","20.37460","0.00577"
"244.77600","20.39816","0.00589"
"245.05800","20.42159","0.00579"
"245.34000","20.44521","0.00625"
"245.62200","20.46859","0.00612"
"245.90400","20.49220","0.00623"
"246.18600","20.51564","0.00569"
"246.46800","20.53920","0.00597"
"246.75000","20.56270","0.00599"
"247.03200","20.58619","0.00639"
"247.31400","20.60963","0.00648"
"247.59600","20.63319","0.00587"
"247.87800","20.65663","0.00588"
"248.16000","20.68018","0.00615"
"248.44200","20.70368","0.00594"
"248.72400","20.72718","0.00603"
"249.00600","20.75068","0.00603"
"249.28800","20.77417","0.00615"
"249.57000","20.79767","0.00610"
"249.85200","20.82117","0.00636"
"250.13400","20.84466","0.00661"
"250.41600","20.86816","0.00686"
"250.69800","20.89166","0.00660"
"250.98000","20.91509","0.00659"
"251.26200","20.93871","0.00648"
"251.54400","20.96215","0.00669"
"251.82600","20.98571","0.00606"
"252.10800","21.00915","0.00654"
"252.39000","21.03270","0.00674"
"252.67200","21.05614","0.00693"
"252.95400","21.07964","0.00672"
"253.23600","21.10319","0.00646"
"253.51800","21.12675","0.00655"
"253.80000","21.15019","0.00689"
"254.08200","21.17369","0.00678"
"254.36400","21.19718","0.00694"
"254.64600","21.22068","0.00698"
"254.92800","21.24418","0.00710"
"255.21000","21.26768","0.00687"
"255.49200","21.29123","0.00702"
"255.77400","21.31467","0.00687"
"256.05600","21.33822","0.00713"
"256.33800","21.36166","0.00686"
"256.62000","21.38516","0.00736"
"256.90200","21.40860","0.00732"
"257.18400","21.43216","0.00731"
"257.46600","21.45559","0.00743"
"257.74800","21.47915","0.00739"
"258.03000","21.50265","0.00759"
"258.31200","21.52614","0.00765"
"258.59400","21.54964","0.00733"
"258.87600","21.57320","0.00765"
"259.15800","21.59670","0.00786"
"259.44000","21.62013","0.00788"
"259.72200","21.64363","0.00771"
"260.00400","21.66713","0.00822"
"260.28600","21.69069","0.00810"
"260.56800","21.71412","0.00798"
"260.85000","21.73768","0.00770"
"261.13200","21.76118","0.00791"
"261.41400","21.78468","0.00788"
"261.69600","21.80805","0.00807"
"261.97800","21.83173","0.00798"
"262.26000","21.85511","0.00816"
"262.54200","21.87867","0.00778"
"262.82400","21.90210","0.00825"
"263.10600","21.92572","0.00801"
"263.38800","21.94916","0.00816"
"263.67000","21.97271","0.00803"
"263.95200","21.99615","0.00840"
"264.23400","22.01971","0.00847"
"264.51600","22.04315","0.00853"
"264.79800","22.06670","0.00837"
"265.08000","22.09014","0.00849"
"265.36200","22.11364","0.00902"
"265.64400","22.13713","0.00888"
"265.92600","22.16063","0.00884"
"266.20800","22.18419","0.00899"
"266.49000","22.20769","0.00896"
"266.77200","22.23118","0.00739"
"267.05400","22.25462","0.00755"
"267.33600","22.27818","0.00705"
"267.61800","22.30168","0.00729"
"267.90000","22.32523","0.00710"
"268.18200","22.34867","0.00728"
"268.46400","22.37217","0.00757"
"268.74600","22.39566","0.00753"
"269.02800","22.41916","0.00753"
"269.31000","22.44266","0.00765"
"269.59200","22.46622","0.00757"
"269.87400","22.48965","0.00782"
"270.15600","22.51321","0.00778"
"270.43800","22.53665","0.00799"
"270.72000","22.56021","0.00812"
"271.00200","22.58370","0.00810"
"271.28400","22.60720","0.00766"
"271.56600","22.63070","0.00772"
"271.84800","22.65419","0.00800"
"272.13000","22.67763","0.00793"
"272.41200","22.70119","0.00801"
"272.69400","22.72468","0.00817"
"272.97600","22.74818","0.00799"
"273.25800","22.77174","0.00766"
"273.54000","22.79518","0.00812"
"273.82200","22.81867","0.00827"
"274.10400","22.84211","0.00801"
"274.38600","22.86561","0.00844"
"274.66800","22.88905","0.00817"
"274.95000","22.91266","0.00825"
"275.23200","22.93610","0.00727"
"275.51400","22.95972","0.00796"
"275.79600","22.98316","0.00801"
"276.07800","23.00672","0.00762"
"276.36000","23.03015","0.00807"
"276.64200","23.05365","0.00836"
"276.92400","23.07715","0.00818"
"277.20600","23.10065","0.00847"
"277.48800","23.12420","0.00853"
"277.77000","23.14770","0.00864"
"278.05200","23.17120","0.00863"
"278.33400","23.19469","0.00906"
"278.61600","23.21825","0.00908"
"278.89800","23.24169","0.00918"
"279.18000","23.26524","0.00975"
"279.46200","23.28868","0.00933"
"279.74400","23.31218","0.01008"
"280.02600","23.33562","0.01027"
"280.30800","23.35923","0.01048"
"280.59000","23.38267","0.01075"
"280.87200","23.40623","0.01120"
"281.15400","23.42961","0.01160"
"281.43600","23.45322","0.01223"
"281.71800","23.47660","0.01210"
"282.00000","23.50016","0.01281"
"282.28200","23.52360","0.01332"
"282.56400","23.54715","0.01393"
"282.84600","23.57065","0.01440"
"283.12800","23.59420","0.01468"
"283.41000","23.61770","0.01577"
"283.69200","23.64120","0.01615"
"283.97400","23.66470","0.01641"
"284.25600","23.68819","0.00805"
"284.53800","23.71169","0.00648"
"284.82000","23.73513","0.00808"
"285.10200","23.75869","0.00756"
"285.38400","23.78212","0.00700"
"285.66600","23.80568","0.00826"
"285.94800","23.82912","0.00743"
"286.23000","23.85268","0.00791"
"286.51200","23.87611","0.00795"
"286.79400","23.89973","0.00908"
"287.07600","23.92317","0.00821"
"287.35800","23.94672","0.00945"
"287.64000","23.97016","0.00893"
"287.92200","23.99372","0.01020"
"288.20400","24.01715","0.00993"
"288.48600","24.04071","0.01150"
"288.76800","24.06415","0.01101"
"289.05000","24.08765","0.01204"
"289.33200","24.11115","0.01224"
"289.61400","24.13464","0.01310"
"289.89600","24.15820","0.01426"
"290.17800","24.18164","0.01408"
"290.46000","24.20519","0.01578"
"290.74200","24.22863","0.01537"
"291.02400","24.25219","0.01667"
"291.30600","24.27563","0.01483"
"291.58800","24.29918","0.00968"
"291.87000","24.32262","0.00980"
"292.15200","24.34618","0.01128"
"292.43400","24.36962","0.01090"
"292.71600","24.39317","0.01049"
"292.99800","24.41661","0.01098"
"293.28000","24.44023","0.01103"
"293.56200","24.46367","0.01156"
"293.84400","24.48716","0.01156"
"294.12600","24.51072","0.01274"
"294.40800","24.53416","0.01272"
"294.69000","24.55765","0.01355"
"294.97200","24.58121","0.01025"
"295.25400","24.60471","0.01174"
"295.53600","24.62821","0.01107"
"295.81800","24.65176","0.01155"
"296.10000","24.67514","0.01152"
"296.38200","24.69870","0.01139"
"296.66400","24.72214","0.01141"
"296.94600","24.74569","0.01131"
"297.22800","24.76913","0.01172"
"297.51000","24.79269","0.01170"
"297.79200","24.81612","0.01211"
"298.07400","24.83968","0.01196"
"298.35600","24.86312","0.01215"
"298.63800","24.88674","0.01196"
"298.92000","24.91011","0.01204"
"299.20200","24.93367","0.01287"
"299.48400","24.95717","0.01300"
"299.76600","24.98066","0.01359"
"300.04800","25.00416","0.01309"
"300.33000","25.02772","0.01369"
"300.61200","25.05116","0.01392"
"300.89400","25.07465","0.01430"
"301.17600","25.09815","0.01421"
"301.45800","25.12165","0.01482"
"301.74000","25.14521","0.01518"
"302.02200","25.16870","0.01586"
"302.30400","25.19220","0.01681"
"302.58600","25.21564","0.01690"
"302.86800","25.23919","0.01790"
"303.15000","25.26269","0.01845"
"303.43200","25.28625","0.01894"
"303.71400","25.30963","0.01993"
"303.99600","25.33319","0.02052"
"304.27800","25.35662","0.02150"
"304.56000","25.38018","0.02216"
"304.84200","25.40368","0.02350"
"305.12400","25.42723","0.02424"
"305.40600","25.45067","0.02520"
"305.68800","25.47417","0.02660"
"305.97000","25.49767","0.02687"
"306.25200","25.52116","0.02870"
"306.53400","25.54460","0.02917"
"306.81600","25.56816","0.02999"
"307.09800","25.59165","0.03094"
"307.38000","25.61515","0.03278"
"307.66200","25.63871","0.03374"
"307.94400","25.66220","0.03466"
"308.22600","25.68570","0.03353"
"308.50800","25.70920","0.01947"
"308.79000","25.73264","0.01840"
"309.07200","25.75614","0.02062"
"309.35400","25.77969","0.02170"
"309.63600","25.80313","0.02146"
"309.91800","25.82668","0.02220"
"310.20000","25.85018","0.02214"
"310.48200","25.87374","0.02455"
"310.76400","25.89712","0.02273"
"311.04600","25.92068","0.02178"
"311.32800","25.94417","0.01982"
"311.61000","25.96767","0.02011"
"311.89200","25.99117","0.02079"
"312.17400","26.01467","0.01943"
"312.45600","26.03822","0.02022"
"312.73800","26.06172","0.02143"
"313.02000","26.08522","0.02108"
"313.30200","26.10866","0.02168"
"313.58400","26.13221","0.02207"
"313.86600","26.15559","0.02444"
"314.14800","26.17921","0.02359"
"314.43000","26.20264","0.02446"
"314.71200","26.22620","0.02535"
"314.99400","26.24964","0.02515"
"315.27600","26.27320","0.02609"
"315.55800","26.29663","0.02559"
"315.84000","26.32025","0.02407"
"316.12200","26.34363","0.02485"
"316.40400","26.36719","0.02613"
"316.68600","26.39062","0.02716"
"316.96800","26.41424","0.02786"
"317.25000","26.43768","0.02922"
"317.53200","26.46117","0.02959"
"317.81400","26.48467","0.03074"
"318.09600","26.50817","0.03152"
"318.37800","26.53161","0.03259"
"318.66000","26.55516","0.02764"
"318.94200","26.57872","0.02773"
"319.22400","26.60216","0.02775"
"319.50600","26.62571","0.02900"
"319.78800","26.64915","0.03107"
"320.07000","26.67271","0.03090"
"320.35200","26.69621","0.03163"
"320.63400","26.71970","0.03203"
"320.91600","26.74314","0.03394"
"321.19800","26.76670","0.03394"
"321.48000","26.79014","0.03305"
"321.76200","26.81369","0.03525"
"322.04400","26.83713","0.03610"
"322.32600","26.86069","0.03723"
"322.60800","26.88406","0.03828"
"322.89000","26.90768","0.03969"
"323.17200","26.93112","0.04099"
"323.45400","26.95468","0.04185"
"323.73600","26.97817","0.04241"
"324.01800","27.00167","0.04171"
"324.30000","27.02511","0.04246"
"324.58200","27.04866","0.04268"
"324.86400","27.07216","0.04349"
"325.14600","27.09566","0.04433"
"325.42800","27.11916","0.04587"
"325.71000","27.14265","0.04563"
"325.99200","27.16615","0.04634"
"326.27400","27.18959","0.04804"
"326.55600","27.21321","0.04744"
"326.83800","27.23664","0.04949"
"327.12000","27.26020","0.04910"
"327.40200","27.28364","0.05087"
"327.68400","27.30725","0.05147"
"327.96600","27.33069","0.05224"
"328.24800","27.35419","0.05309"
"328.53000","27.37769","0.05395"
"328.81200","27.40119","0.05463"
"329.09400","27.42462","0.05527"
"329.37600","27.44818","0.05578"
"329.65800","27.47174","0.05740"
"329.94000","27.49518","0.05757"
"330.22200","27.51867","0.05922"
"330.50400","27.54211","0.05986"
"330.78600","27.56567","0.06150"
"331.06800","27.58916","0.06269"
"331.35000","27.61272","0.06343"
"331.63200","27.63616","0.06543"
"331.91400","27.65971","0.06641"
"332.19600","27.68315","0.06856"
"332.47800","27.70671","0.07018"
"332.76000","27.73015","0.07193"
"333.04200","27.75370","0.07339"
"333.32400","27.77714","0.07483"
"333.60600","27.80070","0.07704"
"333.88800","27.82414","0.07845"
"334.17000","27.84775","0.08088"
"334.45200","27.87113","0.08162"
"334.73400","27.89469","0.06524"
"335.01600","27.91813","0.06307"
"335.29800","27.94168","0.06327"
"335.58000","27.96518","0.06505"
"335.86200","27.98868","0.06729"
"336.14400","28.01217","0.07411"
"336.42600","28.03567","0.07046"
"336.70800","28.05917","0.07316"
"336.99000","28.08266","0.07722"
"337.27200","28.10622","0.07754"
"337.55400","28.12966","0.08102"
"337.83600","28.15322","0.08114"
"338.11800","28.17665","0.08297"
"338.40000","28.20015","0.08579"
"338.68200","28.22359","0.08581"
"338.96400","28.24715","0.08831"
"339.24600","28.27059","0.08958"
"339.52800","28.29420","0.08983"
"339.81000","28.31758","0.09178"
"340.09200","28.34125","0.09288"
"340.37400","28.36463","0.09343"
"340.65600","28.38819","0.09485"
"340.93800","28.41163","0.09489"
"341.22000","28.43512","0.09603"
"341.50200","28.45868","0.09673"
"341.78400","28.48212","0.09762"
"342.06600","28.50568","0.09816"
"342.34800","28.52917","0.09879"
"342.63000","28.55273","0.09930"
"342.91200","28.57617","0.09985"
"343.19400","28.59972","0.10059"
"343.47600","28.62310","0.10107"
"343.75800","28.64672","0.10193"
"344.04000","28.67016","0.04830"
"344.32200","28.69371","0.03921"
"344.60400","28.71715","0.00786"
"344.88600","28.74071","0.00749"
"345.16800","28.76415","0.02315"
"345.45000","28.78770","0.01040"
"345.73200","28.81114","0.00854"
"346.01400","28.83470","0.00942"
"346.29600","28.85820","0.01502"
"346.57800","28.88169","0.01839"
"346.86000","28.90519","0.00716"
"347.14200","28.92869","0.01034"
"347.42400","28.95218","0.01886"
"347.70600","28.97568","0.01040"
"347.98800","28.99918","0.00829"
"348.27000","29.02268","0.01657"
"348.55200","29.04618","0.01416"
"348.83400","29.06967","0.01023"
"349.11600","29.09323","0.01350"
"349.39800","29.11667","0.01731"
"349.68000","29.14016","0.01503"
"349.96200","29.16360","0.01159"
"350.24400","29.18716","0.01485"
"350.52600","29.21060","0.01851"
"350.80800","29.23421","0.01363"
"351.09000","29.25765","0.01369"
"351.37200","29.28121","0.01877"
"351.65400","29.30464","0.01800"
"351.93600","29.32820","0.01616"
"352.21800","29.35164","0.01642"
"352.50000","29.37520","0.01857"
"352.78200","29.39869","0.02024"
"353.06400","29.42219","0.01695"
"353.34600","29.44569","0.01894"
"353.62800","29.46919","0.02257"
"353.91000","29.49268","0.02073"
"354.19200","29.51612","0.02117"
"354.47400","29.53968","0.02151"
"354.75600","29.56311","0.02300"
"355.03800","29.58667","0.02481"
"355.32000","29.61017","0.02365"
"355.60200","29.63372","0.02472"
"355.88400","29.65717","0.02643"
"356.16600","29.68066","0.02674"
"356.44800","29.70410","0.02762"
"356.73000","29.72766","0.02705"
"357.01200","29.75109","0.02811"
"357.29400","29.77477","0.02956"
"357.57600","29.79815","0.02965"
"357.85800","29.82170","0.03194"
"358.14000","29.84514","0.03125"
"358.42200","29.86870","0.03288"
"358.70400","29.89214","0.03377"
"358.98600","29.91569","0.03497"
"359.26800","29.93913","0.03665"
"359.55000","29.96269","0.03598"
"359.83200","29.98618","0.03869"
"360.11400","30.00968","0.03773"
"360.39600","30.03318","0.03980"
"360.67800","30.05667","0.04096"
"360.96000","30.08017","0.04153"
"361.24200","30.10367","0.04302"
"361.52400","30.12717","0.04316"
"361.80600","30.15067","0.04432"
"362.08800","30.17416","0.04497"
"362.37000","30.19760","0.04619"
"362.65200","30.22116","0.04668"
"362.93400","30.24460","0.04809"
"363.21600","30.26822","0.04828"
"363.49800","30.29165","0.04979"
"363.78000","30.31521","0.05040"
"364.06200","30.33864","0.05131"
"364.34400","30.36214","0.05182"
"364.62600","30.38564","0.05292"
"364.90800","30.40914","0.05371"
"365.19000","30.43270","0.05418"
"365.47200","30.45619","0.05522"
"365.75400","30.47969","0.05686"
"366.03600","30.50313","0.05721"
"366.31800","30.52674","0.05886"
"366.60000","30.55018","0.05934"
"366.88200","30.57374","0.06242"
"367.16400","30.59711","0.06272"
"367.44600","30.62067","0.06503"
"367.72800","30.64417","0.01257"
"368.01000","30.66773","0.00624"
"368.29200","30.69117","0.00894"
"368.57400","30.71466","0.00040"
"368.85600","30.73810","0.01481"
"369.13800","30.76166","0.00148"
"369.42000","30.78515","0.01201"
"369.70200","30.80871","0.00005"
"369.98400","30.83215","0.01009"
"370.26600","30.85570","0.00377"
"370.54800","30.87920","0.00630"
"370.83000","30.90264","0.00765"
"371.11200","30.92614","0.00292"
"371.39400","30.94963","0.00991"
"371.67600","30.97313","0.00264"
"371.95800","30.99663","0.01020"
"372.24000","31.02019","0.00490"
"372.52200","31.04368","0.00672"
"372.80400","31.06724","0.00945"
"373.08600","31.09068","0.00480"
"373.36800","31.11417","0.00981"
"373.65000","31.13761","0.00635"
"373.93200","31.16117","0.00814"
"374.21400","31.18461","0.00731"
"374.49600","31.20816","0.00790"
"374.77800","31.23160","0.01040"
"375.06000","31.25521","0.00643"
"375.34200","31.27865","0.01067"
"375.62400","31.30221","0.00847"
"375.90600","31.32565","0.00843"
"376.18800","31.34921","0.01038"
"376.47000","31.37264","0.00867"
"376.75200","31.39620","0.01059"
"377.03400","31.41964","0.00902"
"377.31600","31.44319","0.01049"
"377.59800","31.46669","0.01018"
"377.88000","31.49019","0.00985"
"378.16200","31.51375","0.01250"
"378.44400","31.53718","0.00943"
"378.72600","31.56068","0.01235"
"379.00800","31.58412","0.01267"
"379.29000","31.60768","0.01065"
"379.57200","31.63111","0.01420"
"379.85400","31.65467","0.01184"
"380.13600","31.67811","0.01246"
"380.41800","31.70173","0.01461"
"380.70000","31.72516","0.01218"
"380.98200","31.74872","0.01433"
"381.26400","31.77210","0.01404"
"381.54600","31.79571","0.01408"
"381.82800","31.81915","0.01556"
"382.11000","31.84265","0.01474"
"382.39200","31.86615","0.01641"
"382.67400","31.88970","0.01596"
"382.95600","31.91320","0.01635"
"383.23800","31.93670","0.01750"
"383.52000","31.96020","0.01689"
"383.80200","31.98369","0.01845"
"384.08400","32.00719","0.01771"
"384.36600","32.03063","0.01052"
"384.64800","32.05418","0.01209"
"384.93000","32.07768","0.01012"
"385.21200","32.10124","0.01093"
"385.49400","32.12468","0.01214"
"385.77600","32.14824","0.01112"
"386.05800","32.17167","0.01276"
"386.34000","32.19517","0.01259"
"386.62200","32.21861","0.01262"
"386.90400","32.24216","0.01276"
"387.18600","32.26560","0.01346"
"387.46800","32.28916","0.01436"
"387.75000","32.31265","0.01386"
"388.03200","32.33615","0.01487"
"388.31400","32.35965","0.01530"
"388.59600","32.38315","0.01463"
"388.87800","32.40664","0.01661"
"389.16000","32.43014","0.01585"
"389.44200","32.45370","0.01655"
"389.72400","32.47714","0.01797"
"390.00600","32.50069","0.01673"
"390.28800","32.52413","0.01888"
"390.57000","32.54769","0.01901"
"390.85200","32.57113","0.01834"
"391.13400","32.59468","0.01991"
"391.41600","32.61812","0.01931"
"391.69800","32.64167","0.02125"
"391.98000","32.66512","0.02161"
"392.26200","32.68873","0.02206"
"392.54400","32.71217","0.02292"
"392.82600","32.73566","0.02283"
"393.10800","32.75916","0.02393"
"393.39000","32.78266","0.02532"
"393.67200","32.80622","0.02482"
"393.95400","32.82971","0.02577"
"394.23600","32.85315","0.02647"
"394.51800","32.87665","0.02699"
"394.80000","32.90015","0.02837"
"395.08200","32.92364","0.02707"
"395.36400","32.94714","0.02822"
"395.64600","32.97064","0.02884"
"395.92800","32.99419","0.02992"
"396.21000","33.01763","0.02884"
"396.49200","33.04119","0.02980"
"396.77400","33.06462","0.03056"
"397.05600","33.08818","0.03172"
"397.33800","33.11168","0.03256"
"397.62000","33.13518","0.03412"
"397.90200","33.15862","0.03562"
"398.18400","33.18217","0.03750"
"398.46600","33.20561","0.03819"
"398.74800","33.22923","0.03959"
"399.03000","33.25267","0.04123"
"399.31200","33.27616","0.04194"
"399.59400","33.29966","0.04321"
"399.87600","33.32322","0.04504"
"400.15800","33.34672","0.04606"
"400.44000","33.37021","0.04643"
"400.72200","33.39371","0.04813"
"401.00400","33.41714","0.04880"
"401.28600","33.44065","0.05045"
"401.56800","33.46414","0.05118"
"401.85000","33.48776","0.05302"
"402.13200","33.51120","0.05367"
"402.41400","33.53476","0.05447"
"402.69600","33.55813","0.05558"
"402.97800","33.58169","0.05730"
"403.26000","33.60513","0.05884"
"403.54200","33.62868","0.06016"
"403.82400","33.65206","0.06189"
"404.10600","33.67568","0.06326"
"404.38800","33.69912","0.06519"
"404.67000","33.72267","0.06682"
"404.95200","33.74617","0.06928"
"405.23400","33.76967","0.07048"
"405.51600","33.79316","0.07291"
"405.79800","33.81660","0.07483"
"406.08000","33.84016","0.07681"
"406.36200","33.86366","0.07852"
"406.64400","33.88721","0.08049"
"406.92600","33.91065","0.08272"
"407.20800","33.93420","0.08449"
"407.49000","33.95765","0.08643"
"407.77200","33.98120","0.08768"
"408.05400","34.00464","0.08923"
"408.33600","34.02819","0.09003"
"408.61800","34.05169","0.09107"
"408.90000","34.07519","0.09276"
"409.18200","34.09863","0.09352"
"409.46400","34.12224","0.09480"
"409.74600","34.14562","0.09518"
"410.02800","34.16918","0.09613"
"410.31000","34.19268","0.09700"
"410.59200","34.21623","0.09784"
"410.87400","34.23967","0.09819"
"411.15600","34.26317","0.09890"
"411.43800","34.28667","0.09970"
"411.72000","34.31016","0.10012"
"412.00200","34.33366","0.01013"
"412.28400","34.35715","0.00768"
"412.56600","34.38066","0.02347"
"412.84800","34.40421","0.01309"
"413.13000","34.42771","0.01742"
"413.41200","34.45115","0.01491"
"413.69400","34.47470","0.01534"
"413.97600","34.49814","0.01649"
"414.25800","34.52170","0.01653"
"414.54000","34.54514","0.01394"
"414.82200","34.56863","0.01577"
"415.10400","34.59213","0.01643"
"415.38600","34.61569","0.01413"
"415.66800","34.63912","0.01862"
"415.95000","34.66268","0.01529"
"416.23200","34.68618","0.01812"
"416.51400","34.70968","0.01478"
"416.79600","34.73318","0.02001"
"417.07800","34.75673","0.01641"
"417.36000","34.78023","0.01739"
"417.50600","34.79237","0.01982"