File: Force_trajectories/161226_1/Specimen_RawData_10.csv
End date,"12/26/2016"
Specimen label,"13AT_3"
Maximum Load,"0.34805",N

Time,Extension,Load
(s),(mm),(N)
"0.00000","0.00000","-0.00183"
"0.37800","0.03169","-0.00106"
"0.75600","0.06314","-0.00113"
"1.13400","0.09477","-0.00089"
"1.51200","0.12622","-0.00230"
"1.89000","0.15766","-0.00243"
"2.26800","0.18923","0.00444"
"2.64600","0.22074","0.00465"
"3.02400","0.25219","0.00457"
"3.40200","0.28370","0.00479"
"3.78000","0.31521","0.00485"
"4.15800","0.34672","0.00472"
"4.53600","0.37817","0.00524"
"4.91400","0.40974","0.00494"
"5.29200","0.44119","0.00527"
"5.67000","0.47264","0.00577"
"6.04800","0.50426","0.00599"
"6.42600","0.53577","0.00561"
"6.80400","0.56716","0.00589"
"7.18200","0.59873","0.00546"
"7.56000","0.63018","0.00626"
"7.93800","0.66169","0.00580"
"8.31600","0.69320","0.00560"
"8.69400","0.72477","0.00588"
"9.07200","0.75622","0.00552"
"9.45000","0.78767","0.00605"
"9.82800","0.81918","0.00598"
"10.20600","0.85075","0.00611"
"10.58400","0.88219","0.00606"
"10.96200","0.91370","0.00603"
"11.34000","0.94527","0.00619"
"11.71800","0.97666","0.00600"
"12.09600","1.00811","0.00623"
"12.47400","1.03974","0.00623"
"12.85200","1.07125","0.00651"
"13.23000","1.10264","0.00663"
"13.60800","1.13421","0.00645"
"13.98600","1.16566","0.00644"
"14.36400","1.19717","0.00639"
"14.74200","1.22867","0.00679"
"15.12000","1.26018","0.00658"
"15.49800","1.29169","0.00611"
"15.87600","1.32314","0.00671"
"16.25400","1.35471","0.00672"
"16.63200","1.38622","0.00738"
"17.01000","1.41767","0.00673"
"17.38800","1.44918","0.00681"
"17.76600","1.48069","0.00666"
"18.14400","1.51220","0.00683"
"18.52200","1.54365","0.00729"
"18.90000","1.57522","0.00677"
"19.27800","1.60672","0.00702"
"19.65600","1.63817","0.00740"
"20.03400","1.66974","0.00731"
"20.41200","1.70125","0.00771"
"20.79000","1.73264","0.00742"
"21.16800","1.76415","0.00734"
"21.54600","1.79578","0.00752"
"21.92400","1.82717","0.00795"
"22.30200","1.85868","0.00759"
"22.68000","1.89025","0.00769"
"23.05800","1.92170","0.00814"
"23.43600","1.95314","0.00775"
"23.81400","1.98471","0.00814"
"24.19200","2.01628","0.00789"
"24.57000","2.04767","0.00781"
"24.94800","2.07918","0.00835"
"25.32600","2.11075","0.00844"
"25.70400","2.14220","0.00868"
"26.08200","2.17365","0.00796"
"26.46000","2.20522","0.00787"
"26.83800","2.23679","0.00833"
"27.21600","2.26812","0.00868"
"27.59400","2.29968","0.00859"
"27.97200","2.33119","0.00847"
"28.35000","2.36264","0.00887"
"28.72800","2.39415","0.00863"
"29.10600","2.42572","0.00901"
"29.48400","2.45717","0.00908"
"29.86200","2.48868","0.00935"
"30.24000","2.52019","0.00892"
"30.61800","2.55170","0.00932"
"30.99600","2.58321","0.00916"
"31.37400","2.61466","0.00918"
"31.75200","2.64622","0.00945"
"32.13000","2.67773","0.00968"
"32.50800","2.70918","0.00914"
"32.88600","2.74075","0.00947"
"33.26400","2.77220","0.00889"
"33.64200","2.80365","0.00945"
"34.02000","2.83516","0.00917"
"34.39800","2.86673","0.00911"
"34.77600","2.89818","0.00896"
"35.15400","2.92969","0.00900"
"35.53200","2.96120","0.00928"
"35.91000","2.99271","0.00932"
"36.28800","3.02421","0.00931"
"36.66600","3.05572","0.00942"
"37.04400","3.08723","0.00925"
"37.42200","3.11862","0.00932"
"37.80000","3.15019","0.00971"
"38.17800","3.18176","0.00938"
"38.55600","3.21315","0.00955"
"38.93400","3.24466","0.00946"
"39.31200","3.27629","0.00961"
"39.69000","3.30768","0.00961"
"40.06800","3.33913","0.00987"
"40.44600","3.37075","0.00958"
"40.82400","3.40220","0.00965"
"41.20200","3.43365","0.00974"
"41.58000","3.46522","0.01006"
"41.95800","3.49667","0.00998"
"42.33600","3.52818","0.00971"
"42.71400","3.55963","0.00987"
"43.09200","3.59120","0.01042"
"43.47000","3.62271","0.01025"
"43.84800","3.65416","0.01045"
"44.22600","3.68573","0.01061"
"44.60400","3.71723","0.01046"
"44.98200","3.74868","0.01046"
"45.36000","3.78025","0.01070"
"45.73800","3.81176","0.01057"
"46.11600","3.84315","0.01077"
"46.49400","3.87466","0.01049"
"46.87200","3.90623","0.01078"
"47.25000","3.93774","0.01074"
"47.62800","3.96919","0.01076"
"48.00600","4.00070","0.01051"
"48.38400","4.03221","0.01092"
"48.76200","4.06366","0.01090"
"49.14000","4.09522","0.01107"
"49.51800","4.12673","0.01089"
"49.89600","4.15824","0.01153"
"50.27400","4.18969","0.01215"
"50.65200","4.22120","0.01142"
"51.03000","4.25271","0.01162"
"51.40800","4.28416","0.01162"
"51.78600","4.31573","0.01161"
"52.16400","4.34718","0.01191"
"52.54200","4.37869","0.01218"
"52.92000","4.41020","0.01208"
"53.29800","4.44170","0.01186"
"53.67600","4.47321","0.01271"
"54.05400","4.50472","0.01256"
"54.43200","4.53623","0.01295"
"54.81000","4.56774","0.01267"
"55.18800","4.59913","0.01278"
"55.56600","4.63070","0.01286"
"55.94400","4.66227","0.01310"
"56.32200","4.69366","0.01273"
"56.70000","4.72517","0.01318"
"57.07800","4.75674","0.01328"
"57.45600","4.78819","0.01353"
"57.83400","4.81969","0.01352"
"58.21200","4.85120","0.01388"
"58.59000","4.88271","0.01387"
"58.96800","4.91422","0.01411"
"59.34600","4.94567","0.01423"
"59.72400","4.97724","0.01422"
"60.10200","5.00869","0.01442"
"60.48000","5.04020","0.01465"
"60.85800","5.07177","0.01446"
"61.23600","5.10322","0.01518"
"61.61400","5.13467","0.01544"
"61.99200","5.16623","0.01523"
"62.37000","5.19774","0.01533"
"62.74800","5.22913","0.01534"
"63.12600","5.26070","0.01550"
"63.50400","5.29221","0.01566"
"63.88200","5.32366","0.01610"
"64.26000","5.35517","0.01604"
"64.63800","5.38674","0.01606"
"65.01600","5.41825","0.01658"
"65.39400","5.44964","0.01676"
"65.77200","5.48121","0.01678"
"66.15000","5.51271","0.01676"
"66.52800","5.54416","0.01710"
"66.90600","5.57567","0.01726"
"67.28400","5.60724","0.01710"
"67.66200","5.63869","0.01769"
"68.04000","5.67020","0.01780"
"68.41800","5.70171","0.01824"
"68.79600","5.73316","0.01825"
"69.17400","5.76461","0.01838"
"69.55200","5.79624","0.01867"
"69.93000","5.82775","0.01896"
"70.30800","5.85925","0.01913"
"70.68600","5.89064","0.01956"
"71.06400","5.92221","0.02009"
"71.44200","5.95372","0.02002"
"71.82000","5.98517","0.02030"
"72.19800","6.01668","0.02034"
"72.57600","6.04819","0.02060"
"72.95400","6.07958","0.02122"
"73.33200","6.11121","0.02142"
"73.71000","6.14266","0.02121"
"74.08800","6.17417","0.02169"
"74.46600","6.20574","0.02174"
"74.84400","6.23724","0.02215"
"75.22200","6.26875","0.02301"
"75.60000","6.30020","0.02262"
"75.97800","6.33171","0.02322"
"76.35600","6.36328","0.02362"
"76.73400","6.39467","0.02439"
"77.11200","6.42618","0.02417"
"77.49000","6.45769","0.02455"
"77.86800","6.48920","0.02543"
"78.24600","6.52065","0.02535"
"78.62400","6.55222","0.02577"
"79.00200","6.58366","0.02622"
"79.38000","6.61511","0.02634"
"79.75800","6.64674","0.02703"
"80.13600","6.67825","0.02817"
"80.51400","6.70970","0.02723"
"80.89200","6.74121","0.02818"
"81.27000","6.77278","0.02811"
"81.64800","6.80417","0.02879"
"82.02600","6.83562","0.02908"
"82.40400","6.86725","0.02985"
"82.78200","6.89870","0.03034"
"83.16000","6.93015","0.03047"
"83.53800","6.96171","0.03059"
"83.91600","6.99322","0.03105"
"84.29400","7.02461","0.03160"
"84.67200","7.05618","0.03248"
"85.05000","7.08769","0.03284"
"85.42800","7.11920","0.03285"
"85.80600","7.15071","0.03357"
"86.18400","7.18216","0.03462"
"86.56200","7.21373","0.03205"
"86.94000","7.24518","0.03232"
"87.31800","7.27668","0.03241"
"87.69600","7.30825","0.03296"
"88.07400","7.33970","0.03313"
"88.45200","7.37115","0.03412"
"88.83000","7.40272","0.03390"
"89.20800","7.43423","0.03484"
"89.58600","7.46562","0.03448"
"89.96400","7.49725","0.03471"
"90.34200","7.52870","0.03549"
"90.72000","7.56015","0.03604"
"91.09800","7.59172","0.03722"
"91.47600","7.62317","0.03778"
"91.85400","7.65468","0.03834"
"92.23200","7.68618","0.03785"
"92.61000","7.71769","0.03907"
"92.98800","7.74920","0.03962"
"93.36600","7.78065","0.03949"
"93.74400","7.81222","0.04064"
"94.12200","7.84373","0.04117"
"94.50000","7.87512","0.04308"
"94.87800","7.90669","0.04280"
"95.25600","7.93826","0.04333"
"95.63400","7.96971","0.04455"
"96.01200","8.00115","0.04529"
"96.39000","8.03272","0.04590"
"96.76800","8.06423","0.04659"
"97.14600","8.09562","0.04680"
"97.52400","8.12719","0.04732"
"97.90200","8.15870","0.04750"
"98.28000","8.19021","0.04818"
"98.65800","8.22166","0.04887"
"99.03600","8.25323","0.05018"
"99.41400","8.28468","0.05053"
"99.79200","8.31613","0.05090"
"100.17000","8.34775","0.05136"
"100.54800","8.37920","0.05169"
"100.92600","8.41065","0.05210"
"101.30400","8.44222","0.05278"
"101.68200","8.47367","0.05354"
"102.06000","8.50518","0.05394"
"102.43800","8.53669","0.05518"
"102.81600","8.56820","0.05525"
"103.19400","8.59971","0.05586"
"103.57200","8.63116","0.05682"
"103.95000","8.66273","0.05687"
"104.32800","8.69423","0.05748"
"104.70600","8.72562","0.05809"
"105.08400","8.75719","0.05860"
"105.46200","8.78870","0.05915"
"105.84000","8.82021","0.05957"
"106.21800","8.85172","0.06013"
"106.59600","8.88329","0.06048"
"106.97400","8.91468","0.06116"
"107.35200","8.94613","0.06206"
"107.73000","8.97776","0.06239"
"108.10800","9.00921","0.06314"
"108.48600","9.04072","0.06382"
"108.86400","9.07216","0.06427"
"109.24200","9.10373","0.06533"
"109.62000","9.13518","0.06629"
"109.99800","9.16669","0.06634"
"110.37600","9.19826","0.06775"
"110.75400","9.22971","0.06799"
"111.13200","9.26116","0.06949"
"111.51000","9.29267","0.06946"
"111.88800","9.32418","0.07093"
"112.26600","9.35569","0.07183"
"112.64400","9.38726","0.07268"
"113.02200","9.41870","0.07350"
"113.40000","9.45021","0.07464"
"113.77800","9.48166","0.07533"
"114.15600","9.51317","0.07639"
"114.53400","9.54474","0.07748"
"114.91200","9.57619","0.07826"
"115.29000","9.60770","0.07943"
"115.66800","9.63927","0.08137"
"116.04600","9.67066","0.08142"
"116.42400","9.70217","0.08309"
"116.80200","9.73374","0.08414"
"117.18000","9.76519","0.08527"
"117.55800","9.79669","0.08652"
"117.93600","9.82826","0.08780"
"118.31400","9.85971","0.08953"
"118.69200","9.89122","0.08971"
"119.07000","9.92273","0.09054"
"119.44800","9.95418","0.09184"
"119.82600","9.98569","0.09259"
"120.20400","10.01714","0.09356"
"120.58200","10.04871","0.09505"
"120.96000","10.08022","0.09588"
"121.33800","10.11167","0.09629"
"121.71600","10.14318","0.09738"
"122.09400","10.17474","0.09839"
"122.47200","10.20613","0.09910"
"122.85000","10.23770","0.09947"
"123.22800","10.26921","0.09998"
"123.60600","10.30066","0.10032"
"123.98400","10.33217","0.10066"
"124.36200","10.36374","0.10127"
"124.74000","10.39519","0.10190"
"125.11800","10.42664","0.10234"
"125.49600","10.45821","0.10289"
"125.87400","10.48972","0.10291"
"126.25200","10.52116","0.10355"
"126.63000","10.55273","0.10377"
"127.00800","10.58424","0.10438"
"127.38600","10.61569","0.10439"
"127.76400","10.64720","0.10475"
"128.14200","10.67871","0.10551"
"128.52000","10.71022","0.10545"
"128.89800","10.74167","0.10587"
"129.27600","10.77324","0.10611"
"129.65400","10.80469","0.10641"
"130.03200","10.83619","0.10675"
"130.41000","10.86770","0.10693"
"130.78800","10.89921","0.10687"
"131.16600","10.93072","0.10750"
"131.54400","10.96217","0.10751"
"131.92200","10.99368","0.10776"
"132.30000","11.02525","0.10811"
"132.67800","11.05664","0.10870"
"133.05600","11.08821","0.10903"
"133.43400","11.11978","0.10994"
"133.81200","11.15117","0.10991"
"134.19000","11.18268","0.11028"
"134.56800","11.21418","0.11133"
"134.94600","11.24569","0.11184"
"135.32400","11.27714","0.11197"
"135.70200","11.30871","0.11254"
"136.08000","11.34022","0.11307"
"136.45800","11.37173","0.11320"
"136.83600","11.40318","0.11357"
"137.21400","11.43469","0.11378"
"137.59200","11.46620","0.11430"
"137.97000","11.49771","0.11519"
"138.34800","11.52928","0.00532"
"138.72600","11.56073","0.00434"
"139.10400","11.59217","0.00601"
"139.48200","11.62374","0.00551"
"139.86000","11.65525","0.00516"
"140.23800","11.68664","0.00890"
"140.61600","11.71821","0.00602"
"140.99400","11.74972","0.00730"
"141.37200","11.78117","0.00751"
"141.75000","11.81268","0.00623"
"142.12800","11.84425","0.00732"
"142.50600","11.87570","0.00767"
"142.88400","11.90715","0.00654"
"143.26200","11.93871","0.00738"
"143.64000","11.97028","0.00768"
"144.01800","12.00167","0.00643"
"144.39600","12.03318","0.00751"
"144.77400","12.06475","0.00769"
"145.15200","12.09620","0.00653"
"145.53000","12.12765","0.00772"
"145.90800","12.15922","0.00780"
"146.28600","12.19067","0.00691"
"146.66400","12.22218","0.00724"
"147.04200","12.25369","0.00811"
"147.42000","12.28520","0.00726"
"147.79800","12.31670","0.00724"
"148.17600","12.34815","0.00773"
"148.55400","12.37972","0.00712"
"148.93200","12.41123","0.00682"
"149.31000","12.44274","0.00795"
"149.68800","12.47419","0.00735"
"150.06600","12.50570","0.00725"
"150.44400","12.53709","0.00730"
"150.82200","12.56872","0.00770"
"151.20000","12.60023","0.00727"
"151.57800","12.63167","0.00794"
"151.95600","12.66318","0.00808"
"152.33400","12.69469","0.00755"
"152.71200","12.72620","0.00759"
"153.09000","12.75771","0.00779"
"153.46800","12.78922","0.00709"
"153.84600","12.82079","0.00807"
"154.22400","12.85218","0.00803"
"154.60200","12.88369","0.00765"
"154.98000","12.91520","0.00789"
"155.35800","12.94671","0.00829"
"155.73600","12.97816","0.00779"
"156.11400","13.00972","0.00810"
"156.49200","13.04117","0.00818"
"156.87000","13.07262","0.00784"
"157.24800","13.10419","0.00797"
"157.62600","13.13576","0.00791"
"158.00400","13.16721","0.00856"
"158.38200","13.19866","0.00796"
"158.76000","13.23023","0.00842"
"159.13800","13.26174","0.00856"
"159.51600","13.29319","0.00817"
"159.89400","13.32469","0.00846"
"160.27200","13.35620","0.00876"
"160.65000","13.38759","0.00860"
"161.02800","13.41922","0.00873"
"161.40600","13.45073","0.00878"
"161.78400","13.48218","0.00909"
"162.16200","13.51369","0.00894"
"162.54000","13.54520","0.00922"
"162.91800","13.57671","0.00977"
"163.29600","13.60822","0.00940"
"163.67400","13.63973","0.00878"
"164.05200","13.67124","0.00972"
"164.43000","13.70268","0.00928"
"164.80800","13.73419","0.00920"
"165.18600","13.76570","0.00955"
"165.56400","13.79721","0.00946"
"165.94200","13.82866","0.00959"
"166.32000","13.86023","0.00987"
"166.69800","13.89168","0.00994"
"167.07600","13.92313","0.01031"
"167.45400","13.95476","0.01038"
"167.83200","13.98621","0.01039"
"168.21000","14.01766","0.01048"
"168.58800","14.04922","0.01068"
"168.96600","14.08068","0.01022"
"169.34400","14.11224","0.01082"
"169.72200","14.14369","0.01073"
"170.10000","14.17526","0.01100"
"170.47800","14.20671","0.01074"
"170.85600","14.23816","0.01128"
"171.23400","14.26967","0.01147"
"171.61200","14.30124","0.01141"
"171.99000","14.33269","0.01138"
"172.36800","14.36420","0.01147"
"172.74600","14.39571","0.01176"
"173.12400","14.42721","0.01246"
"173.50200","14.45866","0.01226"
"173.88000","14.49023","0.01238"
"174.25800","14.52174","0.01262"
"174.63600","14.55313","0.01278"
"175.01400","14.58470","0.01295"
"175.39200","14.61621","0.01307"
"175.77000","14.64766","0.01341"
"176.14800","14.67917","0.01346"
"176.52600","14.71074","0.01383"
"176.90400","14.74224","0.01360"
"177.28200","14.77363","0.01414"
"177.66000","14.80520","0.01416"
"178.03800","14.83671","0.01459"
"178.41600","14.86816","0.01494"
"178.79400","14.89973","0.01522"
"179.17200","14.93118","0.01529"
"179.55000","14.96263","0.01566"
"179.92800","14.99420","0.01620"
"180.30600","15.02571","0.01636"
"180.68400","15.05722","0.01719"
"181.06200","15.08867","0.01754"
"181.44000","15.12018","0.01796"
"181.81800","15.15174","0.01813"
"182.19600","15.18313","0.01894"
"182.57400","15.21470","0.01967"
"182.95200","15.24627","0.01986"
"183.33000","15.27766","0.02094"
"183.70800","15.30917","0.02154"
"184.08600","15.34074","0.02242"
"184.46400","15.37219","0.02301"
"184.84200","15.40370","0.02394"
"185.22000","15.43521","0.02541"
"185.59800","15.46678","0.02598"
"185.97600","15.49817","0.02716"
"186.35400","15.52967","0.02837"
"186.73200","15.56118","0.02962"
"187.11000","15.59269","0.03092"
"187.48800","15.62420","0.03227"
"187.86600","15.65571","0.03344"
"188.24400","15.68722","0.03473"
"188.62200","15.71861","0.03655"
"189.00000","15.75018","0.03799"
"189.37800","15.78174","0.04022"
"189.75600","15.81319","0.04126"
"190.13400","15.84470","0.04337"
"190.51200","15.87621","0.04514"
"190.89000","15.90766","0.04743"
"191.26800","15.93917","0.04867"
"191.64600","15.97074","0.05031"
"192.02400","16.00225","0.05151"
"192.40200","16.03370","0.05273"
"192.78000","16.06515","0.05457"
"193.15800","16.09672","0.05566"
"193.53600","16.12817","0.05721"
"193.91400","16.15968","0.05859"
"194.29200","16.19124","0.05968"
"194.67000","16.22269","0.06081"
"195.04800","16.25414","0.06227"
"195.42600","16.28571","0.06434"
"195.80400","16.31722","0.06607"
"196.18200","16.34867","0.06818"
"196.56000","16.38024","0.07038"
"196.93800","16.41169","0.07324"
"197.31600","16.44314","0.07533"
"197.69400","16.47471","0.07775"
"198.07200","16.50622","0.08046"
"198.45000","16.53772","0.08303"
"198.82800","16.56911","0.08601"
"199.20600","16.60074","0.08827"
"199.58400","16.63225","0.09001"
"199.96200","16.66358","0.09256"
"200.34000","16.69527","0.09419"
"200.71800","16.72672","0.09561"
"201.09600","16.75817","0.09722"
"201.47400","16.78962","0.09823"
"201.85200","16.82119","0.09923"
"202.23000","16.85275","0.10066"
"202.60800","16.88415","0.10110"
"202.98600","16.91571","0.10228"
"203.36400","16.94716","0.10303"
"203.74200","16.97867","0.10387"
"204.12000","17.01018","0.10475"
"204.49800","17.04169","0.10517"
"204.87600","17.07320","0.10575"
"205.25400","17.10471","0.10665"
"205.63200","17.13622","0.10743"
"206.01000","17.16773","0.10791"
"206.38800","17.19918","0.10875"
"206.76600","17.23069","0.10993"
"207.14400","17.26219","0.11173"
"207.52200","17.29370","0.11278"
"207.90000","17.32515","0.11440"
"208.27800","17.35672","0.11677"
"208.65600","17.38823","0.11852"
"209.03400","17.41968","0.11986"
"209.41200","17.45119","0.12263"
"209.79000","17.48270","0.12473"
"210.16800","17.51409","0.12752"
"210.54600","17.54572","0.12969"
"210.92400","17.57729","0.13325"
"211.30200","17.60861","0.13538"
"211.68000","17.64018","0.13977"
"212.05800","17.67169","0.14283"
"212.43600","17.70320","0.14621"
"212.81400","17.73471","0.14850"
"213.19200","17.76622","0.15177"
"213.57000","17.79773","0.15491"
"213.94800","17.82912","0.15699"
"214.32600","17.86069","0.15928"
"214.70400","17.89220","0.16122"
"215.08200","17.92371","0.16340"
"215.46000","17.95516","0.16478"
"215.83800","17.98672","0.16651"
"216.21600","18.01823","0.16760"
"216.59400","18.04962","0.16899"
"216.97200","18.08125","0.17012"
"217.35000","18.11270","0.01649"
"217.72800","18.14415","0.00961"
"218.10600","18.17572","0.01113"
"218.48400","18.20717","0.00761"
"218.86200","18.23862","0.01370"
"219.24000","18.27013","0.01230"
"219.61800","18.30176","0.01407"
"219.99600","18.33320","0.01561"
"220.37400","18.36465","0.01381"
"220.75200","18.39616","0.01280"
"221.13000","18.42773","0.01367"
"221.50800","18.45918","0.01060"
"221.88600","18.49069","0.01156"
"222.26400","18.52220","0.01347"
"222.64200","18.55365","0.01301"
"223.02000","18.58516","0.01439"
"223.39800","18.61673","0.01534"
"223.77600","18.64824","0.01398"
"224.15400","18.67962","0.01418"
"224.53200","18.71119","0.01421"
"224.91000","18.74270","0.01246"
"225.28800","18.77421","0.01320"
"225.66600","18.80572","0.01363"
"226.04400","18.83723","0.01321"
"226.42200","18.86874","0.01405"
"226.80000","18.90013","0.01543"
"227.17800","18.93170","0.01456"
"227.55600","18.96321","0.01488"
"227.93400","18.99466","0.01559"
"228.31200","19.02623","0.01387"
"228.69000","19.05773","0.01426"
"229.06800","19.08918","0.01489"
"229.44600","19.12069","0.01355"
"229.82400","19.15220","0.01404"
"230.20200","19.18371","0.01519"
"230.58000","19.21522","0.01426"
"230.95800","19.24673","0.01502"
"231.33600","19.27824","0.01668"
"231.71400","19.30963","0.01502"
"232.09200","19.34114","0.01605"
"232.47000","19.37271","0.01699"
"232.84800","19.40421","0.01562"
"233.22600","19.43560","0.01631"
"233.60400","19.46723","0.01693"
"233.98200","19.49868","0.01547"
"234.36000","19.53013","0.01605"
"234.73800","19.56170","0.01679"
"235.11600","19.59327","0.01601"
"235.49400","19.62466","0.01620"
"235.87200","19.65617","0.01748"
"236.25000","19.68768","0.01640"
"236.62800","19.71925","0.01665"
"237.00600","19.75064","0.01765"
"237.38400","19.78220","0.01725"
"237.76200","19.81371","0.01741"
"238.14000","19.84510","0.01845"
"238.51800","19.87673","0.01800"
"238.89600","19.90824","0.01877"
"239.27400","19.93969","0.01905"
"239.65200","19.97120","0.01892"
"240.03000","20.00271","0.01938"
"240.40800","20.03416","0.02004"
"240.78600","20.06573","0.02021"
"241.16400","20.09723","0.02041"
"241.54200","20.12874","0.02172"
"241.92000","20.16019","0.02115"
"242.29800","20.19170","0.02163"
"242.67600","20.22321","0.02355"
"243.05400","20.25472","0.02313"
"243.43200","20.28617","0.02321"
"243.81000","20.31774","0.02441"
"244.18800","20.34919","0.02477"
"244.56600","20.38064","0.02456"
"244.94400","20.41226","0.02515"
"245.32200","20.44372","0.02595"
"245.70000","20.47517","0.02688"
"246.07800","20.50673","0.02772"
"246.45600","20.53818","0.02853"
"246.83400","20.56969","0.02922"
"247.21200","20.60120","0.03021"
"247.59000","20.63271","0.03049"
"247.96800","20.66422","0.03085"
"248.34600","20.69567","0.03143"
"248.72400","20.72718","0.03292"
"249.10200","20.75875","0.03323"
"249.48000","20.79014","0.03558"
"249.85800","20.82165","0.03587"
"250.23600","20.85321","0.03675"
"250.61400","20.88472","0.03750"
"250.99200","20.91617","0.03845"
"251.37000","20.94774","0.04054"
"251.74800","20.97925","0.04081"
"252.12600","21.01064","0.04289"
"252.50400","21.04215","0.04385"
"252.88200","21.07366","0.04514"
"253.26000","21.10523","0.04623"
"253.63800","21.13667","0.04807"
"254.01600","21.16825","0.04861"
"254.39400","21.19969","0.05050"
"254.77200","21.23114","0.05124"
"255.15000","21.26271","0.05225"
"255.52800","21.29422","0.05471"
"255.90600","21.32567","0.05462"
"256.28400","21.35724","0.05518"
"256.66200","21.38869","0.05739"
"257.04000","21.42020","0.05780"
"257.41800","21.45171","0.05828"
"257.79600","21.48322","0.06107"
"258.17400","21.51467","0.06152"
"258.55200","21.54618","0.06117"
"258.93000","21.57768","0.06426"
"259.30800","21.60925","0.06645"
"259.68600","21.64064","0.06594"
"260.06400","21.67221","0.06792"
"260.44200","21.70378","0.07124"
"260.82000","21.73517","0.07177"
"261.19800","21.76668","0.07203"
"261.57600","21.79825","0.07536"
"261.95400","21.82964","0.07696"
"262.33200","21.86115","0.07785"
"262.71000","21.89271","0.07982"
"263.08800","21.92422","0.08263"
"263.46600","21.95567","0.08342"
"263.84400","21.98718","0.08576"
"264.22200","22.01869","0.08747"
"264.60000","22.05026","0.08911"
"264.97800","22.08165","0.09024"
"265.35600","22.11322","0.09243"
"265.73400","22.14467","0.09425"
"266.11200","22.17612","0.09488"
"266.49000","22.20769","0.09588"
"266.86800","22.23919","0.09776"
"267.24600","22.27071","0.09919"
"267.62400","22.30221","0.09941"
"268.00200","22.33372","0.10058"
"268.38000","22.36523","0.10173"
"268.75800","22.39668","0.10231"
"269.13600","22.42819","0.10301"
"269.51400","22.45976","0.10383"
"269.89200","22.49115","0.10469"
"270.27000","22.52266","0.10547"
"270.64800","22.55423","0.10619"
"271.02600","22.58567","0.10694"
"271.40400","22.61724","0.10763"
"271.78200","22.64881","0.10884"
"272.16000","22.68020","0.10969"
"272.53800","22.71171","0.11128"
"272.91600","22.74322","0.11302"
"273.29400","22.77473","0.11558"
"273.67200","22.80618","0.11706"
"274.05000","22.83775","0.11925"
"274.42800","22.86920","0.12128"
"274.80600","22.90071","0.12481"
"275.18400","22.93216","0.12720"
"275.56200","22.96372","0.13002"
"275.94000","22.99523","0.13322"
"276.31800","23.02662","0.13668"
"276.69600","23.05819","0.14151"
"277.07400","23.08976","0.14527"
"277.45200","23.12109","0.15014"
"277.83000","23.15272","0.15256"
"278.20800","23.18423","0.15602"
"278.58600","23.21568","0.15879"
"278.96400","23.24719","0.16112"
"279.34200","23.27870","0.16335"
"279.72000","23.31021","0.16526"
"280.09800","23.34166","0.16734"
"280.47600","23.37316","0.16877"
"280.85400","23.40473","0.17060"
"281.23200","23.43618","0.17202"
"281.61000","23.46769","0.17439"
"281.98800","23.49920","0.17597"
"282.36600","23.53071","0.17883"
"282.74400","23.56222","0.18043"
"283.12200","23.59373","0.18297"
"283.50000","23.62518","0.18586"
"283.87800","23.65663","0.18846"
"284.25600","23.68819","0.19184"
"284.63400","23.71970","0.19445"
"285.01200","23.75115","0.19715"
"285.39000","23.78266","0.19817"
"285.76800","23.81423","0.20078"
"286.14600","23.84574","0.20211"
"286.52400","23.87719","0.20493"
"286.90200","23.90870","0.20701"
"287.28000","23.94027","0.20867"
"287.65800","23.97166","0.21046"
"288.03600","24.00323","0.21212"
"288.41400","24.03473","0.21318"
"288.79200","24.06612","0.21474"
"289.17000","24.09769","0.21568"
"289.54800","24.12926","0.21748"
"289.92600","24.16071","0.21878"
"290.30400","24.19222","0.22041"
"290.68200","24.22367","0.22233"
"291.06000","24.25518","0.22470"
"291.43800","24.28669","0.22698"
"291.81600","24.31820","0.22902"
"292.19400","24.34971","0.23243"
"292.57200","24.38121","0.23445"
"292.95000","24.41267","0.23640"
"293.32800","24.44429","0.23867"
"293.70600","24.47574","0.24131"
"294.08400","24.50713","0.24328"
"294.46200","24.53876","0.24548"
"294.84000","24.57021","0.24741"
"295.21800","24.60166","0.24890"
"295.59600","24.63317","0.25081"
"295.97400","24.66468","0.25245"
"296.35200","24.69619","0.25381"
"296.73000","24.72770","0.25478"
"297.10800","24.75920","0.25573"
"297.48600","24.79071","0.25699"
"297.86400","24.82216","0.25833"
"298.24200","24.85367","0.25939"
"298.62000","24.88524","0.26112"
"298.99800","24.91663","0.26243"
"299.37600","24.94820","0.26429"
"299.75400","24.97971","0.26532"
"300.13200","25.01122","0.26685"
"300.51000","25.04267","0.27004"
"300.88800","25.07424","0.27360"
"301.26600","25.10568","0.27627"
"301.64400","25.13713","0.27996"
"302.02200","25.16870","0.28434"
"302.40000","25.20021","0.28855"
"302.77800","25.23166","0.29227"
"303.15600","25.26323","0.29660"
"303.53400","25.29474","0.30069"
"303.91200","25.32625","0.30381"
"304.29000","25.35764","0.27559"
"304.66800","25.38921","0.26503"
"305.04600","25.42071","0.25803"
"305.42400","25.45210","0.25707"
"305.80200","25.48373","0.06552"
"306.18000","25.51524","0.06307"
"306.55800","25.54669","0.06248"
"306.93600","25.57820","0.05731"
"307.31400","25.60971","0.05873"
"307.69200","25.64122","0.06637"
"308.07000","25.67273","0.05845"
"308.44800","25.70418","0.06262"
"308.82600","25.73575","0.07184"
"309.20400","25.76720","0.05916"
"309.58200","25.79865","0.06280"
"309.96000","25.83021","0.07256"
"310.33800","25.86172","0.06137"
"310.71600","25.89323","0.06625"
"311.09400","25.92474","0.07441"
"311.47200","25.95619","0.06525"
"311.85000","25.98764","0.07021"
"312.22800","26.01927","0.07587"
"312.60600","26.05072","0.07085"
"312.98400","26.08217","0.07498"
"313.36200","26.11368","0.07861"
"313.74000","26.14519","0.07391"
"314.11800","26.17669","0.08064"
"314.49600","26.20820","0.08189"
"314.87400","26.23977","0.07546"
"315.25200","26.27128","0.08339"
"315.63000","26.30261","0.08711"
"316.00800","26.33418","0.07980"
"316.38600","26.36569","0.08421"
"316.76400","26.39714","0.09068"
"317.14200","26.42871","0.08556"
"317.52000","26.46021","0.08596"
"317.89800","26.49173","0.09252"
"318.27600","26.52324","0.09057"
"318.65400","26.55469","0.09039"
"319.03200","26.58625","0.09475"
"319.41000","26.61770","0.09366"
"319.78800","26.64915","0.09319"
"320.16600","26.68072","0.09747"
"320.54400","26.71223","0.09706"
"320.92200","26.74368","0.09462"
"321.30000","26.77525","0.09826"
"321.67800","26.80664","0.09993"
"322.05600","26.83815","0.09862"
"322.43400","26.86972","0.09920"
"322.81200","26.90122","0.10122"
"323.19000","26.93268","0.10120"
"323.56800","26.96424","0.10163"
"323.94600","26.99569","0.10250"
"324.32400","27.02720","0.10282"
"324.70200","27.05871","0.10260"
"325.08000","27.09022","0.10348"
"325.45800","27.12173","0.10446"
"325.83600","27.15318","0.10423"
"326.21400","27.18469","0.10396"
"326.59200","27.21620","0.10524"
"326.97000","27.24771","0.10584"
"327.34800","27.27916","0.10571"
"327.72600","27.31066","0.10582"
"328.10400","27.34223","0.10669"
"328.48200","27.37362","0.10652"
"328.86000","27.40525","0.10674"
"329.23800","27.43670","0.10772"
"329.61600","27.46821","0.10786"
"329.99400","27.49966","0.10774"
"330.37200","27.53117","0.10810"
"330.75000","27.56268","0.10897"
"331.12800","27.59418","0.10922"
"331.50600","27.62576","0.10932"
"331.88400","27.65721","0.11045"
"332.26200","27.68871","0.11141"
"332.64000","27.72028","0.11160"
"333.01800","27.75173","0.11187"
"333.39600","27.78312","0.11339"
"333.77400","27.81469","0.11449"
"334.15200","27.84614","0.11461"
"334.53000","27.87765","0.11557"
"334.90800","27.90922","0.11721"
"335.28600","27.94072","0.11881"
"335.66400","27.97218","0.11917"
"336.04200","28.00362","0.11963"
"336.42000","28.03519","0.12153"
"336.79800","28.06676","0.12382"
"337.17600","28.09815","0.12345"
"337.55400","28.12966","0.12523"
"337.93200","28.16129","0.12662"
"338.31000","28.19268","0.12910"
"338.68800","28.22419","0.13000"
"339.06600","28.25576","0.13025"
"339.44400","28.28721","0.13199"
"339.82200","28.31866","0.13478"
"340.20000","28.35022","0.13569"
"340.57800","28.38167","0.13689"
"340.95600","28.41318","0.13896"
"341.33400","28.44463","0.14096"
"341.71200","28.47620","0.14320"
"342.09000","28.50765","0.14347"
"342.46800","28.53916","0.14625"
"342.84600","28.57073","0.14799"
"343.22400","28.60224","0.14887"
"343.60200","28.63369","0.14999"
"343.98000","28.66520","0.15251"
"344.35800","28.69670","0.15421"
"344.73600","28.72815","0.15589"
"345.11400","28.75972","0.15670"
"345.49200","28.79117","0.15756"
"345.87000","28.82268","0.15947"
"346.24800","28.85419","0.16158"
"346.62600","28.88570","0.16182"
"347.00400","28.91727","0.16301"
"347.38200","28.94866","0.16381"
"347.76000","28.98017","0.16503"
"348.13800","29.01173","0.16585"
"348.51600","29.04318","0.16603"
"348.89400","29.07470","0.16669"
"349.27200","29.10626","0.16713"
"349.65000","29.13771","0.16823"
"350.02800","29.16916","0.16924"
"350.40600","29.20073","0.16993"
"350.78400","29.23224","0.17011"
"351.16200","29.26369","0.17098"
"351.54000","29.29520","0.17247"
"351.91800","29.32671","0.17310"
"352.29600","29.35822","0.17434"
"352.67400","29.38966","0.17420"
"353.05200","29.42117","0.17599"
"353.43000","29.45274","0.17668"
"353.80800","29.48413","0.17823"
"354.18600","29.51570","0.17913"
"354.56400","29.54721","0.17974"
"354.94200","29.57866","0.18110"
"355.32000","29.61023","0.18246"
"355.69800","29.64174","0.18368"
"356.07600","29.67319","0.18556"
"356.45400","29.70464","0.18635"
"356.83200","29.73621","0.18753"
"357.21000","29.76771","0.18830"
"357.58800","29.79922","0.19024"
"357.96600","29.83067","0.19149"
"358.34400","29.86218","0.19227"
"358.72200","29.89369","0.19349"
"359.10000","29.92520","0.19492"
"359.47800","29.95671","0.19579"
"359.85600","29.98822","0.19760"
"360.23400","30.01967","0.19879"
"360.61200","30.05124","0.19955"
"360.99000","30.08269","0.20041"
"361.36800","30.11414","0.20186"
"361.74600","30.14576","0.20259"
"362.12400","30.17715","0.20346"
"362.50200","30.20872","0.20446"
"362.88000","30.24017","0.20530"
"363.25800","30.27168","0.20569"
"363.63600","30.30325","0.20692"
"364.01400","30.33464","0.20757"
"364.39200","30.36621","0.20849"
"364.77000","30.39778","0.20946"
"365.14800","30.42911","0.20998"
"365.52600","30.46067","0.21063"
"365.90400","30.49224","0.21126"
"366.28200","30.52369","0.21168"
"366.66000","30.55520","0.21240"
"367.03800","30.58671","0.21313"
"367.41600","30.61822","0.21365"
"367.79400","30.64967","0.21425"
"368.17200","30.68124","0.21449"
"368.55000","30.71275","0.21532"
"368.92800","30.74420","0.21580"
"369.30600","30.77565","0.21646"
"369.68400","30.80715","0.21721"
"370.06200","30.83873","0.21803"
"370.44000","30.87011","0.21852"
"370.81800","30.90168","0.21928"
"371.19600","30.93325","0.21980"
"371.57400","30.96470","0.22093"
"371.95200","30.99621","0.22141"
"372.33000","31.02772","0.22250"
"372.70800","31.05911","0.22375"
"373.08600","31.09068","0.22456"
"373.46400","31.12218","0.22585"
"373.84200","31.15370","0.22684"
"374.22000","31.18521","0.22809"
"374.59800","31.21671","0.22930"
"374.97600","31.24822","0.23012"
"375.35400","31.27961","0.23167"
"375.73200","31.31124","0.23297"
"376.11000","31.34275","0.23370"
"376.48800","31.37414","0.23473"
"376.86600","31.40571","0.23564"
"377.24400","31.43721","0.23660"
"377.62200","31.46867","0.23759"
"378.00000","31.50018","0.23875"
"378.37800","31.53168","0.23951"
"378.75600","31.56319","0.24141"
"379.13400","31.59464","0.24258"
"379.51200","31.62621","0.24343"
"379.89000","31.65772","0.24473"
"380.26800","31.68917","0.24557"
"380.64600","31.72068","0.24679"
"381.02400","31.75225","0.24697"
"381.40200","31.78376","0.24867"
"381.78000","31.81515","0.24988"
"382.15800","31.84671","0.25033"
"382.53600","31.87823","0.25128"
"382.91400","31.90967","0.25254"
"383.29200","31.94124","0.25319"
"383.67000","31.97269","0.25392"
"384.04800","32.00414","0.25408"
"384.42600","32.03565","0.25555"
"384.80400","32.06722","0.25616"
"385.18200","32.09867","0.25745"
"385.56000","32.13018","0.25793"
"385.93800","32.16169","0.25896"
"386.31600","32.19326","0.25940"
"386.69400","32.22470","0.26051"
"387.07200","32.25615","0.26088"
"387.45000","32.28772","0.26181"
"387.82800","32.31923","0.26210"
"388.20600","32.35068","0.26314"
"388.58400","32.38219","0.26422"
"388.96200","32.41370","0.26463"
"389.34000","32.44515","0.26549"
"389.71800","32.47678","0.26660"
"390.09600","32.50816","0.26813"
"390.47400","32.53968","0.26921"
"390.85200","32.57119","0.26981"
"391.23000","32.60270","0.27200"
"391.60800","32.63426","0.27297"
"391.98600","32.66565","0.27442"
"392.36400","32.69728","0.27591"
"392.74200","32.72867","0.27744"
"393.12000","32.76012","0.27862"
"393.49800","32.79169","0.28024"
"393.87600","32.82326","0.28095"
"394.25400","32.85464","0.28264"
"394.63200","32.88615","0.28434"
"395.01000","32.91766","0.28662"
"395.38800","32.94918","0.28750"
"395.76600","32.98068","0.28972"
"396.14400","33.01225","0.29049"
"396.52200","33.04376","0.29260"
"396.90000","33.07521","0.29355"
"397.27800","33.10666","0.29554"
"397.65600","33.13817","0.29715"
"398.03400","33.16968","0.29796"
"398.41200","33.20119","0.29873"
"398.79000","33.23276","0.30118"
"399.16800","33.26414","0.30162"
"399.54600","33.29565","0.30296"
"399.92400","33.32722","0.30375"
"400.30200","33.35873","0.30528"
"400.68000","33.39013","0.30607"
"401.05800","33.42169","0.30711"
"401.43600","33.45314","0.30802"
"401.81400","33.48471","0.30930"
"402.19200","33.51622","0.31001"
"402.57000","33.54773","0.31112"
"402.94800","33.57918","0.31149"
"403.32600","33.61063","0.31240"
"403.70400","33.64220","0.31292"
"404.08200","33.67370","0.31344"
"404.46000","33.70521","0.31439"
"404.83800","33.73666","0.31521"
"405.21600","33.76823","0.31516"
"405.59400","33.79968","0.31587"
"405.97200","33.83113","0.31661"
"406.35000","33.86276","0.31735"
"406.72800","33.89427","0.31790"
"407.10600","33.92566","0.31843"
"407.48400","33.95723","0.31867"
"407.86200","33.98880","0.31884"
"408.24000","34.02019","0.31923"
"408.61800","34.05164","0.31940"
"408.99600","34.08320","0.31974"
"409.37400","34.11471","0.32000"
"409.75200","34.14616","0.32010"
"410.13000","34.17773","0.32007"
"410.50800","34.20924","0.32033"
"410.88600","34.24063","0.32049"
"411.26400","34.27220","0.32055"
"411.64200","34.30376","0.32074"
"412.02000","34.33522","0.32072"
"412.39800","34.36672","0.32091"
"412.77600","34.39823","0.32135"
"413.15400","34.42968","0.32128"
"413.53200","34.46113","0.32131"
"413.91000","34.49270","0.32156"
"414.28800","34.52421","0.32159"
"414.66600","34.55566","0.32143"
"415.04400","34.58717","0.32191"
"415.42200","34.61874","0.32181"
"415.80000","34.65019","0.32220"
"416.17800","34.68164","0.32228"
"416.55600","34.71320","0.32245"
"416.93400","34.74466","0.32260"
"417.31200","34.77616","0.32288"
"417.69000","34.80773","0.32321"
"418.06800","34.83918","0.32306"
"418.44600","34.87069","0.32370"
"418.82400","34.90220","0.32412"
"419.20200","34.93371","0.32436"
"419.58000","34.96522","0.32477"
"419.95800","34.99673","0.32525"
"420.33600","35.02823","0.32522"
"420.71400","35.05969","0.32587"
"421.09200","35.09119","0.32635"
"421.47000","35.12270","0.32711"
"421.84800","35.15427","0.32744"
"422.22600","35.18566","0.32834"
"422.60400","35.21723","0.32871"
"422.98200","35.24868","0.32941"
"423.36000","35.28019","0.32980"
"423.73800","35.31164","0.33052"
"424.11600","35.34321","0.33104"
"424.49400","35.37477","0.33144"
"424.87200","35.40617","0.33176"
"425.25000","35.43767","0.33225"
"425.62800","35.46918","0.33310"
"426.00600","35.50069","0.33322"
"426.38400","35.53214","0.33369"
"426.76200","35.56371","0.33437"
"427.14000","35.59516","0.33458"
"427.51800","35.62661","0.33541"
"427.89600","35.65824","0.33558"
"428.27400","35.68975","0.33677"
"428.65200","35.72114","0.33654"
"429.03000","35.75277","0.33729"
"429.40800","35.78416","0.33792"
"429.78600","35.81566","0.33908"
"430.16400","35.84717","0.33924"
"430.54200","35.87868","0.34013"
"430.92000","35.91025","0.34104"
"431.29800","35.94164","0.34256"
"431.67600","35.97315","0.34381"
"432.05400","36.00472","0.34475"
"432.43200","36.03617","0.34487"
"432.81000","36.06773","0.34681"
"433.18800","36.09925","0.34653"
"433.56600","36.13064","0.34756"
"433.94400","36.16214","0.00251"
"434.32200","36.19371","0.00576"
"434.70000","36.22522","0.00479"
"435.07800","36.25673","0.01277"
"435.45600","36.28818","0.00621"
"435.83400","36.31969","0.01155"
"436.21200","36.35114","0.00621"
"436.59000","36.38271","0.01278"
"436.96800","36.41422","0.00588"
"437.34600","36.44572","0.01276"
"437.72400","36.47717","0.00604"
"438.10200","36.50874","0.01062"
"438.48000","36.54020","0.00689"
"438.85800","36.57164","0.00982"
"439.23600","36.60321","0.00865"
"439.61400","36.63472","0.00857"
"439.99200","36.66617","0.00933"
"440.37000","36.69768","0.00766"
"440.74800","36.72925","0.00961"
"441.12600","36.76070","0.00833"
"441.50400","36.79215","0.00827"
"441.88200","36.82372","0.00914"
"442.26000","36.85522","0.00850"
"442.63800","36.88667","0.00955"
"443.01600","36.91818","0.00887"
"443.39400","36.94975","0.00901"
"443.77200","36.98114","0.00874"
"444.15000","37.01265","0.00895"
"444.52800","37.04422","0.00888"
"444.90600","37.07573","0.00858"
"445.28400","37.10718","0.00925"
"445.66200","37.13869","0.00938"
"446.04000","37.17020","0.00845"
"446.41800","37.20171","0.00951"
"446.79600","37.23315","0.00887"
"447.17400","37.26472","0.00904"
"447.55200","37.29623","0.00940"
"447.93000","37.32768","0.00903"
"448.30800","37.35925","0.00921"
"448.68600","37.39076","0.00953"
"449.06400","37.42215","0.00866"
"449.44200","37.45372","0.00997"
"449.82000","37.48523","0.00904"
"450.19800","37.51662","0.00938"
"450.57600","37.54824","0.01006"
"450.95400","37.57969","0.00859"
"451.33200","37.61115","0.01022"
"451.71000","37.64265","0.00939"
"452.08800","37.67422","0.00930"
"452.46600","37.70567","0.00994"
"452.84400","37.73718","0.00944"
"453.22200","37.76869","0.00968"
"453.60000","37.80026","0.00998"
"453.97800","37.83165","0.00991"
"454.35600","37.86316","0.00989"
"454.73400","37.89473","0.00997"
"455.11200","37.92617","0.01074"
"455.49000","37.95768","0.01020"
"455.86800","37.98919","0.00976"
"456.24600","38.02070","0.01024"
"456.62400","38.05215","0.01004"
"457.00200","38.08372","0.00996"
"457.38000","38.11523","0.01064"
"457.75800","38.14674","0.01022"
"458.13600","38.17813","0.01003"
"458.51400","38.20969","0.01084"
"458.89200","38.24121","0.01033"
"459.27000","38.27266","0.01038"
"459.64800","38.30423","0.01030"
"460.02600","38.33573","0.01057"
"460.40400","38.36712","0.01039"
"460.78200","38.39869","0.01076"
"461.16000","38.43020","0.01076"
"461.53800","38.46165","0.01032"
"461.91600","38.49316","0.01068"
"462.29400","38.52467","0.01040"
"462.67200","38.55618","0.01072"
"463.05000","38.58768","0.01045"
"463.42800","38.61919","0.01127"
"463.80600","38.65076","0.01134"
"464.18400","38.68216","0.01061"
"464.56200","38.71367","0.01089"
"464.94000","38.74523","0.01118"
"465.31800","38.77668","0.01132"
"465.69600","38.80819","0.01118"
"466.07400","38.83970","0.01230"
"466.45200","38.87121","0.01183"
"466.83000","38.90266","0.01119"
"467.20800","38.93423","0.01088"
"467.58600","38.96568","0.01179"
"467.96400","38.99718","0.01141"
"468.34200","39.02869","0.01171"
"468.72000","39.06026","0.01113"
"469.09800","39.09171","0.01162"
"469.47600","39.12316","0.01180"
"469.85400","39.15473","0.01133"
"470.23200","39.18618","0.01167"
"470.61000","39.21757","0.01168"
"470.98800","39.24920","0.01147"
"471.36600","39.28077","0.01189"
"471.74400","39.31215","0.01168"
"472.12200","39.34367","0.01159"
"472.50000","39.37523","0.01216"
"472.87800","39.40668","0.01172"
"473.25600","39.43819","0.01166"
"473.63400","39.46970","0.01205"
"474.01200","39.50121","0.01208"
"474.39000","39.53272","0.01180"
"474.76800","39.56411","0.01235"
"475.14600","39.59574","0.01214"
"475.52400","39.62718","0.01271"
"475.90200","39.65863","0.01227"
"476.28000","39.69020","0.01263"
"476.65800","39.72171","0.01248"
"477.03600","39.75310","0.01230"
"477.41400","39.78473","0.01263"
"477.79200","39.81624","0.01275"
"478.17000","39.84763","0.01269"
"478.54800","39.87920","0.01281"
"478.92600","39.91071","0.01279"
"479.30400","39.94216","0.01258"
"479.68200","39.97373","0.01299"
"480.06000","40.00524","0.01287"
"480.43800","40.03669","0.01286"
"480.81600","40.06820","0.01284"
"481.19400","40.09970","0.01330"
"481.57200","40.13121","0.01335"
"481.95000","40.16266","0.01288"
"482.32800","40.19417","0.01373"
"482.70600","40.22574","0.01315"
"483.08400","40.25719","0.01339"
"483.46200","40.28864","0.01366"
"483.84000","40.32027","0.01371"
"484.21800","40.35178","0.01370"
"484.59600","40.38311","0.01363"
"484.97400","40.41467","0.01392"
"485.35200","40.44624","0.01368"
"485.73000","40.47769","0.01397"
"486.10800","40.50914","0.01372"
"486.48600","40.54071","0.01404"
"486.86400","40.57222","0.01421"
"487.24200","40.60361","0.01388"
"487.62000","40.63518","0.01399"
"487.99800","40.66674","0.01402"
"488.37600","40.69813","0.01451"
"488.75400","40.72970","0.01424"
"489.13200","40.76116","0.01444"
"489.51000","40.79272","0.01442"
"489.88800","40.82417","0.01449"
"490.26600","40.85568","0.01471"
"490.64400","40.88719","0.01469"
"491.02200","40.91870","0.01487"
"491.40000","40.95021","0.01498"
"491.77800","40.98178","0.01492"
"492.15600","41.01317","0.01482"
"492.53400","41.04467","0.01482"
"492.91200","41.07619","0.01505"
"493.29000","41.10769","0.01543"
"493.66800","41.13921","0.01535"
"494.04600","41.17078","0.01518"
"494.42400","41.20216","0.01529"
"494.80200","41.23362","0.01553"
"495.18000","41.26524","0.01573"
"495.55800","41.29669","0.01589"
"495.93600","41.32820","0.01561"
"496.31400","41.35970","0.01565"
"496.69200","41.39122","0.01578"
"497.07000","41.42266","0.01602"
"497.44800","41.45412","0.01614"
"497.82600","41.48569","0.01603"
"498.20400","41.51725","0.01622"
"498.58200","41.54865","0.01624"
"498.96000","41.58015","0.01647"
"499.33800","41.61172","0.01670"
"499.71600","41.64317","0.01663"
"500.09400","41.67474","0.01676"
"500.47200","41.70619","0.01691"
"500.85000","41.73770","0.01686"
"501.22800","41.76915","0.01713"
"501.60600","41.80066","0.01726"
"501.98400","41.83229","0.01702"
"502.36200","41.86368","0.01746"
"502.74000","41.89518","0.01752"
"503.11800","41.92669","0.01766"
"503.49600","41.95820","0.01776"
"503.87400","41.98971","0.01779"
"504.25200","42.02122","0.01815"
"504.63000","42.05273","0.01826"
"505.00800","42.08412","0.01861"
"505.38600","42.11575","0.01844"
"505.76400","42.14725","0.01863"
"506.14200","42.17865","0.01902"
"506.52000","42.21021","0.01888"
"506.89800","42.24172","0.01878"
"507.27600","42.27317","0.01885"
"507.65400","42.30468","0.01927"
"508.03200","42.33619","0.01935"
"508.41000","42.36770","0.01983"
"508.78800","42.39915","0.01945"
"509.16600","42.43072","0.01979"
"509.54400","42.46223","0.02052"
"509.92200","42.49362","0.02059"
"510.30000","42.52519","0.02032"
"510.67800","42.55675","0.02076"
"511.05600","42.58815","0.02100"
"511.43400","42.61965","0.02112"
"511.81200","42.65128","0.02139"
"512.19000","42.68273","0.02146"
"512.56800","42.71418","0.02129"
"512.94600","42.74569","0.02221"
"513.32400","42.77714","0.02216"
"513.70200","42.80865","0.02211"
"514.08000","42.84021","0.02272"
"514.45800","42.87167","0.02281"
"514.83600","42.90324","0.02297"
"515.21400","42.93468","0.02278"
"515.59200","42.96619","0.02338"
"515.97000","42.99770","0.02377"
"516.34800","43.02915","0.02337"
"516.72600","43.06078","0.02428"
"517.10400","43.09217","0.02413"
"517.48200","43.12368","0.02427"
"517.86000","43.15519","0.02478"
"518.23800","43.18670","0.02526"
"518.61600","43.21821","0.02585"
"518.99400","43.24966","0.02579"
"519.37200","43.28123","0.02599"
"519.75000","43.31274","0.02624"
"520.12800","43.34418","0.02632"
"520.50600","43.37569","0.02733"
"520.88400","43.40726","0.02725"
"521.26200","43.43871","0.02749"
"521.64000","43.47015","0.02807"
"522.01800","43.50173","0.02788"
"522.39600","43.53318","0.02829"
"522.77400","43.56469","0.02889"
"523.15200","43.59620","0.02849"
"523.53000","43.62777","0.02913"
"523.90800","43.65915","0.02931"
"524.28600","43.69066","0.02930"
"524.66400","43.72217","0.02973"
"525.04200","43.75368","0.03000"
"525.42000","43.78519","0.03014"
"525.79800","43.81676","0.03073"
"526.17600","43.84827","0.03099"
"526.55400","43.87960","0.03145"
"526.93200","43.91122","0.03190"
"527.31000","43.94274","0.03194"
"527.68800","43.97413","0.03271"
"528.06600","44.00576","0.03265"
"528.44400","44.03720","0.03351"
"528.82200","44.06865","0.03367"
"529.20000","44.10016","0.03473"
"529.57800","44.13173","0.03496"
"529.95600","44.16324","0.03547"
"530.33400","44.19463","0.03570"
"530.71200","44.22620","0.03656"
"531.09000","44.25771","0.03608"
"531.46800","44.28916","0.03753"
"531.84600","44.32066","0.03799"
"532.22400","44.35223","0.03802"
"532.60200","44.38375","0.03840"
"532.98000","44.41519","0.03890"
"533.35800","44.44670","0.03977"
"533.73600","44.47815","0.04016"
"534.11400","44.50966","0.04023"
"534.49200","44.54123","0.04076"
"534.87000","44.57268","0.04153"
"535.24800","44.60419","0.04196"
"535.62600","44.63564","0.04294"
"536.00400","44.66720","0.04248"
"536.38200","44.69878","0.04308"
"536.76000","44.73016","0.04267"
"537.13800","44.76173","0.04420"
"537.51600","44.79324","0.04444"
"537.89400","44.82463","0.04466"
"538.27200","44.85620","0.04517"
"538.65000","44.88771","0.04545"
"539.02800","44.91916","0.04618"
"539.40600","44.95066","0.04735"
"539.78400","44.98218","0.04713"
"540.16200","45.01369","0.04779"
"540.54000","45.04520","0.04827"
"540.91800","45.07671","0.04910"
"541.29600","45.10822","0.04906"
"541.67400","45.13972","0.04902"
"542.05200","45.17117","0.04910"
"542.43000","45.20274","0.04976"
"542.80800","45.23425","0.04949"
"543.18600","45.26564","0.05037"
"543.56400","45.29726","0.05046"
"543.94200","45.32872","0.05041"
"544.32000","45.36011","0.05088"
"544.69800","45.39174","0.05103"
"545.07600","45.42325","0.05228"
"545.45400","45.45464","0.05264"
"545.83200","45.48621","0.05303"
"546.21000","45.51771","0.05396"
"546.58800","45.54922","0.05434"
"546.96600","45.58067","0.05423"
"547.34400","45.61224","0.05495"
"547.72200","45.64375","0.05553"
"548.10000","45.67514","0.05535"
"548.47800","45.70665","0.05589"
"548.85600","45.73822","0.05709"
"549.23400","45.76961","0.05736"
"549.61200","45.80117","0.05764"
"549.99000","45.83269","0.05826"
"550.36800","45.86419","0.05839"
"550.74600","45.89570","0.05885"
"551.12400","45.92721","0.05937"
"551.50200","45.95872","0.05982"
"551.88000","45.99017","0.05987"
"552.25800","46.02168","0.06058"
"552.63600","46.05325","0.06120"
"553.01400","46.08469","0.06136"
"553.39200","46.11615","0.06244"
"553.77000","46.14777","0.06304"
"554.14800","46.17916","0.06328"
"554.52600","46.21061","0.06373"
"554.90400","46.24224","0.06375"
"555.28200","46.27369","0.06466"
"555.66000","46.30520","0.06521"
"556.03800","46.33671","0.06632"
"556.41600","46.36816","0.06684"
"556.79400","46.39972","0.06728"
"557.17200","46.43118","0.06810"
"557.55000","46.46275","0.06884"
"557.92800","46.49420","0.07013"
"558.30600","46.52564","0.07041"
"558.68400","46.55716","0.07120"
"559.06200","46.58872","0.07155"
"559.44000","46.62017","0.07262"
"559.81800","46.65168","0.07316"
"560.19600","46.68325","0.07377"
"560.57400","46.71470","0.07429"
"560.95200","46.74615","0.07475"
"561.33000","46.77778","0.07565"
"561.70800","46.80923","0.07679"
"562.08600","46.84068","0.07754"
"562.46400","46.87218","0.07836"
"562.84200","46.90369","0.07930"
"563.22000","46.93520","0.08013"
"563.59800","46.96665","0.08121"
"563.97600","46.99822","0.08235"
"564.35400","47.02973","0.08260"
"564.73200","47.06118","0.08421"
"564.98400","47.08216","0.08427"