File: Force_trajectories/161226_1/Specimen_RawData_7.csv
End date,"12/26/2016"
Specimen label,"22AG_80"
Maximum Load,"0.17213",N

Time,Extension,Load
(s),(mm),(N)
"0.00000","0.00000","0.00011"
"0.24600","0.01818","-0.00009"
"0.49200","0.04131","0.00039"
"0.73800","0.06170","0.00028"
"0.98400","0.08221","0.00094"
"1.23000","0.10266","0.00064"
"1.47600","0.12323","0.00183"
"1.72200","0.14367","0.00106"
"1.96800","0.16412","0.00104"
"2.21400","0.18469","0.00084"
"2.46000","0.20514","0.00140"
"2.70600","0.22571","0.00115"
"2.95200","0.24615","0.00107"
"3.19800","0.26672","0.00124"
"3.44400","0.28711","0.00229"
"3.69000","0.30768","0.00179"
"3.93600","0.32824","0.00178"
"4.18200","0.34863","0.00220"
"4.42800","0.36920","0.00172"
"4.67400","0.38959","0.00187"
"4.92000","0.41022","0.00211"
"5.16600","0.43060","0.00222"
"5.41200","0.45117","0.00200"
"5.65800","0.47168","0.00247"
"5.90400","0.49213","0.00238"
"6.15000","0.51264","0.00289"
"6.39600","0.53320","0.00244"
"6.64200","0.55371","0.00241"
"6.88800","0.57416","0.00213"
"7.13400","0.59467","0.00251"
"7.38000","0.61517","0.00281"
"7.62600","0.63562","0.00322"
"7.87200","0.65613","0.00282"
"8.11800","0.67664","0.00300"
"8.36400","0.69715","0.00337"
"8.61000","0.71771","0.00314"
"8.85600","0.73816","0.00287"
"9.10200","0.75867","0.00290"
"9.34800","0.77918","0.00306"
"9.59400","0.79963","0.00283"
"9.84000","0.82019","0.00362"
"10.08600","0.84070","0.00299"
"10.33200","0.86121","0.00311"
"10.57800","0.88166","0.00303"
"10.82400","0.90216","0.00336"
"11.07000","0.92261","0.00306"
"11.31600","0.94318","0.00381"
"11.56200","0.96363","0.00317"
"11.80800","0.98420","0.00331"
"12.05400","1.00470","0.00374"
"12.30000","1.02515","0.00376"
"12.54600","1.04572","0.00341"
"12.79200","1.06611","0.00367"
"13.03800","1.08667","0.00369"
"13.28400","1.10706","0.00325"
"13.53000","1.12769","0.00330"
"13.77600","1.14814","0.00393"
"14.02200","1.16871","0.00386"
"14.26800","1.18909","0.00354"
"14.51400","1.20966","0.00404"
"14.76000","1.23011","0.00394"
"15.00600","1.25062","0.00379"
"15.25200","1.27119","0.00391"
"15.49800","1.29163","0.00390"
"15.74400","1.31220","0.00419"
"15.99000","1.33259","0.00404"
"16.23600","1.35316","0.00409"
"16.48200","1.37360","0.00460"
"16.72800","1.39417","0.00418"
"16.97400","1.41468","0.00444"
"17.22000","1.43519","0.00481"
"17.46600","1.45570","0.00482"
"17.71200","1.47620","0.00435"
"17.95800","1.49665","0.00442"
"18.20400","1.51716","0.00466"
"18.45000","1.53767","0.00491"
"18.69600","1.55817","0.00447"
"18.94200","1.57868","0.00461"
"19.18800","1.59913","0.00440"
"19.43400","1.61970","0.00512"
"19.68000","1.64015","0.00482"
"19.92600","1.66065","0.00493"
"20.17200","1.68110","0.00496"
"20.41800","1.70173","0.00553"
"20.66400","1.72212","0.00507"
"20.91000","1.74269","0.00496"
"21.15600","1.76319","0.00538"
"21.40200","1.78364","0.00501"
"21.64800","1.80421","0.00509"
"21.89400","1.82460","0.00532"
"22.14000","1.84522","0.00517"
"22.38600","1.86561","0.00541"
"22.63200","1.88618","0.00533"
"22.87800","1.90669","0.00508"
"23.12400","1.92714","0.00534"
"23.37000","1.94764","0.00547"
"23.61600","1.96815","0.00528"
"23.86200","1.98872","0.00586"
"24.10800","2.00911","0.00578"
"24.35400","2.02974","0.00508"
"24.60000","2.05012","0.00551"
"24.84600","2.07069","0.00537"
"25.09200","2.09108","0.00574"
"25.33800","2.11165","0.00549"
"25.58400","2.13215","0.00518"
"25.83000","2.15266","0.00588"
"26.07600","2.17311","0.00588"
"26.32200","2.19368","0.00560"
"26.56800","2.21419","0.00531"
"26.81400","2.23463","0.00600"
"27.06000","2.25514","0.00619"
"27.30600","2.27565","0.00535"
"27.55200","2.29622","0.00564"
"27.79800","2.31661","0.00559"
"28.04400","2.33723","0.00586"
"28.29000","2.35762","0.00581"
"28.53600","2.37819","0.00561"
"28.78200","2.39864","0.00596"
"29.02800","2.41920","0.00538"
"29.27400","2.43965","0.00548"
"29.52000","2.46016","0.00592"
"29.76600","2.48073","0.00584"
"30.01200","2.50112","0.00530"
"30.25800","2.52168","0.00503"
"30.50400","2.54213","0.00462"
"30.75000","2.56276","0.00502"
"30.99600","2.58315","0.00506"
"31.24200","2.60365","0.00495"
"31.48800","2.62410","0.00488"
"31.73400","2.64467","0.00506"
"31.98000","2.66512","0.00515"
"32.22600","2.68569","0.00570"
"32.47200","2.70619","0.00521"
"32.71800","2.72664","0.00481"
"32.96400","2.74721","0.00512"
"33.21000","2.76766","0.00493"
"33.45600","2.78817","0.00511"
"33.70200","2.80861","0.00506"
"33.94800","2.82918","0.00507"
"34.19400","2.84969","0.00472"
"34.44000","2.87020","0.00503"
"34.68600","2.89064","0.00528"
"34.93200","2.91115","0.00498"
"35.17800","2.93166","0.00492"
"35.42400","2.95211","0.00516"
"35.67000","2.97262","0.00553"
"35.91600","2.99312","0.00569"
"36.16200","3.01369","0.00530"
"36.40800","3.03414","0.00546"
"36.65400","3.05465","0.00531"
"36.90000","3.07516","0.00461"
"37.14600","3.09566","0.00530"
"37.39200","3.11611","0.00552"
"37.63800","3.13674","0.00542"
"37.88400","3.15713","0.00531"
"38.13000","3.17763","0.00544"
"38.37600","3.19820","0.00562"
"38.62200","3.21865","0.00534"
"38.86800","3.23916","0.00533"
"39.11400","3.25961","0.00553"
"39.36000","3.28023","0.00572"
"39.60600","3.30062","0.00544"
"39.85200","3.32119","0.00517"
"40.09800","3.34164","0.00546"
"40.34400","3.36214","0.00542"
"40.59000","3.38265","0.00562"
"40.83600","3.40316","0.00568"
"41.08200","3.42373","0.00624"
"41.32800","3.44412","0.00577"
"41.57400","3.46468","0.00579"
"41.82000","3.48519","0.00619"
"42.06600","3.50570","0.00580"
"42.31200","3.52609","0.00539"
"42.55800","3.54666","0.00580"
"42.80400","3.56716","0.00567"
"43.05000","3.58767","0.00549"
"43.29600","3.60812","0.00568"
"43.54200","3.62869","0.00631"
"43.78800","3.64913","0.00613"
"44.03400","3.66964","0.00575"
"44.28000","3.69015","0.00605"
"44.52600","3.71066","0.00596"
"44.77200","3.73117","0.00562"
"45.01800","3.75161","0.00580"
"45.26400","3.77218","0.00528"
"45.51000","3.79263","0.00516"
"45.75600","3.81314","0.00610"
"46.00200","3.83365","0.00562"
"46.24800","3.85421","0.00570"
"46.49400","3.87466","0.00563"
"46.74000","3.89517","0.00554"
"46.98600","3.91574","0.00582"
"47.23200","3.93612","0.00595"
"47.47800","3.95669","0.00574"
"47.72400","3.97708","0.00565"
"47.97000","3.99771","0.00560"
"48.21600","4.01810","0.00564"
"48.46200","4.03872","0.00503"
"48.70800","4.05917","0.00529"
"48.95400","4.07968","0.00567"
"49.20000","4.10013","0.00533"
"49.44600","4.12064","0.00567"
"49.69200","4.14120","0.00564"
"49.93800","4.16165","0.00516"
"50.18400","4.18216","0.00547"
"50.43000","4.20267","0.00555"
"50.67600","4.22317","0.00537"
"50.92200","4.24356","0.00562"
"51.16800","4.26413","0.00567"
"51.41400","4.28464","0.00541"
"51.66000","4.30521","0.00585"
"51.90600","4.32571","0.00554"
"52.15200","4.34616","0.00550"
"52.39800","4.36667","0.00553"
"52.64400","4.38712","0.00586"
"52.89000","4.40768","0.00575"
"53.13600","4.42819","0.00589"
"53.38200","4.44864","0.00543"
"53.62800","4.46915","0.00562"
"53.87400","4.48966","0.00532"
"54.12000","4.51010","0.00577"
"54.36600","4.53067","0.00590"
"54.61200","4.55118","0.00548"
"54.85800","4.57175","0.00619"
"55.10400","4.59213","0.00573"
"55.35000","4.61264","0.00577"
"55.59600","4.63321","0.00556"
"55.84200","4.65366","0.00579"
"56.08800","4.67417","0.00601"
"56.33400","4.69455","0.00602"
"56.58000","4.71524","0.00585"
"56.82600","4.73563","0.00573"
"57.07200","4.75620","0.00649"
"57.31800","4.77665","0.00631"
"57.56400","4.79715","0.00638"
"57.81000","4.81766","0.00613"
"58.05600","4.83811","0.00655"
"58.30200","4.85868","0.00650"
"58.54800","4.87913","0.00602"
"58.79400","4.89969","0.00566"
"59.04000","4.92020","0.00613"
"59.28600","4.94065","0.00608"
"59.53200","4.96110","0.00579"
"59.77800","4.98166","0.00564"
"60.02400","5.00217","0.00598"
"60.27000","5.02268","0.00601"
"60.51600","5.04313","0.00618"
"60.76200","5.06364","0.00593"
"61.00800","5.08414","0.00605"
"61.25400","5.10465","0.00631"
"61.50000","5.12516","0.00576"
"61.74600","5.14567","0.00625"
"61.99200","5.16617","0.00623"
"62.23800","5.18662","0.00573"
"62.48400","5.20719","0.00587"
"62.73000","5.22764","0.00604"
"62.97600","5.24815","0.00606"
"63.22200","5.26859","0.00582"
"63.46800","5.28922","0.00608"
"63.71400","5.30961","0.00620"
"63.96000","5.33018","0.00607"
"64.20600","5.35074","0.00634"
"64.45200","5.37113","0.00604"
"64.69800","5.39170","0.00636"
"64.94400","5.41209","0.00588"
"65.19000","5.43272","0.00572"
"65.43600","5.45316","0.00598"
"65.68200","5.47373","0.00634"
"65.92800","5.49418","0.00646"
"66.17400","5.51469","0.00631"
"66.42000","5.53514","0.00639"
"66.66600","5.55570","0.00645"
"66.91200","5.57621","0.00654"
"67.15800","5.59666","0.00640"
"67.40400","5.61723","0.00628"
"67.65000","5.63767","0.00642"
"67.89600","5.65818","0.00656"
"68.14200","5.67857","0.00652"
"68.38800","5.69914","0.00691"
"68.63400","5.71965","0.00629"
"68.88000","5.74015","0.00608"
"69.12600","5.76066","0.00668"
"69.37200","5.78117","0.00626"
"69.61800","5.80168","0.00656"
"69.86400","5.82219","0.00654"
"70.11000","5.84269","0.00687"
"70.35600","5.86314","0.00678"
"70.60200","5.88371","0.00622"
"70.84800","5.90410","0.00649"
"71.09400","5.92466","0.00643"
"71.34000","5.94511","0.00685"
"71.58600","5.96568","0.00598"
"71.83200","5.98613","0.00654"
"72.07800","6.00670","0.00648"
"72.32400","6.02714","0.00651"
"72.57000","6.04765","0.00647"
"72.81600","6.06816","0.00633"
"73.06200","6.08867","0.00661"
"73.30800","6.10918","0.00641"
"73.55400","6.12962","0.00695"
"73.80000","6.15019","0.00652"
"74.04600","6.17064","0.00637"
"74.29200","6.19115","0.00648"
"74.53800","6.21165","0.00659"
"74.78400","6.23216","0.00612"
"75.03000","6.25267","0.00678"
"75.27600","6.27318","0.00661"
"75.52200","6.29368","0.00663"
"75.76800","6.31413","0.00694"
"76.01400","6.33470","0.00676"
"76.26000","6.35515","0.00715"
"76.50600","6.37566","0.00651"
"76.75200","6.39605","0.00635"
"76.99800","6.41667","0.00552"
"77.24400","6.43718","0.00422"
"77.49000","6.45769","0.00460"
"77.73600","6.47820","0.00445"
"77.98200","6.49870","0.00398"
"78.22800","6.51921","0.00376"
"78.47400","6.53966","0.00436"
"78.72000","6.56011","0.00458"
"78.96600","6.58062","0.00451"
"79.21200","6.60112","0.00432"
"79.45800","6.62163","0.00428"
"79.70400","6.64220","0.00436"
"79.95000","6.66265","0.00462"
"80.19600","6.68321","0.00451"
"80.44200","6.70360","0.00455"
"80.68800","6.72423","0.00420"
"80.93400","6.74468","0.00430"
"81.18000","6.76519","0.00443"
"81.42600","6.78569","0.00481"
"81.67200","6.80614","0.00443"
"81.91800","6.82671","0.00450"
"82.16400","6.84710","0.00473"
"82.41000","6.86772","0.00433"
"82.65600","6.88811","0.00439"
"82.90200","6.90868","0.00462"
"83.14800","6.92913","0.00423"
"83.39400","6.94970","0.00451"
"83.64000","6.97014","0.00491"
"83.88600","6.99065","0.00508"
"84.13200","7.01116","0.00449"
"84.37800","7.03161","0.00486"
"84.62400","7.05224","0.00487"
"84.87000","7.07268","0.00486"
"85.11600","7.09319","0.00446"
"85.36200","7.11358","0.00461"
"85.60800","7.13415","0.00463"
"85.85400","7.15465","0.00403"
"86.10000","7.17516","0.00409"
"86.34600","7.19561","0.00442"
"86.59200","7.21624","0.00445"
"86.83800","7.23669","0.00477"
"87.08400","7.25713","0.00466"
"87.33000","7.27764","0.00444"
"87.57600","7.29815","0.00504"
"87.82200","7.31872","0.00489"
"88.06800","7.33917","0.00499"
"88.31400","7.35967","0.00458"
"88.56000","7.38012","0.00470"
"88.80600","7.40069","0.00452"
"89.05200","7.42114","0.00522"
"89.29800","7.44170","0.00504"
"89.54400","7.46209","0.00489"
"89.79000","7.48266","0.00533"
"90.03600","7.50317","0.00477"
"90.28200","7.52368","0.00479"
"90.52800","7.54418","0.00485"
"90.77400","7.56463","0.00525"
"91.02000","7.58526","0.00543"
"91.26600","7.60559","0.00543"
"91.51200","7.62616","0.00488"
"91.75800","7.64660","0.00468"
"92.00400","7.66717","0.00497"
"92.25000","7.68762","0.00501"
"92.49600","7.70819","0.00503"
"92.74200","7.72869","0.00559"
"92.98800","7.74914","0.00500"
"93.23400","7.76971","0.00538"
"93.48000","7.79016","0.00479"
"93.72600","7.81067","0.00492"
"93.97200","7.83111","0.00538"
"94.21800","7.85162","0.00470"
"94.46400","7.87219","0.00496"
"94.71000","7.89270","0.00477"
"94.95600","7.91314","0.00480"
"95.20200","7.93365","0.00558"
"95.44800","7.95416","0.00486"
"95.69400","7.97467","0.00476"
"95.94000","7.99518","0.00550"
"96.18600","8.01568","0.00529"
"96.43200","8.03613","0.00514"
"96.67800","8.05664","0.00515"
"96.92400","8.07715","0.00529"
"97.17000","8.09760","0.00484"
"97.41600","8.11822","0.00521"
"97.66200","8.13867","0.00532"
"97.90800","8.15924","0.00485"
"98.15400","8.17963","0.00521"
"98.40000","8.20013","0.00542"
"98.64600","8.22070","0.00528"
"98.89200","8.24115","0.00517"
"99.13800","8.26166","0.00562"
"99.38400","8.28211","0.00547"
"99.63000","8.30267","0.00523"
"99.87600","8.32312","0.00553"
"100.12200","8.34369","0.00593"
"100.36800","8.36408","0.00584"
"100.61400","8.38465","0.00569"
"100.86000","8.40515","0.00520"
"101.10600","8.42566","0.00571"
"101.35200","8.44617","0.00558"
"101.59800","8.46662","0.00557"
"101.84400","8.48718","0.00538"
"102.09000","8.50763","0.00513"
"102.33600","8.52814","0.00551"
"102.58200","8.54859","0.00528"
"102.82800","8.56916","0.00559"
"103.07400","8.58966","0.00491"
"103.32000","8.61017","0.00557"
"103.56600","8.63062","0.00559"
"103.81200","8.65119","0.00560"
"104.05800","8.67169","0.00556"
"104.30400","8.69214","0.00535"
"104.55000","8.71265","0.00615"
"104.79600","8.73316","0.00574"
"105.04200","8.75367","0.00511"
"105.28800","8.77411","0.00554"
"105.53400","8.79468","0.00590"
"105.78000","8.81513","0.00574"
"106.02600","8.83570","0.00608"
"106.27200","8.85614","0.00606"
"106.51800","8.87671","0.00595"
"106.76400","8.89716","0.00602"
"107.01000","8.91767","0.00632"
"107.25600","8.93824","0.00627"
"107.50200","8.95862","0.00596"
"107.74800","8.97919","0.00543"
"107.99400","8.99958","0.00598"
"108.24000","9.02021","0.00581"
"108.48600","9.04066","0.00594"
"108.73200","9.06122","0.00593"
"108.97800","9.08161","0.00607"
"109.22400","9.10212","0.00579"
"109.47000","9.12263","0.00543"
"109.71600","9.14320","0.00574"
"109.96200","9.16370","0.00542"
"110.20800","9.18415","0.00518"
"110.45400","9.20472","0.00546"
"110.70000","9.22517","0.00539"
"110.94600","9.24567","0.00556"
"111.19200","9.26606","0.00562"
"111.43800","9.28669","0.00568"
"111.68400","9.30720","0.00563"
"111.93000","9.32765","0.00572"
"112.17600","9.34815","0.00594"
"112.42200","9.36866","0.00606"
"112.66800","9.38917","0.00572"
"112.91400","9.40968","0.00539"
"113.16000","9.43019","0.00571"
"113.40600","9.45063","0.00581"
"113.65200","9.47120","0.00560"
"113.89800","9.49165","0.00598"
"114.14400","9.51216","0.00578"
"114.39000","9.53260","0.00597"
"114.63600","9.55317","0.00594"
"114.88200","9.57362","0.00590"
"115.12800","9.59419","0.00583"
"115.37400","9.61464","0.00644"
"115.62000","9.63514","0.00589"
"115.86600","9.65571","0.00549"
"116.11200","9.67616","0.00585"
"116.35800","9.69673","0.00614"
"116.60400","9.71711","0.00589"
"116.85000","9.73774","0.00592"
"117.09600","9.75813","0.00611"
"117.34200","9.77864","0.00587"
"117.58800","9.79914","0.00595"
"117.83400","9.81965","0.00593"
"118.08000","9.84016","0.00566"
"118.32600","9.86073","0.00589"
"118.57200","9.88124","0.00634"
"118.81800","9.90162","0.00537"
"119.06400","9.92219","0.00620"
"119.31000","9.94264","0.00592"
"119.55600","9.96315","0.00580"
"119.80200","9.98360","0.00530"
"120.04800","10.00422","0.00577"
"120.29400","10.02461","0.00587"
"120.54000","10.04518","0.00593"
"120.78600","10.06563","0.00554"
"121.03200","10.08620","0.00632"
"121.27800","10.10664","0.00592"
"121.52400","10.12715","0.00612"
"121.77000","10.14766","0.00572"
"122.01600","10.16811","0.00596"
"122.26200","10.18867","0.00543"
"122.50800","10.20912","0.00532"
"122.75400","10.22969","0.00506"
"123.00000","10.25014","0.00542"
"123.24600","10.27065","0.00559"
"123.49200","10.29115","0.00496"
"123.73800","10.31178","0.00513"
"123.98400","10.33217","0.00532"
"124.23000","10.35268","0.00534"
"124.47600","10.37318","0.00508"
"124.72200","10.39363","0.00550"
"124.96800","10.41420","0.00575"
"125.21400","10.43465","0.00595"
"125.46000","10.45522","0.00585"
"125.70600","10.47566","0.00510"
"125.95200","10.49617","0.00585"
"126.19800","10.51662","0.00511"
"126.44400","10.53719","0.00505"
"126.69000","10.55764","0.00531"
"126.93600","10.57814","0.00573"
"127.18200","10.59871","0.00596"
"127.42800","10.61916","0.00583"
"127.67400","10.63973","0.00570"
"127.92000","10.66011","0.00555"
"128.16600","10.68068","0.00554"
"128.41200","10.70107","0.00540"
"128.65800","10.72170","0.00588"
"128.90400","10.74221","0.00558"
"129.15000","10.76271","0.00574"
"129.39600","10.78316","0.00561"
"129.64200","10.80367","0.00561"
"129.88800","10.82418","0.00550"
"130.13400","10.84463","0.00538"
"130.38000","10.86513","0.00637"
"130.62600","10.88564","0.00566"
"130.87200","10.90615","0.00587"
"131.11800","10.92660","0.00578"
"131.36400","10.94722","0.00586"
"131.61000","10.96761","0.00547"
"131.85600","10.98818","0.00590"
"132.10200","11.00863","0.00625"
"132.34800","11.02925","0.00587"
"132.59400","11.04964","0.00542"
"132.84000","11.07015","0.00606"
"133.08600","11.09066","0.00567"
"133.33200","11.11111","0.00559"
"133.57800","11.13167","0.00508"
"133.82400","11.15212","0.00605"
"134.07000","11.17275","0.00521"
"134.31600","11.19314","0.00564"
"134.56200","11.21365","0.00549"
"134.80800","11.23409","0.00598"
"135.05400","11.25466","0.00541"
"135.30000","11.27511","0.00558"
"135.54600","11.29568","0.00566"
"135.79200","11.31618","0.00563"
"136.03800","11.33663","0.00583"
"136.28400","11.35720","0.00578"
"136.53000","11.37771","0.00567"
"136.77600","11.39816","0.00595"
"137.02200","11.41860","0.00586"
"137.26800","11.43911","0.00579"
"137.51400","11.45962","0.00548"
"137.76000","11.48019","0.00568"
"138.00600","11.50064","0.00557"
"138.25200","11.52114","0.00595"
"138.49800","11.54165","0.00548"
"138.74400","11.56210","0.00517"
"138.99000","11.58267","0.00539"
"139.23600","11.60318","0.00539"
"139.48200","11.62368","0.00585"
"139.72800","11.64413","0.00571"
"139.97400","11.66470","0.00558"
"140.22000","11.68509","0.00557"
"140.46600","11.70566","0.00543"
"140.71200","11.72616","0.00573"
"140.95800","11.74673","0.00588"
"141.20400","11.76718","0.00585"
"141.45000","11.78769","0.00568"
"141.69600","11.80819","0.00544"
"141.94200","11.82864","0.00547"
"142.18800","11.84921","0.00564"
"142.43400","11.86960","0.00512"
"142.68000","11.89017","0.00521"
"142.92600","11.91061","0.00577"
"143.17200","11.93118","0.00497"
"143.41800","11.95157","0.00555"
"143.66400","11.97220","0.00521"
"143.91000","11.99264","0.00546"
"144.15600","12.01315","0.00495"
"144.40200","12.03372","0.00468"
"144.64800","12.05417","0.00493"
"144.89400","12.07474","0.00458"
"145.14000","12.09512","0.00519"
"145.38600","12.11569","0.00489"
"145.63200","12.13608","0.00474"
"145.87800","12.15665","0.00480"
"146.12400","12.17715","0.00480"
"146.37000","12.19766","0.00469"
"146.61600","12.21817","0.00476"
"146.86200","12.23868","0.00502"
"147.10800","12.25919","0.00450"
"147.35400","12.27963","0.00510"
"147.60000","12.30014","0.00484"
"147.84600","12.32065","0.00517"
"148.09200","12.34116","0.00485"
"148.33800","12.36167","0.00480"
"148.58400","12.38217","0.00540"
"148.83000","12.40262","0.00481"
"149.07600","12.42313","0.00488"
"149.32200","12.44364","0.00467"
"149.56800","12.46426","0.00500"
"149.81400","12.48465","0.00524"
"150.06000","12.50516","0.00486"
"150.30600","12.52567","0.00488"
"150.55200","12.54618","0.00523"
"150.79800","12.56668","0.00506"
"151.04400","12.58707","0.00529"
"151.29000","12.60770","0.00525"
"151.53600","12.62815","0.00513"
"151.78200","12.64865","0.00546"
"152.02800","12.66916","0.00496"
"152.27400","12.68967","0.00580"
"152.52000","12.71018","0.00520"
"152.76600","12.73063","0.00570"
"153.01200","12.75119","0.00554"
"153.25800","12.77164","0.00568"
"153.50400","12.79221","0.00563"
"153.75000","12.81266","0.00540"
"153.99600","12.83317","0.00539"
"154.24200","12.85361","0.00560"
"154.48800","12.87418","0.00487"
"154.73400","12.89469","0.00569"
"154.98000","12.91520","0.00533"
"155.22600","12.93565","0.00535"
"155.47200","12.95621","0.00535"
"155.71800","12.97666","0.00521"
"155.96400","12.99711","0.00534"
"156.21000","13.01762","0.00577"
"156.45600","13.03813","0.00554"
"156.70200","13.05869","0.00570"
"156.94800","13.07914","0.00553"
"157.19400","13.09971","0.00622"
"157.44000","13.12010","0.00561"
"157.68600","13.14066","0.00625"
"157.93200","13.16111","0.00572"
"158.17800","13.18168","0.00601"
"158.42400","13.20213","0.00550"
"158.67000","13.22263","0.00615"
"158.91600","13.24320","0.00532"
"159.16200","13.26365","0.00562"
"159.40800","13.28416","0.00611"
"159.65400","13.30461","0.00570"
"159.90000","13.32523","0.00509"
"160.14600","13.34562","0.00588"
"160.39200","13.36613","0.00579"
"160.63800","13.38658","0.00602"
"160.88400","13.40720","0.00605"
"161.13000","13.42765","0.00524"
"161.37600","13.44822","0.00597"
"161.62200","13.46867","0.00528"
"161.86800","13.48918","0.00594"
"162.11400","13.50969","0.00589"
"162.36000","13.53019","0.00600"
"162.60600","13.55070","0.00569"
"162.85200","13.57109","0.00571"
"163.09800","13.59166","0.00559"
"163.34400","13.61216","0.00592"
"163.59000","13.63267","0.00528"
"163.83600","13.65318","0.00557"
"164.08200","13.67369","0.00560"
"164.32800","13.69413","0.00629"
"164.57400","13.71464","0.00623"
"164.82000","13.73509","0.00568"
"165.06600","13.75566","0.00551"
"165.31200","13.77617","0.00492"
"165.55800","13.79661","0.00560"
"165.80400","13.81718","0.00553"
"166.05000","13.83763","0.00563"
"166.29600","13.85820","0.00578"
"166.54200","13.87864","0.00646"
"166.78800","13.89921","0.00534"
"167.03400","13.91960","0.00588"
"167.28000","13.94017","0.00561"
"167.52600","13.96074","0.00564"
"167.77200","13.98118","0.00592"
"168.01800","14.00169","0.00613"
"168.26400","14.02208","0.00633"
"168.51000","14.04271","0.00553"
"168.75600","14.06310","0.00569"
"169.00200","14.08366","0.00589"
"169.24800","14.10417","0.00619"
"169.49400","14.12468","0.00572"
"169.74000","14.14513","0.00589"
"169.98600","14.16570","0.00502"
"170.23200","14.18620","0.00545"
"170.47800","14.20665","0.00575"
"170.72400","14.22722","0.00560"
"170.97000","14.24767","0.00567"
"171.21600","14.26817","0.00538"
"171.46200","14.28856","0.00613"
"171.70800","14.30919","0.00574"
"171.95400","14.32970","0.00595"
"172.20000","14.35021","0.00559"
"172.44600","14.37059","0.00606"
"172.69200","14.39122","0.00572"
"172.93800","14.41167","0.00622"
"173.18400","14.43218","0.00584"
"173.43000","14.45263","0.00629"
"173.67600","14.47313","0.00616"
"173.92200","14.49364","0.00566"
"174.16800","14.51415","0.00652"
"174.41400","14.53472","0.00637"
"174.66000","14.55516","0.00596"
"174.90600","14.57567","0.00602"
"175.15200","14.59618","0.00602"
"175.39800","14.61675","0.00572"
"175.64400","14.63708","0.00573"
"175.89000","14.65764","0.00551"
"176.13600","14.67821","0.00558"
"176.38200","14.69866","0.00579"
"176.62800","14.71917","0.00628"
"176.87400","14.73961","0.00602"
"177.12000","14.76024","0.00573"
"177.36600","14.78057","0.00564"
"177.61200","14.80120","0.00565"
"177.85800","14.82165","0.00539"
"178.10400","14.84215","0.00529"
"178.35000","14.86266","0.00563"
"178.59600","14.88311","0.00571"
"178.84200","14.90368","0.00599"
"179.08800","14.92413","0.00545"
"179.33400","14.94469","0.00609"
"179.58000","14.96514","0.00590"
"179.82600","14.98565","0.00543"
"180.07200","15.00610","0.00610"
"180.31800","15.02667","0.00569"
"180.56400","15.04717","0.00554"
"180.81000","15.06768","0.00590"
"181.05600","15.08819","0.00565"
"181.30200","15.10864","0.00562"
"181.54800","15.12920","0.00599"
"181.79400","15.14965","0.00617"
"182.04000","15.17016","0.00558"
"182.28600","15.19067","0.00497"
"182.53200","15.21117","0.00496"
"182.77800","15.23168","0.00508"
"183.02400","15.25219","0.00547"
"183.27000","15.27264","0.00528"
"183.51600","15.29315","0.00495"
"183.76200","15.31365","0.00556"
"184.00800","15.33428","0.00499"
"184.25400","15.35461","0.00542"
"184.50000","15.37518","0.00564"
"184.74600","15.39569","0.00592"
"184.99200","15.41619","0.00610"
"185.23800","15.43670","0.00609"
"185.48400","15.45709","0.00530"
"185.73000","15.47772","0.00533"
"185.97600","15.49811","0.00558"
"186.22200","15.51867","0.00559"
"186.46800","15.53906","0.00549"
"186.71400","15.55969","0.00560"
"186.96000","15.58014","0.00540"
"187.20600","15.60065","0.00538"
"187.45200","15.62121","0.00529"
"187.69800","15.64160","0.00520"
"187.94400","15.66217","0.00535"
"188.19000","15.68268","0.00527"
"188.43600","15.70318","0.00548"
"188.68200","15.72357","0.00523"
"188.92800","15.74420","0.00589"
"189.17400","15.76471","0.00523"
"189.42000","15.78521","0.00484"
"189.66600","15.80566","0.00503"
"189.91200","15.82617","0.00505"
"190.15800","15.84668","0.00500"
"190.40400","15.86713","0.00490"
"190.65000","15.88769","0.00540"
"190.89600","15.90814","0.00511"
"191.14200","15.92865","0.00544"
"191.38800","15.94910","0.00540"
"191.63400","15.96972","0.00526"
"191.88000","15.99017","0.00519"
"192.12600","16.01068","0.00511"
"192.37200","16.03113","0.00492"
"192.61800","16.05176","0.00482"
"192.86400","16.07214","0.00521"
"193.11000","16.09265","0.00490"
"193.35600","16.11322","0.00547"
"193.60200","16.13367","0.00525"
"193.84800","16.15417","0.00447"
"194.09400","16.17462","0.00517"
"194.34000","16.19519","0.00521"
"194.58600","16.21564","0.00580"
"194.83200","16.23615","0.00539"
"195.07800","16.25665","0.00538"
"195.32400","16.27716","0.00511"
"195.57000","16.29761","0.00531"
"195.81600","16.31818","0.00525"
"196.06200","16.33875","0.00532"
"196.30800","16.35913","0.00501"
"196.55400","16.37970","0.00534"
"196.80000","16.40015","0.00565"
"197.04600","16.42066","0.00501"
"197.29200","16.44110","0.00516"
"197.53800","16.46167","0.00563"
"197.78400","16.48218","0.00575"
"198.03000","16.50269","0.00492"
"198.27600","16.52320","0.00517"
"198.52200","16.54370","0.00519"
"198.76800","16.56415","0.00536"
"199.01400","16.58460","0.00506"
"199.26000","16.60511","0.00505"
"199.50600","16.62568","0.00550"
"199.75200","16.64618","0.00546"
"199.99800","16.66663","0.00510"
"200.24400","16.68720","0.00541"
"200.49000","16.70765","0.00540"
"200.73600","16.72816","0.00538"
"200.98200","16.74866","0.00541"
"201.22800","16.76923","0.00512"
"201.47400","16.78968","0.00525"
"201.72000","16.81019","0.00558"
"201.96600","16.83069","0.00518"
"202.21200","16.85114","0.00541"
"202.45800","16.87165","0.00545"
"202.70400","16.89210","0.00523"
"202.95000","16.91273","0.00535"
"203.19600","16.93311","0.00545"
"203.44200","16.95368","0.00496"
"203.68800","16.97413","0.00561"
"203.93400","16.99464","0.00566"
"204.18000","17.01514","0.00476"
"204.42600","17.03565","0.00540"
"204.67200","17.05622","0.00595"
"204.91800","17.07661","0.00516"
"205.16400","17.09718","0.00561"
"205.41000","17.11762","0.00542"
"205.65600","17.13819","0.00532"
"205.90200","17.15858","0.00564"
"206.14800","17.17921","0.00579"
"206.39400","17.19965","0.00579"
"206.64000","17.22016","0.00515"
"206.88600","17.24067","0.00586"
"207.13200","17.26118","0.00565"
"207.37800","17.28169","0.00566"
"207.62400","17.30214","0.00517"
"207.87000","17.32264","0.00551"
"208.11600","17.34315","0.00587"
"208.36200","17.36366","0.00546"
"208.60800","17.38411","0.00576"
"208.85400","17.40473","0.00582"
"209.10000","17.42512","0.00534"
"209.34600","17.44569","0.00546"
"209.59200","17.46614","0.00573"
"209.83800","17.48670","0.00544"
"210.08400","17.50715","0.00507"
"210.33000","17.52766","0.00584"
"210.57600","17.54823","0.00544"
"210.82200","17.56862","0.00558"
"211.06800","17.58918","0.00605"
"211.31400","17.60963","0.00542"
"211.56000","17.63020","0.00555"
"211.80600","17.65059","0.00554"
"212.05200","17.67115","0.00572"
"212.29800","17.69166","0.00592"
"212.54400","17.71223","0.00609"
"212.79000","17.73262","0.00545"
"213.03600","17.75319","0.00579"
"213.28200","17.77369","0.00581"
"213.52800","17.79414","0.00553"
"213.77400","17.81471","0.00607"
"214.02000","17.83516","0.00543"
"214.26600","17.85567","0.00583"
"214.51200","17.87611","0.00634"
"214.75800","17.89668","0.00579"
"215.00400","17.91713","0.00582"
"215.25000","17.93770","0.00597"
"215.49600","17.95815","0.00525"
"215.74200","17.97871","0.00562"
"215.98800","17.99916","0.00570"
"216.23400","18.01961","0.00543"
"216.48000","18.04012","0.00581"
"216.72600","18.06063","0.00573"
"216.97200","18.08119","0.00540"
"217.21800","18.10164","0.00574"
"217.46400","18.12215","0.00600"
"217.71000","18.14266","0.00536"
"217.95600","18.16316","0.00547"
"218.20200","18.18367","0.00600"
"218.44800","18.20424","0.00519"
"218.69400","18.22457","0.00596"
"218.94000","18.24519","0.00549"
"219.18600","18.26570","0.00604"
"219.43200","18.28615","0.00627"
"219.67800","18.30666","0.00583"
"219.92400","18.32711","0.00607"
"220.17000","18.34773","0.00630"
"220.41600","18.36812","0.00609"
"220.66200","18.38869","0.00566"
"220.90800","18.40914","0.00625"
"221.15400","18.42964","0.00520"
"221.40000","18.45009","0.00520"
"221.64600","18.47066","0.00543"
"221.89200","18.49117","0.00557"
"222.13800","18.51162","0.00561"
"222.38400","18.53218","0.00588"
"222.63000","18.55263","0.00623"
"222.87600","18.57320","0.00553"
"223.12200","18.59359","0.00535"
"223.36800","18.61416","0.00598"
"223.61400","18.63466","0.00593"
"223.86000","18.65517","0.00587"
"224.10600","18.67562","0.00632"
"224.35200","18.69613","0.00594"
"224.59800","18.71663","0.00577"
"224.84400","18.73714","0.00585"
"225.09000","18.75765","0.00566"
"225.33600","18.77816","0.00644"
"225.58200","18.79867","0.00597"
"225.82800","18.81911","0.00642"
"226.07400","18.83968","0.00568"
"226.32000","18.86013","0.00591"
"226.56600","18.88070","0.00625"
"226.81200","18.90115","0.00633"
"227.05800","18.92171","0.00637"
"227.30400","18.94210","0.00579"
"227.55000","18.96267","0.00634"
"227.79600","18.98324","0.00645"
"228.04200","19.00368","0.00617"
"228.28800","19.02419","0.00634"
"228.53400","19.04458","0.00667"
"228.78000","19.06521","0.00648"
"229.02600","19.08560","0.00646"
"229.27200","19.10616","0.00668"
"229.51800","19.12661","0.00629"
"229.76400","19.14718","0.00603"
"230.01000","19.16769","0.00664"
"230.25600","19.18814","0.00686"
"230.50200","19.20864","0.00679"
"230.74800","19.22915","0.00638"
"230.99400","19.24972","0.00631"
"231.24000","19.27017","0.00663"
"231.48600","19.29067","0.00712"
"231.73200","19.31112","0.00691"
"231.97800","19.33169","0.00666"
"232.22400","19.35214","0.00677"
"232.47000","19.37271","0.00639"
"232.71600","19.39315","0.00730"
"232.96200","19.41366","0.00745"
"233.20800","19.43417","0.00699"
"233.45400","19.45468","0.00680"
"233.70000","19.47518","0.00705"
"233.94600","19.49563","0.00696"
"234.19200","19.51620","0.00691"
"234.43800","19.53665","0.00717"
"234.68400","19.55722","0.00741"
"234.93000","19.57766","0.00713"
"235.17600","19.59817","0.00718"
"235.42200","19.61862","0.00727"
"235.66800","19.63925","0.00704"
"235.91400","19.65964","0.00718"
"236.16000","19.68014","0.00729"
"236.40600","19.70071","0.00743"
"236.65200","19.72116","0.00742"
"236.89800","19.74166","0.00732"
"237.14400","19.76205","0.00595"
"237.39000","19.78268","0.00707"
"237.63600","19.80313","0.00746"
"237.88200","19.82370","0.00735"
"238.12800","19.84415","0.00728"
"238.37400","19.86471","0.00716"
"238.62000","19.88516","0.00760"
"238.86600","19.90567","0.00786"
"239.11200","19.92618","0.00809"
"239.35800","19.94662","0.00783"
"239.60400","19.96719","0.00761"
"239.85000","19.98764","0.00790"
"240.09600","20.00821","0.00785"
"240.34200","20.02860","0.00721"
"240.58800","20.04916","0.00812"
"240.83400","20.06967","0.00815"
"241.08000","20.09018","0.00784"
"241.32600","20.11069","0.00769"
"241.57200","20.13119","0.00800"
"241.81800","20.15164","0.00791"
"242.06400","20.17215","0.00787"
"242.31000","20.19266","0.00831"
"242.55600","20.21317","0.00835"
"242.80200","20.23367","0.00840"
"243.04800","20.25412","0.00829"
"243.29400","20.27463","0.00787"
"243.54000","20.29508","0.00793"
"243.78600","20.31565","0.00820"
"244.03200","20.33615","0.00809"
"244.27800","20.35672","0.00857"
"244.52400","20.37711","0.00819"
"244.77000","20.39768","0.00865"
"245.01600","20.41819","0.00882"
"245.26200","20.43863","0.00882"
"245.50800","20.45920","0.00849"
"245.75400","20.47959","0.00853"
"246.00000","20.50022","0.00864"
"246.24600","20.52061","0.00823"
"246.49200","20.54117","0.00853"
"246.73800","20.56162","0.00891"
"246.98400","20.58219","0.00920"
"247.23000","20.60270","0.00885"
"247.47600","20.62320","0.00899"
"247.72200","20.64371","0.00898"
"247.96800","20.66410","0.00857"
"248.21400","20.68467","0.00875"
"248.46000","20.70518","0.00950"
"248.70600","20.72568","0.00855"
"248.95200","20.74607","0.00915"
"249.19800","20.76670","0.00904"
"249.44400","20.78720","0.00930"
"249.69000","20.80766","0.00946"
"249.93600","20.82816","0.00879"
"250.18200","20.84867","0.00909"
"250.42800","20.86918","0.00917"
"250.67400","20.88969","0.00914"
"250.92000","20.91013","0.00956"
"251.16600","20.93058","0.00943"
"251.41200","20.95115","0.00951"
"251.65800","20.97160","0.00968"
"251.90400","20.99216","0.00980"
"252.15000","21.01261","0.00958"
"252.39600","21.03312","0.01008"
"252.64200","21.05363","0.00986"
"252.88800","21.07425","0.00984"
"253.13400","21.09464","0.00986"
"253.38000","21.11515","0.00977"
"253.62600","21.13572","0.01017"
"253.87200","21.15617","0.00933"
"254.11800","21.17668","0.01016"
"254.36400","21.19712","0.01025"
"254.61000","21.21769","0.01052"
"254.85600","21.23814","0.01039"
"255.10200","21.25865","0.01033"
"255.34800","21.27915","0.01044"
"255.59400","21.29972","0.01035"
"255.84000","21.32017","0.01046"
"256.08600","21.34068","0.01061"
"256.33200","21.36124","0.00993"
"256.57800","21.38164","0.01033"
"256.82400","21.40220","0.01112"
"257.07000","21.42265","0.01108"
"257.31600","21.44316","0.01087"
"257.56200","21.46355","0.01077"
"257.80800","21.48417","0.01091"
"258.05400","21.50468","0.01094"
"258.30000","21.52519","0.01110"
"258.54600","21.54570","0.01128"
"258.79200","21.56614","0.01150"
"259.03800","21.58665","0.01141"
"259.28400","21.60716","0.01154"
"259.53000","21.62761","0.01110"
"259.77600","21.64818","0.01157"
"260.02200","21.66868","0.01200"
"260.26800","21.68907","0.01173"
"260.51400","21.70970","0.01167"
"260.76000","21.73009","0.01183"
"261.00600","21.75065","0.01205"
"261.25200","21.77110","0.01183"
"261.49800","21.79173","0.01249"
"261.74400","21.81212","0.01256"
"261.99000","21.83269","0.01217"
"262.23600","21.85319","0.01265"
"262.48200","21.87364","0.01219"
"262.72800","21.89421","0.01267"
"262.97400","21.91460","0.01257"
"263.22000","21.93523","0.01276"
"263.46600","21.95561","0.01318"
"263.71200","21.97612","0.01283"
"263.95800","21.99663","0.01314"
"264.20400","22.01720","0.01271"
"264.45000","22.03765","0.01306"
"264.69600","22.05815","0.01356"
"264.94200","22.07866","0.01335"
"265.18800","22.09911","0.01332"
"265.43400","22.11968","0.01334"
"265.68000","22.14018","0.01386"
"265.92600","22.16069","0.01379"
"266.17200","22.18114","0.01359"
"266.41800","22.20165","0.01399"
"266.66400","22.22216","0.01394"
"266.91000","22.24266","0.01378"
"267.15600","22.26311","0.01412"
"267.40200","22.28368","0.01438"
"267.64800","22.30419","0.01444"
"267.89400","22.32463","0.01445"
"268.14000","22.34514","0.01453"
"268.38600","22.36565","0.01457"
"268.63200","22.38616","0.01467"
"268.87800","22.40661","0.01474"
"269.12400","22.42717","0.01458"
"269.37000","22.44762","0.01499"
"269.61600","22.46813","0.01493"
"269.86200","22.48864","0.01499"
"270.10800","22.50921","0.01543"
"270.35400","22.52965","0.01507"
"270.60000","22.55016","0.01508"
"270.84600","22.57073","0.01510"
"271.09200","22.59118","0.01528"
"271.33800","22.61168","0.01548"
"271.58400","22.63213","0.01577"
"271.83000","22.65270","0.01590"
"272.07600","22.67315","0.01617"
"272.32200","22.69366","0.01600"
"272.56800","22.71410","0.01606"
"272.81400","22.73473","0.01642"
"273.06000","22.75512","0.01662"
"273.30600","22.77563","0.01644"
"273.55200","22.79619","0.01704"
"273.79800","22.81664","0.01711"
"274.04400","22.83721","0.01766"
"274.29000","22.85766","0.01739"
"274.53600","22.87816","0.01749"
"274.78200","22.89856","0.01783"
"275.02800","22.91918","0.01783"
"275.27400","22.93963","0.01818"
"275.52000","22.96014","0.01841"
"275.76600","22.98065","0.01849"
"276.01200","23.00115","0.01839"
"276.25800","23.02166","0.01908"
"276.50400","23.04217","0.01932"
"276.75000","23.06268","0.01917"
"276.99600","23.08319","0.01956"
"277.24200","23.10363","0.01995"
"277.48800","23.12414","0.01973"
"277.73400","23.14465","0.02038"
"277.98000","23.16510","0.02050"
"278.22600","23.18567","0.02039"
"278.47200","23.20611","0.02028"
"278.71800","23.22674","0.01968"
"278.96400","23.24713","0.02002"
"279.21000","23.26770","0.01988"
"279.45600","23.28820","0.02036"
"279.70200","23.30865","0.02062"
"279.94800","23.32922","0.02094"
"280.19400","23.34955","0.02099"
"280.44000","23.37023","0.02136"
"280.68600","23.39062","0.02162"
"280.93200","23.41119","0.02216"
"281.17800","23.43164","0.02212"
"281.42400","23.45220","0.02238"
"281.67000","23.47265","0.02260"
"281.91600","23.49316","0.02312"
"282.16200","23.51373","0.02330"
"282.40800","23.53411","0.02352"
"282.65400","23.55468","0.02428"
"282.90000","23.57513","0.02475"
"283.14600","23.59564","0.02500"
"283.39200","23.61609","0.02546"
"283.63800","23.63665","0.02527"
"283.88400","23.65716","0.02563"
"284.13000","23.67767","0.02611"
"284.37600","23.69812","0.02681"
"284.62200","23.71875","0.02716"
"284.86800","23.73920","0.02712"
"285.11400","23.75964","0.02752"
"285.36000","23.78015","0.02831"
"285.60600","23.80066","0.02813"
"285.85200","23.82117","0.02899"
"286.09800","23.84162","0.02897"
"286.34400","23.86218","0.02973"
"286.59000","23.88263","0.03026"
"286.83600","23.90320","0.03057"
"287.08200","23.92365","0.03103"
"287.32800","23.94421","0.03126"
"287.57400","23.96466","0.03200"
"287.82000","23.98517","0.03305"
"288.06600","24.00568","0.03257"
"288.31200","24.02619","0.03320"
"288.55800","24.04663","0.03381"
"288.80400","24.06708","0.03420"
"289.05000","24.08777","0.03412"
"289.29600","24.10810","0.03494"
"289.54200","24.12866","0.03587"
"289.78800","24.14911","0.03573"
"290.03400","24.16968","0.03652"
"290.28000","24.19013","0.03650"
"290.52600","24.21070","0.03782"
"290.77200","24.23120","0.03855"
"291.01800","24.25165","0.03917"
"291.26400","24.27222","0.03604"
"291.51000","24.29267","0.03836"
"291.75600","24.31317","0.03757"
"292.00200","24.33362","0.03974"
"292.24800","24.35419","0.03955"
"292.49400","24.37470","0.03965"
"292.74000","24.39520","0.04252"
"292.98600","24.41566","0.04109"
"293.23200","24.43616","0.04349"
"293.47800","24.45667","0.04389"
"293.72400","24.47712","0.04345"
"293.97000","24.49756","0.04493"
"294.21600","24.51813","0.04488"
"294.46200","24.53870","0.04601"
"294.70800","24.55915","0.04690"
"294.95400","24.57965","0.04684"
"295.20000","24.60010","0.04848"
"295.44600","24.62061","0.04875"
"295.69200","24.64112","0.04957"
"295.93800","24.66175","0.05094"
"296.18400","24.68213","0.05053"
"296.43000","24.70264","0.05213"
"296.67600","24.72321","0.05179"
"296.92200","24.74366","0.05279"
"297.16800","24.76417","0.05436"
"297.41400","24.78461","0.05446"
"297.66000","24.80524","0.05542"
"297.90600","24.82563","0.05548"
"298.15200","24.84614","0.05650"
"298.39800","24.86665","0.05784"
"298.64400","24.88716","0.05817"
"298.89000","24.90766","0.05914"
"299.13600","24.92817","0.05935"
"299.38200","24.94874","0.06007"
"299.62800","24.96913","0.06038"
"299.87400","24.98969","0.06135"
"300.12000","25.01014","0.06205"
"300.36600","25.03065","0.06266"
"300.61200","25.05104","0.06323"
"300.85800","25.07166","0.06306"
"301.10400","25.09217","0.06381"
"301.35000","25.11268","0.06438"
"301.59600","25.13313","0.06496"
"301.84200","25.15370","0.06635"
"302.08800","25.17420","0.06772"
"302.33400","25.19465","0.06806"
"302.58000","25.21516","0.06886"
"302.82600","25.23567","0.07034"
"303.07200","25.25617","0.07088"
"303.31800","25.27662","0.07143"
"303.56400","25.29713","0.07306"
"303.81000","25.31764","0.07407"
"304.05600","25.33815","0.07496"
"304.30200","25.35865","0.07611"
"304.54800","25.37922","0.07777"
"304.79400","25.39961","0.07801"
"305.04000","25.42018","0.07902"
"305.28600","25.44069","0.08068"
"305.53200","25.46119","0.08184"
"305.77800","25.48170","0.08329"
"306.02400","25.50209","0.08453"
"306.27000","25.52272","0.08533"
"306.51600","25.54310","0.08700"
"306.76200","25.56367","0.08847"
"307.00800","25.58412","0.08858"
"307.25400","25.60469","0.09053"
"307.50000","25.62514","0.09127"
"307.74600","25.64564","0.09244"
"307.99200","25.66621","0.09324"
"308.23800","25.68666","0.09407"
"308.48400","25.70717","0.09464"
"308.73000","25.72767","0.09572"
"308.97600","25.74818","0.09621"
"309.22200","25.76857","0.09693"
"309.46800","25.78914","0.09800"
"309.71400","25.80965","0.09852"
"309.96000","25.83021","0.09896"
"310.20600","25.85066","0.09946"
"310.45200","25.87123","0.10037"
"310.69800","25.89168","0.10072"
"310.94400","25.91212","0.10091"
"311.19000","25.93263","0.10192"
"311.43600","25.95314","0.10205"
"311.68200","25.97365","0.10255"
"311.92800","25.99416","0.10309"
"312.17400","26.01467","0.10341"
"312.42000","26.03511","0.10369"
"312.66600","26.05568","0.10447"
"312.91200","26.07613","0.10457"
"313.15800","26.09676","0.10524"
"313.40400","26.11714","0.10551"
"313.65000","26.13765","0.10590"
"313.89600","26.15816","0.10613"
"314.14200","26.17861","0.10660"
"314.38800","26.19917","0.10695"
"314.63400","26.21956","0.10721"
"314.88000","26.24025","0.10813"
"315.12600","26.26064","0.10850"
"315.37200","26.28121","0.10867"
"315.61800","26.30159","0.10939"
"315.86400","26.32216","0.11034"
"316.11000","26.34267","0.11102"
"316.35600","26.36312","0.11226"
"316.60200","26.38375","0.11233"
"316.84800","26.40413","0.11361"
"317.09400","26.42470","0.11461"
"317.34000","26.44515","0.11530"
"317.58600","26.46572","0.11647"
"317.83200","26.48611","0.11699"
"318.07800","26.50667","0.11866"
"318.32400","26.52718","0.11946"
"318.57000","26.54769","0.12063"
"318.81600","26.56814","0.12177"
"319.06200","26.58864","0.12279"
"319.30800","26.60915","0.12348"
"319.55400","26.62966","0.12437"
"319.80000","26.65017","0.12533"
"320.04600","26.67068","0.12621"
"320.29200","26.69113","0.12767"
"320.53800","26.71163","0.12908"
"320.78400","26.73220","0.13058"
"321.03000","26.75265","0.13164"
"321.27600","26.77316","0.13331"
"321.52200","26.79360","0.13386"
"321.76800","26.81423","0.13552"
"322.01400","26.83462","0.13680"
"322.26000","26.85513","0.13810"
"322.50600","26.87569","0.13994"
"322.75200","26.89614","0.14235"
"322.99800","26.91671","0.14390"
"323.24400","26.93716","0.14543"
"323.49000","26.95766","0.14734"
"323.73600","26.97812","0.14887"
"323.98200","26.99868","0.14982"
"324.22800","27.01919","0.14883"
"324.47400","27.03970","0.15072"
"324.72000","27.06008","0.15269"
"324.96600","27.08071","0.15375"
"325.21200","27.10122","0.15607"
"325.45800","27.12167","0.15737"
"325.70400","27.14218","0.15848"
"325.95000","27.16262","0.15981"
"326.19600","27.18319","0.16102"
"326.44200","27.20358","0.16217"
"326.68800","27.22421","0.16352"
"326.93400","27.24466","0.16481"
"327.18000","27.26517","0.16535"
"327.42600","27.28567","0.16663"
"327.67200","27.30618","0.16683"
"327.91800","27.32669","0.16810"
"328.16400","27.34713","0.16824"
"328.41000","27.36764","0.16944"
"328.65600","27.38815","0.17017"
"328.90200","27.40866","0.17063"
"329.14800","27.42911","0.17143"
"329.39400","27.44967","0.17164"
"329.64000","27.47018","0.04146"
"329.88600","27.49069","0.04603"
"330.13200","27.51114","0.02871"
"330.37800","27.53170","0.04409"
"330.62400","27.55215","0.03156"
"330.87000","27.57266","0.03255"
"331.11600","27.59317","0.04430"
"331.36200","27.61368","0.03149"
"331.60800","27.63418","0.04486"
"331.85400","27.65457","0.03388"
"332.10000","27.67520","0.03778"
"332.34600","27.69565","0.04527"
"332.59200","27.71616","0.03546"
"332.83800","27.73660","0.04822"
"333.08400","27.75717","0.03710"
"333.33000","27.77762","0.04263"
"333.57600","27.79819","0.04535"
"333.82200","27.81870","0.03959"
"334.06800","27.83914","0.04959"
"334.31400","27.85965","0.04157"
"334.56000","27.88016","0.04720"
"334.80600","27.90067","0.04696"
"335.05200","27.92105","0.04531"
"335.29800","27.94168","0.05041"
"335.54400","27.96219","0.04683"
"335.79000","27.98270","0.05127"
"336.03600","28.00320","0.04883"
"336.28200","28.02365","0.05126"
"336.52800","28.04416","0.04986"
"336.77400","28.06467","0.05089"
"337.02000","28.08512","0.05229"
"337.26600","28.10562","0.05001"
"337.51200","28.12613","0.05397"
"337.75800","28.14658","0.05064"
"338.00400","28.16721","0.05424"
"338.25000","28.18765","0.05293"
"338.49600","28.20816","0.05358"
"338.74200","28.22861","0.05486"
"338.98800","28.24918","0.05397"
"339.23400","28.26963","0.05658"
"339.48000","28.29013","0.05466"
"339.72600","28.31071","0.05667"
"339.97200","28.33115","0.05580"
"340.21800","28.35172","0.05736"
"340.46400","28.37211","0.05814"
"340.71000","28.39274","0.05769"
"340.95600","28.41312","0.05902"
"341.20200","28.43369","0.05891"
"341.44800","28.45414","0.05974"
"341.69400","28.47470","0.05966"
"341.94000","28.49516","0.06101"
"342.18600","28.51566","0.06104"
"342.43200","28.53617","0.06197"
"342.67800","28.55668","0.06150"
"342.92400","28.57724","0.06282"
"343.17000","28.59763","0.06321"
"343.41600","28.61820","0.06340"
"343.66200","28.63859","0.06422"
"343.90800","28.65916","0.06427"
"344.15400","28.67966","0.06581"
"344.40000","28.70017","0.06552"
"344.64600","28.72062","0.06722"
"344.89200","28.74119","0.06748"
"345.13800","28.76170","0.06817"
"345.38400","28.78214","0.06763"
"345.63000","28.80259","0.06916"
"345.87600","28.82316","0.06935"
"346.12200","28.84367","0.07100"
"346.36800","28.86411","0.07091"
"346.61400","28.88468","0.07224"
"346.86000","28.90513","0.07174"
"347.10600","28.92564","0.07154"
"347.35200","28.94615","0.07237"
"347.59800","28.96671","0.07207"
"347.84400","28.98710","0.07350"
"348.09000","29.00767","0.07314"
"348.33600","29.02818","0.07535"
"348.58200","29.04869","0.07489"
"348.82800","29.06919","0.07569"
"349.07400","29.08958","0.07666"
"349.32000","29.11021","0.07727"
"349.56600","29.13060","0.07866"
"349.81200","29.15116","0.07843"
"350.05800","29.17161","0.07965"
"350.30400","29.19218","0.08030"
"350.55000","29.21263","0.08116"
"350.79600","29.23314","0.08124"
"351.04200","29.25370","0.08229"
"351.28800","29.27415","0.08380"
"351.53400","29.29472","0.08426"
"351.78000","29.31511","0.08444"
"352.02600","29.33567","0.08611"
"352.27200","29.35606","0.08599"
"352.51800","29.37663","0.08751"
"352.76400","29.39720","0.08758"
"353.01000","29.41771","0.08875"
"353.25600","29.43815","0.08873"
"353.50200","29.45866","0.08963"
"353.74800","29.47917","0.09021"
"353.99400","29.49962","0.09085"
"354.24000","29.52013","0.09180"
"354.48600","29.54070","0.09142"
"354.73200","29.56114","0.09252"
"354.97800","29.58165","0.09310"
"355.22400","29.60216","0.09407"
"355.47000","29.62260","0.09529"
"355.71600","29.64318","0.09522"
"355.96200","29.66368","0.09597"
"356.20800","29.68425","0.09592"
"356.45400","29.70464","0.09723"
"356.70000","29.72514","0.09669"
"356.94600","29.74571","0.09761"
"357.19200","29.76616","0.09835"
"357.43800","29.78667","0.09850"
"357.68400","29.80705","0.09886"
"357.93000","29.82768","0.09916"
"358.17600","29.84813","0.09935"
"358.42200","29.86864","0.10001"
"358.66800","29.88909","0.10026"
"358.91400","29.90965","0.10031"
"359.16000","29.93022","0.10082"
"359.40600","29.95067","0.10126"
"359.65200","29.97118","0.10137"
"359.89800","29.99162","0.10161"
"360.14400","30.01219","0.09327"
"360.39000","30.03264","-0.00405"
"360.63600","30.05315","-0.00230"
"360.88200","30.07360","0.00309"
"361.12800","30.09417","0.00316"
"361.37400","30.11467","0.00285"
"361.62000","30.13518","0.00329"
"361.86600","30.15563","0.00334"
"362.11200","30.17614","0.00285"
"362.35800","30.19670","0.00273"
"362.60400","30.21715","0.00326"
"362.85000","30.23766","0.00261"
"363.09600","30.25817","0.00323"
"363.34200","30.27868","0.00300"
"363.58800","30.29918","0.00252"
"363.83400","30.31975","0.00297"
"364.08000","30.34014","0.00314"
"364.32600","30.36065","0.00283"
"364.57200","30.38109","0.00274"
"364.81800","30.40172","0.00273"
"365.06400","30.42211","0.00232"
"365.31000","30.44268","0.00325"
"365.55600","30.46325","0.00299"
"365.80200","30.48369","0.00307"
"366.04800","30.50420","0.00342"
"366.29400","30.52459","0.00281"
"366.54000","30.54522","0.00301"
"366.78600","30.56561","0.00292"
"367.03200","30.58624","0.00289"
"367.27800","30.60662","0.00295"
"367.52400","30.62719","0.00336"
"367.77000","30.64764","0.00315"
"368.01600","30.66814","0.00303"
"368.26200","30.68871","0.00315"
"368.50800","30.70910","0.00304"
"368.75400","30.72967","0.00284"
"368.86400","30.73888","0.00309"