File: Force_trajectories/161226_1/Specimen_RawData_8.csv
End date,"12/26/2016"
Specimen label,"22AG_77"
Maximum Load,"0.13139",N

Time,Extension,Load
(s),(mm),(N)
"0.00000","0.00000","-0.00021"
"0.34800","0.02894","-0.00006"
"0.69600","0.05818","-0.00031"
"1.04400","0.08717","0.00011"
"1.39200","0.11617","-0.00021"
"1.74000","0.14517","0.00039"
"2.08800","0.17411","-0.00031"
"2.43600","0.20316","0.00032"
"2.78400","0.23216","-0.00001"
"3.13200","0.26116","0.00025"
"3.48000","0.29016","-0.00017"
"3.82800","0.31910","-0.00009"
"4.17600","0.34809","-0.00015"
"4.52400","0.37715","0.00011"
"4.87200","0.40609","-0.00019"
"5.22000","0.43521","-0.00014"
"5.56800","0.46415","0.00025"
"5.91600","0.49308","0.00015"
"6.26400","0.52214","0.00024"
"6.61200","0.55114","0.00013"
"6.96000","0.58014","0.00027"
"7.30800","0.60920","-0.00008"
"7.65600","0.63819","-0.00023"
"8.00400","0.66713","-0.00038"
"8.35200","0.69619","0.00013"
"8.70000","0.72513","0.00007"
"9.04800","0.75413","0.00012"
"9.39600","0.78318","0.00009"
"9.74400","0.81212","0.00024"
"10.09200","0.84118","-0.00026"
"10.44000","0.87018","0.00033"
"10.78800","0.89912","-0.00015"
"11.13600","0.92817","-0.00004"
"11.48400","0.95717","0.00012"
"11.83200","0.98611","0.00010"
"12.18000","1.01517","0.00018"
"12.52800","1.04416","-0.00021"
"12.87600","1.07310","-0.00049"
"13.22400","1.10216","0.00018"
"13.57200","1.13116","-0.00048"
"13.92000","1.16016","-0.00017"
"14.26800","1.18921","-0.00040"
"14.61600","1.21815","0.00054"
"14.96400","1.24715","-0.00008"
"15.31200","1.27615","-0.00045"
"15.66000","1.30509","-0.00022"
"16.00800","1.33414","-0.00027"
"16.35600","1.36320","-0.00034"
"16.70400","1.39214","-0.00078"
"17.05200","1.42108","-0.00024"
"17.40000","1.45020","-0.00068"
"17.74800","1.47913","-0.00029"
"18.09600","1.50813","0.00018"
"18.44400","1.53719","-0.00023"
"18.79200","1.56613","-0.00021"
"19.14000","1.59518","-0.00011"
"19.48800","1.62418","-0.00070"
"19.83600","1.65312","-0.00013"
"20.18400","1.68218","-0.00019"
"20.53200","1.71112","0.00014"
"20.88000","1.74017","-0.00013"
"21.22800","1.76917","0.00014"
"21.57600","1.79817","-0.00078"
"21.92400","1.82711","-0.00015"
"22.27200","1.85617","-0.00012"
"22.62000","1.88510","-0.00007"
"22.96800","1.91416","0.00007"
"23.31600","1.94316","-0.00030"
"23.66400","1.97210","0.00017"
"24.01200","2.00116","0.00003"
"24.36000","2.03015","-0.00040"
"24.70800","2.05915","0.00015"
"25.05600","2.08815","-0.00046"
"25.40400","2.11715","-0.00035"
"25.75200","2.14615","0.00013"
"26.10000","2.17520","-0.00006"
"26.44800","2.20414","0.00040"
"26.79600","2.23314","-0.00004"
"27.14400","2.26214","-0.00023"
"27.49200","2.29114","0.00065"
"27.84000","2.32007","-0.00074"
"28.18800","2.34919","-0.00025"
"28.53600","2.37807","-0.00024"
"28.88400","2.40719","-0.00004"
"29.23200","2.43618","0.00022"
"29.58000","2.46512","0.00044"
"29.92800","2.49418","0.00012"
"30.27600","2.52312","-0.00043"
"30.62400","2.55212","0.00013"
"30.97200","2.58117","-0.00029"
"31.32000","2.61017","0.00043"
"31.66800","2.63911","-0.00026"
"32.01600","2.66817","-0.00034"
"32.36400","2.69717","-0.00013"
"32.71200","2.72610","-0.00036"
"33.06000","2.75516","-0.00003"
"33.40800","2.78410","-0.00025"
"33.75600","2.81322","0.00008"
"34.10400","2.84222","-0.00016"
"34.45200","2.87115","0.00003"
"34.80000","2.90015","0.00016"
"35.14800","2.92915","0.00009"
"35.49600","2.95809","0.00000"
"35.84400","2.98720","0.00037"
"36.19200","3.01620","-0.00009"
"36.54000","3.04508","-0.00003"
"36.88800","3.07414","0.00005"
"37.23600","3.10320","-0.00027"
"37.58400","3.13213","-0.00016"
"37.93200","3.16119","-0.00021"
"38.28000","3.19013","0.00031"
"38.62800","3.21913","-0.00017"
"38.97600","3.24819","0.00003"
"39.32400","3.27712","0.00014"
"39.67200","3.30612","-0.00032"
"40.02000","3.33512","-0.00003"
"40.36800","3.36412","-0.00001"
"40.71600","3.39312","-0.00036"
"41.06400","3.42217","0.00019"
"41.41200","3.45111","0.00027"
"41.76000","3.48017","-0.00023"
"42.10800","3.50917","-0.00007"
"42.45600","3.53811","-0.00032"
"42.80400","3.56716","-0.00047"
"43.15200","3.59616","0.00031"
"43.50000","3.62510","-0.00049"
"43.84800","3.65416","0.00047"
"44.19600","3.68315","-0.00007"
"44.54400","3.71215","0.00022"
"44.89200","3.74115","0.00028"
"45.24000","3.77015","-0.00023"
"45.58800","3.79915","0.00007"
"45.93600","3.82820","0.00062"
"46.28400","3.85708","0.00075"
"46.63200","3.88620","0.00030"
"46.98000","3.91520","0.00020"
"47.32800","3.94414","0.00052"
"47.67600","3.97319","0.00074"
"48.02400","4.00219","0.00059"
"48.37200","4.03113","-0.00011"
"48.72000","4.06019","0.00025"
"49.06800","4.08913","0.00059"
"49.41600","4.11812","0.00029"
"49.76400","4.14712","0.00019"
"50.11200","4.17618","0.00043"
"50.46000","4.20518","0.00050"
"50.80800","4.23418","0.00029"
"51.15600","4.26311","0.00024"
"51.50400","4.29211","0.00054"
"51.85200","4.32123","0.00003"
"52.20000","4.35011","0.00000"
"52.54800","4.37916","0.00058"
"52.89600","4.40816","0.00026"
"53.24400","4.43710","0.00071"
"53.59200","4.46616","0.00027"
"53.94000","4.49516","0.00033"
"54.28800","4.52409","0.00031"
"54.63600","4.55315","0.00052"
"54.98400","4.58215","0.00040"
"55.33200","4.61115","0.00079"
"55.68000","4.64015","0.00042"
"56.02800","4.66914","0.00049"
"56.37600","4.69814","-0.00013"
"56.72400","4.72720","0.00037"
"57.07200","4.75614","0.00067"
"57.42000","4.78520","0.00057"
"57.76800","4.81413","0.00072"
"58.11600","4.84307","0.00085"
"58.46400","4.87219","0.00025"
"58.81200","4.90113","0.00041"
"59.16000","4.93013","0.00099"
"59.50800","4.95918","0.00044"
"59.85600","4.98812","0.00024"
"60.20400","5.01712","0.00085"
"60.55200","5.04618","0.00058"
"60.90000","5.07511","0.00102"
"61.24800","5.10411","0.00099"
"61.59600","5.13323","0.00064"
"61.94400","5.16211","0.00040"
"62.29200","5.19117","0.00077"
"62.64000","5.22016","0.00061"
"62.98800","5.24910","0.00056"
"63.33600","5.27816","0.00016"
"63.68400","5.30722","0.00051"
"64.03200","5.33610","0.00081"
"64.38000","5.36521","0.00090"
"64.72800","5.39415","0.00022"
"65.07600","5.42315","0.00037"
"65.42400","5.45215","0.00049"
"65.77200","5.48115","0.00101"
"66.12000","5.51008","0.00097"
"66.46800","5.53914","0.00042"
"66.81600","5.56814","0.00109"
"67.16400","5.59714","0.00096"
"67.51200","5.62614","0.00059"
"67.86000","5.65513","0.00049"
"68.20800","5.68419","0.00119"
"68.55600","5.71313","0.00119"
"68.90400","5.74207","0.00098"
"69.25200","5.77112","0.00092"
"69.60000","5.80012","0.00087"
"69.94800","5.82912","0.00074"
"70.29600","5.85818","0.00089"
"70.64400","5.88718","0.00101"
"70.99200","5.91611","0.00114"
"71.34000","5.94517","0.00091"
"71.68800","5.97417","0.00033"
"72.03600","6.00311","0.00051"
"72.38400","6.03223","0.00060"
"72.73200","6.06110","0.00074"
"73.08000","6.09010","0.00033"
"73.42800","6.11916","0.00122"
"73.77600","6.14810","0.00076"
"74.12400","6.17716","0.00063"
"74.47200","6.20615","0.00083"
"74.82000","6.23515","0.00103"
"75.16800","6.26415","0.00072"
"75.51600","6.29315","0.00129"
"75.86400","6.32209","0.00107"
"76.21200","6.35114","0.00068"
"76.56000","6.38014","0.00064"
"76.90800","6.40914","0.00095"
"77.25600","6.43814","0.00070"
"77.60400","6.46713","0.00000"
"77.95200","6.49613","0.00056"
"78.30000","6.52513","0.00095"
"78.64800","6.55419","0.00112"
"78.99600","6.58319","0.00078"
"79.34400","6.61218","0.00096"
"79.69200","6.64112","0.00107"
"80.04000","6.67018","0.00130"
"80.38800","6.69924","0.00117"
"80.73600","6.72812","0.00109"
"81.08400","6.75711","0.00065"
"81.43200","6.78617","0.00101"
"81.78000","6.81505","0.00089"
"82.12800","6.84423","0.00124"
"82.47600","6.87317","0.00139"
"82.82400","6.90210","0.00127"
"83.17200","6.93122","0.00154"
"83.52000","6.96016","0.00188"
"83.86800","6.98916","0.00103"
"84.21600","7.01816","0.00078"
"84.56400","7.04715","0.00104"
"84.91200","7.07615","0.00130"
"85.26000","7.10515","0.00158"
"85.60800","7.13415","0.00067"
"85.95600","7.16309","0.00041"
"86.30400","7.19220","0.00132"
"86.65200","7.22114","0.00101"
"87.00000","7.25020","0.00122"
"87.34800","7.27920","0.00083"
"87.69600","7.30807","0.00111"
"88.04400","7.33713","0.00097"
"88.39200","7.36613","0.00111"
"88.74000","7.39513","0.00148"
"89.08800","7.42419","0.00059"
"89.43600","7.45318","0.00142"
"89.78400","7.48212","0.00133"
"90.13200","7.51118","0.00042"
"90.48000","7.54012","0.00108"
"90.82800","7.56912","0.00126"
"91.17600","7.59817","0.00117"
"91.52400","7.62711","0.00092"
"91.87200","7.65617","0.00102"
"92.22000","7.68517","0.00085"
"92.56800","7.71405","0.00128"
"92.91600","7.74316","0.00151"
"93.26400","7.77216","0.00132"
"93.61200","7.80116","0.00139"
"93.96000","7.83016","0.00096"
"94.30800","7.85915","0.00145"
"94.65600","7.88809","0.00131"
"95.00400","7.91715","0.00110"
"95.35200","7.94615","0.00170"
"95.70000","7.97509","0.00103"
"96.04800","8.00414","0.00111"
"96.39600","8.03314","0.00121"
"96.74400","8.06214","0.00138"
"97.09200","8.09114","0.00095"
"97.44000","8.12008","0.00176"
"97.78800","8.14925","0.00125"
"98.13600","8.17819","0.00089"
"98.48400","8.20713","0.00115"
"98.83200","8.23613","0.00098"
"99.18000","8.26513","0.00110"
"99.52800","8.29412","0.00110"
"99.87600","8.32318","0.00052"
"100.22400","8.35212","0.00139"
"100.57200","8.38112","0.00128"
"100.92000","8.41024","0.00135"
"101.26800","8.43911","0.00149"
"101.61600","8.46817","0.00126"
"101.96400","8.49717","0.00118"
"102.31200","8.52611","0.00081"
"102.66000","8.55516","0.00132"
"103.00800","8.58416","0.00093"
"103.35600","8.61316","0.00117"
"103.70400","8.64216","0.00134"
"104.05200","8.67116","0.00164"
"104.40000","8.70009","0.00178"
"104.74800","8.72915","0.00142"
"105.09600","8.75821","0.00161"
"105.44400","8.78709","0.00142"
"105.79200","8.81621","0.00168"
"106.14000","8.84514","0.00113"
"106.48800","8.87408","0.00154"
"106.83600","8.90320","0.00158"
"107.18400","8.93214","0.00210"
"107.53200","8.96114","0.00132"
"107.88000","8.99019","0.00182"
"108.22800","9.01919","0.00168"
"108.57600","9.04813","0.00156"
"108.92400","9.07713","0.00221"
"109.27200","9.10613","0.00164"
"109.62000","9.13512","0.00208"
"109.96800","9.16424","0.00187"
"110.31600","9.19312","0.00236"
"110.66400","9.22218","0.00158"
"111.01200","9.25117","0.00145"
"111.36000","9.28011","0.00189"
"111.70800","9.30911","0.00182"
"112.05600","9.33811","0.00168"
"112.40400","9.36717","0.00181"
"112.75200","9.39616","0.00169"
"113.10000","9.42516","0.00177"
"113.44800","9.45416","0.00143"
"113.79600","9.48310","0.00167"
"114.14400","9.51216","0.00206"
"114.49200","9.54115","0.00181"
"114.84000","9.57021","0.00213"
"115.18800","9.59909","0.00174"
"115.53600","9.62815","0.00114"
"115.88400","9.65720","0.00145"
"116.23200","9.68608","0.00181"
"116.58000","9.71520","0.00237"
"116.92800","9.74414","0.00189"
"117.27600","9.77314","0.00173"
"117.62400","9.80219","0.00178"
"117.97200","9.83113","0.00198"
"118.32000","9.86007","0.00197"
"118.66800","9.88913","0.00183"
"119.01600","9.91813","0.00189"
"119.36400","9.94718","0.00240"
"119.71200","9.97618","0.00175"
"120.06000","10.00512","0.00186"
"120.40800","10.03412","0.00191"
"120.75600","10.06312","0.00250"
"121.10400","10.09212","0.00199"
"121.45200","10.12117","0.00228"
"121.80000","10.15017","0.00189"
"122.14800","10.17911","0.00226"
"122.49600","10.20817","0.00198"
"122.84400","10.23716","0.00156"
"123.19200","10.26616","0.00170"
"123.54000","10.29516","0.00197"
"123.88800","10.32422","0.00203"
"124.23600","10.35310","0.00257"
"124.58400","10.38215","0.00217"
"124.93200","10.41109","0.00234"
"125.28000","10.44015","0.00229"
"125.62800","10.46921","0.00245"
"125.97600","10.49809","0.00284"
"126.32400","10.52720","0.00273"
"126.67200","10.55614","0.00220"
"127.02000","10.58508","0.00236"
"127.36800","10.61414","0.00249"
"127.71600","10.64319","0.00206"
"128.06400","10.67213","0.00266"
"128.41200","10.70119","0.00227"
"128.76000","10.73013","0.00280"
"129.10800","10.75907","0.00243"
"129.45600","10.78813","0.00243"
"129.80400","10.81712","0.00252"
"130.15200","10.84612","0.00297"
"130.50000","10.87518","0.00230"
"130.84800","10.90418","0.00250"
"131.19600","10.93317","0.00275"
"131.54400","10.96211","0.00226"
"131.89200","10.99111","0.00283"
"132.24000","11.02017","0.00249"
"132.58800","11.04917","0.00278"
"132.93600","11.07816","0.00227"
"133.28400","11.10710","0.00266"
"133.63200","11.13622","0.00230"
"133.98000","11.16510","0.00262"
"134.32800","11.19415","0.00276"
"134.67600","11.22315","0.00239"
"135.02400","11.25209","0.00235"
"135.37200","11.28115","0.00274"
"135.72000","11.31015","0.00221"
"136.06800","11.33914","0.00219"
"136.41600","11.36814","0.00229"
"136.76400","11.39714","0.00247"
"137.11200","11.42614","0.00277"
"137.46000","11.45514","0.00262"
"137.80800","11.48413","0.00300"
"138.15600","11.51313","0.00304"
"138.50400","11.54219","0.00281"
"138.85200","11.57113","0.00320"
"139.20000","11.60019","0.00271"
"139.54800","11.62918","0.00280"
"139.89600","11.65812","0.00301"
"140.24400","11.68718","0.00318"
"140.59200","11.71618","0.00284"
"140.94000","11.74512","0.00284"
"141.28800","11.77417","0.00272"
"141.63600","11.80311","0.00313"
"141.98400","11.83211","0.00272"
"142.33200","11.86117","0.00341"
"142.68000","11.89017","0.00340"
"143.02800","11.91916","0.00363"
"143.37600","11.94816","0.00246"
"143.72400","11.97716","0.00295"
"144.07200","12.00616","0.00323"
"144.42000","12.03522","0.00285"
"144.76800","12.06409","0.00311"
"145.11600","12.09315","0.00313"
"145.46400","12.12221","0.00316"
"145.81200","12.15115","0.00319"
"146.16000","12.18014","0.00358"
"146.50800","12.20914","0.00336"
"146.85600","12.23814","0.00332"
"147.20400","12.26714","0.00342"
"147.55200","12.29614","0.00342"
"147.90000","12.32507","0.00303"
"148.24800","12.35419","0.00318"
"148.59600","12.38313","0.00288"
"148.94400","12.41213","0.00336"
"149.29200","12.44118","0.00334"
"149.64000","12.47007","0.00350"
"149.98800","12.49918","0.00350"
"150.33600","12.52812","0.00378"
"150.68400","12.55706","0.00298"
"151.03200","12.58617","0.00344"
"151.38000","12.61517","0.00367"
"151.72800","12.64411","0.00411"
"152.07600","12.67323","0.00368"
"152.42400","12.70217","0.00375"
"152.77200","12.73110","0.00337"
"153.12000","12.76016","0.00363"
"153.46800","12.78910","0.00343"
"153.81600","12.81810","0.00383"
"154.16400","12.84722","0.00344"
"154.51200","12.87609","0.00351"
"154.86000","12.90515","0.00420"
"155.20800","12.93415","0.00368"
"155.55600","12.96309","0.00363"
"155.90400","12.99221","0.00374"
"156.25200","13.02114","0.00442"
"156.60000","13.05014","0.00341"
"156.94800","13.07914","0.00418"
"157.29600","13.10820","0.00373"
"157.64400","13.13714","0.00399"
"157.99200","13.16613","0.00378"
"158.34000","13.19519","0.00384"
"158.68800","13.22407","0.00403"
"159.03600","13.25319","0.00415"
"159.38400","13.28213","0.00411"
"159.73200","13.31112","0.00393"
"160.08000","13.34018","0.00422"
"160.42800","13.36918","0.00376"
"160.77600","13.39812","0.00409"
"161.12400","13.42718","0.00391"
"161.47200","13.45617","0.00404"
"161.82000","13.48517","0.00381"
"162.16800","13.51417","0.00430"
"162.51600","13.54311","0.00391"
"162.86400","13.57210","0.00431"
"163.21200","13.60116","0.00397"
"163.56000","13.63010","0.00381"
"163.90800","13.65922","0.00459"
"164.25600","13.68816","0.00361"
"164.60400","13.71709","0.00409"
"164.95200","13.74621","0.00400"
"165.30000","13.77515","0.00397"
"165.64800","13.80415","0.00408"
"165.99600","13.83321","0.00405"
"166.34400","13.86220","0.00360"
"166.69200","13.89114","0.00417"
"167.04000","13.92020","0.00437"
"167.38800","13.94914","0.00407"
"167.73600","13.97808","0.00412"
"168.08400","14.00713","0.00362"
"168.43200","14.03613","0.00453"
"168.78000","14.06519","0.00404"
"169.12800","14.09419","0.00461"
"169.47600","14.12306","0.00419"
"169.82400","14.15218","0.00420"
"170.17200","14.18118","0.00420"
"170.52000","14.21012","0.00438"
"170.86800","14.23912","0.00467"
"171.21600","14.26817","0.00452"
"171.56400","14.29717","0.00483"
"171.91200","14.32617","0.00440"
"172.26000","14.35517","0.00441"
"172.60800","14.38411","0.00450"
"172.95600","14.41317","0.00395"
"173.30400","14.44210","0.00448"
"173.65200","14.47116","0.00420"
"174.00000","14.50016","0.00471"
"174.34800","14.52910","0.00503"
"174.69600","14.55821","0.00447"
"175.04400","14.58721","0.00471"
"175.39200","14.61615","0.00471"
"175.74000","14.64515","0.00472"
"176.08800","14.67415","0.00478"
"176.43600","14.70314","0.00501"
"176.78400","14.73220","0.00461"
"177.13200","14.76114","0.00509"
"177.48000","14.79014","0.00519"
"177.82800","14.81920","0.00528"
"178.17600","14.84813","0.00494"
"178.52400","14.87713","0.00474"
"178.87200","14.90619","0.00453"
"179.22000","14.93507","0.00512"
"179.56800","14.96418","0.00481"
"179.91600","14.99324","0.00520"
"180.26400","15.02212","0.00539"
"180.61200","15.05112","0.00507"
"180.96000","15.08012","0.00491"
"181.30800","15.10912","0.00542"
"181.65600","15.13817","0.00528"
"182.00400","15.16717","0.00467"
"182.35200","15.19611","0.00521"
"182.70000","15.22517","0.00496"
"183.04800","15.25416","0.00505"
"183.39600","15.28310","0.00521"
"183.74400","15.31216","0.00510"
"184.09200","15.34110","0.00495"
"184.44000","15.37022","0.00490"
"184.78800","15.39915","0.00511"
"185.13600","15.42809","0.00492"
"185.48400","15.45721","0.00508"
"185.83200","15.48615","0.00502"
"186.18000","15.51515","0.00529"
"186.52800","15.54414","0.00496"
"186.87600","15.57320","0.00527"
"187.22400","15.60214","0.00525"
"187.57200","15.63120","0.00558"
"187.92000","15.66013","0.00553"
"188.26800","15.68913","0.00533"
"188.61600","15.71819","0.00550"
"188.96400","15.74713","0.00518"
"189.31200","15.77613","0.00558"
"189.66000","15.80518","0.00552"
"190.00800","15.83412","0.00544"
"190.35600","15.86312","0.00577"
"190.70400","15.89212","0.00523"
"191.05200","15.92112","0.00531"
"191.40000","15.95017","0.00589"
"191.74800","15.97917","0.00534"
"192.09600","16.00811","0.00567"
"192.44400","16.03717","0.00595"
"192.79200","16.06616","0.00558"
"193.14000","16.09510","0.00547"
"193.48800","16.12416","0.00555"
"193.83600","16.15310","0.00584"
"194.18400","16.18216","0.00567"
"194.53200","16.21121","0.00570"
"194.88000","16.24015","0.00552"
"195.22800","16.26915","0.00559"
"195.57600","16.29815","0.00583"
"195.92400","16.32715","0.00568"
"196.27200","16.35614","0.00589"
"196.62000","16.38520","0.00571"
"196.96800","16.41414","0.00577"
"197.31600","16.44320","0.00540"
"197.66400","16.47226","0.00569"
"198.01200","16.50107","0.00581"
"198.36000","16.53019","0.00583"
"198.70800","16.55919","0.00590"
"199.05600","16.58813","0.00551"
"199.40400","16.61718","0.00569"
"199.75200","16.64618","0.00557"
"200.10000","16.67518","0.00522"
"200.44800","16.70418","0.00535"
"200.79600","16.73312","0.00523"
"201.14400","16.76212","0.00557"
"201.49200","16.79117","0.00528"
"201.84000","16.82011","0.00530"
"202.18800","16.84911","0.00536"
"202.53600","16.87817","0.00553"
"202.88400","16.90705","0.00537"
"203.23200","16.93616","0.00565"
"203.58000","16.96510","0.00586"
"203.92800","16.99410","0.00562"
"204.27600","17.02316","0.00599"
"204.62400","17.05215","0.00579"
"204.97200","17.08109","0.00576"
"205.32000","17.11015","0.00561"
"205.66800","17.13915","0.00552"
"206.01600","17.16809","0.00589"
"206.36400","17.19714","0.00595"
"206.71200","17.22620","0.00552"
"207.06000","17.25514","0.00599"
"207.40800","17.28420","0.00617"
"207.75600","17.31308","0.00552"
"208.10400","17.34219","0.00571"
"208.45200","17.37119","0.00544"
"208.80000","17.40007","0.00536"
"209.14800","17.42919","0.00515"
"209.49600","17.45819","0.00500"
"209.84400","17.48712","0.00430"
"210.19200","17.51618","0.00402"
"210.54000","17.54518","0.00402"
"210.88800","17.57406","0.00474"
"211.23600","17.60323","0.00421"
"211.58400","17.63211","0.00409"
"211.93200","17.66111","0.00458"
"212.28000","17.69017","0.00415"
"212.62800","17.71917","0.00507"
"212.97600","17.74816","0.00404"
"213.32400","17.77716","0.00421"
"213.67200","17.80610","0.00425"
"214.02000","17.83516","0.00422"
"214.36800","17.86410","0.00430"
"214.71600","17.89315","0.00428"
"215.06400","17.92215","0.00443"
"215.41200","17.95121","0.00455"
"215.76000","17.98015","0.00488"
"216.10800","18.00908","0.00439"
"216.45600","18.03820","0.00441"
"216.80400","18.06708","0.00506"
"217.15200","18.09614","0.00492"
"217.50000","18.12514","0.00439"
"217.84800","18.15413","0.00496"
"218.19600","18.18319","0.00513"
"218.54400","18.21213","0.00487"
"218.89200","18.24119","0.00506"
"219.24000","18.27013","0.00492"
"219.58800","18.29913","0.00537"
"219.93600","18.32818","0.00507"
"220.28400","18.35718","0.00478"
"220.63200","18.38612","0.00518"
"220.98000","18.41512","0.00486"
"221.32800","18.44418","0.00520"
"221.67600","18.47311","0.00570"
"222.02400","18.50217","0.00520"
"222.37200","18.53117","0.00556"
"222.72000","18.56011","0.00575"
"223.06800","18.58916","0.00560"
"223.41600","18.61816","0.00537"
"223.76400","18.64710","0.00561"
"224.11200","18.67616","0.00612"
"224.46000","18.70516","0.00590"
"224.80800","18.73409","0.00599"
"225.15600","18.76315","0.00608"
"225.50400","18.79215","0.00574"
"225.85200","18.82115","0.00601"
"226.20000","18.85021","0.00612"
"226.54800","18.87908","0.00613"
"226.89600","18.90820","0.00603"
"227.24400","18.93720","0.00645"
"227.59200","18.96614","0.00642"
"227.94000","18.99519","0.00648"
"228.28800","19.02413","0.00661"
"228.63600","19.05313","0.00619"
"228.98400","19.08219","0.00639"
"229.33200","19.11119","0.00660"
"229.68000","19.14013","0.00611"
"230.02800","19.16912","0.00653"
"230.37600","19.19812","0.00660"
"230.72400","19.22718","0.00657"
"231.07200","19.25624","0.00615"
"231.42000","19.28511","0.00631"
"231.76800","19.31411","0.00633"
"232.11600","19.34323","0.00668"
"232.46400","19.37211","0.00656"
"232.81200","19.40111","0.00656"
"233.16000","19.43016","0.00641"
"233.50800","19.45910","0.00644"
"233.85600","19.48816","0.00625"
"234.20400","19.51716","0.00644"
"234.55200","19.54609","0.00651"
"234.90000","19.57515","0.00657"
"235.24800","19.60415","0.00643"
"235.59600","19.63309","0.00651"
"235.94400","19.66220","0.00691"
"236.29200","19.69114","0.00690"
"236.64000","19.72014","0.00659"
"236.98800","19.74914","0.00714"
"237.33600","19.77814","0.00695"
"237.68400","19.80720","0.00694"
"238.03200","19.83619","0.00717"
"238.38000","19.86513","0.00719"
"238.72800","19.89413","0.00703"
"239.07600","19.92319","0.00726"
"239.42400","19.95213","0.00718"
"239.77200","19.98112","0.00705"
"240.12000","20.01018","0.00717"
"240.46800","20.03918","0.00715"
"240.81600","20.06818","0.00725"
"241.16400","20.09711","0.00677"
"241.51200","20.12611","0.00684"
"241.86000","20.15517","0.00713"
"242.20800","20.18411","0.00715"
"242.55600","20.21323","0.00738"
"242.90400","20.24217","0.00771"
"243.25200","20.27110","0.00720"
"243.60000","20.30016","0.00711"
"243.94800","20.32916","0.00727"
"244.29600","20.35810","0.00726"
"244.64400","20.38715","0.00742"
"244.99200","20.41615","0.00758"
"245.34000","20.44509","0.00735"
"245.68800","20.47421","0.00719"
"246.03600","20.50315","0.00752"
"246.38400","20.53214","0.00770"
"246.73200","20.56120","0.00793"
"247.08000","20.59014","0.00765"
"247.42800","20.61914","0.00808"
"247.77600","20.64814","0.00805"
"248.12400","20.67707","0.00779"
"248.47200","20.70619","0.00798"
"248.82000","20.73519","0.00789"
"249.16800","20.76413","0.00822"
"249.51600","20.79313","0.00786"
"249.86400","20.82218","0.00795"
"250.21200","20.85112","0.00797"
"250.56000","20.88018","0.00792"
"250.90800","20.90918","0.00807"
"251.25600","20.93812","0.00820"
"251.60400","20.96717","0.00840"
"251.95200","20.99617","0.00821"
"252.30000","21.02511","0.00793"
"252.64800","21.05417","0.00826"
"252.99600","21.08316","0.00843"
"253.34400","21.11210","0.00828"
"253.69200","21.14116","0.00865"
"254.04000","21.17016","0.00885"
"254.38800","21.19916","0.00843"
"254.73600","21.22821","0.00830"
"255.08400","21.25715","0.00829"
"255.43200","21.28615","0.00818"
"255.78000","21.31515","0.00876"
"256.12800","21.34409","0.00890"
"256.47600","21.37314","0.00840"
"256.82400","21.40214","0.00852"
"257.17200","21.43114","0.00879"
"257.52000","21.46020","0.00900"
"257.86800","21.48913","0.00823"
"258.21600","21.51813","0.00851"
"258.56400","21.54713","0.00831"
"258.91200","21.57619","0.00788"
"259.26000","21.60513","0.00782"
"259.60800","21.63419","0.00812"
"259.95600","21.66312","0.00787"
"260.30400","21.69212","0.00802"
"260.65200","21.72118","0.00795"
"261.00000","21.75006","0.00821"
"261.34800","21.77918","0.00852"
"261.69600","21.80823","0.00846"
"262.04400","21.83711","0.00830"
"262.39200","21.86617","0.00833"
"262.74000","21.89511","0.00843"
"263.08800","21.92410","0.00851"
"263.43600","21.95316","0.00848"
"263.78400","21.98216","0.00862"
"264.13200","22.01116","0.00870"
"264.48000","22.04016","0.00837"
"264.82800","22.06915","0.00867"
"265.17600","22.09809","0.00880"
"265.52400","22.12715","0.00879"
"265.87200","22.15609","0.00886"
"266.22000","22.18521","0.00901"
"266.56800","22.21414","0.00879"
"266.91600","22.24314","0.00893"
"267.26400","22.27214","0.00925"
"267.61200","22.30114","0.00880"
"267.96000","22.33014","0.00874"
"268.30800","22.35913","0.00886"
"268.65600","22.38819","0.00902"
"269.00400","22.41713","0.00857"
"269.35200","22.44619","0.00823"
"269.70000","22.47518","0.00822"
"270.04800","22.50412","0.00826"
"270.39600","22.53318","0.00860"
"270.74400","22.56212","0.00855"
"271.09200","22.59112","0.00856"
"271.44000","22.62017","0.00865"
"271.78800","22.64911","0.00871"
"272.13600","22.67817","0.00855"
"272.48400","22.70711","0.00853"
"272.83200","22.73611","0.00883"
"273.18000","22.76517","0.00796"
"273.52800","22.79416","0.00860"
"273.87600","22.82310","0.00823"
"274.22400","22.85216","0.00828"
"274.57200","22.88115","0.00809"
"274.92000","22.91015","0.00842"
"275.26800","22.93915","0.00817"
"275.61600","22.96809","0.00867"
"275.96400","22.99715","0.00814"
"276.31200","23.02615","0.00825"
"276.66000","23.05520","0.00839"
"277.00800","23.08414","0.00813"
"277.35600","23.11314","0.00855"
"277.70400","23.14214","0.00843"
"278.05200","23.17114","0.00866"
"278.40000","23.20019","0.00837"
"278.74800","23.22913","0.00864"
"279.09600","23.25813","0.00831"
"279.44400","23.28718","0.00880"
"279.79200","23.31606","0.00854"
"280.14000","23.34518","0.00889"
"280.48800","23.37418","0.00906"
"280.83600","23.40312","0.00895"
"281.18400","23.43218","0.00894"
"281.53200","23.46111","0.00887"
"281.88000","23.49011","0.00900"
"282.22800","23.51917","0.00919"
"282.57600","23.54811","0.00923"
"282.92400","23.57710","0.00934"
"283.27200","23.60616","0.00931"
"283.62000","23.63516","0.00955"
"283.96800","23.66410","0.00955"
"284.31600","23.69316","0.00952"
"284.66400","23.72209","0.00984"
"285.01200","23.75115","0.00893"
"285.36000","23.78021","0.00827"
"285.70800","23.80909","0.00797"
"286.05600","23.83815","0.00918"
"286.40400","23.86714","0.00899"
"286.75200","23.89614","0.00892"
"287.10000","23.92520","0.00933"
"287.44800","23.95414","0.00943"
"287.79600","23.98314","0.00949"
"288.14400","24.01213","0.00937"
"288.49200","24.04113","0.00947"
"288.84000","24.07013","0.00952"
"289.18800","24.09925","0.00841"
"289.53600","24.12813","0.00774"
"289.88400","24.15713","0.00825"
"290.23200","24.18612","0.00828"
"290.58000","24.21506","0.00838"
"290.92800","24.24418","0.00865"
"291.27600","24.27317","0.00877"
"291.62400","24.30217","0.00810"
"291.97200","24.33117","0.00846"
"292.32000","24.36011","0.00841"
"292.66800","24.38911","0.00845"
"293.01600","24.41816","0.00685"
"293.36400","24.44716","0.00473"
"293.71200","24.47616","0.00496"
"294.06000","24.50516","0.00456"
"294.40800","24.53416","0.00553"
"294.75600","24.56310","0.00506"
"295.10400","24.59215","0.00529"
"295.45200","24.62109","0.00520"
"295.80000","24.65021","0.00489"
"296.14800","24.67921","0.00531"
"296.49600","24.70815","0.00598"
"296.84400","24.73714","0.00510"
"297.19200","24.76614","0.00521"
"297.54000","24.79508","0.00555"
"297.88800","24.82420","0.00558"
"298.23600","24.85313","0.00544"
"298.58400","24.88207","0.00555"
"298.93200","24.91119","0.00551"
"299.28000","24.94013","0.00537"
"299.62800","24.96913","0.00553"
"299.97600","24.99818","0.00585"
"300.32400","25.02712","0.00612"
"300.67200","25.05618","0.00598"
"301.02000","25.08517","0.00594"
"301.36800","25.11411","0.00603"
"301.71600","25.14311","0.00568"
"302.06400","25.17217","0.00605"
"302.41200","25.20111","0.00556"
"302.76000","25.23017","0.00637"
"303.10800","25.25922","0.00601"
"303.45600","25.28804","0.00561"
"303.80400","25.31722","0.00618"
"304.15200","25.34622","0.00607"
"304.50000","25.37510","0.00612"
"304.84800","25.40415","0.00652"
"305.19600","25.43315","0.00612"
"305.54400","25.46215","0.00625"
"305.89200","25.49115","0.00639"
"306.24000","25.52015","0.00621"
"306.58800","25.54914","0.00592"
"306.93600","25.57814","0.00658"
"307.28400","25.60714","0.00638"
"307.63200","25.63614","0.00631"
"307.98000","25.66519","0.00652"
"308.32800","25.69407","0.00663"
"308.67600","25.72319","0.00689"
"309.02400","25.75219","0.00708"
"309.37200","25.78113","0.00649"
"309.72000","25.81019","0.00632"
"310.06800","25.83912","0.00651"
"310.41600","25.86812","0.00714"
"310.76400","25.89718","0.00683"
"311.11200","25.92618","0.00697"
"311.46000","25.95518","0.00695"
"311.80800","25.98411","0.00676"
"312.15600","26.01317","0.00689"
"312.50400","26.04211","0.00703"
"312.85200","26.07122","0.00694"
"313.20000","26.10010","0.00688"
"313.54800","26.12910","0.00726"
"313.89600","26.15822","0.00733"
"314.24400","26.18704","0.00731"
"314.59200","26.21615","0.00731"
"314.94000","26.24521","0.00732"
"315.28800","26.27415","0.00739"
"315.63600","26.30315","0.00771"
"315.98400","26.33209","0.00767"
"316.33200","26.36109","0.00784"
"316.68000","26.39014","0.00754"
"317.02800","26.41914","0.00782"
"317.37600","26.44814","0.00795"
"317.72400","26.47714","0.00729"
"318.07200","26.50614","0.00751"
"318.42000","26.53513","0.00777"
"318.76800","26.56419","0.00774"
"319.11600","26.59313","0.00762"
"319.46400","26.62219","0.00744"
"319.81200","26.65118","0.00711"
"320.16000","26.68012","0.00725"
"320.50800","26.70918","0.00624"
"320.85600","26.73818","0.00635"
"321.20400","26.76712","0.00624"
"321.55200","26.79617","0.00637"
"321.90000","26.82517","0.00621"
"322.24800","26.85411","0.00665"
"322.59600","26.88317","0.00687"
"322.94400","26.91217","0.00660"
"323.29200","26.94110","0.00687"
"323.64000","26.97022","0.00677"
"323.98800","26.99910","0.00653"
"324.33600","27.02816","0.00666"
"324.68400","27.05710","0.00656"
"325.03200","27.08609","0.00671"
"325.38000","27.11521","0.00665"
"325.72800","27.14421","0.00682"
"326.07600","27.17309","0.00714"
"326.42400","27.20220","0.00673"
"326.77200","27.23114","0.00694"
"327.12000","27.26014","0.00704"
"327.46800","27.28920","0.00716"
"327.81600","27.31820","0.00701"
"328.16400","27.34708","0.00734"
"328.51200","27.37613","0.00721"
"328.86000","27.40513","0.00703"
"329.20800","27.43413","0.00694"
"329.55600","27.46318","0.00706"
"329.90400","27.49212","0.00722"
"330.25200","27.52118","0.00721"
"330.60000","27.55018","0.00722"
"330.94800","27.57912","0.00712"
"331.29600","27.60812","0.00750"
"331.64400","27.63717","0.00786"
"331.99200","27.66611","0.00761"
"332.34000","27.69517","0.00746"
"332.68800","27.72417","0.00735"
"333.03600","27.75311","0.00717"
"333.38400","27.78216","0.00772"
"333.73200","27.81116","0.00792"
"334.08000","27.84016","0.00798"
"334.42800","27.86916","0.00749"
"334.77600","27.89816","0.00765"
"335.12400","27.92715","0.00761"
"335.47200","27.95615","0.00784"
"335.82000","27.98515","0.00795"
"336.16800","28.01414","0.00782"
"336.51600","28.04315","0.00807"
"336.86400","28.07208","0.00796"
"337.21200","28.10114","0.00754"
"337.56000","28.13020","0.00783"
"337.90800","28.15908","0.00780"
"338.25600","28.18819","0.00797"
"338.60400","28.21719","0.00782"
"338.95200","28.24613","0.00814"
"339.30000","28.27519","0.00810"
"339.64800","28.30413","0.00729"
"339.99600","28.33312","0.00807"
"340.34400","28.36218","0.00800"
"340.69200","28.39112","0.00771"
"341.04000","28.42012","0.00799"
"341.38800","28.44911","0.00798"
"341.73600","28.47811","0.00799"
"342.08400","28.50717","0.00780"
"342.43200","28.53623","0.00810"
"342.78000","28.56511","0.00844"
"343.12800","28.59416","0.00817"
"343.47600","28.62316","0.00820"
"343.82400","28.65210","0.00833"
"344.17200","28.68116","0.00838"
"344.52000","28.71016","0.00845"
"344.86800","28.73915","0.00867"
"345.21600","28.76815","0.00839"
"345.56400","28.79715","0.00843"
"345.91200","28.82609","0.00855"
"346.26000","28.85515","0.00871"
"346.60800","28.88408","0.00841"
"346.95600","28.91314","0.00882"
"347.30400","28.94220","0.00878"
"347.65200","28.97108","0.00902"
"348.00000","29.00019","0.00879"
"348.34800","29.02919","0.00870"
"348.69600","29.05807","0.00891"
"349.04400","29.08719","0.00915"
"349.39200","29.11619","0.00907"
"349.74000","29.14512","0.00933"
"350.08800","29.17418","0.00898"
"350.43600","29.20312","0.00897"
"350.78400","29.23212","0.00935"
"351.13200","29.26118","0.00938"
"351.48000","29.29018","0.00925"
"351.82800","29.31911","0.00924"
"352.17600","29.34823","0.00911"
"352.52400","29.37711","0.00955"
"352.87200","29.40611","0.00944"
"353.22000","29.43517","0.00937"
"353.56800","29.46410","0.00957"
"353.91600","29.49316","0.01004"
"354.26400","29.52216","0.00977"
"354.61200","29.55104","0.00978"
"354.96000","29.58016","0.00956"
"355.30800","29.60915","0.01020"
"355.65600","29.63815","0.00997"
"356.00400","29.66715","0.00995"
"356.35200","29.69621","0.01034"
"356.70000","29.72514","0.00999"
"357.04800","29.75420","0.00998"
"357.39600","29.78314","0.00998"
"357.74400","29.81214","0.01014"
"358.09200","29.84114","0.01031"
"358.44000","29.87013","0.00989"
"358.78800","29.89919","0.00974"
"359.13600","29.92813","0.01023"
"359.48400","29.95713","0.00992"
"359.83200","29.98613","0.00971"
"360.18000","30.01518","0.01003"
"360.52800","30.04412","0.01019"
"360.87600","30.07312","0.01023"
"361.22400","30.10224","0.01040"
"361.57200","30.13112","0.01048"
"361.92000","30.16017","0.01043"
"362.26800","30.18917","0.00983"
"362.61600","30.21811","0.00962"
"362.96400","30.24723","0.00991"
"363.31200","30.27617","0.01010"
"363.66000","30.30516","0.01010"
"364.00800","30.33410","0.00990"
"364.35600","30.36310","0.01024"
"364.70400","30.39216","0.01026"
"365.05200","30.42115","0.01037"
"365.40000","30.45015","0.01003"
"365.74800","30.47915","0.01040"
"366.09600","30.50815","0.00951"
"366.44400","30.53715","0.01027"
"366.79200","30.56614","0.01000"
"367.14000","30.59514","0.01056"
"367.48800","30.62408","0.01016"
"367.83600","30.65320","0.01083"
"368.18400","30.68213","0.01044"
"368.53200","30.71119","0.01060"
"368.88000","30.74019","0.01040"
"369.22800","30.76913","0.01063"
"369.57600","30.79813","0.01061"
"369.92400","30.82719","0.01055"
"370.27200","30.85612","0.01052"
"370.62000","30.88512","0.01082"
"370.96800","30.91418","0.01053"
"371.31600","30.94312","0.01034"
"371.66400","30.97212","0.01066"
"372.01200","31.00123","0.01066"
"372.36000","31.03005","0.01052"
"372.70800","31.05923","0.01088"
"373.05600","31.08817","0.01090"
"373.40400","31.11711","0.01092"
"373.75200","31.14616","0.01118"
"374.10000","31.17510","0.01086"
"374.44800","31.20416","0.01098"
"374.79600","31.23316","0.01129"
"375.14400","31.26215","0.01113"
"375.49200","31.29115","0.01161"
"375.84000","31.32021","0.01134"
"376.18800","31.34914","0.01129"
"376.53600","31.37814","0.01128"
"376.88400","31.40720","0.01156"
"377.23200","31.43608","0.01174"
"377.58000","31.46514","0.01141"
"377.92800","31.49420","0.01181"
"378.27600","31.52313","0.01164"
"378.62400","31.55213","0.01189"
"378.97200","31.58119","0.01191"
"379.32000","31.61013","0.01180"
"379.66800","31.63913","0.01170"
"380.01600","31.66818","0.01219"
"380.36400","31.69712","0.01212"
"380.71200","31.72618","0.01228"
"381.06000","31.75512","0.01247"
"381.40800","31.78417","0.01244"
"381.75600","31.81318","0.01259"
"382.10400","31.84205","0.01249"
"382.45200","31.87117","0.01262"
"382.80000","31.90017","0.01290"
"383.14800","31.92911","0.01285"
"383.49600","31.95816","0.01288"
"383.84400","31.98716","0.01326"
"384.19200","32.01610","0.01351"
"384.54000","32.04515","0.01344"
"384.88800","32.07415","0.01369"
"385.23600","32.10309","0.01383"
"385.58400","32.13215","0.01360"
"385.93200","32.16115","0.01410"
"386.28000","32.19009","0.01387"
"386.62800","32.21920","0.01428"
"386.97600","32.24814","0.01384"
"387.32400","32.27714","0.01380"
"387.67200","32.30614","0.01398"
"388.02000","32.33514","0.01397"
"388.36800","32.36419","0.01451"
"388.71600","32.39313","0.01407"
"389.06400","32.42213","0.01415"
"389.41200","32.45113","0.01443"
"389.76000","32.48018","0.01413"
"390.10800","32.50906","0.01452"
"390.45600","32.53818","0.01459"
"390.80400","32.56718","0.01490"
"391.15200","32.59612","0.01523"
"391.50000","32.62524","0.01538"
"391.84800","32.65411","0.01560"
"392.19600","32.68317","0.01555"
"392.54400","32.71217","0.01592"
"392.89200","32.74111","0.01479"
"393.24000","32.77016","0.01477"
"393.58800","32.79910","0.01485"
"393.93600","32.82816","0.01518"
"394.28400","32.85716","0.01500"
"394.63200","32.88615","0.01564"
"394.98000","32.91509","0.01490"
"395.32800","32.94415","0.01459"
"395.67600","32.97321","0.01482"
"396.02400","33.00209","0.01469"
"396.37200","33.03121","0.01513"
"396.72000","33.06015","0.01555"
"397.06800","33.08908","0.01519"
"397.41600","33.11814","0.01577"
"397.76400","33.14714","0.01579"
"398.11200","33.17607","0.01525"
"398.46000","33.20519","0.01548"
"398.80800","33.23413","0.01565"
"399.15600","33.26313","0.01552"
"399.50400","33.29219","0.01479"
"399.85200","33.32113","0.01525"
"400.20000","33.35012","0.01544"
"400.54800","33.37918","0.01509"
"400.89600","33.40812","0.01524"
"401.24400","33.43718","0.01598"
"401.59200","33.46618","0.01613"
"401.94000","33.49511","0.01609"
"402.28800","33.52417","0.01646"
"402.63600","33.55317","0.01617"
"402.98400","33.58216","0.01639"
"403.33200","33.61116","0.01699"
"403.68000","33.64010","0.01688"
"404.02800","33.66916","0.01770"
"404.37600","33.69816","0.01740"
"404.72400","33.72715","0.01792"
"405.07200","33.75609","0.01768"
"405.42000","33.78521","0.01811"
"405.76800","33.81415","0.01853"
"406.11600","33.84321","0.01848"
"406.46400","33.87221","0.01884"
"406.81200","33.90108","0.01991"
"407.16000","33.93020","0.02014"
"407.50800","33.95920","0.02033"
"407.85600","33.98808","0.02009"
"408.20400","34.01719","0.02059"
"408.55200","34.04613","0.02034"
"408.90000","34.07513","0.02060"
"409.24800","34.10413","0.02121"
"409.59600","34.13313","0.02185"
"409.94400","34.16212","0.02205"
"410.29200","34.19118","0.02249"
"410.64000","34.22012","0.02295"
"410.98800","34.24912","0.02369"
"411.33600","34.27818","0.02376"
"411.68400","34.30711","0.02351"
"412.03200","34.33617","0.02425"
"412.38000","34.36517","0.02426"
"412.72800","34.39417","0.02503"
"413.07600","34.42311","0.02537"
"413.42400","34.45210","0.02517"
"413.77200","34.48110","0.02560"
"414.12000","34.51016","0.02653"
"414.46800","34.53922","0.02709"
"414.81600","34.56809","0.02757"
"415.16400","34.59716","0.02759"
"415.51200","34.62615","0.02785"
"415.86000","34.65515","0.02877"
"416.20800","34.68421","0.02861"
"416.55600","34.71309","0.02908"
"416.90400","34.74220","0.02977"
"417.25200","34.77114","0.03038"
"417.60000","34.80008","0.03037"
"417.94800","34.82920","0.03128"
"418.29600","34.85814","0.03102"
"418.64400","34.88713","0.03214"
"418.99200","34.91619","0.03270"
"419.34000","34.94519","0.03217"
"419.68800","34.97413","0.03298"
"420.03600","35.00312","0.03427"
"420.38400","35.03218","0.03299"
"420.73200","35.06112","0.03428"
"421.08000","35.09024","0.03419"
"421.42800","35.11912","0.03580"
"421.77600","35.14811","0.03689"
"422.12400","35.17711","0.03814"
"422.47200","35.20617","0.03828"
"422.82000","35.23517","0.03717"
"423.16800","35.26416","0.03809"
"423.51600","35.29310","0.03847"
"423.86400","35.32210","0.03809"
"424.21200","35.35122","0.03966"
"424.56000","35.38010","0.04075"
"424.90800","35.40916","0.03977"
"425.25600","35.43815","0.04030"
"425.60400","35.46709","0.04033"
"425.95200","35.49621","0.04129"
"426.30000","35.52515","0.04125"
"426.64800","35.55415","0.04169"
"426.99600","35.58320","0.04230"
"427.34400","35.61214","0.04249"
"427.69200","35.64114","0.04287"
"428.04000","35.67014","0.04420"
"428.38800","35.69913","0.04453"
"428.73600","35.72813","0.04384"
"429.08400","35.75719","0.04451"
"429.43200","35.78613","0.04429"
"429.78000","35.81519","0.04516"
"430.12800","35.84418","0.04511"
"430.47600","35.87312","0.04520"
"430.82400","35.90212","0.04631"
"431.17200","35.93112","0.04724"
"431.52000","35.96012","0.04814"
"431.86800","35.98917","0.04861"
"432.21600","36.01817","0.04848"
"432.56400","36.04711","0.05016"
"432.91200","36.07616","0.05119"
"433.26000","36.10516","0.05203"
"433.60800","36.13410","0.05246"
"433.95600","36.16322","0.05355"
"434.30400","36.19210","0.05334"
"434.65200","36.22116","0.05419"
"435.00000","36.25016","0.05501"
"435.34800","36.27909","0.05573"
"435.69600","36.30821","0.05689"
"436.04400","36.33715","0.05688"
"436.39200","36.36609","0.05762"
"436.74000","36.39520","0.05837"
"437.08800","36.42414","0.05951"
"437.43600","36.45314","0.06007"
"437.78400","36.48220","0.06156"
"438.13200","36.51114","0.06161"
"438.48000","36.54013","0.06230"
"438.82800","36.56913","0.06350"
"439.17600","36.59813","0.06486"
"439.52400","36.62713","0.06447"
"439.87200","36.65619","0.06614"
"440.22000","36.68512","0.06712"
"440.56800","36.71418","0.06803"
"440.91600","36.74312","0.06943"
"441.26400","36.77212","0.06995"
"441.61200","36.80117","0.07189"
"441.96000","36.83017","0.07312"
"442.30800","36.85911","0.07482"
"442.65600","36.88817","0.07618"
"443.00400","36.91717","0.07901"
"443.35200","36.94611","0.07920"
"443.70000","36.97516","0.07957"
"444.04800","37.00416","0.01916"
"444.39600","37.03310","0.02067"
"444.74400","37.06222","0.01877"
"445.09200","37.09109","0.01350"
"445.44000","37.12015","0.02284"
"445.78800","37.14915","0.01431"
"446.13600","37.17809","0.02370"
"446.48400","37.20721","0.01784"
"446.83200","37.23614","0.01978"
"447.18000","37.26514","0.02312"
"447.52800","37.29414","0.02002"
"447.87600","37.32320","0.02484"
"448.22400","37.35214","0.02260"
"448.57200","37.38113","0.02432"
"448.92000","37.41019","0.02554"
"449.26800","37.43907","0.02673"
"449.61600","37.46819","0.02626"
"449.96400","37.49712","0.02903"
"450.31200","37.52612","0.03009"
"450.66000","37.55524","0.02930"
"451.00800","37.58412","0.03350"
"451.35600","37.61312","0.03230"
"451.70400","37.64217","0.03370"
"452.05200","37.67117","0.03600"
"452.40000","37.70011","0.03533"
"452.74800","37.72917","0.03788"
"453.09600","37.75811","0.03864"
"453.44400","37.78717","0.04002"
"453.79200","37.81616","0.04151"
"454.14000","37.84504","0.04242"
"454.48800","37.87416","0.04341"
"454.83600","37.90316","0.04322"
"455.18400","37.93216","0.04423"
"455.53200","37.96115","0.04552"
"455.88000","37.99015","0.04614"
"456.22800","38.01915","0.04746"
"456.57600","38.04815","0.04804"
"456.92400","38.07720","0.04831"
"457.27200","38.10614","0.04966"
"457.62000","38.13514","0.05060"
"457.96800","38.16414","0.05175"
"458.31600","38.19308","0.05188"
"458.66400","38.22219","0.05288"
"459.01200","38.25113","0.05389"
"459.36000","38.28019","0.05476"
"459.70800","38.30925","0.05486"
"460.05600","38.33812","0.05633"
"460.40400","38.36718","0.05656"
"460.75200","38.39612","0.05747"
"461.10000","38.42512","0.05844"
"461.44800","38.45417","0.05997"
"461.79600","38.48311","0.06083"
"462.14400","38.51212","0.06243"
"462.49200","38.54117","0.06341"
"462.84000","38.57011","0.06426"
"463.18800","38.59917","0.06577"
"463.53600","38.62817","0.06680"
"463.88400","38.65710","0.06841"
"464.23200","38.68616","0.07023"
"464.58000","38.71522","0.07235"
"464.92800","38.74409","0.07324"
"465.27600","38.77321","0.07525"
"465.62400","38.80215","0.07674"
"465.97200","38.83115","0.07798"
"466.32000","38.86015","0.07992"
"466.66800","38.88915","0.08151"
"467.01600","38.91809","0.08266"
"467.36400","38.94714","0.08337"
"467.71200","38.97620","0.08558"
"468.06000","39.00520","0.08652"
"468.40800","39.03419","0.08820"
"468.75600","39.06307","0.08981"
"469.10400","39.09213","0.09075"
"469.45200","39.12113","0.09240"
"469.80000","39.15007","0.09356"
"470.14800","39.17918","0.09429"
"470.49600","39.20818","0.09519"
"470.84400","39.23706","0.09571"
"471.19200","39.26612","0.09692"
"471.54000","39.29518","0.09754"
"471.88800","39.32411","0.09812"
"472.23600","39.35312","0.09877"
"472.58400","39.38217","0.09925"
"472.93200","39.41111","0.09991"
"473.28000","39.44017","0.10072"
"473.62800","39.46916","0.10125"
"473.97600","39.49810","0.10148"
"474.32400","39.52710","0.10255"
"474.67200","39.55610","0.10304"
"475.02000","39.58516","0.10324"
"475.36800","39.61415","0.10432"
"475.71600","39.64309","0.10497"
"476.06400","39.67215","0.10601"
"476.41200","39.70115","0.10749"
"476.76000","39.73009","0.10855"
"477.10800","39.75914","0.11017"
"477.45600","39.78820","0.11150"
"477.80400","39.81708","0.11280"
"478.15200","39.84619","0.11476"
"478.50000","39.87513","0.11615"
"478.84800","39.90413","0.11844"
"479.19600","39.93319","0.12039"
"479.54400","39.96212","0.12121"
"479.89200","39.99113","0.12297"
"480.24000","40.02018","0.12512"
"480.58800","40.04912","0.12770"
"480.93600","40.07818","0.13059"
"481.28400","40.10718","0.06783"
"481.63200","40.13617","0.05105"
"481.98000","40.16512","0.03810"
"482.32800","40.19417","0.05933"
"482.67600","40.22311","0.03539"
"483.02400","40.25217","0.05546"
"483.37200","40.28116","0.03730"
"483.72000","40.31010","0.05632"
"484.06800","40.33916","0.04122"
"484.41600","40.36816","0.05706"
"484.76400","40.39709","0.04264"
"485.11200","40.42615","0.05532"
"485.46000","40.45515","0.04447"
"485.80800","40.48409","0.05475"
"486.15600","40.51315","0.04624"
"486.50400","40.54215","0.05380"
"486.85200","40.57109","0.04944"
"487.20000","40.60014","0.05285"
"487.54800","40.62914","0.05365"
"487.89600","40.65814","0.05228"
"488.24400","40.68714","0.05755"
"488.59200","40.71608","0.05278"
"488.94000","40.74519","0.06213"
"489.28800","40.77412","0.05396"
"489.63600","40.80318","0.06593"
"489.98400","40.83218","0.05658"
"490.33200","40.86113","0.06682"
"490.68000","40.89013","0.05833"
"491.02800","40.91918","0.06559"
"491.37600","40.94812","0.06187"
"491.72400","40.97712","0.06391"
"492.07200","41.00617","0.06701"
"492.42000","41.03511","0.06453"
"492.76800","41.06411","0.07298"
"493.11600","41.09323","0.06534"
"493.46400","41.12210","0.07625"
"493.81200","41.15116","0.06851"
"494.16000","41.18016","0.07562"
"494.50800","41.20910","0.07301"
"494.85600","41.23815","0.07353"
"495.20400","41.26709","0.07937"
"495.55200","41.29609","0.07443"
"495.90000","41.32515","0.08366"
"496.24800","41.35415","0.07815"
"496.59600","41.38309","0.08426"
"496.94400","41.41214","0.08287"
"497.29200","41.44114","0.08333"
"497.64000","41.47014","0.08787"
"497.98800","41.49920","0.08507"
"498.33600","41.52808","0.09035"
"498.68400","41.55719","0.08822"
"499.03200","41.58619","0.09037"
"499.38000","41.61513","0.09127"
"499.72800","41.64413","0.09018"
"500.07600","41.67319","0.09390"
"500.42400","41.70213","0.09191"
"500.77200","41.73112","0.09348"
"501.12000","41.76018","0.09456"
"501.46800","41.78912","0.09423"
"501.81600","41.81818","0.09650"
"502.16400","41.84717","0.09557"
"502.51200","41.87611","0.09718"
"502.86000","41.90517","0.09713"
"503.20800","41.93410","0.09719"
"503.55600","41.96317","0.09872"
"503.90400","41.99216","0.09817"
"504.25200","42.02110","0.09926"
"504.60000","42.05016","0.09957"
"504.94800","42.07916","0.09938"
"505.29600","42.10815","0.10079"
"505.64400","42.13715","0.10082"
"505.99200","42.16621","0.10123"
"506.34000","42.19509","0.10171"
"506.68800","42.22415","0.10162"
"507.03600","42.25314","0.10201"
"507.38400","42.28208","0.10167"
"507.73200","42.31114","0.10184"
"508.08000","42.34020","0.10280"
"508.42800","42.36913","0.10236"
"508.77600","42.39813","0.10309"
"509.12400","42.42713","0.10342"
"509.47200","42.45619","0.10294"
"509.82000","42.48513","0.00104"
"510.16800","42.51413","0.00102"
"510.51600","42.54318","0.00041"
"510.86400","42.57218","0.00407"
"511.21200","42.60106","0.00179"
"511.56000","42.63012","0.00172"
"511.90800","42.65911","0.00162"
"512.25600","42.68811","0.00321"
"512.60400","42.71717","0.00142"
"512.95200","42.74611","0.00183"
"513.30000","42.77517","0.00355"
"513.64800","42.80422","0.00124"
"513.99600","42.83316","0.00094"
"514.34400","42.86216","0.00207"
"514.69200","42.89110","0.00163"
"515.04000","42.92015","0.00167"
"515.20400","42.93385","0.00205"