File: Force_trajectories/161226_2/Specimen_RawData_2.csv
End date,"12/26/2016"
Specimen label,"11BG_81_2"
Maximum Load,"0.14144",N

Time,Extension,Load
(s),(mm),(N)
"0.00000","0.00000","0.00024"
"0.28200","0.02272","0.00042"
"0.56400","0.04729","0.00098"
"0.84600","0.07073","0.00101"
"1.12800","0.09423","0.00171"
"1.41000","0.11767","0.00169"
"1.69200","0.14122","0.00164"
"1.97400","0.16472","0.00219"
"2.25600","0.18822","0.00218"
"2.53800","0.21171","0.00202"
"2.82000","0.23515","0.00222"
"3.10200","0.25865","0.00240"
"3.38400","0.28221","0.00267"
"3.66600","0.30564","0.00272"
"3.94800","0.32920","0.00299"
"4.23000","0.35264","0.00340"
"4.51200","0.37620","0.00299"
"4.79400","0.39969","0.00279"
"5.07600","0.42319","0.00294"
"5.35800","0.44669","0.00270"
"5.64000","0.47018","0.00289"
"5.92200","0.49368","0.00342"
"6.20400","0.51724","0.00294"
"6.48600","0.54074","0.00305"
"6.76800","0.56417","0.00343"
"7.05000","0.58773","0.00355"
"7.33200","0.61117","0.00371"
"7.61400","0.63479","0.00360"
"7.89600","0.65816","0.00370"
"8.17800","0.68172","0.00374"
"8.46000","0.70516","0.00429"
"8.74200","0.72877","0.00417"
"9.02400","0.75215","0.00404"
"9.30600","0.77571","0.00412"
"9.58800","0.79915","0.00364"
"9.87000","0.82270","0.00368"
"10.15200","0.84614","0.00445"
"10.43400","0.86970","0.00390"
"10.71600","0.89320","0.00395"
"10.99800","0.91669","0.00446"
"11.28000","0.94013","0.00458"
"11.56200","0.96369","0.00470"
"11.84400","0.98718","0.00533"
"12.12600","1.01068","0.00423"
"12.40800","1.03424","0.00461"
"12.69000","1.05774","0.00453"
"12.97200","1.08117","0.00495"
"13.25400","1.10467","0.00487"
"13.53600","1.12823","0.00525"
"13.81800","1.15167","0.00482"
"14.10000","1.17522","0.00494"
"14.38200","1.19866","0.00476"
"14.66400","1.22216","0.00514"
"14.94600","1.24566","0.00519"
"15.22800","1.26927","0.00484"
"15.51000","1.29271","0.00538"
"15.79200","1.31621","0.00544"
"16.07400","1.33970","0.00534"
"16.35600","1.36326","0.00537"
"16.63800","1.38670","0.00529"
"16.92000","1.41020","0.00568"
"17.20200","1.43369","0.00577"
"17.48400","1.45719","0.00572"
"17.76600","1.48069","0.00566"
"18.04800","1.50419","0.00546"
"18.33000","1.52774","0.00566"
"18.61200","1.55118","0.00491"
"18.89400","1.57468","0.00483"
"19.17600","1.59817","0.00510"
"19.45800","1.62173","0.00476"
"19.74000","1.64523","0.00496"
"20.02200","1.66867","0.00487"
"20.30400","1.69216","0.00524"
"20.58600","1.71566","0.00495"
"20.86800","1.73916","0.00489"
"21.15000","1.76271","0.00502"
"21.43200","1.78615","0.00456"
"21.71400","1.80971","0.00491"
"21.99600","1.83315","0.00483"
"22.27800","1.85670","0.00493"
"22.56000","1.88020","0.00488"
"22.84200","1.90376","0.00482"
"23.12400","1.92720","0.00481"
"23.40600","1.95069","0.00485"
"23.68800","1.97419","0.00526"
"23.97000","1.99775","0.00519"
"24.25200","2.02130","0.00535"
"24.53400","2.04468","0.00516"
"24.81600","2.06824","0.00525"
"25.09800","2.09168","0.00507"
"25.38000","2.11523","0.00538"
"25.66200","2.13867","0.00521"
"25.94400","2.16223","0.00577"
"26.22600","2.18567","0.00570"
"26.50800","2.20922","0.00535"
"26.79000","2.23260","0.00519"
"27.07200","2.25622","0.00532"
"27.35400","2.27966","0.00532"
"27.63600","2.30327","0.00512"
"27.91800","2.32671","0.00469"
"28.20000","2.35021","0.00507"
"28.48200","2.37364","0.00484"
"28.76400","2.39720","0.00514"
"29.04600","2.42070","0.00564"
"29.32800","2.44420","0.00504"
"29.61000","2.46769","0.00540"
"29.89200","2.49125","0.00557"
"30.17400","2.51475","0.00538"
"30.45600","2.53825","0.00518"
"30.73800","2.56174","0.00544"
"31.02000","2.58518","0.00521"
"31.30200","2.60874","0.00454"
"31.58400","2.63217","0.00508"
"31.86600","2.65573","0.00535"
"32.14800","2.67917","0.00499"
"32.43000","2.70279","0.00538"
"32.71200","2.72616","0.00569"
"32.99400","2.74972","0.00545"
"33.27600","2.77316","0.00512"
"33.55800","2.79672","0.00552"
"33.84000","2.82015","0.00565"
"34.12200","2.84371","0.00516"
"34.40400","2.86715","0.00526"
"34.68600","2.89070","0.00487"
"34.96800","2.91414","0.00531"
"35.25000","2.93770","0.00521"
"35.53200","2.96120","0.00516"
"35.81400","2.98469","0.00525"
"36.09600","3.00819","0.00526"
"36.37800","3.03169","0.00538"
"36.66000","3.05519","0.00538"
"36.94200","3.07862","0.00579"
"37.22400","3.10218","0.00544"
"37.50600","3.12568","0.00567"
"37.78800","3.14923","0.00529"
"38.07000","3.17273","0.00513"
"38.35200","3.19623","0.00541"
"38.63400","3.21967","0.00535"
"38.91600","3.24322","0.00521"
"39.19800","3.26666","0.00488"
"39.48000","3.29022","0.00489"
"39.76200","3.31372","0.00538"
"40.04400","3.33721","0.00538"
"40.32600","3.36071","0.00579"
"40.60800","3.38421","0.00548"
"40.89000","3.40770","0.00519"
"41.17200","3.43120","0.00597"
"41.45400","3.45476","0.00557"
"41.73600","3.47814","0.00540"
"42.01800","3.50169","0.00577"
"42.30000","3.52519","0.00524"
"42.58200","3.54875","0.00539"
"42.86400","3.57219","0.00523"
"43.14600","3.59574","0.00592"
"43.42800","3.61918","0.00525"
"43.71000","3.64274","0.00550"
"43.99200","3.66617","0.00544"
"44.27400","3.68967","0.00593"
"44.55600","3.71311","0.00559"
"44.83800","3.73673","0.00562"
"45.12000","3.76016","0.00596"
"45.40200","3.78372","0.00568"
"45.68400","3.80722","0.00554"
"45.96600","3.83078","0.00595"
"46.24800","3.85415","0.00539"
"46.53000","3.87771","0.00575"
"46.81200","3.90121","0.00521"
"47.09400","3.92470","0.00544"
"47.37600","3.94820","0.00575"
"47.65800","3.97176","0.00554"
"47.94000","3.99526","0.00584"
"48.22200","4.01869","0.00602"
"48.50400","4.04225","0.00605"
"48.78600","4.06569","0.00596"
"49.06800","4.08925","0.00524"
"49.35000","4.11268","0.00609"
"49.63200","4.13624","0.00552"
"49.91400","4.15962","0.00565"
"50.19600","4.18323","0.00585"
"50.47800","4.20667","0.00608"
"50.76000","4.23029","0.00553"
"51.04200","4.25367","0.00543"
"51.32400","4.27722","0.00567"
"51.60600","4.30060","0.00545"
"51.88800","4.32422","0.00553"
"52.17000","4.34766","0.00542"
"52.45200","4.37121","0.00540"
"52.73400","4.39465","0.00586"
"53.01600","4.41821","0.00563"
"53.29800","4.44170","0.00589"
"53.58000","4.46520","0.00599"
"53.86200","4.48870","0.00591"
"54.14400","4.51220","0.00603"
"54.42600","4.53569","0.00555"
"54.70800","4.55919","0.00527"
"54.99000","4.58275","0.00597"
"55.27200","4.60619","0.00597"
"55.55400","4.62974","0.00562"
"55.83600","4.65318","0.00596"
"56.11800","4.67674","0.00584"
"56.40000","4.70017","0.00538"
"56.68200","4.72373","0.00542"
"56.96400","4.74717","0.00531"
"57.24600","4.77073","0.00555"
"57.52800","4.79416","0.00583"
"57.81000","4.81772","0.00564"
"58.09200","4.84122","0.00586"
"58.37400","4.86472","0.00591"
"58.65600","4.88827","0.00604"
"58.93800","4.91165","0.00588"
"59.22000","4.93521","0.00588"
"59.50200","4.95870","0.00614"
"59.78400","4.98226","0.00608"
"60.06600","5.00564","0.00637"
"60.34800","5.02926","0.00623"
"60.63000","5.05269","0.00568"
"60.91200","5.07625","0.00610"
"61.19400","5.09963","0.00594"
"61.47600","5.12319","0.00604"
"61.75800","5.14668","0.00657"
"62.04000","5.17024","0.00620"
"62.32200","5.19368","0.00588"
"62.60400","5.21723","0.00638"
"62.88600","5.24073","0.00619"
"63.16800","5.26423","0.00635"
"63.45000","5.28767","0.00619"
"63.73200","5.31116","0.00665"
"64.01400","5.33466","0.00651"
"64.29600","5.35822","0.00623"
"64.57800","5.38172","0.00636"
"64.86000","5.40521","0.00586"
"65.14200","5.42871","0.00633"
"65.42400","5.45215","0.00610"
"65.70600","5.47570","0.00668"
"65.98800","5.49914","0.00621"
"66.27000","5.52270","0.00625"
"66.55200","5.54614","0.00648"
"66.83400","5.56969","0.00637"
"67.11600","5.59313","0.00631"
"67.39800","5.61675","0.00700"
"67.68000","5.64019","0.00655"
"67.96200","5.66374","0.00614"
"68.24400","5.68712","0.00609"
"68.52600","5.71074","0.00705"
"68.80800","5.73417","0.00653"
"69.09000","5.75773","0.00591"
"69.37200","5.78117","0.00648"
"69.65400","5.80473","0.00598"
"69.93600","5.82816","0.00651"
"70.21800","5.85172","0.00639"
"70.50000","5.87522","0.00655"
"70.78200","5.89872","0.00676"
"71.06400","5.92221","0.00662"
"71.34600","5.94571","0.00686"
"71.62800","5.96921","0.00613"
"71.91000","5.99270","0.00670"
"72.19200","6.01626","0.00632"
"72.47400","6.03970","0.00688"
"72.75600","6.06326","0.00663"
"73.03800","6.08669","0.00672"
"73.32000","6.11025","0.00652"
"73.60200","6.13369","0.00651"
"73.88400","6.15725","0.00647"
"74.16600","6.18068","0.00616"
"74.44800","6.20418","0.00652"
"74.73000","6.22768","0.00641"
"75.01200","6.25124","0.00660"
"75.29400","6.27467","0.00656"
"75.57600","6.29823","0.00701"
"75.85800","6.32167","0.00655"
"76.14000","6.34516","0.00664"
"76.42200","6.36872","0.00622"
"76.70400","6.39222","0.00644"
"76.98600","6.41572","0.00616"
"77.26800","6.43921","0.00607"
"77.55000","6.46277","0.00609"
"77.83200","6.48621","0.00595"
"78.11400","6.50971","0.00600"
"78.39600","6.53314","0.00610"
"78.67800","6.55670","0.00631"
"78.96000","6.58020","0.00663"
"79.24200","6.60369","0.00635"
"79.52400","6.62719","0.00633"
"79.80600","6.65075","0.00552"
"80.08800","6.67419","0.00619"
"80.37000","6.69774","0.00614"
"80.65200","6.72118","0.00576"
"80.93400","6.74474","0.00636"
"81.21600","6.76818","0.00643"
"81.49800","6.79173","0.00661"
"81.78000","6.81523","0.00626"
"82.06200","6.83873","0.00542"
"82.34400","6.86222","0.00602"
"82.62600","6.88566","0.00558"
"82.90800","6.90922","0.00558"
"83.19000","6.93266","0.00580"
"83.47200","6.95621","0.00593"
"83.75400","6.97965","0.00545"
"84.03600","7.00321","0.00554"
"84.31800","7.02665","0.00586"
"84.60000","7.05020","0.00577"
"84.88200","7.07364","0.00587"
"85.16400","7.09720","0.00562"
"85.44600","7.12063","0.00576"
"85.72800","7.14419","0.00545"
"86.01000","7.16763","0.00555"
"86.29200","7.19125","0.00575"
"86.57400","7.21468","0.00570"
"86.85600","7.23818","0.00525"
"87.13800","7.26168","0.00529"
"87.42000","7.28524","0.00604"
"87.70200","7.30873","0.00559"
"87.98400","7.33223","0.00553"
"88.26600","7.35573","0.00538"
"88.54800","7.37928","0.00524"
"88.83000","7.40272","0.00491"
"89.11200","7.42622","0.00447"
"89.39400","7.44972","0.00492"
"89.67600","7.47321","0.00482"
"89.95800","7.49671","0.00503"
"90.24000","7.52021","0.00482"
"90.52200","7.54377","0.00529"
"90.80400","7.56720","0.00504"
"91.08600","7.59070","0.00510"
"91.36800","7.61414","0.00506"
"91.65000","7.63769","0.00501"
"91.93200","7.66119","0.00540"
"92.21400","7.68475","0.00588"
"92.49600","7.70819","0.00527"
"92.77800","7.73168","0.00522"
"93.06000","7.75518","0.00541"
"93.34200","7.77868","0.00531"
"93.62400","7.80218","0.00461"
"93.90600","7.82567","0.00501"
"94.18800","7.84923","0.00490"
"94.47000","7.87273","0.00447"
"94.75200","7.89622","0.00477"
"95.03400","7.91972","0.00528"
"95.31600","7.94328","0.00514"
"95.59800","7.96666","0.00500"
"95.88000","7.99021","0.00540"
"96.16200","8.01365","0.00528"
"96.44400","8.03727","0.00546"
"96.72600","8.06071","0.00514"
"97.00800","8.08426","0.00481"
"97.29000","8.10770","0.00520"
"97.57200","8.13126","0.00495"
"97.85400","8.15463","0.00471"
"98.13600","8.17825","0.00522"
"98.41800","8.20169","0.00513"
"98.70000","8.22519","0.00474"
"98.98200","8.24868","0.00469"
"99.26400","8.27218","0.00462"
"99.54600","8.29568","0.00463"
"99.82800","8.31917","0.00530"
"100.11000","8.34267","0.00477"
"100.39200","8.36611","0.00495"
"100.67400","8.38967","0.00471"
"100.95600","8.41317","0.00480"
"101.23800","8.43672","0.00487"
"101.52000","8.46016","0.00489"
"101.80200","8.48372","0.00497"
"102.08400","8.50715","0.00480"
"102.36600","8.53065","0.00477"
"102.64800","8.55415","0.00527"
"102.93000","8.57776","0.00456"
"103.21200","8.60114","0.00447"
"103.49400","8.62476","0.00466"
"103.77600","8.64820","0.00450"
"104.05800","8.67175","0.00515"
"104.34000","8.69519","0.00461"
"104.62200","8.71875","0.00468"
"104.90400","8.74219","0.00508"
"105.18600","8.76574","0.00525"
"105.46800","8.78924","0.00520"
"105.75000","8.81274","0.00522"
"106.03200","8.83624","0.00475"
"106.31400","8.85967","0.00462"
"106.59600","8.88323","0.00507"
"106.87800","8.90673","0.00488"
"107.16000","8.93022","0.00489"
"107.44200","8.95372","0.00437"
"107.72400","8.97722","0.00482"
"108.00600","9.00072","0.00502"
"108.28800","9.02415","0.00410"
"108.57000","9.04765","0.00448"
"108.85200","9.07121","0.00482"
"109.13400","9.09465","0.00480"
"109.41600","9.11826","0.00459"
"109.69800","9.14164","0.00458"
"109.98000","9.16520","0.00461"
"110.26200","9.18869","0.00458"
"110.54400","9.21219","0.00478"
"110.82600","9.23569","0.00456"
"111.10800","9.25925","0.00484"
"111.39000","9.28268","0.00439"
"111.67200","9.30624","0.00460"
"111.95400","9.32980","0.00487"
"112.23600","9.35324","0.00482"
"112.51800","9.37673","0.00491"
"112.80000","9.40017","0.00477"
"113.08200","9.42373","0.00483"
"113.36400","9.44716","0.00470"
"113.64600","9.47078","0.00497"
"113.92800","9.49422","0.00443"
"114.21000","9.51778","0.00473"
"114.49200","9.54115","0.00509"
"114.77400","9.56471","0.00482"
"115.05600","9.58815","0.00454"
"115.33800","9.61171","0.00490"
"115.62000","9.63514","0.00468"
"115.90200","9.65870","0.00485"
"116.18400","9.68220","0.00490"
"116.46600","9.70569","0.00510"
"116.74800","9.72919","0.00489"
"117.03000","9.75269","0.00476"
"117.31200","9.77619","0.00465"
"117.59400","9.79968","0.00514"
"117.87600","9.82318","0.00481"
"118.15800","9.84674","0.00441"
"118.44000","9.87024","0.00521"
"118.72200","9.89373","0.00496"
"119.00400","9.91723","0.00498"
"119.28600","9.94067","0.00466"
"119.56800","9.96422","0.00458"
"119.85000","9.98766","0.00510"
"120.13200","10.01128","0.00492"
"120.41400","10.03466","0.00469"
"120.69600","10.05821","0.00551"
"120.97800","10.08171","0.00495"
"121.26000","10.10527","0.00503"
"121.54200","10.12871","0.00480"
"121.82400","10.15226","0.00511"
"122.10600","10.17564","0.00481"
"122.38800","10.19920","0.00496"
"122.67000","10.22269","0.00498"
"122.95200","10.24619","0.00467"
"123.23400","10.26969","0.00489"
"123.51600","10.29319","0.00460"
"123.79800","10.31668","0.00499"
"124.08000","10.34018","0.00534"
"124.36200","10.36374","0.00473"
"124.64400","10.38718","0.00473"
"124.92600","10.41073","0.00543"
"125.20800","10.43417","0.00493"
"125.49000","10.45767","0.00540"
"125.77200","10.48110","0.00469"
"126.05400","10.50472","0.00447"
"126.33600","10.52816","0.00533"
"126.61800","10.55172","0.00534"
"126.90000","10.57521","0.00516"
"127.18200","10.59877","0.00489"
"127.46400","10.62221","0.00491"
"127.74600","10.64571","0.00471"
"128.02800","10.66914","0.00498"
"128.31000","10.69270","0.00518"
"128.59200","10.71620","0.00450"
"128.87400","10.73975","0.00486"
"129.15600","10.76325","0.00464"
"129.43800","10.78675","0.00506"
"129.72000","10.81025","0.00483"
"130.00200","10.83368","0.00423"
"130.28400","10.85718","0.00468"
"130.56600","10.88068","0.00476"
"130.84800","10.90418","0.00479"
"131.13000","10.92767","0.00526"
"131.41200","10.95117","0.00508"
"131.69400","10.97467","0.00510"
"131.97600","10.99817","0.00482"
"132.25800","11.02160","0.00478"
"132.54000","11.04522","0.00514"
"132.82200","11.06866","0.00494"
"133.10400","11.09221","0.00484"
"133.38600","11.11565","0.00497"
"133.66800","11.13921","0.00473"
"133.95000","11.16271","0.00495"
"134.23200","11.18620","0.00453"
"134.51400","11.20964","0.00533"
"134.79600","11.23320","0.00495"
"135.07800","11.25670","0.00524"
"135.36000","11.28019","0.00527"
"135.64200","11.30375","0.00502"
"135.92400","11.32719","0.00553"
"136.20600","11.35074","0.00531"
"136.48800","11.37418","0.00554"
"136.77000","11.39774","0.00571"
"137.05200","11.42118","0.00520"
"137.33400","11.44479","0.00603"
"137.61600","11.46823","0.00557"
"137.89800","11.49179","0.00652"
"138.18000","11.51517","0.00603"
"138.46200","11.53872","0.00571"
"138.74400","11.56210","0.00620"
"139.02600","11.58572","0.00532"
"139.30800","11.60915","0.00617"
"139.59000","11.63271","0.00574"
"139.87200","11.65621","0.00545"
"140.15400","11.67971","0.00564"
"140.43600","11.70314","0.00576"
"140.71800","11.72664","0.00643"
"141.00000","11.75020","0.00646"
"141.28200","11.77369","0.00650"
"141.56400","11.79725","0.00634"
"141.84600","11.82075","0.00669"
"142.12800","11.84425","0.00680"
"142.41000","11.86768","0.00636"
"142.69200","11.89124","0.00629"
"142.97400","11.91468","0.00687"
"143.25600","11.93824","0.00658"
"143.53800","11.96167","0.00625"
"143.82000","11.98517","0.00648"
"144.10200","12.00867","0.00593"
"144.38400","12.03229","0.00700"
"144.66600","12.05572","0.00690"
"144.94800","12.07922","0.00687"
"145.23000","12.10266","0.00693"
"145.51200","12.12627","0.00716"
"145.79400","12.14971","0.00708"
"146.07600","12.17321","0.00693"
"146.35800","12.19671","0.00705"
"146.64000","12.22020","0.00729"
"146.92200","12.24370","0.00717"
"147.20400","12.26720","0.00755"
"147.48600","12.29070","0.00747"
"147.76800","12.31419","0.00761"
"148.05000","12.33775","0.00775"
"148.33200","12.36119","0.00765"
"148.61400","12.38468","0.00765"
"148.89600","12.40818","0.00776"
"149.17800","12.43168","0.00820"
"149.46000","12.45512","0.00820"
"149.74200","12.47873","0.00840"
"150.02400","12.50217","0.00827"
"150.30600","12.52573","0.00848"
"150.58800","12.54911","0.00837"
"150.87000","12.57272","0.00841"
"151.15200","12.59616","0.00848"
"151.43400","12.61966","0.00881"
"151.71600","12.64316","0.00828"
"151.99800","12.66671","0.00889"
"152.28000","12.69021","0.00878"
"152.56200","12.71377","0.00899"
"152.84400","12.73726","0.00902"
"153.12600","12.76076","0.00936"
"153.40800","12.78426","0.00919"
"153.69000","12.80770","0.00935"
"153.97200","12.83125","0.00932"
"154.25400","12.85475","0.00934"
"154.53600","12.87825","0.00942"
"154.81800","12.90168","0.00941"
"155.10000","12.92524","0.00952"
"155.38200","12.94862","0.00963"
"155.66400","12.97218","0.00988"
"155.94600","12.99562","0.00974"
"156.22800","13.01923","0.01010"
"156.51000","13.04267","0.00980"
"156.79200","13.06628","0.00989"
"157.07400","13.08966","0.01038"
"157.35600","13.11322","0.01014"
"157.63800","13.13666","0.01051"
"157.92000","13.16021","0.01063"
"158.20200","13.18365","0.01070"
"158.48400","13.20721","0.01061"
"158.76600","13.23071","0.01075"
"159.04800","13.25426","0.01119"
"159.33000","13.27776","0.01131"
"159.61200","13.30120","0.01099"
"159.89400","13.32476","0.01110"
"160.17600","13.34819","0.01059"
"160.45800","13.37175","0.01119"
"160.74000","13.39519","0.01121"
"161.02200","13.41875","0.01142"
"161.30400","13.44218","0.01142"
"161.58600","13.46574","0.01169"
"161.86800","13.48918","0.01206"
"162.15000","13.51273","0.01200"
"162.43200","13.53617","0.01232"
"162.71400","13.55973","0.01213"
"162.99600","13.58323","0.01226"
"163.27800","13.60672","0.01262"
"163.56000","13.63016","0.01273"
"163.84200","13.65366","0.01283"
"164.12400","13.67716","0.01313"
"164.40600","13.70065","0.01333"
"164.68800","13.72421","0.01297"
"164.97000","13.74771","0.01369"
"165.25200","13.77120","0.01341"
"165.53400","13.79470","0.01396"
"165.81600","13.81820","0.01429"
"166.09800","13.84164","0.01422"
"166.38000","13.86513","0.01440"
"166.66200","13.88863","0.01480"
"166.94400","13.91219","0.01506"
"167.22600","13.93569","0.01527"
"167.50800","13.95924","0.01555"
"167.79000","13.98268","0.01572"
"168.07200","14.00624","0.01583"
"168.35400","14.02967","0.01604"
"168.63600","14.05317","0.01646"
"168.91800","14.07673","0.01669"
"169.20000","14.10023","0.01679"
"169.48200","14.12372","0.01709"
"169.76400","14.14722","0.01704"
"170.04600","14.17072","0.01771"
"170.32800","14.19421","0.01828"
"170.61000","14.21777","0.01803"
"170.89200","14.24121","0.01880"
"171.17400","14.26477","0.01879"
"171.45600","14.28815","0.01928"
"171.73800","14.31176","0.01946"
"172.02000","14.33520","0.01959"
"172.30200","14.35876","0.02064"
"172.58400","14.38219","0.02065"
"172.86600","14.40569","0.02088"
"173.14800","14.42913","0.02119"
"173.43000","14.45268","0.02059"
"173.71200","14.47612","0.02084"
"173.99400","14.49974","0.02132"
"174.27600","14.52318","0.02181"
"174.55800","14.54673","0.02190"
"174.84000","14.57017","0.02255"
"175.12200","14.59373","0.02251"
"175.40400","14.61717","0.02377"
"175.68600","14.64072","0.02370"
"175.96800","14.66422","0.02442"
"176.25000","14.68772","0.02533"
"176.53200","14.71121","0.02549"
"176.81400","14.73471","0.02599"
"177.09600","14.75827","0.02632"
"177.37800","14.78171","0.02687"
"177.66000","14.80532","0.02665"
"177.94200","14.82870","0.02716"
"178.22400","14.85226","0.02825"
"178.50600","14.87570","0.02859"
"178.78800","14.89919","0.02906"
"179.07000","14.92263","0.02925"
"179.35200","14.94619","0.02956"
"179.63400","14.96969","0.03015"
"179.91600","14.99324","0.03077"
"180.19800","15.01668","0.03060"
"180.48000","15.04018","0.03202"
"180.76200","15.06361","0.03155"
"181.04400","15.08723","0.03264"
"181.32600","15.11067","0.03410"
"181.60800","15.13417","0.03455"
"181.89000","15.15766","0.03535"
"182.17200","15.18116","0.03664"
"182.45400","15.20472","0.03774"
"182.73600","15.22821","0.03820"
"183.01800","15.25171","0.03889"
"183.30000","15.27521","0.03963"
"183.58200","15.29871","0.04029"
"183.86400","15.32220","0.04060"
"184.14600","15.34576","0.04205"
"184.42800","15.36920","0.04298"
"184.71000","15.39270","0.03939"
"184.99200","15.41619","0.03908"
"185.27400","15.43975","0.03986"
"185.55600","15.46319","0.04115"
"185.83800","15.48674","0.04148"
"186.12000","15.51018","0.04268"
"186.40200","15.53374","0.04372"
"186.68400","15.55724","0.04416"
"186.96600","15.58073","0.04507"
"187.24800","15.60423","0.04585"
"187.53000","15.62773","0.04667"
"187.81200","15.65123","0.04685"
"188.09400","15.67466","0.04730"
"188.37600","15.69822","0.04823"
"188.65800","15.72166","0.04920"
"188.94000","15.74522","0.04966"
"189.22200","15.76865","0.05031"
"189.50400","15.79221","0.05106"
"189.78600","15.81565","0.05190"
"190.06800","15.83914","0.05274"
"190.35000","15.86264","0.05302"
"190.63200","15.88620","0.05333"
"190.91400","15.90970","0.05424"
"191.19600","15.93325","0.05479"
"191.47800","15.95669","0.05517"
"191.76000","15.98025","0.05565"
"192.04200","16.00368","0.05646"
"192.32400","16.02724","0.05729"
"192.60600","16.05068","0.05732"
"192.88800","16.07424","0.05836"
"193.17000","16.09767","0.05882"
"193.45200","16.12123","0.05940"
"193.73400","16.14473","0.06004"
"194.01600","16.16823","0.06095"
"194.29800","16.19172","0.06160"
"194.58000","16.21516","0.06199"
"194.86200","16.23872","0.06384"
"195.14400","16.26216","0.06517"
"195.42600","16.28571","0.06590"
"195.70800","16.30915","0.06671"
"195.99000","16.33271","0.06874"
"196.27200","16.35614","0.06863"
"196.55400","16.37970","0.07031"
"196.83600","16.40314","0.07210"
"197.11800","16.42676","0.07272"
"197.40000","16.45013","0.07347"
"197.68200","16.47375","0.07592"
"197.96400","16.49713","0.07611"
"198.24600","16.52069","0.07788"
"198.52800","16.54418","0.07854"
"198.81000","16.56768","0.07966"
"199.09200","16.59118","0.08136"
"199.37400","16.61473","0.08252"
"199.65600","16.63823","0.08353"
"199.93800","16.66167","0.08473"
"200.22000","16.68517","0.08546"
"200.50200","16.70866","0.08708"
"200.78400","16.73222","0.08744"
"201.06600","16.75566","0.08784"
"201.34800","16.77927","0.08914"
"201.63000","16.80271","0.09085"
"201.91200","16.82627","0.09134"
"202.19400","16.84971","0.09248"
"202.47600","16.87326","0.09349"
"202.75800","16.89664","0.09439"
"203.04000","16.92020","0.09518"
"203.32200","16.94370","0.09519"
"203.60400","16.96725","0.09610"
"203.88600","16.99069","0.09654"
"204.16800","17.01425","0.09710"
"204.45000","17.03768","0.09730"
"204.73200","17.06124","0.09789"
"205.01400","17.08474","0.09815"
"205.29600","17.10818","0.09921"
"205.57800","17.13167","0.09953"
"205.86000","17.15517","0.10003"
"206.14200","17.17873","0.10047"
"206.42400","17.20223","0.10092"
"206.70600","17.22578","0.10152"
"206.98800","17.24922","0.10217"
"207.27000","17.27272","0.10242"
"207.55200","17.29609","0.10302"
"207.83400","17.31971","0.10324"
"208.11600","17.34315","0.10349"
"208.39800","17.36671","0.10386"
"208.68000","17.39014","0.10409"
"208.96200","17.41376","0.10486"
"209.24400","17.43720","0.10528"
"209.52600","17.46076","0.10604"
"209.80800","17.48419","0.10667"
"210.09000","17.50775","0.10737"
"210.37200","17.53119","0.10816"
"210.65400","17.55474","0.10998"
"210.93600","17.57824","0.11025"
"211.21800","17.60174","0.11187"
"211.50000","17.62524","0.11262"
"211.78200","17.64867","0.11402"
"212.06400","17.67223","0.11527"
"212.34600","17.69567","0.11630"
"212.62800","17.71923","0.11773"
"212.91000","17.74266","0.11851"
"213.19200","17.76622","0.12016"
"213.47400","17.78966","0.12078"
"213.75600","17.81322","0.12193"
"214.03800","17.83665","0.12400"
"214.32000","17.86021","0.12468"
"214.60200","17.88359","0.12661"
"214.88400","17.90720","0.12960"
"215.16600","17.93058","0.13151"
"215.44800","17.95426","0.13269"
"215.73000","17.97770","0.13557"
"216.01200","18.00119","0.13765"
"216.29400","18.02469","0.13839"
"216.57600","18.04825","0.14047"
"216.85800","18.07174","0.13066"
"217.14000","18.09524","-0.00571"
"217.42200","18.11868","0.00378"
"217.70400","18.14224","0.00369"
"217.98600","18.16573","0.00494"
"218.26800","18.18917","0.00346"
"218.55000","18.21273","0.00317"
"218.83200","18.23623","0.00482"
"219.11400","18.25972","0.00404"
"219.39600","18.28322","0.00475"
"219.67800","18.30672","0.00471"
"219.96000","18.33015","0.00425"
"220.24200","18.35371","0.00403"
"220.52400","18.37715","0.00456"
"220.80600","18.40071","0.00416"
"221.08800","18.42420","0.00499"
"221.37000","18.44776","0.00493"
"221.65200","18.47120","0.00468"
"221.93400","18.49470","0.00439"
"222.21600","18.51819","0.00513"
"222.49800","18.54169","0.00508"
"222.78000","18.56519","0.00529"
"223.06200","18.58869","0.00515"
"223.34400","18.61224","0.00557"
"223.62600","18.63568","0.00549"
"223.90800","18.65924","0.00550"
"224.19000","18.68268","0.00566"
"224.47200","18.70629","0.00512"
"224.75400","18.72967","0.00583"
"225.03600","18.75323","0.00559"
"225.31800","18.77672","0.00586"
"225.60000","18.80022","0.00549"
"225.88200","18.82372","0.00573"
"226.16400","18.84727","0.00610"
"226.44600","18.87071","0.00602"
"226.72800","18.89427","0.00601"
"227.01000","18.91771","0.00589"
"227.29200","18.94120","0.00584"
"227.57400","18.96470","0.00611"
"227.85600","18.98814","0.00588"
"228.13800","19.01164","0.00638"
"228.42000","19.03519","0.00641"
"228.70200","19.05869","0.00666"
"228.98400","19.08219","0.00639"
"229.26600","19.10575","0.00635"
"229.54800","19.12918","0.00690"
"229.83000","19.15268","0.00667"
"230.11200","19.17612","0.00638"
"230.39400","19.19967","0.00652"
"230.67600","19.22317","0.00668"
"230.95800","19.24667","0.00664"
"231.24000","19.27017","0.00701"
"231.52200","19.29372","0.00749"
"231.80400","19.31716","0.00699"
"232.08600","19.34078","0.00707"
"232.36800","19.36416","0.00689"
"232.65000","19.38771","0.00701"
"232.93200","19.41115","0.00722"
"233.21400","19.43471","0.00695"
"233.49600","19.45820","0.00729"
"233.77800","19.48176","0.00738"
"234.06000","19.50520","0.00661"
"234.34200","19.52876","0.00723"
"234.62400","19.55225","0.00727"
"234.90600","19.57575","0.00764"
"235.18800","19.59919","0.00715"
"235.47000","19.62268","0.00744"
"235.75200","19.64624","0.00723"
"236.03400","19.66968","0.00779"
"236.31600","19.69324","0.00749"
"236.59800","19.71667","0.00767"
"236.88000","19.74023","0.00773"
"237.16200","19.76367","0.00770"
"237.44400","19.78717","0.00781"
"237.72600","19.81066","0.00795"
"238.00800","19.83422","0.00804"
"238.29000","19.85766","0.00771"
"238.57200","19.88121","0.00847"
"238.85400","19.90465","0.00770"
"239.13600","19.92821","0.00762"
"239.41800","19.95171","0.00783"
"239.70000","19.97520","0.00770"
"239.98200","19.99870","0.00775"
"240.26400","20.02220","0.00774"
"240.54600","20.04570","0.00822"
"240.82800","20.06919","0.00789"
"241.11000","20.09275","0.00792"
"241.39200","20.11625","0.00815"
"241.67400","20.13975","0.00822"
"241.95600","20.16324","0.00742"
"242.23800","20.18674","0.00814"
"242.52000","20.21018","0.00831"
"242.80200","20.23374","0.00810"
"243.08400","20.25717","0.00831"
"243.36600","20.28073","0.00870"
"243.64800","20.30416","0.00852"
"243.93000","20.32772","0.00864"
"244.21200","20.35116","0.00866"
"244.49400","20.37472","0.00851"
"244.77600","20.39816","0.00832"
"245.05800","20.42165","0.00835"
"245.34000","20.44515","0.00855"
"245.62200","20.46871","0.00874"
"245.90400","20.49214","0.00895"
"246.18600","20.51564","0.00900"
"246.46800","20.53920","0.00914"
"246.75000","20.56270","0.00863"
"247.03200","20.58619","0.00888"
"247.31400","20.60969","0.00906"
"247.59600","20.63325","0.00878"
"247.87800","20.65669","0.00904"
"248.16000","20.68024","0.00903"
"248.44200","20.70368","0.00941"
"248.72400","20.72724","0.00913"
"249.00600","20.75068","0.00898"
"249.28800","20.77423","0.00900"
"249.57000","20.79767","0.00930"
"249.85200","20.82123","0.00923"
"250.13400","20.84466","0.00986"
"250.41600","20.86822","0.00950"
"250.69800","20.89172","0.00970"
"250.98000","20.91527","0.00934"
"251.26200","20.93871","0.00953"
"251.54400","20.96221","0.00940"
"251.82600","20.98571","0.00949"
"252.10800","21.00920","0.00945"
"252.39000","21.03270","0.00970"
"252.67200","21.05620","0.00940"
"252.95400","21.07970","0.00976"
"253.23600","21.10319","0.00962"
"253.51800","21.12669","0.00980"
"253.80000","21.15013","0.00971"
"254.08200","21.17369","0.00963"
"254.36400","21.19718","0.00974"
"254.64600","21.22068","0.00990"
"254.92800","21.24418","0.01028"
"255.21000","21.26768","0.01002"
"255.49200","21.29117","0.01007"
"255.77400","21.31473","0.01019"
"256.05600","21.33817","0.01000"
"256.33800","21.36179","0.00992"
"256.62000","21.38516","0.01021"
"256.90200","21.40866","0.01026"
"257.18400","21.43216","0.01045"
"257.46600","21.45572","0.01013"
"257.74800","21.47921","0.01031"
"258.03000","21.50277","0.01026"
"258.31200","21.52627","0.01028"
"258.59400","21.54976","0.01040"
"258.87600","21.57326","0.01039"
"259.15800","21.59670","0.01037"
"259.44000","21.62025","0.01041"
"259.72200","21.64369","0.01059"
"260.00400","21.66725","0.01038"
"260.28600","21.69069","0.01070"
"260.56800","21.71424","0.01048"
"260.85000","21.73768","0.01086"
"261.13200","21.76118","0.01098"
"261.41400","21.78461","0.01053"
"261.69600","21.80823","0.01093"
"261.97800","21.83161","0.01093"
"262.26000","21.85523","0.01022"
"262.54200","21.87867","0.01046"
"262.82400","21.90222","0.01067"
"263.10600","21.92566","0.01083"
"263.38800","21.94922","0.01076"
"263.67000","21.97265","0.01050"
"263.95200","21.99615","0.01069"
"264.23400","22.01971","0.01102"
"264.51600","22.04321","0.01084"
"264.79800","22.06670","0.01133"
"265.08000","22.09020","0.01076"
"265.36200","22.11376","0.01136"
"265.64400","22.13713","0.01116"
"265.92600","22.16075","0.01112"
"266.20800","22.18419","0.01127"
"266.49000","22.20774","0.01169"
"266.77200","22.23118","0.01156"
"267.05400","22.25480","0.01140"
"267.33600","22.27818","0.01149"
"267.61800","22.30173","0.01156"
"267.90000","22.32517","0.01165"
"268.18200","22.34873","0.01174"
"268.46400","22.37217","0.01150"
"268.74600","22.39572","0.01161"
"269.02800","22.41922","0.01154"
"269.31000","22.44272","0.01179"
"269.59200","22.46616","0.01169"
"269.87400","22.48965","0.01169"
"270.15600","22.51321","0.01190"
"270.43800","22.53671","0.01197"
"270.72000","22.56021","0.01192"
"271.00200","22.58370","0.01187"
"271.28400","22.60720","0.01200"
"271.56600","22.63070","0.01213"
"271.84800","22.65419","0.01224"
"272.13000","22.67769","0.01226"
"272.41200","22.70125","0.01219"
"272.69400","22.72468","0.01194"
"272.97600","22.74824","0.01205"
"273.25800","22.77168","0.01214"
"273.54000","22.79524","0.01246"
"273.82200","22.81867","0.01238"
"274.10400","22.84223","0.01232"
"274.38600","22.86573","0.01259"
"274.66800","22.88923","0.01244"
"274.95000","22.91273","0.01262"
"275.23200","22.93622","0.01237"
"275.51400","22.95972","0.01261"
"275.79600","22.98322","0.01302"
"276.07800","23.00665","0.01282"
"276.36000","23.03015","0.01289"
"276.64200","23.05371","0.01263"
"276.92400","23.07721","0.01265"
"277.20600","23.10070","0.01268"
"277.48800","23.12414","0.01301"
"277.77000","23.14770","0.01291"
"278.05200","23.17120","0.01268"
"278.33400","23.19469","0.01230"
"278.61600","23.21813","0.01225"
"278.89800","23.24169","0.01248"
"279.18000","23.26513","0.01249"
"279.46200","23.28868","0.01262"
"279.74400","23.31218","0.01294"
"280.02600","23.33574","0.01246"
"280.30800","23.35923","0.01246"
"280.59000","23.38273","0.01219"
"280.87200","23.40617","0.01260"
"281.15400","23.42967","0.01219"
"281.43600","23.45322","0.01259"
"281.71800","23.47672","0.01235"
"282.00000","23.50022","0.01213"
"282.28200","23.52371","0.01218"
"282.56400","23.54727","0.01232"
"282.84600","23.57071","0.01252"
"283.12800","23.59426","0.01281"
"283.41000","23.61770","0.01273"
"283.69200","23.64126","0.01258"
"283.97400","23.66464","0.01245"
"284.25600","23.68826","0.01273"
"284.53800","23.71163","0.01275"
"284.82000","23.73525","0.01273"
"285.10200","23.75863","0.01303"
"285.38400","23.78224","0.01298"
"285.66600","23.80568","0.01303"
"285.94800","23.82924","0.01294"
"286.23000","23.85268","0.01314"
"286.51200","23.87617","0.01341"
"286.79400","23.89967","0.01330"
"287.07600","23.92317","0.01334"
"287.35800","23.94666","0.01307"
"287.64000","23.97022","0.01340"
"287.92200","23.99372","0.01331"
"288.20400","24.01722","0.01332"
"288.48600","24.04077","0.01351"
"288.76800","24.06421","0.01323"
"289.05000","24.08777","0.01301"
"289.33200","24.11115","0.01321"
"289.61400","24.13470","0.01342"
"289.89600","24.15820","0.01367"
"290.17800","24.18170","0.01314"
"290.46000","24.20519","0.01334"
"290.74200","24.22875","0.01346"
"291.02400","24.25219","0.01356"
"291.30600","24.27575","0.01351"
"291.58800","24.29918","0.01334"
"291.87000","24.32274","0.01376"
"292.15200","24.34618","0.01370"
"292.43400","24.36974","0.01407"
"292.71600","24.39323","0.01401"
"292.99800","24.41667","0.01364"
"293.28000","24.44017","0.01406"
"293.56200","24.46367","0.01389"
"293.84400","24.48716","0.01389"
"294.12600","24.51066","0.01465"
"294.40800","24.53422","0.01408"
"294.69000","24.55765","0.01398"
"294.97200","24.58121","0.01393"
"295.25400","24.60465","0.01405"
"295.53600","24.62815","0.01367"
"295.81800","24.65164","0.01414"
"296.10000","24.67520","0.01359"
"296.38200","24.69864","0.01416"
"296.66400","24.72220","0.01421"
"296.94600","24.74569","0.01399"
"297.22800","24.76925","0.01414"
"297.51000","24.79269","0.01394"
"297.79200","24.81624","0.01392"
"298.07400","24.83974","0.01391"
"298.35600","24.86324","0.01413"
"298.63800","24.88674","0.01414"
"298.92000","24.91023","0.01399"
"299.20200","24.93373","0.01429"
"299.48400","24.95723","0.01434"
"299.76600","24.98078","0.01442"
"300.04800","25.00416","0.01439"
"300.33000","25.02772","0.01469"
"300.61200","25.05116","0.01436"
"300.89400","25.07477","0.01416"
"301.17600","25.09821","0.01442"
"301.45800","25.12171","0.01455"
"301.74000","25.14515","0.01449"
"302.02200","25.16876","0.01463"
"302.30400","25.19214","0.01416"
"302.58600","25.21570","0.01436"
"302.86800","25.23914","0.01434"
"303.15000","25.26275","0.01468"
"303.43200","25.28619","0.01431"
"303.71400","25.30975","0.01453"
"303.99600","25.33319","0.01466"
"304.27800","25.35668","0.01426"
"304.56000","25.38018","0.01463"
"304.84200","25.40368","0.01449"
"305.12400","25.42717","0.01422"
"305.40600","25.45073","0.01478"
"305.68800","25.47423","0.01470"
"305.97000","25.49772","0.01446"
"306.25200","25.52128","0.01490"
"306.53400","25.54472","0.01474"
"306.81600","25.56828","0.01478"
"307.09800","25.59165","0.01478"
"307.38000","25.61527","0.01482"
"307.66200","25.63871","0.01470"
"307.94400","25.66220","0.01492"
"308.22600","25.68564","0.01466"
"308.50800","25.70926","0.01515"
"308.79000","25.73264","0.01513"
"309.07200","25.75626","0.01492"
"309.35400","25.77969","0.01510"
"309.63600","25.80319","0.01503"
"309.91800","25.82668","0.01528"
"310.20000","25.85018","0.01555"
"310.48200","25.87368","0.01558"
"310.76400","25.89718","0.01545"
"311.04600","25.92068","0.01578"
"311.32800","25.94417","0.01579"
"311.61000","25.96773","0.01565"
"311.89200","25.99117","0.01595"
"312.17400","26.01473","0.01546"
"312.45600","26.03822","0.01581"
"312.73800","26.06172","0.01598"
"313.02000","26.08516","0.01546"
"313.30200","26.10872","0.01628"
"313.58400","26.13221","0.01622"
"313.86600","26.15571","0.01616"
"314.14800","26.17915","0.01627"
"314.43000","26.20271","0.01669"
"314.71200","26.22620","0.01626"
"314.99400","26.24970","0.01629"
"315.27600","26.27320","0.01651"
"315.55800","26.29669","0.01605"
"315.84000","26.32025","0.01600"
"316.12200","26.34375","0.01631"
"316.40400","26.36724","0.01622"
"316.68600","26.39074","0.01666"
"316.96800","26.41424","0.01694"
"317.25000","26.43768","0.01689"
"317.53200","26.46117","0.01577"
"317.81400","26.48467","0.01610"
"318.09600","26.50823","0.01604"
"318.37800","26.53167","0.01637"
"318.66000","26.55522","0.01653"
"318.94200","26.57866","0.01689"
"319.22400","26.60222","0.01664"
"319.50600","26.62566","0.01688"
"319.78800","26.64921","0.01670"
"320.07000","26.67265","0.01646"
"320.35200","26.69627","0.01674"
"320.63400","26.71970","0.01671"
"320.91600","26.74326","0.01687"
"321.19800","26.76670","0.01670"
"321.48000","26.79019","0.01689"
"321.76200","26.81369","0.01696"
"322.04400","26.83719","0.01691"
"322.32600","26.86069","0.01650"
"322.60800","26.88418","0.01578"
"322.89000","26.90774","0.01467"
"323.17200","26.93124","0.00985"
"323.45400","26.95479","0.01073"
"323.73600","26.97823","0.01009"
"324.01800","27.00173","0.01081"
"324.30000","27.02517","0.01049"
"324.58200","27.04873","0.01060"
"324.86400","27.07216","0.01064"
"325.14600","27.09572","0.01087"
"325.42800","27.11916","0.01082"
"325.71000","27.14272","0.01107"
"325.99200","27.16615","0.01107"
"326.27400","27.18971","0.01087"
"326.55600","27.21314","0.01125"
"326.83800","27.23670","0.01102"
"327.12000","27.26014","0.01090"
"327.40200","27.28370","0.01106"
"327.68400","27.30713","0.01126"
"327.96600","27.33069","0.01051"
"328.24800","27.35413","0.01076"
"328.53000","27.37769","0.01065"
"328.81200","27.40119","0.01059"
"329.09400","27.42474","0.01086"
"329.37600","27.44818","0.01104"
"329.65800","27.47168","0.01092"
"329.94000","27.49518","0.01112"
"330.22200","27.51867","0.01157"
"330.50400","27.54223","0.01127"
"330.78600","27.56567","0.01141"
"331.06800","27.58928","0.01140"
"331.35000","27.61272","0.01154"
"331.63200","27.63628","0.01149"
"331.91400","27.65971","0.01159"
"332.19600","27.68321","0.01185"
"332.47800","27.70665","0.01172"
"332.76000","27.73021","0.01193"
"333.04200","27.75370","0.01209"
"333.32400","27.77726","0.01194"
"333.60600","27.80070","0.01170"
"333.88800","27.82420","0.01198"
"334.17000","27.84775","0.01185"
"334.45200","27.87113","0.01182"
"334.73400","27.89469","0.01194"
"335.01600","27.91818","0.01220"
"335.29800","27.94174","0.01207"
"335.58000","27.96518","0.01223"
"335.86200","27.98874","0.01220"
"336.14400","28.01217","0.01235"
"336.42600","28.03573","0.01255"
"336.70800","28.05917","0.01224"
"336.99000","28.08273","0.01256"
"337.27200","28.10616","0.01235"
"337.55400","28.12972","0.01231"
"337.83600","28.15316","0.01292"
"338.11800","28.17672","0.01261"
"338.40000","28.20021","0.01285"
"338.68200","28.22377","0.01312"
"338.96400","28.24721","0.01293"
"339.24600","28.27076","0.01281"
"339.52800","28.29420","0.01297"
"339.81000","28.31776","0.01343"
"340.09200","28.34120","0.01303"
"340.37400","28.36469","0.01308"
"340.65600","28.38825","0.01306"
"340.93800","28.41169","0.01313"
"341.22000","28.43519","0.01362"
"341.50200","28.45868","0.01339"
"341.78400","28.48224","0.01378"
"342.06600","28.50562","0.01356"
"342.34800","28.52917","0.01367"
"342.63000","28.55261","0.01352"
"342.91200","28.57617","0.01334"
"343.19400","28.59961","0.01319"
"343.47600","28.62322","0.01346"
"343.75800","28.64660","0.01337"
"344.04000","28.67022","0.01333"
"344.32200","28.69366","0.01362"
"344.60400","28.71721","0.01385"
"344.88600","28.74071","0.01348"
"345.16800","28.76421","0.01364"
"345.45000","28.78765","0.01357"
"345.73200","28.81120","0.01380"
"346.01400","28.83470","0.01399"
"346.29600","28.85820","0.01375"
"346.57800","28.88169","0.01388"
"346.86000","28.90525","0.01376"
"347.14200","28.92875","0.01406"
"347.42400","28.95218","0.01428"
"347.70600","28.97574","0.01419"
"347.98800","28.99918","0.01440"
"348.27000","29.02274","0.01448"
"348.55200","29.04624","0.01471"
"348.83400","29.06973","0.01430"
"349.11600","29.09317","0.01434"
"349.39800","29.11673","0.01485"
"349.68000","29.14016","0.01481"
"349.96200","29.16372","0.01502"
"350.24400","29.18716","0.01450"
"350.52600","29.21072","0.01472"
"350.80800","29.23415","0.01481"
"351.09000","29.25771","0.01456"
"351.37200","29.28115","0.01517"
"351.65400","29.30464","0.01491"
"351.93600","29.32820","0.01502"
"352.21800","29.35170","0.01524"
"352.50000","29.37526","0.01566"
"352.78200","29.39869","0.01572"
"353.06400","29.42225","0.01579"
"353.34600","29.44569","0.01525"
"353.62800","29.46919","0.01566"
"353.91000","29.49262","0.01593"
"354.19200","29.51624","0.01530"
"354.47400","29.53968","0.01532"
"354.75600","29.56323","0.01539"
"355.03800","29.58667","0.01554"
"355.32000","29.61023","0.01545"
"355.60200","29.63367","0.01558"
"355.88400","29.65728","0.01586"
"356.16600","29.68072","0.01610"
"356.44800","29.70422","0.01546"
"356.73000","29.72771","0.01531"
"357.01200","29.75121","0.01549"
"357.29400","29.77471","0.01597"
"357.57600","29.79821","0.01553"
"357.85800","29.82170","0.01608"
"358.14000","29.84520","0.01563"
"358.42200","29.86870","0.01613"
"358.70400","29.89214","0.01591"
"358.98600","29.91569","0.01613"
"359.26800","29.93913","0.01609"
"359.55000","29.96269","0.01624"
"359.83200","29.98613","0.01618"
"360.11400","30.00968","0.01644"
"360.39600","30.03312","0.01630"
"360.67800","30.05667","0.01616"
"360.96000","30.08012","0.01604"
"361.24200","30.10373","0.01627"
"361.52400","30.12717","0.01655"
"361.80600","30.15073","0.01695"
"362.08800","30.17422","0.01642"
"362.37000","30.19772","0.01615"
"362.65200","30.22122","0.01661"
"362.93400","30.24478","0.01647"
"363.21600","30.26822","0.01589"
"363.49800","30.29171","0.01417"
"363.78000","30.31521","0.01258"
"364.06200","30.33871","0.01333"
"364.34400","30.36220","0.01329"
"364.62600","30.38570","0.01257"
"364.90800","30.40926","0.01296"
"365.19000","30.43270","0.01244"
"365.47200","30.45619","0.01273"
"365.75400","30.47969","0.01278"
"366.03600","30.50319","0.01229"
"366.31800","30.52668","0.01277"
"366.60000","30.55018","0.01297"
"366.88200","30.57362","0.01286"
"367.16400","30.59723","0.01301"
"367.44600","30.62061","0.01325"
"367.72800","30.64423","0.01325"
"368.01000","30.66767","0.01382"
"368.29200","30.69117","0.01324"
"368.57400","30.71466","0.01377"
"368.85600","30.73816","0.01363"
"369.13800","30.76171","0.01377"
"369.42000","30.78521","0.01398"
"369.70200","30.80871","0.01387"
"369.98400","30.83221","0.01441"
"370.26600","30.85576","0.01409"
"370.54800","30.87920","0.01467"
"370.83000","30.90270","0.01475"
"371.11200","30.92620","0.01433"
"371.39400","30.94975","0.01473"
"371.67600","30.97319","0.01490"
"371.95800","30.99675","0.01494"
"372.24000","31.02019","0.01495"
"372.52200","31.04374","0.01519"
"372.80400","31.06718","0.01548"
"373.08600","31.09074","0.01558"
"373.36800","31.11417","0.01594"
"373.65000","31.13767","0.01573"
"373.93200","31.16117","0.01616"
"374.21400","31.18467","0.01585"
"374.49600","31.20816","0.01607"
"374.77800","31.23166","0.01613"
"375.06000","31.25516","0.01653"
"375.34200","31.27865","0.01636"
"375.62400","31.30221","0.01644"
"375.90600","31.32565","0.01637"
"376.18800","31.34921","0.01699"
"376.47000","31.37270","0.01685"
"376.75200","31.39620","0.01559"
"377.03400","31.41970","0.01608"
"377.31600","31.44325","0.01602"
"377.59800","31.46669","0.01648"
"377.88000","31.49019","0.01621"
"378.16200","31.51363","0.01706"
"378.44400","31.53724","0.01653"
"378.72600","31.56062","0.01670"
"379.00800","31.58424","0.01690"
"379.29000","31.60768","0.01693"
"379.57200","31.63124","0.01700"
"379.85400","31.65473","0.01697"
"380.13600","31.67829","0.01716"
"380.41800","31.70167","0.01733"
"380.70000","31.72522","0.01742"
"380.98200","31.74866","0.01776"
"381.26400","31.77222","0.01775"
"381.54600","31.79571","0.01800"
"381.82800","31.81921","0.01767"
"382.11000","31.84271","0.01781"
"382.39200","31.86621","0.01806"
"382.67400","31.88970","0.01749"
"382.95600","31.91320","0.01834"
"383.23800","31.93664","0.01825"
"383.52000","31.96014","0.01844"
"383.80200","31.98369","0.01900"
"384.08400","32.00713","0.01861"
"384.36600","32.03069","0.01907"
"384.64800","32.05418","0.01904"
"384.93000","32.07774","0.01917"
"385.21200","32.10118","0.01883"
"385.49400","32.12474","0.01917"
"385.77600","32.14817","0.01864"
"386.05800","32.17167","0.01895"
"386.34000","32.19517","0.01904"
"386.62200","32.21872","0.01927"
"386.90400","32.24222","0.01921"
"387.18600","32.26578","0.01949"
"387.46800","32.28928","0.01826"
"387.75000","32.31271","0.01875"
"388.03200","32.33627","0.01883"
"388.31400","32.35971","0.01978"
"388.59600","32.38327","0.01910"
"388.87800","32.40670","0.01871"
"389.16000","32.43026","0.01921"
"389.44200","32.45370","0.01935"
"389.72400","32.47720","0.01973"
"390.00600","32.50069","0.01952"
"390.28800","32.52425","0.01992"
"390.57000","32.54763","0.01943"
"390.85200","32.57119","0.01948"
"391.13400","32.59462","0.01991"
"391.41600","32.61818","0.02000"
"391.69800","32.64167","0.02021"
"391.98000","32.66517","0.02046"
"392.26200","32.68867","0.02079"
"392.54400","32.71217","0.02121"
"392.82600","32.73566","0.02070"
"393.10800","32.75916","0.02091"
"393.39000","32.78272","0.02078"
"393.67200","32.80616","0.02024"
"393.95400","32.82971","0.02023"
"394.23600","32.85315","0.02059"
"394.51800","32.87677","0.02089"
"394.80000","32.90015","0.02106"
"395.08200","32.92376","0.02143"
"395.36400","32.94720","0.02092"
"395.64600","32.97076","0.02172"
"395.92800","32.99419","0.02147"
"396.21000","33.01781","0.02183"
"396.49200","33.04119","0.02216"
"396.77400","33.06475","0.02269"
"397.05600","33.08818","0.02254"
"397.33800","33.11174","0.02305"
"397.62000","33.13518","0.02301"
"397.90200","33.15874","0.02347"
"398.18400","33.18223","0.02346"
"398.46600","33.20573","0.02368"
"398.74800","33.22917","0.02373"
"399.03000","33.25267","0.02414"
"399.31200","33.27616","0.02372"
"399.59400","33.29972","0.02380"
"399.87600","33.32322","0.02386"
"400.15800","33.34672","0.02375"
"400.44000","33.37021","0.02413"
"400.72200","33.39365","0.02429"
"401.00400","33.41721","0.02444"
"401.28600","33.44065","0.02501"
"401.56800","33.46420","0.02526"
"401.85000","33.48770","0.02511"
"402.13200","33.51125","0.02538"
"402.41400","33.53463","0.02574"
"402.69600","33.55825","0.02604"
"402.97800","33.58169","0.02629"
"403.26000","33.60518","0.02668"
"403.54200","33.62868","0.02657"
"403.82400","33.65224","0.02699"
"404.10600","33.67574","0.02697"
"404.38800","33.69923","0.02743"
"404.67000","33.72273","0.02752"
"404.95200","33.74623","0.02771"
"405.23400","33.76973","0.02813"
"405.51600","33.79322","0.02808"
"405.79800","33.81672","0.02851"
"406.08000","33.84016","0.02869"
"406.36200","33.86372","0.02881"
"406.64400","33.88715","0.02907"
"406.92600","33.91065","0.02907"
"407.20800","33.93415","0.02847"
"407.49000","33.95771","0.02738"
"407.77200","33.98108","0.02839"
"408.05400","34.00470","0.02880"
"408.33600","34.02819","0.02848"
"408.61800","34.05169","0.02904"
"408.90000","34.07513","0.02934"
"409.18200","34.09875","0.02944"
"409.46400","34.12224","0.02969"
"409.74600","34.14568","0.03001"
"410.02800","34.16918","0.03039"
"410.31000","34.19268","0.02988"
"410.59200","34.21623","0.03012"
"410.87400","34.23973","0.03068"
"411.15600","34.26323","0.03007"
"411.43800","34.28673","0.03075"
"411.72000","34.31028","0.03129"
"412.00200","34.33366","0.03164"
"412.28400","34.35728","0.03175"
"412.56600","34.38071","0.03200"
"412.84800","34.40427","0.03108"
"413.13000","34.42765","0.03153"
"413.41200","34.45126","0.03127"
"413.69400","34.47470","0.03181"
"413.97600","34.49820","0.03171"
"414.25800","34.52164","0.03285"
"414.54000","34.54526","0.03301"
"414.82200","34.56870","0.03355"
"415.10400","34.59219","0.03401"
"415.38600","34.61569","0.03444"
"415.66800","34.63918","0.03489"
"415.95000","34.66274","0.03454"
"416.23200","34.68618","0.03470"
"416.51400","34.70968","0.03487"
"416.79600","34.73323","0.03507"
"417.07800","34.75673","0.03559"
"417.36000","34.78023","0.03593"
"417.64200","34.80373","0.03621"
"417.92400","34.82716","0.03641"
"418.20600","34.85072","0.03706"
"418.48800","34.87422","0.03696"
"418.77000","34.89772","0.03722"
"419.05200","34.92115","0.03764"
"419.33400","34.94465","0.03805"
"419.61600","34.96815","0.03817"
"419.89800","34.99176","0.03830"
"420.18000","35.01520","0.03906"
"420.46200","35.03876","0.03980"
"420.74400","35.06220","0.03949"
"421.02600","35.08575","0.03951"
"421.30800","35.10919","0.04017"
"421.59000","35.13275","0.04062"
"421.72800","35.14417","0.04058"