File: Force_trajectories/161226_2/Specimen_RawData_4.csv
End date,"12/26/2016"
Specimen label,"11BG_81_1"
Maximum Load,"0.25816",N

Time,Extension,Load
(s),(mm),(N)
"0.00000","0.00000","0.00109"
"0.30000","0.02445","0.00173"
"0.60000","0.05028","0.00218"
"0.90000","0.07522","0.00191"
"1.20000","0.10021","0.00221"
"1.50000","0.12520","0.00256"
"1.80000","0.15019","0.00240"
"2.10000","0.17518","0.00303"
"2.40000","0.20012","0.00263"
"2.70000","0.22523","0.00275"
"3.00000","0.25022","0.00346"
"3.30000","0.27521","0.00286"
"3.60000","0.30020","0.00335"
"3.90000","0.32520","0.00284"
"4.20000","0.35025","0.00297"
"4.50000","0.37512","0.00393"
"4.80000","0.40017","0.00319"
"5.10000","0.42516","0.00326"
"5.40000","0.45022","0.00323"
"5.70000","0.47521","0.00365"
"6.00000","0.50020","0.00405"
"6.30000","0.52519","0.00357"
"6.60000","0.55018","0.00389"
"6.90000","0.57524","0.00382"
"7.20000","0.60017","0.00357"
"7.50000","0.62522","0.00388"
"7.80000","0.65015","0.00385"
"8.10000","0.67520","0.00435"
"8.40000","0.70014","0.00430"
"8.70000","0.72519","0.00379"
"9.00000","0.75018","0.00451"
"9.30000","0.77517","0.00440"
"9.60000","0.80022","0.00417"
"9.90000","0.82522","0.00515"
"10.20000","0.85021","0.00460"
"10.50000","0.87514","0.00435"
"10.80000","0.90025","0.00409"
"11.10000","0.92518","0.00445"
"11.40000","0.95018","0.00428"
"11.70000","0.97517","0.00487"
"12.00000","1.00016","0.00447"
"12.30000","1.02521","0.00459"
"12.60000","1.05014","0.00511"
"12.90000","1.07520","0.00524"
"13.20000","1.10019","0.00441"
"13.50000","1.12524","0.00439"
"13.80000","1.15017","0.00507"
"14.10000","1.17522","0.00435"
"14.40000","1.20022","0.00489"
"14.70000","1.22515","0.00547"
"15.00000","1.25020","0.00499"
"15.30000","1.27513","0.00554"
"15.60000","1.30024","0.00509"
"15.90000","1.32518","0.00530"
"16.20000","1.35029","0.00534"
"16.50000","1.37522","0.00507"
"16.80000","1.40027","0.00533"
"17.10000","1.42526","0.00485"
"17.40000","1.45020","0.00516"
"17.70000","1.47519","0.00542"
"18.00000","1.50018","0.00498"
"18.30000","1.52523","0.00576"
"18.60000","1.55016","0.00542"
"18.90000","1.57516","0.00518"
"19.20000","1.60021","0.00547"
"19.50000","1.62514","0.00532"
"19.80000","1.65025","0.00574"
"20.10000","1.67518","0.00552"
"20.40000","1.70024","0.00584"
"20.70000","1.72517","0.00557"
"21.00000","1.75022","0.00566"
"21.30000","1.77521","0.00602"
"21.60000","1.80020","0.00582"
"21.90000","1.82520","0.00573"
"22.20000","1.85019","0.00585"
"22.50000","1.87518","0.00627"
"22.80000","1.90017","0.00606"
"23.10000","1.92522","0.00612"
"23.40000","1.95016","0.00550"
"23.70000","1.97521","0.00553"
"24.00000","2.00020","0.00588"
"24.30000","2.02519","0.00596"
"24.60000","2.05024","0.00580"
"24.90000","2.07518","0.00583"
"25.20000","2.10023","0.00589"
"25.50000","2.12516","0.00583"
"25.80000","2.15021","0.00615"
"26.10000","2.17520","0.00581"
"26.40000","2.20025","0.00584"
"26.70000","2.22525","0.00650"
"27.00000","2.25024","0.00578"
"27.30000","2.27523","0.00606"
"27.60000","2.30022","0.00536"
"27.90000","2.32516","0.00537"
"28.20000","2.35015","0.00555"
"28.50000","2.37520","0.00583"
"28.80000","2.40019","0.00594"
"29.10000","2.42518","0.00563"
"29.40000","2.45017","0.00617"
"29.70000","2.47523","0.00563"
"30.00000","2.50028","0.00542"
"30.30000","2.52515","0.00577"
"30.60000","2.55020","0.00581"
"30.90000","2.57519","0.00576"
"31.20000","2.60025","0.00614"
"31.50000","2.62518","0.00599"
"31.80000","2.65023","0.00542"
"32.10000","2.67522","0.00597"
"32.40000","2.70016","0.00571"
"32.70000","2.72527","0.00579"
"33.00000","2.75020","0.00596"
"33.30000","2.77531","0.00579"
"33.60000","2.80018","0.00540"
"33.90000","2.82523","0.00605"
"34.20000","2.85017","0.00604"
"34.50000","2.87522","0.00564"
"34.80000","2.90021","0.00592"
"35.10000","2.92520","0.00600"
"35.40000","2.95019","0.00635"
"35.70000","2.97519","0.00676"
"36.00000","3.00024","0.00644"
"36.30000","3.02517","0.00621"
"36.60000","3.05028","0.00601"
"36.90000","3.07522","0.00620"
"37.20000","3.10021","0.00639"
"37.50000","3.12514","0.00631"
"37.80000","3.15013","0.00677"
"38.10000","3.17518","0.00624"
"38.40000","3.20017","0.00613"
"38.70000","3.22517","0.00568"
"39.00000","3.25016","0.00596"
"39.30000","3.27521","0.00622"
"39.60000","3.30020","0.00586"
"39.90000","3.32520","0.00665"
"40.20000","3.35019","0.00616"
"40.50000","3.37518","0.00607"
"40.80000","3.40023","0.00618"
"41.10000","3.42516","0.00665"
"41.40000","3.45021","0.00648"
"41.70000","3.47515","0.00645"
"42.00000","3.50020","0.00604"
"42.30000","3.52519","0.00623"
"42.60000","3.55018","0.00682"
"42.90000","3.57523","0.00611"
"43.20000","3.60023","0.00632"
"43.50000","3.62522","0.00620"
"43.80000","3.65015","0.00614"
"44.10000","3.67526","0.00608"
"44.40000","3.70019","0.00659"
"44.70000","3.72519","0.00615"
"45.00000","3.75018","0.00630"
"45.30000","3.77517","0.00631"
"45.60000","3.80022","0.00631"
"45.90000","3.82521","0.00649"
"46.20000","3.85021","0.00617"
"46.50000","3.87514","0.00683"
"46.80000","3.90025","0.00622"
"47.10000","3.92518","0.00647"
"47.40000","3.95017","0.00661"
"47.70000","3.97523","0.00686"
"48.00000","4.00022","0.00668"
"48.30000","4.02521","0.00707"
"48.60000","4.05014","0.00716"
"48.90000","4.07519","0.00638"
"49.20000","4.10019","0.00652"
"49.50000","4.12524","0.00655"
"49.80000","4.15017","0.00659"
"50.10000","4.17522","0.00656"
"50.40000","4.20021","0.00707"
"50.70000","4.22521","0.00680"
"51.00000","4.25026","0.00605"
"51.30000","4.27519","0.00657"
"51.60000","4.30024","0.00667"
"51.90000","4.32517","0.00693"
"52.20000","4.35023","0.00691"
"52.50000","4.37516","0.00663"
"52.80000","4.40021","0.00728"
"53.10000","4.42520","0.00677"
"53.40000","4.45019","0.00657"
"53.70000","4.47525","0.00727"
"54.00000","4.50018","0.00676"
"54.30000","4.52517","0.00714"
"54.60000","4.55016","0.00708"
"54.90000","4.57521","0.00665"
"55.20000","4.60015","0.00675"
"55.50000","4.62520","0.00635"
"55.80000","4.65019","0.00677"
"56.10000","4.67518","0.00707"
"56.40000","4.70029","0.00654"
"56.70000","4.72517","0.00649"
"57.00000","4.75022","0.00698"
"57.30000","4.77515","0.00678"
"57.60000","4.80020","0.00685"
"57.90000","4.82519","0.00694"
"58.20000","4.85013","0.00712"
"58.50000","4.87518","0.00668"
"58.80000","4.90017","0.00654"
"59.10000","4.92522","0.00647"
"59.40000","4.95015","0.00674"
"59.70000","4.97521","0.00714"
"60.00000","5.00020","0.00652"
"60.30000","5.02519","0.00656"
"60.60000","5.05018","0.00623"
"60.90000","5.07517","0.00705"
"61.20000","5.10023","0.00690"
"61.50000","5.12516","0.00651"
"61.80000","5.15021","0.00629"
"62.10000","5.17514","0.00687"
"62.40000","5.20019","0.00701"
"62.70000","5.22519","0.00712"
"63.00000","5.25018","0.00621"
"63.30000","5.27517","0.00617"
"63.60000","5.30022","0.00680"
"63.90000","5.32521","0.00679"
"64.20000","5.35021","0.00640"
"64.50000","5.37520","0.00626"
"64.80000","5.40013","0.00652"
"65.10000","5.42524","0.00647"
"65.40000","5.45017","0.00640"
"65.70000","5.47523","0.00700"
"66.00000","5.50022","0.00610"
"66.30000","5.52527","0.00659"
"66.60000","5.55026","0.00662"
"66.90000","5.57513","0.00721"
"67.20000","5.60019","0.00701"
"67.50000","5.62512","0.00703"
"67.80000","5.65023","0.00683"
"68.10000","5.67510","0.00648"
"68.40000","5.70021","0.00715"
"68.70000","5.72521","0.00738"
"69.00000","5.75020","0.00647"
"69.30000","5.77525","0.00645"
"69.60000","5.80018","0.00725"
"69.90000","5.82523","0.00719"
"70.20000","5.85017","0.00669"
"70.50000","5.87522","0.00723"
"70.80000","5.90021","0.00697"
"71.10000","5.92520","0.00690"
"71.40000","5.95019","0.00699"
"71.70000","5.97519","0.00744"
"72.00000","6.00024","0.00666"
"72.30000","6.02523","0.00720"
"72.60000","6.05022","0.00722"
"72.90000","6.07521","0.00725"
"73.20000","6.10021","0.00709"
"73.50000","6.12514","0.00716"
"73.80000","6.15013","0.00725"
"74.10000","6.17518","0.00717"
"74.40000","6.20011","0.00715"
"74.70000","6.22523","0.00716"
"75.00000","6.25016","0.00690"
"75.30000","6.27521","0.00673"
"75.60000","6.30014","0.00729"
"75.90000","6.32525","0.00682"
"76.20000","6.35019","0.00716"
"76.50000","6.37524","0.00737"
"76.80000","6.40023","0.00649"
"77.10000","6.42516","0.00661"
"77.40000","6.45021","0.00649"
"77.70000","6.47515","0.00689"
"78.00000","6.50020","0.00660"
"78.30000","6.52513","0.00708"
"78.60000","6.55018","0.00731"
"78.90000","6.57517","0.00660"
"79.20000","6.60023","0.00693"
"79.50000","6.62522","0.00692"
"79.80000","6.65015","0.00737"
"80.10000","6.67520","0.00746"
"80.40000","6.70013","0.00664"
"80.70000","6.72519","0.00673"
"81.00000","6.75012","0.00691"
"81.30000","6.77517","0.00656"
"81.60000","6.80016","0.00607"
"81.90000","6.82516","0.00661"
"82.20000","6.85021","0.00709"
"82.50000","6.87520","0.00695"
"82.80000","6.90019","0.00686"
"83.10000","6.92518","0.00673"
"83.40000","6.95023","0.00701"
"83.70000","6.97517","0.00641"
"84.00000","7.00022","0.00722"
"84.30000","7.02521","0.00704"
"84.60000","7.05020","0.00692"
"84.90000","7.07525","0.00718"
"85.20000","7.10019","0.00734"
"85.50000","7.12524","0.00717"
"85.80000","7.15017","0.00755"
"86.10000","7.17522","0.00730"
"86.40000","7.20015","0.00726"
"86.70000","7.22527","0.00699"
"87.00000","7.25020","0.00767"
"87.30000","7.27519","0.00705"
"87.60000","7.30024","0.00724"
"87.90000","7.32523","0.00735"
"88.20000","7.35017","0.00729"
"88.50000","7.37516","0.00696"
"88.80000","7.40021","0.00753"
"89.10000","7.42520","0.00728"
"89.40000","7.45025","0.00757"
"89.70000","7.47519","0.00733"
"90.00000","7.50018","0.00722"
"90.30000","7.52523","0.00772"
"90.60000","7.55016","0.00781"
"90.90000","7.57515","0.00794"
"91.20000","7.60015","0.00800"
"91.50000","7.62520","0.00761"
"91.80000","7.65019","0.00729"
"92.10000","7.67524","0.00730"
"92.40000","7.70029","0.00754"
"92.70000","7.72523","0.00794"
"93.00000","7.75028","0.00722"
"93.30000","7.77515","0.00747"
"93.60000","7.80020","0.00766"
"93.90000","7.82513","0.00755"
"94.20000","7.85019","0.00749"
"94.50000","7.87512","0.00729"
"94.80000","7.90017","0.00772"
"95.10000","7.92522","0.00749"
"95.40000","7.95021","0.00764"
"95.70000","7.97521","0.00778"
"96.00000","8.00020","0.00825"
"96.30000","8.02525","0.00820"
"96.60000","8.05018","0.00761"
"96.90000","8.07523","0.00760"
"97.20000","8.10017","0.00766"
"97.50000","8.12516","0.00718"
"97.80000","8.15021","0.00746"
"98.10000","8.17520","0.00824"
"98.40000","8.20019","0.00794"
"98.70000","8.22519","0.00762"
"99.00000","8.25024","0.00803"
"99.30000","8.27517","0.00778"
"99.60000","8.30016","0.00762"
"99.90000","8.32515","0.00814"
"100.20000","8.35021","0.00772"
"100.50000","8.37520","0.00807"
"100.80000","8.40013","0.00841"
"101.10000","8.42518","0.00823"
"101.40000","8.45011","0.00788"
"101.70000","8.47523","0.00824"
"102.00000","8.50016","0.00759"
"102.30000","8.52527","0.00780"
"102.60000","8.55026","0.00844"
"102.90000","8.57519","0.00805"
"103.20000","8.60025","0.00840"
"103.50000","8.62518","0.00780"
"103.80000","8.65017","0.00808"
"104.10000","8.67510","0.00767"
"104.40000","8.70021","0.00815"
"104.70000","8.72515","0.00816"
"105.00000","8.75020","0.00827"
"105.30000","8.77519","0.00847"
"105.60000","8.80018","0.00833"
"105.90000","8.82523","0.00828"
"106.20000","8.85017","0.00819"
"106.50000","8.87522","0.00819"
"106.80000","8.90021","0.00868"
"107.10000","8.92526","0.00863"
"107.40000","8.95019","0.00843"
"107.70000","8.97519","0.00838"
"108.00000","9.00018","0.00847"
"108.30000","9.02517","0.00871"
"108.60000","9.05022","0.00777"
"108.90000","9.07515","0.00876"
"109.20000","9.10021","0.00831"
"109.50000","9.12520","0.00835"
"109.80000","9.15025","0.00849"
"110.10000","9.17518","0.00863"
"110.40000","9.20017","0.00857"
"110.70000","9.22523","0.00812"
"111.00000","9.25022","0.00857"
"111.30000","9.27521","0.00820"
"111.60000","9.30020","0.00846"
"111.90000","9.32519","0.00839"
"112.20000","9.35019","0.00815"
"112.50000","9.37524","0.00848"
"112.80000","9.40023","0.00843"
"113.10000","9.42522","0.00874"
"113.40000","9.45021","0.00842"
"113.70000","9.47521","0.00897"
"114.00000","9.50020","0.00853"
"114.30000","9.52513","0.00876"
"114.60000","9.55018","0.00839"
"114.90000","9.57511","0.00830"
"115.20000","9.60017","0.00865"
"115.50000","9.62522","0.00901"
"115.80000","9.65027","0.00837"
"116.10000","9.67526","0.00836"
"116.40000","9.70019","0.00850"
"116.70000","9.72519","0.00816"
"117.00000","9.75018","0.00877"
"117.30000","9.77523","0.00892"
"117.60000","9.80016","0.00845"
"117.90000","9.82521","0.00836"
"118.20000","9.85021","0.00876"
"118.50000","9.87520","0.00833"
"118.80000","9.90025","0.00830"
"119.10000","9.92518","0.00849"
"119.40000","9.95029","0.00831"
"119.70000","9.97517","0.00847"
"120.00000","10.00022","0.00853"
"120.30000","10.02521","0.00833"
"120.60000","10.05020","0.00821"
"120.90000","10.07519","0.00829"
"121.20000","10.10013","0.00804"
"121.50000","10.12518","0.00812"
"121.80000","10.15017","0.00794"
"122.10000","10.17522","0.00823"
"122.40000","10.20015","0.00840"
"122.70000","10.22527","0.00860"
"123.00000","10.25020","0.00811"
"123.30000","10.27519","0.00904"
"123.60000","10.30024","0.00839"
"123.90000","10.32517","0.00823"
"124.20000","10.35023","0.00849"
"124.50000","10.37516","0.00861"
"124.80000","10.40015","0.00837"
"125.10000","10.42514","0.00830"
"125.40000","10.45019","0.00790"
"125.70000","10.47525","0.00830"
"126.00000","10.50030","0.00875"
"126.30000","10.52523","0.00856"
"126.60000","10.55016","0.00857"
"126.90000","10.57521","0.00818"
"127.20000","10.60015","0.00829"
"127.50000","10.62526","0.00852"
"127.80000","10.65013","0.00847"
"128.10000","10.67518","0.00851"
"128.40000","10.70023","0.00844"
"128.70000","10.72523","0.00859"
"129.00000","10.75022","0.00823"
"129.30000","10.77515","0.00832"
"129.60000","10.80020","0.00796"
"129.90000","10.82514","0.00857"
"130.20000","10.85025","0.00861"
"130.50000","10.87518","0.00853"
"130.80000","10.90023","0.00845"
"131.10000","10.92516","0.00804"
"131.40000","10.95021","0.00790"
"131.70000","10.97521","0.00826"
"132.00000","11.00020","0.00851"
"132.30000","11.02525","0.00848"
"132.60000","11.05018","0.00863"
"132.90000","11.07523","0.00859"
"133.20000","11.10023","0.00839"
"133.50000","11.12522","0.00829"
"133.80000","11.15021","0.00880"
"134.10000","11.17514","0.00894"
"134.40000","11.20019","0.00882"
"134.70000","11.22513","0.00855"
"135.00000","11.25024","0.00891"
"135.30000","11.27517","0.00886"
"135.60000","11.30022","0.00868"
"135.90000","11.32521","0.00906"
"136.20000","11.35027","0.00889"
"136.50000","11.37520","0.00902"
"136.80000","11.40019","0.00871"
"137.10000","11.42524","0.00846"
"137.40000","11.45017","0.00824"
"137.70000","11.47517","0.00853"
"138.00000","11.50016","0.00751"
"138.30000","11.52527","0.00815"
"138.60000","11.55020","0.00803"
"138.90000","11.57525","0.00828"
"139.20000","11.60019","0.00821"
"139.50000","11.62518","0.00799"
"139.80000","11.65023","0.00835"
"140.10000","11.67516","0.00803"
"140.40000","11.70021","0.00807"
"140.70000","11.72515","0.00823"
"141.00000","11.75020","0.00793"
"141.30000","11.77519","0.00822"
"141.60000","11.80024","0.00815"
"141.90000","11.82523","0.00859"
"142.20000","11.85017","0.00762"
"142.50000","11.87522","0.00789"
"142.80000","11.90021","0.00799"
"143.10000","11.92520","0.00755"
"143.40000","11.95019","0.00840"
"143.70000","11.97524","0.00779"
"144.00000","12.00018","0.00764"
"144.30000","12.02517","0.00766"
"144.60000","12.05022","0.00811"
"144.90000","12.07521","0.00829"
"145.20000","12.10027","0.00814"
"145.50000","12.12520","0.00807"
"145.80000","12.15025","0.00813"
"146.10000","12.17518","0.00787"
"146.40000","12.20017","0.00741"
"146.70000","12.22517","0.00834"
"147.00000","12.25016","0.00782"
"147.30000","12.27521","0.00833"
"147.60000","12.30014","0.00754"
"147.90000","12.32519","0.00826"
"148.20000","12.35018","0.00793"
"148.50000","12.37524","0.00823"
"148.80000","12.40017","0.00768"
"149.10000","12.42522","0.00802"
"149.40000","12.45021","0.00864"
"149.70000","12.47521","0.00852"
"150.00000","12.50026","0.00849"
"150.30000","12.52519","0.00789"
"150.60000","12.55018","0.00832"
"150.90000","12.57517","0.00827"
"151.20000","12.60023","0.00811"
"151.50000","12.62522","0.00816"
"151.80000","12.65027","0.00834"
"152.10000","12.67520","0.00807"
"152.40000","12.70019","0.00800"
"152.70000","12.72525","0.00820"
"153.00000","12.75012","0.00816"
"153.30000","12.77523","0.00833"
"153.60000","12.80010","0.00794"
"153.90000","12.82521","0.00823"
"154.20000","12.85009","0.00824"
"154.50000","12.87520","0.00827"
"154.80000","12.90013","0.00824"
"155.10000","12.92518","0.00845"
"155.40000","12.95023","0.00810"
"155.70000","12.97517","0.00862"
"156.00000","13.00022","0.00853"
"156.30000","13.02515","0.00891"
"156.60000","13.05026","0.00820"
"156.90000","13.07519","0.00875"
"157.20000","13.10019","0.00807"
"157.50000","13.12524","0.00857"
"157.80000","13.15023","0.00870"
"158.10000","13.17522","0.00924"
"158.40000","13.20021","0.00843"
"158.70000","13.22526","0.00861"
"159.00000","13.25020","0.00872"
"159.30000","13.27519","0.00904"
"159.60000","13.30012","0.00858"
"159.90000","13.32517","0.00849"
"160.20000","13.35023","0.00848"
"160.50000","13.37516","0.00879"
"160.80000","13.40021","0.00922"
"161.10000","13.42514","0.00930"
"161.40000","13.45019","0.00879"
"161.70000","13.47519","0.00876"
"162.00000","13.50024","0.00858"
"162.30000","13.52523","0.00894"
"162.60000","13.55022","0.00918"
"162.90000","13.57521","0.00912"
"163.20000","13.60021","0.00938"
"163.50000","13.62520","0.00963"
"163.80000","13.65013","0.00857"
"164.10000","13.67524","0.00890"
"164.40000","13.70017","0.00898"
"164.70000","13.72523","0.00928"
"165.00000","13.75022","0.00871"
"165.30000","13.77527","0.00908"
"165.60000","13.80026","0.00879"
"165.90000","13.82519","0.00910"
"166.20000","13.85025","0.00904"
"166.50000","13.87518","0.00985"
"166.80000","13.90023","0.00937"
"167.10000","13.92516","0.00935"
"167.40000","13.95021","0.00948"
"167.70000","13.97520","0.00963"
"168.00000","14.00014","0.00940"
"168.30000","14.02519","0.00975"
"168.60000","14.05024","0.00912"
"168.90000","14.07523","0.00968"
"169.20000","14.10017","0.00976"
"169.50000","14.12522","0.00933"
"169.80000","14.15021","0.00898"
"170.10000","14.17514","0.00951"
"170.40000","14.20019","0.00933"
"170.70000","14.22519","0.00974"
"171.00000","14.25024","0.00963"
"171.30000","14.27517","0.00961"
"171.60000","14.30028","0.00974"
"171.90000","14.32515","0.00970"
"172.20000","14.35027","0.00987"
"172.50000","14.37520","0.00934"
"172.80000","14.40019","0.00971"
"173.10000","14.42518","0.00987"
"173.40000","14.45017","0.00928"
"173.70000","14.47523","0.00959"
"174.00000","14.50016","0.00964"
"174.30000","14.52515","0.00924"
"174.60000","14.55014","0.00969"
"174.90000","14.57519","0.00932"
"175.20000","14.60019","0.00952"
"175.50000","14.62524","0.00951"
"175.80000","14.65023","0.00948"
"176.10000","14.67522","0.00961"
"176.40000","14.70027","0.00942"
"176.70000","14.72515","0.00957"
"177.00000","14.75020","0.00960"
"177.30000","14.77519","0.00938"
"177.60000","14.80024","0.00950"
"177.90000","14.82523","0.00976"
"178.20000","14.85023","0.00948"
"178.50000","14.87528","0.00977"
"178.80000","14.90015","0.00991"
"179.10000","14.92520","0.00983"
"179.40000","14.95019","0.01004"
"179.70000","14.97525","0.00974"
"180.00000","15.00012","0.00979"
"180.30000","15.02517","0.00953"
"180.60000","15.05016","0.00977"
"180.90000","15.07515","0.00939"
"181.20000","15.10021","0.00967"
"181.50000","15.12520","0.01002"
"181.80000","15.15025","0.00994"
"182.10000","15.17518","0.00947"
"182.40000","15.20029","0.00944"
"182.70000","15.22517","0.00969"
"183.00000","15.25016","0.01012"
"183.30000","15.27521","0.01021"
"183.60000","15.30020","0.01016"
"183.90000","15.32519","0.01035"
"184.20000","15.35019","0.01014"
"184.50000","15.37518","0.00986"
"184.80000","15.40017","0.00985"
"185.10000","15.42522","0.01030"
"185.40000","15.45021","0.00993"
"185.70000","15.47521","0.01037"
"186.00000","15.50020","0.01040"
"186.30000","15.52519","0.01013"
"186.60000","15.55018","0.01009"
"186.90000","15.57511","0.00981"
"187.20000","15.60017","0.00973"
"187.50000","15.62510","0.01023"
"187.80000","15.65021","0.01006"
"188.10000","15.67520","0.01027"
"188.40000","15.70019","0.01035"
"188.70000","15.72518","0.01046"
"189.00000","15.75018","0.01034"
"189.30000","15.77523","0.01041"
"189.60000","15.80016","0.01043"
"189.90000","15.82521","0.01040"
"190.20000","15.85009","0.01043"
"190.50000","15.87520","0.01019"
"190.80000","15.90013","0.01052"
"191.10000","15.92518","0.01070"
"191.40000","15.95017","0.01056"
"191.70000","15.97516","0.01081"
"192.00000","16.00022","0.01016"
"192.30000","16.02521","0.01004"
"192.60000","16.05020","0.01074"
"192.90000","16.07519","0.01070"
"193.20000","16.10019","0.01050"
"193.50000","16.12518","0.01059"
"193.80000","16.15011","0.01055"
"194.10000","16.17516","0.01057"
"194.40000","16.20015","0.01077"
"194.70000","16.22527","0.01077"
"195.00000","16.25020","0.01051"
"195.30000","16.27525","0.01023"
"195.60000","16.30018","0.01092"
"195.90000","16.32523","0.01054"
"196.20000","16.35016","0.01065"
"196.50000","16.37522","0.01077"
"196.80000","16.40021","0.01060"
"197.10000","16.42520","0.01026"
"197.40000","16.45019","0.01038"
"197.70000","16.47519","0.00998"
"198.00000","16.50024","0.01034"
"198.30000","16.52517","0.01019"
"198.60000","16.55028","0.01012"
"198.90000","16.57521","0.00970"
"199.20000","16.60020","0.00992"
"199.50000","16.62520","0.01040"
"199.80000","16.65019","0.01076"
"200.10000","16.67518","0.01002"
"200.40000","16.70011","0.01082"
"200.70000","16.72523","0.01030"
"201.00000","16.75016","0.01063"
"201.30000","16.77521","0.01060"
"201.60000","16.80020","0.01027"
"201.90000","16.82525","0.01058"
"202.20000","16.85030","0.01083"
"202.50000","16.87518","0.01049"
"202.80000","16.90023","0.01106"
"203.10000","16.92516","0.00985"
"203.40000","16.95021","0.01038"
"203.70000","16.97520","0.01043"
"204.00000","17.00026","0.01027"
"204.30000","17.02525","0.01039"
"204.60000","17.05018","0.01031"
"204.90000","17.07529","0.01051"
"205.20000","17.10022","0.01063"
"205.50000","17.12522","0.01035"
"205.80000","17.15015","0.01037"
"206.10000","17.17520","0.01049"
"206.40000","17.20013","0.01025"
"206.70000","17.22519","0.01016"
"207.00000","17.25018","0.01036"
"207.30000","17.27517","0.01061"
"207.60000","17.30022","0.01056"
"207.90000","17.32515","0.01006"
"208.20000","17.35020","0.01063"
"208.50000","17.37520","0.01003"
"208.80000","17.40025","0.00973"
"209.10000","17.42518","0.01027"
"209.40000","17.45023","0.01063"
"209.70000","17.47523","0.00986"
"210.00000","17.50016","0.01065"
"210.30000","17.52521","0.01018"
"210.60000","17.55014","0.01051"
"210.90000","17.57513","0.01026"
"211.20000","17.60012","0.01022"
"211.50000","17.62524","0.01029"
"211.80000","17.65023","0.01040"
"212.10000","17.67528","0.01018"
"212.40000","17.70021","0.00991"
"212.70000","17.72520","0.01053"
"213.00000","17.75026","0.01034"
"213.30000","17.77519","0.01030"
"213.60000","17.80024","0.01053"
"213.90000","17.82511","0.01013"
"214.20000","17.85022","0.01000"
"214.50000","17.87516","0.01047"
"214.80000","17.90027","0.01021"
"215.10000","17.92526","0.01062"
"215.40000","17.95019","0.01066"
"215.70000","17.97524","0.01063"
"216.00000","18.00012","0.01043"
"216.30000","18.02523","0.01068"
"216.60000","18.05016","0.01116"
"216.90000","18.07521","0.01099"
"217.20000","18.10021","0.01084"
"217.50000","18.12520","0.01100"
"217.80000","18.15025","0.01099"
"218.10000","18.17524","0.01114"
"218.40000","18.20023","0.01127"
"218.70000","18.22523","0.01124"
"219.00000","18.25022","0.01093"
"219.30000","18.27515","0.01089"
"219.60000","18.30020","0.01125"
"219.90000","18.32519","0.01119"
"220.20000","18.35019","0.01100"
"220.50000","18.37524","0.01096"
"220.80000","18.40017","0.01138"
"221.10000","18.42522","0.01084"
"221.40000","18.45015","0.01152"
"221.70000","18.47526","0.01130"
"222.00000","18.50020","0.01122"
"222.30000","18.52525","0.01132"
"222.60000","18.55024","0.01153"
"222.90000","18.57523","0.01119"
"223.20000","18.60023","0.01098"
"223.50000","18.62516","0.01113"
"223.80000","18.65021","0.01161"
"224.10000","18.67514","0.01148"
"224.40000","18.70025","0.01211"
"224.70000","18.72519","0.01153"
"225.00000","18.75024","0.01152"
"225.30000","18.77517","0.01161"
"225.60000","18.80016","0.01143"
"225.90000","18.82521","0.01136"
"226.20000","18.85021","0.01137"
"226.50000","18.87520","0.01085"
"226.80000","18.90013","0.01150"
"227.10000","18.92518","0.01124"
"227.40000","18.95017","0.01122"
"227.70000","18.97522","0.01139"
"228.00000","19.00022","0.01164"
"228.30000","19.02521","0.01124"
"228.60000","19.05026","0.01181"
"228.90000","19.07519","0.01114"
"229.20000","19.10024","0.01177"
"229.50000","19.12512","0.01171"
"229.80000","19.15023","0.01158"
"230.10000","19.17522","0.01155"
"230.40000","19.20021","0.01187"
"230.70000","19.22520","0.01217"
"231.00000","19.25020","0.01167"
"231.30000","19.27525","0.01143"
"231.60000","19.30018","0.01167"
"231.90000","19.32523","0.01199"
"232.20000","19.35017","0.01207"
"232.50000","19.37522","0.01112"
"232.80000","19.40021","0.01163"
"233.10000","19.42520","0.01155"
"233.40000","19.45025","0.01178"
"233.70000","19.47518","0.01187"
"234.00000","19.50018","0.01202"
"234.30000","19.52517","0.01183"
"234.60000","19.55022","0.01185"
"234.90000","19.57521","0.01168"
"235.20000","19.60026","0.01230"
"235.50000","19.62526","0.01211"
"235.80000","19.65025","0.01198"
"236.10000","19.67524","0.01234"
"236.40000","19.70023","0.01245"
"236.70000","19.72516","0.01237"
"237.00000","19.75010","0.01227"
"237.30000","19.77521","0.01236"
"237.60000","19.80020","0.01246"
"237.90000","19.82519","0.01281"
"238.20000","19.85024","0.01208"
"238.50000","19.87524","0.01282"
"238.80000","19.90023","0.01294"
"239.10000","19.92510","0.01278"
"239.40000","19.95021","0.01292"
"239.70000","19.97515","0.01295"
"240.00000","20.00026","0.01297"
"240.30000","20.02519","0.01256"
"240.60000","20.05018","0.01325"
"240.90000","20.07517","0.01311"
"241.20000","20.10016","0.01323"
"241.50000","20.12522","0.01359"
"241.80000","20.15021","0.01301"
"242.10000","20.17520","0.01271"
"242.40000","20.20013","0.01277"
"242.70000","20.22525","0.01294"
"243.00000","20.25018","0.01333"
"243.30000","20.27523","0.01285"
"243.60000","20.30016","0.01305"
"243.90000","20.32521","0.01335"
"244.20000","20.35020","0.01336"
"244.50000","20.37520","0.01302"
"244.80000","20.40025","0.01314"
"245.10000","20.42518","0.01337"
"245.40000","20.45017","0.01326"
"245.70000","20.47517","0.01354"
"246.00000","20.50016","0.01385"
"246.30000","20.52521","0.01382"
"246.60000","20.55014","0.01338"
"246.90000","20.57519","0.01368"
"247.20000","20.60012","0.01351"
"247.50000","20.62518","0.01365"
"247.80000","20.65017","0.01380"
"248.10000","20.67522","0.01404"
"248.40000","20.70021","0.01380"
"248.70000","20.72521","0.01417"
"249.00000","20.75026","0.01422"
"249.30000","20.77519","0.01435"
"249.60000","20.80018","0.01397"
"249.90000","20.82511","0.01393"
"250.20000","20.85022","0.01444"
"250.50000","20.87516","0.01421"
"250.80000","20.90021","0.01463"
"251.10000","20.92520","0.01422"
"251.40000","20.95025","0.01429"
"251.70000","20.97518","0.01439"
"252.00000","21.00018","0.01435"
"252.30000","21.02523","0.01471"
"252.60000","21.05016","0.01474"
"252.90000","21.07521","0.01469"
"253.20000","21.10020","0.01487"
"253.50000","21.12520","0.01514"
"253.80000","21.15019","0.01492"
"254.10000","21.17518","0.01496"
"254.40000","21.20023","0.01514"
"254.70000","21.22523","0.01516"
"255.00000","21.25021","0.01482"
"255.30000","21.27515","0.01512"
"255.60000","21.30020","0.01517"
"255.90000","21.32519","0.01549"
"256.20000","21.35018","0.01514"
"256.50000","21.37518","0.01546"
"256.80000","21.40023","0.01529"
"257.10000","21.42522","0.01548"
"257.40000","21.45015","0.01533"
"257.70000","21.47527","0.01574"
"258.00000","21.50020","0.01566"
"258.30000","21.52525","0.01573"
"258.60000","21.55018","0.01588"
"258.90000","21.57523","0.01599"
"259.20000","21.60022","0.01578"
"259.50000","21.62516","0.01582"
"259.80000","21.65015","0.01624"
"260.10000","21.67514","0.01605"
"260.40000","21.70019","0.01620"
"260.70000","21.72513","0.01620"
"261.00000","21.75024","0.01642"
"261.30000","21.77517","0.01636"
"261.60000","21.80022","0.01623"
"261.90000","21.82521","0.01631"
"262.20000","21.85020","0.01648"
"262.50000","21.87526","0.01693"
"262.80000","21.90013","0.01685"
"263.10000","21.92518","0.01696"
"263.40000","21.95017","0.01712"
"263.70000","21.97523","0.01684"
"264.00000","22.00022","0.01699"
"264.30000","22.02521","0.01731"
"264.60000","22.05026","0.01691"
"264.90000","22.07519","0.01710"
"265.20000","22.10025","0.01717"
"265.50000","22.12518","0.01708"
"265.80000","22.15023","0.01710"
"266.10000","22.17516","0.01754"
"266.40000","22.20021","0.01746"
"266.70000","22.22515","0.01747"
"267.00000","22.25014","0.01795"
"267.30000","22.27525","0.01814"
"267.60000","22.30018","0.01717"
"267.90000","22.32523","0.01763"
"268.20000","22.35017","0.01785"
"268.50000","22.37522","0.01819"
"268.80000","22.40021","0.01787"
"269.10000","22.42520","0.01802"
"269.40000","22.45019","0.01831"
"269.70000","22.47518","0.01819"
"270.00000","22.50018","0.01813"
"270.30000","22.52511","0.01832"
"270.60000","22.55016","0.01836"
"270.90000","22.57515","0.01863"
"271.20000","22.60020","0.01831"
"271.50000","22.62520","0.01844"
"271.80000","22.65025","0.01901"
"272.10000","22.67518","0.01909"
"272.40000","22.70017","0.01913"
"272.70000","22.72522","0.01900"
"273.00000","22.75010","0.01912"
"273.30000","22.77515","0.01926"
"273.60000","22.80014","0.01926"
"273.90000","22.82525","0.01943"
"274.20000","22.85019","0.01977"
"274.50000","22.87524","0.01967"
"274.80000","22.90023","0.01979"
"275.10000","22.92522","0.01966"
"275.40000","22.95027","0.02011"
"275.70000","22.97514","0.02038"
"276.00000","23.00026","0.02019"
"276.30000","23.02519","0.02073"
"276.60000","23.05024","0.02050"
"276.90000","23.07517","0.02119"
"277.20000","23.10023","0.02095"
"277.50000","23.12522","0.02134"
"277.80000","23.15015","0.02116"
"278.10000","23.17526","0.02135"
"278.40000","23.20019","0.02147"
"278.70000","23.22524","0.02195"
"279.00000","23.25018","0.02214"
"279.30000","23.27523","0.02185"
"279.60000","23.30016","0.02240"
"279.90000","23.32515","0.02246"
"280.20000","23.35020","0.02283"
"280.50000","23.37519","0.02304"
"280.80000","23.40025","0.02352"
"281.10000","23.42518","0.02298"
"281.40000","23.45023","0.02431"
"281.70000","23.47516","0.02375"
"282.00000","23.50022","0.02412"
"282.30000","23.52521","0.02414"
"282.60000","23.55020","0.02439"
"282.90000","23.57525","0.02454"
"283.20000","23.60012","0.02501"
"283.50000","23.62523","0.02509"
"283.80000","23.65017","0.02526"
"284.10000","23.67522","0.02616"
"284.40000","23.70021","0.02590"
"284.70000","23.72527","0.02600"
"285.00000","23.75020","0.02654"
"285.30000","23.77519","0.02697"
"285.60000","23.80024","0.02571"
"285.90000","23.82523","0.02547"
"286.20000","23.85016","0.02670"
"286.50000","23.87515","0.02648"
"286.80000","23.90021","0.02669"
"287.10000","23.92514","0.02725"
"287.40000","23.95019","0.02718"
"287.70000","23.97518","0.02764"
"288.00000","24.00024","0.02799"
"288.30000","24.02529","0.02841"
"288.60000","24.05016","0.02817"
"288.90000","24.07521","0.02913"
"289.20000","24.10014","0.02944"
"289.50000","24.12526","0.02940"
"289.80000","24.15019","0.02967"
"290.10000","24.17518","0.02994"
"290.40000","24.20023","0.03044"
"290.70000","24.22516","0.03015"
"291.00000","24.25028","0.03107"
"291.30000","24.27521","0.03143"
"291.60000","24.30026","0.03187"
"291.90000","24.32513","0.03222"
"292.20000","24.35024","0.03282"
"292.50000","24.37518","0.03275"
"292.80000","24.40023","0.03350"
"293.10000","24.42522","0.03346"
"293.40000","24.45015","0.03424"
"293.70000","24.47520","0.03458"
"294.00000","24.50019","0.03484"
"294.30000","24.52525","0.03582"
"294.60000","24.55018","0.03574"
"294.90000","24.57523","0.03609"
"295.20000","24.60023","0.03652"
"295.50000","24.62522","0.03758"
"295.80000","24.65015","0.03788"
"296.10000","24.67514","0.03919"
"296.40000","24.70025","0.03922"
"296.70000","24.72518","0.04007"
"297.00000","24.75023","0.04026"
"297.30000","24.77517","0.04103"
"297.60000","24.80022","0.04164"
"297.90000","24.82521","0.04205"
"298.20000","24.85020","0.04230"
"298.50000","24.87520","0.04318"
"298.80000","24.90019","0.04367"
"299.10000","24.92524","0.04468"
"299.40000","24.95017","0.04488"
"299.70000","24.97522","0.04209"
"300.00000","25.00015","0.04067"
"300.30000","25.02521","0.04057"
"300.60000","25.05020","0.04108"
"300.90000","25.07519","0.04258"
"301.20000","25.10024","0.04125"
"301.50000","25.12518","0.04317"
"301.80000","25.15023","0.04320"
"302.10000","25.17516","0.04325"
"302.40000","25.20021","0.04141"
"302.70000","25.22514","0.04140"
"303.00000","25.25019","0.04138"
"303.30000","25.27519","0.04241"
"303.60000","25.30018","0.04252"
"303.90000","25.32523","0.04347"
"304.20000","25.35022","0.04297"
"304.50000","25.37522","0.04103"
"304.80000","25.40021","0.04063"
"305.10000","25.42526","0.04204"
"305.40000","25.45013","0.04173"
"305.70000","25.47518","0.04309"
"306.00000","25.50024","0.04499"
"306.30000","25.52517","0.04402"
"306.60000","25.55016","0.04587"
"306.90000","25.57515","0.04632"
"307.20000","25.60027","0.04758"
"307.50000","25.62519","0.04854"
"307.80000","25.65025","0.04894"
"308.10000","25.67518","0.04924"
"308.40000","25.70023","0.04960"
"308.70000","25.72523","0.05028"
"309.00000","25.75022","0.05120"
"309.30000","25.77521","0.05177"
"309.60000","25.80020","0.05281"
"309.90000","25.82525","0.05307"
"310.20000","25.85012","0.05450"
"310.50000","25.87523","0.05491"
"310.80000","25.90017","0.05567"
"311.10000","25.92528","0.05581"
"311.40000","25.95021","0.05693"
"311.70000","25.97515","0.05766"
"312.00000","26.00020","0.05847"
"312.30000","26.02519","0.05889"
"312.60000","26.05018","0.05932"
"312.90000","26.07511","0.06007"
"313.20000","26.10017","0.06062"
"313.50000","26.12515","0.06112"
"313.80000","26.15015","0.06176"
"314.10000","26.17520","0.06270"
"314.40000","26.20019","0.06292"
"314.70000","26.22524","0.06392"
"315.00000","26.25018","0.06496"
"315.30000","26.27523","0.06550"
"315.60000","26.30016","0.06674"
"315.90000","26.32521","0.06732"
"316.20000","26.35021","0.06806"
"316.50000","26.37514","0.03419"
"316.80000","26.40019","0.03074"
"317.10000","26.42518","0.03572"
"317.40000","26.45023","0.02902"
"317.70000","26.47516","0.03630"
"318.00000","26.50022","0.03220"
"318.30000","26.52515","0.03253"
"318.60000","26.55020","0.03534"
"318.90000","26.57519","0.03276"
"319.20000","26.60018","0.03658"
"319.50000","26.62518","0.03592"
"319.80000","26.65017","0.03638"
"320.10000","26.67522","0.03799"
"320.40000","26.70015","0.03609"
"320.70000","26.72526","0.03897"
"321.00000","26.75020","0.03808"
"321.30000","26.77519","0.03832"
"321.60000","26.80018","0.04045"
"321.90000","26.82523","0.03919"
"322.20000","26.85028","0.04142"
"322.50000","26.87516","0.04263"
"322.80000","26.90021","0.04216"
"323.10000","26.92514","0.04419"
"323.40000","26.95019","0.04427"
"323.70000","26.97518","0.04492"
"324.00000","27.00023","0.04619"
"324.30000","27.02523","0.04561"
"324.60000","27.05022","0.04674"
"324.90000","27.07521","0.04774"
"325.20000","27.10020","0.04799"
"325.50000","27.12520","0.04833"
"325.80000","27.15019","0.04846"
"326.10000","27.17518","0.05011"
"326.40000","27.20011","0.05034"
"326.70000","27.22522","0.05070"
"327.00000","27.25022","0.05128"
"327.30000","27.27521","0.05235"
"327.60000","27.30026","0.05255"
"327.90000","27.32519","0.05279"
"328.20000","27.35024","0.05348"
"328.50000","27.37518","0.05407"
"328.80000","27.40023","0.05474"
"329.10000","27.42516","0.05567"
"329.40000","27.45021","0.05601"
"329.70000","27.47520","0.05747"
"330.00000","27.50019","0.05810"
"330.30000","27.52525","0.05789"
"330.60000","27.55024","0.05834"
"330.90000","27.57523","0.05811"
"331.20000","27.60023","0.05910"
"331.50000","27.62515","0.05924"
"331.80000","27.65015","0.06002"
"332.10000","27.67514","0.06096"
"332.40000","27.70019","0.06146"
"332.70000","27.72518","0.06160"
"333.00000","27.75024","0.06292"
"333.30000","27.77517","0.06361"
"333.60000","27.80022","0.06377"
"333.90000","27.82515","0.06411"
"334.20000","27.85020","0.06474"
"334.50000","27.87520","0.06585"
"334.80000","27.90025","0.06651"
"335.10000","27.92524","0.06710"
"335.40000","27.95017","0.06808"
"335.70000","27.97523","0.06915"
"336.00000","28.00016","0.06975"
"336.30000","28.02521","0.07103"
"336.60000","28.05020","0.07084"
"336.90000","28.07525","0.07159"
"337.20000","28.10018","0.07209"
"337.50000","28.12524","0.07393"
"337.80000","28.15023","0.07564"
"338.10000","28.17516","0.07647"
"338.40000","28.20021","0.07852"
"338.70000","28.22515","0.07987"
"339.00000","28.25020","0.07797"
"339.30000","28.27513","0.07849"
"339.60000","28.30018","0.07617"
"339.90000","28.32523","0.07830"
"340.20000","28.35016","0.07861"
"340.50000","28.37522","0.07945"
"340.80000","28.40015","0.08079"
"341.10000","28.42520","0.08245"
"341.40000","28.45019","0.08311"
"341.70000","28.47519","0.08583"
"342.00000","28.50018","0.08732"
"342.30000","28.52517","0.08898"
"342.60000","28.55022","0.09068"
"342.90000","28.57515","0.09136"
"343.20000","28.60026","0.09314"
"343.50000","28.62514","0.09402"
"343.80000","28.65025","0.09554"
"344.10000","28.67518","0.09639"
"344.40000","28.70023","0.09751"
"344.70000","28.72516","0.09845"
"345.00000","28.75022","0.09936"
"345.30000","28.77521","0.09924"
"345.60000","28.80020","0.10028"
"345.90000","28.82519","0.10013"
"346.20000","28.85019","0.10137"
"346.50000","28.87518","0.10209"
"346.80000","28.90011","0.10271"
"347.10000","28.92522","0.10337"
"347.40000","28.95021","0.10379"
"347.70000","28.97526","0.10474"
"348.00000","29.00019","0.10520"
"348.30000","29.02519","0.10593"
"348.60000","29.05024","0.10634"
"348.90000","29.07511","0.10705"
"349.20000","29.10016","0.10760"
"349.50000","29.12516","0.10816"
"349.80000","29.15021","0.10869"
"350.10000","29.17520","0.10952"
"350.40000","29.20025","0.11012"
"350.70000","29.22524","0.11118"
"351.00000","29.25018","0.11226"
"351.30000","29.27523","0.11343"
"351.60000","29.30016","0.11488"
"351.90000","29.32521","0.11621"
"352.20000","29.35015","0.11776"
"352.50000","29.37520","0.12006"
"352.80000","29.40013","0.12070"
"353.10000","29.42518","0.12338"
"353.40000","29.45017","0.12520"
"353.70000","29.47517","0.12812"
"354.00000","29.50022","0.13018"
"354.30000","29.52515","0.13248"
"354.60000","29.55026","0.13484"
"354.90000","29.57519","0.13699"
"355.20000","29.60018","0.14098"
"355.50000","29.62518","0.14376"
"355.80000","29.65017","0.14622"
"356.10000","29.67522","0.14987"
"356.40000","29.70015","0.15141"
"356.70000","29.72520","0.15436"
"357.00000","29.75020","0.15610"
"357.30000","29.77525","0.15899"
"357.60000","29.80018","0.16062"
"357.90000","29.82523","0.16252"
"358.20000","29.85023","0.16488"
"358.50000","29.87516","0.16633"
"358.80000","29.90021","0.16742"
"359.10000","29.92514","0.16764"
"359.40000","29.95019","0.16908"
"359.70000","29.97506","0.17042"
"360.00000","30.00024","0.17165"
"360.30000","30.02523","0.17249"
"360.60000","30.05028","0.17425"
"360.90000","30.07527","0.17554"
"361.20000","30.10021","0.17754"
"361.50000","30.12526","0.17928"
"361.80000","30.15019","0.18082"
"362.10000","30.17524","0.18293"
"362.40000","30.20011","0.18500"
"362.70000","30.22523","0.18639"
"363.00000","30.25016","0.18819"
"363.30000","30.27521","0.19039"
"363.60000","30.30020","0.19193"
"363.90000","30.32519","0.19451"
"364.20000","30.35025","0.19619"
"364.50000","30.37518","0.19817"
"364.80000","30.40023","0.20049"
"365.10000","30.42516","0.20197"
"365.40000","30.45021","0.20421"
"365.70000","30.47520","0.20580"
"366.00000","30.50014","0.20710"
"366.30000","30.52519","0.20841"
"366.60000","30.55018","0.20902"
"366.90000","30.57523","0.21055"
"367.20000","30.60017","0.21181"
"367.50000","30.62522","0.21303"
"367.80000","30.65021","0.21398"
"368.10000","30.67520","0.21479"
"368.40000","30.70019","0.21605"
"368.70000","30.72519","0.21727"
"369.00000","30.75024","0.21831"
"369.30000","30.77517","0.21955"
"369.60000","30.80022","0.22157"
"369.90000","30.82515","0.22274"
"370.20000","30.85021","0.22447"
"370.50000","30.87520","0.22574"
"370.80000","30.90025","0.22776"
"371.10000","30.92524","0.22851"
"371.40000","30.95023","0.23049"
"371.70000","30.97522","0.23254"
"372.00000","31.00016","0.23445"
"372.30000","31.02515","0.23581"
"372.60000","31.05008","0.23883"
"372.90000","31.07519","0.24075"
"373.20000","31.10019","0.24290"
"373.50000","31.12524","0.24488"
"373.80000","31.15023","0.24740"
"374.10000","31.17522","0.24890"
"374.40000","31.20021","0.25103"
"374.70000","31.22514","0.25252"
"375.00000","31.25019","0.25437"
"375.30000","31.27519","0.25636"
"375.60000","31.30018","0.25786"
"375.90000","31.32517","0.24903"
"376.20000","31.35016","0.23205"
"376.50000","31.37521","0.23416"
"376.80000","31.40021","0.23324"
"377.10000","31.42520","0.23335"
"377.40000","31.45013","0.23570"
"377.70000","31.47524","0.23767"
"378.00000","31.50018","0.12071"
"378.30000","31.52523","0.10684"
"378.60000","31.55022","0.11241"
"378.90000","31.57521","0.10750"
"379.20000","31.60020","0.10892"
"379.50000","31.62519","0.11120"
"379.80000","31.65018","0.10760"
"380.10000","31.67518","0.11327"
"380.40000","31.70023","0.10974"
"380.70000","31.72516","0.11015"
"381.00000","31.75021","0.11427"
"381.30000","31.77521","0.10947"
"381.60000","31.80026","0.11388"
"381.90000","31.82519","0.11292"
"382.20000","31.85018","0.11160"
"382.50000","31.87523","0.11669"
"382.80000","31.90023","0.11269"
"383.10000","31.92516","0.11516"
"383.40000","31.95015","0.11660"
"383.70000","31.97526","0.11403"
"384.00000","32.00026","0.11834"
"384.30000","32.02525","-0.00446"
"384.60000","32.05024","0.01459"
"384.90000","32.07517","0.00556"
"385.20000","32.10016","0.00533"
"385.50000","32.12516","0.00719"
"385.80000","32.15026","0.00814"
"386.10000","32.17520","0.00585"
"386.40000","32.20019","0.00605"
"386.70000","32.22524","0.01143"
"387.00000","32.25023","0.00585"
"387.30000","32.27523","0.00604"
"387.60000","32.30022","0.00837"
"387.90000","32.32521","0.00665"
"388.20000","32.35014","0.00559"
"388.50000","32.37526","0.00650"
"388.80000","32.40019","0.00835"
"389.10000","32.42518","0.00609"
"389.40000","32.45017","0.00594"
"389.70000","32.47522","0.00940"
"390.00000","32.50021","0.00618"
"390.30000","32.52515","0.00592"
"390.60000","32.55025","0.00845"
"390.90000","32.57519","0.00682"
"391.20000","32.60024","0.00570"
"391.50000","32.62518","0.00774"
"391.80000","32.65017","0.00722"
"392.10000","32.67522","0.00675"
"392.40000","32.70015","0.00730"
"392.70000","32.72520","0.00799"
"393.00000","32.75013","0.00650"
"393.30000","32.77525","0.00679"
"393.60000","32.80018","0.00784"
"393.90000","32.82523","0.00642"
"394.20000","32.85016","0.00691"
"394.50000","32.87521","0.00811"
"394.80000","32.90021","0.00700"
"395.10000","32.92520","0.00635"
"395.40000","32.95025","0.00744"
"395.70000","32.97518","0.00642"
"396.00000","33.00023","0.00705"
"396.30000","33.02517","0.00715"
"396.60000","33.05028","0.00670"
"396.90000","33.07521","0.00636"
"397.20000","33.10020","0.00707"
"397.50000","33.12514","0.00705"
"397.80000","33.15012","0.00727"
"398.10000","33.17518","0.00747"
"398.40000","33.20017","0.00740"
"398.70000","33.22522","0.00760"
"399.00000","33.25015","0.00727"
"399.30000","33.27521","0.00708"
"399.60000","33.30020","0.00775"
"399.90000","33.32519","0.00722"
"400.20000","33.35024","0.00729"
"400.50000","33.37518","0.00716"
"400.80000","33.40023","0.00758"
"401.10000","33.42522","0.00733"
"401.40000","33.45021","0.00736"
"401.70000","33.47520","0.00732"
"402.00000","33.50019","0.00768"
"402.30000","33.52519","0.00741"
"402.60000","33.55018","0.00709"
"402.90000","33.57523","0.00731"
"403.20000","33.60016","0.00793"
"403.50000","33.62521","0.00764"
"403.80000","33.65015","0.00724"
"404.10000","33.67526","0.00717"
"404.40000","33.70019","0.00765"
"404.70000","33.72518","0.00745"
"405.00000","33.75017","0.00760"
"405.30000","33.77523","0.00761"
"405.60000","33.80022","0.00773"
"405.90000","33.82515","0.00773"
"406.20000","33.85020","0.00778"
"406.50000","33.87513","0.00829"
"406.80000","33.90025","0.00764"
"407.10000","33.92518","0.00783"
"407.40000","33.95023","0.00776"
"407.70000","33.97522","0.00818"
"408.00000","34.00016","0.00773"
"408.30000","34.02527","0.00778"
"408.60000","34.05020","0.00794"
"408.90000","34.07519","0.00790"
"409.20000","34.10012","0.00768"
"409.50000","34.12524","0.00798"
"409.80000","34.15017","0.00824"
"410.10000","34.17522","0.00782"
"410.40000","34.20021","0.00800"
"410.70000","34.22514","0.00812"
"411.00000","34.25026","0.00852"
"411.30000","34.27518","0.00776"
"411.60000","34.30024","0.00849"
"411.90000","34.32511","0.00813"
"412.20000","34.35016","0.00811"
"412.50000","34.37510","0.00855"
"412.80000","34.40015","0.00880"
"413.10000","34.42520","0.00864"
"413.40000","34.45019","0.00860"
"413.70000","34.47524","0.00839"
"414.00000","34.50018","0.00856"
"414.30000","34.52523","0.00851"
"414.60000","34.55016","0.00855"
"414.90000","34.57521","0.00877"
"415.20000","34.60014","0.00915"
"415.50000","34.62519","0.00812"
"415.80000","34.65019","0.00883"
"416.10000","34.67518","0.00871"
"416.40000","34.70023","0.00897"
"416.70000","34.72522","0.00878"
"417.00000","34.75027","0.00872"
"417.30000","34.77520","0.00843"
"417.60000","34.80014","0.00910"
"417.90000","34.82519","0.00929"
"418.20000","34.85019","0.00897"
"418.50000","34.87523","0.00938"
"418.80000","34.90017","0.00875"
"419.10000","34.92516","0.00904"
"419.40000","34.95015","0.00918"
"419.70000","34.97520","0.00900"
"420.00000","35.00019","0.00912"
"420.30000","35.02525","0.00946"
"420.60000","35.05024","0.00923"
"420.90000","35.07517","0.00941"
"421.20000","35.10022","0.00919"
"421.50000","35.12516","0.00868"
"421.80000","35.15021","0.00939"
"422.10000","35.17514","0.00916"
"422.40000","35.20025","0.00947"
"422.70000","35.22518","0.00930"
"423.00000","35.25018","0.00948"
"423.30000","35.27522","0.00972"
"423.60000","35.30022","0.00941"
"423.90000","35.32521","0.00922"
"424.20000","35.35014","0.01009"
"424.50000","35.37526","0.00979"
"424.80000","35.40018","0.00904"
"425.10000","35.42518","0.00977"
"425.40000","35.45017","0.00970"
"425.70000","35.47522","0.00988"
"426.00000","35.50021","0.01008"
"426.30000","35.52521","0.00998"
"426.60000","35.55026","0.00997"
"426.90000","35.57519","0.00974"
"427.20000","35.60018","0.00994"
"427.50000","35.62518","0.00991"
"427.80000","35.65023","0.00992"
"428.10000","35.67516","0.01037"
"428.40000","35.70015","0.00990"
"428.70000","35.72514","0.01024"
"429.00000","35.75019","0.01054"
"429.30000","35.77519","0.01040"
"429.60000","35.80018","0.01028"
"429.90000","35.82523","0.01043"
"430.20000","35.85016","0.01014"
"430.50000","35.87522","0.01065"
"430.80000","35.90015","0.01066"
"431.10000","35.92520","0.01046"
"431.40000","35.95019","0.01034"
"431.70000","35.97519","0.01028"
"432.00000","36.00017","0.01063"
"432.30000","36.02517","0.01048"
"432.60000","36.05022","0.01046"
"432.90000","36.07515","0.01080"
"433.20000","36.10020","0.01068"
"433.50000","36.12519","0.01079"
"433.80000","36.15019","0.01110"
"434.10000","36.17518","0.01045"
"434.40000","36.20017","0.01095"
"434.70000","36.22522","0.01015"
"435.00000","36.25016","0.01048"
"435.30000","36.27521","0.01110"
"435.60000","36.30014","0.01080"
"435.90000","36.32519","0.01131"
"436.20000","36.35024","0.01085"
"436.50000","36.37524","0.01108"
"436.80000","36.40028","0.01084"
"437.10000","36.42516","0.01140"
"437.40000","36.45021","0.01101"
"437.70000","36.47514","0.01117"
"438.00000","36.50019","0.01147"
"438.30000","36.52513","0.01136"
"438.60000","36.55018","0.01145"
"438.90000","36.57517","0.01171"
"439.20000","36.60016","0.01120"
"439.50000","36.62515","0.01163"
"439.80000","36.65021","0.01177"
"440.10000","36.67526","0.01179"
"440.40000","36.70019","0.01192"
"440.70000","36.72524","0.01165"
"441.00000","36.75018","0.01196"
"441.30000","36.77517","0.01190"
"441.60000","36.80022","0.01179"
"441.90000","36.82521","0.01193"
"442.20000","36.85020","0.01250"
"442.50000","36.87519","0.01258"
"442.80000","36.90018","0.01222"
"443.10000","36.92518","0.01223"
"443.40000","36.95023","0.01225"
"443.70000","36.97522","0.01218"
"444.00000","37.00021","0.01245"
"444.30000","37.02521","0.01264"
"444.60000","37.05020","0.01241"
"444.90000","37.07525","0.01210"
"445.20000","37.10012","0.01238"
"445.50000","37.12518","0.01237"
"445.80000","37.15011","0.01296"
"446.10000","37.17522","0.01258"
"446.40000","37.20021","0.01259"
"446.70000","37.22520","0.01298"
"447.00000","37.25019","0.01269"
"447.30000","37.27519","0.01272"
"447.60000","37.30024","0.01281"
"447.90000","37.32517","0.01286"
"448.20000","37.35022","0.01312"
"448.50000","37.37510","0.01332"
"448.80000","37.40020","0.01340"
"449.02000","37.41850","0.01308"