File: Force_trajectories/161226_2/Specimen_RawData_3.csv
End date,"12/26/2016"
Specimen label,"11BG_81_2_run2"
Maximum Load,"0.05442",N

Time,Extension,Load
(s),(mm),(N)
"0.00000","35.15104","0.01063"
"0.15000","35.15870","0.01059"
"0.30000","35.17514","0.01038"
"0.45000","35.18883","0.01042"
"0.60000","35.20127","0.01061"
"0.75000","35.21376","0.01072"
"0.90000","35.22620","0.01067"
"1.05000","35.23869","0.01107"
"1.20000","35.25125","0.01077"
"1.35000","35.26381","0.01078"
"1.50000","35.27618","0.01100"
"1.65000","35.28874","0.01065"
"1.80000","35.30129","0.01082"
"1.95000","35.31373","0.01078"
"2.10000","35.32623","0.01105"
"2.25000","35.33872","0.01106"
"2.40000","35.35128","0.01108"
"2.55000","35.36366","0.01145"
"2.70000","35.37615","0.01088"
"2.85000","35.38871","0.01142"
"3.00000","35.40120","0.01118"
"3.15000","35.41364","0.01115"
"3.30000","35.42620","0.01182"
"3.45000","35.43869","0.01136"
"3.60000","35.45125","0.01148"
"3.75000","35.46368","0.01127"
"3.90000","35.47624","0.01145"
"4.05000","35.48868","0.01139"
"4.20000","35.50123","0.01171"
"4.35000","35.51373","0.01155"
"4.50000","35.52622","0.01158"
"4.65000","35.53872","0.01140"
"4.80000","35.55116","0.01126"
"4.95000","35.56371","0.01153"
"5.10000","35.57621","0.01182"
"5.25000","35.58870","0.01196"
"5.40000","35.60126","0.01176"
"5.55000","35.61376","0.01166"
"5.70000","35.62619","0.01182"
"5.85000","35.63869","0.01198"
"6.00000","35.65118","0.01209"
"6.15000","35.66368","0.01198"
"6.30000","35.67617","0.01212"
"6.45000","35.68861","0.01220"
"6.60000","35.70123","0.01243"
"6.75000","35.71372","0.01235"
"6.90000","35.72616","0.01249"
"7.05000","35.73871","0.01265"
"7.20000","35.75121","0.01267"
"7.35000","35.76365","0.01307"
"7.50000","35.77608","0.01259"
"7.65000","35.78870","0.01286"
"7.80000","35.80119","0.01248"
"7.95000","35.81369","0.01285"
"8.10000","35.82619","0.01267"
"8.25000","35.83874","0.01318"
"8.40000","35.85118","0.01342"
"8.55000","35.86362","0.01308"
"8.70000","35.87617","0.01328"
"8.85000","35.88873","0.01304"
"9.00000","35.90116","0.01305"
"9.15000","35.91366","0.01367"
"9.30000","35.92627","0.01326"
"9.45000","35.93871","0.01357"
"9.60000","35.95115","0.01358"
"9.75000","35.96364","0.01337"
"9.90000","35.97620","0.01372"
"10.05000","35.98864","0.01335"
"10.20000","36.00113","0.01384"
"10.35000","36.01369","0.01420"
"10.50000","36.02624","0.01424"
"10.65000","36.03868","0.01370"
"10.80000","36.05118","0.01423"
"10.95000","36.06367","0.01449"
"11.10000","36.07623","0.01415"
"11.25000","36.08867","0.01420"
"11.40000","36.10122","0.01447"
"11.55000","36.11372","0.01410"
"11.70000","36.12621","0.01428"
"11.85000","36.13871","0.01474"
"12.00000","36.15126","0.01470"
"12.15000","36.16370","0.01495"
"12.30000","36.17619","0.01483"
"12.45000","36.18869","0.01496"
"12.60000","36.20119","0.01492"
"12.75000","36.21368","0.01514"
"12.90000","36.22612","0.01520"
"13.05000","36.23874","0.01505"
"13.20000","36.25117","0.01533"
"13.35000","36.26367","0.01551"
"13.50000","36.27616","0.01562"
"13.65000","36.28872","0.01524"
"13.80000","36.30116","0.01546"
"13.95000","36.31365","0.01607"
"14.10000","36.32621","0.01593"
"14.25000","36.33876","0.01565"
"14.40000","36.35120","0.01585"
"14.55000","36.36369","0.01539"
"14.70000","36.37625","0.01585"
"14.85000","36.38875","0.01575"
"15.00000","36.40118","0.01583"
"15.15000","36.41374","0.01610"
"15.30000","36.42617","0.01596"
"15.45000","36.43873","0.01601"
"15.60000","36.45117","0.01600"
"15.75000","36.46372","0.01617"
"15.90000","36.47616","0.01672"
"16.05000","36.48866","0.01628"
"16.20000","36.50121","0.01628"
"16.35000","36.51377","0.01668"
"16.50000","36.52620","0.01648"
"16.65000","36.53864","0.01660"
"16.80000","36.55120","0.01648"
"16.95000","36.56369","0.01669"
"17.10000","36.57619","0.01712"
"17.25000","36.58868","0.01677"
"17.40000","36.60124","0.01705"
"17.55000","36.61368","0.01640"
"17.70000","36.62617","0.01667"
"17.85000","36.63866","0.01734"
"18.00000","36.65122","0.01683"
"18.15000","36.66372","0.01678"
"18.30000","36.67621","0.01697"
"18.45000","36.68877","0.01740"
"18.60000","36.70127","0.01711"
"18.75000","36.71370","0.01706"
"18.90000","36.72620","0.01742"
"19.05000","36.73869","0.01747"
"19.20000","36.75119","0.01760"
"19.35000","36.76369","0.01762"
"19.50000","36.77625","0.01762"
"19.65000","36.78874","0.01762"
"19.80000","36.80124","0.01768"
"19.95000","36.81373","0.01846"
"20.10000","36.82617","0.01817"
"20.25000","36.83872","0.01869"
"20.40000","36.85110","0.01817"
"20.55000","36.86372","0.01828"
"20.70000","36.87621","0.01821"
"20.85000","36.88871","0.01832"
"21.00000","36.90114","0.01866"
"21.15000","36.91376","0.01851"
"21.30000","36.92619","0.01876"
"21.45000","36.93869","0.01906"
"21.60000","36.95119","0.01908"
"21.75000","36.96374","0.01914"
"21.90000","36.97624","0.01934"
"22.05000","36.98874","0.01976"
"22.20000","37.00129","0.01934"
"22.35000","37.01367","0.01925"
"22.50000","37.02617","0.01952"
"22.65000","37.03866","0.01972"
"22.80000","37.05122","0.01951"
"22.95000","37.06365","0.02033"
"23.10000","37.07615","0.02005"
"23.25000","37.08870","0.01995"
"23.40000","37.10120","0.02058"
"23.55000","37.11364","0.02052"
"23.70000","37.12619","0.02009"
"23.85000","37.13874","0.02097"
"24.00000","37.15125","0.02044"
"24.15000","37.16368","0.02086"
"24.30000","37.17624","0.02138"
"24.45000","37.18873","0.02122"
"24.60000","37.20123","0.02127"
"24.75000","37.21372","0.02135"
"24.90000","37.22628","0.02136"
"25.05000","37.23871","0.02151"
"25.20000","37.25115","0.02166"
"25.35000","37.26371","0.02223"
"25.50000","37.27620","0.02210"
"25.65000","37.28870","0.02231"
"25.80000","37.30114","0.02254"
"25.95000","37.31375","0.02231"
"26.10000","37.32625","0.02245"
"26.25000","37.33868","0.02207"
"26.40000","37.35118","0.02257"
"26.55000","37.36374","0.02282"
"26.70000","37.37617","0.02283"
"26.85000","37.38861","0.02339"
"27.00000","37.40116","0.02334"
"27.15000","37.41372","0.02365"
"27.30000","37.42616","0.02364"
"27.45000","37.43871","0.02354"
"27.60000","37.45121","0.02314"
"27.75000","37.46370","0.02330"
"27.90000","37.47614","0.02357"
"28.05000","37.48870","0.02253"
"28.20000","37.50119","0.02310"
"28.35000","37.51369","0.02327"
"28.50000","37.52618","0.02319"
"28.65000","37.53868","0.02331"
"28.80000","37.55117","0.02321"
"28.95000","37.56361","0.02339"
"29.10000","37.57617","0.02435"
"29.25000","37.58872","0.02407"
"29.40000","37.60128","0.02431"
"29.55000","37.61366","0.02390"
"29.70000","37.62621","0.02441"
"29.85000","37.63871","0.02456"
"30.00000","37.65120","0.02422"
"30.15000","37.66364","0.02466"
"30.30000","37.67620","0.02476"
"30.45000","37.68869","0.02481"
"30.60000","37.70119","0.02498"
"30.75000","37.71375","0.02534"
"30.90000","37.72618","0.02548"
"31.05000","37.73867","0.02535"
"31.20000","37.75117","0.02575"
"31.35000","37.76373","0.02596"
"31.50000","37.77623","0.02641"
"31.65000","37.78866","0.02601"
"31.80000","37.80121","0.02576"
"31.95000","37.81371","0.02516"
"32.10000","37.82621","0.02554"
"32.25000","37.83864","0.02534"
"32.40000","37.85126","0.02586"
"32.55000","37.86369","0.02561"
"32.70000","37.87619","0.02546"
"32.85000","37.88869","0.02594"
"33.00000","37.90124","0.02537"
"33.15000","37.91368","0.02600"
"33.30000","37.92617","0.02565"
"33.45000","37.93867","0.02589"
"33.60000","37.95123","0.02608"
"33.75000","37.96366","0.02657"
"33.90000","37.97616","0.02661"
"34.05000","37.98872","0.02683"
"34.20000","38.00121","0.02769"
"34.35000","38.01365","0.02698"
"34.50000","38.02620","0.02663"
"34.65000","38.03876","0.02735"
"34.80000","38.05125","0.02753"
"34.95000","38.06369","0.02791"
"35.10000","38.07625","0.02792"
"35.25000","38.08874","0.02772"
"35.40000","38.10118","0.02767"
"35.55000","38.11367","0.02839"
"35.70000","38.12617","0.02833"
"35.85000","38.13867","0.02831"
"36.00000","38.15110","0.02851"
"36.15000","38.16372","0.02841"
"36.30000","38.17622","0.02852"
"36.45000","38.18871","0.02886"
"36.60000","38.20121","0.02888"
"36.75000","38.21370","0.02849"
"36.90000","38.22626","0.02846"
"37.05000","38.23870","0.02834"
"37.20000","38.25125","0.02935"
"37.35000","38.26374","0.02870"
"37.50000","38.27625","0.02881"
"37.65000","38.28868","0.02889"
"37.80000","38.30123","0.02963"
"37.95000","38.31373","0.02911"
"38.10000","38.32623","0.02911"
"38.25000","38.33873","0.00589"
"38.40000","38.35122","0.00720"
"38.55000","38.36371","0.01476"
"38.70000","38.37621","0.00975"
"38.85000","38.38871","0.00447"
"39.00000","38.40120","0.00445"
"39.15000","38.41370","0.00728"
"39.30000","38.42619","0.01044"
"39.45000","38.43869","0.00887"
"39.60000","38.45119","0.00577"
"39.75000","38.46368","0.00589"
"39.90000","38.47618","0.00822"
"40.05000","38.48867","0.00918"
"40.20000","38.50117","0.00798"
"40.35000","38.51367","0.00625"
"40.50000","38.52622","0.00568"
"40.65000","38.53872","0.00811"
"40.80000","38.55116","0.00944"
"40.95000","38.56371","0.00636"
"41.10000","38.57621","0.00518"
"41.25000","38.58870","0.00801"
"41.40000","38.60120","0.00963"
"41.55000","38.61375","0.00760"
"41.70000","38.62619","0.00603"
"41.85000","38.63869","0.00708"
"42.00000","38.65118","0.00810"
"42.15000","38.66374","0.00824"
"42.30000","38.67624","0.00795"
"42.45000","38.68861","0.00656"
"42.60000","38.70123","0.00706"
"42.75000","38.71372","0.00839"
"42.90000","38.72622","0.00842"
"43.05000","38.73866","0.00669"
"43.20000","38.75121","0.00724"
"43.35000","38.76371","0.00880"
"43.50000","38.77620","0.00890"
"43.65000","38.78864","0.00685"
"43.80000","38.80119","0.00711"
"43.95000","38.81369","0.00844"
"44.10000","38.82613","0.00869"
"44.25000","38.83868","0.00812"
"44.40000","38.85124","0.00747"
"44.55000","38.86367","0.00810"
"44.70000","38.87617","0.00844"
"44.85000","38.88867","0.00839"
"45.00000","38.90123","0.00824"
"45.15000","38.91372","0.00732"
"45.30000","38.92621","0.00824"
"45.45000","38.93877","0.00913"
"45.60000","38.95115","0.00843"
"45.75000","38.96364","0.00753"
"45.90000","38.97620","0.00817"
"46.05000","38.98869","0.00867"
"46.20000","39.00119","0.00796"
"46.35000","39.01369","0.00800"
"46.50000","39.02618","0.00885"
"46.65000","39.03868","0.00837"
"46.80000","39.05112","0.00813"
"46.95000","39.06373","0.00807"
"47.10000","39.07617","0.00811"
"47.25000","39.08866","0.00839"
"47.40000","39.10122","0.00910"
"47.55000","39.11372","0.00880"
"47.70000","39.12627","0.00799"
"47.85000","39.13871","0.00835"
"48.00000","39.15120","0.00880"
"48.15000","39.16370","0.00854"
"48.30000","39.17614","0.00833"
"48.45000","39.18869","0.00888"
"48.60000","39.20119","0.00924"
"48.75000","39.21368","0.00867"
"48.90000","39.22617","0.00851"
"49.05000","39.23867","0.00885"
"49.20000","39.25117","0.00900"
"49.35000","39.26366","0.00891"
"49.50000","39.27617","0.00898"
"49.65000","39.28872","0.00834"
"49.80000","39.30122","0.00834"
"49.95000","39.31365","0.00923"
"50.10000","39.32621","0.00902"
"50.25000","39.33870","0.00874"
"50.40000","39.35120","0.00891"
"50.55000","39.36363","0.00939"
"50.70000","39.37625","0.00898"
"50.85000","39.38874","0.00862"
"51.00000","39.40118","0.00874"
"51.15000","39.41368","0.00915"
"51.30000","39.42624","0.00889"
"51.45000","39.43879","0.00918"
"51.60000","39.45116","0.00881"
"51.75000","39.46372","0.00867"
"51.90000","39.47622","0.00904"
"52.05000","39.48871","0.00910"
"52.20000","39.50115","0.00879"
"52.35000","39.51377","0.00899"
"52.50000","39.52620","0.00929"
"52.65000","39.53870","0.00932"
"52.80000","39.55119","0.00903"
"52.95000","39.56369","0.00942"
"53.10000","39.57618","0.00935"
"53.25000","39.58862","0.00906"
"53.40000","39.60118","0.00960"
"53.55000","39.61367","0.00962"
"53.70000","39.62617","0.00920"
"53.85000","39.63867","0.00922"
"54.00000","39.65122","0.00915"
"54.15000","39.66372","0.00945"
"54.30000","39.67615","0.00935"
"54.45000","39.68871","0.00967"
"54.60000","39.70127","0.00953"
"54.75000","39.71370","0.00895"
"54.90000","39.72620","0.00924"
"55.05000","39.73875","0.00955"
"55.20000","39.75119","0.00917"
"55.35000","39.76368","0.00962"
"55.50000","39.77618","0.00985"
"55.65000","39.78874","0.00928"
"55.80000","39.80123","0.00953"
"55.95000","39.81367","0.00954"
"56.10000","39.82623","0.00980"
"56.25000","39.83872","0.00976"
"56.40000","39.85122","0.01005"
"56.55000","39.86372","0.00997"
"56.70000","39.87621","0.00970"
"56.85000","39.88864","0.00963"
"57.00000","39.90114","0.00939"
"57.15000","39.91370","0.00993"
"57.30000","39.92619","0.01012"
"57.45000","39.93863","0.01015"
"57.60000","39.95119","0.00994"
"57.75000","39.96368","0.00986"
"57.90000","39.97624","0.00996"
"58.05000","39.98867","0.00982"
"58.20000","40.00129","0.00999"
"58.35000","40.01372","0.01020"
"58.50000","40.02622","0.01013"
"58.65000","40.03866","0.01000"
"58.80000","40.05122","0.00989"
"58.95000","40.06371","0.01005"
"59.10000","40.07608","0.01021"
"59.25000","40.08870","0.01029"
"59.40000","40.10120","0.01029"
"59.55000","40.11369","0.01026"
"59.70000","40.12613","0.01002"
"59.85000","40.13874","0.01025"
"60.00000","40.15124","0.01036"
"60.15000","40.16368","0.01022"
"60.30000","40.17617","0.01059"
"60.45000","40.18873","0.01022"
"60.60000","40.20117","0.00995"
"60.75000","40.21366","0.01009"
"60.90000","40.22622","0.01024"
"61.05000","40.23872","0.01040"
"61.20000","40.25121","0.01017"
"61.35000","40.26371","0.01034"
"61.50000","40.27620","0.01060"
"61.65000","40.28870","0.01039"
"61.80000","40.30114","0.01031"
"61.95000","40.31369","0.01007"
"62.10000","40.32619","0.01073"
"62.25000","40.33875","0.01069"
"62.40000","40.35117","0.01015"
"62.55000","40.36374","0.01060"
"62.70000","40.37623","0.01066"
"62.85000","40.38866","0.01054"
"63.00000","40.40117","0.01063"
"63.15000","40.41372","0.01074"
"63.30000","40.42615","0.01085"
"63.45000","40.43859","0.01067"
"63.60000","40.45121","0.01044"
"63.75000","40.46370","0.01039"
"63.90000","40.47620","0.01065"
"64.05000","40.48864","0.01072"
"64.20000","40.50125","0.01077"
"64.35000","40.51369","0.01091"
"64.50000","40.52625","0.01074"
"64.65000","40.53874","0.01077"
"64.80000","40.55129","0.01114"
"64.95000","40.56373","0.01119"
"65.10000","40.57616","0.01073"
"65.25000","40.58872","0.01091"
"65.40000","40.60116","0.01084"
"65.55000","40.61372","0.01105"
"65.70000","40.62615","0.01096"
"65.85000","40.63871","0.01137"
"66.00000","40.65114","0.01151"
"66.15000","40.66364","0.01112"
"66.30000","40.67619","0.01150"
"66.45000","40.68869","0.01125"
"66.60000","40.70113","0.01091"
"66.75000","40.71368","0.01107"
"66.90000","40.72618","0.01163"
"67.05000","40.73867","0.01132"
"67.20000","40.75111","0.01154"
"67.35000","40.76373","0.01143"
"67.50000","40.77622","0.01105"
"67.65000","40.78865","0.01144"
"67.80000","40.80121","0.01134"
"67.95000","40.81377","0.01127"
"68.10000","40.82627","0.01131"
"68.25000","40.83870","0.01123"
"68.40000","40.85120","0.01153"
"68.55000","40.86375","0.01153"
"68.70000","40.87619","0.01209"
"68.85000","40.88868","0.01191"
"69.00000","40.90125","0.01118"
"69.15000","40.91374","0.01174"
"69.30000","40.92617","0.01170"
"69.45000","40.93867","0.01189"
"69.60000","40.95117","0.01225"
"69.75000","40.96367","0.01199"
"69.90000","40.97610","0.01194"
"70.05000","40.98866","0.01173"
"70.20000","41.00121","0.01234"
"70.35000","41.01364","0.01242"
"70.50000","41.02614","0.01242"
"70.65000","41.03876","0.01223"
"70.80000","41.05119","0.01211"
"70.95000","41.06369","0.01251"
"71.10000","41.07625","0.01244"
"71.25000","41.08874","0.01242"
"71.40000","41.10118","0.01254"
"71.55000","41.11367","0.01254"
"71.70000","41.12623","0.01244"
"71.85000","41.13873","0.01253"
"72.00000","41.15116","0.01260"
"72.15000","41.16372","0.01273"
"72.30000","41.17622","0.01254"
"72.45000","41.18871","0.01279"
"72.60000","41.20115","0.01307"
"72.75000","41.21376","0.01328"
"72.90000","41.22620","0.01307"
"73.05000","41.23875","0.01294"
"73.20000","41.25119","0.01272"
"73.35000","41.26374","0.01294"
"73.50000","41.27624","0.01337"
"73.65000","41.28868","0.01361"
"73.80000","41.30124","0.01331"
"73.95000","41.31367","0.01317"
"74.10000","41.32617","0.01303"
"74.25000","41.33866","0.01338"
"74.40000","41.35122","0.01338"
"74.55000","41.36372","0.01356"
"74.70000","41.37615","0.01323"
"74.85000","41.38871","0.01288"
"75.00000","41.40126","0.01336"
"75.15000","41.41376","0.01339"
"75.30000","41.42614","0.01382"
"75.45000","41.43875","0.01373"
"75.60000","41.45124","0.01325"
"75.75000","41.46368","0.01371"
"75.90000","41.47617","0.01403"
"76.05000","41.48867","0.01389"
"76.20000","41.50117","0.01421"
"76.35000","41.51361","0.01387"
"76.50000","41.52617","0.01412"
"76.65000","41.53872","0.01403"
"76.80000","41.55121","0.01414"
"76.95000","41.56365","0.01450"
"77.10000","41.57621","0.01435"
"77.25000","41.58870","0.01432"
"77.40000","41.60120","0.01441"
"77.55000","41.61375","0.01465"
"77.70000","41.62625","0.01427"
"77.85000","41.63875","0.01496"
"78.00000","41.65118","0.01455"
"78.15000","41.66374","0.01465"
"78.30000","41.67624","0.01473"
"78.45000","41.68867","0.01480"
"78.60000","41.70116","0.01514"
"78.75000","41.71372","0.01489"
"78.90000","41.72622","0.01517"
"79.05000","41.73859","0.01531"
"79.20000","41.75121","0.01521"
"79.35000","41.76371","0.01425"
"79.50000","41.77614","0.01375"
"79.65000","41.78864","0.01424"
"79.80000","41.80119","0.01422"
"79.95000","41.81369","0.01427"
"80.10000","41.82613","0.01415"
"80.25000","41.83868","0.01453"
"80.40000","41.85124","0.01422"
"80.55000","41.86368","0.01485"
"80.70000","41.87617","0.01482"
"80.85000","41.88873","0.01475"
"81.00000","41.90117","0.01486"
"81.15000","41.91365","0.01469"
"81.30000","41.92615","0.01511"
"81.45000","41.93871","0.01507"
"81.60000","41.95121","0.01489"
"81.75000","41.96365","0.01511"
"81.90000","41.97620","0.01482"
"82.05000","41.98876","0.01473"
"82.20000","42.00119","0.01476"
"82.35000","42.01362","0.01478"
"82.50000","42.02618","0.01472"
"82.65000","42.03868","0.01502"
"82.80000","42.05111","0.01531"
"82.95000","42.06367","0.01530"
"83.10000","42.07617","0.01550"
"83.25000","42.08867","0.01549"
"83.40000","42.10116","0.01581"
"83.55000","42.11371","0.01579"
"83.70000","42.12627","0.01614"
"83.85000","42.13865","0.01569"
"84.00000","42.15120","0.01556"
"84.15000","42.16370","0.01581"
"84.30000","42.17619","0.01592"
"84.45000","42.18863","0.01609"
"84.60000","42.20125","0.01583"
"84.75000","42.21374","0.01605"
"84.90000","42.22618","0.01630"
"85.05000","42.23867","0.01648"
"85.20000","42.25123","0.01664"
"85.35000","42.26373","0.01644"
"85.50000","42.27616","0.01682"
"85.65000","42.28872","0.01641"
"85.80000","42.30127","0.01646"
"85.95000","42.31371","0.01681"
"86.10000","42.32621","0.01662"
"86.25000","42.33876","0.01676"
"86.40000","42.35119","0.01664"
"86.55000","42.36363","0.01705"
"86.70000","42.37613","0.01691"
"86.85000","42.38868","0.01737"
"87.00000","42.40118","0.01702"
"87.15000","42.41368","0.01723"
"87.30000","42.42624","0.01706"
"87.45000","42.43879","0.01761"
"87.60000","42.45123","0.01738"
"87.75000","42.46372","0.01756"
"87.90000","42.47628","0.01768"
"88.05000","42.48872","0.01773"
"88.20000","42.50115","0.01766"
"88.35000","42.51371","0.01774"
"88.50000","42.52626","0.01816"
"88.65000","42.53870","0.01768"
"88.80000","42.55119","0.01829"
"88.95000","42.56369","0.01758"
"89.10000","42.57619","0.01864"
"89.25000","42.58862","0.01848"
"89.40000","42.60118","0.01854"
"89.55000","42.61367","0.01859"
"89.70000","42.62617","0.01835"
"89.85000","42.63867","0.01840"
"90.00000","42.65116","0.01888"
"90.15000","42.66366","0.01885"
"90.30000","42.67615","0.01892"
"90.45000","42.68871","0.01900"
"90.60000","42.70121","0.01904"
"90.75000","42.71370","0.01879"
"90.90000","42.72620","0.01902"
"91.05000","42.73875","0.01935"
"91.20000","42.75125","0.01925"
"91.35000","42.76369","0.01947"
"91.50000","42.77618","0.01939"
"91.65000","42.78874","0.01953"
"91.80000","42.80117","0.01972"
"91.95000","42.81367","0.02014"
"92.10000","42.82616","0.02021"
"92.25000","42.83872","0.02020"
"92.40000","42.85116","0.02014"
"92.55000","42.86366","0.02004"
"92.70000","42.87621","0.02062"
"92.85000","42.88871","0.02059"
"93.00000","42.90114","0.01981"
"93.15000","42.91370","0.01979"
"93.30000","42.92619","0.01998"
"93.45000","42.93869","0.01910"
"93.60000","42.95113","0.01922"
"93.75000","42.96374","0.01969"
"93.90000","42.97624","0.01943"
"94.05000","42.98868","0.01976"
"94.20000","43.00123","0.01975"
"94.35000","43.01373","0.01954"
"94.50000","43.02628","0.01986"
"94.65000","43.03865","0.01992"
"94.80000","43.05128","0.02032"
"94.95000","43.06371","0.01999"
"95.10000","43.07621","0.02053"
"95.25000","43.08865","0.02053"
"95.40000","43.10126","0.02037"
"95.55000","43.11369","0.02058"
"95.70000","43.12613","0.02063"
"95.85000","43.13868","0.02032"
"96.00000","43.15125","0.02119"
"96.15000","43.16368","0.02133"
"96.30000","43.17617","0.02113"
"96.45000","43.18873","0.02112"
"96.60000","43.20123","0.02135"
"96.75000","43.21366","0.02156"
"96.90000","43.22616","0.02145"
"97.05000","43.23872","0.02186"
"97.20000","43.25121","0.02193"
"97.35000","43.26365","0.02206"
"97.50000","43.27620","0.02189"
"97.65000","43.28870","0.02219"
"97.80000","43.30114","0.02188"
"97.95000","43.31363","0.02206"
"98.10000","43.32619","0.02239"
"98.25000","43.33868","0.02219"
"98.40000","43.35118","0.02228"
"98.55000","43.36367","0.02225"
"98.70000","43.37623","0.02255"
"98.85000","43.38866","0.02262"
"99.00000","43.40116","0.02274"
"99.15000","43.41372","0.02274"
"99.30000","43.42622","0.02314"
"99.45000","43.43865","0.02295"
"99.60000","43.45115","0.02282"
"99.75000","43.46364","0.02347"
"99.90000","43.47614","0.02296"
"100.05000","43.48863","0.02304"
"100.20000","43.50119","0.02316"
"100.35000","43.51369","0.02229"
"100.50000","43.52618","0.02237"
"100.65000","43.53874","0.02199"
"100.80000","43.55124","0.02236"
"100.95000","43.56373","0.02265"
"101.10000","43.57616","0.02260"
"101.25000","43.58872","0.02226"
"101.40000","43.60122","0.02330"
"101.55000","43.61366","0.02319"
"101.70000","43.62615","0.02262"
"101.85000","43.63871","0.02281"
"102.00000","43.65120","0.02349"
"102.15000","43.66364","0.02354"
"102.30000","43.67613","0.02367"
"102.45000","43.68869","0.02349"
"102.60000","43.70112","0.02356"
"102.75000","43.71362","0.02381"
"102.90000","43.72623","0.02421"
"103.05000","43.73873","0.02410"
"103.20000","43.75117","0.02383"
"103.35000","43.76367","0.02456"
"103.50000","43.77622","0.02456"
"103.65000","43.78866","0.02462"
"103.80000","43.80115","0.02468"
"103.95000","43.81371","0.02422"
"104.10000","43.82627","0.02496"
"104.25000","43.83870","0.02499"
"104.40000","43.85120","0.02539"
"104.55000","43.86375","0.02500"
"104.70000","43.87625","0.02539"
"104.85000","43.88869","0.02518"
"105.00000","43.90124","0.02538"
"105.15000","43.91374","0.02563"
"105.30000","43.92624","0.02535"
"105.45000","43.93867","0.02589"
"105.60000","43.95123","0.02551"
"105.75000","43.96378","0.02580"
"105.90000","43.97622","0.02621"
"106.05000","43.98866","0.02551"
"106.20000","44.00115","0.02588"
"106.35000","44.01371","0.02608"
"106.50000","44.02614","0.02649"
"106.65000","44.03870","0.02633"
"106.80000","44.05119","0.02583"
"106.95000","44.06369","0.02640"
"107.10000","44.07619","0.02585"
"107.25000","44.08880","0.02637"
"107.40000","44.10124","0.02615"
"107.55000","44.11374","0.02619"
"107.70000","44.12623","0.02656"
"107.85000","44.13879","0.02629"
"108.00000","44.15123","0.02623"
"108.15000","44.16365","0.02676"
"108.30000","44.17628","0.02674"
"108.45000","44.18865","0.02681"
"108.60000","44.20115","0.02698"
"108.75000","44.21365","0.02715"
"108.90000","44.22620","0.02712"
"109.05000","44.23869","0.02661"
"109.20000","44.25119","0.02713"
"109.35000","44.26375","0.02671"
"109.50000","44.27624","0.02744"
"109.65000","44.28862","0.02698"
"109.80000","44.30117","0.02694"
"109.95000","44.31367","0.02752"
"110.10000","44.32623","0.02766"
"110.25000","44.33866","0.02732"
"110.40000","44.35122","0.02765"
"110.55000","44.36372","0.02805"
"110.70000","44.37614","0.02760"
"110.85000","44.38870","0.02745"
"111.00000","44.40126","0.02724"
"111.15000","44.41376","0.02740"
"111.30000","44.42620","0.02757"
"111.45000","44.43875","0.02802"
"111.60000","44.45131","0.02785"
"111.75000","44.46368","0.02806"
"111.90000","44.47611","0.02828"
"112.05000","44.48874","0.02879"
"112.20000","44.50123","0.02769"
"112.35000","44.51366","0.02875"
"112.50000","44.52617","0.02928"
"112.65000","44.53872","0.02903"
"112.80000","44.55116","0.02896"
"112.95000","44.56359","0.02935"
"113.10000","44.57621","0.02971"
"113.25000","44.58876","0.02885"
"113.40000","44.60120","0.02946"
"113.55000","44.61370","0.02962"
"113.70000","44.62625","0.02994"
"113.85000","44.63874","0.02994"
"114.00000","44.65118","0.03047"
"114.15000","44.66374","0.02978"
"114.30000","44.67629","0.03000"
"114.45000","44.68873","0.03047"
"114.60000","44.70117","0.03030"
"114.75000","44.71373","0.03092"
"114.90000","44.72622","0.03109"
"115.05000","44.73859","0.03098"
"115.20000","44.75121","0.03182"
"115.35000","44.76371","0.03086"
"115.50000","44.77620","0.03077"
"115.65000","44.78864","0.03213"
"115.80000","44.80119","0.03186"
"115.95000","44.81369","0.03174"
"116.10000","44.82619","0.03173"
"116.25000","44.83862","0.03249"
"116.40000","44.85118","0.03216"
"116.55000","44.86367","0.03227"
"116.70000","44.87617","0.03262"
"116.85000","44.88873","0.03238"
"117.00000","44.90122","0.03273"
"117.15000","44.91366","0.03246"
"117.30000","44.92615","0.03284"
"117.45000","44.93871","0.03364"
"117.60000","44.95121","0.03333"
"117.75000","44.96370","0.03324"
"117.90000","44.97620","0.03339"
"118.05000","44.98875","0.03369"
"118.20000","45.00125","0.03368"
"118.35000","45.01369","0.03423"
"118.50000","45.02624","0.03397"
"118.65000","45.03874","0.03429"
"118.80000","45.05117","0.03402"
"118.95000","45.06367","0.03378"
"119.10000","45.07623","0.03420"
"119.25000","45.08867","0.03409"
"119.40000","45.10116","0.03443"
"119.55000","45.11372","0.03444"
"119.70000","45.12621","0.03491"
"119.85000","45.13864","0.03449"
"120.00000","45.15115","0.03420"
"120.15000","45.16370","0.03462"
"120.30000","45.17619","0.03437"
"120.45000","45.18869","0.03409"
"120.60000","45.20124","0.03444"
"120.75000","45.21374","0.03362"
"120.90000","45.22618","0.03438"
"121.05000","45.23867","0.03338"
"121.20000","45.25123","0.03399"
"121.35000","45.26373","0.03404"
"121.50000","45.27617","0.03374"
"121.65000","45.28865","0.03392"
"121.80000","45.30121","0.03409"
"121.95000","45.31371","0.03416"
"122.10000","45.32615","0.03457"
"122.25000","45.33870","0.03428"
"122.40000","45.35126","0.03421"
"122.55000","45.36369","0.03429"
"122.70000","45.37619","0.03390"
"122.85000","45.38868","0.03347"
"123.00000","45.40118","0.03289"
"123.15000","45.41368","0.03152"
"123.30000","45.42617","0.02905"
"123.45000","45.43873","0.02920"
"123.60000","45.45117","0.02859"
"123.75000","45.46366","0.02934"
"123.90000","45.47628","0.02897"
"124.05000","45.48872","0.02911"
"124.20000","45.50121","0.02894"
"124.35000","45.51377","0.02856"
"124.50000","45.52620","0.02883"
"124.65000","45.53870","0.02844"
"124.80000","45.55120","0.02867"
"124.95000","45.56375","0.02827"
"125.10000","45.57625","0.02877"
"125.25000","45.58862","0.02790"
"125.40000","45.60117","0.02739"
"125.55000","45.61368","0.02836"
"125.70000","45.62617","0.02828"
"125.85000","45.63861","0.02729"
"126.00000","45.65122","0.02761"
"126.15000","45.66372","0.02849"
"126.30000","45.67616","0.02876"
"126.45000","45.68865","0.02845"
"126.60000","45.70121","0.02843"
"126.75000","45.71376","0.02948"
"126.90000","45.72620","0.02884"
"127.05000","45.73876","0.02933"
"127.20000","45.75125","0.02940"
"127.35000","45.76369","0.02898"
"127.50000","45.77618","0.02871"
"127.65000","45.78874","0.02878"
"127.80000","45.80124","0.02924"
"127.95000","45.81367","0.02858"
"128.10000","45.82617","0.02816"
"128.25000","45.83873","0.02836"
"128.40000","45.85122","0.02866"
"128.55000","45.86366","0.02843"
"128.70000","45.87621","0.02817"
"128.85000","45.88871","0.02847"
"129.00000","45.90120","0.02800"
"129.15000","45.91364","0.02764"
"129.30000","45.92619","0.02785"
"129.45000","45.93869","0.02745"
"129.60000","45.95119","0.02669"
"129.75000","45.96368","0.02576"
"129.90000","45.97624","0.02668"
"130.05000","45.98867","0.02629"
"130.20000","46.00111","0.02558"
"130.35000","46.01367","0.02639"
"130.50000","46.02622","0.02657"
"130.65000","46.03866","0.02611"
"130.80000","46.05122","0.02609"
"130.95000","46.06377","0.02673"
"131.10000","46.07627","0.02641"
"131.25000","46.08870","0.02654"
"131.40000","46.10120","0.02665"
"131.55000","46.11375","0.02677"
"131.70000","46.12613","0.02707"
"131.85000","46.13869","0.02695"
"132.00000","46.15118","0.02702"
"132.15000","46.16368","0.02707"
"132.30000","46.17617","0.02703"
"132.45000","46.18873","0.02678"
"132.60000","46.20122","0.02717"
"132.75000","46.21372","0.02723"
"132.90000","46.22616","0.02709"
"133.05000","46.23872","0.02726"
"133.20000","46.25115","0.02739"
"133.35000","46.26371","0.02773"
"133.50000","46.27620","0.02785"
"133.65000","46.28870","0.02798"
"133.80000","46.30119","0.02743"
"133.95000","46.31363","0.02794"
"134.10000","46.32624","0.02792"
"134.25000","46.33874","0.02698"
"134.40000","46.35118","0.02705"
"134.55000","46.36374","0.02653"
"134.70000","46.37623","0.02725"
"134.85000","46.38873","0.02722"
"135.00000","46.40116","0.02698"
"135.15000","46.41366","0.02719"
"135.30000","46.42621","0.02741"
"135.45000","46.43865","0.02752"
"135.60000","46.45115","0.02637"
"135.75000","46.46370","0.02593"
"135.90000","46.47620","0.02639"
"136.05000","46.48864","0.02617"
"136.20000","46.50119","0.02622"
"136.35000","46.51368","0.02624"
"136.50000","46.52618","0.02720"
"136.65000","46.53862","0.02719"
"136.80000","46.55123","0.02736"
"136.95000","46.56373","0.02673"
"137.10000","46.57623","0.02710"
"137.25000","46.58872","0.02745"
"137.40000","46.60122","0.02746"
"137.55000","46.61372","0.02703"
"137.70000","46.62609","0.02745"
"137.85000","46.63871","0.02808"
"138.00000","46.65120","0.02798"
"138.15000","46.66370","0.02815"
"138.30000","46.67614","0.02829"
"138.45000","46.68875","0.02867"
"138.60000","46.70119","0.02857"
"138.75000","46.71368","0.02902"
"138.90000","46.72617","0.02809"
"139.05000","46.73874","0.02871"
"139.20000","46.75117","0.02864"
"139.35000","46.76361","0.02885"
"139.50000","46.77622","0.02955"
"139.65000","46.78872","0.02903"
"139.80000","46.80116","0.02986"
"139.95000","46.81365","0.02944"
"140.10000","46.82621","0.02937"
"140.25000","46.83870","0.02959"
"140.40000","46.85114","0.02985"
"140.55000","46.86375","0.02957"
"140.70000","46.87625","0.03025"
"140.85000","46.88868","0.03041"
"141.00000","46.90118","0.02978"
"141.15000","46.91373","0.03053"
"141.30000","46.92617","0.03069"
"141.45000","46.93867","0.03114"
"141.60000","46.95117","0.03111"
"141.75000","46.96372","0.03157"
"141.90000","46.97616","0.03159"
"142.05000","46.98865","0.03154"
"142.20000","47.00121","0.03173"
"142.35000","47.01370","0.03185"
"142.50000","47.02620","0.03168"
"142.65000","47.03870","0.03162"
"142.80000","47.05119","0.03223"
"142.95000","47.06363","0.03200"
"143.10000","47.07613","0.03225"
"143.25000","47.08868","0.03245"
"143.40000","47.10124","0.03297"
"143.55000","47.11367","0.03322"
"143.70000","47.12622","0.03284"
"143.85000","47.13878","0.03318"
"144.00000","47.15122","0.03299"
"144.15000","47.16372","0.03379"
"144.30000","47.17628","0.03355"
"144.45000","47.18871","0.03380"
"144.60000","47.20121","0.03373"
"144.75000","47.21364","0.03301"
"144.90000","47.22619","0.03309"
"145.05000","47.23869","0.03370"
"145.20000","47.25119","0.03369"
"145.35000","47.26369","0.03403"
"145.50000","47.27625","0.03371"
"145.65000","47.28868","0.03446"
"145.80000","47.30117","0.03502"
"145.95000","47.31373","0.03517"
"146.10000","47.32622","0.03505"
"146.25000","47.33866","0.03544"
"146.40000","47.35116","0.03512"
"146.55000","47.36371","0.03566"
"146.70000","47.37621","0.03648"
"146.85000","47.38864","0.03599"
"147.00000","47.40120","0.03599"
"147.15000","47.41370","0.03584"
"147.30000","47.42619","0.03639"
"147.45000","47.43875","0.03676"
"147.60000","47.45124","0.03647"
"147.75000","47.46374","0.03743"
"147.90000","47.47618","0.03711"
"148.05000","47.48874","0.03650"
"148.20000","47.50123","0.03744"
"148.35000","47.51373","0.03745"
"148.50000","47.52616","0.03788"
"148.65000","47.53872","0.03738"
"148.80000","47.55121","0.03754"
"148.95000","47.56371","0.03689"
"149.10000","47.57615","0.03765"
"149.25000","47.58864","0.03793"
"149.40000","47.60120","0.03816"
"149.55000","47.61357","0.03811"
"149.70000","47.62619","0.03779"
"149.85000","47.63875","0.03807"
"150.00000","47.65118","0.03802"
"150.15000","47.66368","0.03858"
"150.30000","47.67623","0.03928"
"150.45000","47.68867","0.03831"
"150.60000","47.70117","0.03895"
"150.75000","47.71367","0.03862"
"150.90000","47.72622","0.03950"
"151.05000","47.73872","0.03889"
"151.20000","47.75115","0.03953"
"151.35000","47.76377","0.03950"
"151.50000","47.77614","0.04009"
"151.65000","47.78870","0.03914"
"151.80000","47.80114","0.03970"
"151.95000","47.81369","0.03854"
"152.10000","47.82613","0.03950"
"152.25000","47.83868","0.03992"
"152.40000","47.85124","0.03968"
"152.55000","47.86374","0.03910"
"152.70000","47.87617","0.03890"
"152.85000","47.88872","0.03868"
"153.00000","47.90122","0.03948"
"153.15000","47.91372","0.03901"
"153.30000","47.92609","0.03892"
"153.45000","47.93871","0.03892"
"153.60000","47.95127","0.03924"
"153.75000","47.96370","0.03855"
"153.90000","47.97620","0.03854"
"154.05000","47.98875","0.03936"
"154.20000","48.00125","0.03848"
"154.35000","48.01368","0.03895"
"154.50000","48.02618","0.03872"
"154.65000","48.03873","0.03886"
"154.80000","48.05124","0.03912"
"154.95000","48.06373","0.03930"
"155.10000","48.07629","0.03926"
"155.25000","48.08872","0.03962"
"155.40000","48.10116","0.03978"
"155.55000","48.11365","0.03996"
"155.70000","48.12621","0.04007"
"155.85000","48.13865","0.04057"
"156.00000","48.15108","0.04049"
"156.15000","48.16370","0.04034"
"156.30000","48.17620","0.04113"
"156.45000","48.18869","0.04166"
"156.60000","48.20119","0.04157"
"156.75000","48.21368","0.04119"
"156.90000","48.22623","0.04187"
"157.05000","48.23867","0.04192"
"157.20000","48.25117","0.04255"
"157.35000","48.26373","0.04237"
"157.50000","48.27622","0.04182"
"157.65000","48.28872","0.04179"
"157.80000","48.30122","0.04202"
"157.95000","48.31371","0.04250"
"158.10000","48.32614","0.04225"
"158.25000","48.33870","0.04301"
"158.40000","48.35120","0.04370"
"158.55000","48.36375","0.04295"
"158.70000","48.37619","0.04281"
"158.85000","48.38874","0.04353"
"159.00000","48.40118","0.04358"
"159.15000","48.41368","0.04383"
"159.30000","48.42617","0.04438"
"159.45000","48.43867","0.04461"
"159.60000","48.45122","0.04498"
"159.75000","48.46366","0.04469"
"159.90000","48.47622","0.04442"
"160.05000","48.48871","0.04491"
"160.20000","48.50121","0.04488"
"160.35000","48.51371","0.04565"
"160.50000","48.52626","0.04562"
"160.65000","48.53876","0.04615"
"160.80000","48.55119","0.04565"
"160.95000","48.56369","0.04617"
"161.10000","48.57624","0.04664"
"161.25000","48.58874","0.04659"
"161.40000","48.60118","0.04715"
"161.55000","48.61374","0.04720"
"161.70000","48.62623","0.04732"
"161.85000","48.63866","0.04718"
"162.00000","48.65116","0.04750"
"162.15000","48.66372","0.04743"
"162.30000","48.67615","0.04801"
"162.45000","48.68865","0.04824"
"162.60000","48.70121","0.04797"
"162.75000","48.71370","0.04885"
"162.90000","48.72620","0.04852"
"163.05000","48.73870","0.04894"
"163.20000","48.75119","0.04927"
"163.35000","48.76375","0.04965"
"163.50000","48.77612","0.04997"
"163.65000","48.78873","0.04959"
"163.80000","48.80123","0.04967"
"163.95000","48.81373","0.05017"
"164.10000","48.82617","0.05034"
"164.25000","48.83872","0.05016"
"164.40000","48.85122","0.05026"
"164.55000","48.86372","0.05063"
"164.70000","48.87615","0.05068"
"164.85000","48.88870","0.05031"
"165.00000","48.90120","0.05013"
"165.15000","48.91364","0.05066"
"165.30000","48.92619","0.05126"
"165.45000","48.93875","0.05129"
"165.60000","48.95119","0.05154"
"165.75000","48.96368","0.05144"
"165.90000","48.97618","0.05199"
"166.05000","48.98873","0.05172"
"166.20000","49.00117","0.05184"
"166.35000","49.01372","0.05219"
"166.50000","49.02622","0.05258"
"166.65000","49.03872","0.05285"
"166.80000","49.05116","0.05285"
"166.95000","49.06377","0.05294"
"167.10000","49.07627","0.05366"
"167.25000","49.08870","0.05332"
"167.40000","49.10120","0.05352"
"167.55000","49.11375","0.05341"
"167.70000","49.12625","0.05421"
"167.85000","49.13868","0.05371"
"168.00000","49.15124","0.05331"
"168.15000","49.16374","0.05387"
"168.30000","49.17617","0.05403"
"168.45000","49.18867","0.05382"
"168.60000","49.20123","0.05370"
"168.75000","49.21366","0.05343"
"168.90000","49.22616","0.03227"
"169.05000","49.23865","0.03030"
"169.20000","49.25121","0.02338"
"169.35000","49.26365","0.02145"
"169.50000","49.27614","0.02213"
"169.65000","49.28870","0.02175"
"169.80000","49.30125","0.02263"
"169.95000","49.31363","0.02328"
"170.10000","49.32625","0.02226"
"170.25000","49.33874","0.02178"
"170.40000","49.35123","0.02209"
"170.55000","49.36367","0.02360"
"170.70000","49.37629","0.02456"
"170.85000","49.38873","0.02475"
"171.00000","49.40117","0.02466"
"171.15000","49.41372","0.02433"
"171.30000","49.42622","0.02416"
"171.45000","49.43871","0.02471"
"171.60000","49.45114","0.02557"
"171.75000","49.46376","0.02525"
"171.90000","49.47620","0.02567"
"172.05000","49.48869","0.02597"
"172.20000","49.50113","0.02660"
"172.35000","49.51374","0.02606"
"172.50000","49.52618","0.02620"
"172.65000","49.53868","0.02688"
"172.80000","49.55117","0.02720"
"172.95000","49.56373","0.02724"
"173.10000","49.57616","0.02744"
"173.25000","49.58866","0.02754"
"173.40000","49.60116","0.02762"
"173.55000","49.61372","0.02776"
"173.70000","49.62615","0.02845"
"173.85000","49.63865","0.02793"
"174.00000","49.65120","0.02830"
"174.15000","49.66370","0.02847"
"174.30000","49.67613","0.02932"
"174.45000","49.68869","0.03010"
"174.60000","49.70124","0.02920"
"174.75000","49.71362","0.02972"
"174.90000","49.72618","0.02984"
"175.05000","49.73867","0.03057"
"175.20000","49.75123","0.03019"
"175.35000","49.76366","0.03039"
"175.50000","49.77622","0.03149"
"175.65000","49.78866","0.03143"
"175.80000","49.80115","0.03133"
"175.95000","49.81365","0.03164"
"176.10000","49.82621","0.03179"
"176.25000","49.83870","0.03241"
"176.40000","49.85120","0.03162"
"176.55000","49.86370","0.03252"
"176.70000","49.87619","0.03234"
"176.85000","49.88875","0.03257"
"177.00000","49.90118","0.03339"
"177.15000","49.91373","0.03348"
"177.30000","49.92623","0.03378"
"177.45000","49.93867","0.03372"
"177.60000","49.95123","0.03433"
"177.75000","49.96372","0.03476"
"177.90000","49.97622","0.03474"
"178.05000","49.98872","0.03562"
"178.20000","50.00121","0.03509"
"178.35000","50.01370","0.03532"
"178.50000","50.02614","0.03607"
"178.65000","50.03864","0.03629"
"178.80000","50.05119","0.03633"
"178.95000","50.06369","0.03649"
"179.10000","50.07613","0.03793"
"179.25000","50.08875","0.03818"
"179.40000","50.10118","0.03803"
"179.55000","50.11367","0.03835"
"179.70000","50.12611","0.03928"
"179.85000","50.13872","0.03923"
"180.00000","50.15122","0.03959"
"180.15000","50.16366","0.03976"
"180.30000","50.17622","0.03971"
"180.45000","50.18877","0.03991"
"180.60000","50.20127","0.03954"
"180.75000","50.21364","0.03973"
"180.90000","50.22626","0.04041"
"181.05000","50.23869","0.04034"
"181.20000","50.25119","0.04040"
"181.35000","50.26368","0.04114"
"181.50000","50.27624","0.04142"
"181.65000","50.28874","0.04193"
"181.80000","50.30117","0.04180"
"181.95000","50.31367","0.04226"
"182.10000","50.32623","0.04210"
"182.25000","50.33866","0.04220"
"182.40000","50.35115","0.04273"
"182.55000","50.36371","0.04313"
"182.70000","50.37621","0.04098"
"182.85000","50.38871","0.04034"
"183.00000","50.40120","0.04106"
"183.15000","50.41370","0.04056"
"183.30000","50.42625","0.04002"
"183.45000","50.43869","0.04031"
"183.60000","50.45125","0.04064"
"183.75000","50.46375","0.04068"
"183.90000","50.47617","0.04036"
"184.05000","50.48867","0.04044"
"184.20000","50.50123","0.04095"
"184.35000","50.51373","0.04139"
"184.50000","50.52617","0.04129"
"184.65000","50.53872","0.04125"
"184.80000","50.55122","0.04121"
"184.95000","50.56371","0.04204"
"185.10000","50.57614","0.04174"
"185.25000","50.58870","0.04048"
"185.40000","50.60125","0.04117"
"185.55000","50.61369","0.04230"
"185.70000","50.62619","0.04200"
"185.85000","50.63875","0.04145"
"186.00000","50.65118","0.04176"
"186.15000","50.66362","0.04405"
"186.30000","50.67624","0.04367"
"186.45000","50.68873","0.04312"
"186.60000","50.70116","0.04320"
"186.75000","50.71372","0.04217"
"186.90000","50.72622","0.04322"
"187.05000","50.73872","0.04325"
"187.20000","50.75115","0.04378"
"187.35000","50.76371","0.04394"
"187.50000","50.77620","0.04374"
"187.65000","50.78870","0.04459"
"187.80000","50.80119","0.04505"
"187.95000","50.81369","0.04491"
"188.10000","50.82624","0.04548"
"188.25000","50.83862","0.04616"
"188.40000","50.85118","0.04625"
"188.55000","50.86367","0.04639"
"188.70000","50.87617","0.04693"
"188.85000","50.88866","0.04643"
"189.00000","50.90122","0.04712"
"189.15000","50.91372","0.04721"
"189.30000","50.92621","0.04732"
"189.45000","50.93865","0.04731"
"189.60000","50.95121","0.04785"
"189.75000","50.96370","0.04865"
"189.90000","50.97620","0.04854"
"190.05000","50.98875","0.04880"
"190.20000","51.00125","0.04842"
"190.35000","51.01368","0.04905"
"190.50000","51.02618","0.04928"
"190.65000","51.03873","0.04959"
"190.80000","51.05123","0.04954"
"190.95000","51.06367","0.04979"
"191.10000","51.07623","0.05032"
"191.25000","51.08873","0.05043"
"191.40000","51.10122","0.05071"
"191.55000","51.11365","0.04997"
"191.70000","51.12621","0.04898"
"191.85000","51.13870","0.04402"
"192.00000","51.15120","0.02697"
"192.15000","51.16370","0.02698"
"192.30000","51.17619","0.02126"
"192.45000","51.18869","0.01921"
"192.60000","51.20113","0.01982"
"192.75000","51.21368","0.02312"
"192.90000","51.22618","0.02240"
"193.05000","51.23867","0.02081"
"193.20000","51.25117","0.02073"
"193.35000","51.26373","0.02152"
"193.50000","51.27622","0.02003"
"193.65000","51.28872","0.01962"
"193.80000","51.30122","0.02129"
"193.95000","51.31377","0.02230"
"194.10000","51.32621","0.02110"
"194.25000","51.33864","0.02046"
"194.40000","51.35120","0.02173"
"194.55000","51.36369","0.02223"
"194.70000","51.37613","0.02131"
"194.85000","51.38868","0.02094"
"195.00000","51.40118","0.02210"
"195.15000","51.41368","0.02269"
"195.30000","51.42611","0.02231"
"195.45000","51.43867","0.02234"
"195.60000","51.45123","0.02282"
"195.75000","51.46360","0.02298"
"195.90000","51.47622","0.02274"
"196.05000","51.48865","0.02346"
"196.20000","51.50121","0.02356"
"196.35000","51.51365","0.02324"
"196.50000","51.52620","0.02317"
"196.65000","51.53870","0.02401"
"196.80000","51.55120","0.02433"
"196.95000","51.56369","0.02374"
"197.10000","51.57624","0.02398"
"197.25000","51.58875","0.02423"
"197.40000","51.60117","0.02485"
"197.55000","51.61373","0.02425"
"197.70000","51.62623","0.02431"
"197.85000","51.63867","0.02395"
"198.00000","51.65117","0.02497"
"198.15000","51.66378","0.02507"
"198.30000","51.67627","0.02527"
"198.45000","51.68871","0.02565"
"198.60000","51.70120","0.02579"
"198.75000","51.71370","0.02570"
"198.90000","51.72620","0.02583"
"199.05000","51.73864","0.02600"
"199.20000","51.75119","0.02644"
"199.35000","51.76375","0.02568"
"199.50000","51.77618","0.02711"
"199.65000","51.78862","0.02713"
"199.80000","51.80124","0.02697"
"199.95000","51.81373","0.02734"
"200.10000","51.82616","0.02685"
"200.25000","51.83872","0.02702"
"200.40000","51.85128","0.02712"
"200.55000","51.86372","0.02727"
"200.70000","51.87621","0.02719"
"200.85000","51.88871","0.02743"
"201.00000","51.90126","0.02781"
"201.15000","51.91364","0.02795"
"201.30000","51.92619","0.02832"
"201.45000","51.93869","0.02819"
"201.60000","51.95118","0.02830"
"201.75000","51.96362","0.02879"
"201.90000","51.97624","0.02908"
"202.05000","51.98874","0.02934"
"202.20000","52.00117","0.02985"
"202.35000","52.01366","0.02969"
"202.50000","52.02622","0.02968"
"202.65000","52.03872","0.02972"
"202.80000","52.05121","0.02983"
"202.95000","52.06371","0.02938"
"203.10000","52.07621","0.02980"
"203.25000","52.08870","0.02974"
"203.40000","52.10120","0.02951"
"203.55000","52.11376","0.02960"
"203.70000","52.12625","0.03032"
"203.85000","52.13868","0.02946"
"204.00000","52.15124","0.02975"
"204.15000","52.16373","0.03022"
"204.30000","52.17624","0.02964"
"204.45000","52.18861","0.03031"
"204.60000","52.20123","0.02990"
"204.75000","52.21373","0.03053"
"204.90000","52.22615","0.03077"
"205.05000","52.23871","0.03026"
"205.20000","52.25121","0.03071"
"205.35000","52.26365","0.03104"
"205.50000","52.27614","0.03095"
"205.65000","52.28870","0.03113"
"205.80000","52.30125","0.03194"
"205.95000","52.31369","0.03237"
"206.10000","52.32619","0.03141"
"206.25000","52.33874","0.03241"
"206.40000","52.35124","0.03222"
"206.55000","52.36367","0.03252"
"206.70000","52.37623","0.03260"
"206.85000","52.38873","0.03286"
"207.00000","52.40122","0.03311"
"207.15000","52.41366","0.03291"
"207.30000","52.42622","0.03354"
"207.45000","52.43871","0.03385"
"207.60000","52.45115","0.03368"
"207.75000","52.46364","0.03390"
"207.90000","52.47620","0.03445"
"208.05000","52.48869","0.03407"
"208.20000","52.50113","0.03356"
"208.35000","52.51368","0.03403"
"208.50000","52.52624","0.03501"
"208.65000","52.53868","0.03487"
"208.80000","52.55118","0.03562"
"208.95000","52.56367","0.03520"
"209.10000","52.57617","0.03573"
"209.25000","52.58866","0.03583"
"209.40000","52.60122","0.03543"
"209.55000","52.61371","0.03597"
"209.70000","52.62615","0.03620"
"209.85000","52.63865","0.03693"
"210.00000","52.65120","0.03666"
"210.15000","52.66370","0.03752"
"210.30000","52.67613","0.03739"
"210.45000","52.68869","0.03721"
"210.60000","52.70124","0.03761"
"210.75000","52.71375","0.03801"
"210.90000","52.72618","0.03834"
"211.05000","52.73873","0.03904"
"211.20000","52.75123","0.03923"
"211.35000","52.76367","0.03876"
"211.50000","52.77617","0.03940"
"211.65000","52.78872","0.03976"
"211.80000","52.80115","0.04052"
"211.95000","52.81365","0.04029"
"212.10000","52.82620","0.04004"
"212.25000","52.83870","0.04039"
"212.40000","52.85114","0.04025"
"212.55000","52.86364","0.03866"
"212.70000","52.87619","0.03849"
"212.85000","52.88869","0.03959"
"213.00000","52.90112","0.03882"
"213.15000","52.91374","0.03971"
"213.30000","52.92624","0.03922"
"213.45000","52.93872","0.03975"
"213.60000","52.95116","0.04057"
"213.75000","52.96378","0.04016"
"213.90000","52.97622","0.03985"
"214.05000","52.98866","0.04057"
"214.20000","53.00121","0.04129"
"214.35000","53.01371","0.04103"
"214.50000","53.02620","0.04113"
"214.65000","53.03858","0.04158"
"214.80000","53.05125","0.04165"
"214.95000","53.06375","0.04181"
"215.10000","53.07619","0.04211"
"215.25000","53.08862","0.04185"
"215.40000","53.10124","0.04200"
"215.55000","53.11374","0.04269"
"215.70000","53.12617","0.04298"
"215.85000","53.13866","0.04307"
"216.00000","53.15122","0.04312"
"216.15000","53.16372","0.04415"
"216.30000","53.17616","0.04356"
"216.45000","53.18877","0.04375"
"216.60000","53.20126","0.04370"
"216.75000","53.21370","0.04400"
"216.90000","53.22620","0.04454"
"217.05000","53.23876","0.04448"
"217.20000","53.25119","0.04470"
"217.35000","53.26368","0.04470"
"217.50000","53.27618","0.04589"
"217.65000","53.28873","0.04457"
"217.80000","53.30117","0.04523"
"217.95000","53.31367","0.04565"
"218.10000","53.32623","0.04566"
"218.25000","53.33866","0.04549"
"218.40000","53.35116","0.04602"
"218.55000","53.36371","0.04600"
"218.70000","53.37621","0.04609"
"218.85000","53.38870","0.04649"
"219.00000","53.40120","0.04656"
"219.15000","53.41370","0.04659"
"219.30000","53.42619","0.04690"
"219.42800","53.43684","0.04692"