File: Force_trajectories/161226_2/Specimen_RawData_6.csv
End date,"12/26/2016"
Specimen label,"14CG_13"
Maximum Load,"0.82696",N

Time,Extension,Load
(s),(mm),(N)
"0.00000","0.00000","0.00009"
"0.30600","0.02505","0.00027"
"0.61200","0.05124","0.00072"
"0.91800","0.07677","0.00022"
"1.22400","0.10218","0.00067"
"1.53000","0.12777","0.00075"
"1.83600","0.15318","0.00095"
"2.14200","0.17871","0.00048"
"2.44800","0.20412","0.00150"
"2.75400","0.22971","0.00099"
"3.06000","0.25524","0.00134"
"3.36600","0.28065","0.00111"
"3.67200","0.30624","0.00169"
"3.97800","0.33165","0.00152"
"4.28400","0.35724","0.00174"
"4.59000","0.38265","0.00116"
"4.89600","0.40818","0.00149"
"5.20200","0.43371","0.00194"
"5.50800","0.45918","0.00199"
"5.81400","0.48477","0.00120"
"6.12000","0.51018","0.00141"
"6.42600","0.53571","0.00183"
"6.73200","0.56118","0.00174"
"7.03800","0.58671","0.00224"
"7.34400","0.61219","0.00174"
"7.65000","0.63766","0.00170"
"7.95600","0.66319","0.00215"
"8.26200","0.68866","0.00180"
"8.56800","0.71425","0.00190"
"8.87400","0.73972","0.00181"
"9.18000","0.76525","0.00190"
"9.48600","0.79072","0.00168"
"9.79200","0.81619","0.00184"
"10.09800","0.84178","0.00195"
"10.40400","0.86713","0.00183"
"10.71000","0.89272","0.00175"
"11.01600","0.91819","0.00182"
"11.32200","0.94378","0.00257"
"11.62800","0.96925","0.00244"
"11.93400","0.99472","0.00213"
"12.24000","1.02019","0.00237"
"12.54600","1.04566","0.00216"
"12.85200","1.07119","0.00219"
"13.15800","1.09666","0.00209"
"13.46400","1.12225","0.00224"
"13.77000","1.14772","0.00206"
"14.07600","1.17319","0.00247"
"14.38200","1.19872","0.00196"
"14.68800","1.22419","0.00203"
"14.99400","1.24972","0.00228"
"15.30000","1.27513","0.00231"
"15.60600","1.30072","0.00264"
"15.91200","1.32625","0.00207"
"16.21800","1.35166","0.00227"
"16.52400","1.37725","0.00228"
"16.83000","1.40266","0.00222"
"17.13600","1.42819","0.00259"
"17.44200","1.45360","0.00263"
"17.74800","1.47925","0.00229"
"18.05400","1.50472","0.00225"
"18.36000","1.53025","0.00200"
"18.66600","1.55578","0.00242"
"18.97200","1.58119","0.00222"
"19.27800","1.60666","0.00239"
"19.58400","1.63213","0.00218"
"19.89000","1.65772","0.00266"
"20.19600","1.68319","0.00215"
"20.50200","1.70872","0.00217"
"20.80800","1.73426","0.00264"
"21.11400","1.75967","0.00218"
"21.42000","1.78514","0.00287"
"21.72600","1.81061","0.00231"
"22.03200","1.83620","0.00224"
"22.33800","1.86167","0.00259"
"22.64400","1.88720","0.00251"
"22.95000","1.91273","0.00250"
"23.25600","1.93820","0.00302"
"23.56200","1.96373","0.00272"
"23.86800","1.98914","0.00284"
"24.17400","2.01473","0.00291"
"24.48000","2.04020","0.00272"
"24.78600","2.06579","0.00309"
"25.09200","2.09126","0.00267"
"25.39800","2.11667","0.00274"
"25.70400","2.14220","0.00245"
"26.01000","2.16767","0.00270"
"26.31600","2.19326","0.00260"
"26.62200","2.21867","0.00248"
"26.92800","2.24420","0.00315"
"27.23400","2.26973","0.00280"
"27.54000","2.29526","0.00321"
"27.84600","2.32073","0.00342"
"28.15200","2.34614","0.00318"
"28.45800","2.37173","0.00308"
"28.76400","2.39714","0.00292"
"29.07000","2.42273","0.00289"
"29.37600","2.44826","0.00329"
"29.68200","2.47373","0.00337"
"29.98800","2.49920","0.00322"
"30.29400","2.52467","0.00331"
"30.60000","2.55020","0.00353"
"30.90600","2.57567","0.00318"
"31.21200","2.60120","0.00308"
"31.51800","2.62673","0.00362"
"31.82400","2.65220","0.00325"
"32.13000","2.67773","0.00316"
"32.43600","2.70314","0.00294"
"32.74200","2.72867","0.00367"
"33.04800","2.75414","0.00348"
"33.35400","2.77974","0.00355"
"33.66000","2.80521","0.00340"
"33.96600","2.83074","0.00353"
"34.27200","2.85621","0.00329"
"34.57800","2.88168","0.00371"
"34.88400","2.90721","0.00371"
"35.19000","2.93262","0.00343"
"35.49600","2.95821","0.00383"
"35.80200","2.98368","0.00357"
"36.10800","3.00921","0.00337"
"36.41400","3.03474","0.00411"
"36.72000","3.06015","0.00342"
"37.02600","3.08568","0.00354"
"37.33200","3.11115","0.00394"
"37.63800","3.13674","0.00333"
"37.94400","3.16215","0.00383"
"38.25000","3.18774","0.00355"
"38.55600","3.21321","0.00356"
"38.86200","3.23868","0.00387"
"39.16800","3.26427","0.00357"
"39.47400","3.28968","0.00426"
"39.78000","3.31521","0.00400"
"40.08600","3.34068","0.00408"
"40.39200","3.36621","0.00413"
"40.69800","3.39168","0.00406"
"41.00400","3.41721","0.00408"
"41.31000","3.44280","0.00378"
"41.61600","3.46821","0.00422"
"41.92200","3.49374","0.00362"
"42.22800","3.51915","0.00382"
"42.53400","3.54468","0.00415"
"42.84000","3.57021","0.00434"
"43.14600","3.59568","0.00351"
"43.45200","3.62121","0.00390"
"43.75800","3.64662","0.00420"
"44.06400","3.67221","0.00413"
"44.37000","3.69762","0.00425"
"44.67600","3.72321","0.00372"
"44.98200","3.74868","0.00394"
"45.28800","3.77415","0.00419"
"45.59400","3.79974","0.00406"
"45.90000","3.82515","0.00450"
"46.20600","3.85069","0.00457"
"46.51200","3.87616","0.00454"
"46.81800","3.90175","0.00446"
"47.12400","3.92716","0.00410"
"47.43000","3.95269","0.00413"
"47.73600","3.97822","0.00429"
"48.04200","4.00369","0.00443"
"48.34800","4.02928","0.00380"
"48.65400","4.05469","0.00407"
"48.96000","4.08022","0.00453"
"49.26600","4.10569","0.00436"
"49.57200","4.13116","0.00433"
"49.87800","4.15669","0.00414"
"50.18400","4.18222","0.00423"
"50.49000","4.20775","0.00455"
"50.79600","4.23316","0.00497"
"51.10200","4.25875","0.00438"
"51.40800","4.28422","0.00468"
"51.71400","4.30969","0.00486"
"52.02000","4.33522","0.00475"
"52.32600","4.36063","0.00462"
"52.63200","4.38628","0.00447"
"52.93800","4.41169","0.00481"
"53.24400","4.43722","0.00512"
"53.55000","4.46263","0.00480"
"53.85600","4.48816","0.00484"
"54.16200","4.51369","0.00454"
"54.46800","4.53916","0.00462"
"54.77400","4.56475","0.00483"
"55.08000","4.59016","0.00497"
"55.38600","4.61575","0.00494"
"55.69200","4.64116","0.00508"
"55.99800","4.66669","0.00507"
"56.30400","4.69222","0.00555"
"56.61000","4.71769","0.00525"
"56.91600","4.74322","0.00540"
"57.22200","4.76869","0.00515"
"57.52800","4.79428","0.00546"
"57.83400","4.81963","0.00542"
"58.14000","4.84516","0.00508"
"58.44600","4.87069","0.00524"
"58.75200","4.89616","0.00507"
"59.05800","4.92170","0.00523"
"59.36400","4.94717","0.00552"
"59.67000","4.97276","0.00544"
"59.97600","4.99817","0.00557"
"60.28200","5.02370","0.00567"
"60.58800","5.04917","0.00555"
"60.89400","5.07470","0.00573"
"61.20000","5.10023","0.00558"
"61.50600","5.12564","0.00572"
"61.81200","5.15123","0.00589"
"62.11800","5.17670","0.00577"
"62.42400","5.20223","0.00600"
"62.73000","5.22770","0.00635"
"63.03600","5.25317","0.00594"
"63.34200","5.27870","0.00567"
"63.64800","5.30417","0.00580"
"63.95400","5.32970","0.00617"
"64.26000","5.35517","0.00605"
"64.56600","5.38070","0.00626"
"64.87200","5.40617","0.00605"
"65.17800","5.43170","0.00619"
"65.48400","5.45717","0.00574"
"65.79000","5.48264","0.00588"
"66.09600","5.50817","0.00593"
"66.40200","5.53364","0.00582"
"66.70800","5.55917","0.00632"
"67.01400","5.58470","0.00616"
"67.32000","5.61017","0.00600"
"67.62600","5.63570","0.00616"
"67.93200","5.66117","0.00659"
"68.23800","5.68670","0.00642"
"68.54400","5.71211","0.00645"
"68.85000","5.73770","0.00640"
"69.15600","5.76323","0.00663"
"69.46200","5.78870","0.00647"
"69.76800","5.81417","0.00682"
"70.07400","5.83964","0.00670"
"70.38000","5.86523","0.00641"
"70.68600","5.89064","0.00666"
"70.99200","5.91623","0.00695"
"71.29800","5.94170","0.00655"
"71.60400","5.96723","0.00707"
"71.91000","5.99270","0.00683"
"72.21600","6.01817","0.00700"
"72.52200","6.04371","0.00692"
"72.82800","6.06918","0.00704"
"73.13400","6.09471","0.00707"
"73.44000","6.12018","0.00694"
"73.74600","6.14571","0.00726"
"74.05200","6.17118","0.00709"
"74.35800","6.19671","0.00706"
"74.66400","6.22224","0.00728"
"74.97000","6.24765","0.00734"
"75.27600","6.27318","0.00768"
"75.58200","6.29865","0.00745"
"75.88800","6.32418","0.00754"
"76.19400","6.34971","0.00768"
"76.50000","6.37524","0.00781"
"76.80600","6.40071","0.00780"
"77.11200","6.42618","0.00784"
"77.41800","6.45171","0.00777"
"77.72400","6.47718","0.00756"
"78.03000","6.50277","0.00807"
"78.33600","6.52818","0.00783"
"78.64200","6.55371","0.00803"
"78.94800","6.57924","0.00820"
"79.25400","6.60471","0.00760"
"79.56000","6.63024","0.00789"
"79.86600","6.65565","0.00821"
"80.17200","6.68124","0.00827"
"80.47800","6.70671","0.00831"
"80.78400","6.73224","0.00785"
"81.09000","6.75771","0.00837"
"81.39600","6.78312","0.00830"
"81.70200","6.80871","0.00851"
"82.00800","6.83412","0.00852"
"82.31400","6.85971","0.00844"
"82.62000","6.88518","0.00833"
"82.92600","6.91071","0.00820"
"83.23200","6.93618","0.00828"
"83.53800","6.96165","0.00849"
"83.84400","6.98718","0.00854"
"84.15000","7.01259","0.00832"
"84.45600","7.03818","0.00847"
"84.76200","7.06371","0.00825"
"85.06800","7.08925","0.00844"
"85.37400","7.11472","0.00896"
"85.68000","7.14013","0.00859"
"85.98600","7.16572","0.00842"
"86.29200","7.19113","0.00851"
"86.59800","7.21672","0.00865"
"86.90400","7.24219","0.00870"
"87.21000","7.26772","0.00869"
"87.51600","7.29319","0.00906"
"87.82200","7.31872","0.00906"
"88.12800","7.34425","0.00910"
"88.43400","7.36966","0.00872"
"88.74000","7.39519","0.00892"
"89.04600","7.42066","0.00881"
"89.35200","7.44625","0.00886"
"89.65800","7.47172","0.00896"
"89.96400","7.49725","0.00925"
"90.27000","7.52272","0.00897"
"90.57600","7.54813","0.00913"
"90.88200","7.57372","0.00928"
"91.18800","7.59919","0.00854"
"91.49400","7.62472","0.00862"
"91.80000","7.65019","0.00887"
"92.10600","7.67572","0.00862"
"92.41200","7.70125","0.00900"
"92.71800","7.72672","0.00891"
"93.02400","7.75219","0.00908"
"93.33000","7.77760","0.00858"
"93.63600","7.80319","0.00889"
"93.94200","7.82872","0.00913"
"94.24800","7.85425","0.00875"
"94.55400","7.87978","0.00893"
"94.86000","7.90519","0.00897"
"95.16600","7.93072","0.00890"
"95.47200","7.95613","0.00887"
"95.77800","7.98172","0.00908"
"96.08400","8.00719","0.00923"
"96.39000","8.03272","0.00902"
"96.69600","8.05825","0.00917"
"97.00200","8.08366","0.00916"
"97.30800","8.10919","0.00815"
"97.61400","8.13466","0.00870"
"97.92000","8.16025","0.00877"
"98.22600","8.18567","0.00888"
"98.53200","8.21126","0.00881"
"98.83800","8.23667","0.00899"
"99.14400","8.26220","0.00875"
"99.45000","8.28773","0.00891"
"99.75600","8.31314","0.00894"
"100.06200","8.33873","0.00874"
"100.36800","8.36420","0.00888"
"100.67400","8.38973","0.00910"
"100.98000","8.41526","0.00906"
"101.28600","8.44067","0.00923"
"101.59200","8.46626","0.00950"
"101.89800","8.49167","0.00900"
"102.20400","8.51726","0.00910"
"102.51000","8.54273","0.00911"
"102.81600","8.56820","0.00921"
"103.12200","8.59373","0.00930"
"103.42800","8.61920","0.00910"
"103.73400","8.64479","0.00925"
"104.04000","8.67014","0.00926"
"104.34600","8.69579","0.00897"
"104.65200","8.72114","0.00897"
"104.95800","8.74667","0.00910"
"105.26400","8.77220","0.00923"
"105.57000","8.79767","0.00916"
"105.87600","8.82326","0.00938"
"106.18200","8.84867","0.00948"
"106.48800","8.87420","0.00990"
"106.79400","8.89967","0.00955"
"107.10000","8.92520","0.00964"
"107.40600","8.95073","0.00988"
"107.71200","8.97620","0.00953"
"108.01800","9.00173","0.00983"
"108.32400","9.02720","0.00977"
"108.63000","9.05273","0.00952"
"108.93600","9.07814","0.00959"
"109.24200","9.10367","0.00936"
"109.54800","9.12920","0.00965"
"109.85400","9.15467","0.00987"
"110.16000","9.18021","0.00954"
"110.46600","9.20568","0.01001"
"110.77200","9.23120","0.00987"
"111.07800","9.25667","0.00998"
"111.38400","9.28221","0.00986"
"111.69000","9.30768","0.00997"
"111.99600","9.33315","0.01013"
"112.30200","9.35874","0.01022"
"112.60800","9.38421","0.01049"
"112.91400","9.40974","0.01060"
"113.22000","9.43515","0.01065"
"113.52600","9.46074","0.01048"
"113.83200","9.48621","0.01089"
"114.13800","9.51168","0.01077"
"114.44400","9.53715","0.01109"
"114.75000","9.56268","0.01104"
"115.05600","9.58827","0.01117"
"115.36200","9.61368","0.01140"
"115.66800","9.63927","0.01104"
"115.97400","9.66468","0.01118"
"116.28000","9.69021","0.01095"
"116.58600","9.71568","0.01138"
"116.89200","9.74121","0.01035"
"117.19800","9.76674","0.01053"
"117.50400","9.79221","0.01083"
"117.81000","9.81774","0.01099"
"118.11600","9.84321","0.01120"
"118.42200","9.86868","0.01154"
"118.72800","9.89421","0.01121"
"119.03400","9.91962","0.01173"
"119.34000","9.94521","0.01186"
"119.64600","9.97062","0.01173"
"119.95200","9.99621","0.01182"
"120.25800","10.02168","0.01214"
"120.56400","10.04721","0.01239"
"120.87000","10.07268","0.01234"
"121.17600","10.09815","0.01266"
"121.48200","10.12374","0.01313"
"121.78800","10.14921","0.01314"
"122.09400","10.17474","0.01342"
"122.40000","10.20021","0.01314"
"122.70600","10.22574","0.01389"
"123.01200","10.25121","0.01401"
"123.31800","10.27668","0.01400"
"123.62400","10.30221","0.01417"
"123.93000","10.32769","0.01435"
"124.23600","10.35328","0.01484"
"124.54200","10.37869","0.01531"
"124.84800","10.40421","0.01509"
"125.15400","10.42969","0.01521"
"125.46000","10.45516","0.01551"
"125.76600","10.48075","0.01574"
"126.07200","10.50622","0.01604"
"126.37800","10.53175","0.01626"
"126.68400","10.55722","0.01674"
"126.99000","10.58269","0.01627"
"127.29600","10.60816","0.01647"
"127.60200","10.63363","0.01664"
"127.90800","10.65916","0.01753"
"128.21400","10.68463","0.01766"
"128.52000","10.71022","0.01793"
"128.82600","10.73563","0.01829"
"129.13200","10.76122","0.01900"
"129.43800","10.78669","0.01895"
"129.74400","10.81222","0.01939"
"130.05000","10.83775","0.01951"
"130.35600","10.86316","0.01981"
"130.66200","10.88875","0.02004"
"130.96800","10.91416","0.02046"
"131.27400","10.93969","0.02072"
"131.58000","10.96516","0.02101"
"131.88600","10.99069","0.02095"
"132.19200","11.01622","0.02173"
"132.49800","11.04169","0.02159"
"132.80400","11.06722","0.02221"
"133.11000","11.09269","0.02206"
"133.41600","11.11822","0.02269"
"133.72200","11.14369","0.02314"
"134.02800","11.16922","0.02264"
"134.33400","11.19469","0.02307"
"134.64000","11.22016","0.02363"
"134.94600","11.24575","0.02344"
"135.25200","11.27116","0.02351"
"135.55800","11.29675","0.02397"
"135.86400","11.32222","0.02434"
"136.17000","11.34770","0.02536"
"136.47600","11.37316","0.02439"
"136.78200","11.39863","0.02404"
"137.08800","11.42423","0.02421"
"137.39400","11.44963","0.02450"
"137.70000","11.47523","0.02487"
"138.00600","11.50070","0.02515"
"138.31200","11.52629","0.02543"
"138.61800","11.55170","0.02591"
"138.92400","11.57723","0.02614"
"139.23000","11.60276","0.02639"
"139.53600","11.62817","0.02709"
"139.84200","11.65370","0.02713"
"140.14800","11.67917","0.02719"
"140.45400","11.70470","0.02158"
"140.76000","11.73023","0.02265"
"141.06600","11.75570","0.02162"
"141.37200","11.78123","0.02207"
"141.67800","11.80670","0.02219"
"141.98400","11.83223","0.02438"
"142.29000","11.85764","0.02419"
"142.59600","11.88323","0.02592"
"142.90200","11.90870","0.02255"
"143.20800","11.93423","0.02554"
"143.51400","11.95970","0.02627"
"143.82000","11.98523","0.02594"
"144.12600","12.01076","0.02689"
"144.43200","12.03611","0.02678"
"144.73800","12.06170","0.02703"
"145.04400","12.08717","0.02635"
"145.35000","12.11270","0.02638"
"145.65600","12.13823","0.02656"
"145.96200","12.16364","0.02641"
"146.26800","12.18917","0.02693"
"146.57400","12.21464","0.02767"
"146.88000","12.24023","0.02753"
"147.18600","12.26570","0.02761"
"147.49200","12.29123","0.02764"
"147.79800","12.31676","0.02624"
"148.10400","12.34217","0.02580"
"148.41000","12.36770","0.02603"
"148.71600","12.39311","0.02648"
"149.02200","12.41870","0.02725"
"149.32800","12.44417","0.02757"
"149.63400","12.46977","0.02884"
"149.94000","12.49523","0.02885"
"150.24600","12.52071","0.02912"
"150.55200","12.54618","0.02874"
"150.85800","12.57159","0.02814"
"151.16400","12.59718","0.02853"
"151.47000","12.62265","0.02889"
"151.77600","12.64818","0.02921"
"152.08200","12.67371","0.02921"
"152.38800","12.69918","0.02919"
"152.69400","12.72471","0.02933"
"153.00000","12.75018","0.02958"
"153.30600","12.77571","0.02968"
"153.61200","12.80118","0.02978"
"153.91800","12.82677","0.03053"
"154.22400","12.85224","0.03100"
"154.53000","12.87771","0.03119"
"154.83600","12.90330","0.03182"
"155.14200","12.92865","0.03211"
"155.44800","12.95424","0.03265"
"155.75400","12.97965","0.03313"
"156.06000","13.00524","0.03293"
"156.36600","13.03071","0.03353"
"156.67200","13.05624","0.03407"
"156.97800","13.08171","0.03469"
"157.28400","13.10712","0.03455"
"157.59000","13.13271","0.03507"
"157.89600","13.15812","0.03476"
"158.20200","13.18371","0.03604"
"158.50800","13.20918","0.03595"
"158.81400","13.23471","0.03626"
"159.12000","13.26018","0.03709"
"159.42600","13.28565","0.03735"
"159.73200","13.31118","0.03791"
"160.03800","13.33665","0.03852"
"160.34400","13.36218","0.03919"
"160.65000","13.38771","0.03873"
"160.95600","13.41318","0.03888"
"161.26200","13.43877","0.03963"
"161.56800","13.46419","0.04053"
"161.87400","13.48971","0.04065"
"162.18000","13.51513","0.04197"
"162.48600","13.54072","0.04207"
"162.79200","13.56618","0.04301"
"163.09800","13.59172","0.04334"
"163.40400","13.61725","0.04412"
"163.71000","13.64266","0.04431"
"164.01600","13.66819","0.04516"
"164.32200","13.69366","0.04603"
"164.62800","13.71925","0.04688"
"164.93400","13.74466","0.04702"
"165.24000","13.77019","0.04735"
"165.54600","13.79566","0.04794"
"165.85200","13.82119","0.04873"
"166.15800","13.84678","0.04931"
"166.46400","13.87219","0.05028"
"166.77000","13.89772","0.05041"
"167.07600","13.92319","0.05100"
"167.38200","13.94872","0.05144"
"167.68800","13.97419","0.05094"
"167.99400","13.99972","0.05154"
"168.30000","14.02525","0.05251"
"168.60600","14.05066","0.05288"
"168.91200","14.07625","0.05359"
"169.21800","14.10166","0.05360"
"169.52400","14.12719","0.05443"
"169.83000","14.15272","0.05493"
"170.13600","14.17819","0.05542"
"170.44200","14.20378","0.05580"
"170.74800","14.22919","0.05650"
"171.05400","14.25472","0.05699"
"171.36000","14.28019","0.05753"
"171.66600","14.30572","0.05833"
"171.97200","14.33119","0.05933"
"172.27800","14.35666","0.06063"
"172.58400","14.38219","0.06049"
"172.89000","14.40766","0.06140"
"173.19600","14.43319","0.06115"
"173.50200","14.45860","0.06026"
"173.80800","14.48419","0.06115"
"174.11400","14.50966","0.06060"
"174.42000","14.53513","0.06151"
"174.72600","14.56067","0.06145"
"175.03200","14.58614","0.06139"
"175.33800","14.61172","0.06133"
"175.64400","14.63720","0.06040"
"175.95000","14.66272","0.05601"
"176.25600","14.68820","0.05745"
"176.56200","14.71367","0.05672"
"176.86800","14.73920","0.05601"
"177.17400","14.76473","0.05552"
"177.48000","14.79026","0.05578"
"177.78600","14.81573","0.05538"
"178.09200","14.84126","0.05547"
"178.39800","14.86667","0.05613"
"178.70400","14.89220","0.05643"
"179.01000","14.91767","0.05676"
"179.31600","14.94320","0.05274"
"179.62200","14.96879","0.05385"
"179.92800","14.99414","0.05319"
"180.23400","15.01973","0.05335"
"180.54000","15.04520","0.05497"
"180.84600","15.07073","0.05604"
"181.15200","15.09620","0.05672"
"181.45800","15.12167","0.05701"
"181.76400","15.14726","0.05772"
"182.07000","15.17273","0.05809"
"182.37600","15.19826","0.05832"
"182.68200","15.22367","0.05857"
"182.98800","15.24920","0.05901"
"183.29400","15.27467","0.05841"
"183.60000","15.30014","0.05818"
"183.90600","15.32573","0.05807"
"184.21200","15.35120","0.05857"
"184.51800","15.37673","0.05877"
"184.82400","15.40220","0.05960"
"185.13000","15.42773","0.05986"
"185.43600","15.45320","0.06028"
"185.74200","15.47867","0.06041"
"186.04800","15.50426","0.05953"
"186.35400","15.52973","0.05493"
"186.66000","15.55526","0.05392"
"186.96600","15.58067","0.05181"
"187.27200","15.60614","0.05189"
"187.57800","15.63167","0.04925"
"187.88400","15.65720","0.05061"
"188.19000","15.68273","0.05120"
"188.49600","15.70815","0.05252"
"188.80200","15.73374","0.05313"
"189.10800","15.75921","0.05386"
"189.41400","15.78468","0.05485"
"189.72000","15.81021","0.05587"
"190.02600","15.83568","0.05634"
"190.33200","15.86127","0.05678"
"190.63800","15.88668","0.05690"
"190.94400","15.91221","0.05796"
"191.25000","15.93774","0.05846"
"191.55600","15.96327","0.05943"
"191.86200","15.98868","0.05972"
"192.16800","16.01421","0.06019"
"192.47400","16.03974","0.06042"
"192.78000","16.06515","0.06020"
"193.08600","16.09074","0.06082"
"193.39200","16.11615","0.06231"
"193.69800","16.14174","0.06243"
"194.00400","16.16721","0.06334"
"194.31000","16.19274","0.06389"
"194.61600","16.21821","0.06510"
"194.92200","16.24368","0.06412"
"195.22800","16.26921","0.06464"
"195.53400","16.29468","0.06567"
"195.84000","16.32021","0.06689"
"196.14600","16.34562","0.06766"
"196.45200","16.37121","0.06892"
"196.75800","16.39674","0.06999"
"197.06400","16.42221","0.07134"
"197.37000","16.44774","0.07172"
"197.67600","16.47315","0.07367"
"197.98200","16.49874","0.07529"
"198.28800","16.52421","0.07573"
"198.59400","16.54974","0.07739"
"198.90000","16.57521","0.07789"
"199.20600","16.60068","0.07895"
"199.51200","16.62621","0.08060"
"199.81800","16.65162","0.08199"
"200.12400","16.67721","0.08327"
"200.43000","16.70268","0.08462"
"200.73600","16.72828","0.08571"
"201.04200","16.75368","0.08729"
"201.34800","16.77921","0.08874"
"201.65400","16.80469","0.08957"
"201.96000","16.83010","0.09078"
"202.26600","16.85568","0.09124"
"202.57200","16.88116","0.09203"
"202.87800","16.90675","0.09347"
"203.18400","16.93221","0.09453"
"203.49000","16.95775","0.09532"
"203.79600","16.98328","0.09634"
"204.10200","17.00869","0.09728"
"204.40800","17.03416","0.09808"
"204.71400","17.05963","0.09883"
"205.02000","17.08522","0.09928"
"205.32600","17.11069","0.09665"
"205.63200","17.13622","0.09565"
"205.93800","17.16175","0.09615"
"206.24400","17.18716","0.09670"
"206.55000","17.21269","0.09742"
"206.85600","17.23810","0.09844"
"207.16200","17.26375","0.09883"
"207.46800","17.28922","0.09946"
"207.77400","17.31475","0.10058"
"208.08000","17.34022","0.10143"
"208.38600","17.36563","0.10211"
"208.69200","17.39122","0.10318"
"208.99800","17.41663","0.10388"
"209.30400","17.44228","0.10582"
"209.61000","17.46769","0.10739"
"209.91600","17.49328","0.10874"
"210.22200","17.51869","0.11043"
"210.52800","17.54416","0.11284"
"210.83400","17.56969","0.11546"
"211.14000","17.59510","0.11716"
"211.44600","17.62069","0.11956"
"211.75200","17.64622","0.12261"
"212.05800","17.67175","0.12551"
"212.36400","17.69722","0.12943"
"212.67000","17.72269","0.13272"
"212.97600","17.74822","0.13572"
"213.28200","17.77363","0.13928"
"213.58800","17.79917","0.14302"
"213.89400","17.82469","0.14596"
"214.20000","17.85022","0.14865"
"214.50600","17.87576","0.15163"
"214.81200","17.90117","0.15482"
"215.11800","17.92676","0.15649"
"215.42400","17.95211","0.15905"
"215.73000","17.97770","0.16059"
"216.03600","18.00317","0.16300"
"216.34200","18.02870","0.16493"
"216.64800","18.05423","0.16653"
"216.95400","18.07970","0.16833"
"217.26000","18.10523","0.17051"
"217.56600","18.13070","0.17266"
"217.87200","18.15623","0.17465"
"218.17800","18.18164","0.17714"
"218.48400","18.20723","0.18000"
"218.79000","18.23270","0.18321"
"219.09600","18.25823","0.18606"
"219.40200","18.28370","0.18748"
"219.70800","18.30917","0.18771"
"220.01400","18.33476","0.18929"
"220.32000","18.36017","0.19113"
"220.62600","18.38570","0.19378"
"220.93200","18.41123","0.19620"
"221.23800","18.43670","0.19837"
"221.54400","18.46223","0.20055"
"221.85000","18.48764","0.20225"
"222.15600","18.51323","0.20356"
"222.46200","18.53864","0.20421"
"222.76800","18.56423","0.20506"
"223.07400","18.58970","0.20620"
"223.38000","18.61523","0.20722"
"223.68600","18.64076","0.20783"
"223.99200","18.66611","0.20682"
"224.29800","18.69170","0.20287"
"224.60400","18.71717","0.20273"
"224.91000","18.74270","0.20312"
"225.21600","18.76818","0.20509"
"225.52200","18.79370","0.20640"
"225.82800","18.81923","0.20640"
"226.13400","18.84464","0.20601"
"226.44000","18.87024","0.20682"
"226.74600","18.89565","0.20356"
"227.05200","18.92124","0.20386"
"227.35800","18.94665","0.20578"
"227.66400","18.97218","0.20708"
"227.97000","18.99771","0.20683"
"228.27600","19.02318","0.20859"
"228.58200","19.04877","0.20992"
"228.88800","19.07418","0.21174"
"229.19400","19.09971","0.21483"
"229.50000","19.12518","0.21773"
"229.80600","19.15071","0.22070"
"230.11200","19.17618","0.22441"
"230.41800","19.20171","0.17399"
"230.72400","19.22724","0.17464"
"231.03000","19.25271","0.17159"
"231.33600","19.27824","0.17079"
"231.64200","19.30371","0.17508"
"231.94800","19.32924","0.18429"
"232.25400","19.35471","0.18612"
"232.56000","19.38018","0.18542"
"232.86600","19.40577","0.18978"
"233.17200","19.43118","0.19703"
"233.47800","19.45677","0.20039"
"233.78400","19.48218","0.20121"
"234.09000","19.50771","0.20341"
"234.39600","19.53312","0.20717"
"234.70200","19.55871","0.20967"
"235.00800","19.58430","0.21069"
"235.31400","19.60971","0.21232"
"235.62000","19.63524","0.21617"
"235.92600","19.66071","0.22013"
"236.23200","19.68624","0.22371"
"236.53800","19.71171","0.22685"
"236.84400","19.73718","0.23031"
"237.15000","19.76277","0.23348"
"237.45600","19.78818","0.23710"
"237.76200","19.81371","0.24196"
"238.06800","19.83918","0.24531"
"238.37400","19.86471","0.24772"
"238.68000","19.89018","0.25063"
"238.98600","19.91566","0.25465"
"239.29200","19.94118","0.25738"
"239.59800","19.96665","0.26118"
"239.90400","19.99218","0.26508"
"240.21000","20.01765","0.26926"
"240.51600","20.04318","0.27411"
"240.82200","20.06872","0.27938"
"241.12800","20.09419","0.28120"
"241.43400","20.11971","0.28496"
"241.74000","20.14519","0.28878"
"242.04600","20.17077","0.29476"
"242.35200","20.19619","0.29912"
"242.65800","20.22172","0.30317"
"242.96400","20.24719","0.30648"
"243.27000","20.27266","0.30920"
"243.57600","20.29819","0.31157"
"243.88200","20.32366","0.30658"
"244.18800","20.34931","0.30809"
"244.49400","20.37466","0.31121"
"244.80000","20.40019","0.31384"
"245.10600","20.42566","0.31490"
"245.41200","20.45119","0.31567"
"245.71800","20.47672","0.31707"
"246.02400","20.50219","0.31863"
"246.33000","20.52772","0.32027"
"246.63600","20.55319","0.32338"
"246.94200","20.57878","0.31910"
"247.24800","20.60413","0.32241"
"247.55400","20.62966","0.32541"
"247.86000","20.65519","0.33093"
"248.16600","20.68066","0.33631"
"248.47200","20.70619","0.34248"
"248.77800","20.73166","0.34792"
"249.08400","20.75725","0.35289"
"249.39000","20.78266","0.35789"
"249.69600","20.80825","0.36151"
"250.00200","20.83372","0.36665"
"250.30800","20.85919","0.37016"
"250.61400","20.88472","0.37407"
"250.92000","20.91019","0.37786"
"251.22600","20.93578","0.38164"
"251.53200","20.96119","0.38485"
"251.83800","20.98672","0.38813"
"252.14400","21.01219","0.38245"
"252.45000","21.03772","0.38620"
"252.75600","21.06326","0.39151"
"253.06200","21.08867","0.39492"
"253.36800","21.11426","0.39776"
"253.67400","21.13973","0.40086"
"253.98000","21.16525","0.40372"
"254.28600","21.19066","0.40683"
"254.59200","21.21620","0.40886"
"254.89800","21.24173","0.41168"
"255.20400","21.26720","0.41492"
"255.51000","21.29273","0.41791"
"255.81600","21.31820","0.42109"
"256.12200","21.34373","0.42535"
"256.42800","21.36920","0.42853"
"256.73400","21.39467","0.41874"
"257.04000","21.42020","0.41666"
"257.34600","21.44567","0.41702"
"257.65200","21.47120","0.42269"
"257.95800","21.49661","0.42401"
"258.26400","21.52226","0.42692"
"258.57000","21.54773","0.43312"
"258.87600","21.57326","0.43687"
"259.18200","21.59873","0.44043"
"259.48800","21.62414","0.44653"
"259.79400","21.64973","0.45223"
"260.10000","21.67514","0.45465"
"260.40600","21.70073","0.45849"
"260.71200","21.72620","0.46228"
"261.01800","21.75173","0.46373"
"261.32400","21.77720","0.46640"
"261.63000","21.80267","0.47148"
"261.93600","21.82820","0.47533"
"262.24200","21.85367","0.48041"
"262.54800","21.87920","0.48742"
"262.85400","21.90473","0.49257"
"263.16000","21.93020","0.49887"
"263.46600","21.95573","0.50488"
"263.77200","21.98120","0.51011"
"264.07800","22.00679","0.51419"
"264.38400","22.03221","0.51718"
"264.69000","22.05773","0.52042"
"264.99600","22.08320","0.52248"
"265.30200","22.10873","0.52493"
"265.60800","22.13420","0.52734"
"265.91400","22.15968","0.52988"
"266.22000","22.18521","0.53370"
"266.52600","22.21062","0.53707"
"266.83200","22.23620","0.54145"
"267.13800","22.26167","0.54680"
"267.44400","22.28727","0.55287"
"267.75000","22.31274","0.55828"
"268.05600","22.33821","0.56416"
"268.36200","22.36374","0.56818"
"268.66800","22.38921","0.57248"
"268.97400","22.41468","0.57712"
"269.28000","22.44015","0.57743"
"269.58600","22.46574","0.58361"
"269.89200","22.49121","0.58754"
"270.19800","22.51674","0.59511"
"270.50400","22.54221","0.60014"
"270.81000","22.56768","0.60420"
"271.11600","22.59315","0.60812"
"271.42200","22.61862","0.61065"
"271.72800","22.64421","0.61297"
"272.03400","22.66968","0.61530"
"272.34000","22.69521","0.61747"
"272.64600","22.72068","0.61949"
"272.95200","22.74615","0.62229"
"273.25800","22.77174","0.62539"
"273.56400","22.79715","0.62933"
"273.87000","22.82274","0.63417"
"274.17600","22.84821","0.63933"
"274.48200","22.87368","0.45576"
"274.78800","22.89921","0.45504"
"275.09400","22.92462","0.45865"
"275.40000","22.95021","0.45395"
"275.70600","22.97562","0.45425"
"276.01200","23.00121","0.45918"
"276.31800","23.02668","0.46109"
"276.62400","23.05221","0.46009"
"276.93000","23.07775","0.46254"
"277.23600","23.10315","0.46798"
"277.54200","23.12868","0.46912"
"277.84800","23.15409","0.47157"
"278.15400","23.17969","0.48164"
"278.46000","23.20515","0.49098"
"278.76600","23.23075","0.49618"
"279.07200","23.25622","0.50591"
"279.37800","23.28169","0.51314"
"279.68400","23.30716","0.51368"
"279.99000","23.33263","0.51559"
"280.29600","23.35822","0.51823"
"280.60200","23.38363","0.51973"
"280.90800","23.40922","0.52176"
"281.21400","23.43468","0.52518"
"281.52000","23.46022","0.52842"
"281.82600","23.48575","0.53146"
"282.13200","23.51116","0.53536"
"282.43800","23.53669","0.53770"
"282.74400","23.56216","0.08901"
"283.05000","23.58775","0.10343"
"283.35600","23.61322","0.09740"
"283.66200","23.63875","0.10325"
"283.96800","23.66428","0.11396"
"284.27400","23.68969","0.10126"
"284.58000","23.71522","0.11190"
"284.88600","23.74063","0.12039"
"285.19200","23.76622","0.12116"
"285.49800","23.79169","0.15282"
"285.80400","23.81722","0.12137"
"286.11000","23.84275","0.13290"
"286.41600","23.86816","0.15914"
"286.72200","23.89369","0.14315"
"287.02800","23.91910","0.14980"
"287.33400","23.94475","0.16262"
"287.64000","23.97016","0.16066"
"287.94600","23.99569","0.16563"
"288.25200","24.02122","0.16703"
"288.55800","24.04663","0.16020"
"288.86400","24.07216","0.16973"
"289.17000","24.09764","0.18252"
"289.47600","24.12322","0.17666"
"289.78200","24.14869","0.17870"
"290.08800","24.17416","0.19220"
"290.39400","24.19969","0.19040"
"290.70000","24.22516","0.19486"
"291.00600","24.25076","0.20261"
"291.31200","24.27616","0.19972"
"291.61800","24.30170","0.20169"
"291.92400","24.32717","0.20753"
"292.23000","24.35270","0.21108"
"292.53600","24.37823","0.20829"
"292.84200","24.40364","0.20994"
"293.14800","24.42928","0.21759"
"293.45400","24.45464","0.22160"
"293.76000","24.48022","0.21947"
"294.06600","24.50570","0.22216"
"294.37200","24.53123","0.23100"
"294.67800","24.55664","0.23620"
"294.98400","24.58217","0.23529"
"295.29000","24.60776","0.23682"
"295.59600","24.63323","0.24435"
"295.90200","24.65870","0.24938"
"296.20800","24.68417","0.25069"
"296.51400","24.70976","0.25117"
"296.82000","24.73523","0.25569"
"297.12600","24.76070","0.26252"
"297.43200","24.78629","0.26497"
"297.73800","24.81164","0.26659"
"298.04400","24.83723","0.27029"
"298.35000","24.86264","0.27863"
"298.65600","24.88823","0.28718"
"298.96200","24.91370","0.29186"
"299.26800","24.93917","0.29491"
"299.57400","24.96476","0.29855"
"299.88000","24.99023","0.30364"
"300.18600","25.01570","0.30757"
"300.49200","25.04117","0.31096"
"300.79800","25.06676","0.31186"
"301.10400","25.09223","0.31344"
"301.41000","25.11764","0.31449"
"301.71600","25.14323","0.31528"
"302.02200","25.16870","0.31613"
"302.32800","25.19423","0.31762"
"302.63400","25.21964","0.31870"
"302.94000","25.24523","0.32037"
"303.24600","25.27065","0.32217"
"303.55200","25.29617","0.32465"
"303.85800","25.32170","0.32687"
"304.16400","25.34717","0.32999"
"304.47000","25.37271","0.33134"
"304.77600","25.39817","0.31700"
"305.08200","25.42371","0.22629"
"305.38800","25.44917","0.22263"
"305.69400","25.47471","0.20613"
"306.00000","25.50018","0.20705"
"306.30600","25.52571","0.20724"
"306.61200","25.55124","0.20815"
"306.91800","25.57671","0.20994"
"307.22400","25.60224","0.21134"
"307.53000","25.62765","0.21286"
"307.83600","25.65318","0.21440"
"308.14200","25.67871","0.21562"
"308.44800","25.70418","0.21629"
"308.75400","25.72971","0.21819"
"309.06000","25.75512","0.21884"
"309.36600","25.78071","0.22050"
"309.67200","25.80618","0.22145"
"309.97800","25.83171","0.22335"
"310.28400","25.85718","0.22410"
"310.59000","25.88265","0.22612"
"310.89600","25.90824","0.22771"
"311.20200","25.93371","0.22937"
"311.50800","25.95930","0.23148"
"311.81400","25.98471","0.23323"
"312.12000","26.01024","0.23437"
"312.42600","26.03565","0.23618"
"312.73200","26.06118","0.23818"
"313.03800","26.08671","0.23968"
"313.34400","26.11218","0.24201"
"313.65000","26.13777","0.24350"
"313.95600","26.16318","0.24433"
"314.26200","26.18871","0.24602"
"314.56800","26.21418","0.24717"
"314.87400","26.23971","0.24945"
"315.18000","26.26518","0.24880"
"315.48600","26.29071","0.25059"
"315.79200","26.31624","0.25224"
"316.09800","26.34165","0.25539"
"316.40400","26.36719","0.25480"
"316.71000","26.39266","0.25542"
"317.01600","26.41818","0.25627"
"317.32200","26.44371","0.25757"
"317.62800","26.46913","0.26018"
"317.93400","26.49471","0.26200"
"318.24000","26.52019","0.26351"
"318.54600","26.54572","0.26610"
"318.85200","26.57119","0.26917"
"319.15800","26.59672","0.27247"
"319.46400","26.62219","0.27460"
"319.77000","26.64766","0.27759"
"320.07600","26.67319","0.28101"
"320.38200","26.69866","0.28437"
"320.68800","26.72425","0.28765"
"320.99400","26.74972","0.29043"
"321.30000","26.77525","0.29277"
"321.60600","26.80072","0.29572"
"321.91200","26.82619","0.29782"
"322.21800","26.85172","0.29983"
"322.52400","26.87713","0.30263"
"322.83000","26.90272","0.30438"
"323.13600","26.92825","0.30653"
"323.44200","26.95372","0.30820"
"323.74800","26.97913","0.30980"
"324.05400","27.00466","0.31042"
"324.36000","27.03019","0.31209"
"324.66600","27.05572","0.31301"
"324.97200","27.08119","0.31425"
"325.27800","27.10666","0.31465"
"325.58400","27.13219","0.31485"
"325.89000","27.15772","0.31538"
"326.19600","27.18319","0.31573"
"326.50200","27.20872","0.31632"
"326.80800","27.23413","0.31717"
"327.11400","27.25972","0.31790"
"327.42000","27.28519","0.31878"
"327.72600","27.31072","0.31773"
"328.03200","27.33619","0.31844"
"328.33800","27.36172","0.31979"
"328.64400","27.38725","0.32065"
"328.95000","27.41266","0.32219"
"329.25600","27.43820","0.32324"
"329.56200","27.46366","0.32599"
"329.86800","27.48925","0.32742"
"330.17400","27.51467","0.33002"
"330.48000","27.54020","0.33207"
"330.78600","27.56573","0.33472"
"331.09200","27.59114","0.33759"
"331.39800","27.61667","0.34102"
"331.70400","27.64214","0.34366"
"332.01000","27.66773","0.34620"
"332.31600","27.69320","0.34903"
"332.62200","27.71873","0.35251"
"332.92800","27.74426","0.35456"
"333.23400","27.76967","0.35665"
"333.54000","27.79520","0.35919"
"333.84600","27.82061","0.36153"
"334.15200","27.84620","0.36374"
"334.45800","27.87167","0.36530"
"334.76400","27.89720","0.36737"
"335.07000","27.92273","0.36966"
"335.37600","27.94820","0.37160"
"335.68200","27.97367","0.37340"
"335.98800","27.99914","0.37604"
"336.29400","28.02473","0.37797"
"336.60000","28.05014","0.37984"
"336.90600","28.07573","0.38224"
"337.21200","28.10126","0.38481"
"337.51800","28.12667","0.38719"
"337.82400","28.15220","0.38978"
"338.13000","28.17767","0.39174"
"338.43600","28.20320","0.39362"
"338.74200","28.22867","0.39527"
"339.04800","28.25426","0.39688"
"339.35400","28.27973","0.39878"
"339.66000","28.30514","0.40008"
"339.96600","28.33068","0.40136"
"340.27200","28.35614","0.40346"
"340.57800","28.38173","0.40528"
"340.88400","28.40714","0.40710"
"341.19000","28.43267","0.40813"
"341.49600","28.45820","0.40948"
"341.80200","28.48367","0.41139"
"342.10800","28.50920","0.41319"
"342.41400","28.53467","0.41478"
"342.72000","28.56021","0.41690"
"343.02600","28.58568","0.41835"
"343.33200","28.61121","0.42028"
"343.63800","28.63673","0.42281"
"343.94400","28.66221","0.42490"
"344.25000","28.68774","0.42685"
"344.55600","28.71315","0.42895"
"344.86200","28.73874","0.43186"
"345.16800","28.76415","0.43434"
"345.47400","28.78974","0.43731"
"345.78000","28.81521","0.43967"
"346.08600","28.84068","0.44208"
"346.39200","28.86627","0.44543"
"346.69800","28.89168","0.44829"
"347.00400","28.91721","0.45018"
"347.31000","28.94262","0.45256"
"347.61600","28.96821","0.45463"
"347.92200","28.99368","0.45684"
"348.22800","29.01921","0.45808"
"348.53400","29.04474","0.46020"
"348.84000","29.07015","0.46138"
"349.14600","29.09574","0.46287"
"349.45200","29.12115","0.46460"
"349.75800","29.14674","0.46578"
"350.06400","29.17221","0.46787"
"350.37000","29.19774","0.46973"
"350.67600","29.22327","0.47197"
"350.98200","29.24868","0.47427"
"351.28800","29.27421","0.47686"
"351.59400","29.29968","0.47894"
"351.90000","29.32521","0.48196"
"352.20600","29.35068","0.48530"
"352.51200","29.37621","0.48877"
"352.81800","29.40174","0.49238"
"353.12400","29.42715","0.49554"
"353.43000","29.45268","0.49928"
"353.73600","29.47816","0.50298"
"354.04200","29.50368","0.50629"
"354.34800","29.52909","0.50929"
"354.65400","29.55468","0.51144"
"354.96000","29.58021","0.51422"
"355.26600","29.60568","0.51709"
"355.57200","29.63128","0.51877"
"355.87800","29.65663","0.52053"
"356.18400","29.68222","0.52251"
"356.49000","29.70763","0.52381"
"356.79600","29.73322","0.52524"
"357.10200","29.75869","0.52636"
"357.40800","29.78422","0.52783"
"357.71400","29.80975","0.52942"
"358.02000","29.83522","0.53146"
"358.32600","29.86069","0.53323"
"358.63200","29.88616","0.53569"
"358.93800","29.91169","0.53826"
"359.24400","29.93722","0.54156"
"359.55000","29.96269","0.54445"
"359.85600","29.98828","0.54785"
"360.16200","30.01369","0.55213"
"360.46800","30.03922","0.55664"
"360.77400","30.06469","0.55937"
"361.08000","30.09022","0.56344"
"361.38600","30.11575","0.56594"
"361.69200","30.14116","0.56856"
"361.99800","30.16675","0.57125"
"362.30400","30.19216","0.57352"
"362.61000","30.21775","0.57593"
"362.91600","30.24316","0.57869"
"363.22200","30.26869","0.58130"
"363.52800","30.29416","0.58424"
"363.83400","30.31963","0.58744"
"364.14000","30.34522","0.59064"
"364.44600","30.37069","0.59485"
"364.75200","30.39622","0.59792"
"365.05800","30.42169","0.60058"
"365.36400","30.44728","0.60354"
"365.67000","30.47269","0.60561"
"365.97600","30.49822","0.60780"
"366.28200","30.52369","0.60984"
"366.58800","30.54917","0.61144"
"366.89400","30.57475","0.61318"
"367.20000","30.60017","0.61437"
"367.50600","30.62570","0.61566"
"367.81200","30.65117","0.61693"
"368.11800","30.67669","0.61805"
"368.42400","30.70217","0.61951"
"368.73000","30.72769","0.62173"
"369.03600","30.75323","0.62429"
"369.34200","30.77869","0.62629"
"369.64800","30.80422","0.62972"
"369.95400","30.82970","0.63365"
"370.26000","30.85517","0.63713"
"370.56600","30.88070","0.64196"
"370.87200","30.90617","0.64626"
"371.17800","30.93176","0.65079"
"371.48400","30.95717","0.65440"
"371.79000","30.98276","0.65886"
"372.09600","31.00817","0.66237"
"372.40200","31.03370","0.66494"
"372.70800","31.05917","0.66820"
"373.01400","31.08464","0.67063"
"373.32000","31.11023","0.67318"
"373.62600","31.13570","0.67538"
"373.93200","31.16123","0.67757"
"374.23800","31.18670","0.68044"
"374.54400","31.21223","0.68307"
"374.85000","31.23770","0.68724"
"375.15600","31.26317","0.69045"
"375.46200","31.28876","0.69420"
"375.76800","31.31423","0.69821"
"376.07400","31.33976","0.70185"
"376.38000","31.36517","0.70574"
"376.68600","31.39070","0.70871"
"376.99200","31.41617","0.71117"
"377.29800","31.44164","0.71422"
"377.60400","31.46723","0.71573"
"377.91000","31.49264","0.71761"
"378.21600","31.51823","0.71962"
"378.52200","31.54370","0.72081"
"378.82800","31.56923","0.72226"
"379.13400","31.59470","0.72311"
"379.44000","31.62017","0.72465"
"379.74600","31.64570","0.72549"
"380.05200","31.67117","0.72682"
"380.35800","31.69676","0.72846"
"380.66400","31.72217","0.72964"
"380.97000","31.74776","0.73088"
"381.27600","31.77317","0.73325"
"381.58200","31.79871","0.73558"
"381.88800","31.82423","0.73760"
"382.19400","31.84970","0.73939"
"382.50000","31.87523","0.74232"
"382.80600","31.90064","0.74399"
"383.11200","31.92623","0.75124"
"383.41800","31.95171","0.75718"
"383.72400","31.97718","0.75673"
"384.03000","32.00270","0.75588"
"384.33600","32.02818","0.75667"
"384.64200","32.05371","0.75975"
"384.94800","32.07917","0.76673"
"385.25400","32.10471","0.76712"
"385.56000","32.13018","0.77152"
"385.86600","32.15571","0.77485"
"386.17200","32.18124","0.77720"
"386.47800","32.20665","0.78341"
"386.78400","32.23218","0.78523"
"387.09000","32.25765","0.79182"
"387.39600","32.28324","0.79434"
"387.70200","32.30871","0.80034"
"388.00800","32.33430","0.80667"
"388.31400","32.35977","0.81007"
"388.62000","32.38518","0.81528"
"388.92600","32.41071","0.81811"
"389.23200","32.43618","0.82085"
"389.53800","32.46171","0.82369"
"389.84400","32.48718","0.82572"
"390.15000","32.51277","0.81861"
"390.45600","32.53824","0.23868"
"390.76200","32.56371","0.21180"
"391.06800","32.58918","0.19651"
"391.37400","32.61465","0.19502"
"391.68000","32.64018","0.19859"
"391.98600","32.66565","0.15969"
"392.29200","32.69124","0.15030"
"392.59800","32.71671","0.12481"
"392.90400","32.74224","0.13175"
"393.21000","32.76777","0.14673"
"393.51600","32.79318","0.15325"
"393.82200","32.81871","0.15217"
"394.12800","32.84418","0.14454"
"394.43400","32.86972","0.14475"
"394.74000","32.89518","0.15154"
"395.04600","32.92072","0.15435"
"395.35200","32.94624","0.15688"
"395.65800","32.97165","0.15519"
"395.96400","32.99718","0.15641"
"396.27000","33.02266","0.15865"
"396.57600","33.04824","0.15884"
"396.88200","33.07372","0.16016"
"397.18800","33.09925","0.16165"
"397.49400","33.12471","0.16135"
"397.80000","33.15012","0.16335"
"398.10600","33.17566","0.16285"
"398.41200","33.20113","0.16398"
"398.71800","33.22672","0.16593"
"399.02400","33.25225","0.16548"
"399.33000","33.27772","0.16611"
"399.63600","33.30318","0.16776"
"399.94200","33.32866","0.16884"
"400.24800","33.35419","0.17028"
"400.55400","33.37960","0.16976"
"400.86000","33.40525","0.17037"
"401.16600","33.43072","0.17270"
"401.47200","33.45625","0.17290"
"401.77800","33.48172","0.17478"
"402.08400","33.50719","0.17864"
"402.39000","33.53272","0.17958"
"402.69600","33.55819","0.18207"
"403.00200","33.58372","0.18311"
"403.30800","33.60919","0.18360"
"403.61400","33.63472","0.18465"
"403.92000","33.66025","0.18641"
"404.22600","33.68566","0.18781"
"404.53200","33.71119","0.18989"
"404.83800","33.73666","0.19059"
"405.14400","33.76219","0.19198"
"405.45000","33.78766","0.19408"
"405.75600","33.81319","0.19365"
"406.06200","33.83872","0.19513"
"406.36800","33.86419","0.19756"
"406.67400","33.88972","0.19843"
"406.98000","33.91513","0.19976"
"407.28600","33.94072","0.20126"
"407.59200","33.96614","0.20229"
"407.89800","33.99173","0.20246"
"408.20400","34.01719","0.20326"
"408.51000","34.04272","0.20354"
"408.81600","34.06819","0.20472"
"409.12200","34.09367","0.20549"
"409.42800","34.11920","0.20646"
"409.73400","34.14466","0.20745"
"410.04000","34.17020","0.20795"
"410.34600","34.19572","0.20754"
"410.65200","34.22126","0.20833"
"410.95800","34.24679","0.20974"
"411.26400","34.27220","0.21109"
"411.57000","34.29773","0.21195"
"411.87600","34.32314","0.21369"
"412.18200","34.34872","0.21536"
"412.48800","34.37420","0.21663"
"412.79400","34.39973","0.21744"
"413.10000","34.42526","0.21900"
"413.40600","34.45067","0.22025"
"413.71200","34.47626","0.22156"
"414.01800","34.50167","0.22344"
"414.32400","34.52726","0.22433"
"414.63000","34.55267","0.22671"
"414.93600","34.57820","0.22856"
"415.24200","34.60373","0.23090"
"415.54800","34.62920","0.23266"
"415.85400","34.65473","0.23441"
"416.16000","34.68014","0.23490"
"416.46600","34.70573","0.23528"
"416.77200","34.73114","0.23768"
"417.07800","34.75667","0.23998"
"417.38400","34.78220","0.24148"
"417.69000","34.80767","0.24359"
"417.99600","34.83320","0.24460"
"418.30200","34.85862","0.24547"
"418.60800","34.88420","0.24561"
"418.91400","34.90967","0.24711"
"419.22000","34.93520","0.24895"
"419.52600","34.96067","0.25072"
"419.83200","34.98621","0.25299"
"420.13800","35.01173","0.25476"
"420.44400","35.03720","0.25614"
"420.75000","35.06273","0.25739"
"421.05600","35.08814","0.25925"
"421.36200","35.11367","0.25999"
"421.66800","35.13921","0.26029"
"421.97400","35.16468","0.26181"
"422.28000","35.19027","0.26356"
"422.58600","35.21568","0.26608"
"422.89200","35.24121","0.26837"
"423.19800","35.26667","0.27097"
"423.50400","35.29221","0.27456"
"423.81000","35.31768","0.27663"
"424.11600","35.34321","0.27762"
"424.42200","35.36880","0.18953"
"424.72800","35.39421","0.18827"
"425.03400","35.41973","0.19177"
"425.34000","35.44515","0.19781"
"425.64600","35.47074","0.19079"
"425.95200","35.49621","0.18698"
"426.25800","35.52168","0.19458"
"426.56400","35.54727","0.20011"
"426.87000","35.57268","0.19989"
"427.17600","35.59827","0.19798"
"427.48200","35.62368","0.19754"
"427.78800","35.64921","0.20253"
"428.09400","35.67468","0.20451"
"428.40000","35.70015","0.20294"
"428.70600","35.72574","0.20352"
"429.01200","35.75121","0.20529"
"429.31800","35.77674","0.20706"
"429.62400","35.80215","0.20958"
"429.93000","35.82774","0.20908"
"430.23600","35.85321","0.20901"
"430.54200","35.87868","0.20980"
"430.84800","35.90421","0.21166"
"431.15400","35.92968","0.21246"
"431.46000","35.95527","0.21297"
"431.76600","35.98062","0.21301"
"432.07200","36.00621","0.21420"
"432.37800","36.03168","0.21740"
"432.68400","36.05716","0.22040"
"432.99000","36.08268","0.22047"
"433.29600","36.10815","0.22050"
"433.60200","36.13374","0.22224"
"433.90800","36.15915","0.22348"
"434.21400","36.18468","0.22579"
"434.52000","36.21016","0.22797"
"434.82600","36.23574","0.22816"
"435.13200","36.26122","0.22876"
"435.43800","36.28669","0.23157"
"435.74400","36.31221","0.23246"
"436.05000","36.33768","0.01500"
"436.35600","36.36328","0.00329"
"436.66200","36.38869","0.00308"
"436.96800","36.41422","0.00151"
"437.27400","36.43969","0.00174"
"437.58000","36.46516","0.00223"
"437.88600","36.49068","0.00109"
"438.19200","36.51616","0.00194"
"438.49800","36.54169","0.00098"
"438.80400","36.56716","0.00224"
"439.11000","36.59269","0.00115"
"439.41600","36.61822","0.00116"
"439.72200","36.64369","0.00142"
"440.02800","36.66922","0.00194"
"440.33400","36.69469","0.00096"
"440.64000","36.72028","0.00117"
"440.94600","36.74569","0.00105"
"441.25200","36.77122","0.00166"
"441.55800","36.79669","0.00086"
"441.86400","36.82216","0.00142"
"442.17000","36.84775","0.00204"
"442.47600","36.87316","0.00135"
"442.78200","36.89875","0.00065"
"443.08800","36.92416","0.00098"
"443.39400","36.94975","0.00242"
"443.70000","36.97516","0.00117"
"444.00600","37.00069","0.00216"
"444.31200","37.02622","0.00192"
"444.61800","37.05169","0.00165"
"444.92400","37.07722","0.00149"
"445.23000","37.10270","0.00142"
"445.53600","37.12822","0.00145"
"445.84200","37.15369","0.00198"
"446.14800","37.17916","0.00071"
"446.45400","37.20475","0.00078"
"446.76000","37.23016","0.00171"
"447.06600","37.25570","0.00142"
"447.37200","37.28117","0.00170"
"447.67800","37.30670","0.00131"
"447.98400","37.33223","0.00122"
"448.29000","37.35770","0.00150"
"448.59600","37.38322","0.00110"
"448.90200","37.40863","0.00112"
"449.20800","37.43423","0.00152"
"449.51400","37.45970","0.00116"
"449.82000","37.48523","0.00082"
"450.12600","37.51070","0.00065"
"450.43200","37.53622","0.00182"
"450.73800","37.56170","0.00143"
"451.04400","37.58711","0.00106"
"451.35000","37.61270","0.00118"
"451.65600","37.63817","0.00151"
"451.96200","37.66376","0.00081"
"452.26800","37.68923","0.00031"
"452.57400","37.71476","0.00068"
"452.88000","37.74017","0.00179"
"453.18600","37.76564","0.00078"
"453.49200","37.79123","0.00043"
"453.79800","37.81670","0.00110"
"454.10400","37.84223","0.00176"
"454.41000","37.86764","0.00065"
"454.50600","37.87565","0.00056"