File: Force_trajectories/161226_2/Specimen_RawData_5.csv
End date,"12/26/2016"
Specimen label,"14CG_15"
Maximum Load,"0.31998",N

Time,Extension,Load
(s),(mm),(N)
"0.00000","0.00006","-0.00050"
"0.46800","0.03934","0.00054"
"0.93600","0.07820","-0.00078"
"1.40400","0.11725","-0.00011"
"1.87200","0.15623","-0.00011"
"2.34000","0.19509","0.00075"
"2.80800","0.23414","0.00023"
"3.27600","0.27318","0.00018"
"3.74400","0.31222","0.00107"
"4.21200","0.35126","0.00067"
"4.68000","0.39013","0.00094"
"5.14800","0.42917","0.00095"
"5.61600","0.46815","0.00071"
"6.08400","0.50713","0.00103"
"6.55200","0.54618","0.00064"
"7.02000","0.58522","0.00119"
"7.48800","0.62414","0.00099"
"7.95600","0.66319","0.00098"
"8.42400","0.70217","0.00093"
"8.89200","0.74121","0.00160"
"9.36000","0.78013","0.00131"
"9.82800","0.81912","0.00172"
"10.29600","0.85816","0.00106"
"10.76400","0.89720","0.00224"
"11.23200","0.93618","0.00242"
"11.70000","0.97523","0.00226"
"12.16800","1.01421","0.00170"
"12.63600","1.05319","0.00233"
"13.10400","1.09212","0.00185"
"13.57200","1.13116","0.00206"
"14.04000","1.17020","0.00232"
"14.50800","1.20918","0.00238"
"14.97600","1.24817","0.00253"
"15.44400","1.28715","0.00243"
"15.91200","1.32619","0.00273"
"16.38000","1.36517","0.00243"
"16.84800","1.40410","0.00262"
"17.31600","1.44314","0.00297"
"17.78400","1.48218","0.00251"
"18.25200","1.52117","0.00258"
"18.72000","1.56021","0.00315"
"19.18800","1.59919","0.00311"
"19.65600","1.63823","0.00309"
"20.12400","1.67716","0.00309"
"20.59200","1.71614","0.00367"
"21.06000","1.75518","0.00378"
"21.52800","1.79416","0.00396"
"21.99600","1.83321","0.00379"
"22.46400","1.87213","0.00399"
"22.93200","1.91123","0.00413"
"23.40000","1.95016","0.00390"
"23.86800","1.98914","0.00410"
"24.33600","2.02818","0.00434"
"24.80400","2.06716","0.00462"
"25.27200","2.10621","0.00459"
"25.74000","2.14519","0.00508"
"26.20800","2.18417","0.00526"
"26.67600","2.22327","0.00529"
"27.14400","2.26220","0.00538"
"27.61200","2.30118","0.00604"
"28.08000","2.34016","0.00633"
"28.54800","2.37920","0.00633"
"29.01600","2.41819","0.00652"
"29.48400","2.45723","0.00628"
"29.95200","2.49615","0.00688"
"30.42000","2.53520","0.00721"
"30.88800","2.57418","0.00710"
"31.35600","2.61316","0.00697"
"31.82400","2.65220","0.00688"
"32.29200","2.69125","0.00705"
"32.76000","2.73023","0.00751"
"33.22800","2.76921","0.00752"
"33.69600","2.80825","0.00761"
"34.16400","2.84718","0.00809"
"34.63200","2.88616","0.00831"
"35.10000","2.92508","0.00694"
"35.56800","2.96419","0.00723"
"36.03600","3.00323","0.00756"
"36.50400","3.04221","0.00781"
"36.97200","3.08119","0.00814"
"37.44000","3.12024","0.00813"
"37.90800","3.15916","0.00811"
"38.37600","3.19808","0.00826"
"38.84400","3.23712","0.00857"
"39.31200","3.27623","0.00884"
"39.78000","3.31521","0.00884"
"40.24800","3.35425","0.00892"
"40.71600","3.39324","0.00921"
"41.18400","3.43222","0.00887"
"41.65200","3.47114","0.00945"
"42.12000","3.51012","0.00889"
"42.58800","3.54917","0.00902"
"43.05600","3.58815","0.00891"
"43.52400","3.62713","0.00902"
"43.99200","3.66617","0.00928"
"44.46000","3.70522","0.00941"
"44.92800","3.74420","0.00945"
"45.39600","3.78312","0.00832"
"45.86400","3.82217","0.00845"
"46.33200","3.86115","0.00869"
"46.80000","3.90019","0.00859"
"47.26800","3.93917","0.00884"
"47.73600","3.97816","0.00856"
"48.20400","4.01720","0.00862"
"48.67200","4.05618","0.00879"
"49.14000","4.09510","0.00866"
"49.60800","4.13421","0.00923"
"50.07600","4.17319","0.00931"
"50.54400","4.21217","0.00954"
"51.01200","4.25116","0.00970"
"51.48000","4.29020","0.00838"
"51.94800","4.32918","0.00879"
"52.41600","4.36816","0.00878"
"52.88400","4.40709","0.00893"
"53.35200","4.44619","0.00921"
"53.82000","4.48517","0.00951"
"54.28800","4.52421","0.00977"
"54.75600","4.56320","0.00969"
"55.22400","4.60224","0.00985"
"55.69200","4.64116","0.00987"
"56.16000","4.68015","0.01045"
"56.62800","4.71913","0.01027"
"57.09600","4.75817","0.01054"
"57.56400","4.79721","0.01065"
"58.03200","4.83614","0.01080"
"58.50000","4.87518","0.01090"
"58.96800","4.91428","0.01176"
"59.43600","4.95314","0.01086"
"59.90400","4.99213","0.01115"
"60.37200","5.03117","0.01077"
"60.84000","5.07021","0.01092"
"61.30800","5.10919","0.01116"
"61.77600","5.14818","0.01145"
"62.24400","5.18722","0.01164"
"62.71200","5.22626","0.01165"
"63.18000","5.26513","0.01187"
"63.64800","5.30411","0.01206"
"64.11600","5.34315","0.01228"
"64.58400","5.38219","0.01256"
"65.05200","5.42124","0.01234"
"65.52000","5.46022","0.01242"
"65.98800","5.49920","0.01236"
"66.45600","5.53818","0.01278"
"66.92400","5.57711","0.01312"
"67.39200","5.61615","0.01311"
"67.86000","5.65519","0.01324"
"68.32800","5.69418","0.01346"
"68.79600","5.73322","0.01362"
"69.26400","5.77220","0.01354"
"69.73200","5.81124","0.01316"
"70.20000","5.85017","0.01322"
"70.66800","5.88909","0.01404"
"71.13600","5.92819","0.01381"
"71.60400","5.96723","0.01423"
"72.07200","6.00622","0.01480"
"72.54000","6.04526","0.01362"
"73.00800","6.08418","0.01381"
"73.47600","6.12317","0.01459"
"73.94400","6.16215","0.01412"
"74.41200","6.20107","0.01454"
"74.88000","6.24017","0.01491"
"75.34800","6.27916","0.01507"
"75.81600","6.31820","0.01536"
"76.28400","6.35718","0.01542"
"76.75200","6.39616","0.01562"
"77.22000","6.43515","0.01593"
"77.68800","6.47413","0.01609"
"78.15600","6.51311","0.01613"
"78.62400","6.55222","0.01622"
"79.09200","6.59120","0.01658"
"79.56000","6.63018","0.01682"
"80.02800","6.66922","0.01711"
"80.49600","6.70821","0.01739"
"80.96400","6.74713","0.01550"
"81.43200","6.78611","0.01557"
"81.90000","6.82521","0.01683"
"82.36800","6.86426","0.01750"
"82.83600","6.90318","0.01742"
"83.30400","6.94216","0.01757"
"83.77200","6.98121","0.01845"
"84.24000","7.02019","0.01906"
"84.70800","7.05917","0.01864"
"85.17600","7.09809","0.01912"
"85.64400","7.13720","0.01975"
"86.11200","7.17618","0.01952"
"86.58000","7.21516","0.02019"
"87.04800","7.25415","0.02030"
"87.51600","7.29325","0.01872"
"87.98400","7.33223","0.01886"
"88.45200","7.37115","0.01914"
"88.92000","7.41014","0.01893"
"89.38800","7.44918","0.01910"
"89.85600","7.48822","0.01951"
"90.32400","7.52720","0.01842"
"90.79200","7.56619","0.01880"
"91.26000","7.60517","0.01931"
"91.72800","7.64415","0.01920"
"92.19600","7.68307","0.01963"
"92.66400","7.72218","0.01990"
"93.13200","7.76122","0.01986"
"93.60000","7.80014","0.02020"
"94.06800","7.83919","0.02041"
"94.53600","7.87817","0.02024"
"95.00400","7.91721","0.02024"
"95.47200","7.95613","0.02078"
"95.94000","7.99512","0.02068"
"96.40800","8.03416","0.02048"
"96.87600","8.07320","0.02083"
"97.34400","8.11218","0.02130"
"97.81200","8.15117","0.02141"
"98.28000","8.19021","0.02222"
"98.74800","8.22919","0.02211"
"99.21600","8.26812","0.02247"
"99.68400","8.30716","0.02081"
"100.15200","8.34620","0.02086"
"100.62000","8.38518","0.02152"
"101.08800","8.42422","0.02198"
"101.55600","8.46321","0.02270"
"102.02400","8.50225","0.02276"
"102.49200","8.54111","0.02278"
"102.96000","8.58010","0.02339"
"103.42800","8.61914","0.02358"
"103.89600","8.65818","0.02482"
"104.36400","8.69717","0.02507"
"104.83200","8.73621","0.02546"
"105.30000","8.77519","0.02600"
"105.76800","8.81423","0.02642"
"106.23600","8.85316","0.02684"
"106.70400","8.89208","0.01921"
"107.17200","8.93118","0.02032"
"107.64000","8.97016","0.02117"
"108.10800","9.00921","0.02188"
"108.57600","9.04819","0.02309"
"109.04400","9.08717","0.02397"
"109.51200","9.12621","0.02496"
"109.98000","9.16514","0.02548"
"110.44800","9.20412","0.02603"
"110.91600","9.24316","0.02666"
"111.38400","9.28221","0.02765"
"111.85200","9.32119","0.02733"
"112.32000","9.36017","0.02789"
"112.78800","9.39921","0.02847"
"113.25600","9.43820","0.02892"
"113.72400","9.47706","0.02889"
"114.19200","9.51616","0.02994"
"114.66000","9.55520","0.03062"
"115.12800","9.59419","0.03090"
"115.59600","9.63323","0.03241"
"116.06400","9.67221","0.03303"
"116.53200","9.71120","0.03332"
"117.00000","9.75018","0.03389"
"117.46800","9.78910","0.03525"
"117.93600","9.82820","0.03633"
"118.40400","9.86725","0.03710"
"118.87200","9.90617","0.03764"
"119.34000","9.94515","0.03831"
"119.80800","9.98425","0.03934"
"120.27600","10.02318","0.04031"
"120.74400","10.06216","0.04001"
"121.21200","10.10114","0.04106"
"121.68000","10.14012","0.04148"
"122.14800","10.17917","0.04196"
"122.61600","10.21821","0.04200"
"123.08400","10.25719","0.03032"
"123.55200","10.29624","0.02951"
"124.02000","10.33510","0.03003"
"124.48800","10.37414","0.03095"
"124.95600","10.41312","0.03146"
"125.42400","10.45217","0.03191"
"125.89200","10.49121","0.03274"
"126.36000","10.53019","0.03159"
"126.82800","10.56923","0.03239"
"127.29600","10.60822","0.03300"
"127.76400","10.64714","0.03307"
"128.23200","10.68612","0.03419"
"128.70000","10.72517","0.03489"
"129.16800","10.76415","0.03582"
"129.63600","10.80325","0.03629"
"130.10400","10.84217","0.03739"
"130.57200","10.88122","0.03807"
"131.04000","10.92020","0.03899"
"131.50800","10.95912","0.03964"
"131.97600","10.99817","0.04087"
"132.44400","11.03715","0.04069"
"132.91200","11.07619","0.04143"
"133.38000","11.11523","0.04167"
"133.84800","11.15422","0.04241"
"134.31600","11.19320","0.04398"
"134.78400","11.23218","0.04415"
"135.25200","11.27110","0.04426"
"135.72000","11.31021","0.04451"
"136.18800","11.34919","0.04582"
"136.65600","11.38811","0.04575"
"137.12400","11.42722","0.04742"
"137.59200","11.46620","0.04742"
"138.06000","11.50518","0.04823"
"138.52800","11.54416","0.04881"
"138.99600","11.58309","0.04938"
"139.46400","11.62219","0.05015"
"139.93200","11.66117","0.05085"
"140.40000","11.70015","0.05172"
"140.86800","11.73920","0.05250"
"141.33600","11.77818","0.05250"
"141.80400","11.81722","0.05305"
"142.27200","11.85614","0.05342"
"142.74000","11.89513","0.05422"
"143.20800","11.93417","0.05443"
"143.67600","11.97315","0.05486"
"144.14400","12.01219","0.05560"
"144.61200","12.05118","0.05594"
"145.08000","12.09016","0.05667"
"145.54800","12.12914","0.05645"
"146.01600","12.16813","0.05731"
"146.48400","12.20717","0.05807"
"146.95200","12.24621","0.05915"
"147.42000","12.28513","0.05974"
"147.88800","12.32424","0.06064"
"148.35600","12.36322","0.06109"
"148.82400","12.40226","0.06189"
"149.29200","12.44118","0.06241"
"149.76000","12.48011","0.06290"
"150.22800","12.51909","0.06342"
"150.69600","12.55813","0.06468"
"151.16400","12.59718","0.06548"
"151.63200","12.63616","0.06473"
"152.10000","12.67526","0.06527"
"152.56800","12.71418","0.06589"
"153.03600","12.75317","0.06626"
"153.50400","12.79215","0.06714"
"153.97200","12.83113","0.06812"
"154.44000","12.87017","0.06954"
"154.90800","12.90922","0.06966"
"155.37600","12.94820","0.07090"
"155.84400","12.98724","0.07160"
"156.31200","13.02617","0.07253"
"156.78000","13.06515","0.07371"
"157.24800","13.10413","0.07545"
"157.71600","13.14317","0.07587"
"158.18400","13.18216","0.07688"
"158.65200","13.22120","0.07796"
"159.12000","13.26024","0.08028"
"159.58800","13.29917","0.08172"
"160.05600","13.33815","0.08047"
"160.52400","13.37713","0.08211"
"160.99200","13.41617","0.08360"
"161.46000","13.45522","0.08430"
"161.92800","13.49420","0.08515"
"162.39600","13.53318","0.08582"
"162.86400","13.57222","0.08707"
"163.33200","13.61115","0.08756"
"163.80000","13.65013","0.08820"
"164.26800","13.68911","0.08893"
"164.73600","13.72816","0.09007"
"165.20400","13.76720","0.08995"
"165.67200","13.80624","0.09125"
"166.14000","13.84516","0.09153"
"166.60800","13.88421","0.09250"
"167.07600","13.92313","0.09272"
"167.54400","13.96211","0.09406"
"168.01200","14.00115","0.09443"
"168.48000","14.04020","0.09507"
"168.94800","14.07918","0.09579"
"169.41600","14.11822","0.09608"
"169.88400","14.15721","0.09645"
"170.35200","14.19625","0.09712"
"170.82000","14.23517","0.09789"
"171.28800","14.27415","0.09845"
"171.75600","14.31320","0.09902"
"172.22400","14.35218","0.09948"
"172.69200","14.39116","0.10008"
"173.16000","14.43020","0.10040"
"173.62800","14.46919","0.10072"
"174.09600","14.50823","0.10126"
"174.56400","14.54715","0.10218"
"175.03200","14.58614","0.10293"
"175.50000","14.62518","0.10307"
"175.96800","14.66416","0.10447"
"176.43600","14.70320","0.10558"
"176.90400","14.74224","0.10670"
"177.37200","14.78117","0.10810"
"177.84000","14.82021","0.10909"
"178.30800","14.85913","0.11006"
"178.77600","14.89818","0.11214"
"179.24400","14.93716","0.11286"
"179.71200","14.97614","0.11509"
"180.18000","15.01518","0.11623"
"180.64800","15.05423","0.11756"
"181.11600","15.09321","0.11958"
"181.58400","15.13219","0.12169"
"182.05200","15.17111","0.12337"
"182.52000","15.21016","0.12587"
"182.98800","15.24920","0.12907"
"183.45600","15.28818","0.13121"
"183.92400","15.32723","0.13455"
"184.39200","15.36621","0.13763"
"184.86000","15.40519","0.13941"
"185.32800","15.44417","0.14183"
"185.79600","15.48316","0.14483"
"186.26400","15.52214","0.14712"
"186.73200","15.56118","0.14951"
"187.20000","15.60017","0.15084"
"187.66800","15.63921","0.15358"
"188.13600","15.67825","0.15439"
"188.60400","15.71717","0.15696"
"189.07200","15.75616","0.15865"
"189.54000","15.79514","0.16062"
"190.00800","15.83418","0.16170"
"190.47600","15.87316","0.16357"
"190.94400","15.91221","0.16412"
"191.41200","15.95125","0.16563"
"191.88000","15.99023","0.16722"
"192.34800","16.02916","0.16907"
"192.81600","16.06814","0.17000"
"193.28400","16.10718","0.17196"
"193.75200","16.14616","0.17378"
"194.22000","16.18521","0.17528"
"194.68800","16.22419","0.17775"
"195.15600","16.26323","0.17922"
"195.62400","16.30221","0.18144"
"196.09200","16.34114","0.18388"
"196.56000","16.38012","0.18539"
"197.02800","16.41916","0.18714"
"197.49600","16.45815","0.18817"
"197.96400","16.49719","0.18648"
"198.43200","16.53617","0.18667"
"198.90000","16.57521","0.18704"
"199.36800","16.61419","0.18820"
"199.83600","16.65312","0.18917"
"200.30400","16.69216","0.19106"
"200.77200","16.73120","0.19305"
"201.24000","16.77013","0.19477"
"201.70800","16.80923","0.19561"
"202.17600","16.84815","0.19751"
"202.64400","16.88720","0.19960"
"203.11200","16.92618","0.20161"
"203.58000","16.96516","0.20259"
"204.04800","17.00420","0.20439"
"204.51600","17.04319","0.20533"
"204.98400","17.08217","0.20399"
"205.45200","17.12121","0.20344"
"205.92000","17.16019","0.20400"
"206.38800","17.19918","0.20500"
"206.85600","17.23816","0.20617"
"207.32400","17.27714","0.20716"
"207.79200","17.31618","0.20809"
"208.26000","17.35523","0.20856"
"208.72800","17.39421","0.20911"
"209.19600","17.43325","0.21049"
"209.66400","17.47223","0.21142"
"210.13200","17.51122","0.21303"
"210.60000","17.55014","0.21411"
"211.06800","17.58918","0.21623"
"211.53600","17.62817","0.21841"
"212.00400","17.66715","0.22023"
"212.47200","17.70619","0.22216"
"212.94000","17.74523","0.22374"
"213.40800","17.78422","0.22622"
"213.87600","17.82320","0.22833"
"214.34400","17.86212","0.23004"
"214.81200","17.90117","0.23192"
"215.28000","17.94015","0.22688"
"215.74800","17.97919","0.21328"
"216.21600","18.01817","0.21291"
"216.68400","18.05728","0.21429"
"217.15200","18.09620","0.21561"
"217.62000","18.13512","0.21673"
"218.08800","18.17416","0.21848"
"218.55600","18.21315","0.21772"
"219.02400","18.25219","0.21700"
"219.49200","18.29117","0.21897"
"219.96000","18.33022","0.22183"
"220.42800","18.36920","0.21630"
"220.89600","18.40818","0.21569"
"221.36400","18.44716","0.21749"
"221.83200","18.48621","0.21912"
"222.30000","18.52519","0.22055"
"222.76800","18.56417","0.22184"
"223.23600","18.60321","0.22307"
"223.70400","18.64226","0.22440"
"224.17200","18.68118","0.22657"
"224.64000","18.72016","0.22751"
"225.10800","18.75908","0.22960"
"225.57600","18.79813","0.23087"
"226.04400","18.83717","0.23208"
"226.51200","18.87615","0.23200"
"226.98000","18.91520","0.23453"
"227.44800","18.95424","0.23620"
"227.91600","18.99316","0.23687"
"228.38400","19.03214","0.23864"
"228.85200","19.07113","0.24156"
"229.32000","19.11011","0.24337"
"229.78800","19.14921","0.24475"
"230.25600","19.18820","0.24617"
"230.72400","19.22718","0.24738"
"231.19200","19.26622","0.24953"
"231.66000","19.30514","0.25152"
"232.12800","19.34419","0.25253"
"232.59600","19.38317","0.25446"
"233.06400","19.42215","0.25641"
"233.53200","19.46113","0.25784"
"234.00000","19.50018","0.26046"
"234.46800","19.53922","0.26336"
"234.93600","19.57826","0.26569"
"235.40400","19.61719","0.26759"
"235.87200","19.65617","0.27122"
"236.34000","19.69515","0.27377"
"236.80800","19.73413","0.27732"
"237.27600","19.77317","0.28173"
"237.74400","19.81222","0.28572"
"238.21200","19.85114","0.28931"
"238.68000","19.89018","0.29310"
"239.14800","19.92917","0.29567"
"239.61600","19.96815","0.29772"
"240.08400","20.00713","0.30006"
"240.55200","20.04612","0.30226"
"241.02000","20.08516","0.30337"
"241.48800","20.12426","0.30554"
"241.95600","20.16324","0.30740"
"242.42400","20.20222","0.30859"
"242.89200","20.24115","0.30968"
"243.36000","20.28013","0.31099"
"243.82800","20.31918","0.31218"
"244.29600","20.35815","0.31329"
"244.76400","20.39726","0.31366"
"245.23200","20.43618","0.31449"
"245.70000","20.47517","0.31494"
"246.16800","20.51421","0.31520"
"246.63600","20.55313","0.31587"
"247.10400","20.59217","0.31656"
"247.57200","20.63116","0.31718"
"248.04000","20.67014","0.31760"
"248.50800","20.70918","0.31871"
"248.97600","20.74822","0.31960"
"249.44400","20.78715","0.09412"
"249.91200","20.82613","0.09465"
"250.38000","20.86517","0.09549"
"250.84800","20.90415","0.09614"
"251.31600","20.94320","0.09783"
"251.78400","20.98224","0.09921"
"252.25200","21.02122","0.10017"
"252.72000","21.06020","0.10142"
"253.18800","21.09913","0.10157"
"253.65600","21.13817","0.10173"
"254.12400","21.17715","0.10241"
"254.59200","21.21620","0.10288"
"255.06000","21.25518","0.10381"
"255.52800","21.29422","0.10568"
"255.99600","21.33326","0.10222"
"256.46400","21.37225","0.10856"
"256.93200","21.41117","0.10862"
"257.40000","21.45015","0.11021"
"257.86800","21.48919","0.11175"
"258.33600","21.52812","0.11405"
"258.80400","21.56722","0.11588"
"259.27200","21.60620","0.11752"
"259.74000","21.64519","0.11848"
"260.20800","21.68423","0.12131"
"260.67600","21.72309","0.12471"
"261.14400","21.76213","0.12692"
"261.61200","21.80112","0.13013"
"262.08000","21.84016","0.13285"
"262.54800","21.87920","0.13526"
"263.01600","21.91818","0.13865"
"263.48400","21.95717","0.14117"
"263.95200","21.99621","0.14371"
"264.42000","22.03513","0.14592"
"264.88800","22.07417","0.14785"
"265.35600","22.11316","0.14926"
"265.82400","22.15208","0.15065"
"266.29200","22.19118","0.15316"
"266.76000","22.23017","0.15544"
"267.22800","22.26921","0.15678"
"267.69600","22.30819","0.15821"
"268.16400","22.34711","0.15954"
"268.63200","22.38616","0.16114"
"269.10000","22.42514","0.16271"
"269.56800","22.46418","0.16422"
"270.03600","22.50323","0.16516"
"270.50400","22.54215","0.16686"
"270.97200","22.58113","0.16827"
"271.44000","22.62011","0.16949"
"271.90800","22.65916","0.17102"
"272.37600","22.69814","0.17251"
"272.84400","22.73718","0.17368"
"273.31200","22.77617","0.17504"
"273.78000","22.81521","0.17722"
"274.24800","22.85419","0.17985"
"274.71600","22.89317","0.18130"
"275.18400","22.93216","0.18340"
"275.65200","22.97114","0.18504"
"276.12000","23.01018","0.18623"
"276.58800","23.04910","0.18810"
"277.05600","23.08821","0.18986"
"277.52400","23.12719","0.19147"
"277.99200","23.16629","0.19333"
"278.46000","23.20515","0.19416"
"278.92800","23.24414","0.19565"
"279.39600","23.28312","0.19734"
"279.86400","23.32216","0.19879"
"280.33200","23.36115","0.20030"
"280.80000","23.40019","0.20089"
"281.26800","23.43917","0.20218"
"281.73600","23.47821","0.20334"
"282.20400","23.51720","0.20416"
"282.67200","23.55618","0.20469"
"283.14000","23.59516","0.20574"
"283.60800","23.63415","0.20325"
"284.07600","23.67319","0.20422"
"284.54400","23.71223","0.20459"
"285.01200","23.75121","0.20544"
"285.48000","23.79020","0.20584"
"285.94800","23.82912","0.20616"
"286.41600","23.86816","0.20632"
"286.88400","23.90714","0.20715"
"287.35200","23.94618","0.20770"
"287.82000","23.98523","0.20784"
"288.28800","24.02421","0.20824"
"288.75600","24.06320","0.20886"
"289.22400","24.10218","0.07867"
"289.69200","24.14116","0.06188"
"290.16000","24.18014","0.06275"
"290.62800","24.21913","0.05331"
"291.09600","24.25817","0.05415"
"291.56400","24.29721","0.05487"
"292.03200","24.33619","0.06975"
"292.50000","24.37518","0.06602"
"292.96800","24.41416","0.06243"
"293.43600","24.45314","0.06236"
"293.90400","24.49218","0.06455"
"294.37200","24.53117","0.07412"
"294.84000","24.57021","0.07108"
"295.30800","24.60919","0.06850"
"295.77600","24.64823","0.07120"
"296.24400","24.68716","0.07468"
"296.71200","24.72614","0.08007"
"297.18000","24.76518","0.08292"
"297.64800","24.80416","0.07970"
"298.11600","24.84315","0.08166"
"298.58400","24.88219","0.08381"
"299.05200","24.92118","0.08609"
"299.52000","24.96022","0.08818"
"299.98800","24.99920","0.09053"
"300.45600","25.03818","0.09041"
"300.92400","25.07716","0.09177"
"301.39200","25.11615","0.09242"
"301.86000","25.15519","0.09426"
"302.32800","25.19423","0.09491"
"302.79600","25.23316","0.09598"
"303.26400","25.27220","0.09667"
"303.73200","25.31112","0.09730"
"304.20000","25.35016","0.09795"
"304.66800","25.38909","0.09894"
"305.13600","25.42813","0.09973"
"305.60400","25.46717","0.10042"
"306.07200","25.50622","0.10140"
"306.54000","25.54520","0.10211"
"307.00800","25.58418","0.10373"
"307.47600","25.62316","0.10463"
"307.94400","25.66215","0.10576"
"308.41200","25.70113","0.10655"
"308.88000","25.74011","0.10860"
"309.34800","25.77921","0.10972"
"309.81600","25.81820","0.11127"
"310.28400","25.85718","0.11335"
"310.75200","25.89622","0.11556"
"311.22000","25.93514","0.11723"
"311.68800","25.97413","0.11965"
"312.15600","26.01317","0.12134"
"312.62400","26.05215","0.12336"
"313.09200","26.09126","0.12708"
"313.56000","26.13018","0.12989"
"314.02800","26.16922","0.13401"
"314.49600","26.20820","0.13731"
"314.96400","26.24719","0.14005"
"315.43200","26.28611","0.14257"
"315.90000","26.32521","0.14530"
"316.36800","26.36420","0.14765"
"316.83600","26.40318","0.14941"
"317.30400","26.44216","0.15171"
"317.77200","26.48114","0.15394"
"318.24000","26.52019","0.15574"
"318.70800","26.55917","0.15757"
"319.17600","26.59815","0.15905"
"319.64400","26.63713","0.16026"
"320.11200","26.67624","0.16157"
"320.58000","26.71522","0.16269"
"321.04800","26.75420","0.16438"
"321.51600","26.79318","0.16619"
"321.98400","26.83217","0.16727"
"322.45200","26.87115","0.16964"
"322.92000","26.91019","0.17096"
"323.38800","26.94918","0.17230"
"323.85600","26.98822","0.17339"
"324.32400","27.02714","0.17573"
"324.79200","27.06618","0.17751"
"325.26000","27.10517","0.17900"
"325.72800","27.14415","0.18154"
"326.19600","27.18313","0.18278"
"326.66400","27.22211","0.18486"
"327.13200","27.26122","0.07708"
"327.60000","27.30020","0.07867"
"328.06800","27.33918","0.07749"
"328.53600","27.37816","0.08252"
"329.00400","27.41721","0.08210"
"329.47200","27.45613","0.08571"
"329.94000","27.49518","0.08863"
"330.40800","27.53410","0.09046"
"330.87600","27.57320","0.09140"
"331.34400","27.61218","0.09129"
"331.81200","27.65117","0.09248"
"332.28000","27.69015","0.09263"
"332.74800","27.72919","0.09375"
"333.21600","27.76818","0.09461"
"333.68400","27.80716","0.09525"
"334.15200","27.84620","0.09596"
"334.62000","27.88524","0.09728"
"335.08800","27.92416","0.09826"
"335.55600","27.96315","0.09935"
"336.02400","28.00219","0.09935"
"336.49200","28.04111","0.10051"
"336.96000","28.08010","0.10097"
"337.42800","28.11914","0.10140"
"337.89600","28.15824","0.10226"
"338.36400","28.19722","0.10322"
"338.83200","28.23621","0.10415"
"339.30000","28.27519","0.10506"
"339.76800","28.31417","0.10643"
"340.23600","28.35316","0.10759"
"340.70400","28.39220","0.10910"
"341.17200","28.43112","0.11063"
"341.64000","28.47016","0.11229"
"342.10800","28.50920","0.11340"
"342.57600","28.54825","0.11545"
"343.04400","28.58717","0.11795"
"343.51200","28.62621","0.11929"
"343.98000","28.66514","0.12172"
"344.44800","28.70418","0.12388"
"344.91600","28.74316","0.10475"
"345.38400","28.78220","0.09897"
"345.85200","28.82119","0.09882"
"346.32000","28.86023","0.09928"
"346.78800","28.89915","0.10003"
"347.25600","28.93819","0.10101"
"347.72400","28.97712","0.10134"
"348.19200","29.01616","0.10223"
"348.66000","29.05520","0.10259"
"349.12800","29.09425","0.10360"
"349.59600","29.13317","0.10443"
"350.06400","29.17215","0.10511"
"350.53200","29.21119","0.10599"
"351.00000","29.25018","0.10749"
"351.46800","29.28916","0.10806"
"351.93600","29.32814","0.10825"
"352.40400","29.36719","0.10907"
"352.87200","29.40623","0.11022"
"353.34000","29.44515","0.11206"
"353.80800","29.48419","0.11291"
"354.27600","29.52318","0.11379"
"354.74400","29.56210","0.11456"
"355.21200","29.60114","0.11571"
"355.68000","29.64018","0.11683"
"356.14800","29.67923","0.11752"
"356.61600","29.71815","0.11974"
"357.08400","29.75719","0.12062"
"357.55200","29.79618","0.12189"
"358.02000","29.83516","0.12330"
"358.48800","29.87414","0.12409"
"358.95600","29.91318","0.11932"
"359.42400","29.95217","0.10203"
"359.89200","29.99121","0.10188"
"360.36000","30.03019","0.10184"
"360.82800","30.06917","0.10199"
"361.29600","30.10822","0.10233"
"361.76400","30.14714","0.10231"
"362.23200","30.18612","0.10305"
"362.70000","30.22511","0.10246"
"363.16800","30.26421","0.10144"
"363.63600","30.30319","0.10078"
"364.10400","30.34223","0.10091"
"364.57200","30.38116","0.10095"
"365.04000","30.42020","0.09436"
"365.50800","30.45912","0.08562"
"365.97600","30.49816","0.08012"
"366.44400","30.53715","0.07516"
"366.91200","30.57619","0.07243"
"367.38000","30.61517","0.07481"
"367.84800","30.65421","0.07399"
"368.31600","30.69320","0.07414"
"368.78400","30.73218","0.07509"
"369.25200","30.77110","0.07591"
"369.72000","30.81014","0.07501"
"370.18800","30.84919","0.07491"
"370.65600","30.88817","0.07618"
"371.12400","30.92721","0.07695"
"371.59200","30.96620","0.07932"
"372.06000","31.00518","0.07811"
"372.52800","31.04410","0.07975"
"372.99600","31.08315","0.07833"
"373.46400","31.12213","0.07838"
"373.93200","31.16129","0.07713"
"374.40000","31.20021","0.07540"
"374.86800","31.23919","0.07558"
"375.33600","31.27817","0.07538"
"375.80400","31.31716","0.07584"
"376.27200","31.35614","0.07604"
"376.74000","31.39519","0.07671"
"377.20800","31.43417","0.07726"
"377.67600","31.47321","0.07647"
"378.14400","31.51219","0.07771"
"378.61200","31.55117","0.07711"
"379.08000","31.59016","0.07730"
"379.54800","31.62920","0.07575"
"380.01600","31.66806","0.07573"
"380.48400","31.70717","0.07605"
"380.95200","31.74621","0.07566"
"381.42000","31.78525","0.07694"
"381.88800","31.82417","0.07786"
"382.35600","31.86316","0.07887"
"382.82400","31.90214","0.08006"
"383.29200","31.94118","0.07764"
"383.76000","31.98016","0.07372"
"384.22800","32.01915","0.07410"
"384.69600","32.05819","0.07582"
"385.16400","32.09723","0.07791"
"385.63200","32.13622","0.07952"
"386.10000","32.17520","0.08010"
"386.56800","32.21418","0.08154"
"387.03600","32.25317","0.08298"
"387.50400","32.29214","0.08401"
"387.97200","32.33119","0.08462"
"388.44000","32.37023","0.08615"
"388.90800","32.40921","0.08645"
"389.37600","32.44820","0.08723"
"389.84400","32.48718","0.08730"
"390.31200","32.52616","0.08524"
"390.78000","32.56515","0.08493"
"391.24800","32.60413","0.08528"
"391.71600","32.64317","0.08559"
"392.18400","32.68221","0.08615"
"392.65200","32.72113","0.07958"
"393.12000","32.76018","0.07873"
"393.58800","32.79922","0.08106"
"394.05600","32.83814","0.08115"
"394.52400","32.87719","0.07937"
"394.99200","32.91611","0.07503"
"395.46000","32.95515","0.07120"
"395.92800","32.99419","0.07014"
"396.39600","33.03318","0.06985"
"396.86400","33.07222","0.06930"
"397.33200","33.11115","0.06618"
"397.80000","33.15012","0.06584"
"398.26800","33.18917","0.06653"
"398.73600","33.22815","0.06678"
"399.20400","33.26720","0.06713"
"399.67200","33.30624","0.06680"
"400.14000","33.34516","0.06602"
"400.60800","33.38420","0.06627"
"401.07600","33.42313","0.06698"
"401.54400","33.46211","0.06801"
"402.01200","33.50115","0.06809"
"402.48000","33.54019","0.06738"
"402.94800","33.57918","0.06816"
"403.41600","33.61822","0.06949"
"403.88400","33.65714","0.07045"
"404.35200","33.69619","0.07189"
"404.82000","33.73517","0.07268"
"405.28800","33.77415","0.07301"
"405.75600","33.81313","0.07221"
"406.22400","33.85223","0.07231"
"406.69200","33.89122","0.07338"
"407.16000","33.93020","0.07202"
"407.62800","33.96918","0.07135"
"408.09600","34.00823","0.07229"
"408.56400","34.04715","0.07265"
"409.03200","34.08613","0.07254"
"409.50000","34.12518","0.07237"
"409.96800","34.16422","0.07342"
"410.43600","34.20314","0.07362"
"410.90400","34.24218","0.07430"
"411.37200","34.28117","0.07556"
"411.84000","34.32015","0.07595"
"412.30800","34.35919","0.07728"
"412.77600","34.39817","0.07756"
"413.24400","34.43722","0.07639"
"413.71200","34.47620","0.07740"
"414.18000","34.51518","0.07832"
"414.64800","34.55416","0.07711"
"415.11600","34.59315","0.07277"
"415.58400","34.63207","0.07206"
"416.05200","34.67117","0.07256"
"416.52000","34.71016","0.03254"
"416.98800","34.74920","0.03954"
"417.45600","34.78818","0.03454"
"417.92400","34.82716","0.03601"
"418.39200","34.86621","0.03879"
"418.86000","34.90513","0.04189"
"419.32800","34.94417","0.04122"
"419.79600","34.98315","0.04126"
"420.26400","35.02219","0.04266"
"420.73200","35.06118","0.04357"
"421.20000","35.10016","0.04478"
"421.66800","35.13915","0.04575"
"422.13600","35.17819","0.04554"
"422.60400","35.21723","0.04624"
"423.07200","35.25610","0.04776"
"423.54000","35.29514","0.04854"
"424.00800","35.33418","0.04929"
"424.47600","35.37322","0.04973"
"424.94400","35.41220","0.05025"
"425.41200","35.45119","0.05099"
"425.88000","35.49023","0.05159"
"426.34800","35.52915","0.05249"
"426.81600","35.56820","0.05303"
"427.28400","35.60712","0.05348"
"427.75200","35.64622","0.05435"
"428.22000","35.68520","0.05525"
"428.68800","35.72419","0.05566"
"429.15600","35.76317","0.05683"
"429.62400","35.80215","0.05739"
"430.09200","35.84113","0.05812"
"430.56000","35.88012","0.05900"
"431.02800","35.91922","0.05959"
"431.49600","35.95820","0.05770"
"431.96400","35.99725","0.05864"
"432.43200","36.03623","0.05930"
"432.90000","36.07521","0.06056"
"433.36800","36.11414","0.06166"
"433.83600","36.15311","0.06219"
"434.30400","36.19216","0.06251"
"434.77200","36.23120","0.06327"
"435.24000","36.27024","0.06465"
"435.70800","36.30917","0.06541"
"436.17600","36.34821","0.06661"
"436.64400","36.38720","0.06756"
"437.11200","36.42612","0.06791"
"437.58000","36.46522","0.07020"
"438.04800","36.50414","0.07002"
"438.51600","36.54318","0.07162"
"438.98400","36.58223","0.07272"
"439.45200","36.62121","0.07439"
"439.92000","36.66019","0.07579"
"440.38800","36.69918","0.07755"
"440.85600","36.73816","0.07860"
"441.32400","36.77714","0.07988"
"441.79200","36.81618","0.08179"
"442.26000","36.85522","0.08235"
"442.72800","36.89421","0.08426"
"443.19600","36.93319","0.08447"
"443.66400","36.97217","0.08689"
"444.13200","37.01116","0.08762"
"444.60000","37.05014","0.08822"
"445.06800","37.08918","0.08906"
"445.53600","37.12822","0.09041"
"446.00400","37.16721","0.09168"
"446.47200","37.20613","0.09209"
"446.94000","37.24517","0.09288"
"447.40800","37.28421","0.09360"
"447.87600","37.32314","0.09451"
"448.34400","37.36218","0.09485"
"448.81200","37.40110","0.09534"
"449.28000","37.44021","0.09600"
"449.74800","37.47919","0.09568"
"450.21600","37.51817","0.09587"
"450.68400","37.55721","0.09558"
"451.15200","37.59614","0.09590"
"451.62000","37.63512","0.09672"
"452.08800","37.67416","0.09767"
"452.55600","37.71320","0.09802"
"453.02400","37.75225","0.09864"
"453.49200","37.79111","0.09909"
"453.96000","37.83015","0.09988"
"454.42800","37.86920","0.10043"
"454.89600","37.90818","0.10089"
"455.36400","37.94716","0.10145"
"455.83200","37.98615","0.10218"
"456.30000","38.02518","0.10270"
"456.76800","38.06423","0.10382"
"457.23600","38.10315","0.10419"
"457.70400","38.14219","0.10521"
"458.17200","38.18118","0.10565"
"458.64000","38.22010","0.10749"
"459.10800","38.25914","0.10836"
"459.57600","38.29813","0.10940"
"460.04400","38.33717","0.11111"
"460.51200","38.37621","0.11207"
"460.98000","38.41519","0.11331"
"461.44800","38.45417","0.11470"
"461.91600","38.49316","0.11636"
"462.38400","38.53214","0.11743"
"462.85200","38.57113","0.11924"
"463.32000","38.61023","0.12177"
"463.78800","38.64921","0.12232"
"464.25600","38.68819","0.12508"
"464.72400","38.72718","0.12744"
"465.19200","38.76622","0.12944"
"465.66000","38.80520","0.13194"
"466.12800","38.84412","0.13465"
"466.59600","38.88317","0.13732"
"467.06400","38.92221","0.14048"
"467.53200","38.96119","0.14271"
"468.00000","39.00024","0.14395"
"468.46800","39.03916","0.14504"
"468.93600","39.07820","0.14775"
"469.40400","39.11712","0.14870"
"469.87200","39.15616","0.15042"
"470.34000","39.19515","0.15092"
"470.80800","39.23419","0.15389"
"471.27600","39.27323","0.15583"
"471.74400","39.31221","0.02939"
"472.21200","39.35120","0.00967"
"472.68000","39.39018","0.01631"
"473.14800","39.42911","0.00921"
"473.61600","39.46815","0.01113"
"474.08400","39.50725","0.01724"
"474.55200","39.54623","0.01488"
"475.02000","39.58521","0.02584"
"475.48800","39.62420","0.01586"
"475.95600","39.66318","0.01809"
"476.42400","39.70216","0.01668"
"476.89200","39.74109","0.01362"
"477.36000","39.78012","0.02113"
"477.82800","39.81923","0.02042"
"478.29600","39.85822","0.02341"
"478.76400","39.89714","0.02354"
"479.23200","39.93618","0.01842"
"479.70000","39.97516","0.02048"
"480.16800","40.01414","0.01951"
"480.63600","40.05319","0.02228"
"481.10400","40.09217","0.02725"
"481.57200","40.13116","0.02548"
"482.04000","40.17020","0.02413"
"482.50800","40.20918","0.02242"
"482.97600","40.24822","0.02231"
"483.44400","40.28714","0.02591"
"483.91200","40.32612","0.02880"
"484.38000","40.36511","0.02831"
"484.84800","40.40415","0.02662"
"485.31600","40.44320","0.02447"
"485.78400","40.48217","0.02557"
"486.25200","40.52122","0.02866"
"486.72000","40.56020","0.03033"
"487.18800","40.59919","0.02894"
"487.65600","40.63811","0.03018"
"488.12400","40.67715","-0.00371"
"488.59200","40.71613","0.00563"
"489.06000","40.75524","0.00566"
"489.52800","40.79416","0.00653"
"489.99600","40.83320","0.00683"
"490.46400","40.87218","0.00787"
"490.93200","40.91117","0.00747"
"491.40000","40.95015","0.00807"
"491.86800","40.98913","0.00821"
"492.33600","41.02817","0.00762"
"492.80400","41.06722","0.00781"
"493.27200","41.10620","0.00803"
"493.74000","41.14518","0.00722"
"494.20800","41.18411","0.00682"
"494.67600","41.22309","0.00606"
"495.14400","41.26213","0.00605"
"495.61200","41.30117","0.00566"
"496.08000","41.34016","0.00665"
"496.54800","41.37920","0.00649"
"497.01600","41.41818","0.00685"
"497.48400","41.45716","0.00724"
"497.95200","41.49615","0.00734"
"498.42000","41.53513","0.00804"
"498.88800","41.57411","0.00791"
"499.35600","41.61321","0.00859"
"499.82400","41.65219","0.00830"
"500.29200","41.69118","0.00812"
"500.76000","41.73016","0.00799"
"501.22800","41.76921","0.00739"
"501.69600","41.80813","0.00720"
"502.16400","41.84717","0.00670"
"502.63200","41.88615","0.00714"
"503.10000","41.92520","0.00669"
"503.56800","41.96424","0.00760"
"504.03600","42.00323","0.00710"
"504.50400","42.04221","0.00721"
"504.97200","42.08118","0.00762"
"505.44000","42.12017","0.00750"
"505.90800","42.15915","0.00852"
"506.37600","42.19819","0.00824"
"506.84400","42.23718","0.00912"
"507.31200","42.27616","0.00870"
"507.78000","42.31515","0.00843"
"508.24800","42.35419","0.00844"
"508.71600","42.39317","0.00792"
"509.18400","42.43216","0.00815"
"509.65200","42.47114","0.00734"
"510.12000","42.51024","0.00762"
"510.58800","42.54922","0.00788"
"511.05600","42.58815","0.00765"
"511.52400","42.62719","0.00744"
"511.99200","42.66617","0.00750"
"512.46000","42.70515","0.00790"
"512.92800","42.74413","0.00780"
"513.39600","42.78312","0.00868"
"513.86400","42.82222","0.00860"
"514.33200","42.86120","0.00863"
"514.80000","42.90018","0.00874"
"515.26800","42.93917","0.00879"
"515.73600","42.97815","0.00870"
"516.20400","43.01714","0.00837"
"516.67200","43.05618","0.00867"
"517.14000","43.09516","0.00799"
"517.60800","43.13420","0.00850"
"518.07600","43.17319","0.00797"
"518.54400","43.21223","0.00807"
"519.01200","43.25121","0.00818"
"519.48000","43.29013","0.00844"
"519.94800","43.32912","0.00830"
"520.41600","43.36816","0.00805"
"520.88400","43.40720","0.00880"
"521.35200","43.44624","0.00880"
"521.82000","43.48517","0.00923"
"522.28800","43.52421","0.00931"
"522.75600","43.56319","0.00875"
"523.22400","43.60212","0.00886"
"523.69200","43.64116","0.00895"
"524.16000","43.68014","0.00861"
"524.62800","43.71918","0.00871"
"525.09600","43.75822","0.00854"
"525.56400","43.79715","0.00856"
"526.03200","43.83625","0.00871"
"526.50000","43.87517","0.00843"
"526.96800","43.91410","0.00864"
"527.43600","43.95314","0.00900"
"527.90400","43.99218","0.00899"
"528.37200","44.03117","0.00943"
"528.84000","44.07021","0.00929"
"529.30800","44.10919","0.00949"
"529.77600","44.14823","0.00976"
"530.24400","44.18716","0.00955"
"530.71200","44.22608","0.00938"
"531.18000","44.26518","0.00903"
"531.64800","44.30423","0.00947"
"532.11600","44.34321","0.00905"
"532.58400","44.38218","0.00920"
"533.05200","44.42117","0.00952"
"533.52000","44.46015","0.00956"
"533.98800","44.49914","0.00947"
"534.45600","44.53812","0.00929"
"534.92400","44.57716","0.00955"
"535.39200","44.61620","0.00956"
"535.86000","44.65524","0.00981"
"536.32800","44.69417","0.01019"
"536.79600","44.73315","0.01025"
"537.26400","44.77214","0.01016"
"537.73200","44.81112","0.00994"
"538.20000","44.85016","0.00987"
"538.66800","44.88921","0.00987"
"539.13600","44.92819","0.01012"
"539.60400","44.96711","0.00955"
"540.07200","45.00621","0.00994"
"540.54000","45.04520","0.00958"
"541.00800","45.08412","0.01010"
"541.47600","45.12310","0.01005"
"541.94400","45.16214","0.01032"
"542.41200","45.20124","0.01045"
"542.88000","45.24017","0.01100"
"543.34800","45.27915","0.01075"
"543.81600","45.31820","0.01081"
"544.28400","45.35718","0.01074"
"544.75200","45.39610","0.01085"
"545.22000","45.43515","0.01075"
"545.68800","45.47413","0.01037"
"546.15600","45.51317","0.01039"
"546.62400","45.55221","0.01039"
"547.09200","45.59113","0.01108"
"547.56000","45.63023","0.01081"
"548.02800","45.66916","0.01111"
"548.49600","45.70814","0.01118"
"548.96400","45.74718","0.01156"
"549.43200","45.78617","0.01158"
"549.90000","45.82521","0.01151"
"550.36800","45.86414","0.01132"
"550.83600","45.90318","0.01107"
"551.30400","45.94222","0.01150"
"551.77200","45.98114","0.01132"
"552.24000","46.02006","0.01185"
"552.70800","46.05917","0.01164"
"553.17600","46.09821","0.01166"
"553.64400","46.13719","0.01189"
"554.11200","46.17617","0.01174"
"554.58000","46.21521","0.01199"
"555.04800","46.25420","0.01246"
"555.51600","46.29313","0.01208"
"555.98400","46.33211","0.01240"
"556.45200","46.37121","0.01273"
"556.92000","46.41019","0.01247"
"557.38800","46.44923","0.01247"
"557.85600","46.48816","0.01208"
"558.32400","46.52720","0.01195"
"558.79200","46.56612","0.01209"
"559.26000","46.60510","0.01220"
"559.72800","46.64414","0.01253"
"560.19600","46.68325","0.01238"
"560.66400","46.72218","0.01266"
"561.13200","46.76122","0.01279"
"561.60000","46.80020","0.01311"
"562.06800","46.83918","0.01371"
"562.53600","46.87816","0.01285"
"563.00400","46.91709","0.01328"
"563.47200","46.95618","0.01355"
"563.94000","46.99523","0.01308"
"564.40800","47.03421","0.01378"
"564.87600","47.07314","0.01352"
"565.34400","47.11224","0.01352"
"565.81200","47.15117","0.01337"
"566.28000","47.19014","0.01391"
"566.74800","47.22913","0.01378"
"567.21600","47.26817","0.01432"
"567.68400","47.30716","0.01376"
"568.15200","47.34620","0.01399"
"568.62000","47.38517","0.01392"
"569.08800","47.42422","0.01462"
"569.55600","47.46314","0.01404"
"570.02400","47.50212","0.01474"
"570.49200","47.54111","0.01460"
"570.96000","47.58015","0.01480"
"571.42800","47.61919","0.01445"
"571.89600","47.65818","0.01496"
"572.36400","47.69722","0.01493"
"572.83200","47.73615","0.01533"
"573.30000","47.77519","0.01522"
"573.76800","47.81411","0.01576"
"574.23600","47.85321","0.01591"
"574.70400","47.89219","0.01599"
"575.17200","47.93118","0.01586"
"575.64000","47.97016","0.01628"
"576.10800","48.00920","0.01603"
"576.57600","48.04818","0.01617"
"577.04400","48.08717","0.01648"
"577.51200","48.12609","0.01681"
"577.98000","48.16519","0.01709"
"578.44800","48.20418","0.01687"
"578.91600","48.24322","0.01685"
"579.38400","48.28220","0.01753"
"579.85200","48.32118","0.01691"
"580.32000","48.36017","0.01760"
"580.78800","48.39909","0.01755"
"581.25600","48.43813","0.01796"
"581.72400","48.47711","0.01773"
"582.19200","48.51621","0.01810"
"582.66000","48.55514","0.01807"
"583.12800","48.59424","0.01850"
"583.59600","48.63316","0.01885"
"584.06400","48.67215","0.01860"
"584.53200","48.71113","0.01873"
"585.00000","48.75017","0.01887"
"585.46800","48.78922","0.01885"
"585.93600","48.82820","0.01895"
"586.40400","48.86718","0.01890"
"586.87200","48.90623","0.01921"
"587.34000","48.94521","0.01935"
"587.80800","48.98407","0.01962"
"588.27600","49.02317","0.01963"
"588.74400","49.06215","0.01984"
"589.21200","49.10120","0.01977"
"589.68000","49.14024","0.02048"
"590.14800","49.17916","0.02065"
"590.61600","49.21820","0.02049"
"591.08400","49.25719","0.02091"
"591.55200","49.29612","0.02146"
"592.02000","49.33516","0.02175"
"592.48800","49.37420","0.02209"
"592.95600","49.41324","0.02221"
"593.42400","49.45216","0.02260"
"593.89200","49.49121","0.02247"
"594.36000","49.53019","0.02314"
"594.82800","49.56917","0.02308"
"595.29600","49.60809","0.02307"
"595.76400","49.64720","0.02339"
"596.23200","49.68624","0.02508"
"596.70000","49.72516","0.02771"
"597.16800","49.76420","0.02422"
"597.63600","49.80318","0.02596"
"598.10400","49.84217","0.02552"
"598.57200","49.88115","0.02598"
"599.04000","49.92014","0.02594"
"599.50800","49.95918","0.02613"
"599.97600","49.99816","0.02495"
"600.44400","50.03720","0.02523"
"600.91200","50.07619","0.02572"
"601.38000","50.11523","0.02575"
"601.84800","50.15415","0.02626"
"602.31600","50.19313","0.02674"
"602.78400","50.23212","0.02671"
"603.25200","50.27122","0.02653"
"603.72000","50.31020","0.02694"
"604.18800","50.34918","0.02689"
"604.65600","50.38823","0.02749"
"605.12400","50.42715","0.02699"
"605.59200","50.46614","0.02732"
"606.06000","50.50512","0.02794"
"606.52800","50.54416","0.02780"
"606.99600","50.58320","0.02906"
"607.46400","50.62218","0.02923"
"607.93200","50.66117","0.03010"
"608.40000","50.70021","0.03060"
"608.86800","50.73920","0.03073"
"609.33600","50.77811","0.03115"
"609.80400","50.81715","0.03134"
"610.27200","50.85614","0.03128"
"610.74000","50.89518","0.03168"
"611.20800","50.93422","0.03196"
"611.67600","50.97315","0.03301"
"612.14400","51.01225","0.03337"
"612.61200","51.05117","0.03405"
"613.08000","51.09010","0.03512"
"613.54800","51.12914","0.03508"
"614.01600","51.16819","0.03501"
"614.48400","51.20716","0.03565"
"614.95200","51.24614","0.03675"
"615.42000","51.28519","0.03698"
"615.88800","51.32417","0.03748"
"616.35600","51.36316","0.03786"
"616.82400","51.40208","0.03771"
"617.29200","51.44118","0.03865"
"617.76000","51.48016","0.03870"
"618.22800","51.51920","0.03916"
"618.69600","51.55813","0.04006"
"619.16400","51.59723","0.04099"
"619.63200","51.63621","0.04104"
"620.10000","51.67514","0.04095"
"620.56800","51.71412","0.04161"
"621.03600","51.75316","0.04210"
"621.50400","51.79221","0.04242"
"621.97200","51.83125","0.04288"
"622.44000","51.87023","0.04344"
"622.90800","51.90921","0.04366"
"623.37600","51.94814","0.04460"
"623.84400","51.98712","0.04488"
"624.31200","52.02616","0.04533"
"624.78000","52.06520","0.04593"
"625.24800","52.10419","0.04609"
"625.71600","52.14317","0.04705"
"626.18400","52.18221","0.04673"
"626.65200","52.22120","0.04740"
"627.12000","52.26012","0.04838"
"627.58800","52.29910","0.04844"
"628.05600","52.33815","0.04915"
"628.52400","52.37725","0.04983"
"628.99200","52.41623","0.05050"
"629.46000","52.45521","0.05100"
"629.92800","52.49426","0.05156"
"630.39600","52.53318","0.05174"
"630.86400","52.57216","0.05213"
"631.33200","52.61114","0.05290"
"631.80000","52.65012","0.05330"
"632.26800","52.68916","0.05389"
"632.73600","52.72821","0.05477"
"633.20400","52.76719","0.05514"
"633.67200","52.80623","0.05592"
"634.14000","52.84516","0.05693"
"634.60800","52.88414","0.05735"
"635.07600","52.92313","0.05781"
"635.54400","52.96217","0.05875"
"636.01200","53.00115","0.06001"
"636.48000","53.04020","0.06066"
"636.94800","53.07924","0.06084"
"637.41600","53.11821","0.06236"
"637.88400","53.15714","0.06252"
"638.35200","53.19612","0.06342"
"638.82000","53.23516","0.06482"
"639.28800","53.27421","0.06537"
"639.75600","53.31319","0.06630"
"640.22400","53.35217","0.06748"
"640.69200","53.39122","0.06849"
"641.16000","53.43020","0.06958"
"641.62800","53.46912","0.07108"
"642.09600","53.50817","0.07223"
"642.56400","53.54715","0.07334"
"643.03200","53.58613","0.07456"
"643.50000","53.62518","0.07568"
"643.96800","53.66422","0.07695"
"644.43600","53.70320","0.07878"
"644.90400","53.74212","0.07988"
"645.37200","53.78111","0.06561"
"645.84000","53.82014","0.06983"
"646.30800","53.85913","0.06821"
"646.77600","53.89817","0.07444"
"647.24400","53.93721","0.07461"
"647.71200","53.97626","0.08029"
"648.18000","54.01518","0.08095"
"648.64800","54.05416","0.08376"
"649.11600","54.09315","0.08458"
"649.58400","54.13219","0.08643"
"650.05200","54.17123","0.08673"
"650.52000","54.21022","0.08770"
"650.98800","54.24913","0.08861"
"651.45600","54.28824","0.08913"
"651.92400","54.32716","0.09009"
"652.39200","54.36614","0.09052"
"652.86000","54.40513","0.09138"
"653.32800","54.44417","0.09191"
"653.79600","54.48315","0.09322"
"654.26400","54.52225","0.09324"
"654.73200","54.56118","0.09400"
"655.20000","54.60028","0.09501"
"655.66800","54.63914","0.09536"
"656.13600","54.67813","0.09596"
"656.60400","54.71711","0.09628"
"657.07200","54.75621","0.09699"
"657.54000","54.79520","0.09747"
"658.00800","54.83418","0.09795"
"658.47600","54.87322","0.09880"
"658.94400","54.91220","0.09933"
"659.41200","54.95118","0.09985"
"659.88000","54.99011","0.10064"
"660.34800","55.02921","0.10154"
"660.81600","55.06813","0.10228"
"661.28400","55.10718","0.10282"
"661.75200","55.14616","0.10406"
"662.22000","55.18520","0.10417"
"662.68800","55.22419","0.10587"
"663.15600","55.26311","0.10673"
"663.62400","55.30215","0.10778"
"664.09200","55.34113","0.10891"
"664.56000","55.38017","0.10998"
"665.02800","55.41922","0.11166"
"665.49600","55.45820","0.11118"
"665.96400","55.49718","0.11292"
"666.43200","55.53611","0.11463"
"666.90000","55.57515","0.11555"
"667.36800","55.61413","0.11720"
"667.83600","55.65318","0.11862"
"668.30400","55.69216","0.11981"
"668.77200","55.73114","0.12202"
"669.24000","55.77018","0.12371"
"669.70800","55.80917","0.12511"
"670.17600","55.84815","0.12791"
"670.64400","55.88713","0.12976"
"671.11200","55.92617","0.13197"
"671.58000","55.96522","0.13490"
"672.04800","56.00420","0.13697"
"672.51600","56.04319","0.14011"
"672.98400","56.08223","0.14208"
"673.45200","56.12120","0.14346"
"673.92000","56.16013","0.14419"
"674.38800","56.19912","0.14589"
"674.85600","56.23809","0.14739"
"675.32400","56.27719","0.14893"
"675.79200","56.31618","0.15087"
"676.26000","56.35522","0.15231"
"676.72800","56.39421","0.15371"
"677.19600","56.43319","0.15461"
"677.66400","56.47211","0.15596"
"678.13200","56.51122","0.15748"
"678.60000","56.55013","0.15716"
"679.06800","56.58918","0.15810"
"679.53600","56.62816","0.15955"
"680.00400","56.66721","0.16019"
"680.47200","56.70625","0.16167"
"680.94000","56.74517","0.16310"
"681.40800","56.78410","0.16362"
"681.87600","56.82314","0.16294"
"682.34400","56.86218","0.16447"
"682.81200","56.90122","0.16489"
"683.28000","56.94020","0.16583"
"683.74800","56.97919","0.16688"
"684.21600","57.01817","0.16742"
"684.68400","57.05715","0.16824"
"685.15200","57.09614","0.16924"
"685.62000","57.13518","0.16990"
"686.08800","57.17416","0.17124"
"686.55600","57.21314","0.17199"
"687.02400","57.25218","0.17267"
"687.49200","57.29123","0.17438"
"687.96000","57.33015","0.17528"
"688.42800","57.36914","0.17621"
"688.89600","57.40818","0.17729"
"689.36400","57.44716","0.17860"
"689.83200","57.48620","0.18022"
"690.30000","57.52524","-0.00061"
"690.76800","57.56423","-0.00005"
"691.23600","57.60321","0.00155"
"691.70400","57.64213","0.00152"
"692.17200","57.68111","0.00020"
"692.64000","57.72016","0.00160"
"693.10800","57.75920","0.00284"
"693.57600","57.79818","0.00041"
"694.04400","57.83717","0.00110"
"694.42000","57.86850","0.00243"