File: Force_trajectories/161226_2/Specimen_RawData_7.csv
End date,"12/26/2016"
Specimen label,"14CG_12"
Maximum Load,"0.33605",N

Time,Extension,Load
(s),(mm),(N)
"0.00000","0.00000","-0.00020"
"0.30600","0.02517","0.00012"
"0.61200","0.05112","0.00073"
"0.91800","0.07665","0.00127"
"1.22400","0.10206","0.00080"
"1.53000","0.12765","0.00118"
"1.83600","0.15306","0.00123"
"2.14200","0.17859","0.00177"
"2.44800","0.20418","0.00231"
"2.75400","0.22959","0.00227"
"3.06000","0.25506","0.00229"
"3.36600","0.28053","0.00218"
"3.67200","0.30612","0.00294"
"3.97800","0.33165","0.00254"
"4.28400","0.35712","0.00287"
"4.59000","0.38265","0.00375"
"4.89600","0.40812","0.00300"
"5.20200","0.43359","0.00308"
"5.50800","0.45906","0.00370"
"5.81400","0.48459","0.00348"
"6.12000","0.51012","0.00362"
"6.42600","0.53559","0.00378"
"6.73200","0.56112","0.00377"
"7.03800","0.58660","0.00425"
"7.34400","0.61219","0.00413"
"7.65000","0.63760","0.00363"
"7.95600","0.66319","0.00447"
"8.26200","0.68860","0.00418"
"8.56800","0.71407","0.00452"
"8.87400","0.73966","0.00445"
"9.18000","0.76513","0.00441"
"9.48600","0.79066","0.00504"
"9.79200","0.81607","0.00484"
"10.09800","0.84166","0.00453"
"10.40400","0.86707","0.00501"
"10.71000","0.89260","0.00496"
"11.01600","0.91819","0.00512"
"11.32200","0.94360","0.00550"
"11.62800","0.96913","0.00552"
"11.93400","0.99460","0.00598"
"12.24000","1.02013","0.00552"
"12.54600","1.04560","0.00566"
"12.85200","1.07107","0.00567"
"13.15800","1.09660","0.00551"
"13.46400","1.12207","0.00552"
"13.77000","1.14766","0.00610"
"14.07600","1.17313","0.00582"
"14.38200","1.19860","0.00619"
"14.68800","1.22407","0.00580"
"14.99400","1.24960","0.00627"
"15.30000","1.27513","0.00661"
"15.60600","1.30060","0.00646"
"15.91200","1.32613","0.00659"
"16.21800","1.35154","0.00661"
"16.52400","1.37719","0.00663"
"16.83000","1.40260","0.00678"
"17.13600","1.42813","0.00681"
"17.44200","1.45354","0.00697"
"17.74800","1.47907","0.00724"
"18.05400","1.50466","0.00688"
"18.36000","1.53013","0.00744"
"18.66600","1.55566","0.00774"
"18.97200","1.58107","0.00727"
"19.27800","1.60660","0.00761"
"19.58400","1.63213","0.00796"
"19.89000","1.65761","0.00766"
"20.19600","1.68314","0.00780"
"20.50200","1.70861","0.00752"
"20.80800","1.73414","0.00776"
"21.11400","1.75961","0.00793"
"21.42000","1.78514","0.00799"
"21.72600","1.81061","0.00798"
"22.03200","1.83608","0.00834"
"22.33800","1.86161","0.00830"
"22.64400","1.88708","0.00799"
"22.95000","1.91267","0.00830"
"23.25600","1.93808","0.00842"
"23.56200","1.96361","0.00794"
"23.86800","1.98908","0.00828"
"24.17400","2.01461","0.00873"
"24.48000","2.04014","0.00802"
"24.78600","2.06561","0.00819"
"25.09200","2.09114","0.00857"
"25.39800","2.11661","0.00846"
"25.70400","2.14214","0.00885"
"26.01000","2.16761","0.00838"
"26.31600","2.19308","0.00887"
"26.62200","2.21861","0.00824"
"26.92800","2.24414","0.00837"
"27.23400","2.26961","0.00879"
"27.54000","2.29502","0.00868"
"27.84600","2.32067","0.00872"
"28.15200","2.34608","0.00869"
"28.45800","2.37161","0.00901"
"28.76400","2.39708","0.00890"
"29.07000","2.42261","0.00868"
"29.37600","2.44808","0.00914"
"29.68200","2.47361","0.00915"
"29.98800","2.49914","0.00908"
"30.29400","2.52461","0.00892"
"30.60000","2.55008","0.00936"
"30.90600","2.57561","0.00892"
"31.21200","2.60108","0.00942"
"31.51800","2.62661","0.00974"
"31.82400","2.65202","0.00909"
"32.13000","2.67761","0.00961"
"32.43600","2.70308","0.00928"
"32.74200","2.72861","0.01005"
"33.04800","2.75414","0.00944"
"33.35400","2.77962","0.00942"
"33.66000","2.80515","0.00989"
"33.96600","2.83056","0.00979"
"34.27200","2.85615","0.00977"
"34.57800","2.88162","0.00993"
"34.88400","2.90715","0.01002"
"35.19000","2.93262","0.01020"
"35.49600","2.95809","0.00977"
"35.80200","2.98362","0.00995"
"36.10800","3.00909","0.01044"
"36.41400","3.03462","0.01002"
"36.72000","3.06009","0.01021"
"37.02600","3.08562","0.01049"
"37.33200","3.11115","0.00933"
"37.63800","3.13662","0.01005"
"37.94400","3.16215","0.01030"
"38.25000","3.18756","0.01038"
"38.55600","3.21315","0.01020"
"38.86200","3.23856","0.01074"
"39.16800","3.26415","0.01066"
"39.47400","3.28962","0.01042"
"39.78000","3.31509","0.01079"
"40.08600","3.34062","0.01058"
"40.39200","3.36609","0.01073"
"40.69800","3.39162","0.01050"
"41.00400","3.41709","0.01089"
"41.31000","3.44262","0.01106"
"41.61600","3.46815","0.01103"
"41.92200","3.49362","0.01075"
"42.22800","3.51915","0.01051"
"42.53400","3.54456","0.01077"
"42.84000","3.57009","0.01109"
"43.14600","3.59556","0.01057"
"43.45200","3.62115","0.01111"
"43.75800","3.64662","0.01110"
"44.06400","3.67215","0.01094"
"44.37000","3.69762","0.01113"
"44.67600","3.72309","0.01133"
"44.98200","3.74856","0.01081"
"45.28800","3.77403","0.01104"
"45.59400","3.79962","0.01096"
"45.90000","3.82510","0.01113"
"46.20600","3.85069","0.01129"
"46.51200","3.87610","0.01146"
"46.81800","3.90163","0.01160"
"47.12400","3.92710","0.01149"
"47.43000","3.95257","0.01110"
"47.73600","3.97816","0.01100"
"48.04200","4.00363","0.01123"
"48.34800","4.02910","0.01123"
"48.65400","4.05463","0.01156"
"48.96000","4.08010","0.01205"
"49.26600","4.10563","0.01128"
"49.57200","4.13104","0.01201"
"49.87800","4.15663","0.01158"
"50.18400","4.18210","0.01171"
"50.49000","4.20763","0.01131"
"50.79600","4.23316","0.01141"
"51.10200","4.25863","0.01103"
"51.40800","4.28416","0.01164"
"51.71400","4.30957","0.01155"
"52.02000","4.33516","0.01172"
"52.32600","4.36057","0.01129"
"52.63200","4.38616","0.01162"
"52.93800","4.41163","0.01172"
"53.24400","4.43716","0.01166"
"53.55000","4.46263","0.01204"
"53.85600","4.48804","0.01204"
"54.16200","4.51357","0.01185"
"54.46800","4.53910","0.01215"
"54.77400","4.56457","0.01175"
"55.08000","4.59010","0.01182"
"55.38600","4.61563","0.01223"
"55.69200","4.64116","0.01189"
"55.99800","4.66657","0.01171"
"56.30400","4.69216","0.01217"
"56.61000","4.71757","0.01245"
"56.91600","4.74310","0.01213"
"57.22200","4.76857","0.01196"
"57.52800","4.79416","0.01215"
"57.83400","4.81969","0.01255"
"58.14000","4.84510","0.01240"
"58.44600","4.87064","0.01233"
"58.75200","4.89604","0.01223"
"59.05800","4.92164","0.01213"
"59.36400","4.94705","0.01236"
"59.67000","4.97264","0.01268"
"59.97600","4.99817","0.01261"
"60.28200","5.02364","0.01289"
"60.58800","5.04911","0.01228"
"60.89400","5.07458","0.01258"
"61.20000","5.10017","0.01214"
"61.50600","5.12558","0.01250"
"61.81200","5.15111","0.01264"
"62.11800","5.17664","0.01270"
"62.42400","5.20211","0.01296"
"62.73000","5.22764","0.01246"
"63.03600","5.25305","0.01278"
"63.34200","5.27864","0.01252"
"63.64800","5.30411","0.01277"
"63.95400","5.32958","0.01305"
"64.26000","5.35511","0.01314"
"64.56600","5.38058","0.01275"
"64.87200","5.40617","0.01267"
"65.17800","5.43158","0.01286"
"65.48400","5.45711","0.01322"
"65.79000","5.48258","0.01297"
"66.09600","5.50811","0.01308"
"66.40200","5.53364","0.01271"
"66.70800","5.55911","0.01254"
"67.01400","5.58464","0.01285"
"67.32000","5.61011","0.01278"
"67.62600","5.63558","0.01303"
"67.93200","5.66105","0.01299"
"68.23800","5.68664","0.01322"
"68.54400","5.71211","0.01317"
"68.85000","5.73758","0.01334"
"69.15600","5.76311","0.01335"
"69.46200","5.78864","0.01322"
"69.76800","5.81411","0.01344"
"70.07400","5.83952","0.01342"
"70.38000","5.86511","0.01321"
"70.68600","5.89058","0.01349"
"70.99200","5.91611","0.01325"
"71.29800","5.94164","0.01344"
"71.60400","5.96717","0.01315"
"71.91000","5.99265","0.01329"
"72.21600","6.01812","0.01363"
"72.52200","6.04365","0.01336"
"72.82800","6.06912","0.01338"
"73.13400","6.09459","0.01356"
"73.44000","6.12012","0.01367"
"73.74600","6.14559","0.01349"
"74.05200","6.17112","0.01368"
"74.35800","6.19659","0.01364"
"74.66400","6.22212","0.01347"
"74.97000","6.24759","0.01343"
"75.27600","6.27306","0.01325"
"75.58200","6.29865","0.01378"
"75.88800","6.32412","0.01341"
"76.19400","6.34959","0.01382"
"76.50000","6.37506","0.01370"
"76.80600","6.40065","0.01418"
"77.11200","6.42606","0.01380"
"77.41800","6.45159","0.01395"
"77.72400","6.47712","0.01331"
"78.03000","6.50259","0.01374"
"78.33600","6.52818","0.01403"
"78.64200","6.55359","0.01380"
"78.94800","6.57912","0.01418"
"79.25400","6.60459","0.01383"
"79.56000","6.63012","0.01427"
"79.86600","6.65559","0.01420"
"80.17200","6.68106","0.01413"
"80.47800","6.70665","0.01408"
"80.78400","6.73206","0.01428"
"81.09000","6.75765","0.01450"
"81.39600","6.78306","0.01431"
"81.70200","6.80859","0.01431"
"82.00800","6.83406","0.01411"
"82.31400","6.85953","0.01470"
"82.62000","6.88512","0.01444"
"82.92600","6.91059","0.01392"
"83.23200","6.93612","0.01432"
"83.53800","6.96159","0.01494"
"83.84400","6.98712","0.01433"
"84.15000","7.01265","0.01409"
"84.45600","7.03813","0.01412"
"84.76200","7.06366","0.01457"
"85.06800","7.08907","0.01422"
"85.37400","7.11466","0.01452"
"85.68000","7.14013","0.01446"
"85.98600","7.16566","0.01443"
"86.29200","7.19107","0.01447"
"86.59800","7.21660","0.01471"
"86.90400","7.24213","0.01438"
"87.21000","7.26760","0.01466"
"87.51600","7.29313","0.01462"
"87.82200","7.31860","0.01450"
"88.12800","7.34413","0.01457"
"88.43400","7.36966","0.01436"
"88.74000","7.39507","0.01516"
"89.04600","7.42066","0.01503"
"89.35200","7.44613","0.01493"
"89.65800","7.47166","0.01507"
"89.96400","7.49713","0.01492"
"90.27000","7.52266","0.01509"
"90.57600","7.54807","0.01551"
"90.88200","7.57354","0.01506"
"91.18800","7.59913","0.01495"
"91.49400","7.62454","0.01527"
"91.80000","7.65013","0.01492"
"92.10600","7.67554","0.01503"
"92.41200","7.70113","0.01515"
"92.71800","7.72660","0.01523"
"93.02400","7.75213","0.01544"
"93.33000","7.77766","0.01508"
"93.63600","7.80307","0.01506"
"93.94200","7.82860","0.01517"
"94.24800","7.85407","0.01515"
"94.55400","7.87972","0.01524"
"94.86000","7.90513","0.01546"
"95.16600","7.93066","0.01545"
"95.47200","7.95613","0.01552"
"95.77800","7.98160","0.01492"
"96.08400","8.00713","0.01542"
"96.39000","8.03254","0.01535"
"96.69600","8.05813","0.01584"
"97.00200","8.08360","0.01542"
"97.30800","8.10913","0.01545"
"97.61400","8.13461","0.01547"
"97.92000","8.16008","0.01542"
"98.22600","8.18567","0.01543"
"98.53200","8.21108","0.01539"
"98.83800","8.23661","0.01576"
"99.14400","8.26208","0.01549"
"99.45000","8.28761","0.01559"
"99.75600","8.31308","0.01563"
"100.06200","8.33861","0.01557"
"100.36800","8.36414","0.01565"
"100.67400","8.38955","0.01571"
"100.98000","8.41514","0.01589"
"101.28600","8.44061","0.01559"
"101.59200","8.46620","0.01561"
"101.89800","8.49161","0.01558"
"102.20400","8.51708","0.01557"
"102.51000","8.54267","0.01572"
"102.81600","8.56808","0.01568"
"103.12200","8.59361","0.01550"
"103.42800","8.61908","0.01563"
"103.73400","8.64467","0.01548"
"104.04000","8.67014","0.01526"
"104.34600","8.69561","0.01522"
"104.65200","8.72114","0.01563"
"104.95800","8.74661","0.01569"
"105.26400","8.77208","0.01519"
"105.57000","8.79755","0.01546"
"105.87600","8.82314","0.01551"
"106.18200","8.84861","0.01535"
"106.48800","8.87414","0.01560"
"106.79400","8.89961","0.01517"
"107.10000","8.92508","0.01577"
"107.40600","8.95061","0.01582"
"107.71200","8.97602","0.01550"
"108.01800","9.00161","0.01573"
"108.32400","9.02708","0.01597"
"108.63000","9.05261","0.01563"
"108.93600","9.07814","0.01541"
"109.24200","9.10361","0.01576"
"109.54800","9.12914","0.01563"
"109.85400","9.15455","0.01562"
"110.16000","9.18014","0.01531"
"110.46600","9.20562","0.01569"
"110.77200","9.23115","0.01571"
"111.07800","9.25667","0.01521"
"111.38400","9.28209","0.01553"
"111.69000","9.30762","0.01565"
"111.99600","9.33309","0.01539"
"112.30200","9.35862","0.01488"
"112.60800","9.38409","0.01510"
"112.91400","9.40962","0.01495"
"113.22000","9.43509","0.01484"
"113.52600","9.46062","0.01440"
"113.83200","9.48609","0.01486"
"114.13800","9.51156","0.01470"
"114.44400","9.53709","0.01489"
"114.75000","9.56256","0.01450"
"115.05600","9.58809","0.01493"
"115.36200","9.61362","0.01424"
"115.66800","9.63915","0.01416"
"115.97400","9.66468","0.01489"
"116.28000","9.69003","0.01439"
"116.58600","9.71562","0.01423"
"116.89200","9.74109","0.01423"
"117.19800","9.76656","0.01445"
"117.50400","9.79215","0.01471"
"117.81000","9.81762","0.01457"
"118.11600","9.84315","0.01464"
"118.42200","9.86856","0.01504"
"118.72800","9.89409","0.01499"
"119.03400","9.91950","0.01474"
"119.34000","9.94515","0.01462"
"119.64600","9.97062","0.01462"
"119.95200","9.99615","0.01502"
"120.25800","10.02162","0.01436"
"120.56400","10.04709","0.01419"
"120.87000","10.07262","0.01473"
"121.17600","10.09803","0.01475"
"121.48200","10.12362","0.01487"
"121.78800","10.14909","0.01453"
"122.09400","10.17462","0.01493"
"122.40000","10.20015","0.01444"
"122.70600","10.22556","0.01498"
"123.01200","10.25115","0.01478"
"123.31800","10.27657","0.01477"
"123.62400","10.30216","0.01490"
"123.93000","10.32763","0.01515"
"124.23600","10.35310","0.01473"
"124.54200","10.37863","0.01449"
"124.84800","10.40416","0.01466"
"125.15400","10.42963","0.01507"
"125.46000","10.45510","0.01483"
"125.76600","10.48069","0.01484"
"126.07200","10.50610","0.01533"
"126.37800","10.53163","0.01533"
"126.68400","10.55716","0.01530"
"126.99000","10.58263","0.01518"
"127.29600","10.60816","0.01497"
"127.60200","10.63351","0.01512"
"127.90800","10.65916","0.01502"
"128.21400","10.68457","0.01551"
"128.52000","10.71010","0.01537"
"128.82600","10.73563","0.01544"
"129.13200","10.76110","0.01515"
"129.43800","10.78663","0.01544"
"129.74400","10.81210","0.01505"
"130.05000","10.83763","0.01540"
"130.35600","10.86310","0.01510"
"130.66200","10.88863","0.01505"
"130.96800","10.91410","0.01529"
"131.27400","10.93963","0.01521"
"131.58000","10.96516","0.01540"
"131.88600","10.99057","0.01536"
"132.19200","11.01610","0.01514"
"132.49800","11.04157","0.01529"
"132.80400","11.06716","0.01523"
"133.11000","11.09263","0.01534"
"133.41600","11.11810","0.01553"
"133.72200","11.14363","0.01511"
"134.02800","11.16910","0.01524"
"134.33400","11.19463","0.01572"
"134.64000","11.22010","0.01557"
"134.94600","11.24563","0.01556"
"135.25200","11.27110","0.01537"
"135.55800","11.29657","0.01543"
"135.86400","11.32216","0.01551"
"136.17000","11.34758","0.01580"
"136.47600","11.37322","0.01559"
"136.78200","11.39858","0.01562"
"137.08800","11.42417","0.01552"
"137.39400","11.44963","0.01582"
"137.70000","11.47511","0.01594"
"138.00600","11.50064","0.01552"
"138.31200","11.52611","0.01591"
"138.61800","11.55170","0.01566"
"138.92400","11.57711","0.01575"
"139.23000","11.60264","0.01548"
"139.53600","11.62811","0.01541"
"139.84200","11.65364","0.01545"
"140.14800","11.67911","0.01535"
"140.45400","11.70464","0.01555"
"140.76000","11.73017","0.01543"
"141.06600","11.75558","0.01558"
"141.37200","11.78111","0.01584"
"141.67800","11.80658","0.01552"
"141.98400","11.83205","0.01567"
"142.29000","11.85758","0.01562"
"142.59600","11.88305","0.01570"
"142.90200","11.90864","0.01573"
"143.20800","11.93411","0.01587"
"143.51400","11.95964","0.01549"
"143.82000","11.98511","0.01569"
"144.12600","12.01058","0.01564"
"144.43200","12.03611","0.01552"
"144.73800","12.06158","0.01558"
"145.04400","12.08711","0.01589"
"145.35000","12.11258","0.01584"
"145.65600","12.13817","0.01584"
"145.96200","12.16358","0.01587"
"146.26800","12.18911","0.01572"
"146.57400","12.21458","0.01613"
"146.88000","12.24005","0.01582"
"147.18600","12.26558","0.01552"
"147.49200","12.29111","0.01579"
"147.79800","12.31670","0.01588"
"148.10400","12.34212","0.01602"
"148.41000","12.36758","0.01641"
"148.71600","12.39311","0.01599"
"149.02200","12.41865","0.01621"
"149.32800","12.44411","0.01595"
"149.63400","12.46959","0.01603"
"149.94000","12.49518","0.01562"
"150.24600","12.52059","0.01601"
"150.55200","12.54612","0.01605"
"150.85800","12.57165","0.01617"
"151.16400","12.59706","0.01563"
"151.47000","12.62259","0.01592"
"151.77600","12.64806","0.01601"
"152.08200","12.67365","0.01615"
"152.38800","12.69906","0.01602"
"152.69400","12.72465","0.01608"
"153.00000","12.75012","0.01598"
"153.30600","12.77559","0.01644"
"153.61200","12.80118","0.01619"
"153.91800","12.82659","0.01608"
"154.22400","12.85212","0.01567"
"154.53000","12.87759","0.01588"
"154.83600","12.90312","0.01582"
"155.14200","12.92865","0.01583"
"155.44800","12.95412","0.01604"
"155.75400","12.97959","0.01619"
"156.06000","13.00512","0.01615"
"156.36600","13.03065","0.01579"
"156.67200","13.05606","0.01607"
"156.97800","13.08165","0.01610"
"157.28400","13.10712","0.01627"
"157.59000","13.13265","0.01616"
"157.89600","13.15812","0.01620"
"158.20200","13.18359","0.01620"
"158.50800","13.20906","0.01605"
"158.81400","13.23459","0.01633"
"159.12000","13.26012","0.01654"
"159.42600","13.28559","0.01649"
"159.73200","13.31112","0.01630"
"160.03800","13.33665","0.01629"
"160.34400","13.36212","0.01650"
"160.65000","13.38759","0.01658"
"160.95600","13.41306","0.01670"
"161.26200","13.43859","0.01654"
"161.56800","13.46407","0.01626"
"161.87400","13.48965","0.01691"
"162.18000","13.51513","0.01637"
"162.48600","13.54060","0.01675"
"162.79200","13.56612","0.01670"
"163.09800","13.59160","0.01656"
"163.40400","13.61713","0.01679"
"163.71000","13.64260","0.01675"
"164.01600","13.66813","0.01661"
"164.32200","13.69360","0.01689"
"164.62800","13.71913","0.01677"
"164.93400","13.74460","0.01649"
"165.24000","13.77013","0.01670"
"165.54600","13.79560","0.01623"
"165.85200","13.82101","0.01584"
"166.15800","13.84660","0.01618"
"166.46400","13.87213","0.01640"
"166.77000","13.89760","0.01653"
"167.07600","13.92313","0.01613"
"167.38200","13.94860","0.01646"
"167.68800","13.97413","0.01527"
"167.99400","13.99954","0.01600"
"168.30000","14.02513","0.01608"
"168.60600","14.05066","0.01562"
"168.91200","14.07613","0.01557"
"169.21800","14.10166","0.01647"
"169.52400","14.12713","0.01623"
"169.83000","14.15266","0.01632"
"170.13600","14.17801","0.01635"
"170.44200","14.20366","0.01621"
"170.74800","14.22913","0.01623"
"171.05400","14.25466","0.01643"
"171.36000","14.28013","0.01637"
"171.66600","14.30554","0.01649"
"171.97200","14.33113","0.01643"
"172.27800","14.35654","0.01656"
"172.58400","14.38213","0.01664"
"172.89000","14.40760","0.01679"
"173.19600","14.43313","0.01675"
"173.50200","14.45860","0.01660"
"173.80800","14.48413","0.01688"
"174.11400","14.50961","0.01691"
"174.42000","14.53502","0.01637"
"174.72600","14.56060","0.01571"
"175.03200","14.58608","0.01594"
"175.33800","14.61166","0.01586"
"175.64400","14.63714","0.01603"
"175.95000","14.66267","0.01638"
"176.25600","14.68814","0.01609"
"176.56200","14.71355","0.01611"
"176.86800","14.73914","0.01656"
"177.17400","14.76461","0.01652"
"177.48000","14.79014","0.01650"
"177.78600","14.81567","0.01633"
"178.09200","14.84114","0.01675"
"178.39800","14.86667","0.01668"
"178.70400","14.89208","0.01714"
"179.01000","14.91761","0.01661"
"179.31600","14.94302","0.01656"
"179.62200","14.96861","0.01682"
"179.92800","14.99408","0.01702"
"180.23400","15.01967","0.01722"
"180.54000","15.04514","0.01697"
"180.84600","15.07061","0.01718"
"181.15200","15.09614","0.01678"
"181.45800","15.12161","0.01736"
"181.76400","15.14714","0.01744"
"182.07000","15.17261","0.01740"
"182.37600","15.19814","0.01767"
"182.68200","15.22361","0.01735"
"182.98800","15.24902","0.01767"
"183.29400","15.27461","0.01771"
"183.60000","15.30008","0.01773"
"183.90600","15.32561","0.01776"
"184.21200","15.35108","0.01802"
"184.51800","15.37661","0.01842"
"184.82400","15.40214","0.01820"
"185.13000","15.42755","0.01794"
"185.43600","15.45308","0.01831"
"185.74200","15.47855","0.01825"
"186.04800","15.50414","0.01829"
"186.35400","15.52961","0.01830"
"186.66000","15.55515","0.01854"
"186.96600","15.58067","0.01859"
"187.27200","15.60608","0.01854"
"187.57800","15.63167","0.01853"
"187.88400","15.65708","0.01899"
"188.19000","15.68268","0.01871"
"188.49600","15.70803","0.01905"
"188.80200","15.73361","0.01894"
"189.10800","15.75909","0.01876"
"189.41400","15.78462","0.01891"
"189.72000","15.81015","0.01916"
"190.02600","15.83556","0.01881"
"190.33200","15.86115","0.01951"
"190.63800","15.88656","0.01934"
"190.94400","15.91209","0.01922"
"191.25000","15.93762","0.01967"
"191.55600","15.96309","0.01969"
"191.86200","15.98868","0.01977"
"192.16800","16.01403","0.01962"
"192.47400","16.03962","0.01954"
"192.78000","16.06509","0.01994"
"193.08600","16.09062","0.01974"
"193.39200","16.11609","0.02002"
"193.69800","16.14156","0.01989"
"194.00400","16.16715","0.02003"
"194.31000","16.19262","0.02038"
"194.61600","16.21809","0.02028"
"194.92200","16.24356","0.02022"
"195.22800","16.26909","0.01941"
"195.53400","16.29462","0.01923"
"195.84000","16.32009","0.01961"
"196.14600","16.34562","0.01956"
"196.45200","16.37109","0.02001"
"196.75800","16.39662","0.02013"
"197.06400","16.42203","0.01994"
"197.37000","16.44762","0.02048"
"197.67600","16.47309","0.02055"
"197.98200","16.49862","0.02034"
"198.28800","16.52415","0.02091"
"198.59400","16.54962","0.02111"
"198.90000","16.57515","0.02118"
"199.20600","16.60062","0.02149"
"199.51200","16.62615","0.02169"
"199.81800","16.65156","0.02136"
"200.12400","16.67710","0.02200"
"200.43000","16.70262","0.02221"
"200.73600","16.72816","0.02244"
"201.04200","16.75368","0.02229"
"201.34800","16.77909","0.02237"
"201.65400","16.80469","0.02264"
"201.96000","16.83010","0.02340"
"202.26600","16.85557","0.02390"
"202.57200","16.88116","0.02347"
"202.87800","16.90657","0.02353"
"203.18400","16.93216","0.02400"
"203.49000","16.95763","0.02400"
"203.79600","16.98316","0.02478"
"204.10200","17.00863","0.02506"
"204.40800","17.03410","0.02552"
"204.71400","17.05963","0.02604"
"205.02000","17.08510","0.02586"
"205.32600","17.11063","0.02621"
"205.63200","17.13604","0.02695"
"205.93800","17.16163","0.02772"
"206.24400","17.18710","0.02893"
"206.55000","17.21257","0.02906"
"206.85600","17.23810","0.02994"
"207.16200","17.26357","0.03011"
"207.46800","17.28916","0.03108"
"207.77400","17.31463","0.03227"
"208.08000","17.34016","0.03308"
"208.38600","17.36557","0.03362"
"208.69200","17.39110","0.03437"
"208.99800","17.41657","0.03508"
"209.30400","17.44210","0.03556"
"209.61000","17.46763","0.03625"
"209.91600","17.49310","0.03746"
"210.22200","17.51863","0.03880"
"210.52800","17.54410","0.03998"
"210.83400","17.56957","0.04100"
"211.14000","17.59510","0.04132"
"211.44600","17.62057","0.04326"
"211.75200","17.64610","0.04461"
"212.05800","17.67157","0.04617"
"212.36400","17.69716","0.04731"
"212.67000","17.72257","0.04818"
"212.97600","17.74810","0.04885"
"213.28200","17.77363","0.05029"
"213.58800","17.79910","0.05120"
"213.89400","17.82463","0.05309"
"214.20000","17.85011","0.05341"
"214.50600","17.87564","0.05410"
"214.81200","17.90111","0.05554"
"215.11800","17.92664","0.05688"
"215.42400","17.95205","0.05715"
"215.73000","17.97758","0.05842"
"216.03600","18.00311","0.05954"
"216.34200","18.02858","0.06065"
"216.64800","18.05411","0.06144"
"216.95400","18.07958","0.06272"
"217.26000","18.10511","0.06440"
"217.56600","18.13064","0.06557"
"217.87200","18.15611","0.06633"
"218.17800","18.18164","0.06731"
"218.48400","18.20711","0.06836"
"218.79000","18.23264","0.07050"
"219.09600","18.25811","0.07149"
"219.40200","18.28364","0.07271"
"219.70800","18.30911","0.07446"
"220.01400","18.33458","0.07590"
"220.32000","18.36011","0.07785"
"220.62600","18.38558","0.07950"
"220.93200","18.41117","0.08150"
"221.23800","18.43652","0.08331"
"221.54400","18.46217","0.08535"
"221.85000","18.48764","0.08717"
"222.15600","18.51317","0.08883"
"222.46200","18.53864","0.08703"
"222.76800","18.56411","0.08784"
"223.07400","18.58958","0.08978"
"223.38000","18.61505","0.09178"
"223.68600","18.64064","0.09408"
"223.99200","18.66611","0.09567"
"224.29800","18.69164","0.09699"
"224.60400","18.71711","0.09883"
"224.91000","18.74258","0.10059"
"225.21600","18.76811","0.10129"
"225.52200","18.79353","0.10263"
"225.82800","18.81911","0.10325"
"226.13400","18.84458","0.10445"
"226.44000","18.87012","0.10560"
"226.74600","18.89559","0.10626"
"227.05200","18.92111","0.10709"
"227.35800","18.94665","0.10781"
"227.66400","18.97206","0.10875"
"227.97000","18.99759","0.10963"
"228.27600","19.02306","0.11007"
"228.58200","19.04865","0.11078"
"228.88800","19.07412","0.11200"
"229.19400","19.09965","0.11310"
"229.50000","19.12518","0.11426"
"229.80600","19.15059","0.11596"
"230.11200","19.17612","0.11698"
"230.41800","19.20153","0.11807"
"230.72400","19.22718","0.11985"
"231.03000","19.25265","0.12153"
"231.33600","19.27812","0.12366"
"231.64200","19.30365","0.12587"
"231.94800","19.32906","0.12828"
"232.25400","19.35459","0.13063"
"232.56000","19.38006","0.13384"
"232.86600","19.40565","0.13733"
"233.17200","19.43112","0.14073"
"233.47800","19.45665","0.14407"
"233.78400","19.48212","0.14749"
"234.09000","19.50759","0.14998"
"234.39600","19.53312","0.15360"
"234.70200","19.55853","0.15625"
"235.00800","19.58412","0.15811"
"235.31400","19.60959","0.16059"
"235.62000","19.63518","0.16274"
"235.92600","19.66065","0.16470"
"236.23200","19.68606","0.16642"
"236.53800","19.71159","0.16832"
"236.84400","19.73706","0.17010"
"237.15000","19.76259","0.17146"
"237.45600","19.78806","0.17301"
"237.76200","19.81365","0.17485"
"238.06800","19.83912","0.17615"
"238.37400","19.86459","0.17769"
"238.68000","19.89012","0.17743"
"238.98600","19.91553","0.15978"
"239.29200","19.94113","0.10716"
"239.59800","19.96653","0.10870"
"239.90400","19.99218","0.11241"
"240.21000","20.01765","0.11201"
"240.51600","20.04313","0.11500"
"240.82200","20.06866","0.11668"
"241.12800","20.09407","0.11742"
"241.43400","20.11966","0.12140"
"241.74000","20.14513","0.12166"
"242.04600","20.17066","0.12203"
"242.35200","20.19613","0.12771"
"242.65800","20.22166","0.12660"
"242.96400","20.24713","0.12701"
"243.27000","20.27260","0.13340"
"243.57600","20.29813","0.13273"
"243.88200","20.32354","0.13369"
"244.18800","20.34907","0.14133"
"244.49400","20.37460","0.14106"
"244.80000","20.40013","0.14130"
"245.10600","20.42566","0.14830"
"245.41200","20.45107","0.14878"
"245.71800","20.47660","0.15003"
"246.02400","20.50213","0.15444"
"246.33000","20.52760","0.15708"
"246.63600","20.55313","0.15699"
"246.94200","20.57860","0.16071"
"247.24800","20.60419","0.16345"
"247.55400","20.62960","0.16407"
"247.86000","20.65513","0.16518"
"248.16600","20.68054","0.16872"
"248.47200","20.70613","0.16909"
"248.77800","20.73160","0.16940"
"249.08400","20.75713","0.17172"
"249.39000","20.78260","0.17430"
"249.69600","20.80807","0.17369"
"250.00200","20.83366","0.17541"
"250.30800","20.85907","0.17723"
"250.61400","20.88466","0.17847"
"250.92000","20.91007","0.17954"
"251.22600","20.93560","0.18112"
"251.53200","20.96113","0.18438"
"251.83800","20.98660","0.18539"
"252.14400","21.01213","0.18680"
"252.45000","21.03761","0.18943"
"252.75600","21.06314","0.19241"
"253.06200","21.08861","0.19362"
"253.36800","21.11414","0.19516"
"253.67400","21.13961","0.19783"
"253.98000","21.16508","0.19972"
"254.28600","21.19066","0.20112"
"254.59200","21.21608","0.20340"
"254.89800","21.24161","0.20539"
"255.20400","21.26708","0.20758"
"255.51000","21.29261","0.20890"
"255.81600","21.31814","0.21055"
"256.12200","21.34361","0.21156"
"256.42800","21.36920","0.21280"
"256.73400","21.39455","0.21365"
"257.04000","21.42014","0.21460"
"257.34600","21.44555","0.21547"
"257.65200","21.47114","0.21665"
"257.95800","21.49655","0.21774"
"258.26400","21.52208","0.21858"
"258.57000","21.54767","0.21923"
"258.87600","21.57308","0.22071"
"259.18200","21.59861","0.22265"
"259.48800","21.62408","0.22386"
"259.79400","21.64961","0.22493"
"260.10000","21.67508","0.22751"
"260.40600","21.70061","0.22915"
"260.71200","21.72614","0.23063"
"261.01800","21.75161","0.23217"
"261.32400","21.77714","0.23331"
"261.63000","21.80255","0.23462"
"261.93600","21.82808","0.23610"
"262.24200","21.85361","0.23719"
"262.54800","21.87908","0.23941"
"262.85400","21.90461","0.23995"
"263.16000","21.93008","0.24114"
"263.46600","21.95567","0.24284"
"263.77200","21.98108","0.24495"
"264.07800","22.00667","0.24735"
"264.38400","22.03208","0.24923"
"264.69000","22.05761","0.25163"
"264.99600","22.08315","0.25287"
"265.30200","22.10861","0.25495"
"265.60800","22.13415","0.25636"
"265.91400","22.15956","0.25744"
"266.22000","22.18515","0.25900"
"266.52600","22.21062","0.26072"
"266.83200","22.23609","0.26268"
"267.13800","22.26162","0.26433"
"267.44400","22.28709","0.26622"
"267.75000","22.31268","0.26768"
"268.05600","22.33809","0.26949"
"268.36200","22.36368","0.27121"
"268.66800","22.38909","0.27288"
"268.97400","22.41462","0.27498"
"269.28000","22.44015","0.27729"
"269.58600","22.46562","0.27860"
"269.89200","22.49115","0.28002"
"270.19800","22.51656","0.28234"
"270.50400","22.54209","0.28516"
"270.81000","22.56762","0.28901"
"271.11600","22.59309","0.29173"
"271.42200","22.61856","0.29331"
"271.72800","22.64403","0.29580"
"272.03400","22.66962","0.29555"
"272.34000","22.69509","0.29708"
"272.64600","22.72062","0.29829"
"272.95200","22.74609","0.30175"
"273.25800","22.77162","0.30475"
"273.56400","22.79709","0.30713"
"273.87000","22.82262","0.30987"
"274.17600","22.84809","0.31188"
"274.48200","22.87356","0.31438"
"274.78800","22.89915","0.31553"
"275.09400","22.92462","0.31764"
"275.40000","22.95015","0.31911"
"275.70600","22.97556","0.32042"
"276.01200","23.00109","0.32171"
"276.31800","23.02662","0.32245"
"276.62400","23.05210","0.32327"
"276.93000","23.07768","0.32424"
"277.23600","23.10310","0.32498"
"277.54200","23.12863","0.32582"
"277.84800","23.15409","0.32727"
"278.15400","23.17962","0.32846"
"278.46000","23.20515","0.33041"
"278.76600","23.23062","0.33228"
"279.07200","23.25616","0.33408"
"279.37800","23.28157","0.33597"
"279.68400","23.30716","0.04109"
"279.99000","23.33263","0.04901"
"280.29600","23.35810","0.05683"
"280.60200","23.38363","0.04243"
"280.90800","23.40904","0.04370"
"281.21400","23.43463","0.04959"
"281.52000","23.46010","0.05978"
"281.82600","23.48563","0.05594"
"282.13200","23.51110","0.05535"
"282.43800","23.53663","0.05144"
"282.74400","23.56216","0.05593"
"283.05000","23.58763","0.05724"
"283.35600","23.61316","0.06085"
"283.66200","23.63857","0.06186"
"283.96800","23.66416","0.06441"
"284.27400","23.68963","0.06318"
"284.58000","23.71510","0.06556"
"284.88600","23.74063","0.06429"
"285.19200","23.76610","0.06605"
"285.49800","23.79163","0.06723"
"285.80400","23.81710","0.06820"
"286.11000","23.84269","0.07120"
"286.41600","23.86810","0.07115"
"286.72200","23.89363","0.07448"
"287.02800","23.91910","0.07338"
"287.33400","23.94457","0.07655"
"287.64000","23.97010","0.07592"
"287.94600","23.99557","0.07985"
"288.25200","24.02110","0.07888"
"288.55800","24.04663","0.08213"
"288.86400","24.07216","0.08301"
"289.17000","24.09757","0.08461"
"289.47600","24.12310","0.08658"
"289.78200","24.14863","0.08728"
"290.08800","24.17404","0.09081"
"290.39400","24.19963","0.09006"
"290.70000","24.22504","0.09320"
"291.00600","24.25063","0.09311"
"291.31200","24.27611","0.09496"
"291.61800","24.30163","0.09564"
"291.92400","24.32717","0.09700"
"292.23000","24.35258","0.09864"
"292.53600","24.37810","0.09917"
"292.84200","24.40358","0.10046"
"293.14800","24.42917","0.10079"
"293.45400","24.45457","0.10214"
"293.76000","24.48011","0.10285"
"294.06600","24.50564","0.10357"
"294.37200","24.53111","0.10455"
"294.67800","24.55658","0.10428"
"294.98400","24.58205","0.10602"
"295.29000","24.60764","0.10553"
"295.59600","24.63317","0.10663"
"295.90200","24.65864","0.10698"
"296.20800","24.68417","0.10749"
"296.51400","24.70964","0.10849"
"296.82000","24.73511","0.10888"
"297.12600","24.76058","0.10930"
"297.43200","24.78611","0.10992"
"297.73800","24.81164","0.11041"
"298.04400","24.83711","0.11159"
"298.35000","24.86264","0.11223"
"298.65600","24.88811","0.11276"
"298.96200","24.91364","0.11394"
"299.26800","24.93905","0.11447"
"299.57400","24.96464","0.11597"
"299.88000","24.99011","0.11728"
"300.18600","25.01564","0.11824"
"300.49200","25.04117","0.12009"
"300.79800","25.06658","0.12222"
"301.10400","25.09211","0.12373"
"301.41000","25.11758","0.12584"
"301.71600","25.14311","0.12745"
"302.02200","25.16858","0.12884"
"302.32800","25.19411","0.13139"
"302.63400","25.21964","0.13353"
"302.94000","25.24512","0.13581"
"303.24600","25.27065","0.13736"
"303.55200","25.29605","0.14050"
"303.85800","25.32165","0.14149"
"304.16400","25.34705","0.14061"
"304.47000","25.37264","0.06566"
"304.77600","25.39812","0.05911"
"305.08200","25.42365","0.06480"
"305.38800","25.44917","0.06064"
"305.69400","25.47459","0.06132"
"306.00000","25.50018","0.06469"
"306.30600","25.52559","0.06205"
"306.61200","25.55112","0.06704"
"306.91800","25.57665","0.06730"
"307.22400","25.60218","0.06771"
"307.53000","25.62771","0.07286"
"307.83600","25.65306","0.07191"
"308.14200","25.67859","0.07423"
"308.44800","25.70400","0.07682"
"308.75400","25.72965","0.07690"
"309.06000","25.75512","0.08079"
"309.36600","25.78065","0.08137"
"309.67200","25.80612","0.08116"
"309.97800","25.83159","0.08622"
"310.28400","25.85712","0.08631"
"310.59000","25.88259","0.08824"
"310.89600","25.90812","0.09116"
"311.20200","25.93359","0.09147"
"311.50800","25.95912","0.09369"
"311.81400","25.98465","0.09599"
"312.12000","26.01006","0.09736"
"312.42600","26.03565","0.09898"
"312.73200","26.06106","0.10083"
"313.03800","26.08659","0.10163"
"313.34400","26.11206","0.10283"
"313.65000","26.13765","0.10417"
"313.95600","26.16312","0.10489"
"314.26200","26.18859","0.10581"
"314.56800","26.21412","0.10683"
"314.87400","26.23953","0.10757"
"315.18000","26.26512","0.10920"
"315.48600","26.29059","0.10974"
"315.79200","26.31612","0.11070"
"316.09800","26.34165","0.11254"
"316.40400","26.36712","0.11344"
"316.71000","26.39266","0.11539"
"317.01600","26.41806","0.11623"
"317.32200","26.44366","0.11829"
"317.62800","26.46906","0.12078"
"317.93400","26.49460","0.12291"
"318.24000","26.52007","0.12546"
"318.54600","26.54560","0.12835"
"318.85200","26.57119","0.13171"
"319.15800","26.59654","0.13542"
"319.46400","26.62213","0.13923"
"319.77000","26.64760","0.14335"
"320.07600","26.67313","0.14774"
"320.38200","26.69860","0.15211"
"320.68800","26.72407","0.15401"
"320.99400","26.74966","0.15696"
"321.30000","26.77507","0.16069"
"321.60600","26.80060","0.16266"
"321.91200","26.82613","0.16467"
"322.21800","26.85160","0.15410"
"322.52400","26.87707","0.14657"
"322.83000","26.90260","0.12228"
"323.13600","26.92813","0.12442"
"323.44200","26.95360","0.12885"
"323.74800","26.97913","0.13256"
"324.05400","27.00454","0.13498"
"324.36000","27.03013","0.14036"
"324.66600","27.05560","0.14400"
"324.97200","27.08107","0.14657"
"325.27800","27.10660","0.14836"
"325.58400","27.13201","0.15173"
"325.89000","27.15760","0.15419"
"326.19600","27.18301","0.15701"
"326.50200","27.20860","0.15896"
"326.80800","27.23407","0.16202"
"327.11400","27.25960","0.16335"
"327.42000","27.28514","0.16557"
"327.72600","27.31060","0.16774"
"328.03200","27.33619","0.16971"
"328.33800","27.36160","0.17161"
"328.64400","27.38719","0.17430"
"328.95000","27.41261","0.17630"
"329.25600","27.43813","0.17838"
"329.56200","27.46360","0.17938"
"329.86800","27.48914","0.18199"
"330.17400","27.51467","0.18486"
"330.48000","27.54008","0.18797"
"330.78600","27.56567","0.18995"
"331.09200","27.59108","0.19295"
"331.39800","27.61661","0.19569"
"331.70400","27.64207","0.19791"
"332.01000","27.66755","0.20070"
"332.31600","27.69314","0.20351"
"332.62200","27.71861","0.20571"
"332.92800","27.74414","0.20817"
"333.23400","27.76961","0.21038"
"333.54000","27.79508","0.21217"
"333.84600","27.82061","0.21378"
"334.15200","27.84608","0.21528"
"334.45800","27.87167","0.21659"
"334.76400","27.89708","0.21746"
"335.07000","27.92261","0.21871"
"335.37600","27.94808","0.22087"
"335.68200","27.97361","0.22320"
"335.98800","27.99908","0.22573"
"336.29400","28.02455","0.22718"
"336.60000","28.05014","0.22824"
"336.90600","28.07561","0.22845"
"337.21200","28.10114","0.23008"
"337.51800","28.12661","0.23266"
"337.82400","28.15214","0.23488"
"338.13000","28.17761","0.23724"
"338.43600","28.20308","0.24021"
"338.74200","28.22861","0.24283"
"339.04800","28.25408","0.24561"
"339.35400","28.27967","0.24946"
"339.66000","28.30514","0.25130"
"339.96600","28.33061","0.25345"
"340.27200","28.35608","0.25587"
"340.57800","28.38155","0.25753"
"340.88400","28.40709","0.26058"
"341.19000","28.43255","0.26225"
"341.49600","28.45815","0.26496"
"341.80200","28.48362","0.26679"
"342.10800","28.50914","0.26893"
"342.41400","28.53455","0.26865"
"342.72000","28.56014","0.26942"
"343.02600","28.58562","0.19296"
"343.33200","28.61109","0.13179"
"343.63800","28.63662","0.14145"
"343.94400","28.66209","0.15883"
"344.25000","28.68761","0.15148"
"344.55600","28.71315","0.15400"
"344.86200","28.73862","0.16408"
"345.16800","28.76415","0.16314"
"345.47400","28.78962","0.16199"
"345.78000","28.81509","0.16838"
"346.08600","28.84062","0.17170"
"346.39200","28.86615","0.17027"
"346.69800","28.89162","0.17319"
"347.00400","28.91715","0.17783"
"347.31000","28.94262","0.17779"
"347.61600","28.96815","0.17858"
"347.92200","28.99362","0.18345"
"348.22800","29.01909","0.18538"
"348.53400","29.04462","0.18520"
"348.84000","29.07009","0.18916"
"349.14600","29.09556","0.19364"
"349.45200","29.12109","0.19461"
"349.75800","29.14656","0.19578"
"350.06400","29.17215","0.19869"
"350.37000","29.19756","0.20196"
"350.67600","29.22315","0.20230"
"350.98200","29.24862","0.20466"
"351.28800","29.27415","0.20750"
"351.59400","29.29962","0.20922"
"351.90000","29.32509","0.21049"
"352.20600","29.35062","0.21240"
"352.51200","29.37609","0.21421"
"352.81800","29.40162","0.21510"
"353.12400","29.42709","0.21585"
"353.43000","29.45268","0.21735"
"353.73600","29.47809","0.21898"
"354.04200","29.50362","0.22061"
"354.34800","29.52916","0.22159"
"354.65400","29.55457","0.22358"
"354.96000","29.58009","0.22562"
"355.26600","29.60556","0.22798"
"355.57200","29.63110","0.22964"
"355.87800","29.65657","0.23140"
"356.18400","29.68210","0.23413"
"356.49000","29.70769","0.23559"
"356.79600","29.73310","0.23757"
"357.10200","29.75857","0.23784"
"357.40800","29.78404","0.24049"
"357.71400","29.80963","0.24082"
"358.02000","29.83510","0.13954"
"358.32600","29.86063","0.12145"
"358.63200","29.88616","0.10848"
"358.93800","29.91157","0.14398"
"359.24400","29.93710","0.11738"
"359.55000","29.96257","0.11254"
"359.85600","29.98816","0.11606"
"360.16200","30.01363","0.12347"
"360.46800","30.03916","0.14359"
"360.77400","30.06463","0.11796"
"361.08000","30.09010","0.12377"
"361.38600","30.11563","0.12731"
"361.69200","30.14104","0.12985"
"361.99800","30.16663","0.14984"
"362.30400","30.19210","0.13085"
"362.61000","30.21769","0.13992"
"362.91600","30.24310","0.14045"
"363.22200","30.26857","0.13519"
"363.52800","30.29410","0.15570"
"363.83400","30.31951","0.14389"
"364.14000","30.34510","0.15172"
"364.44600","30.37057","0.15748"
"364.75200","30.39616","0.14964"
"365.05800","30.42163","0.16119"
"365.36400","30.44711","0.15636"
"365.67000","30.47263","0.15718"
"365.97600","30.49804","0.16563"
"366.28200","30.52363","0.15925"
"366.58800","30.54910","0.16518"
"366.89400","30.57469","0.16759"
"367.20000","30.60011","0.16407"
"367.50600","30.62563","0.17142"
"367.81200","30.65117","0.16825"
"368.11800","30.67657","0.16789"
"368.42400","30.70211","0.17470"
"368.73000","30.72752","0.17057"
"369.03600","30.75317","0.17350"
"369.34200","30.77864","0.17740"
"369.64800","30.80416","0.17370"
"369.95400","30.82964","0.17815"
"370.26000","30.85505","0.17896"
"370.56600","30.88070","0.17684"
"370.87200","30.90611","0.18282"
"371.17800","30.93164","0.18082"
"371.48400","30.95711","0.18060"
"371.79000","30.98264","0.18744"
"372.09600","31.00817","0.18393"
"372.40200","31.03358","0.18527"
"372.70800","31.05911","0.19199"
"373.01400","31.08458","0.18841"
"373.32000","31.11011","0.19027"
"373.62600","31.13558","0.19584"
"373.93200","31.16117","0.19234"
"374.23800","31.18670","0.19562"
"374.54400","31.21205","0.19972"
"374.85000","31.23764","0.19608"
"375.15600","31.26311","0.19919"
"375.46200","31.28864","0.20274"
"375.76800","31.31411","0.20061"
"376.07400","31.33964","0.20318"
"376.38000","31.36517","0.20631"
"376.68600","31.39058","0.20417"
"376.99200","31.41611","0.20654"
"377.29800","31.44152","0.20962"
"377.60400","31.46711","0.20746"
"377.91000","31.49258","0.20943"
"378.21600","31.51811","0.21252"
"378.52200","31.54358","0.21107"
"378.82800","31.56905","0.21257"
"379.13400","31.59464","0.21480"
"379.44000","31.62005","0.21374"
"379.74600","31.64564","0.21430"
"380.05200","31.67105","0.21677"
"380.35800","31.69664","0.21582"
"380.66400","31.72211","0.21637"
"380.97000","31.74764","0.21850"
"381.27600","31.77317","0.21810"
"381.58200","31.79858","0.21834"
"381.88800","31.82412","0.22057"
"382.19400","31.84958","0.22029"
"382.50000","31.87511","0.22028"
"382.80600","31.90059","0.22261"
"383.11200","31.92612","0.22392"
"383.41800","31.95171","0.22329"
"383.72400","31.97706","0.22529"
"384.03000","32.00265","0.22759"
"384.33600","32.02806","0.22735"
"384.64200","32.05359","0.22826"
"384.94800","32.07912","0.23125"
"385.25400","32.10458","0.23086"
"385.56000","32.13018","0.23133"
"385.86600","32.15559","0.23377"
"386.17200","32.18112","0.23513"
"386.47800","32.20653","0.23446"
"386.78400","32.23212","0.23591"
"387.09000","32.25759","0.23826"
"387.39600","32.28312","0.23781"
"387.70200","32.30865","0.23900"
"388.00800","32.33412","0.24242"
"388.31400","32.35965","0.24266"
"388.62000","32.38506","0.24251"
"388.92600","32.41065","0.24604"
"389.23200","32.43606","0.24770"
"389.53800","32.46159","0.24737"
"389.84400","32.48712","0.24836"
"390.15000","32.51265","0.25112"
"390.45600","32.53818","0.25157"
"390.76200","32.56359","0.25181"
"391.06800","32.58912","0.25442"
"391.37400","32.61459","0.25546"
"391.68000","32.64012","0.25478"
"391.98600","32.66565","0.25627"
"392.29200","32.69106","0.25893"
"392.59800","32.71666","0.25889"
"392.90400","32.74212","0.25947"
"393.21000","32.76771","0.26063"
"393.51600","32.79306","0.26254"
"393.82200","32.81859","0.26260"
"394.12800","32.84412","0.26295"
"394.43400","32.86959","0.26483"
"394.74000","32.89518","0.26548"
"395.04600","32.92060","0.26583"
"395.35200","32.94613","0.26675"
"395.65800","32.97160","-0.02035"
"395.96400","32.99712","0.00749"
"396.27000","33.02260","0.00882"
"396.57600","33.04807","0.00910"
"396.88200","33.07366","0.00911"
"397.18800","33.09912","0.00924"
"397.49400","33.12466","0.01036"
"397.80000","33.15012","0.00921"
"398.10600","33.17566","0.00879"
"398.41200","33.20113","0.00879"
"398.71800","33.22666","0.00928"
"399.02400","33.25213","0.00864"
"399.33000","33.27760","0.00854"
"399.63600","33.30313","0.00848"
"399.94200","33.32860","0.00910"
"400.24800","33.35407","0.00845"
"400.55400","33.37960","0.00846"
"400.86000","33.40507","0.00871"
"401.16600","33.43060","0.00801"
"401.47200","33.45607","0.00876"
"401.77800","33.48160","0.00841"
"402.08400","33.50707","0.00857"
"402.39000","33.53260","0.00888"
"402.69600","33.55813","0.00902"
"403.00200","33.58360","0.00885"
"403.30800","33.60913","0.00898"
"403.61400","33.63454","0.00868"
"403.92000","33.66019","0.00894"
"404.22600","33.68560","0.00823"
"404.53200","33.71113","0.00818"
"404.83800","33.73654","0.00859"
"405.14400","33.76213","0.00929"
"405.45000","33.78761","0.00904"
"405.75600","33.81308","0.00847"
"406.06200","33.83867","0.00842"
"406.36800","33.86407","0.00876"
"406.67400","33.88960","0.00882"
"406.98000","33.91507","0.00876"
"407.28600","33.94061","0.00909"
"407.59200","33.96614","0.00863"
"407.89800","33.99160","0.00841"
"408.20400","34.01714","0.00887"
"408.51000","34.04255","0.00895"
"408.81600","34.06813","0.00877"
"409.12200","34.09367","0.00893"
"409.42800","34.11914","0.00814"
"409.73400","34.14461","0.00851"
"410.04000","34.17007","0.00842"
"410.34600","34.19561","0.00846"
"410.65200","34.22108","0.00891"
"410.95800","34.24661","0.00889"
"411.26400","34.27208","0.00861"
"411.57000","34.29767","0.00864"
"411.87600","34.32314","0.00843"
"412.18200","34.34861","0.00824"
"412.48800","34.37414","0.00865"
"412.79400","34.39955","0.00890"
"413.10000","34.42514","0.00872"
"413.40600","34.45061","0.00775"
"413.71200","34.47614","0.00824"
"414.01800","34.50155","0.00822"
"414.32400","34.52714","0.00812"
"414.63000","34.55267","0.00751"
"414.93600","34.57808","0.00814"
"415.24200","34.60361","0.00783"
"415.54800","34.62908","0.00844"
"415.85400","34.65467","0.00844"
"416.16000","34.68014","0.00848"
"416.46600","34.70561","0.00880"
"416.77200","34.73108","0.00815"
"417.07800","34.75655","0.00856"
"417.38400","34.78208","0.00870"
"417.69000","34.80755","0.00865"
"417.99600","34.83315","0.00875"
"418.30200","34.85862","0.00862"
"418.60800","34.88414","0.00839"
"418.91400","34.90967","0.00844"
"419.22000","34.93502","0.00870"
"419.52600","34.96061","0.00873"
"419.83200","34.98602","0.00883"
"420.13800","35.01162","0.00887"
"420.44400","35.03714","0.00881"
"420.75000","35.06268","0.00855"
"421.05600","35.08814","0.00898"
"421.36200","35.11356","0.00854"
"421.66800","35.13908","0.00866"
"421.97400","35.16456","0.00887"
"422.28000","35.19015","0.00841"
"422.58600","35.21561","0.00826"
"422.89200","35.24115","0.00828"
"423.19800","35.26662","0.00894"
"423.50400","35.29208","0.00845"
"423.81000","35.31762","0.00846"
"424.11600","35.34303","0.00833"
"424.42200","35.36862","0.00858"
"424.72800","35.39409","0.00841"
"425.03400","35.41962","0.00877"
"425.34000","35.44515","0.00863"
"425.64600","35.47062","0.00838"
"425.95200","35.49615","0.00847"
"426.25800","35.52156","0.00817"
"426.56400","35.54715","0.00833"
"426.87000","35.57262","0.00837"
"427.17600","35.59815","0.00868"
"427.48200","35.62362","0.00856"
"427.78800","35.64909","0.00830"
"428.09400","35.67462","0.00843"
"428.40000","35.70009","0.00847"
"428.70600","35.72562","0.00846"
"429.01200","35.75109","0.00825"
"429.31800","35.77662","0.00875"
"429.62400","35.80215","0.00830"
"429.93000","35.82762","0.00845"
"430.23600","35.85315","0.00863"
"430.54200","35.87856","0.00828"
"430.84800","35.90409","0.00842"
"431.15400","35.92957","0.00880"
"431.46000","35.95515","0.00859"
"431.76600","35.98062","0.00807"
"432.07200","36.00615","0.00885"
"432.37800","36.03162","0.00796"
"432.68400","36.05703","0.00903"
"432.99000","36.08263","0.00838"
"433.29600","36.10804","0.00807"
"433.60200","36.13356","0.00914"
"433.90800","36.15915","0.00921"
"434.21400","36.18462","0.00885"
"434.52000","36.21022","0.00898"
"434.82600","36.23557","0.00865"
"435.13200","36.26116","0.00863"
"435.43800","36.28662","0.00856"
"435.74400","36.31216","0.00873"
"436.05000","36.33762","0.00837"
"436.35600","36.36316","0.00836"
"436.66200","36.38869","0.00876"
"436.96800","36.41410","0.00835"
"437.27400","36.43957","0.00855"
"437.58000","36.46504","0.00899"
"437.88600","36.49063","0.00884"
"438.19200","36.51604","0.00909"
"438.49800","36.54157","0.00845"
"438.80400","36.56710","0.00901"
"439.11000","36.59263","0.00888"
"439.41600","36.61810","0.00893"
"439.72200","36.64357","0.00918"
"440.02800","36.66910","0.00906"
"440.33400","36.69457","0.00884"
"440.64000","36.72010","0.00869"
"440.94600","36.74563","0.00860"
"441.25200","36.77110","0.00888"
"441.55800","36.79663","0.00917"
"441.86400","36.82210","0.00888"
"442.17000","36.84763","0.00893"
"442.47600","36.87304","0.00872"
"442.78200","36.89863","0.00870"
"443.08800","36.92416","0.00890"
"443.39400","36.94957","0.00873"
"443.70000","36.97511","0.00902"
"444.00600","37.00058","0.00893"
"444.31200","37.02610","0.00889"
"444.61800","37.05157","0.00881"
"444.92400","37.07710","0.00885"
"445.23000","37.10263","0.00861"
"445.53600","37.12811","0.00909"
"445.84200","37.15369","0.00913"
"446.14800","37.17910","0.00889"
"446.45400","37.20464","0.00905"
"446.76000","37.23005","0.00857"
"447.06600","37.25563","0.00863"
"447.37200","37.28111","0.00856"
"447.67800","37.30658","0.00851"
"447.98400","37.33216","0.00865"
"448.29000","37.35757","0.00894"
"448.59600","37.38311","0.00902"
"448.90200","37.40858","0.00859"
"449.20800","37.43411","0.00896"
"449.51400","37.45958","0.00905"
"449.82000","37.48511","0.00889"
"450.12600","37.51064","0.00867"
"450.43200","37.53611","0.00863"
"450.73800","37.56158","0.00876"
"451.04400","37.58705","0.00913"
"451.35000","37.61258","0.00883"
"451.65600","37.63805","0.00850"
"451.96200","37.66358","0.00911"
"452.26800","37.68911","0.00932"
"452.57400","37.71464","0.00892"
"452.88000","37.74011","0.00922"
"453.18600","37.76558","0.00859"
"453.49200","37.79111","0.00885"
"453.65200","37.80444","0.00898"