File: Force_trajectories/161226_2/Specimen_RawData_1.csv
End date,"12/26/2016"
Specimen label,"11BG_84"
Maximum Load,"0.83001",N

Time,Extension,Load
(s),(mm),(N)
"0.00000","0.00000","-0.00046"
"0.29400","0.02386","0.00275"
"0.58800","0.04927","0.00290"
"0.88200","0.07372","0.00437"
"1.17600","0.09823","0.00496"
"1.47000","0.12275","0.00483"
"1.76400","0.14726","0.00592"
"2.05800","0.17178","0.00628"
"2.35200","0.19623","0.00645"
"2.64600","0.22068","0.00687"
"2.94000","0.24514","0.00759"
"3.23400","0.26971","0.00747"
"3.52800","0.29416","0.00779"
"3.82200","0.31874","0.00798"
"4.11600","0.34325","0.00905"
"4.41000","0.36777","0.00893"
"4.70400","0.39222","0.00884"
"4.99800","0.41667","0.00903"
"5.29200","0.44125","0.00923"
"5.58600","0.46570","0.00981"
"5.88000","0.49021","0.00975"
"6.17400","0.51467","0.00990"
"6.46800","0.53930","0.01043"
"6.76200","0.56370","0.01054"
"7.05600","0.58827","0.01041"
"7.35000","0.61266","0.01108"
"7.64400","0.63718","0.01095"
"7.93800","0.66169","0.01093"
"8.23200","0.68620","0.01142"
"8.52600","0.71072","0.01137"
"8.82000","0.73517","0.01107"
"9.11400","0.75975","0.01113"
"9.40800","0.78414","0.01103"
"9.70200","0.80871","0.01100"
"9.99600","0.83323","0.01204"
"10.29000","0.85774","0.01198"
"10.58400","0.88225","0.01244"
"10.87800","0.90677","0.01223"
"11.17200","0.93128","0.01289"
"11.46600","0.95568","0.01253"
"11.76000","0.98031","0.01261"
"12.05400","1.00470","0.01285"
"12.34800","1.02928","0.01286"
"12.64200","1.05367","0.01316"
"12.93600","1.07824","0.01319"
"13.23000","1.10264","0.01311"
"13.52400","1.12721","0.01322"
"13.81800","1.15173","0.01365"
"14.11200","1.17618","0.01336"
"14.40600","1.20075","0.01370"
"14.70000","1.22521","0.01396"
"14.99400","1.24972","0.01401"
"15.28800","1.27417","0.01407"
"15.58200","1.29869","0.01405"
"15.87600","1.32314","0.01421"
"16.17000","1.34772","0.01438"
"16.46400","1.37223","0.01437"
"16.75800","1.39674","0.01420"
"17.05200","1.42126","0.01453"
"17.34600","1.44571","0.01489"
"17.64000","1.47028","0.01489"
"17.93400","1.49468","0.01503"
"18.22800","1.51925","0.01525"
"18.52200","1.54371","0.01523"
"18.81600","1.56822","0.01501"
"19.11000","1.59267","0.01542"
"19.40400","1.61725","0.01562"
"19.69800","1.64170","0.01550"
"19.99200","1.66621","0.01536"
"20.28600","1.69073","0.01591"
"20.58000","1.71518","0.01576"
"20.87400","1.73976","0.01579"
"21.16800","1.76421","0.01607"
"21.46200","1.78878","0.01592"
"21.75600","1.81318","0.01617"
"22.05000","1.83775","0.01621"
"22.34400","1.86220","0.01623"
"22.63800","1.88678","0.01621"
"22.93200","1.91123","0.01663"
"23.22600","1.93575","0.01653"
"23.52000","1.96026","0.01655"
"23.81400","1.98477","0.01666"
"24.10800","2.00923","0.01632"
"24.40200","2.03368","0.01641"
"24.69600","2.05825","0.01659"
"24.99000","2.08271","0.01688"
"25.28400","2.10722","0.01682"
"25.57800","2.13168","0.01749"
"25.87200","2.15625","0.01702"
"26.16600","2.18070","0.01756"
"26.46000","2.20522","0.01716"
"26.75400","2.22973","0.01722"
"27.04800","2.25418","0.01748"
"27.34200","2.27876","0.01748"
"27.63600","2.30315","0.01749"
"27.93000","2.32773","0.01796"
"28.22400","2.35218","0.01773"
"28.51800","2.37675","0.01772"
"28.81200","2.40121","0.01763"
"29.10600","2.42578","0.01803"
"29.40000","2.45023","0.01829"
"29.69400","2.47475","0.01753"
"29.98800","2.49926","0.01786"
"30.28200","2.52372","0.01782"
"30.57600","2.54823","0.01807"
"30.87000","2.57268","0.01792"
"31.16400","2.59720","0.01827"
"31.45800","2.62165","0.01829"
"31.75200","2.64628","0.01838"
"32.04600","2.67068","0.01862"
"32.34000","2.69525","0.01855"
"32.63400","2.71971","0.01835"
"32.92800","2.74422","0.01846"
"33.22200","2.76873","0.01805"
"33.51600","2.79319","0.01825"
"33.81000","2.81776","0.01792"
"34.10400","2.84222","0.01874"
"34.39800","2.86673","0.01845"
"34.69200","2.89118","0.01834"
"34.98600","2.91576","0.01856"
"35.28000","2.94021","0.01871"
"35.57400","2.96472","0.01884"
"35.86800","2.98924","0.01921"
"36.16200","3.01375","0.01938"
"36.45600","3.03826","0.01911"
"36.75000","3.06272","0.01943"
"37.04400","3.08723","0.01913"
"37.33800","3.11169","0.01970"
"37.63200","3.13626","0.01983"
"37.92600","3.16071","0.01984"
"38.22000","3.18529","0.01996"
"38.51400","3.20968","0.01918"
"38.80800","3.23419","0.01942"
"39.10200","3.25865","0.01937"
"39.39600","3.28316","0.01975"
"39.69000","3.30768","0.01962"
"39.98400","3.33219","0.02018"
"40.27800","3.35676","0.02001"
"40.57200","3.38122","0.01880"
"40.86600","3.40579","0.01855"
"41.16000","3.43019","0.01865"
"41.45400","3.45470","0.01819"
"41.74800","3.47915","0.01813"
"42.04200","3.50373","0.01822"
"42.33600","3.52824","0.01855"
"42.63000","3.55275","0.01881"
"42.92400","3.57721","0.01883"
"43.21800","3.60172","0.01910"
"43.51200","3.62624","0.01909"
"43.80600","3.65069","0.01912"
"44.10000","3.67520","0.01896"
"44.39400","3.69966","0.01895"
"44.68800","3.72423","0.01915"
"44.98200","3.74868","0.01946"
"45.27600","3.77320","0.01927"
"45.57000","3.79771","0.01941"
"45.86400","3.82223","0.01930"
"46.15800","3.84668","0.01938"
"46.45200","3.87119","0.01938"
"46.74600","3.89577","0.01960"
"47.04000","3.92022","0.01978"
"47.33400","3.94473","0.02003"
"47.62800","3.96925","0.01991"
"47.92200","3.99376","0.02036"
"48.21600","4.01822","0.02058"
"48.51000","4.04273","0.02070"
"48.80400","4.06718","0.02089"
"49.09800","4.09170","0.02093"
"49.39200","4.11621","0.02099"
"49.68600","4.14072","0.02121"
"49.98000","4.16524","0.02129"
"50.27400","4.18969","0.02175"
"50.56800","4.21421","0.02162"
"50.86200","4.23866","0.02194"
"51.15600","4.26323","0.02186"
"51.45000","4.28769","0.02224"
"51.74400","4.31220","0.02171"
"52.03800","4.33671","0.02203"
"52.33200","4.36123","0.02189"
"52.62600","4.38580","0.02216"
"52.92000","4.41020","0.02234"
"53.21400","4.43477","0.02230"
"53.50800","4.45916","0.02168"
"53.80200","4.48374","0.02193"
"54.09600","4.50819","0.02232"
"54.39000","4.53270","0.02269"
"54.68400","4.55722","0.02262"
"54.97800","4.58173","0.02288"
"55.27200","4.60625","0.02315"
"55.56600","4.63076","0.02317"
"55.86000","4.65527","0.02333"
"56.15400","4.67967","0.02337"
"56.44800","4.70424","0.02399"
"56.74200","4.72863","0.02354"
"57.03600","4.75327","0.02378"
"57.33000","4.77766","0.02399"
"57.62400","4.80224","0.02436"
"57.91800","4.82669","0.02465"
"58.21200","4.85120","0.02448"
"58.50600","4.87572","0.02448"
"58.80000","4.90017","0.02433"
"59.09400","4.92474","0.02484"
"59.38800","4.94920","0.02458"
"59.68200","4.97377","0.02401"
"59.97600","4.99823","0.02429"
"60.27000","5.02280","0.02475"
"60.56400","5.04719","0.02484"
"60.85800","5.07171","0.02510"
"61.15200","5.09616","0.02511"
"61.44600","5.12067","0.02568"
"61.74000","5.14519","0.02625"
"62.03400","5.16970","0.02530"
"62.32800","5.19428","0.02524"
"62.62200","5.21873","0.02559"
"62.91600","5.24324","0.02593"
"63.21000","5.26770","0.02582"
"63.50400","5.29227","0.02567"
"63.79800","5.31666","0.02597"
"64.09200","5.34124","0.02637"
"64.38600","5.36569","0.02710"
"64.68000","5.39021","0.02687"
"64.97400","5.41472","0.02731"
"65.26800","5.43917","0.02778"
"65.56200","5.46381","0.02781"
"65.85600","5.48820","0.02816"
"66.15000","5.51277","0.02814"
"66.44400","5.53717","0.02784"
"66.73800","5.56174","0.02808"
"67.03200","5.58620","0.02892"
"67.32600","5.61077","0.02908"
"67.62000","5.63522","0.02951"
"67.91400","5.65974","0.02956"
"68.20800","5.68425","0.03033"
"68.50200","5.70870","0.02998"
"68.79600","5.73322","0.03017"
"69.09000","5.75767","0.03063"
"69.38400","5.78219","0.03087"
"69.67800","5.80664","0.03094"
"69.97200","5.83121","0.03148"
"70.26600","5.85573","0.03222"
"70.56000","5.88024","0.03223"
"70.85400","5.90475","0.03175"
"71.14800","5.92927","0.03231"
"71.44200","5.95378","0.03283"
"71.73600","5.97818","0.03316"
"72.03000","6.00275","0.03316"
"72.32400","6.02720","0.03366"
"72.61800","6.05184","0.03380"
"72.91200","6.07617","0.03432"
"73.20600","6.10074","0.03428"
"73.50000","6.12520","0.03450"
"73.79400","6.14977","0.03501"
"74.08800","6.17423","0.03599"
"74.38200","6.19874","0.03627"
"74.67600","6.22319","0.03672"
"74.97000","6.24771","0.03665"
"75.26400","6.27222","0.03652"
"75.55800","6.29667","0.03722"
"75.85200","6.32125","0.03630"
"76.14600","6.34564","0.03728"
"76.44000","6.37022","0.03780"
"76.73400","6.39467","0.03739"
"77.02800","6.41924","0.03775"
"77.32200","6.44376","0.03823"
"77.61600","6.46821","0.03869"
"77.91000","6.49272","0.03934"
"78.20400","6.51718","0.04029"
"78.49800","6.54175","0.04029"
"78.79200","6.56621","0.04082"
"79.08600","6.59072","0.04091"
"79.38000","6.61517","0.04138"
"79.67400","6.63969","0.04153"
"79.96800","6.66420","0.04169"
"80.26200","6.68871","0.04222"
"80.55600","6.71323","0.04249"
"80.85000","6.73768","0.04295"
"81.14400","6.76220","0.04359"
"81.43800","6.78665","0.04404"
"81.73200","6.81122","0.04430"
"82.02600","6.83568","0.04543"
"82.32000","6.86025","0.04562"
"82.61400","6.88470","0.04542"
"82.90800","6.90928","0.04527"
"83.20200","6.93373","0.04572"
"83.49600","6.95825","0.04575"
"83.79000","6.98270","0.04702"
"84.08400","7.00721","0.04731"
"84.37800","7.03173","0.04754"
"84.67200","7.05618","0.04771"
"84.96600","7.08070","0.04749"
"85.26000","7.10515","0.04822"
"85.55400","7.12972","0.04860"
"85.84800","7.15424","0.04876"
"86.14200","7.17875","0.04951"
"86.43600","7.20320","0.05068"
"86.73000","7.22766","0.05099"
"87.02400","7.25223","0.05182"
"87.31800","7.27668","0.05153"
"87.61200","7.30120","0.05211"
"87.90600","7.32565","0.05296"
"88.20000","7.35023","0.05294"
"88.49400","7.37468","0.05384"
"88.78800","7.39925","0.05438"
"89.08200","7.42371","0.05423"
"89.37600","7.44828","0.05472"
"89.67000","7.47268","0.05488"
"89.96400","7.49725","0.05566"
"90.25800","7.52176","0.05602"
"90.55200","7.54622","0.05602"
"90.84600","7.57073","0.05701"
"91.14000","7.59524","0.05716"
"91.43400","7.61976","0.05789"
"91.72800","7.64421","0.05832"
"92.02200","7.66873","0.05840"
"92.31600","7.69318","0.05865"
"92.61000","7.71769","0.05886"
"92.90400","7.74221","0.05932"
"93.19800","7.76672","0.05945"
"93.49200","7.79123","0.05939"
"93.78600","7.81569","0.06002"
"94.08000","7.84026","0.06092"
"94.37400","7.86471","0.06126"
"94.66800","7.88923","0.06164"
"94.96200","7.91368","0.06143"
"95.25600","7.93826","0.06223"
"95.55000","7.96271","0.06221"
"95.84400","7.98722","0.06263"
"96.13800","8.01174","0.06309"
"96.43200","8.03625","0.06338"
"96.72600","8.06076","0.06364"
"97.02000","8.08516","0.06389"
"97.31400","8.10973","0.06483"
"97.60800","8.13419","0.06522"
"97.90200","8.15870","0.06525"
"98.19600","8.18315","0.06538"
"98.49000","8.20779","0.06599"
"98.78400","8.23218","0.06647"
"99.07800","8.25675","0.06773"
"99.37200","8.28121","0.06766"
"99.66600","8.30566","0.06859"
"99.96000","8.33018","0.06943"
"100.25400","8.35469","0.06961"
"100.54800","8.37926","0.06984"
"100.84200","8.40372","0.07059"
"101.13600","8.42823","0.07115"
"101.43000","8.45275","0.07164"
"101.72400","8.47726","0.07271"
"102.01800","8.50171","0.07235"
"102.31200","8.52623","0.07266"
"102.60600","8.55074","0.07371"
"102.90000","8.57525","0.07415"
"103.19400","8.59977","0.07522"
"103.48800","8.62422","0.07580"
"103.78200","8.64874","0.07642"
"104.07600","8.67319","0.07671"
"104.37000","8.69776","0.07718"
"104.66400","8.72216","0.07813"
"104.95800","8.74673","0.07875"
"105.25200","8.77118","0.07892"
"105.54600","8.79570","0.08007"
"105.84000","8.82021","0.08094"
"106.13400","8.84473","0.08177"
"106.42800","8.86924","0.08311"
"106.72200","8.89369","0.08311"
"107.01600","8.91827","0.08341"
"107.31000","8.94272","0.08524"
"107.60400","8.96729","0.08623"
"107.89800","8.99169","0.08630"
"108.19200","9.01626","0.08745"
"108.48600","9.04072","0.08875"
"108.78000","9.06529","0.08923"
"109.07400","9.08974","0.08956"
"109.36800","9.11426","0.09024"
"109.66200","9.13871","0.09060"
"109.95600","9.16322","0.09196"
"110.25000","9.18768","0.09213"
"110.54400","9.21213","0.09339"
"110.83800","9.23676","0.09391"
"111.13200","9.26116","0.09488"
"111.42600","9.28573","0.09547"
"111.72000","9.31025","0.09654"
"112.01400","9.33476","0.09651"
"112.30800","9.35921","0.09773"
"112.60200","9.38373","0.09832"
"112.89600","9.40824","0.09938"
"113.19000","9.43270","0.09999"
"113.48400","9.45727","0.10079"
"113.77800","9.48166","0.10104"
"114.07200","9.50624","0.10158"
"114.36600","9.53069","0.10254"
"114.66000","9.55520","0.10257"
"114.95400","9.57972","0.10356"
"115.24800","9.60423","0.10387"
"115.54200","9.62875","0.10400"
"115.83600","9.65320","0.10499"
"116.13000","9.67777","0.10529"
"116.42400","9.70217","0.10531"
"116.71800","9.72674","0.10577"
"117.01200","9.75113","0.10611"
"117.30600","9.77571","0.10632"
"117.60000","9.80016","0.10690"
"117.89400","9.82468","0.10750"
"118.18800","9.84919","0.10747"
"118.48200","9.87370","0.10802"
"118.77600","9.89828","0.10825"
"119.07000","9.92273","0.10850"
"119.36400","9.94730","0.10875"
"119.65800","9.97170","0.10911"
"119.95200","9.99627","0.10969"
"120.24600","10.02072","0.11004"
"120.54000","10.04524","0.11039"
"120.83400","10.06969","0.11091"
"121.12800","10.09421","0.11131"
"121.42200","10.11866","0.11199"
"121.71600","10.14318","0.11221"
"122.01000","10.16775","0.11275"
"122.30400","10.19220","0.11288"
"122.59800","10.21672","0.11373"
"122.89200","10.24117","0.11508"
"123.18600","10.26574","0.11579"
"123.48000","10.29014","0.11654"
"123.77400","10.31477","0.11818"
"124.06800","10.33916","0.11954"
"124.36200","10.36374","0.12039"
"124.65600","10.38825","0.12145"
"124.95000","10.41276","0.12312"
"125.24400","10.43728","0.12470"
"125.53800","10.46173","0.12606"
"125.83200","10.48625","0.12724"
"126.12600","10.51070","0.12878"
"126.42000","10.53527","0.13000"
"126.71400","10.55973","0.13186"
"127.00800","10.58424","0.13298"
"127.30200","10.60870","0.13504"
"127.59600","10.63321","0.13746"
"127.89000","10.65766","0.13851"
"128.18400","10.68224","0.14185"
"128.47800","10.70675","0.14340"
"128.77200","10.73120","0.14629"
"129.06600","10.75572","0.14752"
"129.36000","10.78023","0.15005"
"129.65400","10.80475","0.15176"
"129.94800","10.82914","0.15339"
"130.24200","10.85371","0.15532"
"130.53600","10.87817","0.15678"
"130.83000","10.90274","0.15860"
"131.12400","10.92726","0.16041"
"131.41800","10.95177","0.16153"
"131.71200","10.97628","0.16338"
"132.00600","11.00074","0.16437"
"132.30000","11.02525","0.16066"
"132.59400","11.04970","0.16175"
"132.88800","11.07428","0.16268"
"133.18200","11.09861","0.16471"
"133.47600","11.12324","0.16641"
"133.77000","11.14770","0.16731"
"134.06400","11.17221","0.16873"
"134.35800","11.19672","0.16952"
"134.65200","11.22124","0.17055"
"134.94600","11.24575","0.17154"
"135.24000","11.27021","0.17262"
"135.53400","11.29472","0.17372"
"135.82800","11.31912","0.17452"
"136.12200","11.34369","0.17558"
"136.41600","11.36814","0.17633"
"136.71000","11.39272","0.17737"
"137.00400","11.41723","0.17880"
"137.29800","11.44174","0.17978"
"137.59200","11.46626","0.18080"
"137.88600","11.49077","0.18198"
"138.18000","11.51528","0.18295"
"138.47400","11.53968","0.18434"
"138.76800","11.56419","0.18575"
"139.06200","11.58871","0.18731"
"139.35600","11.61322","0.18900"
"139.65000","11.63767","0.19081"
"139.94400","11.66225","0.19198"
"140.23800","11.68670","0.19393"
"140.53200","11.71122","0.19509"
"140.82600","11.73573","0.19637"
"141.12000","11.76018","0.19829"
"141.41400","11.78476","0.20010"
"141.70800","11.80915","0.20192"
"142.00200","11.83372","0.20322"
"142.29600","11.85818","0.20558"
"142.59000","11.88275","0.20713"
"142.88400","11.90721","0.20859"
"143.17800","11.93172","0.21025"
"143.47200","11.95623","0.21119"
"143.76600","11.98081","0.21089"
"144.06000","12.00526","0.21129"
"144.35400","12.02977","0.21310"
"144.64800","12.05429","0.21385"
"144.94200","12.07868","0.21443"
"145.23600","12.10326","0.21444"
"145.53000","12.12765","0.21607"
"145.82400","12.15222","0.21691"
"146.11800","12.17674","0.21779"
"146.41200","12.20125","0.21921"
"146.70600","12.22570","0.22026"
"147.00000","12.25016","0.22144"
"147.29400","12.27473","0.22262"
"147.58800","12.29919","0.22451"
"147.88200","12.32370","0.22397"
"148.17600","12.34815","0.22433"
"148.47000","12.37273","0.22622"
"148.76400","12.39718","0.22788"
"149.05800","12.42175","0.22840"
"149.35200","12.44621","0.22982"
"149.64600","12.47078","0.23239"
"149.94000","12.49523","0.23333"
"150.23400","12.51975","0.23518"
"150.52800","12.54426","0.23698"
"150.82200","12.56872","0.23923"
"151.11600","12.59329","0.24128"
"151.41000","12.61768","0.24278"
"151.70400","12.64226","0.24514"
"151.99800","12.66665","0.24716"
"152.29200","12.69123","0.24910"
"152.58600","12.71568","0.25142"
"152.88000","12.74025","0.25368"
"153.17400","12.76471","0.25448"
"153.46800","12.78922","0.25597"
"153.76200","12.81373","0.25802"
"154.05600","12.83819","0.25907"
"154.35000","12.86276","0.26172"
"154.64400","12.88722","0.26341"
"154.93800","12.91179","0.26422"
"155.23200","12.93618","0.26603"
"155.52600","12.96070","0.26706"
"155.82000","12.98515","0.26922"
"156.11400","13.00966","0.27105"
"156.40800","13.03424","0.27381"
"156.70200","13.05875","0.27591"
"156.99600","13.08327","0.27977"
"157.29000","13.10766","0.28214"
"157.58400","13.13223","0.28531"
"157.87800","13.15669","0.28907"
"158.17200","13.18126","0.29266"
"158.46600","13.20566","0.29662"
"158.76000","13.23029","0.29915"
"159.05400","13.25468","0.30232"
"159.34800","13.27925","0.30534"
"159.64200","13.30371","0.30828"
"159.93600","13.32816","0.31134"
"160.23000","13.35268","0.31298"
"160.52400","13.37719","0.31569"
"160.81800","13.40176","0.31681"
"161.11200","13.42622","0.31814"
"161.40600","13.45079","0.31941"
"161.70000","13.47519","0.32075"
"161.99400","13.49976","0.32185"
"162.28800","13.52427","0.32222"
"162.58200","13.54873","0.32320"
"162.87600","13.57318","0.32333"
"163.17000","13.59775","0.32391"
"163.46400","13.62227","0.32402"
"163.75800","13.64672","0.32459"
"164.05200","13.67124","0.32522"
"164.34600","13.69569","0.32562"
"164.64000","13.72020","0.32675"
"164.93400","13.74466","0.32780"
"165.22800","13.76929","0.32900"
"165.52200","13.79368","0.33082"
"165.81600","13.81826","0.33279"
"166.11000","13.84271","0.33411"
"166.40400","13.86717","0.33627"
"166.69800","13.89174","0.33936"
"166.99200","13.91625","0.34249"
"167.28600","13.94077","0.34624"
"167.58000","13.96522","0.34967"
"167.87400","13.98979","0.35373"
"168.16800","14.01425","0.35663"
"168.46200","14.03876","0.35873"
"168.75600","14.06316","0.36239"
"169.05000","14.08773","0.36518"
"169.34400","14.11224","0.36874"
"169.63800","14.13670","0.37059"
"169.93200","14.16121","0.37124"
"170.22600","14.18566","0.37282"
"170.52000","14.21024","0.37477"
"170.81400","14.23469","0.37732"
"171.10800","14.25927","0.38031"
"171.40200","14.28366","0.38246"
"171.69600","14.30817","0.38502"
"171.99000","14.33269","0.38722"
"172.28400","14.35720","0.39026"
"172.57800","14.38171","0.39291"
"172.87200","14.40623","0.39580"
"173.16600","14.43074","0.39940"
"173.46000","14.45520","0.40132"
"173.75400","14.47977","0.40374"
"174.04800","14.50416","0.40593"
"174.34200","14.52874","0.40791"
"174.63600","14.55319","0.40988"
"174.93000","14.57770","0.41241"
"175.22400","14.60222","0.41353"
"175.51800","14.62673","0.41541"
"175.81200","14.65125","0.41703"
"176.10600","14.67570","0.41913"
"176.40000","14.70027","0.42143"
"176.69400","14.72467","0.42461"
"176.98800","14.74924","0.42619"
"177.28200","14.77363","0.42878"
"177.57600","14.79827","0.43196"
"177.87000","14.82266","0.43534"
"178.16400","14.84724","0.43786"
"178.45800","14.87169","0.44028"
"178.75200","14.89620","0.44071"
"179.04600","14.92072","0.44342"
"179.34000","14.94523","0.44691"
"179.63400","14.96974","0.45023"
"179.92800","14.99420","0.45347"
"180.22200","15.01877","0.45461"
"180.51600","15.04323","0.45737"
"180.81000","15.06780","0.46026"
"181.10400","15.09219","0.46337"
"181.39800","15.11671","0.46256"
"181.69200","15.14116","0.46312"
"181.98600","15.16568","0.46519"
"182.28000","15.19019","0.46703"
"182.57400","15.21470","0.46885"
"182.86800","15.23922","0.47064"
"183.16200","15.26367","0.47244"
"183.45600","15.28818","0.47424"
"183.75000","15.31264","0.47582"
"184.04400","15.33727","0.47854"
"184.33800","15.36166","0.48218"
"184.63200","15.38624","0.48529"
"184.92600","15.41075","0.48964"
"185.22000","15.43527","0.49400"
"185.51400","15.45978","0.49631"
"185.80800","15.48423","0.50126"
"186.10200","15.50875","0.50647"
"186.39600","15.53314","0.51064"
"186.69000","15.55772","0.51509"
"186.98400","15.58223","0.51841"
"187.27800","15.60674","0.52266"
"187.57200","15.63120","0.52502"
"187.86600","15.65577","0.52670"
"188.16000","15.68022","0.52883"
"188.45400","15.70468","0.53056"
"188.74800","15.72925","0.53230"
"189.04200","15.75371","0.53432"
"189.33600","15.77822","0.53666"
"189.63000","15.80267","0.53842"
"189.92400","15.82719","0.54018"
"190.21800","15.85170","0.54313"
"190.51200","15.87621","0.53700"
"190.80600","15.90073","0.53896"
"191.10000","15.92524","0.54150"
"191.39400","15.94975","0.54398"
"191.68800","15.97421","0.54706"
"191.98200","15.99872","0.55096"
"192.27600","16.02318","0.55529"
"192.57000","16.04775","0.55966"
"192.86400","16.07220","0.56523"
"193.15800","16.09678","0.56990"
"193.45200","16.12117","0.57331"
"193.74600","16.14575","0.57738"
"194.04000","16.17014","0.58103"
"194.33400","16.19471","0.58424"
"194.62800","16.21917","0.58827"
"194.92200","16.24368","0.59297"
"195.21600","16.26825","0.59664"
"195.51000","16.29271","0.60158"
"195.80400","16.31722","0.60647"
"196.09800","16.34167","0.61103"
"196.39200","16.36619","0.61418"
"196.68600","16.39064","0.61728"
"196.98000","16.41528","0.61990"
"197.27400","16.43973","0.62197"
"197.56800","16.46424","0.62431"
"197.86200","16.48876","0.62544"
"198.15600","16.51327","0.62763"
"198.45000","16.53778","0.62973"
"198.74400","16.56224","0.63219"
"199.03800","16.58669","0.63535"
"199.33200","16.61115","0.63897"
"199.62600","16.63572","0.64313"
"199.92000","16.66023","0.64768"
"200.21400","16.68475","0.65405"
"200.50800","16.70920","0.65881"
"200.80200","16.73366","0.66330"
"201.09600","16.75823","0.66904"
"201.39000","16.78268","0.67436"
"201.68400","16.80726","0.67837"
"201.97800","16.83165","0.68177"
"202.27200","16.85622","0.68511"
"202.56600","16.88068","0.68850"
"202.86000","16.90525","0.69328"
"203.15400","16.92970","0.69787"
"203.44800","16.95428","0.70307"
"203.74200","16.97873","0.70757"
"204.03600","17.00325","0.69989"
"204.33000","17.02776","0.70487"
"204.62400","17.05221","0.71233"
"204.91800","17.07673","0.71786"
"205.21200","17.10118","0.72281"
"205.50600","17.12576","0.72648"
"205.80000","17.15021","0.72855"
"206.09400","17.17472","0.72823"
"206.38800","17.19918","0.73035"
"206.68200","17.22375","0.73259"
"206.97600","17.24820","0.73373"
"207.27000","17.27272","0.73176"
"207.56400","17.29717","0.73392"
"207.85800","17.32169","0.73602"
"208.15200","17.34626","0.73888"
"208.44600","17.37071","0.74219"
"208.74000","17.39529","0.74299"
"209.03400","17.41968","0.74704"
"209.32800","17.44425","0.75291"
"209.62200","17.46871","0.75964"
"209.91600","17.49328","0.76698"
"210.21000","17.51773","0.77259"
"210.50400","17.54225","0.77748"
"210.79800","17.56676","0.78252"
"211.09200","17.59122","0.78730"
"211.38600","17.61579","0.79426"
"211.68000","17.64018","0.80171"
"211.97400","17.66470","0.80988"
"212.26800","17.68915","0.81773"
"212.56200","17.71379","0.82334"
"212.85600","17.73818","0.82877"
"213.15000","17.76275","0.72923"
"213.44400","17.78721","0.61128"
"213.73800","17.81166","0.61056"
"214.03200","17.83623","0.61178"
"214.32600","17.86075","0.61488"
"214.62000","17.88526","0.61844"
"214.91400","17.90972","0.62023"
"215.20800","17.93423","0.08303"
"215.50200","17.95868","0.09317"
"215.79600","17.98326","0.07993"
"216.09000","18.00771","0.07097"
"216.38400","18.03222","0.06882"
"216.67800","18.05674","0.06585"
"216.97200","18.08125","0.06320"
"217.26600","18.10577","0.07714"
"217.56000","18.13022","0.08798"
"217.85400","18.15473","0.07290"
"218.14800","18.17913","0.06573"
"218.44200","18.20376","0.07549"
"218.73600","18.22821","0.09541"
"219.03000","18.25273","0.08847"
"219.32400","18.27718","0.07773"
"219.61800","18.30169","0.09116"
"219.91200","18.32621","0.10264"
"220.20600","18.35066","0.09347"
"220.50000","18.37524","0.09278"
"220.79400","18.39969","0.10068"
"221.08800","18.42426","0.10439"
"221.38200","18.44872","0.10089"
"221.67600","18.47329","0.10363"
"221.97000","18.49768","0.10645"
"222.26400","18.52226","0.10587"
"222.55800","18.54671","0.10877"
"222.85200","18.57123","0.10901"
"223.14600","18.59568","0.10802"
"223.44000","18.62025","0.11049"
"223.73400","18.64471","0.11293"
"224.02800","18.66922","0.11275"
"224.32200","18.69374","0.11429"
"224.61600","18.71813","0.11375"
"224.91000","18.74270","0.11988"
"225.20400","18.76716","0.12100"
"225.49800","18.79173","0.12090"
"225.79200","18.81618","0.12844"
"226.08600","18.84070","0.12410"
"226.38000","18.86527","0.12912"
"226.67400","18.88967","0.13756"
"226.96800","18.91430","0.14152"
"227.26200","18.93869","0.14191"
"227.55600","18.96327","0.14187"
"227.85000","18.98766","0.15520"
"228.14400","19.01224","0.15248"
"228.43800","19.03669","0.15821"
"228.73200","19.06126","0.16065"
"229.02600","19.08572","0.16734"
"229.32000","19.11023","0.16467"
"229.61400","19.13474","0.16677"
"229.90800","19.15920","0.16930"
"230.20200","19.18377","0.17427"
"230.49600","19.20823","0.17257"
"230.79000","19.23268","0.17504"
"231.08400","19.25713","0.17709"
"231.37800","19.28176","0.18241"
"231.67200","19.30622","0.18174"
"231.96600","19.33073","0.18323"
"232.26000","19.35519","0.18630"
"232.55400","19.37970","0.19473"
"232.84800","19.40421","0.19840"
"233.14200","19.42873","0.19861"
"233.43600","19.45330","0.20197"
"233.73000","19.47770","0.20530"
"234.02400","19.50227","0.21014"
"234.31800","19.52672","0.21100"
"234.61200","19.55124","0.21065"
"234.90600","19.57569","0.21233"
"235.20000","19.60020","0.21462"
"235.49400","19.62472","0.21839"
"235.78800","19.64923","0.21998"
"236.08200","19.67374","0.22010"
"236.37600","19.69820","0.22139"
"236.67000","19.72277","0.22307"
"236.96400","19.74722","0.22696"
"237.25800","19.77168","0.23164"
"237.55200","19.79613","0.23279"
"237.84600","19.82071","0.23342"
"238.14000","19.84516","0.23538"
"238.43400","19.86973","0.23789"
"238.72800","19.89419","0.24249"
"239.02200","19.91876","0.24709"
"239.31600","19.94321","0.25012"
"239.61000","19.96773","0.25099"
"239.90400","19.99230","0.25269"
"240.19800","20.01676","0.25478"
"240.49200","20.04121","0.25674"
"240.78600","20.06567","0.26122"
"241.08000","20.09024","0.26549"
"241.37400","20.11469","0.26843"
"241.66800","20.13921","0.27059"
"241.96200","20.16366","0.27345"
"242.25600","20.18818","0.27650"
"242.55000","20.21269","0.28200"
"242.84400","20.23714","0.28643"
"243.13800","20.26178","0.29482"
"243.43200","20.28617","0.30132"
"243.72600","20.31075","0.30723"
"244.02000","20.33514","0.31090"
"244.31400","20.35977","0.31351"
"244.60800","20.38416","0.31550"
"244.90200","20.40874","0.31778"
"245.19600","20.43319","0.31990"
"245.49000","20.45771","0.32172"
"245.78400","20.48222","0.32321"
"246.07800","20.50673","0.32427"
"246.37200","20.53131","0.32503"
"246.66600","20.55570","0.32627"
"246.96000","20.58022","0.32825"
"247.25400","20.60467","0.33033"
"247.54800","20.62924","0.33253"
"247.84200","20.65370","0.33596"
"248.13600","20.67821","0.33904"
"248.43000","20.70272","0.34313"
"248.72400","20.72724","0.34843"
"249.01800","20.75175","0.35347"
"249.31200","20.77621","0.35766"
"249.60600","20.80072","0.36238"
"249.90000","20.82517","0.36708"
"250.19400","20.84969","0.37042"
"250.48800","20.87414","0.37403"
"250.78200","20.89871","0.37833"
"251.07600","20.92323","0.38242"
"251.37000","20.94774","0.38569"
"251.66400","20.97226","0.38954"
"251.95800","20.99677","0.39391"
"252.25200","21.02128","0.39775"
"252.54600","21.04574","0.40158"
"252.84000","21.07025","0.40428"
"253.13400","21.09470","0.40727"
"253.42800","21.11928","0.41111"
"253.72200","21.14367","0.41430"
"254.01600","21.16825","0.41665"
"254.31000","21.19270","0.41904"
"254.60400","21.21721","0.42212"
"254.89800","21.24166","0.42567"
"255.19200","21.26618","0.42811"
"255.48600","21.29070","0.43027"
"255.78000","21.31521","0.37742"
"256.07400","21.33972","0.20990"
"256.36800","21.36418","0.21370"
"256.66200","21.38875","0.21381"
"256.95600","21.41320","0.21559"
"257.25000","21.43772","0.21866"
"257.54400","21.46223","0.22275"
"257.83800","21.48674","0.22521"
"258.13200","21.51126","0.22591"
"258.42600","21.53571","0.22751"
"258.72000","21.56029","0.23051"
"259.01400","21.58468","0.23461"
"259.30800","21.60925","0.24078"
"259.60200","21.63371","0.24507"
"259.89600","21.65822","0.24698"
"260.19000","21.68267","0.24890"
"260.48400","21.70725","0.25186"
"260.77800","21.73170","0.25541"
"261.07200","21.75621","0.25976"
"261.36600","21.78073","0.26441"
"261.66000","21.80518","0.26722"
"261.95400","21.82976","0.26901"
"262.24800","21.85421","0.27177"
"262.54200","21.87873","0.27448"
"262.83600","21.90318","0.27901"
"263.13000","21.92775","0.28427"
"263.42400","21.95221","0.29247"
"263.71800","21.97678","0.30037"
"264.01200","22.00117","0.30624"
"264.30600","22.02575","0.31171"
"264.60000","22.05020","0.31474"
"264.89400","22.07471","0.31621"
"265.18800","22.09929","0.31876"
"265.48200","22.12368","0.30085"
"265.77600","22.14825","0.30607"
"266.07000","22.17265","0.31089"
"266.36400","22.19722","0.31619"
"266.65800","22.22168","0.31932"
"266.95200","22.24619","0.32175"
"267.24600","22.27071","0.32296"
"267.54000","22.29516","0.32421"
"267.83400","22.31973","0.32516"
"268.12800","22.34419","0.32639"
"268.42200","22.36870","0.32814"
"268.71600","22.39315","0.33050"
"269.01000","22.41773","0.33333"
"269.30400","22.44218","0.33699"
"269.59800","22.46675","0.34225"
"269.89200","22.49127","0.34740"
"270.18600","22.51578","0.35306"
"270.48000","22.54023","0.35915"
"270.77400","22.56475","0.36302"
"271.06800","22.58926","0.28689"
"271.36200","22.61372","0.27777"
"271.65600","22.63829","0.28407"
"271.95000","22.66268","0.28880"
"272.24400","22.68726","0.29733"
"272.53800","22.71165","0.30400"
"272.83200","22.73623","0.30939"
"273.12600","22.76068","0.31310"
"273.42000","22.78519","0.31715"
"273.71400","22.80965","0.31906"
"274.00800","22.83416","0.32166"
"274.30200","22.85874","0.32247"
"274.59600","22.88319","0.32368"
"274.89000","22.90776","0.32413"
"275.18400","22.93222","0.32494"
"275.47800","22.95679","0.32638"
"275.77200","22.98118","0.32849"
"276.06600","23.00576","0.33076"
"276.36000","23.03021","0.19558"
"276.65400","23.05472","0.20097"
"276.94800","23.07924","0.20327"
"277.24200","23.10369","0.20827"
"277.53600","23.12826","0.21055"
"277.83000","23.15272","0.21496"
"278.12400","23.17718","0.21776"
"278.41800","23.20163","0.21844"
"278.71200","23.22626","0.19826"
"279.00600","23.25066","0.19611"
"279.30000","23.27523","0.20344"
"279.59400","23.29968","0.20507"
"279.88800","23.32420","0.20359"
"280.18200","23.34865","0.20741"
"280.47600","23.37322","0.21033"
"280.77000","23.39768","0.21496"
"281.06400","23.42219","0.21802"
"281.35800","23.44676","0.21771"
"281.65200","23.47122","0.21948"
"281.94600","23.49573","0.22163"
"282.24000","23.52024","0.22605"
"282.53400","23.54482","0.23351"
"282.82800","23.56921","0.23574"
"283.12200","23.59373","0.23233"
"283.41600","23.61824","0.23085"
"283.71000","23.64276","0.23424"
"284.00400","23.66721","0.23892"
"284.29800","23.69172","0.24786"
"284.59200","23.71624","0.25320"
"284.88600","23.74069","0.23361"
"285.18000","23.76526","0.23499"
"285.47400","23.78966","0.23748"
"285.76800","23.81423","0.24096"
"286.06200","23.83868","0.24701"
"286.35600","23.86320","0.25416"
"286.65000","23.88771","0.25698"
"286.94400","23.91223","0.25985"
"287.23800","23.93674","0.25038"
"287.53200","23.96119","0.22744"
"287.82600","23.98577","0.22470"
"288.12000","24.01016","0.22822"
"288.41400","24.03473","0.23148"
"288.70800","24.05919","0.23382"
"289.00200","24.08370","0.23756"
"289.29600","24.10822","0.23953"
"289.59000","24.13273","0.24326"
"289.88400","24.15724","0.24789"
"290.17800","24.18170","0.25098"
"290.47200","24.20621","0.25312"
"290.76600","24.23067","0.25561"
"291.06000","24.25518","0.25839"
"291.35400","24.27963","0.26103"
"291.64800","24.30420","0.26457"
"291.94200","24.32866","0.26901"
"292.23600","24.35323","0.27259"
"292.53000","24.37769","0.27580"
"292.82400","24.40226","0.28074"
"293.11800","24.42677","0.28536"
"293.41200","24.45123","0.29035"
"293.70600","24.47574","0.29607"
"294.00000","24.50019","0.30185"
"294.29400","24.52477","0.30655"
"294.58800","24.54916","0.30947"
"294.88200","24.57374","0.31271"
"295.17600","24.59819","0.31548"
"295.47000","24.62271","0.31975"
"295.76400","24.64722","0.32189"
"296.05800","24.67173","0.32320"
"296.35200","24.69625","0.32400"
"296.64600","24.72070","0.32461"
"296.94000","24.74527","0.32478"
"297.23400","24.76967","0.32637"
"297.52800","24.79424","0.32726"
"297.82200","24.81870","0.32886"
"298.11600","24.84327","0.33036"
"298.41000","24.86766","0.33275"
"298.70400","24.89224","0.33657"
"298.99800","24.91669","0.34113"
"299.29200","24.94120","0.34768"
"299.58600","24.96572","0.35341"
"299.88000","24.99017","0.35911"
"300.17400","25.01475","0.36378"
"300.46800","25.03920","0.36882"
"300.76200","25.06377","0.37279"
"301.05600","25.08823","0.37622"
"301.35000","25.11280","0.37929"
"301.64400","25.13720","0.38235"
"301.93800","25.16171","0.38599"
"302.23200","25.18622","0.38913"
"302.52600","25.21068","0.39254"
"302.82000","25.23519","0.29716"
"303.11400","25.25970","0.29124"
"303.40800","25.28422","0.28999"
"303.70200","25.30873","0.28972"
"303.99600","25.33324","0.29124"
"304.29000","25.35764","0.29283"
"304.58400","25.38227","0.29521"
"304.87800","25.40667","0.29792"
"305.17200","25.43124","0.30054"
"305.46600","25.45575","0.30220"
"305.76000","25.48027","0.30411"
"306.05400","25.50478","0.30614"
"306.34800","25.52917","0.30845"
"306.64200","25.55381","0.31053"
"306.93600","25.57820","0.31125"
"307.23000","25.60278","0.31271"
"307.52400","25.62717","0.31390"
"307.81800","25.65174","0.31548"
"308.11200","25.67620","0.31641"
"308.40600","25.70071","0.31816"
"308.70000","25.72523","0.31898"
"308.99400","25.74974","0.32070"
"309.28800","25.77419","0.32154"
"309.58200","25.79865","0.32162"
"309.87600","25.82322","0.32272"
"310.17000","25.84767","0.32331"
"310.46400","25.87219","0.32370"
"310.75800","25.89664","0.32398"
"311.05200","25.92121","0.32414"
"311.34600","25.94573","0.32456"
"311.64000","25.97024","0.32481"
"311.93400","25.99476","0.32586"
"312.22800","26.01927","0.32638"
"312.52200","26.04384","0.32735"
"312.81600","26.06817","0.32848"
"313.11000","26.09275","0.32884"
"313.40400","26.11714","0.32999"
"313.69800","26.14172","0.33015"
"313.99200","26.16611","0.32840"
"314.28600","26.19075","0.32928"
"314.58000","26.21514","0.32978"
"314.87400","26.23971","0.33085"
"315.16800","26.26417","0.33140"
"315.46200","26.28874","0.33250"
"315.75600","26.31325","0.33382"
"316.05000","26.33771","0.33502"
"316.34400","26.36222","0.33630"
"316.63800","26.38668","0.33707"
"316.93200","26.41119","0.33751"
"317.22600","26.43564","0.33856"
"317.52000","26.46021","0.33992"
"317.81400","26.48473","0.34113"
"318.10800","26.50924","0.34261"
"318.40200","26.53376","0.34311"
"318.69600","26.55827","0.34529"
"318.99000","26.58279","0.34584"
"319.28400","26.60718","0.34770"
"319.57800","26.63175","0.34987"
"319.87200","26.65621","0.35245"
"320.16600","26.68072","0.35352"
"320.46000","26.70523","0.35567"
"320.75400","26.72975","0.35744"
"321.04800","26.75426","0.35869"
"321.34200","26.77872","0.36024"
"321.63600","26.80323","0.36221"
"321.93000","26.82768","0.36362"
"322.22400","26.85220","0.36550"
"322.51800","26.87665","0.36719"
"322.81200","26.90129","0.36956"
"323.10600","26.92568","0.37184"
"323.40000","26.95025","0.37328"
"323.69400","26.97471","0.37518"
"323.98800","26.99928","0.37710"
"324.28200","27.02373","0.37894"
"324.57600","27.04825","0.38108"
"324.87000","27.07276","0.38371"
"325.16400","27.09721","0.38551"
"325.45800","27.12173","0.38728"
"325.75200","27.14618","0.38887"
"326.04600","27.17076","0.39099"
"326.34000","27.19521","0.39271"
"326.63400","27.21972","0.39399"
"326.92800","27.24418","0.27418"
"327.22200","27.26869","0.01691"
"327.51600","27.29314","0.03631"
"327.81000","27.31766","0.00934"
"328.10400","27.34223","0.01664"
"328.39800","27.36669","0.01345"
"328.69200","27.39126","0.01008"
"328.98600","27.41566","0.01589"
"329.28000","27.44023","0.01079"
"329.57400","27.46468","0.01950"
"329.86800","27.48925","0.01024"
"330.16200","27.51371","0.01595"
"330.45600","27.53828","0.01389"
"330.75000","27.56274","0.01453"
"331.04400","27.58725","0.01667"
"331.33800","27.61176","0.01191"
"331.63200","27.63622","0.01741"
"331.92600","27.66073","0.01284"
"332.22000","27.68518","0.01661"
"332.51400","27.70976","0.01402"
"332.80800","27.73421","0.01531"
"333.10200","27.75872","0.01610"
"333.39600","27.78318","0.01307"
"333.69000","27.80775","0.01684"
"333.98400","27.83221","0.01435"
"334.27800","27.85666","0.01658"
"334.57200","27.88124","0.01508"
"334.86600","27.90569","0.01502"
"335.16000","27.93026","0.01619"
"335.45400","27.95472","0.01451"
"335.74800","27.97923","0.01685"
"336.04200","28.00374","0.01500"
"336.33600","28.02826","0.01641"
"336.63000","28.05271","0.01631"
"336.92400","28.07722","0.01561"
"337.21800","28.10174","0.01684"
"337.51200","28.12625","0.01538"
"337.80600","28.15077","0.01723"
"338.10000","28.17522","0.01632"
"338.39400","28.19973","0.01614"
"338.68800","28.22419","0.01659"
"338.98200","28.24876","0.01582"
"339.27600","28.27316","0.01732"
"339.57000","28.29773","0.01624"
"339.86400","28.32218","0.01715"
"340.15800","28.34669","0.01720"
"340.45200","28.37115","0.01650"
"340.74600","28.39566","0.01785"
"341.04000","28.42018","0.01677"
"341.33400","28.44469","0.01767"
"341.62800","28.46926","0.01706"
"341.92200","28.49372","0.01700"
"342.21600","28.51829","0.01773"
"342.51000","28.54275","0.01693"
"342.80400","28.56726","0.01816"
"343.09800","28.59171","0.01706"
"343.39200","28.61623","0.01774"
"343.68600","28.64074","0.01762"
"343.98000","28.66525","0.01736"
"344.27400","28.68977","0.01883"
"344.56800","28.71422","0.01788"
"344.86200","28.73874","0.01823"
"345.15600","28.76319","0.01919"
"345.45000","28.78770","0.01808"
"345.74400","28.81216","0.01916"
"346.03800","28.83673","0.01834"
"346.33200","28.86125","0.01904"
"346.62600","28.88570","0.01875"
"346.92000","28.91021","0.01907"
"347.21400","28.93473","0.01951"
"347.50800","28.95924","0.01904"
"347.80200","28.98369","0.01961"
"348.09600","29.00827","0.01932"
"348.39000","29.03266","0.01913"
"348.68400","29.05729","0.02031"
"348.97800","29.08169","0.01989"
"349.27200","29.10620","0.02019"
"349.56600","29.13072","0.02046"
"349.86000","29.15523","0.02061"
"350.15400","29.17969","0.02059"
"350.44800","29.20420","0.02090"
"350.74200","29.22871","0.02113"
"351.03600","29.25317","0.02102"
"351.33000","29.27768","0.02068"
"351.62400","29.30219","0.02127"
"351.91800","29.32671","0.02130"
"352.21200","29.35116","0.02170"
"352.50600","29.37567","0.02145"
"352.80000","29.40019","0.02182"
"353.09400","29.42470","0.02201"
"353.38800","29.44922","0.02198"
"353.68200","29.47373","0.02195"
"353.97600","29.49824","0.02277"
"354.27000","29.52270","0.02290"
"354.56400","29.54727","0.02281"
"354.85800","29.57173","0.02338"
"355.15200","29.59630","0.02362"
"355.44600","29.62075","0.02392"
"355.74000","29.64521","0.02384"
"356.03400","29.66972","0.02432"
"356.32800","29.69423","0.02448"
"356.62200","29.71875","0.02462"
"356.91600","29.74326","0.02534"
"357.21000","29.76777","0.02597"
"357.50400","29.79223","0.02629"
"357.79800","29.81674","0.02619"
"358.09200","29.84114","0.02686"
"358.38600","29.86571","0.02757"
"358.68000","29.89017","0.02824"
"358.97400","29.91474","0.02896"
"359.26800","29.93925","0.02911"
"359.56200","29.96377","0.02970"
"359.85600","29.98822","0.02961"
"360.15000","30.01267","0.03017"
"360.44400","30.03725","0.03131"
"360.73800","30.06170","0.03205"
"361.03200","30.08621","0.03196"
"361.32600","30.11073","0.03189"
"361.62000","30.13524","0.03236"
"361.91400","30.15969","0.03206"
"362.20800","30.18421","0.03251"
"362.50200","30.20866","0.03285"
"362.79600","30.23318","0.03071"
"363.09000","30.25769","0.02337"
"363.38400","30.28214","0.02476"
"363.67800","30.30672","0.02570"
"363.97200","30.33117","0.02477"
"364.26600","30.35574","0.02612"
"364.56000","30.38014","0.02549"
"364.85400","30.40477","0.02638"
"365.14800","30.42923","0.02707"
"365.44200","30.45374","0.02700"
"365.73600","30.47825","0.02803"
"366.03000","30.50271","0.02786"
"366.32400","30.52728","0.02834"
"366.61800","30.55173","0.02891"
"366.91200","30.57625","0.02906"
"367.20600","30.60070","0.02972"
"367.50000","30.62522","0.03020"
"367.79400","30.64967","0.03043"
"368.08800","30.67425","0.03116"
"368.38200","30.69870","0.03097"
"368.67600","30.72327","0.03183"
"368.97000","30.74773","0.03240"
"369.26400","30.77218","0.03284"
"369.55800","30.79675","0.03324"
"369.85200","30.82127","0.03398"
"370.14600","30.84572","0.03459"
"370.44000","30.87023","0.03548"
"370.73400","30.89469","0.03523"
"371.02800","30.91914","0.03640"
"371.32200","30.94371","0.03651"
"371.61600","30.96823","0.03680"
"371.91000","30.99274","0.03840"
"372.20400","31.01726","0.03825"
"372.49800","31.04171","0.03959"
"372.79200","31.06629","0.04053"
"373.08600","31.09068","0.04099"
"373.38000","31.11525","0.04290"
"373.67400","31.13970","0.04321"
"373.96800","31.16428","0.04416"
"374.26200","31.18867","0.04483"
"374.55600","31.21325","0.04623"
"374.85000","31.23770","0.04689"
"375.14400","31.26221","0.04755"
"375.43800","31.28666","0.04915"
"375.73200","31.31118","0.05041"
"376.02600","31.33569","0.05133"
"376.32000","31.36021","0.05200"
"376.61400","31.38472","0.05305"
"376.90800","31.40917","0.05417"
"377.20200","31.43375","0.05482"
"377.49600","31.45814","0.05533"
"377.79000","31.48272","0.05543"
"378.08400","31.50717","0.05667"
"378.37800","31.53174","0.05696"
"378.67200","31.55626","0.05780"
"378.96600","31.58077","0.05882"
"379.26000","31.60528","0.05970"
"379.55400","31.62968","0.06061"
"379.84800","31.65419","0.06110"
"380.14200","31.67865","0.06134"
"380.43600","31.70322","0.06177"
"380.73000","31.72767","0.06278"
"381.02400","31.75219","0.06321"
"381.31800","31.77670","0.06384"
"381.61200","31.80122","0.06493"
"381.90600","31.82573","0.06582"
"382.20000","31.85018","0.06680"
"382.49400","31.87476","0.06770"
"382.78800","31.89915","0.06969"
"383.08200","31.92372","0.07056"
"383.37600","31.94818","0.07223"
"383.67000","31.97275","0.07318"
"383.96400","31.99720","0.07439"
"384.25800","32.02178","0.07646"
"384.55200","32.04623","0.07699"
"384.84600","32.07074","0.07837"
"385.14000","32.09520","0.07847"
"385.43400","32.11971","0.08019"
"385.72800","32.14423","0.07987"
"386.02200","32.16868","0.08200"
"386.31600","32.19320","0.08357"
"386.61000","32.21765","0.08438"
"386.90400","32.24222","0.08514"
"387.19800","32.26668","0.08714"
"387.49200","32.29119","0.08885"
"387.78600","32.31570","0.09099"
"388.08000","32.34016","0.09237"
"388.37400","32.36467","0.09404"
"388.66800","32.38919","0.09609"
"388.96200","32.41370","0.09719"
"389.25600","32.43821","0.09838"
"389.55000","32.46273","0.10047"
"389.84400","32.48718","0.10085"
"390.13800","32.51175","0.10243"
"390.43200","32.53621","0.10319"
"390.72600","32.56078","0.10409"
"391.02000","32.58523","0.10518"
"391.31400","32.60975","0.10568"
"391.60800","32.63426","0.10649"
"391.90200","32.65871","0.10745"
"392.19600","32.68323","0.10784"
"392.49000","32.70762","0.10847"
"392.78400","32.73225","0.10882"
"393.07800","32.75671","0.10974"
"393.37200","32.78128","0.11030"
"393.66600","32.80568","0.11071"
"393.96000","32.83019","0.11137"
"394.25400","32.85471","0.11248"
"394.54800","32.87922","0.11313"
"394.84200","32.90374","0.11436"
"395.13600","32.92819","0.11618"
"395.43000","32.95276","0.11801"
"395.72400","32.97721","0.11923"
"396.01800","33.00173","0.12039"
"396.31200","33.02625","0.12167"
"396.60600","33.05076","0.12411"
"396.90000","33.07521","0.12618"
"397.19400","33.09973","0.12858"
"397.48800","33.12424","0.13053"
"397.78200","33.14869","0.13350"
"398.07600","33.17321","0.13614"
"398.37000","33.19766","0.13908"
"398.66400","33.22223","0.14217"
"398.95800","33.24662","0.14471"
"399.25200","33.27120","0.14780"
"399.54600","33.29559","0.14995"
"399.84000","33.32023","0.15217"
"400.13400","33.34468","0.15112"
"400.42800","33.36926","0.15454"
"400.72200","33.39371","0.15693"
"401.01600","33.41822","0.15879"
"401.31000","33.44273","0.16135"
"401.60400","33.46725","0.16341"
"401.89800","33.49176","0.16425"
"402.19200","33.51622","0.16670"
"402.48600","33.54073","0.16842"
"402.78000","33.56519","0.16953"
"403.07400","33.58976","0.17030"
"403.36800","33.61422","0.17169"
"403.66200","33.63873","0.17331"
"403.95600","33.66324","0.17457"
"404.25000","33.68776","0.17607"
"404.54400","33.71227","0.17779"
"404.83800","33.73672","0.17980"
"405.13200","33.76124","0.18121"
"405.42600","33.78569","0.18324"
"405.72000","33.81026","0.18494"
"406.01400","33.83466","0.18651"
"406.30800","33.85923","0.18845"
"406.60200","33.88368","0.19128"
"406.89600","33.90820","0.19439"
"407.19000","33.93271","0.19695"
"407.48400","33.95723","0.19919"
"407.77800","33.98174","0.20143"
"408.07200","34.00620","0.20388"
"408.36600","34.03077","0.20575"
"408.66000","34.05516","0.20790"
"408.95400","34.07979","0.20978"
"409.24800","34.10425","0.21113"
"409.54200","34.12876","0.21293"
"409.83600","34.15322","0.21424"
"410.13000","34.17773","0.21551"
"410.42400","34.20230","0.21662"
"410.71800","34.22670","0.21791"
"411.01200","34.25121","0.21889"
"411.30600","34.27567","0.21972"
"411.60000","34.30018","0.22080"
"411.89400","34.32463","0.22202"
"412.18800","34.34921","0.22355"
"412.48200","34.37366","0.22559"
"412.77600","34.39817","0.22724"
"413.07000","34.42269","0.22953"
"413.36400","34.44720","0.23166"
"413.65800","34.47171","0.23450"
"413.95200","34.49617","0.23696"
"414.24600","34.52074","0.23886"
"414.54000","34.54519","0.24152"
"414.83400","34.56977","0.24395"
"415.12800","34.59422","0.24714"
"415.42200","34.61880","0.24923"
"415.71600","34.64319","0.25218"
"416.01000","34.66771","0.25370"
"416.30400","34.69222","0.25583"
"416.59800","34.71673","0.25804"
"416.89200","34.74125","0.25953"
"417.18600","34.76570","0.26239"
"417.48000","34.79028","0.26414"
"417.77400","34.81473","0.26596"
"418.06800","34.83924","0.26828"
"418.36200","34.86364","0.27037"
"418.65600","34.88821","0.27248"
"418.95000","34.91267","0.27591"
"419.24400","34.93724","0.27991"
"419.53800","34.96169","0.28354"
"419.83200","34.98621","0.28683"
"420.12600","35.01072","0.29154"
"420.42000","35.03523","0.29626"
"420.71400","35.05981","0.30001"
"421.00800","35.08420","0.30375"
"421.30200","35.10871","0.30656"
"421.59600","35.13317","0.30939"
"421.89000","35.15774","0.31249"
"422.18400","35.18219","0.31442"
"422.47800","35.20671","0.31656"
"422.77200","35.23116","0.31898"
"423.06600","35.25567","0.32090"
"423.36000","35.28025","0.32202"
"423.65400","35.30464","0.32295"
"423.94800","35.32922","0.32368"
"424.24200","35.35367","0.32426"
"424.53600","35.37819","0.32442"
"424.83000","35.40264","0.32538"
"425.12400","35.42727","0.32601"
"425.41800","35.45166","0.01580"
"425.71200","35.47624","0.02080"
"426.00600","35.50076","0.01010"
"426.30000","35.52526","0.01780"
"426.59400","35.54972","0.01453"
"426.88800","35.57423","0.01603"
"427.18200","35.59875","0.01458"
"427.47600","35.62320","0.01491"
"427.77000","35.64778","0.01571"
"428.06400","35.67223","0.01300"
"428.35800","35.69680","0.01555"
"428.65200","35.72120","0.01421"
"428.94600","35.74571","0.01455"
"429.24000","35.77022","0.01474"
"429.53400","35.79474","0.01502"
"429.82800","35.81925","0.01427"
"430.12200","35.84370","0.01500"
"430.41600","35.86822","0.01684"
"430.71000","35.89267","0.01398"
"431.00400","35.91719","0.01504"
"431.29800","35.94164","0.01406"
"431.59200","35.96621","0.01551"
"431.88600","35.99073","0.01393"
"432.18000","36.01524","0.01516"
"432.47400","36.03975","0.01455"
"432.76800","36.06427","0.01547"
"433.06200","36.08878","0.01491"
"433.35600","36.11318","0.01554"
"433.36400","36.11383","0.01559"