File: Force_trajectories/170226_3/Specimen_RawData_5.csv
End date,"2/26/2017"
Specimen label,"4CT_23_pl"
Maximum Load,"0.00139",N

Time,Extension,Load
(s),(mm),(N)
"0.00000","0.00000","0.00061"
"0.02400","0.00024","0.00055"
"0.04800","0.00090","0.00063"
"0.07200","0.00203","0.00065"
"0.09600","0.00359","0.00033"
"0.12000","0.00580","0.00044"
"0.14400","0.00819","0.00037"
"0.16800","0.01070","0.00037"
"0.19200","0.01333","0.00050"
"0.21600","0.01590","0.00089"
"0.24000","0.01847","0.00100"
"0.26400","0.02099","0.00080"
"0.28800","0.02332","0.00051"
"0.31200","0.02565","0.00053"
"0.33600","0.02780","0.00052"
"0.36000","0.02995","0.00055"
"0.38400","0.03211","0.00071"
"0.40800","0.03420","0.00053"
"0.43200","0.03617","0.00032"
"0.45600","0.03821","0.00045"
"0.48000","0.04024","0.00025"
"0.50400","0.04227","0.00054"
"0.52800","0.04430","0.00014"
"0.55200","0.04628","0.00020"
"0.57600","0.04819","-0.00012"
"0.60000","0.05016","0.00008"
"0.62400","0.05214","0.00010"
"0.64800","0.05417","0.00027"
"0.67200","0.05620","0.00027"
"0.69600","0.05818","0.00044"
"0.72000","0.06015","0.00053"
"0.74400","0.06212","0.00025"
"0.76800","0.06415","0.00012"
"0.79200","0.06619","0.00011"
"0.81600","0.06822","-0.00009"
"0.84000","0.07019","0.00016"
"0.86400","0.07217","0.00070"
"0.88800","0.07414","0.00054"
"0.91200","0.07611","0.00043"
"0.93600","0.07820","0.00057"
"0.96000","0.08024","0.00030"
"0.98400","0.08221","0.00045"
"1.00800","0.08418","0.00064"
"1.03200","0.08622","0.00042"
"1.05600","0.08819","0.00004"
"1.08000","0.09022","0.00004"
"1.10400","0.09232","0.00084"
"1.12800","0.09423","0.00139"
"1.15200","0.09620","0.00070"
"1.17600","0.09817","0.00027"
"1.20000","0.10021","0.00069"
"1.22400","0.10218","0.00046"
"1.24800","0.10421","0.00031"
"1.27200","0.10613","0.00020"
"1.29600","0.10810","0.00061"
"1.32000","0.11007","0.00047"
"1.34400","0.11211","0.00040"
"1.36800","0.11414","0.00050"
"1.39200","0.11617","0.00061"
"1.41600","0.11814","0.00055"
"1.44000","0.12012","0.00030"
"1.46400","0.12209","0.00067"
"1.48800","0.12412","0.00059"
"1.51200","0.12616","0.00021"
"1.53600","0.12819","0.00042"
"1.56000","0.13016","0.00072"
"1.58400","0.13213","0.00011"
"1.60800","0.13411","0.00021"
"1.63200","0.13614","0.00057"
"1.65600","0.13817","0.00051"
"1.68000","0.14021","0.00047"
"1.70400","0.14218","0.00066"
"1.72800","0.14415","0.00049"
"1.75200","0.14619","0.00032"
"1.77600","0.14816","0.00076"
"1.80000","0.15019","0.00068"
"1.82400","0.15216","0.00062"
"1.84800","0.15414","0.00047"
"1.87200","0.15611","0.00044"
"1.89600","0.15808","0.00090"
"1.92000","0.16012","0.00074"
"1.94400","0.16215","0.00009"
"1.96800","0.16412","-0.00012"
"1.99200","0.16616","0.00012"
"2.01600","0.16813","0.00057"
"2.04000","0.17016","0.00047"
"2.06400","0.17219","0.00077"
"2.08800","0.17423","0.00095"
"2.11200","0.17620","0.00053"
"2.13600","0.17823","0.00009"
"2.16000","0.18021","0.00018"
"2.18400","0.18218","0.00056"
"2.20800","0.18415","0.00030"
"2.23200","0.18612","0.00027"
"2.25600","0.18816","0.00042"
"2.28000","0.19013","0.00026"
"2.30400","0.19210","0.00073"
"2.32800","0.19414","0.00054"
"2.35200","0.19617","0.00007"
"2.37600","0.19814","0.00006"
"2.40000","0.20018","0.00042"
"2.42400","0.20215","0.00076"
"2.44800","0.20412","0.00120"
"2.47200","0.20609","0.00054"
"2.49600","0.20807","0.00011"
"2.52000","0.21010","0.00034"
"2.54400","0.21213","0.00025"
"2.56800","0.21411","0.00051"
"2.59200","0.21608","0.00101"
"2.61600","0.21811","0.00060"
"2.64000","0.22015","0.00051"
"2.66400","0.22218","0.00071"
"2.68800","0.22421","0.00029"
"2.71200","0.22618","0.00035"
"2.73600","0.22816","0.00032"
"2.76000","0.23013","0.00016"
"2.78400","0.23216","0.00025"
"2.80800","0.23414","-0.00019"
"2.83200","0.23617","0.00019"
"2.85600","0.23814","0.00038"
"2.88000","0.24017","0.00013"
"2.90400","0.24215","0.00046"
"2.92800","0.24412","0.00032"
"2.95200","0.24615","0.00032"
"2.97600","0.24807","0.00064"
"3.00000","0.25010","0.00054"
"3.02400","0.25213","0.00042"
"3.04800","0.25411","0.00030"
"3.07200","0.25608","0.00041"
"3.09600","0.25811","0.00049"
"3.12000","0.26008","0.00007"
"3.14400","0.26212","0.00025"
"3.16800","0.26415","0.00026"
"3.19200","0.26618","0.00053"
"3.21600","0.26816","0.00050"
"3.24000","0.27019","0.00068"
"3.26400","0.27216","0.00053"
"3.28800","0.27419","0.00018"
"3.31200","0.27617","0.00030"
"3.33600","0.27820","0.00031"
"3.36000","0.28017","0.00036"
"3.38400","0.28215","0.00035"
"3.40800","0.28418","0.00019"
"3.43200","0.28615","0.00055"
"3.45600","0.28819","0.00066"
"3.48000","0.29016","0.00061"
"3.50400","0.29213","0.00024"
"3.52800","0.29410","0.00009"
"3.55200","0.29608","0.00033"
"3.57600","0.29811","0.00034"
"3.60000","0.30008","0.00042"
"3.62400","0.30212","0.00048"
"3.64800","0.30409","0.00055"
"3.67200","0.30612","0.00030"
"3.69600","0.30816","0.00037"
"3.72000","0.31019","0.00040"
"3.74400","0.31216","0.00024"
"3.76800","0.31419","0.00020"
"3.79200","0.31617","0.00096"
"3.81600","0.31820","0.00103"
"3.84000","0.32017","0.00045"
"3.86400","0.32215","0.00043"
"3.88800","0.32418","0.00072"
"3.91200","0.32615","0.00076"
"3.93600","0.32812","0.00080"
"3.96000","0.33022","0.00072"
"3.98400","0.33219","0.00070"
"4.00800","0.33416","0.00037"
"4.03200","0.33614","0.00022"
"4.05600","0.33811","0.00054"
"4.08000","0.34014","0.00064"
"4.10400","0.34212","0.00021"
"4.12800","0.34409","0.00028"
"4.15200","0.34606","0.00050"
"4.17600","0.34809","0.00072"
"4.20000","0.35007","0.00039"
"4.22400","0.35210","0.00030"
"4.24800","0.35419","0.00019"
"4.27200","0.35617","0.00033"
"4.29600","0.35820","0.00028"
"4.32000","0.36017","0.00022"
"4.34400","0.36215","-0.00018"
"4.36800","0.36418","0.00015"
"4.39200","0.36621","0.00046"
"4.41600","0.36818","0.00024"
"4.44000","0.37022","0.00027"
"4.46400","0.37219","0.00070"
"4.48800","0.37416","0.00041"
"4.51200","0.37614","0.00023"
"4.53600","0.37817","0.00009"
"4.56000","0.38014","0.00039"
"4.58400","0.38211","0.00061"
"4.60800","0.38409","-0.00008"
"4.63200","0.38612","-0.00040"
"4.65600","0.38809","-0.00029"
"4.68000","0.39013","0.00032"
"4.70400","0.39216","0.00028"
"4.72800","0.39413","0.00011"
"4.75200","0.39611","-0.00006"
"4.77600","0.39808","0.00028"
"4.80000","0.40011","0.00047"
"4.82400","0.40214","0.00038"
"4.84800","0.40418","0.00012"
"4.87200","0.40621","-0.00002"
"4.89600","0.40812","0.00054"
"4.92000","0.41010","0.00079"
"4.94400","0.41213","0.00033"
"4.96800","0.41416","0.00041"
"4.99200","0.41614","0.00027"
"5.01600","0.41817","0.00071"
"5.04000","0.42014","0.00025"
"5.06400","0.42211","0.00054"
"5.08800","0.42409","0.00096"
"5.11200","0.42612","0.00091"
"5.13600","0.42809","0.00062"
"5.16000","0.43007","0.00038"
"5.18400","0.43204","0.00019"
"5.20800","0.43407","0.00018"
"5.23200","0.43610","0.00073"
"5.25600","0.43814","0.00034"
"5.28000","0.44017","0.00033"
"5.30400","0.44214","0.00024"
"5.32800","0.44412","0.00015"
"5.35200","0.44609","0.00004"
"5.37600","0.44812","0.00022"
"5.40000","0.45022","0.00071"
"5.42400","0.45219","0.00090"
"5.44800","0.45416","0.00054"
"5.47200","0.45613","0.00054"
"5.49600","0.45817","0.00024"
"5.52000","0.46014","0.00030"
"5.54400","0.46217","0.00044"
"5.56800","0.46421","0.00005"
"5.59200","0.46618","-0.00011"
"5.61600","0.46815","0.00005"
"5.64000","0.47013","0.00055"
"5.66400","0.47210","0.00055"
"5.68800","0.47413","0.00044"
"5.71200","0.47610","0.00059"
"5.73600","0.47808","0.00057"
"5.76000","0.48005","0.00056"
"5.78400","0.48208","0.00050"
"5.80800","0.48412","0.00057"
"5.83200","0.48615","0.00016"
"5.85600","0.48818","-0.00004"
"5.88000","0.49015","-0.00014"
"5.90400","0.49219","0.00042"
"5.92800","0.49416","0.00071"
"5.95200","0.49619","0.00049"
"5.97600","0.49823","0.00066"
"6.00000","0.50020","0.00083"
"6.02400","0.50217","0.00041"
"6.04800","0.50415","-0.00004"
"6.07200","0.50612","0.00010"
"6.09600","0.50815","0.00045"
"6.12000","0.51018","0.00022"
"6.14400","0.51216","0.00024"
"6.16800","0.51413","0.00031"
"6.19200","0.51610","0.00033"
"6.21600","0.51814","0.00017"
"6.24000","0.52011","0.00024"
"6.26400","0.52214","0.00071"
"6.28800","0.52412","0.00039"
"6.31200","0.52609","0.00039"
"6.33600","0.52806","0.00072"
"6.36000","0.53009","0.00080"
"6.38400","0.53213","0.00096"
"6.40800","0.53416","0.00066"
"6.43200","0.53619","0.00032"
"6.45600","0.53817","-0.00001"
"6.48000","0.54014","-0.00036"
"6.50400","0.54211","-0.00033"
"6.52800","0.54414","0.00019"
"6.55200","0.54618","0.00062"
"6.57600","0.54815","0.00081"
"6.60000","0.55018","0.00063"
"6.62400","0.55216","0.00055"
"6.64800","0.55413","0.00117"
"6.67200","0.55616","0.00092"
"6.69600","0.55820","0.00098"
"6.72000","0.56017","0.00061"
"6.74400","0.56214","0.00056"
"6.76800","0.56417","0.00055"
"6.79200","0.56609","0.00085"
"6.81600","0.56812","0.00060"
"6.84000","0.57009","-0.00008"
"6.86400","0.57213","0.00008"
"6.88800","0.57410","0.00015"
"6.91200","0.57613","0.00042"
"6.93600","0.57810","0.00043"
"6.96000","0.58014","0.00062"
"6.98400","0.58211","0.00039"
"7.00800","0.58414","0.00023"
"7.03200","0.58612","0.00031"
"7.05600","0.58809","0.00014"
"7.08000","0.59012","0.00029"
"7.10400","0.59216","0.00061"
"7.12800","0.59419","0.00073"
"7.15200","0.59616","0.00048"
"7.17600","0.59819","0.00029"
"7.20000","0.60023","0.00046"
"7.22400","0.60214","0.00058"
"7.24800","0.60411","0.00096"
"7.27200","0.60609","0.00042"
"7.29600","0.60812","0.00052"
"7.32000","0.61009","0.00051"
"7.34400","0.61207","0.00088"
"7.36800","0.61404","0.00084"
"7.39200","0.61607","0.00074"
"7.41600","0.61810","0.00024"
"7.44000","0.62014","0.00030"
"7.46400","0.62217","0.00024"
"7.48800","0.62414","0.00060"
"7.51200","0.62618","0.00073"
"7.53600","0.62821","0.00084"
"7.56000","0.63024","0.00046"
"7.58400","0.63221","0.00002"
"7.60800","0.63419","0.00047"
"7.63200","0.63616","0.00030"
"7.65600","0.63813","0.00010"
"7.68000","0.64017","0.00011"
"7.70400","0.64220","0.00039"
"7.72800","0.64417","0.00051"
"7.75200","0.64615","0.00078"
"7.77600","0.64812","0.00056"
"7.80000","0.65015","0.00035"
"7.82400","0.65218","0.00047"
"7.84800","0.65416","0.00000"
"7.87200","0.65613","0.00028"
"7.89600","0.65810","0.00082"
"7.92000","0.66008","0.00059"
"7.94400","0.66211","0.00024"
"7.96800","0.66414","0.00000"
"7.99200","0.66618","0.00021"
"8.01600","0.66815","0.00030"
"8.04000","0.67018","0.00017"
"8.06400","0.67215","0.00025"
"8.08800","0.67419","0.00064"
"8.11200","0.67616","0.00052"
"8.13600","0.67819","0.00039"
"8.16000","0.68017","0.00008"
"8.18400","0.68214","0.00013"
"8.20800","0.68417","0.00074"
"8.23200","0.68614","0.00082"
"8.25600","0.68818","0.00063"
"8.28000","0.69015","0.00044"
"8.30400","0.69218","0.00009"
"8.32800","0.69416","0.00004"
"8.35200","0.69619","0.00072"
"8.37600","0.69816","0.00088"
"8.40000","0.70014","0.00093"
"8.42400","0.70211","0.00016"
"8.44800","0.70414","0.00031"
"8.47200","0.70611","0.00060"
"8.49600","0.70809","0.00033"
"8.52000","0.71012","0.00056"
"8.54400","0.71215","0.00038"
"8.56800","0.71413","0.00040"
"8.59200","0.71616","0.00048"
"8.61600","0.71819","0.00067"
"8.64000","0.72016","0.00085"
"8.66400","0.72214","0.00031"
"8.68800","0.72417","0.00046"
"8.71200","0.72614","0.00048"
"8.73600","0.72812","0.00028"
"8.76000","0.73015","0.00057"
"8.78400","0.73212","0.00067"
"8.80800","0.73416","0.00079"
"8.83200","0.73613","0.00116"
"8.85600","0.73816","0.00035"
"8.88000","0.74013","0.00019"
"8.90400","0.74217","0.00041"
"8.92800","0.74414","0.00054"
"8.95200","0.74611","0.00059"
"8.97600","0.74815","-0.00013"
"9.00000","0.75012","-0.00044"
"9.02400","0.75209","-0.00034"
"9.04800","0.75413","0.00002"
"9.07200","0.75610","0.00033"
"9.09600","0.75813","0.00058"
"9.12000","0.76016","0.00066"
"9.14400","0.76220","0.00046"
"9.16800","0.76423","0.00000"
"9.19200","0.76620","0.00015"
"9.21600","0.76818","0.00046"
"9.24000","0.77015","0.00013"
"9.26400","0.77218","0.00009"
"9.28800","0.77415","0.00032"
"9.31200","0.77613","0.00020"
"9.33600","0.77810","0.00064"
"9.36000","0.78013","0.00058"
"9.38400","0.78211","0.00046"
"9.40800","0.78414","0.00010"
"9.43200","0.78617","0.00000"
"9.45600","0.78815","0.00027"
"9.48000","0.79012","0.00046"
"9.50400","0.79209","0.00056"
"9.52800","0.79406","0.00035"
"9.55200","0.79610","0.00001"
"9.57600","0.79813","0.00005"
"9.60000","0.80016","0.00012"
"9.62400","0.80214","0.00002"
"9.64800","0.80411","0.00044"
"9.67200","0.80614","0.00068"
"9.69600","0.80818","0.00030"
"9.72000","0.81021","0.00001"
"9.74400","0.81218","0.00024"
"9.76800","0.81415","0.00028"
"9.79200","0.81613","0.00066"
"9.81600","0.81816","0.00045"
"9.84000","0.82019","0.00087"
"9.86400","0.82217","0.00051"
"9.88800","0.82414","-0.00009"
"9.91200","0.82611","0.00015"
"9.93600","0.82809","0.00025"
"9.96000","0.83012","-0.00004"
"9.98400","0.83215","0.00046"
"10.00800","0.83418","0.00104"
"10.03200","0.83616","0.00075"
"10.05600","0.83813","0.00052"
"10.08000","0.84010","0.00071"
"10.10400","0.84208","0.00083"
"10.12800","0.84417","0.00067"
"10.15200","0.84614","0.00043"
"10.17600","0.84811","0.00055"
"10.20000","0.85015","0.00097"
"10.22400","0.85218","0.00060"
"10.24800","0.85415","0.00027"
"10.27200","0.85619","0.00064"
"10.29600","0.85822","0.00031"
"10.32000","0.86019","0.00028"
"10.34400","0.86217","0.00062"
"10.36800","0.86420","0.00061"
"10.39200","0.86617","0.00075"
"10.41600","0.86814","0.00040"
"10.44000","0.87018","0.00009"
"10.46400","0.87209","0.00000"
"10.48800","0.87412","-0.00009"
"10.51200","0.87610","-0.00016"
"10.53600","0.87813","0.00046"
"10.56000","0.88010","0.00087"
"10.58400","0.88208","0.00080"
"10.60800","0.88411","0.00089"
"10.63200","0.88614","0.00036"
"10.65600","0.88817","0.00035"
"10.68000","0.89015","0.00058"
"10.70400","0.89218","0.00030"
"10.72800","0.89415","0.00021"
"10.75200","0.89619","0.00037"
"10.77600","0.89822","0.00062"
"10.80000","0.90019","0.00075"
"10.82400","0.90216","0.00063"
"10.84800","0.90414","0.00049"
"10.87200","0.90617","0.00041"
"10.89600","0.90820","0.00054"
"10.92000","0.91018","0.00056"
"10.94400","0.91221","0.00043"
"10.96800","0.91418","0.00042"
"10.99200","0.91616","0.00050"
"11.01600","0.91813","0.00067"
"11.04000","0.92016","0.00043"
"11.06400","0.92213","0.00052"
"11.08800","0.92417","0.00054"
"11.11200","0.92614","0.00054"
"11.13600","0.92811","0.00058"
"11.16000","0.93015","0.00056"
"11.18400","0.93212","0.00072"
"11.20800","0.93415","0.00082"
"11.23200","0.93618","0.00053"
"11.25600","0.93816","0.00030"
"11.28000","0.94019","0.00093"
"11.30400","0.94222","0.00033"
"11.32800","0.94420","0.00009"
"11.35200","0.94617","-0.00012"
"11.37600","0.94814","-0.00011"
"11.40000","0.95018","0.00024"
"11.42400","0.95221","0.00047"
"11.44800","0.95418","0.00045"
"11.47200","0.95615","0.00039"
"11.49600","0.95813","0.00061"
"11.52000","0.96016","0.00021"
"11.54400","0.96213","0.00045"
"11.56800","0.96417","0.00040"
"11.59200","0.96614","0.00040"
"11.61600","0.96811","0.00038"
"11.64000","0.97009","0.00074"
"11.66400","0.97206","0.00047"
"11.68800","0.97409","0.00063"
"11.71200","0.97618","0.00023"
"11.73600","0.97816","0.00039"
"11.76000","0.98013","0.00037"
"11.78400","0.98210","0.00044"
"11.80800","0.98414","0.00038"
"11.83200","0.98617","0.00006"
"11.85600","0.98820","0.00029"
"11.88000","0.99017","0.00044"
"11.90400","0.99215","0.00017"
"11.92800","0.99412","0.00005"
"11.95200","0.99615","0.00017"
"11.97600","0.99819","0.00058"
"12.00000","1.00022","0.00063"
"12.02400","1.00219","0.00065"
"12.04800","1.00417","0.00020"
"12.07200","1.00614","0.00052"
"12.09600","1.00811","0.00056"
"12.12000","1.01014","0.00049"
"12.14400","1.01212","0.00036"
"12.16800","1.01409","0.00027"
"12.19200","1.01612","0.00020"
"12.21600","1.01810","0.00028"
"12.24000","1.02007","0.00058"
"12.26400","1.02210","0.00088"
"12.28800","1.02413","0.00075"
"12.31200","1.02617","0.00021"
"12.33600","1.02820","0.00020"
"12.36000","1.03017","0.00024"
"12.38400","1.03221","0.00047"
"12.40800","1.03418","0.00019"
"12.43200","1.03621","-0.00019"
"12.45600","1.03819","0.00017"
"12.48000","1.04022","0.00014"
"12.50400","1.04219","0.00004"
"12.52800","1.04416","0.00025"
"12.55200","1.04614","0.00021"
"12.57600","1.04817","0.00030"
"12.60000","1.05014","0.00086"
"12.62400","1.05218","0.00050"
"12.64800","1.05415","0.00017"
"12.67200","1.05612","0.00027"
"12.69600","1.05810","0.00064"
"12.72000","1.06007","0.00071"
"12.74400","1.06210","0.00078"
"12.76800","1.06407","0.00056"
"12.79200","1.06611","0.00039"
"12.81600","1.06808","0.00052"
"12.84000","1.07011","0.00038"
"12.86400","1.07215","-0.00006"
"12.88800","1.07418","0.00032"
"12.91200","1.07615","0.00051"
"12.93600","1.07812","0.00021"
"12.96000","1.08010","0.00024"
"12.98400","1.08213","0.00031"
"13.00800","1.08416","0.00029"
"13.03200","1.08614","0.00054"
"13.05600","1.08811","0.00057"
"13.08000","1.09008","0.00073"
"13.10400","1.09212","0.00067"
"13.12800","1.09409","0.00039"
"13.15200","1.09612","0.00030"
"13.17600","1.09815","0.00029"
"13.20000","1.10013","0.00069"
"13.22400","1.10210","0.00069"
"13.24800","1.10407","0.00068"
"13.27200","1.10611","0.00083"
"13.29600","1.10814","0.00049"
"13.32000","1.11011","0.00054"
"13.34400","1.11215","0.00060"
"13.36800","1.11412","0.00031"
"13.39200","1.11609","0.00042"
"13.41600","1.11812","0.00021"
"13.44000","1.12016","0.00011"
"13.46400","1.12219","0.00028"
"13.48800","1.12416","0.00040"
"13.51200","1.12614","0.00020"
"13.53600","1.12817","0.00007"
"13.56000","1.13020","0.00019"
"13.58400","1.13223","0.00006"
"13.60800","1.13421","0.00055"
"13.63200","1.13618","0.00036"
"13.65600","1.13815","0.00075"
"13.68000","1.14013","0.00060"
"13.70400","1.14216","0.00053"
"13.72800","1.14413","0.00065"
"13.75200","1.14617","0.00066"
"13.77600","1.14814","0.00040"
"13.80000","1.15011","0.00070"
"13.82400","1.15208","0.00027"
"13.84800","1.15412","0.00048"
"13.87200","1.15615","0.00051"
"13.89600","1.15818","0.00021"
"13.92000","1.16010","0.00064"
"13.94400","1.16213","0.00048"
"13.96800","1.16410","0.00024"
"13.99200","1.16614","0.00049"
"14.01600","1.16823","0.00060"
"14.04000","1.17020","0.00071"
"14.06400","1.17217","0.00050"
"14.08800","1.17415","0.00011"
"14.11200","1.17618","0.00031"
"14.13600","1.17821","0.00042"
"14.16000","1.18019","0.00059"
"14.18400","1.18222","0.00046"
"14.20800","1.18413","0.00040"
"14.23200","1.18610","0.00025"
"14.25600","1.18814","0.00015"
"14.28000","1.19011","0.00021"
"14.30400","1.19214","0.00070"
"14.32800","1.19412","0.00054"
"14.35200","1.19609","0.00007"
"14.37600","1.19806","0.00029"
"14.40000","1.20010","0.00055"
"14.42400","1.20213","0.00069"
"14.44800","1.20416","0.00075"
"14.47200","1.20613","0.00034"
"14.49600","1.20811","0.00027"
"14.52000","1.21014","0.00061"
"14.54400","1.21217","0.00092"
"14.56800","1.21415","0.00057"
"14.59200","1.21618","0.00035"
"14.61600","1.21815","0.00016"
"14.64000","1.22018","0.00041"
"14.66400","1.22216","0.00107"
"14.68800","1.22419","0.00075"
"14.71200","1.22616","0.00028"
"14.73600","1.22820","0.00054"
"14.76000","1.23017","0.00004"
"14.78400","1.23214","0.00040"
"14.80800","1.23412","0.00025"
"14.83200","1.23615","0.00040"
"14.85600","1.23812","0.00023"
"14.88000","1.24009","0.00046"
"14.90400","1.24213","0.00056"
"14.92800","1.24410","0.00012"
"14.95200","1.24613","0.00037"
"14.97600","1.24811","0.00058"
"15.00000","1.25014","0.00069"
"15.02400","1.25211","0.00031"
"15.04800","1.25415","0.00020"
"15.07200","1.25618","0.00022"
"15.09600","1.25815","0.00000"
"15.12000","1.26012","0.00075"
"15.14400","1.26216","0.00071"
"15.16800","1.26419","0.00040"
"15.19200","1.26616","-0.00001"
"15.21600","1.26820","-0.00003"
"15.24000","1.27017","0.00056"
"15.26400","1.27214","0.00035"
"15.28800","1.27417","-0.00017"
"15.31200","1.27615","0.00053"
"15.33600","1.27812","0.00077"
"15.36000","1.28009","0.00027"
"15.38400","1.28207","0.00041"
"15.40800","1.28410","0.00026"
"15.43200","1.28613","0.00022"
"15.45600","1.28817","0.00029"
"15.48000","1.29014","0.00044"
"15.50400","1.29211","0.00083"
"15.52800","1.29408","0.00071"
"15.55200","1.29612","0.00068"
"15.57600","1.29815","0.00054"
"15.60000","1.30018","0.00016"
"15.62400","1.30216","-0.00012"
"15.64800","1.30413","0.00016"
"15.67200","1.30610","0.00031"
"15.69600","1.30814","0.00048"
"15.72000","1.31017","0.00081"
"15.74400","1.31220","0.00072"
"15.76800","1.31417","0.00053"
"15.79200","1.31615","0.00061"
"15.81600","1.31812","0.00039"
"15.84000","1.32015","-0.00032"
"15.86400","1.32213","0.00017"
"15.88800","1.32410","0.00031"
"15.91200","1.32607","0.00031"
"15.93600","1.32810","0.00019"
"15.96000","1.33008","0.00013"
"15.98400","1.33205","0.00028"
"16.00800","1.33408","0.00080"
"16.03200","1.33612","0.00105"
"16.05600","1.33815","0.00050"
"16.08000","1.34018","-0.00031"
"16.10400","1.34222","0.00011"
"16.12800","1.34419","-0.00008"
"16.15200","1.34616","0.00013"
"16.17600","1.34819","-0.00001"
"16.20000","1.35017","0.00017"
"16.22400","1.35220","0.00002"
"16.24800","1.35417","0.00013"
"16.27200","1.35621","0.00058"
"16.29600","1.35818","0.00104"
"16.32000","1.36015","-0.00026"
"16.34400","1.36219","-0.00032"
"16.36800","1.36416","0.00026"
"16.39200","1.36619","0.00024"
"16.41600","1.36816","0.00032"
"16.44000","1.37014","0.00063"
"16.46400","1.37211","0.00035"
"16.48800","1.37408","0.00033"
"16.51200","1.37612","0.00024"
"16.53600","1.37809","0.00050"
"16.56000","1.38012","0.00017"
"16.58400","1.38209","-0.00001"
"16.60800","1.38413","0.00006"
"16.63200","1.38610","0.00001"
"16.65600","1.38813","0.00021"
"16.68000","1.39017","0.00030"
"16.70400","1.39220","0.00022"
"16.72800","1.39417","0.00025"
"16.75200","1.39621","-0.00012"
"16.77600","1.39818","-0.00006"
"16.80000","1.40015","0.00033"
"16.82400","1.40218","0.00016"
"16.84800","1.40416","0.00040"
"16.87200","1.40619","0.00021"
"16.89600","1.40816","0.00025"
"16.92000","1.41014","0.00032"
"16.94400","1.41211","-0.00010"
"16.96800","1.41414","0.00004"
"16.99200","1.41612","-0.00008"
"17.01600","1.41815","-0.00012"
"17.04000","1.42012","0.00018"
"17.06400","1.42209","0.00046"
"17.08800","1.42413","0.00061"
"17.11200","1.42610","0.00042"
"17.13600","1.42813","0.00039"
"17.16000","1.43017","0.00068"
"17.18400","1.43220","0.00100"
"17.20800","1.43417","0.00085"
"17.23200","1.43620","0.00062"
"17.25600","1.43812","0.00055"
"17.28000","1.44015","-0.00018"
"17.30400","1.44218","0.00006"
"17.32800","1.44416","0.00005"
"17.35200","1.44613","0.00020"
"17.37600","1.44816","0.00038"
"17.40000","1.45014","0.00071"
"17.42400","1.45217","0.00020"
"17.44800","1.45420","0.00011"
"17.47200","1.45617","-0.00003"
"17.49600","1.45815","0.00049"
"17.52000","1.46012","0.00086"
"17.54400","1.46209","0.00040"
"17.56800","1.46407","0.00035"
"17.59200","1.46610","0.00016"
"17.61600","1.46819","0.00044"
"17.64000","1.47016","0.00062"
"17.66400","1.47214","0.00046"
"17.68800","1.47411","0.00031"
"17.71200","1.47614","-0.00002"
"17.73600","1.47818","0.00038"
"17.76000","1.48021","0.00025"
"17.78400","1.48218","0.00031"
"17.80800","1.48416","0.00065"
"17.83200","1.48613","0.00082"
"17.85600","1.48810","0.00081"
"17.88000","1.49013","0.00059"
"17.90400","1.49217","0.00039"
"17.92800","1.49414","0.00062"
"17.95200","1.49611","0.00044"
"17.97600","1.49809","0.00003"
"18.00000","1.50012","0.00046"
"18.02400","1.50215","0.00051"
"18.04800","1.50419","0.00047"
"18.07200","1.50610","0.00000"
"18.09600","1.50813","0.00031"
"18.12000","1.51010","0.00045"
"18.14400","1.51208","0.00021"
"18.16800","1.51417","0.00020"
"18.19200","1.51614","0.00041"
"18.21600","1.51812","0.00052"
"18.24000","1.52015","0.00062"
"18.26400","1.52212","0.00058"
"18.28800","1.52415","0.00091"
"18.31200","1.52619","0.00077"
"18.33600","1.52816","0.00091"
"18.36000","1.53013","0.00096"
"18.38400","1.53217","0.00052"
"18.40800","1.53414","0.00017"
"18.43200","1.53617","0.00028"
"18.45600","1.53821","0.00045"
"18.48000","1.54018","0.00069"
"18.50400","1.54215","0.00049"
"18.52800","1.54412","0.00042"
"18.55200","1.54616","0.00042"
"18.57600","1.54813","0.00007"
"18.60000","1.55010","0.00014"
"18.62400","1.55214","-0.00006"
"18.64800","1.55411","0.00000"
"18.67200","1.55614","0.00056"
"18.69600","1.55812","0.00050"
"18.72000","1.56015","0.00026"
"18.74400","1.56218","0.00006"
"18.76800","1.56415","0.00023"
"18.79200","1.56613","0.00011"
"18.81600","1.56816","-0.00005"
"18.84000","1.57013","0.00026"
"18.86400","1.57217","0.00023"
"18.88800","1.57420","0.00052"
"18.91200","1.57617","0.00042"
"18.93600","1.57820","0.00033"
"18.96000","1.58018","-0.00030"
"18.98400","1.58221","0.00018"
"19.00800","1.58418","0.00022"
"19.03200","1.58622","0.00044"
"19.05600","1.58819","0.00037"
"19.08000","1.59016","0.00020"
"19.10400","1.59214","0.00013"
"19.12800","1.59411","0.00039"
"19.15200","1.59614","0.00038"
"19.17600","1.59817","0.00060"
"19.20000","1.60015","0.00044"
"19.22400","1.60212","0.00045"
"19.24800","1.60409","0.00059"
"19.27200","1.60613","0.00029"
"19.29600","1.60816","0.00066"
"19.32000","1.61019","0.00099"
"19.34400","1.61216","0.00023"
"19.36800","1.61420","0.00051"
"19.39200","1.61611","0.00050"
"19.41600","1.61814","0.00041"
"19.44000","1.62012","0.00029"
"19.46400","1.62215","0.00050"
"19.48800","1.62418","0.00092"
"19.51200","1.62616","0.00076"
"19.53600","1.62813","0.00006"
"19.56000","1.63010","-0.00004"
"19.58400","1.63213","0.00042"
"19.60800","1.63417","0.00069"
"19.63200","1.63614","0.00072"
"19.65600","1.63811","0.00077"
"19.68000","1.64009","0.00040"
"19.70400","1.64206","0.00058"
"19.72800","1.64409","0.00059"
"19.75200","1.64613","0.00074"
"19.77600","1.64810","0.00045"
"19.80000","1.65013","0.00020"
"19.82400","1.65216","0.00048"
"19.84800","1.65414","0.00069"
"19.87200","1.65617","0.00052"
"19.89600","1.65820","0.00043"
"19.92000","1.66018","0.00026"
"19.94400","1.66221","0.00005"
"19.96800","1.66418","0.00012"
"19.99200","1.66615","0.00056"
"20.01600","1.66819","0.00030"
"20.04000","1.67016","0.00024"
"20.06400","1.67219","0.00038"
"20.08800","1.67417","0.00062"
"20.11200","1.67614","0.00073"
"20.13600","1.67811","0.00048"
"20.16000","1.68015","0.00029"
"20.18400","1.68218","0.00038"
"20.20800","1.68415","0.00068"
"20.23200","1.68618","0.00056"
"20.25600","1.68816","0.00051"
"20.28000","1.69007","0.00070"
"20.30400","1.69210","0.00031"
"20.32800","1.69414","0.00013"
"20.35200","1.69617","0.00012"
"20.37600","1.69814","0.00017"
"20.40000","1.70018","0.00039"
"20.42400","1.70215","0.00022"
"20.44800","1.70418","0.00041"
"20.47200","1.70621","0.00005"
"20.49600","1.70819","0.00044"
"20.52000","1.71016","0.00096"
"20.54400","1.71219","0.00057"
"20.56800","1.71417","0.00030"
"20.59200","1.71620","0.00093"
"20.61600","1.71817","0.00112"
"20.64000","1.72020","0.00049"
"20.66400","1.72218","0.00015"
"20.68800","1.72409","0.00036"
"20.71200","1.72612","-0.00037"
"20.73600","1.72816","0.00000"
"20.76000","1.73013","0.00039"
"20.78400","1.73210","0.00082"
"20.80800","1.73408","0.00080"
"20.83200","1.73605","0.00077"
"20.85600","1.73808","0.00010"
"20.88000","1.74011","0.00047"
"20.90400","1.74215","0.00078"
"20.92800","1.74418","0.00041"
"20.95200","1.74615","0.00037"
"20.97600","1.74813","0.00052"
"21.00000","1.75016","0.00085"
"21.02400","1.75219","0.00049"
"21.04800","1.75423","0.00024"
"21.07200","1.75620","0.00055"
"21.09600","1.75817","0.00043"
"21.12000","1.76014","0.00056"
"21.14400","1.76212","0.00074"
"21.16800","1.76415","0.00039"
"21.19200","1.76618","0.00011"
"21.21600","1.76816","0.00037"
"21.24000","1.77013","0.00007"
"21.26400","1.77210","-0.00013"
"21.28800","1.77408","0.00013"
"21.31200","1.77611","0.00025"
"21.33600","1.77808","0.00043"
"21.36000","1.78011","0.00017"
"21.38400","1.78209","0.00003"
"21.40800","1.78412","0.00021"
"21.43200","1.78609","0.00049"
"21.45600","1.78813","0.00004"
"21.48000","1.79022","0.00010"
"21.50400","1.79219","0.00022"
"21.52800","1.79416","0.00075"
"21.55200","1.79620","0.00061"
"21.57600","1.79817","0.00045"
"21.60000","1.80020","-0.00006"
"21.62400","1.80224","0.00001"
"21.64800","1.80421","0.00008"
"21.67200","1.80618","0.00027"
"21.69600","1.80816","0.00033"
"21.72000","1.81013","0.00041"
"21.74400","1.81216","-0.00007"
"21.76800","1.81419","0.00017"
"21.79200","1.81617","0.00046"
"21.81600","1.81814","0.00031"
"21.84000","1.82011","0.00055"
"21.86400","1.82209","-0.00005"
"21.88800","1.82412","-0.00007"
"21.91200","1.82615","0.00017"
"21.93600","1.82812","0.00044"
"21.96000","1.83016","0.00045"
"21.98400","1.83213","0.00071"
"22.00800","1.83416","0.00068"
"22.03200","1.83620","0.00071"
"22.05600","1.83823","0.00048"
"22.08000","1.84020","0.00009"
"22.10400","1.84218","0.00031"
"22.12800","1.84415","0.00045"
"22.15200","1.84618","0.00036"
"22.17600","1.84821","0.00056"
"22.20000","1.85019","0.00066"
"22.22400","1.85216","0.00030"
"22.24800","1.85419","-0.00014"
"22.27200","1.85617","-0.00018"
"22.29600","1.85814","0.00033"
"22.32000","1.86017","0.00034"
"22.34400","1.86215","0.00036"
"22.36800","1.86412","0.00024"
"22.39200","1.86609","0.00074"
"22.41600","1.86806","0.00135"
"22.44000","1.87010","0.00060"
"22.46400","1.87213","0.00025"
"22.48800","1.87410","0.00080"
"22.51200","1.87614","0.00050"
"22.53600","1.87811","0.00024"
"22.56000","1.88008","0.00018"
"22.58400","1.88211","0.00030"
"22.60800","1.88415","0.00056"
"22.63200","1.88618","0.00060"
"22.65600","1.88815","0.00069"
"22.68000","1.89019","-0.00015"
"22.70400","1.89216","0.00000"
"22.72800","1.89419","0.00050"
"22.75200","1.89623","0.00064"
"22.77600","1.89820","0.00009"
"22.80000","1.90017","0.00003"
"22.82400","1.90214","0.00024"
"22.84800","1.90412","0.00028"
"22.87200","1.90609","-0.00006"
"22.89600","1.90812","-0.00018"
"22.92000","1.91016","-0.00010"
"22.94400","1.91207","0.00044"
"22.96800","1.91404","0.00010"
"22.99200","1.91608","-0.00007"
"23.01600","1.91811","0.00016"
"23.04000","1.92014","0.00064"
"23.06400","1.92217","0.00037"
"23.08800","1.92415","0.00019"
"23.11200","1.92618","0.00006"
"23.13600","1.92815","-0.00006"
"23.16000","1.93019","0.00036"
"23.18400","1.93222","0.00026"
"23.20800","1.93419","0.00057"
"23.23200","1.93616","0.00047"
"23.25600","1.93820","0.00042"
"23.28000","1.94017","0.00079"
"23.30400","1.94214","0.00039"
"23.32800","1.94418","0.00043"
"23.35200","1.94615","0.00050"
"23.37600","1.94818","0.00011"
"23.40000","1.95016","0.00055"
"23.42400","1.95213","0.00077"
"23.44800","1.95410","0.00006"
"23.47200","1.95613","0.00027"
"23.49600","1.95811","0.00037"
"23.52000","1.96008","0.00026"
"23.54400","1.96211","0.00053"
"23.56800","1.96415","0.00014"
"23.59200","1.96612","0.00050"
"23.61600","1.96815","0.00065"
"23.64000","1.97012","0.00043"
"23.66400","1.97210","0.00011"
"23.68800","1.97413","0.00042"
"23.71200","1.97616","0.00075"
"23.73600","1.97814","0.00066"
"23.76000","1.98017","0.00038"
"23.78400","1.98214","-0.00004"
"23.80800","1.98418","0.00000"
"23.83200","1.98621","0.00005"
"23.85600","1.98818","0.00020"
"23.88000","1.99015","0.00051"
"23.90400","1.99213","0.00067"
"23.92800","1.99410","0.00071"
"23.95200","1.99613","0.00018"
"23.97600","1.99811","0.00047"
"24.00000","2.00014","0.00022"
"24.02400","2.00211","0.00019"
"24.04800","2.00409","0.00033"
"24.07200","2.00612","0.00039"
"24.09600","2.00815","0.00066"
"24.12000","2.01012","-0.00012"
"24.14400","2.01216","-0.00018"
"24.16800","2.01413","-0.00029"
"24.19200","2.01610","0.00019"
"24.21600","2.01814","0.00041"
"24.24000","2.02017","0.00055"
"24.26400","2.02214","0.00057"
"24.28800","2.02417","0.00048"
"24.31200","2.02615","0.00079"
"24.33600","2.02818","0.00064"
"24.36000","2.03015","0.00027"
"24.38400","2.03219","0.00032"
"24.40800","2.03416","0.00044"
"24.43200","2.03613","0.00073"
"24.45600","2.03817","0.00080"
"24.48000","2.04014","0.00066"
"24.50400","2.04211","0.00052"
"24.52800","2.04414","0.00042"
"24.55200","2.04612","-0.00019"
"24.57600","2.04809","0.00000"
"24.60000","2.05006","0.00074"
"24.62400","2.05216","0.00091"
"24.64800","2.05419","0.00082"
"24.67200","2.05616","0.00081"
"24.69600","2.05814","0.00092"
"24.72000","2.06017","0.00065"
"24.74400","2.06214","0.00040"
"24.76800","2.06423","0.00031"
"24.79200","2.06621","0.00037"
"24.81600","2.06812","0.00001"
"24.84000","2.07009","0.00014"
"24.86400","2.07213","0.00006"
"24.88800","2.07416","0.00026"
"24.91200","2.07619","0.00019"
"24.93600","2.07822","0.00026"
"24.96000","2.08020","-0.00003"
"24.98400","2.08217","0.00016"
"25.00800","2.08414","0.00040"
"25.03200","2.08612","0.00043"
"25.05600","2.08815","0.00003"
"25.08000","2.09012","-0.00032"
"25.10400","2.09210","0.00023"
"25.12800","2.09407","0.00054"
"25.15200","2.09604","0.00030"
"25.17600","2.09807","0.00039"
"25.20000","2.10017","0.00042"
"25.22400","2.10214","0.00061"
"25.24800","2.10417","0.00048"
"25.27200","2.10615","0.00024"
"25.29600","2.10812","0.00012"
"25.32000","2.11015","0.00065"
"25.34400","2.11219","0.00037"
"25.36800","2.11416","0.00033"
"25.39200","2.11613","0.00022"
"25.41600","2.11810","0.00033"
"25.44000","2.12014","0.00048"
"25.46400","2.12217","0.00043"
"25.48800","2.12420","0.00029"
"25.51200","2.12618","-0.00013"
"25.53600","2.12815","0.00002"
"25.56000","2.13012","0.00001"
"25.58400","2.13209","0.00032"
"25.60800","2.13413","0.00051"
"25.63200","2.13616","0.00007"
"25.65600","2.13813","0.00012"
"25.68000","2.14011","0.00049"
"25.70400","2.14208","0.00017"
"25.72800","2.14405","0.00050"
"25.75200","2.14609","0.00054"
"25.77600","2.14812","-0.00023"
"25.80000","2.15015","0.00004"
"25.82400","2.15212","0.00043"
"25.84800","2.15416","0.00058"
"25.87200","2.15613","0.00004"
"25.89600","2.15810","-0.00007"
"25.92000","2.16020","0.00018"
"25.94400","2.16217","-0.00024"
"25.96800","2.16414","-0.00029"
"25.99200","2.16612","0.00067"
"26.01600","2.16809","0.00045"
"26.04000","2.17012","0.00006"
"26.06400","2.17215","-0.00016"
"26.08800","2.17413","0.00006"
"26.11200","2.17610","0.00038"
"26.13600","2.17807","0.00030"
"26.16000","2.18011","0.00032"
"26.18400","2.18208","0.00004"
"26.20800","2.18411","-0.00010"
"26.23200","2.18614","-0.00029"
"26.25600","2.18812","0.00016"
"26.28000","2.19015","0.00020"
"26.30400","2.19212","0.00006"
"26.32800","2.19416","-0.00036"
"26.35200","2.19619","-0.00016"
"26.37600","2.19822","0.00028"
"26.40000","2.20020","0.00102"
"26.42400","2.20211","0.00043"
"26.44800","2.20414","0.00027"
"26.47200","2.20611","0.00056"
"26.49600","2.20815","0.00015"
"26.52000","2.21018","0.00015"
"26.54400","2.21215","0.00032"
"26.56800","2.21413","-0.00013"
"26.59200","2.21610","-0.00022"
"26.61600","2.21813","0.00010"
"26.64000","2.22010","0.00056"
"26.66400","2.22214","0.00036"
"26.68800","2.22411","0.00047"
"26.71200","2.22608","0.00045"
"26.73600","2.22806","0.00017"
"26.76000","2.23009","0.00050"
"26.78400","2.23218","0.00021"
"26.80800","2.23416","0.00027"
"26.83200","2.23613","0.00030"
"26.85600","2.23816","0.00000"
"26.88000","2.24013","0.00009"
"26.90400","2.24217","0.00067"
"26.92800","2.24420","0.00108"
"26.95200","2.24617","0.00048"
"26.97600","2.24815","0.00086"
"27.00000","2.25012","0.00065"
"27.02400","2.25215","0.00024"
"27.04800","2.25413","0.00003"
"27.07200","2.25616","0.00020"
"27.09600","2.25813","0.00061"
"27.12000","2.26010","0.00066"
"27.14400","2.26208","0.00030"
"27.16800","2.26411","0.00027"
"27.19200","2.26608","0.00065"
"27.21600","2.26812","0.00045"
"27.24000","2.27015","0.00033"
"27.26400","2.27212","0.00023"
"27.28800","2.27409","0.00042"
"27.31200","2.27607","0.00066"
"27.33600","2.27810","-0.00004"
"27.36000","2.28013","-0.00029"
"27.38400","2.28211","-0.00003"
"27.40800","2.28414","0.00055"
"27.43200","2.28617","0.00054"
"27.45600","2.28815","0.00049"
"27.48000","2.29018","0.00037"
"27.50400","2.29215","0.00075"
"27.52800","2.29412","0.00057"
"27.55200","2.29616","0.00029"
"27.57600","2.29819","0.00005"
"27.60000","2.30016","0.00022"
"27.62400","2.30220","0.00059"
"27.64800","2.30417","0.00044"
"27.67200","2.30614","-0.00055"
"27.69600","2.30818","0.00005"
"27.72000","2.31015","0.00044"
"27.74400","2.31212","0.00012"
"27.76800","2.31409","0.00043"
"27.79200","2.31607","0.00039"
"27.81600","2.31810","0.00020"
"27.84000","2.32013","0.00008"
"27.86400","2.32217","0.00014"
"27.88800","2.32414","0.00018"
"27.91200","2.32617","0.00042"
"27.93600","2.32814","0.00039"
"27.96000","2.33018","0.00033"
"27.98400","2.33221","-0.00015"
"28.00800","2.33418","-0.00009"
"28.03200","2.33616","-0.00045"
"28.05600","2.33819","-0.00027"
"28.08000","2.34016","-0.00004"
"28.10400","2.34214","0.00051"
"28.12800","2.34417","0.00047"
"28.15200","2.34614","0.00042"
"28.17600","2.34811","-0.00015"
"28.20000","2.35015","-0.00002"
"28.22400","2.35212","0.00026"
"28.24800","2.35409","0.00010"
"28.27200","2.35613","0.00009"
"28.29600","2.35810","-0.00009"
"28.32000","2.36007","0.00017"
"28.34400","2.36211","0.00033"
"28.36800","2.36408","0.00043"
"28.39200","2.36611","0.00060"
"28.41600","2.36814","0.00041"
"28.44000","2.37012","-0.00007"
"28.46400","2.37215","-0.00009"
"28.48800","2.37418","-0.00026"
"28.51200","2.37622","0.00004"
"28.53600","2.37819","0.00064"
"28.56000","2.38016","0.00070"
"28.58400","2.38213","0.00041"
"28.60800","2.38411","-0.00043"
"28.63200","2.38620","0.00037"
"28.65600","2.38817","0.00027"
"28.68000","2.39015","0.00047"
"28.70400","2.39218","0.00038"
"28.72800","2.39409","0.00015"
"28.75200","2.39613","0.00041"
"28.77600","2.39816","0.00031"
"28.80000","2.40013","0.00011"
"28.82400","2.40210","0.00010"
"28.84800","2.40408","0.00016"
"28.87200","2.40605","0.00020"
"28.89600","2.40802","0.00070"
"28.92000","2.41012","0.00029"
"28.94400","2.41215","0.00020"
"28.96800","2.41418","0.00042"
"28.99200","2.41615","0.00037"
"29.01600","2.41813","0.00033"
"29.04000","2.42016","0.00021"
"29.06400","2.42219","0.00031"
"29.08800","2.42423","0.00060"
"29.11200","2.42620","0.00034"
"29.13600","2.42817","0.00022"
"29.16000","2.43015","-0.00027"
"29.18400","2.43218","0.00033"
"29.20800","2.43421","0.00070"
"29.23200","2.43624","0.00036"
"29.25600","2.43822","-0.00011"
"29.28000","2.44019","-0.00006"
"29.30400","2.44216","0.00027"
"29.32800","2.44414","0.00030"
"29.35200","2.44611","-0.00056"
"29.37600","2.44814","-0.00002"
"29.40000","2.45012","0.00031"
"29.42400","2.45209","0.00046"
"29.44800","2.45406","0.00058"
"29.47200","2.45609","0.00026"
"29.49600","2.45819","0.00036"
"29.52000","2.46022","0.00027"
"29.54400","2.46219","0.00034"
"29.56800","2.46417","0.00011"
"29.59200","2.46620","0.00010"
"29.61600","2.46817","0.00010"
"29.64000","2.47020","-0.00007"
"29.66400","2.47224","0.00009"
"29.68800","2.47415","0.00029"
"29.71200","2.47618","0.00015"
"29.73600","2.47816","0.00036"
"29.76000","2.48019","0.00026"
"29.78400","2.48222","0.00045"
"29.80800","2.48426","0.00030"
"29.83200","2.48623","0.00047"
"29.85600","2.48814","0.00011"
"29.88000","2.49011","0.00024"
"29.90400","2.49215","0.00008"
"29.92800","2.49412","0.00026"
"29.95200","2.49609","0.00022"
"29.97600","2.49807","0.00009"
"30.00000","2.50004","-0.00001"
"30.02400","2.50207","0.00033"
"30.04800","2.50416","0.00067"
"30.07200","2.50620","0.00055"
"30.09600","2.50817","0.00027"
"30.12000","2.51020","0.00034"
"30.14400","2.51218","0.00076"
"30.16800","2.51415","0.00076"
"30.19200","2.51618","0.00057"
"30.21600","2.51822","0.00013"
"30.24000","2.52019","0.00029"
"30.26400","2.52216","0.00067"
"30.28800","2.52413","0.00040"
"30.31200","2.52611","0.00033"
"30.33600","2.52814","0.00058"
"30.36000","2.53017","0.00056"
"30.38400","2.53221","0.00035"
"30.40800","2.53412","0.00009"
"30.43200","2.53609","0.00035"
"30.45600","2.53813","0.00043"
"30.48000","2.54010","0.00054"
"30.50400","2.54207","0.00040"
"30.52800","2.54410","0.00029"
"30.55200","2.54614","0.00055"
"30.57600","2.54811","0.00046"
"30.60000","2.55008","0.00053"
"30.62400","2.55206","0.00013"
"30.64800","2.55415","0.00033"
"30.67200","2.55618","-0.00008"
"30.69600","2.55815","-0.00028"
"30.72000","2.56013","-0.00019"
"30.74400","2.56216","0.00065"
"30.76800","2.56413","0.00028"
"30.79200","2.56617","0.00047"
"30.81600","2.56820","0.00041"
"30.84000","2.57017","0.00047"
"30.86400","2.57215","0.00030"
"30.88800","2.57412","0.00080"
"30.91200","2.57609","0.00028"
"30.93600","2.57812","0.00038"
"30.96000","2.58010","0.00082"
"30.98400","2.58207","0.00055"
"31.00800","2.58410","0.00006"
"31.03200","2.58608","-0.00002"
"31.05600","2.58811","0.00064"
"31.08000","2.59014","0.00034"
"31.10400","2.59218","0.00036"
"31.12800","2.59415","0.00014"
"31.15200","2.59612","0.00061"
"31.17600","2.59815","0.00058"
"31.20000","2.60013","0.00058"
"31.22400","2.60216","0.00012"
"31.24800","2.60413","0.00000"
"31.27200","2.60617","-0.00001"
"31.29600","2.60820","0.00018"
"31.32000","2.61023","-0.00003"
"31.34400","2.61220","-0.00032"
"31.36800","2.61418","0.00008"
"31.39200","2.61615","0.00015"
"31.41600","2.61818","0.00022"
"31.44000","2.62016","0.00024"
"31.46400","2.62219","-0.00029"
"31.48800","2.62416","0.00011"
"31.51200","2.62614","0.00024"
"31.53600","2.62811","0.00003"
"31.56000","2.63014","0.00029"
"31.58400","2.63211","0.00051"
"31.60800","2.63415","0.00033"
"31.63200","2.63612","0.00055"
"31.65600","2.63815","0.00042"
"31.68000","2.64013","0.00003"
"31.70400","2.64216","0.00025"
"31.72800","2.64419","0.00037"
"31.75200","2.64616","0.00028"
"31.77600","2.64820","0.00050"
"31.80000","2.65017","0.00030"
"31.82400","2.65214","-0.00012"
"31.84800","2.65418","-0.00058"
"31.87200","2.65621","-0.00050"
"31.89600","2.65824","0.00018"
"31.92000","2.66022","0.00085"
"31.94400","2.66219","0.00033"
"31.96800","2.66416","-0.00014"
"31.99200","2.66613","0.00013"
"32.01600","2.66811","0.00009"
"32.04000","2.67008","-0.00016"
"32.06400","2.67211","-0.00014"
"32.08800","2.67409","0.00000"
"32.11200","2.67606","0.00022"
"32.13600","2.67809","0.00070"
"32.16000","2.68007","0.00097"
"32.18400","2.68210","0.00065"
"32.20800","2.68407","0.00089"
"32.23200","2.68610","0.00032"
"32.25600","2.68814","-0.00033"
"32.28000","2.69017","-0.00029"
"32.30400","2.69214","-0.00021"
"32.32800","2.69412","-0.00035"
"32.35200","2.69615","-0.00005"
"32.37600","2.69818","0.00043"
"32.40000","2.70021","0.00024"
"32.42400","2.70219","0.00043"
"32.44800","2.70416","-0.00003"
"32.47200","2.70613","0.00017"
"32.49600","2.70811","0.00041"
"32.52000","2.71014","0.00072"
"32.54400","2.71217","-0.00040"
"32.56800","2.71409","-0.00041"
"32.59200","2.71606","0.00029"
"32.61600","2.71809","0.00024"
"32.64000","2.72007","0.00038"
"32.66400","2.72210","0.00002"
"32.68800","2.72413","0.00011"
"32.71200","2.72616","0.00041"
"32.73600","2.72814","0.00061"
"32.76000","2.73017","0.00043"
"32.78400","2.73214","0.00038"
"32.80800","2.73424","0.00074"
"32.83200","2.73621","0.00009"
"32.85600","2.73818","0.00010"
"32.88000","2.74015","0.00002"
"32.90400","2.74213","0.00021"
"32.92800","2.74416","0.00031"
"32.95200","2.74619","0.00031"
"32.97600","2.74817","0.00073"
"33.00000","2.75020","0.00075"
"33.02400","2.75217","0.00026"
"33.04800","2.75414","0.00006"
"33.07200","2.75618","0.00030"
"33.09600","2.75815","0.00028"
"33.12000","2.76012","-0.00007"
"33.14400","2.76216","-0.00014"
"33.16800","2.76413","0.00002"
"33.19200","2.76610","0.00009"
"33.21600","2.76808","-0.00041"
"33.24000","2.77017","-0.00027"
"33.26400","2.77214","-0.00007"
"33.28800","2.77411","0.00012"
"33.31200","2.77615","-0.00022"
"33.33600","2.77812","-0.00011"
"33.36000","2.78015","0.00017"
"33.38400","2.78219","-0.00013"
"33.40800","2.78416","0.00032"
"33.43200","2.78613","0.00006"
"33.45600","2.78811","0.00036"
"33.48000","2.79008","-0.00024"
"33.50400","2.79211","-0.00003"
"33.52800","2.79414","0.00037"
"33.55200","2.79618","0.00034"
"33.57600","2.79815","0.00040"
"33.60000","2.80012","0.00047"
"33.62400","2.80210","0.00058"
"33.64800","2.80413","0.00059"
"33.67200","2.80616","0.00037"
"33.69600","2.80814","0.00035"
"33.72000","2.81011","-0.00015"
"33.74400","2.81208","-0.00046"
"33.76800","2.81405","-0.00024"
"33.79200","2.81609","0.00035"
"33.81600","2.81812","0.00003"
"33.84000","2.82015","0.00019"
"33.86400","2.82213","-0.00015"
"33.88800","2.82416","-0.00005"
"33.91200","2.82613","0.00028"
"33.93600","2.82816","0.00064"
"33.96000","2.83020","0.00022"
"33.98400","2.83217","-0.00006"
"34.00800","2.83414","-0.00029"
"34.03200","2.83612","0.00018"
"34.05600","2.83815","0.00019"
"34.08000","2.84012","0.00040"
"34.10400","2.84216","0.00019"
"34.12800","2.84413","0.00020"
"34.15200","2.84610","0.00021"
"34.17600","2.84813","-0.00001"
"34.20000","2.85011","-0.00022"
"34.22400","2.85214","0.00005"
"34.24800","2.85411","0.00015"
"34.27200","2.85615","0.00058"
"34.29600","2.85812","0.00036"
"34.32000","2.86009","0.00003"
"34.34400","2.86212","0.00000"
"34.36800","2.86416","-0.00008"
"34.39200","2.86619","0.00050"
"34.41600","2.86816","0.00042"
"34.44000","2.87014","-0.00023"
"34.46400","2.87217","0.00026"
"34.48800","2.87414","0.00075"
"34.51200","2.87612","0.00020"
"34.53600","2.87821","0.00012"
"34.56000","2.88018","-0.00026"
"34.58400","2.88215","0.00003"
"34.60800","2.88419","-0.00010"
"34.63200","2.88616","-0.00007"
"34.65600","2.88819","0.00018"
"34.68000","2.89017","0.00017"
"34.70400","2.89214","0.00023"
"34.72800","2.89411","-0.00016"
"34.75200","2.89615","-0.00011"
"34.77600","2.89812","-0.00028"
"34.80000","2.90015","0.00011"
"34.82400","2.90212","0.00036"
"34.84800","2.90416","-0.00002"
"34.87200","2.90613","-0.00016"
"34.89600","2.90816","0.00027"
"34.92000","2.91014","0.00030"
"34.94400","2.91217","0.00013"
"34.96800","2.91420","-0.00022"
"34.99200","2.91617","-0.00001"
"35.01600","2.91821","0.00029"
"35.04000","2.92012","0.00021"
"35.06400","2.92215","-0.00024"
"35.08800","2.92419","0.00031"
"35.11200","2.92616","0.00001"
"35.13600","2.92813","0.00005"
"35.16000","2.93017","0.00031"
"35.18400","2.93214","0.00022"
"35.20800","2.93411","0.00018"
"35.23200","2.93614","0.00046"
"35.25600","2.93812","0.00047"
"35.28000","2.94015","0.00050"
"35.30400","2.94212","0.00045"
"35.32800","2.94410","0.00045"
"35.35200","2.94607","0.00070"
"35.37600","2.94810","0.00035"
"35.40000","2.95014","0.00023"
"35.42400","2.95211","0.00009"
"35.44800","2.95414","0.00078"
"35.47200","2.95617","0.00023"
"35.49600","2.95815","0.00038"
"35.52000","2.96018","0.00035"
"35.54400","2.96215","0.00020"
"35.56800","2.96413","-0.00031"
"35.59200","2.96616","-0.00031"
"35.61000","2.96765","-0.00026"