File: Force_trajectories/170226_3/Specimen_RawData_4.csv
End date,"2/26/2017"
Specimen label,"7CG_56"
Maximum Load,"0.48809",N

Time,Extension,Load
(s),(mm),(N)
"0.00000","0.00000","-0.00069"
"0.40200","0.03378","0.00028"
"0.80400","0.06720","0.00131"
"1.20600","0.10069","0.00161"
"1.60800","0.13423","0.00173"
"2.01000","0.16777","0.00187"
"2.41200","0.20125","0.00180"
"2.81400","0.23467","0.00289"
"3.21600","0.26822","0.00303"
"3.61800","0.30170","0.00265"
"4.02000","0.33530","0.00331"
"4.42200","0.36872","0.00334"
"4.82400","0.40214","0.00349"
"5.22600","0.43575","0.00398"
"5.62800","0.46923","0.00397"
"6.03000","0.50265","0.00425"
"6.43200","0.53625","0.00413"
"6.83400","0.56979","0.00499"
"7.23600","0.60322","0.00558"
"7.63800","0.63670","0.00580"
"8.04000","0.67024","0.00547"
"8.44200","0.70378","0.00589"
"8.84400","0.73720","0.00616"
"9.24600","0.77063","0.00679"
"9.64800","0.80423","0.00650"
"10.05000","0.83777","0.00690"
"10.45200","0.87119","0.00703"
"10.85400","0.90468","0.00729"
"11.25600","0.93822","0.00700"
"11.65800","0.97176","0.00725"
"12.06000","1.00524","0.00789"
"12.46200","1.03872","0.00749"
"12.86400","1.07221","0.00813"
"13.26600","1.10575","0.00877"
"13.66800","1.13923","0.00887"
"14.07000","1.17265","0.00853"
"14.47200","1.20625","0.00912"
"14.87400","1.23974","0.00938"
"15.27600","1.27316","0.00966"
"15.67800","1.30670","0.00946"
"16.08000","1.34024","0.01028"
"16.48200","1.37378","0.01009"
"16.88400","1.40721","0.00983"
"17.28600","1.44069","0.01113"
"17.68800","1.47423","0.01020"
"18.09000","1.50777","0.01132"
"18.49200","1.54119","0.01122"
"18.89400","1.57468","0.01031"
"19.29600","1.60822","0.01014"
"19.69800","1.64176","0.01101"
"20.10000","1.67524","0.01146"
"20.50200","1.70872","0.01182"
"20.90400","1.74227","0.01195"
"21.30600","1.77575","0.01180"
"21.70800","1.80917","0.01274"
"22.11000","1.84265","0.01281"
"22.51200","1.87626","0.01283"
"22.91400","1.90974","0.01280"
"23.31600","1.94316","0.01412"
"23.71800","1.97670","0.01439"
"24.12000","2.01024","0.01494"
"24.52200","2.04379","0.01503"
"24.92400","2.07721","0.01542"
"25.32600","2.11069","0.01458"
"25.72800","2.14423","0.01548"
"26.13000","2.17771","0.01589"
"26.53200","2.21120","0.01485"
"26.93400","2.24474","0.01481"
"27.33600","2.27822","0.01476"
"27.73800","2.31176","0.01576"
"28.14000","2.34518","0.01540"
"28.54200","2.37873","0.01577"
"28.94400","2.41221","0.01579"
"29.34600","2.44575","0.01669"
"29.74800","2.47917","0.01593"
"30.15000","2.51272","0.01619"
"30.55200","2.54626","0.01629"
"30.95400","2.57974","0.01688"
"31.35600","2.61316","0.01715"
"31.75800","2.64670","0.01770"
"32.16000","2.68025","0.01836"
"32.56200","2.71379","0.01869"
"32.96400","2.74715","0.01783"
"33.36600","2.78069","0.01744"
"33.76800","2.81423","0.01788"
"34.17000","2.84772","0.01827"
"34.57200","2.88126","0.01850"
"34.97400","2.91468","0.01893"
"35.37600","2.94822","0.01840"
"35.77800","2.98176","0.01658"
"36.18000","3.01519","0.01716"
"36.58200","3.04873","0.01778"
"36.98400","3.08221","0.01705"
"37.38600","3.11575","0.01664"
"37.78800","3.14923","0.01695"
"38.19000","3.18278","0.01516"
"38.59200","3.21626","0.00894"
"38.99400","3.24974","0.00902"
"39.39600","3.28316","0.00879"
"39.79800","3.31670","0.00998"
"40.20000","3.35031","0.01002"
"40.60200","3.38379","0.00918"
"41.00400","3.41715","0.01114"
"41.40600","3.45069","0.01052"
"41.80800","3.48423","0.01088"
"42.21000","3.51772","0.01095"
"42.61200","3.55120","0.01082"
"43.01400","3.58474","0.01020"
"43.41600","3.61822","0.01017"
"43.81800","3.65171","0.00806"
"44.22000","3.68519","0.00834"
"44.62200","3.71879","0.00970"
"45.02400","3.75221","0.00942"
"45.42600","3.78569","0.01000"
"45.82800","3.81918","0.01026"
"46.23000","3.85272","0.00981"
"46.63200","3.88626","0.01050"
"47.03400","3.91974","0.01026"
"47.43600","3.95316","0.01058"
"47.83800","3.98671","0.01123"
"48.24000","4.02025","0.01133"
"48.64200","4.05379","0.01205"
"49.04400","4.08721","0.01231"
"49.44600","4.12069","0.01180"
"49.84800","4.15424","0.00996"
"50.25000","4.18772","0.01042"
"50.65200","4.22120","0.01037"
"51.05400","4.25474","0.01070"
"51.45600","4.28823","0.01107"
"51.85800","4.32171","0.01071"
"52.26000","4.35519","0.01141"
"52.66200","4.38873","0.01095"
"53.06400","4.42227","0.01104"
"53.46600","4.45570","0.01133"
"53.86800","4.48918","0.01233"
"54.27000","4.52272","0.01176"
"54.67200","4.55620","0.01220"
"55.07400","4.58968","0.01186"
"55.47600","4.62317","0.01304"
"55.87800","4.65677","0.01238"
"56.28000","4.69025","0.01204"
"56.68200","4.72373","0.01324"
"57.08400","4.75721","0.01337"
"57.48600","4.79076","0.01269"
"57.88800","4.82424","0.01370"
"58.29000","4.85772","0.01285"
"58.69200","4.89120","0.01375"
"59.09400","4.92474","0.01390"
"59.49600","4.95823","0.01436"
"59.89800","4.99171","0.01456"
"60.30000","5.02519","0.01423"
"60.70200","5.05873","0.01448"
"61.10400","5.09227","0.01479"
"61.50600","5.12564","0.01542"
"61.90800","5.15924","0.01524"
"62.31000","5.19272","0.01563"
"62.71200","5.22626","0.01469"
"63.11400","5.25974","0.01515"
"63.51600","5.29317","0.01493"
"63.91800","5.32677","0.01624"
"64.32000","5.36025","0.01626"
"64.72200","5.39373","0.01582"
"65.12400","5.42722","0.01596"
"65.52600","5.46076","0.01660"
"65.92800","5.49424","0.01599"
"66.33000","5.52766","0.01606"
"66.73200","5.56120","0.01721"
"67.13400","5.59475","0.01718"
"67.53600","5.62817","0.01730"
"67.93800","5.66165","0.01734"
"68.34000","5.69525","0.01776"
"68.74200","5.72879","0.01702"
"69.14400","5.76228","0.01759"
"69.54600","5.79564","0.01776"
"69.94800","5.82918","0.01812"
"70.35000","5.86272","0.01847"
"70.75200","5.89620","0.01865"
"71.15400","5.92969","0.01848"
"71.55600","5.96323","0.01865"
"71.95800","5.99677","0.01827"
"72.36000","6.03019","0.01835"
"72.76200","6.06368","0.01793"
"73.16400","6.09722","0.01833"
"73.56600","6.13076","0.01824"
"73.96800","6.16424","0.01902"
"74.37000","6.19766","0.01924"
"74.77200","6.23127","0.01904"
"75.17400","6.26475","0.01923"
"75.57600","6.29823","0.01944"
"75.97800","6.33165","0.01967"
"76.38000","6.36519","0.01923"
"76.78200","6.39880","0.01935"
"77.18400","6.43222","0.01937"
"77.58600","6.46570","0.01986"
"77.98800","6.49924","0.01980"
"78.39000","6.53272","0.02068"
"78.79200","6.56621","0.02021"
"79.19400","6.59969","0.01992"
"79.59600","6.63323","0.02047"
"79.99800","6.66671","0.02064"
"80.40000","6.70019","0.01994"
"80.80200","6.73374","0.02115"
"81.20400","6.76728","0.02079"
"81.60600","6.80070","0.02141"
"82.00800","6.83424","0.02163"
"82.41000","6.86767","0.02172"
"82.81200","6.90121","0.02199"
"83.21400","6.93475","0.02255"
"83.61600","6.96823","0.02269"
"84.01800","7.00171","0.02257"
"84.42000","7.03525","0.02242"
"84.82200","7.06874","0.02258"
"85.22400","7.10222","0.02253"
"85.62600","7.13564","0.02336"
"86.02800","7.16924","0.02280"
"86.43000","7.20273","0.02347"
"86.83200","7.23621","0.02388"
"87.23400","7.26975","0.02329"
"87.63600","7.30323","0.02340"
"88.03800","7.33671","0.02342"
"88.44000","7.37020","0.02375"
"88.84200","7.40374","0.02353"
"89.24400","7.43728","0.02341"
"89.64600","7.47070","0.02330"
"90.04800","7.50418","0.02426"
"90.45000","7.53773","0.02385"
"90.85200","7.57121","0.02443"
"91.25400","7.60475","0.02472"
"91.65600","7.63817","0.02454"
"92.05800","7.67171","0.02555"
"92.46000","7.70526","0.02517"
"92.86200","7.73874","0.02514"
"93.26400","7.77222","0.02607"
"93.66600","7.80570","0.02610"
"94.06800","7.83924","0.02602"
"94.47000","7.87273","0.02582"
"94.87200","7.90621","0.02644"
"95.27400","7.93975","0.02585"
"95.67600","7.97323","0.02596"
"96.07800","8.00671","0.02491"
"96.48000","8.04020","0.02436"
"96.88200","8.07374","0.02471"
"97.28400","8.10728","0.02474"
"97.68600","8.14076","0.02511"
"98.08800","8.17419","0.02493"
"98.49000","8.20773","0.02568"
"98.89200","8.24127","0.02509"
"99.29400","8.27481","0.02570"
"99.69600","8.30817","0.02606"
"100.09800","8.34172","0.02567"
"100.50000","8.37526","0.02605"
"100.90200","8.40880","0.02538"
"101.30400","8.44222","0.02552"
"101.70600","8.47570","0.02575"
"102.10800","8.50925","0.02643"
"102.51000","8.54273","0.02679"
"102.91200","8.57621","0.02622"
"103.31400","8.60975","0.02643"
"103.71600","8.64323","0.02637"
"104.11800","8.67672","0.02703"
"104.52000","8.71020","0.02753"
"104.92200","8.74374","0.02748"
"105.32400","8.77728","0.02779"
"105.72600","8.81077","0.02759"
"106.12800","8.84419","0.02826"
"106.53000","8.87767","0.02811"
"106.93200","8.91127","0.02888"
"107.33400","8.94475","0.02843"
"107.73600","8.97818","0.02864"
"108.13800","9.01172","0.02850"
"108.54000","9.04520","0.02883"
"108.94200","9.07874","0.02938"
"109.34400","9.11216","0.02942"
"109.74600","9.14571","0.02866"
"110.14800","9.17925","0.02895"
"110.55000","9.21273","0.02944"
"110.95200","9.24621","0.02987"
"111.35400","9.27969","0.02960"
"111.75600","9.31324","0.03015"
"112.15800","9.34672","0.03086"
"112.56000","9.38014","0.03097"
"112.96200","9.41374","0.03152"
"113.36400","9.44722","0.03086"
"113.76600","9.48071","0.03164"
"114.16800","9.51419","0.03144"
"114.57000","9.54767","0.03197"
"114.97200","9.58121","0.03101"
"115.37400","9.61469","0.03167"
"115.77600","9.64818","0.03170"
"116.17800","9.68172","0.03175"
"116.58000","9.71520","0.03276"
"116.98200","9.74874","0.03303"
"117.38400","9.78223","0.03318"
"117.78600","9.81577","0.03359"
"118.18800","9.84919","0.03349"
"118.59000","9.88267","0.03411"
"118.99200","9.91621","0.03465"
"119.39400","9.94976","0.03451"
"119.79600","9.98324","0.03455"
"120.19800","10.01666","0.03515"
"120.60000","10.05020","0.03514"
"121.00200","10.08374","0.03577"
"121.40400","10.11728","0.03652"
"121.80600","10.15071","0.03688"
"122.20800","10.18419","0.03665"
"122.61000","10.21773","0.03731"
"123.01200","10.25127","0.03793"
"123.41400","10.28476","0.03870"
"123.81600","10.31824","0.03890"
"124.21800","10.35172","0.04021"
"124.62000","10.38520","0.03968"
"125.02200","10.41874","0.03992"
"125.42400","10.45223","0.04007"
"125.82600","10.48577","0.04016"
"126.22800","10.51919","0.04078"
"126.63000","10.55267","0.04136"
"127.03200","10.58621","0.04157"
"127.43400","10.61976","0.04206"
"127.83600","10.65324","0.04249"
"128.23800","10.68666","0.04324"
"128.64000","10.72020","0.04272"
"129.04200","10.75375","0.04347"
"129.44400","10.78729","0.04375"
"129.84600","10.82071","0.04429"
"130.24800","10.85419","0.04468"
"130.65000","10.88773","0.04490"
"131.05200","10.92128","0.04519"
"131.45400","10.95470","0.04554"
"131.85600","10.98818","0.04614"
"132.25800","11.02172","0.04627"
"132.66000","11.05526","0.04648"
"133.06200","11.08869","0.04699"
"133.46400","11.12223","0.04718"
"133.86600","11.15577","0.04789"
"134.26800","11.18925","0.04818"
"134.67000","11.22268","0.04881"
"135.07200","11.25622","0.04902"
"135.47400","11.28976","0.04913"
"135.87600","11.32318","0.04993"
"136.27800","11.35666","0.05008"
"136.68000","11.39021","0.05083"
"137.08200","11.42375","0.05099"
"137.48400","11.45729","0.05134"
"137.88600","11.49071","0.05191"
"138.28800","11.52425","0.05248"
"138.69000","11.55774","0.05265"
"139.09200","11.59122","0.05351"
"139.49400","11.62470","0.05389"
"139.89600","11.65824","0.05493"
"140.29800","11.69172","0.05490"
"140.70000","11.72521","0.05515"
"141.10200","11.75869","0.05567"
"141.50400","11.79223","0.05612"
"141.90600","11.82577","0.05706"
"142.30800","11.85925","0.05743"
"142.71000","11.89262","0.05871"
"143.11200","11.92622","0.05730"
"143.51400","11.95970","0.05872"
"143.91600","11.99324","0.05926"
"144.31800","12.02666","0.06044"
"144.72000","12.06021","0.06095"
"145.12200","12.09375","0.06146"
"145.52400","12.12723","0.06228"
"145.92600","12.16071","0.06327"
"146.32800","12.19420","0.06392"
"146.73000","12.22768","0.06513"
"147.13200","12.26122","0.06615"
"147.53400","12.29470","0.06652"
"147.93600","12.32824","0.06788"
"148.33800","12.36172","0.06903"
"148.74000","12.39521","0.06966"
"149.14200","12.42869","0.07037"
"149.54400","12.46217","0.07167"
"149.94600","12.49577","0.07234"
"150.34800","12.52925","0.07405"
"150.75000","12.56268","0.07461"
"151.15200","12.59622","0.07556"
"151.55400","12.62970","0.07597"
"151.95600","12.66324","0.06154"
"152.35800","12.69667","0.06192"
"152.76000","12.73027","0.06260"
"153.16200","12.76375","0.06328"
"153.56400","12.79723","0.06473"
"153.96600","12.83071","0.06520"
"154.36800","12.86426","0.06682"
"154.77000","12.89774","0.06874"
"155.17200","12.93122","0.06969"
"155.57400","12.96470","0.07052"
"155.97600","12.99824","0.07196"
"156.37800","13.03173","0.07250"
"156.78000","13.06521","0.07400"
"157.18200","13.09869","0.07539"
"157.58400","13.13217","0.07705"
"157.98600","13.16578","0.07884"
"158.38800","13.19920","0.07986"
"158.79000","13.23268","0.08135"
"159.19200","13.26628","0.08187"
"159.59400","13.29976","0.08259"
"159.99600","13.33325","0.08346"
"160.39800","13.36673","0.08419"
"160.80000","13.40027","0.08555"
"161.20200","13.43375","0.08586"
"161.60400","13.46723","0.08684"
"162.00600","13.50072","0.08844"
"162.40800","13.53426","0.08948"
"162.81000","13.56774","0.09016"
"163.21200","13.60122","0.09168"
"163.61400","13.63470","0.09270"
"164.01600","13.66825","0.09369"
"164.41800","13.70173","0.09473"
"164.82000","13.73515","0.09592"
"165.22200","13.76869","0.09610"
"165.62400","13.80223","0.09677"
"166.02600","13.83578","0.09890"
"166.42800","13.86920","0.09901"
"166.83000","13.90268","0.10017"
"167.23200","13.93622","0.10116"
"167.63400","13.96976","0.10213"
"168.03600","14.00319","0.10375"
"168.43800","14.03673","0.10447"
"168.84000","14.07027","0.10591"
"169.24200","14.10369","0.10754"
"169.64400","14.13717","0.10856"
"170.04600","14.17078","0.10975"
"170.44800","14.20426","0.11175"
"170.85000","14.23768","0.11361"
"171.25200","14.27116","0.11482"
"171.65400","14.30471","0.11586"
"172.05600","14.33825","0.11572"
"172.45800","14.37173","0.11682"
"172.86000","14.40515","0.11751"
"173.26200","14.43876","0.11937"
"173.66400","14.47224","0.12132"
"174.06600","14.50572","0.12275"
"174.46800","14.53920","0.12457"
"174.87000","14.57268","0.12568"
"175.27200","14.60623","0.12686"
"175.67400","14.63971","0.12315"
"176.07600","14.67319","0.12474"
"176.47800","14.70673","0.12618"
"176.88000","14.74021","0.12717"
"177.28200","14.77376","0.12872"
"177.68400","14.80718","0.13010"
"178.08600","14.84078","0.13089"
"178.48800","14.87426","0.13148"
"178.89000","14.90768","0.13240"
"179.29200","14.94117","0.13376"
"179.69400","14.97471","0.13426"
"180.09600","15.00819","0.13514"
"180.49800","15.04173","0.13563"
"180.90000","15.07515","0.13688"
"181.30200","15.10876","0.13711"
"181.70400","15.14224","0.13761"
"182.10600","15.17572","0.13842"
"182.50800","15.20920","0.13899"
"182.91000","15.24274","0.14031"
"183.31200","15.27623","0.14075"
"183.71400","15.30971","0.14134"
"184.11600","15.34325","0.14208"
"184.51800","15.37679","0.14326"
"184.92000","15.41021","0.14418"
"185.32200","15.44370","0.14535"
"185.72400","15.47712","0.14739"
"186.12600","15.51078","0.14821"
"186.52800","15.54426","0.14970"
"186.93000","15.57768","0.15171"
"187.33200","15.61123","0.15330"
"187.73400","15.64477","0.15594"
"188.13600","15.67825","0.15820"
"188.53800","15.71173","0.16105"
"188.94000","15.74516","0.16177"
"189.34200","15.77876","0.16553"
"189.74400","15.81224","0.16909"
"190.14600","15.84572","0.17198"
"190.54800","15.87920","0.17602"
"190.95000","15.91275","0.17886"
"191.35200","15.94629","0.18011"
"191.75400","15.97971","0.18093"
"192.15600","16.01319","0.18369"
"192.55800","16.04673","0.18528"
"192.96000","16.08022","0.18858"
"193.36200","16.11370","0.19055"
"193.76400","16.14718","0.19282"
"194.16600","16.18078","0.19446"
"194.56800","16.21432","0.19665"
"194.97000","16.24769","0.19843"
"195.37200","16.28123","0.20037"
"195.77400","16.31477","0.20190"
"196.17600","16.34831","0.20390"
"196.57800","16.38173","0.19950"
"196.98000","16.41522","0.20125"
"197.38200","16.44876","0.20276"
"197.78400","16.48224","0.20392"
"198.18600","16.51572","0.20556"
"198.58800","16.54920","0.20789"
"198.99000","16.58275","0.20982"
"199.39200","16.61623","0.21076"
"199.79400","16.64965","0.21246"
"200.19600","16.68319","0.21486"
"200.59800","16.71667","0.21668"
"201.00000","16.75022","0.21881"
"201.40200","16.78370","0.22078"
"201.80400","16.81718","0.22236"
"202.20600","16.85078","0.22468"
"202.60800","16.88427","0.22679"
"203.01000","16.91763","0.22893"
"203.41200","16.95117","0.23074"
"203.81400","16.98477","0.23297"
"204.21600","17.01825","0.23497"
"204.61800","17.05168","0.23651"
"205.02000","17.08522","0.23883"
"205.42200","17.11876","0.24026"
"205.82400","17.15224","0.24218"
"206.22600","17.18572","0.24337"
"206.62800","17.21921","0.24465"
"207.03000","17.25275","0.24583"
"207.43200","17.28623","0.24673"
"207.83400","17.31965","0.24817"
"208.23600","17.35325","0.24875"
"208.63800","17.38674","0.25012"
"209.04000","17.42022","0.25122"
"209.44200","17.45364","0.25160"
"209.84400","17.48718","0.25356"
"210.24600","17.52072","0.25606"
"210.64800","17.55427","0.25775"
"211.05000","17.58769","0.25912"
"211.45200","17.62117","0.26213"
"211.85400","17.65477","0.26369"
"212.25600","17.68826","0.26600"
"212.65800","17.72168","0.26770"
"213.06000","17.75522","0.26994"
"213.46200","17.78870","0.27230"
"213.86400","17.82218","0.27452"
"214.26600","17.85567","0.27641"
"214.66800","17.88927","0.27918"
"215.07000","17.92275","0.28147"
"215.47200","17.95617","0.28414"
"215.87400","17.98965","0.28497"
"216.27600","18.02326","0.28820"
"216.67800","18.05680","0.29055"
"217.08000","18.09028","0.29326"
"217.48200","18.12370","0.29585"
"217.88400","18.15718","0.29889"
"218.28600","18.19073","0.30140"
"218.68800","18.22427","0.30431"
"219.09000","18.25769","0.30668"
"219.49200","18.29123","0.31066"
"219.89400","18.32477","0.31544"
"220.29600","18.35820","0.31994"
"220.69800","18.39168","0.32618"
"221.10000","18.42522","0.33095"
"221.50200","18.45876","0.33450"
"221.90400","18.49218","0.33918"
"222.30600","18.52567","0.34211"
"222.70800","18.55927","0.34503"
"223.11000","18.59275","0.34773"
"223.51200","18.62623","0.34932"
"223.91400","18.65971","0.35174"
"224.31600","18.69326","0.35258"
"224.71800","18.72680","0.35386"
"225.12000","18.76022","0.35453"
"225.52200","18.79370","0.35558"
"225.92400","18.82725","0.35645"
"226.32600","18.86073","0.35744"
"226.72800","18.89421","0.35865"
"227.13000","18.92769","0.35976"
"227.53200","18.96123","0.36135"
"227.93400","18.99478","0.36269"
"228.33600","19.02820","0.36388"
"228.73800","19.06168","0.36668"
"229.14000","19.09528","0.36911"
"229.54200","19.12876","0.37189"
"229.94400","19.16219","0.37558"
"230.34600","19.19567","0.37818"
"230.74800","19.22927","0.38174"
"231.15000","19.26275","0.38346"
"231.55200","19.29618","0.38773"
"231.95400","19.32972","0.39090"
"232.35600","19.36326","0.39519"
"232.75800","19.39674","0.39860"
"233.16000","19.43016","0.39074"
"233.56200","19.46371","0.39166"
"233.96400","19.49725","0.38575"
"234.36600","19.53079","0.38796"
"234.76800","19.56421","0.39041"
"235.17000","19.59769","0.39343"
"235.57200","19.63124","0.39632"
"235.97400","19.66472","0.39976"
"236.37600","19.69820","0.40257"
"236.77800","19.73168","0.40608"
"237.18000","19.76522","0.40912"
"237.58200","19.79871","0.41199"
"237.98400","19.83213","0.41458"
"238.38600","19.86573","0.41679"
"238.78800","19.89927","0.41934"
"239.19000","19.93275","0.42132"
"239.59200","19.96618","0.42506"
"239.99400","19.99966","0.42849"
"240.39600","20.03326","0.43089"
"240.79800","20.06674","0.43344"
"241.20000","20.10023","0.43575"
"241.60200","20.13371","0.43826"
"242.00400","20.16725","0.44032"
"242.40600","20.20073","0.23198"
"242.80800","20.23421","0.23457"
"243.21000","20.26776","0.23454"
"243.61200","20.30124","0.23575"
"244.01400","20.33472","0.23456"
"244.41600","20.36820","0.23647"
"244.81800","20.40168","0.23936"
"245.22000","20.43522","0.24209"
"245.62200","20.46877","0.24612"
"246.02400","20.50213","0.24863"
"246.42600","20.53573","0.24862"
"246.82800","20.56933","0.24854"
"247.23000","20.60275","0.24888"
"247.63200","20.63618","0.25142"
"248.03400","20.66972","0.25560"
"248.43600","20.70326","0.26010"
"248.83800","20.73668","0.26006"
"249.24000","20.77023","0.25956"
"249.64200","20.80371","0.26064"
"250.04400","20.83725","0.26356"
"250.44600","20.87073","0.26819"
"250.84800","20.90421","0.27047"
"251.25000","20.93776","0.26949"
"251.65200","20.97124","0.26944"
"252.05400","21.00472","0.27273"
"252.45600","21.03820","0.27850"
"252.85800","21.07174","0.28144"
"253.26000","21.10523","0.28032"
"253.66200","21.13877","0.28108"
"254.06400","21.17213","0.28364"
"254.46600","21.20567","0.28684"
"254.86800","21.23927","0.28863"
"255.27000","21.27276","0.28807"
"255.67200","21.30618","0.28871"
"256.07400","21.33972","0.29169"
"256.47600","21.37320","0.29407"
"256.87800","21.40668","0.29490"
"257.28000","21.44017","0.29506"
"257.68200","21.47377","0.29552"
"258.08400","21.50719","0.29949"
"258.48600","21.54067","0.30092"
"258.88800","21.57415","0.30177"
"259.29000","21.60776","0.30394"
"259.69200","21.64124","0.30892"
"260.09400","21.67472","0.31384"
"260.49600","21.70821","0.31570"
"260.89800","21.74175","0.31912"
"261.30000","21.77523","0.32407"
"261.70200","21.80865","0.33012"
"262.10400","21.84219","0.33202"
"262.50600","21.87574","0.33449"
"262.90800","21.90928","0.33863"
"263.31000","21.94270","0.34149"
"263.71200","21.97618","0.34365"
"264.11400","22.00972","0.34512"
"264.51600","22.04327","0.34765"
"264.91800","22.07669","0.34925"
"265.32000","22.11017","0.34988"
"265.72200","22.14377","0.35152"
"266.12400","22.17725","0.35317"
"266.52600","22.21068","0.35317"
"266.92800","22.24416","0.35394"
"267.33000","22.27776","0.35496"
"267.73200","22.31124","0.35600"
"268.13400","22.34466","0.35645"
"268.53600","22.37821","0.35760"
"268.93800","22.41175","0.35874"
"269.34000","22.44529","0.35956"
"269.74200","22.47871","0.36044"
"270.14400","22.51219","0.36204"
"270.54600","22.54574","0.36304"
"270.94800","22.57928","0.36425"
"271.35000","22.61270","0.36700"
"271.75200","22.64618","0.36988"
"272.15400","22.67973","0.37209"
"272.55600","22.71326","0.37516"
"272.95800","22.74669","0.37978"
"273.36000","22.78023","0.38234"
"273.76200","22.81371","0.38537"
"274.16400","22.84720","0.38856"
"274.56600","22.88062","0.39102"
"274.96800","22.91422","0.39336"
"275.37000","22.94776","0.39759"
"275.77200","22.98124","0.39928"
"276.17400","23.01467","0.40217"
"276.57600","23.04820","0.40579"
"276.97800","23.08169","0.15690"
"277.38000","23.11523","0.15638"
"277.78200","23.14871","0.16477"
"278.18400","23.18219","0.17395"
"278.58600","23.21574","0.18218"
"278.98800","23.24922","0.18708"
"279.39000","23.28270","0.19215"
"279.79200","23.31624","0.19664"
"280.19400","23.34973","0.20093"
"280.59600","23.38327","0.20388"
"280.99800","23.41669","0.20855"
"281.40000","23.45029","0.21228"
"281.80200","23.48377","0.21602"
"282.20400","23.51720","0.22182"
"282.60600","23.55062","0.22713"
"283.00800","23.58422","0.23216"
"283.41000","23.61776","0.23801"
"283.81200","23.65124","0.24231"
"284.21400","23.68467","0.24549"
"284.61600","23.71827","0.24662"
"285.01800","23.75175","0.24794"
"285.42000","23.78523","0.24886"
"285.82200","23.81871","0.25037"
"286.22400","23.85225","0.25322"
"286.62600","23.88574","0.25643"
"287.02800","23.91916","0.25980"
"287.43000","23.95270","0.26325"
"287.83200","23.98625","0.26555"
"288.23400","24.01979","0.26753"
"288.63600","24.05327","0.26917"
"289.03800","24.08663","0.27206"
"289.44000","24.12029","0.27533"
"289.84200","24.15378","0.28010"
"290.24400","24.18720","0.28342"
"290.64600","24.22068","0.28558"
"291.04800","24.25422","0.28770"
"291.45000","24.28776","0.28977"
"291.85200","24.32125","0.29360"
"292.25400","24.35467","0.29654"
"292.65600","24.38827","0.30014"
"293.05800","24.42169","0.30191"
"293.46000","24.45517","0.30534"
"293.86200","24.48872","0.30789"
"294.26400","24.52220","0.31057"
"294.66600","24.55574","0.31408"
"295.06800","24.58922","0.31803"
"295.47000","24.62271","0.32217"
"295.87200","24.65625","0.32626"
"296.27400","24.68973","0.33053"
"296.67600","24.72321","0.33521"
"297.07800","24.75669","0.33782"
"297.48000","24.79024","0.34010"
"297.88200","24.82378","0.34261"
"298.28400","24.85720","0.34476"
"298.68600","24.89068","0.34717"
"299.08800","24.92422","0.34889"
"299.49000","24.95777","0.35041"
"299.89200","24.99119","0.35185"
"300.29400","25.02467","0.35323"
"300.69600","25.05821","0.35463"
"301.09800","25.09175","0.35517"
"301.50000","25.12524","0.35632"
"301.90200","25.15872","0.35675"
"302.30400","25.19220","0.35814"
"302.70600","25.22574","0.35918"
"303.10800","25.25916","0.36004"
"303.51000","25.29271","0.36160"
"303.91200","25.32625","0.36396"
"304.31400","25.35973","0.36599"
"304.71600","25.39315","0.36754"
"305.11800","25.42669","0.37096"
"305.52000","25.46024","0.37509"
"305.92200","25.49378","0.37901"
"306.32400","25.52714","0.38180"
"306.72600","25.56074","0.38295"
"307.12800","25.59422","0.38503"
"307.53000","25.62777","0.38789"
"307.93200","25.66119","0.39142"
"308.33400","25.69467","0.39483"
"308.73600","25.72827","0.39836"
"309.13800","25.76176","0.40079"
"309.54000","25.79518","0.40403"
"309.94200","25.82878","0.40669"
"310.34400","25.86220","0.41055"
"310.74600","25.89569","0.41315"
"311.14800","25.92917","0.41536"
"311.55000","25.96271","0.41706"
"311.95200","25.99625","0.41880"
"312.35400","26.02973","0.42097"
"312.75600","26.06316","0.42420"
"313.15800","26.09670","0.42594"
"313.56000","26.13024","0.42817"
"313.96200","26.16378","0.43075"
"314.36400","26.19715","0.43282"
"314.76600","26.23075","0.43541"
"315.16800","26.26423","0.43768"
"315.57000","26.29777","0.43969"
"315.97200","26.33119","0.44181"
"316.37400","26.36473","0.44410"
"316.77600","26.39827","0.44627"
"317.17800","26.43170","0.44810"
"317.58000","26.46518","0.44974"
"317.98200","26.49878","0.45132"
"318.38400","26.53226","0.45290"
"318.78600","26.56569","0.45476"
"319.18800","26.59911","0.45701"
"319.59000","26.63271","0.46011"
"319.99200","26.66625","0.46335"
"320.39400","26.69973","0.46659"
"320.79600","26.73322","0.46919"
"321.19800","26.76670","0.47206"
"321.60000","26.80024","0.47585"
"322.00200","26.83372","0.47878"
"322.40400","26.86715","0.48222"
"322.80600","26.90069","0.48536"
"323.20800","26.93417","0.48774"
"323.61000","26.96771","0.36545"
"324.01200","27.00119","0.36090"
"324.41400","27.03480","0.36018"
"324.81600","27.06822","0.36009"
"325.21800","27.10170","0.36052"
"325.62000","27.13518","0.36170"
"326.02200","27.16872","0.36307"
"326.42400","27.20226","0.36349"
"326.82600","27.23569","0.36458"
"327.22800","27.26923","0.36705"
"327.63000","27.30277","0.36909"
"328.03200","27.33625","0.37070"
"328.43400","27.36967","0.37339"
"328.83600","27.40322","0.37776"
"329.23800","27.43676","0.38090"
"329.64000","27.47024","0.38400"
"330.04200","27.50373","0.38662"
"330.44400","27.53721","0.38946"
"330.84600","27.57069","0.39185"
"331.24800","27.60423","0.39435"
"331.65000","27.63771","0.39651"
"332.05200","27.67120","0.39935"
"332.45400","27.70474","0.40159"
"332.85600","27.73828","0.40422"
"333.25800","27.77170","0.40701"
"333.66000","27.80518","0.41015"
"334.06200","27.83879","0.41241"
"334.46400","27.87227","0.41504"
"334.86600","27.90569","0.41661"
"335.26800","27.93917","0.41879"
"335.67000","27.97277","0.42088"
"336.07200","28.00626","0.42392"
"336.47400","28.03968","0.42630"
"336.87600","28.07322","0.42793"
"337.27800","28.10676","0.43006"
"337.68000","28.14025","0.43265"
"338.08200","28.17373","0.43353"
"338.48400","28.20721","0.38628"
"338.88600","28.24075","0.39069"
"339.28800","28.27423","0.39546"
"339.69000","28.30772","0.39521"
"340.09200","28.34125","0.39650"
"340.49400","28.37474","0.40045"
"340.89600","28.40822","0.40434"
"341.29800","28.44164","0.40389"
"341.70000","28.47524","0.40663"
"342.10200","28.50872","0.40949"
"342.50400","28.54227","0.41120"
"342.90600","28.57569","0.41340"
"343.30800","28.60917","0.41598"
"343.71000","28.64277","0.41706"
"344.11200","28.67626","0.41800"
"344.51400","28.70968","0.42023"
"344.91600","28.74322","0.42304"
"345.31800","28.77676","0.42544"
"345.72000","28.81024","0.42779"
"346.12200","28.84373","0.42999"
"346.52400","28.87721","0.43187"
"346.92600","28.91069","0.43317"
"347.32800","28.94423","0.43569"
"347.73000","28.97771","0.43685"
"348.13200","29.01126","0.43804"
"348.53400","29.04474","0.43981"
"348.93600","29.07822","0.44089"
"349.33800","29.11164","0.44252"
"349.74000","29.14525","0.44453"
"350.14200","29.17873","0.44576"
"350.54400","29.21227","0.44655"
"350.94600","29.24569","0.44787"
"351.34800","29.27917","0.44915"
"351.75000","29.31272","0.45070"
"352.15200","29.34620","0.45196"
"352.55400","29.37968","0.45315"
"352.95600","29.41322","0.45459"
"353.35800","29.44671","0.45666"
"353.76000","29.48019","0.45852"
"354.16200","29.51367","0.46048"
"354.56400","29.54727","0.46309"
"354.96600","29.58069","0.46547"
"355.36800","29.61423","0.46737"
"355.77000","29.64766","0.04397"
"356.17200","29.68120","0.02606"
"356.57400","29.71474","0.03435"
"356.97600","29.74822","0.02713"
"357.37800","29.78165","0.01806"
"357.78000","29.81519","0.01178"
"358.18200","29.84873","0.01803"
"358.58400","29.88227","0.01994"
"358.98600","29.91569","0.02632"
"359.38800","29.94924","0.02527"
"359.79000","29.98278","0.03018"
"360.19200","30.01620","0.02622"
"360.59400","30.04968","0.03944"
"360.99600","30.08322","0.03595"
"361.39800","30.11671","0.04514"
"361.80000","30.15019","0.03352"
"362.20200","30.18367","0.03573"
"362.60400","30.21727","0.02954"
"363.00600","30.25075","0.03416"
"363.40800","30.28418","0.03760"
"363.81000","30.31772","0.03712"
"364.21200","30.35120","0.04162"
"364.61400","30.38474","0.03783"
"365.01600","30.41822","0.04126"
"365.41800","30.45165","0.03711"
"365.82000","30.48525","0.04127"
"366.22200","30.51879","0.04187"
"366.62400","30.55221","0.04282"
"367.02600","30.58570","0.04635"
"367.42800","30.61924","0.04493"
"367.83000","30.65278","0.04690"
"368.23200","30.68620","0.04468"
"368.63400","30.71968","0.04457"
"369.03600","30.75323","0.04613"
"369.43800","30.78677","0.04634"
"369.84000","30.82019","0.04892"
"370.24200","30.85373","0.04921"
"370.64400","30.88727","0.05003"
"371.04600","30.92076","0.05147"
"371.44800","30.95418","0.05014"
"371.85000","30.98772","0.05099"
"372.25200","31.02126","0.05133"
"372.65400","31.05480","0.05131"
"373.05600","31.08817","0.05332"
"373.45800","31.12171","0.05471"
"373.86000","31.15525","0.05506"
"374.26200","31.18873","0.05551"
"374.66400","31.22222","0.05702"
"375.06600","31.25570","0.05705"
"375.46800","31.28924","0.05837"
"375.87000","31.32272","0.05978"
"376.27200","31.35614","0.06043"
"376.67400","31.38974","0.06156"
"377.07600","31.42323","0.06366"
"377.47800","31.45671","0.06515"
"377.88000","31.49019","0.06669"
"378.28200","31.52373","0.06842"
"378.68400","31.55727","0.06955"
"379.08600","31.59076","0.07109"
"379.48800","31.62406","0.07369"
"379.89000","31.65772","0.07494"
"380.29200","31.69126","0.07637"
"380.69400","31.72474","0.07845"
"381.09600","31.75817","0.08010"
"381.49800","31.79171","0.08107"
"381.90000","31.82519","0.08292"
"382.30200","31.85873","0.08435"
"382.70400","31.89221","0.08542"
"383.10600","31.92570","0.08687"
"383.50800","31.95918","0.08794"
"383.91000","31.99272","0.08961"
"384.31200","32.02620","0.09077"
"384.71400","32.05975","0.09162"
"385.11600","32.09323","0.09233"
"385.51800","32.12671","0.09392"
"385.92000","32.16019","0.09564"
"386.32200","32.19373","0.09679"
"386.72400","32.22721","0.09716"
"387.12600","32.26070","0.09886"
"387.52800","32.29418","0.10042"
"387.93000","32.32772","0.10027"
"388.33200","32.36120","0.10140"
"388.73400","32.39474","0.10294"
"389.13600","32.42817","0.10476"
"389.53800","32.46171","0.10601"
"389.94000","32.49519","0.10737"
"390.34200","32.52874","0.10935"
"390.74400","32.56221","0.11143"
"391.14600","32.59576","0.11335"
"391.54800","32.62924","0.11554"
"391.95000","32.66272","0.11754"
"392.35200","32.69615","0.11986"
"392.75400","32.72974","0.12130"
"393.15600","32.76329","0.12320"
"393.55800","32.79671","0.12499"
"393.96000","32.83019","0.12629"
"394.36200","32.86374","0.12785"
"394.76400","32.89722","0.12962"
"395.16600","32.93076","0.13043"
"395.56800","32.96418","0.13150"
"395.97000","32.99772","0.13260"
"396.37200","33.03121","0.13342"
"396.77400","33.06469","0.13414"
"397.17600","33.09823","0.13480"
"397.57800","33.13171","0.13546"
"397.98000","33.16520","0.13627"
"398.38200","33.19874","0.13658"
"398.78400","33.23215","0.13738"
"399.18600","33.26576","0.13801"
"399.58800","33.29924","0.13868"
"399.99000","33.33266","0.13958"
"400.39200","33.36615","0.13968"
"400.79400","33.39975","0.14069"
"401.19600","33.43329","0.14151"
"401.59800","33.46671","0.14237"
"402.00000","33.50026","0.02202"
"402.40200","33.53374","0.00619"
"402.80400","33.56728","0.00520"
"403.20600","33.60070","0.01937"
"403.60800","33.63418","0.03932"
"404.01000","33.66772","0.04268"
"404.41200","33.70121","0.02809"
"404.81400","33.73469","0.01317"
"405.21600","33.76817","0.01074"
"405.61800","33.80171","0.02156"
"406.02000","33.83525","0.03591"
"406.42200","33.86868","0.04250"
"406.82400","33.90222","0.03723"
"407.22600","33.93576","0.02648"
"407.62800","33.96924","0.01917"
"408.03000","34.00267","0.02089"
"408.43200","34.03621","0.02914"
"408.83400","34.06969","0.03800"
"409.23600","34.10323","0.04039"
"409.63800","34.13665","0.03572"
"410.04000","34.17020","0.02988"
"410.44200","34.20374","0.02502"
"410.84400","34.23728","0.02676"
"411.24600","34.27070","0.03209"
"411.64800","34.30418","0.03798"
"412.05000","34.33773","0.04061"
"412.45200","34.37121","0.03915"
"412.85400","34.40469","0.03534"
"413.25600","34.43823","0.03142"
"413.65800","34.47171","0.03086"
"414.06000","34.50520","0.03379"
"414.46200","34.53868","0.03761"
"414.86400","34.57222","0.04132"
"415.26600","34.60576","0.04247"
"415.66800","34.63918","0.04127"
"416.07000","34.67266","0.03850"
"416.47200","34.70615","0.03605"
"416.87400","34.73975","0.03647"
"417.27600","34.77324","0.03833"
"417.67800","34.80666","0.04114"
"418.08000","34.84019","0.04284"
"418.48200","34.87374","0.04381"
"418.88400","34.90722","0.04322"
"419.28600","34.94070","0.04193"
"419.68800","34.97425","0.04118"
"420.09000","35.00767","0.04093"
"420.49200","35.04121","0.04171"
"420.89400","35.07469","0.04297"
"421.29600","35.10823","0.04472"
"421.69800","35.14172","0.04596"
"422.10000","35.17520","0.04609"
"422.50200","35.20868","0.04602"
"422.90400","35.24222","0.04574"
"423.30600","35.27576","0.04502"
"423.70800","35.30925","0.04529"
"424.11000","35.34267","0.04556"
"424.51200","35.37615","0.04677"
"424.91400","35.40969","0.04775"
"425.31600","35.44323","0.04799"
"425.71800","35.47672","0.04877"
"426.12000","35.51026","0.04900"
"426.52200","35.54374","0.04853"
"426.92400","35.57722","0.04863"
"427.32600","35.61071","0.04854"
"427.72800","35.64425","0.04857"
"428.13000","35.67773","0.04890"
"428.53200","35.71121","0.04986"
"428.93400","35.74469","0.04985"
"429.33600","35.77824","0.04999"
"429.73800","35.81178","0.05141"
"430.14000","35.84520","0.05135"
"430.54200","35.87868","0.05109"
"430.94400","35.91222","0.05077"
"431.34600","35.94577","0.05110"
"431.74800","35.97919","0.05114"
"432.15000","36.01267","0.05140"
"432.55200","36.04622","0.05164"
"432.95400","36.07975","0.05199"
"433.35600","36.11324","0.05207"
"433.75800","36.14672","0.05311"
"434.16000","36.18026","0.05367"
"434.56200","36.21380","0.05347"
"434.96400","36.24717","0.05421"
"435.36600","36.28071","0.05444"
"435.76800","36.31425","0.05530"
"436.17000","36.34773","0.05603"
"436.57200","36.38116","0.05578"
"436.97400","36.41475","0.05511"
"437.37600","36.44824","0.05627"
"437.77800","36.48178","0.05714"
"438.18000","36.51520","0.05787"
"438.58200","36.54869","0.05826"
"438.98400","36.58229","0.05864"
"439.38600","36.61577","0.05906"
"439.78800","36.64919","0.05808"
"440.19000","36.68267","0.05772"
"440.59200","36.71622","0.05765"
"440.99400","36.74976","0.05844"
"441.39600","36.78324","0.05887"
"441.79800","36.81672","0.05947"
"442.20000","36.85020","0.05985"
"442.60200","36.88369","0.06052"
"443.00400","36.91717","0.06125"
"443.40600","36.95071","0.06156"
"443.80800","36.98425","0.06249"
"444.21000","37.01773","0.06345"
"444.61200","37.05116","0.06321"
"445.01400","37.08476","0.06427"
"445.41600","37.11824","0.06494"
"445.81800","37.15172","0.06592"
"446.22000","37.18514","0.06591"
"446.62200","37.21869","0.06597"
"447.02400","37.25223","0.06614"
"447.42600","37.28571","0.06576"
"447.82800","37.31919","0.06601"
"448.23000","37.35267","0.06704"
"448.63200","37.38622","0.06745"
"449.03400","37.41976","0.06686"
"449.43600","37.45318","0.06809"
"449.83800","37.48672","0.06874"
"450.24000","37.52020","0.07011"
"450.64200","37.55369","0.07023"
"451.04400","37.58717","0.07074"
"451.44600","37.62071","0.07265"
"451.84800","37.65425","0.07436"
"452.25000","37.68773","0.07452"
"452.65200","37.72110","0.07436"
"453.05400","37.75470","0.07431"
"453.45600","37.78824","0.07650"
"453.85800","37.82172","0.07734"
"454.26000","37.85521","0.07834"
"454.66200","37.88875","0.08075"
"455.06400","37.92223","0.08154"
"455.46600","37.95577","0.08221"
"455.86800","37.98919","0.08356"
"456.27000","38.02274","0.08396"
"456.67200","38.05622","0.08511"
"457.07400","38.08970","0.08619"
"457.47600","38.12318","0.08671"
"457.87800","38.15678","0.08651"
"458.28000","38.19020","0.08686"
"458.68200","38.22375","0.08735"
"459.08400","38.25723","0.08863"
"459.48600","38.29071","0.09015"
"459.88800","38.32426","0.09073"
"460.29000","38.35773","0.09193"
"460.69200","38.39116","0.09276"
"461.09400","38.42470","0.09358"
"461.49600","38.45824","0.09415"
"461.89800","38.49173","0.09512"
"462.30000","38.52515","0.09647"
"462.70200","38.55875","0.09794"
"463.10400","38.59223","0.09888"
"463.50600","38.62571","0.10019"
"463.90800","38.65926","0.10059"
"464.31000","38.69273","0.10109"
"464.71200","38.72622","0.10296"
"465.11400","38.75970","0.10442"
"465.51600","38.79318","0.10547"
"465.91800","38.82679","0.10719"
"466.32000","38.86027","0.10840"
"466.72200","38.89369","0.11035"
"467.12400","38.92723","0.11255"
"467.52600","38.96071","0.11405"
"467.92800","38.99426","0.11591"
"468.33000","39.02768","0.11806"
"468.73200","39.06116","0.12073"
"469.13400","39.09476","0.12227"
"469.53600","39.12830","0.12286"
"469.93800","39.16173","0.12411"
"470.34000","39.19521","0.12426"
"470.74200","39.22874","0.12480"
"471.14400","39.26229","0.12638"
"471.54600","39.29571","0.12819"
"471.94800","39.32925","0.12872"
"472.35000","39.36280","0.12919"
"472.75200","39.39621","0.13022"
"473.15400","39.42970","0.13122"
"473.55600","39.46318","0.13235"
"473.95800","39.49672","0.13308"
"474.36000","39.53027","0.13396"
"474.76200","39.56369","0.13463"
"475.16400","39.59723","0.13517"
"475.56600","39.63078","0.13563"
"475.96800","39.66425","0.13645"
"476.37000","39.69768","0.13720"
"476.77200","39.73116","0.13788"
"477.17400","39.76470","0.13858"
"477.57600","39.79824","0.13912"
"477.97800","39.83167","0.14029"
"478.38000","39.86521","0.14091"
"478.78200","39.89875","0.14218"
"479.18400","39.93223","0.14271"
"479.58600","39.96566","0.14360"
"479.98800","39.99926","0.14478"
"480.39000","40.03274","0.14602"
"480.79200","40.06622","0.14712"
"481.19400","40.09964","0.14829"
"481.59600","40.13319","0.14949"
"481.99800","40.16673","0.15071"
"482.40000","40.20027","0.15233"
"482.80200","40.23363","0.15375"
"483.20400","40.26723","0.15505"
"483.60600","40.30072","0.15630"
"484.00800","40.33426","0.15784"
"484.41000","40.36768","0.15865"
"484.81200","40.40117","0.16226"
"485.21400","40.43471","0.16535"
"485.61600","40.46824","0.16900"
"486.01800","40.50167","0.17085"
"486.42000","40.53527","0.17332"
"486.82200","40.56870","0.17602"
"487.22400","40.60224","0.17904"
"487.62600","40.63566","0.18097"
"488.02800","40.66926","0.18356"
"488.43000","40.70274","0.18622"
"488.83200","40.73616","0.18704"
"489.23400","40.76965","0.18937"
"489.63600","40.80325","0.19109"
"490.03800","40.83673","0.19189"
"490.44000","40.87021","0.19340"
"490.84200","40.90369","0.19468"
"491.24400","40.93724","0.19597"
"491.64600","40.97071","0.19774"
"492.04800","41.00426","0.19978"
"492.45000","41.03774","0.20188"
"492.85200","41.07122","0.20382"
"493.25400","41.10471","0.20518"
"493.65600","41.13819","0.20607"
"494.05800","41.17173","0.20755"
"494.46000","41.20521","0.20857"
"494.86200","41.23875","0.20970"
"495.26400","41.27224","0.21056"
"495.66600","41.30566","0.21198"
"496.06800","41.33926","0.21437"
"496.47000","41.37274","0.21580"
"496.87200","41.40616","0.21815"
"497.27400","41.43970","0.22056"
"497.67600","41.47325","0.22164"
"498.07800","41.50679","0.22366"
"498.48000","41.54021","0.22550"
"498.88200","41.57370","0.22705"
"499.28400","41.60724","0.22840"
"499.68600","41.64072","0.22994"
"500.08800","41.67420","0.23219"
"500.49000","41.70774","0.23367"
"500.89200","41.74117","0.23425"
"501.29400","41.77470","0.23584"
"501.69600","41.80819","0.23711"
"502.09800","41.84174","0.23837"
"502.50000","41.87521","0.23985"
"502.90200","41.90876","0.24098"
"503.30400","41.94224","0.24166"
"503.70600","41.97566","0.24207"
"504.10800","42.00920","0.24329"
"504.51000","42.04274","0.24364"
"504.91200","42.07617","0.24424"
"505.31400","42.10971","0.24420"
"505.71600","42.14325","0.24479"
"506.11800","42.17673","0.24513"
"506.52000","42.21015","0.24550"
"506.92200","42.24370","0.24541"
"507.32400","42.27718","0.24552"
"507.72600","42.31072","0.24516"
"508.12800","42.34420","0.24480"
"508.53000","42.37774","0.24508"
"508.93200","42.41122","0.24509"
"509.33400","42.44471","0.24507"
"509.73600","42.47819","0.24509"
"510.13800","42.51173","0.24497"
"510.54000","42.54522","0.24489"
"510.94200","42.57869","0.24531"
"511.34400","42.61212","0.24537"
"511.74600","42.64572","0.24535"
"512.14800","42.67926","0.24589"
"512.55000","42.71280","0.24634"
"512.95200","42.74616","0.24666"
"513.35400","42.77965","0.24766"
"513.75600","42.81325","0.24809"
"514.15800","42.84679","0.24785"
"514.56000","42.88022","0.24899"
"514.96200","42.91370","0.24911"
"515.36400","42.94724","0.24995"
"515.76600","42.98072","0.24985"
"516.16800","43.01421","0.25035"
"516.57000","43.04774","0.25133"
"516.97200","43.08123","0.25144"
"517.37400","43.11471","0.25228"
"517.77600","43.14813","0.25260"
"518.17800","43.18174","0.25343"
"518.58000","43.21527","0.25423"
"518.98200","43.24870","0.25430"
"519.38400","43.28212","0.25513"
"519.78600","43.31572","0.25561"
"520.18800","43.34921","0.25561"
"520.59000","43.38281","0.25600"
"520.99200","43.41617","0.25681"
"521.39400","43.44971","0.25803"
"521.79600","43.48325","0.25836"
"522.19800","43.51674","0.25868"
"522.60000","43.55016","0.25954"
"523.00200","43.58370","0.25990"
"523.40400","43.61724","0.26076"
"523.80600","43.65072","0.26122"
"524.20800","43.68421","0.26273"
"524.61000","43.71781","0.26256"
"525.01200","43.75123","0.26367"
"525.41400","43.78471","0.26418"
"525.81600","43.81819","0.26447"
"526.21800","43.85174","0.26512"
"526.62000","43.88528","0.26613"
"527.02200","43.91870","0.26690"
"527.42400","43.95218","0.26818"
"527.82600","43.98573","0.26904"
"528.22800","44.01926","0.27025"
"528.63000","44.05275","0.27107"
"529.03200","44.08617","0.27176"
"529.43400","44.11972","0.27317"
"529.83600","44.15326","0.27355"
"530.23800","44.18673","0.27473"
"530.64000","44.22022","0.27564"
"531.04200","44.25376","0.27624"
"531.44400","44.28724","0.27690"
"531.84600","44.32066","0.27766"
"532.24800","44.35420","0.27894"
"532.65000","44.38775","0.27995"
"533.05200","44.42129","0.28073"
"533.45400","44.45471","0.28133"
"533.85600","44.48819","0.28206"
"534.25800","44.52173","0.28279"
"534.66000","44.55522","0.28288"
"535.06200","44.58870","0.28443"
"535.46400","44.62224","0.28486"
"535.86600","44.65573","0.28603"
"536.26800","44.68927","0.28785"
"536.67000","44.72275","0.28867"
"537.07200","44.75623","0.28957"
"537.47400","44.78978","0.29080"
"537.87600","44.82325","0.29141"
"538.27800","44.85667","0.29251"
"538.68000","44.89016","0.29394"
"539.08200","44.92376","0.29507"
"539.48400","44.95724","0.29592"
"539.88600","44.99061","0.29780"
"540.28800","45.02415","0.29829"
"540.69000","45.05769","0.30000"
"541.09200","45.09129","0.30087"
"541.49400","45.12466","0.30262"
"541.89600","45.15820","0.30386"
"542.29800","45.19180","0.30512"
"542.70000","45.22522","0.30554"
"543.10200","45.25864","0.30675"
"543.50400","45.29225","0.30819"
"543.90600","45.32573","0.30903"
"544.30800","45.35927","0.31019"
"544.71000","45.39269","0.31161"
"545.11200","45.42623","0.31274"
"545.51400","45.45972","0.31525"
"545.91600","45.49320","0.31784"
"546.31800","45.52668","0.32014"
"546.72000","45.56022","0.32419"
"547.12200","45.59376","0.32634"
"547.52400","45.62719","0.32908"
"547.92600","45.66061","0.33262"
"548.32800","45.69421","0.33512"
"548.73000","45.72775","0.33722"
"549.13200","45.76123","0.33890"
"549.53400","45.79466","0.34079"
"549.93600","45.82820","0.34208"
"550.33800","45.86174","0.34385"
"550.74000","45.89522","0.34576"
"551.14200","45.92870","0.34711"
"551.54400","45.96225","0.34795"
"551.94600","45.99573","0.34876"
"552.34800","46.02921","0.35017"
"552.75000","46.06269","0.35067"
"553.15200","46.09624","0.35179"
"553.55400","46.12966","0.35244"
"553.95600","46.16320","0.35307"
"554.35800","46.19669","0.35333"
"554.76000","46.23022","0.35425"
"555.16200","46.26377","0.35466"
"555.56400","46.29725","0.35518"
"555.96600","46.33067","0.35570"
"556.36800","46.36422","0.35641"
"556.77000","46.39782","0.35678"
"557.17200","46.43124","0.35716"
"557.57400","46.46466","0.35817"
"557.97600","46.49820","0.35885"
"558.37800","46.53175","0.35955"
"558.78000","46.56529","0.35989"
"559.18200","46.59871","0.36037"
"559.58400","46.63225","0.36100"
"559.98600","46.66573","0.36144"
"560.38800","46.69921","0.36227"
"560.79000","46.73269","0.36285"
"561.19200","46.76624","0.36371"
"561.59400","46.79972","0.36506"
"561.99600","46.83320","0.36603"
"562.39800","46.86663","0.36671"
"562.80000","46.90023","0.36799"
"563.20200","46.93371","0.36917"
"563.60400","46.96719","0.36973"
"564.00600","47.00067","0.37094"
"564.40800","47.03427","0.37083"
"564.81000","47.06776","0.37067"
"565.21200","47.10124","0.37218"
"565.61400","47.13466","0.37363"
"566.01600","47.16820","0.37595"
"566.41800","47.20174","0.37709"
"566.82000","47.23517","0.37852"
"567.22200","47.26871","0.38092"
"567.62400","47.30225","0.38176"
"568.02600","47.33573","0.38353"
"568.42800","47.36921","0.38525"
"568.83000","47.40270","0.38634"
"569.23200","47.43624","0.38795"
"569.63400","47.46978","0.38938"
"570.03600","47.50314","0.39018"
"570.43800","47.53668","0.39136"
"570.84000","47.57022","0.39298"
"571.24200","47.60377","0.39437"
"571.64400","47.63725","0.39528"
"572.04600","47.67067","0.39694"
"572.44800","47.70428","0.39875"
"572.85000","47.73775","0.40039"
"573.25200","47.77124","0.40250"
"573.65400","47.80472","0.40359"
"574.05600","47.83826","0.40557"
"574.45800","47.87175","0.40671"
"574.86000","47.90517","0.40843"
"575.26200","47.93871","0.40906"
"575.66400","47.97226","0.41007"
"576.06600","48.00573","0.41206"
"576.46800","48.03922","0.41306"
"576.87000","48.07270","0.41388"
"577.27200","48.10630","0.41451"
"577.67400","48.13972","0.41453"
"578.07600","48.17315","0.41519"
"578.47800","48.20669","0.41576"
"578.88000","48.24023","0.41603"
"579.28200","48.27383","0.01110"
"579.68400","48.30719","0.00574"
"580.08600","48.34067","0.00997"
"580.48800","48.37427","0.00609"
"580.89000","48.40776","0.00517"
"581.29200","48.44124","0.00724"
"581.69400","48.47467","0.00561"
"582.09600","48.50827","0.00631"
"582.49800","48.54174","0.00640"
"582.90000","48.57517","0.00454"
"583.30200","48.60877","0.00569"
"583.70400","48.64220","0.00539"
"584.10600","48.67574","0.00524"
"584.50800","48.70916","0.00713"
"584.91000","48.74276","0.00518"
"585.31200","48.77630","0.00421"
"585.71400","48.80972","0.00715"
"586.11600","48.84309","0.00555"
"586.51800","48.87668","0.00431"
"586.92000","48.91023","0.00728"
"587.32200","48.94371","0.00478"
"587.72400","48.97719","0.00503"
"588.12600","49.01068","0.00692"
"588.52800","49.04422","0.00548"
"588.93000","49.07770","0.00477"
"589.33200","49.11118","0.00690"
"589.73400","49.14472","0.00552"
"590.13600","49.17821","0.00517"
"590.53800","49.21175","0.00628"
"590.94000","49.24517","0.00514"
"591.34200","49.27871","0.00559"
"591.74400","49.31226","0.00629"
"592.14600","49.34573","0.00541"
"592.54800","49.37916","0.00667"
"592.95000","49.41276","0.00598"
"593.35200","49.44630","0.00506"
"593.75400","49.47972","0.00602"
"594.15600","49.51315","0.00623"
"594.55800","49.54675","0.00487"
"594.96000","49.58023","0.00660"
"595.36200","49.61372","0.00609"
"595.76400","49.64720","0.00542"
"596.16600","49.68074","0.00616"
"596.56800","49.71416","0.00623"
"596.97000","49.74770","0.00558"
"597.37200","49.78124","0.00648"
"597.77400","49.81479","0.00644"
"598.17600","49.84821","0.00504"
"598.57800","49.88169","0.00644"
"598.98000","49.91517","0.00632"
"599.38200","49.94871","0.00504"
"599.78400","49.98226","0.00704"
"600.18600","50.01568","0.00540"
"600.58800","50.04916","0.00520"
"600.99000","50.08276","0.00740"
"601.39200","50.11624","0.00595"
"601.79400","50.14973","0.00591"
"602.11600","50.17657","0.00611"