File: Force_trajectories/170226_3/Specimen_RawData_2.csv
End date,"2/26/2017"
Specimen label,"7CG_50"
Maximum Load,"0.10801",N

Time,Extension,Load
(s),(mm),(N)
"0.00000","0.00000","0.00006"
"0.20400","0.01459","0.00059"
"0.40800","0.03426","0.00175"
"0.61200","0.05124","0.00206"
"0.81600","0.06816","0.00286"
"1.02000","0.08520","0.00332"
"1.22400","0.10230","0.00360"
"1.42800","0.11916","0.00380"
"1.63200","0.13620","0.00467"
"1.83600","0.15324","0.00501"
"2.04000","0.17016","0.00554"
"2.24400","0.18726","0.00529"
"2.44800","0.20424","0.00577"
"2.65200","0.22116","0.00610"
"2.85600","0.23826","0.00627"
"3.06000","0.25512","0.00728"
"3.26400","0.27228","0.00662"
"3.46800","0.28920","0.00738"
"3.67200","0.30618","0.00694"
"3.87600","0.32322","0.00726"
"4.08000","0.34020","0.00756"
"4.28400","0.35718","0.00810"
"4.48800","0.37422","0.00782"
"4.69200","0.39120","0.00844"
"4.89600","0.40818","0.00767"
"5.10000","0.42516","0.00891"
"5.30400","0.44214","0.00854"
"5.50800","0.45918","0.00871"
"5.71200","0.47622","0.00875"
"5.91600","0.49320","0.00904"
"6.12000","0.51024","0.00974"
"6.32400","0.52716","0.00899"
"6.52800","0.54420","0.00919"
"6.73200","0.56118","0.00998"
"6.93600","0.57822","0.00895"
"7.14000","0.59526","0.00983"
"7.34400","0.61213","0.00974"
"7.54800","0.62928","0.00993"
"7.75200","0.64621","0.00987"
"7.95600","0.66313","0.00968"
"8.16000","0.68023","0.00969"
"8.36400","0.69715","0.01049"
"8.56800","0.71425","0.01007"
"8.77200","0.73123","0.00973"
"8.97600","0.74821","0.01023"
"9.18000","0.76525","0.01011"
"9.38400","0.78217","0.01061"
"9.58800","0.79921","0.01040"
"9.79200","0.81619","0.01078"
"9.99600","0.83317","0.00985"
"10.20000","0.85021","0.01112"
"10.40400","0.86725","0.01020"
"10.60800","0.88417","0.01048"
"10.81200","0.90121","0.01000"
"11.01600","0.91825","0.01040"
"11.22000","0.93517","0.01078"
"11.42400","0.95221","0.01082"
"11.62800","0.96913","0.01068"
"11.83200","0.98623","0.01138"
"12.03600","1.00321","0.01049"
"12.24000","1.02019","0.01106"
"12.44400","1.03729","0.01091"
"12.64800","1.05421","0.01120"
"12.85200","1.07119","0.01108"
"13.05600","1.08817","0.01089"
"13.26000","1.10515","0.01085"
"13.46400","1.12225","0.01097"
"13.66800","1.13917","0.01134"
"13.87200","1.15621","0.01127"
"14.07600","1.17325","0.01098"
"14.28000","1.19017","0.01054"
"14.48400","1.20721","0.01108"
"14.68800","1.22425","0.01105"
"14.89200","1.24123","0.01145"
"15.09600","1.25821","0.01110"
"15.30000","1.27525","0.01081"
"15.50400","1.29217","0.01098"
"15.70800","1.30921","0.01103"
"15.91200","1.32619","0.01131"
"16.11600","1.34317","0.01132"
"16.32000","1.36027","0.01071"
"16.52400","1.37713","0.01162"
"16.72800","1.39423","0.01176"
"16.93200","1.41121","0.01141"
"17.13600","1.42819","0.01115"
"17.34000","1.44523","0.01093"
"17.54400","1.46215","0.01148"
"17.74800","1.47925","0.01175"
"17.95200","1.49623","0.01103"
"18.15600","1.51315","0.01133"
"18.36000","1.53025","0.01145"
"18.56400","1.54717","0.01179"
"18.76800","1.56421","0.01148"
"18.97200","1.58125","0.01138"
"19.17600","1.59817","0.01120"
"19.38000","1.61521","0.01151"
"19.58400","1.63219","0.01146"
"19.78800","1.64917","0.01190"
"19.99200","1.66621","0.01126"
"20.19600","1.68319","0.01191"
"20.40000","1.70018","0.01194"
"20.60400","1.71722","0.01172"
"20.80800","1.73414","0.01160"
"21.01200","1.75124","0.01198"
"21.21600","1.76822","0.01161"
"21.42000","1.78514","0.01208"
"21.62400","1.80224","0.01190"
"21.82800","1.81916","0.01208"
"22.03200","1.83620","0.01180"
"22.23600","1.85318","0.01134"
"22.44000","1.87016","0.01179"
"22.64400","1.88726","0.01187"
"22.84800","1.90418","0.01164"
"23.05200","1.92122","0.01192"
"23.25600","1.93826","0.01154"
"23.46000","1.95518","0.01173"
"23.66400","1.97228","0.01173"
"23.86800","1.98920","0.01147"
"24.07200","2.00624","0.01188"
"24.27600","2.02322","0.01237"
"24.48000","2.04020","0.01217"
"24.68400","2.05718","0.01202"
"24.88800","2.07422","0.01215"
"25.09200","2.09114","0.01229"
"25.29600","2.10824","0.01201"
"25.50000","2.12528","0.01177"
"25.70400","2.14214","0.01222"
"25.90800","2.15924","0.01219"
"26.11200","2.17616","0.01184"
"26.31600","2.19314","0.01264"
"26.52000","2.21024","0.01182"
"26.72400","2.22716","0.01285"
"26.92800","2.24420","0.01176"
"27.13200","2.26124","0.01252"
"27.33600","2.27816","0.01194"
"27.54000","2.29520","0.01192"
"27.74400","2.31218","0.01253"
"27.94800","2.32922","0.01248"
"28.15200","2.34620","0.01217"
"28.35600","2.36318","0.01194"
"28.56000","2.38022","0.01203"
"28.76400","2.39720","0.01254"
"28.96800","2.41418","0.01238"
"29.17200","2.43116","0.01280"
"29.37600","2.44820","0.01240"
"29.58000","2.46518","0.01286"
"29.78400","2.48222","0.01195"
"29.98800","2.49914","0.01250"
"30.19200","2.51618","0.01258"
"30.39600","2.53322","0.01225"
"30.60000","2.55020","0.01196"
"30.80400","2.56724","0.01235"
"31.00800","2.58416","0.01228"
"31.21200","2.60120","0.01250"
"31.41600","2.61818","0.01277"
"31.62000","2.63516","0.01262"
"31.82400","2.65226","0.01309"
"32.02800","2.66918","0.01251"
"32.23200","2.68622","0.01283"
"32.43600","2.70326","0.01278"
"32.64000","2.72018","0.01228"
"32.84400","2.73728","0.01245"
"33.04800","2.75420","0.01246"
"33.25200","2.77119","0.01317"
"33.45600","2.78823","0.01243"
"33.66000","2.80521","0.01241"
"33.86400","2.82225","0.01262"
"34.06800","2.83923","0.01282"
"34.27200","2.85615","0.01251"
"34.47600","2.87325","0.01288"
"34.68000","2.89023","0.01286"
"34.88400","2.90721","0.01281"
"35.08800","2.92425","0.01233"
"35.29200","2.94117","0.01268"
"35.49600","2.95821","0.01294"
"35.70000","2.97525","0.01281"
"35.90400","2.99211","0.01297"
"36.10800","3.00927","0.01203"
"36.31200","3.02619","0.01311"
"36.51600","3.04317","0.01284"
"36.72000","3.06021","0.01284"
"36.92400","3.07719","0.01306"
"37.12800","3.09423","0.01308"
"37.33200","3.11121","0.01348"
"37.53600","3.12819","0.01357"
"37.74000","3.14523","0.01293"
"37.94400","3.16215","0.01281"
"38.14800","3.17925","0.01274"
"38.35200","3.19623","0.01284"
"38.55600","3.21315","0.01269"
"38.76000","3.23025","0.01276"
"38.96400","3.24723","0.01267"
"39.16800","3.26421","0.01300"
"39.37200","3.28119","0.01260"
"39.57600","3.29823","0.01292"
"39.78000","3.31521","0.01338"
"39.98400","3.33225","0.01207"
"40.18800","3.34917","0.01281"
"40.39200","3.36621","0.01256"
"40.59600","3.38319","0.01266"
"40.80000","3.40023","0.01292"
"41.00400","3.41721","0.01313"
"41.20800","3.43419","0.01278"
"41.41200","3.45123","0.01262"
"41.61600","3.46821","0.01272"
"41.82000","3.48513","0.01257"
"42.02400","3.50229","0.01287"
"42.22800","3.51915","0.01308"
"42.43200","3.53625","0.01350"
"42.63600","3.55323","0.01290"
"42.84000","3.57015","0.01313"
"43.04400","3.58725","0.01263"
"43.24800","3.60417","0.01329"
"43.45200","3.62121","0.01297"
"43.65600","3.63819","0.01318"
"43.86000","3.65517","0.01280"
"44.06400","3.67221","0.01291"
"44.26800","3.68919","0.01322"
"44.47200","3.70617","0.01299"
"44.67600","3.72321","0.01293"
"44.88000","3.74025","0.01306"
"45.08400","3.75717","0.01361"
"45.28800","3.77427","0.01308"
"45.49200","3.79119","0.01314"
"45.69600","3.80823","0.01349"
"45.90000","3.82527","0.01305"
"46.10400","3.84214","0.01338"
"46.30800","3.85929","0.01340"
"46.51200","3.87622","0.01350"
"46.71600","3.89320","0.01356"
"46.92000","3.91018","0.01360"
"47.12400","3.92716","0.01316"
"47.32800","3.94420","0.01374"
"47.53200","3.96118","0.01340"
"47.73600","3.97816","0.01378"
"47.94000","3.99526","0.01378"
"48.14400","4.01218","0.01373"
"48.34800","4.02916","0.01375"
"48.55200","4.04620","0.01346"
"48.75600","4.06324","0.01390"
"48.96000","4.08022","0.01381"
"49.16400","4.09726","0.01382"
"49.36800","4.11418","0.01405"
"49.57200","4.13116","0.01363"
"49.77600","4.14820","0.01411"
"49.98000","4.16524","0.01371"
"50.18400","4.18222","0.01438"
"50.38800","4.19914","0.01370"
"50.59200","4.21624","0.01398"
"50.79600","4.23322","0.01399"
"51.00000","4.25014","0.01406"
"51.20400","4.26730","0.01393"
"51.40800","4.28416","0.01372"
"51.61200","4.30120","0.01363"
"51.81600","4.31824","0.01433"
"52.02000","4.33516","0.01417"
"52.22400","4.35226","0.01447"
"52.42800","4.36918","0.01514"
"52.63200","4.38622","0.01498"
"52.83600","4.40320","0.01454"
"53.04000","4.42018","0.01501"
"53.24400","4.43722","0.01476"
"53.44800","4.45420","0.01526"
"53.65200","4.47118","0.01464"
"53.85600","4.48816","0.01531"
"54.06000","4.50526","0.01509"
"54.26400","4.52218","0.01538"
"54.46800","4.53922","0.01471"
"54.67200","4.55614","0.01495"
"54.87600","4.57324","0.01515"
"55.08000","4.59022","0.01486"
"55.28400","4.60714","0.01481"
"55.48800","4.62424","0.01507"
"55.69200","4.64122","0.01515"
"55.89600","4.65820","0.01465"
"56.10000","4.67518","0.01457"
"56.30400","4.69216","0.01459"
"56.50800","4.70926","0.01536"
"56.71200","4.72618","0.01478"
"56.91600","4.74322","0.01547"
"57.12000","4.76020","0.01453"
"57.32400","4.77718","0.01559"
"57.52800","4.79422","0.01530"
"57.73200","4.81120","0.01543"
"57.93600","4.82818","0.01544"
"58.14000","4.84522","0.01595"
"58.34400","4.86226","0.01500"
"58.54800","4.87918","0.01546"
"58.75200","4.89622","0.01567"
"58.95600","4.91320","0.01568"
"59.16000","4.93018","0.01487"
"59.36400","4.94723","0.01511"
"59.56800","4.96421","0.01534"
"59.77200","4.98125","0.01518"
"59.97600","4.99823","0.01532"
"60.18000","5.01515","0.01594"
"60.38400","5.03225","0.01563"
"60.58800","5.04917","0.01630"
"60.79200","5.06627","0.01582"
"60.99600","5.08319","0.01575"
"61.20000","5.10017","0.01614"
"61.40400","5.11721","0.01591"
"61.60800","5.13419","0.01620"
"61.81200","5.15123","0.01612"
"62.01600","5.16821","0.01645"
"62.22000","5.18519","0.01629"
"62.42400","5.20217","0.01667"
"62.62800","5.21921","0.01690"
"62.83200","5.23619","0.01647"
"63.03600","5.25323","0.01689"
"63.24000","5.27021","0.01653"
"63.44400","5.28725","0.01636"
"63.64800","5.30423","0.01635"
"63.85200","5.32121","0.01632"
"64.05600","5.33825","0.01700"
"64.26000","5.35523","0.01621"
"64.46400","5.37215","0.01635"
"64.66800","5.38925","0.01607"
"64.87200","5.40617","0.01648"
"65.07600","5.42321","0.01739"
"65.28000","5.44019","0.01708"
"65.48400","5.45711","0.01681"
"65.68800","5.47427","0.01695"
"65.89200","5.49119","0.01739"
"66.09600","5.50823","0.01701"
"66.30000","5.52521","0.01728"
"66.50400","5.54213","0.01734"
"66.70800","5.55923","0.01690"
"66.91200","5.57621","0.01714"
"67.11600","5.59319","0.01764"
"67.32000","5.61029","0.01722"
"67.52400","5.62721","0.01747"
"67.72800","5.64419","0.01702"
"67.93200","5.66123","0.01773"
"68.13600","5.67815","0.01720"
"68.34000","5.69525","0.01779"
"68.54400","5.71223","0.01786"
"68.74800","5.72915","0.01806"
"68.95200","5.74625","0.01790"
"69.15600","5.76317","0.01735"
"69.36000","5.78015","0.01817"
"69.56400","5.79725","0.01792"
"69.76800","5.81411","0.01711"
"69.97200","5.83127","0.01730"
"70.17600","5.84819","0.01754"
"70.38000","5.86511","0.01700"
"70.58400","5.88221","0.01741"
"70.78800","5.89919","0.01708"
"70.99200","5.91617","0.01777"
"71.19600","5.93327","0.01736"
"71.40000","5.95014","0.01745"
"71.60400","5.96723","0.01760"
"71.80800","5.98422","0.01776"
"72.01200","6.00120","0.01789"
"72.21600","6.01817","0.01845"
"72.42000","6.03522","0.01853"
"72.62400","6.05220","0.01863"
"72.82800","6.06918","0.01933"
"73.03200","6.08616","0.01805"
"73.23600","6.10320","0.01887"
"73.44000","6.12024","0.01889"
"73.64400","6.13722","0.01944"
"73.84800","6.15420","0.01965"
"74.05200","6.17112","0.01950"
"74.25600","6.18828","0.01965"
"74.46000","6.20520","0.01986"
"74.66400","6.22218","0.01955"
"74.86800","6.23922","0.02034"
"75.07200","6.25620","0.02024"
"75.27600","6.27324","0.02059"
"75.48000","6.29022","0.02052"
"75.68400","6.30714","0.02024"
"75.88800","6.32430","0.02081"
"76.09200","6.34122","0.02143"
"76.29600","6.35820","0.02043"
"76.50000","6.37524","0.02001"
"76.70400","6.39222","0.02003"
"76.90800","6.40926","0.02095"
"77.11200","6.42624","0.02164"
"77.31600","6.44316","0.02089"
"77.52000","6.46026","0.02148"
"77.72400","6.47724","0.02137"
"77.92800","6.49416","0.02092"
"78.13200","6.51126","0.02237"
"78.33600","6.52818","0.02221"
"78.54000","6.54522","0.02219"
"78.74400","6.56226","0.02247"
"78.94800","6.57918","0.02200"
"79.15200","6.59628","0.02264"
"79.35600","6.61320","0.02289"
"79.56000","6.63018","0.02289"
"79.76400","6.64722","0.02262"
"79.96800","6.66420","0.02340"
"80.17200","6.68124","0.02409"
"80.37600","6.69822","0.02383"
"80.58000","6.71514","0.02412"
"80.78400","6.73218","0.02392"
"80.98800","6.74916","0.02443"
"81.19200","6.76620","0.02501"
"81.39600","6.78318","0.02475"
"81.60000","6.80022","0.02550"
"81.80400","6.81726","0.02635"
"82.00800","6.83418","0.02617"
"82.21200","6.85116","0.02580"
"82.41600","6.86820","0.02606"
"82.62000","6.88518","0.02651"
"82.82400","6.90216","0.02677"
"83.02800","6.91920","0.02717"
"83.23200","6.93618","0.02647"
"83.43600","6.95322","0.02633"
"83.64000","6.97020","0.02745"
"83.84400","6.98718","0.02677"
"84.04800","7.00422","0.02724"
"84.25200","7.02120","0.02704"
"84.45600","7.03824","0.02717"
"84.66000","7.05522","0.02755"
"84.86400","7.07214","0.02747"
"85.06800","7.08930","0.02765"
"85.27200","7.10617","0.02797"
"85.47600","7.12321","0.02775"
"85.68000","7.14019","0.02792"
"85.88400","7.15717","0.02817"
"86.08800","7.17427","0.02778"
"86.29200","7.19119","0.02778"
"86.49600","7.20823","0.02738"
"86.70000","7.22521","0.02778"
"86.90400","7.24219","0.02770"
"87.10800","7.25917","0.02809"
"87.31200","7.27621","0.02780"
"87.51600","7.29319","0.02754"
"87.72000","7.31023","0.02764"
"87.92400","7.32721","0.02784"
"88.12800","7.34419","0.02820"
"88.33200","7.36117","0.02851"
"88.53600","7.37821","0.02837"
"88.74000","7.39519","0.02858"
"88.94400","7.41229","0.02933"
"89.14800","7.42915","0.02860"
"89.35200","7.44625","0.02880"
"89.55600","7.46323","0.02886"
"89.76000","7.48021","0.02974"
"89.96400","7.49719","0.02984"
"90.16800","7.51417","0.02932"
"90.37200","7.53121","0.02939"
"90.57600","7.54825","0.03019"
"90.78000","7.56517","0.02856"
"90.98400","7.58227","0.02862"
"91.18800","7.59919","0.02854"
"91.39200","7.61617","0.02938"
"91.59600","7.63321","0.02970"
"91.80000","7.65013","0.02951"
"92.00400","7.66723","0.02918"
"92.20800","7.68421","0.02961"
"92.41200","7.70119","0.02972"
"92.61600","7.71817","0.02981"
"92.82000","7.73521","0.03019"
"93.02400","7.75219","0.03003"
"93.22800","7.76923","0.03065"
"93.43200","7.78615","0.03104"
"93.63600","7.80325","0.03081"
"93.84000","7.82023","0.03111"
"94.04400","7.83715","0.03065"
"94.24800","7.85425","0.03101"
"94.45200","7.87117","0.03138"
"94.65600","7.88821","0.03098"
"94.86000","7.90525","0.03088"
"95.06400","7.92217","0.03084"
"95.26800","7.93927","0.03145"
"95.47200","7.95619","0.03166"
"95.67600","7.97317","0.03118"
"95.88000","7.99027","0.03208"
"96.08400","8.00719","0.03146"
"96.28800","8.02417","0.03119"
"96.49200","8.04121","0.03168"
"96.69600","8.05819","0.03170"
"96.90000","8.07517","0.03251"
"97.10400","8.09221","0.03224"
"97.30800","8.10919","0.03302"
"97.51200","8.12624","0.03256"
"97.71600","8.14316","0.03222"
"97.92000","8.16025","0.03245"
"98.12400","8.17723","0.03285"
"98.32800","8.19415","0.03288"
"98.53200","8.21126","0.03248"
"98.73600","8.22818","0.03337"
"98.94000","8.24522","0.03266"
"99.14400","8.26220","0.03300"
"99.34800","8.27918","0.03271"
"99.55200","8.29622","0.03325"
"99.75600","8.31320","0.03276"
"99.96000","8.33018","0.03239"
"100.16400","8.34722","0.03253"
"100.36800","8.36414","0.03263"
"100.57200","8.38124","0.03345"
"100.77600","8.39822","0.03297"
"100.98000","8.41514","0.03272"
"101.18400","8.43224","0.03313"
"101.38800","8.44922","0.03295"
"101.59200","8.46620","0.03323"
"101.79600","8.48318","0.03403"
"102.00000","8.50022","0.03368"
"102.20400","8.51720","0.03352"
"102.40800","8.53424","0.03321"
"102.61200","8.55116","0.03308"
"102.81600","8.56826","0.03336"
"103.02000","8.58518","0.03338"
"103.22400","8.60216","0.03379"
"103.42800","8.61926","0.03368"
"103.63200","8.63618","0.03356"
"103.83600","8.65322","0.03349"
"104.04000","8.67020","0.03347"
"104.24400","8.68712","0.03285"
"104.44800","8.70422","0.03356"
"104.65200","8.72120","0.03371"
"104.85600","8.73818","0.03359"
"105.06000","8.75522","0.03368"
"105.26400","8.77220","0.03379"
"105.46800","8.78924","0.03310"
"105.67200","8.80622","0.03401"
"105.87600","8.82320","0.03420"
"106.08000","8.84018","0.03382"
"106.28400","8.85722","0.03454"
"106.48800","8.87420","0.03411"
"106.69200","8.89118","0.03486"
"106.89600","8.90816","0.03490"
"107.10000","8.92520","0.03480"
"107.30400","8.94224","0.03472"
"107.50800","8.95916","0.03547"
"107.71200","8.97620","0.03547"
"107.91600","8.99318","0.03534"
"108.12000","9.01016","0.03549"
"108.32400","9.02720","0.03552"
"108.52800","9.04412","0.03602"
"108.73200","9.06122","0.03625"
"108.93600","9.07820","0.03676"
"109.14000","9.09518","0.03647"
"109.34400","9.11222","0.03652"
"109.54800","9.12914","0.03671"
"109.75200","9.14624","0.03693"
"109.95600","9.16322","0.03715"
"110.16000","9.18021","0.03668"
"110.36400","9.19718","0.03708"
"110.56800","9.21422","0.03721"
"110.77200","9.23120","0.03704"
"110.97600","9.24824","0.03724"
"111.18000","9.26517","0.03770"
"111.38400","9.28226","0.03784"
"111.58800","9.29925","0.03798"
"111.79200","9.31611","0.03836"
"111.99600","9.33327","0.03835"
"112.20000","9.35019","0.03793"
"112.40400","9.36717","0.03804"
"112.60800","9.38421","0.03881"
"112.81200","9.40119","0.03865"
"113.01600","9.41823","0.03829"
"113.22000","9.43521","0.03859"
"113.42400","9.45219","0.03851"
"113.62800","9.46923","0.03904"
"113.83200","9.48615","0.03953"
"114.03600","9.50325","0.03925"
"114.24000","9.52023","0.03946"
"114.44400","9.53715","0.03955"
"114.64800","9.55419","0.03959"
"114.85200","9.57123","0.03912"
"115.05600","9.58821","0.03976"
"115.26000","9.60519","0.03898"
"115.46400","9.62223","0.03961"
"115.66800","9.63921","0.04043"
"115.87200","9.65619","0.03967"
"116.07600","9.67317","0.04038"
"116.28000","9.69021","0.04090"
"116.48400","9.70719","0.04095"
"116.68800","9.72423","0.04117"
"116.89200","9.74121","0.04092"
"117.09600","9.75813","0.04120"
"117.30000","9.77523","0.04123"
"117.50400","9.79221","0.04163"
"117.70800","9.80913","0.04203"
"117.91200","9.82629","0.04209"
"118.11600","9.84315","0.04281"
"118.32000","9.86019","0.04252"
"118.52400","9.87723","0.04275"
"118.72800","9.89409","0.04352"
"118.93200","9.91131","0.04246"
"119.13600","9.92817","0.04217"
"119.34000","9.94521","0.04295"
"119.54400","9.96219","0.04281"
"119.74800","9.97917","0.04267"
"119.95200","9.99621","0.04326"
"120.15600","10.01325","0.04308"
"120.36000","10.03011","0.04317"
"120.56400","10.04727","0.04365"
"120.76800","10.06425","0.04336"
"120.97200","10.08117","0.04364"
"121.17600","10.09821","0.04339"
"121.38000","10.11519","0.04450"
"121.58400","10.13217","0.04366"
"121.78800","10.14927","0.04345"
"121.99200","10.16613","0.04362"
"122.19600","10.18329","0.04371"
"122.40000","10.20015","0.04408"
"122.60400","10.21719","0.04443"
"122.80800","10.23423","0.04466"
"123.01200","10.25115","0.04393"
"123.21600","10.26825","0.04506"
"123.42000","10.28523","0.04483"
"123.62400","10.30216","0.04516"
"123.82800","10.31919","0.04539"
"124.03200","10.33618","0.04554"
"124.23600","10.35322","0.04559"
"124.44000","10.37025","0.04576"
"124.64400","10.38718","0.04554"
"124.84800","10.40428","0.04555"
"125.05200","10.42120","0.04571"
"125.25600","10.43818","0.04551"
"125.46000","10.45522","0.04580"
"125.66400","10.47220","0.04627"
"125.86800","10.48918","0.04607"
"126.07200","10.50622","0.04617"
"126.27600","10.52314","0.04603"
"126.48000","10.54018","0.04647"
"126.68400","10.55722","0.04572"
"126.88800","10.57420","0.04492"
"127.09200","10.59124","0.04499"
"127.29600","10.60822","0.04490"
"127.50000","10.62526","0.04524"
"127.70400","10.64224","0.04377"
"127.90800","10.65916","0.04386"
"128.11200","10.67620","0.04444"
"128.31600","10.69318","0.04391"
"128.52000","10.71022","0.04384"
"128.72400","10.72720","0.04436"
"128.92800","10.74418","0.04306"
"129.13200","10.76128","0.04383"
"129.33600","10.77820","0.04451"
"129.54000","10.79518","0.04400"
"129.74400","10.81216","0.04455"
"129.94800","10.82920","0.04443"
"130.15200","10.84618","0.04465"
"130.35600","10.86322","0.04371"
"130.56000","10.88014","0.04461"
"130.76400","10.89724","0.04480"
"130.96800","10.91428","0.04479"
"131.17200","10.93114","0.04424"
"131.37600","10.94824","0.04496"
"131.58000","10.96522","0.04416"
"131.78400","10.98220","0.04502"
"131.98800","10.99924","0.04526"
"132.19200","11.01610","0.04540"
"132.39600","11.03326","0.03703"
"132.60000","11.05018","0.03787"
"132.80400","11.06716","0.03783"
"133.00800","11.08420","0.03784"
"133.21200","11.10118","0.03824"
"133.41600","11.11816","0.03767"
"133.62000","11.13520","0.03867"
"133.82400","11.15218","0.03902"
"134.02800","11.16922","0.03921"
"134.23200","11.18614","0.03913"
"134.43600","11.20318","0.03908"
"134.64000","11.22016","0.03978"
"134.84400","11.23720","0.03996"
"135.04800","11.25418","0.03991"
"135.25200","11.27122","0.04016"
"135.45600","11.28820","0.04020"
"135.66000","11.30524","0.03978"
"135.86400","11.32216","0.04074"
"136.06800","11.33926","0.04069"
"136.27200","11.35625","0.03932"
"136.47600","11.37316","0.03974"
"136.68000","11.39021","0.03968"
"136.88400","11.40724","0.03953"
"137.08800","11.42417","0.03935"
"137.29200","11.44127","0.03907"
"137.49600","11.45819","0.03912"
"137.70000","11.47523","0.03895"
"137.90400","11.49221","0.03955"
"138.10800","11.50919","0.03906"
"138.31200","11.52623","0.03939"
"138.51600","11.54315","0.03948"
"138.72000","11.56019","0.03936"
"138.92400","11.57717","0.04009"
"139.12800","11.59421","0.03955"
"139.33200","11.61119","0.03986"
"139.53600","11.62823","0.04036"
"139.74000","11.64521","0.04008"
"139.94400","11.66225","0.04015"
"140.14800","11.67923","0.04006"
"140.35200","11.69615","0.03966"
"140.55600","11.71325","0.04020"
"140.76000","11.73017","0.03937"
"140.96400","11.74721","0.03946"
"141.16800","11.76419","0.03882"
"141.37200","11.78117","0.03913"
"141.57600","11.79821","0.03797"
"141.78000","11.81519","0.03854"
"141.98400","11.83217","0.03834"
"142.18800","11.84921","0.03880"
"142.39200","11.86619","0.03722"
"142.59600","11.88329","0.03700"
"142.80000","11.90015","0.03663"
"143.00400","11.91719","0.03610"
"143.20800","11.93417","0.03547"
"143.41200","11.95115","0.03565"
"143.61600","11.96819","0.03493"
"143.82000","11.98523","0.03515"
"144.02400","12.00221","0.03552"
"144.22800","12.01925","0.03452"
"144.43200","12.03623","0.03551"
"144.63600","12.05321","0.03525"
"144.84000","12.07025","0.03564"
"145.04400","12.08723","0.03533"
"145.24800","12.10421","0.03532"
"145.45200","12.12125","0.03542"
"145.65600","12.13817","0.03514"
"145.86000","12.15521","0.03530"
"146.06400","12.17219","0.03495"
"146.26800","12.18917","0.03472"
"146.47200","12.20627","0.03504"
"146.67600","12.22313","0.03484"
"146.88000","12.24023","0.03578"
"147.08400","12.25721","0.03587"
"147.28800","12.27413","0.03624"
"147.49200","12.29123","0.03611"
"147.69600","12.30815","0.03605"
"147.90000","12.32525","0.03650"
"148.10400","12.34223","0.03641"
"148.30800","12.35915","0.03654"
"148.51200","12.37619","0.03638"
"148.71600","12.39323","0.03664"
"148.92000","12.41021","0.03675"
"149.12400","12.42719","0.03572"
"149.32800","12.44417","0.03657"
"149.53200","12.46122","0.03642"
"149.73600","12.47820","0.03690"
"149.94000","12.49518","0.03712"
"150.14400","12.51222","0.03696"
"150.34800","12.52925","0.03726"
"150.55200","12.54618","0.03794"
"150.75600","12.56322","0.03710"
"150.96000","12.58020","0.03686"
"151.16400","12.59718","0.03447"
"151.36800","12.61422","0.03558"
"151.57200","12.63114","0.03566"
"151.77600","12.64824","0.03543"
"151.98000","12.66516","0.03589"
"152.18400","12.68220","0.03630"
"152.38800","12.69924","0.03613"
"152.59200","12.71622","0.03632"
"152.79600","12.73326","0.03674"
"153.00000","12.75024","0.03620"
"153.20400","12.76716","0.03674"
"153.40800","12.78420","0.03748"
"153.61200","12.80118","0.03705"
"153.81600","12.81822","0.03731"
"154.02000","12.83520","0.03778"
"154.22400","12.85218","0.03804"
"154.42800","12.86922","0.03805"
"154.63200","12.88626","0.03802"
"154.83600","12.90312","0.03808"
"155.04000","12.92022","0.03790"
"155.24400","12.93726","0.03679"
"155.44800","12.95418","0.03702"
"155.65200","12.97128","0.03708"
"155.85600","12.98814","0.03643"
"156.06000","13.00524","0.03700"
"156.26400","13.02222","0.03769"
"156.46800","13.03920","0.03687"
"156.67200","13.05618","0.03815"
"156.87600","13.07322","0.03802"
"157.08000","13.09020","0.03794"
"157.28400","13.10724","0.03694"
"157.48800","13.12416","0.03734"
"157.69200","13.14126","0.03667"
"157.89600","13.15818","0.03680"
"158.10000","13.17522","0.03706"
"158.30400","13.19220","0.03712"
"158.50800","13.20918","0.03686"
"158.71200","13.22622","0.03681"
"158.91600","13.24320","0.03684"
"159.12000","13.26018","0.03625"
"159.32400","13.27716","0.03593"
"159.52800","13.29426","0.03659"
"159.73200","13.31118","0.03677"
"159.93600","13.32822","0.03670"
"160.14000","13.34514","0.03601"
"160.34400","13.36224","0.03659"
"160.54800","13.37922","0.03650"
"160.75200","13.39620","0.03645"
"160.95600","13.41324","0.03669"
"161.16000","13.43017","0.03690"
"161.36400","13.44720","0.03693"
"161.56800","13.46424","0.03705"
"161.77200","13.48116","0.03668"
"161.97600","13.49826","0.03773"
"162.18000","13.51519","0.03721"
"162.38400","13.53222","0.03720"
"162.58800","13.54921","0.03704"
"162.79200","13.56618","0.03733"
"162.99600","13.58323","0.03784"
"163.20000","13.60021","0.03735"
"163.40400","13.61719","0.03704"
"163.60800","13.63428","0.03700"
"163.81200","13.65121","0.03724"
"164.01600","13.66819","0.03816"
"164.22000","13.68529","0.03826"
"164.42400","13.70215","0.03835"
"164.62800","13.71919","0.03829"
"164.83200","13.73623","0.03846"
"165.03600","13.75309","0.03900"
"165.24000","13.77025","0.03887"
"165.44400","13.78723","0.03857"
"165.64800","13.80415","0.03921"
"165.85200","13.82125","0.03918"
"166.05600","13.83817","0.03891"
"166.26000","13.85521","0.03815"
"166.46400","13.87219","0.03791"
"166.66800","13.88911","0.03864"
"166.87200","13.90621","0.03852"
"167.07600","13.92319","0.03876"
"167.28000","13.94023","0.03907"
"167.48400","13.95721","0.03795"
"167.68800","13.97419","0.03820"
"167.89200","13.99129","0.03748"
"168.09600","14.00821","0.03763"
"168.30000","14.02519","0.03838"
"168.50400","14.04223","0.03761"
"168.70800","14.05921","0.03815"
"168.91200","14.07619","0.03892"
"169.11600","14.09323","0.03824"
"169.32000","14.11015","0.03849"
"169.52400","14.12725","0.03816"
"169.72800","14.14423","0.03785"
"169.93200","14.16121","0.03851"
"170.13600","14.17825","0.03828"
"170.34000","14.19517","0.03926"
"170.54400","14.21221","0.03895"
"170.74800","14.22925","0.03950"
"170.95200","14.24611","0.03916"
"171.15600","14.26327","0.03960"
"171.36000","14.28013","0.03927"
"171.56400","14.29717","0.03932"
"171.76800","14.31421","0.03978"
"171.97200","14.33119","0.04017"
"172.17600","14.34823","0.04061"
"172.38000","14.36521","0.04021"
"172.58400","14.38219","0.04009"
"172.78800","14.39917","0.03987"
"172.99200","14.41621","0.04041"
"173.19600","14.43319","0.04037"
"173.40000","14.45023","0.04007"
"173.60400","14.46715","0.04019"
"173.80800","14.48425","0.04069"
"174.01200","14.50123","0.04081"
"174.21600","14.51816","0.04044"
"174.42000","14.53525","0.03589"
"174.62400","14.55223","0.03583"
"174.82800","14.56915","0.03706"
"175.03200","14.58625","0.03690"
"175.23600","14.60318","0.03778"
"175.44000","14.62027","0.03725"
"175.64400","14.63720","0.03782"
"175.84800","14.65418","0.03717"
"176.05200","14.67122","0.03810"
"176.25600","14.68820","0.03765"
"176.46000","14.70524","0.03784"
"176.66400","14.72222","0.03830"
"176.86800","14.73920","0.03841"
"177.07200","14.75624","0.03763"
"177.27600","14.77316","0.03743"
"177.48000","14.79014","0.03748"
"177.68400","14.80724","0.03771"
"177.88800","14.82422","0.03804"
"178.09200","14.84120","0.03774"
"178.29600","14.85824","0.03812"
"178.50000","14.87522","0.03814"
"178.70400","14.89220","0.03903"
"178.90800","14.90924","0.03936"
"179.11200","14.92622","0.03931"
"179.31600","14.94320","0.03947"
"179.52000","14.96012","0.03986"
"179.72400","14.97722","0.04002"
"179.92800","14.99426","0.03984"
"180.13200","15.01112","0.04034"
"180.33600","15.02828","0.04024"
"180.54000","15.04514","0.04070"
"180.74400","15.06218","0.04067"
"180.94800","15.07922","0.04009"
"181.15200","15.09614","0.04141"
"181.35600","15.11318","0.04118"
"181.56000","15.13016","0.04179"
"181.76400","15.14720","0.03915"
"181.96800","15.16424","0.03943"
"182.17200","15.18116","0.03984"
"182.37600","15.19820","0.04020"
"182.58000","15.21524","0.04066"
"182.78400","15.23222","0.04102"
"182.98800","15.24920","0.04166"
"183.19200","15.26624","0.04167"
"183.39600","15.28322","0.04182"
"183.60000","15.30020","0.04158"
"183.80400","15.31718","0.04197"
"184.00800","15.33422","0.04171"
"184.21200","15.35126","0.04185"
"184.41600","15.36812","0.04246"
"184.62000","15.38522","0.04234"
"184.82400","15.40220","0.04264"
"185.02800","15.41918","0.04312"
"185.23200","15.43622","0.04326"
"185.43600","15.45320","0.04212"
"185.64000","15.47024","0.04113"
"185.84400","15.48716","0.04207"
"186.04800","15.50420","0.04237"
"186.25200","15.52124","0.04211"
"186.45600","15.53816","0.04226"
"186.66000","15.55520","0.04161"
"186.86400","15.57224","0.04238"
"187.06800","15.58917","0.04194"
"187.27200","15.60626","0.04205"
"187.47600","15.62319","0.04256"
"187.68000","15.64016","0.04279"
"187.88400","15.65720","0.04292"
"188.08800","15.67418","0.04281"
"188.29200","15.69122","0.04271"
"188.49600","15.70820","0.04300"
"188.70000","15.72518","0.04277"
"188.90400","15.74223","0.04316"
"189.10800","15.75921","0.04135"
"189.31200","15.77613","0.04175"
"189.51600","15.79328","0.04149"
"189.72000","15.81015","0.04283"
"189.92400","15.82719","0.04289"
"190.12800","15.84423","0.04295"
"190.33200","15.86115","0.04294"
"190.53600","15.87825","0.04313"
"190.74000","15.89517","0.04312"
"190.94400","15.91221","0.04360"
"191.14800","15.92925","0.04392"
"191.35200","15.94617","0.04384"
"191.55600","15.96321","0.04381"
"191.76000","15.98019","0.04409"
"191.96400","15.99723","0.04473"
"192.16800","16.01421","0.04446"
"192.37200","16.03119","0.04450"
"192.57600","16.04823","0.04501"
"192.78000","16.06521","0.04562"
"192.98400","16.08213","0.04531"
"193.18800","16.09923","0.04500"
"193.39200","16.11627","0.04510"
"193.59600","16.13319","0.04552"
"193.80000","16.15023","0.04567"
"194.00400","16.16721","0.04557"
"194.20800","16.18419","0.04578"
"194.41200","16.20123","0.04589"
"194.61600","16.21815","0.04528"
"194.82000","16.23525","0.04624"
"195.02400","16.25217","0.04639"
"195.22800","16.26921","0.04664"
"195.43200","16.28619","0.04682"
"195.63600","16.30317","0.04784"
"195.84000","16.32027","0.04730"
"196.04400","16.33719","0.04747"
"196.24800","16.35417","0.04758"
"196.45200","16.37121","0.04801"
"196.65600","16.38819","0.04845"
"196.86000","16.40517","0.04877"
"197.06400","16.42221","0.04870"
"197.26800","16.43919","0.04878"
"197.47200","16.45623","0.04950"
"197.67600","16.47321","0.04999"
"197.88000","16.49019","0.05018"
"198.08400","16.50723","0.05048"
"198.28800","16.52421","0.05055"
"198.49200","16.54113","0.05139"
"198.69600","16.55823","0.05092"
"198.90000","16.57515","0.05095"
"199.10400","16.59225","0.05120"
"199.30800","16.60917","0.05135"
"199.51200","16.62615","0.05205"
"199.71600","16.64325","0.05211"
"199.92000","16.66017","0.05231"
"200.12400","16.67721","0.05200"
"200.32800","16.69425","0.05261"
"200.53200","16.71117","0.05303"
"200.73600","16.72821","0.05296"
"200.94000","16.74520","0.05363"
"201.14400","16.76223","0.05363"
"201.34800","16.77921","0.05401"
"201.55200","16.79620","0.05393"
"201.75600","16.81318","0.05417"
"201.96000","16.83022","0.05432"
"202.16400","16.84719","0.05444"
"202.36800","16.86418","0.05457"
"202.57200","16.88122","0.05471"
"202.77600","16.89814","0.05488"
"202.98000","16.91518","0.05534"
"203.18400","16.93216","0.05541"
"203.38800","16.94926","0.05528"
"203.59200","16.96624","0.05597"
"203.79600","16.98316","0.05606"
"204.00000","17.00020","0.05575"
"204.20400","17.01724","0.05610"
"204.40800","17.03422","0.05648"
"204.61200","17.05126","0.05653"
"204.81600","17.06812","0.05664"
"205.02000","17.08534","0.05625"
"205.22400","17.10220","0.05679"
"205.42800","17.11918","0.05686"
"205.63200","17.13622","0.05709"
"205.83600","17.15320","0.05726"
"206.04000","17.17024","0.05744"
"206.24400","17.18722","0.05759"
"206.44800","17.20420","0.05763"
"206.65200","17.22124","0.05772"
"206.85600","17.23822","0.05799"
"207.06000","17.25514","0.05820"
"207.26400","17.27218","0.05843"
"207.46800","17.28922","0.05842"
"207.67200","17.30620","0.05842"
"207.87600","17.32324","0.05836"
"208.08000","17.34016","0.05879"
"208.28400","17.35720","0.05870"
"208.48800","17.37424","0.05914"
"208.69200","17.39116","0.05969"
"208.89600","17.40826","0.05936"
"209.10000","17.42524","0.05962"
"209.30400","17.44222","0.05914"
"209.50800","17.45926","0.05959"
"209.71200","17.47612","0.05950"
"209.91600","17.49322","0.06002"
"210.12000","17.51014","0.06015"
"210.32400","17.52724","0.06078"
"210.52800","17.54422","0.06085"
"210.73200","17.56120","0.06108"
"210.93600","17.57824","0.06095"
"211.14000","17.59522","0.06156"
"211.34400","17.61220","0.06141"
"211.54800","17.62918","0.06145"
"211.75200","17.64622","0.06220"
"211.95600","17.66320","0.06231"
"212.16000","17.68024","0.06271"
"212.36400","17.69716","0.06272"
"212.56800","17.71420","0.06336"
"212.77200","17.73124","0.06354"
"212.97600","17.74822","0.06416"
"213.18000","17.76520","0.06419"
"213.38400","17.78218","0.06459"
"213.58800","17.79922","0.06534"
"213.79200","17.81627","0.06537"
"213.99600","17.83312","0.06571"
"214.20000","17.85028","0.06618"
"214.40400","17.86715","0.06638"
"214.60800","17.88419","0.06703"
"214.81200","17.90122","0.06746"
"215.01600","17.91815","0.06738"
"215.22000","17.93525","0.06805"
"215.42400","17.95217","0.06817"
"215.62800","17.96921","0.06817"
"215.83200","17.98619","0.06817"
"216.03600","18.00317","0.06926"
"216.24000","18.02015","0.06952"
"216.44400","18.03719","0.06965"
"216.64800","18.05417","0.07004"
"216.85200","18.07127","0.07047"
"217.05600","18.08825","0.07110"
"217.26000","18.10517","0.07154"
"217.46400","18.12221","0.07215"
"217.66800","18.13925","0.07270"
"217.87200","18.15617","0.07280"
"218.07600","18.17327","0.07223"
"218.28000","18.19013","0.07282"
"218.48400","18.20723","0.07341"
"218.68800","18.22421","0.07382"
"218.89200","18.24113","0.07436"
"219.09600","18.25823","0.07488"
"219.30000","18.27521","0.07549"
"219.50400","18.29225","0.07578"
"219.70800","18.30923","0.07620"
"219.91200","18.32615","0.07665"
"220.11600","18.34325","0.07707"
"220.32000","18.36017","0.07807"
"220.52400","18.37715","0.07772"
"220.72800","18.39425","0.07822"
"220.93200","18.41117","0.07929"
"221.13600","18.42821","0.07902"
"221.34000","18.44519","0.07964"
"221.54400","18.46217","0.08023"
"221.74800","18.47921","0.08161"
"221.95200","18.49625","0.08141"
"222.15600","18.51317","0.08220"
"222.36000","18.53021","0.08288"
"222.56400","18.54713","0.08372"
"222.76800","18.56423","0.08432"
"222.97200","18.58127","0.08522"
"223.17600","18.59807","0.08621"
"223.38000","18.61529","0.08714"
"223.58400","18.63215","0.08665"
"223.78800","18.64919","0.08765"
"223.99200","18.66623","0.08822"
"224.19600","18.68315","0.08880"
"224.40000","18.70025","0.08900"
"224.60400","18.71723","0.08891"
"224.80800","18.73415","0.08955"
"225.01200","18.75125","0.09081"
"225.21600","18.76818","0.09074"
"225.42000","18.78521","0.09119"
"225.62400","18.80219","0.09165"
"225.82800","18.81917","0.09224"
"226.03200","18.83621","0.09268"
"226.23600","18.85325","0.09409"
"226.44000","18.87024","0.09383"
"226.64400","18.88721","0.09431"
"226.84800","18.90419","0.09413"
"227.05200","18.92124","0.09552"
"227.25600","18.93827","0.09457"
"227.46000","18.95519","0.09501"
"227.66400","18.97223","0.09557"
"227.86800","18.98915","0.09605"
"228.07200","19.00620","0.09632"
"228.27600","19.02318","0.09689"
"228.48000","19.04016","0.09783"
"228.68400","19.05720","0.09829"
"228.88800","19.07424","0.09766"
"229.09200","19.09116","0.09827"
"229.29600","19.10820","0.09901"
"229.50000","19.12512","0.09930"
"229.70400","19.14222","0.09958"
"229.90800","19.15926","0.10063"
"230.11200","19.17618","0.10118"
"230.31600","19.19328","0.10151"
"230.52000","19.21020","0.10201"
"230.72400","19.22718","0.10193"
"230.92800","19.24416","0.10247"
"231.13200","19.26120","0.10291"
"231.33600","19.27818","0.10326"
"231.54000","19.29528","0.10368"
"231.74400","19.31214","0.10403"
"231.94800","19.32924","0.10483"
"232.15200","19.34622","0.10555"
"232.35600","19.36314","0.10556"
"232.56000","19.38024","0.10588"
"232.76400","19.39722","0.10670"
"232.96800","19.41420","0.10740"
"233.17200","19.43124","0.10769"
"233.37600","19.44816","0.10796"
"233.58000","19.46526","0.10606"
"233.78400","19.48218","0.01485"
"233.98800","19.49922","0.01372"
"234.19200","19.51626","0.01124"
"234.39600","19.53318","0.01027"
"234.60000","19.55022","0.00921"
"234.80400","19.56720","0.00800"
"235.00800","19.58418","0.00807"
"235.21200","19.60116","0.01062"
"235.41600","19.61820","0.01171"
"235.62000","19.63518","0.00902"
"235.82400","19.65222","0.00979"
"236.02800","19.66914","0.01019"
"236.23200","19.68624","0.01057"
"236.43600","19.70322","0.01011"
"236.64000","19.72020","0.00988"
"236.84400","19.73724","0.00940"
"237.04800","19.75416","0.00943"
"237.25200","19.77120","0.01025"
"237.45600","19.78824","0.01000"
"237.66000","19.80516","0.01091"
"237.86400","19.82220","0.01058"
"238.06800","19.83918","0.00990"
"238.27200","19.85616","0.01045"
"238.47600","19.87320","0.00966"
"238.68000","19.89018","0.01016"
"238.88400","19.90722","0.01029"
"239.08800","19.92420","0.01072"
"239.29200","19.94118","0.01103"
"239.49600","19.95822","0.01022"
"239.70000","19.97520","0.01004"
"239.90400","19.99218","0.00982"
"240.10800","20.00923","0.01034"
"240.31200","20.02615","0.01013"
"240.51600","20.04325","0.01062"
"240.72000","20.06022","0.01042"
"240.92400","20.07709","0.01066"
"241.12800","20.09425","0.01048"
"241.33200","20.11122","0.01077"
"241.53600","20.12815","0.00976"
"241.74000","20.14524","0.01020"
"241.94400","20.16222","0.01032"
"242.14800","20.17921","0.01017"
"242.35200","20.19624","0.01100"
"242.55600","20.21311","0.01097"
"242.76000","20.23026","0.01039"
"242.96400","20.24719","0.01046"
"243.16800","20.26423","0.01054"
"243.37200","20.28127","0.01048"
"243.57600","20.29813","0.01061"
"243.78000","20.31523","0.01064"
"243.98400","20.33221","0.01100"
"244.18800","20.34919","0.01056"
"244.39200","20.36623","0.01073"
"244.59600","20.38321","0.01133"
"244.80000","20.40019","0.01048"
"245.00400","20.41717","0.01093"
"245.20800","20.43415","0.01078"
"245.41200","20.45119","0.01118"
"245.61600","20.46823","0.01034"
"245.82000","20.48521","0.01067"
"246.02400","20.50225","0.01139"
"246.22800","20.51917","0.01112"
"246.43200","20.53621","0.01082"
"246.63600","20.55319","0.01078"
"246.84000","20.57017","0.01083"
"247.04400","20.58727","0.01098"
"247.24800","20.60419","0.01112"
"247.45200","20.62117","0.01124"
"247.65600","20.63827","0.01099"
"247.86000","20.65513","0.01117"
"248.06400","20.67229","0.01082"
"248.26800","20.68915","0.01095"
"248.47200","20.70619","0.01162"
"248.67600","20.72317","0.01145"
"248.88000","20.74015","0.01088"
"249.08400","20.75719","0.01095"
"249.28800","20.77423","0.01027"
"249.49200","20.79115","0.01096"
"249.69600","20.80831","0.01066"
"249.90000","20.82523","0.01036"
"250.10400","20.84215","0.01109"
"250.30800","20.85919","0.01050"
"250.51200","20.87623","0.01111"
"250.71600","20.89315","0.01108"
"250.92000","20.91025","0.01072"
"251.12400","20.92711","0.01093"
"251.32800","20.94421","0.01116"
"251.53200","20.96119","0.01100"
"251.73600","20.97817","0.01081"
"251.94000","20.99527","0.01131"
"252.14400","21.01219","0.01067"
"252.34800","21.02923","0.01012"
"252.55200","21.04622","0.01086"
"252.75600","21.06314","0.01045"
"252.96000","21.08023","0.01043"
"253.16400","21.09722","0.01105"
"253.36800","21.11420","0.01071"
"253.57200","21.13124","0.01075"
"253.77600","21.14816","0.01117"
"253.98000","21.16525","0.01087"
"254.18400","21.18218","0.01095"
"254.38800","21.19921","0.01055"
"254.59200","21.21620","0.01111"
"254.79600","21.23318","0.01108"
"255.00000","21.25016","0.01090"
"255.20400","21.26720","0.01072"
"255.40800","21.28418","0.01069"
"255.61200","21.30122","0.01037"
"255.81600","21.31825","0.01134"
"256.02000","21.33518","0.01108"
"256.22400","21.35222","0.01058"
"256.42800","21.36920","0.01156"
"256.63200","21.38624","0.01081"
"256.83600","21.40322","0.00979"
"257.04000","21.42014","0.01044"
"257.24400","21.43724","0.01054"
"257.44800","21.45422","0.01078"
"257.65200","21.47120","0.01037"
"257.85600","21.48824","0.01078"
"258.06000","21.50516","0.01072"
"258.26400","21.52226","0.01066"
"258.46800","21.53924","0.01115"
"258.67200","21.55616","0.01039"
"258.87600","21.57320","0.01162"
"259.08000","21.59018","0.01091"
"259.28400","21.60722","0.01097"
"259.48800","21.62420","0.01081"
"259.69200","21.64118","0.01117"
"259.89600","21.65822","0.01101"
"260.10000","21.67526","0.01180"
"260.30400","21.69218","0.01095"
"260.50800","21.70916","0.01055"
"260.71200","21.72620","0.01086"
"260.91600","21.74318","0.01119"
"261.12000","21.76022","0.01146"
"261.32400","21.77714","0.01084"
"261.52800","21.79424","0.01112"
"261.73200","21.81122","0.01130"
"261.93600","21.82814","0.01124"
"262.14000","21.84524","0.01056"
"262.34400","21.86222","0.01067"
"262.54800","21.87920","0.01070"
"262.75200","21.89624","0.01113"
"262.95600","21.91316","0.01110"
"263.16000","21.93026","0.01128"
"263.36400","21.94718","0.01060"
"263.56800","21.96422","0.01084"
"263.77200","21.98120","0.01081"
"263.97600","21.99818","0.01098"
"264.18000","22.01516","0.01188"
"264.38400","22.03221","0.01066"
"264.58800","22.04913","0.01110"
"264.79200","22.06623","0.01101"
"264.99600","22.08320","0.01039"
"265.20000","22.10025","0.01131"
"265.40400","22.11723","0.01057"
"265.60800","22.13415","0.01114"
"265.81200","22.15125","0.01079"
"266.01600","22.16822","0.01077"
"266.22000","22.18515","0.01082"
"266.42400","22.20225","0.01092"
"266.62800","22.21917","0.01104"
"266.83200","22.23620","0.01065"
"267.03600","22.25325","0.01063"
"267.24000","22.27017","0.01116"
"267.44400","22.28727","0.01102"
"267.64800","22.30419","0.01141"
"267.85200","22.32122","0.01103"
"268.05600","22.33821","0.01070"
"268.26000","22.35519","0.01104"
"268.46400","22.37217","0.01137"
"268.66800","22.38921","0.01125"
"268.87200","22.40619","0.01105"
"269.07600","22.42323","0.01131"
"269.28000","22.44021","0.01094"
"269.48400","22.45719","0.01244"
"269.68800","22.47423","0.01195"
"269.89200","22.49115","0.01154"
"270.09600","22.50825","0.01130"
"270.30000","22.52523","0.01099"
"270.50400","22.54221","0.01157"
"270.70800","22.55919","0.01076"
"270.91200","22.57617","0.01131"
"271.11600","22.59315","0.01110"
"271.32000","22.61025","0.01161"
"271.52400","22.62717","0.01105"
"271.72800","22.64427","0.01083"
"271.93200","22.66113","0.01178"
"272.13600","22.67811","0.01127"
"272.34000","22.69521","0.01122"
"272.54400","22.71213","0.01114"
"272.74800","22.72923","0.01164"
"272.95200","22.74621","0.01101"
"273.15600","22.76319","0.01140"
"273.36000","22.78023","0.01154"
"273.56400","22.79721","0.01162"
"273.76800","22.81419","0.01174"
"273.97200","22.83123","0.01151"
"274.17600","22.84821","0.01176"
"274.38000","22.86525","0.01139"
"274.58400","22.88223","0.01189"
"274.78800","22.89915","0.01132"
"274.99200","22.91619","0.01107"
"275.19600","22.93323","0.01117"
"275.40000","22.95015","0.01205"
"275.60400","22.96725","0.01172"
"275.80800","22.98417","0.01172"
"276.01200","23.00121","0.01133"
"276.21600","23.01825","0.01114"
"276.42000","23.03511","0.01183"
"276.62400","23.05227","0.01198"
"276.82800","23.06919","0.01149"
"277.03200","23.08624","0.01129"
"277.23600","23.10321","0.01138"
"277.44000","23.12020","0.01165"
"277.64400","23.13717","0.01136"
"277.84800","23.15421","0.01158"
"278.05200","23.17120","0.01137"
"278.25600","23.18817","0.01207"
"278.46000","23.20515","0.01160"
"278.66400","23.22219","0.01161"
"278.86800","23.23918","0.01201"
"279.07200","23.25622","0.01196"
"279.27600","23.27319","0.01142"
"279.48000","23.29024","0.01167"
"279.68400","23.30716","0.01159"
"279.88800","23.32420","0.01188"
"280.09200","23.34118","0.01122"
"280.29600","23.35822","0.01180"
"280.50000","23.37519","0.01191"
"280.70400","23.39218","0.01172"
"280.90800","23.40928","0.01200"
"281.11200","23.42620","0.01245"
"281.31600","23.44318","0.01151"
"281.52000","23.46022","0.01194"
"281.72400","23.47720","0.01201"
"281.92800","23.49424","0.01187"
"282.13200","23.51128","0.01149"
"282.33600","23.52820","0.01130"
"282.54000","23.54524","0.01116"
"282.74400","23.56216","0.01193"
"282.94800","23.57920","0.01177"
"283.15200","23.59624","0.01230"
"283.35600","23.61322","0.01184"
"283.56000","23.63026","0.01142"
"283.76400","23.64724","0.01175"
"283.96800","23.66410","0.01156"
"284.17200","23.68126","0.01183"
"284.37600","23.69824","0.01142"
"284.58000","23.71516","0.01202"
"284.78400","23.73226","0.01163"
"284.98800","23.74912","0.01208"
"285.19200","23.76622","0.01110"
"285.39600","23.78320","0.01224"
"285.60000","23.80018","0.01187"
"285.80400","23.81722","0.01173"
"286.00800","23.83420","0.01143"
"286.21200","23.85118","0.01196"
"286.41600","23.86822","0.01131"
"286.62000","23.88514","0.01191"
"286.82400","23.90224","0.01144"
"287.02800","23.91922","0.01158"
"287.23200","23.93620","0.01197"
"287.43600","23.95318","0.01159"
"287.64000","23.97022","0.01179"
"287.84400","23.98720","0.01157"
"288.04800","24.00418","0.01227"
"288.25200","24.02122","0.01192"
"288.45600","24.03820","0.01234"
"288.66000","24.05524","0.01177"
"288.86400","24.07222","0.01162"
"289.06800","24.08920","0.01183"
"289.27200","24.10618","0.01117"
"289.47600","24.12322","0.01179"
"289.68000","24.14020","0.01208"
"289.88400","24.15718","0.01177"
"290.08800","24.17422","0.01179"
"290.29200","24.19120","0.01148"
"290.49600","24.20819","0.01203"
"290.70000","24.22528","0.01158"
"290.90400","24.24214","0.01118"
"291.10800","24.25924","0.01178"
"291.31200","24.27622","0.01189"
"291.51600","24.29314","0.01151"
"291.72000","24.31018","0.01141"
"291.92400","24.32717","0.01211"
"292.12800","24.34420","0.01153"
"292.33200","24.36125","0.01253"
"292.53600","24.37823","0.01193"
"292.74000","24.39527","0.01219"
"292.94400","24.41225","0.01205"
"293.14800","24.42917","0.01182"
"293.35200","24.44627","0.01210"
"293.55600","24.46319","0.01161"
"293.76000","24.48017","0.01171"
"293.96400","24.49721","0.01242"
"294.16800","24.51413","0.01187"
"294.37200","24.53123","0.01157"
"294.57600","24.54821","0.01180"
"294.78000","24.56519","0.01200"
"294.98400","24.58229","0.01231"
"295.18800","24.59921","0.01253"
"295.39200","24.61619","0.01206"
"295.59600","24.63323","0.01241"
"295.80000","24.65009","0.01238"
"296.00400","24.66725","0.01235"
"296.20800","24.68417","0.01183"
"296.41200","24.70121","0.01208"
"296.61600","24.71825","0.01247"
"296.82000","24.73523","0.01215"
"297.02400","24.75227","0.01220"
"297.22800","24.76919","0.01241"
"297.43200","24.78617","0.01202"
"297.63600","24.80321","0.01215"
"297.84000","24.82019","0.01216"
"298.04400","24.83717","0.01194"
"298.24800","24.85421","0.01214"
"298.45200","24.87119","0.01159"
"298.65600","24.88823","0.01207"
"298.86000","24.90527","0.01247"
"299.06400","24.92219","0.01224"
"299.26800","24.93923","0.01212"
"299.47200","24.95615","0.01222"
"299.67600","24.97319","0.01246"
"299.85600","24.98826","0.01190"