File: Force_trajectories/170226_3/Specimen_RawData_3.csv
End date,"2/26/2017"
Specimen label,"7CG_52"
Maximum Load,"0.04258",N

Time,Extension,Load
(s),(mm),(N)
"0.00000","0.00000","-0.00034"
"0.44400","0.03731","0.00049"
"0.88800","0.07420","0.00100"
"1.33200","0.11121","0.00168"
"1.77600","0.14828","0.00223"
"2.22000","0.18529","0.00147"
"2.66400","0.22218","0.00175"
"3.10800","0.25919","0.00258"
"3.55200","0.29614","0.00263"
"3.99600","0.33321","0.00314"
"4.44000","0.37028","0.00343"
"4.88400","0.40729","0.00341"
"5.32800","0.44424","0.00399"
"5.77200","0.48119","0.00435"
"6.21600","0.51826","0.00443"
"6.66000","0.55521","0.00474"
"7.10400","0.59222","0.00451"
"7.54800","0.62923","0.00483"
"7.99200","0.66623","0.00551"
"8.43600","0.70318","0.00477"
"8.88000","0.74019","0.00553"
"9.32400","0.77720","0.00545"
"9.76800","0.81421","0.00619"
"10.21200","0.85128","0.00660"
"10.65600","0.88823","0.00651"
"11.10000","0.92524","0.00666"
"11.54400","0.96225","0.00763"
"11.98800","0.99926","0.00678"
"12.43200","1.03621","0.00755"
"12.87600","1.07322","0.00808"
"13.32000","1.11017","0.00722"
"13.76400","1.14718","0.00797"
"14.20800","1.18419","0.00820"
"14.65200","1.22120","0.00816"
"15.09600","1.25827","0.00874"
"15.54000","1.29522","0.00867"
"15.98400","1.33211","0.00884"
"16.42800","1.36918","0.00864"
"16.87200","1.40619","0.00914"
"17.31600","1.44320","0.00880"
"17.76000","1.48027","0.00961"
"18.20400","1.51716","0.01071"
"18.64800","1.55417","0.01045"
"19.09200","1.59118","0.01066"
"19.53600","1.62825","0.01045"
"19.98000","1.66526","0.01045"
"20.42400","1.70221","0.01145"
"20.86800","1.73922","0.01122"
"21.31200","1.77623","0.01137"
"21.75600","1.81324","0.01152"
"22.20000","1.85025","0.01184"
"22.64400","1.88720","0.01130"
"23.08800","1.92421","0.01190"
"23.53200","1.96116","0.01158"
"23.97600","1.99823","0.01195"
"24.42000","2.03524","0.01221"
"24.86400","2.07225","0.01186"
"25.30800","2.10931","0.01276"
"25.75200","2.14621","0.01228"
"26.19600","2.18315","0.01251"
"26.64000","2.22022","0.01298"
"27.08400","2.25723","0.01232"
"27.52800","2.29430","0.01291"
"27.97200","2.33119","0.01296"
"28.41600","2.36820","0.01324"
"28.86000","2.40515","0.01264"
"29.30400","2.44222","0.01242"
"29.74800","2.47923","0.01257"
"30.19200","2.51624","0.01242"
"30.63600","2.55325","0.01205"
"31.08000","2.59020","0.01321"
"31.52400","2.62721","0.01249"
"31.96800","2.66416","0.01247"
"32.41200","2.70123","0.01307"
"32.85600","2.73824","0.01327"
"33.30000","2.77525","0.01350"
"33.74400","2.81220","0.01356"
"34.18800","2.84921","0.01421"
"34.63200","2.88628","0.01478"
"35.07600","2.92323","0.01443"
"35.52000","2.96024","0.01400"
"35.96400","2.99719","0.01420"
"36.40800","3.03414","0.01446"
"36.85200","3.07121","0.01447"
"37.29600","3.10822","0.01463"
"37.74000","3.14523","0.01530"
"38.18400","3.18224","0.01500"
"38.62800","3.21919","0.01501"
"39.07200","3.25620","0.01523"
"39.51600","3.29327","0.01548"
"39.96000","3.33028","0.01530"
"40.40400","3.36729","0.01505"
"40.84800","3.40418","0.01535"
"41.29200","3.44119","0.01539"
"41.73600","3.47814","0.01588"
"42.18000","3.51521","0.01502"
"42.62400","3.55222","0.01529"
"43.06800","3.58929","0.01562"
"43.51200","3.62624","0.01527"
"43.95600","3.66313","0.01400"
"44.40000","3.70019","0.01494"
"44.84400","3.73720","0.01535"
"45.28800","3.77421","0.01472"
"45.73200","3.81122","0.01367"
"46.17600","3.84817","0.01439"
"46.62000","3.88518","0.01465"
"47.06400","3.92219","0.01492"
"47.50800","3.95920","0.01564"
"47.95200","3.99627","0.01483"
"48.39600","4.03322","0.01521"
"48.84000","4.07023","0.01542"
"49.28400","4.10718","0.01578"
"49.72800","4.14419","0.01569"
"50.17200","4.18126","0.01617"
"50.61600","4.21827","0.01518"
"51.06000","4.25522","0.01585"
"51.50400","4.29217","0.01555"
"51.94800","4.32924","0.01604"
"52.39200","4.36625","0.01581"
"52.83600","4.40326","0.01522"
"53.28000","4.44027","0.01562"
"53.72400","4.47716","0.01577"
"54.16800","4.51417","0.01516"
"54.61200","4.55118","0.01496"
"55.05600","4.58825","0.01509"
"55.50000","4.62520","0.01603"
"55.94400","4.66227","0.01582"
"56.38800","4.69922","0.01583"
"56.83200","4.73617","0.01634"
"57.27600","4.77324","0.01612"
"57.72000","4.81025","0.01623"
"58.16400","4.84726","0.01666"
"58.60800","4.88421","0.01653"
"59.05200","4.92116","0.01728"
"59.49600","4.95823","0.01756"
"59.94000","4.99524","0.01779"
"60.38400","5.03219","0.01755"
"60.82800","5.06926","0.01853"
"61.27200","5.10620","0.01809"
"61.71600","5.14316","0.01782"
"62.16000","5.18023","0.01871"
"62.60400","5.21729","0.01876"
"63.04800","5.25424","0.01847"
"63.49200","5.29119","0.01914"
"63.93600","5.32820","0.01961"
"64.38000","5.36521","0.01911"
"64.82400","5.40222","0.01955"
"65.26800","5.43917","0.01882"
"65.71200","5.47618","0.01837"
"66.15600","5.51325","0.01875"
"66.60000","5.55014","0.01924"
"67.04400","5.58721","0.01865"
"67.48800","5.62422","0.01892"
"67.93200","5.66129","0.01905"
"68.37600","5.69830","0.01990"
"68.82000","5.73519","0.02005"
"69.26400","5.77220","0.01999"
"69.70800","5.80921","0.01998"
"70.15200","5.84622","0.01998"
"70.59600","5.88323","0.01962"
"71.04000","5.92024","0.02022"
"71.48400","5.95719","0.02003"
"71.92800","5.99420","0.01974"
"72.37200","6.03127","0.02010"
"72.81600","6.06828","0.02147"
"73.26000","6.10523","0.02055"
"73.70400","6.14224","0.02129"
"74.14800","6.17919","0.02136"
"74.59200","6.21620","0.02111"
"75.03600","6.25321","0.02118"
"75.48000","6.29022","0.01994"
"75.92400","6.32723","0.02013"
"76.36800","6.36424","0.02068"
"76.81200","6.40113","0.02089"
"77.25600","6.43820","0.02007"
"77.70000","6.47527","0.02029"
"78.14400","6.51222","0.01938"
"78.58800","6.54929","0.02010"
"79.03200","6.58618","0.02033"
"79.47600","6.62313","0.02040"
"79.92000","6.66019","0.02054"
"80.36400","6.69721","0.02040"
"80.80800","6.73421","0.02089"
"81.25200","6.77128","0.02084"
"81.69600","6.80823","0.02067"
"82.14000","6.84518","0.02068"
"82.58400","6.88219","0.02122"
"83.02800","6.91926","0.02182"
"83.47200","6.95621","0.02154"
"83.91600","6.99322","0.02180"
"84.36000","7.03017","0.02163"
"84.80400","7.06718","0.02191"
"85.24800","7.10425","0.02251"
"85.69200","7.14120","0.02259"
"86.13600","7.17827","0.02330"
"86.58000","7.21528","0.02289"
"87.02400","7.25217","0.02385"
"87.46800","7.28918","0.02378"
"87.91200","7.32625","0.02340"
"88.35600","7.36326","0.02308"
"88.80000","7.40021","0.02350"
"89.24400","7.43716","0.02316"
"89.68800","7.47417","0.02363"
"90.13200","7.51124","0.02312"
"90.57600","7.54825","0.02412"
"91.02000","7.58526","0.02412"
"91.46400","7.62227","0.02449"
"91.90800","7.65922","0.02430"
"92.35200","7.69623","0.02459"
"92.79600","7.73318","0.02391"
"93.24000","7.77025","0.02435"
"93.68400","7.80726","0.02536"
"94.12800","7.84421","0.02501"
"94.57200","7.88116","0.02477"
"95.01600","7.91823","0.02535"
"95.46000","7.95524","0.02545"
"95.90400","7.99225","0.02571"
"96.34800","8.02926","0.02552"
"96.79200","8.06615","0.02533"
"97.23600","8.10316","0.02638"
"97.68000","8.14023","0.02488"
"98.12400","8.17723","0.02488"
"98.56800","8.21418","0.02526"
"99.01200","8.25119","0.02580"
"99.45600","8.28820","0.02605"
"99.90000","8.32521","0.02527"
"100.34400","8.36228","0.02325"
"100.78800","8.39923","0.02325"
"101.23200","8.43624","0.02330"
"101.67600","8.47325","0.02420"
"102.12000","8.51014","0.02452"
"102.56400","8.54721","0.02485"
"103.00800","8.58416","0.02425"
"103.45200","8.62123","0.02555"
"103.89600","8.65824","0.02494"
"104.34000","8.69525","0.02616"
"104.78400","8.73220","0.02651"
"105.22800","8.76915","0.02646"
"105.67200","8.80622","0.02653"
"106.11600","8.84323","0.02674"
"106.56000","8.88024","0.02717"
"107.00400","8.91719","0.02559"
"107.44800","8.95414","0.02670"
"107.89200","8.99115","0.02704"
"108.33600","9.02822","0.02714"
"108.78000","9.06523","0.02736"
"109.22400","9.10224","0.02707"
"109.66800","9.13925","0.02733"
"110.11200","9.17620","0.02760"
"110.55600","9.21327","0.02729"
"111.00000","9.25022","0.02766"
"111.44400","9.28723","0.02760"
"111.88800","9.32424","0.02738"
"112.33200","9.36113","0.02774"
"112.77600","9.39820","0.02761"
"113.22000","9.43521","0.02743"
"113.66400","9.47222","0.02696"
"114.10800","9.50923","0.02644"
"114.55200","9.54624","0.02654"
"114.99600","9.58325","0.02645"
"115.44000","9.62026","0.02685"
"115.88400","9.65727","0.02627"
"116.32800","9.69421","0.02578"
"116.77200","9.73128","0.02632"
"117.21600","9.76823","0.02770"
"117.66000","9.80518","0.02699"
"118.10400","9.84219","0.02678"
"118.54800","9.87926","0.02700"
"118.99200","9.91627","0.02747"
"119.43600","9.95328","0.02660"
"119.88000","9.99017","0.02716"
"120.32400","10.02718","0.02725"
"120.76800","10.06419","0.02688"
"121.21200","10.10126","0.02759"
"121.65600","10.13821","0.02779"
"122.10000","10.17516","0.02830"
"122.54400","10.21217","0.02844"
"122.98800","10.24918","0.02831"
"123.43200","10.28625","0.02900"
"123.87600","10.32326","0.02827"
"124.32000","10.36021","0.02875"
"124.76400","10.39722","0.02885"
"125.20800","10.43417","0.02834"
"125.65200","10.47118","0.02811"
"126.09600","10.50825","0.02891"
"126.54000","10.54520","0.02781"
"126.98400","10.58221","0.02827"
"127.42800","10.61922","0.02917"
"127.87200","10.65617","0.02855"
"128.31600","10.69324","0.02909"
"128.76000","10.73025","0.02897"
"129.20400","10.76726","0.02933"
"129.64800","10.80421","0.02998"
"130.09200","10.84116","0.03048"
"130.53600","10.87823","0.03078"
"130.98000","10.91518","0.03069"
"131.42400","10.95219","0.03086"
"131.86800","10.98920","0.03168"
"132.31200","11.02621","0.03105"
"132.75600","11.06322","0.03159"
"133.20000","11.10023","0.03213"
"133.64400","11.13724","0.03250"
"134.08800","11.17425","0.03328"
"134.53200","11.21132","0.03306"
"134.97600","11.24821","0.03210"
"135.42000","11.28515","0.03242"
"135.86400","11.32216","0.03308"
"136.30800","11.35923","0.03294"
"136.75200","11.39624","0.03326"
"137.19600","11.43325","0.03191"
"137.64000","11.47020","0.03320"
"138.08400","11.50721","0.03279"
"138.52800","11.54428","0.03337"
"138.97200","11.58123","0.03456"
"139.41600","11.61824","0.03409"
"139.86000","11.65519","0.03398"
"140.30400","11.69214","0.03455"
"140.74800","11.72921","0.03130"
"141.19200","11.76628","0.02612"
"141.63600","11.80323","0.02613"
"142.08000","11.84024","0.02665"
"142.52400","11.87725","0.02615"
"142.96800","11.91426","0.02622"
"143.41200","11.95121","0.02620"
"143.85600","11.98822","0.02685"
"144.30000","12.02517","0.02732"
"144.74400","12.06224","0.02781"
"145.18800","12.09925","0.02705"
"145.63200","12.13620","0.02669"
"146.07600","12.17321","0.02769"
"146.52000","12.21028","0.02780"
"146.96400","12.24729","0.02828"
"147.40800","12.28424","0.02863"
"147.85200","12.32119","0.02920"
"148.29600","12.35814","0.02926"
"148.74000","12.39527","0.02877"
"149.18400","12.43228","0.02920"
"149.62800","12.46923","0.02962"
"150.07200","12.50618","0.03055"
"150.51600","12.54313","0.03085"
"150.96000","12.58020","0.03093"
"151.40400","12.61721","0.03175"
"151.84800","12.65428","0.03251"
"152.29200","12.69129","0.03230"
"152.73600","12.72824","0.03286"
"153.18000","12.76519","0.03289"
"153.62400","12.80225","0.03332"
"154.06800","12.83926","0.03394"
"154.51200","12.87621","0.03335"
"154.95600","12.91322","0.03428"
"155.40000","12.95012","0.03446"
"155.84400","12.98718","0.03477"
"156.28800","13.02425","0.03469"
"156.73200","13.06126","0.03574"
"157.17600","13.09827","0.03624"
"157.62000","13.13522","0.03372"
"158.06400","13.17217","0.03184"
"158.50800","13.20924","0.03284"
"158.95200","13.24619","0.03386"
"159.39600","13.28320","0.03486"
"159.84000","13.32021","0.03438"
"160.28400","13.35722","0.03441"
"160.72800","13.39417","0.03413"
"161.17200","13.43124","0.03454"
"161.61600","13.46825","0.03479"
"162.06000","13.50520","0.03537"
"162.50400","13.54227","0.03607"
"162.94800","13.57916","0.03273"
"163.39200","13.61617","0.03192"
"163.83600","13.65318","0.03248"
"164.28000","13.69025","0.03337"
"164.72400","13.72726","0.03297"
"165.16800","13.76415","0.03296"
"165.61200","13.80116","0.03349"
"166.05600","13.83817","0.03406"
"166.50000","13.87524","0.03307"
"166.94400","13.91225","0.03317"
"167.38800","13.94920","0.03370"
"167.83200","13.98621","0.03344"
"168.27600","14.02316","0.03269"
"168.72000","14.06017","0.03208"
"169.16400","14.09724","0.02283"
"169.60800","14.13424","0.02276"
"170.05200","14.17126","0.02195"
"170.49600","14.20821","0.02238"
"170.94000","14.24522","0.02210"
"171.38400","14.28222","0.02173"
"171.82800","14.31923","0.02227"
"172.27200","14.35624","0.02343"
"172.71600","14.39326","0.02400"
"173.16000","14.43020","0.02491"
"173.60400","14.46721","0.02509"
"174.04800","14.50422","0.02520"
"174.49200","14.54123","0.02512"
"174.93600","14.57824","0.02537"
"175.38000","14.61525","0.02504"
"175.82400","14.65220","0.02526"
"176.26800","14.68921","0.02482"
"176.71200","14.72622","0.02510"
"177.15600","14.76323","0.02605"
"177.60000","14.80024","0.02641"
"178.04400","14.83719","0.02619"
"178.48800","14.87414","0.02641"
"178.93200","14.91115","0.02279"
"179.37600","14.94828","0.02163"
"179.82000","14.98523","0.02173"
"180.26400","15.02230","0.02106"
"180.70800","15.05925","0.02167"
"181.15200","15.09620","0.02167"
"181.59600","15.13321","0.02220"
"182.04000","15.17022","0.02216"
"182.48400","15.20723","0.02285"
"182.92800","15.24418","0.02312"
"183.37200","15.28113","0.02372"
"183.81600","15.31820","0.02321"
"184.26000","15.35521","0.02445"
"184.70400","15.39222","0.02468"
"185.14800","15.42923","0.02472"
"185.59200","15.46624","0.02434"
"186.03600","15.50319","0.02457"
"186.48000","15.54020","0.02401"
"186.92400","15.57721","0.02444"
"187.36800","15.61422","0.02397"
"187.81200","15.65123","0.02393"
"188.25600","15.68818","0.02454"
"188.70000","15.72518","0.02514"
"189.14400","15.76219","0.02444"
"189.58800","15.79926","0.02478"
"190.03200","15.83627","0.02450"
"190.47600","15.87322","0.02447"
"190.92000","15.91017","0.02483"
"191.36400","15.94712","0.02338"
"191.80800","15.98419","0.02289"
"192.25200","16.02126","0.02213"
"192.69600","16.05821","0.02273"
"193.14000","16.09522","0.02302"
"193.58400","16.13217","0.02341"
"194.02800","16.16918","0.02274"
"194.47200","16.20619","0.02321"
"194.91600","16.24326","0.02258"
"195.36000","16.28027","0.02305"
"195.80400","16.31722","0.02277"
"196.24800","16.35417","0.02312"
"196.69200","16.39124","0.02372"
"197.13600","16.42825","0.02397"
"197.58000","16.46520","0.02384"
"198.02400","16.50221","0.02336"
"198.46800","16.53922","0.02389"
"198.91200","16.57617","0.02448"
"199.35600","16.61324","0.02436"
"199.80000","16.65025","0.02463"
"200.24400","16.68726","0.02495"
"200.68800","16.72421","0.02492"
"201.13200","16.76122","0.02505"
"201.57600","16.79823","0.02575"
"202.02000","16.83518","0.02605"
"202.46400","16.87225","0.02671"
"202.90800","16.90926","0.02603"
"203.35200","16.94621","0.02557"
"203.79600","16.98322","0.02545"
"204.24000","17.02023","0.02537"
"204.68400","17.05724","0.02549"
"205.12800","17.09425","0.02485"
"205.57200","17.13126","0.02549"
"206.01600","17.16821","0.02637"
"206.46000","17.20515","0.02671"
"206.90400","17.24216","0.02686"
"207.34800","17.27923","0.02725"
"207.79200","17.31624","0.02702"
"208.23600","17.35319","0.02702"
"208.68000","17.39021","0.02708"
"209.12400","17.42721","0.02723"
"209.56800","17.46422","0.02733"
"210.01200","17.50123","0.02687"
"210.45600","17.53818","0.02725"
"210.90000","17.57525","0.02774"
"211.34400","17.61214","0.02748"
"211.78800","17.64921","0.02810"
"212.23200","17.68616","0.02838"
"212.67600","17.72323","0.02896"
"213.12000","17.76024","0.02842"
"213.56400","17.79719","0.02570"
"214.00800","17.83414","0.02668"
"214.45200","17.87121","0.02670"
"214.89600","17.90816","0.02243"
"215.34000","17.94517","0.02362"
"215.78400","17.98224","0.02343"
"216.22800","18.01919","0.02416"
"216.67200","18.05620","0.02442"
"217.11600","18.09321","0.02458"
"217.56000","18.13028","0.02557"
"218.00400","18.16723","0.02609"
"218.44800","18.20424","0.02676"
"218.89200","18.24119","0.02580"
"219.33600","18.27820","0.02667"
"219.78000","18.31521","0.02759"
"220.22400","18.35222","0.02775"
"220.66800","18.38923","0.02815"
"221.11200","18.42624","0.02886"
"221.55600","18.46319","0.02862"
"222.00000","18.50020","0.02986"
"222.44400","18.53727","0.03017"
"222.88800","18.57428","0.03011"
"223.33200","18.61129","0.03100"
"223.77600","18.64818","0.03109"
"224.22000","18.68519","0.03072"
"224.66400","18.72219","0.03048"
"225.10800","18.75921","0.03125"
"225.55200","18.79622","0.03139"
"225.99600","18.83316","0.03159"
"226.44000","18.87017","0.03190"
"226.88400","18.90718","0.03256"
"227.32800","18.94425","0.03226"
"227.77200","18.98126","0.03329"
"228.21600","19.01827","0.03329"
"228.66000","19.05522","0.03442"
"229.10400","19.09217","0.03399"
"229.54800","19.12924","0.03446"
"229.99200","19.16619","0.03478"
"230.43600","19.20320","0.03500"
"230.88000","19.24021","0.03570"
"231.32400","19.27722","0.02356"
"231.76800","19.31417","0.02412"
"232.21200","19.35124","0.02501"
"232.65600","19.38825","0.02576"
"233.10000","19.42520","0.02661"
"233.54400","19.46227","0.02666"
"233.98800","19.49916","0.02739"
"234.43200","19.53617","0.02721"
"234.87600","19.57318","0.02839"
"235.32000","19.61025","0.02829"
"235.76400","19.64720","0.02819"
"236.20800","19.68421","0.02837"
"236.65200","19.72122","0.02881"
"237.09600","19.75823","0.02948"
"237.54000","19.79524","0.02985"
"237.98400","19.83225","0.03005"
"238.42800","19.86926","0.03089"
"238.87200","19.90621","0.03087"
"239.31600","19.94316","0.03107"
"239.76000","19.98017","0.03143"
"240.20400","20.01723","0.03193"
"240.64800","20.05424","0.03232"
"241.09200","20.09126","0.03379"
"241.53600","20.12827","0.03373"
"241.98000","20.16516","0.03344"
"242.42400","20.20222","0.03376"
"242.86800","20.23923","0.03370"
"243.31200","20.27619","0.03450"
"243.75600","20.31326","0.03522"
"244.20000","20.35015","0.03465"
"244.64400","20.38721","0.03545"
"245.08800","20.42422","0.03607"
"245.53200","20.46123","0.03602"
"245.97600","20.49824","0.03702"
"246.42000","20.53525","0.03706"
"246.86400","20.57220","0.03713"
"247.30800","20.60921","0.03794"
"247.75200","20.64616","0.03839"
"248.19600","20.68323","0.03884"
"248.64000","20.72024","0.03882"
"249.08400","20.75719","0.03915"
"249.52800","20.79420","0.04011"
"249.97200","20.83115","0.04051"
"250.41600","20.86822","0.04106"
"250.86000","20.90523","0.04114"
"251.30400","20.94224","0.04198"
"251.74800","20.97925","0.04187"
"252.19200","21.01614","0.01783"
"252.63600","21.05321","0.00540"
"253.08000","21.09022","0.00280"
"253.52400","21.12717","0.00502"
"253.96800","21.16418","0.00322"
"254.41200","21.20113","0.00333"
"254.85600","21.23820","0.00509"
"255.30000","21.27521","0.00360"
"255.74400","21.31222","0.00427"
"256.18800","21.34929","0.00416"
"256.63200","21.38624","0.00495"
"257.07600","21.42319","0.00427"
"257.52000","21.46020","0.00506"
"257.96400","21.49721","0.00415"
"258.40800","21.53422","0.00458"
"258.85200","21.57123","0.00441"
"259.29600","21.60818","0.00546"
"259.74000","21.64524","0.00500"
"260.18400","21.68220","0.00539"
"260.62800","21.71926","0.00475"
"261.07200","21.75621","0.00543"
"261.51600","21.79323","0.00525"
"261.96000","21.83018","0.00571"
"262.40400","21.86719","0.00556"
"262.84800","21.90425","0.00607"
"263.29200","21.94121","0.00606"
"263.73600","21.97821","0.00671"
"264.18000","22.01522","0.00571"
"264.62400","22.05217","0.00646"
"265.06800","22.08918","0.00647"
"265.51200","22.12625","0.00616"
"265.95600","22.16326","0.00663"
"266.40000","22.20027","0.00621"
"266.84400","22.23722","0.00707"
"267.28800","22.27417","0.00581"
"267.73200","22.31118","0.00573"
"268.17600","22.34819","0.00578"
"268.62000","22.38526","0.00546"
"269.06400","22.42221","0.00602"
"269.50800","22.45922","0.00590"
"269.95200","22.49623","0.00541"
"270.39600","22.53318","0.00612"
"270.84000","22.57025","0.00574"
"271.28400","22.60720","0.00604"
"271.72800","22.64427","0.00616"
"272.17200","22.68116","0.00627"
"272.61600","22.71823","0.00590"
"273.06000","22.75518","0.00576"
"273.50400","22.79225","0.00611"
"273.94800","22.82920","0.00595"
"274.39200","22.86627","0.00607"
"274.83600","22.90322","0.00639"
"275.28000","22.94023","0.00610"
"275.72400","22.97724","0.00628"
"276.16800","23.01419","0.00651"
"276.61200","23.05126","0.00638"
"277.05600","23.08815","0.00619"
"277.50000","23.12516","0.00672"
"277.94400","23.16223","0.00639"
"278.38800","23.19924","0.00684"
"278.83200","23.23625","0.00644"
"279.27600","23.27326","0.00639"
"279.72000","23.31021","0.00659"
"280.16400","23.34722","0.00616"
"280.60800","23.38422","0.00663"
"281.05200","23.42124","0.00656"
"281.49600","23.45824","0.00576"
"281.94000","23.49525","0.00571"
"282.38400","23.53220","0.00555"
"282.82800","23.56915","0.00610"
"283.27200","23.60622","0.00546"
"283.71600","23.64323","0.00671"
"284.16000","23.68024","0.00601"
"284.60400","23.71725","0.00620"
"285.04800","23.75414","0.00597"
"285.49200","23.79121","0.00588"
"285.93600","23.82822","0.00650"
"286.38000","23.86523","0.00634"
"286.82400","23.90224","0.00647"
"287.26800","23.93919","0.00641"
"287.71200","23.97620","0.00696"
"288.15600","24.01321","0.00654"
"288.60000","24.05022","0.00684"
"289.04400","24.08729","0.00650"
"289.48800","24.12424","0.00613"
"289.93200","24.16119","0.00636"
"290.37600","24.19820","0.00619"
"290.82000","24.23521","0.00673"
"291.26400","24.27228","0.00660"
"291.70800","24.30923","0.00650"
"292.15200","24.34624","0.00607"
"292.59600","24.38313","0.00622"
"293.04000","24.42014","0.00675"
"293.48400","24.45727","0.00629"
"293.92800","24.49428","0.00612"
"294.37200","24.53129","0.00649"
"294.81600","24.56824","0.00654"
"295.26000","24.60519","0.00695"
"295.70400","24.64220","0.00734"
"296.14800","24.67921","0.00677"
"296.59200","24.71622","0.00609"
"297.03600","24.75322","0.00712"
"297.48000","24.79018","0.00688"
"297.92400","24.82719","0.00695"
"298.36800","24.86425","0.00693"
"298.81200","24.90120","0.00657"
"299.25600","24.93821","0.00650"
"299.70000","24.97522","0.00704"
"300.14400","25.01223","0.00649"
"300.58800","25.04918","0.00718"
"301.03200","25.08619","0.00693"
"301.47600","25.12326","0.00632"
"301.92000","25.16027","0.00653"
"302.36400","25.19722","0.00681"
"302.80800","25.23417","0.00692"
"303.25200","25.27118","0.00664"
"303.69600","25.30825","0.00697"
"304.14000","25.34526","0.00750"
"304.58400","25.38221","0.00693"
"305.02800","25.41922","0.00705"
"305.47200","25.45611","0.00713"
"305.91600","25.49324","0.00783"
"306.36000","25.53025","0.00717"
"306.80400","25.56720","0.00717"
"307.24800","25.60427","0.00753"
"307.69200","25.64122","0.00723"
"308.13600","25.67823","0.00784"
"308.58000","25.71524","0.00728"
"309.02400","25.75225","0.00722"
"309.46800","25.78926","0.00694"
"309.91200","25.82621","0.00808"
"310.35600","25.86316","0.00716"
"310.80000","25.90017","0.00707"
"311.24400","25.93724","0.00753"
"311.68800","25.97425","0.00693"
"312.13200","26.01126","0.00723"
"312.57600","26.04827","0.00749"
"313.02000","26.08522","0.00703"
"313.46400","26.12217","0.00662"
"313.90800","26.15924","0.00632"
"314.35200","26.19619","0.00657"
"314.79600","26.23325","0.00635"
"315.24000","26.27015","0.00686"
"315.68400","26.30715","0.00717"
"316.12800","26.34417","0.00679"
"316.57200","26.38124","0.00702"
"317.01600","26.41825","0.00743"
"317.46000","26.45525","0.00717"
"317.90400","26.49220","0.00769"
"318.34800","26.52915","0.00806"
"318.79200","26.56622","0.00775"
"319.23600","26.60323","0.00701"
"319.68000","26.64024","0.00734"
"320.12400","26.67719","0.00774"
"320.56800","26.71414","0.00804"
"321.01200","26.75121","0.00807"
"321.45600","26.78822","0.00784"
"321.90000","26.82523","0.00818"
"322.34400","26.86224","0.00783"
"322.78800","26.89919","0.00771"
"323.23200","26.93620","0.00821"
"323.67600","26.97321","0.00815"
"324.12000","27.01022","0.00785"
"324.56400","27.04717","0.00803"
"325.00800","27.08418","0.00760"
"325.45200","27.12119","0.00746"
"325.89600","27.15820","0.00867"
"326.34000","27.19527","0.00791"
"326.78400","27.23222","0.00829"
"327.22800","27.26923","0.00874"
"327.67200","27.30624","0.00839"
"328.11600","27.34313","0.00880"
"328.56000","27.38020","0.00830"
"329.00400","27.41721","0.00906"
"329.44800","27.45422","0.00820"
"329.89200","27.49123","0.00837"
"330.33600","27.52818","0.00777"
"330.78000","27.56519","0.00786"
"331.22400","27.60220","0.00868"
"331.66800","27.63921","0.00881"
"332.11200","27.67622","0.00799"
"332.55600","27.71329","0.00916"
"333.00000","27.75018","0.00959"
"333.44400","27.78718","0.00956"
"333.88800","27.82420","0.00946"
"334.33200","27.86126","0.00923"
"334.77600","27.89821","0.00873"
"335.22000","27.93523","0.00829"
"335.66400","27.97218","0.00694"
"336.10800","28.00918","0.00884"
"336.55200","28.04626","0.00868"
"336.99600","28.08327","0.00866"
"337.44000","28.12021","0.00858"
"337.88400","28.15722","0.00828"
"338.32800","28.19411","0.00891"
"338.77200","28.23118","0.00898"
"339.21600","28.26825","0.00933"
"339.66000","28.30520","0.00946"
"340.10400","28.34227","0.00950"
"340.54800","28.37922","0.00953"
"340.99200","28.41623","0.00947"
"341.43600","28.45324","0.00994"
"341.88000","28.49019","0.00951"
"342.32400","28.52720","0.00889"
"342.76800","28.56427","0.00866"
"343.21200","28.60122","0.00867"
"343.65600","28.63817","0.00793"
"344.10000","28.67518","0.00849"
"344.54400","28.71225","0.00832"
"344.98800","28.74932","0.00742"
"345.43200","28.78627","0.00755"
"345.87600","28.82322","0.00856"
"346.32000","28.86017","0.00813"
"346.76400","28.89724","0.00818"
"347.20800","28.93425","0.00822"
"347.65200","28.97120","0.00903"
"348.09600","29.00821","0.00896"
"348.54000","29.04510","0.00903"
"348.98400","29.08223","0.00884"
"349.42800","29.11924","0.00918"
"349.87200","29.15625","0.00876"
"350.31600","29.19326","0.00838"
"350.76000","29.23021","0.00846"
"351.20400","29.26722","0.00864"
"351.64800","29.30423","0.00951"
"352.09200","29.34124","0.01034"
"352.53600","29.37819","0.00917"
"352.98000","29.41519","0.01037"
"353.42400","29.45214","0.01002"
"353.86800","29.48916","0.01005"
"354.31200","29.52622","0.01049"
"354.75600","29.56329","0.01032"
"355.20000","29.60024","0.01119"
"355.64400","29.63720","0.01084"
"356.08800","29.67420","0.01088"
"356.53200","29.71121","0.01087"
"356.97600","29.74822","0.01074"
"357.42000","29.78518","0.01046"
"357.86400","29.82224","0.01017"
"358.30800","29.85919","0.01061"
"358.75200","29.89620","0.01114"
"359.19600","29.93315","0.01091"
"359.64000","29.97022","0.01198"
"360.08400","30.00723","0.01135"
"360.52800","30.04424","0.01184"
"360.97200","30.08119","0.01086"
"361.41600","30.11814","0.01158"
"361.86000","30.15521","0.01226"
"362.30400","30.19222","0.01276"
"362.74800","30.22923","0.01276"
"363.19200","30.26624","0.01292"
"363.63600","30.30319","0.01320"
"364.08000","30.34020","0.01297"
"364.52400","30.37727","0.01376"
"364.96800","30.41428","0.01433"
"365.41200","30.45123","0.01436"
"365.85600","30.48818","0.01470"
"366.30000","30.52519","0.01388"
"366.74400","30.56220","0.01373"
"367.18800","30.59921","0.01464"
"367.63200","30.63622","0.01454"
"368.07600","30.67323","0.01357"
"368.52000","30.71024","0.01240"
"368.96400","30.74719","0.01345"
"369.40800","30.78425","0.01302"
"369.85200","30.82121","0.00697"
"370.29600","30.85822","0.00746"
"370.74000","30.89528","0.00718"
"371.18400","30.93217","0.00753"
"371.62800","30.96918","0.00826"
"372.07200","31.00620","0.00868"
"372.51600","31.04326","0.00801"
"372.96000","31.08027","0.00832"
"373.40400","31.11722","0.00853"
"373.84800","31.15417","0.00858"
"374.29200","31.19118","0.00971"
"374.73600","31.22825","0.00890"
"375.18000","31.26520","0.00998"
"375.62400","31.30227","0.00849"
"376.06800","31.33922","0.00686"
"376.51200","31.37617","0.00726"
"376.95600","31.41318","0.00750"
"377.40000","31.45025","0.00576"
"377.84400","31.48726","0.00566"
"378.28800","31.52427","0.00714"
"378.73200","31.56122","0.00682"
"379.17600","31.59817","0.00645"
"379.62000","31.63524","0.00637"
"380.06400","31.67225","0.00678"
"380.50800","31.70920","0.00733"
"380.95200","31.74615","0.00710"
"381.39600","31.78316","0.00701"
"381.84000","31.82017","0.00661"
"382.28400","31.85724","0.00702"
"382.72800","31.89425","0.00494"
"383.17200","31.93132","0.00473"
"383.61600","31.96827","0.00387"
"384.06000","32.00516","0.00441"
"384.50400","32.04217","0.00440"
"384.94800","32.07917","0.00498"
"385.39200","32.11625","0.00473"
"385.83600","32.15320","0.00449"
"386.28000","32.19021","0.00452"
"386.72400","32.22715","0.00413"
"387.16800","32.26423","0.00487"
"387.61200","32.30130","0.00459"
"388.05600","32.33824","0.00452"
"388.50000","32.37526","0.00463"
"388.94400","32.41220","0.00427"
"389.38800","32.44915","0.00436"
"389.83200","32.48622","0.00447"
"390.27600","32.52329","0.00451"
"390.72000","32.56025","0.00400"
"391.16400","32.59719","0.00459"
"391.60800","32.63414","0.00489"
"392.05200","32.67121","0.00452"
"392.49600","32.70828","0.00422"
"392.94000","32.74529","0.00460"
"393.38400","32.78224","0.00455"
"393.82800","32.81919","0.00454"
"394.27200","32.85620","0.00464"
"394.71600","32.89315","0.00410"
"395.16000","32.93022","0.00479"
"395.60400","32.96723","0.00464"
"396.04800","33.00424","0.00478"
"396.49200","33.04119","0.00439"
"396.93600","33.07820","0.00424"
"397.38000","33.11527","0.00392"
"397.82400","33.15228","0.00457"
"398.26800","33.18923","0.00511"
"398.71200","33.22624","0.00440"
"399.15600","33.26319","0.00358"
"399.60000","33.30020","0.00365"
"400.04400","33.33721","0.00378"
"400.48800","33.37422","0.00458"
"400.93200","33.41123","0.00369"
"401.37600","33.44824","0.00410"
"401.82000","33.48519","0.00396"
"402.26400","33.52220","0.00347"
"402.70800","33.55927","0.00430"
"403.15200","33.59622","0.00363"
"403.59600","33.63329","0.00397"
"404.04000","33.67018","0.00428"
"404.48400","33.70713","0.00461"
"404.92800","33.74420","0.00436"
"405.37200","33.78120","0.00408"
"405.81600","33.81828","0.00429"
"406.26000","33.85522","0.00423"
"406.70400","33.89223","0.00449"
"407.14800","33.92918","0.00411"
"407.59200","33.96619","0.00422"
"408.03600","34.00327","0.00474"
"408.48000","34.04021","0.00460"
"408.92400","34.07722","0.00483"
"409.36800","34.11417","0.00433"
"409.81200","34.15118","0.00438"
"410.25600","34.18825","0.00426"
"410.70000","34.22520","0.00426"
"411.14400","34.26221","0.00453"
"411.58800","34.29922","0.00447"
"412.03200","34.33617","0.00538"
"412.47600","34.37318","0.00507"
"412.92000","34.41025","0.00505"
"413.36400","34.44720","0.00492"
"413.80800","34.48427","0.00489"
"414.25200","34.52116","0.00558"
"414.69600","34.55817","0.00502"
"415.14000","34.59524","0.00472"
"415.58400","34.63225","0.00568"
"416.02800","34.66926","0.00532"
"416.47200","34.70627","0.00526"
"416.91600","34.74322","0.00551"
"417.36000","34.78023","0.00555"
"417.80400","34.81724","0.00509"
"418.24800","34.85425","0.00565"
"418.69200","34.89126","0.00580"
"419.13600","34.92821","0.00551"
"419.58000","34.96516","0.00543"
"420.02400","35.00217","0.00621"
"420.46800","35.03924","0.00549"
"420.91200","35.07624","0.00511"
"421.35600","35.11325","0.00523"
"421.80000","35.15027","0.00528"
"422.24400","35.18716","0.00501"
"422.68800","35.22422","0.00561"
"423.13200","35.26123","0.00588"
"423.57600","35.29825","0.00503"
"424.02000","35.33519","0.00554"
"424.46400","35.37215","0.00565"
"424.90800","35.40921","0.00613"
"425.35200","35.44628","0.00582"
"425.79600","35.48329","0.00511"
"426.24000","35.52024","0.00537"
"426.68400","35.55725","0.00590"
"427.12800","35.59420","0.00715"
"427.57200","35.63121","0.00670"
"428.01600","35.66822","0.00675"
"428.46000","35.70523","0.00734"
"428.90400","35.74218","0.00774"
"429.34800","35.77925","0.00797"
"429.79200","35.81620","0.00660"
"430.23600","35.85321","0.00668"
"430.68000","35.89028","0.00657"
"431.12400","35.92729","0.00832"
"431.56800","35.96430","0.00807"
"432.01200","36.00119","0.00666"
"432.45600","36.03814","0.00724"
"432.90000","36.07521","0.00691"
"433.34400","36.11222","0.00703"
"433.78800","36.14923","0.00654"
"434.23200","36.18618","0.00672"
"434.67600","36.22319","0.00669"
"435.12000","36.26020","0.00691"
"435.56400","36.29721","0.00659"
"436.00800","36.33422","0.00636"
"436.45200","36.37129","0.00737"
"436.89600","36.40818","0.00633"
"437.34000","36.44513","0.00706"
"437.78400","36.48214","0.00640"
"438.22800","36.51921","0.00654"
"438.67200","36.55622","0.00667"
"439.11600","36.59323","0.00711"
"439.56000","36.63018","0.00712"
"440.00400","36.66719","0.00695"
"440.44800","36.70426","0.00586"
"440.89200","36.74126","0.00648"
"441.33600","36.77821","0.00684"
"441.78000","36.81523","0.00645"
"442.22400","36.85218","0.00663"
"442.66800","36.88918","0.00616"
"443.11200","36.92619","0.00625"
"443.55600","36.96321","0.00688"
"444.00000","37.00027","0.00623"
"444.44400","37.03722","0.00696"
"444.88800","37.07417","0.00673"
"445.33200","37.11119","0.00668"
"445.77600","37.14819","0.00650"
"446.22000","37.18526","0.00590"
"446.66400","37.22227","0.00695"
"447.10800","37.25922","0.00680"
"447.55200","37.29611","0.00614"
"447.99600","37.33318","0.00669"
"448.44000","37.37025","0.00597"
"448.88400","37.40726","0.00645"
"449.32800","37.44427","0.00609"
"449.77200","37.48122","0.00649"
"450.21600","37.51823","0.00655"
"450.66000","37.55518","0.00622"
"451.10400","37.59231","0.00630"
"451.54800","37.62920","0.00643"
"451.99200","37.66621","0.00634"
"452.43600","37.70322","0.00698"
"452.88000","37.74017","0.00655"
"453.32400","37.77724","0.00652"
"453.76800","37.81425","0.00637"
"454.21200","37.85132","0.00660"
"454.65600","37.88821","0.00628"
"455.10000","37.92516","0.00665"
"455.54400","37.96217","0.00643"
"455.98800","37.99924","0.00651"
"456.43200","38.03625","0.00661"
"456.87600","38.07326","0.00632"
"457.32000","38.11015","0.00605"
"457.76400","38.14716","0.00647"
"458.20800","38.18417","0.00632"
"458.65200","38.22124","0.00640"
"459.09600","38.25825","0.00658"
"459.54000","38.29526","0.00622"
"459.98400","38.33221","0.00641"
"460.42800","38.36916","0.00667"
"460.87200","38.40623","0.00630"
"461.31600","38.44323","0.00669"
"461.76000","38.48024","0.00602"
"462.20400","38.51725","0.00626"
"462.64800","38.55414","0.00632"
"463.09200","38.59121","0.00674"
"463.53600","38.62822","0.00586"
"463.98000","38.66523","0.00640"
"464.42400","38.70230","0.00629"
"464.86800","38.73919","0.00616"
"465.31200","38.77615","0.00647"
"465.75600","38.81315","0.00664"
"466.20000","38.85022","0.00625"
"466.64400","38.88723","0.00589"
"467.08800","38.92418","0.00733"
"467.53200","38.96119","0.00671"
"467.97600","38.99820","0.00669"
"468.42000","39.03521","0.00650"
"468.86400","39.07228","0.00587"
"469.30800","39.10923","0.00658"
"469.75200","39.14624","0.00672"
"470.19600","39.18319","0.00653"
"470.64000","39.22014","0.00640"
"471.08400","39.25715","0.00613"
"471.52800","39.29422","0.00646"
"471.97200","39.33123","0.00597"
"472.41600","39.36824","0.00631"
"472.86000","39.40519","0.00654"
"473.30400","39.44220","0.00588"
"473.74800","39.47921","0.00650"
"474.19200","39.51628","0.00608"
"474.63600","39.55329","0.00631"
"475.08000","39.59024","0.00624"
"475.52400","39.62718","0.00661"
"475.96800","39.66419","0.00617"
"476.41200","39.70121","0.00626"
"476.85600","39.73827","0.00591"
"477.30000","39.77523","0.00668"
"477.74400","39.81224","0.00574"
"478.18800","39.84919","0.00629"
"478.63200","39.88620","0.00617"
"479.07600","39.92321","0.00602"
"479.52000","39.96022","0.00643"
"479.96400","39.99722","0.00667"
"480.40800","40.03417","0.00655"
"480.85200","40.07118","0.00645"
"481.29600","40.10826","0.00631"
"481.74000","40.14520","0.00742"
"482.18400","40.18227","0.00680"
"482.62800","40.21923","0.00631"
"483.07200","40.25611","0.00682"
"483.51600","40.29324","0.00669"
"483.96000","40.33025","0.00683"
"484.40400","40.36726","0.00662"
"484.84800","40.40421","0.00699"
"485.29200","40.44116","0.00669"
"485.73600","40.47817","0.00716"
"486.18000","40.51524","0.00641"
"486.62400","40.55225","0.00708"
"487.06800","40.58920","0.00663"
"487.51200","40.62627","0.00672"
"487.95600","40.66316","0.00688"
"488.40000","40.70017","0.00751"
"488.84400","40.73718","0.00652"
"489.28800","40.77419","0.00668"
"489.73200","40.81120","0.00658"
"490.17600","40.84821","0.00719"
"490.62000","40.88516","0.00655"
"491.06400","40.92217","0.00690"
"491.50800","40.95930","0.00665"
"491.95200","40.99631","0.00673"
"492.39600","41.03326","0.00691"
"492.84000","41.07021","0.00708"
"493.28400","41.10716","0.00714"
"493.72800","41.14416","0.00751"
"494.17200","41.18124","0.00763"
"494.61600","41.21819","0.00675"
"495.06000","41.25526","0.00650"
"495.50400","41.29220","0.00761"
"495.94800","41.32915","0.00731"
"496.39200","41.36617","0.00820"
"496.83600","41.40323","0.00712"
"497.28000","41.44025","0.00762"
"497.72400","41.47720","0.00721"
"498.16800","41.51415","0.00737"
"498.61200","41.55115","0.00721"
"499.05600","41.58817","0.00701"
"499.50000","41.62524","0.00751"
"499.94400","41.66225","0.00738"
"500.38800","41.69919","0.00727"
"500.83200","41.73615","0.00765"
"501.27600","41.77321","0.00800"
"501.72000","41.81022","0.00689"
"502.16400","41.84723","0.00765"
"502.60800","41.88424","0.00740"
"503.05200","41.92119","0.00703"
"503.49600","41.95814","0.00773"
"503.94000","41.99515","0.00693"
"504.38400","42.03222","0.00711"
"504.82800","42.06923","0.00788"
"505.27200","42.10630","0.00781"
"505.71600","42.14325","0.00758"
"506.16000","42.18020","0.00712"
"506.60400","42.21721","0.00742"
"507.04800","42.25422","0.00734"
"507.49200","42.29123","0.00776"
"507.93600","42.32824","0.00738"
"508.38000","42.36519","0.00806"
"508.82400","42.40220","0.00753"
"509.26800","42.43921","0.00751"
"509.71200","42.47622","0.00759"
"510.15600","42.51329","0.00720"
"510.60000","42.55024","0.00733"
"511.04400","42.58719","0.00773"
"511.48800","42.62420","0.00759"
"511.93200","42.66127","0.00695"
"512.37600","42.69822","0.00790"
"512.82000","42.73523","0.00748"
"513.26400","42.77218","0.00779"
"513.70800","42.80919","0.00752"
"514.15200","42.84620","0.00739"
"514.59600","42.88320","0.00807"
"515.04000","42.92028","0.00770"
"515.48400","42.95723","0.00821"
"515.92800","42.99417","0.00766"
"516.37200","43.03119","0.00778"
"516.81600","43.06825","0.00735"
"517.26000","43.10526","0.00791"
"517.70400","43.14222","0.00760"
"518.14800","43.17916","0.00721"
"518.59200","43.21611","0.00822"
"519.03600","43.25318","0.00790"
"519.48000","43.29025","0.00791"
"519.92400","43.32726","0.00829"
"520.36800","43.36427","0.00793"
"520.81200","43.40116","0.00850"
"521.25600","43.43818","0.00841"
"521.70000","43.47519","0.00821"
"522.14400","43.51219","0.00843"
"522.58800","43.54920","0.00817"
"523.03200","43.58621","0.00850"
"523.47600","43.62322","0.00843"
"523.92000","43.66017","0.00803"
"524.36400","43.69724","0.00866"
"524.80800","43.73425","0.00879"
"525.25200","43.77126","0.00877"
"525.69600","43.80821","0.00885"
"526.14000","43.84516","0.00851"
"526.58400","43.88217","0.00891"
"527.02800","43.91924","0.00872"
"527.47200","43.95625","0.00868"
"527.91600","43.99326","0.00844"
"528.36000","44.03021","0.00904"
"528.80400","44.06722","0.00894"
"529.24800","44.10423","0.00882"
"529.69200","44.14123","0.00858"
"530.13600","44.17825","0.00895"
"530.58000","44.21526","0.00936"
"531.02400","44.25220","0.00908"
"531.46800","44.28916","0.00800"
"531.91200","44.32617","0.00960"
"532.35600","44.36329","0.00947"
"532.80000","44.40025","0.00890"
"533.24400","44.43726","0.00938"
"533.68800","44.47421","0.00963"
"534.13200","44.51122","0.00983"
"534.57600","44.54828","0.00974"
"535.02000","44.58530","0.00994"
"535.46400","44.62224","0.00925"
"535.90800","44.65919","0.00940"
"536.35200","44.69621","0.00907"
"536.79600","44.73315","0.00969"
"537.24000","44.77023","0.00916"
"537.68400","44.80717","0.00925"
"538.12800","44.84424","0.00931"
"538.57200","44.88126","0.00933"
"539.01600","44.91820","0.00935"
"539.46000","44.95521","0.00943"
"539.90400","44.99222","0.00901"
"540.34800","45.02923","0.00887"
"540.79200","45.06624","0.00948"
"541.23600","45.10319","0.00895"
"541.68000","45.14020","0.00889"
"542.12400","45.17715","0.00982"
"542.56800","45.21422","0.00956"
"543.01200","45.25129","0.00906"
"543.45600","45.28830","0.00894"
"543.90000","45.32519","0.00971"
"544.34400","45.36214","0.00927"
"544.78800","45.39921","0.00938"
"545.23200","45.43621","0.00969"
"545.67600","45.47322","0.00948"
"546.12000","45.51018","0.00980"
"546.56400","45.54713","0.00996"
"547.00800","45.58420","0.01003"
"547.45200","45.62127","0.00971"
"547.89600","45.65828","0.00987"
"548.34000","45.69529","0.01022"
"548.78400","45.73224","0.01082"
"549.22800","45.76918","0.00991"
"549.67200","45.80620","0.00992"
"550.11600","45.84320","0.01024"
"550.56000","45.88021","0.01050"
"551.00400","45.91722","0.01084"
"551.44800","45.95417","0.01047"
"551.89200","45.99118","0.01063"
"552.33600","46.02826","0.01033"
"552.78000","46.06521","0.01083"
"553.22400","46.10221","0.01040"
"553.66800","46.13929","0.01126"
"554.11200","46.17617","0.01147"
"554.55600","46.21318","0.01094"
"555.00000","46.25019","0.01071"
"555.44400","46.28726","0.01053"
"555.88800","46.32421","0.01093"
"556.33200","46.36116","0.01133"
"556.77600","46.39817","0.01142"
"557.22000","46.43518","0.01069"
"557.66400","46.47225","0.01069"
"558.10800","46.50926","0.01163"
"558.55200","46.54627","0.01113"
"558.99600","46.58323","0.01160"
"559.44000","46.62017","0.01162"
"559.88400","46.65718","0.01129"
"560.32800","46.69425","0.01138"
"560.77200","46.73125","0.01130"
"561.21600","46.76821","0.01164"
"561.66000","46.80522","0.01188"
"562.10400","46.84223","0.01161"
"562.54800","46.87924","0.01175"
"562.99200","46.91625","0.01138"
"563.43600","46.95320","0.01204"
"563.88000","46.99021","0.01164"
"564.32400","47.02716","0.01223"
"564.76800","47.06423","0.01237"
"565.21200","47.10124","0.01191"
"565.65600","47.13818","0.01213"
"566.10000","47.17519","0.01167"
"566.54400","47.21227","0.01177"
"566.98800","47.24922","0.01251"
"567.43200","47.28628","0.01173"
"567.87600","47.32318","0.01260"
"568.32000","47.36025","0.01214"
"568.76400","47.39725","0.01253"
"569.20800","47.43414","0.01222"
"569.65200","47.47115","0.01224"
"570.09600","47.50816","0.01185"
"570.54000","47.54523","0.01256"
"570.98400","47.58224","0.01224"
"571.42800","47.61926","0.01255"
"571.87200","47.65620","0.01274"
"572.31600","47.69316","0.01344"
"572.76000","47.73022","0.01292"
"573.20400","47.76723","0.01289"
"573.64800","47.80418","0.01312"
"574.09200","47.84113","0.01291"
"574.53600","47.87814","0.01333"
"574.98000","47.91515","0.01306"
"575.42400","47.95222","0.01293"
"575.86800","47.98923","0.01382"
"576.31200","48.02624","0.01263"
"576.75600","48.06319","0.01341"
"577.20000","48.10020","0.01323"
"577.64400","48.13721","0.01310"
"578.08800","48.17422","0.01343"
"578.53200","48.21123","0.01354"
"578.97600","48.24824","0.01324"
"579.42000","48.28513","0.01352"
"579.86400","48.32220","0.01358"
"580.30800","48.35927","0.01421"
"580.75200","48.39622","0.01389"
"581.19600","48.43328","0.01331"
"581.64000","48.47024","0.01372"
"582.08400","48.50719","0.01363"
"582.52800","48.54420","0.01431"
"582.97200","48.58121","0.01368"
"583.41600","48.61822","0.01415"
"583.86000","48.65517","0.01347"
"584.30400","48.69217","0.01367"
"584.74800","48.72913","0.01431"
"585.19200","48.76614","0.01380"
"585.63600","48.80320","0.01416"
"586.08000","48.84021","0.01423"
"586.52400","48.87729","0.01436"
"586.96800","48.91418","0.01428"
"587.41200","48.95119","0.01420"
"587.85600","48.98820","0.01397"
"588.30000","49.02527","0.01393"
"588.74400","49.06221","0.01435"
"589.18800","49.09922","0.01185"
"589.63200","49.13617","0.01292"
"590.07600","49.17324","0.01157"
"590.52000","49.21025","0.01262"
"590.96400","49.24726","0.01210"
"591.40800","49.28427","0.01277"
"591.85200","49.32116","0.01325"
"592.29600","49.35817","0.01236"
"592.74000","49.39518","0.01266"
"593.18400","49.43225","0.01286"
"593.62800","49.46926","0.01306"
"594.07200","49.50621","0.01309"
"594.51600","49.54322","0.01328"
"594.96000","49.58017","0.01319"
"595.40400","49.61724","0.01277"
"595.84800","49.65425","0.01295"
"596.29200","49.69126","0.01314"
"596.73600","49.72827","0.01268"
"597.18000","49.76522","0.01300"
"597.62400","49.80223","0.01369"
"598.06800","49.83918","0.01332"
"598.51200","49.87619","0.01360"
"598.95600","49.91326","0.01369"
"599.40000","49.95021","0.01339"
"599.84400","49.98716","0.01373"
"600.28800","50.02423","0.01391"
"600.73200","50.06118","0.01356"
"601.17600","50.09825","0.01427"
"601.62000","50.13525","0.01452"
"602.06400","50.17221","0.01439"
"602.50800","50.20916","0.01436"
"602.95200","50.24616","0.01446"
"603.39600","50.28318","0.01407"
"603.84000","50.32025","0.01467"
"604.28400","50.35726","0.01479"
"604.72800","50.39420","0.01444"
"605.17200","50.43121","0.01404"
"605.61600","50.46822","0.01423"
"606.06000","50.50523","0.01455"
"606.50400","50.54219","0.01451"
"606.94800","50.57925","0.01437"
"607.39200","50.61615","0.01417"
"607.83600","50.65315","0.01475"
"608.28000","50.69023","0.01535"
"608.72400","50.72724","0.01394"
"609.16800","50.76424","0.01359"
"609.61200","50.80125","0.01430"
"610.05600","50.83820","0.01445"
"610.50000","50.87521","0.01442"
"610.94400","50.91216","0.01419"
"611.38800","50.94923","0.01467"
"611.83200","50.98619","0.01448"
"612.27600","51.02319","0.01465"
"612.72000","51.06014","0.01512"
"613.16400","51.09721","0.01484"
"613.60800","51.13428","0.01465"
"614.05200","51.17123","0.01556"
"614.49600","51.20824","0.01455"
"614.94000","51.24525","0.01440"
"615.38400","51.28220","0.01442"
"615.82800","51.31921","0.01544"
"616.27200","51.35622","0.01466"
"616.71600","51.39323","0.01452"
"617.16000","51.43018","0.01468"
"617.60400","51.46713","0.01483"
"618.04800","51.50420","0.01493"
"618.49200","51.54127","0.01423"
"618.93600","51.57828","0.01532"
"619.38000","51.61529","0.01556"
"619.82400","51.65224","0.01573"
"620.26800","51.68919","0.01536"
"620.71200","51.72620","0.01567"
"621.15600","51.76321","0.01540"
"621.60000","51.80027","0.01547"
"622.04400","51.83723","0.01545"
"622.48800","51.87418","0.01543"
"622.93200","51.91118","0.01520"
"623.37600","51.94826","0.01542"
"623.82000","51.98527","0.01547"
"624.26400","52.02222","0.01525"
"624.70800","52.05922","0.01493"
"625.15200","52.09617","0.01593"
"625.59600","52.13324","0.01558"
"626.04000","52.17020","0.01516"
"626.48400","52.20721","0.01608"
"626.92800","52.24422","0.01578"
"627.37200","52.28123","0.01509"
"627.81600","52.31817","0.01438"
"628.26000","52.35519","0.01413"
"628.70400","52.39231","0.01491"
"629.14800","52.42921","0.01486"
"629.59200","52.46627","0.01519"
"630.03600","52.50316","0.01549"
"630.48000","52.54017","0.01494"
"630.92400","52.57718","0.01483"
"631.36800","52.61425","0.01569"
"631.81200","52.65120","0.01584"
"632.25600","52.68821","0.01517"
"632.70000","52.72522","0.01598"
"633.14400","52.76223","0.01565"
"633.58800","52.79924","0.01536"
"634.03200","52.83625","0.01518"
"634.47600","52.87326","0.01597"
"634.92000","52.91021","0.01614"
"635.36400","52.94716","0.01597"
"635.80800","52.98417","0.01572"
"636.25200","53.02118","0.01565"
"636.69600","53.05825","0.01543"
"637.14000","53.09526","0.01576"
"637.58400","53.13221","0.01637"
"638.02800","53.16922","0.01631"
"638.47200","53.20623","0.01666"
"638.91600","53.24324","0.01610"
"639.36000","53.28025","0.01571"
"639.80400","53.31726","0.01649"
"640.24800","53.35420","0.01644"
"640.69200","53.39122","0.01679"
"641.13600","53.42823","0.01614"
"641.58000","53.46524","0.01616"
"642.02400","53.50225","0.01729"
"642.46800","53.53920","0.01599"
"642.91200","53.57621","0.01633"
"643.35600","53.61315","0.01680"
"643.80000","53.65016","0.01650"
"644.24400","53.68724","0.01667"
"644.68800","53.72424","0.01674"
"645.13200","53.76125","0.01682"
"645.57600","53.79815","0.01722"
"646.02000","53.83521","0.01714"
"646.46400","53.87222","0.01726"
"646.90800","53.90923","0.01736"
"647.35200","53.94625","0.01688"
"647.79600","53.98320","0.01743"
"648.24000","54.02014","0.01692"
"648.68400","54.05721","0.01761"
"649.12800","54.09428","0.01747"
"649.57200","54.13117","0.01720"
"650.01600","54.16824","0.01731"
"650.46000","54.20514","0.01776"
"650.90400","54.24220","0.01763"
"651.34800","54.27921","0.01784"
"651.79200","54.31622","0.01800"
"652.23600","54.35323","0.01772"
"652.68000","54.39018","0.01761"
"653.12400","54.42719","0.01751"
"653.56800","54.46420","0.01781"
"654.01200","54.50121","0.01770"
"654.45600","54.53822","0.01787"
"654.90000","54.57517","0.01807"
"655.34400","54.61218","0.01836"
"655.78800","54.64919","0.01786"
"656.23200","54.68620","0.01815"
"656.67600","54.72327","0.01750"
"657.12000","54.76028","0.01791"
"657.56400","54.79723","0.01839"
"658.00800","54.83418","0.01818"
"658.45200","54.87119","0.01870"
"658.89600","54.90820","0.01804"
"659.34000","54.94521","0.01857"
"659.78400","54.98222","0.01852"
"660.22800","55.01923","0.01920"
"660.67200","55.05618","0.01830"
"661.11600","55.09319","0.01902"
"661.56000","55.13025","0.01907"
"662.00400","55.16727","0.01927"
"662.44800","55.20428","0.01894"
"662.89200","55.24123","0.01964"
"663.33600","55.27811","0.01949"
"663.78000","55.31518","0.01948"
"664.22400","55.35219","0.01834"
"664.31000","55.35937","0.01902"