File: Force_trajectories/170226_3/Specimen_RawData_7.csv
End date,"2/26/2017"
Specimen label,"8CG_71"
Maximum Load,"0.03895",N

Time,Extension,Load
(s),(mm),(N)
"0.00000","0.00000","-0.00025"
"0.40800","0.03432","0.00104"
"0.81600","0.06816","0.00240"
"1.22400","0.10224","0.00302"
"1.63200","0.13626","0.00336"
"2.04000","0.17022","0.00288"
"2.44800","0.20418","0.00368"
"2.85600","0.23820","0.00320"
"3.26400","0.27228","0.00341"
"3.67200","0.30624","0.00350"
"4.08000","0.34020","0.00394"
"4.48800","0.37422","0.00405"
"4.89600","0.40818","0.00378"
"5.30400","0.44226","0.00419"
"5.71200","0.47622","0.00460"
"6.12000","0.51018","0.00465"
"6.52800","0.54420","0.00502"
"6.93600","0.57822","0.00461"
"7.34400","0.61219","0.00488"
"7.75200","0.64615","0.00477"
"8.16000","0.68017","0.00496"
"8.56800","0.71425","0.00492"
"8.97600","0.74827","0.00524"
"9.38400","0.78217","0.00524"
"9.79200","0.81625","0.00535"
"10.20000","0.85021","0.00549"
"10.60800","0.88417","0.00496"
"11.01600","0.91813","0.00498"
"11.42400","0.95227","0.00533"
"11.83200","0.98623","0.00555"
"12.24000","1.02019","0.00520"
"12.64800","1.05415","0.00668"
"13.05600","1.08817","0.00564"
"13.46400","1.12219","0.00584"
"13.87200","1.15627","0.00585"
"14.28000","1.19023","0.00541"
"14.68800","1.22419","0.00582"
"15.09600","1.25827","0.00564"
"15.50400","1.29223","0.00544"
"15.91200","1.32619","0.00563"
"16.32000","1.36021","0.00597"
"16.72800","1.39423","0.00575"
"17.13600","1.42825","0.00600"
"17.54400","1.46221","0.00585"
"17.95200","1.49617","0.00585"
"18.36000","1.53025","0.00621"
"18.76800","1.56427","0.00596"
"19.17600","1.59823","0.00650"
"19.58400","1.63225","0.00568"
"19.99200","1.66621","0.00578"
"20.40000","1.70018","0.00651"
"20.80800","1.73420","0.00714"
"21.21600","1.76816","0.00656"
"21.62400","1.80224","0.00610"
"22.03200","1.83626","0.00639"
"22.44000","1.87022","0.00665"
"22.84800","1.90418","0.00629"
"23.25600","1.93820","0.00635"
"23.66400","1.97222","0.00603"
"24.07200","2.00624","0.00696"
"24.48000","2.04014","0.00623"
"24.88800","2.07422","0.00669"
"25.29600","2.10824","0.00673"
"25.70400","2.14220","0.00766"
"26.11200","2.17616","0.00677"
"26.52000","2.21024","0.00662"
"26.92800","2.24426","0.00631"
"27.33600","2.27828","0.00653"
"27.74400","2.31218","0.00748"
"28.15200","2.34620","0.00673"
"28.56000","2.38028","0.00659"
"28.96800","2.41424","0.00692"
"29.37600","2.44820","0.00669"
"29.78400","2.48216","0.00688"
"30.19200","2.51624","0.00723"
"30.60000","2.55020","0.00672"
"31.00800","2.58416","0.00696"
"31.41600","2.61818","0.00746"
"31.82400","2.65220","0.00732"
"32.23200","2.68622","0.00576"
"32.64000","2.72024","0.00579"
"33.04800","2.75420","0.00662"
"33.45600","2.78823","0.00637"
"33.86400","2.82225","0.00649"
"34.27200","2.85627","0.00652"
"34.68000","2.89023","0.00652"
"35.08800","2.92431","0.00692"
"35.49600","2.95827","0.00711"
"35.90400","2.99223","0.00706"
"36.31200","3.02613","0.00729"
"36.72000","3.06021","0.00720"
"37.12800","3.09423","0.00694"
"37.53600","3.12819","0.00722"
"37.94400","3.16221","0.00706"
"38.35200","3.19623","0.00781"
"38.76000","3.23019","0.00705"
"39.16800","3.26421","0.00726"
"39.57600","3.29823","0.00741"
"39.98400","3.33225","0.00703"
"40.39200","3.36621","0.00732"
"40.80000","3.40023","0.00606"
"41.20800","3.43419","0.00682"
"41.61600","3.46821","0.00606"
"42.02400","3.50223","0.00683"
"42.43200","3.53631","0.00698"
"42.84000","3.57027","0.00669"
"43.24800","3.60417","0.00677"
"43.65600","3.63825","0.00722"
"44.06400","3.67227","0.00695"
"44.47200","3.70617","0.00641"
"44.88000","3.74013","0.00722"
"45.28800","3.77421","0.00715"
"45.69600","3.80823","0.00696"
"46.10400","3.84220","0.00672"
"46.51200","3.87616","0.00677"
"46.92000","3.91024","0.00799"
"47.32800","3.94426","0.00757"
"47.73600","3.97822","0.00726"
"48.14400","4.01224","0.00688"
"48.55200","4.04626","0.00766"
"48.96000","4.08022","0.00731"
"49.36800","4.11424","0.00709"
"49.77600","4.14820","0.00740"
"50.18400","4.18228","0.00750"
"50.59200","4.21630","0.00748"
"51.00000","4.25032","0.00703"
"51.40800","4.28416","0.00686"
"51.81600","4.31818","0.00780"
"52.22400","4.35226","0.00768"
"52.63200","4.38628","0.00726"
"53.04000","4.42018","0.00747"
"53.44800","4.45420","0.00797"
"53.85600","4.48822","0.00770"
"54.26400","4.52224","0.00771"
"54.67200","4.55620","0.00719"
"55.08000","4.59022","0.00789"
"55.48800","4.62424","0.00881"
"55.89600","4.65826","0.00864"
"56.30400","4.69222","0.00891"
"56.71200","4.72618","0.00869"
"57.12000","4.76026","0.00893"
"57.52800","4.79428","0.00872"
"57.93600","4.82818","0.00873"
"58.34400","4.86220","0.00918"
"58.75200","4.89628","0.00927"
"59.16000","4.93024","0.00841"
"59.56800","4.96421","0.00950"
"59.97600","4.99817","0.00843"
"60.38400","5.03225","0.00929"
"60.79200","5.06621","0.00919"
"61.20000","5.10023","0.01019"
"61.60800","5.13419","0.00896"
"62.01600","5.16821","0.00842"
"62.42400","5.20223","0.00832"
"62.83200","5.23631","0.00927"
"63.24000","5.27021","0.00857"
"63.64800","5.30429","0.00905"
"64.05600","5.33825","0.00903"
"64.46400","5.37221","0.00944"
"64.87200","5.40617","0.00890"
"65.28000","5.44025","0.00956"
"65.68800","5.47427","0.00955"
"66.09600","5.50823","0.00974"
"66.50400","5.54219","0.00951"
"66.91200","5.57615","0.00988"
"67.32000","5.61023","0.01016"
"67.72800","5.64419","0.01046"
"68.13600","5.67821","0.01012"
"68.54400","5.71217","0.01032"
"68.95200","5.74625","0.01122"
"69.36000","5.78027","0.01059"
"69.76800","5.81417","0.01062"
"70.17600","5.84819","0.01147"
"70.58400","5.88227","0.01092"
"70.99200","5.91623","0.01179"
"71.40000","5.95025","0.01118"
"71.80800","5.98422","0.01184"
"72.21600","6.01823","0.01130"
"72.62400","6.05226","0.01145"
"73.03200","6.08622","0.01261"
"73.44000","6.12018","0.01145"
"73.84800","6.15420","0.01252"
"74.25600","6.18822","0.01212"
"74.66400","6.22224","0.01271"
"75.07200","6.25614","0.01270"
"75.48000","6.29016","0.01318"
"75.88800","6.32424","0.01302"
"76.29600","6.35826","0.01349"
"76.70400","6.39222","0.01295"
"77.11200","6.42618","0.01322"
"77.52000","6.46026","0.01303"
"77.92800","6.49428","0.01388"
"78.33600","6.52812","0.01335"
"78.74400","6.56220","0.01404"
"79.15200","6.59628","0.01414"
"79.56000","6.63024","0.01432"
"79.96800","6.66420","0.01447"
"80.37600","6.69816","0.01435"
"80.78400","6.73224","0.01405"
"81.19200","6.76620","0.01498"
"81.60000","6.80016","0.01512"
"82.00800","6.83418","0.01529"
"82.41600","6.86826","0.01565"
"82.82400","6.90216","0.01566"
"83.23200","6.93618","0.01571"
"83.64000","6.97014","0.01527"
"84.04800","7.00422","0.01612"
"84.45600","7.03824","0.01619"
"84.86400","7.07227","0.01668"
"85.27200","7.10617","0.01581"
"85.68000","7.14025","0.01682"
"86.08800","7.17421","0.01651"
"86.49600","7.20823","0.01594"
"86.90400","7.24219","0.01671"
"87.31200","7.27621","0.01580"
"87.72000","7.31023","0.01604"
"88.12800","7.34419","0.01625"
"88.53600","7.37815","0.01726"
"88.94400","7.41223","0.01641"
"89.35200","7.44625","0.01764"
"89.76000","7.48027","0.01730"
"90.16800","7.51417","0.01760"
"90.57600","7.54819","0.01752"
"90.98400","7.58221","0.01731"
"91.39200","7.61623","0.01762"
"91.80000","7.65025","0.01779"
"92.20800","7.68421","0.01768"
"92.61600","7.71823","0.01717"
"93.02400","7.75225","0.01785"
"93.43200","7.78615","0.01736"
"93.84000","7.82017","0.01816"
"94.24800","7.85419","0.01826"
"94.65600","7.88821","0.01858"
"95.06400","7.92223","0.01814"
"95.47200","7.95619","0.01881"
"95.88000","7.99021","0.01828"
"96.28800","8.02423","0.01880"
"96.69600","8.05819","0.01892"
"97.10400","8.09215","0.01838"
"97.51200","8.12624","0.01875"
"97.92000","8.16025","0.01904"
"98.32800","8.19422","0.01962"
"98.73600","8.22818","0.01966"
"99.14400","8.26220","0.01844"
"99.55200","8.29622","0.01914"
"99.96000","8.33024","0.01907"
"100.36800","8.36420","0.01876"
"100.77600","8.39822","0.01919"
"101.18400","8.43224","0.01973"
"101.59200","8.46620","0.01927"
"102.00000","8.50022","0.02022"
"102.40800","8.53424","0.02009"
"102.81600","8.56826","0.01999"
"103.22400","8.60222","0.02038"
"103.63200","8.63618","0.02035"
"104.04000","8.67020","0.02039"
"104.44800","8.70422","0.02047"
"104.85600","8.73824","0.02056"
"105.26400","8.77226","0.02057"
"105.67200","8.80622","0.02070"
"106.08000","8.84024","0.02069"
"106.48800","8.87420","0.02109"
"106.89600","8.90822","0.02150"
"107.30400","8.94218","0.02052"
"107.71200","8.97626","0.02125"
"108.12000","9.01028","0.02175"
"108.52800","9.04418","0.02221"
"108.93600","9.07820","0.02218"
"109.34400","9.11216","0.02274"
"109.75200","9.14624","0.02265"
"110.16000","9.18021","0.02305"
"110.56800","9.21416","0.02264"
"110.97600","9.24824","0.02266"
"111.38400","9.28221","0.02351"
"111.79200","9.31623","0.02321"
"112.20000","9.35013","0.02322"
"112.60800","9.38421","0.02333"
"113.01600","9.41823","0.02365"
"113.42400","9.45219","0.02368"
"113.83200","9.48615","0.02323"
"114.24000","9.52017","0.02412"
"114.64800","9.55425","0.02358"
"115.05600","9.58821","0.02353"
"115.46400","9.62223","0.02398"
"115.87200","9.65625","0.02379"
"116.28000","9.69021","0.02394"
"116.68800","9.72423","0.02428"
"117.09600","9.75819","0.02414"
"117.50400","9.79221","0.02429"
"117.91200","9.82623","0.02464"
"118.32000","9.86025","0.02478"
"118.72800","9.89421","0.02431"
"119.13600","9.92817","0.02552"
"119.54400","9.96225","0.02508"
"119.95200","9.99621","0.02478"
"120.36000","10.03017","0.02481"
"120.76800","10.06419","0.02480"
"121.17600","10.09827","0.02457"
"121.58400","10.13223","0.02427"
"121.99200","10.16619","0.02401"
"122.40000","10.20015","0.02417"
"122.80800","10.23423","0.02439"
"123.21600","10.26819","0.02430"
"123.62400","10.30221","0.02230"
"124.03200","10.33618","0.02344"
"124.44000","10.37020","0.02316"
"124.84800","10.40421","0.02318"
"125.25600","10.43824","0.02342"
"125.66400","10.47214","0.02304"
"126.07200","10.50628","0.02305"
"126.48000","10.54024","0.02340"
"126.88800","10.57420","0.02297"
"127.29600","10.60816","0.02311"
"127.70400","10.64224","0.02317"
"128.11200","10.67626","0.02295"
"128.52000","10.71028","0.02345"
"128.92800","10.74424","0.02302"
"129.33600","10.77820","0.02344"
"129.74400","10.81222","0.02367"
"130.15200","10.84624","0.02390"
"130.56000","10.88014","0.02353"
"130.96800","10.91416","0.02389"
"131.37600","10.94824","0.02379"
"131.78400","10.98226","0.02370"
"132.19200","11.01616","0.02372"
"132.60000","11.05018","0.02433"
"133.00800","11.08420","0.02379"
"133.41600","11.11822","0.02350"
"133.82400","11.15224","0.02353"
"134.23200","11.18620","0.02237"
"134.64000","11.22022","0.02286"
"135.04800","11.25424","0.02150"
"135.45600","11.28820","0.02152"
"135.86400","11.32216","0.02157"
"136.27200","11.35625","0.02213"
"136.68000","11.39027","0.02240"
"137.08800","11.42428","0.02235"
"137.49600","11.45813","0.02239"
"137.90400","11.49221","0.02257"
"138.31200","11.52629","0.02239"
"138.72000","11.56025","0.02279"
"139.12800","11.59421","0.02253"
"139.53600","11.62823","0.02280"
"139.94400","11.66225","0.02283"
"140.35200","11.69621","0.02225"
"140.76000","11.73017","0.02259"
"141.16800","11.76419","0.02292"
"141.57600","11.79827","0.02288"
"141.98400","11.83223","0.02289"
"142.39200","11.86619","0.02279"
"142.80000","11.90021","0.02180"
"143.20800","11.93423","0.02145"
"143.61600","11.96825","0.02239"
"144.02400","12.00221","0.02197"
"144.43200","12.03617","0.02270"
"144.84000","12.07025","0.02239"
"145.24800","12.10421","0.02263"
"145.65600","12.13823","0.02235"
"146.06400","12.17219","0.02199"
"146.47200","12.20621","0.02257"
"146.88000","12.24029","0.02255"
"147.28800","12.27425","0.02251"
"147.69600","12.30815","0.02271"
"148.10400","12.34217","0.02293"
"148.51200","12.37619","0.02272"
"148.92000","12.41027","0.02209"
"149.32800","12.44417","0.02332"
"149.73600","12.47826","0.02273"
"150.14400","12.51228","0.02323"
"150.55200","12.54618","0.02242"
"150.96000","12.58014","0.02321"
"151.36800","12.61422","0.02348"
"151.77600","12.64824","0.02265"
"152.18400","12.68232","0.02344"
"152.59200","12.71622","0.02364"
"153.00000","12.75018","0.02363"
"153.40800","12.78420","0.02319"
"153.81600","12.81828","0.02441"
"154.22400","12.85224","0.02446"
"154.63200","12.88620","0.02462"
"155.04000","12.92028","0.02424"
"155.44800","12.95424","0.02431"
"155.85600","12.98820","0.02448"
"156.26400","13.02222","0.02482"
"156.67200","13.05624","0.02497"
"157.08000","13.09026","0.02424"
"157.48800","13.12422","0.02341"
"157.89600","13.15818","0.02160"
"158.30400","13.19226","0.01785"
"158.71200","13.22622","0.01806"
"159.12000","13.26024","0.01828"
"159.52800","13.29420","0.01837"
"159.93600","13.32828","0.01876"
"160.34400","13.36224","0.01813"
"160.75200","13.39620","0.01812"
"161.16000","13.43017","0.01817"
"161.56800","13.46419","0.01926"
"161.97600","13.49821","0.01836"
"162.38400","13.53228","0.01853"
"162.79200","13.56618","0.01915"
"163.20000","13.60021","0.01878"
"163.60800","13.63423","0.01973"
"164.01600","13.66819","0.01836"
"164.42400","13.70215","0.01967"
"164.83200","13.73623","0.01981"
"165.24000","13.77025","0.01980"
"165.64800","13.80421","0.02032"
"166.05600","13.83817","0.02043"
"166.46400","13.87219","0.01980"
"166.87200","13.90627","0.02025"
"167.28000","13.94023","0.02053"
"167.68800","13.97425","0.02045"
"168.09600","14.00821","0.02118"
"168.50400","14.04223","0.02115"
"168.91200","14.07625","0.02203"
"169.32000","14.11021","0.02216"
"169.72800","14.14417","0.02135"
"170.13600","14.17825","0.02192"
"170.54400","14.21221","0.02161"
"170.95200","14.24623","0.02211"
"171.36000","14.28019","0.02175"
"171.76800","14.31421","0.02179"
"172.17600","14.34823","0.02193"
"172.58400","14.38225","0.02247"
"172.99200","14.41621","0.02231"
"173.40000","14.45023","0.02262"
"173.80800","14.48425","0.02254"
"174.21600","14.51821","0.02266"
"174.62400","14.55218","0.02299"
"175.03200","14.58625","0.02313"
"175.44000","14.62027","0.02338"
"175.84800","14.65423","0.02319"
"176.25600","14.68814","0.02378"
"176.66400","14.72216","0.02368"
"177.07200","14.75624","0.02417"
"177.48000","14.79020","0.02465"
"177.88800","14.82422","0.02448"
"178.29600","14.85818","0.02405"
"178.70400","14.89226","0.02449"
"179.11200","14.92622","0.02461"
"179.52000","14.96018","0.02442"
"179.92800","14.99420","0.02497"
"180.33600","15.02822","0.02498"
"180.74400","15.06230","0.02505"
"181.15200","15.09620","0.02564"
"181.56000","15.13016","0.02562"
"181.96800","15.16424","0.02537"
"182.37600","15.19826","0.02569"
"182.78400","15.23216","0.02612"
"183.19200","15.26618","0.02569"
"183.60000","15.30026","0.02593"
"184.00800","15.33422","0.02631"
"184.41600","15.36818","0.02657"
"184.82400","15.40214","0.02642"
"185.23200","15.43622","0.02688"
"185.64000","15.47024","0.02690"
"186.04800","15.50426","0.02687"
"186.45600","15.53816","0.02729"
"186.86400","15.57218","0.02690"
"187.27200","15.60626","0.02733"
"187.68000","15.64022","0.02778"
"188.08800","15.67418","0.02764"
"188.49600","15.70826","0.02787"
"188.90400","15.74228","0.02755"
"189.31200","15.77625","0.02748"
"189.72000","15.81015","0.02754"
"190.12800","15.84423","0.02752"
"190.53600","15.87825","0.02771"
"190.94400","15.91227","0.02804"
"191.35200","15.94623","0.02802"
"191.76000","15.98019","0.02824"
"192.16800","16.01421","0.02812"
"192.57600","16.04823","0.02867"
"192.98400","16.08219","0.02893"
"193.39200","16.11621","0.02878"
"193.80000","16.15023","0.02874"
"194.20800","16.18425","0.02958"
"194.61600","16.21821","0.02942"
"195.02400","16.25223","0.02907"
"195.43200","16.28619","0.02912"
"195.84000","16.32021","0.02975"
"196.24800","16.35423","0.02919"
"196.65600","16.38819","0.02937"
"197.06400","16.42221","0.02936"
"197.47200","16.45617","0.02967"
"197.88000","16.49025","0.02956"
"198.28800","16.52415","0.02972"
"198.69600","16.55823","0.02991"
"199.10400","16.59225","0.02996"
"199.51200","16.62621","0.03007"
"199.92000","16.66017","0.02977"
"200.32800","16.69419","0.02958"
"200.73600","16.72821","0.02969"
"201.14400","16.76223","0.02967"
"201.55200","16.79620","0.03006"
"201.96000","16.83022","0.02950"
"202.36800","16.86418","0.03014"
"202.77600","16.89826","0.02977"
"203.18400","16.93221","0.02946"
"203.59200","16.96618","0.03014"
"204.00000","17.00020","0.02993"
"204.40800","17.03428","0.02990"
"204.81600","17.06818","0.03060"
"205.22400","17.10214","0.02987"
"205.63200","17.13622","0.02982"
"206.04000","17.17024","0.02999"
"206.44800","17.20420","0.03017"
"206.85600","17.23816","0.03008"
"207.26400","17.27224","0.03046"
"207.67200","17.30626","0.03060"
"208.08000","17.34016","0.03077"
"208.48800","17.37418","0.03071"
"208.89600","17.40820","0.03027"
"209.30400","17.44228","0.03021"
"209.71200","17.47624","0.03056"
"210.12000","17.51014","0.02986"
"210.52800","17.54422","0.03057"
"210.93600","17.57824","0.03038"
"211.34400","17.61220","0.03077"
"211.75200","17.64622","0.03043"
"212.16000","17.68024","0.03080"
"212.56800","17.71420","0.03095"
"212.97600","17.74822","0.03017"
"213.38400","17.78218","0.03079"
"213.79200","17.81620","0.03062"
"214.20000","17.85028","0.03093"
"214.60800","17.88424","0.03085"
"215.01600","17.91821","0.03133"
"215.42400","17.95217","0.03081"
"215.83200","17.98625","0.03139"
"216.24000","18.02027","0.03133"
"216.64800","18.05417","0.03157"
"217.05600","18.08819","0.03097"
"217.46400","18.12227","0.03073"
"217.87200","18.15623","0.03038"
"218.28000","18.19019","0.03133"
"218.68800","18.22421","0.03094"
"219.09600","18.25823","0.03085"
"219.50400","18.29225","0.03112"
"219.91200","18.32621","0.03124"
"220.32000","18.36017","0.03062"
"220.72800","18.39419","0.03082"
"221.13600","18.42821","0.03143"
"221.54400","18.46223","0.03148"
"221.95200","18.49619","0.03140"
"222.36000","18.53027","0.03105"
"222.76800","18.56423","0.03106"
"223.17600","18.59825","0.03160"
"223.58400","18.63215","0.03160"
"223.99200","18.66623","0.03167"
"224.40000","18.70025","0.03244"
"224.80800","18.73427","0.03148"
"225.21600","18.76818","0.03186"
"225.62400","18.80219","0.03146"
"226.03200","18.83621","0.03153"
"226.44000","18.87024","0.03175"
"226.84800","18.90419","0.03165"
"227.25600","18.93822","0.03199"
"227.66400","18.97223","0.03220"
"228.07200","19.00626","0.03158"
"228.48000","19.04016","0.03221"
"228.88800","19.07418","0.03121"
"229.29600","19.10820","0.03155"
"229.70400","19.14222","0.03112"
"230.11200","19.17618","0.03113"
"230.52000","19.21020","0.03162"
"230.92800","19.24422","0.03111"
"231.33600","19.27824","0.03124"
"231.74400","19.31226","0.03154"
"232.15200","19.34616","0.03136"
"232.56000","19.38024","0.03134"
"232.96800","19.41432","0.03184"
"233.37600","19.44822","0.03164"
"233.78400","19.48218","0.03115"
"234.19200","19.51620","0.03179"
"234.60000","19.55022","0.03119"
"235.00800","19.58424","0.03198"
"235.41600","19.61820","0.03184"
"235.82400","19.65222","0.03153"
"236.23200","19.68618","0.03182"
"236.64000","19.72026","0.03185"
"237.04800","19.75416","0.03225"
"237.45600","19.78824","0.03105"
"237.86400","19.82226","0.03131"
"238.27200","19.85628","0.03096"
"238.68000","19.89018","0.03092"
"239.08800","19.92420","0.03063"
"239.49600","19.95828","0.03017"
"239.90400","19.99224","0.03045"
"240.31200","20.02620","0.03073"
"240.72000","20.06017","0.03064"
"241.12800","20.09425","0.03057"
"241.53600","20.12827","0.03065"
"241.94400","20.16217","0.03082"
"242.35200","20.19619","0.03081"
"242.76000","20.23026","0.03075"
"243.16800","20.26423","0.02962"
"243.57600","20.29819","0.02959"
"243.98400","20.33221","0.02959"
"244.39200","20.36623","0.02969"
"244.80000","20.40019","0.03040"
"245.20800","20.43421","0.02982"
"245.61600","20.46817","0.02938"
"246.02400","20.50225","0.02985"
"246.43200","20.53621","0.02996"
"246.84000","20.57023","0.03010"
"247.24800","20.60419","0.02944"
"247.65600","20.63815","0.03053"
"248.06400","20.67223","0.02938"
"248.47200","20.70625","0.02954"
"248.88000","20.74021","0.02957"
"249.28800","20.77417","0.02949"
"249.69600","20.80825","0.03001"
"250.10400","20.84221","0.02986"
"250.51200","20.87611","0.03019"
"250.92000","20.91019","0.03022"
"251.32800","20.94427","0.03010"
"251.73600","20.97824","0.03001"
"252.14400","21.01219","0.03049"
"252.55200","21.04622","0.03034"
"252.96000","21.08023","0.03030"
"253.36800","21.11426","0.03047"
"253.77600","21.14821","0.03062"
"254.18400","21.18224","0.03071"
"254.59200","21.21620","0.03051"
"255.00000","21.25021","0.03124"
"255.40800","21.28418","0.03098"
"255.81600","21.31820","0.03029"
"256.22400","21.35222","0.03056"
"256.63200","21.38624","0.03081"
"257.04000","21.42026","0.03109"
"257.44800","21.45416","0.03158"
"257.85600","21.48824","0.03171"
"258.26400","21.52220","0.03229"
"258.67200","21.55622","0.03209"
"259.08000","21.59018","0.03246"
"259.48800","21.62420","0.03247"
"259.89600","21.65822","0.03250"
"260.30400","21.69218","0.03169"
"260.71200","21.72614","0.03276"
"261.12000","21.76028","0.03306"
"261.52800","21.79430","0.03312"
"261.93600","21.82826","0.03342"
"262.34400","21.86216","0.03247"
"262.75200","21.89618","0.03323"
"263.16000","21.93020","0.03342"
"263.56800","21.96422","0.03307"
"263.97600","21.99818","0.03290"
"264.38400","22.03221","0.03317"
"264.79200","22.06623","0.03291"
"265.20000","22.10018","0.03287"
"265.60800","22.13415","0.03325"
"266.01600","22.16816","0.03320"
"266.42400","22.20225","0.01926"
"266.83200","22.23627","0.01735"
"267.24000","22.27023","0.01814"
"267.64800","22.30419","0.01861"
"268.05600","22.33827","0.01877"
"268.46400","22.37223","0.01804"
"268.87200","22.40619","0.01832"
"269.28000","22.44021","0.01893"
"269.68800","22.47429","0.01966"
"270.09600","22.50825","0.02041"
"270.50400","22.54221","0.02046"
"270.91200","22.57617","0.02096"
"271.32000","22.61025","0.02124"
"271.72800","22.64421","0.02235"
"272.13600","22.67823","0.02219"
"272.54400","22.71219","0.02191"
"272.95200","22.74615","0.02276"
"273.36000","22.78023","0.02223"
"273.76800","22.81425","0.02264"
"274.17600","22.84821","0.02292"
"274.58400","22.88229","0.02306"
"274.99200","22.91625","0.02332"
"275.40000","22.95021","0.02397"
"275.80800","22.98417","0.02364"
"276.21600","23.01819","0.02369"
"276.62400","23.05227","0.02434"
"277.03200","23.08629","0.02455"
"277.44000","23.12025","0.02467"
"277.84800","23.15415","0.02517"
"278.25600","23.18823","0.02539"
"278.66400","23.22225","0.02468"
"279.07200","23.25622","0.02487"
"279.48000","23.29018","0.02505"
"279.88800","23.32426","0.02512"
"280.29600","23.35828","0.02420"
"280.70400","23.39224","0.02383"
"281.11200","23.42620","0.02414"
"281.52000","23.46022","0.02416"
"281.92800","23.49424","0.02474"
"282.33600","23.52826","0.02532"
"282.74400","23.56216","0.02472"
"283.15200","23.59624","0.02503"
"283.56000","23.63020","0.02533"
"283.96800","23.66422","0.02547"
"284.37600","23.69818","0.02558"
"284.78400","23.73220","0.02561"
"285.19200","23.76628","0.02582"
"285.60000","23.80024","0.02657"
"286.00800","23.83414","0.02679"
"286.41600","23.86822","0.02662"
"286.82400","23.90218","0.02709"
"287.23200","23.93620","0.02727"
"287.64000","23.97022","0.02749"
"288.04800","24.00424","0.02752"
"288.45600","24.03826","0.02767"
"288.86400","24.07222","0.02683"
"289.27200","24.10618","0.02708"
"289.68000","24.14020","0.02691"
"290.08800","24.17422","0.02708"
"290.49600","24.20824","0.02660"
"290.90400","24.24220","0.02822"
"291.31200","24.27616","0.02792"
"291.72000","24.31025","0.02596"
"292.12800","24.34426","0.02688"
"292.53600","24.37823","0.02709"
"292.94400","24.41225","0.02781"
"293.35200","24.44627","0.02785"
"293.76000","24.48022","0.02779"
"294.16800","24.51419","0.02840"
"294.57600","24.54815","0.02855"
"294.98400","24.58223","0.02846"
"295.39200","24.61631","0.02888"
"295.80000","24.65021","0.02941"
"296.20800","24.68417","0.02985"
"296.61600","24.71819","0.02993"
"297.02400","24.75215","0.03024"
"297.43200","24.78623","0.03050"
"297.84000","24.82025","0.03009"
"298.24800","24.85427","0.03041"
"298.65600","24.88823","0.03025"
"299.06400","24.92225","0.03066"
"299.47200","24.95621","0.03055"
"299.88000","24.99023","0.03142"
"300.28800","25.02425","0.03117"
"300.69600","25.05827","0.03136"
"301.10400","25.09217","0.03161"
"301.51200","25.12619","0.03179"
"301.92000","25.16021","0.03181"
"302.32800","25.19429","0.03180"
"302.73600","25.22820","0.03196"
"303.14400","25.26215","0.03205"
"303.55200","25.29630","0.03218"
"303.96000","25.33025","0.03220"
"304.36800","25.36416","0.03192"
"304.77600","25.39812","0.03244"
"305.18400","25.43226","0.03251"
"305.59200","25.46627","0.03216"
"306.00000","25.50024","0.03266"
"306.40800","25.53420","0.03276"
"306.81600","25.56821","0.03258"
"307.22400","25.60224","0.03255"
"307.63200","25.63620","0.03256"
"308.04000","25.67022","0.03307"
"308.44800","25.70424","0.03262"
"308.85600","25.73826","0.03283"
"309.26400","25.77222","0.03293"
"309.67200","25.80612","0.03337"
"310.08000","25.84026","0.03337"
"310.48800","25.87422","0.03306"
"310.89600","25.90830","0.03339"
"311.30400","25.94220","0.03359"
"311.71200","25.97622","0.03385"
"312.12000","26.01024","0.03410"
"312.52800","26.04426","0.03359"
"312.93600","26.07822","0.03379"
"313.34400","26.11224","0.03359"
"313.75200","26.14626","0.03454"
"314.16000","26.18022","0.03418"
"314.56800","26.21412","0.03455"
"314.97600","26.24820","0.03423"
"315.38400","26.28222","0.03541"
"315.79200","26.31624","0.03493"
"316.20000","26.35021","0.03529"
"316.60800","26.38422","0.03513"
"317.01600","26.41825","0.03557"
"317.42400","26.45221","0.03577"
"317.83200","26.48616","0.03559"
"318.24000","26.52013","0.03584"
"318.64800","26.55426","0.03634"
"319.05600","26.58829","0.03659"
"319.46400","26.62219","0.03631"
"319.87200","26.65621","0.03619"
"320.28000","26.69023","0.03612"
"320.68800","26.72425","0.03643"
"321.09600","26.75827","0.03602"
"321.50400","26.79223","0.03622"
"321.91200","26.82625","0.03613"
"322.32000","26.86021","0.03634"
"322.72800","26.89423","0.03641"
"323.13600","26.92819","0.03679"
"323.54400","26.96227","0.03707"
"323.95200","26.99629","0.03676"
"324.36000","27.03025","0.03673"
"324.76800","27.06421","0.03761"
"325.17600","27.09817","0.03704"
"325.58400","27.13225","0.03715"
"325.99200","27.16627","0.03662"
"326.40000","27.20023","0.03708"
"326.80800","27.23419","0.03740"
"327.21600","27.26821","0.03692"
"327.62400","27.30223","0.03705"
"328.03200","27.33619","0.03694"
"328.44000","27.37021","0.03550"
"328.84800","27.40423","0.03518"
"329.25600","27.43825","0.03629"
"329.66400","27.47221","0.03638"
"330.07200","27.50617","0.03628"
"330.48000","27.54025","0.03634"
"330.88800","27.57416","0.03641"
"331.29600","27.60824","0.03649"
"331.70400","27.64226","0.03706"
"332.11200","27.67622","0.03734"
"332.52000","27.71024","0.03729"
"332.92800","27.74420","0.03746"
"333.33600","27.77816","0.03772"
"333.74400","27.81218","0.03804"
"334.15200","27.84626","0.03836"
"334.56000","27.88028","0.03816"
"334.96800","27.91418","0.03873"
"335.37600","27.94820","0.03821"
"335.78400","27.98222","0.03772"
"336.19200","28.01624","0.03818"
"336.60000","28.05020","0.03786"
"337.00800","28.08428","0.03774"
"337.41600","28.11830","0.03786"
"337.82400","28.15220","0.03786"
"338.23200","28.18616","0.03821"
"338.64000","28.22018","0.03772"
"339.04800","28.25426","0.03764"
"339.45600","28.28822","0.03663"
"339.86400","28.32218","0.03401"
"340.27200","28.35620","0.03370"
"340.68000","28.39022","0.03448"
"341.08800","28.42424","0.03172"
"341.49600","28.45820","0.03066"
"341.90400","28.49217","0.02981"
"342.31200","28.52624","0.02913"
"342.72000","28.56026","0.02839"
"343.12800","28.59422","0.02844"
"343.53600","28.62819","0.02800"
"343.94400","28.66221","0.02858"
"344.35200","28.69623","0.02932"
"344.76000","28.73025","0.02993"
"345.16800","28.76421","0.02956"
"345.57600","28.79823","0.03003"
"345.98400","28.83219","0.03020"
"346.39200","28.86621","0.03025"
"346.80000","28.90023","0.03065"
"347.20800","28.93425","0.03037"
"347.61600","28.96827","0.03026"
"348.02400","29.00223","0.03028"
"348.43200","29.03613","0.03033"
"348.84000","29.07021","0.03044"
"349.24800","29.10423","0.03065"
"349.65600","29.13825","0.03150"
"350.06400","29.17221","0.03110"
"350.47200","29.20623","0.02839"
"350.88000","29.24019","0.02781"
"351.28800","29.27421","0.02808"
"351.69600","29.30817","0.02839"
"352.10400","29.34219","0.02781"
"352.51200","29.37621","0.02890"
"352.92000","29.41023","0.02756"
"353.32800","29.44419","0.02759"
"353.73600","29.47816","0.02782"
"354.14400","29.51217","0.02831"
"354.55200","29.54626","0.02828"
"354.96000","29.58021","0.02810"
"355.36800","29.61418","0.02867"
"355.77600","29.64825","0.02842"
"356.18400","29.68222","0.02905"
"356.59200","29.71618","0.02923"
"357.00000","29.75020","0.02916"
"357.40800","29.78422","0.02935"
"357.81600","29.81830","0.02990"
"358.22400","29.85226","0.02953"
"358.63200","29.88616","0.03027"
"359.04000","29.92018","0.02988"
"359.44800","29.95426","0.02975"
"359.85600","29.98822","0.03002"
"360.26400","30.02218","0.03055"
"360.67200","30.05620","0.03023"
"361.08000","30.09022","0.03058"
"361.48800","30.12424","0.03113"
"361.89600","30.15814","0.03077"
"362.30400","30.19222","0.03099"
"362.71200","30.22624","0.03116"
"363.12000","30.26026","0.03127"
"363.52800","30.29416","0.03139"
"363.93600","30.32818","0.03095"
"364.34400","30.36226","0.03095"
"364.75200","30.39628","0.03091"
"365.16000","30.43018","0.03092"
"365.56800","30.46420","0.03015"
"365.97600","30.49828","0.03015"
"366.38400","30.53224","0.03052"
"366.79200","30.56614","0.03028"
"367.20000","30.60022","0.03074"
"367.60800","30.63418","0.03068"
"368.01600","30.66827","0.03105"
"368.42400","30.70217","0.03147"
"368.83200","30.73612","0.03174"
"369.24000","30.77021","0.03141"
"369.64800","30.80422","0.03222"
"370.05600","30.83819","0.03211"
"370.46400","30.87215","0.03155"
"370.87200","30.90629","0.03228"
"371.28000","30.94025","0.03210"
"371.68800","30.97421","0.03201"
"372.09600","31.00817","0.03165"
"372.50400","31.04225","0.03179"
"372.91200","31.07627","0.03214"
"373.32000","31.11023","0.03170"
"373.72800","31.14419","0.03093"
"374.13600","31.17821","0.03109"
"374.54400","31.21223","0.03087"
"374.95200","31.24619","0.03115"
"375.36000","31.28015","0.03069"
"375.76800","31.31423","0.03056"
"376.17600","31.34819","0.03020"
"376.58400","31.38221","0.03021"
"376.99200","31.41617","0.03019"
"377.40000","31.45019","0.03095"
"377.80800","31.48421","0.03071"
"378.21600","31.51829","0.03068"
"378.62400","31.55225","0.03167"
"379.03200","31.58621","0.03187"
"379.44000","31.62023","0.03176"
"379.84800","31.65425","0.03143"
"380.25600","31.68821","0.03148"
"380.66400","31.72217","0.03156"
"381.07200","31.75625","0.03078"
"381.48000","31.79028","0.02961"
"381.88800","31.82423","0.03015"
"382.29600","31.85819","0.03055"
"382.70400","31.89221","0.02991"
"383.11200","31.92623","0.02996"
"383.52000","31.96026","0.03036"
"383.92800","31.99416","0.03036"
"384.33600","32.02824","0.02991"
"384.74400","32.06219","0.03043"
"385.15200","32.09628","0.03078"
"385.56000","32.13024","0.03087"
"385.96800","32.16420","0.03041"
"386.37600","32.19828","0.03063"
"386.78400","32.23230","0.03096"
"387.19200","32.26614","0.03150"
"387.60000","32.30022","0.03094"
"388.00800","32.33418","0.03073"
"388.41600","32.36826","0.03143"
"388.82400","32.40216","0.03143"
"389.23200","32.43618","0.03057"
"389.64000","32.47026","0.03074"
"390.04800","32.50422","0.03111"
"390.45600","32.53818","0.03093"
"390.86400","32.57214","0.03158"
"391.27200","32.60622","0.03130"
"391.68000","32.64030","0.03150"
"392.08800","32.67426","0.03167"
"392.49600","32.70816","0.03145"
"392.90400","32.74224","0.03152"
"393.31200","32.77620","0.03153"
"393.72000","32.81022","0.03134"
"394.12800","32.84418","0.03135"
"394.53600","32.87827","0.03128"
"394.94400","32.91222","0.03157"
"395.35200","32.94624","0.03145"
"395.76000","32.98014","0.03108"
"396.16800","33.01423","0.03191"
"396.57600","33.04824","0.03183"
"396.98400","33.08221","0.03199"
"397.39200","33.11617","0.03240"
"397.80000","33.15012","0.03254"
"398.20800","33.18421","0.03272"
"398.61600","33.21823","0.03220"
"399.02400","33.25225","0.03243"
"399.43200","33.28627","0.03271"
"399.84000","33.32023","0.03296"
"400.24800","33.35425","0.03244"
"400.65600","33.38821","0.03220"
"401.06400","33.42223","0.03245"
"401.47200","33.45625","0.03214"
"401.88000","33.49027","0.03194"
"402.28800","33.52423","0.03215"
"402.69600","33.55825","0.03205"
"403.10400","33.59227","0.03225"
"403.51200","33.62623","0.03173"
"403.92000","33.66013","0.03177"
"404.32800","33.69415","0.03206"
"404.73600","33.72823","0.03155"
"405.14400","33.76225","0.03113"
"405.55200","33.79622","0.03127"
"405.96000","33.83017","0.03183"
"406.36800","33.86419","0.03122"
"406.77600","33.89821","0.02973"
"407.18400","33.93224","0.02931"
"407.59200","33.96619","0.02933"
"408.00000","34.00021","0.02920"
"408.40800","34.03417","0.02920"
"408.81600","34.06826","0.02925"
"409.22400","34.10216","0.03014"
"409.63200","34.13623","0.02947"
"410.04000","34.17025","0.02945"
"410.44800","34.20422","0.02922"
"410.85600","34.23818","0.02918"
"411.26400","34.27214","0.02904"
"411.67200","34.30622","0.02871"
"412.08000","34.34024","0.02829"
"412.48800","34.37420","0.02765"
"412.89600","34.40822","0.02759"
"413.30400","34.44224","0.02775"
"413.71200","34.47626","0.02816"
"414.12000","34.51016","0.02830"
"414.52800","34.54418","0.02802"
"414.93600","34.57826","0.02799"
"415.34400","34.61228","0.02823"
"415.75200","34.64618","0.02723"
"416.16000","34.68020","0.02813"
"416.56800","34.71422","0.02788"
"416.97600","34.74818","0.02756"
"417.38400","34.78220","0.02701"
"417.79200","34.81622","0.02769"
"418.20000","34.85024","0.02791"
"418.60800","34.88420","0.02776"
"419.01600","34.91816","0.02799"
"419.42400","34.95218","0.02802"
"419.83200","34.98621","0.02817"
"420.24000","35.02023","0.02852"
"420.64800","35.05424","0.02768"
"421.05600","35.08814","0.02752"
"421.46400","35.12216","0.02732"
"421.87200","35.15625","0.02779"
"422.28000","35.19020","0.02770"
"422.68800","35.22417","0.02822"
"423.09600","35.25824","0.02794"
"423.50400","35.29227","0.02822"
"423.91200","35.32617","0.02790"
"424.32000","35.36013","0.02812"
"424.72800","35.39421","0.02823"
"425.13600","35.42823","0.02835"
"425.54400","35.46219","0.02819"
"425.95200","35.49621","0.02829"
"426.36000","35.53023","0.02710"
"426.76800","35.56419","0.02646"
"427.17600","35.59827","0.02736"
"427.58400","35.63217","0.02745"
"427.99200","35.66619","0.02727"
"428.40000","35.70021","0.02683"
"428.80800","35.73423","0.02673"
"429.21600","35.76819","0.02656"
"429.62400","35.80221","0.02746"
"430.03200","35.83623","0.02721"
"430.44000","35.87025","0.02679"
"430.84800","35.90427","0.02653"
"431.25600","35.93818","0.02750"
"431.66400","35.97219","0.02673"
"432.07200","36.00621","0.02678"
"432.48000","36.04023","0.02677"
"432.88800","36.07413","0.02645"
"433.29600","36.10822","0.02616"
"433.70400","36.14229","0.02643"
"434.11200","36.17625","0.02659"
"434.52000","36.21016","0.02577"
"434.92800","36.24417","0.02629"
"435.33600","36.27819","0.02631"
"435.74400","36.31221","0.02697"
"436.15200","36.34624","0.02645"
"436.56000","36.38020","0.02715"
"436.96800","36.41422","0.02761"
"437.37600","36.44824","0.02746"
"437.78400","36.48220","0.02757"
"438.19200","36.51616","0.02746"
"438.60000","36.55024","0.02712"
"439.00800","36.58426","0.02622"
"439.41600","36.61816","0.02627"
"439.82400","36.65218","0.02573"
"440.23200","36.68620","0.02573"
"440.64000","36.72022","0.02600"
"441.04800","36.75418","0.02634"
"441.45600","36.78820","0.02639"
"441.86400","36.82222","0.02651"
"442.27200","36.85618","0.02713"
"442.68000","36.89020","0.02626"
"443.08800","36.92416","0.02668"
"443.49600","36.95824","0.02683"
"443.90400","36.99226","0.02715"
"444.31200","37.02622","0.02751"
"444.72000","37.06018","0.02626"
"445.12800","37.09414","0.02604"
"445.53600","37.12822","0.02614"
"445.94400","37.16219","0.02613"
"446.35200","37.19614","0.02614"
"446.76000","37.23022","0.02604"
"447.16800","37.26419","0.02574"
"447.57600","37.29821","0.02574"
"447.98400","37.33211","0.02636"
"448.39200","37.36618","0.02622"
"448.80000","37.40027","0.02596"
"449.20800","37.43429","0.02650"
"449.61600","37.46819","0.02606"
"450.02400","37.50221","0.02597"
"450.43200","37.53622","0.02627"
"450.84000","37.57025","0.02626"
"451.24800","37.60421","0.02616"
"451.65600","37.63823","0.02647"
"452.06400","37.67225","0.02679"
"452.47200","37.70627","0.02640"
"452.88000","37.74017","0.02649"
"453.28800","37.77419","0.02670"
"453.69600","37.80821","0.02677"
"454.10400","37.84223","0.02708"
"454.51200","37.87625","0.02640"
"454.92000","37.91015","0.02676"
"455.32800","37.94423","0.02633"
"455.73600","37.97819","0.02667"
"456.14400","38.01221","0.02676"
"456.55200","38.04617","0.02692"
"456.96000","38.08025","0.02637"
"457.36800","38.11421","0.02632"
"457.77600","38.14817","0.02648"
"458.18400","38.18214","0.02631"
"458.59200","38.21621","0.02695"
"459.00000","38.25029","0.02661"
"459.40800","38.28425","0.02663"
"459.81600","38.31816","0.02616"
"460.22400","38.35224","0.02654"
"460.63200","38.38620","0.02677"
"461.04000","38.42028","0.02677"
"461.44800","38.45417","0.02694"
"461.85600","38.48826","0.02651"
"462.26400","38.52222","0.02680"
"462.67200","38.55624","0.02711"
"463.08000","38.59014","0.02649"
"463.48800","38.62416","0.02636"
"463.89600","38.65824","0.02587"
"464.30400","38.69226","0.02573"
"464.71200","38.72622","0.02631"
"465.12000","38.76024","0.02615"
"465.52800","38.79426","0.02610"
"465.93600","38.82822","0.02562"
"466.34400","38.86218","0.02514"
"466.75200","38.89620","0.02387"
"467.16000","38.93028","0.02347"
"467.56800","38.96424","0.02244"
"467.97600","38.99820","0.02280"
"468.38400","39.03216","0.02314"
"468.79200","39.06624","0.02256"
"469.20000","39.10020","0.02362"
"469.60800","39.13422","0.02257"
"470.01600","39.16824","0.02293"
"470.42400","39.20220","0.02323"
"470.83200","39.23616","0.02289"
"471.24000","39.27018","0.02328"
"471.64800","39.30415","0.02311"
"472.05600","39.33822","0.02224"
"472.46400","39.37224","0.02227"
"472.87200","39.40627","0.02225"
"473.28000","39.44010","0.02234"
"473.68800","39.47419","0.02289"
"474.09600","39.50820","0.02248"
"474.50400","39.54223","0.02350"
"474.91200","39.57618","0.02257"
"475.32000","39.61021","0.02283"
"475.72800","39.64428","0.02349"
"476.13600","39.67825","0.02263"
"476.54400","39.71221","0.02261"
"476.95200","39.74617","0.02294"
"477.36000","39.78025","0.02281"
"477.76800","39.81427","0.02267"
"478.17600","39.84823","0.02317"
"478.58400","39.88219","0.02339"
"478.99200","39.91621","0.02322"
"479.40000","39.95023","0.02343"
"479.80800","39.98425","0.02330"
"480.21600","40.01821","0.02312"
"480.62400","40.05223","0.02358"
"481.03200","40.08625","0.02393"
"481.44000","40.12020","0.02371"
"481.84800","40.15417","0.02238"
"482.25600","40.18825","0.02190"
"482.66400","40.22221","0.02201"
"483.07200","40.25629","0.02277"
"483.48000","40.29013","0.02269"
"483.88800","40.32421","0.02305"
"484.29600","40.35823","0.02254"
"484.70400","40.39219","0.02296"
"485.11200","40.42621","0.02165"
"485.52000","40.46023","0.02174"
"485.92800","40.49426","0.02199"
"486.33600","40.52822","0.02190"
"486.74400","40.56211","0.02232"
"487.15200","40.59620","0.02223"
"487.56000","40.63022","0.02206"
"487.96800","40.66430","0.02179"
"488.37600","40.69820","0.02181"
"488.78400","40.73222","0.02193"
"489.19200","40.76624","0.02198"
"489.60000","40.80026","0.02260"
"490.00800","40.83421","0.02239"
"490.41600","40.86818","0.02245"
"490.82400","40.90226","0.02235"
"491.23200","40.93622","0.02230"
"491.64000","40.97012","0.02178"
"492.04800","41.00420","0.02237"
"492.45600","41.03822","0.02209"
"492.86400","41.07224","0.02277"
"493.27200","41.10620","0.02295"
"493.68000","41.14016","0.02296"
"494.08800","41.17424","0.02242"
"494.49600","41.20820","0.02236"
"494.90400","41.24222","0.02332"
"495.31200","41.27618","0.02245"
"495.72000","41.31026","0.02312"
"496.12800","41.34423","0.02328"
"496.53600","41.37825","0.02262"
"496.94400","41.41214","0.02344"
"497.35200","41.44622","0.02327"
"497.76000","41.48024","0.02285"
"498.16800","41.51421","0.02251"
"498.57600","41.54822","0.02357"
"498.98400","41.58218","0.02316"
"499.39200","41.61620","0.02366"
"499.80000","41.65023","0.02335"
"500.20800","41.68413","0.02262"
"500.61600","41.71821","0.02248"
"501.02400","41.75223","0.02301"
"501.43200","41.78619","0.02272"
"501.84000","41.82021","0.02219"
"502.24800","41.85416","0.02268"
"502.65600","41.88825","0.02230"
"503.06400","41.92220","0.02234"
"503.47200","41.95623","0.02235"
"503.88000","41.99019","0.02255"
"504.28800","42.02421","0.02219"
"504.69600","42.05823","0.02232"
"505.10400","42.09224","0.02203"
"505.51200","42.12621","0.02193"
"505.92000","42.16017","0.02217"
"506.32800","42.19425","0.02173"
"506.73600","42.22821","0.02242"
"507.14400","42.26217","0.02189"
"507.55200","42.29613","0.02262"
"507.96000","42.33021","0.02191"
"508.36800","42.36417","0.02220"
"508.77600","42.39813","0.02188"
"509.18400","42.43222","0.02259"
"509.59200","42.46623","0.02195"
"510.00000","42.50019","0.02285"
"510.40800","42.53415","0.02215"
"510.81600","42.56824","0.02252"
"511.22400","42.60226","0.02196"
"511.63200","42.63628","0.02258"
"512.04000","42.67017","0.02210"
"512.44800","42.70419","0.02235"
"512.85600","42.73828","0.02240"
"513.26400","42.77230","0.02258"
"513.67200","42.80620","0.02272"
"514.08000","42.84015","0.02231"
"514.48800","42.87424","0.02316"
"514.89600","42.90820","0.02226"
"515.30400","42.94222","0.02248"
"515.71200","42.97618","0.02210"
"516.12000","43.01026","0.02232"
"516.52800","43.04428","0.02299"
"516.93600","43.07824","0.02280"
"517.34400","43.11214","0.02301"
"517.75200","43.14622","0.02305"
"518.16000","43.18024","0.02376"
"518.56800","43.21420","0.02324"
"518.97600","43.24822","0.02329"
"519.38400","43.28230","0.02261"
"519.79200","43.31627","0.02219"
"520.20000","43.35022","0.02306"
"520.60800","43.38418","0.02318"
"521.01600","43.41820","0.02351"
"521.42400","43.45222","0.02321"
"521.83200","43.48619","0.02254"
"522.24000","43.52015","0.02231"
"522.64800","43.55423","0.02276"
"523.05600","43.58818","0.02220"
"523.46400","43.62220","0.02274"
"523.87200","43.65616","0.02257"
"524.28000","43.69025","0.02239"
"524.68800","43.72420","0.02229"
"525.09600","43.75822","0.02312"
"525.50400","43.79219","0.02246"
"525.91200","43.82621","0.02252"
"526.32000","43.86023","0.02295"
"526.72800","43.89424","0.02247"
"527.13600","43.92821","0.02270"
"527.54400","43.96217","0.02268"
"527.95200","43.99625","0.02340"
"528.36000","44.03021","0.02323"
"528.76800","44.06417","0.02287"
"529.17600","44.09819","0.02284"
"529.58400","44.13221","0.02295"
"529.99200","44.16623","0.02245"
"530.40000","44.20019","0.02297"
"530.80800","44.23421","0.02266"
"531.21600","44.26823","0.02214"
"531.62400","44.30219","0.02255"
"532.03200","44.33627","0.02168"
"532.44000","44.37017","0.02193"
"532.84800","44.40425","0.02191"
"533.25600","44.43821","0.02170"
"533.66400","44.47223","0.02157"
"534.07200","44.50613","0.02158"
"534.48000","44.54021","0.02163"
"534.88800","44.57423","0.02104"
"535.29600","44.60825","0.02215"
"535.70400","44.64215","0.02143"
"536.11200","44.67617","0.02141"
"536.52000","44.71025","0.02222"
"536.92800","44.74427","0.02141"
"537.33600","44.77818","0.02180"
"537.74400","44.81219","0.02152"
"538.15200","44.84622","0.02156"
"538.56000","44.88029","0.02181"
"538.96800","44.91419","0.02130"
"539.37600","44.94822","0.02182"
"539.78400","44.98224","0.02130"
"540.19200","45.01626","0.02173"
"540.60000","45.05022","0.02120"
"541.00800","45.08418","0.01990"
"541.41600","45.11826","0.02026"
"541.82400","45.15222","0.02043"
"542.23200","45.18618","0.02116"
"542.64000","45.22020","0.02083"
"543.04800","45.25422","0.02087"
"543.45600","45.28824","0.02085"
"543.86400","45.32220","0.02089"
"544.27200","45.35616","0.02046"
"544.68000","45.39024","0.01990"
"545.08800","45.42420","0.02090"
"545.49600","45.45823","0.02135"
"545.90400","45.49218","0.02111"
"546.31200","45.52620","0.02065"
"546.72000","45.56022","0.02170"
"547.12800","45.59418","0.02197"
"547.53600","45.62814","0.02138"
"547.94400","45.66222","0.02112"
"548.35200","45.69624","0.02075"
"548.76000","45.73020","0.02007"
"549.16800","45.76417","0.01956"
"549.57600","45.79818","0.02075"
"549.98400","45.83221","0.01961"
"550.39200","45.86628","0.01977"
"550.80000","45.90019","0.02053"
"551.20800","45.93421","0.01986"
"551.61600","45.96822","0.01963"
"552.02400","46.00225","0.02025"
"552.43200","46.03621","0.02042"
"552.84000","46.07017","0.02002"
"553.24800","46.10425","0.02064"
"553.65600","46.13826","0.01983"
"554.06400","46.17222","0.02047"
"554.47200","46.20619","0.02004"
"554.88000","46.24027","0.02018"
"555.28800","46.27417","0.02092"
"555.69600","46.30825","0.02013"
"556.10400","46.34227","0.01972"
"556.51200","46.37617","0.01953"
"556.92000","46.41019","0.02001"
"557.32800","46.44421","0.01981"
"557.73600","46.47823","0.02029"
"558.14400","46.51219","0.01978"
"558.55200","46.54627","0.01962"
"558.96000","46.58023","0.01973"
"559.36800","46.61413","0.01959"
"559.77600","46.64822","0.01961"
"560.18400","46.68223","0.01940"
"560.59200","46.71626","0.01942"
"561.00000","46.75021","0.01974"
"561.40800","46.78417","0.01944"
"561.81600","46.81826","0.01926"
"562.22400","46.85227","0.01947"
"562.63200","46.88617","0.01890"
"563.04000","46.92020","0.01958"
"563.44800","46.95427","0.02006"
"563.85600","46.98830","0.02056"
"564.26400","47.02220","0.01981"
"564.67200","47.05615","0.01970"
"565.08000","47.09024","0.01991"
"565.48800","47.12426","0.01980"
"565.89600","47.15816","0.02007"
"566.30400","47.19224","0.01954"
"566.71200","47.22625","0.02019"
"567.12000","47.26022","0.02047"
"567.52800","47.29424","0.01967"
"567.93600","47.32814","0.02020"
"568.34400","47.36228","0.02051"
"568.75200","47.39630","0.02015"
"569.16000","47.43026","0.02040"
"569.56800","47.46416","0.01967"
"569.97600","47.49818","0.01958"
"570.38400","47.53226","0.01979"
"570.79200","47.56622","0.01936"
"571.20000","47.60018","0.01887"
"571.60800","47.63420","0.01967"
"572.01600","47.66822","0.01975"
"572.42400","47.70218","0.01912"
"572.83200","47.73615","0.01891"
"573.24000","47.77028","0.01957"
"573.64800","47.80424","0.01919"
"574.05600","47.83826","0.01913"
"574.46400","47.87222","0.01976"
"574.87200","47.90619","0.01909"
"575.28000","47.94026","0.01857"
"575.68800","47.97422","0.01908"
"576.09600","48.00819","0.01905"
"576.50400","48.04221","0.01901"
"576.91200","48.07629","0.01974"
"577.32000","48.11024","0.01887"
"577.72800","48.14420","0.01796"
"578.13600","48.17817","0.01830"
"578.54400","48.21218","0.01864"
"578.95200","48.24627","0.01811"
"579.36000","48.28023","0.01780"
"579.76800","48.31419","0.01838"
"580.17600","48.34821","0.01797"
"580.58400","48.38217","0.01841"
"580.99200","48.41625","0.01788"
"581.40000","48.45021","0.01842"
"581.80800","48.48423","0.01807"
"582.21600","48.51825","0.01814"
"582.62400","48.55221","0.01804"
"583.03200","48.58617","0.01864"
"583.44000","48.62019","0.01762"
"583.84800","48.65421","0.01762"
"584.25600","48.68829","0.01821"
"584.66400","48.72219","0.01822"
"585.07200","48.75621","0.01804"
"585.48000","48.79023","0.01810"
"585.88800","48.82425","0.01726"
"586.29600","48.85815","0.01771"
"586.70400","48.89217","0.01820"
"587.11200","48.92625","0.01810"
"587.52000","48.96028","0.01802"
"587.92800","48.99417","0.01827"
"588.33600","49.02819","0.01842"
"588.74400","49.06228","0.01816"
"589.15200","49.09623","0.01795"
"589.56000","49.13025","0.01733"
"589.96800","49.16422","0.01720"
"590.37600","49.19818","0.01714"
"590.78400","49.23220","0.01757"
"591.19200","49.26622","0.01711"
"591.60000","49.30017","0.01770"
"592.00800","49.33426","0.01761"
"592.41600","49.36828","0.01818"
"592.82400","49.40224","0.01805"
"593.23200","49.43620","0.01748"
"593.64000","49.47016","0.01769"
"594.04800","49.50423","0.01750"
"594.45600","49.53820","0.01747"
"594.86400","49.57216","0.01724"
"595.27200","49.60624","0.01810"
"595.68000","49.64026","0.01804"
"596.08800","49.67416","0.01764"
"596.49600","49.70818","0.01715"
"596.90400","49.74220","0.01699"
"597.31200","49.77628","0.01727"
"597.72000","49.81024","0.01798"
"598.12800","49.84414","0.01848"
"598.53600","49.87822","0.01839"
"598.94400","49.91219","0.01800"
"599.35200","49.94620","0.01785"
"599.76000","49.98023","0.01796"
"600.16800","50.01418","0.01777"
"600.57600","50.04827","0.01753"
"600.98400","50.08223","0.01825"
"601.39200","50.11618","0.01852"
"601.80000","50.15021","0.01891"
"602.20800","50.18422","0.01861"
"602.61600","50.21825","0.01814"
"603.02400","50.25227","0.01858"
"603.43200","50.28617","0.01854"
"603.84000","50.32025","0.01900"
"604.24800","50.35421","0.01879"
"604.65600","50.38823","0.01831"
"605.06400","50.42218","0.01873"
"605.47200","50.45627","0.01844"
"605.76600","50.48072","0.01885"