File: Force_trajectories/170226_3/Specimen_RawData_6.csv
End date,"2/26/2017"
Specimen label,"4CT_32_pl"
Maximum Load,"0.14378",N

Time,Extension,Load
(s),(mm),(N)
"0.00000","0.00000","0.00022"
"0.04200","0.00060","0.00043"
"0.08400","0.00275","0.00072"
"0.12600","0.00628","0.00105"
"0.16800","0.01064","0.00082"
"0.21000","0.01525","0.00021"
"0.25200","0.01973","0.00061"
"0.29400","0.02404","-0.00060"
"0.33600","0.02792","-0.00004"
"0.37800","0.03169","0.00059"
"0.42000","0.03528","-0.00004"
"0.46200","0.03874","0.00010"
"0.50400","0.04221","-0.00003"
"0.54600","0.04574","-0.00029"
"0.58800","0.04927","0.00071"
"0.63000","0.05273","0.00036"
"0.67200","0.05632","0.00017"
"0.71400","0.05979","0.00035"
"0.75600","0.06320","0.00031"
"0.79800","0.06673","0.00017"
"0.84000","0.07025","0.00013"
"0.88200","0.07378","0.00077"
"0.92400","0.07719","0.00100"
"0.96600","0.08072","0.00048"
"1.00800","0.08418","0.00045"
"1.05000","0.08765","-0.00028"
"1.09200","0.09118","0.00050"
"1.13400","0.09471","0.00078"
"1.17600","0.09823","0.00062"
"1.21800","0.10170","0.00023"
"1.26000","0.10523","0.00138"
"1.30200","0.10876","0.00093"
"1.34400","0.11222","0.00074"
"1.38600","0.11569","-0.00032"
"1.42800","0.11922","0.00050"
"1.47000","0.12269","0.00066"
"1.51200","0.12622","0.00050"
"1.55400","0.12968","0.00051"
"1.59600","0.13315","0.00018"
"1.63800","0.13668","0.00108"
"1.68000","0.14021","0.00082"
"1.72200","0.14373","0.00082"
"1.76400","0.14720","0.00039"
"1.80600","0.15073","0.00023"
"1.84800","0.15420","0.00015"
"1.89000","0.15766","0.00032"
"1.93200","0.16119","0.00049"
"1.97400","0.16466","0.00060"
"2.01600","0.16813","0.00029"
"2.05800","0.17166","0.00055"
"2.10000","0.17512","0.00104"
"2.14200","0.17865","0.00106"
"2.18400","0.18218","0.00067"
"2.22600","0.18571","0.00007"
"2.26800","0.18923","0.00050"
"2.31000","0.19276","0.00059"
"2.35200","0.19623","0.00014"
"2.39400","0.19976","0.00056"
"2.43600","0.20322","0.00073"
"2.47800","0.20669","0.00048"
"2.52000","0.21016","0.00082"
"2.56200","0.21369","0.00018"
"2.60400","0.21722","0.00066"
"2.64600","0.22062","0.00061"
"2.68800","0.22415","0.00042"
"2.73000","0.22774","0.00063"
"2.77200","0.23121","0.00048"
"2.81400","0.23473","0.00086"
"2.85600","0.23826","0.00048"
"2.89800","0.24173","0.00090"
"2.94000","0.24520","0.00045"
"2.98200","0.24872","0.00054"
"3.02400","0.25225","0.00055"
"3.06600","0.25572","0.00102"
"3.10800","0.25919","0.00089"
"3.15000","0.26266","0.00087"
"3.19200","0.26618","0.00077"
"3.23400","0.26965","0.00054"
"3.27600","0.27318","0.00130"
"3.31800","0.27671","0.00129"
"3.36000","0.28023","0.00090"
"3.40200","0.28370","0.00077"
"3.44400","0.28723","0.00123"
"3.48600","0.29070","0.00040"
"3.52800","0.29422","0.00138"
"3.57000","0.29769","0.00076"
"3.61200","0.30122","0.00086"
"3.65400","0.30469","0.00058"
"3.69600","0.30816","0.00052"
"3.73800","0.31168","0.00099"
"3.78000","0.31521","0.00105"
"3.82200","0.31868","0.00078"
"3.86400","0.32227","0.00035"
"3.90600","0.32579","0.00070"
"3.94800","0.32920","0.00067"
"3.99000","0.33273","0.00095"
"4.03200","0.33626","0.00055"
"4.07400","0.33966","0.00168"
"4.11600","0.34313","0.00160"
"4.15800","0.34666","0.00105"
"4.20000","0.35019","0.00069"
"4.24200","0.35366","0.00062"
"4.28400","0.35712","0.00064"
"4.32600","0.36071","0.00085"
"4.36800","0.36418","0.00082"
"4.41000","0.36771","0.00099"
"4.45200","0.37129","0.00136"
"4.49400","0.37476","0.00126"
"4.53600","0.37823","0.00103"
"4.57800","0.38176","0.00062"
"4.62000","0.38522","0.00100"
"4.66200","0.38869","0.00081"
"4.70400","0.39216","0.00118"
"4.74600","0.39569","0.00169"
"4.78800","0.39915","0.00128"
"4.83000","0.40262","0.00074"
"4.87200","0.40621","0.00122"
"4.91400","0.40968","0.00048"
"4.95600","0.41321","0.00056"
"4.99800","0.41673","0.00135"
"5.04000","0.42026","0.00121"
"5.08200","0.42373","0.00112"
"5.12400","0.42720","0.00138"
"5.16600","0.43072","0.00148"
"5.20800","0.43419","0.00107"
"5.25000","0.43766","0.00098"
"5.29200","0.44119","0.00121"
"5.33400","0.44465","0.00104"
"5.37600","0.44812","0.00102"
"5.41800","0.45165","0.00187"
"5.46000","0.45524","0.00151"
"5.50200","0.45877","0.00097"
"5.54400","0.46223","0.00115"
"5.58600","0.46576","0.00078"
"5.62800","0.46923","0.00121"
"5.67000","0.47270","0.00098"
"5.71200","0.47616","0.00135"
"5.75400","0.47969","0.00161"
"5.79600","0.48322","0.00117"
"5.83800","0.48663","0.00152"
"5.88000","0.49015","0.00166"
"5.92200","0.49368","0.00152"
"5.96400","0.49721","0.00170"
"6.00600","0.50068","0.00122"
"6.04800","0.50426","0.00138"
"6.09000","0.50773","0.00126"
"6.13200","0.51120","0.00096"
"6.17400","0.51473","0.00106"
"6.21600","0.51826","0.00160"
"6.25800","0.52166","0.00100"
"6.30000","0.52519","0.00144"
"6.34200","0.52866","0.00119"
"6.38400","0.53213","0.00085"
"6.42600","0.53559","0.00186"
"6.46800","0.53918","0.00134"
"6.51000","0.54265","0.00097"
"6.55200","0.54618","0.00142"
"6.59400","0.54970","0.00177"
"6.63600","0.55323","0.00142"
"6.67800","0.55670","0.00174"
"6.72000","0.56023","0.00096"
"6.76200","0.56376","0.00152"
"6.80400","0.56716","0.00131"
"6.84600","0.57069","0.00118"
"6.88800","0.57416","0.00185"
"6.93000","0.57763","0.00212"
"6.97200","0.58115","0.00233"
"7.01400","0.58468","0.00179"
"7.05600","0.58821","0.00193"
"7.09800","0.59174","0.00187"
"7.14000","0.59520","0.00132"
"7.18200","0.59873","0.00118"
"7.22400","0.60220","0.00126"
"7.26600","0.60579","0.00167"
"7.30800","0.60926","0.00203"
"7.35000","0.61272","0.00146"
"7.39200","0.61619","0.00215"
"7.43400","0.61972","0.00172"
"7.47600","0.62319","0.00154"
"7.51800","0.62671","0.00179"
"7.56000","0.63018","0.00177"
"7.60200","0.63371","0.00145"
"7.64400","0.63724","0.00148"
"7.68600","0.64070","0.00210"
"7.72800","0.64423","0.00197"
"7.77000","0.64776","0.00187"
"7.81200","0.65123","0.00150"
"7.85400","0.65470","0.00146"
"7.89600","0.65822","0.00144"
"7.93800","0.66169","0.00152"
"7.98000","0.66516","0.00184"
"8.02200","0.66863","0.00158"
"8.06400","0.67221","0.00200"
"8.10600","0.67568","0.00161"
"8.14800","0.67921","0.00205"
"8.19000","0.68274","0.00212"
"8.23200","0.68620","0.00136"
"8.27400","0.68967","0.00158"
"8.31600","0.69320","0.00213"
"8.35800","0.69673","0.00154"
"8.40000","0.70020","0.00211"
"8.44200","0.70366","0.00282"
"8.48400","0.70719","0.00229"
"8.52600","0.71060","0.00190"
"8.56800","0.71413","0.00222"
"8.61000","0.71771","0.00231"
"8.65200","0.72124","0.00219"
"8.69400","0.72471","0.00164"
"8.73600","0.72824","0.00164"
"8.77800","0.73176","0.00189"
"8.82000","0.73517","0.00224"
"8.86200","0.73870","0.00168"
"8.90400","0.74223","0.00201"
"8.94600","0.74575","0.00182"
"8.98800","0.74922","0.00242"
"9.03000","0.75275","0.00205"
"9.07200","0.75622","0.00229"
"9.11400","0.75969","0.00204"
"9.15600","0.76321","0.00233"
"9.19800","0.76674","0.00234"
"9.24000","0.77021","0.00207"
"9.28200","0.77374","0.00223"
"9.32400","0.77726","0.00243"
"9.36600","0.78073","0.00212"
"9.40800","0.78426","0.00186"
"9.45000","0.78773","0.00133"
"9.49200","0.79125","0.00194"
"9.53400","0.79472","0.00293"
"9.57600","0.79819","0.00195"
"9.61800","0.80166","0.00220"
"9.66000","0.80519","0.00213"
"9.70200","0.80871","0.00187"
"9.74400","0.81224","0.00178"
"9.78600","0.81571","0.00226"
"9.82800","0.81924","0.00219"
"9.87000","0.82270","0.00215"
"9.91200","0.82623","0.00187"
"9.95400","0.82976","0.00251"
"9.99600","0.83323","0.00217"
"10.03800","0.83675","0.00248"
"10.08000","0.84022","0.00278"
"10.12200","0.84369","0.00270"
"10.16400","0.84716","0.00231"
"10.20600","0.85069","0.00234"
"10.24800","0.85415","0.00235"
"10.29000","0.85768","0.00225"
"10.33200","0.86127","0.00214"
"10.37400","0.86480","0.00294"
"10.41600","0.86820","0.00242"
"10.45800","0.87167","0.00236"
"10.50000","0.87520","0.00240"
"10.54200","0.87867","0.00289"
"10.58400","0.88213","0.00282"
"10.62600","0.88566","0.00249"
"10.66800","0.88913","0.00254"
"10.71000","0.89260","0.00218"
"10.75200","0.89619","0.00269"
"10.79400","0.89971","0.00266"
"10.83600","0.90324","0.00275"
"10.87800","0.90671","0.00333"
"10.92000","0.91024","0.00280"
"10.96200","0.91370","0.00243"
"11.00400","0.91723","0.00323"
"11.04600","0.92070","0.00224"
"11.08800","0.92423","0.00311"
"11.13000","0.92769","0.00296"
"11.17200","0.93116","0.00303"
"11.21400","0.93469","0.00246"
"11.25600","0.93816","0.00311"
"11.29800","0.94163","0.00248"
"11.34000","0.94515","0.00252"
"11.38200","0.94868","0.00292"
"11.42400","0.95221","0.00260"
"11.46600","0.95568","0.00326"
"11.50800","0.95920","0.00334"
"11.55000","0.96267","0.00325"
"11.59200","0.96620","0.00377"
"11.63400","0.96973","0.00285"
"11.67600","0.97319","0.00328"
"11.71800","0.97666","0.00290"
"11.76000","0.98013","0.00304"
"11.80200","0.98366","0.00263"
"11.84400","0.98718","0.00289"
"11.88600","0.99071","0.00354"
"11.92800","0.99430","0.00314"
"11.97000","0.99777","0.00287"
"12.01200","1.00124","0.00308"
"12.05400","1.00476","0.00299"
"12.09600","1.00823","0.00247"
"12.13800","1.01170","0.00307"
"12.18000","1.01523","0.00282"
"12.22200","1.01875","0.00296"
"12.26400","1.02216","0.00310"
"12.30600","1.02569","0.00304"
"12.34800","1.02922","0.00296"
"12.39000","1.03268","0.00366"
"12.43200","1.03615","0.00344"
"12.47400","1.03974","0.00304"
"12.51600","1.04327","0.00354"
"12.55800","1.04668","0.00309"
"12.60000","1.05020","0.00333"
"12.64200","1.05373","0.00400"
"12.68400","1.05720","0.00436"
"12.72600","1.06067","0.00442"
"12.76800","1.06419","0.00370"
"12.81000","1.06766","0.00350"
"12.85200","1.07113","0.00317"
"12.89400","1.07466","0.00326"
"12.93600","1.07818","0.00394"
"12.97800","1.08171","0.00382"
"13.02000","1.08518","0.00363"
"13.06200","1.08877","0.00350"
"13.10400","1.09224","0.00335"
"13.14600","1.09570","0.00298"
"13.18800","1.09923","0.00376"
"13.23000","1.10276","0.00315"
"13.27200","1.10623","0.00335"
"13.31400","1.10969","0.00359"
"13.35600","1.11316","0.00349"
"13.39800","1.11663","0.00367"
"13.44000","1.12016","0.00351"
"13.48200","1.12368","0.00355"
"13.52400","1.12721","0.00307"
"13.56600","1.13074","0.00298"
"13.60800","1.13421","0.00331"
"13.65000","1.13774","0.00342"
"13.69200","1.14120","0.00341"
"13.73400","1.14473","0.00391"
"13.77600","1.14826","0.00425"
"13.81800","1.15173","0.00393"
"13.86000","1.15519","0.00355"
"13.90200","1.15866","0.00345"
"13.94400","1.16213","0.00373"
"13.98600","1.16560","0.00371"
"14.02800","1.16918","0.00357"
"14.07000","1.17277","0.00373"
"14.11200","1.17624","0.00401"
"14.15400","1.17971","0.00393"
"14.19600","1.18323","0.00388"
"14.23800","1.18676","0.00352"
"14.28000","1.19023","0.00428"
"14.32200","1.19370","0.00358"
"14.36400","1.19723","0.00345"
"14.40600","1.20069","0.00433"
"14.44800","1.20416","0.00418"
"14.49000","1.20763","0.00395"
"14.53200","1.21116","0.00371"
"14.57400","1.21468","0.00424"
"14.61600","1.21815","0.00390"
"14.65800","1.22168","0.00427"
"14.70000","1.22521","0.00344"
"14.74200","1.22873","0.00395"
"14.78400","1.23220","0.00446"
"14.82600","1.23573","0.00423"
"14.86800","1.23920","0.00413"
"14.91000","1.24267","0.00457"
"14.95200","1.24613","0.00423"
"14.99400","1.24966","0.00424"
"15.03600","1.25313","0.00414"
"15.07800","1.25666","0.00456"
"15.12000","1.26018","0.00358"
"15.16200","1.26371","0.00456"
"15.20400","1.26724","0.00395"
"15.24600","1.27071","0.00404"
"15.28800","1.27423","0.00438"
"15.33000","1.27776","0.00413"
"15.37200","1.28129","0.00464"
"15.41400","1.28470","0.00411"
"15.45600","1.28817","0.00419"
"15.49800","1.29169","0.00395"
"15.54000","1.29522","0.00346"
"15.58200","1.29863","0.00380"
"15.62400","1.30222","0.00423"
"15.66600","1.30574","0.00462"
"15.70800","1.30921","0.00399"
"15.75000","1.31274","0.00491"
"15.79200","1.31627","0.00429"
"15.83400","1.31973","0.00429"
"15.87600","1.32320","0.00442"
"15.91800","1.32673","0.00436"
"15.96000","1.33026","0.00484"
"16.00200","1.33367","0.00446"
"16.04400","1.33719","0.00471"
"16.08600","1.34072","0.00410"
"16.12800","1.34419","0.00496"
"16.17000","1.34766","0.00444"
"16.21200","1.35124","0.00449"
"16.25400","1.35477","0.00511"
"16.29600","1.35824","0.00524"
"16.33800","1.36177","0.00423"
"16.38000","1.36529","0.00458"
"16.42200","1.36870","0.00402"
"16.46400","1.37217","0.00475"
"16.50600","1.37576","0.00466"
"16.54800","1.37917","0.00458"
"16.59000","1.38263","0.00546"
"16.63200","1.38616","0.00477"
"16.67400","1.38969","0.00530"
"16.71600","1.39322","0.00542"
"16.75800","1.39674","0.00481"
"16.80000","1.40027","0.00488"
"16.84200","1.40368","0.00464"
"16.88400","1.40715","0.00522"
"16.92600","1.41073","0.00477"
"16.96800","1.41420","0.00472"
"17.01000","1.41773","0.00521"
"17.05200","1.42120","0.00512"
"17.09400","1.42472","0.00565"
"17.13600","1.42813","0.00484"
"17.17800","1.43160","0.00490"
"17.22000","1.43519","0.00522"
"17.26200","1.43866","0.00466"
"17.30400","1.44224","0.00526"
"17.34600","1.44571","0.00509"
"17.38800","1.44924","0.00472"
"17.43000","1.45271","0.00492"
"17.47200","1.45617","0.00509"
"17.51400","1.45970","0.00528"
"17.55600","1.46323","0.00574"
"17.59800","1.46670","0.00571"
"17.64000","1.47022","0.00508"
"17.68200","1.47369","0.00565"
"17.72400","1.47716","0.00497"
"17.76600","1.48069","0.00480"
"17.80800","1.48422","0.00549"
"17.85000","1.48768","0.00498"
"17.89200","1.49121","0.00591"
"17.93400","1.49474","0.00532"
"17.97600","1.49821","0.00568"
"18.01800","1.50167","0.00543"
"18.06000","1.50520","0.00524"
"18.10200","1.50873","0.00522"
"18.14400","1.51220","0.00502"
"18.18600","1.51566","0.00523"
"18.22800","1.51919","0.00557"
"18.27000","1.52266","0.00553"
"18.31200","1.52619","0.00585"
"18.35400","1.52972","0.00573"
"18.39600","1.53318","0.00560"
"18.43800","1.53671","0.00538"
"18.48000","1.54018","0.00597"
"18.52200","1.54371","0.00632"
"18.56400","1.54723","0.00545"
"18.60600","1.55070","0.00603"
"18.64800","1.55423","0.00523"
"18.69000","1.55770","0.00572"
"18.73200","1.56122","0.00633"
"18.77400","1.56463","0.00549"
"18.81600","1.56816","0.00507"
"18.85800","1.57169","0.00603"
"18.90000","1.57522","0.00641"
"18.94200","1.57874","0.00570"
"18.98400","1.58221","0.00537"
"19.02600","1.58568","0.00623"
"19.06800","1.58921","0.00605"
"19.11000","1.59267","0.00616"
"19.15200","1.59620","0.00630"
"19.19400","1.59967","0.00611"
"19.23600","1.60320","0.00611"
"19.27800","1.60666","0.00599"
"19.32000","1.61007","0.00613"
"19.36200","1.61366","0.00639"
"19.40400","1.61719","0.00578"
"19.44600","1.62071","0.00672"
"19.48800","1.62418","0.00645"
"19.53000","1.62777","0.00597"
"19.57200","1.63118","0.00631"
"19.61400","1.63471","0.00605"
"19.65600","1.63823","0.00613"
"19.69800","1.64170","0.00606"
"19.74000","1.64517","0.00635"
"19.78200","1.64870","0.00655"
"19.82400","1.65222","0.00659"
"19.86600","1.65563","0.00662"
"19.90800","1.65916","0.00638"
"19.95000","1.66275","0.00646"
"19.99200","1.66621","0.00605"
"20.03400","1.66974","0.00658"
"20.07600","1.67327","0.00677"
"20.11800","1.67674","0.00640"
"20.16000","1.68021","0.00724"
"20.20200","1.68373","0.00708"
"20.24400","1.68726","0.00641"
"20.28600","1.69073","0.00657"
"20.32800","1.69420","0.00674"
"20.37000","1.69766","0.00659"
"20.41200","1.70119","0.00680"
"20.45400","1.70466","0.00688"
"20.49600","1.70819","0.00678"
"20.53800","1.71177","0.00662"
"20.58000","1.71524","0.00611"
"20.62200","1.71871","0.00646"
"20.66400","1.72224","0.00715"
"20.70600","1.72571","0.00737"
"20.74800","1.72917","0.00741"
"20.79000","1.73270","0.00751"
"20.83200","1.73617","0.00724"
"20.87400","1.73964","0.00715"
"20.91600","1.74310","0.00745"
"20.95800","1.74669","0.00776"
"21.00000","1.75022","0.00699"
"21.04200","1.75375","0.00742"
"21.08400","1.75727","0.00741"
"21.12600","1.76080","0.00760"
"21.16800","1.76421","0.00831"
"21.21000","1.76768","0.00808"
"21.25200","1.77121","0.00756"
"21.29400","1.77467","0.00792"
"21.33600","1.77814","0.00760"
"21.37800","1.78167","0.00764"
"21.42000","1.78520","0.00784"
"21.46200","1.78860","0.00736"
"21.50400","1.79213","0.00754"
"21.54600","1.79572","0.00759"
"21.58800","1.79925","0.00804"
"21.63000","1.80271","0.00741"
"21.67200","1.80630","0.00830"
"21.71400","1.80971","0.00794"
"21.75600","1.81324","0.00818"
"21.79800","1.81671","0.00768"
"21.84000","1.82029","0.00760"
"21.88200","1.82370","0.00838"
"21.92400","1.82717","0.00777"
"21.96600","1.83070","0.00771"
"22.00800","1.83410","0.00808"
"22.05000","1.83763","0.00855"
"22.09200","1.84122","0.00782"
"22.13400","1.84475","0.00821"
"22.17600","1.84827","0.00847"
"22.21800","1.85174","0.00814"
"22.26000","1.85521","0.00830"
"22.30200","1.85874","0.00825"
"22.34400","1.86226","0.00833"
"22.38600","1.86573","0.00808"
"22.42800","1.86920","0.00821"
"22.47000","1.87273","0.00879"
"22.51200","1.87614","0.00811"
"22.55400","1.87960","0.00815"
"22.59600","1.88319","0.00826"
"22.63800","1.88672","0.00924"
"22.68000","1.89025","0.00930"
"22.72200","1.89377","0.00850"
"22.76400","1.89730","0.00848"
"22.80600","1.90077","0.00827"
"22.84800","1.90424","0.00845"
"22.89000","1.90770","0.00875"
"22.93200","1.91123","0.00880"
"22.97400","1.91470","0.00825"
"23.01600","1.91823","0.00835"
"23.05800","1.92170","0.00935"
"23.10000","1.92516","0.00867"
"23.14200","1.92869","0.00877"
"23.18400","1.93216","0.00857"
"23.22600","1.93569","0.00900"
"23.26800","1.93927","0.00961"
"23.31000","1.94274","0.00878"
"23.35200","1.94621","0.00883"
"23.39400","1.94974","0.00886"
"23.43600","1.95320","0.00903"
"23.47800","1.95667","0.00934"
"23.52000","1.96020","0.00985"
"23.56200","1.96373","0.00951"
"23.60400","1.96714","0.00917"
"23.64600","1.97060","0.00949"
"23.68800","1.97419","0.00973"
"23.73000","1.97766","0.00972"
"23.77200","1.98119","0.00948"
"23.81400","1.98471","0.00952"
"23.85600","1.98824","0.00984"
"23.89800","1.99171","0.00970"
"23.94000","1.99524","0.01020"
"23.98200","1.99876","0.00976"
"24.02400","2.00217","0.01008"
"24.06600","2.00564","0.00924"
"24.10800","2.00917","0.00978"
"24.15000","2.01264","0.00887"
"24.19200","2.01610","0.00975"
"24.23400","2.01969","0.01010"
"24.27600","2.02322","0.00957"
"24.31800","2.02675","0.00973"
"24.36000","2.03021","0.00979"
"24.40200","2.03380","0.00985"
"24.44400","2.03721","0.00937"
"24.48600","2.04074","0.01007"
"24.52800","2.04426","0.01043"
"24.57000","2.04773","0.01047"
"24.61200","2.05120","0.00979"
"24.65400","2.05467","0.01024"
"24.69600","2.05819","0.01041"
"24.73800","2.06166","0.01042"
"24.78000","2.06519","0.01073"
"24.82200","2.06872","0.01022"
"24.86400","2.07225","0.01001"
"24.90600","2.07571","0.01077"
"24.94800","2.07918","0.01082"
"24.99000","2.08277","0.01077"
"25.03200","2.08624","0.00996"
"25.07400","2.08970","0.01021"
"25.11600","2.09323","0.01101"
"25.15800","2.09670","0.01060"
"25.20000","2.10017","0.01011"
"25.24200","2.10363","0.01021"
"25.28400","2.10722","0.01066"
"25.32600","2.11069","0.01024"
"25.36800","2.11422","0.01072"
"25.41000","2.11775","0.01135"
"25.45200","2.12121","0.01070"
"25.49400","2.12468","0.01072"
"25.53600","2.12821","0.01128"
"25.57800","2.13174","0.01119"
"25.62000","2.13520","0.01121"
"25.66200","2.13867","0.01081"
"25.70400","2.14220","0.01107"
"25.74600","2.14567","0.01099"
"25.78800","2.14913","0.01106"
"25.83000","2.15272","0.01097"
"25.87200","2.15619","0.01125"
"25.91400","2.15972","0.01132"
"25.95600","2.16325","0.01195"
"25.99800","2.16671","0.01118"
"26.04000","2.17024","0.01118"
"26.08200","2.17371","0.01188"
"26.12400","2.17718","0.01159"
"26.16600","2.18070","0.01193"
"26.20800","2.18417","0.01172"
"26.25000","2.18770","0.01177"
"26.29200","2.19117","0.01220"
"26.33400","2.19469","0.01222"
"26.37600","2.19816","0.01228"
"26.41800","2.20169","0.01201"
"26.46000","2.20522","0.01204"
"26.50200","2.20874","0.01210"
"26.54400","2.21221","0.01165"
"26.58600","2.21568","0.01228"
"26.62800","2.21921","0.01195"
"26.67000","2.22274","0.01256"
"26.71200","2.22620","0.01211"
"26.75400","2.22973","0.01234"
"26.79600","2.23320","0.01255"
"26.83800","2.23667","0.01212"
"26.88000","2.24013","0.01257"
"26.92200","2.24366","0.01268"
"26.96400","2.24719","0.01318"
"27.00600","2.25072","0.01232"
"27.04800","2.25424","0.01265"
"27.09000","2.25771","0.01338"
"27.13200","2.26124","0.01283"
"27.17400","2.26471","0.01248"
"27.21600","2.26818","0.01280"
"27.25800","2.27170","0.01277"
"27.30000","2.27523","0.01271"
"27.34200","2.27864","0.01278"
"27.38400","2.28217","0.01344"
"27.42600","2.28569","0.01309"
"27.46800","2.28916","0.01284"
"27.51000","2.29269","0.01259"
"27.55200","2.29622","0.01313"
"27.59400","2.29974","0.01332"
"27.63600","2.30315","0.01270"
"27.67800","2.30668","0.01357"
"27.72000","2.31021","0.01316"
"27.76200","2.31368","0.01317"
"27.80400","2.31714","0.01371"
"27.84600","2.32073","0.01337"
"27.88800","2.32420","0.01296"
"27.93000","2.32767","0.01323"
"27.97200","2.33119","0.01325"
"28.01400","2.33466","0.01334"
"28.05600","2.33819","0.01391"
"28.09800","2.34172","0.01362"
"28.14000","2.34530","0.01347"
"28.18200","2.34871","0.01389"
"28.22400","2.35224","0.01380"
"28.26600","2.35577","0.01349"
"28.30800","2.35918","0.01454"
"28.35000","2.36264","0.01421"
"28.39200","2.36623","0.01451"
"28.43400","2.36970","0.01435"
"28.47600","2.37317","0.01418"
"28.51800","2.37669","0.01517"
"28.56000","2.38022","0.01406"
"28.60200","2.38369","0.01456"
"28.64400","2.38722","0.01468"
"28.68600","2.39074","0.01453"
"28.72800","2.39427","0.01453"
"28.77000","2.39774","0.01458"
"28.81200","2.40121","0.01472"
"28.85400","2.40473","0.01483"
"28.89600","2.40820","0.01509"
"28.93800","2.41167","0.01473"
"28.98000","2.41520","0.01489"
"29.02200","2.41867","0.01482"
"29.06400","2.42219","0.01489"
"29.10600","2.42572","0.01506"
"29.14800","2.42925","0.01457"
"29.19000","2.43278","0.01502"
"29.23200","2.43618","0.01470"
"29.27400","2.43971","0.01539"
"29.31600","2.44318","0.01512"
"29.35800","2.44671","0.01548"
"29.40000","2.45023","0.01539"
"29.44200","2.45376","0.01512"
"29.48400","2.45717","0.01547"
"29.52600","2.46064","0.01515"
"29.56800","2.46423","0.01625"
"29.61000","2.46769","0.01635"
"29.65200","2.47122","0.01587"
"29.69400","2.47475","0.01580"
"29.73600","2.47822","0.01622"
"29.77800","2.48168","0.01631"
"29.82000","2.48521","0.01619"
"29.86200","2.48874","0.01653"
"29.90400","2.49221","0.01638"
"29.94600","2.49567","0.01649"
"29.98800","2.49914","0.01655"
"30.03000","2.50267","0.01661"
"30.07200","2.50620","0.01629"
"30.11400","2.50967","0.01674"
"30.15600","2.51319","0.01738"
"30.19800","2.51672","0.01717"
"30.24000","2.52019","0.01760"
"30.28200","2.52372","0.01718"
"30.32400","2.52718","0.01697"
"30.36600","2.53077","0.01724"
"30.40800","2.53424","0.01759"
"30.45000","2.53771","0.01730"
"30.49200","2.54123","0.01727"
"30.53400","2.54470","0.01719"
"30.57600","2.54817","0.01768"
"30.61800","2.55164","0.01766"
"30.66000","2.55517","0.01816"
"30.70200","2.55869","0.01811"
"30.74400","2.56222","0.01755"
"30.78600","2.56575","0.01806"
"30.82800","2.56922","0.01828"
"30.87000","2.57274","0.01832"
"30.91200","2.57621","0.01808"
"30.95400","2.57974","0.01833"
"30.99600","2.58327","0.01867"
"31.03800","2.58673","0.01905"
"31.08000","2.59020","0.01859"
"31.12200","2.59367","0.01894"
"31.16400","2.59720","0.01894"
"31.20600","2.60061","0.01883"
"31.24800","2.60413","0.01894"
"31.29000","2.60772","0.01940"
"31.33200","2.61125","0.01959"
"31.37400","2.61472","0.01992"
"31.41600","2.61824","0.01976"
"31.45800","2.62177","0.01948"
"31.50000","2.62524","0.01893"
"31.54200","2.62871","0.01944"
"31.58400","2.63223","0.01978"
"31.62600","2.63564","0.01978"
"31.66800","2.63917","0.01984"
"31.71000","2.64270","0.01984"
"31.75200","2.64616","0.01966"
"31.79400","2.64963","0.02043"
"31.83600","2.65316","0.02044"
"31.87800","2.65675","0.02066"
"31.92000","2.66022","0.02050"
"31.96200","2.66368","0.02113"
"32.00400","2.66721","0.02104"
"32.04600","2.67074","0.02086"
"32.08800","2.67415","0.02126"
"32.13000","2.67767","0.02130"
"32.17200","2.68120","0.02125"
"32.21400","2.68461","0.02105"
"32.25600","2.68814","0.02124"
"32.29800","2.69172","0.02085"
"32.34000","2.69519","0.02144"
"32.38200","2.69866","0.02209"
"32.42400","2.70225","0.02192"
"32.46600","2.70578","0.02222"
"32.50800","2.70918","0.02175"
"32.55000","2.71271","0.02154"
"32.59200","2.71624","0.02260"
"32.63400","2.71971","0.02253"
"32.67600","2.72317","0.02214"
"32.71800","2.72670","0.02284"
"32.76000","2.73017","0.02304"
"32.80200","2.73364","0.02298"
"32.84400","2.73716","0.02282"
"32.88600","2.74075","0.02285"
"32.92800","2.74422","0.02354"
"32.97000","2.74775","0.02386"
"33.01200","2.75128","0.02362"
"33.05400","2.75474","0.02356"
"33.09600","2.75821","0.02397"
"33.13800","2.76174","0.02417"
"33.18000","2.76527","0.02403"
"33.22200","2.76867","0.02508"
"33.26400","2.77220","0.02399"
"33.30600","2.77567","0.02418"
"33.34800","2.77914","0.02455"
"33.39000","2.78266","0.02473"
"33.43200","2.78619","0.02494"
"33.47400","2.78972","0.02496"
"33.51600","2.79319","0.02535"
"33.55800","2.79666","0.02524"
"33.60000","2.80024","0.02509"
"33.64200","2.80371","0.02555"
"33.68400","2.80718","0.02553"
"33.72600","2.81071","0.02540"
"33.76800","2.81417","0.02614"
"33.81000","2.81770","0.02628"
"33.85200","2.82117","0.02650"
"33.89400","2.82470","0.02644"
"33.93600","2.82816","0.02676"
"33.97800","2.83169","0.02662"
"34.02000","2.83522","0.02704"
"34.06200","2.83869","0.02658"
"34.10400","2.84216","0.02685"
"34.14600","2.84568","0.02763"
"34.18800","2.84921","0.02752"
"34.23000","2.85274","0.02731"
"34.27200","2.85621","0.02769"
"34.31400","2.85967","0.02764"
"34.35600","2.86314","0.02782"
"34.39800","2.86661","0.02843"
"34.44000","2.87020","0.02823"
"34.48200","2.87372","0.02823"
"34.52400","2.87719","0.02868"
"34.56600","2.88072","0.02887"
"34.60800","2.88425","0.02855"
"34.65000","2.88771","0.02926"
"34.69200","2.89124","0.02999"
"34.73400","2.89477","0.02963"
"34.77600","2.89824","0.02978"
"34.81800","2.90171","0.03005"
"34.86000","2.90523","0.03002"
"34.90200","2.90870","0.03053"
"34.94400","2.91211","0.03019"
"34.98600","2.91564","0.03056"
"35.02800","2.91922","0.03054"
"35.07000","2.92275","0.03104"
"35.11200","2.92622","0.03151"
"35.15400","2.92975","0.03206"
"35.19600","2.93321","0.03180"
"35.23800","2.93674","0.03196"
"35.28000","2.94021","0.03150"
"35.32200","2.94374","0.03222"
"35.36400","2.94721","0.03269"
"35.40600","2.95073","0.03277"
"35.44800","2.95420","0.03271"
"35.49000","2.95767","0.03288"
"35.53200","2.96120","0.03313"
"35.57400","2.96472","0.03351"
"35.61600","2.96819","0.03328"
"35.65800","2.97172","0.03425"
"35.70000","2.97519","0.03410"
"35.74200","2.97871","0.03446"
"35.78400","2.98224","0.03524"
"35.82600","2.98571","0.03500"
"35.86800","2.98924","0.03575"
"35.91000","2.99271","0.03554"
"35.95200","2.99617","0.03644"
"35.99400","2.99964","0.03624"
"36.03600","3.00317","0.03634"
"36.07800","3.00670","0.03671"
"36.12000","3.01016","0.03676"
"36.16200","3.01375","0.03696"
"36.20400","3.01728","0.03721"
"36.24600","3.02069","0.03733"
"36.28800","3.02421","0.03833"
"36.33000","3.02774","0.03814"
"36.37200","3.03115","0.03844"
"36.41400","3.03468","0.03906"
"36.45600","3.03820","0.03875"
"36.49800","3.04167","0.03940"
"36.54000","3.04514","0.03984"
"36.58200","3.04867","0.03975"
"36.62400","3.05220","0.04023"
"36.66600","3.05566","0.04088"
"36.70800","3.05925","0.04034"
"36.75000","3.06278","0.04105"
"36.79200","3.06619","0.04133"
"36.83400","3.06971","0.04138"
"36.87600","3.07324","0.04180"
"36.91800","3.07665","0.04194"
"36.96000","3.08012","0.04225"
"37.00200","3.08365","0.04270"
"37.04400","3.08723","0.04270"
"37.08600","3.09070","0.04320"
"37.12800","3.09417","0.04350"
"37.17000","3.09776","0.04366"
"37.21200","3.10122","0.04445"
"37.25400","3.10469","0.04422"
"37.29600","3.10822","0.04425"
"37.33800","3.11175","0.04467"
"37.38000","3.11521","0.04470"
"37.42200","3.11874","0.04538"
"37.46400","3.12227","0.04570"
"37.50600","3.12568","0.04580"
"37.54800","3.12914","0.04589"
"37.59000","3.13267","0.04582"
"37.63200","3.13614","0.04646"
"37.67400","3.13973","0.04699"
"37.71600","3.14320","0.04703"
"37.75800","3.14672","0.04721"
"37.80000","3.15025","0.04728"
"37.84200","3.15372","0.04810"
"37.88400","3.15719","0.04811"
"37.92600","3.16071","0.04824"
"37.96800","3.16424","0.04876"
"38.01000","3.16771","0.04932"
"38.05200","3.17118","0.04984"
"38.09400","3.17470","0.05047"
"38.13600","3.17817","0.05048"
"38.17800","3.18164","0.05117"
"38.22000","3.18523","0.05163"
"38.26200","3.18876","0.05172"
"38.30400","3.19222","0.05191"
"38.34600","3.19575","0.05245"
"38.38800","3.19922","0.05339"
"38.43000","3.20275","0.05350"
"38.47200","3.20621","0.05354"
"38.51400","3.20974","0.05397"
"38.55600","3.21321","0.05469"
"38.59800","3.21668","0.05533"
"38.64000","3.22020","0.05514"
"38.68200","3.22361","0.05562"
"38.72400","3.22714","0.05671"
"38.76600","3.23073","0.05639"
"38.80800","3.23419","0.05708"
"38.85000","3.23772","0.05751"
"38.89200","3.24125","0.05805"
"38.93400","3.24472","0.05873"
"38.97600","3.24819","0.05896"
"39.01800","3.25171","0.05910"
"39.06000","3.25524","0.05948"
"39.10200","3.25871","0.06001"
"39.14400","3.26218","0.06047"
"39.18600","3.26570","0.06079"
"39.22800","3.26917","0.06137"
"39.27000","3.27264","0.06186"
"39.31200","3.27617","0.06210"
"39.35400","3.27970","0.06308"
"39.39600","3.28322","0.06374"
"39.43800","3.28675","0.06398"
"39.48000","3.29028","0.06494"
"39.52200","3.29375","0.06499"
"39.56400","3.29721","0.06592"
"39.60600","3.30074","0.06680"
"39.64800","3.30421","0.06710"
"39.69000","3.30768","0.06783"
"39.73200","3.31114","0.06842"
"39.77400","3.31467","0.06920"
"39.81600","3.31820","0.06986"
"39.85800","3.32167","0.06986"
"39.90000","3.32520","0.07097"
"39.94200","3.32872","0.07168"
"39.98400","3.33219","0.07202"
"40.02600","3.33572","0.07338"
"40.06800","3.33919","0.07378"
"40.11000","3.34271","0.07401"
"40.15200","3.34618","0.07489"
"40.19400","3.34971","0.07519"
"40.23600","3.35318","0.07588"
"40.27800","3.35664","0.07692"
"40.32000","3.36023","0.07673"
"40.36200","3.36370","0.07739"
"40.40400","3.36717","0.07804"
"40.44600","3.37069","0.07858"
"40.48800","3.37428","0.07898"
"40.53000","3.37769","0.07898"
"40.57200","3.38122","0.07936"
"40.61400","3.38481","0.08005"
"40.65600","3.38827","0.08063"
"40.69800","3.39168","0.08065"
"40.74000","3.39521","0.08101"
"40.78200","3.39868","0.08167"
"40.82400","3.40214","0.08194"
"40.86600","3.40561","0.08240"
"40.90800","3.40920","0.08279"
"40.95000","3.41267","0.08335"
"40.99200","3.41619","0.08340"
"41.03400","3.41978","0.08425"
"41.07600","3.42325","0.08419"
"41.11800","3.42672","0.08489"
"41.16000","3.43024","0.08522"
"41.20200","3.43377","0.08609"
"41.24400","3.43718","0.08591"
"41.28600","3.44065","0.08639"
"41.32800","3.44418","0.08692"
"41.37000","3.44770","0.08704"
"41.41200","3.45117","0.08771"
"41.45400","3.45470","0.08779"
"41.49600","3.45823","0.08858"
"41.53800","3.46169","0.08910"
"41.58000","3.46522","0.08958"
"41.62200","3.46875","0.09022"
"41.66400","3.47222","0.09026"
"41.70600","3.47574","0.09038"
"41.74800","3.47921","0.09151"
"41.79000","3.48274","0.09194"
"41.83200","3.48621","0.09235"
"41.87400","3.48968","0.09262"
"41.91600","3.49320","0.09260"
"41.95800","3.49667","0.09357"
"42.00000","3.50020","0.09432"
"42.04200","3.50373","0.09479"
"42.08400","3.50719","0.09507"
"42.12600","3.51072","0.09532"
"42.16800","3.51425","0.09634"
"42.21000","3.51778","0.09639"
"42.25200","3.52124","0.09674"
"42.29400","3.52471","0.09695"
"42.33600","3.52824","0.09786"
"42.37800","3.53171","0.09866"
"42.42000","3.53518","0.09897"
"42.46200","3.53864","0.09923"
"42.50400","3.54217","0.09943"
"42.54600","3.54564","0.10011"
"42.58800","3.54923","0.10034"
"42.63000","3.55269","0.10068"
"42.67200","3.55616","0.10166"
"42.71400","3.55969","0.10202"
"42.75600","3.56322","0.10241"
"42.79800","3.56668","0.10248"
"42.84000","3.57021","0.10292"
"42.88200","3.57368","0.10357"
"42.92400","3.57715","0.10405"
"42.96600","3.58062","0.10443"
"43.00800","3.58408","0.10457"
"43.05000","3.58767","0.10517"
"43.09200","3.59120","0.10566"
"43.13400","3.59473","0.10565"
"43.17600","3.59825","0.10643"
"43.21800","3.60172","0.10684"
"43.26000","3.60525","0.10712"
"43.30200","3.60872","0.10753"
"43.34400","3.61224","0.10842"
"43.38600","3.61571","0.10916"
"43.42800","3.61924","0.10915"
"43.47000","3.62271","0.11079"
"43.51200","3.62618","0.11094"
"43.55400","3.62970","0.11153"
"43.59600","3.63317","0.11182"
"43.63800","3.63670","0.11274"
"43.68000","3.64023","0.11329"
"43.72200","3.64375","0.11411"
"43.76400","3.64722","0.11438"
"43.80600","3.65075","0.11464"
"43.84800","3.65422","0.11545"
"43.89000","3.65768","0.11623"
"43.93200","3.66127","0.11679"
"43.97400","3.66468","0.11689"
"44.01600","3.66815","0.11762"
"44.05800","3.67174","0.11805"
"44.10000","3.67514","0.11921"
"44.14200","3.67867","0.11990"
"44.18400","3.68220","0.11987"
"44.22600","3.68573","0.12055"
"44.26800","3.68925","0.12134"
"44.31000","3.69266","0.12186"
"44.35200","3.69625","0.12195"
"44.39400","3.69972","0.12276"
"44.43600","3.70318","0.12340"
"44.47800","3.70671","0.12425"
"44.52000","3.71024","0.12424"
"44.56200","3.71365","0.12456"
"44.60400","3.71712","0.12470"
"44.64600","3.72070","0.12506"
"44.68800","3.72417","0.12599"
"44.73000","3.72770","0.12555"
"44.77200","3.73123","0.12606"
"44.81400","3.73475","0.12685"
"44.85600","3.73816","0.12691"
"44.89800","3.74169","0.12754"
"44.94000","3.74522","0.12798"
"44.98200","3.74862","0.12818"
"45.02400","3.75215","0.12840"
"45.06600","3.75574","0.12836"
"45.10800","3.75915","0.12897"
"45.15000","3.76262","0.12913"
"45.19200","3.76620","0.12932"
"45.23400","3.76967","0.12938"
"45.27600","3.77320","0.12968"
"45.31800","3.77673","0.13008"
"45.36000","3.78025","0.13033"
"45.40200","3.78372","0.13063"
"45.44400","3.78725","0.13090"
"45.48600","3.79078","0.13094"
"45.52800","3.79418","0.13121"
"45.57000","3.79771","0.13141"
"45.61200","3.80118","0.13157"
"45.65400","3.80471","0.13182"
"45.69600","3.80817","0.13197"
"45.73800","3.81170","0.13227"
"45.78000","3.81523","0.13245"
"45.82200","3.81870","0.13261"
"45.86400","3.82223","0.13274"
"45.90600","3.82575","0.13273"
"45.94800","3.82922","0.13266"
"45.99000","3.83275","0.13321"
"46.03200","3.83622","0.13325"
"46.07400","3.83974","0.13356"
"46.11600","3.84321","0.13387"
"46.15800","3.84668","0.13372"
"46.20000","3.85021","0.13386"
"46.24200","3.85367","0.13409"
"46.28400","3.85714","0.13451"
"46.32600","3.86067","0.13459"
"46.36800","3.86420","0.13466"
"46.41000","3.86773","0.13473"
"46.45200","3.87119","0.13487"
"46.49400","3.87472","0.13523"
"46.53600","3.87825","0.13500"
"46.57800","3.88172","0.13559"
"46.62000","3.88518","0.13606"
"46.66200","3.88871","0.13608"
"46.70400","3.89218","0.13578"
"46.74600","3.89565","0.13609"
"46.78800","3.89917","0.13663"
"46.83000","3.90270","0.13647"
"46.87200","3.90623","0.13660"
"46.91400","3.90976","0.13672"
"46.95600","3.91322","0.13672"
"46.99800","3.91675","0.13704"
"47.04000","3.92022","0.13747"
"47.08200","3.92369","0.13750"
"47.12400","3.92722","0.13808"
"47.16600","3.93068","0.13756"
"47.20800","3.93421","0.13830"
"47.25000","3.93768","0.13803"
"47.29200","3.94115","0.13836"
"47.33400","3.94467","0.13860"
"47.37600","3.94820","0.13881"
"47.41800","3.95173","0.13833"
"47.46000","3.95520","0.13947"
"47.50200","3.95878","0.13938"
"47.54400","3.96219","0.13923"
"47.58600","3.96572","0.13962"
"47.62800","3.96925","0.13954"
"47.67000","3.97278","0.13999"
"47.71200","3.97618","0.14019"
"47.75400","3.97971","0.14027"
"47.79600","3.98324","0.14013"
"47.83800","3.98665","0.14051"
"47.88000","3.99011","0.14049"
"47.92200","3.99370","0.14060"
"47.96400","3.99723","0.14108"
"48.00600","4.00070","0.14111"
"48.04800","4.00422","0.14115"
"48.09000","4.00775","0.14142"
"48.13200","4.01122","0.14153"
"48.17400","4.01469","0.14164"
"48.21600","4.01828","0.14148"
"48.25800","4.02168","0.14166"
"48.30000","4.02515","0.14173"
"48.34200","4.02868","0.14205"
"48.38400","4.03215","0.14222"
"48.42600","4.03567","0.14246"
"48.46800","4.03920","0.14245"
"48.51000","4.04273","0.14268"
"48.55200","4.04626","0.14286"
"48.59400","4.04972","0.14294"
"48.63600","4.05325","0.14297"
"48.67800","4.05672","0.14360"
"48.72000","4.06019","0.14377"
"48.76200","4.06372","0.14334"
"48.80400","4.06724","0.13165"
"48.84600","4.07065","0.12687"
"48.88800","4.07412","0.12801"
"48.93000","4.07765","0.03616"
"48.97200","4.08123","-0.01258"
"49.01400","4.08470","-0.00940"
"49.05600","4.08823","-0.00929"
"49.09800","4.09176","-0.00882"
"49.14000","4.09522","-0.00832"
"49.18200","4.09869","-0.00757"
"49.22400","4.10228","-0.00665"
"49.26600","4.10575","-0.00519"
"49.30800","4.10916","-0.00346"
"49.35000","4.11268","-0.00198"
"49.39200","4.11621","-0.00091"
"49.43400","4.11962","0.00043"
"49.47600","4.12315","0.00027"
"49.51800","4.12667","0.00030"
"49.56000","4.13014","-0.00031"
"49.60200","4.13367","-0.00116"
"49.64400","4.13720","-0.00156"
"49.68600","4.14072","-0.00174"
"49.72800","4.14419","-0.00091"
"49.77000","4.14772","-0.00118"
"49.81200","4.15125","-0.00055"
"49.85400","4.15471","-0.00075"
"49.89600","4.15812","-0.00055"
"49.93800","4.16171","-0.00095"
"49.98000","4.16512","-0.00120"
"50.02200","4.16859","-0.00231"
"50.06400","4.17217","-0.00275"
"50.10600","4.17576","-0.00301"
"50.14800","4.17923","-0.00292"
"50.19000","4.18270","-0.00277"
"50.23200","4.18628","-0.00397"
"50.27400","4.18975","-0.00318"
"50.31600","4.19322","-0.00327"
"50.35800","4.19675","-0.00315"
"50.40000","4.20021","-0.00334"
"50.44200","4.20368","-0.00266"
"50.48400","4.20721","-0.00230"
"50.52600","4.21068","-0.00246"
"50.56800","4.21421","-0.00307"
"50.61000","4.21767","-0.00263"
"50.65200","4.22120","-0.00267"
"50.69400","4.22467","-0.00282"
"50.73600","4.22820","-0.00248"
"50.77800","4.23172","-0.00284"
"50.82000","4.23519","-0.00311"
"50.86200","4.23878","-0.00307"
"50.90400","4.24225","-0.00258"
"50.94600","4.24571","-0.00308"
"50.98800","4.24918","-0.00347"
"51.03000","4.25271","-0.00314"
"51.07200","4.25618","-0.00293"
"51.11400","4.25971","-0.00282"
"51.15600","4.26323","-0.00276"
"51.19800","4.26670","-0.00258"
"51.24000","4.27023","-0.00311"
"51.28200","4.27370","-0.00296"
"51.32400","4.27722","-0.00345"
"51.36600","4.28075","-0.00332"
"51.40800","4.28422","-0.00324"
"51.45000","4.28775","-0.00357"
"51.49200","4.29121","-0.00288"
"51.53400","4.29468","-0.00324"
"51.57600","4.29815","-0.00336"
"51.61800","4.30162","-0.00313"
"51.66000","4.30521","-0.00305"
"51.70200","4.30873","-0.00336"
"51.74400","4.31220","-0.00288"
"51.78600","4.31573","-0.00304"
"51.82800","4.31926","-0.00300"
"51.87000","4.32266","-0.00259"
"51.91200","4.32619","-0.00227"
"51.95400","4.32978","-0.00315"
"51.99600","4.33325","-0.00307"
"52.03800","4.33671","-0.00284"
"52.08000","4.34024","-0.00280"
"52.12200","4.34371","-0.00326"
"52.16400","4.34712","-0.00314"
"52.20600","4.35065","-0.00328"
"52.24800","4.35423","-0.00316"
"52.29000","4.35776","-0.00343"
"52.33200","4.36123","-0.00384"
"52.37400","4.36476","-0.00329"
"52.41600","4.36822","-0.00291"
"52.45800","4.37169","-0.00265"
"52.50000","4.37522","-0.00296"
"52.54200","4.37875","-0.00254"
"52.58400","4.38221","-0.00257"
"52.62600","4.38568","-0.00338"
"52.66800","4.38921","-0.00310"
"52.71000","4.39268","-0.00307"
"52.75200","4.39614","-0.00367"
"52.79400","4.39967","-0.00382"
"52.83600","4.40320","-0.00386"
"52.87800","4.40673","-0.00381"
"52.92000","4.41020","-0.00329"
"52.96200","4.41372","-0.00365"
"53.00400","4.41719","-0.00336"
"53.04600","4.42066","-0.00329"
"53.08800","4.42419","-0.00343"
"53.13000","4.42765","-0.00302"
"53.17200","4.43118","-0.00290"
"53.21400","4.43465","-0.00329"
"53.25600","4.43818","-0.00264"
"53.29800","4.44165","-0.00303"
"53.34000","4.44517","-0.00283"
"53.38200","4.44876","-0.00325"
"53.42400","4.45223","-0.00298"
"53.46600","4.45570","-0.00373"
"53.50800","4.45922","-0.00307"
"53.55000","4.46269","-0.00330"
"53.59200","4.46616","-0.00354"
"53.63400","4.46969","-0.00333"
"53.67600","4.47321","-0.00318"
"53.71800","4.47668","-0.00298"
"53.76000","4.48015","-0.00273"
"53.80200","4.48368","-0.00270"
"53.84400","4.48720","-0.00257"
"53.88600","4.49073","-0.00296"
"53.92800","4.49420","-0.00347"
"53.97000","4.49773","-0.00355"
"54.01200","4.50119","-0.00330"
"54.05400","4.50472","-0.00383"
"54.09600","4.50819","-0.00403"
"54.13800","4.51172","-0.00363"
"54.18000","4.51519","-0.00375"
"54.22200","4.51865","-0.00338"
"54.26400","4.52218","-0.00358"
"54.30600","4.52565","-0.00356"
"54.34800","4.52912","-0.00328"
"54.39000","4.53270","-0.00291"
"54.43200","4.53617","-0.00356"
"54.47400","4.53970","-0.00243"
"54.51600","4.54323","-0.00335"
"54.55800","4.54669","-0.00298"
"54.60000","4.55022","-0.00283"
"54.64200","4.55375","-0.00327"
"54.68400","4.55722","-0.00307"
"54.72600","4.56069","-0.00313"
"54.76800","4.56421","-0.00329"
"54.81000","4.56762","-0.00342"
"54.85200","4.57115","-0.00302"
"54.89400","4.57468","-0.00328"
"54.93600","4.57820","-0.00317"
"54.97800","4.58173","-0.00295"
"55.02000","4.58526","-0.00334"
"55.03400","4.58645","-0.00345"