File: Force_trajectories/170226_2/Specimen_RawData_1.csv
End date,"2/26/2017"
Specimen label,"2BG_14"
Maximum Load,"0.05342",N

Time,Extension,Load
(s),(mm),(N)
"0.00000","0.00000","0.00007"
"0.25200","0.01973","-0.00004"
"0.50400","0.04227","0.00034"
"0.75600","0.06320","0.00032"
"1.00800","0.08418","0.00044"
"1.26000","0.10523","0.00103"
"1.51200","0.12616","0.00080"
"1.76400","0.14720","0.00102"
"2.01600","0.16813","0.00154"
"2.26800","0.18917","0.00104"
"2.52000","0.21022","0.00121"
"2.77200","0.23115","0.00090"
"3.02400","0.25219","0.00159"
"3.27600","0.27318","0.00174"
"3.52800","0.29416","0.00124"
"3.78000","0.31509","0.00178"
"4.03200","0.33620","0.00201"
"4.28400","0.35718","0.00119"
"4.53600","0.37817","0.00177"
"4.78800","0.39915","0.00196"
"5.04000","0.42020","0.00195"
"5.29200","0.44119","0.00238"
"5.54400","0.46223","0.00161"
"5.79600","0.48316","0.00232"
"6.04800","0.50421","0.00228"
"6.30000","0.52525","0.00236"
"6.55200","0.54618","0.00206"
"6.80400","0.56722","0.00193"
"7.05600","0.58815","0.00181"
"7.30800","0.60920","0.00224"
"7.56000","0.63018","0.00231"
"7.81200","0.65117","0.00220"
"8.06400","0.67209","0.00298"
"8.31600","0.69320","0.00211"
"8.56800","0.71413","0.00156"
"8.82000","0.73523","0.00135"
"9.07200","0.75616","0.00218"
"9.32400","0.77720","0.00283"
"9.57600","0.79825","0.00216"
"9.82800","0.81918","0.00262"
"10.08000","0.84016","0.00290"
"10.33200","0.86121","0.00254"
"10.58400","0.88219","0.00251"
"10.83600","0.90318","0.00353"
"11.08800","0.92417","0.00271"
"11.34000","0.94515","0.00227"
"11.59200","0.96626","0.00333"
"11.84400","0.98718","0.00292"
"12.09600","1.00823","0.00271"
"12.34800","1.02916","0.00342"
"12.60000","1.05020","0.00191"
"12.85200","1.07113","0.00402"
"13.10400","1.09218","0.00284"
"13.35600","1.11316","0.00307"
"13.60800","1.13421","0.00340"
"13.86000","1.15519","0.00290"
"14.11200","1.17618","0.00288"
"14.36400","1.19717","0.00269"
"14.61600","1.21815","0.00332"
"14.86800","1.23920","0.00378"
"15.12000","1.26012","0.00332"
"15.37200","1.28123","0.00317"
"15.62400","1.30210","0.00332"
"15.87600","1.32320","0.00372"
"16.12800","1.34419","0.00300"
"16.38000","1.36523","0.00338"
"16.63200","1.38616","0.00356"
"16.88400","1.40721","0.00408"
"17.13600","1.42813","0.00372"
"17.38800","1.44924","0.00364"
"17.64000","1.47016","0.00401"
"17.89200","1.49121","0.00359"
"18.14400","1.51220","0.00317"
"18.39600","1.53318","0.00369"
"18.64800","1.55423","0.00413"
"18.90000","1.57516","0.00398"
"19.15200","1.59620","0.00377"
"19.40400","1.61713","0.00345"
"19.65600","1.63817","0.00454"
"19.90800","1.65910","0.00415"
"20.16000","1.68021","0.00394"
"20.41200","1.70119","0.00439"
"20.66400","1.72224","0.00449"
"20.91600","1.74316","0.00385"
"21.16800","1.76415","0.00400"
"21.42000","1.78508","0.00424"
"21.67200","1.80624","0.00388"
"21.92400","1.82723","0.00352"
"22.17600","1.84815","0.00368"
"22.42800","1.86920","0.00400"
"22.68000","1.89019","0.00410"
"22.93200","1.91123","0.00413"
"23.18400","1.93210","0.00371"
"23.43600","1.95320","0.00402"
"23.68800","1.97419","0.00440"
"23.94000","1.99524","0.00410"
"24.19200","2.01616","0.00406"
"24.44400","2.03721","0.00405"
"24.69600","2.05814","0.00430"
"24.94800","2.07924","0.00435"
"25.20000","2.10017","0.00467"
"25.45200","2.12115","0.00430"
"25.70400","2.14214","0.00443"
"25.95600","2.16319","0.00452"
"26.20800","2.18423","0.00395"
"26.46000","2.20516","0.00415"
"26.71200","2.22626","0.00375"
"26.96400","2.24719","0.00448"
"27.21600","2.26824","0.00462"
"27.46800","2.28916","0.00438"
"27.72000","2.31021","0.00398"
"27.97200","2.33113","0.00411"
"28.22400","2.35224","0.00441"
"28.47600","2.37317","0.00439"
"28.72800","2.39415","0.00406"
"28.98000","2.41514","0.00368"
"29.23200","2.43618","0.00404"
"29.48400","2.45717","0.00409"
"29.73600","2.47822","0.00410"
"29.98800","2.49920","0.00438"
"30.24000","2.52019","0.00412"
"30.49200","2.54117","0.00412"
"30.74400","2.56210","0.00444"
"30.99600","2.58321","0.00428"
"31.24800","2.60413","0.00474"
"31.50000","2.62518","0.00445"
"31.75200","2.64611","0.00428"
"32.00400","2.66715","0.00381"
"32.25600","2.68820","0.00466"
"32.50800","2.70918","0.00435"
"32.76000","2.73017","0.00460"
"33.01200","2.75122","0.00449"
"33.26400","2.77220","0.00436"
"33.51600","2.79319","0.00419"
"33.76800","2.81417","0.00473"
"34.02000","2.83516","0.00509"
"34.27200","2.85621","0.00445"
"34.52400","2.87713","0.00465"
"34.77600","2.89824","0.00488"
"35.02800","2.91916","0.00458"
"35.28000","2.94021","0.00397"
"35.53200","2.96114","0.00410"
"35.78400","2.98218","0.00449"
"36.03600","3.00317","0.00496"
"36.28800","3.02421","0.00408"
"36.54000","3.04514","0.00440"
"36.79200","3.06619","0.00490"
"37.04400","3.08717","0.00468"
"37.29600","3.10822","0.00499"
"37.54800","3.12920","0.00473"
"37.80000","3.15019","0.00498"
"38.05200","3.17118","0.00464"
"38.30400","3.19222","0.00445"
"38.55600","3.21321","0.00501"
"38.80800","3.23414","0.00488"
"39.06000","3.25518","0.00531"
"39.31200","3.27617","0.00524"
"39.56400","3.29721","0.00492"
"39.81600","3.31814","0.00502"
"40.06800","3.33919","0.00524"
"40.32000","3.36011","0.00504"
"40.57200","3.38122","0.00524"
"40.82400","3.40220","0.00503"
"41.07600","3.42325","0.00477"
"41.32800","3.44418","0.00499"
"41.58000","3.46522","0.00483"
"41.83200","3.48621","0.00505"
"42.08400","3.50713","0.00514"
"42.33600","3.52818","0.00548"
"42.58800","3.54917","0.00556"
"42.84000","3.57021","0.00525"
"43.09200","3.59114","0.00542"
"43.34400","3.61218","0.00590"
"43.59600","3.63317","0.00536"
"43.84800","3.65422","0.00562"
"44.10000","3.67514","0.00589"
"44.35200","3.69619","0.00549"
"44.60400","3.71712","0.00529"
"44.85600","3.73822","0.00541"
"45.10800","3.75915","0.00564"
"45.36000","3.78019","0.00491"
"45.61200","3.80124","0.00531"
"45.86400","3.82223","0.00546"
"46.11600","3.84315","0.00558"
"46.36800","3.86414","0.00565"
"46.62000","3.88518","0.00555"
"46.87200","3.90611","0.00534"
"47.12400","3.92716","0.00545"
"47.37600","3.94814","0.00544"
"47.62800","3.96925","0.00569"
"47.88000","3.99011","0.00546"
"48.13200","4.01122","0.00631"
"48.38400","4.03221","0.00595"
"48.63600","4.05325","0.00559"
"48.88800","4.07418","0.00647"
"49.14000","4.09516","0.00570"
"49.39200","4.11615","0.00526"
"49.64400","4.13720","0.00557"
"49.89600","4.15824","0.00560"
"50.14800","4.17911","0.00595"
"50.40000","4.20021","0.00515"
"50.65200","4.22114","0.00563"
"50.90400","4.24225","0.00580"
"51.15600","4.26311","0.00568"
"51.40800","4.28416","0.00555"
"51.66000","4.30515","0.00578"
"51.91200","4.32619","0.00625"
"52.16400","4.34718","0.00547"
"52.41600","4.36822","0.00588"
"52.66800","4.38921","0.00592"
"52.92000","4.41020","0.00607"
"53.17200","4.43118","0.00591"
"53.42400","4.45223","0.00623"
"53.67600","4.47321","0.00656"
"53.92800","4.49420","0.00610"
"54.18000","4.51519","0.00556"
"54.43200","4.53611","0.00600"
"54.68400","4.55722","0.00550"
"54.93600","4.57814","0.00608"
"55.18800","4.59919","0.00588"
"55.44000","4.62012","0.00572"
"55.69200","4.64116","0.00610"
"55.94400","4.66215","0.00611"
"56.19600","4.68319","0.00613"
"56.44800","4.70412","0.00677"
"56.70000","4.72523","0.00636"
"56.95200","4.74621","0.00626"
"57.20400","4.76726","0.00600"
"57.45600","4.78813","0.00610"
"57.70800","4.80917","0.00585"
"57.96000","4.83022","0.00647"
"58.21200","4.85120","0.00672"
"58.46400","4.87219","0.00663"
"58.71600","4.89312","0.00586"
"58.96800","4.91422","0.00629"
"59.22000","4.93521","0.00612"
"59.47200","4.95619","0.00618"
"59.72400","4.97718","0.00635"
"59.97600","4.99817","0.00529"
"60.22800","5.01915","0.00589"
"60.48000","5.04020","0.00621"
"60.73200","5.06112","0.00595"
"60.98400","5.08217","0.00617"
"61.23600","5.10322","0.00605"
"61.48800","5.12420","0.00576"
"61.74000","5.14519","0.00643"
"61.99200","5.16617","0.00654"
"62.24400","5.18722","0.00579"
"62.49600","5.20815","0.00614"
"62.74800","5.22919","0.00621"
"63.00000","5.25012","0.00636"
"63.25200","5.27122","0.00633"
"63.50400","5.29215","0.00607"
"63.75600","5.31320","0.00656"
"64.00800","5.33418","0.00721"
"64.26000","5.35523","0.00680"
"64.51200","5.37616","0.00671"
"64.76400","5.39720","0.00639"
"65.01600","5.41819","0.00647"
"65.26800","5.43923","0.00657"
"65.52000","5.46022","0.00639"
"65.77200","5.48115","0.00703"
"66.02400","5.50219","0.00683"
"66.27600","5.52318","0.00700"
"66.52800","5.54422","0.00699"
"66.78000","5.56509","0.00663"
"67.03200","5.58620","0.00720"
"67.28400","5.60712","0.00666"
"67.53600","5.62823","0.00704"
"67.78800","5.64909","0.00724"
"68.04000","5.67020","0.00686"
"68.29200","5.69119","0.00694"
"68.54400","5.71217","0.00737"
"68.79600","5.73316","0.00727"
"69.04800","5.75420","0.00712"
"69.30000","5.77519","0.00693"
"69.55200","5.79618","0.00697"
"69.80400","5.81716","0.00743"
"70.05600","5.83815","0.00744"
"70.30800","5.85925","0.00730"
"70.56000","5.88018","0.00755"
"70.81200","5.90117","0.00733"
"71.06400","5.92209","0.00704"
"71.31600","5.94320","0.00785"
"71.56800","5.96413","0.00779"
"71.82000","5.98517","0.00766"
"72.07200","6.00616","0.00716"
"72.32400","6.02720","0.00758"
"72.57600","6.04819","0.00817"
"72.82800","6.06918","0.00736"
"73.08000","6.09016","0.00729"
"73.33200","6.11121","0.00814"
"73.58400","6.13225","0.00788"
"73.83600","6.15318","0.00804"
"74.08800","6.17417","0.00827"
"74.34000","6.19515","0.00817"
"74.59200","6.21620","0.00769"
"74.84400","6.23712","0.00803"
"75.09600","6.25817","0.00802"
"75.34800","6.27910","0.00796"
"75.60000","6.30020","0.00830"
"75.85200","6.32119","0.00801"
"76.10400","6.34223","0.00792"
"76.35600","6.36316","0.00772"
"76.60800","6.38415","0.00828"
"76.86000","6.40513","0.00815"
"77.11200","6.42618","0.00831"
"77.36400","6.44717","0.00791"
"77.61600","6.46815","0.00841"
"77.86800","6.48920","0.00831"
"78.12000","6.51012","0.00815"
"78.37200","6.53123","0.00864"
"78.62400","6.55216","0.00893"
"78.87600","6.57320","0.00883"
"79.12800","6.59413","0.00846"
"79.38000","6.61517","0.00786"
"79.63200","6.63616","0.00830"
"79.88400","6.65721","0.00882"
"80.13600","6.67813","0.00879"
"80.38800","6.69918","0.00918"
"80.64000","6.72016","0.00836"
"80.89200","6.74121","0.00862"
"81.14400","6.76214","0.00905"
"81.39600","6.78318","0.00909"
"81.64800","6.80417","0.00898"
"81.90000","6.82521","0.00943"
"82.15200","6.84620","0.00947"
"82.40400","6.86713","0.00951"
"82.65600","6.88823","0.00871"
"82.90800","6.90916","0.00916"
"83.16000","6.93020","0.00937"
"83.41200","6.95107","0.00962"
"83.66400","6.97218","0.00924"
"83.91600","6.99316","0.00888"
"84.16800","7.01421","0.00868"
"84.42000","7.03519","0.00945"
"84.67200","7.05624","0.00924"
"84.92400","7.07717","0.00972"
"85.17600","7.09815","0.01002"
"85.42800","7.11914","0.00908"
"85.68000","7.14013","0.00915"
"85.93200","7.16123","0.00951"
"86.18400","7.18222","0.00896"
"86.43600","7.20320","0.00976"
"86.68800","7.22413","0.00987"
"86.94000","7.24524","0.00989"
"87.19200","7.26616","0.00988"
"87.44400","7.28715","0.01000"
"87.69600","7.30814","0.01012"
"87.94800","7.32918","0.00951"
"88.20000","7.35017","0.00959"
"88.45200","7.37115","0.01050"
"88.70400","7.39220","0.01022"
"88.95600","7.41324","0.01028"
"89.20800","7.43423","0.00962"
"89.46000","7.45516","0.01012"
"89.71200","7.47614","0.01047"
"89.96400","7.49719","0.01018"
"90.21600","7.51818","0.01023"
"90.46800","7.53916","0.01036"
"90.72000","7.56021","0.01052"
"90.97200","7.58119","0.00981"
"91.22400","7.60224","0.01033"
"91.47600","7.62311","0.01036"
"91.72800","7.64415","0.01055"
"91.98000","7.66514","0.01056"
"92.23200","7.68618","0.01048"
"92.48400","7.70717","0.01048"
"92.73600","7.72822","0.01031"
"92.98800","7.74920","0.01016"
"93.24000","7.77025","0.00992"
"93.49200","7.79117","0.01050"
"93.74400","7.81216","0.01130"
"93.99600","7.83321","0.01048"
"94.24800","7.85419","0.01102"
"94.50000","7.87524","0.01127"
"94.75200","7.89610","0.01102"
"95.00400","7.91721","0.01083"
"95.25600","7.93820","0.01132"
"95.50800","7.95918","0.01050"
"95.76000","7.98017","0.01132"
"96.01200","8.00121","0.01088"
"96.26400","8.02214","0.01108"
"96.51600","8.04325","0.01137"
"96.76800","8.06417","0.01079"
"97.02000","8.08522","0.01126"
"97.27200","8.10620","0.01145"
"97.52400","8.12719","0.01120"
"97.77600","8.14818","0.01092"
"98.02800","8.16916","0.01136"
"98.28000","8.19021","0.01155"
"98.53200","8.21114","0.01193"
"98.78400","8.23218","0.01172"
"99.03600","8.25317","0.01151"
"99.28800","8.27421","0.01158"
"99.54000","8.29514","0.01179"
"99.79200","8.31619","0.01230"
"100.04400","8.33717","0.01227"
"100.29600","8.35822","0.01167"
"100.54800","8.37914","0.01155"
"100.80000","8.40019","0.01247"
"101.05200","8.42118","0.01044"
"101.30400","8.44222","0.01044"
"101.55600","8.46321","0.01138"
"101.80800","8.48413","0.01065"
"102.06000","8.50518","0.01052"
"102.31200","8.52617","0.01115"
"102.56400","8.54721","0.01106"
"102.81600","8.56808","0.01093"
"103.06800","8.58918","0.01096"
"103.32000","8.61017","0.01110"
"103.57200","8.63122","0.01113"
"103.82400","8.65220","0.01164"
"104.07600","8.67319","0.01147"
"104.32800","8.69411","0.01142"
"104.58000","8.71522","0.01193"
"104.83200","8.73615","0.01164"
"105.08400","8.75719","0.01192"
"105.33600","8.77824","0.01204"
"105.58800","8.79917","0.01240"
"105.84000","8.82015","0.01197"
"106.09200","8.84114","0.01200"
"106.34400","8.86218","0.01185"
"106.59600","8.88323","0.01229"
"106.84800","8.90416","0.01223"
"107.10000","8.92514","0.01232"
"107.35200","8.94619","0.01203"
"107.60400","8.96711","0.01218"
"107.85600","8.98816","0.01256"
"108.10800","9.00909","0.01236"
"108.36000","9.03019","0.01247"
"108.61200","9.05118","0.01290"
"108.86400","9.07222","0.01294"
"109.11600","9.09315","0.01274"
"109.36800","9.11420","0.01321"
"109.62000","9.13524","0.01270"
"109.87200","9.15623","0.01278"
"110.12400","9.17715","0.01343"
"110.37600","9.19814","0.01220"
"110.62800","9.21919","0.01356"
"110.88000","9.24017","0.01333"
"111.13200","9.26116","0.01327"
"111.38400","9.28215","0.01355"
"111.63600","9.30325","0.01333"
"111.88800","9.32418","0.01294"
"112.14000","9.34516","0.01263"
"112.39200","9.36615","0.01345"
"112.64400","9.38720","0.01281"
"112.89600","9.40818","0.01308"
"113.14800","9.42917","0.01351"
"113.40000","9.45021","0.01331"
"113.65200","9.47120","0.01345"
"113.90400","9.49225","0.01347"
"114.15600","9.51317","0.01308"
"114.40800","9.53422","0.01356"
"114.66000","9.55515","0.01341"
"114.91200","9.57625","0.01318"
"115.16400","9.59712","0.01344"
"115.41600","9.61816","0.01298"
"115.66800","9.63909","0.01376"
"115.92000","9.66019","0.01244"
"116.17200","9.68112","0.01316"
"116.42400","9.70223","0.01363"
"116.67600","9.72321","0.01319"
"116.92800","9.74420","0.01308"
"117.18000","9.76519","0.01316"
"117.43200","9.78617","0.01359"
"117.68400","9.80722","0.01342"
"117.93600","9.82820","0.01343"
"118.18800","9.84925","0.01357"
"118.44000","9.87012","0.01370"
"118.69200","9.89116","0.01339"
"118.94400","9.91215","0.01371"
"119.19600","9.93325","0.01372"
"119.44800","9.95418","0.01374"
"119.70000","9.97517","0.01406"
"119.95200","9.99609","0.01385"
"120.20400","10.01720","0.01381"
"120.45600","10.03818","0.01392"
"120.70800","10.05923","0.01426"
"120.96000","10.08016","0.01404"
"121.21200","10.10120","0.01425"
"121.46400","10.12219","0.01407"
"121.71600","10.14318","0.01469"
"121.96800","10.16422","0.01476"
"122.22000","10.18521","0.01495"
"122.47200","10.20619","0.01418"
"122.72400","10.22712","0.01474"
"122.97600","10.24817","0.01411"
"123.22800","10.26915","0.01451"
"123.48000","10.29014","0.01456"
"123.73200","10.31112","0.01509"
"123.98400","10.33223","0.01541"
"124.23600","10.35316","0.01530"
"124.48800","10.37420","0.01456"
"124.74000","10.39513","0.01460"
"124.99200","10.41617","0.01490"
"125.24400","10.43722","0.01511"
"125.49600","10.45815","0.01519"
"125.74800","10.47919","0.01516"
"126.00000","10.50018","0.01526"
"126.25200","10.52116","0.01501"
"126.50400","10.54215","0.01593"
"126.75600","10.56320","0.01457"
"127.00800","10.58412","0.01549"
"127.26000","10.60523","0.01510"
"127.51200","10.62615","0.01559"
"127.76400","10.64720","0.01528"
"128.01600","10.66819","0.01584"
"128.26800","10.68917","0.01552"
"128.52000","10.71016","0.01564"
"128.77200","10.73114","0.01620"
"129.02400","10.75213","0.01505"
"129.27600","10.77324","0.01536"
"129.52800","10.79422","0.01586"
"129.78000","10.81515","0.01594"
"130.03200","10.83626","0.01625"
"130.28400","10.85718","0.01593"
"130.53600","10.87823","0.01597"
"130.78800","10.89909","0.01632"
"131.04000","10.92020","0.01529"
"131.29200","10.94113","0.01616"
"131.54400","10.96223","0.01590"
"131.79600","10.98316","0.01583"
"132.04800","11.00426","0.01602"
"132.30000","11.02519","0.01623"
"132.55200","11.04624","0.01617"
"132.80400","11.06716","0.01674"
"133.05600","11.08815","0.01641"
"133.30800","11.10913","0.01711"
"133.56000","11.13018","0.01601"
"133.81200","11.15123","0.01665"
"134.06400","11.17221","0.01672"
"134.31600","11.19320","0.01696"
"134.56800","11.21418","0.01640"
"134.82000","11.23517","0.01685"
"135.07200","11.25610","0.01659"
"135.32400","11.27720","0.01687"
"135.57600","11.29813","0.01646"
"135.82800","11.31923","0.01682"
"136.08000","11.34016","0.01688"
"136.33200","11.36121","0.01725"
"136.58400","11.38219","0.01745"
"136.83600","11.40318","0.01656"
"137.08800","11.42417","0.01688"
"137.34000","11.44515","0.01677"
"137.59200","11.46620","0.01628"
"137.84400","11.48718","0.01694"
"138.09600","11.50817","0.01634"
"138.34800","11.52910","0.01681"
"138.60000","11.55026","0.01670"
"138.85200","11.57113","0.01719"
"139.10400","11.59217","0.01783"
"139.35600","11.61310","0.01726"
"139.60800","11.63421","0.01688"
"139.86000","11.65519","0.01720"
"140.11200","11.67618","0.01689"
"140.36400","11.69716","0.01767"
"140.61600","11.71821","0.01520"
"140.86800","11.73920","0.01534"
"141.12000","11.76018","0.01546"
"141.37200","11.78117","0.01580"
"141.62400","11.80216","0.01626"
"141.87600","11.82320","0.01601"
"142.12800","11.84419","0.01577"
"142.38000","11.86523","0.01646"
"142.63200","11.88616","0.01651"
"142.88400","11.90727","0.01629"
"143.13600","11.92807","0.01658"
"143.38800","11.94918","0.01621"
"143.64000","11.97010","0.01635"
"143.89200","11.99127","0.01623"
"144.14400","12.01214","0.01607"
"144.39600","12.03324","0.01671"
"144.64800","12.05423","0.01596"
"144.90000","12.07521","0.01659"
"145.15200","12.09620","0.01636"
"145.40400","12.11719","0.01660"
"145.65600","12.13823","0.01657"
"145.90800","12.15922","0.01608"
"146.16000","12.18026","0.01650"
"146.41200","12.20113","0.01705"
"146.66400","12.22224","0.01661"
"146.91600","12.24316","0.01733"
"147.16800","12.26421","0.01757"
"147.42000","12.28513","0.01668"
"147.67200","12.30612","0.01674"
"147.92400","12.32717","0.01679"
"148.17600","12.34827","0.01688"
"148.42800","12.36914","0.01795"
"148.68000","12.39019","0.01696"
"148.93200","12.41117","0.01721"
"149.18400","12.43216","0.01720"
"149.43600","12.45320","0.01756"
"149.68800","12.47419","0.01754"
"149.94000","12.49518","0.01683"
"150.19200","12.51622","0.01695"
"150.44400","12.53721","0.01742"
"150.69600","12.55813","0.01656"
"150.94800","12.57918","0.01695"
"151.20000","12.60017","0.01785"
"151.45200","12.62115","0.01766"
"151.70400","12.64214","0.01824"
"151.95600","12.66324","0.01781"
"152.20800","12.68417","0.01715"
"152.46000","12.70522","0.01728"
"152.71200","12.72620","0.01778"
"152.96400","12.74719","0.01726"
"153.21600","12.76817","0.01706"
"153.46800","12.78916","0.01785"
"153.72000","12.81015","0.01783"
"153.97200","12.83113","0.01808"
"154.22400","12.85224","0.01778"
"154.47600","12.87311","0.01807"
"154.72800","12.89421","0.01823"
"154.98000","12.91514","0.01831"
"155.23200","12.93624","0.01800"
"155.48400","12.95717","0.01833"
"155.73600","12.97822","0.01808"
"155.98800","12.99914","0.01840"
"156.24000","13.02019","0.01899"
"156.49200","13.04117","0.01879"
"156.74400","13.06222","0.01810"
"156.99600","13.08321","0.01885"
"157.24800","13.10419","0.01877"
"157.50000","13.12518","0.01892"
"157.75200","13.14616","0.01920"
"158.00400","13.16727","0.01837"
"158.25600","13.18814","0.01909"
"158.50800","13.20918","0.01896"
"158.76000","13.23011","0.01885"
"159.01200","13.25115","0.01925"
"159.26400","13.27220","0.01890"
"159.51600","13.29319","0.01876"
"159.76800","13.31411","0.02007"
"160.02000","13.33522","0.01965"
"160.27200","13.35620","0.01895"
"160.52400","13.37719","0.01940"
"160.77600","13.39818","0.01926"
"161.02800","13.41922","0.01955"
"161.28000","13.44021","0.01961"
"161.53200","13.46120","0.01974"
"161.78400","13.48218","0.01964"
"162.03600","13.50317","0.01950"
"162.28800","13.52421","0.01957"
"162.54000","13.54520","0.01949"
"162.79200","13.56618","0.02020"
"163.04400","13.58711","0.01982"
"163.29600","13.60822","0.01964"
"163.54800","13.62920","0.02072"
"163.80000","13.65019","0.02055"
"164.05200","13.67118","0.02078"
"164.30400","13.69222","0.02081"
"164.55600","13.71315","0.02082"
"164.80800","13.73419","0.02097"
"165.06000","13.75518","0.02101"
"165.31200","13.77617","0.02140"
"165.56400","13.79721","0.02132"
"165.81600","13.81814","0.02161"
"166.06800","13.83918","0.02182"
"166.32000","13.86017","0.02182"
"166.57200","13.88122","0.02155"
"166.82400","13.90214","0.02201"
"167.07600","13.92313","0.02202"
"167.32800","13.94412","0.02160"
"167.58000","13.96522","0.02161"
"167.83200","13.98615","0.02281"
"168.08400","14.00719","0.02256"
"168.33600","14.02818","0.02216"
"168.58800","14.04922","0.02249"
"168.84000","14.07021","0.02302"
"169.09200","14.09120","0.02329"
"169.34400","14.11218","0.02328"
"169.59600","14.13317","0.02333"
"169.84800","14.15422","0.02355"
"170.10000","14.17514","0.02304"
"170.35200","14.19625","0.02346"
"170.60400","14.21711","0.02408"
"170.85600","14.23822","0.02426"
"171.10800","14.25915","0.02409"
"171.36000","14.28019","0.02403"
"171.61200","14.30118","0.02439"
"171.86400","14.32222","0.02448"
"172.11600","14.34315","0.02551"
"172.36800","14.36420","0.02525"
"172.62000","14.38518","0.02549"
"172.87200","14.40623","0.02521"
"173.12400","14.42716","0.02551"
"173.37600","14.44814","0.02581"
"173.62800","14.46925","0.02546"
"173.88000","14.49017","0.02617"
"174.13200","14.51122","0.02602"
"174.38400","14.53209","0.02599"
"174.63600","14.55319","0.02607"
"174.88800","14.57418","0.02645"
"175.14000","14.59516","0.02716"
"175.39200","14.61615","0.02726"
"175.64400","14.63720","0.02744"
"175.89600","14.65818","0.02730"
"176.14800","14.67923","0.02740"
"176.40000","14.70009","0.02791"
"176.65200","14.72120","0.02770"
"176.90400","14.74224","0.02812"
"177.15600","14.76317","0.02790"
"177.40800","14.78422","0.02823"
"177.66000","14.80520","0.02809"
"177.91200","14.82625","0.02883"
"178.16400","14.84712","0.02881"
"178.41600","14.86816","0.02917"
"178.66800","14.88909","0.02921"
"178.92000","14.91020","0.02915"
"179.17200","14.93118","0.02963"
"179.42400","14.95223","0.02955"
"179.67600","14.97315","0.02988"
"179.92800","14.99420","0.02982"
"180.18000","15.01518","0.03052"
"180.43200","15.03617","0.03083"
"180.68400","15.05716","0.03104"
"180.93600","15.07820","0.03145"
"181.18800","15.09919","0.03173"
"181.44000","15.12018","0.03191"
"181.69200","15.14122","0.03130"
"181.94400","15.16215","0.03219"
"182.19600","15.18319","0.03133"
"182.44800","15.20412","0.03193"
"182.70000","15.22517","0.03164"
"182.95200","15.24615","0.03252"
"183.20400","15.26726","0.03248"
"183.45600","15.28818","0.03287"
"183.70800","15.30917","0.03243"
"183.96000","15.33022","0.03255"
"184.21200","15.35126","0.03262"
"184.46400","15.37213","0.03235"
"184.71600","15.39317","0.03301"
"184.96800","15.41416","0.03327"
"185.22000","15.43515","0.03363"
"185.47200","15.45619","0.03350"
"185.72400","15.47718","0.03368"
"185.97600","15.49822","0.03408"
"186.22800","15.51915","0.03350"
"186.48000","15.54020","0.03293"
"186.73200","15.56106","0.03418"
"186.98400","15.58217","0.03405"
"187.23600","15.60316","0.03450"
"187.48800","15.62426","0.03498"
"187.74000","15.64513","0.03483"
"187.99200","15.66623","0.03454"
"188.24400","15.68722","0.03468"
"188.49600","15.70820","0.03543"
"188.74800","15.72919","0.03566"
"189.00000","15.75018","0.03616"
"189.25200","15.77122","0.03598"
"189.50400","15.79221","0.03543"
"189.75600","15.81319","0.03555"
"190.00800","15.83412","0.03631"
"190.26000","15.85523","0.03593"
"190.51200","15.87615","0.03558"
"190.76400","15.89720","0.03609"
"191.01600","15.91813","0.03583"
"191.26800","15.93923","0.03630"
"191.52000","15.96016","0.03674"
"191.77200","15.98120","0.03690"
"192.02400","16.00213","0.03721"
"192.27600","16.02324","0.03698"
"192.52800","16.04416","0.03698"
"192.78000","16.06521","0.03801"
"193.03200","16.08619","0.03810"
"193.28400","16.10718","0.03817"
"193.53600","16.12823","0.03837"
"193.78800","16.14915","0.03941"
"194.04000","16.17020","0.03856"
"194.29200","16.19118","0.03933"
"194.54400","16.21223","0.04014"
"194.79600","16.23310","0.04017"
"195.04800","16.25414","0.03999"
"195.30000","16.27513","0.04014"
"195.55200","16.29630","0.04037"
"195.80400","16.31716","0.04069"
"196.05600","16.33821","0.04165"
"196.30800","16.35919","0.04219"
"196.56000","16.38024","0.04169"
"196.81200","16.40117","0.04227"
"197.06400","16.42215","0.04263"
"197.31600","16.44320","0.04248"
"197.56800","16.46418","0.04325"
"197.82000","16.48523","0.04342"
"198.07200","16.50616","0.04326"
"198.32400","16.52720","0.04336"
"198.57600","16.54819","0.04360"
"198.82800","16.56918","0.04393"
"199.08000","16.59016","0.04396"
"199.33200","16.61115","0.04464"
"199.58400","16.63213","0.04500"
"199.83600","16.65324","0.04502"
"200.08800","16.67416","0.04563"
"200.34000","16.69521","0.04541"
"200.59200","16.71614","0.04567"
"200.84400","16.73718","0.04599"
"201.09600","16.75817","0.04603"
"201.34800","16.77915","0.04636"
"201.60000","16.80020","0.04614"
"201.85200","16.82119","0.04644"
"202.10400","16.84217","0.04646"
"202.35600","16.86316","0.04684"
"202.60800","16.88421","0.04665"
"202.86000","16.90513","0.04705"
"203.11200","16.92618","0.04737"
"203.36400","16.94716","0.04752"
"203.61600","16.96827","0.04784"
"203.86800","16.98919","0.04796"
"204.12000","17.01018","0.04841"
"204.37200","17.03117","0.04861"
"204.62400","17.05221","0.04919"
"204.87600","17.07320","0.04925"
"205.12800","17.09418","0.04902"
"205.38000","17.11517","0.04961"
"205.63200","17.13616","0.05015"
"205.88400","17.15720","0.05049"
"206.13600","17.17813","0.05081"
"206.38800","17.19924","0.05092"
"206.64000","17.22016","0.05153"
"206.89200","17.24127","0.05163"
"207.14400","17.26213","0.05198"
"207.39600","17.28318","0.05251"
"207.64800","17.30411","0.05274"
"207.90000","17.32527","0.05321"
"208.15200","17.34620","0.04931"
"208.40400","17.36719","0.03055"
"208.65600","17.38817","0.02509"
"208.90800","17.40922","0.02658"
"209.16000","17.43020","0.02572"
"209.41200","17.45113","0.02779"
"209.66400","17.47223","0.02688"
"209.91600","17.49316","0.02876"
"210.16800","17.51421","0.03089"
"210.42000","17.53507","0.03040"
"210.67200","17.55618","0.03200"
"210.92400","17.57717","0.03154"
"211.17600","17.59821","0.03302"
"211.42800","17.61914","0.03358"
"211.68000","17.64018","0.03392"
"211.93200","17.66117","0.03421"
"212.18400","17.68228","0.03481"
"212.43600","17.70314","0.02919"
"212.68800","17.72419","0.02608"
"212.94000","17.74523","0.02503"
"213.19200","17.76616","0.02418"
"213.44400","17.78721","0.02388"
"213.69600","17.80819","0.02521"
"213.94800","17.82918","0.02547"
"214.20000","17.85016","0.02670"
"214.45200","17.87121","0.02663"
"214.70400","17.89214","0.02706"
"214.95600","17.91318","0.02788"
"215.20800","17.93417","0.02856"
"215.46000","17.95522","0.02915"
"215.71200","17.97614","0.03031"
"215.96400","17.99719","0.02947"
"216.21600","18.01823","0.02970"
"216.46800","18.03916","0.03106"
"216.72000","18.06015","0.03103"
"216.97200","18.08119","0.02815"
"217.22400","18.10218","0.02746"
"217.47600","18.12317","0.02699"
"217.72800","18.14421","0.02798"
"217.98000","18.16514","0.02879"
"218.23200","18.18624","0.02899"
"218.48400","18.20717","0.03013"
"218.73600","18.22816","0.02948"
"218.98800","18.24914","0.03045"
"219.24000","18.27025","0.03095"
"219.49200","18.29117","0.03159"
"219.74400","18.31216","0.03144"
"219.99600","18.33315","0.03196"
"220.24800","18.35425","0.03293"
"220.50000","18.37524","0.03370"
"220.75200","18.39616","0.03324"
"221.00400","18.41721","0.03406"
"221.25600","18.43814","0.03471"
"221.50800","18.45918","0.03501"
"221.76000","18.48017","0.03546"
"222.01200","18.50121","0.03622"
"222.26400","18.52214","0.03713"
"222.51600","18.54319","0.03699"
"222.76800","18.56411","0.03819"
"223.02000","18.58516","0.03811"
"223.27200","18.60614","0.03864"
"223.52400","18.62725","0.03883"
"223.77600","18.64812","0.03914"
"224.02800","18.66922","0.03944"
"224.28000","18.69021","0.03996"
"224.53200","18.71119","0.04064"
"224.78400","18.73218","0.02203"
"225.03600","18.75317","0.02092"
"225.28800","18.77421","0.02301"
"225.54000","18.79514","0.02233"
"225.79200","18.81618","0.02418"
"226.04400","18.83711","0.02341"
"226.29600","18.85816","0.02553"
"226.54800","18.87920","0.02693"
"226.80000","18.90025","0.02620"
"227.05200","18.92118","0.02756"
"227.30400","18.94222","0.02812"
"227.55600","18.96315","0.02978"
"227.80800","18.98419","0.02877"
"228.06000","19.00512","0.03042"
"228.31200","19.02617","0.02949"
"228.56400","19.04721","0.03094"
"228.81600","19.06820","0.03029"
"229.06800","19.08924","0.03210"
"229.32000","19.11023","0.03133"
"229.57200","19.13122","0.03232"
"229.82400","19.15214","0.03259"
"230.07600","19.17319","0.03294"
"230.32800","19.19417","0.03436"
"230.58000","19.21522","0.03446"
"230.83200","19.23615","0.03505"
"231.08400","19.25719","0.03487"
"231.33600","19.27818","0.03560"
"231.58800","19.29922","0.03628"
"231.84000","19.32015","0.03668"
"232.09200","19.34120","0.03685"
"232.34400","19.36218","0.03641"
"232.59600","19.38317","0.03758"
"232.84800","19.40421","0.03732"
"233.10000","19.42514","0.03712"
"233.35200","19.44625","0.03796"
"233.60400","19.46717","0.03843"
"233.85600","19.48822","0.03820"
"234.10800","19.50909","0.03893"
"234.36000","19.53019","0.03905"
"234.61200","19.55118","0.03955"
"234.86400","19.57222","0.03942"
"235.11600","19.59315","0.04000"
"235.36800","19.61419","0.04033"
"235.62000","19.63518","0.04058"
"235.87200","19.65623","0.04107"
"236.12400","19.67715","0.04131"
"236.37600","19.69814","0.04150"
"236.62800","19.71913","0.04198"
"236.88000","19.74023","0.03250"
"237.13200","19.76122","0.02762"
"237.38400","19.78214","0.03194"
"237.63600","19.80319","0.02774"
"237.88800","19.82418","0.03203"
"238.14000","19.84516","0.02995"
"238.39200","19.86609","0.03231"
"238.64400","19.88719","0.03204"
"238.89600","19.90818","0.03307"
"239.14800","19.92922","0.03456"
"239.40000","19.95015","0.03318"
"239.65200","19.97126","0.03393"
"239.90400","19.99224","0.03018"
"240.15600","20.01317","0.02962"
"240.40800","20.03416","0.03097"
"240.66000","20.05514","0.03084"
"240.91200","20.07625","0.03268"
"241.16400","20.09718","0.03286"
"241.41600","20.11822","0.03373"
"241.66800","20.13915","0.03318"
"241.92000","20.16019","0.03381"
"242.17200","20.18112","0.03335"
"242.42400","20.20217","0.03395"
"242.67600","20.22309","0.03477"
"242.92800","20.24420","0.03466"
"243.18000","20.26518","0.03421"
"243.43200","20.28617","0.03433"
"243.68400","20.30716","0.03419"
"243.93600","20.32820","0.03464"
"244.18800","20.34925","0.03510"
"244.44000","20.37017","0.03514"
"244.69200","20.39116","0.03546"
"244.94400","20.41221","0.03383"
"245.19600","20.43319","0.03384"
"245.44800","20.45418","0.03358"
"245.70000","20.47522","0.01924"
"245.95200","20.49615","0.02031"
"246.20400","20.51720","0.01939"
"246.45600","20.53812","0.01839"
"246.70800","20.55917","0.01662"
"246.96000","20.58015","0.01643"
"247.21200","20.60126","0.01709"
"247.46400","20.62219","0.01673"
"247.71600","20.64323","0.01538"
"247.96800","20.66416","0.01445"
"248.22000","20.68521","0.01665"
"248.47200","20.70619","0.01597"
"248.72400","20.72712","0.01610"
"248.97600","20.74817","0.01660"
"249.22800","20.76921","0.01685"
"249.48000","20.79020","0.01625"
"249.73200","20.81118","0.01646"
"249.98400","20.83223","0.00840"
"250.23600","20.85315","0.01027"
"250.48800","20.87420","0.00891"
"250.74000","20.89513","0.00804"
"250.99200","20.91617","0.00952"
"251.24400","20.93716","0.00994"
"251.49600","20.95821","0.00943"
"251.74800","20.97913","0.00869"
"252.00000","21.00018","0.01004"
"252.25200","21.02122","0.00936"
"252.50400","21.04221","0.00964"
"252.75600","21.06319","0.00985"
"253.00800","21.08418","0.00946"
"253.26000","21.10517","0.00990"
"253.51200","21.12615","0.01081"
"253.76400","21.14720","0.00996"
"254.01600","21.16818","0.01076"
"254.26800","21.18923","0.00995"
"254.52000","21.21016","0.01037"
"254.77200","21.23120","0.01071"
"255.02400","21.25213","0.01112"
"255.27600","21.27324","0.00916"
"255.52800","21.29416","0.00954"
"255.78000","21.31521","0.00897"
"256.03200","21.33619","0.00959"
"256.28400","21.35724","0.00930"
"256.53600","21.37823","0.00929"
"256.78800","21.39915","0.00886"
"257.04000","21.42020","0.00832"
"257.29200","21.44112","0.00850"
"257.54400","21.46217","0.00890"
"257.79600","21.48310","0.00804"
"258.04800","21.50420","0.00809"
"258.30000","21.52513","0.00863"
"258.55200","21.54623","0.00863"
"258.80400","21.56716","0.00863"
"259.05600","21.58815","0.00854"
"259.30800","21.60919","0.00889"
"259.56000","21.63024","0.00783"
"259.81200","21.65117","0.00891"
"260.06400","21.67215","0.00826"
"260.31600","21.69320","0.00899"
"260.56800","21.71418","0.00949"
"260.82000","21.73523","0.00859"
"261.07200","21.75615","0.00876"
"261.32400","21.77720","0.00824"
"261.57600","21.79819","0.00817"
"261.82800","21.81923","0.00870"
"262.08000","21.84010","0.00845"
"262.33200","21.86121","0.00872"
"262.58400","21.88213","0.00880"
"262.83600","21.90318","0.00756"
"263.08800","21.92416","0.00860"
"263.34000","21.94521","0.00811"
"263.59200","21.96619","0.00836"
"263.84400","21.98724","0.00804"
"264.09600","22.00817","0.00871"
"264.34800","22.02921","0.00836"
"264.60000","22.05020","0.00888"
"264.85200","22.07119","0.00822"
"265.10400","22.09217","0.00809"
"265.35600","22.11316","0.00788"
"265.60800","22.13420","0.00854"
"265.86000","22.15519","0.00829"
"266.11200","22.17618","0.00848"
"266.36400","22.19710","0.00882"
"266.61600","22.21821","0.00831"
"266.86800","22.23914","0.00794"
"267.12000","22.26024","0.00804"
"267.37200","22.28117","0.00855"
"267.62400","22.30221","0.00766"
"267.87600","22.32320","0.00769"
"268.12800","22.34419","0.00747"
"268.38000","22.36517","0.00731"
"268.63200","22.38616","0.00767"
"268.88400","22.40720","0.00757"
"269.13600","22.42813","0.00803"
"269.38800","22.44918","0.00778"
"269.64000","22.47016","0.00801"
"269.89200","22.49127","0.00756"
"270.14400","22.51213","0.00734"
"270.39600","22.53318","0.00800"
"270.64800","22.55417","0.00766"
"270.90000","22.57521","0.00737"
"271.15200","22.59614","0.00803"
"271.40400","22.61719","0.00761"
"271.65600","22.63811","0.00817"
"271.90800","22.65922","0.00773"
"272.16000","22.68020","0.00751"
"272.41200","22.70119","0.00756"
"272.66400","22.72218","0.00768"
"272.91600","22.74316","0.00742"
"273.16800","22.76421","0.00765"
"273.42000","22.78514","0.00758"
"273.67200","22.80624","0.00728"
"273.92400","22.82717","0.00772"
"274.17600","22.84821","0.00794"
"274.42800","22.86914","0.00770"
"274.68000","22.89018","0.00768"
"274.93200","22.91117","0.00813"
"275.18400","22.93222","0.00842"
"275.43600","22.95314","0.00764"
"275.68800","22.97419","0.00797"
"275.94000","22.99517","0.00842"
"276.19200","23.01622","0.00822"
"276.44400","23.03721","0.00827"
"276.69600","23.05819","0.00830"
"276.94800","23.07918","0.00865"
"277.20000","23.10023","0.00758"
"277.45200","23.12115","0.00765"
"277.70400","23.14214","0.00762"
"277.95600","23.16318","0.00798"
"278.20800","23.18411","0.00830"
"278.46000","23.20515","0.00763"
"278.71200","23.22620","0.00820"
"278.96400","23.24719","0.00796"
"279.21600","23.26818","0.00741"
"279.46800","23.28922","0.00769"
"279.72000","23.31008","0.00801"
"279.97200","23.33119","0.00792"
"280.22400","23.35224","0.00802"
"280.47600","23.37322","0.00792"
"280.72800","23.39421","0.00849"
"280.98000","23.41520","0.00747"
"281.23200","23.43624","0.00787"
"281.48400","23.45711","0.00887"
"281.73600","23.47821","0.00806"
"281.98800","23.49914","0.00787"
"282.24000","23.52019","0.00787"
"282.49200","23.54117","0.00841"
"282.74400","23.56222","0.00814"
"282.99600","23.58315","0.00814"
"283.24800","23.60419","0.00821"
"283.50000","23.62518","0.00838"
"283.75200","23.64616","0.00770"
"284.00400","23.66715","0.00755"
"284.25600","23.68819","0.00789"
"284.50800","23.70924","0.00842"
"284.76000","23.73017","0.00786"
"285.01200","23.75121","0.00777"
"285.26400","23.77220","0.00785"
"285.51600","23.79324","0.00786"
"285.76800","23.81411","0.00855"
"286.02000","23.83522","0.00750"
"286.27200","23.85614","0.00790"
"286.52400","23.87725","0.00757"
"286.77600","23.89817","0.00793"
"287.02800","23.91916","0.00823"
"287.28000","23.94020","0.00735"
"287.53200","23.96125","0.00758"
"287.78400","23.98212","0.00745"
"288.03600","24.00316","0.00773"
"288.28800","24.02415","0.00717"
"288.54000","24.04520","0.00691"
"288.79200","24.06618","0.00702"
"289.04400","24.08717","0.00696"
"289.29600","24.10822","0.00690"
"289.54800","24.12914","0.00758"
"289.80000","24.15019","0.00729"
"290.05200","24.17112","0.00685"
"290.30400","24.19216","0.00701"
"290.55600","24.21315","0.00731"
"290.80800","24.23425","0.00711"
"291.06000","24.25518","0.00692"
"291.31200","24.27622","0.00710"
"291.56400","24.29721","0.00693"
"291.81600","24.31814","0.00727"
"292.06800","24.33912","0.00716"
"292.32000","24.36017","0.00720"
"292.57200","24.38128","0.00685"
"292.82400","24.40220","0.00752"
"293.07600","24.42324","0.00713"
"293.32800","24.44417","0.00698"
"293.58000","24.46522","0.00729"
"293.83200","24.48615","0.00685"
"294.08400","24.50719","0.00815"
"294.33600","24.52812","0.00708"
"294.58800","24.54922","0.00708"
"294.84000","24.57015","0.00704"
"295.09200","24.59120","0.00703"
"295.34400","24.61218","0.00663"
"295.59600","24.63323","0.00730"
"295.84800","24.65421","0.00737"
"296.10000","24.67520","0.00745"
"296.35200","24.69613","0.00663"
"296.60400","24.71717","0.00739"
"296.85600","24.73822","0.00782"
"297.10800","24.75915","0.00776"
"297.36000","24.78019","0.00754"
"297.61200","24.80118","0.00719"
"297.86400","24.82222","0.00716"
"298.11600","24.84315","0.00754"
"298.36800","24.86413","0.00742"
"298.62000","24.88512","0.00742"
"298.87200","24.90623","0.00765"
"299.12400","24.92715","0.00727"
"299.37600","24.94820","0.00755"
"299.62800","24.96919","0.00748"
"299.88000","24.99023","0.00738"
"300.13200","25.01122","0.00744"
"300.38400","25.03214","0.00749"
"300.63600","25.05319","0.00703"
"300.88800","25.07417","0.00717"
"301.14000","25.09522","0.00724"
"301.39200","25.11615","0.00683"
"301.64400","25.13720","0.00741"
"301.89600","25.15818","0.00752"
"302.14800","25.17916","0.00722"
"302.40000","25.20015","0.00728"
"302.65200","25.22120","0.00774"
"302.90400","25.24212","0.00764"
"303.15600","25.26323","0.00758"
"303.40800","25.28416","0.00741"
"303.66000","25.30520","0.00758"
"303.91200","25.32619","0.00742"
"304.16400","25.34723","0.00752"
"304.41600","25.36816","0.00759"
"304.66800","25.38915","0.00702"
"304.92000","25.41019","0.00744"
"305.17200","25.43112","0.00759"
"305.42400","25.45223","0.00705"
"305.67600","25.47315","0.00754"
"305.92800","25.49420","0.00769"
"306.18000","25.51512","0.00788"
"306.43200","25.53617","0.00746"
"306.68400","25.55716","0.00725"
"306.93600","25.57820","0.00813"
"307.18800","25.59919","0.00808"
"307.44000","25.62017","0.00747"
"307.69200","25.64116","0.00789"
"307.94400","25.66220","0.00766"
"308.19600","25.68325","0.00754"
"308.44800","25.70418","0.00807"
"308.70000","25.72516","0.00768"
"308.95200","25.74615","0.00720"
"309.20400","25.76726","0.00803"
"309.45600","25.78812","0.00809"
"309.70800","25.80917","0.00746"
"309.96000","25.83015","0.00782"
"310.21200","25.85120","0.00723"
"310.46400","25.87219","0.00770"
"310.71600","25.89317","0.00781"
"310.96800","25.91422","0.00784"
"311.22000","25.93521","0.00756"
"311.47200","25.95619","0.00767"
"311.72400","25.97717","0.00827"
"311.97600","25.99816","0.00788"
"312.22800","26.01921","0.00764"
"312.48000","26.04020","0.00773"
"312.73200","26.06112","0.00816"
"312.98400","26.08223","0.00789"
"313.23600","26.10315","0.00799"
"313.48800","26.12420","0.00814"
"313.74000","26.14513","0.00807"
"313.99200","26.16617","0.00793"
"314.24400","26.18716","0.00791"
"314.49600","26.20820","0.00847"
"314.74800","26.22913","0.00808"
"315.00000","26.25018","0.00847"
"315.25200","26.27116","0.00822"
"315.50400","26.29227","0.00808"
"315.75600","26.31319","0.00763"
"316.00800","26.33418","0.00852"
"316.26000","26.35523","0.00803"
"316.51200","26.37621","0.00868"
"316.76400","26.39720","0.00884"
"317.01600","26.41812","0.00880"
"317.26800","26.43923","0.00790"
"317.52000","26.46016","0.00854"
"317.77200","26.48120","0.00851"
"318.02400","26.50213","0.00897"
"318.27600","26.52317","0.00786"
"318.52800","26.54416","0.00938"
"318.78000","26.56521","0.00874"
"319.03200","26.58613","0.00846"
"319.28400","26.60718","0.00904"
"319.53600","26.62823","0.00905"
"319.78800","26.64921","0.00867"
"320.04000","26.67014","0.00926"
"320.29200","26.69118","0.00959"
"320.54400","26.71223","0.00933"
"320.79600","26.73316","0.00910"
"321.04800","26.75414","0.00915"
"321.30000","26.77513","0.00888"
"321.55200","26.79617","0.00881"
"321.80400","26.81716","0.00866"
"322.05600","26.83821","0.00817"
"322.30800","26.85913","0.00868"
"322.56000","26.88018","0.00913"
"322.81200","26.90116","0.00893"
"323.06400","26.92215","0.00925"
"323.31600","26.94320","0.00944"
"323.56800","26.96418","0.00868"
"323.82000","26.98523","0.00933"
"324.07200","27.00616","0.00868"
"324.32400","27.02714","0.00840"
"324.57600","27.04819","0.00889"
"324.82800","27.06923","0.00862"
"325.08000","27.09010","0.00806"
"325.33200","27.11121","0.00894"
"325.58400","27.13213","0.00855"
"325.83600","27.15324","0.00866"
"326.08800","27.17410","0.00885"
"326.34000","27.19515","0.00823"
"326.59200","27.21614","0.00857"
"326.84400","27.23724","0.00924"
"327.09600","27.25817","0.00888"
"327.34800","27.27921","0.00856"
"327.60000","27.30020","0.00886"
"327.85200","27.32119","0.00911"
"328.10400","27.34217","0.00884"
"328.35600","27.36316","0.00928"
"328.60800","27.38420","0.00882"
"328.86000","27.40525","0.00895"
"329.11200","27.42618","0.00939"
"329.36400","27.44710","0.00944"
"329.61600","27.46821","0.00957"
"329.86800","27.48914","0.00904"
"330.12000","27.51018","0.00978"
"330.37200","27.53117","0.01001"
"330.62400","27.55221","0.00957"
"330.87600","27.57314","0.00952"
"331.12800","27.59418","0.00941"
"331.38000","27.61511","0.00998"
"331.63200","27.63616","0.00905"
"331.88400","27.65721","0.00899"
"332.13600","27.67825","0.00928"
"332.38800","27.69917","0.01004"
"332.64000","27.72016","0.00969"
"332.89200","27.74121","0.00957"
"333.14400","27.76213","0.00975"
"333.39600","27.78318","0.01044"
"333.64800","27.80410","0.00966"
"333.90000","27.82521","0.01008"
"334.15200","27.84614","0.01069"
"334.40400","27.86718","0.00984"
"334.65600","27.88817","0.01049"
"334.90800","27.90916","0.01055"
"335.16000","27.93014","0.01004"
"335.41200","27.95119","0.00947"
"335.66400","27.97218","0.01038"
"335.91600","27.99322","0.01056"
"336.16800","28.01421","0.01030"
"336.42000","28.03513","0.00996"
"336.67200","28.05618","0.01037"
"336.92400","28.07717","0.01013"
"337.17600","28.09821","0.00989"
"337.42800","28.11908","0.01040"
"337.68000","28.14018","0.01020"
"337.93200","28.16117","0.01033"
"338.18400","28.18221","0.01057"
"338.43600","28.20314","0.01055"
"338.68800","28.22419","0.01069"
"338.94000","28.24517","0.01066"
"339.19200","28.26622","0.01093"
"339.44400","28.28714","0.01072"
"339.69600","28.30819","0.01143"
"339.94800","28.32918","0.01106"
"340.20000","28.35022","0.01162"
"340.45200","28.37115","0.01085"
"340.70400","28.39214","0.01146"
"340.95600","28.41318","0.01128"
"341.20800","28.43417","0.01188"
"341.46000","28.45521","0.01191"
"341.71200","28.47608","0.01171"
"341.96400","28.49718","0.01184"
"342.21600","28.51811","0.01186"
"342.46800","28.53922","0.01185"
"342.72000","28.56014","0.01167"
"342.97200","28.58125","0.01193"
"343.22400","28.60217","0.01190"
"343.47600","28.62316","0.01254"
"343.72800","28.64415","0.01246"
"343.98000","28.66514","0.01231"
"344.23200","28.68624","0.01277"
"344.48400","28.70717","0.01280"
"344.73600","28.72815","0.01256"
"344.98800","28.74914","0.01262"
"345.24000","28.77018","0.01276"
"345.49200","28.79117","0.01296"
"345.74400","28.81216","0.01281"
"345.99600","28.83314","0.01341"
"346.24800","28.85419","0.01309"
"346.50000","28.87518","0.01265"
"346.75200","28.89616","0.01309"
"347.00400","28.91721","0.01308"
"347.25600","28.93825","0.01348"
"347.50800","28.95924","0.01307"
"347.76000","28.98017","0.01266"
"348.01200","29.00115","0.01241"
"348.26400","29.02214","0.01197"
"348.51600","29.04318","0.01148"
"348.76800","29.06417","0.01112"
"349.02000","29.08521","0.01214"
"349.27200","29.10614","0.01182"
"349.52400","29.12719","0.01213"
"349.77600","29.14812","0.01227"
"350.02800","29.16916","0.01280"
"350.28000","29.19009","0.01233"
"350.53200","29.21119","0.01293"
"350.78400","29.23218","0.01285"
"351.03600","29.25322","0.01266"
"351.28800","29.27415","0.01272"
"351.54000","29.29520","0.01297"
"351.79200","29.31618","0.01341"
"352.04400","29.33711","0.01310"
"352.29600","29.35816","0.01350"
"352.54800","29.37920","0.01269"
"352.80000","29.40025","0.01387"
"353.05200","29.42111","0.01416"
"353.30400","29.44222","0.01434"
"353.55600","29.46315","0.01428"
"353.80800","29.48419","0.01426"
"354.06000","29.50518","0.01451"
"354.31200","29.52617","0.01478"
"354.56400","29.54715","0.01441"
"354.81600","29.56825","0.01442"
"355.06800","29.58918","0.01500"
"355.32000","29.61023","0.01452"
"355.57200","29.63122","0.01508"
"355.82400","29.65220","0.01523"
"356.07600","29.67319","0.01507"
"356.32800","29.69411","0.01515"
"356.58000","29.71516","0.01539"
"356.83200","29.73621","0.01560"
"357.08400","29.75719","0.01592"
"357.33600","29.77812","0.01534"
"357.58800","29.79922","0.01638"
"357.84000","29.82015","0.01648"
"358.09200","29.84120","0.01613"
"358.34400","29.86218","0.01671"
"358.59600","29.88323","0.01684"
"358.84800","29.90415","0.01652"
"359.10000","29.92526","0.01762"
"359.35200","29.94619","0.01719"
"359.60400","29.96723","0.01764"
"359.85600","29.98822","0.01762"
"360.10800","30.00914","0.01759"
"360.36000","30.03019","0.01825"
"360.61200","30.05118","0.01723"
"360.86400","30.07222","0.01778"
"361.11600","30.09315","0.01797"
"361.36800","30.11419","0.01775"
"361.62000","30.13518","0.01831"
"361.87200","30.15623","0.01876"
"362.12400","30.17715","0.01886"
"362.37600","30.19820","0.01928"
"362.62800","30.21913","0.01901"
"362.88000","30.24017","0.01945"
"363.13200","30.26116","0.01992"
"363.38400","30.28221","0.02000"
"363.63600","30.30325","0.01990"
"363.88800","30.32418","0.01999"
"364.14000","30.34522","0.02028"
"364.39200","30.36615","0.01886"
"364.64400","30.38719","0.01464"
"364.89600","30.40818","0.01570"
"365.14800","30.42917","0.01662"
"365.40000","30.45009","0.01555"
"365.65200","30.47120","0.01711"
"365.90400","30.49212","0.01617"
"366.15600","30.51317","0.01772"
"366.40800","30.53415","0.01641"
"366.66000","30.55520","0.01724"
"366.91200","30.57619","0.01626"
"367.16400","30.59723","0.01769"
"367.41600","30.61816","0.01631"
"367.66800","30.63921","0.01789"
"367.92000","30.66019","0.01261"
"368.17200","30.68118","0.00827"
"368.42400","30.70217","0.00798"
"368.67600","30.72315","0.00746"
"368.92800","30.74420","0.00717"
"369.18000","30.76518","0.00672"
"369.43200","30.78623","0.00788"
"369.68400","30.80710","0.00707"
"369.93600","30.82820","0.00777"
"370.18800","30.84919","0.00702"
"370.44000","30.87017","0.00612"
"370.69200","30.89116","0.00749"
"370.94400","30.91221","0.00682"
"371.19600","30.93313","0.00743"
"371.44800","30.95418","0.00783"
"371.70000","30.97516","0.00759"
"371.95200","30.99621","0.00852"
"372.20400","31.01726","0.00779"
"372.45600","31.03818","0.00822"
"372.70800","31.05917","0.00789"
"372.96000","31.08015","0.00719"
"373.21200","31.10120","0.00846"
"373.46400","31.12213","0.00698"
"373.57400","31.13134","0.00792"