File: Force_trajectories/170226_2/Specimen_RawData_2.csv
End date,"2/26/2017"
Specimen label,"7BT_54"
Maximum Load,"0.12958",N

Time,Extension,Load
(s),(mm),(N)
"0.00000","0.00000","-0.00057"
"0.12600","0.00616","0.00010"
"0.25200","0.01967","-0.00015"
"0.37800","0.03163","0.00002"
"0.50400","0.04221","-0.00062"
"0.63000","0.05273","-0.00048"
"0.75600","0.06326","0.00007"
"0.88200","0.07366","0.00001"
"1.00800","0.08412","-0.00048"
"1.13400","0.09471","-0.00011"
"1.26000","0.10523","-0.00053"
"1.38600","0.11563","-0.00010"
"1.51200","0.12610","0.00042"
"1.63800","0.13668","-0.00005"
"1.76400","0.14720","0.00008"
"1.89000","0.15766","0.00013"
"2.01600","0.16819","-0.00013"
"2.14200","0.17865","-0.00012"
"2.26800","0.18923","0.00005"
"2.39400","0.19970","0.00017"
"2.52000","0.21016","-0.00015"
"2.64600","0.22062","0.00021"
"2.77200","0.23127","0.00032"
"2.89800","0.24173","0.00039"
"3.02400","0.25213","0.00007"
"3.15000","0.26260","0.00032"
"3.27600","0.27318","0.00022"
"3.40200","0.28364","0.00029"
"3.52800","0.29410","0.00018"
"3.65400","0.30463","0.00051"
"3.78000","0.31521","0.00038"
"3.90600","0.32573","0.00041"
"4.03200","0.33620","-0.00005"
"4.15800","0.34660","0.00030"
"4.28400","0.35718","0.00049"
"4.41000","0.36771","0.00010"
"4.53600","0.37823","0.00054"
"4.66200","0.38863","0.00025"
"4.78800","0.39915","0.00054"
"4.91400","0.40974","0.00022"
"5.04000","0.42020","0.00025"
"5.16600","0.43066","0.00088"
"5.29200","0.44113","0.00149"
"5.41800","0.45165","0.00099"
"5.54400","0.46217","0.00070"
"5.67000","0.47270","0.00041"
"5.79600","0.48310","0.00072"
"5.92200","0.49368","0.00095"
"6.04800","0.50421","0.00040"
"6.17400","0.51467","0.00109"
"6.30000","0.52513","0.00096"
"6.42600","0.53565","0.00094"
"6.55200","0.54618","0.00070"
"6.67800","0.55670","0.00111"
"6.80400","0.56716","0.00107"
"6.93000","0.57769","0.00125"
"7.05600","0.58821","0.00075"
"7.18200","0.59873","0.00061"
"7.30800","0.60914","0.00119"
"7.43400","0.61960","0.00113"
"7.56000","0.63018","0.00111"
"7.68600","0.64070","0.00081"
"7.81200","0.65123","0.00105"
"7.93800","0.66163","0.00169"
"8.06400","0.67215","0.00085"
"8.19000","0.68268","0.00080"
"8.31600","0.69320","0.00056"
"8.44200","0.70366","0.00106"
"8.56800","0.71413","0.00125"
"8.69400","0.72471","0.00119"
"8.82000","0.73523","0.00115"
"8.94600","0.74570","0.00119"
"9.07200","0.75616","0.00143"
"9.19800","0.76668","0.00169"
"9.32400","0.77720","0.00094"
"9.45000","0.78767","0.00110"
"9.57600","0.79813","0.00140"
"9.70200","0.80871","0.00195"
"9.82800","0.81918","0.00199"
"9.95400","0.82970","0.00192"
"10.08000","0.84016","0.00151"
"10.20600","0.85069","0.00033"
"10.33200","0.86121","-0.00012"
"10.45800","0.87167","0.00026"
"10.58400","0.88213","0.00089"
"10.71000","0.89266","0.00192"
"10.83600","0.90324","0.00133"
"10.96200","0.91370","0.00099"
"11.08800","0.92417","-0.00017"
"11.21400","0.93463","-0.00005"
"11.34000","0.94515","0.00039"
"11.46600","0.95562","0.00072"
"11.59200","0.96614","0.00197"
"11.71800","0.97660","0.00111"
"11.84400","0.98713","0.00080"
"11.97000","0.99771","0.00065"
"12.09600","1.00817","0.00038"
"12.22200","1.01863","0.00133"
"12.34800","1.02916","0.00163"
"12.47400","1.03968","0.00219"
"12.60000","1.05020","0.00084"
"12.72600","1.06067","0.00050"
"12.85200","1.07113","0.00094"
"12.97800","1.08171","0.00095"
"13.10400","1.09218","0.00204"
"13.23000","1.10270","0.00102"
"13.35600","1.11310","0.00188"
"13.48200","1.12368","0.00114"
"13.60800","1.13421","0.00089"
"13.73400","1.14467","0.00124"
"13.86000","1.15519","0.00115"
"13.98600","1.16572","0.00161"
"14.11200","1.17624","0.00143"
"14.23800","1.18670","0.00062"
"14.36400","1.19717","0.00118"
"14.49000","1.20763","0.00161"
"14.61600","1.21815","0.00150"
"14.74200","1.22867","0.00140"
"14.86800","1.23914","0.00129"
"14.99400","1.24960","0.00145"
"15.12000","1.26024","0.00105"
"15.24600","1.27071","0.00194"
"15.37200","1.28123","0.00205"
"15.49800","1.29157","0.00176"
"15.62400","1.30216","0.00197"
"15.75000","1.31268","0.00196"
"15.87600","1.32320","0.00168"
"16.00200","1.33361","0.00243"
"16.12800","1.34413","0.00164"
"16.25400","1.35471","0.00185"
"16.38000","1.36523","0.00230"
"16.50600","1.37564","0.00182"
"16.63200","1.38610","0.00255"
"16.75800","1.39668","0.00242"
"16.88400","1.40721","0.00164"
"17.01000","1.41767","0.00224"
"17.13600","1.42813","0.00231"
"17.26200","1.43866","0.00178"
"17.38800","1.44918","0.00232"
"17.51400","1.45970","0.00238"
"17.64000","1.47016","0.00173"
"17.76600","1.48069","0.00229"
"17.89200","1.49121","0.00224"
"18.01800","1.50173","0.00215"
"18.14400","1.51214","0.00242"
"18.27000","1.52272","0.00275"
"18.39600","1.53324","0.00246"
"18.52200","1.54365","0.00234"
"18.64800","1.55417","0.00235"
"18.77400","1.56457","0.00244"
"18.90000","1.57516","0.00164"
"19.02600","1.58568","0.00238"
"19.15200","1.59620","0.00219"
"19.27800","1.60666","0.00303"
"19.40400","1.61719","0.00276"
"19.53000","1.62765","0.00324"
"19.65600","1.63817","0.00317"
"19.78200","1.64864","0.00300"
"19.90800","1.65916","0.00290"
"20.03400","1.66968","0.00301"
"20.16000","1.68015","0.00309"
"20.28600","1.69067","0.00298"
"20.41200","1.70119","0.00307"
"20.53800","1.71171","0.00333"
"20.66400","1.72218","0.00299"
"20.79000","1.73264","0.00311"
"20.91600","1.74310","0.00367"
"21.04200","1.75369","0.00224"
"21.16800","1.76415","0.00237"
"21.29400","1.77467","0.00266"
"21.42000","1.78508","0.00261"
"21.54600","1.79572","0.00272"
"21.67200","1.80618","0.00276"
"21.79800","1.81665","0.00207"
"21.92400","1.82717","0.00297"
"22.05000","1.83763","0.00263"
"22.17600","1.84821","0.00270"
"22.30200","1.85874","0.00263"
"22.42800","1.86914","0.00293"
"22.55400","1.87966","0.00283"
"22.68000","1.89019","0.00301"
"22.80600","1.90071","0.00330"
"22.93200","1.91117","0.00301"
"23.05800","1.92158","0.00277"
"23.18400","1.93222","0.00303"
"23.31000","1.94268","0.00289"
"23.43600","1.95326","0.00309"
"23.56200","1.96367","0.00335"
"23.68800","1.97419","0.00329"
"23.81400","1.98471","0.00329"
"23.94000","1.99512","0.00324"
"24.06600","2.00564","0.00383"
"24.19200","2.01616","0.00348"
"24.31800","2.02669","0.00336"
"24.44400","2.03721","0.00325"
"24.57000","2.04761","0.00362"
"24.69600","2.05814","0.00399"
"24.82200","2.06872","0.00363"
"24.94800","2.07924","0.00391"
"25.07400","2.08970","0.00342"
"25.20000","2.10017","0.00409"
"25.32600","2.11069","0.00391"
"25.45200","2.12121","0.00392"
"25.57800","2.13168","0.00403"
"25.70400","2.14214","0.00423"
"25.83000","2.15260","0.00397"
"25.95600","2.16313","0.00409"
"26.08200","2.17365","0.00416"
"26.20800","2.18411","0.00408"
"26.33400","2.19463","0.00385"
"26.46000","2.20522","0.00439"
"26.58600","2.21574","0.00451"
"26.71200","2.22614","0.00469"
"26.83800","2.23661","0.00483"
"26.96400","2.24719","0.00449"
"27.09000","2.25765","0.00477"
"27.21600","2.26818","0.00493"
"27.34200","2.27864","0.00507"
"27.46800","2.28916","0.00505"
"27.59400","2.29974","0.00496"
"27.72000","2.31021","0.00509"
"27.84600","2.32067","0.00505"
"27.97200","2.33113","0.00506"
"28.09800","2.34166","0.00483"
"28.22400","2.35218","0.00531"
"28.35000","2.36264","0.00544"
"28.47600","2.37317","0.00546"
"28.60200","2.38375","0.00502"
"28.72800","2.39421","0.00524"
"28.85400","2.40462","0.00527"
"28.98000","2.41508","0.00548"
"29.10600","2.42566","0.00596"
"29.23200","2.43618","0.00588"
"29.35800","2.44665","0.00637"
"29.48400","2.45717","0.00554"
"29.61000","2.46769","0.00635"
"29.73600","2.47822","0.00600"
"29.86200","2.48868","0.00621"
"29.98800","2.49914","0.00579"
"30.11400","2.50967","0.00645"
"30.24000","2.52019","0.00694"
"30.36600","2.53071","0.00641"
"30.49200","2.54112","0.00588"
"30.61800","2.55164","0.00652"
"30.74400","2.56222","0.00696"
"30.87000","2.57268","0.00695"
"30.99600","2.58315","0.00679"
"31.12200","2.59361","0.00722"
"31.24800","2.60419","0.00690"
"31.37400","2.61466","0.00708"
"31.50000","2.62524","0.00723"
"31.62600","2.63564","0.00692"
"31.75200","2.64622","0.00716"
"31.87800","2.65675","0.00770"
"32.00400","2.66721","0.00783"
"32.13000","2.67761","0.00762"
"32.25600","2.68808","0.00842"
"32.38200","2.69872","0.00770"
"32.50800","2.70918","0.00820"
"32.63400","2.71965","0.00757"
"32.76000","2.73011","0.00860"
"32.88600","2.74069","0.00849"
"33.01200","2.75122","0.00847"
"33.13800","2.76168","0.00877"
"33.26400","2.77214","0.00811"
"33.39000","2.78266","0.00914"
"33.51600","2.79313","0.00885"
"33.64200","2.80365","0.00890"
"33.76800","2.81411","0.00918"
"33.89400","2.82470","0.00905"
"34.02000","2.83516","0.00907"
"34.14600","2.84568","0.00935"
"34.27200","2.85615","0.00952"
"34.39800","2.86667","0.00914"
"34.52400","2.87719","0.01002"
"34.65000","2.88766","0.00963"
"34.77600","2.89818","0.01043"
"34.90200","2.90864","0.01002"
"35.02800","2.91916","0.01031"
"35.15400","2.92963","0.01025"
"35.28000","2.94015","0.00996"
"35.40600","2.95061","0.01023"
"35.53200","2.96114","0.01049"
"35.65800","2.97166","0.01052"
"35.78400","2.98218","0.01080"
"35.91000","2.99265","0.01097"
"36.03600","3.00317","0.01102"
"36.16200","3.01369","0.01108"
"36.28800","3.02421","0.01069"
"36.41400","3.03468","0.01152"
"36.54000","3.04514","0.01180"
"36.66600","3.05566","0.01128"
"36.79200","3.06613","0.01158"
"36.91800","3.07665","0.01141"
"37.04400","3.08711","0.01193"
"37.17000","3.09770","0.01252"
"37.29600","3.10816","0.01181"
"37.42200","3.11862","0.01220"
"37.54800","3.12914","0.01266"
"37.67400","3.13961","0.01224"
"37.80000","3.15019","0.01154"
"37.92600","3.16065","0.01164"
"38.05200","3.17118","0.01197"
"38.17800","3.18170","0.01176"
"38.30400","3.19216","0.01172"
"38.43000","3.20275","0.01228"
"38.55600","3.21315","0.01203"
"38.68200","3.22361","0.01193"
"38.80800","3.23419","0.01200"
"38.93400","3.24466","0.01290"
"39.06000","3.25518","0.01203"
"39.18600","3.26564","0.01265"
"39.31200","3.27617","0.01286"
"39.43800","3.28663","0.01266"
"39.56400","3.29715","0.01259"
"39.69000","3.30756","0.01307"
"39.81600","3.31820","0.01376"
"39.94200","3.32878","0.01418"
"40.06800","3.33925","0.01390"
"40.19400","3.34965","0.01386"
"40.32000","3.36017","0.01386"
"40.44600","3.37069","0.01397"
"40.57200","3.38122","0.01457"
"40.69800","3.39168","0.01506"
"40.82400","3.40208","0.01494"
"40.95000","3.41267","0.01501"
"41.07600","3.42325","0.01526"
"41.20200","3.43371","0.01578"
"41.32800","3.44412","0.01570"
"41.45400","3.45464","0.01523"
"41.58000","3.46516","0.01554"
"41.70600","3.47569","0.01639"
"41.83200","3.48609","0.01591"
"41.95800","3.49667","0.01607"
"42.08400","3.50719","0.01591"
"42.21000","3.51772","0.01640"
"42.33600","3.52818","0.01639"
"42.46200","3.53858","0.01693"
"42.58800","3.54923","0.01716"
"42.71400","3.55969","0.01769"
"42.84000","3.57015","0.01721"
"42.96600","3.58062","0.01766"
"43.09200","3.59120","0.01763"
"43.21800","3.60172","0.01781"
"43.34400","3.61218","0.01846"
"43.47000","3.62265","0.01794"
"43.59600","3.63317","0.01835"
"43.72200","3.64363","0.01825"
"43.84800","3.65422","0.01851"
"43.97400","3.66468","0.01958"
"44.10000","3.67520","0.01924"
"44.22600","3.68573","0.01978"
"44.35200","3.69619","0.01929"
"44.47800","3.70665","0.01906"
"44.60400","3.71712","0.01990"
"44.73000","3.72770","0.01988"
"44.85600","3.73816","0.02036"
"44.98200","3.74868","0.02049"
"45.10800","3.75915","0.02110"
"45.23400","3.76967","0.02093"
"45.36000","3.78019","0.02100"
"45.48600","3.79066","0.02097"
"45.61200","3.80118","0.02181"
"45.73800","3.81170","0.02151"
"45.86400","3.82223","0.02157"
"45.99000","3.83269","0.02177"
"46.11600","3.84315","0.02155"
"46.24200","3.85367","0.02204"
"46.36800","3.86420","0.02224"
"46.49400","3.87466","0.02228"
"46.62000","3.88512","0.02314"
"46.74600","3.89565","0.02355"
"46.87200","3.90617","0.02332"
"46.99800","3.91669","0.02349"
"47.12400","3.92716","0.02393"
"47.25000","3.93768","0.02351"
"47.37600","3.94820","0.02401"
"47.50200","3.95866","0.02424"
"47.62800","3.96919","0.02466"
"47.75400","3.97959","0.02475"
"47.88000","3.99017","0.02447"
"48.00600","4.00070","0.02489"
"48.13200","4.01116","0.02530"
"48.25800","4.02168","0.02522"
"48.38400","4.03215","0.02521"
"48.51000","4.04267","0.02576"
"48.63600","4.05319","0.02515"
"48.76200","4.06366","0.02535"
"48.88800","4.07412","0.02558"
"49.01400","4.08470","0.02634"
"49.14000","4.09522","0.02679"
"49.26600","4.10569","0.02645"
"49.39200","4.11609","0.02695"
"49.51800","4.12667","0.02672"
"49.64400","4.13714","0.02684"
"49.77000","4.14766","0.02706"
"49.89600","4.15818","0.02735"
"50.02200","4.16871","0.02774"
"50.14800","4.17923","0.02789"
"50.27400","4.18969","0.02764"
"50.40000","4.20015","0.02796"
"50.52600","4.21068","0.02789"
"50.65200","4.22120","0.02788"
"50.77800","4.23166","0.02882"
"50.90400","4.24213","0.02884"
"51.03000","4.25265","0.02894"
"51.15600","4.26317","0.02890"
"51.28200","4.27370","0.02955"
"51.40800","4.28422","0.02986"
"51.53400","4.29462","0.03023"
"51.66000","4.30515","0.03052"
"51.78600","4.31561","0.03027"
"51.91200","4.32619","0.03103"
"52.03800","4.33659","0.03128"
"52.16400","4.34718","0.03116"
"52.29000","4.35770","0.03164"
"52.41600","4.36822","0.03164"
"52.54200","4.37869","0.03188"
"52.66800","4.38909","0.03212"
"52.79400","4.39967","0.03221"
"52.92000","4.41014","0.02757"
"53.04600","4.42066","0.02726"
"53.17200","4.43112","0.02765"
"53.29800","4.44165","0.02695"
"53.42400","4.45217","0.02641"
"53.55000","4.46263","0.02443"
"53.67600","4.47315","0.02664"
"53.80200","4.48368","0.02772"
"53.92800","4.49420","0.02788"
"54.05400","4.50472","0.02733"
"54.18000","4.51519","0.02819"
"54.30600","4.52565","0.02911"
"54.43200","4.53623","0.02939"
"54.55800","4.54669","0.02918"
"54.68400","4.55716","0.02864"
"54.81000","4.56762","0.02939"
"54.93600","4.57814","0.03005"
"55.06200","4.58867","0.02936"
"55.18800","4.59913","0.03023"
"55.31400","4.60965","0.03046"
"55.44000","4.62018","0.03057"
"55.56600","4.63070","0.03030"
"55.69200","4.64122","0.03090"
"55.81800","4.65163","0.03122"
"55.94400","4.66215","0.03209"
"56.07000","4.67267","0.03095"
"56.19600","4.68319","0.03131"
"56.32200","4.69366","0.03225"
"56.44800","4.70418","0.03287"
"56.57400","4.71476","0.03233"
"56.70000","4.72523","0.03323"
"56.82600","4.73563","0.03313"
"56.95200","4.74609","0.03307"
"57.07800","4.75668","0.03385"
"57.20400","4.76720","0.03460"
"57.33000","4.77766","0.03376"
"57.45600","4.78813","0.03400"
"57.58200","4.79865","0.03474"
"57.70800","4.80923","0.03486"
"57.83400","4.81969","0.03515"
"57.96000","4.83010","0.03433"
"58.08600","4.84062","0.03512"
"58.21200","4.85126","0.03537"
"58.33800","4.86167","0.03582"
"58.46400","4.87219","0.03567"
"58.59000","4.88271","0.03637"
"58.71600","4.89318","0.03637"
"58.84200","4.90370","0.03628"
"58.96800","4.91416","0.03680"
"59.09400","4.92462","0.03710"
"59.22000","4.93509","0.03703"
"59.34600","4.94567","0.03641"
"59.47200","4.95619","0.03667"
"59.59800","4.96660","0.03698"
"59.72400","4.97718","0.03684"
"59.85000","4.98770","0.03719"
"59.97600","4.99823","0.03750"
"60.10200","5.00863","0.03763"
"60.22800","5.01915","0.03772"
"60.35400","5.02968","0.03846"
"60.48000","5.04020","0.03857"
"60.60600","5.05066","0.03846"
"60.73200","5.06118","0.03906"
"60.85800","5.07171","0.03903"
"60.98400","5.08217","0.03902"
"61.11000","5.09269","0.03956"
"61.23600","5.10316","0.03974"
"61.36200","5.11368","0.03997"
"61.48800","5.12414","0.04020"
"61.61400","5.13467","0.03999"
"61.74000","5.14513","0.04044"
"61.86600","5.15565","0.04061"
"61.99200","5.16617","0.04014"
"62.11800","5.17664","0.04082"
"62.24400","5.18716","0.04099"
"62.37000","5.19762","0.04059"
"62.49600","5.20815","0.04099"
"62.62200","5.21867","0.04123"
"62.74800","5.22913","0.04138"
"62.87400","5.23966","0.04158"
"63.00000","5.25018","0.04207"
"63.12600","5.26064","0.04179"
"63.25200","5.27110","0.04238"
"63.37800","5.28163","0.04276"
"63.50400","5.29221","0.04289"
"63.63000","5.30267","0.04289"
"63.75600","5.31320","0.04293"
"63.88200","5.32366","0.04319"
"64.00800","5.33418","0.04320"
"64.13400","5.34471","0.04359"
"64.26000","5.35523","0.04391"
"64.38600","5.36563","0.04388"
"64.51200","5.37609","0.04422"
"64.63800","5.38674","0.04427"
"64.76400","5.39720","0.04456"
"64.89000","5.40772","0.04427"
"65.01600","5.41813","0.04457"
"65.14200","5.42871","0.04510"
"65.26800","5.43917","0.04495"
"65.39400","5.44970","0.04529"
"65.52000","5.46010","0.04532"
"65.64600","5.47068","0.04582"
"65.77200","5.48121","0.04576"
"65.89800","5.49173","0.04610"
"66.02400","5.50219","0.04653"
"66.15000","5.51260","0.04632"
"66.27600","5.52318","0.04634"
"66.40200","5.53370","0.04664"
"66.52800","5.54416","0.04749"
"66.65400","5.55463","0.04726"
"66.78000","5.56521","0.04745"
"66.90600","5.57573","0.04768"
"67.03200","5.58614","0.04832"
"67.15800","5.59660","0.04825"
"67.28400","5.60712","0.04842"
"67.41000","5.61765","0.04848"
"67.53600","5.62817","0.04896"
"67.66200","5.63857","0.04911"
"67.78800","5.64915","0.04945"
"67.91400","5.65974","0.04968"
"68.04000","5.67020","0.05015"
"68.16600","5.68066","0.05030"
"68.29200","5.69113","0.05055"
"68.41800","5.70171","0.05095"
"68.54400","5.71223","0.05162"
"68.67000","5.72264","0.05145"
"68.79600","5.73316","0.05192"
"68.92200","5.74368","0.05220"
"69.04800","5.75420","0.05246"
"69.17400","5.76467","0.05257"
"69.30000","5.77513","0.05310"
"69.42600","5.78571","0.05315"
"69.55200","5.79618","0.05339"
"69.67800","5.80670","0.05386"
"69.80400","5.81716","0.05370"
"69.93000","5.82769","0.05369"
"70.05600","5.83821","0.05398"
"70.18200","5.84867","0.05399"
"70.30800","5.85913","0.05435"
"70.43400","5.86966","0.05395"
"70.56000","5.88018","0.05074"
"70.68600","5.89070","0.05103"
"70.81200","5.90117","0.05068"
"70.93800","5.91163","0.05060"
"71.06400","5.92221","0.05102"
"71.19000","5.93268","0.05127"
"71.31600","5.94320","0.05156"
"71.44200","5.95360","0.05154"
"71.56800","5.96419","0.05194"
"71.69400","5.97465","0.05206"
"71.82000","5.98517","0.05266"
"71.94600","5.99564","0.05272"
"72.07200","6.00616","0.05269"
"72.19800","6.01668","0.05254"
"72.32400","6.02714","0.05141"
"72.45000","6.03761","0.05198"
"72.57600","6.04813","0.05181"
"72.70200","6.05865","0.05263"
"72.82800","6.06918","0.05272"
"72.95400","6.07970","0.05317"
"73.08000","6.09010","0.05333"
"73.20600","6.10068","0.05370"
"73.33200","6.11121","0.05413"
"73.45800","6.12167","0.05388"
"73.58400","6.13207","0.05445"
"73.71000","6.14272","0.05464"
"73.83600","6.15318","0.05380"
"73.96200","6.16364","0.05419"
"74.08800","6.17417","0.05458"
"74.21400","6.18463","0.05491"
"74.34000","6.19521","0.05500"
"74.46600","6.20574","0.05525"
"74.59200","6.21620","0.05523"
"74.71800","6.22660","0.05535"
"74.84400","6.23724","0.05574"
"74.97000","6.24765","0.05576"
"75.09600","6.25823","0.05623"
"75.22200","6.26863","0.05660"
"75.34800","6.27916","0.05691"
"75.47400","6.28968","0.05677"
"75.60000","6.30014","0.05743"
"75.72600","6.31067","0.05710"
"75.85200","6.32113","0.05793"
"75.97800","6.33177","0.05812"
"76.10400","6.34223","0.05827"
"76.23000","6.35270","0.05858"
"76.35600","6.36316","0.05899"
"76.48200","6.37368","0.05916"
"76.60800","6.38421","0.05955"
"76.73400","6.39467","0.05969"
"76.86000","6.40513","0.06061"
"76.98600","6.41566","0.06040"
"77.11200","6.42618","0.06076"
"77.23800","6.43670","0.06064"
"77.36400","6.44711","0.06102"
"77.49000","6.45763","0.06235"
"77.61600","6.46815","0.06237"
"77.74200","6.47867","0.06255"
"77.86800","6.48920","0.06285"
"77.99400","6.49966","0.06323"
"78.12000","6.51018","0.06334"
"78.24600","6.52071","0.06345"
"78.37200","6.53117","0.06365"
"78.49800","6.54157","0.06432"
"78.62400","6.55216","0.06500"
"78.75000","6.56268","0.06519"
"78.87600","6.57314","0.06581"
"79.00200","6.58360","0.06588"
"79.12800","6.59419","0.06585"
"79.25400","6.60471","0.06666"
"79.38000","6.61523","0.06687"
"79.50600","6.62564","0.06777"
"79.63200","6.63616","0.06837"
"79.75800","6.64668","0.06863"
"79.88400","6.65715","0.06853"
"80.01000","6.66767","0.06917"
"80.13600","6.67813","0.06964"
"80.26200","6.68871","0.06977"
"80.38800","6.69918","0.07075"
"80.51400","6.70964","0.07083"
"80.64000","6.72010","0.07083"
"80.76600","6.73069","0.07115"
"80.89200","6.74121","0.07216"
"81.01800","6.75161","0.07245"
"81.14400","6.76214","0.07230"
"81.27000","6.77272","0.07297"
"81.39600","6.78324","0.07353"
"81.52200","6.79371","0.07393"
"81.64800","6.80411","0.07421"
"81.77400","6.81469","0.07451"
"81.90000","6.82521","0.07493"
"82.02600","6.83574","0.07560"
"82.15200","6.84614","0.07537"
"82.27800","6.85660","0.07647"
"82.40400","6.86719","0.07695"
"82.53000","6.87771","0.07693"
"82.65600","6.88811","0.07750"
"82.78200","6.89858","0.07784"
"82.90800","6.90916","0.07834"
"83.03400","6.91968","0.07883"
"83.16000","6.93015","0.07864"
"83.28600","6.94061","0.07877"
"83.41200","6.95119","0.07956"
"83.53800","6.96171","0.07967"
"83.66400","6.97218","0.08005"
"83.79000","6.98264","0.08036"
"83.91600","6.99310","0.08048"
"84.04200","7.00369","0.08083"
"84.16800","7.01421","0.08121"
"84.29400","7.02467","0.08100"
"84.42000","7.03519","0.08127"
"84.54600","7.04572","0.08175"
"84.67200","7.05618","0.08153"
"84.79800","7.06664","0.08233"
"84.92400","7.07711","0.08222"
"85.05000","7.08763","0.08266"
"85.17600","7.09815","0.08283"
"85.30200","7.10868","0.08298"
"85.42800","7.11914","0.08313"
"85.55400","7.12966","0.08402"
"85.68000","7.14019","0.08409"
"85.80600","7.15065","0.08423"
"85.93200","7.16117","0.08487"
"86.05800","7.17164","0.08507"
"86.18400","7.18222","0.08576"
"86.31000","7.19268","0.08526"
"86.43600","7.20320","0.08595"
"86.56200","7.21367","0.08629"
"86.68800","7.22419","0.08638"
"86.81400","7.23465","0.08712"
"86.94000","7.24512","0.08724"
"87.06600","7.25558","0.08737"
"87.19200","7.26616","0.08765"
"87.31800","7.27668","0.08748"
"87.44400","7.28721","0.08824"
"87.57000","7.29767","0.08820"
"87.69600","7.30819","0.08837"
"87.82200","7.31866","0.08819"
"87.94800","7.32912","0.08874"
"88.07400","7.33964","0.08911"
"88.20000","7.35011","0.08899"
"88.32600","7.36069","0.08927"
"88.45200","7.37121","0.08950"
"88.57800","7.38168","0.08987"
"88.70400","7.39214","0.09025"
"88.83000","7.40266","0.09042"
"88.95600","7.41319","0.09123"
"89.08200","7.42365","0.09098"
"89.20800","7.43417","0.09107"
"89.33400","7.44463","0.09130"
"89.46000","7.45522","0.09174"
"89.58600","7.46562","0.09164"
"89.71200","7.47614","0.09212"
"89.83800","7.48667","0.09276"
"89.96400","7.49719","0.09219"
"90.09000","7.50771","0.09296"
"90.21600","7.51812","0.09309"
"90.34200","7.52864","0.09366"
"90.46800","7.53922","0.09388"
"90.59400","7.54974","0.09425"
"90.72000","7.56021","0.09524"
"90.84600","7.57061","0.09489"
"90.97200","7.58119","0.09535"
"91.09800","7.59166","0.09559"
"91.22400","7.60212","0.09614"
"91.35000","7.61264","0.09665"
"91.47600","7.62317","0.09684"
"91.60200","7.63369","0.09774"
"91.72800","7.64421","0.09736"
"91.85400","7.65461","0.09901"
"91.98000","7.66514","0.09867"
"92.10600","7.67572","0.09903"
"92.23200","7.68618","0.09948"
"92.35800","7.69665","0.09992"
"92.48400","7.70711","0.09886"
"92.61000","7.71769","0.09991"
"92.73600","7.72822","0.10069"
"92.86200","7.73868","0.10073"
"92.98800","7.74914","0.10155"
"93.11400","7.75960","0.10195"
"93.24000","7.77019","0.10221"
"93.36600","7.78071","0.10262"
"93.49200","7.79111","0.10255"
"93.61800","7.80164","0.10325"
"93.74400","7.81216","0.10387"
"93.87000","7.82268","0.10361"
"93.99600","7.83315","0.10428"
"94.12200","7.84367","0.10481"
"94.24800","7.85413","0.10488"
"94.37400","7.86471","0.10538"
"94.50000","7.87512","0.10642"
"94.62600","7.88570","0.10649"
"94.75200","7.89622","0.10701"
"94.87800","7.90675","0.10705"
"95.00400","7.91721","0.10742"
"95.13000","7.92761","0.10752"
"95.25600","7.93820","0.10743"
"95.38200","7.94866","0.10828"
"95.50800","7.95918","0.10892"
"95.63400","7.96965","0.10970"
"95.76000","7.98023","0.10999"
"95.88600","7.99075","0.10994"
"96.01200","8.00121","0.11017"
"96.13800","8.01168","0.11118"
"96.26400","8.02214","0.11053"
"96.39000","8.03266","0.11142"
"96.51600","8.04319","0.11135"
"96.64200","8.05365","0.11206"
"96.76800","8.06417","0.11235"
"96.89400","8.07470","0.11238"
"97.02000","8.08516","0.11310"
"97.14600","8.09568","0.11409"
"97.27200","8.10614","0.11384"
"97.39800","8.11667","0.11476"
"97.52400","8.12719","0.11444"
"97.65000","8.13765","0.11479"
"97.77600","8.14812","0.11480"
"97.90200","8.15864","0.11511"
"98.02800","8.16916","0.11512"
"98.15400","8.17969","0.11570"
"98.28000","8.19009","0.11626"
"98.40600","8.20061","0.11648"
"98.53200","8.21119","0.11627"
"98.65800","8.22166","0.11688"
"98.78400","8.23218","0.11719"
"98.91000","8.24264","0.11713"
"99.03600","8.25317","0.11756"
"99.16200","8.26369","0.11747"
"99.28800","8.27415","0.11778"
"99.41400","8.28462","0.11826"
"99.54000","8.29514","0.11834"
"99.66600","8.30566","0.11899"
"99.79200","8.31619","0.11929"
"99.91800","8.32665","0.11941"
"100.04400","8.33717","0.12031"
"100.17000","8.34769","0.12054"
"100.29600","8.35816","0.12051"
"100.42200","8.36862","0.12123"
"100.54800","8.37908","0.12150"
"100.67400","8.38967","0.12185"
"100.80000","8.40019","0.12266"
"100.92600","8.41071","0.12318"
"101.05200","8.42112","0.12392"
"101.17800","8.43170","0.12390"
"101.30400","8.44222","0.12449"
"101.43000","8.45269","0.12422"
"101.55600","8.46315","0.12482"
"101.68200","8.47367","0.12566"
"101.80800","8.48425","0.12545"
"101.93400","8.49472","0.12593"
"102.06000","8.50518","0.12616"
"102.18600","8.51564","0.12654"
"102.31200","8.52617","0.12680"
"102.43800","8.53669","0.12711"
"102.56400","8.54715","0.12725"
"102.69000","8.55762","0.12738"
"102.81600","8.56814","0.12768"
"102.94200","8.57866","0.12799"
"103.06800","8.58918","0.12806"
"103.19400","8.59965","0.12833"
"103.32000","8.61017","0.12888"
"103.44600","8.62063","0.12850"
"103.57200","8.63116","0.12864"
"103.69800","8.64162","0.12913"
"103.82400","8.65214","0.12921"
"103.95000","8.66273","-0.00143"
"104.07600","8.67319","0.00153"
"104.20200","8.68365","0.00072"
"104.32800","8.69411","0.00286"
"104.45400","8.70464","0.00385"
"104.58000","8.71516","0.00947"
"104.70600","8.72568","0.00137"
"104.83200","8.73609","-0.00217"
"104.95800","8.74667","-0.00122"
"105.08400","8.75713","0.01271"
"105.21000","8.76766","0.01570"
"105.33600","8.77818","0.00453"
"105.46200","8.78864","0.00006"
"105.58800","8.79917","-0.00095"
"105.71400","8.80963","0.00353"
"105.84000","8.82015","0.00669"
"105.96600","8.83062","0.00400"
"106.09200","8.84120","-0.00122"
"106.21800","8.85166","-0.00148"
"106.34400","8.86212","0.00302"
"106.47000","8.87259","0.00641"
"106.59600","8.88317","0.00336"
"106.72200","8.89363","-0.00014"
"106.84800","8.90416","0.00091"
"106.97400","8.91468","0.00738"
"107.10000","8.92514","0.00631"
"107.22600","8.93573","-0.00037"
"107.35200","8.94625","0.00100"
"107.47800","8.95665","0.00603"
"107.60400","8.96711","0.00672"
"107.73000","8.97770","0.00300"
"107.85600","8.98816","0.00102"
"107.98200","8.99868","0.00278"
"108.10800","9.00915","0.00518"
"108.23400","9.01973","0.00465"
"108.36000","9.03019","0.00185"
"108.48600","9.04066","0.00182"
"108.61200","9.05106","0.00505"
"108.73800","9.06170","0.00525"
"108.86400","9.07216","0.00267"
"108.99000","9.08269","0.00123"
"109.11600","9.09309","0.00339"
"109.24200","9.10367","0.00394"
"109.36800","9.11420","0.00496"
"109.49400","9.12472","0.00346"
"109.62000","9.13512","0.00264"
"109.74600","9.14565","0.00473"
"109.87200","9.15623","0.00572"
"109.99800","9.16669","0.00319"
"110.12400","9.17715","0.00127"
"110.25000","9.18762","0.00317"
"110.37600","9.19814","0.00547"
"110.50200","9.20866","0.00544"
"110.62800","9.21913","0.00207"
"110.75400","9.22959","0.00165"
"110.88000","9.24017","0.00469"
"111.00600","9.25070","0.00586"
"111.13200","9.26116","0.00200"
"111.25800","9.27168","0.00194"
"111.38400","9.28221","0.00450"
"111.51000","9.29273","0.00556"
"111.63600","9.30319","0.00381"
"111.76200","9.31359","0.00224"
"111.88800","9.32412","0.00327"
"112.01400","9.33470","0.00542"
"112.14000","9.34522","0.00518"
"112.26600","9.35569","0.00308"
"112.39200","9.36615","0.00332"
"112.51800","9.37673","0.00447"
"112.64400","9.38714","0.00507"
"112.77000","9.39766","0.00365"
"112.89600","9.40812","0.00279"
"113.02200","9.41870","0.00415"
"113.14800","9.42917","0.00505"
"113.27400","9.43969","0.00474"
"113.40000","9.45015","0.00412"
"113.52600","9.46068","0.00360"
"113.65200","9.47120","0.00445"
"113.77800","9.48166","0.00586"
"113.90400","9.49213","0.00455"
"114.03000","9.50265","0.00379"
"114.15600","9.51323","0.00416"
"114.28200","9.52369","0.00632"
"114.40800","9.53416","0.00536"
"114.53400","9.54462","0.00385"
"114.66000","9.55520","0.00472"
"114.78600","9.56567","0.00617"
"114.91200","9.57613","0.00568"
"115.03800","9.58659","0.00423"
"115.16400","9.59718","0.00441"
"115.29000","9.60770","0.00579"
"115.41600","9.61822","0.00664"
"115.54200","9.62863","0.00395"
"115.66800","9.63915","0.00391"
"115.79400","9.64967","0.00538"
"115.92000","9.66019","0.00605"
"116.04600","9.67060","0.00484"
"116.17200","9.68112","0.00447"
"116.29800","9.69170","0.00539"
"116.42400","9.70223","0.00522"
"116.55000","9.71269","0.00594"
"116.67600","9.72309","0.00512"
"116.80200","9.73368","0.00463"
"116.92800","9.74414","0.00578"
"117.05400","9.75466","0.00635"
"117.18000","9.76513","0.00594"
"117.30600","9.77571","0.00548"
"117.43200","9.78623","0.00571"
"117.55800","9.79675","0.00564"
"117.68400","9.80716","0.00566"
"117.81000","9.81762","0.00571"
"117.93600","9.82820","0.00582"
"118.06200","9.83873","0.00674"
"118.18800","9.84919","0.00638"
"118.31400","9.85959","0.00577"
"118.44000","9.87018","0.00519"
"118.56600","9.88070","0.00640"
"118.69200","9.89122","0.00684"
"118.81800","9.90162","0.00617"
"118.94400","9.91215","0.00517"
"119.07000","9.92267","0.00640"
"119.19600","9.93313","0.00703"
"119.32200","9.94366","0.00591"
"119.44800","9.95418","0.00522"
"119.57400","9.96470","0.00594"
"119.70000","9.97522","0.00610"
"119.82600","9.98563","0.00685"
"119.95200","9.99609","0.00596"
"120.07800","10.00668","0.00554"
"120.20400","10.01720","0.00712"
"120.33000","10.02766","0.00720"
"120.45600","10.03818","0.00613"
"120.58200","10.04871","0.00574"
"120.70800","10.05923","0.00686"
"120.83400","10.06969","0.00781"
"120.96000","10.08010","0.00672"
"121.08600","10.09062","0.00586"
"121.21200","10.10114","0.00711"
"121.33800","10.11167","0.00762"
"121.46400","10.12213","0.00699"
"121.59000","10.13265","0.00650"
"121.71600","10.14318","0.00701"
"121.84200","10.15364","0.00724"
"121.96800","10.16410","0.00671"
"122.09400","10.17462","0.00634"
"122.22000","10.18521","0.00660"
"122.34600","10.19567","0.00782"
"122.47200","10.20619","0.00795"
"122.59800","10.21666","0.00729"
"122.72400","10.22718","0.00705"
"122.85000","10.23770","0.00788"
"122.97600","10.24817","0.00788"
"123.10200","10.25863","0.00756"
"123.22800","10.26915","0.00769"
"123.35400","10.27967","0.00774"
"123.48000","10.29014","0.00807"
"123.60600","10.30066","0.00885"
"123.73200","10.31118","0.00744"
"123.85800","10.32171","0.00746"
"123.98400","10.33217","0.00817"
"124.11000","10.34263","0.00832"
"124.23600","10.35310","0.00775"
"124.36200","10.36368","0.00785"
"124.48800","10.37420","0.00840"
"124.61400","10.38466","0.00889"
"124.74000","10.39519","0.00832"
"124.86600","10.40577","0.00817"
"124.99200","10.41617","0.00811"
"125.11800","10.42664","0.00891"
"125.24400","10.43716","0.00883"
"125.37000","10.44762","0.00835"
"125.49600","10.45815","0.00789"
"125.62200","10.46867","0.00835"
"125.74800","10.47913","0.00926"
"125.87400","10.48965","0.00850"
"126.00000","10.50018","0.00816"
"126.12600","10.51070","0.00912"
"126.25200","10.52110","0.00946"
"126.37800","10.53157","0.00886"
"126.50400","10.54221","0.00840"
"126.63000","10.55267","0.00902"
"126.75600","10.56326","0.00927"
"126.88200","10.57366","0.00863"
"127.00800","10.58418","0.00887"
"127.13400","10.59471","0.00839"
"127.26000","10.60517","0.00930"
"127.38600","10.61563","0.00963"
"127.51200","10.62615","0.00942"
"127.63800","10.63674","0.00855"
"127.76400","10.64720","0.00972"
"127.89000","10.65766","0.00956"
"128.01600","10.66819","0.01052"
"128.14200","10.67865","0.00945"
"128.26800","10.68917","0.00919"
"128.39400","10.69964","0.01068"
"128.52000","10.71010","0.00977"
"128.64600","10.72068","0.00976"
"128.77200","10.73120","0.00986"
"128.89800","10.74173","0.01066"
"129.02400","10.75219","0.01061"
"129.15000","10.76265","0.00987"
"129.27600","10.77318","0.00987"
"129.40200","10.78364","0.01022"
"129.52800","10.79416","0.01109"
"129.65400","10.80469","0.01022"
"129.78000","10.81521","0.01057"
"129.90600","10.82567","0.01044"
"130.03200","10.83613","0.01110"
"130.15800","10.84660","0.01066"
"130.28400","10.85718","0.01084"
"130.41000","10.86770","0.01092"
"130.53600","10.87817","0.01098"
"130.66200","10.88863","0.01145"
"130.78800","10.89915","0.01125"
"130.91400","10.90968","0.01045"
"131.04000","10.92014","0.01183"
"131.16600","10.93066","0.01146"
"131.29200","10.94113","0.01089"
"131.41800","10.95171","0.01089"
"131.54400","10.96217","0.01157"
"131.67000","10.97263","0.01138"
"131.79600","10.98310","0.01176"
"131.92200","10.99374","0.01056"
"132.04800","11.00420","0.01191"
"132.17400","11.01467","0.01111"
"132.30000","11.02513","0.01218"
"132.42600","11.03565","0.01151"
"132.55200","11.04618","0.01230"
"132.67800","11.05664","0.01178"
"132.80400","11.06716","0.01229"
"132.93000","11.07769","0.01192"
"133.05600","11.08821","0.01236"
"133.18200","11.09867","0.01234"
"133.30800","11.10913","0.01226"
"133.43400","11.11972","0.01303"
"133.56000","11.13024","0.01300"
"133.68600","11.14076","0.01299"
"133.81200","11.15117","0.01311"
"133.93800","11.16163","0.01282"
"134.06400","11.17221","0.01345"
"134.19000","11.18268","0.01310"
"134.31600","11.19314","0.01336"
"134.44200","11.20360","0.01351"
"134.56800","11.21418","0.01315"
"134.69400","11.22465","0.01343"
"134.82000","11.23523","0.01374"
"134.94600","11.24563","0.01389"
"135.07200","11.25616","0.01318"
"135.19800","11.26674","0.01409"
"135.32400","11.27720","0.01380"
"135.45000","11.28767","0.01379"
"135.57600","11.29813","0.01331"
"135.70200","11.30871","0.01380"
"135.82800","11.31917","0.01454"
"135.95400","11.32964","0.01454"
"136.08000","11.34016","0.01390"
"136.20600","11.35069","0.01447"
"136.33200","11.36121","0.01441"
"136.45800","11.37161","0.01505"
"136.58400","11.38207","0.01518"
"136.71000","11.39266","0.01447"
"136.83600","11.40318","0.01475"
"136.96200","11.41370","0.01546"
"137.08800","11.42417","0.01500"
"137.21400","11.43469","0.01516"
"137.34000","11.44521","0.01559"
"137.46600","11.45567","0.01543"
"137.59200","11.46620","0.01576"
"137.71800","11.47666","0.01628"
"137.84400","11.48724","0.01504"
"137.97000","11.49771","0.01626"
"138.09600","11.50817","0.01602"
"138.22200","11.51869","0.01604"
"138.34800","11.52922","0.01615"
"138.47400","11.53968","0.01665"
"138.60000","11.55014","0.01671"
"138.72600","11.56061","0.01625"
"138.85200","11.57119","0.01634"
"138.97800","11.58165","0.01684"
"139.10400","11.59217","0.01718"
"139.23000","11.60264","0.01725"
"139.35600","11.61316","0.01642"
"139.48200","11.62368","0.01673"
"139.60800","11.63415","0.01750"
"139.73400","11.64467","0.01788"
"139.86000","11.65513","0.01782"
"139.98600","11.66572","0.01779"
"140.11200","11.67618","0.01857"
"140.23800","11.68670","0.01806"
"140.36400","11.69716","0.01887"
"140.49000","11.70769","0.01835"
"140.61600","11.71815","0.01847"
"140.74200","11.72861","0.01898"
"140.86800","11.73914","0.01925"
"140.99400","11.74960","0.01825"
"141.12000","11.76018","0.01904"
"141.24600","11.77065","0.01910"
"141.37200","11.78111","0.01956"
"141.49800","11.79163","0.01997"
"141.62400","11.80216","0.01957"
"141.75000","11.81268","0.01905"
"141.87600","11.82308","0.02034"
"142.00200","11.83360","0.01954"
"142.12800","11.84425","0.01988"
"142.25400","11.85471","0.02005"
"142.38000","11.86517","0.02041"
"142.50600","11.87564","0.02098"
"142.63200","11.88616","0.02044"
"142.75800","11.89668","0.02106"
"142.88400","11.90715","0.02125"
"143.01000","11.91767","0.02119"
"143.13600","11.92819","0.02138"
"143.26200","11.93871","0.02137"
"143.38800","11.94924","0.02187"
"143.51400","11.95970","0.02162"
"143.64000","11.97016","0.02233"
"143.76600","11.98069","0.02143"
"143.89200","11.99121","0.02165"
"144.01800","12.00161","0.02223"
"144.14400","12.01208","0.02273"
"144.27000","12.02272","0.02255"
"144.39600","12.03324","0.02301"
"144.52200","12.04370","0.02330"
"144.64800","12.05411","0.02334"
"144.77400","12.06469","0.02363"
"144.90000","12.07515","0.02384"
"145.02600","12.08568","0.02386"
"145.15200","12.09614","0.02409"
"145.27800","12.10666","0.02404"
"145.40400","12.11725","0.02410"
"145.53000","12.12771","0.02440"
"145.65600","12.13811","0.02487"
"145.78200","12.14864","0.02483"
"145.90800","12.15916","0.02519"
"146.03400","12.16968","0.02511"
"146.16000","12.18014","0.02533"
"146.28600","12.19067","0.02547"
"146.41200","12.20119","0.02645"
"146.53800","12.21171","0.02663"
"146.66400","12.22218","0.02659"
"146.79000","12.23264","0.02605"
"146.91600","12.24316","0.02653"
"147.04200","12.25369","0.02723"
"147.16800","12.26415","0.02733"
"147.29400","12.27461","0.02811"
"147.42000","12.28520","0.02816"
"147.54600","12.29572","0.02827"
"147.67200","12.30618","0.02802"
"147.79800","12.31664","0.02832"
"147.92400","12.32711","0.02842"
"148.05000","12.33769","0.02910"
"148.17600","12.34821","0.02882"
"148.30200","12.35868","0.02914"
"148.42800","12.36920","0.02933"
"148.55400","12.37966","0.02982"
"148.68000","12.39019","0.03027"
"148.80600","12.40065","0.03085"
"148.93200","12.41111","0.03070"
"149.05800","12.42163","0.03119"
"149.18400","12.43216","0.03106"
"149.31000","12.44262","0.03103"
"149.43600","12.45314","0.03095"
"149.56200","12.46373","0.03233"
"149.68800","12.47419","0.03192"
"149.81400","12.48471","0.03247"
"149.94000","12.49512","0.03251"
"150.06600","12.50564","0.03281"
"150.19200","12.51622","0.03307"
"150.31800","12.52668","0.03350"
"150.44400","12.53721","0.03337"
"150.57000","12.54761","0.03405"
"150.69600","12.55819","0.03440"
"150.82200","12.56866","0.03432"
"150.94800","12.57918","0.03463"
"151.07400","12.58964","0.03519"
"151.20000","12.60017","0.03566"
"151.32600","12.61069","0.03578"
"151.45200","12.62121","0.03584"
"151.57800","12.63167","0.03616"
"151.70400","12.64220","0.03614"
"151.83000","12.65272","0.03655"
"151.95600","12.66318","0.03677"
"152.08200","12.67365","0.03688"
"152.20800","12.68411","0.03753"
"152.33400","12.69469","0.03776"
"152.46000","12.70522","0.03789"
"152.58600","12.71574","0.03850"
"152.71200","12.72614","0.03826"
"152.83800","12.73673","0.03884"
"152.96400","12.74719","0.03894"
"153.09000","12.75765","0.03940"
"153.21600","12.76817","0.03960"
"153.34200","12.77864","0.04022"
"153.46800","12.78922","0.04038"
"153.59400","12.79968","0.04068"
"153.72000","12.81015","0.04098"
"153.84600","12.82061","0.04144"
"153.97200","12.83119","0.04113"
"154.09800","12.84172","0.04130"
"154.22400","12.85218","0.04152"
"154.35000","12.86264","0.04202"
"154.47600","12.87316","0.04227"
"154.60200","12.88369","0.04228"
"154.72800","12.89421","0.04271"
"154.85400","12.90467","0.04287"
"154.98000","12.91514","0.04336"
"155.10600","12.92566","0.04314"
"155.23200","12.93618","0.04349"
"155.35800","12.94665","0.04389"
"155.48400","12.95717","0.04414"
"155.61000","12.96769","0.04442"
"155.73600","12.97822","0.04484"
"155.86200","12.98868","0.04467"
"155.98800","12.99914","0.04525"
"156.11400","13.00966","0.04553"
"156.24000","13.02013","0.04606"
"156.36600","13.03065","0.04662"
"156.49200","13.04111","0.04667"
"156.61800","13.05164","0.04706"
"156.74400","13.06222","0.04724"
"156.87000","13.07268","0.04778"
"156.99600","13.08315","0.04810"
"157.12200","13.09367","0.04833"
"157.24800","13.10413","0.04902"
"157.37400","13.11466","0.04937"
"157.50000","13.12512","0.04977"
"157.62600","13.13570","0.05030"
"157.75200","13.14622","0.05064"
"157.87800","13.15669","0.05132"
"158.00400","13.16715","0.05123"
"158.13000","13.17761","0.05136"
"158.25600","13.18820","0.05175"
"158.38200","13.19872","0.05231"
"158.50800","13.20918","0.05284"
"158.63400","13.21970","0.05332"
"158.76000","13.23017","0.05423"
"158.88600","13.24069","0.05469"
"159.01200","13.25121","0.05517"
"159.13800","13.26162","0.05606"
"159.26400","13.27214","0.05580"
"159.39000","13.28266","0.05630"
"159.51600","13.29319","0.05744"
"159.64200","13.30365","0.05754"
"159.76800","13.31417","0.05777"
"159.89400","13.32476","0.05848"
"160.02000","13.33516","0.05879"
"160.14600","13.34562","0.05980"
"160.27200","13.35609","0.05987"
"160.39800","13.36673","0.06015"
"160.52400","13.37719","0.06063"
"160.65000","13.38771","0.06093"
"160.77600","13.39812","0.06158"
"160.90200","13.40870","0.06259"
"161.02800","13.41922","0.06278"
"161.15400","13.42969","0.06286"
"161.28000","13.44015","0.06382"
"161.40600","13.45061","0.06405"
"161.53200","13.46120","0.06463"
"161.65800","13.47166","0.06482"
"161.78400","13.48218","0.06605"
"161.91000","13.49258","0.06711"
"162.03600","13.50317","0.06746"
"162.16200","13.51369","0.06806"
"162.28800","13.52415","0.06885"
"162.41400","13.53462","0.06926"
"162.54000","13.54514","0.07023"
"162.66600","13.55566","0.07083"
"162.79200","13.56618","0.07114"
"162.91800","13.57665","0.07267"
"163.04400","13.58717","0.07236"
"163.17000","13.59770","0.07289"
"163.29600","13.60822","0.07384"
"163.42200","13.61862","0.07486"
"163.54800","13.62914","0.07526"
"163.67400","13.63973","0.07563"
"163.80000","13.65025","0.07639"
"163.92600","13.66071","0.07659"
"164.05200","13.67112","0.07707"
"164.17800","13.68170","0.07782"
"164.30400","13.69216","0.07869"
"164.43000","13.70262","0.07874"
"164.55600","13.71309","0.07913"
"164.68200","13.72367","0.07932"
"164.80800","13.73419","0.07975"
"164.93400","13.74466","0.08055"
"165.06000","13.75512","0.08083"
"165.18600","13.76570","0.08159"
"165.31200","13.77617","0.08181"
"165.43800","13.78669","0.08256"
"165.56400","13.79715","0.08301"
"165.69000","13.80768","0.08307"
"165.81600","13.81826","0.08338"
"165.94200","13.82866","0.08373"
"166.06800","13.83918","0.08403"
"166.19400","13.84965","0.08471"
"166.32000","13.86017","0.08495"
"166.44600","13.87069","0.08609"
"166.57200","13.88110","0.08663"
"166.69800","13.89162","0.08666"
"166.82400","13.90214","0.08646"
"166.95000","13.91267","0.08751"
"167.07600","13.92319","0.08750"
"167.20200","13.93365","0.08804"
"167.32800","13.94417","0.08849"
"167.45400","13.95470","0.08892"
"167.58000","13.96522","0.08933"
"167.70600","13.97562","0.08976"
"167.83200","13.98615","0.09044"
"167.95800","13.99673","0.09031"
"168.08400","14.00719","0.09062"
"168.21000","14.01772","0.09125"
"168.33600","14.02812","0.09133"
"168.46200","14.03870","0.09157"
"168.58800","14.04916","0.09237"
"168.71400","14.05963","0.09232"
"168.84000","14.07009","0.09259"
"168.96600","14.08068","0.09360"
"169.09200","14.09126","0.09396"
"169.21800","14.10172","0.09452"
"169.34400","14.11212","0.09508"
"169.47000","14.12265","0.09560"
"169.59600","14.13323","0.09559"
"169.72200","14.14369","0.09598"
"169.84800","14.15416","0.09648"
"169.97400","14.16462","0.09694"
"170.10000","14.17520","0.09773"
"170.22600","14.18572","0.09858"
"170.35200","14.19619","0.09857"
"170.47800","14.20665","0.09940"
"170.60400","14.21711","0.10033"
"170.73000","14.22764","0.10092"
"170.85600","14.23816","0.10116"
"170.98200","14.24862","0.10189"
"171.10800","14.25915","0.10219"
"171.23400","14.26973","0.10312"
"171.36000","14.28019","0.10317"
"171.48600","14.29066","0.10374"
"171.61200","14.30112","0.10402"
"171.73800","14.31170","0.10478"
"171.86400","14.32216","0.10521"
"171.99000","14.33269","0.10555"
"172.11600","14.34309","0.10620"
"172.24200","14.35367","0.10672"
"172.36800","14.36420","0.10779"
"172.49400","14.37472","0.10754"
"172.62000","14.38512","0.10854"
"172.74600","14.39565","0.10905"
"172.87200","14.40611","0.10983"
"172.99800","14.41669","0.10984"
"173.12400","14.42716","0.11151"
"173.25000","14.43768","0.11200"
"173.37600","14.44820","0.11242"
"173.50200","14.45872","0.11331"
"173.62800","14.46919","0.11383"
"173.75400","14.47965","0.11449"
"173.88000","14.49017","0.11506"
"174.00600","14.50064","0.11609"
"174.13200","14.51122","0.11644"
"174.25800","14.52162","0.11744"
"174.38400","14.53220","0.11846"
"174.51000","14.54267","0.11894"
"174.63600","14.55313","0.11979"
"174.76200","14.56365","0.12043"
"174.88800","14.57418","0.12136"
"175.01400","14.58470","0.12160"
"175.14000","14.59516","0.12247"
"175.26600","14.60563","0.12290"
"175.39200","14.61615","0.12273"
"175.51800","14.62673","0.12380"
"175.64400","14.63720","0.12398"
"175.77000","14.64766","0.12459"
"175.89600","14.65812","0.12487"
"176.02200","14.66864","0.01018"
"176.14800","14.67917","-0.00663"
"176.27400","14.68969","-0.00226"
"176.40000","14.70015","-0.00555"
"176.52600","14.71074","-0.00396"
"176.65200","14.72120","-0.00304"
"176.77800","14.73166","-0.00376"
"176.90400","14.74207","-0.00298"
"177.03000","14.75265","-0.00116"
"177.15600","14.76317","-0.00035"
"177.28200","14.77363","-0.00026"
"177.40800","14.78410","0.00042"
"177.53400","14.79468","-0.00036"
"177.66000","14.80520","-0.00102"
"177.78600","14.81567","-0.00088"
"177.91200","14.82613","-0.00085"
"178.03800","14.83659","-0.00156"
"178.16400","14.84718","-0.00126"
"178.29000","14.85776","-0.00200"
"178.41600","14.86822","-0.00160"
"178.54200","14.87862","-0.00188"
"178.66800","14.88921","-0.00168"
"178.79400","14.89967","-0.00208"
"178.92000","14.91020","-0.00174"
"179.04600","14.92066","-0.00136"
"179.17200","14.93118","-0.00177"
"179.29800","14.94170","-0.00208"
"179.42400","14.95223","-0.00195"
"179.55000","14.96263","-0.00183"
"179.67600","14.97321","-0.00221"
"179.80200","14.98368","-0.00106"
"179.92800","14.99420","-0.00184"
"180.05400","15.00466","-0.00150"
"180.07200","15.00616","-0.00145"