File: Force_trajectories/170226_2/Specimen_RawData_3.csv
End date,"2/26/2017"
Specimen label,"5BT_33"
Maximum Load,"0.16845",N

Time,Extension,Load
(s),(mm),(N)
"0.00000","0.00000","0.00005"
"0.45600","0.03827","0.00023"
"0.91200","0.07617","0.00033"
"1.36800","0.11414","0.00055"
"1.82400","0.15216","-0.00035"
"2.28000","0.19019","0.00022"
"2.73600","0.22816","0.00055"
"3.19200","0.26618","0.00022"
"3.64800","0.30421","0.00011"
"4.10400","0.34218","-0.00014"
"4.56000","0.38014","0.00045"
"5.01600","0.41817","0.00056"
"5.47200","0.45619","0.00077"
"5.92800","0.49422","-0.00035"
"6.38400","0.53219","0.00066"
"6.84000","0.57015","0.00071"
"7.29600","0.60818","0.00068"
"7.75200","0.64615","0.00052"
"8.20800","0.68417","0.00043"
"8.66400","0.72214","0.00014"
"9.12000","0.76016","0.00093"
"9.57600","0.79819","0.00066"
"10.03200","0.83622","0.00012"
"10.48800","0.87418","0.00045"
"10.94400","0.91215","0.00041"
"11.40000","0.95018","0.00057"
"11.85600","0.98820","0.00057"
"12.31200","1.02623","0.00009"
"12.76800","1.06425","0.00064"
"13.22400","1.10216","0.00022"
"13.68000","1.14007","0.00061"
"14.13600","1.17815","0.00042"
"14.59200","1.21624","0.00002"
"15.04800","1.25420","0.00038"
"15.50400","1.29217","0.00026"
"15.96000","1.33020","0.00120"
"16.41600","1.36810","0.00071"
"16.87200","1.40619","0.00070"
"17.32800","1.44416","0.00057"
"17.78400","1.48224","0.00074"
"18.24000","1.52021","0.00086"
"18.69600","1.55817","0.00069"
"19.15200","1.59620","0.00070"
"19.60800","1.63417","0.00095"
"20.06400","1.67219","0.00037"
"20.52000","1.71022","0.00055"
"20.97600","1.74825","0.00092"
"21.43200","1.78621","0.00065"
"21.88800","1.82412","0.00064"
"22.34400","1.86215","0.00118"
"22.80000","1.90017","0.00064"
"23.25600","1.93820","0.00076"
"23.71200","1.97622","0.00028"
"24.16800","2.01419","0.00117"
"24.62400","2.05222","0.00055"
"25.08000","2.09018","0.00057"
"25.53600","2.12821","0.00072"
"25.99200","2.16617","0.00090"
"26.44800","2.20414","0.00080"
"26.90400","2.24223","0.00122"
"27.36000","2.28019","0.00062"
"27.81600","2.31822","0.00071"
"28.27200","2.35613","0.00147"
"28.72800","2.39421","0.00145"
"29.18400","2.43218","0.00111"
"29.64000","2.47020","0.00120"
"30.09600","2.50823","0.00122"
"30.55200","2.54626","0.00123"
"31.00800","2.58416","0.00075"
"31.46400","2.62213","0.00028"
"31.92000","2.66016","0.00114"
"32.37600","2.69824","0.00131"
"32.83200","2.73621","0.00144"
"33.28800","2.77423","0.00092"
"33.74400","2.81220","0.00150"
"34.20000","2.85017","0.00079"
"34.65600","2.88813","0.00113"
"35.11200","2.92616","0.00107"
"35.56800","2.96419","0.00118"
"36.02400","3.00215","0.00133"
"36.48000","3.04024","0.00122"
"36.93600","3.07814","0.00100"
"37.39200","3.11611","0.00183"
"37.84800","3.15420","0.00156"
"38.30400","3.19228","0.00144"
"38.76000","3.23019","0.00112"
"39.21600","3.26822","0.00129"
"39.67200","3.30618","0.00131"
"40.12800","3.34421","0.00159"
"40.58400","3.38217","0.00130"
"41.04000","3.42020","0.00133"
"41.49600","3.45823","0.00116"
"41.95200","3.49619","0.00139"
"42.40800","3.53422","0.00116"
"42.86400","3.57219","0.00146"
"43.32000","3.61021","0.00097"
"43.77600","3.64812","0.00169"
"44.23200","3.68614","0.00197"
"44.68800","3.72417","0.00129"
"45.14400","3.76220","0.00185"
"45.60000","3.80022","0.00154"
"46.05600","3.83819","0.00295"
"46.51200","3.87616","0.00198"
"46.96800","3.91418","0.00132"
"47.42400","3.95221","0.00188"
"47.88000","3.99023","0.00190"
"48.33600","4.02820","0.00195"
"48.79200","4.06617","0.00134"
"49.24800","4.10419","0.00185"
"49.70400","4.14216","0.00143"
"50.16000","4.18013","0.00152"
"50.61600","4.21815","0.00198"
"51.07200","4.25624","0.00175"
"51.52800","4.29420","0.00112"
"51.98400","4.33217","0.00159"
"52.44000","4.37014","0.00199"
"52.89600","4.40816","0.00164"
"53.35200","4.44619","0.00159"
"53.80800","4.48421","0.00161"
"54.26400","4.52224","0.00137"
"54.72000","4.56021","0.00208"
"55.17600","4.59811","0.00218"
"55.63200","4.63614","0.00245"
"56.08800","4.67423","0.00155"
"56.54400","4.71219","0.00189"
"57.00000","4.75022","0.00178"
"57.45600","4.78819","0.00251"
"57.91200","4.82615","0.00208"
"58.36800","4.86418","0.00225"
"58.82400","4.90220","0.00210"
"59.28000","4.94017","0.00235"
"59.73600","4.97820","0.00195"
"60.19200","5.01616","0.00211"
"60.64800","5.05419","0.00252"
"61.10400","5.09215","0.00203"
"61.56000","5.13018","0.00254"
"62.01600","5.16815","0.00248"
"62.47200","5.20617","0.00207"
"62.92800","5.24420","0.00266"
"63.38400","5.28223","0.00236"
"63.84000","5.32019","0.00238"
"64.29600","5.35810","0.00265"
"64.75200","5.39618","0.00226"
"65.20800","5.43421","0.00240"
"65.66400","5.47218","0.00207"
"66.12000","5.51020","0.00210"
"66.57600","5.54817","0.00219"
"67.03200","5.58620","0.00187"
"67.48800","5.62410","0.00255"
"67.94400","5.66219","0.00204"
"68.40000","5.70021","0.00222"
"68.85600","5.73818","0.00209"
"69.31200","5.77627","0.00256"
"69.76800","5.81417","0.00224"
"70.22400","5.85214","0.00214"
"70.68000","5.89011","0.00279"
"71.13600","5.92819","0.00229"
"71.59200","5.96622","0.00232"
"72.04800","6.00418","0.00187"
"72.50400","6.04221","0.00252"
"72.96000","6.08012","0.00242"
"73.41600","6.11814","0.00225"
"73.87200","6.15617","0.00216"
"74.32800","6.19426","0.00178"
"74.78400","6.23222","0.00241"
"75.24000","6.27019","0.00211"
"75.69600","6.30815","0.00245"
"76.15200","6.34612","0.00191"
"76.60800","6.38421","0.00245"
"77.06400","6.42223","0.00289"
"77.52000","6.46020","0.00239"
"77.97600","6.49823","0.00209"
"78.43200","6.53619","0.00201"
"78.88800","6.57416","0.00253"
"79.34400","6.61212","0.00212"
"79.80000","6.65021","0.00227"
"80.25600","6.68818","0.00205"
"80.71200","6.72620","0.00293"
"81.16800","6.76423","0.00312"
"81.62400","6.80220","0.00226"
"82.08000","6.84016","0.00235"
"82.53600","6.87813","0.00306"
"82.99200","6.91615","0.00248"
"83.44800","6.95424","0.00276"
"83.90400","6.99221","0.00307"
"84.36000","7.03023","0.00231"
"84.81600","7.06820","0.00348"
"85.27200","7.10617","0.00297"
"85.72800","7.14419","0.00280"
"86.18400","7.18216","0.00306"
"86.64000","7.22018","0.00270"
"87.09600","7.25827","0.00276"
"87.55200","7.29618","0.00336"
"88.00800","7.33414","0.00352"
"88.46400","7.37211","0.00275"
"88.92000","7.41014","0.00305"
"89.37600","7.44822","0.00328"
"89.83200","7.48625","0.00283"
"90.28800","7.52427","0.00310"
"90.74400","7.56212","0.00310"
"91.20000","7.60015","0.00273"
"91.65600","7.63811","0.00305"
"92.11200","7.67620","0.00293"
"92.56800","7.71422","0.00287"
"93.02400","7.75219","0.00299"
"93.48000","7.79016","0.00301"
"93.93600","7.82812","0.00338"
"94.39200","7.86615","0.00254"
"94.84800","7.90418","0.00310"
"95.30400","7.94220","0.00273"
"95.76000","7.98017","0.00285"
"96.21600","8.01820","0.00266"
"96.67200","8.05622","0.00288"
"97.12800","8.09413","0.00285"
"97.58400","8.13215","0.00313"
"98.04000","8.17018","0.00323"
"98.49600","8.20815","0.00313"
"98.95200","8.24617","0.00250"
"99.40800","8.28414","0.00316"
"99.86400","8.32216","0.00356"
"100.32000","8.36013","0.00360"
"100.77600","8.39816","0.00318"
"101.23200","8.43618","0.00213"
"101.68800","8.47415","0.00178"
"102.14400","8.51224","0.00261"
"102.60000","8.55020","0.00199"
"103.05600","8.58811","0.00243"
"103.51200","8.62619","0.00223"
"103.96800","8.66410","0.00261"
"104.42400","8.70219","0.00276"
"104.88000","8.74015","0.00222"
"105.33600","8.77824","0.00291"
"105.79200","8.81615","0.00296"
"106.24800","8.85411","0.00312"
"106.70400","8.89214","0.00191"
"107.16000","8.93022","0.00265"
"107.61600","8.96825","0.00285"
"108.07200","9.00622","0.00270"
"108.52800","9.04418","0.00273"
"108.98400","9.08215","0.00215"
"109.44000","9.12012","0.00259"
"109.89600","9.15820","0.00296"
"110.35200","9.19623","0.00243"
"110.80800","9.23419","0.00308"
"111.26400","9.27216","0.00236"
"111.72000","9.31019","0.00292"
"112.17600","9.34815","0.00266"
"112.63200","9.38618","0.00288"
"113.08800","9.42421","0.00206"
"113.54400","9.46223","0.00343"
"114.00000","9.50020","0.00285"
"114.45600","9.53816","0.00262"
"114.91200","9.57619","0.00282"
"115.36800","9.61416","0.00287"
"115.82400","9.65218","0.00296"
"116.28000","9.69021","0.00310"
"116.73600","9.72818","0.00269"
"117.19200","9.76614","0.00362"
"117.64800","9.80417","0.00341"
"118.10400","9.84213","0.00309"
"118.56000","9.88016","0.00275"
"119.01600","9.91819","0.00304"
"119.47200","9.95615","0.00301"
"119.92800","9.99424","0.00298"
"120.38400","10.03221","0.00258"
"120.84000","10.07017","0.00312"
"121.29600","10.10814","0.00359"
"121.75200","10.14616","0.00375"
"122.20800","10.18419","0.00272"
"122.66400","10.22222","0.00270"
"123.12000","10.26024","0.00225"
"123.57600","10.29821","0.00277"
"124.03200","10.33612","0.00327"
"124.48800","10.37414","0.00298"
"124.94400","10.41217","0.00255"
"125.40000","10.45019","0.00276"
"125.85600","10.48822","0.00284"
"126.31200","10.52619","0.00305"
"126.76800","10.56415","0.00270"
"127.22400","10.60212","0.00296"
"127.68000","10.64020","0.00277"
"128.13600","10.67823","0.00304"
"128.59200","10.71620","0.00258"
"129.04800","10.75422","0.00297"
"129.50400","10.79219","0.00289"
"129.96000","10.83010","0.00310"
"130.41600","10.86818","0.00323"
"130.87200","10.90621","0.00275"
"131.32800","10.94423","0.00319"
"131.78400","10.98220","0.00317"
"132.24000","11.02017","0.00209"
"132.69600","11.05819","0.00265"
"133.15200","11.09610","0.00294"
"133.60800","11.13419","0.00305"
"134.06400","11.17221","0.00291"
"134.52000","11.21018","0.00313"
"134.97600","11.24821","0.00304"
"135.43200","11.28617","0.00353"
"135.88800","11.32414","0.00285"
"136.34400","11.36216","0.00334"
"136.80000","11.40013","0.00307"
"137.25600","11.43822","0.00300"
"137.71200","11.47624","0.00292"
"138.16800","11.51421","0.00321"
"138.62400","11.55218","0.00328"
"139.08000","11.59014","0.00270"
"139.53600","11.62817","0.00346"
"139.99200","11.66619","0.00369"
"140.44800","11.70422","0.00292"
"140.90400","11.74219","0.00291"
"141.36000","11.78021","0.00370"
"141.81600","11.81812","0.00298"
"142.27200","11.85614","0.00370"
"142.72800","11.89411","0.00345"
"143.18400","11.93226","0.00288"
"143.64000","11.97022","0.00321"
"144.09600","12.00825","0.00313"
"144.55200","12.04622","0.00351"
"145.00800","12.08412","0.00337"
"145.46400","12.12221","0.00289"
"145.92000","12.16018","0.00366"
"146.37600","12.19820","0.00303"
"146.83200","12.23623","0.00308"
"147.28800","12.27419","0.00365"
"147.74400","12.31216","0.00328"
"148.20000","12.35013","0.00335"
"148.65600","12.38815","0.00354"
"149.11200","12.42618","0.00358"
"149.56800","12.46415","0.00313"
"150.02400","12.50223","0.00325"
"150.48000","12.54014","0.00284"
"150.93600","12.57816","0.00353"
"151.39200","12.61619","0.00305"
"151.84800","12.65421","0.00384"
"152.30400","12.69224","0.00315"
"152.76000","12.73015","0.00348"
"153.21600","12.76824","0.00344"
"153.67200","12.80614","0.00326"
"154.12800","12.84417","0.00344"
"154.58400","12.88219","0.00354"
"155.04000","12.92016","0.00317"
"155.49600","12.95813","0.00328"
"155.95200","12.99621","0.00330"
"156.40800","13.03418","0.00274"
"156.86400","13.07215","0.00282"
"157.32000","13.11017","0.00303"
"157.77600","13.14814","0.00294"
"158.23200","13.18622","0.00289"
"158.68800","13.22425","0.00308"
"159.14400","13.26221","0.00298"
"159.60000","13.30018","0.00353"
"160.05600","13.33815","0.00324"
"160.51200","13.37611","0.00297"
"160.96800","13.41420","0.00291"
"161.42400","13.45217","0.00337"
"161.88000","13.49019","0.00265"
"162.33600","13.52816","0.00384"
"162.79200","13.56612","0.00355"
"163.24800","13.60415","0.00312"
"163.70400","13.64218","0.00368"
"164.16000","13.68020","0.00337"
"164.61600","13.71817","0.00294"
"165.07200","13.75626","0.00367"
"165.52800","13.79416","0.00249"
"165.98400","13.83213","0.00314"
"166.44000","13.87016","0.00299"
"166.89600","13.90824","0.00284"
"167.35200","13.94621","0.00295"
"167.80800","13.98423","0.00328"
"168.26400","14.02214","0.00315"
"168.72000","14.06017","0.00313"
"169.17600","14.09813","0.00346"
"169.63200","14.13622","0.00293"
"170.08800","14.17418","0.00330"
"170.54400","14.21215","0.00388"
"171.00000","14.25018","0.00351"
"171.45600","14.28815","0.00375"
"171.91200","14.32617","0.00308"
"172.36800","14.36420","0.00265"
"172.82400","14.40216","0.00351"
"173.28000","14.44019","0.00339"
"173.73600","14.47822","0.00369"
"174.19200","14.51624","0.00357"
"174.64800","14.55415","0.00336"
"175.10400","14.59211","0.00347"
"175.56000","14.63020","0.00342"
"176.01600","14.66823","0.00377"
"176.47200","14.70619","0.00339"
"176.92800","14.74422","0.00367"
"177.38400","14.78213","0.00324"
"177.84000","14.82009","0.00377"
"178.29600","14.85812","0.00384"
"178.75200","14.89620","0.00419"
"179.20800","14.93417","0.00314"
"179.66400","14.97220","0.00402"
"180.12000","15.01022","0.00407"
"180.57600","15.04819","0.00366"
"181.03200","15.08615","0.00346"
"181.48800","15.12412","0.00414"
"181.94400","15.16221","0.00371"
"182.40000","15.20017","0.00376"
"182.85600","15.23826","0.00372"
"183.31200","15.27617","0.00348"
"183.76800","15.31407","0.00346"
"184.22400","15.35216","0.00344"
"184.68000","15.39018","0.00376"
"185.13600","15.42821","0.00352"
"185.59200","15.46618","0.00420"
"186.04800","15.50420","0.00444"
"186.50400","15.54211","0.00394"
"186.96000","15.58020","0.00375"
"187.41600","15.61822","0.00382"
"187.87200","15.65619","0.00415"
"188.32800","15.69421","0.00401"
"188.78400","15.73218","0.00380"
"189.24000","15.77015","0.00438"
"189.69600","15.80817","0.00416"
"190.15200","15.84614","0.00432"
"190.60800","15.88416","0.00447"
"191.06400","15.92219","0.00443"
"191.52000","15.96016","0.00454"
"191.97600","15.99824","0.00504"
"192.43200","16.03615","0.00451"
"192.88800","16.07412","0.00399"
"193.34400","16.11214","0.00417"
"193.80000","16.15017","0.00471"
"194.25600","16.18819","0.00392"
"194.71200","16.22622","0.00473"
"195.16800","16.26419","0.00429"
"195.62400","16.30215","0.00419"
"196.08000","16.34012","0.00420"
"196.53600","16.37815","0.00422"
"196.99200","16.41617","0.00424"
"197.44800","16.45420","0.00401"
"197.90400","16.49223","0.00444"
"198.36000","16.53019","0.00511"
"198.81600","16.56810","0.00495"
"199.27200","16.60612","0.00528"
"199.72800","16.64427","0.00447"
"200.18400","16.68218","0.00462"
"200.64000","16.72020","0.00500"
"201.09600","16.75817","0.00491"
"201.55200","16.79613","0.00456"
"202.00800","16.83416","0.00465"
"202.46400","16.87219","0.00515"
"202.92000","16.91021","0.00466"
"203.37600","16.94818","0.00474"
"203.83200","16.98621","0.00502"
"204.28800","17.02417","0.00511"
"204.74400","17.06214","0.00557"
"205.20000","17.10011","0.00486"
"205.65600","17.13819","0.00517"
"206.11200","17.17622","0.00487"
"206.56800","17.21418","0.00543"
"207.02400","17.25215","0.00520"
"207.48000","17.29024","0.00554"
"207.93600","17.32820","0.00532"
"208.39200","17.36617","0.00507"
"208.84800","17.40420","0.00518"
"209.30400","17.44216","0.00538"
"209.76000","17.48019","0.00569"
"210.21600","17.51821","0.00533"
"210.67200","17.55612","0.00543"
"211.12800","17.59421","0.00512"
"211.58400","17.63217","0.00610"
"212.04000","17.67020","0.00561"
"212.49600","17.70823","0.00562"
"212.95200","17.74619","0.00561"
"213.40800","17.78416","0.00586"
"213.86400","17.82212","0.00574"
"214.32000","17.86015","0.00623"
"214.77600","17.89818","0.00598"
"215.23200","17.93620","0.00583"
"215.68800","17.97423","0.00591"
"216.14400","18.01219","0.00618"
"216.60000","18.05010","0.00652"
"217.05600","18.08813","0.00627"
"217.51200","18.12621","0.00645"
"217.96800","18.16418","0.00641"
"218.42400","18.20221","0.00621"
"218.88000","18.24023","0.00642"
"219.33600","18.27814","0.00640"
"219.79200","18.31610","0.00614"
"220.24800","18.35419","0.00502"
"220.70400","18.39222","0.00477"
"221.16000","18.43018","0.00481"
"221.61600","18.46821","0.00536"
"222.07200","18.50618","0.00593"
"222.52800","18.54414","0.00637"
"222.98400","18.58217","0.00537"
"223.44000","18.62020","0.00615"
"223.89600","18.65816","0.00621"
"224.35200","18.69619","0.00573"
"224.80800","18.73421","0.00580"
"225.26400","18.77224","0.00647"
"225.72000","18.81015","0.00598"
"226.17600","18.84817","0.00630"
"226.63200","18.88620","0.00605"
"227.08800","18.92416","0.00650"
"227.54400","18.96219","0.00612"
"228.00000","19.00022","0.00653"
"228.45600","19.03818","0.00663"
"228.91200","19.07615","0.00721"
"229.36800","19.11412","0.00685"
"229.82400","19.15220","0.00686"
"230.28000","19.19023","0.00727"
"230.73600","19.22819","0.00699"
"231.19200","19.26616","0.00705"
"231.64800","19.30413","0.00655"
"232.10400","19.34215","0.00739"
"232.56000","19.38018","0.00736"
"233.01600","19.41821","0.00774"
"233.47200","19.45623","0.00785"
"233.92800","19.49420","0.00813"
"234.38400","19.53216","0.00682"
"234.84000","19.57013","0.00775"
"235.29600","19.60816","0.00817"
"235.75200","19.64624","0.00806"
"236.20800","19.68427","0.00767"
"236.66400","19.72223","0.00786"
"237.12000","19.76020","0.00814"
"237.57600","19.79811","0.00857"
"238.03200","19.83614","0.00872"
"238.48800","19.87422","0.00842"
"238.94400","19.91225","0.00846"
"239.40000","19.95015","0.00869"
"239.85600","19.98818","0.00853"
"240.31200","20.02615","0.00811"
"240.76800","20.06417","0.00841"
"241.22400","20.10214","0.00882"
"241.68000","20.14016","0.00880"
"242.13600","20.17819","0.00932"
"242.59200","20.21622","0.00953"
"243.04800","20.25424","0.00979"
"243.50400","20.29215","0.00904"
"243.96000","20.33018","0.00909"
"244.41600","20.36820","0.00933"
"244.87200","20.40617","0.00944"
"245.32800","20.44419","0.01014"
"245.78400","20.48216","0.00975"
"246.24000","20.52019","0.00990"
"246.69600","20.55815","0.00992"
"247.15200","20.59618","0.01031"
"247.60800","20.63421","0.01006"
"248.06400","20.67217","0.01036"
"248.52000","20.71026","0.01031"
"248.97600","20.74817","0.01071"
"249.43200","20.78613","0.01093"
"249.88800","20.82416","0.01079"
"250.34400","20.86212","0.01118"
"250.80000","20.90015","0.01156"
"251.25600","20.93817","0.01125"
"251.71200","20.97620","0.01115"
"252.16800","21.01417","0.01247"
"252.62400","21.05207","0.01188"
"253.08000","21.09016","0.01187"
"253.53600","21.12825","0.01173"
"253.99200","21.16621","0.01262"
"254.44800","21.20418","0.01264"
"254.90400","21.24220","0.01175"
"255.36000","21.28011","0.01209"
"255.81600","21.31820","0.01213"
"256.27200","21.35622","0.01178"
"256.72800","21.39419","0.01269"
"257.18400","21.43216","0.01236"
"257.64000","21.47018","0.01286"
"258.09600","21.50815","0.01282"
"258.55200","21.54611","0.01348"
"259.00800","21.58414","0.01256"
"259.46400","21.62217","0.01394"
"259.92000","21.66019","0.01374"
"260.37600","21.69816","0.01408"
"260.83200","21.73625","0.01389"
"261.28800","21.77415","0.01377"
"261.74400","21.81212","0.01471"
"262.20000","21.85020","0.01406"
"262.65600","21.88823","0.01450"
"263.11200","21.92620","0.01406"
"263.56800","21.96422","0.01250"
"264.02400","22.00219","0.01251"
"264.48000","22.04016","0.01334"
"264.93600","22.07818","0.01328"
"265.39200","22.11615","0.01351"
"265.84800","22.15417","0.01459"
"266.30400","22.19220","0.01445"
"266.76000","22.23022","0.01525"
"267.21600","22.26819","0.01583"
"267.67200","22.30616","0.01532"
"268.12800","22.34413","0.01583"
"268.58400","22.38221","0.01585"
"269.04000","22.42018","0.01618"
"269.49600","22.45820","0.01645"
"269.95200","22.49617","0.01682"
"270.40800","22.53414","0.01699"
"270.86400","22.57216","0.01719"
"271.32000","22.61019","0.01713"
"271.77600","22.64822","0.01731"
"272.23200","22.68624","0.01753"
"272.68800","22.72421","0.01742"
"273.14400","22.76211","0.01842"
"273.60000","22.80014","0.01839"
"274.05600","22.83817","0.01910"
"274.51200","22.87619","0.01827"
"274.96800","22.91416","0.01698"
"275.42400","22.95224","0.01752"
"275.88000","22.99015","0.01812"
"276.33600","23.02812","0.01829"
"276.79200","23.06620","0.01882"
"277.24800","23.10417","0.01874"
"277.70400","23.14226","0.01916"
"278.16000","23.18016","0.02011"
"278.61600","23.21819","0.02054"
"279.07200","23.25616","0.02060"
"279.52800","23.29412","0.02035"
"279.98400","23.33215","0.02041"
"280.44000","23.37017","0.02149"
"280.89600","23.40820","0.02198"
"281.35200","23.44617","0.02204"
"281.80800","23.48419","0.02252"
"282.26400","23.52216","0.02298"
"282.72000","23.56012","0.02337"
"283.17600","23.59821","0.02385"
"283.63200","23.63618","0.02485"
"284.08800","23.67420","0.02506"
"284.54400","23.71223","0.02537"
"285.00000","23.75014","0.02531"
"285.45600","23.78816","0.02650"
"285.91200","23.82613","0.02686"
"286.36800","23.86415","0.02750"
"286.82400","23.90218","0.02787"
"287.28000","23.94020","0.02880"
"287.73600","23.97817","0.02707"
"288.19200","24.01614","0.02682"
"288.64800","24.05411","0.02814"
"289.10400","24.09213","0.02783"
"289.56000","24.13022","0.02889"
"290.01600","24.16825","0.02791"
"290.47200","24.20621","0.02812"
"290.92800","24.24418","0.02776"
"291.38400","24.28209","0.02910"
"291.84000","24.32017","0.02903"
"292.29600","24.35819","0.02930"
"292.75200","24.39622","0.02984"
"293.20800","24.43419","0.03046"
"293.66400","24.47216","0.03010"
"294.12000","24.51018","0.02971"
"294.57600","24.54809","0.02620"
"295.03200","24.58617","0.02624"
"295.48800","24.62420","0.02768"
"295.94400","24.66217","0.02724"
"296.40000","24.70019","0.02832"
"296.85600","24.73822","0.02953"
"297.31200","24.77618","0.02980"
"297.76800","24.81409","0.02984"
"298.22400","24.85218","0.03073"
"298.68000","24.89026","0.03139"
"299.13600","24.92817","0.03191"
"299.59200","24.96620","0.03212"
"300.04800","25.00416","0.03265"
"300.50400","25.04213","0.03096"
"300.96000","25.08015","0.03061"
"301.41600","25.11818","0.03102"
"301.87200","25.15615","0.03176"
"302.32800","25.19417","0.03233"
"302.78400","25.23220","0.03290"
"303.24000","25.27011","0.03266"
"303.69600","25.30813","0.02896"
"304.15200","25.34616","0.02838"
"304.60800","25.38424","0.02896"
"305.06400","25.42221","0.03008"
"305.52000","25.46024","0.03019"
"305.97600","25.49814","0.03013"
"306.43200","25.53611","0.03089"
"306.88800","25.57414","0.03185"
"307.34400","25.61222","0.03280"
"307.80000","25.65019","0.03300"
"308.25600","25.68821","0.03278"
"308.71200","25.72618","0.03357"
"309.16800","25.76415","0.03412"
"309.62400","25.80217","0.03455"
"310.08000","25.84020","0.03487"
"310.53600","25.87817","0.03563"
"310.99200","25.91619","0.03629"
"311.44800","25.95422","0.03661"
"311.90400","25.99219","0.03693"
"312.36000","26.03015","0.03737"
"312.81600","26.06817","0.03810"
"313.27200","26.10620","0.03438"
"313.72800","26.14423","0.03468"
"314.18400","26.18220","0.03661"
"314.64000","26.22016","0.03712"
"315.09600","26.25819","0.03718"
"315.55200","26.29615","0.03830"
"316.00800","26.33418","0.03810"
"316.46400","26.37221","0.03891"
"316.92000","26.41017","0.03989"
"317.37600","26.44820","0.04073"
"317.83200","26.48616","0.04047"
"318.28800","26.52413","0.04081"
"318.74400","26.56216","0.04211"
"319.20000","26.60018","0.04238"
"319.65600","26.63821","0.04278"
"320.11200","26.67624","0.04307"
"320.56800","26.71426","0.04299"
"321.02400","26.75217","0.04368"
"321.48000","26.79014","0.03593"
"321.93600","26.82816","0.02995"
"322.39200","26.86619","0.03082"
"322.84800","26.90421","0.02863"
"323.30400","26.94218","0.02839"
"323.76000","26.98021","0.02461"
"324.21600","27.01811","0.02576"
"324.67200","27.05614","0.02381"
"325.12800","27.09417","0.02502"
"325.58400","27.13219","0.02684"
"326.04000","27.17022","0.02669"
"326.49600","27.20818","0.02586"
"326.95200","27.24615","0.02743"
"327.40800","27.28418","0.02778"
"327.86400","27.32214","0.02350"
"328.32000","27.36023","0.02264"
"328.77600","27.39820","0.02273"
"329.23200","27.43622","0.02290"
"329.68800","27.47419","0.02255"
"330.14400","27.51210","0.02322"
"330.60000","27.55018","0.02347"
"331.05600","27.58821","0.02333"
"331.51200","27.62617","0.02380"
"331.96800","27.66420","0.02342"
"332.42400","27.70216","0.02465"
"332.88000","27.74019","0.02502"
"333.33600","27.77822","0.02513"
"333.79200","27.81618","0.02612"
"334.24800","27.85421","0.02723"
"334.70400","27.89218","0.02727"
"335.16000","27.93020","0.02870"
"335.61600","27.96817","0.02849"
"336.07200","28.00614","0.02957"
"336.52800","28.04416","0.03007"
"336.98400","28.08213","0.03107"
"337.44000","28.12015","0.03090"
"337.89600","28.15818","0.01927"
"338.35200","28.19621","0.01123"
"338.80800","28.23417","0.00815"
"339.26400","28.27208","0.00885"
"339.72000","28.31017","0.00679"
"340.17600","28.34819","0.00732"
"340.63200","28.38622","0.00892"
"341.08800","28.42424","0.00767"
"341.54400","28.46215","0.00745"
"342.00000","28.50018","0.00879"
"342.45600","28.53814","0.00804"
"342.91200","28.57617","0.00917"
"343.36800","28.61419","0.00858"
"343.82400","28.65222","0.00985"
"344.28000","28.69019","0.00911"
"344.73600","28.72815","0.00979"
"345.19200","28.76606","0.00943"
"345.64800","28.80415","0.00999"
"346.10400","28.84223","0.00999"
"346.56000","28.88020","0.00968"
"347.01600","28.91816","0.01048"
"347.47200","28.95619","0.01078"
"347.92800","28.99416","0.01122"
"348.38400","29.03218","0.01035"
"348.84000","29.07021","0.01111"
"349.29600","29.10818","0.01097"
"349.75200","29.14620","0.01168"
"350.20800","29.18417","0.01161"
"350.66400","29.22214","0.01148"
"351.12000","29.26016","0.01160"
"351.57600","29.29813","0.01164"
"352.03200","29.33615","0.01214"
"352.48800","29.37418","0.01216"
"352.94400","29.41221","0.01263"
"353.40000","29.45023","0.01240"
"353.85600","29.48814","0.01386"
"354.31200","29.52617","0.01342"
"354.76800","29.56413","0.01375"
"355.22400","29.60222","0.01360"
"355.68000","29.64018","0.01441"
"356.13600","29.67821","0.01427"
"356.59200","29.71623","0.01452"
"357.04800","29.75414","0.01354"
"357.50400","29.79217","0.01308"
"357.96000","29.83013","0.01371"
"358.41600","29.86822","0.01338"
"358.87200","29.90619","0.01436"
"359.32800","29.94422","0.01374"
"359.78400","29.98218","0.01395"
"360.24000","30.02009","0.01486"
"360.69600","30.05817","0.01519"
"361.15200","30.09620","0.01520"
"361.60800","30.13423","0.01554"
"362.06400","30.17225","0.01529"
"362.52000","30.21016","0.01622"
"362.97600","30.24818","0.01595"
"363.43200","30.28609","0.01594"
"363.88800","30.32424","0.01587"
"364.34400","30.36220","0.01553"
"364.80000","30.40017","0.01634"
"365.25600","30.43819","0.01632"
"365.71200","30.47616","0.01625"
"366.16800","30.51419","0.01643"
"366.62400","30.55215","0.01741"
"367.08000","30.59024","0.01643"
"367.53600","30.62820","0.01655"
"367.99200","30.66617","0.01675"
"368.44800","30.70420","0.01650"
"368.90400","30.74216","0.01689"
"369.36000","30.78019","0.01739"
"369.81600","30.81816","0.01738"
"370.27200","30.85618","0.01711"
"370.72800","30.89421","0.01831"
"371.18400","30.93217","0.01759"
"371.64000","30.97020","0.01729"
"372.09600","31.00817","0.01790"
"372.55200","31.04619","0.01816"
"373.00800","31.08410","0.01832"
"373.46400","31.12218","0.01883"
"373.92000","31.16027","0.01911"
"374.37600","31.19824","0.01860"
"374.83200","31.23615","0.01888"
"375.28800","31.27411","0.01868"
"375.74400","31.31220","0.01889"
"376.20000","31.35022","0.01951"
"376.65600","31.38825","0.01925"
"377.11200","31.42621","0.01977"
"377.56800","31.46418","0.01996"
"378.02400","31.50209","0.01999"
"378.48000","31.54017","0.02079"
"378.93600","31.57820","0.02116"
"379.39200","31.61617","0.02139"
"379.84800","31.65419","0.02126"
"380.30400","31.69222","0.02189"
"380.76000","31.73013","0.02164"
"381.21600","31.76815","0.02192"
"381.67200","31.80618","0.02278"
"382.12800","31.84420","0.02254"
"382.58400","31.88217","0.02392"
"383.04000","31.92019","0.02333"
"383.49600","31.95816","0.02349"
"383.95200","31.99613","0.02358"
"384.40800","32.03416","0.02453"
"384.86400","32.07224","0.02436"
"385.32000","32.11021","0.02474"
"385.77600","32.14812","0.02525"
"386.23200","32.18620","0.02560"
"386.68800","32.22417","0.02595"
"387.14400","32.26213","0.02644"
"387.60000","32.30016","0.02649"
"388.05600","32.33818","0.02583"
"388.51200","32.37615","0.02667"
"388.96800","32.41418","0.02712"
"389.42400","32.45220","0.02801"
"389.88000","32.49017","0.02857"
"390.33600","32.52814","0.02866"
"390.79200","32.56616","0.02954"
"391.24800","32.60425","0.02934"
"391.70400","32.64222","0.02939"
"392.16000","32.68024","0.02924"
"392.61600","32.71821","0.02964"
"393.07200","32.75611","0.02932"
"393.52800","32.79414","0.03054"
"393.98400","32.83216","0.03047"
"394.44000","32.87019","0.03153"
"394.89600","32.90822","0.03143"
"395.35200","32.94619","0.03056"
"395.80800","32.98415","0.02978"
"396.26400","33.02217","0.03000"
"396.72000","33.06015","0.02857"
"397.17600","33.09823","0.02813"
"397.63200","33.13626","0.02838"
"398.08800","33.17422","0.02806"
"398.54400","33.21213","0.02843"
"399.00000","33.25009","0.02886"
"399.45600","33.28812","0.02853"
"399.91200","33.32627","0.02898"
"400.36800","33.36423","0.02947"
"400.82400","33.40220","0.02917"
"401.28000","33.44017","0.03002"
"401.73600","33.47813","0.02977"
"402.19200","33.51616","0.02991"
"402.64800","33.55418","0.03055"
"403.10400","33.59221","0.03113"
"403.56000","33.63024","0.03063"
"404.01600","33.66820","0.03076"
"404.47200","33.70617","0.02933"
"404.92800","33.74420","0.02920"
"405.38400","33.78216","0.02988"
"405.84000","33.82013","0.03014"
"406.29600","33.85822","0.03079"
"406.75200","33.89618","0.02910"
"407.20800","33.93420","0.02969"
"407.66400","33.97218","0.02956"
"408.12000","34.01014","0.02944"
"408.57600","34.04816","0.02941"
"409.03200","34.08613","0.02993"
"409.48800","34.12416","0.03032"
"409.94400","34.16225","0.02998"
"410.40000","34.20015","0.03046"
"410.85600","34.23818","0.03117"
"411.31200","34.27614","0.03163"
"411.76800","34.31417","0.03162"
"412.22400","34.35220","0.03110"
"412.68000","34.39022","0.03157"
"413.13600","34.42819","0.03185"
"413.59200","34.46616","0.03237"
"414.04800","34.50412","0.03286"
"414.50400","34.54215","0.03321"
"414.96000","34.58023","0.03403"
"415.41600","34.61826","0.03357"
"415.87200","34.65623","0.03430"
"416.32800","34.69419","0.03474"
"416.78400","34.73210","0.03466"
"417.24000","34.77012","0.03502"
"417.69600","34.80821","0.03535"
"418.15200","34.84623","0.03593"
"418.60800","34.88420","0.03597"
"419.06400","34.92217","0.03686"
"419.52000","34.96014","0.03740"
"419.97600","34.99810","0.03770"
"420.43200","35.03619","0.03777"
"420.88800","35.07428","0.03860"
"421.34400","35.11218","0.03789"
"421.80000","35.15021","0.03879"
"422.25600","35.18817","0.03962"
"422.71200","35.22620","0.04005"
"423.16800","35.26416","0.04003"
"423.62400","35.30219","0.04078"
"424.08000","35.34022","0.04109"
"424.53600","35.37812","0.04190"
"424.99200","35.41621","0.04223"
"425.44800","35.45424","0.04251"
"425.90400","35.49208","0.04264"
"426.36000","35.53017","0.04275"
"426.81600","35.56814","0.04325"
"427.27200","35.60622","0.04410"
"427.72800","35.64419","0.04331"
"428.18400","35.68221","0.04360"
"428.64000","35.72018","0.04385"
"429.09600","35.75814","0.04395"
"429.55200","35.79617","0.04393"
"430.00800","35.83420","0.04449"
"430.46400","35.87222","0.04476"
"430.92000","35.91025","0.04443"
"431.37600","35.94822","0.04451"
"431.83200","35.98618","0.04484"
"432.28800","36.02409","0.04509"
"432.74400","36.06218","0.04501"
"433.20000","36.10020","0.04515"
"433.65600","36.13823","0.04468"
"434.11200","36.17625","0.04522"
"434.56800","36.21410","0.04515"
"435.02400","36.25212","0.04590"
"435.48000","36.29015","0.04601"
"435.93600","36.32824","0.04661"
"436.39200","36.36621","0.04660"
"436.84800","36.40417","0.04726"
"437.30400","36.44214","0.04756"
"437.76000","36.48011","0.04762"
"438.21600","36.51819","0.04779"
"438.67200","36.55622","0.04807"
"439.12800","36.59418","0.04859"
"439.58400","36.63221","0.04915"
"440.04000","36.67017","0.04945"
"440.49600","36.70820","0.04963"
"440.95200","36.74611","0.05012"
"441.40800","36.78419","0.05009"
"441.86400","36.82222","0.05092"
"442.32000","36.86019","0.05120"
"442.77600","36.89822","0.05127"
"443.23200","36.93618","0.05149"
"443.68800","36.97421","0.05135"
"444.14400","37.01217","0.05097"
"444.60000","37.05020","0.04944"
"445.05600","37.08816","0.04758"
"445.51200","37.12619","0.04690"
"445.96800","37.16422","0.04703"
"446.42400","37.20218","0.04727"
"446.88000","37.24015","0.04726"
"447.33600","37.27818","0.04737"
"447.79200","37.31620","0.04705"
"448.24800","37.35417","0.04777"
"448.70400","37.39225","0.04818"
"449.16000","37.43016","0.04854"
"449.61600","37.46819","0.04897"
"450.07200","37.50609","0.04935"
"450.52800","37.54418","0.05006"
"450.98400","37.58221","0.05059"
"451.44000","37.62023","0.05082"
"451.89600","37.65826","0.05116"
"452.35200","37.69622","0.05162"
"452.80800","37.73407","0.05251"
"453.26400","37.77216","0.05209"
"453.72000","37.81025","0.05268"
"454.17600","37.84827","0.05349"
"454.63200","37.88618","0.05411"
"455.08800","37.92420","0.05447"
"455.54400","37.96211","0.05506"
"456.00000","38.00014","0.05397"
"456.45600","38.03822","0.05356"
"456.91200","38.07619","0.04918"
"457.36800","38.11415","0.04825"
"457.82400","38.15218","0.04737"
"458.28000","38.19014","0.04764"
"458.73600","38.22817","0.04761"
"459.19200","38.26620","0.04748"
"459.64800","38.30423","0.04774"
"460.10400","38.34225","0.04767"
"460.56000","38.38016","0.04784"
"461.01600","38.41819","0.04807"
"461.47200","38.45621","0.04831"
"461.92800","38.49412","0.04847"
"462.38400","38.53214","0.04876"
"462.84000","38.57017","0.04910"
"463.29600","38.60819","0.04945"
"463.75200","38.64622","0.04984"
"464.20800","38.68419","0.05001"
"464.66400","38.72215","0.05068"
"465.12000","38.76018","0.05092"
"465.57600","38.79815","0.05199"
"466.03200","38.83617","0.05179"
"466.48800","38.87420","0.05201"
"466.94400","38.91222","0.05256"
"467.40000","38.95019","0.05205"
"467.85600","38.98810","0.05272"
"468.31200","39.02612","0.05271"
"468.76800","39.06421","0.05236"
"469.22400","39.10223","0.05278"
"469.68000","39.14026","0.05247"
"470.13600","39.17817","0.05201"
"470.59200","39.21613","0.05207"
"471.04800","39.25416","0.05222"
"471.50400","39.29219","0.05189"
"471.96000","39.33022","0.05247"
"472.41600","39.36824","0.05282"
"472.87200","39.40620","0.05315"
"473.32800","39.44411","0.05329"
"473.78400","39.48214","0.05346"
"474.24000","39.52016","0.05337"
"474.69600","39.55819","0.05394"
"475.15200","39.59621","0.05402"
"475.60800","39.63418","0.05384"
"476.06400","39.67221","0.05441"
"476.52000","39.71011","0.05393"
"476.97600","39.74814","0.05489"
"477.43200","39.78617","0.05529"
"477.88800","39.82420","0.05516"
"478.34400","39.86216","0.05588"
"478.80000","39.90019","0.05586"
"479.25600","39.93815","0.05578"
"479.71200","39.97618","0.05362"
"480.16800","40.01420","0.05348"
"480.62400","40.05223","0.05327"
"481.08000","40.09020","0.05329"
"481.53600","40.12822","0.05352"
"481.99200","40.16625","0.05354"
"482.44800","40.20415","0.05347"
"482.90400","40.24218","0.05328"
"483.36000","40.28009","0.05326"
"483.81600","40.31818","0.05335"
"484.27200","40.35620","0.05314"
"484.72800","40.39423","0.05190"
"485.18400","40.43219","0.05236"
"485.64000","40.47010","0.05256"
"486.09600","40.50812","0.05278"
"486.55200","40.54615","0.05274"
"487.00800","40.58424","0.05266"
"487.46400","40.62226","0.05354"
"487.92000","40.66023","0.05364"
"488.37600","40.69820","0.05419"
"488.83200","40.73616","0.05441"
"489.28800","40.77419","0.05497"
"489.74400","40.81222","0.05537"
"490.20000","40.85018","0.05569"
"490.65600","40.88821","0.05629"
"491.11200","40.92611","0.05676"
"491.56800","40.96414","0.05703"
"492.02400","41.00217","0.05737"
"492.48000","41.04019","0.05792"
"492.93600","41.07822","0.05821"
"493.39200","41.11618","0.05886"
"493.84800","41.15421","0.05933"
"494.30400","41.19218","0.05995"
"494.76000","41.23014","0.06078"
"495.21600","41.26823","0.06074"
"495.67200","41.30620","0.06129"
"496.12800","41.34423","0.06165"
"496.58400","41.38219","0.06187"
"497.04000","41.42022","0.06232"
"497.49600","41.45818","0.06248"
"497.95200","41.49615","0.06338"
"498.40800","41.53418","0.06349"
"498.86400","41.57214","0.06396"
"499.32000","41.61016","0.06471"
"499.77600","41.64819","0.06514"
"500.23200","41.68615","0.06599"
"500.68800","41.72412","0.06624"
"501.14400","41.76215","0.06653"
"501.60000","41.80018","0.06770"
"502.05600","41.83821","0.06809"
"502.51200","41.87623","0.06854"
"502.96800","41.91420","0.06904"
"503.42400","41.95210","0.06988"
"503.88000","41.99013","0.07098"
"504.33600","42.02815","0.07165"
"504.79200","42.06624","0.07293"
"505.24800","42.10420","0.07272"
"505.70400","42.14217","0.06914"
"506.16000","42.18014","0.06740"
"506.61600","42.21811","0.06832"
"507.07200","42.25620","0.06876"
"507.52800","42.29422","0.06881"
"507.98400","42.33225","0.06990"
"508.44000","42.37021","0.07018"
"508.89600","42.40824","0.07142"
"509.35200","42.44614","0.07225"
"509.80800","42.48411","0.07069"
"510.26400","42.52219","0.06879"
"510.72000","42.56022","0.06907"
"511.17600","42.59819","0.06787"
"511.63200","42.63621","0.06662"
"512.08800","42.67418","0.06660"
"512.54400","42.71215","0.06663"
"513.00000","42.75011","0.06509"
"513.45600","42.78820","0.06304"
"513.91200","42.82623","0.06128"
"514.36800","42.86419","0.05838"
"514.82400","42.90222","0.05798"
"515.28000","42.94019","0.05814"
"515.73600","42.97815","0.05756"
"516.19200","43.01617","0.05729"
"516.64800","43.05420","0.05637"
"517.10400","43.09217","0.05683"
"517.56000","43.13026","0.05694"
"518.01600","43.16822","0.05828"
"518.47200","43.20613","0.05880"
"518.92800","43.24410","0.05982"
"519.38400","43.28212","0.06079"
"519.84000","43.32021","0.06133"
"520.29600","43.35823","0.06179"
"520.75200","43.39620","0.06306"
"521.20800","43.43410","0.06367"
"521.66400","43.47213","0.06351"
"522.12000","43.51009","0.06371"
"522.57600","43.54824","0.06443"
"523.03200","43.58627","0.06452"
"523.48800","43.62423","0.06498"
"523.94400","43.66220","0.06630"
"524.40000","43.70017","0.06632"
"524.85600","43.73819","0.06694"
"525.31200","43.77622","0.06815"
"525.76800","43.81425","0.06955"
"526.22400","43.85221","0.06988"
"526.68000","43.89018","0.07094"
"527.13600","43.92815","0.07215"
"527.59200","43.96611","0.07255"
"528.04800","44.00414","0.07270"
"528.50400","44.04217","0.07321"
"528.96000","44.08019","0.07372"
"529.41600","44.11816","0.07472"
"529.87200","44.15619","0.07460"
"530.32800","44.19415","0.07591"
"530.78400","44.23218","0.07697"
"531.24000","44.27020","0.07754"
"531.69600","44.30823","0.07850"
"532.15200","44.34620","0.07914"
"532.60800","44.38422","0.07959"
"533.06400","44.42219","0.08104"
"533.52000","44.46015","0.08083"
"533.97600","44.49812","0.08194"
"534.43200","44.53609","0.08223"
"534.88800","44.57418","0.08334"
"535.34400","44.61220","0.08339"
"535.80000","44.65023","0.08348"
"536.25600","44.68819","0.08422"
"536.71200","44.72610","0.08460"
"537.16800","44.76419","0.08527"
"537.62400","44.80221","0.08570"
"538.08000","44.84024","0.08626"
"538.53600","44.87820","0.08681"
"538.99200","44.91617","0.08745"
"539.44800","44.95414","0.08781"
"539.90400","44.99216","0.08804"
"540.36000","45.03019","0.08715"
"540.81600","45.06827","0.08708"
"541.27200","45.10618","0.08723"
"541.72800","45.14421","0.08790"
"542.18400","45.18211","0.08830"
"542.64000","45.22014","0.08862"
"543.09600","45.25816","0.08875"
"543.55200","45.29619","0.08856"
"544.00800","45.33416","0.08846"
"544.46400","45.37218","0.08915"
"544.92000","45.41021","0.08652"
"545.37600","45.44812","0.08488"
"545.83200","45.48621","0.08516"
"546.28800","45.52422","0.08485"
"546.74400","45.56219","0.08526"
"547.20000","45.60017","0.08540"
"547.65600","45.63813","0.08517"
"548.11200","45.67616","0.08533"
"548.56800","45.71412","0.08600"
"549.02400","45.75215","0.08628"
"549.48000","45.79023","0.08673"
"549.93600","45.82814","0.08707"
"550.39200","45.86623","0.08824"
"550.84800","45.90419","0.08856"
"551.30400","45.94216","0.08947"
"551.76000","45.98013","0.08966"
"552.21600","46.01815","0.09007"
"552.67200","46.05623","0.09080"
"553.12800","46.09420","0.09130"
"553.58400","46.13223","0.09141"
"554.04000","46.17020","0.09176"
"554.49600","46.20810","0.09185"
"554.95200","46.24613","0.09175"
"555.40800","46.28415","0.09184"
"555.86400","46.32224","0.09155"
"556.32000","46.36020","0.09233"
"556.77600","46.39817","0.09242"
"557.23200","46.43614","0.09257"
"557.68800","46.47411","0.09342"
"558.14400","46.51213","0.09318"
"558.60000","46.55022","0.09346"
"559.05600","46.58824","0.09335"
"559.51200","46.62621","0.09372"
"559.96800","46.66418","0.09434"
"560.42400","46.70208","0.09499"
"560.88000","46.74017","0.09533"
"561.33600","46.77819","0.09564"
"561.79200","46.81622","0.09488"
"562.24800","46.85419","0.09442"
"562.70400","46.89215","0.09410"
"563.16000","46.93012","0.09414"
"563.61600","46.96814","0.09402"
"564.07200","47.00618","0.09408"
"564.52800","47.04420","0.09357"
"564.98400","47.08216","0.09438"
"565.44000","47.12019","0.09460"
"565.89600","47.15816","0.09420"
"566.35200","47.19612","0.09486"
"566.80800","47.23415","0.09445"
"567.26400","47.27218","0.09393"
"567.72000","47.31020","0.09337"
"568.17600","47.34823","0.09382"
"568.63200","47.38620","0.09428"
"569.08800","47.42422","0.09503"
"569.54400","47.46213","0.09535"
"570.00000","47.50015","0.09538"
"570.45600","47.53818","0.09606"
"570.91200","47.57615","0.09670"
"571.36800","47.61423","0.09761"
"571.82400","47.65220","0.09736"
"572.28000","47.69011","0.09823"
"572.73600","47.72813","0.09890"
"573.19200","47.76616","0.09932"
"573.64800","47.80418","0.09963"
"574.10400","47.84221","0.10025"
"574.56000","47.88023","0.10101"
"575.01600","47.91814","0.10048"
"575.47200","47.95611","0.10030"
"575.92800","47.99420","0.10054"
"576.38400","48.03216","0.10075"
"576.84000","48.07025","0.10087"
"577.29600","48.10821","0.10204"
"577.75200","48.14618","0.10259"
"578.20800","48.18415","0.10365"
"578.66400","48.22211","0.10298"
"579.12000","48.26020","0.10403"
"579.57600","48.29822","0.10498"
"580.03200","48.33619","0.10530"
"580.48800","48.37422","0.10567"
"580.94400","48.41212","0.10671"
"581.40000","48.45015","0.10748"
"581.85600","48.48817","0.10824"
"582.31200","48.52621","0.10960"
"582.76800","48.56422","0.11027"
"583.22400","48.60219","0.11107"
"583.68000","48.64022","0.11105"
"584.13600","48.67813","0.11201"
"584.59200","48.71621","0.11210"
"585.04800","48.75418","0.11274"
"585.50400","48.79221","0.11361"
"585.96000","48.83011","0.11509"
"586.41600","48.86819","0.11542"
"586.87200","48.90623","0.11618"
"587.32800","48.94419","0.11678"
"587.78400","48.98216","0.11701"
"588.24000","49.02013","0.11672"
"588.69600","49.05820","0.11678"
"589.15200","49.09623","0.11748"
"589.60800","49.13420","0.11737"
"590.06400","49.17217","0.11800"
"590.52000","49.21014","0.11828"
"590.97600","49.24816","0.11916"
"591.43200","49.28619","0.11975"
"591.88800","49.32421","0.12001"
"592.34400","49.36224","0.12074"
"592.80000","49.40014","0.12113"
"593.25600","49.43811","0.12116"
"593.71200","49.47614","0.12165"
"594.16800","49.51417","0.12289"
"594.62400","49.55219","0.12314"
"595.08000","49.59021","0.12421"
"595.53600","49.62818","0.12368"
"595.99200","49.66615","0.12362"
"596.44800","49.70411","0.12465"
"596.90400","49.74214","0.12566"
"597.36000","49.78023","0.12594"
"597.81600","49.81820","0.12673"
"598.27200","49.85622","0.12695"
"598.72800","49.89412","0.12799"
"599.18400","49.93209","0.12842"
"599.64000","49.97018","0.12874"
"600.09600","50.00821","0.12919"
"600.55200","50.04623","0.12955"
"601.00800","50.08414","0.13002"
"601.46400","50.12216","0.13036"
"601.92000","50.16019","0.13013"
"602.37600","50.19816","0.13041"
"602.83200","50.23618","0.12975"
"603.28800","50.27415","0.12953"
"603.74400","50.31217","0.13039"
"604.20000","50.35014","0.13051"
"604.65600","50.38816","0.12982"
"605.11200","50.42620","0.12933"
"605.56800","50.46410","0.12978"
"606.02400","50.50219","0.12998"
"606.48000","50.54021","0.13042"
"606.93600","50.57818","0.13067"
"607.39200","50.61620","0.13075"
"607.84800","50.65417","0.13066"
"608.30400","50.69214","0.13114"
"608.76000","50.73016","0.13180"
"609.21600","50.76819","0.13201"
"609.67200","50.80622","0.13229"
"610.12800","50.84425","0.13276"
"610.58400","50.88221","0.13324"
"611.04000","50.92012","0.13345"
"611.49600","50.95814","0.13326"
"611.95200","50.99611","0.13342"
"612.40800","51.03419","0.13360"
"612.86400","51.07228","0.13386"
"613.32000","51.11024","0.13402"
"613.77600","51.14816","0.13348"
"614.23200","51.18612","0.13387"
"614.68800","51.22414","0.13432"
"615.14400","51.26223","0.13452"
"615.60000","51.30026","0.13445"
"616.05600","51.33817","0.13479"
"616.51200","51.37619","0.13477"
"616.96800","51.41409","0.13514"
"617.42400","51.45218","0.13552"
"617.88000","51.49021","0.13551"
"618.33600","51.52823","0.13557"
"618.79200","51.56620","0.13577"
"619.24800","51.60417","0.13573"
"619.70400","51.64214","0.13559"
"620.16000","51.68016","0.13624"
"620.61600","51.71819","0.13536"
"621.07200","51.75615","0.13520"
"621.52800","51.79418","0.13499"
"621.98400","51.83214","0.13397"
"622.44000","51.87023","0.12986"
"622.89600","51.90820","0.12802"
"623.35200","51.94616","0.12798"
"623.80800","51.98413","0.12809"
"624.26400","52.02216","0.12898"
"624.72000","52.06018","0.12980"
"625.17600","52.09821","0.13095"
"625.63200","52.13618","0.13192"
"626.08800","52.17414","0.13263"
"626.54400","52.21216","0.13324"
"627.00000","52.25019","0.13356"
"627.45600","52.28815","0.13414"
"627.91200","52.32625","0.13464"
"628.36800","52.36421","0.13482"
"628.82400","52.40218","0.13498"
"629.28000","52.44015","0.13568"
"629.73600","52.47811","0.13611"
"630.19200","52.51620","0.13642"
"630.64800","52.55422","0.13686"
"631.10400","52.59225","0.13692"
"631.56000","52.63016","0.13705"
"632.01600","52.66812","0.13733"
"632.47200","52.70615","0.13793"
"632.92800","52.74417","0.13821"
"633.38400","52.78220","0.13837"
"633.84000","52.82016","0.13874"
"634.29600","52.85820","0.13927"
"634.75200","52.89616","0.13934"
"635.20800","52.93412","0.13932"
"635.66400","52.97221","0.13975"
"636.12000","53.01024","0.13939"
"636.57600","53.04814","0.13973"
"637.03200","53.08617","0.14001"
"637.48800","53.12413","0.14013"
"637.94400","53.16217","0.14025"
"638.40000","53.20019","0.14038"
"638.85600","53.23822","0.13982"
"639.31200","53.27618","0.13973"
"639.76800","53.31415","0.13964"
"640.22400","53.35223","0.13995"
"640.68000","53.39020","0.13982"
"641.13600","53.42811","0.14022"
"641.59200","53.46619","0.14069"
"642.04800","53.50416","0.14065"
"642.50400","53.54218","0.14162"
"642.96000","53.58021","0.14148"
"643.41600","53.61818","0.14235"
"643.87200","53.65614","0.14217"
"644.32800","53.69411","0.14268"
"644.78400","53.73219","0.14271"
"645.24000","53.77016","0.14297"
"645.69600","53.80819","0.14296"
"646.15200","53.84622","0.14345"
"646.60800","53.88418","0.14286"
"647.06400","53.92215","0.14310"
"647.52000","53.96011","0.14282"
"647.97600","53.99820","0.14198"
"648.43200","54.03616","0.14193"
"648.88800","54.07425","0.14205"
"649.34400","54.11222","0.14193"
"649.80000","54.15018","0.14193"
"650.25600","54.18815","0.14259"
"650.71200","54.22612","0.14648"
"651.16800","54.26426","0.14245"
"651.62400","54.30217","0.14330"
"652.08000","54.34019","0.14370"
"652.53600","54.37816","0.14402"
"652.99200","54.41613","0.14411"
"653.44800","54.45415","0.14449"
"653.90400","54.49218","0.14459"
"654.36000","54.53021","0.14523"
"654.81600","54.56817","0.14584"
"655.27200","54.60614","0.14578"
"655.72800","54.64417","0.14698"
"656.18400","54.68214","0.14784"
"656.64000","54.72021","0.14847"
"657.09600","54.75819","0.14978"
"657.55200","54.79621","0.15032"
"658.00800","54.83424","0.15114"
"658.46400","54.87214","0.15139"
"658.92000","54.91017","0.15278"
"659.37600","54.94814","0.15381"
"659.83200","54.98616","0.15299"
"660.28800","55.02419","0.15503"
"660.74400","55.06216","0.15599"
"661.20000","55.10018","0.15677"
"661.65600","55.13821","0.15742"
"662.11200","55.17611","0.15809"
"662.56800","55.21420","0.15850"
"663.02400","55.25216","0.15957"
"663.48000","55.29019","0.16064"
"663.93600","55.32822","0.16110"
"664.39200","55.36619","0.16223"
"664.84800","55.40415","0.16318"
"665.30400","55.44218","0.16387"
"665.76000","55.48014","0.16453"
"666.21600","55.51823","0.16551"
"666.67200","55.55626","0.16613"
"667.12800","55.59422","0.16627"
"667.58400","55.63219","0.16642"
"668.04000","55.67010","0.16833"
"668.49600","55.70818","0.09690"
"668.95200","55.74621","0.08769"
"669.40800","55.78423","0.08632"
"669.86400","55.82214","0.09806"
"670.32000","55.86023","0.09078"
"670.77600","55.89813","0.09003"
"671.23200","55.93616","0.09459"
"671.68800","55.97418","0.09624"
"672.14400","56.01221","0.09228"
"672.60000","56.05018","0.09209"
"673.05600","56.08820","0.10616"
"673.51200","56.12617","0.09321"
"673.96800","56.16413","0.09733"
"674.42400","56.20217","0.11354"
"674.88000","56.24018","0.09727"
"675.33600","56.27822","0.09824"
"675.79200","56.31618","0.00670"
"676.24800","56.35421","0.00355"
"676.70400","56.39217","0.00196"
"677.16000","56.43014","0.00140"
"677.61600","56.46817","0.00035"
"678.07200","56.50619","0.00013"
"678.51800","56.54332","0.00091"