File: Force_trajectories/170226_2/Specimen_RawData_8.csv
End date,"2/26/2017"
Specimen label,"8AG_68"
Maximum Load,"0.28868",N

Time,Extension,Load
(s),(mm),(N)
"0.00000","0.00000","0.00037"
"0.43800","0.03683","0.00057"
"0.87600","0.07324","0.00047"
"1.31400","0.10971","0.00132"
"1.75200","0.14619","0.00157"
"2.19000","0.18278","0.00221"
"2.62800","0.21925","0.00233"
"3.06600","0.25578","0.00225"
"3.50400","0.29213","0.00248"
"3.94200","0.32866","0.00239"
"4.38000","0.36519","0.00304"
"4.81800","0.40173","0.00251"
"5.25600","0.43820","0.00266"
"5.69400","0.47473","0.00294"
"6.13200","0.51114","0.00251"
"6.57000","0.54773","0.00277"
"7.00800","0.58420","0.00305"
"7.44600","0.62068","0.00285"
"7.88400","0.65721","0.00342"
"8.32200","0.69368","0.00383"
"8.76000","0.73021","0.00321"
"9.19800","0.76674","0.00357"
"9.63600","0.80327","0.00394"
"10.07400","0.83980","0.00357"
"10.51200","0.87628","0.00378"
"10.95000","0.91269","0.00379"
"11.38800","0.94922","0.00382"
"11.82600","0.98569","0.00336"
"12.26400","1.02222","0.00396"
"12.70200","1.05869","0.00348"
"13.14000","1.09511","0.00341"
"13.57800","1.13164","0.00386"
"14.01600","1.16823","0.00365"
"14.45400","1.20470","0.00428"
"14.89200","1.24123","0.00407"
"15.33000","1.27770","0.00342"
"15.76800","1.31417","0.00409"
"16.20600","1.35071","0.00399"
"16.64400","1.38724","0.00431"
"17.08200","1.42377","0.00466"
"17.52000","1.46024","0.00410"
"17.95800","1.49671","0.00418"
"18.39600","1.53324","0.00381"
"18.83400","1.56971","0.00420"
"19.27200","1.60625","0.00410"
"19.71000","1.64272","0.00441"
"20.14800","1.67919","0.00421"
"20.58600","1.71566","0.00435"
"21.02400","1.75219","0.00473"
"21.46200","1.78872","0.00453"
"21.90000","1.82525","0.00479"
"22.33800","1.86167","0.00384"
"22.77600","1.89820","0.00467"
"23.21400","1.93473","0.00431"
"23.65200","1.97120","0.00435"
"24.09000","2.00773","0.00455"
"24.52800","2.04420","0.00483"
"24.96600","2.08068","0.00475"
"25.40400","2.11721","0.00471"
"25.84200","2.15374","0.00468"
"26.28000","2.19027","0.00498"
"26.71800","2.22668","0.00448"
"27.15600","2.26315","0.00469"
"27.59400","2.29968","0.00543"
"28.03200","2.33622","0.00432"
"28.47000","2.37275","0.00465"
"28.90800","2.40928","0.00501"
"29.34600","2.44569","0.00479"
"29.78400","2.48216","0.00524"
"30.22200","2.51869","0.00456"
"30.66000","2.55523","0.00508"
"31.09800","2.59170","0.00475"
"31.53600","2.62817","0.00492"
"31.97400","2.66464","0.00475"
"32.41200","2.70123","0.00486"
"32.85000","2.73770","0.00512"
"33.28800","2.77423","0.00487"
"33.72600","2.81077","0.00524"
"34.16400","2.84718","0.00523"
"34.60200","2.88371","0.00517"
"35.04000","2.92030","0.00492"
"35.47800","2.95677","0.00526"
"35.91600","2.99324","0.00548"
"36.35400","3.02971","0.00528"
"36.79200","3.06619","0.00583"
"37.23000","3.10272","0.00512"
"37.66800","3.13925","0.00594"
"38.10600","3.17572","0.00583"
"38.54400","3.21219","0.00573"
"38.98200","3.24866","0.00569"
"39.42000","3.28520","0.00594"
"39.85800","3.32173","0.00547"
"40.29600","3.35820","0.00631"
"40.73400","3.39473","0.00610"
"41.17200","3.43114","0.00669"
"41.61000","3.46773","0.00637"
"42.04800","3.50420","0.00696"
"42.48600","3.54074","0.00667"
"42.92400","3.57727","0.00652"
"43.36200","3.61368","0.00680"
"43.80000","3.65015","0.00689"
"44.23800","3.68668","0.00682"
"44.67600","3.72327","0.00689"
"45.11400","3.75975","0.00657"
"45.55200","3.79622","0.00722"
"45.99000","3.83263","0.00748"
"46.42800","3.86916","0.00675"
"46.86600","3.90569","0.00764"
"47.30400","3.94228","0.00781"
"47.74200","3.97875","0.00726"
"48.18000","4.01517","0.00749"
"48.61800","4.05164","0.00779"
"49.05600","4.08823","0.00728"
"49.49400","4.12470","0.00802"
"49.93200","4.16123","0.00720"
"50.37000","4.19770","0.00758"
"50.80800","4.23423","0.00763"
"51.24600","4.27065","0.00749"
"51.68400","4.30718","0.00766"
"52.12200","4.34377","0.00786"
"52.56000","4.38024","0.00796"
"52.99800","4.41671","0.00724"
"53.43600","4.45318","0.00858"
"53.87400","4.48978","0.00753"
"54.31200","4.52625","0.00727"
"54.75000","4.56278","0.00759"
"55.18800","4.59925","0.00803"
"55.62600","4.63572","0.00768"
"56.06400","4.67213","0.00765"
"56.50200","4.70872","0.00802"
"56.94000","4.74514","0.00765"
"57.37800","4.78167","0.00730"
"57.81600","4.81814","0.00791"
"58.25400","4.85473","0.00810"
"58.69200","4.89126","0.00731"
"59.13000","4.92773","0.00784"
"59.56800","4.96426","0.00817"
"60.00600","5.00074","0.00775"
"60.44400","5.03721","0.00737"
"60.88200","5.07374","0.00793"
"61.32000","5.11021","0.00831"
"61.75800","5.14680","0.00793"
"62.19600","5.18321","0.00800"
"62.63400","5.21963","0.00822"
"63.07200","5.25622","0.00788"
"63.51000","5.29275","0.00754"
"63.94800","5.32916","0.00809"
"64.38600","5.36569","0.00814"
"64.82400","5.40216","0.00765"
"65.26200","5.43870","0.00823"
"65.70000","5.47523","0.00804"
"66.13800","5.51170","0.00779"
"66.57600","5.54823","0.00808"
"67.01400","5.58470","0.00777"
"67.45200","5.62123","0.00784"
"67.89000","5.65776","0.00770"
"68.32800","5.69424","0.00779"
"68.76600","5.73077","0.00786"
"69.20400","5.76724","0.00814"
"69.64200","5.80371","0.00786"
"70.08000","5.84018","0.00826"
"70.51800","5.87671","0.00838"
"70.95600","5.91319","0.00786"
"71.39400","5.94972","0.00779"
"71.83200","5.98613","0.00805"
"72.27000","6.02272","0.00810"
"72.70800","6.05919","0.00810"
"73.14600","6.09572","0.00831"
"73.58400","6.13219","0.00841"
"74.02200","6.16867","0.00829"
"74.46000","6.20520","0.00794"
"74.89800","6.24173","0.00799"
"75.33600","6.27820","0.00772"
"75.77400","6.31473","0.00808"
"76.21200","6.35120","0.00820"
"76.65000","6.38773","0.00749"
"77.08800","6.42421","0.00789"
"77.52600","6.46074","0.00766"
"77.96400","6.49721","0.00820"
"78.40200","6.53374","0.00821"
"78.84000","6.57021","0.00813"
"79.27800","6.60668","0.00811"
"79.71600","6.64321","0.00796"
"80.15400","6.67975","0.00834"
"80.59200","6.71628","0.00824"
"81.03000","6.75269","0.00685"
"81.46800","6.78916","0.00753"
"81.90600","6.82569","0.00802"
"82.34400","6.86222","0.00800"
"82.78200","6.89870","0.00795"
"83.22000","6.93523","0.00727"
"83.65800","6.97170","0.00793"
"84.09600","7.00823","0.00769"
"84.53400","7.04476","0.00801"
"84.97200","7.08123","0.00810"
"85.41000","7.11776","0.00781"
"85.84800","7.15424","0.00735"
"86.28600","7.19071","0.00793"
"86.72400","7.22724","0.00765"
"87.16200","7.26377","0.00830"
"87.60000","7.30024","0.00827"
"88.03800","7.33671","0.00786"
"88.47600","7.37313","0.00812"
"88.91400","7.40972","0.00765"
"89.35200","7.44625","0.00816"
"89.79000","7.48272","0.00833"
"90.22800","7.51919","0.00823"
"90.66600","7.55566","0.00813"
"91.10400","7.59220","0.00790"
"91.54200","7.62873","0.00801"
"91.98000","7.66520","0.00839"
"92.41800","7.70173","0.00848"
"92.85600","7.73820","0.00853"
"93.29400","7.77467","0.00791"
"93.73200","7.81120","0.00758"
"94.17000","7.84773","0.00803"
"94.60800","7.88427","0.00817"
"95.04600","7.92068","0.00867"
"95.48400","7.95715","0.00845"
"95.92200","7.99362","0.00797"
"96.36000","8.03021","0.00889"
"96.79800","8.06674","0.00812"
"97.23600","8.10328","0.00853"
"97.67400","8.13963","0.00798"
"98.11200","8.17616","0.00832"
"98.55000","8.21269","0.00870"
"98.98800","8.24922","0.00902"
"99.42600","8.28569","0.00855"
"99.86400","8.32216","0.00921"
"100.30200","8.35864","0.00866"
"100.74000","8.39517","0.00917"
"101.17800","8.43170","0.00888"
"101.61600","8.46829","0.00945"
"102.05400","8.50476","0.00859"
"102.49200","8.54123","0.00920"
"102.93000","8.57771","0.00920"
"103.36800","8.61418","0.00908"
"103.80600","8.65071","0.00942"
"104.24400","8.68724","0.00843"
"104.68200","8.72371","0.00876"
"105.12000","8.76018","0.00931"
"105.55800","8.79665","0.00949"
"105.99600","8.83319","0.00888"
"106.43400","8.86972","0.00863"
"106.87200","8.90619","0.00930"
"107.31000","8.94266","0.00877"
"107.74800","8.97919","0.00888"
"108.18600","9.01572","0.00879"
"108.62400","9.05219","0.00928"
"109.06200","9.08873","0.00894"
"109.50000","9.12520","0.00937"
"109.93800","9.16173","0.00930"
"110.37600","9.19826","0.00883"
"110.81400","9.23473","0.00958"
"111.25200","9.27132","0.00971"
"111.69000","9.30768","0.01003"
"112.12800","9.34421","0.00911"
"112.56600","9.38068","0.01034"
"113.00400","9.41727","0.00921"
"113.44200","9.45374","0.00955"
"113.88000","9.49021","0.01013"
"114.31800","9.52663","0.00994"
"114.75600","9.56316","0.00959"
"115.19400","9.59969","0.00983"
"115.63200","9.63622","0.00956"
"116.07000","9.67269","0.00957"
"116.50800","9.70922","0.01008"
"116.94600","9.74569","0.00977"
"117.38400","9.78223","0.01032"
"117.82200","9.81876","0.00935"
"118.26000","9.85529","0.00873"
"118.69800","9.89170","0.00952"
"119.13600","9.92817","0.00954"
"119.57400","9.96470","0.00965"
"120.01200","10.00117","0.00926"
"120.45000","10.03771","0.00960"
"120.88800","10.07418","0.00971"
"121.32600","10.11071","0.00941"
"121.76400","10.14718","0.00986"
"122.20200","10.18371","0.00961"
"122.64000","10.22024","0.00974"
"123.07800","10.25671","0.01004"
"123.51600","10.29313","0.00993"
"123.95400","10.32966","0.00930"
"124.39200","10.36619","0.00993"
"124.83000","10.40278","0.00909"
"125.26800","10.43925","0.00939"
"125.70600","10.47572","0.00978"
"126.14400","10.51220","0.00930"
"126.58200","10.54873","0.00931"
"127.02000","10.58526","0.00958"
"127.45800","10.62173","0.00945"
"127.89600","10.65820","0.00957"
"128.33400","10.69467","0.00982"
"128.77200","10.73114","0.00915"
"129.21000","10.76774","0.00998"
"129.64800","10.80421","0.00981"
"130.08600","10.84074","0.01058"
"130.52400","10.87715","0.00992"
"130.96200","10.91362","0.01054"
"131.40000","10.95021","0.01003"
"131.83800","10.98669","0.00995"
"132.27600","11.02322","0.01054"
"132.71400","11.05969","0.01036"
"133.15200","11.09616","0.01100"
"133.59000","11.13269","0.00984"
"134.02800","11.16922","0.00952"
"134.46600","11.20575","0.01001"
"134.90400","11.24229","0.01040"
"135.34200","11.27870","0.00970"
"135.78000","11.31523","0.00980"
"136.21800","11.35176","0.01056"
"136.65600","11.38829","0.01049"
"137.09400","11.42476","0.01012"
"137.53200","11.46124","0.01016"
"137.97000","11.49765","0.01038"
"138.40800","11.53418","0.01089"
"138.84600","11.57071","0.01011"
"139.28400","11.60718","0.01043"
"139.72200","11.64371","0.00986"
"140.16000","11.68018","0.01083"
"140.59800","11.71672","0.01025"
"141.03600","11.75325","0.01056"
"141.47400","11.78972","0.01063"
"141.91200","11.82625","0.01007"
"142.35000","11.86272","0.01066"
"142.78800","11.89919","0.01022"
"143.22600","11.93572","0.01093"
"143.66400","11.97226","0.01041"
"144.10200","12.00873","0.01089"
"144.54000","12.04520","0.01122"
"144.97800","12.08167","0.01104"
"145.41600","12.11826","0.01143"
"145.85400","12.15467","0.01064"
"146.29200","12.19121","0.01142"
"146.73000","12.22774","0.01120"
"147.16800","12.26421","0.01139"
"147.60600","12.30068","0.01166"
"148.04400","12.33721","0.01096"
"148.48200","12.37374","0.01128"
"148.92000","12.41021","0.01178"
"149.35800","12.44669","0.01095"
"149.79600","12.48316","0.01198"
"150.23400","12.51969","0.01124"
"150.67200","12.55628","0.01123"
"151.11000","12.59275","0.01148"
"151.54800","12.62922","0.01170"
"151.98600","12.66569","0.01158"
"152.42400","12.70217","0.01189"
"152.86200","12.73876","0.01183"
"153.30000","12.77517","0.01165"
"153.73800","12.81170","0.01129"
"154.17600","12.84817","0.01142"
"154.61400","12.88470","0.01141"
"155.05200","12.92118","0.01180"
"155.49000","12.95771","0.01130"
"155.92800","12.99424","0.01145"
"156.36600","13.03071","0.01115"
"156.80400","13.06712","0.01117"
"157.24200","13.10371","0.01201"
"157.68000","13.14024","0.01144"
"158.11800","13.17672","0.01146"
"158.55600","13.21319","0.01134"
"158.99400","13.24966","0.01232"
"159.43200","13.28619","0.01118"
"159.87000","13.32272","0.01127"
"160.30800","13.35925","0.01176"
"160.74600","13.39573","0.01182"
"161.18400","13.43220","0.01160"
"161.62200","13.46867","0.01206"
"162.06000","13.50520","0.01165"
"162.49800","13.54173","0.01169"
"162.93600","13.57820","0.01167"
"163.37400","13.61467","0.01228"
"163.81200","13.65115","0.01143"
"164.25000","13.68768","0.01137"
"164.68800","13.72421","0.01133"
"165.12600","13.76074","0.01151"
"165.56400","13.79721","0.01165"
"166.00200","13.83368","0.01212"
"166.44000","13.87016","0.01194"
"166.87800","13.90675","0.01204"
"167.31600","13.94322","0.01195"
"167.75400","13.97975","0.01265"
"168.19200","14.01622","0.01173"
"168.63000","14.05269","0.01198"
"169.06800","14.08922","0.01227"
"169.50600","14.12576","0.01217"
"169.94400","14.16223","0.01225"
"170.38200","14.19876","0.01171"
"170.82000","14.23523","0.01198"
"171.25800","14.27164","0.01230"
"171.69600","14.30823","0.01153"
"172.13400","14.34471","0.01143"
"172.57200","14.38124","0.01188"
"173.01000","14.41771","0.01190"
"173.44800","14.45418","0.01203"
"173.88600","14.49065","0.01158"
"174.32400","14.52724","0.01176"
"174.76200","14.56371","0.01087"
"175.20000","14.60025","0.01155"
"175.63800","14.63666","0.01154"
"176.07600","14.67319","0.01180"
"176.51400","14.70978","0.01204"
"176.95200","14.74619","0.01187"
"177.39000","14.78272","0.01235"
"177.82800","14.81920","0.01153"
"178.26600","14.85567","0.01220"
"178.70400","14.89226","0.01233"
"179.14200","14.92873","0.01190"
"179.58000","14.96520","0.01265"
"180.01800","15.00173","0.01199"
"180.45600","15.03820","0.01281"
"180.89400","15.07468","0.01186"
"181.33200","15.11121","0.01249"
"181.77000","15.14768","0.01239"
"182.20800","15.18421","0.01231"
"182.64600","15.22062","0.01240"
"183.08400","15.25721","0.01249"
"183.52200","15.29375","0.01270"
"183.96000","15.33022","0.01233"
"184.39800","15.36669","0.01221"
"184.83600","15.40316","0.01223"
"185.27400","15.43969","0.01221"
"185.71200","15.47622","0.01255"
"186.15000","15.51275","0.01220"
"186.58800","15.54923","0.01232"
"187.02600","15.58570","0.01232"
"187.46400","15.62217","0.01286"
"187.90200","15.65876","0.01214"
"188.34000","15.69523","0.01259"
"188.77800","15.73176","0.01251"
"189.21600","15.76817","0.01335"
"189.65400","15.80464","0.01283"
"190.09200","15.84118","0.01334"
"190.53000","15.87771","0.01290"
"190.96800","15.91418","0.01307"
"191.40600","15.95071","0.01336"
"191.84400","15.98718","0.01346"
"192.28200","16.02371","0.01313"
"192.72000","16.06025","0.01329"
"193.15800","16.09672","0.01344"
"193.59600","16.13325","0.01335"
"194.03400","16.16972","0.01364"
"194.47200","16.20619","0.01402"
"194.91000","16.24272","0.01347"
"195.34800","16.27925","0.01430"
"195.78600","16.31573","0.01362"
"196.22400","16.35220","0.01408"
"196.66200","16.38867","0.01415"
"197.10000","16.42520","0.01421"
"197.53800","16.46173","0.01440"
"197.97600","16.49821","0.01482"
"198.41400","16.53473","0.01445"
"198.85200","16.57121","0.01456"
"199.29000","16.60762","0.01418"
"199.72800","16.64415","0.01420"
"200.16600","16.68074","0.01422"
"200.60400","16.71727","0.01403"
"201.04200","16.75374","0.01445"
"201.48000","16.79016","0.01469"
"201.91800","16.82669","0.01443"
"202.35600","16.86328","0.01404"
"202.79400","16.89975","0.01457"
"203.23200","16.93622","0.01484"
"203.67000","16.97269","0.01476"
"204.10800","17.00916","0.01502"
"204.54600","17.04570","0.01434"
"204.98400","17.08223","0.01533"
"205.42200","17.11876","0.01518"
"205.86000","17.15523","0.01566"
"206.29800","17.19164","0.01458"
"206.73600","17.22817","0.01426"
"207.17400","17.26471","0.01503"
"207.61200","17.30118","0.01517"
"208.05000","17.33771","0.01512"
"208.48800","17.37418","0.01584"
"208.92600","17.41071","0.01489"
"209.36400","17.44724","0.01493"
"209.80200","17.48377","0.01508"
"210.24000","17.52025","0.01520"
"210.67800","17.55672","0.01535"
"211.11600","17.59319","0.01564"
"211.55400","17.62972","0.01599"
"211.99200","17.66625","0.01597"
"212.43000","17.70266","0.01615"
"212.86800","17.73919","0.01642"
"213.30600","17.77567","0.01588"
"213.74400","17.81220","0.01663"
"214.18200","17.84873","0.01688"
"214.62000","17.88520","0.01631"
"215.05800","17.92167","0.01666"
"215.49600","17.95815","0.01772"
"215.93400","17.99468","0.01664"
"216.37200","18.03121","0.01644"
"216.81000","18.06774","0.01646"
"217.24800","18.10421","0.01662"
"217.68600","18.14074","0.01657"
"218.12400","18.17715","0.01637"
"218.56200","18.21375","0.01699"
"219.00000","18.25028","0.01752"
"219.43800","18.28675","0.01736"
"219.87600","18.32322","0.01769"
"220.31400","18.35969","0.01779"
"220.75200","18.39616","0.01831"
"221.19000","18.43275","0.01895"
"221.62800","18.46922","0.01883"
"222.06600","18.50570","0.01930"
"222.50400","18.54217","0.01901"
"222.94200","18.57864","0.01947"
"223.38000","18.61517","0.02008"
"223.81800","18.65170","0.02032"
"224.25600","18.68818","0.01852"
"224.69400","18.72471","0.01779"
"225.13200","18.76112","0.02019"
"225.57000","18.79771","0.01967"
"226.00800","18.83424","0.01878"
"226.44600","18.87077","0.02018"
"226.88400","18.90724","0.02096"
"227.32200","18.94372","0.02081"
"227.76000","18.98025","0.02072"
"228.19800","19.01672","0.02134"
"228.63600","19.05319","0.02167"
"229.07400","19.08972","0.02167"
"229.51200","19.12619","0.02198"
"229.95000","19.16266","0.02042"
"230.38800","19.19920","0.02168"
"230.82600","19.23573","0.02259"
"231.26400","19.27220","0.02292"
"231.70200","19.30867","0.02325"
"232.14000","19.34520","0.02331"
"232.57800","19.38167","0.02354"
"233.01600","19.41827","0.02428"
"233.45400","19.45474","0.02433"
"233.89200","19.49127","0.02475"
"234.33000","19.52768","0.02529"
"234.76800","19.56415","0.02598"
"235.20600","19.60074","0.02646"
"235.64400","19.63727","0.02651"
"236.08200","19.67374","0.02726"
"236.52000","19.71022","0.02717"
"236.95800","19.74669","0.02905"
"237.39600","19.78322","0.02937"
"237.83400","19.81975","0.02930"
"238.27200","19.85616","0.03004"
"238.71000","19.89270","0.02994"
"239.14800","19.92917","0.03034"
"239.58600","19.96570","0.03115"
"240.02400","20.00217","0.03197"
"240.46200","20.03870","0.03212"
"240.90000","20.07523","0.03310"
"241.33800","20.11170","0.03372"
"241.77600","20.14818","0.03401"
"242.21400","20.18471","0.03433"
"242.65200","20.22118","0.03526"
"243.09000","20.25777","0.03616"
"243.52800","20.29424","0.03613"
"243.96600","20.33065","0.03754"
"244.40400","20.36724","0.03793"
"244.84200","20.40372","0.03863"
"245.28000","20.44019","0.03944"
"245.71800","20.47672","0.04007"
"246.15600","20.51319","0.04069"
"246.59400","20.54966","0.04163"
"247.03200","20.58619","0.04091"
"247.47000","20.62267","0.04231"
"247.90800","20.65919","0.04335"
"248.34600","20.69567","0.04406"
"248.78400","20.73220","0.04471"
"249.22200","20.76867","0.04627"
"249.66000","20.80520","0.04723"
"250.09800","20.84173","0.04777"
"250.53600","20.87820","0.04919"
"250.97400","20.91467","0.04933"
"251.41200","20.95121","0.05044"
"251.85000","20.98774","0.05106"
"252.28800","21.02427","0.05152"
"252.72600","21.06075","0.05250"
"253.16400","21.09722","0.05350"
"253.60200","21.13369","0.05373"
"254.04000","21.17022","0.05444"
"254.47800","21.20675","0.05507"
"254.91600","21.24322","0.05593"
"255.35400","21.27969","0.05721"
"255.79200","21.31610","0.05824"
"256.23000","21.35270","0.05937"
"256.66800","21.38923","0.06047"
"257.10600","21.42576","0.06177"
"257.54400","21.46217","0.06336"
"257.98200","21.49864","0.06222"
"258.42000","21.53517","0.04757"
"258.85800","21.57170","0.04790"
"259.29600","21.60824","0.05089"
"259.73400","21.64477","0.05406"
"260.17200","21.68118","0.05484"
"260.61000","21.71765","0.05384"
"261.04800","21.75424","0.05377"
"261.48600","21.79077","0.05505"
"261.92400","21.82718","0.05696"
"262.36200","21.86366","0.05834"
"262.80000","21.90019","0.05978"
"263.23800","21.93672","0.06063"
"263.67600","21.97325","0.06179"
"264.11400","22.00966","0.06412"
"264.55200","22.04625","0.06624"
"264.99000","22.08267","0.06779"
"265.42800","22.11920","0.06916"
"265.86600","22.15573","0.07073"
"266.30400","22.19220","0.07250"
"266.74200","22.22873","0.07422"
"267.18000","22.26520","0.07671"
"267.61800","22.30168","0.07936"
"268.05600","22.33821","0.08197"
"268.49400","22.37474","0.08423"
"268.93200","22.41127","0.08591"
"269.37000","22.44774","0.08706"
"269.80800","22.48415","0.08900"
"270.24600","22.52069","0.08962"
"270.68400","22.55721","0.09103"
"271.12200","22.59369","0.09314"
"271.56000","22.63028","0.09535"
"271.99800","22.66669","0.09556"
"272.43600","22.70322","0.09735"
"272.87400","22.73969","0.09862"
"273.31200","22.77622","0.10038"
"273.75000","22.81269","0.10222"
"274.18800","22.84911","0.10387"
"274.62600","22.88570","0.10529"
"275.06400","22.92217","0.10780"
"275.50200","22.95870","0.11027"
"275.94000","22.99523","0.11240"
"276.37800","23.03176","0.11488"
"276.81600","23.06818","0.11825"
"277.25400","23.10465","0.12077"
"277.69200","23.14124","0.12363"
"278.13000","23.17777","0.12677"
"278.56800","23.21424","0.12924"
"279.00600","23.25071","0.13189"
"279.44400","23.28713","0.13307"
"279.88200","23.32372","0.11184"
"280.32000","23.36025","0.10998"
"280.75800","23.39672","0.11230"
"281.19600","23.43319","0.11299"
"281.63400","23.46966","0.11436"
"282.07200","23.50620","0.11570"
"282.51000","23.54273","0.11610"
"282.94800","23.57926","0.11924"
"283.38600","23.61567","0.12223"
"283.82400","23.65214","0.12524"
"284.26200","23.68867","0.12795"
"284.70000","23.72520","0.13001"
"285.13800","23.76174","0.13200"
"285.57600","23.79827","0.13415"
"286.01400","23.83474","0.13546"
"286.45200","23.87115","0.10393"
"286.89000","23.90774","0.10282"
"287.32800","23.94421","0.10363"
"287.76600","23.98075","0.10470"
"288.20400","24.01722","0.10682"
"288.64200","24.05369","0.10781"
"289.08000","24.09016","0.10976"
"289.51800","24.12675","0.11259"
"289.95600","24.16316","0.11470"
"290.39400","24.19975","0.11437"
"290.83200","24.23616","0.11407"
"291.27000","24.27264","0.11776"
"291.70800","24.30917","0.12004"
"292.14600","24.34570","0.12204"
"292.58400","24.38223","0.12437"
"293.02200","24.41870","0.12660"
"293.46000","24.45517","0.08560"
"293.89800","24.49176","0.09029"
"294.33600","24.52824","0.09243"
"294.77400","24.56477","0.09419"
"295.21200","24.60124","0.09622"
"295.65000","24.63765","0.09686"
"296.08800","24.67418","0.09874"
"296.52600","24.71072","0.10079"
"296.96400","24.74725","0.10246"
"297.40200","24.78372","0.10609"
"297.84000","24.82019","0.11040"
"298.27800","24.85672","0.11534"
"298.71600","24.89319","0.11756"
"299.15400","24.92966","0.11680"
"299.59200","24.96620","0.11792"
"300.03000","25.00267","0.12143"
"300.46800","25.03920","0.12347"
"300.90600","25.07573","0.12385"
"301.34400","25.11226","0.12675"
"301.78200","25.14874","0.13013"
"302.22000","25.18521","0.13230"
"302.65800","25.22168","0.13429"
"303.09600","25.25821","0.13308"
"303.53400","25.29480","0.13555"
"303.97200","25.33121","0.13745"
"304.41000","25.36774","0.13892"
"304.84800","25.40415","0.12745"
"305.28600","25.44063","0.12728"
"305.72400","25.47721","0.12926"
"306.16200","25.51375","0.13135"
"306.60000","25.55022","0.13414"
"307.03800","25.58669","0.13611"
"307.47600","25.62310","0.13769"
"307.91400","25.65969","0.13874"
"308.35200","25.69623","0.13997"
"308.79000","25.73270","0.13976"
"309.22800","25.76923","0.14106"
"309.66600","25.80564","0.14192"
"310.10400","25.84217","0.14305"
"310.54200","25.87876","0.14360"
"310.98000","25.91523","0.14429"
"311.41800","25.95182","0.14528"
"311.85600","25.98824","0.14425"
"312.29400","26.02465","0.14522"
"312.73200","26.06124","0.14569"
"313.17000","26.09771","0.14762"
"313.60800","26.13424","0.14838"
"314.04600","26.17072","0.14891"
"314.48400","26.20713","0.15052"
"314.92200","26.24372","0.15200"
"315.36000","26.28025","0.05371"
"315.79800","26.31666","0.05397"
"316.23600","26.35320","0.05651"
"316.67400","26.38967","0.05549"
"317.11200","26.42620","0.05660"
"317.55000","26.46273","0.05735"
"317.98800","26.49920","0.05941"
"318.42600","26.53579","0.05949"
"318.86400","26.57220","0.05963"
"319.30200","26.60868","0.06120"
"319.74000","26.64527","0.06288"
"320.17800","26.68174","0.06490"
"320.61600","26.71827","0.06669"
"321.05400","26.75474","0.06814"
"321.49200","26.79115","0.07027"
"321.93000","26.82768","0.07278"
"322.36800","26.86421","0.07533"
"322.80600","26.90075","0.07619"
"323.24400","26.93728","0.07742"
"323.68200","26.97369","0.07936"
"324.12000","27.01016","0.08229"
"324.55800","27.04669","0.08402"
"324.99600","27.08322","0.08642"
"325.43400","27.11969","0.08824"
"325.87200","27.15617","0.09022"
"326.31000","27.19270","0.09159"
"326.74800","27.22917","0.09061"
"327.18600","27.26570","0.07839"
"327.62400","27.30229","0.08045"
"328.06200","27.33877","0.08419"
"328.50000","27.37524","0.08549"
"328.93800","27.41171","0.08478"
"329.37600","27.44824","0.08624"
"329.81400","27.48477","0.08876"
"330.25200","27.52130","0.09059"
"330.69000","27.55771","0.09175"
"331.12800","27.59418","0.09311"
"331.56600","27.63066","0.09521"
"332.00400","27.66725","0.09694"
"332.44200","27.70372","0.09838"
"332.88000","27.74019","0.09981"
"333.31800","27.77660","0.10071"
"333.75600","27.81319","0.10187"
"334.19400","27.84973","0.10336"
"334.63200","27.88620","0.10571"
"335.07000","27.92273","0.10767"
"335.50800","27.95920","0.10973"
"335.94600","27.99567","0.11149"
"336.38400","28.03226","0.11453"
"336.82200","28.06874","0.11700"
"337.26000","28.10527","0.11955"
"337.69800","28.14174","0.12260"
"338.13600","28.17821","0.12452"
"338.57400","28.21474","0.12680"
"339.01200","28.25121","0.12869"
"339.45000","28.28769","0.13177"
"339.88800","28.32416","0.13371"
"340.32600","28.36063","0.13567"
"340.76400","28.39716","0.13752"
"341.20200","28.43369","0.13856"
"341.64000","28.47022","0.14021"
"342.07800","28.50675","0.14097"
"342.51600","28.54317","0.14175"
"342.95400","28.57970","0.14310"
"343.39200","28.61623","0.14390"
"343.83000","28.65276","0.14516"
"344.26800","28.68923","0.14603"
"344.70600","28.72570","0.14677"
"345.14400","28.76217","0.14785"
"345.58200","28.79871","0.14896"
"346.02000","28.83524","0.15064"
"346.45800","28.87171","0.15234"
"346.89600","28.90824","0.15460"
"347.33400","28.94465","0.15666"
"347.77200","28.98118","0.15960"
"348.21000","29.01771","0.16256"
"348.64800","29.05419","0.16488"
"349.08600","29.09072","0.16755"
"349.52400","29.12719","0.17245"
"349.96200","29.16366","0.17613"
"350.40000","29.20019","0.18073"
"350.83800","29.23672","0.18462"
"351.27600","29.27320","0.18807"
"351.71400","29.30973","0.19165"
"352.15200","29.34620","0.19608"
"352.59000","29.38273","0.19934"
"353.02800","29.41920","0.20147"
"353.46600","29.45573","0.20430"
"353.90400","29.49226","0.20585"
"354.34200","29.52874","0.20705"
"354.78000","29.56515","0.20877"
"355.21800","29.60174","0.21060"
"355.65600","29.63827","0.21308"
"356.09400","29.67474","0.21548"
"356.53200","29.71115","0.21749"
"356.97000","29.74763","0.21986"
"357.40800","29.78422","0.22353"
"357.84600","29.82075","0.22588"
"358.28400","29.85722","0.22909"
"358.72200","29.89369","0.23113"
"359.16000","29.93016","0.23368"
"359.59800","29.96669","0.23646"
"360.03600","30.00323","0.23919"
"360.47400","30.03975","0.24144"
"360.91200","30.07623","0.24329"
"361.35000","30.11270","0.24551"
"361.78800","30.14923","0.24743"
"362.22600","30.18576","0.24922"
"362.66400","30.22223","0.25042"
"363.10200","30.25877","0.25169"
"363.54000","30.29518","0.25319"
"363.97800","30.33165","0.25432"
"364.41600","30.36818","0.25566"
"364.85400","30.40471","0.25749"
"365.29200","30.44118","0.25936"
"365.73000","30.47772","0.26210"
"366.16800","30.51413","0.26495"
"366.60600","30.55072","0.26759"
"367.04400","30.58719","0.26969"
"367.48200","30.62372","0.27313"
"367.92000","30.66025","0.27540"
"368.35800","30.69673","0.27883"
"368.79600","30.73326","0.28233"
"369.23400","30.76973","0.28534"
"369.67200","30.80626","0.28839"
"370.11000","30.84273","0.21903"
"370.54800","30.87914","0.21866"
"370.98600","30.91567","0.11987"
"371.42400","30.95221","0.13080"
"371.86200","30.98868","0.13255"
"372.30000","31.02521","0.13617"
"372.73800","31.06174","0.13654"
"373.17600","31.09815","0.14012"
"373.61400","31.13468","0.14271"
"374.05200","31.17122","0.14175"
"374.49000","31.20774","0.14230"
"374.92800","31.24422","0.13751"
"375.36600","31.28069","0.13859"
"375.80400","31.31716","0.13998"
"376.24200","31.35369","0.14128"
"376.68000","31.39028","0.14223"
"377.11800","31.42675","0.14313"
"377.55600","31.46322","0.14407"
"377.99400","31.49969","0.14458"
"378.43200","31.53617","0.14476"
"378.87000","31.57270","0.14569"
"379.30800","31.60923","0.14651"
"379.74600","31.64576","0.14760"
"380.18400","31.68217","0.14835"
"380.62200","31.71865","0.14989"
"381.06000","31.75517","0.15097"
"381.49800","31.79171","0.15205"
"381.93600","31.82824","0.15462"
"382.37400","31.86471","0.15603"
"382.81200","31.90112","0.15768"
"383.25000","31.93765","0.15925"
"383.68800","31.97425","0.16197"
"384.12600","32.01072","0.16419"
"384.56400","32.04725","0.16828"
"385.00200","32.08372","0.17165"
"385.44000","32.12019","0.17616"
"385.87800","32.15672","0.18053"
"386.31600","32.19326","0.18424"
"386.75400","32.22979","0.18848"
"387.19200","32.26620","0.19298"
"387.63000","32.30267","0.19670"
"388.06800","32.33920","0.19867"
"388.50600","32.37573","0.20005"
"388.94400","32.41220","0.20304"
"389.38200","32.44873","0.20487"
"389.82000","32.48521","0.20623"
"390.25800","32.52168","0.20678"
"390.69600","32.55821","0.20819"
"391.13400","32.59474","0.21028"
"391.57200","32.63121","0.21176"
"392.01000","32.66763","0.21440"
"392.44800","32.70415","0.21646"
"392.88600","32.74068","0.21946"
"393.32400","32.77722","0.22122"
"393.76200","32.81375","0.22414"
"394.20000","32.85022","0.22707"
"394.63800","32.88670","0.22941"
"395.07600","32.92323","0.23230"
"395.51400","32.95970","0.23413"
"395.95200","32.99629","0.23735"
"396.39000","33.03270","0.23919"
"396.82800","33.06917","0.24212"
"397.26600","33.10564","0.24441"
"397.70400","33.14217","0.24656"
"398.14200","33.17871","0.24839"
"398.58000","33.21524","0.24971"
"399.01800","33.25171","0.25083"
"399.45600","33.28818","0.12897"
"399.89400","33.32471","0.12819"
"400.33200","33.36124","0.13088"
"400.77000","33.39772","0.13605"
"401.20800","33.43419","0.13799"
"401.64600","33.47066","0.13772"
"402.08400","33.50719","0.13957"
"402.52200","33.54372","0.14177"
"402.96000","33.58019","0.14269"
"403.39800","33.61673","0.14267"
"403.83600","33.65319","0.14436"
"404.27400","33.68967","0.14481"
"404.71200","33.72620","0.14569"
"405.15000","33.76273","0.14644"
"405.58800","33.79926","0.14738"
"406.02600","33.83567","0.14822"
"406.46400","33.87215","0.14909"
"406.90200","33.90874","0.15037"
"407.34000","33.94521","0.15137"
"407.77800","33.98174","0.15246"
"408.21600","34.01815","0.15423"
"408.65400","34.05462","0.15721"
"409.09200","34.09116","0.15904"
"409.53000","34.12769","0.16114"
"409.96800","34.16422","0.16370"
"410.40600","34.20069","0.16573"
"410.84400","34.23716","0.16868"
"411.28200","34.27375","0.17127"
"411.72000","34.31022","0.17386"
"412.15800","34.34676","0.17752"
"412.59600","34.38329","0.17992"
"413.03400","34.41970","0.18270"
"413.47200","34.45617","0.18490"
"413.91000","34.49264","0.18821"
"414.34800","34.52929","0.19033"
"414.78600","34.56570","0.19242"
"415.22400","34.60224","0.19620"
"415.66200","34.63865","0.20070"
"416.10000","34.67518","0.20287"
"416.53800","34.71171","0.20442"
"416.97600","34.74818","0.20588"
"417.41400","34.78471","0.20723"
"417.85200","34.82125","0.07672"
"418.29000","34.85766","0.08242"
"418.72800","34.89425","0.05025"
"419.16600","34.93072","0.04481"
"419.60400","34.96725","0.05228"
"420.04200","35.00366","0.05947"
"420.48000","35.04019","0.05915"
"420.91800","35.07673","0.05474"
"421.35600","35.11320","0.05295"
"421.79400","35.14973","0.05432"
"422.23200","35.18620","0.05655"
"422.67000","35.22267","0.05823"
"423.10800","35.25920","0.05827"
"423.54600","35.29573","0.05689"
"423.98400","35.33227","0.05665"
"424.42200","35.36868","0.05794"
"424.86000","35.40515","0.05983"
"425.29800","35.44168","0.06156"
"425.73600","35.47821","0.06194"
"426.17400","35.51474","0.06168"
"426.61200","35.55128","0.06078"
"427.05000","35.58769","0.06094"
"427.48800","35.62416","0.06194"
"427.92600","35.66075","0.06385"
"428.36400","35.69728","0.06466"
"428.80200","35.73375","0.06494"
"429.24000","35.77022","0.06568"
"429.67800","35.80670","0.06588"
"430.11600","35.84317","0.06746"
"430.55400","35.87970","0.01743"
"430.99200","35.91623","0.00642"
"431.43000","35.95276","0.01630"
"431.86800","35.98917","0.02472"
"432.30600","36.02564","0.02565"
"432.74400","36.06218","0.02176"
"433.18200","36.09871","0.01894"
"433.62000","36.13524","0.01808"
"434.05800","36.17165","0.01728"
"434.49600","36.20812","0.01832"
"434.93400","36.24471","0.01673"
"435.37200","36.28125","0.01571"
"435.81000","36.31778","0.01626"
"436.24800","36.35425","0.01842"
"436.68600","36.39072","0.01947"
"437.12400","36.42719","0.02107"
"437.56200","36.46372","0.02158"
"438.00000","36.50025","0.02091"
"438.43800","36.53673","0.02058"
"438.87600","36.57320","0.02068"
"439.31400","36.60973","0.02053"
"439.75200","36.64614","0.02136"
"440.19000","36.68273","0.02157"
"440.62800","36.71920","0.02155"
"441.06600","36.75574","0.02133"
"441.50400","36.79215","0.02120"
"441.94200","36.82868","0.02160"
"442.38000","36.86521","0.02112"
"442.81800","36.90174","0.02213"
"443.25600","36.93821","0.02231"
"443.69400","36.97474","0.02308"
"444.13200","37.01116","0.02356"
"444.57000","37.04775","0.02418"
"445.00800","37.08428","0.02455"
"445.44600","37.12075","0.02435"
"445.88400","37.15722","0.02478"
"446.32200","37.19370","0.02301"
"446.76000","37.23022","0.02439"
"447.19800","37.26670","0.02344"
"447.63600","37.30323","0.02538"
"448.07400","37.33970","0.02454"
"448.51200","37.37623","0.02645"
"448.95000","37.41264","0.02606"
"449.38800","37.44917","0.02777"
"449.82600","37.48570","0.02716"
"450.26400","37.52224","0.02896"
"450.70200","37.55871","0.02789"
"451.14000","37.59518","0.02908"
"451.57800","37.63171","0.02829"
"452.01600","37.66824","0.02912"
"452.45400","37.70471","0.02953"
"452.89200","37.74125","0.02945"
"453.33000","37.77772","0.02941"
"453.76800","37.81425","0.03001"
"454.20600","37.85078","0.02967"
"454.64400","37.88725","0.03045"
"455.08200","37.92373","0.03041"
"455.52000","37.96019","0.03062"
"455.95800","37.99673","0.03118"
"456.39600","38.03320","0.03145"
"456.83400","38.06973","0.03113"
"457.27200","38.10620","0.03183"
"457.71000","38.14273","0.03215"
"458.14800","38.17915","0.03305"
"458.58600","38.21568","0.03270"
"459.02400","38.25221","0.03371"
"459.46200","38.28874","0.03381"
"459.90000","38.32515","0.03433"
"460.33800","38.36168","0.03355"
"460.77600","38.39821","0.03470"
"461.21400","38.43475","0.03443"
"461.65200","38.47128","0.03513"
"462.09000","38.50775","0.03423"
"462.52800","38.54422","0.03482"
"462.96600","38.58069","0.03462"
"463.40400","38.61722","0.03424"
"463.84200","38.65376","0.03281"
"464.28000","38.69022","0.03350"
"464.71800","38.72664","0.03341"
"465.15600","38.76311","0.03337"
"465.59400","38.79964","0.03424"
"466.03200","38.83624","0.03347"
"466.47000","38.87270","0.03476"
"466.90800","38.90923","0.03441"
"467.34600","38.94564","0.03509"
"467.78400","38.98218","0.03512"
"468.22200","39.01871","0.03501"
"468.66000","39.05524","0.03573"
"469.09800","39.09177","0.03553"
"469.53600","39.12824","0.03600"
"469.97400","39.16471","0.03598"
"470.41200","39.20125","0.03564"
"470.85000","39.23778","0.03636"
"471.28800","39.27419","0.03654"
"471.72600","39.31072","0.03710"
"472.16400","39.34719","0.03667"
"472.60200","39.38366","0.03638"
"473.04000","39.42020","0.03741"
"473.47800","39.45673","0.03709"
"473.91600","39.49320","0.03755"
"474.35400","39.52967","0.03758"
"474.79200","39.56620","0.03799"
"475.23000","39.60273","0.03755"
"475.66800","39.63926","0.03699"
"476.10600","39.67574","0.03752"
"476.54400","39.71221","0.03775"
"476.98200","39.74868","0.03759"
"477.42000","39.78521","0.03779"
"477.85800","39.82180","0.03831"
"478.29600","39.85827","0.03839"
"478.73400","39.89468","0.03887"
"479.17200","39.93116","0.03900"
"479.61000","39.96769","0.03949"
"480.04800","40.00428","0.03932"
"480.48600","40.04069","0.03941"
"480.92400","40.07722","0.03977"
"481.36200","40.11369","0.03916"
"481.80000","40.15017","0.03984"
"482.23800","40.18664","0.03995"
"482.67600","40.22323","0.04025"
"483.11400","40.25970","0.04057"
"483.55200","40.29623","0.04082"
"483.99000","40.33264","0.04121"
"484.42800","40.36924","0.04178"
"484.86600","40.40570","0.04168"
"485.30400","40.44224","0.04163"
"485.74200","40.47871","0.04278"
"486.18000","40.51518","0.04284"
"486.61800","40.55165","0.04357"
"487.05600","40.58825","0.04282"
"487.49400","40.62477","0.04268"
"487.93200","40.66125","0.04344"
"488.37000","40.69772","0.04377"
"488.80800","40.73419","0.04388"
"489.24600","40.77072","0.04389"
"489.68400","40.80719","0.04375"
"490.12200","40.84373","0.04339"
"490.56000","40.88020","0.04403"
"490.99800","40.91667","0.04428"
"491.43600","40.95314","0.04501"
"491.87400","40.98973","0.04525"
"492.31200","41.02620","0.04575"
"492.75000","41.06274","0.04586"
"493.18800","41.09921","0.04639"
"493.62600","41.13568","0.04682"
"494.06400","41.17221","0.04556"
"494.50200","41.20874","0.04607"
"494.94000","41.24527","0.04640"
"495.37800","41.28175","0.04691"
"495.81600","41.31816","0.04687"
"496.25400","41.35469","0.04708"
"496.69200","41.39128","0.04640"
"497.13000","41.42775","0.04606"
"497.56800","41.46422","0.04691"
"498.00600","41.50069","0.04710"
"498.44400","41.53717","0.04745"
"498.88200","41.57364","0.04764"
"499.32000","41.61023","0.04838"
"499.75800","41.64676","0.04842"
"500.19600","41.68323","0.04899"
"500.63400","41.71964","0.04878"
"501.07200","41.75618","0.04947"
"501.51000","41.79271","0.04963"
"501.94800","41.82924","0.05026"
"502.38600","41.86571","0.05005"
"502.82400","41.90218","0.05047"
"503.26200","41.93865","0.05110"
"503.70000","41.97524","0.04933"
"504.13800","42.01171","0.04952"
"504.57600","42.04819","0.04957"
"505.01400","42.08472","0.05010"
"505.45200","42.12119","0.04941"
"505.89000","42.15772","0.05005"
"506.32800","42.19419","0.04934"
"506.76600","42.23072","0.04892"
"507.20400","42.26725","0.04935"
"507.64200","42.30367","0.04881"
"508.08000","42.34014","0.04795"
"508.51800","42.37673","0.04886"
"508.95600","42.41320","0.04895"
"509.39400","42.44973","0.04917"
"509.83200","42.48614","0.05005"
"510.27000","42.52267","0.05049"
"510.70800","42.55921","0.05082"
"511.14600","42.59574","0.05137"
"511.58400","42.63221","0.05241"
"512.02200","42.66868","0.05238"
"512.46000","42.70515","0.05269"
"512.89800","42.74174","0.05241"
"513.33600","42.77822","0.05279"
"513.77400","42.81469","0.05291"
"514.21200","42.85122","0.05264"
"514.65000","42.88763","0.05288"
"515.08800","42.92422","0.05274"
"515.52600","42.96069","0.05314"
"515.96400","42.99723","0.05340"
"516.40200","43.03376","0.05355"
"516.84000","43.07017","0.05275"
"517.27800","43.10664","0.05256"
"517.71600","43.14317","0.05291"
"518.15400","43.17970","0.05269"
"518.59200","43.21624","0.05240"
"519.03000","43.25271","0.05218"
"519.46800","43.28918","0.05213"
"519.90600","43.32571","0.05221"
"520.34400","43.36224","0.05240"
"520.78200","43.39871","0.05168"
"521.22000","43.43518","0.05253"
"521.65800","43.47172","0.05306"
"522.09600","43.50813","0.05267"
"522.53400","43.54472","0.05324"
"522.97200","43.58119","0.05351"
"523.41000","43.61772","0.05349"
"523.84800","43.65419","0.05316"
"524.28600","43.69066","0.05307"
"524.72400","43.72720","0.05338"
"525.16200","43.76367","0.05364"
"525.60000","43.80025","0.05364"
"526.03800","43.83673","0.05373"
"526.47600","43.87314","0.05371"
"526.91400","43.90967","0.05400"
"527.35200","43.94627","0.05389"
"527.79000","43.98274","0.05456"
"528.22800","44.01921","0.05486"
"528.66600","44.05568","0.05499"
"529.10400","44.09221","0.05496"
"529.54200","44.12874","0.05526"
"529.98000","44.16521","0.05543"
"530.41800","44.20175","0.05572"
"530.85600","44.23822","0.05548"
"531.29400","44.27469","0.05579"
"531.73200","44.31122","0.05619"
"532.17000","44.34775","0.05661"
"532.60800","44.38422","0.05687"
"533.04600","44.42069","0.05669"
"533.48400","44.45717","0.05737"
"533.92200","44.49370","0.05757"
"534.36000","44.53022","0.05773"
"534.79800","44.56670","0.05801"
"535.23600","44.60323","0.05795"
"535.67400","44.63970","0.05868"
"536.11200","44.67617","0.05888"
"536.55000","44.71276","0.05933"
"536.98800","44.74923","0.05912"
"537.42600","44.78577","0.05930"
"537.86400","44.82224","0.05976"
"538.30200","44.85865","0.05978"
"538.74000","44.89524","0.06045"
"539.17800","44.93177","0.06044"
"539.61600","44.96819","0.06122"
"540.05400","45.00471","0.06088"
"540.49200","45.04113","0.06171"
"540.93000","45.07772","0.06182"
"541.36800","45.11419","0.06190"
"541.80600","45.15067","0.06225"
"542.24400","45.18720","0.06202"
"542.68200","45.22367","0.06274"
"543.12000","45.26014","0.06331"
"543.55800","45.29673","0.06396"
"543.99600","45.33326","0.06399"
"544.43400","45.36973","0.06434"
"544.87200","45.40621","0.06521"
"545.31000","45.44268","0.06505"
"545.74800","45.47921","0.06525"
"546.18600","45.51574","0.06612"
"546.62400","45.55221","0.06627"
"547.06200","45.58874","0.06612"
"547.50000","45.62521","0.06688"
"547.93800","45.66169","0.06687"
"548.37600","45.69822","0.06758"
"548.81400","45.73475","0.06797"
"549.25200","45.77122","0.06816"
"549.69000","45.80763","0.06872"
"550.12800","45.84416","0.06933"
"550.56600","45.88063","0.06964"
"551.00400","45.91722","0.07037"
"551.44200","45.95369","0.07035"
"551.88000","45.99023","0.07047"
"552.31800","46.02664","0.07134"
"552.75600","46.06318","0.07253"
"553.19400","46.09976","0.07230"
"553.63200","46.13630","0.07274"
"554.07000","46.17277","0.07344"
"554.50800","46.20918","0.07367"
"554.94600","46.24565","0.07419"
"555.38400","46.28224","0.07475"
"555.82200","46.31871","0.07499"
"556.26000","46.35518","0.07525"
"556.69800","46.39172","0.07536"
"557.13600","46.42818","0.07627"
"557.57400","46.46472","0.07719"
"558.01200","46.50119","0.07745"
"558.45000","46.53772","0.07779"
"558.88800","46.57420","0.07847"
"559.32600","46.61060","0.07913"
"559.76400","46.64714","0.07949"
"560.20200","46.68373","0.07996"
"560.64000","46.72020","0.08050"
"561.07800","46.75679","0.08125"
"561.51600","46.79326","0.08207"
"561.95400","46.82967","0.08243"
"562.39200","46.86627","0.08286"
"562.83000","46.90274","0.08373"
"563.26800","46.93927","0.08407"
"563.70600","46.97568","0.08454"
"564.14400","47.01215","0.08562"
"564.58200","47.04868","0.08597"
"565.02000","47.08521","0.08635"
"565.45800","47.12169","0.08727"
"565.89600","47.15822","0.08816"
"566.33400","47.19469","0.08861"
"566.77200","47.23116","0.08881"
"567.21000","47.26769","0.08932"
"567.64800","47.30416","0.08964"
"568.08600","47.34075","0.08984"
"568.52400","47.37723","0.09088"
"568.96200","47.41364","0.09139"
"569.40000","47.45023","0.09235"
"569.83800","47.48676","0.09191"
"570.27600","47.52329","0.09245"
"570.71400","47.55976","0.09351"
"571.15200","47.59612","0.09329"
"571.59000","47.63271","0.09386"
"572.02800","47.66924","0.09455"
"572.46600","47.70571","0.09480"
"572.90400","47.74224","0.09531"
"573.34200","47.77871","0.09573"
"573.78000","47.81518","0.09604"
"574.21800","47.85172","0.09684"
"574.65600","47.88819","0.09701"
"575.09400","47.92472","0.09698"
"575.53200","47.96119","0.09748"
"575.97000","47.99767","0.09798"
"576.40800","48.03419","0.09884"
"576.84600","48.07072","0.09917"
"577.28400","48.10720","0.09938"
"577.72200","48.14373","0.09950"
"578.16000","48.18020","0.10074"
"578.59800","48.21673","0.10094"
"579.03600","48.25326","0.10134"
"579.47400","48.28973","0.10156"
"579.91200","48.32627","0.10203"
"580.35000","48.36268","0.10296"
"580.78800","48.39915","0.10354"
"581.22600","48.43574","0.10364"
"581.66400","48.47221","0.10392"
"582.10200","48.50874","0.10478"
"582.54000","48.54515","0.10542"
"582.97800","48.58163","0.10609"
"583.41600","48.61822","0.10668"
"583.85400","48.65469","0.10733"
"584.29200","48.69122","0.10774"
"584.73000","48.72769","0.10854"
"585.16800","48.76416","0.10894"
"585.60600","48.80069","0.10922"
"586.04400","48.83723","0.11032"
"586.48200","48.87376","0.11121"
"586.92000","48.91029","0.11248"
"587.35800","48.94670","0.11196"
"587.79600","48.98317","0.11334"
"588.23400","49.01970","0.11382"
"588.67200","49.05617","0.11431"
"589.11000","49.09271","0.11486"
"589.54800","49.12924","0.11561"
"589.98600","49.16565","0.11658"
"590.42400","49.20213","0.11722"
"590.86200","49.23871","0.11853"
"591.30000","49.27518","0.11963"
"591.73800","49.31172","0.11941"
"592.17600","49.34819","0.12097"
"592.61400","49.38472","0.12152"
"593.05200","49.42125","0.12288"
"593.49000","49.45766","0.12332"
"593.92800","49.49425","0.12451"
"594.36600","49.53072","0.12466"
"594.80400","49.56720","0.12586"
"595.24200","49.60373","0.12654"
"595.68000","49.64020","0.12690"
"596.11800","49.67673","0.12742"
"596.55600","49.71320","0.12847"
"596.99400","49.74967","0.12959"
"597.43200","49.78620","0.13012"
"597.87000","49.82268","0.13098"
"598.30800","49.85921","0.13175"
"598.74600","49.89574","0.13252"
"599.18400","49.93221","0.13322"
"599.62200","49.96868","0.13282"
"600.06000","50.00521","0.13344"
"600.49800","50.04169","0.13385"
"600.93600","50.07822","0.13493"
"601.37400","50.11469","0.13493"
"601.81200","50.15116","0.13622"
"602.25000","50.18769","0.13682"
"602.68800","50.22422","0.13694"
"603.12600","50.26076","0.13756"
"603.56400","50.29723","0.13832"
"604.00200","50.33364","0.13867"
"604.44000","50.37017","0.13896"
"604.87800","50.40676","0.13939"
"605.31600","50.44323","0.13961"
"605.75400","50.47970","0.14060"
"606.19200","50.51617","0.14048"
"606.63000","50.55265","0.14094"
"607.06800","50.58918","0.14098"
"607.50600","50.62571","0.14143"
"607.94400","50.66230","0.14192"
"608.38200","50.69871","0.14207"
"608.82000","50.73512","0.14229"
"609.25800","50.77172","0.14241"
"609.69600","50.80819","0.14287"
"610.13400","50.84466","0.14286"
"610.57200","50.88125","0.14337"
"611.01000","50.91772","0.14376"
"611.44800","50.95419","0.14399"
"611.88600","50.99073","0.14424"
"612.32400","51.02726","0.14471"
"612.76200","51.06385","0.14479"
"613.20000","51.10020","0.14515"
"613.63800","51.13667","0.14556"
"614.07600","51.17327","0.14552"
"614.51400","51.20974","0.14585"
"614.95200","51.24627","0.14604"
"615.39000","51.28268","0.14657"
"615.82800","51.31915","0.14659"
"616.26600","51.35568","0.14696"
"616.70400","51.39221","0.14733"
"617.14200","51.42868","0.14735"
"617.58000","51.46522","0.14764"
"618.01800","51.50169","0.14805"
"618.45600","51.53816","0.14845"
"618.89400","51.57475","0.14909"
"619.33200","51.61122","0.14945"
"619.77000","51.64775","0.14929"
"620.20800","51.68423","0.14983"
"620.64600","51.72063","0.15014"
"621.08400","51.75717","0.15055"
"621.52200","51.79376","0.15070"
"621.96000","51.83023","0.15104"
"622.39800","51.86677","0.15112"
"622.83600","51.90311","0.15190"
"623.27400","51.93964","0.15221"
"623.71200","51.97618","0.15327"
"624.15000","52.01271","0.15344"
"624.58800","52.04924","0.15397"
"625.02600","52.08571","0.15440"
"625.46400","52.12218","0.15477"
"625.90200","52.15872","0.15543"
"626.34000","52.19519","0.15569"
"626.77800","52.23172","0.15618"
"627.21600","52.26819","0.15659"
"627.65400","52.30472","0.15781"
"628.09200","52.34119","0.15799"
"628.53000","52.37766","0.15914"
"628.96800","52.41420","0.15911"
"629.40600","52.45073","0.15998"
"629.84400","52.48720","0.16020"
"630.28200","52.52367","0.16063"
"630.72000","52.56026","0.16094"
"631.15800","52.59674","0.16194"
"631.59600","52.63327","0.16264"
"632.03400","52.66974","0.16270"
"632.47200","52.70621","0.16375"
"632.91000","52.74268","0.16378"
"633.34800","52.77921","0.16507"
"633.78600","52.81568","0.16599"
"634.22400","52.85222","0.16664"
"634.66200","52.88863","0.16851"
"635.10000","52.92522","0.16892"
"635.53800","52.96169","0.16992"
"635.97600","52.99822","0.17093"
"636.41400","53.03475","0.17166"
"636.85200","53.07116","0.17267"
"637.29000","53.10770","0.17273"
"637.72800","53.14423","0.17376"
"638.16600","53.18076","0.17403"
"638.60400","53.21729","0.17504"
"639.04200","53.25370","0.17623"
"639.48000","53.29017","0.17680"
"639.91800","53.32671","0.17772"
"640.35600","53.36324","0.17915"
"640.79400","53.39971","0.17918"
"641.23200","53.43618","0.17978"
"641.67000","53.47265","0.18083"
"642.10800","53.50918","0.18179"
"642.54600","53.54572","0.18271"
"642.98400","53.58219","0.18320"
"643.42200","53.61872","0.18441"
"643.86000","53.65519","0.18485"
"644.29800","53.69166","0.18591"
"644.73600","53.72819","0.18661"
"645.17400","53.76472","0.18793"
"645.61200","53.80125","0.18951"
"646.05000","53.83773","0.18983"
"646.48800","53.87420","0.19123"
"646.92600","53.91072","0.19132"
"647.36400","53.94726","0.19204"
"647.80200","53.98373","0.19247"
"648.24000","54.02026","0.01283"
"648.67800","54.05661","0.00506"
"649.11600","54.09321","0.00721"
"649.55400","54.12973","0.00675"
"649.99200","54.16626","0.00519"
"650.43000","54.20274","0.00714"
"650.86800","54.23915","0.00743"
"651.30600","54.27562","0.00533"
"651.74400","54.31216","0.00733"
"652.18200","54.34874","0.00791"
"652.62000","54.38527","0.00525"
"653.05800","54.42169","0.00745"
"653.49600","54.45816","0.00735"
"653.52600","54.46067","0.00743"