File: Force_trajectories/170226_2/Specimen_RawData_10.csv
End date,"2/26/2017"
Specimen label,"7AG_53"
Maximum Load,"0.03320",N

Time,Extension,Load
(s),(mm),(N)
"0.00000","0.00000","-0.00055"
"0.31200","0.02565","0.00149"
"0.62400","0.05226","0.00198"
"0.93600","0.07814","0.00238"
"1.24800","0.10421","0.00302"
"1.56000","0.13016","0.00369"
"1.87200","0.15617","0.00478"
"2.18400","0.18224","0.00530"
"2.49600","0.20813","0.00555"
"2.80800","0.23420","0.00585"
"3.12000","0.26014","0.00650"
"3.43200","0.28621","0.00719"
"3.74400","0.31222","0.00713"
"4.05600","0.33817","0.00768"
"4.36800","0.36424","0.00807"
"4.68000","0.39013","0.00715"
"4.99200","0.41619","0.00720"
"5.30400","0.44220","0.00787"
"5.61600","0.46821","0.00806"
"5.92800","0.49422","0.00881"
"6.24000","0.52017","0.00852"
"6.55200","0.54618","0.00908"
"6.86400","0.57213","0.00966"
"7.17600","0.59819","0.00946"
"7.48800","0.62420","0.01007"
"7.80000","0.65015","0.01006"
"8.11200","0.67616","0.01027"
"8.42400","0.70211","0.00953"
"8.73600","0.72818","0.00986"
"9.04800","0.75419","0.01011"
"9.36000","0.78019","0.01025"
"9.67200","0.80620","0.01076"
"9.98400","0.83221","0.01097"
"10.29600","0.85822","0.01147"
"10.60800","0.88411","0.01161"
"10.92000","0.91024","0.01121"
"11.23200","0.93618","0.01213"
"11.54400","0.96213","0.01180"
"11.85600","0.98820","0.01266"
"12.16800","1.01415","0.01283"
"12.48000","1.04016","0.01302"
"12.79200","1.06617","0.01284"
"13.10400","1.09218","0.01303"
"13.41600","1.11818","0.01341"
"13.72800","1.14419","0.01408"
"14.04000","1.17020","0.01402"
"14.35200","1.19615","0.01389"
"14.66400","1.22222","0.01397"
"14.97600","1.24817","0.01421"
"15.28800","1.27417","0.01500"
"15.60000","1.30018","0.01480"
"15.91200","1.32613","0.01493"
"16.22400","1.35226","0.01530"
"16.53600","1.37821","0.01514"
"16.84800","1.40422","0.01560"
"17.16000","1.43023","0.01580"
"17.47200","1.45623","0.01543"
"17.78400","1.48218","0.01531"
"18.09600","1.50819","0.01553"
"18.40800","1.53420","0.01591"
"18.72000","1.56021","0.01589"
"19.03200","1.58622","0.01599"
"19.34400","1.61216","0.01576"
"19.65600","1.63817","0.01576"
"19.96800","1.66424","0.01569"
"20.28000","1.69019","0.01588"
"20.59200","1.71620","0.01450"
"20.90400","1.74221","0.01416"
"21.21600","1.76822","0.01333"
"21.52800","1.79422","0.01319"
"21.84000","1.82017","0.01322"
"22.15200","1.84618","0.01415"
"22.46400","1.87213","0.01383"
"22.77600","1.89820","0.01377"
"23.08800","1.92415","0.01379"
"23.40000","1.95022","0.01375"
"23.71200","1.97622","0.01416"
"24.02400","2.00211","0.01430"
"24.33600","2.02818","0.01401"
"24.64800","2.05413","0.01388"
"24.96000","2.08020","0.01344"
"25.27200","2.10615","0.01405"
"25.58400","2.13215","0.01397"
"25.89600","2.15816","0.01302"
"26.20800","2.18411","0.01302"
"26.52000","2.21024","0.01307"
"26.83200","2.23619","0.01339"
"27.14400","2.26226","0.01349"
"27.45600","2.28821","0.01382"
"27.76800","2.31415","0.01385"
"28.08000","2.34016","0.01415"
"28.39200","2.36611","0.01470"
"28.70400","2.39224","0.01410"
"29.01600","2.41819","0.01404"
"29.32800","2.44420","0.01447"
"29.64000","2.47020","0.01444"
"29.95200","2.49615","0.01485"
"30.26400","2.52222","0.01471"
"30.57600","2.54817","0.01522"
"30.88800","2.57424","0.01531"
"31.20000","2.60019","0.01499"
"31.51200","2.62614","0.01534"
"31.82400","2.65220","0.01569"
"32.13600","2.67815","0.01535"
"32.44800","2.70422","0.01601"
"32.76000","2.73017","0.01592"
"33.07200","2.75618","0.01603"
"33.38400","2.78219","0.01604"
"33.69600","2.80819","0.01620"
"34.00800","2.83420","0.01638"
"34.32000","2.86015","0.01629"
"34.63200","2.88622","0.01684"
"34.94400","2.91217","0.01656"
"35.25600","2.93818","0.01702"
"35.56800","2.96419","0.01697"
"35.88000","2.99019","0.01674"
"36.19200","3.01620","0.01764"
"36.50400","3.04215","0.01727"
"36.81600","3.06816","0.01766"
"37.12800","3.09417","0.01790"
"37.44000","3.12012","0.01778"
"37.75200","3.14618","0.01783"
"38.06400","3.17213","0.01814"
"38.37600","3.19820","0.01835"
"38.68800","3.22415","0.01827"
"39.00000","3.25016","0.01825"
"39.31200","3.27623","0.01793"
"39.62400","3.30218","0.01852"
"39.93600","3.32818","0.01885"
"40.24800","3.35407","0.01845"
"40.56000","3.38020","0.01916"
"40.87200","3.40615","0.01866"
"41.18400","3.43216","0.01883"
"41.49600","3.45823","0.01901"
"41.80800","3.48418","0.01953"
"42.12000","3.51024","0.01930"
"42.43200","3.53619","0.01958"
"42.74400","3.56220","0.01991"
"43.05600","3.58821","0.01935"
"43.36800","3.61422","0.01935"
"43.68000","3.64023","0.02044"
"43.99200","3.66612","0.02008"
"44.30400","3.69218","0.02025"
"44.61600","3.71819","0.02018"
"44.92800","3.74420","0.02079"
"45.24000","3.77021","0.02095"
"45.55200","3.79616","0.02087"
"45.86400","3.82217","0.02076"
"46.17600","3.84817","0.02139"
"46.48800","3.87418","0.02106"
"46.80000","3.90019","0.02135"
"47.11200","3.92620","0.02192"
"47.42400","3.95221","0.02210"
"47.73600","3.97810","0.02229"
"48.04800","4.00422","0.02204"
"48.36000","4.03023","0.02089"
"48.67200","4.05624","0.02052"
"48.98400","4.08225","0.02063"
"49.29600","4.10820","0.02051"
"49.60800","4.13427","0.02080"
"49.92000","4.16016","0.02097"
"50.23200","4.18622","0.02116"
"50.54400","4.21223","0.02106"
"50.85600","4.23818","0.02123"
"51.16800","4.26413","0.02083"
"51.48000","4.29014","0.02063"
"51.79200","4.31615","0.02077"
"52.10400","4.34215","0.02121"
"52.41600","4.36822","0.02192"
"52.72800","4.39423","0.02157"
"53.04000","4.42018","0.02152"
"53.35200","4.44619","0.02130"
"53.66400","4.47214","0.02211"
"53.97600","4.49821","0.02208"
"54.28800","4.52415","0.02294"
"54.60000","4.55016","0.02271"
"54.91200","4.57623","0.02348"
"55.22400","4.60212","0.02316"
"55.53600","4.62819","0.02208"
"55.84800","4.65420","0.02323"
"56.16000","4.68021","0.02317"
"56.47200","4.70621","0.02311"
"56.78400","4.73216","0.02248"
"57.09600","4.75823","0.02294"
"57.40800","4.78412","0.02260"
"57.72000","4.81025","0.02273"
"58.03200","4.83614","0.02318"
"58.34400","4.86214","0.02287"
"58.65600","4.88815","0.02331"
"58.96800","4.91416","0.02351"
"59.28000","4.94023","0.02351"
"59.59200","4.96618","0.02389"
"59.90400","4.99219","0.02377"
"60.21600","5.01819","0.02408"
"60.52800","5.04420","0.02392"
"60.84000","5.07021","0.02469"
"61.15200","5.09622","0.02478"
"61.46400","5.12223","0.02487"
"61.77600","5.14812","0.02454"
"62.08800","5.17419","0.02489"
"62.40000","5.20025","0.02544"
"62.71200","5.22620","0.02506"
"63.02400","5.25221","0.02477"
"63.33600","5.27816","0.02504"
"63.64800","5.30423","0.02529"
"63.96000","5.33012","0.02567"
"64.27200","5.35619","0.02540"
"64.58400","5.38225","0.02545"
"64.89600","5.40814","0.02542"
"65.20800","5.43421","0.02590"
"65.52000","5.46010","0.02565"
"65.83200","5.48617","0.02625"
"66.14400","5.51218","0.02577"
"66.45600","5.53818","0.02576"
"66.76800","5.56419","0.02639"
"67.08000","5.59014","0.02664"
"67.39200","5.61621","0.02653"
"67.70400","5.64216","0.02732"
"68.01600","5.66823","0.02685"
"68.32800","5.69424","0.02718"
"68.64000","5.72018","0.02743"
"68.95200","5.74619","0.02748"
"69.26400","5.77208","0.02737"
"69.57600","5.79815","0.02787"
"69.88800","5.82416","0.02770"
"70.20000","5.85017","0.02804"
"70.51200","5.87617","0.02841"
"70.82400","5.90218","0.02829"
"71.13600","5.92813","0.02850"
"71.44800","5.95414","0.02681"
"71.76000","5.98021","0.02788"
"72.07200","6.00622","0.02741"
"72.38400","6.03217","0.02809"
"72.69600","6.05823","0.02808"
"73.00800","6.08418","0.02866"
"73.32000","6.11019","0.02783"
"73.63200","6.13620","0.02764"
"73.94400","6.16221","0.02818"
"74.25600","6.18822","0.02808"
"74.56800","6.21417","0.02761"
"74.88000","6.24023","0.02788"
"75.19200","6.26612","0.02810"
"75.50400","6.29225","0.02723"
"75.81600","6.31814","0.02814"
"76.12800","6.34415","0.02817"
"76.44000","6.37022","0.02824"
"76.75200","6.39610","0.02860"
"77.06400","6.42223","0.02914"
"77.37600","6.44818","0.02839"
"77.68800","6.47425","0.02893"
"78.00000","6.50020","0.02906"
"78.31200","6.52621","0.02962"
"78.62400","6.55222","0.02931"
"78.93600","6.57816","0.02942"
"79.24800","6.60417","0.03005"
"79.56000","6.63018","0.02977"
"79.87200","6.65619","0.03017"
"80.18400","6.68220","0.03002"
"80.49600","6.70815","0.03042"
"80.80800","6.73421","0.03028"
"81.12000","6.76010","0.03060"
"81.43200","6.78623","0.03058"
"81.74400","6.81224","0.03095"
"82.05600","6.83819","0.03091"
"82.36800","6.86420","0.03156"
"82.68000","6.89015","0.03133"
"82.99200","6.91621","0.03155"
"83.30400","6.94216","0.03172"
"83.61600","6.96817","0.03213"
"83.92800","6.99412","0.03200"
"84.24000","7.02019","0.03230"
"84.55200","7.04626","0.03259"
"84.86400","7.07214","0.03264"
"85.17600","7.09821","0.03270"
"85.48800","7.12416","0.03276"
"85.80000","7.15023","0.03320"
"86.11200","7.17624","0.00084"
"86.42400","7.20219","0.00444"
"86.73600","7.22820","0.00362"
"87.04800","7.25415","0.00308"
"87.36000","7.28015","0.00355"
"87.67200","7.30622","0.00409"
"87.98400","7.33223","0.00226"
"88.29600","7.35824","0.00224"
"88.60800","7.38413","0.00267"
"88.92000","7.41020","0.00231"
"89.23200","7.43614","0.00228"
"89.54400","7.46215","0.00178"
"89.85600","7.48822","0.00232"
"90.16800","7.51417","0.00223"
"90.48000","7.54018","0.00181"
"90.79200","7.56613","0.00321"
"91.10400","7.59225","0.00251"
"91.41600","7.61820","0.00253"
"91.72800","7.64421","0.00239"
"92.04000","7.67022","0.00263"
"92.35200","7.69617","0.00275"
"92.66400","7.72218","0.00305"
"92.97600","7.74813","0.00322"
"93.28800","7.77419","0.00357"
"93.60000","7.80020","0.00340"
"93.91200","7.82615","0.00325"
"94.22400","7.85216","0.00371"
"94.53600","7.87817","0.00360"
"94.84800","7.90424","0.00366"
"95.16000","7.93018","0.00385"
"95.47200","7.95619","0.00408"
"95.78400","7.98220","0.00387"
"96.09600","8.00815","0.00430"
"96.40800","8.03416","0.00397"
"96.72000","8.06017","0.00444"
"97.03200","8.08618","0.00428"
"97.34400","8.11212","0.00443"
"97.65600","8.13807","0.00441"
"97.96800","8.16420","0.00456"
"98.28000","8.19015","0.00451"
"98.59200","8.21616","0.00502"
"98.90400","8.24211","0.00495"
"99.21600","8.26818","0.00487"
"99.52800","8.29418","0.00507"
"99.84000","8.32013","0.00451"
"100.15200","8.34626","0.00401"
"100.46400","8.37221","0.00421"
"100.77600","8.39828","0.00463"
"101.08800","8.42417","0.00454"
"101.40000","8.45017","0.00475"
"101.71200","8.47618","0.00456"
"102.02400","8.50213","0.00470"
"102.33600","8.52820","0.00501"
"102.64800","8.55415","0.00455"
"102.96000","8.58022","0.00459"
"103.27200","8.60616","0.00506"
"103.58400","8.63217","0.00485"
"103.89600","8.65824","0.00545"
"104.20800","8.68419","0.00203"
"104.52000","8.71020","0.00041"
"104.83200","8.73615","0.00110"
"105.14400","8.76216","0.00103"
"105.45600","8.78822","0.00219"
"105.76800","8.81417","0.00170"
"106.08000","8.84024","0.00172"
"106.39200","8.86613","0.00206"
"106.70400","8.89220","0.00150"
"107.01600","8.91821","0.00172"
"107.32800","8.94421","0.00142"
"107.64000","8.97028","0.00217"
"107.95200","8.99611","0.00232"
"108.26400","9.02218","0.00176"
"108.57600","9.04813","0.00189"
"108.88800","9.07420","0.00134"
"109.20000","9.10021","0.00185"
"109.51200","9.12621","0.00183"
"109.82400","9.15222","0.00305"
"110.13600","9.17817","0.00269"
"110.44800","9.20424","0.00187"
"110.76000","9.23013","0.00185"
"111.07200","9.25626","0.00199"
"111.38400","9.28221","0.00136"
"111.69600","9.30815","0.00100"
"112.00800","9.33416","0.00121"
"112.32000","9.36011","0.00250"
"112.63200","9.38618","0.00255"
"112.94400","9.41219","0.00219"
"113.25600","9.43820","0.00239"
"113.56800","9.46420","0.00237"
"113.88000","9.49021","0.00277"
"114.19200","9.51622","0.00263"
"114.50400","9.54217","0.00318"
"114.81600","9.56824","0.00262"
"115.12800","9.59419","0.00263"
"115.44000","9.62020","0.00286"
"115.75200","9.64620","0.00291"
"116.06400","9.67215","0.00320"
"116.37600","9.69822","0.00210"
"116.68800","9.72423","0.00318"
"117.00000","9.75024","0.00297"
"117.31200","9.77619","0.00265"
"117.62400","9.80213","0.00319"
"117.93600","9.82820","0.00334"
"118.24800","9.85415","0.00333"
"118.56000","9.88028","0.00300"
"118.87200","9.90611","0.00338"
"119.18400","9.93218","0.00311"
"119.49600","9.95825","0.00287"
"119.80800","9.98419","0.00273"
"120.12000","10.01026","0.00260"
"120.43200","10.03621","0.00304"
"120.74400","10.06222","0.00346"
"121.05600","10.08817","0.00348"
"121.36800","10.11418","0.00394"
"121.68000","10.14024","0.00361"
"121.99200","10.16613","0.00240"
"122.30400","10.19220","0.00326"
"122.61600","10.21815","0.00415"
"122.92800","10.24416","0.00350"
"123.24000","10.27017","0.00400"
"123.55200","10.29618","0.00291"
"123.86400","10.32224","0.00380"
"124.17600","10.34813","0.00262"
"124.48800","10.37420","0.00289"
"124.80000","10.40015","0.00323"
"125.11200","10.42616","0.00295"
"125.42400","10.45223","0.00304"
"125.73600","10.47812","0.00319"
"126.04800","10.50418","0.00361"
"126.36000","10.53007","0.00385"
"126.67200","10.55614","0.00373"
"126.98400","10.58215","0.00425"
"127.29600","10.60816","0.00440"
"127.60800","10.63417","0.00462"
"127.92000","10.66011","0.00445"
"128.23200","10.68618","0.00396"
"128.54400","10.71213","0.00413"
"128.85600","10.73820","0.00481"
"129.16800","10.76427","0.00454"
"129.48000","10.79016","0.00468"
"129.79200","10.81617","0.00464"
"130.10400","10.84211","0.00489"
"130.41600","10.86818","0.00475"
"130.72800","10.89419","0.00487"
"131.04000","10.92020","0.00481"
"131.35200","10.94627","0.00520"
"131.66400","10.97210","0.00529"
"131.97600","10.99817","0.00496"
"132.28800","11.02417","0.00523"
"132.60000","11.05024","0.00518"
"132.91200","11.07619","0.00482"
"133.22400","11.10214","0.00599"
"133.53600","11.12821","0.00577"
"133.84800","11.15410","0.00574"
"134.16000","11.18022","0.00552"
"134.47200","11.20623","0.00628"
"134.78400","11.23218","0.00628"
"135.09600","11.25825","0.00474"
"135.40800","11.28420","0.00453"
"135.72000","11.31021","0.00463"
"136.03200","11.33615","0.00394"
"136.34400","11.36222","0.00425"
"136.65600","11.38823","0.00410"
"136.96800","11.41418","0.00467"
"137.28000","11.44019","0.00475"
"137.59200","11.46614","0.00459"
"137.90400","11.49221","0.00543"
"138.21600","11.51816","0.00529"
"138.52800","11.54416","0.00516"
"138.84000","11.57023","0.00552"
"139.15200","11.59618","0.00503"
"139.46400","11.62219","0.00557"
"139.77600","11.64820","0.00497"
"140.08800","11.67420","0.00561"
"140.40000","11.70015","0.00536"
"140.71200","11.72610","0.00510"
"141.02400","11.75217","0.00538"
"141.33600","11.77818","0.00502"
"141.64800","11.80425","0.00486"
"141.96000","11.83014","0.00517"
"142.27200","11.85620","0.00456"
"142.58400","11.88221","0.00475"
"142.89600","11.90816","0.00525"
"143.20800","11.93423","0.00525"
"143.52000","11.96018","0.00526"
"143.83200","11.98625","0.00590"
"144.14400","12.01219","0.00597"
"144.45600","12.03814","0.00535"
"144.76800","12.06415","0.00566"
"145.08000","12.09016","0.00554"
"145.39200","12.11623","0.00589"
"145.70400","12.14218","0.00544"
"146.01600","12.16819","0.00550"
"146.32800","12.19420","0.00586"
"146.64000","12.22020","0.00474"
"146.95200","12.24627","0.00432"
"147.26400","12.27222","0.00443"
"147.57600","12.29817","0.00445"
"147.88800","12.32418","0.00479"
"148.20000","12.35018","0.00486"
"148.51200","12.37619","0.00461"
"148.82400","12.40214","0.00459"
"149.13600","12.42821","0.00489"
"149.44800","12.45416","0.00532"
"149.76000","12.48023","0.00538"
"150.07200","12.50624","0.00470"
"150.38400","12.53218","0.00502"
"150.69600","12.55825","0.00507"
"151.00800","12.58414","0.00489"
"151.32000","12.61021","0.00480"
"151.63200","12.63616","0.00482"
"151.94400","12.66223","0.00526"
"152.25600","12.68818","0.00532"
"152.56800","12.71418","0.00542"
"152.88000","12.74019","0.00510"
"153.19200","12.76614","0.00466"
"153.50400","12.79215","0.00433"
"153.81600","12.81816","0.00469"
"154.12800","12.84423","0.00419"
"154.44000","12.87017","0.00454"
"154.75200","12.89612","0.00505"
"155.06400","12.92213","0.00489"
"155.37600","12.94808","0.00526"
"155.68800","12.97421","0.00586"
"156.00000","13.00016","0.00513"
"156.31200","13.02617","0.00466"
"156.62400","13.05223","0.00501"
"156.93600","13.07818","0.00542"
"157.24800","13.10419","0.00496"
"157.56000","13.13014","0.00497"
"157.87200","13.15621","0.00491"
"158.18400","13.18216","0.00516"
"158.49600","13.20817","0.00438"
"158.80800","13.23417","0.00498"
"159.12000","13.26012","0.00473"
"159.43200","13.28619","0.00529"
"159.74400","13.31220","0.00463"
"160.05600","13.33821","0.00563"
"160.36800","13.36416","0.00533"
"160.68000","13.39011","0.00527"
"160.99200","13.41623","0.00522"
"161.30400","13.44218","0.00541"
"161.61600","13.46819","0.00477"
"161.92800","13.49414","0.00575"
"162.24000","13.52015","0.00525"
"162.55200","13.54616","0.00495"
"162.86400","13.57216","0.00509"
"163.17600","13.59823","0.00493"
"163.48800","13.62418","0.00493"
"163.80000","13.65019","0.00476"
"164.11200","13.67620","0.00448"
"164.42400","13.70215","0.00494"
"164.73600","13.72822","0.00449"
"165.04800","13.75422","0.00474"
"165.36000","13.78023","0.00491"
"165.67200","13.80612","0.00480"
"165.98400","13.83219","0.00439"
"166.29600","13.85820","0.00512"
"166.60800","13.88415","0.00549"
"166.92000","13.91022","0.00478"
"167.23200","13.93616","0.00472"
"167.54400","13.96223","0.00471"
"167.85600","13.98818","0.00510"
"168.16800","14.01419","0.00542"
"168.48000","14.04026","0.00591"
"168.79200","14.06615","0.00503"
"169.10400","14.09221","0.00586"
"169.41600","14.11810","0.00609"
"169.72800","14.14417","0.00601"
"170.04000","14.17018","0.00610"
"170.35200","14.19613","0.00589"
"170.66400","14.22220","0.00606"
"170.97600","14.24815","0.00623"
"171.28800","14.27421","0.00582"
"171.60000","14.30016","0.00642"
"171.91200","14.32623","0.00601"
"172.22400","14.35224","0.00641"
"172.53600","14.37819","0.00655"
"172.84800","14.40420","0.00679"
"173.16000","14.43008","0.00626"
"173.47200","14.45615","0.00621"
"173.78400","14.48222","0.00466"
"174.09600","14.50817","0.00522"
"174.40800","14.53418","0.00514"
"174.72000","14.56013","0.00517"
"175.03200","14.58619","0.00545"
"175.34400","14.61220","0.00559"
"175.65600","14.63821","0.00616"
"175.96800","14.66422","0.00587"
"176.28000","14.69017","0.00559"
"176.59200","14.71618","0.00558"
"176.90400","14.74213","0.00598"
"177.21600","14.76820","0.00627"
"177.52800","14.79420","0.00579"
"177.84000","14.82021","0.00576"
"178.15200","14.84622","0.00552"
"178.46400","14.87217","0.00649"
"178.77600","14.89824","0.00575"
"179.08800","14.92413","0.00550"
"179.40000","14.95025","0.00507"
"179.71200","14.97620","0.00571"
"180.02400","15.00215","0.00553"
"180.33600","15.02816","0.00558"
"180.64800","15.05411","0.00587"
"180.96000","15.08024","0.00570"
"181.27200","15.10618","0.00585"
"181.58400","15.13219","0.00551"
"181.89600","15.15820","0.00607"
"182.20800","15.18421","0.00548"
"182.52000","15.21022","0.00556"
"182.83200","15.23617","0.00551"
"183.14400","15.26218","0.00608"
"183.45600","15.28813","0.00542"
"183.76800","15.31419","0.00541"
"184.08000","15.34020","0.00606"
"184.39200","15.36615","0.00572"
"184.70400","15.39222","0.00594"
"185.01600","15.41817","0.00625"
"185.32800","15.44417","0.00637"
"185.64000","15.47018","0.00630"
"185.95200","15.49613","0.00703"
"186.26400","15.52220","0.00654"
"186.57600","15.54809","0.00618"
"186.88800","15.57422","0.00638"
"187.20000","15.60011","0.00622"
"187.51200","15.62617","0.00675"
"187.82400","15.65218","0.00612"
"188.13600","15.67819","0.00587"
"188.44800","15.70420","0.00643"
"188.76000","15.73015","0.00599"
"189.07200","15.75622","0.00652"
"189.38400","15.78216","0.00684"
"189.69600","15.80817","0.00708"
"190.00800","15.83424","0.00747"
"190.32000","15.86019","0.00726"
"190.63200","15.88620","0.00684"
"190.94400","15.91215","0.00762"
"191.25600","15.93816","0.00725"
"191.56800","15.96416","0.00727"
"191.88000","15.99011","0.00740"
"192.19200","16.01618","0.00793"
"192.50400","16.04213","0.00688"
"192.81600","16.06820","0.00683"
"193.12800","16.09421","0.00747"
"193.44000","16.12021","0.00689"
"193.75200","16.14628","0.00647"
"194.06400","16.17211","0.00596"
"194.37600","16.19818","0.00634"
"194.68800","16.22413","0.00651"
"195.00000","16.25020","0.00672"
"195.31200","16.27621","0.00716"
"195.62400","16.30215","0.00673"
"195.93600","16.32822","0.00623"
"196.24800","16.35411","0.00672"
"196.56000","16.38018","0.00662"
"196.87200","16.40613","0.00721"
"197.18400","16.43225","0.00680"
"197.49600","16.45820","0.00719"
"197.80800","16.48415","0.00663"
"198.12000","16.51016","0.00676"
"198.43200","16.53605","0.00709"
"198.74400","16.56218","0.00667"
"199.05600","16.58813","0.00717"
"199.36800","16.61414","0.00704"
"199.68000","16.64026","0.00696"
"199.99200","16.66615","0.00727"
"200.30400","16.69216","0.00736"
"200.61600","16.71823","0.00658"
"200.92800","16.74424","0.00644"
"201.24000","16.77019","0.00642"
"201.55200","16.79613","0.00736"
"201.86400","16.82214","0.00642"
"202.17600","16.84815","0.00739"
"202.48800","16.87422","0.00637"
"202.80000","16.90017","0.00705"
"203.11200","16.92624","0.00737"
"203.42400","16.95219","0.00700"
"203.73600","16.97814","0.00710"
"204.04800","17.00426","0.00776"
"204.36000","17.03021","0.00705"
"204.67200","17.05622","0.00786"
"204.98400","17.08211","0.00789"
"205.29600","17.10812","0.00834"
"205.60800","17.13419","0.00794"
"205.92000","17.16019","0.00707"
"206.23200","17.18626","0.00757"
"206.54400","17.21215","0.00712"
"206.85600","17.23822","0.00788"
"207.16800","17.26423","0.00766"
"207.48000","17.29018","0.00688"
"207.79200","17.31624","0.00680"
"208.10400","17.34219","0.00745"
"208.41600","17.36820","0.00764"
"208.72800","17.39415","0.00776"
"209.04000","17.42016","0.00670"
"209.35200","17.44623","0.00716"
"209.66400","17.47218","0.00751"
"209.97600","17.49818","0.00729"
"210.28800","17.52413","0.00754"
"210.60000","17.55020","0.00731"
"210.91200","17.57621","0.00663"
"211.22400","17.60216","0.00647"
"211.53600","17.62823","0.00655"
"211.84800","17.65412","0.00718"
"212.16000","17.68018","0.00692"
"212.47200","17.70613","0.00713"
"212.78400","17.73220","0.00734"
"213.09600","17.75821","0.00677"
"213.40800","17.78416","0.00677"
"213.72000","17.81023","0.00711"
"214.03200","17.83611","0.00561"
"214.34400","17.86218","0.00600"
"214.65600","17.88819","0.00538"
"214.96800","17.91420","0.00629"
"215.28000","17.94021","0.00641"
"215.59200","17.96616","0.00596"
"215.90400","17.99222","0.00592"
"216.21600","18.01817","0.00654"
"216.52800","18.04418","0.00601"
"216.84000","18.07019","0.00625"
"217.15200","18.09620","0.00633"
"217.46400","18.12215","0.00659"
"217.77600","18.14810","0.00734"
"218.08800","18.17416","0.00636"
"218.40000","18.20017","0.00671"
"218.71200","18.22624","0.00688"
"219.02400","18.25225","0.00701"
"219.33600","18.27814","0.00632"
"219.64800","18.30415","0.00703"
"219.96000","18.33010","0.00717"
"220.27200","18.35622","0.00687"
"220.58400","18.38223","0.00706"
"220.89600","18.40818","0.00688"
"221.20800","18.43425","0.00711"
"221.52000","18.46014","0.00793"
"221.83200","18.48621","0.00722"
"222.14400","18.51221","0.00795"
"222.45600","18.53822","0.00754"
"222.76800","18.56417","0.00766"
"223.08000","18.59018","0.00804"
"223.39200","18.61619","0.00817"
"223.70400","18.64214","0.00817"
"224.01600","18.66821","0.00850"
"224.32800","18.69415","0.00689"
"224.64000","18.72016","0.00619"
"224.95200","18.74617","0.00604"
"225.26400","18.77218","0.00634"
"225.57600","18.79825","0.00573"
"225.88800","18.82420","0.00574"
"226.20000","18.85021","0.00504"
"226.51200","18.87615","0.00527"
"226.82400","18.90216","0.00535"
"227.13600","18.92817","0.00562"
"227.44800","18.95412","0.00575"
"227.76000","18.98013","0.00591"
"228.07200","19.00614","0.00672"
"228.38400","19.03220","0.00597"
"228.69600","19.05821","0.00648"
"229.00800","19.08410","0.00626"
"229.32000","19.11023","0.00340"
"229.63200","19.13612","0.00304"
"229.94400","19.16219","0.00309"
"230.25600","19.18814","0.00281"
"230.56800","19.21414","0.00340"
"230.88000","19.24021","0.00340"
"231.19200","19.26616","0.00369"
"231.50400","19.29223","0.00391"
"231.81600","19.31818","0.00386"
"232.12800","19.34419","0.00362"
"232.44000","19.37020","0.00358"
"232.75200","19.39620","0.00349"
"233.06400","19.42227","0.00389"
"233.37600","19.44816","0.00338"
"233.68800","19.47417","0.00396"
"234.00000","19.50012","0.00349"
"234.31200","19.52619","0.00350"
"234.62400","19.55225","0.00363"
"234.93600","19.57820","0.00392"
"235.24800","19.60421","0.00406"
"235.56000","19.63016","0.00412"
"235.87200","19.65623","0.00437"
"236.18400","19.68218","0.00469"
"236.49600","19.70819","0.00499"
"236.80800","19.73425","0.00416"
"237.12000","19.76014","0.00377"
"237.43200","19.78615","0.00471"
"237.74400","19.81210","0.00429"
"238.05600","19.83822","0.00459"
"238.36800","19.86423","0.00445"
"238.68000","19.89018","0.00493"
"238.99200","19.91625","0.00440"
"239.30400","19.94214","0.00427"
"239.61600","19.96821","0.00459"
"239.92800","19.99416","0.00426"
"240.24000","20.02022","0.00432"
"240.55200","20.04618","0.00517"
"240.86400","20.07218","0.00481"
"241.17600","20.09819","0.00472"
"241.48800","20.12408","0.00473"
"241.80000","20.15021","0.00493"
"242.11200","20.17616","0.00476"
"242.42400","20.20217","0.00482"
"242.73600","20.22824","0.00428"
"243.04800","20.25418","0.00490"
"243.36000","20.28019","0.00457"
"243.67200","20.30620","0.00503"
"243.98400","20.33221","0.00464"
"244.29600","20.35822","0.00525"
"244.60800","20.38416","0.00419"
"244.92000","20.41018","0.00463"
"245.23200","20.43612","0.00566"
"245.54400","20.46219","0.00477"
"245.85600","20.48820","0.00518"
"246.16800","20.51415","0.00560"
"246.48000","20.54022","0.00524"
"246.79200","20.56617","0.00494"
"247.10400","20.59223","0.00561"
"247.41600","20.61818","0.00570"
"247.72800","20.64425","0.00546"
"248.04000","20.67014","0.00482"
"248.35200","20.69615","0.00560"
"248.66400","20.72222","0.00548"
"248.97600","20.74817","0.00539"
"249.28800","20.77423","0.00529"
"249.60000","20.80018","0.00540"
"249.91200","20.82619","0.00536"
"250.22400","20.85220","0.00567"
"250.53600","20.87815","0.00581"
"250.84800","20.90421","0.00555"
"251.16000","20.93016","0.00624"
"251.47200","20.95623","0.00586"
"251.78400","20.98218","0.00699"
"252.09600","21.00813","0.00588"
"252.40800","21.03420","0.00759"
"252.72000","21.06015","0.00609"
"253.03200","21.08615","0.00564"
"253.34400","21.11210","0.00376"
"253.65600","21.13817","0.00385"
"253.96800","21.16418","0.00383"
"254.28000","21.19019","0.00361"
"254.59200","21.21620","0.00363"
"254.90400","21.24215","0.00447"
"255.21600","21.26821","0.00429"
"255.52800","21.29410","0.00360"
"255.84000","21.32017","0.00468"
"256.15200","21.34618","0.00431"
"256.46400","21.37213","0.00398"
"256.77600","21.39820","-0.00131"
"257.08800","21.42409","-0.00116"
"257.40000","21.45021","-0.00590"
"257.71200","21.47616","-0.00448"
"258.02400","21.50223","-0.00442"
"258.33600","21.52824","-0.00366"
"258.64800","21.55419","-0.00477"
"258.96000","21.58019","-0.00383"
"259.27200","21.60614","-0.00337"
"259.58400","21.63221","-0.00479"
"259.89600","21.65822","-0.00425"
"260.20800","21.68417","-0.00387"
"260.52000","21.71024","-0.00457"
"260.83200","21.73613","-0.00421"
"261.14400","21.76219","-0.00280"
"261.45600","21.78820","-0.00432"
"261.76800","21.81421","-0.00448"
"262.08000","21.84022","-0.00288"
"262.39200","21.86611","-0.00407"
"262.70400","21.89218","-0.00421"
"263.01600","21.91813","-0.00355"
"263.32800","21.94425","-0.00359"
"263.64000","21.97020","-0.00338"
"263.95200","21.99621","-0.00294"
"264.26400","22.02228","-0.00368"
"264.57600","22.04817","-0.00330"
"264.88800","22.07424","-0.00272"
"265.20000","22.10018","-0.00284"
"265.51200","22.12619","-0.00244"
"265.82400","22.15220","-0.00240"
"266.13600","22.17815","-0.00281"
"266.44800","22.20422","-0.00273"
"266.76000","22.23017","-0.00225"
"267.07200","22.25624","-0.00220"
"267.38400","22.28218","-0.00249"
"267.69600","22.30819","-0.00272"
"268.00800","22.33420","-0.00235"
"268.32000","22.36015","-0.00299"
"268.63200","22.38622","-0.00232"
"268.94400","22.41217","-0.00271"
"269.25600","22.43818","-0.00155"
"269.56800","22.46418","-0.00201"
"269.88000","22.49013","-0.00195"
"270.19200","22.51620","-0.00249"
"270.50400","22.54215","-0.00190"
"270.81600","22.56816","-0.00162"
"271.12800","22.59417","-0.00200"
"271.44000","22.62017","-0.00208"
"271.75200","22.64624","-0.00170"
"272.06400","22.67213","-0.00140"
"272.37600","22.69826","-0.00113"
"272.68800","22.72415","-0.00131"
"273.00000","22.75022","-0.00092"
"273.31200","22.77617","-0.00148"
"273.62400","22.80217","-0.00081"
"273.93600","22.82824","-0.00139"
"274.24800","22.85419","-0.00114"
"274.56000","22.88020","-0.00061"
"274.87200","22.90615","-0.00093"
"275.18400","22.93222","-0.00082"
"275.49600","22.95816","-0.00091"
"275.80800","22.98417","-0.00109"
"276.12000","23.01024","-0.00116"
"276.43200","23.03613","-0.00026"
"276.74400","23.06220","-0.00078"
"277.05600","23.08821","-0.00058"
"277.36800","23.11422","-0.00039"
"277.68000","23.14022","-0.00050"
"277.99200","23.16617","-0.00106"
"278.30400","23.19218","-0.00055"
"278.61600","23.21813","-0.00048"
"278.92800","23.24420","-0.00035"
"279.24000","23.27020","-0.00016"
"279.55200","23.29622","-0.00043"
"279.86400","23.32222","-0.00025"
"280.17600","23.34811","-0.00022"
"280.48800","23.37418","-0.00023"
"280.80000","23.40013","-0.00026"
"281.11200","23.42620","-0.00045"
"281.42400","23.45220","-0.00019"
"281.73600","23.47815","-0.00007"
"282.04800","23.50416","0.00007"
"282.36000","23.53011","-0.00061"
"282.67200","23.55624","-0.00058"
"282.98400","23.58219","0.00013"
"283.29600","23.60814","-0.00039"
"283.60800","23.63420","0.00028"
"283.92000","23.66009","-0.00007"
"284.23200","23.68616","0.00011"
"284.54400","23.71211","0.00058"
"284.85600","23.73818","-0.00020"
"285.16800","23.76413","-0.00034"
"285.48000","23.79013","-0.00079"
"285.79200","23.81621","-0.00094"
"286.10400","23.84209","-0.00091"
"286.41600","23.86816","-0.00153"
"286.72800","23.89417","-0.00135"
"287.04000","23.92018","-0.00136"
"287.35200","23.94618","-0.00154"
"287.66400","23.97213","-0.00169"
"287.97600","23.99821","-0.00090"
"288.28800","24.02415","-0.00117"
"288.60000","24.05022","-0.00154"
"288.91200","24.07617","-0.00175"
"289.22400","24.10218","-0.00165"
"289.53600","24.12819","-0.00140"
"289.84800","24.15413","-0.00134"
"290.16000","24.18026","-0.00091"
"290.47200","24.20621","-0.00058"
"290.78400","24.23222","-0.00121"
"291.09600","24.25817","-0.00098"
"291.40800","24.28411","-0.00074"
"291.72000","24.31025","-0.00053"
"292.03200","24.33619","-0.00115"
"292.34400","24.36220","-0.00155"
"292.65600","24.38821","-0.00047"
"292.96800","24.41416","-0.00162"
"293.28000","24.44017","-0.00157"
"293.59200","24.46618","-0.00119"
"293.90400","24.49218","-0.00128"
"294.21600","24.51819","-0.00060"
"294.52800","24.54420","-0.00135"
"294.84000","24.57021","-0.00121"
"295.15200","24.59616","-0.00090"
"295.46400","24.62223","-0.00084"
"295.77600","24.64818","-0.00119"
"296.08800","24.67418","-0.00103"
"296.40000","24.70019","-0.00036"
"296.71200","24.72620","-0.00193"
"297.02400","24.75221","-0.00202"
"297.33600","24.77816","-0.00041"
"297.64800","24.80423","-0.00192"
"297.96000","24.83011","-0.00130"
"298.27200","24.85618","-0.00214"
"298.58400","24.88219","-0.00171"
"298.89600","24.90820","-0.00177"
"299.20800","24.93427","-0.00217"
"299.52000","24.96010","-0.00125"
"299.83200","24.98623","-0.00169"
"300.14400","25.01217","-0.00193"
"300.45600","25.03824","-0.00124"
"300.76800","25.06419","-0.00204"
"301.08000","25.09020","-0.00146"
"301.39200","25.11627","-0.00111"
"301.70400","25.14215","-0.00150"
"302.01600","25.16816","-0.00138"
"302.32800","25.19417","-0.00207"
"302.64000","25.22024","-0.00092"
"302.95200","25.24619","-0.00213"
"303.26400","25.27220","-0.00179"
"303.57600","25.29821","-0.00149"
"303.88800","25.32409","-0.00146"
"304.20000","25.35016","-0.00171"
"304.51200","25.37617","-0.00121"
"304.82400","25.40218","-0.00118"
"305.13600","25.42819","-0.00152"
"305.44800","25.45414","-0.00099"
"305.76000","25.48021","-0.00315"
"306.07200","25.50615","-0.00478"
"306.38400","25.53222","-0.00324"
"306.69600","25.55823","-0.00434"
"307.00800","25.58418","-0.00365"
"307.32000","25.61025","-0.00396"
"307.63200","25.63614","-0.00420"
"307.94400","25.66220","-0.00453"
"308.25600","25.68815","-0.00400"
"308.56800","25.71422","-0.00408"
"308.88000","25.74023","-0.00417"
"309.19200","25.76618","-0.00440"
"309.50400","25.79219","-0.00423"
"309.81600","25.81820","-0.00369"
"310.12800","25.84427","-0.00402"
"310.44000","25.87016","-0.00398"
"310.75200","25.89616","-0.00470"
"311.06400","25.92217","-0.00413"
"311.37600","25.94818","-0.00449"
"311.68800","25.97419","-0.00420"
"312.00000","26.00020","-0.00482"
"312.31200","26.02621","-0.00455"
"312.62400","26.05215","-0.00402"
"312.93600","26.07816","-0.00461"
"313.24800","26.10423","-0.00418"
"313.56000","26.13012","-0.00440"
"313.87200","26.15619","-0.00404"
"314.18400","26.18214","-0.00433"
"314.49600","26.20814","-0.00465"
"314.80800","26.23421","-0.00417"
"315.12000","26.26016","-0.00435"
"315.43200","26.28617","-0.00418"
"315.74400","26.31212","-0.00402"
"316.05600","26.33819","-0.00387"
"316.36800","26.36414","-0.00430"
"316.68000","26.39020","-0.00350"
"316.99200","26.41621","-0.00324"
"317.30400","26.44216","-0.00407"
"317.61600","26.46823","-0.00394"
"317.92800","26.49412","-0.00386"
"318.24000","26.52019","-0.00413"
"318.55200","26.54613","-0.00500"
"318.86400","26.57220","-0.00476"
"319.17600","26.59827","-0.00430"
"319.48800","26.62416","-0.00436"
"319.80000","26.65017","-0.00392"
"320.11200","26.67612","-0.00404"
"320.42400","26.70218","-0.00407"
"320.73600","26.72825","-0.00486"
"321.04800","26.75414","-0.00363"
"321.36000","26.78021","-0.00450"
"321.67200","26.80616","-0.00357"
"321.98400","26.83217","-0.00456"
"322.29600","26.85823","-0.00429"
"322.60800","26.88418","-0.00439"
"322.92000","26.91025","-0.00375"
"323.23200","26.93614","-0.00443"
"323.54400","26.96221","-0.00424"
"323.85600","26.98816","-0.00432"
"324.16800","27.01423","-0.00419"
"324.48000","27.04023","-0.00428"
"324.79200","27.06618","-0.00447"
"325.10400","27.09219","-0.00413"
"325.41600","27.11808","-0.00354"
"325.72800","27.14421","-0.00386"
"326.04000","27.17022","-0.00455"
"326.35200","27.19617","-0.00447"
"326.66400","27.22218","-0.00438"
"326.97600","27.24812","-0.00370"
"327.28800","27.27419","-0.00469"
"327.60000","27.30014","-0.00405"
"327.91200","27.32627","-0.00458"
"328.22400","27.35216","-0.00409"
"328.53600","27.37816","-0.00388"
"328.84800","27.40423","-0.00367"
"329.16000","27.43018","-0.00406"
"329.47200","27.45619","-0.00366"
"329.78400","27.48220","-0.00427"
"330.09600","27.50821","-0.00410"
"330.40800","27.53422","-0.00383"
"330.72000","27.56016","-0.00433"
"331.03200","27.58618","-0.00410"
"331.34400","27.61218","-0.00393"
"331.65600","27.63819","-0.00410"
"331.96800","27.66420","-0.00344"
"332.28000","27.69021","-0.00382"
"332.59200","27.71622","-0.00376"
"332.90400","27.74216","-0.00458"
"333.21600","27.76823","-0.00428"
"333.52800","27.79418","-0.00420"
"333.84000","27.82019","-0.00358"
"334.15200","27.84614","-0.00390"
"334.46400","27.87215","-0.00360"
"334.77600","27.89827","-0.00366"
"335.08800","27.92416","-0.00394"
"335.40000","27.95023","-0.00373"
"335.71200","27.97618","-0.00355"
"336.02400","28.00219","-0.00376"
"336.33600","28.02820","-0.00363"
"336.64800","28.05415","-0.00331"
"336.96000","28.08021","-0.00352"
"337.27200","28.10616","-0.00414"
"337.58400","28.13223","-0.00405"
"337.89600","28.15818","-0.00320"
"338.20800","28.18419","-0.00379"
"338.52000","28.21026","-0.00350"
"338.83200","28.23621","-0.00413"
"339.14400","28.26221","-0.00333"
"339.45600","28.28816","-0.00309"
"339.76800","28.31417","-0.00295"
"340.08000","28.34024","-0.00343"
"340.39200","28.36613","-0.00368"
"340.70400","28.39220","-0.00383"
"341.01600","28.41814","-0.00341"
"341.32800","28.44421","-0.00339"
"341.64000","28.47016","-0.00314"
"341.95200","28.49617","-0.00329"
"342.26400","28.52224","-0.00356"
"342.57600","28.54807","-0.00371"
"342.88800","28.57420","-0.00350"
"343.20000","28.60009","-0.00310"
"343.51200","28.62621","-0.00365"
"343.82400","28.65216","-0.00426"
"344.13600","28.67817","-0.00333"
"344.44800","28.70418","-0.00331"
"344.76000","28.73013","-0.00342"
"345.07200","28.75613","-0.00392"
"345.38400","28.78214","-0.00342"
"345.69600","28.80821","-0.00386"
"346.00800","28.83422","-0.00356"
"346.32000","28.86017","-0.00342"
"346.63200","28.88618","-0.00374"
"346.94400","28.91207","-0.00312"
"347.25600","28.93819","-0.00305"
"347.56800","28.96420","-0.00286"
"347.88000","28.99021","-0.00316"
"348.19200","29.01622","-0.00323"
"348.50400","29.04211","-0.00364"
"348.81600","29.06818","-0.00375"
"349.12800","29.09413","-0.00323"
"349.44000","29.12019","-0.00333"
"349.75200","29.14620","-0.00364"
"350.06400","29.17215","-0.00307"
"350.37600","29.19822","-0.00297"
"350.68800","29.22417","-0.00317"
"351.00000","29.25023","-0.00279"
"351.31200","29.27618","-0.00282"
"351.62400","29.30219","-0.00318"
"351.93600","29.32820","-0.00326"
"352.24800","29.35415","-0.00263"
"352.56000","29.38022","-0.00257"
"352.87200","29.40617","-0.00344"
"353.18400","29.43224","-0.00331"
"353.49600","29.45818","-0.00284"
"353.80800","29.48413","-0.00285"
"354.12000","29.51020","-0.00244"
"354.43200","29.53621","-0.00368"
"354.74400","29.56222","-0.00254"
"355.05600","29.58817","-0.00242"
"355.36800","29.61418","-0.00271"
"355.68000","29.64012","-0.00293"
"355.99200","29.66613","-0.00321"
"356.30400","29.69226","-0.00326"
"356.61600","29.71809","-0.00297"
"356.92800","29.74422","-0.00299"
"357.24000","29.77017","-0.00306"
"357.55200","29.79618","-0.00280"
"357.86400","29.82218","-0.00239"
"358.17600","29.84819","-0.00298"
"358.48800","29.87426","-0.00254"
"358.80000","29.90015","-0.00260"
"359.11200","29.92622","-0.00247"
"359.42400","29.95217","-0.00264"
"359.73600","29.97817","-0.00228"
"360.04800","30.00424","-0.00287"
"360.36000","30.03019","-0.00247"
"360.67200","30.05626","-0.00218"
"360.98400","30.08221","-0.00284"
"361.29600","30.10822","-0.00253"
"361.60800","30.13416","-0.00296"
"361.92000","30.16017","-0.00209"
"362.23200","30.18624","-0.00284"
"362.54400","30.21213","-0.00274"
"362.85600","30.23820","-0.00242"
"363.16800","30.26415","-0.00237"
"363.48000","30.29021","-0.00258"
"363.79200","30.31628","-0.00267"
"364.10400","30.34217","-0.00274"
"364.41600","30.36818","-0.00248"
"364.72800","30.39413","-0.00234"
"365.04000","30.42020","-0.00270"
"365.35200","30.44621","-0.00265"
"365.66400","30.47221","-0.00255"
"365.97600","30.49822","-0.00291"
"366.28800","30.52411","-0.00231"
"366.60000","30.55018","-0.00246"
"366.91200","30.57619","-0.00264"
"367.22400","30.60220","-0.00236"
"367.53600","30.62827","-0.00321"
"367.84800","30.65415","-0.00301"
"368.16000","30.68016","-0.00311"
"368.47200","30.70611","-0.00304"
"368.78400","30.73224","-0.00249"
"369.09600","30.75819","-0.00202"
"369.40800","30.78420","-0.00262"
"369.72000","30.81020","-0.00278"
"370.03200","30.83615","-0.00255"
"370.34400","30.86216","-0.00246"
"370.65600","30.88817","-0.00291"
"370.96800","30.91424","-0.00261"
"371.28000","30.94013","-0.00266"
"371.59200","30.96614","-0.00322"
"371.90400","30.99221","-0.00297"
"372.21600","31.01815","-0.00250"
"372.52800","31.04416","-0.00193"
"372.84000","31.07011","-0.00248"
"373.15200","31.09618","-0.00253"
"373.46400","31.12218","-0.00280"
"373.77600","31.14814","-0.00225"
"374.08800","31.17421","-0.00253"
"374.40000","31.20015","-0.00241"
"374.71200","31.22616","-0.00220"
"375.02400","31.25217","-0.00152"
"375.33600","31.27817","-0.00254"
"375.64800","31.30418","-0.00248"
"375.96000","31.33014","-0.00224"
"376.27200","31.35620","-0.00222"
"376.58400","31.38221","-0.00246"
"376.89600","31.40822","-0.00214"
"377.20800","31.43417","-0.00171"
"377.52000","31.46018","-0.00235"
"377.83200","31.48624","-0.00214"
"378.14400","31.51213","-0.00208"
"378.45600","31.53820","-0.00242"
"378.76800","31.56415","-0.00189"
"379.08000","31.59016","-0.00134"
"379.39200","31.61623","-0.00115"
"379.70400","31.64218","-0.00207"
"380.01600","31.66818","-0.00159"
"380.32800","31.69419","-0.00165"
"380.64000","31.72020","-0.00192"
"380.95200","31.74615","-0.00230"
"381.26400","31.77210","-0.00207"
"381.57600","31.79823","-0.00144"
"381.88800","31.82417","-0.00116"
"382.20000","31.85018","-0.00143"
"382.51200","31.87613","-0.00165"
"382.82400","31.90214","-0.00124"
"383.13600","31.92821","-0.00157"
"383.44800","31.95416","-0.00197"
"383.76000","31.98022","-0.00156"
"384.07200","32.00611","-0.00161"
"384.38400","32.03218","-0.00151"
"384.69600","32.05819","-0.00126"
"385.00800","32.08420","-0.00160"
"385.32000","32.11021","-0.00201"
"385.63200","32.13610","-0.00176"
"385.94400","32.16222","-0.00135"
"386.25600","32.18811","-0.00140"
"386.56800","32.21418","-0.00121"
"386.88000","32.24019","-0.00135"
"387.19200","32.26620","-0.00172"
"387.50400","32.29214","-0.00147"
"387.81600","32.31810","-0.00026"
"388.12800","32.34416","-0.00125"
"388.44000","32.37017","-0.00101"
"388.75200","32.39618","-0.00109"
"389.06400","32.42219","-0.00142"
"389.37600","32.44820","-0.00116"
"389.68800","32.47414","-0.00186"
"390.00000","32.50010","-0.00131"
"390.31200","32.52622","-0.00080"
"390.62400","32.55217","-0.00113"
"390.93600","32.57818","-0.00126"
"391.24800","32.60419","-0.00114"
"391.56000","32.63008","-0.00078"
"391.87200","32.65614","-0.00116"
"392.18400","32.68221","-0.00076"
"392.49600","32.70823","-0.00085"
"392.80800","32.73423","-0.00160"
"393.12000","32.76018","-0.00087"
"393.43200","32.78625","-0.00088"
"393.74400","32.81214","-0.00092"
"394.05600","32.83826","-0.00083"
"394.36800","32.86421","-0.00089"
"394.68000","32.89022","-0.00105"
"394.99200","32.91623","-0.00055"
"395.30400","32.94218","-0.00060"
"395.61600","32.96825","-0.00096"
"395.92800","32.99419","-0.00122"
"396.24000","33.02021","-0.00032"
"396.55200","33.04621","-0.00105"
"396.86400","33.07216","-0.00080"
"397.17600","33.09817","-0.00069"
"397.48800","33.12418","-0.00026"
"397.80000","33.15018","-0.00082"
"398.11200","33.17614","-0.00039"
"398.42400","33.20214","-0.00113"
"398.73600","33.22821","-0.00077"
"399.04800","33.25422","-0.00054"
"399.36000","33.28023","0.00011"
"399.67200","33.30618","-0.00049"
"399.98400","33.33219","-0.00049"
"400.29600","33.35819","-0.00014"
"400.60800","33.38414","0.00021"
"400.92000","33.41021","0.00032"
"401.23200","33.43616","-0.00055"
"401.54400","33.46217","-0.00020"
"401.85600","33.48812","-0.00062"
"402.16800","33.51419","-0.00025"
"402.48000","33.54013","-0.00033"
"402.79200","33.56620","-0.00008"
"403.10400","33.59221","-0.00056"
"403.41600","33.61810","-0.00030"
"403.72800","33.64417","-0.00062"
"404.04000","33.67012","-0.00038"
"404.35200","33.69619","-0.00070"
"404.66400","33.72219","-0.00029"
"404.97600","33.74814","-0.00041"
"405.28800","33.77421","-0.00074"
"405.60000","33.80010","0.00023"
"405.91200","33.82617","0.00012"
"406.22400","33.85218","0.00015"
"406.53600","33.87825","0.00038"
"406.84800","33.90425","0.00045"
"407.16000","33.93014","-0.00011"
"407.47200","33.95621","-0.00028"
"407.78400","33.98216","-0.00012"
"408.09600","34.00817","-0.00067"
"408.40800","34.03417","0.00016"
"408.72000","34.06018","0.00052"
"409.03200","34.08619","0.00001"
"409.34400","34.11208","0.00060"
"409.65600","34.13821","-0.00022"
"409.96800","34.16416","-0.00010"
"410.28000","34.19023","0.00008"
"410.59200","34.21623","0.00047"
"410.90400","34.24212","0.00008"
"411.21600","34.26819","-0.00053"
"411.52800","34.29414","-0.00014"
"411.84000","34.32021","-0.00032"
"412.15200","34.34621","-0.00007"
"412.46400","34.37223","0.00044"
"412.77600","34.39823","0.00043"
"413.08800","34.42412","0.00053"
"413.40000","34.45019","0.00059"
"413.71200","34.47614","0.00051"
"414.02400","34.50221","-0.00011"
"414.33600","34.52816","0.00096"
"414.64800","34.55416","0.00059"
"414.96000","34.58017","0.00040"
"415.27200","34.60612","0.00040"
"415.58400","34.63219","0.00085"
"415.89600","34.65814","0.00030"
"416.20800","34.68415","0.00031"
"416.52000","34.71016","0.00062"
"416.83200","34.73610","0.00076"
"417.14400","34.76223","0.00084"
"417.45600","34.78818","0.00044"
"417.76800","34.81419","0.00113"
"418.08000","34.84019","0.00052"
"418.39200","34.86615","0.00122"
"418.70400","34.89215","0.00035"
"419.01600","34.91816","0.00086"
"419.32800","34.94423","-0.00076"
"419.64000","34.97018","0.00036"
"419.95200","34.99619","0.00075"
"420.26400","35.02214","0.00091"
"420.57600","35.04815","0.00088"
"420.88800","35.07428","0.00067"
"421.20000","35.10016","0.00077"
"421.51200","35.12623","0.00170"
"421.82400","35.15218","0.00087"
"422.13600","35.17819","0.00019"
"422.44800","35.20426","0.00129"
"422.76000","35.23021","0.00113"
"423.07200","35.25621","0.00110"
"423.38400","35.28216","0.00086"
"423.69600","35.30817","0.00093"
"424.00800","35.33418","0.00112"
"424.32000","35.36019","0.00112"
"424.63200","35.38626","0.00088"
"424.94400","35.41220","0.00113"
"425.25600","35.43821","0.00113"
"425.56800","35.46416","0.00112"
"425.88000","35.49017","0.00093"
"426.19200","35.51624","0.00140"
"426.50400","35.54219","0.00138"
"426.81600","35.56820","0.00145"
"427.12800","35.59408","0.00148"
"427.44000","35.62015","0.00161"
"427.75200","35.64622","0.00095"
"428.06400","35.67223","0.00151"
"428.37600","35.69824","0.00177"
"428.68800","35.72412","0.00185"
"429.00000","35.75026","0.00160"
"429.31200","35.77614","0.00131"
"429.62400","35.80221","0.00146"
"429.93600","35.82822","0.00162"
"430.24800","35.85417","0.00165"
"430.56000","35.88018","0.00176"
"430.87200","35.90612","0.00180"
"431.18400","35.93219","0.00218"
"431.49600","35.95820","0.00204"
"431.80800","35.98421","0.00181"
"432.12000","36.01022","0.00233"
"432.43200","36.03617","0.00195"
"432.74400","36.06218","0.00193"
"433.05600","36.08818","0.00236"
"433.36800","36.11419","0.00199"
"433.68000","36.14021","0.00234"
"433.99200","36.16621","0.00192"
"434.30400","36.19216","0.00210"
"434.61600","36.21811","0.00199"
"434.92800","36.24417","0.00280"
"435.24000","36.27018","0.00268"
"435.55200","36.29625","0.00210"
"435.86400","36.32226","0.00226"
"436.17600","36.34815","0.00254"
"436.48800","36.37422","0.00285"
"436.80000","36.40010","0.00287"
"437.11200","36.42617","0.00227"
"437.42400","36.45219","0.00247"
"437.73600","36.47819","0.00275"
"438.04800","36.50420","0.00234"
"438.36000","36.53015","0.00256"
"438.67200","36.55622","0.00243"
"438.98400","36.58216","0.00261"
"439.29600","36.60823","0.00155"
"439.60800","36.63419","0.00256"
"439.92000","36.66013","0.00218"
"440.23200","36.68620","0.00225"
"440.54400","36.71221","0.00294"
"440.85600","36.73822","0.00230"
"441.16800","36.76417","0.00289"
"441.48000","36.79012","0.00267"
"441.79200","36.81618","0.00230"
"442.10400","36.84213","0.00288"
"442.41600","36.86820","0.00318"
"442.72800","36.89415","0.00275"
"443.04000","36.92022","0.00248"
"443.35200","36.94617","0.00255"
"443.66400","36.97217","0.00306"
"443.97600","36.99824","0.00342"
"444.28800","37.02413","0.00308"
"444.60000","37.05020","0.00303"
"444.91200","37.07615","0.00243"
"445.22400","37.10221","0.00299"
"445.53600","37.12817","0.00284"
"445.84800","37.15417","0.00355"
"446.16000","37.18024","0.00298"
"446.47200","37.20613","0.00342"
"446.78400","37.23220","0.00333"
"447.09600","37.25815","0.00363"
"447.40800","37.28421","0.00319"
"447.72000","37.31022","0.00342"
"448.03200","37.33617","0.00275"
"448.34400","37.36224","0.00358"
"448.65600","37.38813","0.00407"
"448.96800","37.41414","0.00392"
"449.28000","37.44021","0.00326"
"449.59200","37.46621","0.00317"
"449.90400","37.49222","0.00430"
"450.21600","37.51817","0.00368"
"450.52800","37.54418","0.00375"
"450.84000","37.57019","0.00371"
"451.15200","37.59620","0.00316"
"451.46400","37.62221","0.00341"
"451.77600","37.64815","0.00291"
"452.08800","37.67422","0.00371"
"452.40000","37.70011","0.00385"
"452.71200","37.72624","0.00353"
"453.02400","37.75219","0.00358"
"453.33600","37.77819","0.00378"
"453.64800","37.80426","0.00390"
"453.96000","37.83021","0.00361"
"454.27200","37.85622","0.00391"
"454.58400","37.88217","0.00418"
"454.89600","37.90824","0.00386"
"455.20800","37.93419","0.00390"
"455.52000","37.96019","0.00411"
"455.83200","37.98620","0.00440"
"456.14400","38.01215","0.00422"
"456.45600","38.03822","0.00368"
"456.76800","38.06417","0.00392"
"457.08000","38.09018","0.00382"
"457.39200","38.11619","0.00432"
"457.70400","38.14219","0.00358"
"458.01600","38.16820","0.00468"
"458.32800","38.19415","0.00463"
"458.64000","38.22022","0.00424"
"458.95200","38.24617","0.00465"
"459.26400","38.27212","0.00532"
"459.57600","38.29819","0.00471"
"459.88800","38.32413","0.00448"
"460.20000","38.35020","0.00473"
"460.51200","38.37615","0.00453"
"460.82400","38.40216","0.00448"
"461.13600","38.42823","0.00470"
"461.44800","38.45417","0.00469"
"461.76000","38.48024","0.00473"
"462.07200","38.50613","0.00478"
"462.38400","38.53220","0.00558"
"462.60400","38.55044","0.00462"