File: Force_trajectories/170226_2/Specimen_RawData_4.csv
End date,"2/26/2017"
Specimen label,"7DT_51"
Maximum Load,"0.08631",N

Time,Extension,Load
(s),(mm),(N)
"0.00000","0.00000","-0.00048"
"0.29400","0.02386","0.00061"
"0.58800","0.04921","0.00027"
"0.88200","0.07378","0.00061"
"1.17600","0.09817","0.00070"
"1.47000","0.12269","0.00080"
"1.76400","0.14714","0.00124"
"2.05800","0.17166","0.00180"
"2.35200","0.19611","0.00180"
"2.64600","0.22068","0.00172"
"2.94000","0.24520","0.00180"
"3.23400","0.26971","0.00135"
"3.52800","0.29422","0.00151"
"3.82200","0.31874","0.00195"
"4.11600","0.34325","0.00193"
"4.41000","0.36765","0.00167"
"4.70400","0.39222","0.00196"
"4.99800","0.41661","0.00174"
"5.29200","0.44119","0.00182"
"5.58600","0.46564","0.00204"
"5.88000","0.49021","0.00190"
"6.17400","0.51467","0.00236"
"6.46800","0.53918","0.00259"
"6.76200","0.56364","0.00212"
"7.05600","0.58815","0.00272"
"7.35000","0.61266","0.00253"
"7.64400","0.63718","0.00284"
"7.93800","0.66175","0.00282"
"8.23200","0.68620","0.00183"
"8.52600","0.71072","0.00221"
"8.82000","0.73517","0.00237"
"9.11400","0.75969","0.00230"
"9.40800","0.78414","0.00272"
"9.70200","0.80865","0.00297"
"9.99600","0.83317","0.00252"
"10.29000","0.85768","0.00356"
"10.58400","0.88225","0.00302"
"10.87800","0.90665","0.00257"
"11.17200","0.93122","0.00243"
"11.46600","0.95562","0.00282"
"11.76000","0.98019","0.00296"
"12.05400","1.00464","0.00298"
"12.34800","1.02922","0.00261"
"12.64200","1.05361","0.00319"
"12.93600","1.07812","0.00289"
"13.23000","1.10264","0.00317"
"13.52400","1.12715","0.00299"
"13.81800","1.15167","0.00367"
"14.11200","1.17618","0.00307"
"14.40600","1.20075","0.00255"
"14.70000","1.22521","0.00350"
"14.99400","1.24972","0.00354"
"15.28800","1.27417","0.00319"
"15.58200","1.29869","0.00332"
"15.87600","1.32320","0.00358"
"16.17000","1.34772","0.00341"
"16.46400","1.37211","0.00413"
"16.75800","1.39668","0.00390"
"17.05200","1.42120","0.00402"
"17.34600","1.44565","0.00436"
"17.64000","1.47016","0.00376"
"17.93400","1.49462","0.00432"
"18.22800","1.51919","0.00439"
"18.52200","1.54365","0.00427"
"18.81600","1.56822","0.00418"
"19.11000","1.59267","0.00436"
"19.40400","1.61719","0.00380"
"19.69800","1.64170","0.00445"
"19.99200","1.66615","0.00495"
"20.28600","1.69073","0.00468"
"20.58000","1.71518","0.00422"
"20.87400","1.73976","0.00501"
"21.16800","1.76415","0.00486"
"21.46200","1.78872","0.00459"
"21.75600","1.81318","0.00484"
"22.05000","1.83769","0.00477"
"22.34400","1.86215","0.00486"
"22.63800","1.88666","0.00491"
"22.93200","1.91117","0.00450"
"23.22600","1.93569","0.00435"
"23.52000","1.96020","0.00597"
"23.81400","1.98465","0.00491"
"24.10800","2.00917","0.00511"
"24.40200","2.03362","0.00513"
"24.69600","2.05819","0.00483"
"24.99000","2.08265","0.00503"
"25.28400","2.10722","0.00599"
"25.57800","2.13168","0.00574"
"25.87200","2.15619","0.00583"
"26.16600","2.18070","0.00552"
"26.46000","2.20516","0.00622"
"26.75400","2.22973","0.00571"
"27.04800","2.25418","0.00603"
"27.34200","2.27870","0.00619"
"27.63600","2.30315","0.00542"
"27.93000","2.32773","0.00559"
"28.22400","2.35218","0.00603"
"28.51800","2.37669","0.00620"
"28.81200","2.40121","0.00589"
"29.10600","2.42572","0.00643"
"29.40000","2.45023","0.00610"
"29.69400","2.47469","0.00518"
"29.98800","2.49920","0.00614"
"30.28200","2.52366","0.00628"
"30.57600","2.54823","0.00691"
"30.87000","2.57262","0.00628"
"31.16400","2.59720","0.00719"
"31.45800","2.62165","0.00652"
"31.75200","2.64616","0.00653"
"32.04600","2.67068","0.00755"
"32.34000","2.69519","0.00607"
"32.63400","2.71977","0.00696"
"32.92800","2.74416","0.00675"
"33.22200","2.76873","0.00700"
"33.51600","2.79319","0.00726"
"33.81000","2.81770","0.00755"
"34.10400","2.84216","0.00706"
"34.39800","2.86673","0.00698"
"34.69200","2.89118","0.00687"
"34.98600","2.91570","0.00739"
"35.28000","2.94021","0.00715"
"35.57400","2.96466","0.00733"
"35.86800","2.98918","0.00673"
"36.16200","3.01363","0.00730"
"36.45600","3.03815","0.00753"
"36.75000","3.06260","0.00751"
"37.04400","3.08717","0.00777"
"37.33800","3.11163","0.00801"
"37.63200","3.13620","0.00803"
"37.92600","3.16065","0.00835"
"38.22000","3.18523","0.00826"
"38.51400","3.20968","0.00858"
"38.80800","3.23419","0.00865"
"39.10200","3.25877","0.00826"
"39.39600","3.28322","0.00867"
"39.69000","3.30774","0.00847"
"39.98400","3.33213","0.00882"
"40.27800","3.35670","0.00828"
"40.57200","3.38116","0.00889"
"40.86600","3.40567","0.00855"
"41.16000","3.43019","0.00951"
"41.45400","3.45470","0.00951"
"41.74800","3.47921","0.00943"
"42.04200","3.50367","0.00969"
"42.33600","3.52824","0.00932"
"42.63000","3.55269","0.00953"
"42.92400","3.57721","0.01036"
"43.21800","3.60166","0.01014"
"43.51200","3.62618","0.00987"
"43.80600","3.65063","0.00984"
"44.10000","3.67520","0.01008"
"44.39400","3.69972","0.01031"
"44.68800","3.72423","0.01029"
"44.98200","3.74874","0.01059"
"45.27600","3.77320","0.01058"
"45.57000","3.79771","0.01081"
"45.86400","3.82211","0.01105"
"46.15800","3.84668","0.01083"
"46.45200","3.87113","0.01078"
"46.74600","3.89571","0.01098"
"47.04000","3.92010","0.01103"
"47.33400","3.94473","0.01049"
"47.62800","3.96919","0.01079"
"47.92200","3.99370","0.01093"
"48.21600","4.01816","0.01092"
"48.51000","4.04267","0.01083"
"48.80400","4.06724","0.01079"
"49.09800","4.09164","0.01141"
"49.39200","4.11615","0.01115"
"49.68600","4.14066","0.01132"
"49.98000","4.16518","0.01078"
"50.27400","4.18969","0.01200"
"50.56800","4.21421","0.01167"
"50.86200","4.23872","0.01166"
"51.15600","4.26317","0.01240"
"51.45000","4.28769","0.01242"
"51.74400","4.31220","0.01235"
"52.03800","4.33677","0.01251"
"52.33200","4.36117","0.01230"
"52.62600","4.38568","0.01200"
"52.92000","4.41014","0.01199"
"53.21400","4.43471","0.01232"
"53.50800","4.45916","0.01248"
"53.80200","4.48374","0.01171"
"54.09600","4.50825","0.01276"
"54.39000","4.53270","0.01315"
"54.68400","4.55716","0.01295"
"54.97800","4.58167","0.01257"
"55.27200","4.60619","0.01315"
"55.56600","4.63064","0.01287"
"55.86000","4.65515","0.01306"
"56.15400","4.67967","0.01280"
"56.44800","4.70424","0.01358"
"56.74200","4.72869","0.01338"
"57.03600","4.75321","0.01310"
"57.33000","4.77766","0.01340"
"57.62400","4.80224","0.01216"
"57.91800","4.82669","0.01207"
"58.21200","4.85114","0.01220"
"58.50600","4.87566","0.01218"
"58.80000","4.90011","0.01277"
"59.09400","4.92468","0.01237"
"59.38800","4.94914","0.01295"
"59.68200","4.97371","0.01292"
"59.97600","4.99817","0.01307"
"60.27000","5.02268","0.01301"
"60.56400","5.04713","0.01327"
"60.85800","5.07165","0.01382"
"61.15200","5.09616","0.01409"
"61.44600","5.12067","0.01399"
"61.74000","5.14519","0.01391"
"62.03400","5.16964","0.01385"
"62.32800","5.19422","0.01410"
"62.62200","5.21861","0.01435"
"62.91600","5.24324","0.01394"
"63.21000","5.26770","0.01411"
"63.50400","5.29227","0.01442"
"63.79800","5.31672","0.01407"
"64.09200","5.34118","0.01486"
"64.38600","5.36575","0.01558"
"64.68000","5.39015","0.01559"
"64.97400","5.41472","0.01448"
"65.26800","5.43917","0.01495"
"65.56200","5.46369","0.01465"
"65.85600","5.48808","0.01488"
"66.15000","5.51271","0.01532"
"66.44400","5.53717","0.01517"
"66.73800","5.56174","0.01461"
"67.03200","5.58620","0.01516"
"67.32600","5.61071","0.01546"
"67.62000","5.63516","0.01594"
"67.91400","5.65968","0.01498"
"68.20800","5.68425","0.01484"
"68.50200","5.70870","0.01417"
"68.79600","5.73322","0.01422"
"69.09000","5.75767","0.01481"
"69.38400","5.78219","0.01537"
"69.67800","5.80670","0.01478"
"69.97200","5.83121","0.01533"
"70.26600","5.85567","0.01467"
"70.56000","5.88018","0.01527"
"70.85400","5.90475","0.01525"
"71.14800","5.92915","0.01541"
"71.44200","5.95372","0.01561"
"71.73600","5.97812","0.01545"
"72.03000","6.00269","0.01593"
"72.32400","6.02708","0.01477"
"72.61800","6.05172","0.01564"
"72.91200","6.07617","0.01593"
"73.20600","6.10063","0.01542"
"73.50000","6.12514","0.01589"
"73.79400","6.14965","0.01564"
"74.08800","6.17417","0.01627"
"74.38200","6.19868","0.01660"
"74.67600","6.22319","0.01651"
"74.97000","6.24765","0.01681"
"75.26400","6.27222","0.01746"
"75.55800","6.29667","0.01717"
"75.85200","6.32125","0.01757"
"76.14600","6.34564","0.01772"
"76.44000","6.37022","0.01712"
"76.73400","6.39467","0.01798"
"77.02800","6.41918","0.01771"
"77.32200","6.44370","0.01818"
"77.61600","6.46815","0.01830"
"77.91000","6.49266","0.01823"
"78.20400","6.51712","0.01767"
"78.49800","6.54169","0.01868"
"78.79200","6.56615","0.01903"
"79.08600","6.59066","0.01809"
"79.38000","6.61517","0.01895"
"79.67400","6.63969","0.01915"
"79.96800","6.66426","0.01882"
"80.26200","6.68866","0.01899"
"80.55600","6.71329","0.01829"
"80.85000","6.73768","0.01862"
"81.14400","6.76226","0.01886"
"81.43800","6.78665","0.01873"
"81.73200","6.81122","0.01839"
"82.02600","6.83568","0.01857"
"82.32000","6.86019","0.01796"
"82.61400","6.88465","0.01855"
"82.90800","6.90916","0.01883"
"83.20200","6.93367","0.01903"
"83.49600","6.95819","0.01862"
"83.79000","6.98264","0.01937"
"84.08400","7.00715","0.01957"
"84.37800","7.03167","0.02037"
"84.67200","7.05606","0.01985"
"84.96600","7.08070","0.02010"
"85.26000","7.10515","0.02023"
"85.55400","7.12972","0.02036"
"85.84800","7.15418","0.02074"
"86.14200","7.17869","0.02123"
"86.43600","7.20320","0.02144"
"86.73000","7.22772","0.02131"
"87.02400","7.25229","0.02200"
"87.31800","7.27668","0.02129"
"87.61200","7.30120","0.02158"
"87.90600","7.32565","0.02244"
"88.20000","7.35017","0.02215"
"88.49400","7.37468","0.02213"
"88.78800","7.39925","0.02223"
"89.08200","7.42371","0.02262"
"89.37600","7.44816","0.02296"
"89.67000","7.47273","0.02318"
"89.96400","7.49719","0.02347"
"90.25800","7.52170","0.02311"
"90.55200","7.54616","0.02384"
"90.84600","7.57067","0.02396"
"91.14000","7.59512","0.02414"
"91.43400","7.61970","0.02421"
"91.72800","7.64415","0.02396"
"92.02200","7.66873","0.02428"
"92.31600","7.69318","0.02413"
"92.61000","7.71775","0.02355"
"92.90400","7.74227","0.02403"
"93.19800","7.76672","0.02286"
"93.49200","7.79123","0.02345"
"93.78600","7.81569","0.02310"
"94.08000","7.84020","0.02389"
"94.37400","7.86466","0.02345"
"94.66800","7.88923","0.02292"
"94.96200","7.91368","0.02322"
"95.25600","7.93820","0.02300"
"95.55000","7.96265","0.02319"
"95.84400","7.98716","0.02384"
"96.13800","8.01168","0.02330"
"96.43200","8.03607","0.02292"
"96.72600","8.06065","0.02093"
"97.02000","8.08510","0.02076"
"97.31400","8.10967","0.02005"
"97.60800","8.13413","0.01927"
"97.90200","8.15870","0.02001"
"98.19600","8.18321","0.02034"
"98.49000","8.20773","0.02068"
"98.78400","8.23218","0.02125"
"99.07800","8.25669","0.02143"
"99.37200","8.28121","0.02117"
"99.66600","8.30566","0.02158"
"99.96000","8.33024","0.02193"
"100.25400","8.35463","0.02166"
"100.54800","8.37920","0.02195"
"100.84200","8.40360","0.02194"
"101.13600","8.42823","0.02204"
"101.43000","8.45269","0.02160"
"101.72400","8.47720","0.02184"
"102.01800","8.50171","0.02230"
"102.31200","8.52617","0.02280"
"102.60600","8.55074","0.02326"
"102.90000","8.57519","0.02338"
"103.19400","8.59971","0.02256"
"103.48800","8.62416","0.02095"
"103.78200","8.64868","0.02132"
"104.07600","8.67313","0.02111"
"104.37000","8.69770","0.02130"
"104.66400","8.72222","0.02201"
"104.95800","8.74673","0.02267"
"105.25200","8.77124","0.02255"
"105.54600","8.79576","0.01985"
"105.84000","8.82027","0.02053"
"106.13400","8.84467","0.01996"
"106.42800","8.86918","0.01993"
"106.72200","8.89369","0.02002"
"107.01600","8.91821","0.01979"
"107.31000","8.94260","0.01986"
"107.60400","8.96717","0.02019"
"107.89800","8.99169","0.02018"
"108.19200","9.01620","0.02061"
"108.48600","9.04066","0.02006"
"108.78000","9.06517","0.02113"
"109.07400","9.08968","0.02069"
"109.36800","9.11414","0.02080"
"109.66200","9.13865","0.02076"
"109.95600","9.16316","0.02146"
"110.25000","9.18774","0.02218"
"110.54400","9.21213","0.02250"
"110.83800","9.23671","0.02274"
"111.13200","9.26122","0.02266"
"111.42600","9.28573","0.02305"
"111.72000","9.31019","0.01918"
"112.01400","9.33470","0.01695"
"112.30800","9.35921","0.01715"
"112.60200","9.38367","0.01791"
"112.89600","9.40818","0.01818"
"113.19000","9.43264","0.01937"
"113.48400","9.45721","0.01849"
"113.77800","9.48160","0.01896"
"114.07200","9.50624","0.01912"
"114.36600","9.53075","0.01972"
"114.66000","9.55520","0.01991"
"114.95400","9.57972","0.01959"
"115.24800","9.60411","0.02093"
"115.54200","9.62875","0.02043"
"115.83600","9.65314","0.02061"
"116.13000","9.67771","0.02080"
"116.42400","9.70217","0.02072"
"116.71800","9.72674","0.02049"
"117.01200","9.75119","0.02106"
"117.30600","9.77577","0.02043"
"117.60000","9.80016","0.02078"
"117.89400","9.82468","0.02026"
"118.18800","9.84919","0.01999"
"118.48200","9.87364","0.02003"
"118.77600","9.89816","0.02047"
"119.07000","9.92267","0.01998"
"119.36400","9.94718","0.01981"
"119.65800","9.97164","0.02026"
"119.95200","9.99615","0.02033"
"120.24600","10.02061","0.02059"
"120.54000","10.04518","0.02021"
"120.83400","10.06969","0.02008"
"121.12800","10.09415","0.02060"
"121.42200","10.11872","0.02100"
"121.71600","10.14318","0.02108"
"122.01000","10.16769","0.02067"
"122.30400","10.19208","0.02108"
"122.59800","10.21672","0.01973"
"122.89200","10.24117","0.02005"
"123.18600","10.26568","0.02015"
"123.48000","10.29014","0.01989"
"123.77400","10.31471","0.01978"
"124.06800","10.33922","0.02005"
"124.36200","10.36374","0.02017"
"124.65600","10.38825","0.02008"
"124.95000","10.41265","0.02111"
"125.24400","10.43722","0.02066"
"125.53800","10.46167","0.02112"
"125.83200","10.48619","0.02097"
"126.12600","10.51064","0.02062"
"126.42000","10.53522","0.02076"
"126.71400","10.55967","0.02153"
"127.00800","10.58418","0.02151"
"127.30200","10.60864","0.02090"
"127.59600","10.63315","0.02111"
"127.89000","10.65766","0.02089"
"128.18400","10.68218","0.02211"
"128.47800","10.70675","0.02165"
"128.77200","10.73120","0.02110"
"129.06600","10.75572","0.02106"
"129.36000","10.78017","0.01816"
"129.65400","10.80469","0.01837"
"129.94800","10.82920","0.01775"
"130.24200","10.85365","0.01850"
"130.53600","10.87817","0.01871"
"130.83000","10.90268","0.01923"
"131.12400","10.92726","0.01937"
"131.41800","10.95165","0.01852"
"131.71200","10.97622","0.01895"
"132.00600","11.00062","0.01922"
"132.30000","11.02519","0.01909"
"132.59400","11.04958","0.01902"
"132.88800","11.07416","0.01826"
"133.18200","11.09861","0.01773"
"133.47600","11.12319","0.01824"
"133.77000","11.14764","0.01784"
"134.06400","11.17215","0.01815"
"134.35800","11.19667","0.01901"
"134.65200","11.22118","0.01879"
"134.94600","11.24569","0.01896"
"135.24000","11.27015","0.01880"
"135.53400","11.29472","0.02026"
"135.82800","11.31917","0.01961"
"136.12200","11.34375","0.02063"
"136.41600","11.36820","0.02005"
"136.71000","11.39272","0.02110"
"137.00400","11.41723","0.02108"
"137.29800","11.44168","0.02161"
"137.59200","11.46620","0.02178"
"137.88600","11.49065","0.02186"
"138.18000","11.51523","0.02164"
"138.47400","11.53962","0.02195"
"138.76800","11.56419","0.01947"
"139.06200","11.58865","0.01981"
"139.35600","11.61316","0.02056"
"139.65000","11.63767","0.02092"
"139.94400","11.66219","0.02098"
"140.23800","11.68676","0.02111"
"140.53200","11.71116","0.02118"
"140.82600","11.73573","0.02154"
"141.12000","11.76018","0.02103"
"141.41400","11.78476","0.02128"
"141.70800","11.80915","0.02175"
"142.00200","11.83372","0.02228"
"142.29600","11.85818","0.02214"
"142.59000","11.88269","0.02249"
"142.88400","11.90715","0.02203"
"143.17800","11.93166","0.02204"
"143.47200","11.95617","0.02203"
"143.76600","11.98063","0.02086"
"144.06000","12.00520","0.02087"
"144.35400","12.02965","0.02075"
"144.64800","12.05417","0.02104"
"144.94200","12.07856","0.02062"
"145.23600","12.10319","0.02007"
"145.53000","12.12765","0.02082"
"145.82400","12.15216","0.02030"
"146.11800","12.17668","0.02136"
"146.41200","12.20119","0.02200"
"146.70600","12.22570","0.02129"
"147.00000","12.25016","0.02137"
"147.29400","12.27473","0.02181"
"147.58800","12.29919","0.02192"
"147.88200","12.32370","0.02193"
"148.17600","12.34815","0.02190"
"148.47000","12.37273","0.02183"
"148.76400","12.39724","0.02235"
"149.05800","12.42169","0.02283"
"149.35200","12.44615","0.02263"
"149.64600","12.47066","0.02279"
"149.94000","12.49518","0.02262"
"150.23400","12.51963","0.02278"
"150.52800","12.54426","0.02314"
"150.82200","12.56866","0.02358"
"151.11600","12.59317","0.02255"
"151.41000","12.61762","0.02286"
"151.70400","12.64220","0.02362"
"151.99800","12.66665","0.02385"
"152.29200","12.69123","0.02382"
"152.58600","12.71568","0.02406"
"152.88000","12.74019","0.02379"
"153.17400","12.76471","0.02421"
"153.46800","12.78916","0.02374"
"153.76200","12.81373","0.02351"
"154.05600","12.83813","0.02389"
"154.35000","12.86270","0.02461"
"154.64400","12.88716","0.02487"
"154.93800","12.91167","0.02387"
"155.23200","12.93612","0.02451"
"155.52600","12.96064","0.02518"
"155.82000","12.98521","0.02517"
"156.11400","13.00966","0.02535"
"156.40800","13.03424","0.02560"
"156.70200","13.05863","0.02577"
"156.99600","13.08321","0.02644"
"157.29000","13.10766","0.02611"
"157.58400","13.13217","0.02650"
"157.87800","13.15663","0.02648"
"158.17200","13.18120","0.02715"
"158.46600","13.20566","0.02661"
"158.76000","13.23023","0.02702"
"159.05400","13.25474","0.02746"
"159.34800","13.27920","0.02762"
"159.64200","13.30365","0.02823"
"159.93600","13.32816","0.02847"
"160.23000","13.35268","0.02848"
"160.52400","13.37719","0.02878"
"160.81800","13.40170","0.02873"
"161.11200","13.42616","0.02871"
"161.40600","13.45073","0.02840"
"161.70000","13.47519","0.02813"
"161.99400","13.49970","0.02951"
"162.28800","13.52421","0.02906"
"162.58200","13.54867","0.02966"
"162.87600","13.57318","0.02980"
"163.17000","13.59764","0.03030"
"163.46400","13.62215","0.03050"
"163.75800","13.64666","0.03071"
"164.05200","13.67124","0.03086"
"164.34600","13.69563","0.03109"
"164.64000","13.72020","0.03137"
"164.93400","13.74472","0.03187"
"165.22800","13.76923","0.03240"
"165.52200","13.79374","0.03241"
"165.81600","13.81820","0.03274"
"166.11000","13.84277","0.03271"
"166.40400","13.86717","0.03314"
"166.69800","13.89168","0.03356"
"166.99200","13.91613","0.03402"
"167.28600","13.94071","0.03495"
"167.58000","13.96516","0.03554"
"167.87400","13.98974","0.03568"
"168.16800","14.01413","0.03615"
"168.46200","14.03864","0.03644"
"168.75600","14.06316","0.03681"
"169.05000","14.08761","0.03780"
"169.34400","14.11218","0.03825"
"169.63800","14.13664","0.03847"
"169.93200","14.16115","0.03945"
"170.22600","14.18561","0.03919"
"170.52000","14.21018","0.03850"
"170.81400","14.23463","0.03958"
"171.10800","14.25915","0.03956"
"171.40200","14.28366","0.04090"
"171.69600","14.30817","0.04064"
"171.99000","14.33275","0.04194"
"172.28400","14.35720","0.04233"
"172.57800","14.38171","0.04261"
"172.87200","14.40617","0.04295"
"173.16600","14.43068","0.04373"
"173.46000","14.45514","0.04392"
"173.75400","14.47971","0.04428"
"174.04800","14.50416","0.04495"
"174.34200","14.52868","0.04528"
"174.63600","14.55319","0.04530"
"174.93000","14.57770","0.04604"
"175.22400","14.60222","0.04644"
"175.51800","14.62667","0.04690"
"175.81200","14.65119","0.04686"
"176.10600","14.67570","0.04738"
"176.40000","14.70021","0.04811"
"176.69400","14.72467","0.04835"
"176.98800","14.74918","0.04851"
"177.28200","14.77370","0.04890"
"177.57600","14.79827","0.04926"
"177.87000","14.82272","0.04989"
"178.16400","14.84724","0.05008"
"178.45800","14.87169","0.05051"
"178.75200","14.89620","0.05102"
"179.04600","14.92066","0.05159"
"179.34000","14.94517","0.05250"
"179.63400","14.96969","0.05250"
"179.92800","14.99414","0.05302"
"180.22200","15.01865","0.05333"
"180.51600","15.04317","0.05363"
"180.81000","15.06768","0.05447"
"181.10400","15.09213","0.05503"
"181.39800","15.11665","0.05549"
"181.69200","15.14122","0.05643"
"181.98600","15.16568","0.05707"
"182.28000","15.19019","0.05763"
"182.57400","15.21464","0.05819"
"182.86800","15.23922","0.05910"
"183.16200","15.26361","0.06029"
"183.45600","15.28824","0.06048"
"183.75000","15.31270","0.06146"
"184.04400","15.33721","0.06242"
"184.33800","15.36172","0.06308"
"184.63200","15.38618","0.06381"
"184.92600","15.41075","0.06495"
"185.22000","15.43515","0.06564"
"185.51400","15.45966","0.06704"
"185.80800","15.48411","0.06783"
"186.10200","15.50869","0.06916"
"186.39600","15.53314","0.06972"
"186.69000","15.55772","0.07086"
"186.98400","15.58217","0.07210"
"187.27800","15.60674","0.07413"
"187.57200","15.63120","0.07495"
"187.86600","15.65571","0.07617"
"188.16000","15.68022","0.07686"
"188.45400","15.70468","0.07837"
"188.74800","15.72919","0.07955"
"189.04200","15.75371","0.08105"
"189.33600","15.77822","0.08233"
"189.63000","15.80273","0.08279"
"189.92400","15.82719","0.08353"
"190.21800","15.85164","0.08454"
"190.51200","15.87615","0.08558"
"190.80600","15.90067","0.08248"
"191.10000","15.92518","0.07131"
"191.39400","15.94969","0.07224"
"191.68800","15.97415","0.07040"
"191.98200","15.99872","0.07135"
"192.27600","16.02318","0.06976"
"192.57000","16.04769","0.06978"
"192.86400","16.07214","0.07046"
"193.15800","16.09672","0.07035"
"193.45200","16.12117","-0.00357"
"193.74600","16.14569","0.00130"
"194.04000","16.17020","0.00631"
"194.33400","16.19465","0.00396"
"194.62800","16.21917","0.00336"
"194.92200","16.24368","0.00258"
"195.21600","16.26825","0.00411"
"195.51000","16.29265","0.00238"
"195.80400","16.31722","0.00364"
"196.09800","16.34167","0.00229"
"196.39200","16.36619","0.00305"
"196.68600","16.39070","0.00261"
"196.98000","16.41522","0.00309"
"197.27400","16.43973","0.00302"
"197.56800","16.46418","0.00284"
"197.86200","16.48870","0.00303"
"198.15600","16.51315","0.00276"
"198.45000","16.53766","0.00343"
"198.74400","16.56212","0.00275"
"199.03800","16.58663","0.00282"
"199.33200","16.61115","0.00287"
"199.62600","16.63572","0.00332"
"199.92000","16.66017","0.00307"
"200.21400","16.68469","0.00328"
"200.50800","16.70920","0.00253"
"200.80200","16.73372","0.00333"
"201.09600","16.75823","0.00310"
"201.39000","16.78268","0.00292"
"201.68400","16.80726","0.00335"
"201.97800","16.83165","0.00285"
"202.27200","16.85622","0.00356"
"202.56600","16.88068","0.00307"
"202.86000","16.90519","0.00304"
"203.15400","16.92965","0.00328"
"203.44800","16.95422","0.00363"
"203.74200","16.97867","0.00315"
"204.03600","17.00319","0.00309"
"204.33000","17.02770","0.00400"
"204.62400","17.05215","0.00353"
"204.91800","17.07661","0.00282"
"205.21200","17.10112","0.00316"
"205.50600","17.12564","0.00366"
"205.80000","17.15009","0.00381"
"206.09400","17.17466","0.00319"
"206.38800","17.19918","0.00349"
"206.68200","17.22369","0.00346"
"206.97600","17.24820","0.00354"
"207.27000","17.27266","0.00358"
"207.56400","17.29723","0.00382"
"207.85800","17.32169","0.00365"
"208.15200","17.34620","0.00395"
"208.44600","17.37065","0.00369"
"208.74000","17.39523","0.00356"
"209.03400","17.41968","0.00358"
"209.32800","17.44413","0.00370"
"209.62200","17.46871","0.00373"
"209.91600","17.49322","0.00365"
"210.21000","17.51773","0.00387"
"210.50400","17.54213","0.00365"
"210.79800","17.56670","0.00344"
"211.09200","17.59116","0.00373"
"211.38600","17.61573","0.00356"
"211.68000","17.64013","0.00337"
"211.97400","17.66470","0.00408"
"212.26800","17.68915","0.00371"
"212.56200","17.71373","0.00388"
"212.85600","17.73818","0.00366"
"213.15000","17.76275","0.00387"
"213.44400","17.78721","0.00332"
"213.73800","17.81166","0.00487"
"214.03200","17.83623","0.00376"
"214.32600","17.86063","0.00380"
"214.62000","17.88520","0.00374"
"214.91400","17.90965","0.00435"
"215.20800","17.93417","0.00423"
"215.50200","17.95868","0.00418"
"215.79600","17.98314","0.00437"
"216.09000","18.00765","0.00374"
"216.38400","18.03217","0.00411"
"216.67800","18.05668","0.00338"
"216.97200","18.08113","0.00426"
"217.26600","18.10571","0.00359"
"217.56000","18.13010","0.00454"
"217.85400","18.15467","0.00383"
"218.14800","18.17913","0.00424"
"218.44200","18.20376","0.00435"
"218.73600","18.22816","0.00376"
"219.03000","18.25273","0.00491"
"219.32400","18.27718","0.00470"
"219.61800","18.30169","0.00385"
"219.91200","18.32621","0.00434"
"220.20600","18.35066","0.00420"
"220.50000","18.37524","0.00441"
"220.79400","18.39963","0.00421"
"221.08800","18.42420","0.00398"
"221.38200","18.44866","0.00425"
"221.67600","18.47317","0.00441"
"221.97000","18.49763","0.00429"
"222.26400","18.52220","0.00390"
"222.55800","18.54665","0.00386"
"222.85200","18.57117","0.00422"
"223.14600","18.59568","0.00420"
"223.44000","18.62020","0.00430"
"223.73400","18.64471","0.00436"
"224.02800","18.66916","0.00468"
"224.32200","18.69368","0.00375"
"224.61600","18.71813","0.00446"
"224.91000","18.74270","0.00431"
"225.20400","18.76722","0.00398"
"225.49800","18.79173","0.00435"
"225.79200","18.81624","0.00459"
"226.08600","18.84070","0.00432"
"226.38000","18.86527","0.00438"
"226.67400","18.88961","0.00435"
"226.96800","18.91418","0.00448"
"227.26200","18.93863","0.00462"
"227.55600","18.96327","0.00411"
"227.85000","18.98766","0.00471"
"228.14400","19.01224","0.00489"
"228.43800","19.03669","0.00406"
"228.73200","19.06114","0.00478"
"229.02600","19.08566","0.00447"
"229.32000","19.11017","0.00468"
"229.61400","19.13468","0.00428"
"229.90800","19.15914","0.00419"
"230.20200","19.18371","0.00454"
"230.49600","19.20816","0.00463"
"230.79000","19.23268","0.00398"
"231.08400","19.25719","0.00443"
"231.37800","19.28171","0.00429"
"231.67200","19.30616","0.00460"
"231.96600","19.33067","0.00476"
"232.26000","19.35519","0.00440"
"232.55400","19.37964","0.00455"
"232.84800","19.40421","0.00449"
"233.14200","19.42867","0.00494"
"233.43600","19.45318","0.00486"
"233.73000","19.47764","0.00425"
"234.02400","19.50221","0.00455"
"234.31800","19.52666","0.00442"
"234.61200","19.55124","0.00391"
"234.90600","19.57569","0.00430"
"235.20000","19.60015","0.00451"
"235.49400","19.62472","0.00391"
"235.78800","19.64917","0.00419"
"236.08200","19.67369","0.00437"
"236.37600","19.69814","0.00473"
"236.67000","19.72271","0.00411"
"236.96400","19.74717","0.00362"
"237.25800","19.77174","0.00416"
"237.55200","19.79619","0.00349"
"237.84600","19.82077","0.00432"
"238.14000","19.84522","0.00431"
"238.43400","19.86973","0.00421"
"238.72800","19.89419","0.00396"
"239.02200","19.91864","0.00374"
"239.31600","19.94316","0.00379"
"239.61000","19.96761","0.00369"
"239.90400","19.99218","0.00402"
"240.19800","20.01664","0.00403"
"240.49200","20.04121","0.00410"
"240.78600","20.06567","0.00381"
"241.08000","20.09018","0.00392"
"241.37400","20.11463","0.00426"
"241.66800","20.13915","0.00379"
"241.96200","20.16366","0.00362"
"242.25600","20.18818","0.00402"
"242.55000","20.21269","0.00333"
"242.84400","20.23714","0.00392"
"243.13800","20.26172","0.00385"
"243.43200","20.28617","0.00368"
"243.72600","20.31068","0.00371"
"244.02000","20.33520","0.00406"
"244.31400","20.35971","0.00406"
"244.60800","20.38423","0.00316"
"244.90200","20.40868","0.00347"
"245.19600","20.43319","0.00297"
"245.49000","20.45771","0.00363"
"245.78400","20.48222","0.00394"
"246.07800","20.50661","0.00366"
"246.37200","20.53119","0.00370"
"246.66600","20.55564","0.00344"
"246.96000","20.58022","0.00318"
"247.25400","20.60467","0.00381"
"247.54800","20.62918","0.00369"
"247.84200","20.65370","0.00374"
"248.13600","20.67821","0.00362"
"248.43000","20.70272","0.00364"
"248.72400","20.72718","0.00373"
"249.01800","20.75169","0.00360"
"249.31200","20.77615","0.00387"
"249.60600","20.80072","0.00362"
"249.90000","20.82517","0.00377"
"250.19400","20.84969","0.00362"
"250.48800","20.87420","0.00378"
"250.78200","20.89871","0.00387"
"251.07600","20.92317","0.00363"
"251.37000","20.94774","0.00349"
"251.66400","20.97226","0.00426"
"251.95800","20.99659","0.00389"
"252.25200","21.02116","0.00374"
"252.54600","21.04562","0.00347"
"252.84000","21.07025","0.00355"
"253.13400","21.09464","0.00398"
"253.42800","21.11922","0.00362"
"253.72200","21.14367","0.00409"
"254.01600","21.16818","0.00357"
"254.31000","21.19264","0.00351"
"254.60400","21.21715","0.00355"
"254.89800","21.24166","0.00364"
"255.19200","21.26612","0.00365"
"255.48600","21.29075","0.00348"
"255.78000","21.31521","0.00361"
"256.07400","21.33972","0.00388"
"256.36800","21.36418","0.00314"
"256.66200","21.38869","0.00379"
"256.95600","21.41314","0.00372"
"257.25000","21.43766","0.00434"
"257.54400","21.46217","0.00425"
"257.83800","21.48668","0.00375"
"258.13200","21.51120","0.00366"
"258.42600","21.53565","0.00383"
"258.72000","21.56017","0.00395"
"259.01400","21.58468","0.00444"
"259.30800","21.60919","0.00366"
"259.60200","21.63365","0.00384"
"259.89600","21.65822","0.00340"
"260.19000","21.68267","0.00371"
"260.48400","21.70719","0.00348"
"260.77800","21.73170","0.00349"
"261.07200","21.75615","0.00389"
"261.36600","21.78073","0.00381"
"261.66000","21.80518","0.00381"
"261.95400","21.82976","0.00386"
"262.24800","21.85415","0.00343"
"262.54200","21.87873","0.00438"
"262.83600","21.90318","0.00434"
"263.13000","21.92769","0.00344"
"263.42400","21.95215","0.00348"
"263.71800","21.97672","0.00456"
"264.01200","22.00123","0.00420"
"264.30600","22.02575","0.00422"
"264.60000","22.05020","0.00419"
"264.89400","22.07466","0.00371"
"265.18800","22.09917","0.00427"
"265.48200","22.12362","0.00404"
"265.77600","22.14819","0.00328"
"266.07000","22.17265","0.00392"
"266.36400","22.19716","0.00385"
"266.65800","22.22168","0.00376"
"266.95200","22.24619","0.00341"
"267.24600","22.27071","0.00358"
"267.54000","22.29522","0.00405"
"267.83400","22.31973","0.00367"
"268.12800","22.34413","0.00385"
"268.42200","22.36870","0.00347"
"268.71600","22.39315","0.00396"
"269.01000","22.41773","0.00365"
"269.30400","22.44218","0.00351"
"269.59800","22.46663","0.00385"
"269.89200","22.49115","0.00343"
"270.18600","22.51566","0.00427"
"270.48000","22.54023","0.00440"
"270.77400","22.56463","0.00395"
"271.06800","22.58920","0.00386"
"271.36200","22.61366","0.00364"
"271.65600","22.63823","0.00327"
"271.95000","22.66262","0.00401"
"272.24400","22.68720","0.00349"
"272.53800","22.71165","0.00404"
"272.83200","22.73623","0.00365"
"273.12600","22.76068","0.00361"
"273.42000","22.78519","0.00375"
"273.71400","22.80971","0.00366"
"274.00800","22.83422","0.00416"
"274.30200","22.85874","0.00361"
"274.59600","22.88319","0.00362"
"274.89000","22.90770","0.00371"
"275.18400","22.93210","0.00374"
"275.47800","22.95667","0.00374"
"275.77200","22.98118","0.00346"
"276.06600","23.00570","0.00323"
"276.36000","23.03015","0.00428"
"276.65400","23.05460","0.00350"
"276.94800","23.07918","0.00334"
"277.24200","23.10369","0.00363"
"277.53600","23.12821","0.00372"
"277.83000","23.15260","0.00307"
"278.12400","23.17718","0.00364"
"278.41800","23.20163","0.00347"
"278.71200","23.22620","0.00378"
"279.00600","23.25071","0.00303"
"279.30000","23.27523","0.00413"
"279.59400","23.29968","0.00282"
"279.88800","23.32420","0.00303"
"280.18200","23.34871","0.00335"
"280.47600","23.37316","0.00337"
"280.77000","23.39768","0.00342"
"281.06400","23.42213","0.00358"
"281.35800","23.44670","0.00315"
"281.65200","23.47116","0.00361"
"281.94600","23.49573","0.00329"
"282.24000","23.52012","0.00313"
"282.53400","23.54470","0.00348"
"282.82800","23.56921","0.00384"
"283.12200","23.59367","0.00364"
"283.41600","23.61824","0.00377"
"283.71000","23.64269","0.00379"
"284.00400","23.66721","0.00319"
"284.29800","23.69166","0.00355"
"284.59200","23.71618","0.00386"
"284.88600","23.74063","0.00399"
"285.18000","23.76520","0.00302"
"285.47400","23.78966","0.00360"
"285.76800","23.81417","0.00392"
"286.06200","23.83875","0.00372"
"286.35600","23.86320","0.00304"
"286.65000","23.88777","0.00334"
"286.94400","23.91216","0.00266"
"287.23800","23.93668","0.00328"
"287.53200","23.96113","0.00327"
"287.82600","23.98565","0.00345"
"288.12000","24.01010","0.00308"
"288.41400","24.03468","0.00343"
"288.70800","24.05913","0.00344"
"289.00200","24.08370","0.00362"
"289.29600","24.10822","0.00348"
"289.59000","24.13267","0.00360"
"289.88400","24.15718","0.00377"
"290.17800","24.18164","0.00387"
"290.47200","24.20621","0.00319"
"290.76600","24.23061","0.00355"
"291.06000","24.25518","0.00305"
"291.35400","24.27969","0.00338"
"291.64800","24.30420","0.00356"
"291.94200","24.32872","0.00370"
"292.23600","24.35323","0.00338"
"292.53000","24.37769","0.00351"
"292.82400","24.40214","0.00322"
"293.11800","24.42671","0.00351"
"293.41200","24.45117","0.00396"
"293.70600","24.47568","0.00326"
"294.00000","24.50014","0.00319"
"294.29400","24.52471","0.00313"
"294.58800","24.54916","0.00351"
"294.88200","24.57368","0.00326"
"295.17600","24.59819","0.00379"
"295.47000","24.62264","0.00390"
"295.76400","24.64716","0.00424"
"296.05800","24.67161","0.00304"
"296.35200","24.69625","0.00373"
"296.64600","24.72064","0.00409"
"296.94000","24.74521","0.00375"
"297.23400","24.76967","0.00363"
"297.52800","24.79424","0.00342"
"297.82200","24.81870","0.00348"
"298.11600","24.84321","0.00317"
"298.41000","24.86772","0.00366"
"298.70400","24.89224","0.00327"
"298.99800","24.91669","0.00346"
"299.29200","24.94120","0.00381"
"299.58600","24.96572","0.00340"
"299.88000","24.99011","0.00357"
"300.17400","25.01468","0.00321"
"300.46800","25.03914","0.00364"
"300.76200","25.06371","0.00370"
"301.05600","25.08811","0.00376"
"301.35000","25.11268","0.00343"
"301.64400","25.13720","0.00354"
"301.93800","25.16165","0.00369"
"302.23200","25.18616","0.00401"
"302.52600","25.21068","0.00385"
"302.82000","25.23525","0.00407"
"303.11400","25.25964","0.00314"
"303.40800","25.28422","0.00349"
"303.70200","25.30867","0.00349"
"303.99600","25.33319","0.00326"
"304.29000","25.35764","0.00318"
"304.58400","25.38221","0.00435"
"304.87800","25.40672","0.00374"
"305.17200","25.43118","0.00327"
"305.46600","25.45575","0.00348"
"305.76000","25.48015","0.00368"
"306.05400","25.50472","0.00390"
"306.34800","25.52911","0.00373"
"306.64200","25.55369","0.00369"
"306.93600","25.57808","0.00395"
"307.23000","25.60272","0.00354"
"307.52400","25.62717","0.00312"
"307.81800","25.65168","0.00362"
"308.11200","25.67620","0.00402"
"308.40600","25.70071","0.00392"
"308.70000","25.72523","0.00405"
"308.99400","25.74968","0.00324"
"309.28800","25.77425","0.00368"
"309.58200","25.79871","0.00363"
"309.87600","25.82322","0.00355"
"310.17000","25.84767","0.00380"
"310.46400","25.87225","0.00339"
"310.75800","25.89670","0.00393"
"311.05200","25.92115","0.00330"
"311.34600","25.94567","0.00423"
"311.64000","25.97012","0.00385"
"311.93400","25.99469","0.00397"
"312.22800","26.01915","0.00367"
"312.52200","26.04372","0.00388"
"312.81600","26.06812","0.00349"
"313.11000","26.09269","0.00413"
"313.40400","26.11714","0.00369"
"313.69800","26.14172","0.00350"
"313.99200","26.16617","0.00361"
"314.28600","26.19069","0.00388"
"314.58000","26.21520","0.00378"
"314.87400","26.23965","0.00315"
"315.16800","26.26423","0.00392"
"315.46200","26.28868","0.00425"
"315.75600","26.31319","0.00398"
"316.05000","26.33765","0.00423"
"316.34400","26.36222","0.00360"
"316.63800","26.38668","0.00337"
"316.93200","26.41119","0.00355"
"317.22600","26.43570","0.00354"
"317.52000","26.46021","0.00377"
"317.81400","26.48467","0.00379"
"318.10800","26.50912","0.00344"
"318.40200","26.53370","0.00375"
"318.69600","26.55815","0.00372"
"318.99000","26.58267","0.00363"
"319.28400","26.60712","0.00370"
"319.57800","26.63169","0.00381"
"319.87200","26.65615","0.00363"
"320.16600","26.68072","0.00354"
"320.46000","26.70517","0.00366"
"320.75400","26.72969","0.00383"
"321.04800","26.75420","0.00339"
"321.34200","26.77866","0.00373"
"321.63600","26.80323","0.00375"
"321.93000","26.82768","0.00401"
"322.22400","26.85225","0.00350"
"322.51800","26.87665","0.00386"
"322.81200","26.90122","0.00425"
"323.10600","26.92568","0.00394"
"323.40000","26.95025","0.00333"
"323.69400","26.97464","0.00422"
"323.98800","26.99916","0.00351"
"324.28200","27.02367","0.00398"
"324.57600","27.04819","0.00326"
"324.87000","27.07270","0.00371"
"325.16400","27.09721","0.00386"
"325.45800","27.12167","0.00415"
"325.75200","27.14612","0.00381"
"326.04600","27.17064","0.00374"
"326.34000","27.19515","0.00415"
"326.63400","27.21966","0.00337"
"326.92800","27.24418","0.00311"
"327.22200","27.26869","0.00333"
"327.51600","27.29321","0.00359"
"327.81000","27.31766","0.00341"
"328.10400","27.34223","0.00359"
"328.39800","27.36669","0.00327"
"328.69200","27.39120","0.00343"
"328.98600","27.41559","0.00383"
"329.28000","27.44023","0.00365"
"329.57400","27.46468","0.00330"
"329.86800","27.48920","0.00351"
"330.16200","27.51371","0.00379"
"330.45600","27.53816","0.00346"
"330.75000","27.56274","0.00304"
"331.04400","27.58713","0.00340"
"331.33800","27.61170","0.00383"
"331.63200","27.63616","0.00308"
"331.92600","27.66067","0.00340"
"332.22000","27.68513","0.00396"
"332.51400","27.70976","0.00317"
"332.80800","27.73421","0.00360"
"333.10200","27.75872","0.00304"
"333.39600","27.78318","0.00329"
"333.69000","27.80769","0.00363"
"333.98400","27.83227","0.00320"
"334.27800","27.85666","0.00379"
"334.57200","27.88124","0.00363"
"334.86600","27.90569","0.00311"
"335.16000","27.93020","0.00381"
"335.45400","27.95465","0.00332"
"335.74800","27.97917","0.00382"
"336.04200","28.00368","0.00359"
"336.33600","28.02820","0.00321"
"336.63000","28.05271","0.00378"
"336.92400","28.07717","0.00285"
"337.21800","28.10168","0.00317"
"337.51200","28.12613","0.00298"
"337.80600","28.15071","0.00339"
"338.10000","28.17510","0.00275"
"338.39400","28.19967","0.00355"
"338.68800","28.22413","0.00357"
"338.98200","28.24870","0.00283"
"339.27600","28.27316","0.00327"
"339.57000","28.29773","0.00342"
"339.86400","28.32224","0.00312"
"340.15800","28.34669","0.00300"
"340.45200","28.37121","0.00297"
"340.74600","28.39566","0.00323"
"341.04000","28.42018","0.00388"
"341.33400","28.44463","0.00305"
"341.62800","28.46921","0.00305"
"341.92200","28.49366","0.00301"
"342.21600","28.51823","0.00303"
"342.51000","28.54269","0.00351"
"342.80400","28.56714","0.00311"
"343.09800","28.59166","0.00297"
"343.39200","28.61617","0.00310"
"343.68600","28.64068","0.00280"
"343.98000","28.66520","0.00317"
"344.27400","28.68971","0.00351"
"344.56800","28.71416","0.00359"
"344.86200","28.73868","0.00310"
"345.15600","28.76313","0.00378"
"345.45000","28.78770","0.00319"
"345.74400","28.81222","0.00360"
"346.03800","28.83673","0.00317"
"346.33200","28.86125","0.00355"
"346.62600","28.88570","0.00315"
"346.92000","28.91021","0.00309"
"347.21400","28.93461","0.00291"
"347.50800","28.95918","0.00366"
"347.80200","28.98363","0.00326"
"348.09600","29.00821","0.00324"
"348.39000","29.03266","0.00331"
"348.68400","29.05717","0.00330"
"348.97800","29.08163","0.00334"
"349.27200","29.10614","0.00296"
"349.56600","29.13066","0.00332"
"349.86000","29.15517","0.00340"
"350.15400","29.17974","0.00337"
"350.44800","29.20414","0.00334"
"350.74200","29.22871","0.00353"
"351.03600","29.25311","0.00322"
"351.33000","29.27774","0.00279"
"351.62400","29.30219","0.00349"
"351.91800","29.32671","0.00327"
"352.21200","29.35116","0.00255"
"352.50600","29.37574","0.00292"
"352.80000","29.40019","0.00304"
"353.09400","29.42470","0.00352"
"353.38800","29.44922","0.00329"
"353.68200","29.47367","0.00278"
"353.97600","29.49818","0.00296"
"354.27000","29.52264","0.00331"
"354.56400","29.54721","0.00342"
"354.85800","29.57166","0.00280"
"355.15200","29.59618","0.00316"
"355.44600","29.62069","0.00361"
"355.74000","29.64515","0.00270"
"356.03400","29.66972","0.00330"
"356.32800","29.69417","0.00302"
"356.62200","29.71875","0.00292"
"356.91600","29.74314","0.00323"
"357.21000","29.76771","0.00325"
"357.50400","29.79217","0.00302"
"357.79800","29.81668","0.00299"
"358.09200","29.84120","0.00361"
"358.38600","29.86577","0.00366"
"358.68000","29.89017","0.00336"
"358.97400","29.91468","0.00257"
"359.26800","29.93919","0.00302"
"359.56200","29.96365","0.00284"
"359.85600","29.98816","0.00316"
"360.15000","30.01261","0.00289"
"360.44400","30.03719","0.00285"
"360.73800","30.06164","0.00304"
"361.03200","30.08621","0.00328"
"361.32600","30.11067","0.00320"
"361.62000","30.13524","0.00271"
"361.91400","30.15969","0.00322"
"362.20800","30.18415","0.00255"
"362.50200","30.20866","0.00311"
"362.79600","30.23311","0.00345"
"363.09000","30.25775","0.00293"
"363.38400","30.28214","0.00300"
"363.67800","30.30672","0.00303"
"363.97200","30.33117","0.00279"
"364.26600","30.35574","0.00306"
"364.56000","30.38020","0.00286"
"364.85400","30.40465","0.00270"
"365.14800","30.42917","0.00300"
"365.44200","30.45368","0.00312"
"365.73600","30.47825","0.00357"
"366.03000","30.50265","0.00282"
"366.32400","30.52716","0.00305"
"366.61800","30.55167","0.00272"
"366.91200","30.57619","0.00318"
"367.20600","30.60058","0.00277"
"367.50000","30.62522","0.00282"
"367.79400","30.64967","0.00260"
"368.08800","30.67418","0.00242"
"368.38200","30.69870","0.00320"
"368.67600","30.72321","0.00276"
"368.97000","30.74767","0.00369"
"369.26400","30.77218","0.00322"
"369.55800","30.79675","0.00257"
"369.85200","30.82121","0.00377"
"370.14600","30.84572","0.00320"
"370.44000","30.87017","0.00360"
"370.73400","30.89469","0.00311"
"371.02800","30.91920","0.00287"
"371.32200","30.94371","0.00287"
"371.61600","30.96817","0.00312"
"371.91000","30.99268","0.00317"
"372.20400","31.01726","0.00335"
"372.49800","31.04171","0.00328"
"372.79200","31.06622","0.00304"
"373.08600","31.09062","0.00323"
"373.38000","31.11519","0.00272"
"373.67400","31.13959","0.00357"
"373.96800","31.16422","0.00272"
"374.26200","31.18867","0.00274"
"374.55600","31.21318","0.00267"
"374.85000","31.23764","0.00322"
"375.14400","31.26215","0.00292"
"375.43800","31.28673","0.00288"
"375.73200","31.31118","0.00316"
"376.02600","31.33575","0.00280"
"376.32000","31.36015","0.00276"
"376.61400","31.38472","0.00308"
"376.90800","31.40917","0.00286"
"377.20200","31.43369","0.00291"
"377.49600","31.45814","0.00325"
"377.79000","31.48272","0.00312"
"378.08400","31.50717","0.00310"
"378.37800","31.53168","0.00275"
"378.67200","31.55620","0.00300"
"378.96600","31.58065","0.00262"
"379.26000","31.60517","0.00312"
"379.55400","31.62962","0.00338"
"379.84800","31.65413","0.00269"
"380.14200","31.67865","0.00309"
"380.43600","31.70316","0.00269"
"380.73000","31.72767","0.00361"
"381.02400","31.75219","0.00258"
"381.31800","31.77676","0.00282"
"381.61200","31.80116","0.00247"
"381.90600","31.82567","0.00296"
"382.20000","31.85012","0.00281"
"382.49400","31.87470","0.00283"
"382.78800","31.89915","0.00300"
"383.08200","31.92372","0.00330"
"383.37600","31.94818","0.00327"
"383.67000","31.97269","0.00312"
"383.96400","31.99714","0.00307"
"384.25800","32.02166","0.00288"
"384.55200","32.04617","0.00276"
"384.84600","32.07069","0.00300"
"385.14000","32.09520","0.00269"
"385.43400","32.11966","0.00270"
"385.72800","32.14417","0.00362"
"386.02200","32.16862","0.00302"
"386.31600","32.19320","0.00352"
"386.61000","32.21765","0.00320"
"386.90400","32.24222","0.00283"
"387.19800","32.26674","0.00299"
"387.49200","32.29125","0.00329"
"387.78600","32.31570","0.00297"
"388.08000","32.34016","0.00366"
"388.37400","32.36473","0.00305"
"388.66800","32.38919","0.00302"
"388.96200","32.41376","0.00355"
"389.25600","32.43815","0.00299"
"389.55000","32.46267","0.00311"
"389.84400","32.48712","0.00343"
"390.13800","32.51169","0.00343"
"390.43200","32.53615","0.00335"
"390.72600","32.56066","0.00355"
"391.02000","32.58523","0.00311"
"391.31400","32.60963","0.00286"
"391.60800","32.63420","0.00321"
"391.90200","32.65866","0.00295"
"392.19600","32.68317","0.00298"
"392.49000","32.70762","0.00321"
"392.78400","32.73220","0.00274"
"393.07800","32.75665","0.00276"
"393.37200","32.78122","0.00335"
"393.66600","32.80568","0.00359"
"393.96000","32.83019","0.00303"
"394.25400","32.85471","0.00344"
"394.54800","32.87916","0.00326"
"394.84200","32.90374","0.00367"
"395.13600","32.92819","0.00321"
"395.43000","32.95270","0.00361"
"395.72400","32.97716","0.00355"
"396.01800","33.00173","0.00331"
"396.31200","33.02612","0.00372"
"396.60600","33.05064","0.00314"
"396.90000","33.07515","0.00285"
"397.19400","33.09966","0.00337"
"397.48800","33.12418","0.00252"
"397.78200","33.14857","0.00328"
"398.07600","33.17321","0.00286"
"398.37000","33.19760","0.00358"
"398.66400","33.22217","0.00311"
"398.95800","33.24662","0.00395"
"399.25200","33.27126","0.00305"
"399.54600","33.29571","0.00300"
"399.84000","33.32023","0.00301"
"400.13400","33.34474","0.00279"
"400.42800","33.36919","0.00307"
"400.72200","33.39371","0.00384"
"401.01600","33.41816","0.00339"
"401.31000","33.44268","0.00335"
"401.60400","33.46719","0.00311"
"401.89800","33.49176","0.00365"
"402.19200","33.51610","0.00333"
"402.48600","33.54073","0.00338"
"402.78000","33.56519","0.00367"
"403.07400","33.58964","0.00282"
"403.36800","33.61422","0.00306"
"403.66200","33.63867","0.00364"
"403.95600","33.66318","0.00350"
"404.25000","33.68764","0.00316"
"404.54400","33.71215","0.00331"
"404.83800","33.73666","0.00335"
"405.13200","33.76118","0.00285"
"405.42600","33.78563","0.00359"
"405.72000","33.81020","0.00334"
"406.01400","33.83472","0.00248"
"406.30800","33.85923","0.00323"
"406.60200","33.88368","0.00282"
"406.89600","33.90820","0.00321"
"407.19000","33.93271","0.00280"
"407.48400","33.95716","0.00321"
"407.77800","33.98174","0.00357"
"408.07200","34.00613","0.00315"
"408.36600","34.03070","0.00354"
"408.66000","34.05510","0.00306"
"408.95400","34.07967","0.00322"
"409.24800","34.10419","0.00361"
"409.54200","34.12864","0.00314"
"409.83600","34.15316","0.00347"
"410.13000","34.17761","0.00296"
"410.42400","34.20218","0.00299"
"410.71800","34.22664","0.00345"
"411.01200","34.25121","0.00293"
"411.30600","34.27567","0.00296"
"411.60000","34.30024","0.00272"
"411.89400","34.32469","0.00261"
"412.18800","34.34921","0.00293"
"412.48200","34.37372","0.00312"
"412.77600","34.39817","0.00311"
"413.07000","34.42269","0.00281"
"413.36400","34.44720","0.00317"
"413.65800","34.47171","0.00322"
"413.95200","34.49617","0.00312"
"414.24600","34.52068","0.00268"
"414.54000","34.54519","0.00288"
"414.83400","34.56971","0.00297"
"415.12800","34.59410","0.00320"
"415.42200","34.61868","0.00282"
"415.71600","34.64319","0.00346"
"416.01000","34.66764","0.00344"
"416.30400","34.69222","0.00301"
"416.59800","34.71667","0.00306"
"416.89200","34.74125","0.00320"
"417.18600","34.76564","0.00353"
"417.48000","34.79028","0.00283"
"417.77400","34.81467","0.00338"
"418.06800","34.83918","0.00276"
"418.36200","34.86364","0.00346"
"418.65600","34.88821","0.00307"
"418.95000","34.91267","0.00297"
"419.24400","34.93724","0.00313"
"419.53800","34.96175","0.00305"
"419.83200","34.98615","0.00379"
"420.12600","35.01066","0.00342"
"420.42000","35.03511","0.00332"
"420.71400","35.05969","0.00284"
"421.00800","35.08414","0.00349"
"421.30200","35.10865","0.00260"
"421.59600","35.13317","0.00280"
"421.89000","35.15768","0.00264"
"422.18400","35.18219","0.00253"
"422.47800","35.20665","0.00276"
"422.77200","35.23122","0.00315"
"423.06600","35.25562","0.00340"
"423.36000","35.28019","0.00293"
"423.65400","35.30464","0.00286"
"423.94800","35.32922","0.00303"
"424.24200","35.35367","0.00303"
"424.53600","35.37819","0.00222"
"424.83000","35.40269","0.00326"
"425.12400","35.42727","0.00305"
"425.41800","35.45173","0.00236"
"425.71200","35.47618","0.00248"
"426.00600","35.50076","0.00310"
"426.30000","35.52515","0.00292"
"426.59400","35.54972","0.00250"
"426.88800","35.57412","0.00268"
"427.18200","35.59869","0.00251"
"427.47600","35.62308","0.00288"
"427.77000","35.64772","0.00290"
"428.06400","35.67217","0.00342"
"428.35800","35.69668","0.00332"
"428.65200","35.72114","0.00248"
"428.94600","35.74565","0.00287"
"429.24000","35.77022","0.00264"
"429.53400","35.79468","0.00285"
"429.82800","35.81919","0.00237"
"430.12200","35.84364","0.00275"
"430.41600","35.86822","0.00282"
"430.71000","35.89267","0.00316"
"431.00400","35.91719","0.00284"
"431.29800","35.94164","0.00284"
"431.59200","35.96616","0.00372"
"431.88600","35.99067","0.00267"
"432.18000","36.01518","0.00247"
"432.47400","36.03975","0.00253"
"432.76800","36.06415","0.00295"
"433.06200","36.08867","0.00269"
"433.35600","36.11312","0.00269"
"433.65000","36.13769","0.00300"
"433.94400","36.16214","0.00325"
"434.23800","36.18666","0.00310"
"434.53200","36.21117","0.00273"
"434.82600","36.23569","0.00313"
"435.12000","36.26020","0.00243"
"435.41400","36.28465","0.00252"
"435.70800","36.30923","0.00277"
"436.00200","36.33368","0.00309"
"436.29600","36.35826","0.00272"
"436.59000","36.38265","0.00266"
"436.88400","36.40722","0.00254"
"437.17800","36.43167","0.00258"
"437.47200","36.45625","0.00303"
"437.76600","36.48070","0.00260"
"438.06000","36.50515","0.00314"
"438.35400","36.52967","0.00290"
"438.64800","36.55418","0.00299"
"438.94200","36.57870","0.00299"
"439.23600","36.60315","0.00267"
"439.53000","36.62767","0.00305"
"439.82400","36.65212","0.00304"
"440.11800","36.67669","0.00267"
"440.41200","36.70115","0.00263"
"440.44800","36.70420","0.00236"