File: Force_trajectories/170226_2/Specimen_RawData_6.csv
End date,"2/26/2017"
Specimen label,"8CG_70"
Maximum Load,"0.16260",N

Time,Extension,Load
(s),(mm),(N)
"0.00000","0.00000","-0.00008"
"0.50400","0.04227","0.00166"
"1.00800","0.08418","0.00258"
"1.51200","0.12622","0.00308"
"2.01600","0.16819","0.00307"
"2.52000","0.21022","0.00353"
"3.02400","0.25219","0.00306"
"3.52800","0.29422","0.00275"
"4.03200","0.33620","0.00395"
"4.53600","0.37817","0.00479"
"5.04000","0.42008","0.00482"
"5.54400","0.46217","0.00439"
"6.04800","0.50415","0.00477"
"6.55200","0.54618","0.00554"
"7.05600","0.58809","0.00491"
"7.56000","0.63018","0.00554"
"8.06400","0.67221","0.00540"
"8.56800","0.71425","0.00570"
"9.07200","0.75616","0.00614"
"9.57600","0.79825","0.00643"
"10.08000","0.84016","0.00619"
"10.58400","0.88225","0.00583"
"11.08800","0.92417","0.00582"
"11.59200","0.96620","0.00666"
"12.09600","1.00817","0.00624"
"12.60000","1.05020","0.00650"
"13.10400","1.09212","0.00757"
"13.60800","1.13421","0.00709"
"14.11200","1.17618","0.00766"
"14.61600","1.21815","0.00780"
"15.12000","1.26018","0.00888"
"15.62400","1.30216","0.00818"
"16.12800","1.34425","0.00807"
"16.63200","1.38622","0.00872"
"17.13600","1.42819","0.00921"
"17.64000","1.47022","0.00849"
"18.14400","1.51220","0.00873"
"18.64800","1.55423","0.00932"
"19.15200","1.59620","0.00920"
"19.65600","1.63811","0.00961"
"20.16000","1.68021","0.00977"
"20.66400","1.72218","0.01015"
"21.16800","1.76415","0.01046"
"21.67200","1.80618","0.01069"
"22.17600","1.84821","0.01035"
"22.68000","1.89019","0.01038"
"23.18400","1.93222","0.01123"
"23.68800","1.97419","0.01094"
"24.19200","2.01622","0.01167"
"24.69600","2.05825","0.01115"
"25.20000","2.10023","0.01107"
"25.70400","2.14214","0.01094"
"26.20800","2.18423","0.01150"
"26.71200","2.22620","0.01114"
"27.21600","2.26824","0.01174"
"27.72000","2.31015","0.01150"
"28.22400","2.35218","0.01178"
"28.72800","2.39415","0.01226"
"29.23200","2.43612","0.01231"
"29.73600","2.47810","0.01165"
"30.24000","2.52019","0.01173"
"30.74400","2.56216","0.01143"
"31.24800","2.60419","0.01174"
"31.75200","2.64616","0.01199"
"32.25600","2.68820","0.01213"
"32.76000","2.73017","0.01217"
"33.26400","2.77220","0.01223"
"33.76800","2.81417","0.01188"
"34.27200","2.85627","0.01192"
"34.77600","2.89818","0.01237"
"35.28000","2.94027","0.01215"
"35.78400","2.98218","0.01252"
"36.28800","3.02415","0.01324"
"36.79200","3.06613","0.01215"
"37.29600","3.10810","0.01225"
"37.80000","3.15013","0.01230"
"38.30400","3.19216","0.01237"
"38.80800","3.23414","0.01259"
"39.31200","3.27617","0.01239"
"39.81600","3.31820","0.01293"
"40.32000","3.36023","0.01291"
"40.82400","3.40220","0.01321"
"41.32800","3.44424","0.01301"
"41.83200","3.48621","0.01248"
"42.33600","3.52818","0.01260"
"42.84000","3.57027","0.01228"
"43.34400","3.61218","0.01283"
"43.84800","3.65422","0.01281"
"44.35200","3.69613","0.01242"
"44.85600","3.73816","0.01376"
"45.36000","3.78013","0.01253"
"45.86400","3.82217","0.01318"
"46.36800","3.86414","0.01335"
"46.87200","3.90623","0.01301"
"47.37600","3.94820","0.01381"
"47.88000","3.99023","0.01336"
"48.38400","4.03221","0.01367"
"48.88800","4.07424","0.01291"
"49.39200","4.11621","0.01359"
"49.89600","4.15824","0.01354"
"50.40000","4.20015","0.01313"
"50.90400","4.24219","0.01388"
"51.40800","4.28422","0.01336"
"51.91200","4.32619","0.01259"
"52.41600","4.36816","0.01345"
"52.92000","4.41014","0.01305"
"53.42400","4.45217","0.01373"
"53.92800","4.49420","0.01395"
"54.43200","4.53611","0.01470"
"54.93600","4.57820","0.01406"
"55.44000","4.62018","0.01394"
"55.94400","4.66221","0.01419"
"56.44800","4.70418","0.01435"
"56.95200","4.74621","0.01497"
"57.45600","4.78819","0.01510"
"57.96000","4.83022","0.01478"
"58.46400","4.87219","0.01493"
"58.96800","4.91422","0.01526"
"59.47200","4.95619","0.01475"
"59.97600","4.99817","0.01347"
"60.48000","5.04014","0.01526"
"60.98400","5.08217","0.01466"
"61.48800","5.12414","0.01473"
"61.99200","5.16617","0.01438"
"62.49600","5.20815","0.01509"
"63.00000","5.25018","0.01434"
"63.50400","5.29221","0.01439"
"64.00800","5.33418","0.01442"
"64.51200","5.37621","0.01497"
"65.01600","5.41825","0.01513"
"65.52000","5.46028","0.01538"
"66.02400","5.50219","0.01538"
"66.52800","5.54422","0.01471"
"67.03200","5.58620","0.01517"
"67.53600","5.62823","0.01549"
"68.04000","5.67014","0.01520"
"68.54400","5.71217","0.01462"
"69.04800","5.75409","0.01425"
"69.55200","5.79618","0.01503"
"70.05600","5.83815","0.01400"
"70.56000","5.88018","0.01555"
"71.06400","5.92215","0.01470"
"71.56800","5.96425","0.01535"
"72.07200","6.00622","0.01586"
"72.57600","6.04819","0.01507"
"73.08000","6.09016","0.01560"
"73.58400","6.13219","0.01557"
"74.08800","6.17417","0.01596"
"74.59200","6.21620","0.01619"
"75.09600","6.25823","0.01585"
"75.60000","6.30020","0.01598"
"76.10400","6.34217","0.01567"
"76.60800","6.38415","0.01606"
"77.11200","6.42612","0.01673"
"77.61600","6.46815","0.01662"
"78.12000","6.51018","0.01661"
"78.62400","6.55222","0.01624"
"79.12800","6.59419","0.01738"
"79.63200","6.63622","0.01727"
"80.13600","6.67825","0.01734"
"80.64000","6.72022","0.01673"
"81.14400","6.76220","0.01692"
"81.64800","6.80417","0.01690"
"82.15200","6.84620","0.01794"
"82.65600","6.88817","0.01733"
"83.16000","6.93020","0.01762"
"83.66400","6.97218","0.01865"
"84.16800","7.01415","0.01729"
"84.67200","7.05612","0.01771"
"85.17600","7.09815","0.01715"
"85.68000","7.14019","0.01749"
"86.18400","7.18216","0.01663"
"86.68800","7.22413","0.01754"
"87.19200","7.26622","0.01774"
"87.69600","7.30819","0.01743"
"88.20000","7.35023","0.01814"
"88.70400","7.39220","0.01726"
"89.20800","7.43417","0.01801"
"89.71200","7.47620","0.01795"
"90.21600","7.51823","0.01859"
"90.72000","7.56021","0.01871"
"91.22400","7.60218","0.01885"
"91.72800","7.64409","0.01887"
"92.23200","7.68618","0.01949"
"92.73600","7.72810","0.01880"
"93.24000","7.77013","0.01949"
"93.74400","7.81210","0.01931"
"94.24800","7.85419","0.01958"
"94.75200","7.89616","0.01941"
"95.25600","7.93826","0.01991"
"95.76000","7.98017","0.01989"
"96.26400","8.02220","0.02020"
"96.76800","8.06423","0.02093"
"97.27200","8.10620","0.01974"
"97.77600","8.14824","0.02044"
"98.28000","8.19021","0.02045"
"98.78400","8.23218","0.02045"
"99.28800","8.27415","0.02110"
"99.79200","8.31619","0.02046"
"100.29600","8.35810","0.02028"
"100.80000","8.40013","0.02063"
"101.30400","8.44216","0.01955"
"101.80800","8.48419","0.02044"
"102.31200","8.52617","0.02005"
"102.81600","8.56820","0.02031"
"103.32000","8.61017","0.02047"
"103.82400","8.65226","0.02061"
"104.32800","8.69423","0.02059"
"104.83200","8.73621","0.02097"
"105.33600","8.77818","0.02082"
"105.84000","8.82021","0.02074"
"106.34400","8.86218","0.02100"
"106.84800","8.90422","0.02120"
"107.35200","8.94613","0.02167"
"107.85600","8.98822","0.02151"
"108.36000","9.03013","0.02154"
"108.86400","9.07216","0.02242"
"109.36800","9.11414","0.02193"
"109.87200","9.15617","0.02244"
"110.37600","9.19814","0.02216"
"110.88000","9.24023","0.02231"
"111.38400","9.28221","0.02248"
"111.88800","9.32424","0.02246"
"112.39200","9.36621","0.02266"
"112.89600","9.40818","0.02233"
"113.40000","9.45021","0.02210"
"113.90400","9.49219","0.02214"
"114.40800","9.53416","0.02254"
"114.91200","9.57619","0.02272"
"115.41600","9.61816","0.02293"
"115.92000","9.66019","0.02297"
"116.42400","9.70211","0.02357"
"116.92800","9.74414","0.02355"
"117.43200","9.78617","0.02293"
"117.93600","9.82820","0.02360"
"118.44000","9.87018","0.02400"
"118.94400","9.91215","0.02410"
"119.44800","9.95418","0.02405"
"119.95200","9.99621","0.02424"
"120.45600","10.03818","0.02406"
"120.96000","10.08016","0.02404"
"121.46400","10.12225","0.02316"
"121.96800","10.16428","0.02389"
"122.47200","10.20619","0.02303"
"122.97600","10.24817","0.02332"
"123.48000","10.29020","0.02380"
"123.98400","10.33217","0.02434"
"124.48800","10.37414","0.02385"
"124.99200","10.41611","0.02372"
"125.49600","10.45815","0.02448"
"126.00000","10.50018","0.02451"
"126.50400","10.54221","0.02394"
"127.00800","10.58412","0.02357"
"127.51200","10.62615","0.02474"
"128.01600","10.66819","0.02493"
"128.52000","10.71022","0.02502"
"129.02400","10.75219","0.02461"
"129.52800","10.79416","0.02462"
"130.03200","10.83626","0.02511"
"130.53600","10.87823","0.02563"
"131.04000","10.92020","0.02603"
"131.54400","10.96217","0.02569"
"132.04800","11.00414","0.02593"
"132.55200","11.04618","0.02626"
"133.05600","11.08815","0.02595"
"133.56000","11.13018","0.02615"
"134.06400","11.17215","0.02641"
"134.56800","11.21418","0.02657"
"135.07200","11.25622","0.02649"
"135.57600","11.29819","0.02605"
"136.08000","11.34022","0.02632"
"136.58400","11.38219","0.02688"
"137.08800","11.42423","0.02702"
"137.59200","11.46626","0.02682"
"138.09600","11.50823","0.02789"
"138.60000","11.55020","0.02688"
"139.10400","11.59217","0.02774"
"139.60800","11.63421","0.02744"
"140.11200","11.67612","0.02770"
"140.61600","11.71815","0.02746"
"141.12000","11.76018","0.02819"
"141.62400","11.80216","0.02787"
"142.12800","11.84419","0.02829"
"142.63200","11.88622","0.02830"
"143.13600","11.92819","0.02834"
"143.64000","11.97016","0.02879"
"144.14400","12.01219","0.02830"
"144.64800","12.05417","0.02865"
"145.15200","12.09620","0.02935"
"145.65600","12.13817","0.02916"
"146.16000","12.18020","0.02907"
"146.66400","12.22224","0.02936"
"147.16800","12.26421","0.02916"
"147.67200","12.30612","0.02941"
"148.17600","12.34815","0.02941"
"148.68000","12.39012","0.02319"
"149.18400","12.43216","0.02673"
"149.68800","12.47419","0.02555"
"150.19200","12.51616","0.02285"
"150.69600","12.55819","0.02406"
"151.20000","12.60023","0.02521"
"151.70400","12.64220","0.02540"
"152.20800","12.68423","0.02689"
"152.71200","12.72620","0.02696"
"153.21600","12.76824","0.02778"
"153.72000","12.81021","0.02759"
"154.22400","12.85224","0.02819"
"154.72800","12.89421","0.02106"
"155.23200","12.93618","0.02290"
"155.73600","12.97810","0.02171"
"156.24000","13.02013","0.01101"
"156.74400","13.06216","0.01173"
"157.24800","13.10413","0.01231"
"157.75200","13.14616","0.01273"
"158.25600","13.18820","0.01417"
"158.76000","13.23017","0.01437"
"159.26400","13.27220","0.01512"
"159.76800","13.31417","0.01565"
"160.27200","13.35620","0.01677"
"160.77600","13.39818","0.01835"
"161.28000","13.44021","0.01800"
"161.78400","13.48218","0.01930"
"162.28800","13.52415","0.01953"
"162.79200","13.56618","0.02086"
"163.29600","13.60816","0.02155"
"163.80000","13.65013","0.02241"
"164.30400","13.69210","0.02336"
"164.80800","13.73413","0.02330"
"165.31200","13.77617","0.02458"
"165.81600","13.81814","0.02511"
"166.32000","13.86017","0.02575"
"166.82400","13.90220","0.02649"
"167.32800","13.94424","0.02671"
"167.83200","13.98621","0.02707"
"168.33600","14.02818","0.02715"
"168.84000","14.07021","0.02752"
"169.34400","14.11224","0.02798"
"169.84800","14.15422","0.02804"
"170.35200","14.19619","0.02833"
"170.85600","14.23816","0.02892"
"171.36000","14.28019","0.02890"
"171.86400","14.32216","0.02921"
"172.36800","14.36408","0.02901"
"172.87200","14.40611","0.02972"
"173.37600","14.44820","0.03075"
"173.88000","14.49017","0.03028"
"174.38400","14.53215","0.03022"
"174.88800","14.57418","0.03038"
"175.39200","14.61621","0.03031"
"175.89600","14.65824","0.03121"
"176.40000","14.70015","0.03136"
"176.90400","14.74224","0.03093"
"177.40800","14.78422","0.03020"
"177.91200","14.82619","0.03087"
"178.41600","14.86816","0.03079"
"178.92000","14.91013","0.03088"
"179.42400","14.95217","0.03121"
"179.92800","14.99420","0.03167"
"180.43200","15.03611","0.03154"
"180.93600","15.07808","0.03208"
"181.44000","15.12018","0.03184"
"181.94400","15.16221","0.03226"
"182.44800","15.20418","0.03213"
"182.95200","15.24621","0.03210"
"183.45600","15.28824","0.03217"
"183.96000","15.33022","0.03316"
"184.46400","15.37225","0.03237"
"184.96800","15.41416","0.03205"
"185.47200","15.45625","0.03210"
"185.97600","15.49822","0.03265"
"186.48000","15.54020","0.03302"
"186.98400","15.58217","0.03347"
"187.48800","15.62420","0.03347"
"187.99200","15.66611","0.03333"
"188.49600","15.70815","0.03409"
"189.00000","15.75012","0.03404"
"189.50400","15.79221","0.03462"
"190.00800","15.83418","0.03432"
"190.51200","15.87621","0.03485"
"191.01600","15.91819","0.03486"
"191.52000","15.96022","0.03568"
"192.02400","16.00219","0.03457"
"192.52800","16.04422","0.03479"
"193.03200","16.08619","0.03546"
"193.53600","16.12817","0.03637"
"194.04000","16.17020","0.03682"
"194.54400","16.21217","0.03674"
"195.04800","16.25414","0.03730"
"195.55200","16.29618","0.03720"
"196.05600","16.33809","0.03781"
"196.56000","16.38018","0.03800"
"197.06400","16.42215","0.03834"
"197.56800","16.46418","0.03847"
"198.07200","16.50616","0.03931"
"198.57600","16.54819","0.03948"
"199.08000","16.59022","0.03964"
"199.58400","16.63219","0.03936"
"200.08800","16.67422","0.03963"
"200.59200","16.71620","0.04005"
"201.09600","16.75823","0.04024"
"201.60000","16.80020","0.04128"
"202.10400","16.84217","0.04122"
"202.60800","16.88421","0.04155"
"203.11200","16.92618","0.04131"
"203.61600","16.96815","0.04117"
"204.12000","17.01018","0.04018"
"204.62400","17.05209","0.03694"
"205.12800","17.09418","0.03778"
"205.63200","17.13622","0.03714"
"206.13600","17.17819","0.02801"
"206.64000","17.22016","0.02862"
"207.14400","17.26219","0.02881"
"207.64800","17.30423","0.03113"
"208.15200","17.34626","0.02648"
"208.65600","17.38817","0.02633"
"209.16000","17.43020","0.02825"
"209.66400","17.47223","0.02772"
"210.16800","17.51421","0.02865"
"210.67200","17.55612","0.02994"
"211.17600","17.59815","0.02916"
"211.68000","17.64013","0.02959"
"212.18400","17.68216","0.03007"
"212.68800","17.72413","0.03278"
"213.19200","17.76616","0.03093"
"213.69600","17.80813","0.03209"
"214.20000","17.85022","0.03058"
"214.70400","17.89220","0.02847"
"215.20800","17.93423","0.02819"
"215.71200","17.97620","0.02966"
"216.21600","18.01823","0.02979"
"216.72000","18.06021","0.03101"
"217.22400","18.10218","0.03273"
"217.72800","18.14415","0.03259"
"218.23200","18.18624","0.03362"
"218.73600","18.22821","0.03476"
"219.24000","18.27019","0.03533"
"219.74400","18.31210","0.03654"
"220.24800","18.35413","0.03706"
"220.75200","18.39616","0.03786"
"221.25600","18.43820","0.03833"
"221.76000","18.48017","0.03894"
"222.26400","18.52214","0.03943"
"222.76800","18.56417","0.04042"
"223.27200","18.60620","0.04092"
"223.77600","18.64818","0.04146"
"224.28000","18.69015","0.04212"
"224.78400","18.73224","0.04286"
"225.28800","18.77421","0.04256"
"225.79200","18.81618","0.04276"
"226.29600","18.85822","0.04343"
"226.80000","18.90019","0.04389"
"227.30400","18.94216","0.04416"
"227.80800","18.98419","0.04415"
"228.31200","19.02611","0.04458"
"228.81600","19.06820","0.04522"
"229.32000","19.11011","0.04522"
"229.82400","19.15220","0.04605"
"230.32800","19.19417","0.04563"
"230.83200","19.23621","0.04595"
"231.33600","19.27824","0.04575"
"231.84000","19.32021","0.04646"
"232.34400","19.36212","0.04679"
"232.84800","19.40428","0.04672"
"233.35200","19.44619","0.04667"
"233.85600","19.48822","0.04625"
"234.36000","19.53019","0.04678"
"234.86400","19.57216","0.04710"
"235.36800","19.61414","0.04678"
"235.87200","19.65617","0.04671"
"236.37600","19.69814","0.04697"
"236.88000","19.74017","0.04704"
"237.38400","19.78220","0.04732"
"237.88800","19.82418","0.04729"
"238.39200","19.86621","0.04770"
"238.89600","19.90818","0.04830"
"239.40000","19.95015","0.04837"
"239.90400","19.99218","0.04845"
"240.40800","20.03422","0.04870"
"240.91200","20.07625","0.04892"
"241.41600","20.11822","0.04937"
"241.92000","20.16019","0.04974"
"242.42400","20.20217","0.05015"
"242.92800","20.24414","0.05063"
"243.43200","20.28617","0.05089"
"243.93600","20.32814","0.05121"
"244.44000","20.37017","0.05150"
"244.94400","20.41215","0.05187"
"245.44800","20.45424","0.05253"
"245.95200","20.49621","0.05285"
"246.45600","20.53818","0.05310"
"246.96000","20.58022","0.05337"
"247.46400","20.62219","0.05446"
"247.96800","20.66416","0.05252"
"248.47200","20.70625","0.05055"
"248.97600","20.74817","0.05025"
"249.48000","20.79026","0.05160"
"249.98400","20.83223","0.05251"
"250.48800","20.87420","0.05336"
"250.99200","20.91617","0.05331"
"251.49600","20.95821","0.05370"
"252.00000","21.00011","0.05465"
"252.50400","21.04215","0.05474"
"253.00800","21.08412","0.05534"
"253.51200","21.12621","0.05669"
"254.01600","21.16813","0.05762"
"254.52000","21.21016","0.05812"
"255.02400","21.25219","0.05945"
"255.52800","21.29422","0.06027"
"256.03200","21.33619","0.06184"
"256.53600","21.37823","0.06298"
"257.04000","21.42020","0.06324"
"257.54400","21.46223","0.06344"
"258.04800","21.50420","0.06469"
"258.55200","21.54618","0.06585"
"259.05600","21.58815","0.06752"
"259.56000","21.63012","0.06865"
"260.06400","21.67215","0.07029"
"260.56800","21.71412","0.07131"
"261.07200","21.75615","0.07266"
"261.57600","21.79819","0.07415"
"262.08000","21.84022","0.07324"
"262.58400","21.88225","0.07220"
"263.08800","21.92422","0.07362"
"263.59200","21.96619","0.07584"
"264.09600","22.00823","0.07837"
"264.60000","22.05020","0.07933"
"265.10400","22.09223","0.08117"
"265.60800","22.13420","0.08289"
"266.11200","22.17624","0.08459"
"266.61600","22.21821","0.08596"
"267.12000","22.26018","0.08691"
"267.62400","22.30215","0.08841"
"268.12800","22.34413","0.09013"
"268.63200","22.38616","0.09143"
"269.13600","22.42819","0.09178"
"269.64000","22.47016","0.09334"
"270.14400","22.51219","0.09511"
"270.64800","22.55423","0.09618"
"271.15200","22.59626","0.09737"
"271.65600","22.63823","0.09885"
"272.16000","22.68020","0.10083"
"272.66400","22.72218","0.10203"
"273.16800","22.76421","0.10421"
"273.67200","22.80618","0.10615"
"274.17600","22.84821","0.10818"
"274.68000","22.89018","0.11094"
"275.18400","22.93216","0.11336"
"275.68800","22.97413","0.11574"
"276.19200","23.01616","0.11877"
"276.69600","23.05813","0.12094"
"277.20000","23.10023","0.12323"
"277.70400","23.14214","0.12513"
"278.20800","23.18423","0.12683"
"278.71200","23.22620","0.12839"
"279.21600","23.26823","0.12936"
"279.72000","23.31021","0.13140"
"280.22400","23.35218","0.13326"
"280.72800","23.39421","0.13474"
"281.23200","23.43618","0.13566"
"281.73600","23.47821","0.13683"
"282.24000","23.52019","0.13740"
"282.74400","23.56216","0.13787"
"283.24800","23.60413","0.13867"
"283.75200","23.64616","0.13966"
"284.25600","23.68813","0.14041"
"284.76000","23.73017","0.14139"
"285.26400","23.77214","0.14198"
"285.76800","23.81423","0.14325"
"286.27200","23.85620","0.14360"
"286.77600","23.89824","0.14484"
"287.28000","23.94027","0.14589"
"287.78400","23.98224","0.14729"
"288.28800","24.02415","0.14850"
"288.79200","24.06624","0.14945"
"289.29600","24.10822","0.15211"
"289.80000","24.15025","0.15508"
"290.30400","24.19216","0.15744"
"290.80800","24.23419","0.16064"
"291.31200","24.27616","-0.00853"
"291.81600","24.31820","-0.00089"
"292.32000","24.36011","0.00459"
"292.82400","24.40220","-0.00038"
"293.32800","24.44417","0.00018"
"293.83200","24.48620","0.00091"
"294.33600","24.52818","0.00028"
"294.84000","24.57021","0.00122"
"295.34400","24.61218","0.00043"
"295.84800","24.65421","0.00016"
"296.35200","24.69619","0.00108"
"296.85600","24.73822","0.00004"
"297.36000","24.78019","0.00184"
"297.86400","24.82222","0.00047"
"298.36800","24.86419","0.00047"
"298.87200","24.90617","0.00079"
"299.37600","24.94808","-0.00038"
"299.88000","24.99017","0.00123"
"300.38400","25.03214","-0.00041"
"300.88800","25.07417","0.00014"
"301.39200","25.11615","0.00009"
"301.89600","25.15824","0.00058"
"302.40000","25.20021","0.00119"
"302.90400","25.24224","0.00075"
"303.40800","25.28422","0.00091"
"303.91200","25.32619","0.00046"
"304.41600","25.36822","0.00019"
"304.92000","25.41019","0.00176"
"305.42400","25.45217","0.00053"
"305.92800","25.49420","0.00133"
"306.43200","25.53617","0.00057"
"306.93600","25.57814","0.00067"
"307.44000","25.62017","0.00065"
"307.94400","25.66220","0.00042"
"308.44800","25.70418","0.00160"
"308.95200","25.74609","0.00049"
"309.45600","25.78824","0.00111"
"309.96000","25.83015","0.00060"
"310.46400","25.87225","0.00084"
"310.96800","25.91422","0.00071"
"311.47200","25.95619","0.00073"
"311.97600","25.99822","0.00179"
"312.48000","26.04020","0.00102"
"312.98400","26.08217","0.00132"
"313.48800","26.12420","0.00075"
"313.99200","26.16617","0.00143"
"314.49600","26.20820","0.00169"
"315.00000","26.25012","0.00056"
"315.50400","26.29215","0.00081"
"316.00800","26.33418","0.00084"
"316.51200","26.37615","0.00141"
"317.01600","26.41812","0.00056"
"317.52000","26.46021","0.00125"
"318.02400","26.50219","0.00105"
"318.52800","26.54422","0.00108"
"319.03200","26.58619","0.00147"
"319.53600","26.62823","0.00139"
"320.04000","26.67020","0.00169"
"320.54400","26.71223","0.00102"
"321.04800","26.75414","0.00165"
"321.55200","26.79623","0.00114"
"322.05600","26.83815","0.00150"
"322.56000","26.88018","0.00106"
"323.06400","26.92215","0.00089"
"323.56800","26.96412","0.00146"
"324.07200","27.00616","0.00138"
"324.57600","27.04819","0.00150"
"325.08000","27.09016","0.00183"
"325.58400","27.13219","0.00190"
"326.08800","27.17422","0.00138"
"326.59200","27.21626","0.00180"
"327.09600","27.25817","0.00171"
"327.60000","27.30020","0.00180"
"328.10400","27.34223","0.00158"
"328.60800","27.38426","0.00186"
"329.11200","27.42618","0.00189"
"329.61600","27.46821","0.00187"
"330.12000","27.51018","0.00218"
"330.62400","27.55215","0.00156"
"331.12800","27.59413","0.00151"
"331.63200","27.63610","0.00112"
"332.13600","27.67819","0.00220"
"332.64000","27.72016","0.00237"
"333.14400","27.76225","0.00170"
"333.64800","27.80417","0.00215"
"334.15200","27.84620","0.00229"
"334.65600","27.88823","0.00204"
"335.16000","27.93020","0.00184"
"335.66400","27.97218","0.00209"
"336.16800","28.01421","0.00171"
"336.67200","28.05624","0.00224"
"337.17600","28.09821","0.00280"
"337.68000","28.14012","0.00227"
"338.18400","28.18216","0.00241"
"338.68800","28.22413","0.00244"
"339.19200","28.26616","0.00241"
"339.69600","28.30813","0.00251"
"340.20000","28.35016","0.00221"
"340.70400","28.39220","0.00213"
"341.20800","28.43417","0.00178"
"341.71200","28.47620","0.00197"
"342.21600","28.51817","0.00242"
"342.72000","28.56021","0.00235"
"343.22400","28.60224","0.00256"
"343.72800","28.64421","0.00262"
"344.23200","28.68618","0.00219"
"344.73600","28.72815","0.00221"
"345.24000","28.77025","0.00251"
"345.74400","28.81222","0.00274"
"346.24800","28.85419","0.00244"
"346.75200","28.89616","0.00258"
"347.25600","28.93813","0.00227"
"347.76000","28.98017","0.00281"
"348.26400","29.02220","0.00217"
"348.76800","29.06417","0.00222"
"349.27200","29.10620","0.00247"
"349.77600","29.14824","0.00261"
"350.28000","29.19021","0.00295"
"350.78400","29.23224","0.00254"
"351.28800","29.27421","0.00229"
"351.79200","29.31618","0.00252"
"352.29600","29.35822","0.00251"
"352.80000","29.40025","0.00284"
"353.30400","29.44222","0.00242"
"353.80800","29.48425","0.00268"
"354.31200","29.52617","0.00300"
"354.81600","29.56820","0.00264"
"355.32000","29.61011","0.00288"
"355.82400","29.65220","0.00308"
"356.32800","29.69417","0.00288"
"356.83200","29.73621","0.00306"
"357.33600","29.77818","0.00253"
"357.84000","29.82027","0.00322"
"358.34400","29.86218","0.00338"
"358.84800","29.90421","0.00246"
"359.35200","29.94619","0.00280"
"359.85600","29.98816","0.00308"
"360.36000","30.03019","0.00278"
"360.86400","30.07222","0.00266"
"361.36800","30.11419","0.00265"
"361.87200","30.15617","0.00333"
"362.37600","30.19814","0.00323"
"362.88000","30.24011","0.00301"
"363.38400","30.28214","0.00297"
"363.88800","30.32411","0.00312"
"364.39200","30.36615","0.00338"
"364.89600","30.40818","0.00331"
"365.40000","30.45015","0.00355"
"365.90400","30.49218","0.00329"
"366.40800","30.53422","0.00251"
"366.91200","30.57619","0.00307"
"367.41600","30.61816","0.00348"
"367.92000","30.66019","0.00316"
"368.42400","30.70217","0.00294"
"368.92800","30.74420","0.00307"
"369.43200","30.78623","0.00315"
"369.93600","30.82814","0.00338"
"370.44000","30.87017","0.00312"
"370.94400","30.91215","0.00370"
"371.44800","30.95412","0.00316"
"371.95200","30.99615","0.00377"
"372.45600","31.03812","0.00341"
"372.96000","31.08015","0.00372"
"373.46400","31.12225","0.00332"
"373.96800","31.16422","0.00383"
"374.47200","31.20619","0.00375"
"374.97600","31.24822","0.00357"
"375.48000","31.29025","0.00351"
"375.98400","31.33216","0.00352"
"376.48800","31.37420","0.00347"
"376.99200","31.41617","0.00358"
"377.49600","31.45820","0.00352"
"378.00000","31.50018","0.00326"
"378.50400","31.54221","0.00350"
"379.00800","31.58412","0.00411"
"379.51200","31.62615","0.00370"
"380.01600","31.66818","0.00418"
"380.52000","31.71016","0.00383"
"381.02400","31.75213","0.00433"
"381.52800","31.79422","0.00447"
"382.03200","31.83619","0.00423"
"382.53600","31.87823","0.00467"
"383.04000","31.92014","0.00416"
"383.54400","31.96223","0.00405"
"384.04800","32.00420","0.00387"
"384.55200","32.04623","0.00441"
"385.05600","32.08820","0.00407"
"385.56000","32.13018","0.00470"
"386.06400","32.17221","0.00434"
"386.56800","32.21418","0.00447"
"387.07200","32.25609","0.00452"
"387.57600","32.29813","0.00471"
"388.08000","32.34016","0.00455"
"388.58400","32.38219","0.00508"
"389.08800","32.42422","0.00502"
"389.59200","32.46619","0.00418"
"390.09600","32.50823","0.00484"
"390.60000","32.55020","0.00461"
"391.10400","32.59223","0.00464"
"391.60800","32.63414","0.00472"
"392.11200","32.67630","0.00507"
"392.61600","32.71821","0.00464"
"393.12000","32.76018","0.00554"
"393.62400","32.80215","0.00464"
"394.12800","32.84418","0.00479"
"394.63200","32.88615","0.00498"
"395.13600","32.92813","0.00500"
"395.64000","32.97016","0.00525"
"396.14400","33.01219","0.00483"
"396.64800","33.05416","0.00482"
"397.15200","33.09620","0.00494"
"397.65600","33.13817","0.00540"
"398.16000","33.18020","0.00492"
"398.66400","33.22217","0.00559"
"399.16800","33.26421","0.00592"
"399.67200","33.30618","0.00564"
"400.17600","33.34821","0.00528"
"400.68000","33.39018","0.00589"
"401.18400","33.43216","0.00524"
"401.68800","33.47412","0.00566"
"402.19200","33.51616","0.00493"
"402.69600","33.55807","0.00540"
"403.20000","33.60016","0.00551"
"403.70400","33.64214","0.00598"
"404.20800","33.68417","0.00564"
"404.71200","33.72614","0.00625"
"405.21600","33.76817","0.00598"
"405.72000","33.81020","0.00543"
"406.22400","33.85218","0.00607"
"406.72800","33.89421","0.00662"
"407.23200","33.93618","0.00570"
"407.73600","33.97821","0.00604"
"408.24000","34.02024","0.00616"
"408.74400","34.06215","0.00645"
"409.24800","34.10419","0.00597"
"409.75200","34.14622","0.00648"
"410.25600","34.18813","0.00625"
"410.76000","34.23016","0.00688"
"411.26400","34.27214","0.00714"
"411.76800","34.31417","0.00731"
"412.27200","34.35620","0.00727"
"412.77600","34.39817","0.00651"
"413.28000","34.44020","0.00685"
"413.78400","34.48224","0.00669"
"414.28800","34.52421","0.00676"
"414.79200","34.56624","0.00700"
"415.29600","34.60815","0.00646"
"415.80000","34.65019","0.00680"
"416.30400","34.69222","0.00715"
"416.80800","34.73419","0.00733"
"417.31200","34.77616","0.00721"
"417.81600","34.81820","0.00751"
"418.32000","34.86011","0.00731"
"418.82400","34.90214","0.00683"
"419.32800","34.94411","0.00752"
"419.83200","34.98615","0.00696"
"420.33600","35.02811","0.00736"
"420.84000","35.07021","0.00755"
"421.34400","35.11218","0.00696"
"421.84800","35.15421","0.00801"
"422.35200","35.19619","0.00753"
"422.85600","35.23822","0.00721"
"423.36000","35.28019","0.00734"
"423.86400","35.32222","0.00725"
"424.36800","35.36419","0.00708"
"424.87200","35.40622","0.00695"
"425.37600","35.44820","0.00704"
"425.88000","35.49017","0.00736"
"426.38400","35.53214","0.00731"
"426.88800","35.57418","0.00730"
"427.39200","35.61621","0.00715"
"427.89600","35.65818","0.00791"
"428.40000","35.70021","0.00788"
"428.90400","35.74212","0.00772"
"429.40800","35.78421","0.00814"
"429.91200","35.82619","0.00821"
"430.41600","35.86822","0.00803"
"430.92000","35.91019","0.00820"
"431.42400","35.95222","0.00869"
"431.92800","35.99426","0.00826"
"432.43200","36.03623","0.00822"
"432.93600","36.07820","0.00883"
"433.44000","36.12017","0.00867"
"433.94400","36.16214","0.00947"
"434.44800","36.20418","0.00941"
"434.95200","36.24609","0.00885"
"435.45600","36.28818","0.00875"
"435.96000","36.33021","0.00933"
"436.46400","36.37225","0.00873"
"436.96800","36.41416","0.00861"
"437.47200","36.45619","0.00913"
"437.97600","36.49822","0.00948"
"438.48000","36.54026","0.00955"
"438.98400","36.58216","0.00960"
"439.48800","36.62420","0.00967"
"439.99200","36.66617","0.00968"
"440.49600","36.70820","0.00933"
"441.00000","36.75018","0.01004"
"441.50400","36.79221","0.00875"
"442.00800","36.83412","0.00914"
"442.51200","36.87615","0.00958"
"443.01600","36.91818","0.00931"
"443.52000","36.96016","0.00915"
"444.02400","37.00219","0.00891"
"444.52800","37.04416","0.00938"
"445.03200","37.08619","0.00975"
"445.53600","37.12817","0.00972"
"446.04000","37.17020","0.00955"
"446.54400","37.21217","0.00937"
"447.04800","37.25420","0.00959"
"447.55200","37.29623","0.01054"
"448.05600","37.33820","0.00961"
"448.56000","37.38024","0.00967"
"449.06400","37.42221","0.00970"
"449.56800","37.46418","0.00974"
"450.07200","37.50615","0.00957"
"450.57600","37.54813","0.00986"
"451.08000","37.59016","0.00997"
"451.58400","37.63213","0.00993"
"452.08800","37.67416","0.00979"
"452.59200","37.71619","0.01056"
"453.09600","37.75823","0.01089"
"453.60000","37.80020","0.01041"
"454.10400","37.84223","0.01075"
"454.60800","37.88414","0.00986"
"455.11200","37.92624","0.01003"
"455.61600","37.96821","0.00974"
"456.12000","38.01024","0.01019"
"456.62400","38.05221","0.01053"
"457.12800","38.09425","0.01077"
"457.63200","38.13615","0.01077"
"458.13600","38.17819","0.01062"
"458.64000","38.22010","0.01097"
"459.14400","38.26219","0.01060"
"459.64800","38.30416","0.01178"
"460.15200","38.34620","0.01141"
"460.65600","38.38817","0.01094"
"461.16000","38.43020","0.01135"
"461.66400","38.47217","0.01115"
"462.16800","38.51421","0.01119"
"462.67200","38.55618","0.01178"
"463.17600","38.59821","0.01099"
"463.68000","38.64018","0.01190"
"464.18400","38.68222","0.01083"
"464.68800","38.72425","0.01174"
"465.19200","38.76616","0.01201"
"465.69600","38.80819","0.01163"
"466.20000","38.85010","0.01231"
"466.70400","38.89214","0.01123"
"467.20800","38.93417","0.01216"
"467.71200","38.97614","0.01168"
"468.21600","39.01817","0.01212"
"468.72000","39.06020","0.01177"
"469.22400","39.10223","0.01159"
"469.72800","39.14420","0.01161"
"470.23200","39.18618","0.01142"
"470.73600","39.22821","0.01146"
"471.24000","39.27018","0.01152"
"471.74400","39.31221","0.01138"
"472.24800","39.35419","0.01053"
"472.75200","39.39621","0.01111"
"473.25600","39.43819","0.01167"
"473.76000","39.48022","0.01174"
"474.26400","39.52208","0.01164"
"474.76800","39.56417","0.01187"
"475.27200","39.60614","0.01219"
"475.77600","39.64817","0.01132"
"476.28000","39.69014","0.01153"
"476.78400","39.73218","0.01190"
"477.28800","39.77421","0.01200"
"477.79200","39.81624","0.01203"
"478.29600","39.85815","0.01191"
"478.80000","39.90025","0.01221"
"479.30400","39.94216","0.01231"
"479.80800","39.98425","0.01182"
"480.31200","40.02622","0.01168"
"480.81600","40.06813","0.01219"
"481.32000","40.11017","0.01212"
"481.82400","40.15220","0.01189"
"482.32800","40.19411","0.01253"
"482.83200","40.23615","0.01263"
"483.33600","40.27812","0.01292"
"483.84000","40.32014","0.01284"
"484.34400","40.36218","0.01283"
"484.84800","40.40421","0.01209"
"485.35200","40.44619","0.01263"
"485.85600","40.48821","0.01356"
"486.36000","40.53019","0.01337"
"486.86400","40.57222","0.01344"
"487.36800","40.61420","0.01340"
"487.87200","40.65622","0.01330"
"488.37600","40.69820","0.01343"
"488.88000","40.74017","0.01367"
"489.38400","40.78220","0.01354"
"489.88800","40.82417","0.01383"
"490.39200","40.86614","0.01356"
"490.89600","40.90818","0.01376"
"491.40000","40.95021","0.01412"
"491.90400","40.99218","0.01444"
"492.40800","41.03421","0.01400"
"492.91200","41.07619","0.01415"
"493.41600","41.11822","0.01377"
"493.92000","41.16025","0.01477"
"494.42400","41.20222","0.01501"
"494.92800","41.24413","0.01483"
"495.43200","41.28622","0.01501"
"495.93600","41.32826","0.01532"
"496.44000","41.37023","0.01567"
"496.94400","41.41214","0.01593"
"497.44800","41.45418","0.01602"
"497.95200","41.49615","0.01632"
"498.45600","41.53812","0.01578"
"498.96000","41.58015","0.01621"
"499.46400","41.62218","0.01515"
"499.96800","41.66415","0.01589"
"500.47200","41.70619","0.01633"
"500.97600","41.74816","0.01634"
"501.48000","41.79020","0.01682"
"501.98400","41.83222","0.01612"
"502.48800","41.87420","0.01704"
"502.99200","41.91617","0.01636"
"503.49600","41.95820","0.01730"
"504.00000","42.00023","0.01693"
"504.50400","42.04214","0.01732"
"505.00800","42.08418","0.01762"
"505.51200","42.12615","0.01780"
"506.01600","42.16812","0.01773"
"506.52000","42.21015","0.01754"
"507.02400","42.25213","0.01801"
"507.52800","42.29416","0.01868"
"508.03200","42.33613","0.01869"
"508.53600","42.37822","0.01862"
"509.04000","42.42020","0.01796"
"509.54400","42.46223","0.01885"
"510.04800","42.50420","0.01949"
"510.55200","42.54617","0.01829"
"511.05600","42.58826","0.01917"
"511.56000","42.63018","0.01946"
"512.06400","42.67221","0.01911"
"512.56800","42.71418","0.01872"
"513.07200","42.75616","0.01857"
"513.57600","42.79812","0.01912"
"514.08000","42.84021","0.01953"
"514.58400","42.88213","0.01980"
"515.08800","42.92416","0.01911"
"515.59200","42.96613","0.01929"
"516.09600","43.00822","0.01923"
"516.60000","43.05020","0.01963"
"517.10400","43.09217","0.02060"
"517.60800","43.13420","0.01999"
"518.11200","43.17623","0.02112"
"518.61600","43.21814","0.02074"
"519.12000","43.26023","0.02089"
"519.62400","43.30221","0.02146"
"520.12800","43.34418","0.02121"
"520.63200","43.38622","0.02182"
"521.13600","43.42818","0.02182"
"521.64000","43.47010","0.02249"
"522.14400","43.51219","0.02196"
"522.64800","43.55416","0.02148"
"523.15200","43.59614","0.02199"
"523.65600","43.63816","0.02270"
"524.16000","43.68014","0.02264"
"524.66400","43.72223","0.02374"
"525.16800","43.76420","0.02253"
"525.67200","43.80623","0.02387"
"526.17600","43.84821","0.02389"
"526.68000","43.89018","0.02336"
"527.18400","43.93221","0.02403"
"527.68800","43.97419","0.02436"
"528.19200","44.01622","0.01696"
"528.69600","44.05819","0.01722"
"529.20000","44.10016","0.01762"
"529.70400","44.14214","0.01685"
"530.20800","44.18416","0.01753"
"530.71200","44.22614","0.01760"
"531.21600","44.26817","0.01900"
"531.72000","44.31020","0.01942"
"532.22400","44.35217","0.01887"
"532.72800","44.39421","0.01982"
"533.23200","44.43618","0.02001"
"533.73600","44.47821","0.02055"
"534.24000","44.52018","0.02098"
"534.74400","44.56227","0.02102"
"535.24800","44.60419","0.01996"
"535.75200","44.64622","0.02117"
"536.25600","44.68813","0.02133"
"536.76000","44.73022","0.02174"
"537.26400","44.77214","0.02183"
"537.76800","44.81417","0.02146"
"538.27200","44.85614","0.02214"
"538.77600","44.89817","0.02224"
"539.28000","44.94015","0.02337"
"539.78400","44.98224","0.02259"
"540.28800","45.02415","0.02372"
"540.79200","45.06624","0.02422"
"541.29600","45.10822","0.02454"
"541.80000","45.15019","0.02486"
"542.30400","45.19216","0.02497"
"542.80800","45.23419","0.02511"
"543.31200","45.27623","0.02534"
"543.81600","45.31825","0.02583"
"544.32000","45.36011","0.02606"
"544.82400","45.40220","0.02657"
"545.32800","45.44417","0.02597"
"545.83200","45.48615","0.02640"
"546.33600","45.52812","0.02689"
"546.84000","45.57015","0.02673"
"547.34400","45.61218","0.02659"
"547.84800","45.65415","0.02676"
"548.35200","45.69618","0.02729"
"548.85600","45.73822","0.02760"
"549.36000","45.78019","0.02806"
"549.86400","45.82222","0.02859"
"550.36800","45.86419","0.02848"
"550.87200","45.90623","0.02847"
"551.37600","45.94826","0.02849"
"551.88000","45.99023","0.02885"
"552.38400","46.03220","0.02878"
"552.88800","46.07417","0.02959"
"553.39200","46.11615","0.02976"
"553.89600","46.15812","0.02902"
"554.40000","46.20015","0.02902"
"554.90400","46.24218","0.02942"
"555.40800","46.28421","0.02983"
"555.91200","46.32619","0.02960"
"556.41600","46.36822","0.03041"
"556.92000","46.41019","0.03030"
"557.42400","46.45222","0.03036"
"557.92800","46.49420","0.02474"
"558.43200","46.53617","0.02232"
"558.93600","46.57820","0.02209"
"559.44000","46.62023","0.02331"
"559.94400","46.66220","0.02347"
"560.44800","46.70423","0.02341"
"560.95200","46.74615","0.02324"
"561.45600","46.78818","0.02410"
"561.96000","46.83010","0.02459"
"562.46400","46.87218","0.02436"
"562.96800","46.91415","0.02397"
"563.47200","46.95625","0.02463"
"563.97600","46.99816","0.02508"
"564.48000","47.04019","0.02540"
"564.98400","47.08216","0.02527"
"565.48800","47.12426","0.02501"
"565.99200","47.16617","0.02557"
"566.49600","47.20820","0.02550"
"567.00000","47.25023","0.02507"
"567.50400","47.29221","0.02554"
"568.00800","47.33424","0.02597"
"568.51200","47.37621","0.02603"
"569.01600","47.41818","0.02629"
"569.52000","47.46016","0.02709"
"570.02400","47.50212","0.02748"
"570.52800","47.54416","0.02723"
"571.03200","47.58619","0.02711"
"571.53600","47.62817","0.02679"
"572.04000","47.67019","0.02767"
"572.54400","47.71217","0.02846"
"573.04800","47.75420","0.02777"
"573.55200","47.79623","0.02826"
"574.05600","47.83820","0.02909"
"574.56000","47.88017","0.02958"
"575.06400","47.92221","0.02902"
"575.56800","47.96418","0.02978"
"576.07200","48.00627","0.02931"
"576.57600","48.04818","0.02834"
"577.08000","48.09016","0.02768"
"577.58400","48.13213","0.02826"
"578.08800","48.17416","0.02818"
"578.59200","48.21613","0.02855"
"579.09600","48.25816","0.02878"
"579.60000","48.30014","0.02842"
"580.10400","48.34217","0.02863"
"580.60800","48.38420","0.02797"
"581.11200","48.42624","0.02806"
"581.61600","48.46820","0.02823"
"582.12000","48.51017","0.02793"
"582.62400","48.55215","0.02870"
"583.12800","48.59424","0.02890"
"583.63200","48.63616","0.02897"
"584.13600","48.67818","0.02825"
"584.64000","48.72016","0.02910"
"585.14400","48.76213","0.02896"
"585.64800","48.80410","0.02889"
"586.15200","48.84614","0.02929"
"586.65600","48.88817","0.02801"
"587.16000","48.93014","0.02820"
"587.66400","48.97218","0.02786"
"588.16800","49.01420","0.02736"
"588.67200","49.05617","0.02819"
"589.17600","49.09821","0.02831"
"589.68000","49.14018","0.02850"
"590.18400","49.18221","0.02799"
"590.68800","49.22418","0.02802"
"591.19200","49.26622","0.02836"
"591.69600","49.30819","0.02797"
"592.20000","49.35017","0.02805"
"592.70400","49.39219","0.02797"
"593.20800","49.43416","0.02804"
"593.71200","49.47614","0.02835"
"594.21600","49.51811","0.02814"
"594.72000","49.56020","0.02855"
"595.22400","49.60217","0.02862"
"595.72800","49.64426","0.02771"
"596.23200","49.68618","0.02816"
"596.73600","49.72821","0.02763"
"597.24000","49.77018","0.02775"
"597.74400","49.81222","0.02787"
"598.24800","49.85419","0.02825"
"598.75200","49.89622","0.02840"
"599.25600","49.93819","0.02904"
"599.76000","49.98023","0.02941"
"600.26400","50.02214","0.02947"
"600.76800","50.06417","0.02942"
"601.27200","50.10614","0.02929"
"601.77600","50.14811","0.02969"
"602.28000","50.19015","0.02989"
"602.78400","50.23212","0.02983"
"603.28800","50.27415","0.03013"
"603.79200","50.31624","0.02981"
"604.29600","50.35815","0.02969"
"604.80000","50.40024","0.03043"
"605.30400","50.44222","0.02934"
"605.80800","50.48419","0.02946"
"606.31200","50.52617","0.03005"
"606.81600","50.56825","0.03001"
"607.32000","50.61023","0.02982"
"607.82400","50.65219","0.03051"
"608.32800","50.69417","0.03020"
"608.83200","50.73615","0.03022"
"609.33600","50.77811","0.02970"
"609.84000","50.82015","0.03017"
"610.34400","50.86212","0.02956"
"610.84800","50.90416","0.02928"
"611.35200","50.94618","0.02999"
"611.85600","50.98816","0.03039"
"612.36000","51.03019","0.02987"
"612.86400","51.07222","0.02933"
"613.36800","51.11425","0.02869"
"613.87200","51.15623","0.02833"
"614.37600","51.19820","0.02859"
"614.88000","51.24017","0.02914"
"615.38400","51.28220","0.02908"
"615.88800","51.32417","0.02850"
"616.39200","51.36620","0.02854"
"616.89600","51.40812","0.02875"
"617.40000","51.45015","0.02874"
"617.90400","51.49218","0.02924"
"618.40800","51.53421","0.02893"
"618.91200","51.57618","0.02976"
"619.41600","51.61822","0.02880"
"619.92000","51.66013","0.02789"
"620.42400","51.70222","0.02775"
"620.92800","51.74419","0.02858"
"621.43200","51.78623","0.02873"
"621.93600","51.82820","0.02894"
"622.44000","51.87023","0.02872"
"622.94400","51.91220","0.02788"
"623.44800","51.95417","0.02757"
"623.95200","51.99620","0.02777"
"624.45600","52.03824","0.02779"
"624.96000","52.08015","0.02878"
"625.46400","52.12212","0.02836"
"625.96800","52.16416","0.02872"
"626.47200","52.20612","0.02857"
"626.97600","52.24816","0.02893"
"627.48000","52.29019","0.02880"
"627.98400","52.33216","0.02919"
"628.48800","52.37420","0.02892"
"628.99200","52.41623","0.02812"
"629.49600","52.45820","0.02843"
"630.00000","52.50023","0.02858"
"630.50400","52.54220","0.02851"
"631.00800","52.58418","0.02874"
"631.51200","52.62615","0.02898"
"632.01600","52.66818","0.02828"
"632.52000","52.71016","0.02821"
"633.02400","52.75212","0.02844"
"633.52800","52.79416","0.02820"
"634.03200","52.83613","0.02716"
"634.53600","52.87816","0.02733"
"635.04000","52.92019","0.02798"
"635.54400","52.96217","0.02802"
"636.04800","53.00420","0.02857"
"636.55200","53.04623","0.02746"
"637.05600","53.08820","0.02762"
"637.56000","53.13017","0.02840"
"638.06400","53.17220","0.02892"
"638.56800","53.21424","0.02874"
"639.07200","53.25621","0.02932"
"639.57600","53.29812","0.02962"
"640.08000","53.34021","0.02898"
"640.58400","53.38213","0.02894"
"641.08800","53.42416","0.02988"
"641.59200","53.46613","0.02995"
"642.09600","53.50817","0.03012"
"642.60000","53.55019","0.03052"
"643.10400","53.59223","0.03031"
"643.60800","53.63414","0.03001"
"644.11200","53.67618","0.03058"
"644.61600","53.71820","0.02952"
"645.12000","53.76018","0.02919"
"645.62400","53.80221","0.02909"
"646.12800","53.84418","0.02885"
"646.63200","53.88621","0.02916"
"647.13600","53.92819","0.02947"
"647.64000","53.97016","0.02986"
"648.14400","54.01220","0.02953"
"648.64800","54.05410","0.03025"
"649.15200","54.09613","0.03036"
"649.65600","54.13817","0.03106"
"650.16000","54.18014","0.03106"
"650.66400","54.22218","0.03095"
"651.16800","54.26414","0.03168"
"651.67200","54.30618","0.03075"
"652.17600","54.34815","0.03023"
"652.68000","54.39018","0.03029"
"653.18400","54.43221","0.03027"
"653.68800","54.47418","0.03113"
"654.19200","54.51622","0.03113"
"654.69600","54.55825","0.03141"
"655.20000","54.60016","0.02946"
"655.70400","54.64219","0.02979"
"656.20800","54.68417","0.03035"
"656.71200","54.72620","0.03103"
"657.21600","54.76811","0.03029"
"657.72000","54.81014","0.03057"
"658.22400","54.85211","0.03084"
"658.72800","54.89421","0.03096"
"659.23200","54.93624","0.03092"
"659.73600","54.97828","0.03103"
"660.24000","55.02018","0.03141"
"660.74400","55.06221","0.03138"
"661.24800","55.10419","0.03185"
"661.75200","55.14616","0.03226"
"662.25600","55.18819","0.03192"
"662.76000","55.23022","0.03223"
"663.26400","55.27220","0.03243"
"663.76800","55.31423","0.03319"
"664.27200","55.35614","0.03345"
"664.77600","55.39817","0.03340"
"665.28000","55.44014","0.03090"
"665.78400","55.48218","0.02939"
"666.28800","55.52415","0.02935"
"666.79200","55.56618","0.02898"
"667.29600","55.60821","0.02956"
"667.80000","55.65018","0.02808"
"668.30400","55.69216","0.02826"
"668.80800","55.73419","0.02876"
"669.31200","55.77617","0.02966"
"669.81600","55.81819","0.02980"
"670.32000","55.86017","0.02942"
"670.82400","55.90226","0.02955"
"671.32800","55.94423","0.02990"
"671.83200","55.98620","0.02941"
"672.33600","56.02818","0.02949"
"672.84000","56.07009","0.02997"
"673.34400","56.11218","0.03025"
"673.84800","56.15415","0.03071"
"674.35200","56.19613","0.03088"
"674.85600","56.23821","0.03006"
"675.36000","56.28019","0.03082"
"675.86400","56.32222","0.03156"
"676.36800","56.36419","0.03175"
"676.87200","56.40617","0.03237"
"677.37600","56.44820","0.03220"
"677.88000","56.49023","0.03233"
"678.38400","56.53220","0.03227"
"678.88800","56.57417","0.03196"
"679.39200","56.61620","0.03172"
"679.89600","56.65824","0.03159"
"680.40000","56.70021","0.03215"
"680.90400","56.74206","0.03309"
"681.40800","56.78415","0.03291"
"681.91200","56.82619","0.03242"
"682.41600","56.86816","0.03298"
"682.92000","56.91013","0.03344"
"683.42400","56.95222","0.03395"
"683.92800","56.99419","0.03360"
"684.43200","57.03622","0.03247"
"684.93600","57.07820","0.03298"
"685.44000","57.12023","0.03321"
"685.94400","57.16220","0.03292"
"686.44800","57.20424","0.03338"
"686.95200","57.24614","0.03391"
"687.45600","57.28818","0.03383"
"687.96000","57.33021","0.03455"
"688.46400","57.37218","0.03280"
"688.96800","57.41410","0.03317"
"689.47200","57.45607","0.03396"
"689.97600","57.49816","0.03442"
"690.48000","57.54019","0.03452"
"690.98400","57.58216","0.03479"
"691.48800","57.62420","0.03455"
"691.99200","57.66623","0.03447"
"692.49600","57.70820","0.03532"
"693.00000","57.75023","0.03513"
"693.50400","57.79220","0.03429"
"694.00800","57.83424","0.03405"
"694.51200","57.87621","0.02765"
"695.01600","57.91818","0.02672"
"695.52000","57.96021","0.02668"
"696.02400","58.00219","0.02848"
"696.52800","58.04416","0.02819"
"697.03200","58.08619","0.02834"
"697.53600","58.12816","0.02929"
"698.04000","58.17013","0.02923"
"698.54400","58.21211","0.02938"
"699.04800","58.25420","0.02991"
"699.55200","58.29623","0.03004"
"700.05600","58.33826","0.03075"
"700.56000","58.38018","0.03173"
"701.06400","58.42227","0.03216"
"701.56800","58.46418","0.03205"
"702.07200","58.50627","0.03206"
"702.57600","58.54824","0.03151"
"703.08000","58.59021","0.03176"
"703.58400","58.63219","0.03266"
"704.08800","58.67422","0.03282"
"704.59200","58.71613","0.03245"
"705.09600","58.75817","0.03244"
"705.60000","58.80014","0.03266"
"706.10400","58.84217","0.03284"
"706.60800","58.88420","0.03254"
"707.11200","58.92618","0.03320"
"707.61600","58.96815","0.03220"
"708.12000","59.01018","0.03192"
"708.62400","59.05221","0.03128"
"709.12800","59.09418","0.03067"
"709.63200","59.13621","0.02988"
"710.13600","59.17819","0.03055"
"710.64000","59.22022","0.03112"
"711.14400","59.26220","0.03041"
"711.64800","59.30416","0.03069"
"712.15200","59.34613","0.03109"
"712.65600","59.38811","0.03153"
"713.16000","59.43014","0.03129"
"713.66400","59.47211","0.03148"
"714.16800","59.51414","0.03149"
"714.67200","59.55618","0.02846"
"715.17600","59.59815","0.02783"
"715.68000","59.64024","0.02996"
"716.18400","59.68221","0.03073"
"716.68800","59.72425","0.03041"
"717.19200","59.76616","0.03067"
"717.69600","59.80825","0.03132"
"718.20000","59.85022","0.03104"
"718.70400","59.89220","0.03098"
"719.20800","59.93417","0.03129"
"719.71200","59.97620","0.03162"
"720.21600","60.01817","0.03183"
"720.72000","60.06020","0.03222"
"721.22400","60.10212","0.03266"
"721.72800","60.14421","0.03224"
"722.23200","60.18618","0.03268"
"722.73600","60.22821","0.03280"
"723.24000","60.27019","0.03330"
"723.74400","60.31221","0.03382"
"724.24800","60.35425","0.03358"
"724.75200","60.39622","0.03418"
"725.25600","60.43819","0.03433"
"725.76000","60.48022","0.03449"
"726.26400","60.52220","0.03416"
"726.76800","60.56423","0.03455"
"727.27200","60.60614","0.03503"
"727.77600","60.64817","0.03502"
"728.28000","60.69014","0.03466"
"728.78400","60.73212","0.03482"
"729.28800","60.77415","0.03466"
"729.79200","60.81618","0.03458"
"730.29600","60.85815","0.03568"
"730.80000","60.90019","0.03526"
"731.30400","60.94221","0.03590"
"731.80800","60.98419","0.03625"
"732.31200","61.02622","0.03607"
"732.81600","61.06820","0.03712"
"733.32000","61.11023","0.03688"
"733.82400","61.15220","0.03690"
"734.32800","61.19423","0.03674"
"734.83200","61.23626","0.03735"
"735.33600","61.27818","0.03775"
"735.84000","61.32014","0.03769"
"736.34400","61.36218","0.03802"
"736.84800","61.40415","0.03768"
"737.35200","61.44619","0.03697"
"737.85600","61.48816","0.03661"
"738.36000","61.53019","0.03730"
"738.86400","61.57215","0.01155"
"739.36800","61.61419","0.00841"
"739.87200","61.65622","0.01268"
"740.37600","61.69820","0.00996"
"740.88000","61.74017","0.01050"
"741.38400","61.78226","0.01031"
"741.88800","61.82423","0.01142"
"742.39200","61.86620","0.00971"
"742.89600","61.90818","0.01168"
"743.40000","61.95015","0.01150"
"743.90400","61.99212","0.01199"
"744.40800","62.03421","0.01110"
"744.91200","62.07607","0.01215"
"745.41600","62.11816","0.01206"
"745.92000","62.16013","0.01292"
"746.42400","62.20216","0.01300"
"746.92800","62.24419","0.01355"
"747.43200","62.28622","0.01259"
"747.93600","62.32820","0.01345"
"748.44000","62.37023","0.01265"
"748.94400","62.41220","0.01331"
"749.44800","62.45424","0.01310"
"749.95200","62.49621","0.01359"
"750.45600","62.53823","0.01359"
"750.96000","62.58015","0.01388"
"751.46400","62.62212","0.01342"
"751.83800","62.65333","0.01364"