File: Trajectories_together/161104Specimen_RawData_3.csv
"","V1","V2","V3"
"1","End date","11/4/2016",""
"2","Specimen label","",""
"3","Maximum Load","0.01818","N"
"4","Time","Extension","Load"
"5","(s)","(mm)","(N)"
"6","0.00000","0.00000","0.00016"
"25","0.11400","0.00436","0.00041"
"44","0.22800","0.01650","0.00007"
"63","0.34200","0.02834","0.00037"
"82","0.45600","0.03833","0.00022"
"101","0.57000","0.04777","-0.00021"
"120","0.68400","0.05716","0.00023"
"139","0.79800","0.06667","0.00046"
"158","0.91200","0.07623","0.00052"
"177","1.02600","0.08574","0.00038"
"196","1.14000","0.09518","0.00073"
"215","1.25400","0.10463","-0.00012"
"234","1.36800","0.11414","0.00016"
"253","1.48200","0.12370","0.00034"
"272","1.59600","0.13321","0.00024"
"291","1.71000","0.14266","0.00027"
"310","1.82400","0.15210","-0.00025"
"329","1.93800","0.16167","0.00041"
"348","2.05200","0.17112","0.00039"
"367","2.16600","0.18068","0.00039"
"386","2.28000","0.19013","0.00074"
"405","2.39400","0.19964","0.00041"
"424","2.50800","0.20914","0.00049"
"443","2.62200","0.21865","-0.00016"
"462","2.73600","0.22816","0.00075"
"481","2.85000","0.23766","0.00023"
"500","2.96400","0.24717","0.00077"
"519","3.07800","0.25668","0.00038"
"538","3.19200","0.26618","0.00069"
"557","3.30600","0.27569","0.00038"
"576","3.42000","0.28514","0.00039"
"595","3.53400","0.29464","0.00015"
"614","3.64800","0.30415","0.00032"
"633","3.76200","0.31372","0.00081"
"652","3.87600","0.32310","0.00058"
"671","3.99000","0.33261","0.00057"
"690","4.10400","0.34212","0.00054"
"709","4.21800","0.35162","0.00016"
"728","4.33200","0.36113","0.00039"
"747","4.44600","0.37058","0.00038"
"766","4.56000","0.38008","0.00054"
"785","4.67400","0.38965","0.00021"
"804","4.78800","0.39910","0.00041"
"823","4.90200","0.40860","0.00060"
"842","5.01600","0.41811","0.00053"
"861","5.13000","0.42767","0.00059"
"880","5.24400","0.43712","0.00086"
"899","5.35800","0.44663","0.00014"
"918","5.47200","0.45613","0.00046"
"937","5.58600","0.46558","0.00048"
"956","5.70000","0.47515","0.00008"
"975","5.81400","0.48465","0.00024"
"994","5.92800","0.49416","0.00058"
"1013","6.04200","0.50361","0.00053"
"1032","6.15600","0.51311","0.00094"
"1051","6.27000","0.52268","0.00045"
"1070","6.38400","0.53213","0.00015"
"1089","6.49800","0.54163","0.00033"
"1108","6.61200","0.55108","0.00044"
"1127","6.72600","0.56065","0.00032"
"1146","6.84000","0.57015","0.00058"
"1165","6.95400","0.57966","0.00034"
"1184","7.06800","0.58911","0.00022"
"1203","7.18200","0.59855","0.00054"
"1222","7.29600","0.60818","0.00062"
"1241","7.41000","0.61769","0.00038"
"1260","7.52400","0.62719","0.00009"
"1279","7.63800","0.63664","0.00005"
"1298","7.75200","0.64609","0.00079"
"1317","7.86600","0.65565","0.00039"
"1336","7.98000","0.66516","0.00057"
"1355","8.09400","0.67467","0.00090"
"1374","8.20800","0.68411","0.00063"
"1393","8.32200","0.69362","0.00040"
"1412","8.43600","0.70318","0.00062"
"1431","8.55000","0.71269","0.00152"
"1450","8.66400","0.72208","0.00059"
"1469","8.77800","0.73158","0.00065"
"1488","8.89200","0.74109","0.00044"
"1507","9.00600","0.75066","0.00033"
"1526","9.12000","0.76016","0.00029"
"1545","9.23400","0.76961","0.00073"
"1564","9.34800","0.77906","0.00073"
"1583","9.46200","0.78862","0.00026"
"1602","9.57600","0.79819","0.00100"
"1621","9.69000","0.80764","0.00068"
"1640","9.80400","0.81708","0.00079"
"1659","9.91800","0.82659","0.00079"
"1678","10.03200","0.83616","0.00044"
"1697","10.14600","0.84566","0.00076"
"1716","10.26000","0.85511","0.00074"
"1735","10.37400","0.86462","0.00039"
"1754","10.48800","0.87406","0.00110"
"1773","10.60200","0.88369","0.00103"
"1792","10.71600","0.89314","0.00097"
"1811","10.83000","0.90264","0.00109"
"1830","10.94400","0.91209","0.00065"
"1849","11.05800","0.92160","0.00079"
"1868","11.17200","0.93116","0.00103"
"1887","11.28600","0.94067","0.00089"
"1906","11.40000","0.95012","0.00071"
"1925","11.51400","0.95962","0.00100"
"1944","11.62800","0.96913","0.00105"
"1963","11.74200","0.97864","0.00050"
"1982","11.85600","0.98814","0.00071"
"2001","11.97000","0.99765","0.00122"
"2020","12.08400","1.00709","0.00072"
"2039","12.19800","1.01666","0.00068"
"2058","12.31200","1.02617","0.00095"
"2077","12.42600","1.03567","0.00092"
"2096","12.54000","1.04512","0.00066"
"2115","12.65400","1.05457","0.00061"
"2134","12.76800","1.06413","0.00067"
"2153","12.88200","1.07364","0.00088"
"2172","12.99600","1.08309","0.00030"
"2191","13.11000","1.09259","0.00109"
"2210","13.22400","1.10210","0.00052"
"2229","13.33800","1.11167","0.00126"
"2248","13.45200","1.12117","0.00046"
"2267","13.56600","1.13062","0.00136"
"2286","13.68000","1.14013","0.00087"
"2305","13.79400","1.14963","0.00080"
"2324","13.90800","1.15920","0.00070"
"2343","14.02200","1.16865","0.00053"
"2362","14.13600","1.17809","0.00094"
"2381","14.25000","1.18760","0.00036"
"2400","14.36400","1.19717","0.00094"
"2419","14.47800","1.20667","0.00110"
"2438","14.59200","1.21618","0.00120"
"2457","14.70600","1.22557","0.00076"
"2476","14.82000","1.23513","0.00063"
"2495","14.93400","1.24464","0.00131"
"2514","15.04800","1.25415","0.00083"
"2533","15.16200","1.26359","0.00103"
"2552","15.27600","1.27310","0.00163"
"2571","15.39000","1.28266","0.00077"
"2590","15.50400","1.29217","0.00094"
"2609","15.61800","1.30168","0.00098"
"2628","15.73200","1.31112","0.00103"
"2647","15.84600","1.32057","0.00091"
"2666","15.96000","1.33014","0.00091"
"2685","16.07400","1.33964","0.00091"
"2704","16.18800","1.34921","0.00122"
"2723","16.30200","1.35866","0.00100"
"2742","16.41600","1.36810","0.00096"
"2761","16.53000","1.37767","0.00110"
"2780","16.64400","1.38718","0.00097"
"2799","16.75800","1.39662","0.00103"
"2818","16.87200","1.40607","0.00144"
"2837","16.98600","1.41558","0.00113"
"2856","17.10000","1.42508","0.00161"
"2875","17.21400","1.43465","0.00060"
"2894","17.32800","1.44410","0.00098"
"2913","17.44200","1.45354","0.00115"
"2932","17.55600","1.46311","0.00088"
"2951","17.67000","1.47262","0.00118"
"2970","17.78400","1.48218","0.00140"
"2989","17.89800","1.49163","0.00080"
"3008","18.01200","1.50108","0.00107"
"3027","18.12600","1.51064","0.00074"
"3046","18.24000","1.52015","0.00091"
"3065","18.35400","1.52966","0.00073"
"3084","18.46800","1.53916","0.00104"
"3103","18.58200","1.54861","0.00082"
"3122","18.69600","1.55817","0.00113"
"3141","18.81000","1.56768","0.00112"
"3160","18.92400","1.57713","0.00091"
"3179","19.03800","1.58663","0.00085"
"3198","19.15200","1.59614","0.00143"
"3217","19.26600","1.60559","0.00113"
"3236","19.38000","1.61515","0.00116"
"3255","19.49400","1.62460","0.00127"
"3274","19.60800","1.63405","0.00131"
"3293","19.72200","1.64361","0.00083"
"3312","19.83600","1.65312","0.00052"
"3331","19.95000","1.66263","0.00077"
"3350","20.06400","1.67213","0.00151"
"3369","20.17800","1.68164","0.00144"
"3388","20.29200","1.69115","0.00068"
"3407","20.40600","1.70065","0.00157"
"3426","20.52000","1.71016","0.00158"
"3445","20.63400","1.71961","0.00118"
"3464","20.74800","1.72917","0.00130"
"3483","20.86200","1.73868","0.00128"
"3502","20.97600","1.74819","0.00127"
"3521","21.09000","1.75763","0.00136"
"3540","21.20400","1.76714","0.00128"
"3559","21.31800","1.77665","0.00141"
"3578","21.43200","1.78609","0.00154"
"3597","21.54600","1.79560","0.00102"
"3616","21.66000","1.80511","0.00122"
"3635","21.77400","1.81461","0.00153"
"3654","21.88800","1.82412","0.00127"
"3673","22.00200","1.83363","0.00107"
"3692","22.11600","1.84307","0.00129"
"3711","22.23000","1.85264","0.00127"
"3730","22.34400","1.86215","0.00153"
"3749","22.45800","1.87159","0.00176"
"3768","22.57200","1.88116","0.00122"
"3787","22.68600","1.89060","0.00153"
"3806","22.80000","1.90005","0.00172"
"3825","22.91400","1.90962","0.00123"
"3844","23.02800","1.91912","0.00157"
"3863","23.14200","1.92869","0.00146"
"3882","23.25600","1.93808","0.00180"
"3901","23.37000","1.94758","0.00116"
"3920","23.48400","1.95715","0.00152"
"3939","23.59800","1.96666","0.00088"
"3958","23.71200","1.97610","0.00156"
"3977","23.82600","1.98561","0.00160"
"3996","23.94000","1.99518","0.00164"
"4015","24.05400","2.00468","0.00150"
"4034","24.16800","2.01413","0.00133"
"4053","24.28200","2.02364","0.00111"
"4072","24.39600","2.03308","0.00102"
"4091","24.51000","2.04265","0.00144"
"4110","24.62400","2.05222","0.00152"
"4129","24.73800","2.06166","0.00183"
"4148","24.85200","2.07111","0.00121"
"4167","24.96600","2.08056","0.00154"
"4186","25.08000","2.09018","0.00159"
"4205","25.19400","2.09963","0.00195"
"4224","25.30800","2.10914","0.00146"
"4243","25.42200","2.11858","0.00133"
"4262","25.53600","2.12815","0.00150"
"4281","25.65000","2.13766","0.00170"
"4300","25.76400","2.14716","0.00209"
"4319","25.87800","2.15661","0.00177"
"4338","25.99200","2.16606","0.00151"
"4357","26.10600","2.17562","0.00170"
"4376","26.22000","2.18519","0.00098"
"4395","26.33400","2.19469","0.00167"
"4414","26.44800","2.20414","0.00178"
"4433","26.56200","2.21359","0.00174"
"4452","26.67600","2.22309","0.00181"
"4471","26.79000","2.23266","0.00222"
"4490","26.90400","2.24217","0.00155"
"4509","27.01800","2.25161","0.00177"
"4528","27.13200","2.26112","0.00183"
"4547","27.24600","2.27063","0.00190"
"4566","27.36000","2.28019","0.00206"
"4585","27.47400","2.28964","0.00187"
"4604","27.58800","2.29909","0.00170"
"4623","27.70200","2.30859","0.00195"
"4642","27.81600","2.31810","0.00182"
"4661","27.93000","2.32767","0.00164"
"4680","28.04400","2.33711","0.00226"
"4699","28.15800","2.34656","0.00172"
"4718","28.27200","2.35613","0.00253"
"4737","28.38600","2.36563","0.00215"
"4756","28.50000","2.37514","0.00178"
"4775","28.61400","2.38465","0.00230"
"4794","28.72800","2.39409","0.00215"
"4813","28.84200","2.40366","0.00163"
"4832","28.95600","2.41317","0.00238"
"4851","29.07000","2.42267","0.00260"
"4870","29.18400","2.43212","0.00220"
"4889","29.29800","2.44157","0.00178"
"4908","29.41200","2.45119","0.00173"
"4927","29.52600","2.46070","0.00219"
"4946","29.64000","2.47014","0.00195"
"4965","29.75400","2.47959","0.00170"
"4984","29.86800","2.48904","0.00227"
"5003","29.98200","2.49866","0.00183"
"5022","30.09600","2.50817","0.00129"
"5041","30.21000","2.51762","0.00206"
"5060","30.32400","2.52706","0.00210"
"5079","30.43800","2.53657","0.00188"
"5098","30.55200","2.54614","0.00164"
"5117","30.66600","2.55570","0.00203"
"5136","30.78000","2.56515","0.00209"
"5155","30.89400","2.57460","0.00210"
"5174","31.00800","2.58416","0.00226"
"5193","31.12200","2.59367","0.00224"
"5212","31.23600","2.60318","0.00236"
"5231","31.35000","2.61262","0.00217"
"5250","31.46400","2.62213","0.00211"
"5269","31.57800","2.63170","0.00201"
"5288","31.69200","2.64120","0.00166"
"5307","31.80600","2.65071","0.00215"
"5326","31.92000","2.66010","0.00184"
"5345","32.03400","2.66960","0.00244"
"5364","32.14800","2.67917","0.00186"
"5383","32.26200","2.68868","0.00162"
"5402","32.37600","2.69812","0.00135"
"5421","32.49000","2.70757","0.00215"
"5440","32.60400","2.71714","0.00250"
"5459","32.71800","2.72664","0.00210"
"5478","32.83200","2.73621","0.00210"
"5497","32.94600","2.74565","0.00224"
"5516","33.06000","2.75510","0.00191"
"5535","33.17400","2.76467","0.00156"
"5554","33.28800","2.77417","0.00212"
"5573","33.40200","2.78368","0.00167"
"5592","33.51600","2.79307","0.00267"
"5611","33.63000","2.80263","0.00201"
"5630","33.74400","2.81220","0.00209"
"5649","33.85800","2.82171","0.00200"
"5668","33.97200","2.83121","0.00191"
"5687","34.08600","2.84054","0.00234"
"5706","34.20000","2.85011","0.00200"
"5725","34.31400","2.85967","0.00191"
"5744","34.42800","2.86918","0.00236"
"5763","34.54200","2.87863","0.00227"
"5782","34.65600","2.88807","0.00194"
"5801","34.77000","2.89758","0.00202"
"5820","34.88400","2.90715","0.00211"
"5839","34.99800","2.91665","0.00153"
"5858","35.11200","2.92610","0.00182"
"5877","35.22600","2.93555","0.00252"
"5896","35.34000","2.94517","0.00201"
"5915","35.45400","2.95468","0.00249"
"5934","35.56800","2.96419","0.00210"
"5953","35.68200","2.97363","0.00225"
"5972","35.79600","2.98308","0.00252"
"5991","35.91000","2.99265","0.00232"
"6010","36.02400","3.00215","0.00246"
"6029","36.13800","3.01160","0.00300"
"6048","36.25200","3.02111","0.00259"
"6067","36.36600","3.03061","0.00223"
"6086","36.48000","3.04012","0.00173"
"6105","36.59400","3.04963","0.00283"
"6124","36.70800","3.05913","0.00204"
"6143","36.82200","3.06858","0.00194"
"6162","36.93600","3.07814","0.00246"
"6181","37.05000","3.08759","0.00212"
"6200","37.16400","3.09716","0.00206"
"6219","37.27800","3.10666","0.00232"
"6238","37.39200","3.11611","0.00248"
"6257","37.50600","3.12562","0.00197"
"6276","37.62000","3.13512","0.00248"
"6295","37.73400","3.14463","0.00236"
"6314","37.84800","3.15414","0.00284"
"6333","37.96200","3.16358","0.00275"
"6352","38.07600","3.17315","0.00246"
"6371","38.19000","3.18266","0.00222"
"6390","38.30400","3.19210","0.00242"
"6409","38.41800","3.20161","0.00311"
"6428","38.53200","3.21112","0.00226"
"6447","38.64600","3.22062","0.00274"
"6466","38.76000","3.23019","0.00298"
"6485","38.87400","3.23964","0.00216"
"6504","38.98800","3.24914","0.00240"
"6523","39.10200","3.25865","0.00207"
"6542","39.21600","3.26816","0.00239"
"6561","39.33000","3.27766","0.00277"
"6580","39.44400","3.28717","0.00264"
"6599","39.55800","3.29662","0.00227"
"6618","39.67200","3.30612","0.00224"
"6637","39.78600","3.31569","0.00268"
"6656","39.90000","3.32513","0.00258"
"6675","40.01400","3.33458","0.00205"
"6694","40.12800","3.34415","0.00226"
"6713","40.24200","3.35365","0.00170"
"6732","40.35600","3.36316","0.00193"
"6751","40.47000","3.37261","0.00165"
"6770","40.58400","3.38211","0.00213"
"6789","40.69800","3.39168","0.00276"
"6808","40.81200","3.40113","0.00232"
"6827","40.92600","3.41063","0.00304"
"6846","41.04000","3.42008","0.00275"
"6865","41.15400","3.42965","0.00283"
"6884","41.26800","3.43915","0.00239"
"6903","41.38200","3.44866","0.00297"
"6922","41.49600","3.45817","0.00236"
"6941","41.61000","3.46761","0.00222"
"6960","41.72400","3.47718","0.00250"
"6979","41.83800","3.48669","0.00254"
"6998","41.95200","3.49613","0.00289"
"7017","42.06600","3.50564","0.00250"
"7036","42.18000","3.51509","0.00197"
"7055","42.29400","3.52465","0.00270"
"7074","42.40800","3.53416","0.00263"
"7093","42.52200","3.54361","0.00287"
"7112","42.63600","3.55311","0.00207"
"7131","42.75000","3.56256","0.00244"
"7150","42.86400","3.57213","0.00282"
"7169","42.97800","3.58163","0.00266"
"7188","43.09200","3.59114","0.00264"
"7207","43.20600","3.60059","0.00264"
"7226","43.32000","3.61015","0.00234"
"7245","43.43400","3.61966","0.00239"
"7264","43.54800","3.62922","0.00242"
"7283","43.66200","3.63867","0.00287"
"7302","43.77600","3.64812","0.00348"
"7321","43.89000","3.65756","0.00285"
"7340","44.00400","3.66713","0.00262"
"7359","44.11800","3.67664","0.00243"
"7378","44.23200","3.68614","0.00308"
"7397","44.34600","3.69559","0.00290"
"7416","44.46000","3.70516","0.00328"
"7435","44.57400","3.71466","0.00286"
"7454","44.68800","3.72411","0.00311"
"7473","44.80200","3.73356","0.00233"
"7492","44.91600","3.74312","0.00267"
"7511","45.03000","3.75269","0.00303"
"7530","45.14400","3.76214","0.00246"
"7549","45.25800","3.77158","0.00274"
"7568","45.37200","3.78109","0.00258"
"7587","45.48600","3.79060","0.00301"
"7606","45.60000","3.80022","0.00347"
"7625","45.71400","3.80967","0.00317"
"7644","45.82800","3.81912","0.00291"
"7663","45.94200","3.82856","0.00373"
"7682","46.05600","3.83807","0.00315"
"7701","46.17000","3.84764","0.00285"
"7720","46.28400","3.85714","0.00288"
"7739","46.39800","3.86659","0.00304"
"7758","46.51200","3.87610","0.00320"
"7777","46.62600","3.88566","0.00312"
"7796","46.74000","3.89523","0.00286"
"7815","46.85400","3.90468","0.00366"
"7834","46.96800","3.91406","0.00323"
"7853","47.08200","3.92357","0.00329"
"7872","47.19600","3.93314","0.00295"
"7891","47.31000","3.94264","0.00348"
"7910","47.42400","3.95209","0.00329"
"7929","47.53800","3.96159","0.00306"
"7948","47.65200","3.97110","0.00311"
"7967","47.76600","3.98067","0.00283"
"7986","47.88000","3.99011","0.00307"
"8005","47.99400","3.99962","0.00309"
"8024","48.10800","4.00913","0.00297"
"8043","48.22200","4.01863","0.00266"
"8062","48.33600","4.02814","0.00298"
"8081","48.45000","4.03765","0.00317"
"8100","48.56400","4.04709","0.00298"
"8119","48.67800","4.05660","0.00340"
"8138","48.79200","4.06617","0.00316"
"8157","48.90600","4.07567","0.00304"
"8176","49.02000","4.08512","0.00324"
"8195","49.13400","4.09457","0.00292"
"8214","49.24800","4.10413","0.00324"
"8233","49.36200","4.11364","0.00351"
"8252","49.47600","4.12321","0.00274"
"8271","49.59000","4.13259","0.00359"
"8290","49.70400","4.14210","0.00345"
"8309","49.81800","4.15167","0.00307"
"8328","49.93200","4.16117","0.00369"
"8347","50.04600","4.17068","0.00295"
"8366","50.16000","4.18013","0.00357"
"8385","50.27400","4.18951","0.00384"
"8404","50.38800","4.19920","0.00312"
"8423","50.50200","4.20864","0.00344"
"8442","50.61600","4.21821","0.00342"
"8461","50.73000","4.22760","0.00303"
"8480","50.84400","4.23710","0.00343"
"8499","50.95800","4.24667","0.00329"
"8518","51.07200","4.25618","0.00304"
"8537","51.18600","4.26562","0.00306"
"8556","51.30000","4.27513","0.00359"
"8575","51.41400","4.28464","0.00326"
"8594","51.52800","4.29414","0.00312"
"8613","51.64200","4.30365","0.00315"
"8632","51.75600","4.31310","0.00330"
"8651","51.87000","4.32254","0.00329"
"8670","51.98400","4.33211","0.00346"
"8689","52.09800","4.34162","0.00331"
"8708","52.21200","4.35118","0.00345"
"8727","52.32600","4.36063","0.00318"
"8746","52.44000","4.37008","0.00327"
"8765","52.55400","4.37964","0.00305"
"8784","52.66800","4.38915","0.00317"
"8803","52.78200","4.39866","0.00341"
"8822","52.89600","4.40816","0.00324"
"8841","53.01000","4.41761","0.00371"
"8860","53.12400","4.42712","0.00342"
"8879","53.23800","4.43668","0.00385"
"8898","53.35200","4.44619","0.00303"
"8917","53.46600","4.45558","0.00296"
"8936","53.58000","4.46508","0.00355"
"8955","53.69400","4.47465","0.00376"
"8974","53.80800","4.48416","0.00357"
"8993","53.92200","4.49360","0.00378"
"9012","54.03600","4.50305","0.00348"
"9031","54.15000","4.51262","0.00340"
"9050","54.26400","4.52212","0.00339"
"9069","54.37800","4.53169","0.00364"
"9088","54.49200","4.54119","0.00320"
"9107","54.60600","4.55058","0.00368"
"9126","54.72000","4.56015","0.00341"
"9145","54.83400","4.56965","0.00343"
"9164","54.94800","4.57916","0.00364"
"9183","55.06200","4.58861","0.00380"
"9202","55.17600","4.59811","0.00373"
"9221","55.29000","4.60768","0.00329"
"9240","55.40400","4.61713","0.00353"
"9259","55.51800","4.62663","0.00410"
"9278","55.63200","4.63608","0.00411"
"9297","55.74600","4.64559","0.00411"
"9316","55.86000","4.65509","0.00339"
"9335","55.97400","4.66460","0.00345"
"9354","56.08800","4.67411","0.00408"
"9373","56.20200","4.68361","0.00361"
"9392","56.31600","4.69312","0.00374"
"9411","56.43000","4.70269","0.00366"
"9430","56.54400","4.71213","0.00298"
"9449","56.65800","4.72164","0.00406"
"9468","56.77200","4.73115","0.00397"
"9487","56.88600","4.74065","0.00359"
"9506","57.00000","4.75016","0.00398"
"9525","57.11400","4.75961","0.00382"
"9544","57.22800","4.76911","0.00402"
"9563","57.34200","4.77868","0.00385"
"9582","57.45600","4.78813","0.00356"
"9601","57.57000","4.79763","0.00385"
"9620","57.68400","4.80714","0.00373"
"9639","57.79800","4.81664","0.00369"
"9658","57.91200","4.82615","0.00334"
"9677","58.02600","4.83560","0.00421"
"9696","58.14000","4.84516","0.00347"
"9715","58.25400","4.85455","0.00440"
"9734","58.36800","4.86412","0.00393"
"9753","58.48200","4.87368","0.00348"
"9772","58.59600","4.88313","0.00423"
"9791","58.71000","4.89264","0.00373"
"9810","58.82400","4.90208","0.00374"
"9829","58.93800","4.91165","0.00398"
"9848","59.05200","4.92116","0.00442"
"9867","59.16600","4.93066","0.00399"
"9886","59.28000","4.94017","0.00400"
"9905","59.39400","4.94962","0.00435"
"9924","59.50800","4.95918","0.00400"
"9943","59.62200","4.96869","0.00405"
"9962","59.73600","4.97814","0.00404"
"9981","59.85000","4.98758","0.00412"
"10000","59.96400","4.99709","0.00414"
"10019","60.07800","5.00666","0.00443"
"10038","60.19200","5.01616","0.00394"
"10057","60.30600","5.02561","0.00428"
"10076","60.42000","5.03506","0.00389"
"10095","60.53400","5.04462","0.00373"
"10114","60.64800","5.05413","0.00389"
"10133","60.76200","5.06364","0.00389"
"10152","60.87600","5.07314","0.00450"
"10171","60.99000","5.08259","0.00420"
"10190","61.10400","5.09215","0.00370"
"10209","61.21800","5.10166","0.00432"
"10228","61.33200","5.11117","0.00412"
"10247","61.44600","5.12061","0.00441"
"10266","61.56000","5.13006","0.00452"
"10285","61.67400","5.13969","0.00353"
"10304","61.78800","5.14913","0.00392"
"10323","61.90200","5.15864","0.00383"
"10342","62.01600","5.16809","0.00392"
"10361","62.13000","5.17759","0.00433"
"10380","62.24400","5.18716","0.00433"
"10399","62.35800","5.19667","0.00456"
"10418","62.47200","5.20611","0.00462"
"10437","62.58600","5.21556","0.00419"
"10456","62.70000","5.22513","0.00421"
"10475","62.81400","5.23469","0.00396"
"10494","62.92800","5.24414","0.00424"
"10513","63.04200","5.25365","0.00382"
"10532","63.15600","5.26309","0.00421"
"10551","63.27000","5.27260","0.00439"
"10570","63.38400","5.28217","0.00395"
"10589","63.49800","5.29161","0.00416"
"10608","63.61200","5.30112","0.00459"
"10627","63.72600","5.31057","0.00408"
"10646","63.84000","5.32013","0.00404"
"10665","63.95400","5.32964","0.00430"
"10684","64.06800","5.33915","0.00445"
"10703","64.18200","5.34859","0.00473"
"10722","64.29600","5.35810","0.00430"
"10741","64.41000","5.36766","0.00414"
"10760","64.52400","5.37711","0.00450"
"10779","64.63800","5.38662","0.00436"
"10798","64.75200","5.39612","0.00480"
"10817","64.86600","5.40557","0.00380"
"10836","64.98000","5.41520","0.00427"
"10855","65.09400","5.42464","0.00482"
"10874","65.20800","5.43409","0.00392"
"10893","65.32200","5.44360","0.00495"
"10912","65.43600","5.45310","0.00464"
"10931","65.55000","5.46267","0.00472"
"10950","65.66400","5.47212","0.00508"
"10969","65.77800","5.48156","0.00506"
"10988","65.89200","5.49113","0.00492"
"11007","66.00600","5.50064","0.00437"
"11026","66.12000","5.51020","0.00486"
"11045","66.23400","5.51965","0.00527"
"11064","66.34800","5.52904","0.00480"
"11083","66.46200","5.53860","0.00483"
"11102","66.57600","5.54823","0.00482"
"11121","66.69000","5.55768","0.00394"
"11140","66.80400","5.56712","0.00446"
"11159","66.91800","5.57657","0.00503"
"11178","67.03200","5.58614","0.00430"
"11197","67.14600","5.59564","0.00461"
"11216","67.26000","5.60521","0.00464"
"11235","67.37400","5.61460","0.00471"
"11254","67.48800","5.62404","0.00509"
"11273","67.60200","5.63367","0.00450"
"11292","67.71600","5.64318","0.00498"
"11311","67.83000","5.65268","0.00467"
"11330","67.94400","5.66207","0.00497"
"11349","68.05800","5.67158","0.00489"
"11368","68.17200","5.68114","0.00507"
"11387","68.28600","5.69065","0.00466"
"11406","68.40000","5.70010","0.00524"
"11425","68.51400","5.70960","0.00431"
"11444","68.62800","5.71917","0.00445"
"11463","68.74200","5.72861","0.00493"
"11482","68.85600","5.73812","0.00520"
"11501","68.97000","5.74763","0.00517"
"11520","69.08400","5.75707","0.00502"
"11539","69.19800","5.76664","0.00493"
"11558","69.31200","5.77615","0.00504"
"11577","69.42600","5.78571","0.00528"
"11596","69.54000","5.79510","0.00514"
"11615","69.65400","5.80455","0.00510"
"11634","69.76800","5.81417","0.00473"
"11653","69.88200","5.82368","0.00488"
"11672","69.99600","5.83319","0.00484"
"11691","70.11000","5.84263","0.00506"
"11710","70.22400","5.85208","0.00511"
"11729","70.33800","5.86165","0.00479"
"11748","70.45200","5.87115","0.00501"
"11767","70.56600","5.88066","0.00552"
"11786","70.68000","5.89011","0.00502"
"11805","70.79400","5.89961","0.00535"
"11824","70.90800","5.90906","0.00479"
"11843","71.02200","5.91863","0.00548"
"11862","71.13600","5.92813","0.00544"
"11881","71.25000","5.93758","0.00539"
"11900","71.36400","5.94709","0.00504"
"11919","71.47800","5.95665","0.00499"
"11938","71.59200","5.96616","0.00480"
"11957","71.70600","5.97566","0.00514"
"11976","71.82000","5.98505","0.00527"
"11995","71.93400","5.99468","0.00540"
"12014","72.04800","6.00418","0.00513"
"12033","72.16200","6.01363","0.00496"
"12052","72.27600","6.02314","0.00533"
"12071","72.39000","6.03264","0.00529"
"12090","72.50400","6.04215","0.00488"
"12109","72.61800","6.05166","0.00517"
"12128","72.73200","6.06116","0.00536"
"12147","72.84600","6.07061","0.00553"
"12166","72.96000","6.08012","0.00574"
"12185","73.07400","6.08962","0.00523"
"12204","73.18800","6.09913","0.00564"
"12223","73.30200","6.10864","0.00500"
"12242","73.41600","6.11808","0.00562"
"12261","73.53000","6.12759","0.00568"
"12280","73.64400","6.13716","0.00578"
"12299","73.75800","6.14660","0.00544"
"12318","73.87200","6.15611","0.00535"
"12337","73.98600","6.16562","0.00506"
"12356","74.10000","6.17512","0.00520"
"12375","74.21400","6.18463","0.00561"
"12394","74.32800","6.19414","0.00483"
"12413","74.44200","6.20364","0.00566"
"12432","74.55600","6.21315","0.00609"
"12451","74.67000","6.22266","0.00561"
"12470","74.78400","6.23216","0.00531"
"12489","74.89800","6.24161","0.00507"
"12508","75.01200","6.25112","0.00568"
"12527","75.12600","6.26068","0.00542"
"12546","75.24000","6.27013","0.00490"
"12565","75.35400","6.27964","0.00517"
"12584","75.46800","6.28914","0.00605"
"12603","75.58200","6.29865","0.00593"
"12622","75.69600","6.30815","0.00527"
"12641","75.81000","6.31766","0.00557"
"12660","75.92400","6.32717","0.00543"
"12679","76.03800","6.33661","0.00585"
"12698","76.15200","6.34612","0.00553"
"12717","76.26600","6.35563","0.00538"
"12736","76.38000","6.36519","0.00550"
"12755","76.49400","6.37464","0.00544"
"12774","76.60800","6.38409","0.00561"
"12793","76.72200","6.39365","0.00614"
"12812","76.83600","6.40316","0.00509"
"12831","76.95000","6.41267","0.00583"
"12850","77.06400","6.42211","0.00590"
"12869","77.17800","6.43168","0.00557"
"12888","77.29200","6.44119","0.00630"
"12907","77.40600","6.45063","0.00543"
"12926","77.52000","6.46014","0.00504"
"12945","77.63400","6.46959","0.00571"
"12964","77.74800","6.47909","0.00581"
"12983","77.86200","6.48860","0.00598"
"13002","77.97600","6.49817","0.00627"
"13021","78.09000","6.50761","0.00556"
"13040","78.20400","6.51706","0.00553"
"13059","78.31800","6.52663","0.00599"
"13078","78.43200","6.53613","0.00478"
"13097","78.54600","6.54564","0.00584"
"13116","78.66000","6.55509","0.00587"
"13135","78.77400","6.56459","0.00611"
"13154","78.88800","6.57410","0.00528"
"13173","79.00200","6.58360","0.00653"
"13192","79.11600","6.59311","0.00619"
"13211","79.23000","6.60256","0.00607"
"13230","79.34400","6.61212","0.00544"
"13249","79.45800","6.62163","0.00570"
"13268","79.57200","6.63114","0.00593"
"13287","79.68600","6.64064","0.00560"
"13306","79.80000","6.65009","0.00618"
"13325","79.91400","6.65960","0.00617"
"13344","80.02800","6.66916","0.00627"
"13363","80.14200","6.67867","0.00588"
"13382","80.25600","6.68818","0.00684"
"13401","80.37000","6.69762","0.00624"
"13420","80.48400","6.70713","0.00589"
"13439","80.59800","6.71664","0.00590"
"13458","80.71200","6.72614","0.00607"
"13477","80.82600","6.73559","0.00648"
"13496","80.94000","6.74510","0.00624"
"13515","81.05400","6.75460","0.00608"
"13534","81.16800","6.76417","0.00640"
"13553","81.28200","6.77362","0.00648"
"13572","81.39600","6.78312","0.00557"
"13591","81.51000","6.79257","0.00649"
"13610","81.62400","6.80220","0.00614"
"13629","81.73800","6.81164","0.00596"
"13648","81.85200","6.82115","0.00644"
"13667","81.96600","6.83060","0.00618"
"13686","82.08000","6.84016","0.00616"
"13705","82.19400","6.84967","0.00596"
"13724","82.30800","6.85917","0.00638"
"13743","82.42200","6.86862","0.00640"
"13762","82.53600","6.87813","0.00644"
"13781","82.65000","6.88764","0.00652"
"13800","82.76400","6.89720","0.00670"
"13819","82.87800","6.90671","0.00640"
"13838","82.99200","6.91609","0.00666"
"13857","83.10600","6.92560","0.00622"
"13876","83.22000","6.93517","0.00665"
"13895","83.33400","6.94461","0.00664"
"13914","83.44800","6.95412","0.00639"
"13933","83.56200","6.96363","0.00648"
"13952","83.67600","6.97313","0.00642"
"13971","83.79000","6.98264","0.00635"
"13990","83.90400","6.99215","0.00624"
"14009","84.01800","7.00165","0.00623"
"14028","84.13200","7.01110","0.00632"
"14047","84.24600","7.02061","0.00649"
"14066","84.36000","7.03011","0.00609"
"14085","84.47400","7.03968","0.00649"
"14104","84.58800","7.04913","0.00660"
"14123","84.70200","7.05857","0.00645"
"14142","84.81600","7.06820","0.00710"
"14161","84.93000","7.07771","0.00714"
"14180","85.04400","7.08715","0.00644"
"14199","85.15800","7.09666","0.00625"
"14218","85.27200","7.10611","0.00634"
"14237","85.38600","7.11567","0.00675"
"14256","85.50000","7.12518","0.00723"
"14275","85.61400","7.13463","0.00673"
"14294","85.72800","7.14413","0.00651"
"14313","85.84200","7.15358","0.00747"
"14332","85.95600","7.16314","0.00617"
"14351","86.07000","7.17271","0.00732"
"14370","86.18400","7.18210","0.00681"
"14389","86.29800","7.19155","0.00708"
"14408","86.41200","7.20117","0.00718"
"14427","86.52600","7.21068","0.00706"
"14446","86.64000","7.22018","0.00668"
"14465","86.75400","7.22963","0.00714"
"14484","86.86800","7.23908","0.00720"
"14503","86.98200","7.24864","0.00665"
"14522","87.09600","7.25815","0.00731"
"14541","87.21000","7.26766","0.00642"
"14560","87.32400","7.27710","0.00727"
"14579","87.43800","7.28661","0.00657"
"14598","87.55200","7.29612","0.00646"
"14617","87.66600","7.30568","0.00684"
"14636","87.78000","7.31513","0.00665"
"14655","87.89400","7.32458","0.00738"
"14674","88.00800","7.33414","0.00727"
"14693","88.12200","7.34365","0.00738"
"14712","88.23600","7.35322","0.00736"
"14731","88.35000","7.36266","0.00679"
"14750","88.46400","7.37205","0.00730"
"14769","88.57800","7.38162","0.00731"
"14788","88.69200","7.39112","0.00707"
"14807","88.80600","7.40063","0.00735"
"14826","88.92000","7.41014","0.00759"
"14845","89.03400","7.41958","0.00803"
"14864","89.14800","7.42915","0.00677"
"14883","89.26200","7.43865","0.00765"
"14902","89.37600","7.44810","0.00707"
"14921","89.49000","7.45761","0.00708"
"14940","89.60400","7.46712","0.00702"
"14959","89.71800","7.47662","0.00732"
"14978","89.83200","7.48619","0.00744"
"14997","89.94600","7.49563","0.00721"
"15016","90.06000","7.50514","0.00738"
"15035","90.17400","7.51465","0.00758"
"15054","90.28800","7.52415","0.00759"
"15073","90.40200","7.53366","0.00757"
"15092","90.51600","7.54311","0.00759"
"15111","90.63000","7.55255","0.00786"
"15130","90.74400","7.56212","0.00683"
"15149","90.85800","7.57163","0.00744"
"15168","90.97200","7.58113","0.00767"
"15187","91.08600","7.59064","0.00752"
"15206","91.20000","7.60009","0.00721"
"15225","91.31400","7.60959","0.00783"
"15244","91.42800","7.61916","0.00764"
"15263","91.54200","7.62867","0.00773"
"15282","91.65600","7.63811","0.00776"
"15301","91.77000","7.64762","0.00786"
"15320","91.88400","7.65713","0.00781"
"15339","91.99800","7.66669","0.00785"
"15358","92.11200","7.67614","0.00795"
"15377","92.22600","7.68559","0.00733"
"15396","92.34000","7.69515","0.00805"
"15415","92.45400","7.70460","0.00721"
"15434","92.56800","7.71411","0.00814"
"15453","92.68200","7.72361","0.00796"
"15472","92.79600","7.73312","0.00758"
"15491","92.91000","7.74269","0.00756"
"15510","93.02400","7.75219","0.00756"
"15529","93.13800","7.76164","0.00778"
"15548","93.25200","7.77109","0.00802"
"15567","93.36600","7.78065","0.00749"
"15586","93.48000","7.79016","0.00797"
"15605","93.59400","7.79966","0.00758"
"15624","93.70800","7.80911","0.00760"
"15643","93.82200","7.81856","0.00747"
"15662","93.93600","7.82812","0.00764"
"15681","94.05000","7.83769","0.00777"
"15700","94.16400","7.84714","0.00852"
"15719","94.27800","7.85664","0.00797"
"15738","94.39200","7.86609","0.00818"
"15757","94.50600","7.87560","0.00866"
"15776","94.62000","7.88510","0.00808"
"15795","94.73400","7.89461","0.00785"
"15814","94.84800","7.90412","0.00791"
"15833","94.96200","7.91362","0.00815"
"15852","95.07600","7.92313","0.00822"
"15871","95.19000","7.93270","0.00773"
"15890","95.30400","7.94214","0.00865"
"15909","95.41800","7.95159","0.00798"
"15928","95.53200","7.96116","0.00847"
"15947","95.64600","7.97066","0.00755"
"15966","95.76000","7.98017","0.00878"
"15985","95.87400","7.98962","0.00867"
"16004","95.98800","7.99912","0.00835"
"16023","96.10200","8.00863","0.00914"
"16042","96.21600","8.01814","0.00799"
"16061","96.33000","8.02764","0.00790"
"16080","96.44400","8.03715","0.00876"
"16099","96.55800","8.04659","0.00823"
"16118","96.67200","8.05616","0.00890"
"16137","96.78600","8.06567","0.00879"
"16156","96.90000","8.07511","0.00902"
"16175","97.01400","8.08456","0.00881"
"16194","97.12800","8.09413","0.00881"
"16213","97.24200","8.10363","0.00818"
"16232","97.35600","8.11314","0.00889"
"16251","97.47000","8.12259","0.00888"
"16270","97.58400","8.13209","0.00875"
"16289","97.69800","8.14166","0.00843"
"16308","97.81200","8.15117","0.00912"
"16327","97.92600","8.16061","0.00920"
"16346","98.04000","8.17012","0.00829"
"16365","98.15400","8.17963","0.00845"
"16384","98.26800","8.18913","0.00851"
"16403","98.38200","8.19864","0.00879"
"16422","98.49600","8.20815","0.00841"
"16441","98.61000","8.21759","0.00848"
"16460","98.72400","8.22710","0.00900"
"16479","98.83800","8.23667","0.00841"
"16498","98.95200","8.24617","0.00863"
"16517","99.06600","8.25562","0.00873"
"16536","99.18000","8.26513","0.00871"
"16555","99.29400","8.27463","0.00855"
"16574","99.40800","8.28420","0.00853"
"16593","99.52200","8.29365","0.00842"
"16612","99.63600","8.30309","0.00844"
"16631","99.75000","8.31254","0.00891"
"16650","99.86400","8.32210","0.00929"
"16669","99.97800","8.33167","0.00888"
"16688","100.09200","8.34112","0.00927"
"16707","100.20600","8.35056","0.00901"
"16726","100.32000","8.36013","0.00917"
"16745","100.43400","8.36964","0.00949"
"16764","100.54800","8.37914","0.00894"
"16783","100.66200","8.38865","0.00900"
"16802","100.77600","8.39816","0.00852"
"16821","100.89000","8.40760","0.00887"
"16840","101.00400","8.41717","0.00968"
"16859","101.11800","8.42668","0.00880"
"16878","101.23200","8.43612","0.00922"
"16897","101.34600","8.44557","0.00940"
"16916","101.46000","8.45514","0.00953"
"16935","101.57400","8.46470","0.00893"
"16954","101.68800","8.47415","0.00927"
"16973","101.80200","8.48360","0.00921"
"16992","101.91600","8.49304","0.00956"
"17011","102.03000","8.50267","0.00941"
"17030","102.14400","8.51218","0.00925"
"17049","102.25800","8.52162","0.00972"
"17068","102.37200","8.53107","0.00992"
"17087","102.48600","8.54058","0.00916"
"17106","102.60000","8.55014","0.00976"
"17125","102.71400","8.55971","0.00930"
"17144","102.82800","8.56916","0.00995"
"17163","102.94200","8.57860","0.00908"
"17182","103.05600","8.58811","0.00963"
"17201","103.17000","8.59767","0.00977"
"17220","103.28400","8.60718","0.00959"
"17239","103.39800","8.61663","0.00943"
"17258","103.51200","8.62608","0.00904"
"17277","103.62600","8.63564","0.00975"
"17296","103.74000","8.64515","0.00957"
"17315","103.85400","8.65465","0.00965"
"17334","103.96800","8.66410","0.00966"
"17353","104.08200","8.67355","0.00943"
"17372","104.19600","8.68317","0.00964"
"17391","104.31000","8.69268","0.00947"
"17410","104.42400","8.70219","0.01017"
"17429","104.53800","8.71163","0.00906"
"17448","104.65200","8.72114","0.00951"
"17467","104.76600","8.73065","0.00981"
"17486","104.88000","8.74015","0.00913"
"17505","104.99400","8.74966","0.01015"
"17524","105.10800","8.75911","0.00992"
"17543","105.22200","8.76861","0.00978"
"17562","105.33600","8.77812","0.00999"
"17581","105.45000","8.78769","0.01003"
"17600","105.56400","8.79719","0.00972"
"17619","105.67800","8.80658","0.00984"
"17638","105.79200","8.81615","0.00980"
"17657","105.90600","8.82565","0.01007"
"17676","106.02000","8.83516","0.01017"
"17695","106.13400","8.84467","0.00979"
"17714","106.24800","8.85405","0.01023"
"17733","106.36200","8.86362","0.00988"
"17752","106.47600","8.87313","0.01012"
"17771","106.59000","8.88263","0.00997"
"17790","106.70400","8.89214","0.00980"
"17809","106.81800","8.90158","0.00952"
"17828","106.93200","8.91109","0.00982"
"17847","107.04600","8.92066","0.00981"
"17866","107.16000","8.93016","0.01026"
"17885","107.27400","8.93955","0.00964"
"17904","107.38800","8.94912","0.00978"
"17923","107.50200","8.95862","0.00990"
"17942","107.61600","8.96813","0.00996"
"17961","107.73000","8.97764","0.00934"
"17980","107.84400","8.98708","0.01023"
"17999","107.95800","8.99665","0.00945"
"18018","108.07200","9.00616","0.00964"
"18037","108.18600","9.01566","0.00987"
"18056","108.30000","9.02511","0.00932"
"18075","108.41400","9.03462","0.00972"
"18094","108.52800","9.04412","0.00987"
"18113","108.64200","9.05363","0.00992"
"18132","108.75600","9.06308","0.01048"
"18151","108.87000","9.07258","0.01014"
"18170","108.98400","9.08215","0.00985"
"18189","109.09800","9.09166","0.00976"
"18208","109.21200","9.10116","0.01028"
"18227","109.32600","9.11061","0.01016"
"18246","109.44000","9.12012","0.01015"
"18265","109.55400","9.12968","0.01009"
"18284","109.66800","9.13913","0.00990"
"18303","109.78200","9.14858","0.01066"
"18322","109.89600","9.15808","0.00985"
"18341","110.01000","9.16759","0.00968"
"18360","110.12400","9.17715","0.01017"
"18379","110.23800","9.18660","0.00973"
"18398","110.35200","9.19617","0.01053"
"18417","110.46600","9.20562","0.01028"
"18436","110.58000","9.21512","0.00991"
"18455","110.69400","9.22469","0.00954"
"18474","110.80800","9.23419","0.01024"
"18493","110.92200","9.24364","0.01013"
"18512","111.03600","9.25309","0.00956"
"18531","111.15000","9.26259","0.00938"
"18550","111.26400","9.27210","0.00977"
"18569","111.37800","9.28161","0.00985"
"18588","111.49200","9.29111","0.00982"
"18607","111.60600","9.30062","0.01043"
"18626","111.72000","9.31013","0.01059"
"18645","111.83400","9.31963","0.00969"
"18664","111.94800","9.32920","0.01004"
"18683","112.06200","9.33859","0.00994"
"18702","112.17600","9.34809","0.01052"
"18721","112.29000","9.35760","0.00990"
"18740","112.40400","9.36717","0.01008"
"18759","112.51800","9.37661","0.00978"
"18778","112.63200","9.38612","0.01043"
"18797","112.74600","9.39563","0.01020"
"18816","112.86000","9.40519","0.01046"
"18835","112.97400","9.41464","0.00979"
"18854","113.08800","9.42409","0.01082"
"18873","113.20200","9.43359","0.01060"
"18892","113.31600","9.44316","0.01030"
"18911","113.43000","9.45261","0.01132"
"18930","113.54400","9.46217","0.01064"
"18949","113.65800","9.47162","0.01092"
"18968","113.77200","9.48113","0.01097"
"18987","113.88600","9.49069","0.01043"
"19006","114.00000","9.50014","0.01026"
"19025","114.11400","9.50964","0.01018"
"19044","114.22800","9.51909","0.01062"
"19063","114.34200","9.52866","0.01018"
"19082","114.45600","9.53816","0.01019"
"19101","114.57000","9.54761","0.01058"
"19120","114.68400","9.55712","0.01024"
"19139","114.79800","9.56662","0.01039"
"19158","114.91200","9.57613","0.01081"
"19177","115.02600","9.58564","0.01080"
"19196","115.14000","9.59508","0.01081"
"19215","115.25400","9.60459","0.01061"
"19234","115.36800","9.61410","0.01069"
"19253","115.48200","9.62366","0.01058"
"19272","115.59600","9.63311","0.01073"
"19291","115.71000","9.64262","0.01112"
"19310","115.82400","9.65212","0.01065"
"19329","115.93800","9.66163","0.01115"
"19348","116.05200","9.67114","0.01051"
"19367","116.16600","9.68064","0.01052"
"19386","116.28000","9.69015","0.01052"
"19405","116.39400","9.69960","0.01152"
"19424","116.50800","9.70910","0.01074"
"19443","116.62200","9.71867","0.01114"
"19462","116.73600","9.72812","0.01085"
"19481","116.85000","9.73756","0.01101"
"19500","116.96400","9.74707","0.01128"
"19519","117.07800","9.75664","0.01132"
"19538","117.19200","9.76614","0.01119"
"19557","117.30600","9.77565","0.01066"
"19576","117.42000","9.78510","0.01080"
"19595","117.53400","9.79460","0.01068"
"19614","117.64800","9.80411","0.01163"
"19633","117.76200","9.81367","0.01150"
"19652","117.87600","9.82312","0.01154"
"19671","117.99000","9.83263","0.01055"
"19690","118.10400","9.84213","0.01135"
"19709","118.21800","9.85170","0.01125"
"19728","118.33200","9.86115","0.01124"
"19747","118.44600","9.87059","0.01103"
"19766","118.56000","9.88010","0.01150"
"19785","118.67400","9.88961","0.01124"
"19804","118.78800","9.89917","0.01148"
"19823","118.90200","9.90868","0.01193"
"19842","119.01600","9.91807","0.01103"
"19861","119.13000","9.92757","0.01116"
"19880","119.24400","9.93714","0.01152"
"19899","119.35800","9.94665","0.01184"
"19918","119.47200","9.95615","0.01150"
"19937","119.58600","9.96560","0.01133"
"19956","119.70000","9.97505","0.01171"
"19975","119.81400","9.98467","0.01208"
"19994","119.92800","9.99418","0.01183"
"20013","120.04200","10.00363","0.01131"
"20032","120.15600","10.01313","0.01153"
"20051","120.27000","10.02264","0.01216"
"20070","120.38400","10.03221","0.01195"
"20089","120.49800","10.04171","0.01201"
"20108","120.61200","10.05110","0.01217"
"20127","120.72600","10.06055","0.01227"
"20146","120.84000","10.07011","0.01154"
"20165","120.95400","10.07968","0.01203"
"20184","121.06800","10.08918","0.01201"
"20203","121.18200","10.09863","0.01244"
"20222","121.29600","10.10808","0.01240"
"20241","121.41000","10.11764","0.01196"
"20260","121.52400","10.12715","0.01214"
"20279","121.63800","10.13666","0.01236"
"20298","121.75200","10.14610","0.01201"
"20317","121.86600","10.15561","0.01203"
"20336","121.98000","10.16512","0.01215"
"20355","122.09400","10.17468","0.01206"
"20374","122.20800","10.18413","0.01259"
"20393","122.32200","10.19358","0.01272"
"20412","122.43600","10.20314","0.01266"
"20431","122.55000","10.21265","0.01228"
"20450","122.66400","10.22216","0.01212"
"20469","122.77800","10.23160","0.01266"
"20488","122.89200","10.24105","0.01215"
"20507","123.00600","10.25062","0.01216"
"20526","123.12000","10.26012","0.01270"
"20545","123.23400","10.26969","0.01190"
"20564","123.34800","10.27914","0.01293"
"20583","123.46200","10.28858","0.01318"
"20602","123.57600","10.29815","0.01268"
"20621","123.69000","10.30760","0.01198"
"20640","123.80400","10.31716","0.01257"
"20659","123.91800","10.32661","0.01249"
"20678","124.03200","10.33612","0.01231"
"20697","124.14600","10.34562","0.01287"
"20716","124.26000","10.35519","0.01266"
"20735","124.37400","10.36469","0.01279"
"20754","124.48800","10.37408","0.01268"
"20773","124.60200","10.38359","0.01309"
"20792","124.71600","10.39316","0.01302"
"20811","124.83000","10.40266","0.01306"
"20830","124.94400","10.41211","0.01316"
"20849","125.05800","10.42155","0.01321"
"20868","125.17200","10.43112","0.01349"
"20887","125.28600","10.44063","0.01327"
"20906","125.40000","10.45013","0.01276"
"20925","125.51400","10.45964","0.01305"
"20944","125.62800","10.46909","0.01278"
"20963","125.74200","10.47865","0.01295"
"20982","125.85600","10.48810","0.01353"
"21001","125.97000","10.49767","0.01354"
"21020","126.08400","10.50705","0.01303"
"21039","126.19800","10.51662","0.01378"
"21058","126.31200","10.52613","0.01337"
"21077","126.42600","10.53563","0.01322"
"21096","126.54000","10.54514","0.01284"
"21115","126.65400","10.55459","0.01317"
"21134","126.76800","10.56415","0.01376"
"21153","126.88200","10.57366","0.01354"
"21172","126.99600","10.58317","0.01352"
"21191","127.11000","10.59261","0.01333"
"21210","127.22400","10.60206","0.01379"
"21229","127.33800","10.61163","0.01285"
"21248","127.45200","10.62113","0.01366"
"21267","127.56600","10.63064","0.01352"
"21286","127.68000","10.64009","0.01349"
"21305","127.79400","10.64959","0.01336"
"21324","127.90800","10.65922","0.01376"
"21343","128.02200","10.66866","0.01364"
"21362","128.13600","10.67817","0.01318"
"21381","128.25000","10.68756","0.01350"
"21400","128.36400","10.69712","0.01349"
"21419","128.47800","10.70663","0.01359"
"21438","128.59200","10.71614","0.01369"
"21457","128.70599","10.72564","0.01365"
"21476","128.82001","10.73509","0.01358"
"21495","128.93401","10.74460","0.01388"
"21514","129.04800","10.75416","0.01392"
"21533","129.16200","10.76361","0.01364"
"21552","129.27600","10.77306","0.01324"
"21571","129.39000","10.78262","0.01407"
"21590","129.50400","10.79213","0.01394"
"21609","129.61800","10.80164","0.01377"
"21628","129.73199","10.81114","0.01388"
"21647","129.84599","10.82065","0.01416"
"21666","129.96001","10.83010","0.01384"
"21685","130.07401","10.83960","0.01414"
"21704","130.18800","10.84911","0.01445"
"21723","130.30200","10.85862","0.01410"
"21742","130.41600","10.86812","0.01447"
"21761","130.53000","10.87763","0.01401"
"21780","130.64400","10.88713","0.01439"
"21799","130.75800","10.89664","0.01387"
"21818","130.87199","10.90609","0.01409"
"21837","130.98599","10.91566","0.01397"
"21856","131.10001","10.92516","0.01413"
"21875","131.21400","10.93461","0.01417"
"21894","131.32800","10.94412","0.01497"
"21913","131.44200","10.95362","0.01435"
"21932","131.55600","10.96313","0.01414"
"21951","131.67000","10.97263","0.01414"
"21970","131.78400","10.98214","0.01429"
"21989","131.89799","10.99165","0.01435"
"22008","132.01199","11.00109","0.01449"
"22027","132.12601","11.01060","0.01457"
"22046","132.24001","11.02017","0.01461"
"22065","132.35400","11.02962","0.01417"
"22084","132.46800","11.03912","0.01474"
"22103","132.58200","11.04857","0.01466"
"22122","132.69600","11.05813","0.01444"
"22141","132.81000","11.06764","0.01460"
"22160","132.92400","11.07715","0.01527"
"22179","133.03799","11.08665","0.01463"
"22198","133.15199","11.09610","0.01464"
"22217","133.26601","11.10567","0.01475"
"22236","133.38000","11.11511","0.01431"
"22255","133.49400","11.12462","0.01445"
"22274","133.60800","11.13413","0.01463"
"22293","133.72200","11.14363","0.01479"
"22312","133.83600","11.15320","0.01511"
"22331","133.95000","11.16265","0.01538"
"22350","134.06400","11.17209","0.01503"
"22369","134.17799","11.18160","0.01504"
"22388","134.29201","11.19111","0.01509"
"22407","134.40601","11.20067","0.01570"
"22426","134.52000","11.21012","0.01508"
"22445","134.63400","11.21956","0.01550"
"22464","134.74800","11.22907","0.01528"
"22483","134.86200","11.23864","0.01536"
"22502","134.97600","11.24815","0.01539"
"22521","135.09000","11.25765","0.01531"
"22540","135.20399","11.26710","0.01546"
"22559","135.31799","11.27666","0.01597"
"22578","135.43201","11.28617","0.01589"
"22597","135.54601","11.29568","0.01517"
"22616","135.66000","11.30512","0.01555"
"22635","135.77400","11.31457","0.01539"
"22654","135.88800","11.32414","0.01560"
"22673","136.00200","11.33370","0.01544"
"22692","136.11600","11.34315","0.01499"
"22711","136.23000","11.35260","0.01556"
"22730","136.34399","11.36204","0.01574"
"22749","136.45799","11.37161","0.01494"
"22768","136.57201","11.38118","0.01533"
"22787","136.68600","11.39062","0.01504"
"22806","136.80000","11.40013","0.01562"
"22825","136.91400","11.40958","0.01499"
"22844","137.02800","11.41914","0.01569"
"22863","137.14200","11.42865","0.01524"
"22882","137.25600","11.43816","0.01578"
"22901","137.37000","11.44760","0.01581"
"22920","137.48399","11.45711","0.01609"
"22939","137.59801","11.46668","0.01566"
"22958","137.71201","11.47618","0.01545"
"22977","137.82600","11.48557","0.01557"
"22996","137.94000","11.49508","0.01561"
"23015","138.05400","11.50458","0.01506"
"23034","138.16800","11.51415","0.01611"
"23053","138.28200","11.52366","0.01572"
"23072","138.39600","11.53310","0.01615"
"23091","138.50999","11.54255","0.01529"
"23110","138.62399","11.55218","0.01616"
"23129","138.73801","11.56168","0.01576"
"23148","138.85201","11.57119","0.01616"
"23167","138.96600","11.58057","0.01579"
"23186","139.08000","11.59008","0.01583"
"23205","139.19400","11.59959","0.01581"
"23224","139.30800","11.60915","0.01605"
"23243","139.42200","11.61866","0.01557"
"23262","139.53600","11.62811","0.01637"
"23281","139.64999","11.63761","0.01649"
"23300","139.76401","11.64712","0.01641"
"23319","139.87801","11.65669","0.01671"
"23338","139.99200","11.66613","0.01626"
"23357","140.10600","11.67552","0.01682"
"23376","140.22000","11.68515","0.01686"
"23395","140.33400","11.69465","0.01637"
"23414","140.44800","11.70416","0.01659"
"23433","140.56200","11.71361","0.01630"
"23452","140.67599","11.72311","0.01756"
"23471","140.78999","11.73268","0.01662"
"23490","140.90401","11.74213","0.01730"
"23509","141.01801","11.75163","0.01627"
"23528","141.13200","11.76108","0.01674"
"23547","141.24600","11.77059","0.01690"
"23566","141.36000","11.78015","0.01670"
"23585","141.47400","11.78966","0.01666"
"23604","141.58800","11.79917","0.01717"
"23623","141.70200","11.80861","0.01699"
"23642","141.81599","11.81812","0.01745"
"23661","141.92999","11.82769","0.01759"
"23680","142.04401","11.83713","0.01731"
"23699","142.15800","11.84664","0.01781"
"23718","142.27200","11.85609","0.01716"
"23737","142.38600","11.86559","0.01733"
"23756","142.50000","11.87516","0.01727"
"23775","142.61400","11.88466","0.01704"
"23794","142.72800","11.89411","0.01764"
"23813","142.84200","11.90362","0.01807"
"23832","142.95599","11.91312","0.01743"
"23838","142.99001","11.91599","0.01795"