File: Trajectories_together/161104Specimen_RawData_6.csv
"","V1","V2","V3"
"1","End date","11/4/2016",""
"2","Specimen label","63G_21",""
"3","Maximum Load","-0.00015","N"
"4","Time","Extension","Load"
"5","(s)","(mm)","(N)"
"6","0.00000","-0.56860","-0.00761"
"8","0.01200","-0.56860","-0.00769"
"10","0.02400","-0.56842","-0.00771"
"12","0.03600","-0.56818","-0.00760"
"14","0.04800","-0.56776","-0.00752"
"16","0.06000","-0.56728","-0.00746"
"18","0.07200","-0.56680","-0.00743"
"20","0.08400","-0.56609","-0.00736"
"22","0.09600","-0.56531","-0.00735"
"24","0.10800","-0.56441","-0.00742"
"26","0.12000","-0.56340","-0.00737"
"28","0.13200","-0.56232","-0.00733"
"30","0.14400","-0.56118","-0.00732"
"32","0.15600","-0.55987","-0.00730"
"34","0.16800","-0.55855","-0.00727"
"36","0.18000","-0.55724","-0.00716"
"38","0.19200","-0.55592","-0.00704"
"40","0.20400","-0.55461","-0.00696"
"42","0.21600","-0.55323","-0.00689"
"44","0.22800","-0.55186","-0.00681"
"46","0.24000","-0.55054","-0.00683"
"48","0.25200","-0.54923","-0.00680"
"50","0.26400","-0.54797","-0.00667"
"52","0.27600","-0.54666","-0.00658"
"54","0.28800","-0.54540","-0.00651"
"56","0.30000","-0.54426","-0.00656"
"58","0.31200","-0.54307","-0.00664"
"60","0.32400","-0.54193","-0.00660"
"62","0.33600","-0.54080","-0.00645"
"64","0.34800","-0.53966","-0.00640"
"66","0.36000","-0.53852","-0.00643"
"68","0.37200","-0.53751","-0.00649"
"70","0.38400","-0.53643","-0.00640"
"72","0.39600","-0.53536","-0.00634"
"74","0.40800","-0.53434","-0.00641"
"76","0.42000","-0.53332","-0.00639"
"78","0.43200","-0.53231","-0.00638"
"80","0.44400","-0.53129","-0.00636"
"82","0.45600","-0.53027","-0.00625"
"84","0.46800","-0.52926","-0.00615"
"86","0.48000","-0.52830","-0.00618"
"88","0.49200","-0.52728","-0.00628"
"90","0.50400","-0.52633","-0.00620"
"92","0.51600","-0.52531","-0.00627"
"94","0.52800","-0.52429","-0.00639"
"96","0.54000","-0.52334","-0.00635"
"98","0.55200","-0.52232","-0.00608"
"100","0.56400","-0.52136","-0.00598"
"102","0.57600","-0.52035","-0.00602"
"104","0.58800","-0.51939","-0.00607"
"106","0.60000","-0.51838","-0.00613"
"108","0.61200","-0.51736","-0.00604"
"110","0.62400","-0.51634","-0.00599"
"112","0.63600","-0.51539","-0.00594"
"114","0.64800","-0.51437","-0.00592"
"116","0.66000","-0.51335","-0.00601"
"118","0.67200","-0.51234","-0.00603"
"120","0.68400","-0.51138","-0.00589"
"122","0.69600","-0.51036","-0.00585"
"124","0.70800","-0.50941","-0.00589"
"126","0.72000","-0.50839","-0.00580"
"128","0.73200","-0.50737","-0.00575"
"130","0.74400","-0.50636","-0.00579"
"132","0.75600","-0.50534","-0.00585"
"134","0.76800","-0.50432","-0.00594"
"136","0.78000","-0.50331","-0.00591"
"138","0.79200","-0.50235","-0.00579"
"140","0.80400","-0.50134","-0.00563"
"142","0.81600","-0.50038","-0.00534"
"144","0.82800","-0.49936","-0.00513"
"146","0.84000","-0.49841","-0.00508"
"148","0.85200","-0.49739","-0.00517"
"150","0.86400","-0.49637","-0.00531"
"152","0.87600","-0.49536","-0.00542"
"154","0.88800","-0.49434","-0.00548"
"156","0.90000","-0.49332","-0.00555"
"158","0.91200","-0.49237","-0.00560"
"160","0.92400","-0.49135","-0.00564"
"162","0.93600","-0.49033","-0.00561"
"164","0.94800","-0.48938","-0.00542"
"166","0.96000","-0.48836","-0.00542"
"168","0.97200","-0.48740","-0.00545"
"170","0.98400","-0.48639","-0.00541"
"172","0.99600","-0.48543","-0.00548"
"174","1.00800","-0.48441","-0.00548"
"176","1.02000","-0.48340","-0.00559"
"178","1.03200","-0.48244","-0.00562"
"180","1.04400","-0.48143","-0.00580"
"182","1.05600","-0.48041","-0.00576"
"184","1.06800","-0.47945","-0.00556"
"186","1.08000","-0.47844","-0.00540"
"188","1.09200","-0.47742","-0.00524"
"190","1.10400","-0.47646","-0.00520"
"192","1.11600","-0.47545","-0.00526"
"194","1.12800","-0.47443","-0.00527"
"196","1.14000","-0.47341","-0.00531"
"198","1.15200","-0.47240","-0.00522"
"200","1.16400","-0.47144","-0.00517"
"202","1.17600","-0.47042","-0.00520"
"204","1.18800","-0.46941","-0.00523"
"206","1.20000","-0.46839","-0.00525"
"208","1.21200","-0.46737","-0.00516"
"210","1.22400","-0.46636","-0.00526"
"212","1.23600","-0.46534","-0.00529"
"214","1.24800","-0.46439","-0.00521"
"216","1.26000","-0.46337","-0.00521"
"218","1.27200","-0.46235","-0.00518"
"220","1.28400","-0.46134","-0.00518"
"222","1.29600","-0.46038","-0.00515"
"224","1.30800","-0.45936","-0.00501"
"226","1.32000","-0.45835","-0.00490"
"228","1.33200","-0.45739","-0.00491"
"230","1.34400","-0.45637","-0.00487"
"232","1.35600","-0.45542","-0.00499"
"234","1.36800","-0.45440","-0.00510"
"236","1.38000","-0.45338","-0.00494"
"238","1.39200","-0.45237","-0.00499"
"240","1.40400","-0.45135","-0.00496"
"242","1.41600","-0.45033","-0.00503"
"244","1.42800","-0.44932","-0.00507"
"246","1.44000","-0.44836","-0.00493"
"248","1.45200","-0.44735","-0.00491"
"250","1.46400","-0.44639","-0.00501"
"252","1.47600","-0.44537","-0.00518"
"254","1.48800","-0.44442","-0.00528"
"256","1.50000","-0.44340","-0.00533"
"258","1.51200","-0.44244","-0.00534"
"260","1.52400","-0.44143","-0.00517"
"262","1.53600","-0.44041","-0.00504"
"264","1.54800","-0.43939","-0.00497"
"266","1.56000","-0.43838","-0.00483"
"268","1.57200","-0.43742","-0.00476"
"270","1.58400","-0.43640","-0.00462"
"272","1.59600","-0.43545","-0.00454"
"274","1.60800","-0.43449","-0.00472"
"276","1.62000","-0.43347","-0.00483"
"278","1.63200","-0.43246","-0.00486"
"280","1.64400","-0.43150","-0.00504"
"282","1.65600","-0.43048","-0.00510"
"284","1.66800","-0.42947","-0.00504"
"286","1.68000","-0.42851","-0.00501"
"288","1.69200","-0.42744","-0.00484"
"290","1.70400","-0.42648","-0.00466"
"292","1.71600","-0.42546","-0.00463"
"294","1.72800","-0.42445","-0.00462"
"296","1.74000","-0.42343","-0.00471"
"298","1.75200","-0.42247","-0.00467"
"300","1.76400","-0.42146","-0.00456"
"302","1.77600","-0.42044","-0.00448"
"304","1.78800","-0.41942","-0.00450"
"306","1.80000","-0.41841","-0.00453"
"308","1.81200","-0.41739","-0.00460"
"310","1.82400","-0.41637","-0.00460"
"312","1.83600","-0.41536","-0.00457"
"314","1.84800","-0.41434","-0.00451"
"316","1.86000","-0.41333","-0.00443"
"318","1.87200","-0.41237","-0.00446"
"320","1.88400","-0.41135","-0.00460"
"322","1.89600","-0.41040","-0.00476"
"324","1.90800","-0.40938","-0.00482"
"326","1.92000","-0.40842","-0.00477"
"328","1.93200","-0.40741","-0.00467"
"330","1.94400","-0.40639","-0.00448"
"332","1.95600","-0.40537","-0.00441"
"334","1.96800","-0.40436","-0.00444"
"336","1.98000","-0.40340","-0.00437"
"338","1.99200","-0.40238","-0.00444"
"340","2.00400","-0.40137","-0.00446"
"342","2.01600","-0.40041","-0.00450"
"344","2.02800","-0.39939","-0.00463"
"346","2.04000","-0.39844","-0.00467"
"348","2.05200","-0.39742","-0.00472"
"350","2.06400","-0.39646","-0.00470"
"352","2.07600","-0.39545","-0.00462"
"354","2.08800","-0.39443","-0.00453"
"356","2.10000","-0.39342","-0.00449"
"358","2.11200","-0.39240","-0.00448"
"360","2.12400","-0.39138","-0.00451"
"362","2.13600","-0.39043","-0.00457"
"364","2.14800","-0.38941","-0.00437"
"366","2.16000","-0.38839","-0.00428"
"368","2.17200","-0.38744","-0.00435"
"370","2.18400","-0.38642","-0.00447"
"372","2.19600","-0.38546","-0.00466"
"374","2.20800","-0.38445","-0.00456"
"376","2.22000","-0.38349","-0.00463"
"378","2.23200","-0.38247","-0.00457"
"380","2.24400","-0.38146","-0.00440"
"382","2.25600","-0.38044","-0.00440"
"384","2.26800","-0.37942","-0.00441"
"386","2.28000","-0.37841","-0.00450"
"388","2.29200","-0.37739","-0.00456"
"390","2.30400","-0.37638","-0.00436"
"392","2.31600","-0.37542","-0.00419"
"394","2.32800","-0.37440","-0.00431"
"396","2.34000","-0.37339","-0.00448"
"398","2.35200","-0.37243","-0.00457"
"400","2.36400","-0.37141","-0.00465"
"402","2.37600","-0.37040","-0.00460"
"404","2.38800","-0.36932","-0.00443"
"406","2.40000","-0.36836","-0.00446"
"408","2.41200","-0.36735","-0.00444"
"410","2.42400","-0.36633","-0.00442"
"412","2.43600","-0.36537","-0.00425"
"414","2.44800","-0.36436","-0.00395"
"416","2.46000","-0.36340","-0.00388"
"418","2.47200","-0.36238","-0.00391"
"420","2.48400","-0.36137","-0.00392"
"422","2.49600","-0.36041","-0.00408"
"424","2.50800","-0.35939","-0.00436"
"426","2.52000","-0.35838","-0.00445"
"428","2.53200","-0.35736","-0.00433"
"430","2.54400","-0.35635","-0.00418"
"432","2.55600","-0.35533","-0.00409"
"434","2.56800","-0.35431","-0.00405"
"436","2.58000","-0.35336","-0.00390"
"438","2.59200","-0.35234","-0.00363"
"440","2.60400","-0.35138","-0.00364"
"442","2.61600","-0.35043","-0.00405"
"444","2.62800","-0.34941","-0.00423"
"446","2.64000","-0.34845","-0.00414"
"448","2.65200","-0.34744","-0.00406"
"450","2.66400","-0.34642","-0.00388"
"452","2.67600","-0.34546","-0.00389"
"454","2.68800","-0.34445","-0.00390"
"456","2.70000","-0.34343","-0.00397"
"458","2.71200","-0.34241","-0.00409"
"460","2.72400","-0.34146","-0.00401"
"462","2.73600","-0.34044","-0.00389"
"464","2.74800","-0.33949","-0.00377"
"466","2.76000","-0.33847","-0.00371"
"468","2.77200","-0.33745","-0.00388"
"470","2.78400","-0.33650","-0.00403"
"472","2.79600","-0.33548","-0.00412"
"474","2.80800","-0.33446","-0.00411"
"476","2.82000","-0.33345","-0.00401"
"478","2.83200","-0.33243","-0.00389"
"480","2.84400","-0.33135","-0.00382"
"482","2.85600","-0.33040","-0.00395"
"484","2.86800","-0.32938","-0.00411"
"486","2.88000","-0.32842","-0.00433"
"488","2.89200","-0.32741","-0.00424"
"490","2.90400","-0.32639","-0.00414"
"492","2.91600","-0.32537","-0.00411"
"494","2.92800","-0.32436","-0.00406"
"496","2.94000","-0.32340","-0.00388"
"498","2.95200","-0.32239","-0.00372"
"500","2.96400","-0.32137","-0.00379"
"502","2.97600","-0.32035","-0.00396"
"504","2.98800","-0.31934","-0.00394"
"506","3.00000","-0.31832","-0.00390"
"508","3.01200","-0.31736","-0.00384"
"510","3.02400","-0.31635","-0.00390"
"512","3.03600","-0.31539","-0.00395"
"514","3.04800","-0.31437","-0.00390"
"516","3.06000","-0.31336","-0.00384"
"518","3.07200","-0.31240","-0.00378"
"520","3.08400","-0.31138","-0.00371"
"522","3.09600","-0.31037","-0.00378"
"524","3.10800","-0.30941","-0.00393"
"526","3.12000","-0.30839","-0.00403"
"528","3.13200","-0.30738","-0.00393"
"530","3.14400","-0.30636","-0.00377"
"532","3.15600","-0.30540","-0.00360"
"534","3.16800","-0.30439","-0.00352"
"536","3.18000","-0.30343","-0.00352"
"538","3.19200","-0.30242","-0.00362"
"540","3.20400","-0.30146","-0.00373"
"542","3.21600","-0.30044","-0.00377"
"544","3.22800","-0.29943","-0.00388"
"546","3.24000","-0.29841","-0.00396"
"548","3.25200","-0.29745","-0.00400"
"550","3.26400","-0.29644","-0.00408"
"552","3.27600","-0.29542","-0.00394"
"554","3.28800","-0.29440","-0.00375"
"556","3.30000","-0.29345","-0.00374"
"558","3.31200","-0.29249","-0.00374"
"560","3.32400","-0.29147","-0.00365"
"562","3.33600","-0.29046","-0.00378"
"564","3.34800","-0.28944","-0.00371"
"566","3.36000","-0.28842","-0.00379"
"568","3.37200","-0.28747","-0.00382"
"570","3.38400","-0.28645","-0.00372"
"572","3.39600","-0.28544","-0.00379"
"574","3.40800","-0.28442","-0.00367"
"576","3.42000","-0.28340","-0.00360"
"578","3.43200","-0.28239","-0.00352"
"580","3.44400","-0.28137","-0.00357"
"582","3.45600","-0.28035","-0.00358"
"584","3.46800","-0.27940","-0.00361"
"586","3.48000","-0.27838","-0.00357"
"588","3.49200","-0.27736","-0.00352"
"590","3.50400","-0.27641","-0.00362"
"592","3.51600","-0.27539","-0.00360"
"594","3.52800","-0.27437","-0.00371"
"596","3.54000","-0.27342","-0.00364"
"598","3.55200","-0.27234","-0.00352"
"600","3.56400","-0.27132","-0.00359"
"602","3.57600","-0.27037","-0.00359"
"604","3.58800","-0.26935","-0.00361"
"606","3.60000","-0.26840","-0.00357"
"608","3.61200","-0.26738","-0.00358"
"610","3.62400","-0.26636","-0.00365"
"612","3.63600","-0.26541","-0.00352"
"614","3.64800","-0.26439","-0.00333"
"616","3.66000","-0.26343","-0.00335"
"618","3.67200","-0.26242","-0.00333"
"620","3.68400","-0.26140","-0.00326"
"622","3.69600","-0.26038","-0.00309"
"624","3.70800","-0.25937","-0.00326"
"626","3.72000","-0.25841","-0.00347"
"628","3.73200","-0.25739","-0.00342"
"630","3.74400","-0.25644","-0.00329"
"632","3.75600","-0.25542","-0.00330"
"634","3.76800","-0.25446","-0.00357"
"636","3.78000","-0.25345","-0.00374"
"638","3.79200","-0.25243","-0.00380"
"640","3.80400","-0.25147","-0.00361"
"642","3.81600","-0.25046","-0.00342"
"644","3.82800","-0.24944","-0.00330"
"646","3.84000","-0.24843","-0.00327"
"648","3.85200","-0.24741","-0.00346"
"650","3.86400","-0.24645","-0.00359"
"652","3.87600","-0.24544","-0.00366"
"654","3.88800","-0.24442","-0.00359"
"656","3.90000","-0.24346","-0.00338"
"658","3.91200","-0.24245","-0.00335"
"660","3.92400","-0.24143","-0.00341"
"662","3.93600","-0.24047","-0.00321"
"664","3.94800","-0.23946","-0.00298"
"666","3.96000","-0.23844","-0.00278"
"668","3.97200","-0.23742","-0.00278"
"670","3.98400","-0.23641","-0.00268"
"672","3.99600","-0.23539","-0.00283"
"674","4.00800","-0.23438","-0.00303"
"676","4.02000","-0.23342","-0.00323"
"678","4.03200","-0.23240","-0.00326"
"680","4.04400","-0.23139","-0.00339"
"682","4.05600","-0.23043","-0.00333"
"684","4.06800","-0.22941","-0.00323"
"686","4.08000","-0.22840","-0.00329"
"688","4.09200","-0.22738","-0.00313"
"690","4.10400","-0.22636","-0.00308"
"692","4.11600","-0.22535","-0.00318"
"694","4.12800","-0.22439","-0.00322"
"696","4.14000","-0.22337","-0.00332"
"698","4.15200","-0.22236","-0.00334"
"700","4.16400","-0.22140","-0.00341"
"702","4.17600","-0.22038","-0.00331"
"704","4.18800","-0.21937","-0.00314"
"706","4.20000","-0.21841","-0.00315"
"708","4.21200","-0.21739","-0.00317"
"710","4.22400","-0.21644","-0.00317"
"712","4.23600","-0.21542","-0.00314"
"714","4.24800","-0.21441","-0.00317"
"716","4.26000","-0.21339","-0.00305"
"718","4.27200","-0.21243","-0.00309"
"720","4.28400","-0.21142","-0.00326"
"722","4.29600","-0.21046","-0.00335"
"724","4.30800","-0.20944","-0.00329"
"726","4.32000","-0.20843","-0.00334"
"728","4.33200","-0.20747","-0.00338"
"730","4.34400","-0.20645","-0.00344"
"732","4.35600","-0.20544","-0.00331"
"734","4.36800","-0.20448","-0.00315"
"736","4.38000","-0.20346","-0.00304"
"738","4.39200","-0.20245","-0.00308"
"740","4.40400","-0.20143","-0.00306"
"742","4.41600","-0.20041","-0.00310"
"744","4.42800","-0.19940","-0.00310"
"746","4.44000","-0.19844","-0.00332"
"748","4.45200","-0.19743","-0.00339"
"750","4.46400","-0.19641","-0.00324"
"752","4.47600","-0.19539","-0.00309"
"754","4.48800","-0.19444","-0.00319"
"756","4.50000","-0.19342","-0.00316"
"758","4.51200","-0.19240","-0.00314"
"760","4.52400","-0.19139","-0.00324"
"762","4.53600","-0.19043","-0.00330"
"764","4.54800","-0.18941","-0.00321"
"766","4.56000","-0.18840","-0.00302"
"768","4.57200","-0.18738","-0.00293"
"770","4.58400","-0.18642","-0.00295"
"772","4.59600","-0.18541","-0.00305"
"774","4.60800","-0.18439","-0.00298"
"776","4.62000","-0.18337","-0.00288"
"778","4.63200","-0.18236","-0.00273"
"780","4.64400","-0.18140","-0.00265"
"782","4.65600","-0.18039","-0.00274"
"784","4.66800","-0.17937","-0.00301"
"786","4.68000","-0.17841","-0.00325"
"788","4.69200","-0.17740","-0.00321"
"790","4.70400","-0.17638","-0.00314"
"792","4.71600","-0.17536","-0.00307"
"794","4.72800","-0.17435","-0.00298"
"796","4.74000","-0.17339","-0.00283"
"798","4.75200","-0.17237","-0.00287"
"800","4.76400","-0.17142","-0.00288"
"802","4.77600","-0.17040","-0.00294"
"804","4.78800","-0.16944","-0.00308"
"806","4.80000","-0.16843","-0.00308"
"808","4.81200","-0.16741","-0.00298"
"810","4.82400","-0.16645","-0.00285"
"812","4.83600","-0.16544","-0.00279"
"814","4.84800","-0.16442","-0.00299"
"816","4.86000","-0.16346","-0.00304"
"818","4.87200","-0.16245","-0.00299"
"820","4.88400","-0.16143","-0.00287"
"822","4.89600","-0.16048","-0.00262"
"824","4.90800","-0.15946","-0.00264"
"826","4.92000","-0.15844","-0.00282"
"828","4.93200","-0.15749","-0.00282"
"830","4.94400","-0.15647","-0.00291"
"832","4.95600","-0.15545","-0.00298"
"834","4.96800","-0.15444","-0.00282"
"836","4.98000","-0.15342","-0.00271"
"838","4.99200","-0.15240","-0.00262"
"840","5.00400","-0.15145","-0.00252"
"842","5.01600","-0.15043","-0.00277"
"844","5.02800","-0.14941","-0.00289"
"846","5.04000","-0.14846","-0.00267"
"848","5.05200","-0.14744","-0.00260"
"850","5.06400","-0.14642","-0.00261"
"852","5.07600","-0.14541","-0.00256"
"854","5.08800","-0.14445","-0.00262"
"856","5.10000","-0.14344","-0.00259"
"858","5.11200","-0.14242","-0.00282"
"860","5.12400","-0.14140","-0.00300"
"862","5.13600","-0.14039","-0.00294"
"864","5.14800","-0.13943","-0.00290"
"866","5.16000","-0.13841","-0.00287"
"868","5.17200","-0.13740","-0.00283"
"870","5.18400","-0.13644","-0.00281"
"872","5.19600","-0.13542","-0.00286"
"874","5.20800","-0.13441","-0.00292"
"876","5.22000","-0.13345","-0.00306"
"878","5.23200","-0.13243","-0.00289"
"880","5.24400","-0.13142","-0.00275"
"882","5.25600","-0.13046","-0.00267"
"884","5.26800","-0.12938","-0.00271"
"886","5.28000","-0.12837","-0.00255"
"888","5.29200","-0.12741","-0.00234"
"890","5.30400","-0.12640","-0.00225"
"892","5.31600","-0.12544","-0.00246"
"894","5.32800","-0.12442","-0.00275"
"896","5.34000","-0.12347","-0.00294"
"898","5.35200","-0.12245","-0.00294"
"900","5.36400","-0.12149","-0.00279"
"902","5.37600","-0.12048","-0.00241"
"904","5.38800","-0.11946","-0.00226"
"906","5.40000","-0.11844","-0.00241"
"908","5.41200","-0.11743","-0.00261"
"910","5.42400","-0.11641","-0.00273"
"912","5.43600","-0.11539","-0.00268"
"914","5.44800","-0.11444","-0.00268"
"916","5.46000","-0.11342","-0.00265"
"918","5.47200","-0.11246","-0.00269"
"920","5.48400","-0.11145","-0.00250"
"922","5.49600","-0.11043","-0.00244"
"924","5.50800","-0.10947","-0.00244"
"926","5.52000","-0.10846","-0.00238"
"928","5.53200","-0.10744","-0.00235"
"930","5.54400","-0.10643","-0.00244"
"932","5.55600","-0.10541","-0.00246"
"934","5.56800","-0.10439","-0.00242"
"936","5.58000","-0.10338","-0.00239"
"938","5.59200","-0.10242","-0.00249"
"940","5.60400","-0.10140","-0.00250"
"942","5.61600","-0.10045","-0.00252"
"944","5.62800","-0.09943","-0.00262"
"946","5.64000","-0.09841","-0.00266"
"948","5.65200","-0.09740","-0.00274"
"950","5.66400","-0.09644","-0.00265"
"952","5.67600","-0.09542","-0.00257"
"954","5.68800","-0.09441","-0.00256"
"956","5.70000","-0.09339","-0.00268"
"958","5.71200","-0.09237","-0.00264"
"960","5.72400","-0.09136","-0.00257"
"962","5.73600","-0.09034","-0.00247"
"964","5.74800","-0.08939","-0.00243"
"966","5.76000","-0.08837","-0.00234"
"968","5.77200","-0.08735","-0.00226"
"970","5.78400","-0.08640","-0.00232"
"972","5.79600","-0.08538","-0.00248"
"974","5.80800","-0.08436","-0.00245"
"976","5.82000","-0.08341","-0.00237"
"978","5.83200","-0.08239","-0.00234"
"980","5.84400","-0.08137","-0.00230"
"982","5.85600","-0.08042","-0.00221"
"984","5.86800","-0.07940","-0.00226"
"986","5.88000","-0.07844","-0.00212"
"988","5.89200","-0.07743","-0.00203"
"990","5.90400","-0.07647","-0.00215"
"992","5.91600","-0.07545","-0.00220"
"994","5.92800","-0.07444","-0.00223"
"996","5.94000","-0.07342","-0.00223"
"998","5.95200","-0.07246","-0.00235"
"1000","5.96400","-0.07145","-0.00242"
"1002","5.97600","-0.07049","-0.00239"
"1004","5.98800","-0.06948","-0.00227"
"1006","6.00000","-0.06846","-0.00224"
"1008","6.01200","-0.06744","-0.00208"
"1010","6.02400","-0.06643","-0.00191"
"1012","6.03600","-0.06541","-0.00188"
"1014","6.04800","-0.06445","-0.00208"
"1016","6.06000","-0.06344","-0.00218"
"1018","6.07200","-0.06242","-0.00236"
"1020","6.08400","-0.06140","-0.00252"
"1022","6.09600","-0.06045","-0.00254"
"1024","6.10800","-0.05943","-0.00247"
"1026","6.12000","-0.05841","-0.00243"
"1028","6.13200","-0.05740","-0.00230"
"1030","6.14400","-0.05638","-0.00219"
"1032","6.15600","-0.05542","-0.00229"
"1034","6.16800","-0.05441","-0.00216"
"1036","6.18000","-0.05339","-0.00213"
"1038","6.19200","-0.05244","-0.00222"
"1040","6.20400","-0.05142","-0.00225"
"1042","6.21600","-0.05040","-0.00213"
"1044","6.22800","-0.04945","-0.00213"
"1046","6.24000","-0.04843","-0.00210"
"1048","6.25200","-0.04741","-0.00201"
"1050","6.26400","-0.04640","-0.00206"
"1052","6.27600","-0.04538","-0.00213"
"1054","6.28800","-0.04436","-0.00214"
"1056","6.30000","-0.04341","-0.00224"
"1058","6.31200","-0.04239","-0.00238"
"1060","6.32400","-0.04143","-0.00232"
"1062","6.33600","-0.04042","-0.00211"
"1064","6.34800","-0.03946","-0.00207"
"1066","6.36000","-0.03844","-0.00219"
"1068","6.37200","-0.03743","-0.00213"
"1070","6.38400","-0.03647","-0.00196"
"1072","6.39600","-0.03546","-0.00196"
"1074","6.40800","-0.03444","-0.00215"
"1076","6.42000","-0.03342","-0.00221"
"1078","6.43200","-0.03241","-0.00208"
"1080","6.44400","-0.03145","-0.00214"
"1082","6.45600","-0.03049","-0.00212"
"1084","6.46800","-0.02948","-0.00194"
"1086","6.48000","-0.02852","-0.00165"
"1088","6.49200","-0.02750","-0.00169"
"1090","6.50400","-0.02655","-0.00159"
"1092","6.51600","-0.02553","-0.00161"
"1094","6.52800","-0.02457","-0.00170"
"1096","6.54000","-0.02356","-0.00171"
"1098","6.55200","-0.02254","-0.00190"
"1100","6.56400","-0.02146","-0.00211"
"1102","6.57600","-0.02045","-0.00199"
"1104","6.58800","-0.01943","-0.00192"
"1106","6.60000","-0.01842","-0.00169"
"1108","6.61200","-0.01740","-0.00164"
"1110","6.62400","-0.01644","-0.00193"
"1112","6.63600","-0.01543","-0.00199"
"1114","6.64800","-0.01441","-0.00202"
"1116","6.66000","-0.01345","-0.00193"
"1118","6.67200","-0.01244","-0.00184"
"1120","6.68400","-0.01142","-0.00176"
"1122","6.69600","-0.01040","-0.00171"
"1124","6.70800","-0.00939","-0.00174"
"1126","6.72000","-0.00837","-0.00195"
"1128","6.73200","-0.00735","-0.00204"
"1130","6.74400","-0.00640","-0.00208"
"1132","6.75600","-0.00538","-0.00211"
"1134","6.76800","-0.00442","-0.00205"
"1136","6.78000","-0.00341","-0.00164"
"1138","6.79200","-0.00245","-0.00140"
"1140","6.80400","-0.00143","-0.00165"
"1142","6.81600","-0.00042","-0.00177"
"1144","6.82800","0.00054","-0.00172"
"1146","6.84000","0.00161","-0.00168"
"1148","6.85200","0.00263","-0.00152"
"1150","6.86400","0.00365","-0.00152"
"1152","6.87600","0.00466","-0.00167"
"1154","6.88800","0.00562","-0.00174"
"1156","6.90000","0.00664","-0.00166"
"1158","6.91200","0.00759","-0.00173"
"1160","6.92400","0.00861","-0.00183"
"1162","6.93600","0.00957","-0.00160"
"1164","6.94800","0.01058","-0.00143"
"1166","6.96000","0.01154","-0.00155"
"1168","6.97200","0.01256","-0.00172"
"1170","6.98400","0.01357","-0.00169"
"1172","6.99600","0.01459","-0.00166"
"1174","7.00800","0.01555","-0.00164"
"1176","7.02000","0.01656","-0.00162"
"1178","7.03200","0.01758","-0.00169"
"1180","7.04400","0.01853","-0.00163"
"1182","7.05600","0.01955","-0.00158"
"1184","7.06800","0.02051","-0.00164"
"1186","7.08000","0.02152","-0.00174"
"1188","7.09200","0.02254","-0.00186"
"1190","7.10400","0.02356","-0.00166"
"1192","7.11600","0.02451","-0.00159"
"1194","7.12800","0.02553","-0.00172"
"1196","7.14000","0.02655","-0.00170"
"1198","7.15200","0.02756","-0.00175"
"1200","7.16400","0.02858","-0.00177"
"1202","7.17600","0.02954","-0.00183"
"1204","7.18800","0.03055","-0.00194"
"1206","7.20000","0.03157","-0.00188"
"1208","7.21200","0.03259","-0.00166"
"1210","7.22400","0.03354","-0.00147"
"1212","7.23600","0.03456","-0.00154"
"1214","7.24800","0.03557","-0.00176"
"1216","7.26000","0.03659","-0.00187"
"1218","7.27200","0.03761","-0.00195"
"1220","7.28400","0.03862","-0.00180"
"1222","7.29600","0.03964","-0.00169"
"1224","7.30800","0.04060","-0.00177"
"1226","7.32000","0.04161","-0.00176"
"1228","7.33200","0.04263","-0.00190"
"1230","7.34400","0.04359","-0.00184"
"1232","7.35600","0.04460","-0.00164"
"1234","7.36800","0.04556","-0.00157"
"1236","7.38000","0.04658","-0.00139"
"1238","7.39200","0.04759","-0.00143"
"1240","7.40400","0.04855","-0.00149"
"1242","7.41600","0.04957","-0.00156"
"1244","7.42800","0.05058","-0.00163"
"1246","7.44000","0.05160","-0.00163"
"1248","7.45200","0.05261","-0.00172"
"1250","7.46400","0.05357","-0.00157"
"1252","7.47600","0.05459","-0.00169"
"1254","7.48800","0.05554","-0.00177"
"1256","7.50000","0.05650","-0.00166"
"1258","7.51200","0.05752","-0.00151"
"1260","7.52400","0.05853","-0.00145"
"1262","7.53600","0.05955","-0.00150"
"1264","7.54800","0.06057","-0.00144"
"1266","7.56000","0.06158","-0.00132"
"1268","7.57200","0.06260","-0.00124"
"1270","7.58400","0.06356","-0.00137"
"1272","7.59600","0.06457","-0.00135"
"1274","7.60800","0.06553","-0.00121"
"1276","7.62000","0.06655","-0.00113"
"1278","7.63200","0.06750","-0.00117"
"1280","7.64400","0.06852","-0.00144"
"1282","7.65600","0.06954","-0.00169"
"1284","7.66800","0.07055","-0.00187"
"1286","7.68000","0.07157","-0.00185"
"1288","7.69200","0.07258","-0.00147"
"1290","7.70400","0.07360","-0.00132"
"1292","7.71600","0.07462","-0.00126"
"1294","7.72800","0.07563","-0.00098"
"1296","7.74000","0.07665","-0.00101"
"1298","7.75200","0.07761","-0.00119"
"1300","7.76400","0.07862","-0.00135"
"1302","7.77600","0.07964","-0.00150"
"1304","7.78800","0.08060","-0.00154"
"1306","7.80000","0.08161","-0.00140"
"1308","7.81200","0.08257","-0.00125"
"1310","7.82400","0.08359","-0.00116"
"1312","7.83600","0.08460","-0.00115"
"1314","7.84800","0.08556","-0.00138"
"1316","7.86000","0.08658","-0.00162"
"1318","7.87200","0.08759","-0.00173"
"1320","7.88400","0.08861","-0.00160"
"1322","7.89600","0.08956","-0.00141"
"1324","7.90800","0.09058","-0.00120"
"1326","7.92000","0.09160","-0.00112"
"1328","7.93200","0.09261","-0.00120"
"1330","7.94400","0.09363","-0.00124"
"1332","7.95600","0.09459","-0.00120"
"1334","7.96800","0.09560","-0.00132"
"1336","7.98000","0.09656","-0.00133"
"1338","7.99200","0.09758","-0.00111"
"1340","8.00400","0.09859","-0.00113"
"1342","8.01600","0.09961","-0.00117"
"1344","8.02800","0.10063","-0.00125"
"1346","8.04000","0.10158","-0.00138"
"1348","8.05200","0.10260","-0.00144"
"1350","8.06400","0.10356","-0.00142"
"1352","8.07600","0.10457","-0.00149"
"1354","8.08800","0.10559","-0.00153"
"1356","8.10000","0.10654","-0.00137"
"1358","8.11200","0.10756","-0.00123"
"1360","8.12400","0.10852","-0.00117"
"1362","8.13600","0.10953","-0.00130"
"1364","8.14800","0.11055","-0.00127"
"1366","8.16000","0.11157","-0.00133"
"1368","8.17200","0.11252","-0.00133"
"1370","8.18400","0.11354","-0.00119"
"1372","8.19600","0.11456","-0.00123"
"1374","8.20800","0.11557","-0.00144"
"1376","8.22000","0.11659","-0.00143"
"1378","8.23200","0.11761","-0.00125"
"1380","8.24400","0.11856","-0.00105"
"1382","8.25600","0.11958","-0.00126"
"1384","8.26800","0.12060","-0.00136"
"1386","8.28000","0.12161","-0.00136"
"1388","8.29200","0.12263","-0.00126"
"1390","8.30400","0.12358","-0.00123"
"1392","8.31600","0.12460","-0.00123"
"1394","8.32800","0.12562","-0.00104"
"1396","8.34000","0.12663","-0.00085"
"1398","8.35200","0.12759","-0.00088"
"1400","8.36400","0.12861","-0.00103"
"1402","8.37600","0.12962","-0.00123"
"1404","8.38800","0.13064","-0.00128"
"1406","8.40000","0.13166","-0.00132"
"1408","8.41200","0.13261","-0.00131"
"1410","8.42400","0.13363","-0.00135"
"1412","8.43600","0.13459","-0.00117"
"1414","8.44800","0.13560","-0.00105"
"1416","8.46000","0.13662","-0.00118"
"1418","8.47200","0.13764","-0.00115"
"1420","8.48400","0.13859","-0.00107"
"1422","8.49600","0.13961","-0.00113"
"1424","8.50800","0.14062","-0.00099"
"1426","8.52000","0.14158","-0.00102"
"1428","8.53200","0.14260","-0.00087"
"1430","8.54400","0.14361","-0.00078"
"1432","8.55600","0.14457","-0.00092"
"1434","8.56800","0.14559","-0.00088"
"1436","8.58000","0.14660","-0.00090"
"1438","8.59200","0.14762","-0.00102"
"1440","8.60400","0.14858","-0.00118"
"1442","8.61600","0.14959","-0.00128"
"1444","8.62800","0.15061","-0.00129"
"1446","8.64000","0.15157","-0.00125"
"1448","8.65200","0.15258","-0.00106"
"1450","8.66400","0.15360","-0.00083"
"1452","8.67600","0.15456","-0.00081"
"1454","8.68800","0.15557","-0.00105"
"1456","8.70000","0.15653","-0.00126"
"1458","8.71200","0.15755","-0.00126"
"1460","8.72400","0.15856","-0.00121"
"1462","8.73600","0.15958","-0.00121"
"1464","8.74800","0.16059","-0.00114"
"1466","8.76000","0.16155","-0.00095"
"1468","8.77200","0.16257","-0.00083"
"1470","8.78400","0.16358","-0.00075"
"1472","8.79600","0.16454","-0.00085"
"1474","8.80800","0.16556","-0.00095"
"1476","8.82000","0.16657","-0.00105"
"1478","8.83200","0.16759","-0.00101"
"1480","8.84400","0.16855","-0.00097"
"1482","8.85600","0.16956","-0.00096"
"1484","8.86800","0.17064","-0.00091"
"1486","8.88000","0.17166","-0.00092"
"1488","8.89200","0.17261","-0.00100"
"1490","8.90400","0.17357","-0.00107"
"1492","8.91600","0.17459","-0.00100"
"1494","8.92800","0.17560","-0.00080"
"1496","8.94000","0.17656","-0.00071"
"1498","8.95200","0.17757","-0.00075"
"1500","8.96400","0.17859","-0.00083"
"1502","8.97600","0.17961","-0.00093"
"1504","8.98800","0.18062","-0.00099"
"1506","9.00000","0.18164","-0.00094"
"1508","9.01200","0.18260","-0.00091"
"1510","9.02400","0.18361","-0.00084"
"1512","9.03600","0.18463","-0.00068"
"1514","9.04800","0.18559","-0.00067"
"1516","9.06000","0.18654","-0.00073"
"1518","9.07200","0.18756","-0.00095"
"1520","9.08400","0.18852","-0.00096"
"1522","9.09600","0.18953","-0.00096"
"1524","9.10800","0.19055","-0.00111"
"1526","9.12000","0.19151","-0.00127"
"1528","9.13200","0.19252","-0.00109"
"1530","9.14400","0.19360","-0.00093"
"1532","9.15600","0.19461","-0.00094"
"1534","9.16800","0.19557","-0.00093"
"1536","9.18000","0.19659","-0.00075"
"1538","9.19200","0.19754","-0.00056"
"1540","9.20400","0.19856","-0.00052"
"1542","9.21600","0.19952","-0.00052"
"1544","9.22800","0.20053","-0.00062"
"1546","9.24000","0.20155","-0.00086"
"1548","9.25200","0.20257","-0.00118"
"1550","9.26400","0.20352","-0.00134"
"1552","9.27600","0.20454","-0.00135"
"1554","9.28800","0.20562","-0.00115"
"1556","9.30000","0.20663","-0.00102"
"1558","9.31200","0.20759","-0.00095"
"1560","9.32400","0.20861","-0.00077"
"1562","9.33600","0.20962","-0.00068"
"1564","9.34800","0.21058","-0.00074"
"1566","9.36000","0.21160","-0.00065"
"1568","9.37200","0.21261","-0.00067"
"1570","9.38400","0.21357","-0.00060"
"1572","9.39600","0.21458","-0.00068"
"1574","9.40800","0.21560","-0.00110"
"1576","9.42000","0.21662","-0.00106"
"1578","9.43200","0.21757","-0.00090"
"1580","9.44400","0.21859","-0.00078"
"1582","9.45600","0.21961","-0.00086"
"1584","9.46800","0.22056","-0.00079"
"1586","9.48000","0.22158","-0.00077"
"1588","9.49200","0.22260","-0.00093"
"1590","9.50400","0.22361","-0.00096"
"1592","9.51600","0.22463","-0.00076"
"1594","9.52800","0.22559","-0.00050"
"1596","9.54000","0.22660","-0.00036"
"1598","9.55200","0.22762","-0.00044"
"1600","9.56400","0.22864","-0.00066"
"1602","9.57600","0.22965","-0.00061"
"1604","9.58800","0.23061","-0.00058"
"1606","9.60000","0.23162","-0.00082"
"1608","9.61200","0.23258","-0.00069"
"1610","9.62400","0.23360","-0.00069"
"1612","9.63600","0.23455","-0.00049"
"1614","9.64800","0.23557","-0.00062"
"1616","9.66000","0.23659","-0.00060"
"1618","9.67200","0.23754","-0.00071"
"1620","9.68400","0.23856","-0.00077"
"1622","9.69600","0.23958","-0.00072"
"1624","9.70800","0.24053","-0.00077"
"1626","9.72000","0.24155","-0.00078"
"1628","9.73200","0.24257","-0.00066"
"1630","9.74400","0.24352","-0.00072"
"1632","9.75600","0.24454","-0.00084"
"1634","9.76800","0.24556","-0.00076"
"1636","9.78000","0.24657","-0.00084"
"1638","9.79200","0.24753","-0.00087"
"1640","9.80400","0.24855","-0.00090"
"1642","9.81600","0.24956","-0.00087"
"1644","9.82800","0.25058","-0.00084"
"1646","9.84000","0.25153","-0.00077"
"1648","9.85200","0.25255","-0.00082"
"1650","9.86400","0.25357","-0.00083"
"1652","9.87600","0.25458","-0.00080"
"1654","9.88800","0.25560","-0.00064"
"1656","9.90000","0.25656","-0.00059"
"1658","9.91200","0.25757","-0.00063"
"1660","9.92400","0.25859","-0.00064"
"1662","9.93600","0.25961","-0.00060"
"1664","9.94800","0.26062","-0.00058"
"1666","9.96000","0.26158","-0.00048"
"1668","9.97200","0.26260","-0.00055"
"1670","9.98400","0.26361","-0.00053"
"1672","9.99600","0.26463","-0.00062"
"1674","10.00800","0.26559","-0.00070"
"1676","10.02000","0.26660","-0.00056"
"1678","10.03200","0.26762","-0.00037"
"1680","10.04400","0.26857","-0.00029"
"1682","10.05600","0.26959","-0.00031"
"1684","10.06800","0.27061","-0.00043"
"1686","10.08000","0.27156","-0.00055"
"1688","10.09200","0.27258","-0.00059"
"1690","10.10400","0.27360","-0.00045"
"1692","10.11600","0.27455","-0.00030"
"1694","10.12800","0.27557","-0.00024"
"1696","10.14000","0.27659","-0.00015"
"1698","10.15200","0.27760","-0.00029"
"1700","10.16400","0.27862","-0.00053"
"1702","10.17600","0.27958","-0.00048"
"1704","10.18800","0.28059","-0.00049"
"1706","10.20000","0.28155","-0.00049"
"1708","10.21200","0.28257","-0.00056"
"1710","10.22400","0.28358","-0.00064"
"1712","10.23600","0.28454","-0.00058"
"1714","10.24800","0.28555","-0.00050"
"1716","10.26000","0.28651","-0.00035"