File: Trajectories_together/161114Specimen_RawData_7.csv
"","V1","V2","V3"
"1","End date","11/14/2016",""
"2","Specimen label","20BT63.2.r2",""
"3","Maximum Load","0.05861","N"
"4","Time","Extension","Load"
"5","(s)","(mm)","(N)"
"6","0.00000","19.54173","0.00819"
"21","0.09000","19.54454","0.00726"
"36","0.18000","19.55297","0.00715"
"51","0.27000","19.56295","0.00651"
"66","0.36000","19.57174","0.00671"
"81","0.45000","19.57952","0.00738"
"96","0.54000","19.58693","0.00686"
"111","0.63000","19.59435","0.00761"
"126","0.72000","19.60188","0.00790"
"141","0.81000","19.60941","0.00642"
"156","0.90000","19.61689","0.00638"
"171","0.99000","19.62442","0.00605"
"186","1.08000","19.63189","0.00820"
"201","1.17000","19.63931","0.00780"
"216","1.26000","19.64684","0.00872"
"231","1.35000","19.65437","0.00697"
"246","1.44000","19.66191","0.00742"
"261","1.53000","19.66938","0.00684"
"276","1.62000","19.67691","0.00660"
"291","1.71000","19.68433","0.00826"
"306","1.80000","19.69180","0.00835"
"321","1.89000","19.69939","0.00745"
"336","1.98000","19.70687","0.00690"
"351","2.07000","19.71440","0.00693"
"366","2.16000","19.72187","0.00750"
"381","2.25000","19.72935","0.00714"
"396","2.34000","19.73682","0.00883"
"411","2.43000","19.74436","0.00729"
"426","2.52000","19.75189","0.00807"
"441","2.61000","19.75937","0.00698"
"456","2.70000","19.76690","0.00770"
"471","2.79000","19.77431","0.00733"
"486","2.88000","19.78179","0.00698"
"501","2.97000","19.78938","0.00839"
"516","3.06000","19.79685","0.00770"
"531","3.15000","19.80439","0.00768"
"546","3.24000","19.81186","0.00701"
"561","3.33000","19.81933","0.00726"
"576","3.42000","19.82681","0.00774"
"591","3.51000","19.83434","0.00904"
"606","3.60000","19.84187","0.00803"
"621","3.69000","19.84941","0.00845"
"636","3.78000","19.85682","0.00806"
"651","3.87000","19.86436","0.00795"
"666","3.96000","19.87177","0.00848"
"681","4.05000","19.87930","0.00807"
"696","4.14000","19.88690","0.00870"
"711","4.23000","19.89437","0.00923"
"726","4.32000","19.90184","0.00763"
"741","4.41000","19.90932","0.00703"
"756","4.50000","19.91679","0.00777"
"771","4.59000","19.92432","0.00912"
"786","4.68000","19.93186","0.00930"
"801","4.77000","19.93933","0.00897"
"816","4.86000","19.94686","0.00872"
"831","4.95000","19.95434","0.00839"
"846","5.04000","19.96181","0.00873"
"861","5.13000","19.96940","0.00856"
"876","5.22000","19.97688","0.00928"
"891","5.31000","19.98435","0.00994"
"906","5.40000","19.99188","0.00890"
"921","5.49000","19.99936","0.00862"
"936","5.58000","20.00683","0.00934"
"951","5.67000","20.01431","0.00787"
"966","5.76000","20.02190","0.00853"
"981","5.85000","20.02937","0.00949"
"996","5.94000","20.03685","0.00960"
"1011","6.03000","20.04432","0.00917"
"1026","6.12000","20.05180","0.00908"
"1041","6.21000","20.05927","0.00849"
"1056","6.30000","20.06686","0.00860"
"1071","6.39000","20.07433","0.01076"
"1086","6.48000","20.08187","0.01037"
"1101","6.57000","20.08934","0.00994"
"1116","6.66000","20.09676","0.00929"
"1131","6.75000","20.10429","0.00951"
"1146","6.84000","20.11188","0.00930"
"1161","6.93000","20.11936","0.00946"
"1176","7.02000","20.12689","0.01007"
"1191","7.11000","20.13437","0.01118"
"1206","7.20000","20.14178","0.01020"
"1221","7.29000","20.14937","0.00948"
"1236","7.38000","20.15685","0.00969"
"1251","7.47000","20.16432","0.01029"
"1266","7.56000","20.17185","0.01054"
"1281","7.65000","20.17932","0.01060"
"1296","7.74000","20.18686","0.01171"
"1311","7.83000","20.19433","0.00997"
"1326","7.92000","20.20187","0.00964"
"1341","8.01000","20.20940","0.01036"
"1356","8.10000","20.21687","0.01027"
"1371","8.19000","20.22435","0.01114"
"1386","8.28000","20.23182","0.01116"
"1401","8.37000","20.23930","0.01032"
"1416","8.46000","20.24695","0.01038"
"1431","8.55000","20.25436","0.01055"
"1446","8.64000","20.26178","0.01099"
"1461","8.73000","20.26937","0.01081"
"1476","8.82000","20.27678","0.01177"
"1491","8.91000","20.28432","0.01151"
"1506","9.00000","20.29191","0.01144"
"1521","9.09000","20.29939","0.01087"
"1536","9.18000","20.30680","0.01096"
"1551","9.27000","20.31433","0.01085"
"1566","9.36000","20.32181","0.01128"
"1581","9.45000","20.32928","0.01180"
"1596","9.54000","20.33687","0.01127"
"1611","9.63000","20.34440","0.01131"
"1626","9.72000","20.35182","0.01105"
"1641","9.81000","20.35929","0.01200"
"1656","9.90000","20.36683","0.01220"
"1671","9.99000","20.37436","0.01244"
"1686","10.08000","20.38183","0.01121"
"1701","10.17000","20.38937","0.01098"
"1716","10.26000","20.39684","0.01038"
"1731","10.35000","20.40425","0.01130"
"1746","10.44000","20.41179","0.01248"
"1761","10.53000","20.41938","0.01217"
"1776","10.62000","20.42686","0.01207"
"1791","10.71000","20.43439","0.01206"
"1806","10.80000","20.44180","0.01071"
"1821","10.89000","20.44934","0.01229"
"1836","10.98000","20.45675","0.01265"
"1851","11.07000","20.46434","0.01318"
"1866","11.16000","20.47193","0.01234"
"1881","11.25000","20.47935","0.01212"
"1896","11.34000","20.48688","0.01176"
"1911","11.43000","20.49436","0.01198"
"1926","11.52000","20.50177","0.01347"
"1941","11.61000","20.50936","0.01377"
"1956","11.70000","20.51690","0.01307"
"1971","11.79000","20.52443","0.01306"
"1986","11.88000","20.53190","0.01233"
"2001","11.97000","20.53932","0.01161"
"2016","12.06000","20.54679","0.01292"
"2031","12.15000","20.55438","0.01371"
"2046","12.24000","20.56186","0.01368"
"2061","12.33000","20.56939","0.01321"
"2076","12.42000","20.57687","0.01187"
"2091","12.51000","20.58434","0.01295"
"2106","12.60000","20.59181","0.01375"
"2121","12.69000","20.59935","0.01455"
"2136","12.78000","20.60688","0.01492"
"2151","12.87000","20.61442","0.01421"
"2166","12.96000","20.62183","0.01321"
"2181","13.05000","20.62930","0.01266"
"2196","13.14000","20.63678","0.01369"
"2211","13.23000","20.64437","0.01462"
"2226","13.32000","20.65184","0.01450"
"2241","13.41000","20.65938","0.01389"
"2256","13.50000","20.66685","0.01341"
"2271","13.59000","20.67432","0.01327"
"2286","13.68000","20.68186","0.01472"
"2301","13.77000","20.68933","0.01462"
"2316","13.86000","20.69692","0.01494"
"2331","13.95000","20.70440","0.01351"
"2346","14.04000","20.71187","0.01377"
"2361","14.13000","20.71935","0.01420"
"2376","14.22000","20.72682","0.01509"
"2391","14.31000","20.73441","0.01504"
"2406","14.40000","20.74182","0.01652"
"2421","14.49000","20.74942","0.01492"
"2436","14.58000","20.75683","0.01436"
"2451","14.67000","20.76431","0.01375"
"2466","14.76000","20.77184","0.01536"
"2481","14.85000","20.77932","0.01614"
"2496","14.94000","20.78685","0.01597"
"2511","15.03000","20.79438","0.01571"
"2526","15.12000","20.80180","0.01436"
"2541","15.21000","20.80927","0.01506"
"2556","15.30000","20.81680","0.01573"
"2571","15.39000","20.82434","0.01644"
"2586","15.48000","20.83187","0.01681"
"2601","15.57000","20.83934","0.01585"
"2616","15.66000","20.84688","0.01463"
"2631","15.75000","20.85435","0.01546"
"2646","15.84000","20.86182","0.01599"
"2661","15.93000","20.86930","0.01800"
"2676","16.02000","20.87689","0.01791"
"2691","16.11000","20.88437","0.01685"
"2706","16.20000","20.89190","0.01558"
"2721","16.29000","20.89931","0.01521"
"2736","16.38000","20.90679","0.01708"
"2751","16.47000","20.91438","0.01760"
"2766","16.56000","20.92185","0.01830"
"2781","16.65000","20.92933","0.01695"
"2796","16.74000","20.93686","0.01631"
"2811","16.83000","20.94433","0.01578"
"2826","16.92000","20.95181","0.01753"
"2841","17.01000","20.95934","0.01910"
"2856","17.10000","20.96688","0.01823"
"2871","17.19000","20.97435","0.01794"
"2886","17.28000","20.98182","0.01598"
"2901","17.37000","20.98929","0.01714"
"2916","17.46000","20.99677","0.01806"
"2931","17.55000","21.00430","0.01956"
"2946","17.64000","21.01190","0.01929"
"2961","17.73000","21.01937","0.01797"
"2976","17.82000","21.02678","0.01674"
"2991","17.91000","21.03438","0.01815"
"3006","18.00000","21.04185","0.01955"
"3021","18.09000","21.04938","0.02086"
"3036","18.18000","21.05692","0.01956"
"3051","18.27000","21.06439","0.01798"
"3066","18.36000","21.07187","0.01826"
"3081","18.45000","21.07934","0.01885"
"3096","18.54000","21.08681","0.02070"
"3111","18.63000","21.09435","0.02052"
"3126","18.72000","21.10188","0.01985"
"3141","18.81000","21.10935","0.01914"
"3156","18.90000","21.11688","0.01865"
"3171","18.99000","21.12430","0.02002"
"3186","19.08000","21.13183","0.02132"
"3201","19.17000","21.13937","0.02145"
"3216","19.26000","21.14684","0.02036"
"3231","19.35000","21.15437","0.01829"
"3246","19.44000","21.16179","0.01830"
"3261","19.53000","21.16926","0.02061"
"3276","19.62000","21.17686","0.02198"
"3291","19.71000","21.18433","0.02182"
"3306","19.80000","21.19186","0.01994"
"3321","19.89000","21.19940","0.01905"
"3336","19.98000","21.20681","0.02004"
"3351","20.07000","21.21434","0.02173"
"3366","20.16000","21.22182","0.02257"
"3381","20.25000","21.22935","0.02157"
"3396","20.34000","21.23688","0.02041"
"3411","20.43000","21.24436","0.01925"
"3426","20.52000","21.25189","0.02193"
"3441","20.61000","21.25930","0.02319"
"3456","20.70000","21.26678","0.02390"
"3471","20.79000","21.27437","0.02276"
"3486","20.88000","21.28185","0.02023"
"3501","20.97000","21.28938","0.02126"
"3516","21.06000","21.29685","0.02259"
"3531","21.15000","21.30433","0.02363"
"3546","21.24000","21.31186","0.02476"
"3561","21.33000","21.31933","0.02245"
"3576","21.42000","21.32687","0.02079"
"3591","21.51000","21.33440","0.02177"
"3606","21.60000","21.34181","0.02380"
"3621","21.69000","21.34929","0.02440"
"3636","21.78000","21.35682","0.02366"
"3651","21.87000","21.36430","0.02301"
"3666","21.96000","21.37183","0.02205"
"3681","22.05000","21.37942","0.02424"
"3696","22.14000","21.38684","0.02520"
"3711","22.23000","21.39431","0.02531"
"3726","22.32000","21.40184","0.02410"
"3741","22.41000","21.40932","0.02329"
"3756","22.50000","21.41685","0.02363"
"3771","22.59000","21.42439","0.02514"
"3786","22.68000","21.43186","0.02596"
"3801","22.77000","21.43933","0.02583"
"3816","22.86000","21.44681","0.02454"
"3831","22.95000","21.45434","0.02441"
"3846","23.04000","21.46187","0.02435"
"3861","23.13000","21.46934","0.02616"
"3876","23.22000","21.47682","0.02674"
"3891","23.31000","21.48429","0.02576"
"3906","23.40000","21.49183","0.02540"
"3921","23.49000","21.49936","0.02441"
"3936","23.58000","21.50677","0.02596"
"3951","23.67000","21.51437","0.02733"
"3966","23.76000","21.52178","0.02626"
"3981","23.85000","21.52925","0.02616"
"3996","23.94000","21.53685","0.02572"
"4011","24.03000","21.54432","0.02579"
"4026","24.12000","21.55179","0.02589"
"4041","24.21000","21.55939","0.02748"
"4056","24.30000","21.56686","0.02703"
"4071","24.39000","21.57428","0.02675"
"4086","24.48000","21.58181","0.02732"
"4101","24.57000","21.58934","0.02684"
"4116","24.66000","21.59682","0.02761"
"4131","24.75000","21.60435","0.02820"
"4146","24.84000","21.61188","0.02762"
"4161","24.93000","21.61930","0.02797"
"4176","25.02000","21.62683","0.02874"
"4191","25.11000","21.63437","0.02862"
"4206","25.20000","21.64184","0.02819"
"4221","25.29000","21.64937","0.02802"
"4236","25.38000","21.65685","0.02885"
"4251","25.47000","21.66426","0.02906"
"4266","25.56000","21.67179","0.02913"
"4281","25.65000","21.67938","0.02933"
"4296","25.74000","21.68680","0.02959"
"4311","25.83000","21.69433","0.02988"
"4326","25.92000","21.70181","0.02975"
"4341","26.01000","21.70928","0.02993"
"4356","26.10000","21.71687","0.02946"
"4371","26.19000","21.72435","0.02969"
"4386","26.28000","21.73188","0.03040"
"4401","26.37000","21.73935","0.03062"
"4416","26.46000","21.74683","0.03048"
"4431","26.55000","21.75436","0.03064"
"4446","26.64000","21.76184","0.03104"
"4461","26.73000","21.76937","0.03068"
"4476","26.82000","21.77684","0.03154"
"4491","26.91000","21.78438","0.03168"
"4506","27.00000","21.79185","0.03160"
"4521","27.09000","21.79932","0.03176"
"4536","27.18000","21.80686","0.03152"
"4551","27.27000","21.81439","0.03216"
"4566","27.36000","21.82192","0.03263"
"4581","27.45000","21.82934","0.03223"
"4596","27.54000","21.83687","0.03197"
"4611","27.63000","21.84428","0.03216"
"4626","27.72000","21.85182","0.03262"
"4641","27.81000","21.85941","0.03325"
"4656","27.90000","21.86683","0.03361"
"4671","27.99000","21.87436","0.03281"
"4686","28.08000","21.88183","0.03390"
"4701","28.17000","21.88925","0.03427"
"4716","28.26000","21.89684","0.03392"
"4731","28.35000","21.90437","0.03350"
"4746","28.44000","21.91185","0.03419"
"4761","28.53000","21.91938","0.03492"
"4776","28.62000","21.92680","0.03483"
"4791","28.71000","21.93427","0.03505"
"4806","28.80000","21.94186","0.03502"
"4821","28.89000","21.94939","0.03473"
"4836","28.98000","21.95687","0.03494"
"4851","29.07000","21.96440","0.03536"
"4866","29.16000","21.97182","0.03540"
"4881","29.25000","21.97929","0.03594"
"4896","29.34000","21.98682","0.03560"
"4911","29.43000","21.99436","0.03637"
"4926","29.52000","22.00189","0.03620"
"4941","29.61000","22.00937","0.03678"
"4956","29.70000","22.01684","0.03661"
"4971","29.79000","22.02431","0.03701"
"4986","29.88000","22.03179","0.03672"
"5001","29.97000","22.03932","0.03754"
"5016","30.06000","22.04685","0.03690"
"5031","30.15000","22.05433","0.03731"
"5046","30.24000","22.06180","0.03816"
"5061","30.33000","22.06927","0.03802"
"5076","30.42000","22.07681","0.03800"
"5091","30.51000","22.08434","0.03813"
"5106","30.60000","22.09188","0.03823"
"5121","30.69000","22.09935","0.03880"
"5136","30.78000","22.10682","0.03876"
"5151","30.87000","22.11429","0.03919"
"5166","30.96000","22.12183","0.03866"
"5181","31.05000","22.12936","0.03904"
"5196","31.14000","22.13689","0.03931"
"5211","31.23000","22.14437","0.03994"
"5226","31.32000","22.15184","0.04008"
"5241","31.41000","22.15932","0.03963"
"5256","31.50000","22.16685","0.03977"
"5271","31.59000","22.17432","0.04086"
"5286","31.68000","22.18192","0.04034"
"5301","31.77000","22.18933","0.04114"
"5316","31.86000","22.19681","0.04062"
"5331","31.95000","22.20434","0.04105"
"5346","32.04000","22.21181","0.04131"
"5361","32.13000","22.21935","0.04182"
"5376","32.22000","22.22682","0.04150"
"5391","32.31000","22.23435","0.04156"
"5406","32.40000","22.24188","0.04220"
"5421","32.49000","22.24930","0.04245"
"5436","32.58000","22.25683","0.04259"
"5451","32.67000","22.26437","0.04279"
"5466","32.76000","22.27184","0.04287"
"5481","32.85000","22.27938","0.04292"
"5496","32.94000","22.28685","0.04354"
"5511","33.03000","22.29432","0.04360"
"5526","33.12000","22.30185","0.04327"
"5541","33.21000","22.30933","0.04360"
"5556","33.30000","22.31686","0.04410"
"5571","33.39000","22.32440","0.04453"
"5586","33.48000","22.33181","0.04413"
"5601","33.57000","22.33928","0.04438"
"5616","33.66000","22.34682","0.04495"
"5631","33.75000","22.35435","0.04471"
"5646","33.84000","22.36188","0.04517"
"5661","33.93000","22.36930","0.04546"
"5676","34.02000","22.37683","0.04557"
"5691","34.11000","22.38430","0.04539"
"5706","34.20000","22.39184","0.04637"
"5721","34.29000","22.39937","0.04605"
"5736","34.38000","22.40685","0.04664"
"5751","34.47000","22.41432","0.04678"
"5766","34.56000","22.42185","0.04669"
"5781","34.65000","22.42927","0.04701"
"5796","34.74000","22.43686","0.04697"
"5811","34.83000","22.44445","0.04754"
"5826","34.92000","22.45187","0.04771"
"5841","35.01000","22.45934","0.04795"
"5856","35.10000","22.46681","0.04825"
"5871","35.19000","22.47429","0.04817"
"5886","35.28000","22.48188","0.04821"
"5901","35.37000","22.48936","0.04870"
"5916","35.46000","22.49689","0.04864"
"5931","35.55000","22.50442","0.04897"
"5946","35.64000","22.51178","0.04933"
"5961","35.73000","22.51931","0.04905"
"5976","35.82000","22.52684","0.04955"
"5991","35.91000","22.53432","0.04967"
"6006","36.00000","22.54185","0.04975"
"6021","36.09000","22.54932","0.05019"
"6036","36.18000","22.55680","0.04997"
"6051","36.27000","22.56433","0.05035"
"6066","36.36000","22.57187","0.05018"
"6081","36.45000","22.57940","0.05047"
"6096","36.54000","22.58687","0.05060"
"6111","36.63000","22.59429","0.05067"
"6126","36.72000","22.60182","0.05102"
"6141","36.81000","22.60929","0.05123"
"6156","36.90000","22.61683","0.05143"
"6171","36.99000","22.62442","0.05163"
"6186","37.08000","22.63189","0.05136"
"6201","37.17000","22.63937","0.05174"
"6216","37.26000","22.64684","0.05187"
"6231","37.35000","22.65431","0.05172"
"6246","37.44000","22.66185","0.05204"
"6261","37.53000","22.66938","0.05232"
"6276","37.62000","22.67691","0.05243"
"6291","37.71000","22.68439","0.05208"
"6306","37.80000","22.69186","0.05258"
"6321","37.89000","22.69928","0.05265"
"6336","37.98000","22.70687","0.05269"
"6351","38.07000","22.71440","0.05314"
"6366","38.16000","22.72188","0.05291"
"6381","38.25000","22.72935","0.05324"
"6396","38.34000","22.73682","0.05317"
"6411","38.43000","22.74430","0.05338"
"6426","38.52000","22.75183","0.05339"
"6441","38.61000","22.75937","0.05310"
"6456","38.70000","22.76690","0.05345"
"6471","38.79000","22.77431","0.05356"
"6486","38.88000","22.78185","0.05372"
"6501","38.97000","22.78932","0.05386"
"6516","39.06000","22.79679","0.05390"
"6531","39.15000","22.80433","0.05401"
"6546","39.24000","22.81186","0.05399"
"6561","39.33000","22.81933","0.05401"
"6576","39.42000","22.82681","0.05385"
"6591","39.51000","22.83428","0.05383"
"6606","39.60000","22.84188","0.05403"
"6621","39.69000","22.84941","0.05419"
"6636","39.78000","22.85688","0.05424"
"6651","39.87000","22.86435","0.05449"
"6666","39.96000","22.87183","0.05440"
"6681","40.05000","22.87930","0.05468"
"6696","40.14000","22.88684","0.05447"
"6711","40.23000","22.89431","0.05471"
"6726","40.32000","22.90184","0.05480"
"6741","40.41000","22.90938","0.05453"
"6756","40.50000","22.91685","0.05501"
"6771","40.59000","22.92432","0.05507"
"6786","40.68000","22.93180","0.05498"
"6801","40.77000","22.93933","0.05521"
"6816","40.86000","22.94692","0.05538"
"6831","40.95000","22.95428","0.05499"
"6846","41.04000","22.96181","0.05543"
"6861","41.13000","22.96929","0.05559"
"6876","41.22000","22.97682","0.05568"
"6891","41.31000","22.98435","0.05550"
"6906","41.40000","22.99183","0.05570"
"6921","41.49000","22.99936","0.05557"
"6936","41.58000","23.00683","0.05568"
"6951","41.67000","23.01431","0.05588"
"6966","41.76000","23.02184","0.05586"
"6981","41.85000","23.02937","0.05603"
"6996","41.94000","23.03691","0.05600"
"7011","42.03000","23.04438","0.05620"
"7026","42.12000","23.05186","0.05605"
"7041","42.21000","23.05933","0.05601"
"7056","42.30000","23.06686","0.05622"
"7071","42.39000","23.07434","0.05637"
"7086","42.48000","23.08187","0.05643"
"7101","42.57000","23.08940","0.05652"
"7116","42.66000","23.09682","0.05645"
"7131","42.75000","23.10435","0.05665"
"7146","42.84000","23.11182","0.05646"
"7161","42.93000","23.11936","0.05661"
"7176","43.02000","23.12689","0.05653"
"7191","43.11000","23.13430","0.05675"
"7206","43.20000","23.14178","0.05658"
"7221","43.29000","23.14931","0.05670"
"7236","43.38000","23.15684","0.05677"
"7251","43.47000","23.16438","0.05686"
"7266","43.56000","23.17185","0.05683"
"7281","43.65000","23.17933","0.05690"
"7296","43.74000","23.18686","0.05681"
"7311","43.83000","23.19433","0.05684"
"7326","43.92000","23.20187","0.05706"
"7341","44.01000","23.20940","0.05704"
"7356","44.10000","23.21688","0.05703"
"7371","44.19000","23.22435","0.05699"
"7386","44.28000","23.23182","0.05704"
"7401","44.37000","23.23929","0.05710"
"7416","44.46000","23.24689","0.05715"
"7431","44.55000","23.25436","0.05717"
"7446","44.64000","23.26183","0.05720"
"7461","44.73000","23.26937","0.05719"
"7476","44.82000","23.27678","0.05716"
"7491","44.91000","23.28432","0.05725"
"7506","45.00000","23.29185","0.05730"
"7521","45.09000","23.29932","0.05725"
"7536","45.18000","23.30686","0.05734"
"7551","45.27000","23.31433","0.05744"
"7566","45.36000","23.32181","0.05730"
"7581","45.45000","23.32928","0.05736"
"7596","45.54000","23.33687","0.05741"
"7611","45.63000","23.34435","0.05743"
"7626","45.72000","23.35188","0.05740"
"7641","45.81000","23.35935","0.05748"
"7656","45.90000","23.36676","0.05741"
"7671","45.99000","23.37430","0.05753"
"7686","46.08000","23.38189","0.05749"
"7701","46.17000","23.38943","0.05749"
"7716","46.26000","23.39684","0.05745"
"7731","46.35000","23.40438","0.05750"
"7746","46.44000","23.41185","0.05752"
"7761","46.53000","23.41926","0.05755"
"7776","46.62000","23.42691","0.05766"
"7791","46.71000","23.43439","0.05765"
"7806","46.80000","23.44192","0.05763"
"7821","46.89000","23.44940","0.05759"
"7836","46.98000","23.45681","0.05759"
"7851","47.07000","23.46434","0.05763"
"7866","47.16000","23.47188","0.05767"
"7881","47.25000","23.47935","0.05767"
"7896","47.34000","23.48689","0.05773"
"7911","47.43000","23.49436","0.05777"
"7926","47.52000","23.50177","0.05780"
"7941","47.61000","23.50937","0.05777"
"7956","47.70000","23.51684","0.05775"
"7971","47.79000","23.52437","0.05780"
"7986","47.88000","23.53190","0.05781"
"8001","47.97000","23.53932","0.05779"
"8016","48.06000","23.54679","0.05786"
"8031","48.15000","23.55433","0.05786"
"8046","48.24000","23.56186","0.05788"
"8061","48.33000","23.56939","0.05784"
"8076","48.42000","23.57687","0.05780"
"8091","48.51000","23.58434","0.05788"
"8106","48.60000","23.59181","0.05791"
"8121","48.69000","23.59929","0.05809"
"8136","48.78000","23.60682","0.05801"
"8151","48.87000","23.61429","0.05794"
"8166","48.96000","23.62183","0.05796"
"8181","49.05000","23.62936","0.05822"
"8196","49.14000","23.63678","0.05810"
"8211","49.23000","23.64431","0.05818"
"8226","49.32000","23.65184","0.05816"
"8241","49.41000","23.65932","0.05820"
"8256","49.50000","23.66685","0.05821"
"8271","49.59000","23.67432","0.05818"
"8286","49.68000","23.68180","0.05843"
"8301","49.77000","23.68933","0.05826"
"8316","49.86000","23.69686","0.05836"
"8331","49.95000","23.70440","0.05859"
"8346","50.04000","23.71187","0.05853"
"8361","50.13000","23.71935","0.05855"
"8376","50.22000","23.72682","0.05849"
"8391","50.31000","23.73435","0.05855"
"8406","50.40000","23.74189","0.01019"
"8421","50.49000","23.74936","0.01524"
"8436","50.58000","23.75683","0.02410"
"8451","50.67000","23.76436","0.02335"
"8466","50.76000","23.77184","0.01707"
"8481","50.85000","23.77931","0.00336"
"8496","50.94000","23.78685","0.00313"
"8511","51.03000","23.79432","0.00928"
"8526","51.12000","23.80186","0.02334"
"8541","51.21000","23.80933","0.02797"
"8556","51.30000","23.81680","0.01186"
"8571","51.39000","23.82427","0.00313"
"8586","51.48000","23.83187","0.00647"
"8601","51.57000","23.83934","0.01669"
"8616","51.66000","23.84682","0.02712"
"8631","51.75000","23.85435","0.02029"
"8646","51.84000","23.86176","0.00698"
"8661","51.93000","23.86930","0.00630"
"8676","52.02000","23.87683","0.01453"
"8691","52.11000","23.88436","0.02282"
"8706","52.20000","23.89184","0.02034"
"8721","52.29000","23.89931","0.01087"
"8736","52.38000","23.90685","0.00684"
"8751","52.47000","23.91438","0.01379"
"8766","52.56000","23.92185","0.02161"
"8781","52.65000","23.92938","0.02021"
"8796","52.74000","23.93686","0.01197"
"8811","52.83000","23.94427","0.00949"
"8826","52.92000","23.95181","0.01449"
"8841","53.01000","23.95934","0.01973"
"8856","53.10000","23.96688","0.01963"
"8871","53.19000","23.97435","0.01260"
"8886","53.28000","23.98188","0.00961"
"8901","53.37000","23.98930","0.01513"
"8916","53.46000","23.99677","0.02004"
"8931","53.55000","24.00436","0.01922"
"8946","53.64000","24.01189","0.01288"
"8961","53.73000","24.01937","0.01153"
"8976","53.82000","24.02684","0.01525"
"8991","53.91000","24.03438","0.01948"
"9006","54.00000","24.04179","0.01803"
"9021","54.09000","24.04932","0.01316"
"9036","54.18000","24.05686","0.01344"
"9051","54.27000","24.06433","0.01596"
"9066","54.36000","24.07192","0.01866"
"9081","54.45000","24.07934","0.01777"
"9096","54.54000","24.08681","0.01423"
"9111","54.63000","24.09434","0.01312"
"9126","54.72000","24.10188","0.01728"
"9141","54.81000","24.10941","0.01843"
"9156","54.90000","24.11689","0.01694"
"9171","54.99000","24.12430","0.01548"
"9186","55.08000","24.13177","0.01474"
"9201","55.17000","24.13931","0.01680"
"9216","55.26000","24.14690","0.01785"
"9231","55.35000","24.15437","0.01724"
"9246","55.44000","24.16185","0.01428"
"9261","55.53000","24.16932","0.01521"
"9276","55.62000","24.17680","0.01837"
"9291","55.71000","24.18427","0.01788"
"9306","55.80000","24.19186","0.01621"
"9321","55.89000","24.19934","0.01508"
"9336","55.98000","24.20681","0.01600"
"9351","56.07000","24.21434","0.01843"
"9366","56.16000","24.22176","0.01929"
"9381","56.25000","24.22935","0.01702"
"9396","56.34000","24.23688","0.01472"
"9411","56.43000","24.24436","0.01756"
"9426","56.52000","24.25189","0.01875"
"9441","56.61000","24.25930","0.01853"
"9456","56.70000","24.26678","0.01643"
"9471","56.79000","24.27431","0.01654"
"9486","56.88000","24.28185","0.01778"
"9501","56.97000","24.28938","0.01865"
"9516","57.06000","24.29685","0.01840"
"9531","57.15000","24.30433","0.01622"
"9546","57.24000","24.31180","0.01773"
"9561","57.33000","24.31927","0.01885"
"9576","57.42000","24.32686","0.01964"
"9591","57.51000","24.33434","0.01861"
"9606","57.60000","24.34181","0.01742"
"9621","57.69000","24.34929","0.01792"
"9636","57.78000","24.35682","0.01948"
"9651","57.87000","24.36429","0.01921"
"9666","57.96000","24.37183","0.01817"
"9681","58.05000","24.37936","0.01780"
"9696","58.14000","24.38684","0.01875"
"9711","58.23000","24.39431","0.01936"
"9726","58.32000","24.40172","0.02006"
"9741","58.41000","24.40932","0.01834"
"9756","58.50000","24.41691","0.01834"
"9771","58.59000","24.42438","0.01938"
"9786","58.68000","24.43192","0.01914"
"9801","58.77000","24.43933","0.01902"
"9816","58.86000","24.44681","0.01847"
"9831","58.95000","24.45434","0.01922"
"9846","59.04000","24.46187","0.02134"
"9861","59.13000","24.46935","0.02090"
"9876","59.22000","24.47688","0.02024"
"9891","59.31000","24.48429","0.01933"
"9906","59.40000","24.49183","0.02105"
"9921","59.49000","24.49936","0.02181"
"9936","59.58000","24.50689","0.02109"
"9951","59.67000","24.51437","0.02086"
"9966","59.76000","24.52184","0.02046"
"9981","59.85000","24.52931","0.02106"
"9996","59.94000","24.53685","0.02122"
"10011","60.03000","24.54432","0.02101"
"10026","60.12000","24.55191","0.02098"
"10041","60.21000","24.55939","0.02082"
"10056","60.30000","24.56680","0.02240"
"10071","60.39000","24.57440","0.02302"
"10086","60.48000","24.58181","0.02195"
"10101","60.57000","24.58928","0.02173"
"10116","60.66000","24.59688","0.02216"
"10131","60.75000","24.60435","0.02210"
"10146","60.84000","24.61182","0.02150"
"10161","60.93000","24.61930","0.02157"
"10176","61.02000","24.62683","0.02238"
"10191","61.11000","24.63430","0.02235"
"10206","61.20000","24.64184","0.02368"
"10221","61.29000","24.64937","0.02377"
"10236","61.38000","24.65690","0.02342"
"10251","61.47000","24.66432","0.02315"
"10266","61.56000","24.67179","0.02359"
"10281","61.65000","24.67933","0.02358"
"10296","61.74000","24.68680","0.02336"
"10311","61.83000","24.69439","0.02315"
"10326","61.92000","24.70187","0.02347"
"10341","62.01000","24.70934","0.02373"
"10356","62.10000","24.71681","0.02500"
"10371","62.19000","24.72435","0.02407"
"10386","62.28000","24.73188","0.02424"
"10401","62.37000","24.73936","0.02594"
"10416","62.46000","24.74683","0.02566"
"10431","62.55000","24.75436","0.02447"
"10446","62.64000","24.76177","0.02433"
"10461","62.73000","24.76937","0.02479"
"10476","62.82000","24.77690","0.02444"
"10491","62.91000","24.78437","0.02546"
"10506","63.00000","24.79185","0.02542"
"10521","63.09000","24.79932","0.02570"
"10536","63.18000","24.80680","0.02689"
"10551","63.27000","24.81439","0.02645"
"10566","63.36000","24.82186","0.02647"
"10581","63.45000","24.82934","0.02610"
"10596","63.54000","24.83693","0.02636"
"10611","63.63000","24.84429","0.02582"
"10626","63.72000","24.85176","0.02543"
"10641","63.81000","24.85935","0.02614"
"10656","63.90000","24.86683","0.02701"
"10671","63.99000","24.87436","0.02673"
"10686","64.08000","24.88189","0.02689"
"10701","64.17000","24.88931","0.02751"
"10716","64.26000","24.89684","0.02815"
"10731","64.35000","24.90431","0.02762"
"10746","64.44000","24.91185","0.02697"
"10761","64.53000","24.91938","0.02727"
"10776","64.62000","24.92679","0.02675"
"10791","64.71000","24.93433","0.02732"
"10806","64.80000","24.94180","0.02790"
"10821","64.89000","24.94934","0.02823"
"10836","64.98000","24.95687","0.02776"
"10851","65.07000","24.96440","0.02852"
"10866","65.16000","24.97188","0.02815"
"10881","65.25000","24.97935","0.02752"
"10896","65.34000","24.98676","0.02789"
"10911","65.43000","24.99436","0.02761"
"10926","65.52000","25.00189","0.02768"
"10941","65.61000","25.00936","0.02859"
"10956","65.70000","25.01684","0.02884"
"10971","65.79000","25.02431","0.02992"
"10986","65.88000","25.03179","0.02942"
"11001","65.97000","25.03932","0.02924"
"11016","66.06000","25.04685","0.03003"
"11031","66.15000","25.05438","0.02939"
"11046","66.24000","25.06180","0.02912"
"11061","66.33000","25.06933","0.02954"
"11076","66.42000","25.07681","0.02968"
"11091","66.51000","25.08434","0.02930"
"11106","66.60000","25.09181","0.02986"
"11121","66.69000","25.09941","0.03063"
"11136","66.78000","25.10682","0.03055"
"11151","66.87000","25.11430","0.03043"
"11166","66.96000","25.12183","0.03024"
"11181","67.05000","25.12930","0.03021"
"11196","67.14000","25.13683","0.03027"
"11211","67.23000","25.14431","0.02982"
"11226","67.32000","25.15184","0.03006"
"11241","67.41000","25.15938","0.03040"
"11256","67.50000","25.16679","0.03088"
"11271","67.59000","25.17438","0.03075"
"11286","67.68000","25.18186","0.02627"
"11301","67.77000","25.18933","0.02460"
"11316","67.86000","25.19687","0.02555"
"11331","67.95000","25.20434","0.02366"
"11346","68.04000","25.21181","0.02466"
"11361","68.13000","25.21934","0.02706"
"11376","68.22000","25.22682","0.02558"
"11391","68.31000","25.23435","0.02235"
"11406","68.40000","25.24182","0.02575"
"11421","68.49000","25.24930","0.02706"
"11436","68.58000","25.25683","0.02521"
"11451","68.67000","25.26431","0.02495"
"11466","68.76000","25.27184","0.02317"
"11481","68.85000","25.27937","0.02276"
"11496","68.94000","25.28685","0.02478"
"11511","69.03000","25.29432","0.02585"
"11526","69.12000","25.30186","0.02348"
"11541","69.21000","25.30933","0.02476"
"11556","69.30000","25.31686","0.02452"
"11571","69.39000","25.32439","0.02503"
"11586","69.48000","25.33181","0.02600"
"11601","69.57000","25.33934","0.02479"
"11616","69.66000","25.34682","0.02463"
"11631","69.75000","25.35435","0.02607"
"11646","69.84000","25.36189","0.02605"
"11661","69.93000","25.36942","0.02585"
"11676","70.02000","25.37683","0.02526"
"11691","70.11000","25.38431","0.02520"
"11706","70.20000","25.39184","0.02586"
"11721","70.29000","25.39937","0.02596"
"11736","70.38000","25.40684","0.02569"
"11751","70.47000","25.41438","0.02526"
"11766","70.56000","25.42185","0.02531"
"11781","70.65000","25.42933","0.02619"
"11796","70.74000","25.43686","0.02580"
"11811","70.83000","25.44439","0.02631"
"11826","70.92000","25.45186","0.02597"
"11841","71.01000","25.45934","0.02561"
"11856","71.10000","25.46681","0.02615"
"11871","71.19000","25.47429","0.02614"
"11886","71.28000","25.48188","0.02560"
"11901","71.37000","25.48935","0.02621"
"11916","71.46000","25.49683","0.02550"
"11931","71.55000","25.50442","0.02604"
"11946","71.64000","25.51184","0.02719"
"11961","71.73000","25.51931","0.02676"
"11976","71.82000","25.52684","0.02617"
"11991","71.91000","25.53438","0.02714"
"12006","72.00000","25.54191","0.02762"
"12021","72.09000","25.54938","0.02720"
"12036","72.18000","25.55685","0.02748"
"12051","72.27000","25.56433","0.02716"
"12066","72.36000","25.57180","0.02633"
"12081","72.45000","25.57940","0.02786"
"12096","72.54000","25.58687","0.02808"
"12111","72.63000","25.59435","0.02750"
"12126","72.72000","25.60188","0.02726"
"12141","72.81000","25.60929","0.02695"
"12156","72.90000","25.61683","0.02709"
"12171","72.99000","25.62436","0.02737"
"12186","73.08000","25.63183","0.02790"
"12201","73.17000","25.63937","0.02748"
"12216","73.26000","25.64684","0.02742"
"12231","73.35000","25.65431","0.02780"
"12246","73.44000","25.66185","0.02781"
"12261","73.53000","25.66932","0.02825"
"12276","73.62000","25.67685","0.02682"
"12291","73.71000","25.68439","0.02844"
"12306","73.80000","25.69186","0.02855"
"12321","73.89000","25.69934","0.02810"
"12336","73.98000","25.70681","0.02905"
"12351","74.07000","25.71434","0.02903"
"12366","74.16000","25.72187","0.02890"
"12381","74.25000","25.72935","0.02901"
"12396","74.34000","25.73682","0.02894"
"12411","74.43000","25.74430","0.02939"
"12426","74.52000","25.75177","0.02997"
"12441","74.61000","25.75930","0.02934"
"12456","74.70000","25.76684","0.02935"
"12471","74.79000","25.77431","0.02982"
"12486","74.88000","25.78184","0.02939"
"12501","74.97000","25.78926","0.03023"
"12516","75.06000","25.79685","0.03040"
"12531","75.15000","25.80439","0.02971"
"12546","75.24000","25.81186","0.02948"
"12561","75.33000","25.81939","0.03004"
"12576","75.42000","25.82687","0.02967"
"12591","75.51000","25.83428","0.03014"
"12606","75.60000","25.84182","0.02988"
"12621","75.69000","25.84935","0.03013"
"12636","75.78000","25.85682","0.02939"
"12651","75.87000","25.86441","0.03109"
"12666","75.96000","25.87183","0.03113"
"12681","76.05000","25.87936","0.03026"
"12696","76.14000","25.88684","0.03061"
"12711","76.23000","25.89437","0.03047"
"12726","76.32000","25.90190","0.03151"
"12741","76.41000","25.90938","0.03148"
"12756","76.50000","25.91685","0.03108"
"12771","76.59000","25.92432","0.03191"
"12786","76.68000","25.93180","0.03133"
"12801","76.77000","25.93933","0.03150"
"12816","76.86000","25.94686","0.03226"
"12831","76.95000","25.95434","0.03227"
"12846","77.04000","25.96187","0.03177"
"12861","77.13000","25.96929","0.03189"
"12876","77.22000","25.97688","0.03152"
"12891","77.31000","25.98441","0.03219"
"12906","77.40000","25.99183","0.03246"
"12921","77.49000","25.99936","0.03200"
"12936","77.58000","26.00683","0.03222"
"12951","77.67000","26.01431","0.03209"
"12966","77.76000","26.02184","0.03288"
"12981","77.85000","26.02931","0.03365"
"12996","77.94000","26.03685","0.03234"
"13011","78.03000","26.04432","0.03245"
"13026","78.12000","26.05179","0.03288"
"13041","78.21000","26.05933","0.03330"
"13056","78.30000","26.06686","0.03309"
"13071","78.39000","26.07434","0.03356"
"13086","78.48000","26.08193","0.03310"
"13101","78.57000","26.08940","0.03366"
"13116","78.66000","26.09682","0.03427"
"13131","78.75000","26.10429","0.03407"
"13146","78.84000","26.11182","0.03379"
"13161","78.93000","26.11935","0.03409"
"13176","79.02000","26.12689","0.03389"
"13191","79.11000","26.13437","0.03443"
"13206","79.20000","26.14184","0.03511"
"13221","79.29000","26.14931","0.03473"
"13236","79.38000","26.15685","0.03451"
"13251","79.47000","26.16444","0.03477"
"13266","79.56000","26.17185","0.03465"
"13281","79.65000","26.17933","0.03511"
"13296","79.74000","26.18686","0.03513"
"13311","79.83000","26.19427","0.03492"
"13326","79.92000","26.20187","0.03449"
"13341","80.01000","26.20934","0.03495"
"13356","80.10000","26.21687","0.03571"
"13371","80.19000","26.22441","0.03559"
"13386","80.28000","26.23182","0.03536"
"13401","80.37000","26.23923","0.03576"
"13416","80.46000","26.24683","0.03569"
"13431","80.55000","26.25436","0.03610"
"13446","80.64000","26.26190","0.03619"
"13461","80.73000","26.26937","0.03562"
"13476","80.82000","26.27684","0.03598"
"13491","80.91000","26.28426","0.03597"
"13506","81.00000","26.29179","0.03667"
"13521","81.09000","26.29938","0.03709"
"13536","81.18000","26.30686","0.03668"
"13551","81.27000","26.31439","0.03635"
"13566","81.36000","26.32187","0.03625"
"13581","81.45000","26.32928","0.03736"
"13596","81.54000","26.33681","0.03723"
"13611","81.63000","26.34434","0.03718"
"13626","81.72000","26.35188","0.03699"
"13641","81.81000","26.35935","0.03771"
"13656","81.90000","26.36683","0.03787"
"13671","81.99000","26.37430","0.03792"
"13686","82.08000","26.38177","0.03767"
"13701","82.17000","26.38937","0.03821"
"13716","82.26000","26.39690","0.03809"
"13731","82.35000","26.40437","0.03833"
"13746","82.44000","26.41185","0.03893"
"13761","82.53000","26.41926","0.03807"
"13776","82.62000","26.42686","0.03854"
"13791","82.71000","26.43439","0.03876"
"13806","82.80000","26.44186","0.03937"
"13821","82.89000","26.44939","0.03864"
"13836","82.98000","26.45681","0.03927"
"13851","83.07000","26.46434","0.03899"
"13866","83.16000","26.47182","0.03923"
"13881","83.25000","26.47935","0.03901"
"13896","83.34000","26.48682","0.03967"
"13911","83.43000","26.49430","0.03988"
"13926","83.52000","26.50183","0.03955"
"13941","83.61000","26.50931","0.03959"
"13956","83.70000","26.51678","0.03953"
"13971","83.79000","26.52437","0.04037"
"13986","83.88000","26.53184","0.03999"
"14001","83.97000","26.53938","0.04039"
"14016","84.06000","26.54685","0.04018"
"14031","84.15000","26.55426","0.04066"
"14046","84.24000","26.56180","0.04009"
"14061","84.33000","26.56940","0.04057"
"14076","84.42000","26.57681","0.04052"
"14091","84.51000","26.58434","0.04058"
"14106","84.60000","26.59188","0.04091"
"14121","84.69000","26.59929","0.04124"
"14136","84.78000","26.60688","0.04086"
"14151","84.87000","26.61435","0.04103"
"14166","84.96000","26.62189","0.04109"
"14181","85.05000","26.62936","0.04108"
"14196","85.14000","26.63684","0.04095"
"14211","85.23000","26.64431","0.04138"
"14226","85.32000","26.65184","0.04149"
"14241","85.41000","26.65938","0.04224"
"14256","85.50000","26.66685","0.04181"
"14271","85.59000","26.67438","0.04165"
"14286","85.68000","26.68186","0.04182"
"14301","85.77000","26.68933","0.04265"
"14316","85.86000","26.69687","0.04243"
"14331","85.95000","26.70440","0.04272"
"14346","86.04000","26.71187","0.04203"
"14361","86.13000","26.71935","0.04283"
"14376","86.22000","26.72688","0.04296"
"14391","86.31000","26.73429","0.04299"
"14406","86.40000","26.74183","0.04321"
"14421","86.49000","26.74942","0.04326"
"14436","86.58000","26.75689","0.04306"
"14451","86.67000","26.76437","0.04372"
"14466","86.76000","26.77184","0.04363"
"14481","86.85000","26.77931","0.04380"
"14496","86.94000","26.78685","0.04378"
"14511","87.03000","26.79432","0.04388"
"14526","87.12000","26.80185","0.04399"
"14541","87.21000","26.80939","0.04426"
"14556","87.30000","26.81680","0.04413"
"14571","87.39000","26.82428","0.04429"
"14586","87.48000","26.83187","0.04399"
"14601","87.57000","26.83934","0.04440"
"14616","87.66000","26.84682","0.04418"
"14631","87.75000","26.85435","0.04454"
"14646","87.84000","26.86182","0.04474"
"14661","87.93000","26.86936","0.04497"
"14676","88.02000","26.87683","0.04471"
"14691","88.11000","26.88436","0.04493"
"14706","88.20000","26.89190","0.04522"
"14721","88.29000","26.89931","0.04511"
"14736","88.38000","26.90678","0.04549"
"14751","88.47000","26.91426","0.04513"
"14766","88.56000","26.92185","0.04514"
"14781","88.65000","26.92939","0.04528"
"14796","88.74000","26.93686","0.04562"
"14811","88.83000","26.94433","0.04605"
"14826","88.92000","26.95181","0.04579"
"14841","89.01000","26.95928","0.04601"
"14856","89.10000","26.96687","0.04558"
"14871","89.19000","26.97435","0.04628"
"14886","89.28000","26.98188","0.04644"
"14901","89.37000","26.98936","0.04612"
"14916","89.46000","26.99683","0.04602"
"14931","89.55000","27.00430","0.04669"
"14946","89.64000","27.01189","0.04682"
"14961","89.73000","27.01937","0.04693"
"14976","89.82000","27.02690","0.04672"
"14991","89.91000","27.03438","0.04679"
"15006","90.00000","27.04185","0.04707"
"15021","90.09000","27.04932","0.04721"
"15036","90.18000","27.05680","0.04740"
"15051","90.27000","27.06439","0.04745"
"15066","90.36000","27.07186","0.04735"
"15081","90.45000","27.07934","0.04758"
"15096","90.54000","27.08681","0.04775"
"15111","90.63000","27.09429","0.04801"
"15126","90.72000","27.10182","0.04777"
"15141","90.81000","27.10941","0.04800"
"15156","90.90000","27.11689","0.04823"
"15171","90.99000","27.12436","0.04822"
"15186","91.08000","27.13183","0.04843"
"15201","91.17000","27.13925","0.04831"
"15216","91.26000","27.14684","0.04819"
"15231","91.35000","27.15438","0.04819"
"15246","91.44000","27.16185","0.04851"
"15261","91.53000","27.16938","0.04835"
"15276","91.62000","27.17679","0.04883"
"15291","91.71000","27.18427","0.04863"
"15306","91.80000","27.19186","0.04906"
"15321","91.89000","27.19933","0.04875"
"15336","91.98000","27.20687","0.04914"
"15351","92.07000","27.21434","0.04933"
"15366","92.16000","27.22182","0.04967"
"15381","92.25000","27.22935","0.04939"
"15396","92.34000","27.23682","0.04960"
"15411","92.43000","27.24430","0.04932"
"15426","92.52000","27.25189","0.04983"
"15441","92.61000","27.25931","0.04955"
"15456","92.70000","27.26678","0.05017"
"15471","92.79000","27.27431","0.05008"
"15486","92.88000","27.28185","0.05044"
"15501","92.97000","27.28938","0.05011"
"15516","93.06000","27.29685","0.05039"
"15531","93.15000","27.30433","0.05051"
"15546","93.24000","27.31186","0.05078"
"15561","93.33000","27.31933","0.05038"
"15576","93.42000","27.32687","0.05076"
"15591","93.51000","27.33440","0.05080"
"15606","93.60000","27.34187","0.05110"
"15621","93.69000","27.34935","0.05104"
"15636","93.78000","27.35682","0.05083"
"15651","93.87000","27.36429","0.05127"
"15666","93.96000","27.37183","0.05117"
"15681","94.05000","27.37930","0.05131"
"15696","94.14000","27.38684","0.05136"
"15711","94.23000","27.39437","0.05145"
"15726","94.32000","27.40184","0.05171"
"15741","94.41000","27.40932","0.05147"
"15756","94.50000","27.41685","0.05158"
"15771","94.59000","27.42432","0.05198"
"15786","94.68000","27.43185","0.05189"
"15801","94.77000","27.43933","0.05186"
"15816","94.86000","27.44680","0.05201"
"15831","94.95000","27.45428","0.05212"
"15846","95.04000","27.46181","0.05190"
"15861","95.13000","27.46935","0.05213"
"15876","95.22000","27.47682","0.05232"
"15891","95.31000","27.48429","0.05226"
"15906","95.40000","27.49189","0.05233"
"15921","95.49000","27.49930","0.05249"
"15936","95.58000","27.50683","0.05264"
"15951","95.67000","27.51443","0.05266"
"15966","95.76000","27.52184","0.05248"
"15981","95.85000","27.52931","0.05286"
"15996","95.94000","27.53679","0.05262"
"16011","96.03000","27.54432","0.05265"
"16026","96.12000","27.55186","0.05273"
"16041","96.21000","27.55933","0.05295"
"16056","96.30000","27.56686","0.05311"
"16071","96.39000","27.57439","0.05331"
"16086","96.48000","27.58175","0.05314"
"16101","96.57000","27.58934","0.05332"
"16116","96.66000","27.59688","0.05339"
"16131","96.75000","27.60435","0.05333"
"16146","96.84000","27.61188","0.05319"
"16161","96.93000","27.61930","0.05369"
"16176","97.02000","27.62677","0.05351"
"16191","97.11000","27.63431","0.05345"
"16206","97.20000","27.64184","0.05367"
"16221","97.29000","27.64931","0.05381"
"16236","97.38000","27.65691","0.05398"
"16251","97.47000","27.66432","0.05409"
"16266","97.56000","27.67179","0.05404"
"16281","97.65000","27.67933","0.05405"
"16296","97.74000","27.68686","0.05420"
"16311","97.83000","27.69439","0.05397"
"16326","97.92000","27.70187","0.05437"
"16341","98.01000","27.70934","0.05419"
"16356","98.10000","27.71681","0.05426"
"16371","98.19000","27.72429","0.05429"
"16386","98.28000","27.73188","0.05462"
"16401","98.37000","27.73935","0.05461"
"16416","98.46000","27.74689","0.05449"
"16431","98.55000","27.75436","0.05459"
"16446","98.64000","27.76183","0.05479"
"16461","98.73000","27.76937","0.05479"
"16476","98.82000","27.77684","0.05480"
"16491","98.91000","27.78438","0.05470"
"16506","99.00000","27.79191","0.05499"
"16521","99.09000","27.79933","0.05488"
"16536","99.18000","27.80680","0.05508"
"16551","99.27000","27.81433","0.05521"
"16566","99.36000","27.82187","0.05491"
"16581","99.45000","27.82934","0.05501"
"16596","99.54000","27.83693","0.05503"
"16611","99.63000","27.84428","0.05507"
"16626","99.72000","27.85182","0.05529"
"16641","99.81000","27.85929","0.05517"
"16656","99.90000","27.86683","0.05525"
"16671","99.99000","27.87442","0.05542"
"16686","100.08000","27.88183","0.05538"
"16701","100.17000","27.88931","0.05530"
"16716","100.26000","27.89684","0.05561"
"16731","100.35000","27.90425","0.05565"
"16746","100.44000","27.91185","0.05559"
"16761","100.53000","27.91938","0.05576"
"16776","100.62000","27.92685","0.05563"
"16791","100.71000","27.93433","0.05572"
"16806","100.80000","27.94180","0.05582"
"16821","100.89000","27.94934","0.05563"
"16836","100.98000","27.95687","0.05581"
"16851","101.07000","27.96434","0.05580"
"16866","101.16000","27.97187","0.05581"
"16881","101.25000","27.97935","0.05589"
"16896","101.34000","27.98676","0.05580"
"16911","101.43000","27.99435","0.05579"
"16926","101.52000","28.00189","0.05588"
"16941","101.61000","28.00936","0.05587"
"16956","101.70000","28.01690","0.05608"
"16971","101.79000","28.02437","0.05596"
"16986","101.88000","28.03185","0.05598"
"17001","101.97000","28.03932","0.05608"
"17016","102.06000","28.04685","0.05599"
"17031","102.15000","28.05439","0.05615"
"17046","102.24000","28.06186","0.05609"
"17061","102.33000","28.06933","0.05614"
"17076","102.42000","28.07675","0.05623"
"17091","102.51000","28.08428","0.00982"
"17106","102.60000","28.09187","0.00918"
"17121","102.69000","28.09935","0.00384"
"17136","102.78000","28.10688","0.00509"
"17151","102.87000","28.11436","0.00209"
"17166","102.96000","28.12183","0.00334"
"17181","103.05000","28.12936","0.00322"
"17196","103.14000","28.13689","0.00191"
"17211","103.23000","28.14431","0.00268"
"17226","103.32000","28.15184","0.00285"
"17241","103.41000","28.15938","0.00259"
"17256","103.50000","28.16679","0.00229"
"17271","103.59000","28.17432","0.00249"
"17286","103.68000","28.18186","0.00179"
"17301","103.77000","28.18933","0.00158"
"17316","103.86000","28.19686","0.00230"
"17331","103.95000","28.20434","0.00127"
"17346","104.04000","28.21181","0.00215"
"17361","104.13000","28.21934","0.00310"
"17376","104.22000","28.22682","0.00207"
"17391","104.31000","28.23435","0.00204"
"17406","104.40000","28.24188","0.00184"
"17421","104.49000","28.24930","0.00173"
"17436","104.58000","28.25683","0.00212"
"17451","104.67000","28.26431","0.00281"
"17466","104.76000","28.27184","0.00264"
"17481","104.85000","28.27938","0.00345"
"17496","104.94000","28.28685","0.00214"
"17511","105.03000","28.29438","0.00170"
"17526","105.12000","28.30179","0.00175"
"17541","105.21000","28.30933","0.00205"
"17556","105.30000","28.31692","0.00133"
"17571","105.39000","28.32433","0.00173"
"17586","105.48000","28.33181","0.00244"
"17601","105.57000","28.33934","0.00257"
"17616","105.66000","28.34682","0.00362"
"17631","105.75000","28.35435","0.00141"
"17646","105.84000","28.36182","0.00192"
"17661","105.93000","28.36936","0.00191"
"17676","106.02000","28.37689","0.00273"
"17691","106.11000","28.38437","0.00278"
"17706","106.20000","28.39184","0.00222"
"17721","106.29000","28.39931","0.00205"
"17736","106.38000","28.40690","0.00297"
"17751","106.47000","28.41438","0.00164"
"17766","106.56000","28.42185","0.00193"
"17781","106.65000","28.42933","0.00192"
"17796","106.74000","28.43674","0.00291"
"17811","106.83000","28.44433","0.00231"
"17826","106.92000","28.45193","0.00356"
"17841","107.01000","28.45940","0.00191"
"17856","107.10000","28.46687","0.00218"
"17871","107.19000","28.47435","0.00142"
"17886","107.28000","28.48182","0.00192"
"17901","107.37000","28.48930","0.00231"
"17916","107.46000","28.49689","0.00177"
"17931","107.55000","28.50436","0.00209"
"17946","107.64000","28.51184","0.00296"
"17961","107.73000","28.51937","0.00204"
"17976","107.82000","28.52678","0.00095"
"17991","107.91000","28.53426","0.00105"
"18006","108.00000","28.54185","0.00275"
"18021","108.09000","28.54939","0.00187"
"18036","108.18000","28.55692","0.00220"
"18051","108.27000","28.56433","0.00269"
"18066","108.36000","28.57174","0.00239"
"18081","108.45000","28.57934","0.00197"
"18096","108.54000","28.58687","0.00120"
"18110","108.62200","28.59374","0.00202"