File: Trajectories_together/161114Specimen_RawData_4.csv
"","V1","V2","V3"
"1","End date","11/14/2016",""
"2","Specimen label","20AG64U",""
"3","Maximum Load","0.26425","N"
"4","Time","Extension","Load"
"5","(s)","(mm)","(N)"
"6","0.00000","0.00000","-0.00018"
"41","0.21000","0.01513","0.00029"
"76","0.42000","0.03534","0.00007"
"111","0.63000","0.05267","0.00149"
"146","0.84000","0.07025","0.00070"
"181","1.05000","0.08777","0.00134"
"216","1.26000","0.10517","0.00243"
"251","1.47000","0.12275","0.00264"
"286","1.68000","0.14021","0.00236"
"321","1.89000","0.15772","0.00267"
"356","2.10000","0.17524","0.00280"
"391","2.31000","0.19264","0.00325"
"426","2.52000","0.21028","0.00307"
"461","2.73000","0.22774","0.00368"
"496","2.94000","0.24526","0.00344"
"531","3.15000","0.26272","0.00347"
"566","3.36000","0.28017","0.00391"
"601","3.57000","0.29769","0.00400"
"636","3.78000","0.31521","0.00516"
"671","3.99000","0.33267","0.00554"
"706","4.20000","0.35019","0.00522"
"741","4.41000","0.36765","0.00558"
"776","4.62000","0.38516","0.00557"
"811","4.83000","0.40268","0.00594"
"846","5.04000","0.42014","0.00532"
"881","5.25000","0.43766","0.00597"
"916","5.46000","0.45518","0.00639"
"951","5.67000","0.47270","0.00621"
"986","5.88000","0.49021","0.00702"
"1021","6.09000","0.50761","0.00679"
"1056","6.30000","0.52519","0.00745"
"1091","6.51000","0.54265","0.00762"
"1126","6.72000","0.56017","0.00748"
"1161","6.93000","0.57769","0.00702"
"1196","7.14000","0.59515","0.00753"
"1231","7.35000","0.61272","0.00723"
"1266","7.56000","0.63018","0.00889"
"1301","7.77000","0.64764","0.00875"
"1336","7.98000","0.66522","0.00781"
"1371","8.19000","0.68262","0.00841"
"1406","8.40000","0.70026","0.00812"
"1441","8.61000","0.71765","0.00899"
"1476","8.82000","0.73517","0.00924"
"1511","9.03000","0.75269","0.00938"
"1546","9.24000","0.77015","0.00898"
"1581","9.45000","0.78767","0.00944"
"1616","9.66000","0.80519","0.00911"
"1651","9.87000","0.82264","0.01017"
"1686","10.08000","0.84022","0.01003"
"1721","10.29000","0.85768","0.01076"
"1756","10.50000","0.87520","0.01080"
"1791","10.71000","0.89272","0.00980"
"1826","10.92000","0.91012","0.01094"
"1861","11.13000","0.92775","0.01055"
"1896","11.34000","0.94515","0.01111"
"1931","11.55000","0.96267","0.01074"
"1966","11.76000","0.98019","0.01055"
"2001","11.97000","0.99771","0.01099"
"2036","12.18000","1.01517","0.01191"
"2071","12.39000","1.03274","0.01030"
"2106","12.60000","1.05014","0.01066"
"2141","12.81000","1.06766","0.01160"
"2176","13.02000","1.08512","0.01104"
"2211","13.23000","1.10270","0.01263"
"2246","13.44000","1.12022","0.01230"
"2281","13.65000","1.13762","0.01132"
"2316","13.86000","1.15525","0.01174"
"2351","14.07000","1.17271","0.01175"
"2386","14.28000","1.19017","0.01226"
"2421","14.49000","1.20769","0.01104"
"2456","14.70000","1.22515","0.01221"
"2491","14.91000","1.24267","0.01175"
"2526","15.12000","1.26018","0.01238"
"2561","15.33000","1.27764","0.01298"
"2596","15.54000","1.29522","0.01250"
"2631","15.75000","1.31268","0.01352"
"2666","15.96000","1.33020","0.01315"
"2701","16.17000","1.34772","0.01315"
"2736","16.38000","1.36517","0.01273"
"2771","16.59000","1.38269","0.01272"
"2806","16.80000","1.40015","0.01296"
"2841","17.01000","1.41773","0.01368"
"2876","17.22000","1.43513","0.01392"
"2911","17.43000","1.45265","0.01307"
"2946","17.64000","1.47022","0.01309"
"2981","17.85000","1.48768","0.01259"
"3016","18.06000","1.50520","0.01309"
"3051","18.27000","1.52272","0.01278"
"3086","18.48000","1.54012","0.01354"
"3121","18.69000","1.55770","0.01370"
"3156","18.90000","1.57516","0.01313"
"3191","19.11000","1.59267","0.01283"
"3226","19.32000","1.61019","0.01384"
"3261","19.53000","1.62759","0.01319"
"3296","19.74000","1.64523","0.01316"
"3331","19.95000","1.66263","0.01410"
"3366","20.16000","1.68021","0.01322"
"3401","20.37000","1.69772","0.01343"
"3436","20.58000","1.71518","0.01538"
"3471","20.79000","1.73264","0.01429"
"3506","21.00000","1.75016","0.01396"
"3541","21.21000","1.76768","0.01401"
"3576","21.42000","1.78520","0.01468"
"3611","21.63000","1.80265","0.01388"
"3646","21.84000","1.82017","0.01339"
"3681","22.05000","1.83769","0.01411"
"3716","22.26000","1.85515","0.01420"
"3751","22.47000","1.87273","0.01387"
"3786","22.68000","1.89019","0.01508"
"3821","22.89000","1.90770","0.01440"
"3856","23.10000","1.92522","0.01502"
"3891","23.31000","1.94268","0.01435"
"3926","23.52000","1.96020","0.01468"
"3961","23.73000","1.97766","0.01476"
"3996","23.94000","1.99518","0.01504"
"4031","24.15000","2.01269","0.01468"
"4066","24.36000","2.03015","0.01500"
"4101","24.57000","2.04767","0.01508"
"4136","24.78000","2.06519","0.01550"
"4171","24.99000","2.08265","0.01587"
"4206","25.20000","2.10023","0.01518"
"4241","25.41000","2.11769","0.01608"
"4276","25.62000","2.13520","0.01560"
"4311","25.83000","2.15266","0.01540"
"4346","26.04000","2.17012","0.01575"
"4381","26.25000","2.18770","0.01585"
"4416","26.46000","2.20516","0.01622"
"4451","26.67000","2.22274","0.01756"
"4486","26.88000","2.24019","0.01622"
"4521","27.09000","2.25759","0.01687"
"4556","27.30000","2.27517","0.01739"
"4591","27.51000","2.29269","0.01728"
"4626","27.72000","2.31015","0.01727"
"4661","27.93000","2.32773","0.01734"
"4696","28.14000","2.34512","0.01644"
"4731","28.35000","2.36276","0.01617"
"4766","28.56000","2.38016","0.01725"
"4801","28.77000","2.39768","0.01612"
"4836","28.98000","2.41520","0.01758"
"4871","29.19000","2.43266","0.01808"
"4906","29.40000","2.45017","0.01706"
"4941","29.61000","2.46769","0.01719"
"4976","29.82000","2.48515","0.01731"
"5011","30.03000","2.50267","0.01810"
"5046","30.24000","2.52019","0.01893"
"5081","30.45000","2.53771","0.01868"
"5116","30.66000","2.55523","0.01904"
"5151","30.87000","2.57262","0.01838"
"5186","31.08000","2.59020","0.01875"
"5221","31.29000","2.60766","0.01865"
"5256","31.50000","2.62518","0.01974"
"5291","31.71000","2.64270","0.01963"
"5326","31.92000","2.66016","0.01874"
"5361","32.13000","2.67767","0.01914"
"5396","32.34000","2.69513","0.01990"
"5431","32.55000","2.71265","0.01969"
"5466","32.76000","2.73017","0.01992"
"5501","32.97000","2.74769","0.01909"
"5536","33.18000","2.76521","0.02007"
"5571","33.39000","2.78272","0.02011"
"5606","33.60000","2.80012","0.01943"
"5641","33.81000","2.81770","0.01982"
"5676","34.02000","2.83510","0.01888"
"5711","34.23000","2.85280","0.02000"
"5746","34.44000","2.87020","0.02002"
"5781","34.65000","2.88766","0.01998"
"5816","34.86000","2.90523","0.02114"
"5851","35.07000","2.92269","0.02004"
"5886","35.28000","2.94021","0.02040"
"5921","35.49000","2.95773","0.02060"
"5956","35.70000","2.97507","0.02085"
"5991","35.91000","2.99271","0.02145"
"6026","36.12000","3.01022","0.02144"
"6061","36.33000","3.02762","0.02163"
"6096","36.54000","3.04520","0.02198"
"6131","36.75000","3.06260","0.02115"
"6166","36.96000","3.08024","0.02180"
"6201","37.17000","3.09770","0.02147"
"6236","37.38000","3.11521","0.02216"
"6271","37.59000","3.13273","0.02147"
"6306","37.80000","3.15013","0.02201"
"6341","38.01000","3.16771","0.02186"
"6376","38.22000","3.18523","0.02189"
"6411","38.43000","3.20263","0.02193"
"6446","38.64000","3.22014","0.02202"
"6481","38.85000","3.23766","0.02275"
"6516","39.06000","3.25518","0.02252"
"6551","39.27000","3.27270","0.02300"
"6586","39.48000","3.29010","0.02034"
"6621","39.69000","3.30774","0.01992"
"6656","39.90000","3.32513","0.01932"
"6691","40.11000","3.34271","0.02054"
"6726","40.32000","3.36017","0.02081"
"6761","40.53000","3.37769","0.02074"
"6796","40.74000","3.39521","0.02175"
"6831","40.95000","3.41267","0.02088"
"6866","41.16000","3.43013","0.02117"
"6901","41.37000","3.44770","0.02040"
"6936","41.58000","3.46516","0.02143"
"6971","41.79000","3.48268","0.02120"
"7006","42.00000","3.50020","0.02128"
"7041","42.21000","3.51766","0.02139"
"7076","42.42000","3.53518","0.02141"
"7111","42.63000","3.55269","0.02251"
"7146","42.84000","3.57021","0.02178"
"7181","43.05000","3.58767","0.02200"
"7216","43.26000","3.60513","0.02024"
"7251","43.47000","3.62265","0.01972"
"7286","43.68000","3.64017","0.02093"
"7321","43.89000","3.65774","0.02057"
"7356","44.10000","3.67520","0.02098"
"7391","44.31000","3.69260","0.02108"
"7426","44.52000","3.71018","0.02219"
"7461","44.73000","3.72764","0.02037"
"7496","44.94000","3.74516","0.02079"
"7531","45.15000","3.76273","0.02217"
"7566","45.36000","3.78007","0.02113"
"7601","45.57000","3.79777","0.02127"
"7636","45.78000","3.81517","0.02221"
"7671","45.99000","3.83269","0.02153"
"7706","46.20000","3.85021","0.02170"
"7741","46.41000","3.86767","0.02228"
"7776","46.62000","3.88518","0.02240"
"7811","46.83000","3.90270","0.02287"
"7846","47.04000","3.92016","0.02185"
"7881","47.25000","3.93768","0.02274"
"7916","47.46000","3.95514","0.02202"
"7951","47.67000","3.97272","0.02270"
"7986","47.88000","3.99023","0.02263"
"8021","48.09000","4.00763","0.02213"
"8056","48.30000","4.02521","0.02242"
"8091","48.51000","4.04267","0.02235"
"8126","48.72000","4.06019","0.02239"
"8161","48.93000","4.07771","0.02219"
"8196","49.14000","4.09516","0.02153"
"8231","49.35000","4.11274","0.02272"
"8266","49.56000","4.13014","0.02207"
"8301","49.77000","4.14766","0.02291"
"8336","49.98000","4.16518","0.02336"
"8371","50.19000","4.18264","0.02283"
"8406","50.40000","4.20021","0.02291"
"8441","50.61000","4.21767","0.02302"
"8476","50.82000","4.23519","0.02272"
"8511","51.03000","4.25277","0.02312"
"8546","51.24000","4.27011","0.02289"
"8581","51.45000","4.28775","0.02264"
"8616","51.66000","4.30515","0.02316"
"8651","51.87000","4.32266","0.02333"
"8686","52.08000","4.34018","0.02360"
"8721","52.29000","4.35770","0.02422"
"8756","52.50000","4.37522","0.02343"
"8791","52.71000","4.39268","0.02362"
"8826","52.92000","4.41014","0.02380"
"8861","53.13000","4.42771","0.02405"
"8896","53.34000","4.44517","0.02416"
"8931","53.55000","4.46269","0.02357"
"8966","53.76000","4.48021","0.02390"
"9001","53.97000","4.49761","0.02392"
"9036","54.18000","4.51525","0.02391"
"9071","54.39000","4.53270","0.02330"
"9106","54.60000","4.55016","0.02412"
"9141","54.81000","4.56768","0.02467"
"9176","55.02000","4.58520","0.02424"
"9211","55.23000","4.60266","0.02478"
"9246","55.44000","4.62018","0.02476"
"9281","55.65000","4.63763","0.02386"
"9316","55.86000","4.65515","0.02393"
"9351","56.07000","4.67261","0.02384"
"9386","56.28000","4.69019","0.02453"
"9421","56.49000","4.70777","0.02433"
"9456","56.70000","4.72517","0.02407"
"9491","56.91000","4.74274","0.02480"
"9526","57.12000","4.76014","0.02471"
"9561","57.33000","4.77772","0.02505"
"9596","57.54000","4.79518","0.02530"
"9631","57.75000","4.81264","0.02431"
"9666","57.96000","4.83022","0.02452"
"9701","58.17000","4.84762","0.02326"
"9736","58.38000","4.86513","0.02347"
"9771","58.59000","4.88271","0.02314"
"9806","58.80000","4.90017","0.02321"
"9841","59.01000","4.91769","0.02334"
"9876","59.22000","4.93521","0.02396"
"9911","59.43000","4.95267","0.02312"
"9946","59.64000","4.97018","0.02311"
"9981","59.85000","4.98764","0.02354"
"10016","60.06000","5.00528","0.02413"
"10051","60.27000","5.02262","0.02302"
"10086","60.48000","5.04020","0.02314"
"10121","60.69000","5.05772","0.02370"
"10156","60.90000","5.07517","0.02347"
"10191","61.11000","5.09269","0.02406"
"10226","61.32000","5.11021","0.02378"
"10261","61.53000","5.12761","0.02485"
"10296","61.74000","5.14519","0.02339"
"10331","61.95000","5.16271","0.02386"
"10366","62.16000","5.18017","0.02422"
"10401","62.37000","5.19768","0.02417"
"10436","62.58000","5.21508","0.02400"
"10471","62.79000","5.23272","0.02413"
"10506","63.00000","5.25018","0.02467"
"10541","63.21000","5.26770","0.02337"
"10576","63.42000","5.28522","0.02434"
"10611","63.63000","5.30267","0.02474"
"10646","63.84000","5.32019","0.02445"
"10681","64.05000","5.33765","0.02405"
"10716","64.26000","5.35517","0.02450"
"10751","64.47000","5.37269","0.02469"
"10786","64.68000","5.39015","0.02447"
"10821","64.89000","5.40766","0.02421"
"10856","65.10000","5.42524","0.02489"
"10891","65.31000","5.44264","0.02487"
"10926","65.52000","5.46016","0.02508"
"10961","65.73000","5.47774","0.02504"
"10996","65.94000","5.49520","0.02475"
"11031","66.15000","5.51271","0.02470"
"11066","66.36000","5.53017","0.02474"
"11101","66.57000","5.54769","0.02588"
"11136","66.78000","5.56515","0.02515"
"11171","66.99000","5.58273","0.02528"
"11206","67.20000","5.60019","0.02561"
"11241","67.41000","5.61771","0.02600"
"11276","67.62000","5.63516","0.02547"
"11311","67.83000","5.65268","0.02642"
"11346","68.04000","5.67014","0.02539"
"11381","68.25000","5.68772","0.02641"
"11416","68.46000","5.70512","0.02522"
"11451","68.67000","5.72276","0.02499"
"11486","68.88000","5.74015","0.02619"
"11521","69.09000","5.75767","0.02586"
"11556","69.30000","5.77519","0.02622"
"11591","69.51000","5.79265","0.02582"
"11626","69.72000","5.81023","0.02598"
"11661","69.93000","5.82769","0.02622"
"11696","70.14000","5.84508","0.02511"
"11731","70.35000","5.86272","0.02561"
"11766","70.56000","5.88018","0.02597"
"11801","70.77000","5.89764","0.02624"
"11836","70.98000","5.91522","0.02688"
"11871","71.19000","5.93262","0.02699"
"11906","71.40000","5.95019","0.02698"
"11941","71.61000","5.96771","0.02658"
"11976","71.82000","5.98523","0.02706"
"12011","72.03000","6.00269","0.02625"
"12046","72.24000","6.02015","0.02603"
"12081","72.45000","6.03767","0.02710"
"12116","72.66000","6.05518","0.02663"
"12151","72.87000","6.07270","0.02619"
"12186","73.08000","6.09016","0.02670"
"12221","73.29000","6.10768","0.02651"
"12256","73.50000","6.12520","0.02680"
"12291","73.71000","6.14272","0.02758"
"12326","73.92000","6.16012","0.02689"
"12361","74.13000","6.17769","0.02753"
"12396","74.34000","6.19515","0.02732"
"12431","74.55000","6.21267","0.02787"
"12466","74.76000","6.23025","0.02757"
"12501","74.97000","6.24765","0.02726"
"12536","75.18000","6.26523","0.02776"
"12571","75.39000","6.28268","0.02700"
"12606","75.60000","6.30014","0.02718"
"12641","75.81000","6.31766","0.02751"
"12676","76.02000","6.33518","0.02822"
"12711","76.23000","6.35270","0.02831"
"12746","76.44000","6.37022","0.02834"
"12781","76.65000","6.38767","0.02826"
"12816","76.86000","6.40525","0.02875"
"12851","77.07000","6.42265","0.02886"
"12886","77.28000","6.44023","0.02942"
"12921","77.49000","6.45763","0.02901"
"12956","77.70000","6.47521","0.02837"
"12991","77.91000","6.49266","0.02885"
"13026","78.12000","6.51018","0.02963"
"13061","78.33000","6.52770","0.03007"
"13096","78.54000","6.54522","0.02957"
"13131","78.75000","6.56262","0.02985"
"13166","78.96000","6.58020","0.03095"
"13201","79.17000","6.59766","0.03024"
"13236","79.38000","6.61517","0.03059"
"13271","79.59000","6.63275","0.03133"
"13306","79.80000","6.65009","0.03011"
"13341","80.01000","6.66773","0.03087"
"13376","80.22000","6.68519","0.03114"
"13411","80.43000","6.70271","0.03109"
"13446","80.64000","6.72016","0.03121"
"13481","80.85000","6.73768","0.03097"
"13516","81.06000","6.75520","0.03133"
"13551","81.27000","6.77272","0.03155"
"13586","81.48000","6.79018","0.03195"
"13621","81.69000","6.80764","0.03182"
"13656","81.90000","6.82516","0.03235"
"13691","82.11000","6.84267","0.03222"
"13726","82.32000","6.86019","0.03267"
"13761","82.53000","6.87765","0.03263"
"13796","82.74000","6.89517","0.03247"
"13831","82.95000","6.91269","0.03208"
"13866","83.16000","6.93020","0.03266"
"13901","83.37000","6.94766","0.03255"
"13936","83.58000","6.96518","0.03290"
"13971","83.79000","6.98264","0.03280"
"14006","84.00000","7.00016","0.03114"
"14041","84.21000","7.01762","0.03011"
"14076","84.42000","7.03525","0.03061"
"14111","84.63000","7.05265","0.03087"
"14146","84.84000","7.07017","0.03069"
"14181","85.05000","7.08769","0.03076"
"14216","85.26000","7.10515","0.03057"
"14251","85.47000","7.12267","0.03009"
"14286","85.68000","7.14013","0.03065"
"14321","85.89000","7.15770","0.03028"
"14356","86.10000","7.17516","0.03001"
"14391","86.31000","7.19262","0.03027"
"14426","86.52000","7.21020","0.02962"
"14461","86.73000","7.22766","0.03086"
"14496","86.94000","7.24524","0.03064"
"14531","87.15000","7.26269","0.03059"
"14566","87.36000","7.28009","0.03047"
"14601","87.57000","7.29773","0.03033"
"14636","87.78000","7.31519","0.03182"
"14671","87.99000","7.33265","0.03067"
"14706","88.20000","7.35023","0.03099"
"14741","88.41000","7.36763","0.03174"
"14776","88.62000","7.38526","0.03172"
"14811","88.83000","7.40266","0.03163"
"14846","89.04000","7.42018","0.03111"
"14881","89.25000","7.43770","0.03018"
"14916","89.46000","7.45516","0.03141"
"14951","89.67000","7.47268","0.03150"
"14986","89.88000","7.49019","0.03111"
"15021","90.09000","7.50765","0.03190"
"15056","90.30000","7.52517","0.03174"
"15091","90.51000","7.54263","0.03214"
"15126","90.72000","7.56015","0.03215"
"15161","90.93000","7.57773","0.03192"
"15196","91.14000","7.59512","0.03266"
"15231","91.35000","7.61270","0.03222"
"15266","91.56000","7.63016","0.03238"
"15301","91.77000","7.64768","0.03226"
"15336","91.98000","7.66520","0.03284"
"15371","92.19000","7.68266","0.03258"
"15406","92.40000","7.70023","0.02810"
"15441","92.61000","7.71769","0.02936"
"15476","92.82000","7.73515","0.03025"
"15511","93.03000","7.75273","0.03133"
"15546","93.24000","7.77019","0.03022"
"15581","93.45000","7.78765","0.03049"
"15616","93.66000","7.80517","0.03067"
"15651","93.87000","7.82268","0.03181"
"15686","94.08000","7.84020","0.03293"
"15721","94.29000","7.85766","0.03295"
"15756","94.50000","7.87524","0.03222"
"15791","94.71000","7.89270","0.03152"
"15826","94.92000","7.91021","0.03160"
"15861","95.13000","7.92767","0.03278"
"15896","95.34000","7.94519","0.03169"
"15931","95.55000","7.96271","0.03242"
"15966","95.76000","7.98017","0.03288"
"16001","95.97000","7.99763","0.03251"
"16036","96.18000","8.01521","0.03129"
"16071","96.39000","8.03266","0.03097"
"16106","96.60000","8.05018","0.03116"
"16141","96.81000","8.06770","0.03138"
"16176","97.02000","8.08510","0.03106"
"16211","97.23000","8.10274","0.03188"
"16246","97.44000","8.12014","0.03079"
"16281","97.65000","8.13765","0.03143"
"16316","97.86000","8.15517","0.03227"
"16351","98.07000","8.17263","0.03211"
"16386","98.28000","8.19021","0.03312"
"16421","98.49000","8.20767","0.03229"
"16456","98.70000","8.22513","0.03249"
"16491","98.91000","8.24264","0.03323"
"16526","99.12000","8.26010","0.03351"
"16561","99.33000","8.27774","0.03384"
"16596","99.54000","8.29520","0.03327"
"16631","99.75000","8.31266","0.03451"
"16666","99.96000","8.33024","0.03483"
"16701","100.17000","8.34764","0.03408"
"16736","100.38000","8.36521","0.03492"
"16771","100.59000","8.38267","0.03535"
"16806","100.80000","8.40019","0.03538"
"16841","101.01000","8.41765","0.03536"
"16876","101.22000","8.43517","0.03612"
"16911","101.43000","8.45263","0.03609"
"16946","101.64000","8.47020","0.03633"
"16981","101.85000","8.48766","0.03698"
"17016","102.06000","8.50518","0.03668"
"17051","102.27000","8.52270","0.03683"
"17086","102.48000","8.54016","0.03648"
"17121","102.69000","8.55774","0.03753"
"17156","102.90000","8.57513","0.03828"
"17191","103.11000","8.59271","0.03807"
"17226","103.32000","8.61017","0.03825"
"17261","103.53000","8.62769","0.03796"
"17296","103.74000","8.64521","0.03865"
"17331","103.95000","8.66267","0.03890"
"17366","104.16000","8.68018","0.03908"
"17401","104.37000","8.69770","0.03891"
"17436","104.58000","8.71510","0.03935"
"17471","104.79000","8.73274","0.03952"
"17506","105.00000","8.75020","0.03959"
"17541","105.21000","8.76766","0.03906"
"17576","105.42000","8.78523","0.04020"
"17611","105.63000","8.80263","0.04060"
"17646","105.84000","8.82021","0.04041"
"17681","106.05000","8.83767","0.04024"
"17716","106.26000","8.85519","0.04034"
"17751","106.47000","8.87271","0.04129"
"17786","106.68000","8.89017","0.04223"
"17821","106.89000","8.90768","0.04141"
"17856","107.10000","8.92520","0.04239"
"17891","107.31000","8.94266","0.04350"
"17926","107.52000","8.96018","0.04339"
"17961","107.73000","8.97764","0.04308"
"17996","107.94000","8.99522","0.04395"
"18031","108.15000","9.01273","0.04390"
"18066","108.36000","9.03013","0.04443"
"18101","108.57000","9.04771","0.04559"
"18136","108.78000","9.06517","0.04528"
"18171","108.99000","9.08269","0.04575"
"18206","109.20000","9.10021","0.04589"
"18241","109.41000","9.11766","0.04581"
"18276","109.62000","9.13518","0.04680"
"18311","109.83000","9.15270","0.04708"
"18346","110.04000","9.17016","0.04777"
"18381","110.25000","9.18768","0.04592"
"18416","110.46000","9.20520","0.04721"
"18451","110.67000","9.22265","0.04367"
"18486","110.88000","9.24017","0.04555"
"18521","111.09000","9.25769","0.04598"
"18556","111.30000","9.27521","0.04303"
"18591","111.51000","9.29267","0.04465"
"18626","111.72000","9.31025","0.04514"
"18661","111.93000","9.32765","0.04459"
"18696","112.14000","9.34522","0.04398"
"18731","112.35000","9.36268","0.04538"
"18766","112.56000","9.38020","0.04656"
"18801","112.77000","9.39772","0.04716"
"18836","112.98000","9.41524","0.04777"
"18871","113.19000","9.43258","0.04507"
"18906","113.40000","9.45021","0.04721"
"18941","113.61000","9.46773","0.04804"
"18976","113.82000","9.48513","0.04887"
"19011","114.03000","9.50271","0.04949"
"19046","114.24000","9.52017","0.04958"
"19081","114.45000","9.53769","0.05045"
"19116","114.66000","9.55520","0.05100"
"19151","114.87000","9.57266","0.05189"
"19186","115.08000","9.59024","0.05187"
"19221","115.29000","9.60764","0.05239"
"19256","115.50000","9.62522","0.05181"
"19291","115.71000","9.64274","0.05310"
"19326","115.92000","9.66014","0.05318"
"19361","116.13000","9.67765","0.05375"
"19396","116.34000","9.69517","0.05479"
"19431","116.55000","9.71269","0.05512"
"19466","116.76000","9.73021","0.05573"
"19501","116.97000","9.74761","0.05617"
"19536","117.18000","9.76519","0.05611"
"19571","117.39000","9.78264","0.05655"
"19606","117.60000","9.80022","0.05706"
"19641","117.81000","9.81774","0.05715"
"19676","118.02000","9.83520","0.05702"
"19711","118.23000","9.85272","0.05710"
"19746","118.44000","9.87018","0.05687"
"19781","118.65000","9.88763","0.05726"
"19816","118.86000","9.90521","0.05760"
"19851","119.07000","9.92267","0.05787"
"19886","119.28000","9.94019","0.05843"
"19921","119.49000","9.95771","0.05872"
"19956","119.70000","9.97517","0.05888"
"19991","119.91000","9.99274","0.05919"
"20026","120.12000","10.01014","0.05940"
"20061","120.33000","10.02772","0.05941"
"20096","120.54000","10.04518","0.05967"
"20131","120.75000","10.06270","0.05972"
"20166","120.96000","10.08022","0.05997"
"20201","121.17000","10.09768","0.05999"
"20236","121.38000","10.11519","0.06021"
"20271","121.59000","10.13271","0.06025"
"20306","121.80000","10.15011","0.06013"
"20341","122.01000","10.16769","0.06007"
"20376","122.22000","10.18521","0.06005"
"20411","122.43000","10.20267","0.06028"
"20446","122.64000","10.22018","0.06042"
"20481","122.85000","10.23764","0.06049"
"20516","123.06000","10.25522","0.06045"
"20551","123.27000","10.27262","0.06067"
"20586","123.48000","10.29020","0.06078"
"20621","123.69000","10.30772","0.06085"
"20656","123.90000","10.32517","0.06103"
"20691","124.11000","10.34269","0.06117"
"20726","124.32000","10.36021","0.06124"
"20761","124.53000","10.37761","0.06126"
"20796","124.74000","10.39519","0.06125"
"20831","124.95000","10.41265","0.06141"
"20866","125.16000","10.43016","0.06146"
"20901","125.37000","10.44774","0.06154"
"20936","125.58000","10.46508","0.06174"
"20971","125.79000","10.48272","0.06188"
"21006","126.00000","10.50018","0.06186"
"21041","126.21000","10.51770","0.06194"
"21076","126.42000","10.53522","0.06220"
"21111","126.63000","10.55267","0.06232"
"21146","126.84000","10.57019","0.06260"
"21181","127.05000","10.58771","0.06270"
"21216","127.26000","10.60517","0.06285"
"21251","127.47000","10.62275","0.06312"
"21286","127.68000","10.64015","0.06351"
"21321","127.89000","10.65766","0.06364"
"21356","128.10000","10.67518","0.06388"
"21391","128.31000","10.69270","0.06415"
"21426","128.52000","10.71022","0.06489"
"21461","128.73000","10.72768","0.06528"
"21496","128.94000","10.74526","0.06571"
"21531","129.15000","10.76265","0.06649"
"21566","129.36000","10.78017","0.06663"
"21601","129.57000","10.79769","0.06719"
"21636","129.78000","10.81515","0.06803"
"21671","129.99000","10.83273","0.06845"
"21706","130.20000","10.85019","0.06966"
"21741","130.41000","10.86765","0.07009"
"21776","130.62000","10.88522","0.07062"
"21811","130.83000","10.90268","0.07153"
"21846","131.04000","10.92014","0.07205"
"21881","131.25000","10.93772","0.07287"
"21916","131.46000","10.95512","0.07380"
"21951","131.67000","10.97269","0.07492"
"21986","131.88000","10.99015","0.07550"
"22021","132.09000","11.00767","0.07626"
"22056","132.30000","11.02519","0.07724"
"22091","132.51000","11.04265","0.07861"
"22126","132.72000","11.06017","0.07865"
"22161","132.93000","11.07769","0.08000"
"22196","133.14000","11.09514","0.08071"
"22231","133.35000","11.11266","0.08154"
"22266","133.56000","11.13018","0.08314"
"22301","133.77000","11.14770","0.08323"
"22336","133.98000","11.16522","0.08450"
"22371","134.19000","11.18262","0.08516"
"22406","134.40000","11.20019","0.08641"
"22441","134.61000","11.21765","0.08799"
"22476","134.82000","11.23517","0.08849"
"22511","135.03000","11.25269","0.08939"
"22546","135.24000","11.27015","0.09017"
"22581","135.45000","11.28767","0.09101"
"22616","135.66000","11.30512","0.09214"
"22651","135.87000","11.32264","0.09263"
"22686","136.08000","11.34016","0.09351"
"22721","136.29000","11.35762","0.09404"
"22756","136.50000","11.37520","0.09477"
"22791","136.71000","11.39266","0.09564"
"22826","136.92000","11.41017","0.09626"
"22861","137.13000","11.42775","0.09701"
"22896","137.34000","11.44509","0.09753"
"22931","137.55000","11.46279","0.09803"
"22966","137.76000","11.48019","0.09902"
"23001","137.97000","11.49765","0.09977"
"23036","138.18000","11.51523","0.10081"
"23071","138.39000","11.53262","0.10216"
"23106","138.60000","11.55020","0.10348"
"23141","138.81000","11.56772","0.10472"
"23176","139.02000","11.58512","0.10636"
"23211","139.23000","11.60270","0.10697"
"23246","139.44000","11.62015","0.10916"
"23281","139.65000","11.63767","0.11107"
"23316","139.86000","11.65519","0.11268"
"23351","140.07000","11.67265","0.11481"
"23386","140.28000","11.69023","0.11653"
"23421","140.49000","11.70763","0.11802"
"23456","140.70000","11.72521","0.12098"
"23491","140.91000","11.74272","0.12330"
"23526","141.12000","11.76018","0.12479"
"23561","141.33000","11.77770","0.12662"
"23596","141.54000","11.79522","0.12762"
"23631","141.75000","11.81268","0.12889"
"23666","141.96000","11.83014","0.13087"
"23701","142.17000","11.84760","0.13248"
"23736","142.38000","11.86517","0.13427"
"23771","142.59000","11.88269","0.13466"
"23806","142.80000","11.90009","0.13634"
"23841","143.01000","11.91773","0.13793"
"23876","143.22000","11.93519","0.13872"
"23911","143.43000","11.95271","0.14032"
"23946","143.64000","11.97022","0.14124"
"23981","143.85000","11.98768","0.14190"
"24016","144.06000","12.00520","0.14306"
"24051","144.27000","12.02266","0.14335"
"24086","144.48000","12.04012","0.14429"
"24121","144.69000","12.05769","0.14495"
"24156","144.90000","12.07515","0.14532"
"24191","145.11000","12.09267","0.14409"
"24226","145.32000","12.11019","0.14547"
"24261","145.53000","12.12765","0.14595"
"24296","145.74000","12.14517","0.14664"
"24331","145.95000","12.16263","0.14669"
"24366","146.16000","12.18026","0.14723"
"24401","146.37000","12.19766","0.14748"
"24436","146.58000","12.21518","0.14808"
"24471","146.79000","12.23276","0.14817"
"24506","147.00000","12.25016","0.14846"
"24541","147.21000","12.26768","0.14861"
"24576","147.42000","12.28520","0.14914"
"24611","147.63000","12.30259","0.14960"
"24646","147.84000","12.32023","0.15014"
"24681","148.05000","12.33769","0.15045"
"24716","148.26000","12.35515","0.15099"
"24751","148.47000","12.37273","0.15185"
"24786","148.68000","12.39012","0.15221"
"24821","148.89000","12.40770","0.15381"
"24856","149.10000","12.42516","0.15414"
"24891","149.31000","12.44274","0.15513"
"24926","149.52000","12.46026","0.15618"
"24961","149.73000","12.47766","0.15728"
"24996","149.94000","12.49518","0.15814"
"25031","150.15000","12.51269","0.15830"
"25066","150.36000","12.53015","0.15879"
"25101","150.57000","12.54767","0.15920"
"25136","150.78000","12.56513","0.13013"
"25171","150.99000","12.58271","0.13607"
"25206","151.20000","12.60017","0.13895"
"25241","151.41000","12.61762","0.14193"
"25276","151.62000","12.63520","0.14269"
"25311","151.83000","12.65266","0.14476"
"25346","152.04000","12.67018","0.14548"
"25381","152.25000","12.68770","0.14672"
"25416","152.46000","12.70516","0.14715"
"25451","152.67000","12.72273","0.14770"
"25486","152.88000","12.74019","0.14830"
"25521","153.09000","12.75771","0.14884"
"25556","153.30000","12.77523","0.14881"
"25591","153.51000","12.79263","0.14875"
"25626","153.72000","12.81021","0.14955"
"25661","153.93000","12.82773","0.14996"
"25696","154.14000","12.84518","0.15139"
"25731","154.35000","12.86276","0.15220"
"25766","154.56000","12.88016","0.15354"
"25801","154.77000","12.89768","0.15523"
"25836","154.98000","12.91520","0.15643"
"25871","155.19000","12.93266","0.15795"
"25906","155.40000","12.95017","0.15930"
"25941","155.61000","12.96763","0.16120"
"25976","155.82000","12.98521","0.16219"
"26011","156.03000","13.00273","0.16385"
"26046","156.24000","13.02013","0.16489"
"26081","156.45000","13.03771","0.16592"
"26116","156.66000","13.05516","0.16758"
"26151","156.87000","13.07262","0.16807"
"26186","157.08000","13.09020","0.17043"
"26221","157.29000","13.10760","0.17140"
"26256","157.50000","13.12524","0.17287"
"26291","157.71000","13.14264","0.17437"
"26326","157.92000","13.16021","0.17622"
"26361","158.13000","13.17773","0.17804"
"26396","158.34000","13.19519","0.17900"
"26431","158.55000","13.21271","0.18075"
"26466","158.76000","13.23017","0.18250"
"26501","158.97000","13.24769","0.18386"
"26536","159.18000","13.26520","0.18597"
"26571","159.39000","13.28266","0.18727"
"26606","159.60000","13.30018","0.18915"
"26641","159.81000","13.31770","0.19075"
"26676","160.02000","13.33516","0.19204"
"26711","160.23000","13.35268","0.19344"
"26746","160.44000","13.37020","0.19484"
"26781","160.65000","13.38771","0.19639"
"26816","160.86000","13.40523","0.19791"
"26851","161.07000","13.42269","0.19973"
"26886","161.28000","13.44015","0.20127"
"26921","161.49000","13.45767","0.20325"
"26956","161.70000","13.47513","0.20459"
"26991","161.91000","13.49270","0.20543"
"27026","162.12000","13.51016","0.20657"
"27061","162.33000","13.52768","0.20800"
"27096","162.54000","13.54520","0.20805"
"27131","162.75000","13.56266","0.20884"
"27166","162.96000","13.58018","0.20912"
"27201","163.17000","13.59764","0.20945"
"27236","163.38000","13.61527","0.20952"
"27271","163.59000","13.63267","0.20975"
"27306","163.80000","13.65013","0.20985"
"27341","164.01000","13.66771","0.20999"
"27376","164.22000","13.68517","0.21027"
"27411","164.43000","13.70268","0.21046"
"27446","164.64000","13.72020","0.21082"
"27481","164.85000","13.73760","0.21098"
"27516","165.06000","13.75518","0.21203"
"27551","165.27000","13.77264","0.21225"
"27586","165.48000","13.79016","0.21398"
"27621","165.69000","13.80773","0.21551"
"27656","165.90000","13.82513","0.21635"
"27691","166.11000","13.84271","0.21794"
"27726","166.32000","13.86017","0.21945"
"27761","166.53000","13.87769","0.22114"
"27796","166.74000","13.89521","0.22232"
"27831","166.95000","13.91267","0.22383"
"27866","167.16000","13.93018","0.22503"
"27901","167.37000","13.94770","0.22567"
"27936","167.58000","13.96516","0.22707"
"27971","167.79000","13.98268","0.22866"
"28006","168.00000","14.00014","0.22901"
"28041","168.21000","14.01766","0.23107"
"28076","168.42000","14.03518","0.23194"
"28111","168.63000","14.05263","0.23287"
"28146","168.84000","14.07021","0.23359"
"28181","169.05000","14.08767","0.23500"
"28216","169.26000","14.10519","0.23648"
"28251","169.47000","14.12271","0.23767"
"28286","169.68000","14.14016","0.23881"
"28321","169.89000","14.15768","0.23929"
"28356","170.10000","14.17520","0.24063"
"28391","170.31000","14.19266","0.24168"
"28426","170.52000","14.21024","0.24245"
"28461","170.73000","14.22764","0.24348"
"28496","170.94000","14.24516","0.24466"
"28531","171.15000","14.26267","0.24568"
"28566","171.36000","14.28019","0.24631"
"28601","171.57000","14.29771","0.24689"
"28636","171.78000","14.31517","0.24763"
"28671","171.99000","14.33269","0.24829"
"28706","172.20000","14.35021","0.24917"
"28741","172.41000","14.36766","0.25022"
"28776","172.62000","14.38518","0.25089"
"28811","172.83000","14.40264","0.25174"
"28846","173.04000","14.42022","0.25267"
"28881","173.25000","14.43774","0.25349"
"28916","173.46000","14.45514","0.25415"
"28951","173.67000","14.47271","0.25541"
"28986","173.88000","14.49017","0.25604"
"29021","174.09000","14.50763","0.25772"
"29056","174.30000","14.52521","0.25786"
"29091","174.51000","14.54261","0.25935"
"29126","174.72000","14.56025","0.26045"
"29161","174.93000","14.57765","0.26174"
"29196","175.14000","14.59522","0.26233"
"29231","175.35000","14.61274","0.26386"
"29266","175.56000","14.63014","0.02385"
"29301","175.77000","14.64772","0.04385"
"29336","175.98000","14.66518","0.04046"
"29371","176.19000","14.68264","0.04499"
"29406","176.40000","14.70021","0.05395"
"29441","176.61000","14.71761","0.04313"
"29476","176.82000","14.73519","0.04751"
"29511","177.03000","14.75271","0.04427"
"29546","177.24000","14.77011","0.04374"
"29581","177.45000","14.78774","0.04687"
"29616","177.66000","14.80520","0.05592"
"29651","177.87000","14.82272","0.05070"
"29686","178.08000","14.84018","0.04806"
"29721","178.29000","14.85764","0.05422"
"29756","178.50000","14.87522","0.05478"
"29791","178.71000","14.89268","0.05430"
"29826","178.92000","14.91013","0.05457"
"29861","179.13000","14.92765","0.05769"
"29896","179.34000","14.94517","0.05661"
"29931","179.55000","14.96269","0.05707"
"29966","179.76000","14.98015","0.05952"
"30001","179.97000","14.99767","0.05781"
"30036","180.18000","15.01524","0.05846"
"30071","180.39000","15.03258","0.05996"
"30106","180.60000","15.05028","0.05895"
"30141","180.81000","15.06768","0.05959"
"30176","181.02000","15.08514","0.06081"
"30211","181.23000","15.10266","0.05997"
"30246","181.44000","15.12018","0.06036"
"30281","181.65000","15.13769","0.06107"
"30316","181.86000","15.15521","0.06057"
"30351","182.07000","15.17261","0.06080"
"30386","182.28000","15.19019","0.06128"
"30421","182.49000","15.20765","0.06118"
"30456","182.70000","15.22517","0.06123"
"30491","182.91000","15.24268","0.06144"
"30526","183.12000","15.26014","0.06151"
"30561","183.33000","15.27772","0.06156"
"30596","183.54000","15.29518","0.06171"
"30631","183.75000","15.31270","0.06179"
"30666","183.96000","15.33022","0.06197"
"30701","184.17000","15.34767","0.06210"
"30736","184.38000","15.36519","0.06228"
"30771","184.59000","15.38271","0.06249"
"30806","184.80000","15.40017","0.06287"
"30841","185.01000","15.41769","0.06366"
"30876","185.22000","15.43509","0.06326"
"30911","185.43000","15.45273","0.06482"
"30946","185.64000","15.47024","0.06479"
"30981","185.85000","15.48764","0.06460"
"31016","186.06000","15.50522","0.06664"
"31051","186.27000","15.52262","0.06537"
"31086","186.48000","15.54020","0.06653"
"31121","186.69000","15.55772","0.06817"
"31156","186.90000","15.57517","0.06735"
"31191","187.11000","15.59269","0.06971"
"31226","187.32000","15.61015","0.06924"
"31261","187.53000","15.62767","0.06984"
"31296","187.74000","15.64519","0.07143"
"31331","187.95000","15.66265","0.07131"
"31366","188.16000","15.68022","0.07268"
"31401","188.37000","15.69768","0.07344"
"31436","188.58000","15.71514","0.07403"
"31471","188.79000","15.73272","0.07505"
"31506","189.00000","15.75012","0.07642"
"31541","189.21000","15.76775","0.07700"
"31576","189.42000","15.78515","0.07845"
"31611","189.63000","15.80267","0.08057"
"31646","189.84000","15.82019","0.08042"
"31681","190.05000","15.83765","0.08281"
"31716","190.26000","15.85523","0.08339"
"31751","190.47000","15.87269","0.08409"
"31786","190.68000","15.89014","0.08720"
"31821","190.89000","15.90772","0.08664"
"31856","191.10000","15.92518","0.08864"
"31891","191.31000","15.94264","0.08861"
"31926","191.52000","15.96022","0.08943"
"31961","191.73000","15.97762","0.09143"
"31996","191.94000","15.99520","0.09128"
"32031","192.15000","16.01265","0.09289"
"32066","192.36000","16.03017","0.09268"
"32101","192.57000","16.04775","0.09414"
"32136","192.78000","16.06515","0.09398"
"32171","192.99000","16.08267","0.09516"
"32206","193.20000","16.10019","0.09531"
"32241","193.41000","16.11764","0.09667"
"32276","193.62000","16.13516","0.09685"
"32311","193.83000","16.15262","0.09781"
"32346","194.04000","16.17020","0.09820"
"32381","194.25000","16.18772","0.09871"
"32416","194.46000","16.20511","0.10090"
"32451","194.67000","16.22269","0.10040"
"32486","194.88000","16.24021","0.10222"
"32521","195.09000","16.25767","0.10254"
"32556","195.30000","16.27519","0.10360"
"32591","195.51000","16.29265","0.10620"
"32626","195.72000","16.31017","0.10636"
"32661","195.93000","16.32768","0.10808"
"32696","196.14000","16.34520","0.10851"
"32731","196.35000","16.36266","0.10908"
"32766","196.56000","16.38018","0.11054"
"32801","196.77000","16.39770","0.11199"
"32836","196.98000","16.41522","0.11401"
"32871","197.19000","16.43267","0.11613"
"32906","197.40000","16.45025","0.11627"
"32941","197.61000","16.46765","0.11984"
"32976","197.82000","16.48523","0.12025"
"33011","198.03000","16.50269","0.12281"
"33046","198.24000","16.52021","0.12316"
"33081","198.45000","16.53766","0.12540"
"33116","198.66000","16.55518","0.12632"
"33151","198.87000","16.57270","0.12799"
"33186","199.08000","16.59022","0.12978"
"33221","199.29000","16.60762","0.13030"
"33256","199.50000","16.62520","0.13268"
"33291","199.71000","16.64266","0.13353"
"33326","199.92000","16.66017","0.13427"
"33361","200.13000","16.67769","0.13568"
"33396","200.34000","16.69509","0.13631"
"33431","200.55000","16.71273","0.13785"
"33466","200.76000","16.73019","0.13874"
"33501","200.97000","16.74771","0.13953"
"33536","201.18000","16.76522","0.14073"
"33571","201.39000","16.78268","0.14084"
"33606","201.60000","16.80020","0.14272"
"33641","201.81000","16.81772","0.14269"
"33676","202.02000","16.83518","0.14347"
"33711","202.23000","16.85270","0.14404"
"33746","202.44000","16.87015","0.14442"
"33781","202.65000","16.88767","0.14491"
"33816","202.86000","16.90519","0.14484"
"33851","203.07000","16.92265","0.14436"
"33886","203.28000","16.94023","0.04272"
"33921","203.49000","16.95763","0.05433"
"33956","203.70000","16.97520","0.05593"
"33991","203.91000","16.99272","0.05648"
"34026","204.12000","17.01012","0.05700"
"34061","204.33000","17.02770","0.05761"
"34096","204.54000","17.04516","0.05766"
"34131","204.75000","17.06268","0.05774"
"34166","204.96000","17.08019","0.05841"
"34201","205.17000","17.09765","0.05846"
"34236","205.38000","17.11523","0.05801"
"34271","205.59000","17.13269","0.05851"
"34306","205.80000","17.15015","0.05871"
"34341","206.01000","17.16773","0.05855"
"34376","206.22000","17.18513","0.05877"
"34411","206.43000","17.20276","0.05792"
"34446","206.64000","17.22016","0.04092"
"34481","206.85000","17.23768","0.04060"
"34516","207.06000","17.25520","0.03068"
"34551","207.27000","17.27266","0.02309"
"34586","207.48000","17.29024","0.01295"
"34621","207.69000","17.30770","0.01178"
"34656","207.90000","17.32515","0.01151"
"34691","208.11000","17.34273","0.01292"
"34726","208.32000","17.36013","0.01264"
"34761","208.53000","17.37765","0.01227"
"34796","208.74000","17.39523","0.01283"
"34831","208.95000","17.41262","0.01309"
"34866","209.16000","17.43020","0.01267"
"34901","209.37000","17.44766","0.01212"
"34936","209.58000","17.46524","0.01211"
"34971","209.79000","17.48270","0.01217"
"35006","210.00000","17.50016","0.01200"
"35041","210.21000","17.51768","0.01273"
"35076","210.42000","17.53519","0.01325"
"35111","210.63000","17.55265","0.01283"
"35146","210.84000","17.57017","0.01282"
"35181","211.05000","17.58763","0.01235"
"35216","211.26000","17.60521","0.01211"
"35251","211.47000","17.62267","0.01248"
"35286","211.68000","17.64013","0.01162"
"35321","211.89000","17.65770","0.01268"
"35356","212.10000","17.67516","0.01245"
"35391","212.31000","17.69268","0.01222"
"35426","212.52000","17.71020","0.01261"
"35461","212.73000","17.72766","0.01261"
"35496","212.94000","17.74517","0.01289"
"35531","213.15000","17.76269","0.01298"
"35566","213.36000","17.78015","0.01308"
"35601","213.57000","17.79773","0.01253"
"35636","213.78000","17.81513","0.01306"
"35671","213.99000","17.83271","0.01251"
"35706","214.20000","17.85016","0.01279"
"35741","214.41000","17.86768","0.01339"
"35776","214.62000","17.88514","0.01262"
"35811","214.83000","17.90266","0.01235"
"35846","215.04000","17.92024","0.01154"
"35881","215.25000","17.93770","0.01227"
"35916","215.46000","17.95516","0.01124"
"35951","215.67000","17.97273","0.01202"
"35986","215.88000","17.99013","0.01134"
"36021","216.09000","18.00771","0.01217"
"36056","216.30000","18.02523","0.01182"
"36091","216.51000","18.04263","0.01201"
"36126","216.72000","18.06021","0.01239"
"36161","216.93000","18.07766","0.01244"
"36196","217.14000","18.09518","0.01198"
"36231","217.35000","18.11270","0.01147"
"36266","217.56000","18.13010","0.01211"
"36301","217.77000","18.14774","0.01226"
"36336","217.98000","18.16514","0.01153"
"36371","218.19000","18.18271","0.01122"
"36406","218.40000","18.20023","0.01211"
"36441","218.61000","18.21769","0.01230"
"36476","218.82000","18.23521","0.01240"
"36511","219.03000","18.25273","0.01210"
"36546","219.24000","18.27013","0.01192"
"36581","219.45000","18.28765","0.01234"
"36616","219.66000","18.30516","0.01274"
"36651","219.87000","18.32268","0.01184"
"36686","220.08000","18.34020","0.01212"
"36721","220.29000","18.35760","0.01196"
"36756","220.50000","18.37518","0.01222"
"36791","220.71000","18.39269","0.01193"
"36826","220.92000","18.41015","0.01220"
"36861","221.13000","18.42767","0.01223"
"36896","221.34000","18.44513","0.01211"
"36931","221.55000","18.46271","0.01125"
"36966","221.76000","18.48017","0.01221"
"37001","221.97000","18.49763","0.01287"
"37036","222.18000","18.51521","0.01240"
"37071","222.39000","18.53266","0.01251"
"37106","222.60000","18.55018","0.01223"
"37141","222.81000","18.56770","0.01212"
"37176","223.02000","18.58516","0.01194"
"37211","223.23000","18.60268","0.01195"
"37246","223.44000","18.62013","0.01169"
"37281","223.65000","18.63771","0.01229"
"37316","223.86000","18.65517","0.01173"
"37351","224.07000","18.67269","0.01230"
"37386","224.28000","18.69021","0.01221"
"37421","224.49000","18.70767","0.01176"
"37456","224.70000","18.72524","0.01217"
"37491","224.91000","18.74270","0.01232"
"37526","225.12000","18.76016","0.01146"
"37561","225.33000","18.77768","0.01256"
"37596","225.54000","18.79514","0.01276"
"37631","225.75000","18.81266","0.01174"
"37666","225.96000","18.83024","0.01253"
"37701","226.17000","18.84757","0.01285"
"37736","226.38000","18.86521","0.01188"
"37771","226.59000","18.88267","0.01216"
"37806","226.80000","18.90019","0.01253"
"37841","227.01000","18.91771","0.01328"
"37876","227.22000","18.93517","0.01188"
"37911","227.43000","18.95268","0.01206"
"37946","227.64000","18.97020","0.01196"
"37981","227.85000","18.98760","0.01128"
"38016","228.06000","19.00518","0.01222"
"38051","228.27000","19.02258","0.01101"
"38086","228.48000","19.04022","0.01208"
"38121","228.69000","19.05773","0.01234"
"38156","228.90000","19.07513","0.01239"
"38191","229.11000","19.09271","0.01158"
"38226","229.32000","19.11017","0.01231"
"38261","229.53000","19.12775","0.01295"
"38296","229.74000","19.14521","0.01224"
"38331","229.95000","19.16266","0.01156"
"38366","230.16000","19.18018","0.01319"
"38401","230.37000","19.19770","0.01285"
"38436","230.58000","19.21516","0.01141"
"38471","230.79000","19.23274","0.01123"
"38506","231.00000","19.25014","0.01201"
"38541","231.21000","19.26772","0.01239"
"38576","231.42000","19.28517","0.01160"
"38611","231.63000","19.30263","0.01172"
"38646","231.84000","19.32021","0.01247"
"38681","232.05000","19.33761","0.01251"
"38716","232.26000","19.35525","0.01222"
"38751","232.47000","19.37271","0.01218"
"38786","232.68000","19.39016","0.01218"
"38821","232.89000","19.40774","0.01168"
"38856","233.10000","19.42520","0.01188"
"38891","233.31000","19.44272","0.01278"
"38926","233.52000","19.46024","0.01246"
"38961","233.73000","19.47758","0.01238"
"38996","233.94000","19.49521","0.01133"
"39031","234.15000","19.51267","0.01188"
"39066","234.36000","19.53019","0.01235"
"39101","234.57000","19.54771","0.01267"
"39136","234.78000","19.56511","0.01196"
"39171","234.99000","19.58269","0.01183"
"39206","235.20000","19.60015","0.01109"
"39241","235.41000","19.61772","0.01182"
"39276","235.62000","19.63524","0.01327"
"39311","235.83000","19.65264","0.01239"
"39346","236.04000","19.67016","0.01291"
"39381","236.25000","19.68768","0.01151"
"39416","236.46000","19.70519","0.01238"
"39451","236.67000","19.72271","0.01193"
"39486","236.88000","19.74011","0.01190"
"39521","237.09000","19.75769","0.01209"
"39556","237.30000","19.77521","0.01256"
"39591","237.51000","19.79261","0.01275"
"39626","237.72000","19.81025","0.01216"
"39661","237.93000","19.82764","0.01255"
"39696","238.14000","19.84516","0.01137"
"39731","238.35000","19.86268","0.01168"
"39766","238.56000","19.88014","0.01185"
"39801","238.77000","19.89766","0.01096"
"39836","238.98000","19.91518","0.01175"
"39871","239.19000","19.93270","0.01137"
"39906","239.40000","19.95021","0.01167"
"39941","239.61000","19.96767","0.01207"
"39976","239.82000","19.98519","0.01194"
"40011","240.03000","20.00271","0.01162"
"40046","240.24000","20.02017","0.01110"
"40081","240.45000","20.03769","0.01144"
"40116","240.66000","20.05514","0.01252"
"40151","240.87000","20.07272","0.01119"
"40186","241.08000","20.09012","0.01331"
"40221","241.29000","20.10770","0.01133"
"40256","241.50000","20.12522","0.01194"
"40291","241.71000","20.14267","0.01238"
"40326","241.92000","20.16019","0.01234"
"40361","242.13000","20.17771","0.01170"
"40396","242.34000","20.19511","0.01142"
"40431","242.55000","20.21275","0.01064"
"40466","242.76000","20.23021","0.01180"
"40501","242.97000","20.24761","0.01134"
"40536","243.18000","20.26524","0.01164"
"40571","243.39000","20.28264","0.01159"
"40606","243.60000","20.30016","0.01152"
"40641","243.81000","20.31768","0.01171"
"40676","244.02000","20.33514","0.01144"
"40711","244.23000","20.35272","0.01160"
"40746","244.44000","20.37017","0.01199"
"40781","244.65000","20.38769","0.01192"
"40816","244.86000","20.40521","0.01178"
"40851","245.07000","20.42267","0.01126"
"40886","245.28000","20.44019","0.01192"
"40921","245.49000","20.45765","0.01197"
"40956","245.70000","20.47517","0.01103"
"40991","245.91000","20.49268","0.01202"
"41026","246.12000","20.51014","0.01105"
"41061","246.33000","20.52772","0.01199"
"41096","246.54000","20.54512","0.01157"
"41131","246.75000","20.56270","0.01197"
"41166","246.96000","20.58022","0.01176"
"41201","247.17000","20.59767","0.01179"
"41236","247.38000","20.61519","0.01155"
"41271","247.59000","20.63265","0.01164"
"41306","247.80000","20.65017","0.01223"
"41341","248.01000","20.66769","0.01244"
"41376","248.22000","20.68521","0.01154"
"41411","248.43000","20.70272","0.01141"
"41446","248.64000","20.72018","0.01180"
"41481","248.85000","20.73764","0.01154"
"41516","249.06000","20.75522","0.01240"
"41551","249.27000","20.77268","0.01143"
"41586","249.48000","20.79026","0.01180"
"41621","249.69000","20.80766","0.01193"
"41656","249.90000","20.82517","0.01141"
"41691","250.11000","20.84269","0.01285"
"41726","250.32000","20.86015","0.01132"
"41761","250.53000","20.87773","0.01158"
"41796","250.74000","20.89519","0.01207"
"41831","250.95000","20.91259","0.01129"
"41866","251.16000","20.93022","0.01142"
"41901","251.37000","20.94768","0.01133"
"41936","251.58000","20.96520","0.01167"
"41971","251.79000","20.98272","0.01162"
"42006","252.00000","21.00011","0.01223"
"42041","252.21000","21.01769","0.01174"
"42076","252.42000","21.03515","0.01286"
"42111","252.63000","21.05273","0.01183"
"42146","252.84000","21.07025","0.01152"
"42181","253.05000","21.08765","0.01154"
"42216","253.26000","21.10517","0.01228"
"42251","253.47000","21.12269","0.01139"
"42286","253.68000","21.14014","0.01315"
"42321","253.89000","21.15766","0.01261"
"42356","254.10000","21.17512","0.01092"
"42391","254.31000","21.19270","0.01254"
"42426","254.52000","21.21022","0.01214"
"42461","254.73000","21.22762","0.01152"
"42496","254.94000","21.24519","0.01178"
"42531","255.15000","21.26265","0.01277"
"42566","255.36000","21.28017","0.01246"
"42601","255.57000","21.29769","0.01224"
"42636","255.78000","21.31515","0.01260"
"42671","255.99000","21.33273","0.01198"
"42706","256.20000","21.35018","0.01241"
"42741","256.41000","21.36764","0.01214"
"42768","256.57200","21.38121","0.01233"