File: Trajectories_together/161114Specimen_RawData_2.csv
"","V1","V2","V3"
"1","End date","11/14/2016",""
"2","Specimen label","20AG60",""
"3","Maximum Load","1.40394","N"
"4","Time","Extension","Load"
"5","(s)","(mm)","(N)"
"6","0.00000","17.40485","0.04586"
"67","0.36600","17.43522","0.04791"
"128","0.73200","17.46614","0.04886"
"189","1.09800","17.49669","0.04951"
"250","1.46400","17.52700","0.05056"
"311","1.83000","17.55767","0.05115"
"372","2.19600","17.58811","0.05142"
"433","2.56200","17.61860","0.05202"
"494","2.92800","17.64909","0.05259"
"555","3.29400","17.67958","0.05275"
"616","3.66000","17.71008","0.05309"
"677","4.02600","17.74057","0.05321"
"738","4.39200","17.77112","0.05352"
"799","4.75800","17.80156","0.05359"
"860","5.12400","17.83211","0.05356"
"921","5.49000","17.86254","0.05372"
"982","5.85600","17.89310","0.05387"
"1043","6.22200","17.92359","0.05398"
"1104","6.58800","17.95414","0.05418"
"1165","6.95400","17.98457","0.05443"
"1226","7.32000","18.01506","0.05472"
"1287","7.68600","18.04562","0.05501"
"1348","8.05200","18.07611","0.05548"
"1409","8.41800","18.10654","0.05645"
"1470","8.78400","18.13710","0.05716"
"1531","9.15000","18.16765","0.05794"
"1592","9.51600","18.19802","0.05881"
"1653","9.88200","18.22863","0.06013"
"1714","10.24800","18.25907","0.06063"
"1775","10.61400","18.28956","0.06189"
"1836","10.98000","18.32005","0.06342"
"1897","11.34600","18.35060","0.06547"
"1958","11.71200","18.38104","0.06693"
"2019","12.07800","18.41159","0.06915"
"2080","12.44400","18.44214","0.07101"
"2141","12.81000","18.47252","0.07295"
"2202","13.17600","18.50307","0.07539"
"2263","13.54200","18.53362","0.07773"
"2324","13.90800","18.56411","0.07780"
"2385","14.27400","18.59454","0.07959"
"2446","14.64000","18.62510","0.08130"
"2507","15.00600","18.65559","0.08377"
"2568","15.37200","18.68608","0.08577"
"2629","15.73800","18.71663","0.08732"
"2690","16.10400","18.74707","0.08948"
"2751","16.47000","18.77756","0.09054"
"2812","16.83600","18.80811","0.09363"
"2873","17.20200","18.83867","0.09578"
"2934","17.56800","18.86898","0.09941"
"2995","17.93400","18.89959","0.10279"
"3056","18.30000","18.93008","0.10616"
"3117","18.66600","18.96058","0.11142"
"3178","19.03200","18.99107","0.11523"
"3239","19.39800","19.02156","0.11850"
"3300","19.76400","19.05206","0.12251"
"3361","20.13000","19.08261","0.12543"
"3422","20.49600","19.11310","0.12879"
"3483","20.86200","19.14353","0.13093"
"3544","21.22800","19.17414","0.13318"
"3605","21.59400","19.20458","0.13554"
"3666","21.96000","19.23507","0.13743"
"3727","22.32600","19.26556","0.13877"
"3788","22.69200","19.29605","0.13831"
"3849","23.05800","19.32661","0.13926"
"3910","23.42400","19.35704","0.13999"
"3971","23.79000","19.38759","0.14076"
"4032","24.15600","19.41809","0.14145"
"4093","24.52200","19.44858","0.14229"
"4154","24.88800","19.47907","0.14265"
"4215","25.25400","19.50962","0.14439"
"4276","25.62000","19.54000","0.14579"
"4337","25.98600","19.57055","0.14799"
"4398","26.35200","19.60110","0.15050"
"4459","26.71800","19.63153","0.15209"
"4520","27.08400","19.66215","0.15493"
"4581","27.45000","19.69264","0.15750"
"4642","27.81600","19.72307","0.16031"
"4703","28.18200","19.75362","0.15266"
"4764","28.54800","19.78411","0.15349"
"4825","28.91400","19.81449","0.15369"
"4886","29.28000","19.84510","0.15573"
"4947","29.64600","19.87560","0.15837"
"5008","30.01200","19.90603","0.16228"
"5069","30.37800","19.93652","0.16562"
"5130","30.74400","19.96707","0.16910"
"5191","31.11000","19.99756","0.17396"
"5252","31.47600","20.02812","0.17771"
"5313","31.84200","20.05861","0.18147"
"5374","32.20800","20.08904","0.18498"
"5435","32.57400","20.11960","0.18916"
"5496","32.94000","20.15009","0.19246"
"5557","33.30600","20.18058","0.19536"
"5618","33.67200","20.21102","0.19832"
"5679","34.03800","20.24163","0.20012"
"5740","34.40400","20.27212","0.20126"
"5801","34.77000","20.30255","0.20218"
"5862","35.13600","20.33310","0.20281"
"5923","35.50200","20.36366","0.20405"
"5984","35.86800","20.39403","0.20512"
"6045","36.23400","20.42458","0.20786"
"6106","36.60000","20.45508","0.18525"
"6167","36.96600","20.48551","0.19879"
"6228","37.33200","20.51606","0.19933"
"6289","37.69800","20.54661","0.19795"
"6350","38.06400","20.57705","0.20106"
"6411","38.43000","20.60760","0.20331"
"6472","38.79600","20.63803","0.20367"
"6533","39.16200","20.66853","0.20423"
"6594","39.52800","20.69907","0.20934"
"6655","39.89400","20.72957","0.21628"
"6716","40.26000","20.76006","0.21688"
"6777","40.62600","20.79055","0.22130"
"6838","40.99200","20.82111","0.22709"
"6899","41.35800","20.85160","0.22974"
"6960","41.72400","20.88209","0.23099"
"7021","42.09000","20.91259","0.23519"
"7082","42.45600","20.94314","0.23815"
"7143","42.82200","20.97357","0.23983"
"7204","43.18800","21.00406","0.24309"
"7265","43.55400","21.03456","0.24618"
"7326","43.92000","21.06499","0.25013"
"7387","44.28600","21.09560","0.25314"
"7448","44.65200","21.12615","0.25830"
"7509","45.01800","21.15653","0.26219"
"7570","45.38400","21.18708","0.26717"
"7631","45.75000","21.21763","0.27178"
"7692","46.11600","21.24800","0.27731"
"7753","46.48200","21.27862","0.28423"
"7814","46.84800","21.30911","0.28993"
"7875","47.21400","21.33954","0.29560"
"7936","47.58000","21.37009","0.30003"
"7997","47.94600","21.40059","0.30462"
"8058","48.31200","21.43108","0.30932"
"8119","48.67800","21.46163","0.31553"
"8180","49.04400","21.49212","0.32194"
"8241","49.41000","21.52256","0.32731"
"8302","49.77600","21.55305","0.33288"
"8363","50.14200","21.58354","0.33794"
"8424","50.50800","21.61403","0.34254"
"8485","50.87400","21.64459","0.34615"
"8546","51.24000","21.67508","0.34839"
"8607","51.60600","21.70563","0.34864"
"8668","51.97200","21.73606","0.34986"
"8729","52.33800","21.76662","0.35046"
"8790","52.70400","21.79711","0.35068"
"8851","53.07000","21.82755","0.35093"
"8912","53.43600","21.85810","0.35173"
"8973","53.80200","21.88865","0.35295"
"9034","54.16800","21.91902","0.35544"
"9095","54.53400","21.94957","0.35919"
"9156","54.90000","21.98013","0.36426"
"9217","55.26600","22.01056","0.36962"
"9278","55.63200","22.04111","0.37687"
"9339","55.99800","22.07155","0.38471"
"9400","56.36400","22.10204","0.39318"
"9461","56.73000","22.13259","0.39939"
"9522","57.09600","22.16314","0.40366"
"9583","57.46200","22.19358","0.40708"
"9644","57.82800","22.22407","0.41272"
"9705","58.19400","22.25462","0.41950"
"9766","58.56000","22.28505","0.42612"
"9827","58.92600","22.31561","0.43410"
"9888","59.29200","22.34610","0.44057"
"9949","59.65800","22.37659","0.44669"
"10010","60.02400","22.40708","0.45121"
"10071","60.39000","22.43764","0.45480"
"10132","60.75600","22.46807","0.45877"
"10193","61.12200","22.49850","0.46188"
"10254","61.48800","22.52911","0.46549"
"10315","61.85400","22.55960","0.46776"
"10376","62.22000","22.58998","0.47082"
"10437","62.58600","22.62059","0.47398"
"10498","62.95200","22.65115","0.47900"
"10559","63.31800","22.68152","0.48443"
"10620","63.68400","22.71213","0.49045"
"10681","64.05000","22.74256","0.49697"
"10742","64.41600","22.77306","0.50159"
"10803","64.78200","22.80355","0.50307"
"10864","65.14800","22.83410","0.50549"
"10925","65.51400","22.86454","0.50978"
"10986","65.88000","22.89509","0.51659"
"11047","66.24600","22.92564","0.52379"
"11108","66.61200","22.95601","0.52968"
"11169","66.97800","22.98656","0.53721"
"11230","67.34400","23.01712","0.54391"
"11291","67.71000","23.04755","0.54894"
"11352","68.07600","23.07804","0.55183"
"11413","68.44200","23.10859","0.55408"
"11474","68.80800","23.13909","0.55704"
"11535","69.17400","23.16952","0.56143"
"11596","69.54000","23.20013","0.56847"
"11657","69.90600","23.23057","0.57548"
"11718","70.27200","23.26106","0.58225"
"11779","70.63800","23.29161","0.57968"
"11840","71.00400","23.32210","0.58578"
"11901","71.37000","23.35254","0.59102"
"11962","71.73600","23.38309","0.59906"
"12023","72.10200","23.41358","0.60742"
"12084","72.46800","23.44407","0.61253"
"12145","72.83400","23.47463","0.61605"
"12206","73.20000","23.50506","0.62215"
"12267","73.56600","23.53555","0.62978"
"12328","73.93200","23.56610","0.63556"
"12389","74.29800","23.59666","0.64207"
"12450","74.66400","23.62703","0.64702"
"12511","75.03000","23.65758","0.65102"
"12572","75.39600","23.68808","0.65328"
"12633","75.76200","23.71857","0.65517"
"12694","76.12800","23.74900","0.65738"
"12755","76.49400","23.77961","0.66029"
"12816","76.86000","23.81004","0.66385"
"12877","77.22600","23.84054","0.66889"
"12938","77.59200","23.87115","0.67501"
"12999","77.95800","23.90152","0.68058"
"13060","78.32400","23.93208","0.68794"
"13121","78.69000","23.96263","0.69699"
"13182","79.05600","23.99312","0.70193"
"13243","79.42200","24.02356","0.71022"
"13304","79.78800","24.05411","0.71734"
"13365","80.15400","24.08454","0.72444"
"13426","80.52000","24.11503","0.73429"
"13487","80.88600","24.14564","0.74294"
"13548","81.25200","24.17608","0.74920"
"13609","81.61800","24.20657","0.75542"
"13670","81.98400","24.23706","0.75956"
"13731","82.35000","24.26761","0.76353"
"13792","82.71600","24.29805","0.76603"
"13853","83.08200","24.32860","0.76802"
"13914","83.44800","24.35909","0.77008"
"13975","83.81400","24.38952","0.77373"
"14036","84.18000","24.42008","0.77917"
"14097","84.54600","24.45057","0.78627"
"14158","84.91200","24.48106","0.79357"
"14219","85.27800","24.51155","0.80105"
"14280","85.64400","24.54217","0.80794"
"14341","86.01000","24.57254","0.81166"
"14402","86.37600","24.60303","0.81747"
"14463","86.74200","24.63359","0.82340"
"14524","87.10800","24.66408","0.83269"
"14585","87.47400","24.69457","0.84081"
"14646","87.84000","24.72507","0.84865"
"14707","88.20600","24.75550","0.85663"
"14768","88.57200","24.78605","0.86254"
"14829","88.93800","24.81666","0.86846"
"14890","89.30400","24.84709","0.87335"
"14951","89.67000","24.87753","0.87874"
"15012","90.03600","24.90808","0.88325"
"15073","90.40200","24.93857","0.88875"
"15134","90.76800","24.96900","0.89560"
"15195","91.13400","24.99962","0.90446"
"15256","91.50000","25.03011","0.91291"
"15317","91.86600","25.06054","0.91835"
"15378","92.23200","25.09110","0.92360"
"15439","92.59800","25.12159","0.93300"
"15500","92.96400","25.15208","0.94230"
"15561","93.33000","25.18257","0.95066"
"15622","93.69600","25.21313","0.96023"
"15683","94.06200","25.24356","0.96632"
"15744","94.42800","25.27405","0.96964"
"15805","94.79400","25.30460","0.97106"
"15866","95.16000","25.33510","0.97210"
"15927","95.52600","25.36559","0.97469"
"15988","95.89200","25.39614","0.98142"
"16049","96.25800","25.42658","0.97986"
"16110","96.62400","25.45707","0.99224"
"16171","96.99000","25.48762","1.00101"
"16232","97.35600","25.51805","1.00770"
"16293","97.72200","25.54849","1.01894"
"16354","98.08800","25.57910","1.02676"
"16415","98.45400","25.60959","1.03060"
"16476","98.82000","25.64003","1.03607"
"16537","99.18600","25.67057","1.04409"
"16598","99.55200","25.70113","1.04688"
"16659","99.91800","25.73156","1.05227"
"16720","100.28400","25.76212","1.05851"
"16781","100.65000","25.79261","1.06407"
"16842","101.01600","25.82310","1.06809"
"16903","101.38200","25.85353","1.07193"
"16964","101.74800","25.88408","1.07727"
"17025","102.11400","25.91458","1.08302"
"17086","102.48000","25.94507","1.09022"
"17147","102.84600","25.97556","1.09964"
"17208","103.21200","26.00606","1.10937"
"17269","103.57800","26.03655","1.11796"
"17330","103.94400","26.06710","1.12077"
"17391","104.31000","26.09759","1.12405"
"17452","104.67600","26.12809","1.13185"
"17513","105.04200","26.15864","1.14155"
"17574","105.40800","26.18907","1.15168"
"17635","105.77400","26.21951","1.16102"
"17696","106.14000","26.25012","1.16876"
"17757","106.50600","26.28061","1.17363"
"17818","106.87200","26.31104","1.17609"
"17879","107.23800","26.34159","1.17830"
"17940","107.60400","26.37209","1.18047"
"18001","107.97000","26.40246","1.18264"
"18062","108.33600","26.43313","1.18557"
"18123","108.70200","26.46362","1.19058"
"18184","109.06800","26.49406","1.19800"
"18245","109.43400","26.52461","1.20909"
"18306","109.80000","26.55510","1.22097"
"18367","110.16600","26.58554","1.22935"
"18428","110.53200","26.61603","1.23737"
"18489","110.89800","26.64664","1.24928"
"18550","111.26400","26.67707","1.25975"
"18611","111.63000","26.70757","1.26703"
"18672","111.99600","26.73812","1.27210"
"18733","112.36200","26.76855","1.27690"
"18794","112.72800","26.79905","1.28005"
"18855","113.09400","26.82966","1.28308"
"18916","113.46000","26.86009","1.28736"
"18977","113.82600","26.89058","1.29370"
"19038","114.19200","26.92114","1.30296"
"19099","114.55800","26.95157","1.31374"
"19160","114.92400","26.98206","1.32480"
"19221","115.29000","27.01261","1.33112"
"19282","115.65600","27.04310","1.33473"
"19343","116.02200","27.07354","1.34086"
"19404","116.38800","27.10409","1.34925"
"19465","116.75400","27.13464","1.35872"
"19526","117.12000","27.16508","1.36796"
"19587","117.48600","27.19563","1.37540"
"19648","117.85200","27.22612","1.38167"
"19709","118.21800","27.25661","1.38746"
"19770","118.58400","27.28705","1.39145"
"19831","118.95000","27.31760","1.39545"
"19892","119.31600","27.34809","1.40043"
"19953","119.68200","27.37858","1.07793"
"20014","120.04800","27.40908","1.08094"
"20075","120.41400","27.43957","1.08263"
"20136","120.78000","27.47006","1.08809"
"20197","121.14600","27.50061","1.10400"
"20258","121.51200","27.53111","1.10926"
"20319","121.87800","27.56154","1.11894"
"20380","122.24400","27.59215","1.12402"
"20441","122.61000","27.62258","1.13274"
"20502","122.97600","27.65302","1.14714"
"20563","123.34200","27.68363","1.16258"
"20624","123.70800","27.71412","1.17117"
"20685","124.07400","27.74456","1.17198"
"20746","124.44000","27.77511","0.55731"
"20807","124.80600","27.80554","0.55496"
"20868","125.17200","27.83603","0.56070"
"20929","125.53800","27.86664","0.56744"
"20990","125.90400","27.89708","0.56507"
"21051","126.27000","27.92757","0.57903"
"21112","126.63600","27.95806","0.59577"
"21173","127.00200","27.98862","0.59087"
"21234","127.36800","28.01905","0.60156"
"21295","127.73400","28.04954","0.61309"
"21356","128.10000","28.08010","0.61323"
"21417","128.46600","28.11059","0.61791"
"21478","128.83200","28.14108","0.62522"
"21539","129.19800","28.17158","0.63265"
"21600","129.56400","28.20207","0.63713"
"21661","129.93000","28.23256","0.64346"
"21722","130.29600","28.26311","0.64932"
"21783","130.66200","28.29354","0.64666"
"21844","131.02800","28.32404","0.64898"
"21905","131.39400","28.35465","0.65238"
"21966","131.76000","28.38508","0.65354"
"22027","132.12600","28.41557","0.65601"
"22088","132.49200","28.44613","0.65792"
"22149","132.85800","28.47656","0.65948"
"22210","133.22400","28.50699","0.66336"
"22271","133.59000","28.53766","0.66592"
"22332","133.95600","28.56810","0.66989"
"22393","134.32200","28.59859","0.67652"
"22454","134.68800","28.62908","0.68002"
"22515","135.05400","28.65957","0.68561"
"22576","135.42000","28.69007","0.69324"
"22637","135.78600","28.72062","0.69732"
"22698","136.15200","28.75111","0.70574"
"22759","136.51800","28.78160","0.71102"
"22820","136.88400","28.81216","0.71524"
"22881","137.25000","28.84259","0.72253"
"22942","137.61600","28.87309","0.72811"
"23003","137.98200","28.90358","0.73550"
"23064","138.34800","28.93407","0.74179"
"23125","138.71400","28.96456","0.74546"
"23186","139.08000","28.99505","0.75078"
"23247","139.44600","29.02567","0.75471"
"23308","139.81200","29.05610","0.32579"
"23369","140.17800","29.08653","0.33114"
"23430","140.54400","29.11708","0.33572"
"23491","140.91000","29.14758","0.34280"
"23552","141.27600","29.17807","0.34740"
"23613","141.64200","29.20862","0.34851"
"23674","142.00800","29.23906","0.35017"
"23735","142.37400","29.26955","0.35060"
"23796","142.74000","29.30010","0.35077"
"23857","143.10600","29.33059","0.35118"
"23918","143.47200","29.36108","0.35149"
"23979","143.83800","29.39164","0.35146"
"24040","144.20400","29.42219","0.35265"
"24101","144.57000","29.45250","0.35428"
"24162","144.93600","29.48306","0.35696"
"24223","145.30200","29.51361","0.36073"
"24284","145.66800","29.54404","0.36337"
"24345","146.03400","29.57459","0.23783"
"24406","146.40000","29.60509","0.19451"
"24467","146.76600","29.63558","0.19090"
"24528","147.13200","29.66607","0.18960"
"24589","147.49800","29.69663","0.19112"
"24650","147.86400","29.72706","0.19486"
"24711","148.23000","29.75761","0.19880"
"24772","148.59600","29.78810","0.20047"
"24833","148.96200","29.81859","0.20108"
"24894","149.32800","29.84909","0.20121"
"24955","149.69400","29.87964","0.20190"
"25016","150.06000","29.91007","0.20203"
"25077","150.42600","29.94057","0.20223"
"25138","150.79200","29.97112","0.20252"
"25199","151.15800","30.00161","0.20294"
"25260","151.52400","30.03211","0.20317"
"25321","151.89000","30.06254","0.20390"
"25382","152.25600","30.09303","0.20441"
"25443","152.62200","30.12352","0.20489"
"25504","152.98800","30.15407","0.20627"
"25565","153.35400","30.18457","0.20790"
"25626","153.72000","30.21506","0.20921"
"25687","154.08600","30.24555","0.21073"
"25748","154.45200","30.27605","0.21239"
"25809","154.81800","30.30660","0.21455"
"25870","155.18400","30.33709","0.21623"
"25931","155.55000","30.36758","0.21763"
"25992","155.91600","30.39808","0.21953"
"26053","156.28200","30.42857","0.22125"
"26114","156.64800","30.45912","0.22246"
"26175","157.01400","30.48961","0.22312"
"26236","157.38000","30.52005","0.22341"
"26297","157.74600","30.55060","0.22478"
"26358","158.11200","30.58109","0.22513"
"26419","158.47800","30.61153","0.22578"
"26480","158.84400","30.64214","0.22743"
"26541","159.21000","30.67257","0.00642"
"26602","159.57600","30.70306","0.04904"
"26663","159.94200","30.73355","0.04975"
"26724","160.30800","30.76411","0.04080"
"26785","160.67400","30.79454","0.05074"
"26846","161.04000","30.82509","0.04352"
"26907","161.40600","30.85565","0.04150"
"26968","161.77200","30.88602","0.04831"
"27029","162.13800","30.91663","0.04410"
"27090","162.50400","30.94707","0.04137"
"27151","162.87000","30.97750","0.04799"
"27212","163.23600","31.00811","0.04516"
"27273","163.60200","31.03860","0.04371"
"27334","163.96800","31.06903","0.04737"
"27395","164.33400","31.09959","0.04686"
"27456","164.70000","31.13008","0.04506"
"27517","165.06600","31.16051","0.04800"
"27578","165.43200","31.19113","0.04824"
"27639","165.79800","31.22162","0.04719"
"27700","166.16400","31.25205","0.04842"
"27761","166.53000","31.28254","0.04928"
"27822","166.89600","31.31309","0.04835"
"27883","167.26200","31.34359","0.04987"
"27944","167.62800","31.37402","0.04989"
"28005","167.99400","31.40463","0.05023"
"28066","168.36000","31.43513","0.04984"
"28127","168.72600","31.46562","0.05111"
"28188","169.09200","31.49611","0.05056"
"28249","169.45800","31.52654","0.05097"
"28310","169.82400","31.55704","0.05139"
"28371","170.19000","31.58759","0.05163"
"28432","170.55600","31.61808","0.05198"
"28493","170.92200","31.64857","0.05180"
"28554","171.28800","31.67912","0.05243"
"28615","171.65400","31.70962","0.05233"
"28676","172.02000","31.74005","0.05236"
"28737","172.38600","31.77060","0.05284"
"28798","172.75200","31.80110","0.05271"
"28859","173.11800","31.83153","0.05287"
"28920","173.48400","31.86208","0.05309"
"28981","173.85000","31.89257","0.05305"
"29042","174.21600","31.92301","0.05322"
"29103","174.58200","31.95356","0.05331"
"29164","174.94800","31.98411","0.05343"
"29225","175.31400","32.01455","0.05341"
"29286","175.68000","32.04504","0.05341"
"29347","176.04600","32.07559","0.05363"
"29408","176.41200","32.10608","0.05369"
"29469","176.77800","32.13657","0.05371"
"29530","177.14400","32.16713","0.05380"
"29591","177.51000","32.19756","0.05400"
"29652","177.87600","32.22805","0.05402"
"29713","178.24200","32.25860","0.05419"
"29774","178.60800","32.28910","0.05424"
"29835","178.97400","32.31953","0.05434"
"29896","179.34000","32.35014","0.05448"
"29957","179.70600","32.38058","0.05456"
"30018","180.07200","32.41101","0.05498"
"30079","180.43800","32.44162","0.05516"
"30140","180.80400","32.47218","0.05550"
"30201","181.17000","32.50249","0.05588"
"30262","181.53600","32.53310","0.05611"
"30323","181.90200","32.56359","0.05671"
"30384","182.26800","32.59402","0.05699"
"30445","182.63400","32.62464","0.05786"
"30506","183.00000","32.65507","0.05817"
"30567","183.36600","32.68556","0.05890"
"30628","183.73200","32.71605","0.05942"
"30689","184.09800","32.74655","0.06018"
"30750","184.46400","32.77704","0.06131"
"30811","184.83000","32.80759","0.06231"
"30872","185.19600","32.83809","0.06261"
"30933","185.56200","32.86858","0.06397"
"30994","185.92800","32.89907","0.06382"
"31055","186.29400","32.92956","0.06427"
"31116","186.66000","32.96012","0.06586"
"31177","187.02600","32.99055","0.06640"
"31238","187.39200","33.02110","0.06724"
"31299","187.75800","33.05159","0.06847"
"31360","188.12400","33.08209","0.06901"
"31421","188.49000","33.11258","0.06760"
"31482","188.85600","33.14307","0.06863"
"31543","189.22200","33.17350","0.06907"
"31604","189.58800","33.20406","0.07029"
"31665","189.95400","33.23467","0.07123"
"31726","190.32000","33.26498","0.07330"
"31787","190.68600","33.29559","0.07412"
"31848","191.05200","33.32608","0.07550"
"31909","191.41800","33.35658","0.07687"
"31970","191.78400","33.38701","0.07829"
"32031","192.15000","33.41762","0.07936"
"32092","192.51600","33.44806","0.08045"
"32153","192.88200","33.47861","0.08146"
"32214","193.24800","33.50910","0.08242"
"32275","193.61400","33.53960","0.08370"
"32336","193.98000","33.57009","0.08482"
"32397","194.34600","33.60058","0.08570"
"32458","194.71200","33.63113","0.08682"
"32519","195.07800","33.66157","0.08771"
"32580","195.44400","33.69212","0.08870"
"32641","195.81000","33.72255","0.08945"
"32702","196.17600","33.75304","0.09050"
"32763","196.54200","33.78360","0.09117"
"32824","196.90800","33.81409","0.09268"
"32885","197.27400","33.84452","0.09358"
"32946","197.64000","33.87513","0.09476"
"33007","198.00600","33.90569","0.09571"
"33068","198.37200","33.93600","0.09610"
"33129","198.73800","33.96661","0.09656"
"33190","199.10400","33.99710","0.09612"
"33251","199.47000","34.02748","0.09570"
"33312","199.83600","34.05809","0.09461"
"33373","200.20200","34.08864","0.09175"
"33434","200.56800","34.11908","0.09078"
"33495","200.93400","34.14957","0.09033"
"33556","201.30000","34.18012","0.09145"
"33617","201.66600","34.21056","0.09084"
"33678","202.03200","34.24105","0.09109"
"33739","202.39800","34.27160","0.08347"
"33800","202.76400","34.30209","0.08306"
"33861","203.13000","34.33258","0.08417"
"33922","203.49600","34.36308","0.08451"
"33983","203.86200","34.39357","0.08590"
"34044","204.22800","34.42406","0.08700"
"34105","204.59400","34.45456","0.08805"
"34166","204.96000","34.48505","0.08918"
"34227","205.32600","34.51560","0.09020"
"34288","205.69200","34.54609","0.09114"
"34349","206.05800","34.57659","0.09253"
"34410","206.42400","34.60702","0.09432"
"34471","206.79000","34.63757","0.09558"
"34532","207.15600","34.66813","0.09700"
"34593","207.52200","34.69850","0.09815"
"34654","207.88800","34.72911","0.10001"
"34715","208.25400","34.75966","0.10202"
"34776","208.62000","34.79010","0.10325"
"34837","208.98600","34.82053","0.10534"
"34898","209.35200","34.85108","0.10765"
"34959","209.71800","34.88151","0.10895"
"35020","210.08400","34.91206","0.11091"
"35081","210.45000","34.94262","0.11255"
"35142","210.81600","34.97305","0.11464"
"35203","211.18200","35.00354","0.11711"
"35264","211.54800","35.03403","0.11853"
"35325","211.91400","35.06459","0.12049"
"35386","212.28000","35.09508","0.12166"
"35447","212.64600","35.12557","0.12382"
"35508","213.01200","35.15607","0.12493"
"35569","213.37800","35.18656","0.12636"
"35630","213.74400","35.21711","0.12834"
"35691","214.11000","35.24760","0.12969"
"35752","214.47600","35.27804","0.13087"
"35813","214.84200","35.30859","0.13116"
"35874","215.20800","35.33914","0.13266"
"35935","215.57400","35.36951","0.13373"
"35996","215.94000","35.40013","0.13511"
"36057","216.30600","35.43062","0.13593"
"36118","216.67200","35.46099","0.13693"
"36179","217.03800","35.49160","0.13782"
"36240","217.40400","35.52209","0.13828"
"36301","217.77000","35.55253","0.13888"
"36362","218.13600","35.58308","0.13950"
"36423","218.50200","35.61363","0.13988"
"36484","218.86800","35.64401","0.14031"
"36545","219.23400","35.67462","0.14075"
"36606","219.60000","35.70505","0.14095"
"36667","219.96600","35.73561","0.14164"
"36728","220.33200","35.76604","0.14184"
"36789","220.69800","35.79659","0.14220"
"36850","221.06400","35.82708","0.14304"
"36911","221.43000","35.85758","0.14321"
"36972","221.79600","35.88807","0.14380"
"37033","222.16200","35.91856","0.14439"
"37094","222.52800","35.94905","0.14538"
"37155","222.89400","35.97961","0.14645"
"37216","223.26000","36.01010","0.14688"
"37277","223.62600","36.04053","0.14808"
"37338","223.99200","36.07108","0.14926"
"37399","224.35800","36.10158","0.14988"
"37460","224.72400","36.13201","0.15058"
"37521","225.09000","36.16262","0.15115"
"37582","225.45600","36.19312","0.15197"
"37643","225.82200","36.22355","0.15316"
"37704","226.18800","36.25404","0.15453"
"37765","226.55400","36.28459","0.15521"
"37826","226.92000","36.31503","0.15570"
"37887","227.28600","36.34558","0.15716"
"37948","227.65200","36.37607","0.15770"
"38009","228.01800","36.40657","0.15878"
"38070","228.38400","36.43706","0.16016"
"38131","228.75000","36.46761","0.16150"
"38192","229.11600","36.49804","0.16336"
"38253","229.48200","36.52859","0.16447"
"38314","229.84800","36.55915","0.16520"
"38375","230.21400","36.58958","0.16625"
"38436","230.58000","36.62007","0.16793"
"38497","230.94600","36.65062","0.16886"
"38558","231.31200","36.68112","0.17050"
"38619","231.67800","36.71155","0.17119"
"38680","232.04400","36.74204","0.17217"
"38741","232.41000","36.77259","0.17374"
"38802","232.77600","36.80309","0.17459"
"38863","233.14200","36.83358","0.17566"
"38924","233.50800","36.86407","0.17659"
"38985","233.87400","36.89457","0.17714"
"39046","234.24000","36.92512","0.17798"
"39107","234.60600","36.95561","0.17867"
"39168","234.97200","36.98598","0.17963"
"39229","235.33800","37.01660","0.18142"
"39290","235.70400","37.04709","0.18227"
"39351","236.07000","37.07758","0.18315"
"39412","236.43600","37.10814","0.18496"
"39473","236.80200","37.13857","0.18625"
"39534","237.16800","37.16906","0.18707"
"39595","237.53400","37.19955","0.18811"
"39656","237.90000","37.23010","0.18890"
"39717","238.26600","37.26054","0.19021"
"39778","238.63200","37.29109","0.19119"
"39839","238.99800","37.32158","0.19225"
"39900","239.36400","37.35208","0.19236"
"39961","239.73000","37.38257","0.19377"
"40022","240.09600","37.41306","0.19404"
"40083","240.46200","37.44361","0.19581"
"40144","240.82800","37.47405","0.19669"
"40205","241.19400","37.50460","0.19790"
"40266","241.56000","37.53509","0.19807"
"40327","241.92600","37.56553","0.19908"
"40388","242.29200","37.59614","0.19965"
"40449","242.65800","37.62663","0.20027"
"40510","243.02400","37.65706","0.20119"
"40571","243.39000","37.68761","0.20129"
"40632","243.75600","37.71811","0.20159"
"40693","244.12200","37.74860","0.20184"
"40754","244.48800","37.77909","0.03185"
"40815","244.85400","37.80959","0.01587"
"40876","245.22000","37.84008","0.01681"
"40937","245.58600","37.87057","0.01224"
"40998","245.95200","37.90112","0.01791"
"41059","246.31800","37.93156","0.02590"
"41120","246.68400","37.96205","0.01329"
"41181","247.05000","37.99260","0.01741"
"41242","247.41600","38.02304","0.02114"
"41303","247.78200","38.05359","0.01532"
"41364","248.14800","38.08408","0.01711"
"41425","248.51400","38.11457","0.02454"
"41486","248.88000","38.14507","0.01577"
"41547","249.24600","38.17562","0.01594"
"41608","249.61200","38.20605","0.02452"
"41669","249.97800","38.23660","0.01350"
"41730","250.34400","38.26709","0.02044"
"41791","250.71000","38.29758","0.02100"
"41852","251.07600","38.32802","0.01512"
"41913","251.44200","38.35863","0.01755"
"41974","251.80800","38.38913","0.02320"
"42035","252.17400","38.41950","0.01595"
"42096","252.54000","38.45011","0.01787"
"42157","252.90600","38.48054","0.02312"
"42218","253.27200","38.51110","0.01525"
"42279","253.63800","38.54165","0.01936"
"42340","254.00400","38.57208","0.02298"
"42401","254.37000","38.60258","0.01606"
"42462","254.73600","38.63307","0.01989"
"42523","255.10200","38.66362","0.02187"
"42584","255.46800","38.69405","0.01769"
"42645","255.83400","38.72461","0.01928"
"42706","256.20000","38.75504","0.02101"
"42767","256.56600","38.78559","0.01760"
"42828","256.93200","38.81602","0.02001"
"42889","257.29800","38.84657","0.02130"
"42950","257.66400","38.87707","0.01865"
"43011","258.03000","38.90756","0.02042"
"43072","258.39600","38.93811","0.02098"
"43133","258.76200","38.96854","0.01937"
"43194","259.12800","38.99910","0.02031"
"43255","259.49400","39.02959","0.02043"
"43316","259.86000","39.06008","0.02051"
"43377","260.22600","39.09052","0.02064"
"43438","260.59200","39.12113","0.02100"
"43499","260.95800","39.15156","0.02079"
"43560","261.32400","39.18205","0.02054"
"43621","261.69000","39.21267","0.02098"
"43682","262.05600","39.24310","0.02021"
"43743","262.42200","39.27353","0.02086"
"43804","262.78800","39.30408","0.02155"
"43865","263.15400","39.33464","0.02100"
"43926","263.52000","39.36501","0.02118"
"43987","263.88600","39.39557","0.02155"
"44048","264.25200","39.42611","0.02204"
"44109","264.61800","39.45655","0.02080"
"44170","264.98400","39.48704","0.02215"
"44231","265.35000","39.51759","0.02161"
"44292","265.71600","39.54809","0.02165"
"44353","266.08200","39.57858","0.02227"
"44414","266.44800","39.60913","0.02274"
"44475","266.81400","39.63963","0.02278"
"44536","267.18000","39.67006","0.02211"
"44597","267.54600","39.70061","0.02273"
"44658","267.91200","39.73110","0.02221"
"44719","268.27800","39.76154","0.02277"
"44780","268.64400","39.79208","0.02263"
"44841","269.01000","39.82257","0.02289"
"44902","269.37600","39.85307","0.02261"
"44963","269.74200","39.88363","0.02384"
"45024","270.10800","39.91412","0.02370"
"45085","270.47400","39.94455","0.02359"
"45146","270.84000","39.97510","0.02402"
"45207","271.20600","40.00560","0.02375"
"45268","271.57200","40.03597","0.02352"
"45329","271.93800","40.06658","0.02391"
"45390","272.30400","40.09713","0.02375"
"45451","272.67000","40.12756","0.02458"
"45512","273.03600","40.15805","0.02437"
"45573","273.40200","40.18861","0.02534"
"45634","273.76800","40.21904","0.02529"
"45695","274.13400","40.24953","0.02468"
"45756","274.50000","40.28009","0.02442"
"45817","274.86600","40.31058","0.02574"
"45878","275.23200","40.34108","0.02546"
"45939","275.59800","40.37163","0.02519"
"46000","275.96400","40.40212","0.02537"
"46061","276.33000","40.43255","0.02585"
"46122","276.69600","40.46310","0.02577"
"46183","277.06200","40.49359","0.02617"
"46244","277.42800","40.52403","0.02645"
"46305","277.79400","40.55458","0.02617"
"46366","278.16000","40.58507","0.02627"
"46427","278.52600","40.61557","0.02729"
"46488","278.89200","40.64606","0.02772"
"46549","279.25800","40.67661","0.02673"
"46610","279.62400","40.70705","0.02652"
"46671","279.99000","40.73760","0.02756"
"46732","280.35600","40.76815","0.02759"
"46793","280.72200","40.79853","0.02769"
"46854","281.08800","40.82907","0.02804"
"46915","281.45400","40.85957","0.02788"
"46976","281.82000","40.89006","0.02812"
"47037","282.18600","40.92056","0.02835"
"47098","282.55200","40.95111","0.02848"
"47159","282.91800","40.98160","0.02941"
"47220","283.28400","41.01204","0.02956"
"47281","283.65000","41.04264","0.02866"
"47342","284.01600","41.07308","0.02924"
"47403","284.38200","41.10357","0.02954"
"47464","284.74800","41.13412","0.02970"
"47525","285.11400","41.16461","0.02970"
"47586","285.48000","41.19505","0.02950"
"47647","285.84600","41.22560","0.03021"
"47708","286.21200","41.25603","0.03033"
"47769","286.57800","41.28653","0.03056"
"47830","286.94400","41.31714","0.03015"
"47891","287.31000","41.34757","0.03158"
"47952","287.67600","41.37807","0.03086"
"48013","288.04200","41.40862","0.03083"
"48074","288.40800","41.43905","0.03097"
"48135","288.77400","41.46949","0.03118"
"48196","289.14000","41.50009","0.03121"
"48257","289.50600","41.53065","0.03164"
"48318","289.87200","41.56108","0.03189"
"48379","290.23800","41.59157","0.03210"
"48440","290.60400","41.62207","0.03203"
"48501","290.97000","41.65255","0.03186"
"48562","291.33600","41.68305","0.03284"
"48623","291.70200","41.71360","0.03238"
"48684","292.06800","41.74403","0.03277"
"48745","292.43400","41.77459","0.03298"
"48806","292.80000","41.80508","0.03269"
"48867","293.16600","41.83557","0.03324"
"48928","293.53200","41.86607","0.03348"
"48989","293.89800","41.89662","0.03308"
"49050","294.26400","41.92705","0.03325"
"49111","294.63000","41.95754","0.03318"
"49172","294.99600","41.98816","0.03329"
"49233","295.36200","42.01852","0.03355"
"49294","295.72800","42.04902","0.03320"
"49355","296.09400","42.07964","0.03355"
"49416","296.46000","42.11007","0.03404"
"49477","296.82600","42.14050","0.03370"
"49538","297.19200","42.17111","0.03449"
"49599","297.55800","42.20160","0.03411"
"49660","297.92400","42.23204","0.03500"
"49721","298.29000","42.26259","0.03560"
"49782","298.65600","42.29308","0.03591"
"49843","299.02200","42.32351","0.03565"
"49904","299.38800","42.35407","0.03571"
"49965","299.75400","42.38462","0.03585"
"50026","300.12000","42.41505","0.03626"
"50087","300.48600","42.44561","0.03642"
"50148","300.85200","42.47610","0.03650"
"50209","301.21800","42.50659","0.03715"
"50270","301.58400","42.53708","0.03769"
"50331","301.95000","42.56757","0.03748"
"50392","302.31600","42.59813","0.03772"
"50453","302.68200","42.62856","0.03797"
"50514","303.04800","42.65911","0.03816"
"50575","303.41400","42.68955","0.03848"
"50636","303.78000","42.71998","0.03832"
"50697","304.14600","42.75060","0.03841"
"50758","304.51200","42.78102","0.03953"
"50819","304.87800","42.81158","0.03967"
"50880","305.24400","42.84213","0.03929"
"50941","305.61000","42.87256","0.03988"
"51002","305.97600","42.90300","0.03964"
"51063","306.34200","42.93361","0.03992"
"51124","306.70800","42.96404","0.04036"
"51185","307.07400","42.99454","0.03985"
"51246","307.44000","43.02509","0.04061"
"51307","307.80600","43.05558","0.04052"
"51368","308.17200","43.08601","0.04099"
"51429","308.53800","43.11657","0.04118"
"51490","308.90400","43.14712","0.04155"
"51551","309.27000","43.17755","0.04182"
"51612","309.63600","43.20810","0.04172"
"51673","310.00200","43.23854","0.04214"
"51734","310.36800","43.26908","0.04217"
"51795","310.73400","43.29958","0.04236"
"51856","311.10000","43.33007","0.04286"
"51917","311.46600","43.36056","0.04327"
"51978","311.83200","43.39106","0.04351"
"52039","312.19800","43.42161","0.04356"
"52100","312.56400","43.45204","0.04404"
"52161","312.93000","43.48254","0.04458"
"52222","313.29600","43.51309","0.04470"
"52283","313.66200","43.54358","0.04490"
"52344","314.02800","43.57407","0.04545"
"52405","314.39400","43.60463","0.04537"
"52466","314.76000","43.63506","0.04559"
"52527","315.12600","43.66555","0.04592"
"52588","315.49200","43.69611","0.04630"
"52649","315.85800","43.72660","0.04615"
"52710","316.22400","43.75709","0.04622"
"52771","316.59000","43.78758","0.04657"
"52832","316.95600","43.81813","0.04674"
"52893","317.32200","43.84857","0.04710"
"52954","317.68800","43.87912","0.04669"
"53015","318.05400","43.90955","0.04717"
"53076","318.42000","43.94004","0.04730"
"53137","318.78600","43.97054","0.04750"
"53198","319.15200","44.00109","0.04741"
"53259","319.51800","44.03158","0.04808"
"53320","319.88400","44.06208","0.04804"
"53381","320.25000","44.09263","0.04809"
"53442","320.61600","44.12306","0.04842"
"53503","320.98200","44.15356","0.04858"
"53564","321.34800","44.18411","0.04859"
"53625","321.71400","44.21460","0.04878"
"53686","322.08000","44.24509","0.04887"
"53747","322.44600","44.27558","0.04896"
"53808","322.81200","44.30607","0.04918"
"53869","323.17800","44.33651","0.04951"
"53930","323.54400","44.36712","0.04980"
"53991","323.91000","44.39756","0.05010"
"54052","324.27600","44.42805","0.05011"
"54113","324.64200","44.45854","0.05028"
"54174","325.00800","44.48915","0.05044"
"54235","325.37400","44.51952","0.05067"
"54296","325.74000","44.55008","0.05074"
"54357","326.10600","44.58057","0.05067"
"54418","326.47200","44.61106","0.05101"
"54479","326.83800","44.64161","0.05133"
"54540","327.20400","44.67211","0.05119"
"54601","327.57000","44.70254","0.05131"
"54662","327.93600","44.73303","0.05125"
"54723","328.30200","44.76365","0.05155"
"54784","328.66800","44.79401","0.05175"
"54845","329.03400","44.82463","0.05170"
"54906","329.40000","44.85513","0.05214"
"54967","329.76600","44.88556","0.05185"
"55028","330.13200","44.91605","0.05214"
"55089","330.49800","44.94660","0.05221"
"55150","330.86400","44.97709","0.05216"
"55211","331.23000","45.00753","0.05216"
"55272","331.59600","45.03808","0.05195"
"55333","331.96200","45.06857","0.05162"
"55394","332.32800","45.09907","0.05149"
"55455","332.69400","45.12956","0.05170"
"55516","333.06000","45.16011","0.05184"
"55577","333.42600","45.19054","0.05150"
"55638","333.79200","45.22110","0.05179"
"55699","334.15800","45.25159","0.05186"
"55760","334.52400","45.28202","0.05173"
"55821","334.89000","45.31264","0.05122"
"55882","335.25600","45.34306","0.05124"
"55943","335.62200","45.37355","0.05083"
"56004","335.98800","45.40405","0.04982"
"56065","336.35400","45.43460","0.04993"
"56126","336.72000","45.46504","0.05002"
"56187","337.08600","45.49559","0.05000"
"56248","337.45200","45.52608","0.04996"
"56309","337.81800","45.55658","0.05000"
"56370","338.18400","45.58713","0.05071"
"56431","338.55000","45.61762","0.05065"
"56492","338.91600","45.64805","0.05080"
"56553","339.28200","45.67854","0.05107"
"56614","339.64800","45.70916","0.05110"
"56675","340.01400","45.73959","0.05133"
"56736","340.38000","45.77003","0.05127"
"56797","340.74600","45.80058","0.05163"
"56858","341.11200","45.83107","0.05143"
"56919","341.47800","45.86156","0.05167"
"56980","341.84400","45.89206","0.05188"
"57041","342.21000","45.92261","0.05205"
"57102","342.57600","45.95298","0.05201"
"57163","342.94200","45.98359","0.05235"
"57224","343.30800","46.01408","0.05229"
"57285","343.67400","46.04452","0.05216"
"57346","344.04000","46.07507","0.05252"
"57407","344.40600","46.10562","0.05264"
"57468","344.77200","46.13605","0.05259"
"57529","345.13800","46.16661","0.05285"
"57590","345.50400","46.19710","0.05291"
"57651","345.87000","46.22754","0.05286"
"57712","346.23600","46.25809","0.05317"
"57773","346.60200","46.28864","0.05321"
"57834","346.96800","46.31907","0.05332"
"57895","347.33400","46.34956","0.05338"
"57956","347.70000","46.38012","0.05349"
"58017","348.06600","46.41055","0.05355"
"58078","348.43200","46.44104","0.05354"
"58139","348.79800","46.47166","0.05365"
"58200","349.16400","46.50209","0.05369"
"58261","349.53000","46.53258","0.05373"
"58322","349.89600","46.56307","0.05376"
"58383","350.26200","46.59357","0.05390"
"58444","350.62800","46.62406","0.05384"
"58505","350.99400","46.65461","0.05392"
"58566","351.36000","46.68510","0.05409"
"58627","351.72600","46.71553","0.05407"
"58688","352.09200","46.74615","0.05421"
"58749","352.45800","46.77658","0.05431"
"58810","352.82400","46.80707","0.05443"
"58871","353.19000","46.83757","0.05446"
"58932","353.55600","46.86812","0.05488"
"58993","353.92200","46.89855","0.05476"
"59054","354.28800","46.92910","0.05485"
"59115","354.65400","46.95959","0.05488"
"59176","355.02000","46.99003","0.05545"
"59237","355.38600","47.02052","0.05576"
"59298","355.75200","47.05107","0.05583"
"59359","356.11800","47.08163","0.05585"
"59420","356.48400","47.11206","0.05639"
"59481","356.85000","47.14261","0.05655"
"59542","357.21600","47.17305","0.05682"
"59603","357.58200","47.20354","0.05747"
"59664","357.94800","47.23409","0.05778"
"59725","358.31400","47.26458","0.05826"
"59786","358.68000","47.29507","0.05850"
"59847","359.04600","47.32563","0.05899"
"59908","359.41200","47.35612","0.05923"
"59969","359.77800","47.38655","0.06012"
"60030","360.14400","47.41710","0.06022"
"60091","360.51000","47.44760","0.06039"
"60152","360.87600","47.47809","0.06064"
"60213","361.24200","47.50859","0.06123"
"60274","361.60800","47.53908","0.06156"
"60335","361.97400","47.56951","0.06196"
"60396","362.34000","47.60006","0.06228"
"60457","362.70600","47.63061","0.06197"
"60518","363.07200","47.66099","0.06202"
"60579","363.43800","47.69160","0.06245"
"60640","363.80400","47.72209","0.06267"
"60701","364.17000","47.75258","0.06365"
"60762","364.53600","47.78302","0.06362"
"60823","364.90200","47.81363","0.06513"
"60884","365.26800","47.84406","0.06554"
"60945","365.63400","47.87456","0.06583"
"61006","366.00000","47.90505","0.06735"
"61067","366.36600","47.93560","0.06731"
"61128","366.73200","47.96609","0.06796"
"61189","367.09800","47.99659","0.06884"
"61250","367.46400","48.02708","0.06996"
"61311","367.83000","48.05757","0.07076"
"61372","368.19600","48.08813","0.07155"
"61433","368.56200","48.11855","0.07314"
"61494","368.92800","48.14904","0.07368"
"61555","369.29400","48.17955","0.07369"
"61616","369.66000","48.21009","0.07401"
"61677","370.02600","48.24053","0.07426"
"61738","370.39200","48.27108","0.07377"
"61799","370.75800","48.30163","0.07439"
"61860","371.12400","48.33200","0.07443"
"61921","371.49000","48.36256","0.07576"
"61982","371.85600","48.39305","0.07706"
"62043","372.22200","48.42360","0.07734"
"62104","372.58800","48.45404","0.07809"
"62165","372.95400","48.48458","0.07912"
"62226","373.32000","48.51508","0.08005"
"62287","373.68600","48.54558","0.08109"
"62348","374.05200","48.57607","0.08186"
"62409","374.41800","48.60656","0.08257"
"62470","374.78400","48.63711","0.08335"
"62531","375.15000","48.66760","0.08375"
"62592","375.51600","48.69804","0.08504"
"62653","375.88200","48.72853","0.08475"
"62714","376.24800","48.75908","0.08539"
"62775","376.61400","48.78963","0.08573"
"62836","376.98000","48.82000","0.08680"
"62897","377.34600","48.85062","0.08750"
"62958","377.71200","48.88105","0.08865"
"63019","378.07800","48.91154","0.08922"
"63080","378.44400","48.94210","0.08987"
"63141","378.81000","48.97259","0.09068"
"63202","379.17600","49.00303","0.09103"
"63263","379.54200","49.03363","0.09222"
"63324","379.90800","49.06407","0.09297"
"63385","380.27400","49.09450","0.09391"
"63446","380.64000","49.12511","0.09546"
"63507","381.00600","49.15561","0.09658"
"63568","381.37200","49.18604","0.09661"
"63629","381.73800","49.21659","0.09819"
"63690","382.10400","49.24715","0.10044"
"63751","382.47000","49.27752","0.10197"
"63812","382.83600","49.30807","0.10397"
"63873","383.20200","49.33857","0.10553"
"63934","383.56800","49.36906","0.10774"
"63995","383.93400","49.39961","0.10902"
"64056","384.30000","49.43004","0.11052"
"64117","384.66600","49.46059","0.11123"
"64178","385.03200","49.49102","0.11379"
"64239","385.39800","49.52164","0.01413"
"64300","385.76400","49.55207","0.01231"
"64361","386.13000","49.58256","0.01200"
"64422","386.49600","49.61312","0.01116"
"64483","386.86200","49.64361","0.01151"
"64544","387.22800","49.67404","0.01297"
"64605","387.59400","49.70459","0.01161"
"64666","387.96000","49.73508","0.01041"
"64727","388.32600","49.76552","0.01197"
"64788","388.69200","49.79613","0.01186"
"64849","389.05800","49.82662","0.01070"
"64910","389.42400","49.85706","0.01035"
"64971","389.79000","49.88755","0.01203"
"65032","390.15600","49.91810","0.01206"
"65093","390.52200","49.94854","0.01016"
"65154","390.88800","49.97909","0.01156"
"65215","391.25400","50.00958","0.01129"
"65276","391.62000","50.04007","0.01216"
"65337","391.98600","50.07056","0.01049"
"65398","392.35200","50.10106","0.01139"
"65459","392.71800","50.13155","0.01162"
"65520","393.08400","50.16204","0.01078"
"65581","393.45000","50.19260","0.01060"
"65642","393.81600","50.22309","0.01155"
"65703","394.18200","50.25352","0.01147"
"65764","394.54800","50.28408","0.01047"
"65825","394.91400","50.31457","0.01243"
"65886","395.28000","50.34506","0.01120"
"65947","395.64600","50.37561","0.01186"
"66008","396.01200","50.40616","0.00979"
"66069","396.37800","50.43654","0.01193"
"66130","396.74400","50.46715","0.01112"
"66191","397.11000","50.49758","0.01067"
"66252","397.47600","50.52801","0.01132"
"66313","397.84200","50.55863","0.01188"
"66374","398.20800","50.58912","0.01244"
"66435","398.57400","50.61949","0.01071"
"66496","398.94000","50.65011","0.01221"
"66557","399.30600","50.68060","0.01140"
"66618","399.67200","50.71109","0.01089"
"66679","400.03800","50.74164","0.01092"
"66740","400.40400","50.77208","0.01137"
"66801","400.77000","50.80257","0.01126"
"66862","401.13600","50.83306","0.01111"
"66923","401.50200","50.86362","0.01085"
"66984","401.86800","50.89404","0.01219"
"67045","402.23400","50.92460","0.01184"
"67106","402.60000","50.95509","0.01075"
"67167","402.96600","50.98552","0.01095"
"67228","403.33200","51.01608","0.01215"
"67289","403.69800","51.04663","0.01110"
"67350","404.06400","51.07712","0.01029"
"67411","404.43000","51.10756","0.01225"
"67472","404.79600","51.13811","0.01135"
"67533","405.16200","51.16860","0.01098"
"67594","405.52800","51.19897","0.01069"
"67655","405.89400","51.22959","0.01189"
"67716","406.26000","51.26014","0.01081"
"67777","406.62600","51.29057","0.01043"
"67838","406.99200","51.32107","0.01097"
"67899","407.35800","51.35162","0.01165"
"67960","407.72400","51.38199","0.01128"
"68021","408.09000","51.41266","0.01019"
"68082","408.45600","51.44309","0.01265"
"68143","408.82200","51.47358","0.01156"
"68204","409.18800","51.50408","0.01046"
"68265","409.55400","51.53463","0.01140"
"68326","409.92000","51.56506","0.01206"
"68387","410.28600","51.59555","0.01193"
"68448","410.65200","51.62617","0.01045"
"68509","411.01800","51.65654","0.01171"
"68570","411.38400","51.68703","0.01191"
"68631","411.75000","51.71759","0.01155"
"68692","412.11600","51.74808","0.01091"
"68753","412.48200","51.77851","0.01186"
"68814","412.84800","51.80919","0.01148"
"68875","413.21400","51.83961","0.01017"
"68936","413.58000","51.86999","0.01067"
"68997","413.94600","51.90060","0.01103"
"69058","414.31200","51.93110","0.01136"
"69119","414.67800","51.96152","0.01050"
"69180","415.04400","51.99208","0.01146"
"69241","415.41000","52.02258","0.01208"
"69302","415.77600","52.05301","0.01039"
"69363","416.14200","52.08362","0.01059"
"69424","416.50800","52.11411","0.01153"
"69485","416.87400","52.14455","0.01140"
"69546","417.24000","52.17510","0.00962"
"69607","417.60600","52.20553","0.01155"
"69668","417.97200","52.23608","0.01157"
"69729","418.33800","52.26657","0.01086"
"69790","418.70400","52.29713","0.01060"
"69851","419.07000","52.32756","0.01108"
"69912","419.43600","52.35811","0.01153"
"69973","419.80200","52.38855","0.01029"
"70034","420.16800","52.41904","0.01122"
"70095","420.53400","52.44953","0.01155"
"70156","420.90000","52.48008","0.01155"
"70217","421.26600","52.51064","0.01019"
"70278","421.63200","52.54107","0.01150"
"70339","421.99800","52.57162","0.01157"
"70400","422.36400","52.60205","0.01118"
"70461","422.73000","52.63255","0.01035"
"70522","423.09600","52.66310","0.01107"
"70583","423.46200","52.69365","0.01157"
"70644","423.82800","52.72403","0.01071"
"70705","424.19400","52.75458","0.01095"
"70766","424.56000","52.78513","0.01155"
"70827","424.92600","52.81551","0.01089"
"70888","425.29200","52.84612","0.01069"
"70949","425.65800","52.87655","0.01167"
"71010","426.02400","52.90710","0.01159"
"71071","426.39000","52.93760","0.01148"
"71132","426.75600","52.96803","0.01109"
"71193","427.12200","52.99852","0.01093"
"71254","427.48800","53.02907","0.01149"
"71315","427.85400","53.05963","0.01075"
"71376","428.22000","53.09006","0.01060"
"71437","428.58600","53.12055","0.01141"
"71498","428.95200","53.15110","0.01069"
"71559","429.31800","53.18159","0.01010"
"71620","429.68400","53.21203","0.01128"
"71681","430.05000","53.24264","0.01149"
"71742","430.41600","53.27313","0.01053"
"71803","430.78200","53.30350","0.01166"
"71864","431.14800","53.33412","0.01055"
"71925","431.51400","53.36461","0.01121"
"71986","431.88000","53.39504","0.01110"
"72047","432.24600","53.42560","0.01183"
"72108","432.61200","53.45615","0.01123"
"72169","432.97800","53.48646","0.01149"
"72230","433.34400","53.51713","0.01082"
"72291","433.71000","53.54757","0.01123"
"72352","434.07600","53.57806","0.01213"
"72413","434.44200","53.60861","0.00998"
"72474","434.80800","53.63904","0.01123"
"72535","435.17400","53.66953","0.01083"
"72596","435.54000","53.70009","0.01084"
"72657","435.90600","53.73064","0.01012"
"72718","436.27200","53.76108","0.01171"
"72779","436.63800","53.79163","0.01111"
"72840","437.00400","53.82206","0.01115"
"72901","437.37000","53.85255","0.01041"
"72962","437.73600","53.88305","0.01131"
"73023","438.10200","53.91360","0.01073"
"73084","438.46800","53.94409","0.01070"
"73145","438.83400","53.97452","0.01078"
"73206","439.20000","54.00508","0.01121"
"73267","439.56600","54.03557","0.01111"
"73328","439.93200","54.06606","0.01020"
"73389","440.29800","54.09662","0.01101"
"73450","440.66400","54.12711","0.01196"
"73511","441.03000","54.15754","0.01034"
"73572","441.39600","54.18809","0.01036"
"73633","441.76200","54.21858","0.01115"
"73694","442.12800","54.24902","0.01153"
"73755","442.49400","54.27963","0.01083"
"73816","442.86000","54.31006","0.01076"
"73877","443.22600","54.34055","0.01123"
"73938","443.59200","54.37111","0.01213"
"73943","443.61800","54.37326","0.01142"