File: Trajectories_together/161114Specimen_RawData_3.csv
"","V1","V2","V3"
"1","End date","11/14/2016",""
"2","Specimen label","20AG59",""
"3","Maximum Load","0.54546","N"
"4","Time","Extension","Load"
"5","(s)","(mm)","(N)"
"6","0.00000","0.00000","-0.00116"
"72","0.39600","0.03312","-0.00058"
"138","0.79200","0.06613","0.00060"
"204","1.18800","0.09925","0.00028"
"270","1.58400","0.13225","0.00008"
"336","1.98000","0.16514","0.00035"
"402","2.37600","0.19820","0.00090"
"468","2.77200","0.23115","0.00096"
"534","3.16800","0.26421","0.00078"
"600","3.56400","0.29715","0.00012"
"666","3.96000","0.33022","0.00038"
"732","4.35600","0.36322","0.00064"
"798","4.75200","0.39617","0.00049"
"864","5.14800","0.42911","0.00159"
"930","5.54400","0.46217","0.00145"
"996","5.94000","0.49518","0.00078"
"1062","6.33600","0.52812","0.00082"
"1128","6.73200","0.56112","0.00167"
"1194","7.12800","0.59413","0.00137"
"1260","7.52400","0.62713","0.00080"
"1326","7.92000","0.66014","0.00242"
"1392","8.31600","0.69320","0.00189"
"1458","8.71200","0.72614","0.00113"
"1524","9.10800","0.75909","0.00150"
"1590","9.50400","0.79215","0.00154"
"1656","9.90000","0.82522","0.00227"
"1722","10.29600","0.85816","0.00204"
"1788","10.69200","0.89116","0.00297"
"1854","11.08800","0.92411","0.00202"
"1920","11.48400","0.95723","0.00217"
"1986","11.88000","0.99017","0.00203"
"2052","12.27600","1.02312","0.00220"
"2118","12.67200","1.05618","0.00273"
"2184","13.06800","1.08919","0.00314"
"2250","13.46400","1.12213","0.00342"
"2316","13.86000","1.15513","0.00401"
"2382","14.25600","1.18814","0.00307"
"2448","14.65200","1.22120","0.00326"
"2514","15.04800","1.25415","0.00356"
"2580","15.44400","1.28709","0.00260"
"2646","15.84000","1.32015","0.00375"
"2712","16.23600","1.35322","0.00362"
"2778","16.63200","1.38616","0.00330"
"2844","17.02800","1.41916","0.00365"
"2910","17.42400","1.45217","0.00379"
"2976","17.82000","1.48517","0.00324"
"3042","18.21600","1.51812","0.00368"
"3108","18.61200","1.55112","0.00417"
"3174","19.00800","1.58418","0.00391"
"3240","19.40400","1.61719","0.00420"
"3306","19.80000","1.65007","0.00356"
"3372","20.19600","1.68308","0.00400"
"3438","20.59200","1.71620","0.00377"
"3504","20.98800","1.74920","0.00433"
"3570","21.38400","1.78209","0.00439"
"3636","21.78000","1.81515","0.00492"
"3702","22.17600","1.84815","0.00496"
"3768","22.57200","1.88116","0.00414"
"3834","22.96800","1.91416","0.00403"
"3900","23.36400","1.94717","0.00415"
"3966","23.76000","1.98017","0.00463"
"4032","24.15600","2.01317","0.00430"
"4098","24.55200","2.04618","0.00458"
"4164","24.94800","2.07918","0.00494"
"4230","25.34400","2.11213","0.00495"
"4296","25.74000","2.14513","0.00531"
"4362","26.13600","2.17813","0.00554"
"4428","26.53200","2.21120","0.00507"
"4494","26.92800","2.24420","0.00480"
"4560","27.32400","2.27714","0.00512"
"4626","27.72000","2.31015","0.00693"
"4692","28.11600","2.34315","0.00581"
"4758","28.51200","2.37616","0.00654"
"4824","28.90800","2.40910","0.00505"
"4890","29.30400","2.44222","0.00628"
"4956","29.70000","2.47517","0.00688"
"5022","30.09600","2.50811","0.00608"
"5088","30.49200","2.54112","0.00696"
"5154","30.88800","2.57418","0.00650"
"5220","31.28400","2.60718","0.00585"
"5286","31.68000","2.64013","0.00671"
"5352","32.07600","2.67313","0.00693"
"5418","32.47200","2.70619","0.00669"
"5484","32.86800","2.73920","0.00723"
"5550","33.26400","2.77208","0.00722"
"5616","33.66000","2.80515","0.00767"
"5682","34.05600","2.83821","0.00747"
"5748","34.45200","2.87115","0.00818"
"5814","34.84800","2.90410","0.00786"
"5880","35.24400","2.93710","0.00704"
"5946","35.64000","2.97016","0.00866"
"6012","36.03800","3.00335","0.00991"
"6078","36.43400","3.03623","0.00884"
"6144","36.83000","3.06930","0.00842"
"6210","37.22600","3.10230","0.00758"
"6276","37.62200","3.13536","0.00796"
"6342","38.01800","3.16831","0.00985"
"6408","38.41400","3.20131","0.01010"
"6474","38.81000","3.23437","0.00911"
"6540","39.20600","3.26726","0.00798"
"6606","39.60200","3.30032","0.01007"
"6672","39.99800","3.33339","0.00958"
"6738","40.39400","3.36633","0.01038"
"6804","40.79000","3.39927","0.00899"
"6870","41.18600","3.43228","0.00988"
"6936","41.58200","3.46528","0.01001"
"7002","41.97800","3.49835","0.01050"
"7068","42.37400","3.53129","0.01063"
"7134","42.77000","3.56435","0.00999"
"7200","43.16600","3.59736","0.01028"
"7266","43.56200","3.63030","0.01037"
"7332","43.95800","3.66331","0.01199"
"7398","44.35400","3.69637","0.01076"
"7464","44.75000","3.72931","0.01155"
"7530","45.14600","3.76232","0.01110"
"7596","45.54200","3.79526","0.01210"
"7662","45.93800","3.82838","0.01209"
"7728","46.33400","3.86133","0.01214"
"7794","46.73000","3.89427","0.01169"
"7860","47.12600","3.92734","0.01259"
"7926","47.52200","3.96034","0.01261"
"7992","47.91800","3.99334","0.01236"
"8058","48.31400","4.02629","0.01282"
"8124","48.71000","4.05935","0.01314"
"8190","49.10600","4.09235","0.01466"
"8256","49.50200","4.12530","0.01266"
"8322","49.89800","4.15824","0.01345"
"8388","50.29400","4.19137","0.01338"
"8454","50.69000","4.22431","0.01358"
"8520","51.08600","4.25731","0.01390"
"8586","51.48200","4.29026","0.01375"
"8652","51.87800","4.32332","0.01498"
"8718","52.27400","4.35638","0.01524"
"8784","52.67000","4.38933","0.01410"
"8850","53.06600","4.42227","0.01502"
"8916","53.46200","4.45534","0.01434"
"8982","53.85800","4.48840","0.01343"
"9048","54.25400","4.52128","0.01357"
"9114","54.65000","4.55429","0.01373"
"9180","55.04600","4.58735","0.01359"
"9246","55.44200","4.62036","0.01437"
"9312","55.83800","4.65336","0.01425"
"9378","56.23400","4.68630","0.01457"
"9444","56.63000","4.71931","0.01466"
"9510","57.02600","4.75231","0.01487"
"9576","57.42200","4.78532","0.01414"
"9642","57.81800","4.81838","0.01440"
"9708","58.21400","4.85126","0.01445"
"9774","58.61000","4.88433","0.01573"
"9840","59.00600","4.91733","0.01581"
"9906","59.40200","4.95033","0.01216"
"9972","59.79800","4.98334","0.01342"
"10038","60.19400","5.01628","0.01236"
"10104","60.59000","5.04929","0.01315"
"10170","60.98600","5.08235","0.01287"
"10236","61.38200","5.11535","0.01455"
"10302","61.77800","5.14830","0.01450"
"10368","62.17400","5.18136","0.01339"
"10434","62.57000","5.21436","0.01439"
"10500","62.96600","5.24731","0.01468"
"10566","63.36200","5.28031","0.01530"
"10632","63.75800","5.31332","0.01484"
"10698","64.15400","5.34638","0.01597"
"10764","64.55000","5.37926","0.01552"
"10830","64.94600","5.41227","0.01543"
"10896","65.34200","5.44539","0.01631"
"10962","65.73800","5.47840","0.01589"
"11028","66.13400","5.51128","0.01621"
"11094","66.53000","5.54428","0.01695"
"11160","66.92600","5.57735","0.01628"
"11226","67.32200","5.61029","0.01696"
"11292","67.71800","5.64330","0.01723"
"11358","68.11400","5.67630","0.01677"
"11424","68.51000","5.70936","0.01831"
"11490","68.90600","5.74237","0.01722"
"11556","69.30200","5.77525","0.01711"
"11622","69.69800","5.80831","0.01733"
"11688","70.09400","5.84132","0.01828"
"11754","70.49000","5.87438","0.01698"
"11820","70.88600","5.90727","0.01730"
"11886","71.28200","5.94033","0.01827"
"11952","71.67800","5.97333","0.01803"
"12018","72.07400","6.00640","0.01850"
"12084","72.47000","6.03928","0.01884"
"12150","72.86600","6.07234","0.01889"
"12216","73.26200","6.10535","0.01859"
"12282","73.65800","6.13829","0.01952"
"12348","74.05400","6.17136","0.02080"
"12414","74.45000","6.20436","0.02029"
"12480","74.84600","6.23736","0.02042"
"12546","75.24200","6.27031","0.01996"
"12612","75.63800","6.30331","0.02098"
"12678","76.03400","6.33632","0.02129"
"12744","76.43000","6.36932","0.02124"
"12810","76.82600","6.40226","0.02135"
"12876","77.22200","6.43539","0.02145"
"12942","77.61800","6.46833","0.02204"
"13008","78.01400","6.50127","0.02208"
"13074","78.41000","6.53434","0.02189"
"13140","78.80600","6.56734","0.02295"
"13206","79.20200","6.60029","0.02295"
"13272","79.59800","6.63335","0.02244"
"13338","79.99400","6.66623","0.02350"
"13404","80.39000","6.69936","0.02371"
"13470","80.78600","6.73236","0.02410"
"13536","81.18200","6.76525","0.02414"
"13602","81.57800","6.79831","0.02482"
"13668","81.97400","6.83137","0.02417"
"13734","82.37000","6.86432","0.02516"
"13800","82.76600","6.89726","0.02471"
"13866","83.16200","6.93032","0.02503"
"13932","83.55800","6.96339","0.02619"
"13998","83.95400","6.99633","0.02545"
"14064","84.35000","7.02922","0.02706"
"14130","84.74600","7.06228","0.02632"
"14196","85.14200","7.09534","0.02693"
"14262","85.53800","7.12835","0.02723"
"14328","85.93400","7.16129","0.02708"
"14394","86.33200","7.19447","0.02790"
"14460","86.72800","7.22754","0.02732"
"14526","87.12400","7.26054","0.02858"
"14592","87.52000","7.29343","0.02829"
"14658","87.91600","7.32655","0.02879"
"14724","88.31200","7.35955","0.02941"
"14790","88.70800","7.39250","0.02949"
"14856","89.10400","7.42544","0.02977"
"14922","89.50000","7.45845","0.02983"
"14988","89.89600","7.49151","0.03003"
"15054","90.29200","7.52445","0.03027"
"15120","90.68800","7.55746","0.03145"
"15186","91.08400","7.59052","0.03095"
"15252","91.48000","7.62352","0.03181"
"15318","91.87600","7.65641","0.03149"
"15384","92.27200","7.68947","0.03203"
"15450","92.66800","7.72248","0.03282"
"15516","93.06400","7.75548","0.03275"
"15582","93.46000","7.78848","0.03373"
"15648","93.85600","7.82149","0.03317"
"15714","94.25200","7.85449","0.03402"
"15780","94.64800","7.88743","0.03468"
"15846","95.04400","7.92044","0.03503"
"15912","95.44000","7.95350","0.03535"
"15978","95.83600","7.98651","0.03509"
"16044","96.23200","8.01951","0.03604"
"16110","96.62800","8.05245","0.03671"
"16176","97.02400","8.08552","0.03634"
"16242","97.42000","8.11852","0.03684"
"16308","97.81600","8.15141","0.03694"
"16374","98.21200","8.18447","0.03785"
"16440","98.60800","8.21753","0.03630"
"16506","99.00400","8.25048","0.03679"
"16572","99.40000","8.28342","0.03772"
"16638","99.79600","8.31649","0.03780"
"16704","100.19200","8.34949","0.03802"
"16770","100.58800","8.38249","0.03910"
"16836","100.98400","8.41550","0.03882"
"16902","101.38000","8.44850","0.03908"
"16968","101.77600","8.48156","0.03957"
"17034","102.17200","8.51451","0.04001"
"17100","102.56800","8.54745","0.04049"
"17166","102.96400","8.58051","0.03995"
"17232","103.36000","8.61352","0.04137"
"17298","103.75600","8.64646","0.04156"
"17364","104.15200","8.67947","0.04130"
"17430","104.54800","8.71253","0.04205"
"17496","104.94400","8.74547","0.04228"
"17562","105.34000","8.77848","0.04287"
"17628","105.73600","8.81142","0.04327"
"17694","106.13200","8.84449","0.04380"
"17760","106.52800","8.87749","0.04408"
"17826","106.92400","8.91043","0.04420"
"17892","107.32000","8.94350","0.04465"
"17958","107.71600","8.97644","0.04532"
"18024","108.11200","9.00945","0.04543"
"18090","108.50800","9.04245","0.04520"
"18156","108.90400","9.07551","0.04591"
"18222","109.30000","9.10846","0.04584"
"18288","109.69600","9.14146","0.04659"
"18354","110.09200","9.17446","0.04702"
"18420","110.48800","9.20753","0.04717"
"18486","110.88400","9.24047","0.04759"
"18552","111.28000","9.27342","0.04785"
"18618","111.67600","9.30648","0.04737"
"18684","112.07200","9.33948","0.04772"
"18750","112.46800","9.37249","0.04801"
"18816","112.86400","9.40549","0.04853"
"18882","113.26000","9.43849","0.04829"
"18948","113.65600","9.47156","0.04831"
"19014","114.05200","9.50444","0.04897"
"19080","114.44800","9.53739","0.04926"
"19146","114.84400","9.57051","0.04913"
"19212","115.24000","9.60351","0.04936"
"19278","115.63600","9.63646","0.04892"
"19344","116.03200","9.66946","0.04936"
"19410","116.42800","9.70247","0.04976"
"19476","116.82400","9.73553","0.04975"
"19542","117.22000","9.76847","0.05003"
"19608","117.61600","9.80148","0.05020"
"19674","118.01200","9.83454","0.05041"
"19740","118.40800","9.86755","0.05064"
"19806","118.80400","9.90043","0.05067"
"19872","119.20000","9.93349","0.05116"
"19938","119.59600","9.96650","0.05126"
"20004","119.99200","9.99950","0.05144"
"20070","120.38800","10.03244","0.05167"
"20136","120.78400","10.06545","0.05184"
"20202","121.18000","10.09845","0.05188"
"20268","121.57600","10.13151","0.05222"
"20334","121.97200","10.16446","0.05206"
"20400","122.36800","10.19746","0.05232"
"20466","122.76400","10.23053","0.05251"
"20532","123.16000","10.26347","0.05255"
"20598","123.55600","10.29648","0.05271"
"20664","123.95200","10.32954","0.05265"
"20730","124.34800","10.36254","0.05290"
"20796","124.74400","10.39543","0.05293"
"20862","125.14000","10.42849","0.05298"
"20928","125.53600","10.46155","0.05305"
"20994","125.93200","10.49450","0.05316"
"21060","126.32800","10.52744","0.05324"
"21126","126.72400","10.56050","0.05335"
"21192","127.12000","10.59351","0.05339"
"21258","127.51600","10.62645","0.05343"
"21324","127.91200","10.65946","0.05346"
"21390","128.30800","10.69246","0.05352"
"21456","128.70400","10.72552","0.05368"
"21522","129.10000","10.75847","0.05378"
"21588","129.49600","10.79147","0.05397"
"21654","129.89200","10.82448","0.05407"
"21720","130.28800","10.85748","0.05431"
"21786","130.68400","10.89042","0.05465"
"21852","131.08000","10.92349","0.05479"
"21918","131.47600","10.95649","0.05534"
"21984","131.87200","10.98950","0.05568"
"22050","132.26800","11.02244","0.05610"
"22116","132.66400","11.05550","0.05631"
"22182","133.06000","11.08851","0.05705"
"22248","133.45600","11.12151","0.05744"
"22314","133.85200","11.15440","0.05822"
"22380","134.24800","11.18746","0.05904"
"22446","134.64400","11.22052","0.05949"
"22512","135.04000","11.25353","0.06029"
"22578","135.43600","11.28647","0.06104"
"22644","135.83200","11.31953","0.06186"
"22710","136.22800","11.35254","0.06324"
"22776","136.62400","11.38548","0.06400"
"22842","137.02000","11.41849","0.06424"
"22908","137.41600","11.45155","0.06576"
"22974","137.81200","11.48455","0.06697"
"23040","138.20800","11.51750","0.06768"
"23106","138.60400","11.55044","0.06897"
"23172","139.00000","11.58351","0.07048"
"23238","139.39600","11.61651","0.07130"
"23304","139.79200","11.64945","0.07327"
"23370","140.18800","11.68246","0.07478"
"23436","140.58400","11.71552","0.07714"
"23502","140.98000","11.74852","0.07794"
"23568","141.37600","11.78141","0.07892"
"23634","141.77200","11.81453","0.08128"
"23700","142.16800","11.84748","0.08184"
"23766","142.56400","11.88048","0.08299"
"23832","142.96000","11.91348","0.08381"
"23898","143.35600","11.94649","0.08468"
"23964","143.75200","11.97949","0.08559"
"24030","144.14800","12.01243","0.08649"
"24096","144.54400","12.04544","0.08825"
"24162","144.94000","12.07850","0.08868"
"24228","145.33600","12.11151","0.09007"
"24294","145.73200","12.14439","0.09154"
"24360","146.12800","12.17751","0.09232"
"24426","146.52400","12.21052","0.09372"
"24492","146.92000","12.24346","0.09554"
"24558","147.31600","12.27647","0.09594"
"24624","147.71200","12.30947","0.09887"
"24690","148.10800","12.34253","0.10065"
"24756","148.50400","12.37548","0.10354"
"24822","148.90000","12.40842","0.10616"
"24888","149.29600","12.44148","0.10904"
"24954","149.69200","12.47449","0.11295"
"25020","150.08800","12.50749","0.11554"
"25086","150.48400","12.54044","0.11780"
"25152","150.88000","12.57350","0.12044"
"25218","151.27600","12.60650","0.12269"
"25284","151.67200","12.63951","0.12448"
"25350","152.06800","12.67251","0.12668"
"25416","152.46400","12.70551","0.12860"
"25482","152.86000","12.73846","0.13025"
"25548","153.25600","12.77146","0.13200"
"25614","153.65200","12.80447","0.13359"
"25680","154.04800","12.83747","0.13485"
"25746","154.44400","12.87047","0.13647"
"25812","154.84000","12.90348","0.13707"
"25878","155.23600","12.93648","0.13801"
"25944","155.63200","12.96949","0.13853"
"26010","156.02800","13.00249","0.13928"
"26076","156.42400","13.03543","0.13954"
"26142","156.82000","13.06850","0.14010"
"26208","157.21600","13.10150","0.14064"
"26274","157.61200","13.13445","0.14108"
"26340","158.00800","13.16751","0.14165"
"26406","158.40400","13.20051","0.14240"
"26472","158.80000","13.23352","0.14375"
"26538","159.19600","13.26646","0.14480"
"26604","159.59200","13.29946","0.14606"
"26670","159.98800","13.33253","0.14835"
"26736","160.38400","13.36547","0.14861"
"26802","160.78000","13.39842","0.15116"
"26868","161.17600","13.43154","0.15271"
"26934","161.57200","13.46448","0.15414"
"27000","161.96800","13.49749","0.15583"
"27066","162.36400","13.53043","0.15772"
"27132","162.76000","13.56349","0.15956"
"27198","163.15600","13.59650","0.16114"
"27264","163.55200","13.62950","0.16296"
"27330","163.94800","13.66245","0.16506"
"27396","164.34400","13.69545","0.16716"
"27462","164.74000","13.72851","0.16925"
"27528","165.13600","13.76146","0.17171"
"27594","165.53200","13.79446","0.17406"
"27660","165.92800","13.82747","0.17579"
"27726","166.32400","13.86053","0.17774"
"27792","166.72000","13.89341","0.17976"
"27858","167.11600","13.92648","0.18190"
"27924","167.51200","13.95954","0.18402"
"27990","167.90800","13.99249","0.18636"
"28056","168.30400","14.02543","0.18874"
"28122","168.70000","14.05843","0.19086"
"28188","169.09600","14.09150","0.19324"
"28254","169.49200","14.12450","0.19533"
"28320","169.88800","14.15744","0.19771"
"28386","170.28400","14.19045","0.19951"
"28452","170.68000","14.22351","0.20040"
"28518","171.07600","14.25651","0.20122"
"28584","171.47200","14.28946","0.20138"
"28650","171.86800","14.32252","0.20152"
"28716","172.26400","14.35547","0.20157"
"28782","172.66000","14.38847","0.20213"
"28848","173.05600","14.42147","0.20215"
"28914","173.45200","14.45454","0.20298"
"28980","173.84800","14.48754","0.20469"
"29046","174.24400","14.52049","0.20615"
"29112","174.64000","14.55349","0.20874"
"29178","175.03600","14.58649","0.21066"
"29244","175.43200","14.61950","0.21208"
"29310","175.82800","14.65244","0.21560"
"29376","176.22400","14.68550","0.21737"
"29442","176.62000","14.71845","0.21740"
"29508","177.01600","14.75145","0.21658"
"29574","177.41200","14.78446","0.21895"
"29640","177.80800","14.81752","0.22130"
"29706","178.20400","14.85046","0.22343"
"29772","178.60000","14.88347","0.22540"
"29838","178.99600","14.91641","0.22720"
"29904","179.39200","14.94954","0.22959"
"29970","179.78800","14.98248","0.23175"
"30036","180.18400","15.01542","0.23370"
"30102","180.58000","15.04849","0.23513"
"30168","180.97600","15.08149","0.23671"
"30234","181.37200","15.11449","0.23806"
"30300","181.76800","15.14738","0.23961"
"30366","182.16400","15.18044","0.24052"
"30432","182.56000","15.21357","0.24130"
"30498","182.95600","15.24651","0.24266"
"30564","183.35200","15.27939","0.24407"
"30630","183.74800","15.31252","0.24511"
"30696","184.14400","15.34552","0.24693"
"30762","184.54000","15.37847","0.25034"
"30828","184.93600","15.41147","0.25269"
"30894","185.33200","15.44453","0.25653"
"30960","185.72800","15.47748","0.26035"
"31026","186.12400","15.51048","0.26348"
"31092","186.52000","15.54348","0.26688"
"31158","186.91600","15.57649","0.26997"
"31224","187.31200","15.60943","0.27267"
"31290","187.70800","15.64250","0.27567"
"31356","188.10400","15.67550","0.27997"
"31422","188.50000","15.70856","0.28475"
"31488","188.89600","15.74151","0.28929"
"31554","189.29200","15.77445","0.29274"
"31620","189.68800","15.80746","0.29612"
"31686","190.08400","15.84046","0.29806"
"31752","190.48000","15.87352","0.30069"
"31818","190.87600","15.90647","0.30323"
"31884","191.27200","15.93953","0.30602"
"31950","191.66800","15.97248","0.31004"
"32016","192.06400","16.00548","0.31399"
"32082","192.46000","16.03842","0.31996"
"32148","192.85600","16.07149","0.32522"
"32214","193.25200","16.10449","0.32862"
"32280","193.64800","16.13743","0.33191"
"32346","194.04400","16.17050","0.33521"
"32412","194.44000","16.20356","0.33778"
"32478","194.83600","16.23644","0.34020"
"32544","195.23200","16.26945","0.34293"
"32610","195.62800","16.30245","0.34512"
"32676","196.02400","16.33552","0.34696"
"32742","196.42000","16.36846","0.34825"
"32808","196.81600","16.40141","0.34923"
"32874","197.21200","16.43447","0.34970"
"32940","197.60800","16.46753","0.34990"
"33006","198.00400","16.50048","0.35006"
"33072","198.40000","16.53342","0.35016"
"33138","198.79600","16.56648","0.35033"
"33204","199.19200","16.59955","0.35073"
"33270","199.58800","16.63249","0.35147"
"33336","199.98400","16.66550","0.35276"
"33402","200.38000","16.69850","0.35423"
"33468","200.77600","16.73150","0.35599"
"33534","201.17200","16.76445","0.35863"
"33600","201.56800","16.79751","0.36178"
"33666","201.96400","16.83051","0.36500"
"33732","202.36000","16.86352","0.36764"
"33798","202.75600","16.89646","0.37131"
"33864","203.15200","16.92947","0.18978"
"33930","203.54800","16.96253","0.19406"
"33996","203.94400","16.99547","0.20002"
"34062","204.34000","17.02842","0.20158"
"34128","204.73600","17.06148","0.20257"
"34194","205.13200","17.09449","0.20891"
"34260","205.52800","17.12749","0.20820"
"34326","205.92400","17.16049","0.21250"
"34392","206.32000","17.19350","0.21633"
"34458","206.71600","17.22650","0.22047"
"34524","207.11200","17.25950","0.22256"
"34590","207.50800","17.29251","0.22521"
"34656","207.90400","17.32551","0.22800"
"34722","208.30000","17.35851","0.23126"
"34788","208.69600","17.39146","0.23444"
"34854","209.09200","17.42447","0.23719"
"34920","209.48800","17.45753","0.23904"
"34986","209.88400","17.49053","0.24083"
"35052","210.28000","17.52336","0.24222"
"35118","210.67600","17.55654","0.24338"
"35184","211.07200","17.58954","0.24553"
"35250","211.46800","17.62249","0.24670"
"35316","211.86400","17.65543","0.24878"
"35382","212.26000","17.68855","0.25176"
"35448","212.65600","17.72150","0.25492"
"35514","213.05200","17.75444","0.25945"
"35580","213.44800","17.78745","0.26414"
"35646","213.84400","17.82051","0.27037"
"35712","214.24000","17.85357","0.27677"
"35778","214.63600","17.88646","0.28510"
"35844","215.03200","17.91946","0.29188"
"35910","215.42800","17.95252","0.29531"
"35976","215.82400","17.98553","0.29748"
"36042","216.22000","18.01847","0.29874"
"36108","216.61600","18.05142","0.30183"
"36174","217.01200","18.08448","0.30610"
"36240","217.40800","18.11748","0.31216"
"36306","217.80400","18.15043","0.32135"
"36372","218.20000","18.18343","0.32768"
"36438","218.59600","18.21650","0.33026"
"36504","218.99200","18.24956","0.33237"
"36570","219.38800","18.28244","0.33488"
"36636","219.78400","18.31545","0.34018"
"36702","220.18000","18.34851","0.34479"
"36768","220.57600","18.38152","0.34743"
"36834","220.97200","18.41446","0.34853"
"36900","221.36800","18.44758","0.34921"
"36966","221.76400","18.48047","0.34985"
"37032","222.16000","18.51347","0.35010"
"37098","222.55600","18.54647","0.35021"
"37164","222.95200","18.57948","0.35039"
"37230","223.34800","18.61248","0.35062"
"37296","223.74400","18.64548","0.35091"
"37362","224.14000","18.67849","0.35204"
"37428","224.53600","18.71149","0.35389"
"37494","224.93200","18.74450","0.35543"
"37560","225.32800","18.77744","0.35731"
"37626","225.72400","18.81050","0.36091"
"37692","226.12000","18.84351","0.36588"
"37758","226.51600","18.87645","0.36980"
"37824","226.91200","18.90946","0.37245"
"37890","227.30800","18.94252","0.37769"
"37956","227.70400","18.97546","0.38380"
"38022","228.10000","19.00847","0.38891"
"38088","228.49600","19.04147","0.39372"
"38154","228.89200","19.07448","0.39852"
"38220","229.28800","19.10748","0.40224"
"38286","229.68400","19.14048","0.40374"
"38352","230.08000","19.17343","0.40654"
"38418","230.47600","19.20649","0.41206"
"38484","230.87200","19.23955","0.41212"
"38550","231.26800","19.27244","0.37987"
"38616","231.66400","19.30544","0.37744"
"38682","232.06000","19.33850","0.37305"
"38748","232.45600","19.37151","0.37598"
"38814","232.85200","19.40445","0.37888"
"38880","233.24800","19.43746","0.38485"
"38946","233.64400","19.47052","0.39202"
"39012","234.04000","19.50347","0.39820"
"39078","234.43600","19.53641","0.34764"
"39144","234.83200","19.56947","0.34943"
"39210","235.22800","19.60254","0.34967"
"39276","235.62400","19.63548","0.35006"
"39342","236.02000","19.66842","0.35006"
"39408","236.41600","19.70155","0.35023"
"39474","236.81200","19.73455","0.35063"
"39540","237.20800","19.76750","0.35164"
"39606","237.60400","19.80044","0.35216"
"39672","238.00000","19.83356","0.35390"
"39738","238.39600","19.86645","0.35717"
"39804","238.79200","19.89945","0.36286"
"39870","239.18800","19.93246","0.36576"
"39936","239.58400","19.96546","0.18430"
"40002","239.98000","19.99846","0.20293"
"40068","240.37600","20.03147","0.20288"
"40134","240.77200","20.06447","0.20227"
"40200","241.16800","20.09747","0.21740"
"40266","241.56400","20.13048","0.22593"
"40332","241.96000","20.16348","0.22847"
"40398","242.35600","20.19655","0.23622"
"40464","242.75200","20.22949","0.23984"
"40530","243.14800","20.26243","0.24300"
"40596","243.54400","20.29544","0.24830"
"40662","243.94000","20.32850","0.25365"
"40728","244.33600","20.36156","0.25834"
"40794","244.73200","20.39439","0.26500"
"40860","245.12800","20.42751","0.27056"
"40926","245.52400","20.46052","0.27489"
"40992","245.92000","20.49352","0.28057"
"41058","246.31600","20.52641","0.28837"
"41124","246.71200","20.55953","0.29441"
"41190","247.10800","20.59253","0.30033"
"41256","247.50400","20.62547","0.30525"
"41322","247.90000","20.65842","0.31396"
"41388","248.29600","20.69154","0.32550"
"41454","248.69200","20.72455","0.33376"
"41520","249.08800","20.75749","0.33958"
"41586","249.48400","20.79049","0.34512"
"41652","249.88000","20.82350","0.34855"
"41718","250.27600","20.85656","0.34960"
"41784","250.67200","20.88945","0.35002"
"41850","251.06800","20.92245","0.35015"
"41916","251.46400","20.95551","0.35061"
"41982","251.86000","20.98852","0.35156"
"42048","252.25600","21.02140","0.35483"
"42114","252.65200","21.05447","0.36112"
"42180","253.04800","21.08753","0.36789"
"42246","253.44400","21.12047","0.37392"
"42312","253.84000","21.15348","0.37991"
"42378","254.23600","21.18648","0.38771"
"42444","254.63200","21.21948","0.39685"
"42510","255.02800","21.25249","0.40245"
"42576","255.42400","21.28549","0.40720"
"42642","255.82000","21.31850","0.41327"
"42708","256.21600","21.35144","0.42052"
"42774","256.61200","21.38444","0.42840"
"42840","257.00800","21.41745","0.43742"
"42906","257.40400","21.45051","0.44418"
"42972","257.80000","21.48352","0.44884"
"43038","258.19600","21.51646","0.45169"
"43104","258.59200","21.54946","0.45599"
"43170","258.98800","21.58253","0.46008"
"43236","259.38400","21.61547","0.46419"
"43302","259.78000","21.64847","0.46633"
"43368","260.17600","21.68154","0.46830"
"43434","260.57200","21.71448","0.47169"
"43500","260.96800","21.74748","0.47578"
"43566","261.36400","21.78043","0.47924"
"43632","261.76000","21.81350","0.48260"
"43698","262.15600","21.84650","0.48760"
"43764","262.55200","21.87944","0.49358"
"43830","262.94800","21.91238","0.49702"
"43896","263.34400","21.94557","0.49960"
"43962","263.74000","21.97851","0.50178"
"44028","264.13600","22.01140","0.50337"
"44094","264.53200","22.04446","0.50440"
"44160","264.92800","22.07752","0.50606"
"44226","265.32400","22.11053","0.50968"
"44292","265.72000","22.14341","0.51688"
"44358","266.11600","22.17648","0.52289"
"44424","266.51200","22.20948","0.52811"
"44490","266.90800","22.24248","0.53396"
"44556","267.30400","22.27543","0.53902"
"44622","267.70000","22.30843","0.54368"
"44688","268.09600","22.34150","0.02258"
"44754","268.49200","22.37450","0.01000"
"44820","268.88800","22.40744","0.02811"
"44886","269.28400","22.44044","0.02251"
"44952","269.68000","22.47351","0.00723"
"45018","270.07600","22.50651","0.02414"
"45084","270.47200","22.53940","0.02334"
"45150","270.86800","22.57246","0.02975"
"45216","271.26400","22.60553","0.01792"
"45282","271.66000","22.63847","0.02849"
"45348","272.05600","22.67147","0.02364"
"45414","272.45200","22.70454","0.02780"
"45480","272.84800","22.73748","0.03430"
"45546","273.24400","22.77048","0.02945"
"45612","273.64000","22.80349","0.03309"
"45678","274.03600","22.83649","0.03524"
"45744","274.43200","22.86950","0.03438"
"45810","274.82800","22.90250","0.03822"
"45876","275.22400","22.93550","0.03908"
"45942","275.62000","22.96845","0.03882"
"46008","276.01600","23.00145","0.03993"
"46074","276.41200","23.03446","0.04144"
"46140","276.80800","23.06752","0.04254"
"46206","277.20400","23.10046","0.04318"
"46272","277.60000","23.13347","0.04387"
"46338","277.99600","23.16647","0.04457"
"46404","278.39200","23.19954","0.04514"
"46470","278.78800","23.23248","0.04610"
"46536","279.18400","23.26542","0.04681"
"46602","279.58000","23.29849","0.04714"
"46668","279.97600","23.33155","0.04753"
"46734","280.37200","23.36443","0.04847"
"46800","280.76800","23.39738","0.04877"
"46866","281.16400","23.43050","0.04911"
"46932","281.56000","23.46351","0.04965"
"46998","281.95600","23.49645","0.05006"
"47064","282.35200","23.52939","0.05028"
"47130","282.74800","23.56252","0.05074"
"47196","283.14400","23.59552","0.05084"
"47262","283.54000","23.62852","0.05142"
"47328","283.93600","23.66147","0.05158"
"47394","284.33200","23.69447","0.05201"
"47460","284.72800","23.72754","0.05195"
"47526","285.12400","23.76048","0.05205"
"47592","285.52000","23.79349","0.05235"
"47658","285.91600","23.82655","0.05262"
"47724","286.31200","23.85955","0.05273"
"47790","286.70800","23.89249","0.05279"
"47856","287.10400","23.92544","0.05288"
"47922","287.50000","23.95850","0.05310"
"47988","287.89600","23.99151","0.05313"
"48054","288.29200","24.02445","0.05316"
"48120","288.68800","24.05746","0.05333"
"48186","289.08400","24.09046","0.05338"
"48252","289.48000","24.12346","0.05360"
"48318","289.87600","24.15647","0.05365"
"48384","290.27200","24.18947","0.05379"
"48450","290.66800","24.22247","0.05401"
"48516","291.06400","24.25548","0.05426"
"48582","291.46000","24.28848","0.05458"
"48648","291.85600","24.32149","0.05497"
"48714","292.25200","24.35449","0.05541"
"48780","292.64800","24.38749","0.05566"
"48846","293.04400","24.42044","0.05655"
"48912","293.44000","24.45344","0.05705"
"48978","293.83600","24.48650","0.05750"
"49044","294.23200","24.51945","0.05818"
"49110","294.62800","24.55245","0.05869"
"49176","295.02400","24.58552","0.05979"
"49242","295.42000","24.61846","0.06021"
"49308","295.81600","24.65140","0.06164"
"49374","296.21200","24.68453","0.06227"
"49440","296.60800","24.71753","0.06364"
"49506","297.00400","24.75047","0.06462"
"49572","297.40000","24.78342","0.06585"
"49638","297.79600","24.81654","0.06727"
"49704","298.19200","24.84955","0.06790"
"49770","298.58800","24.88243","0.06666"
"49836","298.98400","24.91550","0.06865"
"49902","299.38000","24.94850","0.06987"
"49968","299.77600","24.98150","0.07185"
"50034","300.17200","25.01445","0.07472"
"50100","300.56800","25.04751","0.07667"
"50166","300.96400","25.08051","0.07818"
"50232","301.36000","25.11352","0.08066"
"50298","301.75600","25.14640","0.08184"
"50364","302.15200","25.17946","0.08353"
"50430","302.54800","25.21247","0.08479"
"50496","302.94400","25.24553","0.08611"
"50562","303.34000","25.27848","0.08719"
"50628","303.73600","25.31148","0.08847"
"50694","304.13200","25.34448","0.08921"
"50760","304.52800","25.37749","0.08999"
"50826","304.92400","25.41049","0.09085"
"50892","305.32000","25.44349","0.09184"
"50958","305.71600","25.47650","0.09489"
"51024","306.11200","25.50945","0.09785"
"51090","306.50800","25.54251","0.09953"
"51156","306.90400","25.57551","0.10276"
"51222","307.30000","25.60846","0.10535"
"51288","307.69600","25.64146","0.10961"
"51354","308.09200","25.67452","0.11279"
"51420","308.48800","25.70753","0.11459"
"51486","308.88400","25.74053","0.11891"
"51552","309.28000","25.77348","0.11280"
"51618","309.67600","25.80648","0.11666"
"51684","310.07200","25.83948","0.11937"
"51750","310.46800","25.87249","0.12294"
"51816","310.86400","25.90549","0.12633"
"51882","311.26000","25.93849","0.12869"
"51948","311.65600","25.97150","0.13060"
"52014","312.05200","26.00450","0.13209"
"52080","312.44800","26.03744","0.13385"
"52146","312.84400","26.07057","0.13555"
"52212","313.24000","26.10351","0.13665"
"52278","313.63600","26.13640","0.13777"
"52344","314.03200","26.16946","0.13866"
"52410","314.42800","26.20252","0.13909"
"52476","314.82400","26.23547","0.13982"
"52542","315.22000","26.26841","0.14011"
"52608","315.61600","26.30148","0.14078"
"52674","316.01200","26.33454","0.14154"
"52740","316.40800","26.36748","0.14186"
"52806","316.80400","26.40037","0.14244"
"52872","317.20000","26.43349","0.14341"
"52938","317.59600","26.46649","0.13774"
"53004","317.99200","26.49944","0.10581"
"53070","318.38800","26.53244","0.11524"
"53136","318.78400","26.56544","0.11892"
"53202","319.18000","26.59851","0.12183"
"53268","319.57600","26.63151","0.12504"
"53334","319.97200","26.66440","0.12970"
"53400","320.36800","26.69752","0.13107"
"53466","320.76400","26.73052","0.13012"
"53532","321.16000","26.76347","0.12982"
"53598","321.55600","26.79647","0.13240"
"53664","321.95200","26.82954","0.13654"
"53730","322.34800","26.86254","0.13728"
"53796","322.74400","26.89548","0.13726"
"53862","323.14000","26.92849","0.13717"
"53928","323.53600","26.96149","0.13840"
"53994","323.93200","26.99450","0.13943"
"54060","324.32800","27.02744","0.13774"
"54126","324.72400","27.06050","0.03348"
"54192","325.12000","27.09345","0.02673"
"54258","325.51600","27.12651","0.02678"
"54324","325.91200","27.15945","0.03301"
"54390","326.30800","27.19252","0.03082"
"54456","326.70400","27.22546","0.03205"
"54522","327.10000","27.25847","0.03367"
"54588","327.49600","27.29147","0.03198"
"54654","327.89200","27.32454","0.03338"
"54720","328.28800","27.35748","0.03732"
"54786","328.68400","27.39042","0.03653"
"54852","329.08000","27.42349","0.03634"
"54918","329.47600","27.45655","0.03854"
"54984","329.87200","27.48949","0.03995"
"55050","330.26800","27.52238","0.03927"
"55116","330.66400","27.55550","0.03997"
"55182","331.06000","27.58857","0.04140"
"55248","331.45600","27.62145","0.04188"
"55314","331.85200","27.65439","0.04234"
"55380","332.24800","27.68752","0.04342"
"55446","332.64400","27.72052","0.04355"
"55512","333.04000","27.75347","0.04493"
"55578","333.43600","27.78647","0.04507"
"55644","333.83200","27.81953","0.04517"
"55710","334.22800","27.85254","0.04565"
"55776","334.62400","27.88548","0.04647"
"55842","335.02000","27.91842","0.04750"
"55908","335.41600","27.95155","0.04769"
"55974","335.81200","27.98455","0.04849"
"56040","336.20800","28.01744","0.04909"
"56106","336.60400","28.05044","0.04924"
"56172","337.00000","28.08350","0.04973"
"56238","337.39600","28.11651","0.05016"
"56304","337.79200","28.14945","0.05061"
"56370","338.18800","28.18246","0.05104"
"56436","338.58400","28.21552","0.05130"
"56502","338.98000","28.24852","0.05148"
"56568","339.37600","28.28147","0.05174"
"56634","339.77200","28.31453","0.05218"
"56700","340.16800","28.34748","0.05230"
"56766","340.56400","28.38042","0.05253"
"56832","340.96000","28.41348","0.05277"
"56898","341.35600","28.44648","0.05285"
"56964","341.75200","28.47949","0.05294"
"57030","342.14800","28.51250","0.05304"
"57096","342.54400","28.54544","0.05314"
"57162","342.94000","28.57850","0.05331"
"57228","343.33600","28.61151","0.05335"
"57294","343.73200","28.64445","0.05359"
"57360","344.12800","28.67751","0.05373"
"57426","344.52400","28.71051","0.05381"
"57492","344.92000","28.74352","0.05423"
"57558","345.31600","28.77646","0.05430"
"57624","345.71200","28.80947","0.05494"
"57690","346.10800","28.84247","0.05545"
"57756","346.50400","28.87554","0.05632"
"57822","346.90000","28.90842","0.05693"
"57888","347.29600","28.94154","0.05801"
"57954","347.69200","28.97455","0.05857"
"58020","348.08800","29.00743","0.05944"
"58086","348.48400","29.04049","0.06004"
"58152","348.88000","29.07350","0.06147"
"58218","349.27600","29.10650","0.06267"
"58284","349.67200","29.13944","0.06377"
"58350","350.06800","29.17245","0.06574"
"58416","350.46400","29.20551","0.06697"
"58482","350.86000","29.23852","0.06838"
"58548","351.25600","29.27140","0.07069"
"58614","351.65200","29.30446","0.07231"
"58680","352.04800","29.33747","0.07321"
"58746","352.44400","29.37047","0.07495"
"58812","352.84000","29.40348","0.07809"
"58878","353.23600","29.43642","0.07989"
"58944","353.63200","29.46948","0.08166"
"59010","354.02800","29.50243","0.08337"
"59076","354.42400","29.53543","0.08509"
"59142","354.82000","29.56849","0.08643"
"59208","355.21600","29.60150","0.08735"
"59274","355.61200","29.63450","0.08826"
"59340","356.00800","29.66745","0.08978"
"59406","356.40400","29.70051","0.09096"
"59472","356.80000","29.73352","0.09345"
"59538","357.19600","29.76652","0.09528"
"59604","357.59200","29.79946","0.09828"
"59670","357.98800","29.83253","0.10016"
"59736","358.38400","29.86547","0.10306"
"59802","358.78000","29.89847","0.10512"
"59868","359.17600","29.93154","0.10831"
"59934","359.57200","29.96448","0.11201"
"60000","359.96800","29.99749","0.11524"
"60066","360.36400","30.03049","0.11904"
"60132","360.76000","30.06349","0.12152"
"60198","361.15600","30.09650","0.12463"
"60264","361.55200","30.12950","0.12551"
"60330","361.94800","30.16250","0.12908"
"60396","362.34400","30.19557","0.13108"
"60462","362.74000","30.22851","0.13344"
"60528","363.13600","30.26146","0.13518"
"60594","363.53200","30.29446","0.13626"
"60660","363.92800","30.32752","0.13759"
"60726","364.32400","30.36053","0.13827"
"60792","364.72000","30.39341","0.13905"
"60858","365.11600","30.42648","0.13967"
"60924","365.51200","30.45954","0.14036"
"60990","365.90800","30.49249","0.14075"
"61056","366.30400","30.52543","0.14162"
"61122","366.70000","30.55849","0.14227"
"61188","367.09600","30.59150","0.14377"
"61254","367.49200","30.62450","0.14420"
"61320","367.88800","30.65744","0.14670"
"61386","368.28400","30.69051","0.14745"
"61452","368.68000","30.72351","0.14987"
"61518","369.07600","30.75645","0.15186"
"61584","369.47200","30.78946","0.15352"
"61650","369.86800","30.82252","0.15582"
"61716","370.26400","30.85553","0.15690"
"61782","370.66000","30.88847","0.15921"
"61848","371.05600","30.92147","0.16088"
"61914","371.45200","30.95448","0.16326"
"61980","371.84800","30.98754","0.16512"
"62046","372.24400","31.02048","0.16734"
"62112","372.64000","31.05349","0.17008"
"62178","373.03600","31.08649","0.17312"
"62244","373.43200","31.11950","0.17601"
"62310","373.82800","31.15244","0.17882"
"62376","374.22400","31.18550","0.18095"
"62442","374.62000","31.21851","0.18406"
"62508","375.01600","31.25145","0.18638"
"62574","375.41200","31.28452","0.18911"
"62640","375.80800","31.31752","0.19160"
"62706","376.20400","31.35046","0.19467"
"62772","376.60000","31.38347","0.19727"
"62838","376.99600","31.41647","0.19848"
"62904","377.39200","31.44953","0.19972"
"62970","377.78800","31.48248","0.20068"
"63036","378.18400","31.51548","0.20124"
"63102","378.58000","31.54848","0.20139"
"63168","378.97600","31.58149","0.20170"
"63234","379.37200","31.61449","0.20219"
"63300","379.76800","31.64744","0.15655"
"63366","380.16400","31.68050","0.15526"
"63432","380.56000","31.71356","0.15407"
"63498","380.95600","31.74645","0.15440"
"63564","381.35200","31.77939","0.15748"
"63630","381.74800","31.81257","0.16274"
"63696","382.14400","31.84552","0.16651"
"63762","382.54000","31.87846","0.16717"
"63828","382.93600","31.91147","0.16689"
"63894","383.33200","31.94447","0.16813"
"63960","383.72800","31.97754","0.17158"
"64026","384.12400","32.01048","0.17458"
"64092","384.52000","32.04348","0.17908"
"64158","384.91600","32.07655","0.18206"
"64224","385.31200","32.10955","0.18304"
"64290","385.70800","32.14243","0.18368"
"64356","386.10400","32.17544","0.18500"
"64422","386.50000","32.20850","0.18684"
"64488","386.89600","32.24150","0.18949"
"64554","387.29200","32.27445","0.19146"
"64620","387.68800","32.30745","0.19472"
"64686","388.08400","32.34052","0.19668"
"64752","388.48000","32.37346","0.19794"
"64818","388.87600","32.40646","0.19869"
"64884","389.27200","32.43947","0.20004"
"64950","389.66800","32.47247","0.20055"
"65016","390.06400","32.50547","0.20114"
"65082","390.46000","32.53842","0.20100"
"65148","390.85600","32.57148","0.20143"
"65214","391.25200","32.60455","0.20153"
"65280","391.64800","32.63743","0.20176"
"65346","392.04400","32.67043","0.20198"
"65412","392.44000","32.70350","0.20237"
"65478","392.83600","32.73650","0.20303"
"65544","393.23200","32.76950","0.20371"
"65610","393.62800","32.80251","0.20547"
"65676","394.02400","32.83545","0.20639"
"65742","394.42000","32.86846","0.20919"
"65808","394.81600","32.90146","0.21089"
"65874","395.21200","32.93452","0.21336"
"65940","395.60800","32.96747","0.21491"
"66006","396.00400","33.00047","0.21590"
"66072","396.40000","33.03348","0.21659"
"66138","396.79600","33.06648","0.21867"
"66204","397.19200","33.09948","0.22027"
"66270","397.58800","33.13249","0.22188"
"66336","397.98400","33.16549","0.22319"
"66402","398.38000","33.19850","0.22536"
"66468","398.77600","33.23150","0.22687"
"66534","399.17200","33.26444","0.22839"
"66600","399.56800","33.29745","0.22990"
"66666","399.96400","33.33051","0.23104"
"66732","400.36000","33.36352","0.23243"
"66798","400.75600","33.39640","0.23375"
"66864","401.15200","33.42946","0.23506"
"66930","401.54800","33.46247","0.23605"
"66996","401.94400","33.49547","0.23692"
"67062","402.34000","33.52841","0.23822"
"67128","402.73600","33.56148","0.23910"
"67194","403.13200","33.59448","0.24009"
"67260","403.52800","33.62749","0.24093"
"67326","403.92400","33.66049","0.24235"
"67392","404.32000","33.69349","0.24380"
"67458","404.71600","33.72650","0.24456"
"67524","405.11200","33.75950","0.24541"
"67590","405.50800","33.79245","0.24709"
"67656","405.90400","33.82551","0.24879"
"67722","406.30000","33.85851","0.24987"
"67788","406.69600","33.89146","0.25152"
"67854","407.09200","33.92446","0.25371"
"67920","407.48800","33.95753","0.25478"
"67986","407.88400","33.99047","0.25673"
"68052","408.28000","34.02347","0.25859"
"68118","408.67600","34.05654","0.26057"
"68184","409.07200","34.08948","0.26231"
"68250","409.46800","34.12243","0.26394"
"68316","409.86400","34.15543","0.26639"
"68382","410.26000","34.18855","0.26821"
"68448","410.65600","34.22150","0.26937"
"68514","411.05200","34.25450","0.27147"
"68580","411.44800","34.28745","0.27254"
"68646","411.84400","34.32051","0.27515"
"68712","412.24000","34.35351","0.27734"
"68778","412.63600","34.38640","0.27978"
"68844","413.03200","34.41946","0.28214"
"68910","413.42800","34.45252","0.28470"
"68976","413.82400","34.48547","0.28746"
"69042","414.22000","34.51847","0.29055"
"69108","414.61600","34.55148","0.29270"
"69174","415.01200","34.58454","0.29388"
"69240","415.40800","34.61754","0.13127"
"69306","415.80400","34.65042","0.14510"
"69372","416.20000","34.68349","0.14073"
"69438","416.59600","34.71655","0.13972"
"69504","416.99200","34.74950","0.14184"
"69570","417.38800","34.78244","0.14336"
"69636","417.78400","34.81544","0.14387"
"69702","418.18000","34.84851","0.14227"
"69768","418.57600","34.88145","0.14479"
"69834","418.97200","34.91446","0.14889"
"69900","419.36800","34.94752","0.14710"
"69966","419.76400","34.98053","0.14659"
"70032","420.16000","35.01347","0.14747"
"70098","420.55600","35.04641","0.14992"
"70164","420.95200","35.07948","0.15315"
"70230","421.34800","35.11248","0.15244"
"70296","421.74400","35.14548","0.15195"
"70362","422.14000","35.17842","0.15500"
"70428","422.53600","35.21155","0.15703"
"70494","422.93200","35.24443","0.15730"
"70560","423.32800","35.27750","0.15705"
"70626","423.72400","35.31050","0.15746"
"70692","424.12000","35.34344","0.15939"
"70758","424.51600","35.37651","0.16178"
"70824","424.91200","35.40945","0.16236"
"70890","425.30800","35.44252","0.16206"
"70956","425.70400","35.47552","0.16327"
"71022","426.10000","35.50846","0.16583"
"71088","426.49600","35.54141","0.16850"
"71154","426.89200","35.57453","0.16876"
"71220","427.28800","35.60748","0.16887"
"71286","427.68400","35.64048","0.16948"
"71352","428.08000","35.67348","0.17243"
"71418","428.47600","35.70655","0.17455"
"71484","428.87200","35.73949","0.17542"
"71550","429.26800","35.77238","0.17579"
"71616","429.66400","35.80550","0.17801"
"71682","430.06000","35.83850","0.18003"
"71748","430.45600","35.87144","0.18157"
"71814","430.85200","35.90445","0.18298"
"71880","431.24800","35.93745","0.18280"
"71946","431.64400","35.97052","0.18423"
"72012","432.04000","36.00346","0.18600"
"72078","432.43600","36.03646","0.18758"
"72144","432.83200","36.06953","0.18895"
"72210","433.22800","36.10253","0.19025"
"72276","433.62400","36.13542","0.19081"
"72342","434.02000","36.16848","0.19264"
"72408","434.41600","36.20155","0.19463"
"72474","434.81200","36.23455","0.19633"
"72540","435.20800","36.26743","0.19720"
"72606","435.60400","36.30050","0.19761"
"72672","436.00000","36.33350","0.19869"
"72738","436.39600","36.36656","0.19956"
"72804","436.79200","36.39945","0.20011"
"72870","437.18800","36.43245","0.20053"
"72936","437.58400","36.46552","0.20074"
"73002","437.98000","36.49846","0.20108"
"73068","438.37600","36.53146","0.20129"
"73134","438.77200","36.56447","0.20146"
"73200","439.16800","36.59747","0.20159"
"73266","439.56400","36.63041","0.20168"
"73332","439.96000","36.66348","0.20184"
"73398","440.35600","36.69648","0.20223"
"73464","440.75200","36.72949","0.20227"
"73530","441.14800","36.76249","0.20270"
"73596","441.54400","36.79543","0.20368"
"73662","441.94000","36.82850","0.20450"
"73728","442.33600","36.86150","0.20582"
"73794","442.73200","36.89445","0.20655"
"73860","443.12800","36.92745","0.20818"
"73926","443.52400","36.96045","0.20958"
"73992","443.92000","36.99346","0.20995"
"74058","444.31600","37.02646","0.21174"
"74124","444.71200","37.05953","0.21379"
"74190","445.10800","37.09247","0.21472"
"74256","445.50400","37.12547","0.21588"
"74322","445.90000","37.15842","0.21686"
"74388","446.29600","37.19154","0.21835"
"74454","446.69200","37.22454","0.21981"
"74520","447.08800","37.25749","0.22059"
"74586","447.48400","37.29049","0.22185"
"74652","447.88000","37.32350","0.22280"
"74718","448.27600","37.35650","0.22387"
"74784","448.67200","37.38945","0.22552"
"74850","449.06800","37.42245","0.22643"
"74916","449.46400","37.45551","0.22735"
"74982","449.86000","37.48852","0.22858"
"75048","450.25600","37.52140","0.22965"
"75114","450.65200","37.55447","0.23121"
"75180","451.04800","37.58747","0.23223"
"75246","451.44400","37.62053","0.23296"
"75312","451.84000","37.65342","0.23397"
"75378","452.23600","37.68648","0.23483"
"75444","452.63200","37.71949","0.23594"
"75510","453.02800","37.75249","0.23647"
"75576","453.42400","37.78543","0.23790"
"75642","453.82000","37.81855","0.23819"
"75708","454.21600","37.85144","0.23971"
"75774","454.61200","37.88444","0.24003"
"75840","455.00800","37.91751","0.24050"
"75906","455.40400","37.95051","0.24010"
"75972","455.80000","37.98346","0.24109"
"76038","456.19600","38.01646","0.24180"
"76104","456.59200","38.04946","0.24314"
"76170","456.98800","38.08247","0.24453"
"76236","457.38400","38.11547","0.24620"
"76302","457.78000","38.14848","0.24701"
"76368","458.17600","38.18148","0.24839"
"76434","458.57200","38.21448","0.24923"
"76500","458.96800","38.24749","0.25045"
"76566","459.36400","38.28049","0.25253"
"76632","459.76000","38.31349","0.25357"
"76698","460.15600","38.34650","0.25512"
"76764","460.55200","38.37944","0.25717"
"76830","460.94800","38.41245","0.25907"
"76896","461.34400","38.44556","0.26063"
"76962","461.74000","38.47851","0.26250"
"77028","462.13600","38.51146","0.26368"
"77094","462.53200","38.54446","0.26561"
"77160","462.92800","38.57752","0.26641"
"77226","463.32400","38.61047","0.26840"
"77292","463.72000","38.64341","0.27037"
"77358","464.11600","38.67648","0.27194"
"77424","464.51200","38.70954","0.27359"
"77490","464.90800","38.74248","0.27532"
"77556","465.30400","38.77542","0.27691"
"77622","465.70000","38.80849","0.27968"
"77688","466.09600","38.84149","0.28100"
"77754","466.49200","38.87450","0.28339"
"77820","466.88800","38.90744","0.28529"
"77886","467.28400","38.94044","0.28691"
"77952","467.68000","38.97351","0.28895"
"78018","468.07600","39.00645","0.29168"
"78084","468.47200","39.03946","0.29278"
"78150","468.86800","39.07252","0.29505"
"78216","469.26400","39.10558","0.29672"
"78282","469.66000","39.13846","0.29760"
"78348","470.05600","39.17147","0.29915"
"78414","470.45200","39.20448","0.29952"
"78480","470.84800","39.23748","0.30121"
"78546","471.24400","39.27042","0.30148"
"78612","471.64000","39.30349","0.30277"
"78678","472.03600","39.33649","0.30361"
"78744","472.43200","39.36950","0.30480"
"78810","472.82800","39.40250","0.30575"
"78876","473.22400","39.43544","0.27741"
"78942","473.62000","39.46851","0.01214"
"79008","474.01600","39.50145","0.03797"
"79074","474.41200","39.53445","0.00321"
"79140","474.80800","39.56752","0.03400"
"79206","475.20400","39.60052","0.00827"
"79272","475.60000","39.63346","0.01551"
"79338","475.99600","39.66647","0.01813"
"79404","476.39200","39.69947","0.00757"
"79470","476.78800","39.73254","0.02568"
"79536","477.18400","39.76542","0.01591"
"79602","477.58000","39.79848","0.01495"
"79668","477.97600","39.83149","0.02332"
"79734","478.37200","39.86449","0.01796"
"79800","478.76800","39.89743","0.01844"
"79866","479.16400","39.93050","0.02249"
"79932","479.56000","39.96350","0.02217"
"79998","479.95600","39.99645","0.02086"
"80064","480.35200","40.02939","0.02265"
"80130","480.74800","40.06252","0.02396"
"80196","481.14400","40.09552","0.02388"
"80262","481.54000","40.12840","0.02313"
"80328","481.93600","40.16141","0.02585"
"80394","482.33200","40.19447","0.02598"
"80460","482.72800","40.22753","0.02670"
"80526","483.12400","40.26048","0.02705"
"80560","483.32800","40.27746","0.02763"