File: Trajectories_together/161114Specimen_RawData_6.csv
"","V1","V2","V3"
"1","End date","11/14/2016",""
"2","Specimen label","20BT63.2",""
"3","Maximum Load","0.14899","N"
"4","Time","Extension","Load"
"5","(s)","(mm)","(N)"
"6","0.00000","0.00000","-0.00020"
"38","0.19200","0.01315","0.00025"
"70","0.38400","0.03223","0.00045"
"102","0.57600","0.04819","0.00073"
"134","0.76800","0.06421","0.00025"
"166","0.96000","0.08024","0.00182"
"198","1.15200","0.09620","0.00097"
"230","1.34400","0.11228","0.00215"
"262","1.53600","0.12819","0.00078"
"294","1.72800","0.14421","0.00055"
"326","1.92000","0.16018","0.00136"
"358","2.11200","0.17614","0.00113"
"390","2.30400","0.19216","0.00244"
"422","2.49600","0.20819","0.00188"
"454","2.68800","0.22421","0.00135"
"486","2.88000","0.24017","0.00188"
"518","3.07200","0.25620","0.00234"
"550","3.26400","0.27216","0.00198"
"582","3.45600","0.28825","0.00235"
"614","3.64800","0.30421","0.00246"
"646","3.84000","0.32017","0.00252"
"678","4.03200","0.33626","0.00275"
"710","4.22400","0.35216","0.00201"
"742","4.41600","0.36812","0.00320"
"774","4.60800","0.38421","0.00200"
"806","4.80000","0.40017","0.00288"
"838","4.99200","0.41614","0.00181"
"870","5.18400","0.43216","0.00191"
"902","5.37600","0.44812","0.00280"
"934","5.56800","0.46421","0.00307"
"966","5.76000","0.48023","0.00313"
"998","5.95200","0.49619","0.00261"
"1030","6.14400","0.51216","0.00300"
"1062","6.33600","0.52818","0.00245"
"1094","6.52800","0.54414","0.00311"
"1126","6.72000","0.56023","0.00298"
"1158","6.91200","0.57619","0.00354"
"1190","7.10400","0.59210","0.00341"
"1222","7.29600","0.60824","0.00300"
"1254","7.48800","0.62420","0.00330"
"1286","7.68000","0.64011","0.00299"
"1318","7.87200","0.65625","0.00286"
"1350","8.06400","0.67215","0.00355"
"1382","8.25600","0.68818","0.00347"
"1414","8.44800","0.70426","0.00335"
"1446","8.64000","0.72016","0.00430"
"1478","8.83200","0.73619","0.00372"
"1510","9.02400","0.75221","0.00446"
"1542","9.21600","0.76812","0.00365"
"1574","9.40800","0.78420","0.00372"
"1606","9.60000","0.80022","0.00365"
"1638","9.79200","0.81619","0.00370"
"1670","9.98400","0.83221","0.00383"
"1702","10.17600","0.84817","0.00353"
"1734","10.36800","0.86420","0.00397"
"1766","10.56000","0.88022","0.00371"
"1798","10.75200","0.89619","0.00381"
"1830","10.94400","0.91215","0.00412"
"1862","11.13600","0.92817","0.00316"
"1894","11.32800","0.94420","0.00348"
"1926","11.52000","0.96016","0.00374"
"1958","11.71200","0.97618","0.00442"
"1990","11.90400","0.99215","0.00499"
"2022","12.09600","1.00823","0.00390"
"2054","12.28800","1.02419","0.00392"
"2086","12.48000","1.04016","0.00444"
"2118","12.67200","1.05618","0.00346"
"2150","12.86400","1.07215","0.00489"
"2182","13.05600","1.08817","0.00460"
"2214","13.24800","1.10419","0.00442"
"2246","13.44000","1.12010","0.00375"
"2278","13.63200","1.13618","0.00463"
"2310","13.82400","1.15226","0.00450"
"2342","14.01600","1.16817","0.00508"
"2374","14.20800","1.18419","0.00455"
"2406","14.40000","1.20022","0.00521"
"2438","14.59200","1.21618","0.00469"
"2470","14.78400","1.23226","0.00477"
"2502","14.97600","1.24817","0.00434"
"2534","15.16800","1.26413","0.00557"
"2566","15.36000","1.28021","0.00522"
"2598","15.55200","1.29612","0.00474"
"2630","15.74400","1.31214","0.00534"
"2662","15.93600","1.32828","0.00473"
"2694","16.12800","1.34413","0.00398"
"2726","16.32000","1.36015","0.00505"
"2758","16.51200","1.37624","0.00577"
"2790","16.70400","1.39220","0.00471"
"2822","16.89600","1.40816","0.00538"
"2854","17.08800","1.42425","0.00488"
"2886","17.28000","1.44015","0.00534"
"2918","17.47200","1.45617","0.00423"
"2950","17.66400","1.47220","0.00460"
"2982","17.85600","1.48810","0.00518"
"3014","18.04800","1.50419","0.00450"
"3046","18.24000","1.52021","0.00453"
"3078","18.43200","1.53611","0.00482"
"3110","18.62400","1.55220","0.00462"
"3142","18.81600","1.56822","0.00461"
"3174","19.00800","1.58418","0.00475"
"3206","19.20000","1.60021","0.00558"
"3238","19.39200","1.61617","0.00467"
"3270","19.58400","1.63219","0.00501"
"3302","19.77600","1.64822","0.00474"
"3334","19.96800","1.66412","0.00516"
"3366","20.16000","1.68021","0.00488"
"3398","20.35200","1.69623","0.00492"
"3430","20.54400","1.71213","0.00576"
"3462","20.73600","1.72822","0.00544"
"3494","20.92800","1.74424","0.00466"
"3526","21.12000","1.76014","0.00461"
"3558","21.31200","1.77617","0.00447"
"3590","21.50400","1.79213","0.00518"
"3622","21.69600","1.80816","0.00531"
"3654","21.88800","1.82418","0.00450"
"3686","22.08000","1.84008","0.00518"
"3718","22.27200","1.85623","0.00493"
"3750","22.46400","1.87219","0.00555"
"3782","22.65600","1.88815","0.00489"
"3814","22.84800","1.90424","0.00471"
"3846","23.04000","1.92020","0.00505"
"3878","23.23200","1.93616","0.00529"
"3910","23.42400","1.95219","0.00555"
"3942","23.61600","1.96815","0.00567"
"3974","23.80800","1.98424","0.00529"
"4006","24.00000","2.00020","0.00598"
"4038","24.19200","2.01610","0.00539"
"4070","24.38400","2.03219","0.00500"
"4102","24.57600","2.04821","0.00454"
"4134","24.76800","2.06417","0.00466"
"4166","24.96000","2.08026","0.00499"
"4198","25.15200","2.09622","0.00486"
"4230","25.34400","2.11219","0.00470"
"4262","25.53600","2.12815","0.00531"
"4294","25.72800","2.14423","0.00515"
"4326","25.92000","2.16008","0.00521"
"4358","26.11200","2.17622","0.00448"
"4390","26.30400","2.19218","0.00494"
"4422","26.49600","2.20815","0.00482"
"4454","26.68800","2.22423","0.00457"
"4486","26.88000","2.24019","0.00527"
"4518","27.07200","2.25616","0.00436"
"4550","27.26400","2.27218","0.00474"
"4582","27.45600","2.28815","0.00518"
"4614","27.64800","2.30417","0.00514"
"4646","27.84000","2.32019","0.00503"
"4678","28.03200","2.33616","0.00497"
"4710","28.22400","2.35218","0.00543"
"4742","28.41600","2.36820","0.00487"
"4774","28.60800","2.38411","0.00499"
"4806","28.80000","2.40019","0.00604"
"4838","28.99200","2.41621","0.00521"
"4870","29.18400","2.43218","0.00579"
"4902","29.37600","2.44820","0.00446"
"4934","29.56800","2.46417","0.00472"
"4966","29.76000","2.48019","0.00540"
"4998","29.95200","2.49621","0.00602"
"5030","30.14400","2.51218","0.00541"
"5062","30.33600","2.52814","0.00523"
"5094","30.52800","2.54422","0.00573"
"5126","30.72000","2.56013","0.00534"
"5158","30.91200","2.57621","0.00489"
"5190","31.10400","2.59218","0.00512"
"5222","31.29600","2.60814","0.00528"
"5254","31.48800","2.62422","0.00508"
"5286","31.68000","2.64019","0.00512"
"5318","31.87200","2.65621","0.00437"
"5350","32.06400","2.67217","0.00540"
"5382","32.25600","2.68814","0.00531"
"5414","32.44800","2.70416","0.00591"
"5446","32.64000","2.72018","0.00523"
"5478","32.83200","2.73615","0.00480"
"5510","33.02400","2.75217","0.00445"
"5542","33.21600","2.76820","0.00544"
"5574","33.40800","2.78416","0.00570"
"5606","33.60000","2.80018","0.00552"
"5638","33.79200","2.81621","0.00494"
"5670","33.98400","2.83217","0.00566"
"5702","34.17600","2.84819","0.00621"
"5734","34.36800","2.86416","0.00494"
"5766","34.56000","2.88012","0.00569"
"5798","34.75200","2.89615","0.00529"
"5830","34.94400","2.91217","0.00529"
"5862","35.13600","2.92813","0.00526"
"5894","35.32800","2.94422","0.00469"
"5926","35.52000","2.96018","0.00576"
"5958","35.71200","2.97620","0.00562"
"5990","35.90400","2.99217","0.00577"
"6022","36.09600","3.00813","0.00554"
"6054","36.28800","3.02421","0.00567"
"6086","36.48000","3.04018","0.00530"
"6118","36.67200","3.05608","0.00498"
"6150","36.86400","3.07223","0.00452"
"6182","37.05600","3.08813","0.00583"
"6214","37.24800","3.10415","0.00564"
"6246","37.44000","3.12018","0.00527"
"6278","37.63200","3.13614","0.00631"
"6310","37.82400","3.15216","0.00538"
"6342","38.01600","3.16825","0.00311"
"6374","38.20800","3.18421","0.00466"
"6406","38.40000","3.20017","0.00442"
"6438","38.59200","3.21620","0.00328"
"6470","38.78400","3.23216","0.00401"
"6502","38.97600","3.24813","0.00484"
"6534","39.16800","3.26421","0.00355"
"6566","39.36000","3.28011","0.00423"
"6598","39.55200","3.29620","0.00407"
"6630","39.74400","3.31222","0.00414"
"6662","39.93600","3.32812","0.00400"
"6694","40.12800","3.34421","0.00423"
"6726","40.32000","3.36023","0.00554"
"6758","40.51200","3.37614","0.00446"
"6790","40.70400","3.39216","0.00474"
"6822","40.89600","3.40818","0.00446"
"6854","41.08800","3.42409","0.00443"
"6886","41.28000","3.44023","0.00384"
"6918","41.47200","3.45619","0.00457"
"6950","41.66400","3.47222","0.00417"
"6982","41.85600","3.48824","0.00440"
"7014","42.04800","3.50415","0.00339"
"7046","42.24000","3.52017","0.00496"
"7078","42.43200","3.53619","0.00446"
"7110","42.62400","3.55216","0.00437"
"7142","42.81600","3.56818","0.00401"
"7174","43.00800","3.58420","0.00524"
"7206","43.20000","3.60017","0.00434"
"7238","43.39200","3.61613","0.00441"
"7270","43.58400","3.63215","0.00456"
"7302","43.77600","3.64818","0.00493"
"7334","43.96800","3.66420","0.00441"
"7366","44.16000","3.68017","0.00313"
"7398","44.35200","3.69619","0.00505"
"7430","44.54400","3.71221","0.00421"
"7462","44.73600","3.72818","0.00292"
"7494","44.92800","3.74426","0.00252"
"7526","45.12000","3.76016","0.00351"
"7558","45.31200","3.77613","0.00383"
"7590","45.50400","3.79221","0.00339"
"7622","45.69600","3.80817","0.00282"
"7654","45.88800","3.82420","0.00324"
"7686","46.08000","3.84016","0.00324"
"7718","46.27200","3.85619","0.00315"
"7750","46.46400","3.87221","0.00345"
"7782","46.65600","3.88823","0.00338"
"7814","46.84800","3.90420","0.00273"
"7846","47.04000","3.92022","0.00303"
"7878","47.23200","3.93618","0.00375"
"7910","47.42400","3.95209","0.00366"
"7942","47.61600","3.96817","0.00334"
"7974","47.80800","3.98420","0.00368"
"8006","48.00000","4.00010","0.00352"
"8038","48.19200","4.01624","0.00320"
"8070","48.38400","4.03221","0.00330"
"8102","48.57600","4.04811","0.00302"
"8134","48.76800","4.06425","0.00371"
"8166","48.96000","4.08022","0.00342"
"8198","49.15200","4.09612","0.00328"
"8230","49.34400","4.11226","0.00400"
"8262","49.53600","4.12811","0.00391"
"8294","49.72800","4.14419","0.00392"
"8326","49.92000","4.16022","0.00423"
"8358","50.11200","4.17618","0.00366"
"8390","50.30400","4.19226","0.00406"
"8422","50.49600","4.20823","0.00376"
"8454","50.68800","4.22413","0.00454"
"8486","50.88000","4.24015","0.00368"
"8518","51.07200","4.25624","0.00393"
"8550","51.26400","4.27214","0.00362"
"8582","51.45600","4.28817","0.00385"
"8614","51.64800","4.30419","0.00362"
"8646","51.84000","4.32015","0.00366"
"8678","52.03200","4.33618","0.00482"
"8710","52.22400","4.35220","0.00397"
"8742","52.41600","4.36816","0.00313"
"8774","52.60800","4.38419","0.00411"
"8806","52.80000","4.40015","0.00366"
"8838","52.99200","4.41617","0.00385"
"8870","53.18400","4.43220","0.00386"
"8902","53.37600","4.44816","0.00338"
"8934","53.56800","4.46419","0.00376"
"8966","53.76000","4.48015","0.00311"
"8998","53.95200","4.49617","0.00370"
"9030","54.14400","4.51220","0.00342"
"9062","54.33600","4.52816","0.00312"
"9094","54.52800","4.54418","0.00385"
"9126","54.72000","4.56021","0.00277"
"9158","54.91200","4.57611","0.00430"
"9190","55.10400","4.59219","0.00373"
"9222","55.29600","4.60822","0.00393"
"9254","55.48800","4.62412","0.00362"
"9286","55.68000","4.64021","0.00362"
"9318","55.87200","4.65617","0.00346"
"9350","56.06400","4.67207","0.00445"
"9382","56.25600","4.68822","0.00360"
"9414","56.44800","4.70418","0.00322"
"9446","56.64000","4.72014","0.00405"
"9478","56.83200","4.73623","0.00527"
"9510","57.02400","4.75219","0.00400"
"9542","57.21600","4.76816","0.00446"
"9574","57.40800","4.78424","0.00404"
"9606","57.60000","4.80020","0.00384"
"9638","57.79200","4.81617","0.00434"
"9670","57.98400","4.83219","0.00392"
"9702","58.17600","4.84815","0.00355"
"9734","58.36800","4.86418","0.00419"
"9766","58.56000","4.88026","0.00382"
"9798","58.75200","4.89611","0.00398"
"9830","58.94400","4.91225","0.00271"
"9862","59.13600","4.92821","0.00352"
"9894","59.32800","4.94412","0.00296"
"9926","59.52000","4.96020","0.00331"
"9958","59.71200","4.97622","0.00431"
"9990","59.90400","4.99213","0.00413"
"10022","60.09600","5.00821","0.00364"
"10054","60.28800","5.02411","0.00357"
"10086","60.48000","5.04014","0.00342"
"10118","60.67200","5.05622","0.00322"
"10150","60.86400","5.07219","0.00379"
"10182","61.05600","5.08821","0.00347"
"10214","61.24800","5.10423","0.00382"
"10246","61.44000","5.12014","0.00336"
"10278","61.63200","5.13622","0.00369"
"10310","61.82400","5.15218","0.00400"
"10342","62.01600","5.16821","0.00330"
"10374","62.20800","5.18423","0.00321"
"10406","62.40000","5.20019","0.00375"
"10438","62.59200","5.21610","0.00372"
"10470","62.78400","5.23218","0.00365"
"10502","62.97600","5.24815","0.00408"
"10534","63.16800","5.26423","0.00353"
"10566","63.36000","5.28025","0.00297"
"10598","63.55200","5.29616","0.00295"
"10630","63.74400","5.31218","0.00275"
"10662","63.93600","5.32820","0.00328"
"10694","64.12800","5.34417","0.00332"
"10726","64.32000","5.36019","0.00320"
"10758","64.51200","5.37616","0.00273"
"10790","64.70400","5.39218","0.00297"
"10822","64.89600","5.40820","0.00366"
"10854","65.08800","5.42417","0.00367"
"10886","65.28000","5.44019","0.00322"
"10918","65.47200","5.45621","0.00354"
"10950","65.66400","5.47218","0.00375"
"10982","65.85600","5.48820","0.00304"
"11014","66.04800","5.50416","0.00324"
"11046","66.24000","5.52013","0.00317"
"11078","66.43200","5.53621","0.00346"
"11110","66.62400","5.55218","0.00315"
"11142","66.81600","5.56808","0.00376"
"11174","67.00800","5.58422","0.00304"
"11206","67.20000","5.60019","0.00284"
"11238","67.39200","5.61615","0.00307"
"11270","67.58400","5.63223","0.00337"
"11302","67.77600","5.64820","0.00399"
"11334","67.96800","5.66410","0.00358"
"11366","68.16000","5.68024","0.00301"
"11398","68.35200","5.69615","0.00382"
"11430","68.54400","5.71217","0.00334"
"11462","68.73600","5.72826","0.00361"
"11494","68.92800","5.74410","0.00439"
"11526","69.12000","5.76018","0.00327"
"11558","69.31200","5.77621","0.00343"
"11590","69.50400","5.79217","0.00317"
"11622","69.69600","5.80819","0.00370"
"11654","69.88800","5.82422","0.00360"
"11686","70.08000","5.84012","0.00444"
"11718","70.27200","5.85621","0.00389"
"11750","70.46400","5.87223","0.00358"
"11782","70.65600","5.88819","0.00322"
"11814","70.84800","5.90416","0.00362"
"11846","71.04000","5.92012","0.00352"
"11878","71.23200","5.93620","0.00352"
"11910","71.42400","5.95217","0.00348"
"11942","71.61600","5.96819","0.00415"
"11974","71.80800","5.98416","0.00402"
"12006","72.00000","6.00018","0.00321"
"12038","72.19200","6.01620","0.00419"
"12070","72.38400","6.03217","0.00363"
"12102","72.57600","6.04819","0.00349"
"12134","72.76800","6.06415","0.00353"
"12166","72.96000","6.08018","0.00304"
"12198","73.15200","6.09614","0.00346"
"12230","73.34400","6.11216","0.00418"
"12262","73.53600","6.12819","0.00359"
"12294","73.72800","6.14415","0.00394"
"12326","73.92000","6.16017","0.00310"
"12358","74.11200","6.17620","0.00419"
"12390","74.30400","6.19210","0.00373"
"12422","74.49600","6.20825","0.00414"
"12454","74.68800","6.22421","0.00303"
"12486","74.88000","6.24017","0.00434"
"12518","75.07200","6.25620","0.00442"
"12550","75.26400","6.27216","0.00380"
"12582","75.45600","6.28819","0.00413"
"12614","75.64800","6.30415","0.00419"
"12646","75.84000","6.32017","0.00431"
"12678","76.03200","6.33620","0.00444"
"12710","76.22400","6.35222","0.00359"
"12742","76.41600","6.36818","0.00457"
"12774","76.60800","6.38421","0.00431"
"12806","76.80000","6.40023","0.00502"
"12838","76.99200","6.41613","0.00439"
"12870","77.18400","6.43216","0.00429"
"12902","77.37600","6.44818","0.00412"
"12934","77.56800","6.46409","0.00453"
"12966","77.76000","6.48023","0.00391"
"12998","77.95200","6.49619","0.00431"
"13030","78.14400","6.51216","0.00414"
"13062","78.33600","6.52824","0.00420"
"13094","78.52800","6.54420","0.00521"
"13126","78.72000","6.56017","0.00412"
"13158","78.91200","6.57619","0.00454"
"13190","79.10400","6.59215","0.00338"
"13222","79.29600","6.60818","0.00403"
"13254","79.48800","6.62420","0.00386"
"13286","79.68000","6.64017","0.00508"
"13318","79.87200","6.65619","0.00355"
"13350","80.06400","6.67221","0.00466"
"13382","80.25600","6.68818","0.00412"
"13414","80.44800","6.70420","0.00400"
"13446","80.64000","6.72022","0.00403"
"13478","80.83200","6.73613","0.00427"
"13510","81.02400","6.75215","0.00482"
"13542","81.21600","6.76824","0.00465"
"13574","81.40800","6.78420","0.00427"
"13606","81.60000","6.80022","0.00485"
"13638","81.79200","6.81619","0.00386"
"13670","81.98400","6.83215","0.00422"
"13702","82.17600","6.84817","0.00368"
"13734","82.36800","6.86420","0.00437"
"13766","82.56000","6.88022","0.00406"
"13798","82.75200","6.89618","0.00441"
"13830","82.94400","6.91215","0.00441"
"13862","83.13600","6.92823","0.00512"
"13894","83.32800","6.94420","0.00466"
"13926","83.52000","6.96016","0.00472"
"13958","83.71200","6.97618","0.00482"
"13990","83.90400","6.99215","0.00436"
"14022","84.09600","7.00817","0.00501"
"14054","84.28800","7.02419","0.00446"
"14086","84.48000","7.04016","0.00492"
"14118","84.67200","7.05624","0.00421"
"14150","84.86400","7.07221","0.00450"
"14182","85.05600","7.08811","0.00529"
"14214","85.24800","7.10419","0.00452"
"14246","85.44000","7.12022","0.00510"
"14278","85.63200","7.13612","0.00437"
"14310","85.82400","7.15214","0.00491"
"14342","86.01600","7.16817","0.00478"
"14374","86.20800","7.18413","0.00405"
"14406","86.40000","7.20015","0.00411"
"14438","86.59200","7.21624","0.00360"
"14470","86.78400","7.23220","0.00446"
"14502","86.97600","7.24823","0.00494"
"14534","87.16800","7.26419","0.00423"
"14566","87.36000","7.28021","0.00431"
"14598","87.55200","7.29624","0.00461"
"14630","87.74400","7.31214","0.00385"
"14662","87.93600","7.32816","0.00482"
"14694","88.12800","7.34419","0.00416"
"14726","88.32000","7.36009","0.00439"
"14758","88.51200","7.37617","0.00420"
"14790","88.70400","7.39220","0.00390"
"14822","88.89600","7.40816","0.00382"
"14854","89.08800","7.42425","0.00456"
"14886","89.28000","7.44021","0.00456"
"14918","89.47200","7.45611","0.00412"
"14950","89.66400","7.47226","0.00480"
"14982","89.85600","7.48816","0.00434"
"15014","90.04800","7.50418","0.00441"
"15046","90.24000","7.52021","0.00451"
"15078","90.43200","7.53611","0.00486"
"15110","90.62400","7.55220","0.00423"
"15142","90.81600","7.56828","0.00406"
"15174","91.00800","7.58412","0.00384"
"15206","91.20000","7.60021","0.00421"
"15238","91.39200","7.61623","0.00437"
"15270","91.58400","7.63207","0.00364"
"15302","91.77600","7.64822","0.00405"
"15334","91.96800","7.66424","0.00398"
"15366","92.16000","7.68015","0.00415"
"15398","92.35200","7.69617","0.00425"
"15430","92.54400","7.71219","0.00463"
"15462","92.73600","7.72816","0.00452"
"15494","92.92800","7.74424","0.00526"
"15526","93.12000","7.76020","0.00455"
"15558","93.31200","7.77617","0.00473"
"15590","93.50400","7.79219","0.00446"
"15622","93.69600","7.80816","0.00508"
"15654","93.88800","7.82418","0.00447"
"15686","94.08000","7.84020","0.00479"
"15718","94.27200","7.85616","0.00445"
"15750","94.46400","7.87219","0.00470"
"15782","94.65600","7.88815","0.00467"
"15814","94.84800","7.90418","0.00460"
"15846","95.04000","7.92020","0.00467"
"15878","95.23200","7.93616","0.00448"
"15910","95.42400","7.95219","0.00429"
"15942","95.61600","7.96821","0.00514"
"15974","95.80800","7.98417","0.00465"
"16006","96.00000","8.00020","0.00429"
"16038","96.19200","8.01622","0.00488"
"16070","96.38400","8.03213","0.00467"
"16102","96.57600","8.04821","0.00428"
"16134","96.76800","8.06417","0.00345"
"16166","96.96000","8.08008","0.00538"
"16198","97.15200","8.09622","0.00506"
"16230","97.34400","8.11212","0.00431"
"16262","97.53600","8.12815","0.00493"
"16294","97.72800","8.14423","0.00417"
"16326","97.92000","8.16020","0.00502"
"16358","98.11200","8.17616","0.00436"
"16390","98.30400","8.19218","0.00369"
"16422","98.49600","8.20815","0.00427"
"16454","98.68800","8.22417","0.00440"
"16486","98.88000","8.24019","0.00395"
"16518","99.07200","8.25610","0.00486"
"16550","99.26400","8.27218","0.00477"
"16582","99.45600","8.28820","0.00476"
"16614","99.64800","8.30417","0.00568"
"16646","99.84000","8.32019","0.00472"
"16678","100.03200","8.33622","0.00486"
"16710","100.22400","8.35212","0.00506"
"16742","100.41600","8.36820","0.00457"
"16774","100.60800","8.38423","0.00422"
"16806","100.80000","8.40013","0.00528"
"16838","100.99200","8.41621","0.00513"
"16870","101.18400","8.43212","0.00581"
"16902","101.37600","8.44814","0.00430"
"16934","101.56800","8.46422","0.00428"
"16966","101.76000","8.48013","0.00479"
"16998","101.95200","8.49621","0.00550"
"17030","102.14400","8.51224","0.00474"
"17062","102.33600","8.52814","0.00533"
"17094","102.52800","8.54416","0.00513"
"17126","102.72000","8.56019","0.00481"
"17158","102.91200","8.57615","0.00543"
"17190","103.10400","8.59217","0.00540"
"17222","103.29600","8.60814","0.00499"
"17254","103.48800","8.62416","0.00530"
"17286","103.68000","8.64019","0.00431"
"17318","103.87200","8.65621","0.00493"
"17350","104.06400","8.67217","0.00533"
"17382","104.25600","8.68820","0.00534"
"17414","104.44800","8.70416","0.00487"
"17446","104.64000","8.72018","0.00513"
"17478","104.83200","8.73615","0.00535"
"17510","105.02400","8.75217","0.00445"
"17542","105.21600","8.76819","0.00501"
"17574","105.40800","8.78416","0.00477"
"17606","105.60000","8.80018","0.00479"
"17638","105.79200","8.81621","0.00511"
"17670","105.98400","8.83217","0.00531"
"17702","106.17600","8.84819","0.00538"
"17734","106.36800","8.86422","0.00518"
"17766","106.56000","8.88012","0.00522"
"17798","106.75200","8.89620","0.00511"
"17830","106.94400","8.91223","0.00502"
"17862","107.13600","8.92813","0.00420"
"17894","107.32800","8.94421","0.00538"
"17926","107.52000","8.96018","0.00486"
"17958","107.71200","8.97608","0.00604"
"17990","107.90400","8.99223","0.00560"
"18022","108.09600","9.00819","0.00492"
"18054","108.28800","9.02415","0.00556"
"18086","108.48000","9.04024","0.00556"
"18118","108.67200","9.05614","0.00504"
"18150","108.86400","9.07211","0.00577"
"18182","109.05600","9.08825","0.00529"
"18214","109.24800","9.10415","0.00515"
"18246","109.44000","9.12018","0.00600"
"18278","109.63200","9.13620","0.00509"
"18310","109.82400","9.15210","0.00585"
"18342","110.01600","9.16819","0.00488"
"18374","110.20800","9.18427","0.00501"
"18406","110.40000","9.20012","0.00498"
"18438","110.59200","9.21620","0.00612"
"18470","110.78400","9.23216","0.00526"
"18502","110.97600","9.24819","0.00528"
"18534","111.16800","9.26415","0.00568"
"18566","111.36000","9.28017","0.00604"
"18598","111.55200","9.29614","0.00514"
"18630","111.74400","9.31216","0.00517"
"18662","111.93600","9.32818","0.00497"
"18694","112.12800","9.34415","0.00562"
"18726","112.32000","9.36017","0.00516"
"18758","112.51200","9.37619","0.00517"
"18790","112.70400","9.39222","0.00551"
"18822","112.89600","9.40818","0.00545"
"18854","113.08800","9.42415","0.00532"
"18886","113.28000","9.44017","0.00555"
"18918","113.47200","9.45619","0.00607"
"18950","113.66400","9.47216","0.00492"
"18982","113.85600","9.48818","0.00573"
"19014","114.04800","9.50414","0.00433"
"19046","114.24000","9.52017","0.00539"
"19078","114.43200","9.53619","0.00609"
"19110","114.62400","9.55216","0.00499"
"19142","114.81600","9.56818","0.00530"
"19174","115.00800","9.58420","0.00617"
"19206","115.20000","9.60011","0.00549"
"19238","115.39200","9.61619","0.00531"
"19270","115.58400","9.63221","0.00523"
"19302","115.77600","9.64818","0.00530"
"19334","115.96800","9.66420","0.00456"
"19366","116.16000","9.68010","0.00575"
"19398","116.35200","9.69613","0.00531"
"19430","116.54400","9.71221","0.00521"
"19462","116.73600","9.72818","0.00574"
"19494","116.92800","9.74420","0.00565"
"19526","117.12000","9.76022","0.00505"
"19558","117.31200","9.77613","0.00636"
"19590","117.50400","9.79215","0.00512"
"19622","117.69600","9.80817","0.00615"
"19654","117.88800","9.82414","0.00526"
"19686","118.08000","9.84022","0.00552"
"19718","118.27200","9.85618","0.00510"
"19750","118.46400","9.87209","0.00585"
"19782","118.65600","9.88823","0.00588"
"19814","118.84800","9.90420","0.00496"
"19846","119.04000","9.92016","0.00521"
"19878","119.23200","9.93624","0.00550"
"19910","119.42400","9.95215","0.00580"
"19942","119.61600","9.96817","0.00504"
"19974","119.80800","9.98425","0.00489"
"20006","120.00000","10.00016","0.00557"
"20038","120.19200","10.01618","0.00614"
"20070","120.38400","10.03221","0.00521"
"20102","120.57600","10.04811","0.00584"
"20134","120.76800","10.06419","0.00571"
"20166","120.96000","10.08028","0.00570"
"20198","121.15200","10.09612","0.00543"
"20230","121.34400","10.11220","0.00563"
"20262","121.53600","10.12823","0.00612"
"20294","121.72800","10.14413","0.00544"
"20326","121.92000","10.16015","0.00504"
"20358","122.11200","10.17618","0.00571"
"20390","122.30400","10.19220","0.00619"
"20422","122.49600","10.20823","0.00602"
"20454","122.68800","10.22413","0.00602"
"20486","122.88000","10.24015","0.00500"
"20518","123.07200","10.25618","0.00577"
"20550","123.26400","10.27220","0.00552"
"20582","123.45600","10.28822","0.00579"
"20614","123.64800","10.30419","0.00601"
"20646","123.84000","10.32015","0.00669"
"20678","124.03200","10.33618","0.00625"
"20710","124.22400","10.35214","0.00650"
"20742","124.41600","10.36816","0.00665"
"20774","124.60800","10.38419","0.00614"
"20806","124.80000","10.40015","0.00547"
"20838","124.99200","10.41617","0.00621"
"20870","125.18400","10.43220","0.00631"
"20902","125.37600","10.44816","0.00576"
"20934","125.56800","10.46418","0.00565"
"20966","125.76000","10.48021","0.00637"
"20998","125.95200","10.49611","0.00642"
"21030","126.14400","10.51220","0.00515"
"21062","126.33600","10.52822","0.00649"
"21094","126.52800","10.54412","0.00483"
"21126","126.72000","10.56021","0.00667"
"21158","126.91200","10.57617","0.00614"
"21190","127.10400","10.59213","0.00666"
"21222","127.29600","10.60822","0.00682"
"21254","127.48800","10.62418","0.00593"
"21286","127.68000","10.64015","0.00612"
"21318","127.87200","10.65617","0.00587"
"21350","128.06400","10.67219","0.00622"
"21382","128.25600","10.68816","0.00720"
"21414","128.44800","10.70424","0.00597"
"21446","128.64000","10.72014","0.00561"
"21478","128.83200","10.73617","0.00637"
"21510","129.02400","10.75219","0.00681"
"21542","129.21600","10.76810","0.00587"
"21574","129.40800","10.78424","0.00605"
"21606","129.60000","10.80020","0.00584"
"21638","129.79200","10.81611","0.00649"
"21670","129.98400","10.83219","0.00588"
"21702","130.17600","10.84815","0.00580"
"21734","130.36800","10.86418","0.00752"
"21766","130.56000","10.88020","0.00632"
"21798","130.75200","10.89616","0.00674"
"21830","130.94400","10.91213","0.00683"
"21862","131.13600","10.92821","0.00636"
"21894","131.32800","10.94418","0.00582"
"21926","131.52000","10.96020","0.00674"
"21958","131.71200","10.97616","0.00729"
"21990","131.90400","10.99219","0.00600"
"22022","132.09600","11.00821","0.00714"
"22054","132.28800","11.02423","0.00597"
"22086","132.48000","11.04014","0.00710"
"22118","132.67200","11.05616","0.00652"
"22150","132.86400","11.07224","0.00708"
"22182","133.05600","11.08815","0.00659"
"22214","133.24800","11.10417","0.00655"
"22246","133.44000","11.12014","0.00766"
"22278","133.63200","11.13622","0.00682"
"22310","133.82400","11.15224","0.00683"
"22342","134.01600","11.16815","0.00678"
"22374","134.20800","11.18423","0.00586"
"22406","134.40000","11.20019","0.00712"
"22438","134.59200","11.21616","0.00685"
"22470","134.78400","11.23218","0.00748"
"22502","134.97600","11.24821","0.00677"
"22534","135.16800","11.26417","0.00759"
"22566","135.36000","11.28019","0.00682"
"22598","135.55200","11.29616","0.00724"
"22630","135.74400","11.31218","0.00655"
"22662","135.93600","11.32820","0.00806"
"22694","136.12800","11.34417","0.00783"
"22726","136.32000","11.36019","0.00774"
"22758","136.51200","11.37621","0.00735"
"22790","136.70400","11.39218","0.00663"
"22822","136.89600","11.40820","0.00750"
"22854","137.08800","11.42423","0.00827"
"22886","137.28000","11.44013","0.00710"
"22918","137.47200","11.45627","0.00765"
"22950","137.66400","11.47218","0.00863"
"22982","137.85600","11.48808","0.00793"
"23014","138.04800","11.50422","0.00792"
"23046","138.24000","11.52019","0.00807"
"23078","138.43200","11.53615","0.00811"
"23110","138.62400","11.55223","0.00832"
"23142","138.81600","11.56814","0.00886"
"23174","139.00800","11.58416","0.00815"
"23206","139.20000","11.60019","0.00751"
"23238","139.39200","11.61621","0.00825"
"23270","139.58400","11.63217","0.00861"
"23302","139.77600","11.64820","0.00793"
"23334","139.96800","11.66416","0.00860"
"23366","140.16000","11.68018","0.00782"
"23398","140.35200","11.69621","0.00883"
"23430","140.54400","11.71211","0.00883"
"23462","140.73600","11.72820","0.00816"
"23494","140.92800","11.74422","0.00775"
"23526","141.12000","11.76012","0.01013"
"23558","141.31200","11.77621","0.00936"
"23590","141.50400","11.79217","0.00946"
"23622","141.69600","11.80819","0.00894"
"23654","141.88800","11.82422","0.00994"
"23686","142.08000","11.84018","0.00953"
"23718","142.27200","11.85620","0.00969"
"23750","142.46400","11.87223","0.00989"
"23782","142.65600","11.88807","0.00948"
"23814","142.84800","11.90422","0.00976"
"23846","143.04000","11.92024","0.00931"
"23878","143.23200","11.93608","0.01013"
"23910","143.42400","11.95223","0.01035"
"23942","143.61600","11.96819","0.00999"
"23974","143.80800","11.98415","0.00911"
"24006","144.00000","12.00018","0.01036"
"24038","144.19200","12.01620","0.00960"
"24070","144.38400","12.03217","0.01018"
"24102","144.57600","12.04819","0.00873"
"24134","144.76800","12.06415","0.00742"
"24166","144.96000","12.08024","0.00836"
"24198","145.15200","12.09620","0.00770"
"24230","145.34400","12.11216","0.00823"
"24262","145.53600","12.12819","0.00957"
"24294","145.72800","12.14421","0.00833"
"24326","145.92000","12.16018","0.00789"
"24358","146.11200","12.17620","0.00902"
"24390","146.30400","12.19216","0.00909"
"24422","146.49600","12.20819","0.00940"
"24454","146.68800","12.22421","0.01024"
"24486","146.88000","12.24017","0.00899"
"24518","147.07200","12.25620","0.00823"
"24550","147.26400","12.27216","0.00895"
"24582","147.45600","12.28812","0.00911"
"24614","147.64800","12.30421","0.00807"
"24646","147.84000","12.32017","0.00864"
"24678","148.03200","12.33614","0.00829"
"24710","148.22400","12.35222","0.00734"
"24742","148.41600","12.36812","0.00824"
"24774","148.60800","12.38415","0.00864"
"24806","148.80000","12.40023","0.00936"
"24838","148.99200","12.41613","0.00811"
"24870","149.18400","12.43216","0.00807"
"24902","149.37600","12.44818","0.00777"
"24934","149.56800","12.46415","0.00797"
"24966","149.76000","12.48017","0.00872"
"24998","149.95200","12.49619","0.00888"
"25030","150.14400","12.51216","0.00784"
"25062","150.33600","12.52818","0.00850"
"25094","150.52800","12.54420","0.00801"
"25126","150.72000","12.56011","0.00865"
"25158","150.91200","12.57619","0.00835"
"25190","151.10400","12.59221","0.00898"
"25222","151.29600","12.60812","0.00844"
"25254","151.48800","12.62420","0.00968"
"25286","151.68000","12.64023","0.01040"
"25318","151.87200","12.65607","0.00977"
"25350","152.06400","12.67221","0.01030"
"25382","152.25600","12.68818","0.00925"
"25414","152.44800","12.70414","0.00951"
"25446","152.64000","12.72016","0.00920"
"25478","152.83200","12.73613","0.00979"
"25510","153.02400","12.75215","0.00895"
"25542","153.21600","12.76824","0.00897"
"25574","153.40800","12.78414","0.01027"
"25606","153.60000","12.80022","0.00969"
"25638","153.79200","12.81625","0.00950"
"25670","153.98400","12.83215","0.01034"
"25702","154.17600","12.84817","0.00924"
"25734","154.36800","12.86420","0.00910"
"25766","154.56000","12.88016","0.00998"
"25798","154.75200","12.89618","0.00969"
"25830","154.94400","12.91215","0.00976"
"25862","155.13600","12.92817","0.01064"
"25894","155.32800","12.94420","0.01029"
"25926","155.52000","12.96016","0.01049"
"25958","155.71200","12.97618","0.01017"
"25990","155.90400","12.99215","0.01052"
"26022","156.09600","13.00817","0.01087"
"26054","156.28800","13.02419","0.01104"
"26086","156.48000","13.04022","0.01104"
"26118","156.67200","13.05618","0.01113"
"26150","156.86400","13.07226","0.01113"
"26182","157.05600","13.08817","0.01146"
"26214","157.24800","13.10413","0.01102"
"26246","157.44000","13.12016","0.01156"
"26278","157.63200","13.13612","0.01228"
"26310","157.82400","13.15220","0.01167"
"26342","158.01600","13.16817","0.01151"
"26374","158.20800","13.18413","0.01060"
"26406","158.40000","13.20021","0.01215"
"26438","158.59200","13.21624","0.01233"
"26470","158.78400","13.23214","0.01194"
"26502","158.97600","13.24822","0.01239"
"26534","159.16800","13.26419","0.01206"
"26566","159.36000","13.28009","0.01135"
"26598","159.55200","13.29624","0.01277"
"26630","159.74400","13.31220","0.01221"
"26662","159.93600","13.32810","0.01283"
"26694","160.12800","13.34425","0.01336"
"26726","160.32000","13.36021","0.01345"
"26758","160.51200","13.37611","0.01293"
"26790","160.70400","13.39220","0.01353"
"26822","160.89600","13.40816","0.01319"
"26854","161.08800","13.42413","0.01324"
"26886","161.28000","13.44021","0.01345"
"26918","161.47200","13.45611","0.01307"
"26950","161.66400","13.47220","0.01469"
"26982","161.85600","13.48822","0.01378"
"27014","162.04800","13.50418","0.01506"
"27046","162.24000","13.52021","0.01412"
"27078","162.43200","13.53617","0.01503"
"27110","162.62400","13.55220","0.01503"
"27142","162.81600","13.56816","0.01577"
"27174","163.00800","13.58418","0.01561"
"27206","163.20000","13.60015","0.01580"
"27238","163.39200","13.61617","0.01486"
"27270","163.58400","13.63213","0.01495"
"27302","163.77600","13.64816","0.01605"
"27334","163.96800","13.66424","0.01551"
"27366","164.16000","13.68020","0.01592"
"27398","164.35200","13.69623","0.01639"
"27430","164.54400","13.71219","0.01554"
"27462","164.73600","13.72816","0.01593"
"27494","164.92800","13.74424","0.01657"
"27526","165.12000","13.76014","0.01705"
"27558","165.31200","13.77617","0.01681"
"27590","165.50400","13.79219","0.01628"
"27622","165.69600","13.80815","0.01724"
"27654","165.88800","13.82418","0.01682"
"27686","166.08000","13.84020","0.01758"
"27718","166.27200","13.85616","0.01779"
"27750","166.46400","13.87219","0.01754"
"27782","166.65600","13.88821","0.01833"
"27814","166.84800","13.90411","0.01871"
"27846","167.04000","13.92020","0.01812"
"27878","167.23200","13.93616","0.01907"
"27910","167.42400","13.95213","0.01869"
"27942","167.61600","13.96821","0.01957"
"27974","167.80800","13.98417","0.01958"
"28006","168.00000","14.00014","0.01983"
"28038","168.19200","14.01622","0.02026"
"28070","168.38400","14.03219","0.01971"
"28102","168.57600","14.04815","0.02075"
"28134","168.76800","14.06417","0.01994"
"28166","168.96000","14.08014","0.02114"
"28198","169.15200","14.09622","0.02137"
"28230","169.34400","14.11224","0.02140"
"28262","169.53600","14.12815","0.02164"
"28294","169.72800","14.14417","0.02184"
"28326","169.92000","14.16020","0.02219"
"28358","170.11200","14.17610","0.02212"
"28390","170.30400","14.19218","0.02317"
"28422","170.49600","14.20821","0.02336"
"28454","170.68800","14.22411","0.02306"
"28486","170.88000","14.24025","0.02370"
"28518","171.07200","14.25616","0.02443"
"28550","171.26400","14.27212","0.02472"
"28582","171.45600","14.28820","0.02519"
"28614","171.64800","14.30417","0.02517"
"28646","171.84000","14.32019","0.02502"
"28678","172.03200","14.33622","0.02553"
"28710","172.22400","14.35218","0.02623"
"28742","172.41600","14.36820","0.02702"
"28774","172.60800","14.38423","0.02671"
"28806","172.80000","14.40013","0.02684"
"28838","172.99200","14.41615","0.02725"
"28870","173.18400","14.43224","0.02782"
"28902","173.37600","14.44814","0.02817"
"28934","173.56800","14.46416","0.02863"
"28966","173.76000","14.48019","0.02878"
"28998","173.95200","14.49615","0.02916"
"29030","174.14400","14.51218","0.02932"
"29062","174.33600","14.52820","0.02939"
"29094","174.52800","14.54416","0.03106"
"29126","174.72000","14.56019","0.03058"
"29158","174.91200","14.57621","0.03095"
"29190","175.10400","14.59217","0.03144"
"29222","175.29600","14.60820","0.03216"
"29254","175.48800","14.62410","0.03181"
"29286","175.68000","14.64025","0.03245"
"29318","175.87200","14.65621","0.03389"
"29350","176.06400","14.67217","0.03389"
"29382","176.25600","14.68820","0.03409"
"29414","176.44800","14.70410","0.03517"
"29446","176.64000","14.72018","0.03507"
"29478","176.83200","14.73621","0.03589"
"29510","177.02400","14.75217","0.03605"
"29542","177.21600","14.76820","0.03627"
"29574","177.40800","14.78416","0.03757"
"29606","177.60000","14.80018","0.03790"
"29638","177.79200","14.81621","0.03853"
"29670","177.98400","14.83223","0.03895"
"29702","178.17600","14.84813","0.03961"
"29734","178.36800","14.86422","0.03987"
"29766","178.56000","14.88018","0.04062"
"29798","178.75200","14.89614","0.04076"
"29830","178.94400","14.91223","0.04147"
"29862","179.13600","14.92819","0.04238"
"29894","179.32800","14.94416","0.04197"
"29926","179.52000","14.96018","0.04310"
"29958","179.71200","14.97614","0.04307"
"29990","179.90400","14.99217","0.04411"
"30022","180.09600","15.00825","0.04444"
"30054","180.28800","15.02415","0.04469"
"30086","180.48000","15.04018","0.04484"
"30118","180.67200","15.05620","0.04540"
"30150","180.86400","15.07211","0.04578"
"30182","181.05600","15.08819","0.04635"
"30214","181.24800","15.10421","0.04675"
"30246","181.44000","15.12012","0.04728"
"30278","181.63200","15.13620","0.04748"
"30310","181.82400","15.15216","0.04838"
"30342","182.01600","15.16813","0.04837"
"30374","182.20800","15.18421","0.04876"
"30406","182.40000","15.20017","0.04923"
"30438","182.59200","15.21620","0.04941"
"30470","182.78400","15.23222","0.05003"
"30502","182.97600","15.24813","0.05058"
"30534","183.16800","15.26421","0.05090"
"30566","183.36000","15.28017","0.05093"
"30598","183.55200","15.29620","0.05121"
"30630","183.74400","15.31216","0.05115"
"30662","183.93600","15.32818","0.05144"
"30694","184.12800","15.34415","0.05172"
"30726","184.32000","15.36017","0.05207"
"30758","184.51200","15.37619","0.05279"
"30790","184.70400","15.39216","0.05287"
"30822","184.89600","15.40818","0.05296"
"30854","185.08800","15.42415","0.05321"
"30886","185.28000","15.44017","0.05373"
"30918","185.47200","15.45619","0.05375"
"30950","185.66400","15.47216","0.05408"
"30982","185.85600","15.48818","0.05427"
"31014","186.04800","15.50420","0.05435"
"31046","186.24000","15.52017","0.05463"
"31078","186.43200","15.53619","0.05524"
"31110","186.62400","15.55222","0.05533"
"31142","186.81600","15.56812","0.05547"
"31174","187.00800","15.58420","0.05582"
"31206","187.20000","15.60017","0.05585"
"31238","187.39200","15.61613","0.05609"
"31270","187.58400","15.63215","0.05623"
"31302","187.77600","15.64818","0.05636"
"31334","187.96800","15.66420","0.05650"
"31366","188.16000","15.68022","0.05668"
"31398","188.35200","15.69613","0.05688"
"31430","188.54400","15.71221","0.05691"
"31462","188.73600","15.72823","0.05687"
"31494","188.92800","15.74414","0.05708"
"31526","189.12000","15.76022","0.05708"
"31558","189.31200","15.77619","0.05727"
"31590","189.50400","15.79209","0.05733"
"31622","189.69600","15.80823","0.05736"
"31654","189.88800","15.82420","0.05747"
"31686","190.08000","15.84010","0.05750"
"31718","190.27200","15.85618","0.05756"
"31750","190.46400","15.87221","0.05766"
"31782","190.65600","15.88817","0.05769"
"31814","190.84800","15.90420","0.05783"
"31846","191.04000","15.92016","0.05783"
"31878","191.23200","15.93618","0.05794"
"31910","191.42400","15.95221","0.05807"
"31942","191.61600","15.96817","0.05821"
"31974","191.80800","15.98419","0.05824"
"32006","192.00000","16.00022","0.05848"
"32038","192.19200","16.01612","0.05852"
"32070","192.38400","16.03220","0.05915"
"32102","192.57600","16.04817","0.05916"
"32134","192.76800","16.06419","0.05905"
"32166","192.96000","16.08022","0.05956"
"32198","193.15200","16.09624","0.05980"
"32230","193.34400","16.11214","0.06012"
"32262","193.53600","16.12817","0.06042"
"32294","193.72800","16.14413","0.06063"
"32326","193.92000","16.16015","0.06108"
"32358","194.11200","16.17624","0.06127"
"32390","194.30400","16.19214","0.06163"
"32422","194.49600","16.20822","0.06215"
"32454","194.68800","16.22419","0.06235"
"32486","194.88000","16.24015","0.06289"
"32518","195.07200","16.25624","0.06355"
"32550","195.26400","16.27220","0.06388"
"32582","195.45600","16.28816","0.06418"
"32614","195.64800","16.30413","0.06471"
"32646","195.84000","16.32015","0.06506"
"32678","196.03200","16.33617","0.06541"
"32710","196.22400","16.35220","0.06553"
"32742","196.41600","16.36816","0.06615"
"32774","196.60800","16.38418","0.06655"
"32806","196.80000","16.40021","0.06723"
"32838","196.99200","16.41617","0.06746"
"32870","197.18400","16.43220","0.06740"
"32902","197.37600","16.44822","0.06768"
"32934","197.56800","16.46418","0.06793"
"32966","197.76000","16.48021","0.06849"
"32998","197.95200","16.49617","0.06875"
"33030","198.14400","16.51213","0.06864"
"33062","198.33600","16.52822","0.06928"
"33094","198.52800","16.54418","0.06925"
"33126","198.72000","16.56015","0.06987"
"33158","198.91200","16.57617","0.07017"
"33190","199.10400","16.59219","0.07087"
"33222","199.29600","16.60816","0.07083"
"33254","199.48800","16.62418","0.07113"
"33286","199.68000","16.64014","0.07183"
"33318","199.87200","16.65617","0.07205"
"33350","200.06400","16.67219","0.07321"
"33382","200.25600","16.68815","0.07432"
"33414","200.44800","16.70424","0.07572"
"33446","200.64000","16.72014","0.07646"
"33478","200.83200","16.73611","0.07719"
"33510","201.02400","16.75225","0.07842"
"33542","201.21600","16.76815","0.07999"
"33574","201.40800","16.78418","0.08107"
"33606","201.60000","16.80026","0.08298"
"33638","201.79200","16.81610","0.08424"
"33670","201.98400","16.83219","0.08479"
"33702","202.17600","16.84821","0.08618"
"33734","202.36800","16.86411","0.08744"
"33766","202.56000","16.88020","0.08767"
"33798","202.75200","16.89622","0.08848"
"33830","202.94400","16.91213","0.08898"
"33862","203.13600","16.92821","0.08969"
"33894","203.32800","16.94423","0.09017"
"33926","203.52000","16.96014","0.09079"
"33958","203.71200","16.97622","0.09128"
"33990","203.90400","16.99219","0.09183"
"34022","204.09600","17.00815","0.09185"
"34054","204.28800","17.02417","0.09189"
"34086","204.48000","17.04020","0.09287"
"34118","204.67200","17.05616","0.09321"
"34150","204.86400","17.07218","0.09396"
"34182","205.05600","17.08815","0.09453"
"34214","205.24800","17.10417","0.09541"
"34246","205.44000","17.12019","0.09580"
"34278","205.63200","17.13622","0.09592"
"34310","205.82400","17.15218","0.09635"
"34342","206.01600","17.16821","0.09717"
"34374","206.20800","17.18417","0.09740"
"34406","206.40000","17.20013","0.09804"
"34438","206.59200","17.21616","0.09834"
"34470","206.78400","17.23218","0.09886"
"34502","206.97600","17.24814","0.09972"
"34534","207.16800","17.26417","0.10002"
"34566","207.36000","17.28013","0.10107"
"34598","207.55200","17.29622","0.10178"
"34630","207.74400","17.31218","0.10275"
"34662","207.93600","17.32814","0.10385"
"34694","208.12800","17.34422","0.10534"
"34726","208.32000","17.36013","0.10639"
"34758","208.51200","17.37621","0.10624"
"34790","208.70400","17.39212","0.10797"
"34822","208.89600","17.40814","0.10915"
"34854","209.08800","17.42422","0.10998"
"34886","209.28000","17.44013","0.11163"
"34918","209.47200","17.45615","0.11360"
"34950","209.66400","17.47218","0.11471"
"34982","209.85600","17.48814","0.11643"
"35014","210.04800","17.50422","0.11707"
"35046","210.24000","17.52019","0.11874"
"35078","210.43200","17.53615","0.12104"
"35110","210.62400","17.55223","0.12020"
"35142","210.81600","17.56820","0.12142"
"35174","211.00800","17.58410","0.12247"
"35206","211.20000","17.60018","0.12455"
"35238","211.39200","17.61621","0.12543"
"35270","211.58400","17.63211","0.12769"
"35302","211.77600","17.64820","0.12970"
"35334","211.96800","17.66422","0.13106"
"35366","212.16000","17.68012","0.13301"
"35398","212.35200","17.69627","0.13375"
"35430","212.54400","17.71217","0.13449"
"35462","212.73600","17.72813","0.13504"
"35494","212.92800","17.74422","0.13631"
"35526","213.12000","17.76018","0.13664"
"35558","213.31200","17.77614","0.13770"
"35590","213.50400","17.79223","0.13784"
"35622","213.69600","17.80807","0.13876"
"35654","213.88800","17.82416","0.13943"
"35686","214.08000","17.84024","0.14019"
"35718","214.27200","17.85620","0.14041"
"35750","214.46400","17.87217","0.14091"
"35782","214.65600","17.88819","0.14161"
"35814","214.84800","17.90416","0.14178"
"35846","215.04000","17.92018","0.14189"
"35878","215.23200","17.93614","0.14212"
"35910","215.42400","17.95217","0.14266"
"35942","215.61600","17.96819","0.14265"
"35974","215.80800","17.98415","0.14267"
"36006","216.00000","18.00018","0.14313"
"36038","216.19200","18.01614","0.14352"
"36070","216.38400","18.03217","0.14375"
"36102","216.57600","18.04819","0.14407"
"36134","216.76800","18.06421","0.14420"
"36166","216.96000","18.08018","0.14440"
"36198","217.15200","18.09620","0.14487"
"36230","217.34400","18.11216","0.14483"
"36262","217.53600","18.12825","0.14499"
"36294","217.72800","18.14415","0.14519"
"36326","217.92000","18.16011","0.14510"
"36358","218.11200","18.17620","0.14539"
"36390","218.30400","18.19222","0.14507"
"36422","218.49600","18.20813","0.14507"
"36454","218.68800","18.22421","0.14524"
"36486","218.88000","18.24023","0.14533"
"36518","219.07200","18.25614","0.14585"
"36550","219.26400","18.27222","0.14583"
"36582","219.45600","18.28818","0.14676"
"36614","219.64800","18.30409","0.14646"
"36646","219.84000","18.32017","0.14709"
"36678","220.03200","18.33613","0.14723"
"36710","220.22400","18.35216","0.14723"
"36742","220.41600","18.36824","0.14739"
"36774","220.60800","18.38420","0.14761"
"36806","220.80000","18.40017","0.14745"
"36838","220.99200","18.41619","0.14839"
"36870","221.18400","18.43216","0.14814"
"36902","221.37600","18.44812","0.14834"
"36934","221.56800","18.46420","0.14816"
"36966","221.76000","18.48011","0.14840"
"36998","221.95200","18.49619","0.14878"
"37030","222.14400","18.51221","0.14876"
"37062","222.33600","18.52812","0.14741"
"37094","222.52800","18.54420","0.00692"
"37126","222.72000","18.56017","0.00480"
"37158","222.91200","18.57613","0.00493"
"37190","223.10400","18.59221","0.00225"
"37222","223.29600","18.60818","0.00350"
"37254","223.48800","18.62420","0.01769"
"37286","223.68000","18.64022","0.00546"
"37318","223.87200","18.65619","0.00346"
"37350","224.06400","18.67215","0.01010"
"37382","224.25600","18.68818","0.00215"
"37414","224.44800","18.70414","0.00259"
"37446","224.64000","18.72016","0.01451"
"37478","224.83200","18.73619","0.00383"
"37510","225.02400","18.75221","0.00350"
"37542","225.21600","18.76818","0.00317"
"37574","225.40800","18.78420","0.00875"
"37606","225.60000","18.80016","0.00319"
"37638","225.79200","18.81618","0.00872"
"37670","225.98400","18.83215","0.00870"
"37702","226.17600","18.84817","0.00374"
"37734","226.36800","18.86414","0.00240"
"37766","226.56000","18.88016","0.01033"
"37798","226.75200","18.89618","0.00264"
"37830","226.94400","18.91221","0.00426"
"37862","227.13600","18.92817","0.01671"
"37894","227.32800","18.94419","0.00303"
"37926","227.52000","18.96016","0.00254"
"37958","227.71200","18.97618","0.01073"
"37990","227.90400","18.99220","0.00314"
"38022","228.09600","19.00817","0.00283"
"38054","228.28800","19.02413","0.01446"
"38086","228.48000","19.04016","0.00337"
"38118","228.67200","19.05618","0.00300"
"38150","228.86400","19.07220","0.01096"
"38182","229.05600","19.08823","0.00297"
"38214","229.24800","19.10413","0.00296"
"38246","229.44000","19.12021","0.01103"
"38278","229.63200","19.13618","0.00352"
"38310","229.82400","19.15214","0.00257"
"38342","230.01600","19.16823","0.01292"
"38374","230.20800","19.18419","0.00313"
"38406","230.40000","19.20009","0.00308"
"38438","230.59200","19.21624","0.01320"
"38470","230.78400","19.23220","0.00421"
"38502","230.97600","19.24816","0.00331"
"38534","231.16800","19.26425","0.01365"
"38566","231.36000","19.28015","0.00234"
"38598","231.55200","19.29612","0.00260"
"38630","231.74400","19.31226","0.01087"
"38662","231.93600","19.32816","0.00631"
"38694","232.12800","19.34413","0.00247"
"38726","232.32000","19.36021","0.00713"
"38758","232.51200","19.37611","0.00867"
"38790","232.70400","19.39220","0.00300"
"38822","232.89600","19.40822","0.00828"
"38854","233.08800","19.42413","0.00790"
"38886","233.28000","19.44021","0.00356"
"38918","233.47200","19.45623","0.01178"
"38950","233.66400","19.47214","0.00464"
"38982","233.85600","19.48822","0.00339"
"39014","234.04800","19.50418","0.01175"
"39046","234.24000","19.52015","0.00635"
"39076","234.42000","19.53515","0.00194"