File: Trajectories_together/161114Specimen_RawData_8.csv
"","V1","V2","V3"
"1","End date","11/14/2016",""
"2","Specimen label","20BT60",""
"3","Maximum Load","0.35281","N"
"4","Time","Extension","Load"
"5","(s)","(mm)","(N)"
"6","0.00000","0.00000","-0.00027"
"46","0.24000","0.01853","-0.00026"
"86","0.48000","0.04030","-0.00005"
"126","0.72000","0.06027","0.00062"
"166","0.96000","0.08024","0.00068"
"206","1.20000","0.10027","0.00105"
"246","1.44000","0.12024","0.00149"
"286","1.68000","0.14021","0.00158"
"326","1.92000","0.16024","0.00108"
"366","2.16000","0.18021","0.00178"
"406","2.40000","0.20024","0.00193"
"446","2.64000","0.22020","0.00269"
"486","2.88000","0.24023","0.00183"
"526","3.12000","0.26020","0.00233"
"566","3.36000","0.28023","0.00219"
"606","3.60000","0.30020","0.00301"
"646","3.84000","0.32017","0.00227"
"686","4.08000","0.34026","0.00270"
"726","4.32000","0.36017","0.00292"
"766","4.56000","0.38020","0.00314"
"806","4.80000","0.40023","0.00233"
"846","5.04000","0.42020","0.00306"
"886","5.28000","0.44023","0.00385"
"926","5.52000","0.46014","0.00378"
"966","5.76000","0.48017","0.00361"
"1006","6.00000","0.50020","0.00391"
"1046","6.24000","0.52029","0.00342"
"1086","6.48000","0.54014","0.00362"
"1126","6.72000","0.56023","0.00376"
"1166","6.96000","0.58020","0.00378"
"1206","7.20000","0.60023","0.00394"
"1246","7.44000","0.62020","0.00400"
"1286","7.68000","0.64023","0.00446"
"1326","7.92000","0.66020","0.00412"
"1366","8.16000","0.68017","0.00337"
"1406","8.40000","0.70026","0.00433"
"1446","8.64000","0.72022","0.00489"
"1486","8.88000","0.74025","0.00497"
"1526","9.12000","0.76016","0.00395"
"1566","9.36000","0.78019","0.00518"
"1606","9.60000","0.80022","0.00500"
"1646","9.84000","0.82019","0.00502"
"1686","10.08000","0.84022","0.00441"
"1726","10.32000","0.86013","0.00444"
"1766","10.56000","0.88022","0.00481"
"1806","10.80000","0.90019","0.00564"
"1846","11.04000","0.92022","0.00500"
"1886","11.28000","0.94013","0.00511"
"1926","11.52000","0.96028","0.00561"
"1966","11.76000","0.98019","0.00594"
"2006","12.00000","1.00016","0.00542"
"2046","12.24000","1.02025","0.00547"
"2086","12.48000","1.04016","0.00575"
"2126","12.72000","1.06025","0.00604"
"2166","12.96000","1.08016","0.00595"
"2206","13.20000","1.10025","0.00685"
"2246","13.44000","1.12022","0.00572"
"2286","13.68000","1.14025","0.00688"
"2326","13.92000","1.16016","0.00670"
"2366","14.16000","1.18025","0.00655"
"2406","14.40000","1.20027","0.00658"
"2446","14.64000","1.22018","0.00673"
"2486","14.88000","1.24021","0.00628"
"2526","15.12000","1.26018","0.00683"
"2566","15.36000","1.28021","0.00606"
"2606","15.60000","1.30018","0.00750"
"2646","15.84000","1.32027","0.00645"
"2686","16.08000","1.34018","0.00746"
"2726","16.32000","1.36021","0.00792"
"2766","16.56000","1.38024","0.00708"
"2806","16.80000","1.40021","0.00818"
"2846","17.04000","1.42024","0.00752"
"2886","17.28000","1.44021","0.00788"
"2926","17.52000","1.46024","0.00686"
"2966","17.76000","1.48015","0.00680"
"3006","18.00000","1.50024","0.00747"
"3046","18.24000","1.52021","0.00791"
"3086","18.48000","1.54018","0.00840"
"3126","18.72000","1.56021","0.00740"
"3166","18.96000","1.58018","0.00815"
"3206","19.20000","1.60021","0.00625"
"3246","19.44000","1.62018","0.00535"
"3286","19.68000","1.64021","0.00699"
"3326","19.92000","1.66012","0.00624"
"3366","20.16000","1.68027","0.00663"
"3406","20.40000","1.70024","0.00648"
"3446","20.64000","1.72020","0.00656"
"3486","20.88000","1.74017","0.00613"
"3526","21.12000","1.76020","0.00639"
"3566","21.36000","1.78023","0.00620"
"3606","21.60000","1.80020","0.00637"
"3646","21.84000","1.82023","0.00628"
"3686","22.08000","1.84014","0.00673"
"3726","22.32000","1.86023","0.00755"
"3766","22.56000","1.88020","0.00704"
"3806","22.80000","1.90023","0.00724"
"3846","23.04000","1.92020","0.00760"
"3886","23.28000","1.94023","0.00699"
"3926","23.52000","1.96020","0.00822"
"3966","23.76000","1.98017","0.00827"
"4006","24.00000","2.00026","0.00848"
"4046","24.24000","2.02011","0.00908"
"4086","24.48000","2.04020","0.00794"
"4126","24.72000","2.06017","0.00858"
"4166","24.96000","2.08026","0.00906"
"4206","25.20000","2.10023","0.00897"
"4246","25.44000","2.12026","0.00908"
"4286","25.68000","2.14017","0.00902"
"4326","25.92000","2.16020","0.01002"
"4366","26.16000","2.18023","0.00954"
"4406","26.40000","2.20014","0.01054"
"4446","26.64000","2.22022","0.01048"
"4486","26.88000","2.24019","0.00886"
"4526","27.12000","2.26022","0.00982"
"4566","27.36000","2.28025","0.00935"
"4606","27.60000","2.30022","0.00981"
"4646","27.84000","2.32019","0.00953"
"4686","28.08000","2.34016","0.01114"
"4726","28.32000","2.36025","0.01106"
"4766","28.56000","2.38016","0.00982"
"4806","28.80000","2.40019","0.01034"
"4846","29.04000","2.42022","0.01127"
"4886","29.28000","2.44019","0.01106"
"4926","29.52000","2.46022","0.01089"
"4966","29.76000","2.48019","0.01143"
"5006","30.00000","2.50022","0.01110"
"5046","30.24000","2.52019","0.01155"
"5086","30.48000","2.54028","0.01235"
"5126","30.72000","2.56013","0.01154"
"5166","30.96000","2.58022","0.01222"
"5206","31.20000","2.60019","0.01182"
"5246","31.44000","2.62022","0.01249"
"5286","31.68000","2.64019","0.01284"
"5326","31.92000","2.66022","0.01315"
"5366","32.16000","2.68019","0.01236"
"5406","32.40000","2.70021","0.01278"
"5446","32.64000","2.72024","0.01287"
"5486","32.88000","2.74015","0.01217"
"5526","33.12000","2.76018","0.01341"
"5566","33.36000","2.78015","0.01283"
"5606","33.60000","2.80024","0.01330"
"5646","33.84000","2.82021","0.01335"
"5686","34.08000","2.84024","0.01384"
"5726","34.32000","2.86021","0.01368"
"5766","34.56000","2.88018","0.01455"
"5806","34.80000","2.90021","0.01371"
"5846","35.04000","2.92018","0.01474"
"5886","35.28000","2.94021","0.01375"
"5926","35.52000","2.96012","0.01491"
"5966","35.76000","2.98027","0.01381"
"6006","36.00000","3.00018","0.01466"
"6046","36.24000","3.02021","0.01489"
"6086","36.48000","3.04024","0.01518"
"6126","36.72000","3.06021","0.01507"
"6166","36.96000","3.08024","0.01501"
"6206","37.20000","3.10015","0.01598"
"6246","37.44000","3.12024","0.01545"
"6286","37.68000","3.14015","0.01589"
"6326","37.92000","3.16018","0.01621"
"6366","38.16000","3.18021","0.01707"
"6406","38.40000","3.20017","0.01610"
"6446","38.64000","3.22020","0.01722"
"6486","38.88000","3.24017","0.01769"
"6526","39.12000","3.26020","0.01753"
"6566","39.36000","3.28023","0.01826"
"6606","39.60000","3.30020","0.01788"
"6646","39.84000","3.32017","0.01820"
"6686","40.08000","3.34026","0.01867"
"6726","40.32000","3.36011","0.01783"
"6766","40.56000","3.38026","0.01918"
"6806","40.80000","3.40029","0.01896"
"6846","41.04000","3.42020","0.01980"
"6886","41.28000","3.44023","0.02033"
"6926","41.52000","3.46014","0.01946"
"6966","41.76000","3.48023","0.02027"
"7006","42.00000","3.50014","0.02040"
"7046","42.24000","3.52029","0.02040"
"7086","42.48000","3.54020","0.02070"
"7126","42.72000","3.56023","0.02157"
"7166","42.96000","3.58020","0.02147"
"7206","43.20000","3.60017","0.02183"
"7246","43.44000","3.62020","0.02261"
"7286","43.68000","3.64023","0.02193"
"7326","43.92000","3.66020","0.02257"
"7366","44.16000","3.68011","0.02288"
"7406","44.40000","3.70025","0.02250"
"7446","44.64000","3.72016","0.02346"
"7486","44.88000","3.74025","0.02363"
"7526","45.12000","3.76022","0.02425"
"7566","45.36000","3.78019","0.02427"
"7606","45.60000","3.80028","0.02487"
"7646","45.84000","3.82019","0.02458"
"7686","46.08000","3.84022","0.02476"
"7726","46.32000","3.86013","0.02527"
"7766","46.56000","3.88022","0.02551"
"7806","46.80000","3.90025","0.02582"
"7846","47.04000","3.92028","0.02550"
"7886","47.28000","3.94025","0.02639"
"7926","47.52000","3.96022","0.02617"
"7966","47.76000","3.98019","0.02694"
"8006","48.00000","4.00022","0.02721"
"8046","48.24000","4.02019","0.02707"
"8086","48.48000","4.04016","0.02787"
"8126","48.72000","4.06025","0.02820"
"8166","48.96000","4.08016","0.02821"
"8206","49.20000","4.10025","0.02833"
"8246","49.44000","4.12016","0.02896"
"8286","49.68000","4.14025","0.02915"
"8326","49.92000","4.16016","0.02929"
"8366","50.16000","4.18018","0.02932"
"8406","50.40000","4.20027","0.02989"
"8446","50.64000","4.22012","0.03006"
"8486","50.88000","4.24027","0.02999"
"8526","51.12000","4.26018","0.03009"
"8566","51.36000","4.28021","0.03030"
"8606","51.60000","4.30018","0.03093"
"8646","51.84000","4.32021","0.03119"
"8686","52.08000","4.34018","0.03150"
"8726","52.32000","4.36021","0.03144"
"8766","52.56000","4.38024","0.03193"
"8806","52.80000","4.40015","0.03222"
"8846","53.04000","4.42024","0.03312"
"8886","53.28000","4.44021","0.03358"
"8926","53.52000","4.46018","0.03342"
"8966","53.76000","4.48015","0.03420"
"9006","54.00000","4.50024","0.03323"
"9046","54.24000","4.52021","0.03458"
"9086","54.48000","4.54018","0.03533"
"9126","54.72000","4.56021","0.03508"
"9166","54.96000","4.58018","0.03540"
"9206","55.20000","4.60021","0.03607"
"9246","55.44000","4.62024","0.03579"
"9286","55.68000","4.64021","0.03631"
"9326","55.92000","4.66018","0.03640"
"9366","56.16000","4.68026","0.03668"
"9406","56.40000","4.70017","0.03674"
"9446","56.64000","4.72014","0.03771"
"9486","56.88000","4.74017","0.03848"
"9526","57.12000","4.76014","0.03829"
"9566","57.36000","4.78023","0.03848"
"9606","57.60000","4.80020","0.03893"
"9646","57.84000","4.82023","0.03943"
"9686","58.08000","4.84020","0.03953"
"9726","58.32000","4.86023","0.04004"
"9766","58.56000","4.88020","0.04003"
"9806","58.80000","4.90017","0.04057"
"9846","59.04000","4.92026","0.04106"
"9886","59.28000","4.94017","0.04131"
"9926","59.52000","4.96026","0.04166"
"9966","59.76000","4.98017","0.04194"
"10006","60.00000","5.00020","0.04247"
"10046","60.24000","5.02017","0.04288"
"10086","60.48000","5.04026","0.04316"
"10126","60.72000","5.06017","0.04372"
"10166","60.96000","5.08014","0.04369"
"10206","61.20000","5.10029","0.04362"
"10246","61.44000","5.12020","0.04390"
"10286","61.68000","5.14023","0.04446"
"10326","61.92000","5.16020","0.04508"
"10366","62.16000","5.18023","0.04515"
"10406","62.40000","5.20019","0.04533"
"10446","62.64000","5.22022","0.04573"
"10486","62.88000","5.24019","0.04617"
"10526","63.12000","5.26016","0.04664"
"10566","63.36000","5.28025","0.04696"
"10606","63.60000","5.30016","0.04717"
"10646","63.84000","5.32019","0.04710"
"10686","64.08000","5.34016","0.04768"
"10726","64.32000","5.36025","0.04765"
"10766","64.56000","5.38022","0.04832"
"10806","64.80000","5.40025","0.04818"
"10846","65.04000","5.42022","0.04839"
"10886","65.28000","5.44019","0.04913"
"10926","65.52000","5.46022","0.04940"
"10966","65.76000","5.48019","0.04968"
"11006","66.00000","5.50022","0.04943"
"11046","66.24000","5.52019","0.05009"
"11086","66.48000","5.54022","0.04987"
"11126","66.72000","5.56019","0.05022"
"11166","66.96000","5.58028","0.05058"
"11206","67.20000","5.60019","0.05108"
"11246","67.44000","5.62016","0.05093"
"11286","67.68000","5.64025","0.05121"
"11326","67.92000","5.66022","0.05129"
"11366","68.16000","5.68024","0.05149"
"11406","68.40000","5.70010","0.05173"
"11446","68.64000","5.72024","0.05193"
"11486","68.88000","5.74015","0.05200"
"11526","69.12000","5.76024","0.05243"
"11566","69.36000","5.78015","0.05243"
"11606","69.60000","5.80018","0.05259"
"11646","69.84000","5.82021","0.05291"
"11686","70.08000","5.84018","0.05301"
"11726","70.32000","5.86027","0.05320"
"11766","70.56000","5.88018","0.05334"
"11806","70.80000","5.90027","0.05349"
"11846","71.04000","5.92018","0.05358"
"11886","71.28000","5.94021","0.05405"
"11926","71.52000","5.96018","0.05399"
"11966","71.76000","5.98021","0.05413"
"12006","72.00000","6.00018","0.05436"
"12046","72.24000","6.02021","0.05426"
"12086","72.48000","6.04024","0.05436"
"12126","72.72000","6.06021","0.05454"
"12166","72.96000","6.08024","0.05462"
"12206","73.20000","6.10015","0.05466"
"12246","73.44000","6.12024","0.05474"
"12286","73.68000","6.14015","0.05500"
"12326","73.92000","6.16017","0.05507"
"12366","74.16000","6.18020","0.05506"
"12406","74.40000","6.20023","0.05506"
"12446","74.64000","6.22020","0.05529"
"12486","74.88000","6.24017","0.05524"
"12526","75.12000","6.26020","0.05534"
"12566","75.36000","6.28011","0.05551"
"12606","75.60000","6.30020","0.05547"
"12646","75.84000","6.32017","0.05562"
"12686","76.08000","6.34026","0.05563"
"12726","76.32000","6.36017","0.05563"
"12766","76.56000","6.38020","0.05571"
"12806","76.80000","6.40023","0.05586"
"12846","77.04000","6.42014","0.05577"
"12886","77.28000","6.44023","0.05590"
"12926","77.52000","6.46020","0.05599"
"12966","77.76000","6.48029","0.05591"
"13006","78.00000","6.50014","0.05605"
"13046","78.24000","6.52023","0.05603"
"13086","78.48000","6.54020","0.05626"
"13126","78.72000","6.56023","0.05620"
"13166","78.96000","6.58026","0.05631"
"13206","79.20000","6.60017","0.05643"
"13246","79.44000","6.62026","0.05658"
"13286","79.68000","6.64017","0.05658"
"13326","79.92000","6.66019","0.05686"
"13366","80.16000","6.68016","0.05671"
"13406","80.40000","6.70025","0.05694"
"13446","80.64000","6.72022","0.05694"
"13486","80.88000","6.74025","0.05720"
"13526","81.12000","6.76028","0.05760"
"13566","81.36000","6.78019","0.05790"
"13606","81.60000","6.80022","0.05804"
"13646","81.84000","6.82019","0.05815"
"13686","82.08000","6.84022","0.05845"
"13726","82.32000","6.86019","0.05879"
"13766","82.56000","6.88028","0.05885"
"13806","82.80000","6.90019","0.05929"
"13846","83.04000","6.92022","0.05943"
"13886","83.28000","6.94025","0.06000"
"13926","83.52000","6.96022","0.06038"
"13966","83.76000","6.98025","0.06044"
"14006","84.00000","7.00022","0.06115"
"14046","84.24000","7.02019","0.06156"
"14086","84.48000","7.04010","0.06181"
"14126","84.72000","7.06025","0.06212"
"14166","84.96000","7.08016","0.06267"
"14206","85.20000","7.10025","0.06286"
"14246","85.44000","7.12022","0.06386"
"14286","85.68000","7.14019","0.06402"
"14326","85.92000","7.16022","0.06498"
"14366","86.16000","7.18018","0.06490"
"14406","86.40000","7.20021","0.06508"
"14446","86.64000","7.22012","0.06594"
"14486","86.88000","7.24027","0.06603"
"14526","87.12000","7.26018","0.06636"
"14566","87.36000","7.28027","0.06683"
"14606","87.60000","7.30024","0.06772"
"14646","87.84000","7.32015","0.06842"
"14686","88.08000","7.34024","0.06917"
"14726","88.32000","7.36021","0.06948"
"14766","88.56000","7.38024","0.07038"
"14806","88.80000","7.40015","0.07098"
"14846","89.04000","7.42024","0.07223"
"14886","89.28000","7.44021","0.07205"
"14926","89.52000","7.46024","0.07339"
"14966","89.76000","7.48027","0.07403"
"15006","90.00000","7.50024","0.07507"
"15046","90.24000","7.52021","0.07572"
"15086","90.48000","7.54018","0.07616"
"15126","90.72000","7.56021","0.07760"
"15166","90.96000","7.58018","0.07830"
"15206","91.20000","7.60027","0.07915"
"15246","91.44000","7.62024","0.08012"
"15286","91.68000","7.64021","0.08084"
"15326","91.92000","7.66018","0.08223"
"15366","92.16000","7.68026","0.08205"
"15406","92.40000","7.70018","0.08347"
"15446","92.64000","7.72020","0.08374"
"15486","92.88000","7.74023","0.08419"
"15526","93.12000","7.76014","0.08569"
"15566","93.36000","7.78017","0.08610"
"15606","93.60000","7.80020","0.08622"
"15646","93.84000","7.82023","0.08670"
"15686","94.08000","7.84020","0.08677"
"15726","94.32000","7.86023","0.08719"
"15766","94.56000","7.88026","0.08773"
"15806","94.80000","7.90023","0.08824"
"15846","95.04000","7.92026","0.08915"
"15886","95.28000","7.94011","0.08965"
"15926","95.52000","7.96020","0.08966"
"15966","95.76000","7.98023","0.09028"
"16006","96.00000","8.00020","0.09077"
"16046","96.24000","8.02017","0.09104"
"16086","96.48000","8.04020","0.09191"
"16126","96.72000","8.06023","0.09280"
"16166","96.96000","8.08020","0.09269"
"16206","97.20000","8.10023","0.09328"
"16246","97.44000","8.12008","0.09406"
"16286","97.68000","8.14023","0.09494"
"16326","97.92000","8.16025","0.09524"
"16366","98.16000","8.18022","0.09657"
"16406","98.40000","8.20025","0.09770"
"16446","98.64000","8.22022","0.09825"
"16486","98.88000","8.24025","0.09876"
"16526","99.12000","8.26022","0.10044"
"16566","99.36000","8.28025","0.10199"
"16606","99.60000","8.30016","0.10239"
"16646","99.84000","8.32019","0.10375"
"16686","100.08000","8.34022","0.10431"
"16726","100.32000","8.36019","0.10642"
"16766","100.56000","8.38016","0.10805"
"16806","100.80000","8.40025","0.10879"
"16846","101.04000","8.42022","0.11099"
"16886","101.28000","8.44019","0.11178"
"16926","101.52000","8.46022","0.11377"
"16966","101.76000","8.48013","0.11504"
"17006","102.00000","8.50022","0.11662"
"17046","102.24000","8.52019","0.11778"
"17086","102.48000","8.54022","0.11913"
"17126","102.72000","8.56019","0.12032"
"17166","102.96000","8.58028","0.12105"
"17206","103.20000","8.60025","0.12258"
"17246","103.44000","8.62016","0.12317"
"17286","103.68000","8.64025","0.12514"
"17326","103.92000","8.66016","0.12585"
"17366","104.16000","8.68024","0.12661"
"17406","104.40000","8.70015","0.12839"
"17446","104.64000","8.72024","0.12980"
"17486","104.88000","8.74015","0.13088"
"17526","105.12000","8.76018","0.13110"
"17566","105.36000","8.78021","0.13203"
"17606","105.60000","8.80018","0.13266"
"17646","105.84000","8.82021","0.13329"
"17686","106.08000","8.84012","0.13465"
"17726","106.32000","8.86027","0.13524"
"17766","106.56000","8.88018","0.13646"
"17806","106.80000","8.90027","0.13672"
"17846","107.04000","8.92018","0.13756"
"17886","107.28000","8.94021","0.13796"
"17926","107.52000","8.96024","0.13835"
"17966","107.76000","8.98015","0.13908"
"18006","108.00000","9.00018","0.13944"
"18046","108.24000","9.02021","0.13977"
"18086","108.48000","9.04024","0.14038"
"18126","108.72000","9.06021","0.14082"
"18166","108.96000","9.08024","0.14097"
"18206","109.20000","9.10015","0.14134"
"18246","109.44000","9.12024","0.14157"
"18286","109.68000","9.14027","0.14151"
"18326","109.92000","9.16023","0.14193"
"18366","110.16000","9.18021","0.14211"
"18406","110.40000","9.20017","0.14225"
"18446","110.64000","9.22026","0.14267"
"18486","110.88000","9.24011","0.14301"
"18526","111.12000","9.26026","0.14319"
"18566","111.36000","9.28017","0.14343"
"18606","111.60000","9.30026","0.14360"
"18646","111.84000","9.32023","0.14405"
"18686","112.08000","9.34014","0.14405"
"18726","112.32000","9.36017","0.14467"
"18766","112.56000","9.38020","0.14568"
"18806","112.80000","9.40029","0.14601"
"18846","113.04000","9.42020","0.14627"
"18886","113.28000","9.44023","0.14691"
"18926","113.52000","9.46020","0.14770"
"18966","113.76000","9.48023","0.14858"
"19006","114.00000","9.50020","0.14918"
"19046","114.24000","9.52017","0.15027"
"19086","114.48000","9.54020","0.15128"
"19126","114.72000","9.56023","0.15188"
"19166","114.96000","9.58026","0.15287"
"19206","115.20000","9.60017","0.15346"
"19246","115.44000","9.62020","0.15391"
"19286","115.68000","9.64017","0.15471"
"19326","115.92000","9.66019","0.15585"
"19366","116.16000","9.68022","0.15686"
"19406","116.40000","9.70025","0.15751"
"19446","116.64000","9.72016","0.15825"
"19486","116.88000","9.74019","0.15914"
"19526","117.12000","9.76022","0.15953"
"19566","117.36000","9.78019","0.16006"
"19606","117.60000","9.80022","0.16097"
"19646","117.84000","9.82019","0.16165"
"19686","118.08000","9.84022","0.16219"
"19726","118.32000","9.86019","0.16320"
"19766","118.56000","9.88028","0.16413"
"19806","118.80000","9.90019","0.16468"
"19846","119.04000","9.92016","0.16592"
"19886","119.28000","9.94025","0.16672"
"19926","119.52000","9.96016","0.16692"
"19966","119.76000","9.98025","0.16747"
"20006","120.00000","10.00016","0.16804"
"20046","120.24000","10.02025","0.16973"
"20086","120.48000","10.04022","0.17046"
"20126","120.72000","10.06025","0.17160"
"20166","120.96000","10.08016","0.17301"
"20206","121.20000","10.10013","0.17395"
"20246","121.44000","10.12027","0.17549"
"20286","121.68000","10.14019","0.17637"
"20326","121.92000","10.16022","0.13142"
"20366","122.16000","10.18018","0.13354"
"20406","122.40000","10.20015","0.13457"
"20446","122.64000","10.22018","0.13429"
"20486","122.88000","10.24021","0.13446"
"20526","123.12000","10.26018","0.13405"
"20566","123.36000","10.28015","0.13515"
"20606","123.60000","10.30024","0.13527"
"20646","123.84000","10.32015","0.13649"
"20686","124.08000","10.34024","0.13718"
"20726","124.32000","10.36021","0.13742"
"20766","124.56000","10.38018","0.13773"
"20806","124.80000","10.40021","0.13787"
"20846","125.04000","10.42024","0.13880"
"20886","125.28000","10.44021","0.13915"
"20926","125.52000","10.46018","0.13955"
"20966","125.76000","10.48027","0.14002"
"21006","126.00000","10.50018","0.13982"
"21046","126.24000","10.52021","0.14058"
"21086","126.48000","10.54012","0.14069"
"21126","126.72000","10.56021","0.14100"
"21166","126.96000","10.58024","0.14119"
"21206","127.20000","10.60027","0.14169"
"21246","127.44000","10.62018","0.14198"
"21286","127.68000","10.64020","0.14204"
"21326","127.92000","10.66029","0.14215"
"21366","128.16000","10.68020","0.14259"
"21406","128.40000","10.70023","0.14273"
"21446","128.64000","10.72014","0.14301"
"21486","128.88000","10.74023","0.14326"
"21526","129.12000","10.76020","0.14356"
"21566","129.36000","10.78023","0.14418"
"21606","129.60000","10.80014","0.14464"
"21646","129.84000","10.82017","0.14549"
"21686","130.08000","10.84026","0.14595"
"21726","130.32000","10.86023","0.14779"
"21766","130.56000","10.88026","0.14738"
"21806","130.80000","10.90017","0.14819"
"21846","131.04000","10.92020","0.15061"
"21886","131.28000","10.94017","0.15019"
"21926","131.52000","10.96020","0.15199"
"21966","131.76000","10.98017","0.15236"
"22006","132.00000","11.00020","0.15395"
"22046","132.24000","11.02023","0.15446"
"22086","132.48000","11.04020","0.15541"
"22126","132.72000","11.06023","0.15659"
"22166","132.96000","11.08020","0.15753"
"22206","133.20000","11.10029","0.15827"
"22246","133.44000","11.12014","0.15933"
"22286","133.68000","11.14029","0.15966"
"22326","133.92000","11.16019","0.16077"
"22366","134.16000","11.18022","0.16207"
"22406","134.40000","11.20019","0.16230"
"22446","134.64000","11.22022","0.16405"
"22486","134.88000","11.24025","0.16454"
"22526","135.12000","11.26016","0.16610"
"22566","135.36000","11.28025","0.16712"
"22606","135.60000","11.30010","0.16789"
"22646","135.84000","11.32025","0.16907"
"22686","136.08000","11.34022","0.17049"
"22726","136.32000","11.36019","0.17173"
"22766","136.56000","11.38022","0.17331"
"22806","136.80000","11.40025","0.17397"
"22846","137.04000","11.42022","0.17509"
"22886","137.28000","11.44013","0.17652"
"22926","137.52000","11.46022","0.17748"
"22966","137.76000","11.48019","0.17892"
"23006","138.00000","11.50022","0.18032"
"23046","138.24000","11.52019","0.18131"
"23086","138.48000","11.54022","0.18207"
"23126","138.72000","11.56025","0.18312"
"23166","138.96000","11.58022","0.18415"
"23206","139.20000","11.60025","0.18564"
"23246","139.44000","11.62015","0.18609"
"23286","139.68000","11.64025","0.18798"
"23326","139.92000","11.66016","0.18880"
"23366","140.16000","11.68018","0.19004"
"23406","140.40000","11.70021","0.19136"
"23446","140.64000","11.72024","0.19347"
"23486","140.88000","11.74021","0.19457"
"23526","141.12000","11.76018","0.19558"
"23566","141.36000","11.78021","0.19743"
"23606","141.60000","11.80012","0.19892"
"23646","141.84000","11.82021","0.20002"
"23686","142.08000","11.84018","0.20067"
"23726","142.32000","11.86021","0.20172"
"23766","142.56000","11.88018","0.20153"
"23806","142.80000","11.90021","0.20270"
"23846","143.04000","11.92018","0.20320"
"23886","143.28000","11.94021","0.20328"
"23926","143.52000","11.96024","0.20358"
"23966","143.76000","11.98015","0.20383"
"24006","144.00000","12.00024","0.20397"
"24046","144.24000","12.02015","0.20410"
"24086","144.48000","12.04018","0.20411"
"24126","144.72000","12.06021","0.20432"
"24166","144.96000","12.08024","0.20448"
"24206","145.20000","12.10020","0.20463"
"24246","145.44000","12.12024","0.20507"
"24286","145.68000","12.14020","0.20552"
"24326","145.92000","12.16018","0.20558"
"24366","146.16000","12.18020","0.20613"
"24406","146.40000","12.20017","0.20645"
"24446","146.64000","12.22014","0.20707"
"24486","146.88000","12.24017","0.20837"
"24526","147.12000","12.26020","0.20865"
"24566","147.36000","12.28023","0.21012"
"24606","147.60000","12.30020","0.21095"
"24646","147.84000","12.32023","0.21217"
"24686","148.08000","12.34020","0.21409"
"24726","148.32000","12.36023","0.21506"
"24766","148.56000","12.38020","0.21607"
"24806","148.80000","12.40017","0.21744"
"24846","149.04000","12.42014","0.21875"
"24886","149.28000","12.44029","0.21965"
"24926","149.52000","12.46020","0.22078"
"24966","149.76000","12.48017","0.22151"
"25006","150.00000","12.50020","0.22296"
"25046","150.24000","12.52017","0.22418"
"25086","150.48000","12.54020","0.22535"
"25126","150.72000","12.56017","0.22651"
"25166","150.96000","12.58020","0.22716"
"25206","151.20000","12.60017","0.22872"
"25246","151.44000","12.62025","0.22937"
"25286","151.68000","12.64017","0.23041"
"25326","151.92000","12.66019","0.23164"
"25366","152.16000","12.68022","0.23286"
"25406","152.40000","12.70019","0.23388"
"25446","152.64000","12.72022","0.23513"
"25486","152.88000","12.74019","0.23577"
"25526","153.12000","12.76016","0.23696"
"25566","153.36000","12.78013","0.23649"
"25606","153.60000","12.80028","0.23752"
"25646","153.84000","12.82019","0.23852"
"25686","154.08000","12.84022","0.23957"
"25726","154.32000","12.86025","0.24042"
"25766","154.56000","12.88022","0.24080"
"25806","154.80000","12.90025","0.24170"
"25846","155.04000","12.92016","0.24257"
"25886","155.28000","12.94019","0.24339"
"25926","155.52000","12.96016","0.24403"
"25966","155.76000","12.98025","0.24441"
"26006","156.00000","13.00022","0.24523"
"26046","156.24000","13.02019","0.24594"
"26086","156.48000","13.04028","0.24670"
"26126","156.72000","13.06019","0.24778"
"26166","156.96000","13.08022","0.24868"
"26206","157.20000","13.10019","0.24975"
"26246","157.44000","13.12022","0.25050"
"26286","157.68000","13.14012","0.25167"
"26326","157.92000","13.16021","0.25408"
"26366","158.16000","13.18024","0.25555"
"26406","158.40000","13.20021","0.25687"
"26446","158.64000","13.22024","0.25886"
"26486","158.88000","13.24021","0.26005"
"26526","159.12000","13.26024","0.26084"
"26566","159.36000","13.28015","0.26310"
"26606","159.60000","13.30018","0.26339"
"26646","159.84000","13.32015","0.26444"
"26686","160.08000","13.34024","0.26609"
"26726","160.32000","13.36021","0.26778"
"26766","160.56000","13.38024","0.26862"
"26806","160.80000","13.40021","0.26954"
"26846","161.04000","13.42024","0.27073"
"26886","161.28000","13.44021","0.27202"
"26926","161.52000","13.46024","0.27303"
"26966","161.76000","13.48021","0.27449"
"27006","162.00000","13.50012","0.27618"
"27046","162.24000","13.52021","0.27647"
"27086","162.48000","13.54018","0.27747"
"27126","162.72000","13.56027","0.27991"
"27166","162.96000","13.58024","0.28147"
"27206","163.20000","13.60021","0.28332"
"27246","163.44000","13.62024","0.28562"
"27286","163.68000","13.64015","0.28703"
"27326","163.92000","13.66023","0.28859"
"27366","164.16000","13.68015","0.28928"
"27406","164.40000","13.70023","0.29110"
"27446","164.64000","13.72020","0.29338"
"27486","164.88000","13.74017","0.29490"
"27526","165.12000","13.76020","0.29726"
"27566","165.36000","13.78023","0.29793"
"27606","165.60000","13.80020","0.29928"
"27646","165.84000","13.82017","0.30054"
"27686","166.08000","13.84020","0.29950"
"27726","166.32000","13.86011","0.29260"
"27766","166.56000","13.88026","0.15671"
"27806","166.80000","13.90017","0.14691"
"27846","167.04000","13.92020","0.14324"
"27886","167.28000","13.94023","0.14645"
"27926","167.52000","13.96020","0.14377"
"27966","167.76000","13.98017","0.14899"
"28006","168.00000","14.00014","0.14717"
"28046","168.24000","14.02023","0.14998"
"28086","168.48000","14.04014","0.15096"
"28126","168.72000","14.06023","0.14994"
"28166","168.96000","14.08020","0.14909"
"28206","169.20000","14.10023","0.14642"
"28246","169.44000","14.12014","0.14622"
"28286","169.68000","14.14022","0.14707"
"28326","169.92000","14.16026","0.14947"
"28366","170.16000","14.18016","0.15571"
"28406","170.40000","14.20019","0.15694"
"28446","170.64000","14.22016","0.16278"
"28486","170.88000","14.24025","0.16254"
"28526","171.12000","14.26016","0.16546"
"28566","171.36000","14.28025","0.16296"
"28606","171.60000","14.30016","0.16371"
"28646","171.84000","14.32025","0.16277"
"28686","172.08000","14.34022","0.16337"
"28726","172.32000","14.36019","0.16932"
"28766","172.56000","14.38022","0.17157"
"28806","172.80000","14.40019","0.17935"
"28846","173.04000","14.42022","0.17664"
"28886","173.28000","14.44019","0.17946"
"28926","173.52000","14.46028","0.17659"
"28966","173.76000","14.48019","0.17696"
"29006","174.00000","14.50022","0.18112"
"29046","174.24000","14.52025","0.18363"
"29086","174.48000","14.54022","0.19172"
"29126","174.72000","14.56025","0.18892"
"29166","174.96000","14.58016","0.19121"
"29206","175.20000","14.60019","0.18872"
"29246","175.44000","14.62016","0.19023"
"29286","175.68000","14.64025","0.19676"
"29326","175.92000","14.66021","0.19594"
"29366","176.16000","14.68018","0.20102"
"29406","176.40000","14.70027","0.19891"
"29446","176.64000","14.72018","0.20007"
"29486","176.88000","14.74015","0.20048"
"29526","177.12000","14.76018","0.20146"
"29566","177.36000","14.78021","0.20381"
"29606","177.60000","14.80018","0.20358"
"29646","177.84000","14.82027","0.20395"
"29686","178.08000","14.84012","0.20379"
"29726","178.32000","14.86021","0.20400"
"29766","178.56000","14.88018","0.20466"
"29806","178.80000","14.90021","0.20448"
"29846","179.04000","14.92018","0.20582"
"29886","179.28000","14.94021","0.20511"
"29926","179.52000","14.96024","0.20551"
"29966","179.76000","14.98015","0.20827"
"30006","180.00000","15.00024","0.20738"
"30046","180.24000","15.02015","0.21163"
"30086","180.48000","15.04024","0.21011"
"30126","180.72000","15.06021","0.21111"
"30166","180.96000","15.08018","0.21547"
"30206","181.20000","15.10021","0.21546"
"30246","181.44000","15.12024","0.21853"
"30286","181.68000","15.14026","0.21744"
"30326","181.92000","15.16018","0.21879"
"30366","182.16000","15.18020","0.22184"
"30406","182.40000","15.20017","0.22097"
"30446","182.64000","15.22020","0.22313"
"30486","182.88000","15.24017","0.22383"
"30526","183.12000","15.26020","0.22453"
"30566","183.36000","15.28017","0.22823"
"30606","183.60000","15.30020","0.02589"
"30646","183.84000","15.32023","0.02486"
"30686","184.08000","15.34020","0.00944"
"30726","184.32000","15.36023","0.00818"
"30766","184.56000","15.38020","0.03665"
"30806","184.80000","15.40023","0.00869"
"30846","185.04000","15.42020","0.02337"
"30886","185.28000","15.44023","0.01089"
"30926","185.52000","15.46014","0.02705"
"30966","185.76000","15.48017","0.00807"
"31006","186.00000","15.50026","0.01468"
"31046","186.24000","15.52017","0.02222"
"31086","186.48000","15.54020","0.01838"
"31126","186.72000","15.56017","0.01568"
"31166","186.96000","15.58020","0.01725"
"31206","187.20000","15.60023","0.02408"
"31246","187.44000","15.62020","0.01775"
"31286","187.68000","15.64016","0.01575"
"31326","187.92000","15.66019","0.02520"
"31366","188.16000","15.68022","0.01843"
"31406","188.40000","15.70013","0.01992"
"31446","188.64000","15.72022","0.02153"
"31486","188.88000","15.74013","0.02288"
"31526","189.12000","15.76022","0.02089"
"31566","189.36000","15.78019","0.02070"
"31606","189.60000","15.80022","0.02624"
"31646","189.84000","15.82019","0.02184"
"31686","190.08000","15.84016","0.02313"
"31726","190.32000","15.86025","0.02621"
"31766","190.56000","15.88010","0.02280"
"31806","190.80000","15.90025","0.02432"
"31846","191.04000","15.92022","0.02663"
"31886","191.28000","15.94019","0.02564"
"31926","191.52000","15.96022","0.02653"
"31966","191.76000","15.98019","0.02773"
"32006","192.00000","16.00022","0.02781"
"32046","192.24000","16.02019","0.02728"
"32086","192.48000","16.04028","0.02774"
"32126","192.72000","16.06013","0.03018"
"32166","192.96000","16.08022","0.02891"
"32206","193.20000","16.10024","0.02984"
"32246","193.44000","16.12021","0.03166"
"32286","193.68000","16.14018","0.03034"
"32326","193.92000","16.16027","0.03064"
"32366","194.16000","16.18018","0.03207"
"32406","194.40000","16.20021","0.03144"
"32446","194.64000","16.22024","0.03262"
"32486","194.88000","16.24021","0.03456"
"32526","195.12000","16.26018","0.03372"
"32566","195.36000","16.28015","0.03441"
"32606","195.60000","16.30024","0.03570"
"32646","195.84000","16.32021","0.03522"
"32686","196.08000","16.34024","0.03545"
"32726","196.32000","16.36015","0.03718"
"32766","196.56000","16.38018","0.03784"
"32806","196.80000","16.40027","0.03808"
"32846","197.04000","16.42018","0.03899"
"32886","197.28000","16.44021","0.03908"
"32926","197.52000","16.46018","0.03935"
"32966","197.76000","16.48021","0.04012"
"33006","198.00000","16.50018","0.04063"
"33046","198.24000","16.52027","0.04177"
"33086","198.48000","16.54017","0.04226"
"33126","198.72000","16.56021","0.04272"
"33166","198.96000","16.58023","0.04351"
"33206","199.20000","16.60020","0.04412"
"33246","199.44000","16.62023","0.04428"
"33286","199.68000","16.64014","0.04535"
"33326","199.92000","16.66023","0.04605"
"33366","200.16000","16.68014","0.04639"
"33406","200.40000","16.70023","0.04671"
"33446","200.64000","16.72020","0.04730"
"33486","200.88000","16.74017","0.04758"
"33526","201.12000","16.76020","0.04859"
"33566","201.36000","16.78017","0.04867"
"33606","201.60000","16.80020","0.04931"
"33646","201.84000","16.82017","0.05002"
"33686","202.08000","16.84026","0.05016"
"33726","202.32000","16.86017","0.05070"
"33766","202.56000","16.88026","0.05087"
"33806","202.80000","16.90017","0.05107"
"33846","203.04000","16.92020","0.05171"
"33886","203.28000","16.94017","0.05180"
"33926","203.52000","16.96020","0.05251"
"33966","203.76000","16.98023","0.05269"
"34006","204.00000","17.00014","0.05285"
"34046","204.24000","17.02029","0.05288"
"34086","204.48000","17.04014","0.05346"
"34126","204.72000","17.06023","0.05374"
"34166","204.96000","17.08019","0.05383"
"34206","205.20000","17.10022","0.05395"
"34246","205.44000","17.12025","0.05421"
"34286","205.68000","17.14022","0.05436"
"34326","205.92000","17.16025","0.05461"
"34366","206.16000","17.18010","0.05476"
"34406","206.40000","17.20025","0.05491"
"34446","206.64000","17.22022","0.05493"
"34486","206.88000","17.24025","0.05516"
"34526","207.12000","17.26016","0.05537"
"34566","207.36000","17.28019","0.05546"
"34606","207.60000","17.30022","0.05553"
"34646","207.84000","17.32019","0.05553"
"34686","208.08000","17.34022","0.05574"
"34726","208.32000","17.36019","0.05578"
"34766","208.56000","17.38022","0.05589"
"34806","208.80000","17.40019","0.05598"
"34846","209.04000","17.42016","0.05601"
"34886","209.28000","17.44019","0.05618"
"34926","209.52000","17.46022","0.05641"
"34966","209.76000","17.48019","0.05672"
"35006","210.00000","17.50022","0.05694"
"35046","210.24000","17.52019","0.05672"
"35086","210.48000","17.54016","0.05752"
"35126","210.72000","17.56025","0.05743"
"35166","210.96000","17.58015","0.05784"
"35206","211.20000","17.60024","0.05845"
"35246","211.44000","17.62021","0.05906"
"35286","211.68000","17.64024","0.05967"
"35326","211.92000","17.66021","0.06016"
"35366","212.16000","17.68018","0.06126"
"35406","212.40000","17.70021","0.06124"
"35446","212.64000","17.72018","0.06212"
"35486","212.88000","17.74021","0.06249"
"35526","213.12000","17.76018","0.06362"
"35566","213.36000","17.78021","0.06402"
"35606","213.60000","17.80012","0.06473"
"35646","213.84000","17.82021","0.06542"
"35686","214.08000","17.84018","0.06627"
"35726","214.32000","17.86021","0.06680"
"35766","214.56000","17.88024","0.06775"
"35806","214.80000","17.90021","0.06892"
"35846","215.04000","17.92024","0.07044"
"35886","215.28000","17.94021","0.07154"
"35926","215.52000","17.96018","0.07291"
"35966","215.76000","17.98015","0.07492"
"36006","216.00000","18.00024","0.07576"
"36046","216.24000","18.02021","0.07518"
"36086","216.48000","18.04024","0.07549"
"36126","216.72000","18.06026","0.07732"
"36166","216.96000","18.08012","0.07935"
"36206","217.20000","18.10027","0.07933"
"36246","217.44000","18.12024","0.08112"
"36286","217.68000","18.14020","0.08229"
"36326","217.92000","18.16017","0.08380"
"36366","218.16000","18.18026","0.08555"
"36406","218.40000","18.20017","0.08627"
"36446","218.64000","18.22020","0.08764"
"36486","218.88000","18.24023","0.08843"
"36526","219.12000","18.26014","0.08954"
"36566","219.36000","18.28023","0.09080"
"36606","219.60000","18.30014","0.09082"
"36646","219.84000","18.32023","0.09181"
"36686","220.08000","18.34020","0.09316"
"36726","220.32000","18.36023","0.09364"
"36766","220.56000","18.38014","0.09416"
"36806","220.80000","18.40017","0.09515"
"36846","221.04000","18.42020","0.09591"
"36886","221.28000","18.44023","0.09728"
"36926","221.52000","18.46026","0.09851"
"36966","221.76000","18.48023","0.09992"
"37006","222.00000","18.50020","0.10155"
"37046","222.24000","18.52017","0.10288"
"37086","222.48000","18.54026","0.10443"
"37126","222.72000","18.56017","0.10540"
"37166","222.96000","18.58019","0.10811"
"37206","223.20000","18.60023","0.11033"
"37246","223.44000","18.62020","0.11323"
"37286","223.68000","18.64022","0.11492"
"37326","223.92000","18.66019","0.11746"
"37366","224.16000","18.68022","0.11950"
"37406","224.40000","18.70013","0.12266"
"37446","224.64000","18.72022","0.12381"
"37486","224.88000","18.74019","0.12525"
"37526","225.12000","18.76022","0.12668"
"37566","225.36000","18.78025","0.12735"
"37606","225.60000","18.80022","0.13006"
"37646","225.84000","18.82025","0.13037"
"37686","226.08000","18.84016","0.13191"
"37726","226.32000","18.86019","0.13368"
"37766","226.56000","18.88010","0.13518"
"37806","226.80000","18.90025","0.13572"
"37846","227.04000","18.92022","0.13701"
"37886","227.28000","18.94025","0.13833"
"37926","227.52000","18.96022","0.13892"
"37966","227.76000","18.98025","0.13937"
"38006","228.00000","19.00028","0.14001"
"38046","228.24000","19.02019","0.14054"
"38086","228.48000","19.04022","0.14083"
"38126","228.72000","19.06013","0.14123"
"38166","228.96000","19.08022","0.14127"
"38206","229.20000","19.10019","0.14185"
"38246","229.44000","19.12021","0.14218"
"38286","229.68000","19.14018","0.14237"
"38326","229.92000","19.16027","0.14255"
"38366","230.16000","19.18024","0.14314"
"38406","230.40000","19.20021","0.14337"
"38446","230.64000","19.22024","0.14423"
"38486","230.88000","19.24015","0.14322"
"38526","231.12000","19.26024","0.14320"
"38566","231.36000","19.28021","0.14376"
"38606","231.60000","19.30024","0.14495"
"38646","231.84000","19.32021","0.14617"
"38686","232.08000","19.34024","0.14806"
"38726","232.32000","19.36021","0.14907"
"38766","232.56000","19.38018","0.15106"
"38806","232.80000","19.40027","0.15261"
"38846","233.04000","19.42012","0.15545"
"38886","233.28000","19.44021","0.15597"
"38926","233.52000","19.46018","0.15750"
"38966","233.76000","19.48021","0.15955"
"39006","234.00000","19.50018","0.16039"
"39046","234.24000","19.52021","0.16192"
"39086","234.48000","19.54017","0.16378"
"39126","234.72000","19.56014","0.16422"
"39166","234.96000","19.58024","0.16654"
"39206","235.20000","19.60015","0.16825"
"39246","235.44000","19.62017","0.16976"
"39286","235.68000","19.64014","0.17176"
"39326","235.92000","19.66023","0.17351"
"39366","236.16000","19.68020","0.17491"
"39406","236.40000","19.70023","0.17651"
"39446","236.64000","19.72020","0.17761"
"39486","236.88000","19.74017","0.17979"
"39526","237.12000","19.76026","0.18165"
"39566","237.36000","19.78017","0.18324"
"39606","237.60000","19.80020","0.18469"
"39646","237.84000","19.82023","0.18589"
"39686","238.08000","19.84020","0.18256"
"39726","238.32000","19.86017","0.18470"
"39766","238.56000","19.88026","0.18658"
"39806","238.80000","19.90023","0.18826"
"39846","239.04000","19.92020","0.18980"
"39886","239.28000","19.94023","0.19086"
"39926","239.52000","19.96013","0.19251"
"39966","239.76000","19.98017","0.18725"
"40006","240.00000","20.00014","0.18905"
"40046","240.24000","20.02022","0.18982"
"40086","240.48000","20.04020","0.19238"
"40126","240.72000","20.06022","0.19447"
"40166","240.96000","20.08019","0.19619"
"40206","241.20000","20.10016","0.19819"
"40246","241.44000","20.12025","0.19963"
"40286","241.68000","20.14022","0.20097"
"40326","241.92000","20.16019","0.20181"
"40366","242.16000","20.18016","0.20277"
"40406","242.40000","20.20025","0.20317"
"40446","242.64000","20.22022","0.20341"
"40486","242.88000","20.24019","0.20393"
"40526","243.12000","20.26022","0.20417"
"40566","243.36000","20.28019","0.20415"
"40606","243.60000","20.30022","0.20437"
"40646","243.84000","20.32019","0.20478"
"40686","244.08000","20.34022","0.20501"
"40726","244.32000","20.36019","0.20522"
"40766","244.56000","20.38022","0.20663"
"40806","244.80000","20.40019","0.20757"
"40846","245.04000","20.42022","0.20804"
"40886","245.28000","20.44025","0.20963"
"40926","245.52000","20.46022","0.20967"
"40966","245.76000","20.48019","0.21039"
"41006","246.00000","20.50022","0.21073"
"41046","246.24000","20.52019","0.21289"
"41086","246.48000","20.54022","0.21502"
"41126","246.72000","20.56025","0.21625"
"41166","246.96000","20.58015","0.21790"
"41206","247.20000","20.60024","0.21900"
"41246","247.44000","20.62021","0.22033"
"41286","247.68000","20.64024","0.22150"
"41326","247.92000","20.66021","0.21864"
"41366","248.16000","20.68018","0.21788"
"41406","248.40000","20.70021","0.21869"
"41446","248.64000","20.72018","0.22007"
"41486","248.88000","20.74021","0.22191"
"41526","249.12000","20.76018","0.22324"
"41566","249.36000","20.78027","0.22526"
"41606","249.60000","20.80024","0.22609"
"41646","249.84000","20.82015","0.22769"
"41686","250.08000","20.84018","0.22857"
"41726","250.32000","20.86021","0.22965"
"41766","250.56000","20.88024","0.23146"
"41806","250.80000","20.90015","0.23298"
"41846","251.04000","20.92024","0.23425"
"41886","251.28000","20.94015","0.23566"
"41926","251.52000","20.96018","0.23673"
"41966","251.76000","20.98021","0.23427"
"42006","252.00000","21.00018","0.23456"
"42046","252.24000","21.02020","0.23591"
"42086","252.48000","21.04018","0.23708"
"42126","252.72000","21.06020","0.23804"
"42166","252.96000","21.08017","0.23935"
"42206","253.20000","21.10026","0.24014"
"42246","253.44000","21.12024","0.24071"
"42286","253.68000","21.14021","0.24174"
"42326","253.92000","21.16023","0.24297"
"42366","254.16000","21.18026","0.24406"
"42406","254.40000","21.20017","0.24474"
"42446","254.64000","21.22020","0.24587"
"42486","254.88000","21.24023","0.24672"
"42526","255.12000","21.26014","0.24745"
"42566","255.36000","21.28023","0.24881"
"42606","255.60000","21.30014","0.25026"
"42646","255.84000","21.32023","0.25148"
"42686","256.08000","21.34020","0.25243"
"42726","256.32000","21.36023","0.25351"
"42766","256.56000","21.38020","0.25537"
"42806","256.80000","21.40017","0.25596"
"42846","257.04000","21.42026","0.25724"
"42886","257.28000","21.44011","0.25916"
"42926","257.52000","21.46026","0.26040"
"42966","257.76000","21.48023","0.26167"
"43006","258.00000","21.50020","0.26206"
"43046","258.24000","21.52017","0.26447"
"43086","258.48000","21.54020","0.26501"
"43126","258.72000","21.56017","0.26652"
"43166","258.96000","21.58013","0.26788"
"43206","259.20000","21.60022","0.26958"
"43246","259.44000","21.62013","0.27063"
"43286","259.68000","21.64022","0.27231"
"43326","259.92000","21.66013","0.27342"
"43366","260.16000","21.68022","0.27479"
"43406","260.40000","21.70019","0.27594"
"43446","260.64000","21.72022","0.27687"
"43486","260.88000","21.74019","0.27844"
"43526","261.12000","21.76016","0.27901"
"43566","261.36000","21.78025","0.28118"
"43606","261.60000","21.80016","0.28302"
"43646","261.84000","21.82019","0.28530"
"43686","262.08000","21.84022","0.28708"
"43726","262.32000","21.86019","0.29107"
"43766","262.56000","21.88016","0.29370"
"43806","262.80000","21.90031","0.29488"
"43846","263.04000","21.92016","0.29608"
"43886","263.28000","21.94019","0.29764"
"43926","263.52000","21.96016","0.29934"
"43966","263.76000","21.98018","0.30019"
"44006","264.00000","22.00028","0.30116"
"44046","264.24000","22.02019","0.30308"
"44086","264.48000","22.04022","0.30359"
"44126","264.72000","22.06013","0.30525"
"44166","264.96000","22.08027","0.30585"
"44206","265.20000","22.10018","0.30656"
"44246","265.44000","22.12016","0.30754"
"44286","265.68000","22.14024","0.30931"
"44326","265.92000","22.16021","0.31082"
"44366","266.16000","22.18024","0.31225"
"44406","266.40000","22.20015","0.31351"
"44446","266.64000","22.22024","0.31622"
"44486","266.88000","22.24015","0.31901"
"44526","267.12000","22.26024","0.32219"
"44566","267.36000","22.28021","0.32480"
"44606","267.60000","22.30024","0.32755"
"44646","267.84000","22.32021","0.32997"
"44686","268.08000","22.34018","0.33122"
"44726","268.32000","22.36021","0.33321"
"44766","268.56000","22.38018","0.33424"
"44806","268.80000","22.40027","0.33548"
"44846","269.04000","22.42018","0.33641"
"44886","269.28000","22.44021","0.33861"
"44926","269.52000","22.46018","0.33976"
"44966","269.76000","22.48021","0.34172"
"45006","270.00000","22.50024","0.34328"
"45046","270.24000","22.52021","0.34443"
"45086","270.48000","22.54023","0.34258"
"45126","270.72000","22.56015","0.34484"
"45166","270.96000","22.58023","0.34705"
"45206","271.20000","22.60020","0.34841"
"45246","271.44000","22.62024","0.34965"
"45286","271.68000","22.64020","0.35053"
"45326","271.92000","22.66017","0.35127"
"45366","272.16000","22.68020","0.35179"
"45406","272.40000","22.70023","0.35207"
"45446","272.64000","22.72026","0.35223"
"45486","272.88000","22.74017","0.35247"
"45526","273.12000","22.76026","0.35256"
"45566","273.36000","22.78017","0.35259"
"45606","273.60000","22.80026","0.35264"
"45646","273.84000","22.82017","0.35271"
"45686","274.08000","22.84020","0.35266"
"45726","274.32000","22.86023","0.35273"
"45766","274.56000","22.88020","0.35272"
"45806","274.80000","22.90023","0.26321"
"45846","275.04000","22.92014","0.25828"
"45886","275.28000","22.94023","0.25777"
"45926","275.52000","22.96014","0.25903"
"45966","275.76000","22.98023","0.26034"
"46006","276.00000","23.00020","0.25988"
"46046","276.24000","23.02017","0.26204"
"46086","276.48000","23.04020","0.26327"
"46126","276.72000","23.06016","0.26454"
"46166","276.96000","23.08026","0.26622"
"46206","277.20000","23.10023","0.26670"
"46246","277.44000","23.12025","0.26856"
"46286","277.68000","23.14016","0.26969"
"46326","277.92000","23.16019","0.27056"
"46366","278.16000","23.18016","0.27192"
"46406","278.40000","23.20019","0.27068"
"46446","278.64000","23.22022","0.12972"
"46486","278.88000","23.24019","0.11247"
"46526","279.12000","23.26022","0.12090"
"46566","279.36000","23.28019","0.10764"
"46606","279.60000","23.30022","0.11151"
"46646","279.84000","23.32013","0.12331"
"46686","280.08000","23.34022","0.11469"
"46726","280.32000","23.36019","0.13063"
"46766","280.56000","23.38022","0.11870"
"46806","280.80000","23.40019","0.12990"
"46846","281.04000","23.42016","0.12433"
"46886","281.28000","23.44024","0.12555"
"46926","281.52000","23.46016","0.13099"
"46966","281.76000","23.48025","0.12653"
"47006","282.00000","23.50016","0.13450"
"47046","282.24000","23.52019","0.13165"
"47086","282.48000","23.54016","0.13398"
"47126","282.72000","23.56025","0.13724"
"47166","282.96000","23.58021","0.13339"
"47206","283.20000","23.60024","0.14008"
"47246","283.44000","23.62027","0.13443"
"47286","283.68000","23.64012","0.13801"
"47326","283.92000","23.66021","0.13848"
"47366","284.16000","23.68012","0.13817"
"47406","284.40000","23.70021","0.14094"
"47446","284.64000","23.72012","0.14006"
"47486","284.88000","23.74021","0.13947"
"47526","285.12000","23.76018","0.14166"
"47566","285.36000","23.78015","0.13981"
"47606","285.60000","23.80024","0.14142"
"47646","285.84000","23.82015","0.14127"
"47686","286.08000","23.84024","0.14139"
"47726","286.32000","23.86021","0.14245"
"47766","286.56000","23.88018","0.14173"
"47806","286.80000","23.90015","0.14160"
"47846","287.04000","23.92024","0.14280"
"47886","287.28000","23.94020","0.14194"
"47926","287.52000","23.96024","0.14259"
"47966","287.76000","23.98027","0.14312"
"48006","288.00000","24.00018","0.14269"
"48046","288.24000","24.02026","0.14320"
"48086","288.48000","24.04017","0.14333"
"48126","288.72000","24.06021","0.14324"
"48166","288.96000","24.08017","0.14419"
"48206","289.20000","24.10026","0.14449"
"48246","289.44000","24.12017","0.14412"
"48286","289.68000","24.14020","0.14502"
"48326","289.92000","24.16023","0.14465"
"48366","290.16000","24.18020","0.14420"
"48406","290.40000","24.20023","0.14526"
"48446","290.64000","24.22020","0.14560"
"48486","290.88000","24.24017","0.14542"
"48526","291.12000","24.26014","0.14704"
"48566","291.36000","24.28023","0.14682"
"48606","291.60000","24.30020","0.14784"
"48646","291.84000","24.32023","0.14733"
"48686","292.08000","24.34020","0.14714"
"48726","292.32000","24.36023","0.14730"
"48766","292.56000","24.38026","0.14841"
"48806","292.80000","24.40017","0.14928"
"48846","293.04000","24.42026","0.14990"
"48886","293.28000","24.44017","0.14974"
"48926","293.52000","24.46020","0.14979"
"48966","293.76000","24.48017","0.14935"
"49006","294.00000","24.50019","0.14988"
"49046","294.24000","24.52022","0.14952"
"49086","294.48000","24.54020","0.15083"
"49126","294.72000","24.56022","0.15163"
"49166","294.96000","24.58019","0.15275"
"49206","295.20000","24.60023","0.15292"
"49246","295.44000","24.62013","0.15361"
"49286","295.68000","24.64022","0.15358"
"49326","295.92000","24.66019","0.15346"
"49366","296.16000","24.68022","0.15285"
"49406","296.40000","24.70019","0.15319"
"49446","296.64000","24.72022","0.15317"
"49486","296.88000","24.74019","0.15342"
"49526","297.12000","24.76022","0.15471"
"49566","297.36000","24.78025","0.15511"
"49601","297.57000","24.79765","0.15608"