File: Trajectories_together/161104Specimen_RawData_5.csv
"","V1","V2","V3"
"1","End date","11/4/2016",""
"2","Specimen label","",""
"3","Maximum Load","1.49282","N"
"4","Time","Extension","Load"
"5","(s)","(mm)","(N)"
"6","0.00000","0.00000","0.00006"
"32","0.15600","0.00855","0.00023"
"58","0.31200","0.02541","0.00058"
"84","0.46800","0.03934","0.00021"
"110","0.62400","0.05220","0.00064"
"136","0.78000","0.06511","0.00080"
"162","0.93600","0.07820","0.00090"
"188","1.09200","0.09118","0.00101"
"214","1.24800","0.10415","0.00119"
"240","1.40400","0.11719","0.00103"
"266","1.56000","0.13016","0.00091"
"292","1.71600","0.14314","0.00068"
"318","1.87200","0.15611","0.00097"
"344","2.02800","0.16914","0.00101"
"370","2.18400","0.18218","0.00107"
"396","2.34000","0.19515","0.00120"
"422","2.49600","0.20813","0.00107"
"448","2.65200","0.22116","0.00093"
"474","2.80800","0.23414","0.00125"
"500","2.96400","0.24711","0.00115"
"526","3.12000","0.26020","0.00085"
"552","3.27600","0.27312","0.00126"
"578","3.43200","0.28609","0.00105"
"604","3.58800","0.29913","0.00115"
"630","3.74400","0.31216","0.00112"
"656","3.90000","0.32508","0.00109"
"682","4.05600","0.33811","0.00125"
"708","4.21200","0.35120","0.00146"
"734","4.36800","0.36418","0.00151"
"760","4.52400","0.37709","0.00139"
"786","4.68000","0.39013","0.00103"
"812","4.83600","0.40316","0.00120"
"838","4.99200","0.41608","0.00154"
"864","5.14800","0.42905","0.00103"
"890","5.30400","0.44214","0.00167"
"916","5.46000","0.45512","0.00111"
"942","5.61600","0.46803","0.00122"
"968","5.77200","0.48113","0.00125"
"994","5.92800","0.49416","0.00116"
"1020","6.08400","0.50713","0.00095"
"1046","6.24000","0.52011","0.00128"
"1072","6.39600","0.53314","0.00113"
"1098","6.55200","0.54612","0.00149"
"1124","6.70800","0.55909","0.00174"
"1150","6.86400","0.57213","0.00142"
"1176","7.02000","0.58516","0.00182"
"1202","7.17600","0.59807","0.00159"
"1228","7.33200","0.61111","0.00115"
"1254","7.48800","0.62408","0.00155"
"1280","7.64400","0.63712","0.00184"
"1306","7.80000","0.65009","0.00126"
"1332","7.95600","0.66313","0.00147"
"1358","8.11200","0.67616","0.00166"
"1384","8.26800","0.68907","0.00161"
"1410","8.42400","0.70211","0.00159"
"1436","8.58000","0.71508","0.00162"
"1462","8.73600","0.72812","0.00167"
"1488","8.89200","0.74109","0.00139"
"1514","9.04800","0.75419","0.00202"
"1540","9.20400","0.76716","0.00143"
"1566","9.36000","0.78007","0.00140"
"1592","9.51600","0.79311","0.00136"
"1618","9.67200","0.80614","0.00158"
"1644","9.82800","0.81912","0.00183"
"1670","9.98400","0.83209","0.00171"
"1696","10.14000","0.84513","0.00176"
"1722","10.29600","0.85810","0.00159"
"1748","10.45200","0.87107","0.00207"
"1774","10.60800","0.88411","0.00192"
"1800","10.76400","0.89708","0.00192"
"1826","10.92000","0.91012","0.00218"
"1852","11.07600","0.92309","0.00223"
"1878","11.23200","0.93612","0.00248"
"1904","11.38800","0.94916","0.00252"
"1930","11.54400","0.96207","0.00229"
"1956","11.70000","0.97511","0.00209"
"1982","11.85600","0.98808","0.00201"
"2008","12.01200","1.00106","0.00184"
"2034","12.16800","1.01409","0.00218"
"2060","12.32400","1.02712","0.00266"
"2086","12.48000","1.04010","0.00289"
"2112","12.63600","1.05307","0.00254"
"2138","12.79200","1.06611","0.00260"
"2164","12.94800","1.07914","0.00268"
"2190","13.10400","1.09206","0.00256"
"2216","13.26000","1.10509","0.00275"
"2242","13.41600","1.11812","0.00250"
"2268","13.57200","1.13116","0.00257"
"2294","13.72800","1.14401","0.00238"
"2320","13.88400","1.15717","0.00292"
"2346","14.04000","1.17014","0.00251"
"2372","14.19600","1.18312","0.00265"
"2398","14.35200","1.19609","0.00215"
"2424","14.50800","1.20918","0.00256"
"2450","14.66400","1.22210","0.00255"
"2476","14.82000","1.23507","0.00265"
"2502","14.97600","1.24811","0.00246"
"2528","15.13200","1.26114","0.00296"
"2554","15.28800","1.27411","0.00294"
"2580","15.44400","1.28709","0.00309"
"2606","15.60000","1.30012","0.00296"
"2632","15.75600","1.31310","0.00249"
"2658","15.91200","1.32601","0.00280"
"2684","16.06800","1.33911","0.00283"
"2710","16.22400","1.35214","0.00328"
"2736","16.38000","1.36505","0.00311"
"2762","16.53600","1.37815","0.00283"
"2788","16.69200","1.39118","0.00263"
"2814","16.84800","1.40410","0.00314"
"2840","17.00400","1.41707","0.00315"
"2866","17.16000","1.43011","0.00321"
"2892","17.31600","1.44314","0.00361"
"2918","17.47200","1.45605","0.00291"
"2944","17.62800","1.46909","0.00342"
"2970","17.78400","1.48212","0.00322"
"2996","17.94000","1.49510","0.00316"
"3022","18.09600","1.50807","0.00340"
"3048","18.25200","1.52111","0.00332"
"3074","18.40800","1.53414","0.00311"
"3100","18.56400","1.54705","0.00311"
"3126","18.72000","1.56015","0.00332"
"3152","18.87600","1.57312","0.00384"
"3178","19.03200","1.58610","0.00364"
"3204","19.18800","1.59907","0.00420"
"3230","19.34400","1.61211","0.00325"
"3256","19.50000","1.62508","0.00418"
"3282","19.65600","1.63805","0.00406"
"3308","19.81200","1.65115","0.00375"
"3334","19.96800","1.66412","0.00360"
"3360","20.12400","1.67710","0.00373"
"3386","20.28000","1.69013","0.00443"
"3412","20.43600","1.70310","0.00433"
"3438","20.59200","1.71608","0.00413"
"3464","20.74800","1.72911","0.00388"
"3490","20.90400","1.74215","0.00417"
"3516","21.06000","1.75512","0.00403"
"3542","21.21600","1.76804","0.00404"
"3568","21.37200","1.78113","0.00457"
"3594","21.52800","1.79416","0.00425"
"3620","21.68400","1.80708","0.00437"
"3646","21.84000","1.82011","0.00427"
"3672","21.99600","1.83315","0.00453"
"3698","22.15200","1.84612","0.00536"
"3724","22.30800","1.85904","0.00434"
"3750","22.46400","1.87213","0.00464"
"3776","22.62000","1.88516","0.00425"
"3802","22.77600","1.89808","0.00444"
"3828","22.93200","1.91111","0.00429"
"3854","23.08800","1.92415","0.00458"
"3880","23.24400","1.93706","0.00470"
"3906","23.40000","1.95004","0.00546"
"3932","23.55600","1.96313","0.00464"
"3958","23.71200","1.97616","0.00503"
"3984","23.86800","1.98908","0.00489"
"4010","24.02400","2.00217","0.00475"
"4036","24.18000","2.01515","0.00524"
"4062","24.33600","2.02812","0.00550"
"4088","24.49200","2.04110","0.00490"
"4114","24.64800","2.05407","0.00522"
"4140","24.80400","2.06710","0.00502"
"4166","24.96000","2.08008","0.00506"
"4192","25.11600","2.09311","0.00544"
"4218","25.27200","2.10609","0.00597"
"4244","25.42800","2.11912","0.00562"
"4270","25.58400","2.13209","0.00564"
"4296","25.74000","2.14513","0.00535"
"4322","25.89600","2.15810","0.00511"
"4348","26.05200","2.17108","0.00560"
"4374","26.20800","2.18411","0.00506"
"4400","26.36400","2.19715","0.00548"
"4426","26.52000","2.21012","0.00529"
"4452","26.67600","2.22309","0.00623"
"4478","26.83200","2.23607","0.00610"
"4504","26.98800","2.24910","0.00628"
"4530","27.14400","2.26208","0.00586"
"4556","27.30000","2.27517","0.00583"
"4582","27.45600","2.28815","0.00613"
"4608","27.61200","2.30112","0.00590"
"4634","27.76800","2.31409","0.00632"
"4660","27.92400","2.32713","0.00590"
"4686","28.08000","2.34010","0.00608"
"4712","28.23600","2.35308","0.00619"
"4738","28.39200","2.36611","0.00608"
"4764","28.54800","2.37914","0.00674"
"4790","28.70400","2.39206","0.00641"
"4816","28.86000","2.40515","0.00585"
"4842","29.01600","2.41813","0.00610"
"4868","29.17200","2.43116","0.00634"
"4894","29.32800","2.44408","0.00648"
"4920","29.48400","2.45717","0.00706"
"4946","29.64000","2.47014","0.00655"
"4972","29.79600","2.48306","0.00705"
"4998","29.95200","2.49615","0.00649"
"5024","30.10800","2.50913","0.00703"
"5050","30.26400","2.52210","0.00633"
"5076","30.42000","2.53508","0.00713"
"5102","30.57600","2.54811","0.00727"
"5128","30.73200","2.56114","0.00708"
"5154","30.88800","2.57412","0.00683"
"5180","31.04400","2.58715","0.00680"
"5206","31.20000","2.60019","0.00716"
"5232","31.35600","2.61310","0.00636"
"5258","31.51200","2.62614","0.00734"
"5284","31.66800","2.63911","0.00727"
"5310","31.82400","2.65214","0.00690"
"5336","31.98000","2.66506","0.00756"
"5362","32.13600","2.67809","0.00682"
"5388","32.29200","2.69113","0.00756"
"5414","32.44800","2.70410","0.00755"
"5440","32.60400","2.71714","0.00789"
"5466","32.76000","2.73017","0.00726"
"5492","32.91600","2.74314","0.00749"
"5518","33.07200","2.75606","0.00802"
"5544","33.22800","2.76909","0.00817"
"5570","33.38400","2.78219","0.00801"
"5596","33.54000","2.79516","0.00847"
"5622","33.69600","2.80814","0.00791"
"5648","33.85200","2.82111","0.00808"
"5674","34.00800","2.83414","0.00833"
"5700","34.16400","2.84706","0.00870"
"5726","34.32000","2.86015","0.00889"
"5752","34.47600","2.87313","0.00898"
"5778","34.63200","2.88610","0.00892"
"5804","34.78800","2.89913","0.00907"
"5830","34.94400","2.91211","0.00885"
"5856","35.10000","2.92514","0.00858"
"5882","35.25600","2.93806","0.00915"
"5908","35.41200","2.95115","0.00881"
"5934","35.56800","2.96413","0.00923"
"5960","35.72400","2.97710","0.00938"
"5986","35.88000","2.99007","0.00935"
"6012","36.03600","3.00311","0.00964"
"6038","36.19200","3.01608","0.00952"
"6064","36.34800","3.02912","0.01003"
"6090","36.50400","3.04215","0.00914"
"6116","36.66000","3.05513","0.00886"
"6142","36.81600","3.06810","0.00972"
"6168","36.97200","3.08113","0.01000"
"6194","37.12800","3.09417","0.00970"
"6220","37.28400","3.10708","0.01002"
"6246","37.44000","3.12012","0.00966"
"6272","37.59600","3.13309","0.01062"
"6298","37.75200","3.14613","0.01041"
"6324","37.90800","3.15910","0.01057"
"6350","38.06400","3.17213","0.01063"
"6376","38.22000","3.18517","0.00986"
"6402","38.37600","3.19808","0.01039"
"6428","38.53200","3.21112","0.00939"
"6454","38.68800","3.22409","0.01037"
"6480","38.84400","3.23712","0.01071"
"6506","39.00000","3.25004","0.01100"
"6532","39.15600","3.26313","0.01027"
"6558","39.31200","3.27617","0.01110"
"6584","39.46800","3.28908","0.01078"
"6610","39.62400","3.30212","0.01119"
"6636","39.78000","3.31515","0.01139"
"6662","39.93600","3.32818","0.01136"
"6688","40.09200","3.34116","0.01126"
"6714","40.24800","3.35413","0.01132"
"6740","40.40400","3.36717","0.01184"
"6766","40.56000","3.38008","0.01152"
"6792","40.71600","3.39306","0.01095"
"6818","40.87200","3.40609","0.01175"
"6844","41.02800","3.41906","0.01098"
"6870","41.18400","3.43210","0.01211"
"6896","41.34000","3.44513","0.01175"
"6922","41.49600","3.45817","0.01259"
"6948","41.65200","3.47108","0.01263"
"6974","41.80800","3.48412","0.01267"
"7000","41.96400","3.49715","0.01292"
"7026","42.12000","3.51012","0.01258"
"7052","42.27600","3.52310","0.01290"
"7078","42.43200","3.53607","0.01285"
"7104","42.58800","3.54911","0.01279"
"7130","42.74400","3.56202","0.01309"
"7156","42.90000","3.57511","0.01292"
"7182","43.05600","3.58815","0.01352"
"7208","43.21200","3.60112","0.01321"
"7234","43.36800","3.61410","0.01329"
"7260","43.52400","3.62713","0.01383"
"7286","43.68000","3.64017","0.01370"
"7312","43.83600","3.65308","0.01346"
"7338","43.99200","3.66612","0.01431"
"7364","44.14800","3.67915","0.01386"
"7390","44.30400","3.69212","0.01332"
"7416","44.46000","3.70510","0.01368"
"7442","44.61600","3.71807","0.01387"
"7468","44.77200","3.73111","0.01409"
"7494","44.92800","3.74408","0.01449"
"7520","45.08400","3.75711","0.01461"
"7546","45.24000","3.77015","0.01477"
"7572","45.39600","3.78312","0.01558"
"7598","45.55200","3.79610","0.01448"
"7624","45.70800","3.80913","0.01566"
"7650","45.86400","3.82205","0.01509"
"7676","46.02000","3.83508","0.01523"
"7702","46.17600","3.84811","0.01566"
"7728","46.33200","3.86115","0.01624"
"7754","46.48800","3.87406","0.01620"
"7780","46.64400","3.88716","0.01635"
"7806","46.80000","3.90013","0.01610"
"7832","46.95600","3.91311","0.01610"
"7858","47.11200","3.92608","0.01633"
"7884","47.26800","3.93911","0.01666"
"7910","47.42400","3.95215","0.01662"
"7936","47.58000","3.96512","0.01666"
"7962","47.73600","3.97816","0.01692"
"7988","47.89200","3.99113","0.01676"
"8014","48.04800","4.00405","0.01686"
"8040","48.20400","4.01708","0.01682"
"8066","48.36000","4.03011","0.01745"
"8092","48.51600","4.04315","0.01739"
"8118","48.67200","4.05606","0.01756"
"8144","48.82800","4.06916","0.01779"
"8170","48.98400","4.08213","0.01781"
"8196","49.14000","4.09510","0.01757"
"8222","49.29600","4.10808","0.01793"
"8248","49.45200","4.12111","0.01808"
"8274","49.60800","4.13415","0.01847"
"8300","49.76400","4.14706","0.01839"
"8326","49.92000","4.16016","0.01823"
"8352","50.07600","4.17313","0.01853"
"8378","50.23200","4.18610","0.01888"
"8404","50.38800","4.19908","0.01946"
"8430","50.54400","4.21211","0.01888"
"8456","50.70000","4.22509","0.01897"
"8482","50.85600","4.23806","0.01995"
"8508","51.01200","4.25110","0.01931"
"8534","51.16800","4.26413","0.01958"
"8560","51.32400","4.27704","0.01959"
"8586","51.48000","4.29008","0.01996"
"8612","51.63600","4.30311","0.01954"
"8638","51.79200","4.31609","0.02010"
"8664","51.94800","4.32906","0.02021"
"8690","52.10400","4.34215","0.02050"
"8716","52.26000","4.35513","0.02035"
"8742","52.41600","4.36810","0.02042"
"8768","52.57200","4.38114","0.02086"
"8794","52.72800","4.39417","0.02090"
"8820","52.88400","4.40709","0.02072"
"8846","53.04000","4.42006","0.02149"
"8872","53.19600","4.43315","0.02127"
"8898","53.35200","4.44613","0.02123"
"8924","53.50800","4.45904","0.02209"
"8950","53.66400","4.47208","0.02170"
"8976","53.82000","4.48511","0.02148"
"9002","53.97600","4.49809","0.02201"
"9028","54.13200","4.51112","0.02190"
"9054","54.28800","4.52415","0.02251"
"9080","54.44400","4.53713","0.02254"
"9106","54.60000","4.55010","0.02265"
"9132","54.75600","4.56314","0.02242"
"9158","54.91200","4.57617","0.02263"
"9184","55.06800","4.58909","0.02261"
"9210","55.22400","4.60212","0.02291"
"9236","55.38000","4.61509","0.02345"
"9262","55.53600","4.62807","0.02306"
"9288","55.69200","4.64104","0.02348"
"9314","55.84800","4.65414","0.02358"
"9340","56.00400","4.66723","0.02342"
"9366","56.16000","4.68015","0.02375"
"9392","56.31600","4.69318","0.02360"
"9418","56.47200","4.70615","0.02370"
"9444","56.62800","4.71913","0.02380"
"9470","56.78400","4.73204","0.02446"
"9496","56.94000","4.74514","0.02445"
"9522","57.09600","4.75811","0.02447"
"9548","57.25200","4.77108","0.02484"
"9574","57.40800","4.78406","0.02476"
"9600","57.56400","4.79715","0.02489"
"9626","57.72000","4.81007","0.02463"
"9652","57.87600","4.82310","0.02497"
"9678","58.03200","4.83614","0.02559"
"9704","58.18800","4.84917","0.02513"
"9730","58.34400","4.86208","0.02528"
"9756","58.50000","4.87512","0.02566"
"9782","58.65600","4.88815","0.02581"
"9808","58.81200","4.90107","0.02647"
"9834","58.96800","4.91404","0.02626"
"9860","59.12400","4.92714","0.02624"
"9886","59.28000","4.94011","0.02639"
"9912","59.43600","4.95308","0.02611"
"9938","59.59200","4.96618","0.02673"
"9964","59.74800","4.97915","0.02716"
"9990","59.90400","4.99207","0.02699"
"10016","60.06000","5.00510","0.02726"
"10042","60.21600","5.01814","0.02708"
"10068","60.37200","5.03111","0.02693"
"10094","60.52800","5.04408","0.02748"
"10120","60.68400","5.05712","0.02792"
"10146","60.84000","5.07009","0.02797"
"10172","60.99600","5.08307","0.02794"
"10198","61.15200","5.09610","0.02844"
"10224","61.30800","5.10914","0.02872"
"10250","61.46400","5.12217","0.02873"
"10276","61.62000","5.13514","0.02900"
"10302","61.77600","5.14818","0.02878"
"10328","61.93200","5.16115","0.02951"
"10354","62.08800","5.17407","0.02979"
"10380","62.24400","5.18716","0.02925"
"10406","62.40000","5.20014","0.02953"
"10432","62.55600","5.21311","0.02886"
"10458","62.71200","5.22614","0.02877"
"10484","62.86800","5.23918","0.02953"
"10510","63.02400","5.25215","0.02928"
"10536","63.18000","5.26507","0.02933"
"10562","63.33600","5.27816","0.03014"
"10588","63.49200","5.29113","0.03014"
"10614","63.64800","5.30411","0.03047"
"10640","63.80400","5.31714","0.03026"
"10666","63.96000","5.33012","0.03088"
"10692","64.11600","5.34309","0.03111"
"10718","64.27200","5.35601","0.03123"
"10744","64.42800","5.36916","0.03133"
"10770","64.58400","5.38213","0.03165"
"10796","64.74000","5.39511","0.03132"
"10822","64.89600","5.40814","0.03170"
"10848","65.05200","5.42118","0.03147"
"10874","65.20800","5.43415","0.03225"
"10900","65.36400","5.44701","0.03214"
"10926","65.52000","5.46016","0.03262"
"10952","65.67600","5.47313","0.03315"
"10978","65.83200","5.48617","0.03261"
"11004","65.98800","5.49914","0.03304"
"11030","66.14400","5.51218","0.03376"
"11056","66.30000","5.52509","0.03479"
"11082","66.45600","5.53807","0.03436"
"11108","66.61200","5.55110","0.03405"
"11134","66.76800","5.56419","0.03477"
"11160","66.92400","5.57711","0.03557"
"11186","67.08000","5.59014","0.03559"
"11212","67.23600","5.60312","0.03628"
"11238","67.39200","5.61609","0.03632"
"11264","67.54800","5.62913","0.03716"
"11290","67.70400","5.64210","0.03704"
"11316","67.86000","5.65513","0.03762"
"11342","68.01600","5.66805","0.03775"
"11368","68.17200","5.68108","0.03816"
"11394","68.32800","5.69412","0.03906"
"11420","68.48400","5.70709","0.03930"
"11446","68.64000","5.72012","0.04000"
"11472","68.79600","5.73316","0.04019"
"11498","68.95200","5.74613","0.04108"
"11524","69.10800","5.75905","0.04067"
"11550","69.26400","5.77214","0.04140"
"11576","69.42000","5.78512","0.04243"
"11602","69.57600","5.79809","0.04248"
"11628","69.73200","5.81112","0.04324"
"11654","69.88800","5.82416","0.04344"
"11680","70.04400","5.83713","0.04384"
"11706","70.20000","5.85011","0.04509"
"11732","70.35600","5.86320","0.04487"
"11758","70.51200","5.87617","0.04490"
"11784","70.66800","5.88909","0.04509"
"11810","70.82400","5.90206","0.04636"
"11836","70.98000","5.91510","0.04748"
"11862","71.13600","5.92813","0.04782"
"11888","71.29200","5.94105","0.04796"
"11914","71.44800","5.95408","0.04902"
"11940","71.60400","5.96711","0.04870"
"11966","71.76000","5.98003","0.04935"
"11992","71.91600","5.99312","0.04998"
"12018","72.07200","6.00616","0.05026"
"12044","72.22800","6.01919","0.05137"
"12070","72.38400","6.03211","0.05169"
"12096","72.54000","6.04520","0.05201"
"12122","72.69600","6.05811","0.05347"
"12148","72.85200","6.07103","0.05367"
"12174","73.00800","6.08412","0.05440"
"12200","73.16400","6.09716","0.05433"
"12226","73.32000","6.11007","0.05506"
"12252","73.47600","6.12305","0.05576"
"12278","73.63200","6.13614","0.05571"
"12304","73.78800","6.14911","0.05630"
"12330","73.94400","6.16209","0.05659"
"12356","74.10000","6.17512","0.05663"
"12382","74.25600","6.18816","0.05693"
"12408","74.41200","6.20113","0.05742"
"12434","74.56800","6.21411","0.05811"
"12460","74.72400","6.22714","0.05885"
"12486","74.88000","6.24011","0.05896"
"12512","75.03600","6.25303","0.05943"
"12538","75.19200","6.26612","0.06057"
"12564","75.34800","6.27916","0.06037"
"12590","75.50400","6.29213","0.06144"
"12616","75.66000","6.30511","0.06069"
"12642","75.81600","6.31814","0.06085"
"12668","75.97200","6.33117","0.06198"
"12694","76.12800","6.34409","0.06311"
"12720","76.28400","6.35712","0.06255"
"12746","76.44000","6.37016","0.06302"
"12772","76.59600","6.38307","0.06382"
"12798","76.75200","6.39610","0.06440"
"12824","76.90800","6.40908","0.06472"
"12850","77.06400","6.42211","0.06515"
"12876","77.22000","6.43503","0.06614"
"12902","77.37600","6.44812","0.06661"
"12928","77.53200","6.46116","0.06714"
"12954","77.68800","6.47407","0.06721"
"12980","77.84400","6.48710","0.06843"
"13006","78.00000","6.50008","0.06742"
"13032","78.15600","6.51311","0.06800"
"13058","78.31200","6.52603","0.06787"
"13084","78.46800","6.53912","0.06854"
"13110","78.62400","6.55216","0.06955"
"13136","78.78000","6.56507","0.06908"
"13162","78.93600","6.57810","0.07008"
"13188","79.09200","6.59114","0.07007"
"13214","79.24800","6.60405","0.07047"
"13240","79.40400","6.61709","0.07105"
"13266","79.56000","6.63012","0.07146"
"13292","79.71600","6.64310","0.07199"
"13318","79.87200","6.65613","0.07182"
"13344","80.02800","6.66910","0.07270"
"13370","80.18400","6.68214","0.07335"
"13396","80.34000","6.69505","0.07308"
"13422","80.49600","6.70809","0.07346"
"13448","80.65200","6.72112","0.07395"
"13474","80.80800","6.73416","0.07410"
"13500","80.96400","6.74707","0.07467"
"13526","81.12000","6.76022","0.07504"
"13552","81.27600","6.77314","0.07505"
"13578","81.43200","6.78605","0.07545"
"13604","81.58800","6.79909","0.07543"
"13630","81.74400","6.81212","0.07552"
"13656","81.90000","6.82516","0.07594"
"13682","82.05600","6.83801","0.07592"
"13708","82.21200","6.85116","0.07634"
"13734","82.36800","6.86414","0.07601"
"13760","82.52400","6.87711","0.07615"
"13786","82.68000","6.89015","0.07636"
"13812","82.83600","6.90312","0.07678"
"13838","82.99200","6.91615","0.07671"
"13864","83.14800","6.92913","0.07715"
"13890","83.30400","6.94216","0.07718"
"13916","83.46000","6.95514","0.07733"
"13942","83.61600","6.96805","0.07750"
"13968","83.77200","6.98109","0.07802"
"13994","83.92800","6.99412","0.07802"
"14020","84.08400","7.00709","0.07824"
"14046","84.24000","7.02001","0.07859"
"14072","84.39600","7.03316","0.07850"
"14098","84.55200","7.04614","0.07852"
"14124","84.70800","7.05911","0.07898"
"14150","84.86400","7.07214","0.07910"
"14176","85.02000","7.08518","0.07927"
"14202","85.17600","7.09809","0.07923"
"14228","85.33200","7.11113","0.07968"
"14254","85.48800","7.12410","0.08018"
"14280","85.64400","7.13714","0.07979"
"14306","85.80000","7.14999","0.07907"
"14332","85.95600","7.16314","0.07987"
"14358","86.11200","7.17612","0.07927"
"14384","86.26800","7.18909","0.08060"
"14410","86.42400","7.20207","0.08070"
"14436","86.58000","7.21510","0.08085"
"14462","86.73600","7.22808","0.08179"
"14488","86.89200","7.24105","0.08140"
"14514","87.04800","7.25415","0.08243"
"14540","87.20400","7.26718","0.08210"
"14566","87.36000","7.28015","0.08300"
"14592","87.51600","7.29313","0.08346"
"14618","87.67200","7.30610","0.08381"
"14644","87.82800","7.31908","0.08497"
"14670","87.98400","7.33211","0.08478"
"14696","88.14000","7.34514","0.08557"
"14722","88.29600","7.35818","0.08571"
"14748","88.45200","7.37109","0.08640"
"14774","88.60800","7.38413","0.08687"
"14800","88.76400","7.39710","0.08722"
"14826","88.92000","7.41008","0.08780"
"14852","89.07600","7.42305","0.08804"
"14878","89.23200","7.43614","0.08845"
"14904","89.38800","7.44912","0.08922"
"14930","89.54400","7.46209","0.08956"
"14956","89.70000","7.47513","0.09002"
"14982","89.85600","7.48816","0.09052"
"15008","90.01200","7.50108","0.09124"
"15034","90.16800","7.51411","0.09149"
"15060","90.32400","7.52714","0.09150"
"15086","90.48000","7.54012","0.09204"
"15112","90.63600","7.55309","0.09266"
"15138","90.79200","7.56613","0.09330"
"15164","90.94800","7.57916","0.09424"
"15190","91.10400","7.59208","0.09429"
"15216","91.26000","7.60505","0.09499"
"15242","91.41600","7.61814","0.09523"
"15268","91.57200","7.63118","0.09546"
"15294","91.72800","7.64409","0.09653"
"15320","91.88400","7.65713","0.09697"
"15346","92.04000","7.67016","0.09761"
"15372","92.19600","7.68307","0.09776"
"15398","92.35200","7.69605","0.09884"
"15424","92.50800","7.70914","0.09893"
"15450","92.66400","7.72212","0.10013"
"15476","92.82000","7.73503","0.10079"
"15502","92.97600","7.74813","0.10123"
"15528","93.13200","7.76116","0.10292"
"15554","93.28800","7.77407","0.10342"
"15580","93.44400","7.78711","0.10449"
"15606","93.60000","7.80014","0.10465"
"15632","93.75600","7.81318","0.10565"
"15658","93.91200","7.82615","0.10627"
"15684","94.06800","7.83912","0.10760"
"15710","94.22400","7.85216","0.10884"
"15736","94.38000","7.86507","0.10948"
"15762","94.53600","7.87811","0.11030"
"15788","94.69200","7.89114","0.11086"
"15814","94.84800","7.90412","0.11145"
"15840","95.00400","7.91709","0.11227"
"15866","95.16000","7.93013","0.11377"
"15892","95.31600","7.94316","0.11418"
"15918","95.47200","7.95613","0.11570"
"15944","95.62800","7.96911","0.11638"
"15970","95.78400","7.98214","0.11667"
"15996","95.94000","7.99512","0.11785"
"16022","96.09600","8.00809","0.11893"
"16048","96.25200","8.02112","0.11993"
"16074","96.40800","8.03410","0.12045"
"16100","96.56400","8.04701","0.12131"
"16126","96.72000","8.06011","0.12241"
"16152","96.87600","8.07314","0.12299"
"16178","97.03200","8.08606","0.12406"
"16204","97.18800","8.09909","0.12523"
"16230","97.34400","8.11212","0.12600"
"16256","97.50000","8.12516","0.12700"
"16282","97.65600","8.13807","0.12783"
"16308","97.81200","8.15117","0.12832"
"16334","97.96800","8.16414","0.12955"
"16360","98.12400","8.17718","0.13093"
"16386","98.28000","8.19015","0.13081"
"16412","98.43600","8.20312","0.13207"
"16438","98.59200","8.21610","0.13349"
"16464","98.74800","8.22907","0.13405"
"16490","98.90400","8.24217","0.13432"
"16516","99.06000","8.25520","0.13496"
"16542","99.21600","8.26812","0.13567"
"16568","99.37200","8.28115","0.13619"
"16594","99.52800","8.29412","0.13669"
"16620","99.68400","8.30710","0.13710"
"16646","99.84000","8.32007","0.13776"
"16672","99.99600","8.33317","0.13795"
"16698","100.15200","8.34614","0.13822"
"16724","100.30800","8.35905","0.13863"
"16750","100.46400","8.37209","0.13890"
"16776","100.62000","8.38512","0.13924"
"16802","100.77600","8.39810","0.13933"
"16828","100.93200","8.41113","0.13976"
"16854","101.08800","8.42417","0.13963"
"16880","101.24400","8.43714","0.13987"
"16906","101.40000","8.45011","0.13981"
"16932","101.55600","8.46309","0.14034"
"16958","101.71200","8.47612","0.14091"
"16984","101.86800","8.48910","0.14118"
"17010","102.02400","8.50207","0.14187"
"17036","102.18000","8.51511","0.14186"
"17062","102.33600","8.52814","0.14267"
"17088","102.49200","8.54105","0.14350"
"17114","102.64800","8.55415","0.14378"
"17140","102.80400","8.56718","0.14487"
"17166","102.96000","8.58010","0.14602"
"17192","103.11600","8.59307","0.14699"
"17218","103.27200","8.60610","0.14709"
"17244","103.42800","8.61914","0.14843"
"17270","103.58400","8.63205","0.14955"
"17296","103.74000","8.64515","0.14995"
"17322","103.89600","8.65812","0.15186"
"17348","104.05200","8.67110","0.15230"
"17374","104.20800","8.68413","0.15358"
"17400","104.36400","8.69717","0.15407"
"17426","104.52000","8.71014","0.15590"
"17452","104.67600","8.72311","0.15585"
"17478","104.83200","8.73615","0.15702"
"17504","104.98800","8.74912","0.15753"
"17530","105.14400","8.76204","0.15894"
"17556","105.30000","8.77513","0.15965"
"17582","105.45600","8.78811","0.16037"
"17608","105.61200","8.80108","0.16138"
"17634","105.76800","8.81411","0.16191"
"17660","105.92400","8.82715","0.16298"
"17686","106.08000","8.84018","0.16410"
"17712","106.23600","8.85310","0.16512"
"17738","106.39200","8.86613","0.16549"
"17764","106.54800","8.87916","0.16655"
"17790","106.70400","8.89208","0.16774"
"17816","106.86000","8.90511","0.16792"
"17842","107.01600","8.91815","0.16862"
"17868","107.17200","8.93112","0.16854"
"17894","107.32800","8.94404","0.16787"
"17920","107.48400","8.95713","0.16846"
"17946","107.64000","8.97016","0.16957"
"17972","107.79600","8.98314","0.17053"
"17998","107.95200","8.99617","0.17152"
"18024","108.10800","9.00915","0.17220"
"18050","108.26400","9.02218","0.17299"
"18076","108.42000","9.03504","0.17379"
"18102","108.57600","9.04819","0.17447"
"18128","108.73200","9.06110","0.17503"
"18154","108.88800","9.07408","0.17580"
"18180","109.04400","9.08705","0.17641"
"18206","109.20000","9.10015","0.17713"
"18232","109.35600","9.11306","0.17798"
"18258","109.51200","9.12604","0.17862"
"18284","109.66800","9.13913","0.17927"
"18310","109.82400","9.15216","0.18019"
"18336","109.98000","9.16508","0.18065"
"18362","110.13600","9.17811","0.18187"
"18388","110.29200","9.19109","0.18258"
"18414","110.44800","9.20406","0.18347"
"18440","110.60400","9.21709","0.18423"
"18466","110.76000","9.23007","0.18548"
"18492","110.91600","9.24310","0.18613"
"18518","111.07200","9.25608","0.18739"
"18544","111.22800","9.26911","0.18807"
"18570","111.38400","9.28215","0.18935"
"18596","111.54000","9.29506","0.19025"
"18622","111.69600","9.30809","0.19167"
"18648","111.85200","9.32113","0.19260"
"18674","112.00800","9.33410","0.19300"
"18700","112.16400","9.34708","0.19428"
"18726","112.32000","9.36011","0.19567"
"18752","112.47600","9.37315","0.19727"
"18778","112.63200","9.38612","0.19815"
"18804","112.78800","9.39909","0.19930"
"18830","112.94400","9.41213","0.20133"
"18856","113.10000","9.42516","0.20192"
"18882","113.25600","9.43814","0.20349"
"18908","113.41200","9.45117","0.20470"
"18934","113.56800","9.46414","0.20614"
"18960","113.72400","9.47712","0.20731"
"18986","113.88000","9.49009","0.20917"
"19012","114.03600","9.50313","0.21005"
"19038","114.19200","9.51610","0.21118"
"19064","114.34800","9.52908","0.21415"
"19090","114.50400","9.54211","0.21507"
"19116","114.66000","9.55508","0.21672"
"19142","114.81600","9.56806","0.21927"
"19168","114.97200","9.58115","0.22035"
"19194","115.12800","9.59413","0.22274"
"19220","115.28400","9.60710","0.22401"
"19246","115.44000","9.62008","0.22573"
"19272","115.59600","9.63317","0.22825"
"19298","115.75200","9.64614","0.22946"
"19324","115.90800","9.65906","0.23093"
"19350","116.06400","9.67209","0.23327"
"19376","116.22000","9.68513","0.23426"
"19402","116.37600","9.69804","0.23509"
"19428","116.53200","9.71108","0.23671"
"19454","116.68800","9.72417","0.23794"
"19480","116.84400","9.73720","0.23877"
"19506","117.00000","9.75012","0.24087"
"19532","117.15600","9.76315","0.24178"
"19558","117.31200","9.77619","0.24335"
"19584","117.46800","9.78910","0.24419"
"19610","117.62400","9.80208","0.24590"
"19636","117.78000","9.81511","0.24826"
"19662","117.93600","9.82808","0.24968"
"19688","118.09200","9.84106","0.25144"
"19714","118.24800","9.85409","0.25376"
"19740","118.40400","9.86719","0.25558"
"19766","118.56000","9.88010","0.25790"
"19792","118.71600","9.89313","0.25950"
"19818","118.87200","9.90611","0.26207"
"19844","119.02800","9.91908","0.26420"
"19870","119.18400","9.93206","0.26606"
"19896","119.34000","9.94515","0.26763"
"19922","119.49600","9.95819","0.26869"
"19948","119.65200","9.97110","0.27098"
"19974","119.80800","9.98408","0.27212"
"20000","119.96400","9.99711","0.27427"
"20026","120.12000","10.01008","0.27513"
"20052","120.27600","10.02306","0.27668"
"20078","120.43200","10.03615","0.27793"
"20104","120.58800","10.04919","0.27886"
"20130","120.74400","10.06210","0.28007"
"20156","120.90000","10.07513","0.28114"
"20182","121.05600","10.08811","0.28222"
"20208","121.21200","10.10114","0.28257"
"20234","121.36800","10.11406","0.28379"
"20260","121.52400","10.12715","0.28436"
"20286","121.68000","10.14012","0.28518"
"20312","121.83600","10.15304","0.28560"
"20338","121.99200","10.16613","0.28641"
"20364","122.14800","10.17911","0.28673"
"20390","122.30400","10.19208","0.28718"
"20416","122.46000","10.20506","0.28747"
"20442","122.61600","10.21815","0.28772"
"20468","122.77200","10.23112","0.28796"
"20494","122.92800","10.24410","0.28803"
"20520","123.08400","10.25713","0.28816"
"20546","123.24000","10.27017","0.28822"
"20572","123.39600","10.28308","0.28832"
"20598","123.55200","10.29612","0.28849"
"20624","123.70800","10.30909","0.28893"
"20650","123.86400","10.32212","0.28903"
"20676","124.02000","10.33510","0.28928"
"20702","124.17600","10.34819","0.28992"
"20728","124.33200","10.36111","0.29035"
"20754","124.48800","10.37408","0.29120"
"20780","124.64400","10.38712","0.29177"
"20806","124.80000","10.40009","0.29270"
"20832","124.95600","10.41306","0.29337"
"20858","125.11200","10.42604","0.29461"
"20884","125.26800","10.43913","0.29546"
"20910","125.42400","10.45211","0.29711"
"20936","125.58000","10.46508","0.29878"
"20962","125.73600","10.47812","0.29995"
"20988","125.89200","10.49115","0.30135"
"21014","126.04800","10.50412","0.30311"
"21040","126.20400","10.51710","0.30445"
"21066","126.36000","10.53013","0.30646"
"21092","126.51600","10.54317","0.30885"
"21118","126.67200","10.55608","0.31157"
"21144","126.82800","10.56912","0.31323"
"21170","126.98400","10.58215","0.31630"
"21196","127.14000","10.59506","0.31929"
"21222","127.29600","10.60810","0.32130"
"21248","127.45200","10.62113","0.32417"
"21274","127.60800","10.63417","0.32698"
"21300","127.76400","10.64708","0.32965"
"21326","127.92000","10.66011","0.33180"
"21352","128.07600","10.67315","0.33439"
"21378","128.23199","10.68606","0.33619"
"21404","128.38800","10.69910","0.33715"
"21430","128.54401","10.71207","0.33911"
"21456","128.70000","10.72511","0.34042"
"21482","128.85600","10.73796","0.34141"
"21508","129.01199","10.75117","0.34305"
"21534","129.16800","10.76415","0.34395"
"21560","129.32401","10.77712","0.34582"
"21586","129.48000","10.79010","0.34748"
"21612","129.63600","10.80313","0.35060"
"21638","129.79201","10.81611","0.35281"
"21664","129.94800","10.82908","0.35519"
"21690","130.10400","10.84217","0.35801"
"21716","130.25999","10.85515","0.36109"
"21742","130.41600","10.86812","0.36425"
"21768","130.57201","10.88110","0.36730"
"21794","130.72800","10.89413","0.36984"
"21820","130.88400","10.90711","0.37282"
"21846","131.03999","10.92008","0.37560"
"21872","131.19600","10.93317","0.37807"
"21898","131.35201","10.94615","0.38021"
"21924","131.50800","10.95912","0.38254"
"21950","131.66400","10.97210","0.38476"
"21976","131.82001","10.98507","0.38651"
"22002","131.97600","10.99811","0.38757"
"22028","132.13200","11.01108","0.38880"
"22054","132.28799","11.02411","0.39080"
"22080","132.44400","11.03709","0.39181"
"22106","132.60001","11.05006","0.39325"
"22132","132.75600","11.06316","0.39455"
"22158","132.91200","11.07613","0.39586"
"22184","133.06799","11.08911","0.39744"
"22210","133.22400","11.10208","0.39808"
"22236","133.38000","11.11517","0.39968"
"22262","133.53600","11.12815","0.40101"
"22288","133.69200","11.14106","0.40219"
"22314","133.84801","11.15410","0.40254"
"22340","134.00400","11.16713","0.40419"
"22366","134.16000","11.18010","0.40508"
"22392","134.31599","11.19314","0.40618"
"22418","134.47200","11.20617","0.40687"
"22444","134.62801","11.21915","0.40811"
"22470","134.78400","11.23212","0.40943"
"22496","134.94000","11.24516","0.41046"
"22522","135.09599","11.25813","0.41224"
"22548","135.25200","11.27104","0.41402"
"22574","135.40800","11.28402","0.41599"
"22600","135.56400","11.29711","0.41787"
"22626","135.72000","11.31009","0.42029"
"22652","135.87601","11.32306","0.42225"
"22678","136.03200","11.33610","0.42482"
"22704","136.18800","11.34913","0.42800"
"22730","136.34399","11.36210","0.43014"
"22756","136.50000","11.37514","0.43174"
"22782","136.65601","11.38817","0.43420"
"22808","136.81200","11.40115","0.43623"
"22834","136.96800","11.41412","0.43757"
"22860","137.12399","11.42710","0.43891"
"22886","137.28000","11.44013","0.44023"
"22912","137.43600","11.45304","0.44148"
"22938","137.59200","11.46614","0.44195"
"22964","137.74800","11.47911","0.44308"
"22990","137.90401","11.49209","0.44383"
"23016","138.06000","11.50506","0.44491"
"23042","138.21600","11.51816","0.44706"
"23068","138.37199","11.53113","0.44909"
"23094","138.52800","11.54410","0.45070"
"23120","138.68401","11.55714","0.45270"
"23146","138.84000","11.57017","0.45531"
"23172","138.99600","11.58309","0.45796"
"23198","139.15199","11.59612","0.45964"
"23224","139.30800","11.60910","0.46200"
"23250","139.46400","11.62207","0.46396"
"23276","139.62000","11.63504","0.46666"
"23302","139.77600","11.64814","0.46924"
"23328","139.93201","11.66111","0.47190"
"23354","140.08800","11.67409","0.47407"
"23380","140.24400","11.68706","0.47630"
"23406","140.39999","11.70009","0.47968"
"23432","140.55600","11.71313","0.48123"
"23458","140.71201","11.72604","0.48357"
"23484","140.86800","11.73914","0.48493"
"23510","141.02400","11.75217","0.48660"
"23536","141.17999","11.76509","0.48787"
"23562","141.33600","11.77812","0.48825"
"23588","141.49200","11.79109","0.48939"
"23614","141.64799","11.80407","0.48975"
"23640","141.80400","11.81710","0.49050"
"23666","141.96001","11.83020","0.48959"
"23692","142.11600","11.84317","0.49093"
"23718","142.27200","11.85609","0.49245"
"23744","142.42799","11.86912","0.49350"
"23770","142.58400","11.88215","0.49557"
"23796","142.74001","11.89513","0.49763"
"23822","142.89600","11.90804","0.50113"
"23848","143.05200","11.92114","0.50384"
"23874","143.20799","11.93411","0.50684"
"23900","143.36400","11.94709","0.51021"
"23926","143.52000","11.96012","0.51306"
"23952","143.67599","11.97315","0.51634"
"23978","143.83200","11.98607","0.51979"
"24004","143.98801","11.99910","0.52293"
"24030","144.14400","12.01214","0.52559"
"24056","144.30000","12.02517","0.52862"
"24082","144.45599","12.03808","0.53179"
"24108","144.61200","12.05112","0.53496"
"24134","144.76801","12.06415","0.53753"
"24160","144.92400","12.07707","0.54065"
"24186","145.08000","12.09010","0.54295"
"24212","145.23599","12.10314","0.54598"
"24238","145.39200","12.11617","0.54786"
"24264","145.54800","12.12908","0.54910"
"24290","145.70399","12.14218","0.55126"
"24316","145.86000","12.15515","0.55257"
"24342","146.01601","12.16807","0.55457"
"24368","146.17200","12.18110","0.55781"
"24394","146.32800","12.19413","0.56053"
"24420","146.48399","12.20711","0.56301"
"24446","146.64000","12.22008","0.56587"
"24472","146.79601","12.23312","0.56924"
"24498","146.95200","12.24609","0.57155"
"24524","147.10800","12.25913","0.57226"
"24550","147.26401","12.27210","0.57334"
"24576","147.42000","12.28513","0.57293"
"24602","147.57600","12.29811","0.56924"
"24628","147.73199","12.31108","0.55576"
"24654","147.88800","12.32412","0.54418"
"24680","148.04401","12.33709","0.53475"
"24706","148.20000","12.35001","0.52559"
"24732","148.35600","12.36310","0.52821"
"24758","148.51199","12.37613","0.53063"
"24784","148.66800","12.38911","0.53559"
"24810","148.82401","12.40208","0.54080"
"24836","148.98000","12.41518","0.54499"
"24862","149.13600","12.42815","0.54928"
"24888","149.29201","12.44112","0.55160"
"24914","149.44800","12.45416","0.55471"
"24940","149.60400","12.46719","0.55822"
"24966","149.75999","12.48005","0.56226"
"24992","149.91600","12.49314","0.56717"
"25018","150.07201","12.50612","0.57182"
"25044","150.22800","12.51909","0.57657"
"25070","150.38400","12.53201","0.58135"
"25096","150.53999","12.54516","0.58441"
"25122","150.69600","12.55819","0.58694"
"25148","150.85201","12.57111","0.58947"
"25174","151.00800","12.58414","0.59108"
"25200","151.16400","12.59712","0.59251"
"25226","151.32001","12.61015","0.59394"
"25252","151.47600","12.62307","0.59564"
"25278","151.63200","12.63616","0.59707"
"25304","151.78799","12.64919","0.59843"
"25330","151.94400","12.66211","0.60095"
"25356","152.10001","12.67508","0.60232"
"25382","152.25600","12.68812","0.60538"
"25408","152.41200","12.70109","0.60781"
"25434","152.56799","12.71407","0.60983"
"25460","152.72400","12.72716","0.61249"
"25486","152.88000","12.74019","0.61561"
"25512","153.03600","12.75305","0.61809"
"25538","153.19200","12.76614","0.62208"
"25564","153.34801","12.77912","0.62537"
"25590","153.50400","12.79209","0.63023"
"25616","153.66000","12.80507","0.63417"
"25642","153.81599","12.81810","0.63869"
"25668","153.97200","12.83107","0.64325"
"25694","154.12801","12.84405","0.64699"
"25720","154.28400","12.85708","0.64976"
"25746","154.44000","12.87012","0.65388"
"25772","154.59599","12.88309","0.65612"
"25798","154.75200","12.89612","0.66127"
"25824","154.90800","12.90916","0.66521"
"25850","155.06400","12.92213","0.67016"
"25876","155.22000","12.93511","0.67432"
"25902","155.37601","12.94814","0.67847"
"25928","155.53200","12.96117","0.68094"
"25954","155.68800","12.97409","0.68385"
"25980","155.84399","12.98712","0.68668"
"26006","156.00000","13.00016","0.68955"
"26032","156.15601","13.01319","0.69197"
"26058","156.31200","13.02611","0.69440"
"26084","156.46800","13.03914","0.69618"
"26110","156.62399","13.05211","0.69821"
"26136","156.78000","13.06509","0.69979"
"26162","156.93600","13.07806","0.70102"
"26188","157.09200","13.09110","0.70246"
"26214","157.24800","13.10407","0.70321"
"26240","157.40401","13.11711","0.70464"
"26266","157.56000","13.13008","0.70535"
"26292","157.71600","13.14311","0.70653"
"26318","157.87199","13.15609","0.70772"
"26344","158.02800","13.16912","0.70949"
"26370","158.18401","13.18216","0.71133"
"26396","158.34000","13.19513","0.71418"
"26422","158.49600","13.20811","0.71657"
"26448","158.65199","13.22114","0.71995"
"26474","158.80800","13.23411","0.72315"
"26500","158.96400","13.24709","0.72654"
"26526","159.12000","13.26012","0.73001"
"26552","159.27600","13.27316","0.73320"
"26578","159.43201","13.28607","0.73597"
"26604","159.58800","13.29910","0.74020"
"26630","159.74400","13.31214","0.74422"
"26656","159.89999","13.32517","0.74649"
"26682","160.05600","13.33809","0.74912"
"26708","160.21201","13.35118","0.75153"
"26734","160.36800","13.36416","0.75369"
"26760","160.52400","13.37707","0.75551"
"26786","160.67999","13.39004","0.75788"
"26812","160.83600","13.40308","0.76144"
"26838","160.99200","13.41605","0.76488"
"26864","161.14799","13.42903","0.76831"
"26890","161.30400","13.44212","0.77227"
"26916","161.46001","13.45516","0.77589"
"26942","161.61600","13.46813","0.77823"
"26968","161.77200","13.48116","0.78262"
"26994","161.92799","13.49414","0.78590"
"27020","162.08400","13.50711","0.78985"
"27046","162.24001","13.52009","0.79379"
"27072","162.39600","13.53312","0.79684"
"27098","162.55200","13.54616","0.79978"
"27124","162.70799","13.55913","0.80268"
"27150","162.86400","13.57210","0.80551"
"27176","163.02000","13.58514","0.80815"
"27202","163.17599","13.59811","0.81042"
"27228","163.33200","13.61109","0.81256"
"27254","163.48801","13.62412","0.81526"
"27280","163.64400","13.63716","0.81735"
"27306","163.80000","13.65007","0.81953"
"27332","163.95599","13.66310","0.82189"
"27358","164.11200","13.67608","0.82438"
"27384","164.26801","13.68911","0.82731"
"27410","164.42400","13.70209","0.83050"
"27436","164.58000","13.71512","0.83492"
"27462","164.73599","13.72816","0.83934"
"27488","164.89200","13.74107","0.84364"
"27514","165.04800","13.75410","0.84728"
"27540","165.20399","13.76714","0.85054"
"27566","165.36000","13.78005","0.85432"
"27592","165.51601","13.79309","0.85633"
"27618","165.67200","13.80612","0.86062"
"27644","165.82800","13.81909","0.86471"
"27670","165.98399","13.83207","0.86990"
"27696","166.14000","13.84510","0.87525"
"27722","166.29601","13.85814","0.87987"
"27748","166.45200","13.87105","0.88399"
"27774","166.60800","13.88415","0.88929"
"27800","166.76401","13.89712","0.89329"
"27826","166.92000","13.91009","0.89745"
"27852","167.07600","13.92307","0.90104"
"27878","167.23199","13.93616","0.90443"
"27904","167.38800","13.94914","0.90655"
"27930","167.54401","13.96211","0.90789"
"27956","167.70000","13.97515","0.90823"
"27982","167.85600","13.98812","0.90870"
"28008","168.01199","14.00109","0.90927"
"28034","168.16800","14.01407","0.90997"
"28060","168.32401","14.02716","0.91154"
"28086","168.48000","14.04014","0.91387"
"28112","168.63600","14.05305","0.91716"
"28138","168.79201","14.06615","0.92138"
"28164","168.94800","14.07918","0.92671"
"28190","169.10400","14.09215","0.93089"
"28216","169.25999","14.10513","0.93575"
"28242","169.41600","14.11810","0.94107"
"28268","169.57201","14.13114","0.94574"
"28294","169.72800","14.14405","0.95191"
"28320","169.88400","14.15709","0.95784"
"28346","170.03999","14.17012","0.96161"
"28372","170.19600","14.18309","0.96508"
"28398","170.35201","14.19607","0.96804"
"28424","170.50800","14.20916","0.97110"
"28450","170.66400","14.22214","0.97453"
"28476","170.82001","14.23505","0.97884"
"28502","170.97600","14.24809","0.98298"
"28528","171.13200","14.26118","0.98731"
"28554","171.28799","14.27409","0.99042"
"28580","171.44400","14.28707","0.99395"
"28606","171.60001","14.30004","0.99700"
"28632","171.75600","14.31314","0.99998"
"28658","171.91200","14.32605","1.00227"
"28684","172.06799","14.33915","1.00546"
"28710","172.22400","14.35212","1.00784"
"28736","172.38000","14.36515","1.01040"
"28762","172.53600","14.37813","1.01312"
"28788","172.69200","14.39116","1.01612"
"28814","172.84801","14.40414","1.01908"
"28840","173.00400","14.41705","1.02378"
"28866","173.16000","14.43015","1.02825"
"28892","173.31599","14.44312","1.03393"
"28918","173.47200","14.45603","1.03841"
"28944","173.62801","14.46907","1.04377"
"28970","173.78400","14.48210","1.04887"
"28996","173.94000","14.49508","1.05286"
"29022","174.09599","14.50811","1.05596"
"29048","174.25200","14.52114","1.05817"
"29074","174.40800","14.53412","1.05994"
"29100","174.56400","14.54709","1.06228"
"29126","174.72000","14.56013","1.06653"
"29152","174.87601","14.57310","1.07191"
"29178","175.03200","14.58608","1.07777"
"29204","175.18800","14.59911","1.08423"
"29230","175.34399","14.61214","1.08913"
"29256","175.50000","14.62512","1.09417"
"29282","175.65601","14.63803","1.09890"
"29308","175.81200","14.65113","1.10377"
"29334","175.96800","14.66410","1.10737"
"29360","176.12399","14.67708","1.11030"
"29386","176.28000","14.69011","1.11231"
"29412","176.43600","14.70314","1.11389"
"29438","176.59200","14.71612","1.11598"
"29464","176.74800","14.72903","1.11764"
"29490","176.90401","14.74213","1.11922"
"29516","177.06000","14.75516","1.12077"
"29542","177.21600","14.76807","1.12277"
"29568","177.37199","14.78111","1.12551"
"29594","177.52800","14.79414","1.12886"
"29620","177.68401","14.80718","1.13256"
"29646","177.84000","14.82009","1.13818"
"29672","177.99600","14.83313","1.14521"
"29698","178.15199","14.84616","1.15192"
"29724","178.30800","14.85907","1.15828"
"29750","178.46400","14.87205","1.16423"
"29776","178.62000","14.88514","1.16827"
"29802","178.77600","14.89806","1.17346"
"29828","178.93201","14.91103","1.17946"
"29854","179.08800","14.92413","1.18517"
"29880","179.24400","14.93716","1.19130"
"29906","179.39999","14.95014","1.19743"
"29932","179.55600","14.96311","1.20103"
"29958","179.71201","14.97614","1.20507"
"29984","179.86800","14.98912","1.20850"
"30010","180.02400","15.00209","1.21102"
"30036","180.17999","15.01513","1.21489"
"30062","180.33600","15.02816","1.21696"
"30088","180.49200","15.04107","1.21875"
"30114","180.64799","15.05411","1.22049"
"30140","180.80400","15.06708","1.22249"
"30166","180.96001","15.08012","1.22487"
"30192","181.11600","15.09309","1.22800"
"30218","181.27200","15.10618","1.23269"
"30244","181.42799","15.11916","1.23736"
"30270","181.58400","15.13213","1.24285"
"30296","181.74001","15.14511","1.24903"
"30322","181.89600","15.15814","1.25570"
"30348","182.05200","15.17111","1.26118"
"30374","182.20799","15.18409","1.26589"
"30400","182.36400","15.19713","1.26865"
"30426","182.52000","15.21010","1.27091"
"30452","182.67599","15.22307","1.27356"
"30478","182.83200","15.23611","1.27789"
"30504","182.98801","15.24914","1.28278"
"30530","183.14400","15.26212","1.28716"
"30556","183.30000","15.27509","1.29231"
"30582","183.45599","15.28813","1.29772"
"30608","183.61200","15.30110","1.30328"
"30634","183.76801","15.31407","1.30837"
"30660","183.92400","15.32717","1.31285"
"30686","184.08000","15.34014","1.31633"
"30712","184.23599","15.35306","1.31965"
"30738","184.39200","15.36609","1.32246"
"30764","184.54800","15.37912","1.32447"
"30790","184.70399","15.39210","1.32707"
"30816","184.86000","15.40513","1.32888"
"30842","185.01601","15.41817","1.33090"
"30868","185.17200","15.43120","1.33325"
"30894","185.32800","15.44406","1.33620"
"30920","185.48399","15.45715","1.34071"
"30946","185.64000","15.47012","1.34582"
"30972","185.79601","15.48310","1.35053"
"30998","185.95200","15.49607","1.35700"
"31024","186.10800","15.50917","1.36240"
"31050","186.26401","15.52208","1.36841"
"31076","186.42000","15.53506","1.37181"
"31102","186.57600","15.54815","1.37417"
"31128","186.73199","15.56118","1.37863"
"31154","186.88800","15.57404","1.38367"
"31180","187.04401","15.58713","1.39081"
"31206","187.20000","15.60017","1.39691"
"31232","187.35600","15.61314","1.40230"
"31258","187.51199","15.62605","1.40593"
"31284","187.66800","15.63915","1.40965"
"31310","187.82401","15.65218","1.41261"
"31336","187.98000","15.66510","1.41524"
"31362","188.13600","15.67807","1.41815"
"31388","188.29201","15.69116","1.42054"
"31414","188.44800","15.70414","1.42329"
"31440","188.60400","15.71711","1.42750"
"31466","188.75999","15.73015","1.43254"
"31492","188.91600","15.74312","1.43908"
"31518","189.07201","15.75610","1.44844"
"31544","189.22800","15.76907","1.45766"
"31570","189.38400","15.78210","1.46626"
"31596","189.53999","15.79508","1.47263"
"31622","189.69600","15.80805","1.47660"
"31648","189.85201","15.82115","1.47956"
"31674","190.00800","15.83412","1.48206"
"31700","190.16400","15.84710","1.48546"
"31726","190.32001","15.86013","1.48856"
"31752","190.47600","15.87316","1.49105"
"31778","190.63200","15.88614","1.49203"
"31804","190.78799","15.89911","1.49277"
"31830","190.94400","15.91215","1.48821"
"31856","191.10001","15.92512","-0.06714"
"31882","191.25600","15.93810","0.00439"
"31908","191.41200","15.95113","0.00434"
"31934","191.56799","15.96410","0.00321"
"31960","191.72400","15.97708","0.00154"
"31986","191.88000","15.99011","0.00210"
"32012","192.03600","16.00315","0.00203"
"32038","192.19200","16.01618","0.00170"
"32064","192.34801","16.02909","0.00130"
"32090","192.50400","16.04213","0.00133"
"32116","192.66000","16.05516","0.00155"
"32142","192.81599","16.06808","0.00142"
"32168","192.97200","16.08111","0.00146"
"32194","193.12801","16.09409","0.00139"
"32220","193.28400","16.10712","0.00117"
"32246","193.44000","16.12004","0.00150"
"32272","193.59599","16.13313","0.00120"
"32298","193.75200","16.14616","0.00142"
"32324","193.90800","16.15908","0.00185"
"32350","194.06400","16.17211","0.00130"
"32376","194.22000","16.18515","0.00193"
"32402","194.37601","16.19812","0.00179"
"32428","194.53200","16.21103","0.00176"
"32454","194.68800","16.22419","0.00161"
"32480","194.84399","16.23716","0.00121"
"32506","195.00000","16.25014","0.00143"
"32532","195.15601","16.26311","0.00136"
"32558","195.31200","16.27615","0.00164"
"32584","195.46800","16.28912","0.00144"
"32610","195.62399","16.30209","0.00163"
"32636","195.78000","16.31513","0.00165"
"32662","195.93600","16.32816","0.00147"
"32688","196.09200","16.34108","0.00172"
"32714","196.24800","16.35411","0.00145"
"32724","196.30800","16.35913","0.00096"