File: Trajectories_together/161114Specimen_RawData_1.csv
"","V1","V2","V3"
"1","End date","11/14/2016",""
"2","Specimen label","20AG60",""
"3","Maximum Load","0.05133","N"
"4","Time","Extension","Load"
"5","(s)","(mm)","(N)"
"6","0.00000","0.00000","-0.00363"
"34","0.16800","0.01070","-0.00215"
"62","0.33600","0.02786","-0.00100"
"90","0.50400","0.04221","-0.00093"
"118","0.67200","0.05614","-0.00046"
"146","0.84000","0.07013","0.00072"
"174","1.00800","0.08418","0.00118"
"202","1.17600","0.09817","0.00138"
"230","1.34400","0.11217","0.00208"
"258","1.51200","0.12610","0.00276"
"286","1.68000","0.14015","0.00339"
"314","1.84800","0.15420","0.00283"
"342","2.01600","0.16807","0.00363"
"370","2.18400","0.18224","0.00376"
"398","2.35200","0.19617","0.00521"
"426","2.52000","0.21010","0.00453"
"454","2.68800","0.22415","0.00480"
"482","2.85600","0.23820","0.00518"
"510","3.02400","0.25213","0.00588"
"538","3.19200","0.26612","0.00595"
"566","3.36000","0.28017","0.00597"
"594","3.52800","0.29416","0.00640"
"622","3.69600","0.30810","0.00604"
"650","3.86400","0.32215","0.00630"
"678","4.03200","0.33620","0.00662"
"706","4.20000","0.35013","0.00637"
"734","4.36800","0.36418","0.00710"
"762","4.53600","0.37811","0.00812"
"790","4.70400","0.39204","0.00797"
"818","4.87200","0.40615","0.00730"
"846","5.04000","0.42020","0.00755"
"874","5.20800","0.43407","0.00764"
"902","5.37600","0.44812","0.00760"
"930","5.54400","0.46211","0.00842"
"958","5.71200","0.47610","0.00838"
"986","5.88000","0.49009","0.00873"
"1014","6.04800","0.50415","0.00905"
"1042","6.21600","0.51820","0.00850"
"1070","6.38400","0.53213","0.00912"
"1098","6.55200","0.54618","0.00874"
"1126","6.72000","0.56017","0.00888"
"1154","6.88800","0.57404","0.00913"
"1182","7.05600","0.58815","0.00864"
"1210","7.22400","0.60214","0.00985"
"1238","7.39200","0.61613","0.00970"
"1266","7.56000","0.63012","0.00971"
"1294","7.72800","0.64417","0.01003"
"1322","7.89600","0.65810","0.00957"
"1350","8.06400","0.67215","0.00976"
"1378","8.23200","0.68620","0.01021"
"1406","8.40000","0.70020","0.01071"
"1434","8.56800","0.71413","0.00960"
"1462","8.73600","0.72818","0.00973"
"1490","8.90400","0.74211","0.01031"
"1518","9.07200","0.75610","0.01006"
"1546","9.24000","0.77015","0.00999"
"1574","9.40800","0.78408","0.01051"
"1602","9.57600","0.79807","0.01057"
"1630","9.74400","0.81212","0.01016"
"1658","9.91200","0.82611","0.01047"
"1686","10.08000","0.84004","0.00995"
"1714","10.24800","0.85415","0.01129"
"1742","10.41600","0.86814","0.01118"
"1770","10.58400","0.88213","0.01119"
"1798","10.75200","0.89619","0.01034"
"1826","10.92000","0.91018","0.01067"
"1854","11.08800","0.92411","0.01136"
"1882","11.25600","0.93816","0.01141"
"1910","11.42400","0.95215","0.01056"
"1938","11.59200","0.96614","0.01162"
"1966","11.76000","0.98007","0.01219"
"1994","11.92800","0.99418","0.01153"
"2022","12.09600","1.00823","0.01217"
"2050","12.26400","1.02210","0.01214"
"2078","12.43200","1.03615","0.01219"
"2106","12.60000","1.05014","0.01215"
"2134","12.76800","1.06407","0.01282"
"2162","12.93600","1.07807","0.01226"
"2190","13.10400","1.09218","0.01223"
"2218","13.27200","1.10611","0.01247"
"2246","13.44000","1.12010","0.01285"
"2274","13.60800","1.13415","0.01177"
"2302","13.77600","1.14814","0.01283"
"2330","13.94400","1.16213","0.01301"
"2358","14.11200","1.17618","0.01208"
"2386","14.28000","1.19017","0.01305"
"2414","14.44800","1.20410","0.01257"
"2442","14.61600","1.21815","0.01344"
"2470","14.78400","1.23214","0.01354"
"2498","14.95200","1.24607","0.01348"
"2526","15.12000","1.26012","0.01278"
"2554","15.28800","1.27417","0.01359"
"2582","15.45600","1.28811","0.01450"
"2610","15.62400","1.30210","0.01335"
"2638","15.79200","1.31615","0.01354"
"2666","15.96000","1.33014","0.01359"
"2694","16.12800","1.34413","0.01358"
"2722","16.29600","1.35812","0.01292"
"2750","16.46400","1.37211","0.01384"
"2778","16.63200","1.38604","0.01373"
"2806","16.80000","1.40015","0.01351"
"2834","16.96800","1.41414","0.01396"
"2862","17.13600","1.42807","0.01351"
"2890","17.30400","1.44218","0.01388"
"2918","17.47200","1.45605","0.01458"
"2946","17.64000","1.47005","0.01400"
"2974","17.80800","1.48416","0.01405"
"3002","17.97600","1.49815","0.01453"
"3030","18.14400","1.51208","0.01359"
"3058","18.31200","1.52613","0.01431"
"3086","18.48000","1.54018","0.01441"
"3114","18.64800","1.55411","0.01406"
"3142","18.81600","1.56816","0.01401"
"3170","18.98400","1.58221","0.01445"
"3198","19.15200","1.59614","0.01443"
"3226","19.32000","1.61013","0.01441"
"3254","19.48800","1.62412","0.01489"
"3282","19.65600","1.63811","0.01406"
"3310","19.82400","1.65210","0.01481"
"3338","19.99200","1.66621","0.01439"
"3366","20.16000","1.68021","0.01456"
"3394","20.32800","1.69408","0.01518"
"3422","20.49600","1.70813","0.01492"
"3450","20.66400","1.72212","0.01582"
"3478","20.83200","1.73611","0.01456"
"3506","21.00000","1.75016","0.01547"
"3534","21.16800","1.76421","0.01494"
"3562","21.33600","1.77814","0.01430"
"3590","21.50400","1.79213","0.01507"
"3618","21.67200","1.80618","0.01429"
"3646","21.84000","1.82011","0.01498"
"3674","22.00800","1.83410","0.01469"
"3702","22.17600","1.84815","0.01567"
"3730","22.34400","1.86215","0.01489"
"3758","22.51200","1.87608","0.01522"
"3786","22.68000","1.89013","0.01489"
"3814","22.84800","1.90412","0.01580"
"3842","23.01600","1.91811","0.01560"
"3870","23.18400","1.93210","0.01523"
"3898","23.35200","1.94615","0.01529"
"3926","23.52000","1.96014","0.01475"
"3954","23.68800","1.97413","0.01521"
"3982","23.85600","1.98818","0.01638"
"4010","24.02400","2.00211","0.01577"
"4038","24.19200","2.01610","0.01530"
"4066","24.36000","2.03015","0.01430"
"4094","24.52800","2.04414","0.01527"
"4122","24.69600","2.05814","0.01586"
"4150","24.86400","2.07219","0.01480"
"4178","25.03200","2.08618","0.01482"
"4206","25.20000","2.10011","0.01577"
"4234","25.36800","2.11416","0.01492"
"4262","25.53600","2.12815","0.01526"
"4290","25.70400","2.14208","0.01597"
"4318","25.87200","2.15613","0.01558"
"4346","26.04000","2.17012","0.01537"
"4374","26.20800","2.18411","0.01546"
"4402","26.37600","2.19810","0.01517"
"4430","26.54400","2.21215","0.01529"
"4458","26.71200","2.22614","0.01525"
"4486","26.88000","2.24013","0.01569"
"4514","27.04800","2.25413","0.01512"
"4542","27.21600","2.26812","0.01573"
"4570","27.38400","2.28211","0.01493"
"4598","27.55200","2.29616","0.01564"
"4626","27.72000","2.31015","0.01617"
"4654","27.88800","2.32408","0.01627"
"4682","28.05600","2.33819","0.01600"
"4710","28.22400","2.35212","0.01618"
"4738","28.39200","2.36605","0.01622"
"4766","28.56000","2.38016","0.01629"
"4794","28.72800","2.39421","0.01628"
"4822","28.89600","2.40808","0.01565"
"4850","29.06400","2.42213","0.01667"
"4878","29.23200","2.43618","0.01568"
"4906","29.40000","2.45012","0.01661"
"4934","29.56800","2.46411","0.01573"
"4962","29.73600","2.47816","0.01662"
"4990","29.90400","2.49215","0.01647"
"5018","30.07200","2.50608","0.01644"
"5046","30.24000","2.52013","0.01645"
"5074","30.40800","2.53412","0.01611"
"5102","30.57600","2.54805","0.01604"
"5130","30.74400","2.56216","0.01539"
"5158","30.91200","2.57615","0.01693"
"5186","31.08000","2.59008","0.01590"
"5214","31.24800","2.60413","0.01616"
"5242","31.41600","2.61818","0.01650"
"5270","31.58400","2.63211","0.01666"
"5298","31.75200","2.64616","0.01665"
"5326","31.92000","2.66022","0.01638"
"5354","32.08800","2.67409","0.01655"
"5382","32.25600","2.68814","0.01640"
"5410","32.42400","2.70213","0.01666"
"5438","32.59200","2.71612","0.01675"
"5466","32.76000","2.73011","0.01662"
"5494","32.92800","2.74416","0.01696"
"5522","33.09600","2.75815","0.01712"
"5550","33.26400","2.77208","0.01706"
"5578","33.43200","2.78613","0.01682"
"5606","33.60000","2.80012","0.01684"
"5634","33.76800","2.81411","0.01685"
"5662","33.93600","2.82810","0.01707"
"5690","34.10400","2.84216","0.01673"
"5718","34.27200","2.85609","0.01715"
"5746","34.44000","2.87014","0.01606"
"5774","34.60800","2.88413","0.01706"
"5802","34.77600","2.89812","0.01734"
"5830","34.94400","2.91211","0.01633"
"5858","35.11200","2.92610","0.01628"
"5886","35.28000","2.94009","0.01676"
"5914","35.44800","2.95408","0.01693"
"5942","35.61600","2.96813","0.01693"
"5970","35.78400","2.98218","0.01714"
"5998","35.95200","2.99605","0.01789"
"6026","36.12000","3.01016","0.01728"
"6054","36.28800","3.02415","0.01634"
"6082","36.45600","3.03809","0.01640"
"6110","36.62400","3.05220","0.01676"
"6138","36.79200","3.06619","0.01659"
"6166","36.96000","3.08012","0.01696"
"6194","37.12800","3.09411","0.01673"
"6222","37.29600","3.10816","0.01729"
"6250","37.46400","3.12209","0.01686"
"6278","37.63200","3.13614","0.01639"
"6306","37.80000","3.15013","0.01826"
"6334","37.96800","3.16418","0.01664"
"6362","38.13600","3.17805","0.01696"
"6390","38.30400","3.19216","0.01680"
"6418","38.47200","3.20609","0.01671"
"6446","38.64000","3.22009","0.01692"
"6474","38.80800","3.23414","0.01718"
"6502","38.97600","3.24813","0.01753"
"6530","39.14400","3.26212","0.01716"
"6558","39.31200","3.27617","0.01761"
"6586","39.48000","3.29016","0.01730"
"6614","39.64800","3.30415","0.01699"
"6642","39.81600","3.31814","0.01768"
"6670","39.98400","3.33219","0.01797"
"6698","40.15200","3.34612","0.01735"
"6726","40.32000","3.36005","0.01621"
"6754","40.48800","3.37416","0.01723"
"6782","40.65600","3.38815","0.01621"
"6810","40.82400","3.40214","0.01760"
"6838","40.99200","3.41614","0.01692"
"6866","41.16000","3.43013","0.01655"
"6894","41.32800","3.44406","0.01702"
"6922","41.49600","3.45817","0.01711"
"6950","41.66400","3.47216","0.01717"
"6978","41.83200","3.48609","0.01791"
"7006","42.00000","3.50014","0.01705"
"7034","42.16800","3.51413","0.01707"
"7062","42.33600","3.52812","0.01708"
"7090","42.50400","3.54217","0.01715"
"7118","42.67200","3.55622","0.01698"
"7146","42.84000","3.57015","0.01683"
"7174","43.00800","3.58414","0.01739"
"7202","43.17600","3.59813","0.01680"
"7230","43.34400","3.61213","0.01742"
"7258","43.51200","3.62612","0.01659"
"7286","43.68000","3.64017","0.01712"
"7314","43.84800","3.65416","0.01702"
"7342","44.01600","3.66809","0.01663"
"7370","44.18400","3.68214","0.01649"
"7398","44.35200","3.69613","0.01710"
"7426","44.52000","3.71012","0.01708"
"7454","44.68800","3.72417","0.01689"
"7482","44.85600","3.73816","0.01734"
"7510","45.02400","3.75209","0.01671"
"7538","45.19200","3.76614","0.01707"
"7566","45.36000","3.78013","0.01653"
"7594","45.52800","3.79412","0.01599"
"7622","45.69600","3.80817","0.01644"
"7650","45.86400","3.82211","0.01703"
"7678","46.03200","3.83610","0.01644"
"7706","46.20000","3.85003","0.01622"
"7734","46.36800","3.86414","0.01684"
"7762","46.53600","3.87819","0.01646"
"7790","46.70400","3.89206","0.01706"
"7818","46.87200","3.90617","0.01761"
"7846","47.04000","3.92016","0.01736"
"7874","47.20800","3.93415","0.01649"
"7902","47.37600","3.94814","0.01663"
"7930","47.54400","3.96219","0.01730"
"7958","47.71200","3.97612","0.01634"
"7986","47.88000","3.99011","0.01681"
"8014","48.04800","4.00411","0.01646"
"8042","48.21600","4.01810","0.01699"
"8070","48.38400","4.03215","0.01573"
"8098","48.55200","4.04620","0.01571"
"8126","48.72000","4.06013","0.01536"
"8154","48.88800","4.07412","0.01520"
"8182","49.05600","4.08817","0.01571"
"8210","49.22400","4.10216","0.01634"
"8238","49.39200","4.11609","0.01566"
"8266","49.56000","4.13020","0.01518"
"8294","49.72800","4.14419","0.01553"
"8322","49.89600","4.15812","0.01617"
"8350","50.06400","4.17211","0.01529"
"8378","50.23200","4.18616","0.01623"
"8406","50.40000","4.20015","0.01583"
"8434","50.56800","4.21415","0.01572"
"8462","50.73600","4.22814","0.01547"
"8490","50.90400","4.24213","0.01544"
"8518","51.07200","4.25612","0.01552"
"8546","51.24000","4.27011","0.01573"
"8574","51.40800","4.28416","0.01574"
"8602","51.57600","4.29815","0.01601"
"8630","51.74400","4.31220","0.01602"
"8658","51.91200","4.32613","0.01608"
"8686","52.08000","4.34006","0.01520"
"8714","52.24800","4.35411","0.01546"
"8742","52.41600","4.36816","0.01640"
"8770","52.58400","4.38209","0.01561"
"8798","52.75200","4.39614","0.01531"
"8826","52.92000","4.41014","0.01559"
"8854","53.08800","4.42407","0.01523"
"8882","53.25600","4.43812","0.01587"
"8910","53.42400","4.45217","0.01554"
"8938","53.59200","4.46616","0.01584"
"8966","53.76000","4.48009","0.01543"
"8994","53.92800","4.49414","0.01560"
"9022","54.09600","4.50813","0.01654"
"9050","54.26400","4.52206","0.01553"
"9078","54.43200","4.53611","0.01574"
"9106","54.60000","4.55010","0.01499"
"9134","54.76800","4.56409","0.01648"
"9162","54.93600","4.57814","0.01590"
"9190","55.10400","4.59213","0.01548"
"9218","55.27200","4.60613","0.01521"
"9246","55.44000","4.62012","0.01550"
"9274","55.60800","4.63417","0.01550"
"9302","55.77600","4.64810","0.01530"
"9330","55.94400","4.66209","0.01567"
"9358","56.11200","4.67614","0.01544"
"9386","56.28000","4.69007","0.01584"
"9414","56.44800","4.70412","0.01554"
"9442","56.61600","4.71817","0.01627"
"9470","56.78400","4.73210","0.01608"
"9498","56.95200","4.74609","0.01636"
"9526","57.12000","4.76014","0.01642"
"9554","57.28800","4.77419","0.01650"
"9582","57.45600","4.78813","0.01532"
"9610","57.62400","4.80218","0.01623"
"9638","57.79200","4.81617","0.01576"
"9666","57.96000","4.83010","0.01552"
"9694","58.12800","4.84415","0.01530"
"9722","58.29600","4.85820","0.01627"
"9750","58.46400","4.87213","0.01564"
"9778","58.63200","4.88612","0.01623"
"9806","58.80000","4.90011","0.01606"
"9834","58.96800","4.91410","0.01614"
"9862","59.13600","4.92809","0.01732"
"9890","59.30400","4.94220","0.01668"
"9918","59.47200","4.95613","0.01574"
"9946","59.64000","4.97012","0.01536"
"9974","59.80800","4.98418","0.01564"
"10002","59.97600","4.99817","0.01600"
"10030","60.14400","5.01210","0.01586"
"10058","60.31200","5.02615","0.01577"
"10086","60.48000","5.04014","0.01579"
"10114","60.64800","5.05413","0.01672"
"10142","60.81600","5.06812","0.01615"
"10170","60.98400","5.08211","0.01505"
"10198","61.15200","5.09610","0.01595"
"10226","61.32000","5.11015","0.01624"
"10254","61.48800","5.12414","0.01540"
"10282","61.65600","5.13807","0.01623"
"10310","61.82400","5.15212","0.01553"
"10338","61.99200","5.16617","0.01589"
"10366","62.16000","5.18017","0.01668"
"10394","62.32800","5.19410","0.01606"
"10422","62.49600","5.20815","0.01661"
"10450","62.66400","5.22214","0.01593"
"10478","62.83200","5.23607","0.01592"
"10506","63.00000","5.25012","0.01570"
"10534","63.16800","5.26417","0.01596"
"10562","63.33600","5.27810","0.01500"
"10590","63.50400","5.29215","0.01643"
"10618","63.67200","5.30620","0.01530"
"10646","63.84000","5.32007","0.01577"
"10674","64.00800","5.33406","0.01598"
"10702","64.17600","5.34817","0.01527"
"10730","64.34400","5.36216","0.01589"
"10758","64.51200","5.37616","0.01640"
"10786","64.68000","5.39015","0.01616"
"10814","64.84800","5.40408","0.01652"
"10842","65.01600","5.41807","0.01596"
"10870","65.18400","5.43218","0.01574"
"10898","65.35200","5.44617","0.01581"
"10926","65.52000","5.46010","0.01624"
"10954","65.68800","5.47415","0.01634"
"10982","65.85600","5.48820","0.01600"
"11010","66.02400","5.50213","0.01567"
"11038","66.19200","5.51612","0.01554"
"11066","66.36000","5.53017","0.01671"
"11094","66.52800","5.54410","0.01592"
"11122","66.69600","5.55809","0.01556"
"11150","66.86400","5.57209","0.01631"
"11178","67.03200","5.58608","0.01553"
"11206","67.20000","5.60007","0.01584"
"11234","67.36800","5.61412","0.01626"
"11262","67.53600","5.62817","0.01597"
"11290","67.70400","5.64210","0.01628"
"11318","67.87200","5.65615","0.01639"
"11346","68.04000","5.67014","0.01561"
"11374","68.20800","5.68413","0.01556"
"11402","68.37600","5.69818","0.01556"
"11430","68.54400","5.71211","0.01513"
"11458","68.71200","5.72610","0.01540"
"11486","68.88000","5.74015","0.01549"
"11514","69.04800","5.75414","0.01585"
"11542","69.21600","5.76814","0.01578"
"11570","69.38400","5.78207","0.01562"
"11598","69.55200","5.79612","0.01525"
"11626","69.72000","5.81011","0.01558"
"11654","69.88800","5.82410","0.01542"
"11682","70.05600","5.83815","0.01592"
"11710","70.22400","5.85220","0.01557"
"11738","70.39200","5.86613","0.01558"
"11766","70.56000","5.88012","0.01582"
"11794","70.72800","5.89417","0.01640"
"11822","70.89600","5.90810","0.01458"
"11850","71.06400","5.92215","0.01535"
"11878","71.23200","5.93614","0.01593"
"11906","71.40000","5.95014","0.01512"
"11934","71.56800","5.96413","0.01489"
"11962","71.73600","5.97818","0.01540"
"11990","71.90400","5.99211","0.01574"
"12018","72.07200","6.00616","0.01538"
"12046","72.24000","6.02021","0.01457"
"12074","72.40800","6.03414","0.01559"
"12102","72.57600","6.04807","0.01559"
"12130","72.74400","6.06212","0.01567"
"12158","72.91200","6.07617","0.01558"
"12186","73.08000","6.09010","0.01469"
"12214","73.24800","6.10415","0.01587"
"12242","73.41600","6.11814","0.01547"
"12270","73.58400","6.13207","0.01464"
"12298","73.75200","6.14607","0.01521"
"12326","73.92000","6.16017","0.01484"
"12354","74.08800","6.17417","0.01454"
"12382","74.25600","6.18816","0.01532"
"12410","74.42400","6.20215","0.01602"
"12438","74.59200","6.21614","0.01478"
"12466","74.76000","6.23013","0.01516"
"12494","74.92800","6.24418","0.01534"
"12522","75.09600","6.25811","0.01567"
"12550","75.26400","6.27210","0.01526"
"12578","75.43200","6.28615","0.01519"
"12606","75.60000","6.30020","0.01505"
"12634","75.76800","6.31407","0.01590"
"12662","75.93600","6.32818","0.01535"
"12690","76.10400","6.34217","0.01549"
"12718","76.27200","6.35611","0.01578"
"12746","76.44000","6.37016","0.01540"
"12774","76.60800","6.38415","0.01569"
"12802","76.77600","6.39808","0.01520"
"12830","76.94400","6.41213","0.01534"
"12858","77.11200","6.42618","0.01529"
"12886","77.28000","6.44011","0.01576"
"12914","77.44800","6.45410","0.01584"
"12942","77.61600","6.46815","0.01535"
"12970","77.78400","6.48208","0.01518"
"12998","77.95200","6.49613","0.01521"
"13026","78.12000","6.51018","0.01586"
"13054","78.28800","6.52411","0.01594"
"13082","78.45600","6.53811","0.01535"
"13110","78.62400","6.55210","0.01538"
"13138","78.79200","6.56615","0.01632"
"13166","78.96000","6.58008","0.01579"
"13194","79.12800","6.59413","0.01625"
"13222","79.29600","6.60818","0.01482"
"13250","79.46400","6.62211","0.01550"
"13278","79.63200","6.63616","0.01561"
"13306","79.80000","6.65015","0.01607"
"13334","79.96800","6.66414","0.01583"
"13362","80.13600","6.67813","0.01592"
"13390","80.30400","6.69212","0.01528"
"13418","80.47200","6.70611","0.01618"
"13446","80.64000","6.72004","0.01600"
"13474","80.80800","6.73416","0.01597"
"13502","80.97600","6.74821","0.01608"
"13530","81.14400","6.76208","0.01510"
"13558","81.31200","6.77613","0.01587"
"13586","81.48000","6.79012","0.01602"
"13614","81.64800","6.80411","0.01632"
"13642","81.81600","6.81816","0.01573"
"13670","81.98400","6.83215","0.01554"
"13698","82.15200","6.84608","0.01594"
"13726","82.32000","6.86007","0.01609"
"13754","82.48800","6.87418","0.01569"
"13782","82.65600","6.88811","0.01534"
"13810","82.82400","6.90210","0.01560"
"13838","82.99200","6.91615","0.01558"
"13866","83.16000","6.93015","0.01584"
"13894","83.32800","6.94408","0.01597"
"13922","83.49600","6.95813","0.01538"
"13950","83.66400","6.97212","0.01567"
"13978","83.83200","6.98611","0.01635"
"14006","84.00000","7.00016","0.01551"
"14034","84.16800","7.01415","0.01549"
"14062","84.33600","7.02808","0.01551"
"14090","84.50400","7.04207","0.01618"
"14118","84.67200","7.05612","0.01551"
"14146","84.84000","7.07017","0.01612"
"14174","85.00800","7.08416","0.01648"
"14202","85.17600","7.09815","0.01596"
"14230","85.34400","7.11208","0.01550"
"14258","85.51200","7.12614","0.01584"
"14286","85.68000","7.14013","0.01490"
"14314","85.84800","7.15418","0.01586"
"14342","86.01600","7.16811","0.01511"
"14370","86.18400","7.18216","0.01585"
"14398","86.35200","7.19615","0.01531"
"14426","86.52000","7.21008","0.01540"
"14454","86.68800","7.22407","0.01627"
"14482","86.85600","7.23812","0.01488"
"14510","87.02400","7.25211","0.01538"
"14538","87.19200","7.26616","0.01548"
"14566","87.36000","7.28015","0.01492"
"14594","87.52800","7.29408","0.01522"
"14622","87.69600","7.30814","0.01619"
"14650","87.86400","7.32218","0.01519"
"14678","88.03200","7.33612","0.01676"
"14706","88.20000","7.35011","0.01649"
"14734","88.36800","7.36416","0.01599"
"14762","88.53600","7.37815","0.01548"
"14790","88.70400","7.39208","0.01584"
"14818","88.87200","7.40619","0.01617"
"14846","89.04000","7.42018","0.01623"
"14874","89.20800","7.43405","0.01606"
"14902","89.37600","7.44816","0.01535"
"14930","89.54400","7.46215","0.01575"
"14958","89.71200","7.47608","0.01552"
"14986","89.88000","7.49019","0.01548"
"15014","90.04800","7.50418","0.01597"
"15042","90.21600","7.51812","0.01584"
"15070","90.38400","7.53211","0.01640"
"15098","90.55200","7.54616","0.01690"
"15126","90.72000","7.56009","0.01677"
"15154","90.88800","7.57408","0.01643"
"15182","91.05600","7.58813","0.01601"
"15210","91.22400","7.60212","0.01586"
"15238","91.39200","7.61605","0.01610"
"15266","91.56000","7.63016","0.01557"
"15294","91.72800","7.64421","0.01610"
"15322","91.89600","7.65814","0.01640"
"15350","92.06400","7.67213","0.01581"
"15378","92.23200","7.68618","0.01582"
"15406","92.40000","7.70011","0.01608"
"15434","92.56800","7.71411","0.01555"
"15462","92.73600","7.72816","0.01668"
"15490","92.90400","7.74215","0.01661"
"15518","93.07200","7.75614","0.01553"
"15546","93.24000","7.77013","0.01596"
"15574","93.40800","7.78412","0.01565"
"15602","93.57600","7.79811","0.01620"
"15630","93.74400","7.81216","0.01578"
"15658","93.91200","7.82615","0.01581"
"15686","94.08000","7.84008","0.01632"
"15714","94.24800","7.85419","0.01555"
"15742","94.41600","7.86818","0.01627"
"15770","94.58400","7.88211","0.01597"
"15798","94.75200","7.89616","0.01642"
"15826","94.92000","7.91015","0.01564"
"15854","95.08800","7.92409","0.01586"
"15882","95.25600","7.93814","0.01564"
"15910","95.42400","7.95219","0.01508"
"15938","95.59200","7.96612","0.01581"
"15966","95.76000","7.98017","0.01572"
"15994","95.92800","7.99416","0.01646"
"16022","96.09600","8.00809","0.01630"
"16050","96.26400","8.02214","0.01507"
"16078","96.43200","8.03613","0.01515"
"16106","96.60000","8.05018","0.01499"
"16134","96.76800","8.06411","0.01594"
"16162","96.93600","8.07816","0.01602"
"16190","97.10400","8.09215","0.01500"
"16218","97.27200","8.10603","0.01534"
"16246","97.44000","8.12014","0.01478"
"16274","97.60800","8.13419","0.01586"
"16302","97.77600","8.14812","0.01476"
"16330","97.94400","8.16217","0.01519"
"16358","98.11200","8.17616","0.01469"
"16386","98.28000","8.19015","0.01562"
"16414","98.44800","8.20408","0.01520"
"16442","98.61600","8.21813","0.01560"
"16470","98.78400","8.23212","0.01521"
"16498","98.95200","8.24611","0.01479"
"16526","99.12000","8.26010","0.01600"
"16554","99.28800","8.27409","0.01565"
"16582","99.45600","8.28802","0.01608"
"16610","99.62400","8.30214","0.01570"
"16638","99.79200","8.31619","0.01618"
"16666","99.96000","8.33012","0.01505"
"16694","100.12800","8.34417","0.01507"
"16722","100.29600","8.35816","0.01544"
"16750","100.46400","8.37209","0.01545"
"16778","100.63200","8.38614","0.01508"
"16806","100.80000","8.40019","0.01631"
"16834","100.96800","8.41412","0.01519"
"16862","101.13600","8.42811","0.01604"
"16890","101.30400","8.44210","0.01579"
"16918","101.47200","8.45615","0.01566"
"16946","101.64000","8.47014","0.01618"
"16974","101.80800","8.48413","0.01535"
"17002","101.97600","8.49813","0.01626"
"17030","102.14400","8.51212","0.01609"
"17058","102.31200","8.52617","0.01622"
"17086","102.48000","8.54016","0.01641"
"17114","102.64800","8.55415","0.01578"
"17142","102.81600","8.56814","0.01603"
"17170","102.98400","8.58213","0.01585"
"17198","103.15200","8.59612","0.01557"
"17226","103.32000","8.61011","0.01590"
"17254","103.48800","8.62416","0.01539"
"17282","103.65600","8.63809","0.01639"
"17310","103.82400","8.65208","0.01611"
"17338","103.99200","8.66613","0.01565"
"17366","104.16000","8.68007","0.01616"
"17394","104.32800","8.69411","0.01595"
"17422","104.49600","8.70817","0.01651"
"17450","104.66400","8.72216","0.01591"
"17478","104.83200","8.73615","0.01564"
"17506","105.00000","8.75014","0.01585"
"17534","105.16800","8.76413","0.01552"
"17562","105.33600","8.77806","0.01599"
"17590","105.50400","8.79217","0.01634"
"17618","105.67200","8.80610","0.01629"
"17646","105.84000","8.82003","0.01576"
"17674","106.00800","8.83408","0.01704"
"17702","106.17600","8.84813","0.01588"
"17730","106.34400","8.86212","0.01631"
"17758","106.51200","8.87617","0.01609"
"17786","106.68000","8.89017","0.01600"
"17814","106.84800","8.90410","0.01604"
"17842","107.01600","8.91809","0.01660"
"17870","107.18400","8.93214","0.01596"
"17898","107.35200","8.94613","0.01582"
"17926","107.52000","8.96012","0.01593"
"17954","107.68800","8.97417","0.01505"
"17982","107.85600","8.98816","0.01619"
"18010","108.02400","9.00209","0.01610"
"18038","108.19200","9.01608","0.01591"
"18066","108.36000","9.03019","0.01631"
"18094","108.52800","9.04412","0.01599"
"18122","108.69600","9.05817","0.01663"
"18150","108.86400","9.07216","0.01644"
"18178","109.03200","9.08610","0.01638"
"18206","109.20000","9.10009","0.01601"
"18234","109.36800","9.11414","0.01712"
"18262","109.53600","9.12813","0.01657"
"18290","109.70400","9.14212","0.01715"
"18318","109.87200","9.15605","0.01635"
"18346","110.04000","9.17010","0.01716"
"18374","110.20800","9.18397","0.01680"
"18402","110.37600","9.19814","0.01635"
"18430","110.54400","9.21219","0.01638"
"18458","110.71200","9.22612","0.01648"
"18486","110.88000","9.24017","0.01736"
"18514","111.04800","9.25416","0.01623"
"18542","111.21600","9.26816","0.01687"
"18570","111.38400","9.28209","0.01640"
"18598","111.55200","9.29614","0.01632"
"18626","111.72000","9.31013","0.01567"
"18654","111.88800","9.32412","0.01579"
"18682","112.05600","9.33811","0.01670"
"18710","112.22400","9.35210","0.01653"
"18738","112.39200","9.36609","0.01659"
"18766","112.56000","9.38014","0.01622"
"18794","112.72800","9.39413","0.01635"
"18822","112.89600","9.40812","0.01627"
"18850","113.06400","9.42211","0.01719"
"18878","113.23200","9.43616","0.01621"
"18906","113.40000","9.45015","0.01679"
"18934","113.56800","9.46420","0.01611"
"18962","113.73600","9.47814","0.01660"
"18990","113.90400","9.49213","0.01594"
"19018","114.07200","9.50612","0.01605"
"19046","114.24000","9.52017","0.01698"
"19074","114.40800","9.53416","0.01667"
"19102","114.57600","9.54809","0.01740"
"19130","114.74400","9.56214","0.01630"
"19158","114.91200","9.57613","0.01794"
"19186","115.08000","9.59006","0.01643"
"19214","115.24800","9.60417","0.01637"
"19242","115.41600","9.61816","0.01660"
"19270","115.58400","9.63209","0.01710"
"19298","115.75200","9.64620","0.01666"
"19326","115.92000","9.66014","0.01664"
"19354","116.08800","9.67407","0.01608"
"19382","116.25600","9.68812","0.01706"
"19410","116.42400","9.70217","0.01635"
"19438","116.59200","9.71610","0.01660"
"19466","116.76000","9.73003","0.01653"
"19494","116.92800","9.74414","0.01680"
"19522","117.09600","9.75807","0.01759"
"19550","117.26400","9.77212","0.01713"
"19578","117.43200","9.78617","0.01805"
"19606","117.60000","9.80016","0.01727"
"19634","117.76800","9.81409","0.01691"
"19662","117.93600","9.82808","0.01696"
"19690","118.10400","9.84213","0.01714"
"19718","118.27200","9.85612","0.01751"
"19746","118.44000","9.87012","0.01728"
"19774","118.60800","9.88417","0.01776"
"19802","118.77600","9.89810","0.01706"
"19830","118.94400","9.91215","0.01757"
"19858","119.11200","9.92614","0.01694"
"19886","119.28000","9.94013","0.01759"
"19914","119.44800","9.95412","0.01787"
"19942","119.61600","9.96811","0.01731"
"19970","119.78400","9.98210","0.01766"
"19998","119.95200","9.99609","0.01744"
"20026","120.12000","10.01014","0.01742"
"20054","120.28800","10.02413","0.01767"
"20082","120.45600","10.03812","0.01741"
"20110","120.62400","10.05218","0.01690"
"20138","120.79200","10.06611","0.01709"
"20166","120.96000","10.08004","0.01694"
"20194","121.12800","10.09415","0.01771"
"20222","121.29600","10.10820","0.01754"
"20250","121.46400","10.12213","0.01735"
"20278","121.63200","10.13612","0.01795"
"20306","121.80000","10.15017","0.01719"
"20334","121.96800","10.16410","0.01768"
"20362","122.13600","10.17815","0.01803"
"20390","122.30400","10.19214","0.01839"
"20418","122.47200","10.20613","0.01748"
"20446","122.64000","10.22012","0.01729"
"20474","122.80800","10.23417","0.01723"
"20502","122.97600","10.24817","0.01729"
"20530","123.14400","10.26210","0.01809"
"20558","123.31200","10.27615","0.01777"
"20586","123.48000","10.29020","0.01767"
"20614","123.64800","10.30407","0.01747"
"20642","123.81600","10.31818","0.01814"
"20670","123.98400","10.33217","0.01887"
"20698","124.15200","10.34610","0.01828"
"20726","124.32000","10.36015","0.01726"
"20754","124.48800","10.37414","0.01804"
"20782","124.65600","10.38813","0.01797"
"20810","124.82400","10.40206","0.01838"
"20838","124.99200","10.41617","0.01742"
"20866","125.16000","10.43011","0.01824"
"20894","125.32800","10.44415","0.01789"
"20922","125.49600","10.45815","0.01839"
"20950","125.66400","10.47214","0.01898"
"20978","125.83200","10.48607","0.01736"
"21006","126.00000","10.50018","0.01860"
"21034","126.16800","10.51417","0.01818"
"21062","126.33600","10.52810","0.01811"
"21090","126.50400","10.54215","0.01850"
"21118","126.67200","10.55620","0.01821"
"21146","126.84000","10.57013","0.01880"
"21174","127.00800","10.58412","0.01869"
"21202","127.17600","10.59817","0.01832"
"21230","127.34400","10.61210","0.01839"
"21258","127.51200","10.62609","0.01848"
"21286","127.68000","10.64015","0.01749"
"21314","127.84800","10.65414","0.01845"
"21342","128.01600","10.66813","0.01771"
"21370","128.18400","10.68218","0.01903"
"21398","128.35200","10.69617","0.01827"
"21426","128.52000","10.71010","0.01942"
"21454","128.68800","10.72415","0.01813"
"21482","128.85600","10.73814","0.01852"
"21510","129.02400","10.75207","0.01835"
"21538","129.19200","10.76618","0.01769"
"21566","129.36000","10.78017","0.01903"
"21594","129.52800","10.79404","0.01935"
"21622","129.69600","10.80809","0.01890"
"21650","129.86400","10.82215","0.01831"
"21678","130.03200","10.83613","0.01860"
"21706","130.20000","10.85013","0.01909"
"21734","130.36800","10.86418","0.01898"
"21762","130.53600","10.87817","0.01951"
"21790","130.70400","10.89210","0.01900"
"21818","130.87200","10.90615","0.01962"
"21846","131.04000","10.92014","0.01923"
"21874","131.20800","10.93413","0.01958"
"21902","131.37600","10.94818","0.01997"
"21930","131.54400","10.96211","0.01910"
"21958","131.71200","10.97604","0.01989"
"21986","131.88000","10.99015","0.01896"
"22014","132.04800","11.00420","0.01923"
"22042","132.21600","11.01807","0.02017"
"22070","132.38400","11.03213","0.01964"
"22098","132.55200","11.04618","0.01960"
"22126","132.72000","11.06011","0.01920"
"22154","132.88800","11.07410","0.02033"
"22182","133.05600","11.08821","0.02008"
"22210","133.22400","11.10220","0.01955"
"22238","133.39200","11.11607","0.01993"
"22266","133.56000","11.13012","0.01966"
"22294","133.72800","11.14411","0.02001"
"22322","133.89600","11.15804","0.01955"
"22350","134.06400","11.17215","0.02039"
"22378","134.23200","11.18620","0.02025"
"22406","134.40000","11.20008","0.02010"
"22434","134.56800","11.21412","0.01916"
"22462","134.73600","11.22818","0.01922"
"22490","134.90400","11.24211","0.01972"
"22518","135.07200","11.25616","0.02022"
"22546","135.24000","11.27021","0.01966"
"22574","135.40800","11.28414","0.02082"
"22602","135.57600","11.29813","0.02026"
"22630","135.74400","11.31212","0.02011"
"22658","135.91200","11.32611","0.02011"
"22686","136.08000","11.34010","0.01998"
"22714","136.24800","11.35415","0.01950"
"22742","136.41600","11.36814","0.02041"
"22770","136.58400","11.38207","0.02106"
"22798","136.75200","11.39612","0.02089"
"22826","136.92000","11.41017","0.02048"
"22854","137.08800","11.42411","0.02053"
"22882","137.25600","11.43816","0.02067"
"22910","137.42400","11.45215","0.02095"
"22938","137.59200","11.46608","0.02089"
"22966","137.76000","11.48013","0.02098"
"22994","137.92800","11.49418","0.02094"
"23022","138.09600","11.50817","0.02060"
"23050","138.26400","11.52210","0.02084"
"23078","138.43200","11.53621","0.02080"
"23106","138.60000","11.55008","0.02079"
"23134","138.76800","11.56413","0.02026"
"23162","138.93600","11.57818","0.02049"
"23190","139.10400","11.59217","0.02092"
"23218","139.27200","11.60611","0.02143"
"23246","139.44000","11.62015","0.02119"
"23274","139.60800","11.63415","0.02144"
"23302","139.77600","11.64808","0.02129"
"23330","139.94400","11.66219","0.02120"
"23358","140.11200","11.67618","0.02379"
"23386","140.28000","11.69005","0.02792"
"23414","140.44800","11.70410","0.02108"
"23442","140.61600","11.71815","0.01730"
"23470","140.78400","11.73208","0.01808"
"23498","140.95200","11.74619","0.01872"
"23526","141.12000","11.76018","0.01903"
"23554","141.28800","11.77417","0.01790"
"23582","141.45600","11.78804","0.01837"
"23610","141.62400","11.80216","0.01925"
"23638","141.79200","11.81615","0.01842"
"23666","141.96000","11.83014","0.01675"
"23694","142.12800","11.84413","0.01721"
"23722","142.29600","11.85812","0.01962"
"23750","142.46400","11.87205","0.01838"
"23778","142.63200","11.88610","0.01747"
"23806","142.80000","11.90021","0.01733"
"23834","142.96800","11.91414","0.01959"
"23862","143.13600","11.92819","0.01944"
"23890","143.30400","11.94218","0.01847"
"23918","143.47200","11.95617","0.01886"
"23946","143.64000","11.97010","0.02004"
"23974","143.80800","11.98409","0.01905"
"24002","143.97600","11.99815","0.01825"
"24030","144.14400","12.01214","0.01860"
"24058","144.31200","12.02613","0.01938"
"24086","144.48000","12.04012","0.01983"
"24114","144.64800","12.05405","0.01877"
"24142","144.81600","12.06816","0.01930"
"24170","144.98400","12.08221","0.01896"
"24198","145.15200","12.09614","0.01985"
"24226","145.32000","12.11013","0.02049"
"24254","145.48800","12.12412","0.01934"
"24282","145.65600","12.13811","0.01876"
"24310","145.82400","12.15210","0.01907"
"24338","145.99200","12.16615","0.01958"
"24366","146.16000","12.18014","0.01906"
"24394","146.32800","12.19408","0.01930"
"24422","146.49600","12.20813","0.02089"
"24450","146.66400","12.22206","0.02020"
"24478","146.83200","12.23611","0.02007"
"24506","147.00000","12.25016","0.02105"
"24534","147.16800","12.26415","0.02033"
"24562","147.33600","12.27814","0.02036"
"24590","147.50400","12.29219","0.02014"
"24618","147.67200","12.30612","0.01973"
"24646","147.84000","12.32005","0.02102"
"24674","148.00800","12.33416","0.02075"
"24702","148.17600","12.34821","0.02012"
"24730","148.34400","12.36208","0.02074"
"24758","148.51200","12.37613","0.02102"
"24786","148.68000","12.39012","0.02111"
"24814","148.84800","12.40412","0.02118"
"24842","149.01600","12.41811","0.02149"
"24870","149.18400","12.43210","0.02057"
"24898","149.35200","12.44615","0.01935"
"24926","149.52000","12.46008","0.02042"
"24954","149.68800","12.47419","0.02030"
"24982","149.85600","12.48818","0.01994"
"25010","150.02400","12.50205","0.02020"
"25038","150.19200","12.51616","0.02035"
"25066","150.36000","12.53015","0.01982"
"25094","150.52800","12.54414","0.01964"
"25122","150.69600","12.55813","0.02091"
"25150","150.86400","12.57218","0.02001"
"25178","151.03200","12.58612","0.02093"
"25206","151.20000","12.60017","0.02056"
"25234","151.36800","12.61422","0.01981"
"25262","151.53600","12.62815","0.02076"
"25290","151.70400","12.64214","0.02060"
"25318","151.87200","12.65619","0.02075"
"25346","152.04000","12.67012","0.01957"
"25374","152.20800","12.68405","0.02039"
"25402","152.37600","12.69816","0.01995"
"25430","152.54400","12.71215","0.01964"
"25458","152.71200","12.72608","0.02032"
"25486","152.88000","12.74013","0.02028"
"25514","153.04800","12.75412","0.02030"
"25542","153.21600","12.76805","0.02081"
"25570","153.38400","12.78216","0.02022"
"25598","153.55200","12.79616","0.02040"
"25626","153.72000","12.81015","0.02050"
"25654","153.88800","12.82414","0.02142"
"25682","154.05600","12.83819","0.02098"
"25710","154.22400","12.85206","0.02123"
"25738","154.39200","12.86605","0.02163"
"25766","154.56000","12.88010","0.02147"
"25794","154.72800","12.89415","0.02117"
"25822","154.89600","12.90808","0.02135"
"25850","155.06400","12.92213","0.02120"
"25878","155.23200","12.93606","0.02129"
"25906","155.40000","12.95005","0.02067"
"25934","155.56800","12.96410","0.02070"
"25962","155.73600","12.97822","0.02200"
"25990","155.90400","12.99215","0.02141"
"26018","156.07200","13.00614","0.02086"
"26046","156.24000","13.02013","0.02081"
"26074","156.40800","13.03412","0.02162"
"26102","156.57600","13.04811","0.02082"
"26130","156.74400","13.06216","0.02077"
"26158","156.91200","13.07615","0.02190"
"26186","157.08000","13.09014","0.02124"
"26214","157.24800","13.10413","0.02146"
"26242","157.41600","13.11806","0.02126"
"26270","157.58400","13.13211","0.02148"
"26298","157.75200","13.14616","0.02169"
"26326","157.92000","13.16016","0.02201"
"26354","158.08800","13.17408","0.02207"
"26382","158.25600","13.18814","0.02210"
"26410","158.42400","13.20213","0.02280"
"26438","158.59200","13.21606","0.02225"
"26466","158.76000","13.23017","0.02263"
"26494","158.92800","13.24416","0.02264"
"26522","159.09600","13.25815","0.02183"
"26550","159.26400","13.27214","0.02242"
"26578","159.43200","13.28613","0.02281"
"26606","159.60000","13.30012","0.02223"
"26634","159.76800","13.31411","0.02330"
"26662","159.93600","13.32816","0.02296"
"26690","160.10400","13.34215","0.02384"
"26718","160.27200","13.35609","0.02353"
"26746","160.44000","13.37014","0.02348"
"26774","160.60800","13.38419","0.02291"
"26802","160.77600","13.39812","0.02300"
"26830","160.94400","13.41211","0.02321"
"26858","161.11200","13.42616","0.02381"
"26886","161.28000","13.44009","0.02379"
"26914","161.44800","13.45414","0.02333"
"26942","161.61600","13.46819","0.02383"
"26970","161.78400","13.48212","0.02362"
"26998","161.95200","13.49611","0.02372"
"27026","162.12000","13.51010","0.02423"
"27054","162.28800","13.52415","0.02439"
"27082","162.45600","13.53808","0.02381"
"27110","162.62400","13.55214","0.02371"
"27138","162.79200","13.56612","0.02372"
"27166","162.96000","13.58012","0.02349"
"27194","163.12800","13.59411","0.02434"
"27222","163.29600","13.60810","0.02381"
"27250","163.46400","13.62209","0.02334"
"27278","163.63200","13.63620","0.02427"
"27306","163.80000","13.65013","0.02404"
"27334","163.96800","13.66406","0.02464"
"27362","164.13600","13.67817","0.02473"
"27390","164.30400","13.69216","0.02484"
"27418","164.47200","13.70615","0.02472"
"27446","164.64000","13.72014","0.02490"
"27474","164.80800","13.73413","0.02470"
"27502","164.97600","13.74812","0.02476"
"27530","165.14400","13.76212","0.02506"
"27558","165.31200","13.77611","0.02522"
"27586","165.48000","13.79016","0.02464"
"27614","165.64800","13.80409","0.02538"
"27642","165.81600","13.81814","0.02485"
"27670","165.98400","13.83213","0.02507"
"27698","166.15200","13.84606","0.02557"
"27726","166.32000","13.86017","0.02498"
"27754","166.48800","13.87416","0.02471"
"27782","166.65600","13.88809","0.02525"
"27810","166.82400","13.90214","0.02549"
"27838","166.99200","13.91613","0.02506"
"27866","167.16000","13.93013","0.02525"
"27894","167.32800","13.94412","0.02528"
"27922","167.49600","13.95823","0.02607"
"27950","167.66400","13.97216","0.02511"
"27978","167.83200","13.98609","0.02390"
"28006","168.00000","14.00014","0.02488"
"28034","168.16800","14.01413","0.02436"
"28062","168.33600","14.02806","0.02572"
"28090","168.50400","14.04217","0.02526"
"28118","168.67200","14.05616","0.02520"
"28146","168.84000","14.07009","0.02415"
"28174","169.00800","14.08414","0.02524"
"28202","169.17600","14.09813","0.02484"
"28230","169.34400","14.11206","0.02605"
"28258","169.51200","14.12611","0.02547"
"28286","169.68000","14.14022","0.02501"
"28314","169.84800","14.15410","0.02575"
"28342","170.01600","14.16809","0.02540"
"28370","170.18400","14.18214","0.02543"
"28398","170.35200","14.19613","0.02565"
"28426","170.52000","14.21012","0.02526"
"28454","170.68800","14.22417","0.02544"
"28482","170.85600","14.23816","0.02585"
"28510","171.02400","14.25209","0.02561"
"28538","171.19200","14.26614","0.02552"
"28566","171.36000","14.28013","0.02644"
"28594","171.52800","14.29406","0.02645"
"28622","171.69600","14.30811","0.02700"
"28650","171.86400","14.32222","0.02713"
"28678","172.03200","14.33616","0.02740"
"28706","172.20000","14.35015","0.02647"
"28734","172.36800","14.36414","0.02671"
"28762","172.53600","14.37813","0.02711"
"28790","172.70400","14.39212","0.02633"
"28818","172.87200","14.40611","0.02673"
"28846","173.04000","14.42010","0.02689"
"28874","173.20800","14.43409","0.02709"
"28902","173.37600","14.44820","0.02785"
"28930","173.54400","14.46219","0.02776"
"28958","173.71200","14.47606","0.02723"
"28986","173.88000","14.49011","0.02684"
"29014","174.04800","14.50416","0.02814"
"29042","174.21600","14.51809","0.02746"
"29070","174.38400","14.53220","0.02794"
"29098","174.55200","14.54614","0.02738"
"29126","174.72000","14.56013","0.02618"
"29154","174.88800","14.57412","0.02580"
"29182","175.05600","14.58817","0.02571"
"29210","175.22400","14.60210","0.02644"
"29238","175.39200","14.61615","0.02701"
"29266","175.56000","14.63014","0.02691"
"29294","175.72800","14.64413","0.02683"
"29322","175.89600","14.65812","0.02741"
"29350","176.06400","14.67217","0.02633"
"29378","176.23200","14.68616","0.02581"
"29406","176.40000","14.70015","0.02656"
"29434","176.56800","14.71420","0.02696"
"29462","176.73600","14.72814","0.02699"
"29490","176.90400","14.74207","0.02803"
"29518","177.07200","14.75612","0.02729"
"29546","177.24000","14.77023","0.02764"
"29574","177.40800","14.78410","0.02721"
"29602","177.57600","14.79815","0.02852"
"29630","177.74400","14.81214","0.02650"
"29658","177.91200","14.82613","0.02745"
"29686","178.08000","14.84012","0.02741"
"29714","178.24800","14.85417","0.02692"
"29742","178.41600","14.86816","0.02840"
"29770","178.58400","14.88209","0.02764"
"29798","178.75200","14.89614","0.02780"
"29826","178.92000","14.91008","0.02857"
"29854","179.08800","14.92407","0.02815"
"29882","179.25600","14.93818","0.02811"
"29910","179.42400","14.95217","0.02832"
"29938","179.59200","14.96610","0.02888"
"29966","179.76000","14.98021","0.02825"
"29994","179.92800","14.99414","0.02807"
"30022","180.09600","15.00813","0.02833"
"30050","180.26400","15.02212","0.02858"
"30078","180.43200","15.03617","0.02894"
"30106","180.60000","15.05016","0.02890"
"30134","180.76800","15.06409","0.02839"
"30162","180.93600","15.07808","0.02903"
"30190","181.10400","15.09207","0.02912"
"30218","181.27200","15.10613","0.02903"
"30246","181.44000","15.12024","0.02966"
"30274","181.60800","15.13411","0.02972"
"30302","181.77600","15.14810","0.02998"
"30330","181.94400","15.16215","0.02973"
"30358","182.11200","15.17614","0.02986"
"30386","182.28000","15.19007","0.03005"
"30414","182.44800","15.20412","0.03032"
"30442","182.61600","15.21811","0.02981"
"30470","182.78400","15.23210","0.03052"
"30498","182.95200","15.24615","0.02999"
"30526","183.12000","15.26014","0.03041"
"30554","183.28800","15.27407","0.03066"
"30582","183.45600","15.28813","0.03069"
"30610","183.62400","15.30217","0.03085"
"30638","183.79200","15.31617","0.03071"
"30666","183.96000","15.33010","0.03090"
"30694","184.12800","15.34421","0.03125"
"30722","184.29600","15.35820","0.03053"
"30750","184.46400","15.37207","0.03142"
"30778","184.63200","15.38618","0.03185"
"30806","184.80000","15.40017","0.03102"
"30834","184.96800","15.41410","0.03175"
"30862","185.13600","15.42815","0.03198"
"30890","185.30400","15.44214","0.03158"
"30918","185.47200","15.45607","0.03176"
"30946","185.64000","15.47012","0.03220"
"30974","185.80800","15.48417","0.03153"
"31002","185.97600","15.49811","0.03223"
"31030","186.14400","15.51216","0.03218"
"31058","186.31200","15.52621","0.03232"
"31086","186.48000","15.54014","0.03228"
"31114","186.64800","15.55407","0.03196"
"31142","186.81600","15.56812","0.03230"
"31170","186.98400","15.58217","0.03242"
"31198","187.15200","15.59610","0.03265"
"31226","187.32000","15.61015","0.03306"
"31254","187.48800","15.62420","0.03258"
"31282","187.65600","15.63807","0.03211"
"31310","187.82400","15.65212","0.03187"
"31338","187.99200","15.66617","0.03195"
"31366","188.16000","15.68016","0.03105"
"31394","188.32800","15.69415","0.03174"
"31422","188.49600","15.70815","0.03166"
"31450","188.66400","15.72214","0.03154"
"31478","188.83200","15.73607","0.03242"
"31506","189.00000","15.75012","0.03230"
"31534","189.16800","15.76417","0.03279"
"31562","189.33600","15.77810","0.03321"
"31590","189.50400","15.79221","0.03236"
"31618","189.67200","15.80608","0.03253"
"31646","189.84000","15.82007","0.03311"
"31674","190.00800","15.83412","0.03329"
"31702","190.17600","15.84817","0.03315"
"31730","190.34400","15.86216","0.03283"
"31758","190.51200","15.87609","0.03290"
"31786","190.68000","15.89014","0.03378"
"31814","190.84800","15.90407","0.03330"
"31842","191.01600","15.91813","0.03363"
"31870","191.18400","15.93212","0.03349"
"31898","191.35200","15.94611","0.03377"
"31926","191.52000","15.96010","0.03355"
"31954","191.68800","15.97415","0.03445"
"31982","191.85600","15.98814","0.03452"
"32010","192.02400","16.00213","0.03444"
"32038","192.19200","16.01618","0.03440"
"32066","192.36000","16.03017","0.03477"
"32094","192.52800","16.04410","0.03461"
"32122","192.69600","16.05815","0.03375"
"32150","192.86400","16.07214","0.03528"
"32178","193.03200","16.08607","0.03450"
"32206","193.20000","16.10019","0.03523"
"32234","193.36800","16.11418","0.03450"
"32262","193.53600","16.12811","0.03548"
"32290","193.70400","16.14210","0.03485"
"32318","193.87200","16.15615","0.03503"
"32346","194.04000","16.17014","0.03499"
"32374","194.20800","16.18413","0.03437"
"32402","194.37600","16.19818","0.03526"
"32430","194.54400","16.21211","0.03544"
"32458","194.71200","16.22610","0.03524"
"32486","194.88000","16.24015","0.03577"
"32514","195.04800","16.25414","0.03561"
"32542","195.21600","16.26807","0.03596"
"32570","195.38400","16.28212","0.03649"
"32598","195.55200","16.29618","0.03640"
"32626","195.72000","16.31010","0.03666"
"32654","195.88800","16.32416","0.03694"
"32682","196.05600","16.33815","0.03755"
"32710","196.22400","16.35208","0.03705"
"32738","196.39200","16.36613","0.03811"
"32766","196.56000","16.38018","0.03763"
"32794","196.72800","16.39417","0.03755"
"32822","196.89600","16.40810","0.03858"
"32850","197.06400","16.42221","0.03818"
"32878","197.23200","16.43614","0.03789"
"32906","197.40000","16.45007","0.03858"
"32934","197.56800","16.46412","0.03884"
"32962","197.73600","16.47811","0.03916"
"32990","197.90400","16.49211","0.03925"
"33018","198.07200","16.50616","0.03919"
"33046","198.24000","16.52015","0.03978"
"33074","198.40800","16.53408","0.03990"
"33102","198.57600","16.54813","0.03999"
"33130","198.74400","16.56218","0.03988"
"33158","198.91200","16.57611","0.04020"
"33186","199.08000","16.59016","0.04049"
"33214","199.24800","16.60415","0.04118"
"33242","199.41600","16.61808","0.04123"
"33270","199.58400","16.63207","0.04122"
"33298","199.75200","16.64612","0.04170"
"33326","199.92000","16.66017","0.04171"
"33354","200.08800","16.67410","0.04215"
"33382","200.25600","16.68815","0.04173"
"33410","200.42400","16.70214","0.04260"
"33438","200.59200","16.71608","0.04239"
"33466","200.76000","16.73013","0.04287"
"33494","200.92800","16.74418","0.04308"
"33522","201.09600","16.75811","0.04303"
"33550","201.26400","16.77210","0.04355"
"33578","201.43200","16.78615","0.04349"
"33606","201.60000","16.80008","0.04416"
"33634","201.76800","16.81413","0.04457"
"33662","201.93600","16.82824","0.04452"
"33690","202.10400","16.84217","0.04461"
"33718","202.27200","16.85610","0.04496"
"33746","202.44000","16.87015","0.04496"
"33774","202.60800","16.88408","0.04508"
"33802","202.77600","16.89808","0.04550"
"33830","202.94400","16.91219","0.04553"
"33858","203.11200","16.92618","0.04564"
"33886","203.28000","16.94005","0.04581"
"33914","203.44800","16.95416","0.04564"
"33942","203.61600","16.96815","0.04619"
"33970","203.78400","16.98214","0.04665"
"33998","203.95200","16.99613","0.04653"
"34026","204.12000","17.01012","0.04645"
"34054","204.28800","17.02411","0.04673"
"34082","204.45600","17.03810","0.04667"
"34110","204.62400","17.05215","0.04706"
"34138","204.79200","17.06614","0.04751"
"34166","204.96000","17.08014","0.04720"
"34194","205.12800","17.09413","0.04734"
"34222","205.29600","17.10818","0.04769"
"34250","205.46400","17.12205","0.04797"
"34278","205.63200","17.13610","0.04810"
"34306","205.80000","17.15015","0.04863"
"34334","205.96800","17.16414","0.04855"
"34362","206.13600","17.17813","0.04876"
"34390","206.30400","17.19212","0.04905"
"34418","206.47200","17.20611","0.04932"
"34446","206.64000","17.22010","0.04925"
"34474","206.80800","17.23415","0.04953"
"34502","206.97600","17.24814","0.04966"
"34530","207.14400","17.26213","0.04963"
"34558","207.31200","17.27612","0.04980"
"34586","207.48000","17.29012","0.05030"
"34614","207.64800","17.30411","0.05042"
"34642","207.81600","17.31810","0.05038"
"34670","207.98400","17.33215","0.05051"
"34698","208.15200","17.34608","0.05072"
"34726","208.32000","17.36019","0.05077"
"34754","208.48800","17.37418","0.05116"
"34782","208.65600","17.38811","0.05099"
"34809","208.81800","17.40168","0.05115"