File: Trajectories_together/161223Specimen_RawData_9.csv
"","V1","V2","V3"
"1","End date","12/23/2016",""
"2","Specimen label","17BC_40",""
"3","Maximum Load","2.05197","N"
"4","Time","Extension","Load"
"5","(s)","(mm)","(N)"
"6","0.00000","0.00000","-0.00065"
"69","0.37800","0.03169","-0.00009"
"132","0.75600","0.06326","0.00026"
"195","1.13400","0.09471","0.00063"
"258","1.51200","0.12628","0.00140"
"321","1.89000","0.15772","0.00188"
"384","2.26800","0.18917","0.00211"
"447","2.64600","0.22074","0.00195"
"510","3.02400","0.25219","0.00275"
"573","3.40200","0.28370","0.00344"
"636","3.78000","0.31521","0.00329"
"699","4.15800","0.34672","0.00363"
"762","4.53600","0.37829","0.00403"
"825","4.91400","0.40968","0.00398"
"888","5.29200","0.44119","0.00487"
"951","5.67000","0.47270","0.00489"
"1014","6.04800","0.50421","0.00571"
"1077","6.42600","0.53571","0.00587"
"1140","6.80400","0.56728","0.00597"
"1203","7.18200","0.59867","0.00583"
"1266","7.56000","0.63018","0.00656"
"1329","7.93800","0.66175","0.00665"
"1392","8.31600","0.69320","0.00762"
"1455","8.69400","0.72471","0.00722"
"1518","9.07200","0.75622","0.00779"
"1581","9.45000","0.78767","0.00761"
"1644","9.82800","0.81918","0.00780"
"1707","10.20600","0.85069","0.00825"
"1770","10.58400","0.88219","0.00856"
"1833","10.96200","0.91370","0.00771"
"1896","11.34000","0.94515","0.00862"
"1959","11.71800","0.97672","0.00803"
"2022","12.09600","1.00829","0.00785"
"2085","12.47400","1.03962","0.00833"
"2148","12.85200","1.07125","0.00856"
"2211","13.23000","1.10276","0.00763"
"2274","13.60800","1.13421","0.00809"
"2337","13.98600","1.16566","0.00825"
"2400","14.36400","1.19723","0.00823"
"2463","14.74200","1.22873","0.00861"
"2526","15.12000","1.26018","0.00860"
"2589","15.49800","1.29169","0.00948"
"2652","15.87600","1.32326","0.00937"
"2715","16.25400","1.35465","0.00972"
"2778","16.63200","1.38622","0.01018"
"2841","17.01000","1.41773","0.01013"
"2904","17.38800","1.44918","0.01004"
"2967","17.76600","1.48069","0.01029"
"3030","18.14400","1.51226","0.01085"
"3093","18.52200","1.54371","0.01091"
"3156","18.90000","1.57516","0.01171"
"3219","19.27800","1.60672","0.01153"
"3282","19.65600","1.63823","0.01136"
"3345","20.03400","1.66968","0.01157"
"3408","20.41200","1.70119","0.01145"
"3471","20.79000","1.73270","0.01169"
"3534","21.16800","1.76421","0.01147"
"3597","21.54600","1.79572","0.01223"
"3660","21.92400","1.82723","0.01116"
"3723","22.30200","1.85874","0.01175"
"3786","22.68000","1.89013","0.01181"
"3849","23.05800","1.92176","0.01166"
"3912","23.43600","1.95326","0.01222"
"3975","23.81400","1.98465","0.01227"
"4038","24.19200","2.01628","0.01322"
"4101","24.57000","2.04767","0.01281"
"4164","24.94800","2.07918","0.01248"
"4227","25.32600","2.11075","0.01244"
"4290","25.70400","2.14214","0.01305"
"4353","26.08200","2.17371","0.01318"
"4416","26.46000","2.20516","0.01327"
"4479","26.83800","2.23667","0.01330"
"4542","27.21600","2.26824","0.01297"
"4605","27.59400","2.29968","0.01342"
"4668","27.97200","2.33113","0.01372"
"4731","28.35000","2.36276","0.01411"
"4794","28.72800","2.39421","0.01431"
"4857","29.10600","2.42566","0.01448"
"4920","29.48400","2.45723","0.01458"
"4983","29.86200","2.48874","0.01469"
"5046","30.24000","2.52019","0.01464"
"5109","30.61800","2.55170","0.01513"
"5172","30.99600","2.58321","0.01534"
"5235","31.37400","2.61472","0.01563"
"5298","31.75200","2.64622","0.01577"
"5361","32.13000","2.67773","0.01574"
"5424","32.50800","2.70924","0.01596"
"5487","32.88600","2.74069","0.01620"
"5550","33.26400","2.77220","0.01664"
"5613","33.64200","2.80377","0.01687"
"5676","34.02000","2.83516","0.01705"
"5739","34.39800","2.86667","0.01744"
"5802","34.77600","2.89818","0.01771"
"5865","35.15400","2.92969","0.01763"
"5928","35.53200","2.96120","0.01804"
"5991","35.91000","2.99271","0.01802"
"6054","36.28800","3.02421","0.01802"
"6117","36.66600","3.05572","0.01848"
"6180","37.04400","3.08723","0.01923"
"6243","37.42200","3.11868","0.01948"
"6306","37.80000","3.15019","0.01992"
"6369","38.17800","3.18170","0.02034"
"6432","38.55600","3.21321","0.02097"
"6495","38.93400","3.24472","0.02089"
"6558","39.31200","3.27617","0.02181"
"6621","39.69000","3.30774","0.02118"
"6684","40.06800","3.33919","0.02185"
"6747","40.44600","3.37063","0.02251"
"6810","40.82400","3.40220","0.02256"
"6873","41.20200","3.43371","0.02297"
"6936","41.58000","3.46516","0.02352"
"6999","41.95800","3.49667","0.02384"
"7062","42.33600","3.52824","0.02458"
"7125","42.71400","3.55969","0.02535"
"7188","43.09200","3.59120","0.02533"
"7251","43.47000","3.62271","0.02641"
"7314","43.84800","3.65428","0.02698"
"7377","44.22600","3.68561","0.02717"
"7440","44.60400","3.71718","0.02725"
"7503","44.98200","3.74874","0.02829"
"7566","45.36000","3.78019","0.02837"
"7629","45.73800","3.81170","0.02849"
"7692","46.11600","3.84321","0.02921"
"7755","46.49400","3.87472","0.02958"
"7818","46.87200","3.90617","0.02998"
"7881","47.25000","3.93774","0.03053"
"7944","47.62800","3.96925","0.03064"
"8007","48.00600","4.00070","0.03119"
"8070","48.38400","4.03221","0.03144"
"8133","48.76200","4.06372","0.03239"
"8196","49.14000","4.09516","0.03323"
"8259","49.51800","4.12673","0.03317"
"8322","49.89600","4.15824","0.03374"
"8385","50.27400","4.18969","0.03432"
"8448","50.65200","4.22114","0.03463"
"8511","51.03000","4.25277","0.03505"
"8574","51.40800","4.28422","0.03539"
"8637","51.78600","4.31567","0.03594"
"8700","52.16400","4.34724","0.03620"
"8763","52.54200","4.37869","0.03675"
"8826","52.92000","4.41020","0.03702"
"8889","53.29800","4.44170","0.03749"
"8952","53.67600","4.47315","0.03826"
"9015","54.05400","4.50472","0.03869"
"9078","54.43200","4.53617","0.03902"
"9141","54.81000","4.56768","0.03991"
"9204","55.18800","4.59925","0.04081"
"9267","55.56600","4.63070","0.04112"
"9330","55.94400","4.66221","0.04144"
"9393","56.32200","4.69378","0.04222"
"9456","56.70000","4.72517","0.04295"
"9519","57.07800","4.75668","0.04330"
"9582","57.45600","4.78824","0.04389"
"9645","57.83400","4.81969","0.04510"
"9708","58.21200","4.85120","0.04549"
"9771","58.59000","4.88271","0.04613"
"9834","58.96800","4.91422","0.04730"
"9897","59.34600","4.94567","0.04759"
"9960","59.72400","4.97718","0.04856"
"10023","60.10200","5.00869","0.04980"
"10086","60.48000","5.04020","0.05025"
"10149","60.85800","5.07165","0.05097"
"10212","61.23600","5.10322","0.05205"
"10275","61.61400","5.13478","0.05260"
"10338","61.99200","5.16617","0.05340"
"10401","62.37000","5.19768","0.05410"
"10464","62.74800","5.22919","0.05495"
"10527","63.12600","5.26070","0.05538"
"10590","63.50400","5.29215","0.05561"
"10653","63.88200","5.32372","0.05621"
"10716","64.26000","5.35523","0.05662"
"10779","64.63800","5.38668","0.05722"
"10842","65.01600","5.41819","0.05791"
"10905","65.39400","5.44970","0.05826"
"10968","65.77200","5.48121","0.05903"
"11031","66.15000","5.51265","0.05941"
"11094","66.52800","5.54422","0.06011"
"11157","66.90600","5.57573","0.06042"
"11220","67.28400","5.60718","0.06076"
"11283","67.66200","5.63875","0.06120"
"11346","68.04000","5.67020","0.06182"
"11409","68.41800","5.70165","0.06283"
"11472","68.79600","5.73322","0.06256"
"11535","69.17400","5.76467","0.06349"
"11598","69.55200","5.79618","0.06454"
"11661","69.93000","5.82769","0.06503"
"11724","70.30800","5.85920","0.06612"
"11787","70.68600","5.89064","0.06666"
"11850","71.06400","5.92215","0.06712"
"11913","71.44200","5.95372","0.06850"
"11976","71.82000","5.98529","0.06893"
"12039","72.19800","6.01662","0.06997"
"12102","72.57600","6.04819","0.07119"
"12165","72.95400","6.07976","0.07178"
"12228","73.33200","6.11115","0.07357"
"12291","73.71000","6.14272","0.07376"
"12354","74.08800","6.17429","0.07494"
"12417","74.46600","6.20568","0.07532"
"12480","74.84400","6.23718","0.07640"
"12543","75.22200","6.26869","0.07836"
"12606","75.60000","6.30020","0.07840"
"12669","75.97800","6.33171","0.07923"
"12732","76.35600","6.36322","0.08005"
"12795","76.73400","6.39467","0.08124"
"12858","77.11200","6.42618","0.08165"
"12921","77.49000","6.45763","0.08253"
"12984","77.86800","6.48920","0.08281"
"13047","78.24600","6.52071","0.08324"
"13110","78.62400","6.55216","0.08388"
"13173","79.00200","6.58372","0.08459"
"13236","79.38000","6.61523","0.08529"
"13299","79.75800","6.64668","0.08567"
"13362","80.13600","6.67825","0.08639"
"13425","80.51400","6.70970","0.08706"
"13488","80.89200","6.74115","0.08755"
"13551","81.27000","6.77266","0.08758"
"13614","81.64800","6.80423","0.08892"
"13677","82.02600","6.83574","0.08915"
"13740","82.40400","6.86713","0.08982"
"13803","82.78200","6.89870","0.09007"
"13866","83.16000","6.93026","0.09101"
"13929","83.53800","6.96165","0.09117"
"13992","83.91600","6.99322","0.09217"
"14055","84.29400","7.02479","0.09303"
"14118","84.67200","7.05618","0.09328"
"14181","85.05000","7.08763","0.09446"
"14244","85.42800","7.11920","0.09513"
"14307","85.80600","7.15071","0.09536"
"14370","86.18400","7.18216","0.09646"
"14433","86.56200","7.21373","0.09712"
"14496","86.94000","7.24524","0.09739"
"14559","87.31800","7.27668","0.09842"
"14622","87.69600","7.30819","0.09880"
"14685","88.07400","7.33970","0.09988"
"14748","88.45200","7.37127","0.10064"
"14811","88.83000","7.40266","0.10234"
"14874","89.20800","7.43423","0.10365"
"14937","89.58600","7.46574","0.10386"
"15000","89.96400","7.49719","0.10453"
"15063","90.34200","7.52876","0.10584"
"15126","90.72000","7.56027","0.10646"
"15189","91.09800","7.59166","0.10721"
"15252","91.47600","7.62317","0.10820"
"15315","91.85400","7.65474","0.10943"
"15378","92.23200","7.68618","0.11000"
"15441","92.61000","7.71769","0.11091"
"15504","92.98800","7.74920","0.11221"
"15567","93.36600","7.78071","0.11346"
"15630","93.74400","7.81216","0.11437"
"15693","94.12200","7.84367","0.11631"
"15756","94.50000","7.87524","0.11722"
"15819","94.87800","7.90669","0.11878"
"15882","95.25600","7.93820","0.12004"
"15945","95.63400","7.96971","0.12186"
"16008","96.01200","8.00115","0.12101"
"16071","96.39000","8.03266","0.12266"
"16134","96.76800","8.06423","0.12477"
"16197","97.14600","8.09568","0.12643"
"16260","97.52400","8.12719","0.12862"
"16323","97.90200","8.15870","0.12859"
"16386","98.28000","8.19021","0.13096"
"16449","98.65800","8.22172","0.13233"
"16512","99.03600","8.25317","0.13408"
"16575","99.41400","8.28474","0.13506"
"16638","99.79200","8.31625","0.13657"
"16701","100.17000","8.34764","0.13731"
"16764","100.54800","8.37920","0.13852"
"16827","100.92600","8.41077","0.13976"
"16890","101.30400","8.44216","0.14075"
"16953","101.68200","8.47373","0.14196"
"17016","102.06000","8.50518","0.14290"
"17079","102.43800","8.53669","0.14429"
"17142","102.81600","8.56820","0.14560"
"17205","103.19400","8.59971","0.14787"
"17268","103.57200","8.63122","0.15020"
"17331","103.95000","8.66273","0.15151"
"17394","104.32800","8.69418","0.15299"
"17457","104.70600","8.72568","0.15597"
"17520","105.08400","8.75725","0.15819"
"17583","105.46200","8.78864","0.15979"
"17646","105.84000","8.82021","0.16096"
"17709","106.21800","8.85172","0.16252"
"17772","106.59600","8.88317","0.16395"
"17835","106.97400","8.91474","0.16489"
"17898","107.35200","8.94625","0.16636"
"17961","107.73000","8.97764","0.16739"
"18024","108.10800","9.00921","0.16878"
"18087","108.48600","9.04066","0.17032"
"18150","108.86400","9.07216","0.17146"
"18213","109.24200","9.10367","0.17346"
"18276","109.62000","9.13518","0.17464"
"18339","109.99800","9.16675","0.17680"
"18402","110.37600","9.19814","0.17791"
"18465","110.75400","9.22971","0.17955"
"18528","111.13200","9.26128","0.18100"
"18591","111.51000","9.29261","0.18241"
"18654","111.88800","9.32424","0.18442"
"18717","112.26600","9.35575","0.18560"
"18780","112.64400","9.38720","0.18659"
"18843","113.02200","9.41870","0.18852"
"18906","113.40000","9.45021","0.19013"
"18969","113.77800","9.48172","0.19221"
"19032","114.15600","9.51317","0.19293"
"19095","114.53400","9.54474","0.19504"
"19158","114.91200","9.57625","0.19633"
"19221","115.29000","9.60770","0.19725"
"19284","115.66800","9.63915","0.19866"
"19347","116.04600","9.67072","0.19985"
"19410","116.42400","9.70223","0.20084"
"19473","116.80200","9.73368","0.20261"
"19536","117.18000","9.76525","0.20368"
"19599","117.55800","9.79669","0.20499"
"19662","117.93600","9.82814","0.20630"
"19725","118.31400","9.85971","0.20800"
"19788","118.69200","9.89122","0.20931"
"19851","119.07000","9.92267","0.21119"
"19914","119.44800","9.95418","0.21333"
"19977","119.82600","9.98575","0.21340"
"20040","120.20400","10.01720","0.21558"
"20103","120.58200","10.04865","0.21653"
"20166","120.96000","10.08022","0.21781"
"20229","121.33800","10.11178","0.21939"
"20292","121.71600","10.14311","0.22134"
"20355","122.09400","10.17468","0.22396"
"20418","122.47200","10.20619","0.22583"
"20481","122.85000","10.23770","0.22671"
"20544","123.22800","10.26921","0.22981"
"20607","123.60600","10.30072","0.23196"
"20670","123.98400","10.33223","0.23359"
"20733","124.36200","10.36368","0.23549"
"20796","124.74000","10.39525","0.23742"
"20859","125.11800","10.42676","0.23833"
"20922","125.49600","10.45821","0.24074"
"20985","125.87400","10.48965","0.24249"
"21048","126.25200","10.52122","0.23995"
"21111","126.63000","10.55273","0.24209"
"21174","127.00800","10.58418","0.24302"
"21237","127.38600","10.61575","0.24461"
"21300","127.76400","10.64720","0.24639"
"21363","128.14200","10.67865","0.24921"
"21426","128.52000","10.71028","0.25242"
"21489","128.89800","10.74173","0.25558"
"21552","129.27600","10.77318","0.25836"
"21615","129.65400","10.80475","0.26049"
"21678","130.03200","10.83619","0.26210"
"21741","130.41000","10.86770","0.26438"
"21804","130.78800","10.89921","0.26690"
"21867","131.16600","10.93072","0.26984"
"21930","131.54400","10.96223","0.27309"
"21993","131.92200","10.99368","0.27608"
"22056","132.30000","11.02519","0.27964"
"22119","132.67800","11.05670","0.28317"
"22182","133.05600","11.08821","0.28623"
"22245","133.43400","11.11966","0.28917"
"22308","133.81200","11.15129","0.29080"
"22371","134.19000","11.18268","0.29315"
"22434","134.56800","11.21412","0.29458"
"22497","134.94600","11.24569","0.29651"
"22560","135.32400","11.27720","0.29810"
"22623","135.70200","11.30865","0.30051"
"22686","136.08000","11.34022","0.30258"
"22749","136.45800","11.37167","0.30429"
"22812","136.83600","11.40318","0.30568"
"22875","137.21400","11.43469","0.30733"
"22938","137.59200","11.46620","0.30923"
"23001","137.97000","11.49777","0.29408"
"23064","138.34800","11.52915","0.29533"
"23127","138.72600","11.56073","0.29695"
"23190","139.10400","11.59223","0.29901"
"23253","139.48200","11.62368","0.30109"
"23316","139.86000","11.65519","0.30320"
"23379","140.23800","11.68670","0.30521"
"23442","140.61600","11.71821","0.30714"
"23505","140.99400","11.74972","0.30974"
"23568","141.37200","11.78123","0.31194"
"23631","141.75000","11.81274","0.31460"
"23694","142.12800","11.84419","0.31719"
"23757","142.50600","11.87570","0.31847"
"23820","142.88400","11.90721","0.32040"
"23883","143.26200","11.93865","0.32252"
"23946","143.64000","11.97016","0.32468"
"24009","144.01800","12.00173","0.32681"
"24072","144.39600","12.03318","0.33130"
"24135","144.77400","12.06469","0.33481"
"24198","145.15200","12.09626","0.33796"
"24261","145.53000","12.12771","0.34129"
"24324","145.90800","12.15916","0.34445"
"24387","146.28600","12.19073","0.34699"
"24450","146.66400","12.22224","0.34939"
"24513","147.04200","12.25369","0.35232"
"24576","147.42000","12.28520","0.35740"
"24639","147.79800","12.31670","0.36123"
"24702","148.17600","12.34815","0.36478"
"24765","148.55400","12.37966","0.36766"
"24828","148.93200","12.41123","0.36983"
"24891","149.31000","12.44274","0.37201"
"24954","149.68800","12.47413","0.37420"
"25017","150.06600","12.50570","0.37698"
"25080","150.44400","12.53727","0.37937"
"25143","150.82200","12.56866","0.38384"
"25206","151.20000","12.60023","0.38876"
"25269","151.57800","12.63173","0.39164"
"25332","151.95600","12.66318","0.39349"
"25395","152.33400","12.69463","0.39557"
"25458","152.71200","12.72620","0.39742"
"25521","153.09000","12.75771","0.39955"
"25584","153.46800","12.78922","0.40116"
"25647","153.84600","12.82067","0.40322"
"25710","154.22400","12.85224","0.40526"
"25773","154.60200","12.88369","0.40752"
"25836","154.98000","12.91520","0.40954"
"25899","155.35800","12.94677","0.41210"
"25962","155.73600","12.97822","0.41535"
"26025","156.11400","13.00966","0.41837"
"26088","156.49200","13.04117","0.42155"
"26151","156.87000","13.07274","0.40318"
"26214","157.24800","13.10419","0.40409"
"26277","157.62600","13.13576","0.40475"
"26340","158.00400","13.16721","0.40022"
"26403","158.38200","13.19866","0.40252"
"26466","158.76000","13.23017","0.40455"
"26529","159.13800","13.26174","0.40752"
"26592","159.51600","13.29325","0.40951"
"26655","159.89400","13.32464","0.41254"
"26718","160.27200","13.35620","0.41497"
"26781","160.65000","13.38771","0.41924"
"26844","161.02800","13.41916","0.42267"
"26907","161.40600","13.45067","0.42361"
"26970","161.78400","13.48224","0.33447"
"27033","162.16200","13.51369","0.33671"
"27096","162.54000","13.54514","0.34018"
"27159","162.91800","13.57671","0.34349"
"27222","163.29600","13.60822","0.34631"
"27285","163.67400","13.63961","0.35055"
"27348","164.05200","13.67124","0.35425"
"27411","164.43000","13.70268","0.35969"
"27474","164.80800","13.73419","0.36435"
"27537","165.18600","13.76564","0.36761"
"27600","165.56400","13.79721","0.37034"
"27663","165.94200","13.82878","0.37263"
"27726","166.32000","13.86017","0.37570"
"27789","166.69800","13.89168","0.37964"
"27852","167.07600","13.92325","0.38454"
"27915","167.45400","13.95464","0.38871"
"27978","167.83200","13.98621","0.39219"
"28041","168.21000","14.01772","0.39442"
"28104","168.58800","14.04916","0.39713"
"28167","168.96600","14.08068","0.40030"
"28230","169.34400","14.11224","0.40306"
"28293","169.72200","14.14369","0.40655"
"28356","170.10000","14.17520","0.40946"
"28419","170.47800","14.20671","0.41383"
"28482","170.85600","14.23822","0.41789"
"28545","171.23400","14.26967","0.42133"
"28608","171.61200","14.30124","0.42391"
"28671","171.99000","14.33275","0.42788"
"28734","172.36800","14.36420","0.43201"
"28797","172.74600","14.39571","0.43606"
"28860","173.12400","14.42721","0.44016"
"28923","173.50200","14.45866","0.44317"
"28986","173.88000","14.49017","0.44592"
"29049","174.25800","14.52174","0.44840"
"29112","174.63600","14.55319","0.45184"
"29175","175.01400","14.58470","0.45817"
"29238","175.39200","14.61621","0.46503"
"29301","175.77000","14.64766","0.47058"
"29364","176.14800","14.67923","0.47323"
"29427","176.52600","14.71068","0.47668"
"29490","176.90400","14.74224","0.48116"
"29553","177.28200","14.77376","0.48600"
"29616","177.66000","14.80514","0.48994"
"29679","178.03800","14.83671","0.49434"
"29742","178.41600","14.86828","0.49687"
"29805","178.79400","14.89967","0.50136"
"29868","179.17200","14.93118","0.50400"
"29931","179.55000","14.96269","0.50775"
"29994","179.92800","14.99420","0.51001"
"30057","180.30600","15.02571","0.51246"
"30120","180.68400","15.05722","0.51504"
"30183","181.06200","15.08873","0.51763"
"30246","181.44000","15.12018","0.52067"
"30309","181.81800","15.15168","0.52495"
"30372","182.19600","15.18319","0.52831"
"30435","182.57400","15.21470","0.53375"
"30498","182.95200","15.24621","0.54111"
"30561","183.33000","15.27772","0.54533"
"30624","183.70800","15.30923","0.54943"
"30687","184.08600","15.34062","0.55247"
"30750","184.46400","15.37219","0.55610"
"30813","184.84200","15.40376","0.56052"
"30876","185.22000","15.43515","0.56363"
"30939","185.59800","15.46672","0.56832"
"31002","185.97600","15.49822","0.57267"
"31065","186.35400","15.52967","0.57656"
"31128","186.73200","15.56118","0.57963"
"31191","187.11000","15.59275","0.58374"
"31254","187.48800","15.62420","0.58848"
"31317","187.86600","15.65565","0.59279"
"31380","188.24400","15.68722","0.59670"
"31443","188.62200","15.71873","0.59956"
"31506","189.00000","15.75012","0.60276"
"31569","189.37800","15.78169","0.60816"
"31632","189.75600","15.81326","0.61300"
"31695","190.13400","15.84470","0.61571"
"31758","190.51200","15.87615","0.61929"
"31821","190.89000","15.90772","0.62265"
"31884","191.26800","15.93917","0.62692"
"31947","191.64600","15.97062","0.63255"
"32010","192.02400","16.00219","0.63918"
"32073","192.40200","16.03376","0.64449"
"32136","192.78000","16.06521","0.64738"
"32199","193.15800","16.09666","0.65299"
"32262","193.53600","16.12823","0.65811"
"32325","193.91400","16.15973","0.66547"
"32388","194.29200","16.19118","0.67231"
"32451","194.67000","16.22269","0.67609"
"32514","195.04800","16.25420","0.67921"
"32577","195.42600","16.28565","0.68268"
"32640","195.80400","16.31722","0.68677"
"32703","196.18200","16.34867","0.69335"
"32766","196.56000","16.38018","0.70024"
"32829","196.93800","16.41169","0.70490"
"32892","197.31600","16.44320","0.70917"
"32955","197.69400","16.47471","0.71258"
"33018","198.07200","16.50622","0.71606"
"33081","198.45000","16.53772","0.72041"
"33144","198.82800","16.56923","0.72734"
"33207","199.20600","16.60062","0.72945"
"33270","199.58400","16.63219","0.73355"
"33333","199.96200","16.66370","0.73777"
"33396","200.34000","16.69521","0.74297"
"33459","200.71800","16.72666","0.74823"
"33522","201.09600","16.75823","0.75317"
"33585","201.47400","16.78968","0.75849"
"33648","201.85200","16.82113","0.76587"
"33711","202.23000","16.85270","0.77513"
"33774","202.60800","16.88421","0.78114"
"33837","202.98600","16.91571","0.78626"
"33900","203.36400","16.94716","0.79151"
"33963","203.74200","16.97873","0.79830"
"34026","204.12000","17.01024","0.80446"
"34089","204.49800","17.04169","0.80982"
"34152","204.87600","17.07320","0.81533"
"34215","205.25400","17.10471","0.81975"
"34278","205.63200","17.13610","0.82318"
"34341","206.01000","17.16773","0.82583"
"34404","206.38800","17.19924","0.82824"
"34467","206.76600","17.23063","0.83009"
"34530","207.14400","17.26219","0.83310"
"34593","207.52200","17.29370","0.83626"
"34656","207.90000","17.32515","0.84041"
"34719","208.27800","17.35672","0.84483"
"34782","208.65600","17.38823","0.85058"
"34845","209.03400","17.41974","0.85540"
"34908","209.41200","17.45119","0.86132"
"34971","209.79000","17.48264","0.86696"
"35034","210.16800","17.51427","0.87404"
"35097","210.54600","17.54572","0.88076"
"35160","210.92400","17.57717","0.88499"
"35223","211.30200","17.60874","0.88991"
"35286","211.68000","17.64018","0.89631"
"35349","212.05800","17.67163","0.90168"
"35412","212.43600","17.70326","0.90744"
"35475","212.81400","17.73471","0.91378"
"35538","213.19200","17.76616","0.92000"
"35601","213.57000","17.79773","0.92417"
"35664","213.94800","17.82918","0.92890"
"35727","214.32600","17.86069","0.93373"
"35790","214.70400","17.89220","0.93943"
"35853","215.08200","17.92377","0.94371"
"35916","215.46000","17.95522","0.95028"
"35979","215.83800","17.98666","0.95880"
"36042","216.21600","18.01817","0.96453"
"36105","216.59400","18.04968","0.96986"
"36168","216.97200","18.08119","0.97745"
"36231","217.35000","18.11270","0.95837"
"36294","217.72800","18.14421","0.96460"
"36357","218.10600","18.17566","0.97019"
"36420","218.48400","18.20717","0.97434"
"36483","218.86200","18.23874","0.98247"
"36546","219.24000","18.27025","0.98902"
"36609","219.61800","18.30164","0.99405"
"36672","219.99600","18.33320","0.99799"
"36735","220.37400","18.36471","1.00450"
"36798","220.75200","18.39616","1.00987"
"36861","221.13000","18.42773","1.01444"
"36924","221.50800","18.45924","1.01743"
"36987","221.88600","18.49069","1.02020"
"37050","222.26400","18.52214","1.02310"
"37113","222.64200","18.55371","1.02591"
"37176","223.02000","18.58522","1.03326"
"37239","223.39800","18.61667","1.04229"
"37302","223.77600","18.64824","1.04858"
"37365","224.15400","18.67969","1.05849"
"37428","224.53200","18.71119","1.06256"
"37491","224.91000","18.74270","1.06830"
"37554","225.28800","18.77421","1.07544"
"37617","225.66600","18.80566","1.08009"
"37680","226.04400","18.83717","1.08803"
"37743","226.42200","18.86868","1.09830"
"37806","226.80000","18.90025","1.10705"
"37869","227.17800","18.93164","1.11481"
"37932","227.55600","18.96321","1.12071"
"37995","227.93400","18.99472","1.12715"
"38058","228.31200","19.02623","1.13307"
"38121","228.69000","19.05767","1.13687"
"38184","229.06800","19.08924","1.14004"
"38247","229.44600","19.12069","0.87099"
"38310","229.82400","19.15214","0.68753"
"38373","230.20200","19.18371","0.69862"
"38436","230.58000","19.21522","0.70807"
"38499","230.95800","19.24667","0.71726"
"38562","231.33600","19.27818","0.72828"
"38625","231.71400","19.30975","0.73227"
"38688","232.09200","19.34120","0.73893"
"38751","232.47000","19.37271","0.75396"
"38814","232.84800","19.40421","0.76206"
"38877","233.22600","19.43572","0.77081"
"38940","233.60400","19.46717","0.78235"
"39003","233.98200","19.49868","0.79283"
"39066","234.36000","19.53019","0.80313"
"39129","234.73800","19.56164","0.81551"
"39192","235.11600","19.59327","0.82297"
"39255","235.49400","19.62472","0.82612"
"39318","235.87200","19.65617","0.83320"
"39381","236.25000","19.68768","0.84069"
"39444","236.62800","19.71918","0.84533"
"39507","237.00600","19.75076","0.85610"
"39570","237.38400","19.78220","0.86330"
"39633","237.76200","19.81371","0.87008"
"39696","238.14000","19.84522","0.88105"
"39759","238.51800","19.87667","0.88758"
"39822","238.89600","19.90818","0.90062"
"39885","239.27400","19.93975","0.90635"
"39948","239.65200","19.97120","0.91353"
"40011","240.03000","20.00265","0.92242"
"40074","240.40800","20.03428","0.92817"
"40137","240.78600","20.06573","0.93418"
"40200","241.16400","20.09718","0.94079"
"40263","241.54200","20.12874","0.95283"
"40326","241.92000","20.16019","0.96229"
"40389","242.29800","20.19170","0.97125"
"40452","242.67600","20.22315","0.97975"
"40515","243.05400","20.25472","0.98966"
"40578","243.43200","20.28623","0.99458"
"40641","243.81000","20.31762","1.00241"
"40704","244.18800","20.34919","1.00996"
"40767","244.56600","20.38076","1.01638"
"40830","244.94400","20.41215","1.02124"
"40893","245.32200","20.44372","1.02572"
"40956","245.70000","20.47522","1.03105"
"41019","246.07800","20.50667","1.03591"
"41082","246.45600","20.53818","1.04176"
"41145","246.83400","20.56975","1.05144"
"41208","247.21200","20.60120","1.06333"
"41271","247.59000","20.63271","1.06932"
"41334","247.96800","20.66422","1.07584"
"41397","248.34600","20.69567","1.08543"
"41460","248.72400","20.72712","1.09248"
"41523","249.10200","20.75875","1.09962"
"41586","249.48000","20.79026","1.10826"
"41649","249.85800","20.82170","1.11567"
"41712","250.23600","20.85315","1.12298"
"41775","250.61400","20.88472","1.12970"
"41838","250.99200","20.91617","1.13533"
"41901","251.37000","20.94768","1.13898"
"41964","251.74800","20.97925","1.14333"
"42027","252.12600","21.01070","1.14830"
"42090","252.50400","21.04221","1.15656"
"42153","252.88200","21.07366","1.16442"
"42216","253.26000","21.10523","1.17160"
"42279","253.63800","21.13674","1.18309"
"42342","254.01600","21.16818","1.19346"
"42405","254.39400","21.19969","1.20064"
"42468","254.77200","21.23126","1.21117"
"42531","255.15000","21.26265","1.21895"
"42594","255.52800","21.29422","1.22654"
"42657","255.90600","21.32579","1.23578"
"42720","256.28400","21.35718","1.24141"
"42783","256.66200","21.38863","1.24662"
"42846","257.04000","21.42026","1.25521"
"42909","257.41800","21.45171","1.26528"
"42972","257.79600","21.48315","1.27408"
"43035","258.17400","21.51472","1.27966"
"43098","258.55200","21.54623","1.28733"
"43161","258.93000","21.57768","1.29458"
"43224","259.30800","21.60913","1.30011"
"43287","259.68600","21.64070","1.30828"
"43350","260.06400","21.67215","1.31738"
"43413","260.44200","21.70372","1.32402"
"43476","260.82000","21.73523","1.33246"
"43539","261.19800","21.76674","1.34226"
"43602","261.57600","21.79813","1.34816"
"43665","261.95400","21.82976","1.35472"
"43728","262.33200","21.86121","1.36661"
"43791","262.71000","21.89260","1.37788"
"43854","263.08800","21.92422","1.38528"
"43917","263.46600","21.95567","1.39634"
"43980","263.84400","21.98718","1.40790"
"44043","264.22200","22.01869","1.42018"
"44106","264.60000","22.05026","1.42938"
"44169","264.97800","22.08171","1.43560"
"44232","265.35600","22.11316","1.44006"
"44295","265.73400","22.14467","1.44420"
"44358","266.11200","22.17624","1.45033"
"44421","266.49000","22.20763","1.45837"
"44484","266.86800","22.23919","1.46895"
"44547","267.24600","22.27071","1.47935"
"44610","267.62400","22.30215","1.49169"
"44673","268.00200","22.33366","1.50210"
"44736","268.38000","22.36523","1.51381"
"44799","268.75800","22.39668","1.52787"
"44862","269.13600","22.42819","1.53602"
"44925","269.51400","22.45970","1.54424"
"44988","269.89200","22.49121","1.55298"
"45051","270.27000","22.52272","1.56265"
"45114","270.64800","22.55417","1.57180"
"45177","271.02600","22.58574","1.58179"
"45240","271.40400","22.61724","1.58664"
"45303","271.78200","22.64869","1.59802"
"45366","272.16000","22.68020","1.61178"
"45429","272.53800","22.71171","1.63007"
"45492","272.91600","22.74316","1.63950"
"45555","273.29400","22.77473","1.64873"
"45618","273.67200","22.80618","1.65876"
"45681","274.05000","22.83763","1.67029"
"45744","274.42800","22.86920","1.68560"
"45807","274.80600","22.90071","1.69579"
"45870","275.18400","22.93222","1.70731"
"45933","275.56200","22.96372","1.71697"
"45996","275.94000","22.99523","1.72648"
"46059","276.31800","23.02674","1.73449"
"46122","276.69600","23.05813","1.74222"
"46185","277.07400","23.08970","1.74690"
"46248","277.45200","23.12121","1.75430"
"46311","277.83000","23.15266","1.76399"
"46374","278.20800","23.18417","1.77529"
"46437","278.58600","23.21574","1.78912"
"46500","278.96400","23.24719","1.80341"
"46563","279.34200","23.27864","1.81485"
"46626","279.72000","23.31021","1.83223"
"46689","280.09800","23.34171","1.84338"
"46752","280.47600","23.37322","1.84961"
"46815","280.85400","23.40467","1.85233"
"46878","281.23200","23.43624","1.85025"
"46941","281.61000","23.46775","1.84398"
"47004","281.98800","23.49920","1.84410"
"47067","282.36600","23.53071","1.84899"
"47130","282.74400","23.56222","1.82333"
"47193","283.12200","23.59361","1.84279"
"47256","283.50000","23.62523","1.84831"
"47319","283.87800","23.65675","1.84591"
"47382","284.25600","23.68813","1.85195"
"47445","284.63400","23.71970","1.85912"
"47508","285.01200","23.75121","1.86461"
"47571","285.39000","23.78272","1.87428"
"47634","285.76800","23.81423","1.88839"
"47697","286.14600","23.84568","1.90219"
"47760","286.52400","23.87719","1.91515"
"47823","286.90200","23.90870","1.92941"
"47886","287.28000","23.94020","1.94547"
"47949","287.65800","23.97172","1.95565"
"48012","288.03600","24.00316","1.96619"
"48075","288.41400","24.03468","1.97866"
"48138","288.79200","24.06624","1.99452"
"48201","289.17000","24.09769","2.00772"
"48264","289.54800","24.12914","2.02198"
"48327","289.92600","24.16077","2.03616"
"48390","290.30400","24.19216","2.05057"
"48453","290.68200","24.22367","1.85539"
"48516","291.06000","24.25524","1.86225"
"48579","291.43800","24.28669","1.86991"
"48642","291.81600","24.31820","1.88526"
"48705","292.19400","24.34971","1.89616"
"48768","292.57200","24.38121","1.91308"
"48831","292.95000","24.41267","1.92372"
"48894","293.32800","24.44423","1.94324"
"48957","293.70600","24.47568","1.95395"
"49020","294.08400","24.50725","1.07509"
"49083","294.46200","24.53864","0.83971"
"49146","294.84000","24.57021","0.82874"
"49209","295.21800","24.60172","0.83559"
"49272","295.59600","24.63317","0.85407"
"49335","295.97400","24.66468","0.83616"
"49398","296.35200","24.69625","0.83644"
"49461","296.73000","24.72775","0.85084"
"49524","297.10800","24.75915","0.85952"
"49587","297.48600","24.79071","0.72150"
"49650","297.86400","24.82222","0.72004"
"49713","298.24200","24.85367","0.72661"
"49776","298.62000","24.88518","0.72848"
"49839","298.99800","24.91675","0.74778"
"49902","299.37600","24.94820","0.75130"
"49965","299.75400","24.97965","0.75532"
"50028","300.13200","25.01122","0.78285"
"50091","300.51000","25.04273","0.78324"
"50154","300.88800","25.07417","0.78923"
"50217","301.26600","25.10575","0.81194"
"50280","301.64400","25.13720","0.81339"
"50343","302.02200","25.16864","0.81969"
"50406","302.40000","25.20021","0.83083"
"50469","302.77800","25.23172","0.83804"
"50532","303.15600","25.26317","0.84077"
"50595","303.53400","25.29468","0.85138"
"50658","303.91200","25.32625","0.86861"
"50721","304.29000","25.35776","0.87565"
"50784","304.66800","25.38915","0.88053"
"50847","305.04600","25.42071","0.89477"
"50910","305.42400","25.45223","0.90844"
"50973","305.80200","25.48368","0.91126"
"51036","306.18000","25.51518","0.91944"
"51099","306.55800","25.54675","0.92812"
"51162","306.93600","25.57820","0.94495"
"51225","307.31400","25.60971","0.95954"
"51288","307.69200","25.64122","0.96265"
"51351","308.07000","25.67273","0.96757"
"51414","308.44800","25.70418","0.97605"
"51477","308.82600","25.73569","0.99266"
"51540","309.20400","25.76720","1.00729"
"51603","309.58200","25.79871","1.01277"
"51666","309.96000","25.83015","0.86307"
"51729","310.33800","25.86172","0.86230"
"51792","310.71600","25.89323","0.87518"
"51855","311.09400","25.92462","0.88710"
"51918","311.47200","25.95619","0.89129"
"51981","311.85000","25.98770","0.90028"
"52044","312.22800","26.01915","0.91108"
"52107","312.60600","26.05072","0.26287"
"52170","312.98400","26.08217","0.24724"
"52233","313.36200","26.11368","0.28330"
"52296","313.74000","26.14519","0.31072"
"52359","314.11800","26.17669","0.30032"
"52422","314.49600","26.20827","0.29359"
"52485","314.87400","26.23965","0.30864"
"52548","315.25200","26.27116","0.30903"
"52611","315.63000","26.30273","0.32177"
"52674","316.00800","26.33418","0.35258"
"52737","316.38600","26.36569","0.32903"
"52800","316.76400","26.39726","0.34669"
"52863","317.14200","26.42871","0.34859"
"52926","317.52000","26.46016","0.37941"
"52989","317.89800","26.49173","0.37962"
"53052","318.27600","26.52324","0.38034"
"53115","318.65400","26.55469","0.38717"
"53178","319.03200","26.58619","0.41074"
"53241","319.41000","26.61770","0.40545"
"53304","319.78800","26.64915","0.41546"
"53367","320.16600","26.68066","0.42348"
"53430","320.54400","26.71223","0.44419"
"53493","320.92200","26.74374","0.44194"
"53556","321.30000","26.77519","0.44730"
"53619","321.67800","26.80670","0.47303"
"53682","322.05600","26.83827","0.46870"
"53745","322.43400","26.86960","0.47904"
"53808","322.81200","26.90122","0.50057"
"53871","323.19000","26.93273","0.50414"
"53934","323.56800","26.96418","0.51748"
"53997","323.94600","26.99569","0.51568"
"54060","324.32400","27.02720","0.52512"
"54123","324.70200","27.05877","0.54672"
"54186","325.08000","27.09016","0.54597"
"54249","325.45800","27.12173","0.57069"
"54312","325.83600","27.15318","0.56657"
"54375","326.21400","27.18469","0.58312"
"54438","326.59200","27.21620","0.58827"
"54501","326.97000","27.24771","0.59813"
"54564","327.34800","27.27921","0.60650"
"54627","327.72600","27.31066","0.61317"
"54690","328.10400","27.34223","0.62377"
"54753","328.48200","27.37368","0.62916"
"54816","328.86000","27.40513","0.64468"
"54879","329.23800","27.43670","0.65381"
"54942","329.61600","27.46821","0.66515"
"55005","329.99400","27.49972","0.67942"
"55068","330.37200","27.53117","0.68457"
"55131","330.75000","27.56268","0.70363"
"55194","331.12800","27.59425","0.70642"
"55257","331.50600","27.62564","0.71949"
"55320","331.88400","27.65721","0.72010"
"55383","332.26200","27.68871","0.73118"
"55446","332.64000","27.72016","0.73843"
"55509","333.01800","27.75173","0.74632"
"55572","333.39600","27.78318","0.76695"
"55635","333.77400","27.81463","0.76943"
"55698","334.15200","27.84620","0.78415"
"55761","334.53000","27.87771","0.80154"
"55824","334.90800","27.90922","0.80574"
"55887","335.28600","27.94066","0.81982"
"55950","335.66400","27.97218","0.62391"
"56013","336.04200","28.00374","0.63340"
"56076","336.42000","28.03519","0.64327"
"56139","336.79800","28.06670","0.65732"
"56202","337.17600","28.09821","0.67053"
"56265","337.55400","28.12972","0.68203"
"56328","337.93200","28.16117","0.69910"
"56391","338.31000","28.19274","0.70695"
"56454","338.68800","28.22425","0.72040"
"56517","339.06600","28.25564","0.72289"
"56580","339.44400","28.28727","0.73849"
"56643","339.82200","28.31872","0.74451"
"56706","340.20000","28.35016","0.75953"
"56769","340.57800","28.38173","0.77992"
"56832","340.95600","28.41318","0.78632"
"56895","341.33400","28.44463","0.80630"
"56958","341.71200","28.47614","0.81257"
"57021","342.09000","28.50777","0.82120"
"57084","342.46800","28.53922","0.83192"
"57147","342.84600","28.57067","0.83529"
"57210","343.22400","28.60217","0.84292"
"57273","343.60200","28.63375","0.85933"
"57336","343.98000","28.66520","0.86440"
"57399","344.35800","28.69670","0.87324"
"57462","344.73600","28.72828","0.88872"
"57525","345.11400","28.75966","0.89922"
"57588","345.49200","28.79117","0.77433"
"57651","345.87000","28.82268","0.65768"
"57714","346.24800","28.85419","0.64422"
"57777","346.62600","28.88564","0.65309"
"57840","347.00400","28.91721","0.65739"
"57903","347.38200","28.94872","0.67117"
"57966","347.76000","28.98022","0.68244"
"58029","348.13800","29.01168","0.69275"
"58092","348.51600","29.04318","0.70255"
"58155","348.89400","29.07475","0.71157"
"58218","349.27200","29.10620","0.71692"
"58281","349.65000","29.13771","0.72505"
"58344","350.02800","29.16922","0.73291"
"58407","350.40600","29.20061","0.41015"
"58470","350.78400","29.23224","0.41023"
"58533","351.16200","29.26375","0.41912"
"58596","351.54000","29.29520","0.42699"
"58659","351.91800","29.32671","0.43619"
"58722","352.29600","29.35822","0.45336"
"58785","352.67400","29.38966","0.45667"
"58848","353.05200","29.42117","0.46778"
"58911","353.43000","29.45268","0.47925"
"58974","353.80800","29.48419","0.49262"
"59037","354.18600","29.51564","0.49755"
"59100","354.56400","29.54715","0.50896"
"59163","354.94200","29.57872","0.51413"
"59226","355.32000","29.61017","0.51927"
"59289","355.69800","29.64162","0.52669"
"59352","356.07600","29.67319","0.53673"
"59415","356.45400","29.70470","0.54456"
"59478","356.83200","29.73615","0.39258"
"59541","357.21000","29.76771","0.39613"
"59604","357.58800","29.79928","0.40111"
"59667","357.96600","29.83067","0.40548"
"59730","358.34400","29.86218","0.41103"
"59793","358.72200","29.89369","0.41639"
"59856","359.10000","29.92526","0.42196"
"59919","359.47800","29.95665","0.43162"
"59982","359.85600","29.98822","0.43805"
"60045","360.23400","30.01973","0.44288"
"60108","360.61200","30.05112","0.44745"
"60171","360.99000","30.08269","0.45512"
"60234","361.36800","30.11419","0.46692"
"60297","361.74600","30.14565","0.47137"
"60360","362.12400","30.17721","0.47732"
"60423","362.50200","30.20872","0.49049"
"60486","362.88000","30.24017","0.49522"
"60549","363.25800","30.27168","0.50189"
"60612","363.63600","30.30319","0.51034"
"60675","364.01400","30.33476","0.51236"
"60738","364.39200","30.36615","0.51517"
"60801","364.77000","30.39772","0.52239"
"60864","365.14800","30.42917","0.52762"
"60927","365.52600","30.46067","0.53130"
"60990","365.90400","30.49218","0.53990"
"61053","366.28200","30.52375","0.54500"
"61116","366.66000","30.55520","0.55205"
"61179","367.03800","30.58659","0.56219"
"61242","367.41600","30.61828","0.56900"
"61305","367.79400","30.64973","0.57787"
"61368","368.17200","30.68118","0.58611"
"61431","368.55000","30.71275","0.59311"
"61494","368.92800","30.74420","0.59935"
"61557","369.30600","30.77571","0.60302"
"61620","369.68400","30.80722","0.61110"
"61683","370.06200","30.83873","0.61648"
"61746","370.44000","30.87017","0.62195"
"61809","370.81800","30.90168","0.62954"
"61872","371.19600","30.93313","0.63562"
"61935","371.57400","30.96476","0.64637"
"61998","371.95200","30.99615","0.65175"
"62061","372.33000","31.02766","0.65849"
"62124","372.70800","31.05923","0.47848"
"62187","373.08600","31.09074","0.47816"
"62250","373.46400","31.12218","0.48099"
"62313","373.84200","31.15376","0.48485"
"62376","374.22000","31.18521","0.49106"
"62439","374.59800","31.21666","0.50008"
"62502","374.97600","31.24816","0.50550"
"62565","375.35400","31.27973","0.50956"
"62628","375.73200","31.31118","0.51409"
"62691","376.11000","31.34269","0.51943"
"62754","376.48800","31.37420","0.52579"
"62817","376.86600","31.40571","0.53293"
"62880","377.24400","31.43715","0.53968"
"62943","377.62200","31.46873","0.54654"
"63006","378.00000","31.50023","0.55251"
"63069","378.37800","31.53168","0.55941"
"63132","378.75600","31.56325","0.56873"
"63195","379.13400","31.59470","0.57642"
"63258","379.51200","31.62615","0.58041"
"63321","379.89000","31.65772","0.58883"
"63384","380.26800","31.68923","0.59556"
"63447","380.64600","31.72068","0.59958"
"63510","381.02400","31.75219","0.60492"
"63573","381.40200","31.78370","0.61251"
"63636","381.78000","31.81526","0.61773"
"63699","382.15800","31.84665","0.62268"
"63762","382.53600","31.87823","0.62903"
"63825","382.91400","31.90979","0.33598"
"63888","383.29200","31.94118","0.32120"
"63951","383.67000","31.97269","0.33993"
"64014","384.04800","32.00426","0.35433"
"64077","384.42600","32.03565","0.36356"
"64140","384.80400","32.06716","0.38083"
"64203","385.18200","32.09873","0.39136"
"64266","385.56000","32.13018","0.37923"
"64329","385.93800","32.16169","0.38161"
"64392","386.31600","32.19320","0.38698"
"64455","386.69400","32.22464","0.39706"
"64518","387.07200","32.25621","0.40962"
"64581","387.45000","32.28766","0.42075"
"64644","387.82800","32.31923","0.41419"
"64707","388.20600","32.35074","0.41593"
"64770","388.58400","32.38213","0.42357"
"64833","388.96200","32.41376","0.44047"
"64896","389.34000","32.44521","0.45163"
"64959","389.71800","32.47666","0.44537"
"65022","390.09600","32.50823","0.44696"
"65085","390.47400","32.53968","0.45843"
"65148","390.85200","32.57119","0.47413"
"65211","391.23000","32.60270","0.47417"
"65274","391.60800","32.63420","0.47308"
"65337","391.98600","32.66571","0.48026"
"65400","392.36400","32.69716","0.49609"
"65463","392.74200","32.72867","0.49681"
"65526","393.12000","32.76018","0.49387"
"65589","393.49800","32.79169","0.50377"
"65652","393.87600","32.82320","0.51346"
"65715","394.25400","32.85477","0.51268"
"65778","394.63200","32.88622","0.51381"
"65841","395.01000","32.91766","0.52276"
"65904","395.38800","32.94923","0.53139"
"65967","395.76600","32.98074","0.52917"
"66030","396.14400","33.01213","0.53616"
"66093","396.52200","33.04370","0.54904"
"66156","396.90000","33.07521","0.54839"
"66219","397.27800","33.10666","0.55199"
"66282","397.65600","33.13817","0.56822"
"66345","398.03400","33.16968","0.57064"
"66408","398.41200","33.20119","0.57214"
"66471","398.79000","33.23264","0.54893"
"66534","399.16800","33.26421","0.54964"
"66597","399.54600","33.29577","0.54949"
"66660","399.92400","33.32710","0.56140"
"66723","400.30200","33.35873","0.56836"
"66786","400.68000","33.39024","0.56756"
"66849","401.05800","33.42169","0.57787"
"66912","401.43600","33.45314","0.58173"
"66975","401.81400","33.48471","0.56483"
"67038","402.19200","33.51622","0.57278"
"67101","402.57000","33.54766","0.58006"
"67164","402.94800","33.57918","0.58120"
"67227","403.32600","33.61074","0.47516"
"67290","403.70400","33.64220","0.47624"
"67353","404.08200","33.67365","0.48159"
"67416","404.46000","33.70521","0.47788"
"67479","404.83800","33.73666","0.48344"
"67542","405.21600","33.76823","0.49374"
"67605","405.59400","33.79974","0.50383"
"67668","405.97200","33.83119","0.50438"
"67731","406.35000","33.86264","0.50696"
"67794","406.72800","33.89421","0.51051"
"67857","407.10600","33.92572","0.51635"
"67920","407.48400","33.95716","0.51772"
"67983","407.86200","33.98867","0.51935"
"68046","408.24000","34.02019","0.52511"
"68109","408.61800","34.05169","0.53283"
"68172","408.99600","34.08314","0.53260"
"68235","409.37400","34.11471","0.53415"
"68298","409.75200","34.14628","0.54202"
"68361","410.13000","34.17767","0.54880"
"68424","410.50800","34.20924","0.54759"
"68487","410.88600","34.24075","0.55134"
"68550","411.26400","34.27214","0.56012"
"68613","411.64200","34.30371","0.56214"
"68676","412.02000","34.33522","0.56500"
"68739","412.39800","34.36666","0.57406"
"68802","412.77600","34.39817","0.57820"
"68865","413.15400","34.42968","0.57823"
"68928","413.53200","34.46119","0.58428"
"68991","413.91000","34.49264","0.59209"
"69054","414.28800","34.52415","0.59208"
"69117","414.66600","34.55572","0.59646"
"69180","415.04400","34.58723","0.60112"
"69243","415.42200","34.61861","0.60106"
"69306","415.80000","34.65025","0.60440"
"69369","416.17800","34.68176","0.61108"
"69432","416.55600","34.71315","0.61134"
"69495","416.93400","34.74477","0.61550"
"69558","417.31200","34.77622","0.61246"
"69621","417.69000","34.80767","0.61282"
"69684","418.06800","34.83918","0.61630"
"69747","418.44600","34.87075","0.56340"
"69810","418.82400","34.90220","0.56558"
"69873","419.20200","34.93371","0.57212"
"69936","419.58000","34.96522","0.57982"
"69999","419.95800","34.99673","0.58200"
"70062","420.33600","35.02818","0.58524"
"70125","420.71400","35.05969","0.59529"
"70188","421.09200","35.09126","0.59891"
"70251","421.47000","35.12264","0.60015"
"70314","421.84800","35.15421","0.60587"
"70377","422.22600","35.18566","0.61083"
"70440","422.60400","35.21717","0.61224"
"70503","422.98200","35.24868","0.61820"
"70566","423.36000","35.28025","0.62052"
"70629","423.73800","35.31170","0.61644"
"70692","424.11600","35.34315","0.60147"
"70755","424.49400","35.37472","0.58851"
"70818","424.87200","35.40622","0.56529"
"70881","425.25000","35.43767","0.54440"
"70944","425.62800","35.46918","0.53021"
"71007","426.00600","35.50076","0.51597"
"71070","426.38400","35.53226","0.50937"
"71133","426.76200","35.56365","0.49975"
"71196","427.14000","35.59522","0.49016"
"71259","427.51800","35.62673","0.47829"
"71322","427.89600","35.65812","0.47000"
"71385","428.27400","35.68969","0.45605"
"71448","428.65200","35.72120","0.44460"
"71511","429.03000","35.75265","0.43863"
"71574","429.40800","35.78416","0.43416"
"71637","429.78600","35.81572","0.43245"
"71700","430.16400","35.84717","0.43110"
"71763","430.54200","35.87868","0.43310"
"71826","430.92000","35.91019","0.43471"
"71889","431.29800","35.94176","0.43722"
"71952","431.67600","35.97315","0.43992"
"72015","432.05400","36.00466","0.44189"
"72078","432.43200","36.03623","0.44330"
"72141","432.81000","36.06773","0.44598"
"72204","433.18800","36.09919","0.44833"
"72267","433.56600","36.13070","0.45269"
"72330","433.94400","36.16220","0.45743"
"72393","434.32200","36.19365","0.46088"
"72456","434.70000","36.22522","0.46513"
"72519","435.07800","36.25673","0.46846"
"72582","435.45600","36.28818","0.47300"
"72645","435.83400","36.31969","0.47616"
"72708","436.21200","36.35120","0.47869"
"72771","436.59000","36.38265","0.48226"
"72834","436.96800","36.41422","0.48743"
"72897","437.34600","36.44579","0.49384"
"72960","437.72400","36.47723","0.49952"
"73023","438.10200","36.50863","0.50301"
"73086","438.48000","36.54026","0.50630"
"73149","438.85800","36.57170","0.50983"
"73212","439.23600","36.60315","0.51249"
"73275","439.61400","36.63472","0.51508"
"73338","439.99200","36.66617","0.51799"
"73401","440.37000","36.69768","0.52137"
"73464","440.74800","36.72919","0.52597"
"73527","441.12600","36.76070","0.52979"
"73590","441.50400","36.79227","0.53222"
"73653","441.88200","36.82372","0.53672"
"73716","442.26000","36.85516","0.54237"
"73779","442.63800","36.88673","0.54608"
"73842","443.01600","36.91818","0.54958"
"73905","443.39400","36.94963","0.55267"
"73968","443.77200","36.98126","0.55785"
"74031","444.15000","37.01265","0.56245"
"74094","444.52800","37.04416","0.56693"
"74157","444.90600","37.07573","0.57179"
"74220","445.28400","37.10718","0.57567"
"74283","445.66200","37.13869","0.57790"
"74346","446.04000","37.17026","0.58182"
"74409","446.41800","37.20171","0.58678"
"74472","446.79600","37.23322","0.59054"
"74535","447.17400","37.26472","0.59410"
"74598","447.55200","37.29623","0.59735"
"74661","447.93000","37.32774","0.59936"
"74724","448.30800","37.35913","0.60095"
"74787","448.68600","37.39070","0.27306"
"74850","449.06400","37.42221","0.26898"
"74913","449.44200","37.45366","0.26844"
"74976","449.82000","37.48517","0.27605"
"75039","450.19800","37.51667","0.27016"
"75102","450.57600","37.54818","0.27454"
"75165","450.95400","37.57963","0.28351"
"75228","451.33200","37.61126","0.28076"
"75291","451.71000","37.64272","0.28393"
"75354","452.08800","37.67416","0.28842"
"75417","452.46600","37.70567","0.28989"
"75480","452.84400","37.73724","0.29009"
"75543","453.22200","37.76869","0.28721"
"75606","453.60000","37.80020","-0.00488"
"75669","453.97800","37.83171","-0.01150"
"75732","454.35600","37.86322","-0.01021"
"75795","454.73400","37.89466","-0.00168"
"75858","455.11200","37.92624","-0.00161"
"75921","455.49000","37.95774","-0.01109"
"75984","455.86800","37.98913","-0.00831"
"76047","456.24600","38.02076","0.00104"
"76110","456.62400","38.05221","0.00085"
"76173","457.00200","38.08366","-0.00546"
"76236","457.38000","38.11517","-0.00955"
"76299","457.75800","38.14674","-0.00400"
"76362","458.13600","38.17819","0.00176"
"76425","458.51400","38.20964","-0.00338"
"76488","458.89200","38.24121","-0.00852"
"76551","459.27000","38.27278","-0.00451"
"76614","459.64800","38.30410","0.00054"
"76677","460.02600","38.33567","-0.00165"
"76740","460.40400","38.36730","-0.00615"
"76803","460.78200","38.39869","-0.00508"
"76866","461.16000","38.43020","-0.00143"
"76929","461.53800","38.46171","-0.00120"
"76959","461.71600","38.47648","-0.00264"