File: Trajectories_together/161223_2Specimen_RawData_4.csv
"","V1","V2","V3"
"1","End date","12/23/2016",""
"2","Specimen label","21AT_UNK",""
"3","Maximum Load","0.00834","N"
"4","Time","Extension","Load"
"5","(s)","(mm)","(N)"
"6","0.00000","0.00000","0.00005"
"15","0.05400","0.00114","0.00001"
"24","0.10800","0.00496","-0.00009"
"33","0.16200","0.01040","-0.00016"
"42","0.21600","0.01614","-0.00019"
"51","0.27000","0.02170","-0.00022"
"60","0.32400","0.02679","-0.00004"
"69","0.37800","0.03157","-0.00007"
"78","0.43200","0.03623","-0.00047"
"87","0.48600","0.04072","-0.00015"
"96","0.54000","0.04520","-0.00017"
"105","0.59400","0.04969","-0.00050"
"114","0.64800","0.05417","-0.00032"
"123","0.70200","0.05865","-0.00036"
"132","0.75600","0.06314","0.00002"
"141","0.81000","0.06762","-0.00027"
"150","0.86400","0.07217","0.00006"
"159","0.91800","0.07659","-0.00050"
"168","0.97200","0.08113","-0.00016"
"177","1.02600","0.08568","-0.00037"
"186","1.08000","0.09016","-0.00018"
"195","1.13400","0.09465","0.00001"
"204","1.18800","0.09919","-0.00026"
"213","1.24200","0.10362","-0.00030"
"222","1.29600","0.10816","-0.00024"
"231","1.35000","0.11264","0.00000"
"240","1.40400","0.11713","-0.00026"
"249","1.45800","0.12161","-0.00015"
"258","1.51200","0.12610","-0.00033"
"267","1.56600","0.13064","-0.00014"
"276","1.62000","0.13518","-0.00005"
"285","1.67400","0.13961","-0.00013"
"294","1.72800","0.14415","-0.00035"
"303","1.78200","0.14864","0.00011"
"312","1.83600","0.15306","-0.00031"
"321","1.89000","0.15761","-0.00047"
"330","1.94400","0.16203","0.00023"
"339","1.99800","0.16657","-0.00022"
"348","2.05200","0.17112","-0.00014"
"357","2.10600","0.17560","-0.00006"
"366","2.16000","0.18015","-0.00007"
"375","2.21400","0.18463","0.00002"
"384","2.26800","0.18911","-0.00047"
"393","2.32200","0.19366","-0.00020"
"402","2.37600","0.19808","0.00010"
"411","2.43000","0.20263","-0.00013"
"420","2.48400","0.20711","-0.00052"
"429","2.53800","0.21154","-0.00016"
"438","2.59200","0.21614","0.00015"
"447","2.64600","0.22062","-0.00014"
"456","2.70000","0.22511","0.00000"
"465","2.75400","0.22965","-0.00013"
"474","2.80800","0.23414","-0.00018"
"483","2.86200","0.23868","-0.00015"
"492","2.91600","0.24316","0.00000"
"501","2.97000","0.24765","-0.00008"
"510","3.02400","0.25207","-0.00005"
"519","3.07800","0.25656","-0.00017"
"528","3.13200","0.26110","-0.00023"
"537","3.18600","0.26564","-0.00021"
"546","3.24000","0.27013","-0.00042"
"555","3.29400","0.27461","0.00001"
"564","3.34800","0.27916","0.00015"
"573","3.40200","0.28358","-0.00017"
"582","3.45600","0.28813","-0.00024"
"591","3.51000","0.29261","-0.00026"
"600","3.56400","0.29703","-0.00042"
"609","3.61800","0.30158","0.00039"
"618","3.67200","0.30606","0.00003"
"627","3.72600","0.31067","-0.00033"
"636","3.78000","0.31515","-0.00052"
"645","3.83400","0.31958","-0.00015"
"654","3.88800","0.32418","-0.00010"
"663","3.94200","0.32860","0.00001"
"672","3.99600","0.33309","-0.00033"
"681","4.05000","0.33757","-0.00018"
"690","4.10400","0.34206","-0.00004"
"699","4.15800","0.34660","-0.00053"
"708","4.21200","0.35108","-0.00019"
"717","4.26600","0.35563","0.00006"
"726","4.32000","0.36017","-0.00025"
"735","4.37400","0.36460","-0.00039"
"744","4.42800","0.36914","0.00018"
"753","4.48200","0.37368","0.00028"
"762","4.53600","0.37811","0.00004"
"771","4.59000","0.38259","-0.00021"
"780","4.64400","0.38708","-0.00003"
"789","4.69800","0.39156","-0.00029"
"798","4.75200","0.39617","0.00003"
"807","4.80600","0.40065","0.00000"
"816","4.86000","0.40513","-0.00012"
"825","4.91400","0.40968","0.00018"
"834","4.96800","0.41416","0.00006"
"843","5.02200","0.41871","0.00015"
"852","5.07600","0.42313","0.00022"
"861","5.13000","0.42761","-0.00003"
"870","5.18400","0.43210","0.00007"
"879","5.23800","0.43652","0.00009"
"888","5.29200","0.44113","0.00005"
"897","5.34600","0.44567","-0.00061"
"906","5.40000","0.45016","-0.00006"
"915","5.45400","0.45470","-0.00009"
"924","5.50800","0.45918","-0.00003"
"933","5.56200","0.46361","0.00032"
"942","5.61600","0.46815","-0.00016"
"951","5.67000","0.47258","0.00034"
"960","5.72400","0.47712","0.00006"
"969","5.77800","0.48160","0.00019"
"978","5.83200","0.48603","0.00013"
"987","5.88600","0.49063","-0.00021"
"996","5.94000","0.49512","-0.00018"
"1005","5.99400","0.49960","-0.00011"
"1014","6.04800","0.50421","0.00043"
"1023","6.10200","0.50863","-0.00028"
"1032","6.15600","0.51311","0.00017"
"1041","6.21000","0.51754","-0.00022"
"1050","6.26400","0.52208","0.00054"
"1059","6.31800","0.52657","-0.00031"
"1068","6.37200","0.53111","-0.00006"
"1077","6.42600","0.53565","-0.00010"
"1086","6.48000","0.54014","-0.00015"
"1095","6.53400","0.54468","-0.00011"
"1104","6.58800","0.54917","0.00025"
"1113","6.64200","0.55365","0.00032"
"1122","6.69600","0.55814","-0.00005"
"1131","6.75000","0.56262","0.00023"
"1140","6.80400","0.56710","0.00022"
"1149","6.85800","0.57159","-0.00023"
"1158","6.91200","0.57607","-0.00018"
"1167","6.96600","0.58062","-0.00035"
"1176","7.02000","0.58516","-0.00021"
"1185","7.07400","0.58964","-0.00014"
"1194","7.12800","0.59419","-0.00009"
"1203","7.18200","0.59867","0.00029"
"1212","7.23600","0.60316","-0.00013"
"1221","7.29000","0.60764","-0.00007"
"1230","7.34400","0.61207","-0.00018"
"1239","7.39800","0.61661","-0.00013"
"1248","7.45200","0.62109","-0.00008"
"1257","7.50600","0.62564","-0.00001"
"1266","7.56000","0.63012","-0.00005"
"1275","7.61400","0.63467","-0.00014"
"1284","7.66800","0.63915","0.00014"
"1293","7.72200","0.64363","-0.00019"
"1302","7.77600","0.64818","-0.00029"
"1311","7.83000","0.65260","-0.00002"
"1320","7.88400","0.65709","-0.00017"
"1329","7.93800","0.66163","0.00022"
"1338","7.99200","0.66606","0.00001"
"1347","8.04600","0.67066","0.00023"
"1356","8.10000","0.67508","-0.00032"
"1365","8.15400","0.67963","-0.00014"
"1374","8.20800","0.68417","-0.00045"
"1383","8.26200","0.68860","0.00012"
"1392","8.31600","0.69308","0.00016"
"1401","8.37000","0.69756","0.00018"
"1410","8.42400","0.70205","-0.00004"
"1419","8.47800","0.70659","0.00023"
"1428","8.53200","0.71108","-0.00006"
"1437","8.58600","0.71562","0.00049"
"1446","8.64000","0.72022","0.00009"
"1455","8.69400","0.72459","0.00004"
"1464","8.74800","0.72913","-0.00001"
"1473","8.80200","0.73362","-0.00037"
"1482","8.85600","0.73810","-0.00008"
"1491","8.91000","0.74265","0.00023"
"1500","8.96400","0.74707","-0.00001"
"1509","9.01800","0.75155","0.00007"
"1518","9.07200","0.75610","-0.00022"
"1527","9.12600","0.76064","-0.00010"
"1536","9.18000","0.76513","-0.00024"
"1545","9.23400","0.76961","-0.00027"
"1554","9.28800","0.77415","-0.00012"
"1563","9.34200","0.77864","-0.00016"
"1572","9.39600","0.78312","-0.00031"
"1581","9.45000","0.78761","0.00020"
"1590","9.50400","0.79215","-0.00009"
"1599","9.55800","0.79658","-0.00018"
"1608","9.61200","0.80112","0.00022"
"1617","9.66600","0.80560","0.00032"
"1626","9.72000","0.81009","-0.00055"
"1635","9.77400","0.81469","-0.00018"
"1644","9.82800","0.81918","-0.00017"
"1653","9.88200","0.82366","0.00007"
"1662","9.93600","0.82814","0.00004"
"1671","9.99000","0.83257","0.00036"
"1680","10.04400","0.83711","0.00001"
"1689","10.09800","0.84166","-0.00045"
"1698","10.15200","0.84614","0.00008"
"1707","10.20600","0.85069","-0.00024"
"1716","10.26000","0.85511","-0.00001"
"1725","10.31400","0.85965","0.00006"
"1734","10.36800","0.86414","-0.00013"
"1743","10.42200","0.86862","-0.00030"
"1752","10.47600","0.87311","0.00039"
"1761","10.53000","0.87759","0.00023"
"1770","10.58400","0.88208","-0.00012"
"1779","10.63800","0.88662","0.00012"
"1788","10.69200","0.89116","-0.00002"
"1797","10.74600","0.89565","-0.00002"
"1806","10.80000","0.90019","-0.00041"
"1815","10.85400","0.90462","0.00004"
"1824","10.90800","0.90916","-0.00024"
"1833","10.96200","0.91364","-0.00060"
"1842","11.01600","0.91813","-0.00008"
"1851","11.07000","0.92267","-0.00009"
"1860","11.12400","0.92710","0.00016"
"1869","11.17800","0.93158","-0.00040"
"1878","11.23200","0.93612","-0.00001"
"1887","11.28600","0.94061","-0.00003"
"1896","11.34000","0.94521","0.00040"
"1905","11.39400","0.94964","0.00050"
"1914","11.44800","0.95412","-0.00017"
"1923","11.50200","0.95867","0.00026"
"1932","11.55600","0.96309","-0.00001"
"1941","11.61000","0.96757","0.00000"
"1950","11.66400","0.97206","0.00013"
"1959","11.71800","0.97660","0.00041"
"1968","11.77200","0.98115","0.00033"
"1977","11.82600","0.98563","0.00015"
"1986","11.88000","0.99011","0.00003"
"1995","11.93400","0.99466","0.00000"
"2004","11.98800","0.99914","0.00036"
"2013","12.04200","1.00363","-0.00018"
"2022","12.09600","1.00811","0.00011"
"2031","12.15000","1.01260","0.00002"
"2040","12.20400","1.01708","0.00018"
"2049","12.25800","1.02162","0.00011"
"2058","12.31200","1.02617","0.00044"
"2067","12.36600","1.03065","0.00034"
"2076","12.42000","1.03514","-0.00010"
"2085","12.47400","1.03962","0.00057"
"2094","12.52800","1.04410","0.00024"
"2103","12.58200","1.04859","0.00019"
"2112","12.63600","1.05307","0.00004"
"2121","12.69000","1.05756","-0.00005"
"2130","12.74400","1.06204","-0.00005"
"2139","12.79800","1.06665","0.00008"
"2148","12.85200","1.07113","0.00033"
"2157","12.90600","1.07561","0.00031"
"2166","12.96000","1.08016","0.00016"
"2175","13.01400","1.08464","0.00032"
"2184","13.06800","1.08919","-0.00010"
"2193","13.12200","1.09367","0.00015"
"2202","13.17600","1.09809","-0.00013"
"2211","13.23000","1.10258","-0.00035"
"2220","13.28400","1.10700","0.00019"
"2229","13.33800","1.11161","0.00016"
"2238","13.39200","1.11615","0.00003"
"2247","13.44600","1.12064","0.00025"
"2256","13.50000","1.12518","0.00002"
"2265","13.55400","1.12960","0.00029"
"2274","13.60800","1.13415","0.00008"
"2283","13.66200","1.13869","0.00015"
"2292","13.71600","1.14312","-0.00010"
"2301","13.77000","1.14760","0.00031"
"2310","13.82400","1.15202","0.00047"
"2319","13.87800","1.15657","-0.00014"
"2328","13.93200","1.16117","-0.00028"
"2337","13.98600","1.16566","0.00048"
"2346","14.04000","1.17014","0.00000"
"2355","14.09400","1.17469","-0.00013"
"2364","14.14800","1.17917","-0.00016"
"2373","14.20200","1.18365","-0.00004"
"2382","14.25600","1.18814","0.00001"
"2391","14.31000","1.19262","-0.00003"
"2400","14.36400","1.19705","-0.00020"
"2409","14.41800","1.20159","0.00016"
"2418","14.47200","1.20613","0.00060"
"2427","14.52600","1.21062","0.00005"
"2436","14.58000","1.21516","-0.00009"
"2445","14.63400","1.21965","0.00031"
"2454","14.68800","1.22413","-0.00019"
"2463","14.74200","1.22862","0.00071"
"2472","14.79600","1.23310","-0.00007"
"2481","14.85000","1.23758","0.00026"
"2490","14.90400","1.24207","-0.00014"
"2499","14.95800","1.24655","-0.00003"
"2508","15.01200","1.25110","-0.00021"
"2517","15.06600","1.25564","0.00006"
"2526","15.12000","1.26012","-0.00006"
"2535","15.17400","1.26467","-0.00019"
"2544","15.22800","1.26921","0.00021"
"2553","15.28200","1.27364","0.00025"
"2562","15.33600","1.27812","0.00004"
"2571","15.39000","1.28261","0.00034"
"2580","15.44400","1.28703","0.00022"
"2589","15.49800","1.29163","0.00042"
"2598","15.55200","1.29612","-0.00006"
"2607","15.60600","1.30066","-0.00003"
"2616","15.66000","1.30521","0.00012"
"2625","15.71400","1.30963","-0.00002"
"2634","15.76800","1.31417","0.00032"
"2643","15.82200","1.31866","0.00041"
"2652","15.87600","1.32308","0.00034"
"2661","15.93000","1.32763","0.00029"
"2670","15.98400","1.33211","0.00033"
"2679","16.03800","1.33654","0.00024"
"2688","16.09200","1.34114","0.00000"
"2697","16.14600","1.34562","0.00028"
"2706","16.20000","1.35011","0.00039"
"2715","16.25400","1.35465","0.00060"
"2724","16.30800","1.35914","0.00020"
"2733","16.36200","1.36368","0.00041"
"2742","16.41600","1.36816","0.00046"
"2751","16.47000","1.37259","0.00057"
"2760","16.52400","1.37713","0.00027"
"2769","16.57800","1.38156","0.00031"
"2778","16.63200","1.38610","0.00046"
"2787","16.68600","1.39064","0.00045"
"2796","16.74000","1.39507","0.00029"
"2805","16.79400","1.39967","0.00022"
"2814","16.84800","1.40416","0.00007"
"2823","16.90200","1.40858","0.00013"
"2832","16.95600","1.41313","0.00030"
"2841","17.01000","1.41755","0.00057"
"2850","17.06400","1.42203","0.00028"
"2859","17.11800","1.42658","0.00022"
"2868","17.17200","1.43112","0.00029"
"2877","17.22600","1.43567","0.00043"
"2886","17.28000","1.44009","0.00013"
"2895","17.33400","1.44457","0.00019"
"2904","17.38800","1.44912","0.00016"
"2913","17.44200","1.45360","0.00046"
"2922","17.49600","1.45809","0.00020"
"2931","17.55000","1.46257","0.00028"
"2940","17.60400","1.46706","0.00067"
"2949","17.65800","1.47160","0.00022"
"2958","17.71200","1.47614","0.00046"
"2967","17.76600","1.48063","0.00056"
"2976","17.82000","1.48517","0.00014"
"2985","17.87400","1.48966","0.00024"
"2994","17.92800","1.49414","0.00016"
"3003","17.98200","1.49862","0.00042"
"3012","18.03600","1.50311","0.00032"
"3021","18.09000","1.50765","0.00035"
"3030","18.14400","1.51214","0.00026"
"3039","18.19800","1.51662","0.00013"
"3048","18.25200","1.52117","0.00040"
"3057","18.30600","1.52565","0.00044"
"3066","18.36000","1.53013","0.00020"
"3075","18.41400","1.53462","0.00037"
"3084","18.46800","1.53916","0.00072"
"3093","18.52200","1.54365","0.00028"
"3102","18.57600","1.54813","0.00040"
"3111","18.63000","1.55261","0.00031"
"3120","18.68400","1.55716","0.00039"
"3129","18.73800","1.56164","0.00026"
"3138","18.79200","1.56613","0.00051"
"3147","18.84600","1.57067","0.00046"
"3156","18.90000","1.57510","0.00052"
"3165","18.95400","1.57964","0.00031"
"3174","19.00800","1.58412","-0.00004"
"3183","19.06200","1.58861","0.00068"
"3192","19.11600","1.59315","0.00002"
"3201","19.17000","1.59758","-0.00013"
"3210","19.22400","1.60212","0.00074"
"3219","19.27800","1.60660","0.00067"
"3228","19.33200","1.61115","0.00028"
"3237","19.38600","1.61575","0.00005"
"3246","19.44000","1.62018","0.00056"
"3255","19.49400","1.62466","0.00028"
"3264","19.54800","1.62915","0.00036"
"3273","19.60200","1.63363","0.00063"
"3282","19.65600","1.63811","0.00022"
"3291","19.71000","1.64260","0.00044"
"3300","19.76400","1.64708","0.00042"
"3309","19.81800","1.65163","0.00031"
"3318","19.87200","1.65611","0.00035"
"3327","19.92600","1.66065","0.00063"
"3336","19.98000","1.66514","0.00057"
"3345","20.03400","1.66968","0.00044"
"3354","20.08800","1.67417","0.00089"
"3363","20.14200","1.67865","0.00052"
"3372","20.19600","1.68314","0.00048"
"3381","20.25000","1.68762","0.00048"
"3390","20.30400","1.69210","0.00046"
"3399","20.35800","1.69665","0.00048"
"3408","20.41200","1.70119","0.00077"
"3417","20.46600","1.70562","0.00041"
"3426","20.52000","1.71016","0.00076"
"3435","20.57400","1.71464","0.00035"
"3444","20.62800","1.71913","0.00042"
"3453","20.68200","1.72367","0.00050"
"3462","20.73600","1.72810","0.00012"
"3471","20.79000","1.73258","0.00057"
"3480","20.84400","1.73713","0.00059"
"3489","20.89800","1.74155","0.00097"
"3498","20.95200","1.74615","0.00056"
"3507","21.00600","1.75064","0.00099"
"3516","21.06000","1.75512","0.00055"
"3525","21.11400","1.75967","0.00054"
"3534","21.16800","1.76415","0.00060"
"3543","21.22200","1.76857","0.00067"
"3552","21.27600","1.77306","0.00037"
"3561","21.33000","1.77754","0.00020"
"3570","21.38400","1.78209","0.00035"
"3579","21.43800","1.78663","0.00070"
"3588","21.49200","1.79112","0.00056"
"3597","21.54600","1.79572","0.00074"
"3606","21.60000","1.80014","0.00081"
"3615","21.65400","1.80463","0.00081"
"3624","21.70800","1.80917","0.00071"
"3633","21.76200","1.81360","0.00084"
"3642","21.81600","1.81808","0.00072"
"3651","21.87000","1.82256","0.00089"
"3660","21.92400","1.82705","0.00057"
"3669","21.97800","1.83159","0.00084"
"3678","22.03200","1.83614","0.00098"
"3687","22.08600","1.84062","0.00066"
"3696","22.14000","1.84510","0.00078"
"3705","22.19400","1.84965","0.00091"
"3714","22.24800","1.85413","0.00082"
"3723","22.30200","1.85862","0.00086"
"3732","22.35600","1.86310","0.00078"
"3741","22.41000","1.86759","0.00076"
"3750","22.46400","1.87207","0.00096"
"3759","22.51800","1.87661","0.00085"
"3768","22.57200","1.88116","0.00033"
"3777","22.62600","1.88564","0.00081"
"3786","22.68000","1.89019","0.00055"
"3795","22.73400","1.89467","0.00092"
"3804","22.78800","1.89909","0.00072"
"3813","22.84200","1.90364","0.00094"
"3822","22.89600","1.90812","0.00089"
"3831","22.95000","1.91261","0.00053"
"3840","23.00400","1.91709","0.00074"
"3849","23.05800","1.92158","0.00107"
"3858","23.11200","1.92618","0.00090"
"3867","23.16600","1.93066","0.00084"
"3876","23.22000","1.93509","0.00065"
"3885","23.27400","1.93963","0.00080"
"3894","23.32800","1.94412","0.00097"
"3903","23.38200","1.94860","0.00067"
"3912","23.43600","1.95308","0.00109"
"3921","23.49000","1.95757","0.00109"
"3930","23.54400","1.96211","0.00080"
"3939","23.59800","1.96660","0.00077"
"3948","23.65200","1.97108","0.00064"
"3957","23.70600","1.97569","0.00084"
"3966","23.76000","1.98017","0.00089"
"3975","23.81400","1.98465","0.00055"
"3984","23.86800","1.98914","0.00076"
"3993","23.92200","1.99362","0.00075"
"4002","23.97600","1.99811","0.00139"
"4011","24.03000","2.00259","0.00064"
"4020","24.08400","2.00707","0.00046"
"4029","24.13800","2.01168","0.00066"
"4038","24.19200","2.01616","0.00104"
"4047","24.24600","2.02071","0.00110"
"4056","24.30000","2.02513","0.00110"
"4065","24.35400","2.02962","0.00092"
"4074","24.40800","2.03422","0.00079"
"4083","24.46200","2.03864","0.00067"
"4092","24.51600","2.04313","0.00090"
"4101","24.57000","2.04761","0.00122"
"4110","24.62400","2.05210","0.00086"
"4119","24.67800","2.05664","0.00068"
"4128","24.73200","2.06118","0.00074"
"4137","24.78600","2.06561","0.00088"
"4146","24.84000","2.07021","0.00088"
"4155","24.89400","2.07464","0.00085"
"4164","24.94800","2.07912","0.00100"
"4173","25.00200","2.08367","0.00110"
"4182","25.05600","2.08809","0.00066"
"4191","25.11000","2.09257","0.00085"
"4200","25.16400","2.09706","0.00104"
"4209","25.21800","2.10154","0.00099"
"4218","25.27200","2.10615","0.00091"
"4227","25.32600","2.11063","0.00062"
"4236","25.38000","2.11511","0.00062"
"4245","25.43400","2.11966","0.00143"
"4254","25.48800","2.12414","0.00130"
"4263","25.54200","2.12863","0.00080"
"4272","25.59600","2.13311","0.00103"
"4281","25.65000","2.13754","0.00089"
"4290","25.70400","2.14214","0.00099"
"4299","25.75800","2.14662","0.00121"
"4308","25.81200","2.15111","0.00119"
"4317","25.86600","2.15571","0.00099"
"4326","25.92000","2.16014","0.00080"
"4335","25.97400","2.16468","0.00127"
"4344","26.02800","2.16910","0.00134"
"4353","26.08200","2.17359","0.00072"
"4362","26.13600","2.17813","0.00099"
"4371","26.19000","2.18262","0.00072"
"4380","26.24400","2.18710","0.00104"
"4389","26.29800","2.19165","0.00045"
"4398","26.35200","2.19613","0.00072"
"4407","26.40600","2.20067","0.00081"
"4416","26.46000","2.20510","0.00099"
"4425","26.51400","2.20958","0.00126"
"4434","26.56800","2.21419","0.00092"
"4443","26.62200","2.21861","0.00065"
"4452","26.67600","2.22309","0.00056"
"4461","26.73000","2.22764","0.00126"
"4470","26.78400","2.23206","0.00097"
"4479","26.83800","2.23661","0.00108"
"4488","26.89200","2.24115","0.00062"
"4497","26.94600","2.24564","0.00114"
"4506","27.00000","2.25018","0.00127"
"4515","27.05400","2.25466","0.00072"
"4524","27.10800","2.25915","0.00110"
"4533","27.16200","2.26363","0.00150"
"4542","27.21600","2.26812","0.00110"
"4551","27.27000","2.27260","0.00106"
"4560","27.32400","2.27708","0.00054"
"4569","27.37800","2.28163","0.00120"
"4578","27.43200","2.28611","0.00120"
"4587","27.48600","2.29060","0.00102"
"4596","27.54000","2.29508","0.00142"
"4605","27.59400","2.29957","0.00128"
"4614","27.64800","2.30411","0.00117"
"4623","27.70200","2.30859","0.00116"
"4632","27.75600","2.31308","0.00103"
"4641","27.81000","2.31756","0.00100"
"4650","27.86400","2.32205","0.00110"
"4659","27.91800","2.32665","0.00126"
"4668","27.97200","2.33113","0.00055"
"4677","28.02600","2.33562","0.00119"
"4686","28.08000","2.34016","0.00108"
"4695","28.13400","2.34465","0.00115"
"4704","28.18800","2.34907","0.00087"
"4713","28.24200","2.35356","0.00133"
"4722","28.29600","2.35810","0.00089"
"4731","28.35000","2.36258","0.00131"
"4740","28.40400","2.36713","0.00126"
"4749","28.45800","2.37161","0.00084"
"4758","28.51200","2.37610","0.00097"
"4767","28.56600","2.38064","0.00151"
"4776","28.62000","2.38512","0.00116"
"4785","28.67400","2.38961","0.00068"
"4794","28.72800","2.39415","0.00140"
"4803","28.78200","2.39852","0.00126"
"4812","28.83600","2.40306","0.00101"
"4821","28.89000","2.40760","0.00150"
"4830","28.94400","2.41209","0.00112"
"4839","28.99800","2.41669","0.00132"
"4848","29.05200","2.42112","0.00108"
"4857","29.10600","2.42560","0.00135"
"4866","29.16000","2.43021","0.00136"
"4875","29.21400","2.43463","0.00107"
"4884","29.26800","2.43911","0.00125"
"4893","29.32200","2.44360","0.00169"
"4902","29.37600","2.44802","0.00112"
"4911","29.43000","2.45257","0.00123"
"4920","29.48400","2.45711","0.00155"
"4929","29.53800","2.46165","0.00135"
"4938","29.59200","2.46620","0.00108"
"4947","29.64600","2.47062","0.00146"
"4956","29.70000","2.47517","0.00151"
"4965","29.75400","2.47965","0.00144"
"4974","29.80800","2.48414","0.00173"
"4983","29.86200","2.48862","0.00134"
"4992","29.91600","2.49310","0.00170"
"5001","29.97000","2.49753","0.00177"
"5010","30.02400","2.50207","0.00161"
"5019","30.07800","2.50662","0.00141"
"5028","30.13200","2.51116","0.00136"
"5037","30.18600","2.51558","0.00129"
"5046","30.24000","2.52013","0.00161"
"5055","30.29400","2.52467","0.00114"
"5064","30.34800","2.52916","0.00128"
"5073","30.40200","2.53358","0.00156"
"5082","30.45600","2.53813","0.00141"
"5091","30.51000","2.54255","0.00170"
"5100","30.56400","2.54715","0.00114"
"5109","30.61800","2.55164","0.00135"
"5118","30.67200","2.55612","0.00160"
"5127","30.72600","2.56073","0.00161"
"5136","30.78000","2.56515","0.00101"
"5145","30.83400","2.56963","0.00133"
"5154","30.88800","2.57418","0.00173"
"5163","30.94200","2.57860","0.00163"
"5172","30.99600","2.58309","0.00145"
"5181","31.05000","2.58757","0.00168"
"5190","31.10400","2.59206","0.00184"
"5199","31.15800","2.59660","0.00133"
"5208","31.21200","2.60120","0.00130"
"5217","31.26600","2.60563","0.00153"
"5226","31.32000","2.61017","0.00135"
"5235","31.37400","2.61466","0.00110"
"5244","31.42800","2.61914","0.00189"
"5253","31.48200","2.62362","0.00171"
"5262","31.53600","2.62811","0.00171"
"5271","31.59000","2.63259","0.00127"
"5280","31.64400","2.63714","0.00140"
"5289","31.69800","2.64156","0.00142"
"5298","31.75200","2.64611","0.00170"
"5307","31.80600","2.65059","0.00183"
"5316","31.86000","2.65513","0.00172"
"5325","31.91400","2.65962","0.00182"
"5334","31.96800","2.66410","0.00200"
"5343","32.02200","2.66859","0.00170"
"5352","32.07600","2.67307","0.00181"
"5361","32.13000","2.67761","0.00129"
"5370","32.18400","2.68216","0.00172"
"5379","32.23800","2.68658","0.00195"
"5388","32.29200","2.69119","0.00187"
"5397","32.34600","2.69561","0.00169"
"5406","32.40000","2.70016","0.00173"
"5415","32.45400","2.70470","0.00187"
"5424","32.50800","2.70912","0.00215"
"5433","32.56200","2.71361","0.00156"
"5442","32.61600","2.71809","0.00167"
"5451","32.67000","2.72252","0.00172"
"5460","32.72400","2.72712","0.00168"
"5469","32.77800","2.73160","0.00172"
"5478","32.83200","2.73615","0.00212"
"5487","32.88600","2.74069","0.00197"
"5496","32.94000","2.74518","0.00205"
"5505","32.99400","2.74966","0.00193"
"5514","33.04800","2.75414","0.00159"
"5523","33.10200","2.75857","0.00171"
"5532","33.15600","2.76311","0.00178"
"5541","33.21000","2.76760","0.00157"
"5550","33.26400","2.77208","0.00174"
"5559","33.31800","2.77663","0.00185"
"5568","33.37200","2.78111","0.00216"
"5577","33.42600","2.78565","0.00186"
"5586","33.48000","2.79020","0.00188"
"5595","33.53400","2.79462","0.00190"
"5604","33.58800","2.79917","0.00168"
"5613","33.64200","2.80359","0.00193"
"5622","33.69600","2.80808","0.00184"
"5631","33.75000","2.81262","0.00187"
"5640","33.80400","2.81710","0.00220"
"5649","33.85800","2.82165","0.00215"
"5658","33.91200","2.82613","0.00168"
"5667","33.96600","2.83062","0.00206"
"5676","34.02000","2.83516","0.00213"
"5685","34.07400","2.83964","0.00214"
"5694","34.12800","2.84413","0.00185"
"5703","34.18200","2.84861","0.00166"
"5712","34.23600","2.85304","0.00175"
"5721","34.29000","2.85758","0.00169"
"5730","34.34400","2.86218","0.00188"
"5739","34.39800","2.86661","0.00194"
"5748","34.45200","2.87121","0.00217"
"5757","34.50600","2.87564","0.00202"
"5766","34.56000","2.88012","0.00204"
"5775","34.61400","2.88467","0.00196"
"5784","34.66800","2.88909","0.00169"
"5793","34.72200","2.89357","0.00181"
"5802","34.77600","2.89806","0.00194"
"5811","34.83000","2.90254","0.00194"
"5820","34.88400","2.90709","0.00181"
"5829","34.93800","2.91163","0.00249"
"5838","34.99200","2.91617","0.00172"
"5847","35.04600","2.92066","0.00249"
"5856","35.10000","2.92520","0.00190"
"5865","35.15400","2.92963","0.00223"
"5874","35.20800","2.93411","0.00241"
"5883","35.26200","2.93866","0.00204"
"5892","35.31600","2.94308","0.00234"
"5901","35.37000","2.94762","0.00229"
"5910","35.42400","2.95211","0.00211"
"5919","35.47800","2.95659","0.00228"
"5928","35.53200","2.96120","0.00233"
"5937","35.58600","2.96562","0.00203"
"5946","35.64000","2.97010","0.00246"
"5955","35.69400","2.97465","0.00247"
"5964","35.74800","2.97913","0.00229"
"5973","35.80200","2.98362","0.00240"
"5982","35.85600","2.98810","0.00267"
"5991","35.91000","2.99259","0.00238"
"6000","35.96400","2.99713","0.00222"
"6009","36.01800","3.00167","0.00257"
"6018","36.07200","3.00616","0.00263"
"6027","36.12600","3.01058","0.00212"
"6036","36.18000","3.01513","0.00262"
"6045","36.23400","3.01961","0.00259"
"6054","36.28800","3.02410","0.00240"
"6063","36.34200","3.02864","0.00241"
"6072","36.39600","3.03306","0.00219"
"6081","36.45000","3.03761","0.00195"
"6090","36.50400","3.04209","0.00233"
"6099","36.55800","3.04658","0.00213"
"6108","36.61200","3.05118","0.00225"
"6117","36.66600","3.05560","0.00242"
"6126","36.72000","3.06015","0.00258"
"6135","36.77400","3.06463","0.00241"
"6144","36.82800","3.06906","0.00248"
"6153","36.88200","3.07360","0.00293"
"6162","36.93600","3.07808","0.00246"
"6171","36.99000","3.08257","0.00232"
"6180","37.04400","3.08717","0.00225"
"6189","37.09800","3.09166","0.00250"
"6198","37.15200","3.09614","0.00246"
"6207","37.20600","3.10063","0.00255"
"6216","37.26000","3.10517","0.00303"
"6225","37.31400","3.10971","0.00256"
"6234","37.36800","3.11414","0.00268"
"6243","37.42200","3.11856","0.00255"
"6252","37.47600","3.12311","0.00302"
"6261","37.53000","3.12759","0.00244"
"6270","37.58400","3.13213","0.00293"
"6279","37.63800","3.13668","0.00214"
"6288","37.69200","3.14116","0.00300"
"6297","37.74600","3.14565","0.00215"
"6306","37.80000","3.15013","0.00251"
"6315","37.85400","3.15468","0.00237"
"6324","37.90800","3.15916","0.00248"
"6333","37.96200","3.16358","0.00244"
"6342","38.01600","3.16807","0.00267"
"6351","38.07000","3.17261","0.00207"
"6360","38.12400","3.17710","0.00247"
"6369","38.17800","3.18164","0.00285"
"6378","38.23200","3.18612","0.00252"
"6387","38.28600","3.19061","0.00277"
"6396","38.34000","3.19515","0.00229"
"6405","38.39400","3.19958","0.00275"
"6414","38.44800","3.20406","0.00249"
"6423","38.50200","3.20861","0.00268"
"6432","38.55600","3.21303","0.00236"
"6441","38.61000","3.21757","0.00283"
"6450","38.66400","3.22212","0.00291"
"6459","38.71800","3.22660","0.00251"
"6468","38.77200","3.23115","0.00246"
"6477","38.82600","3.23569","0.00253"
"6486","38.88000","3.24017","0.00257"
"6495","38.93400","3.24466","0.00266"
"6504","38.98800","3.24914","0.00288"
"6513","39.04200","3.25363","0.00242"
"6522","39.09600","3.25811","0.00251"
"6531","39.15000","3.26260","0.00260"
"6540","39.20400","3.26714","0.00264"
"6549","39.25800","3.27162","0.00312"
"6558","39.31200","3.27611","0.00301"
"6567","39.36600","3.28065","0.00276"
"6576","39.42000","3.28514","0.00289"
"6585","39.47400","3.28968","0.00319"
"6594","39.52800","3.29416","0.00285"
"6603","39.58200","3.29859","0.00296"
"6612","39.63600","3.30307","0.00280"
"6621","39.69000","3.30756","0.00302"
"6630","39.74400","3.31216","0.00298"
"6639","39.79800","3.31670","0.00266"
"6648","39.85200","3.32113","0.00273"
"6657","39.90600","3.32567","0.00258"
"6666","39.96000","3.33010","0.00285"
"6675","40.01400","3.33464","0.00254"
"6684","40.06800","3.33913","0.00276"
"6693","40.12200","3.34355","0.00257"
"6702","40.17600","3.34809","0.00322"
"6711","40.23000","3.35258","0.00266"
"6720","40.28400","3.35706","0.00280"
"6729","40.33800","3.36167","0.00270"
"6738","40.39200","3.36609","0.00288"
"6747","40.44600","3.37063","0.00305"
"6756","40.50000","3.37512","0.00321"
"6765","40.55400","3.37960","0.00281"
"6774","40.60800","3.38415","0.00351"
"6783","40.66200","3.38857","0.00270"
"6792","40.71600","3.39306","0.00314"
"6801","40.77000","3.39760","0.00303"
"6810","40.82400","3.40208","0.00317"
"6819","40.87800","3.40663","0.00272"
"6828","40.93200","3.41117","0.00295"
"6837","40.98600","3.41566","0.00305"
"6846","41.04000","3.42020","0.00306"
"6855","41.09400","3.42468","0.00273"
"6864","41.14800","3.42911","0.00307"
"6873","41.20200","3.43359","0.00291"
"6882","41.25600","3.43808","0.00282"
"6891","41.31000","3.44256","0.00324"
"6900","41.36400","3.44717","0.00330"
"6909","41.41800","3.45165","0.00332"
"6918","41.47200","3.45619","0.00292"
"6927","41.52600","3.46068","0.00277"
"6936","41.58000","3.46516","0.00339"
"6945","41.63400","3.46965","0.00313"
"6954","41.68800","3.47407","0.00356"
"6963","41.74200","3.47862","0.00285"
"6972","41.79600","3.48310","0.00336"
"6981","41.85000","3.48758","0.00321"
"6990","41.90400","3.49213","0.00357"
"6999","41.95800","3.49661","0.00350"
"7008","42.01200","3.50110","0.00346"
"7017","42.06600","3.50570","0.00299"
"7026","42.12000","3.51018","0.00371"
"7035","42.17400","3.51461","0.00289"
"7044","42.22800","3.51909","0.00357"
"7053","42.28200","3.52358","0.00287"
"7062","42.33600","3.52812","0.00309"
"7071","42.39000","3.53260","0.00379"
"7080","42.44400","3.53709","0.00366"
"7089","42.49800","3.54163","0.00302"
"7098","42.55200","3.54612","0.00345"
"7107","42.60600","3.55060","0.00332"
"7116","42.66000","3.55515","0.00305"
"7125","42.71400","3.55963","0.00343"
"7134","42.76800","3.56411","0.00332"
"7143","42.82200","3.56860","0.00360"
"7152","42.87600","3.57308","0.00340"
"7161","42.93000","3.57757","0.00299"
"7170","42.98400","3.58211","0.00360"
"7179","43.03800","3.58660","0.00357"
"7188","43.09200","3.59114","0.00333"
"7197","43.14600","3.59568","0.00350"
"7206","43.20000","3.60011","0.00310"
"7215","43.25400","3.60465","0.00334"
"7224","43.30800","3.60914","0.00316"
"7233","43.36200","3.61356","0.00356"
"7242","43.41600","3.61810","0.00300"
"7251","43.47000","3.62259","0.00342"
"7260","43.52400","3.62713","0.00361"
"7269","43.57800","3.63162","0.00320"
"7278","43.63200","3.63616","0.00329"
"7287","43.68600","3.64064","0.00382"
"7296","43.74000","3.64513","0.00357"
"7305","43.79400","3.64967","0.00383"
"7314","43.84800","3.65410","0.00332"
"7323","43.90200","3.65864","0.00369"
"7332","43.95600","3.66313","0.00367"
"7341","44.01000","3.66755","0.00365"
"7350","44.06400","3.67215","0.00361"
"7359","44.11800","3.67664","0.00354"
"7368","44.17200","3.68112","0.00383"
"7377","44.22600","3.68567","0.00366"
"7386","44.28000","3.69015","0.00355"
"7395","44.33400","3.69463","0.00369"
"7404","44.38800","3.69912","0.00354"
"7413","44.44200","3.70360","0.00394"
"7422","44.49600","3.70809","0.00371"
"7431","44.55000","3.71257","0.00361"
"7440","44.60400","3.71712","0.00425"
"7449","44.65800","3.72166","0.00351"
"7458","44.71200","3.72608","0.00381"
"7467","44.76600","3.73063","0.00414"
"7476","44.82000","3.73511","0.00355"
"7485","44.87400","3.73954","0.00382"
"7494","44.92800","3.74414","0.00397"
"7503","44.98200","3.74856","0.00404"
"7512","45.03600","3.75305","0.00358"
"7521","45.09000","3.75765","0.00357"
"7530","45.14400","3.76214","0.00411"
"7539","45.19800","3.76668","0.00381"
"7548","45.25200","3.77116","0.00377"
"7557","45.30600","3.77565","0.00422"
"7566","45.36000","3.78019","0.00379"
"7575","45.41400","3.78462","0.00373"
"7584","45.46800","3.78910","0.00393"
"7593","45.52200","3.79365","0.00389"
"7602","45.57600","3.79807","0.00430"
"7611","45.63000","3.80261","0.00367"
"7620","45.68400","3.80710","0.00371"
"7629","45.73800","3.81164","0.00337"
"7638","45.79200","3.81613","0.00376"
"7647","45.84600","3.82061","0.00408"
"7656","45.90000","3.82515","0.00392"
"7665","45.95400","3.82964","0.00363"
"7674","46.00800","3.83406","0.00411"
"7683","46.06200","3.83861","0.00389"
"7692","46.11600","3.84309","0.00398"
"7701","46.17000","3.84758","0.00410"
"7710","46.22400","3.85218","0.00391"
"7719","46.27800","3.85666","0.00394"
"7728","46.33200","3.86115","0.00398"
"7737","46.38600","3.86569","0.00376"
"7746","46.44000","3.87012","0.00376"
"7755","46.49400","3.87466","0.00318"
"7764","46.54800","3.87914","0.00248"
"7773","46.60200","3.88357","0.00301"
"7782","46.65600","3.88805","0.00306"
"7791","46.71000","3.89260","0.00280"
"7800","46.76400","3.89714","0.00279"
"7809","46.81800","3.90169","0.00309"
"7818","46.87200","3.90611","0.00305"
"7827","46.92600","3.91065","0.00262"
"7836","46.98000","3.91514","0.00317"
"7845","47.03400","3.91962","0.00311"
"7854","47.08800","3.92411","0.00299"
"7863","47.14200","3.92859","0.00269"
"7872","47.19600","3.93307","0.00304"
"7881","47.25000","3.93762","0.00307"
"7890","47.30400","3.94210","0.00270"
"7899","47.35800","3.94665","0.00285"
"7908","47.41200","3.95113","0.00337"
"7917","47.46600","3.95568","0.00298"
"7926","47.52000","3.96016","0.00291"
"7935","47.57400","3.96458","0.00305"
"7944","47.62800","3.96907","0.00300"
"7953","47.68200","3.97355","0.00338"
"7962","47.73600","3.97804","0.00327"
"7971","47.79000","3.98264","0.00343"
"7980","47.84400","3.98718","0.00321"
"7989","47.89800","3.99167","0.00350"
"7998","47.95200","3.99615","0.00349"
"8007","48.00600","4.00064","0.00329"
"8016","48.06000","4.00518","0.00343"
"8025","48.11400","4.00967","0.00319"
"8034","48.16800","4.01415","0.00357"
"8043","48.22200","4.01857","0.00341"
"8052","48.27600","4.02312","0.00341"
"8061","48.33000","4.02760","0.00384"
"8070","48.38400","4.03215","0.00337"
"8079","48.43800","4.03669","0.00327"
"8088","48.49200","4.04117","0.00333"
"8097","48.54600","4.04566","0.00346"
"8106","48.60000","4.05014","0.00379"
"8115","48.65400","4.05463","0.00346"
"8124","48.70800","4.05911","0.00333"
"8133","48.76200","4.06360","0.00341"
"8142","48.81600","4.06808","0.00341"
"8151","48.87000","4.07256","0.00377"
"8160","48.92400","4.07711","0.00364"
"8169","48.97800","4.08165","0.00337"
"8178","49.03200","4.08614","0.00323"
"8187","49.08600","4.09068","0.00365"
"8196","49.14000","4.09510","0.00392"
"8205","49.19400","4.09959","0.00404"
"8214","49.24800","4.10407","0.00372"
"8223","49.30200","4.10856","0.00355"
"8232","49.35600","4.11310","0.00376"
"8241","49.41000","4.11759","0.00346"
"8250","49.46400","4.12213","0.00357"
"8259","49.51800","4.12667","0.00358"
"8268","49.57200","4.13110","0.00369"
"8277","49.62600","4.13564","0.00395"
"8286","49.68000","4.14019","0.00367"
"8295","49.73400","4.14461","0.00370"
"8304","49.78800","4.14909","0.00421"
"8313","49.84200","4.15364","0.00351"
"8322","49.89600","4.15806","0.00406"
"8331","49.95000","4.16261","0.00377"
"8340","50.00400","4.16709","0.00416"
"8349","50.05800","4.17164","0.00372"
"8358","50.11200","4.17618","0.00395"
"8367","50.16600","4.18066","0.00404"
"8376","50.22000","4.18515","0.00389"
"8385","50.27400","4.18963","0.00363"
"8394","50.32800","4.19412","0.00363"
"8403","50.38200","4.19860","0.00415"
"8412","50.43600","4.20308","0.00435"
"8421","50.49000","4.20763","0.00362"
"8430","50.54400","4.21211","0.00390"
"8439","50.59800","4.21666","0.00395"
"8448","50.65200","4.22114","0.00410"
"8457","50.70600","4.22563","0.00427"
"8466","50.76000","4.23011","0.00404"
"8475","50.81400","4.23459","0.00399"
"8484","50.86800","4.23908","0.00430"
"8493","50.92200","4.24356","0.00442"
"8502","50.97600","4.24811","0.00402"
"8511","51.03000","4.25259","0.00427"
"8520","51.08400","4.25713","0.00386"
"8529","51.13800","4.26162","0.00447"
"8538","51.19200","4.26610","0.00403"
"8547","51.24600","4.27071","0.00389"
"8556","51.30000","4.27513","0.00413"
"8565","51.35400","4.27968","0.00407"
"8574","51.40800","4.28416","0.00412"
"8583","51.46200","4.28858","0.00411"
"8592","51.51600","4.29313","0.00420"
"8601","51.57000","4.29761","0.00433"
"8610","51.62400","4.30216","0.00404"
"8619","51.67800","4.30670","0.00407"
"8628","51.73200","4.31112","0.00447"
"8637","51.78600","4.31567","0.00395"
"8646","51.84000","4.32015","0.00390"
"8655","51.89400","4.32464","0.00445"
"8664","51.94800","4.32912","0.00441"
"8673","52.00200","4.33361","0.00433"
"8682","52.05600","4.33809","0.00403"
"8691","52.11000","4.34263","0.00442"
"8700","52.16400","4.34712","0.00423"
"8709","52.21800","4.35166","0.00438"
"8718","52.27200","4.35615","0.00396"
"8727","52.32600","4.36063","0.00436"
"8736","52.38000","4.36511","0.00434"
"8745","52.43400","4.36966","0.00421"
"8754","52.48800","4.37414","0.00424"
"8763","52.54200","4.37863","0.00417"
"8772","52.59600","4.38311","0.00435"
"8781","52.65000","4.38760","0.00435"
"8790","52.70400","4.39214","0.00440"
"8799","52.75800","4.39662","0.00455"
"8808","52.81200","4.40117","0.00431"
"8817","52.86600","4.40565","0.00447"
"8826","52.92000","4.41014","0.00446"
"8835","52.97400","4.41462","0.00408"
"8844","53.02800","4.41904","0.00434"
"8853","53.08200","4.42353","0.00457"
"8862","53.13600","4.42813","0.00455"
"8871","53.19000","4.43256","0.00430"
"8880","53.24400","4.43716","0.00400"
"8889","53.29800","4.44165","0.00457"
"8898","53.35200","4.44607","0.00426"
"8907","53.40600","4.45067","0.00457"
"8916","53.46000","4.45510","0.00456"
"8925","53.51400","4.45964","0.00451"
"8934","53.56800","4.46407","0.00502"
"8943","53.62200","4.46855","0.00475"
"8952","53.67600","4.47315","0.00433"
"8961","53.73000","4.47764","0.00450"
"8970","53.78400","4.48212","0.00483"
"8979","53.83800","4.48673","0.00471"
"8988","53.89200","4.49115","0.00429"
"8997","53.94600","4.49563","0.00469"
"9006","54.00000","4.50012","0.00441"
"9015","54.05400","4.50454","0.00475"
"9024","54.10800","4.50909","0.00452"
"9033","54.16200","4.51357","0.00480"
"9042","54.21600","4.51806","0.00461"
"9051","54.27000","4.52260","0.00482"
"9060","54.32400","4.52708","0.00462"
"9069","54.37800","4.53163","0.00460"
"9078","54.43200","4.53611","0.00495"
"9087","54.48600","4.54060","0.00514"
"9096","54.54000","4.54514","0.00456"
"9105","54.59400","4.54962","0.00513"
"9114","54.64800","4.55405","0.00492"
"9123","54.70200","4.55859","0.00466"
"9132","54.75600","4.56308","0.00525"
"9141","54.81000","4.56762","0.00504"
"9150","54.86400","4.57217","0.00489"
"9159","54.91800","4.57659","0.00523"
"9168","54.97200","4.58119","0.00494"
"9177","55.02600","4.58568","0.00493"
"9186","55.08000","4.59010","0.00492"
"9195","55.13400","4.59465","0.00515"
"9204","55.18800","4.59907","0.00509"
"9213","55.24200","4.60355","0.00496"
"9222","55.29600","4.60810","0.00508"
"9231","55.35000","4.61264","0.00527"
"9240","55.40400","4.61719","0.00503"
"9249","55.45800","4.62161","0.00538"
"9258","55.51200","4.62610","0.00503"
"9267","55.56600","4.63064","0.00486"
"9276","55.62000","4.63512","0.00528"
"9285","55.67400","4.63961","0.00480"
"9294","55.72800","4.64409","0.00481"
"9303","55.78200","4.64858","0.00511"
"9312","55.83600","4.65312","0.00541"
"9321","55.89000","4.65760","0.00527"
"9330","55.94400","4.66215","0.00519"
"9339","55.99800","4.66663","0.00564"
"9348","56.05200","4.67118","0.00503"
"9357","56.10600","4.67566","0.00511"
"9366","56.16000","4.68015","0.00481"
"9375","56.21400","4.68463","0.00503"
"9384","56.26800","4.68905","0.00527"
"9393","56.32200","4.69360","0.00489"
"9402","56.37600","4.69808","0.00516"
"9411","56.43000","4.70263","0.00519"
"9420","56.48400","4.70711","0.00579"
"9429","56.53800","4.71165","0.00555"
"9438","56.59200","4.71614","0.00509"
"9447","56.64600","4.72062","0.00566"
"9456","56.70000","4.72517","0.00516"
"9465","56.75400","4.72959","0.00545"
"9474","56.80800","4.73408","0.00564"
"9483","56.86200","4.73856","0.00521"
"9492","56.91600","4.74304","0.00523"
"9501","56.97000","4.74765","0.00555"
"9510","57.02400","4.75219","0.00540"
"9519","57.07800","4.75668","0.00550"
"9528","57.13200","4.76116","0.00548"
"9537","57.18600","4.76564","0.00568"
"9546","57.24000","4.77013","0.00585"
"9555","57.29400","4.77461","0.00514"
"9564","57.34800","4.77904","0.00577"
"9573","57.40200","4.78358","0.00567"
"9582","57.45600","4.78807","0.00486"
"9591","57.51000","4.79261","0.00559"
"9600","57.56400","4.79721","0.00546"
"9609","57.61800","4.80164","0.00561"
"9618","57.67200","4.80618","0.00516"
"9627","57.72600","4.81067","0.00578"
"9636","57.78000","4.81509","0.00536"
"9645","57.83400","4.81963","0.00600"
"9654","57.88800","4.82406","0.00593"
"9663","57.94200","4.82854","0.00554"
"9672","57.99600","4.83315","0.00557"
"9681","58.05000","4.83757","0.00531"
"9690","58.10400","4.84211","0.00572"
"9699","58.15800","4.84666","0.00551"
"9708","58.21200","4.85114","0.00566"
"9717","58.26600","4.85569","0.00586"
"9726","58.32000","4.86011","0.00594"
"9735","58.37400","4.86460","0.00553"
"9744","58.42800","4.86908","0.00592"
"9753","58.48200","4.87356","0.00558"
"9762","58.53600","4.87811","0.00537"
"9771","58.59000","4.88259","0.00548"
"9780","58.64400","4.88714","0.00591"
"9789","58.69800","4.89162","0.00569"
"9798","58.75200","4.89616","0.00579"
"9807","58.80600","4.90065","0.00559"
"9816","58.86000","4.90513","0.00582"
"9825","58.91400","4.90962","0.00617"
"9834","58.96800","4.91410","0.00609"
"9843","59.02200","4.91859","0.00545"
"9852","59.07600","4.92307","0.00572"
"9861","59.13000","4.92761","0.00588"
"9870","59.18400","4.93216","0.00579"
"9879","59.23800","4.93664","0.00582"
"9888","59.29200","4.94119","0.00589"
"9897","59.34600","4.94567","0.00564"
"9906","59.40000","4.95015","0.00589"
"9915","59.45400","4.95464","0.00563"
"9924","59.50800","4.95906","0.00605"
"9933","59.56200","4.96361","0.00606"
"9942","59.61600","4.96809","0.00610"
"9951","59.67000","4.97258","0.00595"
"9960","59.72400","4.97712","0.00577"
"9969","59.77800","4.98160","0.00619"
"9978","59.83200","4.98615","0.00603"
"9987","59.88600","4.99063","0.00627"
"9996","59.94000","4.99512","0.00639"
"10005","59.99400","4.99960","0.00629"
"10014","60.04800","5.00409","0.00589"
"10023","60.10200","5.00851","0.00631"
"10032","60.15600","5.01311","0.00610"
"10041","60.21000","5.01760","0.00608"
"10050","60.26400","5.02214","0.00590"
"10059","60.31800","5.02663","0.00627"
"10068","60.37200","5.03117","0.00617"
"10077","60.42600","5.03565","0.00627"
"10086","60.48000","5.04014","0.00595"
"10095","60.53400","5.04462","0.00640"
"10104","60.58800","5.04911","0.00616"
"10113","60.64200","5.05359","0.00661"
"10122","60.69600","5.05813","0.00609"
"10131","60.75000","5.06262","0.00623"
"10140","60.80400","5.06710","0.00553"
"10149","60.85800","5.07165","0.00617"
"10158","60.91200","5.07613","0.00607"
"10167","60.96600","5.08062","0.00586"
"10176","61.02000","5.08516","0.00604"
"10185","61.07400","5.08958","0.00583"
"10194","61.12800","5.09413","0.00557"
"10203","61.18200","5.09861","0.00542"
"10212","61.23600","5.10310","0.00605"
"10221","61.29000","5.10764","0.00574"
"10230","61.34400","5.11218","0.00572"
"10239","61.39800","5.11661","0.00652"
"10248","61.45200","5.12115","0.00606"
"10257","61.50600","5.12564","0.00595"
"10266","61.56000","5.13012","0.00608"
"10275","61.61400","5.13461","0.00596"
"10284","61.66800","5.13909","0.00571"
"10293","61.72200","5.14363","0.00618"
"10302","61.77600","5.14812","0.00591"
"10311","61.83000","5.15266","0.00619"
"10320","61.88400","5.15721","0.00568"
"10329","61.93800","5.16163","0.00569"
"10338","61.99200","5.16617","0.00602"
"10347","62.04600","5.17060","0.00599"
"10356","62.10000","5.17508","0.00578"
"10365","62.15400","5.17963","0.00599"
"10374","62.20800","5.18411","0.00583"
"10383","62.26200","5.18860","0.00549"
"10392","62.31600","5.19308","0.00630"
"10401","62.37000","5.19762","0.00623"
"10410","62.42400","5.20217","0.00621"
"10419","62.47800","5.20665","0.00613"
"10428","62.53200","5.21114","0.00600"
"10437","62.58600","5.21568","0.00608"
"10446","62.64000","5.22010","0.00581"
"10455","62.69400","5.22459","0.00612"
"10464","62.74800","5.22913","0.00627"
"10473","62.80200","5.23356","0.00640"
"10482","62.85600","5.23816","0.00638"
"10491","62.91000","5.24265","0.00609"
"10500","62.96400","5.24713","0.00574"
"10509","63.01800","5.25173","0.00659"
"10518","63.07200","5.25616","0.00634"
"10527","63.12600","5.26064","0.00653"
"10536","63.18000","5.26513","0.00595"
"10545","63.23400","5.26961","0.00640"
"10554","63.28800","5.27409","0.00602"
"10563","63.34200","5.27858","0.00620"
"10572","63.39600","5.28312","0.00620"
"10581","63.45000","5.28761","0.00581"
"10590","63.50400","5.29215","0.00622"
"10599","63.55800","5.29664","0.00589"
"10608","63.61200","5.30112","0.00671"
"10617","63.66600","5.30566","0.00647"
"10626","63.72000","5.31009","0.00640"
"10635","63.77400","5.31457","0.00641"
"10644","63.82800","5.31912","0.00640"
"10653","63.88200","5.32354","0.00656"
"10662","63.93600","5.32814","0.00700"
"10671","63.99000","5.33263","0.00633"
"10680","64.04400","5.33717","0.00652"
"10689","64.09800","5.34166","0.00622"
"10698","64.15200","5.34614","0.00683"
"10707","64.20600","5.35063","0.00610"
"10716","64.26000","5.35511","0.00606"
"10725","64.31400","5.35959","0.00633"
"10734","64.36800","5.36408","0.00628"
"10743","64.42200","5.36856","0.00591"
"10752","64.47600","5.37311","0.00640"
"10761","64.53000","5.37765","0.00623"
"10770","64.58400","5.38219","0.00621"
"10779","64.63800","5.38662","0.00669"
"10788","64.69200","5.39116","0.00667"
"10797","64.74600","5.39565","0.00626"
"10806","64.80000","5.40007","0.00621"
"10815","64.85400","5.40456","0.00644"
"10824","64.90800","5.40910","0.00651"
"10833","64.96200","5.41352","0.00652"
"10842","65.01600","5.41813","0.00645"
"10851","65.07000","5.42267","0.00643"
"10860","65.12400","5.42716","0.00633"
"10869","65.17800","5.43164","0.00674"
"10878","65.23200","5.43612","0.00633"
"10887","65.28600","5.44067","0.00636"
"10896","65.34000","5.44515","0.00636"
"10905","65.39400","5.44958","0.00660"
"10914","65.44800","5.45412","0.00618"
"10923","65.50200","5.45854","0.00646"
"10932","65.55600","5.46309","0.00650"
"10941","65.61000","5.46769","0.00680"
"10950","65.66400","5.47218","0.00703"
"10959","65.71800","5.47672","0.00668"
"10968","65.77200","5.48115","0.00663"
"10977","65.82600","5.48557","0.00634"
"10986","65.88000","5.49011","0.00684"
"10995","65.93400","5.49454","0.00630"
"11004","65.98800","5.49908","0.00654"
"11013","66.04200","5.50363","0.00721"
"11022","66.09600","5.50811","0.00708"
"11031","66.15000","5.51265","0.00735"
"11040","66.20400","5.51714","0.00685"
"11049","66.25800","5.52162","0.00731"
"11058","66.31200","5.52617","0.00675"
"11067","66.36600","5.53065","0.00680"
"11076","66.42000","5.53508","0.00696"
"11085","66.47400","5.53956","0.00618"
"11094","66.52800","5.54410","0.00689"
"11103","66.58200","5.54859","0.00710"
"11112","66.63600","5.55307","0.00713"
"11121","66.69000","5.55762","0.00675"
"11130","66.74400","5.56216","0.00647"
"11139","66.79800","5.56665","0.00704"
"11148","66.85200","5.57113","0.00675"
"11157","66.90600","5.57567","0.00730"
"11166","66.96000","5.58010","0.00714"
"11175","67.01400","5.58458","0.00653"
"11184","67.06800","5.58907","0.00692"
"11193","67.12200","5.59355","0.00743"
"11202","67.17600","5.59815","0.00671"
"11211","67.23000","5.60264","0.00704"
"11220","67.28400","5.60712","0.00719"
"11229","67.33800","5.61167","0.00728"
"11238","67.39200","5.61615","0.00676"
"11247","67.44600","5.62063","0.00721"
"11256","67.50000","5.62512","0.00727"
"11265","67.55400","5.62960","0.00694"
"11274","67.60800","5.63409","0.00737"
"11283","67.66200","5.63857","0.00703"
"11292","67.71600","5.64312","0.00725"
"11301","67.77000","5.64760","0.00737"
"11310","67.82400","5.65214","0.00688"
"11319","67.87800","5.65663","0.00760"
"11328","67.93200","5.66117","0.00776"
"11337","67.98600","5.66560","0.00735"
"11346","68.04000","5.67020","0.00718"
"11355","68.09400","5.67462","0.00745"
"11364","68.14800","5.67911","0.00751"
"11373","68.20200","5.68359","0.00743"
"11382","68.25600","5.68808","0.00725"
"11391","68.31000","5.69262","0.00726"
"11400","68.36400","5.69711","0.00735"
"11409","68.41800","5.70159","0.00735"
"11418","68.47200","5.70619","0.00721"
"11427","68.52600","5.71062","0.00760"
"11436","68.58000","5.71510","0.00776"
"11445","68.63400","5.71959","0.00753"
"11454","68.68800","5.72407","0.00786"
"11463","68.74200","5.72861","0.00736"
"11472","68.79600","5.73310","0.00694"
"11481","68.85000","5.73764","0.00792"
"11490","68.90400","5.74219","0.00780"
"11499","68.95800","5.74667","0.00780"
"11508","69.01200","5.75115","0.00791"
"11517","69.06600","5.75564","0.00765"
"11526","69.12000","5.76012","0.00743"
"11535","69.17400","5.76467","0.00758"
"11544","69.22800","5.76909","0.00778"
"11553","69.28200","5.77358","0.00762"
"11562","69.33600","5.77818","0.00748"
"11571","69.39000","5.78266","0.00753"
"11580","69.44400","5.78715","0.00749"
"11589","69.49800","5.79163","0.00816"
"11598","69.55200","5.79612","0.00792"
"11607","69.60600","5.80066","0.00785"
"11616","69.66000","5.80515","0.00743"
"11625","69.71400","5.80963","0.00795"
"11634","69.76800","5.81411","0.00790"
"11643","69.82200","5.81860","0.00792"
"11652","69.87600","5.82314","0.00815"
"11661","69.93000","5.82763","0.00833"
"11670","69.98400","5.83211","0.00783"
"11679","70.03800","5.83671","0.00819"
"11683","70.06000","5.83851","0.00778"