File: Trajectories_together/161226_1Specimen_RawData_6.csv
"","V1","V2","V3"
"1","End date","12/26/2016",""
"2","Specimen label","22AG_78",""
"3","Maximum Load","0.48193","N"
"4","Time","Extension","Load"
"5","(s)","(mm)","(N)"
"6","0.00000","0.00000","0.00007"
"74","0.40800","0.03414","0.00047"
"142","0.81600","0.06810","0.00075"
"210","1.22400","0.10218","0.00104"
"278","1.63200","0.13614","0.00140"
"346","2.04000","0.17010","0.00090"
"414","2.44800","0.20412","0.00143"
"482","2.85600","0.23814","0.00127"
"550","3.26400","0.27216","0.00142"
"618","3.67200","0.30606","0.00211"
"686","4.08000","0.34008","0.00198"
"754","4.48800","0.37410","0.00221"
"822","4.89600","0.40812","0.00231"
"890","5.30400","0.44208","0.00209"
"958","5.71200","0.47610","0.00270"
"1026","6.12000","0.51012","0.00250"
"1094","6.52800","0.54408","0.00275"
"1162","6.93600","0.57810","0.00296"
"1230","7.34400","0.61207","0.00294"
"1298","7.75200","0.64615","0.00307"
"1366","8.16000","0.68017","0.00351"
"1434","8.56800","0.71413","0.00323"
"1502","8.97600","0.74809","0.00349"
"1570","9.38400","0.78211","0.00342"
"1638","9.79200","0.81613","0.00402"
"1706","10.20000","0.85009","0.00370"
"1774","10.60800","0.88411","0.00380"
"1842","11.01600","0.91813","0.00452"
"1910","11.42400","0.95215","0.00387"
"1978","11.83200","0.98617","0.00364"
"2046","12.24000","1.02007","0.00405"
"2114","12.64800","1.05409","0.00413"
"2182","13.05600","1.08811","0.00430"
"2250","13.46400","1.12213","0.00432"
"2318","13.87200","1.15609","0.00480"
"2386","14.28000","1.19005","0.00443"
"2454","14.68800","1.22413","0.00430"
"2522","15.09600","1.25815","0.00437"
"2590","15.50400","1.29211","0.00481"
"2658","15.91200","1.32607","0.00507"
"2726","16.32000","1.36009","0.00426"
"2794","16.72800","1.39417","0.00436"
"2862","17.13600","1.42813","0.00460"
"2930","17.54400","1.46209","0.00441"
"2998","17.95200","1.49605","0.00431"
"3066","18.36000","1.53013","0.00445"
"3134","18.76800","1.56415","0.00443"
"3202","19.17600","1.59805","0.00469"
"3270","19.58400","1.63213","0.00418"
"3338","19.99200","1.66610","0.00418"
"3406","20.40000","1.70012","0.00420"
"3474","20.80800","1.73408","0.00413"
"3542","21.21600","1.76810","0.00414"
"3610","21.62400","1.80218","0.00418"
"3678","22.03200","1.83608","0.00468"
"3746","22.44000","1.87004","0.00461"
"3814","22.84800","1.90412","0.00440"
"3882","23.25600","1.93814","0.00466"
"3950","23.66400","1.97210","0.00517"
"4018","24.07200","2.00612","0.00521"
"4086","24.48000","2.04008","0.00516"
"4154","24.88800","2.07416","0.00501"
"4222","25.29600","2.10812","0.00515"
"4290","25.70400","2.14208","0.00536"
"4358","26.11200","2.17610","0.00504"
"4426","26.52000","2.21012","0.00590"
"4494","26.92800","2.24414","0.00592"
"4562","27.33600","2.27810","0.00567"
"4630","27.74400","2.31206","0.00592"
"4698","28.15200","2.34614","0.00597"
"4766","28.56000","2.38016","0.00635"
"4834","28.96800","2.41412","0.00616"
"4902","29.37600","2.44808","0.00643"
"4970","29.78400","2.48216","0.00649"
"5038","30.19200","2.51612","0.00653"
"5106","30.60000","2.55008","0.00656"
"5174","31.00800","2.58404","0.00649"
"5242","31.41600","2.61812","0.00667"
"5310","31.82400","2.65214","0.00673"
"5378","32.23200","2.68610","0.00641"
"5446","32.64000","2.72007","0.00663"
"5514","33.04800","2.75414","0.00689"
"5582","33.45600","2.78811","0.00696"
"5650","33.86400","2.82207","0.00705"
"5718","34.27200","2.85609","0.00697"
"5786","34.68000","2.89017","0.00659"
"5854","35.08800","2.92407","0.00701"
"5922","35.49600","2.95809","0.00703"
"5990","35.90400","2.99211","0.00735"
"6058","36.31200","3.02613","0.00694"
"6126","36.72000","3.06015","0.00736"
"6194","37.12800","3.09417","0.00742"
"6262","37.53600","3.12807","0.00759"
"6330","37.94400","3.16215","0.00745"
"6398","38.35200","3.19617","0.00793"
"6466","38.76000","3.23013","0.00802"
"6534","39.16800","3.26409","0.00800"
"6602","39.57600","3.29811","0.00834"
"6670","39.98400","3.33219","0.00826"
"6738","40.39200","3.36615","0.00828"
"6806","40.80000","3.40011","0.00822"
"6874","41.20800","3.43413","0.00868"
"6942","41.61600","3.46815","0.00834"
"7010","42.02400","3.50217","0.00880"
"7078","42.43200","3.53613","0.00856"
"7146","42.84000","3.57009","0.00891"
"7214","43.24800","3.60411","0.00867"
"7282","43.65600","3.63813","0.00929"
"7350","44.06400","3.67203","0.00934"
"7418","44.47200","3.70611","0.00971"
"7486","44.88000","3.74013","0.00934"
"7554","45.28800","3.77409","0.00970"
"7622","45.69600","3.80817","0.00992"
"7690","46.10400","3.84208","0.00947"
"7758","46.51200","3.87610","0.00977"
"7826","46.92000","3.91018","0.01022"
"7894","47.32800","3.94414","0.01050"
"7962","47.73600","3.97804","0.01042"
"8030","48.14400","4.01206","0.01064"
"8098","48.55200","4.04614","0.01054"
"8166","48.96000","4.08016","0.01117"
"8234","49.36800","4.11406","0.01083"
"8302","49.77600","4.14814","0.01129"
"8370","50.18400","4.18216","0.01152"
"8438","50.59200","4.21612","0.01139"
"8506","51.00000","4.25008","0.01192"
"8574","51.40800","4.28410","0.01218"
"8642","51.81600","4.31812","0.01221"
"8710","52.22400","4.35220","0.01229"
"8778","52.63200","4.38610","0.01249"
"8846","53.04000","4.42012","0.01278"
"8914","53.44800","4.45414","0.01360"
"8982","53.85600","4.48816","0.01357"
"9050","54.26400","4.52206","0.01382"
"9118","54.67200","4.55608","0.01396"
"9186","55.08000","4.59016","0.01459"
"9254","55.48800","4.62418","0.01471"
"9322","55.89600","4.65808","0.01484"
"9390","56.30400","4.69210","0.01500"
"9458","56.71200","4.72612","0.01536"
"9526","57.12000","4.76014","0.01577"
"9594","57.52800","4.79410","0.01674"
"9662","57.93600","4.82812","0.01670"
"9730","58.34400","4.86214","0.01740"
"9798","58.75200","4.89611","0.01764"
"9866","59.16000","4.93013","0.01815"
"9934","59.56800","4.96409","0.01898"
"10002","59.97600","4.99811","0.01916"
"10070","60.38400","5.03213","0.01977"
"10138","60.79200","5.06615","0.02011"
"10206","61.20000","5.10011","0.02002"
"10274","61.60800","5.13407","0.02072"
"10342","62.01600","5.16809","0.02109"
"10410","62.42400","5.20211","0.02168"
"10478","62.83200","5.23607","0.02242"
"10546","63.24000","5.27009","0.02208"
"10614","63.64800","5.30411","0.02308"
"10682","64.05600","5.33813","0.02294"
"10750","64.46400","5.37203","0.02365"
"10818","64.87200","5.40611","0.02391"
"10886","65.28000","5.44019","0.02484"
"10954","65.68800","5.47415","0.02551"
"11022","66.09600","5.50811","0.02571"
"11090","66.50400","5.54207","0.02668"
"11158","66.91200","5.57615","0.02687"
"11226","67.32000","5.61005","0.02734"
"11294","67.72800","5.64413","0.02738"
"11362","68.13600","5.67809","0.02864"
"11430","68.54400","5.71211","0.02867"
"11498","68.95200","5.74613","0.02959"
"11566","69.36000","5.78009","0.03000"
"11634","69.76800","5.81405","0.03078"
"11702","70.17600","5.84813","0.03157"
"11770","70.58400","5.88209","0.03189"
"11838","70.99200","5.91617","0.03240"
"11906","71.40000","5.95008","0.03357"
"11974","71.80800","5.98410","0.03426"
"12042","72.21600","6.01812","0.03523"
"12110","72.62400","6.05214","0.03604"
"12178","73.03200","6.08604","0.03624"
"12246","73.44000","6.12012","0.03668"
"12314","73.84800","6.15414","0.03757"
"12382","74.25600","6.18810","0.03819"
"12450","74.66400","6.22206","0.03888"
"12518","75.07200","6.25608","0.03965"
"12586","75.48000","6.29016","0.03990"
"12654","75.88800","6.32418","0.04118"
"12722","76.29600","6.35808","0.04122"
"12790","76.70400","6.39210","0.04226"
"12858","77.11200","6.42612","0.04261"
"12926","77.52000","6.46014","0.04375"
"12994","77.92800","6.49410","0.04473"
"13062","78.33600","6.52812","0.04529"
"13130","78.74400","6.56214","0.04648"
"13198","79.15200","6.59610","0.04702"
"13266","79.56000","6.63012","0.04770"
"13334","79.96800","6.66402","0.04913"
"13402","80.37600","6.69810","0.04965"
"13470","80.78400","6.73212","0.05003"
"13538","81.19200","6.76614","0.05060"
"13606","81.60000","6.80004","0.05176"
"13674","82.00800","6.83412","0.05216"
"13742","82.41600","6.86814","0.05287"
"13810","82.82400","6.90204","0.05384"
"13878","83.23200","6.93606","0.05423"
"13946","83.64000","6.97014","0.05464"
"14014","84.04800","7.00416","0.05552"
"14082","84.45600","7.03813","0.05598"
"14150","84.86400","7.07203","0.05628"
"14218","85.27200","7.10611","0.05768"
"14286","85.68000","7.14013","0.05848"
"14354","86.08800","7.17415","0.05915"
"14422","86.49600","7.20811","0.06118"
"14490","86.90400","7.24207","0.06280"
"14558","87.31200","7.27615","0.06411"
"14626","87.72000","7.31005","0.06424"
"14694","88.12800","7.34407","0.06466"
"14762","88.53600","7.37815","0.06661"
"14830","88.94400","7.41217","0.06706"
"14898","89.35200","7.44613","0.06803"
"14966","89.76000","7.48009","0.06983"
"15034","90.16800","7.51411","0.07110"
"15102","90.57600","7.54813","0.07224"
"15170","90.98400","7.58215","0.07429"
"15238","91.39200","7.61617","0.07508"
"15306","91.80000","7.65013","0.07681"
"15374","92.20800","7.68409","0.07801"
"15442","92.61600","7.71811","0.08010"
"15510","93.02400","7.75207","0.08240"
"15578","93.43200","7.78609","0.08385"
"15646","93.84000","7.82017","0.08485"
"15714","94.24800","7.85413","0.08568"
"15782","94.65600","7.88809","0.08752"
"15850","95.06400","7.92211","0.08884"
"15918","95.47200","7.95601","0.08969"
"15986","95.88000","7.99009","0.09044"
"16054","96.28800","8.02411","0.09121"
"16122","96.69600","8.05807","0.09232"
"16190","97.10400","8.09215","0.09298"
"16258","97.51200","8.12611","0.09392"
"16326","97.92000","8.16013","0.09459"
"16394","98.32800","8.19404","0.09508"
"16462","98.73600","8.22812","0.09531"
"16530","99.14400","8.26214","0.09477"
"16598","99.55200","8.29616","0.09495"
"16666","99.96000","8.33006","0.09525"
"16734","100.36800","8.36408","0.09587"
"16802","100.77600","8.39816","0.09678"
"16870","101.18400","8.43212","0.09725"
"16938","101.59200","8.46614","0.09791"
"17006","102.00000","8.50010","0.09861"
"17074","102.40800","8.53412","0.09917"
"17142","102.81600","8.56814","0.09964"
"17210","103.22400","8.60204","0.10023"
"17278","103.63200","8.63612","0.10059"
"17346","104.04000","8.67008","0.10106"
"17414","104.44800","8.70416","0.10188"
"17482","104.85600","8.73812","0.10251"
"17550","105.26400","8.77208","0.10361"
"17618","105.67200","8.80610","0.10519"
"17686","106.08000","8.84012","0.10653"
"17754","106.48800","8.87414","0.10790"
"17822","106.89600","8.90810","0.10914"
"17890","107.30400","8.94218","0.11020"
"17958","107.71200","8.97614","0.11136"
"18026","108.12000","9.01010","0.11254"
"18094","108.52800","9.04406","0.11368"
"18162","108.93600","9.07814","0.11511"
"18230","109.34400","9.11216","0.11781"
"18298","109.75200","9.14612","0.11954"
"18366","110.16000","9.18009","0.12048"
"18434","110.56800","9.21410","0.12399"
"18502","110.97600","9.24807","0.12692"
"18570","111.38400","9.28215","0.12980"
"18638","111.79200","9.31611","0.13281"
"18706","112.20000","9.35013","0.13575"
"18774","112.60800","9.38415","0.13774"
"18842","113.01600","9.41811","0.13866"
"18910","113.42400","9.45207","0.14041"
"18978","113.83200","9.48609","0.14202"
"19046","114.24000","9.52017","0.14455"
"19114","114.64800","9.55419","0.14687"
"19182","115.05600","9.58809","0.14858"
"19250","115.46400","9.62211","0.15052"
"19318","115.87200","9.65613","0.15234"
"19386","116.28000","9.69015","0.15322"
"19454","116.68800","9.72411","0.15586"
"19522","117.09600","9.75807","0.15805"
"19590","117.50400","9.79215","0.16112"
"19658","117.91200","9.82611","0.16288"
"19726","118.32000","9.86007","0.16459"
"19794","118.72800","9.89403","0.16589"
"19862","119.13600","9.92811","0.16739"
"19930","119.54400","9.96213","0.16886"
"19998","119.95200","9.99609","0.16985"
"20066","120.36000","10.03011","0.17145"
"20134","120.76800","10.06413","0.17312"
"20202","121.17600","10.09809","0.17433"
"20270","121.58400","10.13217","0.17690"
"20338","121.99200","10.16613","0.17723"
"20406","122.40000","10.20015","0.17963"
"20474","122.80800","10.23417","0.18066"
"20542","123.21600","10.26814","0.18302"
"20610","123.62400","10.30204","0.18497"
"20678","124.03200","10.33612","0.18575"
"20746","124.44000","10.37014","0.18761"
"20814","124.84800","10.40416","0.18885"
"20882","125.25600","10.43806","0.19056"
"20950","125.66400","10.47208","0.19188"
"21018","126.07200","10.50610","0.19416"
"21086","126.48000","10.54012","0.19468"
"21154","126.88800","10.57414","0.19677"
"21222","127.29600","10.60816","0.19818"
"21290","127.70400","10.64218","0.19977"
"21358","128.11200","10.67614","0.20061"
"21426","128.52000","10.71010","0.20149"
"21494","128.92800","10.74412","0.20289"
"21562","129.33600","10.77814","0.20356"
"21630","129.74400","10.81216","0.20454"
"21698","130.15200","10.84606","0.20566"
"21766","130.56000","10.88008","0.20677"
"21834","130.96800","10.91410","0.20773"
"21902","131.37600","10.94812","0.20867"
"21970","131.78400","10.98208","0.20912"
"22038","132.19200","11.01604","0.21068"
"22106","132.60000","11.05012","0.21156"
"22174","133.00800","11.08414","0.21250"
"22242","133.41600","11.11810","0.21392"
"22310","133.82400","11.15206","0.21561"
"22378","134.23200","11.18608","0.21690"
"22446","134.64000","11.22010","0.21865"
"22514","135.04800","11.25418","0.21997"
"22582","135.45600","11.28808","0.22159"
"22650","135.86400","11.32216","0.22288"
"22718","136.27200","11.35612","0.22504"
"22786","136.68000","11.39015","0.22663"
"22854","137.08800","11.42405","0.22784"
"22922","137.49600","11.45813","0.22928"
"22990","137.90400","11.49215","0.23084"
"23058","138.31200","11.52611","0.23258"
"23126","138.72000","11.56001","0.23460"
"23194","139.12800","11.59403","0.23619"
"23262","139.53600","11.62811","0.23685"
"23330","139.94400","11.66213","0.23896"
"23398","140.35200","11.69609","0.24188"
"23466","140.76000","11.73005","0.24471"
"23534","141.16800","11.76413","0.24558"
"23602","141.57600","11.79815","0.24729"
"23670","141.98400","11.83205","0.24928"
"23738","142.39200","11.86613","0.25188"
"23806","142.80000","11.90015","0.25457"
"23874","143.20800","11.93411","0.25666"
"23942","143.61600","11.96813","0.25878"
"24010","144.02400","12.00209","0.26113"
"24078","144.43200","12.03611","0.26373"
"24146","144.84000","12.07007","0.26700"
"24214","145.24800","12.10409","0.26990"
"24282","145.65600","12.13805","0.27331"
"24350","146.06400","12.17207","0.27672"
"24418","146.47200","12.20609","0.28111"
"24486","146.88000","12.24011","0.28519"
"24554","147.28800","12.27401","0.28919"
"24622","147.69600","12.30803","0.29318"
"24690","148.10400","12.34212","0.29516"
"24758","148.51200","12.37619","0.29846"
"24826","148.92000","12.41010","0.30139"
"24894","149.32800","12.44405","0.30329"
"24962","149.73600","12.47813","0.30519"
"25030","150.14400","12.51216","0.30789"
"25098","150.55200","12.54606","0.30881"
"25166","150.96000","12.58008","0.31023"
"25234","151.36800","12.61416","0.31141"
"25302","151.77600","12.64812","0.31276"
"25370","152.18400","12.68208","0.31305"
"25438","152.59200","12.71610","0.31395"
"25506","153.00000","12.75018","0.31437"
"25574","153.40800","12.78414","0.31499"
"25642","153.81600","12.81804","0.31535"
"25710","154.22400","12.85206","0.31611"
"25778","154.63200","12.88614","0.31650"
"25846","155.04000","12.92010","0.31734"
"25914","155.44800","12.95406","0.31834"
"25982","155.85600","12.98802","0.31928"
"26050","156.26400","13.02216","0.31999"
"26118","156.67200","13.05612","0.32200"
"26186","157.08000","13.09014","0.32362"
"26254","157.48800","13.12410","0.32629"
"26322","157.89600","13.15812","0.32895"
"26390","158.30400","13.19214","0.33167"
"26458","158.71200","13.22616","0.33509"
"26526","159.12000","13.26006","0.33943"
"26594","159.52800","13.29408","0.34301"
"26662","159.93600","13.32810","0.34708"
"26730","160.34400","13.36212","0.35059"
"26798","160.75200","13.39608","0.35436"
"26866","161.16000","13.43010","0.35741"
"26934","161.56800","13.46419","0.36006"
"27002","161.97600","13.49814","0.36429"
"27070","162.38400","13.53205","0.36680"
"27138","162.79200","13.56612","0.36957"
"27206","163.20000","13.60015","0.37293"
"27274","163.60800","13.63417","0.37578"
"27342","164.01600","13.66813","0.37845"
"27410","164.42400","13.70209","0.38035"
"27478","164.83200","13.73611","0.38365"
"27546","165.24000","13.77013","0.38670"
"27614","165.64800","13.80409","0.38940"
"27682","166.05600","13.83805","0.39162"
"27750","166.46400","13.87207","0.39392"
"27818","166.87200","13.90615","0.39599"
"27886","167.28000","13.94011","0.39828"
"27954","167.68800","13.97407","0.40088"
"28022","168.09600","14.00809","0.40147"
"28090","168.50400","14.04211","0.40352"
"28158","168.91200","14.07607","0.40478"
"28226","169.32000","14.11003","0.40676"
"28294","169.72800","14.14411","0.40835"
"28362","170.13600","14.17813","0.41063"
"28430","170.54400","14.21209","0.41240"
"28498","170.95200","14.24605","0.41423"
"28566","171.36000","14.28007","0.41765"
"28634","171.76800","14.31415","0.42141"
"28702","172.17600","14.34817","0.42517"
"28770","172.58400","14.38207","0.42647"
"28838","172.99200","14.41609","0.42884"
"28906","173.40000","14.45011","0.43168"
"28974","173.80800","14.48407","0.43592"
"29042","174.21600","14.51803","0.43642"
"29110","174.62400","14.55212","0.43958"
"29178","175.03200","14.58614","0.44224"
"29246","175.44000","14.62010","0.44621"
"29314","175.84800","14.65400","0.45013"
"29382","176.25600","14.68808","0.43453"
"29450","176.66400","14.72216","0.43825"
"29518","177.07200","14.75612","0.44168"
"29586","177.48000","14.79008","0.44599"
"29654","177.88800","14.82410","0.44985"
"29722","178.29600","14.85812","0.45286"
"29790","178.70400","14.89214","0.45588"
"29858","179.11200","14.92610","0.45866"
"29926","179.52000","14.96006","0.46103"
"29994","179.92800","14.99414","0.46270"
"30062","180.33600","15.02816","0.46500"
"30130","180.74400","15.06212","0.46673"
"30198","181.15200","15.09608","0.47202"
"30266","181.56000","15.13004","0.47514"
"30334","181.96800","15.16412","0.47935"
"30402","182.37600","15.19808","0.23873"
"30470","182.78400","15.23204","0.22660"
"30538","183.19200","15.26612","0.23042"
"30606","183.60000","15.30008","0.22998"
"30674","184.00800","15.33410","0.23346"
"30742","184.41600","15.36806","0.23002"
"30810","184.82400","15.40214","0.22824"
"30878","185.23200","15.43616","0.23341"
"30946","185.64000","15.47012","0.23410"
"31014","186.04800","15.50402","0.23928"
"31082","186.45600","15.53810","0.24023"
"31150","186.86400","15.57218","0.23931"
"31218","187.27200","15.60614","0.24478"
"31286","187.68000","15.64010","0.24760"
"31354","188.08800","15.67413","0.24754"
"31422","188.49600","15.70809","0.24822"
"31490","188.90400","15.74217","0.25004"
"31558","189.31200","15.77607","0.25390"
"31626","189.72000","15.81009","0.25702"
"31694","190.12800","15.84405","0.25651"
"31762","190.53600","15.87813","0.25797"
"31830","190.94400","15.91215","0.26426"
"31898","191.35200","15.94611","0.26669"
"31966","191.76000","15.98013","0.26619"
"32034","192.16800","16.01415","0.27033"
"32102","192.57600","16.04805","0.27757"
"32170","192.98400","16.08213","0.27939"
"32238","193.39200","16.11615","0.27990"
"32306","193.80000","16.15017","0.28417"
"32374","194.20800","16.18407","0.29168"
"32442","194.61600","16.21803","0.29277"
"32510","195.02400","16.25211","0.29426"
"32578","195.43200","16.28613","0.29955"
"32646","195.84000","16.32015","0.30367"
"32714","196.24800","16.35405","0.30414"
"32782","196.65600","16.38807","0.30784"
"32850","197.06400","16.42209","0.31131"
"32918","197.47200","16.45611","0.31212"
"32986","197.88000","16.49007","0.31293"
"33054","198.28800","16.52415","0.31488"
"33122","198.69600","16.55811","0.31546"
"33190","199.10400","16.59213","0.31551"
"33258","199.51200","16.62609","0.31656"
"33326","199.92000","16.66005","0.31846"
"33394","200.32800","16.69413","0.31841"
"33462","200.73600","16.72821","0.32028"
"33530","201.14400","16.76212","0.32278"
"33598","201.55200","16.79613","0.32357"
"33666","201.96000","16.83016","0.32693"
"33734","202.36800","16.86411","0.33142"
"33802","202.77600","16.89808","0.33241"
"33870","203.18400","16.93204","0.33806"
"33938","203.59200","16.96618","0.34346"
"34006","204.00000","17.00020","0.34364"
"34074","204.40800","17.03404","0.31114"
"34142","204.81600","17.06806","0.31318"
"34210","205.22400","17.10208","0.31421"
"34278","205.63200","17.13610","0.31455"
"34346","206.04000","17.17012","0.31574"
"34414","206.44800","17.20408","0.31622"
"34482","206.85600","17.23810","0.31688"
"34550","207.26400","17.27212","0.31925"
"34618","207.67200","17.30614","0.31988"
"34686","208.08000","17.34010","0.32263"
"34754","208.48800","17.37412","0.32586"
"34822","208.89600","17.40814","0.32492"
"34890","209.30400","17.44216","0.32935"
"34958","209.71200","17.47600","0.33782"
"35026","210.12000","17.51014","0.33398"
"35094","210.52800","17.54410","0.33914"
"35162","210.93600","17.57812","0.34750"
"35230","211.34400","17.61208","0.34544"
"35298","211.75200","17.64610","0.35151"
"35366","212.16000","17.68012","0.35589"
"35434","212.56800","17.71414","0.35505"
"35502","212.97600","17.74810","0.36270"
"35570","213.38400","17.78212","0.36325"
"35638","213.79200","17.81614","0.36415"
"35706","214.20000","17.85016","0.37166"
"35774","214.60800","17.88413","0.36992"
"35842","215.01600","17.91809","0.37190"
"35910","215.42400","17.95211","0.37247"
"35978","215.83200","17.98613","0.02830"
"36046","216.24000","18.02009","0.02854"
"36114","216.64800","18.05411","0.03401"
"36182","217.05600","18.08813","0.02658"
"36250","217.46400","18.12209","0.02282"
"36318","217.87200","18.15611","0.02352"
"36386","218.28000","18.19007","0.02703"
"36454","218.68800","18.22415","0.03607"
"36522","219.09600","18.25817","0.04189"
"36590","219.50400","18.29213","0.04262"
"36658","219.91200","18.32609","0.04052"
"36726","220.32000","18.36005","0.03881"
"36794","220.72800","18.39413","0.03830"
"36862","221.13600","18.42809","0.03950"
"36930","221.54400","18.46211","0.04450"
"36998","221.95200","18.49613","0.04948"
"37066","222.36000","18.53009","0.05330"
"37134","222.76800","18.56411","0.05450"
"37202","223.17600","18.59801","0.05370"
"37270","223.58400","18.63209","0.05308"
"37338","223.99200","18.66611","0.05364"
"37406","224.40000","18.70013","0.05313"
"37474","224.80800","18.73403","0.05377"
"37542","225.21600","18.76805","0.05582"
"37610","225.62400","18.80213","0.05935"
"37678","226.03200","18.83615","0.06162"
"37746","226.44000","18.87006","0.06438"
"37814","226.84800","18.90413","0.06643"
"37882","227.25600","18.93816","0.06832"
"37950","227.66400","18.97212","0.06989"
"38018","228.07200","19.00602","0.07040"
"38086","228.48000","19.04010","0.07109"
"38154","228.88800","19.07412","0.07202"
"38222","229.29600","19.10814","0.07231"
"38290","229.70400","19.14210","0.07381"
"38358","230.11200","19.17606","0.07615"
"38426","230.52000","19.21014","0.07762"
"38494","230.92800","19.24410","0.08061"
"38562","231.33600","19.27812","0.08249"
"38630","231.74400","19.31208","0.08504"
"38698","232.15200","19.34616","0.08758"
"38766","232.56000","19.38012","0.08940"
"38834","232.96800","19.41414","0.09089"
"38902","233.37600","19.44804","0.09274"
"38970","233.78400","19.48206","0.09370"
"39038","234.19200","19.51614","0.09468"
"39106","234.60000","19.55016","0.09612"
"39174","235.00800","19.58406","0.09678"
"39242","235.41600","19.61808","0.09750"
"39310","235.82400","19.65216","0.09751"
"39378","236.23200","19.68612","0.09843"
"39446","236.64000","19.72002","0.09936"
"39514","237.04800","19.75416","0.10048"
"39582","237.45600","19.78818","0.10138"
"39650","237.86400","19.82208","0.10220"
"39718","238.27200","19.85604","0.10321"
"39786","238.68000","19.89006","0.10423"
"39854","239.08800","19.92414","0.10579"
"39922","239.49600","19.95811","0.10694"
"39990","239.90400","19.99213","0.10786"
"40058","240.31200","20.02615","0.10514"
"40126","240.72000","20.06010","0.10770"
"40194","241.12800","20.09412","0.10917"
"40262","241.53600","20.12809","0.10913"
"40330","241.94400","20.16205","0.11129"
"40398","242.35200","20.19613","0.11355"
"40466","242.76000","20.23015","0.11698"
"40534","243.16800","20.26411","0.12011"
"40602","243.57600","20.29807","0.12314"
"40670","243.98400","20.33209","0.12626"
"40738","244.39200","20.36611","0.12881"
"40806","244.80000","20.40013","0.13467"
"40874","245.20800","20.43409","0.13850"
"40942","245.61600","20.46811","0.14291"
"41010","246.02400","20.50213","0.14648"
"41078","246.43200","20.53609","0.14920"
"41146","246.84000","20.57011","0.15221"
"41214","247.24800","20.60407","0.15530"
"41282","247.65600","20.63821","0.15812"
"41350","248.06400","20.67217","0.16187"
"41418","248.47200","20.70607","0.16359"
"41486","248.88000","20.74009","0.16563"
"41554","249.28800","20.77411","0.16796"
"41622","249.69600","20.80807","0.17056"
"41690","250.10400","20.84209","0.17412"
"41758","250.51200","20.87611","0.17500"
"41826","250.92000","20.91013","0.17969"
"41894","251.32800","20.94409","0.18312"
"41962","251.73600","20.97805","0.18605"
"42030","252.14400","21.01207","0.18906"
"42098","252.55200","21.04609","0.19181"
"42166","252.96000","21.08017","0.19413"
"42234","253.36800","21.11414","0.19683"
"42302","253.77600","21.14804","0.19992"
"42370","254.18400","21.18211","0.19989"
"42438","254.59200","21.21614","0.20200"
"42506","255.00000","21.25010","0.20451"
"42574","255.40800","21.28406","0.20622"
"42642","255.81600","21.31814","0.20787"
"42710","256.22400","21.35210","0.20948"
"42778","256.63200","21.38612","0.21174"
"42846","257.04000","21.42002","0.21471"
"42914","257.44800","21.45410","0.21782"
"42982","257.85600","21.48812","0.22148"
"43050","258.26400","21.52214","0.22441"
"43118","258.67200","21.55610","0.22734"
"43186","259.08000","21.59006","0.23048"
"43254","259.48800","21.62414","0.23434"
"43322","259.89600","21.65810","0.23820"
"43390","260.30400","21.69206","0.24268"
"43458","260.71200","21.72614","0.24573"
"43526","261.12000","21.76010","0.24947"
"43594","261.52800","21.79412","0.25385"
"43662","261.93600","21.82808","0.25700"
"43730","262.34400","21.86210","0.26056"
"43798","262.75200","21.89612","0.26601"
"43866","263.16000","21.93014","0.27158"
"43934","263.56800","21.96411","0.27785"
"44002","263.97600","21.99806","0.28269"
"44070","264.38400","22.03208","0.29020"
"44138","264.79200","22.06610","0.29189"
"44206","265.20000","22.10006","0.29758"
"44274","265.60800","22.13408","0.30303"
"44342","266.01600","22.16816","0.30703"
"44410","266.42400","22.20213","0.31045"
"44478","266.83200","22.23603","0.31285"
"44546","267.24000","22.27011","0.31412"
"44614","267.64800","22.30412","0.31490"
"44682","268.05600","22.33815","0.30563"
"44750","268.46400","22.37211","0.31236"
"44818","268.87200","22.40607","0.31512"
"44886","269.28000","22.44009","0.31667"
"44954","269.68800","22.47411","0.31927"
"45022","270.09600","22.50813","0.32431"
"45090","270.50400","22.54209","0.32748"
"45158","270.91200","22.57617","0.21420"
"45226","271.32000","22.61013","0.23365"
"45294","271.72800","22.64403","0.21408"
"45362","272.13600","22.67799","0.22258"
"45430","272.54400","22.71207","0.22401"
"45498","272.95200","22.74615","0.25327"
"45566","273.36000","22.78011","0.25956"
"45634","273.76800","22.81407","0.25183"
"45702","274.17600","22.84809","0.25344"
"45770","274.58400","22.88211","0.27337"
"45838","274.99200","22.91613","0.30047"
"45906","275.40000","22.95009","0.28517"
"45974","275.80800","22.98411","0.29241"
"46042","276.21600","23.01813","0.30963"
"46110","276.62400","23.05210","0.31263"
"46178","277.03200","23.08605","0.31037"
"46246","277.44000","23.12008","0.31431"
"46314","277.84800","23.15415","0.31950"
"46382","278.25600","23.18817","0.31803"
"46450","278.66400","23.22207","0.32032"
"46518","279.07200","23.25610","0.33499"
"46586","279.48000","23.29012","0.33141"
"46654","279.88800","23.32414","0.33806"
"46722","280.29600","23.35810","0.34604"
"46790","280.70400","23.39206","0.31238"
"46858","281.11200","23.42614","0.31333"
"46926","281.52000","23.46016","0.31654"
"46994","281.92800","23.49412","0.31831"
"47062","282.33600","23.52808","0.31856"
"47130","282.74400","23.56210","0.32635"
"47198","283.15200","23.59612","0.33009"
"47266","283.56000","23.63014","0.32278"
"47334","283.96800","23.66410","0.32958"
"47402","284.37600","23.69812","0.33763"
"47470","284.78400","23.73208","0.34085"
"47538","285.19200","23.76610","0.35299"
"47606","285.60000","23.80006","0.35847"
"47674","286.00800","23.83408","0.36134"
"47742","286.41600","23.86816","0.37144"
"47810","286.82400","23.90218","0.37203"
"47878","287.23200","23.93608","0.37550"
"47946","287.64000","23.97010","0.37856"
"48014","288.04800","24.00418","0.37304"
"48082","288.45600","24.03814","0.35081"
"48150","288.86400","24.07210","0.18368"
"48218","289.27200","24.10607","0.20664"
"48286","289.68000","24.14020","0.21163"
"48354","290.08800","24.17410","0.23807"
"48422","290.49600","24.20806","0.24339"
"48490","290.90400","24.24208","0.24598"
"48558","291.31200","24.27611","0.24730"
"48626","291.72000","24.31018","0.26194"
"48694","292.12800","24.34409","0.26863"
"48762","292.53600","24.37805","0.28631"
"48830","292.94400","24.41212","0.22363"
"48898","293.35200","24.44608","0.21712"
"48966","293.76000","24.48011","0.17899"
"49034","294.16800","24.51413","0.17835"
"49102","294.57600","24.54815","0.18647"
"49170","294.98400","24.58217","0.19158"
"49238","295.39200","24.61613","0.19898"
"49306","295.80000","24.65003","0.20473"
"49374","296.20800","24.68417","0.20856"
"49442","296.61600","24.71813","0.16213"
"49510","297.02400","24.75215","0.16745"
"49578","297.43200","24.78611","0.17123"
"49646","297.84000","24.82007","0.17903"
"49714","298.24800","24.85415","0.18242"
"49782","298.65600","24.88811","0.18990"
"49850","299.06400","24.92207","0.19379"
"49918","299.47200","24.95609","0.19975"
"49986","299.88000","24.99011","0.19727"
"50054","300.28800","25.02413","0.20126"
"50122","300.69600","25.05803","0.16293"
"50190","301.10400","25.09211","0.13468"
"50258","301.51200","25.12613","0.13707"
"50326","301.92000","25.16015","0.14564"
"50394","302.32800","25.19411","0.14817"
"50462","302.73600","25.22813","0.07273"
"50530","303.14400","25.26209","0.06247"
"50598","303.55200","25.29612","0.06431"
"50666","303.96000","25.33013","0.07702"
"50734","304.36800","25.36403","0.08158"
"50802","304.77600","25.39812","0.07488"
"50870","305.18400","25.43214","0.07614"
"50938","305.59200","25.46609","0.07885"
"51006","306.00000","25.50011","0.08436"
"51074","306.40800","25.53408","0.08991"
"51142","306.81600","25.56810","0.09382"
"51210","307.22400","25.60212","0.09384"
"51278","307.63200","25.63608","0.04658"
"51346","308.04000","25.67016","0.03751"
"51414","308.44800","25.70412","0.04058"
"51482","308.85600","25.73814","0.04494"
"51550","309.26400","25.77210","0.03960"
"51618","309.67200","25.80612","0.04119"
"51686","310.08000","25.84014","0.04736"
"51754","310.48800","25.87416","0.04379"
"51822","310.89600","25.90806","0.04916"
"51890","311.30400","25.94208","0.04531"
"51958","311.71200","25.97616","0.04367"
"52026","312.12000","26.01012","0.04109"
"52094","312.52800","26.04408","0.04395"
"52162","312.93600","26.07810","0.04844"
"52230","313.34400","26.11212","0.04821"
"52298","313.75200","26.14614","0.04917"
"52366","314.16000","26.18004","0.05339"
"52434","314.56800","26.21412","0.05549"
"52502","314.97600","26.24814","0.05385"
"52570","315.38400","26.28211","0.05438"
"52638","315.79200","26.31612","0.05804"
"52706","316.20000","26.35008","0.06070"
"52774","316.60800","26.38416","0.06211"
"52842","317.01600","26.41806","0.06194"
"52910","317.42400","26.45209","0.06420"
"52978","317.83200","26.48611","0.06677"
"53046","318.24000","26.52013","0.07025"
"53114","318.64800","26.55415","0.07116"
"53182","319.05600","26.58817","0.07238"
"53250","319.46400","26.62213","0.07423"
"53318","319.87200","26.65609","0.07620"
"53386","320.28000","26.69011","0.07911"
"53454","320.68800","26.72413","0.08106"
"53522","321.09600","26.75809","0.08291"
"53590","321.50400","26.79205","0.08407"
"53658","321.91200","26.82613","0.08597"
"53726","322.32000","26.86009","0.08766"
"53794","322.72800","26.89405","0.08865"
"53862","323.13600","26.92813","0.09079"
"53930","323.54400","26.96215","0.09231"
"53998","323.95200","26.99611","0.09331"
"54066","324.36000","27.03007","0.09420"
"54134","324.76800","27.06409","0.09567"
"54202","325.17600","27.09817","0.09641"
"54270","325.58400","27.13213","0.09710"
"54338","325.99200","27.16615","0.09754"
"54406","326.40000","27.20011","0.09858"
"54474","326.80800","27.23413","0.09934"
"54542","327.21600","27.26815","0.10038"
"54610","327.62400","27.30206","0.09871"
"54678","328.03200","27.33601","0.09936"
"54746","328.44000","27.37009","0.09989"
"54814","328.84800","27.40411","0.10102"
"54882","329.25600","27.43813","-0.01532"
"54950","329.66400","27.47210","0.00701"
"55018","330.07200","27.50612","-0.00095"
"55086","330.48000","27.54014","0.00380"
"55154","330.88800","27.57410","0.00042"
"55222","331.29600","27.60812","-0.00143"
"55290","331.70400","27.64214","0.00884"
"55358","332.11200","27.67616","-0.00023"
"55426","332.52000","27.71012","0.00881"
"55494","332.92800","27.74408","0.00229"
"55562","333.33600","27.77816","0.00147"
"55630","333.74400","27.81218","0.00747"
"55698","334.15200","27.84614","0.00494"
"55766","334.56000","27.88004","0.00512"
"55834","334.96800","27.91412","0.00622"
"55902","335.37600","27.94814","0.00346"
"55970","335.78400","27.98210","0.00367"
"56038","336.19200","28.01606","0.00648"
"56106","336.60000","28.05008","0.00554"
"56174","337.00800","28.08410","0.00555"
"56242","337.41600","28.11812","0.00730"
"56310","337.82400","28.15208","0.00704"
"56378","338.23200","28.18604","0.00657"
"56446","338.64000","28.22012","0.00586"
"56514","339.04800","28.25420","0.00675"
"56582","339.45600","28.28810","0.00698"
"56650","339.86400","28.32212","0.00666"
"56718","340.27200","28.35614","0.00737"
"56786","340.68000","28.39016","0.00809"
"56854","341.08800","28.42412","0.00795"
"56922","341.49600","28.45808","0.00831"
"56990","341.90400","28.49217","0.00896"
"57058","342.31200","28.52612","0.00872"
"57126","342.72000","28.56009","0.00886"
"57194","343.12800","28.59405","0.00935"
"57262","343.53600","28.62813","0.00930"
"57330","343.94400","28.66215","0.00983"
"57398","344.35200","28.69617","0.01004"
"57466","344.76000","28.73007","0.01033"
"57534","345.16800","28.76409","0.01062"
"57602","345.57600","28.79811","0.01097"
"57670","345.98400","28.83213","0.01130"
"57738","346.39200","28.86609","0.01172"
"57806","346.80000","28.90017","0.01194"
"57874","347.20800","28.93413","0.01232"
"57942","347.61600","28.96815","0.01246"
"58010","348.02400","29.00205","0.01327"
"58078","348.43200","29.03613","0.01354"
"58146","348.84000","29.07015","0.01363"
"58214","349.24800","29.10417","0.01414"
"58282","349.65600","29.13807","0.01439"
"58350","350.06400","29.17209","0.01498"
"58418","350.47200","29.20611","0.01602"
"58486","350.88000","29.24013","0.01575"
"58554","351.28800","29.27409","0.01639"
"58622","351.69600","29.30805","0.01687"
"58690","352.10400","29.34213","0.01761"
"58758","352.51200","29.37615","0.01765"
"58826","352.92000","29.41011","0.01810"
"58894","353.32800","29.44407","0.01864"
"58962","353.73600","29.47803","0.01881"
"59030","354.14400","29.51211","0.01974"
"59098","354.55200","29.54613","0.02016"
"59166","354.96000","29.58009","0.02050"
"59234","355.36800","29.61412","0.02113"
"59302","355.77600","29.64813","0.02187"
"59370","356.18400","29.68210","0.02249"
"59438","356.59200","29.71605","0.02306"
"59506","357.00000","29.75014","0.02384"
"59574","357.40800","29.78416","0.02414"
"59642","357.81600","29.81812","0.02477"
"59710","358.22400","29.85202","0.02534"
"59778","358.63200","29.88610","0.02635"
"59846","359.04000","29.92012","0.02614"
"59914","359.44800","29.95414","0.02705"
"59982","359.85600","29.98810","0.02786"
"60050","360.26400","30.02212","0.02899"
"60118","360.67200","30.05614","0.02970"
"60186","361.08000","30.09016","0.02991"
"60254","361.48800","30.12406","0.03160"
"60322","361.89600","30.15814","0.03226"
"60390","362.30400","30.19210","0.03323"
"60458","362.71200","30.22612","0.03450"
"60526","363.12000","30.26008","0.03499"
"60594","363.52800","30.29410","0.03629"
"60662","363.93600","30.32812","0.03735"
"60730","364.34400","30.36214","0.03794"
"60798","364.75200","30.39610","0.03948"
"60866","365.16000","30.43012","0.04037"
"60934","365.56800","30.46414","0.04045"
"61002","365.97600","30.49810","0.04155"
"61070","366.38400","30.53207","0.04214"
"61138","366.79200","30.56608","0.04270"
"61206","367.20000","30.60017","0.04338"
"61274","367.60800","30.63418","0.04363"
"61342","368.01600","30.66808","0.04433"
"61410","368.42400","30.70211","0.04544"
"61478","368.83200","30.73612","0.04563"
"61546","369.24000","30.77009","0.04651"
"61614","369.64800","30.80416","0.04696"
"61682","370.05600","30.83813","0.04788"
"61750","370.46400","30.87215","0.04837"
"61818","370.87200","30.90611","0.04888"
"61886","371.28000","30.94007","0.04953"
"61954","371.68800","30.97409","0.05042"
"62022","372.09600","31.00811","0.05136"
"62090","372.50400","31.04213","0.05220"
"62158","372.91200","31.07615","0.05186"
"62226","373.32000","31.11005","0.05266"
"62294","373.72800","31.14407","0.05363"
"62362","374.13600","31.17809","0.05401"
"62430","374.54400","31.21211","0.05455"
"62498","374.95200","31.24607","0.05539"
"62566","375.36000","31.28009","0.05547"
"62634","375.76800","31.31417","0.05650"
"62702","376.17600","31.34813","0.05633"
"62770","376.58400","31.38209","0.05732"
"62838","376.99200","31.41605","0.05810"
"62906","377.40000","31.45013","0.05868"
"62974","377.80800","31.48421","0.05953"
"63042","378.21600","31.51811","0.05997"
"63110","378.62400","31.55207","0.06051"
"63178","379.03200","31.58609","0.06105"
"63246","379.44000","31.62011","0.06152"
"63314","379.84800","31.65407","0.06245"
"63382","380.25600","31.68810","0.06283"
"63450","380.66400","31.72217","0.06346"
"63518","381.07200","31.75613","0.06424"
"63586","381.48000","31.79009","0.06527"
"63654","381.88800","31.82400","0.06603"
"63722","382.29600","31.85814","0.06643"
"63790","382.70400","31.89215","0.06757"
"63858","383.11200","31.92617","0.06812"
"63926","383.52000","31.96007","0.06901"
"63994","383.92800","31.99410","0.06963"
"64062","384.33600","32.02812","0.06992"
"64130","384.74400","32.06213","0.07079"
"64198","385.15200","32.09610","0.07176"
"64266","385.56000","32.13012","0.07251"
"64334","385.96800","32.16414","0.07357"
"64402","386.37600","32.19810","0.07417"
"64470","386.78400","32.23200","0.07452"
"64538","387.19200","32.26608","0.07588"
"64606","387.60000","32.30016","0.07754"
"64674","388.00800","32.33418","0.07799"
"64742","388.41600","32.36814","0.07865"
"64810","388.82400","32.40204","0.07982"
"64878","389.23200","32.43612","0.08046"
"64946","389.64000","32.47014","0.08146"
"65014","390.04800","32.50404","0.08235"
"65082","390.45600","32.53806","0.08289"
"65150","390.86400","32.57214","0.08363"
"65218","391.27200","32.60616","0.08459"
"65286","391.68000","32.64012","0.08523"
"65354","392.08800","32.67408","0.08644"
"65422","392.49600","32.70810","0.08702"
"65490","392.90400","32.74212","0.08730"
"65558","393.31200","32.77620","0.08792"
"65626","393.72000","32.81010","0.08816"
"65694","394.12800","32.84406","0.08899"
"65762","394.53600","32.87809","0.08937"
"65830","394.94400","32.91211","0.09021"
"65898","395.35200","32.94613","0.09066"
"65966","395.76000","32.98014","0.09145"
"66034","396.16800","33.01417","0.09222"
"66102","396.57600","33.04813","0.09225"
"66170","396.98400","33.08203","0.09261"
"66238","397.39200","33.11605","0.09333"
"66306","397.80000","33.15012","0.09371"
"66374","398.20800","33.18415","0.09397"
"66442","398.61600","33.21811","-0.00452"
"66510","399.02400","33.25213","0.00058"
"66578","399.43200","33.28615","0.00386"
"66646","399.84000","33.32011","-0.00013"
"66714","400.24800","33.35407","0.00054"
"66782","400.65600","33.38809","0.00333"
"66850","401.06400","33.42217","0.00340"
"66918","401.47200","33.45619","0.00148"
"66986","401.88000","33.49009","0.00086"
"67054","402.28800","33.52405","0.00351"
"67122","402.69600","33.55813","0.00300"
"67190","403.10400","33.59209","0.00233"
"67258","403.51200","33.62611","0.00310"
"67326","403.92000","33.66013","0.00245"
"67394","404.32800","33.69409","0.00151"
"67462","404.73600","33.72811","0.00167"
"67530","405.14400","33.76213","0.00235"
"67598","405.55200","33.79609","0.00242"
"67666","405.96000","33.83011","0.00194"
"67734","406.36800","33.86413","0.00165"
"67802","406.77600","33.89815","0.00241"
"67870","407.18400","33.93205","0.00241"
"67938","407.59200","33.96601","-0.00216"
"68006","408.00000","34.00016","0.00650"
"68074","408.40800","34.03411","0.00621"
"68142","408.81600","34.06807","-0.00163"
"68210","409.22400","34.10216","0.00175"
"68278","409.63200","34.13612","0.00480"
"68346","410.04000","34.17007","-0.00151"
"68414","410.44800","34.20404","0.00271"
"68482","410.85600","34.23806","0.00476"
"68550","411.26400","34.27220","0.00304"
"68618","411.67200","34.30610","0.00177"
"68686","412.08000","34.34006","0.00342"
"68754","412.48800","34.37408","0.00271"
"68822","412.89600","34.40810","0.00258"
"68890","413.30400","34.44212","0.00407"
"68958","413.71200","34.47608","0.00353"
"69026","414.12000","34.51010","0.00277"
"69094","414.52800","34.54418","0.00315"
"69162","414.93600","34.57814","0.00429"
"69230","415.34400","34.61210","0.00433"
"69298","415.75200","34.64612","0.00399"
"69366","416.16000","34.68014","0.00399"
"69434","416.56800","34.71416","0.00389"
"69502","416.97600","34.74812","0.00459"
"69570","417.38400","34.78208","0.00451"
"69638","417.79200","34.81610","0.00468"
"69706","418.20000","34.85012","0.00475"
"69774","418.60800","34.88414","0.00507"
"69842","419.01600","34.91810","0.00503"
"69910","419.42400","34.95212","0.00497"
"69978","419.83200","34.98615","0.00511"
"70046","420.24000","35.02011","0.00524"
"70114","420.64800","35.05400","0.00541"
"70182","421.05600","35.08814","0.00569"
"70250","421.46400","35.12216","0.00563"
"70318","421.87200","35.15613","0.00623"
"70386","422.28000","35.19009","0.00615"
"70454","422.68800","35.22411","0.00605"
"70522","423.09600","35.25813","0.00626"
"70590","423.50400","35.29208","0.00652"
"70658","423.91200","35.32611","0.00674"
"70726","424.32000","35.36007","0.00668"
"70794","424.72800","35.39415","0.00694"
"70862","425.13600","35.42811","0.00712"
"70930","425.54400","35.46207","0.00736"
"70998","425.95200","35.49609","0.00757"
"71066","426.36000","35.53011","0.00752"
"71134","426.76800","35.56419","0.00801"
"71202","427.17600","35.59809","0.00793"
"71270","427.58400","35.63211","0.00836"
"71338","427.99200","35.66613","0.00820"
"71406","428.40000","35.70009","0.00854"
"71474","428.80800","35.73411","0.00870"
"71542","429.21600","35.76807","0.00858"
"71610","429.62400","35.80215","0.00907"
"71678","430.03200","35.83617","0.00941"
"71746","430.44000","35.87013","0.00958"
"71814","430.84800","35.90403","0.00965"
"71882","431.25600","35.93805","0.01010"
"71950","431.66400","35.97213","0.01012"
"72018","432.07200","36.00609","0.01023"
"72086","432.48000","36.04005","0.01066"
"72154","432.88800","36.07413","0.01084"
"72222","433.29600","36.10815","0.01111"
"72290","433.70400","36.14211","0.01160"
"72358","434.11200","36.17601","0.01142"
"72426","434.52000","36.21010","0.01196"
"72494","434.92800","36.24417","0.01264"
"72562","435.33600","36.27814","0.01239"
"72630","435.74400","36.31210","0.01283"
"72698","436.15200","36.34605","0.01314"
"72766","436.56000","36.38014","0.01371"
"72834","436.96800","36.41416","0.01412"
"72902","437.37600","36.44812","0.01473"
"72970","437.78400","36.48208","0.01509"
"73038","438.19200","36.51616","0.01538"
"73106","438.60000","36.55012","0.01577"
"73174","439.00800","36.58402","0.01660"
"73242","439.41600","36.61810","0.01692"
"73310","439.82400","36.65206","0.01746"
"73378","440.23200","36.68614","0.01820"
"73446","440.64000","36.72010","0.01890"
"73514","441.04800","36.75406","0.01955"
"73582","441.45600","36.78814","0.02004"
"73650","441.86400","36.82210","0.02104"
"73718","442.27200","36.85606","0.02173"
"73786","442.68000","36.89008","0.02251"
"73854","443.08800","36.92416","0.02330"
"73922","443.49600","36.95813","0.02398"
"73990","443.90400","36.99208","0.02501"
"74058","444.31200","37.02610","0.02548"
"74126","444.72000","37.06012","0.02650"
"74194","445.12800","37.09414","0.02696"
"74262","445.53600","37.12811","0.02830"
"74330","445.94400","37.16206","0.02884"
"74398","446.35200","37.19608","0.03030"
"74466","446.76000","37.23010","0.03117"
"74534","447.16800","37.26413","0.03240"
"74602","447.57600","37.29803","0.03348"
"74670","447.98400","37.33211","0.03420"
"74738","448.39200","37.36613","0.03569"
"74806","448.80000","37.40009","0.03751"
"74874","449.20800","37.43411","0.03845"
"74942","449.61600","37.46807","0.03852"
"75010","450.02400","37.50209","0.04090"
"75078","450.43200","37.53617","0.04197"
"75146","450.84000","37.57013","0.04219"
"75214","451.24800","37.60409","0.04339"
"75282","451.65600","37.63811","0.04397"
"75350","452.06400","37.67219","0.04483"
"75418","452.47200","37.70609","0.04555"
"75486","452.88000","37.74005","0.04655"
"75554","453.28800","37.77419","0.04812"
"75622","453.69600","37.80815","0.04809"
"75690","454.10400","37.84205","0.03088"
"75758","454.51200","37.87607","0.02898"
"75826","454.92000","37.91009","0.02878"
"75894","455.32800","37.94405","0.02980"
"75962","455.73600","37.97813","0.03078"
"76030","456.14400","38.01209","0.03309"
"76098","456.55200","38.04612","0.03497"
"76166","456.96000","38.08014","0.03486"
"76234","457.36800","38.11415","0.03541"
"76302","457.77600","38.14811","0.03641"
"76370","458.18400","38.18208","0.03746"
"76438","458.59200","38.21616","0.03820"
"76506","459.00000","38.25018","0.03908"
"76574","459.40800","38.28407","0.04006"
"76642","459.81600","38.31809","0.04120"
"76710","460.22400","38.35212","0.04212"
"76778","460.63200","38.38614","0.04228"
"76846","461.04000","38.42010","0.04360"
"76914","461.44800","38.45406","0.04408"
"76982","461.85600","38.48814","0.04495"
"77050","462.26400","38.52210","0.04545"
"77118","462.67200","38.55606","0.04535"
"77186","463.08000","38.59002","0.04738"
"77254","463.48800","38.62410","0.04778"
"77322","463.89600","38.65818","0.04887"
"77390","464.30400","38.69208","0.04967"
"77458","464.71200","38.72610","0.05046"
"77526","465.12000","38.76012","0.05079"
"77594","465.52800","38.79414","0.05216"
"77662","465.93600","38.82816","0.05227"
"77730","466.34400","38.86212","0.05337"
"77798","466.75200","38.89614","0.05367"
"77866","467.16000","38.93010","0.05458"
"77934","467.56800","38.96412","0.05553"
"78002","467.97600","38.99802","0.05627"
"78070","468.38400","39.03216","0.05725"
"78138","468.79200","39.06612","0.05765"
"78206","469.20000","39.10009","0.05844"
"78274","469.60800","39.13404","0.05925"
"78342","470.01600","39.16806","0.06036"
"78410","470.42400","39.20208","0.06100"
"78478","470.83200","39.23610","0.06282"
"78546","471.24000","39.27013","0.06365"
"78614","471.64800","39.30415","0.06477"
"78682","472.05600","39.33817","0.06552"
"78750","472.46400","39.37212","0.06736"
"78818","472.87200","39.40609","0.06939"
"78886","473.28000","39.44004","0.06935"
"78954","473.68800","39.47412","0.07035"
"79022","474.09600","39.50814","0.07134"
"79090","474.50400","39.54211","0.07287"
"79158","474.91200","39.57607","0.07352"
"79226","475.32000","39.61015","0.07427"
"79294","475.72800","39.64417","0.07579"
"79362","476.13600","39.67807","0.07528"
"79430","476.54400","39.71203","0.07623"
"79498","476.95200","39.74611","0.07810"
"79566","477.36000","39.78012","0.07956"
"79634","477.76800","39.81403","0.08046"
"79702","478.17600","39.84811","0.08257"
"79770","478.58400","39.88213","0.08296"
"79838","478.99200","39.91615","0.08446"
"79906","479.40000","39.95011","0.08524"
"79974","479.80800","39.98407","0.08632"
"80042","480.21600","40.01815","0.08798"
"80110","480.62400","40.05211","0.08933"
"80178","481.03200","40.08613","0.08993"
"80246","481.44000","40.12009","0.09107"
"80314","481.84800","40.15411","0.09186"
"80382","482.25600","40.18813","0.09277"
"80450","482.66400","40.22209","0.09345"
"80518","483.07200","40.25605","0.09423"
"80586","483.48000","40.29007","0.09508"
"80654","483.88800","40.32415","0.09551"
"80722","484.29600","40.35812","0.09620"
"80790","484.70400","40.39207","0.09638"
"80858","485.11200","40.42609","0.09692"
"80926","485.52000","40.46012","0.09724"
"80994","485.92800","40.49413","0.09761"
"81062","486.33600","40.52810","0.09850"
"81130","486.74400","40.56211","0.09862"
"81198","487.15200","40.59620","0.06738"
"81266","487.56000","40.63016","0.02108"
"81334","487.96800","40.66412","0.02134"
"81402","488.37600","40.69807","0.02315"
"81470","488.78400","40.73215","0.02358"
"81538","489.19200","40.76606","0.02497"
"81606","489.60000","40.80008","0.02336"
"81674","490.00800","40.83410","0.00903"
"81742","490.41600","40.86811","0.00824"
"81810","490.82400","40.90208","0.00755"
"81878","491.23200","40.93610","0.00840"
"81946","491.64000","40.97006","0.00979"
"82014","492.04800","41.00408","0.00926"
"82082","492.45600","41.03810","0.01030"
"82150","492.86400","41.07212","0.00960"
"82218","493.27200","41.10608","0.01080"
"82286","493.68000","41.14004","0.01115"
"82354","494.08800","41.17412","0.01124"
"82422","494.49600","41.20814","0.01190"
"82490","494.90400","41.24210","0.01163"
"82558","495.31200","41.27618","0.01342"
"82626","495.72000","41.31014","0.01252"
"82694","496.12800","41.34404","0.01462"
"82762","496.53600","41.37801","0.01373"
"82830","496.94400","41.41208","0.01563"
"82898","497.35200","41.44616","0.01468"
"82966","497.76000","41.48013","0.01639"
"83034","498.16800","41.51408","0.01575"
"83102","498.57600","41.54811","0.01604"
"83170","498.98400","41.58207","0.01689"
"83238","499.39200","41.61615","-0.00049"
"83306","499.80000","41.65010","-0.00204"
"83374","500.20800","41.68413","-0.00257"
"83442","500.61600","41.71815","-0.00240"
"83510","501.02400","41.75211","-0.00136"
"83578","501.43200","41.78613","-0.00284"
"83646","501.84000","41.82009","-0.00271"
"83714","502.24800","41.85411","-0.00204"
"83782","502.65600","41.88813","-0.00263"
"83850","503.06400","41.92215","-0.00247"
"83918","503.47200","41.95610","-0.00254"
"83986","503.88000","41.99013","-0.00252"
"84054","504.28800","42.02409","-0.00270"
"84069","504.37600","42.03144","-0.00253"