File: Trajectories_together/161223_2Specimen_RawData_5.csv
"","V1","V2","V3"
"1","End date","12/23/2016",""
"2","Specimen label","23BG_84",""
"3","Maximum Load","1.42711","N"
"4","Time","Extension","Load"
"5","(s)","(mm)","(N)"
"6","0.00000","0.00000","-0.00050"
"64","0.34800","0.02906","-0.00003"
"122","0.69600","0.05824","0.00093"
"180","1.04400","0.08723","0.00153"
"238","1.39200","0.11623","0.00212"
"296","1.74000","0.14523","0.00277"
"354","2.08800","0.17423","0.00353"
"412","2.43600","0.20322","0.00341"
"470","2.78400","0.23216","0.00450"
"528","3.13200","0.26122","0.00475"
"586","3.48000","0.29028","0.00607"
"644","3.82800","0.31916","0.00591"
"702","4.17600","0.34821","0.00638"
"760","4.52400","0.37727","0.00723"
"818","4.87200","0.40621","0.00729"
"876","5.22000","0.43521","0.00771"
"934","5.56800","0.46421","0.00820"
"992","5.91600","0.49320","0.00901"
"1050","6.26400","0.52220","0.00929"
"1108","6.61200","0.55114","0.00983"
"1166","6.96000","0.58026","0.01023"
"1224","7.30800","0.60920","0.01029"
"1282","7.65600","0.63819","0.01057"
"1340","8.00400","0.66719","0.01128"
"1398","8.35200","0.69625","0.01184"
"1456","8.70000","0.72519","0.01243"
"1514","9.04800","0.75424","0.01279"
"1572","9.39600","0.78330","0.01310"
"1630","9.74400","0.81212","0.01317"
"1688","10.09200","0.84124","0.01395"
"1746","10.44000","0.87024","0.01383"
"1804","10.78800","0.89917","0.01424"
"1862","11.13600","0.92823","0.01517"
"1920","11.48400","0.95717","0.01535"
"1978","11.83200","0.98617","0.01502"
"2036","12.18000","1.01523","0.01613"
"2094","12.52800","1.04422","0.01632"
"2152","12.87600","1.07322","0.01646"
"2210","13.22400","1.10228","0.01739"
"2268","13.57200","1.13122","0.01740"
"2326","13.92000","1.16022","0.01756"
"2384","14.26800","1.18927","0.01692"
"2442","14.61600","1.21815","0.01765"
"2500","14.96400","1.24727","0.01843"
"2558","15.31200","1.27621","0.01820"
"2616","15.66000","1.30521","0.01737"
"2674","16.00800","1.33426","0.01818"
"2732","16.35600","1.36320","0.01849"
"2790","16.70400","1.39220","0.01896"
"2848","17.05200","1.42120","0.01925"
"2906","17.40000","1.45025","0.01959"
"2964","17.74800","1.47919","0.01951"
"3022","18.09600","1.50819","0.02024"
"3080","18.44400","1.53713","0.02037"
"3138","18.79200","1.56619","0.02076"
"3196","19.14000","1.59524","0.02062"
"3254","19.48800","1.62418","0.02112"
"3312","19.83600","1.65324","0.02105"
"3370","20.18400","1.68224","0.02151"
"3428","20.53200","1.71112","0.02133"
"3486","20.88000","1.74023","0.02206"
"3544","21.22800","1.76923","0.02277"
"3602","21.57600","1.79817","0.02254"
"3660","21.92400","1.82723","0.02263"
"3718","22.27200","1.85617","0.02280"
"3776","22.62000","1.88516","0.02318"
"3834","22.96800","1.91422","0.02355"
"3892","23.31600","1.94322","0.02391"
"3950","23.66400","1.97216","0.02420"
"4008","24.01200","2.00128","0.02485"
"4066","24.36000","2.03015","0.02505"
"4124","24.70800","2.05921","0.02517"
"4182","25.05600","2.08821","0.02556"
"4240","25.40400","2.11715","0.02575"
"4298","25.75200","2.14615","0.02634"
"4356","26.10000","2.17526","0.02600"
"4414","26.44800","2.20420","0.02648"
"4472","26.79600","2.23320","0.02689"
"4530","27.14400","2.26220","0.02714"
"4588","27.49200","2.29119","0.02771"
"4646","27.84000","2.32025","0.02754"
"4704","28.18800","2.34925","0.02781"
"4762","28.53600","2.37819","0.02792"
"4820","28.88400","2.40725","0.02801"
"4878","29.23200","2.43618","0.02804"
"4936","29.58000","2.46524","0.02881"
"4994","29.92800","2.49424","0.02950"
"5052","30.27600","2.52318","0.03063"
"5110","30.62400","2.55224","0.03025"
"5168","30.97200","2.58123","0.03103"
"5226","31.32000","2.61017","0.03127"
"5284","31.66800","2.63923","0.03238"
"5342","32.01600","2.66823","0.03277"
"5400","32.36400","2.69723","0.03394"
"5458","32.71200","2.72622","0.03394"
"5516","33.06000","2.75522","0.03464"
"5574","33.40800","2.78416","0.03507"
"5632","33.75600","2.81322","0.03554"
"5690","34.10400","2.84222","0.03660"
"5748","34.45200","2.87121","0.03727"
"5806","34.80000","2.90027","0.03754"
"5864","35.14800","2.92915","0.03792"
"5922","35.49600","2.95821","0.03893"
"5980","35.84400","2.98720","0.03912"
"6038","36.19200","3.01620","0.03945"
"6096","36.54000","3.04520","0.04016"
"6154","36.88800","3.07420","0.04077"
"6212","37.23600","3.10320","0.04077"
"6270","37.58400","3.13225","0.04108"
"6328","37.93200","3.16125","0.04095"
"6386","38.28000","3.19013","0.04132"
"6444","38.62800","3.21925","0.04206"
"6502","38.97600","3.24825","0.04249"
"6560","39.32400","3.27718","0.04280"
"6618","39.67200","3.30624","0.04364"
"6676","40.02000","3.33518","0.04439"
"6734","40.36800","3.36424","0.04468"
"6792","40.71600","3.39324","0.04525"
"6850","41.06400","3.42223","0.04585"
"6908","41.41200","3.45117","0.04602"
"6966","41.76000","3.48017","0.04695"
"7024","42.10800","3.50923","0.04799"
"7082","42.45600","3.53822","0.04889"
"7140","42.80400","3.56722","0.04877"
"7198","43.15200","3.59616","0.04904"
"7256","43.50000","3.62522","0.05005"
"7314","43.84800","3.65422","0.05084"
"7372","44.19600","3.68310","0.05196"
"7430","44.54400","3.71221","0.05242"
"7488","44.89200","3.74115","0.05360"
"7546","45.24000","3.77015","0.05436"
"7604","45.58800","3.79927","0.05500"
"7662","45.93600","3.82820","0.05530"
"7720","46.28400","3.85714","0.05669"
"7778","46.63200","3.88626","0.05753"
"7836","46.98000","3.91520","0.05859"
"7894","47.32800","3.94420","0.05945"
"7952","47.67600","3.97325","0.06032"
"8010","48.02400","4.00213","0.06138"
"8068","48.37200","4.03119","0.06253"
"8126","48.72000","4.06019","0.06331"
"8184","49.06800","4.08919","0.06382"
"8242","49.41600","4.11824","0.06452"
"8300","49.76400","4.14718","0.06581"
"8358","50.11200","4.17618","0.06573"
"8416","50.46000","4.20524","0.06632"
"8474","50.80800","4.23423","0.06724"
"8532","51.15600","4.26323","0.06789"
"8590","51.50400","4.29223","0.06857"
"8648","51.85200","4.32123","0.06947"
"8706","52.20000","4.35017","0.06998"
"8764","52.54800","4.37922","0.07028"
"8822","52.89600","4.40816","0.07175"
"8880","53.24400","4.43716","0.07197"
"8938","53.59200","4.46628","0.07269"
"8996","53.94000","4.49522","0.07374"
"9054","54.28800","4.52421","0.07491"
"9112","54.63600","4.55321","0.07613"
"9170","54.98400","4.58215","0.07745"
"9228","55.33200","4.61121","0.07860"
"9286","55.68000","4.64027","0.08008"
"9344","56.02800","4.66920","0.08197"
"9402","56.37600","4.69820","0.08351"
"9460","56.72400","4.72720","0.08438"
"9518","57.07200","4.75620","0.08609"
"9576","57.42000","4.78526","0.08655"
"9634","57.76800","4.81425","0.08790"
"9692","58.11600","4.84319","0.08884"
"9750","58.46400","4.87225","0.08979"
"9808","58.81200","4.90119","0.09093"
"9866","59.16000","4.93024","0.09189"
"9924","59.50800","4.95924","0.09259"
"9982","59.85600","4.98818","0.09276"
"10040","60.20400","5.01724","0.09360"
"10098","60.55200","5.04618","0.09405"
"10156","60.90000","5.07517","0.09457"
"10214","61.24800","5.10417","0.09505"
"10272","61.59600","5.13323","0.09599"
"10330","61.94400","5.16217","0.09681"
"10388","62.29200","5.19123","0.09751"
"10446","62.64000","5.22022","0.09818"
"10504","62.98800","5.24916","0.09896"
"10562","63.33600","5.27822","0.09990"
"10620","63.68400","5.30716","0.10052"
"10678","64.03200","5.33616","0.10150"
"10736","64.38000","5.36527","0.10228"
"10794","64.72800","5.39415","0.10313"
"10852","65.07600","5.42321","0.10379"
"10910","65.42400","5.45221","0.10471"
"10968","65.77200","5.48121","0.10575"
"11026","66.12000","5.51020","0.10648"
"11084","66.46800","5.53926","0.10731"
"11142","66.81600","5.56814","0.10822"
"11200","67.16400","5.59720","0.10928"
"11258","67.51200","5.62619","0.11054"
"11316","67.86000","5.65513","0.11159"
"11374","68.20800","5.68425","0.11227"
"11432","68.55600","5.71319","0.10610"
"11490","68.90400","5.74219","0.10632"
"11548","69.25200","5.77118","0.10682"
"11606","69.60000","5.80024","0.10797"
"11664","69.94800","5.82918","0.10933"
"11722","70.29600","5.85818","0.11037"
"11780","70.64400","5.88724","0.11105"
"11838","70.99200","5.91623","0.11284"
"11896","71.34000","5.94523","0.11408"
"11954","71.68800","5.97417","0.11512"
"12012","72.03600","6.00317","0.11650"
"12070","72.38400","6.03229","0.11737"
"12128","72.73200","6.06110","0.11845"
"12186","73.08000","6.09022","0.11950"
"12244","73.42800","6.11928","0.12083"
"12302","73.77600","6.14816","0.12191"
"12360","74.12400","6.17728","0.12282"
"12418","74.47200","6.20615","0.12486"
"12476","74.82000","6.23515","0.12684"
"12534","75.16800","6.26427","0.12917"
"12592","75.51600","6.29321","0.13043"
"12650","75.86400","6.32215","0.13288"
"12708","76.21200","6.35120","0.13536"
"12766","76.56000","6.38020","0.13796"
"12824","76.90800","6.40920","0.14015"
"12882","77.25600","6.43820","0.14277"
"12940","77.60400","6.46719","0.14460"
"12998","77.95200","6.49625","0.14538"
"13056","78.30000","6.52525","0.14738"
"13114","78.64800","6.55413","0.14895"
"13172","78.99600","6.58325","0.15019"
"13230","79.34400","6.61224","0.15108"
"13288","79.69200","6.64118","0.15308"
"13346","80.04000","6.67024","0.15493"
"13404","80.38800","6.69924","0.15491"
"13462","80.73600","6.72818","0.15739"
"13520","81.08400","6.75723","0.15927"
"13578","81.43200","6.78623","0.16152"
"13636","81.78000","6.81517","0.16370"
"13694","82.12800","6.84429","0.16655"
"13752","82.47600","6.87317","0.16862"
"13810","82.82400","6.90216","0.17025"
"13868","83.17200","6.93116","0.17222"
"13926","83.52000","6.96016","0.17281"
"13984","83.86800","6.98928","0.17471"
"14042","84.21600","7.01822","0.17574"
"14100","84.56400","7.04715","0.17694"
"14158","84.91200","7.07621","0.17792"
"14216","85.26000","7.10527","0.17766"
"14274","85.60800","7.13421","0.17855"
"14332","85.95600","7.16320","0.18013"
"14390","86.30400","7.19220","0.18146"
"14448","86.65200","7.22120","0.18317"
"14506","87.00000","7.25020","0.18516"
"14564","87.34800","7.27920","0.18688"
"14622","87.69600","7.30819","0.18953"
"14680","88.04400","7.33719","0.19082"
"14738","88.39200","7.36619","0.19332"
"14796","88.74000","7.39525","0.19437"
"14854","89.08800","7.42425","0.19597"
"14912","89.43600","7.45318","0.19717"
"14970","89.78400","7.48224","0.19873"
"15028","90.13200","7.51124","0.20091"
"15086","90.48000","7.54012","0.20222"
"15144","90.82800","7.56924","0.20396"
"15202","91.17600","7.59823","0.20587"
"15260","91.52400","7.62717","0.20690"
"15318","91.87200","7.65629","0.20861"
"15376","92.22000","7.68523","0.20986"
"15434","92.56800","7.71417","0.21146"
"15492","92.91600","7.74322","0.21225"
"15550","93.26400","7.77216","0.21364"
"15608","93.61200","7.80122","0.21575"
"15666","93.96000","7.83022","0.21713"
"15724","94.30800","7.85921","0.21953"
"15782","94.65600","7.88821","0.22102"
"15840","95.00400","7.91721","0.22307"
"15898","95.35200","7.94621","0.22444"
"15956","95.70000","7.97521","0.22675"
"16014","96.04800","8.00426","0.22835"
"16072","96.39600","8.03314","0.22972"
"16130","96.74400","8.06226","0.23202"
"16188","97.09200","8.09126","0.23380"
"16246","97.44000","8.12014","0.23642"
"16304","97.78800","8.14925","0.23951"
"16362","98.13600","8.17825","0.24224"
"16420","98.48400","8.20713","0.24410"
"16478","98.83200","8.23625","0.24697"
"16536","99.18000","8.26519","0.24933"
"16594","99.52800","8.29418","0.25091"
"16652","99.87600","8.32318","0.25387"
"16710","100.22400","8.35224","0.25668"
"16768","100.57200","8.38118","0.26043"
"16826","100.92000","8.41029","0.26251"
"16884","101.26800","8.43917","0.26539"
"16942","101.61600","8.46823","0.26845"
"17000","101.96400","8.49723","0.27054"
"17058","102.31200","8.52611","0.27320"
"17116","102.66000","8.55522","0.27509"
"17174","103.00800","8.58422","0.27778"
"17232","103.35600","8.61322","0.28123"
"17290","103.70400","8.64228","0.28569"
"17348","104.05200","8.67122","0.29018"
"17406","104.40000","8.70021","0.29364"
"17464","104.74800","8.72921","0.29700"
"17522","105.09600","8.75821","0.30044"
"17580","105.44400","8.78715","0.30212"
"17638","105.79200","8.81621","0.30456"
"17696","106.14000","8.84520","0.30642"
"17754","106.48800","8.87420","0.30804"
"17812","106.83600","8.90326","0.31008"
"17870","107.18400","8.93214","0.31225"
"17928","107.53200","8.96119","0.31363"
"17986","107.88000","8.99025","0.31585"
"18044","108.22800","9.01919","0.31745"
"18102","108.57600","9.04819","0.31920"
"18160","108.92400","9.07719","0.32121"
"18218","109.27200","9.10618","0.32353"
"18276","109.62000","9.13524","0.32546"
"18334","109.96800","9.16418","0.32716"
"18392","110.31600","9.19318","0.32882"
"18450","110.66400","9.22224","0.33104"
"18508","111.01200","9.25117","0.33260"
"18566","111.36000","9.28023","0.33589"
"18624","111.70800","9.30923","0.33908"
"18682","112.05600","9.33817","0.34336"
"18740","112.40400","9.36723","0.34613"
"18798","112.75200","9.39622","0.34841"
"18856","113.10000","9.42516","0.35077"
"18914","113.44800","9.45422","0.35350"
"18972","113.79600","9.48322","0.35575"
"19030","114.14400","9.51222","0.35763"
"19088","114.49200","9.54121","0.35979"
"19146","114.84000","9.57021","0.36253"
"19204","115.18800","9.59921","0.32263"
"19262","115.53600","9.62821","0.32447"
"19320","115.88400","9.65720","0.32546"
"19378","116.23200","9.68614","0.32731"
"19436","116.58000","9.71526","0.32924"
"19494","116.92800","9.74420","0.33130"
"19552","117.27600","9.77320","0.33379"
"19610","117.62400","9.80225","0.33779"
"19668","117.97200","9.83113","0.34065"
"19726","118.32000","9.86019","0.34460"
"19784","118.66800","9.88925","0.34845"
"19842","119.01600","9.91819","0.35199"
"19900","119.36400","9.94724","0.35487"
"19958","119.71200","9.97624","0.35837"
"20016","120.06000","10.00512","0.36262"
"20074","120.40800","10.03418","0.36724"
"20132","120.75600","10.06318","0.37143"
"20190","121.10400","10.09217","0.37522"
"20248","121.45200","10.12117","0.37788"
"20306","121.80000","10.15017","0.38037"
"20364","122.14800","10.17923","0.38260"
"20422","122.49600","10.20823","0.38536"
"20480","122.84400","10.23722","0.38894"
"20538","123.19200","10.26622","0.39248"
"20596","123.54000","10.29522","0.39600"
"20654","123.88800","10.32422","0.39929"
"20712","124.23600","10.35322","0.40180"
"20770","124.58400","10.38227","0.40439"
"20828","124.93200","10.41109","0.40619"
"20886","125.28000","10.44021","0.40850"
"20944","125.62800","10.46927","0.41064"
"21002","125.97600","10.49815","0.41258"
"21060","126.32400","10.52720","0.41482"
"21118","126.67200","10.55620","0.41700"
"21176","127.02000","10.58520","0.41843"
"21234","127.36800","10.61426","0.42143"
"21292","127.71600","10.64319","0.42375"
"21350","128.06400","10.67219","0.42796"
"21408","128.41200","10.70119","0.43167"
"21466","128.76000","10.73025","0.43514"
"21524","129.10800","10.75919","0.43850"
"21582","129.45600","10.78824","0.44136"
"21640","129.80400","10.81724","0.44528"
"21698","130.15200","10.84618","0.44803"
"21756","130.50000","10.87524","0.45126"
"21814","130.84800","10.90418","0.45419"
"21872","131.19600","10.93323","0.45662"
"21930","131.54400","10.96223","0.45867"
"21988","131.89200","10.99117","0.46223"
"22046","132.24000","11.02023","0.46603"
"22104","132.58800","11.04923","0.47067"
"22162","132.93600","11.07816","0.47512"
"22220","133.28400","11.10722","0.47875"
"22278","133.63200","11.13622","0.48126"
"22336","133.98000","11.16522","0.48392"
"22394","134.32800","11.19427","0.48808"
"22452","134.67600","11.22315","0.49223"
"22510","135.02400","11.25221","0.49716"
"22568","135.37200","11.28127","0.50191"
"22626","135.72000","11.31021","0.50594"
"22684","136.06800","11.33926","0.51063"
"22742","136.41600","11.36820","0.51389"
"22800","136.76400","11.39714","0.51698"
"22858","137.11200","11.42620","0.51933"
"22916","137.46000","11.45520","0.52148"
"22974","137.80800","11.48419","0.52368"
"23032","138.15600","11.51325","0.52647"
"23090","138.50400","11.54225","0.52975"
"23148","138.85200","11.57119","0.53306"
"23206","139.20000","11.60025","0.53677"
"23264","139.54800","11.62918","0.54003"
"23322","139.89600","11.65818","0.54349"
"23380","140.24400","11.68724","0.54840"
"23438","140.59200","11.71618","0.55211"
"23496","140.94000","11.74518","0.55602"
"23554","141.28800","11.77423","0.55999"
"23612","141.63600","11.80317","0.56390"
"23670","141.98400","11.83223","0.56898"
"23728","142.33200","11.86123","0.57434"
"23786","142.68000","11.89022","0.57980"
"23844","143.02800","11.91922","0.58390"
"23902","143.37600","11.94822","0.58719"
"23960","143.72400","11.97716","0.59145"
"24018","144.07200","12.00622","0.59613"
"24076","144.42000","12.03522","0.60128"
"24134","144.76800","12.06421","0.60469"
"24192","145.11600","12.09327","0.60727"
"24250","145.46400","12.12221","0.61045"
"24308","145.81200","12.15121","0.61391"
"24366","146.16000","12.18020","0.61728"
"24424","146.50800","12.20914","0.62122"
"24482","146.85600","12.23826","0.62445"
"24540","147.20400","12.26720","0.62711"
"24598","147.55200","12.29614","0.63089"
"24656","147.90000","12.32519","0.63464"
"24714","148.24800","12.35419","0.63864"
"24772","148.59600","12.38319","0.64391"
"24830","148.94400","12.41219","0.64975"
"24888","149.29200","12.44131","0.65545"
"24946","149.64000","12.47018","0.66103"
"25004","149.98800","12.49924","0.66451"
"25062","150.33600","12.52824","0.66934"
"25120","150.68400","12.55718","0.67455"
"25178","151.03200","12.58623","0.68210"
"25236","151.38000","12.61523","0.68664"
"25294","151.72800","12.64417","0.69065"
"25352","152.07600","12.67323","0.69403"
"25410","152.42400","12.70223","0.69788"
"25468","152.77200","12.73123","0.70352"
"25526","153.12000","12.76022","0.70960"
"25584","153.46800","12.78922","0.71338"
"25642","153.81600","12.81816","0.71776"
"25700","154.16400","12.84728","0.72078"
"25758","154.51200","12.87615","0.72391"
"25816","154.86000","12.90521","0.72674"
"25874","155.20800","12.93427","0.72980"
"25932","155.55600","12.96321","0.73398"
"25990","155.90400","12.99227","0.71351"
"26048","156.25200","13.02114","0.71715"
"26106","156.60000","13.05020","0.72003"
"26164","156.94800","13.07920","0.72360"
"26222","157.29600","13.10820","0.72622"
"26280","157.64400","13.13720","0.72986"
"26338","157.99200","13.16619","0.73403"
"26396","158.34000","13.19519","0.73831"
"26454","158.68800","13.22419","0.74217"
"26512","159.03600","13.25325","0.74585"
"26570","159.38400","13.28213","0.75104"
"26628","159.73200","13.31124","0.75710"
"26686","160.08000","13.34024","0.76191"
"26744","160.42800","13.36912","0.76730"
"26802","160.77600","13.39830","0.77426"
"26860","161.12400","13.42724","0.78185"
"26918","161.47200","13.45623","0.78973"
"26976","161.82000","13.48529","0.79353"
"27034","162.16800","13.51423","0.79921"
"27092","162.51600","13.54317","0.80532"
"27150","162.86400","13.57222","0.81311"
"27208","163.21200","13.60122","0.81930"
"27266","163.56000","13.63022","0.82443"
"27324","163.90800","13.65928","0.82886"
"27382","164.25600","13.68816","0.83163"
"27440","164.60400","13.71721","0.83444"
"27498","164.95200","13.74621","0.83688"
"27556","165.30000","13.77515","0.84034"
"27614","165.64800","13.80427","0.84456"
"27672","165.99600","13.83321","0.84892"
"27730","166.34400","13.86220","0.85402"
"27788","166.69200","13.89120","0.85950"
"27846","167.04000","13.92020","0.86490"
"27904","167.38800","13.94920","0.86911"
"27962","167.73600","13.97826","0.87324"
"28020","168.08400","14.00725","0.88000"
"28078","168.43200","14.03619","0.88641"
"28136","168.78000","14.06525","0.85040"
"28194","169.12800","14.09419","0.85226"
"28252","169.47600","14.12319","0.82601"
"28310","169.82400","14.15224","0.82848"
"28368","170.17200","14.18118","0.83188"
"28426","170.52000","14.21024","0.83581"
"28484","170.86800","14.23918","0.83907"
"28542","171.21600","14.26817","0.84370"
"28600","171.56400","14.29723","0.84704"
"28658","171.91200","14.32623","0.85233"
"28716","172.26000","14.35517","0.85709"
"28774","172.60800","14.38423","0.86350"
"28832","172.95600","14.41328","0.86724"
"28890","173.30400","14.44216","0.83451"
"28948","173.65200","14.47122","0.83882"
"29006","174.00000","14.50022","0.84423"
"29064","174.34800","14.52921","0.84962"
"29122","174.69600","14.55827","0.85623"
"29180","175.04400","14.58721","0.86362"
"29238","175.39200","14.61621","0.86860"
"29296","175.74000","14.64521","0.87443"
"29354","176.08800","14.67421","0.88303"
"29412","176.43600","14.70326","0.89059"
"29470","176.78400","14.73220","0.84932"
"29528","177.13200","14.76120","0.85180"
"29586","177.48000","14.79020","0.85605"
"29644","177.82800","14.81925","0.86165"
"29702","178.17600","14.84819","0.86668"
"29760","178.52400","14.87725","0.86636"
"29818","178.87200","14.90625","0.87086"
"29876","179.22000","14.93519","0.87551"
"29934","179.56800","14.96424","0.88335"
"29992","179.91600","14.99318","0.89092"
"30050","180.26400","15.02224","0.89640"
"30108","180.61200","15.05118","0.90268"
"30166","180.96000","15.08018","0.90944"
"30224","181.30800","15.10923","0.91523"
"30282","181.65600","15.13817","0.92099"
"30340","182.00400","15.16717","0.92687"
"30398","182.35200","15.19617","0.93267"
"30456","182.70000","15.22528","0.93611"
"30514","183.04800","15.25416","0.94020"
"30572","183.39600","15.28322","0.94569"
"30630","183.74400","15.31222","0.95335"
"30688","184.09200","15.34116","0.96316"
"30746","184.44000","15.37028","0.97100"
"30804","184.78800","15.39921","0.97612"
"30862","185.13600","15.42821","0.98244"
"30920","185.48400","15.45721","0.99193"
"30978","185.83200","15.48615","0.99961"
"31036","186.18000","15.51515","1.00425"
"31094","186.52800","15.54420","1.00981"
"31152","186.87600","15.57320","1.01616"
"31210","187.22400","15.60226","1.02098"
"31268","187.57200","15.63120","1.02462"
"31326","187.92000","15.66019","1.02719"
"31384","188.26800","15.68919","1.03049"
"31442","188.61600","15.71825","1.03256"
"31500","188.96400","15.74719","1.03518"
"31558","189.31200","15.77625","1.03961"
"31616","189.66000","15.80524","1.04412"
"31674","190.00800","15.83418","1.04684"
"31732","190.35600","15.86318","1.05257"
"31790","190.70400","15.89218","1.06145"
"31848","191.05200","15.92118","1.05518"
"31906","191.40000","15.95023","1.04171"
"31964","191.74800","15.97923","1.04633"
"32022","192.09600","16.00817","1.05178"
"32080","192.44400","16.03723","1.00355"
"32138","192.79200","16.06623","1.00586"
"32196","193.14000","16.09516","0.98821"
"32254","193.48800","16.12428","0.99252"
"32312","193.83600","16.15316","1.00004"
"32370","194.18400","16.18222","1.00495"
"32428","194.53200","16.21121","1.01112"
"32486","194.88000","16.24015","0.88607"
"32544","195.22800","16.26927","0.88876"
"32602","195.57600","16.29827","0.89275"
"32660","195.92400","16.32721","0.89686"
"32718","196.27200","16.35626","0.90892"
"32776","196.62000","16.38520","0.91232"
"32834","196.96800","16.41414","0.92203"
"32892","197.31600","16.44320","0.92951"
"32950","197.66400","16.47220","0.93084"
"33008","198.01200","16.50113","0.93439"
"33066","198.36000","16.53019","0.91766"
"33124","198.70800","16.55925","0.92550"
"33182","199.05600","16.58819","0.93387"
"33240","199.40400","16.61718","0.93679"
"33298","199.75200","16.64612","0.94164"
"33356","200.10000","16.67524","0.95334"
"33414","200.44800","16.70424","0.96069"
"33472","200.79600","16.73318","0.97017"
"33530","201.14400","16.76217","0.98006"
"33588","201.49200","16.79123","0.98475"
"33646","201.84000","16.82017","0.99360"
"33704","202.18800","16.84923","1.00291"
"33762","202.53600","16.87823","1.00509"
"33820","202.88400","16.90717","1.00727"
"33878","203.23200","16.93622","1.01680"
"33936","203.58000","16.96516","1.02248"
"33994","203.92800","16.99416","1.02548"
"34052","204.27600","17.02321","1.02999"
"34110","204.62400","17.05215","1.03485"
"34168","204.97200","17.08121","1.03952"
"34226","205.32000","17.11015","1.04389"
"34284","205.66800","17.13921","1.05166"
"34342","206.01600","17.16821","1.06148"
"34400","206.36400","17.19726","1.06919"
"34458","206.71200","17.22620","0.93514"
"34516","207.06000","17.25520","0.93766"
"34574","207.40800","17.28426","0.94699"
"34632","207.75600","17.31314","0.95439"
"34690","208.10400","17.34219","0.96589"
"34748","208.45200","17.37125","0.97725"
"34806","208.80000","17.40019","0.98466"
"34864","209.14800","17.42925","0.99501"
"34922","209.49600","17.45819","1.00212"
"34980","209.84400","17.48718","1.00896"
"35038","210.19200","17.51624","1.01922"
"35096","210.54000","17.54524","1.02614"
"35154","210.88800","17.57418","1.03258"
"35212","211.23600","17.60323","1.03684"
"35270","211.58400","17.63217","1.04413"
"35328","211.93200","17.66117","1.05431"
"35386","212.28000","17.69023","1.06839"
"35444","212.62800","17.71917","1.07642"
"35502","212.97600","17.74822","1.08726"
"35560","213.32400","17.77722","1.09915"
"35618","213.67200","17.80616","1.10525"
"35676","214.02000","17.83522","1.11539"
"35734","214.36800","17.86422","1.12546"
"35792","214.71600","17.89327","1.13498"
"35850","215.06400","17.92221","1.14158"
"35908","215.41200","17.95121","1.14493"
"35966","215.76000","17.98021","1.14833"
"36024","216.10800","18.00920","1.15309"
"36082","216.45600","18.03826","1.15847"
"36140","216.80400","18.06720","1.16663"
"36198","217.15200","18.09626","1.17237"
"36256","217.50000","18.12514","1.17805"
"36314","217.84800","18.15425","1.18833"
"36372","218.19600","18.18325","1.19972"
"36430","218.54400","18.21213","1.20709"
"36488","218.89200","18.24125","1.21597"
"36546","219.24000","18.27025","1.22431"
"36604","219.58800","18.29913","1.23157"
"36662","219.93600","18.32824","1.23968"
"36720","220.28400","18.35718","1.24632"
"36778","220.63200","18.38618","1.25181"
"36836","220.98000","18.41524","1.26000"
"36894","221.32800","18.44423","1.27010"
"36952","221.67600","18.47317","1.27865"
"37010","222.02400","18.50223","1.28532"
"37068","222.37200","18.53117","1.29141"
"37126","222.72000","18.56017","1.30028"
"37184","223.06800","18.58922","1.30654"
"37242","223.41600","18.61822","1.31285"
"37300","223.76400","18.64722","1.32228"
"37358","224.11200","18.67628","1.32802"
"37416","224.46000","18.70522","1.33404"
"37474","224.80800","18.73421","1.34139"
"37532","225.15600","18.76321","1.34799"
"37590","225.50400","18.79221","1.35382"
"37648","225.85200","18.82121","1.36007"
"37706","226.20000","18.85027","1.37169"
"37764","226.54800","18.87920","1.38421"
"37822","226.89600","18.90820","1.39251"
"37880","227.24400","18.93720","1.40236"
"37938","227.59200","18.96620","1.41295"
"37996","227.94000","18.99519","1.42225"
"38054","228.28800","19.02413","1.25301"
"38112","228.63600","19.05319","1.24979"
"38170","228.98400","19.08219","1.25194"
"38228","229.33200","19.11119","1.25886"
"38286","229.68000","19.14024","1.26794"
"38344","230.02800","19.16924","1.28093"
"38402","230.37600","19.19824","1.28818"
"38460","230.72400","19.22724","1.29805"
"38518","231.07200","19.25624","1.30476"
"38576","231.42000","19.28517","1.31054"
"38634","231.76800","19.31423","1.31828"
"38692","232.11600","19.34323","1.32019"
"38750","232.46400","19.37223","1.32476"
"38808","232.81200","19.40123","1.16737"
"38866","233.16000","19.43016","0.93331"
"38924","233.50800","19.45916","0.92888"
"38982","233.85600","19.48822","0.93154"
"39040","234.20400","19.51722","0.92936"
"39098","234.55200","19.54622","0.93476"
"39156","234.90000","19.57521","0.94041"
"39214","235.24800","19.60415","0.94158"
"39272","235.59600","19.63321","0.95053"
"39330","235.94400","19.66227","0.95952"
"39388","236.29200","19.69114","0.96657"
"39446","236.64000","19.72020","0.96106"
"39504","236.98800","19.74926","0.96771"
"39562","237.33600","19.77814","0.97406"
"39620","237.68400","19.80726","0.98429"
"39678","238.03200","19.83619","0.99110"
"39736","238.38000","19.86519","0.99497"
"39794","238.72800","19.89425","1.00422"
"39852","239.07600","19.92319","1.01239"
"39910","239.42400","19.95218","1.01777"
"39968","239.77200","19.98118","1.02497"
"40026","240.12000","20.01018","1.03006"
"40084","240.46800","20.03924","1.03270"
"40142","240.81600","20.06824","1.03848"
"40200","241.16400","20.09718","1.04557"
"40258","241.51200","20.12617","1.05130"
"40316","241.86000","20.15529","1.06015"
"40374","242.20800","20.18417","1.07301"
"40432","242.55600","20.21323","1.08253"
"40490","242.90400","20.24222","1.09160"
"40548","243.25200","20.27116","1.09882"
"40606","243.60000","20.30022","1.10712"
"40664","243.94800","20.32922","1.11606"
"40722","244.29600","20.35815","1.12416"
"40780","244.64400","20.38721","1.04250"
"40838","244.99200","20.41621","0.84677"
"40896","245.34000","20.44521","0.49859"
"40954","245.68800","20.47421","0.48217"
"41012","246.03600","20.50321","0.48135"
"41070","246.38400","20.53220","0.49983"
"41128","246.73200","20.56126","0.49083"
"41186","247.08000","20.59008","0.49284"
"41244","247.42800","20.61926","0.49638"
"41302","247.77600","20.64820","0.51607"
"41360","248.12400","20.67713","0.51004"
"41418","248.47200","20.70625","0.51296"
"41476","248.82000","20.73519","0.52096"
"41534","249.16800","20.76419","0.53027"
"41592","249.51600","20.79318","0.52545"
"41650","249.86400","20.82224","0.52734"
"41708","250.21200","20.85118","0.54053"
"41766","250.56000","20.88018","0.54715"
"41824","250.90800","20.90924","0.54788"
"41882","251.25600","20.93817","0.55928"
"41940","251.60400","20.96723","0.56791"
"41998","251.95200","20.99617","0.56248"
"42056","252.30000","21.02523","0.55581"
"42114","252.64800","21.05423","0.56616"
"42172","252.99600","21.08311","0.56151"
"42230","253.34400","21.11222","0.57126"
"42288","253.69200","21.14122","0.58426"
"42346","254.04000","21.17016","0.58196"
"42404","254.38800","21.19921","0.58921"
"42462","254.73600","21.22821","0.60141"
"42520","255.08400","21.25715","0.60127"
"42578","255.43200","21.28627","0.61071"
"42636","255.78000","21.31515","0.61950"
"42694","256.12800","21.34420","0.62133"
"42752","256.47600","21.37332","0.63125"
"42810","256.82400","21.40220","0.63497"
"42868","257.17200","21.43120","0.64013"
"42926","257.52000","21.46026","0.65607"
"42984","257.86800","21.48913","0.65770"
"43042","258.21600","21.51825","0.66992"
"43100","258.56400","21.54719","0.67869"
"43158","258.91200","21.57619","0.68687"
"43216","259.26000","21.60525","0.69594"
"43274","259.60800","21.63424","0.70089"
"43332","259.95600","21.66324","0.71549"
"43390","260.30400","21.69218","0.71860"
"43448","260.65200","21.72124","0.72573"
"43506","261.00000","21.75017","0.72946"
"43564","261.34800","21.77924","0.73624"
"43622","261.69600","21.80823","0.74199"
"43680","262.04400","21.83717","0.74890"
"43738","262.39200","21.86623","0.76213"
"43796","262.74000","21.89517","0.77022"
"43854","263.08800","21.92422","0.78464"
"43912","263.43600","21.95328","0.79235"
"43970","263.78400","21.98216","0.80383"
"44028","264.13200","22.01122","0.81418"
"44086","264.48000","22.04022","0.82364"
"44144","264.82800","22.06921","0.83032"
"44202","265.17600","22.09821","0.83500"
"44260","265.52400","22.12721","0.83991"
"44318","265.87200","22.15615","0.72809"
"44376","266.22000","22.18527","0.64335"
"44434","266.56800","22.21420","0.44280"
"44492","266.91600","22.24320","0.44323"
"44550","267.26400","22.27220","0.43661"
"44608","267.61200","22.30114","0.44650"
"44666","267.96000","22.33019","0.45714"
"44724","268.30800","22.35925","0.38560"
"44782","268.65600","22.38819","0.38078"
"44840","269.00400","22.41719","0.31693"
"44898","269.35200","22.44625","0.31218"
"44956","269.70000","22.47518","0.32571"
"45014","270.04800","22.50418","0.32206"
"45072","270.39600","22.53330","0.33513"
"45130","270.74400","22.56212","0.33533"
"45188","271.09200","22.59124","0.34651"
"45246","271.44000","22.62024","0.35896"
"45304","271.78800","22.64917","0.35814"
"45362","272.13600","22.67823","0.37646"
"45420","272.48400","22.70723","0.37857"
"45478","272.83200","22.73623","0.38155"
"45536","273.18000","22.76522","0.39302"
"45594","273.52800","22.79422","0.39354"
"45652","273.87600","22.82322","0.40168"
"45710","274.22400","22.85222","0.40940"
"45768","274.57200","22.88122","0.41193"
"45826","274.92000","22.91015","0.41742"
"45884","275.26800","22.93921","0.42565"
"45942","275.61600","22.96821","0.42920"
"46000","275.96400","22.99721","0.43606"
"46058","276.31200","23.02626","0.44738"
"46116","276.66000","23.05520","0.45397"
"46174","277.00800","23.08420","0.45793"
"46232","277.35600","23.11320","0.12736"
"46290","277.70400","23.14220","0.13042"
"46348","278.05200","23.17125","0.14504"
"46406","278.40000","23.20025","0.15438"
"46464","278.74800","23.22919","0.17297"
"46522","279.09600","23.25825","0.18546"
"46580","279.44400","23.28725","0.18782"
"46638","279.79200","23.31618","0.18474"
"46696","280.14000","23.34524","0.18477"
"46754","280.48800","23.37418","0.18780"
"46812","280.83600","23.40318","0.19207"
"46870","281.18400","23.43224","0.19903"
"46928","281.53200","23.46111","0.20213"
"46986","281.88000","23.49023","0.20565"
"47044","282.22800","23.51923","0.20978"
"47102","282.57600","23.54817","0.14358"
"47160","282.92400","23.57722","0.12195"
"47218","283.27200","23.60622","0.13565"
"47276","283.62000","23.63522","0.14709"
"47334","283.96800","23.66422","0.15419"
"47392","284.31600","23.69322","0.15990"
"47450","284.66400","23.72221","0.16185"
"47508","285.01200","23.75121","0.15992"
"47566","285.36000","23.78021","0.15981"
"47624","285.70800","23.80915","0.16549"
"47682","286.05600","23.83826","0.17305"
"47740","286.40400","23.86714","0.17755"
"47798","286.75200","23.89626","0.18156"
"47856","287.10000","23.92520","0.18787"
"47914","287.44800","23.95414","0.19541"
"47972","287.79600","23.98320","0.20064"
"48030","288.14400","24.01220","0.20538"
"48088","288.49200","24.04119","0.20930"
"48146","288.84000","24.07019","0.21238"
"48204","289.18800","24.09925","0.21486"
"48262","289.53600","24.12819","0.21772"
"48320","289.88400","24.15724","0.22168"
"48378","290.23200","24.18624","0.22529"
"48436","290.58000","24.21518","0.22829"
"48494","290.92800","24.24430","0.23216"
"48552","291.27600","24.27317","0.23469"
"48610","291.62400","24.30217","0.23824"
"48668","291.97200","24.33123","0.06930"
"48726","292.32000","24.36017","0.06229"
"48784","292.66800","24.38923","0.07317"
"48842","293.01600","24.41816","0.08833"
"48900","293.36400","24.44716","0.07873"
"48958","293.71200","24.47616","0.07580"
"49016","294.06000","24.50522","0.08694"
"49074","294.40800","24.53416","0.09382"
"49132","294.75600","24.56321","0.09451"
"49190","295.10400","24.59227","0.09330"
"49248","295.45200","24.62115","0.09675"
"49306","295.80000","24.65027","0.10266"
"49364","296.14800","24.67921","0.10659"
"49422","296.49600","24.70820","0.10768"
"49480","296.84400","24.73720","0.10909"
"49538","297.19200","24.76620","0.11349"
"49596","297.54000","24.79520","0.11870"
"49654","297.88800","24.82420","0.12271"
"49712","298.23600","24.85325","0.12537"
"49770","298.58400","24.88219","0.13008"
"49828","298.93200","24.91125","0.13763"
"49886","299.28000","24.94013","0.14399"
"49944","299.62800","24.96924","0.14824"
"50002","299.97600","24.99824","0.15157"
"50060","300.32400","25.02712","0.15571"
"50118","300.67200","25.05624","0.09676"
"50176","301.02000","25.08517","0.07501"
"50234","301.36800","25.11418","0.07978"
"50292","301.71600","25.14323","0.09743"
"50350","302.06400","25.17223","0.09025"
"50408","302.41200","25.20117","0.08616"
"50466","302.76000","25.23023","0.09675"
"50524","303.10800","25.25922","0.10068"
"50582","303.45600","25.28816","0.09559"
"50640","303.80400","25.31722","0.09610"
"50698","304.15200","25.34622","0.10346"
"50756","304.50000","25.37522","0.10691"
"50814","304.84800","25.40421","0.10369"
"50872","305.19600","25.43315","0.10400"
"50930","305.54400","25.46227","0.11076"
"50988","305.89200","25.49127","0.11533"
"51046","306.24000","25.52015","0.11514"
"51104","306.58800","25.54921","0.11459"
"51162","306.93600","25.57820","0.11667"
"51220","307.28400","25.60714","0.12042"
"51278","307.63200","25.63626","0.12404"
"51336","307.98000","25.66519","0.12516"
"51394","308.32800","25.69425","0.12655"
"51452","308.67600","25.72319","0.13039"
"51510","309.02400","25.75219","0.13714"
"51568","309.37200","25.78119","0.14093"
"51626","309.72000","25.81025","0.14318"
"51684","310.06800","25.83918","0.14536"
"51742","310.41600","25.86824","0.14802"
"51800","310.76400","25.89724","0.15095"
"51858","311.11200","25.92618","0.15360"
"51916","311.46000","25.95518","0.15706"
"51974","311.80800","25.98417","0.15978"
"52032","312.15600","26.01317","0.16352"
"52090","312.50400","26.04229","0.16729"
"52148","312.85200","26.07122","0.17112"
"52206","313.20000","26.10017","0.17376"
"52264","313.54800","26.12922","0.17497"
"52322","313.89600","26.15822","0.17641"
"52380","314.24400","26.18716","0.17699"
"52438","314.59200","26.21627","0.04549"
"52496","314.94000","26.24516","0.03783"
"52554","315.28800","26.27421","0.03231"
"52612","315.63600","26.30321","0.04170"
"52670","315.98400","26.33215","0.04677"
"52728","316.33200","26.36121","0.03834"
"52786","316.68000","26.39020","0.03617"
"52844","317.02800","26.41920","0.04456"
"52902","317.37600","26.44826","0.04878"
"52960","317.72400","26.47726","0.04320"
"53018","318.07200","26.50620","0.04394"
"53076","318.42000","26.53519","0.05078"
"53134","318.76800","26.56425","0.05357"
"53192","319.11600","26.59319","0.04855"
"53250","319.46400","26.62225","0.04549"
"53308","319.81200","26.65118","0.05242"
"53366","320.16000","26.68018","0.06149"
"53424","320.50800","26.70918","0.05935"
"53482","320.85600","26.73824","0.05645"
"53540","321.20400","26.76723","0.06113"
"53598","321.55200","26.79617","0.06549"
"53656","321.90000","26.82517","0.06682"
"53714","322.24800","26.85423","0.06676"
"53772","322.59600","26.88323","0.06851"
"53830","322.94400","26.91217","0.07155"
"53888","323.29200","26.94123","0.07488"
"53946","323.64000","26.97022","0.07661"
"54004","323.98800","26.99916","0.07753"
"54062","324.33600","27.02822","0.08223"
"54120","324.68400","27.05721","0.08668"
"54178","325.03200","27.08621","0.08972"
"54236","325.38000","27.11527","0.09063"
"54294","325.72800","27.14421","0.08410"
"54352","326.07600","27.17321","0.08688"
"54410","326.42400","27.20220","0.08954"
"54468","326.77200","27.23120","0.09176"
"54526","327.12000","27.26020","0.09337"
"54584","327.46800","27.28920","0.09265"
"54642","327.81600","27.31820","0.09412"
"54700","328.16400","27.34720","0.09623"
"54758","328.51200","27.37625","0.09870"
"54816","328.86000","27.40513","0.10077"
"54874","329.20800","27.43425","0.10333"
"54932","329.55600","27.46325","0.10384"
"54990","329.90400","27.49212","0.10058"
"55048","330.25200","27.52124","0.10195"
"55106","330.60000","27.55018","0.10469"
"55164","330.94800","27.57918","0.10779"
"55222","331.29600","27.60824","0.11171"
"55280","331.64400","27.63723","0.11240"
"55338","331.99200","27.66617","0.11502"
"55396","332.34000","27.69517","0.11728"
"55454","332.68800","27.72417","0.11708"
"55512","333.03600","27.75317","0.11505"
"55570","333.38400","27.78222","0.11733"
"55628","333.73200","27.81116","0.11965"
"55686","334.08000","27.84022","0.12218"
"55744","334.42800","27.86922","0.12604"
"55802","334.77600","27.89816","0.12847"
"55860","335.12400","27.92721","0.13293"
"55918","335.47200","27.95621","0.13803"
"55976","335.82000","27.98515","0.14177"
"56034","336.16800","28.01421","0.14561"
"56092","336.51600","28.04320","0.14311"
"56150","336.86400","28.07220","0.14701"
"56208","337.21200","28.10120","0.14944"
"56266","337.56000","28.13020","0.15238"
"56324","337.90800","28.15914","0.15538"
"56382","338.25600","28.18826","0.15763"
"56440","338.60400","28.21719","0.16162"
"56498","338.95200","28.24619","0.16666"
"56556","339.30000","28.27525","0.17018"
"56614","339.64800","28.30413","0.17281"
"56672","339.99600","28.33324","0.17475"
"56730","340.34400","28.36224","0.17744"
"56788","340.69200","28.39118","0.17726"
"56846","341.04000","28.42024","0.18028"
"56904","341.38800","28.44918","0.17888"
"56962","341.73600","28.47818","0.18148"
"57020","342.08400","28.50723","0.18498"
"57078","342.43200","28.53623","0.18774"
"57136","342.78000","28.56517","0.19049"
"57194","343.12800","28.59422","0.19352"
"57252","343.47600","28.62322","0.19604"
"57310","343.82400","28.65216","0.19893"
"57368","344.17200","28.68122","0.20109"
"57426","344.52000","28.71016","0.20417"
"57484","344.86800","28.73922","0.20636"
"57542","345.21600","28.76821","0.20819"
"57600","345.56400","28.79715","0.20969"
"57658","345.91200","28.82621","0.21053"
"57716","346.26000","28.85521","0.21026"
"57774","346.60800","28.88421","0.21176"
"57832","346.95600","28.91320","0.21384"
"57890","347.30400","28.94226","0.21550"
"57948","347.65200","28.97114","0.21832"
"58006","348.00000","29.00019","0.22099"
"58064","348.34800","29.02925","0.22358"
"58122","348.69600","29.05819","0.22521"
"58180","349.04400","29.08725","0.22735"
"58238","349.39200","29.11619","0.01811"
"58296","349.74000","29.14525","0.03227"
"58354","350.08800","29.17418","0.06719"
"58412","350.43600","29.20318","0.02861"
"58470","350.78400","29.23218","0.02531"
"58528","351.13200","29.26118","0.05634"
"58586","351.48000","29.29018","0.06800"
"58644","351.82800","29.31917","0.04191"
"58702","352.17600","29.34823","0.04198"
"58760","352.52400","29.37717","0.06389"
"58818","352.87200","29.40617","0.06813"
"58876","353.22000","29.43522","0.05559"
"58934","353.56800","29.46416","0.05505"
"58992","353.91600","29.49322","0.06790"
"59050","354.26400","29.52216","0.07586"
"59108","354.61200","29.55122","0.07216"
"59166","354.96000","29.58027","0.06942"
"59224","355.30800","29.60921","0.07475"
"59282","355.65600","29.63821","0.08624"
"59340","356.00400","29.66721","0.08803"
"59398","356.35200","29.69615","0.08298"
"59456","356.70000","29.72520","0.08047"
"59514","357.04800","29.75426","0.08894"
"59572","357.39600","29.78314","0.09329"
"59630","357.74400","29.81220","0.09495"
"59688","358.09200","29.84126","0.09399"
"59746","358.44000","29.87013","0.09490"
"59804","358.78800","29.89925","0.09790"
"59862","359.13600","29.92825","0.10139"
"59920","359.48400","29.95719","0.10201"
"59978","359.83200","29.98624","0.10212"
"60036","360.18000","30.01518","0.10387"
"60094","360.52800","30.04418","0.10809"
"60152","360.87600","30.07324","0.11126"
"60210","361.22400","30.10224","0.11310"
"60268","361.57200","30.13124","0.11516"
"60326","361.92000","30.16023","0.11714"
"60384","362.26800","30.18917","0.11948"
"60442","362.61600","30.21817","0.12333"
"60500","362.96400","30.24723","0.12789"
"60558","363.31200","30.27617","0.13135"
"60616","363.66000","30.30522","0.13315"
"60674","364.00800","30.33422","0.13752"
"60732","364.35600","30.36316","0.14016"
"60790","364.70400","30.39221","0.14413"
"60848","365.05200","30.42122","0.14796"
"60906","365.40000","30.45015","0.14986"
"60964","365.74800","30.47927","0.15160"
"61022","366.09600","30.50821","0.15637"
"61080","366.44400","30.53721","0.16206"
"61138","366.79200","30.56620","0.16662"
"61196","367.14000","30.59520","0.17049"
"61254","367.48800","30.62414","0.17470"
"61312","367.83600","30.65326","0.17767"
"61370","368.18400","30.68220","0.17815"
"61428","368.53200","30.71125","0.18088"
"61486","368.88000","30.74019","0.17289"
"61544","369.22800","30.76913","0.17685"
"61602","369.57600","30.79819","0.18305"
"61660","369.92400","30.82724","0.18738"
"61718","370.27200","30.85625","0.18938"
"61776","370.62000","30.88518","0.19256"
"61834","370.96800","30.91424","0.19571"
"61892","371.31600","30.94318","0.19938"
"61950","371.66400","30.97223","0.20289"
"62008","372.01200","31.00117","0.20659"
"62066","372.36000","31.03017","0.20926"
"62124","372.70800","31.05929","0.21042"
"62182","373.05600","31.08823","0.21279"
"62240","373.40400","31.11716","0.21603"
"62298","373.75200","31.14622","0.21869"
"62356","374.10000","31.17516","0.22236"
"62414","374.44800","31.20422","0.22528"
"62472","374.79600","31.23322","0.22839"
"62530","375.14400","31.26221","0.23151"
"62588","375.49200","31.29121","0.23489"
"62646","375.84000","31.32021","0.23873"
"62704","376.18800","31.34914","0.24220"
"62762","376.53600","31.37820","0.24573"
"62820","376.88400","31.40714","0.25021"
"62878","377.23200","31.43620","0.25342"
"62936","377.58000","31.46526","0.25700"
"62994","377.92800","31.49420","0.26096"
"63052","378.27600","31.52319","0.26577"
"63110","378.62400","31.55225","0.27003"
"63168","378.97200","31.58119","0.27320"
"63226","379.32000","31.61019","0.27624"
"63284","379.66800","31.63918","0.28070"
"63342","380.01600","31.66818","0.28626"
"63400","380.36400","31.69718","0.29211"
"63458","380.71200","31.72624","0.29765"
"63516","381.06000","31.75517","0.30127"
"63574","381.40800","31.78424","0.30405"
"63632","381.75600","31.81323","0.30708"
"63690","382.10400","31.84211","0.31010"
"63748","382.45200","31.87129","0.31273"
"63806","382.80000","31.90023","0.31541"
"63864","383.14800","31.92916","0.31826"
"63922","383.49600","31.95822","0.32096"
"63980","383.84400","31.98716","0.32328"
"64038","384.19200","32.01616","0.32576"
"64096","384.54000","32.04528","0.32499"
"64154","384.88800","32.07415","0.32617"
"64212","385.23600","32.10321","0.20261"
"64270","385.58400","32.13221","0.21352"
"64328","385.93200","32.16121","0.21688"
"64386","386.28000","32.19021","0.21809"
"64444","386.62800","32.21926","0.22222"
"64502","386.97600","32.24814","0.22643"
"64560","387.32400","32.27720","0.22774"
"64618","387.67200","32.30620","0.23212"
"64676","388.02000","32.33520","0.23936"
"64734","388.36800","32.36419","0.24379"
"64792","388.71600","32.39325","0.24595"
"64850","389.06400","32.42219","0.25105"
"64908","389.41200","32.45124","0.25512"
"64966","389.76000","32.48018","0.25804"
"65024","390.10800","32.50918","0.26284"
"65082","390.45600","32.53824","0.26861"
"65140","390.80400","32.56724","0.27149"
"65198","391.15200","32.59618","0.27549"
"65256","391.50000","32.62524","0.28005"
"65314","391.84800","32.65411","0.28520"
"65372","392.19600","32.68323","0.28876"
"65430","392.54400","32.71223","0.08143"
"65488","392.89200","32.74117","0.01430"
"65546","393.24000","32.77028","0.05167"
"65604","393.58800","32.79922","0.04457"
"65662","393.93600","32.82822","0.02474"
"65720","394.28400","32.85722","0.02047"
"65778","394.63200","32.88622","0.04434"
"65836","394.98000","32.91515","0.02824"
"65894","395.32800","32.94421","0.02149"
"65952","395.67600","32.97321","0.02183"
"66010","396.02400","33.00221","0.03625"
"66068","396.37200","33.03127","0.02377"
"66126","396.72000","33.06020","0.02160"
"66184","397.06800","33.08920","0.02366"
"66242","397.41600","33.11826","0.03050"
"66300","397.76400","33.14714","0.02167"
"66358","398.11200","33.17625","0.02184"
"66416","398.46000","33.20525","0.02425"
"66474","398.80800","33.23419","0.02662"
"66532","399.15600","33.26325","0.02211"
"66590","399.50400","33.29224","0.02304"
"66648","399.85200","33.32113","0.02765"
"66706","400.20000","33.35024","0.02698"
"66764","400.54800","33.37924","0.02810"
"66822","400.89600","33.40818","0.02689"
"66880","401.24400","33.43724","0.03070"
"66938","401.59200","33.46624","0.02835"
"66996","401.94000","33.49523","0.03042"
"67054","402.28800","33.52423","0.03194"
"67112","402.63600","33.55317","0.03176"
"67170","402.98400","33.58229","0.03275"
"67228","403.33200","33.61116","0.03295"
"67286","403.68000","33.64016","0.03425"
"67344","404.02800","33.66922","0.03646"
"67402","404.37600","33.69822","0.03635"
"67460","404.72400","33.72721","0.03835"
"67518","405.07200","33.75621","0.03911"
"67576","405.42000","33.78521","0.03938"
"67634","405.76800","33.81415","0.04114"
"67692","406.11600","33.84321","0.04170"
"67750","406.46400","33.87221","0.04301"
"67808","406.81200","33.90114","0.04399"
"67866","407.16000","33.93026","0.04482"
"67924","407.50800","33.95920","0.04587"
"67982","407.85600","33.98820","0.04677"
"68040","408.20400","34.01719","0.04765"
"68098","408.55200","34.04619","0.04929"
"68156","408.90000","34.07519","0.05047"
"68214","409.24800","34.10425","0.05183"
"68272","409.59600","34.13319","0.05268"
"68330","409.94400","34.16219","0.05530"
"68388","410.29200","34.19124","0.05581"
"68446","410.64000","34.22018","0.05770"
"68504","410.98800","34.24924","0.05943"
"68562","411.33600","34.27824","0.06164"
"68620","411.68400","34.30717","0.06285"
"68678","412.03200","34.33623","0.06410"
"68736","412.38000","34.36523","0.06536"
"68794","412.72800","34.39423","0.06649"
"68852","413.07600","34.42323","0.06759"
"68910","413.42400","34.45222","0.06856"
"68968","413.77200","34.48122","0.06969"
"69026","414.12000","34.51016","0.07053"
"69084","414.46800","34.53922","0.07208"
"69142","414.81600","34.56816","0.07325"
"69200","415.16400","34.59721","0.07571"
"69258","415.51200","34.62615","0.07733"
"69316","415.86000","34.65521","0.07999"
"69374","416.20800","34.68427","0.08181"
"69432","416.55600","34.71315","0.08422"
"69490","416.90400","34.74226","0.08643"
"69548","417.25200","34.77120","0.08828"
"69606","417.60000","34.80014","0.08954"
"69664","417.94800","34.82925","0.09147"
"69722","418.29600","34.85819","0.09264"
"69780","418.64400","34.88719","0.09338"
"69838","418.99200","34.91625","0.09414"
"69896","419.34000","34.94525","0.09502"
"69954","419.68800","34.97419","0.09648"
"70012","420.03600","35.00319","0.09713"
"70070","420.38400","35.03218","0.09822"
"70128","420.73200","35.06124","0.09938"
"70186","421.08000","35.09018","0.10077"
"70244","421.42800","35.11917","0.10195"
"70302","421.77600","35.14823","0.10313"
"70360","422.12400","35.17723","0.10415"
"70418","422.47200","35.20617","0.10607"
"70476","422.82000","35.23523","0.10743"
"70534","423.16800","35.26416","0.10965"
"70592","423.51600","35.29322","0.11068"
"70650","423.86400","35.32222","0.11186"
"70708","424.21200","35.35128","0.02449"
"70766","424.56000","35.38022","-0.00322"
"70824","424.90800","35.40921","-0.00233"
"70882","425.25600","35.43821","-0.00391"
"70940","425.60400","35.46715","-0.00312"
"70998","425.95200","35.49627","-0.00279"
"71056","426.30000","35.52521","-0.00342"
"71114","426.64800","35.55426","-0.00265"
"71172","426.99600","35.58320","-0.00264"
"71230","427.34400","35.61214","-0.00418"
"71288","427.69200","35.64120","-0.00269"
"71346","428.04000","35.67020","-0.00308"
"71404","428.38800","35.69913","-0.00366"
"71424","428.50600","35.70900","-0.00348"