File: Trajectories_together/161223_2Specimen_RawData_8.csv
"","V1","V2","V3"
"1","End date","12/23/2016",""
"2","Specimen label","21BG_UNK",""
"3","Maximum Load","0.01081","N"
"4","Time","Extension","Load"
"5","(s)","(mm)","(N)"
"6","0.00000","-0.00006","0.00034"
"19","0.07800","0.00215","0.00030"
"32","0.15600","0.00897","0.00054"
"45","0.23400","0.01764","0.00023"
"58","0.31200","0.02571","0.00022"
"71","0.39000","0.03270","0.00009"
"84","0.46800","0.03928","0.00034"
"97","0.54600","0.04568","0.00061"
"110","0.62400","0.05220","-0.00001"
"123","0.70200","0.05871","0.00053"
"136","0.78000","0.06529","0.00060"
"149","0.85800","0.07175","0.00063"
"162","0.93600","0.07820","0.00047"
"175","1.01400","0.08472","0.00047"
"188","1.09200","0.09118","0.00045"
"201","1.17000","0.09770","0.00038"
"214","1.24800","0.10415","0.00059"
"227","1.32600","0.11073","0.00049"
"240","1.40400","0.11725","0.00031"
"253","1.48200","0.12376","0.00032"
"266","1.56000","0.13016","0.00069"
"279","1.63800","0.13662","0.00043"
"292","1.71600","0.14314","0.00019"
"305","1.79400","0.14965","0.00087"
"318","1.87200","0.15617","0.00065"
"331","1.95000","0.16269","0.00039"
"344","2.02800","0.16926","0.00037"
"357","2.10600","0.17566","0.00053"
"370","2.18400","0.18218","0.00059"
"383","2.26200","0.18864","0.00084"
"396","2.34000","0.19521","0.00064"
"409","2.41800","0.20173","0.00093"
"422","2.49600","0.20825","0.00066"
"435","2.57400","0.21470","0.00061"
"448","2.65200","0.22122","0.00076"
"461","2.73000","0.22768","0.00086"
"474","2.80800","0.23420","0.00122"
"487","2.88600","0.24071","0.00063"
"500","2.96400","0.24723","0.00069"
"513","3.04200","0.25375","0.00063"
"526","3.12000","0.26020","0.00087"
"539","3.19800","0.26672","0.00052"
"552","3.27600","0.27318","0.00075"
"565","3.35400","0.27970","0.00083"
"578","3.43200","0.28615","0.00085"
"591","3.51000","0.29267","0.00096"
"604","3.58800","0.29919","0.00071"
"617","3.66600","0.30570","0.00072"
"630","3.74400","0.31222","0.00077"
"643","3.82200","0.31868","0.00056"
"656","3.90000","0.32514","0.00082"
"669","3.97800","0.33171","0.00085"
"682","4.05600","0.33823","0.00096"
"695","4.13400","0.34475","0.00056"
"708","4.21200","0.35120","0.00132"
"721","4.29000","0.35772","0.00073"
"734","4.36800","0.36418","0.00078"
"747","4.44600","0.37064","0.00056"
"760","4.52400","0.37715","0.00078"
"773","4.60200","0.38367","0.00088"
"786","4.68000","0.39019","0.00104"
"799","4.75800","0.39670","0.00067"
"812","4.83600","0.40316","0.00080"
"825","4.91400","0.40968","0.00047"
"838","4.99200","0.41614","0.00101"
"851","5.07000","0.42277","0.00099"
"864","5.14800","0.42917","0.00091"
"877","5.22600","0.43575","0.00075"
"890","5.30400","0.44220","0.00081"
"903","5.38200","0.44866","0.00085"
"916","5.46000","0.45512","0.00102"
"929","5.53800","0.46169","0.00082"
"942","5.61600","0.46821","0.00080"
"955","5.69400","0.47467","0.00054"
"968","5.77200","0.48119","0.00108"
"981","5.85000","0.48764","0.00044"
"994","5.92800","0.49422","0.00095"
"1007","6.00600","0.50062","0.00101"
"1020","6.08400","0.50719","0.00074"
"1033","6.16200","0.51365","0.00071"
"1046","6.24000","0.52017","0.00100"
"1059","6.31800","0.52675","0.00075"
"1072","6.39600","0.53320","0.00062"
"1085","6.47400","0.53966","0.00054"
"1098","6.55200","0.54618","0.00064"
"1111","6.63000","0.55269","0.00044"
"1124","6.70800","0.55921","0.00107"
"1137","6.78600","0.56567","0.00083"
"1150","6.86400","0.57219","0.00092"
"1163","6.94200","0.57870","0.00077"
"1176","7.02000","0.58516","0.00075"
"1189","7.09800","0.59162","0.00147"
"1202","7.17600","0.59819","0.00100"
"1215","7.25400","0.60471","0.00076"
"1228","7.33200","0.61123","0.00109"
"1241","7.41000","0.61769","0.00131"
"1254","7.48800","0.62420","0.00131"
"1267","7.56600","0.63066","0.00071"
"1280","7.64400","0.63712","0.00092"
"1293","7.72200","0.64369","0.00107"
"1306","7.80000","0.65027","0.00083"
"1319","7.87800","0.65667","0.00087"
"1332","7.95600","0.66319","0.00113"
"1345","8.03400","0.66964","0.00117"
"1358","8.11200","0.67616","0.00098"
"1371","8.19000","0.68262","0.00099"
"1384","8.26800","0.68919","0.00104"
"1397","8.34600","0.69571","0.00077"
"1410","8.42400","0.70223","0.00122"
"1423","8.50200","0.70875","0.00095"
"1436","8.58000","0.71514","0.00083"
"1449","8.65800","0.72166","0.00074"
"1462","8.73600","0.72812","0.00035"
"1475","8.81400","0.73469","0.00107"
"1488","8.89200","0.74121","0.00028"
"1501","8.97000","0.74773","0.00076"
"1514","9.04800","0.75424","0.00078"
"1527","9.12600","0.76070","0.00092"
"1540","9.20400","0.76716","0.00112"
"1553","9.28200","0.77368","0.00125"
"1566","9.36000","0.78025","0.00115"
"1579","9.43800","0.78671","0.00101"
"1592","9.51600","0.79323","0.00090"
"1605","9.59400","0.79969","0.00118"
"1618","9.67200","0.80620","0.00066"
"1631","9.75000","0.81266","0.00077"
"1644","9.82800","0.81918","0.00065"
"1657","9.90600","0.82569","0.00109"
"1670","9.98400","0.83221","0.00085"
"1683","10.06200","0.83873","0.00127"
"1696","10.14000","0.84518","0.00098"
"1709","10.21800","0.85170","0.00108"
"1722","10.29600","0.85816","0.00109"
"1735","10.37400","0.86468","0.00092"
"1748","10.45200","0.87113","0.00090"
"1761","10.53000","0.87777","0.00082"
"1774","10.60800","0.88423","0.00099"
"1787","10.68600","0.89074","0.00084"
"1800","10.76400","0.89714","0.00130"
"1813","10.84200","0.90360","0.00121"
"1826","10.92000","0.91018","0.00097"
"1839","10.99800","0.91669","0.00090"
"1852","11.07600","0.92327","0.00086"
"1865","11.15400","0.92973","0.00051"
"1878","11.23200","0.93624","0.00102"
"1891","11.31000","0.94270","0.00098"
"1904","11.38800","0.94916","0.00058"
"1917","11.46600","0.95568","0.00088"
"1930","11.54400","0.96219","0.00122"
"1943","11.62200","0.96871","0.00076"
"1956","11.70000","0.97523","0.00100"
"1969","11.77800","0.98168","0.00110"
"1982","11.85600","0.98820","0.00115"
"1995","11.93400","0.99466","0.00087"
"2008","12.01200","1.00118","0.00132"
"2021","12.09000","1.00769","0.00122"
"2034","12.16800","1.01421","0.00094"
"2047","12.24600","1.02073","0.00125"
"2060","12.32400","1.02718","0.00096"
"2073","12.40200","1.03364","0.00107"
"2086","12.48000","1.04010","0.00104"
"2099","12.55800","1.04668","0.00084"
"2112","12.63600","1.05319","0.00088"
"2125","12.71400","1.05965","0.00137"
"2138","12.79200","1.06623","0.00141"
"2151","12.87000","1.07268","0.00107"
"2164","12.94800","1.07920","0.00118"
"2177","13.02600","1.08560","0.00100"
"2190","13.10400","1.09224","0.00115"
"2203","13.18200","1.09869","0.00141"
"2216","13.26000","1.10521","0.00132"
"2229","13.33800","1.11167","0.00167"
"2242","13.41600","1.11818","0.00113"
"2255","13.49400","1.12470","0.00095"
"2268","13.57200","1.13116","0.00154"
"2281","13.65000","1.13774","0.00160"
"2294","13.72800","1.14425","0.00161"
"2307","13.80600","1.15077","0.00130"
"2320","13.88400","1.15723","0.00184"
"2333","13.96200","1.16374","0.00166"
"2346","14.04000","1.17020","0.00113"
"2359","14.11800","1.17666","0.00159"
"2372","14.19600","1.18318","0.00155"
"2385","14.27400","1.18975","0.00141"
"2398","14.35200","1.19621","0.00161"
"2411","14.43000","1.20267","0.00138"
"2424","14.50800","1.20918","0.00154"
"2437","14.58600","1.21564","0.00184"
"2450","14.66400","1.22216","0.00154"
"2463","14.74200","1.22867","0.00158"
"2476","14.82000","1.23525","0.00179"
"2489","14.89800","1.24171","0.00149"
"2502","14.97600","1.24823","0.00187"
"2515","15.05400","1.25462","0.00175"
"2528","15.13200","1.26120","0.00186"
"2541","15.21000","1.26766","0.00161"
"2554","15.28800","1.27423","0.00162"
"2567","15.36600","1.28069","0.00195"
"2580","15.44400","1.28721","0.00200"
"2593","15.52200","1.29373","0.00167"
"2606","15.60000","1.30018","0.00157"
"2619","15.67800","1.30664","0.00161"
"2632","15.75600","1.31316","0.00125"
"2645","15.83400","1.31973","0.00158"
"2658","15.91200","1.32619","0.00152"
"2671","15.99000","1.33271","0.00168"
"2684","16.06800","1.33923","0.00191"
"2697","16.14600","1.34568","0.00142"
"2710","16.22400","1.35214","0.00187"
"2723","16.30200","1.35866","0.00128"
"2736","16.38000","1.36523","0.00169"
"2749","16.45800","1.37169","0.00111"
"2762","16.53600","1.37821","0.00151"
"2775","16.61400","1.38467","0.00187"
"2788","16.69200","1.39118","0.00188"
"2801","16.77000","1.39758","0.00202"
"2814","16.84800","1.40422","0.00204"
"2827","16.92600","1.41073","0.00216"
"2840","17.00400","1.41719","0.00166"
"2853","17.08200","1.42371","0.00185"
"2866","17.16000","1.43023","0.00173"
"2879","17.23800","1.43668","0.00190"
"2892","17.31600","1.44314","0.00184"
"2905","17.39400","1.44972","0.00172"
"2918","17.47200","1.45623","0.00226"
"2931","17.55000","1.46275","0.00231"
"2944","17.62800","1.46921","0.00166"
"2957","17.70600","1.47573","0.00169"
"2970","17.78400","1.48218","0.00217"
"2983","17.86200","1.48858","0.00189"
"2996","17.94000","1.49522","0.00161"
"3009","18.01800","1.50173","0.00132"
"3022","18.09600","1.50825","0.00220"
"3035","18.17400","1.51471","0.00176"
"3048","18.25200","1.52123","0.00185"
"3061","18.33000","1.52768","0.00155"
"3074","18.40800","1.53420","0.00195"
"3087","18.48600","1.54066","0.00213"
"3100","18.56400","1.54729","0.00186"
"3113","18.64200","1.55369","0.00169"
"3126","18.72000","1.56021","0.00183"
"3139","18.79800","1.56667","0.00183"
"3152","18.87600","1.57312","0.00206"
"3165","18.95400","1.57964","0.00193"
"3178","19.03200","1.58616","0.00225"
"3191","19.11000","1.59267","0.00220"
"3204","19.18800","1.59919","0.00209"
"3217","19.26600","1.60571","0.00186"
"3230","19.34400","1.61216","0.00199"
"3243","19.42200","1.61862","0.00165"
"3256","19.50000","1.62514","0.00190"
"3269","19.57800","1.63160","0.00208"
"3282","19.65600","1.63817","0.00215"
"3295","19.73400","1.64469","0.00212"
"3308","19.81200","1.65121","0.00212"
"3321","19.89000","1.65766","0.00178"
"3334","19.96800","1.66418","0.00179"
"3347","20.04600","1.67064","0.00196"
"3360","20.12400","1.67716","0.00182"
"3373","20.20200","1.68367","0.00191"
"3386","20.28000","1.69025","0.00226"
"3399","20.35800","1.69671","0.00194"
"3412","20.43600","1.70316","0.00205"
"3425","20.51400","1.70962","0.00199"
"3438","20.59200","1.71620","0.00178"
"3451","20.67000","1.72272","0.00198"
"3464","20.74800","1.72917","0.00178"
"3477","20.82600","1.73569","0.00219"
"3490","20.90400","1.74221","0.00205"
"3503","20.98200","1.74872","0.00222"
"3516","21.06000","1.75512","0.00206"
"3529","21.13800","1.76170","0.00144"
"3542","21.21600","1.76816","0.00187"
"3555","21.29400","1.77473","0.00224"
"3568","21.37200","1.78119","0.00205"
"3581","21.45000","1.78771","0.00222"
"3594","21.52800","1.79416","0.00228"
"3607","21.60600","1.80068","0.00176"
"3620","21.68400","1.80714","0.00191"
"3633","21.76200","1.81372","0.00194"
"3646","21.84000","1.82023","0.00227"
"3659","21.91800","1.82669","0.00208"
"3672","21.99600","1.83321","0.00247"
"3685","22.07400","1.83966","0.00210"
"3698","22.15200","1.84618","0.00243"
"3711","22.23000","1.85264","0.00207"
"3724","22.30800","1.85922","0.00241"
"3737","22.38600","1.86567","0.00241"
"3750","22.46400","1.87225","0.00243"
"3763","22.54200","1.87871","0.00251"
"3776","22.62000","1.88516","0.00211"
"3789","22.69800","1.89168","0.00243"
"3802","22.77600","1.89820","0.00200"
"3815","22.85400","1.90472","0.00206"
"3828","22.93200","1.91117","0.00210"
"3841","23.01000","1.91769","0.00235"
"3854","23.08800","1.92415","0.00220"
"3867","23.16600","1.93060","0.00299"
"3880","23.24400","1.93712","0.00235"
"3893","23.32200","1.94370","0.00228"
"3906","23.40000","1.95022","0.00271"
"3919","23.47800","1.95673","0.00230"
"3932","23.55600","1.96319","0.00205"
"3945","23.63400","1.96965","0.00237"
"3958","23.71200","1.97616","0.00190"
"3971","23.79000","1.98262","0.00247"
"3984","23.86800","1.98920","0.00256"
"3997","23.94600","1.99566","0.00225"
"4010","24.02400","2.00223","0.00198"
"4023","24.10200","2.00869","0.00230"
"4036","24.18000","2.01521","0.00251"
"4049","24.25800","2.02166","0.00243"
"4062","24.33600","2.02812","0.00217"
"4075","24.41400","2.03470","0.00183"
"4088","24.49200","2.04121","0.00211"
"4101","24.57000","2.04773","0.00233"
"4114","24.64800","2.05425","0.00229"
"4127","24.72600","2.06071","0.00227"
"4140","24.80400","2.06716","0.00235"
"4153","24.88200","2.07368","0.00236"
"4166","24.96000","2.08020","0.00246"
"4179","25.03800","2.08671","0.00243"
"4192","25.11600","2.09317","0.00244"
"4205","25.19400","2.09969","0.00268"
"4218","25.27200","2.10615","0.00223"
"4231","25.35000","2.11260","0.00189"
"4244","25.42800","2.11918","0.00229"
"4257","25.50600","2.12570","0.00209"
"4270","25.58400","2.13227","0.00217"
"4283","25.66200","2.13867","0.00220"
"4296","25.74000","2.14525","0.00201"
"4309","25.81800","2.15165","0.00226"
"4322","25.89600","2.15810","0.00231"
"4335","25.97400","2.16462","0.00179"
"4348","26.05200","2.17126","0.00249"
"4361","26.13000","2.17771","0.00219"
"4374","26.20800","2.18417","0.00189"
"4387","26.28600","2.19075","0.00229"
"4400","26.36400","2.19721","0.00212"
"4413","26.44200","2.20366","0.00208"
"4426","26.52000","2.21012","0.00248"
"4439","26.59800","2.21676","0.00194"
"4452","26.67600","2.22321","0.00220"
"4465","26.75400","2.22973","0.00221"
"4478","26.83200","2.23625","0.00238"
"4491","26.91000","2.24271","0.00207"
"4504","26.98800","2.24916","0.00178"
"4517","27.06600","2.25568","0.00182"
"4530","27.14400","2.26220","0.00214"
"4543","27.22200","2.26871","0.00241"
"4556","27.30000","2.27517","0.00205"
"4569","27.37800","2.28169","0.00228"
"4582","27.45600","2.28815","0.00261"
"4595","27.53400","2.29460","0.00251"
"4608","27.61200","2.30112","0.00215"
"4621","27.69000","2.30764","0.00221"
"4634","27.76800","2.31415","0.00191"
"4647","27.84600","2.32073","0.00262"
"4660","27.92400","2.32719","0.00192"
"4673","28.00200","2.33371","0.00266"
"4686","28.08000","2.34010","0.00244"
"4699","28.15800","2.34668","0.00215"
"4712","28.23600","2.35320","0.00220"
"4725","28.31400","2.35971","0.00228"
"4738","28.39200","2.36623","0.00246"
"4751","28.47000","2.37269","0.00265"
"4764","28.54800","2.37914","0.00236"
"4777","28.62600","2.38566","0.00238"
"4790","28.70400","2.39218","0.00267"
"4803","28.78200","2.39870","0.00271"
"4816","28.86000","2.40521","0.00213"
"4829","28.93800","2.41173","0.00268"
"4842","29.01600","2.41825","0.00243"
"4855","29.09400","2.42470","0.00278"
"4868","29.17200","2.43116","0.00252"
"4881","29.25000","2.43768","0.00250"
"4894","29.32800","2.44426","0.00257"
"4907","29.40600","2.45065","0.00262"
"4920","29.48400","2.45723","0.00282"
"4933","29.56200","2.46369","0.00240"
"4946","29.64000","2.47014","0.00244"
"4959","29.71800","2.47666","0.00262"
"4972","29.79600","2.48318","0.00202"
"4985","29.87400","2.48970","0.00229"
"4998","29.95200","2.49615","0.00269"
"5011","30.03000","2.50273","0.00257"
"5024","30.10800","2.50913","0.00282"
"5037","30.18600","2.51570","0.00250"
"5050","30.26400","2.52210","0.00225"
"5063","30.34200","2.52868","0.00278"
"5076","30.42000","2.53520","0.00247"
"5089","30.49800","2.54171","0.00257"
"5102","30.57600","2.54823","0.00231"
"5115","30.65400","2.55469","0.00247"
"5128","30.73200","2.56120","0.00269"
"5141","30.81000","2.56766","0.00261"
"5154","30.88800","2.57424","0.00249"
"5167","30.96600","2.58076","0.00230"
"5180","31.04400","2.58721","0.00267"
"5193","31.12200","2.59373","0.00260"
"5206","31.20000","2.60019","0.00259"
"5219","31.27800","2.60670","0.00230"
"5232","31.35600","2.61322","0.00239"
"5245","31.43400","2.61974","0.00222"
"5258","31.51200","2.62626","0.00300"
"5271","31.59000","2.63271","0.00260"
"5284","31.66800","2.63917","0.00277"
"5297","31.74600","2.64575","0.00269"
"5310","31.82400","2.65214","0.00286"
"5323","31.90200","2.65872","0.00255"
"5336","31.98000","2.66518","0.00303"
"5349","32.05800","2.67170","0.00272"
"5362","32.13600","2.67821","0.00265"
"5375","32.21400","2.68467","0.00264"
"5388","32.29200","2.69113","0.00277"
"5401","32.37000","2.69764","0.00238"
"5414","32.44800","2.70416","0.00279"
"5427","32.52600","2.71068","0.00223"
"5440","32.60400","2.71720","0.00249"
"5453","32.68200","2.72377","0.00242"
"5466","32.76000","2.73023","0.00241"
"5479","32.83800","2.73669","0.00274"
"5492","32.91600","2.74314","0.00231"
"5505","32.99400","2.74966","0.00254"
"5518","33.07200","2.75624","0.00227"
"5531","33.15000","2.76270","0.00235"
"5544","33.22800","2.76921","0.00236"
"5557","33.30600","2.77567","0.00286"
"5570","33.38400","2.78213","0.00233"
"5583","33.46200","2.78870","0.00255"
"5596","33.54000","2.79516","0.00258"
"5609","33.61800","2.80174","0.00242"
"5622","33.69600","2.80819","0.00248"
"5635","33.77400","2.81477","0.00254"
"5648","33.85200","2.82117","0.00297"
"5661","33.93000","2.82763","0.00275"
"5674","34.00800","2.83414","0.00265"
"5687","34.08600","2.84066","0.00277"
"5700","34.16400","2.84718","0.00269"
"5713","34.24200","2.85369","0.00249"
"5726","34.32000","2.86021","0.00287"
"5739","34.39800","2.86667","0.00277"
"5752","34.47600","2.87313","0.00250"
"5765","34.55400","2.87964","0.00276"
"5778","34.63200","2.88622","0.00314"
"5791","34.71000","2.89274","0.00290"
"5804","34.78800","2.89919","0.00268"
"5817","34.86600","2.90571","0.00271"
"5830","34.94400","2.91223","0.00299"
"5843","35.02200","2.91869","0.00271"
"5856","35.10000","2.92514","0.00288"
"5869","35.17800","2.93172","0.00243"
"5882","35.25600","2.93824","0.00276"
"5895","35.33400","2.94475","0.00342"
"5908","35.41200","2.95121","0.00329"
"5921","35.49000","2.95773","0.00275"
"5934","35.56800","2.96419","0.00325"
"5947","35.64600","2.97070","0.00261"
"5960","35.72400","2.97716","0.00252"
"5973","35.80200","2.98374","0.00297"
"5986","35.88000","2.99019","0.00281"
"5999","35.95800","2.99671","0.00265"
"6012","36.03600","3.00317","0.00271"
"6025","36.11400","3.00963","0.00295"
"6038","36.19200","3.01620","0.00321"
"6051","36.27000","3.02266","0.00312"
"6064","36.34800","3.02924","0.00296"
"6077","36.42600","3.03569","0.00265"
"6090","36.50400","3.04221","0.00279"
"6103","36.58200","3.04867","0.00278"
"6116","36.66000","3.05519","0.00278"
"6129","36.73800","3.06164","0.00295"
"6142","36.81600","3.06822","0.00306"
"6155","36.89400","3.07474","0.00311"
"6168","36.97200","3.08119","0.00261"
"6181","37.05000","3.08777","0.00313"
"6194","37.12800","3.09417","0.00260"
"6207","37.20600","3.10069","0.00252"
"6220","37.28400","3.10714","0.00280"
"6233","37.36200","3.11372","0.00155"
"6246","37.44000","3.12018","0.00124"
"6259","37.51800","3.12669","0.00162"
"6272","37.59600","3.13321","0.00173"
"6285","37.67400","3.13967","0.00153"
"6298","37.75200","3.14618","0.00167"
"6311","37.83000","3.15264","0.00217"
"6324","37.90800","3.15916","0.00185"
"6337","37.98600","3.16568","0.00219"
"6350","38.06400","3.17225","0.00135"
"6363","38.14200","3.17865","0.00240"
"6376","38.22000","3.18517","0.00168"
"6389","38.29800","3.19163","0.00115"
"6402","38.37600","3.19820","0.00125"
"6415","38.45400","3.20466","0.00157"
"6428","38.53200","3.21124","0.00181"
"6441","38.61000","3.21769","0.00162"
"6454","38.68800","3.22421","0.00214"
"6467","38.76600","3.23073","0.00199"
"6480","38.84400","3.23718","0.00239"
"6493","38.92200","3.24370","0.00245"
"6506","39.00000","3.25016","0.00232"
"6519","39.07800","3.25674","0.00196"
"6532","39.15600","3.26319","0.00159"
"6545","39.23400","3.26971","0.00191"
"6558","39.31200","3.27617","0.00167"
"6571","39.39000","3.28268","0.00180"
"6584","39.46800","3.28914","0.00190"
"6597","39.54600","3.29572","0.00169"
"6610","39.62400","3.30224","0.00226"
"6623","39.70200","3.30869","0.00191"
"6636","39.78000","3.31521","0.00184"
"6649","39.85800","3.32167","0.00225"
"6662","39.93600","3.32812","0.00202"
"6675","40.01400","3.33470","0.00152"
"6688","40.09200","3.34122","0.00231"
"6701","40.17000","3.34768","0.00205"
"6714","40.24800","3.35419","0.00176"
"6727","40.32600","3.36065","0.00219"
"6740","40.40400","3.36717","0.00217"
"6753","40.48200","3.37362","0.00214"
"6766","40.56000","3.38020","0.00197"
"6779","40.63800","3.38672","0.00264"
"6792","40.71600","3.39324","0.00199"
"6805","40.79400","3.39969","0.00207"
"6818","40.87200","3.40615","0.00195"
"6831","40.95000","3.41267","0.00212"
"6844","41.02800","3.41912","0.00205"
"6857","41.10600","3.42570","0.00250"
"6870","41.18400","3.43222","0.00186"
"6883","41.26200","3.43868","0.00185"
"6896","41.34000","3.44519","0.00216"
"6909","41.41800","3.45165","0.00229"
"6922","41.49600","3.45817","0.00213"
"6935","41.57400","3.46468","0.00210"
"6948","41.65200","3.47126","0.00249"
"6961","41.73000","3.47772","0.00249"
"6974","41.80800","3.48429","0.00185"
"6987","41.88600","3.49069","0.00221"
"7000","41.96400","3.49721","0.00229"
"7013","42.04200","3.50361","0.00232"
"7026","42.12000","3.51018","0.00216"
"7039","42.19800","3.51670","0.00224"
"7052","42.27600","3.52322","0.00234"
"7065","42.35400","3.52973","0.00220"
"7078","42.43200","3.53619","0.00276"
"7091","42.51000","3.54271","0.00243"
"7104","42.58800","3.54917","0.00209"
"7117","42.66600","3.55568","0.00186"
"7130","42.74400","3.56220","0.00213"
"7143","42.82200","3.56872","0.00255"
"7156","42.90000","3.57523","0.00252"
"7169","42.97800","3.58169","0.00227"
"7182","43.05600","3.58815","0.00193"
"7195","43.13400","3.59461","0.00207"
"7208","43.21200","3.60118","0.00232"
"7221","43.29000","3.60770","0.00243"
"7234","43.36800","3.61428","0.00199"
"7247","43.44600","3.62073","0.00246"
"7260","43.52400","3.62725","0.00238"
"7273","43.60200","3.63365","0.00207"
"7286","43.68000","3.64017","0.00226"
"7299","43.75800","3.64662","0.00260"
"7312","43.83600","3.65320","0.00234"
"7325","43.91400","3.65972","0.00228"
"7338","43.99200","3.66623","0.00218"
"7351","44.07000","3.67269","0.00217"
"7364","44.14800","3.67921","0.00237"
"7377","44.22600","3.68567","0.00228"
"7390","44.30400","3.69224","0.00199"
"7403","44.38200","3.69870","0.00265"
"7416","44.46000","3.70522","0.00172"
"7429","44.53800","3.71173","0.00266"
"7442","44.61600","3.71819","0.00231"
"7455","44.69400","3.72465","0.00224"
"7468","44.77200","3.73111","0.00245"
"7481","44.85000","3.73768","0.00240"
"7494","44.92800","3.74420","0.00218"
"7507","45.00600","3.75066","0.00263"
"7520","45.08400","3.75723","0.00235"
"7533","45.16200","3.76363","0.00245"
"7546","45.24000","3.77021","0.00211"
"7559","45.31800","3.77661","0.00228"
"7572","45.39600","3.78318","0.00228"
"7585","45.47400","3.78970","0.00257"
"7598","45.55200","3.79622","0.00264"
"7611","45.63000","3.80267","0.00253"
"7624","45.70800","3.80913","0.00223"
"7637","45.78600","3.81565","0.00243"
"7650","45.86400","3.82217","0.00278"
"7663","45.94200","3.82868","0.00216"
"7676","46.02000","3.83520","0.00272"
"7689","46.09800","3.84172","0.00266"
"7702","46.17600","3.84823","0.00262"
"7715","46.25400","3.85469","0.00241"
"7728","46.33200","3.86115","0.00279"
"7741","46.41000","3.86773","0.00265"
"7754","46.48800","3.87418","0.00226"
"7767","46.56600","3.88070","0.00235"
"7780","46.64400","3.88722","0.00254"
"7793","46.72200","3.89367","0.00323"
"7806","46.80000","3.90019","0.00232"
"7819","46.87800","3.90659","0.00261"
"7832","46.95600","3.91317","0.00248"
"7845","47.03400","3.91968","0.00249"
"7858","47.11200","3.92626","0.00323"
"7871","47.19000","3.93266","0.00337"
"7884","47.26800","3.93923","0.00221"
"7897","47.34600","3.94569","0.00292"
"7910","47.42400","3.95215","0.00292"
"7923","47.50200","3.95866","0.00230"
"7936","47.58000","3.96518","0.00277"
"7949","47.65800","3.97170","0.00263"
"7962","47.73600","3.97822","0.00282"
"7975","47.81400","3.98467","0.00267"
"7988","47.89200","3.99119","0.00299"
"8001","47.97000","3.99765","0.00240"
"8014","48.04800","4.00416","0.00239"
"8027","48.12600","4.01068","0.00296"
"8040","48.20400","4.01720","0.00274"
"8053","48.28200","4.02372","0.00278"
"8066","48.36000","4.03023","0.00316"
"8079","48.43800","4.03669","0.00246"
"8092","48.51600","4.04315","0.00289"
"8105","48.59400","4.04972","0.00318"
"8118","48.67200","4.05624","0.00267"
"8131","48.75000","4.06270","0.00305"
"8144","48.82800","4.06922","0.00292"
"8157","48.90600","4.07567","0.00300"
"8170","48.98400","4.08219","0.00291"
"8183","49.06200","4.08865","0.00293"
"8196","49.14000","4.09516","0.00306"
"8209","49.21800","4.10168","0.00242"
"8222","49.29600","4.10820","0.00251"
"8235","49.37400","4.11472","0.00274"
"8248","49.45200","4.12111","0.00279"
"8261","49.53000","4.12769","0.00276"
"8274","49.60800","4.13415","0.00310"
"8287","49.68600","4.14072","0.00274"
"8300","49.76400","4.14718","0.00294"
"8313","49.84200","4.15370","0.00269"
"8326","49.92000","4.16022","0.00283"
"8339","49.99800","4.16673","0.00289"
"8352","50.07600","4.17313","0.00250"
"8365","50.15400","4.17965","0.00267"
"8378","50.23200","4.18616","0.00310"
"8391","50.31000","4.19274","0.00319"
"8404","50.38800","4.19920","0.00322"
"8417","50.46600","4.20572","0.00313"
"8430","50.54400","4.21223","0.00290"
"8443","50.62200","4.21863","0.00333"
"8456","50.70000","4.22515","0.00317"
"8469","50.77800","4.23172","0.00282"
"8482","50.85600","4.23824","0.00350"
"8495","50.93400","4.24470","0.00277"
"8508","51.01200","4.25121","0.00256"
"8521","51.09000","4.25761","0.00314"
"8534","51.16800","4.26413","0.00284"
"8547","51.24600","4.27065","0.00300"
"8560","51.32400","4.27716","0.00319"
"8573","51.40200","4.28374","0.00326"
"8586","51.48000","4.29020","0.00315"
"8599","51.55800","4.29671","0.00274"
"8612","51.63600","4.30317","0.00264"
"8625","51.71400","4.30969","0.00335"
"8638","51.79200","4.31615","0.00328"
"8651","51.87000","4.32272","0.00341"
"8664","51.94800","4.32924","0.00354"
"8677","52.02600","4.33576","0.00343"
"8690","52.10400","4.34221","0.00318"
"8703","52.18200","4.34867","0.00305"
"8716","52.26000","4.35513","0.00339"
"8729","52.33800","4.36165","0.00319"
"8742","52.41600","4.36828","0.00369"
"8755","52.49400","4.37468","0.00328"
"8768","52.57200","4.38126","0.00328"
"8781","52.65000","4.38765","0.00289"
"8794","52.72800","4.39417","0.00300"
"8807","52.80600","4.40063","0.00323"
"8820","52.88400","4.40715","0.00359"
"8833","52.96200","4.41366","0.00306"
"8846","53.04000","4.42018","0.00316"
"8859","53.11800","4.42676","0.00316"
"8872","53.19600","4.43321","0.00374"
"8885","53.27400","4.43967","0.00368"
"8898","53.35200","4.44613","0.00346"
"8911","53.43000","4.45265","0.00333"
"8924","53.50800","4.45916","0.00323"
"8937","53.58600","4.46568","0.00375"
"8950","53.66400","4.47220","0.00330"
"8963","53.74200","4.47871","0.00366"
"8976","53.82000","4.48517","0.00331"
"8989","53.89800","4.49163","0.00354"
"9002","53.97600","4.49821","0.00336"
"9015","54.05400","4.50472","0.00342"
"9028","54.13200","4.51124","0.00333"
"9041","54.21000","4.51776","0.00318"
"9054","54.28800","4.52421","0.00327"
"9067","54.36600","4.53067","0.00334"
"9080","54.44400","4.53719","0.00338"
"9093","54.52200","4.54365","0.00304"
"9106","54.60000","4.55016","0.00354"
"9119","54.67800","4.55674","0.00320"
"9132","54.75600","4.56326","0.00314"
"9145","54.83400","4.56971","0.00347"
"9158","54.91200","4.57617","0.00349"
"9171","54.99000","4.58269","0.00374"
"9184","55.06800","4.58915","0.00377"
"9197","55.14600","4.59566","0.00304"
"9210","55.22400","4.60218","0.00337"
"9223","55.30200","4.60870","0.00359"
"9236","55.38000","4.61515","0.00349"
"9249","55.45800","4.62161","0.00347"
"9262","55.53600","4.62813","0.00344"
"9275","55.61400","4.63465","0.00392"
"9288","55.69200","4.64122","0.00400"
"9301","55.77000","4.64768","0.00418"
"9314","55.84800","4.65420","0.00381"
"9327","55.92600","4.66071","0.00394"
"9340","56.00400","4.66717","0.00358"
"9353","56.08200","4.67363","0.00373"
"9366","56.16000","4.68021","0.00357"
"9379","56.23800","4.68672","0.00367"
"9392","56.31600","4.69318","0.00391"
"9405","56.39400","4.69970","0.00364"
"9418","56.47200","4.70621","0.00399"
"9431","56.55000","4.71267","0.00372"
"9444","56.62800","4.71919","0.00388"
"9457","56.70600","4.72570","0.00364"
"9470","56.78400","4.73222","0.00392"
"9483","56.86200","4.73874","0.00376"
"9496","56.94000","4.74520","0.00452"
"9509","57.01800","4.75171","0.00363"
"9522","57.09600","4.75817","0.00396"
"9535","57.17400","4.76469","0.00417"
"9548","57.25200","4.77120","0.00330"
"9561","57.33000","4.77772","0.00392"
"9574","57.40800","4.78418","0.00438"
"9587","57.48600","4.79070","0.00395"
"9600","57.56400","4.79721","0.00416"
"9613","57.64200","4.80361","0.00378"
"9626","57.72000","4.81019","0.00414"
"9639","57.79800","4.81670","0.00394"
"9652","57.87600","4.82322","0.00448"
"9665","57.95400","4.82968","0.00439"
"9678","58.03200","4.83620","0.00413"
"9691","58.11000","4.84265","0.00416"
"9704","58.18800","4.84917","0.00398"
"9717","58.26600","4.85563","0.00412"
"9730","58.34400","4.86214","0.00440"
"9743","58.42200","4.86872","0.00396"
"9756","58.50000","4.87518","0.00429"
"9769","58.57800","4.88176","0.00444"
"9782","58.65600","4.88815","0.00445"
"9795","58.73400","4.89467","0.00459"
"9808","58.81200","4.90113","0.00443"
"9821","58.89000","4.90770","0.00449"
"9834","58.96800","4.91416","0.00403"
"9847","59.04600","4.92074","0.00445"
"9860","59.12400","4.92720","0.00417"
"9873","59.20200","4.93365","0.00450"
"9886","59.28000","4.94011","0.00430"
"9899","59.35800","4.94669","0.00417"
"9912","59.43600","4.95320","0.00421"
"9925","59.51400","4.95972","0.00472"
"9938","59.59200","4.96624","0.00407"
"9951","59.67000","4.97269","0.00410"
"9964","59.74800","4.97915","0.00459"
"9977","59.82600","4.98561","0.00375"
"9990","59.90400","4.99219","0.00434"
"10003","59.98200","4.99870","0.00468"
"10016","60.06000","5.00522","0.00422"
"10029","60.13800","5.01174","0.00447"
"10042","60.21600","5.01819","0.00447"
"10055","60.29400","5.02471","0.00437"
"10068","60.37200","5.03111","0.00454"
"10081","60.45000","5.03775","0.00452"
"10094","60.52800","5.04420","0.00487"
"10107","60.60600","5.05072","0.00463"
"10120","60.68400","5.05724","0.00442"
"10133","60.76200","5.06369","0.00459"
"10146","60.84000","5.07015","0.00457"
"10159","60.91800","5.07661","0.00453"
"10172","60.99600","5.08319","0.00448"
"10185","61.07400","5.08970","0.00428"
"10198","61.15200","5.09622","0.00458"
"10211","61.23000","5.10274","0.00446"
"10224","61.30800","5.10919","0.00406"
"10237","61.38600","5.11565","0.00462"
"10250","61.46400","5.12217","0.00470"
"10263","61.54200","5.12863","0.00453"
"10276","61.62000","5.13520","0.00440"
"10289","61.69800","5.14172","0.00465"
"10302","61.77600","5.14818","0.00454"
"10315","61.85400","5.15464","0.00479"
"10328","61.93200","5.16109","0.00445"
"10341","62.01000","5.16767","0.00436"
"10354","62.08800","5.17419","0.00436"
"10367","62.16600","5.18076","0.00423"
"10380","62.24400","5.18716","0.00498"
"10393","62.32200","5.19374","0.00459"
"10406","62.40000","5.20014","0.00441"
"10419","62.47800","5.20671","0.00426"
"10432","62.55600","5.21311","0.00454"
"10445","62.63400","5.21969","0.00471"
"10458","62.71200","5.22620","0.00442"
"10471","62.79000","5.23272","0.00488"
"10484","62.86800","5.23918","0.00454"
"10497","62.94600","5.24569","0.00485"
"10510","63.02400","5.25215","0.00480"
"10523","63.10200","5.25867","0.00482"
"10536","63.18000","5.26513","0.00493"
"10549","63.25800","5.27170","0.00457"
"10562","63.33600","5.27822","0.00498"
"10575","63.41400","5.28474","0.00475"
"10588","63.49200","5.29119","0.00533"
"10601","63.57000","5.29765","0.00509"
"10614","63.64800","5.30417","0.00474"
"10627","63.72600","5.31069","0.00521"
"10640","63.80400","5.31720","0.00498"
"10653","63.88200","5.32372","0.00518"
"10666","63.96000","5.33018","0.00477"
"10679","64.03800","5.33669","0.00475"
"10692","64.11600","5.34315","0.00453"
"10705","64.19400","5.34967","0.00500"
"10718","64.27200","5.35619","0.00474"
"10731","64.35000","5.36270","0.00472"
"10744","64.42800","5.36922","0.00508"
"10757","64.50600","5.37574","0.00509"
"10770","64.58400","5.38219","0.00474"
"10783","64.66200","5.38871","0.00516"
"10796","64.74000","5.39523","0.00503"
"10809","64.81800","5.40169","0.00522"
"10822","64.89600","5.40826","0.00515"
"10835","64.97400","5.41472","0.00455"
"10848","65.05200","5.42124","0.00503"
"10861","65.13000","5.42769","0.00517"
"10874","65.20800","5.43421","0.00468"
"10887","65.28600","5.44067","0.00509"
"10900","65.36400","5.44719","0.00516"
"10913","65.44200","5.45364","0.00505"
"10926","65.52000","5.46022","0.00506"
"10939","65.59800","5.46668","0.00500"
"10952","65.67600","5.47313","0.00521"
"10965","65.75400","5.47965","0.00497"
"10978","65.83200","5.48617","0.00567"
"10991","65.91000","5.49274","0.00486"
"11004","65.98800","5.49920","0.00500"
"11017","66.06600","5.50572","0.00525"
"11030","66.14400","5.51212","0.00519"
"11043","66.22200","5.51863","0.00529"
"11056","66.30000","5.52509","0.00516"
"11069","66.37800","5.53167","0.00525"
"11082","66.45600","5.53824","0.00566"
"11095","66.53400","5.54470","0.00527"
"11108","66.61200","5.55122","0.00555"
"11121","66.69000","5.55762","0.00515"
"11134","66.76800","5.56419","0.00508"
"11147","66.84600","5.57065","0.00557"
"11160","66.92400","5.57717","0.00516"
"11173","67.00200","5.58368","0.00505"
"11186","67.08000","5.59020","0.00543"
"11199","67.15800","5.59666","0.00507"
"11212","67.23600","5.60324","0.00489"
"11225","67.31400","5.60963","0.00593"
"11238","67.39200","5.61615","0.00502"
"11251","67.47000","5.62267","0.00493"
"11264","67.54800","5.62918","0.00475"
"11277","67.62600","5.63570","0.00488"
"11290","67.70400","5.64222","0.00525"
"11303","67.78200","5.64868","0.00502"
"11316","67.86000","5.65513","0.00485"
"11329","67.93800","5.66171","0.00475"
"11342","68.01600","5.66817","0.00454"
"11355","68.09400","5.67474","0.00484"
"11368","68.17200","5.68120","0.00480"
"11381","68.25000","5.68766","0.00502"
"11394","68.32800","5.69418","0.00494"
"11407","68.40600","5.70063","0.00476"
"11420","68.48400","5.70715","0.00511"
"11433","68.56200","5.71373","0.00455"
"11446","68.64000","5.72018","0.00479"
"11459","68.71800","5.72676","0.00498"
"11472","68.79600","5.73322","0.00467"
"11485","68.87400","5.73968","0.00522"
"11498","68.95200","5.74613","0.00488"
"11511","69.03000","5.75265","0.00463"
"11524","69.10800","5.75923","0.00506"
"11537","69.18600","5.76574","0.00481"
"11550","69.26400","5.77220","0.00530"
"11563","69.34200","5.77878","0.00489"
"11576","69.42000","5.78518","0.00520"
"11589","69.49800","5.79163","0.00502"
"11602","69.57600","5.79815","0.00551"
"11615","69.65400","5.80473","0.00501"
"11628","69.73200","5.81118","0.00529"
"11641","69.81000","5.81770","0.00488"
"11654","69.88800","5.82416","0.00488"
"11667","69.96600","5.83068","0.00498"
"11680","70.04400","5.83713","0.00536"
"11693","70.12200","5.84365","0.00516"
"11706","70.20000","5.85023","0.00518"
"11719","70.27800","5.85668","0.00539"
"11732","70.35600","5.86326","0.00516"
"11745","70.43400","5.86966","0.00503"
"11758","70.51200","5.87617","0.00488"
"11771","70.59000","5.88263","0.00516"
"11784","70.66800","5.88915","0.00507"
"11797","70.74600","5.89567","0.00536"
"11810","70.82400","5.90218","0.00492"
"11823","70.90200","5.90870","0.00508"
"11836","70.98000","5.91516","0.00544"
"11849","71.05800","5.92161","0.00528"
"11862","71.13600","5.92813","0.00571"
"11875","71.21400","5.93465","0.00534"
"11888","71.29200","5.94123","0.00529"
"11901","71.37000","5.94768","0.00562"
"11914","71.44800","5.95426","0.00534"
"11927","71.52600","5.96072","0.00551"
"11940","71.60400","5.96717","0.00481"
"11953","71.68200","5.97369","0.00538"
"11966","71.76000","5.98021","0.00580"
"11979","71.83800","5.98673","0.00565"
"11992","71.91600","5.99324","0.00521"
"12005","71.99400","5.99970","0.00576"
"12018","72.07200","6.00622","0.00536"
"12031","72.15000","6.01267","0.00531"
"12044","72.22800","6.01919","0.00540"
"12057","72.30600","6.02565","0.00568"
"12070","72.38400","6.03223","0.00564"
"12083","72.46200","6.03868","0.00533"
"12096","72.54000","6.04520","0.00522"
"12109","72.61800","6.05166","0.00610"
"12122","72.69600","6.05817","0.00559"
"12135","72.77400","6.06463","0.00556"
"12148","72.85200","6.07121","0.00537"
"12161","72.93000","6.07773","0.00555"
"12174","73.00800","6.08418","0.00569"
"12187","73.08600","6.09070","0.00636"
"12200","73.16400","6.09716","0.00514"
"12213","73.24200","6.10367","0.00582"
"12226","73.32000","6.11013","0.00537"
"12239","73.39800","6.11671","0.00574"
"12252","73.47600","6.12323","0.00540"
"12265","73.55400","6.12968","0.00557"
"12278","73.63200","6.13620","0.00542"
"12291","73.71000","6.14266","0.00577"
"12304","73.78800","6.14917","0.00548"
"12317","73.86600","6.15563","0.00546"
"12330","73.94400","6.16221","0.00582"
"12343","74.02200","6.16867","0.00561"
"12356","74.10000","6.17524","0.00584"
"12369","74.17800","6.18170","0.00569"
"12382","74.25600","6.18822","0.00622"
"12395","74.33400","6.19467","0.00598"
"12408","74.41200","6.20119","0.00591"
"12421","74.49000","6.20771","0.00595"
"12434","74.56800","6.21422","0.00576"
"12447","74.64600","6.22074","0.00597"
"12460","74.72400","6.22714","0.00586"
"12473","74.80200","6.23366","0.00604"
"12486","74.88000","6.24011","0.00565"
"12499","74.95800","6.24663","0.00600"
"12512","75.03600","6.25321","0.00568"
"12525","75.11400","6.25973","0.00566"
"12538","75.19200","6.26618","0.00557"
"12551","75.27000","6.27264","0.00592"
"12564","75.34800","6.27916","0.00550"
"12577","75.42600","6.28561","0.00581"
"12590","75.50400","6.29225","0.00593"
"12603","75.58200","6.29871","0.00611"
"12616","75.66000","6.30528","0.00604"
"12629","75.73800","6.31174","0.00610"
"12642","75.81600","6.31826","0.00610"
"12655","75.89400","6.32466","0.00559"
"12668","75.97200","6.33111","0.00607"
"12681","76.05000","6.33769","0.00601"
"12694","76.12800","6.34421","0.00609"
"12707","76.20600","6.35067","0.00604"
"12720","76.28400","6.35724","0.00572"
"12733","76.36200","6.36370","0.00609"
"12746","76.44000","6.37016","0.00599"
"12759","76.51800","6.37661","0.00617"
"12772","76.59600","6.38319","0.00606"
"12785","76.67400","6.38971","0.00605"
"12798","76.75200","6.39622","0.00590"
"12811","76.83000","6.40274","0.00578"
"12824","76.90800","6.40920","0.00617"
"12837","76.98600","6.41566","0.00643"
"12850","77.06400","6.42211","0.00588"
"12863","77.14200","6.42863","0.00623"
"12876","77.22000","6.43521","0.00602"
"12889","77.29800","6.44166","0.00599"
"12902","77.37600","6.44824","0.00637"
"12915","77.45400","6.45464","0.00628"
"12928","77.53200","6.46116","0.00590"
"12941","77.61000","6.46761","0.00672"
"12954","77.68800","6.47419","0.00588"
"12967","77.76600","6.48071","0.00586"
"12980","77.84400","6.48722","0.00633"
"12993","77.92200","6.49368","0.00664"
"13006","78.00000","6.50020","0.00602"
"13019","78.07800","6.50666","0.00622"
"13032","78.15600","6.51311","0.00642"
"13045","78.23400","6.51969","0.00667"
"13058","78.31200","6.52621","0.00650"
"13071","78.39000","6.53278","0.00653"
"13084","78.46800","6.53918","0.00662"
"13097","78.54600","6.54570","0.00649"
"13110","78.62400","6.55216","0.00673"
"13123","78.70200","6.55867","0.00625"
"13136","78.78000","6.56519","0.00598"
"13149","78.85800","6.57171","0.00675"
"13162","78.93600","6.57822","0.00673"
"13175","79.01400","6.58468","0.00655"
"13188","79.09200","6.59114","0.00649"
"13201","79.17000","6.59766","0.00605"
"13214","79.24800","6.60417","0.00641"
"13227","79.32600","6.61069","0.00668"
"13240","79.40400","6.61721","0.00638"
"13253","79.48200","6.62372","0.00657"
"13266","79.56000","6.63024","0.00622"
"13279","79.63800","6.63670","0.00627"
"13292","79.71600","6.64316","0.00655"
"13305","79.79400","6.64967","0.00643"
"13318","79.87200","6.65625","0.00641"
"13331","79.95000","6.66271","0.00666"
"13344","80.02800","6.66922","0.00672"
"13357","80.10600","6.67574","0.00711"
"13370","80.18400","6.68220","0.00664"
"13383","80.26200","6.68866","0.00715"
"13396","80.34000","6.69517","0.00724"
"13409","80.41800","6.70169","0.00720"
"13422","80.49600","6.70821","0.00702"
"13435","80.57400","6.71472","0.00704"
"13448","80.65200","6.72118","0.00688"
"13461","80.73000","6.72770","0.00731"
"13474","80.80800","6.73421","0.00706"
"13487","80.88600","6.74067","0.00720"
"13500","80.96400","6.74719","0.00695"
"13513","81.04200","6.75371","0.00718"
"13526","81.12000","6.76028","0.00719"
"13539","81.19800","6.76668","0.00664"
"13552","81.27600","6.77314","0.00740"
"13565","81.35400","6.77960","0.00736"
"13578","81.43200","6.78617","0.00708"
"13591","81.51000","6.79269","0.00704"
"13604","81.58800","6.79921","0.00663"
"13617","81.66600","6.80572","0.00678"
"13630","81.74400","6.81218","0.00710"
"13643","81.82200","6.81870","0.00759"
"13656","81.90000","6.82516","0.00691"
"13669","81.97800","6.83173","0.00682"
"13682","82.05600","6.83819","0.00745"
"13695","82.13400","6.84471","0.00683"
"13708","82.21200","6.85116","0.00723"
"13721","82.29000","6.85774","0.00737"
"13734","82.36800","6.86420","0.00727"
"13747","82.44600","6.87071","0.00724"
"13760","82.52400","6.87723","0.00713"
"13773","82.60200","6.88375","0.00716"
"13786","82.68000","6.89027","0.00730"
"13799","82.75800","6.89672","0.00763"
"13812","82.83600","6.90324","0.00759"
"13825","82.91400","6.90970","0.00778"
"13838","82.99200","6.91615","0.00737"
"13851","83.07000","6.92267","0.00738"
"13864","83.14800","6.92925","0.00750"
"13877","83.22600","6.93565","0.00751"
"13890","83.30400","6.94216","0.00748"
"13903","83.38200","6.94862","0.00753"
"13916","83.46000","6.95514","0.00749"
"13929","83.53800","6.96165","0.00770"
"13942","83.61600","6.96817","0.00738"
"13955","83.69400","6.97475","0.00722"
"13968","83.77200","6.98121","0.00765"
"13981","83.85000","6.98766","0.00794"
"13994","83.92800","6.99418","0.00726"
"14007","84.00600","7.00064","0.00711"
"14020","84.08400","7.00715","0.00790"
"14033","84.16200","7.01367","0.00746"
"14046","84.24000","7.02019","0.00786"
"14059","84.31800","7.02671","0.00769"
"14072","84.39600","7.03316","0.00751"
"14085","84.47400","7.03962","0.00789"
"14098","84.55200","7.04614","0.00755"
"14111","84.63000","7.05271","0.00767"
"14124","84.70800","7.05923","0.00812"
"14137","84.78600","7.06569","0.00800"
"14150","84.86400","7.07227","0.00763"
"14163","84.94200","7.07866","0.00780"
"14176","85.02000","7.08518","0.00786"
"14189","85.09800","7.09164","0.00766"
"14202","85.17600","7.09815","0.00801"
"14215","85.25400","7.10473","0.00777"
"14228","85.33200","7.11119","0.00771"
"14241","85.41000","7.11770","0.00819"
"14254","85.48800","7.12416","0.00790"
"14267","85.56600","7.13068","0.00788"
"14280","85.64400","7.13708","0.00758"
"14293","85.72200","7.14371","0.00820"
"14306","85.80000","7.15017","0.00798"
"14319","85.87800","7.15669","0.00827"
"14332","85.95600","7.16320","0.00791"
"14345","86.03400","7.16972","0.00777"
"14358","86.11200","7.17618","0.00831"
"14371","86.19000","7.18264","0.00813"
"14384","86.26800","7.18921","0.00793"
"14397","86.34600","7.19573","0.00815"
"14410","86.42400","7.20225","0.00804"
"14423","86.50200","7.20870","0.00818"
"14436","86.58000","7.21522","0.00794"
"14449","86.65800","7.22168","0.00815"
"14462","86.73600","7.22814","0.00845"
"14475","86.81400","7.23465","0.00824"
"14488","86.89200","7.24123","0.00825"
"14501","86.97000","7.24775","0.00821"
"14514","87.04800","7.25426","0.00817"
"14527","87.12600","7.26072","0.00846"
"14540","87.20400","7.26718","0.00830"
"14553","87.28200","7.27370","0.00831"
"14566","87.36000","7.28015","0.00842"
"14579","87.43800","7.28673","0.00834"
"14592","87.51600","7.29319","0.00822"
"14605","87.59400","7.29970","0.00817"
"14618","87.67200","7.30616","0.00806"
"14631","87.75000","7.31268","0.00836"
"14644","87.82800","7.31914","0.00811"
"14657","87.90600","7.32571","0.00825"
"14670","87.98400","7.33223","0.00850"
"14683","88.06200","7.33875","0.00827"
"14696","88.14000","7.34526","0.00809"
"14709","88.21800","7.35166","0.00840"
"14722","88.29600","7.35818","0.00856"
"14735","88.37400","7.36470","0.00818"
"14748","88.45200","7.37121","0.00817"
"14761","88.53000","7.37773","0.00865"
"14774","88.60800","7.38425","0.00819"
"14787","88.68600","7.39070","0.00814"
"14800","88.76400","7.39716","0.00880"
"14813","88.84200","7.40368","0.00888"
"14826","88.92000","7.41014","0.00867"
"14839","88.99800","7.41671","0.00831"
"14852","89.07600","7.42323","0.00873"
"14865","89.15400","7.42975","0.00839"
"14878","89.23200","7.43620","0.00879"
"14891","89.31000","7.44266","0.00874"
"14904","89.38800","7.44918","0.00899"
"14917","89.46600","7.45570","0.00852"
"14930","89.54400","7.46221","0.00899"
"14943","89.62200","7.46867","0.00920"
"14956","89.70000","7.47519","0.00905"
"14969","89.77800","7.48164","0.00878"
"14982","89.85600","7.48816","0.00881"
"14995","89.93400","7.49456","0.00889"
"15008","90.01200","7.50119","0.00888"
"15021","90.09000","7.50771","0.00954"
"15034","90.16800","7.51429","0.00875"
"15047","90.24600","7.52069","0.00920"
"15060","90.32400","7.52720","0.00874"
"15073","90.40200","7.53366","0.00886"
"15086","90.48000","7.54018","0.00883"
"15099","90.55800","7.54669","0.00856"
"15112","90.63600","7.55315","0.00925"
"15125","90.71400","7.55973","0.00932"
"15138","90.79200","7.56619","0.00896"
"15151","90.87000","7.57276","0.00866"
"15164","90.94800","7.57916","0.00927"
"15177","91.02600","7.58568","0.00948"
"15190","91.10400","7.59213","0.00914"
"15203","91.18200","7.59871","0.00937"
"15216","91.26000","7.60517","0.00929"
"15229","91.33800","7.61169","0.00880"
"15242","91.41600","7.61820","0.00921"
"15255","91.49400","7.62466","0.00961"
"15268","91.57200","7.63118","0.00875"
"15281","91.65000","7.63769","0.00925"
"15294","91.72800","7.64421","0.00914"
"15307","91.80600","7.65073","0.00953"
"15320","91.88400","7.65719","0.00962"
"15333","91.96200","7.66370","0.00899"
"15346","92.04000","7.67016","0.00963"
"15359","92.11800","7.67662","0.00940"
"15372","92.19600","7.68313","0.00936"
"15385","92.27400","7.68971","0.00965"
"15398","92.35200","7.69617","0.00981"
"15411","92.43000","7.70269","0.00912"
"15424","92.50800","7.70914","0.00957"
"15437","92.58600","7.71572","0.00971"
"15450","92.66400","7.72212","0.00945"
"15463","92.74200","7.72869","0.00948"
"15476","92.82000","7.73515","0.00961"
"15489","92.89800","7.74167","0.00880"
"15502","92.97600","7.74819","0.00983"
"15515","93.05400","7.75470","0.00943"
"15528","93.13200","7.76116","0.00954"
"15541","93.21000","7.76768","0.00963"
"15554","93.28800","7.77419","0.00941"
"15567","93.36600","7.78071","0.01017"
"15580","93.44400","7.78723","0.00981"
"15593","93.52200","7.79369","0.00999"
"15606","93.60000","7.80020","0.00972"
"15619","93.67800","7.80666","0.00978"
"15632","93.75600","7.81318","0.00987"
"15645","93.83400","7.81963","0.00989"
"15658","93.91200","7.82621","0.00995"
"15671","93.99000","7.83267","0.00994"
"15684","94.06800","7.83919","0.00989"
"15697","94.14600","7.84564","0.01037"
"15710","94.22400","7.85216","0.00952"
"15723","94.30200","7.85868","0.01039"
"15736","94.38000","7.86519","0.01026"
"15749","94.45800","7.87177","-0.00078"
"15762","94.53600","7.87823","0.00118"
"15775","94.61400","7.88474","-0.00093"
"15788","94.69200","7.89114","-0.00048"
"15801","94.77000","7.89766","-0.00097"
"15814","94.84800","7.90412","0.00104"
"15827","94.92600","7.91069","0.00049"
"15840","95.00400","7.91721","0.00136"
"15853","95.08200","7.92373","-0.00013"
"15866","95.16000","7.93024","0.00018"
"15879","95.23800","7.93664","-0.00061"
"15892","95.31600","7.94316","-0.00034"
"15905","95.39400","7.94962","-0.00008"
"15918","95.47200","7.95619","0.00094"
"15931","95.55000","7.96271","0.00047"
"15944","95.62800","7.96923","0.00008"
"15957","95.70600","7.97568","-0.00025"
"15970","95.78400","7.98220","-0.00049"
"15983","95.86200","7.98866","-0.00026"
"15996","95.94000","7.99518","0.00043"
"16009","96.01800","8.00169","0.00105"
"16022","96.09600","8.00821","0.00084"
"16035","96.17400","8.01473","0.00045"
"16048","96.25200","8.02112","0.00002"
"16061","96.33000","8.02770","0.00000"
"16074","96.40800","8.03410","0.00004"
"16087","96.48600","8.04068","0.00033"
"16100","96.56400","8.04713","0.00040"
"16113","96.64200","8.05371","0.00039"
"16126","96.72000","8.06023","0.00035"
"16139","96.79800","8.06668","-0.00020"
"16152","96.87600","8.07314","-0.00024"
"16165","96.95400","8.07966","0.00005"
"16178","97.03200","8.08618","0.00023"
"16191","97.11000","8.09269","0.00059"
"16204","97.18800","8.09921","0.00036"
"16217","97.26600","8.10573","0.00024"
"16230","97.34400","8.11218","0.00003"
"16243","97.42200","8.11870","0.00011"
"16256","97.50000","8.12516","0.00086"
"16269","97.57800","8.13168","0.00099"
"16282","97.65600","8.13819","0.00080"
"16295","97.73400","8.14471","0.00069"
"16308","97.81200","8.15123","0.00019"
"16321","97.89000","8.15768","0.00001"
"16334","97.96800","8.16414","0.00035"
"16347","98.04600","8.17072","0.00060"
"16360","98.12400","8.17718","0.00038"
"16373","98.20200","8.18369","0.00047"
"16386","98.28000","8.19015","0.00018"
"16399","98.35800","8.19673","0.00029"
"16412","98.43600","8.20318","0.00020"
"16425","98.51400","8.20964","0.00039"
"16438","98.59200","8.21616","0.00044"
"16451","98.67000","8.22268","0.00041"
"16459","98.71600","8.22650","0.00063"