File: Trajectories_together/161226_1Specimen_RawData_1.csv
"","V1","V2","V3"
"1","End date","12/26/2016",""
"2","Specimen label","15DT_27",""
"3","Maximum Load","0.05819","N"
"4","Time","Extension","Load"
"5","(s)","(mm)","(N)"
"6","0.00000","0.00000","-0.00011"
"62","0.33600","0.02786","0.00008"
"118","0.67200","0.05620","-0.00005"
"174","1.00800","0.08418","0.00014"
"230","1.34400","0.11222","0.00009"
"286","1.68000","0.14021","-0.00051"
"342","2.01600","0.16819","0.00005"
"398","2.35200","0.19623","-0.00016"
"454","2.68800","0.22415","-0.00014"
"510","3.02400","0.25219","0.00000"
"566","3.36000","0.28017","-0.00035"
"622","3.69600","0.30816","0.00003"
"678","4.03200","0.33626","-0.00011"
"734","4.36800","0.36418","0.00027"
"790","4.70400","0.39216","-0.00012"
"846","5.04000","0.42020","0.00005"
"902","5.37600","0.44818","-0.00042"
"958","5.71200","0.47616","0.00004"
"1014","6.04800","0.50421","-0.00031"
"1070","6.38400","0.53207","-0.00018"
"1126","6.72000","0.56017","-0.00038"
"1182","7.05600","0.58821","-0.00018"
"1238","7.39200","0.61613","-0.00036"
"1294","7.72800","0.64423","-0.00042"
"1350","8.06400","0.67221","-0.00036"
"1406","8.40000","0.70020","-0.00048"
"1462","8.73600","0.72818","-0.00053"
"1518","9.07200","0.75616","-0.00086"
"1574","9.40800","0.78414","-0.00009"
"1630","9.74400","0.81218","-0.00043"
"1686","10.08000","0.84022","-0.00033"
"1742","10.41600","0.86820","-0.00092"
"1798","10.75200","0.89619","-0.00078"
"1854","11.08800","0.92417","-0.00085"
"1910","11.42400","0.95221","-0.00031"
"1966","11.76000","0.98013","-0.00080"
"2022","12.09600","1.00817","-0.00065"
"2078","12.43200","1.03621","-0.00037"
"2134","12.76800","1.06413","-0.00010"
"2190","13.10400","1.09218","-0.00005"
"2246","13.44000","1.12016","-0.00062"
"2302","13.77600","1.14814","-0.00077"
"2358","14.11200","1.17618","-0.00045"
"2414","14.44800","1.20410","-0.00068"
"2470","14.78400","1.23220","-0.00032"
"2526","15.12000","1.26018","-0.00066"
"2582","15.45600","1.28817","-0.00061"
"2638","15.79200","1.31621","-0.00077"
"2694","16.12800","1.34419","-0.00065"
"2750","16.46400","1.37217","-0.00038"
"2806","16.80000","1.40021","-0.00016"
"2862","17.13600","1.42813","-0.00101"
"2918","17.47200","1.45617","-0.00066"
"2974","17.80800","1.48422","-0.00057"
"3030","18.14400","1.51214","-0.00095"
"3086","18.48000","1.54024","-0.00046"
"3142","18.81600","1.56816","-0.00096"
"3198","19.15200","1.59614","-0.00026"
"3254","19.48800","1.62418","-0.00080"
"3310","19.82400","1.65216","-0.00080"
"3366","20.16000","1.68015","-0.00043"
"3422","20.49600","1.70819","-0.00060"
"3478","20.83200","1.73623","-0.00074"
"3534","21.16800","1.76421","-0.00066"
"3590","21.50400","1.79219","-0.00074"
"3646","21.84000","1.82017","-0.00080"
"3702","22.17600","1.84815","-0.00062"
"3758","22.51200","1.87608","-0.00010"
"3814","22.84800","1.90424","-0.00026"
"3870","23.18400","1.93222","-0.00022"
"3926","23.52000","1.96014","-0.00037"
"3982","23.85600","1.98818","-0.00057"
"4038","24.19200","2.01616","-0.00063"
"4094","24.52800","2.04414","-0.00082"
"4150","24.86400","2.07225","-0.00022"
"4206","25.20000","2.10011","-0.00018"
"4262","25.53600","2.12821","-0.00001"
"4318","25.87200","2.15619","-0.00100"
"4374","26.20800","2.18417","-0.00068"
"4430","26.54400","2.21215","-0.00069"
"4486","26.88000","2.24019","-0.00074"
"4542","27.21600","2.26818","-0.00084"
"4598","27.55200","2.29622","-0.00096"
"4654","27.88800","2.32414","-0.00077"
"4710","28.22400","2.35224","-0.00043"
"4766","28.56000","2.38022","-0.00079"
"4822","28.89600","2.40814","-0.00063"
"4878","29.23200","2.43618","-0.00082"
"4934","29.56800","2.46417","-0.00054"
"4990","29.90400","2.49215","-0.00065"
"5046","30.24000","2.52019","-0.00076"
"5102","30.57600","2.54817","-0.00013"
"5158","30.91200","2.57615","-0.00081"
"5214","31.24800","2.60419","-0.00062"
"5270","31.58400","2.63217","-0.00036"
"5326","31.92000","2.66022","-0.00054"
"5382","32.25600","2.68814","-0.00026"
"5438","32.59200","2.71624","-0.00034"
"5494","32.92800","2.74416","-0.00079"
"5550","33.26400","2.77214","-0.00071"
"5606","33.60000","2.80030","-0.00091"
"5662","33.93600","2.82822","-0.00061"
"5718","34.27200","2.85615","-0.00075"
"5774","34.60800","2.88419","-0.00096"
"5830","34.94400","2.91211","-0.00095"
"5886","35.28000","2.94015","-0.00092"
"5942","35.61600","2.96819","-0.00061"
"5998","35.95200","2.99617","-0.00100"
"6054","36.28800","3.02421","-0.00114"
"6110","36.62400","3.05220","-0.00136"
"6166","36.96000","3.08018","-0.00092"
"6222","37.29600","3.10816","-0.00095"
"6278","37.63200","3.13620","-0.00085"
"6334","37.96800","3.16418","-0.00061"
"6390","38.30400","3.19222","-0.00057"
"6446","38.64000","3.22014","-0.00086"
"6502","38.97600","3.24819","-0.00019"
"6558","39.31200","3.27623","-0.00063"
"6614","39.64800","3.30415","-0.00072"
"6670","39.98400","3.33219","-0.00054"
"6726","40.32000","3.36017","-0.00075"
"6782","40.65600","3.38821","-0.00076"
"6838","40.99200","3.41619","-0.00122"
"6894","41.32800","3.44412","-0.00074"
"6950","41.66400","3.47222","-0.00072"
"7006","42.00000","3.50020","-0.00102"
"7062","42.33600","3.52818","-0.00073"
"7118","42.67200","3.55616","-0.00070"
"7174","43.00800","3.58414","-0.00102"
"7230","43.34400","3.61218","-0.00083"
"7286","43.68000","3.64017","-0.00113"
"7342","44.01600","3.66815","-0.00087"
"7398","44.35200","3.69625","-0.00107"
"7454","44.68800","3.72411","-0.00071"
"7510","45.02400","3.75215","-0.00084"
"7566","45.36000","3.78025","-0.00077"
"7622","45.69600","3.80817","-0.00092"
"7678","46.03200","3.83616","-0.00154"
"7734","46.36800","3.86426","-0.00087"
"7790","46.70400","3.89218","-0.00095"
"7846","47.04000","3.92016","-0.00061"
"7902","47.37600","3.94814","-0.00130"
"7958","47.71200","3.97612","-0.00115"
"8014","48.04800","4.00416","-0.00140"
"8070","48.38400","4.03215","-0.00127"
"8126","48.72000","4.06019","-0.00147"
"8182","49.05600","4.08823","-0.00114"
"8238","49.39200","4.11615","-0.00084"
"8294","49.72800","4.14419","-0.00117"
"8350","50.06400","4.17211","-0.00040"
"8406","50.40000","4.20021","-0.00070"
"8462","50.73600","4.22820","-0.00130"
"8518","51.07200","4.25618","-0.00134"
"8574","51.40800","4.28422","-0.00084"
"8630","51.74400","4.31220","-0.00096"
"8686","52.08000","4.34012","-0.00130"
"8742","52.41600","4.36822","-0.00084"
"8798","52.75200","4.39614","-0.00141"
"8854","53.08800","4.42419","-0.00083"
"8910","53.42400","4.45223","-0.00118"
"8966","53.76000","4.48015","-0.00072"
"9022","54.09600","4.50819","-0.00081"
"9078","54.43200","4.53623","-0.00155"
"9134","54.76800","4.56415","-0.00158"
"9190","55.10400","4.59219","-0.00129"
"9246","55.44000","4.62018","-0.00116"
"9302","55.77600","4.64810","-0.00103"
"9358","56.11200","4.67620","-0.00133"
"9414","56.44800","4.70418","-0.00066"
"9470","56.78400","4.73216","-0.00093"
"9526","57.12000","4.76026","-0.00103"
"9582","57.45600","4.78813","-0.00087"
"9638","57.79200","4.81617","-0.00076"
"9694","58.12800","4.84421","-0.00072"
"9750","58.46400","4.87213","-0.00085"
"9806","58.80000","4.90017","-0.00025"
"9862","59.13600","4.92821","-0.00104"
"9918","59.47200","4.95619","-0.00069"
"9974","59.80800","4.98423","-0.00068"
"10030","60.14400","5.01210","-0.00068"
"10086","60.48000","5.04020","-0.00107"
"10142","60.81600","5.06812","-0.00081"
"10198","61.15200","5.09622","-0.00103"
"10254","61.48800","5.12420","-0.00084"
"10310","61.82400","5.15212","-0.00095"
"10366","62.16000","5.18023","-0.00136"
"10422","62.49600","5.20821","-0.00075"
"10478","62.83200","5.23613","-0.00037"
"10534","63.16800","5.26417","-0.00060"
"10590","63.50400","5.29215","-0.00086"
"10646","63.84000","5.32013","-0.00067"
"10702","64.17600","5.34817","-0.00124"
"10758","64.51200","5.37616","-0.00106"
"10814","64.84800","5.40420","-0.00128"
"10870","65.18400","5.43224","-0.00110"
"10926","65.52000","5.46010","-0.00083"
"10982","65.85600","5.48820","-0.00049"
"11038","66.19200","5.51618","-0.00101"
"11094","66.52800","5.54416","-0.00095"
"11150","66.86400","5.57221","-0.00076"
"11206","67.20000","5.60019","-0.00132"
"11262","67.53600","5.62817","-0.00168"
"11318","67.87200","5.65621","-0.00109"
"11374","68.20800","5.68413","-0.00179"
"11430","68.54400","5.71217","-0.00074"
"11486","68.88000","5.74021","-0.00125"
"11542","69.21600","5.76820","-0.00085"
"11598","69.55200","5.79618","-0.00116"
"11654","69.88800","5.82416","-0.00107"
"11710","70.22400","5.85220","-0.00127"
"11766","70.56000","5.88018","-0.00093"
"11822","70.89600","5.90816","-0.00050"
"11878","71.23200","5.93620","-0.00103"
"11934","71.56800","5.96419","-0.00080"
"11990","71.90400","5.99217","-0.00120"
"12046","72.24000","6.02021","-0.00090"
"12102","72.57600","6.04813","-0.00108"
"12158","72.91200","6.07617","-0.00169"
"12214","73.24800","6.10421","-0.00110"
"12270","73.58400","6.13207","-0.00108"
"12326","73.92000","6.16024","-0.00087"
"12382","74.25600","6.18816","-0.00122"
"12438","74.59200","6.21614","-0.00140"
"12494","74.92800","6.24424","-0.00111"
"12550","75.26400","6.27210","-0.00118"
"12606","75.60000","6.30014","-0.00088"
"12662","75.93600","6.32824","-0.00092"
"12718","76.27200","6.35611","-0.00099"
"12774","76.60800","6.38421","-0.00108"
"12830","76.94400","6.41219","-0.00071"
"12886","77.28000","6.44017","-0.00116"
"12942","77.61600","6.46821","-0.00033"
"12998","77.95200","6.49619","-0.00078"
"13054","78.28800","6.52417","-0.00140"
"13110","78.62400","6.55222","-0.00093"
"13166","78.96000","6.58014","-0.00099"
"13222","79.29600","6.60818","-0.00132"
"13278","79.63200","6.63616","-0.00104"
"13334","79.96800","6.66420","-0.00120"
"13390","80.30400","6.69218","-0.00130"
"13446","80.64000","6.72016","-0.00049"
"13502","80.97600","6.74821","-0.00068"
"13558","81.31200","6.77619","-0.00132"
"13614","81.64800","6.80417","-0.00073"
"13670","81.98400","6.83221","-0.00080"
"13726","82.32000","6.86019","-0.00084"
"13782","82.65600","6.88817","-0.00103"
"13838","82.99200","6.91621","-0.00116"
"13894","83.32800","6.94420","-0.00167"
"13950","83.66400","6.97224","-0.00081"
"14006","84.00000","7.00022","-0.00133"
"14062","84.33600","7.02814","-0.00127"
"14118","84.67200","7.05624","-0.00125"
"14174","85.00800","7.08416","-0.00090"
"14230","85.34400","7.11214","-0.00097"
"14286","85.68000","7.14019","-0.00141"
"14342","86.01600","7.16811","-0.00035"
"14398","86.35200","7.19615","-0.00113"
"14454","86.68800","7.22425","-0.00094"
"14510","87.02400","7.25217","-0.00080"
"14566","87.36000","7.28021","-0.00075"
"14622","87.69600","7.30819","-0.00080"
"14678","88.03200","7.33618","-0.00103"
"14734","88.36800","7.36416","-0.00101"
"14790","88.70400","7.39214","-0.00065"
"14846","89.04000","7.42018","-0.00111"
"14902","89.37600","7.44816","-0.00103"
"14958","89.71200","7.47620","-0.00090"
"15014","90.04800","7.50418","-0.00086"
"15070","90.38400","7.53217","-0.00074"
"15126","90.72000","7.56021","-0.00152"
"15182","91.05600","7.58819","-0.00045"
"15238","91.39200","7.61611","-0.00097"
"15294","91.72800","7.64427","-0.00064"
"15350","92.06400","7.67219","-0.00037"
"15406","92.40000","7.70018","-0.00118"
"15462","92.73600","7.72822","-0.00055"
"15518","93.07200","7.75614","-0.00107"
"15574","93.40800","7.78418","-0.00103"
"15630","93.74400","7.81222","-0.00042"
"15686","94.08000","7.84008","-0.00072"
"15742","94.41600","7.86824","-0.00072"
"15798","94.75200","7.89622","-0.00072"
"15854","95.08800","7.92415","-0.00089"
"15910","95.42400","7.95219","-0.00067"
"15966","95.76000","7.98017","-0.00084"
"16022","96.09600","8.00815","-0.00070"
"16078","96.43200","8.03619","-0.00073"
"16134","96.76800","8.06411","-0.00077"
"16190","97.10400","8.09215","-0.00077"
"16246","97.44000","8.12026","-0.00054"
"16302","97.77600","8.14818","-0.00087"
"16358","98.11200","8.17622","-0.00089"
"16414","98.44800","8.20414","-0.00071"
"16470","98.78400","8.23212","-0.00043"
"16526","99.12000","8.26016","-0.00190"
"16582","99.45600","8.28814","-0.00187"
"16638","99.79200","8.31619","-0.00151"
"16694","100.12800","8.34423","-0.00123"
"16750","100.46400","8.37215","-0.00131"
"16806","100.80000","8.40019","-0.00160"
"16862","101.13600","8.42811","-0.00139"
"16918","101.47200","8.45621","-0.00154"
"16974","101.80800","8.48419","-0.00179"
"17030","102.14400","8.51212","-0.00131"
"17086","102.48000","8.54028","-0.00132"
"17142","102.81600","8.56820","-0.00168"
"17198","103.15200","8.59618","-0.00174"
"17254","103.48800","8.62422","-0.00143"
"17310","103.82400","8.65214","-0.00120"
"17366","104.16000","8.68018","-0.00142"
"17422","104.49600","8.70829","-0.00168"
"17478","104.83200","8.73609","-0.00136"
"17534","105.16800","8.76419","-0.00072"
"17590","105.50400","8.79217","-0.00112"
"17646","105.84000","8.82015","-0.00150"
"17702","106.17600","8.84819","-0.00083"
"17758","106.51200","8.87617","-0.00141"
"17814","106.84800","8.90410","-0.00119"
"17870","107.18400","8.93220","-0.00119"
"17926","107.52000","8.96012","-0.00182"
"17982","107.85600","8.98822","-0.00102"
"18038","108.19200","9.01620","-0.00185"
"18094","108.52800","9.04418","-0.00163"
"18150","108.86400","9.07222","-0.00082"
"18206","109.20000","9.10015","-0.00074"
"18262","109.53600","9.12819","-0.00138"
"18318","109.87200","9.15623","-0.00099"
"18374","110.20800","9.18421","-0.00122"
"18430","110.54400","9.21225","-0.00116"
"18486","110.88000","9.24017","-0.00168"
"18542","111.21600","9.26816","-0.00056"
"18598","111.55200","9.29620","-0.00145"
"18654","111.88800","9.32424","-0.00120"
"18710","112.22400","9.35222","-0.00105"
"18766","112.56000","9.38014","-0.00054"
"18822","112.89600","9.40812","-0.00142"
"18878","113.23200","9.43616","-0.00106"
"18934","113.56800","9.46414","-0.00068"
"18990","113.90400","9.49219","-0.00102"
"19046","114.24000","9.52023","-0.00042"
"19102","114.57600","9.54815","-0.00106"
"19158","114.91200","9.57613","-0.00058"
"19214","115.24800","9.60423","-0.00103"
"19270","115.58400","9.63215","-0.00110"
"19326","115.92000","9.66019","-0.00049"
"19382","116.25600","9.68824","-0.00049"
"19438","116.59200","9.71616","-0.00070"
"19494","116.92800","9.74420","-0.00057"
"19550","117.26400","9.77218","-0.00074"
"19606","117.60000","9.80016","-0.00079"
"19662","117.93600","9.82820","-0.00041"
"19718","118.27200","9.85612","-0.00055"
"19774","118.60800","9.88417","-0.00066"
"19830","118.94400","9.91221","-0.00095"
"19886","119.28000","9.94013","-0.00128"
"19942","119.61600","9.96823","-0.00081"
"19998","119.95200","9.99615","-0.00103"
"20054","120.28800","10.02419","-0.00098"
"20110","120.62400","10.05223","-0.00096"
"20166","120.96000","10.08016","-0.00078"
"20222","121.29600","10.10820","-0.00046"
"20278","121.63200","10.13618","-0.00044"
"20334","121.96800","10.16416","-0.00052"
"20390","122.30400","10.19220","-0.00072"
"20446","122.64000","10.22012","-0.00090"
"20502","122.97600","10.24823","-0.00095"
"20558","123.31200","10.27627","-0.00024"
"20614","123.64800","10.30413","-0.00053"
"20670","123.98400","10.33217","-0.00006"
"20726","124.32000","10.36015","-0.00039"
"20782","124.65600","10.38819","-0.00097"
"20838","124.99200","10.41623","-0.00062"
"20894","125.32800","10.44415","-0.00006"
"20950","125.66400","10.47214","-0.00006"
"21006","126.00000","10.50024","-0.00089"
"21062","126.33600","10.52816","-0.00004"
"21118","126.67200","10.55620","0.00031"
"21174","127.00800","10.58424","-0.00018"
"21230","127.34400","10.61216","-0.00022"
"21286","127.68000","10.64020","-0.00035"
"21342","128.01600","10.66819","-0.00034"
"21398","128.35200","10.69623","0.00003"
"21454","128.68800","10.72421","-0.00079"
"21510","129.02400","10.75219","0.00000"
"21566","129.36000","10.78023","-0.00017"
"21622","129.69600","10.80815","-0.00083"
"21678","130.03200","10.83619","-0.00054"
"21734","130.36800","10.86418","-0.00039"
"21790","130.70400","10.89210","-0.00003"
"21846","131.04000","10.92020","-0.00010"
"21902","131.37600","10.94818","0.00006"
"21958","131.71200","10.97616","-0.00007"
"22014","132.04800","11.00420","0.00001"
"22070","132.38400","11.03219","0.00027"
"22126","132.72000","11.06011","0.00004"
"22182","133.05600","11.08821","0.00042"
"22238","133.39200","11.11613","0.00020"
"22294","133.72800","11.14417","-0.00020"
"22350","134.06400","11.17227","-0.00005"
"22406","134.40000","11.20013","0.00004"
"22462","134.73600","11.22824","0.00007"
"22518","135.07200","11.25622","0.00043"
"22574","135.40800","11.28414","0.00029"
"22630","135.74400","11.31224","0.00042"
"22686","136.08000","11.34016","-0.00001"
"22742","136.41600","11.36820","-0.00007"
"22798","136.75200","11.39618","0.00010"
"22854","137.08800","11.42411","0.00022"
"22910","137.42400","11.45221","0.00044"
"22966","137.76000","11.48019","0.00021"
"23022","138.09600","11.50823","0.00052"
"23078","138.43200","11.53615","0.00019"
"23134","138.76800","11.56419","-0.00016"
"23190","139.10400","11.59217","0.00042"
"23246","139.44000","11.62015","-0.00044"
"23302","139.77600","11.64820","-0.00046"
"23358","140.11200","11.67624","-0.00009"
"23414","140.44800","11.70416","-0.00045"
"23470","140.78400","11.73220","0.00029"
"23526","141.12000","11.76018","0.00023"
"23582","141.45600","11.78810","-0.00013"
"23638","141.79200","11.81621","0.00000"
"23694","142.12800","11.84419","0.00029"
"23750","142.46400","11.87211","0.00015"
"23806","142.80000","11.90021","-0.00014"
"23862","143.13600","11.92819","-0.00039"
"23918","143.47200","11.95617","0.00034"
"23974","143.80800","11.98421","0.00011"
"24030","144.14400","12.01214","0.00042"
"24086","144.48000","12.04018","0.00004"
"24142","144.81600","12.06822","0.00008"
"24198","145.15200","12.09614","0.00035"
"24254","145.48800","12.12424","0.00071"
"24310","145.82400","12.15222","0.00096"
"24366","146.16000","12.18020","0.00040"
"24422","146.49600","12.20819","0.00047"
"24478","146.83200","12.23617","0.00055"
"24534","147.16800","12.26421","0.00068"
"24590","147.50400","12.29219","0.00048"
"24646","147.84000","12.32017","0.00122"
"24702","148.17600","12.34815","0.00074"
"24758","148.51200","12.37619","0.00018"
"24814","148.84800","12.40418","0.00085"
"24870","149.18400","12.43216","0.00065"
"24926","149.52000","12.46008","0.00056"
"24982","149.85600","12.48818","0.00130"
"25038","150.19200","12.51616","0.00049"
"25094","150.52800","12.54414","0.00088"
"25150","150.86400","12.57224","0.00081"
"25206","151.20000","12.60017","0.00131"
"25262","151.53600","12.62815","0.00089"
"25318","151.87200","12.65619","0.00154"
"25374","152.20800","12.68411","0.00106"
"25430","152.54400","12.71221","0.00107"
"25486","152.88000","12.74025","0.00128"
"25542","153.21600","12.76817","0.00171"
"25598","153.55200","12.79628","0.00191"
"25654","153.88800","12.82414","0.00180"
"25710","154.22400","12.85212","0.00166"
"25766","154.56000","12.88022","0.00211"
"25822","154.89600","12.90820","0.00263"
"25878","155.23200","12.93618","0.00238"
"25934","155.56800","12.96416","0.00201"
"25990","155.90400","12.99209","0.00263"
"26046","156.24000","13.02019","0.00222"
"26102","156.57600","13.04811","0.00308"
"26158","156.91200","13.07621","0.00271"
"26214","157.24800","13.10425","0.00313"
"26270","157.58400","13.13217","0.00348"
"26326","157.92000","13.16016","0.00325"
"26382","158.25600","13.18820","0.00384"
"26438","158.59200","13.21618","0.00328"
"26494","158.92800","13.24422","0.00368"
"26550","159.26400","13.27220","0.00359"
"26606","159.60000","13.30024","0.00456"
"26662","159.93600","13.32816","0.00449"
"26718","160.27200","13.35609","0.00401"
"26774","160.60800","13.38419","0.00512"
"26830","160.94400","13.41223","0.00518"
"26886","161.28000","13.44015","0.00515"
"26942","161.61600","13.46825","0.00571"
"26998","161.95200","13.49617","0.00594"
"27054","162.28800","13.52409","0.00595"
"27110","162.62400","13.55220","0.00608"
"27166","162.96000","13.58012","0.00651"
"27222","163.29600","13.60822","0.00681"
"27278","163.63200","13.63620","0.00721"
"27334","163.96800","13.66412","0.00718"
"27390","164.30400","13.69222","0.00756"
"27446","164.64000","13.72014","0.00770"
"27502","164.97600","13.74819","0.00798"
"27558","165.31200","13.77623","0.00849"
"27614","165.64800","13.80415","0.00852"
"27670","165.98400","13.83219","0.00872"
"27726","166.32000","13.86023","0.00083"
"27782","166.65600","13.88815","0.00008"
"27838","166.99200","13.91619","-0.00042"
"27894","167.32800","13.94417","-0.00111"
"27950","167.66400","13.97216","-0.00020"
"28006","168.00000","14.00020","0.00014"
"28062","168.33600","14.02812","-0.00107"
"28118","168.67200","14.05616","-0.00109"
"28174","169.00800","14.08420","-0.00044"
"28230","169.34400","14.11218","-0.00032"
"28286","169.68000","14.14022","-0.00075"
"28342","170.01600","14.16815","-0.00051"
"28398","170.35200","14.19619","-0.00071"
"28454","170.68800","14.22417","-0.00095"
"28510","171.02400","14.25215","-0.00092"
"28566","171.36000","14.28025","-0.00018"
"28622","171.69600","14.30817","-0.00112"
"28678","172.03200","14.33616","-0.00031"
"28734","172.36800","14.36420","0.00015"
"28790","172.70400","14.39218","-0.00056"
"28846","173.04000","14.42016","-0.00072"
"28902","173.37600","14.44820","-0.00067"
"28958","173.71200","14.47618","-0.00108"
"29014","174.04800","14.50416","-0.00039"
"29070","174.38400","14.53220","-0.00057"
"29126","174.72000","14.56019","-0.00070"
"29182","175.05600","14.58817","-0.00061"
"29238","175.39200","14.61615","-0.00053"
"29294","175.72800","14.64413","-0.00071"
"29350","176.06400","14.67223","-0.00088"
"29406","176.40000","14.70015","-0.00059"
"29462","176.73600","14.72820","-0.00039"
"29518","177.07200","14.75624","-0.00048"
"29574","177.40800","14.78410","-0.00092"
"29630","177.74400","14.81220","-0.00064"
"29686","178.08000","14.84018","0.00013"
"29742","178.41600","14.86822","-0.00083"
"29798","178.75200","14.89620","-0.00043"
"29854","179.08800","14.92418","0.00020"
"29910","179.42400","14.95217","-0.00011"
"29966","179.76000","14.98015","-0.00091"
"30022","180.09600","15.00813","0.00051"
"30078","180.43200","15.03623","0.00034"
"30134","180.76800","15.06415","-0.00046"
"30190","181.10400","15.09219","-0.00007"
"30246","181.44000","15.12018","0.00000"
"30302","181.77600","15.14810","-0.00003"
"30358","182.11200","15.17620","-0.00019"
"30414","182.44800","15.20418","0.00004"
"30470","182.78400","15.23216","0.00020"
"30526","183.12000","15.26020","-0.00016"
"30582","183.45600","15.28818","0.00028"
"30638","183.79200","15.31617","-0.00053"
"30694","184.12800","15.34421","0.00001"
"30750","184.46400","15.37213","-0.00013"
"30806","184.80000","15.40023","-0.00042"
"30862","185.13600","15.42821","-0.00026"
"30918","185.47200","15.45619","-0.00050"
"30974","185.80800","15.48417","-0.00041"
"31030","186.14400","15.51222","-0.00014"
"31086","186.48000","15.54014","-0.00023"
"31142","186.81600","15.56824","-0.00048"
"31198","187.15200","15.59616","0.00014"
"31254","187.48800","15.62420","-0.00054"
"31310","187.82400","15.65212","-0.00022"
"31366","188.16000","15.68010","-0.00018"
"31422","188.49600","15.70820","-0.00015"
"31478","188.83200","15.73613","0.00025"
"31534","189.16800","15.76423","-0.00014"
"31590","189.50400","15.79221","0.00005"
"31646","189.84000","15.82013","-0.00056"
"31702","190.17600","15.84823","-0.00060"
"31758","190.51200","15.87615","-0.00058"
"31814","190.84800","15.90420","0.00015"
"31870","191.18400","15.93218","0.00037"
"31926","191.52000","15.96016","-0.00014"
"31982","191.85600","15.98820","-0.00010"
"32038","192.19200","16.01624","-0.00019"
"32094","192.52800","16.04410","0.00027"
"32150","192.86400","16.07214","-0.00010"
"32206","193.20000","16.10019","0.00008"
"32262","193.53600","16.12811","0.00008"
"32318","193.87200","16.15621","0.00067"
"32374","194.20800","16.18419","0.00032"
"32430","194.54400","16.21211","0.00017"
"32486","194.88000","16.24027","0.00062"
"32542","195.21600","16.26814","0.00041"
"32598","195.55200","16.29618","0.00073"
"32654","195.88800","16.32422","-0.00024"
"32710","196.22400","16.35220","0.00033"
"32766","196.56000","16.38024","0.00075"
"32822","196.89600","16.40816","-0.00010"
"32878","197.23200","16.43620","-0.00035"
"32934","197.56800","16.46424","-0.00066"
"32990","197.90400","16.49217","0.00010"
"33046","198.24000","16.52021","-0.00006"
"33102","198.57600","16.54819","-0.00045"
"33158","198.91200","16.57611","-0.00038"
"33214","199.24800","16.60421","-0.00057"
"33270","199.58400","16.63219","-0.00049"
"33326","199.92000","16.66023","-0.00011"
"33382","200.25600","16.68822","-0.00064"
"33438","200.59200","16.71614","0.00039"
"33494","200.92800","16.74412","0.00071"
"33550","201.26400","16.77216","-0.00014"
"33606","201.60000","16.80014","-0.00006"
"33662","201.93600","16.82824","0.00006"
"33718","202.27200","16.85616","0.00032"
"33774","202.60800","16.88421","0.00064"
"33830","202.94400","16.91225","-0.00022"
"33886","203.28000","16.94011","0.00004"
"33942","203.61600","16.96827","-0.00014"
"33998","203.95200","16.99619","0.00062"
"34054","204.28800","17.02411","0.00041"
"34110","204.62400","17.05221","0.00073"
"34166","204.96000","17.08019","0.00055"
"34222","205.29600","17.10812","0.00001"
"34278","205.63200","17.13622","0.00021"
"34334","205.96800","17.16414","0.00022"
"34390","206.30400","17.19224","0.00039"
"34446","206.64000","17.22022","0.00028"
"34502","206.97600","17.24814","0.00042"
"34558","207.31200","17.27612","0.00029"
"34614","207.64800","17.30417","0.00032"
"34670","207.98400","17.33221","0.00043"
"34726","208.32000","17.36025","0.00032"
"34782","208.65600","17.38817","0.00037"
"34838","208.99200","17.41621","0.00067"
"34894","209.32800","17.44413","0.00053"
"34950","209.66400","17.47212","0.00077"
"35006","210.00000","17.50016","0.00064"
"35062","210.33600","17.52814","0.00047"
"35118","210.67200","17.55624","0.00018"
"35174","211.00800","17.58422","0.00057"
"35230","211.34400","17.61214","0.00047"
"35286","211.68000","17.64018","0.00045"
"35342","212.01600","17.66822","0.00013"
"35398","212.35200","17.69621","-0.00007"
"35454","212.68800","17.72419","0.00076"
"35510","213.02400","17.75211","0.00045"
"35566","213.36000","17.78015","0.00033"
"35622","213.69600","17.80819","0.00070"
"35678","214.03200","17.83611","0.00075"
"35734","214.36800","17.86422","0.00071"
"35790","214.70400","17.89220","0.00083"
"35846","215.04000","17.92018","0.00057"
"35902","215.37600","17.94822","0.00027"
"35958","215.71200","17.97620","0.00054"
"36014","216.04800","18.00418","0.00080"
"36070","216.38400","18.03222","0.00080"
"36126","216.72000","18.06021","0.00116"
"36182","217.05600","18.08819","0.00082"
"36238","217.39200","18.11617","0.00088"
"36294","217.72800","18.14415","0.00019"
"36350","218.06400","18.17219","0.00065"
"36406","218.40000","18.20017","0.00085"
"36462","218.73600","18.22816","0.00055"
"36518","219.07200","18.25620","0.00063"
"36574","219.40800","18.28418","0.00077"
"36630","219.74400","18.31222","0.00082"
"36686","220.08000","18.34020","0.00086"
"36742","220.41600","18.36818","0.00085"
"36798","220.75200","18.39616","0.00099"
"36854","221.08800","18.42414","0.00098"
"36910","221.42400","18.45219","0.00132"
"36966","221.76000","18.48023","0.00119"
"37022","222.09600","18.50815","0.00119"
"37078","222.43200","18.53625","0.00108"
"37134","222.76800","18.56417","0.00080"
"37190","223.10400","18.59215","0.00104"
"37246","223.44000","18.62025","0.00135"
"37302","223.77600","18.64818","0.00088"
"37358","224.11200","18.67616","0.00133"
"37414","224.44800","18.70420","0.00152"
"37470","224.78400","18.73212","0.00079"
"37526","225.12000","18.76022","0.00043"
"37582","225.45600","18.78820","0.00071"
"37638","225.79200","18.81618","0.00043"
"37694","226.12800","18.84417","0.00050"
"37750","226.46400","18.87215","0.00046"
"37806","226.80000","18.90013","0.00071"
"37862","227.13600","18.92817","0.00059"
"37918","227.47200","18.95615","0.00059"
"37974","227.80800","18.98425","0.00093"
"38030","228.14400","19.01217","0.00082"
"38086","228.48000","19.04022","0.00089"
"38142","228.81600","19.06820","0.00032"
"38198","229.15200","19.09612","0.00071"
"38254","229.48800","19.12422","0.00091"
"38310","229.82400","19.15220","0.00084"
"38366","230.16000","19.18018","0.00081"
"38422","230.49600","19.20823","0.00131"
"38478","230.83200","19.23615","0.00072"
"38534","231.16800","19.26413","0.00092"
"38590","231.50400","19.29223","0.00110"
"38646","231.84000","19.32009","0.00142"
"38702","232.17600","19.34819","0.00113"
"38758","232.51200","19.37623","0.00122"
"38814","232.84800","19.40421","0.00113"
"38870","233.18400","19.43220","0.00123"
"38926","233.52000","19.46024","0.00094"
"38982","233.85600","19.48816","0.00074"
"39038","234.19200","19.51620","0.00089"
"39094","234.52800","19.54412","0.00115"
"39150","234.86400","19.57216","0.00102"
"39206","235.20000","19.60020","0.00163"
"39262","235.53600","19.62813","0.00129"
"39318","235.87200","19.65623","0.00130"
"39374","236.20800","19.68421","0.00189"
"39430","236.54400","19.71213","0.00192"
"39486","236.88000","19.74023","0.00201"
"39542","237.21600","19.76815","0.00194"
"39598","237.55200","19.79619","0.00223"
"39654","237.88800","19.82418","0.00202"
"39710","238.22400","19.85216","0.00184"
"39766","238.56000","19.88026","0.00186"
"39822","238.89600","19.90812","0.00168"
"39878","239.23200","19.93622","0.00291"
"39934","239.56800","19.96414","0.00230"
"39990","239.90400","19.99213","0.00272"
"40046","240.24000","20.02022","0.00315"
"40102","240.57600","20.04821","0.00339"
"40158","240.91200","20.07619","0.00336"
"40214","241.24800","20.10423","0.00360"
"40270","241.58400","20.13215","0.00420"
"40326","241.92000","20.16019","0.00410"
"40382","242.25600","20.18823","0.00481"
"40438","242.59200","20.21616","0.00451"
"40494","242.92800","20.24420","0.00478"
"40550","243.26400","20.27224","0.00507"
"40606","243.60000","20.30016","0.00515"
"40662","243.93600","20.32814","0.00541"
"40718","244.27200","20.35612","0.00544"
"40774","244.60800","20.38416","0.00586"
"40830","244.94400","20.41221","0.00612"
"40886","245.28000","20.44013","0.00617"
"40942","245.61600","20.46817","0.00669"
"40998","245.95200","20.49621","0.00669"
"41054","246.28800","20.52419","0.00686"
"41110","246.62400","20.55223","0.00716"
"41166","246.96000","20.58015","0.00732"
"41222","247.29600","20.60820","0.00796"
"41278","247.63200","20.63618","0.00846"
"41334","247.96800","20.66416","0.00838"
"41390","248.30400","20.69220","0.00852"
"41446","248.64000","20.72012","0.00901"
"41502","248.97600","20.74817","0.00931"
"41558","249.31200","20.77621","0.00970"
"41614","249.64800","20.80419","0.01009"
"41670","249.98400","20.83217","0.01047"
"41726","250.32000","20.86021","0.01070"
"41782","250.65600","20.88813","0.01122"
"41838","250.99200","20.91623","0.01145"
"41894","251.32800","20.94421","0.01187"
"41950","251.66400","20.97214","0.01256"
"42006","252.00000","21.00024","0.01322"
"42062","252.33600","21.02810","0.01371"
"42118","252.67200","21.05614","0.01483"
"42174","253.00800","21.08424","0.01478"
"42230","253.34400","21.11216","0.01573"
"42286","253.68000","21.14021","0.01624"
"42342","254.01600","21.16825","0.01716"
"42398","254.35200","21.19617","0.01771"
"42454","254.68800","21.22421","0.01845"
"42510","255.02400","21.25219","0.01945"
"42566","255.36000","21.28017","0.02008"
"42622","255.69600","21.30821","0.02127"
"42678","256.03200","21.33613","0.02180"
"42734","256.36800","21.36418","0.02316"
"42790","256.70400","21.39215","0.02370"
"42846","257.04000","21.42014","0.02446"
"42902","257.37600","21.44824","0.02468"
"42958","257.71200","21.47616","0.02587"
"43014","258.04800","21.50420","0.02688"
"43070","258.38400","21.53218","0.02743"
"43126","258.72000","21.56017","0.02891"
"43182","259.05600","21.58821","0.02914"
"43238","259.39200","21.61619","0.02977"
"43294","259.72800","21.64417","0.03028"
"43350","260.06400","21.67221","0.03160"
"43406","260.40000","21.70013","0.03324"
"43462","260.73600","21.72823","0.03431"
"43518","261.07200","21.75621","0.03582"
"43574","261.40800","21.78414","0.03713"
"43630","261.74400","21.81218","0.03818"
"43686","262.08000","21.84022","0.03874"
"43742","262.41600","21.86814","0.04008"
"43798","262.75200","21.89624","0.04137"
"43854","263.08800","21.92416","0.04173"
"43910","263.42400","21.95215","0.04202"
"43966","263.76000","21.98025","0.04287"
"44022","264.09600","22.00811","0.04390"
"44078","264.43200","22.03615","0.04531"
"44134","264.76800","22.06425","0.04629"
"44190","265.10400","22.09217","0.04704"
"44246","265.44000","22.12021","0.04854"
"44302","265.77600","22.14819","0.04932"
"44358","266.11200","22.17618","0.04993"
"44414","266.44800","22.20422","0.05146"
"44470","266.78400","22.23214","0.05195"
"44526","267.12000","22.26024","0.05293"
"44582","267.45600","22.28816","0.05360"
"44638","267.79200","22.31614","0.05377"
"44694","268.12800","22.34419","0.05506"
"44750","268.46400","22.37217","0.05525"
"44806","268.80000","22.40021","0.05662"
"44862","269.13600","22.42825","0.05744"
"44918","269.47200","22.45617","0.05698"
"44974","269.80800","22.48415","-0.00579"
"45030","270.14400","22.51213","-0.00227"
"45086","270.48000","22.54012","-0.00089"
"45142","270.81600","22.56816","-0.00036"
"45198","271.15200","22.59620","-0.00028"
"45254","271.48800","22.62424","-0.00008"
"45310","271.82400","22.65222","-0.00075"
"45366","272.16000","22.68008","0.00005"
"45422","272.49600","22.70824","0.00017"
"45478","272.83200","22.73617","-0.00068"
"45534","273.16800","22.76421","0.00045"
"45590","273.50400","22.79225","0.00025"
"45646","273.84000","22.82017","0.00003"
"45702","274.17600","22.84815","-0.00031"
"45758","274.51200","22.87619","0.00006"
"45814","274.84800","22.90417","0.00035"
"45870","275.18400","22.93216","0.00012"
"45926","275.52000","22.96020","0.00069"
"45982","275.85600","22.98818","-0.00037"
"46038","276.19200","23.01616","0.00067"
"46094","276.52800","23.04420","0.00029"
"46150","276.86400","23.07218","0.00073"
"46206","277.20000","23.10016","0.00082"
"46262","277.53600","23.12815","0.00101"
"46318","277.87200","23.15619","0.00056"
"46374","278.20800","23.18417","0.00049"
"46430","278.54400","23.21215","0.00024"
"46486","278.88000","23.24019","0.00098"
"46542","279.21600","23.26818","0.00099"
"46598","279.55200","23.29622","0.00070"
"46654","279.88800","23.32420","0.00082"
"46710","280.22400","23.35212","0.00085"
"46766","280.56000","23.38022","0.00097"
"46822","280.89600","23.40820","0.00094"
"46878","281.23200","23.43618","0.00038"
"46934","281.56800","23.46422","0.00051"
"46990","281.90400","23.49215","0.00065"
"47046","282.24000","23.52019","0.00080"
"47102","282.57600","23.54817","0.00068"
"47158","282.91200","23.57609","0.00072"
"47214","283.24800","23.60425","0.00074"
"47270","283.58400","23.63217","0.00135"
"47326","283.92000","23.66015","0.00064"
"47382","284.25600","23.68819","0.00093"
"47438","284.59200","23.71618","0.00109"
"47494","284.92800","23.74416","0.00149"
"47550","285.26400","23.77226","0.00090"
"47606","285.60000","23.80018","0.00110"
"47662","285.93600","23.82816","0.00043"
"47718","286.27200","23.85620","0.00075"
"47774","286.60800","23.88418","0.00084"
"47830","286.94400","23.91216","0.00107"
"47886","287.28000","23.94015","0.00063"
"47942","287.61600","23.96819","0.00080"
"47998","287.95200","23.99617","0.00125"
"48054","288.28800","24.02415","0.00148"
"48110","288.62400","24.05219","0.00162"
"48166","288.96000","24.08017","0.00128"
"48222","289.29600","24.10816","0.00140"
"48278","289.63200","24.13620","0.00154"
"48334","289.96800","24.16412","0.00126"
"48390","290.30400","24.19216","0.00175"
"48446","290.64000","24.22026","0.00162"
"48502","290.97600","24.24818","0.00108"
"48558","291.31200","24.27622","0.00136"
"48614","291.64800","24.30415","0.00137"
"48670","291.98400","24.33213","0.00207"
"48726","292.32000","24.36023","0.00127"
"48782","292.65600","24.38815","0.00168"
"48838","292.99200","24.41619","0.00156"
"48894","293.32800","24.44423","0.00145"
"48950","293.66400","24.47216","0.00170"
"49006","294.00000","24.50019","0.00197"
"49062","294.33600","24.52818","0.00162"
"49118","294.67200","24.55616","0.00195"
"49174","295.00800","24.58420","0.00192"
"49230","295.34400","24.61212","0.00112"
"49286","295.68000","24.64017","0.00155"
"49342","296.01600","24.66820","0.00151"
"49398","296.35200","24.69619","0.00152"
"49454","296.68800","24.72423","0.00162"
"49510","297.02400","24.75221","0.00174"
"49566","297.36000","24.78019","0.00145"
"49622","297.69600","24.80823","0.00207"
"49678","298.03200","24.83609","0.00164"
"49734","298.36800","24.86425","0.00207"
"49790","298.70400","24.89224","0.00181"
"49846","299.04000","24.92016","0.00203"
"49902","299.37600","24.94820","0.00183"
"49958","299.71200","24.97612","0.00146"
"50014","300.04800","25.00416","0.00159"
"50070","300.38400","25.03220","0.00154"
"50126","300.72000","25.06013","0.00225"
"50182","301.05600","25.08823","0.00146"
"50238","301.39200","25.11621","0.00139"
"50294","301.72800","25.14419","0.00185"
"50350","302.06400","25.17223","0.00198"
"50406","302.40000","25.20015","0.00206"
"50462","302.73600","25.22813","0.00136"
"50518","303.07200","25.25617","0.00198"
"50574","303.40800","25.28410","0.00229"
"50630","303.74400","25.31220","0.00179"
"50686","304.08000","25.34024","0.00191"
"50742","304.41600","25.36816","0.00194"
"50798","304.75200","25.39620","0.00136"
"50854","305.08800","25.42418","0.00231"
"50910","305.42400","25.45217","0.00201"
"50966","305.76000","25.48021","0.00200"
"51022","306.09600","25.50819","0.00195"
"51078","306.43200","25.53617","0.00155"
"51134","306.76800","25.56421","0.00130"
"51190","307.10400","25.59213","0.00148"
"51246","307.44000","25.62017","0.00080"
"51302","307.77600","25.64816","0.00046"
"51358","308.11200","25.67620","0.00094"
"51414","308.44800","25.70418","0.00024"
"51470","308.78400","25.73210","-0.00037"
"51526","309.12000","25.76020","-0.00091"
"51582","309.45600","25.78818","-0.00063"
"51638","309.79200","25.81616","0.00010"
"51694","310.12800","25.84421","-0.00037"
"51750","310.46400","25.87213","-0.00018"
"51806","310.80000","25.90011","-0.00056"
"51862","311.13600","25.92821","-0.00025"
"51918","311.47200","25.95613","-0.00022"
"51974","311.80800","25.98423","-0.00018"
"52030","312.14400","26.01228","-0.00041"
"52086","312.48000","26.04020","-0.00027"
"52142","312.81600","26.06817","-0.00002"
"52198","313.15200","26.09616","-0.00012"
"52254","313.48800","26.12414","-0.00020"
"52310","313.82400","26.15224","-0.00011"
"52366","314.16000","26.18010","0.00042"
"52422","314.49600","26.20827","0.00023"
"52478","314.83200","26.23619","0.00022"
"52534","315.16800","26.26411","0.00043"
"52590","315.50400","26.29215","-0.00024"
"52646","315.84000","26.32019","0.00011"
"52702","316.17600","26.34817","0.00048"
"52758","316.51200","26.37621","0.00044"
"52814","316.84800","26.40419","0.00016"
"52870","317.18400","26.43217","0.00028"
"52926","317.52000","26.46016","0.00022"
"52982","317.85600","26.48814","0.00047"
"53038","318.19200","26.51624","0.00051"
"53094","318.52800","26.54416","0.00035"
"53150","318.86400","26.57220","0.00063"
"53206","319.20000","26.60018","0.00017"
"53262","319.53600","26.62811","-0.00007"
"53318","319.87200","26.65621","0.00052"
"53374","320.20800","26.68419","0.00042"
"53430","320.54400","26.71217","0.00103"
"53486","320.88000","26.74021","0.00104"
"53542","321.21600","26.76813","0.00094"
"53598","321.55200","26.79612","0.00104"
"53654","321.88800","26.82421","0.00115"
"53710","322.22400","26.85220","0.00061"
"53766","322.56000","26.88018","0.00077"
"53822","322.89600","26.90822","0.00126"
"53878","323.23200","26.93614","0.00090"
"53934","323.56800","26.96418","0.00082"
"53990","323.90400","26.99216","0.00111"
"54046","324.24000","27.02015","0.00110"
"54102","324.57600","27.04825","0.00094"
"54158","324.91200","27.07617","0.00106"
"54214","325.24800","27.10421","0.00054"
"54270","325.58400","27.13219","0.00092"
"54326","325.92000","27.16017","0.00083"
"54382","326.25600","27.18821","0.00113"
"54438","326.59200","27.21620","0.00111"
"54494","326.92800","27.24418","0.00119"
"54550","327.26400","27.27216","0.00081"
"54606","327.60000","27.30014","0.00112"
"54662","327.93600","27.32818","0.00126"
"54718","328.27200","27.35616","0.00111"
"54774","328.60800","27.38414","0.00111"
"54830","328.94400","27.41219","0.00177"
"54886","329.28000","27.44017","0.00117"
"54942","329.61600","27.46821","0.00130"
"54998","329.95200","27.49619","0.00117"
"55054","330.28800","27.52411","0.00081"
"55110","330.62400","27.55221","0.00161"
"55166","330.96000","27.58020","0.00105"
"55222","331.29600","27.60812","0.00163"
"55278","331.63200","27.63622","0.00124"
"55334","331.96800","27.66414","0.00168"
"55390","332.30400","27.69218","0.00139"
"55446","332.64000","27.72022","0.00182"
"55502","332.97600","27.74814","0.00137"
"55558","333.31200","27.77618","0.00108"
"55614","333.64800","27.80423","0.00122"
"55670","333.98400","27.83215","0.00115"
"55726","334.32000","27.86019","0.00170"
"55782","334.65600","27.88817","0.00147"
"55838","334.99200","27.91615","0.00131"
"55894","335.32800","27.94419","0.00076"
"55950","335.66400","27.97218","0.00141"
"56006","336.00000","28.00022","0.00116"
"56062","336.33600","28.02814","0.00129"
"56118","336.67200","28.05618","0.00136"
"56174","337.00800","28.08416","0.00162"
"56230","337.34400","28.11214","0.00102"
"56286","337.68000","28.14018","0.00109"
"56342","338.01600","28.16822","0.00132"
"56398","338.35200","28.19614","0.00121"
"56454","338.68800","28.22419","0.00087"
"56510","339.02400","28.25223","0.00097"
"56566","339.36000","28.28015","0.00115"
"56622","339.69600","28.30819","0.00122"
"56678","340.03200","28.33617","0.00125"
"56734","340.36800","28.36421","0.00123"
"56790","340.70400","28.39220","0.00113"
"56846","341.04000","28.42006","0.00127"
"56902","341.37600","28.44822","0.00115"
"56958","341.71200","28.47614","0.00086"
"57014","342.04800","28.50418","0.00133"
"57070","342.38400","28.53222","0.00124"
"57126","342.72000","28.56014","0.00151"
"57182","343.05600","28.58813","0.00169"
"57238","343.39200","28.61623","0.00168"
"57294","343.72800","28.64415","0.00176"
"57350","344.06400","28.67219","0.00148"
"57406","344.40000","28.70023","0.00161"
"57462","344.73600","28.72815","0.00103"
"57518","345.07200","28.75613","0.00159"
"57574","345.40800","28.78418","0.00124"
"57630","345.74400","28.81222","0.00172"
"57686","346.08000","28.84020","0.00104"
"57742","346.41600","28.86818","0.00026"
"57798","346.75200","28.89622","0.00031"
"57854","347.08800","28.92414","-0.00007"
"57910","347.42400","28.95218","-0.00017"
"57966","347.76000","28.98017","0.00010"
"58022","348.09600","29.00815","0.00002"
"58078","348.43200","29.03625","0.00001"
"58134","348.76800","29.06417","0.00018"
"58190","349.10400","29.09209","0.00035"
"58246","349.44000","29.12019","0.00052"
"58302","349.77600","29.14818","0.00057"
"58358","350.11200","29.17616","0.00048"
"58414","350.44800","29.20420","0.00067"
"58470","350.78400","29.23218","0.00096"
"58526","351.12000","29.26016","0.00051"
"58582","351.45600","29.28826","0.00058"
"58638","351.79200","29.31613","0.00086"
"58694","352.12800","29.34422","0.00048"
"58750","352.46400","29.37221","0.00028"
"58806","352.80000","29.40013","0.00080"
"58862","353.13600","29.42823","0.00075"
"58918","353.47200","29.45615","0.00000"
"58974","353.80800","29.48413","0.00025"
"59030","354.14400","29.51223","-0.00004"
"59086","354.48000","29.54016","0.00029"
"59142","354.81600","29.56820","0.00069"
"59198","355.15200","29.59624","0.00039"
"59254","355.48800","29.62422","0.00093"
"59310","355.82400","29.65214","0.00042"
"59366","356.16000","29.68018","0.00044"
"59422","356.49600","29.70817","0.00104"
"59478","356.83200","29.73615","0.00024"
"59534","357.16800","29.76419","0.00068"
"59590","357.50400","29.79217","0.00013"
"59646","357.84000","29.82015","0.00002"
"59702","358.17600","29.84813","0.00019"
"59758","358.51200","29.87617","0.00066"
"59814","358.84800","29.90415","0.00034"
"59870","359.18400","29.93220","0.00035"
"59926","359.52000","29.96024","0.00105"
"59982","359.85600","29.98816","0.00059"
"60038","360.19200","30.01620","0.00072"
"60094","360.52800","30.04418","0.00100"
"60150","360.86400","30.07216","0.00086"
"60206","361.20000","30.10026","0.00099"
"60262","361.53600","30.12813","0.00082"
"60318","361.87200","30.15623","0.00073"
"60374","362.20800","30.18421","0.00046"
"60430","362.54400","30.21213","0.00050"
"60486","362.88000","30.24023","0.00028"
"60542","363.21600","30.26822","0.00092"
"60598","363.55200","30.29619","0.00054"
"60654","363.88800","30.32418","0.00044"
"60710","364.22400","30.35216","0.00078"
"60766","364.56000","30.38014","0.00048"
"60822","364.89600","30.40818","0.00082"
"60878","365.23200","30.43616","0.00074"
"60934","365.56800","30.46420","0.00091"
"60990","365.90400","30.49218","0.00134"
"61046","366.24000","30.52017","0.00122"
"61102","366.57600","30.54821","0.00059"
"61158","366.91200","30.57613","0.00076"
"61214","367.24800","30.60423","0.00102"
"61270","367.58400","30.63221","0.00111"
"61326","367.92000","30.66013","0.00088"
"61382","368.25600","30.68823","0.00070"
"61438","368.59200","30.71615","0.00071"
"61494","368.92800","30.74420","0.00103"
"61550","369.26400","30.77218","0.00135"
"61606","369.60000","30.80016","0.00132"
"61662","369.93600","30.82820","0.00137"
"61718","370.27200","30.85618","0.00109"
"61774","370.60800","30.88416","0.00139"
"61830","370.94400","30.91227","0.00124"
"61886","371.28000","30.94019","0.00109"
"61942","371.61600","30.96817","0.00090"
"61998","371.95200","30.99621","0.00121"
"62054","372.28800","31.02413","0.00105"
"62110","372.62400","31.05217","0.00110"
"62166","372.96000","31.08022","0.00111"
"62222","373.29600","31.10814","0.00118"
"62278","373.63200","31.13624","0.00101"
"62334","373.96800","31.16422","0.00131"
"62390","374.30400","31.19214","0.00119"
"62446","374.64000","31.22018","0.00140"
"62502","374.97600","31.24816","0.00174"
"62558","375.31200","31.27614","0.00166"
"62614","375.64800","31.30418","0.00197"
"62670","375.98400","31.33216","0.00189"
"62726","376.32000","31.36021","0.00192"
"62782","376.65600","31.38813","0.00200"
"62838","376.99200","31.41623","0.00198"
"62894","377.32800","31.44415","0.00170"
"62950","377.66400","31.47207","0.00165"
"63006","378.00000","31.50023","0.00207"
"63062","378.33600","31.52816","0.00175"
"63118","378.67200","31.55614","0.00231"
"63174","379.00800","31.58418","0.00223"
"63230","379.34400","31.61216","0.00199"
"63286","379.68000","31.64014","0.00193"
"63342","380.01600","31.66818","0.00177"
"63398","380.35200","31.69610","0.00164"
"63454","380.68800","31.72421","0.00226"
"63510","381.02400","31.75219","0.00228"
"63566","381.36000","31.78017","0.00235"
"63622","381.69600","31.80821","0.00240"
"63678","382.03200","31.83619","0.00229"
"63734","382.36800","31.86411","0.00229"
"63790","382.70400","31.89221","0.00252"
"63846","383.04000","31.92014","0.00237"
"63902","383.37600","31.94818","0.00233"
"63958","383.71200","31.97622","0.00270"
"64014","384.04800","32.00414","0.00263"
"64070","384.38400","32.03218","0.00263"
"64126","384.72000","32.06023","0.00261"
"64182","385.05600","32.08820","0.00259"
"64238","385.39200","32.11618","0.00300"
"64294","385.72800","32.14417","0.00237"
"64350","386.06400","32.17221","0.00248"
"64406","386.40000","32.20019","0.00278"
"64462","386.73600","32.22817","0.00269"
"64518","387.07200","32.25621","0.00272"
"64574","387.40800","32.28413","0.00329"
"64630","387.74400","32.31224","0.00302"
"64686","388.08000","32.34016","0.00318"
"64742","388.41600","32.36814","0.00275"
"64798","388.75200","32.39624","0.00189"
"64854","389.08800","32.42422","-0.00056"
"64910","389.42400","32.45214","-0.00097"
"64966","389.76000","32.48024","-0.00087"
"65022","390.09600","32.50816","-0.00061"
"65078","390.43200","32.53615","-0.00048"
"65134","390.76800","32.56419","-0.00085"
"65190","391.10400","32.59217","-0.00081"
"65246","391.44000","32.62021","-0.00126"
"65302","391.77600","32.64819","-0.00091"
"65358","392.11200","32.67612","-0.00052"
"65414","392.44800","32.70422","-0.00094"
"65470","392.78400","32.73220","-0.00078"
"65526","393.12000","32.76018","-0.00086"
"65582","393.45600","32.78822","-0.00121"
"65638","393.79200","32.81614","-0.00107"
"65694","394.12800","32.84418","-0.00115"
"65750","394.46400","32.87217","-0.00113"
"65806","394.80000","32.90015","-0.00099"
"65862","395.13600","32.92819","-0.00208"
"65918","395.47200","32.95617","-0.00193"
"65974","395.80800","32.98421","-0.00196"
"66030","396.14400","33.01219","-0.00245"
"66086","396.48000","33.04012","-0.00142"
"66142","396.81600","33.06821","-0.00212"
"66198","397.15200","33.09620","-0.00203"
"66254","397.48800","33.12418","-0.00139"
"66310","397.82400","33.15216","-0.00234"
"66366","398.16000","33.18014","-0.00180"
"66422","398.49600","33.20818","-0.00227"
"66478","398.83200","33.23623","-0.00173"
"66534","399.16800","33.26414","-0.00171"
"66590","399.50400","33.29219","-0.00213"
"66646","399.84000","33.32017","-0.00181"
"66702","400.17600","33.34815","-0.00190"
"66758","400.51200","33.37619","-0.00185"
"66814","400.84800","33.40411","-0.00172"
"66870","401.18400","33.43216","-0.00188"
"66926","401.52000","33.46025","-0.00196"
"66982","401.85600","33.48812","-0.00138"
"67038","402.19200","33.51622","-0.00171"
"67094","402.52800","33.54420","-0.00180"
"67150","402.86400","33.57218","-0.00178"
"67206","403.20000","33.60016","-0.00173"
"67262","403.53600","33.62820","-0.00147"
"67318","403.87200","33.65619","-0.00165"
"67374","404.20800","33.68423","-0.00188"
"67430","404.54400","33.71215","-0.00147"
"67486","404.88000","33.74019","-0.00173"
"67542","405.21600","33.76817","-0.00213"
"67598","405.55200","33.79615","-0.00186"
"67654","405.88800","33.82420","-0.00169"
"67710","406.22400","33.85218","-0.00140"
"67766","406.56000","33.88021","-0.00156"
"67796","406.73800","33.89499","-0.00179"