File: Trajectories_together/161217Specimen_RawData_6.csv
"","V1","V2","V3"
"1","End date","12/17/2016",""
"2","Specimen label","15CG_21",""
"3","Maximum Load","0.00672","N"
"4","Time","Extension","Load"
"5","(s)","(mm)","(N)"
"6","0.00000","0.00000","-0.00007"
"18","0.07200","0.00203","-0.00024"
"30","0.14400","0.00795","-0.00027"
"42","0.21600","0.01578","-0.00010"
"54","0.28800","0.02332","0.00004"
"66","0.36000","0.03001","-0.00003"
"78","0.43200","0.03623","0.00019"
"90","0.50400","0.04221","0.00028"
"102","0.57600","0.04825","0.00063"
"114","0.64800","0.05423","0.00032"
"126","0.72000","0.06027","0.00057"
"138","0.79200","0.06619","0.00055"
"150","0.86400","0.07223","0.00026"
"162","0.93600","0.07820","0.00044"
"174","1.00800","0.08418","0.00053"
"186","1.08000","0.09010","0.00052"
"198","1.15200","0.09620","0.00062"
"210","1.22400","0.10218","0.00060"
"222","1.29600","0.10822","0.00067"
"234","1.36800","0.11420","0.00086"
"246","1.44000","0.12024","0.00093"
"258","1.51200","0.12610","0.00081"
"270","1.58400","0.13213","0.00089"
"282","1.65600","0.13811","0.00053"
"294","1.72800","0.14415","0.00107"
"306","1.80000","0.15019","0.00068"
"318","1.87200","0.15617","0.00103"
"330","1.94400","0.16221","0.00108"
"342","2.01600","0.16819","0.00076"
"354","2.08800","0.17417","0.00110"
"366","2.16000","0.18015","0.00122"
"378","2.23200","0.18618","0.00106"
"390","2.30400","0.19222","0.00085"
"402","2.37600","0.19820","0.00122"
"414","2.44800","0.20418","0.00132"
"426","2.52000","0.21016","0.00114"
"438","2.59200","0.21620","0.00107"
"450","2.66400","0.22212","0.00118"
"462","2.73600","0.22816","0.00147"
"474","2.80800","0.23420","0.00112"
"486","2.88000","0.24023","0.00118"
"498","2.95200","0.24615","0.00148"
"510","3.02400","0.25219","0.00134"
"522","3.09600","0.25817","0.00139"
"534","3.16800","0.26415","0.00109"
"546","3.24000","0.27013","0.00128"
"558","3.31200","0.27617","0.00136"
"570","3.38400","0.28221","0.00124"
"582","3.45600","0.28819","0.00114"
"594","3.52800","0.29416","0.00138"
"606","3.60000","0.30020","0.00150"
"618","3.67200","0.30612","0.00125"
"630","3.74400","0.31210","0.00169"
"642","3.81600","0.31808","0.00150"
"654","3.88800","0.32418","0.00136"
"666","3.96000","0.33022","0.00161"
"678","4.03200","0.33620","0.00171"
"690","4.10400","0.34218","0.00137"
"702","4.17600","0.34821","0.00180"
"714","4.24800","0.35413","0.00159"
"726","4.32000","0.36011","0.00155"
"738","4.39200","0.36615","0.00154"
"750","4.46400","0.37225","0.00173"
"762","4.53600","0.37823","0.00164"
"774","4.60800","0.38421","0.00171"
"786","4.68000","0.39013","0.00168"
"798","4.75200","0.39617","0.00159"
"810","4.82400","0.40214","0.00151"
"822","4.89600","0.40812","0.00162"
"834","4.96800","0.41410","0.00195"
"846","5.04000","0.42020","0.00180"
"858","5.11200","0.42618","0.00198"
"870","5.18400","0.43222","0.00166"
"882","5.25600","0.43814","0.00186"
"894","5.32800","0.44412","0.00185"
"906","5.40000","0.45010","0.00179"
"918","5.47200","0.45613","0.00190"
"930","5.54400","0.46217","0.00223"
"942","5.61600","0.46815","0.00174"
"954","5.68800","0.47419","0.00194"
"966","5.76000","0.48017","0.00199"
"978","5.83200","0.48615","0.00196"
"990","5.90400","0.49213","0.00165"
"1002","5.97600","0.49817","0.00200"
"1014","6.04800","0.50415","0.00200"
"1026","6.12000","0.51018","0.00188"
"1038","6.19200","0.51616","0.00191"
"1050","6.26400","0.52220","0.00188"
"1062","6.33600","0.52818","0.00199"
"1074","6.40800","0.53416","0.00183"
"1086","6.48000","0.54014","0.00204"
"1098","6.55200","0.54612","0.00193"
"1110","6.62400","0.55216","0.00253"
"1122","6.69600","0.55820","0.00214"
"1134","6.76800","0.56417","0.00195"
"1146","6.84000","0.57015","0.00191"
"1158","6.91200","0.57613","0.00217"
"1170","6.98400","0.58211","0.00217"
"1182","7.05600","0.58815","0.00225"
"1194","7.12800","0.59419","0.00195"
"1206","7.20000","0.60017","0.00193"
"1218","7.27200","0.60621","0.00220"
"1230","7.34400","0.61219","0.00210"
"1242","7.41600","0.61816","0.00223"
"1254","7.48800","0.62414","0.00219"
"1266","7.56000","0.63012","0.00221"
"1278","7.63200","0.63610","0.00207"
"1290","7.70400","0.64220","0.00221"
"1302","7.77600","0.64818","0.00179"
"1314","7.84800","0.65416","0.00216"
"1326","7.92000","0.66014","0.00229"
"1338","7.99200","0.66618","0.00191"
"1350","8.06400","0.67209","0.00254"
"1362","8.13600","0.67807","0.00209"
"1374","8.20800","0.68411","0.00222"
"1386","8.28000","0.69021","0.00212"
"1398","8.35200","0.69613","0.00206"
"1410","8.42400","0.70217","0.00211"
"1422","8.49600","0.70815","0.00226"
"1434","8.56800","0.71413","0.00220"
"1446","8.64000","0.72011","0.00236"
"1458","8.71200","0.72620","0.00230"
"1470","8.78400","0.73218","0.00259"
"1482","8.85600","0.73816","0.00199"
"1494","8.92800","0.74420","0.00244"
"1506","9.00000","0.75018","0.00225"
"1518","9.07200","0.75616","0.00223"
"1530","9.14400","0.76220","0.00232"
"1542","9.21600","0.76818","0.00241"
"1554","9.28800","0.77421","0.00222"
"1566","9.36000","0.78013","0.00254"
"1578","9.43200","0.78617","0.00247"
"1590","9.50400","0.79215","0.00229"
"1602","9.57600","0.79813","0.00249"
"1614","9.64800","0.80411","0.00267"
"1626","9.72000","0.81015","0.00231"
"1638","9.79200","0.81619","0.00260"
"1650","9.86400","0.82217","0.00196"
"1662","9.93600","0.82820","0.00243"
"1674","10.00800","0.83418","0.00251"
"1686","10.08000","0.84016","0.00268"
"1698","10.15200","0.84620","0.00285"
"1710","10.22400","0.85218","0.00246"
"1722","10.29600","0.85816","0.00245"
"1734","10.36800","0.86420","0.00235"
"1746","10.44000","0.87024","0.00266"
"1758","10.51200","0.87622","0.00255"
"1770","10.58400","0.88219","0.00252"
"1782","10.65600","0.88817","0.00277"
"1794","10.72800","0.89415","0.00249"
"1806","10.80000","0.90013","0.00260"
"1818","10.87200","0.90617","0.00225"
"1830","10.94400","0.91221","0.00297"
"1842","11.01600","0.91819","0.00229"
"1854","11.08800","0.92423","0.00280"
"1866","11.16000","0.93021","0.00268"
"1878","11.23200","0.93612","0.00263"
"1890","11.30400","0.94210","0.00281"
"1902","11.37600","0.94820","0.00268"
"1914","11.44800","0.95418","0.00264"
"1926","11.52000","0.96016","0.00273"
"1938","11.59200","0.96620","0.00268"
"1950","11.66400","0.97218","0.00273"
"1962","11.73600","0.97816","0.00269"
"1974","11.80800","0.98414","0.00242"
"1986","11.88000","0.99017","0.00280"
"1998","11.95200","0.99615","0.00257"
"2010","12.02400","1.00225","0.00266"
"2022","12.09600","1.00817","0.00248"
"2034","12.16800","1.01421","0.00258"
"2046","12.24000","1.02019","0.00261"
"2058","12.31200","1.02617","0.00240"
"2070","12.38400","1.03209","0.00256"
"2082","12.45600","1.03819","0.00273"
"2094","12.52800","1.04422","0.00273"
"2106","12.60000","1.05020","0.00277"
"2118","12.67200","1.05618","0.00260"
"2130","12.74400","1.06222","0.00282"
"2142","12.81600","1.06814","0.00278"
"2154","12.88800","1.07412","0.00274"
"2166","12.96000","1.08010","0.00290"
"2178","13.03200","1.08620","0.00287"
"2190","13.10400","1.09224","0.00283"
"2202","13.17600","1.09821","0.00294"
"2214","13.24800","1.10419","0.00284"
"2226","13.32000","1.11017","0.00281"
"2238","13.39200","1.11615","0.00296"
"2250","13.46400","1.12213","0.00286"
"2262","13.53600","1.12817","0.00280"
"2274","13.60800","1.13415","0.00258"
"2286","13.68000","1.14025","0.00271"
"2298","13.75200","1.14617","0.00278"
"2310","13.82400","1.15220","0.00298"
"2322","13.89600","1.15812","0.00281"
"2334","13.96800","1.16416","0.00282"
"2346","14.04000","1.17014","0.00260"
"2358","14.11200","1.17612","0.00312"
"2370","14.18400","1.18216","0.00294"
"2382","14.25600","1.18820","0.00282"
"2394","14.32800","1.19424","0.00271"
"2406","14.40000","1.20016","0.00281"
"2418","14.47200","1.20613","0.00276"
"2430","14.54400","1.21211","0.00295"
"2442","14.61600","1.21821","0.00308"
"2454","14.68800","1.22419","0.00275"
"2466","14.76000","1.23023","0.00292"
"2478","14.83200","1.23621","0.00341"
"2490","14.90400","1.24219","0.00307"
"2502","14.97600","1.24817","0.00281"
"2514","15.04800","1.25415","0.00318"
"2526","15.12000","1.26012","0.00274"
"2538","15.19200","1.26616","0.00294"
"2550","15.26400","1.27220","0.00298"
"2562","15.33600","1.27818","0.00331"
"2574","15.40800","1.28422","0.00316"
"2586","15.48000","1.29026","0.00324"
"2598","15.55200","1.29618","0.00299"
"2610","15.62400","1.30216","0.00314"
"2622","15.69600","1.30814","0.00292"
"2634","15.76800","1.31417","0.00322"
"2646","15.84000","1.32015","0.00308"
"2658","15.91200","1.32619","0.00313"
"2670","15.98400","1.33217","0.00336"
"2682","16.05600","1.33815","0.00339"
"2694","16.12800","1.34413","0.00315"
"2706","16.20000","1.35017","0.00334"
"2718","16.27200","1.35615","0.00313"
"2730","16.34400","1.36224","0.00322"
"2742","16.41600","1.36816","0.00350"
"2754","16.48800","1.37420","0.00311"
"2766","16.56000","1.38018","0.00291"
"2778","16.63200","1.38622","0.00304"
"2790","16.70400","1.39214","0.00316"
"2802","16.77600","1.39818","0.00316"
"2814","16.84800","1.40416","0.00296"
"2826","16.92000","1.41020","0.00318"
"2838","16.99200","1.41617","0.00354"
"2850","17.06400","1.42221","0.00310"
"2862","17.13600","1.42813","0.00283"
"2874","17.20800","1.43417","0.00329"
"2886","17.28000","1.44015","0.00323"
"2898","17.35200","1.44619","0.00319"
"2910","17.42400","1.45223","0.00334"
"2922","17.49600","1.45821","0.00291"
"2934","17.56800","1.46419","0.00310"
"2946","17.64000","1.47016","0.00325"
"2958","17.71200","1.47614","0.00342"
"2970","17.78400","1.48212","0.00326"
"2982","17.85600","1.48816","0.00332"
"2994","17.92800","1.49420","0.00328"
"3006","18.00000","1.50018","0.00305"
"3018","18.07200","1.50616","0.00316"
"3030","18.14400","1.51214","0.00322"
"3042","18.21600","1.51818","0.00343"
"3054","18.28800","1.52409","0.00329"
"3066","18.36000","1.53019","0.00339"
"3078","18.43200","1.53617","0.00334"
"3090","18.50400","1.54221","0.00322"
"3102","18.57600","1.54819","0.00317"
"3114","18.64800","1.55417","0.00373"
"3126","18.72000","1.56015","0.00303"
"3138","18.79200","1.56613","0.00337"
"3150","18.86400","1.57211","0.00348"
"3162","18.93600","1.57814","0.00334"
"3174","19.00800","1.58418","0.00350"
"3186","19.08000","1.59016","0.00336"
"3198","19.15200","1.59620","0.00334"
"3210","19.22400","1.60218","0.00321"
"3222","19.29600","1.60816","0.00368"
"3234","19.36800","1.61414","0.00307"
"3246","19.44000","1.62018","0.00363"
"3258","19.51200","1.62622","0.00349"
"3270","19.58400","1.63219","0.00331"
"3282","19.65600","1.63817","0.00357"
"3294","19.72800","1.64415","0.00331"
"3306","19.80000","1.65019","0.00312"
"3318","19.87200","1.65611","0.00362"
"3330","19.94400","1.66215","0.00332"
"3342","20.01600","1.66813","0.00348"
"3354","20.08800","1.67423","0.00358"
"3366","20.16000","1.68015","0.00373"
"3378","20.23200","1.68618","0.00362"
"3390","20.30400","1.69216","0.00368"
"3402","20.37600","1.69814","0.00333"
"3414","20.44800","1.70406","0.00368"
"3426","20.52000","1.71016","0.00337"
"3438","20.59200","1.71620","0.00362"
"3450","20.66400","1.72224","0.00357"
"3462","20.73600","1.72816","0.00337"
"3474","20.80800","1.73420","0.00353"
"3486","20.88000","1.74011","0.00343"
"3498","20.95200","1.74609","0.00338"
"3510","21.02400","1.75213","0.00362"
"3522","21.09600","1.75817","0.00357"
"3534","21.16800","1.76421","0.00376"
"3546","21.24000","1.77019","0.00356"
"3558","21.31200","1.77623","0.00327"
"3570","21.38400","1.78221","0.00368"
"3582","21.45600","1.78819","0.00380"
"3594","21.52800","1.79410","0.00376"
"3606","21.60000","1.80014","0.00362"
"3618","21.67200","1.80618","0.00383"
"3630","21.74400","1.81222","0.00346"
"3642","21.81600","1.81820","0.00375"
"3654","21.88800","1.82418","0.00406"
"3666","21.96000","1.83016","0.00371"
"3678","22.03200","1.83614","0.00370"
"3690","22.10400","1.84218","0.00363"
"3702","22.17600","1.84809","0.00365"
"3714","22.24800","1.85419","0.00374"
"3726","22.32000","1.86017","0.00335"
"3738","22.39200","1.86615","0.00349"
"3750","22.46400","1.87213","0.00382"
"3762","22.53600","1.87811","0.00347"
"3774","22.60800","1.88409","0.00355"
"3786","22.68000","1.89013","0.00388"
"3798","22.75200","1.89611","0.00401"
"3810","22.82400","1.90214","0.00402"
"3822","22.89600","1.90818","0.00368"
"3834","22.96800","1.91416","0.00383"
"3846","23.04000","1.92014","0.00368"
"3858","23.11200","1.92612","0.00335"
"3870","23.18400","1.93210","0.00394"
"3882","23.25600","1.93820","0.00365"
"3894","23.32800","1.94418","0.00429"
"3906","23.40000","1.95022","0.00340"
"3918","23.47200","1.95619","0.00408"
"3930","23.54400","1.96223","0.00361"
"3942","23.61600","1.96815","0.00387"
"3954","23.68800","1.97419","0.00384"
"3966","23.76000","1.98011","0.00412"
"3978","23.83200","1.98621","0.00393"
"3990","23.90400","1.99213","0.00382"
"4002","23.97600","1.99823","0.00381"
"4014","24.04800","2.00420","0.00378"
"4026","24.12000","2.01018","0.00392"
"4038","24.19200","2.01616","0.00380"
"4050","24.26400","2.02214","0.00380"
"4062","24.33600","2.02812","0.00362"
"4074","24.40800","2.03422","0.00397"
"4086","24.48000","2.04020","0.00372"
"4098","24.55200","2.04624","0.00403"
"4110","24.62400","2.05216","0.00375"
"4122","24.69600","2.05814","0.00385"
"4134","24.76800","2.06411","0.00395"
"4146","24.84000","2.07021","0.00387"
"4158","24.91200","2.07619","0.00368"
"4170","24.98400","2.08223","0.00430"
"4182","25.05600","2.08821","0.00358"
"4194","25.12800","2.09419","0.00361"
"4206","25.20000","2.10017","0.00404"
"4218","25.27200","2.10615","0.00370"
"4230","25.34400","2.11213","0.00393"
"4242","25.41600","2.11816","0.00400"
"4254","25.48800","2.12420","0.00405"
"4266","25.56000","2.13018","0.00407"
"4278","25.63200","2.13616","0.00386"
"4290","25.70400","2.14220","0.00392"
"4302","25.77600","2.14818","0.00412"
"4314","25.84800","2.15416","0.00396"
"4326","25.92000","2.16014","0.00385"
"4338","25.99200","2.16617","0.00403"
"4350","26.06400","2.17215","0.00393"
"4362","26.13600","2.17819","0.00418"
"4374","26.20800","2.18417","0.00408"
"4386","26.28000","2.19015","0.00399"
"4398","26.35200","2.19613","0.00407"
"4410","26.42400","2.20217","0.00398"
"4422","26.49600","2.20815","0.00408"
"4434","26.56800","2.21419","0.00394"
"4446","26.64000","2.22016","0.00383"
"4458","26.71200","2.22614","0.00448"
"4470","26.78400","2.23212","0.00387"
"4482","26.85600","2.23810","0.00408"
"4494","26.92800","2.24408","0.00395"
"4506","27.00000","2.25012","0.00413"
"4518","27.07200","2.25616","0.00393"
"4530","27.14400","2.26214","0.00396"
"4542","27.21600","2.26812","0.00412"
"4554","27.28800","2.27409","0.00402"
"4566","27.36000","2.28013","0.00401"
"4578","27.43200","2.28611","0.00423"
"4590","27.50400","2.29215","0.00441"
"4602","27.57600","2.29813","0.00391"
"4614","27.64800","2.30417","0.00378"
"4626","27.72000","2.31015","0.00423"
"4638","27.79200","2.31619","0.00422"
"4650","27.86400","2.32211","0.00406"
"4662","27.93600","2.32808","0.00422"
"4674","28.00800","2.33418","0.00434"
"4686","28.08000","2.34016","0.00413"
"4698","28.15200","2.34620","0.00441"
"4710","28.22400","2.35218","0.00433"
"4722","28.29600","2.35822","0.00436"
"4734","28.36800","2.36420","0.00431"
"4746","28.44000","2.37012","0.00401"
"4758","28.51200","2.37610","0.00416"
"4770","28.58400","2.38213","0.00410"
"4782","28.65600","2.38817","0.00459"
"4794","28.72800","2.39415","0.00413"
"4806","28.80000","2.40019","0.00409"
"4818","28.87200","2.40617","0.00464"
"4830","28.94400","2.41215","0.00420"
"4842","29.01600","2.41813","0.00451"
"4854","29.08800","2.42411","0.00448"
"4866","29.16000","2.43015","0.00414"
"4878","29.23200","2.43618","0.00434"
"4890","29.30400","2.44216","0.00431"
"4902","29.37600","2.44820","0.00445"
"4914","29.44800","2.45418","0.00446"
"4926","29.52000","2.46016","0.00455"
"4938","29.59200","2.46614","0.00414"
"4950","29.66400","2.47218","0.00432"
"4962","29.73600","2.47816","0.00481"
"4974","29.80800","2.48420","0.00473"
"4986","29.88000","2.49023","0.00427"
"4998","29.95200","2.49621","0.00436"
"5010","30.02400","2.50219","0.00436"
"5022","30.09600","2.50811","0.00427"
"5034","30.16800","2.51415","0.00422"
"5046","30.24000","2.52019","0.00454"
"5058","30.31200","2.52623","0.00431"
"5070","30.38400","2.53221","0.00436"
"5082","30.45600","2.53819","0.00472"
"5094","30.52800","2.54416","0.00442"
"5106","30.60000","2.55014","0.00448"
"5118","30.67200","2.55612","0.00473"
"5130","30.74400","2.56216","0.00474"
"5142","30.81600","2.56814","0.00448"
"5154","30.88800","2.57418","0.00446"
"5166","30.96000","2.58016","0.00467"
"5178","31.03200","2.58620","0.00456"
"5190","31.10400","2.59218","0.00480"
"5202","31.17600","2.59809","0.00438"
"5214","31.24800","2.60413","0.00458"
"5226","31.32000","2.61017","0.00469"
"5238","31.39200","2.61621","0.00493"
"5250","31.46400","2.62219","0.00432"
"5262","31.53600","2.62823","0.00433"
"5274","31.60800","2.63415","0.00456"
"5286","31.68000","2.64013","0.00488"
"5298","31.75200","2.64611","0.00439"
"5310","31.82400","2.65214","0.00446"
"5322","31.89600","2.65818","0.00471"
"5334","31.96800","2.66422","0.00475"
"5346","32.04000","2.67020","0.00455"
"5358","32.11200","2.67618","0.00487"
"5370","32.18400","2.68216","0.00487"
"5382","32.25600","2.68814","0.00438"
"5394","32.32800","2.69412","0.00494"
"5406","32.40000","2.70016","0.00466"
"5418","32.47200","2.70619","0.00503"
"5430","32.54400","2.71223","0.00465"
"5442","32.61600","2.71827","0.00476"
"5454","32.68800","2.72419","0.00473"
"5466","32.76000","2.73011","0.00508"
"5478","32.83200","2.73615","0.00420"
"5490","32.90400","2.74213","0.00504"
"5502","32.97600","2.74817","0.00463"
"5514","33.04800","2.75414","0.00451"
"5526","33.12000","2.76018","0.00464"
"5538","33.19200","2.76616","0.00473"
"5550","33.26400","2.77214","0.00477"
"5562","33.33600","2.77812","0.00472"
"5574","33.40800","2.78416","0.00484"
"5586","33.48000","2.79020","0.00515"
"5598","33.55200","2.79624","0.00478"
"5610","33.62400","2.80216","0.00504"
"5622","33.69600","2.80819","0.00470"
"5634","33.76800","2.81417","0.00508"
"5646","33.84000","2.82015","0.00480"
"5658","33.91200","2.82607","0.00523"
"5670","33.98400","2.83211","0.00502"
"5682","34.05600","2.83821","0.00479"
"5694","34.12800","2.84419","0.00501"
"5706","34.20000","2.85023","0.00492"
"5718","34.27200","2.85615","0.00528"
"5730","34.34400","2.86218","0.00459"
"5742","34.41600","2.86816","0.00480"
"5754","34.48800","2.87414","0.00496"
"5766","34.56000","2.88018","0.00516"
"5778","34.63200","2.88622","0.00474"
"5790","34.70400","2.89220","0.00490"
"5802","34.77600","2.89824","0.00480"
"5814","34.84800","2.90422","0.00472"
"5826","34.92000","2.91014","0.00511"
"5838","34.99200","2.91612","0.00503"
"5850","35.06400","2.92215","0.00505"
"5862","35.13600","2.92819","0.00474"
"5874","35.20800","2.93417","0.00508"
"5886","35.28000","2.94021","0.00537"
"5898","35.35200","2.94613","0.00494"
"5910","35.42400","2.95217","0.00478"
"5922","35.49600","2.95815","0.00491"
"5934","35.56800","2.96419","0.00498"
"5946","35.64000","2.97016","0.00490"
"5958","35.71200","2.97620","0.00503"
"5970","35.78400","2.98218","0.00492"
"5982","35.85600","2.98822","0.00507"
"5994","35.92800","2.99414","0.00470"
"6006","36.00000","3.00018","0.00516"
"6018","36.07200","3.00610","0.00506"
"6030","36.14400","3.01220","0.00511"
"6042","36.21600","3.01818","0.00533"
"6054","36.28800","3.02421","0.00499"
"6066","36.36000","3.03019","0.00505"
"6078","36.43200","3.03623","0.00470"
"6090","36.50400","3.04215","0.00475"
"6102","36.57600","3.04819","0.00532"
"6114","36.64800","3.05411","0.00523"
"6126","36.72000","3.06021","0.00517"
"6138","36.79200","3.06619","0.00496"
"6150","36.86400","3.07217","0.00502"
"6162","36.93600","3.07820","0.00520"
"6174","37.00800","3.08424","0.00536"
"6186","37.08000","3.09016","0.00480"
"6198","37.15200","3.09614","0.00498"
"6210","37.22400","3.10218","0.00530"
"6222","37.29600","3.10822","0.00520"
"6234","37.36800","3.11414","0.00520"
"6246","37.44000","3.12024","0.00521"
"6258","37.51200","3.12616","0.00547"
"6270","37.58400","3.13219","0.00515"
"6282","37.65600","3.13811","0.00546"
"6294","37.72800","3.14415","0.00522"
"6306","37.80000","3.15019","0.00545"
"6318","37.87200","3.15623","0.00515"
"6330","37.94400","3.16221","0.00558"
"6342","38.01600","3.16819","0.00500"
"6354","38.08800","3.17417","0.00547"
"6366","38.16000","3.18015","0.00527"
"6378","38.23200","3.18612","0.00523"
"6390","38.30400","3.19216","0.00560"
"6402","38.37600","3.19820","0.00565"
"6414","38.44800","3.20418","0.00520"
"6426","38.52000","3.21022","0.00533"
"6438","38.59200","3.21620","0.00517"
"6450","38.66400","3.22218","0.00547"
"6462","38.73600","3.22816","0.00529"
"6474","38.80800","3.23414","0.00561"
"6486","38.88000","3.24023","0.00588"
"6498","38.95200","3.24621","0.00585"
"6510","39.02400","3.25225","0.00546"
"6522","39.09600","3.25817","0.00566"
"6534","39.16800","3.26421","0.00515"
"6546","39.24000","3.27013","0.00527"
"6558","39.31200","3.27617","0.00550"
"6570","39.38400","3.28215","0.00578"
"6582","39.45600","3.28819","0.00535"
"6594","39.52800","3.29416","0.00518"
"6606","39.60000","3.30020","0.00558"
"6618","39.67200","3.30618","0.00518"
"6630","39.74400","3.31216","0.00541"
"6642","39.81600","3.31814","0.00566"
"6654","39.88800","3.32418","0.00500"
"6666","39.96000","3.33010","0.00548"
"6678","40.03200","3.33620","0.00567"
"6690","40.10400","3.34218","0.00551"
"6702","40.17600","3.34821","0.00583"
"6714","40.24800","3.35413","0.00550"
"6726","40.32000","3.36017","0.00548"
"6738","40.39200","3.36609","0.00502"
"6750","40.46400","3.37219","0.00557"
"6762","40.53600","3.37817","0.00575"
"6774","40.60800","3.38421","0.00553"
"6786","40.68000","3.39019","0.00553"
"6798","40.75200","3.39617","0.00547"
"6810","40.82400","3.40214","0.00602"
"6822","40.89600","3.40818","0.00546"
"6834","40.96800","3.41416","0.00545"
"6846","41.04000","3.42020","0.00571"
"6858","41.11200","3.42612","0.00537"
"6870","41.18400","3.43222","0.00550"
"6882","41.25600","3.43820","0.00545"
"6894","41.32800","3.44418","0.00539"
"6906","41.40000","3.45010","0.00577"
"6918","41.47200","3.45619","0.00540"
"6930","41.54400","3.46211","0.00578"
"6942","41.61600","3.46815","0.00535"
"6954","41.68800","3.47413","0.00563"
"6966","41.76000","3.48017","0.00562"
"6978","41.83200","3.48615","0.00568"
"6990","41.90400","3.49213","0.00561"
"7002","41.97600","3.49811","0.00535"
"7014","42.04800","3.50409","0.00584"
"7026","42.12000","3.51018","0.00558"
"7038","42.19200","3.51616","0.00569"
"7050","42.26400","3.52220","0.00537"
"7062","42.33600","3.52818","0.00567"
"7074","42.40800","3.53422","0.00566"
"7086","42.48000","3.54014","0.00582"
"7098","42.55200","3.54612","0.00549"
"7110","42.62400","3.55216","0.00546"
"7122","42.69600","3.55819","0.00559"
"7134","42.76800","3.56417","0.00559"
"7146","42.84000","3.57015","0.00571"
"7158","42.91200","3.57619","0.00544"
"7170","42.98400","3.58217","0.00553"
"7182","43.05600","3.58815","0.00554"
"7194","43.12800","3.59413","0.00602"
"7206","43.20000","3.60017","0.00555"
"7218","43.27200","3.60615","0.00580"
"7230","43.34400","3.61218","0.00582"
"7242","43.41600","3.61816","0.00596"
"7254","43.48800","3.62414","0.00571"
"7266","43.56000","3.63012","0.00607"
"7278","43.63200","3.63616","0.00547"
"7290","43.70400","3.64214","0.00575"
"7302","43.77600","3.64824","0.00584"
"7314","43.84800","3.65416","0.00578"
"7326","43.92000","3.66020","0.00580"
"7338","43.99200","3.66612","0.00567"
"7350","44.06400","3.67215","0.00572"
"7362","44.13600","3.67807","0.00563"
"7374","44.20800","3.68417","0.00563"
"7386","44.28000","3.69015","0.00586"
"7398","44.35200","3.69619","0.00579"
"7410","44.42400","3.70217","0.00603"
"7422","44.49600","3.70821","0.00596"
"7434","44.56800","3.71413","0.00585"
"7446","44.64000","3.72016","0.00586"
"7458","44.71200","3.72608","0.00603"
"7470","44.78400","3.73218","0.00560"
"7482","44.85600","3.73816","0.00589"
"7494","44.92800","3.74420","0.00592"
"7506","45.00000","3.75018","0.00582"
"7518","45.07200","3.75622","0.00599"
"7530","45.14400","3.76214","0.00610"
"7542","45.21600","3.76812","0.00575"
"7554","45.28800","3.77415","0.00595"
"7566","45.36000","3.78019","0.00615"
"7578","45.43200","3.78617","0.00588"
"7590","45.50400","3.79221","0.00570"
"7602","45.57600","3.79819","0.00581"
"7614","45.64800","3.80417","0.00591"
"7626","45.72000","3.81015","0.00582"
"7638","45.79200","3.81613","0.00590"
"7650","45.86400","3.82217","0.00558"
"7662","45.93600","3.82820","0.00615"
"7674","46.00800","3.83418","0.00593"
"7686","46.08000","3.84016","0.00605"
"7698","46.15200","3.84620","0.00609"
"7710","46.22400","3.85212","0.00581"
"7722","46.29600","3.85810","0.00582"
"7734","46.36800","3.86414","0.00607"
"7746","46.44000","3.87018","0.00594"
"7758","46.51200","3.87622","0.00618"
"7770","46.58400","3.88219","0.00572"
"7782","46.65600","3.88817","0.00563"
"7794","46.72800","3.89415","0.00566"
"7806","46.80000","3.90013","0.00571"
"7818","46.87200","3.90611","0.00585"
"7830","46.94400","3.91221","0.00595"
"7842","47.01600","3.91819","0.00619"
"7854","47.08800","3.92417","0.00633"
"7866","47.16000","3.93021","0.00592"
"7878","47.23200","3.93618","0.00570"
"7890","47.30400","3.94216","0.00583"
"7902","47.37600","3.94814","0.00595"
"7914","47.44800","3.95418","0.00593"
"7926","47.52000","3.96022","0.00606"
"7938","47.59200","3.96620","0.00600"
"7950","47.66400","3.97218","0.00596"
"7962","47.73600","3.97816","0.00613"
"7974","47.80800","3.98414","0.00596"
"7986","47.88000","3.99011","0.00589"
"7998","47.95200","3.99609","0.00617"
"8010","48.02400","4.00213","0.00602"
"8022","48.09600","4.00817","0.00598"
"8034","48.16800","4.01421","0.00580"
"8046","48.24000","4.02019","0.00578"
"8058","48.31200","4.02617","0.00615"
"8070","48.38400","4.03209","0.00591"
"8082","48.45600","4.03813","0.00581"
"8094","48.52800","4.04416","0.00581"
"8106","48.60000","4.05020","0.00606"
"8118","48.67200","4.05618","0.00610"
"8130","48.74400","4.06222","0.00613"
"8142","48.81600","4.06820","0.00587"
"8154","48.88800","4.07418","0.00594"
"8166","48.96000","4.08016","0.00604"
"8178","49.03200","4.08614","0.00602"
"8190","49.10400","4.09211","0.00600"
"8202","49.17600","4.09821","0.00603"
"8214","49.24800","4.10419","0.00605"
"8226","49.32000","4.11017","0.00599"
"8238","49.39200","4.11615","0.00606"
"8250","49.46400","4.12213","0.00604"
"8262","49.53600","4.12811","0.00664"
"8274","49.60800","4.13415","0.00588"
"8286","49.68000","4.14019","0.00607"
"8298","49.75200","4.14616","0.00593"
"8310","49.82400","4.15214","0.00583"
"8322","49.89600","4.15812","0.00552"
"8334","49.96800","4.16410","0.00599"
"8346","50.04000","4.17008","0.00578"
"8358","50.11200","4.17612","0.00606"
"8370","50.18400","4.18216","0.00582"
"8382","50.25600","4.18814","0.00607"
"8394","50.32800","4.19418","0.00582"
"8406","50.40000","4.20015","0.00595"
"8418","50.47200","4.20619","0.00647"
"8430","50.54400","4.21211","0.00571"
"8442","50.61600","4.21809","0.00585"
"8454","50.68800","4.22413","0.00600"
"8466","50.76000","4.23023","0.00618"
"8478","50.83200","4.23615","0.00592"
"8490","50.90400","4.24219","0.00623"
"8502","50.97600","4.24817","0.00610"
"8514","51.04800","4.25414","0.00581"
"8526","51.12000","4.26012","0.00607"
"8538","51.19200","4.26616","0.00598"
"8550","51.26400","4.27214","0.00608"
"8562","51.33600","4.27818","0.00618"
"8574","51.40800","4.28416","0.00613"
"8586","51.48000","4.29020","0.00587"
"8598","51.55200","4.29618","0.00617"
"8610","51.62400","4.30216","0.00603"
"8622","51.69600","4.30813","0.00596"
"8634","51.76800","4.31417","0.00624"
"8646","51.84000","4.32015","0.00573"
"8658","51.91200","4.32619","0.00610"
"8670","51.98400","4.33223","0.00603"
"8682","52.05600","4.33821","0.00603"
"8694","52.12800","4.34413","0.00600"
"8706","52.20000","4.35017","0.00646"
"8718","52.27200","4.35615","0.00584"
"8730","52.34400","4.36218","0.00628"
"8742","52.41600","4.36816","0.00610"
"8754","52.48800","4.37420","0.00581"
"8766","52.56000","4.38012","0.00605"
"8778","52.63200","4.38616","0.00599"
"8790","52.70400","4.39208","0.00635"
"8802","52.77600","4.39818","0.00606"
"8814","52.84800","4.40416","0.00607"
"8826","52.92000","4.41020","0.00579"
"8838","52.99200","4.41617","0.00573"
"8850","53.06400","4.42221","0.00600"
"8862","53.13600","4.42813","0.00636"
"8874","53.20800","4.43417","0.00592"
"8886","53.28000","4.44021","0.00606"
"8898","53.35200","4.44619","0.00611"
"8910","53.42400","4.45217","0.00601"
"8922","53.49600","4.45821","0.00616"
"8934","53.56800","4.46419","0.00613"
"8946","53.64000","4.47016","0.00610"
"8958","53.71200","4.47620","0.00608"
"8970","53.78400","4.48218","0.00581"
"8982","53.85600","4.48816","0.00597"
"8994","53.92800","4.49420","0.00581"
"9006","54.00000","4.50024","0.00652"
"9018","54.07200","4.50622","0.00581"
"9030","54.14400","4.51220","0.00597"
"9042","54.21600","4.51818","0.00593"
"9054","54.28800","4.52409","0.00587"
"9066","54.36000","4.53013","0.00587"
"9078","54.43200","4.53617","0.00606"
"9090","54.50400","4.54221","0.00593"
"9102","54.57600","4.54813","0.00592"
"9114","54.64800","4.55417","0.00603"
"9126","54.72000","4.56015","0.00641"
"9138","54.79200","4.56613","0.00596"
"9150","54.86400","4.57211","0.00604"
"9162","54.93600","4.57814","0.00594"
"9174","55.00800","4.58418","0.00598"
"9186","55.08000","4.59016","0.00588"
"9198","55.15200","4.59620","0.00606"
"9210","55.22400","4.60218","0.00608"
"9222","55.29600","4.60816","0.00622"
"9234","55.36800","4.61414","0.00579"
"9246","55.44000","4.62012","0.00632"
"9258","55.51200","4.62616","0.00605"
"9270","55.58400","4.63219","0.00627"
"9282","55.65600","4.63823","0.00608"
"9294","55.72800","4.64421","0.00605"
"9306","55.80000","4.65019","0.00555"
"9318","55.87200","4.65617","0.00604"
"9330","55.94400","4.66215","0.00583"
"9342","56.01600","4.66807","0.00600"
"9354","56.08800","4.67423","0.00613"
"9366","56.16000","4.68021","0.00589"
"9378","56.23200","4.68618","0.00575"
"9390","56.30400","4.69216","0.00589"
"9402","56.37600","4.69820","0.00565"
"9414","56.44800","4.70412","0.00608"
"9426","56.52000","4.71016","0.00605"
"9438","56.59200","4.71608","0.00572"
"9450","56.66400","4.72224","0.00574"
"9462","56.73600","4.72816","0.00572"
"9474","56.80800","4.73425","0.00602"
"9486","56.88000","4.74011","0.00589"
"9498","56.95200","4.74615","0.00599"
"9510","57.02400","4.75213","0.00592"
"9522","57.09600","4.75817","0.00577"
"9534","57.16800","4.76415","0.00589"
"9546","57.24000","4.77025","0.00604"
"9558","57.31200","4.77617","0.00571"
"9570","57.38400","4.78221","0.00575"
"9582","57.45600","4.78819","0.00643"
"9594","57.52800","4.79416","0.00583"
"9606","57.60000","4.80014","0.00553"
"9618","57.67200","4.80618","0.00578"
"9630","57.74400","4.81216","0.00551"
"9642","57.81600","4.81820","0.00536"
"9654","57.88800","4.82418","0.00587"
"9666","57.96000","4.83022","0.00595"
"9678","58.03200","4.83614","0.00575"
"9690","58.10400","4.84218","0.00577"
"9702","58.17600","4.84815","0.00557"
"9714","58.24800","4.85419","0.00602"
"9726","58.32000","4.86017","0.00563"
"9738","58.39200","4.86621","0.00599"
"9750","58.46400","4.87219","0.00546"
"9762","58.53600","4.87817","0.00554"
"9774","58.60800","4.88415","0.00587"
"9786","58.68000","4.89013","0.00571"
"9798","58.75200","4.89611","0.00584"
"9810","58.82400","4.90220","0.00605"
"9822","58.89600","4.90818","0.00582"
"9834","58.96800","4.91416","0.00581"
"9846","59.04000","4.92020","0.00552"
"9858","59.11200","4.92612","0.00612"
"9870","59.18400","4.93210","0.00546"
"9882","59.25600","4.93814","0.00588"
"9894","59.32800","4.94418","0.00571"
"9906","59.40000","4.95021","0.00552"
"9918","59.47200","4.95619","0.00598"
"9930","59.54400","4.96217","0.00548"
"9942","59.61600","4.96815","0.00568"
"9954","59.68800","4.97419","0.00562"
"9966","59.76000","4.98011","0.00575"
"9978","59.83200","4.98621","0.00559"
"9990","59.90400","4.99219","0.00562"
"10002","59.97600","4.99823","0.00604"
"10014","60.04800","5.00414","0.00577"
"10026","60.12000","5.01018","0.00580"
"10038","60.19200","5.01616","0.00545"
"10050","60.26400","5.02220","0.00588"
"10062","60.33600","5.02812","0.00591"
"10074","60.40800","5.03416","0.00576"
"10086","60.48000","5.04014","0.00609"
"10098","60.55200","5.04618","0.00560"
"10110","60.62400","5.05216","0.00580"
"10122","60.69600","5.05819","0.00538"
"10134","60.76800","5.06411","0.00582"
"10146","60.84000","5.07015","0.00564"
"10158","60.91200","5.07613","0.00565"
"10170","60.98400","5.08223","0.00580"
"10182","61.05600","5.08815","0.00592"
"10194","61.12800","5.09419","0.00579"
"10206","61.20000","5.10017","0.00571"
"10218","61.27200","5.10615","0.00616"
"10230","61.34400","5.11212","0.00557"
"10242","61.41600","5.11816","0.00568"
"10254","61.48800","5.12420","0.00582"
"10266","61.56000","5.13018","0.00579"
"10278","61.63200","5.13622","0.00594"
"10290","61.70400","5.14220","0.00584"
"10302","61.77600","5.14812","0.00571"
"10314","61.84800","5.15416","0.00563"
"10326","61.92000","5.16014","0.00549"
"10338","61.99200","5.16617","0.00597"
"10350","62.06400","5.17215","0.00607"
"10362","62.13600","5.17825","0.00574"
"10374","62.20800","5.18417","0.00558"
"10386","62.28000","5.19021","0.00577"
"10398","62.35200","5.19613","0.00591"
"10410","62.42400","5.20211","0.00580"
"10422","62.49600","5.20815","0.00555"
"10434","62.56800","5.21419","0.00580"
"10446","62.64000","5.22016","0.00596"
"10458","62.71200","5.22620","0.00598"
"10470","62.78400","5.23218","0.00579"
"10482","62.85600","5.23816","0.00592"
"10494","62.92800","5.24414","0.00530"
"10506","63.00000","5.25012","0.00594"
"10518","63.07200","5.25622","0.00585"
"10530","63.14400","5.26220","0.00611"
"10542","63.21600","5.26818","0.00571"
"10554","63.28800","5.27421","0.00569"
"10566","63.36000","5.28013","0.00617"
"10578","63.43200","5.28611","0.00583"
"10590","63.50400","5.29209","0.00575"
"10602","63.57600","5.29819","0.00546"
"10614","63.64800","5.30417","0.00602"
"10626","63.72000","5.31021","0.00581"
"10638","63.79200","5.31619","0.00567"
"10650","63.86400","5.32223","0.00595"
"10662","63.93600","5.32808","0.00576"
"10674","64.00800","5.33412","0.00558"
"10686","64.08000","5.34010","0.00604"
"10698","64.15200","5.34620","0.00575"
"10710","64.22400","5.35224","0.00604"
"10722","64.29600","5.35822","0.00587"
"10734","64.36800","5.36414","0.00591"
"10746","64.44000","5.37024","0.00601"
"10758","64.51200","5.37616","0.00576"
"10770","64.58400","5.38213","0.00584"
"10782","64.65600","5.38811","0.00585"
"10794","64.72800","5.39421","0.00604"
"10806","64.80000","5.40019","0.00534"
"10818","64.87200","5.40623","0.00605"
"10830","64.94400","5.41215","0.00572"
"10842","65.01600","5.41813","0.00563"
"10854","65.08800","5.42411","0.00559"
"10866","65.16000","5.43015","0.00588"
"10878","65.23200","5.43612","0.00597"
"10890","65.30400","5.44216","0.00553"
"10902","65.37600","5.44814","0.00571"
"10914","65.44800","5.45418","0.00577"
"10926","65.52000","5.46010","0.00539"
"10938","65.59200","5.46608","0.00605"
"10950","65.66400","5.47212","0.00553"
"10962","65.73600","5.47816","0.00574"
"10974","65.80800","5.48414","0.00544"
"10986","65.88000","5.49017","0.00558"
"10998","65.95200","5.49615","0.00553"
"11010","66.02400","5.50219","0.00547"
"11022","66.09600","5.50811","0.00586"
"11034","66.16800","5.51415","0.00581"
"11046","66.24000","5.52007","0.00619"
"11058","66.31200","5.52617","0.00568"
"11070","66.38400","5.53215","0.00590"
"11082","66.45600","5.53818","0.00546"
"11094","66.52800","5.54416","0.00586"
"11106","66.60000","5.55020","0.00578"
"11118","66.67200","5.55612","0.00599"
"11130","66.74400","5.56210","0.00625"
"11142","66.81600","5.56820","0.00510"
"11154","66.88800","5.57418","0.00495"
"11166","66.96000","5.58016","0.00521"
"11178","67.03200","5.58620","0.00559"
"11190","67.10400","5.59218","0.00517"
"11202","67.17600","5.59815","0.00550"
"11214","67.24800","5.60413","0.00552"
"11226","67.32000","5.61017","0.00520"
"11238","67.39200","5.61615","0.00526"
"11250","67.46400","5.62219","0.00559"
"11262","67.53600","5.62817","0.00562"
"11274","67.60800","5.63421","0.00570"
"11286","67.68000","5.64013","0.00542"
"11298","67.75200","5.64610","0.00515"
"11310","67.82400","5.65208","0.00519"
"11322","67.89600","5.65812","0.00549"
"11334","67.96800","5.66422","0.00583"
"11346","68.04000","5.67020","0.00543"
"11358","68.11200","5.67618","0.00592"
"11370","68.18400","5.68222","0.00553"
"11382","68.25600","5.68820","0.00566"
"11394","68.32800","5.69418","0.00545"
"11406","68.40000","5.70015","0.00563"
"11418","68.47200","5.70619","0.00553"
"11430","68.54400","5.71217","0.00547"
"11442","68.61600","5.71815","0.00587"
"11454","68.68800","5.72413","0.00542"
"11466","68.76000","5.73017","0.00539"
"11478","68.83200","5.73615","0.00547"
"11490","68.90400","5.74219","0.00549"
"11502","68.97600","5.74817","0.00548"
"11514","69.04800","5.75414","0.00550"
"11526","69.12000","5.76018","0.00544"
"11538","69.19200","5.76622","0.00547"
"11550","69.26400","5.77214","0.00573"
"11562","69.33600","5.77812","0.00550"
"11574","69.40800","5.78410","0.00582"
"11586","69.48000","5.79014","0.00583"
"11598","69.55200","5.79618","0.00579"
"11610","69.62400","5.80222","0.00553"
"11622","69.69600","5.80819","0.00530"
"11634","69.76800","5.81411","0.00544"
"11646","69.84000","5.82015","0.00569"
"11658","69.91200","5.82613","0.00548"
"11670","69.98400","5.83211","0.00579"
"11682","70.05600","5.83815","0.00576"
"11694","70.12800","5.84419","0.00566"
"11706","70.20000","5.85017","0.00540"
"11718","70.27200","5.85621","0.00563"
"11730","70.34400","5.86218","0.00540"
"11742","70.41600","5.86816","0.00556"
"11754","70.48800","5.87414","0.00591"
"11766","70.56000","5.88018","0.00552"
"11778","70.63200","5.88616","0.00570"
"11790","70.70400","5.89220","0.00604"
"11802","70.77600","5.89818","0.00572"
"11814","70.84800","5.90416","0.00561"
"11826","70.92000","5.91014","0.00562"
"11838","70.99200","5.91611","0.00567"
"11850","71.06400","5.92215","0.00539"
"11862","71.13600","5.92819","0.00567"
"11874","71.20800","5.93423","0.00590"
"11886","71.28000","5.94021","0.00613"
"11898","71.35200","5.94625","0.00565"
"11910","71.42400","5.95223","0.00605"
"11922","71.49600","5.95815","0.00556"
"11934","71.56800","5.96413","0.00584"
"11946","71.64000","5.97016","0.00521"
"11958","71.71200","5.97620","0.00506"
"11970","71.78400","5.98218","0.00486"
"11982","71.85600","5.98816","0.00553"
"11994","71.92800","5.99414","0.00512"
"12006","72.00000","6.00012","0.00546"
"12018","72.07200","6.00610","0.00561"
"12030","72.14400","6.01214","0.00527"
"12042","72.21600","6.01812","0.00556"
"12054","72.28800","6.02421","0.00571"
"12066","72.36000","6.03013","0.00532"
"12078","72.43200","6.03617","0.00523"
"12090","72.50400","6.04221","0.00557"
"12102","72.57600","6.04813","0.00535"
"12114","72.64800","6.05411","0.00547"
"12126","72.72000","6.06015","0.00529"
"12138","72.79200","6.06619","0.00514"
"12150","72.86400","6.07223","0.00508"
"12162","72.93600","6.07820","0.00550"
"12174","73.00800","6.08418","0.00545"
"12186","73.08000","6.09016","0.00547"
"12198","73.15200","6.09614","0.00564"
"12210","73.22400","6.10212","0.00543"
"12222","73.29600","6.10816","0.00512"
"12234","73.36800","6.11420","0.00546"
"12246","73.44000","6.12024","0.00512"
"12258","73.51200","6.12621","0.00567"
"12270","73.58400","6.13219","0.00532"
"12282","73.65600","6.13817","0.00561"
"12294","73.72800","6.14421","0.00540"
"12306","73.80000","6.15019","0.00556"
"12318","73.87200","6.15617","0.00566"
"12330","73.94400","6.16221","0.00530"
"12342","74.01600","6.16825","0.00552"
"12354","74.08800","6.17423","0.00573"
"12366","74.16000","6.18014","0.00525"
"12378","74.23200","6.18618","0.00543"
"12390","74.30400","6.19216","0.00571"
"12402","74.37600","6.19820","0.00507"
"12414","74.44800","6.20418","0.00543"
"12426","74.52000","6.21022","0.00561"
"12438","74.59200","6.21620","0.00553"
"12450","74.66400","6.22218","0.00529"
"12462","74.73600","6.22816","0.00559"
"12474","74.80800","6.23414","0.00533"
"12486","74.88000","6.24017","0.00561"
"12498","74.95200","6.24615","0.00576"
"12510","75.02400","6.25219","0.00535"
"12522","75.09600","6.25817","0.00553"
"12534","75.16800","6.26421","0.00581"
"12546","75.24000","6.27013","0.00528"
"12558","75.31200","6.27617","0.00541"
"12570","75.38400","6.28215","0.00552"
"12582","75.45600","6.28819","0.00552"
"12594","75.52800","6.29416","0.00568"
"12606","75.60000","6.30020","0.00554"
"12618","75.67200","6.30618","0.00535"
"12630","75.74400","6.31222","0.00537"
"12642","75.81600","6.31814","0.00543"
"12654","75.88800","6.32418","0.00534"
"12666","75.96000","6.33016","0.00566"
"12678","76.03200","6.33620","0.00554"
"12690","76.10400","6.34212","0.00572"
"12702","76.17600","6.34821","0.00562"
"12714","76.24800","6.35419","0.00539"
"12726","76.32000","6.36017","0.00579"
"12738","76.39200","6.36609","0.00520"
"12750","76.46400","6.37219","0.00522"
"12762","76.53600","6.37817","0.00575"
"12774","76.60800","6.38427","0.00561"
"12786","76.68000","6.39013","0.00519"
"12798","76.75200","6.39622","0.00555"
"12810","76.82400","6.40214","0.00558"
"12822","76.89600","6.40818","0.00529"
"12834","76.96800","6.41410","0.00559"
"12846","77.04000","6.42014","0.00536"
"12858","77.11200","6.42612","0.00542"
"12870","77.18400","6.43222","0.00534"
"12882","77.25600","6.43814","0.00540"
"12894","77.32800","6.44424","0.00556"
"12906","77.40000","6.45015","0.00544"
"12918","77.47200","6.45619","0.00545"
"12930","77.54400","6.46211","0.00560"
"12942","77.61600","6.46821","0.00521"
"12954","77.68800","6.47419","0.00505"
"12966","77.76000","6.48017","0.00541"
"12978","77.83200","6.48615","0.00555"
"12990","77.90400","6.49219","0.00543"
"13002","77.97600","6.49817","0.00536"
"13014","78.04800","6.50415","0.00558"
"13026","78.12000","6.51018","0.00590"
"13038","78.19200","6.51616","0.00558"
"13050","78.26400","6.52220","0.00582"
"13062","78.33600","6.52812","0.00522"
"13074","78.40800","6.53416","0.00548"
"13086","78.48000","6.54014","0.00567"
"13098","78.55200","6.54618","0.00588"
"13110","78.62400","6.55216","0.00530"
"13122","78.69600","6.55813","0.00583"
"13134","78.76800","6.56423","0.00571"
"13146","78.84000","6.57015","0.00578"
"13158","78.91200","6.57619","0.00589"
"13170","78.98400","6.58211","0.00566"
"13182","79.05600","6.58815","0.00555"
"13194","79.12800","6.59413","0.00556"
"13206","79.20000","6.60017","0.00568"
"13218","79.27200","6.60621","0.00514"
"13230","79.34400","6.61218","0.00535"
"13242","79.41600","6.61822","0.00530"
"13254","79.48800","6.62420","0.00518"
"13266","79.56000","6.63018","0.00527"
"13278","79.63200","6.63616","0.00551"
"13290","79.70400","6.64214","0.00523"
"13302","79.77600","6.64818","0.00548"
"13314","79.84800","6.65416","0.00519"
"13326","79.92000","6.66019","0.00550"
"13338","79.99200","6.66617","0.00582"
"13350","80.06400","6.67221","0.00553"
"13362","80.13600","6.67813","0.00585"
"13374","80.20800","6.68417","0.00559"
"13386","80.28000","6.69015","0.00541"
"13398","80.35200","6.69625","0.00545"
"13410","80.42400","6.70217","0.00579"
"13422","80.49600","6.70821","0.00558"
"13434","80.56800","6.71413","0.00560"
"13446","80.64000","6.72016","0.00562"
"13458","80.71200","6.72608","0.00548"
"13470","80.78400","6.73218","0.00571"
"13482","80.85600","6.73816","0.00530"
"13494","80.92800","6.74426","0.00562"
"13506","81.00000","6.75018","0.00548"
"13518","81.07200","6.75622","0.00599"
"13530","81.14400","6.76214","0.00585"
"13542","81.21600","6.76818","0.00542"
"13554","81.28800","6.77409","0.00575"
"13566","81.36000","6.78019","0.00561"
"13578","81.43200","6.78617","0.00551"
"13590","81.50400","6.79221","0.00559"
"13602","81.57600","6.79819","0.00537"
"13614","81.64800","6.80417","0.00551"
"13626","81.72000","6.81015","0.00595"
"13638","81.79200","6.81613","0.00592"
"13650","81.86400","6.82211","0.00565"
"13662","81.93600","6.82820","0.00548"
"13674","82.00800","6.83418","0.00602"
"13686","82.08000","6.84016","0.00594"
"13698","82.15200","6.84620","0.00558"
"13710","82.22400","6.85218","0.00622"
"13722","82.29600","6.85816","0.00561"
"13734","82.36800","6.86420","0.00578"
"13746","82.44000","6.87018","0.00577"
"13758","82.51200","6.87622","0.00544"
"13770","82.58400","6.88219","0.00560"
"13782","82.65600","6.88823","0.00564"
"13794","82.72800","6.89415","0.00539"
"13806","82.80000","6.90019","0.00587"
"13818","82.87200","6.90611","0.00586"
"13830","82.94400","6.91215","0.00601"
"13842","83.01600","6.91813","0.00509"
"13854","83.08800","6.92423","0.00560"
"13866","83.16000","6.93020","0.00588"
"13878","83.23200","6.93618","0.00581"
"13890","83.30400","6.94210","0.00565"
"13902","83.37600","6.94808","0.00565"
"13914","83.44800","6.95412","0.00559"
"13926","83.52000","6.96016","0.00564"
"13938","83.59200","6.96620","0.00603"
"13950","83.66400","6.97218","0.00581"
"13962","83.73600","6.97822","0.00628"
"13974","83.80800","6.98420","0.00607"
"13986","83.88000","6.99017","0.00588"
"13998","83.95200","6.99615","0.00545"
"14010","84.02400","7.00213","0.00593"
"14022","84.09600","7.00817","0.00558"
"14034","84.16800","7.01415","0.00534"
"14046","84.24000","7.02025","0.00581"
"14058","84.31200","7.02617","0.00626"
"14070","84.38400","7.03215","0.00575"
"14082","84.45600","7.03813","0.00553"
"14094","84.52800","7.04416","0.00577"
"14106","84.60000","7.05014","0.00568"
"14118","84.67200","7.05618","0.00561"
"14130","84.74400","7.06210","0.00607"
"14142","84.81600","7.06820","0.00578"
"14154","84.88800","7.07412","0.00579"
"14166","84.96000","7.08010","0.00571"
"14178","85.03200","7.08608","0.00583"
"14190","85.10400","7.09218","0.00579"
"14202","85.17600","7.09815","0.00602"
"14214","85.24800","7.10419","0.00600"
"14226","85.32000","7.11017","0.00570"
"14238","85.39200","7.11621","0.00595"
"14250","85.46400","7.12219","0.00455"
"14262","85.53600","7.12811","0.00478"
"14274","85.60800","7.13415","0.00453"
"14286","85.68000","7.14019","0.00462"
"14298","85.75200","7.14616","0.00511"
"14310","85.82400","7.15214","0.00449"
"14322","85.89600","7.15818","0.00495"
"14334","85.96800","7.16416","0.00475"
"14346","86.04000","7.17014","0.00502"
"14358","86.11200","7.17612","0.00476"
"14370","86.18400","7.18216","0.00481"
"14382","86.25600","7.18814","0.00499"
"14394","86.32800","7.19418","0.00484"
"14406","86.40000","7.20015","0.00508"
"14418","86.47200","7.20613","0.00486"
"14430","86.54400","7.21217","0.00471"
"14442","86.61600","7.21815","0.00505"
"14454","86.68800","7.22413","0.00497"
"14466","86.76000","7.23017","0.00498"
"14478","86.83200","7.23621","0.00452"
"14490","86.90400","7.24213","0.00507"
"14502","86.97600","7.24817","0.00477"
"14514","87.04800","7.25415","0.00527"
"14526","87.12000","7.26012","0.00450"
"14538","87.19200","7.26610","0.00480"
"14550","87.26400","7.27220","0.00515"
"14562","87.33600","7.27818","0.00469"
"14574","87.40800","7.28416","0.00505"
"14586","87.48000","7.29014","0.00475"
"14598","87.55200","7.29618","0.00516"
"14610","87.62400","7.30210","0.00508"
"14622","87.69600","7.30814","0.00494"
"14634","87.76800","7.31411","0.00506"
"14646","87.84000","7.32015","0.00502"
"14658","87.91200","7.32613","0.00507"
"14670","87.98400","7.33217","0.00471"
"14682","88.05600","7.33815","0.00513"
"14694","88.12800","7.34413","0.00489"
"14706","88.20000","7.35011","0.00533"
"14718","88.27200","7.35609","0.00505"
"14730","88.34400","7.36218","0.00556"
"14742","88.41600","7.36822","0.00507"
"14754","88.48800","7.37420","0.00494"
"14766","88.56000","7.38018","0.00479"
"14778","88.63200","7.38616","0.00483"
"14790","88.70400","7.39220","0.00516"
"14802","88.77600","7.39812","0.00536"
"14814","88.84800","7.40416","0.00558"
"14826","88.92000","7.41020","0.00489"
"14838","88.99200","7.41623","0.00568"
"14850","89.06400","7.42221","0.00508"
"14862","89.13600","7.42819","0.00520"
"14874","89.20800","7.43417","0.00483"
"14886","89.28000","7.44009","0.00521"
"14898","89.35200","7.44613","0.00529"
"14910","89.42400","7.45217","0.00538"
"14922","89.49600","7.45821","0.00522"
"14934","89.56800","7.46418","0.00518"
"14946","89.64000","7.47022","0.00517"
"14958","89.71200","7.47620","0.00498"
"14970","89.78400","7.48218","0.00503"
"14982","89.85600","7.48816","0.00521"
"14994","89.92800","7.49414","0.00543"
"15006","90.00000","7.50018","0.00492"
"15018","90.07200","7.50622","0.00531"
"15030","90.14400","7.51220","0.00477"
"15042","90.21600","7.51818","0.00517"
"15054","90.28800","7.52421","0.00525"
"15066","90.36000","7.53013","0.00550"
"15078","90.43200","7.53611","0.00516"
"15090","90.50400","7.54215","0.00521"
"15102","90.57600","7.54819","0.00530"
"15114","90.64800","7.55423","0.00545"
"15126","90.72000","7.56015","0.00510"
"15138","90.79200","7.56619","0.00565"
"15150","90.86400","7.57216","0.00538"
"15162","90.93600","7.57814","0.00530"
"15174","91.00800","7.58412","0.00495"
"15186","91.08000","7.59010","0.00495"
"15198","91.15200","7.59620","0.00523"
"15210","91.22400","7.60218","0.00535"
"15222","91.29600","7.60816","0.00520"
"15234","91.36800","7.61414","0.00493"
"15246","91.44000","7.62012","0.00505"
"15258","91.51200","7.62610","0.00507"
"15270","91.58400","7.63213","0.00510"
"15282","91.65600","7.63817","0.00519"
"15294","91.72800","7.64415","0.00553"
"15306","91.80000","7.65019","0.00533"
"15318","91.87200","7.65617","0.00556"
"15330","91.94400","7.66215","0.00526"
"15342","92.01600","7.66813","0.00525"
"15354","92.08800","7.67417","0.00523"
"15366","92.16000","7.68015","0.00527"
"15378","92.23200","7.68618","0.00541"
"15390","92.30400","7.69222","0.00516"
"15402","92.37600","7.69820","0.00535"
"15414","92.44800","7.70418","0.00523"
"15426","92.52000","7.71010","0.00564"
"15438","92.59200","7.71608","0.00540"
"15450","92.66400","7.72212","0.00524"
"15462","92.73600","7.72816","0.00536"
"15474","92.80800","7.73420","0.00510"
"15486","92.88000","7.74017","0.00526"
"15498","92.95200","7.74615","0.00517"
"15510","93.02400","7.75207","0.00567"
"15522","93.09600","7.75811","0.00514"
"15534","93.16800","7.76415","0.00556"
"15546","93.24000","7.77019","0.00571"
"15558","93.31200","7.77617","0.00534"
"15570","93.38400","7.78221","0.00541"
"15582","93.45600","7.78819","0.00552"
"15592","93.51400","7.79297","0.00540"