File: Trajectories_together/161216Specimen_RawData_5.csv
"","V1","V2","V3"
"1","End date","12/16/2016",""
"2","Specimen label","15BT_21",""
"3","Maximum Load","0.21588","N"
"4","Time","Extension","Load"
"5","(s)","(mm)","(N)"
"6","0.00000","0.00000","0.00002"
"44","0.22800","0.01632","0.00008"
"82","0.45600","0.03833","-0.00018"
"120","0.68400","0.05722","0.00027"
"158","0.91200","0.07623","0.00002"
"196","1.14000","0.09524","0.00015"
"234","1.36800","0.11414","0.00021"
"272","1.59600","0.13321","0.00052"
"310","1.82400","0.15216","0.00050"
"348","2.05200","0.17124","0.00072"
"386","2.28000","0.19019","0.00063"
"424","2.50800","0.20920","0.00035"
"462","2.73600","0.22822","-0.00007"
"500","2.96400","0.24717","0.00053"
"538","3.19200","0.26624","0.00011"
"576","3.42000","0.28520","0.00036"
"614","3.64800","0.30415","0.00022"
"652","3.87600","0.32316","0.00041"
"690","4.10400","0.34212","0.00064"
"728","4.33200","0.36119","0.00078"
"766","4.56000","0.38014","0.00062"
"804","4.78800","0.39921","0.00095"
"842","5.01600","0.41817","0.00042"
"880","5.24400","0.43712","0.00041"
"918","5.47200","0.45619","0.00040"
"956","5.70000","0.47515","0.00050"
"994","5.92800","0.49422","0.00023"
"1032","6.15600","0.51317","0.00078"
"1070","6.38400","0.53213","0.00038"
"1108","6.61200","0.55120","0.00089"
"1146","6.84000","0.57015","0.00085"
"1184","7.06800","0.58923","0.00062"
"1222","7.29600","0.60812","0.00051"
"1260","7.52400","0.62713","0.00091"
"1298","7.75200","0.64615","0.00091"
"1336","7.98000","0.66516","0.00092"
"1374","8.20800","0.68423","0.00041"
"1412","8.43600","0.70307","0.00093"
"1450","8.66400","0.72220","0.00052"
"1488","8.89200","0.74115","0.00082"
"1526","9.12000","0.76016","0.00069"
"1564","9.34800","0.77918","0.00051"
"1602","9.57600","0.79813","0.00089"
"1640","9.80400","0.81720","0.00034"
"1678","10.03200","0.83610","0.00067"
"1716","10.26000","0.85517","0.00016"
"1754","10.48800","0.87412","0.00048"
"1792","10.71600","0.89320","0.00088"
"1830","10.94400","0.91221","0.00088"
"1868","11.17200","0.93116","0.00060"
"1906","11.40000","0.95018","0.00032"
"1944","11.62800","0.96913","0.00048"
"1982","11.85600","0.98820","0.00051"
"2020","12.08400","1.00721","0.00068"
"2058","12.31200","1.02617","0.00067"
"2096","12.54000","1.04512","0.00080"
"2134","12.76800","1.06407","0.00033"
"2172","12.99600","1.08315","0.00069"
"2210","13.22400","1.10216","0.00098"
"2248","13.45200","1.12117","0.00109"
"2286","13.68000","1.14025","0.00057"
"2324","13.90800","1.15914","0.00058"
"2362","14.13600","1.17815","0.00059"
"2400","14.36400","1.19717","0.00063"
"2438","14.59200","1.21618","0.00111"
"2476","14.82000","1.23513","0.00096"
"2514","15.04800","1.25415","0.00064"
"2552","15.27600","1.27316","0.00059"
"2590","15.50400","1.29211","0.00032"
"2628","15.73200","1.31118","0.00067"
"2666","15.96000","1.33014","0.00026"
"2704","16.18800","1.34915","0.00078"
"2742","16.41600","1.36816","0.00089"
"2780","16.64400","1.38718","0.00069"
"2818","16.87200","1.40619","0.00076"
"2856","17.10000","1.42508","0.00074"
"2894","17.32800","1.44422","0.00092"
"2932","17.55600","1.46317","0.00039"
"2970","17.78400","1.48218","0.00071"
"3008","18.01200","1.50114","0.00079"
"3046","18.24000","1.52015","0.00083"
"3084","18.46800","1.53916","0.00081"
"3122","18.69600","1.55817","0.00088"
"3160","18.92400","1.57719","0.00073"
"3198","19.15200","1.59614","0.00131"
"3236","19.38000","1.61515","0.00080"
"3274","19.60800","1.63417","0.00084"
"3312","19.83600","1.65318","0.00091"
"3350","20.06400","1.67219","0.00073"
"3388","20.29200","1.69115","0.00049"
"3426","20.52000","1.71016","0.00106"
"3464","20.74800","1.72911","0.00053"
"3502","20.97600","1.74819","0.00056"
"3540","21.20400","1.76714","0.00055"
"3578","21.43200","1.78621","0.00037"
"3616","21.66000","1.80523","0.00050"
"3654","21.88800","1.82412","0.00070"
"3692","22.11600","1.84319","0.00045"
"3730","22.34400","1.86215","0.00078"
"3768","22.57200","1.88122","0.00040"
"3806","22.80000","1.90017","0.00027"
"3844","23.02800","1.91912","0.00012"
"3882","23.25600","1.93814","0.00041"
"3920","23.48400","1.95709","0.00057"
"3958","23.71200","1.97622","0.00000"
"3996","23.94000","1.99512","0.00010"
"4034","24.16800","2.01419","0.00040"
"4072","24.39600","2.03320","0.00031"
"4110","24.62400","2.05216","0.00050"
"4148","24.85200","2.07117","-0.00021"
"4186","25.08000","2.09018","0.00032"
"4224","25.30800","2.10920","0.00073"
"4262","25.53600","2.12815","0.00058"
"4300","25.76400","2.14716","0.00036"
"4338","25.99200","2.16617","0.00050"
"4376","26.22000","2.18513","0.00038"
"4414","26.44800","2.20420","0.00013"
"4452","26.67600","2.22315","0.00056"
"4490","26.90400","2.24217","0.00036"
"4528","27.13200","2.26112","0.00000"
"4566","27.36000","2.28013","0.00051"
"4604","27.58800","2.29921","0.00028"
"4642","27.81600","2.31810","0.00005"
"4680","28.04400","2.33717","0.00020"
"4718","28.27200","2.35613","0.00057"
"4756","28.50000","2.37520","0.00029"
"4794","28.72800","2.39421","0.00016"
"4832","28.95600","2.41317","0.00021"
"4870","29.18400","2.43224","0.00058"
"4908","29.41200","2.45113","0.00022"
"4946","29.64000","2.47020","0.00020"
"4984","29.86800","2.48910","0.00073"
"5022","30.09600","2.50811","0.00042"
"5060","30.32400","2.52718","0.00047"
"5098","30.55200","2.54608","0.00016"
"5136","30.78000","2.56521","0.00002"
"5174","31.00800","2.58410","0.00005"
"5212","31.23600","2.60318","0.00020"
"5250","31.46400","2.62219","0.00058"
"5288","31.69200","2.64114","0.00025"
"5326","31.92000","2.66016","-0.00006"
"5364","32.14800","2.67911","0.00034"
"5402","32.37600","2.69824","0.00022"
"5440","32.60400","2.71714","-0.00005"
"5478","32.83200","2.73615","0.00030"
"5516","33.06000","2.75516","0.00020"
"5554","33.28800","2.77411","-0.00002"
"5592","33.51600","2.79319","-0.00008"
"5630","33.74400","2.81214","0.00007"
"5668","33.97200","2.83115","-0.00005"
"5706","34.20000","2.85017","-0.00004"
"5744","34.42800","2.86918","0.00019"
"5782","34.65600","2.88819","-0.00010"
"5820","34.88400","2.90715","0.00035"
"5858","35.11200","2.92616","0.00038"
"5896","35.34000","2.94517","0.00002"
"5934","35.56800","2.96413","0.00044"
"5972","35.79600","2.98314","0.00022"
"6010","36.02400","3.00215","0.00080"
"6048","36.25200","3.02117","0.00020"
"6086","36.48000","3.04018","0.00022"
"6124","36.70800","3.05919","0.00047"
"6162","36.93600","3.07814","0.00048"
"6200","37.16400","3.09716","0.00043"
"6238","37.39200","3.11617","0.00033"
"6276","37.62000","3.13518","0.00060"
"6314","37.84800","3.15420","0.00018"
"6352","38.07600","3.17315","0.00064"
"6390","38.30400","3.19216","0.00052"
"6428","38.53200","3.21112","0.00041"
"6466","38.76000","3.23019","0.00053"
"6504","38.98800","3.24914","0.00012"
"6542","39.21600","3.26816","0.00040"
"6580","39.44400","3.28723","0.00059"
"6618","39.67200","3.30612","0.00018"
"6656","39.90000","3.32520","0.00045"
"6694","40.12800","3.34415","0.00084"
"6732","40.35600","3.36316","0.00014"
"6770","40.58400","3.38217","0.00019"
"6808","40.81200","3.40113","0.00028"
"6846","41.04000","3.42020","0.00052"
"6884","41.26800","3.43909","0.00054"
"6922","41.49600","3.45823","0.00041"
"6960","41.72400","3.47718","-0.00005"
"6998","41.95200","3.49619","0.00029"
"7036","42.18000","3.51521","0.00057"
"7074","42.40800","3.53416","0.00058"
"7112","42.63600","3.55317","0.00036"
"7150","42.86400","3.57207","0.00055"
"7188","43.09200","3.59120","0.00045"
"7226","43.32000","3.61015","0.00035"
"7264","43.54800","3.62916","0.00040"
"7302","43.77600","3.64818","0.00064"
"7340","44.00400","3.66713","0.00056"
"7378","44.23200","3.68626","0.00052"
"7416","44.46000","3.70516","0.00031"
"7454","44.68800","3.72423","0.00063"
"7492","44.91600","3.74312","0.00039"
"7530","45.14400","3.76220","0.00048"
"7568","45.37200","3.78115","-0.00004"
"7606","45.60000","3.80016","0.00065"
"7644","45.82800","3.81918","0.00057"
"7682","46.05600","3.83813","0.00067"
"7720","46.28400","3.85720","0.00047"
"7758","46.51200","3.87622","0.00038"
"7796","46.74000","3.89517","0.00009"
"7834","46.96800","3.91418","0.00023"
"7872","47.19600","3.93307","0.00047"
"7910","47.42400","3.95215","0.00038"
"7948","47.65200","3.97116","0.00042"
"7986","47.88000","3.99023","0.00056"
"8024","48.10800","4.00919","0.00071"
"8062","48.33600","4.02808","0.00029"
"8100","48.56400","4.04721","0.00021"
"8138","48.79200","4.06611","0.00039"
"8176","49.02000","4.08518","0.00057"
"8214","49.24800","4.10413","0.00087"
"8252","49.47600","4.12321","0.00017"
"8290","49.70400","4.14222","0.00030"
"8328","49.93200","4.16111","0.00033"
"8366","50.16000","4.18018","0.00050"
"8404","50.38800","4.19914","0.00046"
"8442","50.61600","4.21815","0.00042"
"8480","50.84400","4.23716","0.00061"
"8518","51.07200","4.25618","-0.00001"
"8556","51.30000","4.27519","0.00116"
"8594","51.52800","4.29408","0.00075"
"8632","51.75600","4.31316","0.00059"
"8670","51.98400","4.33217","0.00056"
"8708","52.21200","4.35118","0.00042"
"8746","52.44000","4.37020","0.00109"
"8784","52.66800","4.38915","0.00082"
"8822","52.89600","4.40822","0.00107"
"8860","53.12400","4.42712","0.00089"
"8898","53.35200","4.44619","0.00084"
"8936","53.58000","4.46514","0.00072"
"8974","53.80800","4.48416","0.00070"
"9012","54.03600","4.50311","0.00057"
"9050","54.26400","4.52218","0.00065"
"9088","54.49200","4.54119","0.00069"
"9126","54.72000","4.56015","0.00075"
"9164","54.94800","4.57916","0.00115"
"9202","55.17600","4.59811","0.00052"
"9240","55.40400","4.61719","0.00055"
"9278","55.63200","4.63614","0.00076"
"9316","55.86000","4.65515","0.00068"
"9354","56.08800","4.67417","0.00098"
"9392","56.31600","4.69312","0.00072"
"9430","56.54400","4.71219","0.00080"
"9468","56.77200","4.73121","0.00078"
"9506","57.00000","4.75016","0.00086"
"9544","57.22800","4.76923","0.00082"
"9582","57.45600","4.78819","0.00124"
"9620","57.68400","4.80720","0.00062"
"9658","57.91200","4.82615","0.00057"
"9696","58.14000","4.84516","0.00064"
"9734","58.36800","4.86412","0.00083"
"9772","58.59600","4.88319","0.00021"
"9810","58.82400","4.90220","0.00141"
"9848","59.05200","4.92116","0.00039"
"9886","59.28000","4.94017","0.00082"
"9924","59.50800","4.95918","0.00086"
"9962","59.73600","4.97826","0.00093"
"10000","59.96400","4.99715","0.00071"
"10038","60.19200","5.01616","0.00109"
"10076","60.42000","5.03517","0.00080"
"10114","60.64800","5.05413","0.00061"
"10152","60.87600","5.07314","0.00121"
"10190","61.10400","5.09215","0.00064"
"10228","61.33200","5.11117","0.00067"
"10266","61.56000","5.13018","0.00095"
"10304","61.78800","5.14913","0.00090"
"10342","62.01600","5.16821","0.00084"
"10380","62.24400","5.18716","0.00078"
"10418","62.47200","5.20623","0.00087"
"10456","62.70000","5.22513","0.00131"
"10494","62.92800","5.24414","0.00138"
"10532","63.15600","5.26315","0.00119"
"10570","63.38400","5.28211","0.00088"
"10608","63.61200","5.30118","0.00086"
"10646","63.84000","5.32013","0.00134"
"10684","64.06800","5.33921","0.00081"
"10722","64.29600","5.35810","0.00110"
"10760","64.52400","5.37717","0.00104"
"10798","64.75200","5.39618","0.00147"
"10836","64.98000","5.41514","0.00077"
"10874","65.20800","5.43415","0.00088"
"10912","65.43600","5.45310","0.00084"
"10950","65.66400","5.47224","0.00110"
"10988","65.89200","5.49119","0.00121"
"11026","66.12000","5.51014","0.00061"
"11064","66.34800","5.52922","0.00097"
"11102","66.57600","5.54811","0.00107"
"11140","66.80400","5.56718","0.00054"
"11178","67.03200","5.58614","0.00087"
"11216","67.26000","5.60515","0.00114"
"11254","67.48800","5.62422","0.00114"
"11292","67.71600","5.64312","0.00132"
"11330","67.94400","5.66219","0.00115"
"11368","68.17200","5.68108","0.00078"
"11406","68.40000","5.70015","0.00073"
"11444","68.62800","5.71911","0.00106"
"11482","68.85600","5.73818","0.00110"
"11520","69.08400","5.75719","0.00063"
"11558","69.31200","5.77615","0.00131"
"11596","69.54000","5.79516","0.00125"
"11634","69.76800","5.81417","0.00142"
"11672","69.99600","5.83319","0.00083"
"11710","70.22400","5.85220","0.00105"
"11748","70.45200","5.87115","0.00121"
"11786","70.68000","5.89011","0.00101"
"11824","70.90800","5.90912","0.00096"
"11862","71.13600","5.92819","0.00121"
"11900","71.36400","5.94715","0.00099"
"11938","71.59200","5.96616","0.00136"
"11976","71.82000","5.98511","0.00146"
"12014","72.04800","6.00418","0.00150"
"12052","72.27600","6.02326","0.00099"
"12090","72.50400","6.04215","0.00117"
"12128","72.73200","6.06116","0.00135"
"12166","72.96000","6.08012","0.00120"
"12204","73.18800","6.09919","0.00141"
"12242","73.41600","6.11820","0.00158"
"12280","73.64400","6.13716","0.00129"
"12318","73.87200","6.15617","0.00119"
"12356","74.10000","6.17512","0.00146"
"12394","74.32800","6.19420","0.00158"
"12432","74.55600","6.21315","0.00149"
"12470","74.78400","6.23216","0.00121"
"12508","75.01200","6.25112","0.00160"
"12546","75.24000","6.27019","0.00167"
"12584","75.46800","6.28920","0.00217"
"12622","75.69600","6.30815","0.00163"
"12660","75.92400","6.32717","0.00150"
"12698","76.15200","6.34612","0.00135"
"12736","76.38000","6.36513","0.00160"
"12774","76.60800","6.38421","0.00196"
"12812","76.83600","6.40316","0.00185"
"12850","77.06400","6.42217","0.00164"
"12888","77.29200","6.44113","0.00162"
"12926","77.52000","6.46026","0.00144"
"12964","77.74800","6.47921","0.00188"
"13002","77.97600","6.49817","0.00189"
"13040","78.20400","6.51718","0.00189"
"13078","78.43200","6.53607","0.00187"
"13116","78.66000","6.55520","0.00159"
"13154","78.88800","6.57416","0.00140"
"13192","79.11600","6.59323","0.00187"
"13230","79.34400","6.61212","0.00153"
"13268","79.57200","6.63114","0.00164"
"13306","79.80000","6.65021","0.00161"
"13344","80.02800","6.66910","0.00210"
"13382","80.25600","6.68818","0.00228"
"13420","80.48400","6.70713","0.00239"
"13458","80.71200","6.72620","0.00214"
"13496","80.94000","6.74522","0.00224"
"13534","81.16800","6.76417","0.00215"
"13572","81.39600","6.78312","0.00187"
"13610","81.62400","6.80208","0.00197"
"13648","81.85200","6.82115","0.00243"
"13686","82.08000","6.84016","0.00227"
"13724","82.30800","6.85917","0.00236"
"13762","82.53600","6.87819","0.00229"
"13800","82.76400","6.89708","0.00220"
"13838","82.99200","6.91621","0.00244"
"13876","83.22000","6.93511","0.00215"
"13914","83.44800","6.95418","0.00200"
"13952","83.67600","6.97313","0.00251"
"13990","83.90400","6.99215","0.00237"
"14028","84.13200","7.01116","0.00214"
"14066","84.36000","7.03011","0.00221"
"14104","84.58800","7.04919","0.00216"
"14142","84.81600","7.06814","0.00191"
"14180","85.04400","7.08721","0.00253"
"14218","85.27200","7.10617","0.00229"
"14256","85.50000","7.12518","0.00224"
"14294","85.72800","7.14419","0.00247"
"14332","85.95600","7.16309","0.00248"
"14370","86.18400","7.18210","0.00213"
"14408","86.41200","7.20117","0.00255"
"14446","86.64000","7.22018","0.00216"
"14484","86.86800","7.23920","0.00249"
"14522","87.09600","7.25815","0.00243"
"14560","87.32400","7.27716","0.00279"
"14598","87.55200","7.29618","0.00255"
"14636","87.78000","7.31513","0.00223"
"14674","88.00800","7.33414","0.00243"
"14712","88.23600","7.35316","0.00222"
"14750","88.46400","7.37217","0.00254"
"14788","88.69200","7.39112","0.00253"
"14826","88.92000","7.41020","0.00244"
"14864","89.14800","7.42909","0.00272"
"14902","89.37600","7.44822","0.00246"
"14940","89.60400","7.46717","0.00292"
"14978","89.83200","7.48619","0.00301"
"15016","90.06000","7.50514","0.00260"
"15054","90.28800","7.52415","0.00288"
"15092","90.51600","7.54317","0.00290"
"15130","90.74400","7.56212","0.00265"
"15168","90.97200","7.58119","0.00270"
"15206","91.20000","7.60015","0.00268"
"15244","91.42800","7.61922","0.00301"
"15282","91.65600","7.63817","0.00334"
"15320","91.88400","7.65713","0.00286"
"15358","92.11200","7.67614","0.00271"
"15396","92.34000","7.69509","0.00274"
"15434","92.56800","7.71417","0.00245"
"15472","92.79600","7.73318","0.00246"
"15510","93.02400","7.75213","0.00300"
"15548","93.25200","7.77120","0.00298"
"15586","93.48000","7.79016","0.00285"
"15624","93.70800","7.80917","0.00264"
"15662","93.93600","7.82812","0.00282"
"15700","94.16400","7.84720","0.00284"
"15738","94.39200","7.86615","0.00325"
"15776","94.62000","7.88516","0.00330"
"15814","94.84800","7.90418","0.00303"
"15852","95.07600","7.92313","0.00327"
"15890","95.30400","7.94220","0.00280"
"15928","95.53200","7.96116","0.00340"
"15966","95.76000","7.98017","0.00340"
"16004","95.98800","7.99918","0.00329"
"16042","96.21600","8.01820","0.00311"
"16080","96.44400","8.03721","0.00305"
"16118","96.67200","8.05616","0.00372"
"16156","96.90000","8.07517","0.00379"
"16194","97.12800","8.09413","0.00317"
"16232","97.35600","8.11314","0.00346"
"16270","97.58400","8.13215","0.00331"
"16308","97.81200","8.15111","0.00314"
"16346","98.04000","8.17024","0.00323"
"16384","98.26800","8.18913","0.00389"
"16422","98.49600","8.20821","0.00358"
"16460","98.72400","8.22716","0.00342"
"16498","98.95200","8.24617","0.00308"
"16536","99.18000","8.26524","0.00414"
"16574","99.40800","8.28408","0.00334"
"16612","99.63600","8.30315","0.00364"
"16650","99.86400","8.32210","0.00382"
"16688","100.09200","8.34124","0.00359"
"16726","100.32000","8.36019","0.00340"
"16764","100.54800","8.37914","0.00340"
"16802","100.77600","8.39822","0.00314"
"16840","101.00400","8.41711","0.00415"
"16878","101.23200","8.43618","0.00412"
"16916","101.46000","8.45514","0.00337"
"16954","101.68800","8.47421","0.00388"
"16992","101.91600","8.49316","0.00414"
"17030","102.14400","8.51218","0.00410"
"17068","102.37200","8.53119","0.00407"
"17106","102.60000","8.55014","0.00420"
"17144","102.82800","8.56916","0.00416"
"17182","103.05600","8.58817","0.00409"
"17220","103.28400","8.60718","0.00458"
"17258","103.51200","8.62619","0.00452"
"17296","103.74000","8.64515","0.00453"
"17334","103.96800","8.66416","0.00492"
"17372","104.19600","8.68317","0.00448"
"17410","104.42400","8.70225","0.00428"
"17448","104.65200","8.72114","0.00449"
"17486","104.88000","8.74015","0.00463"
"17524","105.10800","8.75917","0.00436"
"17562","105.33600","8.77812","0.00442"
"17600","105.56400","8.79719","0.00467"
"17638","105.79200","8.81615","0.00463"
"17676","106.02000","8.83516","0.00531"
"17714","106.24800","8.85417","0.00478"
"17752","106.47600","8.87319","0.00503"
"17790","106.70400","8.89214","0.00522"
"17828","106.93200","8.91115","0.00483"
"17866","107.16000","8.93011","0.00481"
"17904","107.38800","8.94912","0.00503"
"17942","107.61600","8.96813","0.00520"
"17980","107.84400","8.98714","0.00503"
"18018","108.07200","9.00616","0.00563"
"18056","108.30000","9.02517","0.00549"
"18094","108.52800","9.04412","0.00521"
"18132","108.75600","9.06320","0.00533"
"18170","108.98400","9.08215","0.00523"
"18208","109.21200","9.10116","0.00608"
"18246","109.44000","9.12018","0.00559"
"18284","109.66800","9.13913","0.00585"
"18322","109.89600","9.15820","0.00612"
"18360","110.12400","9.17710","0.00509"
"18398","110.35200","9.19617","0.00590"
"18436","110.58000","9.21518","0.00545"
"18474","110.80800","9.23425","0.00528"
"18512","111.03600","9.25321","0.00607"
"18550","111.26400","9.27216","0.00637"
"18588","111.49200","9.29117","0.00595"
"18626","111.72000","9.31013","0.00636"
"18664","111.94800","9.32920","0.00704"
"18702","112.17600","9.34815","0.00658"
"18740","112.40400","9.36711","0.00637"
"18778","112.63200","9.38612","0.00662"
"18816","112.86000","9.40513","0.00622"
"18854","113.08800","9.42421","0.00656"
"18892","113.31600","9.44316","0.00611"
"18930","113.54400","9.46217","0.00642"
"18968","113.77200","9.48113","0.00625"
"19006","114.00000","9.50014","0.00550"
"19044","114.22800","9.51915","0.00522"
"19082","114.45600","9.53811","0.00592"
"19120","114.68400","9.55718","0.00590"
"19158","114.91200","9.57607","0.00603"
"19196","115.14000","9.59520","0.00659"
"19234","115.36800","9.61416","0.00674"
"19272","115.59600","9.63311","0.00651"
"19310","115.82400","9.65218","0.00691"
"19348","116.05200","9.67108","0.00646"
"19386","116.28000","9.69021","0.00697"
"19424","116.50800","9.70916","0.00705"
"19462","116.73600","9.72818","0.00731"
"19500","116.96400","9.74719","0.00760"
"19538","117.19200","9.76614","0.00779"
"19576","117.42000","9.78516","0.00722"
"19614","117.64800","9.80417","0.00752"
"19652","117.87600","9.82318","0.00813"
"19690","118.10400","9.84213","0.00777"
"19728","118.33200","9.86115","0.00835"
"19766","118.56000","9.88022","0.00845"
"19804","118.78800","9.89911","0.00797"
"19842","119.01600","9.91819","0.00809"
"19880","119.24400","9.93714","0.00804"
"19918","119.47200","9.95615","0.00843"
"19956","119.70000","9.97517","0.00858"
"19994","119.92800","9.99418","0.00886"
"20032","120.15600","10.01319","0.00550"
"20070","120.38400","10.03209","0.00494"
"20108","120.61200","10.05116","0.00533"
"20146","120.84000","10.07017","0.00516"
"20184","121.06800","10.08918","0.00538"
"20222","121.29600","10.10814","0.00535"
"20260","121.52400","10.12715","0.00550"
"20298","121.75200","10.14616","0.00633"
"20336","121.98000","10.16512","0.00598"
"20374","122.20800","10.18413","0.00647"
"20412","122.43600","10.20314","0.00660"
"20450","122.66400","10.22210","0.00678"
"20488","122.89200","10.24117","0.00689"
"20526","123.12000","10.26012","0.00638"
"20564","123.34800","10.27920","0.00629"
"20602","123.57600","10.29815","0.00709"
"20640","123.80400","10.31716","0.00749"
"20678","124.03200","10.33618","0.00736"
"20716","124.26000","10.35519","0.00717"
"20754","124.48800","10.37414","0.00791"
"20792","124.71600","10.39316","0.00757"
"20830","124.94400","10.41223","0.00800"
"20868","125.17200","10.43112","0.00764"
"20906","125.40000","10.45019","0.00770"
"20944","125.62800","10.46915","0.00783"
"20982","125.85600","10.48816","0.00690"
"21020","126.08400","10.50717","0.00591"
"21058","126.31200","10.52619","0.00630"
"21096","126.54000","10.54520","0.00608"
"21134","126.76800","10.56415","0.00642"
"21172","126.99600","10.58311","0.00605"
"21210","127.22400","10.60212","0.00622"
"21248","127.45200","10.62119","0.00620"
"21286","127.68000","10.64020","0.00632"
"21324","127.90800","10.65916","0.00637"
"21362","128.13600","10.67817","0.00676"
"21400","128.36400","10.69712","0.00692"
"21438","128.59200","10.71620","0.00705"
"21476","128.82000","10.73521","0.00670"
"21514","129.04800","10.75410","0.00722"
"21552","129.27600","10.77318","0.00706"
"21590","129.50400","10.79213","0.00716"
"21628","129.73200","10.81120","0.00675"
"21666","129.96000","10.83016","0.00663"
"21704","130.18800","10.84917","0.00678"
"21742","130.41600","10.86818","0.00701"
"21780","130.64400","10.88713","0.00699"
"21818","130.87200","10.90615","0.00712"
"21856","131.10000","10.92510","0.00708"
"21894","131.32800","10.94423","0.00664"
"21932","131.55600","10.96313","0.00705"
"21970","131.78400","10.98220","0.00737"
"22008","132.01200","11.00121","0.00732"
"22046","132.24000","11.02011","0.00737"
"22084","132.46800","11.03918","0.00794"
"22122","132.69600","11.05819","0.00719"
"22160","132.92400","11.07721","0.00768"
"22198","133.15200","11.09622","0.00785"
"22236","133.38000","11.11517","0.00765"
"22274","133.60800","11.13419","0.00870"
"22312","133.83600","11.15308","0.00875"
"22350","134.06400","11.17221","0.00816"
"22388","134.29200","11.19116","0.00923"
"22426","134.52000","11.21018","0.00904"
"22464","134.74800","11.22919","0.00919"
"22502","134.97600","11.24809","0.01008"
"22540","135.20400","11.26722","0.00943"
"22578","135.43200","11.28611","0.00954"
"22616","135.66000","11.30519","0.00999"
"22654","135.88800","11.32414","0.01020"
"22692","136.11600","11.34315","0.01007"
"22730","136.34400","11.36222","0.01048"
"22768","136.57200","11.38118","0.00988"
"22806","136.80000","11.40019","0.01046"
"22844","137.02800","11.41908","0.00933"
"22882","137.25600","11.43816","0.00948"
"22920","137.48400","11.45717","0.00944"
"22958","137.71200","11.47618","0.00952"
"22996","137.94000","11.49519","0.00967"
"23034","138.16800","11.51415","0.00995"
"23072","138.39600","11.53316","0.00881"
"23110","138.62400","11.55212","0.00902"
"23148","138.85200","11.57119","0.00975"
"23186","139.08000","11.59020","0.01017"
"23224","139.30800","11.60915","0.00989"
"23262","139.53600","11.62823","0.01040"
"23300","139.76400","11.64712","0.01033"
"23338","139.99200","11.66613","0.01011"
"23376","140.22000","11.68515","0.01066"
"23414","140.44800","11.70416","0.01098"
"23452","140.67600","11.72317","0.01137"
"23490","140.90400","11.74213","0.01111"
"23528","141.13200","11.76120","0.01169"
"23566","141.36000","11.78015","0.01207"
"23604","141.58800","11.79917","0.01157"
"23642","141.81600","11.81818","0.01220"
"23680","142.04400","11.83719","0.01229"
"23718","142.27200","11.85620","0.01214"
"23756","142.50000","11.87516","0.01282"
"23794","142.72800","11.89417","0.01259"
"23832","142.95600","11.91312","0.01275"
"23870","143.18400","11.93220","0.01303"
"23908","143.41200","11.95115","0.01303"
"23946","143.64000","11.97010","0.01354"
"23984","143.86800","11.98912","0.01354"
"24022","144.09600","12.00813","0.01370"
"24060","144.32400","12.02720","0.01384"
"24098","144.55200","12.04610","0.01401"
"24136","144.78000","12.06517","0.01462"
"24174","145.00800","12.08412","0.01511"
"24212","145.23600","12.10314","0.01519"
"24250","145.46400","12.12215","0.01547"
"24288","145.69200","12.14110","0.01587"
"24326","145.92000","12.16018","0.01548"
"24364","146.14800","12.17913","0.01614"
"24402","146.37600","12.19820","0.01624"
"24440","146.60400","12.21715","0.01700"
"24478","146.83200","12.23617","0.01647"
"24516","147.06000","12.25518","0.01665"
"24554","147.28800","12.27419","0.01676"
"24592","147.51600","12.29321","0.01726"
"24630","147.74400","12.31216","0.01745"
"24668","147.97200","12.33117","0.01714"
"24706","148.20000","12.35013","0.01810"
"24744","148.42800","12.36914","0.01780"
"24782","148.65600","12.38815","0.01770"
"24820","148.88400","12.40711","0.01821"
"24858","149.11200","12.42624","0.01899"
"24896","149.34000","12.44507","0.01842"
"24934","149.56800","12.46420","0.01872"
"24972","149.79600","12.48316","0.01930"
"25010","150.02400","12.50217","0.01939"
"25048","150.25200","12.52118","0.01936"
"25086","150.48000","12.54008","0.02012"
"25124","150.70800","12.55921","0.02023"
"25162","150.93600","12.57810","0.02033"
"25200","151.16400","12.59718","0.02145"
"25238","151.39200","12.61619","0.02113"
"25276","151.62000","12.63514","0.02156"
"25314","151.84800","12.65421","0.02171"
"25352","152.07600","12.67317","0.02222"
"25390","152.30400","12.69224","0.02187"
"25428","152.53200","12.71114","0.02241"
"25466","152.76000","12.73009","0.02256"
"25504","152.98800","12.74922","0.02206"
"25542","153.21600","12.76812","0.02161"
"25580","153.44400","12.78719","0.02258"
"25618","153.67200","12.80614","0.02294"
"25656","153.90000","12.82521","0.02347"
"25694","154.12800","12.84417","0.02399"
"25732","154.35600","12.86312","0.02416"
"25770","154.58400","12.88219","0.02428"
"25808","154.81200","12.90109","0.02478"
"25846","155.04000","12.92022","0.02552"
"25884","155.26800","12.93917","0.02576"
"25922","155.49600","12.95819","0.02578"
"25960","155.72400","12.97720","0.02607"
"25998","155.95200","12.99615","0.02682"
"26036","156.18000","13.01522","0.02733"
"26074","156.40800","13.03418","0.02783"
"26112","156.63600","13.05319","0.02821"
"26150","156.86400","13.07215","0.02881"
"26188","157.09200","13.09116","0.02894"
"26226","157.32000","13.11017","0.02967"
"26264","157.54800","13.12918","0.02979"
"26302","157.77600","13.14814","0.03048"
"26340","158.00400","13.16709","0.03027"
"26378","158.23200","13.18616","0.03114"
"26416","158.46000","13.20518","0.03160"
"26454","158.68800","13.22419","0.03273"
"26492","158.91600","13.24314","0.03334"
"26530","159.14400","13.26210","0.03429"
"26568","159.37200","13.28117","0.03494"
"26606","159.60000","13.30018","0.03551"
"26644","159.82800","13.31919","0.03546"
"26682","160.05600","13.33821","0.03726"
"26720","160.28400","13.35716","0.03724"
"26758","160.51200","13.37617","0.03849"
"26796","160.74000","13.39513","0.03869"
"26834","160.96800","13.41420","0.03961"
"26872","161.19600","13.43309","0.03952"
"26910","161.42400","13.45217","0.04049"
"26948","161.65200","13.47118","0.04045"
"26986","161.88000","13.49013","0.04107"
"27024","162.10800","13.50921","0.04215"
"27062","162.33600","13.52816","0.04154"
"27100","162.56400","13.54717","0.04077"
"27138","162.79200","13.56612","0.04173"
"27176","163.02000","13.58520","0.04243"
"27214","163.24800","13.60415","0.04306"
"27252","163.47600","13.62316","0.04324"
"27290","163.70400","13.64218","0.04391"
"27328","163.93200","13.66113","0.04447"
"27366","164.16000","13.68020","0.04514"
"27404","164.38800","13.69910","0.04580"
"27442","164.61600","13.71817","0.04663"
"27480","164.84400","13.73718","0.04714"
"27518","165.07200","13.75614","0.04743"
"27556","165.30000","13.77521","0.04848"
"27594","165.52800","13.79410","0.04750"
"27632","165.75600","13.81318","0.04840"
"27670","165.98400","13.83207","0.04918"
"27708","166.21200","13.85114","0.05015"
"27746","166.44000","13.87022","0.05054"
"27784","166.66800","13.88917","0.05046"
"27822","166.89600","13.90818","0.05066"
"27860","167.12400","13.92714","0.05219"
"27898","167.35200","13.94621","0.05316"
"27936","167.58000","13.96510","0.05389"
"27974","167.80800","13.98417","0.05480"
"28012","168.03600","14.00319","0.05535"
"28050","168.26400","14.02214","0.05626"
"28088","168.49200","14.04121","0.05744"
"28126","168.72000","14.06017","0.05892"
"28164","168.94800","14.07918","0.05973"
"28202","169.17600","14.09813","0.06038"
"28240","169.40400","14.11715","0.06095"
"28278","169.63200","14.13622","0.06267"
"28316","169.86000","14.15511","0.06278"
"28354","170.08800","14.17418","0.06339"
"28392","170.31600","14.19308","0.06384"
"28430","170.54400","14.21215","0.06474"
"28468","170.77200","14.23116","0.06574"
"28506","171.00000","14.25012","0.06667"
"28544","171.22800","14.26919","0.06698"
"28582","171.45600","14.28808","0.06778"
"28620","171.68400","14.30716","0.06878"
"28658","171.91200","14.32617","0.06928"
"28696","172.14000","14.34518","0.07021"
"28734","172.36800","14.36420","0.07146"
"28772","172.59600","14.38309","0.07180"
"28810","172.82400","14.40216","0.07270"
"28848","173.05200","14.42118","0.07319"
"28886","173.28000","14.44019","0.07420"
"28924","173.50800","14.45920","0.07535"
"28962","173.73600","14.47810","0.07703"
"29000","173.96400","14.49717","0.07848"
"29038","174.19200","14.51612","0.07956"
"29076","174.42000","14.53513","0.08035"
"29114","174.64800","14.55421","0.08227"
"29152","174.87600","14.57322","0.08362"
"29190","175.10400","14.59223","0.08415"
"29228","175.33200","14.61113","0.08575"
"29266","175.56000","14.63020","0.08735"
"29304","175.78800","14.64909","0.08838"
"29342","176.01600","14.66817","0.08922"
"29380","176.24400","14.68712","0.09009"
"29418","176.47200","14.70619","0.09033"
"29456","176.70000","14.72521","0.09147"
"29494","176.92800","14.74410","0.09257"
"29532","177.15600","14.76317","0.09303"
"29570","177.38400","14.78213","0.09356"
"29608","177.61200","14.80120","0.09460"
"29646","177.84000","14.82015","0.09486"
"29684","178.06800","14.83916","0.09562"
"29722","178.29600","14.85812","0.09625"
"29760","178.52400","14.87713","0.09697"
"29798","178.75200","14.89620","0.09739"
"29836","178.98000","14.91516","0.09863"
"29874","179.20800","14.93417","0.09887"
"29912","179.43600","14.95318","0.09952"
"29950","179.66400","14.97214","0.10015"
"29988","179.89200","14.99121","0.10102"
"30026","180.12000","15.01016","0.10155"
"30064","180.34800","15.02912","0.10244"
"30102","180.57600","15.04813","0.10302"
"30140","180.80400","15.06720","0.10401"
"30178","181.03200","15.08615","0.10443"
"30216","181.26000","15.10517","0.10462"
"30254","181.48800","15.12412","0.10437"
"30292","181.71600","15.14314","0.10514"
"30330","181.94400","15.16215","0.10578"
"30368","182.17200","15.18116","0.10642"
"30406","182.40000","15.20017","0.10715"
"30444","182.62800","15.21919","0.10823"
"30482","182.85600","15.23814","0.10931"
"30520","183.08400","15.25715","0.10987"
"30558","183.31200","15.27611","0.11052"
"30596","183.54000","15.29518","0.11197"
"30634","183.76800","15.31407","0.11291"
"30672","183.99600","15.33321","0.11400"
"30710","184.22400","15.35216","0.11483"
"30748","184.45200","15.37117","0.11544"
"30786","184.68000","15.39018","0.11647"
"30824","184.90800","15.40914","0.11734"
"30862","185.13600","15.42821","0.11862"
"30900","185.36400","15.44716","0.12023"
"30938","185.59200","15.46618","0.12142"
"30976","185.82000","15.48519","0.12206"
"31014","186.04800","15.50414","0.12326"
"31052","186.27600","15.52322","0.12411"
"31090","186.50400","15.54211","0.12599"
"31128","186.73200","15.56124","0.12797"
"31166","186.96000","15.58014","0.12871"
"31204","187.18800","15.59915","0.13012"
"31242","187.41600","15.61822","0.13133"
"31280","187.64400","15.63711","0.13348"
"31318","187.87200","15.65619","0.13495"
"31356","188.10000","15.67514","0.13634"
"31394","188.32800","15.69415","0.13795"
"31432","188.55600","15.71317","0.13877"
"31470","188.78400","15.73212","0.14087"
"31508","189.01200","15.75119","0.14186"
"31546","189.24000","15.77009","0.14356"
"31584","189.46800","15.78916","0.14462"
"31622","189.69600","15.80817","0.14580"
"31660","189.92400","15.82719","0.14669"
"31698","190.15200","15.84614","0.14800"
"31736","190.38000","15.86515","0.14882"
"31774","190.60800","15.88422","0.14980"
"31812","190.83600","15.90312","0.15072"
"31850","191.06400","15.92219","0.15170"
"31888","191.29200","15.94114","0.15344"
"31926","191.52000","15.96016","0.15465"
"31964","191.74800","15.97917","0.15606"
"32002","191.97600","15.99813","0.15699"
"32040","192.20400","16.01720","0.15855"
"32078","192.43200","16.03615","0.15945"
"32116","192.66000","16.05516","0.16112"
"32154","192.88800","16.07424","0.16265"
"32192","193.11600","16.09313","0.10745"
"32230","193.34400","16.11220","0.10522"
"32268","193.57200","16.13110","0.10518"
"32306","193.80000","16.15017","0.10469"
"32344","194.02800","16.16912","0.10680"
"32382","194.25600","16.18819","0.10507"
"32420","194.48400","16.20721","0.10726"
"32458","194.71200","16.22610","0.10665"
"32496","194.94000","16.24524","0.10806"
"32534","195.16800","16.26413","0.10933"
"32572","195.39600","16.28320","0.10886"
"32610","195.62400","16.30215","0.11174"
"32648","195.85200","16.32111","0.11014"
"32686","196.08000","16.34018","0.11243"
"32724","196.30800","16.35913","0.11227"
"32762","196.53600","16.37815","0.11250"
"32800","196.76400","16.39710","0.11442"
"32838","196.99200","16.41617","0.11452"
"32876","197.22000","16.43513","0.11632"
"32914","197.44800","16.45414","0.11597"
"32952","197.67600","16.47321","0.11741"
"32990","197.90400","16.49211","0.11733"
"33028","198.13200","16.51118","0.11877"
"33066","198.36000","16.53019","0.11979"
"33104","198.58800","16.54920","0.12044"
"33142","198.81600","16.56816","0.12205"
"33180","199.04400","16.58711","0.12249"
"33218","199.27200","16.60612","0.12270"
"33256","199.50000","16.62514","0.12361"
"33294","199.72800","16.64415","0.12334"
"33332","199.95600","16.66316","0.12313"
"33370","200.18400","16.68218","0.12477"
"33408","200.41200","16.70113","0.12553"
"33446","200.64000","16.72020","0.12604"
"33484","200.86800","16.73922","0.12662"
"33522","201.09600","16.75811","0.12792"
"33560","201.32400","16.77718","0.12839"
"33598","201.55200","16.79613","0.12988"
"33636","201.78000","16.81521","0.13110"
"33674","202.00800","16.83416","0.13256"
"33712","202.23600","16.85317","0.13457"
"33750","202.46400","16.87219","0.13470"
"33788","202.69200","16.89114","0.13509"
"33826","202.92000","16.91021","0.13609"
"33864","203.14800","16.92917","0.13763"
"33902","203.37600","16.94818","0.13945"
"33940","203.60400","16.96713","0.14058"
"33978","203.83200","16.98615","0.14181"
"34016","204.06000","17.00522","0.14181"
"34054","204.28800","17.02405","0.14351"
"34092","204.51600","17.04319","0.14440"
"34130","204.74400","17.06214","0.14533"
"34168","204.97200","17.08115","0.14598"
"34206","205.20000","17.10022","0.14729"
"34244","205.42800","17.11918","0.14767"
"34282","205.65600","17.13819","0.14848"
"34320","205.88400","17.15709","0.14906"
"34358","206.11200","17.17616","0.14979"
"34396","206.34000","17.19517","0.15051"
"34434","206.56800","17.21412","0.15161"
"34472","206.79600","17.23320","0.15264"
"34510","207.02400","17.25209","0.15373"
"34548","207.25200","17.27122","0.15432"
"34586","207.48000","17.29018","0.15485"
"34624","207.70800","17.30919","0.15643"
"34662","207.93600","17.32814","0.15723"
"34700","208.16400","17.34715","0.15819"
"34738","208.39200","17.36617","0.15924"
"34776","208.62000","17.38506","0.16008"
"34814","208.84800","17.40420","0.16084"
"34852","209.07600","17.42309","0.16232"
"34890","209.30400","17.44216","0.16289"
"34928","209.53200","17.46124","0.16365"
"34966","209.76000","17.48013","0.16474"
"35004","209.98800","17.49920","0.16612"
"35042","210.21600","17.51815","0.16741"
"35080","210.44400","17.53723","0.16777"
"35118","210.67200","17.55612","0.16900"
"35156","210.90000","17.57519","0.16971"
"35194","211.12800","17.59421","0.17103"
"35232","211.35600","17.61310","0.17207"
"35270","211.58400","17.63223","0.17280"
"35308","211.81200","17.65112","0.17282"
"35346","212.04000","17.67020","0.17385"
"35384","212.26800","17.68921","0.17439"
"35422","212.49600","17.70817","0.17439"
"35460","212.72400","17.72718","0.17386"
"35498","212.95200","17.74613","0.17400"
"35536","213.18000","17.76520","0.17513"
"35574","213.40800","17.78416","0.17540"
"35612","213.63600","17.80317","0.17597"
"35650","213.86400","17.82218","0.17662"
"35688","214.09200","17.84114","0.17738"
"35726","214.32000","17.86021","0.17751"
"35764","214.54800","17.87910","0.17832"
"35802","214.77600","17.89818","0.17929"
"35840","215.00400","17.91713","0.18012"
"35878","215.23200","17.93620","0.18125"
"35916","215.46000","17.95522","0.18238"
"35954","215.68800","17.97417","0.18272"
"35992","215.91600","17.99318","0.18332"
"36030","216.14400","18.01219","0.18493"
"36068","216.37200","18.03115","0.18564"
"36106","216.60000","18.05016","0.18742"
"36144","216.82800","18.06911","0.18818"
"36182","217.05600","18.08813","0.18843"
"36220","217.28400","18.10714","0.18914"
"36258","217.51200","18.12615","0.19048"
"36296","217.74000","18.14517","0.19125"
"36334","217.96800","18.16418","0.19152"
"36372","218.19600","18.18319","0.19222"
"36410","218.42400","18.20215","0.13679"
"36448","218.65200","18.22122","0.13615"
"36486","218.88000","18.24017","0.13750"
"36524","219.10800","18.25918","0.13465"
"36562","219.33600","18.27808","0.13940"
"36600","219.56400","18.29721","0.13518"
"36638","219.79200","18.31616","0.13613"
"36676","220.02000","18.33518","0.13888"
"36714","220.24800","18.35419","0.13622"
"36752","220.47600","18.37309","0.14147"
"36790","220.70400","18.39222","0.13897"
"36828","220.93200","18.41117","0.13993"
"36866","221.16000","18.43024","0.14114"
"36904","221.38800","18.44914","0.13928"
"36942","221.61600","18.46815","0.14306"
"36980","221.84400","18.48722","0.14113"
"37018","222.07200","18.50611","0.14319"
"37056","222.30000","18.52519","0.14507"
"37094","222.52800","18.54414","0.14361"
"37132","222.75600","18.56315","0.14648"
"37170","222.98400","18.58217","0.14574"
"37208","223.21200","18.60112","0.14665"
"37246","223.44000","18.62020","0.14782"
"37284","223.66800","18.63915","0.14712"
"37322","223.89600","18.65822","0.14722"
"37360","224.12400","18.67717","0.14645"
"37398","224.35200","18.69613","0.14779"
"37436","224.58000","18.71514","0.14854"
"37474","224.80800","18.73409","0.14914"
"37512","225.03600","18.75317","0.15013"
"37550","225.26400","18.77212","0.14955"
"37588","225.49200","18.79119","0.15062"
"37626","225.72000","18.81015","0.15153"
"37664","225.94800","18.82916","0.15181"
"37702","226.17600","18.84817","0.15289"
"37740","226.40400","18.86719","0.15244"
"37778","226.63200","18.88620","0.15387"
"37816","226.86000","18.90509","0.15430"
"37854","227.08800","18.92416","0.15459"
"37892","227.31600","18.94318","0.15658"
"37930","227.54400","18.96219","0.15720"
"37968","227.77200","18.98114","0.15772"
"38006","228.00000","19.00010","0.15976"
"38044","228.22800","19.01917","0.15922"
"38082","228.45600","19.03818","0.16077"
"38120","228.68400","19.05720","0.16180"
"38158","228.91200","19.07621","0.16229"
"38196","229.14000","19.09510","0.16377"
"38234","229.36800","19.11418","0.16420"
"38272","229.59600","19.13313","0.16428"
"38310","229.82400","19.15220","0.16468"
"38348","230.05200","19.17109","0.16564"
"38386","230.28000","19.19011","0.16677"
"38424","230.50800","19.20924","0.16779"
"38462","230.73600","19.22813","0.16893"
"38500","230.96400","19.24721","0.16915"
"38538","231.19200","19.26610","0.16880"
"38576","231.42000","19.28511","0.16912"
"38614","231.64800","19.30419","0.17002"
"38652","231.87600","19.32314","0.17023"
"38690","232.10400","19.34221","0.17101"
"38728","232.33200","19.36111","0.17185"
"38766","232.56000","19.38018","0.17192"
"38804","232.78800","19.39913","0.17304"
"38842","233.01600","19.41821","0.17343"
"38880","233.24400","19.43716","0.17377"
"38918","233.47200","19.45617","0.17476"
"38956","233.70000","19.47518","0.17538"
"38994","233.92800","19.49414","0.17537"
"39032","234.15600","19.51321","0.17599"
"39070","234.38400","19.53210","0.17648"
"39108","234.61200","19.55118","0.17672"
"39146","234.84000","19.57013","0.17724"
"39184","235.06800","19.58920","0.17815"
"39222","235.29600","19.60822","0.17877"
"39260","235.52400","19.62711","0.17920"
"39298","235.75200","19.64618","0.17966"
"39336","235.98000","19.66514","0.18043"
"39374","236.20800","19.68421","0.18086"
"39412","236.43600","19.70316","0.18174"
"39450","236.66400","19.72217","0.18182"
"39488","236.89200","19.74119","0.18310"
"39526","237.12000","19.76008","0.18178"
"39564","237.34800","19.77915","0.18197"
"39602","237.57600","19.79817","0.18287"
"39640","237.80400","19.81718","0.18385"
"39678","238.03200","19.83614","0.18465"
"39716","238.26000","19.85521","0.18400"
"39754","238.48800","19.87416","0.18591"
"39792","238.71600","19.89311","0.18693"
"39830","238.94400","19.91219","0.18736"
"39868","239.17200","19.93114","0.18827"
"39906","239.40000","19.95015","0.18948"
"39944","239.62800","19.96917","0.18862"
"39982","239.85600","19.98806","0.18981"
"40020","240.08400","20.00719","0.19021"
"40058","240.31200","20.02615","0.19027"
"40096","240.54000","20.04522","0.19079"
"40134","240.76800","20.06417","0.19096"
"40172","240.99600","20.08319","0.18996"
"40210","241.22400","20.10220","0.19109"
"40248","241.45200","20.12115","0.19160"
"40286","241.68000","20.14016","0.19156"
"40324","241.90800","20.15918","0.19270"
"40362","242.13600","20.17819","0.19344"
"40400","242.36400","20.19714","0.19381"
"40438","242.59200","20.21610","0.19463"
"40476","242.82000","20.23517","0.19473"
"40514","243.04800","20.25412","0.19549"
"40552","243.27600","20.27320","0.19563"
"40590","243.50400","20.29215","0.19561"
"40628","243.73200","20.31116","0.19683"
"40666","243.96000","20.33018","0.19658"
"40704","244.18800","20.34913","0.19762"
"40742","244.41600","20.36820","0.19789"
"40780","244.64400","20.38709","0.19842"
"40818","244.87200","20.40623","0.19881"
"40856","245.10000","20.42512","0.19954"
"40894","245.32800","20.44413","0.20027"
"40932","245.55600","20.46321","0.20039"
"40970","245.78400","20.48210","0.20075"
"41008","246.01200","20.50123","0.20119"
"41046","246.24000","20.52013","0.20161"
"41084","246.46800","20.53920","0.20245"
"41122","246.69600","20.55815","0.20307"
"41160","246.92400","20.57716","0.20307"
"41198","247.15200","20.59618","0.20350"
"41236","247.38000","20.61507","0.20400"
"41274","247.60800","20.63414","0.20419"
"41312","247.83600","20.65316","0.20422"
"41350","248.06400","20.67217","0.20527"
"41388","248.29200","20.69118","0.20518"
"41426","248.52000","20.71014","0.20554"
"41464","248.74800","20.72921","0.20616"
"41502","248.97600","20.74810","0.20631"
"41540","249.20400","20.76717","0.20709"
"41578","249.43200","20.78619","0.20715"
"41616","249.66000","20.80520","0.20759"
"41654","249.88800","20.82422","0.20822"
"41692","250.11600","20.84311","0.20782"
"41730","250.34400","20.86218","0.20845"
"41768","250.57200","20.88107","0.20862"
"41806","250.80000","20.90021","0.20940"
"41844","251.02800","20.91916","0.20992"
"41882","251.25600","20.93817","0.20994"
"41920","251.48400","20.95713","0.21060"
"41958","251.71200","20.97614","0.21085"
"41996","251.94000","20.99516","0.21104"
"42034","252.16800","21.01410","0.21186"
"42072","252.39600","21.03318","0.21189"
"42110","252.62400","21.05213","0.21226"
"42148","252.85200","21.07121","0.21270"
"42186","253.08000","21.09022","0.21342"
"42224","253.30800","21.10917","0.21386"
"42262","253.53600","21.12813","0.21402"
"42300","253.76400","21.14714","0.21431"
"42338","253.99200","21.16621","0.21552"
"42376","254.22000","21.18522","0.21514"
"42414","254.44800","21.20412","0.01275"
"42452","254.67600","21.22325","0.01174"
"42490","254.90400","21.24209","0.00476"
"42528","255.13200","21.26116","-0.00202"
"42566","255.36000","21.28011","-0.00110"
"42604","255.58800","21.29918","0.00195"
"42642","255.81600","21.31814","0.00642"
"42680","256.04400","21.33715","0.00386"
"42718","256.27200","21.35622","0.00092"
"42756","256.50000","21.37506","0.00003"
"42794","256.72800","21.39419","0.00141"
"42832","256.95600","21.41308","0.00326"
"42870","257.18400","21.43216","0.00176"
"42908","257.41200","21.45117","0.00053"
"42946","257.64000","21.47012","0.00096"
"42984","257.86800","21.48913","0.00282"
"43022","258.09600","21.50815","0.00264"
"43060","258.32400","21.52716","0.00158"
"43098","258.55200","21.54618","0.00068"
"43136","258.78000","21.56519","0.00209"
"43174","259.00800","21.58414","0.00277"
"43212","259.23600","21.60315","0.00192"
"43250","259.46400","21.62223","0.00160"
"43288","259.69200","21.64112","0.00104"
"43326","259.92000","21.66019","0.00294"
"43364","260.14800","21.67914","0.00326"
"43402","260.37600","21.69816","0.00162"
"43440","260.60400","21.71717","0.00248"
"43478","260.83200","21.73613","0.00223"
"43516","261.06000","21.75520","0.00355"
"43554","261.28800","21.77409","0.00249"
"43592","261.51600","21.79323","0.00229"
"43630","261.74400","21.81218","0.00336"
"43668","261.97200","21.83119","0.00377"
"43706","262.20000","21.85014","0.00298"
"43744","262.42800","21.86910","0.00245"
"43782","262.65600","21.88817","0.00383"
"43820","262.88400","21.90713","0.00400"
"43858","263.11200","21.92620","0.00365"
"43896","263.34000","21.94521","0.00300"
"43934","263.56800","21.96411","0.00382"
"43972","263.79600","21.98324","0.00442"
"44010","264.02400","22.00213","0.00446"
"44048","264.25200","22.02120","0.00289"
"44086","264.48000","22.04009","0.00454"
"44124","264.70800","22.05917","0.00477"
"44162","264.93600","22.07824","0.00442"
"44200","265.16400","22.09707","0.00364"
"44238","265.39200","22.11615","0.00491"
"44276","265.62000","22.13510","0.00580"
"44314","265.84800","22.15417","0.00489"
"44352","266.07600","22.17319","0.00501"
"44390","266.30400","22.19214","0.00008"
"44428","266.53200","22.21121","0.00060"
"44466","266.76000","22.23011","-0.00002"
"44504","266.98800","22.24918","0.00007"
"44542","267.21600","22.26819","0.00037"
"44580","267.44400","22.28720","0.00020"
"44618","267.67200","22.30616","-0.00009"
"44656","267.90000","22.32511","-0.00020"
"44694","268.12800","22.34419","-0.00017"
"44732","268.35600","22.36314","0.00009"
"44770","268.58400","22.38215","0.00003"
"44808","268.81200","22.40110","-0.00019"
"44846","269.04000","22.42018","-0.00011"
"44884","269.26800","22.43919","-0.00031"
"44922","269.49600","22.45815","-0.00008"
"44960","269.72400","22.47722","0.00043"
"44998","269.95200","22.49611","0.00009"
"45036","270.18000","22.51518","-0.00023"
"45074","270.40800","22.53414","0.00053"
"45112","270.63600","22.55321","-0.00008"
"45150","270.86400","22.57210","0.00011"
"45188","271.09200","22.59112","-0.00031"
"45226","271.32000","22.61019","0.00006"
"45264","271.54800","22.62914","0.00000"
"45302","271.77600","22.64822","0.00000"
"45340","272.00400","22.66717","0.00019"
"45378","272.23200","22.68618","-0.00002"
"45416","272.46000","22.70513","-0.00023"
"45454","272.68800","22.72415","0.00030"
"45492","272.91600","22.74316","0.00025"
"45530","273.14400","22.76211","-0.00007"
"45568","273.37200","22.78119","-0.00002"
"45606","273.60000","22.80014","-0.00020"
"45644","273.82800","22.81915","0.00021"
"45682","274.05600","22.83817","0.00051"
"45720","274.28400","22.85712","-0.00015"
"45758","274.51200","22.87619","0.00039"
"45796","274.74000","22.89515","0.00054"
"45834","274.96800","22.91416","0.00053"
"45872","275.19600","22.93317","0.00041"
"45910","275.42400","22.95213","-0.00030"
"45948","275.65200","22.97120","0.00018"
"45986","275.88000","22.99009","0.00038"
"46024","276.10800","23.00923","0.00034"
"46062","276.33600","23.02812","0.00053"
"46100","276.56400","23.04719","0.00025"
"46138","276.79200","23.06614","0.00024"
"46176","277.02000","23.08516","0.00049"
"46214","277.24800","23.10417","0.00015"
"46252","277.47600","23.12318","0.00046"
"46290","277.70400","23.14220","0.00032"
"46328","277.93200","23.16115","0.00040"
"46366","278.16000","23.18016","0.00011"
"46404","278.38800","23.19917","0.00045"
"46442","278.61600","23.21813","0.00037"
"46480","278.84400","23.23714","0.00024"
"46518","279.07200","23.25616","0.00088"
"46556","279.30000","23.27523","0.00043"
"46594","279.52800","23.29412","0.00015"
"46632","279.75600","23.31314","0.00026"
"46670","279.98400","23.33221","0.00027"
"46708","280.21200","23.35110","0.00061"
"46746","280.44000","23.37012","0.00033"
"46784","280.66800","23.38913","0.00075"
"46822","280.89600","23.40820","0.00056"
"46860","281.12400","23.42721","0.00017"
"46898","281.35200","23.44611","0.00012"
"46936","281.58000","23.46524","0.00033"
"46974","281.80800","23.48413","0.00054"
"47012","282.03600","23.50321","0.00059"
"47050","282.26400","23.52216","0.00045"
"47088","282.49200","23.54123","0.00031"
"47126","282.72000","23.56012","0.00030"
"47164","282.94800","23.57920","0.00057"
"47202","283.17600","23.59815","0.00050"
"47240","283.40400","23.61710","0.00097"
"47278","283.62800","23.63576","0.00065"