File: Trajectories_together/161226_2Specimen_RawData_7.csv
"","V1","V2","V3"
"1","End date","12/26/2016",""
"2","Specimen label","14CG_12",""
"3","Maximum Load","0.33605","N"
"4","Time","Extension","Load"
"5","(s)","(mm)","(N)"
"6","0.00000","0.00000","-0.00020"
"68","0.37200","0.03115","0.00052"
"130","0.74400","0.06218","0.00062"
"192","1.11600","0.09315","0.00160"
"254","1.48800","0.12418","0.00172"
"316","1.86000","0.15515","0.00126"
"378","2.23200","0.18607","0.00183"
"440","2.60400","0.21716","0.00216"
"502","2.97600","0.24813","0.00205"
"564","3.34800","0.27910","0.00211"
"626","3.72000","0.31013","0.00304"
"688","4.09200","0.34116","0.00277"
"750","4.46400","0.37207","0.00282"
"812","4.83600","0.40310","0.00321"
"874","5.20800","0.43413","0.00316"
"936","5.58000","0.46516","0.00375"
"998","5.95200","0.49607","0.00342"
"1060","6.32400","0.52710","0.00395"
"1122","6.69600","0.55814","0.00387"
"1184","7.06800","0.58911","0.00476"
"1246","7.44000","0.62014","0.00422"
"1308","7.81200","0.65117","0.00435"
"1370","8.18400","0.68208","0.00488"
"1432","8.55600","0.71305","0.00454"
"1494","8.92800","0.74414","0.00449"
"1556","9.30000","0.77511","0.00464"
"1618","9.67200","0.80608","0.00496"
"1680","10.04400","0.83717","0.00513"
"1742","10.41600","0.86808","0.00521"
"1804","10.78800","0.89906","0.00550"
"1866","11.16000","0.93009","0.00565"
"1928","11.53200","0.96112","0.00580"
"1990","11.90400","0.99209","0.00604"
"2052","12.27600","1.02318","0.00576"
"2114","12.64800","1.05415","0.00639"
"2176","13.02000","1.08500","0.00577"
"2238","13.39200","1.11609","0.00564"
"2300","13.76400","1.14718","0.00615"
"2362","14.13600","1.17809","0.00624"
"2424","14.50800","1.20912","0.00617"
"2486","14.88000","1.24009","0.00633"
"2548","15.25200","1.27113","0.00648"
"2610","15.62400","1.30210","0.00658"
"2672","15.99600","1.33319","0.00661"
"2734","16.36800","1.36416","0.00617"
"2796","16.74000","1.39507","0.00672"
"2858","17.11200","1.42610","0.00673"
"2920","17.48400","1.45713","0.00721"
"2982","17.85600","1.48804","0.00693"
"3044","18.22800","1.51913","0.00718"
"3106","18.60000","1.55010","0.00784"
"3168","18.97200","1.58107","0.00727"
"3230","19.34400","1.61211","0.00726"
"3292","19.71600","1.64314","0.00740"
"3354","20.08800","1.67411","0.00836"
"3416","20.46000","1.70508","0.00775"
"3478","20.83200","1.73617","0.00772"
"3540","21.20400","1.76708","0.00808"
"3602","21.57600","1.79805","0.00830"
"3664","21.94800","1.82914","0.00834"
"3726","22.32000","1.86011","0.00840"
"3788","22.69200","1.89108","0.00803"
"3850","23.06400","1.92211","0.00803"
"3912","23.43600","1.95314","0.00817"
"3974","23.80800","1.98406","0.00835"
"4036","24.18000","2.01509","0.00858"
"4098","24.55200","2.04618","0.00821"
"4160","24.92400","2.07709","0.00835"
"4222","25.29600","2.10812","0.00836"
"4284","25.66800","2.13915","0.00882"
"4346","26.04000","2.17012","0.00829"
"4408","26.41200","2.20109","0.00841"
"4470","26.78400","2.23212","0.00862"
"4532","27.15600","2.26309","0.00829"
"4594","27.52800","2.29406","0.00875"
"4656","27.90000","2.32510","0.00902"
"4718","28.27200","2.35619","0.00885"
"4780","28.64400","2.38704","0.00868"
"4842","29.01600","2.41819","0.00897"
"4904","29.38800","2.44910","0.00901"
"4966","29.76000","2.48007","0.00902"
"5028","30.13200","2.51116","0.00944"
"5090","30.50400","2.54213","0.00912"
"5152","30.87600","2.57310","0.00980"
"5214","31.24800","2.60407","0.00948"
"5276","31.62000","2.63516","0.00944"
"5338","31.99200","2.66619","0.00965"
"5400","32.36400","2.69705","0.00980"
"5462","32.73600","2.72814","0.00976"
"5524","33.10800","2.75917","0.00947"
"5586","33.48000","2.79002","0.00976"
"5648","33.85200","2.82111","0.00953"
"5710","34.22400","2.85214","0.01009"
"5772","34.59600","2.88311","0.00998"
"5834","34.96800","2.91408","0.00952"
"5896","35.34000","2.94511","0.00995"
"5958","35.71200","2.97608","0.01011"
"6020","36.08400","3.00711","0.01031"
"6082","36.45600","3.03815","0.01030"
"6144","36.82800","3.06912","0.01006"
"6206","37.20000","3.10009","0.00961"
"6268","37.57200","3.13118","0.01062"
"6330","37.94400","3.16215","0.01030"
"6392","38.31600","3.19312","0.01017"
"6454","38.68800","3.22409","0.01072"
"6516","39.06000","3.25512","0.01083"
"6578","39.43200","3.28609","0.01003"
"6640","39.80400","3.31706","0.01064"
"6702","40.17600","3.34809","0.01032"
"6764","40.54800","3.37912","0.01035"
"6826","40.92000","3.41010","0.01029"
"6888","41.29200","3.44113","0.01103"
"6950","41.66400","3.47216","0.01063"
"7012","42.03600","3.50313","0.01127"
"7074","42.40800","3.53410","0.01050"
"7136","42.78000","3.56513","0.01101"
"7198","43.15200","3.59610","0.01062"
"7260","43.52400","3.62713","0.01052"
"7322","43.89600","3.65810","0.01150"
"7384","44.26800","3.68907","0.01071"
"7446","44.64000","3.72010","0.01103"
"7508","45.01200","3.75108","0.01068"
"7570","45.38400","3.78211","0.01114"
"7632","45.75600","3.81308","0.01096"
"7694","46.12800","3.84411","0.01119"
"7756","46.50000","3.87514","0.01119"
"7818","46.87200","3.90605","0.01123"
"7880","47.24400","3.93708","0.01154"
"7942","47.61600","3.96811","0.01168"
"8004","47.98800","3.99908","0.01133"
"8066","48.36000","4.03011","0.01116"
"8128","48.73200","4.06114","0.01168"
"8190","49.10400","4.09211","0.01190"
"8252","49.47600","4.12309","0.01171"
"8314","49.84800","4.15412","0.01161"
"8376","50.22000","4.18515","0.01177"
"8438","50.59200","4.21606","0.01211"
"8500","50.96400","4.24715","0.01142"
"8562","51.33600","4.27806","0.01163"
"8624","51.70800","4.30909","0.01162"
"8686","52.08000","4.34012","0.01193"
"8748","52.45200","4.37109","0.01172"
"8810","52.82400","4.40212","0.01141"
"8872","53.19600","4.43315","0.01183"
"8934","53.56800","4.46413","0.01198"
"8996","53.94000","4.49510","0.01201"
"9058","54.31200","4.52607","0.01216"
"9120","54.68400","4.55716","0.01223"
"9182","55.05600","4.58807","0.01189"
"9244","55.42800","4.61910","0.01222"
"9306","55.80000","4.65013","0.01181"
"9368","56.17200","4.68110","0.01222"
"9430","56.54400","4.71213","0.01202"
"9492","56.91600","4.74310","0.01213"
"9554","57.28800","4.77413","0.01201"
"9616","57.66000","4.80505","0.01257"
"9678","58.03200","4.83608","0.01224"
"9740","58.40400","4.86717","0.01280"
"9802","58.77600","4.89808","0.01246"
"9864","59.14800","4.92911","0.01217"
"9926","59.52000","4.96014","0.01246"
"9988","59.89200","4.99111","0.01200"
"10050","60.26400","5.02214","0.01280"
"10112","60.63600","5.05317","0.01229"
"10174","61.00800","5.08408","0.01219"
"10236","61.38000","5.11511","0.01300"
"10298","61.75200","5.14614","0.01224"
"10360","62.12400","5.17712","0.01275"
"10422","62.49600","5.20803","0.01244"
"10484","62.86800","5.23918","0.01299"
"10546","63.24000","5.27015","0.01253"
"10608","63.61200","5.30106","0.01281"
"10670","63.98400","5.33209","0.01254"
"10732","64.35600","5.36312","0.01305"
"10794","64.72800","5.39415","0.01265"
"10856","65.10000","5.42506","0.01244"
"10918","65.47200","5.45609","0.01313"
"10980","65.84400","5.48718","0.01268"
"11042","66.21600","5.51810","0.01311"
"11104","66.58800","5.54919","0.01280"
"11166","66.96000","5.58010","0.01223"
"11228","67.33200","5.61107","0.01287"
"11290","67.70400","5.64216","0.01303"
"11352","68.07600","5.67313","0.01315"
"11414","68.44800","5.70410","0.01356"
"11476","68.82000","5.73513","0.01369"
"11538","69.19200","5.76610","0.01355"
"11600","69.56400","5.79707","0.01312"
"11662","69.93600","5.82810","0.01371"
"11724","70.30800","5.85920","0.01344"
"11786","70.68000","5.89011","0.01343"
"11848","71.05200","5.92108","0.01348"
"11910","71.42400","5.95211","0.01329"
"11972","71.79600","5.98314","0.01388"
"12034","72.16800","6.01411","0.01370"
"12096","72.54000","6.04514","0.01337"
"12158","72.91200","6.07617","0.01358"
"12220","73.28400","6.10702","0.01351"
"12282","73.65600","6.13811","0.01345"
"12344","74.02800","6.16914","0.01333"
"12406","74.40000","6.20005","0.01368"
"12468","74.77200","6.23109","0.01391"
"12530","75.14400","6.26212","0.01352"
"12592","75.51600","6.29315","0.01357"
"12654","75.88800","6.32412","0.01341"
"12716","76.26000","6.35515","0.01358"
"12778","76.63200","6.38612","0.01387"
"12840","77.00400","6.41709","0.01368"
"12902","77.37600","6.44812","0.01410"
"12964","77.74800","6.47909","0.01345"
"13026","78.12000","6.51000","0.01405"
"13088","78.49200","6.54115","0.01389"
"13150","78.86400","6.57212","0.01382"
"13212","79.23600","6.60310","0.01399"
"13274","79.60800","6.63407","0.01425"
"13336","79.98000","6.66510","0.01406"
"13398","80.35200","6.69607","0.01394"
"13460","80.72400","6.72710","0.01419"
"13522","81.09600","6.75813","0.01435"
"13584","81.46800","6.78910","0.01421"
"13646","81.84000","6.82007","0.01416"
"13708","82.21200","6.85116","0.01426"
"13770","82.58400","6.88207","0.01412"
"13832","82.95600","6.91311","0.01410"
"13894","83.32800","6.94414","0.01425"
"13956","83.70000","6.97517","0.01429"
"14018","84.07200","7.00608","0.01437"
"14080","84.44400","7.03711","0.01433"
"14142","84.81600","7.06814","0.01404"
"14204","85.18800","7.09905","0.01475"
"14266","85.56000","7.13008","0.01469"
"14328","85.93200","7.16111","0.01493"
"14390","86.30400","7.19208","0.01451"
"14452","86.67600","7.22311","0.01422"
"14514","87.04800","7.25415","0.01483"
"14576","87.42000","7.28518","0.01468"
"14638","87.79200","7.31603","0.01478"
"14700","88.16400","7.34712","0.01500"
"14762","88.53600","7.37821","0.01499"
"14824","88.90800","7.40906","0.01494"
"14886","89.28000","7.44015","0.01496"
"14948","89.65200","7.47112","0.01517"
"15010","90.02400","7.50209","0.01491"
"15072","90.39600","7.53312","0.01546"
"15134","90.76800","7.56409","0.01503"
"15196","91.14000","7.59507","0.01494"
"15258","91.51200","7.62610","0.01533"
"15320","91.88400","7.65719","0.01514"
"15382","92.25600","7.68816","0.01486"
"15444","92.62800","7.71907","0.01497"
"15506","93.00000","7.75016","0.01518"
"15568","93.37200","7.78113","0.01535"
"15630","93.74400","7.81210","0.01547"
"15692","94.11600","7.84313","0.01558"
"15754","94.48800","7.87416","0.01542"
"15816","94.86000","7.90513","0.01546"
"15878","95.23200","7.93604","0.01553"
"15940","95.60400","7.96707","0.01544"
"16002","95.97600","7.99805","0.01566"
"16064","96.34800","8.02908","0.01556"
"16126","96.72000","8.06017","0.01553"
"16188","97.09200","8.09114","0.01540"
"16250","97.46400","8.12211","0.01538"
"16312","97.83600","8.15308","0.01543"
"16374","98.20800","8.18417","0.01559"
"16436","98.58000","8.21514","0.01548"
"16498","98.95200","8.24605","0.01558"
"16560","99.32400","8.27708","0.01565"
"16622","99.69600","8.30805","0.01571"
"16684","100.06800","8.33909","0.01552"
"16746","100.44000","8.37012","0.01535"
"16808","100.81200","8.40109","0.01541"
"16870","101.18400","8.43212","0.01558"
"16932","101.55600","8.46315","0.01583"
"16994","101.92800","8.49412","0.01551"
"17056","102.30000","8.52509","0.01601"
"17118","102.67200","8.55612","0.01569"
"17180","103.04400","8.58715","0.01562"
"17242","103.41600","8.61806","0.01557"
"17304","103.78800","8.64915","0.01550"
"17366","104.16000","8.68018","0.01563"
"17428","104.53200","8.71110","0.01578"
"17490","104.90400","8.74213","0.01570"
"17552","105.27600","8.77310","0.01523"
"17614","105.64800","8.80407","0.01591"
"17676","106.02000","8.83510","0.01564"
"17738","106.39200","8.86607","0.01561"
"17800","106.76400","8.89710","0.01562"
"17862","107.13600","8.92807","0.01591"
"17924","107.50800","8.95910","0.01545"
"17986","107.88000","8.99013","0.01576"
"18048","108.25200","9.02110","0.01581"
"18110","108.62400","9.05214","0.01567"
"18172","108.99600","9.08317","0.01585"
"18234","109.36800","9.11414","0.01562"
"18296","109.74000","9.14511","0.01537"
"18358","110.11200","9.17614","0.01556"
"18420","110.48400","9.20711","0.01551"
"18482","110.85600","9.23808","0.01545"
"18544","111.22800","9.26917","0.01566"
"18606","111.60000","9.30008","0.01527"
"18668","111.97200","9.33105","0.01532"
"18730","112.34400","9.36214","0.01482"
"18792","112.71600","9.39312","0.01477"
"18854","113.08800","9.42409","0.01501"
"18916","113.46000","9.45512","0.01412"
"18978","113.83200","9.48609","0.01486"
"19040","114.20400","9.51706","0.01476"
"19102","114.57600","9.54809","0.01494"
"19164","114.94800","9.57918","0.01447"
"19226","115.32000","9.61009","0.01466"
"19288","115.69200","9.64112","0.01417"
"19350","116.06400","9.67209","0.01456"
"19412","116.43600","9.70312","0.01465"
"19474","116.80800","9.73409","0.01456"
"19536","117.18000","9.76507","0.01463"
"19598","117.55200","9.79616","0.01463"
"19660","117.92400","9.82707","0.01462"
"19722","118.29600","9.85810","0.01442"
"19784","118.66800","9.88919","0.01505"
"19846","119.04000","9.92004","0.01488"
"19908","119.41200","9.95119","0.01493"
"19970","119.78400","9.98216","0.01476"
"20032","120.15600","10.01307","0.01497"
"20094","120.52800","10.04410","0.01452"
"20156","120.90000","10.07513","0.01442"
"20218","121.27200","10.10611","0.01477"
"20280","121.64400","10.13714","0.01504"
"20342","122.01600","10.16817","0.01478"
"20404","122.38800","10.19914","0.01470"
"20466","122.76000","10.23005","0.01468"
"20528","123.13200","10.26114","0.01479"
"20590","123.50400","10.29211","0.01469"
"20652","123.87600","10.32308","0.01486"
"20714","124.24800","10.35411","0.01454"
"20776","124.62000","10.38514","0.01461"
"20838","124.99200","10.41611","0.01504"
"20900","125.36400","10.44708","0.01468"
"20962","125.73600","10.47812","0.01486"
"21024","126.10800","10.50915","0.01511"
"21086","126.48000","10.54006","0.01505"
"21148","126.85200","10.57115","0.01507"
"21210","127.22400","10.60212","0.01497"
"21272","127.59600","10.63303","0.01507"
"21334","127.96800","10.66412","0.01537"
"21396","128.34000","10.69515","0.01533"
"21458","128.71200","10.72612","0.01525"
"21520","129.08400","10.75709","0.01531"
"21582","129.45600","10.78813","0.01520"
"21644","129.82800","10.81904","0.01527"
"21706","130.20000","10.85013","0.01513"
"21768","130.57200","10.88116","0.01518"
"21830","130.94400","10.91207","0.01551"
"21892","131.31600","10.94310","0.01528"
"21954","131.68800","10.97413","0.01532"
"22016","132.06000","11.00510","0.01538"
"22078","132.43200","11.03613","0.01516"
"22140","132.80400","11.06716","0.01523"
"22202","133.17600","11.09813","0.01489"
"22264","133.54800","11.12904","0.01560"
"22326","133.92000","11.16008","0.01539"
"22388","134.29200","11.19116","0.01560"
"22450","134.66400","11.22208","0.01544"
"22512","135.03600","11.25311","0.01552"
"22574","135.40800","11.28414","0.01560"
"22636","135.78000","11.31511","0.01518"
"22698","136.15200","11.34608","0.01551"
"22760","136.52400","11.37717","0.01583"
"22822","136.89600","11.40814","0.01563"
"22884","137.26800","11.43911","0.01572"
"22946","137.64000","11.47014","0.01548"
"23008","138.01200","11.50111","0.01549"
"23070","138.38400","11.53209","0.01542"
"23132","138.75600","11.56318","0.01566"
"23194","139.12800","11.59409","0.01553"
"23256","139.50000","11.62512","0.01544"
"23318","139.87200","11.65609","0.01521"
"23380","140.24400","11.68712","0.01542"
"23442","140.61600","11.71809","0.01551"
"23504","140.98800","11.74912","0.01514"
"23566","141.36000","11.78009","0.01564"
"23628","141.73200","11.81112","0.01568"
"23690","142.10400","11.84209","0.01581"
"23752","142.47600","11.87312","0.01558"
"23814","142.84800","11.90410","0.01550"
"23876","143.22000","11.93507","0.01569"
"23938","143.59200","11.96610","0.01571"
"24000","143.96400","11.99713","0.01555"
"24062","144.33600","12.02810","0.01585"
"24124","144.70800","12.05913","0.01548"
"24186","145.08000","12.09016","0.01555"
"24248","145.45200","12.12107","0.01574"
"24310","145.82400","12.15210","0.01562"
"24372","146.19600","12.18313","0.01588"
"24434","146.56800","12.21404","0.01618"
"24496","146.94000","12.24508","0.01599"
"24558","147.31200","12.27617","0.01601"
"24620","147.68400","12.30714","0.01606"
"24682","148.05600","12.33811","0.01619"
"24744","148.42800","12.36914","0.01614"
"24806","148.80000","12.40011","0.01566"
"24868","149.17200","12.43108","0.01608"
"24930","149.54400","12.46211","0.01592"
"24992","149.91600","12.49314","0.01569"
"25054","150.28800","12.52405","0.01609"
"25116","150.66000","12.55509","0.01607"
"25178","151.03200","12.58612","0.01589"
"25240","151.40400","12.61715","0.01595"
"25302","151.77600","12.64806","0.01601"
"25364","152.14800","12.67915","0.01635"
"25426","152.52000","12.71012","0.01626"
"25488","152.89200","12.74109","0.01626"
"25550","153.26400","12.77218","0.01613"
"25612","153.63600","12.80315","0.01574"
"25674","154.00800","12.83406","0.01610"
"25736","154.38000","12.86509","0.01622"
"25798","154.75200","12.89612","0.01611"
"25860","155.12400","12.92715","0.01588"
"25922","155.49600","12.95807","0.01622"
"25984","155.86800","12.98916","0.01610"
"26046","156.24000","13.02013","0.01571"
"26108","156.61200","13.05110","0.01607"
"26170","156.98400","13.08219","0.01612"
"26232","157.35600","13.11310","0.01635"
"26294","157.72800","13.14413","0.01603"
"26356","158.10000","13.17516","0.01627"
"26418","158.47200","13.20613","0.01615"
"26480","158.84400","13.23710","0.01626"
"26542","159.21600","13.26807","0.01612"
"26604","159.58800","13.29917","0.01674"
"26666","159.96000","13.33008","0.01659"
"26728","160.33200","13.36111","0.01649"
"26790","160.70400","13.39214","0.01637"
"26852","161.07600","13.42311","0.01643"
"26914","161.44800","13.45408","0.01642"
"26976","161.82000","13.48517","0.01680"
"27038","162.19200","13.51614","0.01627"
"27100","162.56400","13.54705","0.01684"
"27162","162.93600","13.57814","0.01680"
"27224","163.30800","13.60917","0.01687"
"27286","163.68000","13.64003","0.01669"
"27348","164.05200","13.67112","0.01705"
"27410","164.42400","13.70215","0.01655"
"27472","164.79600","13.73306","0.01664"
"27534","165.16800","13.76415","0.01656"
"27596","165.54000","13.79512","0.01629"
"27658","165.91200","13.82609","0.01638"
"27720","166.28400","13.85712","0.01648"
"27782","166.65600","13.88815","0.01659"
"27844","167.02800","13.91912","0.01627"
"27906","167.40000","13.95009","0.01657"
"27968","167.77200","13.98112","0.01559"
"28030","168.14400","14.01210","0.01581"
"28092","168.51600","14.04307","0.01589"
"28154","168.88800","14.07416","0.01564"
"28216","169.26000","14.10513","0.01618"
"28278","169.63200","14.13610","0.01616"
"28340","170.00400","14.16713","0.01571"
"28402","170.37600","14.19816","0.01586"
"28464","170.74800","14.22913","0.01623"
"28526","171.12000","14.26010","0.01637"
"28588","171.49200","14.29119","0.01634"
"28650","171.86400","14.32205","0.01658"
"28712","172.23600","14.35302","0.01670"
"28774","172.60800","14.38417","0.01659"
"28836","172.98000","14.41514","0.01645"
"28898","173.35200","14.44611","0.01700"
"28960","173.72400","14.47714","0.01681"
"29022","174.09600","14.50811","0.01688"
"29084","174.46800","14.53908","0.01530"
"29146","174.84000","14.57011","0.01565"
"29208","175.21200","14.60114","0.01596"
"29270","175.58400","14.63205","0.01621"
"29332","175.95600","14.66314","0.01633"
"29394","176.32800","14.69411","0.01658"
"29456","176.70000","14.72509","0.01639"
"29518","177.07200","14.75606","0.01629"
"29580","177.44400","14.78715","0.01640"
"29642","177.81600","14.81812","0.01670"
"29704","178.18800","14.84909","0.01647"
"29766","178.56000","14.88006","0.01702"
"29828","178.93200","14.91115","0.01697"
"29890","179.30400","14.94206","0.01669"
"29952","179.67600","14.97315","0.01704"
"30014","180.04800","15.00412","0.01690"
"30076","180.42000","15.03509","0.01745"
"30138","180.79200","15.06613","0.01722"
"30200","181.16400","15.09716","0.01692"
"30262","181.53600","15.12813","0.01739"
"30324","181.90800","15.15910","0.01728"
"30386","182.28000","15.19019","0.01723"
"30448","182.65200","15.22110","0.01765"
"30510","183.02400","15.25201","0.01772"
"30572","183.39600","15.28316","0.01787"
"30634","183.76800","15.31413","0.01798"
"30696","184.14000","15.34504","0.01768"
"30758","184.51200","15.37613","0.01846"
"30820","184.88400","15.40717","0.01780"
"30882","185.25600","15.43808","0.01821"
"30944","185.62800","15.46905","0.01825"
"31006","186.00000","15.50014","0.01804"
"31068","186.37200","15.53111","0.01845"
"31130","186.74400","15.56208","0.01860"
"31192","187.11600","15.59311","0.01844"
"31254","187.48800","15.62408","0.01863"
"31316","187.86000","15.65511","0.01875"
"31378","188.23200","15.68614","0.01875"
"31440","188.60400","15.71717","0.01905"
"31502","188.97600","15.74808","0.01866"
"31564","189.34800","15.77912","0.01898"
"31626","189.72000","15.81015","0.01916"
"31688","190.09200","15.84112","0.01910"
"31750","190.46400","15.87209","0.01902"
"31812","190.83600","15.90318","0.01878"
"31874","191.20800","15.93409","0.01963"
"31936","191.58000","15.96512","0.01964"
"31998","191.95200","15.99609","0.01987"
"32060","192.32400","16.02712","0.01959"
"32122","192.69600","16.05809","0.02005"
"32184","193.06800","16.08912","0.01995"
"32246","193.44000","16.12016","0.02009"
"32308","193.81200","16.15100","0.02007"
"32370","194.18400","16.18210","0.01997"
"32432","194.55600","16.21313","0.02028"
"32494","194.92800","16.24404","0.02027"
"32556","195.30000","16.27513","0.01988"
"32618","195.67200","16.30610","0.01955"
"32680","196.04400","16.33707","0.01989"
"32742","196.41600","16.36810","0.01973"
"32804","196.78800","16.39913","0.02016"
"32866","197.16000","16.43016","0.02054"
"32928","197.53200","16.46107","0.02032"
"32990","197.90400","16.49211","0.02081"
"33052","198.27600","16.52314","0.02089"
"33114","198.64800","16.55411","0.02128"
"33176","199.02000","16.58514","0.02111"
"33238","199.39200","16.61611","0.02172"
"33300","199.76400","16.64708","0.02166"
"33362","200.13600","16.67811","0.02212"
"33424","200.50800","16.70908","0.02223"
"33486","200.88000","16.74011","0.02257"
"33548","201.25200","16.77108","0.02261"
"33610","201.62400","16.80217","0.02297"
"33672","201.99600","16.83309","0.02286"
"33734","202.36800","16.86406","0.02312"
"33796","202.74000","16.89515","0.02352"
"33858","203.11200","16.92612","0.02385"
"33920","203.48400","16.95709","0.02397"
"33982","203.85600","16.98812","0.02481"
"34044","204.22800","17.01915","0.02506"
"34106","204.60000","17.05006","0.02529"
"34168","204.97200","17.08109","0.02584"
"34230","205.34400","17.11212","0.02613"
"34292","205.71600","17.14309","0.02756"
"34354","206.08800","17.17413","0.02820"
"34416","206.46000","17.20515","0.02881"
"34478","206.83200","17.23607","0.02998"
"34540","207.20400","17.26710","0.03050"
"34602","207.57600","17.29813","0.03121"
"34664","207.94800","17.32916","0.03192"
"34726","208.32000","17.36007","0.03333"
"34788","208.69200","17.39110","0.03437"
"34850","209.06400","17.42213","0.03537"
"34912","209.43600","17.45310","0.03565"
"34974","209.80800","17.48413","0.03716"
"35036","210.18000","17.51510","0.03828"
"35098","210.55200","17.54608","0.03947"
"35160","210.92400","17.57711","0.04117"
"35222","211.29600","17.60814","0.04278"
"35284","211.66800","17.63911","0.04451"
"35346","212.04000","17.67008","0.04666"
"35408","212.41200","17.70111","0.04752"
"35470","212.78400","17.73214","0.04820"
"35532","213.15600","17.76311","0.04979"
"35594","213.52800","17.79414","0.05086"
"35656","213.90000","17.82517","0.05324"
"35718","214.27200","17.85608","0.05334"
"35780","214.64400","17.88712","0.05490"
"35842","215.01600","17.91809","0.05640"
"35904","215.38800","17.94912","0.05707"
"35966","215.76000","17.98009","0.05872"
"36028","216.13200","18.01112","0.06000"
"36090","216.50400","18.04209","0.06139"
"36152","216.87600","18.07312","0.06241"
"36214","217.24800","18.10415","0.06403"
"36276","217.62000","18.13512","0.06530"
"36338","217.99200","18.16609","0.06715"
"36400","218.36400","18.19712","0.06808"
"36462","218.73600","18.22816","0.07035"
"36524","219.10800","18.25912","0.07154"
"36586","219.48000","18.29004","0.07347"
"36648","219.85200","18.32119","0.07494"
"36710","220.22400","18.35210","0.07689"
"36772","220.59600","18.38307","0.07903"
"36834","220.96800","18.41416","0.08113"
"36896","221.34000","18.44513","0.08405"
"36958","221.71200","18.47610","0.08582"
"37020","222.08400","18.50713","0.08804"
"37082","222.45600","18.53811","0.08670"
"37144","222.82800","18.56907","0.08859"
"37206","223.20000","18.60011","0.09241"
"37268","223.57200","18.63114","0.09416"
"37330","223.94400","18.66205","0.09584"
"37392","224.31600","18.69314","0.09713"
"37454","224.68800","18.72411","0.09936"
"37516","225.06000","18.75508","0.10105"
"37578","225.43200","18.78611","0.10250"
"37640","225.80400","18.81708","0.10368"
"37702","226.17600","18.84811","0.10471"
"37764","226.54800","18.87908","0.10537"
"37826","226.92000","18.91011","0.10709"
"37888","227.29200","18.94114","0.10766"
"37950","227.66400","18.97206","0.10875"
"38012","228.03600","19.00309","0.10935"
"38074","228.40800","19.03412","0.11052"
"38136","228.78000","19.06509","0.11140"
"38198","229.15200","19.09618","0.11292"
"38260","229.52400","19.12715","0.11429"
"38322","229.89600","19.15812","0.11612"
"38384","230.26800","19.18909","0.11712"
"38446","230.64000","19.22018","0.11920"
"38508","231.01200","19.25109","0.12128"
"38570","231.38400","19.28206","0.12412"
"38632","231.75600","19.31315","0.12681"
"38694","232.12800","19.34413","0.12963"
"38756","232.50000","19.37510","0.13297"
"38818","232.87200","19.40619","0.13731"
"38880","233.24400","19.43710","0.14068"
"38942","233.61600","19.46807","0.14514"
"39004","233.98800","19.49916","0.14935"
"39066","234.36000","19.53013","0.15300"
"39128","234.73200","19.56104","0.15607"
"39190","235.10400","19.59213","0.15935"
"39252","235.47600","19.62316","0.16219"
"39314","235.84800","19.65408","0.16357"
"39376","236.22000","19.68511","0.16629"
"39438","236.59200","19.71608","0.16838"
"39500","236.96400","19.74711","0.17105"
"39562","237.33600","19.77814","0.17236"
"39624","237.70800","19.80911","0.17444"
"39686","238.08000","19.84014","0.17608"
"39748","238.45200","19.87105","0.17786"
"39810","238.82400","19.90214","0.17664"
"39872","239.19600","19.93317","0.11533"
"39934","239.56800","19.96402","0.11015"
"39996","239.94000","19.99517","0.11234"
"40058","240.31200","20.02615","0.11186"
"40120","240.68400","20.05706","0.11566"
"40182","241.05600","20.08809","0.11978"
"40244","241.42800","20.11912","0.12201"
"40306","241.80000","20.15009","0.12132"
"40368","242.17200","20.18112","0.12139"
"40430","242.54400","20.21215","0.12554"
"40492","242.91600","20.24312","0.13004"
"40554","243.28800","20.27409","0.13224"
"40616","243.66000","20.30512","0.13536"
"40678","244.03200","20.33615","0.13849"
"40740","244.40400","20.36707","0.14149"
"40802","244.77600","20.39810","0.14190"
"40864","245.14800","20.42913","0.14673"
"40926","245.52000","20.46010","0.15382"
"40988","245.89200","20.49107","0.15596"
"41050","246.26400","20.52216","0.15506"
"41112","246.63600","20.55313","0.15699"
"41174","247.00800","20.58404","0.16044"
"41236","247.38000","20.61513","0.16371"
"41298","247.75200","20.64610","0.16546"
"41360","248.12400","20.67707","0.16758"
"41422","248.49600","20.70811","0.16969"
"41484","248.86800","20.73914","0.17001"
"41546","249.24000","20.77005","0.17131"
"41608","249.61200","20.80114","0.17368"
"41670","249.98400","20.83217","0.17528"
"41732","250.35600","20.86308","0.17749"
"41794","250.72800","20.89411","0.17993"
"41856","251.10000","20.92514","0.18185"
"41918","251.47200","20.95605","0.18297"
"41980","251.84400","20.98708","0.18542"
"42042","252.21600","21.01811","0.18745"
"42104","252.58800","21.04914","0.18953"
"42166","252.96000","21.08012","0.19258"
"42228","253.33200","21.11115","0.19493"
"42290","253.70400","21.14212","0.19723"
"42352","254.07600","21.17303","0.20008"
"42414","254.44800","21.20412","0.20284"
"42476","254.82000","21.23509","0.20511"
"42538","255.19200","21.26606","0.20725"
"42600","255.56400","21.29715","0.20901"
"42662","255.93600","21.32806","0.21099"
"42724","256.30800","21.35915","0.21242"
"42786","256.68000","21.39007","0.21347"
"42848","257.05200","21.42115","0.21463"
"42910","257.42400","21.45213","0.21606"
"42972","257.79600","21.48310","0.21714"
"43034","258.16800","21.51413","0.21826"
"43096","258.54000","21.54510","0.21938"
"43158","258.91200","21.57607","0.22103"
"43220","259.28400","21.60716","0.22300"
"43282","259.65600","21.63813","0.22531"
"43344","260.02800","21.66910","0.22684"
"43406","260.40000","21.70007","0.22907"
"43468","260.77200","21.73110","0.23088"
"43530","261.14400","21.76208","0.23214"
"43592","261.51600","21.79311","0.23397"
"43654","261.88800","21.82420","0.23572"
"43716","262.26000","21.85511","0.23728"
"43778","262.63200","21.88608","0.23976"
"43840","263.00400","21.91711","0.24077"
"43902","263.37600","21.94808","0.24170"
"43964","263.74800","21.97911","0.24488"
"44026","264.12000","22.01008","0.24721"
"44088","264.49200","22.04117","0.25070"
"44150","264.86400","22.07208","0.25222"
"44212","265.23600","22.10311","0.25418"
"44274","265.60800","22.13415","0.25636"
"44336","265.98000","22.16506","0.25803"
"44398","266.35200","22.19609","0.26005"
"44460","266.72400","22.22712","0.26209"
"44522","267.09600","22.25809","0.26403"
"44584","267.46800","22.28912","0.26633"
"44646","267.84000","22.32015","0.26827"
"44708","268.21200","22.35112","0.27000"
"44770","268.58400","22.38209","0.27219"
"44832","268.95600","22.41312","0.27485"
"44894","269.32800","22.44415","0.27760"
"44956","269.70000","22.47507","0.27956"
"45018","270.07200","22.50610","0.28115"
"45080","270.44400","22.53713","0.28451"
"45142","270.81600","22.56810","0.28895"
"45204","271.18800","22.59913","0.29202"
"45266","271.56000","22.63010","0.29411"
"45328","271.93200","22.66113","0.29582"
"45390","272.30400","22.69204","0.29746"
"45452","272.67600","22.72313","0.29892"
"45514","273.04800","22.75416","0.30261"
"45576","273.42000","22.78507","0.30651"
"45638","273.79200","22.81610","0.30937"
"45700","274.16400","22.84714","0.31190"
"45762","274.53600","22.87805","0.31443"
"45824","274.90800","22.90914","0.31645"
"45886","275.28000","22.94011","0.31842"
"45948","275.65200","22.97114","0.32040"
"46010","276.02400","23.00205","0.32180"
"46072","276.39600","23.03314","0.32299"
"46134","276.76800","23.06405","0.32403"
"46196","277.14000","23.09508","0.32467"
"46258","277.51200","23.12617","0.32562"
"46320","277.88400","23.15714","0.32724"
"46382","278.25600","23.18812","0.32918"
"46444","278.62800","23.21908","0.33135"
"46506","279.00000","23.25012","0.33360"
"46568","279.37200","23.28109","0.33605"
"46630","279.74400","23.31206","0.03524"
"46692","280.11600","23.34315","0.04758"
"46754","280.48800","23.37406","0.03804"
"46816","280.86000","23.40509","0.04873"
"46878","281.23200","23.43612","0.04734"
"46940","281.60400","23.46709","0.05067"
"47002","281.97600","23.49806","0.05351"
"47064","282.34800","23.52916","0.05285"
"47126","282.72000","23.56012","0.05640"
"47188","283.09200","23.59110","0.05623"
"47250","283.46400","23.62213","0.05736"
"47312","283.83600","23.65316","0.06181"
"47374","284.20800","23.68401","0.06133"
"47436","284.58000","23.71510","0.06556"
"47498","284.95200","23.74613","0.06670"
"47560","285.32400","23.77710","0.06694"
"47622","285.69600","23.80813","0.07006"
"47684","286.06800","23.83910","0.07017"
"47746","286.44000","23.87013","0.07140"
"47808","286.81200","23.90111","0.07465"
"47870","287.18400","23.93208","0.07407"
"47932","287.55600","23.96311","0.07598"
"47994","287.92800","23.99408","0.07928"
"48056","288.30000","24.02517","0.08011"
"48118","288.67200","24.05614","0.08134"
"48180","289.04400","24.08711","0.08472"
"48242","289.41600","24.11814","0.08498"
"48304","289.78800","24.14911","0.08723"
"48366","290.16000","24.18008","0.09102"
"48428","290.53200","24.21111","0.09194"
"48490","290.90400","24.24214","0.09310"
"48552","291.27600","24.27312","0.09499"
"48614","291.64800","24.30409","0.09593"
"48676","292.02000","24.33518","0.09667"
"48738","292.39200","24.36603","0.09916"
"48800","292.76400","24.39712","0.10025"
"48862","293.13600","24.42815","0.10056"
"48924","293.50800","24.45912","0.10212"
"48986","293.88000","24.49009","0.10318"
"49048","294.25200","24.52112","0.10360"
"49110","294.62400","24.55209","0.10450"
"49172","294.99600","24.58306","0.10593"
"49234","295.36800","24.61409","0.10629"
"49296","295.74000","24.64519","0.10690"
"49358","296.11200","24.67610","0.10755"
"49420","296.48400","24.70713","0.10842"
"49482","296.85600","24.73810","0.10922"
"49544","297.22800","24.76907","0.10937"
"49606","297.60000","24.80010","0.11041"
"49668","297.97200","24.83113","0.11137"
"49730","298.34400","24.86210","0.11228"
"49792","298.71600","24.89307","0.11309"
"49854","299.08800","24.92410","0.11435"
"49916","299.46000","24.95513","0.11592"
"49978","299.83200","24.98605","0.11671"
"50040","300.20400","25.01714","0.11821"
"50102","300.57600","25.04811","0.12060"
"50164","300.94800","25.07908","0.12303"
"50226","301.32000","25.11011","0.12536"
"50288","301.69200","25.14108","0.12729"
"50350","302.06400","25.17211","0.12974"
"50412","302.43600","25.20308","0.13187"
"50474","302.80800","25.23417","0.13416"
"50536","303.18000","25.26514","0.13700"
"50598","303.55200","25.29605","0.14050"
"50660","303.92400","25.32715","0.14268"
"50722","304.29600","25.35812","0.04901"
"50784","304.66800","25.38909","0.05617"
"50846","305.04000","25.42012","0.06379"
"50908","305.41200","25.45115","0.06245"
"50970","305.78400","25.48212","0.06167"
"51032","306.15600","25.51309","0.06623"
"51094","306.52800","25.54412","0.06986"
"51156","306.90000","25.57509","0.06715"
"51218","307.27200","25.60606","0.06745"
"51280","307.64400","25.63709","0.07165"
"51342","308.01600","25.66813","0.07513"
"51404","308.38800","25.69910","0.07611"
"51466","308.76000","25.73013","0.07687"
"51528","309.13200","25.76116","0.07971"
"51590","309.50400","25.79213","0.08220"
"51652","309.87600","25.82316","0.08485"
"51714","310.24800","25.85413","0.08580"
"51776","310.62000","25.88510","0.08838"
"51838","310.99200","25.91613","0.09144"
"51900","311.36400","25.94716","0.09435"
"51962","311.73600","25.97813","0.09590"
"52024","312.10800","26.00910","0.09733"
"52086","312.48000","26.04008","0.09932"
"52148","312.85200","26.07104","0.10114"
"52210","313.22400","26.10214","0.10258"
"52272","313.59600","26.13317","0.10346"
"52334","313.96800","26.16414","0.10481"
"52396","314.34000","26.19511","0.10597"
"52458","314.71200","26.22608","0.10766"
"52520","315.08400","26.25711","0.10854"
"52582","315.45600","26.28808","0.11007"
"52644","315.82800","26.31917","0.11088"
"52706","316.20000","26.35008","0.11275"
"52768","316.57200","26.38112","0.11401"
"52830","316.94400","26.41208","0.11646"
"52892","317.31600","26.44318","0.11838"
"52954","317.68800","26.47415","0.12111"
"53016","318.06000","26.50506","0.12428"
"53078","318.43200","26.53615","0.12803"
"53140","318.80400","26.56712","0.13086"
"53202","319.17600","26.59803","0.13565"
"53264","319.54800","26.62912","0.14039"
"53326","319.92000","26.66009","0.14602"
"53388","320.29200","26.69113","0.15050"
"53450","320.66400","26.72209","0.15380"
"53512","321.03600","26.75307","0.15762"
"53574","321.40800","26.78410","0.16029"
"53636","321.78000","26.81513","0.16344"
"53698","322.15200","26.84616","0.15473"
"53760","322.52400","26.87707","0.14657"
"53822","322.89600","26.90804","0.12263"
"53884","323.26800","26.93913","0.12653"
"53946","323.64000","26.97010","0.13034"
"54008","324.01200","27.00107","0.13534"
"54070","324.38400","27.03210","0.13955"
"54132","324.75600","27.06314","0.14554"
"54194","325.12800","27.09405","0.14683"
"54256","325.50000","27.12508","0.15022"
"54318","325.87200","27.15611","0.15400"
"54380","326.24400","27.18702","0.15728"
"54442","326.61600","27.21811","0.16051"
"54504","326.98800","27.24914","0.16265"
"54566","327.36000","27.28011","0.16518"
"54628","327.73200","27.31108","0.16783"
"54690","328.10400","27.34211","0.17036"
"54752","328.47600","27.37314","0.17286"
"54814","328.84800","27.40405","0.17522"
"54876","329.22000","27.43514","0.17806"
"54938","329.59200","27.46618","0.17975"
"55000","329.96400","27.49703","0.18312"
"55062","330.33600","27.52812","0.18573"
"55124","330.70800","27.55909","0.18966"
"55186","331.08000","27.59006","0.19279"
"55248","331.45200","27.62109","0.19623"
"55310","331.82400","27.65212","0.19898"
"55372","332.19600","27.68309","0.20234"
"55434","332.56800","27.71406","0.20539"
"55496","332.94000","27.74515","0.20834"
"55558","333.31200","27.77618","0.21092"
"55620","333.68400","27.80704","0.21316"
"55682","334.05600","27.83819","0.21523"
"55744","334.42800","27.86916","0.21670"
"55806","334.80000","27.90007","0.21768"
"55868","335.17200","27.93110","0.21967"
"55930","335.54400","27.96213","0.22206"
"55992","335.91600","27.99310","0.22498"
"56054","336.28800","28.02407","0.22717"
"56116","336.66000","28.05516","0.22820"
"56178","337.03200","28.08614","0.22903"
"56240","337.40400","28.11710","0.23203"
"56302","337.77600","28.14813","0.23474"
"56364","338.14800","28.17911","0.23744"
"56426","338.52000","28.21008","0.24082"
"56488","338.89200","28.24111","0.24445"
"56550","339.26400","28.27214","0.24776"
"56612","339.63600","28.30311","0.25086"
"56674","340.00800","28.33408","0.25387"
"56736","340.38000","28.36517","0.25650"
"56798","340.75200","28.39608","0.25964"
"56860","341.12400","28.42711","0.26190"
"56922","341.49600","28.45815","0.26496"
"56984","341.86800","28.48906","0.26755"
"57046","342.24000","28.52009","0.26919"
"57108","342.61200","28.55118","0.26931"
"57170","342.98400","28.58209","0.26765"
"57232","343.35600","28.61312","0.13111"
"57294","343.72800","28.64415","0.13152"
"57356","344.10000","28.67512","0.13954"
"57418","344.47200","28.70603","0.15324"
"57480","344.84400","28.73712","0.16390"
"57542","345.21600","28.76815","0.16660"
"57604","345.58800","28.79906","0.16664"
"57666","345.96000","28.83015","0.16745"
"57728","346.33200","28.86113","0.16956"
"57790","346.70400","28.89210","0.17316"
"57852","347.07600","28.92307","0.17810"
"57914","347.44800","28.95410","0.18137"
"57976","347.82000","28.98513","0.18297"
"58038","348.19200","29.01610","0.18449"
"58100","348.56400","29.04713","0.18643"
"58162","348.93600","29.07810","0.18863"
"58224","349.30800","29.10913","0.19244"
"58286","349.68000","29.14016","0.19599"
"58348","350.05200","29.17113","0.19849"
"58410","350.42400","29.20205","0.20245"
"58472","350.79600","29.23308","0.20482"
"58534","351.16800","29.26411","0.20673"
"58596","351.54000","29.29508","0.20840"
"58658","351.91200","29.32611","0.21038"
"58720","352.28400","29.35714","0.21227"
"58782","352.65600","29.38805","0.21389"
"58844","353.02800","29.41908","0.21581"
"58906","353.40000","29.45017","0.21767"
"58968","353.77200","29.48114","0.21924"
"59030","354.14400","29.51211","0.22090"
"59092","354.51600","29.54314","0.22283"
"59154","354.88800","29.57412","0.22496"
"59216","355.26000","29.60503","0.22782"
"59278","355.63200","29.63612","0.23003"
"59340","356.00400","29.66715","0.23253"
"59402","356.37600","29.69806","0.23491"
"59464","356.74800","29.72915","0.23687"
"59526","357.12000","29.76006","0.23790"
"59588","357.49200","29.79103","0.24096"
"59650","357.86400","29.82207","0.18839"
"59712","358.23600","29.85315","0.10825"
"59774","358.60800","29.88413","0.10918"
"59836","358.98000","29.91504","0.12800"
"59898","359.35200","29.94613","0.13074"
"59960","359.72400","29.97716","0.12461"
"60022","360.09600","30.00807","0.13161"
"60084","360.46800","30.03916","0.14359"
"60146","360.84000","30.07013","0.12707"
"60208","361.21200","30.10110","0.12600"
"60270","361.58400","30.13207","0.13787"
"60332","361.95600","30.16310","0.14393"
"60394","362.32800","30.19413","0.13319"
"60456","362.70000","30.22511","0.13622"
"60518","363.07200","30.25614","0.15292"
"60580","363.44400","30.28711","0.15200"
"60642","363.81600","30.31802","0.14467"
"60704","364.18800","30.34917","0.14825"
"60766","364.56000","30.38014","0.15898"
"60828","364.93200","30.41111","0.15850"
"60890","365.30400","30.44208","0.15276"
"60952","365.67600","30.47311","0.15718"
"61014","366.04800","30.50408","0.16508"
"61076","366.42000","30.53505","0.16548"
"61138","366.79200","30.56608","0.16276"
"61200","367.16400","30.59711","0.16446"
"61262","367.53600","30.62809","0.17048"
"61324","367.90800","30.65918","0.17278"
"61386","368.28000","30.69009","0.16950"
"61448","368.65200","30.72106","0.17003"
"61510","369.02400","30.75215","0.17398"
"61572","369.39600","30.78312","0.17828"
"61634","369.76800","30.81409","0.17654"
"61696","370.14000","30.84512","0.17537"
"61758","370.51200","30.87615","0.17783"
"61820","370.88400","30.90706","0.18242"
"61882","371.25600","30.93815","0.18383"
"61944","371.62800","30.96912","0.18236"
"62006","372.00000","31.00010","0.18250"
"62068","372.37200","31.03113","0.18658"
"62130","372.74400","31.06210","0.19186"
"62192","373.11600","31.09313","0.19264"
"62254","373.48800","31.12410","0.19054"
"62316","373.86000","31.15513","0.19172"
"62378","374.23200","31.18616","0.19585"
"62440","374.60400","31.21701","0.20001"
"62502","374.97600","31.24810","0.20056"
"62564","375.34800","31.27913","0.19911"
"62626","375.72000","31.31004","0.20013"
"62688","376.09200","31.34114","0.20266"
"62750","376.46400","31.37210","0.20681"
"62812","376.83600","31.40314","0.20820"
"62874","377.20800","31.43411","0.20747"
"62936","377.58000","31.46514","0.20755"
"62998","377.95200","31.49611","0.20877"
"63060","378.32400","31.52714","0.21161"
"63122","378.69600","31.55811","0.21392"
"63184","379.06800","31.58908","0.21391"
"63246","379.44000","31.62005","0.21374"
"63308","379.81200","31.65114","0.21436"
"63370","380.18400","31.68212","0.21523"
"63432","380.55600","31.71308","0.21751"
"63494","380.92800","31.74412","0.21840"
"63556","381.30000","31.77515","0.21846"
"63618","381.67200","31.80612","0.21827"
"63680","382.04400","31.83709","0.21918"
"63742","382.41600","31.86818","0.22031"
"63804","382.78800","31.89909","0.22283"
"63866","383.16000","31.93012","0.22474"
"63928","383.53200","31.96115","0.22500"
"63990","383.90400","31.99212","0.22559"
"64052","384.27600","32.02303","0.22667"
"64114","384.64800","32.05413","0.22810"
"64176","385.02000","32.08516","0.23077"
"64238","385.39200","32.11607","0.23247"
"64300","385.76400","32.14710","0.23389"
"64362","386.13600","32.17813","0.23413"
"64424","386.50800","32.20904","0.23443"
"64486","386.88000","32.24013","0.23555"
"64548","387.25200","32.27110","0.23771"
"64610","387.62400","32.30213","0.23960"
"64672","387.99600","32.33310","0.24209"
"64734","388.36800","32.36413","0.24392"
"64796","388.74000","32.39511","0.24467"
"64858","389.11200","32.42607","0.24570"
"64920","389.48400","32.45716","0.24670"
"64982","389.85600","32.48814","0.24876"
"65044","390.22800","32.51911","0.25116"
"65106","390.60000","32.55014","0.25305"
"65168","390.97200","32.58111","0.25436"
"65230","391.34400","32.61208","0.25529"
"65292","391.71600","32.64311","0.25581"
"65354","392.08800","32.67414","0.25675"
"65416","392.46000","32.70511","0.25762"
"65478","392.83200","32.73603","0.25923"
"65540","393.20400","32.76717","0.26059"
"65602","393.57600","32.79815","0.26258"
"65664","393.94800","32.82906","0.26362"
"65726","394.32000","32.86015","0.26518"
"65788","394.69200","32.89112","0.26514"
"65850","395.06400","32.92209","0.26636"
"65912","395.43600","32.95306","0.26641"
"65974","395.80800","32.98409","0.00005"
"66036","396.18000","33.01512","0.00742"
"66098","396.55200","33.04609","0.00859"
"66160","396.92400","33.07718","0.00825"
"66222","397.29600","33.10809","0.00936"
"66284","397.66800","33.13906","0.00879"
"66346","398.04000","33.17015","0.00835"
"66408","398.41200","33.20113","0.00879"
"66470","398.78400","33.23215","0.00978"
"66532","399.15600","33.26313","0.00888"
"66594","399.52800","33.29416","0.00899"
"66656","399.90000","33.32507","0.00945"
"66718","400.27200","33.35604","0.00908"
"66780","400.64400","33.38719","0.00854"
"66842","401.01600","33.41810","0.00926"
"66904","401.38800","33.44913","0.00888"
"66966","401.76000","33.48010","0.00809"
"67028","402.13200","33.51108","0.00818"
"67090","402.50400","33.54211","0.00889"
"67152","402.87600","33.57314","0.00824"
"67214","403.24800","33.60411","0.00875"
"67276","403.62000","33.63508","0.00882"
"67338","403.99200","33.66611","0.00891"
"67400","404.36400","33.69714","0.00888"
"67462","404.73600","33.72805","0.00842"
"67524","405.10800","33.75914","0.00904"
"67586","405.48000","33.79012","0.00886"
"67648","405.85200","33.82114","0.00868"
"67710","406.22400","33.85212","0.00874"
"67772","406.59600","33.88309","0.00912"
"67834","406.96800","33.91406","0.00897"
"67896","407.34000","33.94509","0.00868"
"67958","407.71200","33.97612","0.00886"
"68020","408.08400","34.00715","0.00880"
"68082","408.45600","34.03806","0.00869"
"68144","408.82800","34.06915","0.00870"
"68206","409.20000","34.10006","0.00900"
"68268","409.57200","34.13110","0.00848"
"68330","409.94400","34.16212","0.00851"
"68392","410.31600","34.19315","0.00845"
"68454","410.68800","34.22407","0.00848"
"68516","411.06000","34.25516","0.00866"
"68578","411.43200","34.28613","0.00817"
"68640","411.80400","34.31710","0.00881"
"68702","412.17600","34.34813","0.00822"
"68764","412.54800","34.37916","0.00889"
"68826","412.92000","34.41007","0.00925"
"68888","413.29200","34.44104","0.00814"
"68950","413.66400","34.47219","0.00777"
"69012","414.03600","34.50311","0.00811"
"69074","414.40800","34.53413","0.00770"
"69136","414.78000","34.56517","0.00776"
"69198","415.15200","34.59614","0.00769"
"69260","415.52400","34.62704","0.00810"
"69322","415.89600","34.65814","0.00842"
"69384","416.26800","34.68917","0.00859"
"69446","416.64000","34.72008","0.00842"
"69508","417.01200","34.75111","0.00854"
"69570","417.38400","34.78208","0.00870"
"69632","417.75600","34.81311","0.00847"
"69694","418.12800","34.84409","0.00852"
"69756","418.50000","34.87511","0.00877"
"69818","418.87200","34.90615","0.00876"
"69880","419.24400","34.93700","0.00848"
"69942","419.61600","34.96809","0.00860"
"70004","419.98800","34.99912","0.00881"
"70066","420.36000","35.03003","0.00860"
"70128","420.73200","35.06118","0.00843"
"70190","421.10400","35.09215","0.00941"
"70252","421.47600","35.12306","0.00849"
"70314","421.84800","35.15409","0.00844"
"70376","422.22000","35.18512","0.00818"
"70438","422.59200","35.21609","0.00831"
"70500","422.96400","35.24707","0.00824"
"70562","423.33600","35.27816","0.00880"
"70624","423.70800","35.30913","0.00916"
"70686","424.08000","35.34010","0.00859"
"70748","424.45200","35.37113","0.00821"
"70810","424.82400","35.40216","0.00832"
"70872","425.19600","35.43307","0.00835"
"70934","425.56800","35.46410","0.00821"
"70996","425.94000","35.49513","0.00854"
"71058","426.31200","35.52610","0.00843"
"71120","426.68400","35.55707","0.00836"
"71182","427.05600","35.58817","0.00849"
"71244","427.42800","35.61914","0.00820"
"71306","427.80000","35.65011","0.00838"
"71368","428.17200","35.68114","0.00858"
"71430","428.54400","35.71211","0.00864"
"71492","428.91600","35.74308","0.00878"
"71554","429.28800","35.77411","0.00840"
"71616","429.66000","35.80514","0.00839"
"71678","430.03200","35.83605","0.00850"
"71740","430.40400","35.86708","0.00860"
"71802","430.77600","35.89817","0.00819"
"71864","431.14800","35.92902","0.00884"
"71926","431.52000","35.96012","0.00857"
"71988","431.89200","35.99109","0.00881"
"72050","432.26400","36.02206","0.00864"
"72112","432.63600","36.05309","0.00865"
"72174","433.00800","36.08412","0.00842"
"72236","433.38000","36.11515","0.00861"
"72298","433.75200","36.14612","0.00879"
"72360","434.12400","36.17715","0.00822"
"72422","434.49600","36.20818","0.00833"
"72484","434.86800","36.23904","0.00867"
"72546","435.24000","36.27012","0.00836"
"72608","435.61200","36.30116","0.00898"
"72670","435.98400","36.33207","0.00911"
"72732","436.35600","36.36316","0.00836"
"72794","436.72800","36.39413","0.00845"
"72856","437.10000","36.42510","0.00889"
"72918","437.47200","36.45607","0.00893"
"72980","437.84400","36.48716","0.00871"
"73042","438.21600","36.51807","0.00889"
"73104","438.58800","36.54904","0.00893"
"73166","438.96000","36.58014","0.00900"
"73228","439.33200","36.61110","0.00862"
"73290","439.70400","36.64207","0.00909"
"73352","440.07600","36.67311","0.00863"
"73414","440.44800","36.70408","0.00884"
"73476","440.82000","36.73511","0.00887"
"73538","441.19200","36.76608","0.00868"
"73600","441.56400","36.79717","0.00899"
"73662","441.93600","36.82808","0.00861"
"73724","442.30800","36.85905","0.00871"
"73786","442.68000","36.89014","0.00866"
"73848","443.05200","36.92111","0.00878"
"73910","443.42400","36.95208","0.00866"
"73972","443.79600","36.98311","0.00892"
"74034","444.16800","37.01414","0.00858"
"74096","444.54000","37.04512","0.00859"
"74158","444.91200","37.07608","0.00905"
"74220","445.28400","37.10718","0.00845"
"74282","445.65600","37.13803","0.00918"
"74344","446.02800","37.16912","0.00867"
"74406","446.40000","37.20015","0.00875"
"74468","446.77200","37.23106","0.00846"
"74530","447.14400","37.26215","0.00882"
"74592","447.51600","37.29313","0.00944"
"74654","447.88800","37.32409","0.00868"
"74716","448.26000","37.35506","0.00923"
"74778","448.63200","37.38616","0.00869"
"74840","449.00400","37.41713","0.00939"
"74902","449.37600","37.44810","0.00936"
"74964","449.74800","37.47913","0.00895"
"75026","450.12000","37.51016","0.00868"
"75088","450.49200","37.54107","0.00888"
"75150","450.86400","37.57210","0.00877"
"75212","451.23600","37.60313","0.00874"
"75274","451.60800","37.63411","0.00867"
"75336","451.98000","37.66513","0.00889"
"75398","452.35200","37.69611","0.00870"
"75460","452.72400","37.72713","0.00862"
"75522","453.09600","37.75805","0.00886"
"75584","453.46800","37.78913","0.00909"
"75615","453.65200","37.80444","0.00898"