File: Trajectories_together/161218_2Specimen_RawData_6.csv
"","V1","V2","V3"
"1","End date","12/18/2016",""
"2","Specimen label","16DG_25",""
"3","Maximum Load","0.05567","N"
"4","Time","Extension","Load"
"5","(s)","(mm)","(N)"
"6","0.00000","0.00000","-0.00011"
"57","0.30600","0.02511","-0.00001"
"108","0.61200","0.05124","0.00072"
"159","0.91800","0.07677","0.00043"
"210","1.22400","0.10224","0.00057"
"261","1.53000","0.12771","0.00093"
"312","1.83600","0.15330","0.00075"
"363","2.14200","0.17871","0.00086"
"414","2.44800","0.20418","0.00110"
"465","2.75400","0.22965","0.00145"
"516","3.06000","0.25524","0.00133"
"567","3.36600","0.28071","0.00221"
"618","3.67200","0.30624","0.00121"
"669","3.97800","0.33171","0.00147"
"720","4.28400","0.35718","0.00184"
"771","4.59000","0.38271","0.00195"
"822","4.89600","0.40818","0.00163"
"873","5.20200","0.43371","0.00236"
"924","5.50800","0.45918","0.00199"
"975","5.81400","0.48471","0.00195"
"1026","6.12000","0.51018","0.00231"
"1077","6.42600","0.53565","0.00223"
"1128","6.73200","0.56124","0.00239"
"1179","7.03800","0.58665","0.00233"
"1230","7.34400","0.61219","0.00240"
"1281","7.65000","0.63766","0.00191"
"1332","7.95600","0.66325","0.00273"
"1383","8.26200","0.68872","0.00273"
"1434","8.56800","0.71419","0.00260"
"1485","8.87400","0.73978","0.00281"
"1536","9.18000","0.76525","0.00275"
"1587","9.48600","0.79072","0.00305"
"1638","9.79200","0.81619","0.00251"
"1689","10.09800","0.84178","0.00263"
"1740","10.40400","0.86725","0.00261"
"1791","10.71000","0.89272","0.00319"
"1842","11.01600","0.91819","0.00313"
"1893","11.32200","0.94366","0.00300"
"1944","11.62800","0.96919","0.00301"
"1995","11.93400","0.99466","0.00344"
"2046","12.24000","1.02025","0.00362"
"2097","12.54600","1.04566","0.00320"
"2148","12.85200","1.07119","0.00321"
"2199","13.15800","1.09672","0.00308"
"2250","13.46400","1.12219","0.00305"
"2301","13.77000","1.14766","0.00306"
"2352","14.07600","1.17319","0.00376"
"2403","14.38200","1.19872","0.00335"
"2454","14.68800","1.22425","0.00333"
"2505","14.99400","1.24978","0.00383"
"2556","15.30000","1.27525","0.00335"
"2607","15.60600","1.30066","0.00362"
"2658","15.91200","1.32619","0.00375"
"2709","16.21800","1.35166","0.00407"
"2760","16.52400","1.37725","0.00383"
"2811","16.83000","1.40266","0.00383"
"2862","17.13600","1.42825","0.00409"
"2913","17.44200","1.45378","0.00400"
"2964","17.74800","1.47919","0.00417"
"3015","18.05400","1.50472","0.00433"
"3066","18.36000","1.53013","0.00447"
"3117","18.66600","1.55578","0.00435"
"3168","18.97200","1.58119","0.00424"
"3219","19.27800","1.60672","0.00433"
"3270","19.58400","1.63225","0.00402"
"3321","19.89000","1.65766","0.00463"
"3372","20.19600","1.68319","0.00415"
"3423","20.50200","1.70867","0.00459"
"3474","20.80800","1.73420","0.00482"
"3525","21.11400","1.75967","0.00485"
"3576","21.42000","1.78526","0.00386"
"3627","21.72600","1.81073","0.00448"
"3678","22.03200","1.83620","0.00461"
"3729","22.33800","1.86173","0.00423"
"3780","22.64400","1.88720","0.00472"
"3831","22.95000","1.91273","0.00464"
"3882","23.25600","1.93814","0.00493"
"3933","23.56200","1.96373","0.00465"
"3984","23.86800","1.98926","0.00493"
"4035","24.17400","2.01473","0.00439"
"4086","24.48000","2.04026","0.00479"
"4137","24.78600","2.06567","0.00448"
"4188","25.09200","2.09120","0.00475"
"4239","25.39800","2.11661","0.00475"
"4290","25.70400","2.14226","0.00484"
"4341","26.01000","2.16773","0.00500"
"4392","26.31600","2.19326","0.00499"
"4443","26.62200","2.21879","0.00499"
"4494","26.92800","2.24414","0.00496"
"4545","27.23400","2.26967","0.00517"
"4596","27.54000","2.29514","0.00532"
"4647","27.84600","2.32073","0.00549"
"4698","28.15200","2.34620","0.00519"
"4749","28.45800","2.37167","0.00517"
"4800","28.76400","2.39726","0.00524"
"4851","29.07000","2.42273","0.00556"
"4902","29.37600","2.44820","0.00512"
"4953","29.68200","2.47367","0.00499"
"5004","29.98800","2.49926","0.00503"
"5055","30.29400","2.52473","0.00490"
"5106","30.60000","2.55020","0.00546"
"5157","30.90600","2.57573","0.00556"
"5208","31.21200","2.60114","0.00512"
"5259","31.51800","2.62673","0.00524"
"5310","31.82400","2.65220","0.00538"
"5361","32.13000","2.67773","0.00500"
"5412","32.43600","2.70320","0.00515"
"5463","32.74200","2.72873","0.00582"
"5514","33.04800","2.75426","0.00538"
"5565","33.35400","2.77968","0.00542"
"5616","33.66000","2.80521","0.00595"
"5667","33.96600","2.83068","0.00577"
"5718","34.27200","2.85627","0.00591"
"5769","34.57800","2.88162","0.00594"
"5820","34.88400","2.90721","0.00564"
"5871","35.19000","2.93268","0.00561"
"5922","35.49600","2.95821","0.00587"
"5973","35.80200","2.98374","0.00608"
"6024","36.10800","3.00915","0.00603"
"6075","36.41400","3.03474","0.00573"
"6126","36.72000","3.06021","0.00517"
"6177","37.02600","3.08568","0.00503"
"6228","37.33200","3.11115","0.00523"
"6279","37.63800","3.13668","0.00504"
"6330","37.94400","3.16227","0.00548"
"6381","38.25000","3.18768","0.00533"
"6432","38.55600","3.21321","0.00539"
"6483","38.86200","3.23868","0.00559"
"6534","39.16800","3.26421","0.00535"
"6585","39.47400","3.28974","0.00517"
"6636","39.78000","3.31521","0.00578"
"6687","40.08600","3.34074","0.00492"
"6738","40.39200","3.36621","0.00542"
"6789","40.69800","3.39174","0.00544"
"6840","41.00400","3.41721","0.00537"
"6891","41.31000","3.44274","0.00550"
"6942","41.61600","3.46821","0.00564"
"6993","41.92200","3.49374","0.00501"
"7044","42.22800","3.51927","0.00564"
"7095","42.53400","3.54468","0.00484"
"7146","42.84000","3.57027","0.00497"
"7197","43.14600","3.59562","0.00531"
"7248","43.45200","3.62121","0.00520"
"7299","43.75800","3.64668","0.00474"
"7350","44.06400","3.67215","0.00507"
"7401","44.37000","3.69774","0.00547"
"7452","44.67600","3.72321","0.00521"
"7503","44.98200","3.74874","0.00542"
"7554","45.28800","3.77415","0.00534"
"7605","45.59400","3.79974","0.00562"
"7656","45.90000","3.82515","0.00551"
"7707","46.20600","3.85069","0.00540"
"7758","46.51200","3.87622","0.00548"
"7809","46.81800","3.90175","0.00540"
"7860","47.12400","3.92728","0.00582"
"7911","47.43000","3.95269","0.00589"
"7962","47.73600","3.97828","0.00600"
"8013","48.04200","4.00363","0.00564"
"8064","48.34800","4.02916","0.00579"
"8115","48.65400","4.05469","0.00582"
"8166","48.96000","4.08016","0.00561"
"8217","49.26600","4.10575","0.00593"
"8268","49.57200","4.13116","0.00618"
"8319","49.87800","4.15681","0.00532"
"8370","50.18400","4.18222","0.00519"
"8421","50.49000","4.20769","0.00562"
"8472","50.79600","4.23322","0.00558"
"8523","51.10200","4.25863","0.00501"
"8574","51.40800","4.28428","0.00512"
"8625","51.71400","4.30969","0.00550"
"8676","52.02000","4.33528","0.00550"
"8727","52.32600","4.36069","0.00513"
"8778","52.63200","4.38622","0.00563"
"8829","52.93800","4.41175","0.00542"
"8880","53.24400","4.43716","0.00541"
"8931","53.55000","4.46275","0.00580"
"8982","53.85600","4.48822","0.00577"
"9033","54.16200","4.51375","0.00553"
"9084","54.46800","4.53922","0.00606"
"9135","54.77400","4.56469","0.00535"
"9186","55.08000","4.59022","0.00601"
"9237","55.38600","4.61569","0.00564"
"9288","55.69200","4.64122","0.00582"
"9339","55.99800","4.66669","0.00560"
"9390","56.30400","4.69222","0.00562"
"9441","56.61000","4.71763","0.00584"
"9492","56.91600","4.74322","0.00542"
"9543","57.22200","4.76869","0.00580"
"9594","57.52800","4.79416","0.00580"
"9645","57.83400","4.81969","0.00572"
"9696","58.14000","4.84516","0.00531"
"9747","58.44600","4.87075","0.00590"
"9798","58.75200","4.89616","0.00572"
"9849","59.05800","4.92170","0.00622"
"9900","59.36400","4.94717","0.00599"
"9951","59.67000","4.97269","0.00585"
"10002","59.97600","4.99823","0.00609"
"10053","60.28200","5.02370","0.00608"
"10104","60.58800","5.04923","0.00616"
"10155","60.89400","5.07470","0.00620"
"10206","61.20000","5.10023","0.00626"
"10257","61.50600","5.12570","0.00605"
"10308","61.81200","5.15123","0.00633"
"10359","62.11800","5.17670","0.00641"
"10410","62.42400","5.20223","0.00583"
"10461","62.73000","5.22776","0.00586"
"10512","63.03600","5.25323","0.00608"
"10563","63.34200","5.27876","0.00656"
"10614","63.64800","5.30423","0.00651"
"10665","63.95400","5.32970","0.00651"
"10716","64.26000","5.35523","0.00653"
"10767","64.56600","5.38070","0.00623"
"10818","64.87200","5.40623","0.00645"
"10869","65.17800","5.43170","0.00557"
"10920","65.48400","5.45723","0.00463"
"10971","65.79000","5.48270","0.00308"
"11022","66.09600","5.50823","0.00247"
"11073","66.40200","5.53370","0.00313"
"11124","66.70800","5.55917","0.00318"
"11175","67.01400","5.58470","0.00293"
"11226","67.32000","5.61017","0.00261"
"11277","67.62600","5.63576","0.00304"
"11328","67.93200","5.66123","0.00271"
"11379","68.23800","5.68676","0.00269"
"11430","68.54400","5.71223","0.00308"
"11481","68.85000","5.73770","0.00314"
"11532","69.15600","5.76323","0.00319"
"11583","69.46200","5.78870","0.00343"
"11634","69.76800","5.81423","0.00347"
"11685","70.07400","5.83970","0.00331"
"11736","70.38000","5.86523","0.00375"
"11787","70.68600","5.89070","0.00359"
"11838","70.99200","5.91623","0.00383"
"11889","71.29800","5.94170","0.00392"
"11940","71.60400","5.96711","0.00380"
"11991","71.91000","5.99270","0.00426"
"12042","72.21600","6.01817","0.00400"
"12093","72.52200","6.04376","0.00393"
"12144","72.82800","6.06924","0.00400"
"12195","73.13400","6.09477","0.00413"
"12246","73.44000","6.12024","0.00417"
"12297","73.74600","6.14571","0.00450"
"12348","74.05200","6.17124","0.00415"
"12399","74.35800","6.19665","0.00455"
"12450","74.66400","6.22224","0.00486"
"12501","74.97000","6.24777","0.00482"
"12552","75.27600","6.27324","0.00444"
"12603","75.58200","6.29877","0.00495"
"12654","75.88800","6.32418","0.00511"
"12705","76.19400","6.34971","0.00538"
"12756","76.50000","6.37512","0.00555"
"12807","76.80600","6.40071","0.00539"
"12858","77.11200","6.42624","0.00583"
"12909","77.41800","6.45171","0.00590"
"12960","77.72400","6.47724","0.00569"
"13011","78.03000","6.50271","0.00574"
"13062","78.33600","6.52824","0.00645"
"13113","78.64200","6.55365","0.00631"
"13164","78.94800","6.57924","0.00619"
"13215","79.25400","6.60477","0.00606"
"13266","79.56000","6.63024","0.00634"
"13317","79.86600","6.65571","0.00627"
"13368","80.17200","6.68124","0.00655"
"13419","80.47800","6.70671","0.00677"
"13470","80.78400","6.73212","0.00661"
"13521","81.09000","6.75771","0.00702"
"13572","81.39600","6.78318","0.00683"
"13623","81.70200","6.80871","0.00708"
"13674","82.00800","6.83424","0.00726"
"13725","82.31400","6.85971","0.00699"
"13776","82.62000","6.88524","0.00720"
"13827","82.92600","6.91071","0.00712"
"13878","83.23200","6.93624","0.00763"
"13929","83.53800","6.96171","0.00770"
"13980","83.84400","6.98724","0.00753"
"14031","84.15000","7.01277","0.00759"
"14082","84.45600","7.03824","0.00800"
"14133","84.76200","7.06371","0.00795"
"14184","85.06800","7.08919","0.00833"
"14235","85.37400","7.11478","0.00795"
"14286","85.68000","7.14019","0.00822"
"14337","85.98600","7.16572","0.00804"
"14388","86.29200","7.19125","0.00832"
"14439","86.59800","7.21672","0.00846"
"14490","86.90400","7.24225","0.00856"
"14541","87.21000","7.26766","0.00861"
"14592","87.51600","7.29319","0.00856"
"14643","87.82200","7.31866","0.00864"
"14694","88.12800","7.34425","0.00841"
"14745","88.43400","7.36972","0.00840"
"14796","88.74000","7.39525","0.00897"
"14847","89.04600","7.42072","0.00898"
"14898","89.35200","7.44619","0.00866"
"14949","89.65800","7.47172","0.00897"
"15000","89.96400","7.49713","0.00928"
"15051","90.27000","7.52272","0.00919"
"15102","90.57600","7.54825","0.00891"
"15153","90.88200","7.57372","0.00850"
"15204","91.18800","7.59931","0.00924"
"15255","91.49400","7.62472","0.00934"
"15306","91.80000","7.65019","0.00787"
"15357","92.10600","7.67566","0.00813"
"15408","92.41200","7.70125","0.00861"
"15459","92.71800","7.72672","0.00868"
"15510","93.02400","7.75225","0.00829"
"15561","93.33000","7.77778","0.00789"
"15612","93.63600","7.80319","0.00845"
"15663","93.94200","7.82872","0.00874"
"15714","94.24800","7.85413","0.00846"
"15765","94.55400","7.87978","0.00883"
"15816","94.86000","7.90519","0.00862"
"15867","95.16600","7.93072","0.00927"
"15918","95.47200","7.95625","0.00896"
"15969","95.77800","7.98172","0.00751"
"16020","96.08400","8.00725","0.00756"
"16071","96.39000","8.03272","0.00720"
"16122","96.69600","8.05825","0.00741"
"16173","97.00200","8.08366","0.00735"
"16224","97.30800","8.10925","0.00759"
"16275","97.61400","8.13472","0.00719"
"16326","97.92000","8.16020","0.00744"
"16377","98.22600","8.18572","0.00784"
"16428","98.53200","8.21119","0.00780"
"16479","98.83800","8.23673","0.00799"
"16530","99.14400","8.26214","0.00824"
"16581","99.45000","8.28767","0.00811"
"16632","99.75600","8.31320","0.00783"
"16683","100.06200","8.33873","0.00862"
"16734","100.36800","8.36426","0.00876"
"16785","100.67400","8.38967","0.00855"
"16836","100.98000","8.41526","0.00900"
"16887","101.28600","8.44067","0.00865"
"16938","101.59200","8.46620","0.00870"
"16989","101.89800","8.49173","0.00883"
"17040","102.20400","8.51720","0.00905"
"17091","102.51000","8.54273","0.00896"
"17142","102.81600","8.56820","0.00786"
"17193","103.12200","8.59379","0.00747"
"17244","103.42800","8.61914","0.00753"
"17295","103.73400","8.64473","0.00802"
"17346","104.04000","8.67020","0.00795"
"17397","104.34600","8.69573","0.00826"
"17448","104.65200","8.72120","0.00833"
"17499","104.95800","8.74667","0.00843"
"17550","105.26400","8.77226","0.00838"
"17601","105.57000","8.79767","0.00859"
"17652","105.87600","8.82326","0.00848"
"17703","106.18200","8.84873","0.00874"
"17754","106.48800","8.87420","0.00918"
"17805","106.79400","8.89973","0.00893"
"17856","107.10000","8.92520","0.00916"
"17907","107.40600","8.95073","0.00942"
"17958","107.71200","8.97620","0.00865"
"18009","108.01800","9.00173","0.00898"
"18060","108.32400","9.02720","0.00881"
"18111","108.63000","9.05267","0.00944"
"18162","108.93600","9.07820","0.00921"
"18213","109.24200","9.10373","0.00965"
"18264","109.54800","9.12920","0.00861"
"18315","109.85400","9.15467","0.00867"
"18366","110.16000","9.18026","0.00866"
"18417","110.46600","9.20568","0.00887"
"18468","110.77200","9.23120","0.00922"
"18519","111.07800","9.25674","0.00918"
"18570","111.38400","9.28221","0.00908"
"18621","111.69000","9.30780","0.00941"
"18672","111.99600","9.33315","0.00955"
"18723","112.30200","9.35874","0.00942"
"18774","112.60800","9.38421","0.01000"
"18825","112.91400","9.40968","0.00983"
"18876","113.22000","9.43521","0.00964"
"18927","113.52600","9.46074","0.00994"
"18978","113.83200","9.48627","0.00975"
"19029","114.13800","9.51168","0.01026"
"19080","114.44400","9.53727","0.00881"
"19131","114.75000","9.56268","0.00935"
"19182","115.05600","9.58821","0.00944"
"19233","115.36200","9.61368","0.01004"
"19284","115.66800","9.63915","0.00964"
"19335","115.97400","9.66474","0.00990"
"19386","116.28000","9.69021","0.00995"
"19437","116.58600","9.71574","0.01067"
"19488","116.89200","9.74121","0.01056"
"19539","117.19800","9.76674","0.01098"
"19590","117.50400","9.79227","0.01025"
"19641","117.81000","9.81768","0.01094"
"19692","118.11600","9.84321","0.01092"
"19743","118.42200","9.86868","0.01084"
"19794","118.72800","9.89427","0.01148"
"19845","119.03400","9.91968","0.01120"
"19896","119.34000","9.94521","0.01135"
"19947","119.64600","9.97068","0.01173"
"19998","119.95200","9.99621","0.01155"
"20049","120.25800","10.02174","0.01243"
"20100","120.56400","10.04721","0.01228"
"20151","120.87000","10.07274","0.01193"
"20202","121.17600","10.09815","0.01242"
"20253","121.48200","10.12374","0.01259"
"20304","121.78800","10.14921","0.01220"
"20355","122.09400","10.17468","0.01194"
"20406","122.40000","10.20021","0.01178"
"20457","122.70600","10.22568","0.01210"
"20508","123.01200","10.25121","0.01243"
"20559","123.31800","10.27668","0.01230"
"20610","123.62400","10.30227","0.01201"
"20661","123.93000","10.32769","0.01224"
"20712","124.23600","10.35322","0.01214"
"20763","124.54200","10.37874","0.01249"
"20814","124.84800","10.40421","0.01214"
"20865","125.15400","10.42975","0.01220"
"20916","125.46000","10.45522","0.01245"
"20967","125.76600","10.48075","0.01185"
"21018","126.07200","10.50622","0.01172"
"21069","126.37800","10.53169","0.01206"
"21120","126.68400","10.55722","0.01143"
"21171","126.99000","10.58269","0.01171"
"21222","127.29600","10.60822","0.01149"
"21273","127.60200","10.63369","0.01161"
"21324","127.90800","10.65928","0.01211"
"21375","128.21400","10.68475","0.01208"
"21426","128.52000","10.71022","0.01259"
"21477","128.82600","10.73575","0.01211"
"21528","129.13200","10.76122","0.01204"
"21579","129.43800","10.78675","0.01286"
"21630","129.74400","10.81216","0.01213"
"21681","130.05000","10.83775","0.01259"
"21732","130.35600","10.86322","0.01298"
"21783","130.66200","10.88869","0.01210"
"21834","130.96800","10.91428","0.01271"
"21885","131.27400","10.93969","0.01319"
"21936","131.58000","10.96522","0.01374"
"21987","131.88600","10.99069","0.01319"
"22038","132.19200","11.01628","0.01341"
"22089","132.49800","11.04169","0.01341"
"22140","132.80400","11.06722","0.01411"
"22191","133.11000","11.09269","0.01405"
"22242","133.41600","11.11822","0.01436"
"22293","133.72200","11.14375","0.01400"
"22344","134.02800","11.16922","0.01415"
"22395","134.33400","11.19475","0.01359"
"22446","134.64000","11.22016","0.01412"
"22497","134.94600","11.24569","0.01426"
"22548","135.25200","11.27116","0.01431"
"22599","135.55800","11.29669","0.01434"
"22650","135.86400","11.32222","0.01508"
"22701","136.17000","11.34764","0.01496"
"22752","136.47600","11.37322","0.01516"
"22803","136.78200","11.39863","0.01533"
"22854","137.08800","11.42423","0.01571"
"22905","137.39400","11.44975","0.01569"
"22956","137.70000","11.47523","0.01647"
"23007","138.00600","11.50076","0.01592"
"23058","138.31200","11.52623","0.01598"
"23109","138.61800","11.55176","0.01607"
"23160","138.92400","11.57717","0.01617"
"23211","139.23000","11.60276","0.01635"
"23262","139.53600","11.62823","0.01651"
"23313","139.84200","11.65376","0.01697"
"23364","140.14800","11.67923","0.01649"
"23415","140.45400","11.70464","0.01600"
"23466","140.76000","11.73017","0.01721"
"23517","141.06600","11.75558","0.01677"
"23568","141.37200","11.78123","0.01696"
"23619","141.67800","11.80670","0.01736"
"23670","141.98400","11.83217","0.01762"
"23721","142.29000","11.85770","0.01812"
"23772","142.59600","11.88323","0.01783"
"23823","142.90200","11.90870","0.01788"
"23874","143.20800","11.93417","0.01794"
"23925","143.51400","11.95970","0.01803"
"23976","143.82000","11.98523","0.01871"
"24027","144.12600","12.01076","0.01928"
"24078","144.43200","12.03629","0.01882"
"24129","144.73800","12.06170","0.01877"
"24180","145.04400","12.08723","0.01893"
"24231","145.35000","12.11264","0.01934"
"24282","145.65600","12.13823","0.01963"
"24333","145.96200","12.16364","0.01987"
"24384","146.26800","12.18923","0.01975"
"24435","146.57400","12.21476","0.01976"
"24486","146.88000","12.24017","0.02036"
"24537","147.18600","12.26570","0.02010"
"24588","147.49200","12.29117","0.01952"
"24639","147.79800","12.31670","0.01964"
"24690","148.10400","12.34217","0.01985"
"24741","148.41000","12.36776","0.02042"
"24792","148.71600","12.39323","0.02031"
"24843","149.02200","12.41870","0.02016"
"24894","149.32800","12.44423","0.02025"
"24945","149.63400","12.46971","0.02033"
"24996","149.94000","12.49523","0.02010"
"25047","150.24600","12.52071","0.02026"
"25098","150.55200","12.54624","0.02039"
"25149","150.85800","12.57171","0.02032"
"25200","151.16400","12.59724","0.02057"
"25251","151.47000","12.62277","0.02045"
"25302","151.77600","12.64818","0.02019"
"25353","152.08200","12.67371","0.02047"
"25404","152.38800","12.69918","0.02005"
"25455","152.69400","12.72471","0.02014"
"25506","153.00000","12.75024","0.02041"
"25557","153.30600","12.77571","0.02056"
"25608","153.61200","12.80124","0.02006"
"25659","153.91800","12.82665","0.02042"
"25710","154.22400","12.85218","0.01961"
"25761","154.53000","12.87765","0.01941"
"25812","154.83600","12.90324","0.01929"
"25863","155.14200","12.92871","0.01916"
"25914","155.44800","12.95424","0.01970"
"25965","155.75400","12.97977","0.01965"
"26016","156.06000","13.00512","0.02056"
"26067","156.36600","13.03071","0.02065"
"26118","156.67200","13.05618","0.02086"
"26169","156.97800","13.08177","0.02090"
"26220","157.28400","13.10718","0.02144"
"26271","157.59000","13.13271","0.02137"
"26322","157.89600","13.15824","0.02085"
"26373","158.20200","13.18371","0.02073"
"26424","158.50800","13.20918","0.02059"
"26475","158.81400","13.23465","0.02072"
"26526","159.12000","13.26018","0.02072"
"26577","159.42600","13.28565","0.02129"
"26628","159.73200","13.31118","0.02081"
"26679","160.03800","13.33677","0.02170"
"26730","160.34400","13.36224","0.02134"
"26781","160.65000","13.38771","0.02148"
"26832","160.95600","13.41318","0.02143"
"26883","161.26200","13.43877","0.02148"
"26934","161.56800","13.46419","0.02007"
"26985","161.87400","13.48971","0.02132"
"27036","162.18000","13.51525","0.02128"
"27087","162.48600","13.54072","0.02125"
"27138","162.79200","13.56625","0.02084"
"27189","163.09800","13.59166","0.02136"
"27240","163.40400","13.61725","0.02136"
"27291","163.71000","13.64266","0.02189"
"27342","164.01600","13.66819","0.02164"
"27393","164.32200","13.69366","0.02209"
"27444","164.62800","13.71919","0.02191"
"27495","164.93400","13.74472","0.02237"
"27546","165.24000","13.77019","0.02237"
"27597","165.54600","13.79572","0.02256"
"27648","165.85200","13.82113","0.02226"
"27699","166.15800","13.84672","0.02284"
"27750","166.46400","13.87219","0.02284"
"27801","166.77000","13.89766","0.02296"
"27852","167.07600","13.92325","0.02316"
"27903","167.38200","13.94872","0.02287"
"27954","167.68800","13.97425","0.02278"
"28005","167.99400","13.99972","0.02289"
"28056","168.30000","14.02525","0.02294"
"28107","168.60600","14.05066","0.02333"
"28158","168.91200","14.07619","0.02320"
"28209","169.21800","14.10172","0.02353"
"28260","169.52400","14.12719","0.02361"
"28311","169.83000","14.15278","0.02354"
"28362","170.13600","14.17819","0.02159"
"28413","170.44200","14.20378","0.02262"
"28464","170.74800","14.22925","0.02208"
"28515","171.05400","14.25472","0.02266"
"28566","171.36000","14.28019","0.02296"
"28617","171.66600","14.30566","0.02285"
"28668","171.97200","14.33131","0.02268"
"28719","172.27800","14.35666","0.02220"
"28770","172.58400","14.38225","0.02296"
"28821","172.89000","14.40766","0.02322"
"28872","173.19600","14.43319","0.02342"
"28923","173.50200","14.45872","0.02345"
"28974","173.80800","14.48419","0.02262"
"29025","174.11400","14.50972","0.02339"
"29076","174.42000","14.53519","0.02346"
"29127","174.72600","14.56079","0.02352"
"29178","175.03200","14.58619","0.02397"
"29229","175.33800","14.61172","0.02393"
"29280","175.64400","14.63720","0.02428"
"29331","175.95000","14.66272","0.02387"
"29382","176.25600","14.68826","0.02413"
"29433","176.56200","14.71373","0.02400"
"29484","176.86800","14.73925","0.02447"
"29535","177.17400","14.76467","0.02486"
"29586","177.48000","14.79020","0.02471"
"29637","177.78600","14.81573","0.02542"
"29688","178.09200","14.84120","0.02534"
"29739","178.39800","14.86673","0.02525"
"29790","178.70400","14.89214","0.02502"
"29841","179.01000","14.91779","0.02540"
"29892","179.31600","14.94320","0.02545"
"29943","179.62200","14.96867","0.02514"
"29994","179.92800","14.99420","0.02556"
"30045","180.23400","15.01967","0.02555"
"30096","180.54000","15.04526","0.02541"
"30147","180.84600","15.07067","0.02499"
"30198","181.15200","15.09626","0.02549"
"30249","181.45800","15.12167","0.02556"
"30300","181.76400","15.14720","0.02552"
"30351","182.07000","15.17273","0.02585"
"30402","182.37600","15.19820","0.02596"
"30453","182.68200","15.22373","0.02553"
"30504","182.98800","15.24920","0.02500"
"30555","183.29400","15.27479","0.02561"
"30606","183.60000","15.30020","0.02606"
"30657","183.90600","15.32573","0.02543"
"30708","184.21200","15.35120","0.02527"
"30759","184.51800","15.37673","0.02515"
"30810","184.82400","15.40220","0.02519"
"30861","185.13000","15.42767","0.02546"
"30912","185.43600","15.45320","0.02581"
"30963","185.74200","15.47867","0.02631"
"31014","186.04800","15.50420","0.02609"
"31065","186.35400","15.52967","0.02630"
"31116","186.66000","15.55515","0.02638"
"31167","186.96600","15.58073","0.02665"
"31218","187.27200","15.60620","0.02625"
"31269","187.57800","15.63179","0.02637"
"31320","187.88400","15.65720","0.02609"
"31371","188.19000","15.68273","0.02561"
"31422","188.49600","15.70820","0.02613"
"31473","188.80200","15.73374","0.02599"
"31524","189.10800","15.75921","0.02609"
"31575","189.41400","15.78468","0.02574"
"31626","189.72000","15.81027","0.02630"
"31677","190.02600","15.83568","0.02600"
"31728","190.33200","15.86127","0.02658"
"31779","190.63800","15.88668","0.02645"
"31830","190.94400","15.91221","0.02677"
"31881","191.25000","15.93774","0.02661"
"31932","191.55600","15.96321","0.02712"
"31983","191.86200","15.98868","0.02710"
"32034","192.16800","16.01421","0.02681"
"32085","192.47400","16.03980","0.02740"
"32136","192.78000","16.06527","0.02768"
"32187","193.08600","16.09074","0.02738"
"32238","193.39200","16.11621","0.02762"
"32289","193.69800","16.14174","0.02733"
"32340","194.00400","16.16721","0.02772"
"32391","194.31000","16.19268","0.02719"
"32442","194.61600","16.21821","0.02757"
"32493","194.92200","16.24368","0.02692"
"32544","195.22800","16.26921","0.02730"
"32595","195.53400","16.29468","0.02705"
"32646","195.84000","16.32021","0.02729"
"32697","196.14600","16.34568","0.02742"
"32748","196.45200","16.37115","0.02782"
"32799","196.75800","16.39674","0.02751"
"32850","197.06400","16.42221","0.02812"
"32901","197.37000","16.44774","0.02788"
"32952","197.67600","16.47321","0.02767"
"33003","197.98200","16.49874","0.02743"
"33054","198.28800","16.52427","0.02731"
"33105","198.59400","16.54968","0.02777"
"33156","198.90000","16.57521","0.02772"
"33207","199.20600","16.60068","0.02782"
"33258","199.51200","16.62627","0.02761"
"33309","199.81800","16.65168","0.02691"
"33360","200.12400","16.67721","0.02614"
"33411","200.43000","16.70274","0.02623"
"33462","200.73600","16.72816","0.02663"
"33513","201.04200","16.75368","0.02711"
"33564","201.34800","16.77915","0.02716"
"33615","201.65400","16.80474","0.02773"
"33666","201.96000","16.83022","0.02731"
"33717","202.26600","16.85575","0.02820"
"33768","202.57200","16.88122","0.02805"
"33819","202.87800","16.90669","0.02771"
"33870","203.18400","16.93221","0.02819"
"33921","203.49000","16.95763","0.02848"
"33972","203.79600","16.98322","0.02905"
"34023","204.10200","17.00875","0.02900"
"34074","204.40800","17.03422","0.02696"
"34125","204.71400","17.05975","0.02754"
"34176","205.02000","17.08516","0.02799"
"34227","205.32600","17.11069","0.02778"
"34278","205.63200","17.13610","0.02848"
"34329","205.93800","17.16175","0.02896"
"34380","206.24400","17.18722","0.02915"
"34431","206.55000","17.21269","0.02917"
"34482","206.85600","17.23822","0.03011"
"34533","207.16200","17.26369","0.02993"
"34584","207.46800","17.28922","0.02995"
"34635","207.77400","17.31463","0.02993"
"34686","208.08000","17.34022","0.02955"
"34737","208.38600","17.36569","0.03026"
"34788","208.69200","17.39128","0.03058"
"34839","208.99800","17.41669","0.03060"
"34890","209.30400","17.44222","0.03034"
"34941","209.61000","17.46769","0.03024"
"34992","209.91600","17.49316","0.03095"
"35043","210.22200","17.51875","0.03061"
"35094","210.52800","17.54422","0.03105"
"35145","210.83400","17.56969","0.03020"
"35196","211.14000","17.59522","0.03077"
"35247","211.44600","17.62075","0.03115"
"35298","211.75200","17.64622","0.03087"
"35349","212.05800","17.67169","0.03089"
"35400","212.36400","17.69722","0.03083"
"35451","212.67000","17.72269","0.03124"
"35502","212.97600","17.74828","0.03179"
"35553","213.28200","17.77375","0.03190"
"35604","213.58800","17.79928","0.03155"
"35655","213.89400","17.82475","0.03150"
"35706","214.20000","17.85016","0.03217"
"35757","214.50600","17.87576","0.03221"
"35808","214.81200","17.90117","0.03296"
"35859","215.11800","17.92669","0.03228"
"35910","215.42400","17.95223","0.03345"
"35961","215.73000","17.97770","0.03200"
"36012","216.03600","18.00323","0.03182"
"36063","216.34200","18.02864","0.03203"
"36114","216.64800","18.05423","0.03194"
"36165","216.95400","18.07964","0.03241"
"36216","217.26000","18.10523","0.03256"
"36267","217.56600","18.13070","0.03317"
"36318","217.87200","18.15623","0.03228"
"36369","218.17800","18.18176","0.03267"
"36420","218.48400","18.20717","0.03190"
"36471","218.79000","18.23276","0.03200"
"36522","219.09600","18.25817","0.03150"
"36573","219.40200","18.28370","0.03189"
"36624","219.70800","18.30917","0.03184"
"36675","220.01400","18.33470","0.03265"
"36726","220.32000","18.36023","0.03254"
"36777","220.62600","18.38570","0.03227"
"36828","220.93200","18.41123","0.03254"
"36879","221.23800","18.43670","0.03300"
"36930","221.54400","18.46223","0.03244"
"36981","221.85000","18.48770","0.03333"
"37032","222.15600","18.51323","0.03353"
"37083","222.46200","18.53870","0.03400"
"37134","222.76800","18.56423","0.03421"
"37185","223.07400","18.58976","0.03448"
"37236","223.38000","18.61517","0.03405"
"37287","223.68600","18.64076","0.03383"
"37338","223.99200","18.66617","0.03371"
"37389","224.29800","18.69170","0.03312"
"37440","224.60400","18.71723","0.03393"
"37491","224.91000","18.74270","0.03416"
"37542","225.21600","18.76823","0.03437"
"37593","225.52200","18.79370","0.03522"
"37644","225.82800","18.81929","0.03458"
"37695","226.13400","18.84471","0.03503"
"37746","226.44000","18.87024","0.03547"
"37797","226.74600","18.89570","0.03562"
"37848","227.05200","18.92124","0.03556"
"37899","227.35800","18.94677","0.03525"
"37950","227.66400","18.97218","0.03504"
"38001","227.97000","18.99771","0.03564"
"38052","228.27600","19.02318","0.03542"
"38103","228.58200","19.04871","0.03598"
"38154","228.88800","19.07418","0.03614"
"38205","229.19400","19.09971","0.03576"
"38256","229.50000","19.12524","0.03600"
"38307","229.80600","19.15065","0.03453"
"38358","230.11200","19.17618","0.03513"
"38409","230.41800","19.20165","0.03446"
"38460","230.72400","19.22724","0.03415"
"38511","231.03000","19.25271","0.03432"
"38562","231.33600","19.27818","0.03477"
"38613","231.64200","19.30377","0.03505"
"38664","231.94800","19.32924","0.03528"
"38715","232.25400","19.35477","0.03542"
"38766","232.56000","19.38012","0.03354"
"38817","232.86600","19.40571","0.03351"
"38868","233.17200","19.43118","0.03421"
"38919","233.47800","19.45671","0.03444"
"38970","233.78400","19.48224","0.03512"
"39021","234.09000","19.50771","0.03466"
"39072","234.39600","19.53330","0.03473"
"39123","234.70200","19.55871","0.03493"
"39174","235.00800","19.58424","0.03508"
"39225","235.31400","19.60971","0.03524"
"39276","235.62000","19.63518","0.03453"
"39327","235.92600","19.66071","0.03452"
"39378","236.23200","19.68624","0.03449"
"39429","236.53800","19.71177","0.03421"
"39480","236.84400","19.73724","0.03408"
"39531","237.15000","19.76271","0.03376"
"39582","237.45600","19.78818","0.01581"
"39633","237.76200","19.81371","0.01316"
"39684","238.06800","19.83918","0.01588"
"39735","238.37400","19.86465","0.01277"
"39786","238.68000","19.89018","0.01595"
"39837","238.98600","19.91566","0.01453"
"39888","239.29200","19.94124","0.01566"
"39939","239.59800","19.96665","0.01673"
"39990","239.90400","19.99218","0.01703"
"40041","240.21000","20.01772","0.01845"
"40092","240.51600","20.04318","0.01814"
"40143","240.82200","20.06877","0.01967"
"40194","241.12800","20.09419","0.01992"
"40245","241.43400","20.11978","0.02002"
"40296","241.74000","20.14519","0.02133"
"40347","242.04600","20.17072","0.02098"
"40398","242.35200","20.19619","0.02184"
"40449","242.65800","20.22172","0.02200"
"40500","242.96400","20.24725","0.02207"
"40551","243.27000","20.27271","0.02234"
"40602","243.57600","20.29831","0.02233"
"40653","243.88200","20.32372","0.02201"
"40704","244.18800","20.34925","0.02341"
"40755","244.49400","20.37472","0.02310"
"40806","244.80000","20.40019","0.02308"
"40857","245.10600","20.42572","0.02391"
"40908","245.41200","20.45119","0.02368"
"40959","245.71800","20.47672","0.02487"
"41010","246.02400","20.50225","0.02478"
"41061","246.33000","20.52772","0.02455"
"41112","246.63600","20.55325","0.02555"
"41163","246.94200","20.57866","0.02523"
"41214","247.24800","20.60419","0.02643"
"41265","247.55400","20.62966","0.02635"
"41316","247.86000","20.65525","0.02701"
"41367","248.16600","20.68066","0.02716"
"41418","248.47200","20.70619","0.02695"
"41469","248.77800","20.73172","0.02677"
"41520","249.08400","20.75719","0.02806"
"41571","249.39000","20.78272","0.02739"
"41622","249.69600","20.80819","0.02804"
"41673","250.00200","20.83372","0.02830"
"41724","250.30800","20.85919","0.02849"
"41775","250.61400","20.88472","0.02885"
"41826","250.92000","20.91019","0.02870"
"41877","251.22600","20.93572","0.02932"
"41928","251.53200","20.96119","0.02922"
"41979","251.83800","20.98667","0.02983"
"42030","252.14400","21.01219","0.02972"
"42081","252.45000","21.03766","0.03053"
"42132","252.75600","21.06326","0.03046"
"42183","253.06200","21.08872","0.03092"
"42234","253.36800","21.11420","0.03003"
"42285","253.67400","21.13973","0.03066"
"42336","253.98000","21.16520","0.03062"
"42387","254.28600","21.19078","0.03021"
"42438","254.59200","21.21620","0.03113"
"42489","254.89800","21.24173","0.03157"
"42540","255.20400","21.26720","0.03120"
"42591","255.51000","21.29267","0.03115"
"42642","255.81600","21.31820","0.03183"
"42693","256.12200","21.34367","0.03185"
"42744","256.42800","21.36920","0.03259"
"42795","256.73400","21.39467","0.03276"
"42846","257.04000","21.42026","0.03271"
"42897","257.34600","21.44573","0.03312"
"42948","257.65200","21.47126","0.03271"
"42999","257.95800","21.49673","0.03309"
"43050","258.26400","21.52220","0.03422"
"43101","258.57000","21.54773","0.03392"
"43152","258.87600","21.57314","0.03455"
"43203","259.18200","21.59873","0.03516"
"43254","259.48800","21.62420","0.03604"
"43305","259.79400","21.64973","0.03570"
"43356","260.10000","21.67526","0.03582"
"43407","260.40600","21.70073","0.03552"
"43458","260.71200","21.72620","0.03625"
"43509","261.01800","21.75167","0.03618"
"43560","261.32400","21.77720","0.03627"
"43611","261.63000","21.80267","0.03726"
"43662","261.93600","21.82820","0.03794"
"43713","262.24200","21.85373","0.03834"
"43764","262.54800","21.87926","0.03796"
"43815","262.85400","21.90473","0.03788"
"43866","263.16000","21.93020","0.03852"
"43917","263.46600","21.95573","0.03851"
"43968","263.77200","21.98120","0.03877"
"44019","264.07800","22.00673","0.03924"
"44070","264.38400","22.03226","0.03880"
"44121","264.69000","22.05773","0.03914"
"44172","264.99600","22.08320","0.03943"
"44223","265.30200","22.10861","0.03894"
"44274","265.60800","22.13420","0.03950"
"44325","265.91400","22.15961","0.04049"
"44376","266.22000","22.18527","0.03988"
"44427","266.52600","22.21074","0.04005"
"44478","266.83200","22.23620","0.04027"
"44529","267.13800","22.26174","0.04067"
"44580","267.44400","22.28720","0.04067"
"44631","267.75000","22.31274","0.04060"
"44682","268.05600","22.33809","0.04082"
"44733","268.36200","22.36374","0.04187"
"44784","268.66800","22.38921","0.04143"
"44835","268.97400","22.41474","0.03998"
"44886","269.28000","22.44027","0.04073"
"44937","269.58600","22.46568","0.04138"
"44988","269.89200","22.49115","0.04112"
"45039","270.19800","22.51662","0.04163"
"45090","270.50400","22.54221","0.04128"
"45141","270.81000","22.56768","0.04189"
"45192","271.11600","22.59321","0.04223"
"45243","271.42200","22.61868","0.04249"
"45294","271.72800","22.64421","0.04274"
"45345","272.03400","22.66974","0.04288"
"45396","272.34000","22.69515","0.04320"
"45447","272.64600","22.72074","0.04374"
"45498","272.95200","22.74621","0.04415"
"45549","273.25800","22.77180","0.04353"
"45600","273.56400","22.79727","0.04444"
"45651","273.87000","22.82274","0.04434"
"45702","274.17600","22.84827","0.04414"
"45753","274.48200","22.87368","0.04437"
"45804","274.78800","22.89927","0.04421"
"45855","275.09400","22.92468","0.04476"
"45906","275.40000","22.95021","0.04524"
"45957","275.70600","22.97574","0.04507"
"46008","276.01200","23.00121","0.04584"
"46059","276.31800","23.02674","0.04570"
"46110","276.62400","23.05215","0.04578"
"46161","276.93000","23.07775","0.04573"
"46212","277.23600","23.10315","0.04625"
"46263","277.54200","23.12874","0.04661"
"46314","277.84800","23.15421","0.04621"
"46365","278.15400","23.17974","0.04645"
"46416","278.46000","23.20522","0.04647"
"46467","278.76600","23.23068","0.04692"
"46518","279.07200","23.25622","0.04751"
"46569","279.37800","23.28169","0.04716"
"46620","279.68400","23.30721","0.04749"
"46671","279.99000","23.33274","0.04806"
"46722","280.29600","23.35822","0.04867"
"46773","280.60200","23.38375","0.04893"
"46824","280.90800","23.40916","0.04912"
"46875","281.21400","23.43468","0.04941"
"46926","281.52000","23.46016","0.05006"
"46977","281.82600","23.48575","0.05038"
"47028","282.13200","23.51122","0.05082"
"47079","282.43800","23.53675","0.05053"
"47130","282.74400","23.56228","0.05095"
"47181","283.05000","23.58769","0.05090"
"47232","283.35600","23.61322","0.05051"
"47283","283.66200","23.63863","0.05035"
"47334","283.96800","23.66422","0.05114"
"47385","284.27400","23.68969","0.05069"
"47436","284.58000","23.71522","0.05108"
"47487","284.88600","23.74075","0.05074"
"47538","285.19200","23.76616","0.05140"
"47589","285.49800","23.79175","0.05179"
"47640","285.80400","23.81716","0.05095"
"47691","286.11000","23.84275","0.05144"
"47742","286.41600","23.86816","0.05153"
"47793","286.72200","23.89375","0.05187"
"47844","287.02800","23.91922","0.05207"
"47895","287.33400","23.94475","0.05259"
"47946","287.64000","23.97022","0.05253"
"47997","287.94600","23.99569","0.05263"
"48048","288.25200","24.02122","0.05284"
"48099","288.55800","24.04663","0.05299"
"48150","288.86400","24.07216","0.05268"
"48201","289.17000","24.09775","0.05288"
"48252","289.47600","24.12322","0.05349"
"48303","289.78200","24.14875","0.05382"
"48354","290.08800","24.17422","0.05327"
"48405","290.39400","24.19975","0.05323"
"48456","290.70000","24.22523","0.05342"
"48507","291.00600","24.25069","0.05320"
"48558","291.31200","24.27622","0.05357"
"48609","291.61800","24.30170","0.05401"
"48660","291.92400","24.32723","0.05401"
"48711","292.23000","24.35263","0.05446"
"48762","292.53600","24.37823","0.05367"
"48813","292.84200","24.40364","0.05317"
"48864","293.14800","24.42922","0.05370"
"48915","293.45400","24.45464","0.05368"
"48966","293.76000","24.48017","0.05423"
"49017","294.06600","24.50576","0.05433"
"49068","294.37200","24.53117","0.05453"
"49119","294.67800","24.55670","0.05423"
"49170","294.98400","24.58217","0.05454"
"49221","295.29000","24.60776","0.05488"
"49272","295.59600","24.63317","0.05487"
"49323","295.90200","24.65870","0.05380"
"49374","296.20800","24.68423","0.05368"
"49425","296.51400","24.70970","0.05354"
"49476","296.82000","24.73523","0.05310"
"49527","297.12600","24.76070","0.05361"
"49578","297.43200","24.78623","0.05356"
"49629","297.73800","24.81170","0.05348"
"49680","298.04400","24.83717","0.05372"
"49731","298.35000","24.86270","0.05344"
"49782","298.65600","24.88823","0.05398"
"49833","298.96200","24.91376","0.05386"
"49884","299.26800","24.93917","0.05373"
"49935","299.57400","24.96476","0.05364"
"49986","299.88000","24.99023","0.05424"
"50037","300.18600","25.01570","0.05429"
"50088","300.49200","25.04123","0.05519"
"50139","300.79800","25.06670","0.05461"
"50190","301.10400","25.09223","0.05448"
"50241","301.41000","25.11770","0.05464"
"50292","301.71600","25.14323","0.05442"
"50343","302.02200","25.16864","0.05437"
"50394","302.32800","25.19423","0.05471"
"50445","302.63400","25.21970","0.05503"
"50496","302.94000","25.24517","0.05436"
"50547","303.24600","25.27070","0.05457"
"50598","303.55200","25.29617","0.05488"
"50649","303.85800","25.32176","0.05508"
"50700","304.16400","25.34717","0.05527"
"50751","304.47000","25.37271","0.05543"
"50802","304.77600","25.39817","0.05504"
"50853","305.08200","25.42371","0.05441"
"50904","305.38800","25.44924","0.05387"
"50955","305.69400","25.47471","0.05406"
"51006","306.00000","25.50030","0.05421"
"51057","306.30600","25.52571","0.05417"
"51108","306.61200","25.55118","0.05410"
"51159","306.91800","25.57671","0.05391"
"51210","307.22400","25.60218","0.05435"
"51261","307.53000","25.62771","0.05364"
"51312","307.83600","25.65318","0.05339"
"51363","308.14200","25.67877","0.05297"
"51414","308.44800","25.70418","0.05310"
"51465","308.75400","25.72971","0.05211"
"51516","309.06000","25.75518","0.05027"
"51567","309.36600","25.78065","0.05130"
"51618","309.67200","25.80624","0.05119"
"51669","309.97800","25.83165","0.05113"
"51720","310.28400","25.85730","0.05223"
"51771","310.59000","25.88271","0.04959"
"51822","310.89600","25.90824","0.04974"
"51873","311.20200","25.93371","0.05069"
"51924","311.50800","25.95918","0.05079"
"51975","311.81400","25.98465","0.05045"
"52026","312.12000","26.01018","0.05098"
"52077","312.42600","26.03577","0.05115"
"52128","312.73200","26.06118","0.05148"
"52179","313.03800","26.08671","0.05102"
"52230","313.34400","26.11224","0.05059"
"52281","313.65000","26.13771","0.05063"
"52332","313.95600","26.16318","0.05048"
"52383","314.26200","26.18865","0.04950"
"52434","314.56800","26.21418","0.04949"
"52485","314.87400","26.23965","0.04956"
"52536","315.18000","26.26518","0.04876"
"52587","315.48600","26.29066","0.04911"
"52638","315.79200","26.31618","0.04985"
"52689","316.09800","26.34171","0.05007"
"52740","316.40400","26.36719","0.04877"
"52791","316.71000","26.39271","0.04429"
"52842","317.01600","26.41818","0.02952"
"52893","317.32200","26.44378","0.02864"
"52944","317.62800","26.46918","0.02736"
"52995","317.93400","26.49471","0.02953"
"53046","318.24000","26.52025","0.02882"
"53097","318.54600","26.54565","0.02746"
"53148","318.85200","26.57125","0.02760"
"53199","319.15800","26.59666","0.02831"
"53250","319.46400","26.62225","0.02855"
"53301","319.77000","26.64772","0.02841"
"53352","320.07600","26.67325","0.02872"
"53403","320.38200","26.69872","0.02898"
"53454","320.68800","26.72419","0.02948"
"53505","320.99400","26.74972","0.02996"
"53556","321.30000","26.77519","0.03023"
"53607","321.60600","26.80072","0.03021"
"53658","321.91200","26.82625","0.03069"
"53709","322.21800","26.85172","0.03131"
"53760","322.52400","26.87719","0.03174"
"53811","322.83000","26.90272","0.03181"
"53862","323.13600","26.92825","0.03222"
"53913","323.44200","26.95372","0.03267"
"53964","323.74800","26.97919","0.03301"
"54015","324.05400","27.00472","0.03391"
"54066","324.36000","27.03019","0.03488"
"54117","324.66600","27.05566","0.03493"
"54168","324.97200","27.08119","0.03554"
"54219","325.27800","27.10672","0.03548"
"54270","325.58400","27.13219","0.03646"
"54321","325.89000","27.15766","0.03734"
"54372","326.19600","27.18319","0.03806"
"54423","326.50200","27.20872","0.03810"
"54474","326.80800","27.23419","0.03834"
"54525","327.11400","27.25972","0.03889"
"54576","327.42000","27.28525","0.03948"
"54627","327.72600","27.31072","0.04021"
"54678","328.03200","27.33625","0.04055"
"54729","328.33800","27.36166","0.04108"
"54780","328.64400","27.38725","0.04121"
"54831","328.95000","27.41273","0.04131"
"54882","329.25600","27.43825","0.04240"
"54933","329.56200","27.46372","0.04262"
"54984","329.86800","27.48914","0.04280"
"55035","330.17400","27.51467","0.04297"
"55086","330.48000","27.54014","0.04390"
"55137","330.78600","27.56573","0.04435"
"55188","331.09200","27.59119","0.04476"
"55239","331.39800","27.61672","0.04521"
"55290","331.70400","27.64220","0.04507"
"55341","332.01000","27.66767","0.04614"
"55392","332.31600","27.69320","0.04622"
"55443","332.62200","27.71861","0.04644"
"55494","332.92800","27.74420","0.04731"
"55545","333.23400","27.76973","0.04745"
"55596","333.54000","27.79526","0.04807"
"55647","333.84600","27.82073","0.04863"
"55698","334.15200","27.84620","0.04890"
"55749","334.45800","27.87173","0.03745"
"55800","334.76400","27.89714","0.03703"
"55851","335.07000","27.92273","0.03888"
"55902","335.37600","27.94820","0.03953"
"55953","335.68200","27.97373","0.03986"
"56004","335.98800","27.99920","0.04058"
"56055","336.29400","28.02473","0.04169"
"56106","336.60000","28.05026","0.04219"
"56157","336.90600","28.07567","0.04233"
"56208","337.21200","28.10120","0.04331"
"56259","337.51800","28.12667","0.04390"
"56310","337.82400","28.15226","0.04523"
"56361","338.13000","28.17773","0.04497"
"56412","338.43600","28.20326","0.04585"
"56463","338.74200","28.22873","0.04680"
"56514","339.04800","28.25420","0.04620"
"56565","339.35400","28.27973","0.04642"
"56616","339.66000","28.30514","0.04734"
"56667","339.96600","28.33068","0.04771"
"56718","340.27200","28.35620","0.04846"
"56769","340.57800","28.38179","0.04932"
"56820","340.88400","28.40726","0.04799"
"56871","341.19000","28.43267","0.04915"
"56922","341.49600","28.45820","0.04963"
"56973","341.80200","28.48367","0.04967"
"57024","342.10800","28.50926","0.04984"
"57075","342.41400","28.53474","0.04844"
"57126","342.72000","28.56026","0.04884"
"57177","343.02600","28.58574","0.04840"
"57228","343.33200","28.61114","0.04934"
"57279","343.63800","28.63673","0.04942"
"57330","343.94400","28.66215","0.05019"
"57381","344.25000","28.68768","0.04987"
"57432","344.55600","28.71321","0.04916"
"57483","344.86200","28.73874","0.02333"
"57534","345.16800","28.76427","0.02007"
"57585","345.47400","28.78962","0.00370"
"57636","345.78000","28.81521","0.00118"
"57687","346.08600","28.84062","0.00255"
"57738","346.39200","28.86621","0.00602"
"57789","346.69800","28.89168","0.00265"
"57840","347.00400","28.91721","0.00422"
"57891","347.31000","28.94268","0.00497"
"57942","347.61600","28.96815","0.00201"
"57993","347.92200","28.99374","0.00412"
"58044","348.22800","29.01915","0.00508"
"58095","348.53400","29.04474","0.00371"
"58146","348.84000","29.07021","0.00525"
"58197","349.14600","29.09574","0.00435"
"58248","349.45200","29.12127","0.00398"
"58299","349.75800","29.14668","0.00516"
"58350","350.06400","29.17221","0.00453"
"58401","350.37000","29.19768","0.00470"
"58452","350.67600","29.22321","0.00505"
"58503","350.98200","29.24874","0.00416"
"58554","351.28800","29.27421","0.00511"
"58605","351.59400","29.29974","0.00478"
"58656","351.90000","29.32521","0.00514"
"58707","352.20600","29.35074","0.00557"
"58758","352.51200","29.37615","0.00496"
"58809","352.81800","29.40180","0.00534"
"58860","353.12400","29.42715","0.00491"
"58911","353.43000","29.45268","0.00518"
"58962","353.73600","29.47821","0.00529"
"59013","354.04200","29.50374","0.00534"
"59064","354.34800","29.52928","0.00614"
"59115","354.65400","29.55468","0.00563"
"59166","354.96000","29.58021","0.00549"
"59217","355.26600","29.60568","0.00589"
"59268","355.57200","29.63128","0.00540"
"59319","355.87800","29.65668","0.00568"
"59370","356.18400","29.68222","0.00599"
"59421","356.49000","29.70775","0.00602"
"59472","356.79600","29.73322","0.00583"
"59523","357.10200","29.75875","0.00595"
"59574","357.40800","29.78416","0.00654"
"59625","357.71400","29.80969","0.00598"
"59676","358.02000","29.83516","0.00636"
"59727","358.32600","29.86069","0.00594"
"59778","358.63200","29.88622","0.00613"
"59829","358.93800","29.91169","0.00657"
"59880","359.24400","29.93722","0.00649"
"59931","359.55000","29.96269","0.00637"
"59982","359.85600","29.98822","0.00635"
"60033","360.16200","30.01375","0.00666"
"60084","360.46800","30.03916","0.00663"
"60135","360.77400","30.06469","0.00673"
"60186","361.08000","30.09022","0.00677"
"60237","361.38600","30.11581","0.00666"
"60288","361.69200","30.14116","0.00682"
"60339","361.99800","30.16675","0.00658"
"60390","362.30400","30.19216","0.00691"
"60441","362.61000","30.21769","0.00686"
"60492","362.91600","30.24316","0.00630"
"60543","363.22200","30.26869","0.00684"
"60594","363.52800","30.29428","0.00635"
"60645","363.83400","30.31969","0.00667"
"60696","364.14000","30.34522","0.00712"
"60747","364.44600","30.37075","0.00680"
"60798","364.75200","30.39622","0.00705"
"60849","365.05800","30.42169","0.00688"
"60900","365.36400","30.44722","0.00707"
"60951","365.67000","30.47275","0.00694"
"61002","365.97600","30.49822","0.00784"
"61053","366.28200","30.52375","0.00741"
"61104","366.58800","30.54917","0.00758"
"61155","366.89400","30.57469","0.00757"
"61206","367.20000","30.60017","0.00770"
"61257","367.50600","30.62570","0.00759"
"61308","367.81200","30.65122","0.00774"
"61359","368.11800","30.67664","0.00724"
"61410","368.42400","30.70222","0.00776"
"61461","368.73000","30.72769","0.00741"
"61512","369.03600","30.75323","0.00752"
"61563","369.34200","30.77869","0.00714"
"61614","369.64800","30.80416","0.00765"
"61665","369.95400","30.82976","0.00717"
"61716","370.26000","30.85517","0.00725"
"61767","370.56600","30.88076","0.00788"
"61818","370.87200","30.90623","0.00769"
"61869","371.17800","30.93176","0.00780"
"61920","371.48400","30.95723","0.00800"
"61971","371.79000","30.98270","0.00800"
"62022","372.09600","31.00823","0.00769"
"62073","372.40200","31.03370","0.00794"
"62124","372.70800","31.05929","0.00777"
"62175","373.01400","31.08470","0.00794"
"62226","373.32000","31.11023","0.00798"
"62277","373.62600","31.13570","0.00800"
"62328","373.93200","31.16117","0.00826"
"62379","374.23800","31.18676","0.00787"
"62430","374.54400","31.21217","0.00800"
"62434","374.56600","31.21408","0.00836"