File: Trajectories_together/161217Specimen_RawData_8.csv
"","V1","V2","V3"
"1","End date","12/17/2016",""
"2","Specimen label","15CG_Unk",""
"3","Maximum Load","0.01489","N"
"4","Time","Extension","Load"
"5","(s)","(mm)","(N)"
"6","0.00000","0.00006","-0.00059"
"21","0.09000","0.00305","0.00018"
"36","0.18000","0.01166","0.00025"
"51","0.27000","0.02152","0.00057"
"66","0.36000","0.03013","0.00103"
"81","0.45000","0.03785","0.00145"
"96","0.54000","0.04526","0.00152"
"111","0.63000","0.05273","0.00161"
"126","0.72000","0.06021","0.00202"
"141","0.81000","0.06774","0.00224"
"156","0.90000","0.07528","0.00202"
"171","0.99000","0.08281","0.00255"
"186","1.08000","0.09016","0.00279"
"201","1.17000","0.09770","0.00278"
"216","1.26000","0.10529","0.00298"
"231","1.35000","0.11270","0.00292"
"246","1.44000","0.12024","0.00299"
"261","1.53000","0.12777","0.00307"
"276","1.62000","0.13518","0.00367"
"291","1.71000","0.14272","0.00338"
"306","1.80000","0.15025","0.00328"
"321","1.89000","0.15778","0.00357"
"336","1.98000","0.16526","0.00348"
"351","2.07000","0.17279","0.00379"
"366","2.16000","0.18021","0.00362"
"381","2.25000","0.18768","0.00407"
"396","2.34000","0.19521","0.00380"
"411","2.43000","0.20275","0.00404"
"426","2.52000","0.21022","0.00417"
"441","2.61000","0.21775","0.00414"
"456","2.70000","0.22523","0.00433"
"471","2.79000","0.23270","0.00431"
"486","2.88000","0.24023","0.00448"
"501","2.97000","0.24777","0.00478"
"516","3.06000","0.25518","0.00477"
"531","3.15000","0.26278","0.00468"
"546","3.24000","0.27019","0.00477"
"561","3.33000","0.27766","0.00469"
"576","3.42000","0.28526","0.00463"
"591","3.51000","0.29273","0.00492"
"606","3.60000","0.30026","0.00494"
"621","3.69000","0.30774","0.00504"
"636","3.78000","0.31521","0.00492"
"651","3.87000","0.32274","0.00493"
"666","3.96000","0.33022","0.00511"
"681","4.05000","0.33775","0.00523"
"696","4.14000","0.34528","0.00514"
"711","4.23000","0.35276","0.00529"
"726","4.32000","0.36017","0.00556"
"741","4.41000","0.36771","0.00536"
"756","4.50000","0.37524","0.00546"
"771","4.59000","0.38277","0.00543"
"786","4.68000","0.39019","0.00547"
"801","4.77000","0.39772","0.00539"
"816","4.86000","0.40519","0.00573"
"831","4.95000","0.41261","0.00570"
"846","5.04000","0.42020","0.00589"
"861","5.13000","0.42773","0.00589"
"876","5.22000","0.43521","0.00579"
"891","5.31000","0.44268","0.00578"
"906","5.40000","0.45016","0.00565"
"921","5.49000","0.45763","0.00564"
"936","5.58000","0.46522","0.00613"
"951","5.67000","0.47270","0.00581"
"966","5.76000","0.48023","0.00599"
"981","5.85000","0.48776","0.00620"
"996","5.94000","0.49524","0.00598"
"1011","6.03000","0.50265","0.00620"
"1026","6.12000","0.51024","0.00631"
"1041","6.21000","0.51778","0.00601"
"1056","6.30000","0.52525","0.00604"
"1071","6.39000","0.53272","0.00642"
"1086","6.48000","0.54020","0.00629"
"1101","6.57000","0.54767","0.00646"
"1116","6.66000","0.55521","0.00647"
"1131","6.75000","0.56274","0.00637"
"1146","6.84000","0.57021","0.00650"
"1161","6.93000","0.57769","0.00627"
"1176","7.02000","0.58522","0.00652"
"1191","7.11000","0.59263","0.00677"
"1206","7.20000","0.60023","0.00679"
"1221","7.29000","0.60776","0.00674"
"1236","7.38000","0.61523","0.00672"
"1251","7.47000","0.62271","0.00650"
"1266","7.56000","0.63018","0.00686"
"1281","7.65000","0.63766","0.00679"
"1296","7.74000","0.64525","0.00662"
"1311","7.83000","0.65272","0.00685"
"1326","7.92000","0.66020","0.00696"
"1341","8.01000","0.66779","0.00694"
"1356","8.10000","0.67520","0.00677"
"1371","8.19000","0.68262","0.00682"
"1386","8.28000","0.69021","0.00681"
"1401","8.37000","0.69774","0.00695"
"1416","8.46000","0.70528","0.00713"
"1431","8.55000","0.71269","0.00709"
"1446","8.64000","0.72016","0.00684"
"1461","8.73000","0.72770","0.00732"
"1476","8.82000","0.73517","0.00700"
"1491","8.91000","0.74277","0.00696"
"1506","9.00000","0.75030","0.00716"
"1521","9.09000","0.75771","0.00742"
"1536","9.18000","0.76513","0.00737"
"1551","9.27000","0.77266","0.00733"
"1566","9.36000","0.78019","0.00691"
"1581","9.45000","0.78773","0.00704"
"1596","9.54000","0.79526","0.00749"
"1611","9.63000","0.80273","0.00725"
"1626","9.72000","0.81021","0.00704"
"1641","9.81000","0.81768","0.00737"
"1656","9.90000","0.82516","0.00735"
"1671","9.99000","0.83269","0.00746"
"1686","10.08000","0.84028","0.00718"
"1701","10.17000","0.84770","0.00738"
"1716","10.26000","0.85517","0.00728"
"1731","10.35000","0.86270","0.00740"
"1746","10.44000","0.87024","0.00738"
"1761","10.53000","0.87771","0.00768"
"1776","10.62000","0.88524","0.00749"
"1791","10.71000","0.89272","0.00785"
"1806","10.80000","0.90013","0.00745"
"1821","10.89000","0.90772","0.00737"
"1836","10.98000","0.91520","0.00775"
"1851","11.07000","0.92273","0.00776"
"1866","11.16000","0.93027","0.00779"
"1881","11.25000","0.93774","0.00760"
"1896","11.34000","0.94521","0.00743"
"1911","11.43000","0.95269","0.00746"
"1926","11.52000","0.96016","0.00801"
"1941","11.61000","0.96775","0.00792"
"1956","11.70000","0.97517","0.00807"
"1971","11.79000","0.98270","0.00788"
"1986","11.88000","0.99023","0.00809"
"2001","11.97000","0.99765","0.00796"
"2016","12.06000","1.00518","0.00756"
"2031","12.15000","1.01277","0.00761"
"2046","12.24000","1.02019","0.00794"
"2061","12.33000","1.02772","0.00801"
"2076","12.42000","1.03520","0.00813"
"2091","12.51000","1.04273","0.00818"
"2106","12.60000","1.05026","0.00814"
"2121","12.69000","1.05774","0.00802"
"2136","12.78000","1.06527","0.00812"
"2151","12.87000","1.07274","0.00810"
"2166","12.96000","1.08016","0.00801"
"2181","13.05000","1.08769","0.00820"
"2196","13.14000","1.09522","0.00816"
"2211","13.23000","1.10270","0.00834"
"2226","13.32000","1.11023","0.00810"
"2241","13.41000","1.11771","0.00828"
"2256","13.50000","1.12518","0.00812"
"2271","13.59000","1.13265","0.00827"
"2286","13.68000","1.14025","0.00824"
"2301","13.77000","1.14772","0.00850"
"2316","13.86000","1.15525","0.00813"
"2331","13.95000","1.16273","0.00811"
"2346","14.04000","1.17026","0.00809"
"2361","14.13000","1.17773","0.00874"
"2376","14.22000","1.18521","0.00790"
"2391","14.31000","1.19274","0.00825"
"2406","14.40000","1.20022","0.00828"
"2421","14.49000","1.20775","0.00819"
"2436","14.58000","1.21516","0.00841"
"2451","14.67000","1.22270","0.00841"
"2466","14.76000","1.23023","0.00852"
"2481","14.85000","1.23770","0.00852"
"2496","14.94000","1.24524","0.00867"
"2511","15.03000","1.25277","0.00890"
"2526","15.12000","1.26018","0.00872"
"2541","15.21000","1.26772","0.00842"
"2556","15.30000","1.27525","0.00833"
"2571","15.39000","1.28272","0.00851"
"2586","15.48000","1.29026","0.00868"
"2601","15.57000","1.29767","0.00845"
"2616","15.66000","1.30515","0.00876"
"2631","15.75000","1.31268","0.00882"
"2646","15.84000","1.32021","0.00868"
"2661","15.93000","1.32775","0.00888"
"2676","16.02000","1.33522","0.00861"
"2691","16.11000","1.34269","0.00867"
"2706","16.20000","1.35017","0.00860"
"2721","16.29000","1.35764","0.00878"
"2736","16.38000","1.36523","0.00887"
"2751","16.47000","1.37277","0.00874"
"2766","16.56000","1.38024","0.00891"
"2781","16.65000","1.38777","0.00864"
"2796","16.74000","1.39519","0.00899"
"2811","16.83000","1.40266","0.00904"
"2826","16.92000","1.41026","0.00874"
"2841","17.01000","1.41773","0.00934"
"2856","17.10000","1.42520","0.00905"
"2871","17.19000","1.43274","0.00849"
"2886","17.28000","1.44021","0.00921"
"2901","17.37000","1.44768","0.00905"
"2916","17.46000","1.45522","0.00923"
"2931","17.55000","1.46275","0.00922"
"2946","17.64000","1.47022","0.00914"
"2961","17.73000","1.47770","0.00904"
"2976","17.82000","1.48517","0.00914"
"2991","17.91000","1.49265","0.00912"
"3006","18.00000","1.50018","0.00913"
"3021","18.09000","1.50771","0.00919"
"3036","18.18000","1.51525","0.00929"
"3051","18.27000","1.52266","0.00937"
"3066","18.36000","1.53013","0.00932"
"3081","18.45000","1.53767","0.00943"
"3096","18.54000","1.54526","0.00899"
"3111","18.63000","1.55279","0.00910"
"3126","18.72000","1.56027","0.00958"
"3141","18.81000","1.56774","0.00949"
"3156","18.90000","1.57522","0.00920"
"3171","18.99000","1.58269","0.00898"
"3186","19.08000","1.59022","0.00938"
"3201","19.17000","1.59770","0.00938"
"3216","19.26000","1.60529","0.00957"
"3231","19.35000","1.61276","0.00936"
"3246","19.44000","1.62018","0.00939"
"3261","19.53000","1.62771","0.00922"
"3276","19.62000","1.63524","0.00971"
"3291","19.71000","1.64266","0.00911"
"3306","19.80000","1.65025","0.00972"
"3321","19.89000","1.65766","0.00944"
"3336","19.98000","1.66514","0.00957"
"3351","20.07000","1.67273","0.00955"
"3366","20.16000","1.68021","0.00958"
"3381","20.25000","1.68774","0.00960"
"3396","20.34000","1.69521","0.00969"
"3411","20.43000","1.70269","0.00965"
"3426","20.52000","1.71022","0.00973"
"3441","20.61000","1.71769","0.00992"
"3456","20.70000","1.72523","0.00972"
"3471","20.79000","1.73276","0.00979"
"3486","20.88000","1.74023","0.00936"
"3501","20.97000","1.74771","0.01014"
"3516","21.06000","1.75518","0.00946"
"3531","21.15000","1.76271","0.00989"
"3546","21.24000","1.77019","0.00972"
"3561","21.33000","1.77772","0.00977"
"3576","21.42000","1.78526","0.00955"
"3591","21.51000","1.79273","0.00981"
"3606","21.60000","1.80020","0.00972"
"3621","21.69000","1.80768","0.00986"
"3636","21.78000","1.81527","0.00977"
"3651","21.87000","1.82274","0.01009"
"3666","21.96000","1.83022","0.01000"
"3681","22.05000","1.83775","0.00995"
"3696","22.14000","1.84516","0.00994"
"3711","22.23000","1.85276","0.01015"
"3726","22.32000","1.86023","0.00996"
"3741","22.41000","1.86771","0.00992"
"3756","22.50000","1.87524","0.00973"
"3771","22.59000","1.88271","0.01004"
"3786","22.68000","1.89019","0.01041"
"3801","22.77000","1.89766","0.01001"
"3816","22.86000","1.90519","0.00998"
"3831","22.95000","1.91273","0.01032"
"3846","23.04000","1.92026","0.01058"
"3861","23.13000","1.92767","0.01033"
"3876","23.22000","1.93515","0.01045"
"3891","23.31000","1.94268","0.00990"
"3906","23.40000","1.95027","0.01029"
"3921","23.49000","1.95775","0.01024"
"3936","23.58000","1.96522","0.01017"
"3951","23.67000","1.97276","0.01065"
"3966","23.76000","1.98017","0.01046"
"3981","23.85000","1.98770","0.01082"
"3996","23.94000","1.99524","0.01035"
"4011","24.03000","2.00271","0.01049"
"4026","24.12000","2.01024","0.01034"
"4041","24.21000","2.01772","0.01063"
"4056","24.30000","2.02513","0.01011"
"4071","24.39000","2.03272","0.01008"
"4086","24.48000","2.04026","0.01034"
"4101","24.57000","2.04773","0.01050"
"4116","24.66000","2.05527","0.01054"
"4131","24.75000","2.06268","0.01030"
"4146","24.84000","2.07015","0.01044"
"4161","24.93000","2.07769","0.01069"
"4176","25.02000","2.08522","0.01052"
"4191","25.11000","2.09269","0.01047"
"4206","25.20000","2.10023","0.01075"
"4221","25.29000","2.10770","0.01069"
"4236","25.38000","2.11517","0.01074"
"4251","25.47000","2.12265","0.01024"
"4266","25.56000","2.13024","0.01073"
"4281","25.65000","2.13777","0.01039"
"4296","25.74000","2.14519","0.01057"
"4311","25.83000","2.15272","0.01080"
"4326","25.92000","2.16014","0.01052"
"4341","26.01000","2.16761","0.01062"
"4356","26.10000","2.17526","0.01101"
"4371","26.19000","2.18268","0.01058"
"4386","26.28000","2.19021","0.01076"
"4401","26.37000","2.19768","0.01049"
"4416","26.46000","2.20516","0.01062"
"4431","26.55000","2.21269","0.01088"
"4446","26.64000","2.22016","0.01094"
"4461","26.73000","2.22770","0.01079"
"4476","26.82000","2.23523","0.01075"
"4491","26.91000","2.24265","0.01055"
"4506","27.00000","2.25018","0.01081"
"4521","27.09000","2.25771","0.01073"
"4536","27.18000","2.26525","0.01091"
"4551","27.27000","2.27272","0.01120"
"4566","27.36000","2.28025","0.01096"
"4581","27.45000","2.28773","0.01097"
"4596","27.54000","2.29520","0.01124"
"4611","27.63000","2.30267","0.01119"
"4626","27.72000","2.31021","0.01132"
"4641","27.81000","2.31774","0.01101"
"4656","27.90000","2.32521","0.01101"
"4671","27.99000","2.33275","0.01114"
"4686","28.08000","2.34016","0.01096"
"4701","28.17000","2.34764","0.01100"
"4716","28.26000","2.35523","0.01148"
"4731","28.35000","2.36270","0.01150"
"4746","28.44000","2.37024","0.01129"
"4761","28.53000","2.37771","0.01127"
"4776","28.62000","2.38512","0.01133"
"4791","28.71000","2.39272","0.01133"
"4806","28.80000","2.40025","0.01108"
"4821","28.89000","2.40772","0.01126"
"4836","28.98000","2.41526","0.01152"
"4851","29.07000","2.42273","0.01134"
"4866","29.16000","2.43021","0.01141"
"4881","29.25000","2.43774","0.01144"
"4896","29.34000","2.44521","0.01160"
"4911","29.43000","2.45275","0.01153"
"4926","29.52000","2.46022","0.01153"
"4941","29.61000","2.46769","0.01157"
"4956","29.70000","2.47523","0.01131"
"4971","29.79000","2.48270","0.01114"
"4986","29.88000","2.49017","0.01128"
"5001","29.97000","2.49777","0.01185"
"5016","30.06000","2.50518","0.01189"
"5031","30.15000","2.51266","0.01162"
"5046","30.24000","2.52019","0.01173"
"5061","30.33000","2.52772","0.01142"
"5076","30.42000","2.53526","0.01205"
"5091","30.51000","2.54273","0.01186"
"5106","30.60000","2.55020","0.01190"
"5121","30.69000","2.55768","0.01165"
"5136","30.78000","2.56515","0.01124"
"5151","30.87000","2.57268","0.01160"
"5166","30.96000","2.58022","0.01163"
"5181","31.05000","2.58769","0.01190"
"5196","31.14000","2.59516","0.01175"
"5211","31.23000","2.60270","0.01178"
"5226","31.32000","2.61017","0.01179"
"5241","31.41000","2.61771","0.01153"
"5256","31.50000","2.62518","0.01167"
"5271","31.59000","2.63271","0.01168"
"5286","31.68000","2.64025","0.01146"
"5301","31.77000","2.64766","0.01184"
"5316","31.86000","2.65519","0.01169"
"5331","31.95000","2.66273","0.01214"
"5346","32.04000","2.67020","0.01179"
"5361","32.13000","2.67779","0.01181"
"5376","32.22000","2.68521","0.01225"
"5391","32.31000","2.69268","0.01225"
"5406","32.40000","2.70021","0.01181"
"5421","32.49000","2.70769","0.01202"
"5436","32.58000","2.71528","0.01131"
"5451","32.67000","2.72270","0.01204"
"5466","32.76000","2.73017","0.01167"
"5481","32.85000","2.73764","0.01196"
"5496","32.94000","2.74512","0.01188"
"5511","33.03000","2.75271","0.01180"
"5526","33.12000","2.76030","0.01240"
"5541","33.21000","2.76778","0.01212"
"5556","33.30000","2.77525","0.01194"
"5571","33.39000","2.78272","0.01224"
"5586","33.48000","2.79014","0.01201"
"5601","33.57000","2.79773","0.01174"
"5616","33.66000","2.80521","0.01215"
"5631","33.75000","2.81274","0.01230"
"5646","33.84000","2.82021","0.01217"
"5661","33.93000","2.82769","0.01242"
"5676","34.02000","2.83516","0.01250"
"5691","34.11000","2.84275","0.01214"
"5706","34.20000","2.85029","0.01252"
"5721","34.29000","2.85776","0.01199"
"5736","34.38000","2.86517","0.01233"
"5751","34.47000","2.87271","0.01231"
"5766","34.56000","2.88018","0.01248"
"5781","34.65000","2.88771","0.01239"
"5796","34.74000","2.89519","0.01265"
"5811","34.83000","2.90272","0.01242"
"5826","34.92000","2.91020","0.01291"
"5841","35.01000","2.91767","0.01227"
"5856","35.10000","2.92514","0.01225"
"5871","35.19000","2.93268","0.01216"
"5886","35.28000","2.94027","0.01258"
"5901","35.37000","2.94774","0.01224"
"5916","35.46000","2.95522","0.01229"
"5931","35.55000","2.96275","0.01286"
"5946","35.64000","2.97016","0.01255"
"5961","35.73000","2.97770","0.01270"
"5976","35.82000","2.98523","0.01243"
"5991","35.91000","2.99271","0.01253"
"6006","36.00000","3.00024","0.01235"
"6021","36.09000","3.00765","0.01232"
"6036","36.18000","3.01519","0.01232"
"6051","36.27000","3.02272","0.01289"
"6066","36.36000","3.03019","0.01256"
"6081","36.45000","3.03779","0.01296"
"6096","36.54000","3.04526","0.01295"
"6111","36.63000","3.05267","0.01292"
"6126","36.72000","3.06021","0.01252"
"6141","36.81000","3.06768","0.01309"
"6156","36.90000","3.07516","0.01234"
"6171","36.99000","3.08275","0.01252"
"6186","37.08000","3.09022","0.01314"
"6201","37.17000","3.09764","0.01255"
"6216","37.26000","3.10517","0.01316"
"6231","37.35000","3.11270","0.01272"
"6246","37.44000","3.12030","0.01307"
"6261","37.53000","3.12771","0.01281"
"6276","37.62000","3.13518","0.01312"
"6291","37.71000","3.14272","0.01320"
"6306","37.80000","3.15013","0.01337"
"6321","37.89000","3.15766","0.01290"
"6336","37.98000","3.16526","0.01319"
"6351","38.07000","3.17279","0.01308"
"6366","38.16000","3.18021","0.01288"
"6381","38.25000","3.18774","0.01335"
"6396","38.34000","3.19521","0.01328"
"6411","38.43000","3.20269","0.01329"
"6426","38.52000","3.21022","0.01300"
"6441","38.61000","3.21769","0.01315"
"6456","38.70000","3.22523","0.01323"
"6471","38.79000","3.23270","0.01283"
"6486","38.88000","3.24017","0.01330"
"6501","38.97000","3.24771","0.01306"
"6516","39.06000","3.25518","0.01337"
"6531","39.15000","3.26271","0.01326"
"6546","39.24000","3.27019","0.01334"
"6561","39.33000","3.27772","0.01288"
"6576","39.42000","3.28520","0.01332"
"6591","39.51000","3.29267","0.01322"
"6606","39.60000","3.30026","0.01286"
"6621","39.69000","3.30774","0.01329"
"6636","39.78000","3.31521","0.01326"
"6651","39.87000","3.32268","0.01350"
"6666","39.96000","3.33016","0.01343"
"6681","40.05000","3.33775","0.01330"
"6696","40.14000","3.34522","0.01348"
"6711","40.23000","3.35276","0.01326"
"6726","40.32000","3.36029","0.01358"
"6741","40.41000","3.36765","0.01345"
"6756","40.50000","3.37518","0.01320"
"6771","40.59000","3.38277","0.01331"
"6786","40.68000","3.39019","0.01338"
"6801","40.77000","3.39772","0.01372"
"6816","40.86000","3.40525","0.01367"
"6831","40.95000","3.41267","0.01383"
"6846","41.04000","3.42020","0.01372"
"6861","41.13000","3.42767","0.01364"
"6876","41.22000","3.43521","0.01326"
"6891","41.31000","3.44274","0.01387"
"6906","41.40000","3.45016","0.01376"
"6921","41.49000","3.45769","0.01388"
"6936","41.58000","3.46522","0.01364"
"6951","41.67000","3.47270","0.01365"
"6966","41.76000","3.48023","0.01366"
"6981","41.85000","3.48776","0.01363"
"6996","41.94000","3.49524","0.01347"
"7011","42.03000","3.50271","0.01358"
"7026","42.12000","3.51018","0.01351"
"7041","42.21000","3.51772","0.01350"
"7056","42.30000","3.52525","0.01367"
"7071","42.39000","3.53278","0.01403"
"7086","42.48000","3.54026","0.01376"
"7101","42.57000","3.54767","0.01411"
"7116","42.66000","3.55515","0.01363"
"7131","42.75000","3.56274","0.01366"
"7146","42.84000","3.57021","0.01388"
"7161","42.93000","3.57769","0.01363"
"7176","43.02000","3.58528","0.01383"
"7191","43.11000","3.59269","0.01397"
"7206","43.20000","3.60017","0.01400"
"7221","43.29000","3.60770","0.01400"
"7236","43.38000","3.61523","0.01383"
"7251","43.47000","3.62277","0.01404"
"7266","43.56000","3.63018","0.01376"
"7281","43.65000","3.63766","0.01381"
"7296","43.74000","3.64519","0.01361"
"7311","43.83000","3.65266","0.01402"
"7326","43.92000","3.66020","0.01404"
"7341","44.01000","3.66773","0.01397"
"7356","44.10000","3.67514","0.01371"
"7371","44.19000","3.68268","0.01389"
"7386","44.28000","3.69015","0.01369"
"7401","44.37000","3.69774","0.01383"
"7416","44.46000","3.70528","0.01364"
"7431","44.55000","3.71275","0.01358"
"7446","44.64000","3.72022","0.01392"
"7461","44.73000","3.72770","0.01418"
"7476","44.82000","3.73517","0.01356"
"7491","44.91000","3.74271","0.01376"
"7506","45.00000","3.75018","0.01373"
"7521","45.09000","3.75771","0.01398"
"7536","45.18000","3.76525","0.01382"
"7551","45.27000","3.77266","0.01370"
"7566","45.36000","3.78019","0.01385"
"7581","45.45000","3.78773","0.01384"
"7596","45.54000","3.79520","0.01385"
"7611","45.63000","3.80273","0.01401"
"7626","45.72000","3.81021","0.01392"
"7641","45.81000","3.81768","0.01396"
"7656","45.90000","3.82515","0.01421"
"7671","45.99000","3.83275","0.01418"
"7686","46.08000","3.84022","0.01383"
"7701","46.17000","3.84776","0.01385"
"7716","46.26000","3.85523","0.01394"
"7731","46.35000","3.86270","0.01372"
"7746","46.44000","3.87018","0.01387"
"7761","46.53000","3.87777","0.01391"
"7776","46.62000","3.88524","0.01415"
"7791","46.71000","3.89272","0.01426"
"7806","46.80000","3.90019","0.01376"
"7821","46.89000","3.90772","0.01401"
"7836","46.98000","3.91520","0.01367"
"7851","47.07000","3.92273","0.01402"
"7866","47.16000","3.93027","0.01414"
"7881","47.25000","3.93774","0.01375"
"7896","47.34000","3.94521","0.01394"
"7911","47.43000","3.95269","0.01384"
"7926","47.52000","3.96016","0.01403"
"7941","47.61000","3.96775","0.01402"
"7956","47.70000","3.97517","0.01411"
"7971","47.79000","3.98270","0.01343"
"7986","47.88000","3.99017","0.01380"
"8001","47.97000","3.99765","0.01421"
"8016","48.06000","4.00524","0.01394"
"8031","48.15000","4.01271","0.01448"
"8046","48.24000","4.02019","0.01379"
"8061","48.33000","4.02778","0.01429"
"8076","48.42000","4.03520","0.01418"
"8091","48.51000","4.04267","0.01397"
"8106","48.60000","4.05020","0.01400"
"8121","48.69000","4.05774","0.01395"
"8136","48.78000","4.06521","0.01432"
"8151","48.87000","4.07274","0.01389"
"8166","48.96000","4.08022","0.01417"
"8181","49.05000","4.08769","0.01414"
"8196","49.14000","4.09516","0.01401"
"8211","49.23000","4.10276","0.01424"
"8226","49.32000","4.11023","0.01414"
"8241","49.41000","4.11776","0.01421"
"8256","49.50000","4.12524","0.01379"
"8271","49.59000","4.13271","0.01384"
"8286","49.68000","4.14019","0.01424"
"8301","49.77000","4.14772","0.01425"
"8316","49.86000","4.15525","0.01397"
"8331","49.95000","4.16273","0.01389"
"8346","50.04000","4.17020","0.01444"
"8361","50.13000","4.17767","0.01426"
"8376","50.22000","4.18521","0.01437"
"8391","50.31000","4.19274","0.01405"
"8406","50.40000","4.20021","0.01409"
"8421","50.49000","4.20775","0.01423"
"8436","50.58000","4.21516","0.01363"
"8451","50.67000","4.22264","0.01396"
"8466","50.76000","4.23023","0.01385"
"8481","50.85000","4.23776","0.01426"
"8496","50.94000","4.24524","0.01431"
"8511","51.03000","4.25271","0.01452"
"8526","51.12000","4.26024","0.01401"
"8541","51.21000","4.26766","0.01452"
"8556","51.30000","4.27519","0.01411"
"8571","51.39000","4.28272","0.01374"
"8586","51.48000","4.29026","0.01407"
"8601","51.57000","4.29773","0.01437"
"8616","51.66000","4.30521","0.01394"
"8631","51.75000","4.31268","0.01436"
"8646","51.84000","4.32015","0.01427"
"8661","51.93000","4.32775","0.01425"
"8676","52.02000","4.33522","0.01439"
"8691","52.11000","4.34269","0.01427"
"8706","52.20000","4.35023","0.01407"
"8721","52.29000","4.35764","0.01379"
"8736","52.38000","4.36523","0.01432"
"8751","52.47000","4.37271","0.01401"
"8766","52.56000","4.38018","0.01384"
"8781","52.65000","4.38777","0.01417"
"8796","52.74000","4.39519","0.01402"
"8811","52.83000","4.40272","0.01389"
"8826","52.92000","4.41020","0.01435"
"8841","53.01000","4.41773","0.01412"
"8856","53.10000","4.42526","0.01443"
"8871","53.19000","4.43274","0.01430"
"8886","53.28000","4.44021","0.01437"
"8901","53.37000","4.44768","0.01402"
"8916","53.46000","4.45516","0.01438"
"8931","53.55000","4.46269","0.01424"
"8946","53.64000","4.47022","0.01434"
"8961","53.73000","4.47770","0.01404"
"8976","53.82000","4.48517","0.01473"
"8991","53.91000","4.49265","0.01464"
"9006","54.00000","4.50018","0.01403"
"9021","54.09000","4.50771","0.01412"
"9036","54.18000","4.51519","0.01409"
"9051","54.27000","4.52272","0.01448"
"9066","54.36000","4.53019","0.01415"
"9081","54.45000","4.53761","0.01417"
"9096","54.54000","4.54520","0.01387"
"9111","54.63000","4.55273","0.01449"
"9126","54.72000","4.56021","0.01443"
"9141","54.81000","4.56774","0.01412"
"9156","54.90000","4.57521","0.01427"
"9171","54.99000","4.58269","0.01434"
"9186","55.08000","4.59022","0.01433"
"9201","55.17000","4.59775","0.01442"
"9216","55.26000","4.60523","0.01449"
"9231","55.35000","4.61270","0.01382"
"9246","55.44000","4.62024","0.01444"
"9261","55.53000","4.62771","0.01454"
"9276","55.62000","4.63524","0.01405"
"9291","55.71000","4.64272","0.01423"
"9306","55.80000","4.65025","0.01476"
"9321","55.89000","4.65772","0.01428"
"9336","55.98000","4.66520","0.01413"
"9351","56.07000","4.67267","0.01420"
"9366","56.16000","4.68021","0.01464"
"9381","56.25000","4.68774","0.01381"
"9396","56.34000","4.69521","0.01420"
"9411","56.43000","4.70269","0.01442"
"9426","56.52000","4.71022","0.01424"
"9441","56.61000","4.71763","0.01426"
"9456","56.70000","4.72523","0.01437"
"9471","56.79000","4.73276","0.01455"
"9486","56.88000","4.74023","0.01439"
"9501","56.97000","4.74771","0.01464"
"9516","57.06000","4.75518","0.01410"
"9531","57.15000","4.76271","0.01412"
"9546","57.24000","4.77019","0.01370"
"9561","57.33000","4.77772","0.01387"
"9576","57.42000","4.78526","0.01445"
"9591","57.51000","4.79273","0.01439"
"9606","57.60000","4.80026","0.01453"
"9621","57.69000","4.80768","0.01447"
"9636","57.78000","4.81521","0.01433"
"9651","57.87000","4.82280","0.01462"
"9666","57.96000","4.83022","0.01443"
"9681","58.05000","4.83769","0.01419"
"9696","58.14000","4.84516","0.01405"
"9711","58.23000","4.85270","0.01448"
"9726","58.32000","4.86023","0.01440"
"9741","58.41000","4.86776","0.01429"
"9756","58.50000","4.87524","0.01440"
"9771","58.59000","4.88271","0.01429"
"9786","58.68000","4.89019","0.01413"
"9801","58.77000","4.89766","0.01439"
"9816","58.86000","4.90519","0.01413"
"9831","58.95000","4.91273","0.01450"
"9846","59.04000","4.92026","0.01446"
"9861","59.13000","4.92773","0.01424"
"9876","59.22000","4.93521","0.01419"
"9891","59.31000","4.94268","0.01410"
"9906","59.40000","4.95021","0.01463"
"9921","59.49000","4.95775","0.01426"
"9936","59.58000","4.96522","0.01431"
"9951","59.67000","4.97276","0.01399"
"9966","59.76000","4.98017","0.01438"
"9981","59.85000","4.98764","0.01470"
"9996","59.94000","4.99524","0.01430"
"10011","60.03000","5.00277","0.01439"
"10026","60.12000","5.01024","0.01429"
"10041","60.21000","5.01772","0.01405"
"10056","60.30000","5.02519","0.01417"
"10071","60.39000","5.03266","0.01467"
"10086","60.48000","5.04014","0.01436"
"10101","60.57000","5.04773","0.01433"
"10116","60.66000","5.05526","0.01429"
"10131","60.75000","5.06268","0.01429"
"10146","60.84000","5.07021","0.01383"
"10161","60.93000","5.07769","0.01380"
"10176","61.02000","5.08516","0.01369"
"10191","61.11000","5.09275","0.01350"
"10206","61.20000","5.10023","0.01352"
"10221","61.29000","5.10770","0.01365"
"10236","61.38000","5.11517","0.01308"
"10251","61.47000","5.12265","0.01342"
"10266","61.56000","5.13018","0.01339"
"10281","61.65000","5.13771","0.01331"
"10296","61.74000","5.14525","0.01331"
"10311","61.83000","5.15278","0.01347"
"10326","61.92000","5.16020","0.01337"
"10341","62.01000","5.16767","0.01312"
"10356","62.10000","5.17526","0.01334"
"10371","62.19000","5.18268","0.01331"
"10386","62.28000","5.19027","0.01322"
"10401","62.37000","5.19774","0.01289"
"10416","62.46000","5.20522","0.01322"
"10431","62.55000","5.21269","0.01326"
"10446","62.64000","5.22016","0.01344"
"10461","62.73000","5.22770","0.01317"
"10476","62.82000","5.23523","0.01312"
"10491","62.91000","5.24270","0.01341"
"10506","63.00000","5.25012","0.01351"
"10521","63.09000","5.25765","0.01321"
"10536","63.18000","5.26519","0.01304"
"10551","63.27000","5.27272","0.01314"
"10566","63.36000","5.28025","0.01328"
"10581","63.45000","5.28773","0.01346"
"10596","63.54000","5.29526","0.01328"
"10611","63.63000","5.30267","0.01294"
"10626","63.72000","5.31021","0.01360"
"10641","63.81000","5.31774","0.01319"
"10656","63.90000","5.32521","0.01285"
"10671","63.99000","5.33275","0.01303"
"10686","64.08000","5.34016","0.01321"
"10701","64.17000","5.34770","0.01337"
"10716","64.26000","5.35523","0.01314"
"10731","64.35000","5.36270","0.01309"
"10746","64.44000","5.37024","0.01333"
"10761","64.53000","5.37771","0.01317"
"10776","64.62000","5.38518","0.01365"
"10791","64.71000","5.39272","0.01317"
"10806","64.80000","5.40025","0.01304"
"10821","64.89000","5.40772","0.01322"
"10836","64.98000","5.41526","0.01288"
"10851","65.07000","5.42267","0.01291"
"10866","65.16000","5.43020","0.01304"
"10881","65.25000","5.43768","0.01295"
"10896","65.34000","5.44521","0.01333"
"10911","65.43000","5.45274","0.01322"
"10926","65.52000","5.46022","0.01325"
"10941","65.61000","5.46769","0.01296"
"10956","65.70000","5.47523","0.01276"
"10971","65.79000","5.48264","0.01278"
"10986","65.88000","5.49023","0.01283"
"11001","65.97000","5.49777","0.01284"
"11016","66.06000","5.50524","0.01278"
"11031","66.15000","5.51271","0.01306"
"11046","66.24000","5.52019","0.01298"
"11061","66.33000","5.52772","0.01326"
"11076","66.42000","5.53525","0.01312"
"11091","66.51000","5.54273","0.01298"
"11106","66.60000","5.55026","0.01310"
"11121","66.69000","5.55774","0.01290"
"11136","66.78000","5.56521","0.01340"
"11151","66.87000","5.57268","0.01293"
"11166","66.96000","5.58028","0.01280"
"11181","67.05000","5.58775","0.01332"
"11196","67.14000","5.59528","0.01337"
"11211","67.23000","5.60270","0.01287"
"11226","67.32000","5.61017","0.01308"
"11241","67.41000","5.61771","0.01305"
"11256","67.50000","5.62524","0.01297"
"11271","67.59000","5.63277","0.01290"
"11286","67.68000","5.64025","0.01300"
"11301","67.77000","5.64766","0.01316"
"11316","67.86000","5.65519","0.01309"
"11331","67.95000","5.66267","0.01304"
"11346","68.04000","5.67026","0.01305"
"11361","68.13000","5.67773","0.01280"
"11376","68.22000","5.68521","0.01339"
"11391","68.31000","5.69274","0.01340"
"11406","68.40000","5.70015","0.01317"
"11421","68.49000","5.70763","0.01281"
"11436","68.58000","5.71528","0.01288"
"11451","68.67000","5.72276","0.01315"
"11466","68.76000","5.73023","0.01322"
"11481","68.85000","5.73770","0.01299"
"11496","68.94000","5.74518","0.01303"
"11511","69.03000","5.75265","0.01311"
"11526","69.12000","5.76018","0.01292"
"11541","69.21000","5.76772","0.01294"
"11556","69.30000","5.77525","0.01312"
"11571","69.39000","5.78266","0.01287"
"11586","69.48000","5.79014","0.01280"
"11601","69.57000","5.79773","0.01335"
"11616","69.66000","5.80520","0.01316"
"11631","69.75000","5.81274","0.01269"
"11646","69.84000","5.82027","0.01306"
"11661","69.93000","5.82769","0.01341"
"11676","70.02000","5.83516","0.01264"
"11691","70.11000","5.84263","0.01290"
"11706","70.20000","5.85029","0.01307"
"11721","70.29000","5.85770","0.01303"
"11736","70.38000","5.86523","0.01283"
"11751","70.47000","5.87271","0.01309"
"11766","70.56000","5.88018","0.01303"
"11781","70.65000","5.88771","0.01322"
"11796","70.74000","5.89525","0.01288"
"11811","70.83000","5.90272","0.01315"
"11826","70.92000","5.91025","0.01291"
"11841","71.01000","5.91773","0.01278"
"11856","71.10000","5.92520","0.01280"
"11871","71.19000","5.93268","0.01263"
"11886","71.28000","5.94021","0.01273"
"11901","71.37000","5.94768","0.01247"
"11916","71.46000","5.95528","0.01303"
"11931","71.55000","5.96269","0.01280"
"11946","71.64000","5.97016","0.01275"
"11961","71.73000","5.97776","0.01282"
"11976","71.82000","5.98523","0.01288"
"11991","71.91000","5.99276","0.01296"
"12006","72.00000","6.00024","0.01254"
"12021","72.09000","6.00771","0.01236"
"12036","72.18000","6.01519","0.01261"
"12051","72.27000","6.02266","0.01253"
"12066","72.36000","6.03025","0.01265"
"12081","72.45000","6.03779","0.01260"
"12096","72.54000","6.04520","0.01251"
"12111","72.63000","6.05273","0.01284"
"12126","72.72000","6.06021","0.01257"
"12141","72.81000","6.06768","0.01271"
"12156","72.90000","6.07521","0.01285"
"12171","72.99000","6.08275","0.01304"
"12186","73.08000","6.09022","0.01310"
"12201","73.17000","6.09769","0.01293"
"12216","73.26000","6.10517","0.01247"
"12231","73.35000","6.11264","0.01293"
"12246","73.44000","6.12024","0.01269"
"12261","73.53000","6.12771","0.01254"
"12276","73.62000","6.13518","0.01245"
"12291","73.71000","6.14266","0.01257"
"12306","73.80000","6.15019","0.01227"
"12321","73.89000","6.15772","0.01266"
"12336","73.98000","6.16520","0.01261"
"12351","74.07000","6.17273","0.01287"
"12366","74.16000","6.18020","0.01229"
"12381","74.25000","6.18768","0.01279"
"12396","74.34000","6.19515","0.01217"
"12411","74.43000","6.20269","0.01319"
"12426","74.52000","6.21022","0.01287"
"12441","74.61000","6.21769","0.01276"
"12456","74.70000","6.22523","0.01259"
"12471","74.79000","6.23270","0.01192"
"12486","74.88000","6.24011","0.01114"
"12501","74.97000","6.24771","0.01105"
"12516","75.06000","6.25524","0.01106"
"12531","75.15000","6.26271","0.01107"
"12546","75.24000","6.27025","0.01118"
"12561","75.33000","6.27772","0.01146"
"12576","75.42000","6.28514","0.01093"
"12591","75.51000","6.29267","0.01103"
"12606","75.60000","6.30026","0.01131"
"12621","75.69000","6.30768","0.01110"
"12636","75.78000","6.31521","0.01115"
"12651","75.87000","6.32268","0.01100"
"12666","75.96000","6.33016","0.01123"
"12681","76.05000","6.33769","0.01122"
"12696","76.14000","6.34522","0.01097"
"12711","76.23000","6.35270","0.01088"
"12726","76.32000","6.36029","0.01093"
"12741","76.41000","6.36765","0.01100"
"12756","76.50000","6.37518","0.01106"
"12771","76.59000","6.38271","0.01101"
"12786","76.68000","6.39025","0.01116"
"12801","76.77000","6.39778","0.01139"
"12816","76.86000","6.40519","0.01114"
"12831","76.95000","6.41267","0.01092"
"12846","77.04000","6.42020","0.01081"
"12861","77.13000","6.42767","0.01088"
"12876","77.22000","6.43527","0.01106"
"12891","77.31000","6.44274","0.01120"
"12906","77.40000","6.45021","0.01102"
"12921","77.49000","6.45775","0.01117"
"12936","77.58000","6.46522","0.01101"
"12951","77.67000","6.47270","0.01085"
"12966","77.76000","6.48023","0.01119"
"12981","77.85000","6.48776","0.01116"
"12996","77.94000","6.49524","0.01112"
"13011","78.03000","6.50271","0.01104"
"13026","78.12000","6.51018","0.01110"
"13041","78.21000","6.51772","0.01100"
"13056","78.30000","6.52519","0.01118"
"13071","78.39000","6.53278","0.01144"
"13086","78.48000","6.54026","0.01083"
"13101","78.57000","6.54767","0.01124"
"13116","78.66000","6.55514","0.01090"
"13131","78.75000","6.56268","0.01135"
"13146","78.84000","6.57021","0.01100"
"13161","78.93000","6.57775","0.01117"
"13176","79.02000","6.58522","0.01087"
"13191","79.11000","6.59269","0.01129"
"13206","79.20000","6.60023","0.01124"
"13221","79.29000","6.60770","0.01095"
"13236","79.38000","6.61523","0.01090"
"13251","79.47000","6.62277","0.01142"
"13266","79.56000","6.63024","0.01072"
"13281","79.65000","6.63771","0.01099"
"13296","79.74000","6.64519","0.01102"
"13311","79.83000","6.65272","0.01093"
"13326","79.92000","6.66019","0.01109"
"13341","80.01000","6.66773","0.01103"
"13356","80.10000","6.67520","0.01091"
"13371","80.19000","6.68274","0.01117"
"13386","80.28000","6.69015","0.01090"
"13401","80.37000","6.69768","0.01085"
"13416","80.46000","6.70528","0.01138"
"13431","80.55000","6.71269","0.01094"
"13446","80.64000","6.72028","0.01077"
"13461","80.73000","6.72770","0.01114"
"13476","80.82000","6.73517","0.01129"
"13491","80.91000","6.74271","0.01121"
"13506","81.00000","6.75024","0.01091"
"13521","81.09000","6.75771","0.01078"
"13536","81.18000","6.76525","0.01077"
"13551","81.27000","6.77266","0.01103"
"13566","81.36000","6.78019","0.01110"
"13581","81.45000","6.78767","0.01099"
"13596","81.54000","6.79520","0.01084"
"13611","81.63000","6.80273","0.01094"
"13626","81.72000","6.81021","0.01116"
"13641","81.81000","6.81768","0.01105"
"13656","81.90000","6.82516","0.01127"
"13671","81.99000","6.83269","0.01090"
"13686","82.08000","6.84022","0.01108"
"13701","82.17000","6.84770","0.01122"
"13716","82.26000","6.85523","0.01105"
"13731","82.35000","6.86270","0.01122"
"13746","82.44000","6.87018","0.01101"
"13761","82.53000","6.87765","0.01128"
"13776","82.62000","6.88524","0.01132"
"13791","82.71000","6.89272","0.01102"
"13806","82.80000","6.90019","0.01096"
"13821","82.89000","6.90766","0.01101"
"13836","82.98000","6.91520","0.01120"
"13851","83.07000","6.92273","0.01094"
"13866","83.16000","6.93020","0.01097"
"13881","83.25000","6.93768","0.01116"
"13896","83.34000","6.94527","0.01087"
"13911","83.43000","6.95269","0.01087"
"13926","83.52000","6.96022","0.01080"
"13941","83.61000","6.96769","0.01086"
"13956","83.70000","6.97523","0.01103"
"13971","83.79000","6.98270","0.01093"
"13986","83.88000","6.99017","0.01121"
"14001","83.97000","6.99771","0.01087"
"14016","84.06000","7.00518","0.01093"
"14031","84.15000","7.01265","0.01087"
"14046","84.24000","7.02025","0.01117"
"14061","84.33000","7.02772","0.01048"
"14076","84.42000","7.03514","0.01108"
"14091","84.51000","7.04273","0.01093"
"14106","84.60000","7.05014","0.01069"
"14121","84.69000","7.05768","0.01081"
"14136","84.78000","7.06527","0.01066"
"14151","84.87000","7.07274","0.01078"
"14166","84.96000","7.08022","0.01092"
"14181","85.05000","7.08769","0.01106"
"14196","85.14000","7.09516","0.01116"
"14211","85.23000","7.10276","0.01075"
"14226","85.32000","7.11023","0.01049"
"14241","85.41000","7.11776","0.01090"
"14256","85.50000","7.12524","0.01095"
"14271","85.59000","7.13265","0.01034"
"14286","85.68000","7.14013","0.01057"
"14301","85.77000","7.14772","0.01086"
"14316","85.86000","7.15525","0.01071"
"14331","85.95000","7.16273","0.01107"
"14346","86.04000","7.17020","0.01055"
"14361","86.13000","7.17767","0.01087"
"14376","86.22000","7.18521","0.01073"
"14391","86.31000","7.19268","0.01107"
"14406","86.40000","7.20027","0.01078"
"14421","86.49000","7.20775","0.01059"
"14436","86.58000","7.21522","0.01070"
"14451","86.67000","7.22270","0.01069"
"14466","86.76000","7.23017","0.01099"
"14481","86.85000","7.23764","0.01093"
"14496","86.94000","7.24530","0.01054"
"14511","87.03000","7.25277","0.01079"
"14526","87.12000","7.26018","0.01060"
"14541","87.21000","7.26766","0.01074"
"14556","87.30000","7.27513","0.01084"
"14571","87.39000","7.28266","0.01100"
"14586","87.48000","7.29020","0.01104"
"14601","87.57000","7.29773","0.01108"
"14616","87.66000","7.30521","0.01083"
"14631","87.75000","7.31268","0.01073"
"14646","87.84000","7.32021","0.01119"
"14661","87.93000","7.32775","0.01091"
"14676","88.02000","7.33522","0.01061"
"14691","88.11000","7.34275","0.01093"
"14706","88.20000","7.35023","0.01102"
"14721","88.29000","7.35770","0.01053"
"14736","88.38000","7.36523","0.01071"
"14751","88.47000","7.37271","0.01063"
"14766","88.56000","7.38018","0.01086"
"14781","88.65000","7.38777","0.01100"
"14796","88.74000","7.39519","0.01087"
"14811","88.83000","7.40266","0.01117"
"14826","88.92000","7.41014","0.01110"
"14841","89.01000","7.41767","0.01081"
"14856","89.10000","7.42526","0.01074"
"14871","89.19000","7.43268","0.01076"
"14886","89.28000","7.44021","0.01081"
"14901","89.37000","7.44774","0.01101"
"14916","89.46000","7.45516","0.01092"
"14931","89.55000","7.46269","0.01085"
"14946","89.64000","7.47022","0.01060"
"14961","89.73000","7.47770","0.01080"
"14976","89.82000","7.48517","0.01055"
"14991","89.91000","7.49270","0.01088"
"15006","90.00000","7.50018","0.01054"
"15021","90.09000","7.50771","0.01065"
"15036","90.18000","7.51519","0.00985"
"15051","90.27000","7.52272","0.00934"
"15066","90.36000","7.53019","0.00876"
"15081","90.45000","7.53767","0.00854"
"15096","90.54000","7.54520","0.00906"
"15111","90.63000","7.55267","0.00821"
"15126","90.72000","7.56021","0.00850"
"15141","90.81000","7.56768","0.00881"
"15156","90.90000","7.57515","0.00863"
"15171","90.99000","7.58263","0.00973"
"15186","91.08000","7.59016","0.00996"
"15201","91.17000","7.59775","0.01050"
"15216","91.26000","7.60523","0.01029"
"15231","91.35000","7.61270","0.00906"
"15246","91.44000","7.62018","0.00900"
"15261","91.53000","7.62765","0.00807"
"15276","91.62000","7.63512","0.00809"
"15291","91.71000","7.64272","0.00802"
"15306","91.80000","7.65019","0.00831"
"15321","91.89000","7.65772","0.00849"
"15336","91.98000","7.66520","0.00868"
"15351","92.07000","7.67267","0.00902"
"15366","92.16000","7.68015","0.00850"
"15381","92.25000","7.68774","0.00894"
"15396","92.34000","7.69521","0.00892"
"15411","92.43000","7.70275","0.00874"
"15426","92.52000","7.71028","0.00866"
"15441","92.61000","7.71769","0.00848"
"15456","92.70000","7.72523","0.00859"
"15471","92.79000","7.73276","0.00839"
"15486","92.88000","7.74023","0.00911"
"15501","92.97000","7.74777","0.00878"
"15516","93.06000","7.75518","0.00896"
"15531","93.15000","7.76266","0.00917"
"15546","93.24000","7.77019","0.00929"
"15561","93.33000","7.77772","0.00938"
"15576","93.42000","7.78526","0.00933"
"15591","93.51000","7.79273","0.00962"
"15606","93.60000","7.80026","0.00958"
"15621","93.69000","7.80774","0.00925"
"15636","93.78000","7.81521","0.00887"
"15651","93.87000","7.82274","0.00899"
"15666","93.96000","7.83022","0.00942"
"15681","94.05000","7.83775","0.00962"
"15696","94.14000","7.84522","0.00907"
"15711","94.23000","7.85270","0.00924"
"15726","94.32000","7.86011","0.00878"
"15741","94.41000","7.86776","0.00901"
"15756","94.50000","7.87524","0.00883"
"15771","94.59000","7.88271","0.00913"
"15786","94.68000","7.89024","0.00944"
"15801","94.77000","7.89772","0.00955"
"15816","94.86000","7.90519","0.00925"
"15831","94.95000","7.91267","0.00908"
"15846","95.04000","7.92026","0.00947"
"15861","95.13000","7.92773","0.00940"
"15876","95.22000","7.93521","0.00908"
"15891","95.31000","7.94268","0.00947"
"15906","95.40000","7.95021","0.00916"
"15921","95.49000","7.95769","0.00920"
"15936","95.58000","7.96522","0.00917"
"15951","95.67000","7.97275","0.00928"
"15966","95.76000","7.98017","0.00929"
"15981","95.85000","7.98770","0.00896"
"15996","95.94000","7.99518","0.00908"
"16011","96.03000","8.00271","0.00928"
"16026","96.12000","8.01024","0.00956"
"16041","96.21000","8.01772","0.00963"
"16056","96.30000","8.02525","0.00930"
"16071","96.39000","8.03266","0.00950"
"16086","96.48000","8.04014","0.00923"
"16101","96.57000","8.04773","0.00941"
"16116","96.66000","8.05520","0.00935"
"16131","96.75000","8.06274","0.00936"
"16146","96.84000","8.07021","0.00934"
"16161","96.93000","8.07763","0.00940"
"16176","97.02000","8.08522","0.00921"
"16191","97.11000","8.09275","0.00945"
"16206","97.20000","8.10017","0.00961"
"16221","97.29000","8.10776","0.00933"
"16236","97.38000","8.11523","0.00939"
"16251","97.47000","8.12265","0.00959"
"16266","97.56000","8.13018","0.00960"
"16281","97.65000","8.13771","0.00992"
"16296","97.74000","8.14519","0.00962"
"16311","97.83000","8.15272","0.00969"
"16326","97.92000","8.16020","0.00909"
"16341","98.01000","8.16773","0.00923"
"16356","98.10000","8.17520","0.00952"
"16371","98.19000","8.18274","0.00937"
"16386","98.28000","8.19027","0.00924"
"16401","98.37000","8.19768","0.00941"
"16416","98.46000","8.20522","0.00923"
"16431","98.55000","8.21269","0.00935"
"16446","98.64000","8.22022","0.00932"
"16461","98.73000","8.22770","0.01015"
"16476","98.82000","8.23523","0.01054"
"16491","98.91000","8.24276","0.01131"
"16506","99.00000","8.25024","0.01082"
"16521","99.09000","8.25765","0.01142"
"16536","99.18000","8.26519","0.01029"
"16551","99.27000","8.27272","0.01081"
"16566","99.36000","8.28025","0.00873"
"16581","99.45000","8.28773","0.00812"
"16596","99.54000","8.29520","0.00831"
"16611","99.63000","8.30267","0.00777"
"16626","99.72000","8.31021","0.00795"
"16641","99.81000","8.31774","0.00816"
"16656","99.90000","8.32521","0.00833"
"16671","99.99000","8.33275","0.00852"
"16686","100.08000","8.34016","0.00907"
"16701","100.17000","8.34769","0.00895"
"16716","100.26000","8.35523","0.00909"
"16731","100.35000","8.36270","0.00854"
"16746","100.44000","8.37024","0.00824"
"16761","100.53000","8.37771","0.00823"
"16776","100.62000","8.38518","0.00853"
"16791","100.71000","8.39272","0.00821"
"16806","100.80000","8.40019","0.00887"
"16821","100.89000","8.40772","0.00838"
"16836","100.98000","8.41526","0.00916"
"16851","101.07000","8.42267","0.00901"
"16866","101.16000","8.43020","0.00866"
"16881","101.25000","8.43762","0.00860"
"16896","101.34000","8.44521","0.00864"
"16911","101.43000","8.45275","0.00863"
"16926","101.52000","8.46022","0.00871"
"16941","101.61000","8.46769","0.00884"
"16956","101.70000","8.47523","0.00886"
"16971","101.79000","8.48264","0.00881"
"16986","101.88000","8.49023","0.00872"
"17001","101.97000","8.49771","0.00884"
"17016","102.06000","8.50518","0.00888"
"17031","102.15000","8.51277","0.00859"
"17046","102.24000","8.52019","0.00847"
"17061","102.33000","8.52760","0.00878"
"17076","102.42000","8.53520","0.00889"
"17091","102.51000","8.54273","0.00863"
"17106","102.60000","8.55020","0.00880"
"17121","102.69000","8.55774","0.00859"
"17136","102.78000","8.56521","0.00887"
"17151","102.87000","8.57262","0.00865"
"17166","102.96000","8.58022","0.00870"
"17181","103.05000","8.58775","0.00879"
"17196","103.14000","8.59522","0.00872"
"17211","103.23000","8.60276","0.00894"
"17226","103.32000","8.61023","0.00857"
"17241","103.41000","8.61770","0.00882"
"17256","103.50000","8.62518","0.00882"
"17271","103.59000","8.63283","0.00903"
"17286","103.68000","8.64025","0.00867"
"17301","103.77000","8.64772","0.00899"
"17316","103.86000","8.65519","0.00866"
"17331","103.95000","8.66267","0.00897"
"17346","104.04000","8.67020","0.00907"
"17361","104.13000","8.67773","0.00904"
"17376","104.22000","8.68521","0.00890"
"17391","104.31000","8.69274","0.00904"
"17406","104.40000","8.70015","0.00893"
"17421","104.49000","8.70763","0.00895"
"17436","104.58000","8.71522","0.00881"
"17451","104.67000","8.72269","0.00901"
"17466","104.76000","8.73023","0.00917"
"17481","104.85000","8.73776","0.00891"
"17496","104.94000","8.74518","0.00899"
"17511","105.03000","8.75271","0.00887"
"17526","105.12000","8.76018","0.00912"
"17541","105.21000","8.76772","0.00912"
"17556","105.30000","8.77525","0.00876"
"17571","105.39000","8.78272","0.00891"
"17586","105.48000","8.79026","0.00914"
"17601","105.57000","8.79767","0.00893"
"17616","105.66000","8.80520","0.00907"
"17631","105.75000","8.81280","0.00912"
"17646","105.84000","8.82021","0.00909"
"17661","105.93000","8.82775","0.00882"
"17676","106.02000","8.83522","0.00934"
"17691","106.11000","8.84263","0.00898"
"17706","106.20000","8.85017","0.00867"
"17721","106.29000","8.85776","0.00893"
"17736","106.38000","8.86523","0.00891"
"17751","106.47000","8.87271","0.00899"
"17766","106.56000","8.88018","0.00910"
"17781","106.65000","8.88771","0.00879"
"17796","106.74000","8.89519","0.00859"
"17811","106.83000","8.90272","0.00899"
"17826","106.92000","8.91025","0.00891"
"17841","107.01000","8.91773","0.00870"
"17856","107.10000","8.92520","0.00893"
"17871","107.19000","8.93268","0.00898"
"17886","107.28000","8.94021","0.00907"
"17901","107.37000","8.94774","0.00904"
"17916","107.46000","8.95522","0.00894"
"17931","107.55000","8.96269","0.00924"
"17946","107.64000","8.97016","0.00900"
"17961","107.73000","8.97770","0.00896"
"17976","107.82000","8.98517","0.00880"
"17991","107.91000","8.99276","0.00889"
"18006","108.00000","9.00024","0.00919"
"18021","108.09000","9.00771","0.00903"
"18036","108.18000","9.01525","0.00908"
"18051","108.27000","9.02266","0.00912"
"18066","108.36000","9.03019","0.00937"
"18081","108.45000","9.03779","0.00925"
"18096","108.54000","9.04520","0.00915"
"18111","108.63000","9.05267","0.00924"
"18126","108.72000","9.06021","0.00941"
"18141","108.81000","9.06768","0.00886"
"18156","108.90000","9.07521","0.00907"
"18171","108.99000","9.08269","0.00914"
"18186","109.08000","9.09022","0.00899"
"18201","109.17000","9.09770","0.00912"
"18216","109.26000","9.10511","0.00926"
"18231","109.35000","9.11270","0.00934"
"18246","109.44000","9.12024","0.00914"
"18261","109.53000","9.12777","0.00918"
"18276","109.62000","9.13524","0.00917"
"18291","109.71000","9.14272","0.00917"
"18306","109.80000","9.15019","0.00927"
"18321","109.89000","9.15772","0.00911"
"18336","109.98000","9.16520","0.00939"
"18351","110.07000","9.17273","0.00928"
"18366","110.16000","9.18021","0.00929"
"18381","110.25000","9.18774","0.00942"
"18396","110.34000","9.19515","0.00946"
"18411","110.43000","9.20269","0.00908"
"18426","110.52000","9.21022","0.00918"
"18441","110.61000","9.21775","0.00903"
"18456","110.70000","9.22523","0.00909"
"18471","110.79000","9.23270","0.00923"
"18486","110.88000","9.24017","0.00932"
"18501","110.97000","9.24765","0.00962"
"18516","111.06000","9.25524","0.00940"
"18531","111.15000","9.26271","0.00921"
"18546","111.24000","9.27019","0.00961"
"18561","111.33000","9.27778","0.00891"
"18576","111.42000","9.28519","0.00933"
"18591","111.51000","9.29267","0.00942"
"18606","111.60000","9.30020","0.00935"
"18621","111.69000","9.30774","0.00928"
"18636","111.78000","9.31527","0.00944"
"18651","111.87000","9.32274","0.00899"
"18666","111.96000","9.33016","0.00970"
"18681","112.05000","9.33769","0.00942"
"18696","112.14000","9.34516","0.00929"
"18711","112.23000","9.35276","0.00931"
"18726","112.32000","9.36023","0.00921"
"18741","112.41000","9.36770","0.00921"
"18756","112.50000","9.37518","0.00938"
"18771","112.59000","9.38265","0.00921"
"18786","112.68000","9.39019","0.00937"
"18801","112.77000","9.39772","0.00941"
"18816","112.86000","9.40519","0.00960"
"18831","112.95000","9.41273","0.00943"
"18846","113.04000","9.42020","0.00932"
"18859","113.11400","9.42630","0.00934"