File: Trajectories_together/161218_2Specimen_RawData_3.csv
"","V1","V2","V3"
"1","End date","12/18/2016",""
"2","Specimen label","16DG_27",""
"3","Maximum Load","0.05222","N"
"4","Time","Extension","Load"
"5","(s)","(mm)","(N)"
"6","0.00000","0.00000","0.00033"
"64","0.34800","0.02900","0.00100"
"122","0.69600","0.05824","0.00278"
"180","1.04400","0.08717","0.00357"
"238","1.39200","0.11623","0.00383"
"296","1.74000","0.14529","0.00490"
"354","2.08800","0.17417","0.00516"
"412","2.43600","0.20316","0.00620"
"470","2.78400","0.23216","0.00623"
"528","3.13200","0.26116","0.00680"
"586","3.48000","0.29022","0.00690"
"644","3.82800","0.31922","0.00747"
"702","4.17600","0.34821","0.00769"
"760","4.52400","0.37721","0.00819"
"818","4.87200","0.40621","0.00858"
"876","5.22000","0.43521","0.00863"
"934","5.56800","0.46421","0.00914"
"992","5.91600","0.49320","0.00921"
"1050","6.26400","0.52220","0.00946"
"1108","6.61200","0.55126","0.00921"
"1166","6.96000","0.58014","0.01010"
"1224","7.30800","0.60920","0.01009"
"1282","7.65600","0.63819","0.01039"
"1340","8.00400","0.66713","0.01011"
"1398","8.35200","0.69625","0.01054"
"1456","8.70000","0.72519","0.01060"
"1514","9.04800","0.75419","0.01087"
"1572","9.39600","0.78324","0.01075"
"1630","9.74400","0.81218","0.01158"
"1688","10.09200","0.84118","0.01131"
"1746","10.44000","0.87018","0.01165"
"1804","10.78800","0.89917","0.01159"
"1862","11.13600","0.92817","0.01178"
"1920","11.48400","0.95723","0.01197"
"1978","11.83200","0.98617","0.01230"
"2036","12.18000","1.01517","0.01224"
"2094","12.52800","1.04422","0.01225"
"2152","12.87600","1.07316","0.01228"
"2210","13.22400","1.10222","0.01272"
"2268","13.57200","1.13122","0.01255"
"2326","13.92000","1.16016","0.01285"
"2384","14.26800","1.18921","0.01300"
"2442","14.61600","1.21821","0.01282"
"2500","14.96400","1.24715","0.01332"
"2558","15.31200","1.27621","0.01323"
"2616","15.66000","1.30521","0.01354"
"2674","16.00800","1.33414","0.01337"
"2732","16.35600","1.36320","0.01325"
"2790","16.70400","1.39220","0.01381"
"2848","17.05200","1.42120","0.01362"
"2906","17.40000","1.45025","0.01382"
"2964","17.74800","1.47913","0.01362"
"3022","18.09600","1.50825","0.01425"
"3080","18.44400","1.53719","0.01371"
"3138","18.79200","1.56613","0.01432"
"3196","19.14000","1.59524","0.01426"
"3254","19.48800","1.62424","0.01455"
"3312","19.83600","1.65318","0.01441"
"3370","20.18400","1.68224","0.01459"
"3428","20.53200","1.71118","0.01493"
"3486","20.88000","1.74011","0.01453"
"3544","21.22800","1.76917","0.01510"
"3602","21.57600","1.79817","0.01477"
"3660","21.92400","1.82711","0.01493"
"3718","22.27200","1.85623","0.01494"
"3776","22.62000","1.88516","0.01528"
"3834","22.96800","1.91416","0.01543"
"3892","23.31600","1.94322","0.01515"
"3950","23.66400","1.97216","0.01532"
"4008","24.01200","2.00122","0.01542"
"4066","24.36000","2.03021","0.01506"
"4124","24.70800","2.05915","0.01543"
"4182","25.05600","2.08821","0.01554"
"4240","25.40400","2.11721","0.01572"
"4298","25.75200","2.14615","0.01576"
"4356","26.10000","2.17520","0.01593"
"4414","26.44800","2.20420","0.01606"
"4472","26.79600","2.23314","0.01570"
"4530","27.14400","2.26220","0.01578"
"4588","27.49200","2.29119","0.01627"
"4646","27.84000","2.32019","0.01598"
"4704","28.18800","2.34919","0.01596"
"4762","28.53600","2.37819","0.01604"
"4820","28.88400","2.40719","0.01671"
"4878","29.23200","2.43618","0.01678"
"4936","29.58000","2.46518","0.01670"
"4994","29.92800","2.49418","0.01627"
"5052","30.27600","2.52318","0.01666"
"5110","30.62400","2.55218","0.01672"
"5168","30.97200","2.58123","0.01651"
"5226","31.32000","2.61023","0.01706"
"5284","31.66800","2.63917","0.01637"
"5342","32.01600","2.66823","0.01689"
"5400","32.36400","2.69723","0.01668"
"5458","32.71200","2.72616","0.01704"
"5516","33.06000","2.75522","0.01686"
"5574","33.40800","2.78416","0.01707"
"5632","33.75600","2.81316","0.01744"
"5690","34.10400","2.84222","0.01722"
"5748","34.45200","2.87115","0.01703"
"5806","34.80000","2.90015","0.01720"
"5864","35.14800","2.92921","0.01719"
"5922","35.49600","2.95821","0.01716"
"5980","35.84400","2.98720","0.01697"
"6038","36.19200","3.01614","0.01717"
"6096","36.54000","3.04514","0.01755"
"6154","36.88800","3.07420","0.01756"
"6212","37.23600","3.10320","0.01740"
"6270","37.58400","3.13219","0.01730"
"6328","37.93200","3.16125","0.01776"
"6386","38.28000","3.19019","0.01792"
"6444","38.62800","3.21919","0.01790"
"6502","38.97600","3.24819","0.01773"
"6560","39.32400","3.27718","0.01783"
"6618","39.67200","3.30618","0.01777"
"6676","40.02000","3.33518","0.01771"
"6734","40.36800","3.36418","0.01753"
"6792","40.71600","3.39318","0.01766"
"6850","41.06400","3.42223","0.01765"
"6908","41.41200","3.45117","0.01799"
"6966","41.76000","3.48017","0.01794"
"7024","42.10800","3.50923","0.01798"
"7082","42.45600","3.53811","0.01797"
"7140","42.80400","3.56722","0.01821"
"7198","43.15200","3.59622","0.01794"
"7256","43.50000","3.62516","0.01779"
"7314","43.84800","3.65422","0.01836"
"7372","44.19600","3.68315","0.01838"
"7430","44.54400","3.71215","0.01789"
"7488","44.89200","3.74121","0.01818"
"7546","45.24000","3.77021","0.01841"
"7604","45.58800","3.79921","0.01870"
"7662","45.93600","3.82820","0.01822"
"7720","46.28400","3.85720","0.01864"
"7778","46.63200","3.88614","0.01856"
"7836","46.98000","3.91526","0.01850"
"7894","47.32800","3.94414","0.01877"
"7952","47.67600","3.97319","0.01886"
"8010","48.02400","4.00225","0.01860"
"8068","48.37200","4.03113","0.01860"
"8126","48.72000","4.06019","0.01898"
"8184","49.06800","4.08919","0.01904"
"8242","49.41600","4.11812","0.01902"
"8300","49.76400","4.14724","0.01932"
"8358","50.11200","4.17624","0.01912"
"8416","50.46000","4.20518","0.01895"
"8474","50.80800","4.23423","0.01914"
"8532","51.15600","4.26317","0.01903"
"8590","51.50400","4.29217","0.01893"
"8648","51.85200","4.32123","0.01876"
"8706","52.20000","4.35017","0.01911"
"8764","52.54800","4.37922","0.01921"
"8822","52.89600","4.40822","0.01926"
"8880","53.24400","4.43710","0.01917"
"8938","53.59200","4.46622","0.01964"
"8996","53.94000","4.49522","0.01941"
"9054","54.28800","4.52415","0.01956"
"9112","54.63600","4.55321","0.01958"
"9170","54.98400","4.58227","0.01963"
"9228","55.33200","4.61115","0.01988"
"9286","55.68000","4.64021","0.01982"
"9344","56.02800","4.66920","0.01959"
"9402","56.37600","4.69814","0.01968"
"9460","56.72400","4.72714","0.01989"
"9518","57.07200","4.75620","0.01992"
"9576","57.42000","4.78520","0.01997"
"9634","57.76800","4.81419","0.02001"
"9692","58.11600","4.84319","0.01955"
"9750","58.46400","4.87225","0.02027"
"9808","58.81200","4.90119","0.02026"
"9866","59.16000","4.93018","0.02056"
"9924","59.50800","4.95918","0.02051"
"9982","59.85600","4.98824","0.02029"
"10040","60.20400","5.01712","0.02031"
"10098","60.55200","5.04624","0.02002"
"10156","60.90000","5.07523","0.02038"
"10214","61.24800","5.10417","0.02032"
"10272","61.59600","5.13329","0.02041"
"10330","61.94400","5.16217","0.02049"
"10388","62.29200","5.19123","0.02096"
"10446","62.64000","5.22016","0.02053"
"10504","62.98800","5.24916","0.02102"
"10562","63.33600","5.27822","0.02052"
"10620","63.68400","5.30716","0.02074"
"10678","64.03200","5.33616","0.02114"
"10736","64.38000","5.36515","0.02071"
"10794","64.72800","5.39421","0.02118"
"10852","65.07600","5.42315","0.02131"
"10910","65.42400","5.45221","0.02141"
"10968","65.77200","5.48127","0.02102"
"11026","66.12000","5.51008","0.02106"
"11084","66.46800","5.53926","0.02079"
"11142","66.81600","5.56820","0.02123"
"11200","67.16400","5.59714","0.02129"
"11258","67.51200","5.62626","0.02124"
"11316","67.86000","5.65519","0.02131"
"11374","68.20800","5.68419","0.02126"
"11432","68.55600","5.71325","0.02165"
"11490","68.90400","5.74219","0.02145"
"11548","69.25200","5.77118","0.02164"
"11606","69.60000","5.80018","0.02156"
"11664","69.94800","5.82918","0.02150"
"11722","70.29600","5.85818","0.02164"
"11780","70.64400","5.88724","0.02208"
"11838","70.99200","5.91617","0.02188"
"11896","71.34000","5.94523","0.02159"
"11954","71.68800","5.97423","0.02174"
"12012","72.03600","6.00317","0.02142"
"12070","72.38400","6.03217","0.02159"
"12128","72.73200","6.06116","0.02144"
"12186","73.08000","6.09022","0.02196"
"12244","73.42800","6.11922","0.02166"
"12302","73.77600","6.14822","0.02232"
"12360","74.12400","6.17722","0.02223"
"12418","74.47200","6.20621","0.02247"
"12476","74.82000","6.23515","0.02253"
"12534","75.16800","6.26415","0.02191"
"12592","75.51600","6.29327","0.02172"
"12650","75.86400","6.32215","0.02211"
"12708","76.21200","6.35120","0.02195"
"12766","76.56000","6.38026","0.02170"
"12824","76.90800","6.40914","0.02152"
"12882","77.25600","6.43820","0.02198"
"12940","77.60400","6.46719","0.02178"
"12998","77.95200","6.49619","0.02199"
"13056","78.30000","6.52525","0.02208"
"13114","78.64800","6.55419","0.02197"
"13172","78.99600","6.58313","0.02201"
"13230","79.34400","6.61218","0.02189"
"13288","79.69200","6.64118","0.02188"
"13346","80.04000","6.67018","0.02212"
"13404","80.38800","6.69924","0.02230"
"13462","80.73600","6.72818","0.02225"
"13520","81.08400","6.75717","0.02181"
"13578","81.43200","6.78623","0.02185"
"13636","81.78000","6.81517","0.02161"
"13694","82.12800","6.84423","0.02174"
"13752","82.47600","6.87323","0.02225"
"13810","82.82400","6.90216","0.02224"
"13868","83.17200","6.93116","0.02213"
"13926","83.52000","6.96022","0.02196"
"13984","83.86800","6.98916","0.02227"
"14042","84.21600","7.01822","0.02188"
"14100","84.56400","7.04721","0.02247"
"14158","84.91200","7.07621","0.02195"
"14216","85.26000","7.10521","0.02219"
"14274","85.60800","7.13421","0.02259"
"14332","85.95600","7.16314","0.02230"
"14390","86.30400","7.19220","0.02220"
"14448","86.65200","7.22114","0.02153"
"14506","87.00000","7.25020","0.02177"
"14564","87.34800","7.27920","0.02182"
"14622","87.69600","7.30814","0.02172"
"14680","88.04400","7.33719","0.02168"
"14738","88.39200","7.36625","0.02187"
"14796","88.74000","7.39519","0.02198"
"14854","89.08800","7.42419","0.02202"
"14912","89.43600","7.45318","0.02155"
"14970","89.78400","7.48212","0.02167"
"15028","90.13200","7.51118","0.02172"
"15086","90.48000","7.54018","0.02178"
"15144","90.82800","7.56918","0.02177"
"15202","91.17600","7.59823","0.02167"
"15260","91.52400","7.62717","0.02153"
"15318","91.87200","7.65617","0.02166"
"15376","92.22000","7.68517","0.02189"
"15434","92.56800","7.71417","0.02227"
"15492","92.91600","7.74322","0.02188"
"15550","93.26400","7.77222","0.02194"
"15608","93.61200","7.80116","0.02206"
"15666","93.96000","7.83016","0.02168"
"15724","94.30800","7.85921","0.02186"
"15782","94.65600","7.88809","0.02200"
"15840","95.00400","7.91721","0.02176"
"15898","95.35200","7.94621","0.02199"
"15956","95.70000","7.97515","0.02187"
"16014","96.04800","8.00426","0.02187"
"16072","96.39600","8.03320","0.02176"
"16130","96.74400","8.06220","0.02185"
"16188","97.09200","8.09120","0.02208"
"16246","97.44000","8.12020","0.02197"
"16304","97.78800","8.14919","0.02227"
"16362","98.13600","8.17819","0.02210"
"16420","98.48400","8.20719","0.02222"
"16478","98.83200","8.23613","0.02154"
"16536","99.18000","8.26524","0.02205"
"16594","99.52800","8.29412","0.02209"
"16652","99.87600","8.32318","0.02192"
"16710","100.22400","8.35224","0.02184"
"16768","100.57200","8.38118","0.02188"
"16826","100.92000","8.41024","0.02213"
"16884","101.26800","8.43923","0.02197"
"16942","101.61600","8.46817","0.02212"
"17000","101.96400","8.49723","0.02165"
"17058","102.31200","8.52617","0.02223"
"17116","102.66000","8.55516","0.02160"
"17174","103.00800","8.58416","0.02196"
"17232","103.35600","8.61322","0.02166"
"17290","103.70400","8.64216","0.02229"
"17348","104.05200","8.67122","0.02154"
"17406","104.40000","8.70021","0.02172"
"17464","104.74800","8.72921","0.02164"
"17522","105.09600","8.75821","0.02155"
"17580","105.44400","8.78709","0.02128"
"17638","105.79200","8.81621","0.02151"
"17696","106.14000","8.84526","0.02136"
"17754","106.48800","8.87420","0.02154"
"17812","106.83600","8.90314","0.02139"
"17870","107.18400","8.93220","0.02142"
"17928","107.53200","8.96119","0.02141"
"17986","107.88000","8.99019","0.02148"
"18044","108.22800","9.01919","0.02133"
"18102","108.57600","9.04819","0.02170"
"18160","108.92400","9.07725","0.02143"
"18218","109.27200","9.10618","0.02150"
"18276","109.62000","9.13518","0.02154"
"18334","109.96800","9.16424","0.02155"
"18392","110.31600","9.19312","0.02162"
"18450","110.66400","9.22224","0.02156"
"18508","111.01200","9.25117","0.02174"
"18566","111.36000","9.28017","0.02123"
"18624","111.70800","9.30923","0.02108"
"18682","112.05600","9.33823","0.02145"
"18740","112.40400","9.36717","0.02167"
"18798","112.75200","9.39622","0.02152"
"18856","113.10000","9.42522","0.02134"
"18914","113.44800","9.45416","0.02146"
"18972","113.79600","9.48322","0.02119"
"19030","114.14400","9.51216","0.02095"
"19088","114.49200","9.54115","0.02124"
"19146","114.84000","9.57021","0.02106"
"19204","115.18800","9.59915","0.02095"
"19262","115.53600","9.62821","0.02079"
"19320","115.88400","9.65720","0.02120"
"19378","116.23200","9.68614","0.02131"
"19436","116.58000","9.71520","0.02125"
"19494","116.92800","9.74420","0.02127"
"19552","117.27600","9.77320","0.02135"
"19610","117.62400","9.80219","0.02134"
"19668","117.97200","9.83119","0.02133"
"19726","118.32000","9.86013","0.02103"
"19784","118.66800","9.88919","0.02130"
"19842","119.01600","9.91825","0.02103"
"19900","119.36400","9.94712","0.02114"
"19958","119.71200","9.97624","0.02159"
"20016","120.06000","10.00512","0.02126"
"20074","120.40800","10.03418","0.02075"
"20132","120.75600","10.06324","0.02091"
"20190","121.10400","10.09217","0.02108"
"20248","121.45200","10.12117","0.02099"
"20306","121.80000","10.15023","0.02118"
"20364","122.14800","10.17923","0.02131"
"20422","122.49600","10.20817","0.02094"
"20480","122.84400","10.23722","0.02082"
"20538","123.19200","10.26616","0.02089"
"20596","123.54000","10.29516","0.02105"
"20654","123.88800","10.32428","0.02116"
"20712","124.23600","10.35316","0.02122"
"20770","124.58400","10.38221","0.02073"
"20828","124.93200","10.41121","0.02053"
"20886","125.28000","10.44015","0.02109"
"20944","125.62800","10.46921","0.02059"
"21002","125.97600","10.49820","0.02055"
"21060","126.32400","10.52720","0.02076"
"21118","126.67200","10.55620","0.02054"
"21176","127.02000","10.58520","0.02079"
"21234","127.36800","10.61420","0.02084"
"21292","127.71600","10.64326","0.02088"
"21350","128.06400","10.67219","0.02078"
"21408","128.41200","10.70113","0.02064"
"21466","128.76000","10.73019","0.02066"
"21524","129.10800","10.75919","0.02072"
"21582","129.45600","10.78818","0.02119"
"21640","129.80400","10.81724","0.02067"
"21698","130.15200","10.84612","0.02039"
"21756","130.50000","10.87524","0.02041"
"21814","130.84800","10.90418","0.02057"
"21872","131.19600","10.93317","0.02068"
"21930","131.54400","10.96223","0.02050"
"21988","131.89200","10.99123","0.02066"
"22046","132.24000","11.02017","0.02065"
"22104","132.58800","11.04923","0.02052"
"22162","132.93600","11.07816","0.02066"
"22220","133.28400","11.10710","0.02060"
"22278","133.63200","11.13622","0.02053"
"22336","133.98000","11.16516","0.02061"
"22394","134.32800","11.19421","0.02055"
"22452","134.67600","11.22321","0.02061"
"22510","135.02400","11.25215","0.02045"
"22568","135.37200","11.28127","0.02036"
"22626","135.72000","11.31021","0.02056"
"22684","136.06800","11.33921","0.02070"
"22742","136.41600","11.36820","0.02107"
"22800","136.76400","11.39720","0.02086"
"22858","137.11200","11.42614","0.02084"
"22916","137.46000","11.45520","0.02049"
"22974","137.80800","11.48419","0.02082"
"23032","138.15600","11.51313","0.02092"
"23090","138.50400","11.54219","0.02088"
"23148","138.85200","11.57119","0.02076"
"23206","139.20000","11.60019","0.02101"
"23264","139.54800","11.62918","0.02051"
"23322","139.89600","11.65812","0.02103"
"23380","140.24400","11.68724","0.02082"
"23438","140.59200","11.71624","0.02074"
"23496","140.94000","11.74518","0.02060"
"23554","141.28800","11.77417","0.02065"
"23612","141.63600","11.80323","0.02088"
"23670","141.98400","11.83217","0.02094"
"23728","142.33200","11.86123","0.02066"
"23786","142.68000","11.89022","0.02067"
"23844","143.02800","11.91910","0.02110"
"23902","143.37600","11.94822","0.02070"
"23960","143.72400","11.97722","0.02069"
"24018","144.07200","12.00616","0.02101"
"24076","144.42000","12.03522","0.02073"
"24134","144.76800","12.06415","0.02132"
"24192","145.11600","12.09321","0.02085"
"24250","145.46400","12.12215","0.02087"
"24308","145.81200","12.15121","0.02093"
"24366","146.16000","12.18020","0.02090"
"24424","146.50800","12.20920","0.02088"
"24482","146.85600","12.23820","0.02108"
"24540","147.20400","12.26720","0.02068"
"24598","147.55200","12.29626","0.02052"
"24656","147.90000","12.32513","0.02102"
"24714","148.24800","12.35419","0.02089"
"24772","148.59600","12.38319","0.02067"
"24830","148.94400","12.41213","0.02099"
"24888","149.29200","12.44125","0.02116"
"24946","149.64000","12.47024","0.02139"
"25004","149.98800","12.49918","0.02117"
"25062","150.33600","12.52824","0.02070"
"25120","150.68400","12.55718","0.02091"
"25178","151.03200","12.58617","0.02067"
"25236","151.38000","12.61517","0.02114"
"25294","151.72800","12.64417","0.02105"
"25352","152.07600","12.67317","0.02114"
"25410","152.42400","12.70223","0.02103"
"25468","152.77200","12.73110","0.02092"
"25526","153.12000","12.76022","0.02122"
"25584","153.46800","12.78922","0.02092"
"25642","153.81600","12.81816","0.02072"
"25700","154.16400","12.84722","0.02139"
"25758","154.51200","12.87615","0.02099"
"25816","154.86000","12.90521","0.02079"
"25874","155.20800","12.93421","0.02087"
"25932","155.55600","12.96321","0.02112"
"25990","155.90400","12.99215","0.02105"
"26048","156.25200","13.02114","0.02128"
"26106","156.60000","13.05020","0.02089"
"26164","156.94800","13.07920","0.02096"
"26222","157.29600","13.10826","0.02143"
"26280","157.64400","13.13720","0.02107"
"26338","157.99200","13.16619","0.02083"
"26396","158.34000","13.19525","0.02103"
"26454","158.68800","13.22413","0.02139"
"26512","159.03600","13.25319","0.02128"
"26570","159.38400","13.28219","0.02101"
"26628","159.73200","13.31118","0.02101"
"26686","160.08000","13.34024","0.02098"
"26744","160.42800","13.36924","0.02124"
"26802","160.77600","13.39818","0.02153"
"26860","161.12400","13.42724","0.02087"
"26918","161.47200","13.45617","0.02082"
"26976","161.82000","13.48517","0.02129"
"27034","162.16800","13.51423","0.02112"
"27092","162.51600","13.54317","0.02108"
"27150","162.86400","13.57216","0.02094"
"27208","163.21200","13.60116","0.02137"
"27266","163.56000","13.63010","0.02128"
"27324","163.90800","13.65922","0.02093"
"27382","164.25600","13.68816","0.02100"
"27440","164.60400","13.71715","0.02100"
"27498","164.95200","13.74621","0.02136"
"27556","165.30000","13.77521","0.02109"
"27614","165.64800","13.80415","0.02132"
"27672","165.99600","13.83321","0.02157"
"27730","166.34400","13.86220","0.02128"
"27788","166.69200","13.89114","0.02129"
"27846","167.04000","13.92020","0.02145"
"27904","167.38800","13.94920","0.02135"
"27962","167.73600","13.97814","0.02122"
"28020","168.08400","14.00719","0.02135"
"28078","168.43200","14.03613","0.02131"
"28136","168.78000","14.06519","0.02146"
"28194","169.12800","14.09425","0.02134"
"28252","169.47600","14.12313","0.02156"
"28310","169.82400","14.15224","0.02100"
"28368","170.17200","14.18124","0.02182"
"28426","170.52000","14.21012","0.02162"
"28484","170.86800","14.23924","0.02141"
"28542","171.21600","14.26823","0.02142"
"28600","171.56400","14.29711","0.02172"
"28658","171.91200","14.32623","0.02159"
"28716","172.26000","14.35517","0.02158"
"28774","172.60800","14.38417","0.02149"
"28832","172.95600","14.41322","0.02131"
"28890","173.30400","14.44222","0.02174"
"28948","173.65200","14.47122","0.02142"
"29006","174.00000","14.50016","0.02202"
"29064","174.34800","14.52916","0.02215"
"29122","174.69600","14.55821","0.02138"
"29180","175.04400","14.58715","0.02215"
"29238","175.39200","14.61621","0.02134"
"29296","175.74000","14.64515","0.02190"
"29354","176.08800","14.67421","0.02167"
"29412","176.43600","14.70320","0.02150"
"29470","176.78400","14.73220","0.02190"
"29528","177.13200","14.76120","0.02159"
"29586","177.48000","14.79014","0.02175"
"29644","177.82800","14.81920","0.02168"
"29702","178.17600","14.84819","0.02197"
"29760","178.52400","14.87719","0.02198"
"29818","178.87200","14.90619","0.02165"
"29876","179.22000","14.93519","0.02209"
"29934","179.56800","14.96418","0.02189"
"29992","179.91600","14.99318","0.02177"
"30050","180.26400","15.02218","0.02189"
"30108","180.61200","15.05118","0.02180"
"30166","180.96000","15.08024","0.02204"
"30224","181.30800","15.10917","0.02203"
"30282","181.65600","15.13817","0.02214"
"30340","182.00400","15.16717","0.02229"
"30398","182.35200","15.19611","0.02206"
"30456","182.70000","15.22523","0.02210"
"30514","183.04800","15.25422","0.02238"
"30572","183.39600","15.28316","0.02262"
"30630","183.74400","15.31222","0.02198"
"30688","184.09200","15.34122","0.02211"
"30746","184.44000","15.37016","0.02219"
"30804","184.78800","15.39921","0.02248"
"30862","185.13600","15.42821","0.02220"
"30920","185.48400","15.45715","0.02219"
"30978","185.83200","15.48621","0.02218"
"31036","186.18000","15.51515","0.02256"
"31094","186.52800","15.54420","0.02236"
"31152","186.87600","15.57326","0.02232"
"31210","187.22400","15.60208","0.02272"
"31268","187.57200","15.63126","0.02237"
"31326","187.92000","15.66025","0.02200"
"31384","188.26800","15.68913","0.02235"
"31442","188.61600","15.71825","0.02183"
"31500","188.96400","15.74719","0.02226"
"31558","189.31200","15.77619","0.02236"
"31616","189.66000","15.80524","0.02206"
"31674","190.00800","15.83418","0.02251"
"31732","190.35600","15.86324","0.02238"
"31790","190.70400","15.89218","0.02228"
"31848","191.05200","15.92118","0.02256"
"31906","191.40000","15.95017","0.02284"
"31964","191.74800","15.97923","0.02215"
"32022","192.09600","16.00817","0.02265"
"32080","192.44400","16.03723","0.02258"
"32138","192.79200","16.06623","0.02254"
"32196","193.14000","16.09510","0.02235"
"32254","193.48800","16.12416","0.02255"
"32312","193.83600","16.15322","0.02273"
"32370","194.18400","16.18216","0.02296"
"32428","194.53200","16.21121","0.02242"
"32486","194.88000","16.24021","0.02249"
"32544","195.22800","16.26915","0.02276"
"32602","195.57600","16.29821","0.02270"
"32660","195.92400","16.32721","0.02294"
"32718","196.27200","16.35614","0.02291"
"32776","196.62000","16.38526","0.02312"
"32834","196.96800","16.41420","0.02317"
"32892","197.31600","16.44314","0.02290"
"32950","197.66400","16.47220","0.02261"
"33008","198.01200","16.50119","0.02268"
"33066","198.36000","16.53025","0.02273"
"33124","198.70800","16.55919","0.02281"
"33182","199.05600","16.58813","0.02302"
"33240","199.40400","16.61718","0.02298"
"33298","199.75200","16.64624","0.02292"
"33356","200.10000","16.67518","0.02327"
"33414","200.44800","16.70418","0.02341"
"33472","200.79600","16.73324","0.02294"
"33530","201.14400","16.76217","0.02330"
"33588","201.49200","16.79123","0.02299"
"33646","201.84000","16.82017","0.02297"
"33704","202.18800","16.84911","0.02299"
"33762","202.53600","16.87817","0.02334"
"33820","202.88400","16.90717","0.02301"
"33878","203.23200","16.93622","0.02332"
"33936","203.58000","16.96516","0.02362"
"33994","203.92800","16.99416","0.02346"
"34052","204.27600","17.02321","0.02354"
"34110","204.62400","17.05221","0.02357"
"34168","204.97200","17.08109","0.02360"
"34226","205.32000","17.11021","0.02366"
"34284","205.66800","17.13921","0.02364"
"34342","206.01600","17.16815","0.02375"
"34400","206.36400","17.19726","0.02374"
"34458","206.71200","17.22620","0.02407"
"34516","207.06000","17.25520","0.02402"
"34574","207.40800","17.28426","0.02371"
"34632","207.75600","17.31320","0.02387"
"34690","208.10400","17.34219","0.02406"
"34748","208.45200","17.37113","0.02405"
"34806","208.80000","17.40019","0.02409"
"34864","209.14800","17.42919","0.02399"
"34922","209.49600","17.45819","0.02350"
"34980","209.84400","17.48718","0.02368"
"35038","210.19200","17.51612","0.02398"
"35096","210.54000","17.54524","0.02389"
"35154","210.88800","17.57424","0.02391"
"35212","211.23600","17.60323","0.02401"
"35270","211.58400","17.63223","0.02378"
"35328","211.93200","17.66117","0.02370"
"35386","212.28000","17.69023","0.02403"
"35444","212.62800","17.71917","0.02387"
"35502","212.97600","17.74816","0.02413"
"35560","213.32400","17.77722","0.02407"
"35618","213.67200","17.80622","0.02439"
"35676","214.02000","17.83522","0.02405"
"35734","214.36800","17.86422","0.02460"
"35792","214.71600","17.89315","0.02397"
"35850","215.06400","17.92221","0.02469"
"35908","215.41200","17.95127","0.02414"
"35966","215.76000","17.98015","0.02432"
"36024","216.10800","18.00920","0.02426"
"36082","216.45600","18.03820","0.02428"
"36140","216.80400","18.06714","0.02403"
"36198","217.15200","18.09626","0.02448"
"36256","217.50000","18.12520","0.02440"
"36314","217.84800","18.15413","0.02486"
"36372","218.19600","18.18325","0.02458"
"36430","218.54400","18.21219","0.02484"
"36488","218.89200","18.24119","0.02485"
"36546","219.24000","18.27019","0.02453"
"36604","219.58800","18.29924","0.02452"
"36662","219.93600","18.32818","0.02477"
"36720","220.28400","18.35718","0.02414"
"36778","220.63200","18.38618","0.02490"
"36836","220.98000","18.41517","0.02498"
"36894","221.32800","18.44423","0.02469"
"36952","221.67600","18.47311","0.02469"
"37010","222.02400","18.50223","0.02525"
"37068","222.37200","18.53129","0.02492"
"37126","222.72000","18.56017","0.02506"
"37184","223.06800","18.58916","0.02479"
"37242","223.41600","18.61822","0.02539"
"37300","223.76400","18.64716","0.02534"
"37358","224.11200","18.67622","0.02498"
"37416","224.46000","18.70522","0.02543"
"37474","224.80800","18.73415","0.02545"
"37532","225.15600","18.76315","0.02620"
"37590","225.50400","18.79215","0.02554"
"37648","225.85200","18.82121","0.02587"
"37706","226.20000","18.85021","0.02581"
"37764","226.54800","18.87914","0.02621"
"37822","226.89600","18.90826","0.02613"
"37880","227.24400","18.93720","0.02580"
"37938","227.59200","18.96614","0.02611"
"37996","227.94000","18.99513","0.02599"
"38054","228.28800","19.02419","0.02629"
"38112","228.63600","19.05319","0.02633"
"38170","228.98400","19.08219","0.02616"
"38228","229.33200","19.11125","0.02640"
"38286","229.68000","19.14013","0.02656"
"38344","230.02800","19.16924","0.02641"
"38402","230.37600","19.19818","0.02637"
"38460","230.72400","19.22718","0.02614"
"38518","231.07200","19.25624","0.02620"
"38576","231.42000","19.28517","0.02640"
"38634","231.76800","19.31417","0.02631"
"38692","232.11600","19.34323","0.02646"
"38750","232.46400","19.37217","0.02657"
"38808","232.81200","19.40123","0.02691"
"38866","233.16000","19.43016","0.02699"
"38924","233.50800","19.45916","0.02703"
"38982","233.85600","19.48828","0.02729"
"39040","234.20400","19.51722","0.02678"
"39098","234.55200","19.54615","0.02728"
"39156","234.90000","19.57521","0.02678"
"39214","235.24800","19.60421","0.02710"
"39272","235.59600","19.63321","0.02700"
"39330","235.94400","19.66220","0.02708"
"39388","236.29200","19.69114","0.02729"
"39446","236.64000","19.72020","0.02789"
"39504","236.98800","19.74920","0.02732"
"39562","237.33600","19.77820","0.02746"
"39620","237.68400","19.80720","0.02753"
"39678","238.03200","19.83619","0.02777"
"39736","238.38000","19.86519","0.02810"
"39794","238.72800","19.89419","0.02835"
"39852","239.07600","19.92325","0.02830"
"39910","239.42400","19.95218","0.02844"
"39968","239.77200","19.98118","0.02864"
"40026","240.12000","20.01018","0.02835"
"40084","240.46800","20.03912","0.02887"
"40142","240.81600","20.06824","0.02907"
"40200","241.16400","20.09718","0.02900"
"40258","241.51200","20.12617","0.02948"
"40316","241.86000","20.15523","0.02962"
"40374","242.20800","20.18417","0.02984"
"40432","242.55600","20.21317","0.02974"
"40490","242.90400","20.24222","0.03006"
"40548","243.25200","20.27116","0.03062"
"40606","243.60000","20.30016","0.03052"
"40664","243.94800","20.32922","0.03062"
"40722","244.29600","20.35822","0.03100"
"40780","244.64400","20.38715","0.03101"
"40838","244.99200","20.41621","0.03146"
"40896","245.34000","20.44515","0.03197"
"40954","245.68800","20.47421","0.03169"
"41012","246.03600","20.50321","0.03184"
"41070","246.38400","20.53214","0.03178"
"41128","246.73200","20.56120","0.03229"
"41186","247.08000","20.59020","0.03308"
"41244","247.42800","20.61920","0.03268"
"41302","247.77600","20.64820","0.03333"
"41360","248.12400","20.67719","0.03343"
"41418","248.47200","20.70613","0.03411"
"41476","248.82000","20.73519","0.03417"
"41534","249.16800","20.76419","0.03437"
"41592","249.51600","20.79318","0.03418"
"41650","249.86400","20.82224","0.03475"
"41708","250.21200","20.85118","0.03489"
"41766","250.56000","20.88018","0.03559"
"41824","250.90800","20.90918","0.03567"
"41882","251.25600","20.93812","0.03638"
"41940","251.60400","20.96723","0.03600"
"41998","251.95200","20.99617","0.03650"
"42056","252.30000","21.02523","0.03665"
"42114","252.64800","21.05423","0.03667"
"42172","252.99600","21.08316","0.03778"
"42230","253.34400","21.11216","0.03857"
"42288","253.69200","21.14122","0.03916"
"42346","254.04000","21.17016","0.03973"
"42404","254.38800","21.19921","0.03975"
"42462","254.73600","21.22821","0.04050"
"42520","255.08400","21.25715","0.04079"
"42578","255.43200","21.28615","0.04165"
"42636","255.78000","21.31521","0.04170"
"42694","256.12800","21.34409","0.04245"
"42752","256.47600","21.37326","0.04288"
"42810","256.82400","21.40226","0.04308"
"42868","257.17200","21.43120","0.04392"
"42926","257.52000","21.46020","0.04426"
"42984","257.86800","21.48919","0.04470"
"43042","258.21600","21.51813","0.04526"
"43100","258.56400","21.54725","0.04624"
"43158","258.91200","21.57619","0.04639"
"43216","259.26000","21.60513","0.04727"
"43274","259.60800","21.63424","0.04743"
"43332","259.95600","21.66318","0.04781"
"43390","260.30400","21.69218","0.04833"
"43448","260.65200","21.72124","0.04907"
"43506","261.00000","21.75017","0.05012"
"43564","261.34800","21.77924","0.05035"
"43622","261.69600","21.80817","0.05026"
"43680","262.04400","21.83717","0.05131"
"43738","262.39200","21.86617","0.05194"
"43796","262.74000","21.89523","0.05106"
"43854","263.08800","21.92416","0.03625"
"43912","263.43600","21.95316","0.03699"
"43970","263.78400","21.98222","0.03726"
"44028","264.13200","22.01116","0.03522"
"44086","264.48000","22.04022","0.03493"
"44144","264.82800","22.06921","0.03569"
"44202","265.17600","22.09815","0.03804"
"44260","265.52400","22.12721","0.03817"
"44318","265.87200","22.15621","0.03551"
"44376","266.22000","22.18515","0.03412"
"44434","266.56800","22.21420","0.03462"
"44492","266.91600","22.24320","0.03549"
"44550","267.26400","22.27220","0.03425"
"44608","267.61200","22.30114","0.03578"
"44666","267.96000","22.33014","0.03801"
"44724","268.30800","22.35919","0.03888"
"44782","268.65600","22.38825","0.03936"
"44840","269.00400","22.41713","0.03925"
"44898","269.35200","22.44625","0.04075"
"44956","269.70000","22.47524","0.04215"
"45014","270.04800","22.50418","0.04292"
"45072","270.39600","22.53318","0.04311"
"45130","270.74400","22.56218","0.04349"
"45188","271.09200","22.59118","0.04479"
"45246","271.44000","22.62024","0.04487"
"45304","271.78800","22.64923","0.04567"
"45362","272.13600","22.67817","0.04634"
"45420","272.48400","22.70717","0.04758"
"45478","272.83200","22.73623","0.04799"
"45536","273.18000","22.76517","0.04895"
"45594","273.52800","22.79422","0.04900"
"45652","273.87600","22.82310","0.05040"
"45710","274.22400","22.85216","0.05046"
"45768","274.57200","22.88128","0.05197"
"45826","274.92000","22.91015","0.04736"
"45884","275.26800","22.93927","0.02472"
"45942","275.61600","22.96821","0.02454"
"46000","275.96400","22.99721","0.02442"
"46058","276.31200","23.02621","0.02479"
"46116","276.66000","23.05514","0.02375"
"46174","277.00800","23.08420","0.02423"
"46232","277.35600","23.11320","0.02439"
"46290","277.70400","23.14220","0.02454"
"46348","278.05200","23.17120","0.02467"
"46406","278.40000","23.20019","0.02493"
"46464","278.74800","23.22913","0.02472"
"46522","279.09600","23.25819","0.02496"
"46580","279.44400","23.28725","0.02494"
"46638","279.79200","23.31618","0.02490"
"46696","280.14000","23.34524","0.02471"
"46754","280.48800","23.37418","0.02525"
"46812","280.83600","23.40318","0.02565"
"46870","281.18400","23.43218","0.02499"
"46928","281.53200","23.46123","0.02521"
"46986","281.88000","23.49017","0.02514"
"47044","282.22800","23.51923","0.02535"
"47102","282.57600","23.54817","0.02529"
"47160","282.92400","23.57717","0.02549"
"47218","283.27200","23.60616","0.02557"
"47276","283.62000","23.63516","0.02571"
"47334","283.96800","23.66416","0.02573"
"47392","284.31600","23.69322","0.02600"
"47450","284.66400","23.72215","0.02614"
"47508","285.01200","23.75121","0.02608"
"47566","285.36000","23.78015","0.02629"
"47624","285.70800","23.80915","0.02600"
"47682","286.05600","23.83821","0.02615"
"47740","286.40400","23.86720","0.02666"
"47798","286.75200","23.89608","0.02619"
"47856","287.10000","23.92520","0.02650"
"47914","287.44800","23.95426","0.02697"
"47972","287.79600","23.98314","0.02711"
"48030","288.14400","24.01220","0.02641"
"48088","288.49200","24.04119","0.02708"
"48146","288.84000","24.07013","0.02717"
"48204","289.18800","24.09919","0.02758"
"48262","289.53600","24.12819","0.02740"
"48320","289.88400","24.15718","0.02706"
"48378","290.23200","24.18624","0.02760"
"48436","290.58000","24.21512","0.02726"
"48494","290.92800","24.24418","0.02729"
"48552","291.27600","24.27317","0.02762"
"48610","291.62400","24.30217","0.02739"
"48668","291.97200","24.33117","0.02795"
"48726","292.32000","24.36023","0.02748"
"48784","292.66800","24.38911","0.02784"
"48842","293.01600","24.41823","0.02796"
"48900","293.36400","24.44722","0.02787"
"48958","293.71200","24.47616","0.02826"
"49016","294.06000","24.50522","0.02806"
"49074","294.40800","24.53422","0.02836"
"49132","294.75600","24.56316","0.02827"
"49190","295.10400","24.59221","0.02817"
"49248","295.45200","24.62115","0.02832"
"49306","295.80000","24.65021","0.02804"
"49364","296.14800","24.67914","0.02808"
"49422","296.49600","24.70820","0.02846"
"49480","296.84400","24.73714","0.02853"
"49538","297.19200","24.76620","0.02854"
"49596","297.54000","24.79514","0.02837"
"49654","297.88800","24.82420","0.02878"
"49712","298.23600","24.85325","0.02847"
"49770","298.58400","24.88213","0.02817"
"49828","298.93200","24.91125","0.02865"
"49886","299.28000","24.94025","0.02885"
"49944","299.62800","24.96919","0.02901"
"50002","299.97600","24.99824","0.02846"
"50060","300.32400","25.02718","0.02888"
"50118","300.67200","25.05612","0.02856"
"50176","301.02000","25.08517","0.02892"
"50234","301.36800","25.11418","0.02867"
"50292","301.71600","25.14318","0.02835"
"50350","302.06400","25.17217","0.02846"
"50408","302.41200","25.20117","0.02871"
"50466","302.76000","25.23017","0.02880"
"50524","303.10800","25.25922","0.02783"
"50582","303.45600","25.28816","0.02746"
"50640","303.80400","25.31716","0.02721"
"50698","304.15200","25.34616","0.02741"
"50756","304.50000","25.37516","0.02754"
"50814","304.84800","25.40421","0.02735"
"50872","305.19600","25.43321","0.02743"
"50930","305.54400","25.46221","0.02719"
"50988","305.89200","25.49121","0.02750"
"51046","306.24000","25.52021","0.02717"
"51104","306.58800","25.54914","0.02802"
"51162","306.93600","25.57820","0.02736"
"51220","307.28400","25.60720","0.02795"
"51278","307.63200","25.63620","0.02793"
"51336","307.98000","25.66519","0.02851"
"51394","308.32800","25.69413","0.02796"
"51452","308.67600","25.72319","0.02779"
"51510","309.02400","25.75219","0.02848"
"51568","309.37200","25.78113","0.02836"
"51626","309.72000","25.81019","0.02830"
"51684","310.06800","25.83918","0.02854"
"51742","310.41600","25.86818","0.02874"
"51800","310.76400","25.89724","0.02850"
"51858","311.11200","25.92618","0.02892"
"51916","311.46000","25.95518","0.02877"
"51974","311.80800","25.98423","0.02889"
"52032","312.15600","26.01323","0.02939"
"52090","312.50400","26.04217","0.02914"
"52148","312.85200","26.07122","0.02908"
"52206","313.20000","26.10017","0.02923"
"52264","313.54800","26.12916","0.02937"
"52322","313.89600","26.15822","0.02959"
"52380","314.24400","26.18716","0.03013"
"52438","314.59200","26.21622","0.02958"
"52496","314.94000","26.24521","0.02961"
"52554","315.28800","26.27415","0.03055"
"52612","315.63600","26.30321","0.03047"
"52670","315.98400","26.33221","0.03046"
"52728","316.33200","26.36115","0.03044"
"52786","316.68000","26.39014","0.03072"
"52844","317.02800","26.41926","0.03072"
"52902","317.37600","26.44820","0.03041"
"52960","317.72400","26.47726","0.03050"
"53018","318.07200","26.50620","0.03093"
"53076","318.42000","26.53519","0.03146"
"53134","318.76800","26.56419","0.03102"
"53192","319.11600","26.59319","0.03092"
"53250","319.46400","26.62219","0.03163"
"53308","319.81200","26.65118","0.03140"
"53366","320.16000","26.68018","0.03179"
"53424","320.50800","26.70918","0.03157"
"53482","320.85600","26.73824","0.03162"
"53540","321.20400","26.76718","0.03176"
"53598","321.55200","26.79617","0.03195"
"53656","321.90000","26.82523","0.03244"
"53714","322.24800","26.85417","0.03211"
"53772","322.59600","26.88317","0.03292"
"53830","322.94400","26.91217","0.03286"
"53888","323.29200","26.94117","0.03269"
"53946","323.64000","26.97028","0.03306"
"54004","323.98800","26.99922","0.03369"
"54062","324.33600","27.02816","0.03377"
"54120","324.68400","27.05716","0.03412"
"54178","325.03200","27.08615","0.03367"
"54236","325.38000","27.11515","0.03391"
"54294","325.72800","27.14421","0.03402"
"54352","326.07600","27.17321","0.03422"
"54410","326.42400","27.20220","0.03463"
"54468","326.77200","27.23120","0.03433"
"54526","327.12000","27.26014","0.03451"
"54584","327.46800","27.28920","0.03405"
"54642","327.81600","27.31820","0.03378"
"54700","328.16400","27.34713","0.03435"
"54758","328.51200","27.37625","0.03427"
"54816","328.86000","27.40519","0.03467"
"54874","329.20800","27.43419","0.03525"
"54932","329.55600","27.46318","0.03486"
"54990","329.90400","27.49219","0.03482"
"55048","330.25200","27.52118","0.03546"
"55106","330.60000","27.55018","0.03554"
"55164","330.94800","27.57918","0.03635"
"55222","331.29600","27.60812","0.03581"
"55280","331.64400","27.63723","0.03670"
"55338","331.99200","27.66617","0.03662"
"55396","332.34000","27.69523","0.03676"
"55454","332.68800","27.72429","0.03610"
"55512","333.03600","27.75311","0.03627"
"55570","333.38400","27.78222","0.03681"
"55628","333.73200","27.81122","0.03676"
"55686","334.08000","27.84016","0.03616"
"55744","334.42800","27.86922","0.03662"
"55802","334.77600","27.89816","0.03755"
"55860","335.12400","27.92715","0.03691"
"55918","335.47200","27.95621","0.03700"
"55976","335.82000","27.98515","0.03759"
"56034","336.16800","28.01421","0.03724"
"56092","336.51600","28.04320","0.03770"
"56150","336.86400","28.07214","0.03785"
"56208","337.21200","28.10120","0.03762"
"56266","337.56000","28.13020","0.03814"
"56324","337.90800","28.15914","0.03789"
"56382","338.25600","28.18819","0.03781"
"56440","338.60400","28.21725","0.03756"
"56498","338.95200","28.24619","0.03839"
"56556","339.30000","28.27519","0.03896"
"56614","339.64800","28.30419","0.03796"
"56672","339.99600","28.33318","0.03856"
"56730","340.34400","28.36218","0.02951"
"56788","340.69200","28.39124","0.02960"
"56846","341.04000","28.42018","0.02972"
"56904","341.38800","28.44924","0.02935"
"56962","341.73600","28.47818","0.02729"
"57020","342.08400","28.50717","0.02816"
"57078","342.43200","28.53617","0.02862"
"57136","342.78000","28.56511","0.02875"
"57194","343.12800","28.59422","0.02976"
"57252","343.47600","28.62322","0.02828"
"57310","343.82400","28.65216","0.02905"
"57368","344.17200","28.68122","0.02925"
"57426","344.52000","28.71016","0.02938"
"57484","344.86800","28.73915","0.02990"
"57542","345.21600","28.76821","0.02951"
"57600","345.56400","28.79721","0.02991"
"57658","345.91200","28.82615","0.02976"
"57716","346.26000","28.85521","0.03022"
"57774","346.60800","28.88421","0.03057"
"57832","346.95600","28.91314","0.03039"
"57890","347.30400","28.94220","0.03047"
"57948","347.65200","28.97120","0.03045"
"58006","348.00000","29.00019","0.03079"
"58064","348.34800","29.02919","0.03107"
"58122","348.69600","29.05819","0.03139"
"58180","349.04400","29.08719","0.03158"
"58238","349.39200","29.11619","0.03100"
"58296","349.74000","29.14519","0.03133"
"58354","350.08800","29.17418","0.03219"
"58412","350.43600","29.20324","0.03212"
"58470","350.78400","29.23212","0.03185"
"58528","351.13200","29.26124","0.03217"
"58586","351.48000","29.29024","0.03214"
"58644","351.82800","29.31917","0.03205"
"58702","352.17600","29.34823","0.03217"
"58760","352.52400","29.37717","0.03201"
"58818","352.87200","29.40617","0.03203"
"58876","353.22000","29.43522","0.03227"
"58934","353.56800","29.46416","0.03221"
"58992","353.91600","29.49328","0.03255"
"59050","354.26400","29.52216","0.03250"
"59108","354.61200","29.55116","0.03234"
"59166","354.96000","29.58016","0.03260"
"59224","355.30800","29.60921","0.03250"
"59282","355.65600","29.63815","0.03266"
"59340","356.00400","29.66715","0.03227"
"59398","356.35200","29.69627","0.03284"
"59456","356.70000","29.72514","0.03330"
"59514","357.04800","29.75420","0.03306"
"59572","357.39600","29.78320","0.03279"
"59630","357.74400","29.81214","0.03023"
"59688","358.09200","29.84120","0.03016"
"59746","358.44000","29.87020","0.03088"
"59804","358.78800","29.89913","0.03034"
"59862","359.13600","29.92825","0.03091"
"59920","359.48400","29.95719","0.03105"
"59978","359.83200","29.98618","0.03093"
"60036","360.18000","30.01518","0.03168"
"60094","360.52800","30.04418","0.03116"
"60152","360.87600","30.07318","0.03176"
"60210","361.22400","30.10224","0.03184"
"60268","361.57200","30.13112","0.03220"
"60326","361.92000","30.16023","0.03231"
"60384","362.26800","30.18923","0.03220"
"60442","362.61600","30.21817","0.03234"
"60500","362.96400","30.24723","0.03240"
"60558","363.31200","30.27617","0.03277"
"60616","363.66000","30.30522","0.03236"
"60674","364.00800","30.33422","0.03288"
"60732","364.35600","30.36322","0.03221"
"60790","364.70400","30.39216","0.03266"
"60848","365.05200","30.42115","0.03279"
"60906","365.40000","30.45015","0.03318"
"60964","365.74800","30.47909","0.03229"
"61022","366.09600","30.50821","0.03249"
"61080","366.44400","30.53721","0.03321"
"61138","366.79200","30.56620","0.03280"
"61196","367.14000","30.59526","0.03293"
"61254","367.48800","30.62414","0.03326"
"61312","367.83600","30.65320","0.03330"
"61370","368.18400","30.68220","0.03355"
"61428","368.53200","30.71113","0.03338"
"61486","368.88000","30.74019","0.03401"
"61544","369.22800","30.76919","0.03365"
"61602","369.57600","30.79813","0.03430"
"61660","369.92400","30.82719","0.03399"
"61718","370.27200","30.85618","0.03373"
"61776","370.62000","30.88518","0.03330"
"61834","370.96800","30.91424","0.03316"
"61892","371.31600","30.94318","0.03209"
"61950","371.66400","30.97218","0.03357"
"62008","372.01200","31.00117","0.03328"
"62066","372.36000","31.03017","0.03369"
"62124","372.70800","31.05923","0.03321"
"62182","373.05600","31.08817","0.03244"
"62240","373.40400","31.11716","0.03311"
"62298","373.75200","31.14616","0.03297"
"62356","374.10000","31.17516","0.03304"
"62414","374.44800","31.20416","0.03392"
"62472","374.79600","31.23322","0.03371"
"62530","375.14400","31.26221","0.03356"
"62588","375.49200","31.29115","0.03338"
"62646","375.84000","31.32021","0.03414"
"62704","376.18800","31.34914","0.03443"
"62762","376.53600","31.37814","0.03403"
"62820","376.88400","31.40726","0.03459"
"62878","377.23200","31.43614","0.03379"
"62936","377.58000","31.46526","0.03418"
"62994","377.92800","31.49420","0.03448"
"63052","378.27600","31.52313","0.03484"
"63110","378.62400","31.55219","0.03462"
"63168","378.97200","31.58125","0.03532"
"63226","379.32000","31.61019","0.03525"
"63284","379.66800","31.63924","0.03532"
"63342","380.01600","31.66818","0.03550"
"63400","380.36400","31.69712","0.03546"
"63458","380.71200","31.72618","0.03606"
"63516","381.06000","31.75524","0.03585"
"63574","381.40800","31.78417","0.03555"
"63632","381.75600","31.81323","0.03605"
"63690","382.10400","31.84217","0.03649"
"63748","382.45200","31.87117","0.03631"
"63806","382.80000","31.90017","0.03684"
"63864","383.14800","31.92916","0.03713"
"63922","383.49600","31.95822","0.03725"
"63980","383.84400","31.98722","0.03737"
"64038","384.19200","32.01616","0.03769"
"64096","384.54000","32.04515","0.03706"
"64154","384.88800","32.07427","0.03791"
"64212","385.23600","32.10315","0.03790"
"64270","385.58400","32.13221","0.03732"
"64328","385.93200","32.16121","0.03776"
"64386","386.28000","32.19014","0.03817"
"64444","386.62800","32.21926","0.03769"
"64502","386.97600","32.24820","0.03843"
"64560","387.32400","32.27720","0.03714"
"64618","387.67200","32.30626","0.03766"
"64676","388.02000","32.33514","0.03752"
"64734","388.36800","32.36413","0.03776"
"64792","388.71600","32.39319","0.03825"
"64850","389.06400","32.42219","0.03852"
"64908","389.41200","32.45119","0.03833"
"64966","389.76000","32.48030","0.03898"
"65024","390.10800","32.50912","0.03919"
"65082","390.45600","32.53818","0.03865"
"65140","390.80400","32.56724","0.03946"
"65198","391.15200","32.59612","0.03958"
"65256","391.50000","32.62518","0.03987"
"65314","391.84800","32.65417","0.04002"
"65372","392.19600","32.68317","0.03973"
"65430","392.54400","32.71223","0.04072"
"65488","392.89200","32.74123","0.04081"
"65546","393.24000","32.77016","0.04093"
"65604","393.58800","32.79916","0.04119"
"65662","393.93600","32.82822","0.04111"
"65720","394.28400","32.85716","0.04109"
"65778","394.63200","32.88622","0.04154"
"65836","394.98000","32.91515","0.04168"
"65894","395.32800","32.94415","0.04233"
"65952","395.67600","32.97321","0.04178"
"66010","396.02400","33.00215","0.04148"
"66068","396.37200","33.03121","0.04107"
"66126","396.72000","33.06020","0.04191"
"66184","397.06800","33.08914","0.04185"
"66242","397.41600","33.11820","0.04242"
"66300","397.76400","33.14714","0.04262"
"66358","398.11200","33.17619","0.04175"
"66416","398.46000","33.20519","0.04246"
"66474","398.80800","33.23419","0.04181"
"66532","399.15600","33.26319","0.04243"
"66590","399.50400","33.29219","0.04244"
"66648","399.85200","33.32118","0.04311"
"66706","400.20000","33.35018","0.04083"
"66764","400.54800","33.37918","0.04074"
"66822","400.89600","33.40818","0.04125"
"66880","401.24400","33.43724","0.04188"
"66938","401.59200","33.46618","0.04151"
"66996","401.94000","33.49517","0.04165"
"67054","402.28800","33.52423","0.04185"
"67112","402.63600","33.55323","0.04042"
"67170","402.98400","33.58216","0.04036"
"67228","403.33200","33.61116","0.04141"
"67286","403.68000","33.64022","0.04109"
"67344","404.02800","33.66910","0.04188"
"67402","404.37600","33.69816","0.04180"
"67460","404.72400","33.72721","0.04242"
"67518","405.07200","33.75615","0.04223"
"67576","405.42000","33.78527","0.04253"
"67634","405.76800","33.81415","0.04262"
"67692","406.11600","33.84321","0.04228"
"67750","406.46400","33.87221","0.04301"
"67808","406.81200","33.90114","0.04325"
"67866","407.16000","33.93020","0.04314"
"67924","407.50800","33.95920","0.04317"
"67982","407.85600","33.98814","0.04341"
"68040","408.20400","34.01714","0.04277"
"68098","408.55200","34.04625","0.04277"
"68156","408.90000","34.07519","0.04277"
"68214","409.24800","34.10419","0.04359"
"68272","409.59600","34.13319","0.04370"
"68330","409.94400","34.16212","0.04358"
"68388","410.29200","34.19124","0.04398"
"68446","410.64000","34.22024","0.04379"
"68504","410.98800","34.24918","0.04400"
"68562","411.33600","34.27824","0.04421"
"68620","411.68400","34.30711","0.04452"
"68678","412.03200","34.33617","0.04475"
"68736","412.38000","34.36517","0.04452"
"68794","412.72800","34.39417","0.04425"
"68852","413.07600","34.42316","0.04463"
"68910","413.42400","34.45222","0.04457"
"68968","413.77200","34.48116","0.04477"
"69026","414.12000","34.51022","0.04426"
"69084","414.46800","34.53915","0.04417"
"69142","414.81600","34.56809","0.04437"
"69200","415.16400","34.59727","0.04453"
"69258","415.51200","34.62621","0.04464"
"69316","415.86000","34.65521","0.04509"
"69374","416.20800","34.68421","0.04524"
"69432","416.55600","34.71320","0.04515"
"69490","416.90400","34.74220","0.04528"
"69548","417.25200","34.77120","0.04526"
"69606","417.60000","34.80020","0.04543"
"69664","417.94800","34.82914","0.04542"
"69722","418.29600","34.85819","0.04498"
"69780","418.64400","34.88719","0.04404"
"69838","418.99200","34.91613","0.04466"
"69896","419.34000","34.94525","0.04534"
"69954","419.68800","34.97419","0.04563"
"70012","420.03600","35.00325","0.04561"
"70070","420.38400","35.03224","0.04540"
"70128","420.73200","35.06112","0.04560"
"70186","421.08000","35.09018","0.04575"
"70244","421.42800","35.11917","0.04585"
"70302","421.77600","35.14817","0.04594"
"70360","422.12400","35.17723","0.04602"
"70418","422.47200","35.20623","0.04609"
"70476","422.82000","35.23517","0.04670"
"70534","423.16800","35.26423","0.04656"
"70592","423.51600","35.29316","0.04715"
"70650","423.86400","35.32222","0.04656"
"70708","424.21200","35.35122","0.04645"
"70766","424.56000","35.38010","0.04678"
"70824","424.90800","35.40921","0.04682"
"70882","425.25600","35.43821","0.04717"
"70940","425.60400","35.46715","0.04732"
"70998","425.95200","35.49621","0.04727"
"71056","426.30000","35.52521","0.04734"
"71114","426.64800","35.55415","0.04780"
"71172","426.99600","35.58320","0.03900"
"71230","427.34400","35.61220","0.03988"
"71288","427.69200","35.64114","0.04033"
"71333","427.96000","35.66356","0.04045"