File: Trajectories_together/161226_1Specimen_RawData_8.csv
"","V1","V2","V3"
"1","End date","12/26/2016",""
"2","Specimen label","22AG_77",""
"3","Maximum Load","0.13139","N"
"4","Time","Extension","Load"
"5","(s)","(mm)","(N)"
"6","0.00000","0.00000","-0.00021"
"76","0.42000","0.03522","-0.00013"
"146","0.84000","0.07019","-0.00052"
"216","1.26000","0.10517","0.00027"
"286","1.68000","0.14015","-0.00026"
"356","2.10000","0.17512","-0.00034"
"426","2.52000","0.21022","0.00046"
"496","2.94000","0.24514","-0.00030"
"566","3.36000","0.28017","-0.00012"
"636","3.78000","0.31515","-0.00015"
"706","4.20000","0.35013","-0.00033"
"776","4.62000","0.38516","-0.00039"
"846","5.04000","0.42014","0.00005"
"916","5.46000","0.45512","0.00019"
"986","5.88000","0.49009","-0.00002"
"1056","6.30000","0.52513","0.00016"
"1126","6.72000","0.56017","0.00062"
"1196","7.14000","0.59515","0.00004"
"1266","7.56000","0.63012","0.00034"
"1336","7.98000","0.66516","-0.00042"
"1406","8.40000","0.70014","-0.00006"
"1476","8.82000","0.73517","-0.00010"
"1546","9.24000","0.77015","-0.00077"
"1616","9.66000","0.80513","-0.00035"
"1686","10.08000","0.84016","-0.00048"
"1756","10.50000","0.87514","-0.00025"
"1826","10.92000","0.91018","0.00016"
"1896","11.34000","0.94509","0.00015"
"1966","11.76000","0.98013","0.00050"
"2036","12.18000","1.01517","0.00018"
"2106","12.60000","1.05014","0.00020"
"2176","13.02000","1.08512","-0.00034"
"2246","13.44000","1.12010","-0.00014"
"2316","13.86000","1.15519","-0.00010"
"2386","14.28000","1.19023","0.00004"
"2456","14.70000","1.22515","0.00000"
"2526","15.12000","1.26012","-0.00076"
"2596","15.54000","1.29516","-0.00019"
"2666","15.96000","1.33014","-0.00043"
"2736","16.38000","1.36517","-0.00020"
"2806","16.80000","1.40015","-0.00024"
"2876","17.22000","1.43507","-0.00064"
"2946","17.64000","1.47011","-0.00032"
"3016","18.06000","1.50520","0.00003"
"3086","18.48000","1.54018","-0.00008"
"3156","18.90000","1.57516","-0.00042"
"3226","19.32000","1.61007","0.00046"
"3296","19.74000","1.64517","-0.00025"
"3366","20.16000","1.68021","0.00002"
"3436","20.58000","1.71518","-0.00011"
"3506","21.00000","1.75016","0.00001"
"3576","21.42000","1.78514","0.00025"
"3646","21.84000","1.82023","-0.00078"
"3716","22.26000","1.85515","0.00002"
"3786","22.68000","1.89013","0.00008"
"3856","23.10000","1.92510","-0.00030"
"3926","23.52000","1.96014","-0.00015"
"3996","23.94000","1.99518","0.00029"
"4066","24.36000","2.03015","-0.00040"
"4136","24.78000","2.06507","-0.00014"
"4206","25.20000","2.10017","0.00047"
"4276","25.62000","2.13514","0.00041"
"4346","26.04000","2.17018","-0.00019"
"4416","26.46000","2.20516","0.00015"
"4486","26.88000","2.24013","0.00041"
"4556","27.30000","2.27517","0.00041"
"4626","27.72000","2.31015","0.00033"
"4696","28.14000","2.34518","-0.00017"
"4766","28.56000","2.38010","-0.00040"
"4836","28.98000","2.41508","0.00021"
"4906","29.40000","2.45017","-0.00032"
"4976","29.82000","2.48515","-0.00021"
"5046","30.24000","2.52007","-0.00033"
"5116","30.66000","2.55505","-0.00011"
"5186","31.08000","2.59014","0.00007"
"5256","31.50000","2.62518","-0.00019"
"5326","31.92000","2.66016","0.00022"
"5396","32.34000","2.69513","0.00012"
"5466","32.76000","2.73017","-0.00032"
"5536","33.18000","2.76515","0.00008"
"5606","33.60000","2.80018","0.00030"
"5676","34.02000","2.83516","0.00006"
"5746","34.44000","2.87014","0.00017"
"5816","34.86000","2.90511","-0.00029"
"5886","35.28000","2.94015","0.00038"
"5956","35.70000","2.97525","0.00027"
"6026","36.12000","3.01016","0.00023"
"6096","36.54000","3.04508","-0.00003"
"6166","36.96000","3.08018","-0.00011"
"6236","37.38000","3.11521","0.00035"
"6306","37.80000","3.15019","-0.00002"
"6376","38.22000","3.18511","0.00014"
"6446","38.64000","3.22014","-0.00033"
"6516","39.06000","3.25518","-0.00002"
"6586","39.48000","3.29016","0.00021"
"6656","39.90000","3.32513","0.00027"
"6726","40.32000","3.36005","-0.00028"
"6796","40.74000","3.39515","-0.00036"
"6866","41.16000","3.43013","0.00010"
"6936","41.58000","3.46516","-0.00024"
"7006","42.00000","3.50014","0.00001"
"7076","42.42000","3.53512","0.00014"
"7146","42.84000","3.57015","-0.00078"
"7216","43.26000","3.60519","-0.00017"
"7286","43.68000","3.64017","0.00022"
"7356","44.10000","3.67514","0.00007"
"7426","44.52000","3.71018","0.00014"
"7496","44.94000","3.74516","0.00002"
"7566","45.36000","3.78019","0.00035"
"7636","45.78000","3.81511","-0.00030"
"7706","46.20000","3.85015","0.00058"
"7776","46.62000","3.88518","0.00020"
"7846","47.04000","3.92022","0.00000"
"7916","47.46000","3.95514","0.00013"
"7986","47.88000","3.99005","0.00011"
"8056","48.30000","4.02515","0.00054"
"8126","48.72000","4.06019","0.00025"
"8196","49.14000","4.09522","0.00054"
"8266","49.56000","4.13014","0.00048"
"8336","49.98000","4.16518","0.00078"
"8406","50.40000","4.20021","0.00045"
"8476","50.82000","4.23519","0.00019"
"8546","51.24000","4.27011","0.00001"
"8616","51.66000","4.30509","0.00074"
"8686","52.08000","4.34012","-0.00008"
"8756","52.50000","4.37522","0.00053"
"8826","52.92000","4.41014","0.00062"
"8896","53.34000","4.44511","0.00084"
"8966","53.76000","4.48009","0.00081"
"9036","54.18000","4.51519","0.00021"
"9106","54.60000","4.55016","0.00069"
"9176","55.02000","4.58520","0.00053"
"9246","55.44000","4.62018","0.00093"
"9316","55.86000","4.65515","0.00046"
"9386","56.28000","4.69019","-0.00036"
"9456","56.70000","4.72517","0.00061"
"9526","57.12000","4.76014","0.00071"
"9596","57.54000","4.79512","0.00048"
"9666","57.96000","4.83016","0.00052"
"9736","58.38000","4.86519","0.00029"
"9806","58.80000","4.90017","0.00043"
"9876","59.22000","4.93509","0.00086"
"9946","59.64000","4.97012","0.00052"
"10016","60.06000","5.00516","0.00074"
"10086","60.48000","5.04020","0.00040"
"10156","60.90000","5.07511","0.00102"
"10226","61.32000","5.11015","0.00053"
"10296","61.74000","5.14519","0.00120"
"10366","62.16000","5.18017","0.00060"
"10436","62.58000","5.21514","0.00063"
"10506","63.00000","5.25012","0.00056"
"10576","63.42000","5.28510","0.00032"
"10646","63.84000","5.32019","0.00062"
"10716","64.26000","5.35517","0.00040"
"10786","64.68000","5.39015","0.00055"
"10856","65.10000","5.42512","0.00060"
"10926","65.52000","5.46016","0.00090"
"10996","65.94000","5.49520","0.00077"
"11066","66.36000","5.53017","0.00015"
"11136","66.78000","5.56515","0.00082"
"11206","67.20000","5.60019","0.00065"
"11276","67.62000","5.63510","0.00066"
"11346","68.04000","5.67014","0.00082"
"11416","68.46000","5.70518","0.00093"
"11486","68.88000","5.74003","0.00103"
"11556","69.30000","5.77507","0.00071"
"11626","69.72000","5.81017","0.00102"
"11696","70.14000","5.84514","0.00084"
"11766","70.56000","5.88012","0.00108"
"11836","70.98000","5.91510","0.00087"
"11906","71.40000","5.95014","0.00006"
"11976","71.82000","5.98517","0.00071"
"12046","72.24000","6.02021","0.00106"
"12116","72.66000","6.05513","0.00071"
"12186","73.08000","6.09010","0.00033"
"12256","73.50000","6.12520","0.00078"
"12326","73.92000","6.16017","0.00082"
"12396","74.34000","6.19515","0.00078"
"12466","74.76000","6.23013","0.00034"
"12536","75.18000","6.26517","0.00059"
"12606","75.60000","6.30014","0.00080"
"12676","76.02000","6.33518","0.00062"
"12746","76.44000","6.37010","0.00069"
"12816","76.86000","6.40513","0.00083"
"12886","77.28000","6.44017","0.00083"
"12956","77.70000","6.47521","0.00089"
"13026","78.12000","6.51018","0.00114"
"13096","78.54000","6.54510","0.00092"
"13166","78.96000","6.58020","0.00120"
"13236","79.38000","6.61517","0.00128"
"13306","79.80000","6.65015","0.00103"
"13376","80.22000","6.68507","0.00077"
"13446","80.64000","6.72016","0.00129"
"13516","81.06000","6.75514","0.00123"
"13586","81.48000","6.79018","0.00124"
"13656","81.90000","6.82516","0.00132"
"13726","82.32000","6.86013","0.00045"
"13796","82.74000","6.89517","0.00094"
"13866","83.16000","6.93020","0.00137"
"13936","83.58000","6.96518","0.00172"
"14006","84.00000","7.00016","0.00100"
"14076","84.42000","7.03514","0.00096"
"14146","84.84000","7.07017","0.00118"
"14216","85.26000","7.10515","0.00158"
"14286","85.68000","7.14013","0.00114"
"14356","86.10000","7.17504","0.00076"
"14426","86.52000","7.21008","0.00098"
"14496","86.94000","7.24518","0.00097"
"14566","87.36000","7.28015","0.00118"
"14636","87.78000","7.31513","0.00114"
"14706","88.20000","7.35005","0.00086"
"14776","88.62000","7.38514","0.00130"
"14846","89.04000","7.42018","0.00113"
"14916","89.46000","7.45522","0.00104"
"14986","89.88000","7.49013","0.00141"
"15056","90.30000","7.52517","0.00096"
"15126","90.72000","7.56021","0.00088"
"15196","91.14000","7.59518","0.00088"
"15266","91.56000","7.63010","0.00103"
"15336","91.98000","7.66514","0.00138"
"15406","92.40000","7.70011","0.00065"
"15476","92.82000","7.73515","0.00105"
"15546","93.24000","7.77013","0.00088"
"15616","93.66000","7.80510","0.00114"
"15686","94.08000","7.84014","0.00105"
"15756","94.50000","7.87512","0.00076"
"15826","94.92000","7.91021","0.00101"
"15896","95.34000","7.94519","0.00125"
"15966","95.76000","7.98011","0.00080"
"16036","96.18000","8.01515","0.00120"
"16106","96.60000","8.05018","0.00124"
"16176","97.02000","8.08516","0.00109"
"16246","97.44000","8.12008","0.00176"
"16316","97.86000","8.15511","0.00076"
"16386","98.28000","8.19015","0.00119"
"16456","98.70000","8.22513","0.00081"
"16526","99.12000","8.26010","0.00094"
"16596","99.54000","8.29508","0.00087"
"16666","99.96000","8.33018","0.00153"
"16736","100.38000","8.36521","0.00062"
"16806","100.80000","8.40019","0.00134"
"16876","101.22000","8.43517","0.00134"
"16946","101.64000","8.47020","0.00171"
"17016","102.06000","8.50518","0.00147"
"17086","102.48000","8.54022","0.00126"
"17156","102.90000","8.57513","0.00128"
"17226","103.32000","8.61011","0.00098"
"17296","103.74000","8.64515","0.00155"
"17366","104.16000","8.68018","0.00150"
"17436","104.58000","8.71516","0.00175"
"17506","105.00000","8.75014","0.00226"
"17576","105.42000","8.78512","0.00148"
"17646","105.84000","8.82021","0.00165"
"17716","106.26000","8.85525","0.00199"
"17786","106.68000","8.89017","0.00191"
"17856","107.10000","8.92514","0.00134"
"17926","107.52000","8.96012","0.00156"
"17996","107.94000","8.99522","0.00187"
"18066","108.36000","9.03019","0.00177"
"18136","108.78000","9.06511","0.00170"
"18206","109.20000","9.10009","0.00163"
"18276","109.62000","9.13512","0.00208"
"18346","110.04000","9.17016","0.00147"
"18416","110.46000","9.20514","0.00175"
"18486","110.88000","9.24005","0.00152"
"18556","111.30000","9.27515","0.00200"
"18626","111.72000","9.31013","0.00168"
"18696","112.14000","9.34516","0.00192"
"18766","112.56000","9.38014","0.00203"
"18836","112.98000","9.41512","0.00153"
"18906","113.40000","9.45021","0.00169"
"18976","113.82000","9.48519","0.00188"
"19046","114.24000","9.52017","0.00205"
"19116","114.66000","9.55508","0.00149"
"19186","115.08000","9.59012","0.00225"
"19256","115.50000","9.62516","0.00129"
"19326","115.92000","9.66014","0.00170"
"19396","116.34000","9.69511","0.00156"
"19466","116.76000","9.73009","0.00202"
"19536","117.18000","9.76519","0.00148"
"19606","117.60000","9.80022","0.00182"
"19676","118.02000","9.83514","0.00215"
"19746","118.44000","9.87018","0.00138"
"19816","118.86000","9.90515","0.00192"
"19886","119.28000","9.94019","0.00178"
"19956","119.70000","9.97517","0.00174"
"20026","120.12000","10.01014","0.00225"
"20096","120.54000","10.04506","0.00186"
"20166","120.96000","10.08010","0.00241"
"20236","121.38000","10.11513","0.00179"
"20306","121.80000","10.15017","0.00189"
"20376","122.22000","10.18515","0.00230"
"20446","122.64000","10.22006","0.00191"
"20516","123.06000","10.25516","0.00192"
"20586","123.48000","10.29020","0.00217"
"20656","123.90000","10.32517","0.00220"
"20726","124.32000","10.36009","0.00194"
"20796","124.74000","10.39507","0.00224"
"20866","125.16000","10.43022","0.00196"
"20936","125.58000","10.46520","0.00215"
"21006","126.00000","10.50012","0.00267"
"21076","126.42000","10.53509","0.00201"
"21146","126.84000","10.57013","0.00244"
"21216","127.26000","10.60517","0.00236"
"21286","127.68000","10.64015","0.00254"
"21356","128.10000","10.67518","0.00274"
"21426","128.52000","10.71010","0.00251"
"21496","128.94000","10.74514","0.00287"
"21566","129.36000","10.78017","0.00231"
"21636","129.78000","10.81515","0.00238"
"21706","130.20000","10.85013","0.00218"
"21776","130.62000","10.88516","0.00271"
"21846","131.04000","10.92014","0.00213"
"21916","131.46000","10.95518","0.00250"
"21986","131.88000","10.99009","0.00251"
"22056","132.30000","11.02513","0.00219"
"22126","132.72000","11.06017","0.00249"
"22196","133.14000","11.09514","0.00216"
"22266","133.56000","11.13012","0.00230"
"22336","133.98000","11.16510","0.00262"
"22406","134.40000","11.20013","0.00224"
"22476","134.82000","11.23517","0.00277"
"22546","135.24000","11.27015","0.00258"
"22616","135.66000","11.30512","0.00267"
"22686","136.08000","11.34016","0.00220"
"22756","136.50000","11.37514","0.00253"
"22826","136.92000","11.41017","0.00234"
"22896","137.34000","11.44509","0.00268"
"22966","137.76000","11.48007","0.00308"
"23036","138.18000","11.51511","0.00300"
"23106","138.60000","11.55014","0.00278"
"23176","139.02000","11.58518","0.00333"
"23246","139.44000","11.62010","0.00313"
"23316","139.86000","11.65507","0.00322"
"23386","140.28000","11.69017","0.00253"
"23456","140.70000","11.72515","0.00301"
"23526","141.12000","11.76018","0.00330"
"23596","141.54000","11.79510","0.00300"
"23666","141.96000","11.83014","0.00293"
"23736","142.38000","11.86517","0.00318"
"23806","142.80000","11.90021","0.00365"
"23876","143.22000","11.93513","0.00257"
"23946","143.64000","11.97010","0.00356"
"24016","144.06000","12.00520","0.00353"
"24086","144.48000","12.04018","0.00331"
"24156","144.90000","12.07515","0.00303"
"24226","145.32000","12.11013","0.00329"
"24296","145.74000","12.14517","0.00282"
"24366","146.16000","12.18014","0.00358"
"24436","146.58000","12.21518","0.00340"
"24506","147.00000","12.25016","0.00297"
"24576","147.42000","12.28508","0.00326"
"24646","147.84000","12.32017","0.00347"
"24716","148.26000","12.35515","0.00340"
"24786","148.68000","12.39019","0.00289"
"24856","149.10000","12.42510","0.00354"
"24926","149.52000","12.46008","0.00347"
"24996","149.94000","12.49512","0.00337"
"25066","150.36000","12.53015","0.00395"
"25136","150.78000","12.56513","0.00422"
"25206","151.20000","12.60011","0.00368"
"25276","151.62000","12.63514","0.00325"
"25346","152.04000","12.67018","0.00348"
"25416","152.46000","12.70516","0.00377"
"25486","152.88000","12.74013","0.00372"
"25556","153.30000","12.77511","0.00335"
"25626","153.72000","12.81015","0.00378"
"25696","154.14000","12.84518","0.00331"
"25766","154.56000","12.88016","0.00392"
"25836","154.98000","12.91508","0.00350"
"25906","155.40000","12.95012","0.00373"
"25976","155.82000","12.98521","0.00371"
"26046","156.24000","13.02013","0.00449"
"26116","156.66000","13.05516","0.00424"
"26186","157.08000","13.09014","0.00397"
"26256","157.50000","13.12518","0.00362"
"26326","157.92000","13.16021","0.00407"
"26396","158.34000","13.19519","0.00384"
"26466","158.76000","13.23017","0.00371"
"26536","159.18000","13.26515","0.00344"
"26606","159.60000","13.30018","0.00363"
"26676","160.02000","13.33516","0.00336"
"26746","160.44000","13.37014","0.00374"
"26816","160.86000","13.40511","0.00450"
"26886","161.28000","13.44015","0.00427"
"26956","161.70000","13.47513","0.00373"
"27026","162.12000","13.51016","0.00390"
"27096","162.54000","13.54508","0.00417"
"27166","162.96000","13.58012","0.00394"
"27236","163.38000","13.61515","0.00410"
"27306","163.80000","13.65019","0.00398"
"27376","164.22000","13.68517","0.00367"
"27446","164.64000","13.72008","0.00415"
"27516","165.06000","13.75518","0.00429"
"27586","165.48000","13.79022","0.00408"
"27656","165.90000","13.82519","0.00391"
"27726","166.32000","13.86011","0.00398"
"27796","166.74000","13.89515","0.00428"
"27866","167.16000","13.93013","0.00421"
"27936","167.58000","13.96516","0.00416"
"28006","168.00000","14.00014","0.00404"
"28076","168.42000","14.03512","0.00482"
"28146","168.84000","14.07015","0.00432"
"28216","169.26000","14.10519","0.00457"
"28286","169.68000","14.14016","0.00448"
"28356","170.10000","14.17514","0.00442"
"28426","170.52000","14.21012","0.00438"
"28496","170.94000","14.24516","0.00436"
"28566","171.36000","14.28013","0.00407"
"28636","171.78000","14.31517","0.00419"
"28706","172.20000","14.35009","0.00478"
"28776","172.62000","14.38506","0.00458"
"28846","173.04000","14.42016","0.00472"
"28916","173.46000","14.45514","0.00436"
"28986","173.88000","14.49017","0.00481"
"29056","174.30000","14.52509","0.00472"
"29126","174.72000","14.56019","0.00442"
"29196","175.14000","14.59516","0.00461"
"29266","175.56000","14.63020","0.00418"
"29336","175.98000","14.66512","0.00461"
"29406","176.40000","14.70015","0.00519"
"29476","176.82000","14.73519","0.00466"
"29546","177.24000","14.77017","0.00470"
"29616","177.66000","14.80514","0.00490"
"29686","178.08000","14.84012","0.00514"
"29756","178.50000","14.87516","0.00488"
"29826","178.92000","14.91013","0.00482"
"29896","179.34000","14.94517","0.00506"
"29966","179.76000","14.98015","0.00502"
"30036","180.18000","15.01513","0.00497"
"30106","180.60000","15.05016","0.00489"
"30176","181.02000","15.08520","0.00531"
"30246","181.44000","15.12012","0.00490"
"30316","181.86000","15.15509","0.00484"
"30386","182.28000","15.19019","0.00480"
"30456","182.70000","15.22517","0.00496"
"30526","183.12000","15.26014","0.00497"
"30596","183.54000","15.29512","0.00495"
"30666","183.96000","15.33016","0.00503"
"30736","184.38000","15.36519","0.00479"
"30806","184.80000","15.40017","0.00522"
"30876","185.22000","15.43515","0.00501"
"30946","185.64000","15.47012","0.00503"
"31016","186.06000","15.50516","0.00539"
"31086","186.48000","15.54020","0.00533"
"31156","186.90000","15.57517","0.00507"
"31226","187.32000","15.61015","0.00538"
"31296","187.74000","15.64519","0.00552"
"31366","188.16000","15.68016","0.00535"
"31436","188.58000","15.71514","0.00540"
"31506","189.00000","15.75018","0.00534"
"31576","189.42000","15.78509","0.00502"
"31646","189.84000","15.82013","0.00489"
"31716","190.26000","15.85517","0.00530"
"31786","190.68000","15.89014","0.00527"
"31856","191.10000","15.92512","0.00563"
"31926","191.52000","15.96010","0.00567"
"31996","191.94000","15.99514","0.00536"
"32066","192.36000","16.03023","0.00506"
"32136","192.78000","16.06515","0.00558"
"32206","193.20000","16.10013","0.00547"
"32276","193.62000","16.13516","0.00554"
"32346","194.04000","16.17020","0.00572"
"32416","194.46000","16.20518","0.00587"
"32486","194.88000","16.24015","0.00552"
"32556","195.30000","16.27513","0.00534"
"32626","195.72000","16.31010","0.00550"
"32696","196.14000","16.34514","0.00572"
"32766","196.56000","16.38018","0.00588"
"32836","196.98000","16.41516","0.00553"
"32906","197.40000","16.45013","0.00579"
"32976","197.82000","16.48511","0.00580"
"33046","198.24000","16.52021","0.00536"
"33116","198.66000","16.55518","0.00565"
"33186","199.08000","16.59010","0.00570"
"33256","199.50000","16.62520","0.00577"
"33326","199.92000","16.66023","0.00539"
"33396","200.34000","16.69515","0.00585"
"33466","200.76000","16.73007","0.00525"
"33536","201.18000","16.76510","0.00572"
"33606","201.60000","16.80014","0.00524"
"33676","202.02000","16.83518","0.00550"
"33746","202.44000","16.87009","0.00564"
"33816","202.86000","16.90507","0.00567"
"33886","203.28000","16.94011","0.00567"
"33956","203.70000","16.97520","0.00543"
"34026","204.12000","17.01018","0.00583"
"34096","204.54000","17.04510","0.00583"
"34166","204.96000","17.08014","0.00608"
"34236","205.38000","17.11517","0.00573"
"34306","205.80000","17.15021","0.00585"
"34376","206.22000","17.18513","0.00559"
"34446","206.64000","17.22004","0.00563"
"34516","207.06000","17.25514","0.00599"
"34586","207.48000","17.29018","0.00559"
"34656","207.90000","17.32515","0.00566"
"34726","208.32000","17.36019","0.00614"
"34796","208.74000","17.39511","0.00551"
"34866","209.16000","17.43020","0.00502"
"34936","209.58000","17.46518","0.00456"
"35006","210.00000","17.50016","0.00440"
"35076","210.42000","17.53513","0.00419"
"35146","210.84000","17.57011","0.00441"
"35216","211.26000","17.60521","0.00439"
"35286","211.68000","17.64018","0.00418"
"35356","212.10000","17.67510","0.00497"
"35426","212.52000","17.71014","0.00438"
"35496","212.94000","17.74512","0.00437"
"35566","213.36000","17.78015","0.00445"
"35636","213.78000","17.81513","0.00392"
"35706","214.20000","17.85011","0.00419"
"35776","214.62000","17.88514","0.00438"
"35846","215.04000","17.92012","0.00452"
"35916","215.46000","17.95516","0.00451"
"35986","215.88000","17.99013","0.00465"
"36056","216.30000","18.02511","0.00479"
"36126","216.72000","18.06021","0.00461"
"36196","217.14000","18.09518","0.00481"
"36266","217.56000","18.13022","0.00458"
"36336","217.98000","18.16514","0.00480"
"36406","218.40000","18.20011","0.00486"
"36476","218.82000","18.23515","0.00503"
"36546","219.24000","18.27013","0.00492"
"36616","219.66000","18.30510","0.00526"
"36686","220.08000","18.34008","0.00502"
"36756","220.50000","18.37512","0.00504"
"36826","220.92000","18.41015","0.00546"
"36896","221.34000","18.44519","0.00514"
"36966","221.76000","18.48011","0.00522"
"37036","222.18000","18.51514","0.00540"
"37106","222.60000","18.55018","0.00558"
"37176","223.02000","18.58522","0.00559"
"37246","223.44000","18.62020","0.00559"
"37316","223.86000","18.65511","0.00574"
"37386","224.28000","18.69009","0.00552"
"37456","224.70000","18.72512","0.00549"
"37526","225.12000","18.76022","0.00575"
"37596","225.54000","18.79520","0.00555"
"37666","225.96000","18.83011","0.00598"
"37736","226.38000","18.86515","0.00594"
"37806","226.80000","18.90019","0.00653"
"37876","227.22000","18.93523","0.00660"
"37946","227.64000","18.97014","0.00610"
"38016","228.06000","19.00512","0.00589"
"38086","228.48000","19.04022","0.00628"
"38156","228.90000","19.07519","0.00652"
"38226","229.32000","19.11017","0.00652"
"38296","229.74000","19.14515","0.00644"
"38366","230.16000","19.18012","0.00619"
"38436","230.58000","19.21516","0.00643"
"38506","231.00000","19.25020","0.00641"
"38576","231.42000","19.28511","0.00631"
"38646","231.84000","19.32015","0.00602"
"38716","232.26000","19.35513","0.00667"
"38786","232.68000","19.39016","0.00650"
"38856","233.10000","19.42508","0.00690"
"38926","233.52000","19.46012","0.00642"
"38996","233.94000","19.49515","0.00665"
"39066","234.36000","19.53019","0.00663"
"39136","234.78000","19.56523","0.00633"
"39206","235.20000","19.60009","0.00645"
"39276","235.62000","19.63512","0.00622"
"39346","236.04000","19.67016","0.00673"
"39416","236.46000","19.70514","0.00673"
"39486","236.88000","19.74017","0.00688"
"39556","237.30000","19.77509","0.00683"
"39626","237.72000","19.81013","0.00717"
"39696","238.14000","19.84522","0.00684"
"39766","238.56000","19.88014","0.00715"
"39836","238.98000","19.91518","0.00736"
"39906","239.40000","19.95015","0.00723"
"39976","239.82000","19.98519","0.00753"
"40046","240.24000","20.02017","0.00703"
"40116","240.66000","20.05520","0.00738"
"40186","241.08000","20.09012","0.00710"
"40256","241.50000","20.12510","0.00673"
"40326","241.92000","20.16019","0.00719"
"40396","242.34000","20.19517","0.00722"
"40466","242.76000","20.23015","0.00715"
"40536","243.18000","20.26513","0.00722"
"40606","243.60000","20.30016","0.00711"
"40676","244.02000","20.33520","0.00734"
"40746","244.44000","20.37017","0.00755"
"40816","244.86000","20.40515","0.00722"
"40886","245.28000","20.44019","0.00736"
"40956","245.70000","20.47522","0.00729"
"41026","246.12000","20.51020","0.00780"
"41096","246.54000","20.54512","0.00730"
"41166","246.96000","20.58010","0.00733"
"41236","247.38000","20.61513","0.00756"
"41306","247.80000","20.65011","0.00779"
"41376","248.22000","20.68521","0.00798"
"41446","248.64000","20.72018","0.00748"
"41516","249.06000","20.75510","0.00798"
"41586","249.48000","20.79014","0.00829"
"41656","249.90000","20.82517","0.00785"
"41726","250.32000","20.86015","0.00799"
"41796","250.74000","20.89513","0.00824"
"41866","251.16000","20.93022","0.00815"
"41936","251.58000","20.96520","0.00850"
"42006","252.00000","21.00018","0.00799"
"42076","252.42000","21.03509","0.00821"
"42146","252.84000","21.07013","0.00794"
"42216","253.26000","21.10517","0.00859"
"42286","253.68000","21.14021","0.00865"
"42356","254.10000","21.17512","0.00817"
"42426","254.52000","21.21010","0.00838"
"42496","254.94000","21.24513","0.00858"
"42566","255.36000","21.28023","0.00831"
"42636","255.78000","21.31515","0.00876"
"42706","256.20000","21.35012","0.00861"
"42776","256.62000","21.38516","0.00876"
"42846","257.04000","21.42014","0.00867"
"42916","257.46000","21.45518","0.00872"
"42986","257.88000","21.49015","0.00822"
"43056","258.30000","21.52507","0.00846"
"43126","258.72000","21.56011","0.00822"
"43196","259.14000","21.59514","0.00788"
"43266","259.56000","21.63018","0.00820"
"43336","259.98000","21.66515","0.00771"
"43406","260.40000","21.70007","0.00779"
"43476","260.82000","21.73517","0.00850"
"43546","261.24000","21.77015","0.00852"
"43616","261.66000","21.80518","0.00838"
"43686","262.08000","21.84016","0.00829"
"43756","262.50000","21.87514","0.00839"
"43826","262.92000","21.91017","0.00862"
"43896","263.34000","21.94521","0.00876"
"43966","263.76000","21.98018","0.00848"
"44036","264.18000","22.01510","0.00863"
"44106","264.60000","22.05008","0.00850"
"44176","265.02000","22.08518","0.00882"
"44246","265.44000","22.12016","0.00872"
"44316","265.86000","22.15513","0.00899"
"44386","266.28000","22.19017","0.00891"
"44456","266.70000","22.22515","0.00908"
"44526","267.12000","22.26018","0.00914"
"44596","267.54000","22.29516","0.00860"
"44666","267.96000","22.33014","0.00874"
"44736","268.38000","22.36517","0.00867"
"44806","268.80000","22.40021","0.00886"
"44876","269.22000","22.43519","0.00856"
"44946","269.64000","22.47010","0.00833"
"45016","270.06000","22.50514","0.00824"
"45086","270.48000","22.54018","0.00825"
"45156","270.90000","22.57515","0.00869"
"45226","271.32000","22.61013","0.00864"
"45296","271.74000","22.64511","0.00857"
"45366","272.16000","22.68014","0.00867"
"45436","272.58000","22.71518","0.00860"
"45506","273.00000","22.75016","0.00883"
"45576","273.42000","22.78514","0.00825"
"45646","273.84000","22.82017","0.00841"
"45716","274.26000","22.85515","0.00835"
"45786","274.68000","22.89018","0.00825"
"45856","275.10000","22.92516","0.00826"
"45926","275.52000","22.96008","0.00898"
"45996","275.94000","22.99511","0.00807"
"46066","276.36000","23.03015","0.00814"
"46136","276.78000","23.06519","0.00871"
"46206","277.20000","23.10016","0.00803"
"46276","277.62000","23.13508","0.00870"
"46346","278.04000","23.17018","0.00863"
"46416","278.46000","23.20522","0.00804"
"46486","278.88000","23.24019","0.00839"
"46556","279.30000","23.27517","0.00859"
"46626","279.72000","23.31014","0.00867"
"46696","280.14000","23.34518","0.00889"
"46766","280.56000","23.38016","0.00894"
"46836","280.98000","23.41514","0.00916"
"46906","281.40000","23.45011","0.00876"
"46976","281.82000","23.48515","0.00893"
"47046","282.24000","23.52019","0.00916"
"47116","282.66000","23.55516","0.00916"
"47186","283.08000","23.59008","0.00930"
"47256","283.50000","23.62518","0.00965"
"47326","283.92000","23.66009","0.00917"
"47396","284.34000","23.69513","0.00939"
"47466","284.76000","23.73017","0.00821"
"47536","285.18000","23.76514","0.00786"
"47606","285.60000","23.80018","0.00850"
"47676","286.02000","23.83516","0.00867"
"47746","286.44000","23.87013","0.00893"
"47816","286.86000","23.90511","0.00843"
"47886","287.28000","23.94009","0.00902"
"47956","287.70000","23.97512","0.00897"
"48026","288.12000","24.01010","0.00931"
"48096","288.54000","24.04508","0.00962"
"48166","288.96000","24.08006","0.00945"
"48236","289.38000","24.11515","0.00832"
"48306","289.80000","24.15019","0.00776"
"48376","290.22000","24.18511","0.00827"
"48446","290.64000","24.22014","0.00818"
"48516","291.06000","24.25518","0.00880"
"48586","291.48000","24.29021","0.00857"
"48656","291.90000","24.32519","0.00821"
"48726","292.32000","24.36011","0.00841"
"48796","292.74000","24.39509","0.00560"
"48866","293.16000","24.43012","0.00562"
"48936","293.58000","24.46522","0.00498"
"49006","294.00000","24.50019","0.00524"
"49076","294.42000","24.53511","0.00567"
"49146","294.84000","24.57009","0.00503"
"49216","295.26000","24.60519","0.00471"
"49286","295.68000","24.64017","0.00503"
"49356","296.10000","24.67520","0.00526"
"49426","296.52000","24.71012","0.00575"
"49496","296.94000","24.74509","0.00522"
"49566","297.36000","24.78019","0.00527"
"49636","297.78000","24.81517","0.00529"
"49706","298.20000","24.85009","0.00533"
"49776","298.62000","24.88506","0.00543"
"49846","299.04000","24.92016","0.00549"
"49916","299.46000","24.95513","0.00576"
"49986","299.88000","24.99017","0.00573"
"50056","300.30000","25.02509","0.00588"
"50126","300.72000","25.06013","0.00575"
"50196","301.14000","25.09516","0.00564"
"50266","301.56000","25.13014","0.00626"
"50336","301.98000","25.16517","0.00587"
"50406","302.40000","25.20009","0.00544"
"50476","302.82000","25.23519","0.00565"
"50546","303.24000","25.27016","0.00591"
"50616","303.66000","25.30520","0.00560"
"50686","304.08000","25.34012","0.00589"
"50756","304.50000","25.37510","0.00612"
"50826","304.92000","25.41019","0.00679"
"50896","305.34000","25.44523","0.00628"
"50966","305.76000","25.48015","0.00636"
"51036","306.18000","25.51512","0.00683"
"51106","306.60000","25.55016","0.00600"
"51176","307.02000","25.58520","0.00625"
"51246","307.44000","25.62017","0.00601"
"51316","307.86000","25.65515","0.00666"
"51386","308.28000","25.69013","0.00688"
"51456","308.70000","25.72516","0.00646"
"51526","309.12000","25.76020","0.00672"
"51596","309.54000","25.79518","0.00631"
"51666","309.96000","25.83009","0.00685"
"51736","310.38000","25.86513","0.00681"
"51806","310.80000","25.90023","0.00696"
"51876","311.22000","25.93514","0.00659"
"51946","311.64000","25.97012","0.00706"
"52016","312.06000","26.00510","0.00683"
"52086","312.48000","26.04013","0.00691"
"52156","312.90000","26.07517","0.00715"
"52226","313.32000","26.11015","0.00714"
"52296","313.74000","26.14519","0.00735"
"52366","314.16000","26.18010","0.00704"
"52436","314.58000","26.21520","0.00732"
"52506","315.00000","26.25018","0.00751"
"52576","315.42000","26.28509","0.00716"
"52646","315.84000","26.32007","0.00742"
"52716","316.26000","26.35511","0.00773"
"52786","316.68000","26.39014","0.00754"
"52856","317.10000","26.42518","0.00756"
"52926","317.52000","26.46010","0.00754"
"52996","317.94000","26.49513","0.00780"
"53066","318.36000","26.53011","0.00794"
"53136","318.78000","26.56515","0.00751"
"53206","319.20000","26.60013","0.00749"
"53276","319.62000","26.63516","0.00684"
"53346","320.04000","26.67020","0.00703"
"53416","320.46000","26.70517","0.00616"
"53486","320.88000","26.74015","0.00632"
"53556","321.30000","26.77507","0.00673"
"53626","321.72000","26.81010","0.00672"
"53696","322.14000","26.84514","0.00639"
"53766","322.56000","26.88018","0.00686"
"53836","322.98000","26.91516","0.00639"
"53906","323.40000","26.95007","0.00635"
"53976","323.82000","26.98511","0.00715"
"54046","324.24000","27.02020","0.00683"
"54116","324.66000","27.05512","0.00662"
"54186","325.08000","27.09016","0.00671"
"54256","325.50000","27.12520","0.00657"
"54326","325.92000","27.16011","0.00672"
"54396","326.34000","27.19515","0.00664"
"54466","326.76000","27.23013","0.00688"
"54536","327.18000","27.26510","0.00708"
"54606","327.60000","27.30014","0.00689"
"54676","328.02000","27.33518","0.00695"
"54746","328.44000","27.37016","0.00746"
"54816","328.86000","27.40513","0.00703"
"54886","329.28000","27.44011","0.00748"
"54956","329.70000","27.47514","0.00726"
"55026","330.12000","27.51018","0.00723"
"55096","330.54000","27.54522","0.00728"
"55166","330.96000","27.58014","0.00720"
"55236","331.38000","27.61517","0.00744"
"55306","331.80000","27.65021","0.00709"
"55376","332.22000","27.68518","0.00779"
"55446","332.64000","27.72016","0.00794"
"55516","333.06000","27.75508","0.00720"
"55586","333.48000","27.79017","0.00724"
"55656","333.90000","27.82515","0.00778"
"55726","334.32000","27.86019","0.00775"
"55796","334.74000","27.89511","0.00774"
"55866","335.16000","27.93014","0.00785"
"55936","335.58000","27.96512","0.00799"
"56006","336.00000","28.00016","0.00768"
"56076","336.42000","28.03519","0.00774"
"56146","336.84000","28.07011","0.00816"
"56216","337.26000","28.10514","0.00811"
"56286","337.68000","28.14018","0.00794"
"56356","338.10000","28.17516","0.00791"
"56426","338.52000","28.21008","0.00801"
"56496","338.94000","28.24511","0.00794"
"56566","339.36000","28.28015","0.00784"
"56636","339.78000","28.31513","0.00773"
"56706","340.20000","28.35016","0.00785"
"56776","340.62000","28.38508","0.00804"
"56846","341.04000","28.42012","0.00799"
"56916","341.46000","28.45515","0.00819"
"56986","341.88000","28.49019","0.00814"
"57056","342.30000","28.52517","0.00820"
"57126","342.72000","28.56014","0.00851"
"57196","343.14000","28.59518","0.00810"
"57266","343.56000","28.63016","0.00852"
"57336","343.98000","28.66514","0.00812"
"57406","344.40000","28.70005","0.00826"
"57476","344.82000","28.73509","0.00854"
"57546","345.24000","28.77013","0.00854"
"57616","345.66000","28.80516","0.00867"
"57686","346.08000","28.84014","0.00898"
"57756","346.50000","28.87506","0.00878"
"57826","346.92000","28.91015","0.00855"
"57896","347.34000","28.94519","0.00895"
"57966","347.76000","28.98017","0.00908"
"58036","348.18000","29.01514","0.00905"
"58106","348.60000","29.05012","0.00870"
"58176","349.02000","29.08521","0.00911"
"58246","349.44000","29.12019","0.00885"
"58316","349.86000","29.15511","0.00920"
"58386","350.28000","29.19009","0.00903"
"58456","350.70000","29.22513","0.00890"
"58526","351.12000","29.26016","0.00940"
"58596","351.54000","29.29514","0.00938"
"58666","351.96000","29.33011","0.00938"
"58736","352.38000","29.36515","0.00934"
"58806","352.80000","29.40013","0.00929"
"58876","353.22000","29.43517","0.00937"
"58946","353.64000","29.47014","0.00946"
"59016","354.06000","29.50506","0.00969"
"59086","354.48000","29.54016","0.00976"
"59156","354.90000","29.57519","0.00971"
"59226","355.32000","29.61017","0.01022"
"59296","355.74000","29.64515","0.00972"
"59366","356.16000","29.68012","0.00999"
"59436","356.58000","29.71510","0.00988"
"59506","357.00000","29.75014","0.01007"
"59576","357.42000","29.78511","0.01006"
"59646","357.84000","29.82009","0.01032"
"59716","358.26000","29.85519","0.01002"
"59786","358.68000","29.89017","0.00987"
"59856","359.10000","29.92514","0.01018"
"59926","359.52000","29.96012","0.01005"
"59996","359.94000","29.99515","0.01005"
"60066","360.36000","30.03019","0.01026"
"60136","360.78000","30.06517","0.01014"
"60206","361.20000","30.10021","0.01061"
"60276","361.62000","30.13506","0.01051"
"60346","362.04000","30.17010","0.01010"
"60416","362.46000","30.20519","0.00976"
"60486","362.88000","30.24017","0.01001"
"60556","363.30000","30.27515","0.01012"
"60626","363.72000","30.31013","0.00992"
"60696","364.14000","30.34516","0.01005"
"60766","364.56000","30.38020","0.01036"
"60836","364.98000","30.41518","0.01033"
"60906","365.40000","30.45015","0.01003"
"60976","365.82000","30.48513","0.01005"
"61046","366.24000","30.52017","0.01003"
"61116","366.66000","30.55520","0.01007"
"61186","367.08000","30.59012","0.01058"
"61256","367.50000","30.62510","0.01013"
"61326","367.92000","30.66013","0.01059"
"61396","368.34000","30.69511","0.01050"
"61466","368.76000","30.73014","0.01073"
"61536","369.18000","30.76506","0.01050"
"61606","369.60000","30.80016","0.01055"
"61676","370.02000","30.83514","0.01051"
"61746","370.44000","30.87017","0.01076"
"61816","370.86000","30.90515","0.01034"
"61886","371.28000","30.94013","0.01048"
"61956","371.70000","30.97516","0.01086"
"62026","372.12000","31.01020","0.01076"
"62096","372.54000","31.04518","0.01037"
"62166","372.96000","31.08015","0.01090"
"62236","373.38000","31.11507","0.01124"
"62306","373.80000","31.15017","0.01071"
"62376","374.22000","31.18515","0.01124"
"62446","374.64000","31.22006","0.01123"
"62516","375.06000","31.25510","0.01112"
"62586","375.48000","31.29013","0.01167"
"62656","375.90000","31.32523","0.01172"
"62726","376.32000","31.36021","0.01159"
"62796","376.74000","31.39519","0.01152"
"62866","377.16000","31.43016","0.01152"
"62936","377.58000","31.46514","0.01141"
"63006","378.00000","31.50018","0.01164"
"63076","378.42000","31.53515","0.01179"
"63146","378.84000","31.57007","0.01208"
"63216","379.26000","31.60511","0.01179"
"63286","379.68000","31.64008","0.01165"
"63356","380.10000","31.67518","0.01185"
"63426","380.52000","31.71010","0.01211"
"63496","380.94000","31.74507","0.01218"
"63566","381.36000","31.78017","0.01277"
"63636","381.78000","31.81515","0.01257"
"63706","382.20000","31.85018","0.01255"
"63776","382.62000","31.88510","0.01268"
"63846","383.04000","31.92014","0.01321"
"63916","383.46000","31.95517","0.01325"
"63986","383.88000","31.99021","0.01297"
"64056","384.30000","32.02512","0.01310"
"64126","384.72000","32.06010","0.01364"
"64196","385.14000","32.09514","0.01356"
"64266","385.56000","32.13012","0.01382"
"64336","385.98000","32.16515","0.01399"
"64406","386.40000","32.20013","0.01386"
"64476","386.82000","32.23517","0.01426"
"64546","387.24000","32.27015","0.01402"
"64616","387.66000","32.30518","0.01390"
"64686","388.08000","32.34016","0.01452"
"64756","388.50000","32.37513","0.01444"
"64826","388.92000","32.41017","0.01454"
"64896","389.34000","32.44515","0.01429"
"64966","389.76000","32.48018","0.01413"
"65036","390.18000","32.51510","0.01463"
"65106","390.60000","32.55014","0.01467"
"65176","391.02000","32.58517","0.01489"
"65246","391.44000","32.62015","0.01507"
"65316","391.86000","32.65513","0.01573"
"65386","392.28000","32.69004","0.01564"
"65456","392.70000","32.72514","0.01586"
"65526","393.12000","32.76018","0.01490"
"65596","393.54000","32.79516","0.01520"
"65666","393.96000","32.83014","0.01540"
"65736","394.38000","32.86517","0.01523"
"65806","394.80000","32.90015","0.01514"
"65876","395.22000","32.93518","0.01470"
"65946","395.64000","32.97016","0.01466"
"66016","396.06000","33.00508","0.01458"
"66086","396.48000","33.04012","0.01505"
"66156","396.90000","33.07515","0.01514"
"66226","397.32000","33.11019","0.01555"
"66296","397.74000","33.14510","0.01596"
"66366","398.16000","33.18008","0.01498"
"66436","398.58000","33.21518","0.01545"
"66506","399.00000","33.25015","0.01533"
"66576","399.42000","33.28519","0.01488"
"66646","399.84000","33.32017","0.01537"
"66716","400.26000","33.35509","0.01548"
"66786","400.68000","33.39024","0.01512"
"66856","401.10000","33.42522","0.01536"
"66926","401.52000","33.46014","0.01638"
"66996","401.94000","33.49511","0.01609"
"67066","402.36000","33.53015","0.01649"
"67136","402.78000","33.56519","0.01635"
"67206","403.20000","33.60016","0.01682"
"67276","403.62000","33.63508","0.01673"
"67346","404.04000","33.67018","0.01769"
"67416","404.46000","33.70509","0.01777"
"67486","404.88000","33.74019","0.01740"
"67556","405.30000","33.77510","0.01786"
"67626","405.72000","33.81008","0.01812"
"67696","406.14000","33.84518","0.01897"
"67766","406.56000","33.88015","0.01895"
"67836","406.98000","33.91519","0.01974"
"67906","407.40000","33.95011","0.01962"
"67976","407.82000","33.98509","0.01994"
"68046","408.24000","34.02013","0.02067"
"68116","408.66000","34.05516","0.02059"
"68186","409.08000","34.09014","0.02074"
"68256","409.50000","34.12511","0.02199"
"68326","409.92000","34.16015","0.02251"
"68396","410.34000","34.19519","0.02292"
"68466","410.76000","34.23011","0.02329"
"68536","411.18000","34.26514","0.02338"
"68606","411.60000","34.30018","0.02402"
"68676","412.02000","34.33522","0.02423"
"68746","412.44000","34.37019","0.02434"
"68816","412.86000","34.40517","0.02498"
"68886","413.28000","34.44009","0.02522"
"68956","413.70000","34.47512","0.02559"
"69026","414.12000","34.51016","0.02653"
"69096","414.54000","34.54514","0.02700"
"69166","414.96000","34.58017","0.02715"
"69236","415.38000","34.61515","0.02811"
"69306","415.80000","34.65019","0.02820"
"69376","416.22000","34.68517","0.02890"
"69446","416.64000","34.72020","0.02929"
"69516","417.06000","34.75518","0.03017"
"69586","417.48000","34.79010","0.03030"
"69656","417.90000","34.82519","0.03195"
"69726","418.32000","34.86017","0.03101"
"69796","418.74000","34.89515","0.03251"
"69866","419.16000","34.93012","0.03226"
"69936","419.58000","34.96516","0.03324"
"70006","420.00000","35.00013","0.03412"
"70076","420.42000","35.03517","0.03338"
"70146","420.84000","35.07009","0.03427"
"70216","421.26000","35.10513","0.03532"
"70286","421.68000","35.14016","0.03674"
"70356","422.10000","35.17514","0.03828"
"70426","422.52000","35.21017","0.03845"
"70496","422.94000","35.24509","0.03696"
"70566","423.36000","35.28019","0.03798"
"70636","423.78000","35.31517","0.03876"
"70706","424.20000","35.35014","0.03956"
"70776","424.62000","35.38512","0.04047"
"70846","425.04000","35.42016","0.03989"
"70916","425.46000","35.45514","0.04105"
"70986","425.88000","35.49011","0.04059"
"71056","426.30000","35.52515","0.04125"
"71126","426.72000","35.56012","0.04219"
"71196","427.14000","35.59516","0.04273"
"71266","427.56000","35.63020","0.04296"
"71336","427.98000","35.66517","0.04376"
"71406","428.40000","35.70015","0.04458"
"71476","428.82000","35.73519","0.04422"
"71546","429.24000","35.77016","0.04393"
"71616","429.66000","35.80520","0.04429"
"71686","430.08000","35.84018","0.04488"
"71756","430.50000","35.87509","0.04503"
"71826","430.92000","35.91007","0.04651"
"71896","431.34000","35.94511","0.04803"
"71966","431.76000","35.98014","0.04788"
"72036","432.18000","36.01518","0.04892"
"72106","432.60000","36.05010","0.05010"
"72176","433.02000","36.08520","0.05152"
"72246","433.44000","36.12017","0.05176"
"72316","433.86000","36.15521","0.05313"
"72386","434.28000","36.19012","0.05369"
"72456","434.70000","36.22510","0.05465"
"72526","435.12000","36.26020","0.05543"
"72596","435.54000","36.29517","0.05640"
"72666","435.96000","36.33015","0.05752"
"72736","436.38000","36.36513","0.05741"
"72806","436.80000","36.40010","0.05888"
"72876","437.22000","36.43514","0.05968"
"72946","437.64000","36.47018","0.06116"
"73016","438.06000","36.50510","0.06223"
"73086","438.48000","36.54013","0.06230"
"73156","438.90000","36.57511","0.06398"
"73226","439.32000","36.61015","0.06483"
"73296","439.74000","36.64513","0.06536"
"73366","440.16000","36.68010","0.06637"
"73436","440.58000","36.71520","0.06837"
"73506","441.00000","36.75024","0.06967"
"73576","441.42000","36.78521","0.07051"
"73646","441.84000","36.82013","0.07315"
"73716","442.26000","36.85516","0.07443"
"73786","442.68000","36.89014","0.07605"
"73856","443.10000","36.92512","0.07836"
"73926","443.52000","36.96009","0.07946"
"73996","443.94000","36.99507","0.07886"
"74066","444.36000","37.03017","0.02753"
"74136","444.78000","37.06514","0.01894"
"74206","445.20000","37.10018","0.01248"
"74276","445.62000","37.13516","0.01851"
"74346","446.04000","37.17014","0.02394"
"74416","446.46000","37.20517","0.01797"
"74486","446.88000","37.24021","0.01835"
"74556","447.30000","37.27519","0.02447"
"74626","447.72000","37.31010","0.02324"
"74696","448.14000","37.34508","0.02224"
"74766","448.56000","37.38018","0.02470"
"74836","448.98000","37.41515","0.02508"
"74906","449.40000","37.45013","0.02697"
"74976","449.82000","37.48511","0.02953"
"75046","450.24000","37.52015","0.02867"
"75116","450.66000","37.55524","0.02930"
"75186","451.08000","37.59016","0.03258"
"75256","451.50000","37.62513","0.03530"
"75326","451.92000","37.66011","0.03430"
"75396","452.34000","37.69521","0.03539"
"75466","452.76000","37.73018","0.03803"
"75536","453.18000","37.76516","0.03971"
"75606","453.60000","37.80008","0.04070"
"75676","454.02000","37.83512","0.04176"
"75746","454.44000","37.87016","0.04309"
"75816","454.86000","37.90519","0.04348"
"75886","455.28000","37.94017","0.04446"
"75956","455.70000","37.97514","0.04583"
"76026","456.12000","38.01012","0.04663"
"76096","456.54000","38.04516","0.04765"
"76166","456.96000","38.08019","0.04878"
"76236","457.38000","38.11511","0.04965"
"76306","457.80000","38.15021","0.05093"
"76376","458.22000","38.18518","0.05188"
"76446","458.64000","38.22016","0.05288"
"76516","459.06000","38.25513","0.05414"
"76586","459.48000","38.29011","0.05478"
"76656","459.90000","38.32515","0.05529"
"76726","460.32000","38.36019","0.05673"
"76796","460.74000","38.39510","0.05749"
"76866","461.16000","38.43008","0.05895"
"76936","461.58000","38.46512","0.05985"
"77006","462.00000","38.50016","0.06195"
"77076","462.42000","38.53519","0.06299"
"77146","462.84000","38.57011","0.06426"
"77216","463.26000","38.60509","0.06551"
"77286","463.68000","38.64018","0.06749"
"77356","464.10000","38.67522","0.06944"
"77426","464.52000","38.71014","0.07133"
"77496","464.94000","38.74511","0.07335"
"77566","465.36000","38.78009","0.07496"
"77636","465.78000","38.81519","0.07783"
"77706","466.20000","38.85016","0.07851"
"77776","466.62000","38.88514","0.08158"
"77846","467.04000","38.92012","0.08284"
"77916","467.46000","38.95515","0.08437"
"77986","467.88000","38.99019","0.08624"
"78056","468.30000","39.02517","0.08807"
"78126","468.72000","39.06014","0.08964"
"78196","469.14000","39.09506","0.09102"
"78266","469.56000","39.13022","0.09261"
"78336","469.98000","39.16519","0.09388"
"78406","470.40000","39.20011","0.09481"
"78476","470.82000","39.23509","0.09576"
"78546","471.24000","39.27013","0.09707"
"78616","471.66000","39.30510","0.09770"
"78686","472.08000","39.34014","0.09841"
"78756","472.50000","39.37511","0.09927"
"78826","472.92000","39.41009","0.09997"
"78896","473.34000","39.44513","0.10073"
"78966","473.76000","39.48016","0.10156"
"79036","474.18000","39.51514","0.10178"
"79106","474.60000","39.55006","0.10267"
"79176","475.02000","39.58516","0.10324"
"79246","475.44000","39.62019","0.10450"
"79316","475.86000","39.65516","0.10602"
"79386","476.28000","39.69014","0.10698"
"79456","476.70000","39.72512","0.10836"
"79526","477.12000","39.76016","0.11003"
"79596","477.54000","39.79514","0.11131"
"79666","477.96000","39.83012","0.11389"
"79736","478.38000","39.86509","0.11532"
"79806","478.80000","39.90013","0.11740"
"79876","479.22000","39.93522","0.12005"
"79946","479.64000","39.97020","0.12157"
"80016","480.06000","40.00512","0.12414"
"80086","480.48000","40.04015","0.12735"
"80156","480.90000","40.07525","0.13045"
"80226","481.32000","40.11017","0.03794"
"80296","481.74000","40.14515","0.04760"
"80366","482.16000","40.18012","0.04439"
"80436","482.58000","40.21510","0.03465"
"80506","483.00000","40.25013","0.05581"
"80576","483.42000","40.28517","0.03648"
"80646","483.84000","40.32014","0.04359"
"80716","484.26000","40.35513","0.05052"
"80786","484.68000","40.39016","0.04206"
"80856","485.10000","40.42520","0.05628"
"80926","485.52000","40.46018","0.04599"
"80996","485.94000","40.49516","0.04591"
"81066","486.36000","40.53013","0.05958"
"81136","486.78000","40.56517","0.04743"
"81206","487.20000","40.60014","0.05285"
"81276","487.62000","40.63518","0.05825"
"81346","488.04000","40.67010","0.05130"
"81416","488.46000","40.70513","0.05864"
"81486","488.88000","40.74017","0.05784"
"81556","489.30000","40.77515","0.05417"
"81626","489.72000","40.81012","0.06450"
"81696","490.14000","40.84516","0.05918"
"81766","490.56000","40.88007","0.05733"
"81836","490.98000","40.91517","0.06827"
"81906","491.40000","40.95015","0.06313"
"81976","491.82000","40.98507","0.06208"
"82046","492.24000","41.02016","0.07202"
"82116","492.66000","41.05514","0.06732"
"82186","493.08000","41.09024","0.06566"
"82256","493.50000","41.12516","0.07504"
"82326","493.92000","41.16013","0.07215"
"82396","494.34000","41.19511","0.07017"
"82466","494.76000","41.23014","0.07808"
"82536","495.18000","41.26512","0.07822"
"82606","495.60000","41.30010","0.07447"
"82676","496.02000","41.33514","0.08127"
"82746","496.44000","41.37017","0.08419"
"82816","496.86000","41.40515","0.08051"
"82886","497.28000","41.44019","0.08334"
"82956","497.70000","41.47516","0.08888"
"83026","498.12000","41.51020","0.08647"
"83096","498.54000","41.54517","0.08700"
"83166","498.96000","41.58015","0.09106"
"83236","499.38000","41.61513","0.09127"
"83306","499.80000","41.65005","0.09040"
"83376","500.22000","41.68520","0.09247"
"83446","500.64000","41.72018","0.09451"
"83516","501.06000","41.75510","0.09359"
"83586","501.48000","41.79013","0.09423"
"83656","501.90000","41.82517","0.09640"
"83726","502.32000","41.86021","0.09678"
"83796","502.74000","41.89518","0.09644"
"83866","503.16000","41.93010","0.09732"
"83936","503.58000","41.96514","0.09896"
"84006","504.00000","42.00023","0.09880"
"84076","504.42000","42.03515","0.09892"
"84146","504.84000","42.07013","0.09968"
"84216","505.26000","42.10510","0.10050"
"84286","505.68000","42.14014","0.10108"
"84356","506.10000","42.17511","0.10077"
"84426","506.52000","42.21021","0.10163"
"84496","506.94000","42.24513","0.10206"
"84566","507.36000","42.28011","0.10147"
"84636","507.78000","42.31515","0.10175"
"84706","508.20000","42.35012","0.10282"
"84776","508.62000","42.38516","0.10319"
"84846","509.04000","42.42007","0.10320"
"84916","509.46000","42.45517","0.10310"
"84986","509.88000","42.49015","-0.00168"
"85056","510.30000","42.52519","-0.00060"
"85126","510.72000","42.56010","0.00071"
"85196","511.14000","42.59514","0.00134"
"85266","511.56000","42.63012","0.00172"
"85336","511.98000","42.66515","0.00318"
"85406","512.40000","42.70013","0.00148"
"85476","512.82000","42.73504","0.00087"
"85546","513.24000","42.77014","0.00304"
"85616","513.66000","42.80518","0.00106"
"85686","514.08000","42.84015","0.00233"
"85756","514.50000","42.87513","0.00374"
"85826","514.92000","42.91017","0.00185"
"85874","515.20400","42.93385","0.00205"