File: Trajectories_together/161223Specimen_RawData_8.csv
"","V1","V2","V3"
"1","End date","12/23/2016",""
"2","Specimen label","24DG_90",""
"3","Maximum Load","1.01062","N"
"4","Time","Extension","Load"
"5","(s)","(mm)","(N)"
"6","0.00000","0.00000","0.00002"
"70","0.38400","0.03211","0.00107"
"134","0.76800","0.06415","0.00229"
"198","1.15200","0.09620","0.00269"
"262","1.53600","0.12813","0.00285"
"326","1.92000","0.16012","0.00300"
"390","2.30400","0.19216","0.00403"
"454","2.68800","0.22421","0.00418"
"518","3.07200","0.25608","0.00440"
"582","3.45600","0.28819","0.00492"
"646","3.84000","0.32017","0.00529"
"710","4.22400","0.35216","0.00545"
"774","4.60800","0.38409","0.00577"
"838","4.99200","0.41614","0.00573"
"902","5.37600","0.44812","0.00595"
"966","5.76000","0.48005","0.00656"
"1030","6.14400","0.51216","0.00640"
"1094","6.52800","0.54408","0.00692"
"1158","6.91200","0.57607","0.00660"
"1222","7.29600","0.60812","0.00702"
"1286","7.68000","0.64011","0.00711"
"1350","8.06400","0.67215","0.00737"
"1414","8.44800","0.70408","0.00724"
"1478","8.83200","0.73607","0.00795"
"1542","9.21600","0.76812","0.00787"
"1606","9.60000","0.80016","0.00766"
"1670","9.98400","0.83215","0.00786"
"1734","10.36800","0.86414","0.00830"
"1798","10.75200","0.89619","0.00823"
"1862","11.13600","0.92805","0.00823"
"1926","11.52000","0.96016","0.00854"
"1990","11.90400","0.99215","0.00850"
"2054","12.28800","1.02413","0.00861"
"2118","12.67200","1.05612","0.00897"
"2182","13.05600","1.08817","0.00895"
"2246","13.44000","1.12010","0.00900"
"2310","13.82400","1.15208","0.00909"
"2374","14.20800","1.18419","0.00928"
"2438","14.59200","1.21618","0.00939"
"2502","14.97600","1.24805","0.00931"
"2566","15.36000","1.28009","0.00968"
"2630","15.74400","1.31214","0.00978"
"2694","16.12800","1.34413","0.00975"
"2758","16.51200","1.37612","0.01015"
"2822","16.89600","1.40816","0.00997"
"2886","17.28000","1.44015","0.01010"
"2950","17.66400","1.47208","0.01030"
"3014","18.04800","1.50413","0.00988"
"3078","18.43200","1.53611","0.01041"
"3142","18.81600","1.56816","0.00974"
"3206","19.20000","1.60009","0.00971"
"3270","19.58400","1.63213","0.01017"
"3334","19.96800","1.66412","0.01092"
"3398","20.35200","1.69611","0.01019"
"3462","20.73600","1.72810","0.00983"
"3526","21.12000","1.76014","0.01020"
"3590","21.50400","1.79207","0.01017"
"3654","21.88800","1.82406","0.00995"
"3718","22.27200","1.85617","0.01059"
"3782","22.65600","1.88821","0.01077"
"3846","23.04000","1.92008","0.01046"
"3910","23.42400","1.95207","0.01073"
"3974","23.80800","1.98418","0.01065"
"4038","24.19200","2.01610","0.01048"
"4102","24.57600","2.04809","0.01030"
"4166","24.96000","2.08014","0.01044"
"4230","25.34400","2.11219","0.01062"
"4294","25.72800","2.14411","0.01066"
"4358","26.11200","2.17616","0.01076"
"4422","26.49600","2.20809","0.01086"
"4486","26.88000","2.24013","0.01081"
"4550","27.26400","2.27212","0.01078"
"4614","27.64800","2.30417","0.01082"
"4678","28.03200","2.33616","0.01093"
"4742","28.41600","2.36814","0.01066"
"4806","28.80000","2.40013","0.01104"
"4870","29.18400","2.43218","0.01072"
"4934","29.56800","2.46423","0.01087"
"4998","29.95200","2.49609","0.01135"
"5062","30.33600","2.52814","0.01105"
"5126","30.72000","2.56013","0.01140"
"5190","31.10400","2.59206","0.01114"
"5254","31.48800","2.62410","0.01099"
"5318","31.87200","2.65621","0.01142"
"5382","32.25600","2.68814","0.01104"
"5446","32.64000","2.72012","0.01124"
"5510","33.02400","2.75211","0.01145"
"5574","33.40800","2.78416","0.01114"
"5638","33.79200","2.81609","0.01127"
"5702","34.17600","2.84813","0.01124"
"5766","34.56000","2.88012","0.01132"
"5830","34.94400","2.91211","0.01113"
"5894","35.32800","2.94416","0.01125"
"5958","35.71200","2.97614","0.01151"
"6022","36.09600","3.00813","0.01151"
"6086","36.48000","3.04012","0.01148"
"6150","36.86400","3.07211","0.01161"
"6214","37.24800","3.10409","0.01176"
"6278","37.63200","3.13614","0.01159"
"6342","38.01600","3.16813","0.01166"
"6406","38.40000","3.20012","0.01140"
"6470","38.78400","3.23216","0.01146"
"6534","39.16800","3.26415","0.01129"
"6598","39.55200","3.29608","0.01161"
"6662","39.93600","3.32812","0.01159"
"6726","40.32000","3.36011","0.01158"
"6790","40.70400","3.39210","0.01175"
"6854","41.08800","3.42415","0.01138"
"6918","41.47200","3.45619","0.01177"
"6982","41.85600","3.48806","0.01181"
"7046","42.24000","3.52017","0.01200"
"7110","42.62400","3.55222","0.01190"
"7174","43.00800","3.58414","0.01162"
"7238","43.39200","3.61607","0.01189"
"7302","43.77600","3.64818","0.01193"
"7366","44.16000","3.68011","0.01164"
"7430","44.54400","3.71209","0.01196"
"7494","44.92800","3.74414","0.01182"
"7558","45.31200","3.77613","0.01198"
"7622","45.69600","3.80812","0.01218"
"7686","46.08000","3.84004","0.01209"
"7750","46.46400","3.87215","0.01195"
"7814","46.84800","3.90414","0.01172"
"7878","47.23200","3.93606","0.01225"
"7942","47.61600","3.96811","0.01200"
"8006","48.00000","4.00016","0.01242"
"8070","48.38400","4.03215","0.01201"
"8134","48.76800","4.06413","0.01203"
"8198","49.15200","4.09612","0.01218"
"8262","49.53600","4.12817","0.01245"
"8326","49.92000","4.16010","0.01212"
"8390","50.30400","4.19214","0.01212"
"8454","50.68800","4.22419","0.01199"
"8518","51.07200","4.25612","0.01253"
"8582","51.45600","4.28811","0.01223"
"8646","51.84000","4.32009","0.01209"
"8710","52.22400","4.35220","0.01230"
"8774","52.60800","4.38407","0.01200"
"8838","52.99200","4.41611","0.01213"
"8902","53.37600","4.44810","0.01224"
"8966","53.76000","4.48015","0.01236"
"9030","54.14400","4.51208","0.01245"
"9094","54.52800","4.54418","0.01298"
"9158","54.91200","4.57617","0.01313"
"9222","55.29600","4.60804","0.01299"
"9286","55.68000","4.64015","0.01261"
"9350","56.06400","4.67213","0.01246"
"9414","56.44800","4.70412","0.01309"
"9478","56.83200","4.73611","0.01280"
"9542","57.21600","4.76816","0.01311"
"9606","57.60000","4.80014","0.01269"
"9670","57.98400","4.83213","0.01271"
"9734","58.36800","4.86412","0.01275"
"9798","58.75200","4.89611","0.01293"
"9862","59.13600","4.92815","0.01289"
"9926","59.52000","4.96014","0.01293"
"9990","59.90400","4.99219","0.01310"
"10054","60.28800","5.02423","0.01278"
"10118","60.67200","5.05604","0.01314"
"10182","61.05600","5.08815","0.01327"
"10246","61.44000","5.12014","0.01302"
"10310","61.82400","5.15212","0.01344"
"10374","62.20800","5.18405","0.01312"
"10438","62.59200","5.21610","0.01365"
"10502","62.97600","5.24821","0.01297"
"10566","63.36000","5.28007","0.01376"
"10630","63.74400","5.31212","0.01372"
"10694","64.12800","5.34417","0.01361"
"10758","64.51200","5.37609","0.01404"
"10822","64.89600","5.40808","0.01423"
"10886","65.28000","5.44019","0.01392"
"10950","65.66400","5.47212","0.01387"
"11014","66.04800","5.50410","0.01371"
"11078","66.43200","5.53615","0.01387"
"11142","66.81600","5.56814","0.01389"
"11206","67.20000","5.60013","0.01373"
"11270","67.58400","5.63211","0.01380"
"11334","67.96800","5.66410","0.01374"
"11398","68.35200","5.69615","0.01382"
"11462","68.73600","5.72808","0.01396"
"11526","69.12000","5.76012","0.01414"
"11590","69.50400","5.79211","0.01408"
"11654","69.88800","5.82416","0.01423"
"11718","70.27200","5.85609","0.01443"
"11782","70.65600","5.88813","0.01503"
"11846","71.04000","5.92018","0.01469"
"11910","71.42400","5.95205","0.01502"
"11974","71.80800","5.98410","0.01486"
"12038","72.19200","6.01620","0.01465"
"12102","72.57600","6.04813","0.01463"
"12166","72.96000","6.08012","0.01480"
"12230","73.34400","6.11216","0.01393"
"12294","73.72800","6.14409","0.01463"
"12358","74.11200","6.17608","0.01458"
"12422","74.49600","6.20813","0.01479"
"12486","74.88000","6.24011","0.01445"
"12550","75.26400","6.27210","0.01448"
"12614","75.64800","6.30409","0.01488"
"12678","76.03200","6.33614","0.01544"
"12742","76.41600","6.36818","0.01503"
"12806","76.80000","6.40005","0.01544"
"12870","77.18400","6.43216","0.01516"
"12934","77.56800","6.46409","0.01547"
"12998","77.95200","6.49613","0.01542"
"13062","78.33600","6.52812","0.01580"
"13126","78.72000","6.56017","0.01550"
"13190","79.10400","6.59215","0.01570"
"13254","79.48800","6.62414","0.01626"
"13318","79.87200","6.65607","0.01560"
"13382","80.25600","6.68812","0.01528"
"13446","80.64000","6.72010","0.01577"
"13510","81.02400","6.75209","0.01573"
"13574","81.40800","6.78414","0.01546"
"13638","81.79200","6.81613","0.01579"
"13702","82.17600","6.84805","0.01544"
"13766","82.56000","6.88010","0.01588"
"13830","82.94400","6.91221","0.01580"
"13894","83.32800","6.94408","0.01608"
"13958","83.71200","6.97606","0.01621"
"14022","84.09600","7.00817","0.01587"
"14086","84.48000","7.04016","0.01606"
"14150","84.86400","7.07209","0.01591"
"14214","85.24800","7.10413","0.01620"
"14278","85.63200","7.13612","0.01617"
"14342","86.01600","7.16811","0.01585"
"14406","86.40000","7.20015","0.01694"
"14470","86.78400","7.23214","0.01673"
"14534","87.16800","7.26413","0.01631"
"14598","87.55200","7.29612","0.01683"
"14662","87.93600","7.32810","0.01680"
"14726","88.32000","7.36015","0.01653"
"14790","88.70400","7.39214","0.01663"
"14854","89.08800","7.42413","0.01672"
"14918","89.47200","7.45617","0.01681"
"14982","89.85600","7.48816","0.01647"
"15046","90.24000","7.52009","0.01683"
"15110","90.62400","7.55208","0.01645"
"15174","91.00800","7.58412","0.01651"
"15238","91.39200","7.61611","0.01634"
"15302","91.77600","7.64810","0.01667"
"15366","92.16000","7.68015","0.01702"
"15430","92.54400","7.71213","0.01718"
"15494","92.92800","7.74406","0.01723"
"15558","93.31200","7.77611","0.01689"
"15622","93.69600","7.80816","0.01687"
"15686","94.08000","7.84008","0.01755"
"15750","94.46400","7.87213","0.01693"
"15814","94.84800","7.90418","0.01700"
"15878","95.23200","7.93610","0.01714"
"15942","95.61600","7.96809","0.01719"
"16006","96.00000","8.00020","0.01687"
"16070","96.38400","8.03213","0.01728"
"16134","96.76800","8.06411","0.01757"
"16198","97.15200","8.09610","0.01798"
"16262","97.53600","8.12815","0.01810"
"16326","97.92000","8.16013","0.01764"
"16390","98.30400","8.19212","0.01797"
"16454","98.68800","8.22417","0.01776"
"16518","99.07200","8.25616","0.01788"
"16582","99.45600","8.28814","0.01811"
"16646","99.84000","8.32007","0.01818"
"16710","100.22400","8.35212","0.01825"
"16774","100.60800","8.38417","0.01839"
"16838","100.99200","8.41609","0.01862"
"16902","101.37600","8.44820","0.01884"
"16966","101.76000","8.48019","0.01874"
"17030","102.14400","8.51206","0.01939"
"17094","102.52800","8.54416","0.01917"
"17158","102.91200","8.57615","0.01969"
"17222","103.29600","8.60814","0.01951"
"17286","103.68000","8.64007","0.01941"
"17350","104.06400","8.67211","0.02003"
"17414","104.44800","8.70416","0.02047"
"17478","104.83200","8.73615","0.02061"
"17542","105.21600","8.76807","0.02018"
"17606","105.60000","8.80018","0.02089"
"17670","105.98400","8.83211","0.02104"
"17734","106.36800","8.86410","0.02058"
"17798","106.75200","8.89614","0.02104"
"17862","107.13600","8.92813","0.02206"
"17926","107.52000","8.96012","0.02140"
"17990","107.90400","8.99211","0.02148"
"18054","108.28800","9.02415","0.02208"
"18118","108.67200","9.05614","0.02224"
"18182","109.05600","9.08813","0.02264"
"18246","109.44000","9.12012","0.02252"
"18310","109.82400","9.15210","0.02313"
"18374","110.20800","9.18409","0.02322"
"18438","110.59200","9.21614","0.02373"
"18502","110.97600","9.24813","0.02333"
"18566","111.36000","9.28017","0.02346"
"18630","111.74400","9.31210","0.02388"
"18694","112.12800","9.34409","0.02407"
"18758","112.51200","9.37613","0.02449"
"18822","112.89600","9.40812","0.02487"
"18886","113.28000","9.44011","0.02503"
"18950","113.66400","9.47216","0.02537"
"19014","114.04800","9.50414","0.02509"
"19078","114.43200","9.53607","0.02576"
"19142","114.81600","9.56818","0.02611"
"19206","115.20000","9.60017","0.02611"
"19270","115.58400","9.63209","0.02533"
"19334","115.96800","9.66414","0.02575"
"19398","116.35200","9.69619","0.02654"
"19462","116.73600","9.72806","0.02643"
"19526","117.12000","9.76010","0.02691"
"19590","117.50400","9.79215","0.02733"
"19654","117.88800","9.82414","0.02731"
"19718","118.27200","9.85612","0.02811"
"19782","118.65600","9.88811","0.02781"
"19846","119.04000","9.92010","0.02854"
"19910","119.42400","9.95215","0.02838"
"19974","119.80800","9.98413","0.02893"
"20038","120.19200","10.01612","0.02926"
"20102","120.57600","10.04817","0.02912"
"20166","120.96000","10.08010","0.02950"
"20230","121.34400","10.11208","0.02975"
"20294","121.72800","10.14413","0.02936"
"20358","122.11200","10.17618","0.02945"
"20422","122.49600","10.20811","0.03005"
"20486","122.88000","10.24015","0.03017"
"20550","123.26400","10.27220","0.03059"
"20614","123.64800","10.30407","0.03084"
"20678","124.03200","10.33612","0.03120"
"20742","124.41600","10.36822","0.03115"
"20806","124.80000","10.40009","0.03108"
"20870","125.18400","10.43208","0.03158"
"20934","125.56800","10.46413","0.03140"
"20998","125.95200","10.49611","0.03129"
"21062","126.33600","10.52810","0.03182"
"21126","126.72000","10.56015","0.03178"
"21190","127.10400","10.59213","0.03210"
"21254","127.48800","10.62412","0.03281"
"21318","127.87200","10.65617","0.03239"
"21382","128.25600","10.68816","0.03274"
"21446","128.64000","10.72014","0.03277"
"21510","129.02400","10.75213","0.03297"
"21574","129.40800","10.78412","0.03256"
"21638","129.79200","10.81611","0.03346"
"21702","130.17600","10.84809","0.03340"
"21766","130.56000","10.88008","0.03370"
"21830","130.94400","10.91219","0.03384"
"21894","131.32800","10.94418","0.03420"
"21958","131.71200","10.97610","0.03412"
"22022","132.09600","11.00815","0.03394"
"22086","132.48000","11.04014","0.03416"
"22150","132.86400","11.07213","0.03457"
"22214","133.24800","11.10411","0.03419"
"22278","133.63200","11.13616","0.03390"
"22342","134.01600","11.16815","0.03323"
"22406","134.40000","11.20008","0.03304"
"22470","134.78400","11.23212","0.03338"
"22534","135.16800","11.26417","0.03329"
"22598","135.55200","11.29610","0.03376"
"22662","135.93600","11.32808","0.03386"
"22726","136.32000","11.36013","0.03473"
"22790","136.70400","11.39212","0.03502"
"22854","137.08800","11.42411","0.03490"
"22918","137.47200","11.45615","0.03552"
"22982","137.85600","11.48814","0.03555"
"23046","138.24000","11.52007","0.03639"
"23110","138.62400","11.55212","0.03593"
"23174","139.00800","11.58416","0.03634"
"23238","139.39200","11.61615","0.03683"
"23302","139.77600","11.64814","0.03709"
"23366","140.16000","11.68007","0.03758"
"23430","140.54400","11.71211","0.03798"
"23494","140.92800","11.74416","0.03814"
"23558","141.31200","11.77609","0.03840"
"23622","141.69600","11.80814","0.03865"
"23686","142.08000","11.84018","0.03947"
"23750","142.46400","11.87205","0.03859"
"23814","142.84800","11.90410","0.03928"
"23878","143.23200","11.93614","0.03935"
"23942","143.61600","11.96813","0.04021"
"24006","144.00000","12.00012","0.04090"
"24070","144.38400","12.03217","0.04151"
"24134","144.76800","12.06415","0.04189"
"24198","145.15200","12.09608","0.04288"
"24262","145.53600","12.12819","0.04316"
"24326","145.92000","12.16018","0.04376"
"24390","146.30400","12.19210","0.04464"
"24454","146.68800","12.22409","0.04494"
"24518","147.07200","12.25614","0.04564"
"24582","147.45600","12.28812","0.04650"
"24646","147.84000","12.32011","0.04746"
"24710","148.22400","12.35216","0.04808"
"24774","148.60800","12.38415","0.04896"
"24838","148.99200","12.41613","0.04951"
"24902","149.37600","12.44812","0.05043"
"24966","149.76000","12.48017","0.05140"
"25030","150.14400","12.51222","0.05215"
"25094","150.52800","12.54414","0.05349"
"25158","150.91200","12.57607","0.05461"
"25222","151.29600","12.60812","0.05523"
"25286","151.68000","12.64017","0.05600"
"25350","152.06400","12.67209","0.05669"
"25414","152.44800","12.70420","0.05786"
"25478","152.83200","12.73613","0.05842"
"25542","153.21600","12.76799","0.05937"
"25606","153.60000","12.80010","0.06011"
"25670","153.98400","12.83215","0.06152"
"25734","154.36800","12.86414","0.06221"
"25798","154.75200","12.89612","0.06319"
"25862","155.13600","12.92817","0.06324"
"25926","155.52000","12.96010","0.06441"
"25990","155.90400","12.99209","0.06537"
"26054","156.28800","13.02419","0.06707"
"26118","156.67200","13.05612","0.06858"
"26182","157.05600","13.08811","0.06937"
"26246","157.44000","13.12010","0.07096"
"26310","157.82400","13.15214","0.07235"
"26374","158.20800","13.18413","0.07364"
"26438","158.59200","13.21606","0.07511"
"26502","158.97600","13.24817","0.07573"
"26566","159.36000","13.28015","0.07752"
"26630","159.74400","13.31208","0.07838"
"26694","160.12800","13.34413","0.07915"
"26758","160.51200","13.37617","0.08090"
"26822","160.89600","13.40810","0.08210"
"26886","161.28000","13.44015","0.08271"
"26950","161.66400","13.47214","0.08433"
"27014","162.04800","13.50412","0.08522"
"27078","162.43200","13.53611","0.08601"
"27142","162.81600","13.56810","0.08593"
"27206","163.20000","13.60015","0.08735"
"27270","163.58400","13.63213","0.08814"
"27334","163.96800","13.66406","0.08993"
"27398","164.35200","13.69611","0.09103"
"27462","164.73600","13.72816","0.09222"
"27526","165.12000","13.76008","0.09210"
"27590","165.50400","13.79213","0.09476"
"27654","165.88800","13.82412","0.09746"
"27718","166.27200","13.85611","0.09927"
"27782","166.65600","13.88803","0.10123"
"27846","167.04000","13.92014","0.10317"
"27910","167.42400","13.95213","0.10458"
"27974","167.80800","13.98406","0.10602"
"28038","168.19200","14.01604","0.10738"
"28102","168.57600","14.04815","0.10826"
"28166","168.96000","14.08014","0.10928"
"28230","169.34400","14.11212","0.11062"
"28294","169.72800","14.14417","0.11171"
"28358","170.11200","14.17616","0.11299"
"28422","170.49600","14.20815","0.11410"
"28486","170.88000","14.24013","0.11519"
"28550","171.26400","14.27218","0.11619"
"28614","171.64800","14.30417","0.11728"
"28678","172.03200","14.33609","0.11821"
"28742","172.41600","14.36808","0.11939"
"28806","172.80000","14.40019","0.12087"
"28870","173.18400","14.43212","0.12231"
"28934","173.56800","14.46411","0.12360"
"28998","173.95200","14.49615","0.12574"
"29062","174.33600","14.52820","0.12742"
"29126","174.72000","14.56007","0.12906"
"29190","175.10400","14.59211","0.13084"
"29254","175.48800","14.62416","0.13207"
"29318","175.87200","14.65609","0.13397"
"29382","176.25600","14.68808","0.13624"
"29446","176.64000","14.72018","0.13845"
"29510","177.02400","14.75211","0.14009"
"29574","177.40800","14.78410","0.14376"
"29638","177.79200","14.81614","0.13867"
"29702","178.17600","14.84813","0.14089"
"29766","178.56000","14.88012","0.14434"
"29830","178.94400","14.91211","0.14743"
"29894","179.32800","14.94416","0.15225"
"29958","179.71200","14.97614","0.15447"
"30022","180.09600","15.00813","0.15867"
"30086","180.48000","15.04012","0.16076"
"30150","180.86400","15.07217","0.16365"
"30214","181.24800","15.10409","0.16494"
"30278","181.63200","15.13614","0.16672"
"30342","182.01600","15.16813","0.16971"
"30406","182.40000","15.20017","0.17135"
"30470","182.78400","15.23210","0.17495"
"30534","183.16800","15.26415","0.17894"
"30598","183.55200","15.29620","0.18261"
"30662","183.93600","15.32812","0.18653"
"30726","184.32000","15.36011","0.18873"
"30790","184.70400","15.39216","0.19091"
"30854","185.08800","15.42408","0.19317"
"30918","185.47200","15.45607","0.19586"
"30982","185.85600","15.48818","0.19891"
"31046","186.24000","15.52017","0.20176"
"31110","186.62400","15.55210","0.20447"
"31174","187.00800","15.58414","0.20693"
"31238","187.39200","15.61619","0.20929"
"31302","187.77600","15.64812","0.21195"
"31366","188.16000","15.68010","0.21429"
"31430","188.54400","15.71215","0.21693"
"31494","188.92800","15.74414","0.21897"
"31558","189.31200","15.77607","0.22153"
"31622","189.69600","15.80811","0.22310"
"31686","190.08000","15.84016","0.22505"
"31750","190.46400","15.87215","0.22694"
"31814","190.84800","15.90407","0.22878"
"31878","191.23200","15.93612","0.23125"
"31942","191.61600","15.96817","0.23406"
"32006","192.00000","16.00016","0.23667"
"32070","192.38400","16.03209","0.23897"
"32134","192.76800","16.06419","0.24201"
"32198","193.15200","16.09618","0.24514"
"32262","193.53600","16.12811","0.24817"
"32326","193.92000","16.16015","0.25271"
"32390","194.30400","16.19214","0.25701"
"32454","194.68800","16.22413","0.26047"
"32518","195.07200","16.25612","0.26315"
"32582","195.45600","16.28816","0.26479"
"32646","195.84000","16.32015","0.26880"
"32710","196.22400","16.35202","0.27212"
"32774","196.60800","16.38418","0.27643"
"32838","196.99200","16.41617","0.28067"
"32902","197.37600","16.44804","0.28468"
"32966","197.76000","16.48015","0.28799"
"33030","198.14400","16.51213","0.29147"
"33094","198.52800","16.54412","0.29691"
"33158","198.91200","16.57611","0.30363"
"33222","199.29600","16.60816","0.30925"
"33286","199.68000","16.64014","0.31424"
"33350","200.06400","16.67213","0.31672"
"33414","200.44800","16.70406","0.31980"
"33478","200.83200","16.73617","0.32211"
"33542","201.21600","16.76815","0.32373"
"33606","201.60000","16.80008","0.32628"
"33670","201.98400","16.83213","0.32852"
"33734","202.36800","16.86418","0.33112"
"33798","202.75200","16.89616","0.33365"
"33862","203.13600","16.92809","0.33630"
"33926","203.52000","16.96014","0.33939"
"33990","203.90400","16.99213","0.34191"
"34054","204.28800","17.02411","0.34438"
"34118","204.67200","17.05616","0.34686"
"34182","205.05600","17.08821","0.35008"
"34246","205.44000","17.12008","0.35378"
"34310","205.82400","17.15218","0.35846"
"34374","206.20800","17.18417","0.36326"
"34438","206.59200","17.21610","0.36660"
"34502","206.97600","17.24809","0.37065"
"34566","207.36000","17.28013","0.37489"
"34630","207.74400","17.31212","0.37930"
"34694","208.12800","17.34411","0.38483"
"34758","208.51200","17.37615","0.38981"
"34822","208.89600","17.40808","0.39322"
"34886","209.28000","17.44013","0.39579"
"34950","209.66400","17.47212","0.39893"
"35014","210.04800","17.50410","0.40259"
"35078","210.43200","17.53615","0.40694"
"35142","210.81600","17.56808","0.41189"
"35206","211.20000","17.60007","0.41578"
"35270","211.58400","17.63217","0.41896"
"35334","211.96800","17.66410","0.42146"
"35398","212.35200","17.69615","0.42442"
"35462","212.73600","17.72813","0.42679"
"35526","213.12000","17.76012","0.42989"
"35590","213.50400","17.79211","0.43294"
"35654","213.88800","17.82416","0.43700"
"35718","214.27200","17.85614","0.44137"
"35782","214.65600","17.88813","0.44488"
"35846","215.04000","17.92012","0.44984"
"35910","215.42400","17.95211","0.45318"
"35974","215.80800","17.98421","0.45815"
"36038","216.19200","18.01608","0.46203"
"36102","216.57600","18.04813","0.46712"
"36166","216.96000","18.08018","0.47000"
"36230","217.34400","18.11216","0.47330"
"36294","217.72800","18.14409","0.47691"
"36358","218.11200","18.17620","0.48244"
"36422","218.49600","18.20819","0.48908"
"36486","218.88000","18.24005","0.49394"
"36550","219.26400","18.27216","0.49743"
"36614","219.64800","18.30415","0.50151"
"36678","220.03200","18.33607","0.50511"
"36742","220.41600","18.36812","0.50876"
"36806","220.80000","18.40011","0.51491"
"36870","221.18400","18.43216","0.52022"
"36934","221.56800","18.46408","0.52567"
"36998","221.95200","18.49607","0.52971"
"37062","222.33600","18.52818","0.53330"
"37126","222.72000","18.56011","0.53518"
"37190","223.10400","18.59209","0.53823"
"37254","223.48800","18.62414","0.54114"
"37318","223.87200","18.65619","0.54453"
"37382","224.25600","18.68812","0.54846"
"37446","224.64000","18.72010","0.55290"
"37510","225.02400","18.75215","0.55679"
"37574","225.40800","18.78414","0.56146"
"37638","225.79200","18.81606","0.56692"
"37702","226.17600","18.84817","0.57088"
"37766","226.56000","18.88016","0.57563"
"37830","226.94400","18.91209","0.57950"
"37894","227.32800","18.94414","0.58610"
"37958","227.71200","18.97618","0.59346"
"38022","228.09600","19.00805","0.59843"
"38086","228.48000","19.04004","0.60310"
"38150","228.86400","19.07220","0.60807"
"38214","229.24800","19.10413","0.61349"
"38278","229.63200","19.13612","0.61850"
"38342","230.01600","19.16817","0.62213"
"38406","230.40000","19.20009","0.62472"
"38470","230.78400","19.23214","0.62908"
"38534","231.16800","19.26419","0.63377"
"38598","231.55200","19.29618","0.63718"
"38662","231.93600","19.32816","0.64095"
"38726","232.32000","19.36009","0.64394"
"38790","232.70400","19.39208","0.64799"
"38854","233.08800","19.42413","0.65197"
"38918","233.47200","19.45617","0.65641"
"38982","233.85600","19.48810","0.66248"
"39046","234.24000","19.52021","0.66889"
"39110","234.62400","19.55213","0.67450"
"39174","235.00800","19.58406","0.67857"
"39238","235.39200","19.61611","0.68337"
"39302","235.77600","19.64816","0.69179"
"39366","236.16000","19.68008","0.69941"
"39430","236.54400","19.71213","0.70524"
"39494","236.92800","19.74418","0.70899"
"39558","237.31200","19.77617","0.71354"
"39622","237.69600","19.80809","0.72121"
"39686","238.08000","19.84014","0.72653"
"39750","238.46400","19.87213","0.69998"
"39814","238.84800","19.90411","0.70736"
"39878","239.23200","19.93610","0.71499"
"39942","239.61600","19.96815","0.72521"
"40006","240.00000","20.00014","0.73174"
"40070","240.38400","20.03206","0.73737"
"40134","240.76800","20.06417","0.74170"
"40198","241.15200","20.09610","0.74565"
"40262","241.53600","20.12809","0.75097"
"40326","241.92000","20.16007","0.75564"
"40390","242.30400","20.19218","0.75970"
"40454","242.68800","20.22417","0.76603"
"40518","243.07200","20.25610","0.77214"
"40582","243.45600","20.28808","0.77926"
"40646","243.84000","20.32013","0.78797"
"40710","244.22400","20.35212","0.79808"
"40774","244.60800","20.38410","0.80581"
"40838","244.99200","20.41615","0.81089"
"40902","245.37600","20.44814","0.81714"
"40966","245.76000","20.48007","0.82658"
"41030","246.14400","20.51212","0.83355"
"41094","246.52800","20.54422","0.83987"
"41158","246.91200","20.57615","0.84484"
"41222","247.29600","20.60814","0.84835"
"41286","247.68000","20.64018","0.85207"
"41350","248.06400","20.67217","0.85898"
"41414","248.44800","20.70404","0.86353"
"41478","248.83200","20.73621","0.86808"
"41542","249.21600","20.76813","0.87381"
"41606","249.60000","20.80012","0.87954"
"41670","249.98400","20.83211","0.88404"
"41734","250.36800","20.86415","0.88915"
"41798","250.75200","20.89614","0.89744"
"41862","251.13600","20.92807","0.90463"
"41926","251.52000","20.96012","0.90937"
"41990","251.90400","20.99211","0.85621"
"42054","252.28800","21.02415","0.85246"
"42118","252.67200","21.05614","0.85326"
"42182","253.05600","21.08813","0.85999"
"42246","253.44000","21.12017","0.86567"
"42310","253.82400","21.15210","0.86837"
"42374","254.20800","21.18409","0.87749"
"42438","254.59200","21.21614","0.88546"
"42502","254.97600","21.24813","0.89383"
"42566","255.36000","21.28011","0.90122"
"42630","255.74400","21.31216","0.90906"
"42694","256.12800","21.34414","0.92000"
"42758","256.51200","21.37607","0.92685"
"42822","256.89600","21.40812","0.93154"
"42886","257.28000","21.44017","0.93946"
"42950","257.66400","21.47210","0.94673"
"43014","258.04800","21.50414","0.95201"
"43078","258.43200","21.53613","0.95641"
"43142","258.81600","21.56812","0.96255"
"43206","259.20000","21.60011","0.97565"
"43270","259.58400","21.63215","0.98660"
"43334","259.96800","21.66414","0.99255"
"43398","260.35200","21.69613","0.99985"
"43462","260.73600","21.72817","1.00880"
"43526","261.12000","21.76010","0.78264"
"43590","261.50400","21.79215","0.77593"
"43654","261.88800","21.82408","0.77963"
"43718","262.27200","21.85612","0.51329"
"43782","262.65600","21.88817","0.51496"
"43846","263.04000","21.92010","0.51014"
"43910","263.42400","21.95209","0.51868"
"43974","263.80800","21.98413","0.52209"
"44038","264.19200","22.01612","0.52668"
"44102","264.57600","22.04805","0.53461"
"44166","264.96000","22.08010","0.53462"
"44230","265.34400","22.11220","0.54037"
"44294","265.72800","22.14413","0.54077"
"44358","266.11200","22.17612","0.54608"
"44422","266.49600","22.20817","0.55062"
"44486","266.88000","22.24015","0.55365"
"44550","267.26400","22.27208","0.55881"
"44614","267.64800","22.30412","0.56034"
"44678","268.03200","22.33611","0.56691"
"44742","268.41600","22.36810","0.56737"
"44806","268.80000","22.40015","0.57428"
"44870","269.18400","22.43213","0.57431"
"44934","269.56800","22.46412","0.58017"
"44998","269.95200","22.49605","0.58012"
"45062","270.33600","22.52816","0.58638"
"45126","270.72000","22.56015","0.58711"
"45190","271.10400","22.59207","0.59226"
"45254","271.48800","22.62412","0.59385"
"45318","271.87200","22.65611","0.59771"
"45382","272.25600","22.68816","0.59889"
"45446","272.64000","22.72014","0.60228"
"45510","273.02400","22.75213","0.60280"
"45574","273.40800","22.78412","0.60612"
"45638","273.79200","22.81610","0.60752"
"45702","274.17600","22.84809","0.61167"
"45766","274.56000","22.88014","0.59951"
"45830","274.94400","22.91219","0.59764"
"45894","275.32800","22.94411","0.59559"
"45958","275.71200","22.97610","0.59402"
"46022","276.09600","23.00815","0.59311"
"46086","276.48000","23.04014","0.59272"
"46150","276.86400","23.07206","0.59074"
"46214","277.24800","23.10423","0.56574"
"46278","277.63200","23.13616","0.20689"
"46342","278.01600","23.16809","0.21397"
"46406","278.40000","23.20019","0.22613"
"46470","278.78400","23.23218","0.22436"
"46534","279.16800","23.26411","0.22909"
"46598","279.55200","23.29609","0.22512"
"46662","279.93600","23.32814","0.22755"
"46726","280.32000","23.36007","0.22766"
"46790","280.70400","23.39211","0.23199"
"46854","281.08800","23.42416","0.23692"
"46918","281.47200","23.45609","0.24121"
"46982","281.85600","23.48814","0.24636"
"47046","282.24000","23.52012","0.25631"
"47110","282.62400","23.55211","0.26849"
"47174","283.00800","23.58410","0.27489"
"47238","283.39200","23.61609","0.27475"
"47302","283.77600","23.64814","0.27589"
"47366","284.16000","23.68018","0.28192"
"47430","284.54400","23.71211","0.28683"
"47494","284.92800","23.74410","0.29450"
"47558","285.31200","23.77614","0.30952"
"47622","285.69600","23.80819","0.31491"
"47686","286.08000","23.84006","0.31568"
"47750","286.46400","23.87211","0.31818"
"47814","286.84800","23.90415","0.32191"
"47878","287.23200","23.93608","0.32818"
"47942","287.61600","23.96813","0.31858"
"48006","288.00000","24.00018","0.32025"
"48070","288.38400","24.03210","0.32289"
"48134","288.76800","24.06409","0.32647"
"48198","289.15200","24.09620","0.33144"
"48262","289.53600","24.12813","0.33623"
"48326","289.92000","24.16011","0.33787"
"48390","290.30400","24.19216","0.34002"
"48454","290.68800","24.22415","0.34260"
"48518","291.07200","24.25614","0.34607"
"48582","291.45600","24.28806","0.34881"
"48646","291.84000","24.32011","0.35124"
"48710","292.22400","24.35216","0.35449"
"48774","292.60800","24.38408","0.36082"
"48838","292.99200","24.41607","0.36635"
"48902","293.37600","24.44812","0.36744"
"48966","293.76000","24.48011","0.37133"
"49030","294.14400","24.51209","0.37578"
"49094","294.52800","24.54414","0.37891"
"49158","294.91200","24.57613","0.38104"
"49222","295.29600","24.60811","0.38444"
"49286","295.68000","24.64010","0.38883"
"49350","296.06400","24.67215","0.39072"
"49414","296.44800","24.70414","0.39151"
"49478","296.83200","24.73613","0.39271"
"49542","297.21600","24.76817","0.39498"
"49606","297.60000","24.80022","0.39617"
"49670","297.98400","24.83203","0.39770"
"49734","298.36800","24.86408","0.39979"
"49798","298.75200","24.89618","0.40240"
"49862","299.13600","24.92811","0.40365"
"49926","299.52000","24.96004","0.40670"
"49990","299.90400","24.99220","0.40908"
"50054","300.28800","25.02413","0.40869"
"50118","300.67200","25.05612","0.41069"
"50182","301.05600","25.08817","0.41405"
"50246","301.44000","25.12009","0.41490"
"50310","301.82400","25.15214","0.01482"
"50374","302.20800","25.18413","0.01435"
"50438","302.59200","25.21612","0.01392"
"50502","302.97600","25.24817","0.01674"
"50566","303.36000","25.28015","0.01246"
"50630","303.74400","25.31214","0.01305"
"50694","304.12800","25.34413","0.01610"
"50758","304.51200","25.37611","0.01779"
"50822","304.89600","25.40810","0.01441"
"50886","305.28000","25.44015","0.01487"
"50950","305.66400","25.47219","0.01811"
"51014","306.04800","25.50406","0.01785"
"51078","306.43200","25.53611","0.01590"
"51142","306.81600","25.56816","0.01697"
"51206","307.20000","25.60008","0.01938"
"51270","307.58400","25.63213","0.01865"
"51334","307.96800","25.66418","0.01856"
"51398","308.35200","25.69617","0.02066"
"51462","308.73600","25.72809","0.02087"
"51526","309.12000","25.76014","0.02021"
"51590","309.50400","25.79219","0.02162"
"51654","309.88800","25.82411","0.02254"
"51718","310.27200","25.85610","0.02212"
"51782","310.65600","25.88815","0.02184"
"51846","311.04000","25.92008","0.02392"
"51910","311.42400","25.95213","0.02332"
"51974","311.80800","25.98411","0.02319"
"52038","312.19200","26.01616","0.02426"
"52102","312.57600","26.04815","0.02530"
"52166","312.96000","26.08013","0.02563"
"52230","313.34400","26.11212","0.02611"
"52294","313.72800","26.14417","0.02720"
"52358","314.11200","26.17610","0.02680"
"52422","314.49600","26.20809","0.02759"
"52486","314.88000","26.24013","0.02823"
"52550","315.26400","26.27212","0.02863"
"52614","315.64800","26.30411","0.02911"
"52678","316.03200","26.33621","0.02979"
"52742","316.41600","26.36820","0.03022"
"52806","316.80000","26.40007","0.03025"
"52870","317.18400","26.43212","0.03141"
"52934","317.56800","26.46416","0.03223"
"52998","317.95200","26.49609","0.03246"
"53062","318.33600","26.52808","0.03306"
"53126","318.72000","26.56013","0.03368"
"53190","319.10400","26.59211","0.03421"
"53254","319.48800","26.62410","0.03454"
"53318","319.87200","26.65609","0.03558"
"53382","320.25600","26.68814","0.03607"
"53446","320.64000","26.72012","0.03678"
"53510","321.02400","26.75211","0.03758"
"53574","321.40800","26.78416","0.03764"
"53638","321.79200","26.81614","0.03920"
"53702","322.17600","26.84807","0.03939"
"53766","322.56000","26.88012","0.04022"
"53830","322.94400","26.91211","0.04036"
"53894","323.32800","26.94409","0.04122"
"53958","323.71200","26.97614","0.04227"
"54022","324.09600","27.00813","0.04271"
"54086","324.48000","27.04012","0.04404"
"54150","324.86400","27.07210","0.04463"
"54214","325.24800","27.10409","0.04557"
"54278","325.63200","27.13614","0.04606"
"54342","326.01600","27.16813","0.04711"
"54406","326.40000","27.20011","0.04825"
"54470","326.78400","27.23216","0.04926"
"54534","327.16800","27.26415","0.05081"
"54598","327.55200","27.29608","0.05165"
"54662","327.93600","27.32812","0.05256"
"54726","328.32000","27.36017","0.05308"
"54790","328.70400","27.39210","0.05417"
"54854","329.08800","27.42414","0.05516"
"54918","329.47200","27.45619","0.05609"
"54982","329.85600","27.48812","0.05678"
"55046","330.24000","27.52005","0.05742"
"55110","330.62400","27.55215","0.05787"
"55174","331.00800","27.58414","0.05913"
"55238","331.39200","27.61613","0.05972"
"55302","331.77600","27.64812","0.06011"
"55366","332.16000","27.68016","0.06120"
"55430","332.54400","27.71215","0.06168"
"55494","332.92800","27.74408","0.06248"
"55558","333.31200","27.77612","0.06329"
"55622","333.69600","27.80811","0.06337"
"55686","334.08000","27.84016","0.06472"
"55750","334.46400","27.87209","0.06570"
"55814","334.84800","27.90414","0.06628"
"55878","335.23200","27.93612","0.06742"
"55942","335.61600","27.96811","0.06871"
"56006","336.00000","28.00010","0.06990"
"56070","336.38400","28.03214","0.07118"
"56134","336.76800","28.06413","0.07117"
"56198","337.15200","28.09606","0.07202"
"56262","337.53600","28.12817","0.06894"
"56326","337.92000","28.16015","0.06917"
"56390","338.30400","28.19208","0.07102"
"56454","338.68800","28.22413","0.07221"
"56518","339.07200","28.25618","0.07229"
"56582","339.45600","28.28810","0.07174"
"56646","339.84000","28.32015","0.07130"
"56710","340.22400","28.35214","0.07351"
"56774","340.60800","28.38412","0.07358"
"56838","340.99200","28.41611","0.07507"
"56902","341.37600","28.44816","0.07602"
"56966","341.76000","28.48015","0.07559"
"57030","342.14400","28.51213","0.07642"
"57094","342.52800","28.54412","0.07597"
"57158","342.91200","28.57611","0.07575"
"57222","343.29600","28.60810","0.07577"
"57286","343.68000","28.64008","0.07691"
"57350","344.06400","28.67213","0.07747"
"57414","344.44800","28.70412","0.07785"
"57478","344.83200","28.73616","0.07780"
"57542","345.21600","28.76809","0.07862"
"57606","345.60000","28.80014","0.07960"
"57670","345.98400","28.83213","0.08011"
"57734","346.36800","28.86405","0.08101"
"57798","346.75200","28.89610","0.08148"
"57862","347.13600","28.92815","0.08246"
"57926","347.52000","28.96014","0.08251"
"57990","347.90400","28.99218","0.08322"
"58054","348.28800","29.02417","0.08397"
"58118","348.67200","29.05610","0.08445"
"58182","349.05600","29.08809","0.08494"
"58246","349.44000","29.12013","0.08562"
"58310","349.82400","29.15218","0.08629"
"58374","350.20800","29.18411","0.08647"
"58438","350.59200","29.21609","0.08689"
"58502","350.97600","29.24814","0.08781"
"58566","351.36000","29.28013","0.08814"
"58630","351.74400","29.31206","0.08856"
"58694","352.12800","29.34410","0.09002"
"58758","352.51200","29.37615","0.09042"
"58822","352.89600","29.40808","0.09126"
"58886","353.28000","29.44013","0.09265"
"58950","353.66400","29.47211","0.09213"
"59014","354.04800","29.50410","0.09314"
"59078","354.43200","29.53615","0.09413"
"59142","354.81600","29.56814","0.09497"
"59206","355.20000","29.60012","0.09691"
"59270","355.58400","29.63211","0.09420"
"59334","355.96800","29.66410","0.08934"
"59398","356.35200","29.69615","0.08820"
"59462","356.73600","29.72813","0.08902"
"59526","357.12000","29.76012","0.08654"
"59590","357.50400","29.79217","0.08821"
"59654","357.88800","29.82415","0.08803"
"59718","358.27200","29.85608","0.08803"
"59782","358.65600","29.88807","0.08729"
"59846","359.04000","29.92018","0.08934"
"59910","359.42400","29.95211","0.09110"
"59974","359.80800","29.98403","0.09263"
"60038","360.19200","30.01620","0.09313"
"60102","360.57600","30.04813","0.09452"
"60166","360.96000","30.08012","0.09728"
"60230","361.34400","30.11216","0.09709"
"60294","361.72800","30.14415","0.09731"
"60358","362.11200","30.17608","0.09824"
"60422","362.49600","30.20813","0.09966"
"60486","362.88000","30.24017","0.10133"
"60550","363.26400","30.27216","0.10292"
"60614","363.64800","30.30408","0.10456"
"60678","364.03200","30.33613","0.10532"
"60742","364.41600","30.36812","0.10648"
"60806","364.80000","30.40011","0.10727"
"60870","365.18400","30.43210","0.10812"
"60934","365.56800","30.46414","0.10846"
"60998","365.95200","30.49613","0.10935"
"61062","366.33600","30.52812","0.10985"
"61126","366.72000","30.56010","0.11106"
"61190","367.10400","30.59215","0.11215"
"61254","367.48800","30.62414","0.11284"
"61318","367.87200","30.65606","0.11314"
"61382","368.25600","30.68811","0.11194"
"61446","368.64000","30.72016","0.11091"
"61510","369.02400","30.75209","0.11156"
"61574","369.40800","30.78408","0.11158"
"61638","369.79200","30.81618","0.11232"
"61702","370.17600","30.84811","0.11349"
"61766","370.56000","30.88010","0.11449"
"61830","370.94400","30.91215","0.11533"
"61894","371.32800","30.94413","0.11577"
"61958","371.71200","30.97612","0.11597"
"62022","372.09600","31.00817","0.11663"
"62086","372.48000","31.04015","0.11842"
"62150","372.86400","31.07214","0.11923"
"62214","373.24800","31.10413","0.12032"
"62278","373.63200","31.13618","0.12141"
"62342","374.01600","31.16817","0.12313"
"62406","374.40000","31.20015","0.12352"
"62470","374.78400","31.23214","0.12420"
"62534","375.16800","31.26413","0.12509"
"62598","375.55200","31.29617","0.12502"
"62662","375.93600","31.32810","0.12653"
"62726","376.32000","31.36015","0.12761"
"62790","376.70400","31.39214","0.12877"
"62854","377.08800","31.42412","0.12948"
"62918","377.47200","31.45611","0.12988"
"62982","377.85600","31.48816","0.13139"
"63046","378.24000","31.52014","0.13266"
"63110","378.62400","31.55207","0.13232"
"63174","379.00800","31.58412","0.13215"
"63238","379.39200","31.61617","0.13325"
"63302","379.77600","31.64810","0.13431"
"63366","380.16000","31.68014","0.13558"
"63430","380.54400","31.71213","0.13755"
"63494","380.92800","31.74412","0.10822"
"63558","381.31200","31.77604","0.10808"
"63622","381.69600","31.80821","0.10877"
"63686","382.08000","31.84014","0.11022"
"63750","382.46400","31.87200","0.11171"
"63814","382.84800","31.90417","0.11276"
"63878","383.23200","31.93610","0.11289"
"63942","383.61600","31.96809","0.11433"
"64006","384.00000","32.00008","0.11621"
"64070","384.38400","32.03218","0.11717"
"64134","384.76800","32.06417","0.11758"
"64198","385.15200","32.09610","0.11831"
"64262","385.53600","32.12809","0.11887"
"64326","385.92000","32.16013","0.12079"
"64390","386.30400","32.19212","0.12035"
"64454","386.68800","32.22411","0.12041"
"64518","387.07200","32.25615","0.11262"
"64582","387.45600","32.28820","0.11212"
"64646","387.84000","32.32007","0.11178"
"64710","388.22400","32.35205","0.11110"
"64774","388.60800","32.38416","0.10768"
"64838","388.99200","32.41609","0.10677"
"64902","389.37600","32.44808","0.10660"
"64966","389.76000","32.48013","0.10646"
"65030","390.14400","32.51217","0.10627"
"65094","390.52800","32.54404","0.10694"
"65158","390.91200","32.57615","0.10743"
"65222","391.29600","32.60820","0.10776"
"65286","391.68000","32.64012","0.10878"
"65350","392.06400","32.67211","0.10969"
"65414","392.44800","32.70415","0.11038"
"65478","392.83200","32.73615","0.10913"
"65542","393.21600","32.76813","0.10793"
"65606","393.60000","32.80018","0.10823"
"65670","393.98400","32.83210","0.10889"
"65734","394.36800","32.86409","0.10858"
"65798","394.75200","32.89614","0.10978"
"65862","395.13600","32.92813","0.11016"
"65926","395.52000","32.96017","0.11033"
"65990","395.90400","32.99210","0.11149"
"66054","396.28800","33.02409","0.11247"
"66118","396.67200","33.05614","0.11316"
"66182","397.05600","33.08813","0.11412"
"66246","397.44000","33.12011","0.11482"
"66310","397.82400","33.15210","0.11530"
"66374","398.20800","33.18421","0.11642"
"66438","398.59200","33.21608","0.11760"
"66502","398.97600","33.24812","0.11836"
"66566","399.36000","33.28011","0.11931"
"66630","399.74400","33.31210","0.11980"
"66694","400.12800","33.34408","0.11946"
"66758","400.51200","33.37613","0.12046"
"66822","400.89600","33.40812","0.12201"
"66886","401.28000","33.44011","0.12307"
"66950","401.66400","33.47215","0.12482"
"67014","402.04800","33.50414","0.12551"
"67078","402.43200","33.53613","0.12648"
"67142","402.81600","33.56812","0.12808"
"67206","403.20000","33.60016","0.12991"
"67270","403.58400","33.63215","0.13066"
"67334","403.96800","33.66414","0.13097"
"67398","404.35200","33.69613","0.13231"
"67462","404.73600","33.72811","0.13358"
"67526","405.12000","33.76010","0.13435"
"67590","405.50400","33.79209","0.13548"
"67654","405.88800","33.82413","0.13223"
"67718","406.27200","33.85612","0.13381"
"67782","406.65600","33.88811","0.13555"
"67846","407.04000","33.92016","0.13684"
"67910","407.42400","33.95208","0.13811"
"67974","407.80800","33.98413","0.13994"
"68038","408.19200","34.01606","0.12719"
"68102","408.57600","34.04816","0.12996"
"68166","408.96000","34.08015","0.13066"
"68230","409.34400","34.11202","0.13226"
"68294","409.72800","34.14413","0.13292"
"68358","410.11200","34.17617","0.13336"
"68422","410.49600","34.20810","0.13490"
"68486","410.88000","34.24009","0.13622"
"68550","411.26400","34.27214","0.13847"
"68614","411.64800","34.30418","0.14113"
"68678","412.03200","34.33605","0.14347"
"68742","412.41600","34.36810","0.14656"
"68806","412.80000","34.40015","0.14952"
"68870","413.18400","34.43214","0.15138"
"68934","413.56800","34.46412","0.15379"
"68998","413.95200","34.49617","0.15687"
"69062","414.33600","34.52816","0.15911"
"69126","414.72000","34.56009","0.16140"
"69190","415.10400","34.59213","0.16240"
"69254","415.48800","34.62412","0.16387"
"69318","415.87200","34.65611","0.16582"
"69382","416.25600","34.68809","0.16761"
"69446","416.64000","34.72020","0.16852"
"69510","417.02400","34.75219","0.16920"
"69574","417.40800","34.78406","0.17115"
"69638","417.79200","34.81610","0.17155"
"69702","418.17600","34.84815","0.17081"
"69766","418.56000","34.88014","0.16936"
"69830","418.94400","34.91206","0.17282"
"69894","419.32800","34.94417","0.17657"
"69958","419.71200","34.97616","0.17328"
"70022","420.09600","35.00809","0.16995"
"70086","420.48000","35.04013","0.13230"
"70150","420.86400","35.07218","0.13295"
"70214","421.24800","35.10411","0.13400"
"70278","421.63200","35.13610","0.13497"
"70342","422.01600","35.16814","0.13624"
"70406","422.40000","35.20007","0.13754"
"70470","422.78400","35.23212","0.14131"
"70534","423.16800","35.26416","0.14621"
"70598","423.55200","35.29615","0.14914"
"70662","423.93600","35.32814","0.15084"
"70726","424.32000","35.36013","0.15440"
"70790","424.70400","35.39218","0.15953"
"70854","425.08800","35.42410","0.16083"
"70918","425.47200","35.45609","0.16203"
"70982","425.85600","35.48814","0.16328"
"71046","426.24000","35.52013","0.16543"
"71110","426.62400","35.55211","0.16599"
"71174","427.00800","35.58410","0.16630"
"71238","427.39200","35.61615","0.16861"
"71302","427.77600","35.64813","0.17123"
"71366","428.16000","35.68006","0.17350"
"71430","428.54400","35.71211","0.17652"
"71494","428.92800","35.74416","0.17869"
"71558","429.31200","35.77614","0.18146"
"71622","429.69600","35.80807","0.18408"
"71686","430.08000","35.84018","0.18651"
"71750","430.46400","35.87217","0.18616"
"71814","430.84800","35.90409","0.18650"
"71878","431.23200","35.93614","0.18967"
"71942","431.61600","35.96819","0.19146"
"72006","432.00000","36.00005","0.18846"
"72070","432.38400","36.03210","0.18959"
"72134","432.76800","36.06415","0.18935"
"72198","433.15200","36.09614","0.19065"
"72262","433.53600","36.12806","0.19301"
"72326","433.92000","36.16017","0.19492"
"72390","434.30400","36.19216","0.19661"
"72454","434.68800","36.22409","0.19818"
"72518","435.07200","36.25613","0.19999"
"72582","435.45600","36.28818","0.20261"
"72646","435.84000","36.32011","0.20320"
"72710","436.22400","36.35209","0.20509"
"72774","436.60800","36.38408","0.20797"
"72838","436.99200","36.41613","0.20890"
"72902","437.37600","36.44812","0.21080"
"72966","437.76000","36.48011","0.21357"
"73030","438.14400","36.51215","0.21578"
"73094","438.52800","36.54420","0.21761"
"73158","438.91200","36.57607","0.22005"
"73222","439.29600","36.60812","0.22218"
"73286","439.68000","36.64016","0.22259"
"73350","440.06400","36.67209","0.22254"
"73414","440.44800","36.70414","0.22323"
"73478","440.83200","36.73612","0.22413"
"73542","441.21600","36.76811","0.22635"
"73606","441.60000","36.80010","0.22795"
"73670","441.98400","36.83221","0.23016"
"73734","442.36800","36.86413","0.09835"
"73798","442.75200","36.89606","0.10117"
"73862","443.13600","36.92811","0.10835"
"73926","443.52000","36.96016","0.10888"
"73990","443.90400","36.99208","0.11148"
"74054","444.28800","37.02407","0.11148"
"74118","444.67200","37.05612","0.11252"
"74182","445.05600","37.08810","0.11168"
"74246","445.44000","37.12009","0.11187"
"74310","445.82400","37.15214","0.11319"
"74374","446.20800","37.18413","0.11403"
"74438","446.59200","37.21618","0.11633"
"74502","446.97600","37.24810","0.11858"
"74566","447.36000","37.28015","0.12166"
"74630","447.74400","37.31219","0.12374"
"74694","448.12800","37.34412","0.12419"
"74758","448.51200","37.37611","0.12504"
"74822","448.89600","37.40816","0.12592"
"74886","449.28000","37.44015","0.12722"
"74950","449.66400","37.47207","0.12918"
"75014","450.04800","37.50406","0.13088"
"75078","450.43200","37.53617","0.13190"
"75142","450.81600","37.56810","0.13310"
"75206","451.20000","37.60008","0.13366"
"75270","451.58400","37.63219","0.13450"
"75334","451.96800","37.66412","0.13519"
"75398","452.35200","37.69611","0.13715"
"75462","452.73600","37.72815","0.13885"
"75526","453.12000","37.76014","0.14000"
"75590","453.50400","37.79207","0.14171"
"75654","453.88800","37.82411","0.14319"
"75718","454.27200","37.85610","0.14461"
"75782","454.65600","37.88815","0.14625"
"75846","455.04000","37.92008","0.14940"
"75910","455.42400","37.95213","0.15080"
"75974","455.80800","37.98411","0.15323"
"76038","456.19200","38.01610","0.15484"
"76102","456.57600","38.04815","0.15720"
"76166","456.96000","38.08014","0.15849"
"76230","457.34400","38.11212","0.16028"
"76294","457.72800","38.14411","0.16202"
"76358","458.11200","38.17610","0.16332"
"76422","458.49600","38.20820","0.16364"
"76486","458.88000","38.24013","0.16446"
"76550","459.26400","38.27212","0.16565"
"76614","459.64800","38.30416","0.16625"
"76678","460.03200","38.33615","0.16744"
"76742","460.41600","38.36808","0.16883"
"76806","460.80000","38.40019","0.16833"
"76870","461.18400","38.43217","0.16844"
"76934","461.56800","38.46410","0.16911"
"76998","461.95200","38.49609","0.16997"
"77062","462.33600","38.52814","0.06165"
"77126","462.72000","38.56012","0.01320"
"77190","463.10400","38.59205","0.01290"
"77254","463.48800","38.62416","0.01382"
"77318","463.87200","38.65615","0.01264"
"77382","464.25600","38.68813","0.01462"
"77446","464.64000","38.72018","0.01300"
"77510","465.02400","38.75211","0.01345"
"77574","465.40800","38.78415","0.01370"
"77638","465.79200","38.81608","0.01307"
"77702","466.17600","38.84813","0.01309"
"77766","466.56000","38.88018","0.01322"
"77830","466.94400","38.91211","0.01325"
"77894","467.32800","38.94409","0.01454"
"77958","467.71200","38.97614","0.01371"
"78022","468.09600","39.00813","0.01410"
"78086","468.48000","39.04012","0.01318"
"78150","468.86400","39.07215","0.01379"
"78214","469.24800","39.10415","0.01471"
"78278","469.63200","39.13607","0.01359"
"78342","470.01600","39.16812","0.01481"
"78406","470.40000","39.20017","0.01327"
"78470","470.78400","39.23210","0.01525"
"78511","471.02600","39.25231","0.01444"