File: Trajectories_together/161226_1Specimen_RawData_5.csv
"","V1","V2","V3"
"1","End date","12/26/2016",""
"2","Specimen label","22AG_78",""
"3","Maximum Load","0.26632","N"
"4","Time","Extension","Load"
"5","(s)","(mm)","(N)"
"6","0.00000","0.00000","-0.00080"
"44","0.22800","0.01620","0.00022"
"82","0.45600","0.03833","0.00052"
"120","0.68400","0.05710","0.00102"
"158","0.91200","0.07617","0.00118"
"196","1.14000","0.09518","0.00134"
"234","1.36800","0.11414","0.00104"
"272","1.59600","0.13315","0.00130"
"310","1.82400","0.15210","0.00174"
"348","2.05200","0.17118","0.00178"
"386","2.28000","0.19013","0.00214"
"424","2.50800","0.20914","0.00205"
"462","2.73600","0.22816","0.00213"
"500","2.96400","0.24711","0.00201"
"538","3.19200","0.26612","0.00298"
"576","3.42000","0.28514","0.00273"
"614","3.64800","0.30421","0.00281"
"652","3.87600","0.32310","0.00274"
"690","4.10400","0.34212","0.00235"
"728","4.33200","0.36113","0.00274"
"766","4.56000","0.38008","0.00297"
"804","4.78800","0.39915","0.00237"
"842","5.01600","0.41811","0.00263"
"880","5.24400","0.43712","0.00279"
"918","5.47200","0.45613","0.00354"
"956","5.70000","0.47509","0.00304"
"994","5.92800","0.49416","0.00315"
"1032","6.15600","0.51305","0.00288"
"1070","6.38400","0.53213","0.00369"
"1108","6.61200","0.55114","0.00310"
"1146","6.84000","0.57015","0.00357"
"1184","7.06800","0.58917","0.00360"
"1222","7.29600","0.60806","0.00374"
"1260","7.52400","0.62719","0.00410"
"1298","7.75200","0.64609","0.00368"
"1336","7.98000","0.66522","0.00404"
"1374","8.20800","0.68411","0.00383"
"1412","8.43600","0.70307","0.00440"
"1450","8.66400","0.72214","0.00411"
"1488","8.89200","0.74109","0.00417"
"1526","9.12000","0.76016","0.00432"
"1564","9.34800","0.77906","0.00453"
"1602","9.57600","0.79819","0.00400"
"1640","9.80400","0.81714","0.00418"
"1678","10.03200","0.83616","0.00440"
"1716","10.26000","0.85511","0.00499"
"1754","10.48800","0.87406","0.00474"
"1792","10.71600","0.89314","0.00500"
"1830","10.94400","0.91215","0.00480"
"1868","11.17200","0.93110","0.00461"
"1906","11.40000","0.95018","0.00509"
"1944","11.62800","0.96907","0.00526"
"1982","11.85600","0.98814","0.00496"
"2020","12.08400","1.00709","0.00509"
"2058","12.31200","1.02611","0.00530"
"2096","12.54000","1.04512","0.00478"
"2134","12.76800","1.06407","0.00550"
"2172","12.99600","1.08321","0.00519"
"2210","13.22400","1.10204","0.00522"
"2248","13.45200","1.12117","0.00533"
"2286","13.68000","1.14013","0.00551"
"2324","13.90800","1.15914","0.00522"
"2362","14.13600","1.17809","0.00545"
"2400","14.36400","1.19717","0.00567"
"2438","14.59200","1.21612","0.00549"
"2476","14.82000","1.23507","0.00546"
"2514","15.04800","1.25415","0.00573"
"2552","15.27600","1.27316","0.00571"
"2590","15.50400","1.29211","0.00589"
"2628","15.73200","1.31112","0.00653"
"2666","15.96000","1.33014","0.00632"
"2704","16.18800","1.34915","0.00609"
"2742","16.41600","1.36810","0.00447"
"2780","16.64400","1.38712","0.00453"
"2818","16.87200","1.40607","0.00412"
"2856","17.10000","1.42514","0.00456"
"2894","17.32800","1.44410","0.00403"
"2932","17.55600","1.46311","0.00393"
"2970","17.78400","1.48218","0.00378"
"3008","18.01200","1.50108","0.00423"
"3046","18.24000","1.52015","0.00402"
"3084","18.46800","1.53910","0.00436"
"3122","18.69600","1.55817","0.00409"
"3160","18.92400","1.57713","0.00410"
"3198","19.15200","1.59614","0.00414"
"3236","19.38000","1.61515","0.00414"
"3274","19.60800","1.63411","0.00491"
"3312","19.83600","1.65318","0.00491"
"3350","20.06400","1.67213","0.00487"
"3388","20.29200","1.69115","0.00467"
"3426","20.52000","1.71010","0.00459"
"3464","20.74800","1.72911","0.00497"
"3502","20.97600","1.74813","0.00512"
"3540","21.20400","1.76708","0.00481"
"3578","21.43200","1.78615","0.00509"
"3616","21.66000","1.80517","0.00498"
"3654","21.88800","1.82412","0.00515"
"3692","22.11600","1.84319","0.00516"
"3730","22.34400","1.86209","0.00516"
"3768","22.57200","1.88122","0.00506"
"3806","22.80000","1.90011","0.00517"
"3844","23.02800","1.91918","0.00498"
"3882","23.25600","1.93814","0.00529"
"3920","23.48400","1.95709","0.00550"
"3958","23.71200","1.97616","0.00541"
"3996","23.94000","1.99506","0.00534"
"4034","24.16800","2.01419","0.00552"
"4072","24.39600","2.03308","0.00517"
"4110","24.62400","2.05216","0.00575"
"4148","24.85200","2.07117","0.00604"
"4186","25.08000","2.09012","0.00583"
"4224","25.30800","2.10914","0.00570"
"4262","25.53600","2.12809","0.00606"
"4300","25.76400","2.14716","0.00614"
"4338","25.99200","2.16612","0.00654"
"4376","26.22000","2.18507","0.00590"
"4414","26.44800","2.20414","0.00614"
"4452","26.67600","2.22309","0.00627"
"4490","26.90400","2.24217","0.00594"
"4528","27.13200","2.26106","0.00605"
"4566","27.36000","2.28013","0.00660"
"4604","27.58800","2.29909","0.00648"
"4642","27.81600","2.31816","0.00626"
"4680","28.04400","2.33717","0.00641"
"4718","28.27200","2.35607","0.00635"
"4756","28.50000","2.37514","0.00647"
"4794","28.72800","2.39409","0.00653"
"4832","28.95600","2.41317","0.00640"
"4870","29.18400","2.43212","0.00650"
"4908","29.41200","2.45113","0.00656"
"4946","29.64000","2.47014","0.00609"
"4984","29.86800","2.48904","0.00696"
"5022","30.09600","2.50817","0.00708"
"5060","30.32400","2.52712","0.00673"
"5098","30.55200","2.54614","0.00745"
"5136","30.78000","2.56515","0.00693"
"5174","31.00800","2.58410","0.00691"
"5212","31.23600","2.60318","0.00675"
"5250","31.46400","2.62207","0.00660"
"5288","31.69200","2.64108","0.00695"
"5326","31.92000","2.66010","0.00707"
"5364","32.14800","2.67911","0.00756"
"5402","32.37600","2.69812","0.00732"
"5440","32.60400","2.71714","0.00713"
"5478","32.83200","2.73615","0.00770"
"5516","33.06000","2.75510","0.00757"
"5554","33.28800","2.77417","0.00787"
"5592","33.51600","2.79313","0.00803"
"5630","33.74400","2.81208","0.00758"
"5668","33.97200","2.83109","0.00775"
"5706","34.20000","2.85011","0.00738"
"5744","34.42800","2.86918","0.00789"
"5782","34.65600","2.88813","0.00752"
"5820","34.88400","2.90715","0.00788"
"5858","35.11200","2.92610","0.00811"
"5896","35.34000","2.94517","0.00791"
"5934","35.56800","2.96419","0.00762"
"5972","35.79600","2.98314","0.00799"
"6010","36.02400","3.00209","0.00776"
"6048","36.25200","3.02105","0.00815"
"6086","36.48000","3.04018","0.00825"
"6124","36.70800","3.05907","0.00822"
"6162","36.93600","3.07814","0.00796"
"6200","37.16400","3.09716","0.00844"
"6238","37.39200","3.11605","0.00809"
"6276","37.62000","3.13518","0.00872"
"6314","37.84800","3.15414","0.00899"
"6352","38.07600","3.17315","0.00838"
"6390","38.30400","3.19210","0.00856"
"6428","38.53200","3.21112","0.00877"
"6466","38.76000","3.23013","0.00899"
"6504","38.98800","3.24914","0.00839"
"6542","39.21600","3.26816","0.00886"
"6580","39.44400","3.28711","0.00871"
"6618","39.67200","3.30618","0.00910"
"6656","39.90000","3.32513","0.00841"
"6694","40.12800","3.34415","0.00917"
"6732","40.35600","3.36316","0.00919"
"6770","40.58400","3.38205","0.00923"
"6808","40.81200","3.40119","0.00943"
"6846","41.04000","3.42014","0.00967"
"6884","41.26800","3.43915","0.00967"
"6922","41.49600","3.45811","0.00910"
"6960","41.72400","3.47712","0.00957"
"6998","41.95200","3.49619","0.00975"
"7036","42.18000","3.51509","0.00959"
"7074","42.40800","3.53416","0.00954"
"7112","42.63600","3.55311","0.00976"
"7150","42.86400","3.57213","0.00996"
"7188","43.09200","3.59114","0.00969"
"7226","43.32000","3.61009","0.00960"
"7264","43.54800","3.62916","0.00995"
"7302","43.77600","3.64806","0.00972"
"7340","44.00400","3.66713","0.00978"
"7378","44.23200","3.68614","0.01016"
"7416","44.46000","3.70510","0.00951"
"7454","44.68800","3.72417","0.00978"
"7492","44.91600","3.74306","0.00981"
"7530","45.14400","3.76214","0.00980"
"7568","45.37200","3.78109","0.01051"
"7606","45.60000","3.80016","0.00996"
"7644","45.82800","3.81918","0.01000"
"7682","46.05600","3.83807","0.01037"
"7720","46.28400","3.85714","0.01042"
"7758","46.51200","3.87610","0.01045"
"7796","46.74000","3.89511","0.01093"
"7834","46.96800","3.91412","0.01082"
"7872","47.19600","3.93314","0.01070"
"7910","47.42400","3.95221","0.01080"
"7948","47.65200","3.97104","0.01063"
"7986","47.88000","3.99017","0.01088"
"8024","48.10800","4.00913","0.01068"
"8062","48.33600","4.02814","0.01121"
"8100","48.56400","4.04715","0.01090"
"8138","48.79200","4.06611","0.01123"
"8176","49.02000","4.08512","0.01100"
"8214","49.24800","4.10407","0.01081"
"8252","49.47600","4.12315","0.01121"
"8290","49.70400","4.14210","0.01124"
"8328","49.93200","4.16117","0.01110"
"8366","50.16000","4.18013","0.01184"
"8404","50.38800","4.19914","0.01129"
"8442","50.61600","4.21815","0.01130"
"8480","50.84400","4.23710","0.01128"
"8518","51.07200","4.25612","0.01146"
"8556","51.30000","4.27513","0.01118"
"8594","51.52800","4.29408","0.01132"
"8632","51.75600","4.31316","0.01152"
"8670","51.98400","4.33211","0.01204"
"8708","52.21200","4.35112","0.01165"
"8746","52.44000","4.37014","0.01189"
"8784","52.66800","4.38909","0.01187"
"8822","52.89600","4.40810","0.01227"
"8860","53.12400","4.42712","0.01178"
"8898","53.35200","4.44613","0.01191"
"8936","53.58000","4.46514","0.01191"
"8974","53.80800","4.48421","0.01215"
"9012","54.03600","4.50311","0.01206"
"9050","54.26400","4.52212","0.01247"
"9088","54.49200","4.54113","0.01195"
"9126","54.72000","4.56015","0.01194"
"9164","54.94800","4.57910","0.01200"
"9202","55.17600","4.59811","0.01231"
"9240","55.40400","4.61713","0.01238"
"9278","55.63200","4.63608","0.01247"
"9316","55.86000","4.65515","0.01229"
"9354","56.08800","4.67411","0.01290"
"9392","56.31600","4.69318","0.01243"
"9430","56.54400","4.71213","0.01264"
"9468","56.77200","4.73109","0.01285"
"9506","57.00000","4.75010","0.01271"
"9544","57.22800","4.76905","0.01272"
"9582","57.45600","4.78813","0.01289"
"9620","57.68400","4.80714","0.01295"
"9658","57.91200","4.82609","0.01235"
"9696","58.14000","4.84516","0.01302"
"9734","58.36800","4.86412","0.01308"
"9772","58.59600","4.88319","0.01289"
"9810","58.82400","4.90214","0.01298"
"9848","59.05200","4.92116","0.01336"
"9886","59.28000","4.94011","0.01314"
"9924","59.50800","4.95906","0.01317"
"9962","59.73600","4.97814","0.01318"
"10000","59.96400","4.99709","0.01320"
"10038","60.19200","5.01616","0.01247"
"10076","60.42000","5.03512","0.01284"
"10114","60.64800","5.05413","0.01280"
"10152","60.87600","5.07320","0.01245"
"10190","61.10400","5.09209","0.01253"
"10228","61.33200","5.11117","0.01274"
"10266","61.56000","5.13012","0.01265"
"10304","61.78800","5.14919","0.01266"
"10342","62.01600","5.16809","0.01264"
"10380","62.24400","5.18710","0.01279"
"10418","62.47200","5.20617","0.01331"
"10456","62.70000","5.22501","0.01287"
"10494","62.92800","5.24414","0.01297"
"10532","63.15600","5.26315","0.01276"
"10570","63.38400","5.28217","0.01298"
"10608","63.61200","5.30112","0.01299"
"10646","63.84000","5.32007","0.01310"
"10684","64.06800","5.33915","0.01347"
"10722","64.29600","5.35804","0.01337"
"10760","64.52400","5.37711","0.01353"
"10798","64.75200","5.39612","0.01368"
"10836","64.98000","5.41514","0.01359"
"10874","65.20800","5.43415","0.01356"
"10912","65.43600","5.45310","0.01335"
"10950","65.66400","5.47212","0.01369"
"10988","65.89200","5.49107","0.01375"
"11026","66.12000","5.51014","0.01294"
"11064","66.34800","5.52916","0.01314"
"11102","66.57600","5.54817","0.01297"
"11140","66.80400","5.56718","0.01275"
"11178","67.03200","5.58614","0.01350"
"11216","67.26000","5.60515","0.01305"
"11254","67.48800","5.62410","0.01311"
"11292","67.71600","5.64312","0.01317"
"11330","67.94400","5.66219","0.01350"
"11368","68.17200","5.68108","0.01284"
"11406","68.40000","5.70010","0.01292"
"11444","68.62800","5.71911","0.01303"
"11482","68.85600","5.73812","0.01312"
"11520","69.08400","5.75713","0.01322"
"11558","69.31200","5.77615","0.01346"
"11596","69.54000","5.79516","0.01315"
"11634","69.76800","5.81411","0.01325"
"11672","69.99600","5.83313","0.01342"
"11710","70.22400","5.85214","0.01355"
"11748","70.45200","5.87109","0.01366"
"11786","70.68000","5.89011","0.01348"
"11824","70.90800","5.90918","0.01358"
"11862","71.13600","5.92819","0.01351"
"11900","71.36400","5.94715","0.01385"
"11938","71.59200","5.96616","0.01399"
"11976","71.82000","5.98505","0.01391"
"12014","72.04800","6.00412","0.01415"
"12052","72.27600","6.02314","0.01397"
"12090","72.50400","6.04215","0.01419"
"12128","72.73200","6.06110","0.01433"
"12166","72.96000","6.08012","0.01454"
"12204","73.18800","6.09919","0.01442"
"12242","73.41600","6.11808","0.01430"
"12280","73.64400","6.13716","0.01443"
"12318","73.87200","6.15611","0.01461"
"12356","74.10000","6.17512","0.01430"
"12394","74.32800","6.19414","0.01463"
"12432","74.55600","6.21309","0.01463"
"12470","74.78400","6.23210","0.01491"
"12508","75.01200","6.25106","0.01496"
"12546","75.24000","6.27019","0.01509"
"12584","75.46800","6.28908","0.01516"
"12622","75.69600","6.30815","0.01476"
"12660","75.92400","6.32711","0.01478"
"12698","76.15200","6.34612","0.01496"
"12736","76.38000","6.36519","0.01508"
"12774","76.60800","6.38415","0.01499"
"12812","76.83600","6.40316","0.01520"
"12850","77.06400","6.42211","0.01534"
"12888","77.29200","6.44107","0.01552"
"12926","77.52000","6.46014","0.01540"
"12964","77.74800","6.47909","0.01580"
"13002","77.97600","6.49817","0.01538"
"13040","78.20400","6.51706","0.01564"
"13078","78.43200","6.53613","0.01546"
"13116","78.66000","6.55514","0.01560"
"13154","78.88800","6.57416","0.01596"
"13192","79.11600","6.59317","0.01640"
"13230","79.34400","6.61206","0.01580"
"13268","79.57200","6.63120","0.01555"
"13306","79.80000","6.65009","0.01615"
"13344","80.02800","6.66916","0.01643"
"13382","80.25600","6.68818","0.01617"
"13420","80.48400","6.70701","0.01613"
"13458","80.71200","6.72620","0.01645"
"13496","80.94000","6.74510","0.01646"
"13534","81.16800","6.76411","0.01662"
"13572","81.39600","6.78312","0.01669"
"13610","81.62400","6.80214","0.01695"
"13648","81.85200","6.82121","0.01691"
"13686","82.08000","6.84004","0.01675"
"13724","82.30800","6.85917","0.01720"
"13762","82.53600","6.87807","0.01681"
"13800","82.76400","6.89714","0.01691"
"13838","82.99200","6.91615","0.01702"
"13876","83.22000","6.93505","0.01732"
"13914","83.44800","6.95418","0.01702"
"13952","83.67600","6.97307","0.01712"
"13990","83.90400","6.99215","0.01744"
"14028","84.13200","7.01116","0.01755"
"14066","84.36000","7.03011","0.01772"
"14104","84.58800","7.04919","0.01765"
"14142","84.81600","7.06808","0.01771"
"14180","85.04400","7.08715","0.01781"
"14218","85.27200","7.10611","0.01786"
"14256","85.50000","7.12512","0.01785"
"14294","85.72800","7.14413","0.01792"
"14332","85.95600","7.16314","0.01820"
"14370","86.18400","7.18210","0.01820"
"14408","86.41200","7.20111","0.01841"
"14446","86.64000","7.22018","0.01820"
"14484","86.86800","7.23908","0.01835"
"14522","87.09600","7.25815","0.01848"
"14560","87.32400","7.27710","0.01831"
"14598","87.55200","7.29612","0.01747"
"14636","87.78000","7.31507","0.01740"
"14674","88.00800","7.33408","0.01800"
"14712","88.23600","7.35310","0.01783"
"14750","88.46400","7.37211","0.01788"
"14788","88.69200","7.39118","0.01806"
"14826","88.92000","7.41014","0.01830"
"14864","89.14800","7.42909","0.01829"
"14902","89.37600","7.44816","0.01799"
"14940","89.60400","7.46717","0.01821"
"14978","89.83200","7.48613","0.01823"
"15016","90.06000","7.50508","0.01879"
"15054","90.28800","7.52415","0.01877"
"15092","90.51600","7.54317","0.01898"
"15130","90.74400","7.56212","0.01918"
"15168","90.97200","7.58113","0.01914"
"15206","91.20000","7.60015","0.01942"
"15244","91.42800","7.61910","0.01942"
"15282","91.65600","7.63811","0.01930"
"15320","91.88400","7.65719","0.01995"
"15358","92.11200","7.67614","0.01992"
"15396","92.34000","7.69515","0.01957"
"15434","92.56800","7.71411","0.02011"
"15472","92.79600","7.73312","0.01993"
"15510","93.02400","7.75219","0.02035"
"15548","93.25200","7.77109","0.02041"
"15586","93.48000","7.79016","0.02053"
"15624","93.70800","7.80911","0.02019"
"15662","93.93600","7.82812","0.02045"
"15700","94.16400","7.84714","0.02122"
"15738","94.39200","7.86609","0.02053"
"15776","94.62000","7.88516","0.02147"
"15814","94.84800","7.90406","0.02123"
"15852","95.07600","7.92313","0.02163"
"15890","95.30400","7.94214","0.02194"
"15928","95.53200","7.96110","0.02127"
"15966","95.76000","7.98017","0.02197"
"16004","95.98800","7.99906","0.02168"
"16042","96.21600","8.01820","0.02183"
"16080","96.44400","8.03709","0.02203"
"16118","96.67200","8.05610","0.02112"
"16156","96.90000","8.07517","0.02116"
"16194","97.12800","8.09407","0.02161"
"16232","97.35600","8.11320","0.02140"
"16270","97.58400","8.13209","0.02188"
"16308","97.81200","8.15117","0.02200"
"16346","98.04000","8.17012","0.02211"
"16384","98.26800","8.18913","0.02233"
"16422","98.49600","8.20821","0.02276"
"16460","98.72400","8.22704","0.02263"
"16498","98.95200","8.24617","0.02249"
"16536","99.18000","8.26507","0.02303"
"16574","99.40800","8.28414","0.02285"
"16612","99.63600","8.30315","0.02359"
"16650","99.86400","8.32210","0.02325"
"16688","100.09200","8.34118","0.02319"
"16726","100.32000","8.36007","0.02349"
"16764","100.54800","8.37908","0.02355"
"16802","100.77600","8.39810","0.02398"
"16840","101.00400","8.41711","0.02399"
"16878","101.23200","8.43618","0.02441"
"16916","101.46000","8.45508","0.02479"
"16954","101.68800","8.47415","0.02461"
"16992","101.91600","8.49310","0.02496"
"17030","102.14400","8.51218","0.02496"
"17068","102.37200","8.53119","0.02539"
"17106","102.60000","8.55014","0.02597"
"17144","102.82800","8.56910","0.02557"
"17182","103.05600","8.58805","0.02562"
"17220","103.28400","8.60712","0.02633"
"17258","103.51200","8.62608","0.02627"
"17296","103.74000","8.64515","0.02619"
"17334","103.96800","8.66416","0.02679"
"17372","104.19600","8.68311","0.02688"
"17410","104.42400","8.70219","0.02693"
"17448","104.65200","8.72114","0.02740"
"17486","104.88000","8.74015","0.02761"
"17524","105.10800","8.75911","0.02738"
"17562","105.33600","8.77812","0.02785"
"17600","105.56400","8.79713","0.02779"
"17638","105.79200","8.81609","0.02778"
"17676","106.02000","8.83516","0.02849"
"17714","106.24800","8.85405","0.02875"
"17752","106.47600","8.87313","0.02853"
"17790","106.70400","8.89208","0.02910"
"17828","106.93200","8.91109","0.02904"
"17866","107.16000","8.93016","0.02934"
"17904","107.38800","8.94912","0.02953"
"17942","107.61600","8.96819","0.02974"
"17980","107.84400","8.98714","0.03000"
"18018","108.07200","9.00610","0.03033"
"18056","108.30000","9.02511","0.03077"
"18094","108.52800","9.04412","0.03060"
"18132","108.75600","9.06314","0.03104"
"18170","108.98400","9.08215","0.03160"
"18208","109.21200","9.10110","0.03161"
"18246","109.44000","9.12012","0.03191"
"18284","109.66800","9.13919","0.03201"
"18322","109.89600","9.15814","0.03264"
"18360","110.12400","9.17715","0.03267"
"18398","110.35200","9.19611","0.03280"
"18436","110.58000","9.21512","0.03241"
"18474","110.80800","9.23413","0.03371"
"18512","111.03600","9.25315","0.03377"
"18550","111.26400","9.27216","0.03393"
"18588","111.49200","9.29111","0.03420"
"18626","111.72000","9.31013","0.03480"
"18664","111.94800","9.32914","0.03509"
"18702","112.17600","9.34809","0.03517"
"18740","112.40400","9.36717","0.03565"
"18778","112.63200","9.38612","0.03634"
"18816","112.86000","9.40519","0.03699"
"18854","113.08800","9.42415","0.03654"
"18892","113.31600","9.44316","0.03757"
"18930","113.54400","9.46211","0.03819"
"18968","113.77200","9.48107","0.03840"
"19006","114.00000","9.50020","0.03865"
"19044","114.22800","9.51909","0.03963"
"19082","114.45600","9.53816","0.03924"
"19120","114.68400","9.55718","0.04054"
"19158","114.91200","9.57607","0.04100"
"19196","115.14000","9.59514","0.04179"
"19234","115.36800","9.61410","0.04163"
"19272","115.59600","9.63317","0.04176"
"19310","115.82400","9.65206","0.04212"
"19348","116.05200","9.67108","0.04408"
"19386","116.28000","9.69015","0.04458"
"19424","116.50800","9.70904","0.04456"
"19462","116.73600","9.72818","0.04493"
"19500","116.96400","9.74713","0.04538"
"19538","117.19200","9.76614","0.04650"
"19576","117.42000","9.78516","0.04645"
"19614","117.64800","9.80411","0.04735"
"19652","117.87600","9.82318","0.04727"
"19690","118.10400","9.84207","0.04833"
"19728","118.33200","9.86115","0.04840"
"19766","118.56000","9.88010","0.04938"
"19804","118.78800","9.89917","0.04949"
"19842","119.01600","9.91813","0.04988"
"19880","119.24400","9.93708","0.05018"
"19918","119.47200","9.95615","0.05123"
"19956","119.70000","9.97511","0.05181"
"19994","119.92800","9.99418","0.05143"
"20032","120.15600","10.01313","0.05194"
"20070","120.38400","10.03209","0.05226"
"20108","120.61200","10.05116","0.05218"
"20146","120.84000","10.07011","0.05264"
"20184","121.06800","10.08913","0.05291"
"20222","121.29600","10.10808","0.05360"
"20260","121.52400","10.12715","0.05363"
"20298","121.75200","10.14616","0.05403"
"20336","121.98000","10.16512","0.05490"
"20374","122.20800","10.18413","0.05488"
"20412","122.43600","10.20308","0.05529"
"20450","122.66400","10.22216","0.05584"
"20488","122.89200","10.24105","0.05665"
"20526","123.12000","10.26018","0.05648"
"20564","123.34800","10.27914","0.05701"
"20602","123.57600","10.29809","0.05739"
"20640","123.80400","10.31716","0.05775"
"20678","124.03200","10.33612","0.05799"
"20716","124.26000","10.35513","0.05839"
"20754","124.48800","10.37408","0.05845"
"20792","124.71600","10.39310","0.05853"
"20830","124.94400","10.41217","0.05928"
"20868","125.17200","10.43112","0.05926"
"20906","125.40000","10.45013","0.05979"
"20944","125.62800","10.46915","0.06014"
"20982","125.85600","10.48810","0.06059"
"21020","126.08400","10.50711","0.06088"
"21058","126.31200","10.52613","0.06084"
"21096","126.54000","10.54514","0.06135"
"21134","126.76800","10.56409","0.06171"
"21172","126.99600","10.58317","0.06269"
"21210","127.22400","10.60212","0.06256"
"21248","127.45200","10.62113","0.06330"
"21286","127.68000","10.64015","0.06393"
"21324","127.90800","10.65910","0.06441"
"21362","128.13600","10.67817","0.06450"
"21400","128.36400","10.69712","0.06558"
"21438","128.59200","10.71614","0.06631"
"21476","128.82000","10.73509","0.06660"
"21514","129.04800","10.75416","0.06656"
"21552","129.27600","10.77306","0.06699"
"21590","129.50400","10.79213","0.06818"
"21628","129.73200","10.81114","0.06886"
"21666","129.96000","10.83010","0.06912"
"21704","130.18800","10.84917","0.06903"
"21742","130.41600","10.86812","0.07033"
"21780","130.64400","10.88720","0.07073"
"21818","130.87200","10.90609","0.07165"
"21856","131.10000","10.92516","0.07193"
"21894","131.33000","10.94435","0.07240"
"21932","131.55800","10.96325","0.07330"
"21970","131.78600","10.98232","0.07390"
"22008","132.01400","11.00127","0.07424"
"22046","132.24200","11.02035","0.07509"
"22084","132.47000","11.03924","0.07547"
"22122","132.69800","11.05831","0.07635"
"22160","132.92600","11.07738","0.07671"
"22198","133.15400","11.09622","0.07746"
"22236","133.38200","11.11535","0.07798"
"22274","133.61000","11.13425","0.07885"
"22312","133.83800","11.15326","0.07945"
"22350","134.06600","11.17227","0.08017"
"22388","134.29400","11.19129","0.08088"
"22426","134.52200","11.21036","0.08124"
"22464","134.75000","11.22925","0.08300"
"22502","134.97800","11.24826","0.08297"
"22540","135.20600","11.26728","0.08387"
"22578","135.43400","11.28629","0.08417"
"22616","135.66200","11.30530","0.08533"
"22654","135.89000","11.32426","0.08621"
"22692","136.11800","11.34333","0.08699"
"22730","136.34600","11.36228","0.08649"
"22768","136.57400","11.38136","0.08705"
"22806","136.80200","11.40031","0.08772"
"22844","137.03000","11.41926","0.08873"
"22882","137.25800","11.43834","0.08915"
"22920","137.48600","11.45723","0.09039"
"22958","137.71400","11.47630","0.09046"
"22996","137.94200","11.49525","0.09142"
"23034","138.17000","11.51433","0.09192"
"23072","138.39800","11.53334","0.09248"
"23110","138.62600","11.55229","0.09317"
"23148","138.85400","11.57131","0.09369"
"23186","139.08200","11.59026","0.09453"
"23224","139.31000","11.60933","0.09481"
"23262","139.53800","11.62829","0.09562"
"23300","139.76600","11.64730","0.09581"
"23338","139.99400","11.66631","0.09643"
"23376","140.22200","11.68527","0.09671"
"23414","140.45000","11.70434","0.09742"
"23452","140.67800","11.72329","0.09795"
"23490","140.90600","11.74231","0.09886"
"23528","141.13400","11.76132","0.09890"
"23566","141.36200","11.78027","0.09940"
"23604","141.59000","11.79928","0.09971"
"23642","141.81800","11.81830","0.10028"
"23680","142.04600","11.83731","0.10094"
"23718","142.27400","11.85626","0.10151"
"23756","142.50200","11.87534","0.10200"
"23794","142.73000","11.89429","0.10257"
"23832","142.95800","11.91330","0.10294"
"23870","143.18600","11.93238","0.10307"
"23908","143.41400","11.95127","0.10317"
"23946","143.64200","11.97028","0.10359"
"23984","143.87000","11.98924","0.10358"
"24022","144.09800","12.00831","0.10409"
"24060","144.32600","12.02732","0.10401"
"24098","144.55400","12.04634","0.10469"
"24136","144.78200","12.06529","0.10437"
"24174","145.01000","12.08430","0.10484"
"24212","145.23800","12.10331","0.10552"
"24250","145.46600","12.12227","0.10550"
"24288","145.69400","12.14134","0.10579"
"24326","145.92200","12.16023","0.10644"
"24364","146.15000","12.17931","0.10667"
"24402","146.37800","12.19826","0.10724"
"24440","146.60600","12.21727","0.10719"
"24478","146.83400","12.23629","0.10798"
"24516","147.06200","12.25524","0.10804"
"24554","147.29000","12.27431","0.10870"
"24592","147.51800","12.29333","0.10910"
"24630","147.74600","12.31228","0.10982"
"24668","147.97400","12.33129","0.10974"
"24706","148.20200","12.35025","0.11022"
"24744","148.43000","12.36938","0.11107"
"24782","148.65800","12.38827","0.11161"
"24820","148.88600","12.40734","0.11173"
"24858","149.11400","12.42630","0.11219"
"24896","149.34200","12.44519","0.11224"
"24934","149.57000","12.46432","0.11309"
"24972","149.79800","12.48328","0.11327"
"25010","150.02600","12.50235","0.11352"
"25048","150.25400","12.52124","0.11411"
"25086","150.48200","12.54026","0.11448"
"25124","150.71000","12.55933","0.11468"
"25162","150.93800","12.57828","0.11580"
"25200","151.16600","12.59730","0.11669"
"25238","151.39400","12.61625","0.11742"
"25276","151.62200","12.63526","0.11753"
"25314","151.85000","12.65428","0.11794"
"25352","152.07800","12.67329","0.11866"
"25390","152.30800","12.69248","0.11782"
"25428","152.53600","12.71143","0.11782"
"25466","152.76400","12.73051","0.11885"
"25504","152.99200","12.74946","0.12015"
"25542","153.22000","12.76847","0.12132"
"25580","153.44800","12.78749","0.11816"
"25618","153.67600","12.80644","0.11829"
"25656","153.90400","12.82551","0.11875"
"25694","154.13200","12.84441","0.11935"
"25732","154.36000","12.86348","0.12046"
"25770","154.58800","12.88243","0.12054"
"25808","154.81600","12.90150","0.12138"
"25846","155.04400","12.92046","0.12240"
"25884","155.27200","12.93941","0.12213"
"25922","155.50000","12.95848","0.12282"
"25960","155.72800","12.97744","0.12315"
"25998","155.95600","12.99651","0.12359"
"26036","156.18400","13.01546","0.11408"
"26074","156.41200","13.03448","0.11256"
"26112","156.64000","13.05349","0.11341"
"26150","156.86800","13.07238","0.11357"
"26188","157.09600","13.09146","0.11440"
"26226","157.32400","13.11047","0.11506"
"26264","157.55200","13.12948","0.11537"
"26302","157.78000","13.14850","0.11638"
"26340","158.00800","13.16745","0.11754"
"26378","158.23600","13.18652","0.11805"
"26416","158.46400","13.20541","0.11854"
"26454","158.69200","13.22449","0.11953"
"26492","158.92000","13.24338","0.12006"
"26530","159.14800","13.26239","0.12038"
"26568","159.37600","13.28147","0.12161"
"26606","159.60400","13.30042","0.12294"
"26644","159.83200","13.31949","0.12333"
"26682","160.06000","13.33845","0.12419"
"26720","160.28800","13.35746","0.12565"
"26758","160.51600","13.37647","0.12578"
"26796","160.74400","13.39543","0.12650"
"26834","160.97200","13.41444","0.12815"
"26872","161.20000","13.43345","0.12828"
"26910","161.42800","13.45247","0.12966"
"26948","161.65600","13.47142","0.13073"
"26986","161.88400","13.49049","0.13209"
"27024","162.11200","13.50950","0.13292"
"27062","162.34000","13.52846","0.13353"
"27100","162.56800","13.54747","0.13534"
"27138","162.79600","13.56643","0.13592"
"27176","163.02400","13.58550","0.13743"
"27214","163.25200","13.60445","0.13829"
"27252","163.48000","13.62352","0.13928"
"27290","163.70800","13.64248","0.13646"
"27328","163.93600","13.66143","0.13384"
"27366","164.16400","13.68050","0.13429"
"27404","164.39200","13.69940","0.13548"
"27442","164.62000","13.71847","0.13544"
"27480","164.84800","13.73742","0.13669"
"27518","165.07600","13.75650","0.13714"
"27556","165.30400","13.77545","0.13808"
"27594","165.53200","13.79446","0.13956"
"27632","165.76000","13.81347","0.14047"
"27670","165.98800","13.83243","0.14208"
"27708","166.21600","13.85150","0.14276"
"27746","166.44400","13.87051","0.14517"
"27784","166.67200","13.88947","0.14603"
"27822","166.90000","13.90842","0.14724"
"27860","167.12800","13.92743","0.14918"
"27898","167.35600","13.94645","0.14914"
"27936","167.58400","13.96540","0.15085"
"27974","167.81200","13.98447","0.15136"
"28012","168.04000","14.00343","0.15306"
"28050","168.26800","14.02250","0.15330"
"28088","168.49600","14.04145","0.15479"
"28126","168.72400","14.06040","0.15601"
"28164","168.95200","14.07954","0.15714"
"28202","169.18000","14.09843","0.15854"
"28240","169.40800","14.11750","0.15911"
"28278","169.63600","14.13646","0.15976"
"28316","169.86400","14.15547","0.16092"
"28354","170.09200","14.17448","0.16137"
"28392","170.32000","14.19344","0.16194"
"28430","170.54800","14.21245","0.16299"
"28468","170.77600","14.23140","0.16319"
"28506","171.00400","14.25048","0.16408"
"28544","171.23200","14.26949","0.16392"
"28582","171.46000","14.28844","0.16493"
"28620","171.68800","14.30740","0.16569"
"28658","171.91600","14.32641","0.16633"
"28696","172.14400","14.34548","0.16710"
"28734","172.37200","14.36444","0.16803"
"28772","172.60000","14.38345","0.16868"
"28810","172.82800","14.40246","0.16901"
"28848","173.05600","14.42147","0.17003"
"28886","173.28400","14.44055","0.17182"
"28924","173.51200","14.45938","0.17188"
"28962","173.74000","14.47845","0.17319"
"29000","173.96800","14.49747","0.17428"
"29038","174.19600","14.51648","0.17507"
"29076","174.42400","14.53549","0.17536"
"29114","174.65200","14.55445","0.17655"
"29152","174.88000","14.57352","0.17754"
"29190","175.10800","14.59241","0.17812"
"29228","175.33600","14.61149","0.17917"
"29266","175.56400","14.63044","0.17988"
"29304","175.79200","14.64945","0.18077"
"29342","176.02000","14.66853","0.18142"
"29380","176.24800","14.68742","0.18245"
"29418","176.47600","14.70649","0.18273"
"29456","176.70400","14.72544","0.18415"
"29494","176.93200","14.74446","0.18519"
"29532","177.16000","14.76347","0.18620"
"29570","177.38800","14.78242","0.18733"
"29608","177.61600","14.80150","0.18864"
"29646","177.84400","14.82045","0.18893"
"29684","178.07200","14.83946","0.19066"
"29722","178.30000","14.85842","0.19083"
"29760","178.52800","14.87749","0.19166"
"29798","178.75600","14.89644","0.19278"
"29836","178.98400","14.91546","0.19351"
"29874","179.21200","14.93453","0.19458"
"29912","179.44000","14.95342","0.19598"
"29950","179.66800","14.97250","0.19679"
"29988","179.89600","14.99145","0.19814"
"30026","180.12400","15.01046","0.19919"
"30064","180.35200","15.02941","0.19974"
"30102","180.58000","15.04843","0.20096"
"30140","180.80800","15.06750","0.20224"
"30178","181.03600","15.08645","0.20302"
"30216","181.26400","15.10547","0.20509"
"30254","181.49200","15.12442","0.20630"
"30292","181.72000","15.14355","0.20754"
"30330","181.94800","15.16251","0.20845"
"30368","182.17600","15.18146","0.20930"
"30406","182.40400","15.20047","0.21016"
"30444","182.63200","15.21943","0.21067"
"30482","182.86000","15.23850","0.21086"
"30520","183.08800","15.25745","0.21130"
"30558","183.31600","15.27647","0.21175"
"30596","183.54400","15.29548","0.21244"
"30634","183.77200","15.31437","0.21280"
"30672","184.00000","15.33350","0.21282"
"30710","184.22800","15.35240","0.21308"
"30748","184.45600","15.37147","0.21391"
"30786","184.68400","15.39042","0.21420"
"30824","184.91200","15.40938","0.21486"
"30862","185.14000","15.42851","0.21509"
"30900","185.36800","15.44740","0.21575"
"30938","185.59600","15.46654","0.21625"
"30976","185.82400","15.48543","0.21662"
"31014","186.05200","15.50444","0.21717"
"31052","186.28000","15.52346","0.21806"
"31090","186.50800","15.54241","0.21829"
"31128","186.73600","15.56148","0.21911"
"31166","186.96400","15.58044","0.21981"
"31204","187.19200","15.59945","0.22024"
"31242","187.42000","15.61846","0.22110"
"31280","187.64800","15.63747","0.22197"
"31318","187.87600","15.65649","0.22301"
"31356","188.10400","15.67544","0.22431"
"31394","188.33200","15.69451","0.22517"
"31432","188.56000","15.71341","0.22600"
"31470","188.78800","15.73254","0.22735"
"31508","189.01600","15.75143","0.22767"
"31546","189.24400","15.77051","0.22883"
"31584","189.47200","15.78952","0.22960"
"31622","189.70000","15.80841","0.23111"
"31660","189.92800","15.82748","0.23186"
"31698","190.15600","15.84638","0.23279"
"31736","190.38400","15.86551","0.23336"
"31774","190.61200","15.88446","0.23479"
"31812","190.84000","15.90348","0.23538"
"31850","191.06800","15.92249","0.23567"
"31888","191.29600","15.94138","0.23661"
"31926","191.52400","15.96046","0.23700"
"31964","191.75200","15.97947","0.23656"
"32002","191.98000","15.99848","0.23804"
"32040","192.20800","16.01750","0.23902"
"32078","192.43600","16.03645","0.24045"
"32116","192.66400","16.05546","0.24189"
"32154","192.89200","16.07442","0.24375"
"32192","193.12000","16.09349","0.24496"
"32230","193.34800","16.11238","0.24570"
"32268","193.57600","16.13145","0.24663"
"32306","193.80400","16.15047","0.24787"
"32344","194.03200","16.16942","0.24879"
"32382","194.26000","16.18850","0.24996"
"32420","194.48800","16.20745","0.25040"
"32458","194.71600","16.22652","0.25063"
"32496","194.94400","16.24547","0.25306"
"32534","195.17200","16.26449","0.25342"
"32572","195.40000","16.28350","0.25515"
"32610","195.62800","16.30245","0.25686"
"32648","195.85600","16.32146","0.25737"
"32686","196.08400","16.34042","0.25858"
"32724","196.31200","16.35949","0.25963"
"32762","196.54000","16.37851","0.26085"
"32800","196.76800","16.39752","0.26204"
"32838","196.99600","16.41647","0.25646"
"32876","197.22400","16.43549","0.13635"
"32914","197.45200","16.45438","0.11893"
"32952","197.68000","16.47339","0.11494"
"32990","197.90800","16.49246","0.11372"
"33028","198.13600","16.51142","0.11370"
"33066","198.36400","16.53049","0.11598"
"33104","198.59200","16.54950","0.11844"
"33142","198.82000","16.56840","0.11741"
"33180","199.04800","16.58741","0.12160"
"33218","199.27600","16.60642","0.11901"
"33256","199.50400","16.62556","0.12529"
"33294","199.73200","16.64445","0.12329"
"33332","199.96000","16.66340","0.12737"
"33370","200.18800","16.68248","0.12907"
"33408","200.41600","16.70143","0.13161"
"33446","200.64400","16.72050","0.13741"
"33484","200.87200","16.73945","0.13275"
"33522","201.10000","16.75853","0.13956"
"33560","201.32800","16.77742","0.14010"
"33598","201.55600","16.79643","0.14771"
"33636","201.78400","16.81551","0.14670"
"33674","202.01200","16.83440","0.14808"
"33712","202.24000","16.85347","0.15285"
"33750","202.46800","16.87243","0.15076"
"33788","202.69600","16.89144","0.15578"
"33826","202.92400","16.91045","0.15365"
"33864","203.15200","16.92941","0.15628"
"33902","203.38000","16.94848","0.15853"
"33940","203.60800","16.96749","0.15863"
"33978","203.83600","16.98650","0.16269"
"34016","204.06400","17.00546","0.16051"
"34054","204.29200","17.02441","0.16362"
"34092","204.52000","17.04348","0.16357"
"34130","204.74800","17.06238","0.16462"
"34168","204.97600","17.08151","0.16715"
"34206","205.20400","17.10040","0.16528"
"34244","205.43200","17.11948","0.04665"
"34282","205.66000","17.13849","0.05065"
"34320","205.88800","17.15744","0.04334"
"34358","206.11600","17.17646","0.04584"
"34396","206.34400","17.19541","0.04618"
"34434","206.57200","17.21448","0.04811"
"34472","206.80000","17.23343","0.04797"
"34510","207.02800","17.25245","0.04933"
"34548","207.25600","17.27146","0.04954"
"34586","207.48400","17.29047","0.05069"
"34624","207.71200","17.30949","0.05091"
"34662","207.94000","17.32844","0.05184"
"34700","208.16800","17.34752","0.05218"
"34738","208.39600","17.36647","0.05300"
"34776","208.62400","17.38548","0.05388"
"34814","208.85200","17.40449","0.05315"
"34852","209.08000","17.42339","0.05580"
"34890","209.30800","17.44252","0.05427"
"34928","209.53600","17.46147","0.05729"
"34966","209.76400","17.48049","0.05554"
"35004","209.99200","17.49950","0.05851"
"35042","210.22000","17.51839","0.05755"
"35080","210.44800","17.53747","0.05859"
"35118","210.67600","17.55636","0.05885"
"35156","210.90400","17.57543","0.05868"
"35194","211.13200","17.59445","0.06017"
"35232","211.36000","17.61352","0.05993"
"35270","211.58800","17.63247","0.06127"
"35308","211.81600","17.65149","0.06120"
"35346","212.04400","17.67056","0.06209"
"35384","212.27200","17.68945","0.06131"
"35422","212.50000","17.70840","0.06306"
"35460","212.72800","17.72748","0.06193"
"35498","212.95600","17.74649","0.06452"
"35536","213.18400","17.76550","0.06393"
"35574","213.41200","17.78446","0.06681"
"35612","213.64000","17.80347","0.06571"
"35650","213.86800","17.82248","0.06803"
"35688","214.09600","17.84144","0.06719"
"35726","214.32400","17.86045","0.06905"
"35764","214.55200","17.87946","0.07000"
"35802","214.78000","17.89841","0.07123"
"35840","215.00800","17.91743","0.07101"
"35878","215.23600","17.93650","0.07289"
"35916","215.46400","17.95539","0.07319"
"35954","215.69200","17.97447","0.07429"
"35992","215.92000","17.99342","0.07414"
"36030","216.14800","18.01249","0.07438"
"36068","216.37600","18.03151","0.07568"
"36106","216.60400","18.05046","0.07566"
"36144","216.83200","18.06947","0.07705"
"36182","217.06000","18.08843","0.07752"
"36220","217.28800","18.10750","0.07916"
"36258","217.51600","18.12645","0.07884"
"36296","217.74400","18.14547","0.08135"
"36334","217.97200","18.16448","0.08028"
"36372","218.20000","18.18343","0.08231"
"36410","218.42800","18.20250","0.08251"
"36448","218.65600","18.22146","0.08434"
"36486","218.88400","18.24047","0.08395"
"36524","219.11200","18.25949","0.08588"
"36562","219.34000","18.27844","0.08568"
"36600","219.56800","18.29751","0.08779"
"36638","219.79600","18.31640","0.08733"
"36676","220.02400","18.33554","0.08933"
"36714","220.25200","18.35443","0.08892"
"36752","220.48000","18.37350","0.09061"
"36790","220.70800","18.39246","0.09033"
"36828","220.93600","18.41141","0.09183"
"36866","221.16400","18.43048","0.09172"
"36904","221.39200","18.44938","0.09334"
"36942","221.62000","18.46857","0.09316"
"36980","221.84800","18.48746","0.09431"
"37018","222.07600","18.50641","0.09440"
"37056","222.30400","18.52549","0.09598"
"37094","222.53200","18.54438","0.09584"
"37132","222.76000","18.56346","0.09645"
"37170","222.98800","18.58247","0.09751"
"37208","223.21600","18.60148","0.09838"
"37246","223.44400","18.62037","0.09785"
"37284","223.67200","18.63945","0.09911"
"37322","223.90000","18.65852","0.09893"
"37360","224.12800","18.67741","0.09931"
"37398","224.35600","18.69649","0.09948"
"37436","224.58400","18.71544","0.10010"
"37474","224.81200","18.73451","0.10016"
"37512","225.04000","18.75347","0.10094"
"37550","225.26800","18.77242","0.10127"
"37588","225.49600","18.79149","0.10148"
"37626","225.72400","18.81039","0.10144"
"37664","225.95200","18.82946","0.10215"
"37702","226.18000","18.84841","0.10248"
"37740","226.40800","18.86748","0.10276"
"37778","226.63600","18.88650","0.10323"
"37816","226.86400","18.90539","0.10318"
"37854","227.09200","18.92446","0.10359"
"37892","227.32000","18.94342","0.10372"
"37930","227.54800","18.96249","0.10462"
"37968","227.77600","18.98144","0.10440"
"38006","228.00400","19.00040","0.10496"
"38044","228.23200","19.01947","0.10508"
"38082","228.46000","19.03842","0.10541"
"38120","228.68800","19.05750","0.10543"
"38158","228.91600","19.07645","0.10514"
"38196","229.14400","19.09546","0.10482"
"38234","229.37200","19.11447","0.10558"
"38272","229.60000","19.13343","0.10535"
"38310","229.82800","19.15250","0.10588"
"38348","230.05600","19.17139","0.10598"
"38386","230.28400","19.19047","0.10651"
"38424","230.51200","19.20948","0.10656"
"38462","230.74000","19.22849","0.10715"
"38500","230.96800","19.24745","0.10749"
"38538","231.19600","19.26646","0.10788"
"38576","231.42400","19.28547","0.10798"
"38614","231.65200","19.30443","0.10824"
"38652","231.88000","19.32344","0.10880"
"38690","232.10800","19.34239","0.10902"
"38728","232.33600","19.36147","0.10985"
"38766","232.56400","19.38048","0.10948"
"38804","232.79200","19.39949","0.11026"
"38842","233.02000","19.41850","0.11040"
"38880","233.24800","19.43740","0.11164"
"38918","233.47600","19.45647","0.11187"
"38956","233.70400","19.47542","0.11337"
"38994","233.93200","19.49450","0.11418"
"39032","234.16000","19.51345","0.11506"
"39070","234.38800","19.53246","0.11559"
"39108","234.61600","19.55148","0.11679"
"39146","234.84400","19.57049","0.11782"
"39184","235.07200","19.58950","0.11798"
"39222","235.30000","19.60846","0.11976"
"39260","235.52800","19.62753","0.12011"
"39298","235.75600","19.64642","0.12177"
"39336","235.98400","19.66537","0.12189"
"39374","236.21200","19.68445","0.12302"
"39412","236.44000","19.70340","0.12294"
"39450","236.66800","19.72247","0.12509"
"39488","236.89600","19.74149","0.12524"
"39526","237.12400","19.76050","0.12641"
"39564","237.35200","19.77945","0.12677"
"39602","237.58000","19.79841","0.12836"
"39640","237.80800","19.81754","0.12897"
"39678","238.03600","19.83637","0.13033"
"39716","238.26400","19.85551","0.13284"
"39754","238.49200","19.87440","0.13413"
"39792","238.72000","19.89347","0.13781"
"39830","238.94800","19.91249","0.13879"
"39868","239.17600","19.93144","0.14106"
"39906","239.40400","19.95051","0.14106"
"39944","239.63200","19.96940","0.14216"
"39982","239.86000","19.98848","0.14390"
"40020","240.08800","20.00743","0.14460"
"40058","240.31600","20.02645","0.14692"
"40096","240.54400","20.04546","0.14695"
"40134","240.77200","20.06441","0.14902"
"40172","241.00000","20.08348","0.14948"
"40210","241.22800","20.10244","0.15137"
"40248","241.45600","20.12145","0.15224"
"40286","241.68400","20.14046","0.15254"
"40324","241.91200","20.15942","0.15516"
"40362","242.14000","20.17849","0.15528"
"40400","242.36800","20.19738","0.15730"
"40438","242.59600","20.21651","0.15708"
"40476","242.82400","20.23541","0.15892"
"40514","243.05200","20.25448","0.15933"
"40552","243.28000","20.27355","0.16105"
"40590","243.50800","20.29239","0.16182"
"40628","243.73600","20.31146","0.16259"
"40666","243.96400","20.33041","0.16376"
"40704","244.19200","20.34949","0.16347"
"40742","244.42000","20.36844","0.16501"
"40780","244.64800","20.38739","0.16554"
"40818","244.87600","20.40653","0.16645"
"40856","245.10400","20.42542","0.16703"
"40894","245.33200","20.44443","0.16782"
"40932","245.56000","20.46345","0.16847"
"40970","245.78800","20.48246","0.16980"
"41008","246.01600","20.50153","0.16985"
"41046","246.24400","20.52043","0.17071"
"41084","246.47200","20.53950","0.17182"
"41122","246.70000","20.55839","0.17294"
"41160","246.92800","20.57740","0.17410"
"41198","247.15600","20.59642","0.17559"
"41236","247.38400","20.61543","0.17669"
"41274","247.61200","20.63450","0.17667"
"41312","247.84000","20.65346","0.17797"
"41350","248.06800","20.67247","0.17858"
"41388","248.29600","20.69148","0.18031"
"41426","248.52400","20.71049","0.18121"
"41464","248.75200","20.72945","0.18190"
"41502","248.98000","20.74846","0.18351"
"41540","249.20800","20.76748","0.18441"
"41578","249.43600","20.78649","0.18575"
"41616","249.66400","20.80550","0.18629"
"41654","249.89200","20.82446","0.18727"
"41692","250.12000","20.84347","0.18793"
"41730","250.34800","20.86248","0.18947"
"41768","250.57600","20.88149","0.19045"
"41806","250.80400","20.90045","0.19108"
"41844","251.03200","20.91946","0.19318"
"41882","251.26000","20.93847","0.19380"
"41920","251.48800","20.95743","0.19452"
"41958","251.71600","20.97650","0.19573"
"41996","251.94400","20.99551","0.19661"
"42034","252.17200","21.01447","0.19803"
"42072","252.40000","21.03348","0.19850"
"42110","252.62800","21.05243","0.19951"
"42148","252.85600","21.07151","0.20056"
"42186","253.08400","21.09046","0.20138"
"42224","253.31200","21.10947","0.20274"
"42262","253.54000","21.12842","0.20424"
"42300","253.76800","21.14750","0.20475"
"42338","253.99600","21.16651","0.20547"
"42376","254.22400","21.18541","0.20557"
"42414","254.45200","21.20448","0.20718"
"42452","254.68000","21.22343","0.20791"
"42490","254.90800","21.24250","0.20928"
"42528","255.13600","21.26146","0.20997"
"42566","255.36400","21.28047","0.21012"
"42604","255.59200","21.29948","0.21074"
"42642","255.82000","21.31844","0.21085"
"42680","256.04800","21.33757","0.21167"
"42718","256.27600","21.35646","0.21241"
"42756","256.50400","21.37547","0.21254"
"42794","256.73200","21.39443","0.21291"
"42832","256.96000","21.41344","0.21332"
"42870","257.18800","21.43245","0.21396"
"42908","257.41600","21.45147","0.21483"
"42946","257.64400","21.47054","0.21545"
"42984","257.87200","21.48937","0.21665"
"43022","258.10000","21.50845","0.21714"
"43060","258.32800","21.52746","0.21745"
"43098","258.55600","21.54641","0.21783"
"43136","258.78400","21.56555","0.21840"
"43174","259.01200","21.58444","0.21893"
"43212","259.24000","21.60345","0.21965"
"43250","259.46800","21.62246","0.22040"
"43288","259.69600","21.64148","0.22176"
"43326","259.92400","21.66049","0.22194"
"43364","260.15200","21.67938","0.22278"
"43402","260.38000","21.69852","0.22378"
"43440","260.60800","21.71747","0.22434"
"43478","260.83600","21.73648","0.22551"
"43516","261.06400","21.75550","0.22625"
"43554","261.29200","21.77439","0.22675"
"43592","261.52000","21.79346","0.22818"
"43630","261.74800","21.81236","0.22914"
"43668","261.97600","21.83143","0.22995"
"43706","262.20400","21.85044","0.23114"
"43744","262.43200","21.86946","0.23118"
"43782","262.66000","21.88853","0.23292"
"43820","262.88800","21.90742","0.23372"
"43858","263.11600","21.92650","0.23330"
"43896","263.34400","21.94545","0.23449"
"43934","263.57200","21.96446","0.23553"
"43972","263.80000","21.98348","0.23586"
"44010","264.02800","22.00243","0.23788"
"44048","264.25600","22.02144","0.23802"
"44086","264.48400","22.04039","0.23884"
"44124","264.71200","22.05947","0.24006"
"44162","264.94000","22.07848","0.24085"
"44200","265.16800","22.09749","0.24185"
"44238","265.39600","22.11651","0.24260"
"44276","265.62400","22.13540","0.24399"
"44314","265.85200","22.15447","0.24454"
"44352","266.08000","22.17343","0.24562"
"44390","266.30800","22.19244","0.24609"
"44428","266.53600","22.21145","0.24683"
"44466","266.76400","22.23047","0.24732"
"44504","266.99200","22.24942","0.24865"
"44542","267.22000","22.26843","0.24995"
"44580","267.44800","22.28751","0.24955"
"44618","267.67600","22.30646","0.25084"
"44656","267.90400","22.32547","0.25068"
"44694","268.13200","22.34448","0.25115"
"44732","268.36000","22.36350","0.25335"
"44770","268.58800","22.38251","0.25268"
"44808","268.81600","22.40140","0.25362"
"44846","269.04400","22.42048","0.25343"
"44884","269.27200","22.43943","0.25325"
"44922","269.50000","22.45844","0.25386"
"44960","269.72800","22.47746","0.25408"
"44998","269.95600","22.49647","0.25401"
"45036","270.18400","22.51548","0.25453"
"45074","270.41200","22.53443","0.25454"
"45112","270.64000","22.55345","0.25436"
"45150","270.86800","22.57240","0.25524"
"45188","271.09600","22.59147","0.25622"
"45226","271.32400","22.61043","0.25611"
"45264","271.55200","22.62950","0.25684"
"45302","271.78000","22.64845","0.25763"
"45340","272.00800","22.66741","0.25732"
"45378","272.23600","22.68648","0.25924"
"45416","272.46400","22.70543","0.25956"
"45454","272.69200","22.72445","0.25971"
"45492","272.92000","22.74346","0.26142"
"45530","273.14800","22.76247","0.26108"
"45568","273.37600","22.78143","0.26187"
"45606","273.60400","22.80038","0.26235"
"45644","273.83200","22.81951","0.26250"
"45682","274.06000","22.83841","0.26301"
"45720","274.28800","22.85748","0.26317"
"45758","274.51600","22.87643","0.26317"
"45796","274.74400","22.89545","0.26399"
"45834","274.97200","22.91446","0.26423"
"45872","275.20000","22.93341","0.26418"
"45910","275.42800","22.95255","0.26434"
"45948","275.65600","22.97144","0.26473"
"45986","275.88400","22.99045","0.26487"
"46024","276.11200","23.00952","0.26488"
"46062","276.34000","23.02842","0.26566"
"46100","276.56800","23.04749","0.26478"
"46138","276.79600","23.06644","0.26548"
"46176","277.02400","23.08551","0.26558"
"46214","277.25200","23.10441","0.26552"
"46252","277.48000","23.12348","0.26552"
"46290","277.70800","23.14249","0.26486"
"46328","277.93600","23.16139","0.26502"
"46366","278.16400","23.18052","0.26526"
"46404","278.39200","23.19948","0.26417"
"46442","278.62000","23.21849","-0.01799"
"46480","278.84800","23.23750","-0.00427"
"46518","279.07600","23.25639","0.00204"
"46556","279.30400","23.27547","0.00242"
"46594","279.53200","23.29436","0.00180"
"46632","279.76000","23.31343","0.00198"
"46670","279.98800","23.33245","0.00184"
"46708","280.21600","23.35146","0.00231"
"46746","280.44400","23.37047","0.00266"
"46784","280.67200","23.38943","0.00274"
"46822","280.90000","23.40850","0.00273"
"46860","281.12800","23.42739","0.00193"
"46898","281.35600","23.44646","0.00211"
"46936","281.58400","23.46548","0.00200"
"46974","281.81200","23.48443","0.00279"
"46977","281.82800","23.48581","0.00272"