File: Trajectories_together/161226_2Specimen_RawData_2.csv
"","V1","V2","V3"
"1","End date","12/26/2016",""
"2","Specimen label","11BG_81_2",""
"3","Maximum Load","0.14144","N"
"4","Time","Extension","Load"
"5","(s)","(mm)","(N)"
"6","0.00000","0.00000","0.00024"
"63","0.34200","0.02840","0.00096"
"120","0.68400","0.05728","0.00095"
"177","1.02600","0.08574","0.00087"
"234","1.36800","0.11420","0.00148"
"291","1.71000","0.14272","0.00201"
"348","2.05200","0.17124","0.00192"
"405","2.39400","0.19970","0.00194"
"462","2.73600","0.22822","0.00220"
"519","3.07800","0.25668","0.00235"
"576","3.42000","0.28520","0.00256"
"633","3.76200","0.31372","0.00211"
"690","4.10400","0.34218","0.00253"
"747","4.44600","0.37075","0.00229"
"804","4.78800","0.39921","0.00295"
"861","5.13000","0.42767","0.00280"
"918","5.47200","0.45625","0.00328"
"975","5.81400","0.48465","0.00300"
"1032","6.15600","0.51323","0.00319"
"1089","6.49800","0.54169","0.00292"
"1146","6.84000","0.57015","0.00344"
"1203","7.18200","0.59873","0.00296"
"1260","7.52400","0.62719","0.00333"
"1317","7.86600","0.65565","0.00377"
"1374","8.20800","0.68423","0.00342"
"1431","8.55000","0.71263","0.00402"
"1488","8.89200","0.74121","0.00391"
"1545","9.23400","0.76973","0.00413"
"1602","9.57600","0.79819","0.00370"
"1659","9.91800","0.82677","0.00428"
"1716","10.26000","0.85523","0.00416"
"1773","10.60200","0.88369","0.00418"
"1830","10.94400","0.91221","0.00415"
"1887","11.28600","0.94067","0.00468"
"1944","11.62800","0.96925","0.00436"
"2001","11.97000","0.99771","0.00468"
"2058","12.31200","1.02617","0.00488"
"2115","12.65400","1.05475","0.00471"
"2172","12.99600","1.08321","0.00482"
"2229","13.33800","1.11167","0.00414"
"2286","13.68000","1.14019","0.00481"
"2343","14.02200","1.16871","0.00469"
"2400","14.36400","1.19717","0.00478"
"2457","14.70600","1.22575","0.00541"
"2514","15.04800","1.25420","0.00547"
"2571","15.39000","1.28272","0.00531"
"2628","15.73200","1.31118","0.00534"
"2685","16.07400","1.33970","0.00534"
"2742","16.41600","1.36822","0.00508"
"2799","16.75800","1.39674","0.00556"
"2856","17.10000","1.42520","0.00526"
"2913","17.44200","1.45372","0.00522"
"2970","17.78400","1.48218","0.00567"
"3027","18.12600","1.51070","0.00562"
"3084","18.46800","1.53928","0.00468"
"3141","18.81000","1.56768","0.00494"
"3198","19.15200","1.59620","0.00512"
"3255","19.49400","1.62472","0.00510"
"3312","19.83600","1.65318","0.00542"
"3369","20.17800","1.68170","0.00462"
"3426","20.52000","1.71028","0.00469"
"3483","20.86200","1.73862","0.00487"
"3540","21.20400","1.76720","0.00507"
"3597","21.54600","1.79572","0.00490"
"3654","21.88800","1.82418","0.00476"
"3711","22.23000","1.85270","0.00492"
"3768","22.57200","1.88116","0.00488"
"3825","22.91400","1.90962","0.00491"
"3882","23.25600","1.93826","0.00499"
"3939","23.59800","1.96666","0.00494"
"3996","23.94000","1.99518","0.00580"
"4053","24.28200","2.02382","0.00571"
"4110","24.62400","2.05216","0.00540"
"4167","24.96600","2.08074","0.00564"
"4224","25.30800","2.10920","0.00507"
"4281","25.65000","2.13766","0.00514"
"4338","25.99200","2.16623","0.00507"
"4395","26.33400","2.19469","0.00491"
"4452","26.67600","2.22315","0.00510"
"4509","27.01800","2.25173","0.00534"
"4566","27.36000","2.28013","0.00541"
"4623","27.70200","2.30871","0.00532"
"4680","28.04400","2.33723","0.00520"
"4737","28.38600","2.36563","0.00515"
"4794","28.72800","2.39421","0.00510"
"4851","29.07000","2.42267","0.00533"
"4908","29.41200","2.45119","0.00519"
"4965","29.75400","2.47971","0.00563"
"5022","30.09600","2.50823","0.00561"
"5079","30.43800","2.53675","0.00546"
"5136","30.78000","2.56521","0.00510"
"5193","31.12200","2.59367","0.00513"
"5250","31.46400","2.62219","0.00507"
"5307","31.80600","2.65071","0.00583"
"5364","32.14800","2.67917","0.00499"
"5421","32.49000","2.70775","0.00517"
"5478","32.83200","2.73621","0.00537"
"5535","33.17400","2.76467","0.00553"
"5592","33.51600","2.79319","0.00539"
"5649","33.85800","2.82165","0.00545"
"5706","34.20000","2.85023","0.00518"
"5763","34.54200","2.87875","0.00544"
"5820","34.88400","2.90715","0.00564"
"5877","35.22600","2.93573","0.00534"
"5934","35.56800","2.96419","0.00541"
"5991","35.91000","2.99271","0.00537"
"6048","36.25200","3.02117","0.00534"
"6105","36.59400","3.04968","0.00544"
"6162","36.93600","3.07814","0.00583"
"6219","37.27800","3.10672","0.00500"
"6276","37.62000","3.13524","0.00560"
"6333","37.96200","3.16370","0.00521"
"6390","38.30400","3.19228","0.00524"
"6447","38.64600","3.22068","0.00526"
"6504","38.98800","3.24920","0.00496"
"6561","39.33000","3.27772","0.00538"
"6618","39.67200","3.30618","0.00485"
"6675","40.01400","3.33470","0.00535"
"6732","40.35600","3.36322","0.00557"
"6789","40.69800","3.39168","0.00517"
"6846","41.04000","3.42020","0.00513"
"6903","41.38200","3.44872","0.00524"
"6960","41.72400","3.47712","0.00552"
"7017","42.06600","3.50576","0.00530"
"7074","42.40800","3.53410","0.00527"
"7131","42.75000","3.56274","0.00523"
"7188","43.09200","3.59120","0.00554"
"7245","43.43400","3.61972","0.00525"
"7302","43.77600","3.64824","0.00543"
"7359","44.11800","3.67664","0.00540"
"7416","44.46000","3.70516","0.00548"
"7473","44.80200","3.73374","0.00588"
"7530","45.14400","3.76220","0.00552"
"7587","45.48600","3.79072","0.00559"
"7644","45.82800","3.81924","0.00550"
"7701","46.17000","3.84764","0.00549"
"7758","46.51200","3.87622","0.00574"
"7815","46.85400","3.90474","0.00531"
"7872","47.19600","3.93319","0.00588"
"7929","47.53800","3.96171","0.00589"
"7986","47.88000","3.99017","0.00608"
"8043","48.22200","4.01869","0.00602"
"8100","48.56400","4.04721","0.00531"
"8157","48.90600","4.07567","0.00601"
"8214","49.24800","4.10419","0.00531"
"8271","49.59000","4.13271","0.00561"
"8328","49.93200","4.16117","0.00571"
"8385","50.27400","4.18975","0.00592"
"8442","50.61600","4.21827","0.00610"
"8499","50.95800","4.24667","0.00556"
"8556","51.30000","4.27519","0.00567"
"8613","51.64200","4.30371","0.00567"
"8670","51.98400","4.33217","0.00594"
"8727","52.32600","4.36069","0.00572"
"8784","52.66800","4.38921","0.00532"
"8841","53.01000","4.41773","0.00572"
"8898","53.35200","4.44625","0.00561"
"8955","53.69400","4.47471","0.00567"
"9012","54.03600","4.50323","0.00583"
"9069","54.37800","4.53169","0.00580"
"9126","54.72000","4.56021","0.00548"
"9183","55.06200","4.58873","0.00548"
"9240","55.40400","4.61725","0.00559"
"9297","55.74600","4.64571","0.00583"
"9354","56.08800","4.67423","0.00595"
"9411","56.43000","4.70269","0.00563"
"9468","56.77200","4.73115","0.00562"
"9525","57.11400","4.75973","0.00580"
"9582","57.45600","4.78819","0.00552"
"9639","57.79800","4.81670","0.00564"
"9696","58.14000","4.84522","0.00582"
"9753","58.48200","4.87368","0.00587"
"9810","58.82400","4.90220","0.00574"
"9867","59.16600","4.93072","0.00586"
"9924","59.50800","4.95918","0.00613"
"9981","59.85000","4.98776","0.00566"
"10038","60.19200","5.01616","0.00628"
"10095","60.53400","5.04468","0.00623"
"10152","60.87600","5.07326","0.00593"
"10209","61.21800","5.10166","0.00593"
"10266","61.56000","5.13024","0.00603"
"10323","61.90200","5.15870","0.00605"
"10380","62.24400","5.18722","0.00590"
"10437","62.58600","5.21574","0.00605"
"10494","62.92800","5.24420","0.00624"
"10551","63.27000","5.27272","0.00607"
"10608","63.61200","5.30124","0.00638"
"10665","63.95400","5.32964","0.00654"
"10722","64.29600","5.35822","0.00623"
"10779","64.63800","5.38674","0.00601"
"10836","64.98000","5.41514","0.00604"
"10893","65.32200","5.44372","0.00616"
"10950","65.66400","5.47218","0.00621"
"11007","66.00600","5.50070","0.00664"
"11064","66.34800","5.52922","0.00666"
"11121","66.69000","5.55768","0.00665"
"11178","67.03200","5.58626","0.00646"
"11235","67.37400","5.61472","0.00666"
"11292","67.71600","5.64318","0.00658"
"11349","68.05800","5.67175","0.00652"
"11406","68.40000","5.70021","0.00675"
"11463","68.74200","5.72867","0.00629"
"11520","69.08400","5.75719","0.00598"
"11577","69.42600","5.78565","0.00626"
"11634","69.76800","5.81417","0.00632"
"11691","70.11000","5.84275","0.00680"
"11748","70.45200","5.87121","0.00623"
"11805","70.79400","5.89973","0.00675"
"11862","71.13600","5.92825","0.00700"
"11919","71.47800","5.95665","0.00648"
"11976","71.82000","5.98517","0.00624"
"12033","72.16200","6.01369","0.00681"
"12090","72.50400","6.04221","0.00639"
"12147","72.84600","6.07067","0.00635"
"12204","73.18800","6.09925","0.00650"
"12261","73.53000","6.12771","0.00682"
"12318","73.87200","6.15623","0.00645"
"12375","74.21400","6.18475","0.00642"
"12432","74.55600","6.21315","0.00655"
"12489","74.89800","6.24173","0.00672"
"12546","75.24000","6.27013","0.00663"
"12603","75.58200","6.29871","0.00699"
"12660","75.92400","6.32729","0.00690"
"12717","76.26600","6.35563","0.00670"
"12774","76.60800","6.38421","0.00669"
"12831","76.95000","6.41273","0.00582"
"12888","77.29200","6.44119","0.00621"
"12945","77.63400","6.46977","0.00557"
"13002","77.97600","6.49817","0.00586"
"13059","78.31800","6.52663","0.00652"
"13116","78.66000","6.55520","0.00615"
"13173","79.00200","6.58366","0.00651"
"13230","79.34400","6.61224","0.00618"
"13287","79.68600","6.64070","0.00632"
"13344","80.02800","6.66910","0.00644"
"13401","80.37000","6.69774","0.00614"
"13458","80.71200","6.72620","0.00666"
"13515","81.05400","6.75466","0.00603"
"13572","81.39600","6.78324","0.00676"
"13629","81.73800","6.81164","0.00666"
"13686","82.08000","6.84022","0.00540"
"13743","82.42200","6.86874","0.00550"
"13800","82.76400","6.89714","0.00607"
"13857","83.10600","6.92572","0.00573"
"13914","83.44800","6.95418","0.00572"
"13971","83.79000","6.98270","0.00578"
"14028","84.13200","7.01122","0.00546"
"14085","84.47400","7.03974","0.00574"
"14142","84.81600","7.06820","0.00551"
"14199","85.15800","7.09666","0.00553"
"14256","85.50000","7.12518","0.00558"
"14313","85.84200","7.15376","0.00549"
"14370","86.18400","7.18228","0.00595"
"14427","86.52600","7.21068","0.00571"
"14484","86.86800","7.23920","0.00518"
"14541","87.21000","7.26766","0.00596"
"14598","87.55200","7.29618","0.00553"
"14655","87.89400","7.32476","0.00535"
"14712","88.23600","7.35322","0.00526"
"14769","88.57800","7.38174","0.00510"
"14826","88.92000","7.41020","0.00459"
"14883","89.26200","7.43871","0.00488"
"14940","89.60400","7.46717","0.00511"
"14997","89.94600","7.49569","0.00514"
"15054","90.28800","7.52421","0.00507"
"15111","90.63000","7.55273","0.00548"
"15168","90.97200","7.58119","0.00510"
"15225","91.31400","7.60971","0.00479"
"15282","91.65600","7.63823","0.00494"
"15339","91.99800","7.66669","0.00539"
"15396","92.34000","7.69521","0.00533"
"15453","92.68200","7.72373","0.00564"
"15510","93.02400","7.75219","0.00540"
"15567","93.36600","7.78065","0.00518"
"15624","93.70800","7.80923","0.00527"
"15681","94.05000","7.83763","0.00510"
"15738","94.39200","7.86621","0.00503"
"15795","94.73400","7.89473","0.00463"
"15852","95.07600","7.92319","0.00507"
"15909","95.41800","7.95171","0.00515"
"15966","95.76000","7.98023","0.00486"
"16023","96.10200","8.00869","0.00549"
"16080","96.44400","8.03727","0.00546"
"16137","96.78600","8.06567","0.00501"
"16194","97.12800","8.09419","0.00434"
"16251","97.47000","8.12277","0.00493"
"16308","97.81200","8.15111","0.00427"
"16365","98.15400","8.17975","0.00489"
"16422","98.49600","8.20821","0.00519"
"16479","98.83800","8.23667","0.00513"
"16536","99.18000","8.26531","0.00441"
"16593","99.52200","8.29370","0.00476"
"16650","99.86400","8.32216","0.00496"
"16707","100.20600","8.35068","0.00470"
"16764","100.54800","8.37914","0.00439"
"16821","100.89000","8.40772","0.00536"
"16878","101.23200","8.43624","0.00496"
"16935","101.57400","8.46464","0.00496"
"16992","101.91600","8.49322","0.00530"
"17049","102.25800","8.52168","0.00462"
"17106","102.60000","8.55014","0.00441"
"17163","102.94200","8.57878","0.00473"
"17220","103.28400","8.60712","0.00484"
"17277","103.62600","8.63570","0.00458"
"17334","103.96800","8.66422","0.00498"
"17391","104.31000","8.69268","0.00436"
"17448","104.65200","8.72120","0.00495"
"17505","104.99400","8.74972","0.00530"
"17562","105.33600","8.77818","0.00523"
"17619","105.67800","8.80676","0.00502"
"17676","106.02000","8.83522","0.00475"
"17733","106.36200","8.86368","0.00553"
"17790","106.70400","8.89220","0.00528"
"17847","107.04600","8.92066","0.00504"
"17904","107.38800","8.94918","0.00520"
"17961","107.73000","8.97770","0.00496"
"18018","108.07200","9.00622","0.00463"
"18075","108.41400","9.03462","0.00462"
"18132","108.75600","9.06320","0.00444"
"18189","109.09800","9.09172","0.00477"
"18246","109.44000","9.12024","0.00459"
"18303","109.78200","9.14876","0.00505"
"18360","110.12400","9.17715","0.00425"
"18417","110.46600","9.20568","0.00481"
"18474","110.80800","9.23419","0.00461"
"18531","111.15000","9.26271","0.00426"
"18588","111.49200","9.29123","0.00509"
"18645","111.83400","9.31963","0.00449"
"18702","112.17600","9.34815","0.00440"
"18759","112.51800","9.37673","0.00491"
"18816","112.86000","9.40513","0.00473"
"18873","113.20200","9.43371","0.00494"
"18930","113.54400","9.46223","0.00467"
"18987","113.88600","9.49069","0.00424"
"19044","114.22800","9.51927","0.00533"
"19101","114.57000","9.54767","0.00479"
"19158","114.91200","9.57619","0.00472"
"19215","115.25400","9.60471","0.00481"
"19272","115.59600","9.63317","0.00468"
"19329","115.93800","9.66175","0.00457"
"19386","116.28000","9.69021","0.00485"
"19443","116.62200","9.71867","0.00481"
"19500","116.96400","9.74725","0.00516"
"19557","117.30600","9.77571","0.00450"
"19614","117.64800","9.80417","0.00495"
"19671","117.99000","9.83275","0.00477"
"19728","118.33200","9.86115","0.00496"
"19785","118.67400","9.88973","0.00488"
"19842","119.01600","9.91825","0.00488"
"19899","119.35800","9.94665","0.00483"
"19956","119.70000","9.97522","0.00498"
"20013","120.04200","10.00375","0.00492"
"20070","120.38400","10.03221","0.00501"
"20127","120.72600","10.06073","0.00503"
"20184","121.06800","10.08913","0.00518"
"20241","121.41000","10.11764","0.00514"
"20298","121.75200","10.14622","0.00492"
"20355","122.09400","10.17468","0.00471"
"20412","122.43600","10.20320","0.00505"
"20469","122.77800","10.23172","0.00504"
"20526","123.12000","10.26012","0.00511"
"20583","123.46200","10.28870","0.00445"
"20640","123.80400","10.31722","0.00503"
"20697","124.14600","10.34568","0.00505"
"20754","124.48800","10.37426","0.00515"
"20811","124.83000","10.40272","0.00466"
"20868","125.17200","10.43118","0.00518"
"20925","125.51400","10.45964","0.00548"
"20982","125.85600","10.48822","0.00497"
"21039","126.19800","10.51662","0.00548"
"21096","126.54000","10.54520","0.00519"
"21153","126.88200","10.57366","0.00525"
"21210","127.22400","10.60224","0.00478"
"21267","127.56600","10.63076","0.00474"
"21324","127.90800","10.65916","0.00495"
"21381","128.25000","10.68774","0.00522"
"21438","128.59200","10.71620","0.00450"
"21495","128.93400","10.74466","0.00465"
"21552","129.27600","10.77324","0.00463"
"21609","129.61800","10.80170","0.00423"
"21666","129.96000","10.83016","0.00463"
"21723","130.30200","10.85874","0.00486"
"21780","130.64400","10.88713","0.00482"
"21837","130.98600","10.91572","0.00478"
"21894","131.32800","10.94423","0.00494"
"21951","131.67000","10.97269","0.00520"
"22008","132.01200","11.00121","0.00493"
"22065","132.35400","11.02967","0.00498"
"22122","132.69600","11.05819","0.00481"
"22179","133.03800","11.08677","0.00512"
"22236","133.38000","11.11517","0.00500"
"22293","133.72200","11.14369","0.00467"
"22350","134.06400","11.17227","0.00499"
"22407","134.40600","11.20067","0.00510"
"22464","134.74800","11.22919","0.00517"
"22521","135.09000","11.25771","0.00520"
"22578","135.43200","11.28617","0.00509"
"22635","135.77400","11.31469","0.00533"
"22692","136.11600","11.34321","0.00504"
"22749","136.45800","11.37167","0.00532"
"22806","136.80000","11.40025","0.00565"
"22863","137.14200","11.42865","0.00566"
"22920","137.48400","11.45729","0.00595"
"22977","137.82600","11.48575","0.00594"
"23034","138.16800","11.51415","0.00592"
"23091","138.51000","11.54273","0.00572"
"23148","138.85200","11.57119","0.00597"
"23205","139.19400","11.59971","0.00586"
"23262","139.53600","11.62823","0.00596"
"23319","139.87800","11.65669","0.00552"
"23376","140.22000","11.68521","0.00600"
"23433","140.56200","11.71367","0.00615"
"23490","140.90400","11.74213","0.00590"
"23547","141.24600","11.77071","0.00654"
"23604","141.58800","11.79922","0.00638"
"23661","141.93000","11.82775","0.00616"
"23718","142.27200","11.85626","0.00649"
"23775","142.61400","11.88472","0.00657"
"23832","142.95600","11.91318","0.00673"
"23889","143.29800","11.94170","0.00631"
"23946","143.64000","11.97016","0.00689"
"24003","143.98200","11.99868","0.00634"
"24060","144.32400","12.02720","0.00650"
"24117","144.66600","12.05572","0.00690"
"24174","145.00800","12.08418","0.00686"
"24231","145.35000","12.11276","0.00691"
"24288","145.69200","12.14116","0.00666"
"24345","146.03400","12.16974","0.00747"
"24402","146.37600","12.19820","0.00721"
"24459","146.71800","12.22672","0.00698"
"24516","147.06000","12.25524","0.00683"
"24573","147.40200","12.28370","0.00734"
"24630","147.74400","12.31222","0.00765"
"24687","148.08600","12.34074","0.00784"
"24744","148.42800","12.36920","0.00795"
"24801","148.77000","12.39772","0.00769"
"24858","149.11200","12.42624","0.00792"
"24915","149.45400","12.45464","0.00820"
"24972","149.79600","12.48322","0.00832"
"25029","150.13800","12.51168","0.00844"
"25086","150.48000","12.54014","0.00859"
"25143","150.82200","12.56872","0.00848"
"25200","151.16400","12.59718","0.00852"
"25257","151.50600","12.62570","0.00839"
"25314","151.84800","12.65421","0.00822"
"25371","152.19000","12.68268","0.00894"
"25428","152.53200","12.71125","0.00874"
"25485","152.87400","12.73977","0.00891"
"25542","153.21600","12.76812","0.00889"
"25599","153.55800","12.79669","0.00922"
"25656","153.90000","12.82515","0.00924"
"25713","154.24200","12.85373","0.00954"
"25770","154.58400","12.88225","0.00966"
"25827","154.92600","12.91065","0.00940"
"25884","155.26800","12.93923","0.00951"
"25941","155.61000","12.96775","0.00951"
"25998","155.95200","12.99615","0.00974"
"26055","156.29400","13.02473","0.00973"
"26112","156.63600","13.05319","0.00989"
"26169","156.97800","13.08165","0.01032"
"26226","157.32000","13.11023","0.01028"
"26283","157.66200","13.13869","0.01067"
"26340","158.00400","13.16721","0.01053"
"26397","158.34600","13.19567","0.01058"
"26454","158.68800","13.22419","0.01110"
"26511","159.03000","13.25271","0.01112"
"26568","159.37200","13.28123","0.01106"
"26625","159.71400","13.30969","0.01095"
"26682","160.05600","13.33821","0.01153"
"26739","160.39800","13.36673","0.01109"
"26796","160.74000","13.39519","0.01121"
"26853","161.08200","13.42371","0.01130"
"26910","161.42400","13.45223","0.01167"
"26967","161.76600","13.48069","0.01180"
"27024","162.10800","13.50915","0.01207"
"27081","162.45000","13.53773","0.01219"
"27138","162.79200","13.56625","0.01212"
"27195","163.13400","13.59477","0.01257"
"27252","163.47600","13.62316","0.01237"
"27309","163.81800","13.65168","0.01299"
"27366","164.16000","13.68015","0.01351"
"27423","164.50200","13.70866","0.01316"
"27480","164.84400","13.73724","0.01331"
"27537","165.18600","13.76570","0.01347"
"27594","165.52800","13.79416","0.01390"
"27651","165.87000","13.82274","0.01418"
"27708","166.21200","13.85120","0.01414"
"27765","166.55400","13.87966","0.01453"
"27822","166.89600","13.90824","0.01469"
"27879","167.23800","13.93670","0.01521"
"27936","167.58000","13.96516","0.01492"
"27993","167.92200","13.99368","0.01544"
"28050","168.26400","14.02220","0.01654"
"28107","168.60600","14.05072","0.01631"
"28164","168.94800","14.07918","0.01677"
"28221","169.29000","14.10770","0.01662"
"28278","169.63200","14.13628","0.01723"
"28335","169.97400","14.16468","0.01732"
"28392","170.31600","14.19320","0.01822"
"28449","170.65800","14.22172","0.01812"
"28506","171.00000","14.25012","0.01855"
"28563","171.34200","14.27876","0.01861"
"28620","171.68400","14.30722","0.01947"
"28677","172.02600","14.33568","0.01950"
"28734","172.36800","14.36420","0.02042"
"28791","172.71000","14.39266","0.02075"
"28848","173.05200","14.42118","0.02129"
"28905","173.39400","14.44970","0.01991"
"28962","173.73600","14.47815","0.02037"
"29019","174.07800","14.50673","0.02146"
"29076","174.42000","14.53525","0.02164"
"29133","174.76200","14.56365","0.02256"
"29190","175.10400","14.59223","0.02278"
"29247","175.44600","14.62069","0.02358"
"29304","175.78800","14.64921","0.02396"
"29361","176.13000","14.67773","0.02500"
"29418","176.47200","14.70619","0.02538"
"29475","176.81400","14.73471","0.02599"
"29532","177.15600","14.76317","0.02617"
"29589","177.49800","14.79169","0.02645"
"29646","177.84000","14.82015","0.02697"
"29703","178.18200","14.84867","0.02799"
"29760","178.52400","14.87719","0.02848"
"29817","178.86600","14.90571","0.02950"
"29874","179.20800","14.93417","0.02894"
"29931","179.55000","14.96263","0.02992"
"29988","179.89200","14.99121","0.03076"
"30045","180.23400","15.01973","0.03122"
"30102","180.57600","15.04819","0.03265"
"30159","180.91800","15.07671","0.03280"
"30216","181.26000","15.10523","0.03416"
"30273","181.60200","15.13369","0.03448"
"30330","181.94400","15.16221","0.03601"
"30387","182.28600","15.19067","0.03638"
"30444","182.62800","15.21919","0.03693"
"30501","182.97000","15.24771","0.03870"
"30558","183.31200","15.27623","0.03960"
"30615","183.65400","15.30469","0.04065"
"30672","183.99600","15.33321","0.04142"
"30729","184.33800","15.36166","0.04259"
"30786","184.68000","15.39025","0.03932"
"30843","185.02200","15.41871","0.03927"
"30900","185.36400","15.44722","0.04069"
"30957","185.70600","15.47580","0.04097"
"31014","186.04800","15.50414","0.04298"
"31071","186.39000","15.53272","0.04387"
"31128","186.73200","15.56118","0.04402"
"31185","187.07400","15.58964","0.04483"
"31242","187.41600","15.61822","0.04659"
"31299","187.75800","15.64668","0.04700"
"31356","188.10000","15.67520","0.04721"
"31413","188.44200","15.70378","0.04874"
"31470","188.78400","15.73212","0.04966"
"31527","189.12600","15.76070","0.05046"
"31584","189.46800","15.78928","0.05116"
"31641","189.81000","15.81768","0.05189"
"31698","190.15200","15.84626","0.05299"
"31755","190.49400","15.87472","0.05358"
"31812","190.83600","15.90318","0.05375"
"31869","191.17800","15.93170","0.05450"
"31926","191.52000","15.96022","0.05536"
"31983","191.86200","15.98874","0.05550"
"32040","192.20400","16.01714","0.05685"
"32097","192.54600","16.04560","0.05756"
"32154","192.88800","16.07424","0.05836"
"32211","193.23000","16.10270","0.05882"
"32268","193.57200","16.13121","0.05927"
"32325","193.91400","16.15973","0.06052"
"32382","194.25600","16.18819","0.06143"
"32439","194.59800","16.21671","0.06284"
"32496","194.94000","16.24524","0.06409"
"32553","195.28200","16.27369","0.06509"
"32610","195.62400","16.30221","0.06637"
"32667","195.96600","16.33068","0.06849"
"32724","196.30800","16.35919","0.06887"
"32781","196.65000","16.38771","0.07031"
"32838","196.99200","16.41623","0.07238"
"32895","197.33400","16.44469","0.07351"
"32952","197.67600","16.47321","0.07576"
"33009","198.01800","16.50173","0.07657"
"33066","198.36000","16.53019","0.07777"
"33123","198.70200","16.55871","0.08025"
"33180","199.04400","16.58717","0.08122"
"33237","199.38600","16.61569","0.08262"
"33294","199.72800","16.64421","0.08399"
"33351","200.07000","16.67267","0.08510"
"33408","200.41200","16.70125","0.08645"
"33465","200.75400","16.72971","0.08782"
"33522","201.09600","16.75817","0.08847"
"33579","201.43800","16.78669","0.08990"
"33636","201.78000","16.81521","0.09077"
"33693","202.12200","16.84367","0.09231"
"33750","202.46400","16.87225","0.09325"
"33807","202.80600","16.90065","0.09452"
"33864","203.14800","16.92917","0.09517"
"33921","203.49000","16.95775","0.09605"
"33978","203.83200","16.98621","0.09642"
"34035","204.17400","17.01472","0.09719"
"34092","204.51600","17.04325","0.09763"
"34149","204.85800","17.07170","0.09837"
"34206","205.20000","17.10022","0.09850"
"34263","205.54200","17.12868","0.09914"
"34320","205.88400","17.15720","0.09997"
"34377","206.22600","17.18578","0.10079"
"34434","206.56800","17.21412","0.10156"
"34491","206.91000","17.24270","0.10174"
"34548","207.25200","17.27122","0.10243"
"34605","207.59400","17.29962","0.10305"
"34662","207.93600","17.32826","0.10342"
"34719","208.27800","17.35672","0.10383"
"34776","208.62000","17.38518","0.10423"
"34833","208.96200","17.41376","0.10486"
"34890","209.30400","17.44216","0.10558"
"34947","209.64600","17.47068","0.10625"
"35004","209.98800","17.49926","0.10711"
"35061","210.33000","17.52760","0.10811"
"35118","210.67200","17.55624","0.10967"
"35175","211.01400","17.58470","0.11075"
"35232","211.35600","17.61322","0.11189"
"35289","211.69800","17.64174","0.11301"
"35346","212.04000","17.67026","0.11535"
"35403","212.38200","17.69872","0.11652"
"35460","212.72400","17.72724","0.11777"
"35517","213.06600","17.75570","0.11954"
"35574","213.40800","17.78416","0.12037"
"35631","213.75000","17.81268","0.12184"
"35688","214.09200","17.84120","0.12469"
"35745","214.43400","17.86972","0.12561"
"35802","214.77600","17.89824","0.12800"
"35859","215.11800","17.92669","0.13074"
"35916","215.46000","17.95522","0.13275"
"35973","215.80200","17.98368","0.13566"
"36030","216.14400","18.01219","0.13735"
"36087","216.48600","18.04071","0.13943"
"36144","216.82800","18.06923","0.13051"
"36201","217.17000","18.09769","0.00117"
"36258","217.51200","18.12621","0.00062"
"36315","217.85400","18.15467","0.00291"
"36372","218.19600","18.18319","0.00417"
"36429","218.53800","18.21171","0.00317"
"36486","218.88000","18.24017","0.00532"
"36543","219.22200","18.26869","0.00353"
"36600","219.56400","18.29721","0.00449"
"36657","219.90600","18.32567","0.00450"
"36714","220.24800","18.35419","0.00396"
"36771","220.59000","18.38265","0.00476"
"36828","220.93200","18.41117","0.00372"
"36885","221.27400","18.43969","0.00509"
"36942","221.61600","18.46815","0.00482"
"36999","221.95800","18.49667","0.00504"
"37056","222.30000","18.52525","0.00532"
"37113","222.64200","18.55365","0.00427"
"37170","222.98400","18.58223","0.00526"
"37227","223.32600","18.61075","0.00565"
"37284","223.66800","18.63921","0.00557"
"37341","224.01000","18.66779","0.00586"
"37398","224.35200","18.69619","0.00514"
"37455","224.69400","18.72471","0.00539"
"37512","225.03600","18.75323","0.00559"
"37569","225.37800","18.78163","0.00600"
"37626","225.72000","18.81026","0.00558"
"37683","226.06200","18.83873","0.00605"
"37740","226.40400","18.86713","0.00594"
"37797","226.74600","18.89576","0.00601"
"37854","227.08800","18.92416","0.00664"
"37911","227.43000","18.95268","0.00602"
"37968","227.77200","18.98114","0.00644"
"38025","228.11400","19.00960","0.00615"
"38082","228.45600","19.03824","0.00641"
"38139","228.79800","19.06676","0.00640"
"38196","229.14000","19.09516","0.00633"
"38253","229.48200","19.12374","0.00690"
"38310","229.82400","19.15220","0.00663"
"38367","230.16600","19.18066","0.00642"
"38424","230.50800","19.20924","0.00672"
"38481","230.85000","19.23770","0.00690"
"38538","231.19200","19.26622","0.00676"
"38595","231.53400","19.29474","0.00749"
"38652","231.87600","19.32320","0.00656"
"38709","232.21800","19.35172","0.00739"
"38766","232.56000","19.38018","0.00668"
"38823","232.90200","19.40864","0.00708"
"38880","233.24400","19.43722","0.00732"
"38937","233.58600","19.46574","0.00730"
"38994","233.92800","19.49420","0.00701"
"39051","234.27000","19.52272","0.00725"
"39108","234.61200","19.55124","0.00739"
"39165","234.95400","19.57970","0.00737"
"39222","235.29600","19.60822","0.00757"
"39279","235.63800","19.63674","0.00729"
"39336","235.98000","19.66520","0.00732"
"39393","236.32200","19.69371","0.00751"
"39450","236.66400","19.72217","0.00784"
"39507","237.00600","19.75076","0.00750"
"39564","237.34800","19.77927","0.00776"
"39621","237.69000","19.80767","0.00780"
"39678","238.03200","19.83625","0.00810"
"39735","238.37400","19.86471","0.00776"
"39792","238.71600","19.89317","0.00781"
"39849","239.05800","19.92169","0.00760"
"39906","239.40000","19.95015","0.00795"
"39963","239.74200","19.97867","0.00787"
"40020","240.08400","20.00725","0.00768"
"40077","240.42600","20.03571","0.00773"
"40134","240.76800","20.06417","0.00798"
"40191","241.11000","20.09275","0.00792"
"40248","241.45200","20.12115","0.00818"
"40305","241.79400","20.14973","0.00810"
"40362","242.13600","20.17819","0.00824"
"40419","242.47800","20.20665","0.00824"
"40476","242.82000","20.23523","0.00797"
"40533","243.16200","20.26369","0.00836"
"40590","243.50400","20.29221","0.00856"
"40647","243.84600","20.32073","0.00842"
"40704","244.18800","20.34919","0.00871"
"40761","244.53000","20.37771","0.00861"
"40818","244.87200","20.40623","0.00863"
"40875","245.21400","20.43469","0.00830"
"40932","245.55600","20.46327","0.00899"
"40989","245.89800","20.49167","0.00896"
"41046","246.24000","20.52019","0.00894"
"41103","246.58200","20.54870","0.00866"
"41160","246.92400","20.57716","0.00910"
"41217","247.26600","20.60575","0.00933"
"41274","247.60800","20.63421","0.00890"
"41331","247.95000","20.66267","0.00898"
"41388","248.29200","20.69124","0.00896"
"41445","248.63400","20.71970","0.00928"
"41502","248.97600","20.74822","0.00926"
"41559","249.31800","20.77674","0.00931"
"41616","249.66000","20.80520","0.00928"
"41673","250.00200","20.83372","0.00922"
"41730","250.34400","20.86218","0.00939"
"41787","250.68600","20.89070","0.00954"
"41844","251.02800","20.91916","0.00964"
"41901","251.37000","20.94774","0.00932"
"41958","251.71200","20.97620","0.00933"
"42015","252.05400","21.00472","0.00951"
"42072","252.39600","21.03324","0.00969"
"42129","252.73800","21.06170","0.00974"
"42186","253.08000","21.09022","0.00957"
"42243","253.42200","21.11868","0.00962"
"42300","253.76400","21.14720","0.00959"
"42357","254.10600","21.17566","0.00972"
"42414","254.44800","21.20424","0.00987"
"42471","254.79000","21.23270","0.00997"
"42528","255.13200","21.26128","0.01002"
"42585","255.47400","21.28968","0.00978"
"42642","255.81600","21.31820","0.01010"
"42699","256.15800","21.34672","0.01005"
"42756","256.50000","21.37512","0.01025"
"42813","256.84200","21.40369","0.01030"
"42870","257.18400","21.43216","0.01045"
"42927","257.52600","21.46074","0.01024"
"42984","257.86800","21.48926","0.01012"
"43041","258.21000","21.51760","0.01029"
"43098","258.55200","21.54618","0.01030"
"43155","258.89400","21.57475","0.01049"
"43212","259.23600","21.60315","0.01023"
"43269","259.57800","21.63173","0.01045"
"43326","259.92000","21.66019","0.01076"
"43383","260.26200","21.68871","0.01043"
"43440","260.60400","21.71723","0.01063"
"43497","260.94600","21.74569","0.01071"
"43554","261.28800","21.77415","0.01049"
"43611","261.63000","21.80273","0.01073"
"43668","261.97200","21.83113","0.01098"
"43725","262.31400","21.85971","0.01040"
"43782","262.65600","21.88823","0.01053"
"43839","262.99800","21.91663","0.01059"
"43896","263.34000","21.94521","0.01081"
"43953","263.68200","21.97367","0.01073"
"44010","264.02400","22.00219","0.01086"
"44067","264.36600","22.03071","0.01108"
"44124","264.70800","22.05923","0.01108"
"44181","265.05000","22.08769","0.01095"
"44238","265.39200","22.11621","0.01115"
"44295","265.73400","22.14467","0.01132"
"44352","266.07600","22.17325","0.01118"
"44409","266.41800","22.20171","0.01135"
"44466","266.76000","22.23017","0.01146"
"44523","267.10200","22.25875","0.01132"
"44580","267.44400","22.28720","0.01161"
"44637","267.78600","22.31566","0.01138"
"44694","268.12800","22.34419","0.01187"
"44751","268.47000","22.37264","0.01149"
"44808","268.81200","22.40122","0.01173"
"44865","269.15400","22.42969","0.01150"
"44922","269.49600","22.45820","0.01205"
"44979","269.83800","22.48672","0.01173"
"45036","270.18000","22.51525","0.01176"
"45093","270.52200","22.54370","0.01226"
"45150","270.86400","22.57216","0.01215"
"45207","271.20600","22.60068","0.01197"
"45264","271.54800","22.62920","0.01211"
"45321","271.89000","22.65766","0.01233"
"45378","272.23200","22.68618","0.01206"
"45435","272.57400","22.71470","0.01228"
"45492","272.91600","22.74322","0.01210"
"45549","273.25800","22.77168","0.01214"
"45606","273.60000","22.80020","0.01208"
"45663","273.94200","22.82878","0.01216"
"45720","274.28400","22.85718","0.01274"
"45777","274.62600","22.88570","0.01263"
"45834","274.96800","22.91422","0.01262"
"45891","275.31000","22.94268","0.01273"
"45948","275.65200","22.97126","0.01283"
"46005","275.99400","22.99966","0.01266"
"46062","276.33600","23.02818","0.01310"
"46119","276.67800","23.05670","0.01256"
"46176","277.02000","23.08516","0.01262"
"46233","277.36200","23.11374","0.01270"
"46290","277.70400","23.14220","0.01284"
"46347","278.04600","23.17066","0.01272"
"46404","278.38800","23.19924","0.01283"
"46461","278.73000","23.22770","0.01251"
"46518","279.07200","23.25622","0.01240"
"46575","279.41400","23.28473","0.01268"
"46632","279.75600","23.31314","0.01288"
"46689","280.09800","23.34171","0.01253"
"46746","280.44000","23.37023","0.01227"
"46803","280.78200","23.39869","0.01223"
"46860","281.12400","23.42721","0.01243"
"46917","281.46600","23.45567","0.01250"
"46974","281.80800","23.48419","0.01242"
"47031","282.15000","23.51271","0.01248"
"47088","282.49200","23.54117","0.01246"
"47145","282.83400","23.56969","0.01258"
"47202","283.17600","23.59821","0.01262"
"47259","283.51800","23.62667","0.01290"
"47316","283.86000","23.65525","0.01248"
"47373","284.20200","23.68377","0.01286"
"47430","284.54400","23.71217","0.01267"
"47487","284.88600","23.74075","0.01279"
"47544","285.22800","23.76915","0.01283"
"47601","285.57000","23.79767","0.01262"
"47658","285.91200","23.82625","0.01298"
"47715","286.25400","23.85471","0.01309"
"47772","286.59600","23.88317","0.01334"
"47829","286.93800","23.91169","0.01347"
"47886","287.28000","23.94020","0.01363"
"47943","287.62200","23.96873","0.01348"
"48000","287.96400","23.99725","0.01344"
"48057","288.30600","24.02571","0.01315"
"48114","288.64800","24.05423","0.01321"
"48171","288.99000","24.08269","0.01320"
"48228","289.33200","24.11115","0.01321"
"48285","289.67400","24.13972","0.01356"
"48342","290.01600","24.16818","0.01347"
"48399","290.35800","24.19670","0.01336"
"48456","290.70000","24.22523","0.01376"
"48513","291.04200","24.25368","0.01374"
"48570","291.38400","24.28214","0.01371"
"48627","291.72600","24.31072","0.01385"
"48684","292.06800","24.33912","0.01389"
"48741","292.41000","24.36770","0.01416"
"48798","292.75200","24.39628","0.01393"
"48855","293.09400","24.42468","0.01376"
"48912","293.43600","24.45320","0.01402"
"48969","293.77800","24.48166","0.01365"
"49026","294.12000","24.51018","0.01447"
"49083","294.46200","24.53876","0.01379"
"49140","294.80400","24.56716","0.01377"
"49197","295.14600","24.59568","0.01387"
"49254","295.48800","24.62420","0.01381"
"49311","295.83000","24.65266","0.01404"
"49368","296.17200","24.68124","0.01414"
"49425","296.51400","24.70970","0.01398"
"49482","296.85600","24.73816","0.01369"
"49539","297.19800","24.76674","0.01413"
"49596","297.54000","24.79520","0.01393"
"49653","297.88200","24.82372","0.01418"
"49710","298.22400","24.85224","0.01447"
"49767","298.56600","24.88064","0.01383"
"49824","298.90800","24.90922","0.01391"
"49881","299.25000","24.93774","0.01405"
"49938","299.59200","24.96614","0.01424"
"49995","299.93400","24.99471","0.01442"
"50052","300.27600","25.02318","0.01488"
"50109","300.61800","25.05169","0.01432"
"50166","300.96000","25.08022","0.01434"
"50223","301.30200","25.10873","0.01461"
"50280","301.64400","25.13720","0.01434"
"50337","301.98600","25.16571","0.01477"
"50394","302.32800","25.19417","0.01455"
"50451","302.67000","25.22269","0.01458"
"50508","303.01200","25.25121","0.01432"
"50565","303.35400","25.27973","0.01474"
"50622","303.69600","25.30825","0.01481"
"50679","304.03800","25.33671","0.01449"
"50736","304.38000","25.36517","0.01426"
"50793","304.72200","25.39369","0.01449"
"50850","305.06400","25.42215","0.01486"
"50907","305.40600","25.45073","0.01478"
"50964","305.74800","25.47919","0.01480"
"51021","306.09000","25.50771","0.01425"
"51078","306.43200","25.53617","0.01485"
"51135","306.77400","25.56469","0.01493"
"51192","307.11600","25.59315","0.01457"
"51249","307.45800","25.62173","0.01473"
"51306","307.80000","25.65025","0.01462"
"51363","308.14200","25.67871","0.01497"
"51420","308.48400","25.70723","0.01531"
"51477","308.82600","25.73569","0.01547"
"51534","309.16800","25.76421","0.01531"
"51591","309.51000","25.79273","0.01525"
"51648","309.85200","25.82113","0.01533"
"51705","310.19400","25.84970","0.01559"
"51762","310.53600","25.87823","0.01540"
"51819","310.87800","25.90663","0.01549"
"51876","311.22000","25.93521","0.01566"
"51933","311.56200","25.96373","0.01600"
"51990","311.90400","25.99219","0.01578"
"52047","312.24600","26.02076","0.01560"
"52104","312.58800","26.04917","0.01572"
"52161","312.93000","26.07768","0.01606"
"52218","313.27200","26.10626","0.01591"
"52275","313.61400","26.13466","0.01615"
"52332","313.95600","26.16318","0.01598"
"52389","314.29800","26.19170","0.01623"
"52446","314.64000","26.22016","0.01633"
"52503","314.98200","26.24874","0.01655"
"52560","315.32400","26.27714","0.01613"
"52617","315.66600","26.30566","0.01623"
"52674","316.00800","26.33424","0.01639"
"52731","316.35000","26.36270","0.01634"
"52788","316.69200","26.39122","0.01674"
"52845","317.03400","26.41974","0.01689"
"52902","317.37600","26.44808","0.01576"
"52959","317.71800","26.47672","0.01605"
"53016","318.06000","26.50524","0.01596"
"53073","318.40200","26.53364","0.01595"
"53130","318.74400","26.56222","0.01624"
"53187","319.08600","26.59068","0.01693"
"53244","319.42800","26.61920","0.01686"
"53301","319.77000","26.64772","0.01653"
"53358","320.11200","26.67618","0.01699"
"53415","320.45400","26.70475","0.01670"
"53472","320.79600","26.73328","0.01685"
"53529","321.13800","26.76167","0.01693"
"53586","321.48000","26.79019","0.01689"
"53643","321.82200","26.81871","0.01698"
"53700","322.16400","26.84718","0.01694"
"53757","322.50600","26.87569","0.01658"
"53814","322.84800","26.90421","0.01922"
"53871","323.19000","26.93273","0.00983"
"53928","323.53200","26.96119","0.01013"
"53985","323.87400","26.98971","0.01022"
"54042","324.21600","27.01817","0.01038"
"54099","324.55800","27.04669","0.01050"
"54156","324.90000","27.07521","0.01063"
"54213","325.24200","27.10367","0.01087"
"54270","325.58400","27.13225","0.01089"
"54327","325.92600","27.16071","0.01124"
"54384","326.26800","27.18923","0.01092"
"54441","326.61000","27.21769","0.01113"
"54498","326.95200","27.24615","0.01104"
"54555","327.29400","27.27473","0.01121"
"54612","327.63600","27.30319","0.01110"
"54669","327.97800","27.33165","0.01049"
"54726","328.32000","27.36023","0.01070"
"54783","328.66200","27.38863","0.01056"
"54840","329.00400","27.41721","0.01098"
"54897","329.34600","27.44567","0.01112"
"54954","329.68800","27.47425","0.01083"
"55011","330.03000","27.50271","0.01127"
"55068","330.37200","27.53117","0.01153"
"55125","330.71400","27.55969","0.01132"
"55182","331.05600","27.58827","0.01140"
"55239","331.39800","27.61667","0.01149"
"55296","331.74000","27.64519","0.01171"
"55353","332.08200","27.67377","0.01168"
"55410","332.42400","27.70211","0.01139"
"55467","332.76600","27.73074","0.01196"
"55524","333.10800","27.75920","0.01177"
"55581","333.45000","27.78766","0.01195"
"55638","333.79200","27.81624","0.01201"
"55695","334.13400","27.84470","0.01199"
"55752","334.47600","27.87316","0.01162"
"55809","334.81800","27.90174","0.01196"
"55866","335.16000","27.93014","0.01205"
"55923","335.50200","27.95878","0.01234"
"55980","335.84400","27.98724","0.01245"
"56037","336.18600","28.01570","0.01217"
"56094","336.52800","28.04422","0.01201"
"56151","336.87000","28.07268","0.01257"
"56208","337.21200","28.10120","0.01236"
"56265","337.55400","28.12972","0.01231"
"56322","337.89600","28.15818","0.01277"
"56379","338.23800","28.18670","0.01295"
"56436","338.58000","28.21516","0.01306"
"56493","338.92200","28.24362","0.01282"
"56550","339.26400","28.27226","0.01265"
"56607","339.60600","28.30072","0.01300"
"56664","339.94800","28.32918","0.01320"
"56721","340.29000","28.35770","0.01342"
"56778","340.63200","28.38622","0.01339"
"56835","340.97400","28.41468","0.01351"
"56892","341.31600","28.44326","0.01314"
"56949","341.65800","28.47172","0.01370"
"57006","342.00000","28.50018","0.01326"
"57063","342.34200","28.52869","0.01369"
"57120","342.68400","28.55716","0.01357"
"57177","343.02600","28.58568","0.01372"
"57234","343.36800","28.61419","0.01307"
"57291","343.71000","28.64266","0.01329"
"57348","344.05200","28.67123","0.01318"
"57405","344.39400","28.69975","0.01380"
"57462","344.73600","28.72821","0.01362"
"57519","345.07800","28.75673","0.01378"
"57576","345.42000","28.78519","0.01404"
"57633","345.76200","28.81365","0.01359"
"57690","346.10400","28.84223","0.01395"
"57747","346.44600","28.87069","0.01358"
"57804","346.78800","28.89921","0.01421"
"57861","347.13000","28.92773","0.01407"
"57918","347.47200","28.95613","0.01414"
"57975","347.81400","28.98471","0.01457"
"58032","348.15600","29.01323","0.01418"
"58089","348.49800","29.04169","0.01419"
"58146","348.84000","29.07027","0.01424"
"58203","349.18200","29.09873","0.01463"
"58260","349.52400","29.12719","0.01483"
"58317","349.86600","29.15577","0.01456"
"58374","350.20800","29.18417","0.01460"
"58431","350.55000","29.21269","0.01486"
"58488","350.89200","29.24121","0.01493"
"58545","351.23400","29.26967","0.01494"
"58602","351.57600","29.29825","0.01489"
"58659","351.91800","29.32671","0.01510"
"58716","352.26000","29.35517","0.01527"
"58773","352.60200","29.38369","0.01523"
"58830","352.94400","29.41215","0.01564"
"58887","353.28600","29.44073","0.01551"
"58944","353.62800","29.46919","0.01566"
"59001","353.97000","29.49765","0.01565"
"59058","354.31200","29.52622","0.01548"
"59115","354.65400","29.55474","0.01558"
"59172","354.99600","29.58320","0.01566"
"59229","355.33800","29.61172","0.01553"
"59286","355.68000","29.64018","0.01583"
"59343","356.02200","29.66870","0.01611"
"59400","356.36400","29.69722","0.01511"
"59457","356.70600","29.72568","0.01532"
"59514","357.04800","29.75426","0.01546"
"59571","357.39000","29.78272","0.01611"
"59628","357.73200","29.81112","0.01642"
"59685","358.07400","29.83970","0.01555"
"59742","358.41600","29.86822","0.01618"
"59799","358.75800","29.89668","0.01591"
"59856","359.10000","29.92520","0.01612"
"59913","359.44200","29.95372","0.01639"
"59970","359.78400","29.98218","0.01637"
"60027","360.12600","30.01070","0.01650"
"60084","360.46800","30.03916","0.01583"
"60141","360.81000","30.06768","0.01606"
"60198","361.15200","30.09620","0.01616"
"60255","361.49400","30.12466","0.01654"
"60312","361.83600","30.15324","0.01690"
"60369","362.17800","30.18170","0.01669"
"60426","362.52000","30.21016","0.01616"
"60483","362.86200","30.23874","0.01632"
"60540","363.20400","30.26720","0.01777"
"60597","363.54600","30.29565","0.01400"
"60654","363.88800","30.32424","0.01311"
"60711","364.23000","30.35270","0.01355"
"60768","364.57200","30.38121","0.01222"
"60825","364.91400","30.40980","0.01287"
"60882","365.25600","30.43814","0.01229"
"60939","365.59800","30.46671","0.01287"
"60996","365.94000","30.49517","0.01241"
"61053","366.28200","30.52369","0.01280"
"61110","366.62400","30.55221","0.01305"
"61167","366.96600","30.58067","0.01343"
"61224","367.30800","30.60913","0.01332"
"61281","367.65000","30.63777","0.01317"
"61338","367.99200","30.66617","0.01399"
"61395","368.33400","30.69469","0.01346"
"61452","368.67600","30.72327","0.01396"
"61509","369.01800","30.75161","0.01361"
"61566","369.36000","30.78025","0.01406"
"61623","369.70200","30.80871","0.01387"
"61680","370.04400","30.83717","0.01432"
"61737","370.38600","30.86575","0.01428"
"61794","370.72800","30.89415","0.01462"
"61851","371.07000","30.92267","0.01458"
"61908","371.41200","30.95125","0.01473"
"61965","371.75400","30.97965","0.01505"
"62022","372.09600","31.00823","0.01520"
"62079","372.43800","31.03669","0.01528"
"62136","372.78000","31.06515","0.01530"
"62193","373.12200","31.09373","0.01533"
"62250","373.46400","31.12218","0.01577"
"62307","373.80600","31.15065","0.01624"
"62364","374.14800","31.17923","0.01616"
"62421","374.49000","31.20769","0.01612"
"62478","374.83200","31.23621","0.01632"
"62535","375.17400","31.26472","0.01692"
"62592","375.51600","31.29312","0.01623"
"62649","375.85800","31.32170","0.01667"
"62706","376.20000","31.35022","0.01695"
"62763","376.54200","31.37868","0.01562"
"62820","376.88400","31.40726","0.01586"
"62877","377.22600","31.43572","0.01594"
"62934","377.56800","31.46418","0.01654"
"62991","377.91000","31.49270","0.01624"
"63048","378.25200","31.52122","0.01634"
"63105","378.59400","31.54968","0.01707"
"63162","378.93600","31.57820","0.01669"
"63219","379.27800","31.60666","0.01675"
"63276","379.62000","31.63518","0.01716"
"63333","379.96200","31.66376","0.01712"
"63390","380.30400","31.69222","0.01720"
"63447","380.64600","31.72074","0.01779"
"63504","380.98800","31.74914","0.01787"
"63561","381.33000","31.77766","0.01757"
"63618","381.67200","31.80618","0.01792"
"63675","382.01400","31.83470","0.01795"
"63732","382.35600","31.86322","0.01740"
"63789","382.69800","31.89174","0.01794"
"63846","383.04000","31.92019","0.01796"
"63903","383.38200","31.94866","0.01824"
"63960","383.72400","31.97724","0.01822"
"64017","384.06600","32.00570","0.01865"
"64074","384.40800","32.03421","0.01889"
"64131","384.75000","32.06268","0.01919"
"64188","385.09200","32.09119","0.01893"
"64245","385.43400","32.11971","0.01954"
"64302","385.77600","32.14817","0.01864"
"64359","386.11800","32.17669","0.01922"
"64416","386.46000","32.20521","0.01927"
"64473","386.80200","32.23367","0.01907"
"64530","387.14400","32.26225","0.01965"
"64587","387.48600","32.29077","0.01848"
"64644","387.82800","32.31917","0.01901"
"64701","388.17000","32.34775","0.01897"
"64758","388.51200","32.37615","0.01914"
"64815","388.85400","32.40467","0.01888"
"64872","389.19600","32.43325","0.01878"
"64929","389.53800","32.46165","0.01945"
"64986","389.88000","32.49023","0.01938"
"65043","390.22200","32.51875","0.01955"
"65100","390.56400","32.54715","0.01951"
"65157","390.90600","32.57573","0.02004"
"65214","391.24800","32.60419","0.02028"
"65271","391.59000","32.63271","0.02043"
"65328","391.93200","32.66123","0.02089"
"65385","392.27400","32.68969","0.02051"
"65442","392.61600","32.71815","0.02080"
"65499","392.95800","32.74673","0.02061"
"65556","393.30000","32.77518","0.02121"
"65613","393.64200","32.80371","0.02020"
"65670","393.98400","32.83223","0.02062"
"65727","394.32600","32.86063","0.02102"
"65784","394.66800","32.88921","0.02033"
"65841","395.01000","32.91772","0.02113"
"65898","395.35200","32.94619","0.02103"
"65955","395.69400","32.97470","0.02178"
"66012","396.03600","33.00322","0.02167"
"66069","396.37800","33.03168","0.02225"
"66126","396.72000","33.06020","0.02216"
"66183","397.06200","33.08872","0.02264"
"66240","397.40400","33.11718","0.02300"
"66297","397.74600","33.14570","0.02313"
"66354","398.08800","33.17416","0.02350"
"66411","398.43000","33.20274","0.02360"
"66468","398.77200","33.23120","0.02392"
"66525","399.11400","33.25966","0.02369"
"66582","399.45600","33.28818","0.02393"
"66639","399.79800","33.31676","0.02395"
"66696","400.14000","33.34516","0.02338"
"66753","400.48200","33.37374","0.02399"
"66810","400.82400","33.40220","0.02486"
"66867","401.16600","33.43060","0.02473"
"66924","401.50800","33.45924","0.02525"
"66981","401.85000","33.48770","0.02511"
"67038","402.19200","33.51622","0.02591"
"67095","402.53400","33.54474","0.02580"
"67152","402.87600","33.57314","0.02626"
"67209","403.21800","33.60172","0.02658"
"67266","403.56000","33.63018","0.02644"
"67323","403.90200","33.65864","0.02620"
"67380","404.24400","33.68727","0.02720"
"67437","404.58600","33.71568","0.02730"
"67494","404.92800","33.74420","0.02790"
"67551","405.27000","33.77271","0.02821"
"67608","405.61200","33.80117","0.02766"
"67665","405.95400","33.82976","0.02854"
"67722","406.29600","33.85822","0.02883"
"67779","406.63800","33.88662","0.02905"
"67836","406.98000","33.91526","0.02836"
"67893","407.32200","33.94371","0.02859"
"67950","407.66400","33.97223","0.02778"
"68007","408.00600","34.00076","0.02822"
"68064","408.34800","34.02915","0.02841"
"68121","408.69000","34.05773","0.02881"
"68178","409.03200","34.08619","0.02950"
"68235","409.37400","34.11471","0.02965"
"68292","409.71600","34.14317","0.03001"
"68349","410.05800","34.17169","0.02960"
"68406","410.40000","34.20021","0.02984"
"68463","410.74200","34.22873","0.03040"
"68520","411.08400","34.25719","0.03040"
"68577","411.42600","34.28571","0.03080"
"68634","411.76800","34.31417","0.03168"
"68691","412.11000","34.34269","0.03126"
"68748","412.45200","34.37121","0.03174"
"68805","412.79400","34.39973","0.03142"
"68862","413.13600","34.42813","0.03153"
"68919","413.47800","34.45671","0.03145"
"68976","413.82000","34.48517","0.03230"
"69033","414.16200","34.51369","0.03279"
"69090","414.50400","34.54221","0.03337"
"69147","414.84600","34.57067","0.03404"
"69204","415.18800","34.59919","0.03409"
"69261","415.53000","34.62770","0.03495"
"69318","415.87200","34.65623","0.03449"
"69375","416.21400","34.68468","0.03458"
"69432","416.55600","34.71320","0.03504"
"69489","416.89800","34.74166","0.03549"
"69546","417.24000","34.77018","0.03592"
"69603","417.58200","34.79870","0.03623"
"69660","417.92400","34.82716","0.03641"
"69717","418.26600","34.85574","0.03655"
"69774","418.60800","34.88420","0.03706"
"69831","418.95000","34.91267","0.03735"
"69888","419.29200","34.94118","0.03820"
"69945","419.63400","34.96964","0.03826"
"70002","419.97600","34.99822","0.03887"
"70059","420.31800","35.02680","0.03926"
"70116","420.66000","35.05514","0.03958"
"70173","421.00200","35.08378","0.03954"
"70230","421.34400","35.11218","0.03996"
"70287","421.68600","35.14070","0.04088"
"70294","421.72800","35.14417","0.04058"