File: Trajectories_together/161226_1Specimen_RawData_2.csv
"","V1","V2","V3"
"1","End date","12/26/2016",""
"2","Specimen label","15DT_23",""
"3","Maximum Load","0.28588","N"
"4","Time","Extension","Load"
"5","(s)","(mm)","(N)"
"6","0.00000","0.00000","-0.00035"
"62","0.33600","0.02798","-0.00018"
"118","0.67200","0.05620","-0.00010"
"174","1.00800","0.08424","-0.00021"
"230","1.34400","0.11228","0.00028"
"286","1.68000","0.14015","0.00044"
"342","2.01600","0.16825","0.00003"
"398","2.35200","0.19617","-0.00094"
"454","2.68800","0.22409","-0.00063"
"510","3.02400","0.25219","-0.00010"
"566","3.36000","0.28017","0.00010"
"622","3.69600","0.30822","0.00028"
"678","4.03200","0.33626","0.00001"
"734","4.36800","0.36412","-0.00068"
"790","4.70400","0.39222","-0.00023"
"846","5.04000","0.42020","0.00022"
"902","5.37600","0.44818","0.00058"
"958","5.71200","0.47622","0.00010"
"1014","6.04800","0.50421","0.00036"
"1070","6.38400","0.53219","0.00090"
"1126","6.72000","0.56017","0.00032"
"1182","7.05600","0.58815","0.00123"
"1238","7.39200","0.61619","0.00109"
"1294","7.72800","0.64417","0.00144"
"1350","8.06400","0.67221","0.00162"
"1406","8.40000","0.70020","0.00194"
"1462","8.73600","0.72818","0.00183"
"1518","9.07200","0.75622","0.00225"
"1574","9.40800","0.78426","0.00218"
"1630","9.74400","0.81212","0.00217"
"1686","10.08000","0.84022","0.00147"
"1742","10.41600","0.86814","0.00215"
"1798","10.75200","0.89613","0.00193"
"1854","11.08800","0.92417","0.00188"
"1910","11.42400","0.95221","0.00221"
"1966","11.76000","0.98019","0.00238"
"2022","12.09600","1.00829","0.00189"
"2078","12.43200","1.03609","0.00248"
"2134","12.76800","1.06419","0.00222"
"2190","13.10400","1.09224","0.00209"
"2246","13.44000","1.12016","0.00268"
"2302","13.77600","1.14820","0.00225"
"2358","14.11200","1.17618","0.00237"
"2414","14.44800","1.20416","0.00228"
"2470","14.78400","1.23220","0.00274"
"2526","15.12000","1.26012","0.00264"
"2582","15.45600","1.28817","0.00297"
"2638","15.79200","1.31615","0.00239"
"2694","16.12800","1.34419","0.00281"
"2750","16.46400","1.37223","0.00263"
"2806","16.80000","1.40021","0.00263"
"2862","17.13600","1.42819","0.00280"
"2918","17.47200","1.45617","0.00278"
"2974","17.80800","1.48416","0.00290"
"3030","18.14400","1.51214","0.00253"
"3086","18.48000","1.54018","0.00306"
"3142","18.81600","1.56816","0.00257"
"3198","19.15200","1.59620","0.00300"
"3254","19.48800","1.62418","0.00360"
"3310","19.82400","1.65222","0.00342"
"3366","20.16000","1.68027","0.00300"
"3422","20.49600","1.70813","0.00290"
"3478","20.83200","1.73623","0.00319"
"3534","21.16800","1.76421","0.00283"
"3590","21.50400","1.79219","0.00294"
"3646","21.84000","1.82023","0.00288"
"3702","22.17600","1.84821","0.00246"
"3758","22.51200","1.87620","0.00344"
"3814","22.84800","1.90424","0.00281"
"3870","23.18400","1.93216","0.00270"
"3926","23.52000","1.96020","0.00321"
"3982","23.85600","1.98824","0.00330"
"4038","24.19200","2.01622","0.00338"
"4094","24.52800","2.04420","0.00262"
"4150","24.86400","2.07225","0.00313"
"4206","25.20000","2.10017","0.00282"
"4262","25.53600","2.12821","0.00274"
"4318","25.87200","2.15619","0.00289"
"4374","26.20800","2.18423","0.00288"
"4430","26.54400","2.21221","0.00324"
"4486","26.88000","2.24019","0.00270"
"4542","27.21600","2.26824","0.00250"
"4598","27.55200","2.29616","0.00271"
"4654","27.88800","2.32420","0.00239"
"4710","28.22400","2.35218","0.00323"
"4766","28.56000","2.38010","0.00237"
"4822","28.89600","2.40820","0.00271"
"4878","29.23200","2.43618","0.00226"
"4934","29.56800","2.46417","0.00301"
"4990","29.90400","2.49221","0.00307"
"5046","30.24000","2.52013","0.00273"
"5102","30.57600","2.54817","0.00284"
"5158","30.91200","2.57627","0.00308"
"5214","31.24800","2.60413","0.00243"
"5270","31.58400","2.63223","0.00297"
"5326","31.92000","2.66016","0.00258"
"5382","32.25600","2.68820","0.00306"
"5438","32.59200","2.71624","0.00318"
"5494","32.92800","2.74416","0.00264"
"5550","33.26400","2.77214","0.00328"
"5606","33.60000","2.80024","0.00305"
"5662","33.93600","2.82816","0.00335"
"5718","34.27200","2.85621","0.00186"
"5774","34.60800","2.88419","0.00276"
"5830","34.94400","2.91217","0.00245"
"5886","35.28000","2.94015","0.00230"
"5942","35.61600","2.96819","0.00244"
"5998","35.95200","2.99623","0.00312"
"6054","36.28800","3.02421","0.00273"
"6110","36.62400","3.05220","0.00351"
"6166","36.96000","3.08024","0.00303"
"6222","37.29600","3.10822","0.00293"
"6278","37.63200","3.13620","0.00250"
"6334","37.96800","3.16418","0.00272"
"6390","38.30400","3.19216","0.00243"
"6446","38.64000","3.22020","0.00306"
"6502","38.97600","3.24825","0.00257"
"6558","39.31200","3.27617","0.00277"
"6614","39.64800","3.30421","0.00310"
"6670","39.98400","3.33219","0.00279"
"6726","40.32000","3.36017","0.00263"
"6782","40.65600","3.38821","0.00321"
"6838","40.99200","3.41614","0.00328"
"6894","41.32800","3.44418","0.00295"
"6950","41.66400","3.47222","0.00251"
"7006","42.00000","3.50014","0.00277"
"7062","42.33600","3.52824","0.00277"
"7118","42.67200","3.55616","0.00182"
"7174","43.00800","3.58414","0.00227"
"7230","43.34400","3.61218","0.00254"
"7286","43.68000","3.64017","0.00231"
"7342","44.01600","3.66821","0.00270"
"7398","44.35200","3.69625","0.00255"
"7454","44.68800","3.72417","0.00211"
"7510","45.02400","3.75221","0.00253"
"7566","45.36000","3.78019","0.00286"
"7622","45.69600","3.80817","0.00284"
"7678","46.03200","3.83616","0.00233"
"7734","46.36800","3.86414","0.00204"
"7790","46.70400","3.89224","0.00255"
"7846","47.04000","3.92022","0.00300"
"7902","47.37600","3.94814","0.00268"
"7958","47.71200","3.97624","0.00245"
"8014","48.04800","4.00416","0.00244"
"8070","48.38400","4.03221","0.00233"
"8126","48.72000","4.06019","0.00255"
"8182","49.05600","4.08811","0.00239"
"8238","49.39200","4.11627","0.00253"
"8294","49.72800","4.14425","0.00300"
"8350","50.06400","4.17217","0.00312"
"8406","50.40000","4.20021","0.00289"
"8462","50.73600","4.22814","0.00317"
"8518","51.07200","4.25618","0.00277"
"8574","51.40800","4.28422","0.00280"
"8630","51.74400","4.31214","0.00230"
"8686","52.08000","4.34018","0.00250"
"8742","52.41600","4.36828","0.00284"
"8798","52.75200","4.39620","0.00312"
"8854","53.08800","4.42425","0.00267"
"8910","53.42400","4.45217","0.00288"
"8966","53.76000","4.48015","0.00319"
"9022","54.09600","4.50819","0.00283"
"9078","54.43200","4.53617","0.00287"
"9134","54.76800","4.56421","0.00317"
"9190","55.10400","4.59225","0.00322"
"9246","55.44000","4.62012","0.00304"
"9302","55.77600","4.64822","0.00309"
"9358","56.11200","4.67620","0.00293"
"9414","56.44800","4.70418","0.00329"
"9470","56.78400","4.73216","0.00295"
"9526","57.12000","4.76020","0.00314"
"9582","57.45600","4.78824","0.00290"
"9638","57.79200","4.81623","0.00297"
"9694","58.12800","4.84421","0.00339"
"9750","58.46400","4.87225","0.00295"
"9806","58.80000","4.90017","0.00321"
"9862","59.13600","4.92815","0.00333"
"9918","59.47200","4.95625","0.00305"
"9974","59.80800","4.98412","0.00352"
"10030","60.14400","5.01222","0.00392"
"10086","60.48000","5.04020","0.00352"
"10142","60.81600","5.06818","0.00393"
"10198","61.15200","5.09622","0.00380"
"10254","61.48800","5.12414","0.00338"
"10310","61.82400","5.15212","0.00409"
"10366","62.16000","5.18028","0.00360"
"10422","62.49600","5.20821","0.00399"
"10478","62.83200","5.23625","0.00389"
"10534","63.16800","5.26423","0.00428"
"10590","63.50400","5.29215","0.00424"
"10646","63.84000","5.32019","0.00452"
"10702","64.17600","5.34817","0.00431"
"10758","64.51200","5.37616","0.00466"
"10814","64.84800","5.40420","0.00425"
"10870","65.18400","5.43224","0.00378"
"10926","65.52000","5.46022","0.00444"
"10982","65.85600","5.48820","0.00496"
"11038","66.19200","5.51612","0.00427"
"11094","66.52800","5.54422","0.00423"
"11150","66.86400","5.57215","0.00456"
"11206","67.20000","5.60019","0.00451"
"11262","67.53600","5.62817","0.00459"
"11318","67.87200","5.65615","0.00425"
"11374","68.20800","5.68419","0.00458"
"11430","68.54400","5.71217","0.00470"
"11486","68.88000","5.74021","0.00476"
"11542","69.21600","5.76826","0.00470"
"11598","69.55200","5.79618","0.00432"
"11654","69.88800","5.82416","0.00493"
"11710","70.22400","5.85220","0.00500"
"11766","70.56000","5.88018","0.00441"
"11822","70.89600","5.90822","0.00491"
"11878","71.23200","5.93620","0.00465"
"11934","71.56800","5.96419","0.00509"
"11990","71.90400","5.99223","0.00475"
"12046","72.24000","6.02021","0.00471"
"12102","72.57600","6.04819","0.00465"
"12158","72.91200","6.07629","0.00524"
"12214","73.24800","6.10415","0.00502"
"12270","73.58400","6.13219","0.00458"
"12326","73.92000","6.16024","0.00487"
"12382","74.25600","6.18816","0.00417"
"12438","74.59200","6.21626","0.00487"
"12494","74.92800","6.24418","0.00520"
"12550","75.26400","6.27216","0.00501"
"12606","75.60000","6.30020","0.00556"
"12662","75.93600","6.32812","0.00534"
"12718","76.27200","6.35617","0.00572"
"12774","76.60800","6.38421","0.00515"
"12830","76.94400","6.41219","0.00552"
"12886","77.28000","6.44017","0.00560"
"12942","77.61600","6.46821","0.00587"
"12998","77.95200","6.49625","0.00564"
"13054","78.28800","6.52423","0.00537"
"13110","78.62400","6.55216","0.00562"
"13166","78.96000","6.58020","0.00598"
"13222","79.29600","6.60824","0.00584"
"13278","79.63200","6.63616","0.00591"
"13334","79.96800","6.66420","0.00540"
"13390","80.30400","6.69218","0.00562"
"13446","80.64000","6.72016","0.00527"
"13502","80.97600","6.74827","0.00567"
"13558","81.31200","6.77613","0.00576"
"13614","81.64800","6.80423","0.00543"
"13670","81.98400","6.83221","0.00632"
"13726","82.32000","6.86019","0.00601"
"13782","82.65600","6.88823","0.00582"
"13838","82.99200","6.91621","0.00578"
"13894","83.32800","6.94420","0.00604"
"13950","83.66400","6.97224","0.00631"
"14006","84.00000","7.00016","0.00644"
"14062","84.33600","7.02820","0.00629"
"14118","84.67200","7.05624","0.00629"
"14174","85.00800","7.08416","0.00666"
"14230","85.34400","7.11220","0.00684"
"14286","85.68000","7.14019","0.00690"
"14342","86.01600","7.16817","0.00704"
"14398","86.35200","7.19621","0.00682"
"14454","86.68800","7.22419","0.00663"
"14510","87.02400","7.25217","0.00717"
"14566","87.36000","7.28021","0.00720"
"14622","87.69600","7.30819","0.00738"
"14678","88.03200","7.33624","0.00786"
"14734","88.36800","7.36416","0.00750"
"14790","88.70400","7.39220","0.00741"
"14846","89.04000","7.42024","0.00788"
"14902","89.37600","7.44810","0.00796"
"14958","89.71200","7.47626","0.00771"
"15014","90.04800","7.50424","0.00799"
"15070","90.38400","7.53217","0.00841"
"15126","90.72000","7.56027","0.00812"
"15182","91.05600","7.58819","0.00853"
"15238","91.39200","7.61617","0.00856"
"15294","91.72800","7.64421","0.00780"
"15350","92.06400","7.67213","0.00822"
"15406","92.40000","7.70023","0.00828"
"15462","92.73600","7.72822","0.00833"
"15518","93.07200","7.75620","0.00865"
"15574","93.40800","7.78418","0.00907"
"15630","93.74400","7.81216","0.00756"
"15686","94.08000","7.84020","0.00720"
"15742","94.41600","7.86818","0.00754"
"15798","94.75200","7.89616","0.00762"
"15854","95.08800","7.92421","0.00763"
"15910","95.42400","7.95219","0.00836"
"15966","95.76000","7.98023","0.00849"
"16022","96.09600","8.00821","0.00895"
"16078","96.43200","8.03619","0.00909"
"16134","96.76800","8.06417","0.00950"
"16190","97.10400","8.09221","0.00962"
"16246","97.44000","8.12014","0.00994"
"16302","97.77600","8.14824","0.00852"
"16358","98.11200","8.17616","0.00855"
"16414","98.44800","8.20414","0.00925"
"16470","98.78400","8.23218","0.00895"
"16526","99.12000","8.26016","0.00923"
"16582","99.45600","8.28820","0.00973"
"16638","99.79200","8.31625","0.00968"
"16694","100.12800","8.34411","0.01014"
"16750","100.46400","8.37221","0.00959"
"16806","100.80000","8.40025","0.00790"
"16862","101.13600","8.42817","0.00845"
"16918","101.47200","8.45627","0.00877"
"16974","101.80800","8.48413","0.00914"
"17030","102.14400","8.51218","0.00920"
"17086","102.48000","8.54022","0.00891"
"17142","102.81600","8.56814","0.00949"
"17198","103.15200","8.59618","0.00945"
"17254","103.48800","8.62422","0.00959"
"17310","103.82400","8.65220","0.01012"
"17366","104.16000","8.68024","0.01033"
"17422","104.49600","8.70811","0.00981"
"17478","104.83200","8.73615","0.00973"
"17534","105.16800","8.76419","0.00998"
"17590","105.50400","8.79217","0.01018"
"17646","105.84000","8.82027","0.00973"
"17702","106.17600","8.84819","0.00982"
"17758","106.51200","8.87617","0.00999"
"17814","106.84800","8.90422","0.01042"
"17870","107.18400","8.93214","0.01033"
"17926","107.52000","8.96018","0.01098"
"17982","107.85600","8.98822","0.01069"
"18038","108.19200","9.01614","0.01051"
"18094","108.52800","9.04424","0.01070"
"18150","108.86400","9.07216","0.01102"
"18206","109.20000","9.10015","0.01149"
"18262","109.53600","9.12825","0.01158"
"18318","109.87200","9.15617","0.01136"
"18374","110.20800","9.18421","0.01172"
"18430","110.54400","9.21219","0.01195"
"18486","110.88000","9.24011","0.01224"
"18542","111.21600","9.26822","0.01100"
"18598","111.55200","9.29620","0.01163"
"18654","111.88800","9.32418","0.01236"
"18710","112.22400","9.35222","0.01246"
"18766","112.56000","9.38020","0.01229"
"18822","112.89600","9.40812","0.01229"
"18878","113.23200","9.43622","0.01307"
"18934","113.56800","9.46420","0.01335"
"18990","113.90400","9.49225","0.01328"
"19046","114.24000","9.52023","0.01399"
"19102","114.57600","9.54821","0.01414"
"19158","114.91200","9.57619","0.01238"
"19214","115.24800","9.60417","0.01205"
"19270","115.58400","9.63221","0.01234"
"19326","115.92000","9.66026","0.01314"
"19382","116.25600","9.68818","0.01372"
"19438","116.59200","9.71622","0.01388"
"19494","116.92800","9.74414","0.01416"
"19550","117.26400","9.77218","0.01470"
"19606","117.60000","9.80022","0.01536"
"19662","117.93600","9.82814","0.01645"
"19718","118.27200","9.85624","0.01673"
"19774","118.60800","9.88422","0.01658"
"19830","118.94400","9.91215","0.01735"
"19886","119.28000","9.94019","0.01672"
"19942","119.61600","9.96817","0.01647"
"19998","119.95200","9.99621","0.01529"
"20054","120.28800","10.02425","0.01605"
"20110","120.62400","10.05218","0.01658"
"20166","120.96000","10.08022","0.01737"
"20222","121.29600","10.10826","0.01793"
"20278","121.63200","10.13612","0.01912"
"20334","121.96800","10.16422","0.01959"
"20390","122.30400","10.19220","0.02064"
"20446","122.64000","10.22018","0.02226"
"20502","122.97600","10.24823","0.02298"
"20558","123.31200","10.27621","0.02366"
"20614","123.64800","10.30419","0.02424"
"20670","123.98400","10.33223","0.02511"
"20726","124.32000","10.36015","0.02614"
"20782","124.65600","10.38825","0.02622"
"20838","124.99200","10.41617","0.02765"
"20894","125.32800","10.44415","0.02892"
"20950","125.66400","10.47220","0.02989"
"21006","126.00000","10.50018","0.03117"
"21062","126.33600","10.52822","0.03279"
"21118","126.67200","10.55620","0.03375"
"21174","127.00800","10.58418","0.03544"
"21230","127.34400","10.61222","0.03720"
"21286","127.68000","10.64020","0.03891"
"21342","128.01600","10.66819","0.04104"
"21398","128.35200","10.69623","0.04198"
"21454","128.68800","10.72415","0.04355"
"21510","129.02400","10.75225","0.04446"
"21566","129.36000","10.78023","0.04582"
"21622","129.69600","10.80815","0.04696"
"21678","130.03200","10.83619","0.04740"
"21734","130.36800","10.86418","0.04865"
"21790","130.70400","10.89210","0.05015"
"21846","131.04000","10.92026","0.05169"
"21902","131.37600","10.94818","0.05331"
"21958","131.71200","10.97622","0.05287"
"22014","132.04800","11.00426","0.05226"
"22070","132.38400","11.03213","0.01507"
"22126","132.72000","11.06023","0.01039"
"22182","133.05600","11.08821","0.01141"
"22238","133.39200","11.11619","0.01193"
"22294","133.72800","11.14423","0.01116"
"22350","134.06400","11.17221","0.01196"
"22406","134.40000","11.20019","0.01276"
"22462","134.73600","11.22818","0.01244"
"22518","135.07200","11.25616","0.01341"
"22574","135.40800","11.28420","0.01350"
"22630","135.74400","11.31218","0.01413"
"22686","136.08000","11.34022","0.01493"
"22742","136.41600","11.36820","0.01523"
"22798","136.75200","11.39612","0.01544"
"22854","137.08800","11.42423","0.01667"
"22910","137.42400","11.45221","0.01657"
"22966","137.76000","11.48019","0.01751"
"23022","138.09600","11.50823","0.01796"
"23078","138.43200","11.53615","0.01875"
"23134","138.76800","11.56413","0.01872"
"23190","139.10400","11.59223","0.01959"
"23246","139.44000","11.62015","0.02069"
"23302","139.77600","11.64820","0.02069"
"23358","140.11200","11.67624","0.02138"
"23414","140.44800","11.70422","0.02188"
"23470","140.78400","11.73220","0.02251"
"23526","141.12000","11.76018","0.02303"
"23582","141.45600","11.78816","0.02383"
"23638","141.79200","11.81627","0.02374"
"23694","142.12800","11.84413","0.02488"
"23750","142.46400","11.87217","0.02596"
"23806","142.80000","11.90015","0.02656"
"23862","143.13600","11.92813","0.02701"
"23918","143.47200","11.95617","0.02766"
"23974","143.80800","11.98421","0.02846"
"24030","144.14400","12.01219","0.02938"
"24086","144.48000","12.04018","0.02936"
"24142","144.81600","12.06816","0.03035"
"24198","145.15200","12.09620","0.03106"
"24254","145.48800","12.12418","0.03089"
"24310","145.82400","12.15222","0.03200"
"24366","146.16000","12.18020","0.03398"
"24422","146.49600","12.20813","0.03308"
"24478","146.83200","12.23623","0.03508"
"24534","147.16800","12.26421","0.03626"
"24590","147.50400","12.29213","0.03700"
"24646","147.84000","12.32017","0.03786"
"24702","148.17600","12.34821","0.03948"
"24758","148.51200","12.37613","0.04011"
"24814","148.84800","12.40423","0.04110"
"24870","149.18400","12.43222","0.04051"
"24926","149.52000","12.46014","0.04175"
"24982","149.85600","12.48824","0.04251"
"25038","150.19200","12.51610","0.04382"
"25094","150.52800","12.54420","0.04466"
"25150","150.86400","12.57224","0.04551"
"25206","151.20000","12.60017","0.04569"
"25262","151.53600","12.62827","0.04663"
"25318","151.87200","12.65619","0.04783"
"25374","152.20800","12.68423","0.04828"
"25430","152.54400","12.71227","0.04882"
"25486","152.88000","12.74019","0.05023"
"25542","153.21600","12.76824","0.05121"
"25598","153.55200","12.79622","0.05203"
"25654","153.88800","12.82414","0.05312"
"25710","154.22400","12.85218","0.05430"
"25766","154.56000","12.88022","0.05509"
"25822","154.89600","12.90820","0.05615"
"25878","155.23200","12.93618","0.05637"
"25934","155.56800","12.96410","0.05718"
"25990","155.90400","12.99215","0.05785"
"26046","156.24000","13.02019","0.05601"
"26102","156.57600","13.04817","0.05680"
"26158","156.91200","13.07621","0.05864"
"26214","157.24800","13.10419","0.05876"
"26270","157.58400","13.13223","0.05959"
"26326","157.92000","13.16021","0.06141"
"26382","158.25600","13.18808","0.06304"
"26438","158.59200","13.21624","0.06426"
"26494","158.92800","13.24422","0.06547"
"26550","159.26400","13.27214","0.06620"
"26606","159.60000","13.30024","0.06826"
"26662","159.93600","13.32822","0.06966"
"26718","160.27200","13.35614","0.07073"
"26774","160.60800","13.38425","0.07216"
"26830","160.94400","13.41211","0.07502"
"26886","161.28000","13.44021","0.07647"
"26942","161.61600","13.46819","0.07831"
"26998","161.95200","13.49617","0.07971"
"27054","162.28800","13.52415","0.08150"
"27110","162.62400","13.55220","0.08358"
"27166","162.96000","13.58018","0.08491"
"27222","163.29600","13.60822","0.08607"
"27278","163.63200","13.63614","0.08804"
"27334","163.96800","13.66424","0.08916"
"27390","164.30400","13.69222","0.09087"
"27446","164.64000","13.72014","0.09200"
"27502","164.97600","13.74819","0.09329"
"27558","165.31200","13.77623","0.09391"
"27614","165.64800","13.80421","0.09539"
"27670","165.98400","13.83219","0.09569"
"27726","166.32000","13.86017","0.09667"
"27782","166.65600","13.88821","0.09776"
"27838","166.99200","13.91619","0.09853"
"27894","167.32800","13.94417","0.09878"
"27950","167.66400","13.97222","0.09949"
"28006","168.00000","14.00014","0.10004"
"28062","168.33600","14.02818","0.10063"
"28118","168.67200","14.05622","0.10150"
"28174","169.00800","14.08414","0.10183"
"28230","169.34400","14.11230","0.10232"
"28286","169.68000","14.14016","0.10298"
"28342","170.01600","14.16815","0.10373"
"28398","170.35200","14.19625","0.10447"
"28454","170.68800","14.22417","0.10522"
"28510","171.02400","14.25221","0.10600"
"28566","171.36000","14.28025","0.10662"
"28622","171.69600","14.30817","0.10768"
"28678","172.03200","14.33616","0.10898"
"28734","172.36800","14.36420","0.10997"
"28790","172.70400","14.39218","0.11162"
"28846","173.04000","14.42016","0.11256"
"28902","173.37600","14.44820","0.11417"
"28958","173.71200","14.47618","0.11593"
"29014","174.04800","14.50416","0.11760"
"29070","174.38400","14.53220","0.11987"
"29126","174.72000","14.56025","0.12161"
"29182","175.05600","14.58823","0.12372"
"29238","175.39200","14.61621","0.12535"
"29294","175.72800","14.64419","0.12863"
"29350","176.06400","14.67217","0.13105"
"29406","176.40000","14.70021","0.13317"
"29462","176.73600","14.72826","0.13713"
"29518","177.07200","14.75618","0.14054"
"29574","177.40800","14.78422","0.14278"
"29630","177.74400","14.81220","0.14649"
"29686","178.08000","14.84018","0.14840"
"29742","178.41600","14.86822","0.15030"
"29798","178.75200","14.89614","0.15267"
"29854","179.08800","14.92424","0.15532"
"29910","179.42400","14.95223","0.15567"
"29966","179.76000","14.98015","0.15566"
"30022","180.09600","15.00819","0.15782"
"30078","180.43200","15.03623","0.15916"
"30134","180.76800","15.06421","0.16044"
"30190","181.10400","15.09219","0.16221"
"30246","181.44000","15.12018","0.16415"
"30302","181.77600","15.14816","0.16604"
"30358","182.11200","15.17626","0.16711"
"30414","182.44800","15.20418","0.16871"
"30470","182.78400","15.23222","0.17049"
"30526","183.12000","15.26020","0.17206"
"30582","183.45600","15.28818","0.17393"
"30638","183.79200","15.31617","0.17603"
"30694","184.12800","15.34415","0.17794"
"30750","184.46400","15.37219","0.18075"
"30806","184.80000","15.40023","0.18296"
"30862","185.13600","15.42821","0.18614"
"30918","185.47200","15.45625","0.18765"
"30974","185.80800","15.48417","0.18919"
"31030","186.14400","15.51216","0.19202"
"31086","186.48000","15.54020","0.19373"
"31142","186.81600","15.56812","0.19555"
"31198","187.15200","15.59628","0.19787"
"31254","187.48800","15.62420","0.19928"
"31310","187.82400","15.65218","0.20096"
"31366","188.16000","15.68022","0.20231"
"31422","188.49600","15.70820","0.20385"
"31478","188.83200","15.73619","0.20517"
"31534","189.16800","15.76423","0.20628"
"31590","189.50400","15.79215","0.20756"
"31646","189.84000","15.82019","0.20901"
"31702","190.17600","15.84829","0.21024"
"31758","190.51200","15.87615","0.21171"
"31814","190.84800","15.90420","0.21279"
"31870","191.18400","15.93218","0.21359"
"31926","191.52000","15.96016","0.21504"
"31982","191.85600","15.98820","0.21668"
"32038","192.19200","16.01618","0.21831"
"32094","192.52800","16.04416","0.22115"
"32150","192.86400","16.07226","0.22324"
"32206","193.20000","16.10019","0.22547"
"32262","193.53600","16.12829","0.22726"
"32318","193.87200","16.15615","0.22930"
"32374","194.20800","16.18419","0.23116"
"32430","194.54400","16.21217","0.23296"
"32486","194.88000","16.24015","0.23473"
"32542","195.21600","16.26825","0.23775"
"32598","195.55200","16.29618","0.23980"
"32654","195.88800","16.32416","0.24222"
"32710","196.22400","16.35226","0.24418"
"32766","196.56000","16.38018","0.24608"
"32822","196.89600","16.40816","0.24838"
"32878","197.23200","16.43620","0.24999"
"32934","197.56800","16.46412","0.25268"
"32990","197.90400","16.49223","0.25364"
"33046","198.24000","16.52021","0.25586"
"33102","198.57600","16.54813","0.25698"
"33158","198.91200","16.57617","0.25881"
"33214","199.24800","16.60415","0.26125"
"33270","199.58400","16.63213","0.26331"
"33326","199.92000","16.66023","0.26494"
"33382","200.25600","16.68815","0.26759"
"33438","200.59200","16.71620","0.27058"
"33494","200.92800","16.74424","0.27216"
"33550","201.26400","16.77216","0.27583"
"33606","201.60000","16.80020","0.27806"
"33662","201.93600","16.82818","0.28175"
"33718","202.27200","16.85616","0.28540"
"33774","202.60800","16.88421","0.19677"
"33830","202.94400","16.91219","0.09041"
"33886","203.28000","16.94023","0.08453"
"33942","203.61600","16.96821","0.08997"
"33998","203.95200","16.99619","0.08809"
"34054","204.28800","17.02423","0.08792"
"34110","204.62400","17.05215","0.09199"
"34166","204.96000","17.08014","0.08476"
"34222","205.29600","17.10818","0.08932"
"34278","205.63200","17.13616","0.09120"
"34334","205.96800","17.16426","0.08518"
"34390","206.30400","17.19218","0.09332"
"34446","206.64000","17.22016","0.09039"
"34502","206.97600","17.24820","0.08814"
"34558","207.31200","17.27612","0.09365"
"34614","207.64800","17.30417","0.09178"
"34670","207.98400","17.33221","0.09253"
"34726","208.32000","17.36013","0.09280"
"34782","208.65600","17.38823","0.09212"
"34838","208.99200","17.41621","0.09692"
"34894","209.32800","17.44413","0.09274"
"34950","209.66400","17.47223","0.09260"
"35006","210.00000","17.50016","0.09749"
"35062","210.33600","17.52820","0.09446"
"35118","210.67200","17.55624","0.09570"
"35174","211.00800","17.58410","0.09668"
"35230","211.34400","17.61220","0.09571"
"35286","211.68000","17.64018","0.09785"
"35342","212.01600","17.66811","0.09599"
"35398","212.35200","17.69621","0.09575"
"35454","212.68800","17.72419","0.09939"
"35510","213.02400","17.75217","0.09670"
"35566","213.36000","17.78021","0.09675"
"35622","213.69600","17.80819","0.09899"
"35678","214.03200","17.83617","0.09803"
"35734","214.36800","17.86416","0.09884"
"35790","214.70400","17.89220","0.09879"
"35846","215.04000","17.92018","0.09877"
"35902","215.37600","17.94816","0.10063"
"35958","215.71200","17.97626","0.09907"
"36014","216.04800","18.00418","0.09882"
"36070","216.38400","18.03217","0.10165"
"36126","216.72000","18.06021","0.10041"
"36182","217.05600","18.08819","0.10031"
"36238","217.39200","18.11617","0.10156"
"36294","217.72800","18.14421","0.10062"
"36350","218.06400","18.17219","0.10153"
"36406","218.40000","18.20017","0.10225"
"36462","218.73600","18.22821","0.10116"
"36518","219.07200","18.25607","0.10247"
"36574","219.40800","18.28418","0.10250"
"36630","219.74400","18.31222","0.10145"
"36686","220.08000","18.34020","0.10325"
"36742","220.41600","18.36824","0.10288"
"36798","220.75200","18.39616","0.10260"
"36854","221.08800","18.42420","0.10413"
"36910","221.42400","18.45225","0.10320"
"36966","221.76000","18.48017","0.10366"
"37022","222.09600","18.50821","0.10544"
"37078","222.43200","18.53619","0.10358"
"37134","222.76800","18.56417","0.10393"
"37190","223.10400","18.59221","0.10604"
"37246","223.44000","18.62020","0.10471"
"37302","223.77600","18.64824","0.10482"
"37358","224.11200","18.67628","0.10631"
"37414","224.44800","18.70414","0.10491"
"37470","224.78400","18.73218","0.10621"
"37526","225.12000","18.76016","0.10754"
"37582","225.45600","18.78820","0.10599"
"37638","225.79200","18.81618","0.10650"
"37694","226.12800","18.84417","0.10910"
"37750","226.46400","18.87227","0.10763"
"37806","226.80000","18.90019","0.10815"
"37862","227.13600","18.92811","0.10918"
"37918","227.47200","18.95627","0.10808"
"37974","227.80800","18.98419","0.10966"
"38030","228.14400","19.01217","0.11066"
"38086","228.48000","19.04028","0.10851"
"38142","228.81600","19.06814","0.11017"
"38198","229.15200","19.09618","0.11204"
"38254","229.48800","19.12422","0.11024"
"38310","229.82400","19.15214","0.11137"
"38366","230.16000","19.18018","0.11356"
"38422","230.49600","19.20823","0.11150"
"38478","230.83200","19.23621","0.11386"
"38534","231.16800","19.26419","0.11500"
"38590","231.50400","19.29223","0.11318"
"38646","231.84000","19.32021","0.11394"
"38702","232.17600","19.34819","0.11671"
"38758","232.51200","19.37617","0.11508"
"38814","232.84800","19.40415","0.11607"
"38870","233.18400","19.43220","0.11801"
"38926","233.52000","19.46012","0.11647"
"38982","233.85600","19.48822","0.11796"
"39038","234.19200","19.51620","0.12013"
"39094","234.52800","19.54418","0.11768"
"39150","234.86400","19.57216","0.11834"
"39206","235.20000","19.60015","0.12153"
"39262","235.53600","19.62818","0.11949"
"39318","235.87200","19.65623","0.11983"
"39374","236.20800","19.68421","0.12303"
"39430","236.54400","19.71225","0.12141"
"39486","236.88000","19.74011","0.12109"
"39542","237.21600","19.76821","0.12519"
"39598","237.55200","19.79619","0.12389"
"39654","237.88800","19.82412","0.12264"
"39710","238.22400","19.85228","0.12613"
"39766","238.56000","19.88020","0.12586"
"39822","238.89600","19.90818","0.12568"
"39878","239.23200","19.93622","0.12775"
"39934","239.56800","19.96414","0.12937"
"39990","239.90400","19.99218","0.12786"
"40046","240.24000","20.02022","0.12889"
"40102","240.57600","20.04815","0.13300"
"40158","240.91200","20.07619","0.12957"
"40214","241.24800","20.10417","0.13085"
"40270","241.58400","20.13221","0.13435"
"40326","241.92000","20.16019","0.13216"
"40382","242.25600","20.18818","0.13314"
"40438","242.59200","20.21616","0.13660"
"40494","242.92800","20.24420","0.13473"
"40550","243.26400","20.27218","0.13372"
"40606","243.60000","20.30022","0.13862"
"40662","243.93600","20.32820","0.13887"
"40718","244.27200","20.35618","0.13780"
"40774","244.60800","20.38423","0.14013"
"40830","244.94400","20.41215","0.14230"
"40886","245.28000","20.44019","0.14071"
"40942","245.61600","20.46823","0.14264"
"40998","245.95200","20.49615","0.14519"
"41054","246.28800","20.52425","0.14404"
"41110","246.62400","20.55217","0.14308"
"41166","246.96000","20.58015","0.14689"
"41222","247.29600","20.60826","0.14582"
"41278","247.63200","20.63612","0.14531"
"41334","247.96800","20.66422","0.14735"
"41390","248.30400","20.69220","0.14792"
"41446","248.64000","20.72018","0.14689"
"41502","248.97600","20.74822","0.14885"
"41558","249.31200","20.77621","0.15029"
"41614","249.64800","20.80419","0.14943"
"41670","249.98400","20.83223","0.14959"
"41726","250.32000","20.86015","0.15138"
"41782","250.65600","20.88813","0.15124"
"41838","250.99200","20.91623","0.15087"
"41894","251.32800","20.94415","0.15240"
"41950","251.66400","20.97219","0.15365"
"42006","252.00000","21.00024","0.15229"
"42062","252.33600","21.02822","0.15300"
"42118","252.67200","21.05620","0.15483"
"42174","253.00800","21.08418","0.15392"
"42230","253.34400","21.11222","0.15406"
"42286","253.68000","21.14021","0.15610"
"42342","254.01600","21.16818","0.15585"
"42398","254.35200","21.19623","0.15581"
"42454","254.68800","21.22415","0.15752"
"42510","255.02400","21.25213","0.15788"
"42566","255.36000","21.28017","0.15754"
"42622","255.69600","21.30815","0.15776"
"42678","256.03200","21.33619","0.15992"
"42734","256.36800","21.36423","0.15956"
"42790","256.70400","21.39215","0.15902"
"42846","257.04000","21.42026","0.16004"
"42902","257.37600","21.44818","0.16095"
"42958","257.71200","21.47616","0.16049"
"43014","258.04800","21.50420","0.16057"
"43070","258.38400","21.53212","0.16147"
"43126","258.72000","21.56023","0.16142"
"43182","259.05600","21.58827","0.16145"
"43238","259.39200","21.61613","0.16199"
"43294","259.72800","21.64417","0.16311"
"43350","260.06400","21.67221","0.16219"
"43406","260.40000","21.70013","0.16237"
"43462","260.73600","21.72823","0.16371"
"43518","261.07200","21.75621","0.16393"
"43574","261.40800","21.78419","0.16341"
"43630","261.74400","21.81224","0.16466"
"43686","262.08000","21.84016","0.16462"
"43742","262.41600","21.86820","0.16455"
"43798","262.75200","21.89624","0.16482"
"43854","263.08800","21.92416","0.16609"
"43910","263.42400","21.95221","0.16593"
"43966","263.76000","21.98018","0.16611"
"44022","264.09600","22.00823","0.16673"
"44078","264.43200","22.03621","0.16741"
"44134","264.76800","22.06419","0.16675"
"44190","265.10400","22.09223","0.16736"
"44246","265.44000","22.12016","0.16817"
"44302","265.77600","22.14814","0.16823"
"44358","266.11200","22.17624","0.16778"
"44414","266.44800","22.20416","0.16894"
"44470","266.78400","22.23226","0.16965"
"44526","267.12000","22.26024","0.16955"
"44582","267.45600","22.28816","0.16962"
"44638","267.79200","22.31620","0.17040"
"44694","268.12800","22.34419","0.17120"
"44750","268.46400","22.37217","0.17038"
"44806","268.80000","22.40021","0.17109"
"44862","269.13600","22.42813","0.17237"
"44918","269.47200","22.45623","0.17202"
"44974","269.80800","22.48421","0.17255"
"45030","270.14400","22.51213","0.17298"
"45086","270.48000","22.54018","0.17334"
"45142","270.81600","22.56822","0.17377"
"45198","271.15200","22.59614","0.17387"
"45254","271.48800","22.62424","0.17539"
"45310","271.82400","22.65216","0.17539"
"45366","272.16000","22.68020","0.17542"
"45422","272.49600","22.70819","0.17582"
"45478","272.83200","22.73617","0.17688"
"45534","273.16800","22.76421","0.17664"
"45590","273.50400","22.79219","0.17648"
"45646","273.84000","22.82023","0.17809"
"45702","274.17600","22.84815","0.17868"
"45758","274.51200","22.87613","0.17875"
"45814","274.84800","22.90423","0.17868"
"45870","275.18400","22.93222","0.18003"
"45926","275.52000","22.96020","0.18110"
"45982","275.85600","22.98824","0.18064"
"46038","276.19200","23.01616","0.18097"
"46094","276.52800","23.04420","0.18192"
"46150","276.86400","23.07218","0.18225"
"46206","277.20000","23.10016","0.18285"
"46262","277.53600","23.12821","0.18339"
"46318","277.87200","23.15619","0.18458"
"46374","278.20800","23.18411","0.18433"
"46430","278.54400","23.21221","0.18441"
"46486","278.88000","23.24019","0.18583"
"46542","279.21600","23.26818","0.18648"
"46598","279.55200","23.29622","0.18578"
"46654","279.88800","23.32414","0.18654"
"46710","280.22400","23.35218","0.18722"
"46766","280.56000","23.38022","0.18782"
"46822","280.89600","23.40820","0.18794"
"46878","281.23200","23.43624","0.18893"
"46934","281.56800","23.46416","0.18954"
"46990","281.90400","23.49215","0.19008"
"47046","282.24000","23.52019","0.18979"
"47102","282.57600","23.54817","0.19054"
"47158","282.91200","23.57615","0.19145"
"47214","283.24800","23.60419","0.19209"
"47270","283.58400","23.63217","0.19252"
"47326","283.92000","23.66021","0.19226"
"47382","284.25600","23.68819","0.19358"
"47438","284.59200","23.71624","0.19405"
"47494","284.92800","23.74422","0.19367"
"47550","285.26400","23.77214","0.19419"
"47606","285.60000","23.80024","0.19520"
"47662","285.93600","23.82816","0.19548"
"47718","286.27200","23.85614","0.19609"
"47774","286.60800","23.88424","0.19692"
"47830","286.94400","23.91216","0.19826"
"47886","287.28000","23.94015","0.19779"
"47942","287.61600","23.96825","0.19839"
"47998","287.95200","23.99611","0.19892"
"48054","288.28800","24.02421","0.20020"
"48110","288.62400","24.05225","0.19968"
"48166","288.96000","24.08017","0.19996"
"48222","289.29600","24.10822","0.20023"
"48278","289.63200","24.13614","0.20048"
"48334","289.96800","24.16418","0.20126"
"48390","290.30400","24.19222","0.20155"
"48446","290.64000","24.22014","0.20214"
"48502","290.97600","24.24818","0.20302"
"48558","291.31200","24.27616","0.20361"
"48614","291.64800","24.30415","0.20374"
"48670","291.98400","24.33219","0.20384"
"48726","292.32000","24.36017","0.20459"
"48782","292.65600","24.38821","0.20527"
"48838","292.99200","24.41625","0.20560"
"48894","293.32800","24.44417","0.20551"
"48950","293.66400","24.47216","0.20632"
"49006","294.00000","24.50026","0.20625"
"49062","294.33600","24.52818","0.20648"
"49118","294.67200","24.55622","0.20672"
"49174","295.00800","24.58420","0.20728"
"49230","295.34400","24.61224","0.20768"
"49286","295.68000","24.64017","0.20794"
"49342","296.01600","24.66809","0.20829"
"49398","296.35200","24.69619","0.20836"
"49454","296.68800","24.72423","0.20886"
"49510","297.02400","24.75221","0.20948"
"49566","297.36000","24.78025","0.20998"
"49622","297.69600","24.80817","0.20959"
"49678","298.03200","24.83615","0.21045"
"49734","298.36800","24.86419","0.21031"
"49790","298.70400","24.89212","0.21037"
"49846","299.04000","24.92022","0.21126"
"49902","299.37600","24.94820","0.21172"
"49958","299.71200","24.97612","0.21205"
"50014","300.04800","25.00422","0.21214"
"50070","300.38400","25.03220","0.21220"
"50126","300.72000","25.06019","0.21266"
"50182","301.05600","25.08823","0.21319"
"50238","301.39200","25.11615","0.21304"
"50294","301.72800","25.14419","0.21335"
"50350","302.06400","25.17217","0.21388"
"50406","302.40000","25.20015","0.21441"
"50462","302.73600","25.22820","0.21408"
"50518","303.07200","25.25617","0.21446"
"50574","303.40800","25.28422","0.21487"
"50630","303.74400","25.31220","0.21515"
"50686","304.08000","25.34012","0.21541"
"50742","304.41600","25.36816","0.21578"
"50798","304.75200","25.39620","0.21668"
"50854","305.08800","25.42418","0.21703"
"50910","305.42400","25.45223","0.21715"
"50966","305.76000","25.48021","0.21694"
"51022","306.09600","25.50819","0.21763"
"51078","306.43200","25.53623","0.21750"
"51134","306.76800","25.56409","0.21855"
"51190","307.10400","25.59225","0.21891"
"51246","307.44000","25.62024","0.21820"
"51302","307.77600","25.64816","0.21320"
"51358","308.11200","25.67626","0.21015"
"51414","308.44800","25.70418","-0.00034"
"51470","308.78400","25.73216","0.00030"
"51526","309.12000","25.76020","-0.00049"
"51582","309.45600","25.78818","-0.00150"
"51638","309.79200","25.81623","-0.00143"
"51694","310.12800","25.84427","0.00043"
"51750","310.46400","25.87219","-0.00095"
"51806","310.80000","25.90017","-0.00075"
"51862","311.13600","25.92821","-0.00008"
"51918","311.47200","25.95613","-0.00064"
"51974","311.80800","25.98423","-0.00131"
"52030","312.14400","26.01215","-0.00132"
"52086","312.48000","26.04020","0.00060"
"52142","312.81600","26.06824","-0.00090"
"52198","313.15200","26.09616","-0.00145"
"52254","313.48800","26.12420","-0.00055"
"52310","313.82400","26.15218","0.00015"
"52366","314.16000","26.18022","-0.00095"
"52422","314.49600","26.20820","-0.00154"
"52478","314.83200","26.23619","-0.00100"
"52534","315.16800","26.26423","0.00026"
"52590","315.50400","26.29215","-0.00104"
"52646","315.84000","26.32019","-0.00122"
"52702","316.17600","26.34823","-0.00020"
"52758","316.51200","26.37615","-0.00089"
"52814","316.84800","26.40419","-0.00108"
"52870","317.18400","26.43217","-0.00085"
"52926","317.52000","26.46010","0.00047"
"52982","317.85600","26.48820","-0.00074"
"53038","318.19200","26.51618","-0.00099"
"53094","318.52800","26.54422","-0.00059"
"53150","318.86400","26.57220","0.00054"
"53206","319.20000","26.60018","-0.00129"
"53262","319.53600","26.62811","-0.00060"
"53318","319.87200","26.65621","-0.00062"
"53374","320.20800","26.68419","-0.00044"
"53430","320.54400","26.71223","-0.00106"
"53486","320.88000","26.74021","-0.00080"
"53542","321.21600","26.76813","0.00017"
"53598","321.55200","26.79617","-0.00124"
"53654","321.88800","26.82416","-0.00125"
"53710","322.22400","26.85220","-0.00104"
"53766","322.56000","26.88024","0.00040"
"53822","322.89600","26.90816","-0.00131"
"53878","323.23200","26.93626","-0.00090"
"53934","323.56800","26.96412","-0.00077"
"53990","323.90400","26.99216","-0.00001"
"54046","324.24000","27.02020","-0.00083"
"54102","324.57600","27.04819","-0.00072"
"54158","324.91200","27.07623","0.00042"
"54214","325.24800","27.10421","-0.00032"
"54270","325.58400","27.13219","-0.00091"
"54326","325.92000","27.16023","-0.00015"
"54382","326.25600","27.18821","0.00056"
"54438","326.59200","27.21620","-0.00052"
"54494","326.92800","27.24424","-0.00065"
"54550","327.26400","27.27210","0.00005"
"54606","327.60000","27.30020","0.00028"
"54662","327.93600","27.32824","-0.00083"
"54718","328.27200","27.35616","-0.00051"
"54774","328.60800","27.38420","0.00048"
"54830","328.94400","27.41219","-0.00004"
"54886","329.28000","27.44017","-0.00044"
"54942","329.61600","27.46821","-0.00073"
"54998","329.95200","27.49619","0.00061"
"55054","330.28800","27.52417","-0.00092"
"55110","330.62400","27.55221","-0.00060"
"55166","330.96000","27.58020","-0.00043"
"55222","331.29600","27.60824","0.00006"
"55278","331.63200","27.63622","-0.00069"
"55334","331.96800","27.66420","-0.00064"
"55390","332.30400","27.69218","0.00077"
"55446","332.64000","27.72016","-0.00069"
"55502","332.97600","27.74821","-0.00091"
"55558","333.31200","27.77618","0.00060"
"55614","333.64800","27.80417","0.00130"
"55670","333.98400","27.83221","-0.00064"
"55726","334.32000","27.86019","0.00004"
"55782","334.65600","27.88817","0.00068"
"55838","334.99200","27.91615","-0.00002"
"55894","335.32800","27.94413","-0.00051"
"55950","335.66400","27.97224","0.00046"
"56006","336.00000","28.00022","0.00049"
"56062","336.33600","28.02814","-0.00020"
"56118","336.67200","28.05618","0.00043"
"56174","337.00800","28.08416","0.00086"
"56230","337.34400","28.11214","-0.00027"
"56286","337.68000","28.14018","0.00013"
"56342","338.01600","28.16817","0.00093"
"56398","338.35200","28.19621","0.00041"
"56454","338.68800","28.22425","-0.00066"
"56510","339.02400","28.25211","0.00026"
"56566","339.36000","28.28021","0.00045"
"56622","339.69600","28.30819","-0.00008"
"56678","340.03200","28.33617","0.00027"
"56734","340.36800","28.36421","0.00058"
"56790","340.70400","28.39220","0.00018"
"56846","341.04000","28.42018","0.00039"
"56902","341.37600","28.44816","0.00055"
"56958","341.71200","28.47614","0.00051"
"57014","342.04800","28.50424","0.00001"
"57070","342.38400","28.53216","0.00056"
"57126","342.72000","28.56021","0.00001"
"57182","343.05600","28.58813","0.00073"
"57238","343.39200","28.61611","0.00068"
"57294","343.72800","28.64421","0.00115"
"57350","344.06400","28.67225","0.00106"
"57406","344.40000","28.70017","0.00086"
"57462","344.73600","28.72828","0.00063"
"57518","345.07200","28.75620","0.00055"
"57574","345.40800","28.78418","0.00053"
"57630","345.74400","28.81222","0.00092"
"57686","346.08000","28.84020","0.00121"
"57742","346.41600","28.86824","0.00117"
"57798","346.75200","28.89622","0.00133"
"57854","347.08800","28.92414","0.00157"
"57910","347.42400","28.95225","0.00168"
"57966","347.76000","28.98017","0.00136"
"58022","348.09600","29.00815","0.00133"
"58078","348.43200","29.03625","0.00131"
"58134","348.76800","29.06411","0.00148"
"58190","349.10400","29.09221","0.00067"
"58246","349.44000","29.12019","0.00195"
"58302","349.77600","29.14818","0.00125"
"58358","350.11200","29.17622","0.00144"
"58414","350.44800","29.20420","0.00130"
"58470","350.78400","29.23218","0.00142"
"58526","351.12000","29.26016","0.00163"
"58582","351.45600","29.28814","0.00167"
"58638","351.79200","29.31618","0.00122"
"58694","352.12800","29.34417","0.00091"
"58750","352.46400","29.37221","0.00128"
"58806","352.80000","29.40019","0.00163"
"58862","353.13600","29.42817","0.00192"
"58918","353.47200","29.45621","0.00158"
"58974","353.80800","29.48419","0.00193"
"59030","354.14400","29.51217","0.00198"
"59086","354.48000","29.54016","0.00195"
"59142","354.81600","29.56820","0.00199"
"59198","355.15200","29.59612","0.00244"
"59254","355.48800","29.62422","0.00273"
"59310","355.82400","29.65214","0.00217"
"59366","356.16000","29.68018","0.00286"
"59422","356.49600","29.70828","0.00259"
"59478","356.83200","29.73615","0.00294"
"59534","357.16800","29.76419","0.00303"
"59590","357.50400","29.79223","0.00312"
"59646","357.84000","29.82015","0.00296"
"59702","358.17600","29.84819","0.00368"
"59758","358.51200","29.87617","0.00305"
"59814","358.84800","29.90415","0.00369"
"59870","359.18400","29.93226","0.00403"
"59926","359.52000","29.96018","0.00372"
"59982","359.85600","29.98816","0.00387"
"60038","360.19200","30.01620","0.00446"
"60094","360.52800","30.04412","0.00454"
"60150","360.86400","30.07222","0.00446"
"60206","361.20000","30.10021","0.00498"
"60262","361.53600","30.12825","0.00534"
"60318","361.87200","30.15617","0.00495"
"60374","362.20800","30.18415","0.00529"
"60430","362.54400","30.21219","0.00545"
"60486","362.88000","30.24017","0.00561"
"60542","363.21600","30.26822","0.00506"
"60598","363.55200","30.29619","0.00629"
"60654","363.88800","30.32418","0.00597"
"60710","364.22400","30.35222","0.00654"
"60766","364.56000","30.38020","0.00689"
"60822","364.89600","30.40812","0.00685"
"60878","365.23200","30.43622","0.00705"
"60934","365.56800","30.46420","0.00760"
"60990","365.90400","30.49212","0.00756"
"61046","366.24000","30.52023","0.00747"
"61102","366.57600","30.54821","0.00767"
"61158","366.91200","30.57619","0.00758"
"61214","367.24800","30.60423","0.00843"
"61270","367.58400","30.63215","0.00821"
"61326","367.92000","30.66019","0.00810"
"61382","368.25600","30.68823","0.00831"
"61438","368.59200","30.71615","0.00879"
"61494","368.92800","30.74420","0.00820"
"61550","369.26400","30.77224","0.00904"
"61606","369.60000","30.80022","0.00876"
"61662","369.93600","30.82820","0.00828"
"61718","370.27200","30.85618","0.00658"
"61774","370.60800","30.88422","0.00686"
"61830","370.94400","30.91221","0.00668"
"61886","371.28000","30.94019","0.00680"
"61942","371.61600","30.96817","0.00746"
"61998","371.95200","30.99621","0.00654"
"62054","372.28800","31.02419","0.00744"
"62110","372.62400","31.05217","0.00747"
"62166","372.96000","31.08010","0.00730"
"62222","373.29600","31.10819","0.00819"
"62278","373.63200","31.13618","0.00718"
"62334","373.96800","31.16422","0.00738"
"62390","374.30400","31.19220","0.00754"
"62446","374.64000","31.22012","0.00777"
"62502","374.97600","31.24822","0.00745"
"62558","375.31200","31.27620","0.00690"
"62614","375.64800","31.30412","0.00600"
"62670","375.98400","31.33228","0.00454"
"62726","376.32000","31.36021","0.00466"
"62782","376.65600","31.38813","0.00517"
"62838","376.99200","31.41629","0.00502"
"62894","377.32800","31.44415","0.00497"
"62950","377.66400","31.47219","0.00572"
"63006","378.00000","31.50018","0.00549"
"63062","378.33600","31.52816","0.00570"
"63118","378.67200","31.55620","0.00601"
"63174","379.00800","31.58418","0.00592"
"63230","379.34400","31.61216","0.00601"
"63286","379.68000","31.64014","0.00597"
"63342","380.01600","31.66824","0.00639"
"63398","380.35200","31.69616","0.00623"
"63454","380.68800","31.72421","0.00641"
"63510","381.02400","31.75219","0.00624"
"63566","381.36000","31.78023","0.00694"
"63622","381.69600","31.80821","0.00667"
"63678","382.03200","31.83613","0.00695"
"63734","382.36800","31.86423","0.00704"
"63790","382.70400","31.89215","0.00667"
"63846","383.04000","31.92019","0.00696"
"63902","383.37600","31.94824","0.00686"
"63958","383.71200","31.97610","0.00747"
"64014","384.04800","32.00420","0.00720"
"64070","384.38400","32.03218","0.00699"
"64126","384.72000","32.06017","0.00695"
"64182","385.05600","32.08820","0.00664"
"64238","385.39200","32.11613","0.00636"
"64294","385.72800","32.14417","0.00674"
"64350","386.06400","32.17221","0.00575"
"64406","386.40000","32.20013","0.00561"
"64462","386.73600","32.22823","0.00515"
"64518","387.07200","32.25621","0.00219"
"64574","387.40800","32.28419","0.00160"
"64630","387.74400","32.31224","0.00149"
"64686","388.08000","32.34016","0.00126"
"64742","388.41600","32.36814","0.00164"
"64798","388.75200","32.39624","0.00132"
"64854","389.08800","32.42416","0.00156"
"64910","389.42400","32.45220","0.00161"
"64966","389.76000","32.48018","0.00137"
"65022","390.09600","32.50816","0.00095"
"65078","390.43200","32.53615","0.00148"
"65134","390.76800","32.56413","0.00145"
"65190","391.10400","32.59223","0.00082"
"65246","391.44000","32.62021","0.00113"
"65302","391.77600","32.64819","0.00139"
"65358","392.11200","32.67624","0.00199"
"65414","392.44800","32.70415","0.00169"
"65470","392.78400","32.73220","0.00133"
"65526","393.12000","32.76024","0.00149"
"65582","393.45600","32.78816","0.00163"
"65638","393.79200","32.81620","0.00141"
"65694","394.12800","32.84418","0.00167"
"65750","394.46400","32.87217","0.00160"
"65806","394.80000","32.90021","0.00154"
"65862","395.13600","32.92819","0.00147"
"65918","395.47200","32.95617","0.00169"
"65974","395.80800","32.98421","0.00192"
"66030","396.14400","33.01213","0.00186"
"66086","396.48000","33.04017","0.00158"
"66142","396.81600","33.06827","0.00190"
"66198","397.15200","33.09620","0.00197"
"66254","397.48800","33.12424","0.00172"
"66310","397.82400","33.15222","0.00247"
"66366","398.16000","33.18008","0.00244"
"66422","398.49600","33.20818","0.00211"
"66478","398.83200","33.23616","0.00224"
"66534","399.16800","33.26421","0.00212"
"66590","399.50400","33.29224","0.00190"
"66646","399.84000","33.32017","0.00248"
"66702","400.17600","33.34815","0.00132"
"66758","400.51200","33.37625","0.00139"
"66814","400.84800","33.40417","0.00164"
"66870","401.18400","33.43222","0.00161"
"66926","401.52000","33.46020","0.00166"
"66982","401.85600","33.48824","0.00173"
"67038","402.19200","33.51622","0.00279"
"67094","402.52800","33.54420","0.00170"
"67150","402.86400","33.57224","0.00208"
"67206","403.20000","33.60016","0.00232"
"67262","403.53600","33.62820","0.00192"
"67318","403.87200","33.65619","0.00211"
"67374","404.20800","33.68411","0.00288"
"67430","404.54400","33.71221","0.00271"
"67486","404.88000","33.74019","0.00333"
"67542","405.21600","33.76817","0.00326"
"67598","405.55200","33.79622","0.00309"
"67654","405.88800","33.82413","0.00355"
"67710","406.22400","33.85218","0.00378"
"67766","406.56000","33.88021","0.00355"
"67822","406.89600","33.90814","0.00107"
"67878","407.23200","33.93618","0.00081"
"67934","407.56800","33.96428","0.00099"
"67990","407.90400","33.99214","0.00017"
"68046","408.24000","34.02019","0.00134"
"68102","408.57600","34.04823","0.00105"
"68158","408.91200","34.07615","0.00077"
"68214","409.24800","34.10419","0.00067"
"68270","409.58400","34.13223","0.00093"
"68326","409.92000","34.16021","0.00102"
"68382","410.25600","34.18819","0.00043"
"68438","410.59200","34.21617","0.00058"
"68494","410.92800","34.24416","0.00047"
"68550","411.26400","34.27220","0.00061"
"68606","411.60000","34.30018","0.00019"
"68653","411.87800","34.32338","0.00056"