File: Trajectories_together/161218_2Specimen_RawData_1.csv
"","V1","V2","V3"
"1","End date","12/18/2016",""
"2","Specimen label","16CT_30",""
"3","Maximum Load","0.20278","N"
"4","Time","Extension","Load"
"5","(s)","(mm)","(N)"
"6","0.00000","0.00000","0.00013"
"76","0.42000","0.03534","0.00007"
"146","0.84000","0.07025","0.00011"
"216","1.26000","0.10523","0.00025"
"286","1.68000","0.14021","-0.00015"
"356","2.10000","0.17530","0.00057"
"426","2.52000","0.21028","0.00015"
"496","2.94000","0.24526","0.00007"
"566","3.36000","0.28017","0.00039"
"636","3.78000","0.31521","-0.00002"
"706","4.20000","0.35019","0.00038"
"776","4.62000","0.38522","0.00001"
"846","5.04000","0.42020","-0.00011"
"916","5.46000","0.45524","0.00017"
"986","5.88000","0.49021","0.00048"
"1056","6.30000","0.52525","0.00021"
"1126","6.72000","0.56023","0.00000"
"1196","7.14000","0.59515","0.00037"
"1266","7.56000","0.63024","0.00030"
"1336","7.98000","0.66528","0.00034"
"1406","8.40000","0.70020","0.00031"
"1476","8.82000","0.73517","0.00044"
"1546","9.24000","0.77021","0.00008"
"1616","9.66000","0.80519","0.00041"
"1686","10.08000","0.84016","0.00067"
"1756","10.50000","0.87520","0.00050"
"1826","10.92000","0.91018","0.00038"
"1896","11.34000","0.94521","0.00062"
"1966","11.76000","0.98025","0.00026"
"2036","12.18000","1.01523","0.00045"
"2106","12.60000","1.05020","0.00041"
"2176","13.02000","1.08518","0.00066"
"2246","13.44000","1.12028","0.00055"
"2316","13.86000","1.15525","0.00046"
"2386","14.28000","1.19023","0.00053"
"2456","14.70000","1.22515","0.00072"
"2526","15.12000","1.26018","0.00077"
"2596","15.54000","1.29522","0.00104"
"2666","15.96000","1.33026","0.00036"
"2736","16.38000","1.36523","0.00003"
"2806","16.80000","1.40015","0.00059"
"2876","17.22000","1.43525","0.00025"
"2946","17.64000","1.47028","0.00084"
"3016","18.06000","1.50520","0.00086"
"3086","18.48000","1.54018","0.00065"
"3156","18.90000","1.57522","0.00019"
"3226","19.32000","1.61025","0.00087"
"3296","19.74000","1.64523","0.00064"
"3366","20.16000","1.68027","0.00094"
"3436","20.58000","1.71518","0.00071"
"3506","21.00000","1.75016","0.00050"
"3576","21.42000","1.78526","0.00078"
"3646","21.84000","1.82023","0.00114"
"3716","22.26000","1.85521","0.00048"
"3786","22.68000","1.89019","0.00072"
"3856","23.10000","1.92522","0.00078"
"3926","23.52000","1.96026","0.00073"
"3996","23.94000","1.99524","0.00083"
"4066","24.36000","2.03015","0.00079"
"4136","24.78000","2.06525","0.00082"
"4206","25.20000","2.10023","0.00099"
"4276","25.62000","2.13526","0.00125"
"4346","26.04000","2.17018","0.00094"
"4416","26.46000","2.20516","0.00080"
"4486","26.88000","2.24025","0.00082"
"4556","27.30000","2.27517","0.00077"
"4626","27.72000","2.31021","0.00104"
"4696","28.14000","2.34518","0.00108"
"4766","28.56000","2.38022","0.00108"
"4836","28.98000","2.41526","0.00104"
"4906","29.40000","2.45023","0.00100"
"4976","29.82000","2.48515","0.00123"
"5046","30.24000","2.52019","0.00094"
"5116","30.66000","2.55523","0.00140"
"5186","31.08000","2.59026","0.00126"
"5256","31.50000","2.62524","0.00133"
"5326","31.92000","2.66016","0.00125"
"5396","32.34000","2.69519","0.00130"
"5466","32.76000","2.73023","0.00154"
"5536","33.18000","2.76527","0.00134"
"5606","33.60000","2.80018","0.00137"
"5676","34.02000","2.83516","0.00129"
"5746","34.44000","2.87020","0.00153"
"5816","34.86000","2.90523","0.00152"
"5886","35.28000","2.94021","0.00151"
"5956","35.70000","2.97519","0.00140"
"6026","36.12000","3.01022","0.00135"
"6096","36.54000","3.04526","0.00126"
"6166","36.96000","3.08024","0.00165"
"6236","37.38000","3.11521","0.00117"
"6306","37.80000","3.15019","0.00121"
"6376","38.22000","3.18517","0.00178"
"6446","38.64000","3.22020","0.00163"
"6516","39.06000","3.25524","0.00180"
"6586","39.48000","3.29016","0.00125"
"6656","39.90000","3.32520","0.00123"
"6726","40.32000","3.36023","0.00096"
"6796","40.74000","3.39521","0.00095"
"6866","41.16000","3.43019","0.00089"
"6936","41.58000","3.46516","0.00109"
"7006","42.00000","3.50026","0.00121"
"7076","42.42000","3.53524","0.00108"
"7146","42.84000","3.57021","0.00114"
"7216","43.26000","3.60519","0.00126"
"7286","43.68000","3.64017","0.00133"
"7356","44.10000","3.67520","0.00165"
"7426","44.52000","3.71018","0.00159"
"7496","44.94000","3.74522","0.00170"
"7566","45.36000","3.78019","0.00140"
"7636","45.78000","3.81523","0.00160"
"7706","46.20000","3.85027","0.00178"
"7776","46.62000","3.88524","0.00158"
"7846","47.04000","3.92022","0.00161"
"7916","47.46000","3.95520","0.00188"
"7986","47.88000","3.99023","0.00160"
"8056","48.30000","4.02527","0.00192"
"8126","48.72000","4.06025","0.00182"
"8196","49.14000","4.09516","0.00176"
"8266","49.56000","4.13020","0.00186"
"8336","49.98000","4.16524","0.00224"
"8406","50.40000","4.20027","0.00237"
"8476","50.82000","4.23519","0.00226"
"8546","51.24000","4.27017","0.00246"
"8616","51.66000","4.30521","0.00219"
"8686","52.08000","4.34024","0.00266"
"8756","52.50000","4.37522","0.00246"
"8826","52.92000","4.41020","0.00228"
"8896","53.34000","4.44523","0.00281"
"8966","53.76000","4.48027","0.00276"
"9036","54.18000","4.51525","0.00222"
"9106","54.60000","4.55022","0.00285"
"9176","55.02000","4.58514","0.00272"
"9246","55.44000","4.62018","0.00309"
"9316","55.86000","4.65521","0.00288"
"9386","56.28000","4.69019","0.00304"
"9456","56.70000","4.72523","0.00293"
"9526","57.12000","4.76014","0.00307"
"9596","57.54000","4.79518","0.00337"
"9666","57.96000","4.83022","0.00310"
"9736","58.38000","4.86525","0.00345"
"9806","58.80000","4.90017","0.00385"
"9876","59.22000","4.93527","0.00327"
"9946","59.64000","4.97030","0.00345"
"10016","60.06000","5.00522","0.00405"
"10086","60.48000","5.04020","0.00418"
"10156","60.90000","5.07517","0.00402"
"10226","61.32000","5.11021","0.00398"
"10296","61.74000","5.14519","0.00439"
"10366","62.16000","5.18023","0.00411"
"10436","62.58000","5.21514","0.00443"
"10506","63.00000","5.25018","0.00450"
"10576","63.42000","5.28527","0.00447"
"10646","63.84000","5.32031","0.00484"
"10716","64.26000","5.35517","0.00503"
"10786","64.68000","5.39021","0.00501"
"10856","65.10000","5.42530","0.00505"
"10926","65.52000","5.46022","0.00507"
"10996","65.94000","5.49526","0.00526"
"11066","66.36000","5.53017","0.00593"
"11136","66.78000","5.56515","0.00562"
"11206","67.20000","5.60019","0.00585"
"11276","67.62000","5.63522","0.00587"
"11346","68.04000","5.67014","0.00603"
"11416","68.46000","5.70518","0.00601"
"11486","68.88000","5.74021","0.00617"
"11556","69.30000","5.77525","0.00602"
"11626","69.72000","5.81023","0.00654"
"11696","70.14000","5.84520","0.00671"
"11766","70.56000","5.88024","0.00663"
"11836","70.98000","5.91528","0.00673"
"11906","71.40000","5.95025","0.00660"
"11976","71.82000","5.98523","0.00664"
"12046","72.24000","6.02015","0.00661"
"12116","72.66000","6.05518","0.00707"
"12186","73.08000","6.09022","0.00697"
"12256","73.50000","6.12526","0.00692"
"12326","73.92000","6.16024","0.00709"
"12396","74.34000","6.19515","0.00769"
"12466","74.76000","6.23019","0.00806"
"12536","75.18000","6.26523","0.00766"
"12606","75.60000","6.30026","0.00847"
"12676","76.02000","6.33518","0.00829"
"12746","76.44000","6.37028","0.00872"
"12816","76.86000","6.40525","0.00839"
"12886","77.28000","6.44023","0.00814"
"12956","77.70000","6.47521","0.00896"
"13026","78.12000","6.51018","0.00900"
"13096","78.54000","6.54522","0.00963"
"13166","78.96000","6.58020","0.00966"
"13236","79.38000","6.61523","0.00972"
"13306","79.80000","6.65015","0.00991"
"13376","80.22000","6.68519","0.01047"
"13446","80.64000","6.72022","0.01034"
"13516","81.06000","6.75526","0.01074"
"13586","81.48000","6.79018","0.01099"
"13656","81.90000","6.82521","0.01115"
"13726","82.32000","6.86025","0.01126"
"13796","82.74000","6.89529","0.01181"
"13866","83.16000","6.93026","0.01215"
"13936","83.58000","6.96512","0.01227"
"14006","84.00000","7.00016","0.01307"
"14076","84.42000","7.03525","0.01413"
"14146","84.84000","7.07023","0.01435"
"14216","85.26000","7.10521","0.01530"
"14286","85.68000","7.14019","0.01107"
"14356","86.10000","7.17522","0.00996"
"14426","86.52000","7.21026","0.01053"
"14496","86.94000","7.24524","0.01056"
"14566","87.36000","7.28021","0.01186"
"14636","87.78000","7.31519","0.01178"
"14706","88.20000","7.35023","0.01259"
"14776","88.62000","7.38520","0.01262"
"14846","89.04000","7.42024","0.01322"
"14916","89.46000","7.45516","0.01339"
"14986","89.88000","7.49019","0.01373"
"15056","90.30000","7.52523","0.01479"
"15126","90.72000","7.56021","0.01559"
"15196","91.14000","7.59518","0.01608"
"15266","91.56000","7.63016","0.01673"
"15336","91.98000","7.66526","0.01758"
"15406","92.40000","7.70023","0.01833"
"15476","92.82000","7.73521","0.01839"
"15546","93.24000","7.77013","0.01912"
"15616","93.66000","7.80522","0.01995"
"15686","94.08000","7.84026","0.02095"
"15756","94.50000","7.87524","0.02099"
"15826","94.92000","7.91015","0.02171"
"15896","95.34000","7.94519","0.02222"
"15966","95.76000","7.98023","0.02300"
"16036","96.18000","8.01521","0.02309"
"16106","96.60000","8.05024","0.02430"
"16176","97.02000","8.08516","0.02465"
"16246","97.44000","8.12020","0.02541"
"16316","97.86000","8.15529","0.02601"
"16386","98.28000","8.19027","0.02639"
"16456","98.70000","8.22525","0.02666"
"16526","99.12000","8.26022","0.02717"
"16596","99.54000","8.29526","0.02726"
"16666","99.96000","8.33024","0.02824"
"16736","100.38000","8.36527","0.02921"
"16806","100.80000","8.40013","0.02934"
"16876","101.22000","8.43517","0.02980"
"16946","101.64000","8.47026","0.02966"
"17016","102.06000","8.50530","0.03036"
"17086","102.48000","8.54016","0.03082"
"17156","102.90000","8.57519","0.03185"
"17226","103.32000","8.61023","0.03183"
"17296","103.74000","8.64521","0.03264"
"17366","104.16000","8.68024","0.03426"
"17436","104.58000","8.71522","0.03499"
"17506","105.00000","8.75020","0.03603"
"17576","105.42000","8.78523","0.03651"
"17646","105.84000","8.82021","0.03719"
"17716","106.26000","8.85519","0.03803"
"17786","106.68000","8.89017","0.03810"
"17856","107.10000","8.92520","0.04026"
"17926","107.52000","8.96024","0.04049"
"17996","107.94000","8.99522","0.04132"
"18066","108.36000","9.03019","0.04157"
"18136","108.78000","9.06517","0.04243"
"18206","109.20000","9.10021","0.04305"
"18276","109.62000","9.13524","0.04463"
"18346","110.04000","9.17022","0.04530"
"18416","110.46000","9.20520","0.04550"
"18486","110.88000","9.24023","0.04713"
"18556","111.30000","9.27527","0.04799"
"18626","111.72000","9.31025","0.04901"
"18696","112.14000","9.34516","0.04981"
"18766","112.56000","9.38020","0.05058"
"18836","112.98000","9.41524","0.05111"
"18906","113.40000","9.45021","0.05163"
"18976","113.82000","9.48519","0.05265"
"19046","114.24000","9.52017","0.05395"
"19116","114.66000","9.55520","0.05464"
"19186","115.08000","9.59024","0.05504"
"19256","115.50000","9.62528","0.05551"
"19326","115.92000","9.66019","0.05678"
"19396","116.34000","9.69523","0.05850"
"19466","116.76000","9.73021","0.05948"
"19536","117.18000","9.76525","0.05984"
"19606","117.60000","9.80028","0.06195"
"19676","118.02000","9.83520","0.06270"
"19746","118.44000","9.87018","0.06378"
"19816","118.86000","9.90521","0.06546"
"19886","119.28000","9.94025","0.06707"
"19956","119.70000","9.97517","0.06778"
"20026","120.12000","10.01014","0.06879"
"20096","120.54000","10.04524","0.07046"
"20166","120.96000","10.08022","0.07254"
"20236","121.38000","10.11519","0.07350"
"20306","121.80000","10.15023","0.07500"
"20376","122.22000","10.18521","0.07571"
"20446","122.64000","10.22024","0.07635"
"20516","123.06000","10.25522","0.07776"
"20586","123.48000","10.29026","0.07862"
"20656","123.90000","10.32517","0.07925"
"20726","124.32000","10.36021","0.08034"
"20796","124.74000","10.39525","0.08148"
"20866","125.16000","10.43022","0.08254"
"20936","125.58000","10.46520","0.08322"
"21006","126.00000","10.50018","0.08403"
"21076","126.42000","10.53522","0.08508"
"21146","126.84000","10.57025","0.08619"
"21216","127.26000","10.60523","0.08754"
"21286","127.68000","10.64020","0.08857"
"21356","128.10000","10.67524","0.08958"
"21426","128.52000","10.71028","0.09077"
"21496","128.94000","10.74520","0.09177"
"21566","129.36000","10.78017","0.09271"
"21636","129.78000","10.81521","0.09381"
"21706","130.20000","10.85025","0.09418"
"21776","130.62000","10.88522","0.09593"
"21846","131.04000","10.92020","0.09771"
"21916","131.46000","10.95518","0.09950"
"21986","131.88000","10.99021","0.10035"
"22056","132.30000","11.02525","0.10252"
"22126","132.72000","11.06023","0.10228"
"22196","133.14000","11.09520","0.10407"
"22266","133.56000","11.13018","0.10577"
"22336","133.98000","11.16522","0.10702"
"22406","134.40000","11.20025","0.10925"
"22476","134.82000","11.23529","0.11110"
"22546","135.24000","11.27015","0.11273"
"22616","135.66000","11.30519","0.11552"
"22686","136.08000","11.34022","0.11779"
"22756","136.50000","11.37526","0.12070"
"22826","136.92000","11.41017","0.12332"
"22896","137.34000","11.44515","0.12521"
"22966","137.76000","11.48025","0.12768"
"23036","138.18000","11.51523","0.12974"
"23106","138.60000","11.55020","0.13206"
"23176","139.02000","11.58518","0.13360"
"23246","139.44000","11.62022","0.02641"
"23316","139.86000","11.65525","0.01765"
"23386","140.28000","11.69029","0.01754"
"23456","140.70000","11.72521","0.01680"
"23526","141.12000","11.76018","0.01792"
"23596","141.54000","11.79516","0.01940"
"23666","141.96000","11.83026","0.02233"
"23736","142.38000","11.86517","0.02444"
"23806","142.80000","11.90015","0.02603"
"23876","143.22000","11.93519","0.02652"
"23946","143.64000","11.97022","0.02768"
"24016","144.06000","12.00520","0.02810"
"24086","144.48000","12.04024","0.02839"
"24156","144.90000","12.07515","0.02921"
"24226","145.32000","12.11025","0.03013"
"24296","145.74000","12.14523","0.03054"
"24366","146.16000","12.18020","0.03114"
"24436","146.58000","12.21518","0.03207"
"24506","147.00000","12.25022","0.03286"
"24576","147.42000","12.28520","0.03408"
"24646","147.84000","12.32017","0.03505"
"24716","148.26000","12.35521","0.03578"
"24786","148.68000","12.39012","0.03737"
"24856","149.10000","12.42522","0.03803"
"24926","149.52000","12.46026","0.03923"
"24996","149.94000","12.49529","0.04032"
"25066","150.36000","12.53021","0.04054"
"25136","150.78000","12.56519","0.04176"
"25206","151.20000","12.60023","0.04300"
"25276","151.62000","12.63526","0.04386"
"25346","152.04000","12.67024","0.04421"
"25416","152.46000","12.70516","0.04492"
"25486","152.88000","12.74019","0.04584"
"25556","153.30000","12.77523","0.04712"
"25626","153.72000","12.81027","0.04846"
"25696","154.14000","12.84518","0.04920"
"25766","154.56000","12.88016","0.04974"
"25836","154.98000","12.91520","0.05073"
"25906","155.40000","12.95023","0.05147"
"25976","155.82000","12.98527","0.05197"
"26046","156.24000","13.02025","0.05331"
"26116","156.66000","13.05522","0.05345"
"26186","157.08000","13.09020","0.05463"
"26256","157.50000","13.12524","0.05480"
"26326","157.92000","13.16021","0.05538"
"26396","158.34000","13.19519","0.05581"
"26466","158.76000","13.23023","0.05588"
"26536","159.18000","13.26520","0.05693"
"26606","159.60000","13.30018","0.05797"
"26676","160.02000","13.33522","0.05928"
"26746","160.44000","13.37014","0.06040"
"26816","160.86000","13.40523","0.06173"
"26886","161.28000","13.44021","0.06372"
"26956","161.70000","13.47525","0.06517"
"27026","162.12000","13.51016","0.06688"
"27096","162.54000","13.54520","0.06804"
"27166","162.96000","13.58030","0.06870"
"27236","163.38000","13.61527","0.07014"
"27306","163.80000","13.65019","0.07181"
"27376","164.22000","13.68517","0.07205"
"27446","164.64000","13.72020","0.07336"
"27516","165.06000","13.75518","0.07455"
"27586","165.48000","13.79022","0.07531"
"27656","165.90000","13.82513","0.07641"
"27726","166.32000","13.86023","0.07693"
"27796","166.74000","13.89527","0.07771"
"27866","167.16000","13.93024","0.07833"
"27936","167.58000","13.96522","0.07875"
"28006","168.00000","14.00020","0.07900"
"28076","168.42000","14.03529","0.08005"
"28146","168.84000","14.07027","0.08064"
"28216","169.26000","14.10525","0.08061"
"28286","169.68000","14.14016","0.08169"
"28356","170.10000","14.17520","0.08227"
"28426","170.52000","14.21024","0.08349"
"28496","170.94000","14.24522","0.08442"
"28566","171.36000","14.28019","0.08524"
"28636","171.78000","14.31517","0.08540"
"28706","172.20000","14.35021","0.08661"
"28776","172.62000","14.38524","0.08759"
"28846","173.04000","14.42022","0.08764"
"28916","173.46000","14.45526","0.08823"
"28986","173.88000","14.49017","0.08846"
"29056","174.30000","14.52521","0.08955"
"29126","174.72000","14.56025","0.09067"
"29196","175.14000","14.59522","0.09189"
"29266","175.56000","14.63014","0.09279"
"29336","175.98000","14.66518","0.09285"
"29406","176.40000","14.70021","0.09432"
"29476","176.82000","14.73519","0.09545"
"29546","177.24000","14.77017","0.09640"
"29616","177.66000","14.80520","0.09723"
"29686","178.08000","14.84024","0.09880"
"29756","178.50000","14.87522","0.10033"
"29826","178.92000","14.91025","0.10139"
"29896","179.34000","14.94517","0.10313"
"29966","179.76000","14.98027","0.10492"
"30036","180.18000","15.01524","0.10715"
"30106","180.60000","15.05028","0.10809"
"30176","181.02000","15.08520","0.11031"
"30246","181.44000","15.12024","0.11332"
"30316","181.86000","15.15527","0.11603"
"30386","182.28000","15.19019","0.11906"
"30456","182.70000","15.22523","0.12007"
"30526","183.12000","15.26014","0.12169"
"30596","183.54000","15.29518","0.12426"
"30666","183.96000","15.33028","0.12668"
"30736","184.38000","15.36525","0.13014"
"30806","184.80000","15.40023","0.13009"
"30876","185.22000","15.43521","0.13182"
"30946","185.64000","15.47024","0.13387"
"31016","186.06000","15.50528","0.13573"
"31086","186.48000","15.54032","0.13861"
"31156","186.90000","15.57517","0.14056"
"31226","187.32000","15.61021","0.14222"
"31296","187.74000","15.64525","0.14365"
"31366","188.16000","15.68022","0.14537"
"31436","188.58000","15.71514","0.14665"
"31506","189.00000","15.75018","0.14891"
"31576","189.42000","15.78521","0.15002"
"31646","189.84000","15.82025","0.14883"
"31716","190.26000","15.85523","0.15132"
"31786","190.68000","15.89014","0.15239"
"31856","191.10000","15.92518","0.15422"
"31926","191.52000","15.96022","0.14877"
"31996","191.94000","15.99525","0.15173"
"32066","192.36000","16.03023","0.15378"
"32136","192.78000","16.06521","0.15447"
"32206","193.20000","16.10019","0.15180"
"32276","193.62000","16.13522","0.15398"
"32346","194.04000","16.17020","0.15428"
"32416","194.46000","16.20523","0.15532"
"32486","194.88000","16.24021","0.15744"
"32556","195.30000","16.27525","0.15926"
"32626","195.72000","16.31023","0.16022"
"32696","196.14000","16.34526","0.16195"
"32766","196.56000","16.38018","0.16358"
"32836","196.98000","16.41522","0.16619"
"32906","197.40000","16.45025","0.16861"
"32976","197.82000","16.48523","0.17138"
"33046","198.24000","16.52021","0.17154"
"33116","198.66000","16.55518","0.17474"
"33186","199.08000","16.59022","0.17292"
"33256","199.50000","16.62520","0.12532"
"33326","199.92000","16.66023","0.12995"
"33396","200.34000","16.69515","0.12664"
"33466","200.76000","16.73025","0.13236"
"33536","201.18000","16.76528","0.13429"
"33606","201.60000","16.80026","0.13363"
"33676","202.02000","16.83518","0.13768"
"33746","202.44000","16.87015","0.13899"
"33816","202.86000","16.90519","0.13971"
"33886","203.28000","16.94029","0.14307"
"33956","203.70000","16.97527","0.14309"
"34026","204.12000","17.01018","0.14537"
"34096","204.54000","17.04516","0.14680"
"34166","204.96000","17.08019","0.14547"
"34236","205.38000","17.11523","0.14835"
"34306","205.80000","17.15021","0.14889"
"34376","206.22000","17.18518","0.15012"
"34446","206.64000","17.22022","0.15301"
"34516","207.06000","17.25526","0.15421"
"34586","207.48000","17.29018","0.15707"
"34656","207.90000","17.32521","0.15674"
"34726","208.32000","17.36019","0.15822"
"34796","208.74000","17.39529","0.15353"
"34866","209.16000","17.43026","0.15427"
"34936","209.58000","17.46524","0.15617"
"35006","210.00000","17.50022","0.15513"
"35076","210.42000","17.53519","0.15629"
"35146","210.84000","17.57023","0.15772"
"35216","211.26000","17.60521","0.15976"
"35286","211.68000","17.64018","0.16120"
"35356","212.10000","17.67522","0.16195"
"35426","212.52000","17.71014","0.16452"
"35496","212.94000","17.74523","0.16555"
"35566","213.36000","17.78021","0.16730"
"35636","213.78000","17.81519","0.16696"
"35706","214.20000","17.85022","0.16776"
"35776","214.62000","17.88526","0.17013"
"35846","215.04000","17.92024","0.17203"
"35916","215.46000","17.95522","0.17404"
"35986","215.88000","17.99019","0.17589"
"36056","216.30000","18.02517","0.17816"
"36126","216.72000","18.06021","0.17908"
"36196","217.14000","18.09518","0.18155"
"36266","217.56000","18.13016","0.18351"
"36336","217.98000","18.16526","0.18488"
"36406","218.40000","18.20023","0.18679"
"36476","218.82000","18.23527","0.18838"
"36546","219.24000","18.27019","0.18992"
"36616","219.66000","18.30522","0.19116"
"36686","220.08000","18.34026","0.18977"
"36756","220.50000","18.37524","0.19100"
"36826","220.92000","18.41027","0.19266"
"36896","221.34000","18.44519","0.18688"
"36966","221.76000","18.48017","0.18734"
"37036","222.18000","18.51521","0.18904"
"37106","222.60000","18.55024","0.19069"
"37176","223.02000","18.58522","0.19234"
"37246","223.44000","18.62020","0.19379"
"37316","223.86000","18.65523","0.19567"
"37386","224.28000","18.69027","0.19787"
"37456","224.70000","18.72524","0.19923"
"37526","225.12000","18.76022","0.19934"
"37596","225.54000","18.79520","0.20097"
"37666","225.96000","18.83024","0.20204"
"37736","226.38000","18.86527","0.08562"
"37806","226.80000","18.90019","0.08847"
"37876","227.22000","18.93517","0.08874"
"37946","227.64000","18.97020","0.08997"
"38016","228.06000","19.00518","0.09198"
"38086","228.48000","19.04022","0.08645"
"38156","228.90000","19.07513","0.07802"
"38226","229.32000","19.11017","0.07997"
"38296","229.74000","19.14521","0.08000"
"38366","230.16000","19.18024","0.08157"
"38436","230.58000","19.21522","0.08304"
"38506","231.00000","19.25014","0.08521"
"38576","231.42000","19.28523","0.08722"
"38646","231.84000","19.32027","0.08975"
"38716","232.26000","19.35525","0.09168"
"38786","232.68000","19.39022","0.09337"
"38856","233.10000","19.42520","0.09542"
"38926","233.52000","19.46024","0.09695"
"38996","233.94000","19.49515","0.09942"
"39066","234.36000","19.53019","0.10192"
"39136","234.78000","19.56523","0.10417"
"39206","235.20000","19.60026","0.10774"
"39276","235.62000","19.63524","0.10997"
"39346","236.04000","19.67022","0.11339"
"39416","236.46000","19.70519","0.11675"
"39486","236.88000","19.74023","0.12169"
"39556","237.30000","19.77527","0.12622"
"39626","237.72000","19.81025","0.12998"
"39696","238.14000","19.84522","0.13235"
"39766","238.56000","19.88014","0.13549"
"39836","238.98000","19.91518","0.13832"
"39906","239.40000","19.95021","0.14111"
"39976","239.82000","19.98525","0.14410"
"40046","240.24000","20.02017","0.14675"
"40116","240.66000","20.05514","0.14869"
"40186","241.08000","20.09018","0.14758"
"40256","241.50000","20.12522","0.15069"
"40326","241.92000","20.16025","0.03013"
"40396","242.34000","20.19517","0.03195"
"40466","242.76000","20.23021","0.04288"
"40536","243.18000","20.26524","0.03994"
"40606","243.60000","20.30028","0.03545"
"40676","244.02000","20.33520","0.04846"
"40746","244.44000","20.37017","0.04305"
"40816","244.86000","20.40515","0.04616"
"40886","245.28000","20.44025","0.05174"
"40956","245.70000","20.47522","0.04556"
"41026","246.12000","20.51020","0.05577"
"41096","246.54000","20.54518","0.05117"
"41166","246.96000","20.58022","0.05883"
"41236","247.38000","20.61525","0.05797"
"41306","247.80000","20.65023","0.05966"
"41376","248.22000","20.68521","0.06650"
"41446","248.64000","20.72024","0.06893"
"41516","249.06000","20.75528","0.07011"
"41586","249.48000","20.79026","0.07204"
"41656","249.90000","20.82523","0.07749"
"41726","250.32000","20.86021","0.08002"
"41796","250.74000","20.89525","0.07847"
"41866","251.16000","20.93022","0.08079"
"41936","251.58000","20.96526","0.08158"
"42006","252.00000","21.00018","0.08677"
"42076","252.42000","21.03515","0.08750"
"42146","252.84000","21.07019","0.08666"
"42216","253.26000","21.10523","0.08883"
"42286","253.68000","21.14021","0.08975"
"42356","254.10000","21.17518","0.09390"
"42426","254.52000","21.21028","0.09634"
"42496","254.94000","21.24525","0.09615"
"42566","255.36000","21.28029","0.09661"
"42636","255.78000","21.31515","0.09819"
"42706","256.20000","21.35018","0.10054"
"42776","256.62000","21.38522","0.10506"
"42846","257.04000","21.42020","0.10849"
"42916","257.46000","21.45518","0.10969"
"42986","257.88000","21.49015","0.10995"
"43056","258.30000","21.52519","0.11225"
"43126","258.72000","21.56023","0.11506"
"43196","259.14000","21.59520","0.11958"
"43266","259.56000","21.63018","0.12473"
"43336","259.98000","21.66515","0.12984"
"43406","260.40000","21.70025","0.13270"
"43476","260.82000","21.73523","0.13512"
"43546","261.24000","21.77027","0.13686"
"43616","261.66000","21.80518","0.13700"
"43686","262.08000","21.84016","0.13385"
"43756","262.50000","21.87519","0.13810"
"43826","262.92000","21.91023","0.14057"
"43896","263.34000","21.94521","0.14377"
"43966","263.76000","21.98018","0.14678"
"44036","264.18000","22.01522","0.14904"
"44106","264.60000","22.05020","0.15166"
"44176","265.02000","22.08524","0.15373"
"44246","265.44000","22.12016","0.15497"
"44316","265.86000","22.15525","0.05705"
"44386","266.28000","22.19029","0.06045"
"44456","266.70000","22.22520","0.06251"
"44526","267.12000","22.26018","0.06422"
"44596","267.54000","22.29522","0.06935"
"44666","267.96000","22.33019","0.07056"
"44736","268.38000","22.36517","0.07543"
"44806","268.80000","22.40021","0.07527"
"44876","269.22000","22.43513","0.07604"
"44946","269.64000","22.47016","0.07785"
"45016","270.06000","22.50526","0.08045"
"45086","270.48000","22.54023","0.08075"
"45156","270.90000","22.57521","0.08129"
"45226","271.32000","22.61025","0.08226"
"45296","271.74000","22.64529","0.08426"
"45366","272.16000","22.68026","0.08390"
"45436","272.58000","22.71530","0.08448"
"45506","273.00000","22.75022","0.08481"
"45576","273.42000","22.78519","0.08643"
"45646","273.84000","22.82023","0.08916"
"45716","274.26000","22.85521","0.09053"
"45786","274.68000","22.89018","0.09183"
"45856","275.10000","22.92516","0.09292"
"45926","275.52000","22.96020","0.09390"
"45996","275.94000","22.99523","0.09577"
"46066","276.36000","23.03021","0.09813"
"46136","276.78000","23.06519","0.10065"
"46206","277.20000","23.10016","0.10206"
"46276","277.62000","23.13526","0.10377"
"46346","278.04000","23.17024","0.10678"
"46416","278.46000","23.20522","0.10940"
"46486","278.88000","23.24019","0.11194"
"46556","279.30000","23.27517","0.11551"
"46626","279.72000","23.31027","0.11929"
"46696","280.14000","23.34524","0.12247"
"46766","280.56000","23.38022","0.12590"
"46836","280.98000","23.41520","0.12789"
"46906","281.40000","23.45023","0.13195"
"46976","281.82000","23.48521","0.13413"
"47046","282.24000","23.52024","0.13675"
"47116","282.66000","23.55516","0.13951"
"47186","283.08000","23.59026","0.14300"
"47256","283.50000","23.62523","0.14464"
"47326","283.92000","23.66027","0.14692"
"47396","284.34000","23.69525","0.13896"
"47466","284.76000","23.73017","0.14326"
"47536","285.18000","23.76520","0.14600"
"47606","285.60000","23.80018","0.14772"
"47676","286.02000","23.83522","0.15090"
"47746","286.44000","23.87019","0.15402"
"47816","286.86000","23.90523","0.15489"
"47886","287.28000","23.94020","0.15800"
"47956","287.70000","23.97524","0.16106"
"48026","288.12000","24.01016","0.16292"
"48096","288.54000","24.04526","0.16648"
"48166","288.96000","24.08024","0.16884"
"48236","289.38000","24.11527","0.17170"
"48306","289.80000","24.15025","0.17407"
"48376","290.22000","24.18516","0.17704"
"48446","290.64000","24.22020","0.17976"
"48516","291.06000","24.25524","0.18080"
"48586","291.48000","24.29021","0.17491"
"48656","291.90000","24.32525","0.16593"
"48726","292.32000","24.36011","0.16232"
"48796","292.74000","24.39520","0.06202"
"48866","293.16000","24.43024","0.04667"
"48936","293.58000","24.46522","0.04357"
"49006","294.00000","24.50019","0.04542"
"49076","294.42000","24.53517","0.04635"
"49146","294.84000","24.57027","0.04673"
"49216","295.26000","24.60525","0.04863"
"49286","295.68000","24.64017","0.04891"
"49356","296.10000","24.67520","0.04990"
"49426","296.52000","24.71018","0.05177"
"49496","296.94000","24.74527","0.05148"
"49566","297.36000","24.78019","0.05256"
"49636","297.78000","24.81517","0.05376"
"49706","298.20000","24.85020","0.05459"
"49776","298.62000","24.88518","0.05447"
"49846","299.04000","24.92022","0.05602"
"49916","299.46000","24.95520","0.05702"
"49986","299.88000","24.99017","0.05757"
"50056","300.30000","25.02527","0.05870"
"50126","300.72000","25.06024","0.05998"
"50196","301.14000","25.09528","0.05993"
"50266","301.56000","25.13020","0.06099"
"50336","301.98000","25.16517","0.06166"
"50406","302.40000","25.20021","0.06220"
"50476","302.82000","25.23525","0.06307"
"50546","303.24000","25.27023","0.06482"
"50616","303.66000","25.30514","0.06597"
"50686","304.08000","25.34018","0.06618"
"50756","304.50000","25.37522","0.01511"
"50826","304.92000","25.41025","0.01592"
"50896","305.34000","25.44523","0.01365"
"50966","305.76000","25.48021","0.01319"
"51036","306.18000","25.51530","0.01302"
"51106","306.60000","25.55028","0.01353"
"51176","307.02000","25.58526","0.01390"
"51246","307.44000","25.62017","0.01415"
"51316","307.86000","25.65521","0.01520"
"51386","308.28000","25.69025","0.01590"
"51456","308.70000","25.72523","0.01595"
"51526","309.12000","25.76020","0.01666"
"51596","309.54000","25.79512","0.01629"
"51666","309.96000","25.83021","0.01759"
"51736","310.38000","25.86525","0.01775"
"51806","310.80000","25.90023","0.01768"
"51876","311.22000","25.93521","0.01810"
"51946","311.64000","25.97024","0.01894"
"52016","312.06000","26.00528","0.01962"
"52086","312.48000","26.04025","0.01969"
"52156","312.90000","26.07517","0.02036"
"52226","313.32000","26.11021","0.02049"
"52296","313.74000","26.14519","0.02122"
"52366","314.16000","26.18022","0.02188"
"52436","314.58000","26.21520","0.02174"
"52506","315.00000","26.25018","0.02151"
"52576","315.42000","26.28515","0.02234"
"52646","315.84000","26.32019","0.02234"
"52716","316.26000","26.35523","0.02245"
"52786","316.68000","26.39026","0.02315"
"52856","317.10000","26.42518","0.02300"
"52926","317.52000","26.46021","0.02086"
"52996","317.94000","26.49525","0.02131"
"53066","318.36000","26.53023","0.02178"
"53136","318.78000","26.56521","0.02228"
"53206","319.20000","26.60018","0.02200"
"53276","319.62000","26.63522","0.02287"
"53346","320.04000","26.67020","0.02342"
"53416","320.46000","26.70523","0.02394"
"53486","320.88000","26.74015","0.02378"
"53556","321.30000","26.77519","0.02412"
"53626","321.72000","26.81022","0.01965"
"53696","322.14000","26.84526","0.01887"
"53766","322.56000","26.88018","0.02013"
"53836","322.98000","26.91521","0.02033"
"53906","323.40000","26.95025","0.02062"
"53976","323.82000","26.98523","0.02042"
"54046","324.24000","27.02027","0.02170"
"54116","324.66000","27.05518","0.02209"
"54186","325.08000","27.09016","0.02147"
"54256","325.50000","27.12520","0.02264"
"54326","325.92000","27.16023","0.02288"
"54396","326.34000","27.19521","0.02270"
"54466","326.76000","27.23019","0.02351"
"54536","327.18000","27.26522","0.02367"
"54606","327.60000","27.30026","0.02239"
"54676","328.02000","27.33524","0.02302"
"54746","328.44000","27.37021","0.02338"
"54816","328.86000","27.40519","0.02324"
"54886","329.28000","27.44023","0.02312"
"54956","329.70000","27.47526","0.02386"
"55026","330.12000","27.51024","0.02446"
"55096","330.54000","27.54522","0.02436"
"55166","330.96000","27.58020","0.02503"
"55236","331.38000","27.61523","0.02537"
"55306","331.80000","27.65027","0.02618"
"55376","332.22000","27.68518","0.02624"
"55446","332.64000","27.72016","0.02647"
"55516","333.06000","27.75520","0.02651"
"55586","333.48000","27.79024","0.02643"
"55656","333.90000","27.82521","0.02649"
"55726","334.32000","27.86019","0.02742"
"55796","334.74000","27.89523","0.02778"
"55866","335.16000","27.93026","0.02809"
"55936","335.58000","27.96524","0.02835"
"56006","336.00000","28.00022","0.02894"
"56076","336.42000","28.03519","0.02883"
"56146","336.84000","28.07023","0.02909"
"56216","337.26000","28.10521","0.02957"
"56286","337.68000","28.14025","0.03013"
"56356","338.10000","28.17516","0.03109"
"56426","338.52000","28.21014","0.03133"
"56496","338.94000","28.24524","0.03162"
"56566","339.36000","28.28021","0.03148"
"56636","339.78000","28.31519","0.03222"
"56706","340.20000","28.35022","0.03220"
"56776","340.62000","28.38526","0.03297"
"56846","341.04000","28.42024","0.03124"
"56916","341.46000","28.45528","0.02916"
"56986","341.88000","28.49019","0.02972"
"57056","342.30000","28.52517","0.03056"
"57126","342.72000","28.56021","0.03172"
"57196","343.14000","28.59524","0.03243"
"57266","343.56000","28.63022","0.03309"
"57336","343.98000","28.66514","0.03357"
"57406","344.40000","28.70023","0.03460"
"57476","344.82000","28.73527","0.03512"
"57546","345.24000","28.77018","0.03567"
"57616","345.66000","28.80522","0.03573"
"57686","346.08000","28.84020","0.03679"
"57756","346.50000","28.87524","0.03723"
"57826","346.92000","28.91021","0.03841"
"57896","347.34000","28.94525","0.03943"
"57966","347.76000","28.98022","0.04001"
"58036","348.18000","29.01520","0.04125"
"58106","348.60000","29.05024","0.04141"
"58176","349.02000","29.08521","0.04236"
"58246","349.44000","29.12019","0.04281"
"58316","349.86000","29.15517","0.04348"
"58386","350.28000","29.19021","0.04433"
"58456","350.70000","29.22524","0.04478"
"58526","351.12000","29.26022","0.04590"
"58596","351.54000","29.29514","0.04644"
"58666","351.96000","29.33018","0.04686"
"58736","352.38000","29.36521","0.04759"
"58806","352.80000","29.40025","0.04927"
"58876","353.22000","29.43522","0.04875"
"58946","353.64000","29.47020","0.04940"
"59016","354.06000","29.50518","0.04971"
"59086","354.48000","29.54021","0.05109"
"59156","354.90000","29.57519","0.05214"
"59226","355.32000","29.61017","0.05103"
"59296","355.74000","29.64521","0.03555"
"59366","356.16000","29.68024","0.03697"
"59436","356.58000","29.71522","0.03793"
"59506","357.00000","29.75020","0.03907"
"59576","357.42000","29.78523","0.03948"
"59646","357.84000","29.82027","0.04037"
"59716","358.26000","29.85525","0.04088"
"59786","358.68000","29.89028","0.04158"
"59856","359.10000","29.92514","0.04250"
"59926","359.52000","29.96018","0.04235"
"59996","359.94000","29.99527","0.04238"
"60066","360.36000","30.03025","0.04332"
"60136","360.78000","30.06517","0.04401"
"60206","361.20000","30.10015","0.04425"
"60276","361.62000","30.13518","0.04486"
"60346","362.04000","30.17022","0.04556"
"60416","362.46000","30.20525","0.04609"
"60486","362.88000","30.24017","0.04631"
"60556","363.30000","30.27521","0.04604"
"60626","363.72000","30.31018","0.04664"
"60696","364.14000","30.34522","0.04715"
"60766","364.56000","30.38020","0.04799"
"60836","364.98000","30.41518","0.04884"
"60906","365.40000","30.45021","0.04961"
"60976","365.82000","30.48525","0.05025"
"61046","366.24000","30.52023","0.05085"
"61116","366.66000","30.55520","0.05145"
"61186","367.08000","30.59018","0.05209"
"61256","367.50000","30.62522","0.05313"
"61326","367.92000","30.66025","0.05353"
"61396","368.34000","30.69523","0.05420"
"61466","368.76000","30.73021","0.05491"
"61536","369.18000","30.76518","0.05583"
"61606","369.60000","30.80022","0.05668"
"61676","370.02000","30.83526","0.05665"
"61746","370.44000","30.87023","0.05651"
"61816","370.86000","30.90521","0.05711"
"61886","371.28000","30.94025","0.05745"
"61956","371.70000","30.97522","0.05729"
"62026","372.12000","31.01020","0.05888"
"62096","372.54000","31.04518","0.05901"
"62166","372.96000","31.08027","0.06005"
"62236","373.38000","31.11525","0.06103"
"62306","373.80000","31.15029","0.06271"
"62376","374.22000","31.18521","0.06349"
"62446","374.64000","31.22024","0.06401"
"62516","375.06000","31.25521","0.06601"
"62586","375.48000","31.29025","0.06694"
"62656","375.90000","31.32529","0.06804"
"62726","376.32000","31.36021","0.07054"
"62796","376.74000","31.39519","0.07158"
"62866","377.16000","31.43022","0.07215"
"62936","377.58000","31.46520","0.07233"
"63006","378.00000","31.50018","0.07364"
"63076","378.42000","31.53515","0.07411"
"63146","378.84000","31.57019","0.07561"
"63216","379.26000","31.60522","0.07640"
"63286","379.68000","31.64020","0.07719"
"63356","380.10000","31.67524","0.07810"
"63426","380.52000","31.71016","0.07814"
"63496","380.94000","31.74519","0.07921"
"63566","381.36000","31.78023","0.07852"
"63636","381.78000","31.81520","0.06819"
"63706","382.20000","31.85018","0.06589"
"63776","382.62000","31.88516","0.06811"
"63846","383.04000","31.92019","0.06785"
"63916","383.46000","31.95523","0.06752"
"63986","383.88000","31.99015","0.06952"
"64056","384.30000","32.02519","0.07200"
"64126","384.72000","32.06023","0.07182"
"64196","385.14000","32.09526","0.07068"
"64266","385.56000","32.13024","0.07228"
"64336","385.98000","32.16515","0.07371"
"64406","386.40000","32.20025","0.07440"
"64476","386.82000","32.23523","0.07482"
"64546","387.24000","32.27020","0.07553"
"64616","387.66000","32.30524","0.07593"
"64686","388.08000","32.34022","0.07666"
"64756","388.50000","32.37526","0.07720"
"64826","388.92000","32.41023","0.07705"
"64896","389.34000","32.44521","0.07793"
"64966","389.76000","32.48013","0.07819"
"65036","390.18000","32.51516","0.07841"
"65106","390.60000","32.55020","0.07841"
"65176","391.02000","32.58523","0.07879"
"65246","391.44000","32.62021","0.07929"
"65316","391.86000","32.65519","0.06071"
"65386","392.28000","32.69023","0.06129"
"65456","392.70000","32.72520","0.06175"
"65526","393.12000","32.76024","0.06322"
"65596","393.54000","32.79516","0.06647"
"65666","393.96000","32.83019","0.06708"
"65736","394.38000","32.86523","0.06846"
"65806","394.80000","32.90026","0.07039"
"65876","395.22000","32.93518","0.07154"
"65946","395.64000","32.97016","0.07225"
"66016","396.06000","33.00526","0.07324"
"66086","396.48000","33.04029","0.07429"
"66156","396.90000","33.07521","0.07612"
"66226","397.32000","33.11019","0.07598"
"66296","397.74000","33.14516","0.07640"
"66366","398.16000","33.18026","0.07732"
"66436","398.58000","33.21529","0.07758"
"66506","399.00000","33.25021","0.07819"
"66576","399.42000","33.28519","0.07862"
"66646","399.84000","33.32017","0.07880"
"66716","400.26000","33.35521","0.07940"
"66786","400.68000","33.39024","0.08009"
"66856","401.10000","33.42516","0.08074"
"66926","401.52000","33.46020","0.08135"
"66996","401.94000","33.49523","0.01576"
"67066","402.36000","33.53021","-0.00106"
"67136","402.78000","33.56525","0.02046"
"67206","403.20000","33.60016","-0.00061"
"67276","403.62000","33.63520","0.00099"
"67346","404.04000","33.67023","0.00499"
"67416","404.46000","33.70521","0.00133"
"67486","404.88000","33.74025","0.00494"
"67556","405.30000","33.77523","0.00395"
"67626","405.72000","33.81020","-0.00022"
"67696","406.14000","33.84518","0.00385"
"67766","406.56000","33.88021","0.00782"
"67836","406.98000","33.91513","0.00081"
"67906","407.40000","33.95017","0.00112"
"67976","407.82000","33.98521","0.00550"
"68046","408.24000","34.02024","0.00530"
"68116","408.66000","34.05516","0.00154"
"68186","409.08000","34.09020","0.00214"
"68256","409.50000","34.12524","0.00358"
"68326","409.92000","34.16021","0.00485"
"68396","410.34000","34.19525","0.00341"
"68466","410.76000","34.23022","0.00336"
"68536","411.18000","34.26520","0.00393"
"68606","411.60000","34.30024","0.00426"
"68676","412.02000","34.33527","0.00394"
"68746","412.44000","34.37019","0.00374"
"68816","412.86000","34.40511","0.00486"
"68886","413.28000","34.44027","0.00433"
"68956","413.70000","34.47524","0.00413"
"69026","414.12000","34.51022","0.00344"
"69096","414.54000","34.54519","0.00475"
"69166","414.96000","34.58017","0.00486"
"69236","415.38000","34.61521","0.00495"
"69306","415.80000","34.65025","0.00404"
"69376","416.22000","34.68522","0.00476"
"69446","416.64000","34.72020","0.00577"
"69516","417.06000","34.75518","0.00534"
"69586","417.48000","34.79021","0.00527"
"69656","417.90000","34.82519","0.00448"
"69726","418.32000","34.86017","0.00564"
"69796","418.74000","34.89515","0.00587"
"69866","419.16000","34.93024","0.00559"
"69936","419.58000","34.96522","0.00561"
"70006","420.00000","35.00025","0.00524"
"70076","420.42000","35.03517","0.00635"
"70146","420.84000","35.07021","0.00608"
"70216","421.26000","35.10524","0.00618"
"70286","421.68000","35.14028","0.00575"
"70356","422.10000","35.17520","0.00600"
"70426","422.52000","35.21017","0.00664"
"70496","422.94000","35.24521","0.00689"
"70566","423.36000","35.28019","0.00665"
"70636","423.78000","35.31523","0.00659"
"70706","424.20000","35.35014","0.00634"
"70776","424.62000","35.38524","0.00700"
"70846","425.04000","35.42022","0.00715"
"70916","425.46000","35.45519","0.00772"
"70986","425.88000","35.49017","0.00717"
"71056","426.30000","35.52521","0.00715"
"71126","426.72000","35.56024","0.00755"
"71196","427.14000","35.59522","0.00802"
"71266","427.56000","35.63026","0.00863"
"71336","427.98000","35.66517","0.00881"
"71406","428.40000","35.70021","0.00859"
"71476","428.82000","35.73524","0.00831"
"71546","429.24000","35.77022","0.00839"
"71616","429.66000","35.80520","0.00871"
"71686","430.08000","35.84018","0.00955"
"71756","430.50000","35.87522","0.00941"
"71826","430.92000","35.91025","0.00911"
"71896","431.34000","35.94523","0.00919"
"71966","431.76000","35.98021","0.00951"
"72036","432.18000","36.01518","0.00973"
"72106","432.60000","36.05022","0.01055"
"72176","433.02000","36.08525","0.01022"
"72246","433.44000","36.12017","0.01071"
"72316","433.86000","36.15515","0.01078"
"72386","434.28000","36.19019","0.01072"
"72456","434.70000","36.22522","0.01076"
"72526","435.12000","36.26020","0.01100"
"72596","435.54000","36.29517","0.01152"
"72666","435.96000","36.33021","0.01162"
"72736","436.38000","36.36525","0.01211"
"72806","436.80000","36.40023","0.01198"
"72876","437.22000","36.43526","0.01223"
"72946","437.64000","36.47012","0.01204"
"73016","438.06000","36.50522","0.01289"
"73086","438.48000","36.54026","0.01312"
"73156","438.90000","36.57529","0.01407"
"73226","439.32000","36.61021","0.01398"
"73296","439.74000","36.64518","0.01407"
"73366","440.16000","36.68022","0.01418"
"73436","440.58000","36.71520","0.01473"
"73506","441.00000","36.75024","0.01534"
"73576","441.42000","36.78521","0.01525"
"73646","441.84000","36.82025","0.01600"
"73716","442.26000","36.85522","0.01584"
"73786","442.68000","36.89026","0.01672"
"73856","443.10000","36.92518","0.01267"
"73926","443.52000","36.96021","0.00917"
"73996","443.94000","36.99525","0.00896"
"74066","444.36000","37.03023","0.00977"
"74136","444.78000","37.06533","0.00790"
"74206","445.20000","37.10018","0.00797"
"74276","445.62000","37.13522","0.00954"
"74346","446.04000","37.17026","0.00960"
"74416","446.46000","37.20523","0.00972"
"74486","446.88000","37.24015","0.00916"
"74556","447.30000","37.27513","0.00969"
"74626","447.72000","37.31022","0.00962"
"74696","448.14000","37.34526","0.00949"
"74766","448.56000","37.38024","0.01007"
"74836","448.98000","37.41521","0.01019"
"74906","449.40000","37.45019","0.01039"
"74976","449.82000","37.48523","0.01088"
"75046","450.24000","37.52026","0.01022"
"75116","450.66000","37.55524","0.01016"
"75186","451.08000","37.59022","0.01126"
"75256","451.50000","37.62519","0.01072"
"75326","451.92000","37.66023","0.01122"
"75396","452.34000","37.69521","0.01121"
"75466","452.76000","37.73024","0.01143"
"75536","453.18000","37.76522","0.01192"
"75606","453.60000","37.80020","0.01186"
"75676","454.02000","37.83524","0.01210"
"75746","454.44000","37.87027","0.01244"
"75816","454.86000","37.90519","0.01267"
"75886","455.28000","37.94023","0.01273"
"75956","455.70000","37.97526","0.01317"
"76026","456.12000","38.01024","0.01280"
"76096","456.54000","38.04522","0.01365"
"76166","456.96000","38.08019","0.01342"
"76236","457.38000","38.11523","0.01436"
"76306","457.80000","38.15021","0.01373"
"76376","458.22000","38.18518","0.01439"
"76446","458.64000","38.22016","0.01553"
"76516","459.06000","38.25520","0.01503"
"76586","459.48000","38.29023","0.01521"
"76656","459.90000","38.32527","0.01516"
"76726","460.32000","38.36019","0.01563"
"76796","460.74000","38.39516","0.01672"
"76866","461.16000","38.43020","0.01671"
"76936","461.58000","38.46530","0.01640"
"77006","462.00000","38.50027","0.01728"
"77076","462.42000","38.53519","0.01737"
"77146","462.84000","38.57017","0.01810"
"77216","463.26000","38.60521","0.01821"
"77286","463.68000","38.64018","0.01853"
"77356","464.10000","38.67516","0.01882"
"77426","464.52000","38.71020","0.01949"
"77496","464.94000","38.74523","0.01945"
"77566","465.36000","38.78027","0.01946"
"77636","465.78000","38.81519","0.01948"
"77706","466.20000","38.85022","0.01966"
"77776","466.62000","38.88520","0.01946"
"77846","467.04000","38.92030","0.02027"
"77916","467.46000","38.95527","0.02070"
"77986","467.88000","38.99025","0.02096"
"78056","468.30000","39.02517","0.02115"
"78126","468.72000","39.06020","0.02146"
"78196","469.14000","39.09518","0.02127"
"78266","469.56000","39.13022","0.02223"
"78336","469.98000","39.16519","0.02169"
"78406","470.40000","39.20017","0.02225"
"78476","470.82000","39.23521","0.02280"
"78546","471.24000","39.27024","0.02280"
"78616","471.66000","39.30522","0.02334"
"78686","472.08000","39.34014","0.02341"
"78756","472.50000","39.37523","0.02430"
"78826","472.92000","39.41027","0.02424"
"78896","473.34000","39.44524","0.02487"
"78966","473.76000","39.48022","0.02526"
"79036","474.18000","39.51520","0.02547"
"79106","474.60000","39.55018","0.02518"
"79176","475.02000","39.58521","0.02643"
"79246","475.44000","39.62019","0.02635"
"79316","475.86000","39.65516","0.02665"
"79386","476.28000","39.69020","0.02683"
"79456","476.70000","39.72519","0.02714"
"79526","477.12000","39.76022","0.02746"
"79596","477.54000","39.79526","0.02723"
"79666","477.96000","39.83023","-0.00079"
"79736","478.38000","39.86526","-0.00020"
"79806","478.80000","39.90025","-0.00041"
"79876","479.22000","39.93528","-0.00068"
"79946","479.64000","39.97020","-0.00051"
"80016","480.06000","40.00518","-0.00097"
"80086","480.48000","40.04021","-0.00120"
"80156","480.90000","40.07525","0.00011"
"80226","481.32000","40.11022","-0.00033"
"80296","481.74000","40.14520","-0.00062"
"80366","482.16000","40.18018","-0.00018"
"80436","482.58000","40.21522","-0.00044"
"80506","483.00000","40.25019","-0.00074"
"80576","483.42000","40.28523","-0.00009"
"80646","483.84000","40.32020","-0.00066"
"80716","484.26000","40.35525","-0.00068"
"80786","484.68000","40.39028","0.00010"
"80856","485.10000","40.42520","-0.00056"
"80926","485.52000","40.46018","-0.00040"
"80996","485.94000","40.49521","-0.00092"
"81066","486.36000","40.53019","-0.00024"
"81136","486.78000","40.56523","-0.00081"
"81206","487.20000","40.60020","-0.00045"
"81276","487.62000","40.63518","-0.00023"
"81346","488.04000","40.67015","-0.00056"
"81416","488.46000","40.70519","-0.00021"
"81486","488.88000","40.74023","0.00029"
"81556","489.30000","40.77515","-0.00082"
"81626","489.72000","40.81018","-0.00049"
"81696","490.14000","40.84528","0.00010"
"81766","490.56000","40.88026","-0.00051"
"81836","490.98000","40.91523","-0.00054"
"81906","491.40000","40.95015","-0.00005"
"81976","491.82000","40.98518","-0.00069"
"82046","492.24000","41.02022","-0.00085"
"82116","492.66000","41.05520","0.00013"
"82186","493.08000","41.09018","-0.00107"
"82256","493.50000","41.12522","-0.00051"
"82326","493.92000","41.16025","0.00011"
"82396","494.34000","41.19523","-0.00050"
"82466","494.76000","41.23014","-0.00065"
"82536","495.18000","41.26518","0.00020"
"82606","495.60000","41.30022","-0.00047"
"82676","496.02000","41.33525","-0.00074"
"82746","496.44000","41.37029","0.00088"
"82816","496.86000","41.40515","-0.00051"
"82886","497.28000","41.44019","-0.00096"
"82956","497.70000","41.47522","0.00091"
"83026","498.12000","41.51026","-0.00066"
"83096","498.54000","41.54517","-0.00080"
"83166","498.96000","41.58015","0.00045"
"83236","499.38000","41.61518","-0.00014"
"83306","499.80000","41.65023","-0.00072"
"83376","500.22000","41.68526","0.00085"
"83446","500.64000","41.72024","-0.00036"
"83516","501.06000","41.75516","-0.00049"
"83586","501.48000","41.79025","0.00076"
"83656","501.90000","41.82523","-0.00061"
"83726","502.32000","41.86021","-0.00069"
"83796","502.74000","41.89524","0.00081"
"83866","503.16000","41.93016","-0.00082"
"83936","503.58000","41.96525","-0.00030"
"84006","504.00000","42.00023","0.00123"
"84076","504.42000","42.03521","-0.00059"
"84146","504.84000","42.07025","-0.00038"
"84216","505.26000","42.10522","0.00054"
"84286","505.68000","42.14020","-0.00074"
"84356","506.10000","42.17524","-0.00004"
"84426","506.52000","42.21015","0.00065"
"84496","506.94000","42.24519","-0.00080"
"84566","507.36000","42.28029","0.00069"
"84636","507.78000","42.31527","0.00007"
"84706","508.20000","42.35019","-0.00050"
"84776","508.62000","42.38522","0.00186"
"84846","509.04000","42.42020","-0.00024"
"84916","509.46000","42.45517","-0.00058"
"84986","509.88000","42.49027","0.00160"
"85056","510.30000","42.52519","0.00001"
"85126","510.72000","42.56016","0.00001"
"85196","511.14000","42.59520","0.00080"
"85266","511.56000","42.63023","-0.00024"
"85336","511.98000","42.66515","0.00028"
"85406","512.40000","42.70013","0.00033"
"85476","512.82000","42.73523","0.00016"
"85546","513.24000","42.77026","0.00159"
"85616","513.66000","42.80524","0.00029"
"85686","514.08000","42.84015","0.00045"
"85756","514.50000","42.87519","0.00154"
"85826","514.92000","42.91023","0.00027"
"85896","515.34000","42.94521","0.00169"
"85966","515.76000","42.98019","0.00035"
"86016","516.05600","43.00488","0.00081"