File: Trajectories_together/161223_2Specimen_RawData_10.csv
"","V1","V2","V3"
"1","End date","12/23/2016",""
"2","Specimen label","21DG_71",""
"3","Maximum Load","0.74697","N"
"4","Time","Extension","Load"
"5","(s)","(mm)","(N)"
"6","0.00000","0.00000","0.00016"
"69","0.37800","0.03169","0.00048"
"132","0.75600","0.06326","0.00065"
"195","1.13400","0.09471","0.00103"
"258","1.51200","0.12622","0.00117"
"321","1.89000","0.15766","0.00121"
"384","2.26800","0.18917","0.00107"
"447","2.64600","0.22068","0.00143"
"510","3.02400","0.25219","0.00143"
"573","3.40200","0.28370","0.00137"
"636","3.78000","0.31521","0.00173"
"699","4.15800","0.34660","0.00252"
"762","4.53600","0.37823","0.00233"
"825","4.91400","0.40974","0.00260"
"888","5.29200","0.44113","0.00284"
"951","5.67000","0.47270","0.00261"
"1014","6.04800","0.50421","0.00317"
"1077","6.42600","0.53571","0.00321"
"1140","6.80400","0.56716","0.00389"
"1203","7.18200","0.59867","0.00391"
"1266","7.56000","0.63024","0.00383"
"1329","7.93800","0.66163","0.00381"
"1392","8.31600","0.69314","0.00417"
"1455","8.69400","0.72471","0.00411"
"1518","9.07200","0.75622","0.00463"
"1581","9.45000","0.78761","0.00463"
"1644","9.82800","0.81918","0.00502"
"1707","10.20600","0.85069","0.00488"
"1770","10.58400","0.88213","0.00512"
"1833","10.96200","0.91370","0.00553"
"1896","11.34000","0.94521","0.00576"
"1959","11.71800","0.97666","0.00544"
"2022","12.09600","1.00817","0.00597"
"2085","12.47400","1.03974","0.00646"
"2148","12.85200","1.07119","0.00646"
"2211","13.23000","1.10270","0.00636"
"2274","13.60800","1.13427","0.00695"
"2337","13.98600","1.16572","0.00700"
"2400","14.36400","1.19711","0.00708"
"2463","14.74200","1.22867","0.00742"
"2526","15.12000","1.26024","0.00731"
"2589","15.49800","1.29169","0.00783"
"2652","15.87600","1.32314","0.00812"
"2715","16.25400","1.35465","0.00835"
"2778","16.63200","1.38616","0.00842"
"2841","17.01000","1.41767","0.00866"
"2904","17.38800","1.44924","0.00850"
"2967","17.76600","1.48075","0.00876"
"3030","18.14400","1.51220","0.00908"
"3093","18.52200","1.54365","0.00939"
"3156","18.90000","1.57522","0.00934"
"3219","19.27800","1.60666","0.01012"
"3282","19.65600","1.63811","0.00939"
"3345","20.03400","1.66974","0.00998"
"3408","20.41200","1.70119","0.01010"
"3471","20.79000","1.73270","0.01007"
"3534","21.16800","1.76427","0.01045"
"3597","21.54600","1.79572","0.01080"
"3660","21.92400","1.82717","0.01081"
"3723","22.30200","1.85874","0.01148"
"3786","22.68000","1.89019","0.01151"
"3849","23.05800","1.92170","0.01115"
"3912","23.43600","1.95314","0.01188"
"3975","23.81400","1.98465","0.01258"
"4038","24.19200","2.01622","0.01199"
"4101","24.57000","2.04767","0.01217"
"4164","24.94800","2.07918","0.01249"
"4227","25.32600","2.11075","0.01330"
"4290","25.70400","2.14214","0.01324"
"4353","26.08200","2.17371","0.01324"
"4416","26.46000","2.20522","0.01346"
"4479","26.83800","2.23667","0.01340"
"4542","27.21600","2.26812","0.01415"
"4605","27.59400","2.29974","0.01391"
"4668","27.97200","2.33119","0.01449"
"4731","28.35000","2.36264","-0.00032"
"4794","28.72800","2.39415","-0.00461"
"4857","29.10600","2.42572","-0.00376"
"4920","29.48400","2.45723","-0.00444"
"4983","29.86200","2.48862","-0.00389"
"5046","30.24000","2.52019","-0.00379"
"5109","30.61800","2.55170","-0.00336"
"5172","30.99600","2.58315","-0.00356"
"5235","31.37400","2.61472","-0.00369"
"5298","31.75200","2.64622","-0.00355"
"5361","32.13000","2.67767","-0.00371"
"5424","32.50800","2.70924","-0.00351"
"5487","32.88600","2.74069","-0.00328"
"5550","33.26400","2.77214","-0.00297"
"5613","33.64200","2.80371","-0.00289"
"5676","34.02000","2.83516","-0.00322"
"5739","34.39800","2.86667","-0.00281"
"5802","34.77600","2.89818","-0.00348"
"5865","35.15400","2.92969","-0.00361"
"5928","35.53200","2.96126","-0.00270"
"5991","35.91000","2.99265","-0.00326"
"6054","36.28800","3.02421","-0.00319"
"6117","36.66600","3.05572","-0.00304"
"6180","37.04400","3.08717","-0.00337"
"6243","37.42200","3.11862","-0.00308"
"6306","37.80000","3.15025","-0.00270"
"6369","38.17800","3.18170","-0.00311"
"6432","38.55600","3.21315","-0.00298"
"6495","38.93400","3.24472","-0.00259"
"6558","39.31200","3.27623","-0.00308"
"6621","39.69000","3.30768","-0.00283"
"6684","40.06800","3.33913","-0.00336"
"6747","40.44600","3.37069","-0.00358"
"6810","40.82400","3.40220","-0.00335"
"6873","41.20200","3.43365","-0.00266"
"6936","41.58000","3.46522","-0.00350"
"6999","41.95800","3.49673","-0.00348"
"7062","42.33600","3.52818","-0.00358"
"7125","42.71400","3.55963","-0.00304"
"7188","43.09200","3.59126","-0.00317"
"7251","43.47000","3.62271","-0.00278"
"7314","43.84800","3.65416","-0.00309"
"7377","44.22600","3.68573","-0.00310"
"7440","44.60400","3.71718","-0.00333"
"7503","44.98200","3.74868","-0.00367"
"7566","45.36000","3.78019","-0.00398"
"7629","45.73800","3.81170","-0.00324"
"7692","46.11600","3.84315","-0.00367"
"7755","46.49400","3.87466","-0.00326"
"7818","46.87200","3.90623","-0.00271"
"7881","47.25000","3.93768","-0.00305"
"7944","47.62800","3.96925","-0.00330"
"8007","48.00600","4.00076","-0.00339"
"8070","48.38400","4.03215","-0.00324"
"8133","48.76200","4.06366","-0.00298"
"8196","49.14000","4.09522","-0.00342"
"8259","49.51800","4.12673","-0.00403"
"8322","49.89600","4.15818","-0.00318"
"8385","50.27400","4.18969","-0.00337"
"8448","50.65200","4.22120","-0.00311"
"8511","51.03000","4.25265","-0.00306"
"8574","51.40800","4.28416","-0.00332"
"8637","51.78600","4.31573","-0.00264"
"8700","52.16400","4.34724","-0.00315"
"8763","52.54200","4.37863","-0.00273"
"8826","52.92000","4.41014","-0.00275"
"8889","53.29800","4.44176","-0.00292"
"8952","53.67600","4.47309","-0.00287"
"9015","54.05400","4.50466","-0.00266"
"9078","54.43200","4.53623","-0.00289"
"9141","54.81000","4.56768","-0.00343"
"9204","55.18800","4.59919","-0.00312"
"9267","55.56600","4.63076","-0.00293"
"9330","55.94400","4.66215","-0.00281"
"9393","56.32200","4.69372","-0.00303"
"9456","56.70000","4.72523","-0.00311"
"9519","57.07800","4.75668","-0.00277"
"9582","57.45600","4.78819","-0.00245"
"9645","57.83400","4.81969","-0.00253"
"9708","58.21200","4.85120","-0.00244"
"9771","58.59000","4.88265","-0.00291"
"9834","58.96800","4.91422","-0.00265"
"9897","59.34600","4.94567","-0.00302"
"9960","59.72400","4.97718","-0.00275"
"10023","60.10200","5.00863","-0.00233"
"10086","60.48000","5.04026","-0.00265"
"10149","60.85800","5.07165","-0.00279"
"10212","61.23600","5.10316","-0.00241"
"10275","61.61400","5.13467","-0.00265"
"10338","61.99200","5.16623","-0.00310"
"10401","62.37000","5.19768","-0.00280"
"10464","62.74800","5.22919","-0.00271"
"10527","63.12600","5.26070","-0.00273"
"10590","63.50400","5.29221","-0.00274"
"10653","63.88200","5.32366","-0.00257"
"10716","64.26000","5.35517","-0.00265"
"10779","64.63800","5.38668","-0.00383"
"10842","65.01600","5.41819","-0.00375"
"10905","65.39400","5.44964","-0.00370"
"10968","65.77200","5.48121","-0.00368"
"11031","66.15000","5.51265","-0.00354"
"11094","66.52800","5.54416","-0.00364"
"11157","66.90600","5.57567","-0.00360"
"11220","67.28400","5.60724","-0.00327"
"11283","67.66200","5.63869","-0.00395"
"11346","68.04000","5.67014","-0.00321"
"11409","68.41800","5.70171","-0.00351"
"11472","68.79600","5.73316","-0.00366"
"11535","69.17400","5.76467","-0.00307"
"11598","69.55200","5.79618","-0.00319"
"11661","69.93000","5.82775","-0.00367"
"11724","70.30800","5.85913","-0.00393"
"11787","70.68600","5.89070","-0.00351"
"11850","71.06400","5.92221","-0.00330"
"11913","71.44200","5.95360","-0.00346"
"11976","71.82000","5.98523","-0.00330"
"12039","72.19800","6.01674","-0.00403"
"12102","72.57600","6.04819","-0.00395"
"12165","72.95400","6.07964","-0.00386"
"12228","73.33200","6.11121","-0.00429"
"12291","73.71000","6.14272","-0.00420"
"12354","74.08800","6.17417","-0.00366"
"12417","74.46600","6.20568","-0.00374"
"12480","74.84400","6.23724","-0.00377"
"12543","75.22200","6.26863","-0.00367"
"12606","75.60000","6.30020","-0.00385"
"12669","75.97800","6.33177","-0.00388"
"12732","76.35600","6.36316","-0.00396"
"12795","76.73400","6.39467","-0.00418"
"12858","77.11200","6.42618","-0.00384"
"12921","77.49000","6.45769","-0.00402"
"12984","77.86800","6.48914","-0.00403"
"13047","78.24600","6.52071","-0.00399"
"13110","78.62400","6.55222","-0.00399"
"13173","79.00200","6.58372","-0.00334"
"13236","79.38000","6.61517","-0.00360"
"13299","79.75800","6.64674","-0.00395"
"13362","80.13600","6.67819","-0.00345"
"13425","80.51400","6.70964","-0.00377"
"13488","80.89200","6.74121","-0.00407"
"13551","81.27000","6.77272","-0.00369"
"13614","81.64800","6.80411","-0.00317"
"13677","82.02600","6.83568","-0.00352"
"13740","82.40400","6.86719","-0.00347"
"13803","82.78200","6.89870","-0.00337"
"13866","83.16000","6.93015","-0.00344"
"13929","83.53800","6.96171","-0.00347"
"13992","83.91600","6.99322","-0.00356"
"14055","84.29400","7.02467","-0.00325"
"14118","84.67200","7.05618","-0.00299"
"14181","85.05000","7.08775","-0.00310"
"14244","85.42800","7.11914","-0.00309"
"14307","85.80600","7.15065","-0.00280"
"14370","86.18400","7.18222","-0.00307"
"14433","86.56200","7.21373","-0.00294"
"14496","86.94000","7.24518","-0.00343"
"14559","87.31800","7.27668","-0.00321"
"14622","87.69600","7.30819","-0.00328"
"14685","88.07400","7.33964","-0.00253"
"14748","88.45200","7.37121","-0.00304"
"14811","88.83000","7.40272","-0.00302"
"14874","89.20800","7.43417","-0.00282"
"14937","89.58600","7.46568","-0.00291"
"15000","89.96400","7.49719","-0.00266"
"15063","90.34200","7.52870","-0.00287"
"15126","90.72000","7.56015","-0.00324"
"15189","91.09800","7.59172","-0.00231"
"15252","91.47600","7.62323","-0.00302"
"15315","91.85400","7.65461","-0.00323"
"15378","92.23200","7.68618","-0.00294"
"15441","92.61000","7.71769","-0.00303"
"15504","92.98800","7.74920","-0.00276"
"15567","93.36600","7.78071","-0.00294"
"15630","93.74400","7.81222","-0.00303"
"15693","94.12200","7.84367","-0.00255"
"15756","94.50000","7.87518","-0.00294"
"15819","94.87800","7.90669","-0.00311"
"15882","95.25600","7.93826","-0.00273"
"15945","95.63400","7.96965","-0.00269"
"16008","96.01200","8.00115","-0.00241"
"16071","96.39000","8.03272","-0.00206"
"16134","96.76800","8.06417","-0.00256"
"16197","97.14600","8.09562","-0.00255"
"16260","97.52400","8.12725","-0.00321"
"16323","97.90200","8.15870","-0.00339"
"16386","98.28000","8.19015","-0.00377"
"16449","98.65800","8.22172","-0.00285"
"16512","99.03600","8.25323","-0.00329"
"16575","99.41400","8.28468","-0.00286"
"16638","99.79200","8.31625","-0.00237"
"16701","100.17000","8.34769","-0.00286"
"16764","100.54800","8.37920","-0.00272"
"16827","100.92600","8.41071","-0.00251"
"16890","101.30400","8.44222","-0.00285"
"16953","101.68200","8.47373","-0.00263"
"17016","102.06000","8.50512","-0.00235"
"17079","102.43800","8.53663","-0.00276"
"17142","102.81600","8.56820","-0.00290"
"17205","103.19400","8.59965","-0.00290"
"17268","103.57200","8.63116","-0.00294"
"17331","103.95000","8.66273","-0.00245"
"17394","104.32800","8.69418","-0.00265"
"17457","104.70600","8.72568","-0.00224"
"17520","105.08400","8.75725","-0.00228"
"17583","105.46200","8.78870","-0.00237"
"17646","105.84000","8.82015","-0.00257"
"17709","106.21800","8.85166","-0.00236"
"17772","106.59600","8.88323","-0.00224"
"17835","106.97400","8.91468","-0.00232"
"17898","107.35200","8.94613","-0.00234"
"17961","107.73000","8.97770","-0.00219"
"18024","108.10800","9.00921","-0.00198"
"18087","108.48600","9.04072","-0.00243"
"18150","108.86400","9.07222","-0.00188"
"18213","109.24200","9.10373","-0.00166"
"18276","109.62000","9.13512","-0.00162"
"18339","109.99800","9.16675","-0.00169"
"18402","110.37600","9.19820","-0.00184"
"18465","110.75400","9.22971","-0.00143"
"18528","111.13200","9.26116","-0.00142"
"18591","111.51000","9.29267","-0.00149"
"18654","111.88800","9.32418","-0.00186"
"18717","112.26600","9.35563","-0.00137"
"18780","112.64400","9.38720","-0.00112"
"18843","113.02200","9.41877","-0.00095"
"18906","113.40000","9.45015","-0.00145"
"18969","113.77800","9.48172","-0.00117"
"19032","114.15600","9.51323","-0.00119"
"19095","114.53400","9.54468","-0.00123"
"19158","114.91200","9.57619","-0.00067"
"19221","115.29000","9.60776","-0.00111"
"19284","115.66800","9.63921","-0.00049"
"19347","116.04600","9.67066","-0.00067"
"19410","116.42400","9.70223","-0.00049"
"19473","116.80200","9.73368","-0.00015"
"19536","117.18000","9.76519","0.00010"
"19599","117.55800","9.79669","-0.00038"
"19662","117.93600","9.82820","0.00003"
"19725","118.31400","9.85971","0.00000"
"19788","118.69200","9.89116","0.00029"
"19851","119.07000","9.92273","0.00039"
"19914","119.44800","9.95424","0.00018"
"19977","119.82600","9.98563","0.00020"
"20040","120.20400","10.01714","0.00032"
"20103","120.58200","10.04877","0.00061"
"20166","120.96000","10.08016","0.00086"
"20229","121.33800","10.11167","0.00037"
"20292","121.71600","10.14318","0.00101"
"20355","122.09400","10.17468","0.00127"
"20418","122.47200","10.20619","0.00144"
"20481","122.85000","10.23770","0.00122"
"20544","123.22800","10.26921","0.00188"
"20607","123.60600","10.30066","0.00136"
"20670","123.98400","10.33217","0.00167"
"20733","124.36200","10.36368","0.00166"
"20796","124.74000","10.39519","0.00233"
"20859","125.11800","10.42664","0.00127"
"20922","125.49600","10.45821","0.00143"
"20985","125.87400","10.48965","0.00244"
"21048","126.25200","10.52110","0.00226"
"21111","126.63000","10.55273","0.00206"
"21174","127.00800","10.58418","0.00216"
"21237","127.38600","10.61569","0.00133"
"21300","127.76400","10.64720","0.00062"
"21363","128.14200","10.67871","0.00127"
"21426","128.52000","10.71016","0.00190"
"21489","128.89800","10.74167","0.00154"
"21552","129.27600","10.77324","0.00237"
"21615","129.65400","10.80475","0.00211"
"21678","130.03200","10.83613","0.00233"
"21741","130.41000","10.86770","0.00197"
"21804","130.78800","10.89927","0.00323"
"21867","131.16600","10.93066","0.00364"
"21930","131.54400","10.96223","0.00372"
"21993","131.92200","10.99374","0.00327"
"22056","132.30000","11.02513","0.00374"
"22119","132.67800","11.05664","0.00383"
"22182","133.05600","11.08821","0.00524"
"22245","133.43400","11.11972","0.00534"
"22308","133.81200","11.15117","0.00505"
"22371","134.19000","11.18268","0.00553"
"22434","134.56800","11.21418","0.00565"
"22497","134.94600","11.24569","0.00633"
"22560","135.32400","11.27714","0.00611"
"22623","135.70200","11.30871","0.00712"
"22686","136.08000","11.34022","0.00706"
"22749","136.45800","11.37167","0.00686"
"22812","136.83600","11.40318","0.00710"
"22875","137.21400","11.43469","0.00813"
"22938","137.59200","11.46614","0.00874"
"23001","137.97000","11.49771","0.00875"
"23064","138.34800","11.52922","0.00897"
"23127","138.72600","11.56067","0.00972"
"23190","139.10400","11.59217","0.00972"
"23253","139.48200","11.62374","0.01054"
"23316","139.86000","11.65519","0.01085"
"23379","140.23800","11.68664","0.01134"
"23442","140.61600","11.71821","0.01164"
"23505","140.99400","11.74972","0.01264"
"23568","141.37200","11.78111","0.01306"
"23631","141.75000","11.81268","0.01314"
"23694","142.12800","11.84425","0.01389"
"23757","142.50600","11.87570","0.01448"
"23820","142.88400","11.90715","0.01438"
"23883","143.26200","11.93871","0.01498"
"23946","143.64000","11.97022","0.01528"
"24009","144.01800","12.00167","0.01625"
"24072","144.39600","12.03318","0.01708"
"24135","144.77400","12.06475","0.01727"
"24198","145.15200","12.09620","0.01787"
"24261","145.53000","12.12765","0.01868"
"24324","145.90800","12.15916","0.01950"
"24387","146.28600","12.19073","0.02023"
"24450","146.66400","12.22218","0.02039"
"24513","147.04200","12.25369","0.02098"
"24576","147.42000","12.28525","0.02193"
"24639","147.79800","12.31664","0.02298"
"24702","148.17600","12.34821","0.02270"
"24765","148.55400","12.37972","0.02303"
"24828","148.93200","12.41111","0.02337"
"24891","149.31000","12.44274","0.02500"
"24954","149.68800","12.47419","0.02619"
"25017","150.06600","12.50564","0.02753"
"25080","150.44400","12.53715","0.02842"
"25143","150.82200","12.56872","0.03030"
"25206","151.20000","12.60017","0.03171"
"25269","151.57800","12.63167","0.03289"
"25332","151.95600","12.66318","0.03384"
"25395","152.33400","12.69469","0.03543"
"25458","152.71200","12.72614","0.03644"
"25521","153.09000","12.75771","0.03786"
"25584","153.46800","12.78928","0.03904"
"25647","153.84600","12.82067","0.03932"
"25710","154.22400","12.85212","0.04036"
"25773","154.60200","12.88375","0.04051"
"25836","154.98000","12.91520","0.04186"
"25899","155.35800","12.94665","0.04345"
"25962","155.73600","12.97822","0.04427"
"26025","156.11400","13.00966","0.04657"
"26088","156.49200","13.04117","0.04787"
"26151","156.87000","13.07268","0.04981"
"26214","157.24800","13.10419","0.05188"
"26277","157.62600","13.13570","0.05128"
"26340","158.00400","13.16715","0.05423"
"26403","158.38200","13.19872","0.05664"
"26466","158.76000","13.23029","0.05829"
"26529","159.13800","13.26162","0.06041"
"26592","159.51600","13.29319","0.06136"
"26655","159.89400","13.32469","0.06307"
"26718","160.27200","13.35620","0.06429"
"26781","160.65000","13.38771","0.06499"
"26844","161.02800","13.41922","0.06690"
"26907","161.40600","13.45067","0.06824"
"26970","161.78400","13.48218","0.06953"
"27033","162.16200","13.51369","0.07178"
"27096","162.54000","13.54520","0.07387"
"27159","162.91800","13.57671","0.07602"
"27222","163.29600","13.60816","0.07897"
"27285","163.67400","13.63973","0.07932"
"27348","164.05200","13.67118","0.08184"
"27411","164.43000","13.70262","0.08302"
"27474","164.80800","13.73419","0.08521"
"27537","165.18600","13.76570","0.08681"
"27600","165.56400","13.79715","0.08792"
"27663","165.94200","13.82878","0.08860"
"27726","166.32000","13.86023","0.09007"
"27789","166.69800","13.89162","0.09142"
"27852","167.07600","13.92319","0.09253"
"27915","167.45400","13.95470","0.09358"
"27978","167.83200","13.98615","0.09496"
"28041","168.21000","14.01766","0.09568"
"28104","168.58800","14.04922","0.09688"
"28167","168.96600","14.08074","0.09857"
"28230","169.34400","14.11212","0.10003"
"28293","169.72200","14.14369","0.10158"
"28356","170.10000","14.17526","0.10310"
"28419","170.47800","14.20665","0.10532"
"28482","170.85600","14.23822","0.10647"
"28545","171.23400","14.26973","0.10926"
"28608","171.61200","14.30118","0.11075"
"28671","171.99000","14.33269","0.11171"
"28734","172.36800","14.36420","0.11391"
"28797","172.74600","14.39571","0.11548"
"28860","173.12400","14.42716","0.11731"
"28923","173.50200","14.45866","0.11975"
"28986","173.88000","14.49023","0.12157"
"29049","174.25800","14.52174","0.12510"
"29112","174.63600","14.55313","0.12760"
"29175","175.01400","14.58470","0.13158"
"29238","175.39200","14.61615","0.13466"
"29301","175.77000","14.64766","0.13841"
"29364","176.14800","14.67923","0.14039"
"29427","176.52600","14.71074","0.14348"
"29490","176.90400","14.74219","0.14482"
"29553","177.28200","14.77370","0.14702"
"29616","177.66000","14.80520","0.14941"
"29679","178.03800","14.83665","0.15209"
"29742","178.41600","14.86822","0.15458"
"29805","178.79400","14.89967","0.15844"
"29868","179.17200","14.93118","0.16184"
"29931","179.55000","14.96263","0.16463"
"29994","179.92800","14.99414","0.16779"
"30057","180.30600","15.02571","0.17032"
"30120","180.68400","15.05716","0.17157"
"30183","181.06200","15.08867","0.17414"
"30246","181.44000","15.12024","0.17615"
"30309","181.81800","15.15168","0.17811"
"30372","182.19600","15.18313","0.18064"
"30435","182.57400","15.21476","0.13419"
"30498","182.95200","15.24621","0.12241"
"30561","183.33000","15.27766","0.11658"
"30624","183.70800","15.30917","0.10815"
"30687","184.08600","15.34068","0.10855"
"30750","184.46400","15.37219","0.10260"
"30813","184.84200","15.40370","0.10101"
"30876","185.22000","15.43527","0.10295"
"30939","185.59800","15.46672","0.10361"
"31002","185.97600","15.49817","0.10666"
"31065","186.35400","15.52973","0.10836"
"31128","186.73200","15.56130","0.11020"
"31191","187.11000","15.59263","0.11145"
"31254","187.48800","15.62420","0.11330"
"31317","187.86600","15.65571","0.11527"
"31380","188.24400","15.68722","0.11694"
"31443","188.62200","15.71867","0.11959"
"31506","189.00000","15.75024","0.12293"
"31569","189.37800","15.78169","0.12642"
"31632","189.75600","15.81319","0.13057"
"31695","190.13400","15.84464","0.13520"
"31758","190.51200","15.87627","0.13919"
"31821","190.89000","15.90766","0.14254"
"31884","191.26800","15.93917","0.14515"
"31947","191.64600","15.97074","0.14765"
"32010","192.02400","16.00219","0.14966"
"32073","192.40200","16.03370","0.15334"
"32136","192.78000","16.06521","0.15610"
"32199","193.15800","16.09666","0.16063"
"32262","193.53600","16.12811","0.16505"
"32325","193.91400","16.15968","0.16801"
"32388","194.29200","16.19118","0.17070"
"32451","194.67000","16.22269","0.17308"
"32514","195.04800","16.25414","0.17562"
"32577","195.42600","16.28565","0.17842"
"32640","195.80400","16.31716","0.18192"
"32703","196.18200","16.34867","0.18239"
"32766","196.56000","16.38024","0.18525"
"32829","196.93800","16.41175","0.18837"
"32892","197.31600","16.44314","0.19199"
"32955","197.69400","16.47471","0.19501"
"33018","198.07200","16.50622","0.19834"
"33081","198.45000","16.53766","0.20149"
"33144","198.82800","16.56918","0.20444"
"33207","199.20600","16.60068","0.20674"
"33270","199.58400","16.63219","0.20882"
"33333","199.96200","16.66364","0.21099"
"33396","200.34000","16.69521","0.21384"
"33459","200.71800","16.72672","0.21655"
"33522","201.09600","16.75817","0.21957"
"33585","201.47400","16.78968","0.22159"
"33648","201.85200","16.82119","0.22403"
"33711","202.23000","16.85270","0.22678"
"33774","202.60800","16.88415","0.23010"
"33837","202.98600","16.91577","0.23404"
"33900","203.36400","16.94716","0.23705"
"33963","203.74200","16.97861","0.24037"
"34026","204.12000","17.01024","0.24286"
"34089","204.49800","17.04169","0.24667"
"34152","204.87600","17.07314","0.25018"
"34215","205.25400","17.10471","0.25316"
"34278","205.63200","17.13616","0.25777"
"34341","206.01000","17.16773","0.26208"
"34404","206.38800","17.19918","0.26559"
"34467","206.76600","17.23069","0.22107"
"34530","207.14400","17.26225","0.22354"
"34593","207.52200","17.29358","0.22620"
"34656","207.90000","17.32515","0.23156"
"34719","208.27800","17.35678","0.23680"
"34782","208.65600","17.38817","0.24176"
"34845","209.03400","17.41968","0.24650"
"34908","209.41200","17.45119","0.25002"
"34971","209.79000","17.48264","0.25719"
"35034","210.16800","17.51421","0.26143"
"35097","210.54600","17.54572","0.26589"
"35160","210.92400","17.57717","0.27108"
"35223","211.30200","17.60874","0.27513"
"35286","211.68000","17.64018","0.28143"
"35349","212.05800","17.67163","0.28809"
"35412","212.43600","17.70320","0.29384"
"35475","212.81400","17.73471","0.29565"
"35538","213.19200","17.76622","0.29964"
"35601","213.57000","17.79773","0.30254"
"35664","213.94800","17.82918","0.30454"
"35727","214.32600","17.86069","0.30793"
"35790","214.70400","17.89220","0.31076"
"35853","215.08200","17.92365","0.31374"
"35916","215.46000","17.95522","0.31754"
"35979","215.83800","17.98672","0.32037"
"36042","216.21600","18.01817","0.32290"
"36105","216.59400","18.04962","0.32517"
"36168","216.97200","18.08125","0.32930"
"36231","217.35000","18.11270","0.33360"
"36294","217.72800","18.14421","0.33906"
"36357","218.10600","18.17572","0.34475"
"36420","218.48400","18.20723","0.34910"
"36483","218.86200","18.23862","0.35334"
"36546","219.24000","18.27019","0.35901"
"36609","219.61800","18.30176","0.36536"
"36672","219.99600","18.33315","0.37074"
"36735","220.37400","18.36471","0.37459"
"36798","220.75200","18.39622","0.37807"
"36861","221.13000","18.42767","0.38337"
"36924","221.50800","18.45918","0.38820"
"36987","221.88600","18.49069","0.39382"
"37050","222.26400","18.52226","0.39862"
"37113","222.64200","18.55365","0.40099"
"37176","223.02000","18.58516","0.40476"
"37239","223.39800","18.61673","0.40839"
"37302","223.77600","18.64824","0.41238"
"37365","224.15400","18.67969","0.41729"
"37428","224.53200","18.71125","0.42231"
"37491","224.91000","18.74270","0.42238"
"37554","225.28800","18.77409","0.42698"
"37617","225.66600","18.80572","0.43112"
"37680","226.04400","18.83723","0.43622"
"37743","226.42200","18.86868","0.44239"
"37806","226.80000","18.90019","0.44760"
"37869","227.17800","18.93170","0.45140"
"37932","227.55600","18.96321","0.45625"
"37995","227.93400","18.99466","0.46183"
"38058","228.31200","19.02623","0.46853"
"38121","228.69000","19.05773","0.47452"
"38184","229.06800","19.08918","0.47868"
"38247","229.44600","19.12069","0.48333"
"38310","229.82400","19.15220","0.49107"
"38373","230.20200","19.18365","0.49720"
"38436","230.58000","19.21516","0.50478"
"38499","230.95800","19.24673","0.50965"
"38562","231.33600","19.27818","0.51325"
"38625","231.71400","19.30963","0.51660"
"38688","232.09200","19.34120","0.51980"
"38751","232.47000","19.37271","0.52384"
"38814","232.84800","19.40415","0.52901"
"38877","233.22600","19.43572","0.53379"
"38940","233.60400","19.46717","0.53848"
"39003","233.98200","19.49868","0.54499"
"39066","234.36000","19.53019","0.55078"
"39129","234.73800","19.56170","0.55567"
"39192","235.11600","19.59321","0.55780"
"39255","235.49400","19.62460","0.56249"
"39318","235.87200","19.65623","0.57089"
"39381","236.25000","19.68773","0.57836"
"39444","236.62800","19.71913","0.58361"
"39507","237.00600","19.75070","0.58998"
"39570","237.38400","19.78220","0.59576"
"39633","237.76200","19.81371","0.60105"
"39696","238.14000","19.84516","0.60542"
"39759","238.51800","19.87667","0.60972"
"39822","238.89600","19.90818","0.61483"
"39885","239.27400","19.93975","0.62004"
"39948","239.65200","19.97120","0.62503"
"40011","240.03000","20.00271","0.63002"
"40074","240.40800","20.03416","0.63663"
"40137","240.78600","20.06567","0.64417"
"40200","241.16400","20.09718","0.65291"
"40263","241.54200","20.12868","0.65852"
"40326","241.92000","20.16019","0.64756"
"40389","242.29800","20.19176","0.49529"
"40452","242.67600","20.22321","0.34684"
"40515","243.05400","20.25460","0.30922"
"40578","243.43200","20.28623","0.31516"
"40641","243.81000","20.31774","0.32075"
"40704","244.18800","20.34913","0.32330"
"40767","244.56600","20.38064","0.32670"
"40830","244.94400","20.41221","0.33968"
"40893","245.32200","20.44366","0.35099"
"40956","245.70000","20.47517","0.35496"
"41019","246.07800","20.50673","0.36011"
"41082","246.45600","20.53824","0.37208"
"41145","246.83400","20.56963","0.38194"
"41208","247.21200","20.60120","0.39112"
"41271","247.59000","20.63277","0.39779"
"41334","247.96800","20.66416","0.40311"
"41397","248.34600","20.69567","0.41010"
"41460","248.72400","20.72724","0.41493"
"41523","249.10200","20.75875","0.42225"
"41586","249.48000","20.79020","0.43289"
"41649","249.85800","20.82170","0.44102"
"41712","250.23600","20.85321","0.44828"
"41775","250.61400","20.88466","0.45470"
"41838","250.99200","20.91617","0.46357"
"41901","251.37000","20.94768","0.47071"
"41964","251.74800","20.97919","0.47894"
"42027","252.12600","21.01064","0.48625"
"42090","252.50400","21.04221","0.49484"
"42153","252.88200","21.07366","0.50792"
"42216","253.26000","21.10517","0.51330"
"42279","253.63800","21.13674","0.51816"
"42342","254.01600","21.16818","0.52451"
"42405","254.39400","21.19969","0.53007"
"42468","254.77200","21.23120","0.53884"
"42531","255.15000","21.26265","0.54554"
"42594","255.52800","21.29416","0.55392"
"42657","255.90600","21.32573","0.56067"
"42720","256.28400","21.35718","0.56944"
"42783","256.66200","21.38875","0.57917"
"42846","257.04000","21.42014","0.58456"
"42909","257.41800","21.45165","0.59399"
"42972","257.79600","21.48328","0.60115"
"43035","258.17400","21.51467","0.60637"
"43098","258.55200","21.54618","0.61225"
"43161","258.93000","21.57774","0.61901"
"43224","259.30800","21.60913","0.62403"
"43287","259.68600","21.64064","0.63043"
"43350","260.06400","21.67227","0.63618"
"43413","260.44200","21.70372","0.64697"
"43476","260.82000","21.73511","0.65495"
"43539","261.19800","21.76668","0.66266"
"43602","261.57600","21.79819","0.67203"
"43665","261.95400","21.82970","0.68387"
"43728","262.33200","21.86115","0.68932"
"43791","262.71000","21.89271","0.70208"
"43854","263.08800","21.92422","0.70953"
"43917","263.46600","21.95567","0.71685"
"43980","263.84400","21.98724","0.72235"
"44043","264.22200","22.01869","0.72847"
"44106","264.60000","22.05014","0.73567"
"44169","264.97800","22.08171","0.73551"
"44232","265.35600","22.11322","0.74027"
"44295","265.73400","22.14467","0.74565"
"44358","266.11200","22.17618","0.68038"
"44421","266.49000","22.20769","0.68389"
"44484","266.86800","22.23919","0.47509"
"44547","267.24600","22.27071","0.47693"
"44610","267.62400","22.30215","0.48188"
"44673","268.00200","22.33372","0.48991"
"44736","268.38000","22.36517","0.49850"
"44799","268.75800","22.39668","0.50499"
"44862","269.13600","22.42825","0.51136"
"44925","269.51400","22.45964","0.51431"
"44988","269.89200","22.49121","0.51648"
"45051","270.27000","22.52272","0.52000"
"45114","270.64800","22.55417","0.52274"
"45177","271.02600","22.58562","0.17477"
"45240","271.40400","22.61724","0.16130"
"45303","271.78200","22.64863","0.16857"
"45366","272.16000","22.68020","0.18003"
"45429","272.53800","22.71165","0.18635"
"45492","272.91600","22.74316","0.19689"
"45555","273.29400","22.77467","0.20039"
"45618","273.67200","22.80618","0.21220"
"45681","274.05000","22.83775","0.21898"
"45744","274.42800","22.86926","0.22599"
"45807","274.80600","22.90059","0.23010"
"45870","275.18400","22.93216","0.23844"
"45933","275.56200","22.96372","0.26127"
"45996","275.94000","22.99517","0.29075"
"46059","276.31800","23.02668","0.29923"
"46122","276.69600","23.05819","0.28615"
"46185","277.07400","23.08964","0.27965"
"46248","277.45200","23.12115","0.29317"
"46311","277.83000","23.15272","0.29879"
"46374","278.20800","23.18423","0.30946"
"46437","278.58600","23.21568","0.32874"
"46500","278.96400","23.24719","0.32769"
"46563","279.34200","23.27870","0.32164"
"46626","279.72000","23.31021","0.32693"
"46689","280.09800","23.34166","0.33602"
"46752","280.47600","23.37322","0.36911"
"46815","280.85400","23.40467","0.36111"
"46878","281.23200","23.43618","0.35839"
"46941","281.61000","23.46769","0.36862"
"47004","281.98800","23.49920","0.39095"
"47067","282.36600","23.53065","0.39187"
"47130","282.74400","23.56222","0.38733"
"47193","283.12200","23.59367","0.39574"
"47256","283.50000","23.62523","0.41384"
"47319","283.87800","23.65668","0.40677"
"47382","284.25600","23.68819","0.40996"
"47445","284.63400","23.71970","0.42367"
"47508","285.01200","23.75115","0.43232"
"47571","285.39000","23.78272","0.42977"
"47634","285.76800","23.81423","0.43866"
"47697","286.14600","23.84562","0.45376"
"47760","286.52400","23.87719","0.44892"
"47823","286.90200","23.90876","0.45889"
"47886","287.28000","23.94015","0.47592"
"47949","287.65800","23.97160","0.47176"
"48012","288.03600","24.00323","0.48292"
"48075","288.41400","24.03468","0.49086"
"48138","288.79200","24.06612","0.49206"
"48201","289.17000","24.09769","0.51119"
"48264","289.54800","24.12920","0.50899"
"48327","289.92600","24.16071","0.51388"
"48390","290.30400","24.19216","0.52387"
"48453","290.68200","24.22373","0.52202"
"48516","291.06000","24.25518","0.53524"
"48579","291.43800","24.28663","0.53438"
"48642","291.81600","24.31820","0.54180"
"48705","292.19400","24.34976","0.55210"
"48768","292.57200","24.38116","0.55351"
"48831","292.95000","24.41272","0.57009"
"48894","293.32800","24.44417","0.56774"
"48957","293.70600","24.47568","0.58422"
"49020","294.08400","24.50719","0.58545"
"49083","294.46200","24.53876","0.59951"
"49146","294.84000","24.57021","0.60052"
"49209","295.21800","24.60166","0.60813"
"49272","295.59600","24.63317","0.61093"
"49335","295.97400","24.66474","0.61919"
"49398","296.35200","24.69613","0.62292"
"49461","296.73000","24.72770","0.63126"
"49524","297.10800","24.75920","0.63665"
"49587","297.48600","24.79065","0.65031"
"49650","297.86400","24.82216","0.65447"
"49713","298.24200","24.85373","0.66539"
"49776","298.62000","24.88518","0.66700"
"49839","298.99800","24.91663","0.68409"
"49902","299.37600","24.94820","0.68491"
"49965","299.75400","24.97971","0.69490"
"50028","300.13200","25.01122","0.69895"
"50091","300.51000","25.04267","0.70850"
"50154","300.88800","25.07417","0.71447"
"50217","301.26600","25.10575","0.71824"
"50280","301.64400","25.13720","0.72550"
"50343","302.02200","25.16870","0.72732"
"50406","302.40000","25.20021","0.73498"
"50469","302.77800","25.23160","0.39538"
"50532","303.15600","25.26323","0.39789"
"50595","303.53400","25.29474","0.41312"
"50658","303.91200","25.32613","0.40997"
"50721","304.29000","25.35770","0.41873"
"50784","304.66800","25.38921","0.42444"
"50847","305.04600","25.42065","0.43966"
"50910","305.42400","25.45217","0.43705"
"50973","305.80200","25.48373","0.44545"
"51036","306.18000","25.51524","0.45930"
"51099","306.55800","25.54669","0.45691"
"51162","306.93600","25.57820","0.46518"
"51225","307.31400","25.60971","0.48092"
"51288","307.69200","25.64116","0.47978"
"51351","308.07000","25.67267","0.48779"
"51414","308.44800","25.70424","0.50329"
"51477","308.82600","25.73569","0.50463"
"51540","309.20400","25.76720","0.51012"
"51603","309.58200","25.79865","0.51680"
"51666","309.96000","25.83021","0.51844"
"51729","310.33800","25.86166","0.52792"
"51792","310.71600","25.89323","0.53067"
"51855","311.09400","25.92468","0.53500"
"51918","311.47200","25.95619","0.54442"
"51981","311.85000","25.98764","0.54776"
"52044","312.22800","26.01921","0.45401"
"52107","312.60600","26.05072","0.44080"
"52170","312.98400","26.08217","0.44499"
"52233","313.36200","26.11368","0.44988"
"52296","313.74000","26.14519","0.45341"
"52359","314.11800","26.17664","0.45866"
"52422","314.49600","26.20820","0.47046"
"52485","314.87400","26.23971","0.47695"
"52548","315.25200","26.27116","0.48042"
"52611","315.63000","26.30261","0.48954"
"52674","316.00800","26.33418","0.49444"
"52737","316.38600","26.36569","0.50165"
"52800","316.76400","26.39720","0.51121"
"52863","317.14200","26.42871","0.51442"
"52926","317.52000","26.46021","0.51952"
"52989","317.89800","26.49167","0.52498"
"53052","318.27600","26.52312","0.53052"
"53115","318.65400","26.55469","0.53526"
"53178","319.03200","26.58619","0.54005"
"53241","319.41000","26.61765","0.54812"
"53304","319.78800","26.64921","0.40918"
"53367","320.16600","26.68066","0.41034"
"53430","320.54400","26.71211","0.40877"
"53493","320.92200","26.74374","0.41810"
"53556","321.30000","26.77519","0.23075"
"53619","321.67800","26.80670","0.22981"
"53682","322.05600","26.83821","0.23111"
"53745","322.43400","26.86972","0.23829"
"53808","322.81200","26.90116","0.24473"
"53871","323.19000","26.93268","0.24926"
"53934","323.56800","26.96424","0.25855"
"53997","323.94600","26.99569","0.26738"
"54060","324.32400","27.02714","0.27140"
"54123","324.70200","27.05871","0.26483"
"54186","325.08000","27.09022","0.26688"
"54249","325.45800","27.12167","0.26855"
"54312","325.83600","27.15318","0.27306"
"54375","326.21400","27.18469","0.28152"
"54438","326.59200","27.21620","0.29148"
"54501","326.97000","27.24765","0.29781"
"54564","327.34800","27.27921","0.30132"
"54627","327.72600","27.31072","0.30337"
"54690","328.10400","27.34217","0.30669"
"54753","328.48200","27.37362","0.31086"
"54816","328.86000","27.40525","0.31611"
"54879","329.23800","27.43670","0.32051"
"54942","329.61600","27.46815","0.32215"
"55005","329.99400","27.49972","0.32423"
"55068","330.37200","27.53117","0.32814"
"55131","330.75000","27.56268","0.33557"
"55194","331.12800","27.59418","0.34208"
"55257","331.50600","27.62569","0.34674"
"55320","331.88400","27.65714","0.35027"
"55383","332.26200","27.68871","0.35747"
"55446","332.64000","27.72016","0.36796"
"55509","333.01800","27.75167","0.37245"
"55572","333.39600","27.78318","0.37506"
"55635","333.77400","27.81469","0.37930"
"55698","334.15200","27.84620","0.38591"
"55761","334.53000","27.87765","0.39088"
"55824","334.90800","27.90916","0.24781"
"55887","335.28600","27.94079","0.24846"
"55950","335.66400","27.97218","0.24875"
"56013","336.04200","28.00362","0.24684"
"56076","336.42000","28.03525","0.25111"
"56139","336.79800","28.06670","0.25813"
"56202","337.17600","28.09815","0.27066"
"56265","337.55400","28.12972","0.27820"
"56328","337.93200","28.16123","0.28208"
"56391","338.31000","28.19262","0.28720"
"56454","338.68800","28.22419","0.29022"
"56517","339.06600","28.25570","0.29437"
"56580","339.44400","28.28721","0.29220"
"56643","339.82200","28.31866","0.29371"
"56706","340.20000","28.35022","0.29906"
"56769","340.57800","28.38173","0.30643"
"56832","340.95600","28.41312","0.31021"
"56895","341.33400","28.44475","0.31171"
"56958","341.71200","28.47626","0.31168"
"57021","342.09000","28.50765","0.31385"
"57084","342.46800","28.53922","0.31338"
"57147","342.84600","28.57073","0.31677"
"57210","343.22400","28.60217","0.32279"
"57273","343.60200","28.63369","0.32847"
"57336","343.98000","28.66520","0.32746"
"57399","344.35800","28.69670","0.32807"
"57462","344.73600","28.72815","0.33154"
"57525","345.11400","28.75972","0.33660"
"57588","345.49200","28.79123","0.34584"
"57651","345.87000","28.82262","0.35216"
"57714","346.24800","28.85419","0.35126"
"57777","346.62600","28.88570","0.35330"
"57840","347.00400","28.91721","0.36251"
"57903","347.38200","28.94866","0.37056"
"57966","347.76000","28.98022","0.37276"
"58029","348.13800","29.01168","0.37416"
"58092","348.51600","29.04313","0.37684"
"58155","348.89400","29.07475","0.38239"
"58218","349.27200","29.10620","0.39001"
"58281","349.65000","29.13771","0.38943"
"58344","350.02800","29.16916","0.39205"
"58407","350.40600","29.20067","0.39931"
"58470","350.78400","29.23218","0.40288"
"58533","351.16200","29.26369","0.40379"
"58596","351.54000","29.29520","0.40576"
"58659","351.91800","29.32677","0.41013"
"58722","352.29600","29.35810","0.41448"
"58785","352.67400","29.38961","0.41521"
"58848","353.05200","29.42123","0.41959"
"58911","353.43000","29.45268","0.42589"
"58974","353.80800","29.48413","0.42764"
"59037","354.18600","29.51570","0.43056"
"59100","354.56400","29.54721","0.34726"
"59163","354.94200","29.57866","0.34885"
"59226","355.32000","29.61023","0.34440"
"59289","355.69800","29.64174","0.34516"
"59352","356.07600","29.67319","0.35256"
"59415","356.45400","29.70464","0.35644"
"59478","356.83200","29.73615","0.35404"
"59541","357.21000","29.76765","0.35813"
"59604","357.58800","29.79917","0.29653"
"59667","357.96600","29.83073","0.19906"
"59730","358.34400","29.86218","0.19920"
"59793","358.72200","29.89363","0.20087"
"59856","359.10000","29.92520","0.20137"
"59919","359.47800","29.95671","0.20252"
"59982","359.85600","29.98810","0.20422"
"60045","360.23400","30.01973","0.20544"
"60108","360.61200","30.05118","0.20705"
"60171","360.99000","30.08262","0.20897"
"60234","361.36800","30.11414","0.21090"
"60297","361.74600","30.14576","0.21338"
"60360","362.12400","30.17721","0.21519"
"60423","362.50200","30.20866","0.21673"
"60486","362.88000","30.24017","0.21850"
"60549","363.25800","30.27174","0.22037"
"60612","363.63600","30.30313","0.22225"
"60675","364.01400","30.33464","0.22372"
"60738","364.39200","30.36627","0.22559"
"60801","364.77000","30.39766","-0.00991"
"60864","365.14800","30.42917","0.01159"
"60927","365.52600","30.46073","0.00893"
"60990","365.90400","30.49218","0.00571"
"61053","366.28200","30.52363","0.00765"
"61116","366.66000","30.55520","0.00976"
"61179","367.03800","30.58671","0.01458"
"61242","367.41600","30.61822","0.00995"
"61305","367.79400","30.64967","0.00870"
"61368","368.17200","30.68118","0.00843"
"61431","368.55000","30.71269","0.01490"
"61494","368.92800","30.74414","0.01399"
"61557","369.30600","30.77571","0.01209"
"61620","369.68400","30.80722","0.01047"
"61683","370.06200","30.83867","0.01581"
"61746","370.44000","30.87023","0.01704"
"61809","370.81800","30.90168","0.01853"
"61872","371.19600","30.93319","0.01310"
"61935","371.57400","30.96470","0.01216"
"61998","371.95200","30.99621","0.01331"
"62061","372.33000","31.02772","0.01707"
"62124","372.70800","31.05917","0.01654"
"62187","373.08600","31.09068","0.01309"
"62250","373.46400","31.12225","0.01163"
"62313","373.84200","31.15364","0.01503"
"62376","374.22000","31.18521","0.01659"
"62439","374.59800","31.21666","0.01681"
"62502","374.97600","31.24816","0.01475"
"62565","375.35400","31.27967","0.01574"
"62628","375.73200","31.31124","0.01678"
"62691","376.11000","31.34269","0.01854"
"62754","376.48800","31.37420","0.01820"
"62817","376.86600","31.40571","0.01707"
"62880","377.24400","31.43721","0.01716"
"62943","377.62200","31.46867","0.01872"
"63006","378.00000","31.50018","0.01734"
"63069","378.37800","31.53174","0.01880"
"63132","378.75600","31.56319","0.01795"
"63195","379.13400","31.59464","0.01826"
"63258","379.51200","31.62621","0.00552"
"63321","379.89000","31.65778","0.00931"
"63384","380.26800","31.68911","0.02124"
"63447","380.64600","31.72074","0.02834"
"63510","381.02400","31.75225","0.02109"
"63573","381.40200","31.78364","0.01206"
"63636","381.78000","31.81520","0.01291"
"63699","382.15800","31.84671","0.02092"
"63762","382.53600","31.87816","0.03250"
"63825","382.91400","31.90967","0.02708"
"63888","383.29200","31.94118","0.02297"
"63951","383.67000","31.97269","0.01768"
"64014","384.04800","32.00414","0.02431"
"64077","384.42600","32.03565","0.02868"
"64140","384.80400","32.06722","0.03357"
"64203","385.18200","32.09867","0.02687"
"64266","385.56000","32.13018","0.02184"
"64329","385.93800","32.16175","0.02239"
"64392","386.31600","32.19320","0.02592"
"64455","386.69400","32.22464","0.03631"
"64518","387.07200","32.25621","0.03549"
"64581","387.45000","32.28772","0.03534"
"64644","387.82800","32.31917","0.02910"
"64707","388.20600","32.35074","0.02910"
"64770","388.58400","32.38219","0.03505"
"64833","388.96200","32.41370","0.03697"
"64896","389.34000","32.44515","0.04160"
"64959","389.71800","32.47672","0.04159"
"65022","390.09600","32.50823","0.03540"
"65085","390.47400","32.53968","0.03750"
"65148","390.85200","32.57119","0.03881"
"65211","391.23000","32.60275","0.04127"
"65274","391.60800","32.63414","0.04189"
"65337","391.98600","32.66565","0.04406"
"65400","392.36400","32.69722","0.04385"
"65463","392.74200","32.72867","0.04217"
"65526","393.12000","32.76018","0.04467"
"65589","393.49800","32.79169","0.04853"
"65652","393.87600","32.82320","0.05199"
"65715","394.25400","32.85471","0.05610"
"65778","394.63200","32.88622","0.05626"
"65841","395.01000","32.91772","0.05569"
"65904","395.38800","32.94912","0.05723"
"65967","395.76600","32.98068","0.06008"
"66030","396.14400","33.01219","0.06314"
"66093","396.52200","33.04370","0.06554"
"66156","396.90000","33.07509","0.06702"
"66219","397.27800","33.10672","0.06809"
"66282","397.65600","33.13817","0.06945"
"66345","398.03400","33.16962","0.07372"
"66408","398.41200","33.20119","0.07763"
"66471","398.79000","33.23270","0.08132"
"66534","399.16800","33.26421","0.08365"
"66597","399.54600","33.29565","0.08551"
"66660","399.92400","33.32716","0.08734"
"66723","400.30200","33.35867","0.08939"
"66786","400.68000","33.39018","0.09196"
"66849","401.05800","33.42169","0.09383"
"66912","401.43600","33.45320","0.09553"
"66975","401.81400","33.48459","0.09728"
"67038","402.19200","33.51622","0.09971"
"67101","402.57000","33.54766","0.10253"
"67164","402.94800","33.57918","0.10541"
"67227","403.32600","33.61069","0.10808"
"67290","403.70400","33.64220","0.11104"
"67353","404.08200","33.67365","0.11296"
"67416","404.46000","33.70521","0.11597"
"67479","404.83800","33.73672","0.11938"
"67542","405.21600","33.76823","0.12479"
"67605","405.59400","33.79968","0.13049"
"67668","405.97200","33.83113","0.13508"
"67731","406.35000","33.86276","0.13865"
"67794","406.72800","33.89421","0.14238"
"67857","407.10600","33.92566","0.14709"
"67920","407.48400","33.95723","0.15103"
"67983","407.86200","33.98867","0.15505"
"68046","408.24000","34.02013","0.15785"
"68109","408.61800","34.05175","0.16183"
"68172","408.99600","34.08320","0.16612"
"68235","409.37400","34.11465","0.17004"
"68298","409.75200","34.14622","0.17436"
"68361","410.13000","34.17773","0.17762"
"68424","410.50800","34.20918","0.18027"
"68487","410.88600","34.24063","0.18301"
"68550","411.26400","34.27220","0.18569"
"68613","411.64200","34.30371","0.18959"
"68676","412.02000","34.33516","0.19309"
"68739","412.39800","34.36666","0.19667"
"68802","412.77600","34.39823","0.20023"
"68865","413.15400","34.42968","0.20267"
"68928","413.53200","34.46119","0.20521"
"68991","413.91000","34.49270","0.20658"
"69054","414.28800","34.52421","0.20879"
"69117","414.66600","34.55566","0.21103"
"69180","415.04400","34.58729","0.21497"
"69243","415.42200","34.61874","0.21813"
"69306","415.80000","34.65013","0.22146"
"69369","416.17800","34.68170","0.22371"
"69432","416.55600","34.71320","0.22688"
"69495","416.93400","34.74471","0.23017"
"69558","417.31200","34.77616","0.23331"
"69621","417.69000","34.80767","0.23588"
"69684","418.06800","34.83918","0.23942"
"69747","418.44600","34.87063","0.24213"
"69810","418.82400","34.90220","0.24548"
"69873","419.20200","34.93377","0.24858"
"69936","419.58000","34.96516","0.25246"
"69999","419.95800","34.99673","0.25576"
"70062","420.33600","35.02818","0.25939"
"70125","420.71400","35.05969","0.26254"
"70188","421.09200","35.09119","0.26596"
"70251","421.47000","35.12270","0.26814"
"70314","421.84800","35.15421","0.27054"
"70377","422.22600","35.18566","0.27432"
"70440","422.60400","35.21717","0.27850"
"70503","422.98200","35.24874","0.28231"
"70566","423.36000","35.28013","0.28682"
"70629","423.73800","35.31170","0.29059"
"70692","424.11600","35.34321","0.29468"
"70755","424.49400","35.37472","0.29793"
"70818","424.87200","35.40617","0.29995"
"70881","425.25000","35.43773","0.30240"
"70944","425.62800","35.46918","0.30368"
"71007","426.00600","35.50069","0.03766"
"71070","426.38400","35.53226","0.00099"
"71133","426.76200","35.56371","0.01940"
"71196","427.14000","35.59516","0.03194"
"71259","427.51800","35.62667","0.06905"
"71322","427.89600","35.65818","0.07771"
"71385","428.27400","35.68969","0.06917"
"71448","428.65200","35.72114","0.04453"
"71511","429.03000","35.75270","0.03219"
"71574","429.40800","35.78428","0.02719"
"71637","429.78600","35.81561","0.03730"
"71700","430.16400","35.84711","0.05212"
"71763","430.54200","35.87874","0.06859"
"71826","430.92000","35.91019","0.07632"
"71889","431.29800","35.94170","0.07123"
"71952","431.67600","35.97321","0.06205"
"72015","432.05400","36.00466","0.05393"
"72078","432.43200","36.03617","0.05153"
"72141","432.81000","36.06768","0.05622"
"72204","433.18800","36.09925","0.06615"
"72267","433.56600","36.13070","0.07727"
"72330","433.94400","36.16214","0.08406"
"72393","434.32200","36.19365","0.08506"
"72456","434.70000","36.22522","0.07986"
"72519","435.07800","36.25667","0.07460"
"72582","435.45600","36.28818","0.07630"
"72645","435.83400","36.31969","0.08290"
"72708","436.21200","36.35114","0.08924"
"72771","436.59000","36.38271","0.09324"
"72834","436.96800","36.41422","0.09562"
"72897","437.34600","36.44567","0.09533"
"72960","437.72400","36.47723","0.09446"
"73023","438.10200","36.50868","0.09595"
"73086","438.48000","36.54013","0.09813"
"73149","438.85800","36.57164","0.10250"
"73212","439.23600","36.60321","0.10831"
"73275","439.61400","36.63472","0.11072"
"73338","439.99200","36.66617","0.11142"
"73401","440.37000","36.69768","0.11251"
"73464","440.74800","36.72925","0.11492"
"73527","441.12600","36.76064","0.11988"
"73590","441.50400","36.79215","0.12556"
"73653","441.88200","36.82372","0.13163"
"73716","442.26000","36.85516","0.13688"
"73779","442.63800","36.88667","0.14050"
"73842","443.01600","36.91818","0.14416"
"73905","443.39400","36.94970","0.14603"
"73968","443.77200","36.98114","0.14850"
"74031","444.15000","37.01271","0.15297"
"74094","444.52800","37.04416","0.15976"
"74157","444.90600","37.07573","0.16529"
"74220","445.28400","37.10718","0.16914"
"74283","445.66200","37.13869","0.17071"
"74346","446.04000","37.17020","0.17203"
"74409","446.41800","37.20171","0.17451"
"74472","446.79600","37.23315","0.17798"
"74535","447.17400","37.26472","0.18416"
"74598","447.55200","37.29611","0.18876"
"74661","447.93000","37.32768","0.19281"
"74724","448.30800","37.35919","0.19524"
"74787","448.68600","37.39070","0.19583"
"74850","449.06400","37.42215","0.19757"
"74913","449.44200","37.45372","0.19970"
"74976","449.82000","37.48517","0.20239"
"75039","450.19800","37.51662","0.20550"
"75102","450.57600","37.54818","0.20821"
"75165","450.95400","37.57976","0.21107"
"75228","451.33200","37.61115","0.21404"
"75291","451.71000","37.64265","0.21646"
"75354","452.08800","37.67422","0.21823"
"75417","452.46600","37.70567","0.22173"
"75480","452.84400","37.73718","0.22384"
"75543","453.22200","37.76875","0.22681"
"75606","453.60000","37.80020","0.23006"
"75669","453.97800","37.83165","0.23405"
"75732","454.35600","37.86316","0.23772"
"75795","454.73400","37.89473","0.24124"
"75858","455.11200","37.92617","0.24421"
"75921","455.49000","37.95768","0.24692"
"75984","455.86800","37.98919","0.25058"
"76047","456.24600","38.02070","0.25428"
"76110","456.62400","38.05215","0.25812"
"76173","457.00200","38.08372","0.26254"
"76236","457.38000","38.11523","0.26589"
"76299","457.75800","38.14662","0.26896"
"76362","458.13600","38.17819","0.27241"
"76425","458.51400","38.20976","0.27695"
"76488","458.89200","38.24109","0.28049"
"76551","459.27000","38.27272","0.28583"
"76614","459.64800","38.30423","0.28959"
"76677","460.02600","38.33567","0.29402"
"76740","460.40400","38.36718","0.29709"
"76803","460.78200","38.39869","0.29947"
"76866","461.16000","38.43020","-0.00970"
"76929","461.53800","38.46165","-0.00734"
"76992","461.91600","38.49316","-0.00611"
"77055","462.29400","38.52467","-0.00788"
"77118","462.67200","38.55618","-0.00649"
"77181","463.05000","38.58763","-0.00599"
"77244","463.42800","38.61926","-0.00749"
"77260","463.52200","38.62703","-0.00788"