File: Trajectories_together/161226_1Specimen_RawData_3.csv
"","V1","V2","V3"
"1","End date","12/26/2016",""
"2","Specimen label","10AT_64",""
"3","Maximum Load","0.01466","N"
"4","Time","Extension","Load"
"5","(s)","(mm)","(N)"
"6","0.00000","0.00000","-0.00008"
"23","0.10200","0.00395","0.00044"
"40","0.20400","0.01441","-0.00010"
"57","0.30600","0.02511","0.00003"
"74","0.40800","0.03420","0.00019"
"91","0.51000","0.04281","-0.00039"
"108","0.61200","0.05124","-0.00047"
"125","0.71400","0.05967","-0.00057"
"142","0.81600","0.06816","-0.00012"
"159","0.91800","0.07671","-0.00008"
"176","1.02000","0.08520","-0.00003"
"193","1.12200","0.09375","0.00022"
"210","1.22400","0.10218","0.00055"
"227","1.32600","0.11067","0.00011"
"244","1.42800","0.11916","0.00030"
"261","1.53000","0.12771","0.00001"
"278","1.63200","0.13626","0.00010"
"295","1.73400","0.14469","0.00011"
"312","1.83600","0.15318","0.00045"
"329","1.93800","0.16167","-0.00028"
"346","2.04000","0.17022","-0.00056"
"363","2.14200","0.17871","-0.00029"
"380","2.24400","0.18720","0.00000"
"397","2.34600","0.19569","0.00058"
"414","2.44800","0.20418","0.00016"
"431","2.55000","0.21273","0.00002"
"448","2.65200","0.22116","0.00008"
"465","2.75400","0.22971","0.00005"
"482","2.85600","0.23820","-0.00011"
"499","2.95800","0.24663","0.00019"
"516","3.06000","0.25518","-0.00038"
"533","3.16200","0.26373","-0.00033"
"550","3.26400","0.27222","-0.00025"
"567","3.36600","0.28065","-0.00022"
"584","3.46800","0.28920","-0.00042"
"601","3.57000","0.29769","0.00019"
"618","3.67200","0.30618","-0.00031"
"635","3.77400","0.31473","-0.00048"
"652","3.87600","0.32322","-0.00034"
"669","3.97800","0.33165","-0.00074"
"686","4.08000","0.34020","-0.00023"
"703","4.18200","0.34875","-0.00070"
"720","4.28400","0.35718","0.00017"
"737","4.38600","0.36567","-0.00063"
"754","4.48800","0.37416","-0.00062"
"771","4.59000","0.38265","-0.00044"
"788","4.69200","0.39120","-0.00004"
"805","4.79400","0.39969","-0.00037"
"822","4.89600","0.40818","-0.00070"
"839","4.99800","0.41667","-0.00056"
"856","5.10000","0.42516","-0.00033"
"873","5.20200","0.43365","-0.00055"
"890","5.30400","0.44220","-0.00051"
"907","5.40600","0.45069","-0.00045"
"924","5.50800","0.45918","-0.00089"
"941","5.61000","0.46767","-0.00055"
"958","5.71200","0.47616","-0.00032"
"975","5.81400","0.48471","-0.00039"
"992","5.91600","0.49320","-0.00074"
"1009","6.01800","0.50175","-0.00036"
"1026","6.12000","0.51018","-0.00042"
"1043","6.22200","0.51867","-0.00051"
"1060","6.32400","0.52722","-0.00057"
"1077","6.42600","0.53571","-0.00036"
"1094","6.52800","0.54420","-0.00027"
"1111","6.63000","0.55269","-0.00022"
"1128","6.73200","0.56118","-0.00045"
"1145","6.83400","0.56973","-0.00046"
"1162","6.93600","0.57816","-0.00042"
"1179","7.03800","0.58677","-0.00061"
"1196","7.14000","0.59520","-0.00031"
"1213","7.24200","0.60358","-0.00080"
"1230","7.34400","0.61224","-0.00034"
"1247","7.44600","0.62073","-0.00065"
"1264","7.54800","0.62917","-0.00067"
"1281","7.65000","0.63772","-0.00041"
"1298","7.75200","0.64621","-0.00059"
"1315","7.85400","0.65464","-0.00039"
"1332","7.95600","0.66325","-0.00022"
"1349","8.05800","0.67174","-0.00063"
"1366","8.16000","0.68023","-0.00050"
"1383","8.26200","0.68872","-0.00072"
"1400","8.36400","0.69715","-0.00035"
"1417","8.46600","0.70570","-0.00068"
"1434","8.56800","0.71425","-0.00053"
"1451","8.67000","0.72268","-0.00061"
"1468","8.77200","0.73117","-0.00060"
"1485","8.87400","0.73966","-0.00012"
"1502","8.97600","0.74815","-0.00078"
"1519","9.07800","0.75670","-0.00036"
"1536","9.18000","0.76525","-0.00030"
"1553","9.28200","0.77368","0.00005"
"1570","9.38400","0.78211","-0.00021"
"1587","9.48600","0.79072","-0.00028"
"1604","9.58800","0.79927","0.00008"
"1621","9.69000","0.80776","-0.00060"
"1638","9.79200","0.81625","-0.00030"
"1655","9.89400","0.82468","-0.00061"
"1672","9.99600","0.83311","-0.00037"
"1689","10.09800","0.84166","-0.00005"
"1706","10.20000","0.85027","-0.00034"
"1723","10.30200","0.85870","-0.00032"
"1740","10.40400","0.86719","-0.00025"
"1757","10.50600","0.87562","-0.00046"
"1774","10.60800","0.88423","-0.00054"
"1791","10.71000","0.89266","-0.00045"
"1808","10.81200","0.90121","-0.00014"
"1825","10.91400","0.90970","-0.00030"
"1842","11.01600","0.91807","-0.00058"
"1859","11.11800","0.92668","-0.00044"
"1876","11.22000","0.93523","-0.00074"
"1893","11.32200","0.94372","-0.00038"
"1910","11.42400","0.95221","-0.00056"
"1927","11.52600","0.96070","0.00031"
"1944","11.62800","0.96925","-0.00051"
"1961","11.73000","0.97768","-0.00058"
"1978","11.83200","0.98623","-0.00059"
"1995","11.93400","0.99472","-0.00034"
"2012","12.03600","1.00321","-0.00051"
"2029","12.13800","1.01170","-0.00031"
"2046","12.24000","1.02025","-0.00031"
"2063","12.34200","1.02874","-0.00044"
"2080","12.44400","1.03723","0.00001"
"2097","12.54600","1.04572","-0.00029"
"2114","12.64800","1.05421","-0.00045"
"2131","12.75000","1.06270","-0.00064"
"2148","12.85200","1.07119","-0.00024"
"2165","12.95400","1.07968","-0.00014"
"2182","13.05600","1.08817","-0.00031"
"2199","13.15800","1.09666","0.00036"
"2216","13.26000","1.10515","-0.00026"
"2233","13.36200","1.11376","0.00026"
"2250","13.46400","1.12225","-0.00040"
"2267","13.56600","1.13068","0.00009"
"2284","13.66800","1.13917","-0.00024"
"2301","13.77000","1.14772","0.00006"
"2318","13.87200","1.15621","-0.00021"
"2335","13.97400","1.16476","0.00007"
"2352","14.07600","1.17325","-0.00057"
"2369","14.17800","1.18168","-0.00002"
"2386","14.28000","1.19017","-0.00052"
"2403","14.38200","1.19872","-0.00001"
"2420","14.48400","1.20721","-0.00019"
"2437","14.58600","1.21570","-0.00012"
"2454","14.68800","1.22419","-0.00025"
"2471","14.79000","1.23268","-0.00008"
"2488","14.89200","1.24123","-0.00045"
"2505","14.99400","1.24966","-0.00032"
"2522","15.09600","1.25821","-0.00055"
"2539","15.19800","1.26670","-0.00089"
"2556","15.30000","1.27507","0.00020"
"2573","15.40200","1.28368","0.00038"
"2590","15.50400","1.29229","-0.00058"
"2607","15.60600","1.30072","-0.00061"
"2624","15.70800","1.30915","0.00012"
"2641","15.81000","1.31764","-0.00006"
"2658","15.91200","1.32619","0.00005"
"2675","16.01400","1.33474","-0.00030"
"2692","16.11600","1.34317","-0.00031"
"2709","16.21800","1.35172","0.00005"
"2726","16.32000","1.36021","-0.00007"
"2743","16.42200","1.36864","0.00008"
"2760","16.52400","1.37719","-0.00033"
"2777","16.62600","1.38574","-0.00026"
"2794","16.72800","1.39417","-0.00018"
"2811","16.83000","1.40272","-0.00019"
"2828","16.93200","1.41121","-0.00007"
"2845","17.03400","1.41964","-0.00052"
"2862","17.13600","1.42819","0.00010"
"2879","17.23800","1.43668","-0.00061"
"2896","17.34000","1.44517","0.00045"
"2913","17.44200","1.45360","0.00016"
"2930","17.54400","1.46221","0.00032"
"2947","17.64600","1.47070","0.00010"
"2964","17.74800","1.47919","-0.00006"
"2981","17.85000","1.48774","-0.00023"
"2998","17.95200","1.49617","0.00013"
"3015","18.05400","1.50466","0.00013"
"3032","18.15600","1.51321","-0.00013"
"3049","18.25800","1.52176","-0.00015"
"3066","18.36000","1.53025","0.00009"
"3083","18.46200","1.53868","0.00020"
"3100","18.56400","1.54717","0.00039"
"3117","18.66600","1.55572","-0.00050"
"3134","18.76800","1.56421","0.00025"
"3151","18.87000","1.57270","-0.00033"
"3168","18.97200","1.58125","0.00001"
"3185","19.07400","1.58968","-0.00019"
"3202","19.17600","1.59817","-0.00035"
"3219","19.27800","1.60666","-0.00071"
"3236","19.38000","1.61521","0.00021"
"3253","19.48200","1.62370","-0.00011"
"3270","19.58400","1.63213","0.00016"
"3287","19.68600","1.64068","0.00018"
"3304","19.78800","1.64923","0.00014"
"3321","19.89000","1.65772","-0.00040"
"3338","19.99200","1.66621","-0.00013"
"3355","20.09400","1.67470","0.00061"
"3372","20.19600","1.68314","-0.00027"
"3389","20.29800","1.69169","0.00002"
"3406","20.40000","1.70018","0.00015"
"3423","20.50200","1.70867","0.00008"
"3440","20.60400","1.71716","0.00008"
"3457","20.70600","1.72565","0.00023"
"3474","20.80800","1.73420","0.00005"
"3491","20.91000","1.74269","-0.00007"
"3508","21.01200","1.75118","0.00016"
"3525","21.11400","1.75973","0.00016"
"3542","21.21600","1.76816","-0.00030"
"3559","21.31800","1.77671","0.00006"
"3576","21.42000","1.78520","0.00029"
"3593","21.52200","1.79369","-0.00010"
"3610","21.62400","1.80218","-0.00003"
"3627","21.72600","1.81067","0.00048"
"3644","21.82800","1.81916","-0.00026"
"3661","21.93000","1.82771","-0.00023"
"3678","22.03200","1.83620","0.00005"
"3695","22.13400","1.84469","0.00017"
"3712","22.23600","1.85318","-0.00031"
"3729","22.33800","1.86167","0.00010"
"3746","22.44000","1.87016","0.00022"
"3763","22.54200","1.87877","0.00008"
"3780","22.64400","1.88720","-0.00037"
"3797","22.74600","1.89563","-0.00049"
"3814","22.84800","1.90418","0.00069"
"3831","22.95000","1.91273","0.00028"
"3848","23.05200","1.92116","0.00029"
"3865","23.15400","1.92971","-0.00001"
"3882","23.25600","1.93820","-0.00037"
"3899","23.35800","1.94663","0.00004"
"3916","23.46000","1.95518","-0.00029"
"3933","23.56200","1.96373","-0.00010"
"3950","23.66400","1.97222","-0.00036"
"3967","23.76600","1.98071","0.00013"
"3984","23.86800","1.98914","-0.00022"
"4001","23.97000","1.99769","-0.00041"
"4018","24.07200","2.00624","-0.00021"
"4035","24.17400","2.01473","-0.00031"
"4052","24.27600","2.02328","-0.00008"
"4069","24.37800","2.03171","-0.00011"
"4086","24.48000","2.04014","-0.00023"
"4103","24.58200","2.04869","0.00004"
"4120","24.68400","2.05724","0.00037"
"4137","24.78600","2.06573","-0.00026"
"4154","24.88800","2.07416","0.00052"
"4171","24.99000","2.08265","-0.00017"
"4188","25.09200","2.09120","0.00018"
"4205","25.19400","2.09975","0.00056"
"4222","25.29600","2.10824","-0.00025"
"4239","25.39800","2.11667","-0.00008"
"4256","25.50000","2.12516","0.00015"
"4273","25.60200","2.13371","0.00014"
"4290","25.70400","2.14220","0.00025"
"4307","25.80600","2.15069","0.00002"
"4324","25.90800","2.15918","0.00004"
"4341","26.01000","2.16767","0.00007"
"4358","26.11200","2.17622","-0.00059"
"4375","26.21400","2.18465","0.00003"
"4392","26.31600","2.19320","0.00026"
"4409","26.41800","2.20175","-0.00005"
"4426","26.52000","2.21018","0.00034"
"4443","26.62200","2.21861","0.00010"
"4460","26.72400","2.22722","0.00051"
"4477","26.82600","2.23577","-0.00071"
"4494","26.92800","2.24420","-0.00009"
"4511","27.03000","2.25269","-0.00002"
"4528","27.13200","2.26118","-0.00009"
"4545","27.23400","2.26967","0.00060"
"4562","27.33600","2.27822","0.00007"
"4579","27.43800","2.28677","-0.00006"
"4596","27.54000","2.29520","0.00021"
"4613","27.64200","2.30363","0.00024"
"4630","27.74400","2.31218","0.00012"
"4647","27.84600","2.32067","0.00011"
"4664","27.94800","2.32916","-0.00005"
"4681","28.05000","2.33765","-0.00024"
"4698","28.15200","2.34614","-0.00003"
"4715","28.25400","2.35463","0.00015"
"4732","28.35600","2.36318","-0.00032"
"4749","28.45800","2.37173","0.00010"
"4766","28.56000","2.38022","0.00010"
"4783","28.66200","2.38871","-0.00004"
"4800","28.76400","2.39714","-0.00003"
"4817","28.86600","2.40569","-0.00047"
"4834","28.96800","2.41424","-0.00018"
"4851","29.07000","2.42273","-0.00013"
"4868","29.17200","2.43122","0.00027"
"4885","29.27400","2.43965","-0.00012"
"4902","29.37600","2.44820","-0.00001"
"4919","29.47800","2.45675","0.00029"
"4936","29.58000","2.46518","-0.00002"
"4953","29.68200","2.47367","-0.00029"
"4970","29.78400","2.48222","0.00018"
"4987","29.88600","2.49071","0.00022"
"5004","29.98800","2.49926","-0.00001"
"5021","30.09000","2.50769","0.00020"
"5038","30.19200","2.51618","0.00042"
"5055","30.29400","2.52467","0.00029"
"5072","30.39600","2.53316","-0.00013"
"5089","30.49800","2.54165","0.00014"
"5106","30.60000","2.55020","-0.00029"
"5123","30.70200","2.55875","0.00023"
"5140","30.80400","2.56712","0.00014"
"5157","30.90600","2.57567","0.00043"
"5174","31.00800","2.58422","0.00039"
"5191","31.11000","2.59271","0.00008"
"5208","31.21200","2.60120","0.00037"
"5225","31.31400","2.60969","-0.00003"
"5242","31.41600","2.61818","0.00029"
"5259","31.51800","2.62667","0.00006"
"5276","31.62000","2.63522","0.00000"
"5293","31.72200","2.64371","0.00002"
"5310","31.82400","2.65220","-0.00001"
"5327","31.92600","2.66069","-0.00033"
"5344","32.02800","2.66918","0.00015"
"5361","32.13000","2.67773","-0.00029"
"5378","32.23200","2.68622","-0.00017"
"5395","32.33400","2.69465","-0.00020"
"5412","32.43600","2.70320","-0.00008"
"5429","32.53800","2.71163","-0.00001"
"5446","32.64000","2.72018","0.00049"
"5463","32.74200","2.72873","-0.00027"
"5480","32.84400","2.73722","-0.00038"
"5497","32.94600","2.74571","0.00016"
"5514","33.04800","2.75420","0.00013"
"5531","33.15000","2.76270","-0.00007"
"5548","33.25200","2.77124","0.00053"
"5565","33.35400","2.77974","0.00024"
"5582","33.45600","2.78823","0.00043"
"5599","33.55800","2.79666","0.00023"
"5616","33.66000","2.80515","-0.00004"
"5633","33.76200","2.81376","0.00030"
"5650","33.86400","2.82225","0.00041"
"5667","33.96600","2.83068","0.00018"
"5684","34.06800","2.83917","0.00049"
"5701","34.17000","2.84772","0.00035"
"5718","34.27200","2.85615","0.00021"
"5735","34.37400","2.86470","0.00022"
"5752","34.47600","2.87319","0.00033"
"5769","34.57800","2.88168","0.00030"
"5786","34.68000","2.89017","0.00023"
"5803","34.78200","2.89866","0.00090"
"5820","34.88400","2.90721","0.00019"
"5837","34.98600","2.91576","-0.00001"
"5854","35.08800","2.92419","0.00066"
"5871","35.19000","2.93268","0.00052"
"5888","35.29200","2.94123","0.00056"
"5905","35.39400","2.94972","0.00004"
"5922","35.49600","2.95821","-0.00023"
"5939","35.59800","2.96670","0.00032"
"5956","35.70000","2.97519","0.00017"
"5973","35.80200","2.98368","0.00024"
"5990","35.90400","2.99217","0.00048"
"6007","36.00600","3.00072","0.00065"
"6024","36.10800","3.00915","0.00045"
"6041","36.21000","3.01764","0.00042"
"6058","36.31200","3.02619","0.00045"
"6075","36.41400","3.03468","0.00049"
"6092","36.51600","3.04317","0.00056"
"6109","36.61800","3.05172","0.00044"
"6126","36.72000","3.06021","0.00045"
"6143","36.82200","3.06864","-0.00003"
"6160","36.92400","3.07719","0.00017"
"6177","37.02600","3.08568","0.00013"
"6194","37.12800","3.09417","0.00062"
"6211","37.23000","3.10272","0.00030"
"6228","37.33200","3.11115","0.00034"
"6245","37.43400","3.11970","0.00070"
"6262","37.53600","3.12825","0.00046"
"6279","37.63800","3.13668","0.00046"
"6296","37.74000","3.14523","0.00054"
"6313","37.84200","3.15366","0.00047"
"6330","37.94400","3.16215","0.00000"
"6347","38.04600","3.17070","0.00008"
"6364","38.14800","3.17925","0.00072"
"6381","38.25000","3.18768","0.00044"
"6398","38.35200","3.19617","0.00077"
"6415","38.45400","3.20466","0.00029"
"6432","38.55600","3.21315","0.00028"
"6449","38.65800","3.22170","0.00070"
"6466","38.76000","3.23025","0.00080"
"6483","38.86200","3.23868","0.00039"
"6500","38.96400","3.24711","0.00000"
"6517","39.06600","3.25572","-0.00018"
"6534","39.16800","3.26421","0.00087"
"6551","39.27000","3.27270","0.00050"
"6568","39.37200","3.28119","0.00051"
"6585","39.47400","3.28968","0.00067"
"6602","39.57600","3.29817","0.00065"
"6619","39.67800","3.30666","0.00049"
"6636","39.78000","3.31521","0.00032"
"6653","39.88200","3.32376","0.00084"
"6670","39.98400","3.33219","0.00000"
"6687","40.08600","3.34068","0.00073"
"6704","40.18800","3.34923","0.00051"
"6721","40.29000","3.35772","0.00045"
"6738","40.39200","3.36621","0.00049"
"6755","40.49400","3.37470","0.00031"
"6772","40.59600","3.38313","0.00026"
"6789","40.69800","3.39168","0.00033"
"6806","40.80000","3.40023","0.00062"
"6823","40.90200","3.40872","0.00061"
"6840","41.00400","3.41721","0.00037"
"6857","41.10600","3.42564","0.00052"
"6874","41.20800","3.43419","0.00063"
"6891","41.31000","3.44274","0.00019"
"6908","41.41200","3.45117","0.00040"
"6925","41.51400","3.45972","0.00060"
"6942","41.61600","3.46821","0.00071"
"6959","41.71800","3.47664","0.00071"
"6976","41.82000","3.48525","0.00059"
"6993","41.92200","3.49374","0.00028"
"7010","42.02400","3.50223","0.00054"
"7027","42.12600","3.51072","0.00064"
"7044","42.22800","3.51915","0.00082"
"7061","42.33000","3.52770","0.00083"
"7078","42.43200","3.53619","0.00080"
"7095","42.53400","3.54468","0.00071"
"7112","42.63600","3.55317","0.00083"
"7129","42.73800","3.56166","0.00047"
"7146","42.84000","3.57015","0.00070"
"7163","42.94200","3.57870","0.00084"
"7180","43.04400","3.58725","0.00080"
"7197","43.14600","3.59568","0.00052"
"7214","43.24800","3.60411","0.00040"
"7231","43.35000","3.61272","0.00094"
"7248","43.45200","3.62121","0.00070"
"7265","43.55400","3.62964","0.00075"
"7282","43.65600","3.63819","0.00089"
"7299","43.75800","3.64668","0.00073"
"7316","43.86000","3.65511","0.00068"
"7333","43.96200","3.66366","0.00059"
"7350","44.06400","3.67227","0.00090"
"7367","44.16600","3.68070","0.00064"
"7384","44.26800","3.68919","0.00112"
"7401","44.37000","3.69762","0.00104"
"7418","44.47200","3.70617","0.00058"
"7435","44.57400","3.71472","0.00055"
"7452","44.67600","3.72321","0.00082"
"7469","44.77800","3.73170","0.00091"
"7486","44.88000","3.74013","0.00116"
"7503","44.98200","3.74868","0.00095"
"7520","45.08400","3.75723","0.00102"
"7537","45.18600","3.76572","0.00078"
"7554","45.28800","3.77421","0.00086"
"7571","45.39000","3.78264","0.00076"
"7588","45.49200","3.79119","0.00067"
"7605","45.59400","3.79974","0.00068"
"7622","45.69600","3.80823","0.00161"
"7639","45.79800","3.81672","0.00133"
"7656","45.90000","3.82521","0.00149"
"7673","46.00200","3.83365","0.00087"
"7690","46.10400","3.84220","0.00089"
"7707","46.20600","3.85074","0.00092"
"7724","46.30800","3.85918","0.00099"
"7741","46.41000","3.86767","0.00094"
"7758","46.51200","3.87622","0.00121"
"7775","46.61400","3.88471","0.00174"
"7792","46.71600","3.89320","0.00098"
"7809","46.81800","3.90175","0.00159"
"7826","46.92000","3.91024","0.00162"
"7843","47.02200","3.91867","0.00136"
"7860","47.12400","3.92716","0.00139"
"7877","47.22600","3.93577","0.00107"
"7894","47.32800","3.94420","0.00172"
"7911","47.43000","3.95263","0.00171"
"7928","47.53200","3.96118","0.00108"
"7945","47.63400","3.96967","0.00086"
"7962","47.73600","3.97822","0.00192"
"7979","47.83800","3.98671","0.00101"
"7996","47.94000","3.99526","0.00169"
"8013","48.04200","4.00369","0.00104"
"8030","48.14400","4.01218","0.00120"
"8047","48.24600","4.02073","0.00159"
"8064","48.34800","4.02922","0.00147"
"8081","48.45000","4.03771","0.00144"
"8098","48.55200","4.04620","0.00117"
"8115","48.65400","4.05463","0.00141"
"8132","48.75600","4.06312","0.00174"
"8149","48.85800","4.07173","0.00165"
"8166","48.96000","4.08022","0.00125"
"8183","49.06200","4.08871","0.00143"
"8200","49.16400","4.09714","0.00133"
"8217","49.26600","4.10569","0.00130"
"8234","49.36800","4.11430","0.00117"
"8251","49.47000","4.12267","0.00151"
"8268","49.57200","4.13122","0.00138"
"8285","49.67400","4.13965","0.00142"
"8302","49.77600","4.14814","0.00135"
"8319","49.87800","4.15675","0.00133"
"8336","49.98000","4.16524","0.00125"
"8353","50.08200","4.17373","0.00214"
"8370","50.18400","4.18222","0.00167"
"8387","50.28600","4.19065","0.00129"
"8404","50.38800","4.19920","0.00108"
"8421","50.49000","4.20775","0.00174"
"8438","50.59200","4.21624","0.00143"
"8455","50.69400","4.22473","0.00190"
"8472","50.79600","4.23316","0.00163"
"8489","50.89800","4.24165","0.00177"
"8506","51.00000","4.25026","0.00169"
"8523","51.10200","4.25875","0.00155"
"8540","51.20400","4.26724","0.00226"
"8557","51.30600","4.27567","0.00153"
"8574","51.40800","4.28416","0.00193"
"8591","51.51000","4.29271","0.00157"
"8608","51.61200","4.30120","0.00157"
"8625","51.71400","4.30969","0.00183"
"8642","51.81600","4.31818","0.00134"
"8659","51.91800","4.32661","0.00162"
"8676","52.02000","4.33516","0.00194"
"8693","52.12200","4.34371","0.00167"
"8710","52.22400","4.35220","0.00188"
"8727","52.32600","4.36069","0.00152"
"8744","52.42800","4.36918","0.00125"
"8761","52.53000","4.37767","0.00152"
"8778","52.63200","4.38622","0.00189"
"8795","52.73400","4.39477","0.00198"
"8812","52.83600","4.40320","0.00198"
"8829","52.93800","4.41169","0.00175"
"8846","53.04000","4.42018","0.00190"
"8863","53.14200","4.42867","0.00163"
"8880","53.24400","4.43728","0.00155"
"8897","53.34600","4.44571","0.00145"
"8914","53.44800","4.45420","0.00200"
"8931","53.55000","4.46263","0.00171"
"8948","53.65200","4.47118","0.00237"
"8965","53.75400","4.47967","0.00197"
"8982","53.85600","4.48822","0.00142"
"8999","53.95800","4.49665","0.00178"
"9016","54.06000","4.50508","0.00223"
"9033","54.16200","4.51369","0.00190"
"9050","54.26400","4.52224","0.00149"
"9067","54.36600","4.53073","0.00217"
"9084","54.46800","4.53916","0.00180"
"9101","54.57000","4.54771","0.00207"
"9118","54.67200","4.55620","0.00182"
"9135","54.77400","4.56469","0.00214"
"9152","54.87600","4.57318","0.00215"
"9169","54.97800","4.58173","0.00219"
"9186","55.08000","4.59016","0.00219"
"9203","55.18200","4.59865","0.00228"
"9220","55.28400","4.60720","0.00184"
"9237","55.38600","4.61569","0.00213"
"9254","55.48800","4.62418","0.00197"
"9271","55.59000","4.63267","0.00206"
"9288","55.69200","4.64116","0.00218"
"9305","55.79400","4.64971","0.00199"
"9322","55.89600","4.65820","0.00230"
"9339","55.99800","4.66669","0.00216"
"9356","56.10000","4.67518","0.00180"
"9373","56.20200","4.68367","0.00189"
"9390","56.30400","4.69216","0.00219"
"9407","56.40600","4.70071","0.00257"
"9424","56.50800","4.70920","0.00264"
"9441","56.61000","4.71763","0.00265"
"9458","56.71200","4.72618","0.00259"
"9475","56.81400","4.73473","0.00282"
"9492","56.91600","4.74316","0.00237"
"9509","57.01800","4.75171","0.00244"
"9526","57.12000","4.76026","0.00307"
"9543","57.22200","4.76863","0.00249"
"9560","57.32400","4.77718","0.00257"
"9577","57.42600","4.78573","0.00265"
"9594","57.52800","4.79416","0.00208"
"9611","57.63000","4.80271","0.00277"
"9628","57.73200","4.81120","0.00237"
"9645","57.83400","4.81963","0.00265"
"9662","57.93600","4.82818","0.00247"
"9679","58.03800","4.83673","0.00243"
"9696","58.14000","4.84522","0.00234"
"9713","58.24200","4.85371","0.00264"
"9730","58.34400","4.86214","0.00304"
"9747","58.44600","4.87069","0.00296"
"9764","58.54800","4.87930","0.00300"
"9781","58.65000","4.88773","0.00298"
"9798","58.75200","4.89616","0.00317"
"9815","58.85400","4.90465","0.00301"
"9832","58.95600","4.91320","0.00286"
"9849","59.05800","4.92170","0.00339"
"9866","59.16000","4.93018","0.00282"
"9883","59.26200","4.93873","0.00290"
"9900","59.36400","4.94717","0.00302"
"9917","59.46600","4.95560","0.00291"
"9934","59.56800","4.96426","0.00317"
"9951","59.67000","4.97276","0.00348"
"9968","59.77200","4.98119","0.00271"
"9985","59.87400","4.98968","0.00307"
"10002","59.97600","4.99817","0.00319"
"10019","60.07800","5.00666","0.00288"
"10036","60.18000","5.01521","0.00322"
"10053","60.28200","5.02376","0.00360"
"10070","60.38400","5.03213","0.00340"
"10087","60.48600","5.04068","0.00339"
"10104","60.58800","5.04917","0.00357"
"10121","60.69000","5.05778","0.00373"
"10138","60.79200","5.06621","0.00388"
"10155","60.89400","5.07470","0.00365"
"10172","60.99600","5.08319","0.00403"
"10189","61.09800","5.09162","0.00382"
"10206","61.20000","5.10023","0.00315"
"10223","61.30200","5.10872","0.00410"
"10240","61.40400","5.11721","0.00418"
"10257","61.50600","5.12564","0.00395"
"10274","61.60800","5.13413","0.00416"
"10291","61.71000","5.14268","0.00380"
"10308","61.81200","5.15117","0.00343"
"10325","61.91400","5.15972","0.00362"
"10342","62.01600","5.16821","0.00387"
"10359","62.11800","5.17664","0.00397"
"10376","62.22000","5.18513","0.00381"
"10393","62.32200","5.19368","0.00397"
"10410","62.42400","5.20223","0.00412"
"10427","62.52600","5.21066","0.00338"
"10444","62.62800","5.21915","0.00410"
"10461","62.73000","5.22770","0.00364"
"10478","62.83200","5.23625","0.00372"
"10495","62.93400","5.24468","0.00422"
"10512","63.03600","5.25323","0.00456"
"10529","63.13800","5.26172","0.00419"
"10546","63.24000","5.27015","0.00428"
"10563","63.34200","5.27870","0.00480"
"10580","63.44400","5.28719","0.00449"
"10597","63.54600","5.29568","0.00426"
"10614","63.64800","5.30417","0.00444"
"10631","63.75000","5.31266","0.00443"
"10648","63.85200","5.32121","0.00455"
"10665","63.95400","5.32970","0.00468"
"10682","64.05600","5.33819","0.00450"
"10699","64.15800","5.34668","0.00456"
"10716","64.26000","5.35511","0.00408"
"10733","64.36200","5.36366","0.00431"
"10750","64.46400","5.37227","0.00485"
"10767","64.56600","5.38070","0.00399"
"10784","64.66800","5.38913","0.00434"
"10801","64.77000","5.39768","0.00450"
"10818","64.87200","5.40617","0.00533"
"10835","64.97400","5.41472","0.00376"
"10852","65.07600","5.42321","0.00260"
"10869","65.17800","5.43170","0.00202"
"10886","65.28000","5.44013","0.00253"
"10903","65.38200","5.44868","0.00300"
"10920","65.48400","5.45723","0.00224"
"10937","65.58600","5.46572","0.00257"
"10954","65.68800","5.47421","0.00314"
"10971","65.79000","5.48264","0.00339"
"10988","65.89200","5.49113","0.00291"
"11005","65.99400","5.49974","0.00271"
"11022","66.09600","5.50817","0.00278"
"11039","66.19800","5.51672","0.00265"
"11056","66.30000","5.52521","0.00316"
"11073","66.40200","5.53364","0.00304"
"11090","66.50400","5.54219","0.00337"
"11107","66.60600","5.55074","0.00318"
"11124","66.70800","5.55923","0.00302"
"11141","66.81000","5.56766","0.00322"
"11158","66.91200","5.57615","0.00326"
"11175","67.01400","5.58470","0.00303"
"11192","67.11600","5.59319","0.00396"
"11209","67.21800","5.60168","0.00353"
"11226","67.32000","5.61023","0.00336"
"11243","67.42200","5.61866","0.00335"
"11260","67.52400","5.62709","0.00421"
"11277","67.62600","5.63570","0.00327"
"11294","67.72800","5.64425","0.00379"
"11311","67.83000","5.65268","0.00448"
"11328","67.93200","5.66117","0.00354"
"11345","68.03400","5.66966","0.00311"
"11362","68.13600","5.67815","0.00361"
"11379","68.23800","5.68670","0.00373"
"11396","68.34000","5.69525","0.00420"
"11413","68.44200","5.70374","0.00341"
"11430","68.54400","5.71217","0.00379"
"11447","68.64600","5.72066","0.00386"
"11464","68.74800","5.72921","0.00400"
"11481","68.85000","5.73770","0.00378"
"11498","68.95200","5.74619","0.00373"
"11515","69.05400","5.75468","0.00401"
"11532","69.15600","5.76317","0.00414"
"11549","69.25800","5.77172","0.00368"
"11566","69.36000","5.78021","0.00341"
"11583","69.46200","5.78870","0.00377"
"11600","69.56400","5.79713","0.00391"
"11617","69.66600","5.80568","0.00420"
"11634","69.76800","5.81417","0.00378"
"11651","69.87000","5.82272","0.00389"
"11668","69.97200","5.83121","0.00387"
"11685","70.07400","5.83970","0.00442"
"11702","70.17600","5.84819","0.00370"
"11719","70.27800","5.85662","0.00386"
"11736","70.38000","5.86517","0.00494"
"11753","70.48200","5.87372","0.00429"
"11770","70.58400","5.88221","0.00458"
"11787","70.68600","5.89064","0.00389"
"11804","70.78800","5.89919","0.00428"
"11821","70.89000","5.90774","0.00430"
"11838","70.99200","5.91617","0.00419"
"11855","71.09400","5.92466","0.00422"
"11872","71.19600","5.93321","0.00416"
"11889","71.29800","5.94164","0.00404"
"11906","71.40000","5.95019","0.00360"
"11923","71.50200","5.95874","0.00407"
"11940","71.60400","5.96723","0.00338"
"11957","71.70600","5.97566","0.00344"
"11974","71.80800","5.98416","0.00412"
"11991","71.91000","5.99265","0.00391"
"12008","72.01200","6.00125","0.00375"
"12025","72.11400","6.00969","0.00367"
"12042","72.21600","6.01817","0.00422"
"12059","72.31800","6.02667","0.00375"
"12076","72.42000","6.03516","0.00406"
"12093","72.52200","6.04371","0.00372"
"12110","72.62400","6.05220","0.00413"
"12127","72.72600","6.06069","0.00418"
"12144","72.82800","6.06918","0.00419"
"12161","72.93000","6.07767","0.00475"
"12178","73.03200","6.08622","0.00428"
"12195","73.13400","6.09471","0.00418"
"12212","73.23600","6.10320","0.00452"
"12229","73.33800","6.11169","0.00434"
"12246","73.44000","6.12018","0.00403"
"12263","73.54200","6.12867","0.00413"
"12280","73.64400","6.13722","0.00448"
"12297","73.74600","6.14571","0.00471"
"12314","73.84800","6.15414","0.00441"
"12331","73.95000","6.16263","0.00476"
"12348","74.05200","6.17118","0.00442"
"12365","74.15400","6.17967","0.00497"
"12382","74.25600","6.18822","0.00470"
"12399","74.35800","6.19671","0.00531"
"12416","74.46000","6.20514","0.00512"
"12433","74.56200","6.21363","0.00488"
"12450","74.66400","6.22224","0.00529"
"12467","74.76600","6.23073","0.00493"
"12484","74.86800","6.23916","0.00526"
"12501","74.97000","6.24765","0.00480"
"12518","75.07200","6.25620","0.00557"
"12535","75.17400","6.26475","0.00551"
"12552","75.27600","6.27318","0.00545"
"12569","75.37800","6.28167","0.00551"
"12586","75.48000","6.29016","0.00576"
"12603","75.58200","6.29859","0.00533"
"12620","75.68400","6.30720","0.00535"
"12637","75.78600","6.31575","0.00113"
"12654","75.88800","6.32424","0.00140"
"12671","75.99000","6.33267","0.00101"
"12688","76.09200","6.34116","0.00103"
"12705","76.19400","6.34971","0.00138"
"12722","76.29600","6.35820","0.00162"
"12739","76.39800","6.36675","0.00088"
"12756","76.50000","6.37524","0.00158"
"12773","76.60200","6.38367","0.00178"
"12790","76.70400","6.39210","0.00136"
"12807","76.80600","6.40077","0.00144"
"12824","76.90800","6.40926","0.00143"
"12841","77.01000","6.41769","0.00117"
"12858","77.11200","6.42618","0.00123"
"12875","77.21400","6.43467","0.00167"
"12892","77.31600","6.44316","0.00132"
"12909","77.41800","6.45171","0.00110"
"12926","77.52000","6.46026","0.00170"
"12943","77.62200","6.46869","0.00114"
"12960","77.72400","6.47712","0.00158"
"12977","77.82600","6.48561","0.00125"
"12994","77.92800","6.49422","0.00125"
"13011","78.03000","6.50277","0.00185"
"13028","78.13200","6.51120","0.00156"
"13045","78.23400","6.51963","0.00188"
"13062","78.33600","6.52818","0.00154"
"13079","78.43800","6.53673","0.00159"
"13096","78.54000","6.54522","0.00166"
"13113","78.64200","6.55371","0.00170"
"13130","78.74400","6.56214","0.00126"
"13147","78.84600","6.57069","0.00093"
"13164","78.94800","6.57918","0.00152"
"13181","79.05000","6.58773","0.00125"
"13198","79.15200","6.59622","0.00162"
"13215","79.25400","6.60465","0.00166"
"13232","79.35600","6.61320","0.00235"
"13249","79.45800","6.62169","0.00148"
"13266","79.56000","6.63012","0.00129"
"13283","79.66200","6.63873","0.00139"
"13300","79.76400","6.64716","0.00125"
"13317","79.86600","6.65559","0.00171"
"13334","79.96800","6.66420","0.00134"
"13351","80.07000","6.67275","0.00177"
"13368","80.17200","6.68118","0.00168"
"13385","80.27400","6.68967","0.00173"
"13402","80.37600","6.69816","0.00156"
"13419","80.47800","6.70671","0.00211"
"13436","80.58000","6.71520","0.00195"
"13453","80.68200","6.72369","0.00127"
"13470","80.78400","6.73218","0.00178"
"13487","80.88600","6.74073","0.00182"
"13504","80.98800","6.74916","0.00154"
"13521","81.09000","6.75771","0.00185"
"13538","81.19200","6.76620","0.00200"
"13555","81.29400","6.77469","0.00252"
"13572","81.39600","6.78318","0.00170"
"13589","81.49800","6.79167","0.00221"
"13606","81.60000","6.80016","0.00184"
"13623","81.70200","6.80871","0.00167"
"13640","81.80400","6.81720","0.00212"
"13657","81.90600","6.82569","0.00195"
"13674","82.00800","6.83412","0.00188"
"13691","82.11000","6.84273","0.00136"
"13708","82.21200","6.85122","0.00161"
"13725","82.31400","6.85971","0.00189"
"13742","82.41600","6.86820","0.00178"
"13759","82.51800","6.87669","0.00209"
"13776","82.62000","6.88512","0.00239"
"13793","82.72200","6.89367","0.00183"
"13810","82.82400","6.90222","0.00199"
"13827","82.92600","6.91071","0.00188"
"13844","83.02800","6.91914","0.00238"
"13861","83.13000","6.92763","0.00201"
"13878","83.23200","6.93624","0.00240"
"13895","83.33400","6.94467","0.00239"
"13912","83.43600","6.95322","0.00257"
"13929","83.53800","6.96171","0.00215"
"13946","83.64000","6.97020","0.00175"
"13963","83.74200","6.97869","0.00233"
"13980","83.84400","6.98724","0.00206"
"13997","83.94600","6.99573","0.00185"
"14014","84.04800","7.00416","0.00201"
"14031","84.15000","7.01259","0.00142"
"14048","84.25200","7.02120","0.00185"
"14065","84.35400","7.02975","0.00237"
"14082","84.45600","7.03824","0.00183"
"14099","84.55800","7.04673","0.00190"
"14116","84.66000","7.05516","0.00187"
"14133","84.76200","7.06366","0.00184"
"14150","84.86400","7.07221","0.00206"
"14167","84.96600","7.08070","0.00183"
"14184","85.06800","7.08919","0.00140"
"14201","85.17000","7.09767","0.00213"
"14218","85.27200","7.10611","0.00188"
"14235","85.37400","7.11472","0.00181"
"14252","85.47600","7.12321","0.00151"
"14269","85.57800","7.13170","0.00202"
"14286","85.68000","7.14019","0.00191"
"14303","85.78200","7.14862","0.00241"
"14320","85.88400","7.15717","0.00230"
"14337","85.98600","7.16572","0.00213"
"14354","86.08800","7.17421","0.00200"
"14371","86.19000","7.18270","0.00201"
"14388","86.29200","7.19119","0.00243"
"14405","86.39400","7.19968","0.00244"
"14422","86.49600","7.20823","0.00252"
"14439","86.59800","7.21672","0.00267"
"14456","86.70000","7.22521","0.00259"
"14473","86.80200","7.23370","0.00260"
"14490","86.90400","7.24213","0.00238"
"14507","87.00600","7.25068","0.00263"
"14524","87.10800","7.25923","0.00204"
"14541","87.21000","7.26766","0.00227"
"14558","87.31200","7.27615","0.00276"
"14575","87.41400","7.28464","0.00216"
"14592","87.51600","7.29319","0.00262"
"14609","87.61800","7.30168","0.00239"
"14626","87.72000","7.31023","0.00208"
"14643","87.82200","7.31872","0.00282"
"14660","87.92400","7.32715","0.00293"
"14677","88.02600","7.33570","0.00268"
"14694","88.12800","7.34425","0.00239"
"14711","88.23000","7.35268","0.00304"
"14728","88.33200","7.36123","0.00210"
"14745","88.43400","7.36966","0.00247"
"14762","88.53600","7.37815","0.00292"
"14779","88.63800","7.38670","0.00327"
"14796","88.74000","7.39519","0.00269"
"14813","88.84200","7.40374","0.00228"
"14830","88.94400","7.41223","0.00245"
"14847","89.04600","7.42066","0.00299"
"14864","89.14800","7.42921","0.00267"
"14881","89.25000","7.43776","0.00305"
"14898","89.35200","7.44619","0.00263"
"14915","89.45400","7.45468","0.00270"
"14932","89.55600","7.46317","0.00311"
"14949","89.65800","7.47166","0.00295"
"14966","89.76000","7.48015","0.00281"
"14983","89.86200","7.48876","0.00267"
"15000","89.96400","7.49719","0.00287"
"15017","90.06600","7.50568","0.00297"
"15034","90.16800","7.51423","0.00292"
"15051","90.27000","7.52272","0.00309"
"15068","90.37200","7.53121","0.00310"
"15085","90.47400","7.53970","0.00317"
"15102","90.57600","7.54819","0.00349"
"15119","90.67800","7.55668","0.00321"
"15136","90.78000","7.56517","0.00275"
"15153","90.88200","7.57372","0.00307"
"15170","90.98400","7.58221","0.00317"
"15187","91.08600","7.59064","0.00329"
"15204","91.18800","7.59913","0.00304"
"15221","91.29000","7.60768","0.00335"
"15238","91.39200","7.61623","0.00338"
"15255","91.49400","7.62472","0.00345"
"15272","91.59600","7.63321","0.00433"
"15289","91.69800","7.64170","0.00328"
"15306","91.80000","7.65019","0.00336"
"15323","91.90200","7.65868","0.00341"
"15340","92.00400","7.66723","0.00332"
"15357","92.10600","7.67572","0.00370"
"15374","92.20800","7.68409","0.00358"
"15391","92.31000","7.69270","0.00378"
"15408","92.41200","7.70125","0.00349"
"15425","92.51400","7.70968","0.00398"
"15442","92.61600","7.71817","0.00378"
"15459","92.71800","7.72666","0.00374"
"15476","92.82000","7.73515","0.00364"
"15493","92.92200","7.74370","0.00398"
"15510","93.02400","7.75219","0.00363"
"15527","93.12600","7.76080","0.00364"
"15544","93.22800","7.76917","0.00406"
"15561","93.33000","7.77760","0.00450"
"15578","93.43200","7.78621","0.00391"
"15595","93.53400","7.79476","0.00396"
"15612","93.63600","7.80325","0.00405"
"15629","93.73800","7.81168","0.00384"
"15646","93.84000","7.82011","0.00382"
"15663","93.94200","7.82866","0.00417"
"15680","94.04400","7.83727","0.00414"
"15697","94.14600","7.84570","0.00388"
"15714","94.24800","7.85419","0.00470"
"15731","94.35000","7.86268","0.00463"
"15748","94.45200","7.87117","0.00449"
"15765","94.55400","7.87972","0.00404"
"15782","94.65600","7.88821","0.00483"
"15799","94.75800","7.89670","0.00485"
"15816","94.86000","7.90519","0.00424"
"15833","94.96200","7.91362","0.00509"
"15850","95.06400","7.92217","0.00474"
"15867","95.16600","7.93072","0.00516"
"15884","95.26800","7.93927","0.00494"
"15901","95.37000","7.94764","0.00472"
"15918","95.47200","7.95613","0.00516"
"15935","95.57400","7.96474","0.00499"
"15952","95.67600","7.97317","0.00500"
"15969","95.77800","7.98172","0.00512"
"15986","95.88000","7.99021","0.00508"
"16003","95.98200","7.99870","0.00510"
"16020","96.08400","8.00719","0.00503"
"16037","96.18600","8.01574","0.00516"
"16054","96.28800","8.02423","0.00488"
"16071","96.39000","8.03272","0.00505"
"16088","96.49200","8.04121","0.00523"
"16105","96.59400","8.04970","0.00513"
"16122","96.69600","8.05819","0.00577"
"16139","96.79800","8.06668","0.00553"
"16156","96.90000","8.07523","0.00544"
"16173","97.00200","8.08366","0.00509"
"16190","97.10400","8.09209","0.00546"
"16207","97.20600","8.10070","0.00520"
"16224","97.30800","8.10919","0.00577"
"16241","97.41000","8.11768","0.00571"
"16258","97.51200","8.12617","0.00579"
"16275","97.61400","8.13466","0.00565"
"16292","97.71600","8.14316","0.00586"
"16309","97.81800","8.15170","0.00609"
"16326","97.92000","8.16020","0.00553"
"16343","98.02200","8.16868","0.00561"
"16360","98.12400","8.17718","0.00601"
"16377","98.22600","8.18561","0.00634"
"16394","98.32800","8.19422","0.00561"
"16411","98.43000","8.20277","0.00577"
"16428","98.53200","8.21119","0.00590"
"16445","98.63400","8.21969","0.00631"
"16462","98.73600","8.22818","0.00585"
"16479","98.83800","8.23667","0.00575"
"16496","98.94000","8.24522","0.00549"
"16513","99.04200","8.25371","0.00611"
"16530","99.14400","8.26220","0.00593"
"16547","99.24600","8.27063","0.00637"
"16564","99.34800","8.27912","0.00617"
"16581","99.45000","8.28773","0.00646"
"16598","99.55200","8.29622","0.00612"
"16615","99.65400","8.30465","0.00641"
"16632","99.75600","8.31320","0.00660"
"16649","99.85800","8.32169","0.00672"
"16666","99.96000","8.33012","0.00685"
"16683","100.06200","8.33873","0.00681"
"16700","100.16400","8.34722","0.00644"
"16717","100.26600","8.35565","0.00693"
"16734","100.36800","8.36414","0.00735"
"16751","100.47000","8.37275","0.00678"
"16768","100.57200","8.38118","0.00713"
"16785","100.67400","8.38973","0.00700"
"16802","100.77600","8.39822","0.00719"
"16819","100.87800","8.40671","0.00690"
"16836","100.98000","8.41520","0.00719"
"16853","101.08200","8.42369","0.00721"
"16870","101.18400","8.43224","0.00734"
"16887","101.28600","8.44067","0.00719"
"16904","101.38800","8.44916","0.00737"
"16921","101.49000","8.45771","0.00756"
"16938","101.59200","8.46620","0.00736"
"16955","101.69400","8.47475","0.00712"
"16972","101.79600","8.48324","0.00724"
"16989","101.89800","8.49161","0.00780"
"17006","102.00000","8.50016","0.00765"
"17023","102.10200","8.50871","0.00777"
"17040","102.20400","8.51720","0.00809"
"17057","102.30600","8.52575","0.00792"
"17074","102.40800","8.53418","0.00750"
"17091","102.51000","8.54261","0.00669"
"17108","102.61200","8.55122","0.00710"
"17125","102.71400","8.55971","0.00667"
"17142","102.81600","8.56820","0.00103"
"17159","102.91800","8.57669","0.00234"
"17176","103.02000","8.58518","0.00496"
"17193","103.12200","8.59367","0.00233"
"17210","103.22400","8.60222","0.00099"
"17227","103.32600","8.61071","0.00156"
"17244","103.42800","8.61914","0.00334"
"17261","103.53000","8.62763","0.00253"
"17278","103.63200","8.63618","0.00081"
"17295","103.73400","8.64473","0.00081"
"17312","103.83600","8.65322","0.00205"
"17329","103.93800","8.66171","0.00224"
"17346","104.04000","8.67020","0.00292"
"17363","104.14200","8.67863","0.00147"
"17380","104.24400","8.68724","0.00150"
"17397","104.34600","8.69573","0.00274"
"17414","104.44800","8.70422","0.00277"
"17431","104.55000","8.71265","0.00159"
"17448","104.65200","8.72114","0.00137"
"17465","104.75400","8.72969","0.00184"
"17482","104.85600","8.73818","0.00297"
"17499","104.95800","8.74673","0.00238"
"17516","105.06000","8.75522","0.00182"
"17533","105.16200","8.76365","0.00222"
"17550","105.26400","8.77220","0.00265"
"17567","105.36600","8.78069","0.00265"
"17584","105.46800","8.78924","0.00208"
"17601","105.57000","8.79767","0.00179"
"17618","105.67200","8.80616","0.00204"
"17635","105.77400","8.81471","0.00286"
"17652","105.87600","8.82320","0.00290"
"17669","105.97800","8.83169","0.00215"
"17686","106.08000","8.84018","0.00233"
"17703","106.18200","8.84873","0.00302"
"17720","106.28400","8.85710","0.00318"
"17737","106.38600","8.86571","0.00231"
"17754","106.48800","8.87420","0.00203"
"17771","106.59000","8.88269","0.00289"
"17788","106.69200","8.89124","0.00318"
"17805","106.79400","8.89967","0.00305"
"17822","106.89600","8.90822","0.00288"
"17839","106.99800","8.91671","0.00246"
"17856","107.10000","8.92520","0.00335"
"17873","107.20200","8.93375","0.00282"
"17890","107.30400","8.94218","0.00285"
"17907","107.40600","8.95067","0.00267"
"17924","107.50800","8.95928","0.00295"
"17941","107.61000","8.96771","0.00320"
"17958","107.71200","8.97614","0.00330"
"17975","107.81400","8.98463","0.00314"
"17992","107.91600","8.99318","0.00348"
"18009","108.01800","9.00167","0.00395"
"18026","108.12000","9.01016","0.00360"
"18043","108.22200","9.01871","0.00318"
"18060","108.32400","9.02720","0.00312"
"18077","108.42600","9.03563","0.00404"
"18094","108.52800","9.04418","0.00376"
"18111","108.63000","9.05279","0.00257"
"18128","108.73200","9.06122","0.00352"
"18145","108.83400","9.06959","0.00361"
"18162","108.93600","9.07814","0.00378"
"18179","109.03800","9.08675","0.00360"
"18196","109.14000","9.09524","0.00330"
"18213","109.24200","9.10373","0.00387"
"18230","109.34400","9.11222","0.00385"
"18247","109.44600","9.12065","0.00354"
"18264","109.54800","9.12920","0.00315"
"18281","109.65000","9.13775","0.00444"
"18298","109.75200","9.14618","0.00392"
"18315","109.85400","9.15467","0.00364"
"18332","109.95600","9.16316","0.00341"
"18349","110.05800","9.17171","0.00415"
"18366","110.16000","9.18021","0.00469"
"18383","110.26200","9.18869","0.00409"
"18400","110.36400","9.19724","0.00383"
"18417","110.46600","9.20568","0.00408"
"18434","110.56800","9.21416","0.00440"
"18451","110.67000","9.22272","0.00438"
"18468","110.77200","9.23127","0.00431"
"18485","110.87400","9.23969","0.00429"
"18502","110.97600","9.24819","0.00445"
"18519","111.07800","9.25667","0.00439"
"18536","111.18000","9.26517","0.00425"
"18553","111.28200","9.27372","0.00390"
"18570","111.38400","9.28221","0.00436"
"18587","111.48600","9.29070","0.00504"
"18604","111.58800","9.29913","0.00440"
"18621","111.69000","9.30774","0.00460"
"18638","111.79200","9.31629","0.00479"
"18655","111.89400","9.32472","0.00512"
"18672","111.99600","9.33321","0.00476"
"18689","112.09800","9.34164","0.00456"
"18706","112.20000","9.35019","0.00458"
"18723","112.30200","9.35868","0.00535"
"18740","112.40400","9.36723","0.00520"
"18757","112.50600","9.37578","0.00526"
"18774","112.60800","9.38415","0.00534"
"18791","112.71000","9.39264","0.00571"
"18808","112.81200","9.40119","0.00526"
"18825","112.91400","9.40974","0.00519"
"18842","113.01600","9.41823","0.00540"
"18859","113.11800","9.42672","0.00542"
"18876","113.22000","9.43515","0.00560"
"18893","113.32200","9.44370","0.00536"
"18910","113.42400","9.45225","0.00575"
"18927","113.52600","9.46074","0.00586"
"18944","113.62800","9.46923","0.00540"
"18961","113.73000","9.47766","0.00530"
"18978","113.83200","9.48615","0.00559"
"18995","113.93400","9.49470","0.00576"
"19012","114.03600","9.50319","0.00593"
"19029","114.13800","9.51168","0.00616"
"19046","114.24000","9.52017","0.00560"
"19063","114.34200","9.52866","0.00569"
"19080","114.44400","9.53721","0.00612"
"19097","114.54600","9.54570","0.00620"
"19114","114.64800","9.55419","0.00560"
"19131","114.75000","9.56274","0.00582"
"19148","114.85200","9.57117","0.00558"
"19165","114.95400","9.57966","0.00582"
"19182","115.05600","9.58821","0.00648"
"19199","115.15800","9.59670","0.00561"
"19216","115.26000","9.60519","0.00622"
"19233","115.36200","9.61368","0.00653"
"19250","115.46400","9.62217","0.00615"
"19267","115.56600","9.63078","0.00630"
"19284","115.66800","9.63921","0.00693"
"19301","115.77000","9.64770","0.00661"
"19318","115.87200","9.65619","0.00619"
"19335","115.97400","9.66468","0.00658"
"19352","116.07600","9.67323","0.00630"
"19369","116.17800","9.68166","0.00644"
"19386","116.28000","9.69015","0.00641"
"19403","116.38200","9.69870","0.00700"
"19420","116.48400","9.70713","0.00688"
"19437","116.58600","9.71568","0.00694"
"19454","116.68800","9.72423","0.00724"
"19471","116.79000","9.73272","0.00697"
"19488","116.89200","9.74115","0.00709"
"19505","116.99400","9.74964","0.00704"
"19522","117.09600","9.75819","0.00776"
"19539","117.19800","9.76668","0.00750"
"19556","117.30000","9.77523","0.00733"
"19573","117.40200","9.78372","0.00732"
"19590","117.50400","9.79215","0.00744"
"19607","117.60600","9.80064","0.00776"
"19624","117.70800","9.80925","0.00782"
"19641","117.81000","9.81774","0.00755"
"19658","117.91200","9.82623","0.00719"
"19675","118.01400","9.83466","0.00764"
"19692","118.11600","9.84315","0.00789"
"19709","118.21800","9.85170","0.00794"
"19726","118.32000","9.86019","0.00790"
"19743","118.42200","9.86868","0.00827"
"19760","118.52400","9.87717","0.00841"
"19777","118.62600","9.88560","0.00804"
"19794","118.72800","9.89421","0.00827"
"19811","118.83000","9.90270","0.00814"
"19828","118.93200","9.91125","0.00832"
"19845","119.03400","9.91968","0.00824"
"19862","119.13600","9.92817","0.00863"
"19879","119.23800","9.93672","0.00864"
"19896","119.34000","9.94521","0.00828"
"19913","119.44200","9.95370","0.00879"
"19930","119.54400","9.96225","0.00861"
"19947","119.64600","9.97068","0.00854"
"19964","119.74800","9.97917","0.00874"
"19981","119.85000","9.98772","0.00886"
"19998","119.95200","9.99627","0.00868"
"20015","120.05400","10.00470","0.00885"
"20032","120.15600","10.01319","0.00900"
"20049","120.25800","10.02168","0.00908"
"20066","120.36000","10.03017","0.00905"
"20083","120.46200","10.03866","0.00976"
"20100","120.56400","10.04721","0.00939"
"20117","120.66600","10.05570","0.00946"
"20134","120.76800","10.06413","0.00949"
"20151","120.87000","10.07268","0.00938"
"20168","120.97200","10.08123","0.00978"
"20185","121.07400","10.08972","0.00992"
"20202","121.17600","10.09821","0.00972"
"20219","121.27800","10.10664","0.01002"
"20236","121.38000","10.11519","0.01013"
"20253","121.48200","10.12368","0.01042"
"20270","121.58400","10.13223","0.01032"
"20287","121.68600","10.14072","0.01016"
"20304","121.78800","10.14915","0.01011"
"20321","121.89000","10.15764","0.01065"
"20338","121.99200","10.16613","0.01066"
"20355","122.09400","10.17468","0.01062"
"20372","122.19600","10.18323","0.01090"
"20389","122.29800","10.19166","0.01051"
"20406","122.40000","10.20015","0.01087"
"20423","122.50200","10.20870","0.01107"
"20440","122.60400","10.21719","0.01133"
"20457","122.70600","10.22568","0.01133"
"20474","122.80800","10.23417","0.01124"
"20491","122.91000","10.24260","0.01138"
"20508","123.01200","10.25115","0.01147"
"20525","123.11400","10.25970","0.01181"
"20542","123.21600","10.26814","0.01173"
"20559","123.31800","10.27668","0.01202"
"20576","123.42000","10.28517","0.01218"
"20593","123.52200","10.29366","0.01221"
"20610","123.62400","10.30221","0.01257"
"20627","123.72600","10.31071","0.01250"
"20644","123.82800","10.31919","0.01274"
"20661","123.93000","10.32769","0.01256"
"20678","124.03200","10.33618","0.01285"
"20695","124.13400","10.34472","0.01294"
"20712","124.23600","10.35322","0.01338"
"20729","124.33800","10.36170","0.01337"
"20746","124.44000","10.37020","0.01337"
"20763","124.54200","10.37869","0.01349"
"20780","124.64400","10.38718","0.01359"
"20797","124.74600","10.39573","0.01372"
"20814","124.84800","10.40421","0.01378"
"20831","124.95000","10.41265","0.01424"
"20848","125.05200","10.42114","0.01452"
"20865","125.15400","10.42969","0.01408"
"20882","125.25600","10.43824","0.01444"
"20899","125.35800","10.44667","0.01437"
"20916","125.46000","10.45516","0.01351"
"20933","125.56200","10.46365","0.01188"
"20950","125.66400","10.47214","0.00879"
"20967","125.76600","10.48069","0.00221"
"20984","125.86800","10.48918","-0.00078"
"21001","125.97000","10.49773","-0.00104"
"21018","126.07200","10.50616","-0.00087"
"21035","126.17400","10.51465","-0.00020"
"21052","126.27600","10.52326","-0.00068"
"21069","126.37800","10.53175","-0.00033"
"21086","126.48000","10.54024","-0.00128"
"21103","126.58200","10.54873","-0.00143"
"21120","126.68400","10.55716","-0.00117"
"21137","126.78600","10.56571","-0.00152"
"21154","126.88800","10.57426","-0.00129"
"21171","126.99000","10.58275","-0.00158"
"21188","127.09200","10.59118","-0.00142"
"21205","127.19400","10.59967","-0.00131"
"21222","127.29600","10.60822","-0.00102"
"21239","127.39800","10.61671","-0.00081"
"21256","127.50000","10.62520","-0.00048"
"21273","127.60200","10.63375","-0.00045"
"21290","127.70400","10.64218","-0.00030"
"21307","127.80600","10.65061","-0.00068"
"21324","127.90800","10.65922","-0.00107"
"21341","128.01000","10.66777","-0.00166"
"21358","128.11200","10.67620","-0.00101"
"21375","128.21400","10.68469","-0.00188"
"21392","128.31600","10.69312","-0.00153"
"21409","128.41800","10.70173","-0.00129"
"21426","128.52000","10.71022","-0.00160"
"21443","128.62200","10.71871","-0.00146"
"21460","128.72400","10.72726","-0.00093"
"21477","128.82600","10.73569","-0.00117"
"21494","128.92800","10.74418","-0.00122"
"21511","129.03000","10.75273","-0.00076"
"21528","129.13200","10.76122","-0.00105"
"21545","129.23400","10.76965","-0.00096"
"21562","129.33600","10.77814","-0.00135"
"21579","129.43800","10.78669","-0.00124"
"21596","129.54000","10.79518","-0.00131"
"21613","129.64200","10.80373","-0.00123"
"21630","129.74400","10.81222","-0.00187"
"21647","129.84600","10.82071","-0.00173"
"21664","129.94800","10.82914","-0.00187"
"21681","130.05000","10.83769","-0.00134"
"21698","130.15200","10.84618","-0.00104"
"21715","130.25400","10.85473","-0.00023"
"21732","130.35600","10.86322","-0.00050"
"21749","130.45800","10.87165","-0.00125"
"21756","130.49800","10.87500","-0.00101"