File: Trajectories_together/161226_2Specimen_RawData_1.csv
"","V1","V2","V3"
"1","End date","12/26/2016",""
"2","Specimen label","11BG_84",""
"3","Maximum Load","0.83001","N"
"4","Time","Extension","Load"
"5","(s)","(mm)","(N)"
"6","0.00000","0.00000","-0.00046"
"65","0.35400","0.02960","0.00173"
"124","0.70800","0.05919","0.00431"
"183","1.06200","0.08873","0.00455"
"242","1.41600","0.11826","0.00567"
"301","1.77000","0.14774","0.00587"
"360","2.12400","0.17728","0.00655"
"419","2.47800","0.20669","0.00706"
"478","2.83200","0.23617","0.00767"
"537","3.18600","0.26570","0.00796"
"596","3.54000","0.29518","0.00750"
"655","3.89400","0.32472","0.00798"
"714","4.24800","0.35425","0.00870"
"773","4.60200","0.38373","0.00940"
"832","4.95600","0.41321","0.00930"
"891","5.31000","0.44274","0.00931"
"950","5.66400","0.47216","0.01016"
"1009","6.01800","0.50169","0.01005"
"1068","6.37200","0.53123","0.01037"
"1127","6.72600","0.56071","0.01014"
"1186","7.08000","0.59024","0.00996"
"1245","7.43400","0.61978","0.01043"
"1304","7.78800","0.64919","0.01129"
"1363","8.14200","0.67873","0.01100"
"1422","8.49600","0.70821","0.01161"
"1481","8.85000","0.73768","0.01172"
"1540","9.20400","0.76722","0.01127"
"1599","9.55800","0.79676","0.01161"
"1658","9.91200","0.82623","0.01142"
"1717","10.26600","0.85571","0.01205"
"1776","10.62000","0.88524","0.01252"
"1835","10.97400","0.91472","0.01185"
"1894","11.32800","0.94420","0.01288"
"1953","11.68200","0.97373","0.01296"
"2012","12.03600","1.00321","0.01309"
"2071","12.39000","1.03274","0.01259"
"2130","12.74400","1.06222","0.01311"
"2189","13.09800","1.09170","0.01325"
"2248","13.45200","1.12123","0.01311"
"2307","13.80600","1.15071","0.01354"
"2366","14.16000","1.18019","0.01319"
"2425","14.51400","1.20978","0.01359"
"2484","14.86800","1.23920","0.01412"
"2543","15.22200","1.26873","0.01386"
"2602","15.57600","1.29821","0.01414"
"2661","15.93000","1.32769","0.01409"
"2720","16.28400","1.35716","0.01400"
"2779","16.63800","1.38676","0.01434"
"2838","16.99200","1.41623","0.01453"
"2897","17.34600","1.44571","0.01489"
"2956","17.70000","1.47525","0.01462"
"3015","18.05400","1.50472","0.01501"
"3074","18.40800","1.53420","0.01491"
"3133","18.76200","1.56374","0.01538"
"3192","19.11600","1.59321","0.01535"
"3251","19.47000","1.62275","0.01535"
"3310","19.82400","1.65222","0.01566"
"3369","20.17800","1.68164","0.01534"
"3428","20.53200","1.71124","0.01566"
"3487","20.88600","1.74077","0.01562"
"3546","21.24000","1.77019","0.01603"
"3605","21.59400","1.79972","0.01583"
"3664","21.94800","1.82926","0.01565"
"3723","22.30200","1.85868","0.01636"
"3782","22.65600","1.88827","0.01620"
"3841","23.01000","1.91775","0.01632"
"3900","23.36400","1.94723","0.01648"
"3959","23.71800","1.97670","0.01684"
"4018","24.07200","2.00618","0.01620"
"4077","24.42600","2.03565","0.01677"
"4136","24.78000","2.06525","0.01683"
"4195","25.13400","2.09473","0.01694"
"4254","25.48800","2.12420","0.01710"
"4313","25.84200","2.15374","0.01724"
"4372","26.19600","2.18321","0.01786"
"4431","26.55000","2.21269","0.01733"
"4490","26.90400","2.24223","0.01700"
"4549","27.25800","2.27176","0.01740"
"4608","27.61200","2.30118","0.01743"
"4667","27.96600","2.33078","0.01789"
"4726","28.32000","2.36025","0.01767"
"4785","28.67400","2.38973","0.01782"
"4844","29.02800","2.41926","0.01808"
"4903","29.38200","2.44874","0.01814"
"4962","29.73600","2.47822","0.01754"
"5021","30.09000","2.50775","0.01787"
"5080","30.44400","2.53723","0.01788"
"5139","30.79800","2.56670","0.01836"
"5198","31.15200","2.59624","0.01823"
"5257","31.50600","2.62566","0.01812"
"5316","31.86000","2.65525","0.01864"
"5375","32.21400","2.68473","0.01825"
"5434","32.56800","2.71421","0.01814"
"5493","32.92200","2.74368","0.01852"
"5552","33.27600","2.77328","0.01835"
"5611","33.63000","2.80263","0.01804"
"5670","33.98400","2.83223","0.01826"
"5729","34.33800","2.86177","0.01829"
"5788","34.69200","2.89118","0.01834"
"5847","35.04600","2.92072","0.01899"
"5906","35.40000","2.95025","0.01885"
"5965","35.75400","2.97967","0.01899"
"6024","36.10800","3.00921","0.01902"
"6083","36.46200","3.03874","0.01914"
"6142","36.81600","3.06816","0.01943"
"6201","37.17000","3.09776","0.01946"
"6260","37.52400","3.12723","0.01965"
"6319","37.87800","3.15671","0.01983"
"6378","38.23200","3.18624","0.01970"
"6437","38.58600","3.21578","0.01964"
"6496","38.94000","3.24520","0.01966"
"6555","39.29400","3.27473","0.01957"
"6614","39.64800","3.30415","0.01992"
"6673","40.00200","3.33374","0.02000"
"6732","40.35600","3.36328","0.01876"
"6791","40.71000","3.39270","0.01842"
"6850","41.06400","3.42217","0.01838"
"6909","41.41800","3.45171","0.01814"
"6968","41.77200","3.48119","0.01806"
"7027","42.12600","3.51072","0.01834"
"7086","42.48000","3.54026","0.01839"
"7145","42.83400","3.56973","0.01868"
"7204","43.18800","3.59921","0.01887"
"7263","43.54200","3.62869","0.01914"
"7322","43.89600","3.65828","0.01949"
"7381","44.25000","3.68770","0.01899"
"7440","44.60400","3.71723","0.01921"
"7499","44.95800","3.74671","0.01967"
"7558","45.31200","3.77625","0.01924"
"7617","45.66600","3.80578","0.01966"
"7676","46.02000","3.83514","0.01953"
"7735","46.37400","3.86474","0.01940"
"7794","46.72800","3.89427","0.01971"
"7853","47.08200","3.92369","0.01984"
"7912","47.43600","3.95322","0.02029"
"7971","47.79000","3.98276","0.02003"
"8030","48.14400","4.01212","0.02043"
"8089","48.49800","4.04177","0.02058"
"8148","48.85200","4.07119","0.02096"
"8207","49.20600","4.10067","0.02095"
"8266","49.56000","4.13026","0.02097"
"8325","49.91400","4.15974","0.02127"
"8384","50.26800","4.18921","0.02184"
"8443","50.62200","4.21875","0.02218"
"8502","50.97600","4.24823","0.02182"
"8561","51.33000","4.27770","0.02217"
"8620","51.68400","4.30730","0.02171"
"8679","52.03800","4.33671","0.02203"
"8738","52.39200","4.36619","0.02180"
"8797","52.74600","4.39573","0.02238"
"8856","53.10000","4.42520","0.02232"
"8915","53.45400","4.45468","0.02168"
"8974","53.80800","4.48427","0.02193"
"9033","54.16200","4.51369","0.02204"
"9092","54.51600","4.54317","0.02228"
"9151","54.87000","4.57276","0.02248"
"9210","55.22400","4.60224","0.02306"
"9269","55.57800","4.63172","0.02319"
"9328","55.93200","4.66125","0.02325"
"9387","56.28600","4.69067","0.02361"
"9446","56.64000","4.72020","0.02392"
"9505","56.99400","4.74968","0.02368"
"9564","57.34800","4.77922","0.02429"
"9623","57.70200","4.80869","0.02432"
"9682","58.05600","4.83823","0.02409"
"9741","58.41000","4.86770","0.02465"
"9800","58.76400","4.89718","0.02428"
"9859","59.11800","4.92672","0.02482"
"9918","59.47200","4.95613","0.02417"
"9977","59.82600","4.98579","0.02407"
"10036","60.18000","5.01521","0.02441"
"10095","60.53400","5.04474","0.02464"
"10154","60.88800","5.07422","0.02506"
"10213","61.24200","5.10375","0.02590"
"10272","61.59600","5.13317","0.02614"
"10331","61.95000","5.16277","0.02531"
"10390","62.30400","5.19224","0.02519"
"10449","62.65800","5.22166","0.02546"
"10508","63.01200","5.25126","0.02605"
"10567","63.36600","5.28073","0.02588"
"10626","63.72000","5.31015","0.02627"
"10685","64.07400","5.33968","0.02624"
"10744","64.42800","5.36928","0.02689"
"10803","64.78200","5.39870","0.02751"
"10862","65.13600","5.42829","0.02738"
"10921","65.49000","5.45771","0.02749"
"10980","65.84400","5.48718","0.02816"
"11039","66.19800","5.51678","0.02800"
"11098","66.55200","5.54620","0.02825"
"11157","66.90600","5.57573","0.02844"
"11216","67.26000","5.60527","0.02848"
"11275","67.61400","5.63469","0.02942"
"11334","67.96800","5.66422","0.02929"
"11393","68.32200","5.69370","0.02987"
"11452","68.67600","5.72317","0.03018"
"11511","69.03000","5.75271","0.03055"
"11570","69.38400","5.78219","0.03087"
"11629","69.73800","5.81166","0.03095"
"11688","70.09200","5.84120","0.03157"
"11747","70.44600","5.87073","0.03180"
"11806","70.80000","5.90021","0.03260"
"11865","71.15400","5.92975","0.03235"
"11924","71.50800","5.95922","0.03280"
"11983","71.86200","5.98870","0.03301"
"12042","72.21600","6.01823","0.03337"
"12101","72.57000","6.04777","0.03386"
"12160","72.92400","6.07719","0.03429"
"12219","73.27800","6.10672","0.03448"
"12278","73.63200","6.13626","0.03509"
"12337","73.98600","6.16568","0.03486"
"12396","74.34000","6.19527","0.03565"
"12455","74.69400","6.22475","0.03663"
"12514","75.04800","6.25422","0.03642"
"12573","75.40200","6.28376","0.03692"
"12632","75.75600","6.31324","0.03628"
"12691","76.11000","6.34265","0.03708"
"12750","76.46400","6.37225","0.03749"
"12809","76.81800","6.40173","0.03738"
"12868","77.17200","6.43120","0.03792"
"12927","77.52600","6.46074","0.03886"
"12986","77.88000","6.49021","0.03918"
"13045","78.23400","6.51969","0.04024"
"13104","78.58800","6.54923","0.04030"
"13163","78.94200","6.57870","0.04087"
"13222","79.29600","6.60818","0.04093"
"13281","79.65000","6.63771","0.04171"
"13340","80.00400","6.66719","0.04163"
"13399","80.35800","6.69673","0.04254"
"13458","80.71200","6.72626","0.04294"
"13517","81.06600","6.75574","0.04298"
"13576","81.42000","6.78522","0.04413"
"13635","81.77400","6.81475","0.04459"
"13694","82.12800","6.84423","0.04544"
"13753","82.48200","6.87370","0.04540"
"13812","82.83600","6.90324","0.04609"
"13871","83.19000","6.93272","0.04536"
"13930","83.54400","6.96225","0.04521"
"13989","83.89800","6.99173","0.04673"
"14048","84.25200","7.02120","0.04801"
"14107","84.60600","7.05068","0.04804"
"14166","84.96000","7.08022","0.04759"
"14225","85.31400","7.10969","0.04818"
"14284","85.66800","7.13923","0.04909"
"14343","86.02200","7.16876","0.04978"
"14402","86.37600","7.19824","0.05014"
"14461","86.73000","7.22766","0.05099"
"14520","87.08400","7.25725","0.05122"
"14579","87.43800","7.28667","0.05237"
"14638","87.79200","7.31627","0.05231"
"14697","88.14600","7.34574","0.05287"
"14756","88.50000","7.37516","0.05373"
"14815","88.85400","7.40475","0.05401"
"14874","89.20800","7.43423","0.05470"
"14933","89.56200","7.46365","0.05461"
"14992","89.91600","7.49324","0.05550"
"15051","90.27000","7.52278","0.05601"
"15110","90.62400","7.55220","0.05579"
"15169","90.97800","7.58173","0.05658"
"15228","91.33200","7.61127","0.05747"
"15287","91.68600","7.64074","0.05809"
"15346","92.04000","7.67022","0.05861"
"15405","92.39400","7.69970","0.05827"
"15464","92.74800","7.72911","0.05920"
"15523","93.10200","7.75877","0.05986"
"15582","93.45600","7.78824","0.05965"
"15641","93.81000","7.81772","0.06019"
"15700","94.16400","7.84720","0.06055"
"15759","94.51800","7.87673","0.06111"
"15818","94.87200","7.90621","0.06179"
"15877","95.22600","7.93569","0.06194"
"15936","95.58000","7.96522","0.06246"
"15995","95.93400","7.99470","0.06296"
"16054","96.28800","8.02423","0.06269"
"16113","96.64200","8.05371","0.06368"
"16172","96.99600","8.08325","0.06385"
"16231","97.35000","8.11272","0.06422"
"16290","97.70400","8.14226","0.06502"
"16349","98.05800","8.17173","0.06536"
"16408","98.41200","8.20121","0.06564"
"16467","98.76600","8.23069","0.06636"
"16526","99.12000","8.26022","0.06787"
"16585","99.47400","8.28976","0.06820"
"16644","99.82800","8.31917","0.06913"
"16703","100.18200","8.34871","0.06922"
"16762","100.53600","8.37825","0.07014"
"16821","100.89000","8.40772","0.07050"
"16880","101.24400","8.43726","0.07181"
"16939","101.59800","8.46680","0.07187"
"16998","101.95200","8.49615","0.07234"
"17057","102.30600","8.52575","0.07257"
"17116","102.66000","8.55522","0.07335"
"17175","103.01400","8.58470","0.07418"
"17234","103.36800","8.61424","0.07524"
"17293","103.72200","8.64377","0.07629"
"17352","104.07600","8.67319","0.07671"
"17411","104.43000","8.70278","0.07733"
"17470","104.78400","8.73220","0.07882"
"17529","105.13800","8.76168","0.07868"
"17588","105.49200","8.79121","0.08009"
"17647","105.84600","8.82075","0.08116"
"17706","106.20000","8.85017","0.08248"
"17765","106.55400","8.87976","0.08333"
"17824","106.90800","8.90924","0.08366"
"17883","107.26200","8.93871","0.08495"
"17942","107.61600","8.96825","0.08615"
"18001","107.97000","8.99767","0.08614"
"18060","108.32400","9.02720","0.08802"
"18119","108.67800","9.05674","0.08897"
"18178","109.03200","9.08622","0.08949"
"18237","109.38600","9.11569","0.09049"
"18296","109.74000","9.14523","0.09135"
"18355","110.09400","9.17470","0.09209"
"18414","110.44800","9.20418","0.09366"
"18473","110.80200","9.23378","0.09399"
"18532","111.15600","9.26313","0.09466"
"18591","111.51000","9.29273","0.09608"
"18650","111.86400","9.32226","0.09690"
"18709","112.21800","9.35168","0.09749"
"18768","112.57200","9.38116","0.09849"
"18827","112.92600","9.41075","0.09916"
"18886","113.28000","9.44017","0.10004"
"18945","113.63400","9.46971","0.10107"
"19004","113.98800","9.49924","0.10173"
"19063","114.34200","9.52866","0.10248"
"19122","114.69600","9.55819","0.10308"
"19181","115.05000","9.58779","0.10368"
"19240","115.40400","9.61715","0.10393"
"19299","115.75800","9.64674","0.10462"
"19358","116.11200","9.67628","0.10518"
"19417","116.46600","9.70569","0.10556"
"19476","116.82000","9.73523","0.10594"
"19535","117.17400","9.76471","0.10659"
"19594","117.52800","9.79418","0.10699"
"19653","117.88200","9.82372","0.10723"
"19712","118.23600","9.85320","0.10807"
"19771","118.59000","9.88267","0.10804"
"19830","118.94400","9.91227","0.10828"
"19889","119.29800","9.94174","0.10880"
"19948","119.65200","9.97122","0.10916"
"20007","120.00600","10.00076","0.10956"
"20066","120.36000","10.03023","0.10997"
"20125","120.71400","10.05971","0.11050"
"20184","121.06800","10.08918","0.11086"
"20243","121.42200","10.11866","0.11199"
"20302","121.77600","10.14820","0.11226"
"20361","122.13000","10.17773","0.11309"
"20420","122.48400","10.20721","0.11350"
"20479","122.83800","10.23669","0.11440"
"20538","123.19200","10.26622","0.11589"
"20597","123.54600","10.29570","0.11677"
"20656","123.90000","10.32517","0.11882"
"20715","124.25400","10.35483","0.12017"
"20774","124.60800","10.38419","0.12160"
"20833","124.96200","10.41378","0.12312"
"20892","125.31600","10.44320","0.12451"
"20951","125.67000","10.47268","0.12648"
"21010","126.02400","10.50221","0.12804"
"21069","126.37800","10.53175","0.13035"
"21128","126.73200","10.56122","0.13171"
"21187","127.08600","10.59076","0.13293"
"21246","127.44000","10.62024","0.13589"
"21305","127.79400","10.64965","0.13878"
"21364","128.14800","10.67925","0.14195"
"21423","128.50200","10.70872","0.14389"
"21482","128.85600","10.73820","0.14656"
"21541","129.21000","10.76774","0.14920"
"21600","129.56400","10.79727","0.15098"
"21659","129.91800","10.82663","0.15318"
"21718","130.27200","10.85622","0.15525"
"21777","130.62600","10.88570","0.15758"
"21836","130.98000","10.91512","0.15918"
"21895","131.33400","10.94477","0.16137"
"21954","131.68800","10.97431","0.16256"
"22013","132.04200","11.00367","0.16432"
"22072","132.39600","11.03326","0.16053"
"22131","132.75000","11.06274","0.16231"
"22190","133.10400","11.09221","0.16366"
"22249","133.45800","11.12175","0.16616"
"22308","133.81200","11.15117","0.16763"
"22367","134.16600","11.18064","0.16840"
"22426","134.52000","11.21030","0.16962"
"22485","134.87400","11.23966","0.17117"
"22544","135.22800","11.26925","0.17271"
"22603","135.58200","11.29879","0.17354"
"22662","135.93600","11.32820","0.17489"
"22721","136.29000","11.35774","0.17604"
"22780","136.64400","11.38722","0.17676"
"22839","136.99800","11.41669","0.17866"
"22898","137.35200","11.44623","0.18001"
"22957","137.70600","11.47570","0.18138"
"23016","138.06000","11.50524","0.18273"
"23075","138.41400","11.53466","0.18374"
"23134","138.76800","11.56419","0.18575"
"23193","139.12200","11.59367","0.18794"
"23252","139.47600","11.62327","0.18945"
"23311","139.83000","11.65274","0.19218"
"23370","140.18400","11.68222","0.19338"
"23429","140.53800","11.71169","0.19519"
"23488","140.89200","11.74129","0.19723"
"23547","141.24600","11.77065","0.19895"
"23606","141.60000","11.80030","0.20113"
"23665","141.95400","11.82978","0.20330"
"23724","142.30800","11.85919","0.20568"
"23783","142.66200","11.88873","0.20779"
"23842","143.01600","11.91821","0.20896"
"23901","143.37000","11.94762","0.21073"
"23960","143.72400","11.97728","0.21091"
"24019","144.07800","12.00675","0.21149"
"24078","144.43200","12.03617","0.21315"
"24137","144.78600","12.06577","0.21414"
"24196","145.14000","12.09518","0.21414"
"24255","145.49400","12.12472","0.21563"
"24314","145.84800","12.15425","0.21704"
"24373","146.20200","12.18373","0.21846"
"24432","146.55600","12.21327","0.21936"
"24491","146.91000","12.24274","0.22127"
"24550","147.26400","12.27216","0.22222"
"24609","147.61800","12.30170","0.22480"
"24668","147.97200","12.33123","0.22367"
"24727","148.32600","12.36071","0.22513"
"24786","148.68000","12.39019","0.22740"
"24845","149.03400","12.41972","0.22830"
"24904","149.38800","12.44926","0.23032"
"24963","149.74200","12.47867","0.23217"
"25022","150.09600","12.50827","0.23409"
"25081","150.45000","12.53769","0.23671"
"25140","150.80400","12.56728","0.23866"
"25199","151.15800","12.59670","0.24163"
"25258","151.51200","12.62623","0.24343"
"25317","151.86600","12.65571","0.24611"
"25376","152.22000","12.68531","0.24889"
"25435","152.57400","12.71472","0.25114"
"25494","152.92800","12.74426","0.25347"
"25553","153.28200","12.77368","0.25514"
"25612","153.63600","12.80315","0.25755"
"25671","153.99000","12.83275","0.25916"
"25730","154.34400","12.86222","0.26172"
"25789","154.69800","12.89170","0.26309"
"25848","155.05200","12.92124","0.26502"
"25907","155.40600","12.95077","0.26697"
"25966","155.76000","12.98019","0.26872"
"26025","156.11400","13.00966","0.27105"
"26084","156.46800","13.03920","0.27458"
"26143","156.82200","13.06874","0.27814"
"26202","157.17600","13.09827","0.28065"
"26261","157.53000","13.12781","0.28387"
"26320","157.88400","13.15717","0.28892"
"26379","158.23800","13.18676","0.29327"
"26438","158.59200","13.21624","0.29725"
"26497","158.94600","13.24565","0.30144"
"26556","159.30000","13.27525","0.30463"
"26615","159.65400","13.30473","0.30848"
"26674","160.00800","13.33420","0.31163"
"26733","160.36200","13.36374","0.31471"
"26792","160.71600","13.39322","0.31637"
"26851","161.07000","13.42269","0.31765"
"26910","161.42400","13.45229","0.31984"
"26969","161.77800","13.48170","0.32123"
"27028","162.13200","13.51124","0.32216"
"27087","162.48600","13.54072","0.32309"
"27146","162.84000","13.57019","0.32327"
"27205","163.19400","13.59973","0.32384"
"27264","163.54800","13.62926","0.32429"
"27323","163.90200","13.65868","0.32489"
"27382","164.25600","13.68822","0.32534"
"27441","164.61000","13.71775","0.32653"
"27500","164.96400","13.74723","0.32812"
"27559","165.31800","13.77676","0.32982"
"27618","165.67200","13.80618","0.33156"
"27677","166.02600","13.83572","0.33377"
"27736","166.38000","13.86519","0.33615"
"27795","166.73400","13.89479","0.33938"
"27854","167.08800","13.92420","0.34357"
"27913","167.44200","13.95374","0.34821"
"27972","167.79600","13.98328","0.35337"
"28031","168.15000","14.01269","0.35671"
"28090","168.50400","14.04223","0.35928"
"28149","168.85800","14.07171","0.36347"
"28208","169.21200","14.10112","0.36612"
"28267","169.56600","14.13078","0.36935"
"28326","169.92000","14.16020","0.37123"
"28385","170.27400","14.18967","0.37309"
"28444","170.62800","14.21921","0.37609"
"28503","170.98200","14.24874","0.37900"
"28562","171.33600","14.27816","0.38184"
"28621","171.69000","14.30769","0.38503"
"28680","172.04400","14.33723","0.38773"
"28739","172.39800","14.36671","0.39133"
"28798","172.75200","14.39624","0.39515"
"28857","173.10600","14.42572","0.39905"
"28916","173.46000","14.45520","0.40132"
"28975","173.81400","14.48473","0.40434"
"29034","174.16800","14.51427","0.40682"
"29093","174.52200","14.54368","0.40929"
"29152","174.87600","14.57322","0.41193"
"29211","175.23000","14.60270","0.41365"
"29270","175.58400","14.63217","0.41593"
"29329","175.93800","14.66171","0.41795"
"29388","176.29200","14.69118","0.42086"
"29447","176.64600","14.72072","0.42336"
"29506","177.00000","14.75026","0.42643"
"29565","177.35400","14.77973","0.43013"
"29624","177.70800","14.80921","0.43334"
"29683","178.06200","14.83881","0.43737"
"29742","178.41600","14.86822","0.44029"
"29801","178.77000","14.89770","0.44106"
"29860","179.12400","14.92717","0.44474"
"29919","179.47800","14.95671","0.44841"
"29978","179.83200","14.98625","0.45249"
"30037","180.18600","15.01572","0.45487"
"30096","180.54000","15.04520","0.45767"
"30155","180.89400","15.07474","0.46107"
"30214","181.24800","15.10421","0.46456"
"30273","181.60200","15.13363","0.46405"
"30332","181.95600","15.16322","0.46514"
"30391","182.31000","15.19270","0.46771"
"30450","182.66400","15.22218","0.46994"
"30509","183.01800","15.25171","0.47154"
"30568","183.37200","15.28131","0.47369"
"30627","183.72600","15.31067","0.47521"
"30686","184.08000","15.34026","0.47906"
"30745","184.43400","15.36974","0.48283"
"30804","184.78800","15.39921","0.48807"
"30863","185.14200","15.42875","0.49307"
"30922","185.49600","15.45823","0.49648"
"30981","185.85000","15.48770","0.50182"
"31040","186.20400","15.51724","0.50842"
"31099","186.55800","15.54671","0.51264"
"31158","186.91200","15.57619","0.51780"
"31217","187.26600","15.60573","0.52261"
"31276","187.62000","15.63520","0.52531"
"31335","187.97400","15.66468","0.52733"
"31394","188.32800","15.69421","0.53015"
"31453","188.68200","15.72375","0.53215"
"31512","189.03600","15.75323","0.53413"
"31571","189.39000","15.78276","0.53677"
"31630","189.74400","15.81218","0.53898"
"31689","190.09800","15.84166","0.54161"
"31748","190.45200","15.87125","0.53702"
"31807","190.80600","15.90073","0.53896"
"31866","191.16000","15.93020","0.54214"
"31925","191.51400","15.95968","0.54524"
"31984","191.86800","15.98922","0.54925"
"32043","192.22200","16.01869","0.55411"
"32102","192.57600","16.04823","0.55981"
"32161","192.93000","16.07764","0.56566"
"32220","193.28400","16.10730","0.57053"
"32279","193.63800","16.13672","0.57624"
"32338","193.99200","16.16619","0.58065"
"32397","194.34600","16.19573","0.58419"
"32456","194.70000","16.22527","0.58949"
"32515","195.05400","16.25468","0.59395"
"32574","195.40800","16.28428","0.60051"
"32633","195.76200","16.31375","0.60605"
"32692","196.11600","16.34317","0.61144"
"32751","196.47000","16.37277","0.61469"
"32810","196.82400","16.40224","0.61828"
"32869","197.17800","16.43172","0.62104"
"32928","197.53200","16.46119","0.62369"
"32987","197.88600","16.49073","0.62587"
"33046","198.24000","16.52021","0.62782"
"33105","198.59400","16.54974","0.63103"
"33164","198.94800","16.57922","0.63439"
"33223","199.30200","16.60863","0.63852"
"33282","199.65600","16.63823","0.64332"
"33341","200.01000","16.66777","0.64885"
"33400","200.36400","16.69718","0.65620"
"33459","200.71800","16.72678","0.66105"
"33518","201.07200","16.75620","0.66844"
"33577","201.42600","16.78567","0.67463"
"33636","201.78000","16.81527","0.67940"
"33695","202.13400","16.84468","0.68354"
"33754","202.48800","16.87422","0.68761"
"33813","202.84200","16.90370","0.69283"
"33872","203.19600","16.93323","0.69851"
"33931","203.55000","16.96271","0.70480"
"33990","203.90400","16.99224","0.70063"
"34049","204.25800","17.02166","0.70394"
"34108","204.61200","17.05126","0.71208"
"34167","204.96600","17.08073","0.71869"
"34226","205.32000","17.11021","0.72456"
"34285","205.67400","17.13975","0.72754"
"34344","206.02800","17.16934","0.72801"
"34403","206.38200","17.19864","0.73035"
"34462","206.73600","17.22824","0.73304"
"34521","207.09000","17.25777","0.73337"
"34580","207.44400","17.28713","0.73283"
"34639","207.79800","17.31672","0.73529"
"34698","208.15200","17.34626","0.73888"
"34757","208.50600","17.37568","0.74284"
"34816","208.86000","17.40521","0.74466"
"34875","209.21400","17.43481","0.75110"
"34934","209.56800","17.46410","0.75888"
"34993","209.92200","17.49376","0.76723"
"35052","210.27600","17.52324","0.77399"
"35111","210.63000","17.55271","0.77925"
"35170","210.98400","17.58225","0.78543"
"35229","211.33800","17.61172","0.79207"
"35288","211.69200","17.64114","0.80196"
"35347","212.04600","17.67074","0.81176"
"35406","212.40000","17.70021","0.82065"
"35465","212.75400","17.72969","0.82728"
"35524","213.10800","17.75928","0.74079"
"35583","213.46200","17.78870","0.61030"
"35642","213.81600","17.81818","0.61251"
"35701","214.17000","17.84771","0.61253"
"35760","214.52400","17.87725","0.61529"
"35819","214.87800","17.90672","0.62030"
"35878","215.23200","17.93626","0.06014"
"35937","215.58600","17.96568","0.08461"
"35996","215.94000","17.99521","0.05224"
"36055","216.29400","18.02475","0.08390"
"36114","216.64800","18.05423","0.06567"
"36173","217.00200","18.08370","0.07894"
"36232","217.35600","18.11324","0.07219"
"36291","217.71000","18.14272","0.06777"
"36350","218.06400","18.17219","0.07672"
"36409","218.41800","18.20173","0.07143"
"36468","218.77200","18.23120","0.09115"
"36527","219.12600","18.26074","0.08767"
"36586","219.48000","18.29022","0.09994"
"36645","219.83400","18.31963","0.09404"
"36704","220.18800","18.34923","0.09495"
"36763","220.54200","18.37877","0.09918"
"36822","220.89600","18.40818","0.09534"
"36881","221.25000","18.43778","0.10234"
"36940","221.60400","18.46719","0.10066"
"36999","221.95800","18.49667","0.10696"
"37058","222.31200","18.52621","0.10651"
"37117","222.66600","18.55574","0.10734"
"37176","223.02000","18.58522","0.11046"
"37235","223.37400","18.61469","0.11003"
"37294","223.72800","18.64423","0.11327"
"37353","224.08200","18.67371","0.11678"
"37412","224.43600","18.70324","0.11515"
"37471","224.79000","18.73272","0.11813"
"37530","225.14400","18.76220","0.12132"
"37589","225.49800","18.79173","0.12090"
"37648","225.85200","18.82127","0.12641"
"37707","226.20600","18.85068","0.13464"
"37766","226.56000","18.88022","0.13571"
"37825","226.91400","18.90969","0.13592"
"37884","227.26800","18.93923","0.14199"
"37943","227.62200","18.96877","0.14758"
"38002","227.97600","18.99824","0.15021"
"38061","228.33000","19.02772","0.15557"
"38120","228.68400","19.05725","0.16281"
"38179","229.03800","19.08673","0.16758"
"38238","229.39200","19.11621","0.16862"
"38297","229.74600","19.14574","0.16935"
"38356","230.10000","19.17522","0.17020"
"38415","230.45400","19.20476","0.17261"
"38474","230.80800","19.23417","0.17544"
"38533","231.16200","19.26371","0.17663"
"38592","231.51600","19.29325","0.17976"
"38651","231.87000","19.32272","0.18183"
"38710","232.22400","19.35220","0.18808"
"38769","232.57800","19.38173","0.19358"
"38828","232.93200","19.41121","0.19915"
"38887","233.28600","19.44075","0.20391"
"38946","233.64000","19.47016","0.20673"
"39005","233.99400","19.49976","0.21020"
"39064","234.34800","19.52923","0.21210"
"39123","234.70200","19.55871","0.21361"
"39182","235.05600","19.58825","0.21545"
"39241","235.41000","19.61766","0.21745"
"39300","235.76400","19.64726","0.21934"
"39359","236.11800","19.67673","0.22144"
"39418","236.47200","19.70621","0.22319"
"39477","236.82600","19.73575","0.22598"
"39536","237.18000","19.76528","0.22880"
"39595","237.53400","19.79464","0.23221"
"39654","237.88800","19.82424","0.23515"
"39713","238.24200","19.85371","0.23845"
"39772","238.59600","19.88325","0.24179"
"39831","238.95000","19.91278","0.24569"
"39890","239.30400","19.94226","0.24962"
"39949","239.65800","19.97168","0.25291"
"40008","240.01200","20.00127","0.25598"
"40067","240.36600","20.03075","0.25935"
"40126","240.72000","20.06022","0.26185"
"40185","241.07400","20.08976","0.26553"
"40244","241.42800","20.11918","0.26833"
"40303","241.78200","20.14871","0.27236"
"40362","242.13600","20.17825","0.27644"
"40421","242.49000","20.20773","0.28128"
"40480","242.84400","20.23714","0.28643"
"40539","243.19800","20.26674","0.29372"
"40598","243.55200","20.29621","0.29956"
"40657","243.90600","20.32569","0.30601"
"40716","244.26000","20.35523","0.31100"
"40775","244.61400","20.38470","0.31589"
"40834","244.96800","20.41424","0.31972"
"40893","245.32200","20.44372","0.32198"
"40952","245.67600","20.47319","0.32354"
"41011","246.03000","20.50267","0.32423"
"41070","246.38400","20.53226","0.32494"
"41129","246.73800","20.56168","0.32598"
"41188","247.09200","20.59127","0.32778"
"41247","247.44600","20.62069","0.33039"
"41306","247.80000","20.65023","0.33418"
"41365","248.15400","20.67970","0.33977"
"41424","248.50800","20.70924","0.34555"
"41483","248.86200","20.73866","0.35154"
"41542","249.21600","20.76825","0.35615"
"41601","249.57000","20.79773","0.36217"
"41660","249.92400","20.82715","0.36790"
"41719","250.27800","20.85668","0.37343"
"41778","250.63200","20.88622","0.37839"
"41837","250.98600","20.91570","0.38250"
"41896","251.34000","20.94523","0.38553"
"41955","251.69400","20.97476","0.39012"
"42014","252.04800","21.00418","0.39641"
"42073","252.40200","21.03372","0.40155"
"42132","252.75600","21.06326","0.40475"
"42191","253.11000","21.09273","0.40709"
"42250","253.46400","21.12227","0.41122"
"42309","253.81800","21.15174","0.41518"
"42368","254.17200","21.18116","0.41956"
"42427","254.52600","21.21076","0.42208"
"42486","254.88000","21.24017","0.42552"
"42545","255.23400","21.26971","0.42927"
"42604","255.58800","21.29924","0.43332"
"42663","255.94200","21.32872","0.19513"
"42722","256.29600","21.35820","0.21185"
"42781","256.65000","21.38773","0.21379"
"42840","257.00400","21.41721","0.21605"
"42899","257.35800","21.44674","0.21852"
"42958","257.71200","21.47628","0.22114"
"43017","258.06600","21.50564","0.22386"
"43076","258.42000","21.53523","0.22752"
"43135","258.77400","21.56471","0.23038"
"43194","259.12800","21.59425","0.23470"
"43253","259.48200","21.62372","0.24038"
"43312","259.83600","21.65326","0.24453"
"43371","260.19000","21.68267","0.24890"
"43430","260.54400","21.71221","0.25319"
"43489","260.89800","21.74175","0.25737"
"43548","261.25200","21.77110","0.26143"
"43607","261.60600","21.80076","0.26517"
"43666","261.96000","21.83023","0.26942"
"43725","262.31400","21.85965","0.27477"
"43784","262.66800","21.88919","0.28092"
"43843","263.02200","21.91878","0.28799"
"43902","263.37600","21.94814","0.29418"
"43961","263.73000","21.97773","0.30002"
"44020","264.08400","22.00727","0.30425"
"44079","264.43800","22.03669","0.31057"
"44138","264.79200","22.06623","0.31368"
"44197","265.14600","22.09576","0.31799"
"44256","265.50000","22.12518","0.30164"
"44315","265.85400","22.15477","0.30894"
"44374","266.20800","22.18419","0.31495"
"44433","266.56200","22.21367","0.31926"
"44492","266.91600","22.24326","0.32185"
"44551","267.27000","22.27274","0.32295"
"44610","267.62400","22.30215","0.32408"
"44669","267.97800","22.33175","0.32526"
"44728","268.33200","22.36123","0.32696"
"44787","268.68600","22.39064","0.32996"
"44846","269.04000","22.42024","0.33442"
"44905","269.39400","22.44971","0.34078"
"44964","269.74800","22.47925","0.34771"
"45023","270.10200","22.50873","0.35396"
"45082","270.45600","22.53820","0.35885"
"45141","270.81000","22.56774","0.36336"
"45200","271.16400","22.59722","0.28385"
"45259","271.51800","22.62669","0.28545"
"45318","271.87200","22.65623","0.29298"
"45377","272.22600","22.68576","0.29741"
"45436","272.58000","22.71518","0.30602"
"45495","272.93400","22.74478","0.31267"
"45554","273.28800","22.77419","0.31346"
"45613","273.64200","22.80373","0.31734"
"45672","273.99600","22.83321","0.32173"
"45731","274.35000","22.86280","0.32272"
"45790","274.70400","22.89215","0.32383"
"45849","275.05800","22.92175","0.32527"
"45908","275.41200","22.95129","0.32632"
"45967","275.76600","22.98070","0.32853"
"46026","276.12000","23.01018","0.24133"
"46085","276.47400","23.03972","0.19879"
"46144","276.82800","23.06919","0.19956"
"46203","277.18200","23.09873","0.20566"
"46262","277.53600","23.12826","0.21055"
"46321","277.89000","23.15768","0.21406"
"46380","278.24400","23.18722","0.21813"
"46439","278.59800","23.21675","0.22053"
"46498","278.95200","23.24617","0.19845"
"46557","279.30600","23.27576","0.20301"
"46616","279.66000","23.30524","0.20522"
"46675","280.01400","23.33472","0.20993"
"46734","280.36800","23.36426","0.21354"
"46793","280.72200","23.39373","0.21618"
"46852","281.07600","23.42321","0.21817"
"46911","281.43000","23.45274","0.22052"
"46970","281.78400","23.48222","0.22406"
"47029","282.13800","23.51169","0.22879"
"47088","282.49200","23.54123","0.23314"
"47147","282.84600","23.57071","0.23635"
"47206","283.20000","23.60024","0.23258"
"47265","283.55400","23.62972","0.23675"
"47324","283.90800","23.65914","0.24136"
"47383","284.26200","23.68873","0.24809"
"47442","284.61600","23.71827","0.25332"
"47501","284.97000","23.74768","0.23600"
"47560","285.32400","23.77716","0.23875"
"47619","285.67800","23.80676","0.24290"
"47678","286.03200","23.83618","0.24818"
"47737","286.38600","23.86571","0.25402"
"47796","286.74000","23.89524","0.25803"
"47855","287.09400","23.92466","0.26250"
"47914","287.44800","23.95426","0.22721"
"47973","287.80200","23.98374","0.22513"
"48032","288.15600","24.01315","0.22738"
"48091","288.51000","24.04275","0.23200"
"48150","288.86400","24.07222","0.23614"
"48209","289.21800","24.10164","0.23955"
"48268","289.57200","24.13129","0.24292"
"48327","289.92600","24.16071","0.24746"
"48386","290.28000","24.19019","0.25125"
"48445","290.63400","24.21972","0.25419"
"48504","290.98800","24.24920","0.25800"
"48563","291.34200","24.27868","0.26088"
"48622","291.69600","24.30827","0.26459"
"48681","292.05000","24.33775","0.26893"
"48740","292.40400","24.36716","0.27408"
"48799","292.75800","24.39676","0.27918"
"48858","293.11200","24.42624","0.28517"
"48917","293.46600","24.45571","0.29093"
"48976","293.82000","24.48525","0.29752"
"49035","294.17400","24.51472","0.30329"
"49094","294.52800","24.54414","0.30849"
"49153","294.88200","24.57374","0.31271"
"49212","295.23600","24.60321","0.31625"
"49271","295.59000","24.63269","0.32110"
"49330","295.94400","24.66222","0.32321"
"49389","296.29800","24.69170","0.32393"
"49448","296.65200","24.72118","0.32451"
"49507","297.00600","24.75077","0.32504"
"49566","297.36000","24.78019","0.32649"
"49625","297.71400","24.80972","0.32737"
"49684","298.06800","24.83926","0.32953"
"49743","298.42200","24.86868","0.33336"
"49802","298.77600","24.89822","0.33863"
"49861","299.13000","24.92769","0.34534"
"49920","299.48400","24.95723","0.35131"
"49979","299.83800","24.98670","0.35881"
"50038","300.19200","25.01618","0.36416"
"50097","300.54600","25.04572","0.36987"
"50156","300.90000","25.07525","0.37386"
"50215","301.25400","25.10473","0.37796"
"50274","301.60800","25.13420","0.38248"
"50333","301.96200","25.16368","0.38573"
"50392","302.31600","25.19328","0.38959"
"50451","302.67000","25.22269","0.39179"
"50510","303.02400","25.25223","0.29144"
"50569","303.37800","25.28177","0.29153"
"50628","303.73200","25.31118","0.28831"
"50687","304.08600","25.34072","0.29242"
"50746","304.44000","25.37025","0.29506"
"50805","304.79400","25.39967","0.29442"
"50864","305.14800","25.42927","0.30006"
"50923","305.50200","25.45874","0.30087"
"50982","305.85600","25.48822","0.30374"
"51041","306.21000","25.51775","0.30685"
"51100","306.56400","25.54723","0.30829"
"51159","306.91800","25.57671","0.31134"
"51218","307.27200","25.60624","0.31208"
"51277","307.62600","25.63572","0.31398"
"51336","307.98000","25.66519","0.31520"
"51395","308.33400","25.69473","0.31743"
"51454","308.68800","25.72421","0.31904"
"51513","309.04200","25.75368","0.32030"
"51572","309.39600","25.78322","0.32113"
"51631","309.75000","25.81269","0.32256"
"51690","310.10400","25.84223","0.32341"
"51749","310.45800","25.87171","0.32374"
"51808","310.81200","25.90125","0.32395"
"51867","311.16600","25.93066","0.32436"
"51926","311.52000","25.96025","0.32500"
"51985","311.87400","25.98967","0.32547"
"52044","312.22800","26.01927","0.32638"
"52103","312.58200","26.04869","0.32749"
"52162","312.93600","26.07816","0.32896"
"52221","313.29000","26.10776","0.32976"
"52280","313.64400","26.13723","0.33022"
"52339","313.99800","26.16665","0.32853"
"52398","314.35200","26.19625","0.32974"
"52457","314.70600","26.22578","0.33042"
"52516","315.06000","26.25514","0.33155"
"52575","315.41400","26.28473","0.33292"
"52634","315.76800","26.31421","0.33379"
"52693","316.12200","26.34375","0.33507"
"52752","316.47600","26.37322","0.33620"
"52811","316.83000","26.40270","0.33758"
"52870","317.18400","26.43217","0.33815"
"52929","317.53800","26.46171","0.33997"
"52988","317.89200","26.49125","0.34077"
"53047","318.24600","26.52072","0.34337"
"53106","318.60000","26.55020","0.34457"
"53165","318.95400","26.57974","0.34587"
"53224","319.30800","26.60921","0.34784"
"53283","319.66200","26.63875","0.35067"
"53342","320.01600","26.66823","0.35280"
"53401","320.37000","26.69764","0.35477"
"53460","320.72400","26.72724","0.35690"
"53519","321.07800","26.75677","0.35885"
"53578","321.43200","26.78619","0.36028"
"53637","321.78600","26.81573","0.36262"
"53696","322.14000","26.84526","0.36475"
"53755","322.49400","26.87468","0.36716"
"53814","322.84800","26.90434","0.36990"
"53873","323.20200","26.93369","0.37181"
"53932","323.55600","26.96322","0.37370"
"53991","323.91000","26.99270","0.37642"
"54050","324.26400","27.02218","0.37846"
"54109","324.61800","27.05172","0.38178"
"54168","324.97200","27.08119","0.38410"
"54227","325.32600","27.11073","0.38643"
"54286","325.68000","27.14020","0.38852"
"54345","326.03400","27.16974","0.39102"
"54404","326.38800","27.19915","0.39271"
"54463","326.74200","27.22875","0.39404"
"54522","327.09600","27.25823","0.03942"
"54581","327.45000","27.28770","0.00906"
"54640","327.80400","27.31718","0.00906"
"54699","328.15800","27.34678","0.01517"
"54758","328.51200","27.37619","0.01013"
"54817","328.86600","27.40573","0.02309"
"54876","329.22000","27.43521","0.01095"
"54935","329.57400","27.46468","0.01950"
"54994","329.92800","27.49416","0.01753"
"55053","330.28200","27.52375","0.01158"
"55112","330.63600","27.55317","0.01766"
"55171","330.99000","27.58270","0.01384"
"55230","331.34400","27.61224","0.01174"
"55289","331.69800","27.64166","0.01651"
"55348","332.05200","27.67125","0.01534"
"55407","332.40600","27.70073","0.01321"
"55466","332.76000","27.73021","0.01651"
"55525","333.11400","27.75968","0.01645"
"55584","333.46800","27.78922","0.01383"
"55643","333.82200","27.81870","0.01556"
"55702","334.17600","27.84823","0.01661"
"55761","334.53000","27.87771","0.01427"
"55820","334.88400","27.90725","0.01487"
"55879","335.23800","27.93672","0.01688"
"55938","335.59200","27.96626","0.01542"
"55997","335.94600","27.99573","0.01455"
"56056","336.30000","28.02527","0.01672"
"56115","336.65400","28.05469","0.01669"
"56174","337.00800","28.08416","0.01535"
"56233","337.36200","28.11370","0.01616"
"56292","337.71600","28.14317","0.01720"
"56351","338.07000","28.17277","0.01600"
"56410","338.42400","28.20218","0.01600"
"56469","338.77800","28.23172","0.01704"
"56528","339.13200","28.26120","0.01647"
"56587","339.48600","28.29079","0.01609"
"56646","339.84000","28.32015","0.01729"
"56705","340.19400","28.34975","0.01711"
"56764","340.54800","28.37922","0.01651"
"56823","340.90200","28.40870","0.01708"
"56882","341.25600","28.43823","0.01768"
"56941","341.61000","28.46777","0.01706"
"57000","341.96400","28.49718","0.01694"
"57059","342.31800","28.52672","0.01771"
"57118","342.67200","28.55626","0.01759"
"57177","343.02600","28.58562","0.01701"
"57236","343.38000","28.61527","0.01788"
"57295","343.73400","28.64475","0.01790"
"57354","344.08800","28.67422","0.01768"
"57413","344.44200","28.70376","0.01771"
"57472","344.79600","28.73329","0.01857"
"57531","345.15000","28.76265","0.01908"
"57590","345.50400","28.79225","0.01777"
"57649","345.85800","28.82172","0.01846"
"57708","346.21200","28.85114","0.01891"
"57767","346.56600","28.88074","0.01843"
"57826","346.92000","28.91021","0.01907"
"57885","347.27400","28.93969","0.01933"
"57944","347.62800","28.96923","0.01964"
"58003","347.98200","28.99870","0.01920"
"58062","348.33600","29.02818","0.01951"
"58121","348.69000","29.05778","0.02038"
"58180","349.04400","29.08719","0.02005"
"58239","349.39800","29.11667","0.01999"
"58298","349.75200","29.14626","0.02044"
"58357","350.10600","29.17574","0.02079"
"58416","350.46000","29.20521","0.02080"
"58475","350.81400","29.23481","0.02074"
"58534","351.16800","29.26417","0.02122"
"58593","351.52200","29.29376","0.02088"
"58652","351.87600","29.32324","0.02136"
"58711","352.23000","29.35265","0.02145"
"58770","352.58400","29.38225","0.02197"
"58829","352.93800","29.41167","0.02171"
"58888","353.29200","29.44120","0.02215"
"58947","353.64600","29.47068","0.02279"
"59006","354.00000","29.50028","0.02264"
"59065","354.35400","29.52963","0.02311"
"59124","354.70800","29.55929","0.02295"
"59183","355.06200","29.58871","0.02316"
"59242","355.41600","29.61818","0.02386"
"59301","355.77000","29.64766","0.02437"
"59360","356.12400","29.67725","0.02461"
"59419","356.47800","29.70667","0.02460"
"59478","356.83200","29.73626","0.02540"
"59537","357.18600","29.76580","0.02588"
"59596","357.54000","29.79516","0.02663"
"59655","357.89400","29.82469","0.02698"
"59714","358.24800","29.85423","0.02719"
"59773","358.60200","29.88365","0.02753"
"59832","358.95600","29.91324","0.02856"
"59891","359.31000","29.94278","0.02914"
"59950","359.66400","29.97219","0.02971"
"60009","360.01800","30.00173","0.03032"
"60068","360.37200","30.03121","0.03067"
"60127","360.72600","30.06068","0.03228"
"60186","361.08000","30.09028","0.03174"
"60245","361.43400","30.11975","0.03185"
"60304","361.78800","30.14923","0.03206"
"60363","362.14200","30.17871","0.03262"
"60422","362.49600","30.20818","0.03286"
"60481","362.85000","30.23772","0.02213"
"60540","363.20400","30.26726","0.02463"
"60599","363.55800","30.29673","0.02464"
"60658","363.91200","30.32621","0.02593"
"60717","364.26600","30.35574","0.02612"
"60776","364.62000","30.38516","0.02657"
"60835","364.97400","30.41470","0.02662"
"60894","365.32800","30.44429","0.02732"
"60953","365.68200","30.47365","0.02793"
"61012","366.03600","30.50324","0.02794"
"61071","366.39000","30.53272","0.02833"
"61130","366.74400","30.56220","0.02928"
"61189","367.09800","30.59173","0.02999"
"61248","367.45200","30.62127","0.02961"
"61307","367.80600","30.65069","0.03042"
"61366","368.16000","30.68022","0.03096"
"61425","368.51400","30.70970","0.03177"
"61484","368.86800","30.73911","0.03164"
"61543","369.22200","30.76871","0.03257"
"61602","369.57600","30.79825","0.03359"
"61661","369.93000","30.82772","0.03437"
"61720","370.28400","30.85726","0.03486"
"61779","370.63800","30.88680","0.03541"
"61838","370.99200","30.91615","0.03639"
"61897","371.34600","30.94575","0.03675"
"61956","371.70000","30.97522","0.03745"
"62015","372.05400","31.00470","0.03869"
"62074","372.40800","31.03429","0.03977"
"62133","372.76200","31.06377","0.04027"
"62192","373.11600","31.09319","0.04166"
"62251","373.47000","31.12272","0.04250"
"62310","373.82400","31.15220","0.04326"
"62369","374.17800","31.18168","0.04530"
"62428","374.53200","31.21127","0.04661"
"62487","374.88600","31.24069","0.04702"
"62546","375.24000","31.27023","0.04857"
"62605","375.59400","31.29970","0.05001"
"62664","375.94800","31.32918","0.05092"
"62723","376.30200","31.35871","0.05187"
"62782","376.65600","31.38825","0.05284"
"62841","377.01000","31.41766","0.05445"
"62900","377.36400","31.44720","0.05503"
"62959","377.71800","31.47674","0.05564"
"63018","378.07200","31.50621","0.05659"
"63077","378.42600","31.53569","0.05728"
"63136","378.78000","31.56523","0.05867"
"63195","379.13400","31.59470","0.05946"
"63254","379.48800","31.62418","0.06100"
"63313","379.84200","31.65371","0.06106"
"63372","380.19600","31.68319","0.06100"
"63431","380.55000","31.71273","0.06197"
"63490","380.90400","31.74220","0.06335"
"63549","381.25800","31.77168","0.06392"
"63608","381.61200","31.80122","0.06493"
"63667","381.96600","31.83075","0.06634"
"63726","382.32000","31.86017","0.06785"
"63785","382.67400","31.88976","0.06916"
"63844","383.02800","31.91924","0.07069"
"63903","383.38200","31.94866","0.07228"
"63962","383.73600","31.97825","0.07385"
"64021","384.09000","32.00767","0.07506"
"64080","384.44400","32.03714","0.07674"
"64139","384.79800","32.06674","0.07832"
"64198","385.15200","32.09622","0.07818"
"64257","385.50600","32.12569","0.07924"
"64316","385.86000","32.15523","0.08142"
"64375","386.21400","32.18470","0.08185"
"64434","386.56800","32.21424","0.08323"
"64493","386.92200","32.24372","0.08539"
"64552","387.27600","32.27325","0.08808"
"64611","387.63000","32.30273","0.08916"
"64670","387.98400","32.33220","0.09200"
"64729","388.33800","32.36168","0.09390"
"64788","388.69200","32.39122","0.09619"
"64847","389.04600","32.42075","0.09827"
"64906","389.40000","32.45023","0.09939"
"64965","389.75400","32.47971","0.10133"
"65024","390.10800","32.50924","0.10226"
"65083","390.46200","32.53872","0.10321"
"65142","390.81600","32.56820","0.10464"
"65201","391.17000","32.59773","0.10538"
"65260","391.52400","32.62720","0.10615"
"65319","391.87800","32.65675","0.10732"
"65378","392.23200","32.68622","0.10796"
"65437","392.58600","32.71570","0.10855"
"65496","392.94000","32.74523","0.10933"
"65555","393.29400","32.77477","0.11011"
"65614","393.64800","32.80418","0.11089"
"65673","394.00200","32.83372","0.11195"
"65732","394.35600","32.86320","0.11262"
"65791","394.71000","32.89267","0.11385"
"65850","395.06400","32.92221","0.11531"
"65909","395.41800","32.95175","0.11778"
"65968","395.77200","32.98116","0.11948"
"66027","396.12600","33.01076","0.12098"
"66086","396.48000","33.04029","0.12314"
"66145","396.83400","33.06965","0.12562"
"66204","397.18800","33.09919","0.12854"
"66263","397.54200","33.12872","0.13116"
"66322","397.89600","33.15820","0.13447"
"66381","398.25000","33.18774","0.13792"
"66440","398.60400","33.21727","0.14081"
"66499","398.95800","33.24662","0.14471"
"66558","399.31200","33.27628","0.14759"
"66617","399.66600","33.30576","0.15087"
"66676","400.02000","33.33517","0.15268"
"66735","400.37400","33.36471","0.15363"
"66794","400.72800","33.39419","0.15704"
"66853","401.08200","33.42366","0.15892"
"66912","401.43600","33.45326","0.16118"
"66971","401.79000","33.48273","0.16455"
"67030","402.14400","33.51221","0.16588"
"67089","402.49800","33.54175","0.16835"
"67148","402.85200","33.57116","0.16976"
"67207","403.20600","33.60070","0.17124"
"67266","403.56000","33.63018","0.17271"
"67325","403.91400","33.65971","0.17389"
"67384","404.26800","33.68919","0.17588"
"67443","404.62200","33.71878","0.17839"
"67502","404.97600","33.74820","0.18072"
"67561","405.33000","33.77774","0.18218"
"67620","405.68400","33.80721","0.18505"
"67679","406.03800","33.83669","0.18698"
"67738","406.39200","33.86623","0.18945"
"67797","406.74600","33.89570","0.19288"
"67856","407.10000","33.92518","0.19598"
"67915","407.45400","33.95471","0.19941"
"67974","407.80800","33.98431","0.20171"
"68033","408.16200","34.01367","0.20384"
"68092","408.51600","34.04321","0.20649"
"68151","408.87000","34.07280","0.20935"
"68210","409.22400","34.10221","0.21119"
"68269","409.57800","34.13169","0.21294"
"68328","409.93200","34.16123","0.21448"
"68387","410.28600","34.19070","0.21622"
"68446","410.64000","34.22024","0.21765"
"68505","410.99400","34.24971","0.21867"
"68564","411.34800","34.27913","0.21962"
"68623","411.70200","34.30873","0.22092"
"68682","412.05600","34.33821","0.22302"
"68741","412.41000","34.36768","0.22514"
"68800","412.76400","34.39722","0.22725"
"68859","413.11800","34.42675","0.22997"
"68918","413.47200","34.45617","0.23311"
"68977","413.82600","34.48571","0.23572"
"69036","414.18000","34.51524","0.23836"
"69095","414.53400","34.54472","0.24158"
"69154","414.88800","34.57426","0.24504"
"69213","415.24200","34.60379","0.24757"
"69272","415.59600","34.63314","0.25046"
"69331","415.95000","34.66274","0.25362"
"69390","416.30400","34.69222","0.25583"
"69449","416.65800","34.72169","0.25881"
"69508","417.01200","34.75129","0.26119"
"69567","417.36600","34.78071","0.26346"
"69626","417.72000","34.81018","0.26569"
"69685","418.07400","34.83972","0.26840"
"69744","418.42800","34.86926","0.27082"
"69803","418.78200","34.89867","0.27464"
"69862","419.13600","34.92826","0.27858"
"69921","419.49000","34.95768","0.28306"
"69980","419.84400","34.98722","0.28702"
"70039","420.19800","35.01670","0.29231"
"70098","420.55200","35.04617","0.29736"
"70157","420.90600","35.07571","0.30240"
"70216","421.26000","35.10524","0.30573"
"70275","421.61400","35.13472","0.30952"
"70334","421.96800","35.16426","0.31297"
"70393","422.32200","35.19379","0.31596"
"70452","422.67600","35.22315","0.31851"
"70511","423.03000","35.25275","0.32087"
"70570","423.38400","35.28222","0.32214"
"70629","423.73800","35.31170","0.32315"
"70688","424.09200","35.34123","0.32377"
"70747","424.44600","35.37077","0.32450"
"70806","424.80000","35.40018","0.32512"
"70865","425.15400","35.42972","0.32604"
"70924","425.50800","35.45926","0.01912"
"70983","425.86200","35.48868","0.01053"
"71042","426.21600","35.51821","0.01594"
"71101","426.57000","35.54775","0.01514"
"71160","426.92400","35.57716","0.01666"
"71219","427.27800","35.60676","0.01411"
"71278","427.63200","35.63623","0.01496"
"71337","427.98600","35.66565","0.01319"
"71396","428.34000","35.69531","0.01597"
"71455","428.69400","35.72472","0.01429"
"71514","429.04800","35.75420","0.01537"
"71573","429.40200","35.78374","0.01348"
"71632","429.75600","35.81321","0.01523"
"71691","430.11000","35.84269","0.01497"
"71750","430.46400","35.87228","0.01642"
"71809","430.81800","35.90164","0.01505"
"71868","431.17200","35.93124","0.01417"
"71927","431.52600","35.96072","0.01546"
"71986","431.88000","35.99019","0.01393"
"72045","432.23400","36.01973","0.01538"
"72104","432.58800","36.04920","0.01452"
"72163","432.94200","36.07874","0.01507"
"72222","433.29600","36.10827","0.01494"
"72234","433.36400","36.11383","0.01559"