File: Trajectories_together/161218Specimen_RawData_6.csv
"","V1","V2","V3"
"1","End date","12/18/2016",""
"2","Specimen label","17AT_40",""
"3","Maximum Load","0.55607","N"
"4","Time","Extension","Load"
"5","(s)","(mm)","(N)"
"6","0.00000","0.00000","-0.00016"
"81","0.45000","0.03773","0.00064"
"156","0.90000","0.07516","0.00069"
"231","1.35000","0.11264","0.00062"
"306","1.80000","0.15013","0.00149"
"381","2.25000","0.18762","0.00148"
"456","2.70000","0.22517","0.00175"
"531","3.15000","0.26266","0.00199"
"606","3.60000","0.30014","0.00257"
"681","4.05000","0.33763","0.00289"
"756","4.50000","0.37506","0.00301"
"831","4.95000","0.41255","0.00344"
"906","5.40000","0.45010","0.00334"
"981","5.85000","0.48770","0.00391"
"1056","6.30000","0.52519","0.00404"
"1131","6.75000","0.56268","0.00422"
"1206","7.20000","0.60017","0.00446"
"1281","7.65000","0.63760","0.00516"
"1356","8.10000","0.67514","0.00512"
"1431","8.55000","0.71263","0.00583"
"1506","9.00000","0.75018","0.00574"
"1581","9.45000","0.78767","0.00613"
"1656","9.90000","0.82510","0.00679"
"1731","10.35000","0.86258","0.00681"
"1806","10.80000","0.90013","0.00738"
"1881","11.25000","0.93762","0.00790"
"1956","11.70000","0.97517","0.00807"
"2031","12.15000","1.01266","0.00834"
"2106","12.60000","1.05014","0.00910"
"2181","13.05000","1.08757","0.00943"
"2256","13.50000","1.12512","0.01000"
"2331","13.95000","1.16261","0.01014"
"2406","14.40000","1.20016","0.01057"
"2481","14.85000","1.23764","0.01121"
"2556","15.30000","1.27513","0.01211"
"2631","15.75000","1.31262","0.01271"
"2706","16.20000","1.35011","0.01280"
"2781","16.65000","1.38766","0.01353"
"2856","17.10000","1.42514","0.01401"
"2931","17.55000","1.46263","0.01450"
"3006","18.00000","1.50012","0.01567"
"3081","18.45000","1.53761","0.01631"
"3156","18.90000","1.57516","0.01655"
"3231","19.35000","1.61270","0.01734"
"3306","19.80000","1.65013","0.01790"
"3381","20.25000","1.68762","0.01869"
"3456","20.70000","1.72511","0.01935"
"3531","21.15000","1.76254","0.01916"
"3606","21.60000","1.80008","0.01988"
"3681","22.05000","1.83763","0.02064"
"3756","22.50000","1.87512","0.02068"
"3831","22.95000","1.91267","0.02021"
"3906","23.40000","1.95016","0.02074"
"3981","23.85000","1.98764","0.02131"
"4056","24.30000","2.02513","0.02182"
"4131","24.75000","2.06256","0.02242"
"4206","25.20000","2.10017","0.02270"
"4281","25.65000","2.13766","0.02317"
"4356","26.10000","2.17514","0.02362"
"4431","26.55000","2.21263","0.02307"
"4506","27.00000","2.25012","0.02391"
"4581","27.45000","2.28761","0.02370"
"4656","27.90000","2.32516","0.02455"
"4731","28.35000","2.36264","0.02513"
"4806","28.80000","2.40019","0.02481"
"4881","29.25000","2.43768","0.02514"
"4956","29.70000","2.47505","0.02606"
"5031","30.15000","2.51266","0.02638"
"5106","30.60000","2.55014","0.02699"
"5181","31.05000","2.58757","0.02743"
"5256","31.50000","2.62512","0.02816"
"5331","31.95000","2.66261","0.02787"
"5406","32.40000","2.70016","0.02889"
"5481","32.85000","2.73764","0.02853"
"5556","33.30000","2.77513","0.02974"
"5631","33.75000","2.81268","0.03100"
"5706","34.20000","2.85017","0.02962"
"5781","34.65000","2.88760","0.02923"
"5856","35.10000","2.92508","0.03035"
"5931","35.55000","2.96257","0.03093"
"6006","36.00000","3.00012","0.03086"
"6081","36.45000","3.03767","0.03191"
"6156","36.90000","3.07516","0.03127"
"6231","37.35000","3.11264","0.03245"
"6306","37.80000","3.15007","0.03229"
"6381","38.25000","3.18762","0.03335"
"6456","38.70000","3.22517","0.03430"
"6531","39.15000","3.26265","0.03384"
"6606","39.60000","3.30014","0.03454"
"6681","40.05000","3.33763","0.03560"
"6756","40.50000","3.37506","0.03604"
"6831","40.95000","3.41261","0.03655"
"6906","41.40000","3.45016","0.03665"
"6981","41.85000","3.48764","0.03760"
"7056","42.30000","3.52519","0.03824"
"7131","42.75000","3.56262","0.03860"
"7206","43.20000","3.60011","0.03946"
"7281","43.65000","3.63766","0.04039"
"7356","44.10000","3.67508","0.04076"
"7431","44.55000","3.71263","0.04068"
"7506","45.00000","3.75018","0.04167"
"7581","45.45000","3.78767","0.04220"
"7656","45.90000","3.82510","0.04226"
"7731","46.35000","3.86258","0.04325"
"7806","46.80000","3.90013","0.04320"
"7881","47.25000","3.93768","0.04358"
"7956","47.70000","3.97517","0.04429"
"8031","48.15000","4.01259","0.04567"
"8106","48.60000","4.05014","0.04620"
"8181","49.05000","4.08757","0.04576"
"8256","49.50000","4.12512","0.04666"
"8331","49.95000","4.16267","0.04827"
"8406","50.40000","4.20009","0.04804"
"8481","50.85000","4.23764","0.04839"
"8556","51.30000","4.27513","0.04954"
"8631","51.75000","4.31262","0.05007"
"8706","52.20000","4.35011","0.05107"
"8781","52.65000","4.38765","0.05157"
"8856","53.10000","4.42514","0.05246"
"8931","53.55000","4.46263","0.05282"
"9006","54.00000","4.50012","0.05411"
"9081","54.45000","4.53761","0.05524"
"9156","54.90000","4.57515","0.05669"
"9231","55.35000","4.61270","0.05762"
"9306","55.80000","4.65019","0.05925"
"9381","56.25000","4.68762","0.05986"
"9456","56.70000","4.72511","0.06136"
"9531","57.15000","4.76254","0.06381"
"9606","57.60000","4.80008","0.06452"
"9681","58.05000","4.83763","0.04963"
"9756","58.50000","4.87512","0.05115"
"9831","58.95000","4.91267","0.05092"
"9906","59.40000","4.95015","0.05222"
"9981","59.85000","4.98758","0.05338"
"10056","60.30000","5.02513","0.05472"
"10131","60.75000","5.06262","0.05534"
"10206","61.20000","5.10011","0.05704"
"10281","61.65000","5.13765","0.05885"
"10356","62.10000","5.17514","0.06068"
"10431","62.55000","5.21263","0.06242"
"10506","63.00000","5.25006","0.06412"
"10581","63.45000","5.28761","0.06634"
"10656","63.90000","5.32515","0.06661"
"10731","64.35000","5.36264","0.06883"
"10806","64.80000","5.40013","0.07022"
"10881","65.25000","5.43756","0.07170"
"10956","65.70000","5.47517","0.07271"
"11031","66.15000","5.51265","0.07306"
"11106","66.60000","5.55014","0.07457"
"11181","67.05000","5.58763","0.07546"
"11256","67.50000","5.62512","0.07639"
"11331","67.95000","5.66255","0.07666"
"11406","68.40000","5.70015","0.07812"
"11481","68.85000","5.73764","0.07795"
"11556","69.30000","5.77519","0.07996"
"11631","69.75000","5.81268","0.08033"
"11706","70.20000","5.85011","0.08137"
"11781","70.65000","5.88760","0.08249"
"11856","71.10000","5.92508","0.08325"
"11931","71.55000","5.96263","0.08420"
"12006","72.00000","6.00018","0.08494"
"12081","72.45000","6.03767","0.07877"
"12156","72.90000","6.07515","0.08024"
"12231","73.35000","6.11258","0.07908"
"12306","73.80000","6.15007","0.06914"
"12381","74.25000","6.18756","0.07018"
"12456","74.70000","6.22517","0.07198"
"12531","75.15000","6.26265","0.07317"
"12606","75.60000","6.30014","0.07426"
"12681","76.05000","6.33763","0.07492"
"12756","76.50000","6.37506","0.07333"
"12831","76.95000","6.41261","0.07406"
"12906","77.40000","6.45010","0.07520"
"12981","77.85000","6.48764","0.07570"
"13056","78.30000","6.52519","0.07677"
"13131","78.75000","6.56262","0.07788"
"13206","79.20000","6.60005","0.07871"
"13281","79.65000","6.63759","0.07973"
"13356","80.10000","6.67514","0.08027"
"13431","80.55000","6.71263","0.08155"
"13506","81.00000","6.75012","0.08204"
"13581","81.45000","6.78761","0.08328"
"13656","81.90000","6.82510","0.08402"
"13731","82.35000","6.86264","0.08444"
"13806","82.80000","6.90013","0.06455"
"13881","83.25000","6.93768","0.06620"
"13956","83.70000","6.97511","0.06766"
"14031","84.15000","7.01259","0.06922"
"14106","84.60000","7.05008","0.07095"
"14181","85.05000","7.08763","0.07195"
"14256","85.50000","7.12518","0.07316"
"14331","85.95000","7.16261","0.07391"
"14406","86.40000","7.20015","0.07522"
"14481","86.85000","7.23764","0.07597"
"14556","87.30000","7.27513","0.07692"
"14631","87.75000","7.31256","0.07732"
"14706","88.20000","7.35017","0.07856"
"14781","88.65000","7.38765","0.07913"
"14856","89.10000","7.42520","0.08037"
"14931","89.55000","7.46257","0.08121"
"15006","90.00000","7.50006","0.08209"
"15081","90.45000","7.53761","0.08274"
"15156","90.90000","7.57509","0.08392"
"15231","91.35000","7.61264","0.08486"
"15306","91.80000","7.65019","0.08578"
"15381","92.25000","7.68762","0.08666"
"15456","92.70000","7.72511","0.08698"
"15531","93.15000","7.76259","0.08792"
"15606","93.60000","7.80008","0.08864"
"15681","94.05000","7.83763","0.07277"
"15756","94.50000","7.87518","0.07302"
"15831","94.95000","7.91261","0.07449"
"15906","95.40000","7.95015","0.07553"
"15981","95.85000","7.98758","0.07636"
"16056","96.30000","8.02513","0.07715"
"16131","96.75000","8.06262","0.07794"
"16206","97.20000","8.10011","0.07880"
"16281","97.65000","8.13765","0.07967"
"16356","98.10000","8.17514","0.08024"
"16431","98.55000","8.21257","0.08180"
"16506","99.00000","8.25018","0.08186"
"16581","99.45000","8.28761","0.08345"
"16656","99.90000","8.32515","0.08403"
"16731","100.35000","8.36264","0.08497"
"16806","100.80000","8.40007","0.05148"
"16881","101.25000","8.43762","0.05406"
"16956","101.70000","8.47517","0.05373"
"17031","102.15000","8.51265","0.05639"
"17106","102.60000","8.55014","0.05763"
"17181","103.05000","8.58763","0.05748"
"17256","103.50000","8.62512","0.06143"
"17331","103.95000","8.66261","0.05955"
"17406","104.40000","8.70009","0.06310"
"17481","104.85000","8.73764","0.06373"
"17556","105.30000","8.77519","0.06677"
"17631","105.75000","8.81268","0.06680"
"17706","106.20000","8.85011","0.06987"
"17781","106.65000","8.88754","0.07040"
"17856","107.10000","8.92508","0.07069"
"17931","107.55000","8.96263","0.07179"
"18006","108.00000","9.00018","0.07252"
"18081","108.45000","9.03767","0.07376"
"18156","108.90000","9.07509","0.07397"
"18231","109.35000","9.11252","0.07558"
"18306","109.80000","9.15007","0.07555"
"18381","110.25000","9.18768","0.07705"
"18456","110.70000","9.22511","0.07703"
"18531","111.15000","9.26265","0.07815"
"18606","111.60000","9.30008","0.07873"
"18681","112.05000","9.33757","0.07981"
"18756","112.50000","9.37512","0.07988"
"18831","112.95000","9.41261","0.08111"
"18906","113.40000","9.45015","0.08132"
"18981","113.85000","9.48758","0.08249"
"19056","114.30000","9.52513","0.08289"
"19131","114.75000","9.56262","0.08420"
"19206","115.20000","9.60011","0.08470"
"19281","115.65000","9.63765","0.08548"
"19356","116.10000","9.67514","0.08612"
"19431","116.55000","9.71263","0.08757"
"19506","117.00000","9.75012","0.08805"
"19581","117.45000","9.78761","0.08868"
"19656","117.90000","9.82509","0.08973"
"19731","118.35000","9.86270","0.09065"
"19806","118.80000","9.90013","0.09203"
"19881","119.25000","9.93762","0.09284"
"19956","119.70000","9.97517","0.09430"
"20031","120.15000","10.01253","0.09482"
"20106","120.60000","10.05014","0.09643"
"20181","121.05000","10.08763","0.09746"
"20256","121.50000","10.12512","0.09957"
"20331","121.95000","10.16267","0.10099"
"20406","122.40000","10.20009","0.10169"
"20481","122.85000","10.23764","0.10344"
"20556","123.30000","10.27513","0.10560"
"20631","123.75000","10.31262","0.10744"
"20706","124.20000","10.35011","0.10925"
"20781","124.65000","10.38765","0.11061"
"20856","125.10000","10.42514","0.11376"
"20931","125.55000","10.46263","0.11507"
"21006","126.00000","10.50006","0.11724"
"21081","126.45000","10.53761","0.11971"
"21156","126.90000","10.57515","0.12181"
"21231","127.35000","10.61264","0.12446"
"21306","127.80000","10.65013","0.12568"
"21381","128.25000","10.68762","0.12831"
"21456","128.70000","10.72511","0.12940"
"21531","129.15000","10.76259","0.13042"
"21606","129.60000","10.80014","0.13227"
"21681","130.05000","10.83757","0.13436"
"21756","130.50000","10.87512","0.13606"
"21831","130.95000","10.91261","0.13754"
"21906","131.40000","10.95009","0.13968"
"21981","131.85000","10.98764","0.14101"
"22056","132.30000","11.02513","0.14217"
"22131","132.75000","11.06262","0.14374"
"22206","133.20000","11.10011","0.14505"
"22281","133.65000","11.13759","0.14701"
"22356","134.10000","11.17508","0.14841"
"22431","134.55000","11.21263","0.14991"
"22506","135.00000","11.25018","0.15194"
"22581","135.45000","11.28767","0.15350"
"22656","135.90000","11.32515","0.15484"
"22731","136.35000","11.36264","0.15612"
"22806","136.80000","11.40007","0.15750"
"22881","137.25000","11.43762","0.15929"
"22956","137.70000","11.47511","0.16201"
"23031","138.15000","11.51271","0.16359"
"23106","138.60000","11.55020","0.16595"
"23181","139.05000","11.58763","0.16835"
"23256","139.50000","11.62512","0.17051"
"23331","139.95000","11.66261","0.17244"
"23406","140.40000","11.70015","0.17362"
"23481","140.85000","11.73764","0.17542"
"23556","141.30000","11.77519","0.17707"
"23631","141.75000","11.81268","0.17929"
"23706","142.20000","11.85005","0.18107"
"23781","142.65000","11.88759","0.18264"
"23856","143.10000","11.92514","0.18389"
"23931","143.55000","11.96269","0.18600"
"24006","144.00000","12.00012","0.18762"
"24081","144.45000","12.03761","0.18915"
"24156","144.90000","12.07509","0.19103"
"24231","145.35000","12.11258","0.19201"
"24306","145.80000","12.15013","0.19387"
"24381","146.25000","12.18768","0.19512"
"24456","146.70000","12.22511","0.19726"
"24531","147.15000","12.26265","0.19953"
"24606","147.60000","12.30008","0.20111"
"24681","148.05000","12.33763","0.20363"
"24756","148.50000","12.37518","0.20586"
"24831","148.95000","12.41267","0.20748"
"24906","149.40000","12.45009","0.21019"
"24981","149.85000","12.48764","0.21162"
"25056","150.30000","12.52507","0.21414"
"25131","150.75000","12.56262","0.21689"
"25206","151.20000","12.60017","0.21965"
"25281","151.65000","12.63765","0.22302"
"25356","152.10000","12.67514","0.22518"
"25431","152.55000","12.71263","0.22742"
"25506","153.00000","12.75012","0.23011"
"25581","153.45000","12.78761","0.23167"
"25656","153.90000","12.82509","0.23445"
"25731","154.35000","12.86264","0.23738"
"25806","154.80000","12.90019","0.23989"
"25881","155.25000","12.93768","0.24242"
"25956","155.70000","12.97511","0.24544"
"26031","156.15000","13.01259","0.24757"
"26106","156.60000","13.05008","0.25023"
"26181","157.05000","13.08763","0.25292"
"26256","157.50000","13.12518","0.25581"
"26331","157.95000","13.16267","0.25799"
"26406","158.40000","13.20015","0.26108"
"26481","158.85000","13.23758","0.26471"
"26556","159.30000","13.27513","0.26900"
"26631","159.75000","13.31262","0.27315"
"26706","160.20000","13.35011","0.27547"
"26781","160.65000","13.38759","0.27875"
"26856","161.10000","13.42514","0.28090"
"26931","161.55000","13.46263","0.28184"
"27006","162.00000","13.50018","0.28403"
"27081","162.45000","13.53767","0.28523"
"27156","162.90000","13.57515","0.28721"
"27231","163.35000","13.61258","0.28929"
"27306","163.80000","13.65007","0.29201"
"27381","164.25000","13.68762","0.29374"
"27456","164.70000","13.72511","0.29576"
"27531","165.15000","13.76259","0.29726"
"27606","165.60000","13.80014","0.29854"
"27681","166.05000","13.83763","0.29975"
"27756","166.50000","13.87512","0.30137"
"27831","166.95000","13.91255","0.30329"
"27906","167.40000","13.95009","0.30481"
"27981","167.85000","13.98764","0.30681"
"28056","168.30000","14.02513","0.30938"
"28131","168.75000","14.06262","0.31165"
"28206","169.20000","14.10011","0.31427"
"28281","169.65000","14.13753","0.31607"
"28356","170.10000","14.17508","0.31897"
"28431","170.55000","14.21263","0.32244"
"28506","171.00000","14.25012","0.32700"
"28581","171.45000","14.28773","0.16124"
"28656","171.90000","14.32509","0.15487"
"28731","172.35000","14.36258","0.15614"
"28806","172.80000","14.40013","0.15958"
"28881","173.25000","14.43756","0.15843"
"28956","173.70000","14.47517","0.15895"
"29031","174.15000","14.51265","0.16101"
"29106","174.60000","14.55020","0.15961"
"29181","175.05000","14.58763","0.16069"
"29256","175.50000","14.62512","0.16567"
"29331","175.95000","14.66261","0.16638"
"29406","176.40000","14.70021","0.16546"
"29481","176.85000","14.73764","0.16701"
"29556","177.30000","14.77513","0.16899"
"29631","177.75000","14.81262","0.16928"
"29706","178.20000","14.85011","0.17300"
"29781","178.65000","14.88765","0.17540"
"29856","179.10000","14.92520","0.17445"
"29931","179.55000","14.96263","0.17427"
"30006","180.00000","15.00012","0.17736"
"30081","180.45000","15.03761","0.18014"
"30156","180.90000","15.07515","0.17967"
"30231","181.35000","15.11258","0.17955"
"30306","181.80000","15.15013","0.18171"
"30381","182.25000","15.18762","0.18359"
"30456","182.70000","15.22511","0.18487"
"30531","183.15000","15.26259","0.18573"
"30606","183.60000","15.30008","0.18660"
"30681","184.05000","15.33763","0.18699"
"30756","184.50000","15.37518","0.18830"
"30831","184.95000","15.41267","0.19017"
"30906","185.40000","15.45015","0.19127"
"30981","185.85000","15.48758","0.19130"
"31056","186.30000","15.52507","0.19215"
"31131","186.75000","15.56256","0.19356"
"31206","187.20000","15.60017","0.19486"
"31281","187.65000","15.63765","0.19533"
"31356","188.10000","15.67514","0.19625"
"31431","188.55000","15.71263","0.19857"
"31506","189.00000","15.75006","0.20146"
"31581","189.45000","15.78761","0.20147"
"31656","189.90000","15.82509","0.20251"
"31731","190.35000","15.86264","0.20480"
"31806","190.80000","15.90019","0.20645"
"31881","191.25000","15.93762","0.20709"
"31956","191.70000","15.97510","0.20856"
"32031","192.15000","16.01259","0.21129"
"32106","192.60000","16.05014","0.21274"
"32181","193.05000","16.08763","0.21331"
"32256","193.50000","16.12512","0.21572"
"32331","193.95000","16.16267","0.21974"
"32406","194.40000","16.20009","0.22184"
"32481","194.85000","16.23764","0.22278"
"32556","195.30000","16.27513","0.22558"
"32631","195.75000","16.31268","0.22785"
"32706","196.20000","16.35011","0.22879"
"32781","196.65000","16.38759","0.23090"
"32856","197.10000","16.42508","0.23371"
"32931","197.55000","16.46263","0.23527"
"33006","198.00000","16.50018","0.23574"
"33081","198.45000","16.53766","0.23865"
"33156","198.90000","16.57515","0.24095"
"33231","199.35000","16.61258","0.24175"
"33306","199.80000","16.65007","0.24383"
"33381","200.25000","16.68756","0.24621"
"33456","200.70000","16.72510","0.24704"
"33531","201.15000","16.76265","0.24848"
"33606","201.60000","16.80014","0.25121"
"33681","202.05000","16.83769","0.25268"
"33756","202.50000","16.87506","0.25513"
"33831","202.95000","16.91261","0.25768"
"33906","203.40000","16.95009","0.25857"
"33981","203.85000","16.98764","0.26137"
"34056","204.30000","17.02513","0.26600"
"34131","204.75000","17.06262","0.26790"
"34206","205.20000","17.10011","0.27295"
"34281","205.65000","17.13753","0.27741"
"34356","206.10000","17.17514","0.28003"
"34431","206.55000","17.21263","0.28278"
"34506","207.00000","17.25018","0.28584"
"34581","207.45000","17.28773","0.28778"
"34656","207.90000","17.32509","0.29022"
"34731","208.35000","17.36258","0.29209"
"34806","208.80000","17.40007","0.29335"
"34881","209.25000","17.43762","0.29555"
"34956","209.70000","17.47511","0.29671"
"35031","210.15000","17.51265","0.29794"
"35106","210.60000","17.55014","0.29939"
"35181","211.05000","17.58763","0.30028"
"35256","211.50000","17.62512","0.30153"
"35331","211.95000","17.66261","0.30234"
"35406","212.40000","17.70015","0.30435"
"35481","212.85000","17.73764","0.30616"
"35556","213.30000","17.77513","0.30830"
"35631","213.75000","17.81256","0.30994"
"35706","214.20000","17.85011","0.31191"
"35781","214.65000","17.88765","0.31153"
"35856","215.10000","17.92514","0.30816"
"35931","215.55000","17.96263","0.31033"
"36006","216.00000","18.00018","0.31279"
"36081","216.45000","18.03754","0.31588"
"36156","216.90000","18.07509","0.31924"
"36231","217.35000","18.11264","0.32252"
"36306","217.80000","18.15019","0.32633"
"36381","218.25000","18.18768","0.32986"
"36456","218.70000","18.22511","0.33250"
"36531","219.15000","18.26253","0.33483"
"36606","219.60000","18.30008","0.33619"
"36681","220.05000","18.33763","0.33958"
"36756","220.50000","18.37518","0.34252"
"36831","220.95000","18.41266","0.34587"
"36906","221.40000","18.45009","0.34799"
"36981","221.85000","18.48758","0.35158"
"37056","222.30000","18.52507","0.35454"
"37131","222.75000","18.56262","0.35668"
"37206","223.20000","18.60011","0.36024"
"37281","223.65000","18.63765","0.36168"
"37356","224.10000","18.67514","0.36419"
"37431","224.55000","18.71263","0.36590"
"37506","225.00000","18.75012","0.36793"
"37581","225.45000","18.78766","0.37141"
"37656","225.90000","18.82515","0.37482"
"37731","226.35000","18.86258","0.37829"
"37806","226.80000","18.90013","0.38123"
"37881","227.25000","18.93762","0.38355"
"37956","227.70000","18.97511","0.38631"
"38031","228.15000","19.01265","0.38769"
"38106","228.60000","19.05014","0.38963"
"38181","229.05000","19.08769","0.39165"
"38256","229.50000","19.12512","0.39158"
"38331","229.95000","19.16261","0.39321"
"38406","230.40000","19.20015","0.39476"
"38481","230.85000","19.23764","0.39675"
"38556","231.30000","19.27513","0.39976"
"38631","231.75000","19.31262","0.40255"
"38706","232.20000","19.35017","0.40676"
"38781","232.65000","19.38759","0.40903"
"38856","233.10000","19.42508","0.41278"
"38931","233.55000","19.46263","0.41522"
"39006","234.00000","19.50018","0.41669"
"39081","234.45000","19.53766","0.41918"
"39156","234.90000","19.57515","0.42360"
"39231","235.35000","19.61264","0.42767"
"39306","235.80000","19.65007","0.40266"
"39381","236.25000","19.68762","0.40750"
"39456","236.70000","19.72516","0.40990"
"39531","237.15000","19.76265","0.41594"
"39606","237.60000","19.80020","0.41852"
"39681","238.05000","19.83763","0.42177"
"39756","238.50000","19.87506","0.42585"
"39831","238.95000","19.91261","0.42422"
"39906","239.40000","19.95015","0.43097"
"39981","239.85000","19.98758","0.43308"
"40056","240.30000","20.02519","0.43613"
"40131","240.75000","20.06262","0.43836"
"40206","241.20000","20.10010","0.44075"
"40281","241.65000","20.13765","0.44360"
"40356","242.10000","20.17508","0.44435"
"40431","242.55000","20.21263","0.44619"
"40506","243.00000","20.25012","0.44735"
"40581","243.45000","20.28766","0.44946"
"40656","243.90000","20.32509","0.42429"
"40731","244.35000","20.36258","0.42351"
"40806","244.80000","20.40013","0.42797"
"40881","245.25000","20.43761","0.42953"
"40956","245.70000","20.47517","0.42908"
"41031","246.15000","20.51259","0.42394"
"41106","246.60000","20.55008","0.42603"
"41181","247.05000","20.58763","0.43128"
"41256","247.50000","20.62518","0.43314"
"41331","247.95000","20.66267","0.43779"
"41406","248.40000","20.70009","0.43782"
"41481","248.85000","20.73764","0.44218"
"41556","249.30000","20.77507","0.44407"
"41631","249.75000","20.81262","0.44619"
"41706","250.20000","20.85011","0.44951"
"41781","250.65000","20.88765","0.45133"
"41856","251.10000","20.92520","0.45569"
"41931","251.55000","20.96263","0.45784"
"42006","252.00000","21.00011","0.46109"
"42081","252.45000","21.03761","0.46599"
"42156","252.90000","21.07509","0.46787"
"42231","253.35000","21.11270","0.47516"
"42306","253.80000","21.15019","0.48036"
"42381","254.25000","21.18768","0.26589"
"42456","254.70000","21.22510","0.13419"
"42531","255.15000","21.26259","0.12806"
"42606","255.60000","21.30008","0.13144"
"42681","256.05000","21.33769","0.13129"
"42756","256.50000","21.37512","0.13053"
"42831","256.95000","21.41266","0.13416"
"42906","257.40000","21.45009","0.13319"
"42981","257.85000","21.48758","0.14033"
"43056","258.30000","21.52513","0.14238"
"43131","258.75000","21.56262","0.14793"
"43206","259.20000","21.60011","0.15425"
"43281","259.65000","21.63759","0.15497"
"43356","260.10000","21.67514","0.16075"
"43431","260.55000","21.71263","0.16073"
"43506","261.00000","21.75012","0.16026"
"43581","261.45000","21.78767","0.16155"
"43656","261.90000","21.82515","0.15879"
"43731","262.35000","21.86264","0.16098"
"43806","262.80000","21.90007","0.16307"
"43881","263.25000","21.93756","0.16802"
"43956","263.70000","21.97511","0.17539"
"44031","264.15000","22.01271","0.18253"
"44106","264.60000","22.05014","0.18998"
"44181","265.05000","22.08763","0.19410"
"44256","265.50000","22.12512","0.19630"
"44331","265.95000","22.16255","0.19492"
"44406","266.40000","22.20015","0.19430"
"44481","266.85000","22.23764","0.19064"
"44556","267.30000","22.27519","0.19331"
"44631","267.75000","22.31262","0.19918"
"44706","268.20000","22.35011","0.19456"
"44781","268.65000","22.38759","0.19867"
"44856","269.10000","22.42514","0.20043"
"44931","269.55000","22.46263","0.20046"
"45006","270.00000","22.50012","0.20258"
"45081","270.45000","22.53766","0.20588"
"45156","270.90000","22.57515","0.21261"
"45231","271.35000","22.61252","0.22261"
"45306","271.80000","22.65013","0.22652"
"45381","272.25000","22.68762","0.22345"
"45456","272.70000","22.72516","0.22340"
"45531","273.15000","22.76259","0.22852"
"45606","273.60000","22.80014","0.23511"
"45681","274.05000","22.83763","0.24070"
"45756","274.50000","22.87512","0.24202"
"45831","274.95000","22.91261","0.24385"
"45906","275.40000","22.95015","0.24896"
"45981","275.85000","22.98764","0.25653"
"46056","276.30000","23.02513","0.26133"
"46131","276.75000","23.06262","0.26329"
"46206","277.20000","23.10016","0.26969"
"46281","277.65000","23.13765","0.28037"
"46356","278.10000","23.17514","0.28522"
"46431","278.55000","23.21263","0.28693"
"46506","279.00000","23.25012","0.29060"
"46581","279.45000","23.28755","0.29591"
"46656","279.90000","23.32509","0.29801"
"46731","280.35000","23.36264","0.29899"
"46806","280.80000","23.40013","0.30210"
"46881","281.25000","23.43762","0.30491"
"46956","281.70000","23.47510","0.30686"
"47031","282.15000","23.51259","0.31077"
"47106","282.60000","23.55008","0.31659"
"47181","283.05000","23.58763","0.31944"
"47256","283.50000","23.62518","0.32519"
"47331","283.95000","23.66266","0.33297"
"47406","284.40000","23.70015","0.33677"
"47481","284.85000","23.73764","0.34271"
"47556","285.30000","23.77507","0.34947"
"47631","285.75000","23.81262","0.35266"
"47706","286.20000","23.85016","0.35705"
"47781","286.65000","23.88765","0.36063"
"47856","287.10000","23.92520","0.36037"
"47931","287.55000","23.96269","0.36385"
"48006","288.00000","24.00006","0.36852"
"48081","288.45000","24.03760","0.37306"
"48156","288.90000","24.07515","0.37861"
"48231","289.35000","24.11264","0.38097"
"48306","289.80000","24.15013","0.38475"
"48381","290.25000","24.18768","0.38820"
"48456","290.70000","24.22511","0.39190"
"48531","291.15000","24.26265","0.39623"
"48606","291.60000","24.30014","0.40004"
"48681","292.05000","24.33763","0.40463"
"48756","292.50000","24.37511","0.39509"
"48831","292.95000","24.41261","0.39880"
"48906","293.40000","24.45009","0.40495"
"48981","293.85000","24.48758","0.40986"
"49056","294.30000","24.52513","0.41736"
"49131","294.75000","24.56268","0.42191"
"49206","295.20000","24.60010","0.42866"
"49281","295.65000","24.63765","0.43418"
"49356","296.10000","24.67508","0.43912"
"49431","296.55000","24.71263","0.44212"
"49506","297.00000","24.75018","0.44587"
"49581","297.45000","24.78761","0.44750"
"49656","297.90000","24.82515","0.44878"
"49731","298.35000","24.86258","0.45134"
"49806","298.80000","24.90001","0.45327"
"49881","299.25000","24.93761","0.45619"
"49956","299.70000","24.97517","0.45965"
"50031","300.15000","25.01265","0.46621"
"50106","300.60000","25.05020","0.47178"
"50181","301.05000","25.08763","0.48041"
"50256","301.50000","25.12506","0.48795"
"50331","301.95000","25.16260","0.49371"
"50406","302.40000","25.20009","0.49922"
"50481","302.85000","25.23764","0.50273"
"50556","303.30000","25.27513","0.50668"
"50631","303.75000","25.31268","0.51054"
"50706","304.20000","25.35011","0.51404"
"50781","304.65000","25.38759","0.51888"
"50856","305.10000","25.42514","0.41648"
"50931","305.55000","25.46269","0.41673"
"51006","306.00000","25.50011","0.43238"
"51081","306.45000","25.53767","0.43511"
"51156","306.90000","25.57509","0.44639"
"51231","307.35000","25.61258","0.44623"
"51306","307.80000","25.65013","0.45871"
"51381","308.25000","25.68768","0.46246"
"51456","308.70000","25.72510","0.47795"
"51531","309.15000","25.76265","0.48384"
"51606","309.60000","25.80008","0.48735"
"51681","310.05000","25.83763","0.49130"
"51756","310.50000","25.87512","0.49852"
"51831","310.95000","25.91266","0.48853"
"51906","311.40000","25.95009","0.35281"
"51981","311.85000","25.98764","0.28048"
"52056","312.30000","26.02513","0.02590"
"52131","312.75000","26.06256","0.01136"
"52206","313.20000","26.10010","0.01479"
"52281","313.65000","26.13771","0.02607"
"52356","314.10000","26.17514","0.02691"
"52431","314.55000","26.21269","0.01716"
"52506","315.00000","26.25012","0.01681"
"52581","315.45000","26.28755","0.02571"
"52656","315.90000","26.32509","0.03144"
"52731","316.35000","26.36264","0.02839"
"52806","316.80000","26.40013","0.02417"
"52881","317.25000","26.43768","0.02535"
"52956","317.70000","26.47511","0.02748"
"53031","318.15000","26.51259","0.02975"
"53106","318.60000","26.55008","0.03200"
"53181","319.05000","26.58763","0.03267"
"53256","319.50000","26.62512","0.03152"
"53331","319.95000","26.66266","0.03326"
"53406","320.40000","26.70015","0.03669"
"53481","320.85000","26.73758","0.03757"
"53556","321.30000","26.77507","0.03801"
"53631","321.75000","26.81262","0.03847"
"53706","322.20000","26.85016","0.03822"
"53781","322.65000","26.88765","0.03867"
"53856","323.10000","26.92514","0.04061"
"53931","323.55000","26.96263","0.04167"
"54006","324.00000","27.00012","0.04239"
"54081","324.45000","27.03761","0.04480"
"54156","324.90000","27.07515","0.04625"
"54231","325.35000","27.11264","0.04745"
"54306","325.80000","27.15007","0.04859"
"54381","326.25000","27.18756","0.05073"
"54456","326.70000","27.22510","0.05214"
"54531","327.15000","27.26265","0.05309"
"54606","327.60000","27.30014","0.05585"
"54681","328.05000","27.33763","0.05681"
"54756","328.50000","27.37512","0.05864"
"54831","328.95000","27.41261","0.06032"
"54906","329.40000","27.45009","0.06267"
"54981","329.85000","27.48764","0.06443"
"55056","330.30000","27.52513","0.06723"
"55131","330.75000","27.56268","0.06994"
"55206","331.20000","27.60016","0.07200"
"55281","331.65000","27.63753","0.07353"
"55356","332.10000","27.67508","0.07464"
"55431","332.55000","27.71263","0.07542"
"55506","333.00000","27.75018","0.07607"
"55581","333.45000","27.78766","0.07598"
"55656","333.90000","27.82515","0.07796"
"55731","334.35000","27.86264","0.07912"
"55806","334.80000","27.90007","0.08098"
"55881","335.25000","27.93762","0.08212"
"55956","335.70000","27.97511","0.08365"
"56031","336.15000","28.01265","0.08538"
"56106","336.60000","28.05020","0.08717"
"56181","337.05000","28.08757","0.08808"
"56256","337.50000","28.12506","0.08987"
"56331","337.95000","28.16261","0.09137"
"56406","338.40000","28.20015","0.09316"
"56481","338.85000","28.23764","0.09529"
"56556","339.30000","28.27513","0.09832"
"56631","339.75000","28.31262","0.10131"
"56706","340.20000","28.35010","0.10511"
"56781","340.65000","28.38765","0.10868"
"56856","341.10000","28.42514","0.11373"
"56931","341.55000","28.46269","0.11851"
"57006","342.00000","28.50012","0.12294"
"57081","342.45000","28.53761","0.12813"
"57156","342.90000","28.57509","0.13093"
"57231","343.35000","28.61264","0.13463"
"57306","343.80000","28.65019","0.13934"
"57381","344.25000","28.68761","0.14242"
"57456","344.70000","28.72516","0.14483"
"57531","345.15000","28.76265","0.13706"
"57606","345.60000","28.80008","0.14316"
"57681","346.05000","28.83763","0.14562"
"57756","346.50000","28.87518","0.14969"
"57831","346.95000","28.91266","0.15344"
"57906","347.40000","28.95021","0.15687"
"57981","347.85000","28.98758","0.16041"
"58056","348.30000","29.02507","0.16612"
"58131","348.75000","29.06256","0.17032"
"58206","349.20000","29.10011","0.17444"
"58281","349.65000","29.13765","0.17692"
"58356","350.10000","29.17520","0.18060"
"58431","350.55000","29.21263","0.18413"
"58506","351.00000","29.25011","0.18840"
"58581","351.45000","29.28760","0.19117"
"58656","351.90000","29.32509","0.19447"
"58731","352.35000","29.36264","0.19791"
"58806","352.80000","29.40019","0.20187"
"58881","353.25000","29.43762","0.20538"
"58956","353.70000","29.47510","0.21003"
"59031","354.15000","29.51259","0.21421"
"59106","354.60000","29.55014","0.21911"
"59181","355.05000","29.58763","0.22431"
"59256","355.50000","29.62512","0.22794"
"59331","355.95000","29.66266","0.23125"
"59406","356.40000","29.70015","0.23475"
"59481","356.85000","29.73758","0.23909"
"59556","357.30000","29.77513","0.24300"
"59631","357.75000","29.81261","0.24721"
"59706","358.20000","29.85016","0.25155"
"59781","358.65000","29.88759","0.25650"
"59856","359.10000","29.92508","0.26409"
"59931","359.55000","29.96263","0.27260"
"60006","360.00000","30.00012","0.27925"
"60081","360.45000","30.03767","0.28491"
"60156","360.90000","30.07509","0.28933"
"60231","361.35000","30.11264","0.29324"
"60306","361.80000","30.15007","0.29648"
"60381","362.25000","30.18756","0.29909"
"60456","362.70000","30.22511","0.30059"
"60531","363.15000","30.26265","0.30288"
"60606","363.60000","30.30014","0.30612"
"60681","364.05000","30.33763","0.30994"
"60756","364.50000","30.37512","0.31431"
"60831","364.95000","30.41254","0.32100"
"60906","365.40000","30.45009","0.32748"
"60981","365.85000","30.48764","0.33269"
"61056","366.30000","30.52513","0.33815"
"61131","366.75000","30.56268","0.34404"
"61206","367.20000","30.60011","0.34950"
"61281","367.65000","30.63753","0.35318"
"61356","368.10000","30.67508","0.35713"
"61431","368.55000","30.71263","0.36015"
"61506","369.00000","30.75012","0.36413"
"61581","369.45000","30.78766","0.36811"
"61656","369.90000","30.82509","0.37236"
"61731","370.35000","30.86258","0.37844"
"61806","370.80000","30.90013","0.38266"
"61881","371.25000","30.93762","0.38749"
"61956","371.70000","30.97510","0.39116"
"62031","372.15000","31.01265","0.39485"
"62106","372.60000","31.05020","0.39930"
"62181","373.05000","31.08763","0.40481"
"62256","373.50000","31.12506","0.41120"
"62331","373.95000","31.16267","0.41700"
"62406","374.40000","31.20015","0.42288"
"62481","374.85000","31.23764","0.43009"
"62556","375.30000","31.27513","0.43363"
"62631","375.75000","31.31261","0.43857"
"62706","376.20000","31.35010","0.44364"
"62781","376.65000","31.38765","0.44710"
"62856","377.10000","31.42520","0.45021"
"62931","377.55000","31.46263","0.45430"
"63006","378.00000","31.50012","0.46010"
"63081","378.45000","31.53754","0.46631"
"63156","378.90000","31.57515","0.47316"
"63231","379.35000","31.61264","0.48098"
"63306","379.80000","31.65013","0.48843"
"63381","380.25000","31.68761","0.49498"
"63456","380.70000","31.72510","0.50013"
"63531","381.15000","31.76265","0.50412"
"63606","381.60000","31.80008","0.50767"
"63681","382.05000","31.83763","0.51173"
"63756","382.50000","31.87517","0.51576"
"63831","382.95000","31.91266","0.51954"
"63906","383.40000","31.95015","0.52436"
"63981","383.85000","31.98764","0.20081"
"64056","384.30000","32.02507","0.21891"
"64131","384.75000","32.06261","0.23163"
"64206","385.20000","32.10016","0.23058"
"64281","385.65000","32.13765","0.23074"
"64356","386.10000","32.17514","0.23272"
"64431","386.55000","32.21257","0.23593"
"64506","387.00000","32.25011","0.24171"
"64581","387.45000","32.28760","0.25504"
"64656","387.90000","32.32515","0.27046"
"64731","388.35000","32.36258","0.27381"
"64806","388.80000","32.40013","0.26859"
"64881","389.25000","32.43768","0.27753"
"64956","389.70000","32.47510","0.28878"
"65031","390.15000","32.51259","0.29601"
"65106","390.60000","32.55014","0.29754"
"65181","391.05000","32.58768","0.29823"
"65256","391.50000","32.62512","0.30110"
"65331","391.95000","32.66261","0.30735"
"65406","392.40000","32.70009","0.31141"
"65481","392.85000","32.73764","0.31291"
"65556","393.30000","32.77518","0.31977"
"65631","393.75000","32.81268","0.33213"
"65706","394.20000","32.85010","0.33714"
"65781","394.65000","32.88765","0.34093"
"65856","395.10000","32.92508","0.34992"
"65931","395.55000","32.96263","0.35686"
"66006","396.00000","33.00018","0.36058"
"66081","396.45000","33.03766","0.36536"
"66156","396.90000","33.07515","0.37334"
"66231","397.35000","33.11258","0.37847"
"66306","397.80000","33.15007","0.38442"
"66381","398.25000","33.18762","0.39016"
"66456","398.70000","33.22511","0.39423"
"66531","399.15000","33.26265","0.39963"
"66606","399.60000","33.30020","0.40621"
"66681","400.05000","33.33768","0.41037"
"66756","400.50000","33.37505","0.41831"
"66831","400.95000","33.41260","0.35384"
"66906","401.40000","33.45009","0.34954"
"66981","401.85000","33.48770","0.35781"
"67056","402.30000","33.52519","0.36505"
"67131","402.75000","33.56261","0.36522"
"67206","403.20000","33.60010","0.37347"
"67281","403.65000","33.63759","0.38329"
"67356","404.10000","33.67514","0.38494"
"67431","404.55000","33.71262","0.39080"
"67506","405.00000","33.75011","0.39745"
"67581","405.45000","33.78766","0.39956"
"67656","405.90000","33.82509","0.41054"
"67731","406.35000","33.86264","0.41509"
"67806","406.80000","33.90013","0.41241"
"67881","407.25000","33.93768","0.39805"
"67956","407.70000","33.97516","0.39980"
"68031","408.15000","34.01265","0.40714"
"68106","408.60000","34.05008","0.41421"
"68181","409.05000","34.08763","0.41978"
"68256","409.50000","34.12511","0.42852"
"68331","409.95000","34.16260","0.43380"
"68406","410.40000","34.20015","0.43933"
"68481","410.85000","34.23764","0.44411"
"68556","411.30000","34.27507","0.44829"
"68631","411.75000","34.31255","0.45205"
"68706","412.20000","34.35011","0.45718"
"68781","412.65000","34.38765","0.46263"
"68856","413.10000","34.42514","0.46762"
"68931","413.55000","34.46263","0.45008"
"69006","414.00000","34.50011","0.45446"
"69081","414.45000","34.53760","0.46046"
"69156","414.90000","34.57509","0.46064"
"69231","415.35000","34.61264","0.46730"
"69306","415.80000","34.65013","0.45845"
"69381","416.25000","34.68768","0.46242"
"69456","416.70000","34.72516","0.46572"
"69531","417.15000","34.76253","0.47313"
"69606","417.60000","34.80014","0.47918"
"69681","418.05000","34.83763","0.48888"
"69756","418.50000","34.87511","0.49418"
"69831","418.95000","34.91267","0.49989"
"69906","419.40000","34.95015","0.50343"
"69981","419.85000","34.98764","0.50682"
"70056","420.30000","35.02513","0.51074"
"70131","420.75000","35.06268","0.46448"
"70206","421.20000","35.10016","0.45509"
"70281","421.65000","35.13765","0.45688"
"70356","422.10000","35.17508","0.44016"
"70431","422.55000","35.21257","0.37500"
"70506","423.00000","35.25006","0.37340"
"70581","423.45000","35.28761","0.37555"
"70656","423.90000","35.32515","0.38197"
"70731","424.35000","35.36264","0.38599"
"70806","424.80000","35.40013","0.38930"
"70881","425.25000","35.43755","0.39135"
"70956","425.70000","35.47510","0.38772"
"71031","426.15000","35.51265","0.39112"
"71106","426.60000","35.55014","0.39619"
"71181","427.05000","35.58763","0.36577"
"71256","427.50000","35.62511","0.37082"
"71331","427.95000","35.66254","0.37323"
"71406","428.40000","35.70009","0.37527"
"71481","428.85000","35.73764","0.37607"
"71556","429.30000","35.77512","0.37864"
"71631","429.75000","35.81268","0.38304"
"71706","430.20000","35.85011","0.38744"
"71781","430.65000","35.88759","0.38981"
"71856","431.10000","35.92514","0.39385"
"71931","431.55000","35.96257","0.39717"
"72006","432.00000","36.00017","0.40159"
"72081","432.45000","36.03766","0.40703"
"72156","432.90000","36.07521","0.41149"
"72231","433.35000","36.11258","0.41671"
"72306","433.80000","36.15013","0.42121"
"72381","434.25000","36.18761","0.42635"
"72456","434.70000","36.22516","0.43105"
"72531","435.15000","36.26265","0.43458"
"72606","435.60000","36.30014","0.43901"
"72681","436.05000","36.33762","0.44241"
"72756","436.50000","36.37505","0.44533"
"72831","436.95000","36.41261","0.44903"
"72906","437.40000","36.45015","0.45311"
"72981","437.85000","36.48764","0.45719"
"73056","438.30000","36.52513","0.46182"
"73131","438.75000","36.56261","0.46656"
"73206","439.20000","36.60010","0.47491"
"73281","439.65000","36.63765","0.48221"
"73356","440.10000","36.67514","0.48910"
"73431","440.55000","36.71263","0.49536"
"73506","441.00000","36.75011","0.49969"
"73581","441.45000","36.78760","0.50216"
"73656","441.90000","36.82503","0.50337"
"73731","442.35000","36.86258","0.50582"
"73806","442.80000","36.90018","0.50906"
"73881","443.25000","36.93768","0.51104"
"73956","443.70000","36.97516","0.51374"
"74031","444.15000","37.01259","0.51257"
"74106","444.60000","37.05002","0.51349"
"74181","445.05000","37.08757","0.51327"
"74256","445.50000","37.12511","0.51496"
"74331","445.95000","37.16266","0.51744"
"74406","446.40000","37.20015","0.51977"
"74481","446.85000","37.23764","0.51419"
"74556","447.30000","37.27507","0.51831"
"74631","447.75000","37.31261","0.52210"
"74706","448.20000","37.35010","0.52723"
"74781","448.65000","37.38765","0.53048"
"74856","449.10000","37.42520","0.53426"
"74931","449.55000","37.46263","0.53809"
"75006","450.00000","37.50011","0.54159"
"75081","450.45000","37.53761","0.54612"
"75156","450.90000","37.57509","0.54973"
"75231","451.35000","37.61264","0.55371"
"75306","451.80000","37.65013","0.52162"
"75381","452.25000","37.68768","0.51915"
"75456","452.70000","37.72510","0.52066"
"75531","453.15000","37.76259","0.52597"
"75606","453.60000","37.80014","0.52587"
"75681","454.05000","37.83769","0.36545"
"75756","454.50000","37.87511","0.36278"
"75831","454.95000","37.91261","0.35871"
"75906","455.40000","37.95009","0.36348"
"75981","455.85000","37.98764","0.37593"
"76056","456.30000","38.02513","0.37566"
"76131","456.75000","38.06261","0.37589"
"76206","457.20000","38.10016","0.38421"
"76281","457.65000","38.13759","0.39048"
"76356","458.10000","38.17508","0.38857"
"76431","458.55000","38.21257","0.39308"
"76506","459.00000","38.25011","0.40288"
"76581","459.45000","38.28766","0.40042"
"76656","459.90000","38.32515","0.40543"
"76731","460.35000","38.36264","0.41685"
"76806","460.80000","38.40007","0.41587"
"76881","461.25000","38.43761","0.34138"
"76956","461.70000","38.47511","0.34831"
"77031","462.15000","38.51265","0.35223"
"77106","462.60000","38.55014","0.35225"
"77181","463.05000","38.58763","0.35406"
"77256","463.50000","38.62511","0.36025"
"77331","463.95000","38.66260","0.36530"
"77406","464.40000","38.70009","0.36515"
"77481","464.85000","38.73758","0.37029"
"77556","465.30000","38.77513","0.37857"
"77631","465.75000","38.81268","0.37779"
"77706","466.20000","38.85010","0.37905"
"77781","466.65000","38.88759","0.38452"
"77856","467.10000","38.92508","0.38834"
"77931","467.55000","38.96263","0.38924"
"78006","468.00000","39.00011","0.39257"
"78081","468.45000","39.03766","0.39712"
"78156","468.90000","39.07515","0.39782"
"78231","469.35000","39.11264","0.40257"
"78306","469.80000","39.15012","0.40792"
"78381","470.25000","39.18767","0.41083"
"78456","470.70000","39.22522","0.41553"
"78531","471.15000","39.26265","0.42108"
"78606","471.60000","39.30008","0.42331"
"78681","472.05000","39.33757","0.42924"
"78756","472.50000","39.37511","0.43485"
"78831","472.95000","39.41266","0.43738"
"78906","473.40000","39.45015","0.44119"
"78981","473.85000","39.48763","0.44469"
"79056","474.30000","39.52512","0.44621"
"79131","474.75000","39.56255","0.45003"
"79206","475.20000","39.60010","0.45259"
"79281","475.65000","39.63771","0.45592"
"79356","476.10000","39.67514","0.46008"
"79431","476.55000","39.71268","0.46293"
"79506","477.00000","39.75011","0.35885"
"79581","477.45000","39.78754","0.35719"
"79656","477.90000","39.82509","0.35407"
"79731","478.35000","39.86264","0.35697"
"79806","478.80000","39.90019","0.36266"
"79881","479.25000","39.93768","0.36319"
"79956","479.70000","39.97510","0.36299"
"80031","480.15000","40.01259","0.36865"
"80106","480.60000","40.05008","0.37504"
"80181","481.05000","40.08762","0.37431"
"80256","481.50000","40.12512","0.37856"
"80331","481.95000","40.16266","0.38398"
"80406","482.40000","40.20015","0.38592"
"80481","482.85000","40.23764","0.38709"
"80556","483.30000","40.27507","0.39186"
"80631","483.75000","40.31261","0.39441"
"80706","484.20000","40.35010","0.39616"
"80781","484.65000","40.38759","0.40011"
"80856","485.10000","40.42514","0.40483"
"80931","485.55000","40.46263","0.40730"
"81006","486.00000","40.50011","0.41162"
"81081","486.45000","40.53766","0.04500"
"81156","486.90000","40.57515","0.06719"
"81231","487.35000","40.61263","0.06717"
"81306","487.80000","40.65013","0.06544"
"81381","488.25000","40.68761","0.07318"
"81456","488.70000","40.72510","0.08003"
"81531","489.15000","40.76265","0.07105"
"81606","489.60000","40.80014","0.07443"
"81681","490.05000","40.83762","0.08095"
"81756","490.50000","40.87511","0.08017"
"81831","490.95000","40.91254","0.08519"
"81906","491.40000","40.95009","0.08840"
"81981","491.85000","40.98764","0.08508"
"82056","492.30000","41.02519","0.08859"
"82131","492.75000","41.06261","0.08969"
"82206","493.20000","41.10016","0.09039"
"82281","493.65000","41.13765","0.09536"
"82356","494.10000","41.17502","0.09828"
"82431","494.55000","41.21263","0.09922"
"82506","495.00000","41.25017","0.10211"
"82581","495.45000","41.28766","0.10475"
"82656","495.90000","41.32521","0.10500"
"82731","496.35000","41.36264","0.10915"
"82806","496.80000","41.40007","0.11483"
"82881","497.25000","41.43755","0.11644"
"82956","497.70000","41.47510","0.12214"
"83031","498.15000","41.51259","0.12629"
"83106","498.60000","41.55014","0.12776"
"83181","499.05000","41.58763","0.13140"
"83256","499.50000","41.62511","0.13493"
"83331","499.95000","41.66261","0.13695"
"83406","500.40000","41.70009","0.13986"
"83481","500.85000","41.73764","0.14255"
"83556","501.30000","41.77513","0.09763"
"83631","501.75000","41.81267","0.09900"
"83706","502.20000","41.85010","0.09670"
"83781","502.65000","41.88759","0.10056"
"83856","503.10000","41.92514","0.10211"
"83931","503.55000","41.96262","0.10626"
"84006","504.00000","42.00018","0.11141"
"84081","504.45000","42.03760","0.11706"
"84156","504.90000","42.07509","0.12373"
"84231","505.35000","42.11264","0.12365"
"84306","505.80000","42.15019","0.12643"
"84381","506.25000","42.18768","0.12877"
"84456","506.70000","42.22511","0.12916"
"84531","507.15000","42.26265","0.13251"
"84606","507.60000","42.30008","0.13455"
"84681","508.05000","42.33763","0.13683"
"84756","508.50000","42.37511","0.13946"
"84831","508.95000","42.41266","0.14200"
"84906","509.40000","42.45015","0.14339"
"84981","509.85000","42.48764","0.14548"
"85056","510.30000","42.52512","0.14783"
"85131","510.75000","42.56261","0.14847"
"85206","511.20000","42.60010","0.08142"
"85281","511.65000","42.63765","0.02945"
"85356","512.10000","42.67514","0.02904"
"85431","512.55000","42.71269","0.06236"
"85506","513.00000","42.75011","0.04421"
"85581","513.45000","42.78754","0.03502"
"85656","513.90000","42.82509","0.05242"
"85731","514.35000","42.86264","0.06136"
"85806","514.80000","42.90013","0.04136"
"85881","515.25000","42.93761","0.04150"
"85956","515.70000","42.97510","0.06362"
"86031","516.15000","43.01259","0.05791"
"86106","516.60000","43.05008","0.04578"
"86181","517.05000","43.08762","0.04982"
"86256","517.50000","43.12511","0.06842"
"86331","517.95000","43.16260","0.06050"
"86406","518.40000","43.20015","0.05155"
"86481","518.85000","43.23764","0.05647"
"86556","519.30000","43.27512","0.07071"
"86631","519.75000","43.31261","0.06821"
"86706","520.20000","43.35016","0.06059"
"86781","520.65000","43.38759","0.06310"
"86856","521.10000","43.42514","0.07237"
"86931","521.55000","43.46257","0.07492"
"87006","522.00000","43.50011","0.07069"
"87081","522.45000","43.53766","0.06951"
"87156","522.90000","43.57515","0.07468"
"87231","523.35000","43.61264","0.07767"
"87306","523.80000","43.65012","0.07674"
"87381","524.25000","43.68756","0.07548"
"87456","524.70000","43.72516","0.07709"
"87531","525.15000","43.76265","0.07953"
"87606","525.60000","43.80020","0.08163"
"87681","526.05000","43.83768","0.08089"
"87756","526.50000","43.87511","0.08033"
"87831","526.95000","43.91261","0.08199"
"87906","527.40000","43.95015","0.08439"
"87981","527.85000","43.98764","0.08480"
"88056","528.30000","44.02518","0.08473"
"88131","528.75000","44.06268","0.08522"
"88206","529.20000","44.10016","0.08629"
"88281","529.65000","44.13753","0.08773"
"88356","530.10000","44.17508","0.08822"
"88431","530.55000","44.21257","0.08827"
"88506","531.00000","44.25018","0.08778"
"88581","531.45000","44.28766","0.08780"
"88656","531.90000","44.32515","0.08734"
"88731","532.35000","44.36264","0.08661"
"88806","532.80000","44.40013","0.08629"
"88881","533.25000","44.43761","0.08607"
"88956","533.70000","44.47511","0.08467"
"89031","534.15000","44.51265","0.08496"
"89106","534.60000","44.55014","0.08478"
"89181","535.05000","44.58763","0.08495"
"89256","535.50000","44.62511","0.08545"
"89331","535.95000","44.66260","0.08526"
"89406","536.40000","44.70015","0.08443"
"89481","536.85000","44.73764","0.08429"
"89556","537.30000","44.77512","0.08361"
"89631","537.75000","44.81261","0.08363"
"89706","538.20000","44.85011","0.08429"
"89781","538.65000","44.88765","0.08466"
"89856","539.10000","44.92514","0.08475"
"89931","539.55000","44.96262","0.08559"
"90006","540.00000","45.00011","0.08640"
"90081","540.45000","45.03761","0.08687"
"90156","540.90000","45.07509","0.08789"
"90231","541.35000","45.11258","0.08872"
"90306","541.80000","45.15019","0.08938"
"90381","542.25000","45.18761","0.09031"
"90456","542.70000","45.22516","0.09205"
"90531","543.15000","45.26265","0.09261"
"90606","543.60000","45.30008","0.09382"
"90681","544.05000","45.33757","0.09510"
"90756","544.50000","45.37518","0.09578"
"90831","544.95000","45.41266","0.09714"
"90906","545.40000","45.45021","0.09175"
"90981","545.85000","45.48764","0.09387"
"91056","546.30000","45.52506","0.09450"
"91131","546.75000","45.56261","0.09584"
"91206","547.20000","45.60010","0.09818"
"91281","547.65000","45.63765","0.09948"
"91356","548.10000","45.67514","0.10044"
"91431","548.55000","45.71263","0.10291"
"91506","549.00000","45.75011","0.10389"
"91581","549.45000","45.78760","0.10555"
"91656","549.90000","45.82515","0.10707"
"91731","550.35000","45.86264","0.10869"
"91806","550.80000","45.90012","0.10988"
"91881","551.25000","45.93762","0.11202"
"91956","551.70000","45.97511","0.11435"
"92031","552.15000","46.01259","0.11605"
"92106","552.60000","46.05008","0.11800"
"92181","553.05000","46.08762","0.11911"
"92256","553.50000","46.12511","-0.01408"
"92310","553.82200","46.15190","-0.00514"