File: Trajectories_together/161218Specimen_RawData_7.csv
"","V1","V2","V3"
"1","End date","12/18/2016",""
"2","Specimen label","17AT_35",""
"3","Maximum Load","0.28481","N"
"4","Time","Extension","Load"
"5","(s)","(mm)","(N)"
"6","0.00000","0.00000","-0.00166"
"67","0.36600","0.03055","0.00009"
"128","0.73200","0.06110","0.00084"
"189","1.09800","0.09166","0.00213"
"250","1.46400","0.12215","0.00290"
"311","1.83000","0.15264","0.00346"
"372","2.19600","0.18314","0.00370"
"433","2.56200","0.21363","0.00418"
"494","2.92800","0.24418","0.00463"
"555","3.29400","0.27461","0.00522"
"616","3.66000","0.30511","0.00496"
"677","4.02600","0.33566","0.00514"
"738","4.39200","0.36621","0.00546"
"799","4.75800","0.39658","0.00577"
"860","5.12400","0.42714","0.00598"
"921","5.49000","0.45769","0.00596"
"982","5.85600","0.48812","0.00644"
"1043","6.22200","0.51867","0.00618"
"1104","6.58800","0.54917","0.00645"
"1165","6.95400","0.57966","0.00632"
"1226","7.32000","0.61015","0.00647"
"1287","7.68600","0.64064","0.00699"
"1348","8.05200","0.67114","0.00711"
"1409","8.41800","0.70163","0.00718"
"1470","8.78400","0.73218","0.00744"
"1531","9.15000","0.76262","0.00742"
"1592","9.51600","0.79317","0.00790"
"1653","9.88200","0.82360","0.00764"
"1714","10.24800","0.85409","0.00772"
"1775","10.61400","0.88459","0.00739"
"1836","10.98000","0.91514","0.00790"
"1897","11.34600","0.94563","0.00827"
"1958","11.71200","0.97612","0.00834"
"2019","12.07800","1.00668","0.00824"
"2080","12.44400","1.03717","0.00818"
"2141","12.81000","1.06760","0.00827"
"2202","13.17600","1.09815","0.00841"
"2263","13.54200","1.12865","0.00860"
"2324","13.90800","1.15908","0.00861"
"2385","14.27400","1.18969","0.00846"
"2446","14.64000","1.22012","0.00842"
"2507","15.00600","1.25062","0.00896"
"2568","15.37200","1.28117","0.00872"
"2629","15.73800","1.31166","0.00887"
"2690","16.10400","1.34210","0.00894"
"2751","16.47000","1.37265","0.00881"
"2812","16.83600","1.40320","0.00915"
"2873","17.20200","1.43363","0.00906"
"2934","17.56800","1.46419","0.00920"
"2995","17.93400","1.49462","0.00915"
"3056","18.30000","1.52511","0.00933"
"3117","18.66600","1.55560","0.00960"
"3178","19.03200","1.58610","0.00949"
"3239","19.39800","1.61665","0.00960"
"3300","19.76400","1.64714","0.00920"
"3361","20.13000","1.67769","0.00977"
"3422","20.49600","1.70813","0.00986"
"3483","20.86200","1.73862","0.00976"
"3544","21.22800","1.76917","0.00946"
"3605","21.59400","1.79967","0.00958"
"3666","21.96000","1.83010","0.00984"
"3727","22.32600","1.86071","0.00951"
"3788","22.69200","1.89114","0.00986"
"3849","23.05800","1.92158","0.00975"
"3910","23.42400","1.95219","0.00995"
"3971","23.79000","1.98268","0.00992"
"4032","24.15600","2.01311","0.00970"
"4093","24.52200","2.04367","0.00968"
"4154","24.88800","2.07422","0.00982"
"4215","25.25400","2.10459","0.00998"
"4276","25.62000","2.13514","0.01026"
"4337","25.98600","2.16564","0.01003"
"4398","26.35200","2.19613","0.00975"
"4459","26.71800","2.22662","0.01002"
"4520","27.08400","2.25717","0.01012"
"4581","27.45000","2.28767","0.00999"
"4642","27.81600","2.31810","0.00964"
"4703","28.18200","2.34865","0.00989"
"4764","28.54800","2.37914","0.00991"
"4825","28.91400","2.40964","0.01001"
"4886","29.28000","2.44013","0.01026"
"4947","29.64600","2.47068","0.01043"
"5008","30.01200","2.50112","0.01044"
"5069","30.37800","2.53167","0.01035"
"5130","30.74400","2.56210","0.00983"
"5191","31.11000","2.59259","0.00986"
"5252","31.47600","2.62321","0.00999"
"5313","31.84200","2.65364","0.01046"
"5374","32.20800","2.68413","0.01029"
"5435","32.57400","2.71462","0.01013"
"5496","32.94000","2.74518","0.01051"
"5557","33.30600","2.77555","0.01027"
"5618","33.67200","2.80616","0.01041"
"5679","34.03800","2.83665","0.01038"
"5740","34.40400","2.86715","0.00999"
"5801","34.77000","2.89764","0.01046"
"5862","35.13600","2.92813","0.01050"
"5923","35.50200","2.95868","0.01034"
"5984","35.86800","2.98912","0.01087"
"6045","36.23400","3.01967","0.01043"
"6106","36.60000","3.05010","0.01041"
"6167","36.96600","3.08066","0.01028"
"6228","37.33200","3.11115","0.01039"
"6289","37.69800","3.14164","0.01072"
"6350","38.06400","3.17213","0.01061"
"6411","38.43000","3.20263","0.01071"
"6472","38.79600","3.23312","0.01031"
"6533","39.16200","3.26361","0.01068"
"6594","39.52800","3.29416","0.01071"
"6655","39.89400","3.32466","0.01043"
"6716","40.26000","3.35509","0.01068"
"6777","40.62600","3.38564","0.01038"
"6838","40.99200","3.41619","0.01063"
"6899","41.35800","3.44663","0.01057"
"6960","41.72400","3.47718","0.01070"
"7021","42.09000","3.50767","0.01091"
"7082","42.45600","3.53811","0.01072"
"7143","42.82200","3.56866","0.01098"
"7204","43.18800","3.59915","0.01083"
"7265","43.55400","3.62958","0.01054"
"7326","43.92000","3.66008","0.01102"
"7387","44.28600","3.69063","0.01085"
"7448","44.65200","3.72112","0.01056"
"7509","45.01800","3.75161","0.01108"
"7570","45.38400","3.78217","0.01073"
"7631","45.75000","3.81260","0.01078"
"7692","46.11600","3.84309","0.01091"
"7753","46.48200","3.87364","0.01094"
"7814","46.84800","3.90414","0.01124"
"7875","47.21400","3.93463","0.01110"
"7936","47.58000","3.96518","0.01124"
"7997","47.94600","3.99562","0.01078"
"8058","48.31200","4.02611","0.01089"
"8119","48.67800","4.05672","0.01130"
"8180","49.04400","4.08715","0.01089"
"8241","49.41000","4.11765","0.01099"
"8302","49.77600","4.14820","0.01129"
"8363","50.14200","4.17863","0.01085"
"8424","50.50800","4.20900","0.01123"
"8485","50.87400","4.23968","0.01128"
"8546","51.24000","4.27017","0.01075"
"8607","51.60600","4.30060","0.01122"
"8668","51.97200","4.33115","0.01143"
"8729","52.33800","4.36165","0.01132"
"8790","52.70400","4.39214","0.01119"
"8851","53.07000","4.42257","0.01128"
"8912","53.43600","4.45318","0.01131"
"8973","53.80200","4.48362","0.01127"
"9034","54.16800","4.51417","0.01134"
"9095","54.53400","4.54460","0.01152"
"9156","54.90000","4.57515","0.01134"
"9217","55.26600","4.60565","0.01166"
"9278","55.63200","4.63614","0.01159"
"9339","55.99800","4.66663","0.01184"
"9400","56.36400","4.69713","0.01173"
"9461","56.73000","4.72768","0.01168"
"9522","57.09600","4.75811","0.01202"
"9583","57.46200","4.78860","0.01173"
"9644","57.82800","4.81916","0.01195"
"9705","58.19400","4.84965","0.01195"
"9766","58.56000","4.88008","0.01217"
"9827","58.92600","4.91063","0.01190"
"9888","59.29200","4.94113","0.01204"
"9949","59.65800","4.97162","0.01184"
"10010","60.02400","5.00217","0.01204"
"10071","60.39000","5.03266","0.01209"
"10132","60.75600","5.06316","0.01217"
"10193","61.12200","5.09359","0.01236"
"10254","61.48800","5.12420","0.01229"
"10315","61.85400","5.15458","0.01203"
"10376","62.22000","5.18519","0.01210"
"10437","62.58600","5.21562","0.01240"
"10498","62.95200","5.24611","0.01243"
"10559","63.31800","5.27661","0.01179"
"10620","63.68400","5.30716","0.01225"
"10681","64.05000","5.33765","0.01254"
"10742","64.41600","5.36814","0.01264"
"10803","64.78200","5.39870","0.01207"
"10864","65.14800","5.42913","0.01259"
"10925","65.51400","5.45956","0.01230"
"10986","65.88000","5.49017","0.01187"
"11047","66.24600","5.52061","0.01252"
"11108","66.61200","5.55110","0.01277"
"11169","66.97800","5.58165","0.01270"
"11230","67.34400","5.61214","0.01271"
"11291","67.71000","5.64258","0.01269"
"11352","68.07600","5.67319","0.01283"
"11413","68.44200","5.70362","0.01279"
"11474","68.80800","5.73412","0.01292"
"11535","69.17400","5.76467","0.01262"
"11596","69.54000","5.79516","0.01296"
"11657","69.90600","5.82559","0.01324"
"11718","70.27200","5.85615","0.01317"
"11779","70.63800","5.88664","0.01313"
"11840","71.00400","5.91713","0.01305"
"11901","71.37000","5.94768","0.01315"
"11962","71.73600","5.97812","0.01298"
"12023","72.10200","6.00861","0.01331"
"12084","72.46800","6.03916","0.01336"
"12145","72.83400","6.06965","0.01296"
"12206","73.20000","6.10015","0.01344"
"12267","73.56600","6.13058","0.01350"
"12328","73.93200","6.16119","0.01340"
"12389","74.29800","6.19157","0.01362"
"12450","74.66400","6.22212","0.01365"
"12511","75.03000","6.25267","0.01344"
"12572","75.39600","6.28316","0.01341"
"12633","75.76200","6.31359","0.01359"
"12694","76.12800","6.34415","0.01342"
"12755","76.49400","6.37464","0.01351"
"12816","76.86000","6.40507","0.01373"
"12877","77.22600","6.43563","0.01348"
"12938","77.59200","6.46618","0.01317"
"12999","77.95800","6.49661","0.01373"
"13060","78.32400","6.52716","0.01323"
"13121","78.69000","6.55772","0.01369"
"13182","79.05600","6.58809","0.01354"
"13243","79.42200","6.61870","0.01357"
"13304","79.78800","6.64913","0.01331"
"13365","80.15400","6.67963","0.01331"
"13426","80.52000","6.71012","0.01365"
"13487","80.88600","6.74067","0.01335"
"13548","81.25200","6.77111","0.01344"
"13609","81.61800","6.80160","0.01377"
"13670","81.98400","6.83221","0.01356"
"13731","82.35000","6.86258","0.01387"
"13792","82.71600","6.89314","0.01359"
"13853","83.08200","6.92363","0.01386"
"13914","83.44800","6.95412","0.01389"
"13975","83.81400","6.98461","0.01344"
"14036","84.18000","7.01517","0.01381"
"14097","84.54600","7.04560","0.01401"
"14158","84.91200","7.07609","0.01437"
"14219","85.27800","7.10670","0.01395"
"14280","85.64400","7.13714","0.01423"
"14341","86.01000","7.16763","0.01458"
"14402","86.37600","7.19812","0.01422"
"14463","86.74200","7.22873","0.01403"
"14524","87.10800","7.25905","0.01424"
"14585","87.47400","7.28960","0.01443"
"14646","87.84000","7.32015","0.01421"
"14707","88.20600","7.35058","0.01460"
"14768","88.57200","7.38114","0.01504"
"14829","88.93800","7.41163","0.01430"
"14890","89.30400","7.44212","0.01417"
"14951","89.67000","7.47262","0.01454"
"15012","90.03600","7.50323","0.01450"
"15073","90.40200","7.53360","0.01438"
"15134","90.76800","7.56415","0.01489"
"15195","91.13400","7.59471","0.01467"
"15256","91.50000","7.62514","0.01447"
"15317","91.86600","7.65563","0.01453"
"15378","92.23200","7.68618","0.01477"
"15439","92.59800","7.71662","0.01500"
"15500","92.96400","7.74711","0.01478"
"15561","93.33000","7.77772","0.01482"
"15622","93.69600","7.80816","0.01497"
"15683","94.06200","7.83865","0.01488"
"15744","94.42800","7.86914","0.01505"
"15805","94.79400","7.89969","0.01526"
"15866","95.16000","7.93013","0.01527"
"15927","95.52600","7.96068","0.01524"
"15988","95.89200","7.99111","0.01526"
"16049","96.25800","8.02160","0.01513"
"16110","96.62400","8.05221","0.01412"
"16171","96.99000","8.08265","0.01456"
"16232","97.35600","8.11314","0.01435"
"16293","97.72200","8.14357","0.01424"
"16354","98.08800","8.17419","0.01511"
"16415","98.45400","8.20462","0.01479"
"16476","98.82000","8.23517","0.01457"
"16537","99.18600","8.26566","0.01466"
"16598","99.55200","8.29610","0.01503"
"16659","99.91800","8.32665","0.01484"
"16720","100.28400","8.35714","0.01460"
"16781","100.65000","8.38763","0.01432"
"16842","101.01600","8.41813","0.01440"
"16903","101.38200","8.44868","0.01401"
"16964","101.74800","8.47911","0.01438"
"17025","102.11400","8.50961","0.01328"
"17086","102.48000","8.54016","0.01394"
"17147","102.84600","8.57065","0.01409"
"17208","103.21200","8.60114","0.01375"
"17269","103.57800","8.63169","0.01376"
"17330","103.94400","8.66219","0.01388"
"17391","104.31000","8.69256","0.01399"
"17452","104.67600","8.72311","0.01368"
"17513","105.04200","8.75367","0.01417"
"17574","105.40800","8.78410","0.01410"
"17635","105.77400","8.81465","0.01376"
"17696","106.14000","8.84514","0.01366"
"17757","106.50600","8.87564","0.01383"
"17818","106.87200","8.90619","0.01427"
"17879","107.23800","8.93668","0.01376"
"17940","107.60400","8.96706","0.01384"
"18001","107.97000","8.99767","0.01373"
"18062","108.33600","9.02816","0.01411"
"18123","108.70200","9.05865","0.01346"
"18184","109.06800","9.08909","0.01274"
"18245","109.43400","9.11964","0.01241"
"18306","109.80000","9.15013","0.01308"
"18367","110.16600","9.18056","0.01260"
"18428","110.53200","9.21117","0.01300"
"18489","110.89800","9.24167","0.01237"
"18550","111.26400","9.27216","0.01269"
"18611","111.63000","9.30265","0.01268"
"18672","111.99600","9.33315","0.01319"
"18733","112.36200","9.36358","0.01310"
"18794","112.72800","9.39413","0.01284"
"18855","113.09400","9.42462","0.01314"
"18916","113.46000","9.45512","0.01296"
"18977","113.82600","9.48567","0.01273"
"19038","114.19200","9.51616","0.01326"
"19099","114.55800","9.54659","0.01313"
"19160","114.92400","9.57709","0.01321"
"19221","115.29000","9.60770","0.01326"
"19282","115.65600","9.63807","0.01352"
"19343","116.02200","9.66869","0.01351"
"19404","116.38800","9.69918","0.01338"
"19465","116.75400","9.72961","0.01330"
"19526","117.12000","9.76010","0.01339"
"19587","117.48600","9.79060","0.01343"
"19648","117.85200","9.82115","0.01377"
"19709","118.21800","9.85158","0.01371"
"19770","118.58400","9.88219","0.01376"
"19831","118.95000","9.91263","0.01432"
"19892","119.31600","9.94312","0.01446"
"19953","119.68200","9.97367","0.01405"
"20014","120.04800","10.00410","0.01425"
"20075","120.41400","10.03460","0.01364"
"20136","120.78000","10.06515","0.01419"
"20197","121.14600","10.09570","0.01376"
"20258","121.51200","10.12613","0.01382"
"20319","121.87800","10.15669","0.01368"
"20380","122.24400","10.18712","0.01361"
"20441","122.61000","10.21761","0.01421"
"20502","122.97600","10.24817","0.01431"
"20563","123.34200","10.27866","0.01428"
"20624","123.70800","10.30909","0.01447"
"20685","124.07400","10.33964","0.01437"
"20746","124.44000","10.37020","0.01443"
"20807","124.80600","10.40057","0.01476"
"20868","125.17200","10.43118","0.01520"
"20929","125.53800","10.46161","0.01473"
"20990","125.90400","10.49217","0.01513"
"21051","126.27000","10.52260","0.01504"
"21112","126.63600","10.55321","0.01454"
"21173","127.00200","10.58358","0.01504"
"21234","127.36800","10.61414","0.01527"
"21295","127.73400","10.64463","0.01549"
"21356","128.10000","10.67512","0.01532"
"21417","128.46600","10.70561","0.01556"
"21478","128.83200","10.73617","0.01554"
"21539","129.19800","10.76666","0.01568"
"21600","129.56400","10.79715","0.01584"
"21661","129.93000","10.82765","0.01560"
"21722","130.29600","10.85814","0.01557"
"21783","130.66200","10.88863","0.01567"
"21844","131.02800","10.91912","0.01610"
"21905","131.39400","10.94968","0.01597"
"21966","131.76000","10.98011","0.01657"
"22027","132.12600","11.01060","0.01647"
"22088","132.49200","11.04121","0.01660"
"22149","132.85800","11.07159","0.01592"
"22210","133.22400","11.10214","0.01588"
"22271","133.59000","11.13263","0.01595"
"22332","133.95600","11.16313","0.01630"
"22393","134.32200","11.19362","0.01672"
"22454","134.68800","11.22417","0.01677"
"22515","135.05400","11.25466","0.01688"
"22576","135.42000","11.28515","0.01683"
"22637","135.78600","11.31565","0.01745"
"22698","136.15200","11.34614","0.01740"
"22759","136.51800","11.37663","0.01724"
"22820","136.88400","11.40718","0.01780"
"22881","137.25000","11.43762","0.01780"
"22942","137.61600","11.46811","0.01800"
"23003","137.98200","11.49866","0.01806"
"23064","138.34800","11.52915","0.01824"
"23125","138.71400","11.55959","0.01864"
"23186","139.08000","11.59014","0.01889"
"23247","139.44600","11.62063","0.01937"
"23308","139.81200","11.65113","0.01864"
"23369","140.17800","11.68162","0.01923"
"23430","140.54400","11.71217","0.01948"
"23491","140.91000","11.74254","0.01982"
"23552","141.27600","11.77316","0.01987"
"23613","141.64200","11.80365","0.02031"
"23674","142.00800","11.83408","0.01980"
"23735","142.37400","11.86464","0.02020"
"23796","142.74000","11.89519","0.02020"
"23857","143.10600","11.92562","0.01992"
"23918","143.47200","11.95611","0.02058"
"23979","143.83800","11.98673","0.02051"
"24040","144.20400","12.01710","0.02099"
"24101","144.57000","12.04765","0.02128"
"24162","144.93600","12.07814","0.02097"
"24223","145.30200","12.10864","0.02166"
"24284","145.66800","12.13913","0.02059"
"24345","146.03400","12.16962","0.02032"
"24406","146.40000","12.20017","0.02108"
"24467","146.76600","12.23061","0.01863"
"24528","147.13200","12.26116","0.01630"
"24589","147.49800","12.29165","0.01665"
"24650","147.86400","12.32214","0.01731"
"24711","148.23000","12.35270","0.01639"
"24772","148.59600","12.38319","0.01697"
"24833","148.96200","12.41362","0.01757"
"24894","149.32800","12.44417","0.01779"
"24955","149.69400","12.47461","0.01768"
"25016","150.06000","12.50510","0.01822"
"25077","150.42600","12.53565","0.01794"
"25138","150.79200","12.56621","0.01859"
"25199","151.15800","12.59664","0.01870"
"25260","151.52400","12.62713","0.01953"
"25321","151.89000","12.65762","0.01962"
"25382","152.25600","12.68812","0.01960"
"25443","152.62200","12.71861","0.01963"
"25504","152.98800","12.74916","0.02007"
"25565","153.35400","12.77959","0.02014"
"25626","153.72000","12.81009","0.01999"
"25687","154.08600","12.84064","0.01999"
"25748","154.45200","12.87113","0.01995"
"25809","154.81800","12.90163","0.01991"
"25870","155.18400","12.93218","0.02062"
"25931","155.55000","12.96261","0.02074"
"25992","155.91600","12.99304","0.02091"
"26053","156.28200","13.02366","0.02147"
"26114","156.64800","13.05415","0.02138"
"26175","157.01400","13.08458","0.02146"
"26236","157.38000","13.11519","0.02159"
"26297","157.74600","13.14569","0.02179"
"26358","158.11200","13.17612","0.02123"
"26419","158.47800","13.20673","0.02130"
"26480","158.84400","13.23716","0.02152"
"26541","159.21000","13.26760","0.02236"
"26602","159.57600","13.29815","0.02302"
"26663","159.94200","13.32870","0.02306"
"26724","160.30800","13.35908","0.02277"
"26785","160.67400","13.38963","0.02345"
"26846","161.04000","13.42018","0.02337"
"26907","161.40600","13.45061","0.02318"
"26968","161.77200","13.48116","0.02362"
"27029","162.13800","13.51160","0.02407"
"27090","162.50400","13.54215","0.02366"
"27151","162.87000","13.57258","0.02419"
"27212","163.23600","13.60314","0.02421"
"27273","163.60200","13.63363","0.02463"
"27334","163.96800","13.66412","0.02503"
"27395","164.33400","13.69467","0.02456"
"27456","164.70000","13.72511","0.02517"
"27517","165.06600","13.75560","0.02508"
"27578","165.43200","13.78615","0.02554"
"27639","165.79800","13.81664","0.02394"
"27700","166.16400","13.84708","0.02456"
"27761","166.53000","13.87769","0.02475"
"27822","166.89600","13.90812","0.02549"
"27883","167.26200","13.93856","0.02565"
"27944","167.62800","13.96917","0.02559"
"28005","167.99400","13.99966","0.02643"
"28066","168.36000","14.03015","0.02656"
"28127","168.72600","14.06064","0.02695"
"28188","169.09200","14.09114","0.02757"
"28249","169.45800","14.12157","0.02739"
"28310","169.82400","14.15218","0.02807"
"28371","170.19000","14.18262","0.02884"
"28432","170.55600","14.21311","0.02872"
"28493","170.92200","14.24360","0.02832"
"28554","171.28800","14.27415","0.02960"
"28615","171.65400","14.30459","0.02879"
"28676","172.02000","14.33514","0.02942"
"28737","172.38600","14.36569","0.02947"
"28798","172.75200","14.39612","0.02982"
"28859","173.11800","14.42662","0.02987"
"28920","173.48400","14.45717","0.03098"
"28981","173.85000","14.48760","0.03139"
"29042","174.21600","14.51803","0.03151"
"29103","174.58200","14.54871","0.03218"
"29164","174.94800","14.57920","0.03285"
"29225","175.31400","14.60957","0.03296"
"29286","175.68000","14.64019","0.03318"
"29347","176.04600","14.67068","0.03329"
"29408","176.41200","14.70111","0.03314"
"29469","176.77800","14.73166","0.03366"
"29530","177.14400","14.76216","0.03326"
"29591","177.51000","14.79259","0.03430"
"29652","177.87600","14.82320","0.03488"
"29713","178.24200","14.85363","0.03428"
"29774","178.60800","14.88413","0.03483"
"29835","178.97400","14.91468","0.03549"
"29896","179.34000","14.94511","0.03487"
"29957","179.70600","14.97560","0.03532"
"30018","180.07200","15.00616","0.03575"
"30079","180.43800","15.03665","0.03645"
"30140","180.80400","15.06714","0.03757"
"30201","181.17000","15.09763","0.03749"
"30262","181.53600","15.12813","0.03783"
"30323","181.90200","15.15862","0.03853"
"30384","182.26800","15.18911","0.03830"
"30445","182.63400","15.21967","0.03821"
"30506","183.00000","15.25016","0.03838"
"30567","183.36600","15.28059","0.03965"
"30628","183.73200","15.31120","0.04006"
"30689","184.09800","15.34164","0.04034"
"30750","184.46400","15.37207","0.04034"
"30811","184.83000","15.40268","0.04139"
"30872","185.19600","15.43317","0.04237"
"30933","185.56200","15.46361","0.04215"
"30994","185.92800","15.49416","0.04307"
"31055","186.29400","15.52465","0.04384"
"31116","186.66000","15.55508","0.04397"
"31177","187.02600","15.58570","0.02565"
"31238","187.39200","15.61613","0.02539"
"31299","187.75800","15.64668","0.02354"
"31360","188.12400","15.67717","0.02351"
"31421","188.49000","15.70761","0.02375"
"31482","188.85600","15.73810","0.02366"
"31543","189.22200","15.76865","0.02441"
"31604","189.58800","15.79914","0.02411"
"31665","189.95400","15.82958","0.02341"
"31726","190.32000","15.86013","0.02416"
"31787","190.68600","15.89062","0.02324"
"31848","191.05200","15.92118","0.02328"
"31909","191.41800","15.95161","0.02384"
"31970","191.78400","15.98216","0.02456"
"32031","192.15000","16.01259","0.02563"
"32092","192.51600","16.04309","0.02437"
"32153","192.88200","16.07370","0.02317"
"32214","193.24800","16.10419","0.02328"
"32275","193.61400","16.13462","0.02475"
"32336","193.98000","16.16518","0.02568"
"32397","194.34600","16.19567","0.02516"
"32458","194.71200","16.22604","0.02634"
"32519","195.07800","16.25671","0.02744"
"32580","195.44400","16.28715","0.02754"
"32641","195.81000","16.31764","0.02882"
"32702","196.17600","16.34819","0.02934"
"32763","196.54200","16.37862","0.02997"
"32824","196.90800","16.40906","0.03064"
"32885","197.27400","16.43961","0.03091"
"32946","197.64000","16.47016","0.03183"
"33007","198.00600","16.50060","0.03168"
"33068","198.37200","16.53115","0.03228"
"33129","198.73800","16.56164","0.03221"
"33190","199.10400","16.59213","0.03341"
"33251","199.47000","16.62263","0.03335"
"33312","199.83600","16.65318","0.03387"
"33373","200.20200","16.68361","0.03391"
"33434","200.56800","16.71410","0.03502"
"33495","200.93400","16.74466","0.03539"
"33556","201.30000","16.77515","0.03608"
"33617","201.66600","16.80558","0.03631"
"33678","202.03200","16.83619","0.03505"
"33739","202.39800","16.86669","0.03547"
"33800","202.76400","16.89712","0.03533"
"33861","203.13000","16.92767","0.03499"
"33922","203.49600","16.95811","0.03614"
"33983","203.86200","16.98860","0.03667"
"34044","204.22800","17.01915","0.03702"
"34105","204.59400","17.04964","0.03592"
"34166","204.96000","17.08008","0.03480"
"34227","205.32600","17.11063","0.03558"
"34288","205.69200","17.14118","0.03626"
"34349","206.05800","17.17155","0.03673"
"34410","206.42400","17.20217","0.03698"
"34471","206.79000","17.23266","0.03741"
"34532","207.15600","17.26309","0.03778"
"34593","207.52200","17.29364","0.03877"
"34654","207.88800","17.32414","0.03546"
"34715","208.25400","17.35469","0.03232"
"34776","208.62000","17.38506","0.03291"
"34837","208.98600","17.41562","0.03303"
"34898","209.35200","17.44617","0.03461"
"34959","209.71800","17.47660","0.03423"
"35020","210.08400","17.50715","0.03430"
"35081","210.45000","17.53765","0.03373"
"35142","210.81600","17.56814","0.03472"
"35203","211.18200","17.59863","0.03540"
"35264","211.54800","17.62912","0.03599"
"35325","211.91400","17.65956","0.03649"
"35386","212.28000","17.69017","0.03757"
"35447","212.64600","17.72066","0.03732"
"35508","213.01200","17.75109","0.03676"
"35569","213.37800","17.78165","0.03698"
"35630","213.74400","17.81214","0.03718"
"35691","214.11000","17.84257","0.03794"
"35752","214.47600","17.87312","0.03847"
"35813","214.84200","17.90368","0.03925"
"35874","215.20800","17.93411","0.04028"
"35935","215.57400","17.96466","0.04102"
"35996","215.94000","17.99516","0.04172"
"36057","216.30600","18.02559","0.04205"
"36118","216.67200","18.05614","0.04312"
"36179","217.03800","18.08663","0.04399"
"36240","217.40400","18.11713","0.04438"
"36301","217.77000","18.14762","0.04589"
"36362","218.13600","18.17811","0.04570"
"36423","218.50200","18.20860","0.04564"
"36484","218.86800","18.23915","0.04628"
"36545","219.23400","18.26965","0.04722"
"36606","219.60000","18.30014","0.04836"
"36667","219.96600","18.33063","0.04571"
"36728","220.33200","18.36113","0.04516"
"36789","220.69800","18.39168","0.04651"
"36850","221.06400","18.42211","0.04680"
"36911","221.43000","18.45267","0.04345"
"36972","221.79600","18.48316","0.04408"
"37033","222.16200","18.51359","0.04500"
"37094","222.52800","18.54414","0.04508"
"37155","222.89400","18.57469","0.04330"
"37216","223.26000","18.60507","0.04349"
"37277","223.62600","18.63568","0.04405"
"37338","223.99200","18.66611","0.04490"
"37399","224.35800","18.69661","0.04503"
"37460","224.72400","18.72710","0.04640"
"37521","225.09000","18.75765","0.04713"
"37582","225.45600","18.78814","0.04882"
"37643","225.82200","18.81864","0.04641"
"37704","226.18800","18.84919","0.04788"
"37765","226.55400","18.87962","0.04926"
"37826","226.92000","18.91011","0.05045"
"37887","227.28600","18.94067","0.04972"
"37948","227.65200","18.97116","0.05043"
"38009","228.01800","19.00159","0.05122"
"38070","228.38400","19.03214","0.05153"
"38131","228.75000","19.06264","0.04882"
"38192","229.11600","19.09307","0.04927"
"38253","229.48200","19.12368","0.04669"
"38314","229.84800","19.15417","0.04463"
"38375","230.21400","19.18461","0.04231"
"38436","230.58000","19.21516","0.04299"
"38497","230.94600","19.24565","0.04404"
"38558","231.31200","19.27603","0.04527"
"38619","231.67800","19.30664","0.04713"
"38680","232.04400","19.33719","0.04798"
"38741","232.41000","19.36757","0.04863"
"38802","232.77600","19.39817","0.04950"
"38863","233.14200","19.42867","0.04966"
"38924","233.50800","19.45910","0.05129"
"38985","233.87400","19.48965","0.05172"
"39046","234.24000","19.52015","0.05163"
"39107","234.60600","19.55058","0.05284"
"39168","234.97200","19.58113","0.05226"
"39229","235.33800","19.61163","0.05273"
"39290","235.70400","19.64212","0.05454"
"39351","236.07000","19.67261","0.05189"
"39412","236.43600","19.70316","0.05210"
"39473","236.80200","19.73365","0.05161"
"39534","237.16800","19.76415","0.05246"
"39595","237.53400","19.79464","0.05342"
"39656","237.90000","19.82513","0.05428"
"39717","238.26600","19.85563","0.05566"
"39778","238.63200","19.88618","0.05643"
"39839","238.99800","19.91667","0.05766"
"39900","239.36400","19.94704","0.05683"
"39961","239.73000","19.97766","0.05742"
"40022","240.09600","20.00815","0.05441"
"40083","240.46200","20.03864","0.05533"
"40144","240.82800","20.06913","0.05661"
"40205","241.19400","20.09963","0.05667"
"40266","241.56000","20.13012","0.05586"
"40327","241.92600","20.16061","0.05232"
"40388","242.29200","20.19116","0.05357"
"40449","242.65800","20.22160","0.05538"
"40510","243.02400","20.25215","0.05647"
"40571","243.39000","20.28258","0.05693"
"40632","243.75600","20.31314","0.05722"
"40693","244.12200","20.34363","0.05806"
"40754","244.48800","20.37412","0.05808"
"40815","244.85400","20.40467","0.05749"
"40876","245.22000","20.43517","0.05751"
"40937","245.58600","20.46566","0.05955"
"40998","245.95200","20.49609","0.05934"
"41059","246.31800","20.52664","0.05855"
"41120","246.68400","20.55720","0.05828"
"41181","247.05000","20.58769","0.05579"
"41242","247.41600","20.61812","0.05507"
"41303","247.78200","20.64867","0.05622"
"41364","248.14800","20.67911","0.05658"
"41425","248.51400","20.70954","0.05537"
"41486","248.88000","20.74015","0.05588"
"41547","249.24600","20.77065","0.05650"
"41608","249.61200","20.80114","0.05729"
"41669","249.97800","20.83163","0.05834"
"41730","250.34400","20.86218","0.05851"
"41791","250.71000","20.89256","0.05981"
"41852","251.07600","20.92311","0.05316"
"41913","251.44200","20.95372","0.05162"
"41974","251.80800","20.98409","0.05402"
"42035","252.17400","21.01471","0.05519"
"42096","252.54000","21.04514","0.05543"
"42157","252.90600","21.07557","0.05596"
"42218","253.27200","21.10612","0.05924"
"42279","253.63800","21.13667","0.05903"
"42340","254.00400","21.16711","0.05293"
"42401","254.37000","21.19760","0.04340"
"42462","254.73600","21.22816","0.04643"
"42523","255.10200","21.25858","0.04947"
"42584","255.46800","21.28914","0.04916"
"42645","255.83400","21.31963","0.04779"
"42706","256.20000","21.35012","0.03882"
"42767","256.56600","21.38062","0.03794"
"42828","256.93200","21.41117","0.03106"
"42889","257.29800","21.44160","0.02916"
"42950","257.66400","21.47216","0.02804"
"43011","258.03000","21.50265","0.03073"
"43072","258.39600","21.53314","0.03108"
"43133","258.76200","21.56357","0.03273"
"43194","259.12800","21.59407","0.03395"
"43255","259.49400","21.62474","0.03533"
"43316","259.86000","21.65511","0.03573"
"43377","260.22600","21.68566","0.03657"
"43438","260.59200","21.71616","0.03736"
"43499","260.95800","21.74659","0.03840"
"43560","261.32400","21.77714","0.03939"
"43621","261.69000","21.80763","0.03983"
"43682","262.05600","21.83813","0.04083"
"43743","262.42200","21.86862","0.04138"
"43804","262.78800","21.89917","0.04070"
"43865","263.15400","21.92960","0.04146"
"43926","263.52000","21.96016","0.04272"
"43987","263.88600","21.99065","0.04370"
"44048","264.25200","22.02108","0.04443"
"44109","264.61800","22.05163","0.04546"
"44170","264.98400","22.08219","0.04641"
"44231","265.35000","22.11268","0.04736"
"44292","265.71600","22.14305","0.04778"
"44353","266.08200","22.17367","0.04777"
"44414","266.44800","22.20416","0.04900"
"44475","266.81400","22.23465","0.04935"
"44536","267.18000","22.26514","0.05017"
"44597","267.54600","22.29570","0.05135"
"44658","267.91200","22.32607","0.05181"
"44719","268.27800","22.35662","0.05120"
"44780","268.64400","22.38712","0.05268"
"44841","269.01000","22.41761","0.05328"
"44902","269.37600","22.44816","0.05026"
"44963","269.74200","22.47865","0.04797"
"45024","270.10800","22.50908","0.04983"
"45085","270.47400","22.53964","0.04997"
"45146","270.84000","22.57019","0.05086"
"45207","271.20600","22.60056","0.05212"
"45268","271.57200","22.63112","0.05060"
"45329","271.93800","22.66161","0.05169"
"45390","272.30400","22.69210","0.05213"
"45451","272.67000","22.72260","0.05351"
"45512","273.03600","22.75315","0.05457"
"45573","273.40200","22.78364","0.05587"
"45634","273.76800","22.81413","0.05733"
"45695","274.13400","22.84468","0.05768"
"45756","274.50000","22.87512","0.05659"
"45817","274.86600","22.90561","0.05639"
"45878","275.23200","22.93610","0.05718"
"45939","275.59800","22.96666","0.05850"
"46000","275.96400","22.99709","0.06022"
"46061","276.33000","23.02758","0.06061"
"46122","276.69600","23.05813","0.06183"
"46183","277.06200","23.08862","0.06266"
"46244","277.42800","23.11918","0.06364"
"46305","277.79400","23.14973","0.06460"
"46366","278.16000","23.18010","0.06276"
"46427","278.52600","23.21060","0.06361"
"46488","278.89200","23.24121","0.06373"
"46549","279.25800","23.27158","0.05764"
"46610","279.62400","23.30213","0.05900"
"46671","279.99000","23.33269","0.06120"
"46732","280.35600","23.36306","0.06203"
"46793","280.72200","23.39361","0.06267"
"46854","281.08800","23.42416","0.06044"
"46915","281.45400","23.45460","0.05948"
"46976","281.82000","23.48515","0.05746"
"47037","282.18600","23.51570","0.05817"
"47098","282.55200","23.54613","0.06053"
"47159","282.91800","23.57663","0.06224"
"47220","283.28400","23.60712","0.06364"
"47281","283.65000","23.63761","0.06464"
"47342","284.01600","23.66811","0.06510"
"47403","284.38200","23.69866","0.06529"
"47464","284.74800","23.72915","0.06615"
"47525","285.11400","23.75964","0.06540"
"47586","285.48000","23.79013","0.06497"
"47647","285.84600","23.82063","0.06590"
"47708","286.21200","23.85112","0.05731"
"47769","286.57800","23.88161","0.05881"
"47830","286.94400","23.91216","0.06039"
"47891","287.31000","23.94260","0.06225"
"47952","287.67600","23.97315","0.06446"
"48013","288.04200","24.00370","0.06662"
"48074","288.40800","24.03407","0.06729"
"48135","288.77400","24.06463","0.06900"
"48196","289.14000","24.09518","0.07095"
"48257","289.50600","24.12561","0.07276"
"48318","289.87200","24.15611","0.07370"
"48379","290.23800","24.18666","0.07438"
"48440","290.60400","24.21709","0.07476"
"48501","290.97000","24.24764","0.07544"
"48562","291.33600","24.27814","0.07683"
"48623","291.70200","24.30863","0.07466"
"48684","292.06800","24.33912","0.07557"
"48745","292.43400","24.36968","0.05403"
"48806","292.80000","24.40017","0.05479"
"48867","293.16600","24.43066","0.05475"
"48928","293.53200","24.46115","0.05542"
"48989","293.89800","24.49165","0.05632"
"49050","294.26400","24.52208","0.05707"
"49111","294.63000","24.55263","0.05858"
"49172","294.99600","24.58318","0.06081"
"49233","295.36200","24.61362","0.06295"
"49294","295.72800","24.64411","0.06218"
"49355","296.09400","24.67472","0.06361"
"49416","296.46000","24.70509","0.06421"
"49477","296.82600","24.73565","0.06197"
"49538","297.19200","24.76620","0.06227"
"49599","297.55800","24.79663","0.06406"
"49660","297.92400","24.82712","0.06479"
"49721","298.29000","24.85762","0.06638"
"49782","298.65600","24.88817","0.06694"
"49843","299.02200","24.91860","0.06897"
"49904","299.38800","24.94916","0.07022"
"49965","299.75400","24.97959","0.07185"
"50026","300.12000","25.01014","0.07339"
"50087","300.48600","25.04063","0.07516"
"50148","300.85200","25.07113","0.07716"
"50209","301.21800","25.10162","0.07861"
"50270","301.58400","25.13211","0.08017"
"50331","301.95000","25.16266","0.08186"
"50392","302.31600","25.19310","0.08239"
"50453","302.68200","25.22365","0.08400"
"50514","303.04800","25.25414","0.08491"
"50575","303.41400","25.28464","0.08548"
"50636","303.78000","25.31513","0.08655"
"50697","304.14600","25.34568","0.08747"
"50758","304.51200","25.37605","0.08831"
"50819","304.87800","25.40667","0.08913"
"50880","305.24400","25.43716","0.08945"
"50941","305.61000","25.46759","0.08968"
"51002","305.97600","25.49814","0.09005"
"51063","306.34200","25.52864","0.09067"
"51124","306.70800","25.55913","0.09116"
"51185","307.07400","25.58962","0.09173"
"51246","307.44000","25.62017","0.09235"
"51307","307.80600","25.65061","0.07373"
"51368","308.17200","25.68110","0.06959"
"51429","308.53800","25.71165","0.07242"
"51490","308.90400","25.74215","0.07523"
"51551","309.27000","25.77264","0.07840"
"51612","309.63600","25.80319","0.08140"
"51673","310.00200","25.83362","0.08332"
"51734","310.36800","25.86411","0.08294"
"51795","310.73400","25.89467","0.08527"
"51856","311.10000","25.92510","0.08673"
"51917","311.46600","25.95565","0.08743"
"51978","311.83200","25.98615","0.08777"
"52039","312.19800","26.01670","0.08901"
"52100","312.56400","26.04707","0.08961"
"52161","312.93000","26.07763","0.09067"
"52222","313.29600","26.10818","0.09133"
"52283","313.66200","26.13867","0.09286"
"52344","314.02800","26.16916","0.09324"
"52405","314.39400","26.19965","0.09464"
"52466","314.76000","26.23014","0.09404"
"52527","315.12600","26.26058","0.09506"
"52588","315.49200","26.29113","0.09665"
"52649","315.85800","26.32162","0.09779"
"52710","316.22400","26.35212","0.09868"
"52771","316.59000","26.38267","0.09980"
"52832","316.95600","26.41310","0.10092"
"52893","317.32200","26.44360","0.10003"
"52954","317.68800","26.47415","0.10108"
"53015","318.05400","26.50464","0.10162"
"53076","318.42000","26.53513","0.09427"
"53137","318.78600","26.56569","0.09493"
"53198","319.15200","26.59612","0.09601"
"53259","319.51800","26.62661","0.09701"
"53320","319.88400","26.65716","0.09886"
"53381","320.25000","26.68766","0.09945"
"53442","320.61600","26.71809","0.10025"
"53503","320.98200","26.74864","0.10107"
"53564","321.34800","26.77913","0.09939"
"53625","321.71400","26.80957","0.09662"
"53686","322.08000","26.84018","0.09739"
"53747","322.44600","26.87067","0.09873"
"53808","322.81200","26.90110","0.09971"
"53869","323.17800","26.93160","0.10038"
"53930","323.54400","26.96215","0.10147"
"53991","323.91000","26.99264","0.10237"
"54052","324.27600","27.02308","0.10366"
"54113","324.64200","27.05369","0.10403"
"54174","325.00800","27.08412","0.10340"
"54235","325.37400","27.11461","0.10462"
"54296","325.74000","27.14511","0.10514"
"54357","326.10600","27.17560","0.10570"
"54418","326.47200","27.20615","0.10597"
"54479","326.83800","27.23664","0.10714"
"54540","327.20400","27.26714","0.10831"
"54601","327.57000","27.29757","0.10941"
"54662","327.93600","27.32818","0.11101"
"54723","328.30200","27.35862","0.11289"
"54784","328.66800","27.38917","0.11367"
"54845","329.03400","27.41960","0.11422"
"54906","329.40000","27.45015","0.11432"
"54967","329.76600","27.48058","0.10980"
"55028","330.13200","27.51114","0.11086"
"55089","330.49800","27.54163","0.11121"
"55150","330.86400","27.57212","0.11290"
"55211","331.23000","27.60268","0.11442"
"55272","331.59600","27.63317","0.11534"
"55333","331.96200","27.66366","0.11399"
"55394","332.32800","27.69410","0.10009"
"55455","332.69400","27.72465","0.10006"
"55516","333.06000","27.75508","0.10093"
"55577","333.42600","27.78563","0.10288"
"55638","333.79200","27.81612","0.10400"
"55699","334.15800","27.84662","0.10605"
"55760","334.52400","27.87711","0.10681"
"55821","334.89000","27.90766","0.10911"
"55882","335.25600","27.93815","0.11091"
"55943","335.62200","27.96865","0.11145"
"56004","335.98800","27.99920","0.11299"
"56065","336.35400","28.02963","0.11390"
"56126","336.72000","28.06013","0.11583"
"56187","337.08600","28.09068","0.11722"
"56248","337.45200","28.12111","0.11831"
"56309","337.81800","28.15160","0.11947"
"56370","338.18400","28.18221","0.12100"
"56431","338.55000","28.21265","0.12316"
"56492","338.91600","28.24308","0.12548"
"56553","339.28200","28.27369","0.12753"
"56614","339.64800","28.30413","0.12900"
"56675","340.01400","28.33462","0.12962"
"56736","340.38000","28.36511","0.12994"
"56797","340.74600","28.39566","0.11450"
"56858","341.11200","28.42610","0.11662"
"56919","341.47800","28.45665","0.12026"
"56980","341.84400","28.48714","0.12283"
"57041","342.21000","28.51764","0.12606"
"57102","342.57600","28.54819","0.12814"
"57163","342.94200","28.57862","0.12982"
"57224","343.30800","28.60911","0.10621"
"57285","343.67400","28.63967","0.10728"
"57346","344.04000","28.67016","0.10705"
"57407","344.40600","28.70059","0.10824"
"57468","344.77200","28.73114","0.10893"
"57529","345.13800","28.76163","0.11073"
"57590","345.50400","28.79213","0.11187"
"57651","345.87000","28.82256","0.11337"
"57712","346.23600","28.85317","0.11437"
"57773","346.60200","28.88367","0.11639"
"57834","346.96800","28.91410","0.11881"
"57895","347.33400","28.94465","0.12102"
"57956","347.70000","28.97514","0.12366"
"58017","348.06600","29.00558","0.12583"
"58078","348.43200","29.03613","0.12815"
"58139","348.79800","29.06668","0.11528"
"58200","349.16400","29.09712","0.11592"
"58261","349.53000","29.12767","0.11862"
"58322","349.89600","29.15816","0.12160"
"58383","350.26200","29.18859","0.12422"
"58444","350.62800","29.21915","0.12728"
"58505","350.99400","29.24964","0.13099"
"58566","351.36000","29.28013","0.13323"
"58627","351.72600","29.31062","0.13585"
"58688","352.09200","29.34118","0.13933"
"58749","352.45800","29.37161","0.14192"
"58810","352.82400","29.40210","0.14347"
"58871","353.19000","29.43265","0.14559"
"58932","353.55600","29.46315","0.14747"
"58993","353.92200","29.49358","0.14994"
"59054","354.28800","29.52413","0.15103"
"59115","354.65400","29.55463","0.15306"
"59176","355.02000","29.58512","0.15411"
"59237","355.38600","29.61567","0.15430"
"59298","355.75200","29.64616","0.14716"
"59359","356.11800","29.67659","0.14806"
"59420","356.48400","29.70721","0.15114"
"59481","356.85000","29.73764","0.15303"
"59542","357.21600","29.76807","0.15477"
"59603","357.58200","29.79863","0.15695"
"59664","357.94800","29.82918","0.15801"
"59725","358.31400","29.85955","0.15959"
"59786","358.68000","29.89017","0.16082"
"59847","359.04600","29.92066","0.16214"
"59908","359.41200","29.95109","0.16396"
"59969","359.77800","29.98164","0.16468"
"60030","360.14400","30.01208","0.16560"
"60091","360.51000","30.04263","0.16661"
"60152","360.87600","30.07312","0.16805"
"60213","361.24200","30.10367","0.16914"
"60274","361.60800","30.13416","0.17016"
"60335","361.97400","30.16466","0.17148"
"60396","362.34000","30.19515","0.17330"
"60457","362.70600","30.22564","0.17404"
"60518","363.07200","30.25614","0.17522"
"60579","363.43800","30.28663","0.17738"
"60640","363.80400","30.31718","0.17864"
"60701","364.17000","30.34761","0.17898"
"60762","364.53600","30.37817","0.17986"
"60823","364.90200","30.40866","0.17450"
"60884","365.26800","30.43909","0.17755"
"60945","365.63400","30.46964","0.17904"
"61006","366.00000","30.50020","0.17973"
"61067","366.36600","30.53063","0.17888"
"61128","366.73200","30.56118","0.16843"
"61189","367.09800","30.59161","0.16749"
"61250","367.46400","30.62211","0.16916"
"61311","367.83000","30.65272","0.16991"
"61372","368.19600","30.68315","0.16791"
"61433","368.56200","30.71364","0.16853"
"61494","368.92800","30.74414","0.16665"
"61555","369.29400","30.77469","0.16364"
"61616","369.66000","30.80512","0.14678"
"61677","370.02600","30.83562","0.14579"
"61738","370.39200","30.86611","0.13145"
"61799","370.75800","30.89666","0.13194"
"61860","371.12400","30.92709","0.13182"
"61921","371.49000","30.95765","0.12620"
"61982","371.85600","30.98820","0.12661"
"62043","372.22200","31.01863","0.12803"
"62104","372.58800","31.04918","0.12812"
"62165","372.95400","31.07968","0.12982"
"62226","373.32000","31.11011","0.12883"
"62287","373.68600","31.14066","0.13007"
"62348","374.05200","31.17115","0.12994"
"62409","374.41800","31.20159","0.12336"
"62470","374.78400","31.23214","0.12460"
"62531","375.15000","31.26269","0.12593"
"62592","375.51600","31.29306","0.12888"
"62653","375.88200","31.32368","0.13134"
"62714","376.24800","31.35417","0.13364"
"62775","376.61400","31.38466","0.13732"
"62836","376.98000","31.41515","0.14009"
"62897","377.34600","31.44564","0.14224"
"62958","377.71200","31.47608","0.14487"
"63019","378.07800","31.50663","0.14712"
"63080","378.44400","31.53712","0.14954"
"63141","378.81000","31.56756","0.15135"
"63202","379.17600","31.59817","0.15259"
"63263","379.54200","31.62866","0.15408"
"63324","379.90800","31.65916","0.15553"
"63385","380.27400","31.68959","0.15790"
"63446","380.64000","31.72020","0.15936"
"63507","381.00600","31.75064","0.16052"
"63568","381.37200","31.78113","0.16211"
"63629","381.73800","31.81168","0.16405"
"63690","382.10400","31.84217","0.16640"
"63751","382.47000","31.87260","0.16728"
"63812","382.83600","31.90315","0.16855"
"63873","383.20200","31.93365","0.17045"
"63934","383.56800","31.96408","0.17179"
"63995","383.93400","31.99463","0.17225"
"64056","384.30000","32.02512","0.17373"
"64117","384.66600","32.05556","0.17560"
"64178","385.03200","32.08617","0.17710"
"64239","385.39800","32.11666","0.17926"
"64300","385.76400","32.14710","0.18055"
"64361","386.13000","32.17771","0.18190"
"64422","386.49600","32.20820","0.18389"
"64483","386.86200","32.23857","0.18483"
"64544","387.22800","32.26919","0.18609"
"64605","387.59400","32.29968","0.18814"
"64666","387.96000","32.33012","0.18998"
"64727","388.32600","32.36061","0.19181"
"64788","388.69200","32.39110","0.19292"
"64849","389.05800","32.42165","0.19352"
"64910","389.42400","32.45208","0.19419"
"64971","389.79000","32.48264","0.19322"
"65032","390.15600","32.51313","0.19300"
"65093","390.52200","32.54362","0.19489"
"65154","390.88800","32.57411","0.19662"
"65215","391.25400","32.60467","0.19774"
"65276","391.62000","32.63510","0.18162"
"65337","391.98600","32.66565","0.18135"
"65398","392.35200","32.69615","0.18314"
"65459","392.71800","32.72658","0.18554"
"65520","393.08400","32.75719","0.18757"
"65581","393.45000","32.78769","0.18851"
"65642","393.81600","32.81812","0.19092"
"65703","394.18200","32.84867","0.19238"
"65764","394.54800","32.87916","0.18904"
"65825","394.91400","32.90953","0.18861"
"65886","395.28000","32.94015","0.18742"
"65947","395.64600","32.97064","0.18778"
"66008","396.01200","33.00107","0.18924"
"66069","396.37800","33.03168","0.19056"
"66130","396.74400","33.06211","0.19061"
"66191","397.11000","33.09261","0.19124"
"66252","397.47600","33.12310","0.19286"
"66313","397.84200","33.15365","0.19440"
"66374","398.20800","33.18409","0.19562"
"66435","398.57400","33.21464","0.19610"
"66496","398.94000","33.24513","0.19771"
"66557","399.30600","33.27563","0.19861"
"66618","399.67200","33.30612","0.20004"
"66679","400.03800","33.33667","0.20178"
"66740","400.40400","33.36716","0.20282"
"66801","400.77000","33.39759","0.20332"
"66862","401.13600","33.42821","0.20419"
"66923","401.50200","33.45858","0.20531"
"66984","401.86800","33.48907","0.20602"
"67045","402.23400","33.51968","0.20684"
"67106","402.60000","33.55012","0.20744"
"67167","402.96600","33.58061","0.20813"
"67228","403.33200","33.61116","0.20914"
"67289","403.69800","33.64165","0.20949"
"67350","404.06400","33.67203","0.20873"
"67411","404.43000","33.70264","0.20975"
"67472","404.79600","33.73313","0.21069"
"67533","405.16200","33.76363","0.21119"
"67594","405.52800","33.79412","0.21191"
"67655","405.89400","33.82461","0.21310"
"67716","406.26000","33.85511","0.21317"
"67777","406.62600","33.88566","0.21456"
"67838","406.99200","33.91615","0.21577"
"67899","407.35800","33.94659","0.21686"
"67960","407.72400","33.97713","0.21799"
"68021","408.09000","34.00763","0.21986"
"68082","408.45600","34.03818","0.22079"
"68143","408.82200","34.06861","0.22212"
"68204","409.18800","34.09917","0.22199"
"68265","409.55400","34.12960","0.20742"
"68326","409.92000","34.16009","0.20819"
"68387","410.28600","34.19070","0.20914"
"68448","410.65200","34.22113","0.21052"
"68509","411.01800","34.25163","0.21148"
"68570","411.38400","34.28212","0.21385"
"68631","411.75000","34.31267","0.21491"
"68692","412.11600","34.34305","0.21651"
"68753","412.48200","34.37366","0.21743"
"68814","412.84800","34.40415","0.21955"
"68875","413.21400","34.43459","0.22046"
"68936","413.58000","34.46514","0.22157"
"68997","413.94600","34.49569","0.22119"
"69058","414.31200","34.52607","0.22048"
"69119","414.67800","34.55656","0.22159"
"69180","415.04400","34.58717","0.22303"
"69241","415.41000","34.61760","0.22434"
"69302","415.77600","34.64816","0.22622"
"69363","416.14200","34.67865","0.22786"
"69424","416.50800","34.70914","0.22861"
"69485","416.87400","34.73963","0.23100"
"69546","417.24000","34.77018","0.23347"
"69607","417.60600","34.80062","0.23547"
"69668","417.97200","34.83117","0.23749"
"69729","418.33800","34.86166","0.23908"
"69790","418.70400","34.89209","0.24067"
"69851","419.07000","34.92265","0.24189"
"69912","419.43600","34.95320","0.24335"
"69973","419.80200","34.98363","0.24471"
"70034","420.16800","35.01413","0.24578"
"70095","420.53400","35.04468","0.24668"
"70156","420.90000","35.07511","0.24792"
"70217","421.26600","35.10561","0.24934"
"70278","421.63200","35.13615","0.25102"
"70339","421.99800","35.16671","0.25213"
"70400","422.36400","35.19708","0.25337"
"70461","422.73000","35.22757","0.25485"
"70522","423.09600","35.25819","0.25598"
"70583","423.46200","35.28862","0.25744"
"70644","423.82800","35.31911","0.25876"
"70705","424.19400","35.34966","0.26103"
"70766","424.56000","35.38010","0.26213"
"70827","424.92600","35.41059","0.26363"
"70888","425.29200","35.44114","0.26500"
"70949","425.65800","35.47164","0.26635"
"71010","426.02400","35.50219","0.26711"
"71071","426.39000","35.53268","0.26787"
"71132","426.75600","35.56305","0.26987"
"71193","427.12200","35.59361","0.27058"
"71254","427.48800","35.62416","0.27214"
"71315","427.85400","35.65465","0.27353"
"71376","428.22000","35.68514","0.27574"
"71437","428.58600","35.71564","0.27784"
"71498","428.95200","35.74619","0.28059"
"71559","429.31800","35.77656","0.28330"
"71620","429.68400","35.80717","0.28101"
"71681","430.05000","35.83767","0.01757"
"71742","430.41600","35.86816","0.00986"
"71803","430.78200","35.89865","0.01360"
"71864","431.14800","35.92914","0.01194"
"71925","431.51400","35.95958","0.00906"
"71986","431.88000","35.99013","0.01241"
"72047","432.24600","36.02068","0.01048"
"72108","432.61200","36.05112","0.00953"
"72169","432.97800","36.08167","0.01274"
"72230","433.34400","36.11210","0.00961"
"72291","433.71000","36.14259","0.01107"
"72352","434.07600","36.17315","0.01245"
"72413","434.44200","36.20370","0.00917"
"72474","434.80800","36.23407","0.01309"
"72535","435.17400","36.26463","0.01066"
"72596","435.54000","36.29512","0.00967"
"72657","435.90600","36.32561","0.01318"
"72718","436.27200","36.35616","0.00931"
"72779","436.63800","36.38665","0.01036"
"72840","437.00400","36.41714","0.01246"
"72901","437.37000","36.44758","0.01017"
"72962","437.73600","36.47813","0.01025"
"73023","438.10200","36.50868","0.01221"
"73084","438.46800","36.53912","0.01029"
"73145","438.83400","36.56961","0.01050"
"73206","439.20000","36.60016","0.01300"
"73267","439.56600","36.63060","0.00976"
"73328","439.93200","36.66109","0.01146"
"73389","440.29800","36.69164","0.01264"
"73450","440.66400","36.72208","0.01038"
"73511","441.03000","36.75269","0.01227"
"73572","441.39600","36.78312","0.01158"
"73633","441.76200","36.81361","0.01072"
"73694","442.12800","36.84410","0.01168"
"73755","442.49400","36.87466","0.01279"
"73816","442.86000","36.90509","0.01075"
"73877","443.22600","36.93564","0.01279"
"73938","443.59200","36.96619","0.01274"
"73999","443.95800","36.99662","0.01147"
"74060","444.32400","37.02712","0.01289"
"74121","444.69000","37.05767","0.01377"
"74182","445.05600","37.08816","0.01173"
"74243","445.42200","37.11860","0.01305"
"74304","445.78800","37.14915","0.01412"
"74365","446.15400","37.17964","0.01211"
"74426","446.52000","37.21014","0.01275"
"74487","446.88600","37.24063","0.01472"
"74548","447.25200","37.27118","0.01323"
"74609","447.61800","37.30162","0.01333"
"74670","447.98400","37.33211","0.01577"
"74731","448.35000","37.36272","0.01370"
"74792","448.71600","37.39303","0.01398"
"74853","449.08200","37.42365","0.01573"
"74914","449.44800","37.45414","0.01466"
"74975","449.81400","37.48457","0.01478"
"75036","450.18000","37.51512","0.01542"
"75097","450.54600","37.54567","0.01590"
"75158","450.91200","37.57611","0.01636"
"75219","451.27800","37.60660","0.01547"
"75280","451.64400","37.63721","0.01619"
"75312","451.83200","37.65282","0.01598"