File: Trajectories_together/161223Specimen_RawData_5.csv
"","V1","V2","V3"
"1","End date","12/23/2016",""
"2","Specimen label","22CG_76",""
"3","Maximum Load","0.01683","N"
"4","Time","Extension","Load"
"5","(s)","(mm)","(N)"
"6","0.00000","0.00000","-0.00026"
"70","0.38400","0.03223","0.00006"
"134","0.76800","0.06427","0.00092"
"198","1.15200","0.09620","0.00141"
"262","1.53600","0.12825","0.00189"
"326","1.92000","0.16024","0.00196"
"390","2.30400","0.19222","0.00186"
"454","2.68800","0.22421","0.00261"
"518","3.07200","0.25626","0.00279"
"582","3.45600","0.28819","0.00281"
"646","3.84000","0.32017","0.00355"
"710","4.22400","0.35222","0.00334"
"774","4.60800","0.38421","0.00357"
"838","4.99200","0.41619","0.00391"
"902","5.37600","0.44818","0.00353"
"966","5.76000","0.48023","0.00365"
"1030","6.14400","0.51222","0.00415"
"1094","6.52800","0.54420","0.00417"
"1158","6.91200","0.57619","0.00441"
"1222","7.29600","0.60824","0.00421"
"1286","7.68000","0.64017","0.00469"
"1350","8.06400","0.67215","0.00461"
"1414","8.44800","0.70420","0.00470"
"1478","8.83200","0.73631","0.00484"
"1542","9.21600","0.76818","0.00488"
"1606","9.60000","0.80022","0.00481"
"1670","9.98400","0.83227","0.00499"
"1734","10.36800","0.86420","0.00487"
"1798","10.75200","0.89619","0.00515"
"1862","11.13600","0.92823","0.00494"
"1926","11.52000","0.96016","0.00519"
"1990","11.90400","0.99215","0.00535"
"2054","12.28800","1.02419","0.00547"
"2118","12.67200","1.05618","0.00556"
"2182","13.05600","1.08823","0.00560"
"2246","13.44000","1.12016","0.00571"
"2310","13.82400","1.15226","0.00545"
"2374","14.20800","1.18425","0.00573"
"2438","14.59200","1.21618","0.00563"
"2502","14.97600","1.24823","0.00532"
"2566","15.36000","1.28021","0.00583"
"2630","15.74400","1.31220","0.00529"
"2694","16.12800","1.34419","0.00583"
"2758","16.51200","1.37618","0.00559"
"2822","16.89600","1.40822","0.00581"
"2886","17.28000","1.44015","0.00591"
"2950","17.66400","1.47220","0.00602"
"3014","18.04800","1.50424","0.00601"
"3078","18.43200","1.53623","0.00670"
"3142","18.81600","1.56816","0.00650"
"3206","19.20000","1.60021","0.00636"
"3270","19.58400","1.63225","0.00638"
"3334","19.96800","1.66418","0.00595"
"3398","20.35200","1.69617","0.00621"
"3462","20.73600","1.72816","0.00653"
"3526","21.12000","1.76020","0.00639"
"3590","21.50400","1.79219","0.00668"
"3654","21.88800","1.82424","0.00664"
"3718","22.27200","1.85623","0.00649"
"3782","22.65600","1.88815","0.00681"
"3846","23.04000","1.92020","0.00661"
"3910","23.42400","1.95219","0.00694"
"3974","23.80800","1.98418","0.00671"
"4038","24.19200","2.01616","0.00661"
"4102","24.57600","2.04821","0.00648"
"4166","24.96000","2.08026","0.00663"
"4230","25.34400","2.11219","0.00703"
"4294","25.72800","2.14417","0.00699"
"4358","26.11200","2.17622","0.00685"
"4422","26.49600","2.20821","0.00697"
"4486","26.88000","2.24019","0.00717"
"4550","27.26400","2.27218","0.00669"
"4614","27.64800","2.30429","0.00707"
"4678","28.03200","2.33616","0.00687"
"4742","28.41600","2.36820","0.00708"
"4806","28.80000","2.40019","0.00667"
"4870","29.18400","2.43224","0.00727"
"4934","29.56800","2.46417","0.00708"
"4998","29.95200","2.49615","0.00687"
"5062","30.33600","2.52826","0.00749"
"5126","30.72000","2.56013","0.00756"
"5190","31.10400","2.59218","0.00713"
"5254","31.48800","2.62422","0.00722"
"5318","31.87200","2.65615","0.00697"
"5382","32.25600","2.68820","0.00737"
"5446","32.64000","2.72024","0.00800"
"5510","33.02400","2.75223","0.00709"
"5574","33.40800","2.78416","0.00773"
"5638","33.79200","2.81621","0.00714"
"5702","34.17600","2.84819","0.00741"
"5766","34.56000","2.88018","0.00723"
"5830","34.94400","2.91217","0.00761"
"5894","35.32800","2.94422","0.00754"
"5958","35.71200","2.97620","0.00697"
"6022","36.09600","3.00813","0.00743"
"6086","36.48000","3.04018","0.00758"
"6150","36.86400","3.07223","0.00784"
"6214","37.24800","3.10421","0.00757"
"6278","37.63200","3.13620","0.00782"
"6342","38.01600","3.16819","0.00749"
"6406","38.40000","3.20029","0.00737"
"6470","38.78400","3.23216","0.00740"
"6534","39.16800","3.26421","0.00761"
"6598","39.55400","3.29644","0.00762"
"6662","39.93800","3.32836","0.00771"
"6726","40.32200","3.36035","0.00728"
"6790","40.70600","3.39240","0.00786"
"6854","41.09000","3.42439","0.00750"
"6918","41.47400","3.45631","0.00811"
"6982","41.85800","3.48836","0.00797"
"7046","42.24200","3.52041","0.00778"
"7110","42.62600","3.55234","0.00725"
"7174","43.01000","3.58432","0.00784"
"7238","43.39400","3.61637","0.00763"
"7302","43.77800","3.64842","0.00767"
"7366","44.16200","3.68034","0.00771"
"7430","44.54600","3.71239","0.00793"
"7494","44.93000","3.74432","0.00774"
"7558","45.31400","3.77643","0.00768"
"7622","45.69800","3.80835","0.00776"
"7686","46.08200","3.84040","0.00773"
"7750","46.46600","3.87239","0.00787"
"7814","46.85000","3.90438","0.00808"
"7878","47.23400","3.93636","0.00786"
"7942","47.61800","3.96835","0.00791"
"8006","48.00200","4.00040","0.00775"
"8070","48.38600","4.03233","0.00785"
"8134","48.77000","4.06437","0.00801"
"8198","49.15400","4.09636","0.00822"
"8262","49.53800","4.12835","0.00773"
"8326","49.92200","4.16033","0.00841"
"8390","50.30600","4.19244","0.00838"
"8454","50.69000","4.22437","0.00834"
"8518","51.07400","4.25630","0.00823"
"8582","51.45800","4.28840","0.00808"
"8646","51.84200","4.32039","0.00813"
"8710","52.22600","4.35232","0.00803"
"8774","52.61000","4.38443","0.00774"
"8838","52.99400","4.41635","0.00837"
"8902","53.37800","4.44840","0.00842"
"8966","53.76200","4.48033","0.00830"
"9030","54.14600","4.51238","0.00811"
"9094","54.53000","4.54436","0.00805"
"9158","54.91400","4.57635","0.00851"
"9222","55.29800","4.60840","0.00809"
"9286","55.68200","4.64039","0.00811"
"9350","56.06600","4.67237","0.00863"
"9414","56.45000","4.70436","0.00869"
"9478","56.83400","4.73641","0.00828"
"9542","57.21800","4.76839","0.00806"
"9606","57.60200","4.80038","0.00886"
"9670","57.98600","4.83231","0.00834"
"9734","58.37000","4.86436","0.00834"
"9798","58.75400","4.89640","0.00824"
"9862","59.13800","4.92833","0.00837"
"9926","59.52200","4.96038","0.00817"
"9990","59.90600","4.99243","0.00824"
"10054","60.29000","5.02429","0.00832"
"10118","60.67400","5.05634","0.00868"
"10182","61.05800","5.08839","0.00836"
"10246","61.44200","5.12032","0.00854"
"10310","61.82600","5.15236","0.00822"
"10374","62.21000","5.18441","0.00840"
"10438","62.59400","5.21634","0.00847"
"10502","62.97800","5.24832","0.00834"
"10566","63.36200","5.28043","0.00873"
"10630","63.74600","5.31236","0.00853"
"10694","64.13000","5.34435","0.00875"
"10758","64.51400","5.37633","0.00826"
"10822","64.89800","5.40844","0.00852"
"10886","65.28200","5.44043","0.00830"
"10950","65.66600","5.47236","0.00829"
"11014","66.05000","5.50440","0.00811"
"11078","66.43400","5.53639","0.00823"
"11142","66.81800","5.56838","0.00886"
"11206","67.20200","5.60037","0.00882"
"11270","67.58600","5.63241","0.00856"
"11334","67.97000","5.66440","0.00870"
"11398","68.35400","5.69633","0.00851"
"11462","68.73800","5.72837","0.00847"
"11526","69.12200","5.76042","0.00822"
"11590","69.50600","5.79235","0.00852"
"11654","69.89000","5.82440","0.00775"
"11718","70.27400","5.85638","0.00827"
"11782","70.65800","5.88837","0.00832"
"11846","71.04200","5.92030","0.00830"
"11910","71.42600","5.95235","0.00868"
"11974","71.81000","5.98439","0.00826"
"12038","72.19400","6.01638","0.00823"
"12102","72.57800","6.04831","0.00816"
"12166","72.96200","6.08042","0.00861"
"12230","73.34600","6.11240","0.00836"
"12294","73.73000","6.14433","0.00862"
"12358","74.11400","6.17638","0.00844"
"12422","74.49800","6.20837","0.00851"
"12486","74.88200","6.24035","0.00874"
"12550","75.26600","6.27234","0.00853"
"12614","75.65000","6.30439","0.00832"
"12678","76.03400","6.33638","0.00879"
"12742","76.41800","6.36836","0.00872"
"12806","76.80200","6.40035","0.00851"
"12870","77.18600","6.43234","0.00868"
"12934","77.57000","6.46432","0.00860"
"12998","77.95400","6.49637","0.00843"
"13062","78.33800","6.52836","0.00846"
"13126","78.72200","6.56041","0.00839"
"13190","79.10600","6.59233","0.00877"
"13254","79.49000","6.62432","0.00853"
"13318","79.87400","6.65637","0.00850"
"13382","80.25800","6.68836","0.00838"
"13446","80.64200","6.72034","0.00827"
"13510","81.02600","6.75239","0.00809"
"13574","81.41000","6.78438","0.00881"
"13638","81.79400","6.81631","0.00869"
"13702","82.17800","6.84841","0.00860"
"13766","82.56200","6.88040","0.00888"
"13830","82.94600","6.91233","0.00811"
"13894","83.33000","6.94437","0.00840"
"13958","83.71400","6.97642","0.00821"
"14022","84.09800","7.00829","0.00818"
"14086","84.48200","7.04034","0.00867"
"14150","84.86600","7.07244","0.00859"
"14214","85.25000","7.10437","0.00835"
"14278","85.63400","7.13636","0.00831"
"14342","86.01800","7.16835","0.00852"
"14406","86.40200","7.20033","0.00871"
"14470","86.78600","7.23238","0.00870"
"14534","87.17000","7.26437","0.00868"
"14598","87.55400","7.29636","0.00867"
"14662","87.93800","7.32840","0.00889"
"14726","88.32200","7.36039","0.00830"
"14790","88.70600","7.39232","0.00849"
"14854","89.09000","7.42442","0.00828"
"14918","89.47400","7.45641","0.00842"
"14982","89.85800","7.48834","0.00852"
"15046","90.24200","7.52039","0.00881"
"15110","90.62600","7.55243","0.00849"
"15174","91.01000","7.58430","0.00847"
"15238","91.39400","7.61635","0.00846"
"15302","91.77800","7.64846","0.00859"
"15366","92.16200","7.68032","0.00859"
"15430","92.54600","7.71231","0.00806"
"15494","92.93000","7.74442","0.00871"
"15558","93.31400","7.77635","0.00829"
"15622","93.69800","7.80833","0.00826"
"15686","94.08200","7.84038","0.00870"
"15750","94.46600","7.87237","0.00848"
"15814","94.85000","7.90436","0.00861"
"15878","95.23400","7.93634","0.00862"
"15942","95.61800","7.96839","0.00881"
"16006","96.00200","8.00038","0.00857"
"16070","96.38600","8.03236","0.00875"
"16134","96.77000","8.06435","0.00852"
"16198","97.15400","8.09634","0.00852"
"16262","97.53800","8.12833","0.00875"
"16326","97.92200","8.16031","0.00873"
"16390","98.30600","8.19242","0.00856"
"16454","98.69000","8.22441","0.00874"
"16518","99.07400","8.25634","0.00891"
"16582","99.45800","8.28832","0.00860"
"16646","99.84200","8.32037","0.00893"
"16710","100.22600","8.35242","0.00893"
"16774","100.61000","8.38435","0.00876"
"16838","100.99400","8.41639","0.00907"
"16902","101.37800","8.44844","0.00882"
"16966","101.76200","8.48031","0.00849"
"17030","102.14600","8.51236","0.00909"
"17094","102.53000","8.54440","0.00896"
"17158","102.91400","8.57633","0.00907"
"17222","103.29800","8.60832","0.00888"
"17286","103.68200","8.64042","0.00885"
"17350","104.06600","8.67235","0.00872"
"17414","104.45000","8.70440","0.00906"
"17478","104.83400","8.73639","0.00890"
"17542","105.21800","8.76837","0.00839"
"17606","105.60200","8.80036","0.00910"
"17670","105.98600","8.83235","0.00886"
"17734","106.37000","8.86440","0.00862"
"17798","106.75400","8.89638","0.00901"
"17862","107.13800","8.92837","0.00852"
"17926","107.52200","8.96036","0.00898"
"17990","107.90600","8.99235","0.00865"
"18054","108.29000","9.02439","0.00917"
"18118","108.67400","9.05638","0.00884"
"18182","109.05800","9.08837","0.00876"
"18246","109.44200","9.12041","0.00855"
"18310","109.82600","9.15234","0.00912"
"18374","110.21000","9.18433","0.00950"
"18438","110.59400","9.21638","0.00907"
"18502","110.97800","9.24836","0.00899"
"18566","111.36200","9.28035","0.00912"
"18630","111.74600","9.31246","0.00855"
"18694","112.13000","9.34445","0.00909"
"18758","112.51400","9.37631","0.00892"
"18822","112.89800","9.40842","0.00915"
"18886","113.28200","9.44041","0.00864"
"18950","113.66600","9.47234","0.00908"
"19014","114.05000","9.50432","0.00918"
"19078","114.43400","9.53637","0.00943"
"19142","114.81800","9.56836","0.00903"
"19206","115.20200","9.60035","0.00907"
"19270","115.58600","9.63239","0.00888"
"19334","115.97000","9.66438","0.00881"
"19398","116.35400","9.69637","0.00933"
"19462","116.73800","9.72836","0.00897"
"19526","117.12200","9.76040","0.00929"
"19590","117.50600","9.79245","0.00908"
"19654","117.89000","9.82438","0.00878"
"19718","118.27400","9.85636","0.00910"
"19782","118.65800","9.88835","0.00931"
"19846","119.04200","9.92040","0.00902"
"19910","119.42600","9.95233","0.00910"
"19974","119.81000","9.98437","0.00917"
"20038","120.19400","10.01636","0.00878"
"20102","120.57800","10.04829","0.00944"
"20166","120.96200","10.08040","0.00951"
"20230","121.34600","10.11238","0.00933"
"20294","121.73000","10.14437","0.00979"
"20358","122.11400","10.17636","0.00936"
"20422","122.49800","10.20834","0.00948"
"20486","122.88200","10.24039","0.00929"
"20550","123.26600","10.27232","0.00898"
"20614","123.65000","10.30437","0.00932"
"20678","124.03400","10.33635","0.00933"
"20742","124.41800","10.36834","0.00928"
"20806","124.80200","10.40033","0.00936"
"20870","125.18600","10.43244","0.00956"
"20934","125.57000","10.46442","0.00954"
"20998","125.95400","10.49629","0.00950"
"21062","126.33800","10.52840","0.00973"
"21126","126.72200","10.56039","0.00919"
"21190","127.10600","10.59231","0.00977"
"21254","127.49000","10.62436","0.00950"
"21318","127.87400","10.65641","0.00980"
"21382","128.25800","10.68833","0.00975"
"21446","128.64200","10.72038","0.00944"
"21510","129.02600","10.75237","0.00935"
"21574","129.41000","10.78436","0.00913"
"21638","129.79400","10.81634","0.00939"
"21702","130.17800","10.84833","0.00955"
"21766","130.56200","10.88038","0.00949"
"21830","130.94600","10.91243","0.00953"
"21894","131.33000","10.94429","0.00937"
"21958","131.71400","10.97634","0.00945"
"22022","132.09800","11.00839","0.00898"
"22086","132.48200","11.04038","0.00939"
"22150","132.86600","11.07236","0.00930"
"22214","133.25000","11.10441","0.00949"
"22278","133.63400","11.13640","0.00946"
"22342","134.01800","11.16827","0.00940"
"22406","134.40200","11.20037","0.00974"
"22470","134.78600","11.23242","0.00978"
"22534","135.17000","11.26435","0.00967"
"22598","135.55400","11.29628","0.00968"
"22662","135.93800","11.32844","0.00976"
"22726","136.32200","11.36037","0.00974"
"22790","136.70600","11.39236","0.00930"
"22854","137.09000","11.42440","0.00931"
"22918","137.47400","11.45633","0.00961"
"22982","137.85800","11.48838","0.00980"
"23046","138.24200","11.52037","0.00941"
"23110","138.62600","11.55235","0.00894"
"23174","139.01000","11.58440","0.00977"
"23238","139.39400","11.61633","0.00965"
"23302","139.77800","11.64832","0.00964"
"23366","140.16200","11.68036","0.00943"
"23430","140.54600","11.71235","0.00954"
"23494","140.93000","11.74434","0.00966"
"23558","141.31400","11.77639","0.00956"
"23622","141.69800","11.80843","0.00999"
"23686","142.08200","11.84030","0.01027"
"23750","142.46600","11.87241","0.00982"
"23814","142.85000","11.90439","0.00982"
"23878","143.23400","11.93632","0.00980"
"23942","143.61800","11.96837","0.00943"
"24006","144.00200","12.00042","0.00966"
"24070","144.38600","12.03234","0.00932"
"24134","144.77000","12.06433","0.00911"
"24198","145.15400","12.09638","0.00928"
"24262","145.53800","12.12837","0.00902"
"24326","145.92200","12.16035","0.00938"
"24390","146.30600","12.19234","0.00968"
"24454","146.69000","12.22439","0.00960"
"24518","147.07400","12.25638","0.00979"
"24582","147.45800","12.28836","0.00923"
"24646","147.84200","12.32035","0.00916"
"24710","148.22600","12.35240","0.00914"
"24774","148.61000","12.38433","0.00928"
"24838","148.99400","12.41637","0.00949"
"24902","149.37800","12.44842","0.00951"
"24966","149.76200","12.48041","0.00960"
"25030","150.14600","12.51228","0.00931"
"25094","150.53000","12.54438","0.00995"
"25158","150.91400","12.57643","0.00986"
"25222","151.29800","12.60842","0.01087"
"25286","151.68200","12.64028","0.01030"
"25350","152.06600","12.67239","0.01070"
"25414","152.45000","12.70438","0.00999"
"25478","152.83400","12.73631","0.00947"
"25542","153.21800","12.76835","0.00946"
"25606","153.60200","12.80040","0.00930"
"25670","153.98600","12.83239","0.00952"
"25734","154.37000","12.86438","0.00919"
"25798","154.75400","12.89642","0.00951"
"25862","155.13800","12.92841","0.00935"
"25926","155.52200","12.96034","0.00951"
"25990","155.90600","12.99239","0.00929"
"26054","156.29000","13.02437","0.00971"
"26118","156.67400","13.05630","0.00963"
"26182","157.05800","13.08835","0.00970"
"26246","157.44200","13.12039","0.00973"
"26310","157.82600","13.15238","0.00939"
"26374","158.21000","13.18431","0.00935"
"26438","158.59400","13.21636","0.00967"
"26502","158.97800","13.24834","0.00960"
"26566","159.36200","13.28039","0.00930"
"26630","159.74600","13.31232","0.00936"
"26694","160.13000","13.34443","0.00950"
"26758","160.51400","13.37641","0.00959"
"26822","160.89800","13.40834","0.00964"
"26886","161.28200","13.44039","0.00982"
"26950","161.66600","13.47238","0.00966"
"27014","162.05000","13.50436","0.00940"
"27078","162.43400","13.53635","0.01001"
"27142","162.81800","13.56846","0.00968"
"27206","163.20200","13.60038","0.00985"
"27270","163.58600","13.63225","0.00962"
"27334","163.97000","13.66442","0.00956"
"27398","164.35400","13.69641","0.00925"
"27462","164.73800","13.72827","0.00950"
"27526","165.12200","13.76038","0.00959"
"27590","165.50600","13.79237","0.00986"
"27654","165.89000","13.82436","0.00944"
"27718","166.27400","13.85634","0.00947"
"27782","166.65800","13.88845","0.00957"
"27846","167.04200","13.92038","0.00929"
"27910","167.42600","13.95237","0.00940"
"27974","167.81000","13.98435","0.00927"
"28038","168.19400","14.01640","0.00932"
"28102","168.57800","14.04839","0.00956"
"28166","168.96200","14.08032","0.00896"
"28230","169.34600","14.11236","0.00961"
"28294","169.73000","14.14441","0.00989"
"28358","170.11400","14.17640","0.00923"
"28422","170.49800","14.20832","0.00960"
"28486","170.88200","14.24037","0.00981"
"28550","171.26600","14.27236","0.00930"
"28614","171.65000","14.30435","0.00946"
"28678","172.03400","14.33639","0.00994"
"28742","172.41800","14.36844","0.00948"
"28806","172.80200","14.40037","0.00963"
"28870","173.18600","14.43242","0.01003"
"28934","173.57000","14.46440","0.00962"
"28998","173.95400","14.49633","0.00963"
"29062","174.33800","14.52832","0.00978"
"29126","174.72200","14.56037","0.00990"
"29190","175.10600","14.59235","0.00977"
"29254","175.49000","14.62434","0.00964"
"29318","175.87400","14.65639","0.00978"
"29382","176.25800","14.68837","0.01007"
"29446","176.64200","14.72036","0.00959"
"29510","177.02600","14.75235","0.01019"
"29574","177.41000","14.78440","0.01030"
"29638","177.79400","14.81638","0.00986"
"29702","178.17800","14.84831","0.00987"
"29766","178.56200","14.88030","0.00983"
"29830","178.94600","14.91241","0.01007"
"29894","179.33000","14.94433","0.00980"
"29958","179.71400","14.97632","0.00995"
"30022","180.09800","15.00837","0.01008"
"30086","180.48200","15.04036","0.00983"
"30150","180.86600","15.07234","0.00973"
"30214","181.25000","15.10439","0.00985"
"30278","181.63400","15.13638","0.00982"
"30342","182.01800","15.16837","0.01020"
"30406","182.40200","15.20035","0.01028"
"30470","182.78600","15.23234","0.01051"
"30534","183.17000","15.26445","0.01042"
"30598","183.55400","15.29632","0.01027"
"30662","183.93800","15.32836","0.00982"
"30726","184.32200","15.36041","0.01036"
"30790","184.70600","15.39240","0.00986"
"30854","185.09000","15.42432","0.00996"
"30918","185.47400","15.45643","0.00966"
"30982","185.85800","15.48842","0.00976"
"31046","186.24200","15.52035","0.00990"
"31110","186.62600","15.55239","0.00982"
"31174","187.01000","15.58438","0.00937"
"31238","187.39400","15.61637","0.00990"
"31302","187.77800","15.64836","0.01008"
"31366","188.16200","15.68040","0.00995"
"31430","188.54600","15.71239","0.00998"
"31494","188.93000","15.74438","0.00920"
"31558","189.31400","15.77636","0.00966"
"31622","189.69800","15.80841","0.00957"
"31686","190.08200","15.84040","0.00959"
"31750","190.46600","15.87233","0.00957"
"31814","190.85000","15.90437","0.00984"
"31878","191.23400","15.93642","0.00987"
"31942","191.61800","15.96835","0.00940"
"32006","192.00200","16.00034","0.00967"
"32070","192.38600","16.03244","0.00969"
"32134","192.77000","16.06443","0.00965"
"32198","193.15400","16.09630","0.00966"
"32262","193.53800","16.12835","0.00997"
"32326","193.92200","16.16039","0.01000"
"32390","194.30600","16.19232","0.00973"
"32454","194.69000","16.22437","0.00995"
"32518","195.07400","16.25641","0.00933"
"32582","195.45800","16.28834","0.00953"
"32646","195.84200","16.32027","0.00958"
"32710","196.22600","16.35244","0.00952"
"32774","196.61000","16.38442","0.00958"
"32838","196.99400","16.41635","0.00991"
"32902","197.37800","16.44840","0.00996"
"32966","197.76200","16.48033","0.00973"
"33030","198.14600","16.51237","0.00990"
"33094","198.53000","16.54442","0.00992"
"33158","198.91400","16.57635","0.01001"
"33222","199.29800","16.60840","0.01013"
"33286","199.68200","16.64032","0.00997"
"33350","200.06600","16.67231","0.00971"
"33414","200.45000","16.70436","0.00966"
"33478","200.83400","16.73635","0.00989"
"33542","201.21800","16.76833","0.00956"
"33606","201.60200","16.80044","0.00983"
"33670","201.98600","16.83243","0.00969"
"33734","202.37000","16.86436","0.01004"
"33798","202.75400","16.89640","0.01006"
"33862","203.13800","16.92839","0.01016"
"33926","203.52200","16.96038","0.00991"
"33990","203.90600","16.99236","0.01002"
"34054","204.29000","17.02441","0.00989"
"34118","204.67400","17.05640","0.01002"
"34182","205.05800","17.08833","0.00993"
"34246","205.44200","17.12037","0.00954"
"34310","205.82600","17.15242","0.01032"
"34374","206.21000","17.18435","0.00987"
"34438","206.59400","17.21634","0.01005"
"34502","206.97800","17.24838","0.00997"
"34566","207.36200","17.28037","0.00990"
"34630","207.74600","17.31230","0.01019"
"34694","208.13000","17.34441","0.01037"
"34758","208.51400","17.37633","0.01003"
"34822","208.89800","17.40832","0.01003"
"34886","209.28200","17.44037","0.00984"
"34950","209.66600","17.47241","0.00966"
"35014","210.05000","17.50440","0.00968"
"35078","210.43400","17.53633","0.01008"
"35142","210.81800","17.56832","0.01003"
"35206","211.20200","17.60036","0.01021"
"35270","211.58600","17.63241","0.00986"
"35334","211.97000","17.66434","0.01015"
"35398","212.35400","17.69639","0.01037"
"35462","212.73800","17.72837","0.01025"
"35526","213.12200","17.76030","0.01042"
"35590","213.50600","17.79241","0.01021"
"35654","213.89000","17.82446","0.01017"
"35718","214.27400","17.85638","0.01022"
"35782","214.65800","17.88837","0.01000"
"35846","215.04200","17.92042","0.01027"
"35910","215.42600","17.95240","0.01043"
"35974","215.81000","17.98427","0.01067"
"36038","216.19400","18.01638","0.01061"
"36102","216.57800","18.04843","0.01054"
"36166","216.96200","18.08035","0.01082"
"36230","217.34600","18.11234","0.01074"
"36294","217.73000","18.14439","0.01064"
"36358","218.11400","18.17638","0.00995"
"36422","218.49800","18.20831","0.01063"
"36486","218.88200","18.24041","0.01075"
"36550","219.26600","18.27234","0.01011"
"36614","219.65000","18.30433","0.01011"
"36678","220.03400","18.33637","0.01035"
"36742","220.41800","18.36836","0.01025"
"36806","220.80200","18.40041","0.01043"
"36870","221.18600","18.43234","0.01030"
"36934","221.57000","18.46432","0.01046"
"36998","221.95400","18.49637","0.01074"
"37062","222.33800","18.52836","0.01052"
"37126","222.72200","18.56034","0.01057"
"37190","223.10600","18.59245","0.01051"
"37254","223.49000","18.62438","0.01009"
"37318","223.87400","18.65631","0.01065"
"37382","224.25800","18.68835","0.01033"
"37446","224.64200","18.72040","0.01030"
"37510","225.02600","18.75233","0.01041"
"37574","225.41000","18.78438","0.01042"
"37638","225.79400","18.81636","0.01031"
"37702","226.17800","18.84835","0.01020"
"37766","226.56200","18.88040","0.01048"
"37830","226.94600","18.91245","0.01067"
"37894","227.33000","18.94437","0.01066"
"37958","227.71400","18.97636","0.01011"
"38022","228.09800","19.00835","0.01094"
"38086","228.48200","19.04039","0.01048"
"38150","228.86600","19.07244","0.01074"
"38214","229.25000","19.10431","0.01047"
"38278","229.63400","19.13636","0.01052"
"38342","230.01800","19.16841","0.01042"
"38406","230.40200","19.20039","0.01045"
"38470","230.78600","19.23238","0.01028"
"38534","231.17000","19.26437","0.01066"
"38598","231.55400","19.29635","0.01034"
"38662","231.93800","19.32834","0.01087"
"38726","232.32200","19.36039","0.01094"
"38790","232.70600","19.39244","0.01051"
"38854","233.09000","19.42436","0.01012"
"38918","233.47400","19.45635","0.01076"
"38982","233.85800","19.48840","0.01057"
"39046","234.24200","19.52039","0.01077"
"39110","234.62600","19.55231","0.01106"
"39174","235.01000","19.58436","0.01077"
"39238","235.39400","19.61641","0.01049"
"39302","235.77800","19.64834","0.01054"
"39366","236.16200","19.68038","0.01089"
"39430","236.54600","19.71243","0.01069"
"39494","236.93000","19.74436","0.01038"
"39558","237.31400","19.77628","0.01064"
"39622","237.69800","19.80839","0.01070"
"39686","238.08200","19.84038","0.01066"
"39750","238.46600","19.87231","0.01052"
"39814","238.85000","19.90435","0.01088"
"39878","239.23400","19.93640","0.01103"
"39942","239.61800","19.96839","0.01076"
"40006","240.00200","20.00038","0.01070"
"40070","240.38600","20.03236","0.01052"
"40134","240.77000","20.06435","0.01072"
"40198","241.15400","20.09640","0.01090"
"40262","241.53800","20.12832","0.01057"
"40326","241.92200","20.16037","0.01095"
"40390","242.30600","20.19236","0.01087"
"40454","242.69000","20.22435","0.01072"
"40518","243.07400","20.25640","0.01112"
"40582","243.45800","20.28838","0.01095"
"40646","243.84200","20.32037","0.01100"
"40710","244.22600","20.35230","0.01116"
"40774","244.61000","20.38446","0.01086"
"40838","244.99400","20.41639","0.01082"
"40902","245.37800","20.44832","0.01048"
"40966","245.76200","20.48043","0.01107"
"41030","246.14600","20.51241","0.01121"
"41094","246.53000","20.54434","0.01076"
"41158","246.91400","20.57633","0.01081"
"41222","247.29800","20.60838","0.01105"
"41286","247.68200","20.64036","0.01097"
"41350","248.06600","20.67235","0.01035"
"41414","248.45000","20.70440","0.01073"
"41478","248.83400","20.73633","0.01096"
"41542","249.21800","20.76831","0.01108"
"41606","249.60200","20.80036","0.01103"
"41670","249.98600","20.83235","0.01103"
"41734","250.37000","20.86439","0.01119"
"41798","250.75400","20.89632","0.01094"
"41862","251.13800","20.92837","0.01146"
"41926","251.52200","20.96036","0.01104"
"41990","251.90600","20.99234","0.01109"
"42054","252.29000","21.02433","0.01107"
"42118","252.67400","21.05638","0.01117"
"42182","253.05800","21.08842","0.01112"
"42246","253.44200","21.12029","0.01119"
"42310","253.82600","21.15234","0.01113"
"42374","254.21000","21.18439","0.01158"
"42438","254.59400","21.21631","0.01098"
"42502","254.97800","21.24836","0.01125"
"42566","255.36200","21.28041","0.01105"
"42630","255.74600","21.31234","0.01103"
"42694","256.13000","21.34433","0.01171"
"42758","256.51400","21.37643","0.01152"
"42822","256.89800","21.40842","0.01099"
"42886","257.28200","21.44035","0.01121"
"42950","257.66600","21.47239","0.01129"
"43014","258.05000","21.50438","0.01126"
"43078","258.43400","21.53637","0.01128"
"43142","258.81800","21.56830","0.01158"
"43206","259.20200","21.60034","0.01142"
"43270","259.58600","21.63239","0.01157"
"43334","259.97000","21.66432","0.01126"
"43398","260.35400","21.69637","0.01174"
"43462","260.73800","21.72835","0.01101"
"43526","261.12200","21.76034","0.01115"
"43590","261.50600","21.79233","0.01147"
"43654","261.89000","21.82438","0.01147"
"43718","262.27400","21.85642","0.01132"
"43782","262.65800","21.88835","0.01160"
"43846","263.04200","21.92034","0.01167"
"43910","263.42600","21.95238","0.01153"
"43974","263.81000","21.98437","0.01191"
"44038","264.19400","22.01636","0.01197"
"44102","264.57800","22.04841","0.01151"
"44166","264.96200","22.08046","0.01201"
"44230","265.34600","22.11232","0.01158"
"44294","265.73000","22.14437","0.01160"
"44358","266.11400","22.17641","0.01171"
"44422","266.49800","22.20834","0.01125"
"44486","266.88200","22.24027","0.01182"
"44550","267.26600","22.27244","0.01175"
"44614","267.65000","22.30437","0.01211"
"44678","268.03400","22.33629","0.01178"
"44742","268.41800","22.36840","0.01173"
"44806","268.80200","22.40039","0.01168"
"44870","269.18600","22.43237","0.01231"
"44934","269.57000","22.46436","0.01205"
"44998","269.95400","22.49635","0.01184"
"45062","270.33800","22.52840","0.01155"
"45126","270.72200","22.56039","0.01207"
"45190","271.10600","22.59237","0.01202"
"45254","271.49000","22.62442","0.01183"
"45318","271.87400","22.65635","0.01230"
"45382","272.25800","22.68833","0.01198"
"45446","272.64200","22.72038","0.01208"
"45510","273.02600","22.75243","0.01268"
"45574","273.41000","22.78430","0.01233"
"45638","273.79400","22.81634","0.01225"
"45702","274.17800","22.84839","0.01220"
"45766","274.56200","22.88038","0.01176"
"45830","274.94600","22.91236","0.01208"
"45894","275.33000","22.94441","0.01217"
"45958","275.71400","22.97640","0.01260"
"46022","276.09800","23.00827","0.01235"
"46086","276.48200","23.04037","0.01218"
"46150","276.86600","23.07242","0.01212"
"46214","277.25000","23.10435","0.01240"
"46278","277.63400","23.13634","0.01182"
"46342","278.01800","23.16838","0.01221"
"46406","278.40200","23.20031","0.01277"
"46470","278.78600","23.23236","0.01233"
"46534","279.17000","23.26435","0.01270"
"46598","279.55400","23.29639","0.01210"
"46662","279.93800","23.32838","0.01203"
"46726","280.32200","23.36037","0.01220"
"46790","280.70600","23.39236","0.01255"
"46854","281.09000","23.42440","0.01257"
"46918","281.47400","23.45639","0.01239"
"46982","281.85800","23.48832","0.01238"
"47046","282.24200","23.52036","0.01247"
"47110","282.62600","23.55235","0.01252"
"47174","283.01000","23.58434","0.01250"
"47238","283.39400","23.61639","0.01248"
"47302","283.77800","23.64843","0.01240"
"47366","284.16200","23.68030","0.01280"
"47430","284.54600","23.71235","0.01250"
"47494","284.93000","23.74439","0.01245"
"47558","285.31400","23.77632","0.01271"
"47622","285.69800","23.80831","0.01282"
"47686","286.08200","23.84036","0.01265"
"47750","286.46600","23.87241","0.01288"
"47814","286.85000","23.90433","0.01305"
"47878","287.23400","23.93632","0.01309"
"47942","287.61800","23.96837","0.01304"
"48006","288.00200","24.00035","0.01287"
"48070","288.38600","24.03234","0.01281"
"48134","288.77000","24.06439","0.01276"
"48198","289.15400","24.09638","0.01291"
"48262","289.53800","24.12831","0.01353"
"48326","289.92200","24.16041","0.01274"
"48390","290.30600","24.19234","0.01321"
"48454","290.69000","24.22433","0.01277"
"48518","291.07400","24.25637","0.01336"
"48582","291.45800","24.28836","0.01313"
"48646","291.84200","24.32035","0.01334"
"48710","292.22600","24.35234","0.01311"
"48774","292.61000","24.38433","0.01261"
"48838","292.99400","24.41637","0.01299"
"48902","293.37800","24.44836","0.01366"
"48966","293.76200","24.48034","0.01340"
"49030","294.14600","24.51239","0.01326"
"49094","294.53000","24.54438","0.01334"
"49158","294.91400","24.57631","0.01355"
"49222","295.29800","24.60830","0.01350"
"49286","295.68200","24.64040","0.01310"
"49350","296.06600","24.67233","0.01377"
"49414","296.45000","24.70432","0.01346"
"49478","296.83400","24.73642","0.01343"
"49542","297.21800","24.76835","0.01372"
"49606","297.60200","24.80028","0.01303"
"49670","297.98600","24.83239","0.01403"
"49734","298.37000","24.86443","0.01375"
"49798","298.75400","24.89636","0.01341"
"49862","299.13800","24.92835","0.01396"
"49926","299.52200","24.96040","0.01401"
"49990","299.90600","24.99238","0.01366"
"50054","300.29000","25.02437","0.01345"
"50118","300.67400","25.05636","0.01387"
"50182","301.05800","25.08835","0.01360"
"50246","301.44200","25.12033","0.01398"
"50310","301.82600","25.15238","0.01384"
"50374","302.21000","25.18437","0.01394"
"50438","302.59400","25.21642","0.01351"
"50502","302.97800","25.24834","0.01372"
"50566","303.36200","25.28033","0.01413"
"50630","303.74600","25.31238","0.01395"
"50694","304.13000","25.34436","0.01388"
"50758","304.51400","25.37629","0.01395"
"50822","304.89800","25.40840","0.01377"
"50886","305.28200","25.44039","0.01396"
"50950","305.66600","25.47231","0.01393"
"51014","306.05000","25.50436","0.01420"
"51078","306.43400","25.53641","0.01420"
"51142","306.81800","25.56834","0.01362"
"51206","307.20200","25.60038","0.01392"
"51270","307.58600","25.63237","0.01432"
"51334","307.97000","25.66436","0.01434"
"51398","308.35400","25.69629","0.01409"
"51462","308.73800","25.72845","0.01445"
"51526","309.12200","25.76038","0.01434"
"51590","309.50600","25.79237","0.01375"
"51654","309.89000","25.82435","0.01384"
"51718","310.27400","25.85640","0.01448"
"51782","310.65800","25.88839","0.01433"
"51846","311.04200","25.92032","0.01387"
"51910","311.42600","25.95237","0.01395"
"51974","311.81000","25.98441","0.01429"
"52038","312.19400","26.01640","0.01454"
"52102","312.57800","26.04833","0.01395"
"52166","312.96200","26.08038","0.01433"
"52230","313.34600","26.11242","0.01403"
"52294","313.73000","26.14429","0.01424"
"52358","314.11400","26.17634","0.01448"
"52422","314.49800","26.20838","0.01439"
"52486","314.88200","26.24037","0.01471"
"52550","315.26600","26.27236","0.01467"
"52614","315.65000","26.30441","0.01419"
"52678","316.03400","26.33639","0.01463"
"52742","316.41800","26.36832","0.01426"
"52806","316.80200","26.40037","0.01481"
"52870","317.18600","26.43242","0.01474"
"52934","317.57000","26.46434","0.01437"
"52998","317.95400","26.49633","0.01470"
"53062","318.33800","26.52844","0.01447"
"53126","318.72200","26.56037","0.01479"
"53190","319.10600","26.59235","0.01415"
"53254","319.49000","26.62440","0.01434"
"53318","319.87400","26.65639","0.01428"
"53382","320.25800","26.68831","0.01448"
"53446","320.64200","26.72036","0.01419"
"53510","321.02600","26.75241","0.01451"
"53574","321.41000","26.78433","0.01453"
"53638","321.79400","26.81638","0.01433"
"53702","322.17800","26.84837","0.01485"
"53766","322.56200","26.88036","0.01472"
"53830","322.94600","26.91234","0.01456"
"53894","323.33000","26.94433","0.01477"
"53958","323.71400","26.97638","0.01439"
"54022","324.09800","27.00837","0.01476"
"54086","324.48200","27.04036","0.01463"
"54150","324.86600","27.07234","0.01453"
"54214","325.25000","27.10445","0.01490"
"54278","325.63400","27.13638","0.01486"
"54342","326.01800","27.16837","0.01496"
"54406","326.40200","27.20041","0.01457"
"54470","326.78600","27.23240","0.01545"
"54534","327.17000","27.26427","0.01479"
"54598","327.55400","27.29638","0.01516"
"54662","327.93800","27.32842","0.01499"
"54726","328.32200","27.36035","0.01494"
"54790","328.70600","27.39240","0.01502"
"54854","329.09000","27.42438","0.01471"
"54918","329.47400","27.45631","0.01507"
"54982","329.85800","27.48836","0.01483"
"55046","330.24200","27.52040","0.01482"
"55110","330.62600","27.55239","0.01479"
"55174","331.01000","27.58432","0.01413"
"55238","331.39400","27.61637","0.01425"
"55302","331.77800","27.64836","0.01453"
"55366","332.16200","27.68040","0.01463"
"55430","332.54600","27.71233","0.01434"
"55494","332.93000","27.74438","0.01443"
"55558","333.31400","27.77636","0.01485"
"55622","333.69800","27.80835","0.01480"
"55686","334.08200","27.84034","0.01444"
"55750","334.46600","27.87239","0.01463"
"55814","334.85000","27.90437","0.01430"
"55878","335.23400","27.93630","0.01424"
"55942","335.61800","27.96835","0.01450"
"56006","336.00200","28.00039","0.01450"
"56070","336.38600","28.03232","0.01469"
"56134","336.77000","28.06437","0.01471"
"56198","337.15400","28.09642","0.01475"
"56262","337.53800","28.12840","0.01440"
"56326","337.92200","28.16033","0.01414"
"56390","338.30600","28.19238","0.01494"
"56454","338.69000","28.22437","0.01442"
"56518","339.07400","28.25636","0.01454"
"56582","339.45800","28.28840","0.01458"
"56646","339.84200","28.32039","0.01467"
"56710","340.22600","28.35238","0.01462"
"56774","340.61000","28.38437","0.01338"
"56838","340.99400","28.41641","0.01407"
"56902","341.37800","28.44840","0.01371"
"56966","341.76200","28.48038","0.01386"
"57030","342.14600","28.51237","0.01354"
"57094","342.53000","28.54442","0.01376"
"57158","342.91400","28.57635","0.01364"
"57222","343.29800","28.60834","0.01375"
"57286","343.68200","28.64038","0.01380"
"57350","344.06600","28.67237","0.01397"
"57414","344.45000","28.70436","0.01443"
"57478","344.83400","28.73635","0.01435"
"57542","345.21800","28.76839","0.01395"
"57606","345.60200","28.80038","0.01358"
"57670","345.98600","28.83231","0.01362"
"57734","346.37000","28.86435","0.01368"
"57798","346.75400","28.89640","0.01397"
"57862","347.13800","28.92833","0.01356"
"57926","347.52200","28.96038","0.01339"
"57990","347.90600","28.99236","0.01372"
"58054","348.29000","29.02435","0.01365"
"58118","348.67400","29.05628","0.01384"
"58182","349.05800","29.08845","0.01330"
"58246","349.44200","29.12037","0.01374"
"58310","349.82600","29.15224","0.01374"
"58374","350.21000","29.18441","0.01332"
"58438","350.59400","29.21639","0.01371"
"58502","350.97800","29.24838","0.01383"
"58566","351.36200","29.28031","0.01379"
"58630","351.74600","29.31242","0.01377"
"58694","352.13000","29.34435","0.01377"
"58758","352.51400","29.37639","0.01395"
"58822","352.89800","29.40838","0.01365"
"58886","353.28200","29.44036","0.01360"
"58950","353.66600","29.47235","0.01413"
"59014","354.05000","29.50434","0.01393"
"59078","354.43400","29.53639","0.01435"
"59142","354.81800","29.56844","0.01403"
"59206","355.20200","29.60036","0.01364"
"59270","355.58600","29.63229","0.01393"
"59334","355.97000","29.66440","0.01377"
"59398","356.35400","29.69638","0.01399"
"59462","356.73800","29.72831","0.01432"
"59526","357.12200","29.76036","0.01433"
"59590","357.50600","29.79241","0.01434"
"59654","357.89000","29.82427","0.01405"
"59718","358.27400","29.85638","0.01491"
"59782","358.65800","29.88843","0.01430"
"59846","359.04200","29.92036","0.01419"
"59910","359.42600","29.95234","0.01456"
"59974","359.81000","29.98439","0.01414"
"60038","360.19400","30.01638","0.01458"
"60102","360.57800","30.04837","0.01440"
"60166","360.96200","30.08042","0.01442"
"60230","361.34600","30.11234","0.01461"
"60294","361.73000","30.14433","0.01521"
"60358","362.11400","30.17638","0.01491"
"60422","362.49800","30.20836","0.01483"
"60486","362.88200","30.24041","0.01448"
"60550","363.26600","30.27234","0.01458"
"60614","363.65000","30.30432","0.01472"
"60678","364.03400","30.33637","0.01476"
"60742","364.41800","30.36836","0.01523"
"60806","364.80200","30.40035","0.01523"
"60870","365.18600","30.43240","0.01506"
"60934","365.57000","30.46444","0.01453"
"60998","365.95400","30.49631","0.01430"
"61062","366.33800","30.52835","0.01467"
"61126","366.72200","30.56034","0.01526"
"61190","367.10600","30.59233","0.01517"
"61254","367.49000","30.62438","0.01466"
"61318","367.87400","30.65637","0.01505"
"61382","368.25800","30.68841","0.01539"
"61446","368.64200","30.72028","0.01508"
"61510","369.02600","30.75239","0.01512"
"61574","369.41000","30.78438","0.01503"
"61638","369.79400","30.81636","0.01491"
"61702","370.17800","30.84835","0.01497"
"61766","370.56200","30.88040","0.01541"
"61830","370.94600","30.91238","0.01532"
"61894","371.33000","30.94437","0.01543"
"61958","371.71400","30.97636","0.01498"
"62022","372.09800","31.00841","0.01546"
"62086","372.48200","31.04033","0.01479"
"62150","372.86600","31.07238","0.01546"
"62214","373.25000","31.10437","0.01514"
"62278","373.63400","31.13636","0.01553"
"62342","374.01800","31.16834","0.01499"
"62406","374.40200","31.20033","0.01526"
"62470","374.78600","31.23238","0.01517"
"62534","375.17000","31.26436","0.01602"
"62598","375.55400","31.29629","0.01504"
"62662","375.93800","31.32840","0.01542"
"62726","376.32200","31.36039","0.01566"
"62790","376.70600","31.39231","0.01551"
"62854","377.09000","31.42436","0.01541"
"62918","377.47400","31.45647","0.01492"
"62982","377.85800","31.48834","0.01425"
"63046","378.24200","31.52032","0.01490"
"63110","378.62600","31.55243","0.01486"
"63174","379.01000","31.58442","0.01515"
"63238","379.39400","31.61629","0.01460"
"63302","379.77800","31.64833","0.01505"
"63366","380.16200","31.68038","0.01500"
"63430","380.54600","31.71237","0.01495"
"63494","380.93000","31.74435","0.01522"
"63558","381.31400","31.77640","0.01510"
"63622","381.69800","31.80833","0.01521"
"63686","382.08200","31.84032","0.01506"
"63750","382.46600","31.87243","0.01525"
"63814","382.85000","31.90435","0.01520"
"63878","383.23400","31.93634","0.01533"
"63942","383.61800","31.96839","0.01537"
"64006","384.00200","32.00043","0.01577"
"64070","384.38600","32.03242","0.01567"
"64134","384.77000","32.06435","0.01539"
"64198","385.15400","32.09634","0.01479"
"64262","385.53800","32.12838","0.01493"
"64326","385.92200","32.16037","0.01545"
"64390","386.30600","32.19230","0.01508"
"64454","386.69000","32.22441","0.01571"
"64518","387.07400","32.25639","0.01570"
"64582","387.45800","32.28832","0.01539"
"64646","387.84200","32.32037","0.01544"
"64710","388.22600","32.35241","0.01589"
"64774","388.61000","32.38434","0.01541"
"64838","388.99400","32.41633","0.01535"
"64902","389.37800","32.44838","0.01579"
"64966","389.76200","32.48036","0.01556"
"65030","390.14600","32.51235","0.01588"
"65094","390.53000","32.54440","0.01563"
"65158","390.91400","32.57639","0.01601"
"65222","391.29800","32.60838","0.01587"
"65286","391.68200","32.64036","0.01592"
"65350","392.06600","32.67241","0.01547"
"65414","392.45000","32.70440","0.01567"
"65478","392.83400","32.73632","0.01567"
"65542","393.21800","32.76837","0.01573"
"65606","393.60200","32.80036","0.01586"
"65670","393.98600","32.83241","0.01571"
"65734","394.37000","32.86433","0.01601"
"65798","394.75400","32.89638","0.01617"
"65862","395.13800","32.92831","0.01582"
"65926","395.52200","32.96030","0.01576"
"65990","395.90600","32.99234","0.01603"
"66054","396.29000","33.02439","0.01565"
"66118","396.67400","33.05638","0.01575"
"66182","397.05800","33.08830","0.01586"
"66246","397.44200","33.12041","0.01559"
"66310","397.82600","33.15240","0.01630"
"66374","398.21000","33.18427","0.01587"
"66438","398.59400","33.21637","0.01646"
"66502","398.97800","33.24836","0.01614"
"66566","399.36200","33.28029","0.01593"
"66630","399.74600","33.31234","0.01621"
"66694","400.13000","33.34438","0.01670"
"66758","400.51400","33.37637","0.01666"
"66822","400.89800","33.40830","0.01613"
"66886","401.28200","33.44040","0.01620"
"66950","401.66600","33.47239","0.01623"
"67014","402.05000","33.50432","0.01582"
"67078","402.43400","33.53637","0.01619"
"67142","402.81800","33.56842","0.01621"
"67206","403.20200","33.60034","0.01643"
"67270","403.58600","33.63239","0.01634"
"67334","403.97000","33.66438","0.01583"
"67398","404.35400","33.69637","0.01599"
"67462","404.73800","33.72835","0.01624"
"67526","405.12200","33.76040","0.01610"
"67590","405.50600","33.79239","0.01631"
"67654","405.89000","33.82443","0.01623"
"67718","406.27400","33.85630","0.01578"
"67782","406.65800","33.88835","0.01400"
"67846","407.04200","33.92039","0.01240"
"67910","407.42600","33.95238","0.01228"
"67974","407.81000","33.98431","0.01235"
"68038","408.19400","34.01636","0.01233"
"68102","408.57800","34.04834","0.01203"
"68166","408.96200","34.08033","0.01228"
"68230","409.34600","34.11238","0.01233"
"68294","409.73000","34.14443","0.01262"
"68358","410.11400","34.17624","0.01220"
"68422","410.49800","34.20834","0.01229"
"68486","410.88200","34.24039","0.01243"
"68550","411.26600","34.27232","0.01281"
"68614","411.65000","34.30437","0.01299"
"68678","412.03400","34.33641","0.01215"
"68742","412.41800","34.36834","0.01201"
"68806","412.80200","34.40033","0.01204"
"68870","413.18600","34.43237","0.01237"
"68934","413.57000","34.46436","0.01240"
"68998","413.95400","34.49641","0.01206"
"69062","414.33800","34.52840","0.01264"
"69126","414.72200","34.56038","0.01218"
"69190","415.10600","34.59243","0.01226"
"69254","415.49000","34.62436","0.01228"
"69318","415.87400","34.65635","0.01234"
"69382","416.25800","34.68839","0.01226"
"69446","416.64200","34.72038","0.01223"
"69510","417.02600","34.75230","0.01237"
"69574","417.41000","34.78436","0.01247"
"69638","417.79400","34.81640","0.01251"
"69702","418.17800","34.84833","0.01262"
"69766","418.56200","34.88032","0.01254"
"69830","418.94600","34.91242","0.01254"
"69894","419.33000","34.94435","0.01240"
"69958","419.71400","34.97634","0.01278"
"70022","420.09800","35.00838","0.01210"
"70086","420.48200","35.04037","0.01246"
"70150","420.86600","35.07236","0.01267"
"70214","421.25000","35.10435","0.01237"
"70278","421.63400","35.13639","0.01285"
"70342","422.01800","35.16838","0.01248"
"70406","422.40200","35.20037","0.01214"
"70470","422.78600","35.23236","0.01245"
"70534","423.17000","35.26434","0.01286"
"70598","423.55400","35.29639","0.01268"
"70662","423.93800","35.32838","0.01273"
"70726","424.32200","35.36037","0.01256"
"70790","424.70600","35.39236","0.01292"
"70854","425.09000","35.42434","0.01293"
"70918","425.47400","35.45633","0.01237"
"70982","425.85800","35.48843","0.01235"
"71046","426.24200","35.52036","0.01260"
"71110","426.62600","35.55235","0.01263"
"71174","427.01000","35.58440","0.01270"
"71238","427.39400","35.61639","0.01265"
"71302","427.77800","35.64831","0.01267"
"71366","428.16200","35.68036","0.01265"
"71430","428.54600","35.71241","0.01279"
"71494","428.93000","35.74434","0.01276"
"71558","429.31400","35.77638","0.01325"
"71622","429.69800","35.80843","0.01283"
"71686","430.08200","35.84036","0.01319"
"71750","430.46600","35.87228","0.01273"
"71814","430.85000","35.90439","0.01276"
"71878","431.23400","35.93638","0.01269"
"71942","431.61800","35.96837","0.01317"
"72006","432.00200","36.00041","0.01237"
"72070","432.38600","36.03234","0.01204"
"72134","432.77000","36.06439","0.01267"
"72198","433.15400","36.09637","0.01252"
"72262","433.53800","36.12843","0.01211"
"72326","433.92200","36.16041","0.01238"
"72390","434.30600","36.19240","0.01241"
"72454","434.69000","36.22432","0.01248"
"72518","435.07400","36.25637","0.01225"
"72582","435.45800","36.28836","0.01206"
"72646","435.84200","36.32035","0.01213"
"72710","436.22600","36.35239","0.01174"
"72774","436.61000","36.38438","0.01211"
"72838","436.99400","36.41631","0.01210"
"72902","437.37800","36.44836","0.01246"
"72966","437.76200","36.48040","0.01204"
"73030","438.14600","36.51239","0.01206"
"73094","438.53000","36.54432","0.01203"
"73158","438.91400","36.57637","0.01192"
"73222","439.29800","36.60841","0.01227"
"73286","439.68200","36.64034","0.01182"
"73350","440.06600","36.67239","0.01243"
"73414","440.45000","36.70438","0.01245"
"73478","440.83400","36.73636","0.01228"
"73542","441.21800","36.76829","0.01244"
"73606","441.60200","36.80040","0.01238"
"73670","441.98600","36.83239","0.01222"
"73734","442.37000","36.86432","0.01232"
"73798","442.75400","36.89642","0.01222"
"73862","443.13800","36.92835","0.01190"
"73926","443.52200","36.96033","0.01225"
"73990","443.90600","36.99232","0.01262"
"74054","444.29000","37.02437","0.01234"
"74118","444.67400","37.05642","0.01245"
"74182","445.05800","37.08834","0.01207"
"74246","445.44200","37.12033","0.01241"
"74310","445.82600","37.15238","0.01232"
"74374","446.21000","37.18443","0.01235"
"74438","446.59400","37.21635","0.01227"
"74502","446.97800","37.24840","0.01259"
"74566","447.36200","37.28045","0.01247"
"74630","447.74600","37.31232","0.01228"
"74694","448.13000","37.34436","0.01226"
"74758","448.51400","37.37635","0.01283"
"74822","448.89800","37.40834","0.01217"
"74886","449.28200","37.44033","0.01224"
"74950","449.66600","37.47237","0.01280"
"75014","450.05000","37.50436","0.01255"
"75078","450.43400","37.53629","0.01249"
"75142","450.81800","37.56833","0.01197"
"75206","451.20200","37.60038","0.01234"
"75270","451.58600","37.63237","0.01248"
"75334","451.97000","37.66430","0.01267"
"75398","452.35400","37.69640","0.01251"
"75462","452.73800","37.72839","0.01275"
"75526","453.12200","37.76032","0.01266"
"75590","453.50600","37.79237","0.01285"
"75654","453.89000","37.82436","0.01234"
"75718","454.27400","37.85634","0.01303"
"75782","454.65800","37.88833","0.01262"
"75846","455.04200","37.92038","0.01290"
"75910","455.42600","37.95236","0.01304"
"75974","455.81000","37.98435","0.01285"
"76038","456.19400","38.01640","0.01328"
"76102","456.57800","38.04839","0.01286"
"76166","456.96200","38.08043","0.01289"
"76230","457.34600","38.11236","0.01295"
"76294","457.73000","38.14441","0.01312"
"76358","458.11400","38.17646","0.01251"
"76422","458.49800","38.20826","0.01323"
"76486","458.88200","38.24031","0.01314"
"76550","459.26600","38.27242","0.01267"
"76614","459.65000","38.30441","0.01287"
"76678","460.03400","38.33633","0.01266"
"76742","460.41800","38.36838","0.01286"
"76806","460.80200","38.40042","0.01280"
"76870","461.18600","38.43229","0.01260"
"76934","461.57000","38.46440","0.01287"
"76998","461.95400","38.49639","0.01313"
"77062","462.33800","38.52837","0.01307"
"77126","462.72200","38.56036","0.01317"
"77190","463.10600","38.59241","0.01335"
"77254","463.49000","38.62434","0.01304"
"77318","463.87400","38.65638","0.01309"
"77382","464.25800","38.68837","0.01306"
"77446","464.64200","38.72036","0.01315"
"77510","465.02600","38.75235","0.01315"
"77574","465.41000","38.78440","0.01344"
"77638","465.79400","38.81638","0.01338"
"77702","466.17800","38.84843","0.01308"
"77766","466.56200","38.88036","0.01305"
"77830","466.94600","38.91235","0.01323"
"77894","467.33000","38.94439","0.01314"
"77958","467.71400","38.97638","0.01292"
"78022","468.09800","39.00830","0.01307"
"78086","468.48200","39.04041","0.01303"
"78150","468.86600","39.07240","0.01328"
"78214","469.25000","39.10433","0.01239"
"78278","469.63400","39.13638","0.01269"
"78342","470.01800","39.16842","0.01201"
"78406","470.40200","39.20035","0.01210"
"78470","470.78600","39.23233","0.01254"
"78534","471.17000","39.26438","0.01277"
"78598","471.55400","39.29631","0.01288"
"78662","471.93800","39.32830","0.01241"
"78726","472.32200","39.36041","0.01325"
"78790","472.70600","39.39233","0.01274"
"78854","473.09000","39.42438","0.01281"
"78918","473.47400","39.45637","0.01250"
"78982","473.85800","39.48836","0.01254"
"79046","474.24200","39.52040","0.01291"
"79110","474.62600","39.55239","0.01266"
"79169","474.97800","39.58169","0.01278"