File: Trajectories_together/161216Specimen_RawData_2.csv
"","V1","V2","V3"
"1","End date","12/16/2016",""
"2","Specimen label","6DG_45",""
"3","Maximum Load","0.00540","N"
"4","Time","Extension","Load"
"5","(s)","(mm)","(N)"
"6","0.00000","0.00000","-0.00002"
"65","0.35400","0.02954","0.00005"
"124","0.70800","0.05931","0.00038"
"183","1.06200","0.08867","0.00017"
"242","1.41600","0.11820","0.00061"
"301","1.77000","0.14774","0.00065"
"360","2.12400","0.17716","0.00070"
"419","2.47800","0.20669","0.00053"
"478","2.83200","0.23623","0.00049"
"537","3.18600","0.26564","0.00031"
"596","3.54000","0.29524","0.00032"
"655","3.89400","0.32466","0.00100"
"714","4.24800","0.35413","0.00092"
"773","4.60200","0.38373","0.00095"
"832","4.95600","0.41315","0.00047"
"891","5.31000","0.44268","0.00043"
"950","5.66400","0.47222","0.00053"
"1009","6.01800","0.50163","0.00044"
"1068","6.37200","0.53117","0.00084"
"1127","6.72600","0.56071","0.00097"
"1186","7.08000","0.59018","0.00047"
"1245","7.43400","0.61966","0.00079"
"1304","7.78800","0.64919","0.00080"
"1363","8.14200","0.67873","0.00043"
"1422","8.49600","0.70821","0.00052"
"1481","8.85000","0.73774","0.00062"
"1540","9.20400","0.76716","0.00025"
"1599","9.55800","0.79670","0.00080"
"1658","9.91200","0.82617","0.00104"
"1717","10.26600","0.85571","0.00068"
"1776","10.62000","0.88512","0.00049"
"1835","10.97400","0.91472","0.00030"
"1894","11.32800","0.94420","0.00074"
"1953","11.68200","0.97367","0.00059"
"2012","12.03600","1.00321","0.00009"
"2071","12.39000","1.03268","0.00050"
"2130","12.74400","1.06216","0.00038"
"2189","13.09800","1.09170","0.00053"
"2248","13.45200","1.12117","0.00067"
"2307","13.80600","1.15065","0.00062"
"2366","14.16000","1.18025","0.00065"
"2425","14.51400","1.20966","0.00074"
"2484","14.86800","1.23920","0.00029"
"2543","15.22200","1.26873","0.00097"
"2602","15.57600","1.29815","0.00048"
"2661","15.93000","1.32769","0.00082"
"2720","16.28400","1.35722","0.00100"
"2779","16.63800","1.38664","0.00057"
"2838","16.99200","1.41617","0.00081"
"2897","17.34600","1.44571","0.00064"
"2956","17.70000","1.47513","0.00042"
"3015","18.05400","1.50472","0.00062"
"3074","18.40800","1.53414","0.00065"
"3133","18.76200","1.56368","0.00112"
"3192","19.11600","1.59321","0.00081"
"3251","19.47000","1.62269","0.00047"
"3310","19.82400","1.65222","0.00068"
"3369","20.17800","1.68164","0.00101"
"3428","20.53200","1.71118","0.00073"
"3487","20.88600","1.74071","0.00104"
"3546","21.24000","1.77019","0.00089"
"3605","21.59400","1.79967","0.00092"
"3664","21.94800","1.82920","0.00043"
"3723","22.30200","1.85868","0.00119"
"3782","22.65600","1.88815","0.00095"
"3841","23.01000","1.91763","0.00070"
"3900","23.36400","1.94717","0.00087"
"3959","23.71800","1.97670","0.00100"
"4018","24.07200","2.00618","0.00076"
"4077","24.42600","2.03565","0.00106"
"4136","24.78000","2.06519","0.00060"
"4195","25.13400","2.09467","0.00112"
"4254","25.48800","2.12420","0.00057"
"4313","25.84200","2.15362","0.00081"
"4372","26.19600","2.18321","0.00036"
"4431","26.55000","2.21269","0.00085"
"4490","26.90400","2.24217","0.00067"
"4549","27.25800","2.27170","0.00035"
"4608","27.61200","2.30118","0.00105"
"4667","27.96600","2.33060","0.00073"
"4726","28.32000","2.36019","0.00059"
"4785","28.67400","2.38967","0.00121"
"4844","29.02800","2.41914","0.00092"
"4903","29.38200","2.44868","0.00050"
"4962","29.73600","2.47822","0.00076"
"5021","30.09000","2.50769","0.00079"
"5080","30.44400","2.53717","0.00073"
"5139","30.79800","2.56670","0.00114"
"5198","31.15200","2.59612","0.00096"
"5257","31.50600","2.62572","0.00096"
"5316","31.86000","2.65519","0.00006"
"5375","32.21400","2.68467","0.00106"
"5434","32.56800","2.71421","0.00085"
"5493","32.92200","2.74368","0.00094"
"5552","33.27600","2.77316","0.00076"
"5611","33.63000","2.80269","0.00062"
"5670","33.98400","2.83217","0.00067"
"5729","34.33800","2.86165","0.00071"
"5788","34.69200","2.89124","0.00085"
"5847","35.04600","2.92066","0.00065"
"5906","35.40000","2.95014","0.00040"
"5965","35.75400","2.97973","0.00084"
"6024","36.10800","3.00921","0.00129"
"6083","36.46200","3.03868","0.00050"
"6142","36.81600","3.06822","0.00079"
"6201","37.17000","3.09770","0.00061"
"6260","37.52400","3.12717","0.00048"
"6319","37.87800","3.15665","0.00044"
"6378","38.23200","3.18612","0.00045"
"6437","38.58600","3.21566","0.00089"
"6496","38.94000","3.24520","0.00084"
"6555","39.29400","3.27467","0.00062"
"6614","39.64800","3.30415","0.00090"
"6673","40.00200","3.33369","0.00083"
"6732","40.35600","3.36316","0.00072"
"6791","40.71000","3.39270","0.00116"
"6850","41.06400","3.42223","0.00087"
"6909","41.41800","3.45165","0.00118"
"6968","41.77200","3.48119","0.00060"
"7027","42.12600","3.51078","0.00162"
"7086","42.48000","3.54008","0.00058"
"7145","42.83400","3.56973","0.00176"
"7204","43.18800","3.59927","0.00341"
"7263","43.54200","3.62863","0.00069"
"7322","43.89600","3.65816","0.00291"
"7381","44.25000","3.68770","0.00213"
"7440","44.60400","3.71712","0.00125"
"7499","44.95800","3.74671","0.00080"
"7558","45.31200","3.77619","0.00066"
"7617","45.66600","3.80560","0.00082"
"7676","46.02000","3.83520","0.00147"
"7735","46.37400","3.86468","0.00100"
"7794","46.72800","3.89421","0.00069"
"7853","47.08200","3.92369","0.00118"
"7912","47.43600","3.95322","0.00064"
"7971","47.79000","3.98264","0.00195"
"8030","48.14400","4.01218","0.00133"
"8089","48.49800","4.04171","0.00120"
"8148","48.85200","4.07113","0.00062"
"8207","49.20600","4.10067","0.00100"
"8266","49.56000","4.13020","0.00067"
"8325","49.91400","4.15968","0.00051"
"8384","50.26800","4.18915","0.00113"
"8443","50.62200","4.21869","0.00073"
"8502","50.97600","4.24817","0.00065"
"8561","51.33000","4.27770","0.00104"
"8620","51.68400","4.30712","0.00117"
"8679","52.03800","4.33671","0.00152"
"8738","52.39200","4.36625","0.00101"
"8797","52.74600","4.39567","0.00116"
"8856","53.10000","4.42514","0.00137"
"8915","53.45400","4.45468","0.00055"
"8974","53.80800","4.48416","0.00083"
"9033","54.16200","4.51369","0.00135"
"9092","54.51600","4.54323","0.00071"
"9151","54.87000","4.57258","0.00083"
"9210","55.22400","4.60218","0.00071"
"9269","55.57800","4.63166","0.00077"
"9328","55.93200","4.66113","0.00088"
"9387","56.28600","4.69067","0.00113"
"9446","56.64000","4.72020","0.00045"
"9505","56.99400","4.74962","0.00072"
"9564","57.34800","4.77922","0.00060"
"9623","57.70200","4.80869","0.00086"
"9682","58.05600","4.83811","0.00083"
"9741","58.41000","4.86765","0.00081"
"9800","58.76400","4.89718","0.00084"
"9859","59.11800","4.92660","0.00097"
"9918","59.47200","4.95619","0.00060"
"9977","59.82600","4.98567","0.00050"
"10036","60.18000","5.01515","0.00081"
"10095","60.53400","5.04468","0.00080"
"10154","60.88800","5.07416","0.00066"
"10213","61.24200","5.10363","0.00078"
"10272","61.59600","5.13323","0.00123"
"10331","61.95000","5.16271","0.00060"
"10390","62.30400","5.19218","0.00084"
"10449","62.65800","5.22172","0.00067"
"10508","63.01200","5.25113","0.00089"
"10567","63.36600","5.28067","0.00086"
"10626","63.72000","5.31021","0.00083"
"10685","64.07400","5.33962","0.00068"
"10744","64.42800","5.36922","0.00077"
"10803","64.78200","5.39870","0.00065"
"10862","65.13600","5.42817","0.00095"
"10921","65.49000","5.45765","0.00085"
"10980","65.84400","5.48718","0.00088"
"11039","66.19800","5.51666","0.00061"
"11098","66.55200","5.54614","0.00096"
"11157","66.90600","5.57567","0.00091"
"11216","67.26000","5.60521","0.00086"
"11275","67.61400","5.63463","0.00106"
"11334","67.96800","5.66422","0.00177"
"11393","68.32200","5.69364","0.00112"
"11452","68.67600","5.72323","0.00102"
"11511","69.03000","5.75277","0.00088"
"11570","69.38400","5.78219","0.00123"
"11629","69.73800","5.81172","0.00085"
"11688","70.09200","5.84120","0.00081"
"11747","70.44600","5.87067","0.00067"
"11806","70.80000","5.90021","0.00088"
"11865","71.15400","5.92969","0.00081"
"11924","71.50800","5.95910","0.00142"
"11983","71.86200","5.98870","0.00123"
"12042","72.21600","6.01817","0.00120"
"12101","72.57000","6.04771","0.00082"
"12160","72.92400","6.07719","0.00086"
"12219","73.27800","6.10666","0.00099"
"12278","73.63200","6.13620","0.00119"
"12337","73.98600","6.16568","0.00161"
"12396","74.34000","6.19515","0.00106"
"12455","74.69400","6.22463","0.00089"
"12514","75.04800","6.25416","0.00096"
"12573","75.40200","6.28370","0.00092"
"12632","75.75600","6.31318","0.00097"
"12691","76.11000","6.34271","0.00108"
"12750","76.46400","6.37219","0.00092"
"12809","76.81800","6.40167","0.00084"
"12868","77.17200","6.43120","0.00120"
"12927","77.52600","6.46062","0.00128"
"12986","77.88000","6.49021","0.00068"
"13045","78.23400","6.51969","0.00101"
"13104","78.58800","6.54917","0.00072"
"13163","78.94200","6.57864","0.00109"
"13222","79.29600","6.60824","0.00144"
"13281","79.65000","6.63771","0.00093"
"13340","80.00400","6.66725","0.00140"
"13399","80.35800","6.69667","0.00145"
"13458","80.71200","6.72614","0.00113"
"13517","81.06600","6.75568","0.00145"
"13576","81.42000","6.78522","0.00108"
"13635","81.77400","6.81469","0.00141"
"13694","82.12800","6.84417","0.00123"
"13753","82.48200","6.87370","0.00063"
"13812","82.83600","6.90312","0.00094"
"13871","83.19000","6.93272","0.00142"
"13930","83.54400","6.96219","0.00171"
"13989","83.89800","6.99161","0.00098"
"14048","84.25200","7.02120","0.00125"
"14107","84.60600","7.05068","0.00112"
"14166","84.96000","7.08016","0.00129"
"14225","85.31400","7.10969","0.00153"
"14284","85.66800","7.13923","0.00124"
"14343","86.02200","7.16871","0.00115"
"14402","86.37600","7.19818","0.00183"
"14461","86.73000","7.22766","0.00160"
"14520","87.08400","7.25707","0.00136"
"14579","87.43800","7.28673","0.00145"
"14638","87.79200","7.31615","0.00116"
"14697","88.14600","7.34568","0.00142"
"14756","88.50000","7.37522","0.00153"
"14815","88.85400","7.40469","0.00171"
"14874","89.20800","7.43417","0.00218"
"14933","89.56200","7.46371","0.00187"
"14992","89.91600","7.49318","0.00151"
"15051","90.27000","7.52272","0.00204"
"15110","90.62400","7.55226","0.00210"
"15169","90.97800","7.58167","0.00178"
"15228","91.33200","7.61115","0.00148"
"15287","91.68600","7.64068","0.00125"
"15346","92.04000","7.67016","0.00177"
"15405","92.39400","7.69970","0.00102"
"15464","92.74800","7.72917","0.00146"
"15523","93.10200","7.75871","0.00167"
"15582","93.45600","7.78819","0.00140"
"15641","93.81000","7.81772","0.00158"
"15700","94.16400","7.84714","0.00147"
"15759","94.51800","7.87673","0.00112"
"15818","94.87200","7.90621","0.00138"
"15877","95.22600","7.93563","0.00129"
"15936","95.58000","7.96516","0.00202"
"15995","95.93400","7.99470","0.00191"
"16054","96.28800","8.02411","0.00156"
"16113","96.64200","8.05371","0.00169"
"16172","96.99600","8.08319","0.00178"
"16231","97.35000","8.11260","0.00158"
"16290","97.70400","8.14220","0.00152"
"16349","98.05800","8.17167","0.00141"
"16408","98.41200","8.20115","0.00109"
"16467","98.76600","8.23069","0.00162"
"16526","99.12000","8.26022","0.00163"
"16585","99.47400","8.28964","0.00160"
"16644","99.82800","8.31917","0.00190"
"16703","100.18200","8.34865","0.00158"
"16762","100.53600","8.37819","0.00213"
"16821","100.89000","8.40772","0.00169"
"16880","101.24400","8.43720","0.00183"
"16939","101.59800","8.46662","0.00166"
"16998","101.95200","8.49621","0.00167"
"17057","102.30600","8.52563","0.00173"
"17116","102.66000","8.55516","0.00122"
"17175","103.01400","8.58470","0.00186"
"17234","103.36800","8.61418","0.00174"
"17293","103.72200","8.64365","0.00186"
"17352","104.07600","8.67319","0.00169"
"17411","104.43000","8.70267","0.00189"
"17470","104.78400","8.73214","0.00204"
"17529","105.13800","8.76168","0.00163"
"17588","105.49200","8.79121","0.00260"
"17647","105.84600","8.82069","0.00199"
"17706","106.20000","8.85017","0.00223"
"17765","106.55400","8.87964","0.00136"
"17824","106.90800","8.90918","0.00206"
"17883","107.26200","8.93871","0.00191"
"17942","107.61600","8.96819","0.00170"
"18001","107.97000","8.99767","0.00178"
"18060","108.32400","9.02726","0.00218"
"18119","108.67800","9.05662","0.00182"
"18178","109.03200","9.08615","0.00177"
"18237","109.38600","9.11569","0.00200"
"18296","109.74000","9.14517","0.00148"
"18355","110.09400","9.17470","0.00136"
"18414","110.44800","9.20424","0.00142"
"18473","110.80200","9.23360","0.00159"
"18532","111.15600","9.26319","0.00137"
"18591","111.51000","9.29273","0.00179"
"18650","111.86400","9.32215","0.00164"
"18709","112.21800","9.35168","0.00178"
"18768","112.57200","9.38116","0.00179"
"18827","112.92600","9.41063","0.00219"
"18886","113.28000","9.44023","0.00145"
"18945","113.63400","9.46971","0.00200"
"19004","113.98800","9.49912","0.00213"
"19063","114.34200","9.52872","0.00190"
"19122","114.69600","9.55819","0.00210"
"19181","115.05000","9.58767","0.00156"
"19240","115.40400","9.61721","0.00127"
"19299","115.75800","9.64668","0.00114"
"19358","116.11200","9.67616","0.00164"
"19417","116.46600","9.70569","0.00191"
"19476","116.82000","9.73517","0.00187"
"19535","117.17400","9.76465","0.00153"
"19594","117.52800","9.79418","0.00169"
"19653","117.88200","9.82372","0.00211"
"19712","118.23600","9.85320","0.00174"
"19771","118.59000","9.88273","0.00163"
"19830","118.94400","9.91221","0.00127"
"19889","119.29800","9.94162","0.00161"
"19948","119.65200","9.97122","0.00159"
"20007","120.00600","10.00064","0.00156"
"20066","120.36000","10.03017","0.00142"
"20125","120.71400","10.05977","0.00197"
"20184","121.06800","10.08913","0.00183"
"20243","121.42200","10.11866","0.00208"
"20302","121.77600","10.14826","0.00137"
"20361","122.13000","10.17761","0.00146"
"20420","122.48400","10.20721","0.00180"
"20479","122.83800","10.23669","0.00226"
"20538","123.19200","10.26616","0.00200"
"20597","123.54600","10.29570","0.00173"
"20656","123.90000","10.32523","0.00172"
"20715","124.25400","10.35465","0.00162"
"20774","124.60800","10.38419","0.00178"
"20833","124.96200","10.41366","0.00179"
"20892","125.31600","10.44314","0.00142"
"20951","125.67000","10.47268","0.00117"
"21010","126.02400","10.50221","0.00192"
"21069","126.37800","10.53169","0.00205"
"21128","126.73200","10.56122","0.00179"
"21187","127.08600","10.59070","0.00205"
"21246","127.44000","10.62012","0.00182"
"21305","127.79400","10.64971","0.00179"
"21364","128.14800","10.67919","0.00129"
"21423","128.50200","10.70866","0.00175"
"21482","128.85600","10.73820","0.00190"
"21541","129.21000","10.76768","0.00168"
"21600","129.56400","10.79715","0.00129"
"21659","129.91800","10.82669","0.00155"
"21718","130.27200","10.85617","0.00193"
"21777","130.62600","10.88564","0.00186"
"21836","130.98000","10.91524","0.00220"
"21895","131.33400","10.94465","0.00176"
"21954","131.68800","10.97419","0.00196"
"22013","132.04200","11.00360","0.00181"
"22072","132.39600","11.03320","0.00211"
"22131","132.75000","11.06268","0.00191"
"22190","133.10400","11.09227","0.00182"
"22249","133.45800","11.12163","0.00196"
"22308","133.81200","11.15117","0.00164"
"22367","134.16600","11.18070","0.00204"
"22426","134.52000","11.21012","0.00200"
"22485","134.87400","11.23966","0.00195"
"22544","135.22800","11.26913","0.00233"
"22603","135.58200","11.29867","0.00219"
"22662","135.93600","11.32820","0.00205"
"22721","136.29000","11.35774","0.00206"
"22780","136.64400","11.38710","0.00191"
"22839","136.99800","11.41675","0.00227"
"22898","137.35200","11.44623","0.00193"
"22957","137.70600","11.47565","0.00193"
"23016","138.06000","11.50518","0.00219"
"23075","138.41400","11.53472","0.00232"
"23134","138.76800","11.56413","0.00214"
"23193","139.12200","11.59373","0.00258"
"23252","139.47600","11.62320","0.00242"
"23311","139.83000","11.65262","0.00221"
"23370","140.18400","11.68222","0.00226"
"23429","140.53800","11.71163","0.00246"
"23488","140.89200","11.74111","0.00233"
"23547","141.24600","11.77071","0.00180"
"23606","141.60000","11.80018","0.00245"
"23665","141.95400","11.82972","0.00236"
"23724","142.30800","11.85925","0.00204"
"23783","142.66200","11.88861","0.00220"
"23842","143.01600","11.91815","0.00229"
"23901","143.37000","11.94768","0.00238"
"23960","143.72400","11.97722","0.00243"
"24019","144.07800","12.00663","0.00245"
"24078","144.43200","12.03617","0.00262"
"24137","144.78600","12.06559","0.00287"
"24196","145.14000","12.09512","0.00257"
"24255","145.49400","12.12472","0.00304"
"24314","145.84800","12.15414","0.00254"
"24373","146.20200","12.18367","0.00242"
"24432","146.55600","12.21321","0.00257"
"24491","146.91000","12.24268","0.00295"
"24550","147.26400","12.27216","0.00309"
"24609","147.61800","12.30170","0.00268"
"24668","147.97200","12.33111","0.00224"
"24727","148.32600","12.36071","0.00257"
"24786","148.68000","12.39019","0.00201"
"24845","149.03400","12.41966","0.00302"
"24904","149.38800","12.44926","0.00279"
"24963","149.74200","12.47873","0.00229"
"25022","150.09600","12.50815","0.00259"
"25081","150.45000","12.53769","0.00279"
"25140","150.80400","12.56716","0.00293"
"25199","151.15800","12.59664","0.00291"
"25258","151.51200","12.62617","0.00224"
"25317","151.86600","12.65571","0.00243"
"25376","152.22000","12.68519","0.00261"
"25435","152.57400","12.71466","0.00258"
"25494","152.92800","12.74420","0.00273"
"25553","153.28200","12.77361","0.00279"
"25612","153.63600","12.80321","0.00282"
"25671","153.99000","12.83269","0.00271"
"25730","154.34400","12.86216","0.00259"
"25789","154.69800","12.89176","0.00269"
"25848","155.05200","12.92118","0.00267"
"25907","155.40600","12.95065","0.00255"
"25966","155.76000","12.98019","0.00304"
"26025","156.11400","13.00966","0.00323"
"26084","156.46800","13.03914","0.00306"
"26143","156.82200","13.06874","0.00308"
"26202","157.17600","13.09815","0.00263"
"26261","157.53000","13.12763","0.00294"
"26320","157.88400","13.15717","0.00324"
"26379","158.23800","13.18664","0.00310"
"26438","158.59200","13.21624","0.00321"
"26497","158.94600","13.24571","0.00315"
"26556","159.30000","13.27513","0.00338"
"26615","159.65400","13.30467","0.00344"
"26674","160.00800","13.33414","0.00312"
"26733","160.36200","13.36368","0.00303"
"26792","160.71600","13.39315","0.00307"
"26851","161.07000","13.42269","0.00331"
"26910","161.42400","13.45217","0.00312"
"26969","161.77800","13.48170","0.00328"
"27028","162.13200","13.51124","0.00296"
"27087","162.48600","13.54060","0.00341"
"27146","162.84000","13.57019","0.00323"
"27205","163.19400","13.59967","0.00346"
"27264","163.54800","13.62914","0.00367"
"27323","163.90200","13.65868","0.00362"
"27382","164.25600","13.68822","0.00308"
"27441","164.61000","13.71769","0.00269"
"27500","164.96400","13.74723","0.00303"
"27559","165.31800","13.77670","0.00298"
"27618","165.67200","13.80612","0.00333"
"27677","166.02600","13.83572","0.00302"
"27736","166.38000","13.86519","0.00305"
"27795","166.73400","13.89461","0.00323"
"27854","167.08800","13.92420","0.00364"
"27913","167.44200","13.95368","0.00302"
"27972","167.79600","13.98316","0.00306"
"28031","168.15000","14.01269","0.00338"
"28090","168.50400","14.04211","0.00300"
"28149","168.85800","14.07165","0.00329"
"28208","169.21200","14.10118","0.00328"
"28267","169.56600","14.13072","0.00341"
"28326","169.92000","14.16020","0.00314"
"28385","170.27400","14.18967","0.00319"
"28444","170.62800","14.21915","0.00308"
"28503","170.98200","14.24868","0.00319"
"28562","171.33600","14.27816","0.00307"
"28621","171.69000","14.30769","0.00286"
"28680","172.04400","14.33717","0.00313"
"28739","172.39800","14.36671","0.00346"
"28798","172.75200","14.39618","0.00317"
"28857","173.10600","14.42566","0.00330"
"28916","173.46000","14.45520","0.00329"
"28975","173.81400","14.48467","0.00356"
"29034","174.16800","14.51421","0.00385"
"29093","174.52200","14.54368","0.00366"
"29152","174.87600","14.57316","0.00352"
"29211","175.23000","14.60270","0.00385"
"29270","175.58400","14.63223","0.00341"
"29329","175.93800","14.66165","0.00396"
"29388","176.29200","14.69118","0.00391"
"29447","176.64600","14.72066","0.00318"
"29506","177.00000","14.75020","0.00360"
"29565","177.35400","14.77973","0.00374"
"29624","177.70800","14.80921","0.00351"
"29683","178.06200","14.83869","0.00371"
"29742","178.41600","14.86816","0.00376"
"29801","178.77000","14.89770","0.00307"
"29860","179.12400","14.92712","0.00365"
"29919","179.47800","14.95665","0.00374"
"29978","179.83200","14.98619","0.00402"
"30037","180.18600","15.01566","0.00412"
"30096","180.54000","15.04520","0.00414"
"30155","180.89400","15.07474","0.00391"
"30214","181.24800","15.10415","0.00443"
"30273","181.60200","15.13369","0.00374"
"30332","181.95600","15.16316","0.00364"
"30391","182.31000","15.19270","0.00406"
"30450","182.66400","15.22224","0.00469"
"30509","183.01800","15.25165","0.00405"
"30568","183.37200","15.28119","0.00425"
"30627","183.72600","15.31067","0.00402"
"30686","184.08000","15.34020","0.00439"
"30745","184.43400","15.36968","0.00431"
"30804","184.78800","15.39921","0.00413"
"30863","185.14200","15.42869","0.00370"
"30922","185.49600","15.45817","0.00406"
"30981","185.85000","15.48770","0.00448"
"31040","186.20400","15.51718","0.00402"
"31099","186.55800","15.54665","0.00426"
"31158","186.91200","15.57619","0.00388"
"31217","187.26600","15.60567","0.00294"
"31276","187.62000","15.63520","0.00332"
"31335","187.97400","15.66468","0.00279"
"31394","188.32800","15.69415","0.00215"
"31453","188.68200","15.72369","0.00346"
"31512","189.03600","15.75323","0.00258"
"31571","189.39000","15.78264","0.00303"
"31630","189.74400","15.81218","0.00216"
"31689","190.09800","15.84177","0.00278"
"31748","190.45200","15.87113","0.00337"
"31807","190.80600","15.90067","0.00236"
"31866","191.16000","15.93020","0.00262"
"31925","191.51400","15.95962","0.00255"
"31984","191.86800","15.98922","0.00258"
"32043","192.22200","16.01869","0.00309"
"32102","192.57600","16.04817","0.00324"
"32161","192.93000","16.07771","0.00290"
"32220","193.28400","16.10724","0.00343"
"32279","193.63800","16.13666","0.00272"
"32338","193.99200","16.16619","0.00306"
"32397","194.34600","16.19567","0.00263"
"32456","194.70000","16.22514","0.00309"
"32515","195.05400","16.25474","0.00310"
"32574","195.40800","16.28422","0.00257"
"32633","195.76200","16.31357","0.00273"
"32692","196.11600","16.34323","0.00320"
"32751","196.47000","16.37271","0.00313"
"32810","196.82400","16.40218","0.00332"
"32869","197.17800","16.43166","0.00294"
"32928","197.53200","16.46119","0.00306"
"32987","197.88600","16.49067","0.00308"
"33046","198.24000","16.52021","0.00274"
"33105","198.59400","16.54968","0.00291"
"33164","198.94800","16.57910","0.00323"
"33223","199.30200","16.60869","0.00327"
"33282","199.65600","16.63811","0.00236"
"33341","200.01000","16.66771","0.00283"
"33400","200.36400","16.69718","0.00294"
"33459","200.71800","16.72666","0.00321"
"33518","201.07200","16.75620","0.00296"
"33577","201.42600","16.78573","0.00301"
"33636","201.78000","16.81515","0.00304"
"33695","202.13400","16.84463","0.00358"
"33754","202.48800","16.87422","0.00329"
"33813","202.84200","16.90370","0.00314"
"33872","203.19600","16.93317","0.00359"
"33931","203.55000","16.96265","0.00345"
"33990","203.90400","16.99213","0.00349"
"34049","204.25800","17.02172","0.00332"
"34108","204.61200","17.05120","0.00329"
"34167","204.96600","17.08061","0.00353"
"34226","205.32000","17.11021","0.00358"
"34285","205.67400","17.13969","0.00371"
"34344","206.02800","17.16916","0.00372"
"34403","206.38200","17.19876","0.00359"
"34462","206.73600","17.22817","0.00382"
"34521","207.09000","17.25765","0.00349"
"34580","207.44400","17.28725","0.00330"
"34639","207.79800","17.31666","0.00384"
"34698","208.15200","17.34614","0.00337"
"34757","208.50600","17.37574","0.00397"
"34816","208.86000","17.40515","0.00377"
"34875","209.21400","17.43463","0.00393"
"34934","209.56800","17.46416","0.00378"
"34993","209.92200","17.49364","0.00404"
"35052","210.27600","17.52317","0.00377"
"35111","210.63000","17.55271","0.00427"
"35170","210.98400","17.58219","0.00423"
"35229","211.33800","17.61166","0.00412"
"35288","211.69200","17.64114","0.00401"
"35347","212.04600","17.67068","0.00376"
"35406","212.40000","17.70015","0.00384"
"35465","212.75400","17.72975","0.00391"
"35524","213.10800","17.75916","0.00380"
"35583","213.46200","17.78870","0.00434"
"35642","213.81600","17.81824","0.00341"
"35701","214.17000","17.84765","0.00388"
"35760","214.52400","17.87719","0.00398"
"35819","214.87800","17.90672","0.00349"
"35878","215.23200","17.93608","0.00328"
"35937","215.58600","17.96568","0.00300"
"35996","215.94000","17.99521","0.00333"
"36055","216.29400","18.02463","0.00309"
"36114","216.64800","18.05423","0.00335"
"36173","217.00200","18.08364","0.00324"
"36232","217.35600","18.11312","0.00321"
"36291","217.71000","18.14272","0.00329"
"36350","218.06400","18.17225","0.00311"
"36409","218.41800","18.20161","0.00305"
"36468","218.77200","18.23126","0.00279"
"36527","219.12600","18.26068","0.00328"
"36586","219.48000","18.29010","0.00292"
"36645","219.83400","18.31969","0.00353"
"36704","220.18800","18.34923","0.00359"
"36763","220.54200","18.37864","0.00287"
"36822","220.89600","18.40818","0.00322"
"36881","221.25000","18.43766","0.00363"
"36940","221.60400","18.46713","0.00357"
"36999","221.95800","18.49673","0.00336"
"37058","222.31200","18.52621","0.00374"
"37117","222.66600","18.55568","0.00384"
"37176","223.02000","18.58522","0.00361"
"37235","223.37400","18.61469","0.00401"
"37294","223.72800","18.64417","0.00395"
"37353","224.08200","18.67371","0.00364"
"37412","224.43600","18.70312","0.00383"
"37471","224.79000","18.73266","0.00423"
"37530","225.14400","18.76220","0.00395"
"37589","225.49800","18.79167","0.00365"
"37648","225.85200","18.82115","0.00398"
"37707","226.20600","18.85068","0.00457"
"37766","226.56000","18.88016","0.00424"
"37825","226.91400","18.90969","0.00412"
"37884","227.26800","18.93917","0.00401"
"37943","227.62200","18.96859","0.00415"
"38002","227.97600","18.99818","0.00378"
"38061","228.33000","19.02772","0.00412"
"38120","228.68400","19.05720","0.00428"
"38179","229.03800","19.08667","0.00438"
"38238","229.39200","19.11615","0.00400"
"38297","229.74600","19.14562","0.00419"
"38356","230.10000","19.17522","0.00435"
"38415","230.45400","19.20470","0.00424"
"38474","230.80800","19.23411","0.00453"
"38533","231.16200","19.26371","0.00371"
"38592","231.51600","19.29319","0.00399"
"38651","231.87000","19.32260","0.00347"
"38710","232.22400","19.35214","0.00339"
"38769","232.57800","19.38173","0.00343"
"38828","232.93200","19.41115","0.00315"
"38887","233.28600","19.44075","0.00364"
"38946","233.64000","19.47016","0.00346"
"39005","233.99400","19.49970","0.00372"
"39064","234.34800","19.52923","0.00382"
"39123","234.70200","19.55871","0.00377"
"39182","235.05600","19.58819","0.00352"
"39241","235.41000","19.61772","0.00367"
"39300","235.76400","19.64714","0.00298"
"39359","236.11800","19.67668","0.00320"
"39418","236.47200","19.70615","0.00302"
"39477","236.82600","19.73563","0.00339"
"39536","237.18000","19.76516","0.00368"
"39595","237.53400","19.79470","0.00352"
"39654","237.88800","19.82418","0.00334"
"39713","238.24200","19.85365","0.00325"
"39772","238.59600","19.88319","0.00357"
"39831","238.95000","19.91267","0.00356"
"39890","239.30400","19.94220","0.00349"
"39949","239.65800","19.97168","0.00352"
"40008","240.01200","20.00115","0.00336"
"40067","240.36600","20.03069","0.00363"
"40126","240.72000","20.06022","0.00383"
"40185","241.07400","20.08964","0.00378"
"40244","241.42800","20.11918","0.00350"
"40303","241.78200","20.14865","0.00337"
"40362","242.13600","20.17813","0.00405"
"40421","242.49000","20.20767","0.00371"
"40480","242.84400","20.23720","0.00360"
"40539","243.19800","20.26668","0.00392"
"40598","243.55200","20.29621","0.00364"
"40657","243.90600","20.32569","0.00371"
"40716","244.26000","20.35505","0.00355"
"40775","244.61400","20.38476","0.00342"
"40834","244.96800","20.41418","0.00425"
"40893","245.32200","20.44366","0.00427"
"40952","245.67600","20.47319","0.00484"
"41011","246.03000","20.50273","0.00383"
"41070","246.38400","20.53214","0.00464"
"41129","246.73800","20.56174","0.00440"
"41188","247.09200","20.59115","0.00333"
"41247","247.44600","20.62063","0.00397"
"41306","247.80000","20.65023","0.00425"
"41365","248.15400","20.67970","0.00420"
"41424","248.50800","20.70918","0.00435"
"41483","248.86200","20.73872","0.00429"
"41542","249.21600","20.76819","0.00464"
"41601","249.57000","20.79767","0.00436"
"41660","249.92400","20.82721","0.00476"
"41719","250.27800","20.85668","0.00455"
"41778","250.63200","20.88616","0.00481"
"41837","250.98600","20.91570","0.00505"
"41896","251.34000","20.94517","0.00502"
"41955","251.69400","20.97465","0.00481"
"42014","252.04800","21.00418","0.00509"
"42073","252.40200","21.03366","0.00505"
"42132","252.75600","21.06314","0.00443"
"42191","253.11000","21.09267","0.00354"
"42250","253.46400","21.12209","0.00283"
"42309","253.81800","21.15168","0.00231"
"42368","254.17200","21.18122","0.00233"
"42427","254.52600","21.21070","0.00283"
"42486","254.88000","21.24011","0.00216"
"42545","255.23400","21.26971","0.00269"
"42604","255.58800","21.29918","0.00294"
"42663","255.94200","21.32872","0.00231"
"42722","256.29600","21.35820","0.00268"
"42781","256.65000","21.38767","0.00249"
"42840","257.00400","21.41721","0.00302"
"42899","257.35800","21.44674","0.00305"
"42958","257.71200","21.47610","0.00284"
"43017","258.06600","21.50570","0.00200"
"43076","258.42000","21.53523","0.00287"
"43135","258.77400","21.56465","0.00209"
"43194","259.12800","21.59425","0.00254"
"43253","259.48200","21.62366","0.00269"
"43312","259.83600","21.65320","0.00270"
"43371","260.19000","21.68273","0.00288"
"43430","260.54400","21.71221","0.00315"
"43489","260.89800","21.74162","0.00242"
"43548","261.25200","21.77122","0.00222"
"43607","261.60600","21.80070","0.00219"
"43666","261.96000","21.83023","0.00236"
"43725","262.31400","21.85971","0.00292"
"43784","262.66800","21.88913","0.00275"
"43843","263.02200","21.91866","0.00307"
"43902","263.37600","21.94820","0.00281"
"43961","263.73000","21.97768","0.00287"
"44020","264.08400","22.00715","0.00293"
"44079","264.43800","22.03669","0.00351"
"44138","264.79200","22.06616","0.00268"
"44197","265.14600","22.09564","0.00246"
"44256","265.50000","22.12518","0.00309"
"44315","265.85400","22.15465","0.00297"
"44374","266.20800","22.18413","0.00312"
"44433","266.56200","22.21372","0.00258"
"44492","266.91600","22.24320","0.00300"
"44551","267.27000","22.27268","0.00258"
"44610","267.62400","22.30221","0.00289"
"44669","267.97800","22.33163","0.00324"
"44728","268.33200","22.36117","0.00315"
"44787","268.68600","22.39070","0.00293"
"44846","269.04000","22.42018","0.00310"
"44905","269.39400","22.44971","0.00299"
"44964","269.74800","22.47919","0.00261"
"45023","270.10200","22.50861","0.00318"
"45082","270.45600","22.53815","0.00309"
"45141","270.81000","22.56774","0.00310"
"45200","271.16400","22.59716","0.00272"
"45259","271.51800","22.62669","0.00370"
"45318","271.87200","22.65623","0.00360"
"45377","272.22600","22.68564","0.00384"
"45436","272.58000","22.71524","0.00446"
"45495","272.93400","22.74466","0.00393"
"45554","273.28800","22.77419","0.00234"
"45613","273.64200","22.80367","0.00237"
"45672","273.99600","22.83321","0.00255"
"45731","274.35000","22.86262","0.00261"
"45790","274.70400","22.89222","0.00233"
"45849","275.05800","22.92169","0.00317"
"45908","275.41200","22.95117","0.00314"
"45967","275.76600","22.98070","0.00242"
"46026","276.12000","23.01018","0.00329"
"46085","276.47400","23.03966","0.00307"
"46144","276.82800","23.06919","0.00269"
"46203","277.18200","23.09873","0.00307"
"46262","277.53600","23.12815","0.00346"
"46321","277.89000","23.15768","0.00350"
"46380","278.24400","23.18716","0.00351"
"46439","278.59800","23.21663","0.00353"
"46498","278.95200","23.24617","0.00344"
"46557","279.30600","23.27571","0.00400"
"46616","279.66000","23.30518","0.00343"
"46675","280.01400","23.33472","0.00359"
"46734","280.36800","23.36414","0.00354"
"46793","280.72200","23.39361","0.00353"
"46852","281.07600","23.42321","0.00363"
"46911","281.43000","23.45262","0.00386"
"46970","281.78400","23.48216","0.00420"
"47029","282.13800","23.51169","0.00433"
"47088","282.49200","23.54117","0.00432"
"47147","282.84600","23.57065","0.00373"
"47206","283.20000","23.60018","0.00438"
"47265","283.55400","23.62960","0.00418"
"47324","283.90800","23.65920","0.00451"
"47383","284.26200","23.68873","0.00443"
"47442","284.61600","23.71815","0.00422"
"47501","284.97000","23.74768","0.00432"
"47560","285.32400","23.77716","0.00435"
"47619","285.67800","23.80664","0.00446"
"47678","286.03200","23.83623","0.00370"
"47737","286.38600","23.86571","0.00359"
"47796","286.74000","23.89513","0.00323"
"47855","287.09400","23.92472","0.00340"
"47914","287.44800","23.95420","0.00342"
"47973","287.80200","23.98368","0.00355"
"48032","288.15600","24.01315","0.00374"
"48091","288.51000","24.04269","0.00320"
"48150","288.86400","24.07216","0.00361"
"48209","289.21800","24.10170","0.00355"
"48268","289.57200","24.13111","0.00378"
"48327","289.92600","24.16065","0.00360"
"48386","290.28000","24.19019","0.00362"
"48445","290.63400","24.21972","0.00355"
"48504","290.98800","24.24920","0.00321"
"48563","291.34200","24.27868","0.00336"
"48622","291.69600","24.30815","0.00381"
"48681","292.05000","24.33769","0.00383"
"48740","292.40400","24.36722","0.00334"
"48799","292.75800","24.39664","0.00360"
"48858","293.11200","24.42618","0.00368"
"48917","293.46600","24.45565","0.00379"
"48976","293.82000","24.48513","0.00331"
"49035","294.17400","24.51466","0.00387"
"49094","294.52800","24.54420","0.00347"
"49153","294.88200","24.57362","0.00415"
"49212","295.23600","24.60316","0.00152"
"49271","295.59000","24.63269","0.00114"
"49330","295.94400","24.66211","0.00081"
"49389","296.29800","24.69170","0.00100"
"49448","296.65200","24.72118","0.00072"
"49507","297.00600","24.75072","0.00180"
"49566","297.36000","24.78019","0.00027"
"49625","297.71400","24.80972","0.00097"
"49684","298.06800","24.83914","0.00123"
"49743","298.42200","24.86874","0.00097"
"49802","298.77600","24.89822","0.00049"
"49861","299.13000","24.92763","0.00147"
"49920","299.48400","24.95723","0.00140"
"49979","299.83800","24.98670","0.00095"
"50038","300.19200","25.01612","0.00097"
"50097","300.54600","25.04572","0.00162"
"50156","300.90000","25.07519","0.00107"
"50215","301.25400","25.10467","0.00106"
"50274","301.60800","25.13420","0.00145"
"50333","301.96200","25.16362","0.00131"
"50392","302.31600","25.19310","0.00073"
"50451","302.67000","25.22275","0.00080"
"50510","303.02400","25.25217","0.00100"
"50569","303.37800","25.28164","0.00082"
"50628","303.73200","25.31124","0.00163"
"50687","304.08600","25.34066","0.00148"
"50746","304.44000","25.37013","0.00125"
"50805","304.79400","25.39967","0.00086"
"50864","305.14800","25.42921","0.00125"
"50923","305.50200","25.45868","0.00146"
"50982","305.85600","25.48816","0.00112"
"51041","306.21000","25.51763","0.00122"
"51100","306.56400","25.54711","0.00145"
"51159","306.91800","25.57665","0.00120"
"51218","307.27200","25.60618","0.00166"
"51277","307.62600","25.63572","0.00173"
"51336","307.98000","25.66514","0.00169"
"51395","308.33400","25.69467","0.00078"
"51454","308.68800","25.72409","0.00183"
"51513","309.04200","25.75374","0.00176"
"51572","309.39600","25.78310","0.00132"
"51631","309.75000","25.81276","0.00124"
"51690","310.10400","25.84223","0.00153"
"51749","310.45800","25.87165","0.00115"
"51808","310.81200","25.90118","0.00103"
"51867","311.16600","25.93066","0.00190"
"51926","311.52000","25.96014","0.00161"
"51985","311.87400","25.98973","0.00096"
"52044","312.22800","26.01915","0.00157"
"52103","312.58200","26.04863","0.00155"
"52162","312.93600","26.07822","0.00133"
"52221","313.29000","26.10770","0.00193"
"52280","313.64400","26.13717","0.00143"
"52339","313.99800","26.16665","0.00143"
"52398","314.35200","26.19613","0.00120"
"52457","314.70600","26.22572","0.00169"
"52516","315.06000","26.25520","0.00154"
"52575","315.41400","26.28468","0.00152"
"52634","315.76800","26.31415","0.00167"
"52693","316.12200","26.34375","0.00149"
"52752","316.47600","26.37317","0.00101"
"52811","316.83000","26.40264","0.00109"
"52870","317.18400","26.43217","0.00111"
"52929","317.53800","26.46171","0.00115"
"52988","317.89200","26.49113","0.00113"
"53047","318.24600","26.52067","0.00138"
"53106","318.60000","26.55014","0.00148"
"53165","318.95400","26.57968","0.00189"
"53224","319.30800","26.60915","0.00171"
"53283","319.66200","26.63869","0.00144"
"53342","320.01600","26.66817","0.00174"
"53401","320.37000","26.69770","0.00132"
"53460","320.72400","26.72712","0.00172"
"53519","321.07800","26.75671","0.00129"
"53578","321.43200","26.78613","0.00151"
"53637","321.78600","26.81561","0.00129"
"53696","322.14000","26.84520","0.00154"
"53755","322.49400","26.87474","0.00150"
"53814","322.84800","26.90415","0.00154"
"53873","323.20200","26.93369","0.00188"
"53932","323.55600","26.96317","0.00142"
"53991","323.91000","26.99264","0.00153"
"54050","324.26400","27.02218","0.00180"
"54109","324.61800","27.05165","0.00154"
"54168","324.97200","27.08119","0.00153"
"54227","325.32600","27.11073","0.00188"
"54286","325.68000","27.14026","0.00178"
"54345","326.03400","27.16962","0.00182"
"54404","326.38800","27.19922","0.00216"
"54463","326.74200","27.22869","0.00149"
"54522","327.09600","27.25817","0.00181"
"54581","327.45000","27.28770","0.00159"
"54640","327.80400","27.31718","0.00198"
"54699","328.15800","27.34666","0.00175"
"54758","328.51200","27.37619","0.00183"
"54817","328.86600","27.40567","0.00125"
"54876","329.22000","27.43514","0.00221"
"54935","329.57400","27.46468","0.00174"
"54994","329.92800","27.49416","0.00205"
"55053","330.28200","27.52364","0.00174"
"55112","330.63600","27.55317","0.00142"
"55171","330.99000","27.58265","0.00193"
"55230","331.34400","27.61218","0.00142"
"55289","331.69800","27.64166","0.00230"
"55348","332.05200","27.67114","0.00210"
"55407","332.40600","27.70067","0.00173"
"55466","332.76000","27.73021","0.00165"
"55525","333.11400","27.75968","0.00161"
"55584","333.46800","27.78922","0.00173"
"55643","333.82200","27.81864","0.00195"
"55702","334.17600","27.84817","0.00222"
"55761","334.53000","27.87759","0.00201"
"55820","334.88400","27.90718","0.00209"
"55879","335.23800","27.93666","0.00176"
"55938","335.59200","27.96614","0.00236"
"55997","335.94600","27.99573","0.00186"
"56056","336.30000","28.02515","0.00170"
"56115","336.65400","28.05462","0.00219"
"56174","337.00800","28.08422","0.00193"
"56233","337.36200","28.11364","0.00145"
"56292","337.71600","28.14317","0.00189"
"56351","338.07000","28.17265","0.00200"
"56410","338.42400","28.20212","0.00146"
"56469","338.77800","28.23172","0.00194"
"56528","339.13200","28.26120","0.00189"
"56587","339.48600","28.29062","0.00190"
"56646","339.84000","28.32015","0.00190"
"56705","340.19400","28.34968","0.00164"
"56764","340.54800","28.37916","0.00221"
"56823","340.90200","28.40870","0.00161"
"56882","341.25600","28.43818","0.00173"
"56941","341.61000","28.46771","0.00244"
"57000","341.96400","28.49718","0.00174"
"57059","342.31800","28.52666","0.00177"
"57118","342.67200","28.55614","0.00191"
"57177","343.02600","28.58568","0.00209"
"57236","343.38000","28.61521","0.00167"
"57295","343.73400","28.64469","0.00200"
"57354","344.08800","28.67417","0.00225"
"57413","344.44200","28.70364","0.00174"
"57472","344.79600","28.73318","0.00165"
"57531","345.15000","28.76271","0.00204"
"57590","345.50400","28.79219","0.00220"
"57649","345.85800","28.82167","0.00215"
"57708","346.21200","28.85126","0.00229"
"57767","346.56600","28.88068","0.00220"
"57826","346.92000","28.91021","0.00227"
"57885","347.27400","28.93963","0.00211"
"57944","347.62800","28.96917","0.00204"
"58003","347.98200","28.99870","0.00213"
"58062","348.33600","29.02824","0.00227"
"58121","348.69000","29.05766","0.00245"
"58180","349.04400","29.08719","0.00187"
"58239","349.39800","29.11667","0.00254"
"58298","349.75200","29.14608","0.00162"
"58357","350.10600","29.17568","0.00232"
"58416","350.46000","29.20516","0.00203"
"58475","350.81400","29.23463","0.00198"
"58534","351.16800","29.26417","0.00216"
"58593","351.52200","29.29376","0.00154"
"58652","351.87600","29.32312","0.00166"
"58711","352.23000","29.35272","0.00232"
"58770","352.58400","29.38219","0.00235"
"58829","352.93800","29.41167","0.00213"
"58888","353.29200","29.44120","0.00220"
"58947","353.64600","29.47068","0.00178"
"59006","354.00000","29.50010","0.00264"
"59065","354.35400","29.52975","0.00182"
"59124","354.70800","29.55923","0.00217"
"59183","355.06200","29.58864","0.00186"
"59242","355.41600","29.61818","0.00226"
"59301","355.77000","29.64766","0.00208"
"59360","356.12400","29.67713","0.00216"
"59419","356.47800","29.70673","0.00211"
"59478","356.83200","29.73615","0.00250"
"59537","357.18600","29.76562","0.00190"
"59596","357.54000","29.79522","0.00234"
"59655","357.89400","29.82463","0.00218"
"59714","358.24800","29.85417","0.00176"
"59773","358.60200","29.88371","0.00239"
"59832","358.95600","29.91318","0.00217"
"59891","359.31000","29.94266","0.00163"
"59950","359.66400","29.97214","0.00253"
"60009","360.01800","30.00161","0.00229"
"60068","360.37200","30.03115","0.00192"
"60127","360.72600","30.06074","0.00250"
"60186","361.08000","30.09016","0.00216"
"60245","361.43400","30.11970","0.00268"
"60304","361.78800","30.14917","0.00246"
"60363","362.14200","30.17865","0.00298"
"60422","362.49600","30.20813","0.00228"
"60481","362.85000","30.23772","0.00232"
"60540","363.20400","30.26714","0.00251"
"60599","363.55800","30.29667","0.00237"
"60658","363.91200","30.32627","0.00227"
"60717","364.26600","30.35563","0.00242"
"60776","364.62000","30.38522","0.00232"
"60835","364.97400","30.41470","0.00245"
"60894","365.32800","30.44417","0.00303"
"60953","365.68200","30.47365","0.00279"
"61012","366.03600","30.50319","0.00277"
"61071","366.39000","30.53266","0.00271"
"61130","366.74400","30.56220","0.00229"
"61189","367.09800","30.59167","0.00262"
"61248","367.45200","30.62115","0.00235"
"61307","367.80600","30.65075","0.00241"
"61366","368.16000","30.68022","0.00263"
"61425","368.51400","30.70964","0.00254"
"61484","368.86800","30.73918","0.00235"
"61543","369.22200","30.76865","0.00278"
"61602","369.57600","30.79813","0.00268"
"61661","369.93000","30.82772","0.00214"
"61720","370.28400","30.85714","0.00255"
"61779","370.63800","30.88668","0.00303"
"61838","370.99200","30.91621","0.00219"
"61897","371.34600","30.94563","0.00254"
"61956","371.70000","30.97516","0.00277"
"62015","372.05400","31.00470","0.00265"
"62074","372.40800","31.03412","0.00280"
"62133","372.76200","31.06371","0.00259"
"62192","373.11600","31.09319","0.00253"
"62251","373.47000","31.12272","0.00230"
"62310","373.82400","31.15220","0.00198"
"62369","374.17800","31.18174","0.00199"
"62428","374.53200","31.21110","0.00246"
"62487","374.88600","31.24069","0.00257"
"62546","375.24000","31.27023","0.00244"
"62605","375.59400","31.29964","0.00241"
"62664","375.94800","31.32912","0.00242"
"62723","376.30200","31.35871","0.00226"
"62782","376.65600","31.38819","0.00235"
"62841","377.01000","31.41766","0.00213"
"62900","377.36400","31.44726","0.00180"
"62959","377.71800","31.47656","0.00240"
"63018","378.07200","31.50621","0.00192"
"63077","378.42600","31.53569","0.00257"
"63136","378.78000","31.56511","0.00200"
"63195","379.13400","31.59470","0.00236"
"63254","379.48800","31.62418","0.00219"
"63313","379.84200","31.65359","0.00229"
"63372","380.19600","31.68325","0.00250"
"63431","380.55000","31.71267","0.00190"
"63490","380.90400","31.74214","0.00223"
"63549","381.25800","31.77174","0.00220"
"63608","381.61200","31.80122","0.00260"
"63667","381.96600","31.83063","0.00189"
"63726","382.32000","31.86017","0.00219"
"63785","382.67400","31.88970","0.00239"
"63844","383.02800","31.91918","0.00201"
"63903","383.38200","31.94872","0.00179"
"63962","383.73600","31.97813","0.00175"
"64021","384.09000","32.00767","0.00249"
"64080","384.44400","32.03720","0.00214"
"64139","384.79800","32.06668","0.00177"
"64198","385.15200","32.09615","0.00130"
"64257","385.50600","32.12569","0.00144"
"64316","385.86000","32.15517","0.00171"
"64375","386.21400","32.18470","0.00146"
"64434","386.56800","32.21418","0.00137"
"64493","386.92200","32.24366","0.00208"
"64552","387.27600","32.27319","0.00156"
"64611","387.63000","32.30273","0.00212"
"64670","387.98400","32.33220","0.00185"
"64729","388.33800","32.36168","0.00190"
"64788","388.69200","32.39122","0.00226"
"64847","389.04600","32.42064","0.00163"
"64906","389.40000","32.45023","0.00195"
"64965","389.75400","32.47971","0.00116"
"65024","390.10800","32.50918","0.00175"
"65083","390.46200","32.53866","0.00131"
"65142","390.81600","32.56825","0.00189"
"65201","391.17000","32.59761","0.00160"
"65260","391.52400","32.62720","0.00159"
"65319","391.87800","32.65668","0.00187"
"65378","392.23200","32.68616","0.00179"
"65437","392.58600","32.71570","0.00157"
"65496","392.94000","32.74517","0.00198"
"65555","393.29400","32.77465","0.00185"
"65614","393.64800","32.80418","0.00186"
"65673","394.00200","32.83372","0.00171"
"65732","394.35600","32.86314","0.00220"
"65791","394.71000","32.89267","0.00184"
"65850","395.06400","32.92221","0.00185"
"65909","395.41800","32.95169","0.00187"
"65968","395.77200","32.98122","0.00178"
"66027","396.12600","33.01070","0.00201"
"66086","396.48000","33.04017","0.00176"
"66145","396.83400","33.06971","0.00151"
"66204","397.18800","33.09912","0.00169"
"66263","397.54200","33.12866","0.00219"
"66322","397.89600","33.15820","0.00175"
"66381","398.25000","33.18762","0.00186"
"66440","398.60400","33.21721","0.00160"
"66499","398.95800","33.24669","0.00195"
"66558","399.31200","33.27616","0.00239"
"66617","399.66600","33.30570","0.00245"
"66676","400.02000","33.33517","0.00198"
"66735","400.37400","33.36465","0.00190"
"66794","400.72800","33.39419","0.00218"
"66853","401.08200","33.42373","0.00271"
"66912","401.43600","33.45320","0.00206"
"66971","401.79000","33.48262","0.00219"
"67030","402.14400","33.51221","0.00230"
"67089","402.49800","33.54163","0.00187"
"67148","402.85200","33.57116","0.00188"
"67207","403.20600","33.60070","0.00183"
"67266","403.56000","33.63012","0.00216"
"67325","403.91400","33.65971","0.00242"
"67384","404.26800","33.68919","0.00235"
"67443","404.62200","33.71861","0.00251"
"67502","404.97600","33.74820","0.00213"
"67561","405.33000","33.77774","0.00254"
"67620","405.68400","33.80709","0.00174"
"67679","406.03800","33.83675","0.00236"
"67738","406.39200","33.86617","0.00224"
"67797","406.74600","33.89564","0.00219"
"67856","407.10000","33.92524","0.00258"
"67915","407.45400","33.95471","0.00251"
"67974","407.80800","33.98413","0.00205"
"68033","408.16200","34.01367","0.00198"
"68092","408.51600","34.04321","0.00211"
"68151","408.87000","34.07268","0.00255"
"68210","409.22400","34.10221","0.00210"
"68269","409.57800","34.13163","0.00208"
"68328","409.93200","34.16117","0.00224"
"68387","410.28600","34.19070","0.00223"
"68446","410.64000","34.22018","0.00223"
"68505","410.99400","34.24960","0.00214"
"68564","411.34800","34.27919","0.00216"
"68623","411.70200","34.30873","0.00245"
"68682","412.05600","34.33821","0.00225"
"68741","412.41000","34.36768","0.00220"
"68800","412.76400","34.39716","0.00174"
"68859","413.11800","34.42663","0.00250"
"68918","413.47200","34.45623","0.00216"
"68977","413.82600","34.48571","0.00235"
"69036","414.18000","34.51513","0.00198"
"69095","414.53400","34.54466","0.00222"
"69154","414.88800","34.57420","0.00234"
"69213","415.24200","34.60367","0.00240"
"69272","415.59600","34.63314","0.00245"
"69331","415.95000","34.66262","0.00215"
"69390","416.30400","34.69216","0.00207"
"69449","416.65800","34.72176","0.00183"
"69508","417.01200","34.75117","0.00221"
"69567","417.36600","34.78071","0.00236"
"69626","417.72000","34.81024","0.00173"
"69685","418.07400","34.83966","0.00181"
"69744","418.42800","34.86913","0.00223"
"69803","418.78200","34.89867","0.00198"
"69862","419.13600","34.92815","0.00215"
"69921","419.49000","34.95768","0.00231"
"69980","419.84400","34.98722","0.00208"
"70039","420.19800","35.01664","0.00232"
"70098","420.55200","35.04617","0.00214"
"70157","420.90600","35.07571","0.00251"
"70216","421.26000","35.10518","0.00200"
"70275","421.61400","35.13472","0.00242"
"70334","421.96800","35.16420","0.00220"
"70393","422.32200","35.19368","0.00225"
"70452","422.67600","35.22321","0.00250"
"70511","423.03000","35.25269","0.00254"
"70570","423.38400","35.28216","0.00253"
"70629","423.73800","35.31170","0.00266"
"70688","424.09200","35.34118","0.00232"
"70747","424.44600","35.37065","0.00240"
"70806","424.80000","35.40018","0.00221"
"70865","425.15400","35.42972","0.00233"
"70924","425.50800","35.45920","0.00225"
"70983","425.86200","35.48868","0.00266"
"71042","426.21600","35.51815","0.00264"
"71101","426.57000","35.54769","0.00283"
"71160","426.92400","35.57716","0.00285"
"71219","427.27800","35.60670","0.00235"
"71278","427.63200","35.63618","0.00300"
"71337","427.98600","35.66571","0.00260"
"71396","428.34000","35.69519","0.00289"
"71455","428.69400","35.72467","0.00280"
"71514","429.04800","35.75420","0.00261"
"71573","429.40200","35.78362","0.00271"
"71632","429.75600","35.81321","0.00250"
"71691","430.11000","35.84275","0.00269"
"71750","430.46400","35.87210","0.00286"
"71809","430.81800","35.90170","0.00276"
"71868","431.17200","35.93124","0.00282"
"71927","431.52600","35.96059","0.00285"
"71986","431.88000","35.99025","0.00281"
"72045","432.23400","36.01966","0.00309"
"72104","432.58800","36.04920","0.00327"
"72163","432.94200","36.07874","0.00240"
"72222","433.29600","36.10822","0.00269"
"72281","433.65000","36.13763","0.00284"
"72293","433.72200","36.14361","0.00302"