File: Trajectories_together/161221_2Specimen_RawData_1.csv
"","V1","V2","V3"
"1","End date","12/21/2016",""
"2","Specimen label","24T_89",""
"3","Maximum Load","0.18898","N"
"4","Time","Extension","Load"
"5","(s)","(mm)","(N)"
"6","0.00000","0.00000","0.00015"
"80","0.44400","0.03731","0.00017"
"154","0.88800","0.07426","0.00004"
"228","1.33200","0.11121","-0.00039"
"302","1.77600","0.14822","0.00016"
"376","2.22000","0.18523","-0.00013"
"450","2.66400","0.22224","0.00013"
"524","3.10800","0.25925","0.00025"
"598","3.55200","0.29620","0.00048"
"672","3.99600","0.33315","0.00030"
"746","4.44000","0.37022","0.00032"
"820","4.88400","0.40729","0.00052"
"894","5.32800","0.44424","0.00031"
"968","5.77200","0.48119","0.00038"
"1042","6.21600","0.51820","0.00057"
"1116","6.66000","0.55515","0.00043"
"1190","7.10400","0.59222","0.00054"
"1264","7.54800","0.62928","0.00044"
"1338","7.99200","0.66623","0.00037"
"1412","8.43600","0.70324","0.00066"
"1486","8.88000","0.74019","0.00050"
"1560","9.32400","0.77720","0.00038"
"1634","9.76800","0.81421","0.00025"
"1708","10.21200","0.85122","0.00088"
"1782","10.65600","0.88823","0.00062"
"1856","11.10000","0.92524","0.00059"
"1930","11.54400","0.96219","0.00064"
"2004","11.98800","0.99926","0.00081"
"2078","12.43200","1.03621","0.00064"
"2152","12.87600","1.07322","0.00072"
"2226","13.32000","1.11029","0.00067"
"2300","13.76400","1.14724","0.00046"
"2374","14.20800","1.18425","0.00069"
"2448","14.65200","1.22126","0.00058"
"2522","15.09600","1.25821","0.00084"
"2596","15.54000","1.29522","0.00036"
"2670","15.98400","1.33223","0.00086"
"2744","16.42800","1.36918","0.00092"
"2818","16.87200","1.40625","0.00083"
"2892","17.31600","1.44320","0.00097"
"2966","17.76000","1.48021","0.00069"
"3040","18.20400","1.51728","0.00086"
"3114","18.64800","1.55429","0.00072"
"3188","19.09200","1.59118","0.00057"
"3262","19.53600","1.62819","0.00084"
"3336","19.98000","1.66526","0.00083"
"3410","20.42400","1.70227","0.00096"
"3484","20.86800","1.73928","0.00088"
"3558","21.31200","1.77623","0.00061"
"3632","21.75600","1.81312","0.00078"
"3706","22.20000","1.85019","0.00090"
"3780","22.64400","1.88726","0.00094"
"3854","23.08800","1.92427","0.00113"
"3928","23.53200","1.96128","0.00117"
"4002","23.97600","1.99829","0.00107"
"4076","24.42000","2.03518","0.00096"
"4150","24.86400","2.07225","0.00112"
"4224","25.30800","2.10926","0.00067"
"4298","25.75200","2.14621","0.00125"
"4372","26.19600","2.18321","0.00123"
"4446","26.64000","2.22016","0.00090"
"4520","27.08400","2.25717","0.00109"
"4594","27.52800","2.29424","0.00131"
"4668","27.97200","2.33131","0.00091"
"4742","28.41600","2.36826","0.00124"
"4816","28.86000","2.40521","0.00150"
"4890","29.30400","2.44216","0.00106"
"4964","29.74800","2.47917","0.00121"
"5038","30.19200","2.51624","0.00122"
"5112","30.63600","2.55325","0.00147"
"5186","31.08000","2.59026","0.00086"
"5260","31.52400","2.62721","0.00131"
"5334","31.96800","2.66422","0.00115"
"5408","32.41200","2.70123","0.00136"
"5482","32.85600","2.73824","0.00112"
"5556","33.30000","2.77525","0.00137"
"5630","33.74400","2.81226","0.00142"
"5704","34.18800","2.84915","0.00153"
"5778","34.63200","2.88616","0.00143"
"5852","35.07600","2.92323","0.00158"
"5926","35.52000","2.96024","0.00126"
"6000","35.96400","2.99719","0.00130"
"6074","36.40800","3.03420","0.00135"
"6148","36.85200","3.07121","0.00148"
"6222","37.29600","3.10822","0.00122"
"6296","37.74000","3.14529","0.00187"
"6370","38.18400","3.18224","0.00185"
"6444","38.62800","3.21925","0.00178"
"6518","39.07200","3.25620","0.00158"
"6592","39.51600","3.29315","0.00161"
"6666","39.96000","3.33028","0.00185"
"6740","40.40400","3.36729","0.00182"
"6814","40.84800","3.40424","0.00160"
"6888","41.29200","3.44125","0.00195"
"6962","41.73600","3.47820","0.00193"
"7036","42.18000","3.51521","0.00161"
"7110","42.62400","3.55228","0.00190"
"7184","43.06800","3.58923","0.00164"
"7258","43.51200","3.62624","0.00166"
"7332","43.95600","3.66319","0.00191"
"7406","44.40000","3.70019","0.00167"
"7480","44.84400","3.73714","0.00157"
"7554","45.28800","3.77421","0.00187"
"7628","45.73200","3.81128","0.00205"
"7702","46.17600","3.84823","0.00220"
"7776","46.62000","3.88530","0.00177"
"7850","47.06400","3.92219","0.00200"
"7924","47.50800","3.95920","0.00214"
"7998","47.95200","3.99621","0.00188"
"8072","48.39600","4.03322","0.00239"
"8146","48.84000","4.07023","0.00218"
"8220","49.28400","4.10718","0.00209"
"8294","49.72800","4.14413","0.00226"
"8368","50.17200","4.18120","0.00200"
"8442","50.61600","4.21827","0.00201"
"8516","51.06000","4.25528","0.00209"
"8590","51.50400","4.29229","0.00205"
"8664","51.94800","4.32924","0.00198"
"8738","52.39200","4.36619","0.00197"
"8812","52.83600","4.40320","0.00242"
"8886","53.28000","4.44027","0.00226"
"8960","53.72400","4.47728","0.00226"
"9034","54.16800","4.51423","0.00246"
"9108","54.61200","4.55118","0.00225"
"9182","55.05600","4.58819","0.00191"
"9256","55.50000","4.62520","0.00265"
"9330","55.94400","4.66227","0.00220"
"9404","56.38800","4.69928","0.00241"
"9478","56.83200","4.73623","0.00234"
"9552","57.27600","4.77318","0.00236"
"9626","57.72000","4.81025","0.00289"
"9700","58.16400","4.84720","0.00214"
"9774","58.60800","4.88421","0.00207"
"9848","59.05200","4.92122","0.00260"
"9922","59.49600","4.95817","0.00214"
"9996","59.94000","4.99518","0.00246"
"10070","60.38400","5.03225","0.00233"
"10144","60.82800","5.06920","0.00240"
"10218","61.27200","5.10620","0.00245"
"10292","61.71600","5.14327","0.00271"
"10366","62.16000","5.18023","0.00277"
"10440","62.60400","5.21718","0.00226"
"10514","63.04800","5.25424","0.00249"
"10588","63.49200","5.29125","0.00234"
"10662","63.93600","5.32820","0.00245"
"10736","64.38000","5.36521","0.00296"
"10810","64.82400","5.40216","0.00273"
"10884","65.26800","5.43923","0.00305"
"10958","65.71200","5.47630","0.00281"
"11032","66.15600","5.51325","0.00162"
"11106","66.60000","5.55026","0.00197"
"11180","67.04400","5.58721","0.00239"
"11254","67.48800","5.62416","0.00180"
"11328","67.93200","5.66117","0.00215"
"11402","68.37600","5.69824","0.00239"
"11476","68.82000","5.73519","0.00162"
"11550","69.26400","5.77220","0.00201"
"11624","69.70800","5.80921","0.00180"
"11698","70.15200","5.84622","0.00189"
"11772","70.59600","5.88329","0.00186"
"11846","71.04000","5.92024","0.00171"
"11920","71.48400","5.95725","0.00201"
"11994","71.92800","5.99426","0.00189"
"12068","72.37200","6.03115","0.00204"
"12142","72.81600","6.06822","0.00223"
"12216","73.26000","6.10517","0.00207"
"12290","73.70400","6.14224","0.00233"
"12364","74.14800","6.17925","0.00210"
"12438","74.59200","6.21620","0.00252"
"12512","75.03600","6.25321","0.00218"
"12586","75.48000","6.29022","0.00261"
"12660","75.92400","6.32723","0.00228"
"12734","76.36800","6.36424","0.00233"
"12808","76.81200","6.40125","0.00233"
"12882","77.25600","6.43820","0.00284"
"12956","77.70000","6.47515","0.00270"
"13030","78.14400","6.51222","0.00275"
"13104","78.58800","6.54923","0.00270"
"13178","79.03200","6.58624","0.00261"
"13252","79.47600","6.62331","0.00294"
"13326","79.92000","6.66025","0.00283"
"13400","80.36400","6.69721","0.00291"
"13474","80.80800","6.73427","0.00331"
"13548","81.25200","6.77122","0.00302"
"13622","81.69600","6.80829","0.00322"
"13696","82.14000","6.84524","0.00323"
"13770","82.58400","6.88213","0.00336"
"13844","83.02800","6.91920","0.00336"
"13918","83.47200","6.95621","0.00353"
"13992","83.91600","6.99322","0.00357"
"14066","84.36000","7.03029","0.00374"
"14140","84.80400","7.06724","0.00257"
"14214","85.24800","7.10419","0.00247"
"14288","85.69200","7.14120","0.00302"
"14362","86.13600","7.17827","0.00329"
"14436","86.58000","7.21522","0.00321"
"14510","87.02400","7.25223","0.00333"
"14584","87.46800","7.28924","0.00348"
"14658","87.91200","7.32613","0.00369"
"14732","88.35600","7.36320","0.00358"
"14806","88.80000","7.40027","0.00367"
"14880","89.24400","7.43722","0.00387"
"14954","89.68800","7.47423","0.00372"
"15028","90.13200","7.51118","0.00398"
"15102","90.57600","7.54819","0.00409"
"15176","91.02000","7.58520","0.00417"
"15250","91.46400","7.62227","0.00384"
"15324","91.90800","7.65922","0.00412"
"15398","92.35200","7.69617","0.00407"
"15472","92.79600","7.73312","0.00468"
"15546","93.24000","7.77019","0.00446"
"15620","93.68400","7.80726","0.00482"
"15694","94.12800","7.84427","0.00507"
"15768","94.57200","7.88128","0.00517"
"15842","95.01600","7.91823","0.00496"
"15916","95.46000","7.95518","0.00508"
"15990","95.90400","7.99219","0.00492"
"16064","96.34800","8.02920","0.00486"
"16138","96.79200","8.06627","0.00523"
"16212","97.23600","8.10328","0.00425"
"16286","97.68000","8.14023","0.00418"
"16360","98.12400","8.17718","0.00405"
"16434","98.56800","8.21424","0.00416"
"16508","99.01200","8.25125","0.00491"
"16582","99.45600","8.28826","0.00487"
"16656","99.90000","8.32521","0.00469"
"16730","100.34400","8.36222","0.00448"
"16804","100.78800","8.39923","0.00490"
"16878","101.23200","8.43624","0.00536"
"16952","101.67600","8.47325","0.00545"
"17026","102.12000","8.51026","0.00520"
"17100","102.56400","8.54721","0.00550"
"17174","103.00800","8.58422","0.00579"
"17248","103.45200","8.62123","0.00597"
"17322","103.89600","8.65824","0.00559"
"17396","104.34000","8.69525","0.00620"
"17470","104.78400","8.73226","0.00655"
"17544","105.22800","8.76927","0.00654"
"17618","105.67200","8.80616","0.00623"
"17692","106.11600","8.84323","0.00704"
"17766","106.56000","8.88024","0.00691"
"17840","107.00400","8.91725","0.00663"
"17914","107.44800","8.95426","0.00666"
"17988","107.89200","8.99121","0.00684"
"18062","108.33600","9.02822","0.00717"
"18136","108.78000","9.06529","0.00769"
"18210","109.22400","9.10224","0.00752"
"18284","109.66800","9.13925","0.00789"
"18358","110.11200","9.17626","0.00840"
"18432","110.55600","9.21315","0.00800"
"18506","111.00000","9.25016","0.00832"
"18580","111.44400","9.28723","0.00877"
"18654","111.88800","9.32418","0.00881"
"18728","112.33200","9.36125","0.00898"
"18802","112.77600","9.39826","0.00910"
"18876","113.22000","9.43521","0.00963"
"18950","113.66400","9.47222","0.00958"
"19024","114.10800","9.50923","0.00812"
"19098","114.55200","9.54624","0.00913"
"19172","114.99600","9.58325","0.00913"
"19246","115.44000","9.62020","0.00924"
"19320","115.88400","9.65715","0.00805"
"19394","116.32800","9.69421","0.00899"
"19468","116.77200","9.73128","0.00975"
"19542","117.21600","9.76829","0.00992"
"19616","117.66000","9.80518","0.01023"
"19690","118.10400","9.84219","0.01090"
"19764","118.54800","9.87914","0.01147"
"19838","118.99200","9.91621","0.01201"
"19912","119.43600","9.95322","0.01141"
"19986","119.88000","9.99023","0.01235"
"20060","120.32400","10.02724","0.01243"
"20134","120.76800","10.06413","0.01313"
"20208","121.21200","10.10120","0.01352"
"20282","121.65600","10.13827","0.01408"
"20356","122.10000","10.17528","0.01389"
"20430","122.54400","10.21235","0.01466"
"20504","122.98800","10.24924","0.01476"
"20578","123.43200","10.28613","0.01605"
"20652","123.87600","10.32320","0.01637"
"20726","124.32000","10.36021","0.01762"
"20800","124.76400","10.39722","0.01780"
"20874","125.20800","10.43423","0.01825"
"20948","125.65200","10.47118","0.01869"
"21022","126.09600","10.50819","0.01942"
"21096","126.54000","10.54526","0.02026"
"21170","126.98400","10.58227","0.02127"
"21244","127.42800","10.61928","0.02207"
"21318","127.87200","10.65617","0.02343"
"21392","128.31600","10.69318","0.02314"
"21466","128.76000","10.73019","0.02456"
"21540","129.20400","10.76720","0.02508"
"21614","129.64800","10.80421","0.02586"
"21688","130.09200","10.84122","0.02640"
"21762","130.53600","10.87823","0.02549"
"21836","130.98000","10.91518","0.02511"
"21910","131.42400","10.95225","0.02669"
"21984","131.86800","10.98932","0.02791"
"22058","132.31200","11.02627","0.02875"
"22132","132.75600","11.06328","0.02914"
"22206","133.20000","11.10023","0.03066"
"22280","133.64400","11.13718","0.03131"
"22354","134.08800","11.17425","0.03250"
"22428","134.53200","11.21126","0.03342"
"22502","134.97600","11.24821","0.03465"
"22576","135.42000","11.28521","0.03564"
"22650","135.86400","11.32216","0.03701"
"22724","136.30800","11.35923","0.03750"
"22798","136.75200","11.39624","0.03878"
"22872","137.19600","11.43325","0.03917"
"22946","137.64000","11.47032","0.04036"
"23020","138.08400","11.50721","0.04124"
"23094","138.52800","11.54422","0.04240"
"23168","138.97200","11.58123","0.04317"
"23242","139.41600","11.61818","0.04471"
"23316","139.86000","11.65525","0.04595"
"23390","140.30400","11.69226","0.04719"
"23464","140.74800","11.72921","0.04842"
"23538","141.19200","11.76622","0.04956"
"23612","141.63600","11.80323","0.05105"
"23686","142.08000","11.84024","0.05195"
"23760","142.52400","11.87725","0.05319"
"23834","142.96800","11.91426","0.05434"
"23908","143.41200","11.95115","0.05513"
"23982","143.85600","11.98816","0.05596"
"24056","144.30000","12.02523","0.05806"
"24130","144.74400","12.06224","0.06143"
"24204","145.18800","12.09931","0.06278"
"24278","145.63200","12.13626","0.06572"
"24352","146.07600","12.17321","0.06841"
"24426","146.52000","12.21016","0.07003"
"24500","146.96400","12.24717","0.07193"
"24574","147.40800","12.28424","0.07379"
"24648","147.85200","12.32119","0.07418"
"24722","148.29600","12.35820","0.07558"
"24796","148.74000","12.39515","0.07668"
"24870","149.18400","12.43222","0.07837"
"24944","149.62800","12.46923","0.07936"
"25018","150.07200","12.50624","0.08053"
"25092","150.51600","12.54325","0.08199"
"25166","150.96000","12.58020","0.08318"
"25240","151.40400","12.61721","0.08476"
"25314","151.84800","12.65421","0.08551"
"25388","152.29200","12.69129","0.07793"
"25462","152.73600","12.72818","0.07998"
"25536","153.18000","12.76525","0.08233"
"25610","153.62400","12.80219","0.08398"
"25684","154.06800","12.83920","0.08621"
"25758","154.51200","12.87627","0.08810"
"25832","154.95600","12.91322","0.09020"
"25906","155.40000","12.95029","0.09235"
"25980","155.84400","12.98724","0.09437"
"26054","156.28800","13.02419","0.09596"
"26128","156.73200","13.06120","0.09742"
"26202","157.17600","13.09815","0.09905"
"26276","157.62000","13.13528","0.09919"
"26350","158.06400","13.17229","0.10119"
"26424","158.50800","13.20918","0.10357"
"26498","158.95200","13.24619","0.10555"
"26572","159.39600","13.28320","0.10835"
"26646","159.84000","13.32027","0.11122"
"26720","160.28400","13.35728","0.11407"
"26794","160.72800","13.39423","0.11716"
"26868","161.17200","13.43118","0.11888"
"26942","161.61600","13.46819","0.12187"
"27016","162.06000","13.50526","0.12466"
"27090","162.50400","13.54221","0.12617"
"27164","162.94800","13.57922","0.12825"
"27238","163.39200","13.61623","0.13041"
"27312","163.83600","13.65318","0.13272"
"27386","164.28000","13.69025","0.13582"
"27460","164.72400","13.72726","0.13882"
"27534","165.16800","13.76427","0.14081"
"27608","165.61200","13.80128","0.14392"
"27682","166.05600","13.83823","0.14595"
"27756","166.50000","13.87512","0.14811"
"27830","166.94400","13.91225","0.15054"
"27904","167.38800","13.94926","0.15297"
"27978","167.83200","13.98621","0.15512"
"28052","168.27600","14.02322","0.15830"
"28126","168.72000","14.06017","0.16227"
"28200","169.16400","14.09724","0.16818"
"28274","169.60800","14.13419","0.17323"
"28348","170.05200","14.17126","0.17661"
"28422","170.49600","14.20821","0.18027"
"28496","170.94000","14.24522","0.18261"
"28570","171.38400","14.28222","0.18593"
"28644","171.82800","14.31918","0.18834"
"28718","172.27200","14.35618","0.16292"
"28792","172.71600","14.39319","0.16109"
"28866","173.16000","14.43026","0.01701"
"28940","173.60400","14.46727","0.00935"
"29014","174.04800","14.50422","0.01208"
"29088","174.49200","14.54117","0.01260"
"29162","174.93600","14.57824","0.01107"
"29236","175.38000","14.61525","0.01295"
"29310","175.82400","14.65226","0.01652"
"29384","176.26800","14.68915","0.01655"
"29458","176.71200","14.72616","0.01601"
"29532","177.15600","14.76323","0.01756"
"29606","177.60000","14.80024","0.01907"
"29680","178.04400","14.83725","0.02062"
"29754","178.48800","14.87420","0.02232"
"29828","178.93200","14.91121","0.02345"
"29902","179.37600","14.94822","0.02269"
"29976","179.82000","14.98529","0.02519"
"30050","180.26400","15.02224","0.02711"
"30124","180.70800","15.05925","0.02806"
"30198","181.15200","15.09620","0.02876"
"30272","181.59600","15.13315","0.03039"
"30346","182.04000","15.17016","0.03116"
"30420","182.48400","15.20723","0.03222"
"30494","182.92800","15.24424","0.03449"
"30568","183.37200","15.28125","0.03671"
"30642","183.81600","15.31826","0.03669"
"30716","184.26000","15.35521","0.03717"
"30790","184.70400","15.39222","0.03981"
"30864","185.14800","15.42923","0.03923"
"30938","185.59200","15.46618","0.04077"
"31012","186.03600","15.50325","0.04167"
"31086","186.48000","15.54020","0.04285"
"31160","186.92400","15.57721","0.04394"
"31234","187.36800","15.61422","0.04579"
"31308","187.81200","15.65129","0.04731"
"31382","188.25600","15.68824","0.04846"
"31456","188.70000","15.72524","0.05014"
"31530","189.14400","15.76219","0.05123"
"31604","189.58800","15.79914","0.05270"
"31678","190.03200","15.83622","0.05447"
"31752","190.47600","15.87322","0.05397"
"31826","190.92000","15.91023","0.05605"
"31900","191.36400","15.94724","0.05866"
"31974","191.80800","15.98413","0.06178"
"32048","192.25200","16.02120","0.06484"
"32122","192.69600","16.05827","0.06827"
"32196","193.14000","16.09528","0.07093"
"32270","193.58400","16.13223","0.07356"
"32344","194.02800","16.16924","0.07515"
"32418","194.47200","16.20619","0.07693"
"32492","194.91600","16.24320","0.07678"
"32566","195.36000","16.28027","0.07845"
"32640","195.80400","16.31722","0.08149"
"32714","196.24800","16.35423","0.08301"
"32788","196.69200","16.39124","0.08519"
"32862","197.13600","16.42819","0.08736"
"32936","197.58000","16.46526","0.08922"
"33010","198.02400","16.50221","0.09229"
"33084","198.46800","16.53922","0.09507"
"33158","198.91200","16.57623","0.09654"
"33232","199.35600","16.61318","0.09855"
"33306","199.80000","16.65019","0.10048"
"33380","200.24400","16.68714","0.10305"
"33454","200.68800","16.72427","0.10559"
"33528","201.13200","16.76128","0.10881"
"33602","201.57600","16.79823","0.11224"
"33676","202.02000","16.83518","0.11452"
"33750","202.46400","16.87225","0.11823"
"33824","202.90800","16.90926","0.12129"
"33898","203.35200","16.94621","0.12367"
"33972","203.79600","16.98322","0.12673"
"34046","204.24000","17.02017","0.12854"
"34120","204.68400","17.05718","0.13110"
"34194","205.12800","17.09425","0.13283"
"34268","205.57200","17.13126","0.13685"
"34342","206.01600","17.16826","0.13973"
"34416","206.46000","17.20522","0.12682"
"34490","206.90400","17.24223","0.13018"
"34564","207.34800","17.27923","0.13210"
"34638","207.79200","17.31624","0.13403"
"34712","208.23600","17.35325","0.13555"
"34786","208.68000","17.39021","0.13758"
"34860","209.12400","17.42721","0.14010"
"34934","209.56800","17.46416","0.14257"
"35008","210.01200","17.50117","0.14652"
"35082","210.45600","17.53824","0.14868"
"35156","210.90000","17.57525","0.14471"
"35230","211.34400","17.61220","0.12836"
"35304","211.78800","17.64927","0.12837"
"35378","212.23200","17.68622","0.13085"
"35452","212.67600","17.72323","0.13229"
"35526","213.12000","17.76018","0.10953"
"35600","213.56400","17.79725","0.11121"
"35674","214.00800","17.83426","0.11231"
"35748","214.45200","17.87121","0.11281"
"35822","214.89600","17.90816","0.11789"
"35896","215.34000","17.94517","0.11906"
"35970","215.78400","17.98224","0.09912"
"36044","216.22800","18.01925","0.10298"
"36118","216.67200","18.05632","0.10456"
"36192","217.11600","18.09321","0.10713"
"36266","217.56000","18.13022","0.11126"
"36340","218.00400","18.16723","0.11308"
"36414","218.44800","18.20424","0.11816"
"36488","218.89200","18.24125","0.11870"
"36562","219.33600","18.27820","0.08230"
"36636","219.78000","18.31515","0.08383"
"36710","220.22400","18.35222","0.08290"
"36784","220.66800","18.38923","0.04840"
"36858","221.11200","18.42624","0.05082"
"36932","221.55600","18.46325","0.05448"
"37006","222.00000","18.50020","0.05327"
"37080","222.44400","18.53721","0.05584"
"37154","222.88800","18.57421","0.06054"
"37228","223.33200","18.61123","0.06209"
"37302","223.77600","18.64824","0.06381"
"37376","224.22000","18.68525","0.02019"
"37450","224.66400","18.72219","0.01628"
"37524","225.10800","18.75921","0.01748"
"37598","225.55200","18.79627","0.02089"
"37672","225.99600","18.83323","0.02254"
"37746","226.44000","18.87024","0.02236"
"37820","226.88400","18.90724","0.02285"
"37894","227.32800","18.94419","0.02361"
"37968","227.77200","18.98120","0.02434"
"38042","228.21600","19.01821","0.02623"
"38116","228.66000","19.05522","0.02824"
"38190","229.10400","19.09223","0.02938"
"38264","229.54800","19.12918","0.03163"
"38338","229.99200","19.16619","0.03325"
"38412","230.43600","19.20320","0.03302"
"38486","230.88000","19.24027","0.03489"
"38560","231.32400","19.27722","0.03621"
"38634","231.76800","19.31423","0.03746"
"38708","232.21200","19.35118","0.03924"
"38782","232.65600","19.38819","0.04158"
"38856","233.10000","19.42514","0.04272"
"38930","233.54400","19.46227","0.04429"
"39004","233.98800","19.49928","0.04616"
"39078","234.43200","19.53623","0.04713"
"39152","234.87600","19.57324","0.04795"
"39226","235.32000","19.61025","0.04971"
"39300","235.76400","19.64726","0.05132"
"39374","236.20800","19.68427","0.05305"
"39448","236.65200","19.72122","0.05463"
"39522","237.09600","19.75823","0.05804"
"39596","237.54000","19.79518","0.05970"
"39670","237.98400","19.83219","0.06066"
"39744","238.42800","19.86920","0.06460"
"39818","238.87200","19.90621","0.06809"
"39892","239.31600","19.94328","0.07097"
"39966","239.76000","19.98023","0.07225"
"40040","240.20400","20.01723","0.07365"
"40114","240.64800","20.05424","0.07577"
"40188","241.09200","20.09120","0.07649"
"40262","241.53600","20.12821","0.07841"
"40336","241.98000","20.16522","0.07950"
"40410","242.42400","20.20217","0.08184"
"40484","242.86800","20.23918","0.08359"
"40558","243.31200","20.27619","0.08526"
"40632","243.75600","20.31326","0.08673"
"40706","244.20000","20.35026","0.08064"
"40780","244.64400","20.38728","0.04503"
"40854","245.08800","20.42422","0.04875"
"40928","245.53200","20.46123","0.04644"
"41002","245.97600","20.49824","0.04801"
"41076","246.42000","20.53525","0.05097"
"41150","246.86400","20.57226","0.05132"
"41224","247.30800","20.60921","0.05200"
"41298","247.75200","20.64616","0.05569"
"41372","248.19600","20.68323","0.03416"
"41446","248.64000","20.72024","0.03672"
"41520","249.08400","20.75725","0.03891"
"41594","249.52800","20.79426","0.03908"
"41668","249.97200","20.83121","0.03908"
"41742","250.41600","20.86822","0.03647"
"41816","250.86000","20.90523","0.03885"
"41890","251.30400","20.94230","0.04127"
"41964","251.74800","20.97919","0.04274"
"42038","252.19200","21.01620","0.04476"
"42112","252.63600","21.05315","0.04607"
"42186","253.08000","21.09022","0.04839"
"42260","253.52400","21.12729","0.05052"
"42334","253.96800","21.16430","0.05237"
"42408","254.41200","21.20125","0.05466"
"42482","254.85600","21.23820","0.02903"
"42556","255.30000","21.27521","0.03227"
"42630","255.74400","21.31216","0.03596"
"42704","256.18800","21.34923","0.03948"
"42778","256.63200","21.38624","0.04127"
"42852","257.07600","21.42325","0.04312"
"42926","257.52000","21.46020","0.04537"
"43000","257.96400","21.49721","0.03517"
"43074","258.40800","21.53422","0.03615"
"43148","258.85200","21.57123","0.03773"
"43222","259.29600","21.60830","0.03982"
"43296","259.74000","21.64524","0.04220"
"43370","260.18400","21.68220","0.04318"
"43444","260.62800","21.71921","0.04530"
"43518","261.07200","21.75621","0.04572"
"43592","261.51600","21.79323","0.02261"
"43666","261.96000","21.83023","0.01866"
"43740","262.40400","21.86724","0.02001"
"43814","262.84800","21.90419","0.02257"
"43888","263.29200","21.94121","0.02514"
"43962","263.73600","21.97827","0.02530"
"44036","264.18000","22.01522","0.02570"
"44110","264.62400","22.05223","0.02674"
"44184","265.06800","22.08918","0.02774"
"44258","265.51200","22.12619","0.02908"
"44332","265.95600","22.16320","0.02972"
"44406","266.40000","22.20027","0.03078"
"44480","266.84400","22.23722","0.03049"
"44554","267.28800","22.27423","0.02704"
"44628","267.73200","22.31124","0.01702"
"44702","268.17600","22.34819","0.01129"
"44776","268.62000","22.38526","0.01466"
"44850","269.06400","22.42227","0.01637"
"44924","269.50800","22.45928","0.01779"
"44998","269.95200","22.49623","0.02102"
"45072","270.39600","22.53318","0.02130"
"45146","270.84000","22.57019","0.02194"
"45220","271.28400","22.60720","0.02460"
"45294","271.72800","22.64421","0.02590"
"45368","272.17200","22.68122","0.02513"
"45442","272.61600","22.71823","0.02699"
"45516","273.06000","22.75524","0.02754"
"45590","273.50400","22.79225","0.02927"
"45664","273.94800","22.82926","0.02961"
"45738","274.39200","22.86621","0.02986"
"45812","274.83600","22.90322","0.03137"
"45886","275.28000","22.94023","0.03212"
"45960","275.72400","22.97724","0.03310"
"46034","276.16800","23.01419","0.03323"
"46108","276.61200","23.05120","0.03599"
"46182","277.05600","23.08827","0.03643"
"46256","277.50000","23.12528","0.03843"
"46330","277.94400","23.16217","0.04031"
"46404","278.38800","23.19917","0.04212"
"46478","278.83200","23.23625","0.04309"
"46552","279.27600","23.27326","0.04482"
"46626","279.72000","23.31021","0.04700"
"46700","280.16400","23.34722","0.04878"
"46774","280.60800","23.38416","0.05011"
"46848","281.05200","23.42124","0.05178"
"46922","281.49600","23.45824","0.05298"
"46996","281.94000","23.49525","0.05536"
"47070","282.38400","23.53232","0.05836"
"47144","282.82800","23.56915","0.06140"
"47218","283.27200","23.60616","0.06429"
"47292","283.71600","23.64323","0.06631"
"47366","284.16000","23.68018","0.06832"
"47440","284.60400","23.71719","0.07132"
"47514","285.04800","23.75426","0.07258"
"47588","285.49200","23.79121","0.07460"
"47662","285.93600","23.82816","0.07621"
"47736","286.38000","23.86517","0.07817"
"47810","286.82400","23.90224","0.07942"
"47884","287.26800","23.93925","0.08098"
"47958","287.71200","23.97626","0.08306"
"48032","288.15600","24.01321","0.08440"
"48106","288.60000","24.05022","0.08639"
"48180","289.04400","24.08723","0.08793"
"48254","289.48800","24.12424","0.09052"
"48328","289.93200","24.16119","0.09293"
"48402","290.37600","24.19820","0.09513"
"48476","290.82000","24.23515","0.09720"
"48550","291.26400","24.27222","0.09868"
"48624","291.70800","24.30929","0.10009"
"48698","292.15200","24.34630","0.10149"
"48772","292.59600","24.38331","0.10297"
"48846","293.04000","24.42026","0.02810"
"48920","293.48400","24.45721","0.01795"
"48994","293.92800","24.49422","0.01757"
"49068","294.37200","24.53123","0.01956"
"49142","294.81600","24.56824","0.02183"
"49216","295.26000","24.60525","0.02646"
"49290","295.70400","24.64220","0.02242"
"49364","296.14800","24.67921","0.02294"
"49438","296.59200","24.71628","0.02839"
"49512","297.03600","24.75322","0.02713"
"49586","297.48000","24.79030","0.02808"
"49660","297.92400","24.82719","0.03143"
"49734","298.36800","24.86419","0.03079"
"49808","298.81200","24.90120","0.03270"
"49882","299.25600","24.93821","0.03598"
"49956","299.70000","24.97522","0.03386"
"50030","300.14400","25.01223","0.03516"
"50104","300.58800","25.04918","0.03873"
"50178","301.03200","25.08619","0.03817"
"50252","301.47600","25.12320","0.03805"
"50326","301.92000","25.16021","0.03997"
"50400","302.36400","25.19722","0.04204"
"50474","302.80800","25.23429","0.04176"
"50548","303.25200","25.27124","0.04203"
"50622","303.69600","25.30819","0.04395"
"50696","304.14000","25.34526","0.04536"
"50770","304.58400","25.38227","0.04520"
"50844","305.02800","25.41922","0.04577"
"50918","305.47200","25.45623","0.04729"
"50992","305.91600","25.49318","0.04873"
"51066","306.36000","25.53019","0.04871"
"51140","306.80400","25.56726","0.04867"
"51214","307.24800","25.60427","0.05038"
"51288","307.69200","25.64122","0.05181"
"51362","308.13600","25.67823","0.05220"
"51436","308.58000","25.71512","0.05237"
"51510","309.02400","25.75219","0.05412"
"51584","309.46800","25.78920","0.03627"
"51658","309.91200","25.82621","0.03509"
"51732","310.35600","25.86328","0.03547"
"51806","310.80000","25.90023","0.03600"
"51880","311.24400","25.93718","0.03530"
"51954","311.68800","25.97419","0.03616"
"52028","312.13200","26.01126","0.03568"
"52102","312.57600","26.04827","0.03705"
"52176","313.02000","26.08522","0.03766"
"52250","313.46400","26.12217","0.03848"
"52324","313.90800","26.15917","0.03861"
"52398","314.35200","26.19619","0.03968"
"52472","314.79600","26.23325","0.03999"
"52546","315.24000","26.27027","0.04008"
"52620","315.68400","26.30722","0.04148"
"52694","316.12800","26.34423","0.04168"
"52768","316.57200","26.38117","0.04185"
"52842","317.01600","26.41825","0.04298"
"52916","317.46000","26.45520","0.04337"
"52990","317.90400","26.49220","0.04384"
"53064","318.34800","26.52921","0.04405"
"53138","318.79200","26.56616","0.04485"
"53212","319.23600","26.60323","0.04495"
"53286","319.68000","26.64024","0.04613"
"53360","320.12400","26.67725","0.04642"
"53434","320.56800","26.71432","0.04690"
"53508","321.01200","26.75121","0.04718"
"53582","321.45600","26.78816","0.04785"
"53656","321.90000","26.82523","0.04804"
"53730","322.34400","26.86224","0.04826"
"53804","322.78800","26.89919","0.04885"
"53878","323.23200","26.93620","0.04824"
"53952","323.67600","26.97315","0.04918"
"54026","324.12000","27.01022","0.04993"
"54100","324.56400","27.04723","0.05026"
"54174","325.00800","27.08424","0.05085"
"54248","325.45200","27.12125","0.05099"
"54322","325.89600","27.15820","0.05204"
"54396","326.34000","27.19515","0.05272"
"54470","326.78400","27.23222","0.05361"
"54544","327.22800","27.26923","0.05472"
"54618","327.67200","27.30624","0.05522"
"54692","328.11600","27.34325","0.05614"
"54766","328.56000","27.38020","0.05690"
"54840","329.00400","27.41721","0.05766"
"54914","329.44800","27.45422","0.00002"
"54988","329.89200","27.49129","0.00052"
"55062","330.33600","27.52830","-0.00001"
"55136","330.78000","27.56525","-0.00034"
"55210","331.22400","27.60220","0.00359"
"55284","331.66800","27.63921","-0.00066"
"55358","332.11200","27.67622","0.00379"
"55432","332.55600","27.71329","0.00009"
"55506","333.00000","27.75024","0.00123"
"55580","333.44400","27.78718","0.00049"
"55654","333.88800","27.82420","0.00103"
"55728","334.33200","27.86120","0.00170"
"55802","334.77600","27.89821","0.00050"
"55876","335.22000","27.93523","0.00312"
"55950","335.66400","27.97229","0.00119"
"56024","336.10800","28.00924","0.00402"
"56098","336.55200","28.04619","0.00166"
"56172","336.99600","28.08320","0.00471"
"56246","337.44000","28.12021","0.00239"
"56320","337.88400","28.15722","0.00501"
"56394","338.32800","28.19423","0.00326"
"56468","338.77200","28.23118","0.00522"
"56542","339.21600","28.26819","0.00464"
"56616","339.66000","28.30520","0.00461"
"56690","340.10400","28.34221","0.00438"
"56764","340.54800","28.37922","0.00528"
"56838","340.99200","28.41623","0.00625"
"56912","341.43600","28.45318","0.00575"
"56986","341.88000","28.49013","0.00726"
"57060","342.32400","28.52720","0.00706"
"57134","342.76800","28.56427","0.00767"
"57208","343.21200","28.60128","0.00733"
"57282","343.65600","28.63823","0.00862"
"57356","344.10000","28.67518","0.00866"
"57430","344.54400","28.71219","0.00924"
"57504","344.98800","28.74920","0.00962"
"57578","345.43200","28.78627","0.01043"
"57652","345.87600","28.82322","0.01097"
"57726","346.32000","28.86023","0.01133"
"57800","346.76400","28.89712","0.01198"
"57874","347.20800","28.93419","0.01242"
"57948","347.65200","28.97126","0.01352"
"58022","348.09600","29.00821","0.01394"
"58096","348.54000","29.04528","0.01285"
"58170","348.98400","29.08223","0.01287"
"58244","349.42800","29.11918","0.01334"
"58318","349.87200","29.15619","0.01391"
"58392","350.31600","29.19326","0.01455"
"58466","350.76000","29.23021","0.01513"
"58540","351.20400","29.26722","0.01158"
"58614","351.64800","29.30417","0.01067"
"58688","352.09200","29.34124","0.00988"
"58762","352.53600","29.37824","0.01036"
"58836","352.98000","29.41525","0.01019"
"58910","353.42400","29.45227","0.00994"
"58984","353.86800","29.48921","0.01027"
"59058","354.31200","29.52622","0.01141"
"59132","354.75600","29.56318","0.01131"
"59206","355.20000","29.60024","0.01154"
"59280","355.64400","29.63725","0.01269"
"59354","356.08800","29.67426","0.01013"
"59428","356.53200","29.71115","0.01074"
"59502","356.97600","29.74822","0.01042"
"59576","357.42000","29.78523","0.01186"
"59650","357.86400","29.82230","0.01226"
"59724","358.30800","29.85931","0.01266"
"59798","358.75200","29.89626","0.00973"
"59872","359.19600","29.93321","0.00558"
"59946","359.64000","29.97016","0.00317"
"60020","360.08400","30.00723","0.00249"
"60094","360.52800","30.04424","0.00118"
"60168","360.97200","30.08125","0.00051"
"60242","361.41600","30.11820","0.00099"
"60316","361.86000","30.15515","0.00044"
"60390","362.30400","30.19222","0.00125"
"60464","362.74800","30.22923","0.00079"
"60538","363.19200","30.26624","0.00121"
"60612","363.63600","30.30331","0.00076"
"60686","364.08000","30.34020","0.00124"
"60760","364.52400","30.37715","0.00110"
"60834","364.96800","30.41422","0.00116"
"60908","365.41200","30.45123","0.00104"
"60982","365.85600","30.48824","0.00105"
"61056","366.30000","30.52525","0.00095"
"61130","366.74400","30.56220","0.00106"
"61204","367.18800","30.59921","0.00119"
"61278","367.63200","30.63622","0.00112"
"61352","368.07600","30.67329","0.00134"
"61426","368.52000","30.71024","0.00154"
"61500","368.96400","30.74725","0.00132"
"61574","369.40800","30.78414","0.00139"
"61648","369.85200","30.82121","0.00139"
"61722","370.29600","30.85822","0.00126"
"61796","370.74000","30.89528","0.00121"
"61870","371.18400","30.93224","0.00168"
"61944","371.62800","30.96924","0.00128"
"62018","372.07200","31.00620","0.00120"
"62092","372.51600","31.04321","0.00135"
"62166","372.96000","31.08027","0.00153"
"62240","373.40400","31.11722","0.00186"
"62314","373.84800","31.15423","0.00157"
"62388","374.29200","31.19118","0.00169"
"62462","374.73600","31.22813","0.00165"
"62536","375.18000","31.26520","0.00187"
"62610","375.62400","31.30227","0.00197"
"62684","376.06800","31.33922","0.00173"
"62758","376.51200","31.37623","0.00176"
"62832","376.95600","31.41324","0.00161"
"62906","377.40000","31.45019","0.00178"
"62980","377.84400","31.48726","0.00191"
"63054","378.28800","31.52427","0.00231"
"63128","378.73200","31.56122","0.00211"
"63202","379.17600","31.59823","0.00211"
"63276","379.62000","31.63518","0.00226"
"63350","380.06400","31.67219","0.00223"
"63424","380.50800","31.70926","0.00244"
"63498","380.95200","31.74627","0.00215"
"63572","381.39600","31.78328","0.00195"
"63646","381.84000","31.82029","0.00198"
"63720","382.28400","31.85712","0.00222"
"63794","382.72800","31.89425","0.00272"
"63868","383.17200","31.93126","0.00257"
"63942","383.61600","31.96827","0.00194"
"64016","384.06000","32.00528","0.00178"
"64090","384.50400","32.04217","0.00102"
"64164","384.94800","32.07917","0.00125"
"64238","385.39200","32.11618","0.00109"
"64312","385.83600","32.15326","0.00122"
"64386","386.28000","32.19027","0.00118"
"64460","386.72400","32.22721","0.00093"
"64534","387.16800","32.26423","0.00150"
"64608","387.61200","32.30118","0.00149"
"64682","388.05600","32.33818","0.00104"
"64756","388.50000","32.37526","0.00137"
"64830","388.94400","32.41220","0.00137"
"64904","389.38800","32.44921","0.00143"
"64978","389.83200","32.48616","0.00109"
"65052","390.27600","32.52317","0.00139"
"65126","390.72000","32.56030","0.00103"
"65200","391.16400","32.59725","0.00149"
"65274","391.60800","32.63426","0.00152"
"65348","392.05200","32.67115","0.00146"
"65422","392.49600","32.70816","0.00152"
"65496","392.94000","32.74523","0.00131"
"65570","393.38400","32.78224","0.00144"
"65644","393.82800","32.81919","0.00130"
"65718","394.27200","32.85620","0.00151"
"65792","394.71600","32.89321","0.00136"
"65866","395.16000","32.93022","0.00133"
"65940","395.60400","32.96723","0.00140"
"66014","396.04800","33.00424","0.00145"
"66088","396.49200","33.04125","0.00113"
"66162","396.93600","33.07820","0.00126"
"66236","397.38000","33.11521","0.00130"
"66310","397.82400","33.15216","0.00123"
"66384","398.26800","33.18917","0.00158"
"66458","398.71200","33.22624","0.00124"
"66532","399.15600","33.26325","0.00135"
"66606","399.60000","33.30020","0.00157"
"66680","400.04400","33.33721","0.00118"
"66754","400.48800","33.37422","0.00153"
"66828","400.93200","33.41123","0.00162"
"66902","401.37600","33.44830","0.00135"
"66976","401.82000","33.48525","0.00173"
"67050","402.26400","33.52220","0.00151"
"67124","402.70800","33.55915","0.00154"
"67198","403.15200","33.59622","0.00141"
"67272","403.59600","33.63322","0.00141"
"67346","404.04000","33.67023","0.00177"
"67420","404.48400","33.70724","0.00166"
"67494","404.92800","33.74420","0.00150"
"67568","405.37200","33.78127","0.00197"
"67642","405.81600","33.81821","0.00177"
"67716","406.26000","33.85529","0.00187"
"67790","406.70400","33.89223","0.00195"
"67864","407.14800","33.92924","0.00217"
"67938","407.59200","33.96619","0.00184"
"68012","408.03600","34.00314","0.00219"
"68086","408.48000","34.04021","0.00230"
"68160","408.92400","34.07728","0.00217"
"68234","409.36800","34.11429","0.00231"
"68308","409.81200","34.15124","0.00245"
"68382","410.25600","34.18819","0.00221"
"68456","410.70000","34.22520","0.00225"
"68530","411.14400","34.26221","0.00189"
"68604","411.58800","34.29922","0.00234"
"68678","412.03200","34.33623","0.00236"
"68752","412.47600","34.37318","0.00232"
"68826","412.92000","34.41025","0.00216"
"68900","413.36400","34.44720","0.00219"
"68974","413.80800","34.48427","-0.00001"
"69048","414.25200","34.52128","-0.00004"
"69122","414.69600","34.55829","-0.00016"
"69196","415.14000","34.59518","-0.00036"
"69270","415.58400","34.63219","0.00045"
"69344","416.02800","34.66926","-0.00006"
"69418","416.47200","34.70627","-0.00022"
"69492","416.91600","34.74328","-0.00012"
"69566","417.36000","34.78017","-0.00006"
"69640","417.80400","34.81718","-0.00014"
"69714","418.24800","34.85419","0.00014"
"69788","418.69200","34.89126","-0.00011"
"69862","419.13600","34.92826","-0.00019"
"69936","419.58000","34.96522","-0.00021"
"70010","420.02400","35.00217","0.00046"
"70084","420.46800","35.03918","0.00019"
"70158","420.91200","35.07624","-0.00036"
"70232","421.35600","35.11325","0.00029"
"70306","421.80000","35.15021","0.00053"
"70380","422.24400","35.18721","0.00026"
"70454","422.68800","35.22417","0.00001"
"70528","423.13200","35.26118","0.00015"
"70602","423.57600","35.29825","-0.00002"
"70676","424.02000","35.33525","-0.00029"
"70750","424.46400","35.37226","0.00006"
"70824","424.90800","35.40921","-0.00022"
"70898","425.35200","35.44616","-0.00023"
"70972","425.79600","35.48323","-0.00002"
"71046","426.24000","35.52018","-0.00025"
"71120","426.68400","35.55725","-0.00005"
"71194","427.12800","35.59426","0.00002"
"71268","427.57200","35.63121","-0.00001"
"71342","428.01600","35.66816","0.00026"
"71416","428.46000","35.70523","-0.00021"
"71490","428.90400","35.74230","0.00011"
"71564","429.34800","35.77925","-0.00004"
"71638","429.79200","35.81620","0.00007"
"71712","430.23600","35.85321","0.00000"
"71786","430.68000","35.89022","-0.00011"
"71860","431.12400","35.92717","0.00011"
"71934","431.56800","35.96418","0.00032"
"72008","432.01200","36.00119","0.00033"
"72082","432.45600","36.03826","0.00002"
"72156","432.90000","36.07515","0.00002"
"72230","433.34400","36.11222","0.00023"
"72304","433.78800","36.14929","-0.00006"
"72378","434.23200","36.18624","0.00005"
"72452","434.67600","36.22325","0.00027"
"72526","435.12000","36.26020","0.00035"
"72600","435.56400","36.29721","-0.00024"
"72674","436.00800","36.33422","0.00029"
"72748","436.45200","36.37123","-0.00009"
"72822","436.89600","36.40824","0.00007"
"72896","437.34000","36.44525","0.00038"
"72970","437.78400","36.48225","0.00006"
"73044","438.22800","36.51921","0.00033"
"73118","438.67200","36.55628","0.00003"
"73192","439.11600","36.59323","0.00012"
"73266","439.56000","36.63023","0.00013"
"73340","440.00400","36.66719","0.00021"
"73414","440.44800","36.70426","0.00012"
"73488","440.89200","36.74120","0.00002"
"73562","441.33600","36.77821","0.00031"
"73636","441.78000","36.81528","0.00013"
"73710","442.22400","36.85229","0.00016"
"73784","442.66800","36.88924","0.00003"
"73858","443.11200","36.92619","0.00033"
"73932","443.55600","36.96315","0.00015"
"74006","444.00000","37.00027","0.00010"
"74080","444.44400","37.03728","0.00012"
"74154","444.88800","37.07423","-0.00002"
"74228","445.33200","37.11119","0.00023"
"74302","445.77600","37.14813","0.00008"
"74376","446.22000","37.18520","0.00039"
"74450","446.66400","37.22221","0.00016"
"74524","447.10800","37.25928","0.00001"
"74598","447.55200","37.29629","0.00011"
"74672","447.99600","37.33318","0.00026"
"74746","448.44000","37.37019","0.00036"
"74820","448.88400","37.40720","0.00025"
"74894","449.32800","37.44427","0.00049"
"74968","449.77200","37.48122","0.00029"
"75042","450.21600","37.51823","0.00047"
"75116","450.66000","37.55518","0.00062"
"75190","451.10400","37.59219","0.00020"
"75264","451.54800","37.62920","0.00037"
"75338","451.99200","37.66627","0.00021"
"75412","452.43600","37.70322","-0.00008"
"75486","452.88000","37.74023","0.00049"
"75560","453.32400","37.77718","0.00030"
"75634","453.76800","37.81419","0.00051"
"75708","454.21200","37.85120","0.00023"
"75782","454.65600","37.88821","0.00015"
"75856","455.10000","37.92522","0.00050"
"75930","455.54400","37.96217","0.00033"
"76004","455.98800","37.99918","0.00029"
"76078","456.43200","38.03619","0.00035"
"76152","456.87600","38.07326","0.00066"
"76226","457.32000","38.11027","0.00069"
"76300","457.76400","38.14722","0.00061"
"76374","458.20800","38.18423","0.00059"
"76448","458.65200","38.22118","0.00063"
"76522","459.09600","38.25819","0.00037"
"76596","459.54000","38.29526","0.00048"
"76670","459.98400","38.33226","0.00026"
"76744","460.42800","38.36922","0.00024"
"76818","460.87200","38.40617","0.00046"
"76892","461.31600","38.44317","0.00058"
"76966","461.76000","38.48024","0.00026"
"77040","462.20400","38.51731","0.00014"
"77114","462.64800","38.55427","0.00041"
"77188","463.09200","38.59121","0.00020"
"77262","463.53600","38.62817","0.00036"
"77336","463.98000","38.66523","0.00063"
"77410","464.42400","38.70218","0.00047"
"77484","464.86800","38.73919","0.00024"
"77558","465.31200","38.77626","0.00041"
"77632","465.75600","38.81327","-0.00013"
"77706","466.20000","38.85022","0.00035"
"77780","466.64400","38.88723","0.00017"
"77854","467.08800","38.92424","0.00039"
"77928","467.53200","38.96125","0.00051"
"78002","467.97600","38.99826","0.00033"
"78076","468.42000","39.03515","0.00057"
"78150","468.86400","39.07222","0.00054"
"78224","469.30800","39.10923","0.00045"
"78298","469.75200","39.14624","0.00065"
"78372","470.19600","39.18325","0.00021"
"78446","470.64000","39.22020","0.00041"
"78520","471.08400","39.25721","0.00024"
"78594","471.52800","39.29422","0.00065"
"78668","471.97200","39.33123","0.00067"
"78742","472.41600","39.36824","0.00025"
"78816","472.86000","39.40525","0.00062"
"78890","473.30400","39.44220","0.00066"
"78964","473.74800","39.47915","0.00047"
"79038","474.19200","39.51622","0.00050"
"79112","474.63600","39.55323","0.00053"
"79186","475.08000","39.59024","0.00018"
"79260","475.52400","39.62731","0.00063"
"79334","475.96800","39.66425","0.00060"
"79408","476.41200","39.70115","0.00054"
"79482","476.85600","39.73822","0.00057"
"79556","477.30000","39.77528","0.00066"
"79630","477.74400","39.81224","0.00035"
"79704","478.18800","39.84919","0.00062"
"79778","478.63200","39.88613","0.00054"
"79852","479.07600","39.92321","0.00020"
"79926","479.52000","39.96022","0.00028"
"80000","479.96400","39.99722","0.00042"
"80074","480.40800","40.03429","0.00046"
"80148","480.85200","40.07118","0.00052"
"80222","481.29600","40.10819","0.00069"
"80296","481.74000","40.14526","0.00075"
"80370","482.18400","40.18221","0.00045"
"80444","482.62800","40.21923","0.00021"
"80518","483.07200","40.25617","0.00042"
"80592","483.51600","40.29318","0.00054"
"80666","483.96000","40.33019","0.00059"
"80740","484.40400","40.36720","0.00104"
"80814","484.84800","40.40427","0.00015"
"80888","485.29200","40.44128","0.00023"
"80962","485.73600","40.47829","0.00045"
"81036","486.18000","40.51524","0.00038"
"81110","486.62400","40.55213","0.00048"
"81184","487.06800","40.58926","0.00009"
"81258","487.51200","40.62621","0.00006"
"81332","487.95600","40.66322","0.00044"
"81406","488.40000","40.70023","0.00080"
"81480","488.84400","40.73712","0.00036"
"81554","489.28800","40.77425","0.00047"
"81628","489.73200","40.81120","0.00037"
"81702","490.17600","40.84827","0.00068"
"81776","490.62000","40.88534","0.00069"
"81850","491.06400","40.92217","0.00068"
"81924","491.50800","40.95918","0.00053"
"81998","491.95200","40.99619","0.00039"
"82072","492.39600","41.03326","0.00059"
"82146","492.84000","41.07027","0.00030"
"82220","493.28400","41.10722","0.00069"
"82294","493.72800","41.14416","0.00022"
"82368","494.17200","41.18118","0.00033"
"82442","494.61600","41.21825","0.00012"
"82516","495.06000","41.25526","0.00076"
"82590","495.50400","41.29227","0.00089"
"82664","495.94800","41.32921","0.00067"
"82738","496.39200","41.36622","0.00114"
"82812","496.83600","41.40318","0.00100"
"82886","497.28000","41.44025","0.00107"
"82960","497.72400","41.47726","0.00153"
"83034","498.16800","41.51421","0.00129"
"83108","498.61200","41.55121","0.00148"
"83182","499.05600","41.58823","0.00159"
"83256","499.50000","41.62524","0.00177"
"83330","499.94400","41.66225","0.00172"
"83404","500.38800","41.69925","0.00182"
"83478","500.83200","41.73626","0.00229"
"83552","501.27600","41.77321","0.00212"
"83626","501.72000","41.81016","0.00224"
"83700","502.16400","41.84717","0.00237"
"83774","502.60800","41.88424","0.00274"
"83848","503.05200","41.92125","0.00260"
"83922","503.49600","41.95820","0.00280"
"83996","503.94000","41.99521","0.00284"
"84070","504.38400","42.03222","0.00313"
"84144","504.82800","42.06923","0.00338"
"84218","505.27200","42.10624","0.00381"
"84292","505.71600","42.14325","0.00380"
"84366","506.16000","42.18020","0.00433"
"84440","506.60400","42.21715","0.00396"
"84514","507.04800","42.25416","0.00441"
"84588","507.49200","42.29123","0.00434"
"84662","507.93600","42.32824","0.00505"
"84736","508.38000","42.36525","0.00500"
"84810","508.82400","42.40220","0.00551"
"84884","509.26800","42.43914","0.00544"
"84958","509.71200","42.47622","0.00597"
"85032","510.15600","42.51323","0.00600"
"85106","510.60000","42.55024","0.00676"
"85180","511.04400","42.58724","0.00652"
"85254","511.48800","42.62414","0.00698"
"85328","511.93200","42.66121","0.00721"
"85402","512.37600","42.69822","0.00732"
"85476","512.82000","42.73529","0.00786"
"85550","513.26400","42.77224","0.00796"
"85624","513.70800","42.80919","0.00880"
"85698","514.15200","42.84620","0.00897"
"85772","514.59600","42.88320","0.00960"
"85846","515.04000","42.92022","0.00926"
"85920","515.48400","42.95723","0.01039"
"85994","515.92800","42.99423","0.01070"
"86068","516.37200","43.03119","0.01087"
"86142","516.81600","43.06814","0.01180"
"86216","517.26000","43.10521","0.01201"
"86290","517.70400","43.14222","0.01201"
"86364","518.14800","43.17928","0.01237"
"86438","518.59200","43.21630","0.01382"
"86512","519.03600","43.25324","0.01396"
"86586","519.48000","43.29013","0.01385"
"86660","519.92400","43.32721","0.01425"
"86734","520.36800","43.36427","0.01503"
"86808","520.81200","43.40128","0.01526"
"86882","521.25600","43.43823","0.01628"
"86956","521.70000","43.47519","0.01606"
"87030","522.14400","43.51219","0.01663"
"87104","522.58800","43.54926","0.01732"
"87178","523.03200","43.58627","0.01746"
"87252","523.47600","43.62328","0.01795"
"87326","523.92000","43.66023","0.01907"
"87400","524.36400","43.69718","0.01919"
"87474","524.80800","43.73425","0.01983"
"87548","525.25200","43.77119","0.01186"
"87622","525.69600","43.80821","0.01264"
"87696","526.14000","43.84528","0.01146"
"87770","526.58400","43.88223","0.01254"
"87844","527.02800","43.91918","0.01302"
"87918","527.47200","43.95619","0.01259"
"87992","527.91600","43.99326","0.01463"
"88066","528.36000","44.03021","0.01294"
"88140","528.80400","44.06728","0.01552"
"88214","529.24800","44.10417","0.01449"
"88288","529.69200","44.14117","0.01520"
"88362","530.13600","44.17818","0.01593"
"88436","530.58000","44.21526","0.01580"
"88510","531.02400","44.25220","0.01651"
"88584","531.46800","44.28922","0.01632"
"88658","531.91200","44.32623","0.01687"
"88732","532.35600","44.36324","0.01765"
"88806","532.80000","44.40025","0.01785"
"88880","533.24400","44.43726","0.01754"
"88954","533.68800","44.47427","0.01815"
"89028","534.13200","44.51122","0.01854"
"89102","534.57600","44.54816","0.01844"
"89176","535.02000","44.58517","0.00332"
"89250","535.46400","44.62218","-0.00037"
"89324","535.90800","44.65925","-0.00035"
"89398","536.35200","44.69626","-0.00086"
"89472","536.79600","44.73327","-0.00049"
"89546","537.24000","44.77016","-0.00064"
"89620","537.68400","44.80723","-0.00069"
"89694","538.12800","44.84424","-0.00040"
"89768","538.57200","44.88120","-0.00048"
"89842","539.01600","44.91820","-0.00047"
"89916","539.46000","44.95521","-0.00054"
"89990","539.90400","44.99216","-0.00063"
"90064","540.34800","45.02923","-0.00077"
"90138","540.79200","45.06618","-0.00081"
"90212","541.23600","45.10325","-0.00056"
"90286","541.68000","45.14020","-0.00052"
"90352","542.07200","45.17285","-0.00068"