File: Trajectories_together/161218Specimen_RawData_1.csv
"","V1","V2","V3"
"1","End date","12/18/2016",""
"2","Specimen label","",""
"3","Maximum Load","0.00305","N"
"4","Time","Extension","Load"
"5","(s)","(mm)","(N)"
"6","0.00000","-0.00024","0.00233"
"7","0.00600","-0.00024","0.00225"
"8","0.01200","-0.00024","0.00229"
"9","0.01800","-0.00012","0.00230"
"10","0.02400","0.00000","0.00221"
"11","0.03000","0.00006","0.00218"
"12","0.03600","0.00018","0.00213"
"13","0.04200","0.00036","0.00216"
"14","0.04800","0.00054","0.00229"
"15","0.05400","0.00072","0.00240"
"16","0.06000","0.00096","0.00242"
"17","0.06600","0.00126","0.00235"
"18","0.07200","0.00155","0.00233"
"19","0.07800","0.00185","0.00244"
"20","0.08400","0.00221","0.00250"
"21","0.09000","0.00263","0.00252"
"22","0.09600","0.00305","0.00258"
"23","0.10200","0.00347","0.00255"
"24","0.10800","0.00395","0.00248"
"25","0.11400","0.00442","0.00261"
"26","0.12000","0.00496","0.00268"
"27","0.12600","0.00550","0.00273"
"28","0.13200","0.00610","0.00271"
"29","0.13800","0.00664","0.00265"
"30","0.14400","0.00723","0.00256"
"31","0.15000","0.00789","0.00249"
"32","0.15600","0.00855","0.00245"
"33","0.16200","0.00915","0.00249"
"34","0.16800","0.00987","0.00245"
"35","0.17400","0.01052","0.00238"
"36","0.18000","0.01118","0.00235"
"37","0.18600","0.01184","0.00230"
"38","0.19200","0.01250","0.00232"
"39","0.19800","0.01321","0.00234"
"40","0.20400","0.01387","0.00240"
"41","0.21000","0.01453","0.00244"
"42","0.21600","0.01519","0.00239"
"43","0.22200","0.01590","0.00240"
"44","0.22800","0.01656","0.00247"
"45","0.23400","0.01722","0.00253"
"46","0.24000","0.01788","0.00252"
"47","0.24600","0.01853","0.00248"
"48","0.25200","0.01919","0.00248"
"49","0.25800","0.01979","0.00248"
"50","0.26400","0.02045","0.00248"
"51","0.27000","0.02111","0.00248"
"52","0.27600","0.02176","0.00241"
"53","0.28200","0.02236","0.00230"
"54","0.28800","0.02296","0.00222"
"55","0.29400","0.02356","0.00223"
"56","0.30000","0.02415","0.00222"
"57","0.30600","0.02475","0.00223"
"58","0.31200","0.02529","0.00221"
"59","0.31800","0.02589","0.00219"
"60","0.32400","0.02643","0.00220"
"61","0.33000","0.02702","0.00229"
"62","0.33600","0.02756","0.00238"
"63","0.34200","0.02816","0.00250"
"64","0.34800","0.02870","0.00254"
"65","0.35400","0.02924","0.00254"
"66","0.36000","0.02978","0.00255"
"67","0.36600","0.03031","0.00260"
"68","0.37200","0.03085","0.00261"
"69","0.37800","0.03133","0.00266"
"70","0.38400","0.03187","0.00262"
"71","0.39000","0.03241","0.00259"
"72","0.39600","0.03294","0.00254"
"73","0.40200","0.03348","0.00253"
"74","0.40800","0.03402","0.00256"
"75","0.41400","0.03450","0.00261"
"76","0.42000","0.03504","0.00258"
"77","0.42600","0.03551","0.00257"
"78","0.43200","0.03599","0.00262"
"79","0.43800","0.03653","0.00266"
"80","0.44400","0.03701","0.00264"
"81","0.45000","0.03749","0.00256"
"82","0.45600","0.03803","0.00254"
"83","0.46200","0.03850","0.00254"
"84","0.46800","0.03898","0.00257"
"85","0.47400","0.03952","0.00261"
"86","0.48000","0.04000","0.00268"
"87","0.48600","0.04048","0.00269"
"88","0.49200","0.04096","0.00268"
"89","0.49800","0.04149","0.00264"
"90","0.50400","0.04197","0.00263"
"91","0.51000","0.04245","0.00265"
"92","0.51600","0.04299","0.00266"
"93","0.52200","0.04353","0.00266"
"94","0.52800","0.04401","0.00265"
"95","0.53400","0.04454","0.00254"
"96","0.54000","0.04502","0.00251"
"97","0.54600","0.04556","0.00259"
"98","0.55200","0.04604","0.00259"
"99","0.55800","0.04652","0.00254"
"100","0.56400","0.04705","0.00252"
"101","0.57000","0.04753","0.00253"
"102","0.57600","0.04801","0.00250"
"103","0.58200","0.04849","0.00246"
"104","0.58800","0.04903","0.00249"
"105","0.59400","0.04951","0.00253"
"106","0.60000","0.04998","0.00256"
"107","0.60600","0.05052","0.00259"
"108","0.61200","0.05100","0.00258"
"109","0.61800","0.05148","0.00246"
"110","0.62400","0.05196","0.00234"
"111","0.63000","0.05250","0.00236"
"112","0.63600","0.05297","0.00238"
"113","0.64200","0.05351","0.00240"
"114","0.64800","0.05399","0.00238"
"115","0.65400","0.05447","0.00231"
"116","0.66000","0.05501","0.00221"
"117","0.66600","0.05548","0.00217"
"118","0.67200","0.05602","0.00225"
"119","0.67800","0.05650","0.00239"
"120","0.68400","0.05698","0.00251"
"121","0.69000","0.05752","0.00254"
"122","0.69600","0.05800","0.00256"
"123","0.70200","0.05847","0.00253"
"124","0.70800","0.05895","0.00251"
"125","0.71400","0.05949","0.00256"
"126","0.72000","0.05997","0.00255"
"127","0.72600","0.06045","0.00249"
"128","0.73200","0.06093","0.00238"
"129","0.73800","0.06146","0.00226"
"130","0.74400","0.06194","0.00219"
"131","0.75000","0.06242","0.00215"
"132","0.75600","0.06296","0.00217"
"133","0.76200","0.06344","0.00227"
"134","0.76800","0.06397","0.00233"
"135","0.77400","0.06445","0.00230"
"136","0.78000","0.06499","0.00227"
"137","0.78600","0.06547","0.00228"
"138","0.79200","0.06595","0.00227"
"139","0.79800","0.06649","0.00226"
"140","0.80400","0.06696","0.00226"
"141","0.81000","0.06744","0.00226"
"142","0.81600","0.06798","0.00225"
"143","0.82200","0.06846","0.00226"
"144","0.82800","0.06900","0.00234"
"145","0.83400","0.06948","0.00243"
"146","0.84000","0.07001","0.00242"
"147","0.84600","0.07049","0.00234"
"148","0.85200","0.07097","0.00219"
"149","0.85800","0.07151","0.00209"
"150","0.86400","0.07199","0.00213"
"151","0.87000","0.07246","0.00223"
"152","0.87600","0.07300","0.00227"
"153","0.88200","0.07348","0.00224"
"154","0.88800","0.07396","0.00222"
"155","0.89400","0.07450","0.00230"
"156","0.90000","0.07498","0.00228"
"157","0.90600","0.07545","0.00230"
"158","0.91200","0.07599","0.00242"
"159","0.91800","0.07647","0.00247"
"160","0.92400","0.07695","0.00249"
"161","0.93000","0.07749","0.00251"
"162","0.93600","0.07797","0.00254"
"163","0.94200","0.07850","0.00262"
"164","0.94800","0.07898","0.00268"
"165","0.95400","0.07946","0.00265"
"166","0.96000","0.08000","0.00267"
"167","0.96600","0.08048","0.00268"
"168","0.97200","0.08096","0.00272"
"169","0.97800","0.08143","0.00275"
"170","0.98400","0.08197","0.00273"
"171","0.99000","0.08245","0.00269"
"172","0.99600","0.08293","0.00264"
"173","1.00200","0.08341","0.00251"
"174","1.00800","0.08388","0.00236"
"175","1.01400","0.08442","0.00228"
"176","1.02000","0.08490","0.00221"
"177","1.02600","0.08538","0.00224"
"178","1.03200","0.08592","0.00240"
"179","1.03800","0.08640","0.00250"
"180","1.04400","0.08693","0.00255"
"181","1.05000","0.08741","0.00253"
"182","1.05600","0.08795","0.00251"
"183","1.06200","0.08849","0.00252"
"184","1.06800","0.08897","0.00249"
"185","1.07400","0.08945","0.00243"
"186","1.08000","0.08998","0.00246"
"187","1.08600","0.09046","0.00253"
"188","1.09200","0.09100","0.00254"
"189","1.09800","0.09148","0.00255"
"190","1.10400","0.09202","0.00256"
"191","1.11000","0.09249","0.00263"
"192","1.11600","0.09297","0.00262"
"193","1.12200","0.09351","0.00261"
"194","1.12800","0.09399","0.00260"
"195","1.13400","0.09447","0.00252"
"196","1.14000","0.09501","0.00247"
"197","1.14600","0.09548","0.00245"
"198","1.15200","0.09596","0.00246"
"199","1.15800","0.09650","0.00243"
"200","1.16400","0.09698","0.00247"
"201","1.17000","0.09746","0.00244"
"202","1.17600","0.09800","0.00241"
"203","1.18200","0.09853","0.00243"
"204","1.18800","0.09901","0.00250"
"205","1.19400","0.09955","0.00253"
"206","1.20000","0.10003","0.00250"
"207","1.20600","0.10057","0.00247"
"208","1.21200","0.10104","0.00248"
"209","1.21800","0.10152","0.00243"
"210","1.22400","0.10206","0.00234"
"211","1.23000","0.10254","0.00230"
"212","1.23600","0.10302","0.00230"
"213","1.24200","0.10350","0.00237"
"214","1.24800","0.10403","0.00242"
"215","1.25400","0.10451","0.00245"
"216","1.26000","0.10499","0.00246"
"217","1.26600","0.10553","0.00244"
"218","1.27200","0.10601","0.00246"
"219","1.27800","0.10649","0.00254"
"220","1.28400","0.10696","0.00250"
"221","1.29000","0.10744","0.00242"
"222","1.29600","0.10798","0.00235"
"223","1.30200","0.10846","0.00224"
"224","1.30800","0.10894","0.00215"
"225","1.31400","0.10941","0.00213"
"226","1.32000","0.10995","0.00208"
"227","1.32600","0.11043","0.00207"
"228","1.33200","0.11097","0.00209"
"229","1.33800","0.11145","0.00210"
"230","1.34400","0.11199","0.00213"
"231","1.35000","0.11246","0.00214"
"232","1.35600","0.11294","0.00212"
"233","1.36200","0.11348","0.00215"
"234","1.36800","0.11396","0.00218"
"235","1.37400","0.11444","0.00219"
"236","1.38000","0.11492","0.00222"
"237","1.38600","0.11545","0.00222"
"238","1.39200","0.11593","0.00226"
"239","1.39800","0.11641","0.00238"
"240","1.40400","0.11695","0.00248"
"241","1.41000","0.11743","0.00264"
"242","1.41600","0.11796","0.00277"
"243","1.42200","0.11844","0.00275"
"244","1.42800","0.11892","0.00268"
"245","1.43400","0.11946","0.00257"
"246","1.44000","0.11994","0.00252"
"247","1.44600","0.12042","0.00255"
"248","1.45200","0.12095","0.00248"
"249","1.45800","0.12143","0.00248"
"250","1.46400","0.12191","0.00251"
"251","1.47000","0.12245","0.00252"
"252","1.47600","0.12293","0.00256"
"253","1.48200","0.12347","0.00259"
"254","1.48800","0.12394","0.00258"
"255","1.49400","0.12448","0.00257"
"256","1.50000","0.12496","0.00251"
"257","1.50600","0.12550","0.00248"
"258","1.51200","0.12598","0.00253"
"259","1.51800","0.12645","0.00259"
"260","1.52400","0.12693","0.00259"
"261","1.53000","0.12747","0.00260"
"262","1.53600","0.12795","0.00262"
"263","1.54200","0.12843","0.00268"
"264","1.54800","0.12897","0.00273"
"265","1.55400","0.12944","0.00276"
"266","1.56000","0.12998","0.00276"
"267","1.56600","0.13046","0.00268"
"268","1.57200","0.13094","0.00266"
"269","1.57800","0.13148","0.00274"
"270","1.58400","0.13196","0.00278"
"271","1.59000","0.13243","0.00282"
"272","1.59600","0.13297","0.00281"
"273","1.60200","0.13345","0.00274"
"274","1.60800","0.13393","0.00263"
"275","1.61400","0.13447","0.00252"
"276","1.62000","0.13494","0.00244"
"277","1.62600","0.13548","0.00240"
"278","1.63200","0.13596","0.00241"
"279","1.63800","0.13644","0.00237"
"280","1.64400","0.13698","0.00229"
"281","1.65000","0.13746","0.00216"
"282","1.65600","0.13793","0.00208"
"283","1.66200","0.13847","0.00203"
"284","1.66800","0.13895","0.00198"
"285","1.67400","0.13943","0.00192"
"286","1.68000","0.13997","0.00200"
"287","1.68600","0.14045","0.00204"
"288","1.69200","0.14098","0.00209"
"289","1.69800","0.14146","0.00220"
"290","1.70400","0.14200","0.00230"
"291","1.71000","0.14248","0.00239"
"292","1.71600","0.14302","0.00241"
"293","1.72200","0.14349","0.00238"
"294","1.72800","0.14403","0.00242"
"295","1.73400","0.14451","0.00242"
"296","1.74000","0.14499","0.00246"
"297","1.74600","0.14553","0.00259"
"298","1.75200","0.14601","0.00263"
"299","1.75800","0.14648","0.00260"
"300","1.76400","0.14702","0.00258"
"301","1.77000","0.14750","0.00253"
"302","1.77600","0.14798","0.00247"
"303","1.78200","0.14846","0.00240"
"304","1.78800","0.14900","0.00240"
"305","1.79400","0.14947","0.00240"
"306","1.80000","0.14995","0.00230"
"307","1.80600","0.15049","0.00218"
"308","1.81200","0.15097","0.00218"
"309","1.81800","0.15145","0.00224"
"310","1.82400","0.15198","0.00233"
"311","1.83000","0.15246","0.00238"
"312","1.83600","0.15294","0.00242"
"313","1.84200","0.15348","0.00247"
"314","1.84800","0.15396","0.00249"
"315","1.85400","0.15450","0.00247"
"316","1.86000","0.15497","0.00261"
"317","1.86600","0.15545","0.00274"
"318","1.87200","0.15593","0.00275"
"319","1.87800","0.15647","0.00275"
"320","1.88400","0.15695","0.00267"
"321","1.89000","0.15743","0.00262"
"322","1.89600","0.15796","0.00266"
"323","1.90200","0.15844","0.00268"
"324","1.90800","0.15892","0.00268"
"325","1.91400","0.15940","0.00271"
"326","1.92000","0.15988","0.00266"
"327","1.92600","0.16042","0.00260"
"328","1.93200","0.16089","0.00254"
"329","1.93800","0.16137","0.00253"
"330","1.94400","0.16191","0.00252"
"331","1.95000","0.16239","0.00249"
"332","1.95600","0.16293","0.00239"
"333","1.96200","0.16340","0.00236"
"334","1.96800","0.16388","0.00238"
"335","1.97400","0.16442","0.00242"
"336","1.98000","0.16490","0.00250"
"337","1.98600","0.16544","0.00256"
"338","1.99200","0.16592","0.00259"
"339","1.99800","0.16645","0.00264"
"340","2.00400","0.16693","0.00263"
"341","2.01000","0.16741","0.00262"
"342","2.01600","0.16795","0.00259"
"343","2.02200","0.16843","0.00249"
"344","2.02800","0.16891","0.00243"
"345","2.03400","0.16944","0.00235"
"346","2.04000","0.16992","0.00226"
"347","2.04600","0.17040","0.00229"
"348","2.05200","0.17094","0.00226"
"349","2.05800","0.17142","0.00225"
"350","2.06400","0.17189","0.00226"
"351","2.07000","0.17237","0.00230"
"352","2.07600","0.17291","0.00231"
"353","2.08200","0.17339","0.00232"
"354","2.08800","0.17387","0.00233"
"355","2.09400","0.17441","0.00242"
"356","2.10000","0.17488","0.00247"
"357","2.10600","0.17542","0.00240"
"358","2.11200","0.17590","0.00235"
"359","2.11800","0.17644","0.00227"
"360","2.12400","0.17692","0.00228"
"361","2.13000","0.17746","0.00231"
"362","2.13600","0.17793","0.00230"
"363","2.14200","0.17847","0.00227"
"364","2.14800","0.17895","0.00219"
"365","2.15400","0.17943","0.00207"
"366","2.16000","0.17997","0.00208"
"367","2.16600","0.18044","0.00219"
"368","2.17200","0.18092","0.00226"
"369","2.17800","0.18140","0.00241"
"370","2.18400","0.18194","0.00255"
"371","2.19000","0.18242","0.00259"
"372","2.19600","0.18290","0.00263"
"373","2.20200","0.18343","0.00261"
"374","2.20800","0.18391","0.00255"
"375","2.21400","0.18445","0.00249"
"376","2.22000","0.18493","0.00241"
"377","2.22600","0.18541","0.00231"
"378","2.23200","0.18595","0.00222"
"379","2.23800","0.18642","0.00211"
"380","2.24400","0.18696","0.00203"
"381","2.25000","0.18744","0.00200"
"382","2.25600","0.18798","0.00205"
"383","2.26200","0.18852","0.00211"
"384","2.26800","0.18899","0.00214"
"385","2.27400","0.18953","0.00213"
"386","2.28000","0.19001","0.00216"
"387","2.28600","0.19055","0.00221"
"388","2.29200","0.19103","0.00228"
"389","2.29800","0.19151","0.00231"
"390","2.30400","0.19198","0.00229"
"391","2.31000","0.19252","0.00228"
"392","2.31600","0.19300","0.00224"
"393","2.32200","0.19348","0.00225"
"394","2.32800","0.19396","0.00231"
"395","2.33400","0.19450","0.00231"
"396","2.34000","0.19497","0.00227"
"397","2.34600","0.19545","0.00229"
"398","2.35200","0.19599","0.00233"
"399","2.35800","0.19647","0.00245"
"400","2.36400","0.19701","0.00251"
"401","2.37000","0.19748","0.00250"
"402","2.37600","0.19796","0.00250"
"403","2.38200","0.19850","0.00250"
"404","2.38800","0.19898","0.00250"
"405","2.39400","0.19946","0.00252"
"406","2.40000","0.20000","0.00245"
"407","2.40600","0.20047","0.00230"
"408","2.41200","0.20101","0.00221"
"409","2.41800","0.20149","0.00213"
"410","2.42400","0.20197","0.00202"
"411","2.43000","0.20245","0.00192"
"412","2.43600","0.20299","0.00190"
"413","2.44200","0.20346","0.00197"
"414","2.44800","0.20394","0.00207"
"415","2.45400","0.20442","0.00222"
"416","2.46000","0.20496","0.00239"
"417","2.46600","0.20544","0.00244"
"418","2.47200","0.20592","0.00242"
"419","2.47800","0.20639","0.00248"
"420","2.48400","0.20693","0.00251"
"421","2.49000","0.20741","0.00247"
"422","2.49600","0.20795","0.00241"
"423","2.50200","0.20843","0.00233"
"424","2.50800","0.20890","0.00233"
"425","2.51400","0.20944","0.00230"
"426","2.52000","0.20992","0.00230"
"427","2.52600","0.21040","0.00237"
"428","2.53200","0.21094","0.00239"
"429","2.53800","0.21142","0.00237"
"430","2.54400","0.21189","0.00240"
"431","2.55000","0.21243","0.00243"
"432","2.55600","0.21291","0.00234"
"433","2.56200","0.21345","0.00231"
"434","2.56800","0.21393","0.00235"
"435","2.57400","0.21447","0.00246"
"436","2.58000","0.21494","0.00255"
"437","2.58600","0.21542","0.00261"
"438","2.59200","0.21590","0.00264"
"439","2.59800","0.21644","0.00266"
"440","2.60400","0.21692","0.00269"
"441","2.61000","0.21745","0.00278"
"442","2.61600","0.21793","0.00276"
"443","2.62200","0.21841","0.00263"
"444","2.62800","0.21895","0.00258"
"445","2.63400","0.21943","0.00254"
"446","2.64000","0.21991","0.00247"
"447","2.64600","0.22044","0.00251"
"448","2.65200","0.22092","0.00254"
"449","2.65800","0.22140","0.00250"
"450","2.66400","0.22194","0.00246"
"451","2.67000","0.22242","0.00241"
"452","2.67600","0.22290","0.00243"
"453","2.68200","0.22343","0.00240"
"454","2.68800","0.22391","0.00236"
"455","2.69400","0.22445","0.00240"
"456","2.70000","0.22493","0.00242"
"457","2.70600","0.22547","0.00235"
"458","2.71200","0.22594","0.00232"
"459","2.71800","0.22648","0.00228"
"460","2.72400","0.22696","0.00229"
"461","2.73000","0.22744","0.00235"
"462","2.73600","0.22792","0.00236"
"463","2.74200","0.22846","0.00234"
"464","2.74800","0.22893","0.00236"
"465","2.75400","0.22941","0.00237"
"466","2.76000","0.22995","0.00238"
"467","2.76600","0.23043","0.00237"
"468","2.77200","0.23097","0.00227"
"469","2.77800","0.23145","0.00215"
"470","2.78400","0.23198","0.00210"
"471","2.79000","0.23246","0.00206"
"472","2.79600","0.23294","0.00209"
"473","2.80200","0.23348","0.00218"
"474","2.80800","0.23396","0.00219"
"475","2.81400","0.23449","0.00220"
"476","2.82000","0.23497","0.00225"
"477","2.82600","0.23545","0.00234"
"478","2.83200","0.23593","0.00239"
"479","2.83800","0.23647","0.00243"
"480","2.84400","0.23695","0.00250"
"481","2.85000","0.23748","0.00258"
"482","2.85600","0.23796","0.00261"
"483","2.86200","0.23844","0.00267"
"484","2.86800","0.23898","0.00272"
"485","2.87400","0.23946","0.00270"
"486","2.88000","0.23994","0.00265"
"487","2.88600","0.24047","0.00251"
"488","2.89200","0.24095","0.00238"
"489","2.89800","0.24149","0.00234"
"490","2.90400","0.24197","0.00234"
"491","2.91000","0.24245","0.00234"
"492","2.91600","0.24298","0.00234"
"493","2.92200","0.24352","0.00232"
"494","2.92800","0.24400","0.00237"
"495","2.93400","0.24448","0.00243"
"496","2.94000","0.24502","0.00243"
"497","2.94600","0.24550","0.00250"
"498","2.95200","0.24597","0.00257"
"499","2.95800","0.24645","0.00258"
"500","2.96400","0.24699","0.00250"
"501","2.97000","0.24747","0.00238"
"502","2.97600","0.24795","0.00229"
"503","2.98200","0.24849","0.00221"
"504","2.98800","0.24896","0.00214"
"505","2.99400","0.24944","0.00213"
"506","3.00000","0.24998","0.00210"
"507","3.00600","0.25046","0.00212"
"508","3.01200","0.25094","0.00228"
"509","3.01800","0.25147","0.00244"
"510","3.02400","0.25195","0.00258"
"511","3.03000","0.25243","0.00270"
"512","3.03600","0.25291","0.00278"
"513","3.04200","0.25345","0.00282"
"514","3.04800","0.25393","0.00277"
"515","3.05400","0.25440","0.00263"
"516","3.06000","0.25494","0.00253"
"517","3.06600","0.25542","0.00248"
"518","3.07200","0.25590","0.00247"
"519","3.07800","0.25644","0.00258"
"520","3.08400","0.25692","0.00262"
"521","3.09000","0.25739","0.00255"
"522","3.09600","0.25793","0.00249"
"523","3.10200","0.25841","0.00243"
"524","3.10800","0.25889","0.00241"
"525","3.11400","0.25937","0.00243"
"526","3.12000","0.25991","0.00248"
"527","3.12600","0.26038","0.00258"
"528","3.13200","0.26092","0.00259"
"529","3.13800","0.26140","0.00253"
"530","3.14400","0.26188","0.00257"
"531","3.15000","0.26242","0.00256"
"532","3.15600","0.26289","0.00250"
"533","3.16200","0.26337","0.00251"
"534","3.16800","0.26391","0.00253"
"535","3.17400","0.26439","0.00253"
"536","3.18000","0.26487","0.00253"
"537","3.18600","0.26541","0.00247"
"538","3.19200","0.26588","0.00245"
"539","3.19800","0.26642","0.00247"
"540","3.20400","0.26690","0.00247"
"541","3.21000","0.26744","0.00251"
"542","3.21600","0.26792","0.00252"
"543","3.22200","0.26840","0.00248"
"544","3.22800","0.26893","0.00249"
"545","3.23400","0.26941","0.00250"
"546","3.24000","0.26989","0.00245"
"547","3.24600","0.27043","0.00240"
"548","3.25200","0.27091","0.00230"
"549","3.25800","0.27144","0.00226"
"550","3.26400","0.27192","0.00230"
"551","3.27000","0.27246","0.00241"
"552","3.27600","0.27294","0.00248"
"553","3.28200","0.27348","0.00248"
"554","3.28800","0.27396","0.00241"
"555","3.29400","0.27449","0.00239"
"556","3.30000","0.27497","0.00234"
"557","3.30600","0.27551","0.00230"
"558","3.31200","0.27599","0.00241"
"559","3.31800","0.27647","0.00250"
"560","3.32400","0.27700","0.00259"
"561","3.33000","0.27748","0.00268"
"562","3.33600","0.27796","0.00272"
"563","3.34200","0.27844","0.00278"
"564","3.34800","0.27898","0.00280"
"565","3.35400","0.27946","0.00277"
"566","3.36000","0.27993","0.00274"
"567","3.36600","0.28047","0.00258"
"568","3.37200","0.28095","0.00237"
"569","3.37800","0.28143","0.00222"
"570","3.38400","0.28197","0.00213"
"571","3.39000","0.28245","0.00203"
"572","3.39600","0.28292","0.00199"
"573","3.40200","0.28346","0.00202"
"574","3.40800","0.28394","0.00207"
"575","3.41400","0.28448","0.00212"
"576","3.42000","0.28496","0.00215"
"577","3.42600","0.28550","0.00230"
"578","3.43200","0.28597","0.00234"
"579","3.43800","0.28645","0.00219"
"580","3.44400","0.28699","0.00212"
"581","3.45000","0.28747","0.00207"
"582","3.45600","0.28795","0.00206"
"583","3.46200","0.28842","0.00210"
"584","3.46800","0.28896","0.00218"
"585","3.47400","0.28944","0.00224"
"586","3.48000","0.28992","0.00225"
"587","3.48600","0.29046","0.00224"
"588","3.49200","0.29094","0.00224"
"589","3.49800","0.29147","0.00217"
"590","3.50400","0.29195","0.00216"
"591","3.51000","0.29249","0.00232"
"592","3.51600","0.29297","0.00244"
"593","3.52200","0.29345","0.00246"
"594","3.52800","0.29393","0.00245"
"595","3.53400","0.29446","0.00246"
"596","3.54000","0.29494","0.00245"
"597","3.54600","0.29548","0.00238"
"598","3.55200","0.29596","0.00229"
"599","3.55800","0.29650","0.00232"
"600","3.56400","0.29697","0.00232"
"601","3.57000","0.29751","0.00234"
"602","3.57600","0.29799","0.00245"
"603","3.58200","0.29847","0.00255"
"604","3.58800","0.29895","0.00263"
"605","3.59400","0.29949","0.00264"
"606","3.60000","0.29996","0.00265"
"607","3.60600","0.30044","0.00267"
"608","3.61200","0.30092","0.00274"
"609","3.61800","0.30146","0.00283"
"610","3.62400","0.30194","0.00299"
"611","3.63000","0.30242","0.00305"
"612","3.63600","0.30289","0.00298"
"613","3.64200","0.30343","0.00294"
"614","3.64800","0.30391","0.00292"
"615","3.65400","0.30439","0.00285"
"616","3.66000","0.30487","0.00282"
"617","3.66600","0.30540","0.00281"
"618","3.67200","0.30588","0.00271"
"619","3.67800","0.30636","0.00255"
"620","3.68400","0.30690","0.00239"
"621","3.69000","0.30738","0.00228"
"622","3.69600","0.30792","0.00231"
"623","3.70200","0.30839","0.00233"
"624","3.70800","0.30887","0.00236"
"625","3.71400","0.30941","0.00234"
"626","3.72000","0.30989","0.00226"
"627","3.72600","0.31043","0.00230"
"628","3.73200","0.31091","0.00236"
"629","3.73800","0.31144","0.00243"
"630","3.74400","0.31192","0.00249"
"631","3.75000","0.31240","0.00246"
"632","3.75600","0.31288","0.00243"
"633","3.76200","0.31336","0.00229"
"634","3.76800","0.31390","0.00213"
"635","3.77400","0.31437","0.00201"
"636","3.78000","0.31491","0.00198"
"637","3.78600","0.31539","0.00200"
"638","3.79200","0.31587","0.00204"
"639","3.79800","0.31641","0.00203"
"640","3.80400","0.31688","0.00202"
"641","3.81000","0.31742","0.00203"
"642","3.81600","0.31790","0.00205"
"643","3.82200","0.31844","0.00201"
"644","3.82800","0.31898","0.00196"
"645","3.83400","0.31946","0.00195"
"646","3.84000","0.31993","0.00197"
"647","3.84600","0.32047","0.00206"
"648","3.85200","0.32095","0.00212"
"649","3.85800","0.32149","0.00218"
"650","3.86400","0.32197","0.00223"
"651","3.87000","0.32244","0.00227"
"652","3.87600","0.32298","0.00235"
"653","3.88200","0.32346","0.00242"
"654","3.88800","0.32400","0.00240"
"655","3.89400","0.32448","0.00242"
"656","3.90000","0.32496","0.00239"
"657","3.90600","0.32543","0.00232"
"658","3.91200","0.32591","0.00235"
"659","3.91800","0.32639","0.00239"
"660","3.92400","0.32693","0.00239"
"661","3.93000","0.32741","0.00239"
"662","3.93600","0.32789","0.00234"
"663","3.94200","0.32842","0.00231"
"664","3.94800","0.32890","0.00227"
"665","3.95400","0.32938","0.00219"
"666","3.96000","0.32992","0.00217"
"667","3.96600","0.33040","0.00215"
"668","3.97200","0.33094","0.00217"
"669","3.97800","0.33141","0.00221"
"670","3.98400","0.33195","0.00226"
"671","3.99000","0.33243","0.00225"
"672","3.99600","0.33297","0.00221"
"673","4.00200","0.33345","0.00226"
"674","4.00800","0.33398","0.00229"
"675","4.01400","0.33446","0.00230"
"676","4.02000","0.33494","0.00229"
"677","4.02600","0.33548","0.00232"
"678","4.03200","0.33596","0.00233"
"679","4.03800","0.33650","0.00230"
"680","4.04400","0.33697","0.00234"
"681","4.05000","0.33745","0.00240"
"682","4.05600","0.33793","0.00240"
"683","4.06200","0.33841","0.00241"
"684","4.06800","0.33895","0.00239"
"685","4.07400","0.33943","0.00232"
"686","4.08000","0.33990","0.00230"
"687","4.08600","0.34038","0.00224"
"688","4.09200","0.34086","0.00217"
"689","4.09800","0.34140","0.00204"
"690","4.10400","0.34188","0.00188"
"691","4.11000","0.34235","0.00197"
"692","4.11600","0.34289","0.00207"
"693","4.12200","0.34337","0.00213"
"694","4.12800","0.34391","0.00224"
"695","4.13400","0.34439","0.00235"
"696","4.14000","0.34493","0.00239"
"697","4.14600","0.34540","0.00235"
"698","4.15200","0.34594","0.00229"
"699","4.15800","0.34642","0.00234"
"700","4.16400","0.34690","0.00234"
"701","4.17000","0.34738","0.00235"
"702","4.17600","0.34786","0.00237"
"703","4.18200","0.34833","0.00233"
"704","4.18800","0.34887","0.00222"
"705","4.19400","0.34935","0.00214"
"706","4.20000","0.34983","0.00208"
"707","4.20600","0.35031","0.00201"
"708","4.21200","0.35084","0.00197"
"709","4.21800","0.35132","0.00200"
"710","4.22400","0.35186","0.00209"
"711","4.23000","0.35234","0.00213"
"712","4.23600","0.35282","0.00211"
"713","4.24200","0.35336","0.00212"
"714","4.24800","0.35383","0.00216"
"715","4.25400","0.35437","0.00219"
"716","4.26000","0.35485","0.00220"
"717","4.26600","0.35539","0.00231"
"718","4.27200","0.35587","0.00240"
"719","4.27800","0.35641","0.00239"
"720","4.28400","0.35694","0.00239"
"721","4.29000","0.35742","0.00243"
"722","4.29600","0.35796","0.00241"
"723","4.30200","0.35844","0.00244"
"724","4.30800","0.35892","0.00256"
"725","4.31400","0.35945","0.00267"
"726","4.32000","0.35993","0.00262"
"727","4.32600","0.36047","0.00266"
"728","4.33200","0.36095","0.00268"
"729","4.33800","0.36143","0.00265"
"730","4.34400","0.36191","0.00262"
"731","4.35000","0.36244","0.00251"
"732","4.35600","0.36292","0.00238"
"733","4.36200","0.36346","0.00231"
"734","4.36800","0.36394","0.00222"
"735","4.37400","0.36442","0.00218"
"736","4.38000","0.36496","0.00221"
"737","4.38600","0.36543","0.00226"
"738","4.39200","0.36591","0.00235"
"739","4.39800","0.36645","0.00239"
"740","4.40400","0.36693","0.00238"
"741","4.41000","0.36747","0.00239"
"742","4.41600","0.36794","0.00235"
"743","4.42200","0.36848","0.00224"
"744","4.42800","0.36896","0.00217"
"745","4.43400","0.36950","0.00210"
"746","4.44000","0.36998","0.00205"
"747","4.44600","0.37052","0.00204"
"748","4.45200","0.37099","0.00202"
"749","4.45800","0.37147","0.00200"
"750","4.46400","0.37201","0.00193"
"751","4.47000","0.37249","0.00189"
"752","4.47600","0.37297","0.00194"
"753","4.48200","0.37345","0.00198"
"754","4.48800","0.37392","0.00201"
"755","4.49400","0.37446","0.00206"
"756","4.50000","0.37494","0.00207"
"757","4.50600","0.37542","0.00212"
"758","4.51200","0.37596","0.00235"
"759","4.51800","0.37643","0.00246"
"760","4.52400","0.37697","0.00256"
"761","4.53000","0.37745","0.00260"
"762","4.53600","0.37799","0.00253"
"763","4.54200","0.37847","0.00247"
"764","4.54800","0.37895","0.00238"
"765","4.55400","0.37948","0.00227"
"766","4.56000","0.37996","0.00223"
"767","4.56600","0.38050","0.00222"
"768","4.57200","0.38098","0.00221"
"769","4.57800","0.38152","0.00223"
"770","4.58400","0.38200","0.00232"
"771","4.59000","0.38247","0.00238"
"772","4.59600","0.38301","0.00239"
"773","4.60200","0.38349","0.00239"
"774","4.60800","0.38397","0.00247"
"775","4.61400","0.38445","0.00248"
"776","4.62000","0.38492","0.00242"
"777","4.62600","0.38546","0.00240"
"778","4.63200","0.38594","0.00228"
"779","4.63800","0.38642","0.00211"
"780","4.64400","0.38690","0.00207"
"781","4.65000","0.38744","0.00207"
"782","4.65600","0.38791","0.00202"
"783","4.66200","0.38839","0.00199"
"784","4.66800","0.38887","0.00202"
"785","4.67400","0.38941","0.00205"
"786","4.68000","0.38989","0.00212"
"787","4.68600","0.39043","0.00219"
"788","4.69200","0.39090","0.00231"
"789","4.69800","0.39138","0.00237"
"790","4.70400","0.39192","0.00237"
"791","4.71000","0.39240","0.00241"
"792","4.71600","0.39288","0.00243"
"793","4.72200","0.39342","0.00246"
"794","4.72800","0.39389","0.00251"
"795","4.73400","0.39437","0.00255"
"796","4.74000","0.39491","0.00254"
"797","4.74600","0.39539","0.00250"
"798","4.75200","0.39587","0.00242"
"799","4.75800","0.39640","0.00238"
"800","4.76400","0.39688","0.00242"
"801","4.77000","0.39736","0.00246"
"802","4.77600","0.39790","0.00249"
"803","4.78200","0.39838","0.00249"
"804","4.78800","0.39886","0.00249"
"805","4.79400","0.39939","0.00249"
"806","4.80000","0.39987","0.00250"
"807","4.80600","0.40035","0.00255"
"808","4.81200","0.40089","0.00257"
"809","4.81800","0.40137","0.00248"
"810","4.82400","0.40191","0.00241"
"811","4.83000","0.40238","0.00241"
"812","4.83600","0.40292","0.00235"
"813","4.84200","0.40340","0.00229"
"814","4.84800","0.40388","0.00226"
"815","4.85400","0.40442","0.00222"
"816","4.86000","0.40489","0.00217"
"817","4.86600","0.40543","0.00211"
"818","4.87200","0.40597","0.00216"
"819","4.87800","0.40645","0.00223"
"820","4.88400","0.40693","0.00226"
"821","4.89000","0.40747","0.00233"
"822","4.89600","0.40794","0.00235"
"823","4.90200","0.40842","0.00225"
"824","4.90800","0.40896","0.00221"
"825","4.91400","0.40944","0.00223"
"826","4.92000","0.40998","0.00229"
"827","4.92600","0.41046","0.00238"
"828","4.93200","0.41093","0.00241"
"829","4.93800","0.41147","0.00233"
"830","4.94400","0.41195","0.00227"
"831","4.95000","0.41243","0.00219"
"832","4.95600","0.41297","0.00207"
"833","4.96200","0.41344","0.00209"
"834","4.96800","0.41398","0.00220"
"835","4.97400","0.41446","0.00225"
"836","4.98000","0.41494","0.00221"
"837","4.98600","0.41548","0.00216"
"838","4.99200","0.41596","0.00220"
"839","4.99800","0.41649","0.00221"
"840","5.00400","0.41697","0.00221"
"841","5.01000","0.41745","0.00222"
"842","5.01600","0.41793","0.00218"
"843","5.02200","0.41847","0.00209"
"844","5.02800","0.41895","0.00216"
"845","5.03400","0.41942","0.00233"
"846","5.04000","0.41996","0.00243"
"847","5.04600","0.42044","0.00247"
"848","5.05200","0.42092","0.00241"
"849","5.05800","0.42146","0.00234"
"850","5.06400","0.42193","0.00227"
"851","5.07000","0.42247","0.00229"
"852","5.07600","0.42295","0.00239"
"853","5.08200","0.42343","0.00249"
"854","5.08800","0.42397","0.00250"
"855","5.09400","0.42445","0.00245"
"856","5.10000","0.42492","0.00233"
"857","5.10600","0.42546","0.00220"
"858","5.11200","0.42594","0.00222"
"859","5.11800","0.42642","0.00224"
"860","5.12400","0.42696","0.00231"
"861","5.13000","0.42744","0.00234"
"862","5.13600","0.42791","0.00232"
"863","5.14200","0.42845","0.00236"
"864","5.14800","0.42893","0.00241"
"865","5.15400","0.42947","0.00243"
"866","5.16000","0.42995","0.00248"
"867","5.16600","0.43042","0.00249"
"868","5.17200","0.43096","0.00248"
"869","5.17800","0.43144","0.00250"
"870","5.18400","0.43192","0.00253"
"871","5.19000","0.43246","0.00253"
"872","5.19600","0.43294","0.00247"
"873","5.20200","0.43347","0.00233"
"874","5.20800","0.43395","0.00223"
"875","5.21400","0.43443","0.00215"
"876","5.22000","0.43497","0.00211"
"877","5.22600","0.43545","0.00210"
"878","5.23200","0.43593","0.00213"
"879","5.23800","0.43646","0.00212"
"880","5.24400","0.43694","0.00209"
"881","5.25000","0.43742","0.00202"
"882","5.25600","0.43796","0.00206"
"883","5.26200","0.43844","0.00207"
"884","5.26800","0.43891","0.00210"
"885","5.27400","0.43939","0.00216"
"886","5.28000","0.43993","0.00219"
"887","5.28600","0.44041","0.00214"
"888","5.29200","0.44089","0.00212"
"889","5.29800","0.44137","0.00213"
"890","5.30400","0.44190","0.00219"
"891","5.31000","0.44238","0.00232"
"892","5.31600","0.44286","0.00236"
"893","5.32200","0.44340","0.00232"
"894","5.32800","0.44388","0.00232"
"895","5.33400","0.44436","0.00239"
"896","5.34000","0.44489","0.00247"
"897","5.34600","0.44537","0.00244"
"898","5.35200","0.44591","0.00240"
"899","5.35800","0.44639","0.00236"
"900","5.36400","0.44687","0.00229"
"901","5.37000","0.44741","0.00212"
"902","5.37600","0.44788","0.00198"
"903","5.38200","0.44842","0.00192"
"904","5.38800","0.44890","0.00188"
"905","5.39400","0.44938","0.00191"
"906","5.40000","0.44992","0.00188"
"907","5.40600","0.45039","0.00194"
"908","5.41200","0.45093","0.00208"
"909","5.41800","0.45141","0.00220"
"910","5.42400","0.45195","0.00234"
"911","5.43000","0.45243","0.00241"
"912","5.43600","0.45297","0.00240"
"913","5.44200","0.45344","0.00239"
"914","5.44800","0.45398","0.00242"
"915","5.45400","0.45446","0.00245"
"916","5.46000","0.45494","0.00249"
"917","5.46600","0.45548","0.00253"
"918","5.47200","0.45596","0.00257"
"919","5.47800","0.45649","0.00261"
"920","5.48400","0.45697","0.00252"
"921","5.49000","0.45745","0.00236"
"922","5.49600","0.45799","0.00225"
"923","5.50200","0.45847","0.00216"
"924","5.50800","0.45900","0.00215"
"925","5.51400","0.45948","0.00217"
"926","5.52000","0.45996","0.00208"
"927","5.52600","0.46044","0.00203"
"928","5.53200","0.46098","0.00208"
"929","5.53800","0.46146","0.00212"
"930","5.54400","0.46193","0.00212"
"931","5.55000","0.46247","0.00207"
"932","5.55600","0.46295","0.00203"
"933","5.56200","0.46343","0.00206"
"934","5.56800","0.46397","0.00207"
"935","5.57400","0.46445","0.00212"
"936","5.58000","0.46498","0.00218"
"937","5.58600","0.46546","0.00223"
"938","5.59200","0.46594","0.00230"
"939","5.59800","0.46648","0.00234"
"940","5.60400","0.46696","0.00226"
"941","5.61000","0.46743","0.00220"
"942","5.61600","0.46791","0.00218"
"943","5.62200","0.46845","0.00214"
"944","5.62800","0.46893","0.00212"
"945","5.63400","0.46941","0.00214"
"946","5.64000","0.46995","0.00226"
"947","5.64600","0.47042","0.00234"
"948","5.65200","0.47090","0.00232"
"949","5.65800","0.47144","0.00230"
"950","5.66400","0.47192","0.00223"
"951","5.67000","0.47240","0.00214"
"952","5.67600","0.47294","0.00208"
"953","5.68200","0.47341","0.00202"
"954","5.68800","0.47389","0.00201"
"955","5.69400","0.47437","0.00206"
"956","5.70000","0.47491","0.00215"
"957","5.70600","0.47539","0.00217"
"958","5.71200","0.47592","0.00217"
"959","5.71800","0.47640","0.00217"
"960","5.72400","0.47694","0.00221"
"961","5.73000","0.47742","0.00226"
"962","5.73600","0.47796","0.00231"
"963","5.74200","0.47844","0.00238"
"964","5.74800","0.47891","0.00244"
"965","5.75400","0.47939","0.00246"
"966","5.76000","0.47993","0.00246"
"967","5.76600","0.48041","0.00251"
"968","5.77200","0.48089","0.00260"
"969","5.77800","0.48137","0.00272"
"970","5.78400","0.48190","0.00275"
"971","5.79000","0.48238","0.00272"
"972","5.79600","0.48292","0.00260"
"973","5.80200","0.48340","0.00246"
"974","5.80800","0.48388","0.00245"
"975","5.81400","0.48441","0.00244"
"976","5.82000","0.48489","0.00240"
"977","5.82600","0.48537","0.00241"
"978","5.83200","0.48585","0.00238"
"979","5.83800","0.48639","0.00224"
"980","5.84400","0.48687","0.00219"
"981","5.85000","0.48740","0.00222"
"982","5.85600","0.48788","0.00221"
"983","5.86200","0.48842","0.00223"
"984","5.86800","0.48890","0.00232"
"985","5.87400","0.48938","0.00240"
"986","5.88000","0.48992","0.00245"
"987","5.88600","0.49039","0.00239"
"988","5.89200","0.49093","0.00235"
"989","5.89800","0.49141","0.00237"
"990","5.90400","0.49189","0.00243"
"991","5.91000","0.49237","0.00247"
"992","5.91600","0.49290","0.00246"
"993","5.92200","0.49338","0.00236"
"994","5.92800","0.49386","0.00227"
"995","5.93400","0.49440","0.00220"
"996","5.94000","0.49488","0.00214"
"997","5.94600","0.49536","0.00207"
"998","5.95200","0.49583","0.00202"
"999","5.95800","0.49637","0.00205"
"1000","5.96400","0.49685","0.00211"
"1001","5.97000","0.49739","0.00211"
"1002","5.97600","0.49787","0.00219"
"1003","5.98200","0.49841","0.00226"
"1004","5.98800","0.49888","0.00237"
"1005","5.99400","0.49942","0.00240"
"1006","6.00000","0.49990","0.00236"
"1007","6.00600","0.50044","0.00229"
"1008","6.01200","0.50098","0.00225"
"1009","6.01800","0.50145","0.00211"
"1010","6.02400","0.50199","0.00204"
"1011","6.03000","0.50247","0.00208"
"1012","6.03600","0.50295","0.00214"
"1013","6.04200","0.50349","0.00211"
"1014","6.04800","0.50397","0.00202"
"1015","6.05400","0.50444","0.00198"
"1016","6.06000","0.50492","0.00207"
"1017","6.06600","0.50546","0.00222"
"1018","6.07200","0.50594","0.00237"
"1019","6.07800","0.50642","0.00259"
"1020","6.08400","0.50690","0.00267"
"1021","6.09000","0.50743","0.00270"
"1022","6.09600","0.50791","0.00277"
"1023","6.10200","0.50839","0.00278"
"1024","6.10800","0.50893","0.00280"
"1025","6.11400","0.50941","0.00281"
"1026","6.12000","0.50989","0.00278"
"1027","6.12600","0.51042","0.00265"
"1028","6.13200","0.51090","0.00248"
"1029","6.13800","0.51144","0.00241"
"1030","6.14400","0.51198","0.00236"
"1031","6.15000","0.51246","0.00221"
"1032","6.15600","0.51293","0.00208"
"1033","6.16200","0.51347","0.00203"
"1034","6.16800","0.51395","0.00210"
"1035","6.17400","0.51443","0.00216"
"1036","6.18000","0.51497","0.00221"
"1037","6.18600","0.51545","0.00218"
"1038","6.19200","0.51592","0.00224"
"1039","6.19800","0.51646","0.00219"
"1040","6.20400","0.51694","0.00211"
"1041","6.21000","0.51742","0.00208"
"1042","6.21600","0.51796","0.00205"
"1043","6.22200","0.51844","0.00202"
"1044","6.22800","0.51891","0.00211"
"1045","6.23400","0.51939","0.00218"
"1046","6.24000","0.51987","0.00224"
"1047","6.24600","0.52041","0.00227"
"1048","6.25200","0.52089","0.00227"
"1049","6.25800","0.52136","0.00233"
"1050","6.26400","0.52190","0.00237"
"1051","6.27000","0.52238","0.00238"
"1052","6.27600","0.52292","0.00245"
"1053","6.28200","0.52340","0.00244"
"1054","6.28800","0.52394","0.00235"
"1055","6.29400","0.52441","0.00225"
"1056","6.30000","0.52489","0.00218"
"1057","6.30600","0.52543","0.00213"
"1058","6.31200","0.52591","0.00209"
"1059","6.31800","0.52639","0.00208"
"1060","6.32400","0.52687","0.00214"
"1061","6.33000","0.52740","0.00217"
"1062","6.33600","0.52788","0.00214"
"1063","6.34200","0.52836","0.00214"
"1064","6.34800","0.52890","0.00213"
"1065","6.35400","0.52938","0.00205"
"1066","6.36000","0.52985","0.00196"
"1067","6.36600","0.53039","0.00197"
"1068","6.37200","0.53087","0.00191"
"1069","6.37800","0.53135","0.00185"
"1070","6.38400","0.53189","0.00186"
"1071","6.39000","0.53237","0.00194"
"1072","6.39600","0.53284","0.00203"
"1073","6.40200","0.53338","0.00207"
"1074","6.40800","0.53386","0.00220"
"1075","6.41400","0.53440","0.00236"
"1076","6.42000","0.53488","0.00247"
"1077","6.42600","0.53536","0.00248"
"1078","6.43200","0.53589","0.00243"
"1079","6.43800","0.53643","0.00239"
"1080","6.44400","0.53691","0.00232"
"1081","6.45000","0.53745","0.00226"
"1082","6.45600","0.53793","0.00232"
"1083","6.46200","0.53840","0.00235"
"1084","6.46800","0.53894","0.00229"
"1085","6.47400","0.53942","0.00227"
"1086","6.48000","0.53990","0.00226"
"1087","6.48600","0.54038","0.00218"
"1088","6.49200","0.54092","0.00216"
"1089","6.49800","0.54139","0.00221"
"1090","6.50400","0.54193","0.00226"
"1091","6.51000","0.54241","0.00236"
"1092","6.51600","0.54289","0.00240"
"1093","6.52200","0.54343","0.00247"
"1094","6.52800","0.54391","0.00248"
"1095","6.53400","0.54438","0.00245"
"1096","6.54000","0.54492","0.00245"
"1097","6.54600","0.54540","0.00244"
"1098","6.55200","0.54588","0.00239"
"1099","6.55800","0.54642","0.00239"
"1100","6.56400","0.54689","0.00244"
"1101","6.57000","0.54743","0.00243"
"1102","6.57600","0.54797","0.00242"
"1103","6.58200","0.54845","0.00239"
"1104","6.58800","0.54899","0.00236"
"1105","6.59400","0.54947","0.00229"
"1106","6.60000","0.54994","0.00222"
"1107","6.60600","0.55048","0.00218"
"1108","6.61200","0.55096","0.00225"
"1109","6.61800","0.55144","0.00224"
"1110","6.62400","0.55192","0.00223"
"1111","6.63000","0.55246","0.00225"
"1112","6.63600","0.55293","0.00218"
"1113","6.64200","0.55347","0.00217"
"1114","6.64800","0.55395","0.00225"
"1115","6.65400","0.55443","0.00238"
"1116","6.66000","0.55497","0.00246"
"1117","6.66600","0.55544","0.00249"
"1118","6.67200","0.55598","0.00247"
"1119","6.67800","0.55646","0.00243"
"1120","6.68400","0.55694","0.00231"
"1121","6.69000","0.55748","0.00232"
"1122","6.69600","0.55796","0.00237"
"1123","6.70200","0.55843","0.00229"
"1124","6.70800","0.55897","0.00228"
"1125","6.71400","0.55945","0.00233"
"1126","6.72000","0.55999","0.00230"
"1127","6.72600","0.56047","0.00236"
"1128","6.73200","0.56095","0.00243"
"1129","6.73800","0.56148","0.00248"
"1130","6.74400","0.56196","0.00241"
"1131","6.75000","0.56244","0.00224"
"1132","6.75600","0.56298","0.00214"
"1133","6.76200","0.56346","0.00219"
"1134","6.76800","0.56393","0.00229"
"1135","6.77400","0.56447","0.00238"
"1136","6.78000","0.56495","0.00238"
"1137","6.78600","0.56543","0.00236"
"1138","6.79200","0.56597","0.00241"
"1139","6.79800","0.56645","0.00237"
"1140","6.80400","0.56692","0.00232"
"1141","6.81000","0.56740","0.00228"
"1142","6.81600","0.56794","0.00224"
"1143","6.82200","0.56842","0.00215"
"1144","6.82800","0.56890","0.00209"
"1145","6.83400","0.56944","0.00205"
"1146","6.84000","0.56991","0.00211"
"1147","6.84600","0.57039","0.00220"
"1148","6.85200","0.57093","0.00226"
"1149","6.85800","0.57141","0.00234"
"1150","6.86400","0.57195","0.00244"
"1151","6.87000","0.57242","0.00250"
"1152","6.87600","0.57290","0.00257"
"1153","6.88200","0.57344","0.00252"
"1154","6.88800","0.57392","0.00243"
"1155","6.89400","0.57440","0.00237"
"1156","6.90000","0.57488","0.00233"
"1157","6.90600","0.57541","0.00234"
"1158","6.91200","0.57589","0.00237"
"1159","6.91800","0.57643","0.00237"
"1160","6.92400","0.57691","0.00234"
"1161","6.93000","0.57739","0.00230"
"1162","6.93600","0.57787","0.00229"
"1163","6.94200","0.57834","0.00230"
"1164","6.94800","0.57888","0.00234"
"1165","6.95400","0.57936","0.00234"
"1166","6.96000","0.57984","0.00236"
"1167","6.96600","0.58038","0.00243"
"1168","6.97200","0.58086","0.00250"
"1169","6.97800","0.58133","0.00255"
"1170","6.98400","0.58187","0.00250"
"1171","6.99000","0.58241","0.00245"
"1172","6.99600","0.58289","0.00246"
"1173","7.00200","0.58343","0.00230"
"1174","7.00800","0.58390","0.00225"
"1175","7.01400","0.58444","0.00232"
"1176","7.02000","0.58492","0.00239"
"1177","7.02600","0.58546","0.00240"
"1178","7.03200","0.58594","0.00241"
"1179","7.03800","0.58648","0.00244"
"1180","7.04400","0.58695","0.00252"
"1181","7.05000","0.58749","0.00255"
"1182","7.05600","0.58797","0.00254"
"1183","7.06200","0.58845","0.00251"
"1184","7.06800","0.58899","0.00245"
"1185","7.07400","0.58947","0.00242"
"1186","7.08000","0.59000","0.00237"
"1187","7.08600","0.59048","0.00228"
"1188","7.09200","0.59096","0.00214"
"1189","7.09800","0.59150","0.00209"
"1190","7.10400","0.59198","0.00213"
"1191","7.11000","0.59245","0.00222"
"1192","7.11600","0.59299","0.00230"
"1193","7.12200","0.59347","0.00233"
"1194","7.12800","0.59395","0.00230"
"1195","7.13400","0.59443","0.00213"
"1196","7.14000","0.59497","0.00205"
"1197","7.14600","0.59544","0.00208"
"1198","7.15200","0.59598","0.00208"
"1199","7.15800","0.59646","0.00210"
"1200","7.16400","0.59700","0.00215"
"1201","7.17000","0.59748","0.00216"
"1202","7.17600","0.59796","0.00221"
"1203","7.18200","0.59849","0.00225"
"1204","7.18800","0.59897","0.00228"
"1205","7.19400","0.59945","0.00232"
"1206","7.20000","0.59993","0.00233"
"1207","7.20600","0.60047","0.00229"
"1208","7.21200","0.60094","0.00225"
"1209","7.21800","0.60148","0.00215"
"1210","7.22400","0.60196","0.00211"
"1211","7.23000","0.60244","0.00217"
"1212","7.23600","0.60292","0.00219"
"1213","7.24200","0.60346","0.00222"
"1214","7.24800","0.60393","0.00219"
"1215","7.25400","0.60441","0.00208"
"1216","7.26000","0.60495","0.00199"
"1217","7.26600","0.60543","0.00193"
"1218","7.27200","0.60597","0.00193"
"1219","7.27800","0.60645","0.00201"
"1220","7.28400","0.60698","0.00208"
"1221","7.29000","0.60746","0.00219"
"1222","7.29600","0.60800","0.00233"
"1223","7.30200","0.60848","0.00241"
"1224","7.30800","0.60896","0.00246"
"1225","7.31400","0.60949","0.00249"
"1226","7.32000","0.60997","0.00244"
"1227","7.32600","0.61051","0.00242"
"1228","7.32800","0.61063","0.00241"