File: Trajectories_together/161221_1Specimen_RawData_8.csv
"","V1","V2","V3"
"1","End date","12/21/2016",""
"2","Specimen label","24BG_95_run2",""
"3","Maximum Load","0.01226","N"
"4","Time","Extension","Load"
"5","(s)","(mm)","(N)"
"6","0.00000","7.50783","0.00789"
"24","0.10800","7.51160","0.00773"
"42","0.21600","7.52260","0.00818"
"60","0.32400","7.53432","0.00812"
"78","0.43200","7.54406","0.00790"
"96","0.54000","7.55303","0.00824"
"114","0.64800","7.56206","0.00826"
"132","0.75600","7.57103","0.00817"
"150","0.86400","7.58000","0.00791"
"168","0.97200","7.58903","0.00808"
"186","1.08000","7.59805","0.00783"
"204","1.18800","7.60708","0.00799"
"222","1.29600","7.61605","0.00817"
"240","1.40400","7.62502","0.00794"
"258","1.51200","7.63399","0.00802"
"276","1.62000","7.64302","0.00781"
"294","1.72800","7.65198","0.00839"
"312","1.83600","7.66101","0.00803"
"330","1.94400","7.67004","0.00791"
"348","2.05200","7.67895","0.00833"
"366","2.16000","7.68798","0.00816"
"384","2.26800","7.69707","0.00823"
"402","2.37600","7.70603","0.00830"
"420","2.48400","7.71494","0.00816"
"438","2.59200","7.72397","0.00803"
"456","2.70000","7.73300","0.00806"
"474","2.80800","7.74203","0.00794"
"492","2.91600","7.75106","0.00795"
"510","3.02400","7.75996","0.00807"
"528","3.13200","7.76893","0.00812"
"546","3.24000","7.77802","0.00809"
"564","3.34800","7.78705","0.00871"
"582","3.45600","7.79602","0.00831"
"600","3.56400","7.80499","0.00860"
"618","3.67200","7.81395","0.00820"
"636","3.78000","7.82298","0.00841"
"654","3.88800","7.83201","0.00824"
"672","3.99600","7.84104","0.00849"
"690","4.10400","7.85007","0.00831"
"708","4.21200","7.85897","0.00840"
"726","4.32000","7.86794","0.00855"
"744","4.42800","7.87703","0.00829"
"762","4.53600","7.88606","0.00878"
"780","4.64400","7.89497","0.00837"
"798","4.75200","7.90394","0.00847"
"816","4.86000","7.91297","0.00864"
"834","4.96800","7.92199","0.00825"
"852","5.07600","7.93102","0.00798"
"870","5.18400","7.93993","0.00847"
"888","5.29200","7.94890","0.00835"
"906","5.40000","7.95799","0.00820"
"924","5.50800","7.96701","0.00801"
"942","5.61600","7.97598","0.00820"
"960","5.72400","7.98495","0.00823"
"978","5.83200","7.99398","0.00805"
"996","5.94000","8.00295","0.00858"
"1014","6.04800","8.01198","0.00817"
"1032","6.15600","8.02100","0.00818"
"1050","6.26400","8.02997","0.00833"
"1068","6.37200","8.03894","0.00835"
"1086","6.48000","8.04797","0.00852"
"1104","6.58800","8.05700","0.00805"
"1122","6.69600","8.06597","0.00836"
"1140","6.80400","8.07493","0.00856"
"1158","6.91200","8.08390","0.00849"
"1176","7.02000","8.09299","0.00815"
"1194","7.12800","8.10202","0.00817"
"1212","7.23600","8.11099","0.00830"
"1230","7.34400","8.11996","0.00835"
"1248","7.45200","8.12893","0.00827"
"1266","7.56000","8.13801","0.00841"
"1284","7.66800","8.14704","0.00839"
"1302","7.77600","8.15595","0.00823"
"1320","7.88400","8.16498","0.00814"
"1338","7.99200","8.17395","0.00864"
"1356","8.10000","8.18297","0.00820"
"1374","8.20800","8.19194","0.00815"
"1392","8.31600","8.20097","0.00835"
"1410","8.42400","8.21000","0.00817"
"1428","8.53200","8.21897","0.00843"
"1446","8.64000","8.22800","0.00866"
"1464","8.74800","8.23702","0.00839"
"1482","8.85600","8.24599","0.00815"
"1500","8.96400","8.25496","0.00861"
"1518","9.07200","8.26393","0.00814"
"1536","9.18000","8.27296","0.00831"
"1554","9.28800","8.28199","0.00837"
"1572","9.39600","8.29101","0.00817"
"1590","9.50400","8.29992","0.00847"
"1608","9.61200","8.30895","0.00816"
"1626","9.72000","8.31798","0.00811"
"1644","9.82800","8.32701","0.00813"
"1662","9.93600","8.33604","0.00819"
"1680","10.04400","8.34500","0.00808"
"1698","10.15200","8.35391","0.00851"
"1716","10.26000","8.36300","0.00808"
"1734","10.36800","8.37197","0.00830"
"1752","10.47600","8.38100","0.00808"
"1770","10.58400","8.39003","0.00866"
"1788","10.69200","8.39899","0.00817"
"1806","10.80000","8.40802","0.00818"
"1824","10.90800","8.41699","0.00840"
"1842","11.01600","8.42602","0.00856"
"1860","11.12400","8.43499","0.00813"
"1878","11.23200","8.44390","0.00858"
"1896","11.34000","8.45298","0.00799"
"1914","11.44800","8.46201","0.00815"
"1932","11.55600","8.47104","0.00844"
"1950","11.66400","8.47995","0.00834"
"1968","11.77200","8.48892","0.00812"
"1986","11.88000","8.49801","0.00845"
"2004","11.98800","8.50703","0.00837"
"2022","12.09600","8.51600","0.00801"
"2040","12.20400","8.52497","0.00782"
"2058","12.31200","8.53388","0.00848"
"2076","12.42000","8.54303","0.00810"
"2094","12.52800","8.55200","0.00836"
"2112","12.63600","8.56096","0.00822"
"2130","12.74400","8.56999","0.00827"
"2148","12.85200","8.57896","0.00839"
"2166","12.96000","8.58793","0.00808"
"2184","13.06800","8.59696","0.00795"
"2202","13.17600","8.60599","0.00817"
"2220","13.28400","8.61495","0.00815"
"2238","13.39200","8.62392","0.00856"
"2256","13.50000","8.63295","0.00838"
"2274","13.60800","8.64198","0.00806"
"2292","13.71600","8.65101","0.00808"
"2310","13.82400","8.65998","0.00816"
"2328","13.93200","8.66894","0.00819"
"2346","14.04000","8.67797","0.00832"
"2364","14.14800","8.68700","0.00799"
"2382","14.25600","8.69603","0.00800"
"2400","14.36400","8.70500","0.00809"
"2418","14.47200","8.71397","0.00823"
"2436","14.58000","8.72299","0.00840"
"2454","14.68800","8.73202","0.00803"
"2472","14.79600","8.74099","0.00851"
"2490","14.90400","8.74996","0.00819"
"2508","15.01200","8.75899","0.00811"
"2526","15.12000","8.76802","0.00829"
"2544","15.22800","8.77692","0.00801"
"2562","15.33600","8.78601","0.00871"
"2580","15.44400","8.79498","0.00840"
"2598","15.55200","8.80395","0.00810"
"2616","15.66000","8.81298","0.00838"
"2634","15.76800","8.82201","0.00859"
"2652","15.87600","8.83103","0.00833"
"2670","15.98400","8.84000","0.00822"
"2688","16.09200","8.84891","0.00822"
"2706","16.20000","8.85800","0.00838"
"2724","16.30800","8.86703","0.00825"
"2742","16.41600","8.87599","0.00814"
"2760","16.52400","8.88496","0.00818"
"2778","16.63200","8.89393","0.00853"
"2796","16.74000","8.90296","0.00829"
"2814","16.84800","8.91199","0.00853"
"2832","16.95600","8.92102","0.00853"
"2850","17.06400","8.92999","0.00841"
"2868","17.17200","8.93901","0.00835"
"2886","17.28000","8.94804","0.00854"
"2904","17.38800","8.95695","0.00869"
"2922","17.49600","8.96598","0.00840"
"2940","17.60400","8.97495","0.00864"
"2958","17.71200","8.98398","0.00786"
"2976","17.82000","8.99300","0.00848"
"2994","17.92800","9.00197","0.00856"
"3012","18.03600","9.01100","0.00876"
"3030","18.14400","9.01997","0.00831"
"3048","18.25200","9.02894","0.00841"
"3066","18.36000","9.03796","0.00843"
"3084","18.46800","9.04699","0.00861"
"3102","18.57600","9.05602","0.00819"
"3120","18.68400","9.06493","0.00825"
"3138","18.79200","9.07396","0.00842"
"3156","18.90000","9.08299","0.00845"
"3174","19.00800","9.09202","0.00858"
"3192","19.11600","9.10098","0.00841"
"3210","19.22400","9.10995","0.00848"
"3228","19.33200","9.11898","0.00846"
"3246","19.44000","9.12801","0.00832"
"3264","19.54800","9.13698","0.00821"
"3282","19.65600","9.14595","0.00838"
"3300","19.76400","9.15491","0.00808"
"3318","19.87200","9.16400","0.00829"
"3336","19.98000","9.17297","0.00847"
"3354","20.08800","9.18200","0.00806"
"3372","20.19600","9.19103","0.00836"
"3390","20.30400","9.20000","0.00784"
"3408","20.41200","9.20896","0.00811"
"3426","20.52000","9.21799","0.00856"
"3444","20.62800","9.22696","0.00820"
"3462","20.73600","9.23605","0.00848"
"3480","20.84400","9.24496","0.00803"
"3498","20.95200","9.25392","0.00809"
"3516","21.06000","9.26301","0.00847"
"3534","21.16800","9.27204","0.00820"
"3552","21.27600","9.28101","0.00821"
"3570","21.38400","9.28998","0.00826"
"3588","21.49200","9.29895","0.00800"
"3606","21.60000","9.30797","0.00802"
"3624","21.70800","9.31700","0.00818"
"3642","21.81600","9.32603","0.00842"
"3660","21.92400","9.33494","0.00828"
"3678","22.03200","9.34397","0.00844"
"3696","22.14000","9.35300","0.00836"
"3714","22.24800","9.36202","0.00837"
"3732","22.35600","9.37099","0.00821"
"3750","22.46400","9.37996","0.00831"
"3768","22.57200","9.38893","0.00880"
"3786","22.68000","9.39802","0.00843"
"3804","22.78800","9.40699","0.00852"
"3822","22.89600","9.41601","0.00842"
"3840","23.00400","9.42498","0.00862"
"3858","23.11200","9.43395","0.00856"
"3876","23.22000","9.44298","0.00858"
"3894","23.32800","9.45207","0.00853"
"3912","23.43600","9.46098","0.00853"
"3930","23.54400","9.46994","0.00881"
"3948","23.65200","9.47897","0.00859"
"3966","23.76000","9.48800","0.00820"
"3984","23.86800","9.49697","0.00884"
"4002","23.97600","9.50594","0.00834"
"4020","24.08400","9.51491","0.00849"
"4038","24.19200","9.52399","0.00847"
"4056","24.30000","9.53296","0.00866"
"4074","24.40800","9.54199","0.00826"
"4092","24.51600","9.55096","0.00857"
"4110","24.62400","9.55999","0.00869"
"4128","24.73200","9.56896","0.00853"
"4146","24.84000","9.57798","0.00858"
"4164","24.94800","9.58701","0.00851"
"4182","25.05600","9.59604","0.00825"
"4200","25.16400","9.60501","0.00833"
"4218","25.27200","9.61398","0.00857"
"4236","25.38000","9.62307","0.00866"
"4254","25.48800","9.63203","0.00864"
"4272","25.59600","9.64100","0.00839"
"4290","25.70400","9.64997","0.00834"
"4308","25.81200","9.65900","0.00868"
"4326","25.92000","9.66803","0.00834"
"4344","26.02800","9.67700","0.00840"
"4362","26.13600","9.68590","0.00871"
"4380","26.24400","9.69493","0.00876"
"4398","26.35200","9.70396","0.00842"
"4416","26.46000","9.71305","0.00860"
"4434","26.56800","9.72202","0.00868"
"4452","26.67600","9.73099","0.00864"
"4470","26.78400","9.73995","0.00812"
"4488","26.89200","9.74898","0.00839"
"4506","27.00000","9.75801","0.00880"
"4524","27.10800","9.76704","0.00862"
"4542","27.21600","9.77601","0.00854"
"4560","27.32400","9.78491","0.00859"
"4578","27.43200","9.79394","0.00839"
"4596","27.54000","9.80303","0.00846"
"4614","27.64800","9.81200","0.00882"
"4632","27.75600","9.82103","0.00877"
"4650","27.86400","9.82994","0.00860"
"4668","27.97200","9.83897","0.00855"
"4686","28.08000","9.84805","0.00857"
"4704","28.18800","9.85702","0.00873"
"4722","28.29600","9.86593","0.00834"
"4740","28.40400","9.87490","0.00851"
"4758","28.51200","9.88399","0.00859"
"4776","28.62000","9.89301","0.00882"
"4794","28.72800","9.90198","0.00860"
"4812","28.83600","9.91101","0.00869"
"4830","28.94400","9.91992","0.00857"
"4848","29.05200","9.92901","0.00852"
"4866","29.16000","9.93804","0.00851"
"4884","29.26800","9.94701","0.00894"
"4902","29.37600","9.95597","0.00844"
"4920","29.48400","9.96494","0.00868"
"4938","29.59200","9.97397","0.00862"
"4956","29.70000","9.98306","0.00830"
"4974","29.80800","9.99203","0.00856"
"4992","29.91600","10.00099","0.00866"
"5010","30.02400","10.00996","0.00858"
"5028","30.13200","10.01893","0.00879"
"5046","30.24000","10.02802","0.00851"
"5064","30.34800","10.03705","0.00857"
"5082","30.45600","10.04596","0.00897"
"5100","30.56400","10.05493","0.00825"
"5118","30.67200","10.06395","0.00871"
"5136","30.78000","10.07298","0.00872"
"5154","30.88800","10.08201","0.00852"
"5172","30.99600","10.09098","0.00903"
"5190","31.10400","10.09995","0.00867"
"5208","31.21200","10.10898","0.00857"
"5226","31.32000","10.11800","0.00872"
"5244","31.42800","10.12697","0.00823"
"5262","31.53600","10.13600","0.00862"
"5280","31.64400","10.14497","0.00863"
"5298","31.75200","10.15394","0.00869"
"5316","31.86000","10.16297","0.00861"
"5334","31.96800","10.17199","0.00848"
"5352","32.07600","10.18102","0.00819"
"5370","32.18400","10.18993","0.00879"
"5388","32.29200","10.19890","0.00849"
"5406","32.40000","10.20799","0.00894"
"5424","32.50800","10.21707","0.00868"
"5442","32.61600","10.22598","0.00846"
"5460","32.72400","10.23489","0.00835"
"5478","32.83200","10.24398","0.00882"
"5496","32.94000","10.25307","0.00852"
"5514","33.04800","10.26204","0.00902"
"5532","33.15600","10.27094","0.00848"
"5550","33.26400","10.27997","0.00892"
"5568","33.37200","10.28900","0.00861"
"5586","33.48000","10.29803","0.00859"
"5604","33.58800","10.30694","0.00872"
"5622","33.69600","10.31597","0.00844"
"5640","33.80400","10.32500","0.00859"
"5658","33.91200","10.33396","0.00873"
"5676","34.02000","10.34299","0.00901"
"5694","34.12800","10.35202","0.00863"
"5712","34.23600","10.36099","0.00876"
"5730","34.34400","10.36996","0.00868"
"5748","34.45200","10.37898","0.00852"
"5766","34.56000","10.38801","0.00844"
"5784","34.66800","10.39698","0.00866"
"5802","34.77600","10.40595","0.00847"
"5820","34.88400","10.41498","0.00853"
"5838","34.99200","10.42401","0.00908"
"5856","35.10000","10.43303","0.00868"
"5874","35.20800","10.44200","0.00841"
"5892","35.31600","10.45097","0.00884"
"5910","35.42400","10.45994","0.00883"
"5928","35.53200","10.46897","0.00877"
"5946","35.64000","10.47806","0.00834"
"5964","35.74800","10.48696","0.00881"
"5982","35.85600","10.49593","0.00882"
"6000","35.96400","10.50502","0.00856"
"6018","36.07200","10.51405","0.00893"
"6036","36.18000","10.52296","0.00869"
"6054","36.28800","10.53205","0.00878"
"6072","36.39600","10.54101","0.00899"
"6090","36.50400","10.54998","0.00901"
"6108","36.61200","10.55901","0.00898"
"6126","36.72000","10.56804","0.00910"
"6144","36.82800","10.57701","0.00884"
"6162","36.93600","10.58598","0.00893"
"6180","37.04400","10.59494","0.00884"
"6198","37.15200","10.60397","0.00880"
"6216","37.26000","10.61300","0.00894"
"6234","37.36800","10.62203","0.00911"
"6252","37.47600","10.63094","0.00882"
"6270","37.58400","10.63997","0.00906"
"6288","37.69200","10.64899","0.00889"
"6306","37.80000","10.65802","0.00894"
"6324","37.90800","10.66699","0.00892"
"6342","38.01600","10.67596","0.00892"
"6360","38.12400","10.68493","0.00895"
"6378","38.23200","10.69401","0.00919"
"6396","38.34000","10.70298","0.00890"
"6414","38.44800","10.71201","0.00909"
"6432","38.55600","10.72098","0.00877"
"6450","38.66400","10.72995","0.00852"
"6468","38.77200","10.73898","0.00921"
"6486","38.88000","10.74800","0.00882"
"6504","38.98800","10.75703","0.00872"
"6522","39.09600","10.76600","0.00880"
"6540","39.20400","10.77491","0.00926"
"6558","39.31200","10.78394","0.00876"
"6576","39.42000","10.79303","0.00915"
"6594","39.52800","10.80206","0.00909"
"6612","39.63600","10.81096","0.00929"
"6630","39.74400","10.81993","0.00896"
"6648","39.85200","10.82896","0.00859"
"6666","39.96000","10.83805","0.00872"
"6684","40.06800","10.84696","0.00897"
"6702","40.17600","10.85599","0.00909"
"6720","40.28400","10.86495","0.00892"
"6738","40.39200","10.87398","0.00895"
"6756","40.50000","10.88295","0.00860"
"6774","40.60800","10.89198","0.00913"
"6792","40.71600","10.90095","0.00877"
"6810","40.82400","10.90998","0.00899"
"6828","40.93200","10.91900","0.00918"
"6846","41.04000","10.92797","0.00925"
"6864","41.14800","10.93700","0.00916"
"6882","41.25600","10.94597","0.00939"
"6900","41.36400","10.95488","0.00887"
"6918","41.47200","10.96397","0.00898"
"6936","41.58000","10.97299","0.00890"
"6954","41.68800","10.98202","0.00910"
"6972","41.79600","10.99099","0.00913"
"6990","41.90400","10.99996","0.00890"
"7008","42.01200","11.00899","0.00924"
"7026","42.12000","11.01802","0.00901"
"7044","42.22800","11.02698","0.00892"
"7062","42.33600","11.03601","0.00903"
"7080","42.44400","11.04498","0.00906"
"7098","42.55200","11.05395","0.00888"
"7116","42.66000","11.06298","0.00910"
"7134","42.76800","11.07201","0.00906"
"7152","42.87600","11.08097","0.00899"
"7170","42.98400","11.09000","0.00881"
"7188","43.09200","11.09897","0.00879"
"7206","43.20000","11.10794","0.00900"
"7224","43.30800","11.11697","0.00926"
"7242","43.41600","11.12599","0.00920"
"7260","43.52400","11.13490","0.00868"
"7278","43.63200","11.14393","0.00916"
"7296","43.74000","11.15296","0.00929"
"7314","43.84800","11.16199","0.00881"
"7332","43.95600","11.17096","0.00924"
"7350","44.06400","11.17993","0.00898"
"7368","44.17200","11.18901","0.00885"
"7386","44.28000","11.19804","0.00882"
"7404","44.38800","11.20701","0.00885"
"7422","44.49600","11.21592","0.00889"
"7440","44.60400","11.22495","0.00908"
"7458","44.71200","11.23403","0.00877"
"7476","44.82000","11.24294","0.00903"
"7494","44.92800","11.25197","0.00891"
"7512","45.03600","11.26094","0.00888"
"7530","45.14400","11.26997","0.00899"
"7548","45.25200","11.27900","0.00864"
"7566","45.36000","11.28796","0.00879"
"7584","45.46800","11.29693","0.00909"
"7602","45.57600","11.30596","0.00896"
"7620","45.68400","11.31493","0.00898"
"7638","45.79200","11.32396","0.00899"
"7656","45.90000","11.33305","0.00895"
"7674","46.00800","11.34202","0.00918"
"7692","46.11600","11.35098","0.00909"
"7710","46.22400","11.35995","0.00915"
"7728","46.33200","11.36898","0.00922"
"7746","46.44000","11.37801","0.00903"
"7764","46.54800","11.38698","0.00896"
"7782","46.65600","11.39594","0.00908"
"7800","46.76400","11.40491","0.00887"
"7818","46.87200","11.41406","0.00905"
"7836","46.98000","11.42303","0.00903"
"7854","47.08800","11.43200","0.00878"
"7872","47.19600","11.44097","0.00893"
"7890","47.30400","11.44999","0.00904"
"7908","47.41200","11.45902","0.00888"
"7926","47.52000","11.46799","0.00915"
"7944","47.62800","11.47696","0.00900"
"7962","47.73600","11.48593","0.00901"
"7980","47.84400","11.49496","0.00920"
"7998","47.95200","11.50399","0.00882"
"8016","48.06000","11.51301","0.00865"
"8034","48.16800","11.52204","0.00908"
"8052","48.27600","11.53095","0.00917"
"8070","48.38400","11.53992","0.00922"
"8088","48.49200","11.54901","0.00912"
"8106","48.60000","11.55803","0.00924"
"8124","48.70800","11.56700","0.00921"
"8142","48.81600","11.57597","0.00904"
"8160","48.92400","11.58494","0.00871"
"8178","49.03200","11.59397","0.00918"
"8196","49.14000","11.60306","0.00878"
"8214","49.24800","11.61196","0.00926"
"8232","49.35600","11.62093","0.00905"
"8250","49.46400","11.62996","0.00878"
"8268","49.57200","11.63899","0.00879"
"8286","49.68000","11.64802","0.00884"
"8304","49.78800","11.65705","0.00872"
"8322","49.89600","11.66595","0.00909"
"8340","50.00400","11.67492","0.00906"
"8358","50.11200","11.68401","0.00882"
"8376","50.22000","11.69298","0.00918"
"8394","50.32800","11.70201","0.00893"
"8412","50.43600","11.71098","0.00930"
"8430","50.54400","11.71994","0.00918"
"8448","50.65200","11.72903","0.00928"
"8466","50.76000","11.73800","0.00900"
"8484","50.86800","11.74703","0.00939"
"8502","50.97600","11.75600","0.00924"
"8520","51.08400","11.76497","0.00880"
"8538","51.19200","11.77399","0.00883"
"8556","51.30000","11.78302","0.00921"
"8574","51.40800","11.79199","0.00917"
"8592","51.51600","11.80096","0.00937"
"8610","51.62400","11.80993","0.00900"
"8628","51.73200","11.81902","0.00936"
"8646","51.84000","11.82792","0.00935"
"8664","51.94800","11.83689","0.00924"
"8682","52.05600","11.84592","0.00916"
"8700","52.16400","11.85501","0.00911"
"8718","52.27200","11.86398","0.00922"
"8736","52.38000","11.87300","0.00880"
"8754","52.48800","11.88197","0.00900"
"8772","52.59600","11.89100","0.00907"
"8790","52.70400","11.89991","0.00942"
"8808","52.81200","11.90894","0.00906"
"8826","52.92000","11.91797","0.00905"
"8844","53.02800","11.92706","0.00925"
"8862","53.13600","11.93590","0.00883"
"8880","53.24400","11.94493","0.00936"
"8898","53.35200","11.95402","0.00931"
"8916","53.46000","11.96305","0.00897"
"8934","53.56800","11.97202","0.00899"
"8952","53.67600","11.98099","0.00949"
"8970","53.78400","11.99001","0.00912"
"8988","53.89200","11.99904","0.00903"
"9006","54.00000","12.00801","0.00932"
"9024","54.10800","12.01698","0.00949"
"9042","54.21600","12.02595","0.00941"
"9060","54.32400","12.03498","0.00942"
"9078","54.43200","12.04400","0.00935"
"9096","54.54000","12.05297","0.00940"
"9114","54.64800","12.06200","0.00952"
"9132","54.75600","12.07097","0.00921"
"9150","54.86400","12.08000","0.00913"
"9168","54.97200","12.08902","0.00919"
"9186","55.08000","12.09799","0.00939"
"9204","55.18800","12.10702","0.00926"
"9222","55.29600","12.11599","0.00930"
"9240","55.40400","12.12496","0.00936"
"9258","55.51200","12.13405","0.00909"
"9276","55.62000","12.14302","0.00941"
"9294","55.72800","12.15198","0.00919"
"9312","55.83600","12.16095","0.00968"
"9330","55.94400","12.16998","0.00952"
"9348","56.05200","12.17907","0.00891"
"9366","56.16000","12.18804","0.00966"
"9384","56.26800","12.19695","0.00940"
"9402","56.37600","12.20591","0.00939"
"9420","56.48400","12.21500","0.00941"
"9438","56.59200","12.22403","0.00949"
"9456","56.70000","12.23300","0.00916"
"9474","56.80800","12.24197","0.00990"
"9492","56.91600","12.25099","0.00956"
"9510","57.02400","12.25996","0.00964"
"9528","57.13200","12.26899","0.00931"
"9546","57.24000","12.27802","0.00950"
"9564","57.34800","12.28699","0.00969"
"9582","57.45600","12.29596","0.00937"
"9600","57.56400","12.30498","0.00917"
"9618","57.67200","12.31401","0.00918"
"9636","57.78000","12.32298","0.00969"
"9654","57.88800","12.33201","0.00938"
"9672","57.99600","12.34098","0.00972"
"9690","58.10400","12.35001","0.00917"
"9708","58.21200","12.35903","0.00914"
"9726","58.32000","12.36800","0.00936"
"9744","58.42800","12.37697","0.00925"
"9762","58.53600","12.38594","0.00955"
"9780","58.64400","12.39497","0.00930"
"9798","58.75200","12.40406","0.00923"
"9816","58.86000","12.41297","0.00955"
"9834","58.96800","12.42199","0.00948"
"9852","59.07600","12.43096","0.00911"
"9870","59.18400","12.43999","0.00907"
"9888","59.29200","12.44902","0.00923"
"9906","59.40000","12.45799","0.00936"
"9924","59.50800","12.46701","0.00953"
"9942","59.61600","12.47598","0.00901"
"9960","59.72400","12.48495","0.00917"
"9978","59.83200","12.49398","0.00948"
"9996","59.94000","12.50307","0.00929"
"10014","60.04800","12.51204","0.00954"
"10032","60.15600","12.52094","0.00953"
"10050","60.26400","12.52997","0.00937"
"10068","60.37200","12.53906","0.00946"
"10086","60.48000","12.54803","0.00950"
"10104","60.58800","12.55694","0.00952"
"10122","60.69600","12.56591","0.00967"
"10140","60.80400","12.57500","0.00957"
"10158","60.91200","12.58402","0.00951"
"10176","61.02000","12.59293","0.00941"
"10194","61.12800","12.60190","0.00936"
"10212","61.23600","12.61099","0.00933"
"10230","61.34400","12.62002","0.00915"
"10248","61.45200","12.62898","0.00934"
"10266","61.56000","12.63801","0.00931"
"10284","61.66800","12.64698","0.00950"
"10302","61.77600","12.65595","0.00962"
"10320","61.88400","12.66498","0.00942"
"10338","61.99200","12.67401","0.00952"
"10356","62.10000","12.68303","0.00936"
"10374","62.20800","12.69200","0.00939"
"10392","62.31600","12.70091","0.00949"
"10410","62.42400","12.71000","0.00933"
"10428","62.53200","12.71903","0.00946"
"10446","62.64000","12.72800","0.00973"
"10464","62.74800","12.73696","0.00986"
"10482","62.85600","12.74593","0.00964"
"10500","62.96400","12.75496","0.00972"
"10518","63.07200","12.76399","0.00979"
"10536","63.18000","12.77302","0.00978"
"10554","63.28800","12.78199","0.00950"
"10572","63.39600","12.79095","0.00952"
"10590","63.50400","12.79998","0.00944"
"10608","63.61200","12.80901","0.00985"
"10626","63.72000","12.81804","0.00944"
"10644","63.82800","12.82701","0.00956"
"10662","63.93600","12.83592","0.00979"
"10680","64.04400","12.84501","0.00931"
"10698","64.15200","12.85397","0.00951"
"10716","64.26000","12.86300","0.00992"
"10734","64.36800","12.87203","0.00979"
"10752","64.47600","12.88094","0.00983"
"10770","64.58400","12.88991","0.00988"
"10788","64.69200","12.89899","0.00976"
"10806","64.80000","12.90802","0.00986"
"10824","64.90800","12.91699","0.00960"
"10842","65.01600","12.92590","0.01011"
"10860","65.12400","12.93493","0.00965"
"10878","65.23200","12.94401","0.00988"
"10896","65.34000","12.95304","0.00960"
"10914","65.44800","12.96201","0.00992"
"10932","65.55600","12.97098","0.00990"
"10950","65.66400","12.97995","0.00980"
"10968","65.77200","12.98904","0.00951"
"10986","65.88000","12.99800","0.00973"
"11004","65.98800","13.00697","0.00958"
"11022","66.09600","13.01600","0.00966"
"11040","66.20400","13.02497","0.00943"
"11058","66.31200","13.03400","0.00985"
"11076","66.42000","13.04303","0.00954"
"11094","66.52800","13.05206","0.01004"
"11112","66.63600","13.06096","0.00990"
"11130","66.74400","13.06999","0.00955"
"11148","66.85200","13.07902","0.00954"
"11166","66.96000","13.08799","0.00970"
"11184","67.06800","13.09696","0.01009"
"11202","67.17600","13.10593","0.00934"
"11220","67.28400","13.11495","0.00952"
"11238","67.39200","13.12398","0.00968"
"11256","67.50000","13.13301","0.00969"
"11274","67.60800","13.14198","0.00958"
"11292","67.71600","13.15095","0.00943"
"11310","67.82400","13.16004","0.00981"
"11328","67.93200","13.16900","0.00958"
"11346","68.04000","13.17797","0.00992"
"11364","68.14800","13.18694","0.00976"
"11382","68.25600","13.19597","0.00929"
"11400","68.36400","13.20500","0.00933"
"11418","68.47200","13.21397","0.00958"
"11436","68.58000","13.22299","0.00995"
"11454","68.68800","13.23202","0.00983"
"11472","68.79600","13.24099","0.00983"
"11490","68.90400","13.25002","0.01007"
"11508","69.01200","13.25899","0.00963"
"11526","69.12000","13.26796","0.00974"
"11544","69.22800","13.27698","0.00975"
"11562","69.33600","13.28595","0.00985"
"11580","69.44400","13.29492","0.00978"
"11598","69.55200","13.30401","0.00980"
"11616","69.66000","13.31304","0.00948"
"11634","69.76800","13.32195","0.01020"
"11652","69.87600","13.33091","0.00959"
"11670","69.98400","13.34000","0.00982"
"11688","70.09200","13.34903","0.00994"
"11706","70.20000","13.35800","0.00971"
"11724","70.30800","13.36697","0.00991"
"11742","70.41600","13.37594","0.00977"
"11760","70.52400","13.38496","0.00976"
"11778","70.63200","13.39399","0.01021"
"11796","70.74000","13.40302","0.01005"
"11814","70.84800","13.41199","0.00981"
"11832","70.95600","13.42090","0.00959"
"11850","71.06400","13.42998","0.01034"
"11868","71.17200","13.43901","0.00976"
"11886","71.28000","13.44798","0.00957"
"11904","71.38800","13.45695","0.00983"
"11922","71.49600","13.46592","0.00942"
"11940","71.60400","13.47501","0.00970"
"11958","71.71200","13.48403","0.00973"
"11976","71.82000","13.49306","0.00992"
"11994","71.92800","13.50191","0.00945"
"12012","72.03600","13.51088","0.01000"
"12030","72.14400","13.52003","0.00972"
"12048","72.25200","13.52906","0.00977"
"12066","72.36000","13.53797","0.01000"
"12084","72.46800","13.54699","0.00987"
"12102","72.57600","13.55590","0.00975"
"12120","72.68400","13.56505","0.01005"
"12138","72.79200","13.57402","0.00984"
"12156","72.90000","13.58299","0.00986"
"12174","73.00800","13.59195","0.00986"
"12192","73.11600","13.60098","0.00974"
"12210","73.22400","13.60995","0.00962"
"12228","73.33200","13.61898","0.01000"
"12246","73.44000","13.62801","0.01014"
"12264","73.54800","13.63698","0.00988"
"12282","73.65600","13.64594","0.00999"
"12300","73.76400","13.65497","0.00989"
"12318","73.87200","13.66400","0.00959"
"12336","73.98000","13.67303","0.00978"
"12354","74.08800","13.68194","0.00962"
"12372","74.19600","13.69091","0.00995"
"12390","74.30400","13.70005","0.00974"
"12408","74.41200","13.70902","0.00941"
"12426","74.52000","13.71799","0.00969"
"12444","74.62800","13.72696","0.00992"
"12462","74.73600","13.73599","0.00989"
"12480","74.84400","13.74502","0.00962"
"12498","74.95200","13.75399","0.00955"
"12516","75.06000","13.76301","0.00977"
"12534","75.16800","13.77198","0.00982"
"12552","75.27600","13.78101","0.01009"
"12570","75.38400","13.78998","0.00978"
"12588","75.49200","13.79895","0.00960"
"12606","75.60000","13.80797","0.01010"
"12624","75.70800","13.81694","0.00984"
"12642","75.81600","13.82591","0.01005"
"12660","75.92400","13.83500","0.00952"
"12678","76.03200","13.84397","0.00995"
"12696","76.14000","13.85300","0.01017"
"12714","76.24800","13.86202","0.00944"
"12732","76.35600","13.87093","0.00928"
"12750","76.46400","13.88002","0.00981"
"12768","76.57200","13.88899","0.00960"
"12786","76.68000","13.89802","0.00976"
"12804","76.78800","13.90699","0.00966"
"12822","76.89600","13.91595","0.00973"
"12840","77.00400","13.92498","0.00994"
"12858","77.11200","13.93401","0.01001"
"12876","77.22000","13.94298","0.00970"
"12894","77.32800","13.95195","0.00977"
"12912","77.43600","13.96098","0.00971"
"12930","77.54400","13.97000","0.00961"
"12948","77.65200","13.97897","0.00954"
"12966","77.76000","13.98794","0.00953"
"12984","77.86800","13.99697","0.00980"
"13002","77.97600","14.00594","0.00950"
"13020","78.08400","14.01497","0.00984"
"13038","78.19200","14.02399","0.00970"
"13056","78.30000","14.03296","0.00984"
"13074","78.40800","14.04193","0.00971"
"13092","78.51600","14.05096","0.00972"
"13110","78.62400","14.05999","0.00965"
"13128","78.73200","14.06896","0.00983"
"13146","78.84000","14.07798","0.00943"
"13164","78.94800","14.08695","0.00967"
"13182","79.05600","14.09598","0.00972"
"13200","79.16400","14.10501","0.00980"
"13218","79.27200","14.11404","0.00983"
"13236","79.38000","14.12300","0.00984"
"13254","79.48800","14.13197","0.00986"
"13272","79.59600","14.14100","0.01018"
"13290","79.70400","14.15003","0.00958"
"13308","79.81200","14.15900","0.00980"
"13326","79.92000","14.16797","0.01025"
"13344","80.02800","14.17694","0.00988"
"13362","80.13600","14.18596","0.00967"
"13380","80.24400","14.19499","0.00989"
"13398","80.35200","14.20396","0.00984"
"13416","80.46000","14.21305","0.00968"
"13434","80.56800","14.22196","0.00972"
"13452","80.67600","14.23093","0.00979"
"13470","80.78400","14.24001","0.00968"
"13488","80.89200","14.24904","0.00992"
"13506","81.00000","14.25801","0.00981"
"13524","81.10800","14.26698","0.00994"
"13542","81.21600","14.27595","0.01021"
"13560","81.32400","14.28504","0.00982"
"13578","81.43200","14.29400","0.00973"
"13596","81.54000","14.30297","0.00978"
"13614","81.64800","14.31194","0.01004"
"13632","81.75600","14.32097","0.00953"
"13650","81.86400","14.33000","0.00997"
"13668","81.97200","14.33902","0.01029"
"13686","82.08000","14.34799","0.00993"
"13704","82.18800","14.35696","0.00997"
"13722","82.29600","14.36599","0.00958"
"13740","82.40400","14.37502","0.01022"
"13758","82.51200","14.38399","0.00988"
"13776","82.62000","14.39301","0.00982"
"13794","82.72800","14.40198","0.00972"
"13812","82.83600","14.41095","0.00986"
"13830","82.94400","14.41998","0.00979"
"13848","83.05200","14.42901","0.00976"
"13866","83.16000","14.43804","0.00995"
"13884","83.26800","14.44695","0.00979"
"13902","83.37600","14.45591","0.00982"
"13920","83.48400","14.46500","0.00978"
"13938","83.59200","14.47403","0.00992"
"13956","83.70000","14.48300","0.00984"
"13974","83.80800","14.49197","0.00961"
"13992","83.91600","14.50100","0.00955"
"14010","84.02400","14.51002","0.00988"
"14028","84.13200","14.51899","0.00997"
"14046","84.24000","14.52796","0.00975"
"14064","84.34800","14.53693","0.01016"
"14082","84.45600","14.54602","0.01010"
"14100","84.56400","14.55504","0.01030"
"14118","84.67200","14.56395","0.00986"
"14136","84.78000","14.57298","0.01001"
"14154","84.88800","14.58201","0.01006"
"14172","84.99600","14.59098","0.00997"
"14190","85.10400","14.59995","0.00991"
"14208","85.21200","14.60898","0.01004"
"14226","85.32000","14.61800","0.00943"
"14244","85.42800","14.62697","0.00986"
"14262","85.53600","14.63594","0.00974"
"14280","85.64400","14.64503","0.00995"
"14298","85.75200","14.65400","0.01007"
"14316","85.86000","14.66302","0.00990"
"14334","85.96800","14.67199","0.00987"
"14352","86.07600","14.68096","0.00983"
"14370","86.18400","14.68999","0.00977"
"14388","86.29200","14.69902","0.01023"
"14406","86.40000","14.70799","0.01011"
"14424","86.50800","14.71696","0.01004"
"14442","86.61600","14.72592","0.01027"
"14460","86.72400","14.73501","0.00982"
"14478","86.83200","14.74398","0.00990"
"14496","86.94000","14.75295","0.00989"
"14514","87.04800","14.76198","0.01014"
"14532","87.15600","14.77100","0.01027"
"14550","87.26400","14.77997","0.00988"
"14568","87.37200","14.78900","0.00990"
"14586","87.48000","14.79803","0.00969"
"14604","87.58800","14.80694","0.01007"
"14622","87.69600","14.81597","0.00988"
"14640","87.80400","14.82499","0.00989"
"14658","87.91200","14.83402","0.01019"
"14676","88.02000","14.84299","0.00960"
"14694","88.12800","14.85196","0.00969"
"14712","88.23600","14.86093","0.00999"
"14730","88.34400","14.87002","0.01012"
"14748","88.45200","14.87898","0.01006"
"14766","88.56000","14.88789","0.00954"
"14784","88.66800","14.89692","0.00986"
"14802","88.77600","14.90595","0.01020"
"14820","88.88400","14.91504","0.00970"
"14838","88.99200","14.92401","0.00962"
"14856","89.10000","14.93297","0.00971"
"14874","89.20800","14.94200","0.01005"
"14892","89.31600","14.95103","0.00982"
"14910","89.42400","14.96000","0.01000"
"14928","89.53200","14.96903","0.01034"
"14946","89.64000","14.97799","0.01020"
"14964","89.74800","14.98696","0.00980"
"14982","89.85600","14.99593","0.01018"
"15000","89.96400","15.00508","0.00988"
"15018","90.07200","15.01399","0.01007"
"15036","90.18000","15.02302","0.01014"
"15054","90.28800","15.03193","0.00993"
"15072","90.39600","15.04095","0.00969"
"15090","90.50400","15.05004","0.00984"
"15108","90.61200","15.05901","0.01009"
"15126","90.72000","15.06792","0.00976"
"15144","90.82800","15.07695","0.00991"
"15162","90.93600","15.08592","0.01019"
"15180","91.04400","15.09501","0.01035"
"15198","91.15200","15.10397","0.00967"
"15216","91.26000","15.11300","0.00999"
"15234","91.36800","15.12197","0.01021"
"15252","91.47600","15.13094","0.00997"
"15270","91.58400","15.13997","0.01017"
"15288","91.69200","15.14899","0.00966"
"15306","91.80000","15.15796","0.01017"
"15324","91.90800","15.16693","0.00981"
"15342","92.01600","15.17596","0.00976"
"15360","92.12400","15.18499","0.01004"
"15378","92.23200","15.19402","0.01000"
"15396","92.34000","15.20304","0.01001"
"15414","92.44800","15.21195","0.01011"
"15432","92.55600","15.22098","0.01052"
"15450","92.66400","15.22995","0.00987"
"15468","92.77200","15.23904","0.01008"
"15486","92.88000","15.24795","0.00994"
"15504","92.98800","15.25691","0.01021"
"15522","93.09600","15.26600","0.00979"
"15540","93.20400","15.27509","0.01013"
"15558","93.31200","15.28400","0.01000"
"15576","93.42000","15.29303","0.00965"
"15594","93.52800","15.30194","0.01003"
"15612","93.63600","15.31102","0.01013"
"15630","93.74400","15.32005","0.00983"
"15648","93.85200","15.32902","0.01010"
"15666","93.96000","15.33799","0.01032"
"15684","94.06800","15.34696","0.00976"
"15702","94.17600","15.35599","0.01048"
"15720","94.28400","15.36501","0.01002"
"15738","94.39200","15.37398","0.00992"
"15756","94.50000","15.38301","0.00990"
"15774","94.60800","15.39198","0.00995"
"15792","94.71600","15.40095","0.01007"
"15810","94.82400","15.41004","0.01027"
"15828","94.93200","15.41900","0.01048"
"15846","95.04000","15.42797","0.01008"
"15864","95.14800","15.43688","0.01048"
"15882","95.25600","15.44597","0.01020"
"15900","95.36400","15.45500","0.01000"
"15918","95.47200","15.46397","0.01028"
"15936","95.58000","15.47293","0.01014"
"15954","95.68800","15.48196","0.01000"
"15972","95.79600","15.49099","0.01015"
"15990","95.90400","15.50002","0.01001"
"16008","96.01200","15.50899","0.01043"
"16026","96.12000","15.51796","0.01021"
"16044","96.22800","15.52692","0.01025"
"16062","96.33600","15.53601","0.01027"
"16080","96.44400","15.54498","0.01039"
"16098","96.55200","15.55401","0.01016"
"16116","96.66000","15.56304","0.01002"
"16134","96.76800","15.57195","0.01042"
"16152","96.87600","15.58097","0.01009"
"16170","96.98400","15.59000","0.00970"
"16188","97.09200","15.59903","0.01002"
"16206","97.20000","15.60794","0.00981"
"16224","97.30800","15.61691","0.01024"
"16242","97.41600","15.62599","0.01014"
"16260","97.52400","15.63502","0.01009"
"16278","97.63200","15.64405","0.01002"
"16296","97.74000","15.65296","0.01028"
"16314","97.84800","15.66193","0.01021"
"16332","97.95600","15.67101","0.01024"
"16350","98.06400","15.68004","0.01044"
"16368","98.17200","15.68901","0.01029"
"16386","98.28000","15.69798","0.01030"
"16404","98.38800","15.70689","0.01011"
"16422","98.49600","15.71604","0.00995"
"16440","98.60400","15.72501","0.01029"
"16458","98.71200","15.73403","0.01039"
"16476","98.82000","15.74300","0.01011"
"16494","98.92800","15.75197","0.01008"
"16512","99.03600","15.76100","0.00997"
"16530","99.14400","15.77003","0.01001"
"16548","99.25200","15.77900","0.00980"
"16566","99.36000","15.78796","0.01041"
"16584","99.46800","15.79693","0.00999"
"16602","99.57600","15.80596","0.01034"
"16620","99.68400","15.81499","0.01012"
"16638","99.79200","15.82402","0.01045"
"16656","99.90000","15.83298","0.01046"
"16674","100.00800","15.84195","0.01012"
"16692","100.11600","15.85098","0.01025"
"16710","100.22400","15.86007","0.01058"
"16728","100.33200","15.86898","0.01010"
"16746","100.44000","15.87795","0.01034"
"16764","100.54800","15.88698","0.01016"
"16782","100.65600","15.89600","0.01032"
"16800","100.76400","15.90497","0.01055"
"16818","100.87200","15.91400","0.01046"
"16836","100.98000","15.92297","0.01012"
"16854","101.08800","15.93200","0.01036"
"16872","101.19600","15.94097","0.01072"
"16890","101.30400","15.94993","0.01043"
"16908","101.41200","15.95896","0.01046"
"16926","101.52000","15.96799","0.01071"
"16944","101.62800","15.97690","0.01061"
"16962","101.73600","15.98599","0.01045"
"16980","101.84400","15.99496","0.01049"
"16998","101.95200","16.00404","0.01051"
"17016","102.06000","16.01295","0.01033"
"17034","102.16800","16.02192","0.01047"
"17052","102.27600","16.03095","0.01037"
"17070","102.38400","16.04004","0.01051"
"17088","102.49200","16.04895","0.01028"
"17106","102.60000","16.05791","0.01036"
"17124","102.70800","16.06694","0.01069"
"17142","102.81600","16.07597","0.01057"
"17160","102.92400","16.08494","0.01024"
"17178","103.03200","16.09403","0.01033"
"17196","103.14000","16.10294","0.01026"
"17214","103.24800","16.11197","0.01066"
"17232","103.35600","16.12099","0.01024"
"17250","103.46400","16.12996","0.01040"
"17268","103.57200","16.13899","0.01044"
"17286","103.68000","16.14796","0.01080"
"17304","103.78800","16.15693","0.01046"
"17322","103.89600","16.16595","0.01074"
"17340","104.00400","16.17498","0.01037"
"17358","104.11200","16.18401","0.01057"
"17376","104.22000","16.19298","0.01053"
"17394","104.32800","16.20195","0.01028"
"17412","104.43600","16.21098","0.01060"
"17430","104.54400","16.22000","0.01060"
"17448","104.65200","16.22897","0.01079"
"17466","104.76000","16.23794","0.01045"
"17484","104.86800","16.24697","0.01081"
"17502","104.97600","16.25606","0.01052"
"17520","105.08400","16.26497","0.01029"
"17538","105.19200","16.27399","0.01081"
"17556","105.30000","16.28296","0.01045"
"17574","105.40800","16.29199","0.01062"
"17592","105.51600","16.30102","0.01048"
"17610","105.62400","16.30993","0.01061"
"17628","105.73200","16.31895","0.01069"
"17646","105.84000","16.32798","0.01045"
"17664","105.94800","16.33695","0.01077"
"17682","106.05600","16.34598","0.01067"
"17700","106.16400","16.35495","0.01053"
"17718","106.27200","16.36404","0.01070"
"17736","106.38000","16.37295","0.01080"
"17754","106.48800","16.38191","0.01050"
"17772","106.59600","16.39100","0.01043"
"17790","106.70400","16.39997","0.01049"
"17808","106.81200","16.40900","0.01084"
"17826","106.92000","16.41797","0.01065"
"17844","107.02800","16.42693","0.01059"
"17862","107.13600","16.43596","0.01103"
"17880","107.24400","16.44499","0.01115"
"17898","107.35200","16.45402","0.01051"
"17916","107.46000","16.46299","0.01064"
"17934","107.56800","16.47196","0.01085"
"17952","107.67600","16.48098","0.01048"
"17970","107.78400","16.49001","0.01104"
"17988","107.89200","16.49898","0.01103"
"18006","108.00000","16.50801","0.01078"
"18024","108.10800","16.51698","0.01040"
"18042","108.21600","16.52595","0.01063"
"18060","108.32400","16.53498","0.01078"
"18078","108.43200","16.54406","0.01101"
"18096","108.54000","16.55297","0.01078"
"18114","108.64800","16.56194","0.01060"
"18132","108.75600","16.57097","0.01079"
"18150","108.86400","16.58000","0.01073"
"18168","108.97200","16.58903","0.01090"
"18186","109.08000","16.59793","0.01078"
"18204","109.18800","16.60696","0.01062"
"18222","109.29600","16.61599","0.01101"
"18240","109.40400","16.62502","0.01070"
"18258","109.51200","16.63399","0.01107"
"18276","109.62000","16.64301","0.01118"
"18294","109.72800","16.65198","0.01106"
"18312","109.83600","16.66101","0.01046"
"18330","109.94400","16.66992","0.01074"
"18348","110.05200","16.67895","0.01097"
"18366","110.16000","16.68792","0.01111"
"18384","110.26800","16.69695","0.01086"
"18402","110.37600","16.70597","0.01070"
"18420","110.48400","16.71500","0.01118"
"18438","110.59200","16.72397","0.01097"
"18456","110.70000","16.73300","0.01124"
"18474","110.80800","16.74196","0.01119"
"18492","110.91600","16.75099","0.01089"
"18510","111.02400","16.76002","0.01118"
"18528","111.13200","16.76899","0.01119"
"18546","111.24000","16.77802","0.01118"
"18564","111.34800","16.78699","0.01089"
"18582","111.45600","16.79607","0.01118"
"18600","111.56400","16.80504","0.01107"
"18618","111.67200","16.81395","0.01093"
"18636","111.78000","16.82298","0.01107"
"18654","111.88800","16.83195","0.01097"
"18672","111.99600","16.84104","0.01124"
"18690","112.10400","16.84995","0.01110"
"18708","112.21200","16.85897","0.01106"
"18726","112.32000","16.86794","0.01114"
"18744","112.42800","16.87697","0.01143"
"18762","112.53600","16.88600","0.01141"
"18780","112.64400","16.89503","0.01077"
"18798","112.75200","16.90400","0.01120"
"18816","112.86000","16.91302","0.01096"
"18834","112.96800","16.92199","0.01141"
"18852","113.07600","16.93096","0.01107"
"18870","113.18400","16.94005","0.01124"
"18888","113.29200","16.94902","0.01108"
"18906","113.40000","16.95793","0.01086"
"18924","113.50800","16.96695","0.01103"
"18942","113.61600","16.97604","0.01114"
"18960","113.72400","16.98501","0.01139"
"18978","113.83200","16.99398","0.01117"
"18996","113.94000","17.00295","0.01093"
"19014","114.04800","17.01192","0.01077"
"19032","114.15600","17.02100","0.01089"
"19050","114.26400","17.02997","0.01098"
"19068","114.37200","17.03900","0.01117"
"19086","114.48000","17.04791","0.01116"
"19104","114.58800","17.05694","0.01101"
"19122","114.69600","17.06603","0.01122"
"19140","114.80400","17.07505","0.01092"
"19158","114.91200","17.08402","0.01134"
"19176","115.02000","17.09293","0.01158"
"19194","115.12800","17.10196","0.01130"
"19212","115.23600","17.11099","0.01120"
"19230","115.34400","17.11996","0.01117"
"19248","115.45200","17.12904","0.01131"
"19266","115.56000","17.13795","0.01109"
"19284","115.66800","17.14692","0.01154"
"19302","115.77600","17.15601","0.01169"
"19320","115.88400","17.16504","0.01083"
"19338","115.99200","17.17401","0.01097"
"19356","116.10000","17.18297","0.01117"
"19374","116.20800","17.19194","0.01132"
"19392","116.31600","17.20103","0.01134"
"19410","116.42400","17.21000","0.01122"
"19428","116.53200","17.21891","0.01134"
"19446","116.64000","17.22793","0.01109"
"19464","116.74800","17.23696","0.01126"
"19482","116.85600","17.24599","0.01152"
"19500","116.96400","17.25502","0.01137"
"19518","117.07200","17.26399","0.01166"
"19536","117.18000","17.27296","0.01142"
"19554","117.28800","17.28198","0.01101"
"19572","117.39600","17.29101","0.01120"
"19590","117.50400","17.29998","0.01155"
"19608","117.61200","17.30901","0.01176"
"19626","117.72000","17.31798","0.01141"
"19644","117.82800","17.32695","0.01140"
"19662","117.93600","17.33603","0.01150"
"19680","118.04400","17.34500","0.01166"
"19698","118.15200","17.35403","0.01097"
"19716","118.26000","17.36300","0.01145"
"19734","118.36800","17.37197","0.01121"
"19752","118.47600","17.38099","0.01161"
"19770","118.58400","17.39002","0.01167"
"19788","118.69200","17.39899","0.01158"
"19806","118.80000","17.40790","0.01163"
"19824","118.90800","17.41699","0.01157"
"19842","119.01600","17.42602","0.01146"
"19860","119.12400","17.43499","0.01144"
"19878","119.23200","17.44395","0.01160"
"19896","119.34000","17.45298","0.01128"
"19914","119.44800","17.46201","0.01156"
"19932","119.55600","17.47098","0.01146"
"19950","119.66400","17.48001","0.01154"
"19968","119.77200","17.48898","0.01127"
"19986","119.88000","17.49795","0.01126"
"20004","119.98800","17.50697","0.01139"
"20022","120.09600","17.51600","0.01146"
"20040","120.20400","17.52497","0.01153"
"20058","120.31200","17.53400","0.01130"
"20076","120.42000","17.54296","0.01156"
"20094","120.52800","17.55194","0.01151"
"20112","120.63600","17.56108","0.01160"
"20130","120.74400","17.56999","0.01167"
"20148","120.85200","17.57896","0.01109"
"20166","120.96000","17.58793","0.01143"
"20184","121.06800","17.59696","0.01120"
"20202","121.17600","17.60604","0.01124"
"20220","121.28400","17.61495","0.01141"
"20238","121.39200","17.62392","0.01143"
"20256","121.50000","17.63295","0.01143"
"20274","121.60800","17.64198","0.01189"
"20292","121.71600","17.65101","0.01141"
"20310","121.82400","17.66003","0.01168"
"20328","121.93200","17.66894","0.01173"
"20346","122.04000","17.67791","0.01164"
"20364","122.14800","17.68700","0.01178"
"20382","122.25600","17.69603","0.01135"
"20400","122.36400","17.70500","0.01176"
"20418","122.47200","17.71396","0.01167"
"20436","122.58000","17.72293","0.01127"
"20454","122.68800","17.73202","0.01164"
"20472","122.79600","17.74099","0.01176"
"20490","122.90400","17.75002","0.01192"
"20508","123.01200","17.75899","0.01182"
"20526","123.12000","17.76789","0.01151"
"20544","123.22800","17.77698","0.01171"
"20562","123.33600","17.78607","0.01174"
"20580","123.44400","17.79504","0.01146"
"20598","123.55200","17.80395","0.01190"
"20616","123.66000","17.81292","0.01171"
"20634","123.76800","17.82200","0.01158"
"20652","123.87600","17.83103","0.01146"
"20670","123.98400","17.84000","0.01182"
"20688","124.09200","17.84903","0.01145"
"20706","124.20000","17.85794","0.01165"
"20724","124.30800","17.86697","0.01151"
"20742","124.41600","17.87599","0.01147"
"20760","124.52400","17.88502","0.01164"
"20778","124.63200","17.89399","0.01152"
"20796","124.74000","17.90296","0.01176"
"20814","124.84800","17.91193","0.01173"
"20832","124.95600","17.92096","0.01138"
"20850","125.06400","17.93004","0.01140"
"20868","125.17200","17.93895","0.01135"
"20886","125.28000","17.94792","0.01117"
"20904","125.38800","17.95695","0.01131"
"20922","125.49600","17.96604","0.01097"
"20940","125.60400","17.97501","0.01088"
"20958","125.71200","17.98397","0.01113"
"20976","125.82000","17.99300","0.01114"
"20994","125.92800","18.00197","0.01136"
"21012","126.03600","18.01106","0.01128"
"21030","126.14400","18.02003","0.01102"
"21048","126.25200","18.02900","0.01078"
"21066","126.36000","18.03796","0.01088"
"21084","126.46800","18.04693","0.01113"
"21102","126.57600","18.05596","0.01090"
"21120","126.68400","18.06505","0.01083"
"21138","126.79200","18.07402","0.01085"
"21156","126.90000","18.08293","0.01055"
"21174","127.00800","18.09196","0.01106"
"21192","127.11600","18.10092","0.01099"
"21210","127.22400","18.11001","0.01117"
"21228","127.33200","18.11898","0.01082"
"21246","127.44000","18.12795","0.01086"
"21264","127.54800","18.13698","0.01128"
"21282","127.65600","18.14600","0.01105"
"21300","127.76400","18.15503","0.01103"
"21318","127.87200","18.16400","0.01086"
"21336","127.98000","18.17297","0.01069"
"21354","128.08800","18.18194","0.01104"
"21372","128.19600","18.19102","0.01098"
"21390","128.30400","18.19999","0.01138"
"21408","128.41200","18.20896","0.01097"
"21426","128.52000","18.21793","0.01083"
"21444","128.62800","18.22702","0.01075"
"21462","128.73600","18.23599","0.01111"
"21480","128.84400","18.24502","0.01098"
"21498","128.95200","18.25398","0.01131"
"21516","129.06000","18.26295","0.01105"
"21534","129.16800","18.27192","0.01080"
"21552","129.27600","18.28095","0.01100"
"21570","129.38400","18.28998","0.01146"
"21588","129.49200","18.29901","0.01128"
"21606","129.60000","18.30791","0.01131"
"21624","129.70800","18.31694","0.01130"
"21642","129.81600","18.32597","0.01098"
"21660","129.92400","18.33500","0.01080"
"21678","130.03200","18.34397","0.01115"
"21696","130.14000","18.35294","0.01100"
"21714","130.24800","18.36196","0.01136"
"21732","130.35600","18.37099","0.01114"
"21750","130.46400","18.38002","0.01116"
"21768","130.57200","18.38899","0.01116"
"21786","130.68000","18.39796","0.01140"
"21804","130.78800","18.40705","0.01081"
"21822","130.89600","18.41595","0.01102"
"21840","131.00400","18.42498","0.01115"
"21858","131.11200","18.43401","0.01135"
"21876","131.22000","18.44298","0.01108"
"21894","131.32800","18.45201","0.01118"
"21912","131.43600","18.46097","0.01121"
"21930","131.54400","18.47000","0.01108"
"21948","131.65200","18.47897","0.01114"
"21966","131.76000","18.48794","0.01124"
"21984","131.86800","18.49697","0.01109"
"22002","131.97600","18.50600","0.01094"
"22020","132.08400","18.51502","0.01088"
"22038","132.19200","18.52393","0.01111"
"22056","132.30000","18.53290","0.01132"
"22074","132.40800","18.54199","0.01123"
"22092","132.51600","18.55102","0.01112"
"22110","132.62400","18.55999","0.01092"
"22128","132.73200","18.56895","0.01077"
"22146","132.84000","18.57792","0.01093"
"22164","132.94800","18.58701","0.01125"
"22182","133.05600","18.59598","0.01106"
"22200","133.16400","18.60501","0.01095"
"22218","133.27200","18.61398","0.01082"
"22236","133.38000","18.62300","0.01102"
"22254","133.48800","18.63197","0.01132"
"22272","133.59600","18.64094","0.01119"
"22290","133.70400","18.64997","0.01127"
"22308","133.81200","18.65900","0.01126"
"22326","133.92000","18.66791","0.01114"
"22344","134.02800","18.67694","0.01110"
"22362","134.13600","18.68602","0.01099"
"22380","134.24400","18.69505","0.01110"
"22398","134.35200","18.70396","0.01085"
"22416","134.46000","18.71287","0.01104"
"22434","134.56800","18.72202","0.01082"
"22452","134.67600","18.73104","0.01113"
"22470","134.78400","18.74001","0.01085"
"22488","134.89200","18.74898","0.01142"
"22506","135.00000","18.75795","0.01105"
"22524","135.10800","18.76698","0.01099"
"22542","135.21600","18.77601","0.01103"
"22560","135.32400","18.78504","0.01140"
"22578","135.43200","18.79394","0.01104"
"22596","135.54000","18.80291","0.01077"
"22614","135.64800","18.81200","0.01069"
"22632","135.75600","18.82097","0.01119"
"22650","135.86400","18.83000","0.01095"
"22668","135.97000","18.83879","0.01101"