File: Trajectories_together/161218Specimen_RawData_4.csv
"","V1","V2","V3"
"1","End date","12/18/2016",""
"2","Specimen label","16AT_26_run2",""
"3","Maximum Load","0.19149","N"
"4","Time","Extension","Load"
"5","(s)","(mm)","(N)"
"6","0.00000","0.00000","-0.00028"
"58","0.31200","0.02535","0.00010"
"110","0.62400","0.05214","0.00037"
"162","0.93600","0.07820","0.00026"
"214","1.24800","0.10415","0.00055"
"266","1.56000","0.13016","0.00075"
"318","1.87200","0.15623","0.00087"
"370","2.18400","0.18218","0.00067"
"422","2.49600","0.20813","0.00097"
"474","2.80800","0.23414","0.00122"
"526","3.12000","0.26014","0.00142"
"578","3.43200","0.28615","0.00129"
"630","3.74400","0.31210","0.00145"
"682","4.05600","0.33817","0.00135"
"734","4.36800","0.36412","0.00156"
"786","4.68000","0.39013","0.00146"
"838","4.99200","0.41614","0.00180"
"890","5.30400","0.44214","0.00213"
"942","5.61600","0.46815","0.00141"
"994","5.92800","0.49410","0.00185"
"1046","6.24000","0.52011","0.00145"
"1098","6.55200","0.54606","0.00175"
"1150","6.86400","0.57213","0.00138"
"1202","7.17600","0.59819","0.00173"
"1254","7.48800","0.62414","0.00162"
"1306","7.80000","0.65015","0.00158"
"1358","8.11200","0.67610","0.00208"
"1410","8.42400","0.70217","0.00163"
"1462","8.73600","0.72818","0.00141"
"1514","9.04800","0.75419","0.00181"
"1566","9.36000","0.78013","0.00197"
"1618","9.67200","0.80614","0.00202"
"1670","9.98400","0.83209","0.00215"
"1722","10.29600","0.85804","0.00220"
"1774","10.60800","0.88417","0.00251"
"1826","10.92000","0.91018","0.00219"
"1878","11.23200","0.93618","0.00259"
"1930","11.54400","0.96219","0.00241"
"1982","11.85600","0.98814","0.00245"
"2034","12.16800","1.01415","0.00263"
"2086","12.48000","1.04016","0.00263"
"2138","12.79200","1.06611","0.00258"
"2190","13.10400","1.09212","0.00315"
"2242","13.41600","1.11812","0.00252"
"2294","13.72800","1.14413","0.00292"
"2346","14.04000","1.17008","0.00278"
"2398","14.35200","1.19621","0.00283"
"2450","14.66400","1.22216","0.00286"
"2502","14.97600","1.24811","0.00283"
"2554","15.28800","1.27417","0.00323"
"2606","15.60000","1.30012","0.00298"
"2658","15.91200","1.32619","0.00306"
"2710","16.22400","1.35214","0.00290"
"2762","16.53600","1.37815","0.00353"
"2814","16.84800","1.40416","0.00313"
"2866","17.16000","1.43011","0.00364"
"2918","17.47200","1.45617","0.00386"
"2970","17.78400","1.48212","0.00363"
"3022","18.09600","1.50819","0.00339"
"3074","18.40800","1.53414","0.00377"
"3126","18.72000","1.56015","0.00410"
"3178","19.03200","1.58610","0.00406"
"3230","19.34400","1.61216","0.00384"
"3282","19.65600","1.63817","0.00423"
"3334","19.96800","1.66412","0.00406"
"3386","20.28000","1.69013","0.00396"
"3438","20.59200","1.71614","0.00437"
"3490","20.90400","1.74209","0.00442"
"3542","21.21600","1.76816","0.00445"
"3594","21.52800","1.79416","0.00413"
"3646","21.84000","1.82017","0.00434"
"3698","22.15200","1.84612","0.00419"
"3750","22.46400","1.87213","0.00432"
"3802","22.77600","1.89814","0.00408"
"3854","23.08800","1.92415","0.00420"
"3906","23.40000","1.95016","0.00421"
"3958","23.71200","1.97610","0.00438"
"4010","24.02400","2.00217","0.00396"
"4062","24.33600","2.02812","0.00432"
"4114","24.64800","2.05413","0.00410"
"4166","24.96000","2.08014","0.00449"
"4218","25.27200","2.10609","0.00472"
"4270","25.58400","2.13215","0.00461"
"4322","25.89600","2.15804","0.00479"
"4374","26.20800","2.18411","0.00468"
"4426","26.52000","2.21012","0.00420"
"4478","26.83200","2.23619","0.00438"
"4530","27.14400","2.26214","0.00428"
"4582","27.45600","2.28809","0.00435"
"4634","27.76800","2.31415","0.00469"
"4686","28.08000","2.34004","0.00466"
"4738","28.39200","2.36611","0.00456"
"4790","28.70400","2.39212","0.00483"
"4842","29.01600","2.41813","0.00480"
"4894","29.32800","2.44414","0.00522"
"4946","29.64000","2.47008","0.00533"
"4998","29.95200","2.49615","0.00486"
"5050","30.26400","2.52216","0.00515"
"5102","30.57600","2.54823","0.00491"
"5154","30.88800","2.57418","0.00530"
"5206","31.20000","2.60007","0.00541"
"5258","31.51200","2.62614","0.00459"
"5310","31.82400","2.65208","0.00500"
"5362","32.13600","2.67815","0.00501"
"5414","32.44800","2.70410","0.00519"
"5466","32.76000","2.73017","0.00510"
"5518","33.07200","2.75618","0.00552"
"5570","33.38400","2.78207","0.00531"
"5622","33.69600","2.80814","0.00556"
"5674","34.00800","2.83414","0.00568"
"5726","34.32000","2.86015","0.00607"
"5778","34.63200","2.88616","0.00591"
"5830","34.94400","2.91211","0.00576"
"5882","35.25600","2.93812","0.00619"
"5934","35.56800","2.96413","0.00577"
"5986","35.88000","2.99013","0.00613"
"6038","36.19200","3.01608","0.00598"
"6090","36.50400","3.04215","0.00648"
"6142","36.81600","3.06816","0.00655"
"6194","37.12800","3.09417","0.00623"
"6246","37.44000","3.12018","0.00683"
"6298","37.75200","3.14613","0.00685"
"6350","38.06400","3.17213","0.00656"
"6402","38.37600","3.19814","0.00661"
"6454","38.68800","3.22409","0.00673"
"6506","39.00000","3.25016","0.00721"
"6558","39.31200","3.27611","0.00724"
"6610","39.62400","3.30218","0.00734"
"6662","39.93600","3.32812","0.00705"
"6714","40.24800","3.35419","0.00692"
"6766","40.56000","3.38014","0.00676"
"6818","40.87200","3.40609","0.00695"
"6870","41.18400","3.43222","0.00695"
"6922","41.49600","3.45805","0.00698"
"6974","41.80800","3.48418","0.00735"
"7026","42.12000","3.51006","0.00751"
"7078","42.43200","3.53613","0.00667"
"7130","42.74400","3.56220","0.00696"
"7182","43.05600","3.58815","0.00735"
"7234","43.36800","3.61416","0.00733"
"7286","43.68000","3.64011","0.00751"
"7338","43.99200","3.66617","0.00745"
"7390","44.30400","3.69212","0.00772"
"7442","44.61600","3.71813","0.00742"
"7494","44.92800","3.74420","0.00761"
"7546","45.24000","3.77009","0.00761"
"7598","45.55200","3.79616","0.00801"
"7650","45.86400","3.82211","0.00795"
"7702","46.17600","3.84811","0.00784"
"7754","46.48800","3.87418","0.00751"
"7806","46.80000","3.90013","0.00739"
"7858","47.11200","3.92614","0.00763"
"7910","47.42400","3.95215","0.00812"
"7962","47.73600","3.97816","0.00796"
"8014","48.04800","4.00416","0.00835"
"8066","48.36000","4.03017","0.00783"
"8118","48.67200","4.05618","0.00823"
"8170","48.98400","4.08207","0.00820"
"8222","49.29600","4.10820","0.00823"
"8274","49.60800","4.13409","0.00849"
"8326","49.92000","4.16016","0.00764"
"8378","50.23200","4.18616","0.00795"
"8430","50.54400","4.21211","0.00786"
"8482","50.85600","4.23818","0.00843"
"8534","51.16800","4.26407","0.00843"
"8586","51.48000","4.29020","0.00842"
"8638","51.79200","4.31615","0.00895"
"8690","52.10400","4.34215","0.00841"
"8742","52.41600","4.36816","0.00872"
"8794","52.72800","4.39411","0.00904"
"8846","53.04000","4.42012","0.00899"
"8898","53.35200","4.44607","0.00873"
"8950","53.66400","4.47214","0.00938"
"9002","53.97600","4.49815","0.00922"
"9054","54.28800","4.52409","0.00923"
"9106","54.60000","4.55016","0.00960"
"9158","54.91200","4.57611","0.00935"
"9210","55.22400","4.60218","0.00952"
"9262","55.53600","4.62813","0.00958"
"9314","55.84800","4.65414","0.00941"
"9366","56.16000","4.68015","0.01011"
"9418","56.47200","4.70609","0.01026"
"9470","56.78400","4.73216","0.01002"
"9522","57.09600","4.75805","0.01037"
"9574","57.40800","4.78418","0.01029"
"9626","57.72000","4.81013","0.01044"
"9678","58.03200","4.83614","0.01028"
"9730","58.34400","4.86214","0.01011"
"9782","58.65600","4.88809","0.01076"
"9834","58.96800","4.91422","0.01049"
"9886","59.28000","4.94011","0.01094"
"9938","59.59200","4.96618","0.01038"
"9990","59.90400","4.99207","0.01067"
"10042","60.21600","5.01808","0.01174"
"10094","60.52800","5.04414","0.01145"
"10146","60.84000","5.07009","0.01106"
"10198","61.15200","5.09616","0.01049"
"10250","61.46400","5.12211","0.01055"
"10302","61.77600","5.14812","0.01091"
"10354","62.08800","5.17413","0.01077"
"10406","62.40000","5.20014","0.01076"
"10458","62.71200","5.22620","0.01150"
"10510","63.02400","5.25215","0.01118"
"10562","63.33600","5.27816","0.01114"
"10614","63.64800","5.30411","0.01183"
"10666","63.96000","5.33012","0.01144"
"10718","64.27200","5.35619","0.01173"
"10770","64.58400","5.38207","0.01148"
"10822","64.89600","5.40814","0.01166"
"10874","65.20800","5.43415","0.01227"
"10926","65.52000","5.46016","0.01236"
"10978","65.83200","5.48617","0.01189"
"11030","66.14400","5.51212","0.01229"
"11082","66.45600","5.53818","0.01234"
"11134","66.76800","5.56407","0.01220"
"11186","67.08000","5.59014","0.01313"
"11238","67.39200","5.61609","0.01295"
"11290","67.70400","5.64216","0.01280"
"11342","68.01600","5.66817","0.01257"
"11394","68.32800","5.69412","0.01287"
"11446","68.64000","5.72018","0.01309"
"11498","68.95200","5.74613","0.01317"
"11550","69.26400","5.77214","0.01236"
"11602","69.57600","5.79815","0.01163"
"11654","69.88800","5.82416","0.00039"
"11706","70.20000","5.85017","0.00104"
"11758","70.51200","5.87606","0.00073"
"11810","70.82400","5.90212","0.00142"
"11862","71.13600","5.92813","0.00112"
"11914","71.44800","5.95414","0.00101"
"11966","71.76000","5.98015","0.00118"
"12018","72.07200","6.00610","0.00138"
"12070","72.38400","6.03217","0.00141"
"12122","72.69600","6.05811","0.00131"
"12174","73.00800","6.08412","0.00126"
"12226","73.32000","6.11013","0.00157"
"12278","73.63200","6.13614","0.00128"
"12330","73.94400","6.16215","0.00135"
"12382","74.25600","6.18810","0.00130"
"12434","74.56800","6.21411","0.00129"
"12486","74.88000","6.24011","0.00127"
"12538","75.19200","6.26618","0.00112"
"12590","75.50400","6.29213","0.00115"
"12642","75.81600","6.31814","0.00111"
"12694","76.12800","6.34421","0.00124"
"12746","76.44000","6.37010","0.00101"
"12798","76.75200","6.39616","0.00124"
"12850","77.06400","6.42211","0.00145"
"12902","77.37600","6.44812","0.00153"
"12954","77.68800","6.47413","0.00140"
"13006","78.00000","6.50014","0.00140"
"13058","78.31200","6.52615","0.00128"
"13110","78.62400","6.55210","0.00142"
"13162","78.93600","6.57816","0.00168"
"13214","79.24800","6.60411","0.00131"
"13266","79.56000","6.63018","0.00163"
"13318","79.87200","6.65613","0.00145"
"13370","80.18400","6.68214","0.00166"
"13422","80.49600","6.70815","0.00164"
"13474","80.80800","6.73416","0.00100"
"13526","81.12000","6.76010","0.00108"
"13578","81.43200","6.78617","0.00125"
"13630","81.74400","6.81206","0.00111"
"13682","82.05600","6.83813","0.00129"
"13734","82.36800","6.86408","0.00125"
"13786","82.68000","6.89021","0.00144"
"13838","82.99200","6.91609","0.00151"
"13890","83.30400","6.94216","0.00112"
"13942","83.61600","6.96817","0.00167"
"13994","83.92800","6.99412","0.00128"
"14046","84.24000","7.02013","0.00120"
"14098","84.55200","7.04608","0.00101"
"14150","84.86400","7.07214","0.00140"
"14202","85.17600","7.09809","0.00146"
"14254","85.48800","7.12410","0.00148"
"14306","85.80000","7.15017","0.00149"
"14358","86.11200","7.17612","0.00164"
"14410","86.42400","7.20219","0.00141"
"14462","86.73600","7.22808","0.00126"
"14514","87.04800","7.25415","0.00127"
"14566","87.36000","7.28015","0.00147"
"14618","87.67200","7.30616","0.00156"
"14670","87.98400","7.33217","0.00124"
"14722","88.29600","7.35812","0.00131"
"14774","88.60800","7.38413","0.00157"
"14826","88.92000","7.41008","0.00150"
"14878","89.23200","7.43614","0.00129"
"14930","89.54400","7.46215","0.00167"
"14982","89.85600","7.48816","0.00150"
"15034","90.16800","7.51411","0.00153"
"15086","90.48000","7.54006","0.00170"
"15138","90.79200","7.56613","0.00163"
"15190","91.10400","7.59213","0.00208"
"15242","91.41600","7.61814","0.00190"
"15294","91.72800","7.64421","0.00181"
"15346","92.04000","7.67004","0.00200"
"15398","92.35200","7.69617","0.00175"
"15450","92.66400","7.72212","0.00197"
"15502","92.97600","7.74819","0.00182"
"15554","93.28800","7.77413","0.00179"
"15606","93.60000","7.80014","0.00207"
"15658","93.91200","7.82615","0.00184"
"15710","94.22400","7.85204","0.00177"
"15762","94.53600","7.87817","0.00147"
"15814","94.84800","7.90418","0.00186"
"15866","95.16000","7.93018","0.00194"
"15918","95.47200","7.95613","0.00196"
"15970","95.78400","7.98214","0.00193"
"16022","96.09600","8.00815","0.00219"
"16074","96.40800","8.03404","0.00224"
"16126","96.72000","8.06017","0.00213"
"16178","97.03200","8.08612","0.00163"
"16230","97.34400","8.11212","0.00218"
"16282","97.65600","8.13813","0.00186"
"16334","97.96800","8.16408","0.00146"
"16386","98.28000","8.19015","0.00188"
"16438","98.59200","8.21616","0.00113"
"16490","98.90400","8.24211","0.00171"
"16542","99.21600","8.26812","0.00169"
"16594","99.52800","8.29406","0.00177"
"16646","99.84000","8.32013","0.00179"
"16698","100.15200","8.34608","0.00151"
"16750","100.46400","8.37215","0.00167"
"16802","100.77600","8.39810","0.00169"
"16854","101.08800","8.42417","0.00151"
"16906","101.40000","8.45017","0.00169"
"16958","101.71200","8.47612","0.00126"
"17010","102.02400","8.50219","0.00149"
"17062","102.33600","8.52814","0.00203"
"17114","102.64800","8.55415","0.00196"
"17166","102.96000","8.58010","0.00210"
"17218","103.27200","8.60610","0.00149"
"17270","103.58400","8.63217","0.00144"
"17322","103.89600","8.65812","0.00211"
"17374","104.20800","8.68419","0.00169"
"17426","104.52000","8.71014","0.00206"
"17478","104.83200","8.73621","0.00240"
"17530","105.14400","8.76210","0.00219"
"17582","105.45600","8.78811","0.00212"
"17634","105.76800","8.81417","0.00224"
"17686","106.08000","8.84006","0.00224"
"17738","106.39200","8.86619","0.00202"
"17790","106.70400","8.89214","0.00197"
"17842","107.01600","8.91809","0.00262"
"17894","107.32800","8.94416","0.00197"
"17946","107.64000","8.97016","0.00140"
"17998","107.95200","8.99617","0.00098"
"18050","108.26400","9.02212","0.00108"
"18102","108.57600","9.04819","0.00147"
"18154","108.88800","9.07414","0.00157"
"18206","109.20000","9.10015","0.00138"
"18258","109.51200","9.12615","0.00120"
"18310","109.82400","9.15210","0.00143"
"18362","110.13600","9.17817","0.00160"
"18414","110.44800","9.20406","0.00157"
"18466","110.76000","9.23013","0.00204"
"18518","111.07200","9.25614","0.00192"
"18570","111.38400","9.28209","0.00197"
"18622","111.69600","9.30815","0.00198"
"18674","112.00800","9.33410","0.00209"
"18726","112.32000","9.36017","0.00169"
"18778","112.63200","9.38612","0.00201"
"18830","112.94400","9.41213","0.00226"
"18882","113.25600","9.43814","0.00204"
"18934","113.56800","9.46408","0.00188"
"18986","113.88000","9.49015","0.00184"
"19038","114.19200","9.51610","0.00219"
"19090","114.50400","9.54217","0.00225"
"19142","114.81600","9.56818","0.00188"
"19194","115.12800","9.59413","0.00199"
"19246","115.44000","9.62014","0.00209"
"19298","115.75200","9.64608","0.00179"
"19350","116.06400","9.67215","0.00231"
"19402","116.37600","9.69816","0.00236"
"19454","116.68800","9.72417","0.00195"
"19506","117.00000","9.75018","0.00241"
"19558","117.31200","9.77613","0.00242"
"19610","117.62400","9.80213","0.00237"
"19662","117.93600","9.82808","0.00226"
"19714","118.24800","9.85415","0.00245"
"19766","118.56000","9.88016","0.00244"
"19818","118.87200","9.90611","0.00239"
"19870","119.18400","9.93218","0.00227"
"19922","119.49600","9.95807","0.00254"
"19974","119.80800","9.98419","0.00230"
"20026","120.12000","10.01008","0.00247"
"20078","120.43200","10.03615","0.00249"
"20130","120.74400","10.06216","0.00247"
"20182","121.05600","10.08811","0.00279"
"20234","121.36800","10.11418","0.00270"
"20286","121.68000","10.14007","0.00255"
"20338","121.99200","10.16613","0.00264"
"20390","122.30400","10.19214","0.00255"
"20442","122.61600","10.21815","0.00321"
"20494","122.92800","10.24416","0.00257"
"20546","123.24000","10.27011","0.00247"
"20598","123.55200","10.29618","0.00305"
"20650","123.86400","10.32212","0.00285"
"20702","124.17600","10.34813","0.00254"
"20754","124.48800","10.37414","0.00283"
"20806","124.80000","10.40009","0.00258"
"20858","125.11200","10.42616","0.00336"
"20910","125.42400","10.45205","0.00309"
"20962","125.73600","10.47818","0.00321"
"21014","126.04800","10.50412","0.00302"
"21066","126.36000","10.53013","0.00287"
"21118","126.67200","10.55614","0.00288"
"21170","126.98400","10.58215","0.00327"
"21222","127.29600","10.60816","0.00324"
"21274","127.60800","10.63405","0.00335"
"21326","127.92000","10.66018","0.00348"
"21378","128.23200","10.68606","0.00385"
"21430","128.54400","10.71213","0.00366"
"21482","128.85600","10.73814","0.00359"
"21534","129.16800","10.76409","0.00365"
"21586","129.48000","10.79016","0.00344"
"21638","129.79200","10.81611","0.00367"
"21690","130.10400","10.84211","0.00326"
"21742","130.41600","10.86812","0.00338"
"21794","130.72800","10.89413","0.00337"
"21846","131.04000","10.92014","0.00298"
"21898","131.35200","10.94609","0.00336"
"21950","131.66400","10.97216","0.00356"
"22002","131.97600","10.99811","0.00334"
"22054","132.28800","11.02417","0.00370"
"22106","132.60000","11.05018","0.00331"
"22158","132.91200","11.07607","0.00333"
"22210","133.22400","11.10214","0.00355"
"22262","133.53600","11.12815","0.00374"
"22314","133.84800","11.15416","0.00338"
"22366","134.16000","11.18016","0.00379"
"22418","134.47200","11.20611","0.00429"
"22470","134.78400","11.23218","0.00380"
"22522","135.09600","11.25807","0.00387"
"22574","135.40800","11.28414","0.00401"
"22626","135.72000","11.31009","0.00405"
"22678","136.03200","11.33622","0.00421"
"22730","136.34400","11.36216","0.00470"
"22782","136.65600","11.38811","0.00422"
"22834","136.96800","11.41418","0.00444"
"22886","137.28000","11.44007","0.00464"
"22938","137.59200","11.46614","0.00478"
"22990","137.90400","11.49215","0.00509"
"23042","138.21600","11.51816","0.00495"
"23094","138.52800","11.54416","0.00491"
"23146","138.84000","11.57011","0.00493"
"23198","139.15200","11.59612","0.00538"
"23250","139.46400","11.62207","0.00537"
"23302","139.77600","11.64820","0.00545"
"23354","140.08800","11.67415","0.00471"
"23406","140.40000","11.70015","0.00482"
"23458","140.71200","11.72622","0.00521"
"23510","141.02400","11.75211","0.00518"
"23562","141.33600","11.77818","0.00502"
"23614","141.64800","11.80413","0.00555"
"23666","141.96000","11.83014","0.00553"
"23718","142.27200","11.85614","0.00565"
"23770","142.58400","11.88209","0.00566"
"23822","142.89600","11.90816","0.00552"
"23874","143.20800","11.93411","0.00562"
"23926","143.52000","11.96018","0.00544"
"23978","143.83200","11.98613","0.00605"
"24030","144.14400","12.01214","0.00615"
"24082","144.45600","12.03821","0.00649"
"24134","144.76800","12.06415","0.00644"
"24186","145.08000","12.09022","0.00662"
"24238","145.39200","12.11611","0.00635"
"24290","145.70400","12.14212","0.00636"
"24342","146.01600","12.16813","0.00637"
"24394","146.32800","12.19408","0.00637"
"24446","146.64000","12.22014","0.00598"
"24498","146.95200","12.24615","0.00618"
"24550","147.26400","12.27216","0.00638"
"24602","147.57600","12.29811","0.00600"
"24654","147.88800","12.32412","0.00603"
"24706","148.20000","12.35013","0.00601"
"24758","148.51200","12.37607","0.00694"
"24810","148.82400","12.40214","0.00675"
"24862","149.13600","12.42809","0.00633"
"24914","149.44800","12.45416","0.00664"
"24966","149.76000","12.48017","0.00646"
"25018","150.07200","12.50612","0.00731"
"25070","150.38400","12.53218","0.00756"
"25122","150.69600","12.55813","0.00763"
"25174","151.00800","12.58414","0.00749"
"25226","151.32000","12.61015","0.00647"
"25278","151.63200","12.63610","0.00705"
"25330","151.94400","12.66217","0.00616"
"25382","152.25600","12.68812","0.00479"
"25434","152.56800","12.71413","0.00482"
"25486","152.88000","12.74007","0.00395"
"25538","153.19200","12.76614","0.00433"
"25590","153.50400","12.79209","0.00463"
"25642","153.81600","12.81816","0.00498"
"25694","154.12800","12.84417","0.00518"
"25746","154.44000","12.87012","0.00521"
"25798","154.75200","12.89612","0.00517"
"25850","155.06400","12.92207","0.00549"
"25902","155.37600","12.94814","0.00541"
"25954","155.68800","12.97415","0.00532"
"26006","156.00000","13.00016","0.00552"
"26058","156.31200","13.02611","0.00560"
"26110","156.62400","13.05200","0.00520"
"26162","156.93600","13.07812","0.00521"
"26214","157.24800","13.10407","0.00546"
"26266","157.56000","13.13014","0.00560"
"26318","157.87200","13.15615","0.00569"
"26370","158.18400","13.18216","0.00579"
"26422","158.49600","13.20811","0.00556"
"26474","158.80800","13.23405","0.00559"
"26526","159.12000","13.26012","0.00569"
"26578","159.43200","13.28619","0.00580"
"26630","159.74400","13.31220","0.00620"
"26682","160.05600","13.33815","0.00622"
"26734","160.36800","13.36410","0.00674"
"26786","160.68000","13.39016","0.00638"
"26838","160.99200","13.41611","0.00601"
"26890","161.30400","13.44212","0.00630"
"26942","161.61600","13.46813","0.00544"
"26994","161.92800","13.49414","0.00534"
"27046","162.24000","13.52015","0.00582"
"27098","162.55200","13.54610","0.00526"
"27150","162.86400","13.57216","0.00565"
"27202","163.17600","13.59811","0.00543"
"27254","163.48800","13.62412","0.00572"
"27306","163.80000","13.65013","0.00479"
"27358","164.11200","13.67608","0.00511"
"27410","164.42400","13.70221","0.00493"
"27462","164.73600","13.72816","0.00433"
"27514","165.04800","13.75416","0.00473"
"27566","165.36000","13.78011","0.00521"
"27618","165.67200","13.80618","0.00525"
"27670","165.98400","13.83213","0.00524"
"27722","166.29600","13.85814","0.00528"
"27774","166.60800","13.88421","0.00536"
"27826","166.92000","13.91015","0.00576"
"27878","167.23200","13.93616","0.00533"
"27930","167.54400","13.96211","0.00576"
"27982","167.85600","13.98812","0.00582"
"28034","168.16800","14.01419","0.00523"
"28086","168.48000","14.04008","0.00570"
"28138","168.79200","14.06621","0.00587"
"28190","169.10400","14.09215","0.00599"
"28242","169.41600","14.11816","0.00615"
"28294","169.72800","14.14417","0.00552"
"28346","170.04000","14.17012","0.00550"
"28398","170.35200","14.19613","0.00556"
"28450","170.66400","14.22208","0.00554"
"28502","170.97600","14.24815","0.00560"
"28554","171.28800","14.27409","0.00522"
"28606","171.60000","14.30010","0.00591"
"28658","171.91200","14.32617","0.00593"
"28710","172.22400","14.35212","0.00633"
"28762","172.53600","14.37819","0.00611"
"28814","172.84800","14.40414","0.00566"
"28866","173.16000","14.43015","0.00593"
"28918","173.47200","14.45615","0.00645"
"28970","173.78400","14.48216","0.00629"
"29022","174.09600","14.50811","0.00583"
"29074","174.40800","14.53412","0.00550"
"29126","174.72000","14.56013","0.00558"
"29178","175.03200","14.58614","0.00648"
"29230","175.34400","14.61214","0.00612"
"29282","175.65600","14.63815","0.00634"
"29334","175.96800","14.66410","0.00667"
"29386","176.28000","14.69011","0.00664"
"29438","176.59200","14.71612","0.00634"
"29490","176.90400","14.74213","0.00711"
"29542","177.21600","14.76814","0.00702"
"29594","177.52800","14.79414","0.00730"
"29646","177.84000","14.82015","0.00663"
"29698","178.15200","14.84610","0.00699"
"29750","178.46400","14.87217","0.00710"
"29802","178.77600","14.89812","0.00724"
"29854","179.08800","14.92424","0.00706"
"29906","179.40000","14.95019","0.00720"
"29958","179.71200","14.97614","0.00758"
"30010","180.02400","15.00215","0.00671"
"30062","180.33600","15.02804","0.00708"
"30114","180.64800","15.05417","0.00729"
"30166","180.96000","15.08012","0.00713"
"30218","181.27200","15.10613","0.00729"
"30270","181.58400","15.13213","0.00765"
"30322","181.89600","15.15814","0.00725"
"30374","182.20800","15.18409","0.00807"
"30426","182.52000","15.21010","0.00825"
"30478","182.83200","15.23617","0.00773"
"30530","183.14400","15.26218","0.00872"
"30582","183.45600","15.28813","0.00802"
"30634","183.76800","15.31413","0.00864"
"30686","184.08000","15.34014","0.00901"
"30738","184.39200","15.36615","0.00866"
"30790","184.70400","15.39210","0.00873"
"30842","185.01600","15.41805","0.00885"
"30894","185.32800","15.44411","0.00892"
"30946","185.64000","15.47006","0.00856"
"30998","185.95200","15.49613","0.00918"
"31050","186.26400","15.52208","0.00904"
"31102","186.57600","15.54815","0.00990"
"31154","186.88800","15.57410","0.00962"
"31206","187.20000","15.60011","0.00954"
"31258","187.51200","15.62617","0.01021"
"31310","187.82400","15.65212","0.00971"
"31362","188.13600","15.67819","0.00990"
"31414","188.44800","15.70408","0.00982"
"31466","188.76000","15.73015","0.01022"
"31518","189.07200","15.75610","0.00993"
"31570","189.38400","15.78210","0.01038"
"31622","189.69600","15.80817","0.01047"
"31674","190.00800","15.83406","0.00230"
"31726","190.32000","15.86019","0.00073"
"31778","190.63200","15.88614","0.00130"
"31830","190.94400","15.91209","0.00084"
"31882","191.25600","15.93816","0.00152"
"31934","191.56800","15.96416","0.00172"
"31986","191.88000","15.99017","0.00145"
"32038","192.19200","16.01612","0.00126"
"32090","192.50400","16.04213","0.00186"
"32142","192.81600","16.06814","0.00192"
"32194","193.12800","16.09415","0.00223"
"32246","193.44000","16.12016","0.00262"
"32298","193.75200","16.14610","0.00244"
"32350","194.06400","16.17217","0.00263"
"32402","194.37600","16.19812","0.00228"
"32454","194.68800","16.22413","0.00329"
"32506","195.00000","16.25020","0.00277"
"32558","195.31200","16.27608","0.00316"
"32610","195.62400","16.30215","0.00306"
"32662","195.93600","16.32804","0.00346"
"32714","196.24800","16.35417","0.00357"
"32766","196.56000","16.38012","0.00358"
"32818","196.87200","16.40613","0.00348"
"32870","197.18400","16.43214","0.00342"
"32922","197.49600","16.45808","0.00382"
"32974","197.80800","16.48421","0.00416"
"33026","198.12000","16.51016","0.00438"
"33078","198.43200","16.53617","0.00439"
"33130","198.74400","16.56218","0.00489"
"33182","199.05600","16.58813","0.00464"
"33234","199.36800","16.61414","0.00470"
"33286","199.68000","16.64002","0.00461"
"33338","199.99200","16.66609","0.00490"
"33390","200.30400","16.69210","0.00514"
"33442","200.61600","16.71817","0.00547"
"33494","200.92800","16.74418","0.00549"
"33546","201.24000","16.77013","0.00530"
"33598","201.55200","16.79620","0.00551"
"33650","201.86400","16.82202","0.00601"
"33702","202.17600","16.84815","0.00604"
"33754","202.48800","16.87416","0.00667"
"33806","202.80000","16.90017","0.00700"
"33858","203.11200","16.92618","0.00660"
"33910","203.42400","16.95213","0.00691"
"33962","203.73600","16.97814","0.00695"
"34014","204.04800","17.00414","0.00726"
"34066","204.36000","17.03015","0.00747"
"34118","204.67200","17.05616","0.00768"
"34170","204.98400","17.08211","0.00708"
"34222","205.29600","17.10818","0.00750"
"34274","205.60800","17.13413","0.00787"
"34326","205.92000","17.16019","0.00788"
"34378","206.23200","17.18608","0.00831"
"34430","206.54400","17.21215","0.00828"
"34482","206.85600","17.23816","0.00815"
"34534","207.16800","17.26411","0.00891"
"34586","207.48000","17.29018","0.00947"
"34638","207.79200","17.31613","0.00931"
"34690","208.10400","17.34213","0.00938"
"34742","208.41600","17.36814","0.00975"
"34794","208.72800","17.39415","0.00956"
"34846","209.04000","17.42016","0.00976"
"34898","209.35200","17.44611","0.01072"
"34950","209.66400","17.47218","0.00991"
"35002","209.97600","17.49813","0.01052"
"35054","210.28800","17.52407","0.01087"
"35106","210.60000","17.55020","0.01085"
"35158","210.91200","17.57615","0.01068"
"35210","211.22400","17.60216","0.01109"
"35262","211.53600","17.62811","0.01120"
"35314","211.84800","17.65412","0.01113"
"35366","212.16000","17.68012","0.01144"
"35418","212.47200","17.70607","0.01135"
"35470","212.78400","17.73220","0.01184"
"35522","213.09600","17.75815","0.01240"
"35574","213.40800","17.78416","0.01289"
"35626","213.72000","17.81005","0.01280"
"35678","214.03200","17.83617","0.01369"
"35730","214.34400","17.86212","0.01455"
"35782","214.65600","17.88807","0.01408"
"35834","214.96800","17.91414","0.01514"
"35886","215.28000","17.94015","0.01521"
"35938","215.59200","17.96616","0.01487"
"35990","215.90400","17.99211","0.01539"
"36042","216.21600","18.01811","0.01612"
"36094","216.52800","18.04418","0.01625"
"36146","216.84000","18.07013","0.01696"
"36198","217.15200","18.09614","0.01672"
"36250","217.46400","18.12209","0.01674"
"36302","217.77600","18.14810","0.01604"
"36354","218.08800","18.17410","0.01721"
"36406","218.40000","18.20011","0.01742"
"36458","218.71200","18.22618","0.01667"
"36510","219.02400","18.25207","0.01546"
"36562","219.33600","18.27808","0.01706"
"36614","219.64800","18.30409","0.01793"
"36666","219.96000","18.33015","0.01808"
"36718","220.27200","18.35616","0.01153"
"36770","220.58400","18.38211","0.01152"
"36822","220.89600","18.40818","0.01226"
"36874","221.20800","18.43407","0.01298"
"36926","221.52000","18.46014","0.01355"
"36978","221.83200","18.48615","0.01471"
"37030","222.14400","18.51215","0.01477"
"37082","222.45600","18.53816","0.01494"
"37134","222.76800","18.56417","0.01605"
"37186","223.08000","18.59018","0.01609"
"37238","223.39200","18.61607","0.01748"
"37290","223.70400","18.64220","0.01775"
"37342","224.01600","18.66814","0.01885"
"37394","224.32800","18.69415","0.01945"
"37446","224.64000","18.72016","0.02014"
"37498","224.95200","18.74611","0.02142"
"37550","225.26400","18.77212","0.02210"
"37602","225.57600","18.79813","0.02285"
"37654","225.88800","18.82414","0.02388"
"37706","226.20000","18.85021","0.02437"
"37758","226.51200","18.87615","0.02530"
"37810","226.82400","18.90216","0.02612"
"37862","227.13600","18.92811","0.02721"
"37914","227.44800","18.95418","0.02763"
"37966","227.76000","18.98013","0.02857"
"38018","228.07200","19.00607","0.02913"
"38070","228.38400","19.03214","0.03009"
"38122","228.69600","19.05809","0.03099"
"38174","229.00800","19.08416","0.03162"
"38226","229.32000","19.11011","0.03228"
"38278","229.63200","19.13612","0.03332"
"38330","229.94400","19.16213","0.03420"
"38382","230.25600","19.18814","0.03482"
"38434","230.56800","19.21414","0.03620"
"38486","230.88000","19.24009","0.03758"
"38538","231.19200","19.26616","0.03806"
"38590","231.50400","19.29211","0.03958"
"38642","231.81600","19.31812","0.04017"
"38694","232.12800","19.34413","0.04101"
"38746","232.44000","19.37013","0.04235"
"38798","232.75200","19.39620","0.04260"
"38850","233.06400","19.42209","0.04335"
"38902","233.37600","19.44822","0.04426"
"38954","233.68800","19.47417","0.04505"
"39006","234.00000","19.50018","0.04645"
"39058","234.31200","19.52619","0.04753"
"39110","234.62400","19.55213","0.04809"
"39162","234.93600","19.57814","0.04887"
"39214","235.24800","19.60409","0.05009"
"39266","235.56000","19.63016","0.05209"
"39318","235.87200","19.65611","0.05273"
"39370","236.18400","19.68212","0.05469"
"39422","236.49600","19.70819","0.05585"
"39474","236.80800","19.73413","0.05698"
"39526","237.12000","19.76014","0.05838"
"39578","237.43200","19.78615","0.05901"
"39630","237.74400","19.81216","0.06081"
"39682","238.05600","19.83817","0.06355"
"39734","238.36800","19.86412","0.06457"
"39786","238.68000","19.89012","0.06625"
"39838","238.99200","19.91607","0.06796"
"39890","239.30400","19.94220","0.07005"
"39942","239.61600","19.96815","0.07170"
"39994","239.92800","19.99416","0.07242"
"40046","240.24000","20.02017","0.07419"
"40098","240.55200","20.04605","0.07480"
"40150","240.86400","20.07212","0.07675"
"40202","241.17600","20.09813","0.07760"
"40254","241.48800","20.12420","0.07850"
"40306","241.80000","20.15015","0.07945"
"40358","242.11200","20.17610","0.08046"
"40410","242.42400","20.20210","0.08091"
"40462","242.73600","20.22805","0.08227"
"40514","243.04800","20.25418","0.08321"
"40566","243.36000","20.28013","0.08361"
"40618","243.67200","20.30614","0.08483"
"40670","243.98400","20.33215","0.08544"
"40722","244.29600","20.35810","0.08602"
"40774","244.60800","20.38410","0.08610"
"40826","244.92000","20.41005","0.08727"
"40878","245.23200","20.43618","0.08823"
"40930","245.54400","20.46213","0.08856"
"40982","245.85600","20.48808","0.08925"
"41034","246.16800","20.51415","0.09026"
"41086","246.48000","20.54010","0.09133"
"41138","246.79200","20.56617","0.09187"
"41190","247.10400","20.59211","0.09260"
"41242","247.41600","20.61818","0.09347"
"41294","247.72800","20.64413","0.09395"
"41346","248.04000","20.67008","0.09512"
"41398","248.35200","20.69615","0.09605"
"41450","248.66400","20.72210","0.09746"
"41502","248.97600","20.74817","0.09822"
"41554","249.28800","20.77411","0.10015"
"41606","249.60000","20.80012","0.10114"
"41658","249.91200","20.82613","0.10155"
"41710","250.22400","20.85214","0.10281"
"41762","250.53600","20.87815","0.10425"
"41814","250.84800","20.90410","0.10599"
"41866","251.16000","20.93016","0.10684"
"41918","251.47200","20.95617","0.10819"
"41970","251.78400","20.98212","0.11047"
"42022","252.09600","21.00813","0.11168"
"42074","252.40800","21.03414","0.11149"
"42126","252.72000","21.06015","0.11341"
"42178","253.03200","21.08610","0.11602"
"42230","253.34400","21.11210","0.11848"
"42282","253.65600","21.13811","0.11449"
"42334","253.96800","21.16412","0.11684"
"42386","254.28000","21.19013","0.11917"
"42438","254.59200","21.21608","0.12188"
"42490","254.90400","21.24215","0.12387"
"42542","255.21600","21.26809","0.12641"
"42594","255.52800","21.29410","0.12807"
"42646","255.84000","21.32017","0.13015"
"42698","256.15200","21.34612","0.13127"
"42750","256.46400","21.37219","0.13324"
"42802","256.77600","21.39808","0.13418"
"42854","257.08800","21.42414","0.13684"
"42906","257.40000","21.45009","0.13792"
"42958","257.71200","21.47610","0.13881"
"43010","258.02400","21.50211","0.14057"
"43062","258.33600","21.52812","0.14201"
"43114","258.64800","21.55419","0.14338"
"43166","258.96000","21.58008","0.14466"
"43218","259.27200","21.60614","0.14590"
"43270","259.58400","21.63221","0.14680"
"43322","259.89600","21.65816","0.14788"
"43374","260.20800","21.68417","0.14888"
"43426","260.52000","21.71006","0.14953"
"43478","260.83200","21.73613","0.15037"
"43530","261.14400","21.76213","0.15164"
"43582","261.45600","21.78814","0.15220"
"43634","261.76800","21.81415","0.15316"
"43686","262.08000","21.84010","0.15448"
"43738","262.39200","21.86617","0.15610"
"43790","262.70400","21.89212","0.15653"
"43842","263.01600","21.91818","0.15747"
"43894","263.32800","21.94413","0.15894"
"43946","263.64000","21.97008","0.15946"
"43998","263.95200","21.99615","0.16086"
"44050","264.26400","22.02204","0.16131"
"44102","264.57600","22.04817","0.16293"
"44154","264.88800","22.07417","0.16424"
"44206","265.20000","22.10018","0.16506"
"44258","265.51200","22.12613","0.16615"
"44310","265.82400","22.15214","0.16695"
"44362","266.13600","22.17815","0.16812"
"44414","266.44800","22.20410","0.16952"
"44466","266.76000","22.23017","0.17097"
"44518","267.07200","22.25611","0.17196"
"44570","267.38400","22.28213","0.17247"
"44622","267.69600","22.30807","0.17333"
"44674","268.00800","22.33408","0.17491"
"44726","268.32000","22.36015","0.17679"
"44778","268.63200","22.38616","0.17802"
"44830","268.94400","22.41217","0.17948"
"44882","269.25600","22.43818","0.18105"
"44934","269.56800","22.46412","0.18260"
"44986","269.88000","22.49019","0.18456"
"45038","270.19200","22.51608","0.18594"
"45090","270.50400","22.54215","0.18749"
"45142","270.81600","22.56810","0.18876"
"45194","271.12800","22.59411","0.18991"
"45246","271.44000","22.62011","0.18980"
"45298","271.75200","22.64606","0.19092"
"45350","272.06400","22.67219","0.19097"
"45402","272.37600","22.69814","0.00779"
"45454","272.68800","22.72415","0.00407"
"45506","273.00000","22.75016","0.00288"
"45558","273.31200","22.77611","0.00624"
"45610","273.62400","22.80217","0.00226"
"45662","273.93600","22.82806","0.00392"
"45714","274.24800","22.85419","0.00456"
"45766","274.56000","22.88008","0.00362"
"45818","274.87200","22.90615","0.00541"
"45870","275.18400","22.93210","0.00430"
"45922","275.49600","22.95816","0.00472"
"45974","275.80800","22.98417","0.00512"
"46026","276.12000","23.01012","0.00483"
"46078","276.43200","23.03613","0.00650"
"46130","276.74400","23.06208","0.00497"
"46182","277.05600","23.08815","0.00581"
"46234","277.36800","23.11416","0.00588"
"46286","277.68000","23.14016","0.00545"
"46338","277.99200","23.16611","0.00597"
"46390","278.30400","23.19206","0.00564"
"46442","278.61600","23.21813","0.00705"
"46494","278.92800","23.24414","0.00578"
"46546","279.24000","23.27009","0.00701"
"46598","279.55200","23.29616","0.00650"
"46650","279.86400","23.32216","0.00716"
"46702","280.17600","23.34817","0.00678"
"46754","280.48800","23.37412","0.00685"
"46806","280.80000","23.40013","0.00732"
"46858","281.11200","23.42620","0.00688"
"46910","281.42400","23.45208","0.00794"
"46962","281.73600","23.47815","0.00752"
"47014","282.04800","23.50410","0.00764"
"47066","282.36000","23.53011","0.00780"
"47118","282.67200","23.55612","0.00789"
"47170","282.98400","23.58213","0.00763"
"47222","283.29600","23.60814","0.00736"
"47274","283.60800","23.63408","0.00778"
"47326","283.92000","23.66009","0.00816"
"47378","284.23200","23.68604","0.00792"
"47430","284.54400","23.71217","0.00381"
"47482","284.85600","23.73812","0.00366"
"47534","285.16800","23.76413","0.00295"
"47586","285.48000","23.79008","0.00354"
"47638","285.79200","23.81602","0.00396"
"47690","286.10400","23.84209","0.00345"
"47742","286.41600","23.86810","0.00398"
"47794","286.72800","23.89411","0.00397"
"47846","287.04000","23.92018","0.00406"
"47898","287.35200","23.94618","0.00410"
"47950","287.66400","23.97213","0.00344"
"48002","287.97600","23.99809","0.00362"
"48054","288.28800","24.02415","0.00416"
"48106","288.60000","24.05016","0.00420"
"48158","288.91200","24.07611","0.00435"
"48210","289.22400","24.10212","0.00435"
"48262","289.53600","24.12807","0.00451"
"48314","289.84800","24.15420","0.00445"
"48366","290.16000","24.18014","0.00469"
"48418","290.47200","24.20615","0.00456"
"48470","290.78400","24.23216","0.00478"
"48522","291.09600","24.25811","0.00442"
"48574","291.40800","24.28418","0.00467"
"48626","291.72000","24.31013","0.00497"
"48678","292.03200","24.33619","0.00490"
"48730","292.34400","24.36208","0.00482"
"48782","292.65600","24.38815","0.00488"
"48834","292.96800","24.41416","0.00519"
"48886","293.28000","24.44011","0.00500"
"48938","293.59200","24.46618","0.00529"
"48990","293.90400","24.49213","0.00479"
"49042","294.21600","24.51813","0.00518"
"49094","294.52800","24.54414","0.00539"
"49146","294.84000","24.57015","0.00523"
"49198","295.15200","24.59616","0.00476"
"49250","295.46400","24.62211","0.00486"
"49302","295.77600","24.64818","0.00461"
"49354","296.08800","24.67413","0.00535"
"49406","296.40000","24.70007","0.00493"
"49458","296.71200","24.72614","0.00534"
"49510","297.02400","24.75215","0.00544"
"49562","297.33600","24.77816","0.00487"
"49614","297.64800","24.80411","0.00511"
"49666","297.96000","24.83018","0.00552"
"49718","298.27200","24.85612","0.00519"
"49770","298.58400","24.88213","0.00552"
"49822","298.89600","24.90820","0.00571"
"49874","299.20800","24.93409","0.00251"
"49926","299.52000","24.96016","0.00369"
"49978","299.83200","24.98611","0.00312"
"50030","300.14400","25.01211","0.00316"
"50082","300.45600","25.03812","0.00364"
"50134","300.76800","25.06413","0.00305"
"50186","301.08000","25.09020","0.00346"
"50238","301.39200","25.11609","0.00316"
"50290","301.70400","25.14215","0.00377"
"50342","302.01600","25.16811","0.00360"
"50394","302.32800","25.19411","0.00329"
"50446","302.64000","25.22018","0.00346"
"50498","302.95200","25.24613","0.00375"
"50550","303.26400","25.27214","0.00358"
"50602","303.57600","25.29809","0.00405"
"50654","303.88800","25.32409","0.00372"
"50706","304.20000","25.35011","0.00403"
"50758","304.51200","25.37617","0.00429"
"50810","304.82400","25.40212","0.00375"
"50862","305.13600","25.42807","0.00396"
"50914","305.44800","25.45414","0.00365"
"50966","305.76000","25.48015","0.00435"
"51018","306.07200","25.50615","0.00424"
"51070","306.38400","25.53216","0.00387"
"51122","306.69600","25.55811","0.00354"
"51174","307.00800","25.58412","0.00419"
"51226","307.32000","25.61007","0.00409"
"51278","307.63200","25.63614","0.00477"
"51330","307.94400","25.66215","0.00456"
"51382","308.25600","25.68815","0.00406"
"51434","308.56800","25.71422","0.00337"
"51486","308.88000","25.74011","0.00370"
"51538","309.19200","25.76618","0.00389"
"51590","309.50400","25.79213","0.00445"
"51642","309.81600","25.81814","0.00363"
"51694","310.12800","25.84414","0.00413"
"51746","310.44000","25.87009","0.00445"
"51798","310.75200","25.89610","0.00421"
"51850","311.06400","25.92211","0.00415"
"51902","311.37600","25.94818","0.00434"
"51954","311.68800","25.97407","0.00398"
"52006","312.00000","26.00014","0.00420"
"52058","312.31200","26.02614","0.00408"
"52110","312.62400","26.05209","0.00427"
"52162","312.93600","26.07816","0.00425"
"52214","313.24800","26.10411","0.00446"
"52266","313.56000","26.13012","0.00421"
"52318","313.87200","26.15607","0.00459"
"52370","314.18400","26.18208","0.00439"
"52422","314.49600","26.20814","0.00491"
"52474","314.80800","26.23409","0.00510"
"52526","315.12000","26.26016","0.00498"
"52578","315.43200","26.28611","0.00458"
"52630","315.74400","26.31218","0.00473"
"52682","316.05600","26.33813","0.00481"
"52734","316.36800","26.36407","0.00426"
"52786","316.68000","26.39020","0.00463"
"52838","316.99200","26.41609","0.00455"
"52890","317.30400","26.44216","0.00463"
"52942","317.61600","26.46811","0.00489"
"52994","317.92800","26.49412","0.00531"
"53046","318.24000","26.52013","0.00469"
"53098","318.55200","26.54613","0.00518"
"53150","318.86400","26.57214","0.00453"
"53202","319.17600","26.59809","0.00493"
"53254","319.48800","26.62416","0.00476"
"53306","319.80000","26.65011","0.00481"
"53358","320.11200","26.67612","0.00497"
"53410","320.42400","26.70218","0.00519"
"53462","320.73600","26.72813","0.00507"
"53514","321.04800","26.75414","0.00493"
"53566","321.36000","26.78009","0.00563"
"53618","321.67200","26.80616","0.00485"
"53670","321.98400","26.83217","0.00491"
"53722","322.29600","26.85812","0.00522"
"53774","322.60800","26.88412","0.00519"
"53826","322.92000","26.91007","0.00494"
"53878","323.23200","26.93620","0.00487"
"53930","323.54400","26.96215","0.00466"
"53982","323.85600","26.98816","0.00526"
"54034","324.16800","27.01423","0.00504"
"54086","324.48000","27.04012","0.00510"
"54138","324.79200","27.06612","0.00519"
"54190","325.10400","27.09207","0.00508"
"54242","325.41600","27.11814","0.00489"
"54294","325.72800","27.14415","0.00502"
"54346","326.04000","27.17016","0.00529"
"54398","326.35200","27.19617","0.00522"
"54450","326.66400","27.22211","0.00538"
"54502","326.97600","27.24818","0.00502"
"54554","327.28800","27.27413","0.00538"
"54606","327.60000","27.30014","0.00558"
"54658","327.91200","27.32615","0.00560"
"54710","328.22400","27.35210","0.00535"
"54762","328.53600","27.37811","0.00586"
"54814","328.84800","27.40405","0.00561"
"54866","329.16000","27.43018","0.00622"
"54918","329.47200","27.45607","0.00559"
"54970","329.78400","27.48214","0.00594"
"55022","330.09600","27.50815","0.00607"
"55074","330.40800","27.53410","0.00626"
"55126","330.72000","27.56016","0.00515"
"55178","331.03200","27.58611","0.00640"
"55230","331.34400","27.61218","0.00547"
"55282","331.65600","27.63813","0.00567"
"55334","331.96800","27.66414","0.00577"
"55386","332.28000","27.69015","0.00567"
"55438","332.59200","27.71609","0.00557"
"55490","332.90400","27.74216","0.00535"
"55542","333.21600","27.76811","0.00563"
"55594","333.52800","27.79418","0.00514"
"55646","333.84000","27.82013","0.00580"
"55698","334.15200","27.84608","0.00591"
"55750","334.46400","27.87215","0.00560"
"55802","334.77600","27.89810","0.00609"
"55854","335.08800","27.92416","0.00510"
"55906","335.40000","27.95005","0.00532"
"55958","335.71200","27.97612","0.00521"
"56010","336.02400","28.00213","0.00578"
"56062","336.33600","28.02814","0.00532"
"56114","336.64800","28.05421","0.00528"
"56166","336.96000","28.08016","0.00529"
"56218","337.27200","28.10616","0.00566"
"56270","337.58400","28.13211","0.00575"
"56322","337.89600","28.15812","0.00606"
"56374","338.20800","28.18413","0.00503"
"56426","338.52000","28.21008","0.00522"
"56478","338.83200","28.23615","0.00491"
"56530","339.14400","28.26209","0.00467"
"56582","339.45600","28.28810","0.00475"
"56634","339.76800","28.31417","0.00489"
"56686","340.08000","28.34012","0.00513"
"56738","340.39200","28.36613","0.00454"
"56790","340.70400","28.39208","0.00474"
"56842","341.01600","28.41814","0.00554"
"56894","341.32800","28.44415","0.00499"
"56946","341.64000","28.47010","0.00497"
"56998","341.95200","28.49617","0.00538"
"57050","342.26400","28.52206","0.00431"
"57102","342.57600","28.54813","0.00441"
"57154","342.88800","28.57408","0.00501"
"57206","343.20000","28.60014","0.00458"
"57258","343.51200","28.62615","0.00446"
"57310","343.82400","28.65210","0.00439"
"57362","344.13600","28.67817","0.00442"
"57414","344.44800","28.70412","0.00410"
"57466","344.76000","28.73019","0.00434"
"57518","345.07200","28.75613","0.00456"
"57570","345.38400","28.78214","0.00433"
"57622","345.69600","28.80821","0.00469"
"57674","346.00800","28.83410","0.00423"
"57726","346.32000","28.86011","0.00460"
"57778","346.63200","28.88606","0.00460"
"57830","346.94400","28.91213","0.00499"
"57882","347.25600","28.93813","0.00503"
"57934","347.56800","28.96408","0.00415"
"57986","347.88000","28.99015","0.00480"
"58038","348.19200","29.01604","0.00466"
"58090","348.50400","29.04211","0.00410"
"58142","348.81600","29.06812","0.00502"
"58194","349.12800","29.09418","0.00407"
"58246","349.44000","29.12019","0.00441"
"58298","349.75200","29.14608","0.00447"
"58350","350.06400","29.17215","0.00438"
"58402","350.37600","29.19804","0.00501"
"58454","350.68800","29.22417","0.00476"
"58506","351.00000","29.25018","0.00403"
"58558","351.31200","29.27618","0.00436"
"58610","351.62400","29.30219","0.00484"
"58662","351.93600","29.32814","0.00473"
"58714","352.24800","29.35415","0.00480"
"58766","352.56000","29.38010","0.00502"
"58818","352.87200","29.40617","0.00482"
"58870","353.18400","29.43218","0.00446"
"58922","353.49600","29.45812","0.00491"
"58974","353.80800","29.48413","0.00506"
"59026","354.12000","29.51008","0.00500"
"59078","354.43200","29.53621","0.00489"
"59130","354.74400","29.56210","0.00434"
"59182","355.05600","29.58811","0.00441"
"59234","355.36800","29.61418","0.00500"
"59286","355.68000","29.64012","0.00497"
"59338","355.99200","29.66619","0.00487"
"59390","356.30400","29.69214","0.00500"
"59442","356.61600","29.71815","0.00516"
"59494","356.92800","29.74410","0.00483"
"59546","357.24000","29.77004","0.00528"
"59598","357.55200","29.79618","0.00529"
"59650","357.86400","29.82212","0.00534"
"59702","358.17600","29.84819","0.00543"
"59754","358.48800","29.87408","0.00567"
"59806","358.80000","29.90015","0.00504"
"59858","359.11200","29.92616","0.00536"
"59910","359.42400","29.95211","0.00544"
"59962","359.73600","29.97817","0.00564"
"60014","360.04800","30.00412","0.00532"
"60066","360.36000","30.03013","0.00601"
"60118","360.67200","30.05608","0.00562"
"60170","360.98400","30.08209","0.00614"
"60222","361.29600","30.10816","0.00540"
"60274","361.60800","30.13416","0.00593"
"60326","361.92000","30.16017","0.00603"
"60378","362.23200","30.18612","0.00604"
"60430","362.54400","30.21213","0.00632"
"60482","362.85600","30.23814","0.00638"
"60534","363.16800","30.26409","0.00660"
"60586","363.48000","30.29016","0.00647"
"60638","363.79200","30.31610","0.00657"
"60690","364.10400","30.34211","0.00639"
"60742","364.41600","30.36812","0.00673"
"60794","364.72800","30.39413","0.00649"
"60846","365.04000","30.42020","0.00636"
"60898","365.35200","30.44615","0.00664"
"60950","365.66400","30.47216","0.00571"
"61002","365.97600","30.49810","0.00635"
"61054","366.28800","30.52417","0.00631"
"61106","366.60000","30.55012","0.00620"
"61158","366.91200","30.57613","0.00674"
"61210","367.22400","30.60220","0.00678"
"61262","367.53600","30.62809","0.00711"
"61314","367.84800","30.65415","0.00728"
"61366","368.16000","30.68004","0.00701"
"61418","368.47200","30.70617","0.00710"
"61470","368.78400","30.73218","0.00653"
"61522","369.09600","30.75813","0.00728"
"61574","369.40800","30.78414","0.00713"
"61626","369.72000","30.81009","0.00674"
"61678","370.03200","30.83615","0.00665"
"61730","370.34400","30.86210","0.00651"
"61782","370.65600","30.88817","0.00691"
"61834","370.96800","30.91412","0.00671"
"61886","371.28000","30.94007","0.00686"
"61938","371.59200","30.96614","0.00601"
"61990","371.90400","30.99208","0.00643"
"62042","372.21600","31.01815","0.00693"
"62094","372.52800","31.04410","0.00683"
"62146","372.84000","31.07011","0.00703"
"62198","373.15200","31.09618","0.00702"
"62250","373.46400","31.12207","0.00681"
"62302","373.77600","31.14814","0.00724"
"62354","374.08800","31.17414","0.00696"
"62406","374.40000","31.20015","0.00694"
"62458","374.71200","31.22616","0.00710"
"62510","375.02400","31.25211","0.00682"
"62562","375.33600","31.27811","0.00675"
"62614","375.64800","31.30407","0.00680"
"62666","375.96000","31.33014","0.00723"
"62718","376.27200","31.35614","0.00759"
"62770","376.58400","31.38215","0.00715"
"62822","376.89600","31.40816","0.00764"
"62874","377.20800","31.43411","0.00720"
"62926","377.52000","31.46018","0.00766"
"62978","377.83200","31.48612","0.00758"
"63030","378.14400","31.51213","0.00761"
"63082","378.45600","31.53808","0.00757"
"63134","378.76800","31.56409","0.00804"
"63186","379.08000","31.59016","0.00775"
"63238","379.39200","31.61611","0.00802"
"63290","379.70400","31.64218","0.00801"
"63342","380.01600","31.66812","0.00781"
"63394","380.32800","31.69419","0.00799"
"63446","380.64000","31.72014","0.00867"
"63498","380.95200","31.74609","0.00823"
"63550","381.26400","31.77222","0.00849"
"63602","381.57600","31.79816","0.00835"
"63654","381.88800","31.82417","0.00873"
"63706","382.20000","31.85012","0.00846"
"63758","382.51200","31.87607","0.00869"
"63810","382.82400","31.90214","0.00864"
"63826","382.91800","31.90997","0.00860"