File: Trajectories_together/161218_2Specimen_RawData_4.csv
"","V1","V2","V3"
"1","End date","12/18/2016",""
"2","Specimen label","16DG_31",""
"3","Maximum Load","0.03697","N"
"4","Time","Extension","Load"
"5","(s)","(mm)","(N)"
"6","0.00000","0.00000","0.00006"
"70","0.38400","0.03211","0.00027"
"134","0.76800","0.06415","0.00095"
"198","1.15200","0.09620","0.00036"
"262","1.53600","0.12825","0.00024"
"326","1.92000","0.16012","0.00024"
"390","2.30400","0.19216","0.00088"
"454","2.68800","0.22421","0.00081"
"518","3.07200","0.25614","0.00097"
"582","3.45600","0.28819","0.00073"
"646","3.84000","0.32023","0.00110"
"710","4.22400","0.35216","0.00084"
"774","4.60800","0.38415","0.00052"
"838","4.99200","0.41619","0.00076"
"902","5.37600","0.44818","0.00127"
"966","5.76000","0.48011","0.00079"
"1030","6.14400","0.51216","0.00093"
"1094","6.52800","0.54420","0.00136"
"1158","6.91200","0.57619","0.00073"
"1222","7.29600","0.60818","0.00119"
"1286","7.68000","0.64017","0.00088"
"1350","8.06400","0.67215","0.00088"
"1414","8.44800","0.70414","0.00112"
"1478","8.83200","0.73619","0.00134"
"1542","9.21600","0.76818","0.00124"
"1606","9.60000","0.80016","0.00122"
"1670","9.98400","0.83215","0.00089"
"1734","10.36800","0.86414","0.00073"
"1798","10.75200","0.89619","0.00066"
"1862","11.13600","0.92817","0.00017"
"1926","11.52000","0.96010","0.00079"
"1990","11.90400","0.99221","0.00084"
"2054","12.28800","1.02419","0.00056"
"2118","12.67200","1.05612","0.00066"
"2182","13.05600","1.08817","0.00062"
"2246","13.44000","1.12022","0.00088"
"2310","13.82400","1.15214","0.00075"
"2374","14.20800","1.18413","0.00066"
"2438","14.59200","1.21624","0.00058"
"2502","14.97600","1.24817","0.00077"
"2566","15.36000","1.28015","0.00083"
"2630","15.74400","1.31220","0.00066"
"2694","16.12800","1.34419","0.00094"
"2758","16.51200","1.37612","0.00056"
"2822","16.89600","1.40816","0.00080"
"2886","17.28000","1.44015","0.00106"
"2950","17.66400","1.47214","0.00083"
"3014","18.04800","1.50419","0.00084"
"3078","18.43200","1.53617","0.00075"
"3142","18.81600","1.56816","0.00086"
"3206","19.20000","1.60021","0.00051"
"3270","19.58400","1.63213","0.00089"
"3334","19.96800","1.66418","0.00066"
"3398","20.35200","1.69623","0.00051"
"3462","20.73600","1.72810","0.00053"
"3526","21.12000","1.76014","0.00098"
"3590","21.50400","1.79219","0.00039"
"3654","21.88800","1.82412","0.00082"
"3718","22.27200","1.85617","0.00055"
"3782","22.65600","1.88821","0.00060"
"3846","23.04000","1.92014","0.00038"
"3910","23.42400","1.95213","0.00044"
"3974","23.80800","1.98418","0.00064"
"4038","24.19200","2.01616","0.00057"
"4102","24.57600","2.04815","0.00022"
"4166","24.96000","2.08020","0.00048"
"4230","25.34400","2.11219","0.00048"
"4294","25.72800","2.14417","0.00056"
"4358","26.11200","2.17616","0.00075"
"4422","26.49600","2.20821","0.00007"
"4486","26.88000","2.24019","0.00044"
"4550","27.26400","2.27218","0.00049"
"4614","27.64800","2.30417","0.00051"
"4678","28.03200","2.33616","0.00046"
"4742","28.41600","2.36814","0.00078"
"4806","28.80000","2.40013","0.00029"
"4870","29.18400","2.43218","0.00048"
"4934","29.56800","2.46423","0.00042"
"4998","29.95200","2.49615","0.00034"
"5062","30.33600","2.52814","0.00055"
"5126","30.72000","2.56019","0.00055"
"5190","31.10400","2.59224","0.00055"
"5254","31.48800","2.62416","0.00049"
"5318","31.87200","2.65615","0.00048"
"5382","32.25600","2.68820","0.00074"
"5446","32.64000","2.72012","0.00028"
"5510","33.02400","2.75223","0.00075"
"5574","33.40800","2.78422","0.00094"
"5638","33.79200","2.81615","0.00035"
"5702","34.17600","2.84813","0.00021"
"5766","34.56000","2.88024","0.00056"
"5830","34.94400","2.91223","0.00058"
"5894","35.32800","2.94410","0.00056"
"5958","35.71200","2.97620","0.00021"
"6022","36.09600","3.00813","0.00022"
"6086","36.48000","3.04018","0.00055"
"6150","36.86400","3.07211","0.00085"
"6214","37.24800","3.10415","0.00041"
"6278","37.63200","3.13620","0.00041"
"6342","38.01600","3.16819","0.00068"
"6406","38.40000","3.20017","0.00055"
"6470","38.78400","3.23216","0.00084"
"6534","39.16800","3.26415","0.00084"
"6598","39.55200","3.29614","0.00063"
"6662","39.93600","3.32818","0.00075"
"6726","40.32000","3.36017","0.00043"
"6790","40.70400","3.39216","0.00050"
"6854","41.08800","3.42415","0.00111"
"6918","41.47200","3.45619","0.00089"
"6982","41.85600","3.48818","0.00028"
"7046","42.24000","3.52011","0.00086"
"7110","42.62400","3.55222","0.00064"
"7174","43.00800","3.58426","0.00051"
"7238","43.39200","3.61613","0.00025"
"7302","43.77600","3.64812","0.00081"
"7366","44.16000","3.68017","0.00085"
"7430","44.54400","3.71221","0.00044"
"7494","44.92800","3.74414","0.00049"
"7558","45.31200","3.77619","0.00058"
"7622","45.69600","3.80817","0.00070"
"7686","46.08000","3.84016","0.00038"
"7750","46.46400","3.87221","0.00078"
"7814","46.84800","3.90414","0.00045"
"7878","47.23200","3.93612","0.00074"
"7942","47.61600","3.96817","0.00074"
"8006","48.00000","4.00016","0.00050"
"8070","48.38400","4.03227","0.00037"
"8134","48.76800","4.06413","0.00088"
"8198","49.15200","4.09618","0.00039"
"8262","49.53600","4.12823","0.00116"
"8326","49.92000","4.16016","0.00069"
"8390","50.30400","4.19214","0.00092"
"8454","50.68800","4.22419","0.00068"
"8518","51.07200","4.25618","0.00063"
"8582","51.45600","4.28811","0.00022"
"8646","51.84000","4.32015","0.00044"
"8710","52.22400","4.35214","0.00096"
"8774","52.60800","4.38419","0.00095"
"8838","52.99200","4.41617","0.00074"
"8902","53.37600","4.44816","0.00076"
"8966","53.76000","4.48021","0.00071"
"9030","54.14400","4.51214","0.00111"
"9094","54.52800","4.54418","0.00092"
"9158","54.91200","4.57617","0.00079"
"9222","55.29600","4.60816","0.00039"
"9286","55.68000","4.64015","0.00047"
"9350","56.06400","4.67225","0.00128"
"9414","56.44800","4.70424","0.00070"
"9478","56.83200","4.73605","0.00091"
"9542","57.21600","4.76822","0.00068"
"9606","57.60000","4.80020","0.00087"
"9670","57.98400","4.83219","0.00094"
"9734","58.36800","4.86418","0.00090"
"9798","58.75200","4.89616","0.00058"
"9862","59.13600","4.92821","0.00084"
"9926","59.52000","4.96020","0.00099"
"9990","59.90400","4.99219","0.00083"
"10054","60.28800","5.02417","0.00068"
"10118","60.67200","5.05616","0.00113"
"10182","61.05600","5.08815","0.00061"
"10246","61.44000","5.12020","0.00109"
"10310","61.82400","5.15218","0.00082"
"10374","62.20800","5.18411","0.00071"
"10438","62.59200","5.21616","0.00108"
"10502","62.97600","5.24821","0.00095"
"10566","63.36000","5.28019","0.00123"
"10630","63.74400","5.31212","0.00065"
"10694","64.12800","5.34417","0.00092"
"10758","64.51200","5.37621","0.00093"
"10822","64.89600","5.40808","0.00103"
"10886","65.28000","5.44019","0.00071"
"10950","65.66400","5.47218","0.00049"
"11014","66.04800","5.50410","0.00097"
"11078","66.43200","5.53615","0.00070"
"11142","66.81600","5.56826","0.00135"
"11206","67.20000","5.60019","0.00078"
"11270","67.58400","5.63211","0.00104"
"11334","67.96800","5.66416","0.00129"
"11398","68.35200","5.69615","0.00129"
"11462","68.73600","5.72814","0.00091"
"11526","69.12000","5.76018","0.00098"
"11590","69.50400","5.79217","0.00118"
"11654","69.88800","5.82422","0.00111"
"11718","70.27200","5.85615","0.00128"
"11782","70.65600","5.88813","0.00091"
"11846","71.04000","5.92018","0.00116"
"11910","71.42400","5.95217","0.00063"
"11974","71.80800","5.98410","0.00089"
"12038","72.19200","6.01614","0.00103"
"12102","72.57600","6.04819","0.00105"
"12166","72.96000","6.08012","0.00113"
"12230","73.34400","6.11216","0.00138"
"12294","73.72800","6.14421","0.00121"
"12358","74.11200","6.17614","0.00126"
"12422","74.49600","6.20813","0.00143"
"12486","74.88000","6.24017","0.00118"
"12550","75.26400","6.27216","0.00119"
"12614","75.64800","6.30409","0.00138"
"12678","76.03200","6.33626","0.00076"
"12742","76.41600","6.36818","0.00177"
"12806","76.80000","6.40017","0.00111"
"12870","77.18400","6.43216","0.00155"
"12934","77.56800","6.46415","0.00143"
"12998","77.95200","6.49619","0.00130"
"13062","78.33600","6.52812","0.00148"
"13126","78.72000","6.56017","0.00129"
"13190","79.10400","6.59215","0.00143"
"13254","79.48800","6.62414","0.00172"
"13318","79.87200","6.65619","0.00154"
"13382","80.25600","6.68818","0.00146"
"13446","80.64000","6.72016","0.00185"
"13510","81.02400","6.75215","0.00141"
"13574","81.40800","6.78414","0.00181"
"13638","81.79200","6.81619","0.00157"
"13702","82.17600","6.84817","0.00134"
"13766","82.56000","6.88010","0.00169"
"13830","82.94400","6.91221","0.00155"
"13894","83.32800","6.94420","0.00196"
"13958","83.71200","6.97606","0.00176"
"14022","84.09600","7.00817","0.00175"
"14086","84.48000","7.04022","0.00214"
"14150","84.86400","7.07214","0.00176"
"14214","85.24800","7.10413","0.00177"
"14278","85.63200","7.13624","0.00180"
"14342","86.01600","7.16823","0.00154"
"14406","86.40000","7.20015","0.00163"
"14470","86.78400","7.23220","0.00193"
"14534","87.16800","7.26419","0.00244"
"14598","87.55200","7.29612","0.00189"
"14662","87.93600","7.32816","0.00180"
"14726","88.32000","7.36021","0.00192"
"14790","88.70400","7.39220","0.00213"
"14854","89.08800","7.42413","0.00215"
"14918","89.47200","7.45617","0.00264"
"14982","89.85600","7.48816","0.00234"
"15046","90.24000","7.52015","0.00241"
"15110","90.62400","7.55214","0.00224"
"15174","91.00800","7.58418","0.00248"
"15238","91.39200","7.61623","0.00202"
"15302","91.77600","7.64810","0.00237"
"15366","92.16000","7.68015","0.00221"
"15430","92.54400","7.71219","0.00263"
"15494","92.92800","7.74418","0.00248"
"15558","93.31200","7.77617","0.00197"
"15622","93.69600","7.80821","0.00250"
"15686","94.08000","7.84014","0.00223"
"15750","94.46400","7.87213","0.00251"
"15814","94.84800","7.90418","0.00243"
"15878","95.23200","7.93616","0.00253"
"15942","95.61600","7.96815","0.00224"
"16006","96.00000","8.00014","0.00237"
"16070","96.38400","8.03219","0.00233"
"16134","96.76800","8.06417","0.00278"
"16198","97.15200","8.09616","0.00248"
"16262","97.53600","8.12821","0.00221"
"16326","97.92000","8.16020","0.00269"
"16390","98.30400","8.19218","0.00221"
"16454","98.68800","8.22417","0.00276"
"16518","99.07200","8.25622","0.00243"
"16582","99.45600","8.28820","0.00260"
"16646","99.84000","8.32013","0.00250"
"16710","100.22400","8.35218","0.00270"
"16774","100.60800","8.38417","0.00280"
"16838","100.99200","8.41615","0.00277"
"16902","101.37600","8.44820","0.00339"
"16966","101.76000","8.48025","0.00292"
"17030","102.14400","8.51218","0.00294"
"17094","102.52800","8.54410","0.00314"
"17158","102.91200","8.57615","0.00282"
"17222","103.29600","8.60820","0.00329"
"17286","103.68000","8.64013","0.00306"
"17350","104.06400","8.67217","0.00327"
"17414","104.44800","8.70422","0.00311"
"17478","104.83200","8.73621","0.00313"
"17542","105.21600","8.76814","0.00299"
"17606","105.60000","8.80012","0.00263"
"17670","105.98400","8.83217","0.00317"
"17734","106.36800","8.86416","0.00282"
"17798","106.75200","8.89614","0.00301"
"17862","107.13600","8.92819","0.00328"
"17926","107.52000","8.96018","0.00324"
"17990","107.90400","8.99217","0.00345"
"18054","108.28800","9.02427","0.00316"
"18118","108.67200","9.05620","0.00385"
"18182","109.05600","9.08813","0.00356"
"18246","109.44000","9.12018","0.00374"
"18310","109.82400","9.15216","0.00354"
"18374","110.20800","9.18421","0.00346"
"18438","110.59200","9.21614","0.00379"
"18502","110.97600","9.24819","0.00405"
"18566","111.36000","9.28017","0.00399"
"18630","111.74400","9.31216","0.00373"
"18694","112.12800","9.34415","0.00385"
"18758","112.51200","9.37619","0.00459"
"18822","112.89600","9.40818","0.00426"
"18886","113.28000","9.44017","0.00424"
"18950","113.66400","9.47216","0.00420"
"19014","114.04800","9.50426","0.00463"
"19078","114.43200","9.53613","0.00423"
"19142","114.81600","9.56818","0.00424"
"19206","115.20000","9.60017","0.00477"
"19270","115.58400","9.63221","0.00458"
"19334","115.96800","9.66408","0.00484"
"19398","116.35200","9.69625","0.00495"
"19462","116.73600","9.72824","0.00475"
"19526","117.12000","9.76016","0.00460"
"19590","117.50400","9.79221","0.00433"
"19654","117.88800","9.82420","0.00478"
"19718","118.27200","9.85612","0.00478"
"19782","118.65600","9.88811","0.00484"
"19846","119.04000","9.92022","0.00485"
"19910","119.42400","9.95221","0.00473"
"19974","119.80800","9.98413","0.00466"
"20038","120.19200","10.01618","0.00527"
"20102","120.57600","10.04823","0.00482"
"20166","120.96000","10.08016","0.00474"
"20230","121.34400","10.11214","0.00500"
"20294","121.72800","10.14419","0.00474"
"20358","122.11200","10.17618","0.00495"
"20422","122.49600","10.20817","0.00536"
"20486","122.88000","10.24009","0.00492"
"20550","123.26400","10.27220","0.00538"
"20614","123.64800","10.30425","0.00476"
"20678","124.03200","10.33612","0.00528"
"20742","124.41600","10.36816","0.00531"
"20806","124.80000","10.40021","0.00510"
"20870","125.18400","10.43208","0.00548"
"20934","125.56800","10.46418","0.00546"
"20998","125.95200","10.49617","0.00525"
"21062","126.33600","10.52816","0.00542"
"21126","126.72000","10.56015","0.00495"
"21190","127.10400","10.59225","0.00467"
"21254","127.48800","10.62418","0.00377"
"21318","127.87200","10.65611","0.00346"
"21382","128.25600","10.68816","0.00305"
"21446","128.64000","10.72014","0.00339"
"21510","129.02400","10.75213","0.00291"
"21574","129.40800","10.78418","0.00331"
"21638","129.79200","10.81617","0.00255"
"21702","130.17600","10.84821","0.00302"
"21766","130.56000","10.88020","0.00282"
"21830","130.94400","10.91219","0.00295"
"21894","131.32800","10.94418","0.00275"
"21958","131.71200","10.97616","0.00312"
"22022","132.09600","11.00809","0.00297"
"22086","132.48000","11.04020","0.00345"
"22150","132.86400","11.07224","0.00337"
"22214","133.24800","11.10411","0.00315"
"22278","133.63200","11.13616","0.00335"
"22342","134.01600","11.16815","0.00348"
"22406","134.40000","11.20019","0.00328"
"22470","134.78400","11.23212","0.00340"
"22534","135.16800","11.26417","0.00372"
"22598","135.55200","11.29616","0.00402"
"22662","135.93600","11.32808","0.00394"
"22726","136.32000","11.36019","0.00395"
"22790","136.70400","11.39224","0.00430"
"22854","137.08800","11.42417","0.00389"
"22918","137.47200","11.45615","0.00397"
"22982","137.85600","11.48814","0.00459"
"23046","138.24000","11.52019","0.00425"
"23110","138.62400","11.55218","0.00464"
"23174","139.00800","11.58416","0.00446"
"23238","139.39200","11.61615","0.00463"
"23302","139.77600","11.64820","0.00490"
"23366","140.16000","11.68018","0.00483"
"23430","140.54400","11.71217","0.00453"
"23494","140.92800","11.74422","0.00482"
"23558","141.31200","11.77615","0.00463"
"23622","141.69600","11.80819","0.00477"
"23686","142.08000","11.84018","0.00538"
"23750","142.46400","11.87223","0.00489"
"23814","142.84800","11.90416","0.00510"
"23878","143.23200","11.93620","0.00543"
"23942","143.61600","11.96825","0.00535"
"24006","144.00000","12.00012","0.00523"
"24070","144.38400","12.03217","0.00546"
"24134","144.76800","12.06421","0.00552"
"24198","145.15200","12.09614","0.00537"
"24262","145.53600","12.12813","0.00567"
"24326","145.92000","12.16018","0.00576"
"24390","146.30400","12.19216","0.00570"
"24454","146.68800","12.22409","0.00582"
"24518","147.07200","12.25620","0.00591"
"24582","147.45600","12.28812","0.00610"
"24646","147.84000","12.32017","0.00582"
"24710","148.22400","12.35216","0.00624"
"24774","148.60800","12.38421","0.00605"
"24838","148.99200","12.41619","0.00665"
"24902","149.37600","12.44812","0.00682"
"24966","149.76000","12.48023","0.00659"
"25030","150.14400","12.51216","0.00714"
"25094","150.52800","12.54414","0.00709"
"25158","150.91200","12.57613","0.00703"
"25222","151.29600","12.60818","0.00686"
"25286","151.68000","12.64023","0.00719"
"25350","152.06400","12.67215","0.00737"
"25414","152.44800","12.70414","0.00764"
"25478","152.83200","12.73619","0.00730"
"25542","153.21600","12.76817","0.00782"
"25606","153.60000","12.80016","0.00788"
"25670","153.98400","12.83221","0.00764"
"25734","154.36800","12.86414","0.00787"
"25798","154.75200","12.89606","0.00773"
"25862","155.13600","12.92817","0.00786"
"25926","155.52000","12.96022","0.00777"
"25990","155.90400","12.99215","0.00815"
"26054","156.28800","13.02419","0.00800"
"26118","156.67200","13.05618","0.00816"
"26182","157.05600","13.08817","0.00799"
"26246","157.44000","13.12010","0.00798"
"26310","157.82400","13.15220","0.00823"
"26374","158.20800","13.18419","0.00854"
"26438","158.59200","13.21618","0.00854"
"26502","158.97600","13.24811","0.00871"
"26566","159.36000","13.28021","0.00883"
"26630","159.74400","13.31220","0.00924"
"26694","160.12800","13.34413","0.00932"
"26758","160.51200","13.37611","0.00888"
"26822","160.89600","13.40816","0.00914"
"26886","161.28000","13.44015","0.00902"
"26950","161.66400","13.47214","0.00965"
"27014","162.04800","13.50424","0.01021"
"27078","162.43200","13.53617","0.00981"
"27142","162.81600","13.56816","0.00986"
"27206","163.20000","13.60015","0.00957"
"27270","163.58400","13.63219","0.00992"
"27334","163.96800","13.66418","0.00959"
"27398","164.35200","13.69617","0.00975"
"27462","164.73600","13.72822","0.00979"
"27526","165.12000","13.76020","0.00992"
"27590","165.50400","13.79213","0.00976"
"27654","165.88800","13.82418","0.01025"
"27718","166.27200","13.85616","0.01052"
"27782","166.65600","13.88815","0.01028"
"27846","167.04000","13.92014","0.01002"
"27910","167.42400","13.95219","0.01036"
"27974","167.80800","13.98417","0.01098"
"28038","168.19200","14.01610","0.01067"
"28102","168.57600","14.04821","0.01108"
"28166","168.96000","14.08020","0.01076"
"28230","169.34400","14.11212","0.01070"
"28294","169.72800","14.14411","0.01070"
"28358","170.11200","14.17622","0.01086"
"28422","170.49600","14.20821","0.01062"
"28486","170.88000","14.24013","0.01049"
"28550","171.26400","14.27218","0.01101"
"28614","171.64800","14.30411","0.01105"
"28678","172.03200","14.33616","0.01031"
"28742","172.41600","14.36814","0.01089"
"28806","172.80000","14.40019","0.01101"
"28870","173.18400","14.43218","0.00894"
"28934","173.56800","14.46416","0.00972"
"28998","173.95200","14.49615","0.01010"
"29062","174.33600","14.52820","0.01018"
"29126","174.72000","14.56019","0.01025"
"29190","175.10400","14.59217","0.01013"
"29254","175.48800","14.62422","0.00971"
"29318","175.87200","14.65621","0.01069"
"29382","176.25600","14.68808","0.01018"
"29446","176.64000","14.72018","0.01056"
"29510","177.02400","14.75223","0.01076"
"29574","177.40800","14.78410","0.01031"
"29638","177.79200","14.81621","0.01066"
"29702","178.17600","14.84825","0.01090"
"29766","178.56000","14.88012","0.01089"
"29830","178.94400","14.91211","0.01063"
"29894","179.32800","14.94422","0.01014"
"29958","179.71200","14.97614","0.00995"
"30022","180.09600","15.00813","0.01074"
"30086","180.48000","15.04018","0.01083"
"30150","180.86400","15.07217","0.01049"
"30214","181.24800","15.10415","0.01117"
"30278","181.63200","15.13614","0.01118"
"30342","182.01600","15.16813","0.01108"
"30406","182.40000","15.20017","0.01159"
"30470","182.78400","15.23216","0.01161"
"30534","183.16800","15.26415","0.01132"
"30598","183.55200","15.29620","0.01134"
"30662","183.93600","15.32818","0.01131"
"30726","184.32000","15.36011","0.01198"
"30790","184.70400","15.39216","0.01072"
"30854","185.08800","15.42421","0.01079"
"30918","185.47200","15.45613","0.01092"
"30982","185.85600","15.48812","0.01114"
"31046","186.24000","15.52023","0.01174"
"31110","186.62400","15.55216","0.01162"
"31174","187.00800","15.58414","0.01170"
"31238","187.39200","15.61619","0.01220"
"31302","187.77600","15.64824","0.01240"
"31366","188.16000","15.68010","0.01278"
"31430","188.54400","15.71215","0.01270"
"31494","188.92800","15.74414","0.01246"
"31558","189.31200","15.77619","0.01237"
"31622","189.69600","15.80817","0.01291"
"31686","190.08000","15.84016","0.01309"
"31750","190.46400","15.87215","0.01331"
"31814","190.84800","15.90413","0.01193"
"31878","191.23200","15.93618","0.01202"
"31942","191.61600","15.96817","0.01235"
"32006","192.00000","16.00016","0.01313"
"32070","192.38400","16.03214","0.01285"
"32134","192.76800","16.06413","0.01254"
"32198","193.15200","16.09618","0.01242"
"32262","193.53600","16.12817","0.01242"
"32326","193.92000","16.16015","0.01347"
"32390","194.30400","16.19220","0.01291"
"32454","194.68800","16.22419","0.01354"
"32518","195.07200","16.25612","0.01181"
"32582","195.45600","16.28816","0.01229"
"32646","195.84000","16.32021","0.01247"
"32710","196.22400","16.35214","0.01171"
"32774","196.60800","16.38418","0.01220"
"32838","196.99200","16.41623","0.01246"
"32902","197.37600","16.44816","0.01299"
"32966","197.76000","16.48015","0.01265"
"33030","198.14400","16.51220","0.01208"
"33094","198.52800","16.54418","0.01181"
"33158","198.91200","16.57617","0.01150"
"33222","199.29600","16.60822","0.01147"
"33286","199.68000","16.64014","0.01159"
"33350","200.06400","16.67213","0.01174"
"33414","200.44800","16.70418","0.01138"
"33478","200.83200","16.73623","0.01185"
"33542","201.21600","16.76821","0.01151"
"33606","201.60000","16.80014","0.01223"
"33670","201.98400","16.83213","0.01199"
"33734","202.36800","16.86423","0.01279"
"33798","202.75200","16.89622","0.01276"
"33862","203.13600","16.92815","0.01309"
"33926","203.52000","16.96020","0.01343"
"33990","203.90400","16.99219","0.01334"
"34054","204.28800","17.02417","0.01354"
"34118","204.67200","17.05610","0.01455"
"34182","205.05600","17.08815","0.01414"
"34246","205.44000","17.12019","0.01493"
"34310","205.82400","17.15218","0.01438"
"34374","206.20800","17.18423","0.01461"
"34438","206.59200","17.21622","0.01523"
"34502","206.97600","17.24809","0.01454"
"34566","207.36000","17.28019","0.01487"
"34630","207.74400","17.31218","0.01530"
"34694","208.12800","17.34411","0.01486"
"34758","208.51200","17.37615","0.01482"
"34822","208.89600","17.40820","0.01511"
"34886","209.28000","17.44019","0.01552"
"34950","209.66400","17.47218","0.01544"
"35014","210.04800","17.50416","0.01597"
"35078","210.43200","17.53621","0.01555"
"35142","210.81600","17.56814","0.01577"
"35206","211.20000","17.60018","0.01628"
"35270","211.58400","17.63217","0.01612"
"35334","211.96800","17.66422","0.01613"
"35398","212.35200","17.69615","0.01623"
"35462","212.73600","17.72813","0.01673"
"35526","213.12000","17.76018","0.01688"
"35590","213.50400","17.79217","0.01713"
"35654","213.88800","17.82416","0.01678"
"35718","214.27200","17.85620","0.01662"
"35782","214.65600","17.88813","0.01442"
"35846","215.04000","17.92012","0.01436"
"35910","215.42400","17.95223","0.01601"
"35974","215.80800","17.98421","0.01593"
"36038","216.19200","18.01620","0.01598"
"36102","216.57600","18.04813","0.01585"
"36166","216.96000","18.08018","0.01599"
"36230","217.34400","18.11216","0.01628"
"36294","217.72800","18.14409","0.01649"
"36358","218.11200","18.17614","0.01662"
"36422","218.49600","18.20824","0.01642"
"36486","218.88000","18.24017","0.01766"
"36550","219.26400","18.27216","0.01755"
"36614","219.64800","18.30421","0.01742"
"36678","220.03200","18.33619","0.01765"
"36742","220.41600","18.36812","0.01840"
"36806","220.80000","18.40023","0.01838"
"36870","221.18400","18.43216","0.01793"
"36934","221.56800","18.46414","0.01773"
"36998","221.95200","18.49619","0.01837"
"37062","222.33600","18.52818","0.01786"
"37126","222.72000","18.56017","0.01809"
"37190","223.10400","18.59209","0.01822"
"37254","223.48800","18.62414","0.01823"
"37318","223.87200","18.65619","0.01805"
"37382","224.25600","18.68818","0.01583"
"37446","224.64000","18.72016","0.01579"
"37510","225.02400","18.75215","0.01576"
"37574","225.40800","18.78420","0.01594"
"37638","225.79200","18.81612","0.01553"
"37702","226.17600","18.84817","0.01596"
"37766","226.56000","18.88016","0.01664"
"37830","226.94400","18.91215","0.01657"
"37894","227.32800","18.94414","0.01717"
"37958","227.71200","18.97618","0.01529"
"38022","228.09600","19.00823","0.01598"
"38086","228.48000","19.04010","0.01633"
"38150","228.86400","19.07226","0.01630"
"38214","229.24800","19.10419","0.01700"
"38278","229.63200","19.13612","0.01727"
"38342","230.01600","19.16811","0.01722"
"38406","230.40000","19.20015","0.01674"
"38470","230.78400","19.23220","0.01641"
"38534","231.16800","19.26413","0.01694"
"38598","231.55200","19.29623","0.01469"
"38662","231.93600","19.32816","0.01608"
"38726","232.32000","19.36015","0.01605"
"38790","232.70400","19.39220","0.01657"
"38854","233.08800","19.42418","0.01618"
"38918","233.47200","19.45617","0.01742"
"38982","233.85600","19.48816","0.01816"
"39046","234.24000","19.52015","0.01822"
"39110","234.62400","19.55219","0.01874"
"39174","235.00800","19.58418","0.01885"
"39238","235.39200","19.61611","0.01927"
"39302","235.77600","19.64816","0.01841"
"39366","236.16000","19.68020","0.01935"
"39430","236.54400","19.71207","0.01935"
"39494","236.92800","19.74418","0.01947"
"39558","237.31200","19.77623","0.01936"
"39622","237.69600","19.80815","0.01946"
"39686","238.08000","19.84020","0.01939"
"39750","238.46400","19.87219","0.02011"
"39814","238.84800","19.90417","0.02076"
"39878","239.23200","19.93610","0.01973"
"39942","239.61600","19.96821","0.01944"
"40006","240.00000","20.00014","0.01985"
"40070","240.38400","20.03213","0.01913"
"40134","240.76800","20.06411","0.01939"
"40198","241.15200","20.09616","0.01912"
"40262","241.53600","20.12821","0.01954"
"40326","241.92000","20.16014","0.01983"
"40390","242.30400","20.19218","0.02009"
"40454","242.68800","20.22417","0.02039"
"40518","243.07200","20.25616","0.02032"
"40582","243.45600","20.28814","0.02085"
"40646","243.84000","20.32019","0.02011"
"40710","244.22400","20.35224","0.02062"
"40774","244.60800","20.38416","0.02093"
"40838","244.99200","20.41615","0.02142"
"40902","245.37600","20.44820","0.02035"
"40966","245.76000","20.48019","0.02021"
"41030","246.14400","20.51217","0.02076"
"41094","246.52800","20.54416","0.02096"
"41158","246.91200","20.57621","0.02106"
"41222","247.29600","20.60814","0.02114"
"41286","247.68000","20.64018","0.02163"
"41350","248.06400","20.67223","0.02018"
"41414","248.44800","20.70410","0.02059"
"41478","248.83400","20.73633","0.02073"
"41542","249.21800","20.76837","0.02087"
"41606","249.60200","20.80030","0.01861"
"41670","249.98600","20.83229","0.01981"
"41734","250.37000","20.86439","0.02013"
"41798","250.75400","20.89632","0.02004"
"41862","251.13800","20.92831","0.01889"
"41926","251.52200","20.96030","0.01863"
"41990","251.90600","20.99234","0.02029"
"42054","252.29000","21.02433","0.01695"
"42118","252.67400","21.05632","0.01829"
"42182","253.05800","21.08831","0.01912"
"42246","253.44200","21.12035","0.01883"
"42310","253.82600","21.15234","0.02014"
"42374","254.21000","21.18433","0.02019"
"42438","254.59400","21.21638","0.02110"
"42502","254.97800","21.24836","0.02046"
"42566","255.36200","21.28029","0.02103"
"42630","255.74600","21.31228","0.02070"
"42694","256.13000","21.34433","0.01997"
"42758","256.51400","21.37631","0.02000"
"42822","256.89800","21.40830","0.01929"
"42886","257.28200","21.44041","0.01951"
"42950","257.66600","21.47233","0.01925"
"43014","258.05000","21.50426","0.01977"
"43078","258.43400","21.53637","0.01957"
"43142","258.81800","21.56836","0.01993"
"43206","259.20200","21.60029","0.02031"
"43270","259.58600","21.63233","0.02089"
"43334","259.97000","21.66438","0.02042"
"43398","260.35400","21.69631","0.02050"
"43462","260.73800","21.72829","0.02045"
"43526","261.12200","21.76040","0.02093"
"43590","261.50600","21.79233","0.02096"
"43654","261.89000","21.82432","0.02057"
"43718","262.27400","21.85636","0.02156"
"43782","262.65800","21.88835","0.02118"
"43846","263.04200","21.92034","0.02120"
"43910","263.42600","21.95226","0.02151"
"43974","263.81000","21.98431","0.02222"
"44038","264.19400","22.01636","0.02255"
"44102","264.57800","22.04835","0.02297"
"44166","264.96200","22.08027","0.02262"
"44230","265.34600","22.11238","0.02302"
"44294","265.73000","22.14437","0.02302"
"44358","266.11400","22.17630","0.02299"
"44422","266.49800","22.20834","0.02331"
"44486","266.88200","22.24033","0.02190"
"44550","267.26600","22.27232","0.02289"
"44614","267.65000","22.30430","0.02204"
"44678","268.03400","22.33636","0.02148"
"44742","268.41800","22.36834","0.02189"
"44806","268.80200","22.40027","0.02008"
"44870","269.18600","22.43237","0.02122"
"44934","269.57000","22.46436","0.02179"
"44998","269.95400","22.49629","0.02180"
"45062","270.33800","22.52834","0.02291"
"45126","270.72200","22.56039","0.02075"
"45190","271.10600","22.59237","0.02083"
"45254","271.49000","22.62430","0.02002"
"45318","271.87400","22.65635","0.02062"
"45382","272.25800","22.68839","0.01813"
"45446","272.64200","22.72032","0.01802"
"45510","273.02600","22.75231","0.01758"
"45574","273.41000","22.78436","0.01709"
"45638","273.79400","22.81628","0.01863"
"45702","274.17800","22.84833","0.01859"
"45766","274.56200","22.88038","0.01884"
"45830","274.94600","22.91231","0.01886"
"45894","275.33000","22.94435","0.01921"
"45958","275.71400","22.97634","0.01916"
"46022","276.09800","23.00833","0.01912"
"46086","276.48200","23.04032","0.01911"
"46150","276.86600","23.07230","0.01946"
"46214","277.25000","23.10429","0.01918"
"46278","277.63400","23.13640","0.01950"
"46342","278.01800","23.16833","0.01879"
"46406","278.40200","23.20031","0.01910"
"46470","278.78600","23.23242","0.01855"
"46534","279.17000","23.26435","0.01947"
"46598","279.55400","23.29627","0.01888"
"46662","279.93800","23.32838","0.01798"
"46726","280.32200","23.36037","0.01867"
"46790","280.70600","23.39230","0.01921"
"46854","281.09000","23.42435","0.01886"
"46918","281.47400","23.45633","0.01891"
"46982","281.85800","23.48832","0.01901"
"47046","282.24200","23.52031","0.01986"
"47110","282.62600","23.55235","0.02017"
"47174","283.01000","23.58434","0.01992"
"47238","283.39400","23.61633","0.01938"
"47302","283.77800","23.64831","0.01953"
"47366","284.16200","23.68036","0.02054"
"47430","284.54600","23.71235","0.01986"
"47494","284.93000","23.74434","0.01944"
"47558","285.31400","23.77632","0.01909"
"47622","285.69800","23.80837","0.01968"
"47686","286.08200","23.84030","0.01994"
"47750","286.46600","23.87229","0.01923"
"47814","286.85000","23.90433","0.01878"
"47878","287.23400","23.93638","0.01932"
"47942","287.61800","23.96831","0.01935"
"48006","288.00200","24.00035","0.02057"
"48070","288.38600","24.03240","0.01879"
"48134","288.77000","24.06427","0.01911"
"48198","289.15400","24.09632","0.01895"
"48262","289.53800","24.12843","0.01976"
"48326","289.92200","24.16029","0.01989"
"48390","290.30600","24.19228","0.01974"
"48454","290.69000","24.22439","0.01974"
"48518","291.07400","24.25637","0.01887"
"48582","291.45800","24.28830","0.01973"
"48646","291.84200","24.32035","0.01879"
"48710","292.22600","24.35234","0.01831"
"48774","292.61000","24.38433","0.01920"
"48838","292.99400","24.41637","0.01957"
"48902","293.37800","24.44836","0.01983"
"48966","293.76200","24.48034","0.01926"
"49030","294.14600","24.51233","0.01929"
"49094","294.53000","24.54432","0.01939"
"49158","294.91400","24.57637","0.01929"
"49222","295.29800","24.60830","0.01909"
"49286","295.68200","24.64028","0.01995"
"49350","296.06600","24.67233","0.01936"
"49414","296.45000","24.70444","0.01946"
"49478","296.83400","24.73624","0.01976"
"49542","297.21800","24.76829","0.01970"
"49606","297.60200","24.80040","0.01965"
"49670","297.98600","24.83233","0.01967"
"49734","298.37000","24.86432","0.01984"
"49798","298.75400","24.89636","0.01973"
"49862","299.13800","24.92835","0.01925"
"49926","299.52200","24.96028","0.01962"
"49990","299.90600","24.99232","0.01953"
"50054","300.29000","25.02437","0.01914"
"50118","300.67400","25.05636","0.01974"
"50182","301.05800","25.08829","0.01992"
"50246","301.44200","25.12039","0.01993"
"50310","301.82600","25.15232","0.02028"
"50374","302.21000","25.18425","0.02067"
"50438","302.59400","25.21636","0.02050"
"50502","302.97800","25.24834","0.02068"
"50566","303.36200","25.28027","0.02056"
"50630","303.74600","25.31231","0.02141"
"50694","304.13000","25.34436","0.02055"
"50758","304.51400","25.37635","0.01770"
"50822","304.89800","25.40834","0.01859"
"50886","305.28200","25.44027","0.01915"
"50950","305.66600","25.47231","0.02045"
"51014","306.05000","25.50436","0.02027"
"51078","306.43400","25.53629","0.02021"
"51142","306.81800","25.56834","0.01737"
"51206","307.20200","25.60038","0.01769"
"51270","307.58600","25.63225","0.01807"
"51334","307.97000","25.66436","0.01967"
"51398","308.35400","25.69634","0.01891"
"51462","308.73800","25.72833","0.01927"
"51526","309.12200","25.76026","0.01893"
"51590","309.50600","25.79237","0.01886"
"51654","309.89000","25.82435","0.01935"
"51718","310.27400","25.85628","0.01999"
"51782","310.65800","25.88833","0.01979"
"51846","311.04200","25.92038","0.02018"
"51910","311.42600","25.95230","0.02013"
"51974","311.81000","25.98429","0.02058"
"52038","312.19400","26.01628","0.02064"
"52102","312.57800","26.04833","0.01997"
"52166","312.96200","26.08031","0.02029"
"52230","313.34600","26.11236","0.01997"
"52294","313.73000","26.14429","0.01977"
"52358","314.11400","26.17634","0.02083"
"52422","314.49800","26.20832","0.02058"
"52486","314.88200","26.24037","0.02018"
"52550","315.26600","26.27236","0.02084"
"52614","315.65000","26.30429","0.02162"
"52678","316.03400","26.33633","0.02127"
"52742","316.41800","26.36832","0.02112"
"52806","316.80200","26.40031","0.02156"
"52870","317.18600","26.43229","0.02210"
"52934","317.57000","26.46434","0.02199"
"52998","317.95400","26.49639","0.02224"
"53062","318.33800","26.52826","0.02200"
"53126","318.72200","26.56030","0.02237"
"53190","319.10600","26.59235","0.02228"
"53254","319.49000","26.62428","0.02215"
"53318","319.87400","26.65633","0.02234"
"53382","320.25800","26.68837","0.02243"
"53446","320.64200","26.72036","0.02306"
"53510","321.02600","26.75229","0.02318"
"53574","321.41000","26.78440","0.02320"
"53638","321.79400","26.81633","0.02296"
"53702","322.17800","26.84837","0.02310"
"53766","322.56200","26.88036","0.02342"
"53830","322.94600","26.91234","0.02323"
"53894","323.33000","26.94439","0.02315"
"53958","323.71400","26.97632","0.02338"
"54022","324.09800","27.00837","0.02393"
"54086","324.48200","27.04036","0.02425"
"54150","324.86600","27.07234","0.02459"
"54214","325.25000","27.10433","0.02435"
"54278","325.63400","27.13638","0.02447"
"54342","326.01800","27.16837","0.02447"
"54406","326.40200","27.20029","0.02456"
"54470","326.78600","27.23234","0.02463"
"54534","327.17000","27.26433","0.02474"
"54598","327.55400","27.29631","0.02485"
"54662","327.93800","27.32830","0.02528"
"54726","328.32200","27.36035","0.02514"
"54790","328.70600","27.39240","0.02500"
"54854","329.09000","27.42432","0.02434"
"54918","329.47400","27.45625","0.02402"
"54982","329.85800","27.48842","0.02270"
"55046","330.24200","27.52034","0.02294"
"55110","330.62600","27.55233","0.02400"
"55174","331.01000","27.58438","0.02390"
"55238","331.39400","27.61637","0.02423"
"55302","331.77800","27.64829","0.02510"
"55366","332.16200","27.68040","0.02461"
"55430","332.54600","27.71239","0.02486"
"55494","332.93000","27.74432","0.02456"
"55558","333.31400","27.77630","0.01689"
"55622","333.69800","27.80835","0.01755"
"55686","334.08200","27.84034","0.01864"
"55750","334.46600","27.87233","0.01866"
"55814","334.85000","27.90431","0.01879"
"55878","335.23400","27.93630","0.01891"
"55942","335.61800","27.96835","0.02024"
"56006","336.00200","28.00033","0.02026"
"56070","336.38600","28.03232","0.02066"
"56134","336.77000","28.06431","0.02165"
"56198","337.15400","28.09630","0.02136"
"56262","337.53800","28.12829","0.02250"
"56326","337.92200","28.16033","0.02270"
"56390","338.30600","28.19232","0.02310"
"56454","338.69000","28.22431","0.02329"
"56518","339.07400","28.25636","0.02401"
"56582","339.45800","28.28840","0.02409"
"56646","339.84200","28.32027","0.02436"
"56710","340.22600","28.35238","0.02500"
"56774","340.61000","28.38437","0.02403"
"56838","340.99400","28.41629","0.02450"
"56902","341.37800","28.44834","0.02199"
"56966","341.76200","28.48038","0.02248"
"57030","342.14600","28.51231","0.02315"
"57094","342.53000","28.54430","0.02350"
"57158","342.91400","28.57635","0.02360"
"57222","343.29800","28.60834","0.02397"
"57286","343.68200","28.64032","0.02415"
"57350","344.06600","28.67237","0.02472"
"57414","344.45000","28.70436","0.02480"
"57478","344.83400","28.73628","0.02515"
"57542","345.21800","28.76833","0.02558"
"57606","345.60200","28.80032","0.02578"
"57670","345.98600","28.83231","0.02548"
"57734","346.37000","28.86435","0.02425"
"57798","346.75400","28.89634","0.02468"
"57862","347.13800","28.92839","0.02478"
"57926","347.52200","28.96038","0.02510"
"57990","347.90600","28.99230","0.02548"
"58054","348.29000","29.02435","0.02582"
"58118","348.67400","29.05634","0.02597"
"58182","349.05800","29.08833","0.02648"
"58246","349.44200","29.12032","0.02680"
"58310","349.82600","29.15236","0.02701"
"58374","350.21000","29.18435","0.02724"
"58438","350.59400","29.21628","0.02737"
"58502","350.97800","29.24838","0.02738"
"58566","351.36200","29.28037","0.02738"
"58630","351.74600","29.31230","0.02790"
"58694","352.13000","29.34429","0.02882"
"58758","352.51400","29.37639","0.02881"
"58822","352.89800","29.40832","0.02648"
"58886","353.28200","29.44031","0.02679"
"58950","353.66600","29.47235","0.02672"
"59014","354.05000","29.50434","0.02725"
"59078","354.43400","29.53633","0.02718"
"59142","354.81800","29.56832","0.02691"
"59206","355.20200","29.60030","0.02753"
"59270","355.58600","29.63235","0.02389"
"59334","355.97000","29.66428","0.02524"
"59398","356.35400","29.69633","0.02607"
"59462","356.73800","29.72837","0.02635"
"59526","357.12200","29.76036","0.02677"
"59590","357.50600","29.79235","0.02573"
"59654","357.89000","29.82434","0.02617"
"59718","358.27400","29.85638","0.02679"
"59782","358.65800","29.88831","0.02747"
"59846","359.04200","29.92036","0.02663"
"59910","359.42600","29.95234","0.02687"
"59974","359.81000","29.98433","0.02790"
"60038","360.19400","30.01632","0.02783"
"60102","360.57800","30.04843","0.02771"
"60166","360.96200","30.08036","0.02753"
"60230","361.34600","30.11228","0.02772"
"60294","361.73000","30.14439","0.02750"
"60358","362.11400","30.17638","0.02720"
"60422","362.49800","30.20831","0.02674"
"60486","362.88200","30.24035","0.02719"
"60550","363.26600","30.27234","0.02656"
"60614","363.65000","30.30439","0.02748"
"60678","364.03400","30.33632","0.02754"
"60742","364.41800","30.36836","0.02752"
"60806","364.80200","30.40035","0.02300"
"60870","365.18600","30.43233","0.02427"
"60934","365.57000","30.46432","0.02291"
"60998","365.95400","30.49637","0.02391"
"61062","366.33800","30.52835","0.02457"
"61126","366.72200","30.56034","0.02528"
"61190","367.10600","30.59233","0.02591"
"61254","367.49000","30.62438","0.02571"
"61318","367.87400","30.65631","0.02626"
"61382","368.25800","30.68829","0.02703"
"61446","368.64200","30.72040","0.02751"
"61510","369.02600","30.75233","0.02759"
"61574","369.41000","30.78432","0.02779"
"61638","369.79400","30.81636","0.02771"
"61702","370.17800","30.84841","0.02800"
"61766","370.56200","30.88022","0.02859"
"61830","370.94600","30.91233","0.02846"
"61894","371.33000","30.94437","0.02869"
"61958","371.71400","30.97630","0.02715"
"62022","372.09800","31.00835","0.02565"
"62086","372.48200","31.04033","0.02635"
"62150","372.86600","31.07238","0.02707"
"62214","373.25000","31.10431","0.02729"
"62278","373.63400","31.13636","0.02802"
"62342","374.01800","31.16834","0.02847"
"62406","374.40200","31.20033","0.02917"
"62470","374.78600","31.23232","0.02929"
"62534","375.17000","31.26436","0.02941"
"62598","375.55400","31.29635","0.02921"
"62662","375.93800","31.32834","0.02910"
"62726","376.32200","31.36033","0.02933"
"62790","376.70600","31.39237","0.02919"
"62854","377.09000","31.42436","0.02873"
"62918","377.47400","31.45635","0.02932"
"62982","377.85800","31.48834","0.02909"
"63046","378.24200","31.52032","0.02982"
"63110","378.62600","31.55231","0.02978"
"63174","379.01000","31.58430","0.03033"
"63238","379.39400","31.61634","0.03117"
"63302","379.77800","31.64833","0.03123"
"63366","380.16200","31.68032","0.02992"
"63430","380.54600","31.71231","0.03060"
"63494","380.93000","31.74435","0.03022"
"63558","381.31400","31.77628","0.03101"
"63622","381.69800","31.80833","0.03119"
"63686","382.08200","31.84038","0.03018"
"63750","382.46600","31.87237","0.03026"
"63814","382.85000","31.90429","0.02914"
"63878","383.23400","31.93634","0.02727"
"63942","383.61800","31.96832","0.02714"
"64006","384.00200","32.00031","0.02720"
"64070","384.38600","32.03236","0.02824"
"64134","384.77000","32.06435","0.02810"
"64198","385.15400","32.09634","0.02884"
"64262","385.53800","32.12832","0.02178"
"64326","385.92200","32.16037","0.02235"
"64390","386.30600","32.19236","0.02205"
"64454","386.69000","32.22429","0.02252"
"64518","387.07400","32.25633","0.02394"
"64582","387.45800","32.28832","0.02442"
"64646","387.84200","32.32031","0.02465"
"64710","388.22600","32.35236","0.02486"
"64774","388.61000","32.38434","0.02468"
"64838","388.99400","32.41639","0.02472"
"64902","389.37800","32.44826","0.02471"
"64966","389.76200","32.48030","0.02538"
"65030","390.14600","32.51235","0.02504"
"65094","390.53000","32.54434","0.02538"
"65158","390.91400","32.57632","0.02623"
"65222","391.29800","32.60838","0.02549"
"65286","391.68200","32.64036","0.02591"
"65350","392.06600","32.67229","0.02635"
"65414","392.45000","32.70433","0.02665"
"65478","392.83400","32.73638","0.02685"
"65542","393.21800","32.76831","0.02733"
"65606","393.60200","32.80030","0.02697"
"65670","393.98600","32.83241","0.02744"
"65734","394.37000","32.86433","0.02731"
"65798","394.75400","32.89632","0.02744"
"65862","395.13800","32.92837","0.02745"
"65926","395.52200","32.96035","0.02767"
"65990","395.90600","32.99234","0.02816"
"66054","396.29000","33.02433","0.02839"
"66118","396.67400","33.05632","0.02888"
"66182","397.05800","33.08830","0.02763"
"66246","397.44200","33.12029","0.02784"
"66310","397.82600","33.15228","0.02862"
"66374","398.21000","33.18433","0.02872"
"66438","398.59400","33.21637","0.02807"
"66502","398.97800","33.24830","0.02844"
"66566","399.36200","33.28035","0.02820"
"66630","399.74600","33.31234","0.02845"
"66694","400.13000","33.34426","0.02866"
"66758","400.51400","33.37637","0.02855"
"66822","400.89800","33.40842","0.02907"
"66886","401.28200","33.44028","0.02859"
"66950","401.66600","33.47227","0.02882"
"67014","402.05000","33.50438","0.02847"
"67078","402.43400","33.53637","0.02850"
"67142","402.81800","33.56830","0.02913"
"67206","403.20200","33.60034","0.02868"
"67270","403.58600","33.63233","0.02931"
"67334","403.97000","33.66431","0.02844"
"67398","404.35400","33.69637","0.02851"
"67462","404.73800","33.72835","0.02871"
"67526","405.12200","33.76034","0.02883"
"67590","405.50600","33.79232","0.02945"
"67654","405.89000","33.82431","0.02895"
"67718","406.27400","33.85630","0.02909"
"67782","406.65800","33.88835","0.02939"
"67846","407.04200","33.92034","0.02937"
"67910","407.42600","33.95232","0.02933"
"67974","407.81000","33.98437","0.02850"
"68038","408.19400","34.01630","0.02812"
"68102","408.57800","34.04829","0.02891"
"68166","408.96200","34.08033","0.02918"
"68230","409.34600","34.11232","0.02905"
"68294","409.73000","34.14431","0.02963"
"68358","410.11400","34.17635","0.02964"
"68422","410.49800","34.20840","0.02953"
"68486","410.88200","34.24027","0.02929"
"68550","411.26600","34.27238","0.02840"
"68614","411.65000","34.30437","0.02834"
"68678","412.03400","34.33629","0.02806"
"68742","412.41800","34.36834","0.02850"
"68806","412.80200","34.40038","0.02794"
"68870","413.18600","34.43237","0.02855"
"68934","413.57000","34.46430","0.02820"
"68998","413.95400","34.49635","0.02832"
"69062","414.33800","34.52834","0.02843"
"69126","414.72200","34.56032","0.02840"
"69190","415.10600","34.59231","0.02807"
"69254","415.49000","34.62436","0.02858"
"69318","415.87400","34.65635","0.02816"
"69382","416.25800","34.68827","0.02881"
"69446","416.64200","34.72032","0.02888"
"69510","417.02600","34.75237","0.02898"
"69574","417.41000","34.78436","0.02907"
"69638","417.79400","34.81628","0.02989"
"69702","418.17800","34.84833","0.02921"
"69766","418.56200","34.88038","0.03021"
"69830","418.94600","34.91230","0.03007"
"69894","419.33000","34.94435","0.03022"
"69958","419.71400","34.97634","0.02957"
"70022","420.09800","35.00833","0.02989"
"70086","420.48200","35.04037","0.03037"
"70150","420.86600","35.07236","0.03021"
"70214","421.25000","35.10435","0.03084"
"70278","421.63400","35.13628","0.03072"
"70342","422.01800","35.16832","0.03150"
"70406","422.40200","35.20037","0.03089"
"70470","422.78600","35.23230","0.03152"
"70534","423.17000","35.26434","0.03124"
"70598","423.55400","35.29633","0.03215"
"70662","423.93800","35.32832","0.03227"
"70726","424.32200","35.36031","0.03281"
"70790","424.70600","35.39230","0.03262"
"70854","425.09000","35.42434","0.03311"
"70918","425.47400","35.45633","0.03318"
"70982","425.85800","35.48832","0.03320"
"71046","426.24200","35.52036","0.03183"
"71110","426.62600","35.55235","0.03275"
"71174","427.01000","35.58434","0.03303"
"71238","427.39400","35.61633","0.03337"
"71302","427.77800","35.64837","0.03340"
"71366","428.16200","35.68030","0.03366"
"71430","428.54600","35.71229","0.03278"
"71494","428.93000","35.74440","0.03339"
"71558","429.31400","35.77638","0.03375"
"71622","429.69800","35.80831","0.03405"
"71686","430.08200","35.84036","0.03369"
"71750","430.46600","35.87240","0.03480"
"71814","430.85000","35.90433","0.03431"
"71878","431.23400","35.93632","0.03462"
"71942","431.61800","35.96837","0.03527"
"72006","432.00200","36.00035","0.03500"
"72070","432.38600","36.03234","0.03583"
"72134","432.77000","36.06433","0.03608"
"72198","433.15400","36.09637","0.03635"
"72262","433.53800","36.12830","0.03604"
"72326","433.92200","36.16035","0.03678"
"72390","434.30600","36.19234","0.03123"
"72454","434.69000","36.22432","0.03029"
"72518","435.07400","36.25631","0.03135"
"72582","435.45800","36.28836","0.03168"
"72646","435.84200","36.32041","0.03039"
"72710","436.22600","36.35234","0.03109"
"72774","436.61000","36.38432","0.03194"
"72838","436.99400","36.41637","0.03173"
"72902","437.37800","36.44830","0.03239"
"72966","437.76200","36.48029","0.03358"
"73030","438.14600","36.51233","0.03338"
"73094","438.53000","36.54432","0.03312"
"73158","438.91400","36.57637","0.03360"
"73222","439.29800","36.60835","0.03392"
"73286","439.68200","36.64034","0.03398"
"73350","440.06600","36.67233","0.03515"
"73414","440.45000","36.70432","0.03479"
"73478","440.83400","36.73636","0.02891"
"73542","441.21800","36.76835","0.02559"
"73606","441.60200","36.80028","0.02467"
"73670","441.98600","36.83232","0.02483"
"73734","442.37000","36.86437","0.02564"
"73798","442.75400","36.89636","0.02461"
"73862","443.13800","36.92829","0.02482"
"73926","443.52200","36.96039","0.02436"
"73990","443.90600","36.99238","0.02373"
"74054","444.29000","37.02425","0.02275"
"74118","444.67400","37.05636","0.02373"
"74182","445.05800","37.08841","0.02379"
"74246","445.44200","37.12033","0.02396"
"74310","445.82600","37.15232","0.02459"
"74374","446.21000","37.18436","0.02442"
"74438","446.59400","37.21635","0.02457"
"74502","446.97800","37.24834","0.02510"
"74566","447.36200","37.28033","0.02514"
"74630","447.74600","37.31232","0.02575"
"74694","448.13000","37.34430","0.02549"
"74758","448.51400","37.37635","0.02564"
"74822","448.89800","37.40834","0.02582"
"74886","449.28200","37.44038","0.02595"
"74950","449.66600","37.47231","0.02623"
"75014","450.05000","37.50430","0.02586"
"75078","450.43400","37.53635","0.02570"
"75142","450.81800","37.56833","0.02572"
"75206","451.20200","37.60027","0.02577"
"75270","451.58600","37.63231","0.02589"
"75334","451.97000","37.66442","0.02641"
"75398","452.35400","37.69628","0.02649"
"75462","452.73800","37.72833","0.02608"
"75526","453.12200","37.76038","0.02661"
"75590","453.50600","37.79230","0.02673"
"75654","453.89000","37.82430","0.02688"
"75718","454.27400","37.85640","0.02765"
"75782","454.65800","37.88833","0.02764"
"75846","455.04200","37.92031","0.02808"
"75910","455.42600","37.95236","0.02799"
"75974","455.81000","37.98429","0.02827"
"76038","456.19400","38.01634","0.02852"
"76102","456.57800","38.04826","0.02862"
"76166","456.96200","38.08031","0.02851"
"76230","457.34600","38.11236","0.02891"
"76294","457.73000","38.14435","0.02898"
"76358","458.11400","38.17633","0.02943"
"76422","458.49800","38.20832","0.02964"
"76486","458.88200","38.24031","0.02936"
"76550","459.26600","38.27230","0.03016"
"76614","459.65000","38.30434","0.03005"
"76678","460.03400","38.33633","0.03032"
"76742","460.41800","38.36826","0.03085"
"76806","460.80200","38.40031","0.03040"
"76870","461.18600","38.43235","0.03045"
"76934","461.57000","38.46434","0.03077"
"76998","461.95400","38.49633","0.03103"
"77062","462.33800","38.52837","0.03091"
"77126","462.72200","38.56036","0.03079"
"77190","463.10600","38.59229","0.03105"
"77254","463.49000","38.62434","0.03083"
"77318","463.87400","38.65638","0.03132"
"77382","464.25800","38.68831","0.03055"
"77446","464.64200","38.72030","0.03066"
"77510","465.02600","38.75241","0.03113"
"77574","465.41000","38.78434","0.03030"
"77638","465.79400","38.81626","0.03074"
"77702","466.17800","38.84837","0.03079"
"77766","466.56200","38.88036","0.03059"
"77830","466.94600","38.91228","0.03104"
"77894","467.33000","38.94433","0.03074"
"77958","467.71400","38.97632","0.03089"
"78022","468.09800","39.00837","0.03111"
"78086","468.48200","39.04029","0.03130"
"78150","468.86600","39.07234","0.03137"
"78214","469.25000","39.10433","0.03200"
"78278","469.63400","39.13632","0.03193"
"78342","470.01800","39.16824","0.03171"
"78406","470.40200","39.20035","0.03179"
"78470","470.78600","39.23233","0.03239"
"78534","471.17000","39.26427","0.03204"
"78598","471.55400","39.29631","0.03193"
"78662","471.93800","39.32836","0.03237"
"78726","472.32200","39.36034","0.03242"
"78790","472.70600","39.39227","0.03219"
"78791","472.71200","39.39281","0.03214"