File: Trajectories_together/161218Specimen_RawData_2.csv
"","V1","V2","V3"
"1","End date","12/18/2016",""
"2","Specimen label","16AT_32",""
"3","Maximum Load","0.01616","N"
"4","Time","Extension","Load"
"5","(s)","(mm)","(N)"
"6","0.00000","0.00000","0.00084"
"76","0.42000","0.03522","0.00228"
"146","0.84000","0.07025","0.00425"
"216","1.26000","0.10523","0.00506"
"286","1.68000","0.14021","0.00587"
"356","2.10000","0.17518","0.00606"
"426","2.52000","0.21022","0.00686"
"496","2.94000","0.24526","0.00711"
"566","3.36000","0.28023","0.00721"
"636","3.78000","0.31515","0.00748"
"706","4.20000","0.35013","0.00746"
"776","4.62000","0.38522","0.00778"
"846","5.04000","0.42020","0.00837"
"916","5.46000","0.45518","0.00809"
"986","5.88000","0.49021","0.00829"
"1056","6.30000","0.52519","0.00816"
"1126","6.72000","0.56017","0.00833"
"1196","7.14000","0.59520","0.00812"
"1266","7.56000","0.63018","0.00822"
"1336","7.98000","0.66516","0.00812"
"1406","8.40000","0.70020","0.00837"
"1476","8.82000","0.73517","0.00832"
"1546","9.24000","0.77015","0.00869"
"1616","9.66000","0.80513","0.00881"
"1686","10.08000","0.84022","0.00879"
"1756","10.50000","0.87520","0.00889"
"1826","10.92000","0.91018","0.00899"
"1896","11.34000","0.94509","0.00930"
"1966","11.76000","0.98019","0.00939"
"2036","12.18000","1.01517","0.00923"
"2106","12.60000","1.05020","0.00951"
"2176","13.02000","1.08512","0.00963"
"2246","13.44000","1.12016","0.00939"
"2316","13.86000","1.15519","0.00968"
"2386","14.28000","1.19023","0.00954"
"2456","14.70000","1.22521","0.00964"
"2526","15.12000","1.26018","0.00985"
"2596","15.54000","1.29516","0.00978"
"2666","15.96000","1.33020","0.00975"
"2736","16.38000","1.36523","0.00998"
"2806","16.80000","1.40015","0.00983"
"2876","17.22000","1.43513","0.01028"
"2946","17.64000","1.47016","0.01013"
"3016","18.06000","1.50520","0.00991"
"3086","18.48000","1.54018","0.01037"
"3156","18.90000","1.57522","0.01040"
"3226","19.32000","1.61013","0.01032"
"3296","19.74000","1.64529","0.01018"
"3366","20.16000","1.68027","0.01024"
"3436","20.58000","1.71524","0.01083"
"3506","21.00000","1.75016","0.00996"
"3576","21.42000","1.78514","0.01028"
"3646","21.84000","1.82023","0.01036"
"3716","22.26000","1.85521","0.01079"
"3786","22.68000","1.89013","0.01082"
"3856","23.10000","1.92516","0.01055"
"3926","23.52000","1.96014","0.01068"
"3996","23.94000","1.99518","0.01089"
"4066","24.36000","2.03021","0.01075"
"4136","24.78000","2.06519","0.01052"
"4206","25.20000","2.10017","0.01102"
"4276","25.62000","2.13520","0.01109"
"4346","26.04000","2.17024","0.01078"
"4416","26.46000","2.20522","0.01091"
"4486","26.88000","2.24013","0.01114"
"4556","27.30000","2.27523","0.01126"
"4626","27.72000","2.31021","0.01081"
"4696","28.14000","2.34518","0.01106"
"4766","28.56000","2.38010","0.01103"
"4836","28.98000","2.41520","0.01076"
"4906","29.40000","2.45017","0.01095"
"4976","29.82000","2.48515","0.01095"
"5046","30.24000","2.52019","0.01134"
"5116","30.66000","2.55517","0.01132"
"5186","31.08000","2.59020","0.01111"
"5256","31.50000","2.62524","0.01116"
"5326","31.92000","2.66022","0.01124"
"5396","32.34000","2.69519","0.01139"
"5466","32.76000","2.73023","0.01136"
"5536","33.18000","2.76515","0.01133"
"5606","33.60000","2.80018","0.01134"
"5676","34.02000","2.83516","0.01128"
"5746","34.44000","2.87014","0.01164"
"5816","34.86000","2.90517","0.01134"
"5886","35.28000","2.94021","0.01165"
"5956","35.70000","2.97519","0.01190"
"6026","36.12000","3.01016","0.01174"
"6096","36.54000","3.04514","0.01169"
"6166","36.96000","3.08024","0.01148"
"6236","37.38000","3.11527","0.01206"
"6306","37.80000","3.15019","0.01192"
"6376","38.22000","3.18517","0.01197"
"6446","38.64000","3.22020","0.01197"
"6516","39.06000","3.25524","0.01183"
"6586","39.48000","3.29022","0.01226"
"6656","39.90000","3.32520","0.01199"
"6726","40.32000","3.36017","0.01183"
"6796","40.74000","3.39521","0.01190"
"6866","41.16000","3.43019","0.01194"
"6936","41.58000","3.46522","0.01202"
"7006","42.00000","3.50014","0.01215"
"7076","42.42000","3.53518","0.01211"
"7146","42.84000","3.57021","0.01219"
"7216","43.26000","3.60525","0.01253"
"7286","43.68000","3.64023","0.01237"
"7356","44.10000","3.67514","0.01246"
"7426","44.52000","3.71024","0.01213"
"7496","44.94000","3.74522","0.01218"
"7566","45.36000","3.78019","0.01293"
"7636","45.78000","3.81517","0.01248"
"7706","46.20000","3.85021","0.01227"
"7776","46.62000","3.88518","0.01239"
"7846","47.04000","3.92016","0.01250"
"7916","47.46000","3.95514","0.01249"
"7986","47.88000","3.99011","0.01316"
"8056","48.30000","4.02521","0.01275"
"8126","48.72000","4.06025","0.01256"
"8196","49.14000","4.09516","0.01295"
"8266","49.56000","4.13014","0.01322"
"8336","49.98000","4.16518","0.01282"
"8406","50.40000","4.20021","0.01306"
"8476","50.82000","4.23519","0.01312"
"8546","51.24000","4.27017","0.01282"
"8616","51.66000","4.30509","0.01349"
"8686","52.08000","4.34012","0.01259"
"8756","52.50000","4.37522","0.01312"
"8826","52.92000","4.41020","0.01269"
"8896","53.34000","4.44517","0.01290"
"8966","53.76000","4.48015","0.01300"
"9036","54.18000","4.51525","0.01254"
"9106","54.60000","4.55022","0.01315"
"9176","55.02000","4.58520","0.01144"
"9246","55.44000","4.62018","0.01130"
"9316","55.86000","4.65521","0.01158"
"9386","56.28000","4.69025","0.01171"
"9456","56.70000","4.72523","0.01162"
"9526","57.12000","4.76014","0.01185"
"9596","57.54000","4.79512","0.01163"
"9666","57.96000","4.83016","0.01184"
"9736","58.38000","4.86519","0.01203"
"9806","58.80000","4.90023","0.01171"
"9876","59.22000","4.93515","0.01203"
"9946","59.64000","4.97018","0.01181"
"10016","60.06000","5.00522","0.01233"
"10086","60.48000","5.04026","0.01189"
"10156","60.90000","5.07517","0.01224"
"10226","61.32000","5.11015","0.01229"
"10296","61.74000","5.14519","0.01237"
"10366","62.16000","5.18023","0.01202"
"10436","62.58000","5.21520","0.01206"
"10506","63.00000","5.25018","0.01204"
"10576","63.42000","5.28516","0.01249"
"10646","63.84000","5.32019","0.01240"
"10716","64.26000","5.35517","0.01228"
"10786","64.68000","5.39015","0.01220"
"10856","65.10000","5.42512","0.01250"
"10926","65.52000","5.46022","0.01251"
"10996","65.94000","5.49526","0.01235"
"11066","66.36000","5.53017","0.01245"
"11136","66.78000","5.56515","0.01234"
"11206","67.20000","5.60019","0.01239"
"11276","67.62000","5.63522","0.01290"
"11346","68.04000","5.67020","0.01210"
"11416","68.46000","5.70518","0.01272"
"11486","68.88000","5.74015","0.01260"
"11556","69.30000","5.77513","0.01277"
"11626","69.72000","5.81023","0.01278"
"11696","70.14000","5.84520","0.01278"
"11766","70.56000","5.88018","0.01252"
"11836","70.98000","5.91516","0.01271"
"11906","71.40000","5.95019","0.01282"
"11976","71.82000","5.98523","0.01297"
"12046","72.24000","6.02021","0.01269"
"12116","72.66000","6.05513","0.01264"
"12186","73.08000","6.09016","0.01257"
"12256","73.50000","6.12520","0.01273"
"12326","73.92000","6.16017","0.01299"
"12396","74.34000","6.19521","0.01285"
"12466","74.76000","6.23019","0.01275"
"12536","75.18000","6.26517","0.01290"
"12606","75.60000","6.30020","0.01284"
"12676","76.02000","6.33518","0.01322"
"12746","76.44000","6.37016","0.01250"
"12816","76.86000","6.40519","0.01274"
"12886","77.28000","6.44017","0.01305"
"12956","77.70000","6.47521","0.01304"
"13026","78.12000","6.51018","0.01257"
"13096","78.54000","6.54510","0.01305"
"13166","78.96000","6.58020","0.01316"
"13236","79.38000","6.61517","0.01315"
"13306","79.80000","6.65021","0.01291"
"13376","80.22000","6.68513","0.01285"
"13446","80.64000","6.72016","0.01260"
"13516","81.06000","6.75520","0.01309"
"13586","81.48000","6.79024","0.01312"
"13656","81.90000","6.82521","0.01290"
"13726","82.32000","6.86013","0.01315"
"13796","82.74000","6.89517","0.01315"
"13866","83.16000","6.93020","0.01307"
"13936","83.58000","6.96518","0.01324"
"14006","84.00000","7.00022","0.01338"
"14076","84.42000","7.03519","0.01324"
"14146","84.84000","7.07023","0.01300"
"14216","85.26000","7.10515","0.01317"
"14286","85.68000","7.14019","0.01343"
"14356","86.10000","7.17516","0.01344"
"14426","86.52000","7.21008","0.01350"
"14496","86.94000","7.24524","0.01295"
"14566","87.36000","7.28021","0.01331"
"14636","87.78000","7.31519","0.01304"
"14706","88.20000","7.35017","0.01309"
"14776","88.62000","7.38520","0.01345"
"14846","89.04000","7.42024","0.01373"
"14916","89.46000","7.45522","0.01328"
"14986","89.88000","7.49013","0.01342"
"15056","90.30000","7.52517","0.01333"
"15126","90.72000","7.56021","0.01356"
"15196","91.14000","7.59512","0.01377"
"15266","91.56000","7.63016","0.01349"
"15336","91.98000","7.66514","0.01335"
"15406","92.40000","7.70018","0.01375"
"15476","92.82000","7.73515","0.01348"
"15546","93.24000","7.77019","0.01358"
"15616","93.66000","7.80517","0.01331"
"15686","94.08000","7.84020","0.01339"
"15756","94.50000","7.87518","0.01392"
"15826","94.92000","7.91021","0.01392"
"15896","95.34000","7.94513","0.01346"
"15966","95.76000","7.98017","0.01356"
"16036","96.18000","8.01521","0.01395"
"16106","96.60000","8.05024","0.01376"
"16176","97.02000","8.08522","0.01418"
"16246","97.44000","8.12014","0.01363"
"16316","97.86000","8.15517","0.01381"
"16386","98.28000","8.19021","0.01374"
"16456","98.70000","8.22525","0.01376"
"16526","99.12000","8.26016","0.01401"
"16596","99.54000","8.29514","0.01378"
"16666","99.96000","8.33018","0.01374"
"16736","100.38000","8.36521","0.01351"
"16806","100.80000","8.40025","0.01361"
"16876","101.22000","8.43517","0.01426"
"16946","101.64000","8.47020","0.01370"
"17016","102.06000","8.50524","0.01374"
"17086","102.48000","8.54016","0.01371"
"17156","102.90000","8.57519","0.01366"
"17226","103.32000","8.61011","0.01395"
"17296","103.74000","8.64515","0.01381"
"17366","104.16000","8.68018","0.01424"
"17436","104.58000","8.71516","0.01401"
"17506","105.00000","8.75020","0.01389"
"17576","105.42000","8.78518","0.01428"
"17646","105.84000","8.82021","0.01397"
"17716","106.26000","8.85519","0.01385"
"17786","106.68000","8.89017","0.01395"
"17856","107.10000","8.92520","0.01377"
"17926","107.52000","8.96018","0.01423"
"17996","107.94000","8.99522","0.01402"
"18066","108.36000","9.03019","0.01462"
"18136","108.78000","9.06517","0.01420"
"18206","109.20000","9.10015","0.01399"
"18276","109.62000","9.13518","0.01411"
"18346","110.04000","9.17022","0.01450"
"18416","110.46000","9.20520","0.01437"
"18486","110.88000","9.24011","0.01451"
"18556","111.30000","9.27515","0.01430"
"18626","111.72000","9.31019","0.01433"
"18696","112.14000","9.34522","0.01413"
"18766","112.56000","9.38020","0.01432"
"18836","112.98000","9.41518","0.01422"
"18906","113.40000","9.45021","0.01447"
"18976","113.82000","9.48519","0.01424"
"19046","114.24000","9.52023","0.01428"
"19116","114.66000","9.55515","0.01454"
"19186","115.08000","9.59018","0.01469"
"19256","115.50000","9.62522","0.01421"
"19326","115.92000","9.66014","0.01458"
"19396","116.34000","9.69517","0.01429"
"19466","116.76000","9.73015","0.01393"
"19536","117.18000","9.76519","0.01458"
"19606","117.60000","9.80022","0.01457"
"19676","118.02000","9.83520","0.01478"
"19746","118.44000","9.87018","0.01402"
"19816","118.86000","9.90515","0.01437"
"19886","119.28000","9.94019","0.01458"
"19956","119.70000","9.97522","0.01454"
"20026","120.12000","10.01014","0.01479"
"20096","120.54000","10.04512","0.01450"
"20166","120.96000","10.08010","0.01464"
"20236","121.38000","10.11519","0.01520"
"20306","121.80000","10.15023","0.01429"
"20376","122.22000","10.18521","0.01458"
"20446","122.64000","10.22018","0.01494"
"20516","123.06000","10.25522","0.01509"
"20586","123.48000","10.29020","0.01473"
"20656","123.90000","10.32523","0.01461"
"20726","124.32000","10.36021","0.01442"
"20796","124.74000","10.39519","0.01465"
"20866","125.16000","10.43022","0.01437"
"20936","125.58000","10.46520","0.01446"
"21006","126.00000","10.50018","0.01480"
"21076","126.42000","10.53515","0.01473"
"21146","126.84000","10.57019","0.01456"
"21216","127.26000","10.60523","0.01466"
"21286","127.68000","10.64020","0.01545"
"21356","128.10000","10.67512","0.01453"
"21426","128.52000","10.71016","0.01492"
"21496","128.94000","10.74520","0.01484"
"21566","129.36000","10.78017","0.01458"
"21636","129.78000","10.81515","0.01473"
"21706","130.20000","10.85019","0.01506"
"21776","130.62000","10.88522","0.01469"
"21846","131.04000","10.92020","0.01493"
"21916","131.46000","10.95518","0.01440"
"21986","131.88000","10.99009","0.01491"
"22056","132.30000","11.02513","0.01478"
"22126","132.72000","11.06017","0.01520"
"22196","133.14000","11.09520","0.01492"
"22266","133.56000","11.13012","0.01499"
"22336","133.98000","11.16510","0.01490"
"22406","134.40000","11.20019","0.01521"
"22476","134.82000","11.23523","0.01537"
"22546","135.24000","11.27021","0.01516"
"22616","135.66000","11.30519","0.01556"
"22686","136.08000","11.34022","0.01533"
"22756","136.50000","11.37520","0.01551"
"22826","136.92000","11.41017","0.01536"
"22896","137.34000","11.44521","0.01530"
"22966","137.76000","11.48013","0.01503"
"23036","138.18000","11.51517","0.01563"
"23106","138.60000","11.55020","0.01513"
"23176","139.02000","11.58524","0.01575"
"23246","139.44000","11.62015","0.01566"
"23316","139.86000","11.65513","0.01571"
"23386","140.28000","11.69023","0.01543"
"23456","140.70000","11.72521","0.01557"
"23526","141.12000","11.76024","0.01583"
"23596","141.54000","11.79516","0.01563"
"23666","141.96000","11.83020","0.01583"
"23736","142.38000","11.86523","0.01530"
"23806","142.80000","11.90021","0.01528"
"23876","143.22000","11.93513","0.01541"
"23946","143.64000","11.97010","0.01557"
"24016","144.06000","12.00520","0.01551"
"24086","144.48000","12.04018","0.01506"
"24156","144.90000","12.07521","0.01527"
"24226","145.32000","12.11019","0.01568"
"24296","145.74000","12.14517","0.01559"
"24366","146.16000","12.18020","0.01490"
"24436","146.58000","12.21518","0.01499"
"24506","147.00000","12.25016","0.01486"
"24576","147.42000","12.28520","0.01491"
"24646","147.84000","12.32023","0.01525"
"24716","148.26000","12.35521","0.01516"
"24786","148.68000","12.39019","0.01534"
"24856","149.10000","12.42510","0.01521"
"24926","149.52000","12.46014","0.01522"
"24996","149.94000","12.49523","0.01543"
"25066","150.36000","12.53021","0.01530"
"25136","150.78000","12.56519","0.01388"
"25206","151.20000","12.60011","0.01400"
"25276","151.62000","12.63520","0.01478"
"25346","152.04000","12.67024","0.01445"
"25416","152.46000","12.70522","0.01392"
"25486","152.88000","12.74019","0.01481"
"25556","153.30000","12.77517","0.01428"
"25626","153.72000","12.81021","0.01456"
"25696","154.14000","12.84524","0.01443"
"25766","154.56000","12.88022","0.01456"
"25836","154.98000","12.91514","0.01463"
"25906","155.40000","12.95017","0.01445"
"25976","155.82000","12.98521","0.01418"
"26046","156.24000","13.02019","0.01446"
"26116","156.66000","13.05516","0.01428"
"26186","157.08000","13.09008","0.01426"
"26256","157.50000","13.12518","0.01433"
"26326","157.92000","13.16021","0.01428"
"26396","158.34000","13.19519","0.01459"
"26466","158.76000","13.23023","0.01470"
"26536","159.18000","13.26520","0.01447"
"26606","159.60000","13.30018","0.01453"
"26676","160.02000","13.33522","0.01416"
"26746","160.44000","13.37014","0.01413"
"26816","160.86000","13.40517","0.01426"
"26886","161.28000","13.44015","0.01412"
"26956","161.70000","13.47525","0.01449"
"27026","162.12000","13.51016","0.01420"
"27096","162.54000","13.54514","0.01383"
"27166","162.96000","13.58018","0.01412"
"27236","163.38000","13.61515","0.01414"
"27306","163.80000","13.65019","0.01447"
"27376","164.22000","13.68517","0.01447"
"27446","164.64000","13.72014","0.01442"
"27516","165.06000","13.75518","0.01444"
"27586","165.48000","13.79022","0.01438"
"27656","165.90000","13.82519","0.01435"
"27726","166.32000","13.86011","0.01445"
"27796","166.74000","13.89515","0.01469"
"27866","167.16000","13.93024","0.01473"
"27936","167.58000","13.96522","0.01482"
"28006","168.00000","14.00014","0.01451"
"28076","168.42000","14.03512","0.01434"
"28146","168.84000","14.07015","0.01463"
"28216","169.26000","14.10525","0.01465"
"28286","169.68000","14.14016","0.01484"
"28356","170.10000","14.17520","0.01477"
"28426","170.52000","14.21024","0.01474"
"28496","170.94000","14.24516","0.01461"
"28566","171.36000","14.28019","0.01468"
"28636","171.78000","14.31517","0.01494"
"28706","172.20000","14.35009","0.01433"
"28776","172.62000","14.38512","0.01476"
"28846","173.04000","14.42022","0.01512"
"28916","173.46000","14.45520","0.01471"
"28986","173.88000","14.49017","0.01339"
"29056","174.30000","14.52515","0.01388"
"29126","174.72000","14.56019","0.01419"
"29196","175.14000","14.59516","0.01342"
"29266","175.56000","14.63026","0.01328"
"29336","175.98000","14.66518","0.01312"
"29406","176.40000","14.70015","0.01346"
"29476","176.82000","14.73525","0.01340"
"29546","177.24000","14.77023","0.01332"
"29616","177.66000","14.80520","0.01294"
"29686","178.08000","14.84018","0.01256"
"29756","178.50000","14.87522","0.01277"
"29826","178.92000","14.91020","0.01310"
"29896","179.34000","14.94523","0.01267"
"29966","179.76000","14.98015","0.01318"
"30036","180.18000","15.01518","0.01305"
"30106","180.60000","15.05022","0.01274"
"30176","181.02000","15.08520","0.01297"
"30246","181.44000","15.12018","0.01251"
"30316","181.86000","15.15515","0.01277"
"30386","182.28000","15.19019","0.01282"
"30456","182.70000","15.22517","0.01307"
"30526","183.12000","15.26020","0.01288"
"30596","183.54000","15.29512","0.01250"
"30666","183.96000","15.33022","0.01318"
"30736","184.38000","15.36519","0.01296"
"30806","184.80000","15.40017","0.01322"
"30876","185.22000","15.43521","0.01330"
"30946","185.64000","15.47018","0.01289"
"31016","186.06000","15.50516","0.01329"
"31086","186.48000","15.54020","0.01251"
"31156","186.90000","15.57523","0.01374"
"31226","187.32000","15.61015","0.01335"
"31296","187.74000","15.64519","0.01364"
"31366","188.16000","15.68022","0.01385"
"31436","188.58000","15.71520","0.01352"
"31506","189.00000","15.75018","0.01377"
"31576","189.42000","15.78509","0.01347"
"31646","189.84000","15.82013","0.01158"
"31716","190.26000","15.85523","0.01146"
"31786","190.68000","15.89020","0.01150"
"31856","191.10000","15.92518","0.01118"
"31926","191.52000","15.96016","0.01127"
"31996","191.94000","15.99520","0.01134"
"32066","192.36000","16.03023","0.01137"
"32136","192.78000","16.06521","0.01146"
"32206","193.20000","16.10019","0.01138"
"32276","193.62000","16.13516","0.01136"
"32346","194.04000","16.17020","0.01131"
"32416","194.46000","16.20518","0.01175"
"32486","194.88000","16.24015","0.01137"
"32556","195.30000","16.27513","0.01171"
"32626","195.72000","16.31017","0.01181"
"32696","196.14000","16.34520","0.01115"
"32766","196.56000","16.38018","0.01133"
"32836","196.98000","16.41516","0.01186"
"32906","197.40000","16.45019","0.01175"
"32976","197.82000","16.48517","0.01154"
"33046","198.24000","16.52021","0.01180"
"33116","198.66000","16.55524","0.01158"
"33186","199.08000","16.59016","0.01148"
"33256","199.50000","16.62520","0.01189"
"33326","199.92000","16.66017","0.01153"
"33396","200.34000","16.69521","0.01161"
"33466","200.76000","16.73013","0.01164"
"33536","201.18000","16.76516","0.01162"
"33606","201.60000","16.80020","0.01171"
"33676","202.02000","16.83518","0.01181"
"33746","202.44000","16.87015","0.01202"
"33816","202.86000","16.90513","0.01155"
"33886","203.28000","16.94023","0.01187"
"33956","203.70000","16.97520","0.01198"
"34026","204.12000","17.01024","0.01145"
"34096","204.54000","17.04522","0.01149"
"34166","204.96000","17.08019","0.01187"
"34236","205.38000","17.11523","0.01220"
"34306","205.80000","17.15021","0.01153"
"34376","206.22000","17.18518","0.01192"
"34446","206.64000","17.22010","0.01189"
"34516","207.06000","17.25514","0.01205"
"34586","207.48000","17.29024","0.01162"
"34656","207.90000","17.32521","0.01198"
"34726","208.32000","17.36019","0.01216"
"34796","208.74000","17.39517","0.01178"
"34866","209.16000","17.43026","0.01245"
"34936","209.58000","17.46524","0.01228"
"35006","210.00000","17.50022","0.01230"
"35076","210.42000","17.53519","0.01204"
"35146","210.84000","17.57011","0.01213"
"35216","211.26000","17.60521","0.01213"
"35286","211.68000","17.64024","0.01238"
"35356","212.10000","17.67516","0.01239"
"35426","212.52000","17.71014","0.01214"
"35496","212.94000","17.74517","0.01241"
"35566","213.36000","17.78015","0.01220"
"35636","213.78000","17.81519","0.01228"
"35706","214.20000","17.85011","0.01234"
"35776","214.62000","17.88520","0.01247"
"35846","215.04000","17.92018","0.01216"
"35916","215.46000","17.95522","0.01271"
"35986","215.88000","17.99019","0.01257"
"36056","216.30000","18.02517","0.01252"
"36126","216.72000","18.06021","0.01291"
"36196","217.14000","18.09518","0.01240"
"36266","217.56000","18.13022","0.01238"
"36336","217.98000","18.16514","0.01281"
"36406","218.40000","18.20017","0.01241"
"36476","218.82000","18.23521","0.01262"
"36546","219.24000","18.27019","0.01248"
"36616","219.66000","18.30516","0.01279"
"36686","220.08000","18.34014","0.01281"
"36756","220.50000","18.37518","0.01283"
"36826","220.92000","18.41021","0.01295"
"36896","221.34000","18.44519","0.01222"
"36966","221.76000","18.48023","0.01295"
"37036","222.18000","18.51521","0.01256"
"37106","222.60000","18.55018","0.01298"
"37176","223.02000","18.58522","0.01309"
"37246","223.44000","18.62020","0.01316"
"37316","223.86000","18.65511","0.01305"
"37386","224.28000","18.69015","0.01288"
"37456","224.70000","18.72519","0.01300"
"37526","225.12000","18.76016","0.01297"
"37596","225.54000","18.79514","0.01262"
"37666","225.96000","18.83011","0.01315"
"37736","226.38000","18.86521","0.01306"
"37806","226.80000","18.90019","0.01338"
"37876","227.22000","18.93523","0.01335"
"37946","227.64000","18.97014","0.01315"
"38016","228.06000","19.00512","0.01293"
"38086","228.48000","19.04022","0.01334"
"38156","228.90000","19.07519","0.01301"
"38226","229.32000","19.11017","0.01310"
"38296","229.74000","19.14509","0.01278"
"38366","230.16000","19.18018","0.01281"
"38436","230.58000","19.21516","0.01198"
"38506","231.00000","19.25020","0.01186"
"38576","231.42000","19.28517","0.01250"
"38646","231.84000","19.32015","0.01216"
"38716","232.26000","19.35519","0.01227"
"38786","232.68000","19.39022","0.01107"
"38856","233.10000","19.42520","0.01103"
"38926","233.52000","19.46018","0.01143"
"38996","233.94000","19.49521","0.01129"
"39066","234.36000","19.53019","0.01113"
"39136","234.78000","19.56523","0.01197"
"39206","235.20000","19.60015","0.01119"
"39276","235.62000","19.63518","0.01134"
"39346","236.04000","19.67022","0.01122"
"39416","236.46000","19.70519","0.01172"
"39486","236.88000","19.74017","0.01132"
"39556","237.30000","19.77509","0.01162"
"39626","237.72000","19.81018","0.01128"
"39696","238.14000","19.84522","0.01130"
"39766","238.56000","19.88020","0.01149"
"39836","238.98000","19.91518","0.01126"
"39906","239.40000","19.95021","0.01119"
"39976","239.82000","19.98519","0.01126"
"40046","240.24000","20.02022","0.01129"
"40116","240.66000","20.05514","0.01147"
"40186","241.08000","20.09012","0.01156"
"40256","241.50000","20.12516","0.01126"
"40326","241.92000","20.16019","0.01148"
"40396","242.34000","20.19523","0.01128"
"40466","242.76000","20.23015","0.01143"
"40536","243.18000","20.26518","0.01134"
"40606","243.60000","20.30022","0.01131"
"40676","244.02000","20.33520","0.01142"
"40746","244.44000","20.37023","0.01158"
"40816","244.86000","20.40515","0.01120"
"40886","245.28000","20.44019","0.01177"
"40956","245.70000","20.47522","0.01155"
"41026","246.12000","20.51020","0.01131"
"41096","246.54000","20.54512","0.01132"
"41166","246.96000","20.58015","0.01135"
"41236","247.38000","20.61519","0.01162"
"41306","247.80000","20.65017","0.01146"
"41376","248.22000","20.68521","0.01129"
"41446","248.64000","20.72012","0.01123"
"41516","249.06000","20.75516","0.01163"
"41586","249.48000","20.79014","0.01115"
"41656","249.90000","20.82523","0.01163"
"41726","250.32000","20.86021","0.01157"
"41796","250.74000","20.89513","0.01092"
"41866","251.16000","20.93016","0.01150"
"41936","251.58000","20.96520","0.01192"
"42006","252.00000","21.00024","0.01130"
"42076","252.42000","21.03515","0.01182"
"42146","252.84000","21.07013","0.01159"
"42216","253.26000","21.10517","0.01179"
"42286","253.68000","21.14014","0.01146"
"42356","254.10000","21.17518","0.01115"
"42426","254.52000","21.21016","0.01173"
"42496","254.94000","21.24519","0.01141"
"42566","255.36000","21.28023","0.01135"
"42636","255.78000","21.31521","0.01132"
"42706","256.20000","21.35012","0.01124"
"42776","256.62000","21.38522","0.01124"
"42846","257.04000","21.42020","0.01144"
"42916","257.46000","21.45523","0.01158"
"42986","257.88000","21.49015","0.01163"
"43056","258.30000","21.52513","0.01142"
"43126","258.72000","21.56017","0.01133"
"43196","259.14000","21.59520","0.01150"
"43266","259.56000","21.63018","0.01134"
"43336","259.98000","21.66521","0.01146"
"43406","260.40000","21.70019","0.01123"
"43476","260.82000","21.73523","0.01138"
"43546","261.24000","21.77021","0.01179"
"43616","261.66000","21.80524","0.01133"
"43686","262.08000","21.84016","0.01164"
"43756","262.50000","21.87519","0.01138"
"43826","262.92000","21.91023","0.01162"
"43896","263.34000","21.94521","0.01123"
"43966","263.76000","21.98018","0.01141"
"44036","264.18000","22.01516","0.01187"
"44106","264.60000","22.05014","0.01162"
"44176","265.02000","22.08518","0.01190"
"44246","265.44000","22.12021","0.01141"
"44316","265.86000","22.15513","0.01139"
"44386","266.28000","22.19011","0.01149"
"44456","266.70000","22.22520","0.01146"
"44526","267.12000","22.26024","0.01169"
"44596","267.54000","22.29516","0.01156"
"44666","267.96000","22.33014","0.01130"
"44736","268.38000","22.36517","0.01134"
"44806","268.80000","22.40021","0.01176"
"44876","269.22000","22.43519","0.01141"
"44946","269.64000","22.47010","0.01152"
"45016","270.06000","22.50520","0.01165"
"45086","270.48000","22.54018","0.01147"
"45156","270.90000","22.57521","0.01162"
"45226","271.32000","22.61019","0.01142"
"45296","271.74000","22.64517","0.01155"
"45366","272.16000","22.68014","0.01158"
"45436","272.58000","22.71524","0.01153"
"45506","273.00000","22.75022","0.01157"
"45576","273.42000","22.78519","0.01161"
"45646","273.84000","22.82023","0.01129"
"45716","274.26000","22.85521","0.01152"
"45786","274.68000","22.89018","0.01136"
"45856","275.10000","22.92522","0.01166"
"45926","275.52000","22.96014","0.01149"
"45996","275.94000","22.99511","0.01164"
"46066","276.36000","23.03021","0.01139"
"46136","276.78000","23.06519","0.01181"
"46206","277.20000","23.10016","0.01152"
"46276","277.62000","23.13514","0.01116"
"46346","278.04000","23.17024","0.01149"
"46416","278.46000","23.20522","0.01184"
"46486","278.88000","23.24019","0.01189"
"46556","279.30000","23.27511","0.01175"
"46626","279.72000","23.31014","0.01184"
"46696","280.14000","23.34524","0.01159"
"46766","280.56000","23.38022","0.01189"
"46836","280.98000","23.41514","0.01167"
"46906","281.40000","23.45011","0.01172"
"46976","281.82000","23.48515","0.01179"
"47046","282.24000","23.52019","0.01170"
"47116","282.66000","23.55522","0.01158"
"47186","283.08000","23.59020","0.01177"
"47256","283.50000","23.62518","0.01195"
"47326","283.92000","23.66015","0.01200"
"47396","284.34000","23.69519","0.01158"
"47466","284.76000","23.73017","0.01166"
"47536","285.18000","23.76514","0.01161"
"47606","285.60000","23.80024","0.01202"
"47676","286.02000","23.83522","0.01166"
"47746","286.44000","23.87019","0.01140"
"47816","286.86000","23.90517","0.01179"
"47886","287.28000","23.94015","0.01171"
"47956","287.70000","23.97518","0.01191"
"48026","288.12000","24.01016","0.01185"
"48096","288.54000","24.04520","0.01164"
"48166","288.96000","24.08017","0.01129"
"48236","289.38000","24.11521","0.01123"
"48306","289.80000","24.15019","0.01168"
"48376","290.22000","24.18516","0.01163"
"48446","290.64000","24.22020","0.01162"
"48516","291.06000","24.25518","0.01176"
"48586","291.48000","24.29021","0.01160"
"48656","291.90000","24.32519","0.01142"
"48726","292.32000","24.36017","0.01189"
"48796","292.74000","24.39515","0.01141"
"48866","293.16000","24.43018","0.01159"
"48936","293.58000","24.46522","0.01192"
"49006","294.00000","24.50019","0.01127"
"49076","294.42000","24.53517","0.01155"
"49146","294.84000","24.57015","0.01164"
"49216","295.26000","24.60519","0.01153"
"49286","295.68000","24.64022","0.01159"
"49356","296.10000","24.67520","0.01164"
"49426","296.52000","24.71018","0.01174"
"49496","296.94000","24.74516","0.01167"
"49566","297.36000","24.78025","0.01147"
"49636","297.78000","24.81523","0.01130"
"49706","298.20000","24.85015","0.01161"
"49776","298.62000","24.88512","0.01159"
"49846","299.04000","24.92016","0.01134"
"49916","299.46000","24.95513","0.01156"
"49986","299.88000","24.99017","0.01166"
"50056","300.30000","25.02515","0.01156"
"50126","300.72000","25.06019","0.01135"
"50196","301.14000","25.09516","0.01153"
"50266","301.56000","25.13020","0.01119"
"50336","301.98000","25.16517","0.01175"
"50406","302.40000","25.20015","0.01137"
"50476","302.82000","25.23519","0.01179"
"50546","303.24000","25.27023","0.01168"
"50616","303.66000","25.30520","0.01158"
"50686","304.08000","25.34018","0.01189"
"50756","304.50000","25.37516","0.01165"
"50826","304.92000","25.41019","0.01170"
"50896","305.34000","25.44517","0.01169"
"50966","305.76000","25.48015","0.01169"
"51036","306.18000","25.51512","0.01130"
"51106","306.60000","25.55016","0.01167"
"51176","307.02000","25.58526","0.01135"
"51246","307.44000","25.62024","0.01157"
"51316","307.86000","25.65515","0.01195"
"51386","308.28000","25.69019","0.01143"
"51456","308.70000","25.72516","0.01126"
"51526","309.12000","25.76020","0.01129"
"51596","309.54000","25.79518","0.01121"
"51666","309.96000","25.83009","0.01085"
"51736","310.38000","25.86513","0.01130"
"51806","310.80000","25.90023","0.01139"
"51876","311.22000","25.93521","0.01138"
"51946","311.64000","25.97018","0.01147"
"52016","312.06000","26.00516","0.01150"
"52086","312.48000","26.04020","0.01135"
"52156","312.90000","26.07517","0.01122"
"52226","313.32000","26.11021","0.01152"
"52296","313.74000","26.14519","0.01177"
"52366","314.16000","26.18016","0.01135"
"52436","314.58000","26.21526","0.01184"
"52506","315.00000","26.25018","0.01134"
"52576","315.42000","26.28515","0.01155"
"52646","315.84000","26.32013","0.01147"
"52716","316.26000","26.35517","0.01146"
"52786","316.68000","26.39014","0.01144"
"52856","317.10000","26.42518","0.01177"
"52926","317.52000","26.46010","0.01195"
"52996","317.94000","26.49513","0.01128"
"53066","318.36000","26.53017","0.01149"
"53136","318.78000","26.56521","0.01150"
"53206","319.20000","26.60018","0.01126"
"53276","319.62000","26.63510","0.01140"
"53346","320.04000","26.67020","0.01135"
"53416","320.46000","26.70517","0.01153"
"53486","320.88000","26.74021","0.01165"
"53556","321.30000","26.77513","0.01162"
"53626","321.72000","26.81017","0.01169"
"53696","322.14000","26.84520","0.01166"
"53766","322.56000","26.88018","0.01154"
"53836","322.98000","26.91516","0.01147"
"53906","323.40000","26.95013","0.01149"
"53976","323.82000","26.98517","0.01178"
"54046","324.24000","27.02020","0.01169"
"54116","324.66000","27.05518","0.01137"
"54186","325.08000","27.09016","0.01179"
"54256","325.50000","27.12520","0.01169"
"54326","325.92000","27.16023","0.01179"
"54396","326.34000","27.19521","0.01157"
"54466","326.76000","27.23019","0.01196"
"54536","327.18000","27.26517","0.01179"
"54606","327.60000","27.30014","0.01160"
"54676","328.02000","27.33518","0.01188"
"54746","328.44000","27.37021","0.01134"
"54816","328.86000","27.40519","0.01201"
"54886","329.28000","27.44017","0.01183"
"54956","329.70000","27.47520","0.01188"
"55026","330.12000","27.51018","0.01168"
"55096","330.54000","27.54522","0.01211"
"55166","330.96000","27.58020","0.01212"
"55236","331.38000","27.61517","0.01181"
"55306","331.80000","27.65021","0.01182"
"55376","332.22000","27.68518","0.01191"
"55446","332.64000","27.72022","0.01197"
"55516","333.06000","27.75514","0.01235"
"55586","333.48000","27.79017","0.01192"
"55656","333.90000","27.82521","0.01222"
"55726","334.32000","27.86019","0.01201"
"55796","334.74000","27.89517","0.01203"
"55866","335.16000","27.93020","0.01202"
"55936","335.58000","27.96518","0.01192"
"56006","336.00000","28.00016","0.01068"
"56076","336.42000","28.03513","0.01070"
"56146","336.84000","28.07017","0.01068"
"56216","337.26000","28.10521","0.01084"
"56286","337.68000","28.14018","0.01050"
"56356","338.10000","28.17522","0.01060"
"56426","338.52000","28.21014","0.01008"
"56496","338.94000","28.24517","0.01077"
"56566","339.36000","28.28015","0.01069"
"56636","339.78000","28.31519","0.01049"
"56706","340.20000","28.35022","0.01096"
"56776","340.62000","28.38514","0.01083"
"56846","341.04000","28.42018","0.01067"
"56916","341.46000","28.45521","0.01074"
"56986","341.88000","28.49019","0.01043"
"57056","342.30000","28.52523","0.01061"
"57126","342.72000","28.56021","0.01059"
"57196","343.14000","28.59524","0.01035"
"57266","343.56000","28.63022","0.01049"
"57336","343.98000","28.66520","0.01086"
"57406","344.40000","28.70011","0.01057"
"57476","344.82000","28.73515","0.01055"
"57546","345.24000","28.77018","0.01057"
"57616","345.66000","28.80522","0.01097"
"57686","346.08000","28.84020","0.01053"
"57756","346.50000","28.87518","0.01051"
"57826","346.92000","28.91015","0.01082"
"57896","347.34000","28.94519","0.01081"
"57966","347.76000","28.98022","0.01057"
"58036","348.18000","29.01514","0.01028"
"58106","348.60000","29.05018","0.01080"
"58176","349.02000","29.08521","0.01063"
"58246","349.44000","29.12025","0.01084"
"58316","349.86000","29.15517","0.01050"
"58386","350.28000","29.19015","0.01047"
"58456","350.70000","29.22518","0.01042"
"58526","351.12000","29.26016","0.01050"
"58596","351.54000","29.29520","0.01069"
"58666","351.96000","29.33018","0.01040"
"58736","352.38000","29.36515","0.01052"
"58806","352.80000","29.40019","0.01079"
"58876","353.22000","29.43517","0.01064"
"58946","353.64000","29.47014","0.01045"
"59016","354.06000","29.50512","0.01098"
"59086","354.48000","29.54021","0.01051"
"59156","354.90000","29.57525","0.01083"
"59226","355.32000","29.61023","0.01067"
"59296","355.74000","29.64515","0.01057"
"59366","356.16000","29.68018","0.01078"
"59436","356.58000","29.71516","0.01073"
"59506","357.00000","29.75026","0.01085"
"59576","357.42000","29.78518","0.01062"
"59646","357.84000","29.82015","0.01108"
"59716","358.26000","29.85519","0.01063"
"59786","358.68000","29.89028","0.01051"
"59856","359.10000","29.92520","0.01073"
"59926","359.52000","29.96018","0.01084"
"59996","359.94000","29.99521","0.01061"
"60066","360.36000","30.03019","0.01053"
"60136","360.78000","30.06523","0.01049"
"60206","361.20000","30.10015","0.01059"
"60276","361.62000","30.13506","0.01088"
"60346","362.04000","30.17016","0.01078"
"60416","362.46000","30.20519","0.01091"
"60486","362.88000","30.24017","0.01058"
"60556","363.30000","30.27521","0.01046"
"60626","363.72000","30.31013","0.01076"
"60696","364.14000","30.34522","0.01050"
"60766","364.56000","30.38020","0.01083"
"60836","364.98000","30.41524","0.01064"
"60906","365.40000","30.45021","0.01057"
"60976","365.82000","30.48519","0.01074"
"61046","366.24000","30.52023","0.01050"
"61116","366.66000","30.55520","0.01046"
"61186","367.08000","30.59018","0.01074"
"61256","367.50000","30.62515","0.01037"
"61326","367.92000","30.66019","0.01074"
"61396","368.34000","30.69523","0.01078"
"61466","368.76000","30.73021","0.01054"
"61536","369.18000","30.76512","0.01068"
"61606","369.60000","30.80016","0.01102"
"61676","370.02000","30.83520","0.01069"
"61746","370.44000","30.87017","0.01064"
"61816","370.86000","30.90521","0.01107"
"61886","371.28000","30.94019","0.01040"
"61956","371.70000","30.97522","0.01089"
"62026","372.12000","31.01020","0.01044"
"62096","372.54000","31.04518","0.01075"
"62166","372.96000","31.08015","0.01060"
"62236","373.38000","31.11513","0.01063"
"62306","373.80000","31.15023","0.01058"
"62376","374.22000","31.18515","0.01061"
"62446","374.64000","31.22018","0.01069"
"62516","375.06000","31.25510","0.01053"
"62586","375.48000","31.29019","0.01075"
"62656","375.90000","31.32523","0.01039"
"62726","376.32000","31.36021","0.01086"
"62796","376.74000","31.39519","0.01086"
"62866","377.16000","31.43022","0.01053"
"62936","377.58000","31.46520","0.01084"
"63006","378.00000","31.50018","0.01079"
"63076","378.42000","31.53521","0.01097"
"63146","378.84000","31.57013","0.01036"
"63216","379.26000","31.60511","0.01019"
"63286","379.68000","31.64020","0.01073"
"63356","380.10000","31.67518","0.01052"
"63426","380.52000","31.71021","0.01102"
"63496","380.94000","31.74513","0.01053"
"63566","381.36000","31.78023","0.01062"
"63636","381.78000","31.81520","0.01075"
"63706","382.20000","31.85024","0.01057"
"63776","382.62000","31.88516","0.01068"
"63846","383.04000","31.92019","0.01087"
"63916","383.46000","31.95523","0.01068"
"63986","383.88000","31.99021","0.01063"
"64056","384.30000","32.02519","0.01093"
"64126","384.72000","32.06017","0.01092"
"64196","385.14000","32.09520","0.01054"
"64266","385.56000","32.13018","0.01066"
"64336","385.98000","32.16521","0.01057"
"64406","386.40000","32.20013","0.01069"
"64476","386.82000","32.23517","0.01072"
"64546","387.24000","32.27015","0.01041"
"64616","387.66000","32.30518","0.01074"
"64686","388.08000","32.34016","0.01055"
"64756","388.50000","32.37519","0.01073"
"64826","388.92000","32.41023","0.01070"
"64896","389.34000","32.44521","0.01052"
"64966","389.76000","32.48018","0.01073"
"65036","390.18000","32.51516","0.01059"
"65106","390.60000","32.55014","0.01023"
"65176","391.02000","32.58517","0.01058"
"65246","391.44000","32.62015","0.01070"
"65316","391.86000","32.65513","0.01054"
"65386","392.28000","32.69011","0.01078"
"65456","392.70000","32.72520","0.01091"
"65526","393.12000","32.76024","0.01081"
"65596","393.54000","32.79522","0.01065"
"65666","393.96000","32.83019","0.01098"
"65736","394.38000","32.86517","0.01040"
"65806","394.80000","32.90021","0.01062"
"65876","395.22000","32.93524","0.01064"
"65946","395.64000","32.97016","0.01051"
"66016","396.06000","33.00514","0.01058"
"66086","396.48000","33.04012","0.01075"
"66156","396.90000","33.07521","0.01085"
"66226","397.32000","33.11024","0.01071"
"66296","397.74000","33.14516","0.01100"
"66366","398.16000","33.18014","0.01112"
"66436","398.58000","33.21518","0.01115"
"66506","399.00000","33.25021","0.01063"
"66576","399.42000","33.28519","0.01092"
"66646","399.84000","33.32017","0.01027"
"66716","400.26000","33.35515","0.01073"
"66786","400.68000","33.39024","0.01076"
"66856","401.10000","33.42522","0.01046"
"66926","401.52000","33.46014","0.01079"
"66996","401.94000","33.49511","0.01122"
"67066","402.36000","33.53015","0.01081"
"67136","402.78000","33.56519","0.01082"
"67206","403.20000","33.60022","0.01093"
"67276","403.62000","33.63514","0.01075"
"67346","404.04000","33.67018","0.01109"
"67416","404.46000","33.70521","0.01071"
"67486","404.88000","33.74019","0.01049"
"67556","405.30000","33.77523","0.01047"
"67626","405.72000","33.81014","0.01079"
"67696","406.14000","33.84518","0.01095"
"67766","406.56000","33.88021","0.01067"
"67836","406.98000","33.91519","0.01117"
"67906","407.40000","33.95011","0.01095"
"67976","407.82000","33.98515","0.01080"
"68046","408.24000","34.02019","0.01104"
"68116","408.66000","34.05522","0.01097"
"68186","409.08000","34.09014","0.01047"
"68256","409.50000","34.12511","0.01082"
"68326","409.92000","34.16021","0.01078"
"68396","410.34000","34.19525","0.01062"
"68466","410.76000","34.23022","0.01070"
"68536","411.18000","34.26520","0.01059"
"68606","411.60000","34.30018","0.01102"
"68676","412.02000","34.33522","0.01080"
"68746","412.44000","34.37019","0.01090"
"68816","412.86000","34.40517","0.01060"
"68886","413.28000","34.44014","0.01090"
"68956","413.70000","34.47512","0.01123"
"69026","414.12000","34.51022","0.01104"
"69096","414.54000","34.54519","0.01061"
"69166","414.96000","34.58011","0.01111"
"69236","415.38000","34.61509","0.01071"
"69306","415.80000","34.65019","0.01023"
"69376","416.22000","34.68522","0.01110"
"69446","416.64000","34.72020","0.01064"
"69516","417.06000","34.75518","0.01064"
"69586","417.48000","34.79015","0.01081"
"69656","417.90000","34.82519","0.01041"
"69726","418.32000","34.86023","0.01057"
"69796","418.74000","34.89515","0.01054"
"69866","419.16000","34.93012","0.01068"
"69936","419.58000","34.96516","0.01055"
"70006","420.00000","35.00019","0.01069"
"70076","420.42000","35.03523","0.01064"
"70146","420.84000","35.07015","0.01036"
"70216","421.26000","35.10518","0.01102"
"70286","421.68000","35.14016","0.01066"
"70356","422.10000","35.17520","0.01076"
"70426","422.52000","35.21017","0.01085"
"70496","422.94000","35.24521","0.01057"
"70566","423.36000","35.28019","0.01065"
"70636","423.78000","35.31523","0.01065"
"70706","424.20000","35.35020","0.01058"
"70776","424.62000","35.38512","0.01096"
"70846","425.04000","35.42010","0.01068"
"70916","425.46000","35.45519","0.01081"
"70986","425.88000","35.49017","0.01068"
"71056","426.30000","35.52515","0.01054"
"71126","426.72000","35.56012","0.01091"
"71196","427.14000","35.59516","0.01070"
"71266","427.56000","35.63020","0.01078"
"71336","427.98000","35.66517","0.01080"
"71406","428.40000","35.70021","0.01106"
"71476","428.82000","35.73519","0.01095"
"71546","429.24000","35.77016","0.01073"
"71616","429.66000","35.80520","0.01074"
"71686","430.08000","35.84018","0.01065"
"71756","430.50000","35.87509","0.01082"
"71826","430.92000","35.91013","0.01093"
"71896","431.34000","35.94523","0.01049"
"71966","431.76000","35.98021","0.01056"
"72036","432.18000","36.01518","0.01069"
"72106","432.60000","36.05016","0.01093"
"72176","433.02000","36.08520","0.01094"
"72246","433.44000","36.12017","0.01042"
"72316","433.86000","36.15521","0.01076"
"72386","434.28000","36.19019","0.01047"
"72456","434.70000","36.22522","0.01064"
"72526","435.12000","36.26026","0.01072"
"72596","435.54000","36.29523","0.01058"
"72666","435.96000","36.33015","0.01067"
"72736","436.38000","36.36513","0.01092"
"72806","436.80000","36.40023","0.01067"
"72876","437.22000","36.43520","0.01057"
"72946","437.64000","36.47018","0.01068"
"73016","438.06000","36.50515","0.01102"
"73086","438.48000","36.54020","0.01114"
"73156","438.90000","36.57523","0.01077"
"73226","439.32000","36.61021","0.01064"
"73296","439.74000","36.64518","0.01071"
"73366","440.16000","36.68016","0.01104"
"73436","440.58000","36.71520","0.01091"
"73506","441.00000","36.75024","0.01055"
"73576","441.42000","36.78521","0.01089"
"73646","441.84000","36.82013","0.01076"
"73716","442.26000","36.85516","0.01055"
"73786","442.68000","36.89020","0.01047"
"73856","443.10000","36.92518","0.01076"
"73926","443.52000","36.96016","0.01099"
"73996","443.94000","36.99513","0.01051"
"74066","444.36000","37.03017","0.01046"
"74136","444.78000","37.06527","0.01062"
"74206","445.20000","37.10018","0.01080"
"74276","445.62000","37.13522","0.01095"
"74346","446.04000","37.17014","0.01104"
"74416","446.46000","37.20517","0.01088"
"74486","446.88000","37.24021","0.01057"
"74556","447.30000","37.27519","0.01063"
"74626","447.72000","37.31010","0.01050"
"74696","448.14000","37.34514","0.01112"
"74766","448.56000","37.38018","0.01092"
"74836","448.98000","37.41521","0.01081"
"74906","449.40000","37.45019","0.01079"
"74976","449.82000","37.48511","0.01119"
"75046","450.24000","37.52020","0.01077"
"75116","450.66000","37.55518","0.01090"
"75186","451.08000","37.59022","0.01079"
"75256","451.50000","37.62519","0.01078"
"75326","451.92000","37.66017","0.01071"
"75396","452.34000","37.69521","0.01052"
"75466","452.76000","37.73018","0.01071"
"75536","453.18000","37.76516","0.01056"
"75606","453.60000","37.80014","0.01054"
"75676","454.02000","37.83518","0.01082"
"75746","454.44000","37.87021","0.01073"
"75816","454.86000","37.90519","0.01055"
"75886","455.28000","37.94017","0.01063"
"75956","455.70000","37.97514","0.01056"
"76026","456.12000","38.01018","0.01053"
"76096","456.54000","38.04522","0.01099"
"76166","456.96000","38.08019","0.01051"
"76236","457.38000","38.11511","0.01084"
"76306","457.80000","38.15015","0.01109"
"76376","458.22000","38.18524","0.01093"
"76446","458.64000","38.22022","0.01049"
"76516","459.06000","38.25520","0.01096"
"76586","459.48000","38.29017","0.01065"
"76656","459.90000","38.32515","0.01066"
"76726","460.32000","38.36019","0.01079"
"76796","460.74000","38.39516","0.01054"
"76866","461.16000","38.43014","0.01095"
"76936","461.58000","38.46518","0.01081"
"77006","462.00000","38.50022","0.01035"
"77076","462.42000","38.53519","0.01059"
"77146","462.84000","38.57017","0.01083"
"77216","463.26000","38.60521","0.01044"
"77286","463.68000","38.64018","0.01058"
"77356","464.10000","38.67522","0.01050"
"77426","464.52000","38.71020","0.01055"
"77496","464.94000","38.74511","0.01072"
"77566","465.36000","38.78015","0.01079"
"77636","465.78000","38.81525","0.01065"
"77706","466.20000","38.85016","0.01048"
"77776","466.62000","38.88520","0.01076"
"77846","467.04000","38.92012","0.01096"
"77916","467.46000","38.95521","0.01041"
"77986","467.88000","38.99025","0.01051"
"78056","468.30000","39.02523","0.01093"
"78126","468.72000","39.06020","0.01069"
"78196","469.14000","39.09512","0.01055"
"78266","469.56000","39.13022","0.01093"
"78336","469.98000","39.16525","0.01103"
"78406","470.40000","39.20017","0.01055"
"78476","470.82000","39.23515","0.01064"
"78546","471.24000","39.27013","0.01071"
"78616","471.66000","39.30516","0.01089"
"78686","472.08000","39.34020","0.01058"
"78756","472.50000","39.37511","0.01118"
"78826","472.92000","39.41015","0.01069"
"78896","473.34000","39.44518","0.01083"
"78966","473.76000","39.48016","0.01097"
"79036","474.18000","39.51520","0.01074"
"79106","474.60000","39.55018","0.01092"
"79176","475.02000","39.58521","0.01082"
"79246","475.44000","39.62025","0.01075"
"79316","475.86000","39.65523","0.01077"
"79386","476.28000","39.69014","0.01079"
"79456","476.70000","39.72512","0.01113"
"79526","477.12000","39.76022","0.01109"
"79596","477.54000","39.79519","0.01079"
"79666","477.96000","39.83012","0.01095"
"79736","478.38000","39.86515","0.01094"
"79806","478.80000","39.90019","0.01076"
"79876","479.22000","39.93522","0.01086"
"79946","479.64000","39.97020","0.01123"
"80016","480.06000","40.00518","0.01110"
"80086","480.48000","40.04021","0.01104"
"80156","480.90000","40.07519","0.01082"
"80226","481.32000","40.11022","0.01087"
"80296","481.74000","40.14520","0.01072"
"80366","482.16000","40.18012","0.01043"
"80436","482.58000","40.21516","0.01117"
"80506","483.00000","40.25019","0.01056"
"80576","483.42000","40.28517","0.01052"
"80646","483.84000","40.32014","0.01071"
"80716","484.26000","40.35513","0.01054"
"80786","484.68000","40.39022","0.01082"
"80856","485.10000","40.42520","0.01084"
"80926","485.52000","40.46023","0.01058"
"80996","485.94000","40.49516","0.01078"
"81066","486.36000","40.53013","0.01039"
"81136","486.78000","40.56528","0.01064"
"81206","487.20000","40.60020","0.01040"
"81276","487.62000","40.63518","0.01065"
"81346","488.04000","40.67010","0.01066"
"81416","488.46000","40.70519","0.01056"
"81486","488.88000","40.74017","0.01106"
"81556","489.30000","40.77521","0.01064"
"81626","489.72000","40.81018","0.01094"
"81696","490.14000","40.84516","0.01079"
"81766","490.56000","40.88020","0.01066"
"81836","490.98000","40.91523","0.01082"
"81906","491.40000","40.95021","0.01077"
"81976","491.82000","40.98513","0.01032"
"82046","492.24000","41.02022","0.01083"
"82116","492.66000","41.05520","0.01059"
"82186","493.08000","41.09024","0.01053"
"82256","493.50000","41.12516","0.01052"
"82326","493.92000","41.16013","0.01063"
"82396","494.34000","41.19517","0.01062"
"82466","494.76000","41.23021","0.01073"
"82536","495.18000","41.26518","0.01090"
"82606","495.60000","41.30010","0.01106"
"82676","496.02000","41.33514","0.01089"
"82746","496.44000","41.37017","0.01080"
"82816","496.86000","41.40521","0.01078"
"82886","497.28000","41.44012","0.01080"
"82956","497.70000","41.47516","0.01068"
"83026","498.12000","41.51020","0.01093"
"83096","498.54000","41.54523","0.01035"
"83166","498.96000","41.58021","0.01083"
"83236","499.38000","41.61513","0.01048"
"83306","499.80000","41.65017","0.01064"
"83376","500.22000","41.68520","0.01102"
"83446","500.64000","41.72018","0.01069"
"83516","501.06000","41.75516","0.01051"
"83586","501.48000","41.79020","0.01057"
"83656","501.90000","41.82517","0.01067"
"83726","502.32000","41.86021","0.01104"
"83796","502.74000","41.89518","0.01062"
"83866","503.16000","41.93016","0.01060"
"83936","503.58000","41.96519","0.01078"
"84006","504.00000","42.00023","0.01087"
"84076","504.42000","42.03521","0.01073"
"84146","504.84000","42.07019","0.01066"
"84216","505.26000","42.10516","0.01076"
"84286","505.68000","42.14020","0.01058"
"84356","506.10000","42.17517","0.01086"
"84426","506.52000","42.21021","0.01061"
"84496","506.94000","42.24513","0.01099"
"84566","507.36000","42.28017","0.01046"
"84636","507.78000","42.31515","0.01032"
"84706","508.20000","42.35024","0.01083"
"84776","508.62000","42.38516","0.01037"
"84846","509.04000","42.42014","0.01087"
"84916","509.46000","42.45517","0.01062"
"84986","509.88000","42.49021","0.01050"
"85056","510.30000","42.52525","0.01048"
"85126","510.72000","42.56016","0.01049"
"85196","511.14000","42.59508","0.01057"
"85266","511.56000","42.63018","0.01039"
"85336","511.98000","42.66521","0.01056"
"85406","512.40000","42.70019","0.01044"
"85476","512.82000","42.73517","0.01057"
"85546","513.24000","42.77020","0.01060"
"85616","513.66000","42.80524","0.01062"
"85686","514.08000","42.84015","0.01081"
"85756","514.50000","42.87513","0.01063"
"85826","514.92000","42.91017","0.01039"
"85896","515.34000","42.94521","0.01078"
"85966","515.76000","42.98024","0.01074"
"86036","516.18000","43.01522","0.01027"
"86106","516.60000","43.05014","0.01026"
"86176","517.02000","43.08511","0.01056"
"86246","517.44000","43.12021","0.01037"
"86316","517.86000","43.15519","0.01062"
"86350","518.06200","43.17205","0.01067"