File: Trajectories_together/161217Specimen_RawData_2.csv
"","V1","V2","V3"
"1","End date","12/17/2016",""
"2","Specimen label","6CT_42",""
"3","Maximum Load","0.30066","N"
"4","Time","Extension","Load"
"5","(s)","(mm)","(N)"
"6","0.00000","0.00000","-0.00009"
"56","0.30000","0.02410","0.00110"
"106","0.60000","0.05016","0.00251"
"156","0.90000","0.07522","0.00292"
"206","1.20000","0.10015","0.00328"
"256","1.50000","0.12514","0.00360"
"306","1.80000","0.15013","0.00389"
"356","2.10000","0.17512","0.00374"
"406","2.40000","0.20018","0.00429"
"456","2.70000","0.22517","0.00415"
"506","3.00000","0.25016","0.00422"
"556","3.30000","0.27515","0.00445"
"606","3.60000","0.30014","0.00451"
"656","3.90000","0.32514","0.00460"
"706","4.20000","0.35013","0.00481"
"756","4.50000","0.37512","0.00485"
"806","4.80000","0.40011","0.00465"
"856","5.10000","0.42516","0.00499"
"906","5.40000","0.45016","0.00495"
"956","5.70000","0.47515","0.00520"
"1006","6.00000","0.50014","0.00524"
"1056","6.30000","0.52519","0.00525"
"1106","6.60000","0.55012","0.00506"
"1156","6.90000","0.57512","0.00515"
"1206","7.20000","0.60017","0.00536"
"1256","7.50000","0.62510","0.00533"
"1306","7.80000","0.65015","0.00532"
"1356","8.10000","0.67508","0.00527"
"1406","8.40000","0.70014","0.00504"
"1456","8.70000","0.72513","0.00563"
"1506","9.00000","0.75018","0.00571"
"1556","9.30000","0.77517","0.00558"
"1606","9.60000","0.80016","0.00542"
"1656","9.90000","0.82516","0.00562"
"1706","10.20000","0.85015","0.00554"
"1756","10.50000","0.87514","0.00544"
"1806","10.80000","0.90007","0.00583"
"1856","11.10000","0.92512","0.00566"
"1906","11.40000","0.95006","0.00567"
"1956","11.70000","0.97511","0.00561"
"2006","12.00000","1.00016","0.00599"
"2056","12.30000","1.02515","0.00572"
"2106","12.60000","1.05020","0.00564"
"2156","12.90000","1.07508","0.00577"
"2206","13.20000","1.10013","0.00592"
"2256","13.50000","1.12512","0.00579"
"2306","13.80000","1.15017","0.00562"
"2356","14.10000","1.17516","0.00584"
"2406","14.40000","1.20016","0.00580"
"2456","14.70000","1.22515","0.00612"
"2506","15.00000","1.25008","0.00615"
"2556","15.30000","1.27519","0.00565"
"2606","15.60000","1.30012","0.00588"
"2656","15.90000","1.32518","0.00604"
"2706","16.20000","1.35011","0.00610"
"2756","16.50000","1.37516","0.00610"
"2806","16.80000","1.40009","0.00614"
"2856","17.10000","1.42514","0.00600"
"2906","17.40000","1.45008","0.00615"
"2956","17.70000","1.47507","0.00634"
"3006","18.00000","1.50012","0.00609"
"3056","18.30000","1.52511","0.00625"
"3106","18.60000","1.55016","0.00629"
"3156","18.90000","1.57516","0.00607"
"3206","19.20000","1.60015","0.00605"
"3256","19.50000","1.62508","0.00622"
"3306","19.80000","1.65013","0.00621"
"3356","20.10000","1.67512","0.00626"
"3406","20.40000","1.70012","0.00627"
"3456","20.70000","1.72517","0.00635"
"3506","21.00000","1.75010","0.00615"
"3556","21.30000","1.77509","0.00622"
"3606","21.60000","1.80008","0.00617"
"3656","21.90000","1.82514","0.00598"
"3706","22.20000","1.85019","0.00610"
"3756","22.50000","1.87518","0.00614"
"3806","22.80000","1.90017","0.00649"
"3856","23.10000","1.92510","0.00637"
"3906","23.40000","1.95022","0.00686"
"3956","23.70000","1.97515","0.00655"
"4006","24.00000","2.00014","0.00622"
"4056","24.30000","2.02507","0.00641"
"4106","24.60000","2.05012","0.00635"
"4156","24.90000","2.07518","0.00668"
"4206","25.20000","2.10017","0.00675"
"4256","25.50000","2.12516","0.00671"
"4306","25.80000","2.15009","0.00628"
"4356","26.10000","2.17514","0.00670"
"4406","26.40000","2.20008","0.00635"
"4456","26.70000","2.22519","0.00692"
"4506","27.00000","2.25012","0.00661"
"4556","27.30000","2.27517","0.00664"
"4606","27.60000","2.30016","0.00661"
"4656","27.90000","2.32516","0.00661"
"4706","28.20000","2.35015","0.00653"
"4756","28.50000","2.37514","0.00694"
"4806","28.80000","2.40019","0.00675"
"4856","29.10000","2.42512","0.00682"
"4906","29.40000","2.45017","0.00681"
"4956","29.70000","2.47511","0.00672"
"5006","30.00000","2.50010","0.00696"
"5056","30.30000","2.52515","0.00689"
"5106","30.60000","2.55008","0.00684"
"5156","30.90000","2.57513","0.00682"
"5206","31.20000","2.60013","0.00664"
"5256","31.50000","2.62512","0.00696"
"5306","31.80000","2.65011","0.00696"
"5356","32.10000","2.67516","0.00689"
"5406","32.40000","2.70016","0.00684"
"5456","32.70000","2.72515","0.00686"
"5506","33.00000","2.75020","0.00711"
"5556","33.30000","2.77513","0.00719"
"5606","33.60000","2.80018","0.00743"
"5656","33.90000","2.82512","0.00714"
"5706","34.20000","2.85011","0.00765"
"5756","34.50000","2.87510","0.00743"
"5806","34.80000","2.90021","0.00729"
"5856","35.10000","2.92508","0.00737"
"5906","35.40000","2.95014","0.00742"
"5956","35.70000","2.97513","0.00720"
"6006","36.00000","3.00012","0.00714"
"6056","36.30000","3.02517","0.00756"
"6106","36.60000","3.05010","0.00686"
"6156","36.90000","3.07510","0.00728"
"6206","37.20000","3.10003","0.00716"
"6256","37.50000","3.12514","0.00759"
"6306","37.80000","3.15013","0.00742"
"6356","38.10000","3.17512","0.00720"
"6406","38.40000","3.20012","0.00735"
"6456","38.70000","3.22511","0.00737"
"6506","39.00000","3.25016","0.00770"
"6556","39.30000","3.27515","0.00734"
"6606","39.60000","3.30020","0.00749"
"6656","39.90000","3.32508","0.00740"
"6706","40.20000","3.35013","0.00753"
"6756","40.50000","3.37512","0.00743"
"6806","40.80000","3.40011","0.00738"
"6856","41.10000","3.42516","0.00745"
"6906","41.40000","3.45010","0.00746"
"6956","41.70000","3.47521","0.00766"
"7006","42.00000","3.50014","0.00769"
"7056","42.30000","3.52519","0.00776"
"7106","42.60000","3.55012","0.00742"
"7156","42.90000","3.57511","0.00771"
"7206","43.20000","3.60011","0.00725"
"7256","43.50000","3.62510","0.00697"
"7306","43.80000","3.65015","0.00696"
"7356","44.10000","3.67514","0.00737"
"7406","44.40000","3.70014","0.00747"
"7456","44.70000","3.72507","0.00756"
"7506","45.00000","3.75018","0.00746"
"7556","45.30000","3.77511","0.00729"
"7606","45.60000","3.80016","0.00715"
"7656","45.90000","3.82515","0.00728"
"7706","46.20000","3.85015","0.00711"
"7756","46.50000","3.87520","0.00720"
"7806","46.80000","3.90013","0.00729"
"7856","47.10000","3.92512","0.00743"
"7906","47.40000","3.95006","0.00747"
"7956","47.70000","3.97517","0.00756"
"8006","48.00000","4.00010","0.00726"
"8056","48.30000","4.02515","0.00740"
"8106","48.60000","4.05020","0.00736"
"8156","48.90000","4.07514","0.00763"
"8206","49.20000","4.10019","0.00768"
"8256","49.50000","4.12506","0.00770"
"8306","49.80000","4.15017","0.00780"
"8356","50.10000","4.17504","0.00761"
"8406","50.40000","4.20015","0.00739"
"8456","50.70000","4.22509","0.00777"
"8506","51.00000","4.25014","0.00744"
"8556","51.30000","4.27513","0.00733"
"8606","51.60000","4.30012","0.00780"
"8656","51.90000","4.32517","0.00787"
"8706","52.20000","4.35011","0.00764"
"8756","52.50000","4.37516","0.00781"
"8806","52.80000","4.40009","0.00783"
"8856","53.10000","4.42514","0.00773"
"8906","53.40000","4.45008","0.00768"
"8956","53.70000","4.47513","0.00777"
"9006","54.00000","4.50018","0.00791"
"9056","54.30000","4.52511","0.00795"
"9106","54.60000","4.55016","0.00796"
"9156","54.90000","4.57510","0.00789"
"9206","55.20000","4.60021","0.00781"
"9256","55.50000","4.62508","0.00789"
"9306","55.80000","4.65007","0.00822"
"9356","56.10000","4.67512","0.00790"
"9406","56.40000","4.70011","0.00795"
"9456","56.70000","4.72511","0.00815"
"9506","57.00000","4.75004","0.00820"
"9556","57.30000","4.77515","0.00766"
"9606","57.60000","4.80008","0.00776"
"9656","57.90000","4.82513","0.00788"
"9706","58.20000","4.85007","0.00806"
"9756","58.50000","4.87518","0.00788"
"9806","58.80000","4.90017","0.00809"
"9856","59.10000","4.92516","0.00789"
"9906","59.40000","4.95015","0.00799"
"9956","59.70000","4.97515","0.00813"
"10006","60.00000","5.00014","0.00799"
"10056","60.30000","5.02507","0.00793"
"10106","60.60000","5.05018","0.00801"
"10156","60.90000","5.07506","0.00787"
"10206","61.20000","5.10017","0.00777"
"10256","61.50000","5.12516","0.00787"
"10306","61.80000","5.15015","0.00787"
"10356","62.10000","5.17514","0.00770"
"10406","62.40000","5.20008","0.00764"
"10456","62.70000","5.22519","0.00799"
"10506","63.00000","5.25006","0.00765"
"10556","63.30000","5.27517","0.00783"
"10606","63.60000","5.30010","0.00776"
"10656","63.90000","5.32515","0.00785"
"10706","64.20000","5.35015","0.00770"
"10756","64.50000","5.37514","0.00769"
"10806","64.80000","5.40019","0.00825"
"10856","65.10000","5.42512","0.00815"
"10906","65.40000","5.45017","0.00835"
"10956","65.70000","5.47511","0.00827"
"11006","66.00000","5.50016","0.00798"
"11056","66.30000","5.52509","0.00808"
"11106","66.60000","5.55014","0.00830"
"11156","66.90000","5.57513","0.00827"
"11206","67.20000","5.60013","0.00823"
"11256","67.50000","5.62518","0.00807"
"11306","67.80000","5.65011","0.00784"
"11356","68.10000","5.67516","0.00798"
"11406","68.40000","5.70015","0.00796"
"11456","68.70000","5.72521","0.00829"
"11506","69.00000","5.75008","0.00809"
"11556","69.30000","5.77513","0.00823"
"11606","69.60000","5.80018","0.00806"
"11656","69.90000","5.82511","0.00816"
"11706","70.20000","5.85011","0.00839"
"11756","70.50000","5.87510","0.00777"
"11806","70.80000","5.90009","0.00831"
"11856","71.10000","5.92508","0.00839"
"11906","71.40000","5.95014","0.00843"
"11956","71.70000","5.97513","0.00805"
"12006","72.00000","6.00018","0.00810"
"12056","72.30000","6.02511","0.00801"
"12106","72.60000","6.05010","0.00805"
"12156","72.90000","6.07515","0.00802"
"12206","73.20000","6.10009","0.00818"
"12256","73.50000","6.12514","0.00805"
"12306","73.80000","6.15007","0.00814"
"12356","74.10000","6.17512","0.00810"
"12406","74.40000","6.20017","0.00831"
"12456","74.70000","6.22517","0.00801"
"12506","75.00000","6.25016","0.00816"
"12556","75.30000","6.27509","0.00818"
"12606","75.60000","6.30014","0.00795"
"12656","75.90000","6.32508","0.00794"
"12706","76.20000","6.35013","0.00820"
"12756","76.50000","6.37512","0.00821"
"12806","76.80000","6.40017","0.00763"
"12856","77.10000","6.42510","0.00781"
"12906","77.40000","6.45010","0.00758"
"12956","77.70000","6.47515","0.00789"
"13006","78.00000","6.50014","0.00824"
"13056","78.30000","6.52519","0.00797"
"13106","78.60000","6.55006","0.00766"
"13156","78.90000","6.57511","0.00784"
"13206","79.20000","6.60011","0.00769"
"13256","79.50000","6.62516","0.00755"
"13306","79.80000","6.65015","0.00787"
"13356","80.10000","6.67514","0.00788"
"13406","80.40000","6.70013","0.00783"
"13456","80.70000","6.72513","0.00781"
"13506","81.00000","6.75012","0.00765"
"13556","81.30000","6.77511","0.00791"
"13606","81.60000","6.80016","0.00800"
"13656","81.90000","6.82516","0.00770"
"13706","82.20000","6.85015","0.00780"
"13756","82.50000","6.87514","0.00799"
"13806","82.80000","6.90013","0.00813"
"13856","83.10000","6.92518","0.00821"
"13906","83.40000","6.95006","0.00823"
"13956","83.70000","6.97511","0.00828"
"14006","84.00000","7.00004","0.00818"
"14056","84.30000","7.02515","0.00795"
"14106","84.60000","7.05014","0.00808"
"14156","84.90000","7.07519","0.00810"
"14206","85.20000","7.10019","0.00791"
"14256","85.50000","7.12512","0.00846"
"14306","85.80000","7.15017","0.00804"
"14356","86.10000","7.17510","0.00811"
"14406","86.40000","7.20015","0.00834"
"14456","86.70000","7.22509","0.00816"
"14506","87.00000","7.25014","0.00827"
"14556","87.30000","7.27513","0.00812"
"14606","87.60000","7.30012","0.00860"
"14656","87.90000","7.32512","0.00863"
"14706","88.20000","7.35005","0.00816"
"14756","88.50000","7.37516","0.00819"
"14806","88.80000","7.40015","0.00844"
"14856","89.10000","7.42514","0.00812"
"14906","89.40000","7.45013","0.00851"
"14956","89.70000","7.47513","0.00845"
"15006","90.00000","7.50012","0.00837"
"15056","90.30000","7.52511","0.00881"
"15106","90.60000","7.55016","0.00794"
"15156","90.90000","7.57509","0.00826"
"15206","91.20000","7.60015","0.00821"
"15256","91.50000","7.62508","0.00786"
"15306","91.80000","7.65013","0.00795"
"15356","92.10000","7.67512","0.00794"
"15406","92.40000","7.70018","0.00786"
"15456","92.70000","7.72517","0.00806"
"15506","93.00000","7.75010","0.00787"
"15556","93.30000","7.77515","0.00815"
"15606","93.60000","7.80008","0.00829"
"15656","93.90000","7.82513","0.00794"
"15706","94.20000","7.85007","0.00824"
"15756","94.50000","7.87512","0.00823"
"15806","94.80000","7.90011","0.00842"
"15856","95.10000","7.92522","0.00833"
"15906","95.40000","7.95015","0.00817"
"15956","95.70000","7.97515","0.00844"
"16006","96.00000","8.00014","0.00830"
"16056","96.30000","8.02513","0.00842"
"16106","96.60000","8.05012","0.00817"
"16156","96.90000","8.07506","0.00807"
"16206","97.20000","8.10017","0.00875"
"16256","97.50000","8.12510","0.00830"
"16306","97.80000","8.15015","0.00883"
"16356","98.10000","8.17514","0.00871"
"16406","98.40000","8.20013","0.00879"
"16456","98.70000","8.22519","0.00873"
"16506","99.00000","8.25012","0.00831"
"16556","99.30000","8.27517","0.00869"
"16606","99.60000","8.30010","0.00845"
"16656","99.90000","8.32515","0.00881"
"16706","100.20000","8.35015","0.00822"
"16756","100.50000","8.37514","0.00807"
"16806","100.80000","8.40019","0.00832"
"16856","101.10000","8.42506","0.00836"
"16906","101.40000","8.45017","0.00831"
"16956","101.70000","8.47511","0.00778"
"17006","102.00000","8.50022","0.00799"
"17056","102.30000","8.52509","0.00765"
"17106","102.60000","8.55014","0.00797"
"17156","102.90000","8.57513","0.00774"
"17206","103.20000","8.60019","0.00802"
"17256","103.50000","8.62518","0.00773"
"17306","103.80000","8.65011","0.00817"
"17356","104.10000","8.67510","0.00817"
"17406","104.40000","8.70009","0.00797"
"17456","104.70000","8.72521","0.00829"
"17506","105.00000","8.75014","0.00781"
"17556","105.30000","8.77519","0.00791"
"17606","105.60000","8.80012","0.00796"
"17656","105.90000","8.82511","0.00835"
"17706","106.20000","8.85011","0.00854"
"17756","106.50000","8.87510","0.00848"
"17806","106.80000","8.90015","0.00812"
"17856","107.10000","8.92508","0.00830"
"17906","107.40000","8.95013","0.00858"
"17956","107.70000","8.97513","0.00851"
"18006","108.00000","9.00018","0.00869"
"18056","108.30000","9.02517","0.00825"
"18106","108.60000","9.05016","0.00863"
"18156","108.90000","9.07515","0.00845"
"18206","109.20000","9.10009","0.00842"
"18256","109.50000","9.12514","0.00850"
"18306","109.80000","9.15007","0.00870"
"18356","110.10000","9.17512","0.00862"
"18406","110.40000","9.20005","0.00838"
"18456","110.70000","9.22517","0.00854"
"18506","111.00000","9.25016","0.00860"
"18556","111.30000","9.27515","0.00853"
"18606","111.60000","9.30020","0.00864"
"18656","111.90000","9.32513","0.00856"
"18706","112.20000","9.35019","0.00874"
"18756","112.50000","9.37506","0.00891"
"18806","112.80000","9.40017","0.00919"
"18856","113.10000","9.42510","0.00878"
"18906","113.40000","9.45015","0.00910"
"18956","113.70000","9.47509","0.00914"
"19006","114.00000","9.50008","0.00924"
"19056","114.30000","9.52519","0.00941"
"19106","114.60000","9.55012","0.00968"
"19156","114.90000","9.57517","0.00961"
"19206","115.20000","9.60011","0.00935"
"19256","115.50000","9.62516","0.00975"
"19306","115.80000","9.65009","0.00926"
"19356","116.10000","9.67514","0.00950"
"19406","116.40000","9.70019","0.00924"
"19456","116.70000","9.72507","0.00980"
"19506","117.00000","9.75012","0.00956"
"19556","117.30000","9.77505","0.00950"
"19606","117.60000","9.80016","0.00986"
"19656","117.90000","9.82515","0.00962"
"19706","118.20000","9.85021","0.00991"
"19756","118.50000","9.87514","0.00974"
"19806","118.80000","9.90019","0.00975"
"19856","119.10000","9.92518","0.01003"
"19906","119.40000","9.95011","0.01029"
"19956","119.70000","9.97517","0.01030"
"20006","120.00000","10.00010","0.01023"
"20056","120.30000","10.02515","0.01033"
"20106","120.60000","10.05008","0.01024"
"20156","120.90000","10.07519","0.01030"
"20206","121.20000","10.10013","0.01071"
"20256","121.50000","10.12518","0.01068"
"20306","121.80000","10.15017","0.01060"
"20356","122.10000","10.17510","0.01055"
"20406","122.40000","10.20015","0.01038"
"20456","122.70000","10.22509","0.01078"
"20506","123.00000","10.25014","0.01086"
"20556","123.30000","10.27507","0.01088"
"20606","123.60000","10.30012","0.01119"
"20656","123.90000","10.32511","0.01144"
"20706","124.20000","10.35011","0.01110"
"20756","124.50000","10.37516","0.01141"
"20806","124.80000","10.40015","0.01111"
"20856","125.10000","10.42514","0.01160"
"20906","125.40000","10.45013","0.01183"
"20956","125.70000","10.47513","0.01184"
"21006","126.00000","10.50012","0.01231"
"21056","126.30000","10.52511","0.01218"
"21106","126.60000","10.55010","0.01219"
"21156","126.90000","10.57509","0.01215"
"21206","127.20000","10.60015","0.01232"
"21256","127.50000","10.62508","0.01265"
"21306","127.80000","10.65013","0.01255"
"21356","128.10000","10.67506","0.01262"
"21406","128.40000","10.70017","0.01278"
"21456","128.70000","10.72511","0.01312"
"21506","129.00000","10.75016","0.01321"
"21556","129.30000","10.77515","0.01313"
"21606","129.60000","10.80008","0.01280"
"21656","129.90000","10.82514","0.01318"
"21706","130.20000","10.85013","0.01373"
"21756","130.50000","10.87512","0.01355"
"21806","130.80000","10.90011","0.01363"
"21856","131.10000","10.92516","0.01372"
"21906","131.40000","10.95009","0.01385"
"21956","131.70000","10.97515","0.01387"
"22006","132.00000","11.00014","0.01390"
"22056","132.30000","11.02513","0.01421"
"22106","132.60000","11.05018","0.01454"
"22156","132.90000","11.07512","0.01408"
"22206","133.20000","11.10017","0.01281"
"22256","133.50000","11.12510","0.01264"
"22306","133.80000","11.15015","0.01289"
"22356","134.10000","11.17514","0.01312"
"22406","134.40000","11.20013","0.01333"
"22456","134.70000","11.22519","0.01356"
"22506","135.00000","11.25018","0.01377"
"22556","135.30000","11.27517","0.01393"
"22606","135.60000","11.30010","0.01433"
"22656","135.90000","11.32515","0.01386"
"22706","136.20000","11.35009","0.01407"
"22756","136.50000","11.37514","0.01439"
"22806","136.80000","11.40007","0.01497"
"22856","137.10000","11.42512","0.01489"
"22906","137.40000","11.45011","0.01499"
"22956","137.70000","11.47511","0.01491"
"23006","138.00000","11.50016","0.01516"
"23056","138.30000","11.52515","0.01535"
"23106","138.60000","11.55014","0.01592"
"23156","138.90000","11.57507","0.01589"
"23206","139.20000","11.60019","0.01575"
"23256","139.50000","11.62512","0.01620"
"23306","139.80000","11.65017","0.01669"
"23356","140.10000","11.67510","0.01684"
"23406","140.40000","11.70009","0.01644"
"23456","140.70000","11.72515","0.01701"
"23506","141.00000","11.75014","0.01703"
"23556","141.30000","11.77519","0.01777"
"23606","141.60000","11.80012","0.01763"
"23656","141.90000","11.82511","0.01838"
"23706","142.20000","11.85011","0.01828"
"23756","142.50000","11.87504","0.01872"
"23806","142.80000","11.90015","0.01862"
"23856","143.10000","11.92508","0.01898"
"23906","143.40000","11.95019","0.01953"
"23956","143.70000","11.97513","0.01905"
"24006","144.00000","12.00018","0.01976"
"24056","144.30000","12.02511","0.01983"
"24106","144.60000","12.05016","0.02027"
"24156","144.90000","12.07515","0.02077"
"24206","145.20000","12.10015","0.02029"
"24256","145.50000","12.12520","0.02093"
"24306","145.80000","12.15007","0.02143"
"24356","146.10000","12.17512","0.01976"
"24406","146.40000","12.20006","0.02002"
"24456","146.70000","12.22517","0.02053"
"24506","147.00000","12.25010","0.01959"
"24556","147.30000","12.27515","0.02010"
"24606","147.60000","12.30008","0.02131"
"24656","147.90000","12.32513","0.02105"
"24706","148.20000","12.35013","0.02097"
"24756","148.50000","12.37506","0.02071"
"24806","148.80000","12.40017","0.02174"
"24856","149.10000","12.42510","0.02223"
"24906","149.40000","12.45015","0.02257"
"24956","149.70000","12.47509","0.02307"
"25006","150.00000","12.50014","0.02327"
"25056","150.30000","12.52513","0.02295"
"25106","150.60000","12.55012","0.02348"
"25156","150.90000","12.57517","0.02298"
"25206","151.20000","12.60011","0.02400"
"25256","151.50000","12.62516","0.02409"
"25306","151.80000","12.65015","0.02405"
"25356","152.10000","12.67514","0.02232"
"25406","152.40000","12.70013","0.02343"
"25456","152.70000","12.72513","0.02370"
"25506","153.00000","12.75018","0.02411"
"25556","153.30000","12.77511","0.02447"
"25606","153.60000","12.80016","0.02470"
"25656","153.90000","12.82509","0.02514"
"25706","154.20000","12.85021","0.02589"
"25756","154.50000","12.87514","0.02581"
"25806","154.80000","12.90019","0.02715"
"25856","155.10000","12.92512","0.02682"
"25906","155.40000","12.95017","0.02801"
"25956","155.70000","12.97517","0.02802"
"26006","156.00000","13.00010","0.02879"
"26056","156.30000","13.02515","0.02949"
"26106","156.60000","13.05014","0.02958"
"26156","156.90000","13.07513","0.03044"
"26206","157.20000","13.10007","0.03058"
"26256","157.50000","13.12518","0.03156"
"26306","157.80000","13.15017","0.03023"
"26356","158.10000","13.17516","0.03131"
"26406","158.40000","13.20015","0.03137"
"26456","158.70000","13.22509","0.03169"
"26506","159.00000","13.25014","0.03294"
"26556","159.30000","13.27507","0.03347"
"26606","159.60000","13.30012","0.03439"
"26656","159.90000","13.32511","0.03500"
"26706","160.20000","13.35017","0.03556"
"26756","160.50000","13.37516","0.03573"
"26806","160.80000","13.40015","0.03693"
"26856","161.10000","13.42520","0.03756"
"26906","161.40000","13.45013","0.03762"
"26956","161.70000","13.47519","0.03857"
"27006","162.00000","13.50006","0.03934"
"27056","162.30000","13.52511","0.03931"
"27106","162.60000","13.55004","0.03991"
"27156","162.90000","13.57515","0.04047"
"27206","163.20000","13.60009","0.04120"
"27256","163.50000","13.62508","0.04165"
"27306","163.80000","13.65013","0.04211"
"27356","164.10000","13.67512","0.04227"
"27406","164.40000","13.70017","0.01736"
"27456","164.70000","13.72511","0.02094"
"27506","165.00000","13.75022","0.02127"
"27556","165.30000","13.77515","0.02000"
"27606","165.60000","13.80014","0.01906"
"27656","165.90000","13.82513","0.02019"
"27706","166.20000","13.85013","0.02255"
"27756","166.50000","13.87512","0.02338"
"27806","166.80000","13.90011","0.02232"
"27856","167.10000","13.92516","0.02175"
"27906","167.40000","13.95015","0.02301"
"27956","167.70000","13.97515","0.02500"
"28006","168.00000","14.00014","0.02570"
"28056","168.30000","14.02513","0.02449"
"28106","168.60000","14.05012","0.02496"
"28156","168.90000","14.07511","0.02609"
"28206","169.20000","14.10017","0.02758"
"28256","169.50000","14.12510","0.02749"
"28306","169.80000","14.15015","0.02767"
"28356","170.10000","14.17508","0.02758"
"28406","170.40000","14.20019","0.02903"
"28456","170.70000","14.22513","0.03057"
"28506","171.00000","14.25018","0.03022"
"28556","171.30000","14.27517","0.03014"
"28606","171.60000","14.30016","0.03125"
"28656","171.90000","14.32515","0.03291"
"28706","172.20000","14.35009","0.03290"
"28756","172.50000","14.37514","0.03286"
"28806","172.80000","14.40007","0.03352"
"28856","173.10000","14.42518","0.03468"
"28906","173.40000","14.45011","0.03546"
"28956","173.70000","14.47517","0.03569"
"29006","174.00000","14.50016","0.03636"
"29056","174.30000","14.52515","0.03803"
"29106","174.60000","14.55020","0.03890"
"29156","174.90000","14.57507","0.03957"
"29206","175.20000","14.60013","0.03968"
"29256","175.50000","14.62518","0.04069"
"29306","175.80000","14.65017","0.04115"
"29356","176.10000","14.67510","0.04229"
"29406","176.40000","14.70009","0.04216"
"29456","176.70000","14.72515","0.04237"
"29506","177.00000","14.75008","0.04294"
"29556","177.30000","14.77513","0.04339"
"29606","177.60000","14.80006","0.04284"
"29656","177.90000","14.82517","0.03615"
"29706","178.20000","14.85011","0.03522"
"29756","178.50000","14.87516","0.03703"
"29806","178.80000","14.90015","0.03755"
"29856","179.10000","14.92514","0.03663"
"29906","179.40000","14.95019","0.03709"
"29956","179.70000","14.97519","0.03906"
"30006","180.00000","15.00018","0.04023"
"30056","180.30000","15.02511","0.04118"
"30106","180.60000","15.05010","0.04043"
"30156","180.90000","15.07510","0.04224"
"30206","181.20000","15.10015","0.04304"
"30256","181.50000","15.12520","0.04276"
"30306","181.80000","15.15013","0.04335"
"30356","182.10000","15.17518","0.04400"
"30406","182.40000","15.20012","0.04492"
"30456","182.70000","15.22511","0.04565"
"30506","183.00000","15.25004","0.04554"
"30556","183.30000","15.27515","0.04593"
"30606","183.60000","15.30008","0.04647"
"30656","183.90000","15.32508","0.01997"
"30706","184.20000","15.35013","0.01409"
"30756","184.50000","15.37518","0.01327"
"30806","184.80000","15.40017","0.01660"
"30856","185.10000","15.42510","0.01634"
"30906","185.40000","15.45015","0.01368"
"30956","185.70000","15.47509","0.01412"
"31006","186.00000","15.50014","0.01830"
"31056","186.30000","15.52513","0.01754"
"31106","186.60000","15.55012","0.01662"
"31156","186.90000","15.57517","0.01651"
"31206","187.20000","15.60011","0.01760"
"31256","187.50000","15.62522","0.01792"
"31306","187.80000","15.65015","0.01831"
"31356","188.10000","15.67520","0.01928"
"31406","188.40000","15.70007","0.02044"
"31456","188.70000","15.72518","0.01921"
"31506","189.00000","15.75012","0.01945"
"31556","189.30000","15.77517","0.02076"
"31606","189.60000","15.80010","0.02205"
"31656","189.90000","15.82509","0.02132"
"31706","190.20000","15.85015","0.02147"
"31756","190.50000","15.87514","0.02192"
"31806","190.80000","15.90019","0.02259"
"31856","191.10000","15.92512","0.02282"
"31906","191.40000","15.95017","0.02371"
"31956","191.70000","15.97516","0.01468"
"32006","192.00000","16.00016","0.01439"
"32056","192.30000","16.02515","0.01489"
"32106","192.60000","16.05014","0.01644"
"32156","192.90000","16.07519","0.01468"
"32206","193.20000","16.10013","0.01765"
"32256","193.50000","16.12506","0.01687"
"32306","193.80000","16.15011","0.01752"
"32356","194.10000","16.17516","0.01642"
"32406","194.40000","16.20015","0.01764"
"32456","194.70000","16.22521","0.01752"
"32506","195.00000","16.25020","0.01857"
"32556","195.30000","16.27513","0.01782"
"32606","195.60000","16.30012","0.01861"
"32656","195.90000","16.32505","0.01940"
"32706","196.20000","16.35016","0.01961"
"32756","196.50000","16.37510","0.01978"
"32806","196.80000","16.40015","0.01972"
"32856","197.10000","16.42514","0.02027"
"32906","197.40000","16.45019","0.01947"
"32956","197.70000","16.47519","0.01957"
"33006","198.00000","16.50012","0.01978"
"33056","198.30000","16.52511","0.02089"
"33106","198.60000","16.55004","0.02045"
"33156","198.90000","16.57515","0.01998"
"33206","199.20000","16.60009","0.01604"
"33256","199.50000","16.62514","0.01735"
"33306","199.80000","16.65013","0.01735"
"33356","200.10000","16.67512","0.01618"
"33406","200.40000","16.70011","0.01702"
"33456","200.70000","16.72510","0.01783"
"33506","201.00000","16.75016","0.01819"
"33556","201.30000","16.77509","0.01848"
"33606","201.60000","16.80014","0.01822"
"33656","201.90000","16.82507","0.01869"
"33706","202.20000","16.85012","0.01950"
"33756","202.50000","16.87512","0.01977"
"33806","202.80000","16.90011","0.01996"
"33856","203.10000","16.92516","0.01969"
"33906","203.40000","16.95009","0.01988"
"33956","203.70000","16.97515","0.02070"
"34006","204.00000","17.00008","0.02031"
"34056","204.30000","17.02513","0.02059"
"34106","204.60000","17.05012","0.02141"
"34156","204.90000","17.07517","0.02124"
"34206","205.20000","17.10016","0.02201"
"34256","205.50000","17.12516","0.02164"
"34306","205.80000","17.15015","0.02220"
"34356","206.10000","17.17508","0.02202"
"34406","206.40000","17.20013","0.02238"
"34456","206.70000","17.22513","0.02269"
"34506","207.00000","17.25018","0.02299"
"34556","207.30000","17.27517","0.02377"
"34606","207.60000","17.30022","0.02466"
"34656","207.90000","17.32515","0.02543"
"34706","208.20000","17.35015","0.02580"
"34756","208.50000","17.37514","0.02402"
"34806","208.80000","17.40007","0.02520"
"34856","209.10000","17.42512","0.02643"
"34906","209.40000","17.45011","0.02669"
"34956","209.70000","17.47511","0.02740"
"35006","210.00000","17.50016","0.02770"
"35056","210.30000","17.52515","0.02790"
"35106","210.60000","17.55020","0.02920"
"35156","210.90000","17.57513","0.02943"
"35206","211.20000","17.60012","0.03002"
"35256","211.50000","17.62512","0.03105"
"35306","211.80000","17.65017","0.03159"
"35356","212.10000","17.67510","0.03308"
"35406","212.40000","17.70015","0.03372"
"35456","212.70000","17.72515","0.03461"
"35506","213.00000","17.75014","0.03428"
"35556","213.30000","17.77513","0.03511"
"35606","213.60000","17.80012","0.03546"
"35656","213.90000","17.82517","0.03658"
"35706","214.20000","17.85011","0.03611"
"35756","214.50000","17.87516","0.02929"
"35806","214.80000","17.90015","0.03078"
"35856","215.10000","17.92514","0.03294"
"35906","215.40000","17.95007","0.03327"
"35956","215.70000","17.97513","0.03465"
"36006","216.00000","18.00012","0.03524"
"36056","216.30000","18.02511","0.03018"
"36106","216.60000","18.05010","0.02428"
"36156","216.90000","18.07509","0.02526"
"36206","217.20000","18.10014","0.02711"
"36256","217.50000","18.12508","0.02484"
"36306","217.80000","18.15013","0.02521"
"36356","218.10000","18.17512","0.02749"
"36406","218.40000","18.20011","0.02878"
"36456","218.70000","18.22516","0.02749"
"36506","219.00000","18.25010","0.02878"
"36556","219.30000","18.27515","0.02963"
"36606","219.60000","18.30008","0.03048"
"36656","219.90000","18.32513","0.02982"
"36706","220.20000","18.35019","0.03194"
"36756","220.50000","18.37518","0.03241"
"36806","220.80000","18.40017","0.03276"
"36856","221.10000","18.42516","0.03328"
"36906","221.40000","18.45021","0.03509"
"36956","221.70000","18.47509","0.03309"
"37006","222.00000","18.50014","0.03369"
"37056","222.30000","18.52507","0.03584"
"37106","222.60000","18.55012","0.03636"
"37156","222.90000","18.57505","0.03702"
"37206","223.20000","18.60011","0.03687"
"37256","223.50000","18.62516","0.03744"
"37306","223.80000","18.65009","0.03802"
"37356","224.10000","18.67520","0.03887"
"37406","224.40000","18.70013","0.03965"
"37456","224.70000","18.72519","0.04068"
"37506","225.00000","18.75012","0.04124"
"37556","225.30000","18.77517","0.04178"
"37606","225.60000","18.80010","0.04285"
"37656","225.90000","18.82509","0.04362"
"37706","226.20000","18.85015","0.04400"
"37756","226.50000","18.87514","0.04471"
"37806","226.80000","18.90019","0.04478"
"37856","227.10000","18.92518","0.04492"
"37906","227.40000","18.95023","0.04458"
"37956","227.70000","18.97516","0.04459"
"38006","228.00000","19.00010","0.04550"
"38056","228.30000","19.02509","0.04484"
"38106","228.60000","19.05008","0.04282"
"38156","228.90000","19.07513","0.04226"
"38206","229.20000","19.10013","0.04182"
"38256","229.50000","19.12512","0.04227"
"38306","229.80000","19.15005","0.04496"
"38356","230.10000","19.17510","0.04313"
"38406","230.40000","19.20009","0.04385"
"38456","230.70000","19.22520","0.04484"
"38506","231.00000","19.25014","0.04588"
"38556","231.30000","19.27513","0.04557"
"38606","231.60000","19.30018","0.04643"
"38656","231.90000","19.32511","0.04719"
"38706","232.20000","19.35011","0.04703"
"38756","232.50000","19.37510","0.04664"
"38806","232.80000","19.40015","0.04747"
"38856","233.10000","19.42514","0.04831"
"38906","233.40000","19.45019","0.04797"
"38956","233.70000","19.47518","0.04858"
"39006","234.00000","19.50018","0.04898"
"39056","234.30000","19.52517","0.04980"
"39106","234.60000","19.55010","0.04962"
"39156","234.90000","19.57515","0.05011"
"39206","235.20000","19.60009","0.05091"
"39256","235.50000","19.62514","0.05132"
"39306","235.80000","19.65007","0.05226"
"39356","236.10000","19.67512","0.05247"
"39406","236.40000","19.70017","0.05308"
"39456","236.70000","19.72511","0.05377"
"39506","237.00000","19.75016","0.05464"
"39556","237.30000","19.77515","0.05498"
"39606","237.60000","19.80014","0.05548"
"39656","237.90000","19.82513","0.05699"
"39706","238.20000","19.85018","0.05775"
"39756","238.50000","19.87511","0.05862"
"39806","238.80000","19.90011","0.05563"
"39856","239.10000","19.92510","0.05526"
"39906","239.40000","19.95009","0.05621"
"39956","239.70000","19.97515","0.05738"
"40006","240.00000","20.00008","0.05884"
"40056","240.30000","20.02519","0.05837"
"40106","240.60000","20.05012","0.06043"
"40156","240.90000","20.07517","0.06141"
"40206","241.20000","20.10010","0.06175"
"40256","241.50000","20.12510","0.06229"
"40306","241.80000","20.15015","0.06365"
"40356","242.10000","20.17514","0.06560"
"40406","242.40000","20.20013","0.06554"
"40456","242.70000","20.22507","0.06681"
"40506","243.00000","20.25012","0.06841"
"40556","243.30000","20.27511","0.06870"
"40606","243.60000","20.30016","0.07000"
"40656","243.90000","20.32515","0.07157"
"40706","244.20000","20.35015","0.07186"
"40756","244.50000","20.37514","0.07378"
"40806","244.80000","20.40007","0.07371"
"40856","245.10000","20.42512","0.07497"
"40906","245.40000","20.45011","0.07641"
"40956","245.70000","20.47517","0.07693"
"41006","246.00000","20.50010","0.07761"
"41056","246.30000","20.52515","0.07853"
"41106","246.60000","20.55014","0.07944"
"41156","246.90000","20.57513","0.08018"
"41206","247.20000","20.60019","0.08109"
"41256","247.50000","20.62512","0.08179"
"41306","247.80000","20.65017","0.08302"
"41356","248.10000","20.67510","0.08365"
"41406","248.40000","20.70015","0.08461"
"41456","248.70000","20.72508","0.08519"
"41506","249.00000","20.75014","0.08652"
"41556","249.30000","20.77513","0.08727"
"41606","249.60000","20.80006","0.08827"
"41656","249.90000","20.82511","0.08853"
"41706","250.20000","20.85011","0.08956"
"41756","250.50000","20.87522","0.09025"
"41806","250.80000","20.90009","0.09066"
"41856","251.10000","20.92520","0.09170"
"41906","251.40000","20.95013","0.09164"
"41956","251.70000","20.97513","0.09246"
"42006","252.00000","21.00018","0.09291"
"42056","252.30000","21.02511","0.09301"
"42106","252.60000","21.05016","0.09368"
"42156","252.90000","21.07509","0.09401"
"42206","253.20000","21.10015","0.01797"
"42256","253.50000","21.12508","0.03076"
"42306","253.80000","21.15013","0.01315"
"42356","254.10000","21.17512","0.00809"
"42406","254.40000","21.20011","0.02181"
"42456","254.70000","21.22510","0.01179"
"42506","255.00000","21.25010","0.00849"
"42556","255.30000","21.27515","0.01907"
"42606","255.60000","21.30008","0.01865"
"42656","255.90000","21.32513","0.01406"
"42706","256.20000","21.35007","0.01481"
"42756","256.50000","21.37518","0.01834"
"42806","256.80000","21.40011","0.01299"
"42856","257.10000","21.42516","0.01568"
"42906","257.40000","21.45015","0.01707"
"42956","257.70000","21.47515","0.01546"
"43006","258.00000","21.50014","0.01612"
"43056","258.30000","21.52507","0.01822"
"43106","258.60000","21.55012","0.01714"
"43156","258.90000","21.57505","0.01798"
"43206","259.20000","21.60016","0.01847"
"43256","259.50000","21.62510","0.01834"
"43306","259.80000","21.65015","0.01799"
"43356","260.10000","21.67514","0.01930"
"43406","260.40000","21.70013","0.02045"
"43456","260.70000","21.72513","0.01898"
"43506","261.00000","21.75012","0.01920"
"43556","261.30000","21.77517","0.02197"
"43606","261.60000","21.80010","0.02133"
"43656","261.90000","21.82515","0.02045"
"43706","262.20000","21.85008","0.02223"
"43756","262.50000","21.87508","0.02326"
"43806","262.80000","21.90013","0.02217"
"43856","263.10000","21.92512","0.02207"
"43906","263.40000","21.95017","0.02406"
"43956","263.70000","21.97511","0.02462"
"44006","264.00000","22.00016","0.02302"
"44056","264.30000","22.02509","0.02314"
"44106","264.60000","22.05014","0.02539"
"44156","264.90000","22.07513","0.02562"
"44206","265.20000","22.10012","0.02434"
"44256","265.50000","22.12518","0.02573"
"44306","265.80000","22.15011","0.02722"
"44356","266.10000","22.17516","0.02810"
"44406","266.40000","22.20009","0.02706"
"44456","266.70000","22.22515","0.02774"
"44506","267.00000","22.25014","0.02967"
"44556","267.30000","22.27519","0.02971"
"44606","267.60000","22.30018","0.03001"
"44656","267.90000","22.32511","0.03146"
"44706","268.20000","22.35017","0.03291"
"44756","268.50000","22.37516","0.03271"
"44806","268.80000","22.40009","0.03389"
"44856","269.10000","22.42502","0.03500"
"44906","269.40000","22.45013","0.03527"
"44956","269.70000","22.47512","0.03640"
"45006","270.00000","22.50012","0.03694"
"45056","270.30000","22.52511","0.03761"
"45106","270.60000","22.55016","0.03794"
"45156","270.90000","22.57521","0.03840"
"45206","271.20000","22.60008","0.03513"
"45256","271.50000","22.62514","0.03557"
"45306","271.80000","22.65013","0.03298"
"45356","272.10000","22.67518","0.03664"
"45406","272.40000","22.70017","0.03772"
"45456","272.70000","22.72516","0.03678"
"45506","273.00000","22.75016","0.03892"
"45556","273.30000","22.77515","0.03969"
"45606","273.60000","22.80020","0.03974"
"45656","273.90000","22.82513","0.04115"
"45706","274.20000","22.85019","0.04226"
"45756","274.50000","22.87506","0.04266"
"45806","274.80000","22.90017","0.04365"
"45856","275.10000","22.92510","0.04416"
"45906","275.40000","22.95009","0.04483"
"45956","275.70000","22.97514","0.04562"
"46006","276.00000","23.00014","0.04614"
"46056","276.30000","23.02513","0.04640"
"46106","276.60000","23.05012","0.04709"
"46156","276.90000","23.07517","0.04740"
"46206","277.20000","23.10016","0.04818"
"46256","277.50000","23.12516","0.04860"
"46306","277.80000","23.15015","0.04918"
"46356","278.10000","23.17514","0.04968"
"46406","278.40000","23.20013","0.05058"
"46456","278.70000","23.22512","0.05089"
"46506","279.00000","23.25012","0.05152"
"46556","279.30000","23.27505","0.05231"
"46606","279.60000","23.30010","0.05244"
"46656","279.90000","23.32509","0.05371"
"46706","280.20000","23.35015","0.05398"
"46756","280.50000","23.37519","0.05532"
"46806","280.80000","23.40013","0.05663"
"46856","281.10000","23.42518","0.05749"
"46906","281.40000","23.45011","0.05874"
"46956","281.70000","23.47516","0.06074"
"47006","282.00000","23.50010","0.06198"
"47056","282.30000","23.52521","0.06420"
"47106","282.60000","23.55008","0.06537"
"47156","282.90000","23.57513","0.06810"
"47206","283.20000","23.60012","0.06890"
"47256","283.50000","23.62518","0.07074"
"47306","283.80000","23.65017","0.07243"
"47356","284.10000","23.67510","0.07412"
"47406","284.40000","23.70015","0.07466"
"47456","284.70000","23.72508","0.07631"
"47506","285.00000","23.75014","0.07756"
"47556","285.30000","23.77513","0.07924"
"47606","285.60000","23.80018","0.08031"
"47656","285.90000","23.82511","0.08197"
"47706","286.20000","23.85011","0.08272"
"47756","286.50000","23.87522","0.08395"
"47806","286.80000","23.90015","0.08545"
"47856","287.10000","23.92520","0.08681"
"47906","287.40000","23.95013","0.08771"
"47956","287.70000","23.97512","0.08925"
"48006","288.00000","24.00006","0.09021"
"48056","288.30000","24.02511","0.09095"
"48106","288.60000","24.05016","0.09187"
"48156","288.90000","24.07509","0.09260"
"48206","289.20000","24.10014","0.09340"
"48256","289.50000","24.12514","0.09451"
"48306","289.80000","24.15013","0.09459"
"48356","290.10000","24.17512","0.09523"
"48406","290.40000","24.20011","0.09581"
"48456","290.70000","24.22511","0.09658"
"48506","291.00000","24.25016","0.09678"
"48556","291.30000","24.27515","0.09715"
"48606","291.60000","24.30014","0.09743"
"48656","291.90000","24.32519","0.09776"
"48706","292.20000","24.35013","0.09784"
"48756","292.50000","24.37511","0.09806"
"48806","292.80000","24.40011","0.09814"
"48856","293.10000","24.42516","0.09823"
"48906","293.40000","24.45015","0.09880"
"48956","293.70000","24.47515","0.09926"
"49006","294.00000","24.50014","0.09954"
"49056","294.30000","24.52513","0.09955"
"49106","294.60000","24.55018","0.10023"
"49156","294.90000","24.57512","0.10032"
"49206","295.20000","24.60010","0.10079"
"49256","295.50000","24.62503","0.10142"
"49306","295.80000","24.65015","0.10196"
"49356","296.10000","24.67508","0.10214"
"49406","296.40000","24.70013","0.10307"
"49456","296.70000","24.72518","0.10365"
"49506","297.00000","24.75012","0.10489"
"49556","297.30000","24.77517","0.10588"
"49606","297.60000","24.80016","0.10643"
"49656","297.90000","24.82515","0.10743"
"49706","298.20000","24.85009","0.10848"
"49756","298.50000","24.87514","0.10970"
"49806","298.80000","24.90013","0.11064"
"49856","299.10000","24.92512","0.11188"
"49906","299.40000","24.95017","0.11330"
"49956","299.70000","24.97517","0.11366"
"50006","300.00000","25.00022","0.11530"
"50056","300.30000","25.02509","0.11689"
"50106","300.60000","25.05014","0.11795"
"50156","300.90000","25.07508","0.11910"
"50206","301.20000","25.10012","0.11985"
"50256","301.50000","25.12512","0.12097"
"50306","301.80000","25.15011","0.12185"
"50356","302.10000","25.17516","0.12325"
"50406","302.40000","25.20009","0.12383"
"50456","302.70000","25.22509","0.12506"
"50506","303.00000","25.25008","0.12655"
"50556","303.30000","25.27519","0.12684"
"50606","303.60000","25.30012","0.12754"
"50656","303.90000","25.32517","0.12849"
"50706","304.20000","25.35016","0.12965"
"50756","304.50000","25.37516","0.12992"
"50806","304.80000","25.40021","0.13124"
"50856","305.10000","25.42514","0.13107"
"50906","305.40000","25.45013","0.13232"
"50956","305.70000","25.47507","0.13276"
"51006","306.00000","25.50018","0.13325"
"51056","306.30000","25.52511","0.13370"
"51106","306.60000","25.55016","0.13480"
"51156","306.90000","25.57515","0.13517"
"51206","307.20000","25.60014","0.13687"
"51256","307.50000","25.62519","0.13689"
"51306","307.80000","25.65007","0.13864"
"51356","308.10000","25.67512","0.13867"
"51406","308.40000","25.70005","0.13899"
"51456","308.70000","25.72516","0.13981"
"51506","309.00000","25.75010","0.14170"
"51556","309.30000","25.77515","0.14174"
"51606","309.60000","25.80014","0.14261"
"51656","309.90000","25.82513","0.14350"
"51706","310.20000","25.85018","0.14424"
"51756","310.50000","25.87512","0.14449"
"51806","310.80000","25.90017","0.14555"
"51856","311.10000","25.92510","0.14565"
"51906","311.40000","25.95015","0.14597"
"51956","311.70000","25.97509","0.14727"
"52006","312.00000","26.00014","0.14799"
"52056","312.30000","26.02513","0.14929"
"52106","312.60000","26.05012","0.14981"
"52156","312.90000","26.07517","0.15027"
"52206","313.20000","26.10010","0.15043"
"52256","313.50000","26.12515","0.15178"
"52306","313.80000","26.15009","0.15235"
"52356","314.10000","26.17514","0.15343"
"52406","314.40000","26.20013","0.15393"
"52456","314.70000","26.22512","0.15435"
"52506","315.00000","26.25012","0.15426"
"52556","315.30000","26.27505","0.15488"
"52606","315.60000","26.30010","0.15540"
"52656","315.90000","26.32509","0.15566"
"52706","316.20000","26.35014","0.15650"
"52756","316.50000","26.37514","0.15682"
"52806","316.80000","26.40019","0.15718"
"52856","317.10000","26.42518","0.15756"
"52906","317.40000","26.45017","0.15781"
"52956","317.70000","26.47516","0.15807"
"53006","318.00000","26.50016","0.15832"
"53056","318.30000","26.52515","0.15869"
"53106","318.60000","26.55002","0.15903"
"53156","318.90000","26.57519","0.15918"
"53206","319.20000","26.60006","0.15971"
"53256","319.50000","26.62518","0.16004"
"53306","319.80000","26.65017","0.16055"
"53356","320.10000","26.67516","0.16081"
"53406","320.40000","26.70015","0.16150"
"53456","320.70000","26.72508","0.16218"
"53506","321.00000","26.75014","0.16226"
"53556","321.30000","26.77507","0.16319"
"53606","321.60000","26.80018","0.16499"
"53656","321.90000","26.82511","0.16647"
"53706","322.20000","26.85016","0.16854"
"53756","322.50000","26.87516","0.17003"
"53806","322.80000","26.90009","0.17184"
"53856","323.10000","26.92514","0.17357"
"53906","323.40000","26.95013","0.17522"
"53956","323.70000","26.97518","0.17708"
"54006","324.00000","27.00012","0.17907"
"54056","324.30000","27.02517","0.18022"
"54106","324.60000","27.05016","0.18207"
"54156","324.90000","27.07509","0.18372"
"54206","325.20000","27.10015","0.18558"
"54256","325.50000","27.12514","0.18754"
"54306","325.80000","27.15013","0.18875"
"54356","326.10000","27.17506","0.19094"
"54406","326.40000","27.20017","0.19285"
"54456","326.70000","27.22516","0.19400"
"54506","327.00000","27.25016","0.19549"
"54556","327.30000","27.27509","0.19644"
"54606","327.60000","27.30014","0.19796"
"54656","327.90000","27.32513","0.19850"
"54706","328.20000","27.35007","0.19966"
"54756","328.50000","27.37512","0.20046"
"54806","328.80000","27.40011","0.20115"
"54856","329.10000","27.42516","0.20163"
"54906","329.40000","27.45009","0.20276"
"54956","329.70000","27.47514","0.20345"
"55006","330.00000","27.50014","0.20403"
"55056","330.30000","27.52519","0.20436"
"55106","330.60000","27.55012","0.20540"
"55156","330.90000","27.57511","0.20586"
"55206","331.20000","27.60016","0.20658"
"55256","331.50000","27.62510","0.20723"
"55306","331.80000","27.65015","0.20796"
"55356","332.10000","27.67508","0.20873"
"55406","332.40000","27.70013","0.20935"
"55456","332.70000","27.72518","0.20979"
"55506","333.00000","27.75018","0.21094"
"55556","333.30000","27.77517","0.21165"
"55606","333.60000","27.80010","0.21255"
"55656","333.90000","27.82515","0.21328"
"55706","334.20000","27.85008","0.21388"
"55756","334.50000","27.87514","0.21504"
"55806","334.80000","27.90007","0.21575"
"55856","335.10000","27.92512","0.21698"
"55906","335.40000","27.95011","0.21832"
"55956","335.70000","27.97511","0.21901"
"56006","336.00000","28.00016","0.21964"
"56056","336.30000","28.02515","0.22018"
"56106","336.60000","28.05020","0.22145"
"56156","336.90000","28.07507","0.22235"
"56206","337.20000","28.10018","0.22321"
"56256","337.50000","28.12511","0.22409"
"56306","337.80000","28.15011","0.22533"
"56356","338.10000","28.17510","0.22579"
"56406","338.40000","28.20015","0.22686"
"56456","338.70000","28.22515","0.22778"
"56506","339.00000","28.25008","0.22856"
"56556","339.30000","28.27513","0.22919"
"56606","339.60000","28.30012","0.23074"
"56656","339.90000","28.32517","0.23154"
"56706","340.20000","28.35016","0.23265"
"56756","340.50000","28.37516","0.23347"
"56806","340.80000","28.40015","0.23420"
"56856","341.10000","28.42514","0.23535"
"56906","341.40000","28.45019","0.23642"
"56956","341.70000","28.47507","0.23816"
"57006","342.00000","28.50012","0.23892"
"57056","342.30000","28.52505","0.24026"
"57106","342.60000","28.55016","0.24148"
"57156","342.90000","28.57515","0.24250"
"57206","343.20000","28.60014","0.24363"
"57256","343.50000","28.62520","0.24437"
"57306","343.80000","28.65013","0.24544"
"57356","344.10000","28.67518","0.24651"
"57406","344.40000","28.70011","0.24685"
"57456","344.70000","28.72516","0.24803"
"57506","345.00000","28.75010","0.24852"
"57556","345.30000","28.77515","0.24935"
"57606","345.60000","28.80014","0.25013"
"57656","345.90000","28.82513","0.25010"
"57706","346.20000","28.85012","0.25089"
"57756","346.50000","28.87506","0.25153"
"57806","346.80000","28.90017","0.25214"
"57856","347.10000","28.92510","0.25260"
"57906","347.40000","28.95015","0.25327"
"57956","347.70000","28.97508","0.25453"
"58006","348.00000","29.00014","0.25541"
"58056","348.30000","29.02513","0.25564"
"58106","348.60000","29.05012","0.25584"
"58156","348.90000","29.07517","0.25646"
"58206","349.20000","29.10016","0.25698"
"58256","349.50000","29.12516","0.25874"
"58306","349.80000","29.15009","0.26019"
"58356","350.10000","29.17514","0.26047"
"58406","350.40000","29.20013","0.26104"
"58456","350.70000","29.22513","0.26197"
"58506","351.00000","29.25011","0.26276"
"58556","351.30000","29.27511","0.26338"
"58606","351.60000","29.30016","0.26449"
"58656","351.90000","29.32509","0.26533"
"58706","352.20000","29.35015","0.26636"
"58756","352.50000","29.37508","0.26774"
"58806","352.80000","29.40019","0.26890"
"58856","353.10000","29.42512","0.26949"
"58906","353.40000","29.45017","0.27177"
"58956","353.70000","29.47517","0.27367"
"59006","354.00000","29.50015","0.27450"
"59056","354.30000","29.52521","0.27609"
"59106","354.60000","29.55014","0.27741"
"59156","354.90000","29.57507","0.27813"
"59206","355.20000","29.60007","0.27886"
"59256","355.50000","29.62518","0.27925"
"59306","355.80000","29.65011","0.27951"
"59356","356.10000","29.67516","0.28059"
"59406","356.40000","29.70015","0.28072"
"59456","356.70000","29.72514","0.28197"
"59506","357.00000","29.75020","0.28262"
"59556","357.30000","29.77513","0.28334"
"59606","357.60000","29.80018","0.28355"
"59656","357.90000","29.82511","0.28552"
"59706","358.20000","29.85016","0.28629"
"59756","358.50000","29.87516","0.28416"
"59806","358.80000","29.90015","0.27546"
"59856","359.10000","29.92520","0.27052"
"59906","359.40000","29.95007","0.27146"
"59956","359.70000","29.97519","0.27431"
"60006","360.00000","30.00012","0.27742"
"60056","360.30000","30.02523","0.27995"
"60106","360.60000","30.05010","0.28159"
"60156","360.90000","30.07515","0.28393"
"60206","361.20000","30.10008","0.28601"
"60256","361.50000","30.12514","0.28760"
"60306","361.80000","30.15013","0.29007"
"60356","362.10000","30.17512","0.29104"
"60406","362.40000","30.20011","0.29284"
"60456","362.70000","30.22511","0.29501"
"60506","363.00000","30.25022","0.29648"
"60556","363.30000","30.27515","0.29826"
"60606","363.60000","30.30014","0.29872"
"60656","363.90000","30.32513","0.29990"
"60706","364.20000","30.35018","0.29981"
"60756","364.50000","30.37512","0.30055"
"60806","364.80000","30.40011","0.29997"
"60856","365.10000","30.42516","0.29910"
"60906","365.40000","30.45015","0.29789"
"60956","365.70000","30.47515","0.02211"
"61006","366.00000","30.50014","0.01352"
"61056","366.30000","30.52519","0.01092"
"61106","366.60000","30.55012","0.00683"
"61156","366.90000","30.57517","0.00797"
"61206","367.20000","30.60017","0.00691"
"61256","367.50000","30.62510","0.00650"
"61306","367.80000","30.65015","0.00623"
"61356","368.10000","30.67508","0.00709"
"61406","368.40000","30.70013","0.00648"
"61456","368.70000","30.72512","0.00653"
"61506","369.00000","30.75012","0.00640"
"61556","369.30000","30.77511","0.00706"
"61606","369.60000","30.80010","0.00660"
"61656","369.90000","30.82521","0.00648"
"61706","370.20000","30.85014","0.00637"
"61756","370.50000","30.87514","0.00650"
"61806","370.80000","30.90007","0.00718"
"61850","371.06400","30.92213","0.00646"