File: Trajectories_together/161217Specimen_RawData_5.csv
"","V1","V2","V3"
"1","End date","12/17/2016",""
"2","Specimen label","15CG_17",""
"3","Maximum Load","0.12803","N"
"4","Time","Extension","Load"
"5","(s)","(mm)","(N)"
"6","0.00000","0.00000","-0.00020"
"63","0.34200","0.02822","0.00101"
"120","0.68400","0.05710","0.00204"
"177","1.02600","0.08568","0.00231"
"234","1.36800","0.11420","0.00299"
"291","1.71000","0.14260","0.00340"
"348","2.05200","0.17118","0.00315"
"405","2.39400","0.19958","0.00419"
"462","2.73600","0.22810","0.00464"
"519","3.07800","0.25668","0.00447"
"576","3.42000","0.28508","0.00502"
"633","3.76200","0.31366","0.00497"
"690","4.10400","0.34212","0.00519"
"747","4.44600","0.37058","0.00514"
"804","4.78800","0.39915","0.00522"
"861","5.13000","0.42761","0.00544"
"918","5.47200","0.45613","0.00566"
"975","5.81400","0.48465","0.00566"
"1032","6.15600","0.51311","0.00583"
"1089","6.49800","0.54163","0.00602"
"1146","6.84000","0.57009","0.00615"
"1203","7.18200","0.59855","0.00618"
"1260","7.52400","0.62713","0.00598"
"1317","7.86600","0.65565","0.00600"
"1374","8.20800","0.68411","0.00607"
"1431","8.55000","0.71257","0.00656"
"1488","8.89200","0.74109","0.00659"
"1545","9.23400","0.76961","0.00669"
"1602","9.57600","0.79819","0.00652"
"1659","9.91800","0.82665","0.00674"
"1716","10.26000","0.85511","0.00681"
"1773","10.60200","0.88363","0.00723"
"1830","10.94400","0.91209","0.00732"
"1887","11.28600","0.94061","0.00751"
"1944","11.62800","0.96913","0.00745"
"2001","11.97000","0.99759","0.00747"
"2058","12.31200","1.02617","0.00755"
"2115","12.65400","1.05469","0.00753"
"2172","12.99600","1.08309","0.00738"
"2229","13.33800","1.11167","0.00795"
"2286","13.68000","1.14013","0.00805"
"2343","14.02200","1.16859","0.00849"
"2400","14.36400","1.19711","0.00790"
"2457","14.70600","1.22563","0.00835"
"2514","15.04800","1.25415","0.00859"
"2571","15.39000","1.28266","0.00894"
"2628","15.73200","1.31106","0.00888"
"2685","16.07400","1.33964","0.00915"
"2742","16.41600","1.36810","0.00942"
"2799","16.75800","1.39662","0.00934"
"2856","17.10000","1.42514","0.00931"
"2913","17.44200","1.45360","0.00964"
"2970","17.78400","1.48206","0.00970"
"3027","18.12600","1.51064","0.00919"
"3084","18.46800","1.53910","0.01021"
"3141","18.81000","1.56762","0.01006"
"3198","19.15200","1.59620","0.01059"
"3255","19.49400","1.62454","0.01070"
"3312","19.83600","1.65318","0.01072"
"3369","20.17800","1.68164","0.01075"
"3426","20.52000","1.71010","0.01093"
"3483","20.86200","1.73868","0.01110"
"3540","21.20400","1.76708","0.01103"
"3597","21.54600","1.79560","0.01137"
"3654","21.88800","1.82412","0.01086"
"3711","22.23000","1.85258","0.01128"
"3768","22.57200","1.88116","0.01140"
"3825","22.91400","1.90962","0.01110"
"3882","23.25600","1.93808","0.01127"
"3939","23.59800","1.96666","0.01161"
"3996","23.94000","1.99512","0.01201"
"4053","24.28200","2.02364","0.01196"
"4110","24.62400","2.05210","0.01183"
"4167","24.96600","2.08062","0.01188"
"4224","25.30800","2.10914","0.01255"
"4281","25.65000","2.13760","0.01279"
"4338","25.99200","2.16606","0.01296"
"4395","26.33400","2.19463","0.01329"
"4452","26.67600","2.22309","0.01383"
"4509","27.01800","2.25161","0.01389"
"4566","27.36000","2.28013","0.01415"
"4623","27.70200","2.30865","0.01404"
"4680","28.04400","2.33711","0.01495"
"4737","28.38600","2.36563","0.01499"
"4794","28.72800","2.39415","0.01510"
"4851","29.07000","2.42267","0.01546"
"4908","29.41200","2.45113","0.01598"
"4965","29.75400","2.47959","0.01589"
"5022","30.09600","2.50811","0.01652"
"5079","30.43800","2.53663","0.01638"
"5136","30.78000","2.56503","0.01666"
"5193","31.12200","2.59367","0.01686"
"5250","31.46400","2.62213","0.01761"
"5307","31.80600","2.65065","0.01759"
"5364","32.14800","2.67911","0.01795"
"5421","32.49000","2.70757","0.01808"
"5478","32.83200","2.73609","0.01852"
"5535","33.17400","2.76467","0.01796"
"5592","33.51600","2.79313","0.01838"
"5649","33.85800","2.82165","0.01817"
"5706","34.20000","2.85017","0.01898"
"5763","34.54200","2.87857","0.01886"
"5820","34.88400","2.90715","0.01912"
"5877","35.22600","2.93561","0.01934"
"5934","35.56800","2.96407","0.01983"
"5991","35.91000","2.99265","0.02009"
"6048","36.25200","3.02111","0.02062"
"6105","36.59400","3.04957","0.02064"
"6162","36.93600","3.07820","0.02171"
"6219","37.27800","3.10654","0.02153"
"6276","37.62000","3.13512","0.02218"
"6333","37.96200","3.16364","0.02240"
"6390","38.30400","3.19210","0.02260"
"6447","38.64600","3.22062","0.02264"
"6504","38.98800","3.24914","0.02336"
"6561","39.33000","3.27760","0.02367"
"6618","39.67200","3.30612","0.02392"
"6675","40.01400","3.33458","0.02331"
"6732","40.35600","3.36316","0.02356"
"6789","40.69800","3.39162","0.02378"
"6846","41.04000","3.42008","0.02434"
"6903","41.38200","3.44866","0.02457"
"6960","41.72400","3.47712","0.02502"
"7017","42.06600","3.50564","0.02497"
"7074","42.40800","3.53416","0.02412"
"7131","42.75000","3.56262","0.02448"
"7188","43.09200","3.59108","0.02475"
"7245","43.43400","3.61960","0.02565"
"7302","43.77600","3.64806","0.02539"
"7359","44.11800","3.67664","0.02496"
"7416","44.46000","3.70510","0.02564"
"7473","44.80200","3.73362","0.02628"
"7530","45.14400","3.76208","0.02603"
"7587","45.48600","3.79066","0.02675"
"7644","45.82800","3.81912","0.02639"
"7701","46.17000","3.84770","0.02685"
"7758","46.51200","3.87610","0.02712"
"7815","46.85400","3.90462","0.02648"
"7872","47.19600","3.93314","0.02630"
"7929","47.53800","3.96165","0.02611"
"7986","47.88000","3.99011","0.02595"
"8043","48.22200","4.01863","0.02652"
"8100","48.56400","4.04709","0.02643"
"8157","48.90600","4.07567","0.02701"
"8214","49.24800","4.10413","0.02721"
"8271","49.59000","4.13259","0.02698"
"8328","49.93200","4.16111","0.02741"
"8385","50.27400","4.18957","0.02764"
"8442","50.61600","4.21815","0.02763"
"8499","50.95800","4.24661","0.02771"
"8556","51.30000","4.27513","0.02887"
"8613","51.64200","4.30359","0.02857"
"8670","51.98400","4.33217","0.02964"
"8727","52.32600","4.36057","0.02922"
"8784","52.66800","4.38915","0.02957"
"8841","53.01000","4.41767","0.02979"
"8898","53.35200","4.44607","0.03035"
"8955","53.69400","4.47465","0.03032"
"9012","54.03600","4.50311","0.03072"
"9069","54.37800","4.53163","0.03017"
"9126","54.72000","4.56015","0.03054"
"9183","55.06200","4.58855","0.02982"
"9240","55.40400","4.61713","0.02889"
"9297","55.74600","4.64565","0.02865"
"9354","56.08800","4.67405","0.02881"
"9411","56.43000","4.70269","0.02912"
"9468","56.77200","4.73115","0.02939"
"9525","57.11400","4.75961","0.03007"
"9582","57.45600","4.78819","0.03034"
"9639","57.79800","4.81659","0.03055"
"9696","58.14000","4.84505","0.03099"
"9753","58.48200","4.87362","0.03071"
"9810","58.82400","4.90208","0.03075"
"9867","59.16600","4.93066","0.03124"
"9924","59.50800","4.95912","0.03106"
"9981","59.85000","4.98758","0.03130"
"10038","60.19200","5.01610","0.03110"
"10095","60.53400","5.04462","0.03007"
"10152","60.87600","5.07314","0.02049"
"10209","61.21800","5.10160","0.01902"
"10266","61.56000","5.13012","0.01843"
"10323","61.90200","5.15864","0.01904"
"10380","62.24400","5.18716","0.01933"
"10437","62.58600","5.21556","0.01990"
"10494","62.92800","5.24414","0.02074"
"10551","63.27000","5.27266","0.02086"
"10608","63.61200","5.30106","0.02170"
"10665","63.95400","5.32964","0.02119"
"10722","64.29600","5.35810","0.02173"
"10779","64.63800","5.38656","0.02217"
"10836","64.98000","5.41514","0.01890"
"10893","65.32200","5.44360","0.01974"
"10950","65.66400","5.47212","0.01775"
"11007","66.00600","5.50064","0.01825"
"11064","66.34800","5.52910","0.01797"
"11121","66.69000","5.55762","0.01775"
"11178","67.03200","5.58614","0.01799"
"11235","67.37400","5.61460","0.01833"
"11292","67.71600","5.64312","0.01817"
"11349","68.05800","5.67164","0.01885"
"11406","68.40000","5.70010","0.01920"
"11463","68.74200","5.72861","0.01912"
"11520","69.08400","5.75713","0.01965"
"11577","69.42600","5.78559","0.01989"
"11634","69.76800","5.81417","0.02019"
"11691","70.11000","5.84257","0.02043"
"11748","70.45200","5.87109","0.02066"
"11805","70.79400","5.89973","0.02126"
"11862","71.13600","5.92807","0.02147"
"11919","71.47800","5.95665","0.02151"
"11976","71.82000","5.98511","0.02180"
"12033","72.16200","6.01357","0.02254"
"12090","72.50400","6.04215","0.02280"
"12147","72.84600","6.07055","0.02298"
"12204","73.18800","6.09907","0.02350"
"12261","73.53000","6.12765","0.02367"
"12318","73.87200","6.15605","0.02376"
"12375","74.21400","6.18463","0.02415"
"12432","74.55600","6.21315","0.02488"
"12489","74.89800","6.24161","0.02483"
"12546","75.24000","6.27013","0.02470"
"12603","75.58200","6.29859","0.02529"
"12660","75.92400","6.32711","0.02562"
"12717","76.26600","6.35563","0.02565"
"12774","76.60800","6.38409","0.02622"
"12831","76.95000","6.41267","0.02653"
"12888","77.29200","6.44119","0.02678"
"12945","77.63400","6.46959","0.02686"
"13002","77.97600","6.49811","0.02742"
"13059","78.31800","6.52663","0.02776"
"13116","78.66000","6.55509","0.02794"
"13173","79.00200","6.58360","0.02828"
"13230","79.34400","6.61212","0.02859"
"13287","79.68600","6.64058","0.02892"
"13344","80.02800","6.66910","0.02692"
"13401","80.37000","6.69762","0.02745"
"13458","80.71200","6.72614","0.02764"
"13515","81.05400","6.75466","0.02873"
"13572","81.39600","6.78306","0.02834"
"13629","81.73800","6.81164","0.02922"
"13686","82.08000","6.84010","0.02991"
"13743","82.42200","6.86862","0.02953"
"13800","82.76400","6.89720","0.03044"
"13857","83.10600","6.92560","0.03052"
"13914","83.44800","6.95412","0.03030"
"13971","83.79000","6.98258","0.03082"
"14028","84.13200","7.01116","0.03143"
"14085","84.47400","7.03962","0.03231"
"14142","84.81600","7.06814","0.03274"
"14199","85.15800","7.09660","0.03308"
"14256","85.50000","7.12512","0.03315"
"14313","85.84200","7.15364","0.03305"
"14370","86.18400","7.18210","0.03403"
"14427","86.52600","7.21062","0.03429"
"14484","86.86800","7.23908","0.03487"
"14541","87.21000","7.26760","0.03540"
"14598","87.55200","7.29612","0.03566"
"14655","87.89400","7.32458","0.03667"
"14712","88.23600","7.35310","0.03613"
"14769","88.57800","7.38168","0.03648"
"14826","88.92000","7.41002","0.03653"
"14883","89.26200","7.43859","0.03712"
"14940","89.60400","7.46717","0.03701"
"14997","89.94600","7.49563","0.03840"
"15054","90.28800","7.52421","0.03806"
"15111","90.63000","7.55261","0.03841"
"15168","90.97200","7.58107","0.03908"
"15225","91.31400","7.60965","0.03881"
"15282","91.65600","7.63805","0.03794"
"15339","91.99800","7.66663","0.03840"
"15396","92.34000","7.69515","0.03936"
"15453","92.68200","7.72355","0.03925"
"15510","93.02400","7.75219","0.03791"
"15567","93.36600","7.78059","0.03842"
"15624","93.70800","7.80905","0.03987"
"15681","94.05000","7.83763","0.03907"
"15738","94.39200","7.86615","0.03959"
"15795","94.73400","7.89461","0.04028"
"15852","95.07600","7.92313","0.04041"
"15909","95.41800","7.95159","0.04045"
"15966","95.76000","7.98017","0.03882"
"16023","96.10200","8.00863","0.03909"
"16080","96.44400","8.03703","0.04039"
"16137","96.78600","8.06561","0.04129"
"16194","97.12800","8.09413","0.04155"
"16251","97.47000","8.12265","0.04208"
"16308","97.81200","8.15117","0.04251"
"16365","98.15400","8.17957","0.04268"
"16422","98.49600","8.20809","0.04317"
"16479","98.83800","8.23661","0.04420"
"16536","99.18000","8.26513","0.04450"
"16593","99.52200","8.29365","0.04528"
"16650","99.86400","8.32216","0.04559"
"16707","100.20600","8.35063","0.04573"
"16764","100.54800","8.37914","0.04580"
"16821","100.89000","8.40760","0.04651"
"16878","101.23200","8.43606","0.04672"
"16935","101.57400","8.46458","0.04665"
"16992","101.91600","8.49310","0.04704"
"17049","102.25800","8.52162","0.04723"
"17106","102.60000","8.55014","0.04719"
"17163","102.94200","8.57860","0.04764"
"17220","103.28400","8.60712","0.04821"
"17277","103.62600","8.63564","0.04823"
"17334","103.96800","8.66410","0.04867"
"17391","104.31000","8.69262","0.04809"
"17448","104.65200","8.72114","0.04885"
"17505","104.99400","8.74960","0.04893"
"17562","105.33600","8.77812","0.04909"
"17619","105.67800","8.80664","0.04885"
"17676","106.02000","8.83516","0.04905"
"17733","106.36200","8.86362","0.04898"
"17790","106.70400","8.89202","0.04923"
"17847","107.04600","8.92060","0.04951"
"17904","107.38800","8.94912","0.05013"
"17961","107.73000","8.97758","0.05040"
"18018","108.07200","9.00616","0.05052"
"18075","108.41400","9.03462","0.05072"
"18132","108.75600","9.06308","0.05108"
"18189","109.09800","9.09172","0.05123"
"18246","109.44000","9.12012","0.05193"
"18303","109.78200","9.14864","0.05198"
"18360","110.12400","9.17715","0.05219"
"18417","110.46600","9.20556","0.05244"
"18474","110.80800","9.23413","0.05203"
"18531","111.15000","9.26259","0.05205"
"18588","111.49200","9.29111","0.05249"
"18645","111.83400","9.31963","0.05279"
"18702","112.17600","9.34809","0.05285"
"18759","112.51800","9.37661","0.05314"
"18816","112.86000","9.40513","0.05346"
"18873","113.20200","9.43359","0.05372"
"18930","113.54400","9.46211","0.05400"
"18987","113.88600","9.49063","0.05474"
"19044","114.22800","9.51903","0.05265"
"19101","114.57000","9.54767","0.04994"
"19158","114.91200","9.57619","0.05018"
"19215","115.25400","9.60459","0.05020"
"19272","115.59600","9.63311","0.04993"
"19329","115.93800","9.66157","0.05019"
"19386","116.28000","9.69015","0.05005"
"19443","116.62200","9.71861","0.05033"
"19500","116.96400","9.74713","0.05052"
"19557","117.30600","9.77559","0.05084"
"19614","117.64800","9.80411","0.05119"
"19671","117.99000","9.83263","0.05159"
"19728","118.33200","9.86115","0.05210"
"19785","118.67400","9.88967","0.05255"
"19842","119.01600","9.91813","0.05284"
"19899","119.35800","9.94665","0.05305"
"19956","119.70000","9.97511","0.05366"
"20013","120.04200","10.00363","0.05418"
"20070","120.38400","10.03209","0.05464"
"20127","120.72600","10.06066","0.05450"
"20184","121.06800","10.08906","0.05483"
"20241","121.41000","10.11764","0.05492"
"20298","121.75200","10.14610","0.05519"
"20355","122.09400","10.17462","0.05527"
"20412","122.43600","10.20314","0.05440"
"20469","122.77800","10.23160","0.05508"
"20526","123.12000","10.26018","0.05544"
"20583","123.46200","10.28864","0.05559"
"20640","123.80400","10.31710","0.05655"
"20697","124.14600","10.34568","0.05731"
"20754","124.48800","10.37408","0.05750"
"20811","124.83000","10.40260","0.05844"
"20868","125.17200","10.43118","0.05915"
"20925","125.51400","10.45958","0.05947"
"20982","125.85600","10.48810","0.05916"
"21039","126.19800","10.51662","0.05990"
"21096","126.54000","10.54508","0.06060"
"21153","126.88200","10.57360","0.05868"
"21210","127.22400","10.60212","0.05909"
"21267","127.56600","10.63058","0.06006"
"21324","127.90800","10.65916","0.05978"
"21381","128.25000","10.68762","0.06033"
"21438","128.59200","10.71614","0.06150"
"21495","128.93400","10.74472","0.06180"
"21552","129.27600","10.77306","0.06322"
"21609","129.61800","10.80164","0.06362"
"21666","129.96000","10.83010","0.06398"
"21723","130.30200","10.85856","0.06497"
"21780","130.64400","10.88713","0.06465"
"21837","130.98600","10.91566","0.06418"
"21894","131.32800","10.94412","0.06157"
"21951","131.67000","10.97263","0.06406"
"22008","132.01200","11.00109","0.06541"
"22065","132.35400","11.02962","0.06648"
"22122","132.69600","11.05813","0.06681"
"22179","133.03800","11.08659","0.06799"
"22236","133.38000","11.11517","0.02113"
"22293","133.72200","11.14363","0.01957"
"22350","134.06400","11.17209","0.02144"
"22407","134.40600","11.20061","0.02091"
"22464","134.74800","11.22907","0.02111"
"22521","135.09000","11.25765","0.01957"
"22578","135.43200","11.28611","0.02345"
"22635","135.77400","11.31457","0.02241"
"22692","136.11600","11.34315","0.02218"
"22749","136.45800","11.37161","0.02405"
"22806","136.80000","11.40007","0.02341"
"22863","137.14200","11.42859","0.02363"
"22920","137.48400","11.45711","0.02528"
"22977","137.82600","11.48563","0.02543"
"23034","138.16800","11.51415","0.02514"
"23091","138.51000","11.54267","0.02718"
"23148","138.85200","11.57113","0.02769"
"23205","139.19400","11.59959","0.02729"
"23262","139.53600","11.62805","0.02770"
"23319","139.87800","11.65657","0.02870"
"23376","140.22000","11.68515","0.02819"
"23433","140.56200","11.71361","0.02946"
"23490","140.90400","11.74213","0.03050"
"23547","141.24600","11.77065","0.03095"
"23604","141.58800","11.79911","0.03085"
"23661","141.93000","11.82762","0.03205"
"23718","142.27200","11.85609","0.03191"
"23775","142.61400","11.88461","0.03182"
"23832","142.95600","11.91318","0.03258"
"23889","143.29800","11.94158","0.03349"
"23946","143.64000","11.97016","0.03350"
"24003","143.98200","11.99862","0.03436"
"24060","144.32400","12.02702","0.03447"
"24117","144.66600","12.05560","0.03439"
"24174","145.00800","12.08412","0.03396"
"24231","145.35000","12.11258","0.03512"
"24288","145.69200","12.14116","0.03572"
"24345","146.03400","12.16962","0.03517"
"24402","146.37600","12.19814","0.03666"
"24459","146.71800","12.22666","0.03598"
"24516","147.06000","12.25512","0.03547"
"24573","147.40200","12.28364","0.03612"
"24630","147.74400","12.31216","0.03555"
"24687","148.08600","12.34062","0.03555"
"24744","148.42800","12.36914","0.03650"
"24801","148.77000","12.39760","0.03728"
"24858","149.11200","12.42612","0.03770"
"24915","149.45400","12.45464","0.03810"
"24972","149.79600","12.48310","0.03909"
"25029","150.13800","12.51168","0.04001"
"25086","150.48000","12.54014","0.03973"
"25143","150.82200","12.56854","0.04026"
"25200","151.16400","12.59712","0.04168"
"25257","151.50600","12.62564","0.04018"
"25314","151.84800","12.65410","0.04087"
"25371","152.19000","12.68262","0.04143"
"25428","152.53200","12.71114","0.04105"
"25485","152.87400","12.73960","0.04120"
"25542","153.21600","12.76812","0.04133"
"25599","153.55800","12.79658","0.04147"
"25656","153.90000","12.82515","0.04132"
"25713","154.24200","12.85361","0.04202"
"25770","154.58400","12.88213","0.04221"
"25827","154.92600","12.91065","0.04233"
"25884","155.26800","12.93911","0.04301"
"25941","155.61000","12.96757","0.04348"
"25998","155.95200","12.99609","0.04332"
"26055","156.29400","13.02467","0.04362"
"26112","156.63600","13.05307","0.04414"
"26169","156.97800","13.08159","0.04438"
"26226","157.32000","13.11011","0.04363"
"26283","157.66200","13.13863","0.04447"
"26340","158.00400","13.16715","0.04445"
"26397","158.34600","13.19555","0.04423"
"26454","158.68800","13.22413","0.04352"
"26511","159.03000","13.25259","0.04485"
"26568","159.37200","13.28111","0.04487"
"26625","159.71400","13.30963","0.04621"
"26682","160.05600","13.33815","0.04591"
"26739","160.39800","13.36661","0.04615"
"26796","160.74000","13.39513","0.04601"
"26853","161.08200","13.42359","0.04623"
"26910","161.42400","13.45211","0.04621"
"26967","161.76600","13.48069","0.04691"
"27024","162.10800","13.50909","0.04731"
"27081","162.45000","13.53767","0.04727"
"27138","162.79200","13.56612","0.04797"
"27195","163.13400","13.59465","0.04778"
"27252","163.47600","13.62316","0.04850"
"27309","163.81800","13.65156","0.04826"
"27366","164.16000","13.68008","0.04845"
"27423","164.50200","13.70860","0.04898"
"27480","164.84400","13.73712","0.04896"
"27537","165.18600","13.76564","0.04917"
"27594","165.52800","13.79416","0.04933"
"27651","165.87000","13.82256","0.04788"
"27708","166.21200","13.85120","0.04797"
"27765","166.55400","13.87966","0.04789"
"27822","166.89600","13.90812","0.04842"
"27879","167.23800","13.93664","0.04844"
"27936","167.58000","13.96510","0.04864"
"27993","167.92200","13.99362","0.04892"
"28050","168.26400","14.02214","0.04860"
"28107","168.60600","14.05054","0.04879"
"28164","168.94800","14.07918","0.04931"
"28221","169.29000","14.10764","0.04928"
"28278","169.63200","14.13610","0.04945"
"28335","169.97400","14.16468","0.04977"
"28392","170.31600","14.19314","0.05007"
"28449","170.65800","14.22160","0.05044"
"28506","171.00000","14.25012","0.04967"
"28563","171.34200","14.27858","0.04944"
"28620","171.68400","14.30716","0.04912"
"28677","172.02600","14.33568","0.04946"
"28734","172.36800","14.36408","0.04967"
"28791","172.71000","14.39260","0.04955"
"28848","173.05200","14.42112","0.04977"
"28905","173.39400","14.44964","0.05005"
"28962","173.73600","14.47815","0.05033"
"29019","174.07800","14.50668","0.05040"
"29076","174.42000","14.53508","0.05002"
"29133","174.76200","14.56365","0.05059"
"29190","175.10400","14.59211","0.05064"
"29247","175.44600","14.62063","0.05069"
"29304","175.78800","14.64915","0.05118"
"29361","176.13000","14.67761","0.05143"
"29418","176.47200","14.70613","0.05131"
"29475","176.81400","14.73465","0.05177"
"29532","177.15600","14.76311","0.05145"
"29589","177.49800","14.79163","0.05127"
"29646","177.84000","14.82015","0.05141"
"29703","178.18200","14.84855","0.05109"
"29760","178.52400","14.87713","0.05096"
"29817","178.86600","14.90565","0.05029"
"29874","179.20800","14.93411","0.05015"
"29931","179.55000","14.96263","0.05004"
"29988","179.89200","14.99109","0.05008"
"30045","180.23400","15.01961","0.05039"
"30102","180.57600","15.04819","0.05068"
"30159","180.91800","15.07659","0.05014"
"30216","181.26000","15.10517","0.05052"
"30273","181.60200","15.13363","0.05045"
"30330","181.94400","15.16209","0.05062"
"30387","182.28600","15.19067","0.05063"
"30444","182.62800","15.21913","0.05083"
"30501","182.97000","15.24759","0.05113"
"30558","183.31200","15.27611","0.05136"
"30615","183.65400","15.30457","0.05164"
"30672","183.99600","15.33315","0.05219"
"30729","184.33800","15.36172","0.05232"
"30786","184.68000","15.39006","0.05183"
"30843","185.02200","15.41864","0.05104"
"30900","185.36400","15.44710","0.05121"
"30957","185.70600","15.47556","0.05132"
"31014","186.04800","15.50414","0.05119"
"31071","186.39000","15.53260","0.05184"
"31128","186.73200","15.56118","0.05163"
"31185","187.07400","15.58958","0.05193"
"31242","187.41600","15.61810","0.05202"
"31299","187.75800","15.64662","0.05097"
"31356","188.10000","15.67514","0.05141"
"31413","188.44200","15.70360","0.05149"
"31470","188.78400","15.73218","0.05174"
"31527","189.12600","15.76058","0.05189"
"31584","189.46800","15.78910","0.05256"
"31641","189.81000","15.81762","0.05212"
"31698","190.15200","15.84608","0.05251"
"31755","190.49400","15.87460","0.05317"
"31812","190.83600","15.90312","0.05372"
"31869","191.17800","15.93158","0.05330"
"31926","191.52000","15.96016","0.05380"
"31983","191.86200","15.98862","0.05400"
"32040","192.20400","16.01708","0.05352"
"32097","192.54600","16.04566","0.05329"
"32154","192.88800","16.07412","0.05343"
"32211","193.23000","16.10264","0.05357"
"32268","193.57200","16.13110","0.05372"
"32325","193.91400","16.15962","0.05356"
"32382","194.25600","16.18808","0.05377"
"32439","194.59800","16.21665","0.05388"
"32496","194.94000","16.24512","0.05414"
"32553","195.28200","16.27363","0.05466"
"32610","195.62400","16.30215","0.05413"
"32667","195.96600","16.33055","0.05473"
"32724","196.30800","16.35913","0.05501"
"32781","196.65000","16.38759","0.05515"
"32838","196.99200","16.41611","0.05609"
"32895","197.33400","16.44469","0.05631"
"32952","197.67600","16.47309","0.05726"
"33009","198.01800","16.50155","0.05687"
"33066","198.36000","16.53013","0.05747"
"33123","198.70200","16.55859","0.05765"
"33180","199.04400","16.58711","0.05819"
"33237","199.38600","16.61563","0.05910"
"33294","199.72800","16.64403","0.05976"
"33351","200.07000","16.67267","0.06060"
"33408","200.41200","16.70113","0.05951"
"33465","200.75400","16.72965","0.06024"
"33522","201.09600","16.75817","0.06112"
"33579","201.43800","16.78657","0.06157"
"33636","201.78000","16.81515","0.06177"
"33693","202.12200","16.84367","0.06263"
"33750","202.46400","16.87207","0.06129"
"33807","202.80600","16.90065","0.06138"
"33864","203.14800","16.92911","0.06185"
"33921","203.49000","16.95757","0.06273"
"33978","203.83200","16.98615","0.06192"
"34035","204.17400","17.01461","0.06102"
"34092","204.51600","17.04307","0.06377"
"34149","204.85800","17.07165","0.06352"
"34206","205.20000","17.10005","0.06448"
"34263","205.54200","17.12862","0.06457"
"34320","205.88400","17.15714","0.06570"
"34377","206.22600","17.18560","0.06651"
"34434","206.56800","17.21412","0.06780"
"34491","206.91000","17.24258","0.06758"
"34548","207.25200","17.27110","0.06782"
"34605","207.59400","17.29962","0.06900"
"34662","207.93600","17.32814","0.06901"
"34719","208.27800","17.35660","0.06802"
"34776","208.62000","17.38512","0.07000"
"34833","208.96200","17.41358","0.06981"
"34890","209.30400","17.44210","0.07024"
"34947","209.64600","17.47068","0.07109"
"35004","209.98800","17.49908","0.07043"
"35061","210.33000","17.52760","0.07190"
"35118","210.67200","17.55612","0.07277"
"35175","211.01400","17.58452","0.07474"
"35232","211.35600","17.61310","0.07516"
"35289","211.69800","17.64162","0.07598"
"35346","212.04000","17.67014","0.07581"
"35403","212.38200","17.69860","0.07700"
"35460","212.72400","17.72712","0.07810"
"35517","213.06600","17.75558","0.07884"
"35574","213.40800","17.78416","0.07990"
"35631","213.75000","17.81262","0.07948"
"35688","214.09200","17.84114","0.08103"
"35745","214.43400","17.86966","0.08117"
"35802","214.77600","17.89812","0.08250"
"35859","215.11800","17.92664","0.08302"
"35916","215.46000","17.95510","0.08384"
"35973","215.80200","17.98362","0.08377"
"36030","216.14400","18.01213","0.08466"
"36087","216.48600","18.04060","0.08537"
"36144","216.82800","18.06911","0.08652"
"36201","217.17000","18.09763","0.08659"
"36258","217.51200","18.12603","0.08726"
"36315","217.85400","18.15467","0.08886"
"36372","218.19600","18.18313","0.08881"
"36429","218.53800","18.21159","0.08886"
"36486","218.88000","18.24017","0.08988"
"36543","219.22200","18.26857","0.09040"
"36600","219.56400","18.29709","0.09112"
"36657","219.90600","18.32561","0.09168"
"36714","220.24800","18.35413","0.09217"
"36771","220.59000","18.38265","0.09115"
"36828","220.93200","18.41111","0.09161"
"36885","221.27400","18.43957","0.08953"
"36942","221.61600","18.46815","0.09000"
"36999","221.95800","18.49661","0.09093"
"37056","222.30000","18.52513","0.09108"
"37113","222.64200","18.55365","0.09126"
"37170","222.98400","18.58211","0.09187"
"37227","223.32600","18.61069","0.09287"
"37284","223.66800","18.63915","0.09313"
"37341","224.01000","18.66755","0.09395"
"37398","224.35200","18.69613","0.09379"
"37455","224.69400","18.72465","0.09422"
"37512","225.03600","18.75311","0.08781"
"37569","225.37800","18.78163","0.08769"
"37626","225.72000","18.81015","0.08796"
"37683","226.06200","18.83860","0.08802"
"37740","226.40400","18.86713","0.08132"
"37797","226.74600","18.89565","0.08161"
"37854","227.08800","18.92410","0.08200"
"37911","227.43000","18.95268","0.08080"
"37968","227.77200","18.98114","0.08305"
"38025","228.11400","19.00966","0.08532"
"38082","228.45600","19.03806","0.08458"
"38139","228.79800","19.06658","0.07850"
"38196","229.14000","19.09516","0.07569"
"38253","229.48200","19.12362","0.07715"
"38310","229.82400","19.15208","0.07944"
"38367","230.16600","19.18060","0.08093"
"38424","230.50800","19.20912","0.08133"
"38481","230.85000","19.23764","0.08129"
"38538","231.19200","19.26616","0.08085"
"38595","231.53400","19.29462","0.08296"
"38652","231.87600","19.32308","0.08254"
"38709","232.21800","19.35166","0.08094"
"38766","232.56000","19.38012","0.08143"
"38823","232.90200","19.40858","0.08248"
"38880","233.24400","19.43710","0.08306"
"38937","233.58600","19.46556","0.08076"
"38994","233.92800","19.49414","0.08159"
"39051","234.27000","19.52260","0.08185"
"39108","234.61200","19.55106","0.08221"
"39165","234.95400","19.57964","0.08331"
"39222","235.29600","19.60810","0.08004"
"39279","235.63800","19.63662","0.08082"
"39336","235.98000","19.66514","0.08191"
"39393","236.32200","19.69360","0.08083"
"39450","236.66400","19.72211","0.08058"
"39507","237.00600","19.75058","0.08191"
"39564","237.34800","19.77909","0.08241"
"39621","237.69000","19.80767","0.07840"
"39678","238.03200","19.83607","0.07851"
"39735","238.37400","19.86465","0.07894"
"39792","238.71600","19.89311","0.07921"
"39849","239.05800","19.92157","0.07938"
"39906","239.40000","19.95015","0.07894"
"39963","239.74200","19.97861","0.07974"
"40020","240.08400","20.00713","0.07986"
"40077","240.42600","20.03565","0.08071"
"40134","240.76800","20.06411","0.08099"
"40191","241.11000","20.09263","0.08181"
"40248","241.45200","20.12109","0.08165"
"40305","241.79400","20.14961","0.08258"
"40362","242.13600","20.17813","0.08292"
"40419","242.47800","20.20659","0.08332"
"40476","242.82000","20.23505","0.08375"
"40533","243.16200","20.26357","0.08489"
"40590","243.50400","20.29215","0.08498"
"40647","243.84600","20.32061","0.08497"
"40704","244.18800","20.34913","0.08553"
"40761","244.53000","20.37759","0.08614"
"40818","244.87200","20.40611","0.08703"
"40875","245.21400","20.43463","0.08777"
"40932","245.55600","20.46309","0.08846"
"40989","245.89800","20.49167","0.08817"
"41046","246.24000","20.52013","0.08842"
"41103","246.58200","20.54865","0.08901"
"41160","246.92400","20.57716","0.08977"
"41217","247.26600","20.60563","0.08996"
"41274","247.60800","20.63408","0.09022"
"41331","247.95000","20.66267","0.08935"
"41388","248.29200","20.69112","0.08908"
"41445","248.63400","20.71964","0.08851"
"41502","248.97600","20.74817","0.08819"
"41559","249.31800","20.77656","0.08872"
"41616","249.66000","20.80508","0.08849"
"41673","250.00200","20.83366","0.08888"
"41730","250.34400","20.86212","0.08976"
"41787","250.68600","20.89064","0.08953"
"41844","251.02800","20.91916","0.08996"
"41901","251.37000","20.94756","0.09026"
"41958","251.71200","20.97614","0.08961"
"42015","252.05400","21.00460","0.08999"
"42072","252.39600","21.03312","0.09074"
"42129","252.73800","21.06170","0.09125"
"42186","253.08000","21.09004","0.09215"
"42243","253.42200","21.11862","0.09192"
"42300","253.76400","21.14714","0.09230"
"42357","254.10600","21.17554","0.09215"
"42414","254.44800","21.20418","0.09300"
"42471","254.79000","21.23264","0.09342"
"42528","255.13200","21.26110","0.09400"
"42585","255.47400","21.28962","0.09378"
"42642","255.81600","21.31814","0.09233"
"42699","256.15800","21.34660","0.09265"
"42756","256.50000","21.37518","0.09322"
"42813","256.84200","21.40358","0.09392"
"42870","257.18400","21.43210","0.09426"
"42927","257.52600","21.46067","0.09468"
"42984","257.86800","21.48908","0.09406"
"43041","258.21000","21.51765","0.09498"
"43098","258.55200","21.54611","0.09476"
"43155","258.89400","21.57463","0.08152"
"43212","259.23600","21.60315","0.08307"
"43269","259.57800","21.63161","0.08334"
"43326","259.92000","21.66007","0.08264"
"43383","260.26200","21.68859","0.08295"
"43440","260.60400","21.71705","0.08361"
"43497","260.94600","21.74563","0.08447"
"43554","261.28800","21.77415","0.08562"
"43611","261.63000","21.80255","0.08555"
"43668","261.97200","21.83113","0.08621"
"43725","262.31400","21.85953","0.08725"
"43782","262.65600","21.88811","0.08717"
"43839","262.99800","21.91663","0.08736"
"43896","263.34000","21.94515","0.08850"
"43953","263.68200","21.97361","0.08884"
"44010","264.02400","22.00213","0.08968"
"44067","264.36600","22.03059","0.09057"
"44124","264.70800","22.05911","0.09103"
"44181","265.05000","22.08763","0.09163"
"44238","265.39200","22.11609","0.09283"
"44295","265.73400","22.14461","0.09333"
"44352","266.07600","22.17313","0.09377"
"44409","266.41800","22.20159","0.09399"
"44466","266.76000","22.23011","0.09395"
"44523","267.10200","22.25863","0.09408"
"44580","267.44400","22.28709","0.09476"
"44637","267.78600","22.31561","0.09513"
"44694","268.12800","22.34407","0.09607"
"44751","268.47000","22.37264","0.09667"
"44808","268.81200","22.40117","0.09676"
"44865","269.15400","22.42962","0.09730"
"44922","269.49600","22.45815","0.09767"
"44979","269.83800","22.48660","0.09776"
"45036","270.18000","22.51506","0.09788"
"45093","270.52200","22.54364","0.09797"
"45150","270.86400","22.57210","0.09811"
"45207","271.20600","22.60062","0.09818"
"45264","271.54800","22.62914","0.09867"
"45321","271.89000","22.65754","0.09919"
"45378","272.23200","22.68612","0.09888"
"45435","272.57400","22.71458","0.09916"
"45492","272.91600","22.74310","0.09939"
"45549","273.25800","22.77168","0.09941"
"45606","273.60000","22.80014","0.09947"
"45663","273.94200","22.82860","0.09879"
"45720","274.28400","22.85712","0.09799"
"45777","274.62600","22.88558","0.09659"
"45834","274.96800","22.91416","0.09545"
"45891","275.31000","22.94262","0.09572"
"45948","275.65200","22.97108","0.09607"
"46005","275.99400","22.99966","0.09643"
"46062","276.33600","23.02818","0.09706"
"46119","276.67800","23.05658","0.09650"
"46176","277.02000","23.08516","0.09655"
"46233","277.36200","23.11362","0.09758"
"46290","277.70400","23.14214","0.09782"
"46347","278.04600","23.17060","0.09830"
"46404","278.38800","23.19906","0.09806"
"46461","278.73000","23.22763","0.09814"
"46518","279.07200","23.25616","0.09811"
"46575","279.41400","23.28456","0.09823"
"46632","279.75600","23.31314","0.09870"
"46689","280.09800","23.34160","0.09876"
"46746","280.44000","23.37012","0.09934"
"46803","280.78200","23.39869","0.09959"
"46860","281.12400","23.42710","0.09934"
"46917","281.46600","23.45561","0.09984"
"46974","281.80800","23.48413","0.09991"
"47031","282.15000","23.51259","0.10025"
"47088","282.49200","23.54111","0.10024"
"47145","282.83400","23.56963","0.10070"
"47202","283.17600","23.59809","0.10066"
"47259","283.51800","23.62661","0.10105"
"47316","283.86000","23.65513","0.10130"
"47373","284.20200","23.68359","0.10178"
"47430","284.54400","23.71217","0.10177"
"47487","284.88600","23.74063","0.10175"
"47544","285.22800","23.76909","0.10196"
"47601","285.57000","23.79761","0.10201"
"47658","285.91200","23.82613","0.10260"
"47715","286.25400","23.85459","0.10320"
"47772","286.59600","23.88317","0.10319"
"47829","286.93800","23.91157","0.10367"
"47886","287.28000","23.94015","0.10426"
"47943","287.62200","23.96867","0.10484"
"48000","287.96400","23.99713","0.10528"
"48057","288.30600","24.02564","0.10628"
"48114","288.64800","24.05411","0.10671"
"48171","288.99000","24.08257","0.10762"
"48228","289.33200","24.11115","0.10846"
"48285","289.67400","24.13960","0.10874"
"48342","290.01600","24.16813","0.10649"
"48399","290.35800","24.19665","0.10710"
"48456","290.70000","24.22504","0.10733"
"48513","291.04200","24.25362","0.10843"
"48570","291.38400","24.28214","0.10879"
"48627","291.72600","24.31060","0.10950"
"48684","292.06800","24.33912","0.11063"
"48741","292.41000","24.36758","0.11103"
"48798","292.75200","24.39610","0.11149"
"48855","293.09400","24.42462","0.11335"
"48912","293.43600","24.45308","0.11392"
"48969","293.77800","24.48166","0.11486"
"49026","294.12000","24.51012","0.11363"
"49083","294.46200","24.53858","0.11089"
"49140","294.80400","24.56716","0.11180"
"49197","295.14600","24.59562","0.11326"
"49254","295.48800","24.62408","0.11396"
"49311","295.83000","24.65260","0.09693"
"49368","296.17200","24.68112","0.09699"
"49425","296.51400","24.70964","0.09830"
"49482","296.85600","24.73810","0.09835"
"49539","297.19800","24.76662","0.09889"
"49596","297.54000","24.79514","0.09920"
"49653","297.88200","24.82366","0.09954"
"49710","298.22400","24.85212","0.09953"
"49767","298.56600","24.88064","0.09976"
"49824","298.90800","24.90910","0.10003"
"49881","299.25000","24.93761","0.10045"
"49938","299.59200","24.96614","0.10104"
"49995","299.93400","24.99459","0.10142"
"50052","300.27600","25.02318","0.10161"
"50109","300.61800","25.05164","0.10208"
"50166","300.96000","25.08010","0.10250"
"50223","301.30200","25.10862","0.10320"
"50280","301.64400","25.13713","0.10435"
"50337","301.98600","25.16559","0.10469"
"50394","302.32800","25.19411","0.10500"
"50451","302.67000","25.22264","0.10599"
"50508","303.01200","25.25103","0.10726"
"50565","303.35400","25.27961","0.10755"
"50622","303.69600","25.30807","0.10898"
"50679","304.03800","25.33665","0.10998"
"50736","304.38000","25.36517","0.11076"
"50793","304.72200","25.39357","0.11227"
"50850","305.06400","25.42209","0.11291"
"50907","305.40600","25.45055","0.11201"
"50964","305.74800","25.47907","0.11308"
"51021","306.09000","25.50765","0.11403"
"51078","306.43200","25.53611","0.11283"
"51135","306.77400","25.56457","0.11387"
"51192","307.11600","25.59315","0.11351"
"51249","307.45800","25.62161","0.11496"
"51306","307.80000","25.65013","0.11823"
"51363","308.14200","25.67865","0.11877"
"51420","308.48400","25.70705","0.11512"
"51477","308.82600","25.73557","0.11286"
"51534","309.16800","25.76415","0.04905"
"51591","309.51000","25.79261","0.04649"
"51648","309.85200","25.82113","0.04339"
"51705","310.19400","25.84958","0.04462"
"51762","310.53600","25.87811","0.04543"
"51819","310.87800","25.90663","0.04660"
"51876","311.22000","25.93508","0.04695"
"51933","311.56200","25.96367","0.04627"
"51990","311.90400","25.99212","0.04723"
"52047","312.24600","26.02052","0.04831"
"52104","312.58800","26.04917","0.04872"
"52161","312.93000","26.07768","0.04828"
"52218","313.27200","26.10608","0.04946"
"52275","313.61400","26.13461","0.04930"
"52332","313.95600","26.16312","0.04980"
"52389","314.29800","26.19164","0.05048"
"52446","314.64000","26.22016","0.05029"
"52503","314.98200","26.24856","0.05110"
"52560","315.32400","26.27714","0.05199"
"52617","315.66600","26.30560","0.05201"
"52674","316.00800","26.33412","0.05236"
"52731","316.35000","26.36264","0.05323"
"52788","316.69200","26.39110","0.05385"
"52845","317.03400","26.41962","0.05420"
"52902","317.37600","26.44814","0.05397"
"52959","317.71800","26.47660","0.05537"
"53016","318.06000","26.50512","0.05666"
"53073","318.40200","26.53358","0.05643"
"53130","318.74400","26.56210","0.05743"
"53187","319.08600","26.59062","0.05866"
"53244","319.42800","26.61914","0.05945"
"53301","319.77000","26.64760","0.05964"
"53358","320.11200","26.67612","0.06036"
"53415","320.45400","26.70464","0.06184"
"53472","320.79600","26.73310","0.06321"
"53529","321.13800","26.76162","0.06350"
"53586","321.48000","26.79014","0.06372"
"53643","321.82200","26.81860","0.06440"
"53700","322.16400","26.84718","0.06511"
"53757","322.50600","26.87563","0.06552"
"53814","322.84800","26.90409","0.06677"
"53871","323.19000","26.93268","0.06728"
"53928","323.53200","26.96107","0.06801"
"53985","323.87400","26.98965","0.06992"
"54042","324.21600","27.01811","0.06975"
"54099","324.55800","27.04663","0.07040"
"54156","324.90000","27.07515","0.07111"
"54213","325.24200","27.10361","0.07277"
"54270","325.58400","27.13213","0.07347"
"54327","325.92600","27.16059","0.07377"
"54384","326.26800","27.18905","0.07443"
"54441","326.61000","27.21757","0.07537"
"54498","326.95200","27.24615","0.07528"
"54555","327.29400","27.27455","0.07629"
"54612","327.63600","27.30313","0.07731"
"54669","327.97800","27.33165","0.07760"
"54726","328.32000","27.36005","0.07821"
"54783","328.66200","27.38869","0.07888"
"54840","329.00400","27.41715","0.08033"
"54897","329.34600","27.44561","0.08086"
"54954","329.68800","27.47413","0.08130"
"55011","330.03000","27.50259","0.08236"
"55068","330.37200","27.53117","0.08311"
"55125","330.71400","27.55969","0.08364"
"55182","331.05600","27.58809","0.08412"
"55239","331.39800","27.61667","0.08453"
"55296","331.74000","27.64507","0.08465"
"55353","332.08200","27.67359","0.08326"
"55410","332.42400","27.70211","0.08224"
"55467","332.76600","27.73057","0.08088"
"55524","333.10800","27.75915","0.08116"
"55581","333.45000","27.78760","0.08193"
"55638","333.79200","27.81606","0.08193"
"55695","334.13400","27.84464","0.08172"
"55752","334.47600","27.87310","0.08127"
"55809","334.81800","27.90162","0.03925"
"55866","335.16000","27.93014","0.04015"
"55923","335.50200","27.95866","0.03692"
"55980","335.84400","27.98712","0.04118"
"56037","336.18600","28.01564","0.04269"
"56094","336.52800","28.04416","0.04141"
"56151","336.87000","28.07256","0.04263"
"56208","337.21200","28.10114","0.04304"
"56265","337.55400","28.12960","0.04402"
"56322","337.89600","28.15812","0.04617"
"56379","338.23800","28.18664","0.04494"
"56436","338.58000","28.21510","0.04426"
"56493","338.92200","28.24362","0.04578"
"56550","339.26400","28.27214","0.04691"
"56607","339.60600","28.30060","0.04716"
"56664","339.94800","28.32912","0.04732"
"56721","340.29000","28.35758","0.04720"
"56778","340.63200","28.38610","0.04785"
"56835","340.97400","28.41462","0.04873"
"56892","341.31600","28.44308","0.04915"
"56949","341.65800","28.47166","0.04855"
"57006","342.00000","28.50018","0.04903"
"57063","342.34200","28.52857","0.04954"
"57120","342.68400","28.55716","0.05020"
"57177","343.02600","28.58562","0.05017"
"57234","343.36800","28.61408","0.04349"
"57291","343.71000","28.64266","0.04479"
"57348","344.05200","28.67105","0.04517"
"57405","344.39400","28.69957","0.04576"
"57462","344.73600","28.72815","0.04547"
"57519","345.07800","28.75661","0.04585"
"57576","345.42000","28.78513","0.04642"
"57633","345.76200","28.81365","0.04657"
"57690","346.10400","28.84205","0.04648"
"57747","346.44600","28.87063","0.04607"
"57804","346.78800","28.89909","0.04697"
"57861","347.13000","28.92755","0.04762"
"57918","347.47200","28.95619","0.04762"
"57975","347.81400","28.98459","0.04748"
"58032","348.15600","29.01317","0.04761"
"58089","348.49800","29.04163","0.04772"
"58146","348.84000","29.07003","0.04792"
"58203","349.18200","29.09867","0.04769"
"58260","349.52400","29.12713","0.04764"
"58317","349.86600","29.15559","0.04837"
"58374","350.20800","29.18417","0.04797"
"58431","350.55000","29.21263","0.04816"
"58488","350.89200","29.24115","0.04855"
"58545","351.23400","29.26961","0.04915"
"58602","351.57600","29.29807","0.04935"
"58659","351.91800","29.32665","0.04955"
"58716","352.26000","29.35511","0.04916"
"58773","352.60200","29.38363","0.04940"
"58830","352.94400","29.41215","0.04956"
"58887","353.28600","29.44061","0.05027"
"58944","353.62800","29.46913","0.05027"
"59001","353.97000","29.49765","0.05071"
"59058","354.31200","29.52617","0.05113"
"59115","354.65400","29.55463","0.05109"
"59172","354.99600","29.58309","0.05108"
"59229","355.33800","29.61160","0.05139"
"59286","355.68000","29.64012","0.05192"
"59343","356.02200","29.66864","0.05219"
"59400","356.36400","29.69704","0.05242"
"59457","356.70600","29.72562","0.05198"
"59514","357.04800","29.75414","0.05260"
"59571","357.39000","29.78260","0.05308"
"59628","357.73200","29.81118","0.05302"
"59685","358.07400","29.83958","0.05303"
"59742","358.41600","29.86810","0.05336"
"59799","358.75800","29.89662","0.05388"
"59856","359.10000","29.92514","0.05405"
"59913","359.44200","29.95360","0.05455"
"59970","359.78400","29.98218","0.05491"
"60027","360.12600","30.01052","0.05539"
"60084","360.46800","30.03916","0.05559"
"60141","360.81000","30.06762","0.05629"
"60198","361.15200","30.09608","0.05690"
"60255","361.49400","30.12460","0.05723"
"60312","361.83600","30.15312","0.05813"
"60369","362.17800","30.18158","0.05944"
"60426","362.52000","30.21010","0.05935"
"60483","362.86200","30.23856","0.05859"
"60540","363.20400","30.26714","0.05895"
"60597","363.54600","30.29565","0.06050"
"60654","363.88800","30.32406","0.06021"
"60711","364.23000","30.35264","0.06084"
"60768","364.57200","30.38109","0.06164"
"60825","364.91400","30.40955","0.06242"
"60882","365.25600","30.43814","0.06397"
"60939","365.59800","30.46660","0.06478"
"60996","365.94000","30.49505","0.06564"
"61053","366.28200","30.52363","0.06626"
"61110","366.62400","30.55203","0.06692"
"61167","366.96600","30.58067","0.06834"
"61224","367.30800","30.60913","0.06891"
"61281","367.65000","30.63753","0.06955"
"61338","367.99200","30.66611","0.07003"
"61395","368.33400","30.69463","0.07098"
"61452","368.67600","30.72315","0.07217"
"61509","369.01800","30.75161","0.07202"
"61566","369.36000","30.78007","0.01934"
"61623","369.70200","30.80859","0.00934"
"61680","370.04400","30.83711","0.01145"
"61737","370.38600","30.86563","0.01439"
"61794","370.72800","30.89409","0.01071"
"61851","371.07000","30.92261","0.01323"
"61908","371.41200","30.95113","0.00978"
"61965","371.75400","30.97965","0.01345"
"62022","372.09600","31.00817","0.01022"
"62079","372.43800","31.03663","0.01236"
"62136","372.78000","31.06515","0.01031"
"62193","373.12200","31.09361","0.01192"
"62250","373.46400","31.12213","0.01069"
"62307","373.80600","31.15065","0.01217"
"62364","374.14800","31.17911","0.01093"
"62421","374.49000","31.20757","0.01220"
"62478","374.83200","31.23615","0.01139"
"62535","375.17400","31.26454","0.01211"
"62592","375.51600","31.29312","0.01100"
"62649","375.85800","31.32164","0.01182"
"62706","376.20000","31.35016","0.01095"
"62763","376.54200","31.37862","0.01207"
"62820","376.88400","31.40708","0.01110"
"62877","377.22600","31.43560","0.01191"
"62934","377.56800","31.46412","0.01118"
"62991","377.91000","31.49258","0.01162"
"63048","378.25200","31.52110","0.01118"
"63105","378.59400","31.54968","0.01150"
"63162","378.93600","31.57808","0.01146"
"63219","379.27800","31.60666","0.01157"
"63276","379.62000","31.63512","0.01114"
"63333","379.96200","31.66358","0.01142"
"63390","380.30400","31.69216","0.01152"
"63447","380.64600","31.72056","0.01162"
"63504","380.98800","31.74914","0.01190"
"63561","381.33000","31.77760","0.01130"
"63618","381.67200","31.80606","0.01154"
"63675","382.01400","31.83464","0.01136"
"63732","382.35600","31.86316","0.01167"
"63789","382.69800","31.89162","0.01129"
"63846","383.04000","31.92014","0.01165"
"63903","383.38200","31.94860","0.01179"
"63960","383.72400","31.97712","0.01204"
"64017","384.06600","32.00563","0.01194"
"64074","384.40800","32.03403","0.01178"
"64131","384.75000","32.06261","0.01191"
"64188","385.09200","32.09107","0.01157"
"64245","385.43400","32.11953","0.01137"
"64302","385.77600","32.14812","0.01185"
"64359","386.11800","32.17663","0.01204"
"64416","386.46000","32.20509","0.01143"
"64473","386.80200","32.23362","0.01174"
"64530","387.14400","32.26213","0.01212"
"64587","387.48600","32.29059","0.01159"
"64644","387.82800","32.31911","0.01186"
"64701","388.17000","32.34763","0.01208"
"64758","388.51200","32.37609","0.01198"
"64815","388.85400","32.40461","0.01189"
"64872","389.19600","32.43307","0.01185"
"64929","389.53800","32.46159","0.01178"
"64986","389.88000","32.49011","0.01100"
"65043","390.22200","32.51857","0.01198"
"65100","390.56400","32.54721","0.01118"
"65157","390.90600","32.57561","0.01115"
"65214","391.24800","32.60407","0.01208"
"65271","391.59000","32.63259","0.01114"
"65328","391.93200","32.66111","0.01077"
"65385","392.27400","32.68963","0.01081"
"65442","392.61600","32.71815","0.01038"
"65499","392.95800","32.74660","0.01026"
"65556","393.30000","32.77518","0.01051"
"65613","393.64200","32.80365","0.01090"
"65670","393.98400","32.83205","0.01077"
"65727","394.32600","32.86063","0.01085"
"65784","394.66800","32.88909","0.00838"
"65841","395.01000","32.91760","0.02110"
"65898","395.35200","32.94619","0.01348"
"65955","395.69400","32.97464","0.01075"
"66012","396.03600","33.00304","0.01050"
"66069","396.37800","33.03168","0.00982"
"66126","396.72000","33.06009","0.00964"
"66183","397.06200","33.08866","0.00857"
"66240","397.40400","33.11718","0.01019"
"66297","397.74600","33.14552","0.01000"
"66354","398.08800","33.17410","0.00904"
"66411","398.43000","33.20262","0.00982"
"66468","398.77200","33.23108","0.00933"
"66525","399.11400","33.25966","0.00912"
"66582","399.45600","33.28806","0.00895"
"66639","399.79800","33.31664","0.01005"
"66696","400.14000","33.34516","0.00893"
"66753","400.48200","33.37356","0.00930"
"66810","400.82400","33.40214","0.00885"
"66867","401.16600","33.43060","0.01041"
"66924","401.50800","33.45912","0.00872"
"66981","401.85000","33.48764","0.00893"
"67038","402.19200","33.51610","0.00920"
"67095","402.53400","33.54462","0.01000"
"67152","402.87600","33.57307","0.00888"
"67209","403.21800","33.60154","0.00895"
"67266","403.56000","33.63018","0.00941"
"67323","403.90200","33.65864","0.01027"
"67380","404.24400","33.68710","0.00919"
"67437","404.58600","33.71562","0.00921"
"67494","404.92800","33.74408","0.00960"
"67551","405.27000","33.77259","0.00937"
"67608","405.61200","33.80112","0.00983"
"67665","405.95400","33.82957","0.00970"
"67722","406.29600","33.85809","0.01032"
"67779","406.63800","33.88662","0.00939"
"67836","406.98000","33.91507","0.00952"
"67893","407.32200","33.94365","0.00934"
"67950","407.66400","33.97218","0.01003"
"68007","408.00600","34.00057","0.00932"
"68064","408.34800","34.02915","0.00986"
"68121","408.69000","34.05761","0.00968"
"68178","409.03200","34.08601","0.01001"
"68235","409.37400","34.11465","0.00944"
"68292","409.71600","34.14311","0.00969"
"68349","410.05800","34.17163","0.00979"
"68406","410.40000","34.20009","0.00979"
"68463","410.74200","34.22861","0.00977"
"68520","411.08400","34.25713","0.00975"
"68577","411.42600","34.28565","0.00938"
"68634","411.76800","34.31411","0.00936"
"68691","412.11000","34.34263","0.00974"
"68748","412.45200","34.37115","0.00980"
"68805","412.79400","34.39961","0.00975"
"68862","413.13600","34.42813","0.00976"
"68919","413.47800","34.45659","0.00981"
"68976","413.82000","34.48505","0.00981"
"69033","414.16200","34.51369","0.00959"
"69090","414.50400","34.54209","0.00934"
"69147","414.84600","34.57067","0.00993"
"69204","415.18800","34.59919","0.00996"
"69261","415.53000","34.62753","0.00968"
"69318","415.87200","34.65617","0.00960"
"69375","416.21400","34.68468","0.00954"
"69432","416.55600","34.71309","0.01045"
"69489","416.89800","34.74166","0.00949"
"69546","417.24000","34.77007","0.00952"
"69577","417.42600","34.78567","0.00970"