File: Trajectories_together/161223Specimen_RawData_7.csv
"","V1","V2","V3"
"1","End date","12/23/2016",""
"2","Specimen label","24DG_92",""
"3","Maximum Load","0.21653","N"
"4","Time","Extension","Load"
"5","(s)","(mm)","(N)"
"6","0.00000","0.00000","-0.00011"
"47","0.24600","0.01901","0.00006"
"88","0.49200","0.04125","0.00071"
"129","0.73800","0.06170","0.00098"
"170","0.98400","0.08227","0.00087"
"211","1.23000","0.10266","0.00135"
"252","1.47600","0.12317","0.00146"
"293","1.72200","0.14361","0.00179"
"334","1.96800","0.16424","0.00190"
"375","2.21400","0.18469","0.00216"
"416","2.46000","0.20526","0.00211"
"457","2.70600","0.22571","0.00237"
"498","2.95200","0.24615","0.00219"
"539","3.19800","0.26672","0.00242"
"580","3.44400","0.28717","0.00234"
"621","3.69000","0.30768","0.00259"
"662","3.93600","0.32812","0.00233"
"703","4.18200","0.34875","0.00274"
"744","4.42800","0.36914","0.00296"
"785","4.67400","0.38965","0.00273"
"826","4.92000","0.41016","0.00298"
"867","5.16600","0.43072","0.00268"
"908","5.41200","0.45117","0.00315"
"949","5.65800","0.47168","0.00321"
"990","5.90400","0.49219","0.00277"
"1031","6.15000","0.51264","0.00278"
"1072","6.39600","0.53320","0.00254"
"1113","6.64200","0.55365","0.00262"
"1154","6.88800","0.57416","0.00304"
"1195","7.13400","0.59461","0.00300"
"1236","7.38000","0.61517","0.00301"
"1277","7.62600","0.63568","0.00292"
"1318","7.87200","0.65619","0.00265"
"1359","8.11800","0.67658","0.00318"
"1400","8.36400","0.69721","0.00308"
"1441","8.61000","0.71771","0.00366"
"1482","8.85600","0.73822","0.00307"
"1523","9.10200","0.75867","0.00337"
"1564","9.34800","0.77918","0.00286"
"1605","9.59400","0.79974","0.00297"
"1646","9.84000","0.82013","0.00297"
"1687","10.08600","0.84076","0.00282"
"1728","10.33200","0.86115","0.00312"
"1769","10.57800","0.88172","0.00332"
"1810","10.82400","0.90216","0.00285"
"1851","11.07000","0.92267","0.00324"
"1892","11.31600","0.94312","0.00331"
"1933","11.56200","0.96369","0.00302"
"1974","11.80800","0.98426","0.00316"
"2015","12.05400","1.00470","0.00308"
"2056","12.30000","1.02521","0.00340"
"2097","12.54600","1.04566","0.00328"
"2138","12.79200","1.06623","0.00351"
"2179","13.03800","1.08661","0.00354"
"2220","13.28400","1.10712","0.00358"
"2261","13.53000","1.12763","0.00317"
"2302","13.77600","1.14826","0.00368"
"2343","14.02200","1.16871","0.00367"
"2384","14.26800","1.18915","0.00379"
"2425","14.51400","1.20966","0.00322"
"2466","14.76000","1.23017","0.00327"
"2507","15.00600","1.25074","0.00330"
"2548","15.25200","1.27119","0.00367"
"2589","15.49800","1.29169","0.00357"
"2630","15.74400","1.31214","0.00327"
"2671","15.99000","1.33265","0.00354"
"2712","16.23600","1.35316","0.00370"
"2753","16.48200","1.37366","0.00373"
"2794","16.72800","1.39417","0.00354"
"2835","16.97400","1.41474","0.00358"
"2876","17.22000","1.43525","0.00347"
"2917","17.46600","1.45570","0.00346"
"2958","17.71200","1.47614","0.00404"
"2999","17.95800","1.49671","0.00354"
"3040","18.20400","1.51722","0.00379"
"3081","18.45000","1.53761","0.00413"
"3122","18.69600","1.55817","0.00386"
"3163","18.94200","1.57862","0.00370"
"3204","19.18800","1.59919","0.00380"
"3245","19.43400","1.61964","0.00389"
"3286","19.68000","1.64021","0.00361"
"3327","19.92600","1.66065","0.00414"
"3368","20.17200","1.68116","0.00399"
"3409","20.41800","1.70173","0.00376"
"3450","20.66400","1.72218","0.00378"
"3491","20.91000","1.74269","0.00396"
"3532","21.15600","1.76313","0.00410"
"3573","21.40200","1.78376","0.00392"
"3614","21.64800","1.80415","0.00401"
"3655","21.89400","1.82466","0.00400"
"3696","22.14000","1.84516","0.00394"
"3737","22.38600","1.86573","0.00412"
"3778","22.63200","1.88624","0.00422"
"3819","22.87800","1.90669","0.00407"
"3860","23.12400","1.92726","0.00428"
"3901","23.37000","1.94770","0.00404"
"3942","23.61600","1.96821","0.00436"
"3983","23.86200","1.98866","0.00390"
"4024","24.10800","2.00917","0.00400"
"4065","24.35400","2.02962","0.00388"
"4106","24.60000","2.05018","0.00403"
"4147","24.84600","2.07069","0.00383"
"4188","25.09200","2.09120","0.00416"
"4229","25.33800","2.11165","0.00404"
"4270","25.58400","2.13221","0.00415"
"4311","25.83000","2.15266","0.00384"
"4352","26.07600","2.17317","0.00395"
"4393","26.32200","2.19368","0.00423"
"4434","26.56800","2.21419","0.00402"
"4475","26.81400","2.23475","0.00442"
"4516","27.06000","2.25508","0.00411"
"4557","27.30600","2.27571","0.00397"
"4598","27.55200","2.29616","0.00412"
"4639","27.79800","2.31672","0.00411"
"4680","28.04400","2.33717","0.00405"
"4721","28.29000","2.35774","0.00394"
"4762","28.53600","2.37819","0.00426"
"4803","28.78200","2.39864","0.00442"
"4844","29.02800","2.41920","0.00426"
"4885","29.27400","2.43965","0.00430"
"4926","29.52000","2.46022","0.00409"
"4967","29.76600","2.48067","0.00407"
"5008","30.01200","2.50118","0.00414"
"5049","30.25800","2.52162","0.00435"
"5090","30.50400","2.54219","0.00413"
"5131","30.75000","2.56270","0.00415"
"5172","30.99600","2.58327","0.00421"
"5213","31.24200","2.60365","0.00472"
"5254","31.48800","2.62416","0.00416"
"5295","31.73400","2.64473","0.00450"
"5336","31.98000","2.66518","0.00417"
"5377","32.22600","2.68569","0.00467"
"5418","32.47200","2.70619","0.00431"
"5459","32.71800","2.72670","0.00424"
"5500","32.96400","2.74709","0.00430"
"5541","33.21000","2.76766","0.00434"
"5582","33.45600","2.78817","0.00429"
"5623","33.70200","2.80867","0.00431"
"5664","33.94800","2.82918","0.00465"
"5705","34.19400","2.84969","0.00413"
"5746","34.44000","2.87020","0.00415"
"5787","34.68600","2.89070","0.00458"
"5828","34.93200","2.91115","0.00470"
"5869","35.17800","2.93166","0.00418"
"5910","35.42400","2.95223","0.00454"
"5951","35.67000","2.97268","0.00421"
"5992","35.91600","2.99318","0.00447"
"6033","36.16200","3.01369","0.00451"
"6074","36.40800","3.03420","0.00432"
"6115","36.65400","3.05465","0.00454"
"6156","36.90000","3.07527","0.00472"
"6197","37.14600","3.09566","0.00455"
"6238","37.39200","3.11617","0.00469"
"6279","37.63800","3.13668","0.00438"
"6320","37.88400","3.15719","0.00458"
"6361","38.13000","3.17769","0.00461"
"6402","38.37600","3.19814","0.00439"
"6443","38.62200","3.21871","0.00457"
"6484","38.86800","3.23916","0.00478"
"6525","39.11400","3.25967","0.00453"
"6566","39.36000","3.28011","0.00458"
"6607","39.60600","3.30074","0.00495"
"6648","39.85200","3.32113","0.00447"
"6689","40.09800","3.34170","0.00480"
"6730","40.34400","3.36226","0.00480"
"6771","40.59000","3.38265","0.00458"
"6812","40.83600","3.40322","0.00470"
"6853","41.08200","3.42367","0.00439"
"6894","41.32800","3.44424","0.00445"
"6935","41.57400","3.46462","0.00487"
"6976","41.82000","3.48519","0.00473"
"7017","42.06600","3.50570","0.00498"
"7058","42.31200","3.52621","0.00462"
"7099","42.55800","3.54666","0.00474"
"7140","42.80400","3.56722","0.00491"
"7181","43.05000","3.58767","0.00497"
"7222","43.29600","3.60824","0.00473"
"7263","43.54200","3.62869","0.00491"
"7304","43.78800","3.64919","0.00492"
"7345","44.03400","3.66970","0.00456"
"7386","44.28000","3.69009","0.00457"
"7427","44.52600","3.71072","0.00446"
"7468","44.77200","3.73117","0.00499"
"7509","45.01800","3.75167","0.00499"
"7550","45.26400","3.77212","0.00480"
"7591","45.51000","3.79269","0.00456"
"7632","45.75600","3.81314","0.00487"
"7673","46.00200","3.83365","0.00467"
"7714","46.24800","3.85421","0.00505"
"7755","46.49400","3.87466","0.00479"
"7796","46.74000","3.89523","0.00478"
"7837","46.98600","3.91568","0.00497"
"7878","47.23200","3.93624","0.00469"
"7919","47.47800","3.95663","0.00508"
"7960","47.72400","3.97714","0.00507"
"8001","47.97000","3.99765","0.00482"
"8042","48.21600","4.01822","0.00500"
"8083","48.46200","4.03872","0.00482"
"8124","48.70800","4.05917","0.00500"
"8165","48.95400","4.07974","0.00473"
"8206","49.20000","4.10019","0.00474"
"8247","49.44600","4.12069","0.00512"
"8288","49.69200","4.14114","0.00466"
"8329","49.93800","4.16171","0.00454"
"8370","50.18400","4.18210","0.00472"
"8411","50.43000","4.20267","0.00504"
"8452","50.67600","4.22311","0.00477"
"8493","50.92200","4.24368","0.00470"
"8534","51.16800","4.26413","0.00477"
"8575","51.41400","4.28470","0.00501"
"8616","51.66000","4.30521","0.00455"
"8657","51.90600","4.32571","0.00502"
"8698","52.15200","4.34616","0.00475"
"8739","52.39800","4.36667","0.00487"
"8780","52.64400","4.38718","0.00522"
"8821","52.89000","4.40762","0.00474"
"8862","53.13600","4.42825","0.00520"
"8903","53.38200","4.44864","0.00476"
"8944","53.62800","4.46921","0.00500"
"8985","53.87400","4.48966","0.00490"
"9026","54.12000","4.51022","0.00513"
"9067","54.36600","4.53067","0.00463"
"9108","54.61200","4.55118","0.00476"
"9149","54.85800","4.57169","0.00458"
"9190","55.10400","4.59219","0.00498"
"9231","55.35000","4.61270","0.00476"
"9272","55.59600","4.63315","0.00484"
"9313","55.84200","4.65372","0.00502"
"9354","56.08800","4.67417","0.00514"
"9395","56.33400","4.69467","0.00532"
"9436","56.58000","4.71518","0.00467"
"9477","56.82600","4.73575","0.00428"
"9518","57.07200","4.75614","0.00518"
"9559","57.31800","4.77665","0.00498"
"9600","57.56400","4.79721","0.00462"
"9641","57.81000","4.81766","0.00505"
"9682","58.05600","4.83823","0.00490"
"9723","58.30200","4.85868","0.00500"
"9764","58.54800","4.87918","0.00505"
"9805","58.79400","4.89969","0.00517"
"9846","59.04000","4.92020","0.00486"
"9887","59.28600","4.94065","0.00488"
"9928","59.53200","4.96122","0.00498"
"9969","59.77800","4.98166","0.00475"
"10010","60.02400","5.00223","0.00478"
"10051","60.27000","5.02274","0.00497"
"10092","60.51600","5.04319","0.00492"
"10133","60.76200","5.06364","0.00510"
"10174","61.00800","5.08420","0.00545"
"10215","61.25400","5.10471","0.00480"
"10256","61.50000","5.12510","0.00494"
"10297","61.74600","5.14573","0.00521"
"10338","61.99200","5.16611","0.00555"
"10379","62.23800","5.18668","0.00526"
"10420","62.48400","5.20719","0.00514"
"10461","62.73000","5.22776","0.00541"
"10502","62.97600","5.24821","0.00498"
"10543","63.22200","5.26865","0.00515"
"10584","63.46800","5.28922","0.00505"
"10625","63.71400","5.30967","0.00528"
"10666","63.96000","5.33024","0.00520"
"10707","64.20600","5.35069","0.00547"
"10748","64.45200","5.37125","0.00535"
"10789","64.69800","5.39164","0.00489"
"10830","64.94400","5.41215","0.00505"
"10871","65.19000","5.43266","0.00540"
"10912","65.43600","5.45322","0.00542"
"10953","65.68200","5.47367","0.00549"
"10994","65.92800","5.49418","0.00526"
"11035","66.17400","5.51469","0.00535"
"11076","66.42000","5.53520","0.00540"
"11117","66.66600","5.55570","0.00469"
"11158","66.91200","5.57615","0.00531"
"11199","67.15800","5.59672","0.00487"
"11240","67.40400","5.61711","0.00545"
"11281","67.65000","5.63773","0.00558"
"11322","67.89600","5.65818","0.00551"
"11363","68.14200","5.67869","0.00558"
"11404","68.38800","5.69914","0.00550"
"11445","68.63400","5.71971","0.00504"
"11486","68.88000","5.74021","0.00549"
"11527","69.12600","5.76066","0.00604"
"11568","69.37200","5.78117","0.00530"
"11609","69.61800","5.80168","0.00567"
"11650","69.86400","5.82219","0.00537"
"11691","70.11000","5.84263","0.00561"
"11732","70.35600","5.86320","0.00566"
"11773","70.60200","5.88365","0.00571"
"11814","70.84800","5.90422","0.00547"
"11855","71.09400","5.92466","0.00568"
"11896","71.34000","5.94517","0.00542"
"11937","71.58600","5.96568","0.00563"
"11978","71.83200","5.98619","0.00572"
"12019","72.07800","6.00664","0.00615"
"12060","72.32400","6.02714","0.00580"
"12101","72.57000","6.04771","0.00573"
"12142","72.81600","6.06816","0.00591"
"12183","73.06200","6.08879","0.00588"
"12224","73.30800","6.10912","0.00552"
"12265","73.55400","6.12968","0.00571"
"12306","73.80000","6.15019","0.00592"
"12347","74.04600","6.17076","0.00574"
"12388","74.29200","6.19121","0.00608"
"12429","74.53800","6.21165","0.00549"
"12470","74.78400","6.23222","0.00567"
"12511","75.03000","6.25267","0.00558"
"12552","75.27600","6.27324","0.00536"
"12593","75.52200","6.29368","0.00601"
"12634","75.76800","6.31419","0.00575"
"12675","76.01400","6.33464","0.00605"
"12716","76.26000","6.35515","0.00591"
"12757","76.50600","6.37572","0.00583"
"12798","76.75200","6.39616","0.00564"
"12839","76.99800","6.41661","0.00600"
"12880","77.24400","6.43724","0.00574"
"12921","77.49000","6.45769","0.00577"
"12962","77.73600","6.47820","0.00528"
"13003","77.98200","6.49864","0.00544"
"13044","78.22800","6.51921","0.00569"
"13085","78.47400","6.53972","0.00557"
"13126","78.72000","6.56011","0.00555"
"13167","78.96600","6.58068","0.00575"
"13208","79.21200","6.60112","0.00563"
"13249","79.45800","6.62175","0.00569"
"13290","79.70400","6.64220","0.00537"
"13331","79.95000","6.66271","0.00548"
"13372","80.19600","6.68315","0.00567"
"13413","80.44200","6.70366","0.00556"
"13454","80.68800","6.72423","0.00587"
"13495","80.93400","6.74468","0.00577"
"13536","81.18000","6.76519","0.00573"
"13577","81.42600","6.78569","0.00552"
"13618","81.67200","6.80626","0.00573"
"13659","81.91800","6.82665","0.00583"
"13700","82.16400","6.84716","0.00558"
"13741","82.41000","6.86767","0.00568"
"13782","82.65600","6.88817","0.00599"
"13823","82.90200","6.90868","0.00556"
"13864","83.14800","6.92919","0.00577"
"13905","83.39400","6.94970","0.00554"
"13946","83.64000","6.97014","0.00567"
"13987","83.88600","6.99071","0.00569"
"14028","84.13200","7.01116","0.00552"
"14069","84.37800","7.03173","0.00537"
"14110","84.62400","7.05212","0.00603"
"14151","84.87000","7.07268","0.00589"
"14192","85.11600","7.09319","0.00577"
"14233","85.36200","7.11370","0.00581"
"14274","85.60800","7.13415","0.00551"
"14315","85.85400","7.15471","0.00596"
"14356","86.10000","7.17522","0.00599"
"14397","86.34600","7.19567","0.00603"
"14438","86.59200","7.21618","0.00590"
"14479","86.83800","7.23663","0.00548"
"14520","87.08400","7.25725","0.00549"
"14561","87.33000","7.27764","0.00577"
"14602","87.57600","7.29821","0.00582"
"14643","87.82200","7.31866","0.00570"
"14684","88.06800","7.33917","0.00606"
"14725","88.31400","7.35967","0.00585"
"14766","88.56000","7.38024","0.00590"
"14807","88.80600","7.40069","0.00595"
"14848","89.05200","7.42114","0.00572"
"14889","89.29800","7.44170","0.00576"
"14930","89.54400","7.46215","0.00526"
"14971","89.79000","7.48266","0.00587"
"15012","90.03600","7.50317","0.00561"
"15053","90.28200","7.52374","0.00619"
"15094","90.52800","7.54412","0.00588"
"15135","90.77400","7.56463","0.00573"
"15176","91.02000","7.58514","0.00615"
"15217","91.26600","7.60577","0.00607"
"15258","91.51200","7.62616","0.00634"
"15299","91.75800","7.64666","0.00606"
"15340","92.00400","7.66717","0.00637"
"15381","92.25000","7.68768","0.00597"
"15422","92.49600","7.70825","0.00586"
"15463","92.74200","7.72869","0.00613"
"15504","92.98800","7.74920","0.00582"
"15545","93.23400","7.76959","0.00595"
"15586","93.48000","7.79016","0.00606"
"15627","93.72600","7.81067","0.00600"
"15668","93.97200","7.83117","0.00633"
"15709","94.21800","7.85162","0.00610"
"15750","94.46400","7.87219","0.00579"
"15791","94.71000","7.89270","0.00586"
"15832","94.95600","7.91320","0.00624"
"15873","95.20200","7.93365","0.00624"
"15914","95.44800","7.95422","0.00632"
"15955","95.69400","7.97473","0.00626"
"15996","95.94000","7.99512","0.00625"
"16037","96.18600","8.01574","0.00652"
"16078","96.43200","8.03613","0.00628"
"16119","96.67800","8.05670","0.00597"
"16160","96.92400","8.07715","0.00630"
"16201","97.17000","8.09771","0.00627"
"16242","97.41600","8.11816","0.00631"
"16283","97.66200","8.13867","0.00623"
"16324","97.90800","8.15924","0.00646"
"16365","98.15400","8.17969","0.00646"
"16406","98.40000","8.20019","0.00691"
"16447","98.64600","8.22064","0.00672"
"16488","98.89200","8.24121","0.00663"
"16529","99.13800","8.26166","0.00668"
"16570","99.38400","8.28217","0.00645"
"16611","99.63000","8.30261","0.00673"
"16652","99.87600","8.32324","0.00696"
"16693","100.12200","8.34369","0.00680"
"16734","100.36800","8.36420","0.00697"
"16775","100.61400","8.38470","0.00683"
"16816","100.86000","8.40515","0.00693"
"16857","101.10600","8.42572","0.00696"
"16898","101.35200","8.44623","0.00684"
"16939","101.59800","8.46668","0.00662"
"16980","101.84400","8.48712","0.00708"
"17021","102.09000","8.50769","0.00713"
"17062","102.33600","8.52814","0.00673"
"17103","102.58200","8.54865","0.00689"
"17144","102.82800","8.56916","0.00705"
"17185","103.07400","8.58972","0.00694"
"17226","103.32000","8.61023","0.00671"
"17267","103.56600","8.63068","0.00677"
"17308","103.81200","8.65119","0.00703"
"17349","104.05800","8.67169","0.00694"
"17390","104.30400","8.69226","0.00692"
"17431","104.55000","8.71259","0.00688"
"17472","104.79600","8.73322","0.00705"
"17513","105.04200","8.75367","0.00655"
"17554","105.28800","8.77417","0.00705"
"17595","105.53400","8.79468","0.00753"
"17636","105.78000","8.81525","0.00701"
"17677","106.02600","8.83570","0.00702"
"17718","106.27200","8.85614","0.00723"
"17759","106.51800","8.87671","0.00712"
"17800","106.76400","8.89722","0.00720"
"17841","107.01000","8.91773","0.00694"
"17882","107.25600","8.93818","0.00723"
"17923","107.50200","8.95868","0.00706"
"17964","107.74800","8.97919","0.00727"
"18005","107.99400","8.99970","0.00698"
"18046","108.24000","9.02015","0.00730"
"18087","108.48600","9.04072","0.00716"
"18128","108.73200","9.06116","0.00727"
"18169","108.97800","9.08173","0.00711"
"18210","109.22400","9.10224","0.00682"
"18251","109.47000","9.12269","0.00688"
"18292","109.71600","9.14320","0.00708"
"18333","109.96200","9.16364","0.00704"
"18374","110.20800","9.18415","0.00734"
"18415","110.45400","9.20460","0.00694"
"18456","110.70000","9.22517","0.00733"
"18497","110.94600","9.24567","0.00675"
"18538","111.19200","9.26618","0.00767"
"18579","111.43800","9.28669","0.00694"
"18620","111.68400","9.30720","0.00747"
"18661","111.93000","9.32771","0.00691"
"18702","112.17600","9.34815","0.00713"
"18743","112.42200","9.36872","0.00735"
"18784","112.66800","9.38917","0.00752"
"18825","112.91400","9.40974","0.00721"
"18866","113.16000","9.43012","0.00753"
"18907","113.40600","9.45069","0.00754"
"18948","113.65200","9.47120","0.00693"
"18989","113.89800","9.49171","0.00718"
"19030","114.14400","9.51216","0.00732"
"19071","114.39000","9.53272","0.00725"
"19112","114.63600","9.55317","0.00704"
"19153","114.88200","9.57368","0.00704"
"19194","115.12800","9.59419","0.00736"
"19235","115.37400","9.61464","0.00696"
"19276","115.62000","9.63520","0.00719"
"19317","115.86600","9.65565","0.00706"
"19358","116.11200","9.67628","0.00721"
"19399","116.35800","9.69661","0.00720"
"19440","116.60400","9.71711","0.00694"
"19481","116.85000","9.73768","0.00651"
"19522","117.09600","9.75825","0.00675"
"19563","117.34200","9.77864","0.00685"
"19604","117.58800","9.79920","0.00691"
"19645","117.83400","9.81971","0.00716"
"19686","118.08000","9.84016","0.00714"
"19727","118.32600","9.86073","0.00717"
"19768","118.57200","9.88118","0.00697"
"19809","118.81800","9.90168","0.00699"
"19850","119.06400","9.92213","0.00697"
"19891","119.31000","9.94270","0.00711"
"19932","119.55600","9.96321","0.00749"
"19973","119.80200","9.98372","0.00724"
"20014","120.04800","10.00416","0.00720"
"20055","120.29400","10.02473","0.00758"
"20096","120.54000","10.04524","0.00718"
"20137","120.78600","10.06569","0.00746"
"20178","121.03200","10.08620","0.00737"
"20219","121.27800","10.10670","0.00724"
"20260","121.52400","10.12721","0.00700"
"20301","121.77000","10.14760","0.00765"
"20342","122.01600","10.16817","0.00744"
"20383","122.26200","10.18867","0.00756"
"20424","122.50800","10.20918","0.00741"
"20465","122.75400","10.22969","0.00720"
"20506","123.00000","10.25014","0.00786"
"20547","123.24600","10.27065","0.00730"
"20588","123.49200","10.29121","0.00737"
"20629","123.73800","10.31172","0.00734"
"20670","123.98400","10.33217","0.00748"
"20711","124.23000","10.35274","0.00758"
"20752","124.47600","10.37318","0.00739"
"20793","124.72200","10.39375","0.00724"
"20834","124.96800","10.41414","0.00785"
"20875","125.21400","10.43465","0.00768"
"20916","125.46000","10.45516","0.00753"
"20957","125.70600","10.47572","0.00767"
"20998","125.95200","10.49617","0.00724"
"21039","126.19800","10.51668","0.00749"
"21080","126.44400","10.53719","0.00762"
"21121","126.69000","10.55770","0.00743"
"21162","126.93600","10.57820","0.00770"
"21203","127.18200","10.59871","0.00795"
"21244","127.42800","10.61922","0.00784"
"21285","127.67400","10.63961","0.00774"
"21326","127.92000","10.66018","0.00824"
"21367","128.16600","10.68068","0.00790"
"21408","128.41200","10.70125","0.00742"
"21449","128.65800","10.72164","0.00752"
"21490","128.90400","10.74221","0.00801"
"21531","129.15000","10.76271","0.00764"
"21572","129.39600","10.78316","0.00796"
"21613","129.64200","10.80373","0.00789"
"21654","129.88800","10.82418","0.00806"
"21695","130.13400","10.84468","0.00821"
"21736","130.38000","10.86513","0.00824"
"21777","130.62600","10.88570","0.00818"
"21818","130.87200","10.90615","0.00794"
"21859","131.11800","10.92672","0.00796"
"21900","131.36400","10.94717","0.00817"
"21941","131.61000","10.96773","0.00830"
"21982","131.85600","10.98818","0.00825"
"22023","132.10200","11.00869","0.00837"
"22064","132.34800","11.02920","0.00845"
"22105","132.59400","11.04970","0.00855"
"22146","132.84000","11.07021","0.00796"
"22187","133.08600","11.09066","0.00816"
"22228","133.33200","11.11123","0.00876"
"22269","133.57800","11.13162","0.00795"
"22310","133.82400","11.15218","0.00864"
"22351","134.07000","11.17263","0.00839"
"22392","134.31600","11.19326","0.00833"
"22433","134.56200","11.21365","0.00818"
"22474","134.80800","11.23421","0.00835"
"22515","135.05400","11.25472","0.00830"
"22556","135.30000","11.27517","0.00841"
"22597","135.54600","11.29568","0.00874"
"22638","135.79200","11.31613","0.00883"
"22679","136.03800","11.33663","0.00907"
"22720","136.28400","11.35714","0.00872"
"22761","136.53000","11.37771","0.00901"
"22802","136.77600","11.39816","0.00906"
"22843","137.02200","11.41866","0.00890"
"22884","137.26800","11.43911","0.00877"
"22925","137.51400","11.45968","0.00851"
"22966","137.76000","11.48019","0.00867"
"23007","138.00600","11.50070","0.00866"
"23048","138.25200","11.52120","0.00890"
"23089","138.49800","11.54165","0.00844"
"23130","138.74400","11.56222","0.00897"
"23171","138.99000","11.58267","0.00880"
"23212","139.23600","11.60324","0.00905"
"23253","139.48200","11.62362","0.00900"
"23294","139.72800","11.64419","0.00892"
"23335","139.97400","11.66470","0.00894"
"23376","140.22000","11.68521","0.00915"
"23417","140.46600","11.70572","0.00930"
"23458","140.71200","11.72616","0.00896"
"23499","140.95800","11.74673","0.00924"
"23540","141.20400","11.76718","0.00890"
"23581","141.45000","11.78769","0.00913"
"23622","141.69600","11.80814","0.00919"
"23663","141.94200","11.82876","0.00956"
"23704","142.18800","11.84915","0.00928"
"23745","142.43400","11.86966","0.00953"
"23786","142.68000","11.89011","0.00931"
"23827","142.92600","11.91073","0.00939"
"23868","143.17200","11.93118","0.01004"
"23909","143.41800","11.95169","0.00922"
"23950","143.66400","11.97214","0.00961"
"23991","143.91000","11.99270","0.00962"
"24032","144.15600","12.01321","0.00982"
"24073","144.40200","12.03366","0.00984"
"24114","144.64800","12.05423","0.00962"
"24155","144.89400","12.07462","0.00982"
"24196","145.14000","12.09518","0.00977"
"24237","145.38600","12.11569","0.00966"
"24278","145.63200","12.13620","0.01000"
"24319","145.87800","12.15665","0.00987"
"24360","146.12400","12.17721","0.00980"
"24401","146.37000","12.19772","0.00954"
"24442","146.61600","12.21817","0.00987"
"24483","146.86200","12.23862","0.01006"
"24524","147.10800","12.25919","0.00992"
"24565","147.35400","12.27969","0.00982"
"24606","147.60000","12.30014","0.01056"
"24647","147.84600","12.32071","0.01022"
"24688","148.09200","12.34116","0.01039"
"24729","148.33800","12.36167","0.01046"
"24770","148.58400","12.38211","0.00992"
"24811","148.83000","12.40268","0.01037"
"24852","149.07600","12.42319","0.01009"
"24893","149.32200","12.44364","0.01016"
"24934","149.56800","12.46420","0.01006"
"24975","149.81400","12.48471","0.01043"
"25016","150.06000","12.50522","0.01053"
"25057","150.30600","12.52567","0.01038"
"25098","150.55200","12.54624","0.01085"
"25139","150.79800","12.56662","0.01058"
"25180","151.04400","12.58719","0.01054"
"25221","151.29000","12.60764","0.01084"
"25262","151.53600","12.62821","0.01083"
"25303","151.78200","12.64872","0.01084"
"25344","152.02800","12.66922","0.01147"
"25385","152.27400","12.68973","0.01099"
"25426","152.52000","12.71024","0.01132"
"25467","152.76600","12.73069","0.01102"
"25508","153.01200","12.75113","0.01101"
"25549","153.25800","12.77170","0.01164"
"25590","153.50400","12.79209","0.01107"
"25631","153.75000","12.81266","0.01167"
"25672","153.99600","12.83317","0.01110"
"25713","154.24200","12.85367","0.01154"
"25754","154.48800","12.87412","0.01187"
"25795","154.73400","12.89475","0.01142"
"25836","154.98000","12.91520","0.01130"
"25877","155.22600","12.93571","0.01177"
"25918","155.47200","12.95621","0.01187"
"25959","155.71800","12.97666","0.01202"
"26000","155.96400","12.99723","0.01165"
"26041","156.21000","13.01762","0.01220"
"26082","156.45600","13.03818","0.01201"
"26123","156.70200","13.05863","0.01213"
"26164","156.94800","13.07920","0.01251"
"26205","157.19400","13.09965","0.01214"
"26246","157.44000","13.12022","0.01203"
"26287","157.68600","13.14066","0.01216"
"26328","157.93200","13.16117","0.01212"
"26369","158.17800","13.18168","0.01227"
"26410","158.42400","13.20219","0.01225"
"26451","158.67000","13.22269","0.01283"
"26492","158.91600","13.24314","0.01235"
"26533","159.16200","13.26371","0.01258"
"26574","159.40800","13.28416","0.01259"
"26615","159.65400","13.30467","0.01247"
"26656","159.90000","13.32517","0.01286"
"26697","160.14600","13.34574","0.01274"
"26738","160.39200","13.36619","0.01237"
"26779","160.63800","13.38670","0.01306"
"26820","160.88400","13.40720","0.01319"
"26861","161.13000","13.42771","0.01295"
"26902","161.37600","13.44816","0.01348"
"26943","161.62200","13.46867","0.01343"
"26984","161.86800","13.48924","0.01392"
"27025","162.11400","13.50962","0.01309"
"27066","162.36000","13.53013","0.01332"
"27107","162.60600","13.55070","0.01354"
"27148","162.85200","13.57121","0.01374"
"27189","163.09800","13.59166","0.01413"
"27230","163.34400","13.61222","0.01358"
"27271","163.59000","13.63273","0.01403"
"27312","163.83600","13.65318","0.01430"
"27353","164.08200","13.67363","0.01421"
"27394","164.32800","13.69413","0.01407"
"27435","164.57400","13.71470","0.01448"
"27476","164.82000","13.73515","0.01444"
"27517","165.06600","13.75572","0.01445"
"27558","165.31200","13.77617","0.01449"
"27599","165.55800","13.79667","0.01453"
"27640","165.80400","13.81718","0.01487"
"27681","166.05000","13.83775","0.01524"
"27722","166.29600","13.85814","0.01508"
"27763","166.54200","13.87864","0.01489"
"27804","166.78800","13.89921","0.01560"
"27845","167.03400","13.91966","0.01556"
"27886","167.28000","13.94023","0.01596"
"27927","167.52600","13.96068","0.01580"
"27968","167.77200","13.98124","0.01566"
"28009","168.01800","14.00163","0.01572"
"28050","168.26400","14.02220","0.01558"
"28091","168.51000","14.04265","0.01602"
"28132","168.75600","14.06322","0.01607"
"28173","169.00200","14.08366","0.01632"
"28214","169.24800","14.10417","0.01592"
"28255","169.49400","14.12474","0.01617"
"28296","169.74000","14.14519","0.01613"
"28337","169.98600","14.16570","0.01659"
"28378","170.23200","14.18620","0.01633"
"28419","170.47800","14.20671","0.01680"
"28460","170.72400","14.22710","0.01720"
"28501","170.97000","14.24773","0.01737"
"28542","171.21600","14.26823","0.01724"
"28583","171.46200","14.28868","0.01718"
"28624","171.70800","14.30913","0.01712"
"28665","171.95400","14.32970","0.01714"
"28706","172.20000","14.35021","0.01748"
"28747","172.44600","14.37071","0.01764"
"28788","172.69200","14.39122","0.01767"
"28829","172.93800","14.41167","0.01808"
"28870","173.18400","14.43224","0.01796"
"28911","173.43000","14.45263","0.01807"
"28952","173.67600","14.47319","0.01827"
"28993","173.92200","14.49370","0.01855"
"29034","174.16800","14.51415","0.01853"
"29075","174.41400","14.53466","0.01902"
"29116","174.66000","14.55522","0.01880"
"29157","174.90600","14.57567","0.01931"
"29198","175.15200","14.59618","0.01956"
"29239","175.39800","14.61669","0.01960"
"29280","175.64400","14.63720","0.01997"
"29321","175.89000","14.65770","0.02010"
"29362","176.13600","14.67815","0.01951"
"29403","176.38200","14.69872","0.02026"
"29444","176.62800","14.71917","0.01997"
"29485","176.87400","14.73967","0.02023"
"29526","177.12000","14.76012","0.02005"
"29567","177.36600","14.78075","0.02069"
"29608","177.61200","14.80120","0.02095"
"29649","177.85800","14.82171","0.02034"
"29690","178.10400","14.84221","0.02094"
"29731","178.35000","14.86266","0.02102"
"29772","178.59600","14.88317","0.02152"
"29813","178.84200","14.90368","0.02191"
"29854","179.08800","14.92418","0.02165"
"29895","179.33400","14.94463","0.02178"
"29936","179.58000","14.96520","0.02209"
"29977","179.82600","14.98559","0.02242"
"30018","180.07200","15.00622","0.02195"
"30059","180.31800","15.02661","0.02264"
"30100","180.56400","15.04717","0.02263"
"30141","180.81000","15.06774","0.02258"
"30182","181.05600","15.08819","0.02352"
"30223","181.30200","15.10864","0.02368"
"30264","181.54800","15.12920","0.02399"
"30305","181.79400","15.14971","0.02411"
"30346","182.04000","15.17010","0.02455"
"30387","182.28600","15.19073","0.02462"
"30428","182.53200","15.21117","0.02508"
"30469","182.77800","15.23168","0.02492"
"30510","183.02400","15.25219","0.02514"
"30551","183.27000","15.27270","0.02505"
"30592","183.51600","15.29315","0.02518"
"30633","183.76200","15.31371","0.02551"
"30674","184.00800","15.33422","0.02580"
"30715","184.25400","15.35473","0.02619"
"30756","184.50000","15.37518","0.02631"
"30797","184.74600","15.39563","0.02693"
"30838","184.99200","15.41625","0.02687"
"30879","185.23800","15.43664","0.02638"
"30920","185.48400","15.45715","0.02772"
"30961","185.73000","15.47760","0.02690"
"31002","185.97600","15.49828","0.02775"
"31043","186.22200","15.51867","0.02789"
"31084","186.46800","15.53912","0.02820"
"31125","186.71400","15.55969","0.02799"
"31166","186.96000","15.58014","0.02836"
"31207","187.20600","15.60070","0.02862"
"31248","187.45200","15.62115","0.02866"
"31289","187.69800","15.64166","0.02886"
"31330","187.94400","15.66211","0.02886"
"31371","188.19000","15.68268","0.02897"
"31412","188.43600","15.70318","0.02914"
"31453","188.68200","15.72369","0.02933"
"31494","188.92800","15.74414","0.02924"
"31535","189.17400","15.76471","0.02929"
"31576","189.42000","15.78521","0.03001"
"31617","189.66600","15.80566","0.02930"
"31658","189.91200","15.82611","0.02873"
"31699","190.15800","15.84668","0.02739"
"31740","190.40400","15.86724","0.02785"
"31781","190.65000","15.88763","0.02755"
"31822","190.89600","15.90826","0.02739"
"31863","191.14200","15.92865","0.02753"
"31904","191.38800","15.94922","0.02744"
"31945","191.63400","15.96966","0.02723"
"31986","191.88000","15.99023","0.02802"
"32027","192.12600","16.01068","0.02769"
"32068","192.37200","16.03113","0.02699"
"32109","192.61800","16.05169","0.02717"
"32150","192.86400","16.07214","0.02731"
"32191","193.11000","16.09271","0.02730"
"32232","193.35600","16.11316","0.02690"
"32273","193.60200","16.13373","0.02722"
"32314","193.84800","16.15411","0.02737"
"32355","194.09400","16.17462","0.02723"
"32396","194.34000","16.19513","0.02747"
"32437","194.58600","16.21576","0.02755"
"32478","194.83200","16.23615","0.02743"
"32519","195.07800","16.25671","0.02758"
"32560","195.32400","16.27722","0.02844"
"32601","195.57000","16.29773","0.02864"
"32642","195.81600","16.31824","0.02861"
"32683","196.06200","16.33863","0.02840"
"32724","196.30800","16.35919","0.02897"
"32765","196.55400","16.37964","0.02914"
"32806","196.80000","16.40021","0.02923"
"32847","197.04600","16.42072","0.02888"
"32888","197.29200","16.44116","0.02968"
"32929","197.53800","16.46167","0.02978"
"32970","197.78400","16.48224","0.03028"
"33011","198.03000","16.50269","0.03014"
"33052","198.27600","16.52320","0.03029"
"33093","198.52200","16.54370","0.03066"
"33134","198.76800","16.56421","0.03114"
"33175","199.01400","16.58472","0.03097"
"33216","199.26000","16.60517","0.03140"
"33257","199.50600","16.62568","0.03150"
"33298","199.75200","16.64612","0.03170"
"33339","199.99800","16.66669","0.03201"
"33380","200.24400","16.68720","0.03232"
"33421","200.49000","16.70771","0.03196"
"33462","200.73600","16.72816","0.03227"
"33503","200.98200","16.74866","0.03207"
"33544","201.22800","16.76917","0.03248"
"33585","201.47400","16.78968","0.03244"
"33626","201.72000","16.81019","0.03261"
"33667","201.96600","16.83064","0.03280"
"33708","202.21200","16.85126","0.03320"
"33749","202.45800","16.87165","0.03338"
"33790","202.70400","16.89216","0.03331"
"33831","202.95000","16.91266","0.03424"
"33872","203.19600","16.93323","0.03393"
"33913","203.44200","16.95368","0.03447"
"33954","203.69000","16.97437","0.03506"
"33995","203.93600","16.99487","0.03545"
"34036","204.18200","17.01532","0.03487"
"34077","204.42800","17.03589","0.03540"
"34118","204.67600","17.05652","0.03590"
"34159","204.92200","17.07703","0.03639"
"34200","205.16800","17.09742","0.03664"
"34241","205.41400","17.11804","0.03689"
"34282","205.66000","17.13849","0.03738"
"34323","205.90600","17.15906","0.03815"
"34364","206.15200","17.17951","0.03761"
"34405","206.39800","17.20001","0.03754"
"34446","206.64400","17.22058","0.03908"
"34487","206.89000","17.24103","0.03771"
"34528","207.13600","17.26148","0.03855"
"34569","207.38200","17.28205","0.03962"
"34610","207.62800","17.30255","0.03970"
"34651","207.87400","17.32294","0.03975"
"34692","208.12000","17.34351","0.04008"
"34733","208.36600","17.36396","0.04022"
"34774","208.61200","17.38452","0.04114"
"34815","208.85800","17.40503","0.04202"
"34856","209.10400","17.42554","0.04322"
"34897","209.35000","17.44599","0.04240"
"34938","209.59600","17.46650","0.04442"
"34979","209.84200","17.48706","0.04352"
"35020","210.08800","17.50757","0.04464"
"35061","210.33400","17.52802","0.04477"
"35102","210.58000","17.54847","0.04506"
"35143","210.82600","17.56903","0.04581"
"35184","211.07200","17.58948","0.04554"
"35225","211.31800","17.60993","0.04668"
"35266","211.56400","17.63050","0.04707"
"35307","211.81000","17.65107","0.04740"
"35348","212.05600","17.67151","0.04734"
"35389","212.30200","17.69202","0.04836"
"35430","212.54800","17.71253","0.04880"
"35471","212.79400","17.73304","0.04892"
"35512","213.04000","17.75348","0.04956"
"35553","213.28600","17.77399","0.04953"
"35594","213.53200","17.79456","0.05022"
"35635","213.77800","17.81495","0.05011"
"35676","214.02400","17.83552","0.05055"
"35717","214.27000","17.85602","0.05069"
"35758","214.51600","17.87653","0.05081"
"35799","214.76200","17.89698","0.05166"
"35840","215.00800","17.91755","0.05159"
"35881","215.25400","17.93806","0.05227"
"35922","215.50000","17.95850","0.05207"
"35963","215.74600","17.97901","0.05250"
"36004","215.99200","17.99946","0.05326"
"36045","216.23800","18.02009","0.05362"
"36086","216.48400","18.04047","0.05414"
"36127","216.73000","18.06104","0.05475"
"36168","216.97600","18.08149","0.05538"
"36209","217.22200","18.10200","0.05550"
"36250","217.46800","18.12245","0.05670"
"36291","217.71400","18.14307","0.05707"
"36332","217.96000","18.16346","0.05756"
"36373","218.20600","18.18397","0.05823"
"36414","218.45200","18.20454","0.05867"
"36455","218.69800","18.22499","0.05972"
"36496","218.94400","18.24555","0.06007"
"36537","219.19000","18.26600","0.06048"
"36578","219.43600","18.28657","0.06086"
"36619","219.68200","18.30696","0.06207"
"36660","219.92800","18.32747","0.06228"
"36701","220.17400","18.34797","0.06334"
"36742","220.42000","18.36860","0.06482"
"36783","220.66600","18.38899","0.06468"
"36824","220.91200","18.40956","0.06633"
"36865","221.15800","18.43000","0.06640"
"36906","221.40400","18.45051","0.06785"
"36947","221.65000","18.47102","0.06893"
"36988","221.89600","18.49147","0.07011"
"37029","222.14200","18.51204","0.07091"
"37070","222.38800","18.53242","0.07161"
"37111","222.63400","18.55299","0.07221"
"37152","222.88000","18.57356","0.07316"
"37193","223.12600","18.59401","0.07391"
"37234","223.37200","18.61445","0.07524"
"37275","223.61800","18.63502","0.07593"
"37316","223.86400","18.65553","0.07634"
"37357","224.11000","18.67604","0.07669"
"37398","224.35600","18.69655","0.07741"
"37439","224.60200","18.71705","0.07759"
"37480","224.84800","18.73756","0.07781"
"37521","225.09400","18.75795","0.07884"
"37562","225.34000","18.77852","0.07945"
"37603","225.58600","18.79897","0.07997"
"37644","225.83200","18.81953","0.08098"
"37685","226.07800","18.83998","0.08172"
"37726","226.32400","18.86055","0.08279"
"37767","226.57000","18.88100","0.08360"
"37808","226.81600","18.90150","0.08474"
"37849","227.06200","18.92207","0.08580"
"37890","227.30800","18.94252","0.08696"
"37931","227.55400","18.96303","0.08858"
"37972","227.80000","18.98348","0.08901"
"38013","228.04600","19.00404","0.09025"
"38054","228.29200","19.02449","0.09168"
"38095","228.53800","19.04500","0.09188"
"38136","228.78400","19.06545","0.09402"
"38177","229.03000","19.08607","0.09460"
"38218","229.27600","19.10652","0.09607"
"38259","229.52200","19.12703","0.09650"
"38300","229.76800","19.14754","0.09804"
"38341","230.01400","19.16799","0.09918"
"38382","230.26000","19.18849","0.09929"
"38423","230.50600","19.20900","0.10084"
"38464","230.75200","19.22951","0.10144"
"38505","230.99800","19.24996","0.10192"
"38546","231.24400","19.27053","0.10240"
"38587","231.49000","19.29097","0.10374"
"38628","231.73600","19.31154","0.10127"
"38669","231.98200","19.33199","0.10182"
"38710","232.22800","19.35256","0.10213"
"38751","232.47400","19.37306","0.10350"
"38792","232.72000","19.39351","0.10397"
"38833","232.96600","19.41402","0.10437"
"38874","233.21200","19.43453","0.10563"
"38915","233.45800","19.45510","0.10564"
"38956","233.70400","19.47542","0.10621"
"38997","233.95000","19.49605","0.10697"
"39038","234.19600","19.51650","0.10774"
"39079","234.44200","19.53701","0.10823"
"39120","234.68800","19.55746","0.10891"
"39161","234.93400","19.57808","0.10987"
"39202","235.18000","19.59847","0.10987"
"39243","235.42600","19.61898","0.11124"
"39284","235.67200","19.63955","0.11198"
"39325","235.91800","19.66005","0.11263"
"39366","236.16400","19.68056","0.11368"
"39407","236.41000","19.70101","0.11466"
"39448","236.65600","19.72152","0.11572"
"39489","236.90200","19.74196","0.11711"
"39530","237.14800","19.76253","0.11893"
"39571","237.39400","19.78298","0.11967"
"39612","237.64000","19.80361","0.12032"
"39653","237.88600","19.82399","0.12128"
"39694","238.13200","19.84450","0.12210"
"39735","238.37800","19.86507","0.12243"
"39776","238.62400","19.88552","0.12318"
"39817","238.87000","19.90603","0.12308"
"39858","239.11600","19.92648","0.12328"
"39899","239.36200","19.94704","0.12358"
"39940","239.60800","19.96743","0.12455"
"39981","239.85400","19.98800","0.12462"
"40022","240.10000","20.00851","0.12512"
"40063","240.34600","20.02902","0.12456"
"40104","240.59200","20.04952","0.12421"
"40145","240.83800","20.07009","0.12557"
"40186","241.08400","20.09054","0.12627"
"40227","241.33000","20.11105","0.12785"
"40268","241.57600","20.13149","0.12886"
"40309","241.82200","20.15200","0.12871"
"40350","242.06800","20.17257","0.12989"
"40391","242.31400","20.19296","0.13168"
"40432","242.56000","20.21353","0.13348"
"40473","242.80600","20.23397","0.13481"
"40514","243.05200","20.25454","0.13660"
"40555","243.29800","20.27499","0.13709"
"40596","243.54400","20.29556","0.13869"
"40637","243.79000","20.31600","0.14056"
"40678","244.03600","20.33651","0.14222"
"40719","244.28200","20.35702","0.14177"
"40760","244.52800","20.37747","0.14249"
"40801","244.77400","20.39804","0.14500"
"40842","245.02000","20.41848","0.14641"
"40883","245.26600","20.43911","0.14808"
"40924","245.51200","20.45944","0.14997"
"40965","245.75800","20.48001","0.15075"
"41006","246.00400","20.50052","0.15123"
"41047","246.25000","20.52108","0.15144"
"41088","246.49600","20.54147","0.15136"
"41129","246.74200","20.56204","0.15180"
"41170","246.98800","20.58255","0.15354"
"41211","247.23400","20.60299","0.15480"
"41252","247.48000","20.62350","0.15641"
"41293","247.72600","20.64401","0.15734"
"41334","247.97200","20.66452","0.15904"
"41375","248.21800","20.68497","0.16064"
"41416","248.46400","20.70553","0.16230"
"41457","248.71000","20.72604","0.16399"
"41498","248.95600","20.74655","0.16562"
"41539","249.20200","20.76694","0.16786"
"41580","249.44800","20.78757","0.17054"
"41621","249.69400","20.80801","0.17223"
"41662","249.94000","20.82852","0.17477"
"41703","250.18600","20.84903","0.17678"
"41744","250.43200","20.86953","0.17801"
"41785","250.67800","20.89004","0.17990"
"41826","250.92400","20.91043","0.18136"
"41867","251.17000","20.93100","0.18302"
"41908","251.41600","20.95151","0.18394"
"41949","251.66200","20.97202","0.18512"
"41990","251.90800","20.99253","0.18579"
"42031","252.15400","21.01303","0.18708"
"42072","252.40000","21.03348","0.18823"
"42113","252.64600","21.05399","0.18966"
"42154","252.89200","21.07456","0.19150"
"42195","253.13800","21.09500","0.19347"
"42236","253.38400","21.11551","0.19398"
"42277","253.63000","21.13602","0.19501"
"42318","253.87600","21.15653","0.19739"
"42359","254.12200","21.17697","0.19823"
"42400","254.36800","21.19748","0.18957"
"42441","254.61400","21.21799","0.18937"
"42482","254.86000","21.23856","0.19142"
"42523","255.10600","21.25900","0.19342"
"42564","255.35200","21.27951","0.19519"
"42605","255.59800","21.30002","0.19835"
"42646","255.84400","21.32053","0.19909"
"42687","256.09000","21.34104","0.19877"
"42728","256.33600","21.36154","0.20051"
"42769","256.58200","21.38205","0.20101"
"42810","256.82800","21.40244","0.19994"
"42851","257.07400","21.42301","0.20113"
"42892","257.32000","21.44352","0.20249"
"42933","257.56600","21.46402","0.20443"
"42974","257.81200","21.48447","0.20608"
"43015","258.05800","21.50504","0.20730"
"43056","258.30400","21.52561","0.20891"
"43097","258.55000","21.54600","0.21033"
"43138","258.79600","21.56650","0.21190"
"43179","259.04200","21.58707","0.21328"
"43220","259.28800","21.60758","0.21478"
"43261","259.53400","21.62797","0.21557"
"43302","259.78000","21.64853","0.21600"
"43343","260.02600","21.66898","0.21581"
"43384","260.27200","21.68955","-0.00049"
"43425","260.51800","21.71000","0.00766"
"43466","260.76400","21.73057","0.00613"
"43507","261.01000","21.75101","0.00841"
"43548","261.25600","21.77152","0.00957"
"43589","261.50200","21.79203","0.00821"
"43630","261.74800","21.81254","0.00659"
"43671","261.99400","21.83304","0.00987"
"43712","262.24000","21.85343","0.00706"
"43753","262.48600","21.87406","0.00898"
"43794","262.73200","21.89451","0.00782"
"43835","262.97800","21.91496","0.00919"
"43876","263.22400","21.93546","0.00698"
"43917","263.47000","21.95603","0.00908"
"43958","263.71600","21.97648","0.00761"
"43999","263.96200","21.99699","0.00909"
"44040","264.20800","22.01756","0.00799"
"44081","264.45400","22.03800","0.00899"
"44122","264.70000","22.05851","0.00768"
"44163","264.94600","22.07902","0.00904"
"44204","265.19200","22.09953","0.00821"
"44245","265.43800","22.11997","0.00902"
"44286","265.68400","22.14054","0.00869"
"44327","265.93000","22.16105","0.00902"
"44368","266.17600","22.18156","0.00858"
"44409","266.42200","22.20195","0.00874"
"44450","266.66800","22.22251","0.00900"
"44491","266.91400","22.24302","0.00846"
"44532","267.16000","22.26353","0.00907"
"44573","267.40600","22.28404","0.00867"
"44614","267.65200","22.30449","0.00938"
"44655","267.89800","22.32505","0.00884"
"44696","268.14400","22.34544","0.00953"
"44737","268.39000","22.36607","0.00865"
"44778","268.63600","22.38646","0.00948"
"44819","268.88200","22.40702","0.00874"
"44860","269.12800","22.42753","0.00953"
"44901","269.37400","22.44804","0.00904"
"44942","269.62000","22.46849","0.00950"
"44983","269.86600","22.48900","0.00919"
"45024","270.11200","22.50956","0.00946"
"45065","270.35800","22.53001","0.00942"
"45106","270.60400","22.55052","0.00972"
"45147","270.85000","22.57097","0.00990"
"45188","271.09600","22.59159","0.00962"
"45229","271.34200","22.61198","0.00956"
"45270","271.58800","22.63249","0.00985"
"45311","271.83400","22.65294","0.01004"
"45352","272.08000","22.67363","0.00985"
"45393","272.32600","22.69401","0.00951"
"45434","272.57200","22.71452","0.00965"
"45475","272.81800","22.73497","0.01007"
"45516","273.06400","22.75548","0.01002"
"45557","273.31000","22.77604","0.01027"
"45598","273.55600","22.79650","0.01029"
"45639","273.80200","22.81706","0.01020"
"45680","274.04800","22.83745","0.01069"
"45721","274.29400","22.85802","0.01081"
"45762","274.54000","22.87853","0.01054"
"45803","274.78600","22.89903","0.01013"
"45844","275.03200","22.91948","0.01012"
"45885","275.27800","22.94005","0.01082"
"45926","275.52400","22.96056","0.01104"
"45967","275.77000","22.98100","0.01081"
"46008","276.01600","23.00151","0.01111"
"46049","276.26200","23.02196","0.01064"
"46090","276.50800","23.04253","0.01105"
"46131","276.75400","23.06298","0.01080"
"46172","277.00000","23.08360","0.01080"
"46213","277.24600","23.10399","0.01169"
"46254","277.49200","23.12450","0.01122"
"46295","277.73800","23.14495","0.01131"
"46336","277.98400","23.16551","0.01131"
"46377","278.23000","23.18602","0.01176"
"46418","278.47600","23.20647","0.01115"
"46459","278.72200","23.22704","0.01160"
"46500","278.96800","23.24755","0.01196"
"46541","279.21400","23.26805","0.01160"
"46582","279.46000","23.28850","0.01194"
"46623","279.70600","23.30907","0.01217"
"46664","279.95200","23.32952","0.01204"
"46705","280.19800","23.35003","0.01232"
"46746","280.44400","23.37047","0.01208"
"46787","280.69000","23.39098","0.01189"
"46828","280.93600","23.41155","0.01267"
"46869","281.18200","23.43206","0.01189"
"46910","281.42800","23.45256","0.01247"
"46951","281.67400","23.47307","0.01182"
"46992","281.92000","23.49352","0.01273"
"47033","282.16600","23.51397","0.01273"
"47074","282.41200","23.53454","0.01280"
"47115","282.65800","23.55492","0.01324"
"47156","282.90400","23.57549","0.01293"
"47197","283.15000","23.59600","0.01349"
"47238","283.39600","23.61651","0.01311"
"47279","283.64200","23.63696","0.01360"
"47320","283.88800","23.65758","0.01350"
"47361","284.13400","23.67803","0.01349"
"47402","284.38000","23.69854","0.01336"
"47443","284.62600","23.71904","0.01324"
"47484","284.87200","23.73949","0.01352"
"47525","285.11800","23.76006","0.01280"
"47566","285.36400","23.78045","0.01292"
"47607","285.61000","23.80102","0.01283"
"47648","285.85600","23.82146","0.01327"
"47689","286.10200","23.84203","0.01334"
"47730","286.34800","23.86248","0.01263"
"47771","286.59400","23.88311","0.01275"
"47812","286.84000","23.90349","0.01253"
"47853","287.08600","23.92400","0.01283"
"47894","287.33200","23.94451","0.01300"
"47935","287.57800","23.96502","0.01298"
"47976","287.82400","23.98553","0.01317"
"48017","288.07000","24.00598","0.01308"
"48058","288.31600","24.02654","0.01312"
"48099","288.56200","24.04699","0.01323"
"48140","288.80800","24.06750","0.01346"
"48181","289.05400","24.08795","0.01316"
"48222","289.30000","24.10857","0.01332"
"48263","289.54600","24.12902","0.01334"
"48304","289.79200","24.14953","0.01306"
"48345","290.03800","24.17004","0.01354"
"48386","290.28400","24.19054","0.01346"
"48427","290.53000","24.21099","0.01393"
"48468","290.77600","24.23150","0.01350"
"48509","291.02200","24.25207","0.01377"
"48550","291.26800","24.27246","0.01298"
"48591","291.51400","24.29303","0.01358"
"48632","291.76000","24.31353","0.01357"
"48673","292.00600","24.33404","0.01390"
"48714","292.25200","24.35449","0.01418"
"48755","292.49800","24.37506","0.01414"
"48796","292.74400","24.39557","0.01354"
"48837","292.99000","24.41601","0.01408"
"48878","293.23600","24.43652","0.01413"
"48919","293.48200","24.45697","0.01435"
"48960","293.72800","24.47754","0.01454"
"49001","293.97400","24.49798","0.01436"
"49042","294.22000","24.51855","0.01378"
"49083","294.46600","24.53900","0.01427"
"49124","294.71200","24.55951","0.01459"
"49165","294.95800","24.57996","0.01408"
"49206","295.20400","24.60058","0.01422"
"49247","295.45000","24.62103","0.01393"
"49288","295.69600","24.64148","0.01420"
"49329","295.94200","24.66205","0.01438"
"49370","296.18800","24.68250","0.01412"
"49411","296.43400","24.70306","0.01369"
"49452","296.68000","24.72351","0.01378"
"49493","296.92600","24.74402","0.01411"
"49534","297.17200","24.76447","0.01442"
"49575","297.41800","24.78497","0.01475"
"49616","297.66400","24.80548","0.01474"
"49657","297.91000","24.82605","0.01486"
"49698","298.15600","24.84650","0.01477"
"49739","298.40200","24.86700","0.01478"
"49780","298.64800","24.88757","0.01454"
"49821","298.89400","24.90802","0.01503"
"49862","299.14000","24.92853","0.01479"
"49903","299.38600","24.94898","0.01499"
"49944","299.63200","24.96954","0.01545"
"49985","299.87800","24.98999","0.01496"
"50026","300.12400","25.01050","0.01587"
"50067","300.37000","25.03101","0.01585"
"50108","300.61600","25.05152","0.01563"
"50149","300.86200","25.07196","0.01582"
"50190","301.10800","25.09253","0.01579"
"50231","301.35400","25.11304","0.01553"
"50272","301.60000","25.13355","0.01630"
"50313","301.84600","25.15400","0.01579"
"50354","302.09200","25.17450","0.01615"
"50395","302.33800","25.19507","0.01678"
"50436","302.58400","25.21546","0.01644"
"50477","302.83000","25.23603","0.01635"
"50518","303.07600","25.25653","0.01626"
"50559","303.32200","25.27704","0.01621"
"50569","303.38200","25.28212","0.01617"