File: Trajectories_together/161223_2Specimen_RawData_3.csv
"","V1","V2","V3"
"1","End date","12/23/2016",""
"2","Specimen label","21AT_67",""
"3","Maximum Load","0.37712","N"
"4","Time","Extension","Load"
"5","(s)","(mm)","(N)"
"6","0.00000","0.00000","-0.00014"
"56","0.30000","0.02457","-0.00004"
"106","0.60000","0.05022","-0.00014"
"156","0.90000","0.07522","0.00009"
"206","1.20000","0.10021","0.00007"
"256","1.50000","0.12526","0.00014"
"306","1.80000","0.15013","-0.00004"
"356","2.10000","0.17518","0.00031"
"406","2.40000","0.20024","0.00067"
"456","2.70000","0.22517","0.00025"
"506","3.00000","0.25022","0.00040"
"556","3.30000","0.27521","0.00048"
"606","3.60000","0.30020","0.00051"
"656","3.90000","0.32508","0.00042"
"706","4.20000","0.35025","0.00065"
"756","4.50000","0.37512","0.00014"
"806","4.80000","0.40017","0.00055"
"856","5.10000","0.42516","0.00015"
"906","5.40000","0.45022","-0.00015"
"956","5.70000","0.47521","0.00085"
"1006","6.00000","0.50020","0.00029"
"1056","6.30000","0.52525","0.00054"
"1106","6.60000","0.55018","0.00063"
"1156","6.90000","0.57524","0.00110"
"1206","7.20000","0.60017","0.00089"
"1256","7.50000","0.62516","0.00091"
"1306","7.80000","0.65021","0.00074"
"1356","8.10000","0.67514","0.00068"
"1406","8.40000","0.70020","0.00088"
"1456","8.70000","0.72513","0.00069"
"1506","9.00000","0.75018","0.00122"
"1556","9.30000","0.77517","0.00050"
"1606","9.60000","0.80022","0.00111"
"1656","9.90000","0.82516","0.00116"
"1706","10.20000","0.85027","0.00076"
"1756","10.50000","0.87520","0.00124"
"1806","10.80000","0.90013","0.00076"
"1856","11.10000","0.92518","0.00108"
"1906","11.40000","0.95012","0.00096"
"1956","11.70000","0.97523","0.00078"
"2006","12.00000","1.00016","0.00072"
"2056","12.30000","1.02521","0.00108"
"2106","12.60000","1.05020","0.00120"
"2156","12.90000","1.07520","0.00073"
"2206","13.20000","1.10019","0.00134"
"2256","13.50000","1.12512","0.00097"
"2306","13.80000","1.15017","0.00131"
"2356","14.10000","1.17510","0.00139"
"2406","14.40000","1.20022","0.00123"
"2456","14.70000","1.22515","0.00170"
"2506","15.00000","1.25014","0.00125"
"2556","15.30000","1.27513","0.00123"
"2606","15.60000","1.30018","0.00151"
"2656","15.90000","1.32523","0.00149"
"2706","16.20000","1.35023","0.00177"
"2756","16.50000","1.37522","0.00091"
"2806","16.80000","1.40015","0.00119"
"2856","17.10000","1.42520","0.00097"
"2906","17.40000","1.45020","0.00078"
"2956","17.70000","1.47519","0.00120"
"3006","18.00000","1.50018","0.00109"
"3056","18.30000","1.52517","0.00117"
"3106","18.60000","1.55022","0.00079"
"3156","18.90000","1.57516","0.00134"
"3206","19.20000","1.60021","0.00120"
"3256","19.50000","1.62520","0.00170"
"3306","19.80000","1.65025","0.00163"
"3356","20.10000","1.67524","0.00160"
"3406","20.40000","1.70018","0.00145"
"3456","20.70000","1.72523","0.00122"
"3506","21.00000","1.75022","0.00155"
"3556","21.30000","1.77521","0.00141"
"3606","21.60000","1.80014","0.00159"
"3656","21.90000","1.82520","0.00163"
"3706","22.20000","1.85013","0.00162"
"3756","22.50000","1.87524","0.00139"
"3806","22.80000","1.90017","0.00179"
"3856","23.10000","1.92528","0.00197"
"3906","23.40000","1.95022","0.00190"
"3956","23.70000","1.97521","0.00225"
"4006","24.00000","2.00020","0.00210"
"4056","24.30000","2.02513","0.00182"
"4106","24.60000","2.05018","0.00232"
"4156","24.90000","2.07512","0.00219"
"4206","25.20000","2.10017","0.00179"
"4256","25.50000","2.12516","0.00227"
"4306","25.80000","2.15021","0.00202"
"4356","26.10000","2.17520","0.00205"
"4406","26.40000","2.20014","0.00190"
"4456","26.70000","2.22519","0.00251"
"4506","27.00000","2.25018","0.00220"
"4556","27.30000","2.27517","0.00217"
"4606","27.60000","2.30016","0.00213"
"4656","27.90000","2.32521","0.00255"
"4706","28.20000","2.35021","0.00205"
"4756","28.50000","2.37520","0.00181"
"4806","28.80000","2.40019","0.00227"
"4856","29.10000","2.42518","0.00218"
"4906","29.40000","2.45029","0.00224"
"4956","29.70000","2.47517","0.00234"
"5006","30.00000","2.50022","0.00254"
"5056","30.30000","2.52515","0.00261"
"5106","30.60000","2.55020","0.00269"
"5156","30.90000","2.57519","0.00251"
"5206","31.20000","2.60019","0.00258"
"5256","31.50000","2.62518","0.00253"
"5306","31.80000","2.65017","0.00261"
"5356","32.10000","2.67522","0.00304"
"5406","32.40000","2.70016","0.00298"
"5456","32.70000","2.72527","0.00289"
"5506","33.00000","2.75020","0.00268"
"5556","33.30000","2.77519","0.00237"
"5606","33.60000","2.80018","0.00227"
"5656","33.90000","2.82523","0.00223"
"5706","34.20000","2.85023","0.00227"
"5756","34.50000","2.87516","0.00228"
"5806","34.80000","2.90015","0.00198"
"5856","35.10000","2.92508","0.00249"
"5906","35.40000","2.95019","0.00232"
"5956","35.70000","2.97519","0.00244"
"6006","36.00000","3.00030","0.00262"
"6056","36.30000","3.02523","0.00221"
"6106","36.60000","3.05022","0.00230"
"6156","36.90000","3.07522","0.00248"
"6206","37.20000","3.10021","0.00240"
"6256","37.50000","3.12526","0.00239"
"6306","37.80000","3.15013","0.00193"
"6356","38.10000","3.17524","0.00211"
"6406","38.40000","3.20017","0.00221"
"6456","38.70000","3.22517","0.00288"
"6506","39.00000","3.25022","0.00218"
"6556","39.30000","3.27521","0.00229"
"6606","39.60000","3.30020","0.00184"
"6656","39.90000","3.32513","0.00180"
"6706","40.20000","3.35019","0.00215"
"6756","40.50000","3.37518","0.00223"
"6806","40.80000","3.40023","0.00183"
"6856","41.10000","3.42516","0.00222"
"6906","41.40000","3.45021","0.00231"
"6956","41.70000","3.47521","0.00198"
"7006","42.00000","3.50020","0.00201"
"7056","42.30000","3.52519","0.00227"
"7106","42.60000","3.55018","0.00241"
"7156","42.90000","3.57523","0.00220"
"7206","43.20000","3.60017","0.00240"
"7256","43.50000","3.62522","0.00212"
"7306","43.80000","3.65021","0.00259"
"7356","44.10000","3.67520","0.00254"
"7406","44.40000","3.70019","0.00248"
"7456","44.70000","3.72513","0.00272"
"7506","45.00000","3.75018","0.00193"
"7556","45.30000","3.77511","0.00218"
"7606","45.60000","3.80022","0.00159"
"7656","45.90000","3.82515","0.00229"
"7706","46.20000","3.85021","0.00212"
"7756","46.50000","3.87520","0.00225"
"7806","46.80000","3.90025","0.00246"
"7856","47.10000","3.92524","0.00208"
"7906","47.40000","3.95017","0.00249"
"7956","47.70000","3.97523","0.00224"
"8006","48.00000","4.00010","0.00214"
"8056","48.30000","4.02521","0.00230"
"8106","48.60000","4.05014","0.00266"
"8156","48.90000","4.07519","0.00257"
"8206","49.20000","4.10019","0.00233"
"8256","49.50000","4.12518","0.00286"
"8306","49.80000","4.15023","0.00259"
"8356","50.10000","4.17516","0.00257"
"8406","50.40000","4.20021","0.00226"
"8456","50.70000","4.22515","0.00251"
"8506","51.00000","4.25020","0.00261"
"8556","51.30000","4.27513","0.00217"
"8606","51.60000","4.30018","0.00269"
"8656","51.90000","4.32517","0.00251"
"8706","52.20000","4.35017","0.00255"
"8756","52.50000","4.37528","0.00240"
"8806","52.80000","4.40021","0.00287"
"8856","53.10000","4.42520","0.00252"
"8906","53.40000","4.45013","0.00245"
"8956","53.70000","4.47525","0.00268"
"9006","54.00000","4.50018","0.00282"
"9056","54.30000","4.52517","0.00257"
"9106","54.60000","4.55022","0.00259"
"9156","54.90000","4.57515","0.00283"
"9206","55.20000","4.60027","0.00289"
"9256","55.50000","4.62514","0.00234"
"9306","55.80000","4.65025","0.00173"
"9356","56.10000","4.67518","0.00193"
"9406","56.40000","4.70023","0.00205"
"9456","56.70000","4.72517","0.00172"
"9506","57.00000","4.75022","0.00142"
"9556","57.30000","4.77521","0.00208"
"9606","57.60000","4.80020","0.00174"
"9656","57.90000","4.82519","0.00198"
"9706","58.20000","4.85013","0.00228"
"9756","58.50000","4.87518","0.00205"
"9806","58.80000","4.90011","0.00259"
"9856","59.10000","4.92522","0.00228"
"9906","59.40000","4.95021","0.00267"
"9956","59.70000","4.97521","0.00253"
"10006","60.00000","5.00026","0.00274"
"10056","60.30000","5.02519","0.00238"
"10106","60.60000","5.05024","0.00325"
"10156","60.90000","5.07517","0.00296"
"10206","61.20000","5.10017","0.00353"
"10256","61.50000","5.12510","0.00346"
"10306","61.80000","5.15021","0.00299"
"10356","62.10000","5.17520","0.00341"
"10406","62.40000","5.20019","0.00318"
"10456","62.70000","5.22525","0.00340"
"10506","63.00000","5.25018","0.00349"
"10556","63.30000","5.27523","0.00340"
"10606","63.60000","5.30010","0.00407"
"10656","63.90000","5.32521","0.00360"
"10706","64.20000","5.35015","0.00364"
"10756","64.50000","5.37520","0.00385"
"10806","64.80000","5.40013","0.00387"
"10856","65.10000","5.42518","0.00361"
"10906","65.40000","5.45017","0.00377"
"10956","65.70000","5.47517","0.00467"
"11006","66.00000","5.50022","0.00396"
"11056","66.30000","5.52515","0.00443"
"11106","66.60000","5.55020","0.00434"
"11156","66.90000","5.57513","0.00398"
"11206","67.20000","5.60019","0.00468"
"11256","67.50000","5.62518","0.00442"
"11306","67.80000","5.65017","0.00447"
"11356","68.10000","5.67522","0.00509"
"11406","68.40000","5.70015","0.00521"
"11456","68.70000","5.72521","0.00489"
"11506","69.00000","5.75014","0.00529"
"11556","69.30000","5.77519","0.00507"
"11606","69.60000","5.80018","0.00522"
"11656","69.90000","5.82517","0.00468"
"11706","70.20000","5.85017","0.00507"
"11756","70.50000","5.87516","0.00524"
"11806","70.80000","5.90021","0.00489"
"11856","71.10000","5.92514","0.00526"
"11906","71.40000","5.95019","0.00477"
"11956","71.70000","5.97513","0.00480"
"12006","72.00000","6.00024","0.00544"
"12056","72.30000","6.02523","0.00548"
"12106","72.60000","6.05022","0.00549"
"12156","72.90000","6.07521","0.00595"
"12206","73.20000","6.10021","0.00603"
"12256","73.50000","6.12520","0.00579"
"12306","73.80000","6.15019","0.00580"
"12356","74.10000","6.17524","0.00613"
"12406","74.40000","6.20017","0.00633"
"12456","74.70000","6.22517","0.00660"
"12506","75.00000","6.25016","0.00628"
"12556","75.30000","6.27521","0.00675"
"12606","75.60000","6.30020","0.00600"
"12656","75.90000","6.32519","0.00564"
"12706","76.20000","6.35025","0.00583"
"12756","76.50000","6.37518","0.00495"
"12806","76.80000","6.40017","0.00561"
"12856","77.10000","6.42516","0.00548"
"12906","77.40000","6.45021","0.00530"
"12956","77.70000","6.47521","0.00550"
"13006","78.00000","6.50020","0.00641"
"13056","78.30000","6.52519","0.00659"
"13106","78.60000","6.55012","0.00613"
"13156","78.90000","6.57523","0.00642"
"13206","79.20000","6.60017","0.00651"
"13256","79.50000","6.62522","0.00639"
"13306","79.80000","6.65021","0.00654"
"13356","80.10000","6.67520","0.00573"
"13406","80.40000","6.70013","0.00624"
"13456","80.70000","6.72519","0.00550"
"13506","81.00000","6.75018","0.00610"
"13556","81.30000","6.77511","0.00505"
"13606","81.60000","6.80022","0.00550"
"13656","81.90000","6.82516","0.00592"
"13706","82.20000","6.85027","0.00534"
"13756","82.50000","6.87520","0.00664"
"13806","82.80000","6.90025","0.00608"
"13856","83.10000","6.92518","0.00591"
"13906","83.40000","6.95017","0.00623"
"13956","83.70000","6.97523","0.00680"
"14006","84.00000","7.00016","0.00640"
"14056","84.30000","7.02515","0.00630"
"14106","84.60000","7.05008","0.00703"
"14156","84.90000","7.07519","0.00717"
"14206","85.20000","7.10019","0.00717"
"14256","85.50000","7.12518","0.00754"
"14306","85.80000","7.15017","0.00759"
"14356","86.10000","7.17522","0.00777"
"14406","86.40000","7.20021","0.00819"
"14456","86.70000","7.22515","0.00787"
"14506","87.00000","7.25020","0.00814"
"14556","87.30000","7.27519","0.00827"
"14606","87.60000","7.30024","0.00797"
"14656","87.90000","7.32517","0.00822"
"14706","88.20000","7.35023","0.00881"
"14756","88.50000","7.37522","0.00879"
"14806","88.80000","7.40015","0.00972"
"14856","89.10000","7.42526","0.01006"
"14906","89.40000","7.45019","0.01005"
"14956","89.70000","7.47519","0.01023"
"15006","90.00000","7.50012","0.01025"
"15056","90.30000","7.52523","0.01100"
"15106","90.60000","7.55016","0.01057"
"15156","90.90000","7.57521","0.01111"
"15206","91.20000","7.60021","0.01183"
"15256","91.50000","7.62514","0.01164"
"15306","91.80000","7.65019","0.01155"
"15356","92.10000","7.67518","0.01177"
"15406","92.40000","7.70023","0.01270"
"15456","92.70000","7.72517","0.01288"
"15506","93.00000","7.75022","0.01293"
"15556","93.30000","7.77515","0.01357"
"15606","93.60000","7.80020","0.01285"
"15656","93.90000","7.82519","0.01395"
"15706","94.20000","7.85013","0.01428"
"15756","94.50000","7.87518","0.01365"
"15806","94.80000","7.90017","0.01402"
"15856","95.10000","7.92522","0.01408"
"15906","95.40000","7.95021","0.01407"
"15956","95.70000","7.97521","0.01434"
"16006","96.00000","8.00020","0.01562"
"16056","96.30000","8.02519","0.01547"
"16106","96.60000","8.05018","0.01607"
"16156","96.90000","8.07511","0.01670"
"16206","97.20000","8.10023","0.01754"
"16256","97.50000","8.12510","0.01774"
"16306","97.80000","8.15021","0.01858"
"16356","98.10000","8.17514","0.01851"
"16406","98.40000","8.20019","0.01925"
"16456","98.70000","8.22519","0.01996"
"16506","99.00000","8.25024","0.02030"
"16556","99.30000","8.27523","0.02112"
"16606","99.60000","8.30016","0.02116"
"16656","99.90000","8.32515","0.02179"
"16706","100.20000","8.35009","0.02212"
"16756","100.50000","8.37520","0.02239"
"16806","100.80000","8.40013","0.02308"
"16856","101.10000","8.42518","0.02207"
"16906","101.40000","8.45017","0.02326"
"16956","101.70000","8.47517","0.02309"
"17006","102.00000","8.50022","0.02330"
"17056","102.30000","8.52515","0.02399"
"17106","102.60000","8.55020","0.02452"
"17156","102.90000","8.57513","0.02494"
"17206","103.20000","8.60025","0.02489"
"17256","103.50000","8.62518","0.02597"
"17306","103.80000","8.65017","0.02647"
"17356","104.10000","8.67516","0.02689"
"17406","104.40000","8.70015","0.02742"
"17456","104.70000","8.72521","0.02864"
"17506","105.00000","8.75014","0.02870"
"17556","105.30000","8.77519","0.02935"
"17606","105.60000","8.80018","0.03000"
"17656","105.90000","8.82517","0.03076"
"17706","106.20000","8.85017","0.03111"
"17756","106.50000","8.87522","0.03192"
"17806","106.80000","8.90021","0.03274"
"17856","107.10000","8.92514","0.03349"
"17906","107.40000","8.95019","0.03481"
"17956","107.70000","8.97519","0.03584"
"18006","108.00000","9.00018","0.03638"
"18056","108.30000","9.02517","0.03766"
"18106","108.60000","9.05028","0.03849"
"18156","108.90000","9.07521","0.03938"
"18206","109.20000","9.10021","0.04017"
"18256","109.50000","9.12520","0.04123"
"18306","109.80000","9.15019","0.04214"
"18356","110.10000","9.17518","0.03164"
"18406","110.40000","9.20012","0.03204"
"18456","110.70000","9.22517","0.03275"
"18506","111.00000","9.25010","0.03400"
"18556","111.30000","9.27521","0.03469"
"18606","111.60000","9.30020","0.03588"
"18656","111.90000","9.32519","0.03715"
"18706","112.20000","9.35025","0.03703"
"18756","112.50000","9.37518","0.03846"
"18806","112.80000","9.40023","0.03944"
"18856","113.10000","9.42516","0.03967"
"18906","113.40000","9.45021","0.04047"
"18956","113.70000","9.47521","0.04122"
"19006","114.00000","9.50026","0.04173"
"19056","114.30000","9.52525","0.04297"
"19106","114.60000","9.55018","0.04334"
"19156","114.90000","9.57523","0.04399"
"19206","115.20000","9.60017","0.04525"
"19256","115.50000","9.62522","0.04559"
"19306","115.80000","9.65015","0.04628"
"19356","116.10000","9.67526","0.04683"
"19406","116.40000","9.70019","0.04720"
"19456","116.70000","9.72519","0.04787"
"19506","117.00000","9.75018","0.04916"
"19556","117.30000","9.77517","0.04940"
"19606","117.60000","9.80022","0.04944"
"19656","117.90000","9.82515","0.05000"
"19706","118.20000","9.85021","0.05095"
"19756","118.50000","9.87520","0.05168"
"19806","118.80000","9.90025","0.05287"
"19856","119.10000","9.92512","0.05327"
"19906","119.40000","9.95017","0.05465"
"19956","119.70000","9.97517","0.05499"
"20006","120.00000","10.00016","0.05559"
"20056","120.30000","10.02521","0.05685"
"20106","120.60000","10.05014","0.05812"
"20156","120.90000","10.07513","0.05937"
"20206","121.20000","10.10013","0.05981"
"20256","121.50000","10.12518","0.06149"
"20306","121.80000","10.15017","0.06271"
"20356","122.10000","10.17522","0.06448"
"20406","122.40000","10.20021","0.06528"
"20456","122.70000","10.22521","0.06657"
"20506","123.00000","10.25026","0.06757"
"20556","123.30000","10.27519","0.06822"
"20606","123.60000","10.30018","0.06920"
"20656","123.90000","10.32511","0.07011"
"20706","124.20000","10.35023","0.07104"
"20756","124.50000","10.37516","0.07123"
"20806","124.80000","10.40021","0.07186"
"20856","125.10000","10.42520","0.07276"
"20906","125.40000","10.45019","0.07322"
"20956","125.70000","10.47525","0.07368"
"21006","126.00000","10.50018","0.07416"
"21056","126.30000","10.52523","0.07471"
"21106","126.60000","10.55016","0.07536"
"21156","126.90000","10.57521","0.07511"
"21206","127.20000","10.60021","0.01902"
"21256","127.50000","10.62520","0.01193"
"21306","127.80000","10.65019","0.01369"
"21356","128.10000","10.67518","0.01190"
"21406","128.40000","10.70023","0.01260"
"21456","128.70000","10.72523","0.01435"
"21506","129.00000","10.75022","0.01388"
"21556","129.30000","10.77515","0.01498"
"21606","129.60000","10.80014","0.01413"
"21656","129.90000","10.82519","0.01563"
"21706","130.20000","10.85019","0.01670"
"21756","130.50000","10.87524","0.01777"
"21806","130.80000","10.90017","0.01810"
"21856","131.10000","10.92522","0.01896"
"21906","131.40000","10.95015","0.01950"
"21956","131.70000","10.97526","0.02152"
"22006","132.00000","11.00020","0.02171"
"22056","132.30000","11.02525","0.02314"
"22106","132.60000","11.05024","0.02322"
"22156","132.90000","11.07523","0.02384"
"22206","133.20000","11.10023","0.02465"
"22256","133.50000","11.12516","0.02469"
"22306","133.80000","11.15021","0.02564"
"22356","134.10000","11.17514","0.02637"
"22406","134.40000","11.20025","0.02679"
"22456","134.70000","11.22519","0.02799"
"22506","135.00000","11.25024","0.02837"
"22556","135.30000","11.27517","0.02924"
"22606","135.60000","11.30022","0.02965"
"22656","135.90000","11.32521","0.02977"
"22706","136.20000","11.35021","0.03172"
"22756","136.50000","11.37520","0.03222"
"22806","136.80000","11.40013","0.03311"
"22856","137.10000","11.42518","0.03431"
"22906","137.40000","11.45011","0.03485"
"22956","137.70000","11.47517","0.03658"
"23006","138.00000","11.50022","0.03767"
"23056","138.30000","11.52515","0.03894"
"23106","138.60000","11.55020","0.04056"
"23156","138.90000","11.57519","0.04139"
"23206","139.20000","11.60025","0.04194"
"23256","139.50000","11.62518","0.04394"
"23306","139.80000","11.65023","0.04429"
"23356","140.10000","11.67516","0.04515"
"23406","140.40000","11.70015","0.04666"
"23456","140.70000","11.72521","0.04682"
"23506","141.00000","11.75020","0.04828"
"23556","141.30000","11.77519","0.04931"
"23606","141.60000","11.80018","0.04940"
"23656","141.90000","11.82523","0.05153"
"23706","142.20000","11.85011","0.05201"
"23756","142.50000","11.87516","0.05326"
"23806","142.80000","11.90015","0.05530"
"23856","143.10000","11.92520","0.05590"
"23906","143.40000","11.95019","0.05637"
"23956","143.70000","11.97519","0.05764"
"24006","144.00000","12.00018","0.05885"
"24056","144.30000","12.02517","0.05989"
"24106","144.60000","12.05016","0.06191"
"24156","144.90000","12.07515","0.06373"
"24206","145.20000","12.10020","0.06510"
"24256","145.50000","12.12520","0.06681"
"24306","145.80000","12.15025","0.06765"
"24356","146.10000","12.17524","0.06895"
"24406","146.40000","12.20023","0.07074"
"24456","146.70000","12.22523","0.07180"
"24506","147.00000","12.25016","0.07226"
"24556","147.30000","12.27521","0.07373"
"24606","147.60000","12.30020","0.07422"
"24656","147.90000","12.32525","0.07591"
"24706","148.20000","12.35018","0.07651"
"24756","148.50000","12.37524","0.07859"
"24806","148.80000","12.40023","0.08027"
"24856","149.10000","12.42516","0.08186"
"24906","149.40000","12.45021","0.08468"
"24956","149.70000","12.47515","0.08546"
"25006","150.00000","12.50026","0.08750"
"25056","150.30000","12.52513","0.08961"
"25106","150.60000","12.55018","0.09043"
"25156","150.90000","12.57517","0.09196"
"25206","151.20000","12.60017","0.09337"
"25256","151.50000","12.62516","0.09415"
"25306","151.80000","12.65015","0.09537"
"25356","152.10000","12.67526","0.09635"
"25406","152.40000","12.70019","0.09755"
"25456","152.70000","12.72525","0.09830"
"25506","153.00000","12.75018","0.09858"
"25556","153.30000","12.77523","0.09999"
"25606","153.60000","12.80016","0.10060"
"25656","153.90000","12.82515","0.10148"
"25706","154.20000","12.85021","0.10285"
"25756","154.50000","12.87520","0.10385"
"25806","154.80000","12.90025","0.10544"
"25856","155.10000","12.92512","0.10621"
"25906","155.40000","12.95012","0.10679"
"25956","155.70000","12.97511","0.09015"
"26006","156.00000","13.00016","0.09022"
"26056","156.30000","13.02515","0.09262"
"26106","156.60000","13.05014","0.09403"
"26156","156.90000","13.07519","0.09499"
"26206","157.20000","13.10013","0.09565"
"26256","157.50000","13.12518","0.09692"
"26306","157.80000","13.15011","0.09750"
"26356","158.10000","13.17522","0.09835"
"26406","158.40000","13.20021","0.09942"
"26456","158.70000","13.22521","0.10074"
"26506","159.00000","13.25026","0.10207"
"26556","159.30000","13.27519","0.10334"
"26606","159.60000","13.30024","0.10459"
"26656","159.90000","13.32511","0.10619"
"26706","160.20000","13.35017","0.10651"
"26756","160.50000","13.37510","0.10740"
"26806","160.80000","13.40021","0.10895"
"26856","161.10000","13.42520","0.10976"
"26906","161.40000","13.45019","0.11136"
"26956","161.70000","13.47519","0.11320"
"27006","162.00000","13.50018","0.11534"
"27056","162.30000","13.52529","0.11678"
"27106","162.60000","13.55016","0.11896"
"27156","162.90000","13.57521","0.11997"
"27206","163.20000","13.60015","0.12140"
"27256","163.50000","13.62520","0.12242"
"27306","163.80000","13.65019","0.12440"
"27356","164.10000","13.67512","0.12516"
"27406","164.40000","13.70017","0.12720"
"27456","164.70000","13.72517","0.12927"
"27506","165.00000","13.75022","0.13158"
"27556","165.30000","13.77521","0.13478"
"27606","165.60000","13.80020","0.13737"
"27656","165.90000","13.82519","0.13968"
"27706","166.20000","13.85019","0.14240"
"27756","166.50000","13.87518","0.14523"
"27806","166.80000","13.90017","0.14699"
"27856","167.10000","13.92522","0.14938"
"27906","167.40000","13.95015","0.15041"
"27956","167.70000","13.97520","0.15208"
"28006","168.00000","14.00014","0.15408"
"28056","168.30000","14.02525","0.15565"
"28106","168.60000","14.05018","0.15865"
"28156","168.90000","14.07523","0.16064"
"28206","169.20000","14.10023","0.16269"
"28256","169.50000","14.12516","0.16565"
"28306","169.80000","14.15021","0.16866"
"28356","170.10000","14.17514","0.17102"
"28406","170.40000","14.20019","0.17364"
"28456","170.70000","14.22513","0.17576"
"28506","171.00000","14.25018","0.17762"
"28556","171.30000","14.27517","0.17930"
"28606","171.60000","14.30022","0.18146"
"28656","171.90000","14.32521","0.18332"
"28706","172.20000","14.35021","0.18553"
"28756","172.50000","14.37526","0.18777"
"28806","172.80000","14.40013","0.19003"
"28856","173.10000","14.42518","0.19218"
"28906","173.40000","14.45011","0.19274"
"28956","173.70000","14.47517","0.18412"
"29006","174.00000","14.50016","0.18597"
"29056","174.30000","14.52521","0.18888"
"29106","174.60000","14.55020","0.19178"
"29156","174.90000","14.57519","0.19405"
"29206","175.20000","14.60025","0.19572"
"29256","175.50000","14.62518","0.19854"
"29306","175.80000","14.65017","0.20149"
"29356","176.10000","14.67516","0.20314"
"29406","176.40000","14.70021","0.20491"
"29456","176.70000","14.72515","0.20661"
"29506","177.00000","14.75014","0.20897"
"29556","177.30000","14.77519","0.21067"
"29606","177.60000","14.80018","0.21203"
"29656","177.90000","14.82523","0.21344"
"29706","178.20000","14.85023","0.21435"
"29756","178.50000","14.87522","0.21572"
"29806","178.80000","14.90015","0.21747"
"29856","179.10000","14.92520","0.21956"
"29906","179.40000","14.95014","0.22147"
"29956","179.70000","14.97519","0.22361"
"30006","180.00000","15.00018","0.22595"
"30056","180.30000","15.02517","0.22795"
"30106","180.60000","15.05010","0.23052"
"30156","180.90000","15.07510","0.23209"
"30206","181.20000","15.10021","0.23442"
"30256","181.50000","15.12520","0.23675"
"30306","181.80000","15.15019","0.23963"
"30356","182.10000","15.17518","0.24118"
"30406","182.40000","15.20023","0.24462"
"30456","182.70000","15.22523","0.22251"
"30506","183.00000","15.25016","0.22112"
"30556","183.30000","15.27521","0.22069"
"30606","183.60000","15.30014","0.22050"
"30656","183.90000","15.32519","0.22102"
"30706","184.20000","15.35013","0.22144"
"30756","184.50000","15.37524","0.22434"
"30806","184.80000","15.40023","0.22635"
"30856","185.10000","15.42522","0.22748"
"30906","185.40000","15.45027","0.22861"
"30956","185.70000","15.47515","0.23050"
"31006","186.00000","15.50020","0.23046"
"31056","186.30000","15.52513","0.22866"
"31106","186.60000","15.55024","0.09468"
"31156","186.90000","15.57511","0.10135"
"31206","187.20000","15.60017","0.10783"
"31256","187.50000","15.62516","0.10918"
"31306","187.80000","15.65015","0.10872"
"31356","188.10000","15.67520","0.10683"
"31406","188.40000","15.70019","0.10947"
"31456","188.70000","15.72524","0.10758"
"31506","189.00000","15.75018","0.10000"
"31556","189.30000","15.77523","0.10141"
"31606","189.60000","15.80016","0.10511"
"31656","189.90000","15.82515","0.10743"
"31706","190.20000","15.85015","0.10869"
"31756","190.50000","15.87514","0.11162"
"31806","190.80000","15.90019","0.11075"
"31856","191.10000","15.92512","0.11148"
"31906","191.40000","15.95017","0.11247"
"31956","191.70000","15.97510","0.11711"
"32006","192.00000","16.00022","0.11930"
"32056","192.30000","16.02521","0.12361"
"32106","192.60000","16.05020","0.12708"
"32156","192.90000","16.07519","0.13155"
"32206","193.20000","16.10013","0.13024"
"32256","193.50000","16.12518","0.13244"
"32306","193.80000","16.15017","0.13607"
"32356","194.10000","16.17522","0.14517"
"32406","194.40000","16.20015","0.14994"
"32456","194.70000","16.22527","0.15184"
"32506","195.00000","16.25020","0.14616"
"32556","195.30000","16.27519","0.14826"
"32606","195.60000","16.30018","0.15060"
"32656","195.90000","16.32517","0.15389"
"32706","196.20000","16.35016","0.15739"
"32756","196.50000","16.37510","0.16098"
"32806","196.80000","16.40021","0.16291"
"32856","197.10000","16.42514","0.16582"
"32906","197.40000","16.45019","0.17017"
"32956","197.70000","16.47519","0.17450"
"33006","198.00000","16.50024","0.17746"
"33056","198.30000","16.52523","0.17939"
"33106","198.60000","16.55016","0.18062"
"33156","198.90000","16.57521","0.18387"
"33206","199.20000","16.60015","0.18829"
"33256","199.50000","16.62520","0.19126"
"33306","199.80000","16.65019","0.19407"
"33356","200.10000","16.67518","0.19556"
"33406","200.40000","16.70017","0.19905"
"33456","200.70000","16.72510","0.20099"
"33506","201.00000","16.75022","0.20301"
"33556","201.30000","16.77515","0.20559"
"33606","201.60000","16.80026","0.20835"
"33656","201.90000","16.82519","0.21099"
"33706","202.20000","16.85024","0.21227"
"33756","202.50000","16.87518","0.21409"
"33806","202.80000","16.90023","0.21617"
"33856","203.10000","16.92522","0.21870"
"33906","203.40000","16.95015","0.22065"
"33956","203.70000","16.97520","0.22355"
"34006","204.00000","17.00014","0.22608"
"34056","204.30000","17.02519","0.22687"
"34106","204.60000","17.05012","0.22801"
"34156","204.90000","17.07523","0.23009"
"34206","205.20000","17.10022","0.23157"
"34256","205.50000","17.12522","0.23322"
"34306","205.80000","17.15015","0.23532"
"34356","206.10000","17.17514","0.23820"
"34406","206.40000","17.20019","0.24186"
"34456","206.70000","17.22519","0.24420"
"34506","207.00000","17.25024","0.24749"
"34556","207.30000","17.27511","0.25059"
"34606","207.60000","17.30022","0.25357"
"34656","207.90000","17.32521","0.25665"
"34706","208.20000","17.35026","0.20299"
"34756","208.50000","17.37520","0.20867"
"34806","208.80000","17.40025","0.20849"
"34856","209.10000","17.42524","0.20900"
"34906","209.40000","17.45011","0.21276"
"34956","209.70000","17.47523","0.21600"
"35006","210.00000","17.50010","0.21623"
"35056","210.30000","17.52521","0.21700"
"35106","210.60000","17.55014","0.22163"
"35156","210.90000","17.57519","0.22662"
"35206","211.20000","17.60018","0.22688"
"35256","211.50000","17.62518","0.22778"
"35306","211.80000","17.65023","0.23222"
"35356","212.10000","17.67516","0.23546"
"35406","212.40000","17.70021","0.23561"
"35456","212.70000","17.72515","0.23966"
"35506","213.00000","17.75026","0.24490"
"35556","213.30000","17.77519","0.24641"
"35606","213.60000","17.80018","0.24885"
"35656","213.90000","17.82517","0.25365"
"35706","214.20000","17.85016","0.25639"
"35756","214.50000","17.87522","0.23085"
"35806","214.80000","17.90015","0.23202"
"35856","215.10000","17.92526","0.23399"
"35906","215.40000","17.95019","0.23604"
"35956","215.70000","17.97519","0.23923"
"36006","216.00000","18.00024","0.24337"
"36056","216.30000","18.02523","0.24447"
"36106","216.60000","18.05022","0.24688"
"36156","216.90000","18.07515","0.24937"
"36206","217.20000","18.10021","0.25214"
"36256","217.50000","18.12514","0.25396"
"36306","217.80000","18.15025","0.25696"
"36356","218.10000","18.17518","0.26085"
"36406","218.40000","18.20023","0.26396"
"36456","218.70000","18.22523","0.26734"
"36506","219.00000","18.25022","0.27018"
"36556","219.30000","18.27521","0.27294"
"36606","219.60000","18.30020","0.27424"
"36656","219.90000","18.32519","0.27655"
"36706","220.20000","18.35012","0.27906"
"36756","220.50000","18.37524","0.28140"
"36806","220.80000","18.40017","0.28501"
"36856","221.10000","18.42522","0.28766"
"36906","221.40000","18.45021","0.29158"
"36956","221.70000","18.47520","0.29519"
"37006","222.00000","18.50020","0.29878"
"37056","222.30000","18.52513","0.30173"
"37106","222.60000","18.55018","0.30420"
"37156","222.90000","18.57511","0.30572"
"37206","223.20000","18.60017","0.30753"
"37256","223.50000","18.62516","0.30955"
"37306","223.80000","18.65015","0.31139"
"37356","224.10000","18.67514","0.31286"
"37406","224.40000","18.70013","0.31396"
"37456","224.70000","18.72524","0.31562"
"37506","225.00000","18.75018","0.31725"
"37556","225.30000","18.77523","0.31890"
"37606","225.60000","18.80016","0.32079"
"37656","225.90000","18.82521","0.32208"
"37706","226.20000","18.85021","0.32390"
"37756","226.50000","18.87514","0.32490"
"37806","226.80000","18.90019","0.32695"
"37856","227.10000","18.92518","0.32838"
"37906","227.40000","18.95023","0.33026"
"37956","227.70000","18.97511","0.33179"
"38006","228.00000","19.00022","0.33300"
"38056","228.30000","19.02515","0.33491"
"38106","228.60000","19.05026","0.33678"
"38156","228.90000","19.07519","0.33964"
"38206","229.20000","19.10019","0.34398"
"38256","229.50000","19.12518","0.34673"
"38306","229.80000","19.15017","0.35032"
"38356","230.10000","19.17522","0.35396"
"38406","230.40000","19.20015","0.35593"
"38456","230.70000","19.22515","0.35858"
"38506","231.00000","19.25014","0.36224"
"38556","231.30000","19.27519","0.36349"
"38606","231.60000","19.30018","0.36502"
"38656","231.90000","19.32517","0.36778"
"38706","232.20000","19.35023","0.37175"
"38756","232.50000","19.37516","0.37487"
"38806","232.80000","19.40021","0.27692"
"38856","233.10000","19.42514","0.06542"
"38906","233.40000","19.45019","0.06996"
"38956","233.70000","19.47518","0.06654"
"39006","234.00000","19.50024","0.07020"
"39056","234.30000","19.52523","0.09204"
"39106","234.60000","19.55022","0.07343"
"39156","234.90000","19.57521","0.09507"
"39206","235.20000","19.60015","0.08079"
"39256","235.50000","19.62519","0.09290"
"39306","235.80000","19.65013","0.07865"
"39356","236.10000","19.67518","0.07437"
"39406","236.40000","19.70011","0.09751"
"39456","236.70000","19.72522","0.09007"
"39506","237.00000","19.75016","0.09928"
"39556","237.30000","19.77515","0.08198"
"39606","237.60000","19.80020","0.08653"
"39656","237.90000","19.82519","0.09539"
"39706","238.20000","19.85024","0.09496"
"39756","238.50000","19.87518","0.10164"
"39806","238.80000","19.90023","0.09520"
"39856","239.10000","19.92516","0.09868"
"39906","239.40000","19.95021","0.10126"
"39956","239.70000","19.97520","0.09747"
"40006","240.00000","20.00020","0.10472"
"40056","240.30000","20.02525","0.09994"
"40106","240.60000","20.05018","0.10065"
"40156","240.90000","20.07523","0.10662"
"40206","241.20000","20.10016","0.10232"
"40256","241.50000","20.12522","0.10788"
"40306","241.80000","20.15021","0.10447"
"40356","242.10000","20.17514","0.10470"
"40406","242.40000","20.20013","0.11446"
"40456","242.70000","20.22512","0.10778"
"40506","243.00000","20.25023","0.10828"
"40556","243.30000","20.27517","0.11604"
"40606","243.60000","20.30022","0.11185"
"40656","243.90000","20.32515","0.11509"
"40706","244.20000","20.35026","0.11661"
"40756","244.50000","20.37514","0.11490"
"40806","244.80000","20.40019","0.12035"
"40856","245.10000","20.42524","0.11885"
"40906","245.40000","20.45017","0.11817"
"40956","245.70000","20.47517","0.12451"
"41006","246.00000","20.50010","0.12143"
"41056","246.30000","20.52521","0.12196"
"41106","246.60000","20.55014","0.12887"
"41156","246.90000","20.57525","0.12458"
"41206","247.20000","20.60019","0.12576"
"41256","247.50000","20.62524","0.13552"
"41306","247.80000","20.65023","0.13107"
"41356","248.10000","20.67516","0.13111"
"41406","248.40000","20.70021","0.14091"
"41456","248.70000","20.72515","0.13943"
"41506","249.00000","20.75019","0.13766"
"41556","249.30000","20.77513","0.14516"
"41606","249.60000","20.80018","0.14846"
"41656","249.90000","20.82517","0.14486"
"41706","250.20000","20.85016","0.14807"
"41756","250.50000","20.87522","0.15364"
"41806","250.80000","20.90015","0.15010"
"41856","251.10000","20.92520","0.15166"
"41906","251.40000","20.95019","0.15536"
"41956","251.70000","20.97524","0.15578"
"42006","252.00000","21.00018","0.15455"
"42056","252.30000","21.02517","0.15698"
"42106","252.60000","21.05022","0.15978"
"42156","252.90000","21.07521","0.16032"
"42206","253.20000","21.10020","0.16261"
"42256","253.50000","21.12514","0.16792"
"42306","253.80000","21.15019","0.16801"
"42356","254.10000","21.17512","0.16904"
"42406","254.40000","21.20023","0.17239"
"42456","254.70000","21.22517","0.17509"
"42506","255.00000","21.25028","0.17528"
"42556","255.30000","21.27521","0.17703"
"42606","255.60000","21.30020","0.17981"
"42656","255.90000","21.32519","0.18115"
"42706","256.20000","21.35018","0.18166"
"42756","256.50000","21.37518","0.18371"
"42806","256.80000","21.40011","0.18683"
"42856","257.10000","21.42516","0.18839"
"42906","257.40000","21.45015","0.18930"
"42956","257.70000","21.47520","0.19207"
"43006","258.00000","21.50020","0.19496"
"43056","258.30000","21.52519","0.19637"
"43106","258.60000","21.55018","0.19722"
"43156","258.90000","21.57511","0.19989"
"43206","259.20000","21.60016","0.20163"
"43256","259.50000","21.62516","0.20309"
"43306","259.80000","21.65021","0.20449"
"43356","260.10000","21.67520","0.20581"
"43406","260.40000","21.70019","0.20770"
"43456","260.70000","21.72524","0.20969"
"43506","261.00000","21.75017","0.21086"
"43556","261.30000","21.77529","0.21215"
"43606","261.60000","21.80016","0.21354"
"43656","261.90000","21.82521","0.21502"
"43706","262.20000","21.85008","0.21636"
"43756","262.50000","21.87519","0.21000"
"43806","262.80000","21.90013","0.21152"
"43856","263.10000","21.92512","0.21242"
"43906","263.40000","21.95017","0.21317"
"43956","263.70000","21.97516","0.21421"
"44006","264.00000","22.00022","0.21525"
"44056","264.30000","22.02515","0.21564"
"44106","264.60000","22.05026","0.21635"
"44156","264.90000","22.07519","0.21771"
"44206","265.20000","22.10025","0.21958"
"44256","265.50000","22.12518","0.22123"
"44306","265.80000","22.15017","0.22247"
"44356","266.10000","22.17516","0.22425"
"44406","266.40000","22.20015","0.22572"
"44456","266.70000","22.22515","0.22690"
"44506","267.00000","22.25014","0.22916"
"44556","267.30000","22.27519","0.23075"
"44606","267.60000","22.30018","0.23253"
"44656","267.90000","22.32517","0.23467"
"44706","268.20000","22.35023","0.23624"
"44756","268.50000","22.37522","0.23880"
"44806","268.80000","22.40021","0.24164"
"44856","269.10000","22.42514","0.24392"
"44906","269.40000","22.45019","0.24620"
"44956","269.70000","22.47512","0.24879"
"45006","270.00000","22.50024","0.25125"
"45056","270.30000","22.52517","0.25317"
"45106","270.60000","22.55022","0.25590"
"45156","270.90000","22.57521","0.25779"
"45206","271.20000","22.60020","0.26004"
"45256","271.50000","22.62520","0.26232"
"45306","271.80000","22.65013","0.26490"
"45356","272.10000","22.67518","0.26721"
"45406","272.40000","22.70011","0.26998"
"45456","272.70000","22.72522","0.27231"
"45506","273.00000","22.75016","0.27470"
"45556","273.30000","22.77515","0.27696"
"45606","273.60000","22.80014","0.27902"
"45656","273.90000","22.82519","0.28150"
"45706","274.20000","22.85024","0.28349"
"45756","274.50000","22.87518","0.28646"
"45806","274.80000","22.90023","0.28839"
"45856","275.10000","22.92516","0.29236"
"45906","275.40000","22.95021","0.29577"
"45956","275.70000","22.97514","0.29817"
"46006","276.00000","23.00014","0.30103"
"46056","276.30000","23.02519","0.30226"
"46106","276.60000","23.05018","0.30491"
"46156","276.90000","23.07523","0.30597"
"46206","277.20000","23.10016","0.30770"
"46256","277.50000","23.12522","0.30873"
"46306","277.80000","23.15021","0.31032"
"46356","278.10000","23.17520","0.31174"
"46406","278.40000","23.20019","0.31332"
"46456","278.70000","23.22519","0.31467"
"46506","279.00000","23.25024","0.31625"
"46556","279.30000","23.27517","0.31760"
"46606","279.60000","23.30022","0.31905"
"46656","279.90000","23.32515","0.32060"
"46706","280.20000","23.35020","0.32141"
"46756","280.50000","23.37514","0.32293"
"46806","280.80000","23.40019","0.32367"
"46856","281.10000","23.42518","0.32518"
"46906","281.40000","23.45023","0.32646"
"46956","281.70000","23.47516","0.32818"
"47006","282.00000","23.50022","0.32908"
"47056","282.30000","23.52515","0.33038"
"47106","282.60000","23.55014","0.08864"
"47156","282.90000","23.57519","0.09216"
"47206","283.20000","23.60012","0.05768"
"47256","283.50000","23.62518","0.09143"
"47306","283.80000","23.65017","0.10050"
"47356","284.10000","23.67522","0.05586"
"47406","284.40000","23.70021","0.08720"
"47456","284.70000","23.72515","0.06881"
"47506","285.00000","23.75020","0.08987"
"47556","285.30000","23.77519","0.09299"
"47606","285.60000","23.80024","0.06672"
"47656","285.90000","23.82517","0.09600"
"47706","286.20000","23.85016","0.08133"
"47756","286.50000","23.87522","0.08018"
"47806","286.80000","23.90021","0.10428"
"47856","287.10000","23.92520","0.08324"
"47906","287.40000","23.95019","0.08310"
"47956","287.70000","23.97524","0.11073"
"48006","288.00000","24.00012","0.08423"
"48056","288.30000","24.02523","0.09389"
"48106","288.60000","24.05016","0.10637"
"48156","288.90000","24.07521","0.08956"
"48206","289.20000","24.10014","0.10025"
"48256","289.50000","24.12514","0.10939"
"48306","289.80000","24.15019","0.10309"
"48356","290.10000","24.17518","0.10159"
"48406","290.40000","24.20023","0.11345"
"48456","290.70000","24.22516","0.10108"
"48506","291.00000","24.25022","0.10361"
"48556","291.30000","24.27521","0.12120"
"48606","291.60000","24.30020","0.10716"
"48656","291.90000","24.32519","0.10716"
"48706","292.20000","24.35018","0.11906"
"48756","292.50000","24.37524","0.11603"
"48806","292.80000","24.40023","0.11445"
"48856","293.10000","24.42516","0.11890"
"48906","293.40000","24.45009","0.12771"
"48956","293.70000","24.47520","0.11709"
"49006","294.00000","24.50019","0.11969"
"49056","294.30000","24.52525","0.13836"
"49106","294.60000","24.55024","0.12862"
"49156","294.90000","24.57517","0.12533"
"49206","295.20000","24.60023","0.12987"
"49256","295.50000","24.62516","0.14573"
"49306","295.80000","24.65021","0.14170"
"49356","296.10000","24.67514","0.13248"
"49406","296.40000","24.70019","0.14243"
"49456","296.70000","24.72518","0.15222"
"49506","297.00000","24.75023","0.14320"
"49556","297.30000","24.77523","0.14744"
"49606","297.60000","24.80022","0.15284"
"49656","297.90000","24.82521","0.15530"
"49706","298.20000","24.85015","0.15398"
"49756","298.50000","24.87520","0.15075"
"49806","298.80000","24.90019","0.15698"
"49856","299.10000","24.92524","0.16758"
"49906","299.40000","24.95017","0.15829"
"49956","299.70000","24.97517","0.15622"
"50006","300.00000","25.00022","0.16204"
"50056","300.30000","25.02521","0.16912"
"50106","300.60000","25.05020","0.17022"
"50156","300.90000","25.07519","0.16650"
"50206","301.20000","25.10024","0.16496"
"50256","301.50000","25.12518","0.17402"
"50306","301.80000","25.15017","0.17628"
"50356","302.10000","25.17522","0.17189"
"50406","302.40000","25.20015","0.17227"
"50456","302.70000","25.22514","0.17407"
"50506","303.00000","25.25014","0.17899"
"50556","303.30000","25.27519","0.18011"
"50606","303.60000","25.30012","0.17795"
"50656","303.90000","25.32517","0.17582"
"50706","304.20000","25.35016","0.17810"
"50756","304.50000","25.37528","0.18186"
"50806","304.80000","25.40021","0.02627"
"50856","305.10000","25.42520","0.00525"
"50906","305.40000","25.45025","0.02908"
"50956","305.70000","25.47518","0.02477"
"51006","306.00000","25.50018","0.01438"
"51056","306.30000","25.52511","0.02383"
"51106","306.60000","25.55022","0.02583"
"51156","306.90000","25.57515","0.01850"
"51206","307.20000","25.60020","0.02404"
"51256","307.50000","25.62514","0.02571"
"51306","307.80000","25.65019","0.02203"
"51356","308.10000","25.67518","0.02400"
"51406","308.40000","25.70011","0.02785"
"51456","308.70000","25.72516","0.02502"
"51506","309.00000","25.75016","0.02402"
"51556","309.30000","25.77515","0.02866"
"51606","309.60000","25.80014","0.02841"
"51656","309.90000","25.82519","0.02749"
"51706","310.20000","25.85018","0.02799"
"51756","310.50000","25.87523","0.03119"
"51806","310.80000","25.90029","0.03173"
"51856","311.10000","25.92522","0.03169"
"51906","311.40000","25.95021","0.03406"
"51956","311.70000","25.97515","0.03674"
"52006","312.00000","26.00020","0.03715"
"52056","312.30000","26.02519","0.03819"
"52106","312.60000","26.05018","0.04039"
"52156","312.90000","26.07517","0.03263"
"52206","313.20000","26.10017","0.03832"
"52256","313.50000","26.12522","0.03785"
"52306","313.80000","26.15015","0.03651"
"52356","314.10000","26.17520","0.03988"
"52406","314.40000","26.20019","0.04160"
"52456","314.70000","26.22519","0.04168"
"52506","315.00000","26.25018","0.04308"
"52556","315.30000","26.27523","0.04438"
"52606","315.60000","26.30022","0.04495"
"52656","315.90000","26.32515","0.04640"
"52706","316.20000","26.35021","0.04778"
"52756","316.50000","26.37514","0.04816"
"52806","316.80000","26.40019","0.04894"
"52856","317.10000","26.42518","0.05023"
"52906","317.40000","26.45023","0.05141"
"52956","317.70000","26.47523","0.05236"
"53006","318.00000","26.50022","0.05328"
"53056","318.30000","26.52521","0.05386"
"53106","318.60000","26.55020","0.05581"
"53156","318.90000","26.57519","0.05749"
"53206","319.20000","26.60013","0.05881"
"53256","319.50000","26.62518","0.06001"
"53306","319.80000","26.65017","0.06192"
"53356","320.10000","26.67522","0.06415"
"53406","320.40000","26.70021","0.06563"
"53456","320.70000","26.72520","0.06679"
"53506","321.00000","26.75026","0.06793"
"53556","321.30000","26.77513","0.06942"
"53606","321.60000","26.80024","0.07003"
"53656","321.90000","26.82511","0.07136"
"53706","322.20000","26.85016","0.07240"
"53756","322.50000","26.87510","0.07319"
"53806","322.80000","26.90015","0.07402"
"53856","323.10000","26.92514","0.07540"
"53906","323.40000","26.95019","0.07741"
"53956","323.70000","26.97524","0.07858"
"54006","324.00000","27.00018","0.08020"
"54056","324.30000","27.02523","0.08191"
"54106","324.60000","27.05016","0.08389"
"54156","324.90000","27.07521","0.08591"
"54206","325.20000","27.10015","0.08758"
"54256","325.50000","27.12520","0.08951"
"54306","325.80000","27.15019","0.09147"
"54356","326.10000","27.17518","0.09358"
"54406","326.40000","27.20017","0.09385"
"54456","326.70000","27.22522","0.09534"
"54506","327.00000","27.25022","0.09624"
"54556","327.30000","27.27515","0.09707"
"54606","327.60000","27.30020","0.09774"
"54656","327.90000","27.32519","0.09876"
"54706","328.20000","27.35019","0.09990"
"54756","328.50000","27.37524","0.10082"
"54806","328.80000","27.40017","0.10176"
"54856","329.10000","27.42522","0.10294"
"54906","329.40000","27.45015","0.10368"
"54956","329.70000","27.47520","0.10484"
"55006","330.00000","27.50014","0.10556"
"55056","330.30000","27.52525","0.10699"
"55106","330.60000","27.55018","0.10767"
"55156","330.90000","27.57523","0.10938"
"55206","331.20000","27.60023","0.11055"
"55256","331.50000","27.62515","0.11201"
"55306","331.80000","27.65015","0.11330"
"55356","332.10000","27.67514","0.11463"
"55406","332.40000","27.70025","0.11625"
"55456","332.70000","27.72518","0.11747"
"55506","333.00000","27.75018","0.11867"
"55556","333.30000","27.77517","0.11980"
"55606","333.60000","27.80022","0.12155"
"55656","333.90000","27.82515","0.12309"
"55706","334.20000","27.85014","0.12377"
"55756","334.50000","27.87526","0.12557"
"55806","334.80000","27.90013","0.12718"
"55856","335.10000","27.92518","0.12921"
"55906","335.40000","27.95011","0.13143"
"55956","335.70000","27.97523","0.13336"
"56006","336.00000","28.00022","0.13542"
"56056","336.30000","28.02521","0.13845"
"56106","336.60000","28.05020","0.14181"
"56156","336.90000","28.07519","0.14493"
"56206","337.20000","28.10018","0.14734"
"56256","337.50000","28.12518","0.14886"
"56306","337.80000","28.15023","0.15119"
"56356","338.10000","28.17516","0.15210"
"56406","338.40000","28.20015","0.15299"
"56456","338.70000","28.22515","0.15478"
"56506","339.00000","28.25014","0.15642"
"56556","339.30000","28.27519","0.15867"
"56606","339.60000","28.30012","0.16056"
"56656","339.90000","28.32523","0.16220"
"56706","340.20000","28.35016","0.16573"
"56756","340.50000","28.37527","0.16886"
"56806","340.80000","28.40015","0.17177"
"56856","341.10000","28.42520","0.17288"
"56906","341.40000","28.45019","0.03867"
"56956","341.70000","28.47519","0.05623"
"57006","342.00000","28.50018","0.04703"
"57056","342.30000","28.52517","0.05091"
"57106","342.60000","28.55016","0.04759"
"57156","342.90000","28.57509","0.05245"
"57206","343.20000","28.60020","0.01783"
"57256","343.50000","28.62520","0.02216"
"57306","343.80000","28.65019","0.03277"
"57356","344.10000","28.67524","0.02985"
"57406","344.40000","28.70023","0.02384"
"57456","344.70000","28.72523","0.03905"
"57506","345.00000","28.75015","0.02930"
"57556","345.30000","28.77521","0.02765"
"57606","345.60000","28.80014","0.03851"
"57656","345.90000","28.82519","0.03093"
"57706","346.20000","28.85019","0.03428"
"57756","346.50000","28.87518","0.03740"
"57806","346.80000","28.90023","0.03995"
"57856","347.10000","28.92522","0.03511"
"57906","347.40000","28.95021","0.04553"
"57956","347.70000","28.97514","0.03927"
"58006","348.00000","29.00019","0.04386"
"58056","348.30000","29.02507","0.04521"
"58106","348.60000","29.05018","0.04568"
"58156","348.90000","29.07517","0.04484"
"58206","349.20000","29.10016","0.04866"
"58256","349.50000","29.12516","0.04798"
"58306","349.80000","29.15015","0.04820"
"58356","350.10000","29.17526","0.05248"
"58406","350.40000","29.20019","0.05072"
"58456","350.70000","29.22524","0.05304"
"58506","351.00000","29.25018","0.05475"
"58556","351.30000","29.27523","0.05633"
"58606","351.60000","29.30016","0.05485"
"58656","351.90000","29.32521","0.05953"
"58706","352.20000","29.35020","0.06041"
"58756","352.50000","29.37514","0.06076"
"58806","352.80000","29.40013","0.06349"
"58856","353.10000","29.42512","0.06561"
"58906","353.40000","29.45017","0.06636"
"58956","353.70000","29.47517","0.06690"
"59006","354.00000","29.50022","0.06952"
"59056","354.30000","29.52521","-0.00130"
"59106","354.60000","29.55014","-0.00187"
"59156","354.90000","29.57519","-0.00089"
"59206","355.20000","29.60012","-0.00084"
"59256","355.50000","29.62518","-0.00124"
"59306","355.80000","29.65011","-0.00131"
"59356","356.10000","29.67522","-0.00180"
"59406","356.40000","29.70015","-0.00108"
"59456","356.70000","29.72520","-0.00062"
"59506","357.00000","29.75020","-0.00066"
"59556","357.30000","29.77519","-0.00156"
"59606","357.60000","29.80024","-0.00189"
"59656","357.90000","29.82517","-0.00126"
"59706","358.20000","29.85016","-0.00111"
"59756","358.50000","29.87510","-0.00151"
"59806","358.80000","29.90021","-0.00180"
"59856","359.10000","29.92514","-0.00145"
"59906","359.40000","29.95019","-0.00125"
"59956","359.70000","29.97519","-0.00141"
"60006","360.00000","30.00018","-0.00167"
"60056","360.30000","30.02523","-0.00169"
"60106","360.60000","30.05016","-0.00123"
"60156","360.90000","30.07521","-0.00123"
"60206","361.20000","30.10015","-0.00116"
"60256","361.50000","30.12519","-0.00178"
"60306","361.80000","30.15019","-0.00108"
"60356","362.10000","30.17518","-0.00122"
"60406","362.40000","30.20017","-0.00103"
"60456","362.70000","30.22516","-0.00166"
"60506","363.00000","30.25022","-0.00127"
"60556","363.30000","30.27515","-0.00125"
"60606","363.60000","30.30020","-0.00112"
"60656","363.90000","30.32513","-0.00128"
"60706","364.20000","30.35018","-0.00130"
"60756","364.50000","30.37518","-0.00093"
"60806","364.80000","30.40017","-0.00064"
"60856","365.10000","30.42522","-0.00131"
"60906","365.40000","30.45015","-0.00169"
"60956","365.70000","30.47520","-0.00101"
"61006","366.00000","30.50014","-0.00126"
"61056","366.30000","30.52519","-0.00110"
"61106","366.60000","30.55018","-0.00104"
"61156","366.90000","30.57523","-0.00157"
"61206","367.20000","30.60022","-0.00082"
"61256","367.50000","30.62522","-0.00121"
"61306","367.80000","30.65021","-0.00186"
"61356","368.10000","30.67520","-0.00164"
"61406","368.40000","30.70019","-0.00115"
"61456","368.70000","30.72512","-0.00148"
"61506","369.00000","30.75018","-0.00146"
"61556","369.30000","30.77511","-0.00172"
"61606","369.60000","30.80022","-0.00166"
"61656","369.90000","30.82521","-0.00099"
"61706","370.20000","30.85021","-0.00136"
"61756","370.50000","30.87525","-0.00135"
"61777","370.62200","30.88536","-0.00139"