File: Trajectories_together/161217Specimen_RawData_1.csv
"","V1","V2","V3"
"1","End date","12/17/2016",""
"2","Specimen label","15AG_22",""
"3","Maximum Load","0.00258","N"
"4","Time","Extension","Load"
"5","(s)","(mm)","(N)"
"6","0.00000","0.00000","-0.00036"
"81","0.45000","0.03779","0.00019"
"156","0.90000","0.07522","0.00027"
"231","1.35000","0.11270","0.00004"
"306","1.80000","0.15019","0.00009"
"381","2.25000","0.18774","0.00016"
"456","2.70000","0.22523","-0.00009"
"531","3.15000","0.26266","0.00046"
"606","3.60000","0.30014","-0.00008"
"681","4.05000","0.33763","0.00008"
"756","4.50000","0.37512","0.00038"
"831","4.95000","0.41267","0.00010"
"906","5.40000","0.45022","0.00030"
"981","5.85000","0.48776","0.00025"
"1056","6.30000","0.52519","0.00048"
"1131","6.75000","0.56268","0.00025"
"1206","7.20000","0.60011","0.00031"
"1281","7.65000","0.63766","0.00059"
"1356","8.10000","0.67520","0.00010"
"1431","8.55000","0.71269","0.00056"
"1506","9.00000","0.75018","0.00032"
"1581","9.45000","0.78767","0.00000"
"1656","9.90000","0.82516","0.00035"
"1731","10.35000","0.86270","0.00005"
"1806","10.80000","0.90025","0.00017"
"1881","11.25000","0.93768","0.00032"
"1956","11.70000","0.97523","0.00024"
"2031","12.15000","1.01272","0.00047"
"2106","12.60000","1.05014","0.00031"
"2181","13.05000","1.08769","-0.00015"
"2256","13.50000","1.12518","0.00006"
"2331","13.95000","1.16273","0.00032"
"2406","14.40000","1.20016","0.00029"
"2481","14.85000","1.23764","0.00029"
"2556","15.30000","1.27513","0.00021"
"2631","15.75000","1.31268","0.00019"
"2706","16.20000","1.35023","-0.00009"
"2781","16.65000","1.38771","0.00051"
"2856","17.10000","1.42520","0.00036"
"2931","17.55000","1.46269","0.00030"
"3006","18.00000","1.50012","0.00003"
"3081","18.45000","1.53767","0.00036"
"3156","18.90000","1.57522","0.00050"
"3231","19.35000","1.61270","0.00025"
"3306","19.80000","1.65025","0.00021"
"3381","20.25000","1.68768","0.00020"
"3456","20.70000","1.72511","0.00000"
"3531","21.15000","1.76266","0.00009"
"3606","21.60000","1.80020","0.00023"
"3681","22.05000","1.83775","0.00049"
"3756","22.50000","1.87524","0.00040"
"3831","22.95000","1.91273","0.00048"
"3906","23.40000","1.95016","0.00014"
"3981","23.85000","1.98770","0.00036"
"4056","24.30000","2.02513","0.00047"
"4131","24.75000","2.06268","0.00045"
"4206","25.20000","2.10023","0.00018"
"4281","25.65000","2.13772","0.00019"
"4356","26.10000","2.17514","0.00039"
"4431","26.55000","2.21269","0.00032"
"4506","27.00000","2.25018","0.00024"
"4581","27.45000","2.28773","0.00021"
"4656","27.90000","2.32516","0.00016"
"4731","28.35000","2.36270","0.00030"
"4806","28.80000","2.40019","0.00033"
"4881","29.25000","2.43762","0.00043"
"4956","29.70000","2.47523","0.00033"
"5031","30.15000","2.51272","0.00053"
"5106","30.60000","2.55020","0.00009"
"5181","31.05000","2.58763","0.00037"
"5256","31.50000","2.62512","0.00061"
"5331","31.95000","2.66267","0.00038"
"5406","32.40000","2.70027","0.00044"
"5481","32.85000","2.73770","0.00022"
"5556","33.30000","2.77519","0.00040"
"5631","33.75000","2.81268","0.00058"
"5706","34.20000","2.85011","0.00021"
"5781","34.65000","2.88766","0.00043"
"5856","35.10000","2.92508","0.00029"
"5931","35.55000","2.96269","0.00046"
"6006","36.00000","3.00024","0.00064"
"6081","36.45000","3.03773","0.00026"
"6156","36.90000","3.07516","0.00025"
"6231","37.35000","3.11258","0.00027"
"6306","37.80000","3.15019","0.00017"
"6381","38.25000","3.18768","0.00034"
"6456","38.70000","3.22523","0.00027"
"6531","39.15000","3.26265","0.00013"
"6606","39.60000","3.30020","0.00028"
"6681","40.05000","3.33763","0.00021"
"6756","40.50000","3.37518","0.00016"
"6831","40.95000","3.41273","0.00049"
"6906","41.40000","3.45016","0.00018"
"6981","41.85000","3.48770","0.00047"
"7056","42.30000","3.52519","0.00064"
"7131","42.75000","3.56262","0.00060"
"7206","43.20000","3.60017","0.00050"
"7281","43.65000","3.63766","0.00025"
"7356","44.10000","3.67514","0.00041"
"7431","44.55000","3.71269","0.00065"
"7506","45.00000","3.75018","0.00028"
"7581","45.45000","3.78767","0.00007"
"7656","45.90000","3.82521","0.00047"
"7731","46.35000","3.86270","0.00037"
"7806","46.80000","3.90019","0.00038"
"7881","47.25000","3.93774","0.00078"
"7956","47.70000","3.97517","0.00070"
"8031","48.15000","4.01259","-0.00003"
"8106","48.60000","4.05014","0.00049"
"8181","49.05000","4.08769","0.00028"
"8256","49.50000","4.12524","0.00049"
"8331","49.95000","4.16267","0.00066"
"8406","50.40000","4.20021","0.00044"
"8481","50.85000","4.23764","0.00055"
"8556","51.30000","4.27519","0.00014"
"8631","51.75000","4.31268","0.00055"
"8706","52.20000","4.35023","0.00036"
"8781","52.65000","4.38771","0.00030"
"8856","53.10000","4.42520","0.00062"
"8931","53.55000","4.46263","0.00033"
"9006","54.00000","4.50018","0.00059"
"9081","54.45000","4.53767","0.00032"
"9156","54.90000","4.57521","0.00043"
"9231","55.35000","4.61276","0.00014"
"9306","55.80000","4.65019","0.00042"
"9381","56.25000","4.68768","0.00029"
"9456","56.70000","4.72511","0.00015"
"9531","57.15000","4.76265","0.00022"
"9606","57.60000","4.80020","0.00040"
"9681","58.05000","4.83769","0.00032"
"9756","58.50000","4.87518","0.00041"
"9831","58.95000","4.91267","0.00050"
"9906","59.40000","4.95015","0.00067"
"9981","59.85000","4.98770","0.00034"
"10056","60.30000","5.02519","0.00019"
"10131","60.75000","5.06268","0.00056"
"10206","61.20000","5.10017","0.00051"
"10281","61.65000","5.13771","0.00066"
"10356","62.10000","5.17514","0.00032"
"10431","62.55000","5.21269","0.00029"
"10506","63.00000","5.25018","0.00019"
"10581","63.45000","5.28773","0.00032"
"10656","63.90000","5.32521","0.00046"
"10731","64.35000","5.36264","0.00047"
"10806","64.80000","5.40013","0.00069"
"10881","65.25000","5.43768","0.00048"
"10956","65.70000","5.47523","0.00066"
"11031","66.15000","5.51265","0.00053"
"11106","66.60000","5.55020","0.00028"
"11181","67.05000","5.58763","0.00037"
"11256","67.50000","5.62512","0.00035"
"11331","67.95000","5.66273","0.00058"
"11406","68.40000","5.70021","0.00041"
"11481","68.85000","5.73776","0.00030"
"11556","69.30000","5.77525","0.00055"
"11631","69.75000","5.81262","0.00049"
"11706","70.20000","5.85017","0.00037"
"11781","70.65000","5.88765","0.00040"
"11856","71.10000","5.92520","0.00056"
"11931","71.55000","5.96269","0.00054"
"12006","72.00000","6.00024","0.00056"
"12081","72.45000","6.03773","0.00042"
"12156","72.90000","6.07509","0.00074"
"12231","73.35000","6.11264","0.00037"
"12306","73.80000","6.15013","0.00030"
"12381","74.25000","6.18768","0.00041"
"12456","74.70000","6.22523","0.00029"
"12531","75.15000","6.26265","0.00062"
"12606","75.60000","6.30014","0.00036"
"12681","76.05000","6.33763","0.00069"
"12756","76.50000","6.37518","0.00069"
"12831","76.95000","6.41267","0.00072"
"12906","77.40000","6.45015","0.00059"
"12981","77.85000","6.48764","0.00070"
"13056","78.30000","6.52513","0.00042"
"13131","78.75000","6.56262","0.00042"
"13206","79.20000","6.60017","0.00073"
"13281","79.65000","6.63771","0.00051"
"13356","80.10000","6.67520","0.00050"
"13431","80.55000","6.71269","0.00079"
"13506","81.00000","6.75012","0.00066"
"13581","81.45000","6.78761","0.00031"
"13656","81.90000","6.82521","0.00027"
"13731","82.35000","6.86270","0.00037"
"13806","82.80000","6.90019","0.00060"
"13881","83.25000","6.93768","0.00052"
"13956","83.70000","6.97511","0.00037"
"14031","84.15000","7.01265","0.00054"
"14106","84.60000","7.05020","0.00058"
"14181","85.05000","7.08769","0.00072"
"14256","85.50000","7.12524","0.00061"
"14331","85.95000","7.16273","0.00058"
"14406","86.40000","7.20015","0.00081"
"14481","86.85000","7.23764","0.00034"
"14556","87.30000","7.27513","0.00065"
"14631","87.75000","7.31268","0.00092"
"14706","88.20000","7.35023","0.00058"
"14781","88.65000","7.38777","0.00058"
"14856","89.10000","7.42520","0.00047"
"14931","89.55000","7.46263","0.00074"
"15006","90.00000","7.50018","0.00063"
"15081","90.45000","7.53767","0.00048"
"15156","90.90000","7.57521","0.00054"
"15231","91.35000","7.61264","0.00040"
"15306","91.80000","7.65019","0.00074"
"15381","92.25000","7.68768","0.00075"
"15456","92.70000","7.72511","0.00051"
"15531","93.15000","7.76271","0.00052"
"15606","93.60000","7.80014","0.00045"
"15681","94.05000","7.83775","0.00074"
"15756","94.50000","7.87518","0.00086"
"15831","94.95000","7.91267","0.00064"
"15906","95.40000","7.95015","0.00059"
"15981","95.85000","7.98770","0.00067"
"16056","96.30000","8.02519","0.00056"
"16131","96.75000","8.06274","0.00057"
"16206","97.20000","8.10017","0.00062"
"16281","97.65000","8.13760","0.00029"
"16356","98.10000","8.17514","0.00053"
"16431","98.55000","8.21269","0.00032"
"16506","99.00000","8.25024","0.00053"
"16581","99.45000","8.28767","0.00090"
"16656","99.90000","8.32515","0.00081"
"16731","100.35000","8.36264","0.00067"
"16806","100.80000","8.40013","0.00056"
"16881","101.25000","8.43768","0.00029"
"16956","101.70000","8.47523","0.00034"
"17031","102.15000","8.51277","0.00081"
"17106","102.60000","8.55020","0.00094"
"17181","103.05000","8.58769","0.00055"
"17256","103.50000","8.62518","0.00083"
"17331","103.95000","8.66267","0.00056"
"17406","104.40000","8.70021","0.00058"
"17481","104.85000","8.73776","0.00087"
"17556","105.30000","8.77519","0.00100"
"17631","105.75000","8.81268","0.00057"
"17706","106.20000","8.85017","0.00082"
"17781","106.65000","8.88771","0.00082"
"17856","107.10000","8.92520","0.00072"
"17931","107.55000","8.96269","0.00068"
"18006","108.00000","9.00018","0.00076"
"18081","108.45000","9.03767","0.00069"
"18156","108.90000","9.07515","0.00069"
"18231","109.35000","9.11270","0.00083"
"18306","109.80000","9.15019","0.00056"
"18381","110.25000","9.18768","0.00049"
"18456","110.70000","9.22523","0.00063"
"18531","111.15000","9.26265","0.00071"
"18606","111.60000","9.30014","0.00071"
"18681","112.05000","9.33769","0.00086"
"18756","112.50000","9.37518","0.00038"
"18831","112.95000","9.41267","0.00072"
"18906","113.40000","9.45015","0.00055"
"18981","113.85000","9.48764","0.00095"
"19056","114.30000","9.52513","0.00097"
"19131","114.75000","9.56268","0.00079"
"19206","115.20000","9.60023","0.00081"
"19281","115.65000","9.63771","0.00073"
"19356","116.10000","9.67526","0.00078"
"19431","116.55000","9.71263","0.00077"
"19506","117.00000","9.75012","0.00076"
"19581","117.45000","9.78767","0.00077"
"19656","117.90000","9.82521","0.00082"
"19731","118.35000","9.86270","0.00076"
"19806","118.80000","9.90019","0.00056"
"19881","119.25000","9.93768","0.00083"
"19956","119.70000","9.97511","0.00093"
"20031","120.15000","10.01271","0.00081"
"20106","120.60000","10.05020","0.00046"
"20181","121.05000","10.08769","0.00072"
"20256","121.50000","10.12524","0.00110"
"20331","121.95000","10.16273","0.00102"
"20406","122.40000","10.20015","0.00084"
"20481","122.85000","10.23764","0.00087"
"20556","123.30000","10.27513","0.00098"
"20631","123.75000","10.31268","0.00084"
"20706","124.20000","10.35023","0.00079"
"20781","124.65000","10.38771","0.00076"
"20856","125.10000","10.42520","0.00073"
"20931","125.55000","10.46263","0.00077"
"21006","126.00000","10.50024","0.00060"
"21081","126.45000","10.53772","0.00115"
"21156","126.90000","10.57515","0.00100"
"21231","127.35000","10.61270","0.00119"
"21306","127.80000","10.65013","0.00082"
"21381","128.25000","10.68768","0.00097"
"21456","128.70000","10.72523","0.00080"
"21531","129.15000","10.76271","0.00101"
"21606","129.60000","10.80020","0.00102"
"21681","130.05000","10.83763","0.00132"
"21756","130.50000","10.87518","0.00095"
"21831","130.95000","10.91261","0.00102"
"21906","131.40000","10.95021","0.00095"
"21981","131.85000","10.98770","0.00101"
"22056","132.30000","11.02519","0.00103"
"22131","132.75000","11.06268","0.00089"
"22206","133.20000","11.10011","0.00103"
"22281","133.65000","11.13765","0.00090"
"22356","134.10000","11.17514","0.00102"
"22431","134.55000","11.21275","0.00111"
"22506","135.00000","11.25024","0.00104"
"22581","135.45000","11.28767","0.00099"
"22656","135.90000","11.32515","0.00090"
"22731","136.35000","11.36258","0.00112"
"22806","136.80000","11.40019","0.00111"
"22881","137.25000","11.43768","0.00086"
"22956","137.70000","11.47523","0.00084"
"23031","138.15000","11.51271","0.00091"
"23106","138.60000","11.55020","0.00092"
"23181","139.05000","11.58769","0.00104"
"23256","139.50000","11.62518","0.00112"
"23331","139.95000","11.66273","0.00115"
"23406","140.40000","11.70015","0.00086"
"23481","140.85000","11.73770","0.00080"
"23556","141.30000","11.77519","0.00124"
"23631","141.75000","11.81262","0.00133"
"23706","142.20000","11.85017","0.00115"
"23781","142.65000","11.88771","0.00092"
"23856","143.10000","11.92520","0.00122"
"23931","143.55000","11.96269","0.00106"
"24006","144.00000","12.00012","0.00104"
"24081","144.45000","12.03761","0.00091"
"24156","144.90000","12.07515","0.00116"
"24231","145.35000","12.11270","0.00098"
"24306","145.80000","12.15019","0.00095"
"24381","146.25000","12.18768","0.00148"
"24456","146.70000","12.22517","0.00112"
"24531","147.15000","12.26265","0.00105"
"24606","147.60000","12.30014","0.00078"
"24681","148.05000","12.33775","0.00107"
"24756","148.50000","12.37524","0.00107"
"24831","148.95000","12.41273","0.00114"
"24906","149.40000","12.45015","0.00113"
"24981","149.85000","12.48758","0.00088"
"25056","150.30000","12.52513","0.00111"
"25131","150.75000","12.56268","0.00104"
"25206","151.20000","12.60023","0.00118"
"25281","151.65000","12.63771","0.00128"
"25356","152.10000","12.67520","0.00115"
"25431","152.55000","12.71269","0.00097"
"25506","153.00000","12.75018","0.00102"
"25581","153.45000","12.78767","0.00080"
"25656","153.90000","12.82515","0.00096"
"25731","154.35000","12.86270","0.00116"
"25806","154.80000","12.90019","0.00127"
"25881","155.25000","12.93768","0.00123"
"25956","155.70000","12.97517","0.00130"
"26031","156.15000","13.01265","0.00108"
"26106","156.60000","13.05020","0.00134"
"26181","157.05000","13.08769","0.00127"
"26256","157.50000","13.12524","0.00148"
"26331","157.95000","13.16267","0.00131"
"26406","158.40000","13.20015","0.00100"
"26481","158.85000","13.23770","0.00123"
"26556","159.30000","13.27519","0.00106"
"26631","159.75000","13.31268","0.00129"
"26706","160.20000","13.35017","0.00130"
"26781","160.65000","13.38765","0.00126"
"26856","161.10000","13.42520","0.00117"
"26931","161.55000","13.46275","0.00143"
"27006","162.00000","13.50024","0.00119"
"27081","162.45000","13.53773","0.00089"
"27156","162.90000","13.57521","0.00118"
"27231","163.35000","13.61264","0.00113"
"27306","163.80000","13.65013","0.00105"
"27381","164.25000","13.68768","0.00098"
"27456","164.70000","13.72517","0.00100"
"27531","165.15000","13.76271","0.00138"
"27606","165.60000","13.80020","0.00125"
"27681","166.05000","13.83763","0.00135"
"27756","166.50000","13.87512","0.00101"
"27831","166.95000","13.91267","0.00095"
"27906","167.40000","13.95021","0.00102"
"27981","167.85000","13.98770","0.00134"
"28056","168.30000","14.02519","0.00094"
"28131","168.75000","14.06268","0.00115"
"28206","169.20000","14.10011","0.00108"
"28281","169.65000","14.13765","0.00127"
"28356","170.10000","14.17520","0.00127"
"28431","170.55000","14.21269","0.00106"
"28506","171.00000","14.25024","0.00100"
"28581","171.45000","14.28767","0.00147"
"28656","171.90000","14.32515","0.00120"
"28731","172.35000","14.36270","0.00127"
"28806","172.80000","14.40013","0.00157"
"28881","173.25000","14.43768","0.00138"
"28956","173.70000","14.47517","0.00103"
"29031","174.15000","14.51271","0.00116"
"29106","174.60000","14.55014","0.00107"
"29181","175.05000","14.58769","0.00111"
"29256","175.50000","14.62518","0.00115"
"29331","175.95000","14.66272","0.00116"
"29406","176.40000","14.70021","0.00135"
"29481","176.85000","14.73764","0.00096"
"29556","177.30000","14.77513","0.00107"
"29631","177.75000","14.81268","0.00113"
"29706","178.20000","14.85023","0.00149"
"29781","178.65000","14.88771","0.00116"
"29856","179.10000","14.92514","0.00139"
"29931","179.55000","14.96269","0.00118"
"30006","180.00000","15.00012","0.00072"
"30081","180.45000","15.03767","0.00111"
"30156","180.90000","15.07521","0.00086"
"30231","181.35000","15.11270","0.00121"
"30306","181.80000","15.15019","0.00133"
"30381","182.25000","15.18768","0.00112"
"30456","182.70000","15.22511","0.00142"
"30531","183.15000","15.26271","0.00142"
"30606","183.60000","15.30020","0.00092"
"30681","184.05000","15.33775","0.00107"
"30756","184.50000","15.37524","0.00106"
"30831","184.95000","15.41273","0.00114"
"30906","185.40000","15.45015","0.00121"
"30981","185.85000","15.48758","0.00132"
"31056","186.30000","15.52513","0.00109"
"31131","186.75000","15.56274","0.00106"
"31206","187.20000","15.60017","0.00139"
"31281","187.65000","15.63771","0.00119"
"31356","188.10000","15.67520","0.00143"
"31431","188.55000","15.71263","0.00123"
"31506","189.00000","15.75018","0.00133"
"31581","189.45000","15.78772","0.00154"
"31656","189.90000","15.82515","0.00138"
"31731","190.35000","15.86270","0.00148"
"31806","190.80000","15.90019","0.00134"
"31881","191.25000","15.93768","0.00127"
"31956","191.70000","15.97516","0.00121"
"32031","192.15000","16.01265","0.00140"
"32106","192.60000","16.05020","0.00126"
"32181","193.05000","16.08775","0.00140"
"32256","193.50000","16.12512","0.00118"
"32331","193.95000","16.16267","0.00145"
"32406","194.40000","16.20015","0.00140"
"32481","194.85000","16.23770","0.00131"
"32556","195.30000","16.27519","0.00137"
"32631","195.75000","16.31268","0.00115"
"32706","196.20000","16.35016","0.00155"
"32781","196.65000","16.38759","0.00150"
"32856","197.10000","16.42520","0.00121"
"32931","197.55000","16.46269","0.00131"
"33006","198.00000","16.50024","0.00146"
"33081","198.45000","16.53772","0.00128"
"33156","198.90000","16.57509","0.00124"
"33231","199.35000","16.61264","0.00127"
"33306","199.80000","16.65013","0.00103"
"33381","200.25000","16.68768","0.00121"
"33456","200.70000","16.72517","0.00135"
"33531","201.15000","16.76277","0.00132"
"33606","201.60000","16.80020","0.00141"
"33681","202.05000","16.83763","0.00105"
"33756","202.50000","16.87518","0.00143"
"33831","202.95000","16.91266","0.00131"
"33906","203.40000","16.95021","0.00114"
"33981","203.85000","16.98770","0.00115"
"34056","204.30000","17.02519","0.00160"
"34131","204.75000","17.06262","0.00134"
"34206","205.20000","17.10011","0.00125"
"34281","205.65000","17.13771","0.00151"
"34356","206.10000","17.17520","0.00133"
"34431","206.55000","17.21269","0.00138"
"34506","207.00000","17.25018","0.00127"
"34581","207.45000","17.28766","0.00118"
"34656","207.90000","17.32509","0.00141"
"34731","208.35000","17.36264","0.00154"
"34806","208.80000","17.40025","0.00142"
"34881","209.25000","17.43768","0.00157"
"34956","209.70000","17.47517","0.00141"
"35031","210.15000","17.51265","0.00129"
"35106","210.60000","17.55014","0.00126"
"35181","211.05000","17.58769","0.00140"
"35256","211.50000","17.62524","0.00141"
"35331","211.95000","17.66272","0.00151"
"35406","212.40000","17.70021","0.00144"
"35481","212.85000","17.73764","0.00161"
"35556","213.30000","17.77513","0.00184"
"35631","213.75000","17.81268","0.00138"
"35706","214.20000","17.85022","0.00132"
"35781","214.65000","17.88771","0.00126"
"35856","215.10000","17.92520","0.00170"
"35931","215.55000","17.96263","0.00122"
"36006","216.00000","18.00012","0.00133"
"36081","216.45000","18.03761","0.00150"
"36156","216.90000","18.07521","0.00139"
"36231","217.35000","18.11276","0.00143"
"36306","217.80000","18.15025","0.00143"
"36381","218.25000","18.18768","0.00149"
"36456","218.70000","18.22516","0.00150"
"36531","219.15000","18.26265","0.00176"
"36606","219.60000","18.30020","0.00140"
"36681","220.05000","18.33769","0.00159"
"36756","220.50000","18.37518","0.00161"
"36831","220.95000","18.41266","0.00173"
"36906","221.40000","18.45015","0.00137"
"36981","221.85000","18.48764","0.00160"
"37056","222.30000","18.52519","0.00151"
"37131","222.75000","18.56268","0.00167"
"37206","223.20000","18.60017","0.00152"
"37281","223.65000","18.63765","0.00149"
"37356","224.10000","18.67514","0.00123"
"37431","224.55000","18.71263","0.00137"
"37506","225.00000","18.75018","0.00150"
"37581","225.45000","18.78766","0.00165"
"37656","225.90000","18.82515","0.00155"
"37731","226.35000","18.86270","0.00119"
"37806","226.80000","18.90013","0.00138"
"37881","227.25000","18.93768","0.00157"
"37956","227.70000","18.97522","0.00130"
"38031","228.15000","19.01271","0.00180"
"38106","228.60000","19.05020","0.00143"
"38181","229.05000","19.08769","0.00198"
"38256","229.50000","19.12512","0.00147"
"38331","229.95000","19.16266","0.00153"
"38406","230.40000","19.20015","0.00144"
"38481","230.85000","19.23770","0.00146"
"38556","231.30000","19.27525","0.00143"
"38631","231.75000","19.31268","0.00152"
"38706","232.20000","19.35017","0.00152"
"38781","232.65000","19.38771","0.00154"
"38856","233.10000","19.42514","0.00141"
"38931","233.55000","19.46269","0.00161"
"39006","234.00000","19.50024","0.00154"
"39081","234.45000","19.53773","0.00152"
"39156","234.90000","19.57515","0.00172"
"39231","235.35000","19.61264","0.00151"
"39306","235.80000","19.65019","0.00189"
"39381","236.25000","19.68773","0.00154"
"39456","236.70000","19.72522","0.00162"
"39531","237.15000","19.76265","0.00188"
"39606","237.60000","19.80020","0.00144"
"39681","238.05000","19.83763","0.00135"
"39756","238.50000","19.87518","0.00160"
"39831","238.95000","19.91272","0.00140"
"39906","239.40000","19.95015","0.00159"
"39981","239.85000","19.98770","0.00167"
"40056","240.30000","20.02519","0.00153"
"40131","240.75000","20.06268","0.00169"
"40206","241.20000","20.10023","0.00159"
"40281","241.65000","20.13765","0.00152"
"40356","242.10000","20.17520","0.00158"
"40431","242.55000","20.21269","0.00171"
"40506","243.00000","20.25018","0.00187"
"40581","243.45000","20.28761","0.00191"
"40656","243.90000","20.32515","0.00191"
"40731","244.35000","20.36270","0.00175"
"40806","244.80000","20.40019","0.00189"
"40881","245.25000","20.43774","0.00150"
"40956","245.70000","20.47517","0.00174"
"41031","246.15000","20.51259","0.00138"
"41106","246.60000","20.55014","0.00168"
"41181","247.05000","20.58775","0.00171"
"41256","247.50000","20.62518","0.00176"
"41331","247.95000","20.66267","0.00176"
"41406","248.40000","20.70015","0.00167"
"41481","248.85000","20.73764","0.00160"
"41556","249.30000","20.77519","0.00164"
"41631","249.75000","20.81268","0.00203"
"41706","250.20000","20.85016","0.00178"
"41781","250.65000","20.88771","0.00160"
"41856","251.10000","20.92520","0.00191"
"41931","251.55000","20.96263","0.00176"
"42006","252.00000","21.00018","0.00152"
"42081","252.45000","21.03766","0.00176"
"42156","252.90000","21.07521","0.00167"
"42231","253.35000","21.11276","0.00171"
"42306","253.80000","21.15019","0.00181"
"42381","254.25000","21.18768","0.00171"
"42456","254.70000","21.22517","0.00189"
"42531","255.15000","21.26271","0.00172"
"42606","255.60000","21.30026","0.00159"
"42681","256.05000","21.33769","0.00167"
"42756","256.50000","21.37518","0.00194"
"42831","256.95000","21.41261","0.00184"
"42906","257.40000","21.45021","0.00188"
"42981","257.85000","21.48770","0.00186"
"43056","258.30000","21.52519","0.00157"
"43131","258.75000","21.56268","0.00167"
"43206","259.20000","21.60016","0.00208"
"43281","259.65000","21.63765","0.00164"
"43356","260.10000","21.67514","0.00179"
"43431","260.55000","21.71269","0.00180"
"43506","261.00000","21.75017","0.00192"
"43581","261.45000","21.78773","0.00165"
"43656","261.90000","21.82515","0.00199"
"43731","262.35000","21.86264","0.00211"
"43806","262.80000","21.90013","0.00183"
"43881","263.25000","21.93768","0.00188"
"43956","263.70000","21.97523","0.00158"
"44031","264.15000","22.01277","0.00187"
"44106","264.60000","22.05014","0.00172"
"44181","265.05000","22.08769","0.00177"
"44256","265.50000","22.12512","0.00166"
"44331","265.95000","22.16266","0.00195"
"44406","266.40000","22.20015","0.00154"
"44481","266.85000","22.23770","0.00193"
"44556","267.30000","22.27519","0.00173"
"44631","267.75000","22.31268","0.00207"
"44706","268.20000","22.35017","0.00194"
"44781","268.65000","22.38765","0.00206"
"44856","269.10000","22.42520","0.00170"
"44931","269.55000","22.46269","0.00208"
"45006","270.00000","22.50018","0.00195"
"45081","270.45000","22.53773","0.00186"
"45156","270.90000","22.57515","0.00173"
"45231","271.35000","22.61264","0.00204"
"45306","271.80000","22.65019","0.00176"
"45381","272.25000","22.68774","0.00201"
"45456","272.70000","22.72522","0.00172"
"45531","273.15000","22.76265","0.00200"
"45606","273.60000","22.80014","0.00206"
"45681","274.05000","22.83769","0.00215"
"45756","274.50000","22.87524","0.00183"
"45831","274.95000","22.91266","0.00198"
"45906","275.40000","22.95015","0.00204"
"45981","275.85000","22.98770","0.00188"
"46056","276.30000","23.02513","0.00175"
"46131","276.75000","23.06268","0.00186"
"46206","277.20000","23.10023","0.00199"
"46281","277.65000","23.13771","0.00188"
"46356","278.10000","23.17520","0.00205"
"46431","278.55000","23.21269","0.00196"
"46506","279.00000","23.25012","0.00207"
"46581","279.45000","23.28761","0.00207"
"46656","279.90000","23.32515","0.00207"
"46731","280.35000","23.36270","0.00225"
"46806","280.80000","23.40019","0.00228"
"46881","281.25000","23.43768","0.00216"
"46956","281.70000","23.47516","0.00204"
"47031","282.15000","23.51265","0.00197"
"47106","282.60000","23.55014","0.00208"
"47181","283.05000","23.58769","0.00205"
"47256","283.50000","23.62523","0.00193"
"47331","283.95000","23.66266","0.00194"
"47406","284.40000","23.70015","0.00213"
"47481","284.85000","23.73764","0.00197"
"47556","285.30000","23.77513","0.00216"
"47631","285.75000","23.81273","0.00217"
"47706","286.20000","23.85016","0.00209"
"47781","286.65000","23.88771","0.00187"
"47856","287.10000","23.92520","0.00182"
"47931","287.55000","23.96263","0.00204"
"48006","288.00000","24.00018","0.00186"
"48081","288.45000","24.03772","0.00201"
"48156","288.90000","24.07515","0.00188"
"48231","289.35000","24.11264","0.00206"
"48306","289.80000","24.15013","0.00210"
"48381","290.25000","24.18768","0.00221"
"48456","290.70000","24.22523","0.00203"
"48531","291.15000","24.26277","0.00181"
"48606","291.60000","24.30020","0.00203"
"48681","292.05000","24.33769","0.00224"
"48756","292.50000","24.37511","0.00202"
"48831","292.95000","24.41267","0.00187"
"48906","293.40000","24.45015","0.00188"
"48981","293.85000","24.48770","0.00178"
"49056","294.30000","24.52525","0.00184"
"49131","294.75000","24.56268","0.00182"
"49206","295.20000","24.60016","0.00221"
"49281","295.65000","24.63759","0.00211"
"49356","296.10000","24.67514","0.00184"
"49431","296.55000","24.71269","0.00196"
"49506","297.00000","24.75018","0.00218"
"49581","297.45000","24.78766","0.00234"
"49656","297.90000","24.82515","0.00181"
"49731","298.35000","24.86264","0.00225"
"49806","298.80000","24.90013","0.00195"
"49881","299.25000","24.93774","0.00179"
"49956","299.70000","24.97517","0.00176"
"50031","300.15000","25.01277","0.00179"
"50106","300.60000","25.05014","0.00202"
"50181","301.05000","25.08763","0.00205"
"50256","301.50000","25.12518","0.00162"
"50331","301.95000","25.16260","0.00203"
"50406","302.40000","25.20021","0.00181"
"50481","302.85000","25.23770","0.00201"
"50556","303.30000","25.27519","0.00177"
"50631","303.75000","25.31268","0.00178"
"50706","304.20000","25.35016","0.00180"
"50781","304.65000","25.38771","0.00176"
"50856","305.10000","25.42526","0.00179"
"50931","305.55000","25.46269","0.00170"
"51006","306.00000","25.50018","0.00161"
"51081","306.45000","25.53767","0.00187"
"51156","306.90000","25.57515","0.00181"
"51231","307.35000","25.61270","0.00209"
"51306","307.80000","25.65019","0.00167"
"51381","308.25000","25.68768","0.00167"
"51456","308.70000","25.72516","0.00198"
"51531","309.15000","25.76265","0.00170"
"51606","309.60000","25.80014","0.00167"
"51681","310.05000","25.83769","0.00166"
"51756","310.50000","25.87518","0.00194"
"51831","310.95000","25.91272","0.00185"
"51906","311.40000","25.95021","0.00160"
"51981","311.85000","25.98764","0.00170"
"52056","312.30000","26.02513","0.00184"
"52131","312.75000","26.06274","0.00171"
"52206","313.20000","26.10022","0.00160"
"52281","313.65000","26.13771","0.00168"
"52356","314.10000","26.17520","0.00158"
"52431","314.55000","26.21263","0.00160"
"52506","315.00000","26.25006","0.00203"
"52581","315.45000","26.28766","0.00186"
"52656","315.90000","26.32521","0.00172"
"52731","316.35000","26.36270","0.00183"
"52806","316.80000","26.40025","0.00170"
"52881","317.25000","26.43768","0.00169"
"52956","317.70000","26.47516","0.00162"
"53031","318.15000","26.51265","0.00191"
"53106","318.60000","26.55020","0.00158"
"53181","319.05000","26.58763","0.00172"
"53256","319.50000","26.62518","0.00160"
"53331","319.95000","26.66266","0.00171"
"53406","320.40000","26.70009","0.00142"
"53481","320.85000","26.73764","0.00177"
"53556","321.30000","26.77519","0.00157"
"53631","321.75000","26.81274","0.00144"
"53706","322.20000","26.85023","0.00140"
"53781","322.65000","26.88765","0.00179"
"53856","323.10000","26.92514","0.00178"
"53931","323.55000","26.96269","0.00168"
"54006","324.00000","27.00023","0.00182"
"54081","324.45000","27.03773","0.00145"
"54156","324.90000","27.07521","0.00151"
"54231","325.35000","27.11264","0.00157"
"54306","325.80000","27.15007","0.00142"
"54381","326.25000","27.18768","0.00173"
"54456","326.70000","27.22522","0.00136"
"54531","327.15000","27.26277","0.00162"
"54606","327.60000","27.30026","0.00156"
"54681","328.05000","27.33763","0.00178"
"54756","328.50000","27.37518","0.00156"
"54831","328.95000","27.41261","0.00148"
"54906","329.40000","27.45021","0.00163"
"54981","329.85000","27.48770","0.00153"
"55056","330.30000","27.52525","0.00162"
"55131","330.75000","27.56268","0.00176"
"55206","331.20000","27.60011","0.00157"
"55281","331.65000","27.63765","0.00153"
"55356","332.10000","27.67514","0.00169"
"55431","332.55000","27.71269","0.00139"
"55506","333.00000","27.75018","0.00141"
"55581","333.45000","27.78766","0.00146"
"55656","333.90000","27.82515","0.00146"
"55731","334.35000","27.86264","0.00134"
"55806","334.80000","27.90019","0.00142"
"55881","335.25000","27.93762","0.00144"
"55956","335.70000","27.97516","0.00130"
"56031","336.15000","28.01271","0.00201"
"56106","336.60000","28.05020","0.00163"
"56181","337.05000","28.08763","0.00167"
"56256","337.50000","28.12518","0.00149"
"56331","337.95000","28.16273","0.00142"
"56406","338.40000","28.20015","0.00149"
"56481","338.85000","28.23770","0.00176"
"56556","339.30000","28.27513","0.00145"
"56631","339.75000","28.31262","0.00159"
"56706","340.20000","28.35016","0.00155"
"56781","340.65000","28.38771","0.00150"
"56856","341.10000","28.42520","0.00179"
"56931","341.55000","28.46269","0.00176"
"57006","342.00000","28.50012","0.00162"
"57081","342.45000","28.53766","0.00205"
"57156","342.90000","28.57521","0.00169"
"57231","343.35000","28.61270","0.00185"
"57306","343.80000","28.65019","0.00150"
"57381","344.25000","28.68774","0.00173"
"57456","344.70000","28.72516","0.00160"
"57531","345.15000","28.76265","0.00155"
"57606","345.60000","28.80014","0.00152"
"57681","346.05000","28.83769","0.00192"
"57756","346.50000","28.87524","0.00157"
"57831","346.95000","28.91278","0.00186"
"57906","347.40000","28.95015","0.00157"
"57981","347.85000","28.98764","0.00186"
"58056","348.30000","29.02513","0.00148"
"58131","348.75000","29.06268","0.00163"
"58206","349.20000","29.10022","0.00138"
"58281","349.65000","29.13771","0.00162"
"58356","350.10000","29.17520","0.00159"
"58431","350.55000","29.21263","0.00155"
"58506","351.00000","29.25011","0.00169"
"58581","351.45000","29.28766","0.00146"
"58656","351.90000","29.32515","0.00161"
"58731","352.35000","29.36270","0.00143"
"58806","352.80000","29.40019","0.00164"
"58881","353.25000","29.43768","0.00160"
"58956","353.70000","29.47517","0.00169"
"59031","354.15000","29.51265","0.00175"
"59106","354.60000","29.55020","0.00159"
"59181","355.05000","29.58769","0.00171"
"59256","355.50000","29.62518","0.00175"
"59331","355.95000","29.66261","0.00162"
"59406","356.40000","29.70015","0.00162"
"59481","356.85000","29.73770","0.00181"
"59556","357.30000","29.77525","0.00134"
"59631","357.75000","29.81268","0.00150"
"59706","358.20000","29.85016","0.00154"
"59781","358.65000","29.88759","0.00152"
"59856","359.10000","29.92514","0.00164"
"59931","359.55000","29.96269","0.00156"
"60006","360.00000","30.00024","0.00142"
"60081","360.45000","30.03772","0.00170"
"60156","360.90000","30.07515","0.00167"
"60231","361.35000","30.11264","0.00130"
"60306","361.80000","30.15019","0.00160"
"60381","362.25000","30.18762","0.00166"
"60456","362.70000","30.22523","0.00113"
"60531","363.15000","30.26271","0.00159"
"60606","363.60000","30.30020","0.00142"
"60681","364.05000","30.33769","0.00139"
"60756","364.50000","30.37512","0.00139"
"60831","364.95000","30.41266","0.00138"
"60906","365.40000","30.45021","0.00155"
"60981","365.85000","30.48770","0.00139"
"61056","366.30000","30.52519","0.00156"
"61131","366.75000","30.56268","0.00176"
"61206","367.20000","30.60011","0.00143"
"61281","367.65000","30.63765","0.00152"
"61356","368.10000","30.67520","0.00158"
"61431","368.55200","30.71281","0.00170"
"61506","369.00200","30.75035","0.00140"
"61581","369.45200","30.78778","0.00157"
"61656","369.90200","30.82533","0.00174"
"61731","370.35200","30.86288","0.00168"
"61806","370.80200","30.90031","0.00140"
"61881","371.25200","30.93786","0.00171"
"61956","371.70200","30.97534","0.00153"
"62031","372.15200","31.01289","0.00139"
"62106","372.60200","31.05032","0.00128"
"62181","373.05200","31.08781","0.00178"
"62256","373.50200","31.12536","0.00143"
"62331","373.95200","31.16285","0.00156"
"62406","374.40200","31.20039","0.00150"
"62481","374.85200","31.23782","0.00155"
"62556","375.30200","31.27525","0.00172"
"62631","375.75200","31.31279","0.00177"
"62706","376.20200","31.35040","0.00160"
"62781","376.65200","31.38789","0.00172"
"62856","377.10200","31.42532","0.00136"
"62931","377.55200","31.46287","0.00154"
"63006","378.00200","31.50030","0.00184"
"63081","378.45200","31.53784","0.00139"
"63156","378.90200","31.57533","0.00172"
"63231","379.35200","31.61288","0.00170"
"63306","379.80200","31.65036","0.00162"
"63381","380.25200","31.68785","0.00139"
"63456","380.70200","31.72534","0.00170"
"63531","381.15200","31.76283","0.00178"
"63606","381.60200","31.80032","0.00145"
"63681","382.05200","31.83787","0.00149"
"63756","382.50200","31.87541","0.00172"
"63831","382.95200","31.91290","0.00170"
"63906","383.40200","31.95033","0.00150"
"63981","383.85200","31.98782","0.00153"
"64056","384.30200","32.02537","0.00157"
"64131","384.75200","32.06292","0.00143"
"64206","385.20200","32.10034","0.00157"
"64281","385.65200","32.13789","0.00136"
"64356","386.10200","32.17532","0.00161"
"64431","386.55200","32.21286","0.00161"
"64506","387.00200","32.25035","0.00119"
"64581","387.45200","32.28784","0.00143"
"64656","387.90200","32.32533","0.00155"
"64731","388.35200","32.36282","0.00155"
"64806","388.80200","32.40037","0.00157"
"64881","389.25200","32.43785","0.00157"
"64956","389.70200","32.47540","0.00132"
"65031","390.15200","32.51283","0.00165"
"65106","390.60200","32.55038","0.00167"
"65181","391.05200","32.58787","0.00130"
"65256","391.50200","32.62529","0.00145"
"65331","391.95200","32.66278","0.00181"
"65406","392.40200","32.70033","0.00155"
"65481","392.85200","32.73788","0.00153"
"65556","393.30200","32.77542","0.00159"
"65631","393.75200","32.81279","0.00152"
"65706","394.20200","32.85035","0.00187"
"65781","394.65200","32.88777","0.00159"
"65856","395.10200","32.92532","0.00149"
"65931","395.55200","32.96287","0.00160"
"66006","396.00200","33.00041","0.00170"
"66081","396.45200","33.03790","0.00188"
"66156","396.90200","33.07533","0.00176"
"66231","397.35200","33.11282","0.00140"
"66306","397.80200","33.15031","0.00157"
"66381","398.25200","33.18785","0.00178"
"66456","398.70200","33.22534","0.00144"
"66531","399.15200","33.26289","0.00143"
"66606","399.60200","33.30038","0.00155"
"66681","400.05200","33.33781","0.00171"
"66756","400.50200","33.37535","0.00170"
"66831","400.95200","33.41284","0.00137"
"66906","401.40200","33.45039","0.00144"
"66981","401.85200","33.48788","0.00144"
"67056","402.30200","33.52531","0.00173"
"67131","402.75200","33.56279","0.00165"
"67206","403.20200","33.60034","0.00144"
"67281","403.65200","33.63789","0.00167"
"67356","404.10200","33.67532","0.00171"
"67431","404.55200","33.71287","0.00160"
"67506","405.00200","33.75035","0.00152"
"67581","405.45200","33.78778","0.00151"
"67656","405.90200","33.82533","0.00147"
"67731","406.35200","33.86288","0.00151"
"67806","406.80200","33.90036","0.00136"
"67881","407.25200","33.93791","0.00152"
"67956","407.70200","33.97534","0.00154"
"68031","408.15200","34.01277","0.00150"
"68106","408.60200","34.05032","0.00159"
"68181","409.05200","34.08787","0.00155"
"68256","409.50200","34.12535","0.00148"
"68331","409.95200","34.16284","0.00168"
"68406","410.40200","34.20033","0.00152"
"68481","410.85200","34.23782","0.00155"
"68556","411.30200","34.27530","0.00192"
"68631","411.75200","34.31280","0.00145"
"68706","412.20200","34.35034","0.00151"
"68781","412.65200","34.38789","0.00167"
"68856","413.10200","34.42538","0.00176"
"68931","413.55200","34.46286","0.00163"
"69006","414.00200","34.50035","0.00155"
"69081","414.45200","34.53778","0.00149"
"69156","414.90200","34.57539","0.00183"
"69231","415.35200","34.61288","0.00169"
"69306","415.80200","34.65037","0.00145"
"69381","416.25200","34.68785","0.00158"
"69456","416.70200","34.72528","0.00159"
"69531","417.15200","34.76283","0.00147"
"69606","417.60200","34.80032","0.00180"
"69681","418.05200","34.83780","0.00163"
"69756","418.50200","34.87535","0.00150"
"69831","418.95200","34.91284","0.00144"
"69906","419.40200","34.95033","0.00139"
"69981","419.85200","34.98788","0.00147"
"70056","420.30200","35.02536","0.00150"
"70131","420.75200","35.06285","0.00155"
"70206","421.20200","35.10040","0.00149"
"70281","421.65200","35.13783","0.00168"
"70356","422.10200","35.17532","0.00158"
"70431","422.55200","35.21281","0.00154"
"70506","423.00200","35.25035","0.00150"
"70581","423.45200","35.28790","0.00129"
"70656","423.90200","35.32539","0.00165"
"70731","424.35200","35.36282","0.00130"
"70806","424.80200","35.40025","0.00174"
"70881","425.25200","35.43779","0.00135"
"70956","425.70200","35.47534","0.00154"
"71031","426.15200","35.51289","0.00155"
"71106","426.60200","35.55032","0.00142"
"71181","427.05200","35.58781","0.00153"
"71256","427.50200","35.62529","0.00181"
"71331","427.95200","35.66284","0.00125"
"71406","428.40200","35.70039","0.00160"
"71481","428.85200","35.73782","0.00137"
"71556","429.30200","35.77542","0.00135"
"71631","429.75200","35.81279","0.00160"
"71706","430.20200","35.85028","0.00179"
"71781","430.65200","35.88783","0.00132"
"71856","431.10200","35.92532","0.00144"
"71931","431.55200","35.96286","0.00135"
"72006","432.00200","36.00035","0.00134"
"72081","432.45200","36.03790","0.00167"
"72156","432.90200","36.07533","0.00136"
"72231","433.35200","36.11282","0.00142"
"72306","433.80200","36.15037","0.00195"
"72381","434.25200","36.18791","0.00178"
"72456","434.70200","36.22534","0.00154"
"72531","435.15200","36.26283","0.00138"
"72606","435.60200","36.30032","0.00131"
"72681","436.05200","36.33781","0.00166"
"72756","436.50200","36.37535","0.00174"
"72831","436.95200","36.41290","0.00134"
"72906","437.40200","36.45027","0.00142"
"72981","437.85200","36.48788","0.00178"
"73056","438.30200","36.52531","0.00169"
"73131","438.75200","36.56285","0.00141"
"73206","439.20200","36.60035","0.00147"
"73281","439.65200","36.63789","0.00159"
"73356","440.10200","36.67538","0.00152"
"73431","440.55200","36.71287","0.00182"
"73506","441.00200","36.75029","0.00144"
"73581","441.45200","36.78784","0.00140"
"73656","441.90200","36.82539","0.00152"
"73731","442.35200","36.86288","0.00157"
"73806","442.80200","36.90043","0.00178"
"73881","443.25200","36.93785","0.00159"
"73956","443.70200","36.97528","0.00154"
"74031","444.15200","37.01277","0.00160"
"74106","444.60200","37.05032","0.00141"
"74181","445.05200","37.08786","0.00131"
"74256","445.50200","37.12535","0.00171"
"74331","445.95200","37.16290","0.00149"
"74406","446.40200","37.20033","0.00161"
"74481","446.85200","37.23782","0.00126"
"74556","447.30200","37.27537","0.00129"
"74631","447.75200","37.31285","0.00147"
"74706","448.20200","37.35034","0.00160"
"74781","448.65200","37.38789","0.00144"
"74856","449.10200","37.42532","0.00173"
"74931","449.55200","37.46280","0.00164"
"75006","450.00200","37.50035","0.00153"
"75081","450.45200","37.53784","0.00140"
"75156","450.90200","37.57539","0.00161"
"75231","451.35200","37.61288","0.00165"
"75306","451.80200","37.65031","0.00178"
"75381","452.25200","37.68779","0.00157"
"75456","452.70200","37.72534","0.00148"
"75531","453.15200","37.76289","0.00170"
"75606","453.60200","37.80038","0.00146"
"75681","454.05200","37.83781","0.00158"
"75756","454.50200","37.87535","0.00143"
"75831","454.95200","37.91278","0.00174"
"75906","455.40200","37.95033","0.00174"
"75981","455.85200","37.98788","0.00159"
"76056","456.30200","38.02536","0.00167"
"76131","456.75200","38.06292","0.00141"
"76206","457.20200","38.10034","0.00171"
"76281","457.65200","38.13783","0.00155"
"76356","458.10200","38.17532","0.00138"
"76431","458.55200","38.21286","0.00174"
"76506","459.00200","38.25041","0.00162"
"76581","459.45200","38.28790","0.00126"
"76656","459.90200","38.32539","0.00165"
"76731","460.35200","38.36276","0.00172"
"76806","460.80200","38.40031","0.00164"
"76881","461.25200","38.43779","0.00150"
"76956","461.70200","38.47540","0.00146"
"77031","462.15200","38.51289","0.00153"
"77106","462.60200","38.55032","0.00148"
"77181","463.05200","38.58781","0.00172"
"77256","463.50200","38.62529","0.00161"
"77331","463.95200","38.66284","0.00140"
"77406","464.40200","38.70033","0.00159"
"77481","464.85200","38.73782","0.00155"
"77556","465.30200","38.77536","0.00147"
"77631","465.75200","38.81285","0.00166"
"77706","466.20200","38.85028","0.00163"
"77781","466.65200","38.88783","0.00168"
"77856","467.10200","38.92538","0.00147"
"77931","467.55200","38.96287","0.00189"
"78006","468.00200","39.00035","0.00157"
"78081","468.45200","39.03784","0.00175"
"78156","468.90200","39.07533","0.00149"
"78231","469.35200","39.11287","0.00184"
"78306","469.80200","39.15036","0.00184"
"78381","470.25200","39.18785","0.00155"
"78456","470.70200","39.22534","0.00163"
"78531","471.15200","39.26283","0.00156"
"78606","471.60200","39.30025","0.00168"
"78681","472.05200","39.33787","0.00151"
"78756","472.50200","39.37541","0.00165"
"78831","472.95200","39.41284","0.00184"
"78906","473.40200","39.45039","0.00175"
"78981","473.85200","39.48788","0.00153"
"79056","474.30200","39.52531","0.00193"
"79131","474.75200","39.56279","0.00186"
"79206","475.20200","39.60040","0.00180"
"79281","475.65200","39.63783","0.00177"
"79356","476.10200","39.67544","0.00176"
"79431","476.55200","39.71281","0.00167"
"79506","477.00200","39.75029","0.00174"
"79581","477.45200","39.78778","0.00179"
"79656","477.90200","39.82533","0.00178"
"79731","478.35200","39.86288","0.00179"
"79806","478.80200","39.90036","0.00202"
"79881","479.25200","39.93785","0.00160"
"79956","479.70200","39.97534","0.00194"
"80031","480.15200","40.01277","0.00203"
"80106","480.60200","40.05038","0.00194"
"80181","481.05200","40.08781","0.00152"
"80256","481.50200","40.12535","0.00161"
"80331","481.95200","40.16284","0.00180"
"80406","482.40200","40.20033","0.00146"
"80481","482.85200","40.23782","0.00178"
"80556","483.30200","40.27536","0.00171"
"80631","483.75200","40.31285","0.00150"
"80706","484.20200","40.35034","0.00191"
"80781","484.65200","40.38783","0.00157"
"80856","485.10200","40.42532","0.00169"
"80931","485.55200","40.46280","0.00182"
"81006","486.00200","40.50035","0.00195"
"81081","486.45200","40.53790","0.00179"
"81156","486.90200","40.57539","0.00183"
"81231","487.35200","40.61282","0.00137"
"81306","487.80200","40.65030","0.00170"
"81381","488.25200","40.68779","0.00202"
"81456","488.70200","40.72534","0.00198"
"81531","489.15200","40.76289","0.00161"
"81606","489.60200","40.80038","0.00180"
"81681","490.05200","40.83786","0.00192"
"81756","490.50200","40.87529","0.00177"
"81831","490.95200","40.91284","0.00161"
"81906","491.40200","40.95033","0.00179"
"81981","491.85200","40.98788","0.00197"
"82056","492.30200","41.02536","0.00201"
"82131","492.75200","41.06291","0.00190"
"82206","493.20200","41.10034","0.00189"
"82281","493.65200","41.13777","0.00189"
"82356","494.10200","41.17532","0.00174"
"82431","494.55200","41.21286","0.00160"
"82506","495.00200","41.25035","0.00190"
"82581","495.45200","41.28790","0.00163"
"82656","495.90200","41.32533","0.00185"
"82731","496.35200","41.36282","0.00144"
"82806","496.80200","41.40031","0.00184"
"82881","497.25200","41.43785","0.00191"
"82956","497.70200","41.47534","0.00155"
"83031","498.15200","41.51289","0.00181"
"83106","498.60200","41.55032","0.00169"
"83181","499.05200","41.58780","0.00169"
"83256","499.50200","41.62535","0.00187"
"83331","499.95200","41.66284","0.00164"
"83406","500.40200","41.70033","0.00194"
"83481","500.85200","41.73782","0.00138"
"83556","501.30200","41.77530","0.00173"
"83631","501.75200","41.81279","0.00146"
"83706","502.20200","41.85028","0.00160"
"83781","502.65200","41.88789","0.00143"
"83856","503.10200","41.92538","0.00173"
"83931","503.55200","41.96292","0.00162"
"84006","504.00200","42.00035","0.00171"
"84081","504.45200","42.03778","0.00133"
"84156","504.90200","42.07533","0.00174"
"84231","505.35200","42.11288","0.00154"
"84306","505.80200","42.15036","0.00176"
"84381","506.25200","42.18785","0.00138"
"84456","506.70200","42.22540","0.00147"
"84531","507.15200","42.26277","0.00146"
"84606","507.60200","42.30032","0.00154"
"84681","508.05200","42.33781","0.00177"
"84756","508.50200","42.37535","0.00174"
"84831","508.95200","42.41290","0.00175"
"84906","509.40200","42.45033","0.00197"
"84981","509.85200","42.48782","0.00143"
"85056","510.30200","42.52531","0.00167"
"85131","510.75200","42.56285","0.00164"
"85206","511.20200","42.60034","0.00157"
"85281","511.65200","42.63789","0.00145"
"85356","512.10200","42.67538","0.00159"
"85431","512.55200","42.71287","0.00162"
"85506","513.00200","42.75029","0.00154"
"85581","513.45200","42.78784","0.00153"
"85656","513.90200","42.82539","0.00130"
"85731","514.35200","42.86282","0.00121"
"85806","514.80200","42.90036","0.00160"
"85881","515.25200","42.93779","0.00150"
"85956","515.70200","42.97535","0.00136"
"86031","516.15200","43.01283","0.00156"
"86106","516.60200","43.05032","0.00153"
"86181","517.05200","43.08787","0.00143"
"86256","517.50200","43.12529","0.00137"
"86331","517.95200","43.16284","0.00152"
"86406","518.40200","43.20033","0.00139"
"86481","518.85200","43.23788","0.00135"
"86556","519.30200","43.27536","0.00160"
"86631","519.75200","43.31285","0.00141"
"86706","520.20200","43.35034","0.00148"
"86781","520.65200","43.38777","0.00138"
"86856","521.10200","43.42532","0.00111"
"86931","521.55200","43.46281","0.00142"
"87006","522.00200","43.50035","0.00131"
"87081","522.45200","43.53790","0.00138"
"87156","522.90200","43.57533","0.00133"
"87231","523.35200","43.61288","0.00134"
"87306","523.80200","43.65031","0.00143"
"87381","524.25200","43.68785","0.00133"
"87456","524.70200","43.72534","0.00135"
"87531","525.15200","43.76294","0.00118"
"87606","525.60200","43.80038","0.00137"
"87681","526.05200","43.83787","0.00124"
"87756","526.50200","43.87535","0.00122"
"87831","526.95200","43.91278","0.00128"
"87906","527.40200","43.95033","0.00153"
"87981","527.85200","43.98788","0.00144"
"88056","528.30200","44.02542","0.00142"
"88131","528.75200","44.06291","0.00121"
"88206","529.20200","44.10028","0.00127"
"88281","529.65200","44.13783","0.00121"
"88356","530.10200","44.17532","0.00091"
"88431","530.55200","44.21287","0.00131"
"88506","531.00200","44.25035","0.00132"
"88581","531.45200","44.28784","0.00107"
"88656","531.90200","44.32533","0.00100"
"88731","532.35200","44.36288","0.00120"
"88806","532.80200","44.40036","0.00125"
"88881","533.25200","44.43785","0.00091"
"88956","533.70200","44.47534","0.00112"
"89031","534.15200","44.51283","0.00117"
"89106","534.60200","44.55032","0.00140"
"89181","535.05200","44.58781","0.00122"
"89256","535.50200","44.62535","0.00102"
"89331","535.95200","44.66290","0.00098"
"89406","536.40200","44.70039","0.00073"
"89481","536.85200","44.73788","0.00108"
"89556","537.30200","44.77525","0.00121"
"89631","537.75200","44.81279","0.00100"
"89706","538.20200","44.85040","0.00117"
"89781","538.65200","44.88789","0.00102"
"89856","539.10200","44.92538","0.00116"
"89931","539.55200","44.96286","0.00124"
"90006","540.00200","45.00030","0.00136"
"90081","540.45200","45.03784","0.00100"
"90156","540.90200","45.07533","0.00132"
"90231","541.35200","45.11288","0.00094"
"90306","541.80200","45.15036","0.00123"
"90381","542.25200","45.18785","0.00083"
"90456","542.70200","45.22534","0.00097"
"90531","543.15200","45.26283","0.00136"
"90606","543.60200","45.30032","0.00133"
"90681","544.05200","45.33787","0.00097"
"90756","544.50200","45.37535","0.00114"
"90831","544.95200","45.41290","0.00102"
"90906","545.40200","45.45039","0.00131"
"90981","545.85200","45.48775","0.00123"
"91056","546.30200","45.52536","0.00096"
"91131","546.75200","45.56285","0.00118"
"91206","547.20200","45.60034","0.00102"
"91281","547.65200","45.63783","0.00089"
"91356","548.10200","45.67532","0.00123"
"91431","548.55200","45.71281","0.00120"
"91506","549.00200","45.75041","0.00114"
"91581","549.45200","45.78790","0.00105"
"91656","549.90200","45.82539","0.00120"
"91731","550.35200","45.86288","0.00101"
"91806","550.80200","45.90031","0.00135"
"91881","551.25200","45.93779","0.00113"
"91956","551.70200","45.97534","0.00105"
"92031","552.15200","46.01283","0.00099"
"92106","552.60200","46.05032","0.00131"
"92181","553.05200","46.08786","0.00091"
"92256","553.50200","46.12535","0.00106"
"92331","553.95200","46.16278","0.00113"
"92406","554.40200","46.20033","0.00093"
"92481","554.85200","46.23788","0.00095"
"92556","555.30200","46.27537","0.00112"
"92589","555.50000","46.29187","0.00117"