File: Trajectories_together/161226_2Specimen_RawData_4.csv
"","V1","V2","V3"
"1","End date","12/26/2016",""
"2","Specimen label","11BG_81_1",""
"3","Maximum Load","0.25816","N"
"4","Time","Extension","Load"
"5","(s)","(mm)","(N)"
"6","0.00000","0.00000","0.00109"
"67","0.36600","0.03061","0.00183"
"128","0.73200","0.06116","0.00198"
"189","1.09800","0.09178","0.00201"
"250","1.46400","0.12221","0.00277"
"311","1.83000","0.15264","0.00268"
"372","2.19600","0.18320","0.00274"
"433","2.56200","0.21369","0.00237"
"494","2.92800","0.24418","0.00251"
"555","3.29400","0.27473","0.00300"
"616","3.66000","0.30523","0.00333"
"677","4.02600","0.33572","0.00292"
"738","4.39200","0.36615","0.00319"
"799","4.75800","0.39676","0.00353"
"860","5.12400","0.42714","0.00390"
"921","5.49000","0.45775","0.00416"
"982","5.85600","0.48824","0.00400"
"1043","6.22200","0.51867","0.00393"
"1104","6.58800","0.54917","0.00408"
"1165","6.95400","0.57972","0.00369"
"1226","7.32000","0.61021","0.00397"
"1287","7.68600","0.64070","0.00416"
"1348","8.05200","0.67120","0.00408"
"1409","8.41800","0.70163","0.00440"
"1470","8.78400","0.73212","0.00478"
"1531","9.15000","0.76274","0.00397"
"1592","9.51600","0.79317","0.00360"
"1653","9.88200","0.82372","0.00455"
"1714","10.24800","0.85427","0.00427"
"1775","10.61400","0.88471","0.00409"
"1836","10.98000","0.91520","0.00484"
"1897","11.34600","0.94575","0.00451"
"1958","11.71200","0.97618","0.00464"
"2019","12.07800","1.00668","0.00473"
"2080","12.44400","1.03717","0.00477"
"2141","12.81000","1.06772","0.00479"
"2202","13.17600","1.09815","0.00444"
"2263","13.54200","1.12865","0.00472"
"2324","13.90800","1.15920","0.00535"
"2385","14.27400","1.18963","0.00491"
"2446","14.64000","1.22018","0.00500"
"2507","15.00600","1.25068","0.00501"
"2568","15.37200","1.28117","0.00506"
"2629","15.73800","1.31172","0.00537"
"2690","16.10400","1.34222","0.00501"
"2751","16.47000","1.37265","0.00523"
"2812","16.83600","1.40314","0.00540"
"2873","17.20200","1.43375","0.00529"
"2934","17.56800","1.46419","0.00607"
"2995","17.93400","1.49462","0.00515"
"3056","18.30000","1.52523","0.00576"
"3117","18.66600","1.55572","0.00536"
"3178","19.03200","1.58616","0.00535"
"3239","19.39800","1.61671","0.00550"
"3300","19.76400","1.64720","0.00555"
"3361","20.13000","1.67769","0.00534"
"3422","20.49600","1.70825","0.00555"
"3483","20.86200","1.73874","0.00526"
"3544","21.22800","1.76923","0.00544"
"3605","21.59400","1.79967","0.00588"
"3666","21.96000","1.83028","0.00598"
"3727","22.32600","1.86065","0.00598"
"3788","22.69200","1.89120","0.00638"
"3849","23.05800","1.92170","0.00570"
"3910","23.42400","1.95219","0.00560"
"3971","23.79000","1.98268","0.00602"
"4032","24.15600","2.01317","0.00621"
"4093","24.52200","2.04373","0.00564"
"4154","24.88800","2.07416","0.00596"
"4215","25.25400","2.10477","0.00587"
"4276","25.62000","2.13514","0.00585"
"4337","25.98600","2.16564","0.00614"
"4398","26.35200","2.19619","0.00631"
"4459","26.71800","2.22674","0.00631"
"4520","27.08400","2.25717","0.00592"
"4581","27.45000","2.28773","0.00552"
"4642","27.81600","2.31816","0.00552"
"4703","28.18200","2.34865","0.00580"
"4764","28.54800","2.37926","0.00576"
"4825","28.91400","2.40976","0.00528"
"4886","29.28000","2.44019","0.00593"
"4947","29.64600","2.47068","0.00593"
"5008","30.01200","2.50130","0.00574"
"5069","30.37800","2.53161","0.00567"
"5130","30.74400","2.56216","0.00517"
"5191","31.11000","2.59271","0.00576"
"5252","31.47600","2.62321","0.00618"
"5313","31.84200","2.65376","0.00561"
"5374","32.20800","2.68419","0.00537"
"5435","32.57400","2.71468","0.00623"
"5496","32.94000","2.74518","0.00577"
"5557","33.30600","2.77579","0.00583"
"5618","33.67200","2.80616","0.00608"
"5679","34.03800","2.83671","0.00600"
"5740","34.40400","2.86721","0.00605"
"5801","34.77000","2.89770","0.00655"
"5862","35.13600","2.92819","0.00615"
"5923","35.50200","2.95874","0.00590"
"5984","35.86800","2.98924","0.00591"
"6045","36.23400","3.01973","0.00649"
"6106","36.60000","3.05028","0.00601"
"6167","36.96600","3.08072","0.00594"
"6228","37.33200","3.11121","0.00623"
"6289","37.69800","3.14170","0.00591"
"6350","38.06400","3.17225","0.00603"
"6411","38.43000","3.20269","0.00616"
"6472","38.79600","3.23318","0.00616"
"6533","39.16200","3.26373","0.00672"
"6594","39.52800","3.29416","0.00647"
"6655","39.89400","3.32472","0.00661"
"6716","40.26000","3.35521","0.00626"
"6777","40.62600","3.38570","0.00656"
"6838","40.99200","3.41619","0.00621"
"6899","41.35800","3.44675","0.00669"
"6960","41.72400","3.47718","0.00631"
"7021","42.09000","3.50767","0.00671"
"7082","42.45600","3.53822","0.00666"
"7143","42.82200","3.56872","0.00671"
"7204","43.18800","3.59921","0.00627"
"7265","43.55400","3.62970","0.00659"
"7326","43.92000","3.66020","0.00600"
"7387","44.28600","3.69069","0.00662"
"7448","44.65200","3.72124","0.00704"
"7509","45.01800","3.75167","0.00659"
"7570","45.38400","3.78211","0.00666"
"7631","45.75000","3.81272","0.00695"
"7692","46.11600","3.84321","0.00639"
"7753","46.48200","3.87370","0.00682"
"7814","46.84800","3.90426","0.00621"
"7875","47.21400","3.93475","0.00705"
"7936","47.58000","3.96512","0.00665"
"7997","47.94600","3.99573","0.00675"
"8058","48.31200","4.02623","0.00727"
"8119","48.67800","4.05666","0.00672"
"8180","49.04400","4.08721","0.00748"
"8241","49.41000","4.11770","0.00708"
"8302","49.77600","4.14814","0.00636"
"8363","50.14200","4.17869","0.00677"
"8424","50.50800","4.20924","0.00746"
"8485","50.87400","4.23962","0.00650"
"8546","51.24000","4.27023","0.00637"
"8607","51.60600","4.30072","0.00649"
"8668","51.97200","4.33115","0.00723"
"8729","52.33800","4.36171","0.00659"
"8790","52.70400","4.39220","0.00635"
"8851","53.07000","4.42263","0.00719"
"8912","53.43600","4.45318","0.00666"
"8973","53.80200","4.48374","0.00631"
"9034","54.16800","4.51423","0.00659"
"9095","54.53400","4.54472","0.00672"
"9156","54.90000","4.57521","0.00665"
"9217","55.26600","4.60571","0.00658"
"9278","55.63200","4.63620","0.00668"
"9339","55.99800","4.66669","0.00661"
"9400","56.36400","4.69725","0.00692"
"9461","56.73000","4.72768","0.00667"
"9522","57.09600","4.75823","0.00684"
"9583","57.46200","4.78872","0.00706"
"9644","57.82800","4.81916","0.00679"
"9705","58.19400","4.84965","0.00722"
"9766","58.56000","4.88026","0.00639"
"9827","58.92600","4.91069","0.00643"
"9888","59.29200","4.94119","0.00666"
"9949","59.65800","4.97174","0.00668"
"10010","60.02400","5.00217","0.00657"
"10071","60.39000","5.03266","0.00698"
"10132","60.75600","5.06322","0.00662"
"10193","61.12200","5.09377","0.00662"
"10254","61.48800","5.12420","0.00686"
"10315","61.85400","5.15475","0.00635"
"10376","62.22000","5.18519","0.00689"
"10437","62.58600","5.21568","0.00608"
"10498","62.95200","5.24623","0.00650"
"10559","63.31800","5.27673","0.00667"
"10620","63.68400","5.30722","0.00662"
"10681","64.05000","5.33771","0.00709"
"10742","64.41600","5.36826","0.00713"
"10803","64.78200","5.39870","0.00635"
"10864","65.14800","5.42925","0.00691"
"10925","65.51400","5.45968","0.00700"
"10986","65.88000","5.49017","0.00694"
"11047","66.24600","5.52073","0.00743"
"11108","66.61200","5.55122","0.00657"
"11169","66.97800","5.58165","0.00693"
"11230","67.34400","5.61220","0.00733"
"11291","67.71000","5.64276","0.00659"
"11352","68.07600","5.67313","0.00723"
"11413","68.44200","5.70374","0.00712"
"11474","68.80800","5.73417","0.00706"
"11535","69.17400","5.76473","0.00695"
"11596","69.54000","5.79516","0.00698"
"11657","69.90600","5.82571","0.00712"
"11718","70.27200","5.85615","0.00703"
"11779","70.63800","5.88670","0.00622"
"11840","71.00400","5.91719","0.00734"
"11901","71.37000","5.94774","0.00696"
"11962","71.73600","5.97824","0.00759"
"12023","72.10200","6.00873","0.00665"
"12084","72.46800","6.03922","0.00729"
"12145","72.83400","6.06971","0.00699"
"12206","73.20000","6.10021","0.00709"
"12267","73.56600","6.13070","0.00745"
"12328","73.93200","6.16119","0.00720"
"12389","74.29800","6.19168","0.00755"
"12450","74.66400","6.22224","0.00748"
"12511","75.03000","6.25267","0.00712"
"12572","75.39600","6.28322","0.00735"
"12633","75.76200","6.31377","0.00769"
"12694","76.12800","6.34415","0.00711"
"12755","76.49400","6.37470","0.00742"
"12816","76.86000","6.40519","0.00675"
"12877","77.22600","6.43569","0.00695"
"12938","77.59200","6.46618","0.00708"
"12999","77.95800","6.49673","0.00665"
"13060","78.32400","6.52716","0.00670"
"13121","78.69000","6.55772","0.00700"
"13182","79.05600","6.58827","0.00676"
"13243","79.42200","6.61870","0.00675"
"13304","79.78800","6.64919","0.00720"
"13365","80.15400","6.67975","0.00731"
"13426","80.52000","6.71018","0.00706"
"13487","80.88600","6.74067","0.00694"
"13548","81.25200","6.77122","0.00637"
"13609","81.61800","6.80172","0.00658"
"13670","81.98400","6.83215","0.00698"
"13731","82.35000","6.86270","0.00675"
"13792","82.71600","6.89320","0.00696"
"13853","83.08200","6.92369","0.00688"
"13914","83.44800","6.95418","0.00730"
"13975","83.81400","6.98473","0.00694"
"14036","84.18000","7.01517","0.00704"
"14097","84.54600","7.04572","0.00738"
"14158","84.91200","7.07621","0.00697"
"14219","85.27800","7.10664","0.00691"
"14280","85.64400","7.13726","0.00688"
"14341","86.01000","7.16769","0.00706"
"14402","86.37600","7.19818","0.00776"
"14463","86.74200","7.22867","0.00687"
"14524","87.10800","7.25929","0.00756"
"14585","87.47400","7.28972","0.00770"
"14646","87.84000","7.32015","0.00741"
"14707","88.20600","7.35071","0.00739"
"14768","88.57200","7.38120","0.00707"
"14829","88.93800","7.41169","0.00749"
"14890","89.30400","7.44218","0.00808"
"14951","89.67000","7.47273","0.00715"
"15012","90.03600","7.50323","0.00784"
"15073","90.40200","7.53372","0.00751"
"15134","90.76800","7.56421","0.00792"
"15195","91.13400","7.59471","0.00765"
"15256","91.50000","7.62520","0.00761"
"15317","91.86600","7.65575","0.00796"
"15378","92.23200","7.68618","0.00756"
"15439","92.59800","7.71674","0.00774"
"15500","92.96400","7.74723","0.00714"
"15561","93.33000","7.77766","0.00774"
"15622","93.69600","7.80827","0.00720"
"15683","94.06200","7.83877","0.00743"
"15744","94.42800","7.86920","0.00741"
"15805","94.79400","7.89963","0.00777"
"15866","95.16000","7.93018","0.00776"
"15927","95.52600","7.96068","0.00766"
"15988","95.89200","7.99117","0.00822"
"16049","96.25800","8.02172","0.00837"
"16110","96.62400","8.05221","0.00769"
"16171","96.99000","8.08271","0.00762"
"16232","97.35600","8.11320","0.00791"
"16293","97.72200","8.14369","0.00790"
"16354","98.08800","8.17419","0.00827"
"16415","98.45400","8.20474","0.00768"
"16476","98.82000","8.23517","0.00794"
"16537","99.18600","8.26566","0.00826"
"16598","99.55200","8.29616","0.00834"
"16659","99.91800","8.32665","0.00787"
"16720","100.28400","8.35714","0.00797"
"16781","100.65000","8.38775","0.00825"
"16842","101.01600","8.41825","0.00843"
"16903","101.38200","8.44862","0.00796"
"16964","101.74800","8.47929","0.00835"
"17025","102.11400","8.50972","0.00881"
"17086","102.48000","8.54016","0.00755"
"17147","102.84600","8.57071","0.00804"
"17208","103.21200","8.60126","0.00821"
"17269","103.57800","8.63164","0.00841"
"17330","103.94400","8.66219","0.00823"
"17391","104.31000","8.69280","0.00830"
"17452","104.67600","8.72317","0.00818"
"17513","105.04200","8.75379","0.00852"
"17574","105.40800","8.78416","0.00850"
"17635","105.77400","8.81471","0.00823"
"17696","106.14000","8.84514","0.00852"
"17757","106.50600","8.87570","0.00838"
"17818","106.87200","8.90619","0.00780"
"17879","107.23800","8.93668","0.00846"
"17940","107.60400","8.96723","0.00773"
"18001","107.97000","8.99767","0.00857"
"18062","108.33600","9.02822","0.00875"
"18123","108.70200","9.05877","0.00819"
"18184","109.06800","9.08920","0.00842"
"18245","109.43400","9.11964","0.00889"
"18306","109.80000","9.15025","0.00849"
"18367","110.16600","9.18068","0.00850"
"18428","110.53200","9.21112","0.00811"
"18489","110.89800","9.24173","0.00844"
"18550","111.26400","9.27228","0.00841"
"18611","111.63000","9.30271","0.00846"
"18672","111.99600","9.33321","0.00828"
"18733","112.36200","9.36376","0.00824"
"18794","112.72800","9.39413","0.00873"
"18855","113.09400","9.42474","0.00865"
"18916","113.46000","9.45524","0.00893"
"18977","113.82600","9.48567","0.00860"
"19038","114.19200","9.51622","0.00846"
"19099","114.55800","9.54671","0.00868"
"19160","114.92400","9.57715","0.00858"
"19221","115.29000","9.60770","0.00846"
"19282","115.65600","9.63831","0.00805"
"19343","116.02200","9.66875","0.00820"
"19404","116.38800","9.69918","0.00810"
"19465","116.75400","9.72967","0.00800"
"19526","117.12000","9.76016","0.00820"
"19587","117.48600","9.79066","0.00869"
"19648","117.85200","9.82127","0.00825"
"19709","118.21800","9.85176","0.00865"
"19770","118.58400","9.88213","0.00860"
"19831","118.95000","9.91275","0.00867"
"19892","119.31600","9.94324","0.00859"
"19953","119.68200","9.97367","0.00858"
"20014","120.04800","10.00422","0.00864"
"20075","120.41400","10.03472","0.00871"
"20136","120.78000","10.06515","0.00803"
"20197","121.14600","10.09570","0.00872"
"20258","121.51200","10.12619","0.00830"
"20319","121.87800","10.15669","0.00880"
"20380","122.24400","10.18724","0.00881"
"20441","122.61000","10.21767","0.00794"
"20502","122.97600","10.24823","0.00830"
"20563","123.34200","10.27872","0.00821"
"20624","123.70800","10.30921","0.00835"
"20685","124.07400","10.33970","0.00829"
"20746","124.44000","10.37020","0.00858"
"20807","124.80600","10.40069","0.00843"
"20868","125.17200","10.43118","0.00848"
"20929","125.53800","10.46167","0.00883"
"20990","125.90400","10.49223","0.00801"
"21051","126.27000","10.52272","0.00870"
"21112","126.63600","10.55315","0.00833"
"21173","127.00200","10.58376","0.00852"
"21234","127.36800","10.61420","0.00833"
"21295","127.73400","10.64469","0.00852"
"21356","128.10000","10.67518","0.00851"
"21417","128.46600","10.70579","0.00857"
"21478","128.83200","10.73611","0.00838"
"21539","129.19800","10.76666","0.00828"
"21600","129.56400","10.79721","0.00846"
"21661","129.93000","10.82765","0.00844"
"21722","130.29600","10.85826","0.00894"
"21783","130.66200","10.88869","0.00894"
"21844","131.02800","10.91924","0.00861"
"21905","131.39400","10.94968","0.00785"
"21966","131.76000","10.98017","0.00888"
"22027","132.12600","11.01066","0.00899"
"22088","132.49200","11.04121","0.00893"
"22149","132.85800","11.07177","0.00920"
"22210","133.22400","11.10214","0.00858"
"22271","133.59000","11.13269","0.00833"
"22332","133.95600","11.16318","0.00883"
"22393","134.32200","11.19374","0.00883"
"22454","134.68800","11.22417","0.00854"
"22515","135.05400","11.25472","0.00833"
"22576","135.42000","11.28521","0.00850"
"22637","135.78600","11.31565","0.00869"
"22698","136.15200","11.34626","0.00835"
"22759","136.51800","11.37675","0.00903"
"22820","136.88400","11.40718","0.00935"
"22881","137.25000","11.43774","0.00898"
"22942","137.61600","11.46823","0.00902"
"23003","137.98200","11.49860","0.00767"
"23064","138.34800","11.52922","0.00805"
"23125","138.71400","11.55971","0.00779"
"23186","139.08000","11.59020","0.00822"
"23247","139.44600","11.62069","0.00847"
"23308","139.81200","11.65119","0.00844"
"23369","140.17800","11.68168","0.00857"
"23430","140.54400","11.71217","0.00867"
"23491","140.91000","11.74272","0.00771"
"23552","141.27600","11.77316","0.00829"
"23613","141.64200","11.80371","0.00856"
"23674","142.00800","11.83420","0.00795"
"23735","142.37400","11.86469","0.00827"
"23796","142.74000","11.89513","0.00776"
"23857","143.10600","11.92574","0.00758"
"23918","143.47200","11.95623","0.00802"
"23979","143.83800","11.98661","0.00807"
"24040","144.20400","12.01722","0.00743"
"24101","144.57000","12.04771","0.00808"
"24162","144.93600","12.07814","0.00817"
"24223","145.30200","12.10876","0.00841"
"24284","145.66800","12.13925","0.00846"
"24345","146.03400","12.16968","0.00804"
"24406","146.40000","12.20017","0.00741"
"24467","146.76600","12.23067","0.00797"
"24528","147.13200","12.26116","0.00797"
"24589","147.49800","12.29171","0.00807"
"24650","147.86400","12.32220","0.00827"
"24711","148.23000","12.35270","0.00808"
"24772","148.59600","12.38319","0.00768"
"24833","148.96200","12.41374","0.00788"
"24894","149.32800","12.44411","0.00835"
"24955","149.69400","12.47473","0.00846"
"25016","150.06000","12.50522","0.00789"
"25077","150.42600","12.53571","0.00799"
"25138","150.79200","12.56615","0.00802"
"25199","151.15800","12.59670","0.00814"
"25260","151.52400","12.62725","0.00809"
"25321","151.89000","12.65768","0.00798"
"25382","152.25600","12.68818","0.00801"
"25443","152.62200","12.71873","0.00797"
"25504","152.98800","12.74916","0.00804"
"25565","153.35400","12.77971","0.00863"
"25626","153.72000","12.81027","0.00835"
"25687","154.08600","12.84070","0.00865"
"25748","154.45200","12.87119","0.00850"
"25809","154.81800","12.90168","0.00839"
"25870","155.18400","12.93212","0.00813"
"25931","155.55000","12.96273","0.00842"
"25992","155.91600","12.99322","0.00869"
"26053","156.28200","13.02366","0.00893"
"26114","156.64800","13.05421","0.00842"
"26175","157.01400","13.08470","0.00850"
"26236","157.38000","13.11513","0.00872"
"26297","157.74600","13.14574","0.00863"
"26358","158.11200","13.17624","0.00929"
"26419","158.47800","13.20667","0.00858"
"26480","158.84400","13.23722","0.00830"
"26541","159.21000","13.26772","0.00864"
"26602","159.57600","13.29815","0.00853"
"26663","159.94200","13.32864","0.00859"
"26724","160.30800","13.35919","0.00888"
"26785","160.67400","13.38969","0.00899"
"26846","161.04000","13.42018","0.00872"
"26907","161.40600","13.45073","0.00878"
"26968","161.77200","13.48116","0.00908"
"27029","162.13800","13.51166","0.00900"
"27090","162.50400","13.54221","0.00917"
"27151","162.87000","13.57270","0.00912"
"27212","163.23600","13.60320","0.00917"
"27273","163.60200","13.63375","0.00952"
"27334","163.96800","13.66424","0.00928"
"27395","164.33400","13.69467","0.00927"
"27456","164.70000","13.72523","0.00928"
"27517","165.06600","13.75572","0.00930"
"27578","165.43200","13.78615","0.00913"
"27639","165.79800","13.81670","0.00878"
"27700","166.16400","13.84726","0.00869"
"27761","166.53000","13.87769","0.00958"
"27822","166.89600","13.90824","0.00918"
"27883","167.26200","13.93867","0.00948"
"27944","167.62800","13.96911","0.00914"
"28005","167.99400","13.99966","0.00930"
"28066","168.36000","14.03021","0.00966"
"28127","168.72600","14.06070","0.00962"
"28188","169.09200","14.09120","0.00942"
"28249","169.45800","14.12175","0.00933"
"28310","169.82400","14.15218","0.00905"
"28371","170.19000","14.18267","0.00904"
"28432","170.55600","14.21323","0.00995"
"28493","170.92200","14.24372","0.00929"
"28554","171.28800","14.27415","0.00969"
"28615","171.65400","14.30471","0.00942"
"28676","172.02000","14.33520","0.00908"
"28737","172.38600","14.36563","0.00917"
"28798","172.75200","14.39624","0.00991"
"28859","173.11800","14.42674","0.00994"
"28920","173.48400","14.45717","0.00968"
"28981","173.85000","14.48772","0.00927"
"29042","174.21600","14.51821","0.00923"
"29103","174.58200","14.54859","0.00975"
"29164","174.94800","14.57920","0.00954"
"29225","175.31400","14.60975","0.00960"
"29286","175.68000","14.64019","0.00947"
"29347","176.04600","14.67068","0.00962"
"29408","176.41200","14.70123","0.00961"
"29469","176.77800","14.73172","0.00969"
"29530","177.14400","14.76216","0.00978"
"29591","177.51000","14.79271","0.00996"
"29652","177.87600","14.82314","0.00969"
"29713","178.24200","14.85375","0.01010"
"29774","178.60800","14.88419","0.00921"
"29835","178.97400","14.91468","0.00988"
"29896","179.34000","14.94523","0.01016"
"29957","179.70600","14.97572","0.00987"
"30018","180.07200","15.00622","0.00977"
"30079","180.43800","15.03665","0.00986"
"30140","180.80400","15.06720","0.00923"
"30201","181.17000","15.09769","0.01002"
"30262","181.53600","15.12825","0.01015"
"30323","181.90200","15.15874","0.01004"
"30384","182.26800","15.18923","0.00936"
"30445","182.63400","15.21967","0.00934"
"30506","183.00000","15.25016","0.01012"
"30567","183.36600","15.28077","0.00995"
"30628","183.73200","15.31114","0.01011"
"30689","184.09800","15.34170","0.01015"
"30750","184.46400","15.37219","0.01023"
"30811","184.83000","15.40268","0.00984"
"30872","185.19600","15.43317","0.00988"
"30933","185.56200","15.46373","0.00983"
"30994","185.92800","15.49416","0.01034"
"31055","186.29400","15.52471","0.01023"
"31116","186.66000","15.55520","0.01014"
"31177","187.02600","15.58570","0.01036"
"31238","187.39200","15.61619","0.01043"
"31299","187.75800","15.64668","0.01023"
"31360","188.12400","15.67723","0.01032"
"31421","188.49000","15.70773","0.01056"
"31482","188.85600","15.73822","0.01051"
"31543","189.22200","15.76865","0.01005"
"31604","189.58800","15.79920","0.01044"
"31665","189.95400","15.82976","0.01070"
"31726","190.32000","15.86019","0.01090"
"31787","190.68600","15.89068","0.01073"
"31848","191.05200","15.92124","0.01020"
"31909","191.41800","15.95173","0.01051"
"31970","191.78400","15.98210","0.01020"
"32031","192.15000","16.01271","0.01056"
"32092","192.51600","16.04321","0.01077"
"32153","192.88200","16.07370","0.01060"
"32214","193.24800","16.10413","0.01023"
"32275","193.61400","16.13468","0.01034"
"32336","193.98000","16.16518","0.01036"
"32397","194.34600","16.19567","0.01060"
"32458","194.71200","16.22628","0.01085"
"32519","195.07800","16.25665","0.01049"
"32580","195.44400","16.28727","0.01066"
"32641","195.81000","16.31770","0.01045"
"32702","196.17600","16.34813","0.01093"
"32763","196.54200","16.37868","0.01090"
"32824","196.90800","16.40918","0.01040"
"32885","197.27400","16.43967","0.01030"
"32946","197.64000","16.47016","0.01012"
"33007","198.00600","16.50072","0.01051"
"33068","198.37200","16.53115","0.01022"
"33129","198.73800","16.56170","0.01048"
"33190","199.10400","16.59219","0.01036"
"33251","199.47000","16.62275","0.00997"
"33312","199.83600","16.65318","0.01056"
"33373","200.20200","16.68373","0.01037"
"33434","200.56800","16.71422","0.01017"
"33495","200.93400","16.74466","0.01069"
"33556","201.30000","16.77521","0.01060"
"33617","201.66600","16.80576","0.01071"
"33678","202.03200","16.83619","0.01078"
"33739","202.39800","16.86663","0.01076"
"33800","202.76400","16.89724","0.01072"
"33861","203.13000","16.92761","0.01029"
"33922","203.49600","16.95816","0.00997"
"33983","203.86200","16.98872","0.01013"
"34044","204.22800","17.01921","0.01041"
"34105","204.59400","17.04970","0.01038"
"34166","204.96000","17.08026","0.01084"
"34227","205.32600","17.11069","0.01078"
"34288","205.69200","17.14118","0.01032"
"34349","206.05800","17.17173","0.01056"
"34410","206.42400","17.20217","0.01053"
"34471","206.79000","17.23272","0.01062"
"34532","207.15600","17.26321","0.01080"
"34593","207.52200","17.29370","0.01029"
"34654","207.88800","17.32414","0.00992"
"34715","208.25400","17.35475","0.01017"
"34776","208.62000","17.38524","0.01078"
"34837","208.98600","17.41567","0.01028"
"34898","209.35200","17.44623","0.01007"
"34959","209.71800","17.47672","0.01018"
"35020","210.08400","17.50721","0.01024"
"35081","210.45000","17.53765","0.01049"
"35142","210.81600","17.56826","0.01024"
"35203","211.18200","17.59863","0.01023"
"35264","211.54800","17.62918","0.01025"
"35325","211.91400","17.65973","0.01037"
"35386","212.28000","17.69017","0.01077"
"35447","212.64600","17.72072","0.01031"
"35508","213.01200","17.75121","0.01040"
"35569","213.37800","17.78171","0.01019"
"35630","213.74400","17.81220","0.01026"
"35691","214.11000","17.84275","0.01023"
"35752","214.47600","17.87318","0.01014"
"35813","214.84200","17.90374","0.01063"
"35874","215.20800","17.93423","0.01072"
"35935","215.57400","17.96466","0.01087"
"35996","215.94000","17.99516","0.01058"
"36057","216.30600","18.02571","0.01071"
"36118","216.67200","18.05620","0.01078"
"36179","217.03800","18.08669","0.01095"
"36240","217.40400","18.11724","0.01086"
"36301","217.77000","18.14774","0.01109"
"36362","218.13600","18.17817","0.01099"
"36423","218.50200","18.20866","0.01068"
"36484","218.86800","18.23922","0.01099"
"36545","219.23400","18.26965","0.01130"
"36606","219.60000","18.30020","0.01125"
"36667","219.96600","18.33075","0.01176"
"36728","220.33200","18.36119","0.01109"
"36789","220.69800","18.39174","0.01129"
"36850","221.06400","18.42223","0.01138"
"36911","221.43000","18.45267","0.01137"
"36972","221.79600","18.48316","0.01118"
"37033","222.16200","18.51371","0.01117"
"37094","222.52800","18.54420","0.01143"
"37155","222.89400","18.57469","0.01118"
"37216","223.26000","18.60525","0.01156"
"37277","223.62600","18.63562","0.01136"
"37338","223.99200","18.66617","0.01134"
"37399","224.35800","18.69673","0.01159"
"37460","224.72400","18.72716","0.01133"
"37521","225.09000","18.75771","0.01107"
"37582","225.45600","18.78826","0.01146"
"37643","225.82200","18.81870","0.01141"
"37704","226.18800","18.84919","0.01171"
"37765","226.55400","18.87974","0.01136"
"37826","226.92000","18.91017","0.01167"
"37887","227.28600","18.94067","0.01118"
"37948","227.65200","18.97122","0.01139"
"38009","228.01800","19.00171","0.01151"
"38070","228.38400","19.03214","0.01159"
"38131","228.75000","19.06270","0.01151"
"38192","229.11600","19.09319","0.01169"
"38253","229.48200","19.12362","0.01180"
"38314","229.84800","19.15417","0.01180"
"38375","230.21400","19.18473","0.01206"
"38436","230.58000","19.21516","0.01181"
"38497","230.94600","19.24571","0.01181"
"38558","231.31200","19.27626","0.01163"
"38619","231.67800","19.30664","0.01171"
"38680","232.04400","19.33719","0.01202"
"38741","232.41000","19.36774","0.01168"
"38802","232.77600","19.39817","0.01172"
"38863","233.14200","19.42867","0.01157"
"38924","233.50800","19.45922","0.01187"
"38985","233.87400","19.48971","0.01186"
"39046","234.24000","19.52021","0.01199"
"39107","234.60600","19.55076","0.01179"
"39168","234.97200","19.58119","0.01198"
"39229","235.33800","19.61174","0.01188"
"39290","235.70400","19.64224","0.01227"
"39351","236.07000","19.67273","0.01245"
"39412","236.43600","19.70316","0.01223"
"39473","236.80200","19.73365","0.01226"
"39534","237.16800","19.76421","0.01229"
"39595","237.53400","19.79470","0.01219"
"39656","237.90000","19.82519","0.01281"
"39717","238.26600","19.85574","0.01266"
"39778","238.63200","19.88618","0.01242"
"39839","238.99800","19.91667","0.01251"
"39900","239.36400","19.94728","0.01291"
"39961","239.73000","19.97766","0.01305"
"40022","240.09600","20.00821","0.01267"
"40083","240.46200","20.03876","0.01266"
"40144","240.82800","20.06919","0.01332"
"40205","241.19400","20.09968","0.01328"
"40266","241.56000","20.13024","0.01291"
"40327","241.92600","20.16067","0.01285"
"40388","242.29200","20.19116","0.01320"
"40449","242.65800","20.22178","0.01321"
"40510","243.02400","20.25215","0.01316"
"40571","243.39000","20.28270","0.01289"
"40632","243.75600","20.31320","0.01298"
"40693","244.12200","20.34369","0.01343"
"40754","244.48800","20.37418","0.01309"
"40815","244.85400","20.40473","0.01310"
"40876","245.22000","20.43522","0.01339"
"40937","245.58600","20.46566","0.01341"
"40998","245.95200","20.49621","0.01390"
"41059","246.31800","20.52670","0.01391"
"41120","246.68400","20.55720","0.01393"
"41181","247.05000","20.58769","0.01359"
"41242","247.41600","20.61824","0.01399"
"41303","247.78200","20.64861","0.01371"
"41364","248.14800","20.67923","0.01384"
"41425","248.51400","20.70978","0.01410"
"41486","248.88000","20.74015","0.01360"
"41547","249.24600","20.77070","0.01391"
"41608","249.61200","20.80120","0.01407"
"41669","249.97800","20.83169","0.01391"
"41730","250.34400","20.86218","0.01424"
"41791","250.71000","20.89273","0.01474"
"41852","251.07600","20.92317","0.01429"
"41913","251.44200","20.95366","0.01462"
"41974","251.80800","20.98421","0.01447"
"42035","252.17400","21.01471","0.01458"
"42096","252.54000","21.04520","0.01492"
"42157","252.90600","21.07575","0.01474"
"42218","253.27200","21.10618","0.01468"
"42279","253.63800","21.13667","0.01481"
"42340","254.00400","21.16723","0.01481"
"42401","254.37000","21.19766","0.01493"
"42462","254.73600","21.22821","0.01503"
"42523","255.10200","21.25871","0.01504"
"42584","255.46800","21.28920","0.01511"
"42645","255.83400","21.31963","0.01499"
"42706","256.20000","21.35018","0.01514"
"42767","256.56600","21.38074","0.01550"
"42828","256.93200","21.41117","0.01572"
"42889","257.29800","21.44172","0.01552"
"42950","257.66400","21.47222","0.01559"
"43011","258.03000","21.50271","0.01588"
"43072","258.39600","21.53320","0.01609"
"43133","258.76200","21.56369","0.01548"
"43194","259.12800","21.59418","0.01581"
"43255","259.49400","21.62468","0.01587"
"43316","259.86000","21.65523","0.01605"
"43377","260.22600","21.68566","0.01623"
"43438","260.59200","21.71616","0.01605"
"43499","260.95800","21.74671","0.01610"
"43560","261.32400","21.77720","0.01650"
"43621","261.69000","21.80769","0.01658"
"43682","262.05600","21.83825","0.01642"
"43743","262.42200","21.86868","0.01667"
"43804","262.78800","21.89917","0.01693"
"43865","263.15400","21.92972","0.01709"
"43926","263.52000","21.96016","0.01712"
"43987","263.88600","21.99065","0.01699"
"44048","264.25200","22.02120","0.01725"
"44109","264.61800","22.05176","0.01699"
"44170","264.98400","22.08213","0.01709"
"44231","265.35000","22.11274","0.01703"
"44292","265.71600","22.14323","0.01753"
"44353","266.08200","22.17367","0.01748"
"44414","266.44800","22.20422","0.01789"
"44475","266.81400","22.23471","0.01796"
"44536","267.18000","22.26520","0.01766"
"44597","267.54600","22.29570","0.01745"
"44658","267.91200","22.32625","0.01761"
"44719","268.27800","22.35668","0.01837"
"44780","268.64400","22.38717","0.01805"
"44841","269.01000","22.41773","0.01792"
"44902","269.37600","22.44816","0.01820"
"44963","269.74200","22.47871","0.01820"
"45024","270.10800","22.50921","0.01826"
"45085","270.47400","22.53970","0.01836"
"45146","270.84000","22.57013","0.01874"
"45207","271.20600","22.60074","0.01826"
"45268","271.57200","22.63118","0.01868"
"45329","271.93800","22.66173","0.01890"
"45390","272.30400","22.69216","0.01887"
"45451","272.67000","22.72271","0.01961"
"45512","273.03600","22.75315","0.01924"
"45573","273.40200","22.78364","0.01954"
"45634","273.76800","22.81425","0.01930"
"45695","274.13400","22.84468","0.01985"
"45756","274.50000","22.87524","0.01967"
"45817","274.86600","22.90573","0.01956"
"45878","275.23200","22.93616","0.01979"
"45939","275.59800","22.96666","0.02019"
"46000","275.96400","22.99721","0.02025"
"46061","276.33000","23.02770","0.02094"
"46122","276.69600","23.05819","0.02081"
"46183","277.06200","23.08875","0.02118"
"46244","277.42800","23.11918","0.02129"
"46305","277.79400","23.14967","0.02130"
"46366","278.16000","23.18022","0.02163"
"46427","278.52600","23.21072","0.02174"
"46488","278.89200","23.24121","0.02197"
"46549","279.25800","23.27176","0.02223"
"46610","279.62400","23.30219","0.02235"
"46671","279.99000","23.33269","0.02289"
"46732","280.35600","23.36318","0.02280"
"46793","280.72200","23.39367","0.02355"
"46854","281.08800","23.42416","0.02313"
"46915","281.45400","23.45477","0.02378"
"46976","281.82000","23.48521","0.02406"
"47037","282.18600","23.51564","0.02387"
"47098","282.55200","23.54626","0.02422"
"47159","282.91800","23.57669","0.02494"
"47220","283.28400","23.60718","0.02510"
"47281","283.65000","23.63767","0.02524"
"47342","284.01600","23.66822","0.02550"
"47403","284.38200","23.69866","0.02583"
"47464","284.74800","23.72915","0.02610"
"47525","285.11400","23.75970","0.02655"
"47586","285.48000","23.79020","0.02541"
"47647","285.84600","23.82075","0.02567"
"47708","286.21200","23.85118","0.02661"
"47769","286.57800","23.88173","0.02660"
"47830","286.94400","23.91223","0.02713"
"47891","287.31000","23.94266","0.02709"
"47952","287.67600","23.97315","0.02778"
"48013","288.04200","24.00370","0.02790"
"48074","288.40800","24.03419","0.02873"
"48135","288.77400","24.06469","0.02888"
"48196","289.14000","24.09518","0.02918"
"48257","289.50600","24.12573","0.02942"
"48318","289.87200","24.15623","0.02990"
"48379","290.23800","24.18666","0.03014"
"48440","290.60400","24.21715","0.03018"
"48501","290.97000","24.24771","0.03146"
"48562","291.33600","24.27814","0.03212"
"48623","291.70200","24.30869","0.03195"
"48684","292.06800","24.33924","0.03251"
"48745","292.43400","24.36968","0.03286"
"48806","292.80000","24.40023","0.03350"
"48867","293.16600","24.43072","0.03361"
"48928","293.53200","24.46115","0.03389"
"48989","293.89800","24.49176","0.03508"
"49050","294.26400","24.52220","0.03535"
"49111","294.63000","24.55269","0.03566"
"49172","294.99600","24.58318","0.03646"
"49233","295.36200","24.61368","0.03738"
"49294","295.72800","24.64417","0.03795"
"49355","296.09400","24.67466","0.03877"
"49416","296.46000","24.70521","0.03908"
"49477","296.82600","24.73571","0.03982"
"49538","297.19200","24.76620","0.04097"
"49599","297.55800","24.79669","0.04150"
"49660","297.92400","24.82719","0.04232"
"49721","298.29000","24.85768","0.04252"
"49782","298.65600","24.88823","0.04290"
"49843","299.02200","24.91872","0.04464"
"49904","299.38800","24.94916","0.04482"
"49965","299.75400","24.97977","0.03977"
"50026","300.12000","25.01020","0.03993"
"50087","300.48600","25.04063","0.04169"
"50148","300.85200","25.07118","0.04185"
"50209","301.21800","25.10174","0.04173"
"50270","301.58400","25.13211","0.04251"
"50331","301.95000","25.16273","0.04334"
"50392","302.31600","25.19322","0.04230"
"50453","302.68200","25.22365","0.04165"
"50514","303.04800","25.25420","0.04180"
"50575","303.41400","25.28464","0.04221"
"50636","303.78000","25.31519","0.04308"
"50697","304.14600","25.34568","0.04331"
"50758","304.51200","25.37623","0.04163"
"50819","304.87800","25.40672","0.04114"
"50880","305.24400","25.43722","0.04142"
"50941","305.61000","25.46771","0.04364"
"51002","305.97600","25.49820","0.04446"
"51063","306.34200","25.52864","0.04485"
"51124","306.70800","25.55919","0.04608"
"51185","307.07400","25.58974","0.04713"
"51246","307.44000","25.62017","0.04792"
"51307","307.80600","25.65073","0.04877"
"51368","308.17200","25.68122","0.04923"
"51429","308.53800","25.71165","0.05058"
"51490","308.90400","25.74220","0.05123"
"51551","309.27000","25.77276","0.05197"
"51612","309.63600","25.80319","0.05307"
"51673","310.00200","25.83368","0.05377"
"51734","310.36800","25.86418","0.05464"
"51795","310.73400","25.89461","0.05543"
"51856","311.10000","25.92528","0.05581"
"51917","311.46600","25.95572","0.05701"
"51978","311.83200","25.98621","0.05771"
"52039","312.19800","26.01670","0.05851"
"52100","312.56400","26.04719","0.05938"
"52161","312.93000","26.07763","0.06001"
"52222","313.29600","26.10818","0.06102"
"52283","313.66200","26.13873","0.06154"
"52344","314.02800","26.16922","0.06225"
"52405","314.39400","26.19971","0.06301"
"52466","314.76000","26.23021","0.06442"
"52527","315.12600","26.26070","0.06509"
"52588","315.49200","26.29119","0.06655"
"52649","315.85800","26.32174","0.06719"
"52710","316.22400","26.35224","0.06831"
"52771","316.59000","26.38267","0.03981"
"52832","316.95600","26.41322","0.02884"
"52893","317.32200","26.44371","0.03171"
"52954","317.68800","26.47415","0.03744"
"53015","318.05400","26.50470","0.03374"
"53076","318.42000","26.53525","0.03054"
"53137","318.78600","26.56562","0.03413"
"53198","319.15200","26.59624","0.03745"
"53259","319.51800","26.62673","0.03644"
"53320","319.88400","26.65716","0.03523"
"53381","320.25000","26.68772","0.03712"
"53442","320.61600","26.71821","0.03858"
"53503","320.98200","26.74864","0.03783"
"53564","321.34800","26.77919","0.03844"
"53625","321.71400","26.80968","0.04034"
"53686","322.08000","26.84018","0.04177"
"53747","322.44600","26.87073","0.04182"
"53808","322.81200","26.90116","0.04212"
"53869","323.17800","26.93166","0.04419"
"53930","323.54400","26.96215","0.04544"
"53991","323.91000","26.99276","0.04582"
"54052","324.27600","27.02326","0.04522"
"54113","324.64200","27.05369","0.04691"
"54174","325.00800","27.08424","0.04767"
"54235","325.37400","27.11473","0.04785"
"54296","325.74000","27.14517","0.04828"
"54357","326.10600","27.17572","0.05011"
"54418","326.47200","27.20621","0.05019"
"54479","326.83800","27.23664","0.05094"
"54540","327.20400","27.26726","0.05242"
"54601","327.57000","27.29769","0.05254"
"54662","327.93600","27.32812","0.05253"
"54723","328.30200","27.35873","0.05394"
"54784","328.66800","27.38923","0.05451"
"54845","329.03400","27.41966","0.05572"
"54906","329.40000","27.45021","0.05601"
"54967","329.76600","27.48077","0.05729"
"55028","330.13200","27.51114","0.05751"
"55089","330.49800","27.54175","0.05831"
"55150","330.86400","27.57224","0.05860"
"55211","331.23000","27.60268","0.05875"
"55272","331.59600","27.63317","0.05904"
"55333","331.96200","27.66366","0.06035"
"55394","332.32800","27.69421","0.06169"
"55455","332.69400","27.72465","0.06171"
"55516","333.06000","27.75520","0.06290"
"55577","333.42600","27.78569","0.06413"
"55638","333.79200","27.81618","0.06447"
"55699","334.15800","27.84668","0.06443"
"55760","334.52400","27.87723","0.06566"
"55821","334.89000","27.90766","0.06679"
"55882","335.25600","27.93822","0.06773"
"55943","335.62200","27.96871","0.06850"
"56004","335.98800","27.99914","0.06993"
"56065","336.35400","28.02975","0.07086"
"56126","336.72000","28.06019","0.07140"
"56187","337.08600","28.09068","0.07191"
"56248","337.45200","28.12123","0.07394"
"56309","337.81800","28.15166","0.07578"
"56370","338.18400","28.18210","0.07752"
"56431","338.55000","28.21271","0.07877"
"56492","338.91600","28.24320","0.07972"
"56553","339.28200","28.27363","0.07845"
"56614","339.64800","28.30424","0.07651"
"56675","340.01400","28.33468","0.07800"
"56736","340.38000","28.36517","0.07929"
"56797","340.74600","28.39566","0.08064"
"56858","341.11200","28.42622","0.08251"
"56919","341.47800","28.45665","0.08422"
"56980","341.84400","28.48720","0.08668"
"57041","342.21000","28.51769","0.08848"
"57102","342.57600","28.54819","0.09077"
"57163","342.94200","28.57868","0.09184"
"57224","343.30800","28.60923","0.09260"
"57285","343.67400","28.63972","0.09530"
"57346","344.04000","28.67016","0.09637"
"57407","344.40600","28.70077","0.09757"
"57468","344.77200","28.73114","0.09848"
"57529","345.13800","28.76163","0.09966"
"57590","345.50400","28.79225","0.09978"
"57651","345.87000","28.82268","0.10044"
"57712","346.23600","28.85317","0.10125"
"57773","346.60200","28.88373","0.10229"
"57834","346.96800","28.91422","0.10292"
"57895","347.33400","28.94465","0.10394"
"57956","347.70000","28.97526","0.10474"
"58017","348.06600","29.00570","0.10542"
"58078","348.43200","29.03619","0.10643"
"58139","348.79800","29.06668","0.10660"
"58200","349.16400","29.09717","0.10754"
"58261","349.53000","29.12767","0.10826"
"58322","349.89600","29.15822","0.10887"
"58383","350.26200","29.18871","0.10993"
"58444","350.62800","29.21915","0.11083"
"58505","350.99400","29.24970","0.11229"
"58566","351.36000","29.28019","0.11414"
"58627","351.72600","29.31074","0.11576"
"58688","352.09200","29.34118","0.11706"
"58749","352.45800","29.37173","0.11996"
"58810","352.82400","29.40216","0.12125"
"58871","353.19000","29.43265","0.12383"
"58932","353.55600","29.46326","0.12626"
"58993","353.92200","29.49370","0.13020"
"59054","354.28800","29.52419","0.13241"
"59115","354.65400","29.55468","0.13520"
"59176","355.02000","29.58524","0.13875"
"59237","355.38600","29.61561","0.14280"
"59298","355.75200","29.64622","0.14573"
"59359","356.11800","29.67672","0.15027"
"59420","356.48400","29.70715","0.15230"
"59481","356.85000","29.73770","0.15540"
"59542","357.21600","29.76825","0.15838"
"59603","357.58200","29.79869","0.16089"
"59664","357.94800","29.82918","0.16341"
"59725","358.31400","29.85979","0.16577"
"59786","358.68000","29.89017","0.16670"
"59847","359.04600","29.92066","0.16755"
"59908","359.41200","29.95121","0.16916"
"59969","359.77800","29.98170","0.17020"
"60030","360.14400","30.01219","0.17206"
"60091","360.51000","30.04275","0.17411"
"60152","360.87600","30.07324","0.17555"
"60213","361.24200","30.10373","0.17728"
"60274","361.60800","30.13423","0.17956"
"60335","361.97400","30.16472","0.18186"
"60396","362.34000","30.19515","0.18429"
"60457","362.70600","30.22570","0.18644"
"60518","363.07200","30.25626","0.18919"
"60579","363.43800","30.28663","0.19142"
"60640","363.80400","30.31724","0.19370"
"60701","364.17000","30.34773","0.19632"
"60762","364.53600","30.37811","0.19875"
"60823","364.90200","30.40872","0.20082"
"60884","365.26800","30.43927","0.20318"
"60945","365.63400","30.46970","0.20482"
"61006","366.00000","30.50014","0.20710"
"61067","366.36600","30.53075","0.20873"
"61128","366.73200","30.56118","0.21012"
"61189","367.09800","30.59167","0.21125"
"61250","367.46400","30.62217","0.21276"
"61311","367.83000","30.65266","0.21429"
"61372","368.19600","30.68321","0.21491"
"61433","368.56200","30.71371","0.21634"
"61494","368.92800","30.74426","0.21815"
"61555","369.29400","30.77469","0.21949"
"61616","369.66000","30.80524","0.22151"
"61677","370.02600","30.83568","0.22364"
"61738","370.39200","30.86617","0.22556"
"61799","370.75800","30.89672","0.22748"
"61860","371.12400","30.92727","0.22876"
"61921","371.49000","30.95770","0.23162"
"61982","371.85600","30.98820","0.23371"
"62043","372.22200","31.01875","0.23551"
"62104","372.58800","31.04912","0.23883"
"62165","372.95400","31.07973","0.24160"
"62226","373.32000","31.11023","0.24341"
"62287","373.68600","31.14072","0.24598"
"62348","374.05200","31.17122","0.24960"
"62409","374.41800","31.20171","0.25097"
"62470","374.78400","31.23214","0.25307"
"62531","375.15000","31.26263","0.25530"
"62592","375.51600","31.29324","0.25688"
"62653","375.88200","31.32368","0.25192"
"62714","376.24800","31.35423","0.23050"
"62775","376.61400","31.38472","0.23226"
"62836","376.98000","31.41515","0.23433"
"62897","377.34600","31.44564","0.23604"
"62958","377.71200","31.47626","0.23756"
"63019","378.07800","31.50669","0.12166"
"63080","378.44400","31.53718","0.10783"
"63141","378.81000","31.56780","0.10663"
"63202","379.17600","31.59823","0.10988"
"63263","379.54200","31.62872","0.11253"
"63324","379.90800","31.65922","0.10884"
"63385","380.27400","31.68971","0.10871"
"63446","380.64000","31.72014","0.11209"
"63507","381.00600","31.75069","0.11443"
"63568","381.37200","31.78124","0.11096"
"63629","381.73800","31.81168","0.11068"
"63690","382.10400","31.84217","0.11470"
"63751","382.47000","31.87272","0.11642"
"63812","382.83600","31.90315","0.11305"
"63873","383.20200","31.93365","0.11296"
"63934","383.56800","31.96426","0.11659"
"63995","383.93400","31.99463","0.11886"
"64056","384.30000","32.02525","-0.00446"
"64117","384.66600","32.05568","0.00869"
"64178","385.03200","32.08617","0.00523"
"64239","385.39800","32.11666","0.00636"
"64300","385.76400","32.14722","0.01008"
"64361","386.13000","32.17771","0.00598"
"64422","386.49600","32.20820","0.00661"
"64483","386.86200","32.23875","0.00755"
"64544","387.22800","32.26913","0.00541"
"64605","387.59400","32.29974","0.00824"
"64666","387.96000","32.33023","0.00636"
"64727","388.32600","32.36073","0.00606"
"64788","388.69200","32.39116","0.00987"
"64849","389.05800","32.42177","0.00595"
"64910","389.42400","32.45220","0.00607"
"64971","389.79000","32.48270","0.00877"
"65032","390.15600","32.51319","0.00602"
"65093","390.52200","32.54368","0.00720"
"65154","390.88800","32.57423","0.00708"
"65215","391.25400","32.60467","0.00583"
"65276","391.62000","32.63522","0.00806"
"65337","391.98600","32.66559","0.00614"
"65398","392.35200","32.69621","0.00662"
"65459","392.71800","32.72670","0.00786"
"65520","393.08400","32.75713","0.00619"
"65581","393.45000","32.78774","0.00777"
"65642","393.81600","32.81824","0.00660"
"65703","394.18200","32.84867","0.00680"
"65764","394.54800","32.87916","0.00736"
"65825","394.91400","32.90971","0.00664"
"65886","395.28000","32.94015","0.00701"
"65947","395.64600","32.97070","0.00747"
"66008","396.01200","33.00125","0.00717"
"66069","396.37800","33.03168","0.00742"
"66130","396.74400","33.06218","0.00688"
"66191","397.11000","33.09273","0.00754"
"66252","397.47600","33.12316","0.00719"
"66313","397.84200","33.15365","0.00715"
"66374","398.20800","33.18421","0.00725"
"66435","398.57400","33.21470","0.00741"
"66496","398.94000","33.24519","0.00728"
"66557","399.30600","33.27568","0.00719"
"66618","399.67200","33.30618","0.00775"
"66679","400.03800","33.33667","0.00698"
"66740","400.40400","33.36716","0.00737"
"66801","400.77000","33.39777","0.00722"
"66862","401.13600","33.42815","0.00738"
"66923","401.50200","33.45876","0.00777"
"66984","401.86800","33.48919","0.00691"
"67045","402.23400","33.51968","0.00709"
"67106","402.60000","33.55018","0.00709"
"67167","402.96600","33.58067","0.00778"
"67228","403.33200","33.61116","0.00743"
"67289","403.69800","33.64172","0.00765"
"67350","404.06400","33.67221","0.00722"
"67411","404.43000","33.70264","0.00802"
"67472","404.79600","33.73319","0.00729"
"67533","405.16200","33.76375","0.00795"
"67594","405.52800","33.79418","0.00761"
"67655","405.89400","33.82467","0.00775"
"67716","406.26000","33.85522","0.00792"
"67777","406.62600","33.88566","0.00822"
"67838","406.99200","33.91615","0.00759"
"67899","407.35800","33.94670","0.00763"
"67960","407.72400","33.97720","0.00817"
"68021","408.09000","34.00769","0.00814"
"68082","408.45600","34.03818","0.00814"
"68143","408.82200","34.06873","0.00821"
"68204","409.18800","34.09917","0.00804"
"68265","409.55400","34.12972","0.00825"
"68326","409.92000","34.16021","0.00823"
"68387","410.28600","34.19064","0.00801"
"68448","410.65200","34.22120","0.00795"
"68509","411.01800","34.25175","0.00847"
"68570","411.38400","34.28218","0.00810"
"68631","411.75000","34.31267","0.00896"
"68692","412.11600","34.34323","0.00849"
"68753","412.48200","34.37360","0.00863"
"68814","412.84800","34.40421","0.00861"
"68875","413.21400","34.43471","0.00790"
"68936","413.58000","34.46520","0.00869"
"68997","413.94600","34.49569","0.00839"
"69058","414.31200","34.52625","0.00876"
"69119","414.67800","34.55674","0.00840"
"69180","415.04400","34.58723","0.00857"
"69241","415.41000","34.61772","0.00862"
"69302","415.77600","34.64816","0.00871"
"69363","416.14200","34.67870","0.00898"
"69424","416.50800","34.70920","0.00893"
"69485","416.87400","34.73975","0.00873"
"69546","417.24000","34.77018","0.00910"
"69607","417.60600","34.80062","0.00887"
"69668","417.97200","34.83123","0.00903"
"69729","418.33800","34.86166","0.00916"
"69790","418.70400","34.89222","0.00932"
"69851","419.07000","34.92271","0.00890"
"69912","419.43600","34.95320","0.00923"
"69973","419.80200","34.98369","0.00967"
"70034","420.16800","35.01424","0.00902"
"70095","420.53400","35.04462","0.00937"
"70156","420.90000","35.07517","0.00941"
"70217","421.26600","35.10572","0.00956"
"70278","421.63200","35.13622","0.00943"
"70339","421.99800","35.16671","0.00991"
"70400","422.36400","35.19720","0.00962"
"70461","422.73000","35.22770","0.01005"
"70522","423.09600","35.25813","0.00969"
"70583","423.46200","35.28874","0.00968"
"70644","423.82800","35.31923","0.00976"
"70705","424.19400","35.34966","0.00996"
"70766","424.56000","35.38022","0.01007"
"70827","424.92600","35.41065","0.01040"
"70888","425.29200","35.44114","0.00951"
"70949","425.65800","35.47169","0.00950"
"71010","426.02400","35.50225","0.01012"
"71071","426.39000","35.53268","0.00990"
"71132","426.75600","35.56323","0.00971"
"71193","427.12200","35.59373","0.01036"
"71254","427.48800","35.62416","0.01001"
"71315","427.85400","35.65465","0.00993"
"71376","428.22000","35.68526","0.00997"
"71437","428.58600","35.71564","0.00986"
"71498","428.95200","35.74619","0.01007"
"71559","429.31800","35.77674","0.01033"
"71620","429.68400","35.80711","0.01047"
"71681","430.05000","35.83773","0.01024"
"71742","430.41600","35.86816","0.01032"
"71803","430.78200","35.89871","0.01094"
"71864","431.14800","35.92920","0.01038"
"71925","431.51400","35.95970","0.01033"
"71986","431.88000","35.99019","0.01042"
"72047","432.24600","36.02068","0.01072"
"72108","432.61200","36.05124","0.01038"
"72169","432.97800","36.08167","0.01067"
"72230","433.34400","36.11222","0.01092"
"72291","433.71000","36.14272","0.01040"
"72352","434.07600","36.17321","0.01054"
"72413","434.44200","36.20370","0.01098"
"72474","434.80800","36.23425","0.01083"
"72535","435.17400","36.26474","0.01119"
"72596","435.54000","36.29517","0.01100"
"72657","435.90600","36.32567","0.01142"
"72718","436.27200","36.35622","0.01096"
"72779","436.63800","36.38665","0.01110"
"72840","437.00400","36.41721","0.01093"
"72901","437.37000","36.44776","0.01126"
"72962","437.73600","36.47819","0.01138"
"73023","438.10200","36.50874","0.01120"
"73084","438.46800","36.53924","0.01161"
"73145","438.83400","36.56967","0.01169"
"73206","439.20000","36.60016","0.01120"
"73267","439.56600","36.63071","0.01143"
"73328","439.93200","36.66121","0.01220"
"73389","440.29800","36.69170","0.01172"
"73450","440.66400","36.72226","0.01208"
"73511","441.03000","36.75269","0.01183"
"73572","441.39600","36.78318","0.01178"
"73633","441.76200","36.81373","0.01193"
"73694","442.12800","36.84422","0.01190"
"73755","442.49400","36.87466","0.01254"
"73816","442.86000","36.90527","0.01248"
"73877","443.22600","36.93570","0.01209"
"73938","443.59200","36.96613","0.01242"
"73999","443.95800","36.99675","0.01219"
"74060","444.32400","37.02718","0.01260"
"74121","444.69000","37.05767","0.01231"
"74182","445.05600","37.08823","0.01273"
"74243","445.42200","37.11878","0.01269"
"74304","445.78800","37.14909","0.01285"
"74365","446.15400","37.17976","0.01264"
"74426","446.52000","37.21025","0.01274"
"74487","446.88600","37.24063","0.01290"
"74548","447.25200","37.27124","0.01259"
"74609","447.61800","37.30173","0.01289"
"74670","447.98400","37.33216","0.01290"
"74731","448.35000","37.36266","0.01347"
"74792","448.71600","37.39327","0.01315"
"74843","449.02000","37.41850","0.01308"