File: Trajectories_together/161218Specimen_RawData_9.csv
"","V1","V2","V3"
"1","End date","12/18/2016",""
"2","Specimen label","16CT_29_run2",""
"3","Maximum Load","0.16028","N"
"4","Time","Extension","Load"
"5","(s)","(mm)","(N)"
"6","0.00000","10.26192","0.01566"
"39","0.19800","10.27471","0.01696"
"72","0.39600","10.29504","0.01853"
"105","0.59400","10.31154","0.02019"
"138","0.79200","10.32810","0.02145"
"171","0.99000","10.34461","0.02254"
"204","1.18800","10.36105","0.02356"
"237","1.38600","10.37755","0.02461"
"270","1.58400","10.39405","0.02511"
"303","1.78200","10.41055","0.02633"
"336","1.98000","10.42712","0.02714"
"369","2.17800","10.44350","0.02840"
"402","2.37600","10.46000","0.02860"
"435","2.57400","10.47656","0.02991"
"468","2.77200","10.49300","0.03069"
"501","2.97000","10.50957","0.03144"
"534","3.16800","10.52607","0.03218"
"567","3.36600","10.54257","0.03321"
"600","3.56400","10.55907","0.03391"
"633","3.76200","10.57551","0.03465"
"666","3.96000","10.59208","0.03617"
"699","4.15800","10.60857","0.03741"
"732","4.35600","10.62502","0.03818"
"765","4.55400","10.64158","0.03908"
"798","4.75200","10.65802","0.04036"
"831","4.95000","10.67446","0.04079"
"864","5.14800","10.69109","0.04164"
"897","5.34600","10.70753","0.04234"
"930","5.54400","10.72403","0.04345"
"963","5.74200","10.74053","0.04404"
"996","5.94000","10.75697","0.04462"
"1029","6.13800","10.77354","0.04537"
"1062","6.33600","10.79004","0.04586"
"1095","6.53400","10.80648","0.04701"
"1128","6.73200","10.82310","0.04783"
"1161","6.93000","10.83954","0.04821"
"1194","7.12800","10.85605","0.04923"
"1227","7.32600","10.87255","0.05007"
"1260","7.52400","10.88905","0.05058"
"1293","7.72200","10.90555","0.05092"
"1326","7.92000","10.92205","0.05230"
"1359","8.11800","10.93844","0.05237"
"1392","8.31600","10.95512","0.05367"
"1425","8.51400","10.97150","0.05372"
"1458","8.71200","10.98800","0.05384"
"1491","8.91000","11.00456","0.05344"
"1524","9.10800","11.02106","0.05326"
"1557","9.30600","11.03757","0.05377"
"1590","9.50400","11.05407","0.05416"
"1623","9.70200","11.07051","0.05443"
"1656","9.90000","11.08707","0.05062"
"1689","10.09800","11.10351","0.04968"
"1722","10.29600","11.12002","0.04956"
"1755","10.49400","11.13658","0.05049"
"1788","10.69200","11.15296","0.05062"
"1821","10.89000","11.16958","0.05077"
"1854","11.08800","11.18602","0.05111"
"1887","11.28600","11.20247","0.05113"
"1920","11.48400","11.21903","0.05208"
"1953","11.68200","11.23559","0.05313"
"1986","11.88000","11.25197","0.05370"
"2019","12.07800","11.26859","0.05387"
"2052","12.27600","11.28498","0.05458"
"2085","12.47400","11.30154","0.05610"
"2118","12.67200","11.31804","0.05542"
"2151","12.87000","11.33448","0.05700"
"2184","13.06800","11.35104","0.05748"
"2217","13.26600","11.36760","0.05736"
"2250","13.46400","11.38399","0.05851"
"2283","13.66200","11.40061","0.05901"
"2316","13.86000","11.41699","0.06094"
"2349","14.05800","11.43355","0.06092"
"2382","14.25600","11.45005","0.06232"
"2415","14.45400","11.46650","0.06309"
"2448","14.65200","11.48300","0.06452"
"2481","14.85000","11.49956","0.06564"
"2514","15.04800","11.51606","0.06660"
"2547","15.24600","11.53256","0.06753"
"2580","15.44400","11.54907","0.06824"
"2613","15.64200","11.56551","0.07027"
"2646","15.84000","11.58201","0.07069"
"2679","16.03800","11.59857","0.07193"
"2712","16.23600","11.61501","0.07258"
"2745","16.43400","11.63152","0.07367"
"2778","16.63200","11.64802","0.07417"
"2811","16.83000","11.66452","0.07535"
"2844","17.02800","11.68108","0.07608"
"2877","17.22600","11.69752","0.07680"
"2910","17.42400","11.71403","0.07715"
"2943","17.62200","11.73053","0.07779"
"2976","17.82000","11.74697","0.07904"
"3009","18.01800","11.76353","0.07901"
"3042","18.21600","11.78009","0.07964"
"3075","18.41400","11.79648","0.08023"
"3108","18.61200","11.81304","0.08063"
"3141","18.81000","11.82954","0.08141"
"3174","19.00800","11.84604","0.08213"
"3207","19.20600","11.86254","0.08251"
"3240","19.40400","11.87898","0.08343"
"3273","19.60200","11.89555","0.08353"
"3306","19.80000","11.91205","0.08431"
"3339","19.99800","11.92849","0.08522"
"3372","20.19600","11.94505","0.08561"
"3405","20.39400","11.96155","0.08622"
"3438","20.59200","11.97806","0.08714"
"3471","20.79000","11.99456","0.08769"
"3504","20.98800","12.01100","0.08793"
"3537","21.18600","12.02756","0.08879"
"3570","21.38400","12.04406","0.08911"
"3603","21.58200","12.06045","0.09004"
"3636","21.78000","12.07713","0.09075"
"3669","21.97800","12.09351","0.09088"
"3702","22.17600","12.11001","0.07639"
"3735","22.37400","12.12657","0.07765"
"3768","22.57200","12.14302","0.07883"
"3801","22.77000","12.15952","0.07978"
"3834","22.96800","12.17608","0.07959"
"3867","23.16600","12.19246","0.08036"
"3900","23.36400","12.20902","0.08101"
"3933","23.56200","12.22558","0.08236"
"3966","23.76000","12.24197","0.08324"
"3999","23.95800","12.25859","0.08435"
"4032","24.15600","12.27503","0.08445"
"4065","24.35400","12.29153","0.08532"
"4098","24.55200","12.30803","0.08707"
"4131","24.75000","12.32454","0.08816"
"4164","24.94800","12.34104","0.08806"
"4197","25.14600","12.35754","0.08872"
"4230","25.34400","12.37398","0.08978"
"4263","25.54200","12.39054","0.09043"
"4296","25.74000","12.40699","0.09196"
"4329","25.93800","12.42349","0.09331"
"4362","26.13600","12.44005","0.09355"
"4395","26.33400","12.45649","0.09423"
"4428","26.53200","12.47305","0.09501"
"4461","26.73000","12.48956","0.09619"
"4494","26.92800","12.50600","0.09732"
"4527","27.12600","12.52262","0.09812"
"4560","27.32400","12.53906","0.09881"
"4593","27.52200","12.55556","0.10006"
"4626","27.72000","12.57206","0.10109"
"4659","27.91800","12.58851","0.10198"
"4692","28.11600","12.60501","0.10376"
"4725","28.31400","12.62157","0.10432"
"4758","28.51200","12.63801","0.10521"
"4791","28.71000","12.65451","0.10577"
"4824","28.90800","12.67108","0.10775"
"4857","29.10600","12.68752","0.10866"
"4890","29.30400","12.70408","0.10901"
"4923","29.50200","12.72052","0.10963"
"4956","29.70000","12.73702","0.11079"
"4989","29.89800","12.75353","0.11180"
"5022","30.09600","12.77003","0.11384"
"5055","30.29400","12.78659","0.11553"
"5088","30.49200","12.80303","0.11639"
"5121","30.69000","12.81953","0.11866"
"5154","30.88800","12.83609","0.11987"
"5187","31.08600","12.85254","0.12092"
"5220","31.28400","12.86904","0.12200"
"5253","31.48200","12.88554","0.12348"
"5286","31.68000","12.90204","0.12440"
"5319","31.87800","12.91849","0.12520"
"5352","32.07600","12.93511","0.12630"
"5385","32.27400","12.95149","0.12795"
"5418","32.47200","12.96805","0.12873"
"5451","32.67000","12.98455","0.12997"
"5484","32.86800","13.00099","0.13103"
"5517","33.06600","13.01756","0.13211"
"5550","33.26400","13.03406","0.13307"
"5583","33.46200","13.05050","0.13403"
"5616","33.66000","13.06700","0.13472"
"5649","33.85800","13.08350","0.13512"
"5682","34.05600","13.10001","0.13637"
"5715","34.25400","13.11651","0.13736"
"5748","34.45200","13.13301","0.13820"
"5781","34.65000","13.14957","0.13837"
"5814","34.84800","13.16607","0.13937"
"5847","35.04600","13.18252","0.14026"
"5880","35.24400","13.19902","0.14220"
"5913","35.44200","13.21558","0.14297"
"5946","35.64000","13.23202","0.14355"
"5979","35.83800","13.24852","0.14466"
"6012","36.03600","13.26497","0.14622"
"6045","36.23400","13.28153","0.14636"
"6078","36.43200","13.29803","0.14723"
"6111","36.63000","13.31453","0.14778"
"6144","36.82800","13.33103","0.14819"
"6177","37.02600","13.34759","0.14885"
"6210","37.22400","13.36398","0.14989"
"6243","37.42200","13.38054","0.15070"
"6276","37.62000","13.39698","0.15139"
"6309","37.81800","13.41354","0.15260"
"6342","38.01600","13.43004","0.15362"
"6375","38.21400","13.44649","0.15438"
"6408","38.41200","13.46305","0.15531"
"6441","38.61000","13.47961","0.15650"
"6474","38.80800","13.49593","0.15759"
"6507","39.00600","13.51255","0.15893"
"6540","39.20400","13.52906","0.15890"
"6573","39.40200","13.54550","0.16025"
"6606","39.60000","13.56206","0.01300"
"6639","39.79800","13.57856","0.00238"
"6672","39.99600","13.59501","0.00193"
"6705","40.19400","13.61157","0.00364"
"6738","40.39200","13.62801","0.00713"
"6771","40.59000","13.64457","0.00278"
"6804","40.78800","13.66107","0.00650"
"6837","40.98600","13.67745","0.00287"
"6870","41.18400","13.69402","0.00748"
"6903","41.38200","13.71052","0.00495"
"6936","41.58000","13.72702","0.00412"
"6969","41.77800","13.74358","0.00368"
"7002","41.97600","13.75996","0.00342"
"7035","42.17400","13.77658","0.00459"
"7068","42.37200","13.79303","0.00398"
"7101","42.57000","13.80947","0.00484"
"7134","42.76800","13.82609","0.00573"
"7167","42.96600","13.84253","0.00750"
"7200","43.16400","13.85903","0.00711"
"7233","43.36200","13.87554","0.00630"
"7266","43.56000","13.89204","0.00703"
"7299","43.75800","13.90860","0.00701"
"7332","43.95600","13.92504","0.00623"
"7365","44.15400","13.94155","0.00720"
"7398","44.35200","13.95811","0.00747"
"7431","44.55000","13.97449","0.00916"
"7464","44.74800","13.99105","0.00955"
"7497","44.94600","14.00755","0.00968"
"7530","45.14400","14.02399","0.01028"
"7563","45.34200","14.04050","0.00898"
"7596","45.54000","14.05706","0.00955"
"7629","45.73800","14.07350","0.00984"
"7662","45.93600","14.09006","0.01049"
"7695","46.13400","14.10656","0.01302"
"7728","46.33200","14.12300","0.01302"
"7761","46.53000","14.13951","0.01439"
"7794","46.72800","14.15601","0.01428"
"7827","46.92600","14.17257","0.01378"
"7860","47.12400","14.18907","0.01460"
"7893","47.32200","14.20551","0.01360"
"7926","47.52000","14.22208","0.01474"
"7959","47.71800","14.23858","0.01690"
"7992","47.91600","14.25502","0.01692"
"8025","48.11400","14.27158","0.01857"
"8058","48.31200","14.28802","0.01914"
"8091","48.51000","14.30453","0.01748"
"8124","48.70800","14.32103","0.01937"
"8157","48.90600","14.33753","0.01769"
"8190","49.10400","14.35397","0.01956"
"8223","49.30200","14.37053","0.02114"
"8256","49.50000","14.38698","0.02032"
"8289","49.69800","14.40360","0.02348"
"8322","49.89600","14.42004","0.02285"
"8355","50.09400","14.43654","0.02366"
"8388","50.29200","14.45304","0.02382"
"8421","50.49000","14.46960","0.02321"
"8454","50.68800","14.48599","0.02541"
"8487","50.88600","14.50255","0.02474"
"8520","51.08400","14.51899","0.02640"
"8553","51.28200","14.53555","0.02727"
"8586","51.48000","14.55206","0.02768"
"8619","51.67800","14.56850","0.02861"
"8652","51.87600","14.58500","0.02764"
"8685","52.07400","14.60156","0.02852"
"8718","52.27200","14.61800","0.02936"
"8751","52.47000","14.63457","0.02953"
"8784","52.66800","14.65107","0.03151"
"8817","52.86600","14.66757","0.03152"
"8850","53.06400","14.68407","0.03272"
"8883","53.26200","14.70051","0.03260"
"8916","53.46000","14.71702","0.03226"
"8949","53.65800","14.73352","0.03394"
"8982","53.85600","14.74996","0.03325"
"9015","54.05400","14.76652","0.03498"
"9048","54.25200","14.78302","0.03531"
"9081","54.45000","14.79953","0.03573"
"9114","54.64800","14.81609","0.03789"
"9147","54.84600","14.83247","0.03727"
"9180","55.04400","14.84909","0.03793"
"9213","55.24200","14.86553","0.03791"
"9246","55.44000","14.88197","0.03918"
"9279","55.63800","14.89853","0.04066"
"9312","55.83600","14.91504","0.04021"
"9345","56.03400","14.93148","0.04173"
"9378","56.23200","14.94810","0.04209"
"9411","56.43000","14.96454","0.04229"
"9444","56.62800","14.98098","0.04302"
"9477","56.82600","14.99755","0.04313"
"9510","57.02400","15.01405","0.04457"
"9543","57.22200","15.03055","0.04393"
"9576","57.42000","15.04705","0.04583"
"9609","57.61800","15.06350","0.04580"
"9642","57.81600","15.08006","0.04627"
"9675","58.01400","15.09656","0.04758"
"9708","58.21200","15.11300","0.04683"
"9741","58.41000","15.12962","0.04820"
"9774","58.60800","15.14600","0.04798"
"9807","58.80600","15.16257","0.04905"
"9840","59.00400","15.17907","0.03156"
"9873","59.20200","15.19545","0.03319"
"9906","59.40000","15.21201","0.03413"
"9939","59.59800","15.22851","0.03510"
"9972","59.79600","15.24496","0.03627"
"10005","59.99400","15.26158","0.03565"
"10038","60.19200","15.27802","0.03722"
"10071","60.39000","15.29452","0.03788"
"10104","60.58800","15.31108","0.03834"
"10137","60.78600","15.32753","0.03949"
"10170","60.98400","15.34403","0.04005"
"10203","61.18200","15.36059","0.04087"
"10236","61.38000","15.37697","0.04150"
"10269","61.57800","15.39359","0.04164"
"10302","61.77600","15.40998","0.04217"
"10335","61.97400","15.42654","0.03118"
"10368","62.17200","15.44304","0.00289"
"10401","62.37000","15.45948","0.00471"
"10434","62.56800","15.47604","0.00507"
"10467","62.76600","15.49255","0.00535"
"10500","62.96400","15.50905","0.00566"
"10533","63.16200","15.52561","0.00649"
"10566","63.36000","15.54205","0.00713"
"10599","63.55800","15.55855","0.00719"
"10632","63.75600","15.57506","0.00781"
"10665","63.95400","15.59150","0.00757"
"10698","64.15200","15.60806","0.00810"
"10731","64.35000","15.62456","0.00885"
"10764","64.54800","15.64100","0.00846"
"10797","64.74600","15.65750","0.00978"
"10830","64.94400","15.67406","0.01030"
"10863","65.14200","15.69051","0.00999"
"10896","65.34000","15.70713","0.01095"
"10929","65.53800","15.72351","0.01072"
"10962","65.73600","15.74001","0.01131"
"10995","65.93400","15.75651","0.01273"
"11028","66.13200","15.77302","0.01219"
"11061","66.33000","15.78946","0.01239"
"11094","66.52800","15.80608","0.01422"
"11127","66.72600","15.82252","0.01369"
"11160","66.92400","15.83902","0.01516"
"11193","67.12200","15.85559","0.01553"
"11226","67.32000","15.87203","0.01573"
"11259","67.51800","15.88853","0.01675"
"11292","67.71600","15.90509","0.01706"
"11325","67.91400","15.92153","0.01801"
"11358","68.11200","15.93804","0.01787"
"11391","68.31000","15.95448","0.01856"
"11424","68.50800","15.97104","0.02007"
"11457","68.70600","15.98754","0.02004"
"11490","68.90400","16.00398","0.02005"
"11523","69.10200","16.02055","0.02131"
"11556","69.30000","16.03705","0.02158"
"11589","69.49800","16.05349","0.02317"
"11622","69.69600","16.07005","0.02277"
"11655","69.89400","16.08649","0.02339"
"11688","70.09200","16.10299","0.02384"
"11721","70.29000","16.11956","0.02400"
"11754","70.48800","16.13600","0.02488"
"11787","70.68600","16.15250","0.02463"
"11820","70.88400","16.16906","0.02512"
"11853","71.08200","16.18550","0.02554"
"11886","71.28000","16.20207","0.02595"
"11919","71.47800","16.21857","0.02722"
"11952","71.67600","16.23501","0.02702"
"11985","71.87400","16.25157","0.02745"
"12018","72.07200","16.26801","0.02814"
"12051","72.27000","16.28452","0.02824"
"12084","72.46800","16.30102","0.02885"
"12117","72.66600","16.31746","0.02946"
"12150","72.86400","16.33408","0.02972"
"12183","73.06200","16.35058","0.03079"
"12216","73.26000","16.36697","0.03064"
"12249","73.45800","16.38359","0.03098"
"12282","73.65600","16.40003","0.00881"
"12315","73.85400","16.41653","0.00902"
"12348","74.05200","16.43303","0.01003"
"12381","74.25000","16.44954","0.01049"
"12414","74.44800","16.46604","0.01120"
"12447","74.64600","16.48254","0.01152"
"12480","74.84400","16.49898","0.01125"
"12513","75.04200","16.51560","0.01206"
"12546","75.24000","16.53198","0.01319"
"12579","75.43800","16.54849","0.01284"
"12612","75.63600","16.56505","0.01429"
"12645","75.83400","16.58155","0.01429"
"12678","76.03200","16.59799","0.01471"
"12711","76.23000","16.61456","0.01565"
"12744","76.42800","16.63100","0.01496"
"12777","76.62600","16.64756","0.01626"
"12810","76.82400","16.66400","0.01711"
"12843","77.02200","16.68044","0.01693"
"12876","77.22000","16.69706","0.01764"
"12909","77.41800","16.71350","0.01828"
"12942","77.61600","16.73001","0.01926"
"12975","77.81400","16.74657","0.01960"
"13008","78.01200","16.76301","0.02030"
"13041","78.21000","16.77957","0.02112"
"13074","78.40800","16.79607","0.02175"
"13107","78.60600","16.81252","0.02167"
"13140","78.80400","16.82908","0.02252"
"13173","79.00200","16.84552","0.02292"
"13206","79.20000","16.86202","0.02363"
"13239","79.39800","16.87852","0.02401"
"13272","79.59600","16.89497","0.02308"
"13305","79.79400","16.91153","0.02418"
"13338","79.99200","16.92809","0.02406"
"13371","80.19000","16.94447","0.02484"
"13404","80.38800","16.96109","0.02554"
"13437","80.58600","16.97754","0.02584"
"13470","80.78400","16.99404","0.02689"
"13503","80.98200","17.01054","0.02632"
"13536","81.18000","17.02698","0.02739"
"13569","81.37800","17.04348","0.02812"
"13602","81.57600","17.06005","0.02815"
"13635","81.77400","17.07649","0.02902"
"13668","81.97200","17.09305","0.02873"
"13701","82.17000","17.10955","0.02965"
"13734","82.36800","17.12599","0.03042"
"13767","82.56600","17.14256","0.03045"
"13800","82.76400","17.15906","0.03092"
"13833","82.96200","17.17550","0.03158"
"13866","83.16000","17.19206","0.03245"
"13899","83.35800","17.20856","0.03319"
"13932","83.55600","17.22500","0.03310"
"13965","83.75400","17.24157","0.03407"
"13998","83.95200","17.25801","0.03457"
"14031","84.15000","17.27457","0.03521"
"14064","84.34800","17.29107","0.03532"
"14097","84.54600","17.30751","0.03616"
"14130","84.74400","17.32402","0.03715"
"14163","84.94200","17.34052","0.03702"
"14196","85.14000","17.35696","0.03752"
"14229","85.33800","17.37352","0.03813"
"14262","85.53600","17.38997","0.03925"
"14295","85.73400","17.40653","0.03975"
"14328","85.93200","17.42303","0.04006"
"14361","86.13000","17.43953","0.04050"
"14394","86.32800","17.45603","0.04148"
"14427","86.52600","17.47260","0.04220"
"14460","86.72400","17.48898","0.04280"
"14493","86.92200","17.50560","0.04268"
"14526","87.12000","17.52204","0.04364"
"14559","87.31800","17.53848","0.04452"
"14592","87.51600","17.55504","0.04509"
"14625","87.71400","17.57149","0.04598"
"14658","87.91200","17.58805","0.04602"
"14691","88.11000","17.60455","0.04702"
"14724","88.30800","17.62099","0.04762"
"14757","88.50600","17.63761","0.04785"
"14790","88.70400","17.65406","0.04890"
"14823","88.90200","17.67056","0.04984"
"14856","89.10000","17.68706","0.05009"
"14889","89.29800","17.70350","0.05139"
"14922","89.49600","17.72006","0.05258"
"14955","89.69400","17.73656","0.05262"
"14988","89.89200","17.75295","0.05335"
"15021","90.09000","17.76957","0.05365"
"15054","90.28800","17.78601","0.05454"
"15087","90.48600","17.80245","0.05537"
"15120","90.68400","17.81913","0.05562"
"15153","90.88200","17.83552","0.05635"
"15186","91.08000","17.85202","0.05648"
"15219","91.27800","17.86858","0.05736"
"15252","91.47600","17.88502","0.05784"
"15285","91.67400","17.90158","0.05905"
"15318","91.87200","17.91803","0.05983"
"15351","92.07000","17.93447","0.06012"
"15384","92.26800","17.95103","0.06110"
"15417","92.46600","17.96747","0.06067"
"15450","92.66400","17.98403","0.06171"
"15483","92.86200","18.00054","0.06258"
"15516","93.06000","18.01704","0.06330"
"15549","93.25800","18.03354","0.06442"
"15582","93.45600","18.05010","0.06551"
"15615","93.65400","18.06648","0.06703"
"15648","93.85200","18.08311","0.06794"
"15681","94.05000","18.09955","0.06918"
"15714","94.24800","18.11599","0.06963"
"15747","94.44600","18.13255","0.07155"
"15780","94.64400","18.14905","0.07218"
"15813","94.84200","18.16555","0.07313"
"15846","95.04000","18.18206","0.07405"
"15879","95.23800","18.19856","0.07445"
"15912","95.43600","18.21500","0.07577"
"15945","95.63400","18.23150","0.07604"
"15978","95.83200","18.24800","0.07683"
"16011","96.03000","18.26457","0.07790"
"16044","96.22800","18.28095","0.07796"
"16077","96.42600","18.29751","0.07853"
"16110","96.62400","18.31407","0.07923"
"16143","96.82200","18.33051","0.07938"
"16176","97.02000","18.34702","0.08030"
"16209","97.21800","18.36358","0.08107"
"16242","97.41600","18.37996","0.08121"
"16275","97.61400","18.39658","0.08196"
"16308","97.81200","18.41302","0.08288"
"16341","98.01000","18.42953","0.08307"
"16374","98.20800","18.44603","0.08363"
"16407","98.40600","18.46253","0.08378"
"16440","98.60400","18.47903","0.00536"
"16473","98.80200","18.49553","0.00418"
"16506","99.00000","18.51204","0.01143"
"16539","99.19800","18.52854","0.02136"
"16572","99.39600","18.54504","0.00493"
"16605","99.59400","18.56148","0.00800"
"16638","99.79200","18.57804","0.01876"
"16671","99.99000","18.59454","0.00473"
"16704","100.18800","18.61105","0.00674"
"16737","100.38600","18.62755","0.01510"
"16770","100.58400","18.64399","0.00685"
"16803","100.78200","18.66055","0.00679"
"16836","100.98000","18.67705","0.01717"
"16869","101.17800","18.69350","0.00961"
"16902","101.37600","18.71006","0.00848"
"16935","101.57400","18.72656","0.01659"
"16968","101.77200","18.74300","0.01225"
"17001","101.97000","18.75956","0.01007"
"17034","102.16800","18.77607","0.01808"
"17067","102.36600","18.79251","0.01419"
"17100","102.56400","18.80907","0.01189"
"17133","102.76200","18.82545","0.01901"
"17166","102.96000","18.84201","0.01517"
"17199","103.15800","18.85858","0.01514"
"17232","103.35600","18.87502","0.01945"
"17265","103.55400","18.89158","0.01682"
"17298","103.75200","18.90808","0.01692"
"17331","103.95000","18.92446","0.02165"
"17364","104.14800","18.94102","0.00369"
"17397","104.34600","18.95753","-0.00045"
"17430","104.54400","18.97409","-0.00015"
"17463","104.74200","18.99053","-0.00073"
"17496","104.94000","19.00697","-0.00073"
"17529","105.13800","19.02353","0.00068"
"17562","105.33600","19.04004","-0.00048"
"17595","105.53400","19.05648","-0.00043"
"17628","105.73200","19.07304","0.00093"
"17661","105.93000","19.08954","-0.00102"
"17694","106.12800","19.10604","-0.00012"
"17727","106.32600","19.12261","0.00047"
"17760","106.52400","19.13899","-0.00066"
"17793","106.72200","19.15555","-0.00023"
"17826","106.92000","19.17205","0.00061"
"17859","107.11800","19.18849","-0.00044"
"17892","107.31600","19.20512","-0.00068"
"17925","107.51400","19.22156","0.00054"
"17958","107.71200","19.23800","-0.00021"
"17991","107.91000","19.25456","0.00001"
"18024","108.10800","19.27100","0.00029"
"18057","108.30600","19.28757","-0.00012"
"18090","108.50400","19.30407","-0.00036"
"18123","108.70200","19.32051","0.00012"
"18156","108.90000","19.33707","0.00007"
"18189","109.09800","19.35351","-0.00011"
"18222","109.29600","19.36996","0.00036"
"18255","109.49400","19.38658","-0.00028"
"18288","109.69200","19.40302","-0.00003"
"18321","109.89000","19.41952","0.00023"
"18354","110.08800","19.43602","0.00048"
"18387","110.28600","19.45253","0.00025"
"18420","110.48400","19.46903","0.00023"
"18453","110.68200","19.48553","-0.00033"
"18486","110.88000","19.50197","0.00005"
"18519","111.07800","19.51853","0.00050"
"18552","111.27600","19.53498","0.00038"
"18585","111.47400","19.55154","0.00064"
"18618","111.67200","19.56804","0.00073"
"18651","111.87000","19.58454","0.00003"
"18684","112.06800","19.60104","0.00076"
"18717","112.26600","19.61754","0.00045"
"18750","112.46400","19.63399","0.00030"
"18783","112.66200","19.65055","0.00070"
"18816","112.86000","19.66705","0.00035"
"18849","113.05800","19.68349","-0.00010"
"18882","113.25600","19.70005","0.00081"
"18915","113.45400","19.71649","0.00052"
"18948","113.65200","19.73306","0.00077"
"18981","113.85000","19.74956","0.00130"
"19014","114.04800","19.76606","0.00028"
"19047","114.24600","19.78256","0.00023"
"19080","114.44400","19.79906","0.00053"
"19113","114.64200","19.81551","0.00083"
"19146","114.84000","19.83207","0.00078"
"19179","115.03800","19.84851","0.00084"
"19212","115.23600","19.86501","0.00021"
"19245","115.43400","19.88151","0.00064"
"19278","115.63200","19.89802","0.00103"
"19311","115.83000","19.91452","0.00085"
"19344","116.02800","19.93102","0.00126"
"19377","116.22600","19.94752","0.00065"
"19410","116.42400","19.96408","0.00016"
"19443","116.62200","19.98059","0.00096"
"19476","116.82000","19.99697","0.00094"
"19509","117.01800","20.01353","0.00116"
"19542","117.21600","20.03009","0.00125"
"19575","117.41400","20.04653","0.00091"
"19608","117.61200","20.06304","0.00073"
"19641","117.81000","20.07948","0.00066"
"19674","118.00800","20.09604","0.00130"
"19707","118.20600","20.11254","0.00125"
"19740","118.40400","20.12904","0.00094"
"19773","118.60200","20.14554","0.00063"
"19806","118.80000","20.16211","0.00098"
"19839","118.99800","20.17849","0.00146"
"19872","119.19600","20.19505","0.00137"
"19905","119.39400","20.21155","0.00120"
"19938","119.59200","20.22799","0.00084"
"19971","119.79000","20.24456","0.00080"
"20004","119.98800","20.26094","0.00112"
"20037","120.18600","20.27756","0.00113"
"20070","120.38400","20.29406","0.00100"
"20103","120.58200","20.31050","0.00113"
"20136","120.78000","20.32707","0.00085"
"20169","120.97800","20.34351","0.00104"
"20202","121.17600","20.36001","0.00166"
"20235","121.37400","20.37657","0.00135"
"20268","121.57200","20.39301","0.00150"
"20301","121.77000","20.40952","0.00096"
"20334","121.96800","20.42602","0.00151"
"20367","122.16600","20.44246","0.00158"
"20400","122.36400","20.45908","0.00186"
"20433","122.56200","20.47552","0.00181"
"20466","122.76000","20.49196","0.00160"
"20499","122.95800","20.50859","0.00120"
"20532","123.15600","20.52497","0.00158"
"20565","123.35400","20.54153","0.00255"
"20598","123.55200","20.55803","0.00174"
"20631","123.75000","20.57447","0.00149"
"20664","123.94800","20.59110","0.00122"
"20697","124.14600","20.60754","0.00174"
"20730","124.34400","20.62392","0.00220"
"20763","124.54200","20.64060","0.00258"
"20796","124.74000","20.65704","0.00160"
"20829","124.93800","20.67349","0.00156"
"20862","125.13600","20.69005","0.00197"
"20895","125.33400","20.70655","0.00277"
"20928","125.53200","20.72305","0.00284"
"20961","125.73000","20.73956","0.00195"
"20994","125.92800","20.75600","0.00203"
"21027","126.12600","20.77256","0.00278"
"21060","126.32400","20.78900","0.00314"
"21093","126.52200","20.80550","0.00227"
"21126","126.72000","20.82206","0.00189"
"21159","126.91800","20.83851","0.00271"
"21192","127.11600","20.85507","0.00324"
"21225","127.31400","20.87157","0.00352"
"21258","127.51200","20.88801","0.00282"
"21291","127.71000","20.90457","0.00224"
"21324","127.90800","20.92102","0.00380"
"21357","128.10600","20.93746","0.00421"
"21390","128.30400","20.95402","0.00365"
"21423","128.50200","20.97052","0.00321"
"21456","128.70000","20.98702","0.00365"
"21489","128.89800","21.00359","0.00480"
"21522","129.09600","21.02003","0.00427"
"21555","129.29400","21.03653","0.00391"
"21588","129.49200","21.05309","0.00412"
"21621","129.69000","21.06953","0.00549"
"21654","129.88800","21.08610","0.00541"
"21687","130.08600","21.10248","0.00520"
"21720","130.28400","21.11904","0.00516"
"21753","130.48200","21.13554","0.00600"
"21786","130.68000","21.15198","0.00664"
"21819","130.87800","21.16849","0.00622"
"21852","131.07600","21.18505","0.00650"
"21885","131.27400","21.20155","0.00697"
"21918","131.47200","21.21805","0.00751"
"21951","131.67000","21.23455","0.00773"
"21984","131.86800","21.25105","0.00736"
"22017","132.06600","21.26755","0.00817"
"22050","132.26400","21.28406","0.00789"
"22083","132.46200","21.30050","0.00810"
"22116","132.66000","21.31700","0.00833"
"22149","132.85800","21.33350","0.00832"
"22182","133.05600","21.35000","0.00897"
"22215","133.25400","21.36657","0.00858"
"22248","133.45200","21.38295","0.00868"
"22281","133.65000","21.39957","0.00903"
"22314","133.84800","21.41607","0.01025"
"22347","134.04600","21.43245","0.00977"
"22380","134.24400","21.44901","0.01011"
"22413","134.44200","21.46552","0.01011"
"22446","134.64000","21.48202","0.01091"
"22479","134.83800","21.49852","0.01038"
"22512","135.03600","21.51497","0.01007"
"22545","135.23400","21.53153","0.01112"
"22578","135.43200","21.54809","0.01091"
"22611","135.63000","21.56447","0.01128"
"22644","135.82800","21.58103","0.01137"
"22677","136.02600","21.59759","0.01151"
"22710","136.22400","21.61398","0.01198"
"22743","136.42200","21.63054","0.01188"
"22776","136.62000","21.64704","0.01206"
"22809","136.81800","21.66354","0.01290"
"22842","137.01600","21.68004","0.01353"
"22875","137.21400","21.69648","0.01353"
"22908","137.41200","21.71305","0.01376"
"22941","137.61000","21.72955","0.01408"
"22974","137.80800","21.74599","0.01453"
"23007","138.00600","21.76255","0.01457"
"23040","138.20400","21.77905","0.01474"
"23073","138.40200","21.79550","0.01546"
"23106","138.60000","21.81200","0.01612"
"23139","138.79800","21.82850","0.01557"
"23172","138.99600","21.84500","0.01632"
"23205","139.19400","21.86151","0.01594"
"23238","139.39200","21.87801","0.01684"
"23271","139.59000","21.89457","0.01719"
"23304","139.78800","21.91101","0.01698"
"23337","139.98600","21.92751","0.01745"
"23370","140.18400","21.94407","0.01746"
"23403","140.38200","21.96046","0.00427"
"23436","140.58000","21.97702","0.00678"
"23469","140.77800","21.99352","0.00378"
"23502","140.97600","22.01002","0.00357"
"23535","141.17400","22.02652","0.00378"
"23568","141.37200","22.04303","0.00302"
"23601","141.57000","22.05947","0.00238"
"23634","141.76800","22.07609","0.00282"
"23667","141.96600","22.09253","0.00328"
"23700","142.16400","22.10897","0.00251"
"23733","142.36200","22.12560","0.00259"
"23766","142.56000","22.14198","0.00221"
"23799","142.75800","22.15854","0.00310"
"23832","142.95600","22.17504","0.00284"
"23865","143.15400","22.19148","0.00312"
"23898","143.35200","22.20805","0.00312"
"23931","143.55000","22.22449","0.00332"
"23964","143.74800","22.24099","0.00312"
"23997","143.94600","22.25755","0.00312"
"24030","144.14400","22.27399","0.00292"
"24063","144.34200","22.29049","0.00321"
"24096","144.54000","22.30706","0.00316"
"24129","144.73800","22.32350","0.00307"
"24162","144.93600","22.34006","0.00355"
"24195","145.13400","22.35656","0.00320"
"24228","145.33200","22.37300","0.00332"
"24261","145.53000","22.38951","0.00325"
"24294","145.72800","22.40601","0.00321"
"24327","145.92600","22.42251","0.00324"
"24360","146.12400","22.43907","0.00269"
"24393","146.32200","22.45557","0.00333"
"24426","146.52000","22.47202","0.00397"
"24459","146.71800","22.48852","0.00340"
"24492","146.91600","22.50502","0.00378"
"24525","147.11400","22.52158","0.00312"
"24558","147.31200","22.53802","0.00353"
"24591","147.51000","22.55453","0.00377"
"24624","147.70800","22.57103","0.00387"
"24657","147.90600","22.58747","0.00349"
"24690","148.10400","22.60403","0.00412"
"24723","148.30200","22.62053","0.00385"
"24756","148.50000","22.63698","0.00370"
"24789","148.69800","22.65354","0.00415"
"24822","148.89600","22.67004","0.00391"
"24855","149.09400","22.68654","0.00382"
"24888","149.29200","22.70304","0.00400"
"24921","149.49000","22.71960","0.00397"
"24954","149.68800","22.73604","0.00381"
"24987","149.88600","22.75255","0.00423"
"25020","150.08400","22.76905","0.00385"
"25053","150.28200","22.78555","0.00478"
"25086","150.48000","22.80206","0.00455"
"25119","150.67800","22.81856","0.00435"
"25152","150.87600","22.83506","0.00420"
"25185","151.07400","22.85156","0.00443"
"25218","151.27200","22.86800","0.00473"
"25251","151.47000","22.88450","0.00472"
"25284","151.66800","22.90107","0.00413"
"25317","151.86600","22.91751","0.00457"
"25350","152.06400","22.93407","0.00490"
"25383","152.26200","22.95051","0.00468"
"25416","152.46000","22.96701","0.00487"
"25449","152.65800","22.98357","0.00464"
"25482","152.85600","22.99996","0.00483"
"25515","153.05400","23.01658","0.00503"
"25548","153.25200","23.03302","0.00524"
"25581","153.45000","23.04952","0.00476"
"25614","153.64800","23.06602","0.00489"
"25647","153.84600","23.08247","0.00515"
"25680","154.04400","23.09903","0.00494"
"25713","154.24200","23.11559","0.00524"
"25746","154.44000","23.13197","0.00522"
"25779","154.63800","23.14853","0.00478"
"25812","154.83600","23.16510","0.00517"
"25845","155.03400","23.18148","0.00556"
"25878","155.23200","23.19810","0.00511"
"25911","155.43000","23.21454","0.00555"
"25944","155.62800","23.23099","0.00551"
"25977","155.82600","23.24761","0.00552"
"26010","156.02400","23.26399","0.00534"
"26043","156.22200","23.28049","0.00620"
"26076","156.42000","23.29705","0.00579"
"26109","156.61800","23.31349","0.00550"
"26142","156.81600","23.33006","0.00551"
"26175","157.01400","23.34656","0.00604"
"26208","157.21200","23.36300","0.00568"
"26241","157.41000","23.37950","0.00579"
"26274","157.60800","23.39606","0.00582"
"26307","157.80600","23.41257","0.00624"
"26340","158.00400","23.42907","0.00599"
"26373","158.20200","23.44551","0.00632"
"26406","158.40000","23.46207","0.00599"
"26439","158.59800","23.47851","0.00590"
"26472","158.79600","23.49496","0.00608"
"26505","158.99400","23.51158","0.00638"
"26538","159.19200","23.52802","0.00678"
"26571","159.39000","23.54452","0.00658"
"26604","159.58800","23.56108","0.00674"
"26637","159.78600","23.57752","0.00663"
"26670","159.98400","23.59409","0.00674"
"26703","160.18200","23.61059","0.00676"
"26736","160.38000","23.62703","0.00661"
"26769","160.57800","23.64359","0.00639"
"26802","160.77600","23.66003","0.00615"
"26835","160.97400","23.67654","0.00627"
"26868","161.17200","23.69304","0.00672"
"26901","161.37000","23.70954","0.00671"
"26934","161.56800","23.72598","0.00704"
"26967","161.76600","23.74254","0.00674"
"27000","161.96400","23.75899","0.00680"
"27033","162.16200","23.77555","0.00732"
"27066","162.36000","23.79205","0.00713"
"27099","162.55800","23.80849","0.00713"
"27132","162.75600","23.82505","0.00747"
"27165","162.95400","23.84150","0.00745"
"27198","163.15200","23.85806","0.00704"
"27231","163.35000","23.87456","0.00778"
"27264","163.54800","23.89106","0.00744"
"27297","163.74600","23.90750","0.00760"
"27330","163.94400","23.92407","0.00739"
"27363","164.14200","23.94051","0.00790"
"27396","164.34000","23.95701","0.00793"
"27429","164.53800","23.97351","0.00814"
"27462","164.73600","23.99001","0.00767"
"27495","164.93400","24.00652","0.00773"
"27528","165.13200","24.02302","0.00788"
"27561","165.33000","24.03952","0.00795"
"27594","165.52800","24.05608","0.00813"
"27627","165.72600","24.07252","0.00779"
"27660","165.92400","24.08902","0.00758"
"27693","166.12200","24.10552","0.00814"
"27726","166.32000","24.12203","0.00841"
"27759","166.51800","24.13853","0.00827"
"27792","166.71600","24.15503","0.00806"
"27825","166.91400","24.17153","0.00867"
"27858","167.11200","24.18803","0.00866"
"27891","167.31000","24.20453","0.00873"
"27924","167.50800","24.22104","0.00876"
"27957","167.70600","24.23754","0.00852"
"27990","167.90400","24.25398","0.00891"
"28023","168.10200","24.27055","0.00905"
"28056","168.30000","24.28711","0.00925"
"28089","168.49800","24.30349","0.00914"
"28122","168.69600","24.32005","0.00952"
"28155","168.89400","24.33649","0.00887"
"28188","169.09200","24.35299","0.00988"
"28221","169.29000","24.36955","0.00967"
"28254","169.48800","24.38600","0.00957"
"28287","169.68600","24.40250","0.00975"
"28320","169.88400","24.41912","0.00977"
"28353","170.08200","24.43550","0.00998"
"28386","170.28000","24.45206","0.00964"
"28419","170.47800","24.46857","0.00987"
"28452","170.67600","24.48501","0.00986"
"28485","170.87400","24.50157","0.01002"
"28518","171.07200","24.51807","0.01011"
"28551","171.27000","24.53452","0.00990"
"28584","171.46800","24.55108","0.01013"
"28617","171.66600","24.56746","0.01009"
"28650","171.86400","24.58408","0.01084"
"28683","172.06200","24.60052","0.01030"
"28716","172.26000","24.61696","0.01071"
"28749","172.45800","24.63359","0.01100"
"28782","172.65600","24.65009","0.01129"
"28815","172.85400","24.66653","0.01074"
"28848","173.05200","24.68303","0.01119"
"28881","173.25000","24.69953","0.01096"
"28914","173.44800","24.71603","0.01130"
"28947","173.64600","24.73254","0.01154"
"28980","173.84400","24.74898","0.01166"
"29013","174.04200","24.76560","0.01175"
"29046","174.24000","24.78198","0.01161"
"29079","174.43800","24.79848","0.01205"
"29112","174.63600","24.81499","0.01147"
"29145","174.83400","24.83149","0.01192"
"29178","175.03200","24.84805","0.01203"
"29211","175.23000","24.86455","0.01187"
"29244","175.42800","24.88099","0.01215"
"29277","175.62600","24.89762","0.01229"
"29310","175.82400","24.91406","0.01247"
"29343","176.02200","24.93050","0.01271"
"29376","176.22000","24.94712","0.01297"
"29409","176.41800","24.96350","0.01281"
"29442","176.61600","24.98001","0.01352"
"29475","176.81400","24.99651","0.01366"
"29508","177.01200","25.01301","0.01343"
"29541","177.21000","25.02957","0.01373"
"29574","177.40800","25.04607","0.01363"
"29607","177.60600","25.06252","0.01364"
"29640","177.80400","25.07908","0.01350"
"29673","178.00200","25.09552","0.01416"
"29706","178.20000","25.11202","0.01429"
"29739","178.39800","25.12858","0.01407"
"29772","178.59600","25.14503","0.01382"
"29805","178.79400","25.16159","0.01399"
"29838","178.99200","25.17803","0.01408"
"29871","179.19000","25.19453","0.01465"
"29904","179.38800","25.21103","0.01416"
"29937","179.58600","25.22754","0.01472"
"29970","179.78400","25.24404","0.01461"
"30003","179.98200","25.26054","0.01517"
"30036","180.18000","25.27704","0.01528"
"30069","180.37800","25.29354","0.01464"
"30102","180.57600","25.31005","0.01553"
"30135","180.77400","25.32655","0.01501"
"30168","180.97200","25.34305","0.01591"
"30201","181.17000","25.35949","0.01603"
"30234","181.36800","25.37605","0.01598"
"30267","181.56600","25.39256","0.01634"
"30300","181.76400","25.40900","0.01639"
"30333","181.96200","25.42550","0.01662"
"30366","182.16000","25.44206","0.01648"
"30399","182.35800","25.45850","0.01667"
"30432","182.55600","25.47501","0.01679"
"30465","182.75400","25.49157","0.01740"
"30498","182.95200","25.50807","0.01726"
"30531","183.15000","25.52451","0.01694"
"30564","183.34800","25.54107","0.01794"
"30597","183.54600","25.55751","0.01751"
"30630","183.74400","25.57401","0.01854"
"30663","183.94200","25.59058","0.01760"
"30696","184.14000","25.60702","0.01794"
"30729","184.33800","25.62352","0.01905"
"30762","184.53600","25.64003","0.01829"
"30795","184.73400","25.65652","0.01932"
"30828","184.93200","25.67303","0.01967"
"30861","185.13000","25.68947","0.01998"
"30894","185.32800","25.70603","0.02028"
"30927","185.52600","25.72253","0.02111"
"30960","185.72400","25.73898","0.02077"
"30993","185.92200","25.75554","0.02067"
"31026","186.12000","25.77198","0.02110"
"31059","186.31800","25.78854","0.02146"
"31092","186.51600","25.80504","0.02151"
"31125","186.71400","25.82149","0.02166"
"31158","186.91200","25.83799","0.02191"
"31191","187.11000","25.85461","0.02173"
"31224","187.30800","25.87093","0.02196"
"31257","187.50600","25.88755","0.02224"
"31290","187.70400","25.90406","0.02227"
"31323","187.90200","25.92050","0.02271"
"31356","188.10000","25.93706","0.02346"
"31389","188.29800","25.95350","0.02336"
"31422","188.49600","25.97000","0.02409"
"31455","188.69400","25.98656","0.02359"
"31488","188.89200","26.00294","0.02425"
"31521","189.09000","26.01957","0.02440"
"31554","189.28800","26.03607","0.02448"
"31587","189.48600","26.05251","0.02485"
"31620","189.68400","26.06907","0.02497"
"31653","189.88200","26.08552","0.02524"
"31686","190.08000","26.10202","0.02522"
"31719","190.27800","26.11852","0.02510"
"31752","190.47600","26.13502","0.02529"
"31785","190.67400","26.15158","0.02590"
"31818","190.87200","26.16802","0.02544"
"31851","191.07000","26.18447","0.02573"
"31884","191.26800","26.20109","0.02503"
"31917","191.46600","26.21747","0.02625"
"31950","191.66400","26.23403","0.02567"
"31983","191.86200","26.25054","0.02645"
"32016","192.06000","26.26698","0.02594"
"32049","192.25800","26.28360","0.02711"
"32082","192.45600","26.30004","0.02633"
"32115","192.65400","26.31648","0.02714"
"32148","192.85200","26.33311","0.02676"
"32181","193.05000","26.34949","0.02728"
"32214","193.24800","26.36599","0.02709"
"32247","193.44600","26.38255","0.02786"
"32280","193.64400","26.39905","0.02755"
"32313","193.84200","26.41555","0.02762"
"32346","194.04000","26.43206","0.02820"
"32379","194.23800","26.44850","0.02610"
"32412","194.43600","26.46506","0.02798"
"32445","194.63400","26.48150","0.02258"
"32478","194.83200","26.49800","0.02882"
"32511","195.03000","26.51457","0.02342"
"32544","195.22800","26.53101","0.02763"
"32577","195.42600","26.54751","0.02439"
"32610","195.62400","26.56407","0.02798"
"32643","195.82200","26.58051","0.02547"
"32676","196.02000","26.59707","0.02783"
"32709","196.21800","26.61358","0.02611"
"32742","196.41600","26.63002","0.02815"
"32775","196.61400","26.64652","0.02631"
"32808","196.81200","26.66302","0.02898"
"32841","197.01000","26.67952","0.02753"
"32874","197.20800","26.69603","0.02891"
"32907","197.40600","26.71253","0.02154"
"32940","197.60400","26.72897","0.02049"
"32973","197.80200","26.74559","0.02250"
"33006","198.00000","26.76204","0.01507"
"33039","198.19800","26.77854","0.02091"
"33072","198.39600","26.79504","0.01339"
"33105","198.59400","26.81154","0.01954"
"33138","198.79200","26.82804","0.01411"
"33171","198.99000","26.84454","0.01895"
"33204","199.18800","26.86105","0.01437"
"33237","199.38600","26.87749","0.01979"
"33270","199.58400","26.89399","0.01560"
"33303","199.78200","26.91055","0.01863"
"33336","199.98000","26.92705","0.01723"
"33369","200.17800","26.94350","0.01832"
"33402","200.37600","26.96006","0.01784"
"33435","200.57400","26.97656","0.01861"
"33468","200.77200","26.99300","0.01824"
"33501","200.97000","27.00956","0.01835"
"33534","201.16800","27.02607","0.01934"
"33567","201.36600","27.04257","0.01948"
"33600","201.56400","27.05907","0.01937"
"33633","201.76200","27.07551","0.01883"
"33666","201.96000","27.09201","0.01905"
"33699","202.15800","27.10857","0.01812"
"33732","202.35600","27.12496","0.01980"
"33765","202.55400","27.14158","0.01823"
"33798","202.75200","27.15808","0.02024"
"33831","202.95000","27.17452","0.01865"
"33864","203.14800","27.19108","0.02046"
"33897","203.34600","27.20753","0.01937"
"33930","203.54400","27.22403","0.01992"
"33963","203.74200","27.24059","0.01999"
"33996","203.94000","27.25691","0.02074"
"34029","204.13800","27.27354","0.02031"
"34062","204.33600","27.29010","0.02109"
"34095","204.53400","27.30648","0.02022"
"34128","204.73200","27.32304","0.02186"
"34161","204.93000","27.33948","0.02089"
"34194","205.12800","27.35598","0.02168"
"34227","205.32600","27.37255","0.02160"
"34260","205.52400","27.38905","0.02184"
"34293","205.72200","27.40555","0.02149"
"34326","205.92000","27.42205","0.02213"
"34359","206.11800","27.43849","0.02210"
"34392","206.31600","27.45511","0.02260"
"34425","206.51400","27.47156","0.02269"
"34458","206.71200","27.48800","0.02268"
"34491","206.91000","27.50456","0.02201"
"34524","207.10800","27.52100","0.02296"
"34557","207.30600","27.53750","0.02250"
"34590","207.50400","27.55407","0.02300"
"34623","207.70200","27.57045","0.02327"
"34656","207.90000","27.58707","0.02313"
"34689","208.09800","27.60351","0.02303"
"34722","208.29600","27.61996","0.02294"
"34755","208.49400","27.63658","0.02339"
"34788","208.69200","27.65302","0.02388"
"34821","208.89000","27.66952","0.02399"
"34854","209.08800","27.68602","0.02410"
"34887","209.28600","27.70253","0.02290"
"34920","209.48400","27.71908","0.02376"
"34953","209.68200","27.73559","0.02296"
"34986","209.88000","27.75197","0.02401"
"35019","210.07800","27.76865","0.02281"
"35052","210.27600","27.78503","0.02422"
"35085","210.47400","27.80148","0.02346"
"35118","210.67200","27.81804","0.02400"
"35151","210.87000","27.83454","0.02339"
"35184","211.06800","27.85104","0.02409"
"35217","211.26600","27.86754","0.02380"
"35250","211.46400","27.88398","0.02488"
"35283","211.66200","27.90061","0.02407"
"35316","211.86000","27.91705","0.02509"
"35349","212.05800","27.93349","0.02457"
"35382","212.25600","27.95005","0.02474"
"35415","212.45400","27.96650","0.02411"
"35448","212.65200","27.98299","0.02472"
"35481","212.85000","27.99956","0.02442"
"35514","213.04800","28.01600","0.02439"
"35547","213.24600","28.03250","0.02441"
"35580","213.44400","28.04906","0.02473"
"35613","213.64200","28.06551","0.02525"
"35646","213.84000","28.08207","0.02524"
"35679","214.03800","28.09851","0.02539"
"35712","214.23600","28.11501","0.02505"
"35745","214.43400","28.13157","0.02560"
"35778","214.63200","28.14801","0.02578"
"35811","214.83000","28.16452","0.02614"
"35844","215.02800","28.18108","0.02591"
"35877","215.22600","28.19752","0.02627"
"35910","215.42400","28.21402","0.02603"
"35943","215.62200","28.23053","0.02623"
"35976","215.82000","28.24703","0.02651"
"36009","216.01800","28.26353","0.02637"
"36042","216.21600","28.28009","0.02619"
"36075","216.41400","28.29653","0.02699"
"36108","216.61200","28.31304","0.02653"
"36141","216.81000","28.32954","0.02707"
"36174","217.00800","28.34604","0.02699"
"36207","217.20600","28.36254","0.02686"
"36240","217.40400","28.37904","0.02695"
"36273","217.60200","28.39548","0.02685"
"36306","217.80000","28.41205","0.02750"
"36339","217.99800","28.42849","0.02756"
"36372","218.19600","28.44505","0.02762"
"36405","218.39400","28.46155","0.02758"
"36438","218.59200","28.47805","0.02806"
"36471","218.79000","28.49456","0.02832"
"36504","218.98800","28.51100","0.02824"
"36537","219.18600","28.52756","0.02885"
"36570","219.38400","28.54412","0.02943"
"36603","219.58200","28.56050","0.02934"
"36636","219.78000","28.57706","0.02973"
"36669","219.97800","28.59357","0.02976"
"36702","220.17600","28.60995","0.02995"
"36735","220.37400","28.62657","0.03004"
"36768","220.57200","28.64301","0.03006"
"36801","220.77000","28.65952","0.03040"
"36834","220.96800","28.67607","0.03089"
"36867","221.16600","28.69252","0.03085"
"36900","221.36400","28.70902","0.03125"
"36933","221.56200","28.72558","0.03125"
"36966","221.76000","28.74196","0.03206"
"36999","221.95800","28.75853","0.03110"
"37032","222.15600","28.77503","0.03184"
"37065","222.35400","28.79153","0.03200"
"37098","222.55200","28.80803","0.03296"
"37131","222.75000","28.82454","0.03192"
"37164","222.94800","28.84104","0.03243"
"37197","223.14600","28.85760","0.03316"
"37230","223.34400","28.87392","0.03311"
"37263","223.54200","28.89060","0.03287"
"37296","223.74000","28.90704","0.03248"
"37329","223.93800","28.92349","0.03218"
"37362","224.13600","28.94005","0.03162"
"37395","224.33400","28.95655","0.03182"
"37428","224.53200","28.97305","0.03260"
"37461","224.73000","28.98961","0.03279"
"37494","224.92800","29.00599","0.03242"
"37527","225.12600","29.02256","0.03361"
"37560","225.32400","29.03900","0.03277"
"37593","225.52200","29.05544","0.03313"
"37626","225.72000","29.07206","0.03328"
"37659","225.91800","29.08850","0.03408"
"37692","226.11600","29.10501","0.03319"
"37725","226.31400","29.12157","0.03372"
"37758","226.51200","29.13801","0.03408"
"37791","226.71000","29.15457","0.03425"
"37824","226.90800","29.17107","0.03429"
"37857","227.10600","29.18746","0.03424"
"37890","227.30400","29.20408","0.03484"
"37923","227.50200","29.22046","0.03517"
"37956","227.70000","29.23702","0.03504"
"37989","227.89800","29.25352","0.03550"
"38022","228.09600","29.26997","0.03589"
"38055","228.29400","29.28653","0.03610"
"38088","228.49200","29.30309","0.03630"
"38121","228.69000","29.31947","0.01848"
"38154","228.88800","29.33609","0.00200"
"38187","229.08600","29.35254","0.00181"
"38220","229.28400","29.36904","-0.00052"
"38253","229.48200","29.38554","-0.00099"
"38286","229.68000","29.40204","-0.00089"
"38319","229.87800","29.41849","-0.00110"
"38352","230.07600","29.43505","-0.00057"
"38385","230.27400","29.45149","-0.00025"
"38418","230.47200","29.46799","-0.00004"
"38451","230.67000","29.48449","-0.00118"
"38484","230.86800","29.50105","-0.00066"
"38517","231.06600","29.51755","-0.00035"
"38550","231.26400","29.53406","-0.00080"
"38583","231.46200","29.55050","-0.00072"
"38616","231.66000","29.56700","0.00001"
"38649","231.85800","29.58356","-0.00069"
"38682","232.05600","29.60007","-0.00066"
"38715","232.25400","29.61651","-0.00082"
"38748","232.45200","29.63301","-0.00093"
"38781","232.65000","29.64951","-0.00058"
"38814","232.84800","29.66601","-0.00030"
"38847","233.04600","29.68252","-0.00063"
"38880","233.24400","29.69908","-0.00086"
"38913","233.44200","29.71552","-0.00117"
"38946","233.64000","29.73202","-0.00074"
"38979","233.83800","29.74852","-0.00084"
"39012","234.03600","29.76502","-0.00078"
"39045","234.23400","29.78153","-0.00061"
"39078","234.43200","29.79803","-0.00077"
"39111","234.63000","29.81453","-0.00101"
"39144","234.82800","29.83103","-0.00073"
"39177","235.02600","29.84759","-0.00110"
"39210","235.22400","29.86403","-0.00099"
"39243","235.42200","29.88054","-0.00039"
"39276","235.62000","29.89710","-0.00088"
"39309","235.81800","29.91354","-0.00081"
"39342","236.01600","29.93004","-0.00097"
"39375","236.21400","29.94654","-0.00085"
"39408","236.41200","29.96299","-0.00041"
"39441","236.61000","29.97955","-0.00056"
"39474","236.80800","29.99599","-0.00120"
"39507","237.00600","30.01255","-0.00089"
"39540","237.20400","30.02905","-0.00073"
"39573","237.40200","30.04550","-0.00048"
"39606","237.60000","30.06206","-0.00073"
"39639","237.79800","30.07850","-0.00036"
"39672","237.99600","30.09500","-0.00083"
"39705","238.19400","30.11156","-0.00106"
"39738","238.39200","30.12801","-0.00089"
"39771","238.59000","30.14451","-0.00102"
"39804","238.78800","30.16107","-0.00093"
"39837","238.98600","30.17751","-0.00047"
"39870","239.18400","30.19407","-0.00055"
"39903","239.38200","30.21052","-0.00093"
"39936","239.58000","30.22702","-0.00079"
"39969","239.77800","30.24358","-0.00052"
"40002","239.97600","30.26002","-0.00092"
"40035","240.17400","30.27652","-0.00097"
"40068","240.37200","30.29309","-0.00098"
"40101","240.57000","30.30947","-0.00086"
"40134","240.76800","30.32609","-0.00090"
"40167","240.96600","30.34253","-0.00063"
"40200","241.16400","30.35897","-0.00074"
"40233","241.36200","30.37553","-0.00067"
"40266","241.56000","30.39204","-0.00062"
"40299","241.75800","30.40854","-0.00045"
"40332","241.95600","30.42504","-0.00058"
"40365","242.15400","30.44148","-0.00074"
"40398","242.35200","30.45810","-0.00061"
"40431","242.55000","30.47449","-0.00059"
"40464","242.74800","30.49099","-0.00060"
"40497","242.94600","30.50755","-0.00068"
"40530","243.14400","30.52399","-0.00084"
"40563","243.34200","30.54050","-0.00098"
"40566","243.35800","30.54187","-0.00103"