File: Trajectories_together/161216Specimen_RawData_3.csv
"","V1","V2","V3"
"1","End date","12/16/2016",""
"2","Specimen label","6DG_Unk",""
"3","Maximum Load","0.12815","N"
"4","Time","Extension","Load"
"5","(s)","(mm)","(N)"
"6","0.00000","0.00000","0.00001"
"54","0.28800","0.02338","0.00009"
"102","0.57600","0.04825","0.00049"
"150","0.86400","0.07229","0.00043"
"198","1.15200","0.09620","0.00023"
"246","1.44000","0.12024","0.00013"
"294","1.72800","0.14421","0.00071"
"342","2.01600","0.16825","0.00030"
"390","2.30400","0.19216","0.00021"
"438","2.59200","0.21614","0.00023"
"486","2.88000","0.24023","0.00050"
"534","3.16800","0.26421","0.00058"
"582","3.45600","0.28825","0.00030"
"630","3.74400","0.31222","0.00088"
"678","4.03200","0.33626","0.00022"
"726","4.32000","0.36017","0.00065"
"774","4.60800","0.38421","0.00100"
"822","4.89600","0.40818","0.00032"
"870","5.18400","0.43216","0.00108"
"918","5.47200","0.45619","0.00082"
"966","5.76000","0.48017","0.00078"
"1014","6.04800","0.50421","0.00045"
"1062","6.33600","0.52824","0.00083"
"1110","6.62400","0.55228","0.00078"
"1158","6.91200","0.57619","0.00069"
"1206","7.20000","0.60023","0.00077"
"1254","7.48800","0.62414","0.00086"
"1302","7.77600","0.64824","0.00131"
"1350","8.06400","0.67215","0.00116"
"1398","8.35200","0.69625","0.00066"
"1446","8.64000","0.72022","0.00078"
"1494","8.92800","0.74426","0.00090"
"1542","9.21600","0.76824","0.00133"
"1590","9.50400","0.79227","0.00099"
"1638","9.79200","0.81619","0.00123"
"1686","10.08000","0.84016","0.00126"
"1734","10.36800","0.86420","0.00119"
"1782","10.65600","0.88817","0.00140"
"1830","10.94400","0.91221","0.00109"
"1878","11.23200","0.93618","0.00132"
"1926","11.52000","0.96022","0.00117"
"1974","11.80800","0.98420","0.00148"
"2022","12.09600","1.00823","0.00139"
"2070","12.38400","1.03215","0.00138"
"2118","12.67200","1.05624","0.00103"
"2166","12.96000","1.08022","0.00125"
"2214","13.24800","1.10419","0.00163"
"2262","13.53600","1.12817","0.00142"
"2310","13.82400","1.15220","0.00172"
"2358","14.11200","1.17618","0.00166"
"2406","14.40000","1.20022","0.00164"
"2454","14.68800","1.22425","0.00171"
"2502","14.97600","1.24817","0.00185"
"2550","15.26400","1.27220","0.00182"
"2598","15.55200","1.29618","0.00191"
"2646","15.84000","1.32021","0.00188"
"2694","16.12800","1.34419","0.00199"
"2742","16.41600","1.36822","0.00162"
"2790","16.70400","1.39214","0.00163"
"2838","16.99200","1.41623","0.00189"
"2886","17.28000","1.44021","0.00156"
"2934","17.56800","1.46425","0.00164"
"2982","17.85600","1.48816","0.00177"
"3030","18.14400","1.51220","0.00209"
"3078","18.43200","1.53617","0.00224"
"3126","18.72000","1.56015","0.00194"
"3174","19.00800","1.58424","0.00244"
"3222","19.29600","1.60822","0.00228"
"3270","19.58400","1.63219","0.00235"
"3318","19.87200","1.65611","0.00202"
"3366","20.16000","1.68015","0.00214"
"3414","20.44800","1.70412","0.00239"
"3462","20.73600","1.72816","0.00172"
"3510","21.02400","1.75219","0.00237"
"3558","21.31200","1.77623","0.00199"
"3606","21.60000","1.80014","0.00207"
"3654","21.88800","1.82418","0.00213"
"3702","22.17600","1.84821","0.00199"
"3750","22.46400","1.87219","0.00228"
"3798","22.75200","1.89617","0.00240"
"3846","23.04000","1.92014","0.00276"
"3894","23.32800","1.94430","0.00241"
"3942","23.61600","1.96821","0.00257"
"3990","23.90400","1.99219","0.00254"
"4038","24.19200","2.01610","0.00267"
"4086","24.48000","2.04020","0.00269"
"4134","24.76800","2.06411","0.00257"
"4182","25.05600","2.08821","0.00245"
"4230","25.34400","2.11213","0.00235"
"4278","25.63200","2.13622","0.00269"
"4326","25.92000","2.16014","0.00251"
"4374","26.20800","2.18417","0.00249"
"4422","26.49600","2.20821","0.00254"
"4470","26.78400","2.23218","0.00325"
"4518","27.07200","2.25622","0.00284"
"4566","27.36000","2.28013","0.00266"
"4614","27.64800","2.30417","0.00240"
"4662","27.93600","2.32808","0.00252"
"4710","28.22400","2.35218","0.00281"
"4758","28.51200","2.37616","0.00256"
"4806","28.80000","2.40019","0.00292"
"4854","29.08800","2.42411","0.00273"
"4902","29.37600","2.44820","0.00265"
"4950","29.66400","2.47218","0.00308"
"4998","29.95200","2.49621","0.00280"
"5046","30.24000","2.52019","0.00331"
"5094","30.52800","2.54416","0.00285"
"5142","30.81600","2.56826","0.00329"
"5190","31.10400","2.59212","0.00304"
"5238","31.39200","2.61615","0.00291"
"5286","31.68000","2.64013","0.00316"
"5334","31.96800","2.66416","0.00325"
"5382","32.25600","2.68814","0.00325"
"5430","32.54400","2.71217","0.00285"
"5478","32.83200","2.73609","0.00321"
"5526","33.12000","2.76018","0.00318"
"5574","33.40800","2.78416","0.00320"
"5622","33.69600","2.80819","0.00302"
"5670","33.98400","2.83217","0.00340"
"5718","34.27200","2.85621","0.00349"
"5766","34.56000","2.88018","0.00319"
"5814","34.84800","2.90416","0.00317"
"5862","35.13600","2.92819","0.00358"
"5910","35.42400","2.95217","0.00316"
"5958","35.71200","2.97620","0.00340"
"6006","36.00000","3.00012","0.00375"
"6054","36.28800","3.02415","0.00340"
"6102","36.57600","3.04813","0.00347"
"6150","36.86400","3.07223","0.00316"
"6198","37.15200","3.09614","0.00353"
"6246","37.44000","3.12018","0.00383"
"6294","37.72800","3.14421","0.00324"
"6342","38.01600","3.16819","0.00389"
"6390","38.30400","3.19216","0.00397"
"6438","38.59200","3.21614","0.00433"
"6486","38.88000","3.24017","0.00371"
"6534","39.16800","3.26421","0.00340"
"6582","39.45600","3.28824","0.00330"
"6630","39.74400","3.31216","0.00390"
"6678","40.03200","3.33620","0.00360"
"6726","40.32000","3.36011","0.00358"
"6774","40.60800","3.38421","0.00424"
"6822","40.89600","3.40818","0.00383"
"6870","41.18400","3.43222","0.00400"
"6918","41.47200","3.45619","0.00405"
"6966","41.76000","3.48023","0.00395"
"7014","42.04800","3.50420","0.00340"
"7062","42.33600","3.52818","0.00433"
"7110","42.62400","3.55222","0.00386"
"7158","42.91200","3.57625","0.00395"
"7206","43.20000","3.60023","0.00446"
"7254","43.48800","3.62414","0.00418"
"7302","43.77600","3.64818","0.00441"
"7350","44.06400","3.67215","0.00428"
"7398","44.35200","3.69625","0.00434"
"7446","44.64000","3.72022","0.00417"
"7494","44.92800","3.74426","0.00412"
"7542","45.21600","3.76818","0.00407"
"7590","45.50400","3.79221","0.00442"
"7638","45.79200","3.81619","0.00391"
"7686","46.08000","3.84022","0.00425"
"7734","46.36800","3.86414","0.00405"
"7782","46.65600","3.88823","0.00440"
"7830","46.94400","3.91221","0.00471"
"7878","47.23200","3.93624","0.00454"
"7926","47.52000","3.96022","0.00492"
"7974","47.80800","3.98420","0.00424"
"8022","48.09600","4.00823","0.00476"
"8070","48.38400","4.03221","0.00466"
"8118","48.67200","4.05624","0.00479"
"8166","48.96000","4.08022","0.00463"
"8214","49.24800","4.10425","0.00462"
"8262","49.53600","4.12823","0.00431"
"8310","49.82400","4.15220","0.00500"
"8358","50.11200","4.17618","0.00490"
"8406","50.40000","4.20021","0.00441"
"8454","50.68800","4.22419","0.00446"
"8502","50.97600","4.24823","0.00493"
"8550","51.26400","4.27220","0.00522"
"8598","51.55200","4.29618","0.00487"
"8646","51.84000","4.32021","0.00511"
"8694","52.12800","4.34413","0.00469"
"8742","52.41600","4.36822","0.00471"
"8790","52.70400","4.39220","0.00536"
"8838","52.99200","4.41623","0.00513"
"8886","53.28000","4.44015","0.00537"
"8934","53.56800","4.46419","0.00532"
"8982","53.85600","4.48816","0.00519"
"9030","54.14400","4.51220","0.00530"
"9078","54.43200","4.53623","0.00516"
"9126","54.72000","4.56021","0.00556"
"9174","55.00800","4.58418","0.00515"
"9222","55.29600","4.60816","0.00533"
"9270","55.58400","4.63219","0.00562"
"9318","55.87200","4.65617","0.00548"
"9366","56.16000","4.68021","0.00569"
"9414","56.44800","4.70418","0.00537"
"9462","56.73600","4.72816","0.00534"
"9510","57.02400","4.75219","0.00547"
"9558","57.31200","4.77617","0.00567"
"9606","57.60000","4.80020","0.00560"
"9654","57.88800","4.82418","0.00546"
"9702","58.17600","4.84815","0.00564"
"9750","58.46400","4.87219","0.00606"
"9798","58.75200","4.89616","0.00545"
"9846","59.04000","4.92020","0.00526"
"9894","59.32800","4.94424","0.00589"
"9942","59.61600","4.96821","0.00611"
"9990","59.90400","4.99225","0.00608"
"10038","60.19200","5.01616","0.00568"
"10086","60.48000","5.04020","0.00569"
"10134","60.76800","5.06417","0.00626"
"10182","61.05600","5.08815","0.00590"
"10230","61.34400","5.11212","0.00551"
"10278","61.63200","5.13622","0.00652"
"10326","61.92000","5.16020","0.00590"
"10374","62.20800","5.18429","0.00606"
"10422","62.49600","5.20821","0.00613"
"10470","62.78400","5.23224","0.00618"
"10518","63.07200","5.25622","0.00668"
"10566","63.36000","5.28019","0.00565"
"10614","63.64800","5.30423","0.00568"
"10662","63.93600","5.32814","0.00573"
"10710","64.22400","5.35218","0.00624"
"10758","64.51200","5.37616","0.00615"
"10806","64.80000","5.40019","0.00558"
"10854","65.08800","5.42417","0.00640"
"10902","65.37600","5.44820","0.00597"
"10950","65.66400","5.47218","0.00600"
"10998","65.95200","5.49621","0.00591"
"11046","66.24000","5.52013","0.00581"
"11094","66.52800","5.54422","0.00614"
"11142","66.81600","5.56826","0.00600"
"11190","67.10400","5.59223","0.00654"
"11238","67.39200","5.61621","0.00626"
"11286","67.68000","5.64019","0.00603"
"11334","67.96800","5.66422","0.00607"
"11382","68.25600","5.68820","0.00590"
"11430","68.54400","5.71223","0.00621"
"11478","68.83200","5.73615","0.00585"
"11526","69.12000","5.76018","0.00629"
"11574","69.40800","5.78410","0.00581"
"11622","69.69600","5.80825","0.00631"
"11670","69.98400","5.83217","0.00630"
"11718","70.27200","5.85621","0.00584"
"11766","70.56000","5.88018","0.00614"
"11814","70.84800","5.90422","0.00630"
"11862","71.13600","5.92819","0.00620"
"11910","71.42400","5.95217","0.00580"
"11958","71.71200","5.97620","0.00583"
"12006","72.00000","6.00018","0.00590"
"12054","72.28800","6.02415","0.00623"
"12102","72.57600","6.04819","0.00557"
"12150","72.86400","6.07217","0.00612"
"12198","73.15200","6.09614","0.00630"
"12246","73.44000","6.12018","0.00601"
"12294","73.72800","6.14409","0.00627"
"12342","74.01600","6.16819","0.00640"
"12390","74.30400","6.19216","0.00628"
"12438","74.59200","6.21620","0.00637"
"12486","74.88000","6.24017","0.00642"
"12534","75.16800","6.26421","0.00601"
"12582","75.45600","6.28824","0.00614"
"12630","75.74400","6.31216","0.00664"
"12678","76.03200","6.33620","0.00631"
"12726","76.32000","6.36017","0.00640"
"12774","76.60800","6.38421","0.00651"
"12822","76.89600","6.40818","0.00626"
"12870","77.18400","6.43222","0.00648"
"12918","77.47200","6.45613","0.00643"
"12966","77.76000","6.48023","0.00628"
"13014","78.04800","6.50415","0.00667"
"13062","78.33600","6.52824","0.00660"
"13110","78.62400","6.55216","0.00642"
"13158","78.91200","6.57619","0.00670"
"13206","79.20000","6.60017","0.00630"
"13254","79.48800","6.62420","0.00684"
"13302","79.77600","6.64818","0.00631"
"13350","80.06400","6.67215","0.00625"
"13398","80.35200","6.69625","0.00648"
"13446","80.64000","6.72022","0.00683"
"13494","80.92800","6.74426","0.00626"
"13542","81.21600","6.76824","0.00692"
"13590","81.50400","6.79227","0.00671"
"13638","81.79200","6.81619","0.00630"
"13686","82.08000","6.84022","0.00609"
"13734","82.36800","6.86414","0.00668"
"13782","82.65600","6.88823","0.00602"
"13830","82.94400","6.91221","0.00652"
"13878","83.23200","6.93624","0.00647"
"13926","83.52000","6.96022","0.00676"
"13974","83.80800","6.98420","0.00660"
"14022","84.09600","7.00823","0.00731"
"14070","84.38400","7.03215","0.00751"
"14118","84.67200","7.05624","0.00686"
"14166","84.96000","7.08016","0.00681"
"14214","85.24800","7.10425","0.00671"
"14262","85.53600","7.12817","0.00678"
"14310","85.82400","7.15226","0.00631"
"14358","86.11200","7.17624","0.00708"
"14406","86.40000","7.20027","0.00706"
"14454","86.68800","7.22419","0.00736"
"14502","86.97600","7.24823","0.00714"
"14550","87.26400","7.27220","0.00664"
"14598","87.55200","7.29618","0.00723"
"14646","87.84000","7.32021","0.00711"
"14694","88.12800","7.34419","0.00690"
"14742","88.41600","7.36822","0.00731"
"14790","88.70400","7.39220","0.00692"
"14838","88.99200","7.41629","0.00759"
"14886","89.28000","7.44021","0.00743"
"14934","89.56800","7.46425","0.00703"
"14982","89.85600","7.48816","0.00716"
"15030","90.14400","7.51226","0.00697"
"15078","90.43200","7.53617","0.00736"
"15126","90.72000","7.56021","0.00691"
"15174","91.00800","7.58418","0.00736"
"15222","91.29600","7.60822","0.00717"
"15270","91.58400","7.63213","0.00720"
"15318","91.87200","7.65617","0.00721"
"15366","92.16000","7.68021","0.00752"
"15414","92.44800","7.70418","0.00743"
"15462","92.73600","7.72828","0.00765"
"15510","93.02400","7.75219","0.00751"
"15558","93.31200","7.77623","0.00742"
"15606","93.60000","7.80020","0.00768"
"15654","93.88800","7.82424","0.00777"
"15702","94.17600","7.84815","0.00765"
"15750","94.46400","7.87219","0.00798"
"15798","94.75200","7.89616","0.00785"
"15846","95.04000","7.92020","0.00757"
"15894","95.32800","7.94418","0.00785"
"15942","95.61600","7.96821","0.00805"
"15990","95.90400","7.99219","0.00769"
"16038","96.19200","8.01622","0.00783"
"16086","96.48000","8.04020","0.00771"
"16134","96.76800","8.06411","0.00790"
"16182","97.05600","8.08821","0.00822"
"16230","97.34400","8.11212","0.00786"
"16278","97.63200","8.13622","0.00781"
"16326","97.92000","8.16013","0.00740"
"16374","98.20800","8.18423","0.00794"
"16422","98.49600","8.20815","0.00820"
"16470","98.78400","8.23218","0.00805"
"16518","99.07200","8.25622","0.00843"
"16566","99.36000","8.28019","0.00831"
"16614","99.64800","8.30411","0.00773"
"16662","99.93600","8.32814","0.00828"
"16710","100.22400","8.35224","0.00821"
"16758","100.51200","8.37621","0.00859"
"16806","100.80000","8.40025","0.00823"
"16854","101.08800","8.42417","0.00818"
"16902","101.37600","8.44820","0.00836"
"16950","101.66400","8.47218","0.00865"
"16998","101.95200","8.49621","0.00899"
"17046","102.24000","8.52013","0.00874"
"17094","102.52800","8.54422","0.00832"
"17142","102.81600","8.56814","0.00864"
"17190","103.10400","8.59223","0.00907"
"17238","103.39200","8.61621","0.00855"
"17286","103.68000","8.64019","0.00893"
"17334","103.96800","8.66416","0.00890"
"17382","104.25600","8.68814","0.00879"
"17430","104.54400","8.71223","0.00906"
"17478","104.83200","8.73615","0.00874"
"17526","105.12000","8.76018","0.00890"
"17574","105.40800","8.78416","0.00905"
"17622","105.69600","8.80819","0.00895"
"17670","105.98400","8.83211","0.00932"
"17718","106.27200","8.85614","0.00936"
"17766","106.56000","8.88012","0.00927"
"17814","106.84800","8.90422","0.00899"
"17862","107.13600","8.92819","0.00948"
"17910","107.42400","8.95217","0.00949"
"17958","107.71200","8.97614","0.00967"
"18006","108.00000","9.00018","0.00941"
"18054","108.28800","9.02421","0.00946"
"18102","108.57600","9.04819","0.00974"
"18150","108.86400","9.07222","0.00950"
"18198","109.15200","9.09620","0.00919"
"18246","109.44000","9.12018","0.00940"
"18294","109.72800","9.14415","0.00967"
"18342","110.01600","9.16819","0.00970"
"18390","110.30400","9.19210","0.00947"
"18438","110.59200","9.21620","0.01006"
"18486","110.88000","9.24017","0.00986"
"18534","111.16800","9.26421","0.00981"
"18582","111.45600","9.28813","0.00992"
"18630","111.74400","9.31222","0.00945"
"18678","112.03200","9.33619","0.00964"
"18726","112.32000","9.36017","0.00993"
"18774","112.60800","9.38421","0.01008"
"18822","112.89600","9.40818","0.01022"
"18870","113.18400","9.43222","0.00998"
"18918","113.47200","9.45619","0.01068"
"18966","113.76000","9.48017","0.01048"
"19014","114.04800","9.50414","0.00997"
"19062","114.33600","9.52812","0.01013"
"19110","114.62400","9.55210","0.01040"
"19158","114.91200","9.57619","0.01084"
"19206","115.20000","9.60011","0.01062"
"19254","115.48800","9.62420","0.01026"
"19302","115.77600","9.64818","0.01035"
"19350","116.06400","9.67215","0.01043"
"19398","116.35200","9.69619","0.01076"
"19446","116.64000","9.72016","0.01128"
"19494","116.92800","9.74420","0.01085"
"19542","117.21600","9.76812","0.01049"
"19590","117.50400","9.79221","0.01112"
"19638","117.79200","9.81613","0.01033"
"19686","118.08000","9.84022","0.01076"
"19734","118.36800","9.86414","0.01010"
"19782","118.65600","9.88817","0.00991"
"19830","118.94400","9.91215","0.01049"
"19878","119.23200","9.93618","0.01103"
"19926","119.52000","9.96016","0.01050"
"19974","119.80800","9.98419","0.00995"
"20022","120.09600","10.00817","0.01039"
"20070","120.38400","10.03215","0.01037"
"20118","120.67200","10.05618","0.01020"
"20166","120.96000","10.08016","0.01037"
"20214","121.24800","10.10419","0.00950"
"20262","121.53600","10.12817","0.01044"
"20310","121.82400","10.15220","0.01016"
"20358","122.11200","10.17618","0.01043"
"20406","122.40000","10.20015","0.01030"
"20454","122.68800","10.22413","0.00989"
"20502","122.97600","10.24823","0.01000"
"20550","123.26400","10.27214","0.01030"
"20598","123.55200","10.29618","0.01064"
"20646","123.84000","10.32015","0.00997"
"20694","124.12800","10.34419","0.01082"
"20742","124.41600","10.36816","0.01129"
"20790","124.70400","10.39226","0.01055"
"20838","124.99200","10.41623","0.01110"
"20886","125.28000","10.44021","0.01089"
"20934","125.56800","10.46424","0.01130"
"20982","125.85600","10.48822","0.01131"
"21030","126.14400","10.51231","0.01111"
"21078","126.43200","10.53617","0.01111"
"21126","126.72000","10.56021","0.01109"
"21174","127.00800","10.58418","0.01130"
"21222","127.29600","10.60822","0.01163"
"21270","127.58400","10.63219","0.01171"
"21318","127.87200","10.65623","0.01145"
"21366","128.16000","10.68020","0.01136"
"21414","128.44800","10.70424","0.01161"
"21462","128.73600","10.72822","0.01127"
"21510","129.02400","10.75219","0.01178"
"21558","129.31200","10.77623","0.01162"
"21606","129.60000","10.80014","0.01152"
"21654","129.88800","10.82418","0.01188"
"21702","130.17600","10.84815","0.01193"
"21750","130.46400","10.87225","0.01200"
"21798","130.75200","10.89616","0.01192"
"21846","131.04000","10.92020","0.01189"
"21894","131.32800","10.94418","0.01217"
"21942","131.61600","10.96821","0.01197"
"21990","131.90400","10.99219","0.01175"
"22038","132.19200","11.01622","0.01223"
"22086","132.48000","11.04026","0.01230"
"22134","132.76800","11.06423","0.01241"
"22182","133.05600","11.08815","0.01219"
"22230","133.34400","11.11218","0.01209"
"22278","133.63200","11.13622","0.01203"
"22326","133.92000","11.16019","0.01223"
"22374","134.20800","11.18423","0.01251"
"22422","134.49600","11.20821","0.01250"
"22470","134.78400","11.23218","0.01248"
"22518","135.07200","11.25616","0.01196"
"22566","135.36000","11.28019","0.01173"
"22614","135.64800","11.30417","0.01181"
"22662","135.93600","11.32820","0.01213"
"22710","136.22400","11.35218","0.01198"
"22758","136.51200","11.37621","0.01212"
"22806","136.80000","11.40025","0.01217"
"22854","137.08800","11.42417","0.01204"
"22902","137.37600","11.44820","0.01246"
"22950","137.66400","11.47218","0.01237"
"22998","137.95200","11.49621","0.01225"
"23046","138.24000","11.52013","0.01230"
"23094","138.52800","11.54422","0.01198"
"23142","138.81600","11.56820","0.01240"
"23190","139.10400","11.59223","0.01258"
"23238","139.39200","11.61615","0.01242"
"23286","139.68000","11.64025","0.01237"
"23334","139.96800","11.66416","0.01265"
"23382","140.25600","11.68820","0.01230"
"23430","140.54400","11.71217","0.01230"
"23478","140.83200","11.73621","0.01268"
"23526","141.12000","11.76018","0.01302"
"23574","141.40800","11.78416","0.01247"
"23622","141.69600","11.80825","0.01262"
"23670","141.98400","11.83217","0.01268"
"23718","142.27200","11.85620","0.01243"
"23766","142.56000","11.88012","0.01260"
"23814","142.84800","11.90422","0.01299"
"23862","143.13600","11.92813","0.01268"
"23910","143.42400","11.95223","0.01271"
"23958","143.71200","11.97614","0.01268"
"24006","144.00000","12.00024","0.01265"
"24054","144.28800","12.02421","0.01254"
"24102","144.57600","12.04819","0.01295"
"24150","144.86400","12.07222","0.01308"
"24198","145.15200","12.09620","0.01295"
"24246","145.44000","12.12018","0.01308"
"24294","145.72800","12.14415","0.01351"
"24342","146.01600","12.16819","0.01355"
"24390","146.30400","12.19216","0.01290"
"24438","146.59200","12.21620","0.01364"
"24486","146.88000","12.24017","0.01393"
"24534","147.16800","12.26427","0.01360"
"24582","147.45600","12.28812","0.01357"
"24630","147.74400","12.31222","0.01363"
"24678","148.03200","12.33614","0.01340"
"24726","148.32000","12.36023","0.01361"
"24774","148.60800","12.38421","0.01350"
"24822","148.89600","12.40818","0.01371"
"24870","149.18400","12.43222","0.01334"
"24918","149.47200","12.45619","0.01369"
"24966","149.76000","12.48023","0.01407"
"25014","150.04800","12.50420","0.01351"
"25062","150.33600","12.52818","0.01375"
"25110","150.62400","12.55216","0.01383"
"25158","150.91200","12.57619","0.01383"
"25206","151.20000","12.60011","0.01383"
"25254","151.48800","12.62420","0.01399"
"25302","151.77600","12.64818","0.01399"
"25350","152.06400","12.67221","0.01406"
"25398","152.35200","12.69619","0.01440"
"25446","152.64000","12.72022","0.01424"
"25494","152.92800","12.74420","0.01424"
"25542","153.21600","12.76817","0.01403"
"25590","153.50400","12.79221","0.01422"
"25638","153.79200","12.81619","0.01394"
"25686","154.08000","12.84022","0.01462"
"25734","154.36800","12.86420","0.01438"
"25782","154.65600","12.88823","0.01446"
"25830","154.94400","12.91215","0.01444"
"25878","155.23200","12.93618","0.01470"
"25926","155.52000","12.96016","0.01483"
"25974","155.80800","12.98425","0.01487"
"26022","156.09600","13.00817","0.01510"
"26070","156.38400","13.03221","0.01494"
"26118","156.67200","13.05612","0.01482"
"26166","156.96000","13.08022","0.01490"
"26214","157.24800","13.10419","0.01443"
"26262","157.53600","13.12817","0.01491"
"26310","157.82400","13.15220","0.01503"
"26358","158.11200","13.17618","0.01523"
"26406","158.40000","13.20021","0.01541"
"26454","158.68800","13.22413","0.01526"
"26502","158.97600","13.24817","0.01535"
"26550","159.26400","13.27220","0.01536"
"26598","159.55200","13.29624","0.01486"
"26646","159.84000","13.32015","0.01533"
"26694","160.12800","13.34425","0.01590"
"26742","160.41600","13.36822","0.01513"
"26790","160.70400","13.39220","0.01522"
"26838","160.99200","13.41617","0.01540"
"26886","161.28000","13.44021","0.01548"
"26934","161.56800","13.46424","0.01512"
"26982","161.85600","13.48816","0.01554"
"27030","162.14400","13.51226","0.01526"
"27078","162.43200","13.53617","0.01540"
"27126","162.72000","13.56027","0.01560"
"27174","163.00800","13.58418","0.01579"
"27222","163.29600","13.60822","0.01570"
"27270","163.58400","13.63213","0.01586"
"27318","163.87200","13.65623","0.01554"
"27366","164.16000","13.68015","0.01564"
"27414","164.44800","13.70424","0.01566"
"27462","164.73600","13.72822","0.01544"
"27510","165.02400","13.75219","0.01583"
"27558","165.31200","13.77617","0.01568"
"27606","165.60000","13.80020","0.01573"
"27654","165.88800","13.82418","0.01560"
"27702","166.17600","13.84815","0.01580"
"27750","166.46400","13.87225","0.01621"
"27798","166.75200","13.89622","0.01575"
"27846","167.04000","13.92020","0.01635"
"27894","167.32800","13.94417","0.01596"
"27942","167.61600","13.96821","0.01583"
"27990","167.90400","13.99219","0.01636"
"28038","168.19200","14.01622","0.01650"
"28086","168.48000","14.04020","0.01608"
"28134","168.76800","14.06417","0.01602"
"28182","169.05600","14.08821","0.01645"
"28230","169.34400","14.11224","0.01662"
"28278","169.63200","14.13622","0.01645"
"28326","169.92000","14.16026","0.01608"
"28374","170.20800","14.18423","0.01623"
"28422","170.49600","14.20821","0.01670"
"28470","170.78400","14.23230","0.01704"
"28518","171.07200","14.25616","0.01648"
"28566","171.36000","14.28025","0.01674"
"28614","171.64800","14.30417","0.01675"
"28662","171.93600","14.32826","0.01685"
"28710","172.22400","14.35224","0.01691"
"28758","172.51200","14.37621","0.01650"
"28806","172.80000","14.40019","0.01669"
"28854","173.08800","14.42422","0.01701"
"28902","173.37600","14.44820","0.01704"
"28950","173.66400","14.47218","0.01695"
"28998","173.95200","14.49621","0.01770"
"29046","174.24000","14.52025","0.01773"
"29094","174.52800","14.54422","0.01725"
"29142","174.81600","14.56814","0.01775"
"29190","175.10400","14.59223","0.01699"
"29238","175.39200","14.61621","0.01747"
"29286","175.68000","14.64019","0.01748"
"29334","175.96800","14.66416","0.01764"
"29382","176.25600","14.68820","0.01726"
"29430","176.54400","14.71217","0.01786"
"29478","176.83200","14.73621","0.01758"
"29526","177.12000","14.76018","0.01765"
"29574","177.40800","14.78422","0.01817"
"29622","177.69600","14.80819","0.01897"
"29670","177.98400","14.83217","0.01808"
"29718","178.27200","14.85620","0.01781"
"29766","178.56000","14.88018","0.01809"
"29814","178.84800","14.90422","0.01774"
"29862","179.13600","14.92813","0.01796"
"29910","179.42400","14.95217","0.01856"
"29958","179.71200","14.97614","0.01826"
"30006","180.00000","15.00024","0.01798"
"30054","180.28800","15.02415","0.01867"
"30102","180.57600","15.04819","0.01863"
"30150","180.86400","15.07217","0.01831"
"30198","181.15200","15.09620","0.01823"
"30246","181.44000","15.12018","0.01833"
"30294","181.72800","15.14421","0.01856"
"30342","182.01600","15.16819","0.01877"
"30390","182.30400","15.19216","0.01890"
"30438","182.59200","15.21620","0.01961"
"30486","182.88000","15.24017","0.01896"
"30534","183.16800","15.26415","0.01893"
"30582","183.45600","15.28813","0.01891"
"30630","183.74400","15.31216","0.01896"
"30678","184.03200","15.33614","0.01904"
"30726","184.32000","15.36017","0.01934"
"30774","184.60800","15.38415","0.01929"
"30822","184.89600","15.40824","0.01944"
"30870","185.18400","15.43222","0.01926"
"30918","185.47200","15.45613","0.01918"
"30966","185.76000","15.48017","0.01942"
"31014","186.04800","15.50414","0.01954"
"31062","186.33600","15.52818","0.01911"
"31110","186.62400","15.55210","0.01880"
"31158","186.91200","15.57619","0.01880"
"31206","187.20000","15.60017","0.01887"
"31254","187.48800","15.62420","0.01833"
"31302","187.77600","15.64818","0.01834"
"31350","188.06400","15.67227","0.01807"
"31398","188.35200","15.69619","0.01789"
"31446","188.64000","15.72028","0.01800"
"31494","188.92800","15.74408","0.01843"
"31542","189.21600","15.76817","0.01811"
"31590","189.50400","15.79215","0.01799"
"31638","189.79200","15.81618","0.01787"
"31686","190.08000","15.84016","0.01759"
"31734","190.36800","15.86414","0.01744"
"31782","190.65600","15.88817","0.01739"
"31830","190.94400","15.91215","0.01744"
"31878","191.23200","15.93618","0.01799"
"31926","191.52000","15.96016","0.01712"
"31974","191.80800","15.98419","0.01723"
"32022","192.09600","16.00811","0.01751"
"32070","192.38400","16.03220","0.01722"
"32118","192.67200","16.05618","0.01770"
"32166","192.96000","16.08022","0.01760"
"32214","193.24800","16.10419","0.01661"
"32262","193.53600","16.12823","0.01666"
"32310","193.82400","16.15214","0.01704"
"32358","194.11200","16.17612","0.01664"
"32406","194.40000","16.20015","0.01704"
"32454","194.68800","16.22413","0.01679"
"32502","194.97600","16.24822","0.01725"
"32550","195.26400","16.27214","0.01683"
"32598","195.55200","16.29623","0.01697"
"32646","195.84000","16.32015","0.01656"
"32694","196.12800","16.34425","0.01635"
"32742","196.41600","16.36810","0.01615"
"32790","196.70400","16.39220","0.01584"
"32838","196.99200","16.41611","0.01571"
"32886","197.28000","16.44021","0.01613"
"32934","197.56800","16.46418","0.01577"
"32982","197.85600","16.48816","0.01618"
"33030","198.14400","16.51220","0.01559"
"33078","198.43200","16.53617","0.01527"
"33126","198.72000","16.56021","0.01524"
"33174","199.00800","16.58418","0.01582"
"33222","199.29600","16.60816","0.01548"
"33270","199.58400","16.63213","0.01564"
"33318","199.87200","16.65617","0.01589"
"33366","200.16000","16.68014","0.01551"
"33414","200.44800","16.70418","0.01617"
"33462","200.73600","16.72816","0.01609"
"33510","201.02400","16.75225","0.01624"
"33558","201.31200","16.77617","0.01624"
"33606","201.60000","16.80014","0.01651"
"33654","201.88800","16.82412","0.01640"
"33702","202.17600","16.84821","0.01662"
"33750","202.46400","16.87219","0.01707"
"33798","202.75200","16.89616","0.01696"
"33846","203.04000","16.92020","0.01638"
"33894","203.32800","16.94417","0.01690"
"33942","203.61600","16.96821","0.01712"
"33990","203.90400","16.99213","0.01688"
"34038","204.19200","17.01622","0.01733"
"34086","204.48000","17.04014","0.01755"
"34134","204.76800","17.06423","0.01780"
"34182","205.05600","17.08815","0.01768"
"34230","205.34400","17.11224","0.01832"
"34278","205.63200","17.13622","0.01856"
"34326","205.92000","17.16025","0.01856"
"34374","206.20800","17.18423","0.01853"
"34422","206.49600","17.20821","0.01871"
"34470","206.78400","17.23224","0.01894"
"34518","207.07200","17.25616","0.01903"
"34566","207.36000","17.28025","0.01956"
"34614","207.64800","17.30417","0.01924"
"34662","207.93600","17.32826","0.01934"
"34710","208.22400","17.35218","0.01937"
"34758","208.51200","17.37621","0.01956"
"34806","208.80000","17.40013","0.01918"
"34854","209.08800","17.42422","0.01933"
"34902","209.37600","17.44814","0.01968"
"34950","209.66400","17.47218","0.01953"
"34998","209.95200","17.49621","0.02036"
"35046","210.24000","17.52025","0.01971"
"35094","210.52800","17.54422","0.01981"
"35142","210.81600","17.56826","0.02076"
"35190","211.10400","17.59223","0.02033"
"35238","211.39200","17.61615","0.02046"
"35286","211.68000","17.64018","0.02076"
"35334","211.96800","17.66416","0.02105"
"35382","212.25600","17.68819","0.02130"
"35430","212.54400","17.71217","0.02135"
"35478","212.83200","17.73621","0.02133"
"35526","213.12000","17.76018","0.02177"
"35574","213.40800","17.78422","0.02204"
"35622","213.69600","17.80819","0.02226"
"35670","213.98400","17.83223","0.02196"
"35718","214.27200","17.85620","0.02268"
"35766","214.56000","17.88018","0.02234"
"35814","214.84800","17.90421","0.02301"
"35862","215.13600","17.92819","0.02316"
"35910","215.42400","17.95223","0.02310"
"35958","215.71200","17.97614","0.02337"
"36006","216.00000","18.00024","0.02336"
"36054","216.28800","18.02415","0.02368"
"36102","216.57600","18.04819","0.02353"
"36150","216.86400","18.07216","0.02448"
"36198","217.15200","18.09620","0.02466"
"36246","217.44000","18.12017","0.02444"
"36294","217.72800","18.14421","0.02500"
"36342","218.01600","18.16818","0.02467"
"36390","218.30400","18.19222","0.02523"
"36438","218.59200","18.21620","0.02582"
"36486","218.88000","18.24017","0.02556"
"36534","219.16800","18.26415","0.02636"
"36582","219.45600","18.28818","0.02610"
"36630","219.74400","18.31222","0.02633"
"36678","220.03200","18.33619","0.02664"
"36726","220.32000","18.36023","0.02685"
"36774","220.60800","18.38420","0.02660"
"36822","220.89600","18.40824","0.02677"
"36870","221.18400","18.43216","0.02703"
"36918","221.47200","18.45625","0.02757"
"36966","221.76000","18.48017","0.02758"
"37014","222.04800","18.50420","0.02801"
"37062","222.33600","18.52818","0.02803"
"37110","222.62400","18.55221","0.02809"
"37158","222.91200","18.57619","0.02863"
"37206","223.20000","18.60017","0.02897"
"37254","223.48800","18.62426","0.02916"
"37302","223.77600","18.64818","0.02939"
"37350","224.06400","18.67215","0.02950"
"37398","224.35200","18.69613","0.02992"
"37446","224.64000","18.72022","0.02971"
"37494","224.92800","18.74414","0.03015"
"37542","225.21600","18.76818","0.03074"
"37590","225.50400","18.79215","0.03052"
"37638","225.79200","18.81624","0.03119"
"37686","226.08000","18.84016","0.03164"
"37734","226.36800","18.86419","0.03155"
"37782","226.65600","18.88823","0.03244"
"37830","226.94400","18.91221","0.03300"
"37878","227.23200","18.93612","0.03289"
"37926","227.52000","18.96016","0.03299"
"37974","227.80800","18.98419","0.03352"
"38022","228.09600","19.00817","0.03368"
"38070","228.38400","19.03220","0.03395"
"38118","228.67200","19.05618","0.03424"
"38166","228.96000","19.08022","0.03517"
"38214","229.24800","19.10413","0.03626"
"38262","229.53600","19.12823","0.03674"
"38310","229.82400","19.15220","0.03721"
"38358","230.11200","19.17624","0.03780"
"38406","230.40000","19.20021","0.03838"
"38454","230.68800","19.22413","0.03847"
"38502","230.97600","19.24816","0.03893"
"38550","231.26400","19.27214","0.03916"
"38598","231.55200","19.29618","0.03954"
"38646","231.84000","19.32015","0.03984"
"38694","232.12800","19.34431","0.04093"
"38742","232.41600","19.36816","0.04091"
"38790","232.70400","19.39220","0.04080"
"38838","232.99200","19.41611","0.04186"
"38886","233.28000","19.44027","0.04227"
"38934","233.56800","19.46418","0.04224"
"38982","233.85600","19.48822","0.04277"
"39030","234.14400","19.51214","0.04304"
"39078","234.43200","19.53617","0.04398"
"39126","234.72000","19.56021","0.04429"
"39174","235.00800","19.58418","0.04502"
"39222","235.29600","19.60822","0.04554"
"39270","235.58400","19.63219","0.04556"
"39318","235.87200","19.65623","0.04675"
"39366","236.16000","19.68020","0.04696"
"39414","236.44800","19.70424","0.04737"
"39462","236.73600","19.72815","0.04809"
"39510","237.02400","19.75219","0.04862"
"39558","237.31200","19.77617","0.04891"
"39606","237.60000","19.80020","0.04968"
"39654","237.88800","19.82418","0.05038"
"39702","238.17600","19.84821","0.05034"
"39750","238.46400","19.87219","0.05097"
"39798","238.75200","19.89616","0.05233"
"39846","239.04000","19.92020","0.05260"
"39894","239.32800","19.94417","0.05366"
"39942","239.61600","19.96821","0.05397"
"39990","239.90400","19.99218","0.05549"
"40038","240.19200","20.01622","0.05569"
"40086","240.48000","20.04014","0.05672"
"40134","240.76800","20.06423","0.05788"
"40182","241.05600","20.08815","0.05846"
"40230","241.34400","20.11224","0.05994"
"40278","241.63200","20.13616","0.06061"
"40326","241.92000","20.16025","0.06199"
"40374","242.20800","20.18417","0.06298"
"40422","242.49600","20.20820","0.06360"
"40470","242.78400","20.23218","0.06534"
"40518","243.07200","20.25621","0.06572"
"40566","243.36000","20.28025","0.06713"
"40614","243.64800","20.30416","0.06780"
"40662","243.93600","20.32820","0.06898"
"40710","244.22400","20.35217","0.06940"
"40758","244.51200","20.37627","0.07013"
"40806","244.80000","20.40019","0.07106"
"40854","245.08800","20.42422","0.07184"
"40902","245.37600","20.44814","0.07220"
"40950","245.66400","20.47218","0.07345"
"40998","245.95200","20.49615","0.07359"
"41046","246.24000","20.52024","0.07419"
"41094","246.52800","20.54422","0.07458"
"41142","246.81600","20.56820","0.07604"
"41190","247.10400","20.59223","0.07570"
"41238","247.39200","20.61621","0.07556"
"41286","247.68000","20.64024","0.07686"
"41334","247.96800","20.66416","0.07711"
"41382","248.25600","20.68825","0.07844"
"41430","248.54400","20.71217","0.07958"
"41478","248.83200","20.73621","0.08078"
"41526","249.12000","20.76018","0.08207"
"41574","249.40800","20.78422","0.08216"
"41622","249.69600","20.80819","0.08431"
"41670","249.98400","20.83223","0.08579"
"41718","250.27200","20.85614","0.08755"
"41766","250.56000","20.88024","0.08885"
"41814","250.84800","20.90421","0.09066"
"41862","251.13600","20.92825","0.09090"
"41910","251.42400","20.95223","0.09193"
"41958","251.71200","20.97626","0.09312"
"42006","252.00000","21.00024","0.09441"
"42054","252.28800","21.02415","0.09494"
"42102","252.57600","21.04819","0.09595"
"42150","252.86400","21.07216","0.09665"
"42198","253.15200","21.09614","0.09718"
"42246","253.44000","21.12011","0.09841"
"42294","253.72800","21.14421","0.09887"
"42342","254.01600","21.16825","0.10019"
"42390","254.30400","21.19222","0.10079"
"42438","254.59200","21.21620","0.10178"
"42486","254.88000","21.24017","0.10267"
"42534","255.16800","21.26421","0.10313"
"42582","255.45600","21.28818","0.10429"
"42630","255.74400","21.31222","0.10587"
"42678","256.03200","21.33625","0.10615"
"42726","256.32000","21.36023","0.10741"
"42774","256.60800","21.38415","0.10804"
"42822","256.89600","21.40818","0.10910"
"42870","257.18400","21.43216","0.10984"
"42918","257.47200","21.45619","0.11054"
"42966","257.76000","21.48017","0.11153"
"43014","258.04800","21.50420","0.11305"
"43062","258.33600","21.52818","0.11428"
"43110","258.62400","21.55221","0.11498"
"43158","258.91200","21.57619","0.11695"
"43206","259.20000","21.60022","0.11796"
"43254","259.48800","21.62420","0.11971"
"43302","259.77600","21.64824","0.12032"
"43350","260.06400","21.67221","0.12223"
"43398","260.35200","21.69619","0.12330"
"43446","260.64000","21.72016","0.12437"
"43494","260.92800","21.74414","0.12590"
"43542","261.21600","21.76823","0.12667"
"43590","261.50400","21.79215","0.12711"
"43638","261.79200","21.81618","0.12561"
"43686","262.08000","21.84016","0.12189"
"43734","262.36800","21.86420","0.00105"
"43782","262.65600","21.88817","0.00633"
"43830","262.94400","21.91215","0.00539"
"43878","263.23200","21.93612","0.00474"
"43926","263.52000","21.96010","0.00628"
"43974","263.80800","21.98419","0.00573"
"44022","264.09600","22.00817","0.00410"
"44070","264.38400","22.03221","0.00514"
"44118","264.67200","22.05618","0.00640"
"44166","264.96000","22.08022","0.00436"
"44214","265.24800","22.10413","0.00492"
"44262","265.53600","22.12817","0.00525"
"44310","265.82400","22.15214","0.00499"
"44358","266.11200","22.17624","0.00473"
"44406","266.40000","22.20015","0.00501"
"44454","266.68800","22.22425","0.00493"
"44502","266.97600","22.24816","0.00505"
"44550","267.26400","22.27214","0.00537"
"44598","267.55200","22.29618","0.00501"
"44646","267.84000","22.32021","0.00520"
"44694","268.12800","22.34419","0.00505"
"44742","268.41600","22.36822","0.00542"
"44790","268.70400","22.39226","0.00514"
"44838","268.99200","22.41611","0.00541"
"44886","269.28000","22.44015","0.00560"
"44934","269.56800","22.46412","0.00547"
"44982","269.85600","22.48822","0.00558"
"45030","270.14400","22.51213","0.00541"
"45078","270.43200","22.53617","0.00527"
"45126","270.72000","22.56009","0.00555"
"45174","271.00800","22.58418","0.00516"
"45222","271.29600","22.60816","0.00546"
"45270","271.58400","22.63213","0.00542"
"45318","271.87200","22.65617","0.00556"
"45366","272.16000","22.68014","0.00523"
"45414","272.44800","22.70418","0.00524"
"45462","272.73600","22.72816","0.00553"
"45510","273.02400","22.75219","0.00534"
"45558","273.31200","22.77617","0.00519"
"45606","273.60000","22.80020","0.00543"
"45654","273.88800","22.82412","0.00562"
"45702","274.17600","22.84827","0.00514"
"45750","274.46400","22.87213","0.00575"
"45798","274.75200","22.89622","0.00569"
"45846","275.04000","22.92014","0.00581"
"45894","275.32800","22.94417","0.00607"
"45942","275.61600","22.96815","0.00561"
"45990","275.90400","22.99218","0.00573"
"46038","276.19200","23.01616","0.00597"
"46086","276.48000","23.04020","0.00553"
"46134","276.76800","23.06417","0.00556"
"46182","277.05600","23.08815","0.00586"
"46230","277.34400","23.11218","0.00601"
"46278","277.63200","23.13616","0.00584"
"46326","277.92000","23.16019","0.00609"
"46374","278.20800","23.18411","0.00564"
"46422","278.49600","23.20815","0.00619"
"46470","278.78400","23.23212","0.00588"
"46518","279.07200","23.25622","0.00616"
"46566","279.36000","23.28019","0.00604"
"46614","279.64800","23.30417","0.00597"
"46662","279.93600","23.32814","0.00608"
"46710","280.22400","23.35212","0.00633"
"46758","280.51200","23.37615","0.00625"
"46806","280.80000","23.40013","0.00648"
"46854","281.08800","23.42416","0.00582"
"46902","281.37600","23.44814","0.00625"
"46950","281.66400","23.47218","0.00665"
"46998","281.95200","23.49615","0.00660"
"47046","282.24000","23.52019","0.00582"
"47094","282.52800","23.54416","0.00569"
"47142","282.81600","23.56826","0.00626"
"47190","283.10400","23.59217","0.00603"
"47238","283.39200","23.61621","0.00640"
"47286","283.68000","23.64018","0.00615"
"47334","283.96800","23.66422","0.00597"
"47382","284.25600","23.68819","0.00482"
"47430","284.54400","23.71217","0.00495"
"47478","284.83200","23.73621","0.00548"
"47526","285.12000","23.76018","0.00473"
"47574","285.40800","23.78422","0.00536"
"47622","285.69600","23.80819","0.00544"
"47670","285.98400","23.83223","0.00529"
"47718","286.27200","23.85614","0.00497"
"47766","286.56000","23.88018","0.00491"
"47814","286.84800","23.90415","0.00495"
"47862","287.13600","23.92819","0.00498"
"47910","287.42400","23.95216","0.00509"
"47958","287.71200","23.97620","0.00514"
"48006","288.00000","24.00018","0.00468"
"48054","288.28800","24.02421","0.00508"
"48102","288.57600","24.04819","0.00519"
"48150","288.86400","24.07210","0.00540"
"48198","289.15200","24.09620","0.00487"
"48246","289.44000","24.12017","0.00522"
"48294","289.72800","24.14427","0.00535"
"48342","290.01600","24.16818","0.00511"
"48390","290.30400","24.19222","0.00506"
"48438","290.59200","24.21620","0.00545"
"48486","290.88000","24.24023","0.00504"
"48534","291.16800","24.26421","0.00496"
"48582","291.45600","24.28824","0.00490"
"48630","291.74400","24.31222","0.00491"
"48678","292.03200","24.33625","0.00548"
"48726","292.32000","24.36023","0.00562"
"48774","292.60800","24.38420","0.00514"
"48822","292.89600","24.40818","0.00492"
"48870","293.18400","24.43216","0.00513"
"48918","293.47200","24.45625","0.00493"
"48966","293.76000","24.48017","0.00516"
"49014","294.04800","24.50420","0.00555"
"49062","294.33600","24.52818","0.00509"
"49110","294.62400","24.55222","0.00507"
"49158","294.91200","24.57619","0.00500"
"49206","295.20000","24.60023","0.00504"
"49254","295.48800","24.62420","0.00522"
"49302","295.77600","24.64823","0.00456"
"49350","296.06400","24.67221","0.00435"
"49398","296.35200","24.69619","0.00415"
"49446","296.64000","24.72016","0.00430"
"49494","296.92800","24.74420","0.00429"
"49542","297.21600","24.76823","0.00425"
"49590","297.50400","24.79221","0.00419"
"49638","297.79200","24.81618","0.00465"
"49686","298.08000","24.84016","0.00425"
"49734","298.36800","24.86419","0.00473"
"49782","298.65600","24.88817","0.00422"
"49830","298.94400","24.91215","0.00470"
"49878","299.23200","24.93618","0.00455"
"49926","299.52000","24.96022","0.00439"
"49974","299.80800","24.98419","0.00483"
"50022","300.09600","25.00823","0.00460"
"50070","300.38400","25.03220","0.00448"
"50118","300.67200","25.05618","0.00434"
"50166","300.96000","25.08022","0.00470"
"50214","301.24800","25.10413","0.00469"
"50262","301.53600","25.12823","0.00472"
"50310","301.82400","25.15214","0.00456"
"50358","302.11200","25.17617","0.00471"
"50406","302.40000","25.20015","0.00420"
"50454","302.68800","25.22425","0.00459"
"50502","302.97600","25.24817","0.00466"
"50550","303.26400","25.27226","0.00409"
"50598","303.55200","25.29617","0.00414"
"50646","303.84000","25.32021","0.00402"
"50694","304.12800","25.34418","0.00477"
"50742","304.41600","25.36822","0.00472"
"50790","304.70400","25.39226","0.00474"
"50838","304.99200","25.41623","0.00382"
"50886","305.28000","25.44021","0.00491"
"50934","305.56800","25.46412","0.00471"
"50982","305.85600","25.48822","0.00454"
"51030","306.14400","25.51213","0.00481"
"51078","306.43200","25.53623","0.00426"
"51126","306.72000","25.56020","0.00477"
"51174","307.00800","25.58424","0.00443"
"51222","307.29600","25.60822","0.00391"
"51270","307.58400","25.63225","0.00467"
"51318","307.87200","25.65617","0.00406"
"51366","308.16000","25.68020","0.00461"
"51414","308.44800","25.70418","0.00416"
"51462","308.73600","25.72816","0.00479"
"51510","309.02400","25.75219","0.00461"
"51558","309.31200","25.77617","0.00468"
"51606","309.60000","25.80026","0.00442"
"51654","309.88800","25.82423","0.00466"
"51702","310.17600","25.84821","0.00459"
"51750","310.46400","25.87219","0.00416"
"51798","310.75200","25.89616","0.00474"
"51846","311.04000","25.92014","0.00452"
"51894","311.32800","25.94423","0.00465"
"51942","311.61600","25.96815","0.00459"
"51990","311.90400","25.99224","0.00514"
"52038","312.19200","26.01616","0.00464"
"52086","312.48000","26.04020","0.00469"
"52134","312.76800","26.06417","0.00436"
"52182","313.05600","26.08821","0.00401"
"52230","313.34400","26.11224","0.00475"
"52278","313.63200","26.13616","0.00434"
"52326","313.92000","26.16019","0.00476"
"52374","314.20800","26.18417","0.00504"
"52422","314.49600","26.20814","0.00517"
"52470","314.78400","26.23212","0.00499"
"52518","315.07200","26.25622","0.00461"
"52566","315.36000","26.28013","0.00521"
"52614","315.64800","26.30423","0.00475"
"52662","315.93600","26.32814","0.00496"
"52710","316.22400","26.35224","0.00501"
"52758","316.51200","26.37615","0.00505"
"52806","316.80000","26.40013","0.00487"
"52854","317.08800","26.42422","0.00477"
"52902","317.37600","26.44820","0.00470"
"52950","317.66400","26.47223","0.00454"
"52998","317.95200","26.49615","0.00383"
"53046","318.24000","26.52025","0.00428"
"53094","318.52800","26.54416","0.00455"
"53142","318.81600","26.56820","0.00453"
"53190","319.10400","26.59211","0.00486"
"53238","319.39200","26.61627","0.00470"
"53286","319.68000","26.64013","0.00464"
"53334","319.96800","26.66422","0.00437"
"53382","320.25600","26.68819","0.00450"
"53430","320.54400","26.71217","0.00464"
"53478","320.83200","26.73620","0.00462"
"53526","321.12000","26.76018","0.00458"
"53574","321.40800","26.78422","0.00468"
"53622","321.69600","26.80819","0.00459"
"53670","321.98400","26.83223","0.00495"
"53718","322.27200","26.85620","0.00500"
"53766","322.56000","26.88018","0.00450"
"53814","322.84800","26.90415","0.00490"
"53862","323.13600","26.92819","0.00504"
"53910","323.42400","26.95217","0.00433"
"53958","323.71200","26.97620","0.00423"
"54006","324.00000","27.00018","0.00494"
"54054","324.28800","27.02421","0.00429"
"54102","324.57600","27.04819","0.00464"
"54150","324.86400","27.07216","0.00489"
"54198","325.15200","27.09620","0.00467"
"54246","325.44000","27.12017","0.00468"
"54294","325.72800","27.14421","0.00474"
"54342","326.01600","27.16819","0.00485"
"54390","326.30400","27.19228","0.00466"
"54438","326.59200","27.21620","0.00472"
"54486","326.88000","27.24023","0.00401"
"54534","327.16800","27.26415","0.00491"
"54582","327.45600","27.28824","0.00451"
"54630","327.74400","27.31222","0.00459"
"54678","328.03200","27.33625","0.00445"
"54726","328.32000","27.36023","0.00469"
"54774","328.60800","27.38420","0.00480"
"54822","328.89600","27.40818","0.00438"
"54870","329.18400","27.43222","0.00437"
"54918","329.47200","27.45619","0.00457"
"54966","329.76000","27.48017","0.00408"
"55014","330.04800","27.50426","0.00460"
"55062","330.33600","27.52818","0.00374"
"55110","330.62400","27.55221","0.00477"
"55158","330.91200","27.57619","0.00411"
"55206","331.20000","27.60023","0.00425"
"55254","331.48800","27.62420","0.00436"
"55302","331.77600","27.64824","0.00470"
"55350","332.06400","27.67221","0.00428"
"55398","332.35200","27.69625","0.00434"
"55446","332.64000","27.72016","0.00476"
"55494","332.92800","27.74420","0.00433"
"55542","333.21600","27.76818","0.00437"
"55590","333.50400","27.79221","0.00405"
"55638","333.79200","27.81631","0.00426"
"55686","334.08000","27.84016","0.00448"
"55734","334.36800","27.86419","0.00452"
"55782","334.65600","27.88811","0.00455"
"55830","334.94400","27.91227","0.00433"
"55878","335.23200","27.93612","0.00482"
"55926","335.52000","27.96028","0.00477"
"55974","335.80800","27.98419","0.00419"
"56022","336.09600","28.00823","0.00414"
"56070","336.38400","28.03220","0.00452"
"56118","336.67200","28.05624","0.00431"
"56166","336.96000","28.08021","0.00465"
"56214","337.24800","28.10419","0.00427"
"56262","337.53600","28.12823","0.00471"
"56310","337.82400","28.15220","0.00394"
"56358","338.11200","28.17624","0.00456"
"56406","338.40000","28.20015","0.00451"
"56454","338.68800","28.22419","0.00451"
"56502","338.97600","28.24817","0.00409"
"56550","339.26400","28.27220","0.00441"
"56598","339.55200","28.29617","0.00408"
"56646","339.84000","28.32021","0.00436"
"56694","340.12800","28.34419","0.00443"
"56742","340.41600","28.36822","0.00444"
"56790","340.70400","28.39214","0.00426"
"56838","340.99200","28.41617","0.00478"
"56886","341.28000","28.44021","0.00451"
"56934","341.56800","28.46418","0.00396"
"56982","341.85600","28.48822","0.00424"
"57030","342.14400","28.51213","0.00463"
"57078","342.43200","28.53623","0.00415"
"57126","342.72000","28.56014","0.00409"
"57174","343.00800","28.58424","0.00391"
"57222","343.29600","28.60815","0.00467"
"57270","343.58400","28.63219","0.00451"
"57318","343.87200","28.65611","0.00415"
"57366","344.16000","28.68020","0.00411"
"57414","344.44800","28.70418","0.00394"
"57462","344.73600","28.72821","0.00435"
"57510","345.02400","28.75213","0.00424"
"57558","345.31200","28.77622","0.00412"
"57606","345.60000","28.80026","0.00435"
"57654","345.88800","28.82424","0.00407"
"57702","346.17600","28.84827","0.00396"
"57750","346.46400","28.87219","0.00386"
"57798","346.75200","28.89616","0.00424"
"57846","347.04000","28.92014","0.00426"
"57894","347.32800","28.94417","0.00425"
"57942","347.61600","28.96815","0.00432"
"57990","347.90400","28.99218","0.00449"
"58038","348.19200","29.01616","0.00465"
"58086","348.48000","29.04020","0.00454"
"58134","348.76800","29.06411","0.00421"
"58182","349.05600","29.08815","0.00392"
"58230","349.34400","29.11218","0.00418"
"58278","349.63200","29.13616","0.00476"
"58326","349.92000","29.16019","0.00441"
"58374","350.20800","29.18411","0.00464"
"58422","350.49600","29.20820","0.00405"
"58470","350.78400","29.23218","0.00454"
"58518","351.07200","29.25621","0.00461"
"58566","351.36000","29.28013","0.00477"
"58614","351.64800","29.30417","0.00411"
"58662","351.93600","29.32814","0.00468"
"58710","352.22400","29.35218","0.00484"
"58758","352.51200","29.37615","0.00407"
"58806","352.80000","29.40019","0.00439"
"58854","353.08800","29.42422","0.00423"
"58902","353.37600","29.44820","0.00454"
"58950","353.66400","29.47223","0.00432"
"58998","353.95200","29.49621","0.00463"
"59046","354.24000","29.52019","0.00458"
"59094","354.52800","29.54416","0.00445"
"59142","354.81600","29.56814","0.00465"
"59190","355.10400","29.59211","0.00426"
"59238","355.39200","29.61615","0.00443"
"59277","355.62400","29.63546","0.00467"