File: Trajectories_together/161218_2Specimen_RawData_5.csv
"","V1","V2","V3"
"1","End date","12/18/2016",""
"2","Specimen label","16DG_31_run2",""
"3","Maximum Load","0.05678","N"
"4","Time","Extension","Load"
"5","(s)","(mm)","(N)"
"6","0.00000","39.39938","0.01421"
"45","0.23400","39.41619","0.01508"
"84","0.46800","39.43861","0.01572"
"123","0.70200","39.45810","0.01609"
"162","0.93600","39.47754","0.01637"
"201","1.17000","39.49702","0.01675"
"240","1.40400","39.51652","0.01743"
"279","1.63800","39.53601","0.01772"
"318","1.87200","39.55556","0.01733"
"357","2.10600","39.57499","0.01802"
"396","2.34000","39.59454","0.01867"
"435","2.57400","39.61403","0.01875"
"474","2.80800","39.63352","0.01897"
"513","3.04200","39.65302","0.01948"
"552","3.27600","39.67251","0.01922"
"591","3.51000","39.69200","0.01965"
"630","3.74400","39.71149","0.02003"
"669","3.97800","39.73098","0.02053"
"708","4.21200","39.75047","0.02032"
"747","4.44600","39.77008","0.02092"
"786","4.68000","39.78946","0.02106"
"825","4.91400","39.80901","0.02191"
"864","5.14800","39.82850","0.02207"
"903","5.38200","39.84793","0.02206"
"942","5.61600","39.86754","0.02271"
"981","5.85000","39.88697","0.02139"
"1020","6.08400","39.90652","0.02221"
"1059","6.31800","39.92601","0.02164"
"1098","6.55200","39.94551","0.02022"
"1137","6.78600","39.96500","0.02095"
"1176","7.02000","39.98449","0.02150"
"1215","7.25400","40.00404","0.02069"
"1254","7.48800","40.02341","0.02124"
"1293","7.72200","40.04308","0.02145"
"1332","7.95600","40.06246","0.01830"
"1371","8.19000","40.08195","0.01853"
"1410","8.42400","40.10150","0.01890"
"1449","8.65800","40.12099","0.01961"
"1488","8.89200","40.14054","0.01917"
"1527","9.12600","40.15997","0.02084"
"1566","9.36000","40.17946","0.01903"
"1605","9.59400","40.19902","0.01826"
"1644","9.82800","40.21850","0.01888"
"1683","10.06200","40.23800","0.01886"
"1722","10.29600","40.25754","0.01874"
"1761","10.53000","40.27704","0.01930"
"1800","10.76400","40.29653","0.01969"
"1839","10.99800","40.31602","0.01949"
"1878","11.23200","40.33545","0.01955"
"1917","11.46600","40.35506","0.02029"
"1956","11.70000","40.37444","0.02000"
"1995","11.93400","40.39399","0.01975"
"2034","12.16800","40.41354","0.01859"
"2073","12.40200","40.43297","0.01915"
"2112","12.63600","40.45252","0.01800"
"2151","12.87000","40.47195","0.01621"
"2190","13.10400","40.49150","0.01635"
"2229","13.33800","40.51100","0.01634"
"2268","13.57200","40.53049","0.01649"
"2307","13.80600","40.55004","0.01775"
"2346","14.04000","40.56953","0.01682"
"2385","14.27400","40.58902","0.01637"
"2424","14.50800","40.60846","0.01537"
"2463","14.74200","40.62800","0.01540"
"2502","14.97600","40.64750","0.01595"
"2541","15.21000","40.66704","0.01485"
"2580","15.44400","40.68648","0.01563"
"2619","15.67800","40.70597","0.01528"
"2658","15.91200","40.72552","0.01527"
"2697","16.14600","40.74495","0.01617"
"2736","16.38000","40.76450","0.01672"
"2775","16.61400","40.78399","0.01646"
"2814","16.84800","40.80355","0.01614"
"2853","17.08200","40.82304","0.01622"
"2892","17.31600","40.84253","0.01585"
"2931","17.55000","40.86202","0.01694"
"2970","17.78400","40.88151","0.01654"
"3009","18.01800","40.90100","0.01673"
"3048","18.25200","40.92049","0.01646"
"3087","18.48600","40.94005","0.01697"
"3126","18.72000","40.95948","0.01785"
"3165","18.95400","40.97903","0.01761"
"3204","19.18800","40.99852","0.01834"
"3243","19.42200","41.01801","0.01778"
"3282","19.65600","41.03750","0.01831"
"3321","19.89000","41.05693","0.01841"
"3360","20.12400","41.07655","0.01836"
"3399","20.35800","41.09597","0.01908"
"3438","20.59200","41.11547","0.01871"
"3477","20.82600","41.13502","0.01936"
"3516","21.06000","41.15451","0.01982"
"3555","21.29400","41.17400","0.02005"
"3594","21.52800","41.19349","0.02010"
"3633","21.76200","41.21298","0.02025"
"3672","21.99600","41.23248","0.02075"
"3711","22.23000","41.25208","0.02072"
"3750","22.46400","41.27145","0.02125"
"3789","22.69800","41.29101","0.02116"
"3828","22.93200","41.31056","0.02065"
"3867","23.16600","41.32994","0.02138"
"3906","23.40000","41.34954","0.02121"
"3945","23.63400","41.36898","0.02246"
"3984","23.86800","41.38853","0.02259"
"4023","24.10200","41.40796","0.02226"
"4062","24.33600","41.42751","0.02238"
"4101","24.57000","41.44700","0.02274"
"4140","24.80400","41.46649","0.02319"
"4179","25.03800","41.48604","0.02269"
"4218","25.27200","41.50547","0.02270"
"4257","25.50600","41.52503","0.02302"
"4296","25.74000","41.54452","0.02346"
"4335","25.97400","41.56401","0.02348"
"4374","26.20800","41.58344","0.02385"
"4413","26.44200","41.60299","0.02349"
"4452","26.67600","41.62254","0.02461"
"4491","26.91000","41.64191","0.02452"
"4530","27.14400","41.66153","0.02456"
"4569","27.37800","41.68095","0.02498"
"4608","27.61200","41.70057","0.02471"
"4647","27.84600","41.71999","0.02485"
"4686","28.08000","41.73949","0.02506"
"4725","28.31400","41.75898","0.02500"
"4764","28.54800","41.77853","0.02531"
"4803","28.78200","41.79802","0.02554"
"4842","29.01600","41.81746","0.02511"
"4881","29.25000","41.83701","0.02538"
"4920","29.48400","41.85650","0.02552"
"4959","29.71800","41.87605","0.02553"
"4998","29.95200","41.89554","0.02562"
"5037","30.18600","41.91497","0.02642"
"5076","30.42000","41.93453","0.02598"
"5115","30.65400","41.95390","0.02639"
"5154","30.88800","41.97351","0.02624"
"5193","31.12200","41.99294","0.02634"
"5232","31.35600","42.01255","0.02656"
"5271","31.59000","42.03198","0.02616"
"5310","31.82400","42.05153","0.02681"
"5349","32.05800","42.07103","0.02656"
"5388","32.29200","42.09051","0.02679"
"5427","32.52600","42.11001","0.02670"
"5466","32.76000","42.12944","0.02687"
"5505","32.99400","42.14905","0.02691"
"5544","33.22800","42.16848","0.02633"
"5583","33.46200","42.18803","0.02639"
"5622","33.69600","42.20752","0.02682"
"5661","33.93000","42.22695","0.02693"
"5700","34.16400","42.24657","0.02717"
"5739","34.39800","42.26594","0.02701"
"5778","34.63200","42.28549","0.02694"
"5817","34.86600","42.30498","0.02697"
"5856","35.10000","42.32447","0.02698"
"5895","35.33400","42.34402","0.02718"
"5934","35.56800","42.36352","0.02725"
"5973","35.80200","42.38295","0.02753"
"6012","36.03600","42.40250","0.02791"
"6051","36.27000","42.42205","0.02801"
"6090","36.50400","42.44148","0.02708"
"6129","36.73800","42.46103","0.02751"
"6168","36.97200","42.48046","0.02784"
"6207","37.20600","42.49995","0.02775"
"6246","37.44000","42.51950","0.02787"
"6285","37.67400","42.53894","0.02861"
"6324","37.90800","42.55849","0.02864"
"6363","38.14200","42.57792","0.02877"
"6402","38.37600","42.59747","0.02845"
"6441","38.61000","42.61702","0.02872"
"6480","38.84400","42.63651","0.02856"
"6519","39.07800","42.65601","0.02917"
"6558","39.31200","42.67550","0.02834"
"6597","39.54600","42.69499","0.02873"
"6636","39.78000","42.71448","0.02884"
"6675","40.01400","42.73409","0.02843"
"6714","40.24800","42.75346","0.02862"
"6753","40.48200","42.77301","0.02878"
"6792","40.71600","42.79251","0.02873"
"6831","40.95000","42.81200","0.02885"
"6870","41.18400","42.83155","0.02887"
"6909","41.41800","42.85092","0.02919"
"6948","41.65200","42.87047","0.02890"
"6987","41.88600","42.88996","0.02870"
"7026","42.12000","42.90952","0.02856"
"7065","42.35400","42.92900","0.02886"
"7104","42.58800","42.94855","0.02886"
"7143","42.82200","42.96805","0.02888"
"7182","43.05600","42.98748","0.02931"
"7221","43.29000","43.00703","0.02930"
"7260","43.52400","43.02646","0.02917"
"7299","43.75800","43.04607","0.02969"
"7338","43.99200","43.06550","0.03006"
"7377","44.22600","43.08500","0.03028"
"7416","44.46000","43.10448","0.02983"
"7455","44.69400","43.12398","0.03026"
"7494","44.92800","43.14352","0.02985"
"7533","45.16200","43.16296","0.03025"
"7572","45.39600","43.18245","0.02996"
"7611","45.63000","43.20200","0.02997"
"7650","45.86400","43.22149","0.03060"
"7689","46.09800","43.24093","0.03069"
"7728","46.33200","43.26053","0.03062"
"7767","46.56600","43.28003","0.03042"
"7806","46.80000","43.29946","0.03016"
"7845","47.03400","43.31901","0.03005"
"7884","47.26800","43.33850","0.03049"
"7923","47.50200","43.35806","0.03033"
"7962","47.73600","43.37743","0.03120"
"8001","47.97000","43.39698","0.03086"
"8040","48.20400","43.41653","0.03081"
"8079","48.43800","43.43596","0.03116"
"8118","48.67200","43.45551","0.03096"
"8157","48.90600","43.47494","0.03104"
"8196","49.14000","43.49456","0.03125"
"8235","49.37400","43.51398","0.03127"
"8274","49.60800","43.53348","0.03122"
"8313","49.84200","43.55302","0.03185"
"8352","50.07600","43.57246","0.03160"
"8391","50.31000","43.59201","0.03136"
"8430","50.54400","43.61145","0.03106"
"8469","50.77800","43.63105","0.03077"
"8508","51.01200","43.65042","0.03121"
"8547","51.24600","43.66998","0.03159"
"8586","51.48000","43.68946","0.03091"
"8625","51.71400","43.70896","0.03103"
"8664","51.94800","43.72851","0.03098"
"8703","52.18200","43.74794","0.03134"
"8742","52.41600","43.76749","0.03158"
"8781","52.65000","43.78698","0.03128"
"8820","52.88400","43.80654","0.03218"
"8859","53.11800","43.82603","0.03179"
"8898","53.35200","43.84552","0.03212"
"8937","53.58600","43.86501","0.03200"
"8976","53.82000","43.88450","0.03198"
"9015","54.05400","43.90399","0.03205"
"9054","54.28800","43.92343","0.03234"
"9093","54.52200","43.94304","0.03180"
"9132","54.75600","43.96247","0.03197"
"9171","54.99000","43.98201","0.03159"
"9210","55.22400","44.00157","0.03210"
"9249","55.45800","44.02094","0.02869"
"9288","55.69200","44.04055","0.02018"
"9327","55.92600","44.05998","0.02093"
"9366","56.16000","44.07954","0.02110"
"9405","56.39400","44.09896","0.01942"
"9444","56.62800","44.11852","0.02104"
"9483","56.86200","44.13801","0.02021"
"9522","57.09600","44.15750","0.02049"
"9561","57.33000","44.17705","0.02197"
"9600","57.56400","44.19642","0.02286"
"9639","57.79800","44.21603","0.02119"
"9678","58.03200","44.23547","0.02110"
"9717","58.26600","44.25507","0.02227"
"9756","58.50000","44.27451","0.02163"
"9795","58.73400","44.29400","0.02243"
"9834","58.96800","44.31355","0.02236"
"9873","59.20200","44.33292","0.02288"
"9912","59.43600","44.35253","0.02217"
"9951","59.67000","44.37197","0.02255"
"9990","59.90400","44.39151","0.02383"
"10029","60.13800","44.41101","0.02312"
"10068","60.37200","44.43050","0.02350"
"10107","60.60600","44.44999","0.02369"
"10146","60.84000","44.46948","0.02400"
"10185","61.07400","44.48898","0.02403"
"10224","61.30800","44.50846","0.02435"
"10263","61.54200","44.52802","0.02503"
"10302","61.77600","44.54751","0.02438"
"10341","62.01000","44.56706","0.02456"
"10380","62.24400","44.58655","0.02509"
"10419","62.47800","44.60598","0.02524"
"10458","62.71200","44.62553","0.02479"
"10497","62.94600","44.64491","0.02530"
"10536","63.18000","44.66452","0.02545"
"10575","63.41400","44.68401","0.02500"
"10614","63.64800","44.70350","0.02521"
"10653","63.88200","44.72299","0.02610"
"10692","64.11600","44.74249","0.02565"
"10731","64.35000","44.76203","0.02557"
"10770","64.58400","44.78152","0.02481"
"10809","64.81800","44.80101","0.02509"
"10848","65.05200","44.82044","0.02545"
"10887","65.28600","44.84000","0.02572"
"10926","65.52000","44.85949","0.02569"
"10965","65.75400","44.87904","0.02519"
"11004","65.98800","44.89859","0.02536"
"11043","66.22200","44.91796","0.02558"
"11082","66.45600","44.93751","0.02583"
"11121","66.69000","44.95695","0.02606"
"11160","66.92400","44.97649","0.02655"
"11199","67.15800","44.99599","0.02621"
"11238","67.39200","45.01548","0.02613"
"11277","67.62600","45.03503","0.02640"
"11316","67.86000","45.05452","0.02686"
"11355","68.09400","45.07402","0.02602"
"11394","68.32800","45.09351","0.02659"
"11433","68.56200","45.11300","0.02652"
"11472","68.79600","45.13249","0.02679"
"11511","69.03000","45.15204","0.02668"
"11550","69.26400","45.17147","0.02693"
"11589","69.49800","45.19096","0.02705"
"11628","69.73200","45.21051","0.02691"
"11667","69.96600","45.22995","0.02704"
"11706","70.20000","45.24950","0.02695"
"11745","70.43400","45.26899","0.02687"
"11784","70.66800","45.28848","0.02719"
"11823","70.90200","45.30803","0.02769"
"11862","71.13600","45.32752","0.02728"
"11901","71.37000","45.34701","0.02756"
"11940","71.60400","45.36644","0.02783"
"11979","71.83800","45.38600","0.02793"
"12018","72.07200","45.40543","0.02767"
"12057","72.30600","45.42504","0.02797"
"12096","72.54000","45.44447","0.02699"
"12135","72.77400","45.46402","0.02729"
"12174","73.00800","45.48351","0.02743"
"12213","73.24200","45.50301","0.02732"
"12252","73.47600","45.52256","0.02761"
"12291","73.71000","45.54193","0.02765"
"12330","73.94400","45.56148","0.02704"
"12369","74.17800","45.58097","0.02610"
"12408","74.41200","45.60052","0.02672"
"12447","74.64600","45.62001","0.02633"
"12486","74.88000","45.63950","0.02625"
"12525","75.11400","45.65899","0.02645"
"12564","75.34800","45.67849","0.02642"
"12603","75.58200","45.69804","0.02647"
"12642","75.81600","45.71747","0.02710"
"12681","76.05000","45.73702","0.02651"
"12720","76.28400","45.75645","0.02716"
"12759","76.51800","45.77607","0.02468"
"12798","76.75200","45.79550","0.02456"
"12837","76.98600","45.81498","0.02532"
"12876","77.22000","45.83454","0.02587"
"12915","77.45400","45.85397","0.02546"
"12954","77.68800","45.87346","0.02605"
"12993","77.92200","45.89301","0.02556"
"13032","78.15600","45.91251","0.02524"
"13071","78.39000","45.93200","0.02566"
"13110","78.62400","45.95155","0.02568"
"13149","78.85800","45.97098","0.02567"
"13188","79.09200","45.99047","0.02600"
"13227","79.32600","46.01002","0.02531"
"13266","79.56000","46.02951","0.02583"
"13305","79.79400","46.04906","0.02622"
"13344","80.02800","46.06843","0.02603"
"13383","80.26200","46.08798","0.02635"
"13422","80.49600","46.10748","0.02590"
"13461","80.73000","46.12697","0.02546"
"13500","80.96400","46.14651","0.02464"
"13539","81.19800","46.16595","0.02364"
"13578","81.43200","46.18550","0.02424"
"13617","81.66600","46.20499","0.02429"
"13656","81.90000","46.22454","0.02457"
"13695","82.13400","46.24397","0.02411"
"13734","82.36800","46.26353","0.02452"
"13773","82.60200","46.28301","0.02489"
"13812","82.83600","46.30245","0.02496"
"13851","83.07000","46.32206","0.02526"
"13890","83.30400","46.34150","0.02502"
"13929","83.53800","46.36105","0.02518"
"13968","83.77200","46.38054","0.02527"
"14007","84.00600","46.40002","0.02256"
"14046","84.24000","46.41952","0.02336"
"14085","84.47400","46.43895","0.02316"
"14124","84.70800","46.45850","0.02380"
"14163","84.94200","46.47793","0.02370"
"14202","85.17600","46.49748","0.02397"
"14241","85.41000","46.51698","0.02409"
"14280","85.64400","46.53653","0.02408"
"14319","85.87800","46.55602","0.02401"
"14358","86.11200","46.57545","0.02454"
"14397","86.34600","46.59500","0.02403"
"14436","86.58000","46.61443","0.02430"
"14475","86.81400","46.63404","0.02431"
"14514","87.04800","46.65347","0.02443"
"14553","87.28200","46.67297","0.02444"
"14592","87.51600","46.69251","0.02517"
"14631","87.75000","46.71194","0.02429"
"14670","87.98400","46.73150","0.02511"
"14709","88.21800","46.75099","0.02448"
"14748","88.45200","46.77054","0.02474"
"14787","88.68600","46.78997","0.02408"
"14826","88.92000","46.80946","0.02403"
"14865","89.15400","46.82896","0.02450"
"14904","89.38800","46.84851","0.02346"
"14943","89.62200","46.86800","0.02367"
"14982","89.85600","46.88749","0.02462"
"15021","90.09000","46.90704","0.02413"
"15060","90.32400","46.92641","0.02452"
"15099","90.55800","46.94609","0.02491"
"15138","90.79200","46.96546","0.02497"
"15177","91.02600","46.98500","0.02463"
"15216","91.26000","47.00456","0.02536"
"15255","91.49400","47.02393","0.02554"
"15294","91.72800","47.04354","0.02472"
"15333","91.96200","47.06297","0.01997"
"15372","92.19600","47.08252","0.02140"
"15411","92.43000","47.10201","0.02143"
"15450","92.66400","47.12144","0.02208"
"15489","92.89800","47.14100","0.02259"
"15528","93.13200","47.16049","0.02274"
"15567","93.36600","47.18004","0.02290"
"15606","93.60000","47.19947","0.02325"
"15645","93.83400","47.21902","0.02384"
"15684","94.06800","47.23851","0.02379"
"15723","94.30200","47.25801","0.02409"
"15762","94.53600","47.27750","0.02413"
"15801","94.77000","47.29699","0.02446"
"15840","95.00400","47.31654","0.02447"
"15879","95.23800","47.33591","0.02435"
"15918","95.47200","47.35546","0.02447"
"15957","95.70600","47.37502","0.02367"
"15996","95.94000","47.39456","0.02453"
"16035","96.17400","47.41400","0.02494"
"16074","96.40800","47.43349","0.02509"
"16113","96.64200","47.45304","0.02479"
"16152","96.87600","47.47247","0.02554"
"16191","97.11000","47.49196","0.02496"
"16230","97.34400","47.51146","0.02538"
"16269","97.57800","47.53100","0.02573"
"16308","97.81200","47.55050","0.02568"
"16347","98.04600","47.56999","0.02561"
"16386","98.28000","47.58954","0.02604"
"16425","98.51400","47.60897","0.02633"
"16464","98.74800","47.62852","0.02601"
"16503","98.98200","47.64795","0.02625"
"16542","99.21600","47.66751","0.02655"
"16581","99.45000","47.68699","0.02632"
"16620","99.68400","47.70649","0.02481"
"16659","99.91800","47.72604","0.02530"
"16698","100.15200","47.74553","0.02527"
"16737","100.38600","47.76502","0.02500"
"16776","100.62000","47.78439","0.02547"
"16815","100.85400","47.80406","0.02503"
"16854","101.08800","47.82349","0.02554"
"16893","101.32200","47.84299","0.02585"
"16932","101.55600","47.86248","0.02627"
"16971","101.79000","47.88197","0.02559"
"17010","102.02400","47.90152","0.02590"
"17049","102.25800","47.92095","0.02629"
"17088","102.49200","47.94050","0.02618"
"17127","102.72600","47.95999","0.02556"
"17166","102.96000","47.97948","0.02618"
"17205","103.19400","47.99898","0.02660"
"17244","103.42800","48.01853","0.02586"
"17283","103.66200","48.03802","0.02612"
"17322","103.89600","48.05751","0.02591"
"17361","104.13000","48.07700","0.02617"
"17400","104.36400","48.09644","0.02594"
"17439","104.59800","48.11604","0.02668"
"17478","104.83200","48.13548","0.02704"
"17517","105.06600","48.15503","0.02670"
"17556","105.30000","48.17446","0.02669"
"17595","105.53400","48.19401","0.02656"
"17634","105.76800","48.21350","0.02664"
"17673","106.00200","48.23294","0.02605"
"17712","106.23600","48.25249","0.02621"
"17751","106.47000","48.27198","0.02612"
"17790","106.70400","48.29153","0.02653"
"17829","106.93800","48.31096","0.02636"
"17868","107.17200","48.33051","0.02687"
"17907","107.40600","48.35000","0.02655"
"17946","107.64000","48.36949","0.02700"
"17985","107.87400","48.38899","0.02677"
"18024","108.10800","48.40842","0.02664"
"18063","108.34200","48.42803","0.02716"
"18102","108.57600","48.44746","0.02721"
"18141","108.81000","48.46701","0.02729"
"18180","109.04400","48.48650","0.02747"
"18219","109.27800","48.50600","0.02748"
"18258","109.51200","48.52548","0.02715"
"18297","109.74600","48.54497","0.02741"
"18336","109.98000","48.56452","0.02749"
"18375","110.21400","48.58402","0.02756"
"18414","110.44800","48.60351","0.02754"
"18453","110.68200","48.62300","0.02286"
"18492","110.91600","48.64255","0.02353"
"18531","111.15000","48.66204","0.02410"
"18570","111.38400","48.68148","0.02445"
"18609","111.61800","48.70103","0.02455"
"18648","111.85200","48.72046","0.02482"
"18687","112.08600","48.74001","0.02547"
"18726","112.32000","48.75950","0.02509"
"18765","112.55400","48.77899","0.02551"
"18804","112.78800","48.79848","0.02541"
"18843","113.02200","48.81797","0.02579"
"18882","113.25600","48.83753","0.02577"
"18921","113.49000","48.85696","0.02619"
"18960","113.72400","48.87651","0.02578"
"18999","113.95800","48.89600","0.02600"
"19038","114.19200","48.91555","0.02609"
"19077","114.42600","48.93499","0.02562"
"19116","114.66000","48.95447","0.02593"
"19155","114.89400","48.97403","0.02618"
"19194","115.12800","48.99345","0.02630"
"19233","115.36200","49.01307","0.02658"
"19272","115.59600","49.03244","0.02664"
"19311","115.83000","49.05205","0.02633"
"19350","116.06400","49.07154","0.02670"
"19389","116.29800","49.09097","0.02668"
"19428","116.53200","49.11052","0.02676"
"19467","116.76600","49.12996","0.02697"
"19506","117.00000","49.14957","0.02684"
"19545","117.23400","49.16894","0.02661"
"19584","117.46800","49.18855","0.02716"
"19623","117.70200","49.20805","0.02704"
"19662","117.93600","49.22753","0.02695"
"19701","118.17000","49.24702","0.02716"
"19740","118.40400","49.26646","0.02721"
"19779","118.63800","49.28600","0.02773"
"19818","118.87200","49.30544","0.02731"
"19857","119.10600","49.32505","0.02714"
"19896","119.34000","49.34448","0.02745"
"19935","119.57400","49.36403","0.02734"
"19974","119.80800","49.38353","0.02773"
"20013","120.04200","49.40295","0.02764"
"20052","120.27600","49.42257","0.02772"
"20091","120.51000","49.44194","0.02716"
"20130","120.74400","49.46149","0.02738"
"20169","120.97800","49.48092","0.02758"
"20208","121.21200","49.50053","0.02722"
"20247","121.44600","49.51996","0.02783"
"20286","121.68000","49.53951","0.02765"
"20325","121.91400","49.55901","0.02748"
"20364","122.14800","49.57850","0.02750"
"20403","122.38200","49.59805","0.02720"
"20442","122.61600","49.61748","0.02747"
"20481","122.85000","49.63709","0.02752"
"20520","123.08400","49.65646","0.02786"
"20559","123.31800","49.67602","0.02816"
"20598","123.55200","49.69550","0.02803"
"20637","123.78600","49.71500","0.02830"
"20676","124.02000","49.73455","0.02812"
"20715","124.25400","49.75398","0.02792"
"20754","124.48800","49.77353","0.02819"
"20793","124.72200","49.79296","0.02805"
"20832","124.95600","49.81252","0.02765"
"20871","125.19000","49.83200","0.02825"
"20910","125.42400","49.85150","0.02803"
"20949","125.65800","49.87105","0.02825"
"20988","125.89200","49.89048","0.02866"
"21027","126.12600","49.91003","0.02911"
"21066","126.36000","49.92946","0.02838"
"21105","126.59400","49.94907","0.02813"
"21144","126.82800","49.96851","0.02823"
"21183","127.06200","49.98794","0.02834"
"21222","127.29600","50.00755","0.02855"
"21261","127.53000","50.02692","0.02884"
"21300","127.76400","50.04647","0.02895"
"21339","127.99800","50.06596","0.02901"
"21378","128.23200","50.08551","0.02901"
"21417","128.46600","50.10501","0.02903"
"21456","128.70000","50.12449","0.02942"
"21495","128.93400","50.14399","0.02873"
"21534","129.16800","50.16348","0.02859"
"21573","129.40200","50.18303","0.02886"
"21612","129.63600","50.20246","0.02857"
"21651","129.87000","50.22201","0.02849"
"21690","130.10400","50.24150","0.02873"
"21729","130.33800","50.26100","0.02907"
"21768","130.57200","50.28054","0.02896"
"21807","130.80600","50.29992","0.02893"
"21846","131.04000","50.31947","0.02913"
"21885","131.27400","50.33896","0.02924"
"21924","131.50800","50.35846","0.02943"
"21963","131.74200","50.37800","0.02887"
"22002","131.97600","50.39750","0.02884"
"22041","132.21000","50.41698","0.02914"
"22080","132.44400","50.43648","0.02902"
"22119","132.67800","50.45603","0.02981"
"22158","132.91200","50.47546","0.02837"
"22197","133.14600","50.49501","0.02866"
"22236","133.38000","50.51445","0.02846"
"22275","133.61400","50.53405","0.02821"
"22314","133.84800","50.55349","0.02856"
"22353","134.08200","50.57298","0.02929"
"22392","134.31600","50.59253","0.02877"
"22431","134.55000","50.61196","0.02912"
"22470","134.78400","50.63157","0.02888"
"22509","135.01800","50.65100","0.02929"
"22548","135.25200","50.67050","0.02920"
"22587","135.48600","50.68999","0.02968"
"22626","135.72000","50.70948","0.03014"
"22665","135.95400","50.72897","0.02989"
"22704","136.18800","50.74846","0.02958"
"22743","136.42200","50.76801","0.03024"
"22782","136.65600","50.78744","0.03034"
"22821","136.89000","50.80706","0.02920"
"22860","137.12400","50.82648","0.02955"
"22899","137.35800","50.84604","0.02940"
"22938","137.59200","50.86552","0.02948"
"22977","137.82600","50.88502","0.02935"
"23016","138.06000","50.90457","0.02957"
"23055","138.29400","50.92400","0.02926"
"23094","138.52800","50.94349","0.02946"
"23133","138.76200","50.96298","0.02913"
"23172","138.99600","50.98254","0.02970"
"23211","139.23000","51.00196","0.02954"
"23250","139.46400","51.02152","0.02961"
"23289","139.69800","51.04101","0.02911"
"23328","139.93200","51.06044","0.02962"
"23367","140.16600","51.07999","0.02967"
"23406","140.40000","51.09949","0.02914"
"23445","140.63400","51.11897","0.02910"
"23484","140.86800","51.13847","0.02866"
"23523","141.10200","51.15802","0.02846"
"23562","141.33600","51.17751","0.02886"
"23601","141.57000","51.19700","0.02899"
"23640","141.80400","51.21655","0.02890"
"23679","142.03800","51.23598","0.02927"
"23718","142.27200","51.25547","0.02966"
"23757","142.50600","51.27497","0.02993"
"23796","142.74000","51.29452","0.02984"
"23835","142.97400","51.31401","0.02955"
"23874","143.20800","51.33356","0.02899"
"23913","143.44200","51.35299","0.02925"
"23952","143.67600","51.37243","0.02917"
"23991","143.91000","51.39204","0.02894"
"24030","144.14400","51.41146","0.02892"
"24069","144.37800","51.43102","0.02910"
"24108","144.61200","51.45045","0.02931"
"24147","144.84600","51.47000","0.02777"
"24186","145.08000","51.48949","0.02853"
"24225","145.31400","51.50898","0.02892"
"24264","145.54800","51.52853","0.02865"
"24303","145.78200","51.54796","0.02840"
"24342","146.01600","51.56752","0.02858"
"24381","146.25000","51.58694","0.02864"
"24420","146.48400","51.60656","0.02844"
"24459","146.71800","51.62599","0.02860"
"24498","146.95200","51.64548","0.02883"
"24537","147.18600","51.66497","0.02838"
"24576","147.42000","51.68440","0.02867"
"24615","147.65400","51.70408","0.02910"
"24654","147.88800","51.72345","0.02933"
"24693","148.12200","51.74300","0.02937"
"24732","148.35600","51.76255","0.02899"
"24771","148.59000","51.78198","0.02913"
"24810","148.82400","51.80147","0.02954"
"24849","149.05800","51.82097","0.02946"
"24888","149.29200","51.84052","0.02914"
"24927","149.52600","51.86001","0.02972"
"24966","149.76000","51.87949","0.02871"
"25005","149.99400","51.89899","0.02850"
"25044","150.22800","51.91854","0.02845"
"25083","150.46200","51.93798","0.02886"
"25122","150.69600","51.95746","0.02876"
"25161","150.93000","51.97702","0.02823"
"25200","151.16400","51.99645","0.02822"
"25239","151.39800","52.01606","0.02838"
"25278","151.63200","52.03549","0.02800"
"25317","151.86600","52.05504","0.02854"
"25356","152.10000","52.07459","0.02894"
"25395","152.33400","52.09396","0.02944"
"25434","152.56800","52.11351","0.02875"
"25473","152.80200","52.13295","0.02915"
"25512","153.03600","52.15255","0.02912"
"25551","153.27000","52.17193","0.02932"
"25590","153.50400","52.19148","0.02892"
"25629","153.73800","52.21097","0.02936"
"25668","153.97200","52.23053","0.02942"
"25707","154.20600","52.25001","0.02892"
"25746","154.44000","52.26951","0.02907"
"25785","154.67400","52.28905","0.02937"
"25824","154.90800","52.30848","0.02932"
"25863","155.14200","52.32804","0.02939"
"25902","155.37600","52.34747","0.02936"
"25941","155.61000","52.36697","0.02942"
"25980","155.84400","52.38652","0.02798"
"26019","156.07800","52.40594","0.02784"
"26058","156.31200","52.42549","0.02824"
"26097","156.54600","52.44499","0.02893"
"26136","156.78000","52.46454","0.02869"
"26175","157.01400","52.48397","0.02916"
"26214","157.24800","52.50352","0.02885"
"26253","157.48200","52.52295","0.02886"
"26292","157.71600","52.54250","0.02936"
"26331","157.95000","52.56200","0.02928"
"26370","158.18400","52.58149","0.02896"
"26409","158.41800","52.60104","0.02907"
"26448","158.65200","52.62047","0.02934"
"26487","158.88600","52.64003","0.02935"
"26526","159.12000","52.65957","0.02942"
"26565","159.35400","52.67894","0.02900"
"26604","159.58800","52.69855","0.02928"
"26643","159.82200","52.71798","0.02979"
"26682","160.05600","52.73754","0.02936"
"26721","160.29000","52.75691","0.02959"
"26760","160.52400","52.77658","0.02966"
"26799","160.75800","52.79601","0.03041"
"26838","160.99200","52.81551","0.03080"
"26877","161.22600","52.83499","0.03085"
"26916","161.46000","52.85449","0.03064"
"26955","161.69400","52.87403","0.03077"
"26994","161.92800","52.89347","0.03119"
"27033","162.16200","52.91302","0.03113"
"27072","162.39600","52.93251","0.03135"
"27111","162.63000","52.95206","0.03023"
"27150","162.86400","52.97156","0.03068"
"27189","163.09800","52.99093","0.03064"
"27228","163.33200","53.01048","0.03135"
"27267","163.56600","53.03003","0.03132"
"27306","163.80000","53.04946","0.03172"
"27345","164.03400","53.06895","0.03146"
"27384","164.26800","53.08850","0.03032"
"27423","164.50200","53.10799","0.02820"
"27462","164.73600","53.12748","0.02902"
"27501","164.97000","53.14697","0.02924"
"27540","165.20400","53.16647","0.02963"
"27579","165.43800","53.18608","0.02976"
"27618","165.67200","53.20545","0.03015"
"27657","165.90600","53.22506","0.03018"
"27696","166.14000","53.24450","0.03013"
"27735","166.37400","53.26398","0.03059"
"27774","166.60800","53.28348","0.03079"
"27813","166.84200","53.30297","0.03059"
"27852","167.07600","53.32252","0.03068"
"27891","167.31000","53.34201","0.03097"
"27930","167.54400","53.36150","0.03078"
"27969","167.77800","53.38093","0.03123"
"28008","168.01200","53.40055","0.03117"
"28047","168.24600","53.41998","0.03161"
"28086","168.48000","53.43947","0.03150"
"28125","168.71400","53.45901","0.03174"
"28164","168.94800","53.47845","0.03156"
"28203","169.18200","53.49806","0.03171"
"28242","169.41600","53.51743","0.03148"
"28281","169.65000","53.53704","0.03139"
"28320","169.88400","53.55647","0.03210"
"28359","170.11800","53.57603","0.03161"
"28398","170.35200","53.59552","0.03186"
"28437","170.58600","53.61495","0.03138"
"28476","170.82000","53.63450","0.03159"
"28515","171.05400","53.65399","0.03191"
"28554","171.28800","53.67348","0.03175"
"28593","171.52200","53.69298","0.03197"
"28632","171.75600","53.71252","0.03171"
"28671","171.99000","53.73202","0.03247"
"28710","172.22400","53.75151","0.03217"
"28749","172.45800","53.77106","0.03175"
"28788","172.69200","53.79037","0.03208"
"28827","172.92600","53.81004","0.03206"
"28866","173.16000","53.82953","0.03200"
"28905","173.39400","53.84903","0.03289"
"28944","173.62800","53.86846","0.03267"
"28983","173.86200","53.88794","0.03291"
"29022","174.09600","53.90750","0.03276"
"29061","174.33000","53.92699","0.03254"
"29100","174.56400","53.94648","0.03292"
"29139","174.79800","53.96597","0.03295"
"29178","175.03200","53.98552","0.03225"
"29217","175.26600","54.00496","0.03222"
"29256","175.50000","54.02451","0.03289"
"29295","175.73400","54.04400","0.03270"
"29334","175.96800","54.06343","0.03113"
"29373","176.20200","54.08304","0.03148"
"29412","176.43600","54.10247","0.03190"
"29451","176.67000","54.12202","0.03224"
"29490","176.90400","54.14151","0.03228"
"29529","177.13800","54.16101","0.03208"
"29568","177.37200","54.18050","0.03249"
"29607","177.60600","54.19993","0.03248"
"29646","177.84000","54.21954","0.03288"
"29685","178.07400","54.23898","0.03250"
"29724","178.30800","54.25852","0.03335"
"29763","178.54200","54.27796","0.03226"
"29802","178.77600","54.29750","0.03281"
"29841","179.01000","54.31694","0.03313"
"29880","179.24400","54.33643","0.03365"
"29919","179.47800","54.35604","0.03350"
"29958","179.71200","54.37541","0.03389"
"29997","179.94600","54.39502","0.03423"
"30036","180.18000","54.41446","0.03328"
"30075","180.41400","54.43401","0.03364"
"30114","180.64800","54.45356","0.03365"
"30153","180.88200","54.47299","0.03376"
"30192","181.11600","54.49254","0.03402"
"30231","181.35000","54.51197","0.03429"
"30270","181.58400","54.53152","0.03417"
"30309","181.81800","54.55095","0.03130"
"30348","182.05200","54.57051","0.03101"
"30387","182.28600","54.58999","0.03126"
"30426","182.52000","54.60949","0.03141"
"30465","182.75400","54.62898","0.03145"
"30504","182.98800","54.64853","0.03161"
"30543","183.22200","54.66802","0.03157"
"30582","183.45600","54.68739","0.03169"
"30621","183.69000","54.70700","0.03184"
"30660","183.92400","54.72650","0.03254"
"30699","184.15800","54.74599","0.03236"
"30738","184.39200","54.76554","0.03263"
"30777","184.62600","54.78497","0.03224"
"30816","184.86000","54.80452","0.03298"
"30855","185.09400","54.82395","0.03263"
"30894","185.32800","54.84351","0.03291"
"30933","185.56200","54.86294","0.03318"
"30972","185.79600","54.88255","0.03363"
"31011","186.03000","54.90198","0.03368"
"31050","186.26400","54.92153","0.03389"
"31089","186.49800","54.94102","0.03384"
"31128","186.73200","54.96046","0.03382"
"31167","186.96600","54.98006","0.03384"
"31206","187.20000","54.99950","0.03301"
"31245","187.43400","55.01904","0.03373"
"31284","187.66800","55.03848","0.03387"
"31323","187.90200","55.05797","0.03358"
"31362","188.13600","55.07752","0.03356"
"31401","188.37000","55.09695","0.03400"
"31440","188.60400","55.11650","0.03460"
"31479","188.83800","55.13599","0.03374"
"31518","189.07200","55.15555","0.03467"
"31557","189.30600","55.17498","0.03473"
"31596","189.54000","55.19453","0.03512"
"31635","189.77400","55.21402","0.03497"
"31674","190.00800","55.23345","0.03526"
"31713","190.24200","55.25300","0.03532"
"31752","190.47600","55.27243","0.03539"
"31791","190.71000","55.29205","0.03467"
"31830","190.94400","55.31147","0.03411"
"31869","191.17800","55.33103","0.03378"
"31908","191.41200","55.35052","0.03420"
"31947","191.64600","55.37001","0.03376"
"31986","191.88000","55.38950","0.03215"
"32025","192.11400","55.40900","0.03106"
"32064","192.34800","55.42848","0.03129"
"32103","192.58200","55.44798","0.03171"
"32142","192.81600","55.46753","0.03256"
"32181","193.05000","55.48702","0.03291"
"32220","193.28400","55.50651","0.03278"
"32259","193.51800","55.52600","0.03318"
"32298","193.75200","55.54549","0.03295"
"32337","193.98600","55.56505","0.03311"
"32376","194.22000","55.58442","0.03320"
"32415","194.45400","55.60403","0.03379"
"32454","194.68800","55.62346","0.03397"
"32493","194.92200","55.64301","0.03377"
"32532","195.15600","55.66256","0.03421"
"32571","195.39000","55.68199","0.03433"
"32610","195.62400","55.70149","0.03432"
"32649","195.85800","55.72097","0.03491"
"32688","196.09200","55.74053","0.03512"
"32727","196.32600","55.75996","0.03569"
"32766","196.56000","55.77951","0.03566"
"32805","196.79400","55.79900","0.03522"
"32844","197.02800","55.81849","0.03562"
"32883","197.26200","55.83799","0.03581"
"32922","197.49600","55.85747","0.03613"
"32961","197.73000","55.87703","0.03626"
"33000","197.96400","55.89646","0.03604"
"33039","198.19800","55.91601","0.03671"
"33078","198.43200","55.93550","0.03642"
"33117","198.66600","55.95499","0.03626"
"33156","198.90000","55.97448","0.03644"
"33195","199.13400","55.99398","0.03655"
"33234","199.36800","56.01352","0.03685"
"33273","199.60200","56.03302","0.03767"
"33312","199.83600","56.05251","0.03804"
"33351","200.07000","56.07200","0.03796"
"33390","200.30400","56.09155","0.03775"
"33429","200.53800","56.11098","0.03807"
"33468","200.77200","56.13048","0.03808"
"33507","201.00600","56.15003","0.03799"
"33546","201.24000","56.16946","0.03805"
"33585","201.47400","56.18901","0.03843"
"33624","201.70800","56.20844","0.03801"
"33663","201.94200","56.22805","0.03893"
"33702","202.17600","56.24748","0.03849"
"33741","202.41000","56.26703","0.03891"
"33780","202.64400","56.28653","0.03905"
"33819","202.87800","56.30602","0.03829"
"33858","203.11200","56.32551","0.03864"
"33897","203.34600","56.34494","0.03949"
"33936","203.58000","56.36455","0.03936"
"33975","203.81400","56.38398","0.04010"
"34014","204.04800","56.40354","0.03417"
"34053","204.28200","56.42297","0.03405"
"34092","204.51600","56.44246","0.03674"
"34131","204.75000","56.46206","0.03613"
"34170","204.98400","56.48144","0.03671"
"34209","205.21800","56.50099","0.03646"
"34248","205.45200","56.52048","0.03799"
"34287","205.68600","56.54004","0.03766"
"34326","205.92000","56.55952","0.03813"
"34365","206.15400","56.57902","0.03814"
"34404","206.38800","56.59857","0.03948"
"34443","206.62200","56.61800","0.03933"
"34482","206.85600","56.63749","0.03925"
"34521","207.09000","56.65692","0.04004"
"34560","207.32400","56.67653","0.03883"
"34599","207.55800","56.69596","0.03863"
"34638","207.79200","56.71552","0.03851"
"34677","208.02600","56.73495","0.03885"
"34716","208.26000","56.75444","0.03671"
"34755","208.49400","56.77405","0.03736"
"34794","208.72800","56.79348","0.03788"
"34833","208.96200","56.81303","0.03679"
"34872","209.19600","56.83253","0.03705"
"34911","209.43000","56.85201","0.03709"
"34950","209.66400","56.87151","0.03746"
"34989","209.89800","56.89100","0.03728"
"35028","210.13200","56.91055","0.03756"
"35067","210.36600","56.92998","0.03829"
"35106","210.60000","56.94947","0.03809"
"35145","210.83400","56.96896","0.03837"
"35184","211.06800","56.98857","0.03878"
"35223","211.30200","57.00795","0.03849"
"35262","211.53600","57.02750","0.03948"
"35301","211.77000","57.04705","0.03648"
"35340","212.00400","57.06642","0.03661"
"35379","212.23800","57.08609","0.03802"
"35418","212.47200","57.10546","0.03847"
"35457","212.70600","57.12502","0.03864"
"35496","212.94000","57.14457","0.03910"
"35535","213.17400","57.16400","0.03934"
"35574","213.40800","57.18349","0.03878"
"35613","213.64200","57.20298","0.03616"
"35652","213.87600","57.22253","0.03683"
"35691","214.11000","57.24196","0.03776"
"35730","214.34400","57.26157","0.03781"
"35769","214.57800","57.28094","0.03796"
"35808","214.81200","57.30055","0.03782"
"35847","215.04600","57.31998","0.03803"
"35886","215.28000","57.33948","0.03863"
"35925","215.51400","57.35903","0.03922"
"35964","215.74800","57.37840","0.03957"
"36003","215.98200","57.39801","0.03957"
"36042","216.21600","57.41750","0.04000"
"36081","216.45000","57.43700","0.04065"
"36120","216.68400","57.45655","0.04046"
"36159","216.91800","57.47598","0.04175"
"36198","217.15200","57.49553","0.04137"
"36237","217.38600","57.51496","0.04112"
"36276","217.62000","57.53452","0.04139"
"36315","217.85400","57.55395","0.04154"
"36354","218.08800","57.57350","0.04112"
"36393","218.32200","57.59293","0.04180"
"36432","218.55600","57.61248","0.04236"
"36471","218.79000","57.63203","0.04234"
"36510","219.02400","57.65146","0.04265"
"36549","219.25800","57.67101","0.04319"
"36588","219.49200","57.69044","0.04246"
"36627","219.72600","57.71006","0.04158"
"36666","219.96000","57.72948","0.04182"
"36705","220.19400","57.74898","0.04176"
"36744","220.42800","57.76847","0.04236"
"36783","220.66200","57.78796","0.04273"
"36822","220.89600","57.80751","0.04337"
"36861","221.13000","57.82694","0.04327"
"36900","221.36400","57.84655","0.04385"
"36939","221.59800","57.86599","0.04423"
"36978","221.83200","57.88548","0.04389"
"37017","222.06600","57.90496","0.04387"
"37056","222.30000","57.92446","0.04447"
"37095","222.53400","57.94407","0.04441"
"37134","222.76800","57.96345","0.04302"
"37173","223.00200","57.98299","0.04294"
"37212","223.23600","58.00249","0.04371"
"37251","223.47000","58.02203","0.04378"
"37290","223.70400","58.04153","0.04382"
"37329","223.93800","58.06096","0.04437"
"37368","224.17200","58.08051","0.04511"
"37407","224.40600","58.10006","0.04452"
"37446","224.64000","58.11949","0.04322"
"37485","224.87400","58.13893","0.04365"
"37524","225.10800","58.15854","0.04333"
"37563","225.34200","58.17797","0.04383"
"37602","225.57600","58.19752","0.04370"
"37641","225.81000","58.21701","0.04437"
"37680","226.04400","58.23650","0.04450"
"37719","226.27800","58.25605","0.04427"
"37758","226.51200","58.27542","0.04491"
"37797","226.74600","58.29498","0.04527"
"37836","226.98000","58.31446","0.04542"
"37875","227.21400","58.33402","0.04581"
"37914","227.44800","58.35350","0.04582"
"37953","227.68200","58.37300","0.04603"
"37992","227.91600","58.39249","0.04613"
"38031","228.15000","58.41199","0.04689"
"38070","228.38400","58.43148","0.04693"
"38109","228.61800","58.45096","0.04664"
"38148","228.85200","58.47058","0.04681"
"38187","229.08600","58.49001","0.04721"
"38226","229.32000","58.50950","0.04708"
"38265","229.55400","58.52905","0.04770"
"38304","229.78800","58.54842","0.04764"
"38343","230.02200","58.56810","0.04814"
"38382","230.25600","58.58747","0.04838"
"38421","230.49000","58.60702","0.04833"
"38460","230.72400","58.62645","0.04865"
"38499","230.95800","58.64600","0.04891"
"38538","231.19200","58.66549","0.04893"
"38577","231.42600","58.68498","0.04897"
"38616","231.66000","58.70454","0.04924"
"38655","231.89400","58.72397","0.04915"
"38694","232.12800","58.74352","0.04840"
"38733","232.36200","58.76295","0.04919"
"38772","232.59600","58.78256","0.04938"
"38811","232.83000","58.80199","0.04977"
"38850","233.06400","58.82148","0.04927"
"38889","233.29800","58.84103","0.05014"
"38928","233.53200","58.86046","0.05033"
"38967","233.76600","58.88002","0.05101"
"39006","234.00000","58.89951","0.05082"
"39045","234.23400","58.91900","0.05174"
"39084","234.46800","58.93849","0.05178"
"39123","234.70200","58.95798","0.05209"
"39162","234.93600","58.97747","0.05243"
"39201","235.17000","58.99703","0.05290"
"39240","235.40400","59.01646","0.05128"
"39279","235.63800","59.03601","0.05150"
"39318","235.87200","59.05556","0.05111"
"39357","236.10600","59.07493","0.05109"
"39396","236.34000","59.09454","0.05158"
"39435","236.57400","59.11397","0.05219"
"39474","236.80800","59.13353","0.05158"
"39513","237.04200","59.15301","0.05214"
"39552","237.27600","59.17239","0.05203"
"39591","237.51000","59.19199","0.05184"
"39630","237.74400","59.21149","0.05185"
"39669","237.97800","59.23104","0.05262"
"39708","238.21200","59.25053","0.05304"
"39747","238.44600","59.27002","0.05313"
"39786","238.68000","59.28952","0.05320"
"39825","238.91400","59.30901","0.05357"
"39864","239.14800","59.32850","0.05395"
"39903","239.38200","59.34799","0.05363"
"39942","239.61600","59.36754","0.05379"
"39981","239.85000","59.38697","0.05337"
"40020","240.08400","59.40652","0.05322"
"40059","240.31800","59.42602","0.05324"
"40098","240.55200","59.44545","0.05389"
"40137","240.78600","59.46506","0.05258"
"40176","241.02000","59.48443","0.04955"
"40215","241.25400","59.50398","0.05056"
"40254","241.48800","59.52347","0.04909"
"40293","241.72200","59.54303","0.05025"
"40332","241.95600","59.56251","0.04855"
"40371","242.19000","59.58200","0.04910"
"40410","242.42400","59.60155","0.04977"
"40449","242.65800","59.62099","0.05024"
"40488","242.89200","59.64048","0.05050"
"40527","243.12600","59.65997","0.05074"
"40566","243.36000","59.67952","0.05114"
"40605","243.59400","59.69895","0.05173"
"40644","243.82800","59.71851","0.05146"
"40683","244.06200","59.73806","0.05162"
"40722","244.29600","59.75743","0.05210"
"40761","244.53000","59.77703","0.05226"
"40800","244.76400","59.79647","0.05215"
"40839","244.99800","59.81609","0.05204"
"40878","245.23200","59.83558","0.05156"
"40917","245.46600","59.85500","0.05207"
"40956","245.70000","59.87450","0.05221"
"40995","245.93400","59.89393","0.05235"
"41034","246.16800","59.91354","0.05373"
"41073","246.40200","59.93297","0.05371"
"41112","246.63600","59.95252","0.05311"
"41151","246.87000","59.97202","0.05342"
"41190","247.10400","59.99156","0.05379"
"41229","247.33800","60.01099","0.05395"
"41268","247.57200","60.03049","0.05453"
"41307","247.80600","60.04998","0.05401"
"41346","248.04000","60.06941","0.05414"
"41385","248.27400","60.08896","0.05470"
"41424","248.50800","60.10851","0.05461"
"41463","248.74200","60.12800","0.05496"
"41502","248.97600","60.14755","0.05543"
"41541","249.21000","60.16698","0.05556"
"41580","249.44400","60.18653","0.05578"
"41619","249.67800","60.20597","0.05601"
"41658","249.91200","60.22552","0.05658"
"41697","250.14600","60.24495","0.05614"
"41736","250.38000","60.26456","0.05531"
"41775","250.61400","60.28399","0.05543"
"41814","250.84800","60.30349","0.05571"
"41853","251.08200","60.32303","0.05576"
"41892","251.31600","60.34247","0.05610"
"41931","251.55000","60.36202","0.02905"
"41970","251.78400","60.38151","0.02895"
"42009","252.01800","60.40106","0.02020"
"42048","252.25200","60.42049","0.01469"
"42087","252.48600","60.43998","0.02296"
"42126","252.72000","60.45948","0.01729"
"42165","252.95400","60.47903","0.02280"
"42204","253.18800","60.49852","0.02240"
"42243","253.42200","60.51795","0.01794"
"42282","253.65600","60.53750","0.02389"
"42321","253.89000","60.55700","0.02012"
"42360","254.12400","60.57654","0.02171"
"42399","254.35800","60.59598","0.02302"
"42438","254.59200","60.61546","0.01997"
"42477","254.82600","60.63502","0.02411"
"42516","255.06000","60.65439","0.02127"
"42555","255.29400","60.67406","0.02334"
"42594","255.52800","60.69344","0.02370"
"42633","255.76200","60.71305","0.02234"
"42672","255.99600","60.73253","0.02471"
"42711","256.23000","60.75196","0.02255"
"42750","256.46400","60.77152","0.02416"
"42789","256.69800","60.79101","0.02456"
"42828","256.93200","60.81050","0.02336"
"42867","257.16600","60.82999","0.02533"
"42906","257.40000","60.84954","0.02449"
"42945","257.63400","60.86904","0.02527"
"42984","257.86800","60.88853","0.02488"
"43023","258.10200","60.90802","0.02507"
"43062","258.33600","60.92745","0.02572"
"43101","258.57000","60.94700","0.02482"
"43140","258.80400","60.96643","0.02582"
"43179","259.03800","60.98598","0.02576"
"43218","259.27200","61.00547","0.02585"
"43257","259.50600","61.02502","0.02643"
"43296","259.74000","61.04451","0.02645"
"43335","259.97400","61.06401","0.02692"
"43374","260.20800","61.08350","0.02684"
"43413","260.44200","61.10305","0.02734"
"43452","260.67600","61.12248","0.02745"
"43491","260.91000","61.14191","0.02691"
"43530","261.14400","61.16152","0.02739"
"43569","261.37800","61.18096","0.02715"
"43608","261.61200","61.20051","0.02735"
"43647","261.84600","61.22000","0.02755"
"43686","262.08000","61.23943","0.02843"
"43725","262.31400","61.25904","0.02792"
"43764","262.54800","61.27842","0.02842"
"43803","262.78200","61.29803","0.02875"
"43842","263.01600","61.31752","0.02872"
"43881","263.25000","61.33701","0.02830"
"43920","263.48400","61.35650","0.02896"
"43959","263.71800","61.37599","0.02889"
"43998","263.95200","61.39554","0.02902"
"44037","264.18600","61.41491","0.02861"
"44076","264.42000","61.43452","0.02844"
"44115","264.65400","61.45395","0.02787"
"44154","264.88800","61.47351","0.02711"
"44193","265.12200","61.49294","0.02691"
"44232","265.35600","61.51243","0.02748"
"44271","265.59000","61.53210","0.02772"
"44310","265.82400","61.55141","0.02710"
"44349","266.05800","61.57102","0.02786"
"44388","266.29200","61.59045","0.02740"
"44427","266.52600","61.61000","0.02782"
"44466","266.76000","61.62950","0.02837"
"44505","266.99400","61.64899","0.02808"
"44544","267.22800","61.66854","0.02832"
"44583","267.46200","61.68803","0.02867"
"44622","267.69600","61.70746","0.02845"
"44661","267.93000","61.72696","0.02862"
"44700","268.16400","61.74651","0.02896"
"44739","268.39800","61.76600","0.02977"
"44778","268.63200","61.78548","0.02954"
"44817","268.86600","61.80499","0.02983"
"44856","269.10000","61.82447","0.02997"
"44895","269.33400","61.84402","0.02977"
"44934","269.56800","61.86346","0.03026"
"44973","269.80200","61.88300","0.03003"
"45012","270.03600","61.90250","0.03048"
"45051","270.27000","61.92205","0.03079"
"45090","270.50400","61.94154","0.03061"
"45129","270.73800","61.96103","0.03091"
"45168","270.97200","61.98052","0.03060"
"45207","271.20600","61.99995","0.03050"
"45246","271.44000","62.01951","0.03037"
"45285","271.67400","62.03894","0.03062"
"45324","271.90800","62.05855","0.03044"
"45363","272.14200","62.07798","0.03055"
"45402","272.37600","62.09753","0.03081"
"45441","272.61000","62.11702","0.03051"
"45480","272.84400","62.13639","0.03047"
"45519","273.07800","62.15606","0.03062"
"45558","273.31200","62.17543","0.02991"
"45597","273.54600","62.19499","0.02912"
"45636","273.78000","62.21448","0.02925"
"45675","274.01400","62.23397","0.02952"
"45714","274.24800","62.25352","0.02998"
"45753","274.48200","62.27295","0.02959"
"45792","274.71600","62.29256","0.03030"
"45831","274.95000","62.31200","0.02975"
"45870","275.18400","62.33155","0.02994"
"45909","275.41800","62.35092","0.03000"
"45948","275.65200","62.37053","0.03016"
"45987","275.88600","62.38996","0.03055"
"46026","276.12000","62.40945","0.03016"
"46065","276.35400","62.42901","0.03072"
"46104","276.58800","62.44844","0.03033"
"46143","276.82200","62.46805","0.03087"
"46182","277.05600","62.48748","0.03027"
"46221","277.29000","62.50703","0.03038"
"46260","277.52400","62.52652","0.03057"
"46299","277.75800","62.54601","0.03030"
"46338","277.99200","62.56550","0.03073"
"46377","278.22600","62.58499","0.03102"
"46416","278.46000","62.60454","0.03096"
"46455","278.69400","62.62404","0.03135"
"46494","278.92800","62.64353","0.03159"
"46533","279.16200","62.66296","0.03137"
"46572","279.39600","62.68251","0.03146"
"46611","279.63000","62.70200","0.03197"
"46650","279.86400","62.72149","0.03181"
"46689","280.09800","62.74104","0.03198"
"46728","280.33200","62.76041","0.03180"
"46767","280.56600","62.77996","0.03271"
"46806","280.80000","62.79945","0.03226"
"46845","281.03400","62.81900","0.03281"
"46884","281.26800","62.83856","0.03252"
"46923","281.50200","62.85799","0.03332"
"46962","281.73600","62.87754","0.03310"
"47001","281.97000","62.89697","0.03404"
"47040","282.20400","62.91652","0.03334"
"47079","282.43800","62.93596","0.03370"
"47118","282.67200","62.95557","0.03403"
"47157","282.90600","62.97494","0.03389"
"47159","282.91800","62.97596","0.03395"