File: Trajectories_together/161216Specimen_RawData_6.csv
"","V1","V2","V3"
"1","End date","12/16/2016",""
"2","Specimen label","15BT_19",""
"3","Maximum Load","0.60469","N"
"4","Time","Extension","Load"
"5","(s)","(mm)","(N)"
"6","0.00000","0.00000","-0.00005"
"57","0.30600","0.02511","0.00014"
"108","0.61200","0.05130","0.00070"
"159","0.91800","0.07665","0.00050"
"210","1.22400","0.10224","0.00105"
"261","1.53000","0.12771","0.00108"
"312","1.83600","0.15330","0.00099"
"363","2.14200","0.17865","0.00130"
"414","2.44800","0.20418","0.00097"
"465","2.75400","0.22971","0.00076"
"516","3.06000","0.25518","0.00188"
"567","3.36600","0.28071","0.00154"
"618","3.67200","0.30618","0.00128"
"669","3.97800","0.33171","0.00191"
"720","4.28400","0.35712","0.00113"
"771","4.59000","0.38271","0.00176"
"822","4.89600","0.40818","0.00155"
"873","5.20200","0.43371","0.00128"
"924","5.50800","0.45918","0.00198"
"975","5.81400","0.48471","0.00139"
"1026","6.12000","0.51018","0.00178"
"1077","6.42600","0.53559","0.00170"
"1128","6.73200","0.56118","0.00142"
"1179","7.03800","0.58671","0.00202"
"1230","7.34400","0.61213","0.00201"
"1281","7.65000","0.63766","0.00200"
"1332","7.95600","0.66313","0.00161"
"1383","8.26200","0.68872","0.00183"
"1434","8.56800","0.71419","0.00155"
"1485","8.87400","0.73972","0.00218"
"1536","9.18000","0.76519","0.00192"
"1587","9.48600","0.79066","0.00217"
"1638","9.79200","0.81619","0.00250"
"1689","10.09800","0.84172","0.00222"
"1740","10.40400","0.86719","0.00227"
"1791","10.71000","0.89266","0.00257"
"1842","11.01600","0.91825","0.00220"
"1893","11.32200","0.94372","0.00197"
"1944","11.62800","0.96919","0.00234"
"1995","11.93400","0.99460","0.00205"
"2046","12.24000","1.02013","0.00272"
"2097","12.54600","1.04566","0.00258"
"2148","12.85200","1.07113","0.00205"
"2199","13.15800","1.09672","0.00229"
"2250","13.46400","1.12219","0.00246"
"2301","13.77000","1.14772","0.00252"
"2352","14.07600","1.17319","0.00211"
"2403","14.38200","1.19872","0.00202"
"2454","14.68800","1.22419","0.00224"
"2505","14.99400","1.24966","0.00276"
"2556","15.30000","1.27519","0.00243"
"2607","15.60600","1.30066","0.00261"
"2658","15.91200","1.32619","0.00271"
"2709","16.21800","1.35172","0.00211"
"2760","16.52400","1.37719","0.00243"
"2811","16.83000","1.40266","0.00241"
"2862","17.13600","1.42813","0.00275"
"2913","17.44200","1.45366","0.00256"
"2964","17.74800","1.47913","0.00249"
"3015","18.05400","1.50472","0.00336"
"3066","18.36000","1.53013","0.00268"
"3117","18.66600","1.55572","0.00302"
"3168","18.97200","1.58119","0.00262"
"3219","19.27800","1.60666","0.00261"
"3270","19.58400","1.63219","0.00246"
"3321","19.89000","1.65766","0.00291"
"3372","20.19600","1.68325","0.00313"
"3423","20.50200","1.70867","0.00290"
"3474","20.80800","1.73420","0.00293"
"3525","21.11400","1.75967","0.00292"
"3576","21.42000","1.78514","0.00286"
"3627","21.72600","1.81073","0.00267"
"3678","22.03200","1.83614","0.00314"
"3729","22.33800","1.86173","0.00329"
"3780","22.64400","1.88720","0.00322"
"3831","22.95000","1.91273","0.00323"
"3882","23.25600","1.93820","0.00317"
"3933","23.56200","1.96367","0.00299"
"3984","23.86800","1.98914","0.00324"
"4035","24.17400","2.01461","0.00262"
"4086","24.48000","2.04020","0.00348"
"4137","24.78600","2.06567","0.00303"
"4188","25.09200","2.09120","0.00309"
"4239","25.39800","2.11673","0.00320"
"4290","25.70400","2.14220","0.00303"
"4341","26.01000","2.16773","0.00305"
"4392","26.31600","2.19308","0.00285"
"4443","26.62200","2.21867","0.00296"
"4494","26.92800","2.24414","0.00312"
"4545","27.23400","2.26973","0.00347"
"4596","27.54000","2.29520","0.00346"
"4647","27.84600","2.32073","0.00309"
"4698","28.15200","2.34620","0.00351"
"4749","28.45800","2.37167","0.00274"
"4800","28.76400","2.39720","0.00318"
"4851","29.07000","2.42261","0.00316"
"4902","29.37600","2.44820","0.00332"
"4953","29.68200","2.47367","0.00336"
"5004","29.98800","2.49914","0.00383"
"5055","30.29400","2.52467","0.00346"
"5106","30.60000","2.55020","0.00377"
"5157","30.90600","2.57567","0.00323"
"5208","31.21200","2.60108","0.00337"
"5259","31.51800","2.62667","0.00301"
"5310","31.82400","2.65214","0.00350"
"5361","32.13000","2.67767","0.00387"
"5412","32.43600","2.70320","0.00336"
"5463","32.74200","2.72867","0.00357"
"5514","33.04800","2.75420","0.00339"
"5565","33.35400","2.77962","0.00338"
"5616","33.66000","2.80521","0.00377"
"5667","33.96600","2.83068","0.00354"
"5718","34.27200","2.85621","0.00390"
"5769","34.57800","2.88174","0.00354"
"5820","34.88400","2.90715","0.00375"
"5871","35.19000","2.93268","0.00386"
"5922","35.49600","2.95815","0.00392"
"5973","35.80200","2.98374","0.00358"
"6024","36.10800","3.00921","0.00373"
"6075","36.41400","3.03468","0.00391"
"6126","36.72000","3.06021","0.00346"
"6177","37.02600","3.08568","0.00363"
"6228","37.33200","3.11115","0.00388"
"6279","37.63800","3.13662","0.00383"
"6330","37.94400","3.16221","0.00340"
"6381","38.25000","3.18762","0.00326"
"6432","38.55600","3.21321","0.00387"
"6483","38.86200","3.23868","0.00406"
"6534","39.16800","3.26415","0.00375"
"6585","39.47400","3.28962","0.00407"
"6636","39.78000","3.31509","0.00391"
"6687","40.08600","3.34068","0.00423"
"6738","40.39200","3.36615","0.00403"
"6789","40.69800","3.39168","0.00389"
"6840","41.00400","3.41721","0.00433"
"6891","41.31000","3.44268","0.00393"
"6942","41.61600","3.46827","0.00407"
"6993","41.92200","3.49368","0.00464"
"7044","42.22800","3.51921","0.00389"
"7095","42.53400","3.54462","0.00475"
"7146","42.84000","3.57015","0.00411"
"7197","43.14600","3.59568","0.00471"
"7248","43.45200","3.62121","0.00456"
"7299","43.75800","3.64674","0.00434"
"7350","44.06400","3.67215","0.00393"
"7401","44.37000","3.69768","0.00409"
"7452","44.67600","3.72309","0.00427"
"7503","44.98200","3.74868","0.00448"
"7554","45.28800","3.77415","0.00425"
"7605","45.59400","3.79968","0.00484"
"7656","45.90000","3.82521","0.00476"
"7707","46.20600","3.85063","0.00481"
"7758","46.51200","3.87622","0.00413"
"7809","46.81800","3.90169","0.00454"
"7860","47.12400","3.92722","0.00388"
"7911","47.43000","3.95263","0.00424"
"7962","47.73600","3.97822","0.00436"
"8013","48.04200","4.00369","0.00431"
"8064","48.34800","4.02916","0.00428"
"8115","48.65400","4.05469","0.00426"
"8166","48.96000","4.08016","0.00450"
"8217","49.26600","4.10569","0.00464"
"8268","49.57200","4.13116","0.00464"
"8319","49.87800","4.15669","0.00445"
"8370","50.18400","4.18222","0.00413"
"8421","50.49000","4.20769","0.00425"
"8472","50.79600","4.23322","0.00485"
"8523","51.10200","4.25863","0.00490"
"8574","51.40800","4.28422","0.00485"
"8625","51.71400","4.30969","0.00408"
"8676","52.02000","4.33516","0.00468"
"8727","52.32600","4.36069","0.00485"
"8778","52.63200","4.38616","0.00466"
"8829","52.93800","4.41175","0.00443"
"8880","53.24400","4.43716","0.00444"
"8931","53.55000","4.46275","0.00564"
"8982","53.85600","4.48810","0.00545"
"9033","54.16200","4.51369","0.00518"
"9084","54.46800","4.53916","0.00525"
"9135","54.77400","4.56469","0.00508"
"9186","55.08000","4.59022","0.00554"
"9237","55.38600","4.61557","0.00537"
"9288","55.69200","4.64122","0.00524"
"9339","55.99800","4.66669","0.00544"
"9390","56.30400","4.69222","0.00510"
"9441","56.61000","4.71763","0.00554"
"9492","56.91600","4.74316","0.00570"
"9543","57.22200","4.76875","0.00566"
"9594","57.52800","4.79416","0.00597"
"9645","57.83400","4.81969","0.00577"
"9696","58.14000","4.84516","0.00585"
"9747","58.44600","4.87069","0.00626"
"9798","58.75200","4.89616","0.00637"
"9849","59.05800","4.92164","0.00591"
"9900","59.36400","4.94723","0.00620"
"9951","59.67000","4.97264","0.00594"
"10002","59.97600","4.99817","0.00630"
"10053","60.28200","5.02364","0.00628"
"10104","60.58800","5.04923","0.00631"
"10155","60.89400","5.07470","0.00695"
"10206","61.20000","5.10017","0.00547"
"10257","61.50600","5.12570","0.00656"
"10308","61.81200","5.15117","0.00622"
"10359","62.11800","5.17670","0.00688"
"10410","62.42400","5.20211","0.00707"
"10461","62.73000","5.22770","0.00684"
"10512","63.03600","5.25317","0.00741"
"10563","63.34200","5.27864","0.00717"
"10614","63.64800","5.30417","0.00762"
"10665","63.95400","5.32964","0.00716"
"10716","64.26000","5.35523","0.00771"
"10767","64.56600","5.38064","0.00776"
"10818","64.87200","5.40623","0.00807"
"10869","65.17800","5.43164","0.00768"
"10920","65.48400","5.45717","0.00828"
"10971","65.79000","5.48270","0.00824"
"11022","66.09600","5.50817","0.00833"
"11073","66.40200","5.53370","0.00880"
"11124","66.70800","5.55917","0.00846"
"11175","67.01400","5.58470","0.00851"
"11226","67.32000","5.61017","0.00919"
"11277","67.62600","5.63570","0.00903"
"11328","67.93200","5.66117","0.00895"
"11379","68.23800","5.68664","0.00940"
"11430","68.54400","5.71223","0.01004"
"11481","68.85000","5.73764","0.01005"
"11532","69.15600","5.76323","0.01054"
"11583","69.46200","5.78870","0.01084"
"11634","69.76800","5.81411","0.01108"
"11685","70.07400","5.83970","0.01094"
"11736","70.38000","5.86511","0.01041"
"11787","70.68600","5.89070","0.01038"
"11838","70.99200","5.91611","0.01100"
"11889","71.29800","5.94170","0.01158"
"11940","71.60400","5.96717","0.01202"
"11991","71.91000","5.99270","0.01212"
"12042","72.21600","6.01817","0.01301"
"12093","72.52200","6.04365","0.01333"
"12144","72.82800","6.06918","0.01401"
"12195","73.13400","6.09465","0.01427"
"12246","73.44000","6.12024","0.01361"
"12297","73.74600","6.14571","0.01503"
"12348","74.05200","6.17124","0.01521"
"12399","74.35800","6.19665","0.01619"
"12450","74.66400","6.22224","0.01641"
"12501","74.97000","6.24771","0.01709"
"12552","75.27600","6.27312","0.01771"
"12603","75.58200","6.29871","0.01846"
"12654","75.88800","6.32418","0.01916"
"12705","76.19400","6.34971","0.01968"
"12756","76.50000","6.37518","0.02028"
"12807","76.80600","6.40065","0.02055"
"12858","77.11200","6.42618","0.02158"
"12909","77.41800","6.45159","0.02188"
"12960","77.72400","6.47718","0.02236"
"13011","78.03000","6.50265","0.02306"
"13062","78.33600","6.52818","0.02416"
"13113","78.64200","6.55365","0.02435"
"13164","78.94800","6.57918","0.02569"
"13215","79.25400","6.60471","0.02532"
"13266","79.56000","6.63012","0.02629"
"13317","79.86600","6.65571","0.02702"
"13368","80.17200","6.68118","0.02813"
"13419","80.47800","6.70671","0.02920"
"13470","80.78400","6.73218","0.03085"
"13521","81.09000","6.75765","0.03269"
"13572","81.39600","6.78324","0.03333"
"13623","81.70200","6.80865","0.03486"
"13674","82.00800","6.83418","0.03530"
"13725","82.31400","6.85959","0.03647"
"13776","82.62000","6.88518","0.03812"
"13827","82.92600","6.91065","0.03883"
"13878","83.23200","6.93618","0.03984"
"13929","83.53800","6.96165","0.04080"
"13980","83.84400","6.98718","0.04215"
"14031","84.15000","7.01271","0.04301"
"14082","84.45600","7.03818","0.04347"
"14133","84.76200","7.06371","0.04468"
"14184","85.06800","7.08919","0.04498"
"14235","85.37400","7.11466","0.04667"
"14286","85.68000","7.14019","0.04781"
"14337","85.98600","7.16560","0.04885"
"14388","86.29200","7.19119","0.05016"
"14439","86.59800","7.21666","0.05124"
"14490","86.90400","7.24219","0.05245"
"14541","87.21000","7.26766","0.05412"
"14592","87.51600","7.29325","0.05488"
"14643","87.82200","7.31872","0.05670"
"14694","88.12800","7.34413","0.05743"
"14745","88.43400","7.36972","0.05865"
"14796","88.74000","7.39513","0.06015"
"14847","89.04600","7.42066","0.06118"
"14898","89.35200","7.44619","0.06314"
"14949","89.65800","7.47178","0.06353"
"15000","89.96400","7.49719","0.06479"
"15051","90.27000","7.52266","0.06618"
"15102","90.57600","7.54819","0.06710"
"15153","90.88200","7.57366","0.06794"
"15204","91.18800","7.59919","0.06917"
"15255","91.49400","7.62460","0.07038"
"15306","91.80000","7.65019","0.07187"
"15357","92.10600","7.67566","0.07324"
"15408","92.41200","7.70119","0.07466"
"15459","92.71800","7.72672","0.07649"
"15510","93.02400","7.75219","0.07838"
"15561","93.33000","7.77766","0.07840"
"15612","93.63600","7.80313","0.06263"
"15663","93.94200","7.82872","0.06646"
"15714","94.24800","7.85419","0.06740"
"15765","94.55400","7.87972","0.06912"
"15816","94.86000","7.90525","0.07096"
"15867","95.16600","7.93066","0.07227"
"15918","95.47200","7.95619","0.07572"
"15969","95.77800","7.98160","0.07726"
"16020","96.08400","8.00719","0.07740"
"16071","96.39000","8.03266","0.08044"
"16122","96.69600","8.05819","0.08236"
"16173","97.00200","8.08372","0.08399"
"16224","97.30800","8.10913","0.08599"
"16275","97.61400","8.13472","0.08609"
"16326","97.92000","8.16013","0.08779"
"16377","98.22600","8.18572","0.08927"
"16428","98.53200","8.21114","0.08993"
"16479","98.83800","8.23673","0.09108"
"16530","99.14400","8.26220","0.09151"
"16581","99.45000","8.28767","0.09260"
"16632","99.75600","8.31320","0.09324"
"16683","100.06200","8.33861","0.09377"
"16734","100.36800","8.36414","0.09440"
"16785","100.67400","8.38967","0.09567"
"16836","100.98000","8.41520","0.09609"
"16887","101.28600","8.44067","0.09720"
"16938","101.59200","8.46620","0.09795"
"16989","101.89800","8.49167","0.09847"
"17040","102.20400","8.51714","0.09966"
"17091","102.51000","8.54273","0.10009"
"17142","102.81600","8.56820","0.10080"
"17193","103.12200","8.59367","0.10160"
"17244","103.42800","8.61920","0.10226"
"17295","103.73400","8.64467","0.10291"
"17346","104.04000","8.67026","0.10363"
"17397","104.34600","8.69561","0.10445"
"17448","104.65200","8.72120","0.10521"
"17499","104.95800","8.74661","0.10551"
"17550","105.26400","8.77220","0.10682"
"17601","105.57000","8.79773","0.10788"
"17652","105.87600","8.82320","0.10859"
"17703","106.18200","8.84873","0.10950"
"17754","106.48800","8.87408","0.11035"
"17805","106.79400","8.89967","0.11134"
"17856","107.10000","8.92514","0.11272"
"17907","107.40600","8.95073","0.11306"
"17958","107.71200","8.97614","0.11352"
"18009","108.01800","9.00167","0.11542"
"18060","108.32400","9.02720","0.11603"
"18111","108.63000","9.05267","0.11714"
"18162","108.93600","9.07820","0.11803"
"18213","109.24200","9.10361","0.11868"
"18264","109.54800","9.12920","0.11944"
"18315","109.85400","9.15467","0.12114"
"18366","110.16000","9.18021","0.12150"
"18417","110.46600","9.20573","0.12236"
"18468","110.77200","9.23108","0.12354"
"18519","111.07800","9.25667","0.12420"
"18570","111.38400","9.28215","0.12554"
"18621","111.69000","9.30768","0.12745"
"18672","111.99600","9.33315","0.12825"
"18723","112.30200","9.35868","0.13011"
"18774","112.60800","9.38427","0.13191"
"18825","112.91400","9.40968","0.13368"
"18876","113.22000","9.43521","0.13611"
"18927","113.52600","9.46062","0.13822"
"18978","113.83200","9.48621","0.14012"
"19029","114.13800","9.51162","0.14157"
"19080","114.44400","9.53721","0.14323"
"19131","114.75000","9.56268","0.14474"
"19182","115.05600","9.58815","0.14573"
"19233","115.36200","9.61374","0.14627"
"19284","115.66800","9.63909","0.14865"
"19335","115.97400","9.66474","0.14887"
"19386","116.28000","9.69021","0.15055"
"19437","116.58600","9.71568","0.15252"
"19488","116.89200","9.74115","0.15345"
"19539","117.19800","9.76668","0.15511"
"19590","117.50400","9.79227","0.15652"
"19641","117.81000","9.81762","0.15910"
"19692","118.11600","9.84321","0.16103"
"19743","118.42200","9.86868","0.16299"
"19794","118.72800","9.89421","0.16520"
"19845","119.03400","9.91962","0.16685"
"19896","119.34000","9.94515","0.16861"
"19947","119.64600","9.97074","0.17011"
"19998","119.95200","9.99615","0.17075"
"20049","120.25800","10.02168","0.17211"
"20100","120.56400","10.04715","0.17293"
"20151","120.87000","10.07268","0.17469"
"20202","121.17600","10.09815","0.17581"
"20253","121.48200","10.12368","0.17684"
"20304","121.78800","10.14927","0.17841"
"20355","122.09400","10.17462","0.17972"
"20406","122.40000","10.20021","0.18133"
"20457","122.70600","10.22563","0.18332"
"20508","123.01200","10.25121","0.18487"
"20559","123.31800","10.27662","0.18654"
"20610","123.62400","10.30216","0.18897"
"20661","123.93000","10.32769","0.19067"
"20712","124.23600","10.35316","0.19266"
"20763","124.54200","10.37869","0.19407"
"20814","124.84800","10.40421","0.19557"
"20865","125.15400","10.42969","0.19803"
"20916","125.46000","10.45516","0.19944"
"20967","125.76600","10.48069","0.20141"
"21018","126.07200","10.50622","0.20319"
"21069","126.37800","10.53169","0.20526"
"21120","126.68400","10.55716","0.20666"
"21171","126.99000","10.58263","0.20847"
"21222","127.29600","10.60822","0.20993"
"21273","127.60200","10.63369","0.21169"
"21324","127.90800","10.65916","0.21375"
"21375","128.21400","10.68469","0.21592"
"21426","128.52000","10.71016","0.21851"
"21477","128.82600","10.73569","0.22090"
"21528","129.13200","10.76116","0.22316"
"21579","129.43800","10.78675","0.22532"
"21630","129.74400","10.81216","0.22776"
"21681","130.05000","10.83769","0.22948"
"21732","130.35600","10.86322","0.23162"
"21783","130.66200","10.88863","0.23477"
"21834","130.96800","10.91428","0.23782"
"21885","131.27400","10.93963","0.24048"
"21936","131.58000","10.96522","0.24288"
"21987","131.88600","10.99063","0.23322"
"22038","132.19200","11.01616","0.31014"
"22089","132.49800","11.04163","0.29637"
"22140","132.80400","11.06716","0.29852"
"22191","133.11000","11.09269","0.29964"
"22242","133.41600","11.11816","0.30194"
"22293","133.72200","11.14369","0.30427"
"22344","134.02800","11.16916","0.30678"
"22395","134.33400","11.19469","0.30926"
"22446","134.64000","11.22016","0.31157"
"22497","134.94600","11.24569","0.31319"
"22548","135.25200","11.27122","0.31077"
"22599","135.55800","11.29663","0.31328"
"22650","135.86400","11.32216","0.31604"
"22701","136.17000","11.34770","0.31861"
"22752","136.47600","11.37316","0.32117"
"22803","136.78200","11.39863","0.32406"
"22854","137.08800","11.42411","0.32654"
"22905","137.39400","11.44969","0.32934"
"22956","137.70000","11.47517","0.33291"
"23007","138.00600","11.50070","0.33834"
"23058","138.31200","11.52617","0.34415"
"23109","138.61800","11.55170","0.34818"
"23160","138.92400","11.57717","0.35180"
"23211","139.23000","11.60270","0.35563"
"23262","139.53600","11.62823","0.36038"
"23313","139.84200","11.65364","0.36589"
"23364","140.14800","11.67923","0.37067"
"23415","140.45400","11.70470","0.37469"
"23466","140.76000","11.73023","0.37785"
"23517","141.06600","11.75564","0.38060"
"23568","141.37200","11.78117","0.38489"
"23619","141.67800","11.80670","0.38951"
"23670","141.98400","11.83217","0.39489"
"23721","142.29000","11.85770","0.39864"
"23772","142.59600","11.88317","0.40212"
"23823","142.90200","11.90876","0.40580"
"23874","143.20800","11.93417","0.40858"
"23925","143.51400","11.95970","0.41127"
"23976","143.82000","11.98523","0.41342"
"24027","144.12600","12.01064","0.41630"
"24078","144.43200","12.03617","0.41992"
"24129","144.73800","12.06164","0.42438"
"24180","145.04400","12.08723","0.42878"
"24231","145.35000","12.11270","0.43307"
"24282","145.65600","12.13823","0.39952"
"24333","145.96200","12.16370","0.40082"
"24384","146.26800","12.18917","0.40364"
"24435","146.57400","12.21470","0.40596"
"24486","146.88000","12.24011","0.40838"
"24537","147.18600","12.26564","0.41069"
"24588","147.49200","12.29117","0.41245"
"24639","147.79800","12.31670","0.41478"
"24690","148.10400","12.34223","0.41830"
"24741","148.41000","12.36770","0.42145"
"24792","148.71600","12.39323","0.42602"
"24843","149.02200","12.41865","0.43026"
"24894","149.32800","12.44417","0.43344"
"24945","149.63400","12.46971","0.43772"
"24996","149.94000","12.49523","0.44246"
"25047","150.24600","12.52065","0.44698"
"25098","150.55200","12.54618","0.45062"
"25149","150.85800","12.57171","0.45402"
"25200","151.16400","12.59712","0.45692"
"25251","151.47000","12.62265","0.46074"
"25302","151.77600","12.64818","0.46532"
"25353","152.08200","12.67371","0.47033"
"25404","152.38800","12.69918","0.47521"
"25455","152.69400","12.72471","0.47806"
"25506","153.00000","12.75018","0.48135"
"25557","153.30600","12.77565","0.48521"
"25608","153.61200","12.80118","0.38386"
"25659","153.91800","12.82665","0.37905"
"25710","154.22400","12.85218","0.37937"
"25761","154.53000","12.87765","0.37137"
"25812","154.83600","12.90318","0.37124"
"25863","155.14200","12.92871","0.37335"
"25914","155.44800","12.95412","0.37625"
"25965","155.75400","12.97965","0.37917"
"26016","156.06000","13.00512","0.38327"
"26067","156.36600","13.03071","0.38829"
"26118","156.67200","13.05624","0.39276"
"26169","156.97800","13.08171","0.39748"
"26220","157.28400","13.10724","0.40028"
"26271","157.59000","13.13265","0.40228"
"26322","157.89600","13.15818","0.40550"
"26373","158.20200","13.18359","0.40898"
"26424","158.50800","13.20924","0.41066"
"26475","158.81400","13.23465","0.41295"
"26526","159.12000","13.26018","0.41564"
"26577","159.42600","13.28571","0.41936"
"26628","159.73200","13.31118","0.42486"
"26679","160.03800","13.33671","0.42699"
"26730","160.34400","13.36212","0.43111"
"26781","160.65000","13.38771","0.43481"
"26832","160.95600","13.41318","0.43903"
"26883","161.26200","13.43871","0.44255"
"26934","161.56800","13.46424","0.44720"
"26985","161.87400","13.48965","0.44992"
"27036","162.18000","13.51519","0.45281"
"27087","162.48600","13.54066","0.45588"
"27138","162.79200","13.56618","0.45912"
"27189","163.09800","13.59172","0.46208"
"27240","163.40400","13.61725","0.46599"
"27291","163.71000","13.64272","0.46908"
"27342","164.01600","13.66819","0.47183"
"27393","164.32200","13.69372","0.47526"
"27444","164.62800","13.71913","0.47837"
"27495","164.93400","13.74472","0.48196"
"27546","165.24000","13.77013","0.48568"
"27597","165.54600","13.79572","0.49080"
"27648","165.85200","13.82125","0.49512"
"27699","166.15800","13.84666","0.49180"
"27750","166.46400","13.87225","0.49663"
"27801","166.77000","13.89760","0.49325"
"27852","167.07600","13.92319","0.49835"
"27903","167.38200","13.94860","0.50176"
"27954","167.68800","13.97419","0.50421"
"28005","167.99400","13.99966","0.37163"
"28056","168.30000","14.02519","0.36327"
"28107","168.60600","14.05066","0.36097"
"28158","168.91200","14.07607","0.35914"
"28209","169.21800","14.10172","0.36040"
"28260","169.52400","14.12713","0.36044"
"28311","169.83000","14.15266","0.36242"
"28362","170.13600","14.17819","0.36445"
"28413","170.44200","14.20366","0.36618"
"28464","170.74800","14.22925","0.36813"
"28515","171.05400","14.25466","0.37009"
"28566","171.36000","14.28019","0.37041"
"28617","171.66600","14.30566","0.36872"
"28668","171.97200","14.33119","0.37028"
"28719","172.27800","14.35672","0.37319"
"28770","172.58400","14.38225","0.37546"
"28821","172.89000","14.40772","0.37707"
"28872","173.19600","14.43313","0.37859"
"28923","173.50200","14.45866","0.38093"
"28974","173.80800","14.48407","0.38293"
"29025","174.11400","14.50972","0.18704"
"29076","174.42000","14.53513","0.14041"
"29127","174.72600","14.56067","0.14716"
"29178","175.03200","14.58614","0.14963"
"29229","175.33800","14.61161","0.14835"
"29280","175.64400","14.63720","0.15230"
"29331","175.95000","14.66267","0.15715"
"29382","176.25600","14.68820","0.16018"
"29433","176.56200","14.71367","0.16155"
"29484","176.86800","14.73920","0.16360"
"29535","177.17400","14.76473","0.16806"
"29586","177.48000","14.79020","0.17013"
"29637","177.78600","14.81573","0.17251"
"29688","178.09200","14.84114","0.17333"
"29739","178.39800","14.86667","0.17533"
"29790","178.70400","14.89214","0.17755"
"29841","179.01000","14.91773","0.17839"
"29892","179.31600","14.94320","0.17827"
"29943","179.62200","14.96861","0.02364"
"29994","179.92800","14.99420","0.02091"
"30045","180.23400","15.01967","0.02894"
"30096","180.54000","15.04520","0.03238"
"30147","180.84600","15.07067","0.02261"
"30198","181.15200","15.09620","0.02859"
"30249","181.45800","15.12173","0.02630"
"30300","181.76400","15.14714","0.03604"
"30351","182.07000","15.17279","0.03609"
"30402","182.37600","15.19820","0.03866"
"30453","182.68200","15.22373","0.03080"
"30504","182.98800","15.24908","0.03844"
"30555","183.29400","15.27467","0.03802"
"30606","183.60000","15.30020","0.04379"
"30657","183.90600","15.32567","0.04170"
"30708","184.21200","15.35120","0.04408"
"30759","184.51800","15.37661","0.04226"
"30810","184.82400","15.40220","0.04801"
"30861","185.13000","15.42767","0.04934"
"30912","185.43600","15.45320","0.05150"
"30963","185.74200","15.47867","0.04894"
"31014","186.04800","15.50414","0.05142"
"31065","186.35400","15.52973","0.05284"
"31116","186.66000","15.55520","0.05725"
"31167","186.96600","15.58073","0.05862"
"31218","187.27200","15.60614","0.05830"
"31269","187.57800","15.63167","0.06060"
"31320","187.88400","15.65714","0.06197"
"31371","188.19000","15.68262","0.06469"
"31422","188.49600","15.70820","0.06535"
"31473","188.80200","15.73367","0.06573"
"31524","189.10800","15.75921","0.06498"
"31575","189.41400","15.78462","0.06734"
"31626","189.72000","15.81021","0.07039"
"31677","190.02600","15.83568","0.07082"
"31728","190.33200","15.86115","0.07196"
"31779","190.63800","15.88668","0.07374"
"31830","190.94400","15.91215","0.07788"
"31881","191.25000","15.93768","0.08108"
"31932","191.55600","15.96315","0.08354"
"31983","191.86200","15.98868","0.08465"
"32034","192.16800","16.01415","0.08619"
"32085","192.47400","16.03968","0.08866"
"32136","192.78000","16.06515","0.09043"
"32187","193.08600","16.09062","0.09127"
"32238","193.39200","16.11621","0.09232"
"32289","193.69800","16.14162","0.09314"
"32340","194.00400","16.16721","0.09456"
"32391","194.31000","16.19268","0.09548"
"32442","194.61600","16.21815","0.09685"
"32493","194.92200","16.24374","0.09722"
"32544","195.22800","16.26915","0.09831"
"32595","195.53400","16.29474","0.09911"
"32646","195.84000","16.32015","0.09942"
"32697","196.14600","16.34574","0.09994"
"32748","196.45200","16.37115","0.10062"
"32799","196.75800","16.39668","0.10125"
"32850","197.06400","16.42215","0.10261"
"32901","197.37000","16.44762","0.10384"
"32952","197.67600","16.47315","0.10462"
"33003","197.98200","16.49868","0.10383"
"33054","198.28800","16.52421","0.10520"
"33105","198.59400","16.54968","0.10594"
"33156","198.90000","16.57515","0.10760"
"33207","199.20600","16.60068","0.10735"
"33258","199.51200","16.62615","0.10770"
"33309","199.81800","16.65174","0.10843"
"33360","200.12400","16.67715","0.10951"
"33411","200.43000","16.70268","0.10874"
"33462","200.73600","16.72816","0.10857"
"33513","201.04200","16.75368","0.10915"
"33564","201.34800","16.77915","0.10915"
"33615","201.65400","16.80469","0.10950"
"33666","201.96000","16.83022","0.11081"
"33717","202.26600","16.85563","0.11152"
"33768","202.57200","16.88122","0.11305"
"33819","202.87800","16.90669","0.11392"
"33870","203.18400","16.93221","0.11536"
"33921","203.49000","16.95763","0.11717"
"33972","203.79600","16.98322","0.11852"
"34023","204.10200","17.00875","0.11987"
"34074","204.40800","17.03416","0.12157"
"34125","204.71400","17.05975","0.12358"
"34176","205.02000","17.08522","0.12579"
"34227","205.32600","17.11069","0.12814"
"34278","205.63200","17.13616","0.13091"
"34329","205.93800","17.16163","0.13321"
"34380","206.24400","17.18722","0.13503"
"34431","206.55000","17.21263","0.13682"
"34482","206.85600","17.23822","0.13819"
"34533","207.16200","17.26363","0.14033"
"34584","207.46800","17.28922","0.14200"
"34635","207.77400","17.31469","0.14371"
"34686","208.08000","17.34016","0.14558"
"34737","208.38600","17.36569","0.14613"
"34788","208.69200","17.39110","0.14798"
"34839","208.99800","17.41669","0.15055"
"34890","209.30400","17.44216","0.15053"
"34941","209.61000","17.46775","0.15189"
"34992","209.91600","17.49322","0.15366"
"35043","210.22200","17.51869","0.15598"
"35094","210.52800","17.54422","0.15598"
"35145","210.83400","17.56963","0.15744"
"35196","211.14000","17.59516","0.15910"
"35247","211.44600","17.62063","0.16127"
"35298","211.75200","17.64616","0.16317"
"35349","212.05800","17.67163","0.16455"
"35400","212.36400","17.69722","0.16663"
"35451","212.67000","17.72269","0.16826"
"35502","212.97600","17.74816","0.17012"
"35553","213.28200","17.77369","0.17088"
"35604","213.58800","17.79917","0.17218"
"35655","213.89400","17.82469","0.17349"
"35706","214.20000","17.85016","0.17481"
"35757","214.50600","17.87570","0.17587"
"35808","214.81200","17.90117","0.17733"
"35859","215.11800","17.92664","0.17886"
"35910","215.42400","17.95223","0.18056"
"35961","215.73000","17.97764","0.18180"
"36012","216.03600","18.00317","0.18295"
"36063","216.34200","18.02864","0.18473"
"36114","216.64800","18.05423","0.18671"
"36165","216.95400","18.07970","0.18818"
"36216","217.26000","18.10517","0.19026"
"36267","217.56600","18.13076","0.19158"
"36318","217.87200","18.15617","0.19345"
"36369","218.17800","18.18170","0.19514"
"36420","218.48400","18.20711","0.19719"
"36471","218.79000","18.23276","0.19899"
"36522","219.09600","18.25817","0.20084"
"36573","219.40200","18.28370","0.20244"
"36624","219.70800","18.30917","0.20360"
"36675","220.01400","18.33464","0.20396"
"36726","220.32000","18.36017","0.20502"
"36777","220.62600","18.38558","0.20666"
"36828","220.93200","18.41117","0.20835"
"36879","221.23800","18.43670","0.20907"
"36930","221.54400","18.46217","0.21025"
"36981","221.85000","18.48770","0.21134"
"37032","222.15600","18.51317","0.21295"
"37083","222.46200","18.53864","0.21440"
"37134","222.76800","18.56411","0.21654"
"37185","223.07400","18.58970","0.21834"
"37236","223.38000","18.61517","0.21976"
"37287","223.68600","18.64076","0.22164"
"37338","223.99200","18.66623","0.22377"
"37389","224.29800","18.69170","0.22475"
"37440","224.60400","18.71723","0.22690"
"37491","224.91000","18.74264","0.22827"
"37542","225.21600","18.76823","0.22966"
"37593","225.52200","18.79364","0.23149"
"37644","225.82800","18.81923","0.23402"
"37695","226.13400","18.84471","0.23578"
"37746","226.44000","18.87017","0.23758"
"37797","226.74600","18.89570","0.24007"
"37848","227.05200","18.92118","0.24187"
"37899","227.35800","18.94670","0.24421"
"37950","227.66400","18.97218","0.24568"
"38001","227.97000","18.99771","0.24716"
"38052","228.27600","19.02318","0.24922"
"38103","228.58200","19.04865","0.25220"
"38154","228.88800","19.07418","0.25408"
"38205","229.19400","19.09959","0.25729"
"38256","229.50000","19.12518","0.26034"
"38307","229.80600","19.15059","0.26262"
"38358","230.11200","19.17618","0.26536"
"38409","230.41800","19.20171","0.26773"
"38460","230.72400","19.22718","0.26922"
"38511","231.03000","19.25271","0.27099"
"38562","231.33600","19.27812","0.27346"
"38613","231.64200","19.30371","0.27582"
"38664","231.94800","19.32918","0.27899"
"38715","232.25400","19.35471","0.28274"
"38766","232.56000","19.38018","0.28668"
"38817","232.86600","19.40565","0.29038"
"38868","233.17200","19.43124","0.29393"
"38919","233.47800","19.45665","0.29742"
"38970","233.78400","19.48218","0.29958"
"39021","234.09000","19.50759","0.30151"
"39072","234.39600","19.53318","0.30314"
"39123","234.70200","19.55871","0.30545"
"39174","235.00800","19.58424","0.30749"
"39225","235.31400","19.60977","0.30990"
"39276","235.62000","19.63512","0.31173"
"39327","235.92600","19.66065","0.31438"
"39378","236.23200","19.68612","0.31588"
"39429","236.53800","19.71171","0.31753"
"39480","236.84400","19.73712","0.31919"
"39531","237.15000","19.76271","0.32114"
"39582","237.45600","19.78818","0.32283"
"39633","237.76200","19.81365","0.32427"
"39684","238.06800","19.83918","0.32656"
"39735","238.37400","19.86465","0.32902"
"39786","238.68000","19.89018","0.33075"
"39837","238.98600","19.91566","0.33415"
"39888","239.29200","19.94118","0.33831"
"39939","239.59800","19.96671","0.34199"
"39990","239.90400","19.99213","0.34604"
"40041","240.21000","20.01772","0.34933"
"40092","240.51600","20.04318","0.35218"
"40143","240.82200","20.06866","0.35514"
"40194","241.12800","20.09412","0.35702"
"40245","241.43400","20.11966","0.36081"
"40296","241.74000","20.14524","0.36426"
"40347","242.04600","20.17066","0.36860"
"40398","242.35200","20.19624","0.37158"
"40449","242.65800","20.22160","0.37405"
"40500","242.96400","20.24719","0.37694"
"40551","243.27000","20.27260","0.37857"
"40602","243.57600","20.29819","0.38144"
"40653","243.88200","20.32366","0.38429"
"40704","244.18800","20.34913","0.38740"
"40755","244.49400","20.37472","0.39002"
"40806","244.80000","20.40013","0.39438"
"40857","245.10600","20.42572","0.39789"
"40908","245.41200","20.45113","0.40056"
"40959","245.71800","20.47666","0.40320"
"41010","246.02400","20.50219","0.40582"
"41061","246.33000","20.52766","0.40800"
"41112","246.63600","20.55325","0.40988"
"41163","246.94200","20.57866","0.41176"
"41214","247.24800","20.60419","0.41386"
"41265","247.55400","20.62966","0.41565"
"41316","247.86000","20.65519","0.41872"
"41367","248.16600","20.68066","0.42107"
"41418","248.47200","20.70613","0.42510"
"41469","248.77800","20.73172","0.42809"
"41520","249.08400","20.75719","0.43212"
"41571","249.39000","20.78272","0.43505"
"41622","249.69600","20.80813","0.43811"
"41673","250.00200","20.83366","0.44186"
"41724","250.30800","20.85919","0.44561"
"41775","250.61400","20.88466","0.45001"
"41826","250.92000","20.91019","0.45297"
"41877","251.22600","20.93566","0.45524"
"41928","251.53200","20.96119","0.45811"
"41979","251.83800","20.98660","0.45903"
"42030","252.14400","21.01219","0.46139"
"42081","252.45000","21.03766","0.46488"
"42132","252.75600","21.06319","0.46759"
"42183","253.06200","21.08867","0.47199"
"42234","253.36800","21.11420","0.47436"
"42285","253.67400","21.13973","0.47827"
"42336","253.98000","21.16514","0.48016"
"42387","254.28600","21.19066","0.48325"
"42438","254.59200","21.21614","0.48666"
"42489","254.89800","21.24166","0.28602"
"42540","255.20400","21.26720","0.30327"
"42591","255.51000","21.29267","0.30226"
"42642","255.81600","21.31820","0.30049"
"42693","256.12200","21.34367","0.30951"
"42744","256.42800","21.36920","0.31556"
"42795","256.73400","21.39467","0.31731"
"42846","257.04000","21.42020","0.31908"
"42897","257.34600","21.44567","0.32184"
"42948","257.65200","21.47114","0.32356"
"42999","257.95800","21.49673","0.32855"
"43050","258.26400","21.52214","0.34133"
"43101","258.57000","21.54773","0.34742"
"43152","258.87600","21.57320","0.35197"
"43203","259.18200","21.59867","0.35786"
"43254","259.48800","21.62420","0.36177"
"43305","259.79400","21.64961","0.36581"
"43356","260.10000","21.67520","0.37157"
"43407","260.40600","21.70061","0.37521"
"43458","260.71200","21.72620","0.38112"
"43509","261.01800","21.75167","0.38524"
"43560","261.32400","21.77720","0.38935"
"43611","261.63000","21.80261","0.39755"
"43662","261.93600","21.82814","0.40304"
"43713","262.24200","21.85367","0.40672"
"43764","262.54800","21.87914","0.40825"
"43815","262.85400","21.90473","0.41032"
"43866","263.16000","21.93014","0.41300"
"43917","263.46600","21.95573","0.41529"
"43968","263.77200","21.98120","0.41720"
"44019","264.07800","22.00667","0.42025"
"44070","264.38400","22.03221","0.42489"
"44121","264.69000","22.05767","0.43028"
"44172","264.99600","22.08320","0.43265"
"44223","265.30200","22.10873","0.43570"
"44274","265.60800","22.13420","0.43987"
"44325","265.91400","22.15961","0.44432"
"44376","266.22000","22.18515","0.44841"
"44427","266.52600","22.21068","0.45003"
"44478","266.83200","22.23609","0.45386"
"44529","267.13800","22.26167","0.45683"
"44580","267.44400","22.28715","0.45973"
"44631","267.75000","22.31268","0.46330"
"44682","268.05600","22.33815","0.46750"
"44733","268.36200","22.36374","0.47140"
"44784","268.66800","22.38927","0.47384"
"44835","268.97400","22.41462","0.47604"
"44886","269.28000","22.44021","0.47702"
"44937","269.58600","22.46562","0.47903"
"44988","269.89200","22.49127","0.48144"
"45039","270.19800","22.51668","0.48413"
"45090","270.50400","22.54221","0.48796"
"45141","270.81000","22.56768","0.49232"
"45192","271.11600","22.59315","0.49727"
"45243","271.42200","22.61868","0.50080"
"45294","271.72800","22.64415","0.50493"
"45345","272.03400","22.66974","0.50814"
"45396","272.34000","22.69515","0.51089"
"45447","272.64600","22.72068","0.50339"
"45498","272.95200","22.74621","0.50798"
"45549","273.25800","22.77168","0.51159"
"45600","273.56400","22.79721","0.51452"
"45651","273.87000","22.82268","0.51615"
"45702","274.17600","22.84821","0.51863"
"45753","274.48200","22.87368","0.52033"
"45804","274.78800","22.89921","0.52220"
"45855","275.09400","22.92468","0.52346"
"45906","275.40000","22.95015","0.52616"
"45957","275.70600","22.97568","0.52843"
"46008","276.01200","23.00115","0.53076"
"46059","276.31800","23.02668","0.53255"
"46110","276.62400","23.05215","0.53526"
"46161","276.93000","23.07775","0.53750"
"46212","277.23600","23.10321","0.54018"
"46263","277.54200","23.12868","0.54334"
"46314","277.84800","23.15421","0.54694"
"46365","278.15400","23.17969","0.54956"
"46416","278.46000","23.20522","0.55333"
"46467","278.76600","23.23068","0.55481"
"46518","279.07200","23.25628","0.55844"
"46569","279.37800","23.28169","0.56022"
"46620","279.68400","23.30716","0.56381"
"46671","279.99000","23.33269","0.56790"
"46722","280.29600","23.35816","0.57146"
"46773","280.60200","23.38363","0.57543"
"46824","280.90800","23.40910","0.57753"
"46875","281.21400","23.43475","0.58073"
"46926","281.52000","23.46016","0.58303"
"46977","281.82600","23.48569","0.58597"
"47028","282.13200","23.51116","0.58773"
"47079","282.43800","23.53663","0.59011"
"47130","282.74400","23.56216","0.59382"
"47181","283.05000","23.58763","0.59572"
"47232","283.35600","23.61322","0.59869"
"47283","283.66200","23.63869","0.60115"
"47334","283.96800","23.66416","0.60354"
"47385","284.27400","23.68969","0.39829"
"47436","284.58000","23.71516","0.39016"
"47487","284.88600","23.74069","0.39684"
"47538","285.19200","23.76610","0.38595"
"47589","285.49800","23.79169","0.39065"
"47640","285.80400","23.81722","0.39221"
"47691","286.11000","23.84275","0.39184"
"47742","286.41600","23.86822","0.39646"
"47793","286.72200","23.89369","0.39540"
"47844","287.02800","23.91916","0.39864"
"47895","287.33400","23.94463","0.40322"
"47946","287.64000","23.97022","0.40256"
"47997","287.94600","23.99563","0.40560"
"48048","288.25200","24.02122","0.40775"
"48099","288.55800","24.04669","0.40824"
"48150","288.86400","24.07216","0.41017"
"48201","289.17000","24.09769","0.40973"
"48252","289.47600","24.12316","0.41198"
"48303","289.78200","24.14875","0.41259"
"48354","290.08800","24.17416","0.41254"
"48405","290.39400","24.19969","0.25446"
"48456","290.70000","24.22523","0.26678"
"48507","291.00600","24.25069","0.25355"
"48558","291.31200","24.27622","0.24105"
"48609","291.61800","24.30170","0.24477"
"48660","291.92400","24.32723","0.24926"
"48711","292.23000","24.35270","0.25580"
"48762","292.53600","24.37823","0.25045"
"48813","292.84200","24.40370","0.25258"
"48864","293.14800","24.42917","0.24503"
"48915","293.45400","24.45476","0.25624"
"48966","293.76000","24.48011","0.25733"
"49017","294.06600","24.50570","0.25992"
"49068","294.37200","24.53111","0.25092"
"49119","294.67800","24.55670","0.25877"
"49170","294.98400","24.58217","0.26132"
"49221","295.29000","24.60770","0.26673"
"49272","295.59600","24.63323","0.26091"
"49323","295.90200","24.65864","0.26565"
"49374","296.20800","24.68417","0.26729"
"49425","296.51400","24.70964","0.27333"
"49476","296.82000","24.73517","0.27193"
"49527","297.12600","24.76070","0.27218"
"49578","297.43200","24.78617","0.27624"
"49629","297.73800","24.81170","0.28137"
"49680","298.04400","24.83711","0.28836"
"49731","298.35000","24.86270","0.28428"
"49782","298.65600","24.88811","0.28957"
"49833","298.96200","24.91364","0.29056"
"49884","299.26800","24.93917","0.29797"
"49935","299.57400","24.96464","0.29842"
"49986","299.88000","24.99023","0.29937"
"50037","300.18600","25.01564","0.30175"
"50088","300.49200","25.04117","0.30317"
"50139","300.79800","25.06670","0.30629"
"50190","301.10400","25.09223","0.30612"
"50241","301.41000","25.11770","0.30830"
"50292","301.71600","25.14323","0.30990"
"50343","302.02200","25.16876","0.31142"
"50394","302.32800","25.19417","0.31502"
"50445","302.63400","25.21970","0.31532"
"50496","302.94000","25.24512","0.31670"
"50547","303.24600","25.27070","0.31823"
"50598","303.55200","25.29612","0.31947"
"50649","303.85800","25.32165","0.32278"
"50700","304.16400","25.34717","0.32313"
"50751","304.47000","25.37264","0.32422"
"50802","304.77600","25.39817","0.32650"
"50853","305.08200","25.42365","0.32641"
"50904","305.38800","25.44917","0.32911"
"50955","305.69400","25.47465","0.33269"
"51006","306.00000","25.50018","0.33279"
"51057","306.30600","25.52571","0.33503"
"51108","306.61200","25.55118","0.33943"
"51159","306.91800","25.57677","0.34085"
"51210","307.22400","25.60212","0.34438"
"51261","307.53000","25.62771","0.34731"
"51312","307.83600","25.65312","0.34843"
"51363","308.14200","25.67871","0.35048"
"51414","308.44800","25.70418","0.35293"
"51465","308.75400","25.72965","0.35455"
"51516","309.06000","25.75524","0.35899"
"51567","309.36600","25.78065","0.36353"
"51618","309.67200","25.80618","0.36542"
"51669","309.97800","25.83171","0.36715"
"51720","310.28400","25.85718","0.37068"
"51771","310.59000","25.88271","0.37353"
"51822","310.89600","25.90812","0.37467"
"51873","311.20200","25.93371","0.37776"
"51924","311.50800","25.95918","0.38030"
"51975","311.81400","25.98471","0.38152"
"52026","312.12000","26.01012","0.38314"
"52077","312.42600","26.03571","0.38594"
"52128","312.73200","26.06118","0.38974"
"52179","313.03800","26.08665","0.39185"
"52230","313.34400","26.11218","0.39483"
"52281","313.65000","26.13765","0.39925"
"52332","313.95600","26.16318","0.40184"
"52383","314.26200","26.18865","0.40305"
"52434","314.56800","26.21424","0.40497"
"52485","314.87400","26.23965","0.40685"
"52536","315.18000","26.26518","0.40856"
"52587","315.48600","26.29071","0.41004"
"52638","315.79200","26.31618","0.41152"
"52689","316.09800","26.34171","0.41334"
"52740","316.40400","26.36719","0.41536"
"52791","316.71000","26.39271","0.41761"
"52842","317.01600","26.41812","0.41925"
"52893","317.32200","26.44366","0.42150"
"52944","317.62800","26.46918","0.42399"
"52995","317.93400","26.49466","0.42751"
"53046","318.24000","26.52019","0.43015"
"53097","318.54600","26.54565","0.43229"
"53148","318.85200","26.57119","0.43488"
"53199","319.15800","26.59666","0.43787"
"53250","319.46400","26.62219","0.36508"
"53301","319.77000","26.64772","0.32926"
"53352","320.07600","26.67313","0.33140"
"53403","320.38200","26.69866","0.10133"
"53454","320.68800","26.72413","0.12738"
"53505","320.99400","26.74972","0.12063"
"53556","321.30000","26.77513","0.10538"
"53607","321.60600","26.80066","0.11537"
"53658","321.91200","26.82619","0.12604"
"53709","322.21800","26.85166","0.11620"
"53760","322.52400","26.87719","0.10700"
"53811","322.83000","26.90266","0.13331"
"53862","323.13600","26.92825","0.13051"
"53913","323.44200","26.95366","0.11629"
"53964","323.74800","26.97919","0.13490"
"54015","324.05400","27.00472","0.12733"
"54066","324.36000","27.03019","0.12273"
"54117","324.66600","27.05572","0.14514"
"54168","324.97200","27.08113","0.13422"
"54219","325.27800","27.10672","0.13669"
"54270","325.58400","27.13213","0.14630"
"54321","325.89000","27.15766","0.14012"
"54372","326.19600","27.18319","0.14680"
"54423","326.50200","27.20866","0.15386"
"54474","326.80800","27.23419","0.14512"
"54525","327.11400","27.25966","0.15303"
"54576","327.42000","27.28525","0.15018"
"54627","327.72600","27.31066","0.16394"
"54678","328.03200","27.33619","0.16188"
"54729","328.33800","27.36166","0.15903"
"54780","328.64400","27.38719","0.16940"
"54831","328.95000","27.41273","0.16896"
"54882","329.25600","27.43820","0.17305"
"54933","329.56200","27.46372","0.16530"
"54984","329.86800","27.48920","0.17622"
"55035","330.17400","27.51472","0.17482"
"55086","330.48000","27.54014","0.18168"
"55137","330.78600","27.56567","0.17574"
"55188","331.09200","27.59119","0.18554"
"55239","331.39800","27.61661","0.18618"
"55290","331.70400","27.64220","0.18581"
"55341","332.01000","27.66767","0.18440"
"55392","332.31600","27.69326","0.19408"
"55443","332.62200","27.71867","0.18932"
"55494","332.92800","27.74414","0.19492"
"55545","333.23400","27.76973","0.19493"
"55596","333.54000","27.79520","0.19965"
"55647","333.84600","27.82067","0.19609"
"55698","334.15200","27.84614","0.20323"
"55749","334.45800","27.87173","0.20155"
"55800","334.76400","27.89714","0.20197"
"55851","335.07000","27.92261","0.20577"
"55902","335.37600","27.94820","0.20402"
"55953","335.68200","27.97361","0.20546"
"56004","335.98800","27.99920","0.20764"
"56055","336.29400","28.02461","0.20846"
"56106","336.60000","28.05020","0.20655"
"56157","336.90600","28.07567","0.21049"
"56208","337.21200","28.10120","0.20840"
"56259","337.51800","28.12667","0.20854"
"56310","337.82400","28.15214","0.21358"
"56361","338.13000","28.17767","0.20940"
"56412","338.43600","28.20314","0.21235"
"56463","338.74200","28.22867","0.21397"
"56514","339.04800","28.25420","0.21108"
"56565","339.35400","28.27973","0.21571"
"56616","339.66000","28.30520","0.21396"
"56667","339.96600","28.33068","0.21344"
"56718","340.27200","28.35620","0.21534"
"56769","340.57800","28.38167","0.21413"
"56820","340.88400","28.40714","0.21538"
"56871","341.19000","28.43262","0.21614"
"56922","341.49600","28.45820","0.21513"
"56973","341.80200","28.48374","0.21820"
"57024","342.10800","28.50920","0.21778"
"57075","342.41400","28.53474","0.21663"
"57126","342.72000","28.56014","0.21989"
"57177","343.02600","28.58568","0.21904"
"57228","343.33200","28.61114","0.21879"
"57279","343.63800","28.63668","0.22116"
"57330","343.94400","28.66221","0.21934"
"57381","344.25000","28.68768","0.22061"
"57432","344.55600","28.71321","0.22168"
"57483","344.86200","28.73868","0.21996"
"57534","345.16800","28.76421","0.22206"
"57585","345.47400","28.78962","0.22046"
"57636","345.78000","28.81521","0.22019"
"57687","346.08600","28.84068","0.22085"
"57738","346.39200","28.86621","0.21827"
"57789","346.69800","28.89174","0.22091"
"57840","347.00400","28.91715","-0.00261"
"57891","347.31000","28.94268","-0.00254"
"57942","347.61600","28.96809","-0.00096"
"57993","347.92200","28.99374","0.00032"
"58044","348.22800","29.01921","-0.00110"
"58095","348.53400","29.04468","0.00171"
"58146","348.84000","29.07015","-0.00146"
"58197","349.14600","29.09562","-0.00037"
"58248","349.45200","29.12115","-0.00072"
"58299","349.75800","29.14662","-0.00116"
"58350","350.06400","29.17221","-0.00026"
"58401","350.37000","29.19768","-0.00135"
"58452","350.67600","29.22321","-0.00056"
"58503","350.98200","29.24868","-0.00028"
"58554","351.28800","29.27415","-0.00105"
"58605","351.59400","29.29968","-0.00106"
"58656","351.90000","29.32515","-0.00096"
"58707","352.20600","29.35074","-0.00036"
"58758","352.51200","29.37615","-0.00056"
"58809","352.81800","29.40174","-0.00100"
"58860","353.12400","29.42721","-0.00088"
"58911","353.43000","29.45268","-0.00028"
"58962","353.73600","29.47821","-0.00062"
"59013","354.04200","29.50362","-0.00066"
"59064","354.34800","29.52921","-0.00091"
"59115","354.65400","29.55463","-0.00013"
"59166","354.96000","29.58021","-0.00059"
"59217","355.26600","29.60568","-0.00046"
"59268","355.57200","29.63122","-0.00063"
"59319","355.87800","29.65675","-0.00080"
"59370","356.18400","29.68216","-0.00037"
"59421","356.49000","29.70769","-0.00056"
"59472","356.79600","29.73310","-0.00111"
"59523","357.10200","29.75869","-0.00072"
"59574","357.40800","29.78416","-0.00079"
"59625","357.71400","29.80969","-0.00079"
"59676","358.02000","29.83522","-0.00017"
"59727","358.32600","29.86063","-0.00091"
"59778","358.63200","29.88616","-0.00033"
"59829","358.93800","29.91157","-0.00103"
"59880","359.24400","29.93722","-0.00092"
"59931","359.55000","29.96269","-0.00089"
"59982","359.85600","29.98822","-0.00041"
"60033","360.16200","30.01375","-0.00053"
"60084","360.46800","30.03910","-0.00090"
"60135","360.77400","30.06469","-0.00076"
"60186","361.08000","30.09022","-0.00080"
"60237","361.38600","30.11569","-0.00049"
"60288","361.69200","30.14116","-0.00078"
"60339","361.99800","30.16669","-0.00061"
"60390","362.30400","30.19222","-0.00068"
"60441","362.61000","30.21763","-0.00104"
"60492","362.91600","30.24316","-0.00049"
"60543","363.22200","30.26857","-0.00060"
"60594","363.52800","30.29416","-0.00060"
"60645","363.83400","30.31963","-0.00088"
"60696","364.14000","30.34522","-0.00022"
"60747","364.44600","30.37075","-0.00053"
"60798","364.75200","30.39610","-0.00044"
"60849","365.05800","30.42169","-0.00062"
"60900","365.36400","30.44716","-0.00070"
"60951","365.67000","30.47275","-0.00010"
"61002","365.97600","30.49816","-0.00053"
"61053","366.28200","30.52369","-0.00071"
"61104","366.58800","30.54917","-0.00080"
"61155","366.89400","30.57463","-0.00035"
"61206","367.20000","30.60022","-0.00053"
"61257","367.50600","30.62570","-0.00061"
"61308","367.81200","30.65117","-0.00035"
"61359","368.11800","30.67664","-0.00058"
"61410","368.42400","30.70217","-0.00030"
"61461","368.73000","30.72769","-0.00060"
"61512","369.03600","30.75311","-0.00076"
"61563","369.34200","30.77869","-0.00080"
"61614","369.64800","30.80416","-0.00073"
"61665","369.95400","30.82970","-0.00053"
"61716","370.26000","30.85517","-0.00052"
"61767","370.56600","30.88070","-0.00065"
"61818","370.87200","30.90623","-0.00067"
"61869","371.17800","30.93164","-0.00041"
"61920","371.48400","30.95723","-0.00088"
"61971","371.79000","30.98264","-0.00090"
"62022","372.09600","31.00817","-0.00046"
"62073","372.40200","31.03358","-0.00028"
"62124","372.70800","31.05917","-0.00073"
"62175","373.01400","31.08464","-0.00083"
"62186","373.07800","31.09002","-0.00083"