File: Trajectories_together/161226_1Specimen_RawData_7.csv
"","V1","V2","V3"
"1","End date","12/26/2016",""
"2","Specimen label","22AG_80",""
"3","Maximum Load","0.17213","N"
"4","Time","Extension","Load"
"5","(s)","(mm)","(N)"
"6","0.00000","0.00000","0.00011"
"56","0.30000","0.02404","0.00051"
"106","0.60000","0.05022","0.00010"
"156","0.90000","0.07522","0.00088"
"206","1.20000","0.10021","0.00089"
"256","1.50000","0.12520","0.00126"
"306","1.80000","0.15019","0.00090"
"356","2.10000","0.17518","0.00131"
"406","2.40000","0.20012","0.00104"
"456","2.70000","0.22517","0.00119"
"506","3.00000","0.25016","0.00232"
"556","3.30000","0.27515","0.00183"
"606","3.60000","0.30008","0.00136"
"656","3.90000","0.32520","0.00160"
"706","4.20000","0.35013","0.00221"
"756","4.50000","0.37518","0.00130"
"806","4.80000","0.40023","0.00193"
"856","5.10000","0.42516","0.00201"
"906","5.40000","0.45016","0.00220"
"956","5.70000","0.47515","0.00251"
"1006","6.00000","0.50020","0.00208"
"1056","6.30000","0.52513","0.00261"
"1106","6.60000","0.55018","0.00275"
"1156","6.90000","0.57512","0.00226"
"1206","7.20000","0.60017","0.00244"
"1256","7.50000","0.62516","0.00311"
"1306","7.80000","0.65009","0.00318"
"1356","8.10000","0.67514","0.00293"
"1406","8.40000","0.70014","0.00320"
"1456","8.70000","0.72519","0.00298"
"1506","9.00000","0.75012","0.00302"
"1556","9.30000","0.77517","0.00326"
"1606","9.60000","0.80010","0.00286"
"1656","9.90000","0.82516","0.00317"
"1706","10.20000","0.85015","0.00356"
"1756","10.50000","0.87514","0.00307"
"1806","10.80000","0.90019","0.00331"
"1856","11.10000","0.92512","0.00349"
"1906","11.40000","0.95018","0.00345"
"1956","11.70000","0.97517","0.00340"
"2006","12.00000","1.00016","0.00308"
"2056","12.30000","1.02515","0.00376"
"2106","12.60000","1.05014","0.00395"
"2156","12.90000","1.07520","0.00383"
"2206","13.20000","1.10013","0.00417"
"2256","13.50000","1.12518","0.00346"
"2306","13.80000","1.15011","0.00390"
"2356","14.10000","1.17522","0.00356"
"2406","14.40000","1.20016","0.00391"
"2456","14.70000","1.22521","0.00371"
"2506","15.00000","1.25014","0.00378"
"2556","15.30000","1.27513","0.00348"
"2606","15.60000","1.30018","0.00390"
"2656","15.90000","1.32512","0.00431"
"2706","16.20000","1.35017","0.00453"
"2756","16.50000","1.37510","0.00432"
"2806","16.80000","1.40021","0.00424"
"2856","17.10000","1.42514","0.00483"
"2906","17.40000","1.45020","0.00433"
"2956","17.70000","1.47519","0.00451"
"3006","18.00000","1.50018","0.00462"
"3056","18.30000","1.52517","0.00522"
"3106","18.60000","1.55010","0.00492"
"3156","18.90000","1.57516","0.00498"
"3206","19.20000","1.60015","0.00446"
"3256","19.50000","1.62514","0.00437"
"3306","19.80000","1.65013","0.00486"
"3356","20.10000","1.67512","0.00434"
"3406","20.40000","1.70018","0.00540"
"3456","20.70000","1.72517","0.00507"
"3506","21.00000","1.75022","0.00496"
"3556","21.30000","1.77509","0.00524"
"3606","21.60000","1.80020","0.00520"
"3656","21.90000","1.82508","0.00530"
"3706","22.20000","1.85019","0.00531"
"3756","22.50000","1.87512","0.00538"
"3806","22.80000","1.90011","0.00530"
"3856","23.10000","1.92510","0.00555"
"3906","23.40000","1.95016","0.00522"
"3956","23.70000","1.97521","0.00563"
"4006","24.00000","2.00014","0.00598"
"4056","24.30000","2.02519","0.00588"
"4106","24.60000","2.05012","0.00551"
"4156","24.90000","2.07518","0.00552"
"4206","25.20000","2.10017","0.00586"
"4256","25.50000","2.12516","0.00568"
"4306","25.80000","2.15015","0.00564"
"4356","26.10000","2.17514","0.00589"
"4406","26.40000","2.20014","0.00585"
"4456","26.70000","2.22513","0.00524"
"4506","27.00000","2.25018","0.00586"
"4556","27.30000","2.27517","0.00550"
"4606","27.60000","2.30016","0.00517"
"4656","27.90000","2.32521","0.00542"
"4706","28.20000","2.35015","0.00576"
"4756","28.50000","2.37520","0.00604"
"4806","28.80000","2.40013","0.00639"
"4856","29.10000","2.42518","0.00522"
"4906","29.40000","2.45012","0.00517"
"4956","29.70000","2.47517","0.00546"
"5006","30.00000","2.50010","0.00498"
"5056","30.30000","2.52521","0.00488"
"5106","30.60000","2.55020","0.00521"
"5156","30.90000","2.57519","0.00473"
"5206","31.20000","2.60019","0.00530"
"5256","31.50000","2.62512","0.00499"
"5306","31.80000","2.65017","0.00481"
"5356","32.10000","2.67510","0.00517"
"5406","32.40000","2.70021","0.00595"
"5456","32.70000","2.72515","0.00434"
"5506","33.00000","2.75014","0.00482"
"5556","33.30000","2.77507","0.00477"
"5606","33.60000","2.80018","0.00537"
"5656","33.90000","2.82523","0.00496"
"5706","34.20000","2.85017","0.00472"
"5756","34.50000","2.87522","0.00547"
"5806","34.80000","2.90015","0.00466"
"5856","35.10000","2.92520","0.00538"
"5906","35.40000","2.95014","0.00495"
"5956","35.70000","2.97513","0.00542"
"6006","36.00000","3.00018","0.00509"
"6056","36.30000","3.02511","0.00502"
"6106","36.60000","3.05016","0.00532"
"6156","36.90000","3.07516","0.00461"
"6206","37.20000","3.10021","0.00579"
"6256","37.50000","3.12514","0.00545"
"6306","37.80000","3.15013","0.00531"
"6356","38.10000","3.17518","0.00567"
"6406","38.40000","3.20017","0.00539"
"6456","38.70000","3.22517","0.00604"
"6506","39.00000","3.25016","0.00516"
"6556","39.30000","3.27521","0.00549"
"6606","39.60000","3.30014","0.00550"
"6656","39.90000","3.32520","0.00521"
"6706","40.20000","3.35013","0.00590"
"6756","40.50000","3.37518","0.00543"
"6806","40.80000","3.40017","0.00535"
"6856","41.10000","3.42522","0.00573"
"6906","41.40000","3.45016","0.00593"
"6956","41.70000","3.47515","0.00576"
"7006","42.00000","3.50014","0.00576"
"7056","42.30000","3.52507","0.00538"
"7106","42.60000","3.55012","0.00553"
"7156","42.90000","3.57511","0.00561"
"7206","43.20000","3.60017","0.00570"
"7256","43.50000","3.62516","0.00583"
"7306","43.80000","3.65015","0.00615"
"7356","44.10000","3.67514","0.00616"
"7406","44.40000","3.70014","0.00595"
"7456","44.70000","3.72519","0.00570"
"7506","45.00000","3.75012","0.00555"
"7556","45.30000","3.77517","0.00511"
"7606","45.60000","3.80016","0.00547"
"7656","45.90000","3.82515","0.00559"
"7706","46.20000","3.85015","0.00572"
"7756","46.50000","3.87514","0.00578"
"7806","46.80000","3.90019","0.00587"
"7856","47.10000","3.92518","0.00570"
"7906","47.40000","3.95023","0.00568"
"7956","47.70000","3.97511","0.00551"
"8006","48.00000","4.00022","0.00526"
"8056","48.30000","4.02515","0.00565"
"8106","48.60000","4.05020","0.00614"
"8156","48.90000","4.07514","0.00561"
"8206","49.20000","4.10013","0.00533"
"8256","49.50000","4.12518","0.00563"
"8306","49.80000","4.15011","0.00572"
"8356","50.10000","4.17516","0.00505"
"8406","50.40000","4.20015","0.00535"
"8456","50.70000","4.22521","0.00518"
"8506","51.00000","4.25020","0.00570"
"8556","51.30000","4.27519","0.00557"
"8606","51.60000","4.30018","0.00543"
"8656","51.90000","4.32517","0.00555"
"8706","52.20000","4.35023","0.00548"
"8756","52.50000","4.37516","0.00573"
"8806","52.80000","4.40015","0.00548"
"8856","53.10000","4.42508","0.00602"
"8906","53.40000","4.45013","0.00554"
"8956","53.70000","4.47513","0.00553"
"9006","54.00000","4.50018","0.00573"
"9056","54.30000","4.52523","0.00532"
"9106","54.60000","4.55016","0.00540"
"9156","54.90000","4.57521","0.00569"
"9206","55.20000","4.60009","0.00533"
"9256","55.50000","4.62520","0.00607"
"9306","55.80000","4.65013","0.00567"
"9356","56.10000","4.67518","0.00604"
"9406","56.40000","4.70017","0.00550"
"9456","56.70000","4.72517","0.00603"
"9506","57.00000","4.75016","0.00638"
"9556","57.30000","4.77515","0.00633"
"9606","57.60000","4.80020","0.00618"
"9656","57.90000","4.82513","0.00611"
"9706","58.20000","4.85019","0.00610"
"9756","58.50000","4.87512","0.00621"
"9806","58.80000","4.90017","0.00573"
"9856","59.10000","4.92516","0.00625"
"9906","59.40000","4.95015","0.00645"
"9956","59.70000","4.97521","0.00595"
"10006","60.00000","5.00020","0.00636"
"10056","60.30000","5.02525","0.00600"
"10106","60.60000","5.05012","0.00622"
"10156","60.90000","5.07523","0.00615"
"10206","61.20000","5.10017","0.00620"
"10256","61.50000","5.12516","0.00576"
"10306","61.80000","5.15015","0.00638"
"10356","62.10000","5.17514","0.00614"
"10406","62.40000","5.20014","0.00652"
"10456","62.70000","5.22513","0.00580"
"10506","63.00000","5.25012","0.00626"
"10556","63.30000","5.27511","0.00576"
"10606","63.60000","5.30016","0.00638"
"10656","63.90000","5.32515","0.00582"
"10706","64.20000","5.35021","0.00619"
"10756","64.50000","5.37514","0.00632"
"10806","64.80000","5.40019","0.00588"
"10856","65.10000","5.42524","0.00572"
"10906","65.40000","5.45017","0.00585"
"10956","65.70000","5.47517","0.00646"
"11006","66.00000","5.50010","0.00659"
"11056","66.30000","5.52521","0.00602"
"11106","66.60000","5.55014","0.00650"
"11156","66.90000","5.57519","0.00621"
"11206","67.20000","5.60019","0.00640"
"11256","67.50000","5.62524","0.00661"
"11306","67.80000","5.65023","0.00700"
"11356","68.10000","5.67510","0.00608"
"11406","68.40000","5.70015","0.00682"
"11456","68.70000","5.72515","0.00604"
"11506","69.00000","5.75020","0.00652"
"11556","69.30000","5.77507","0.00613"
"11606","69.60000","5.80012","0.00655"
"11656","69.90000","5.82517","0.00621"
"11706","70.20000","5.85017","0.00660"
"11756","70.50000","5.87522","0.00667"
"11806","70.80000","5.90015","0.00652"
"11856","71.10000","5.92520","0.00644"
"11906","71.40000","5.95014","0.00673"
"11956","71.70000","5.97513","0.00639"
"12006","72.00000","6.00012","0.00628"
"12056","72.30000","6.02517","0.00649"
"12106","72.60000","6.05016","0.00650"
"12156","72.90000","6.07515","0.00649"
"12206","73.20000","6.10021","0.00636"
"12256","73.50000","6.12514","0.00665"
"12306","73.80000","6.15019","0.00652"
"12356","74.10000","6.17512","0.00679"
"12406","74.40000","6.20023","0.00625"
"12456","74.70000","6.22517","0.00667"
"12506","75.00000","6.25016","0.00612"
"12556","75.30000","6.27521","0.00650"
"12606","75.60000","6.30014","0.00739"
"12656","75.90000","6.32514","0.00684"
"12706","76.20000","6.35013","0.00698"
"12756","76.50000","6.37512","0.00642"
"12806","76.80000","6.40011","0.00639"
"12856","77.10000","6.42516","0.00453"
"12906","77.40000","6.45021","0.00434"
"12956","77.70000","6.47515","0.00414"
"13006","78.00000","6.50020","0.00377"
"13056","78.30000","6.52519","0.00368"
"13106","78.60000","6.55018","0.00460"
"13156","78.90000","6.57511","0.00430"
"13206","79.20000","6.60017","0.00426"
"13256","79.50000","6.62510","0.00430"
"13306","79.80000","6.65015","0.00414"
"13356","80.10000","6.67520","0.00464"
"13406","80.40000","6.70019","0.00432"
"13456","80.70000","6.72525","0.00416"
"13506","81.00000","6.75018","0.00471"
"13556","81.30000","6.77517","0.00460"
"13606","81.60000","6.80010","0.00391"
"13656","81.90000","6.82521","0.00436"
"13706","82.20000","6.85009","0.00453"
"13756","82.50000","6.87514","0.00445"
"13806","82.80000","6.90013","0.00508"
"13856","83.10000","6.92512","0.00436"
"13906","83.40000","6.95017","0.00447"
"13956","83.70000","6.97511","0.00504"
"14006","84.00000","7.00016","0.00449"
"14056","84.30000","7.02515","0.00459"
"14106","84.60000","7.05020","0.00463"
"14156","84.90000","7.07513","0.00494"
"14206","85.20000","7.10019","0.00435"
"14256","85.50000","7.12518","0.00435"
"14306","85.80000","7.15017","0.00452"
"14356","86.10000","7.17516","0.00409"
"14406","86.40000","7.20009","0.00411"
"14456","86.70000","7.22521","0.00462"
"14506","87.00000","7.25014","0.00415"
"14556","87.30000","7.27519","0.00449"
"14606","87.60000","7.30012","0.00482"
"14656","87.90000","7.32517","0.00449"
"14706","88.20000","7.35017","0.00457"
"14756","88.50000","7.37516","0.00463"
"14806","88.80000","7.40021","0.00454"
"14856","89.10000","7.42508","0.00490"
"14906","89.40000","7.45019","0.00516"
"14956","89.70000","7.47513","0.00475"
"15006","90.00000","7.50018","0.00528"
"15056","90.30000","7.52517","0.00488"
"15106","90.60000","7.55022","0.00482"
"15156","90.90000","7.57521","0.00523"
"15206","91.20000","7.60015","0.00523"
"15256","91.50000","7.62520","0.00491"
"15306","91.80000","7.65013","0.00490"
"15356","92.10000","7.67518","0.00488"
"15406","92.40000","7.70006","0.00490"
"15456","92.70000","7.72517","0.00488"
"15506","93.00000","7.75016","0.00501"
"15556","93.30000","7.77515","0.00485"
"15606","93.60000","7.80014","0.00519"
"15656","93.90000","7.82513","0.00508"
"15706","94.20000","7.85019","0.00493"
"15756","94.50000","7.87512","0.00458"
"15806","94.80000","7.90017","0.00524"
"15856","95.10000","7.92510","0.00511"
"15906","95.40000","7.95015","0.00497"
"15956","95.70000","7.97515","0.00477"
"16006","96.00000","8.00014","0.00507"
"16056","96.30000","8.02519","0.00533"
"16106","96.60000","8.05012","0.00548"
"16156","96.90000","8.07517","0.00520"
"16206","97.20000","8.10011","0.00479"
"16256","97.50000","8.12522","0.00489"
"16306","97.80000","8.15015","0.00489"
"16356","98.10000","8.17520","0.00489"
"16406","98.40000","8.20013","0.00542"
"16456","98.70000","8.22513","0.00477"
"16506","99.00000","8.25018","0.00508"
"16556","99.30000","8.27517","0.00520"
"16606","99.60000","8.30016","0.00564"
"16656","99.90000","8.32509","0.00529"
"16706","100.20000","8.35021","0.00522"
"16756","100.50000","8.37520","0.00524"
"16806","100.80000","8.40019","0.00531"
"16856","101.10000","8.42512","0.00570"
"16906","101.40000","8.45017","0.00563"
"16956","101.70000","8.47517","0.00570"
"17006","102.00000","8.50010","0.00587"
"17056","102.30000","8.52515","0.00577"
"17106","102.60000","8.55008","0.00550"
"17156","102.90000","8.57513","0.00517"
"17206","103.20000","8.60013","0.00536"
"17256","103.50000","8.62518","0.00552"
"17306","103.80000","8.65017","0.00551"
"17356","104.10000","8.67522","0.00544"
"17406","104.40000","8.70021","0.00584"
"17456","104.70000","8.72515","0.00542"
"17506","105.00000","8.75020","0.00585"
"17556","105.30000","8.77513","0.00558"
"17606","105.60000","8.80012","0.00530"
"17656","105.90000","8.82517","0.00557"
"17706","106.20000","8.85017","0.00572"
"17756","106.50000","8.87522","0.00580"
"17806","106.80000","8.90015","0.00639"
"17856","107.10000","8.92520","0.00583"
"17906","107.40000","8.95013","0.00607"
"17956","107.70000","8.97519","0.00588"
"18006","108.00000","9.00006","0.00589"
"18056","108.30000","9.02523","0.00566"
"18106","108.60000","9.05016","0.00600"
"18156","108.90000","9.07515","0.00543"
"18206","109.20000","9.10015","0.00574"
"18256","109.50000","9.12514","0.00563"
"18306","109.80000","9.15019","0.00563"
"18356","110.10000","9.17518","0.00595"
"18406","110.40000","9.20023","0.00620"
"18456","110.70000","9.22517","0.00539"
"18506","111.00000","9.25022","0.00579"
"18556","111.30000","9.27515","0.00582"
"18606","111.60000","9.30014","0.00590"
"18656","111.90000","9.32519","0.00535"
"18706","112.20000","9.35013","0.00591"
"18756","112.50000","9.37518","0.00535"
"18806","112.80000","9.40017","0.00569"
"18856","113.10000","9.42516","0.00553"
"18906","113.40000","9.45015","0.00571"
"18956","113.70000","9.47515","0.00574"
"19006","114.00000","9.50014","0.00583"
"19056","114.30000","9.52519","0.00568"
"19106","114.60000","9.55018","0.00623"
"19156","114.90000","9.57511","0.00585"
"19206","115.20000","9.60017","0.00604"
"19256","115.50000","9.62510","0.00568"
"19306","115.80000","9.65021","0.00640"
"19356","116.10000","9.67514","0.00594"
"19406","116.40000","9.70019","0.00608"
"19456","116.70000","9.72519","0.00568"
"19506","117.00000","9.75018","0.00590"
"19556","117.30000","9.77523","0.00620"
"19606","117.60000","9.80010","0.00609"
"19656","117.90000","9.82515","0.00616"
"19706","118.20000","9.85015","0.00586"
"19756","118.50000","9.87520","0.00590"
"19806","118.80000","9.90013","0.00564"
"19856","119.10000","9.92518","0.00576"
"19906","119.40000","9.95011","0.00552"
"19956","119.70000","9.97517","0.00586"
"20006","120.00000","10.00022","0.00587"
"20056","120.30000","10.02515","0.00592"
"20106","120.60000","10.05020","0.00582"
"20156","120.90000","10.07513","0.00589"
"20206","121.20000","10.10019","0.00614"
"20256","121.50000","10.12512","0.00586"
"20306","121.80000","10.15017","0.00609"
"20356","122.10000","10.17516","0.00586"
"20406","122.40000","10.20009","0.00502"
"20456","122.70000","10.22515","0.00547"
"20506","123.00000","10.25014","0.00542"
"20556","123.30000","10.27519","0.00468"
"20606","123.60000","10.30018","0.00569"
"20656","123.90000","10.32517","0.00532"
"20706","124.20000","10.35017","0.00512"
"20756","124.50000","10.37516","0.00515"
"20806","124.80000","10.40015","0.00548"
"20856","125.10000","10.42514","0.00573"
"20906","125.40000","10.45019","0.00521"
"20956","125.70000","10.47513","0.00514"
"21006","126.00000","10.50024","0.00552"
"21056","126.30000","10.52517","0.00536"
"21106","126.60000","10.55022","0.00552"
"21156","126.90000","10.57515","0.00540"
"21206","127.20000","10.60021","0.00539"
"21256","127.50000","10.62514","0.00565"
"21306","127.80000","10.65013","0.00561"
"21356","128.10000","10.67512","0.00581"
"21406","128.40000","10.70005","0.00549"
"21456","128.70000","10.72517","0.00606"
"21506","129.00000","10.75010","0.00557"
"21556","129.30000","10.77515","0.00598"
"21606","129.60000","10.80014","0.00579"
"21656","129.90000","10.82519","0.00566"
"21706","130.20000","10.85025","0.00579"
"21756","130.50000","10.87518","0.00547"
"21806","130.80000","10.90017","0.00538"
"21856","131.10000","10.92516","0.00559"
"21906","131.40000","10.95021","0.00544"
"21956","131.70000","10.97515","0.00544"
"22006","132.00000","11.00020","0.00562"
"22056","132.30000","11.02519","0.00582"
"22106","132.60000","11.05012","0.00547"
"22156","132.90000","11.07517","0.00549"
"22206","133.20000","11.10017","0.00561"
"22256","133.50000","11.12522","0.00557"
"22306","133.80000","11.15009","0.00576"
"22356","134.10000","11.17520","0.00499"
"22406","134.40000","11.20013","0.00543"
"22456","134.70000","11.22513","0.00555"
"22506","135.00000","11.25012","0.00521"
"22556","135.30000","11.27511","0.00558"
"22606","135.60000","11.30016","0.00546"
"22656","135.90000","11.32515","0.00564"
"22706","136.20000","11.35021","0.00579"
"22756","136.50000","11.37514","0.00560"
"22806","136.80000","11.40019","0.00588"
"22856","137.10000","11.42512","0.00530"
"22906","137.40000","11.45011","0.00536"
"22956","137.70000","11.47517","0.00535"
"23006","138.00000","11.50016","0.00553"
"23056","138.30000","11.52515","0.00561"
"23106","138.60000","11.55008","0.00594"
"23156","138.90000","11.57513","0.00570"
"23206","139.20000","11.60007","0.00559"
"23256","139.50000","11.62518","0.00585"
"23306","139.80000","11.65017","0.00555"
"23356","140.10000","11.67522","0.00508"
"23406","140.40000","11.70021","0.00577"
"23456","140.70000","11.72515","0.00535"
"23506","141.00000","11.75020","0.00520"
"23556","141.30000","11.77513","0.00576"
"23606","141.60000","11.80018","0.00542"
"23656","141.90000","11.82505","0.00581"
"23706","142.20000","11.85022","0.00560"
"23756","142.50000","11.87516","0.00504"
"23806","142.80000","11.90015","0.00547"
"23856","143.10000","11.92514","0.00538"
"23906","143.40000","11.95013","0.00529"
"23956","143.70000","11.97524","0.00508"
"24006","144.00000","12.00018","0.00481"
"24056","144.30000","12.02517","0.00472"
"24106","144.60000","12.05010","0.00503"
"24156","144.90000","12.07521","0.00457"
"24206","145.20000","12.10015","0.00518"
"24256","145.50000","12.12514","0.00527"
"24306","145.80000","12.15019","0.00508"
"24356","146.10000","12.17512","0.00482"
"24406","146.40000","12.20017","0.00522"
"24456","146.70000","12.22517","0.00505"
"24506","147.00000","12.25022","0.00496"
"24556","147.30000","12.27515","0.00496"
"24606","147.60000","12.30014","0.00484"
"24656","147.90000","12.32513","0.00461"
"24706","148.20000","12.35013","0.00493"
"24756","148.50000","12.37518","0.00498"
"24806","148.80000","12.40011","0.00477"
"24856","149.10000","12.42516","0.00535"
"24906","149.40000","12.45009","0.00537"
"24956","149.70000","12.47521","0.00526"
"25006","150.00000","12.50014","0.00474"
"25056","150.30000","12.52519","0.00472"
"25106","150.60000","12.55018","0.00544"
"25156","150.90000","12.57517","0.00535"
"25206","151.20000","12.60023","0.00497"
"25256","151.50000","12.62516","0.00539"
"25306","151.80000","12.65015","0.00544"
"25356","152.10000","12.67508","0.00570"
"25406","152.40000","12.70019","0.00532"
"25456","152.70000","12.72513","0.00535"
"25506","153.00000","12.75018","0.00566"
"25556","153.30000","12.77517","0.00562"
"25606","153.60000","12.80022","0.00556"
"25656","153.90000","12.82521","0.00577"
"25706","154.20000","12.85015","0.00554"
"25756","154.50000","12.87520","0.00504"
"25806","154.80000","12.90007","0.00532"
"25856","155.10000","12.92518","0.00526"
"25906","155.40000","12.95012","0.00568"
"25956","155.70000","12.97517","0.00549"
"26006","156.00000","13.00016","0.00540"
"26056","156.30000","13.02509","0.00516"
"26106","156.60000","13.05020","0.00543"
"26156","156.90000","13.07513","0.00546"
"26206","157.20000","13.10019","0.00613"
"26256","157.50000","13.12512","0.00598"
"26306","157.80000","13.15023","0.00563"
"26356","158.10000","13.17516","0.00549"
"26406","158.40000","13.20015","0.00622"
"26456","158.70000","13.22515","0.00547"
"26506","159.00000","13.25014","0.00629"
"26556","159.30000","13.27525","0.00585"
"26606","159.60000","13.30018","0.00583"
"26656","159.90000","13.32523","0.00509"
"26706","160.20000","13.35017","0.00570"
"26756","160.50000","13.37516","0.00601"
"26806","160.80000","13.40015","0.00587"
"26856","161.10000","13.42520","0.00529"
"26906","161.40000","13.45019","0.00557"
"26956","161.70000","13.47519","0.00544"
"27006","162.00000","13.50012","0.00514"
"27056","162.30000","13.52511","0.00588"
"27106","162.60000","13.55016","0.00563"
"27156","162.90000","13.57515","0.00606"
"27206","163.20000","13.60021","0.00597"
"27256","163.50000","13.62520","0.00582"
"27306","163.80000","13.65019","0.00529"
"27356","164.10000","13.67518","0.00577"
"27406","164.40000","13.70017","0.00522"
"27456","164.70000","13.72517","0.00580"
"27506","165.00000","13.75010","0.00585"
"27556","165.30000","13.77521","0.00502"
"27606","165.60000","13.80014","0.00531"
"27656","165.90000","13.82519","0.00566"
"27706","166.20000","13.85019","0.00559"
"27756","166.50000","13.87518","0.00568"
"27806","166.80000","13.90023","0.00552"
"27856","167.10000","13.92516","0.00626"
"27906","167.40000","13.95015","0.00616"
"27956","167.70000","13.97509","0.00611"
"28006","168.00000","14.00020","0.00626"
"28056","168.30000","14.02507","0.00563"
"28106","168.60000","14.05012","0.00592"
"28156","168.90000","14.07511","0.00538"
"28206","169.20000","14.10017","0.00594"
"28256","169.50000","14.12516","0.00552"
"28306","169.80000","14.15015","0.00569"
"28356","170.10000","14.17520","0.00604"
"28406","170.40000","14.20013","0.00557"
"28456","170.70000","14.22519","0.00575"
"28506","171.00000","14.25012","0.00537"
"28556","171.30000","14.27517","0.00543"
"28606","171.60000","14.30016","0.00552"
"28656","171.90000","14.32515","0.00546"
"28706","172.20000","14.35021","0.00559"
"28756","172.50000","14.37514","0.00561"
"28806","172.80000","14.40019","0.00576"
"28856","173.10000","14.42512","0.00594"
"28906","173.40000","14.45011","0.00609"
"28956","173.70000","14.47511","0.00566"
"29006","174.00000","14.50016","0.00550"
"29056","174.30000","14.52521","0.00564"
"29106","174.60000","14.55014","0.00591"
"29156","174.90000","14.57519","0.00589"
"29206","175.20000","14.60013","0.00615"
"29256","175.50000","14.62512","0.00573"
"29306","175.80000","14.65011","0.00578"
"29356","176.10000","14.67522","0.00595"
"29406","176.40000","14.70015","0.00569"
"29456","176.70000","14.72521","0.00575"
"29506","177.00000","14.75020","0.00572"
"29556","177.30000","14.77513","0.00573"
"29606","177.60000","14.80018","0.00523"
"29656","177.90000","14.82511","0.00539"
"29706","178.20000","14.85017","0.00553"
"29756","178.50000","14.87510","0.00546"
"29806","178.80000","14.90021","0.00604"
"29856","179.10000","14.92514","0.00558"
"29906","179.40000","14.95014","0.00599"
"29956","179.70000","14.97519","0.00560"
"30006","180.00000","15.00018","0.00576"
"30056","180.30000","15.02517","0.00606"
"30106","180.60000","15.05010","0.00541"
"30156","180.90000","15.07515","0.00579"
"30206","181.20000","15.10015","0.00567"
"30256","181.50000","15.12520","0.00491"
"30306","181.80000","15.15013","0.00611"
"30356","182.10000","15.17512","0.00525"
"30406","182.40000","15.20017","0.00536"
"30456","182.70000","15.22517","0.00533"
"30506","183.00000","15.25022","0.00524"
"30556","183.30000","15.27515","0.00561"
"30606","183.60000","15.30020","0.00529"
"30656","183.90000","15.32513","0.00572"
"30706","184.20000","15.35019","0.00552"
"30756","184.50000","15.37518","0.00564"
"30806","184.80000","15.40017","0.00544"
"30856","185.10000","15.42522","0.00550"
"30906","185.40000","15.45015","0.00539"
"30956","185.70000","15.47521","0.00538"
"31006","186.00000","15.50008","0.00524"
"31056","186.30000","15.52519","0.00544"
"31106","186.60000","15.55012","0.00547"
"31156","186.90000","15.57517","0.00553"
"31206","187.20000","15.60017","0.00537"
"31256","187.50000","15.62516","0.00491"
"31306","187.80000","15.65015","0.00516"
"31356","188.10000","15.67508","0.00581"
"31406","188.40000","15.70013","0.00543"
"31456","188.70000","15.72507","0.00495"
"31506","189.00000","15.75018","0.00561"
"31556","189.30000","15.77517","0.00526"
"31606","189.60000","15.80016","0.00549"
"31656","189.90000","15.82515","0.00506"
"31706","190.20000","15.85015","0.00512"
"31756","190.50000","15.87520","0.00534"
"31806","190.80000","15.90013","0.00523"
"31856","191.10000","15.92518","0.00497"
"31906","191.40000","15.95011","0.00537"
"31956","191.70000","15.97516","0.00530"
"32006","192.00000","16.00016","0.00513"
"32056","192.30000","16.02515","0.00467"
"32106","192.60000","16.05020","0.00496"
"32156","192.90000","16.07519","0.00471"
"32206","193.20000","16.10024","0.00497"
"32256","193.50000","16.12512","0.00504"
"32306","193.80000","16.15017","0.00556"
"32356","194.10000","16.17510","0.00510"
"32406","194.40000","16.20021","0.00491"
"32456","194.70000","16.22508","0.00568"
"32506","195.00000","16.25014","0.00518"
"32556","195.30000","16.27513","0.00472"
"32606","195.60000","16.30018","0.00540"
"32656","195.90000","16.32523","0.00525"
"32706","196.20000","16.35016","0.00505"
"32756","196.50000","16.37522","0.00518"
"32806","196.80000","16.40015","0.00565"
"32856","197.10000","16.42520","0.00584"
"32906","197.40000","16.45013","0.00566"
"32956","197.70000","16.47519","0.00567"
"33006","198.00000","16.50018","0.00512"
"33056","198.30000","16.52517","0.00507"
"33106","198.60000","16.55016","0.00519"
"33156","198.90000","16.57509","0.00540"
"33206","199.20000","16.60015","0.00490"
"33256","199.50000","16.62514","0.00545"
"33306","199.80000","16.65019","0.00570"
"33356","200.10000","16.67518","0.00532"
"33406","200.40000","16.70017","0.00510"
"33456","200.70000","16.72523","0.00553"
"33506","201.00000","16.75016","0.00557"
"33556","201.30000","16.77515","0.00497"
"33606","201.60000","16.80014","0.00537"
"33656","201.90000","16.82519","0.00525"
"33706","202.20000","16.85012","0.00539"
"33756","202.50000","16.87518","0.00506"
"33806","202.80000","16.90017","0.00552"
"33856","203.10000","16.92516","0.00511"
"33906","203.40000","16.95021","0.00546"
"33956","203.70000","16.97509","0.00577"
"34006","204.00000","17.00014","0.00569"
"34056","204.30000","17.02507","0.00562"
"34106","204.60000","17.05018","0.00520"
"34156","204.90000","17.07511","0.00551"
"34206","205.20000","17.10016","0.00589"
"34256","205.50000","17.12516","0.00522"
"34306","205.80000","17.15015","0.00548"
"34356","206.10000","17.17526","0.00536"
"34406","206.40000","17.20019","0.00586"
"34456","206.70000","17.22519","0.00599"
"34506","207.00000","17.25012","0.00545"
"34556","207.30000","17.27517","0.00531"
"34606","207.60000","17.30010","0.00542"
"34656","207.90000","17.32509","0.00582"
"34706","208.20000","17.35015","0.00612"
"34756","208.50000","17.37508","0.00514"
"34806","208.80000","17.40019","0.00574"
"34856","209.10000","17.42512","0.00534"
"34906","209.40000","17.45017","0.00619"
"34956","209.70000","17.47511","0.00598"
"35006","210.00000","17.50022","0.00571"
"35056","210.30000","17.52515","0.00571"
"35106","210.60000","17.55020","0.00560"
"35156","210.90000","17.57519","0.00520"
"35206","211.20000","17.60012","0.00553"
"35256","211.50000","17.62518","0.00554"
"35306","211.80000","17.65011","0.00559"
"35356","212.10000","17.67516","0.00540"
"35406","212.40000","17.70015","0.00597"
"35456","212.70000","17.72520","0.00571"
"35506","213.00000","17.75014","0.00593"
"35556","213.30000","17.77519","0.00577"
"35606","213.60000","17.80018","0.00567"
"35656","213.90000","17.82511","0.00603"
"35706","214.20000","17.85016","0.00574"
"35756","214.50000","17.87510","0.00624"
"35806","214.80000","17.90021","0.00589"
"35856","215.10000","17.92508","0.00568"
"35906","215.40000","17.95013","0.00571"
"35956","215.70000","17.97513","0.00534"
"36006","216.00000","18.00018","0.00572"
"36056","216.30000","18.02523","0.00574"
"36106","216.60000","18.05016","0.00563"
"36156","216.90000","18.07515","0.00576"
"36206","217.20000","18.10014","0.00603"
"36256","217.50000","18.12520","0.00566"
"36306","217.80000","18.15013","0.00568"
"36356","218.10000","18.17518","0.00515"
"36406","218.40000","18.20017","0.00579"
"36456","218.70000","18.22511","0.00607"
"36506","219.00000","18.25022","0.00600"
"36556","219.30000","18.27515","0.00579"
"36606","219.60000","18.30020","0.00589"
"36656","219.90000","18.32513","0.00589"
"36706","220.20000","18.35019","0.00615"
"36756","220.50000","18.37518","0.00588"
"36806","220.80000","18.40017","0.00608"
"36856","221.10000","18.42510","0.00582"
"36906","221.40000","18.45009","0.00520"
"36956","221.70000","18.47520","0.00479"
"37006","222.00000","18.50014","0.00526"
"37056","222.30000","18.52519","0.00570"
"37106","222.60000","18.55012","0.00609"
"37156","222.90000","18.57517","0.00564"
"37206","223.20000","18.60017","0.00592"
"37256","223.50000","18.62522","0.00589"
"37306","223.80000","18.65021","0.00593"
"37356","224.10000","18.67514","0.00638"
"37406","224.40000","18.70019","0.00584"
"37456","224.70000","18.72512","0.00592"
"37506","225.00000","18.75012","0.00612"
"37556","225.30000","18.77511","0.00588"
"37606","225.60000","18.80022","0.00608"
"37656","225.90000","18.82515","0.00584"
"37706","226.20000","18.85021","0.00615"
"37756","226.50000","18.87520","0.00585"
"37806","226.80000","18.90019","0.00616"
"37856","227.10000","18.92518","0.00582"
"37906","227.40000","18.95011","0.00607"
"37956","227.70000","18.97516","0.00603"
"38006","228.00000","19.00010","0.00630"
"38056","228.30000","19.02515","0.00627"
"38106","228.60000","19.05014","0.00642"
"38156","228.90000","19.07519","0.00636"
"38206","229.20000","19.10019","0.00659"
"38256","229.50000","19.12512","0.00591"
"38306","229.80000","19.15017","0.00639"
"38356","230.10000","19.17510","0.00650"
"38406","230.40000","19.20015","0.00681"
"38456","230.70000","19.22508","0.00677"
"38506","231.00000","19.25020","0.00626"
"38556","231.30000","19.27513","0.00645"
"38606","231.60000","19.30012","0.00689"
"38656","231.90000","19.32517","0.00688"
"38706","232.20000","19.35017","0.00677"
"38756","232.50000","19.37522","0.00702"
"38806","232.80000","19.40015","0.00655"
"38856","233.10000","19.42520","0.00684"
"38906","233.40000","19.45019","0.00661"
"38956","233.70000","19.47518","0.00705"
"39006","234.00000","19.50018","0.00687"
"39056","234.30000","19.52511","0.00717"
"39106","234.60000","19.55016","0.00699"
"39156","234.90000","19.57509","0.00724"
"39206","235.20000","19.60015","0.00717"
"39256","235.50000","19.62507","0.00690"
"39306","235.80000","19.65019","0.00676"
"39356","236.10000","19.67518","0.00724"
"39406","236.40000","19.70023","0.00745"
"39456","236.70000","19.72516","0.00685"
"39506","237.00000","19.75016","0.00655"
"39556","237.30000","19.77521","0.00722"
"39606","237.60000","19.80014","0.00699"
"39656","237.90000","19.82519","0.00726"
"39706","238.20000","19.85013","0.00725"
"39756","238.50000","19.87518","0.00747"
"39806","238.80000","19.90017","0.00750"
"39856","239.10000","19.92522","0.00814"
"39906","239.40000","19.95015","0.00790"
"39956","239.70000","19.97520","0.00776"
"40006","240.00000","20.00020","0.00748"
"40056","240.30000","20.02513","0.00792"
"40106","240.60000","20.05012","0.00807"
"40156","240.90000","20.07511","0.00771"
"40206","241.20000","20.10016","0.00808"
"40256","241.50000","20.12516","0.00849"
"40306","241.80000","20.15015","0.00811"
"40356","242.10000","20.17514","0.00794"
"40406","242.40000","20.20013","0.00781"
"40456","242.70000","20.22525","0.00796"
"40506","243.00000","20.25012","0.00801"
"40556","243.30000","20.27517","0.00772"
"40606","243.60000","20.30010","0.00834"
"40656","243.90000","20.32515","0.00824"
"40706","244.20000","20.35015","0.00867"
"40756","244.50000","20.37514","0.00830"
"40806","244.80000","20.40019","0.00829"
"40856","245.10000","20.42512","0.00891"
"40906","245.40000","20.45017","0.00884"
"40956","245.70000","20.47511","0.00886"
"41006","246.00000","20.50022","0.00864"
"41056","246.30000","20.52515","0.00843"
"41106","246.60000","20.55020","0.00860"
"41156","246.90000","20.57513","0.00860"
"41206","247.20000","20.60019","0.00903"
"41256","247.50000","20.62518","0.00874"
"41306","247.80000","20.65011","0.00835"
"41356","248.10000","20.67516","0.00894"
"41406","248.40000","20.70015","0.00858"
"41456","248.70000","20.72521","0.00844"
"41506","249.00000","20.75014","0.00839"
"41556","249.30000","20.77519","0.00895"
"41606","249.60000","20.80018","0.00927"
"41656","249.90000","20.82517","0.00882"
"41706","250.20000","20.85016","0.00920"
"41756","250.50000","20.87516","0.00918"
"41806","250.80000","20.90021","0.00911"
"41856","251.10000","20.92514","0.00915"
"41906","251.40000","20.95019","0.00953"
"41956","251.70000","20.97513","0.00961"
"42006","252.00000","21.00018","0.00985"
"42056","252.30000","21.02517","0.00951"
"42106","252.60000","21.05022","0.00960"
"42156","252.90000","21.07521","0.00997"
"42206","253.20000","21.10015","0.00988"
"42256","253.50000","21.12514","0.00950"
"42306","253.80000","21.15013","0.01001"
"42356","254.10000","21.17518","0.00985"
"42406","254.40000","21.20011","0.01005"
"42456","254.70000","21.22517","0.01000"
"42506","255.00000","21.25010","0.01038"
"42556","255.30000","21.27515","0.01046"
"42606","255.60000","21.30020","0.01048"
"42656","255.90000","21.32519","0.01049"
"42706","256.20000","21.35018","0.01072"
"42756","256.50000","21.37518","0.01103"
"42806","256.80000","21.40023","0.01094"
"42856","257.10000","21.42516","0.01082"
"42906","257.40000","21.45015","0.01073"
"42956","257.70000","21.47515","0.01105"
"43006","258.00000","21.50014","0.01116"
"43056","258.30000","21.52519","0.01110"
"43106","258.60000","21.55012","0.01099"
"43156","258.90000","21.57517","0.01138"
"43206","259.20000","21.60016","0.01129"
"43256","259.50000","21.62522","0.01122"
"43306","259.80000","21.65015","0.01164"
"43356","260.10000","21.67514","0.01146"
"43406","260.40000","21.70013","0.01187"
"43456","260.70000","21.72513","0.01153"
"43506","261.00000","21.75012","0.01197"
"43556","261.30000","21.77511","0.01204"
"43606","261.60000","21.80016","0.01199"
"43656","261.90000","21.82515","0.01215"
"43706","262.20000","21.85020","0.01248"
"43756","262.50000","21.87514","0.01233"
"43806","262.80000","21.90019","0.01269"
"43856","263.10000","21.92524","0.01289"
"43906","263.40000","21.95011","0.01283"
"43956","263.70000","21.97516","0.01288"
"44006","264.00000","22.00010","0.01298"
"44056","264.30000","22.02521","0.01298"
"44106","264.60000","22.05008","0.01323"
"44156","264.90000","22.07519","0.01343"
"44206","265.20000","22.10012","0.01307"
"44256","265.50000","22.12518","0.01336"
"44306","265.80000","22.15017","0.01342"
"44356","266.10000","22.17516","0.01364"
"44406","266.40000","22.20015","0.01397"
"44456","266.70000","22.22515","0.01404"
"44506","267.00000","22.25020","0.01373"
"44556","267.30000","22.27513","0.01397"
"44606","267.60000","22.30018","0.01435"
"44656","267.90000","22.32511","0.01441"
"44706","268.20000","22.35011","0.01459"
"44756","268.50000","22.37516","0.01447"
"44806","268.80000","22.40015","0.01463"
"44856","269.10000","22.42520","0.01459"
"44906","269.40000","22.45013","0.01474"
"44956","269.70000","22.47518","0.01525"
"45006","270.00000","22.50018","0.01539"
"45056","270.30000","22.52517","0.01488"
"45106","270.60000","22.55016","0.01508"
"45156","270.90000","22.57515","0.01525"
"45206","271.20000","22.60020","0.01551"
"45256","271.50000","22.62514","0.01550"
"45306","271.80000","22.65019","0.01583"
"45356","272.10000","22.67512","0.01623"
"45406","272.40000","22.70017","0.01634"
"45456","272.70000","22.72516","0.01621"
"45506","273.00000","22.75022","0.01659"
"45556","273.30000","22.77515","0.01641"
"45606","273.60000","22.80014","0.01694"
"45656","273.90000","22.82519","0.01690"
"45706","274.20000","22.85013","0.01725"
"45756","274.50000","22.87518","0.01747"
"45806","274.80000","22.90011","0.01791"
"45856","275.10000","22.92516","0.01825"
"45906","275.40000","22.95015","0.01825"
"45956","275.70000","22.97514","0.01820"
"46006","276.00000","23.00020","0.01845"
"46056","276.30000","23.02519","0.01885"
"46106","276.60000","23.05018","0.01942"
"46156","276.90000","23.07511","0.01965"
"46206","277.20000","23.10016","0.01983"
"46256","277.50000","23.12510","0.01974"
"46306","277.80000","23.15015","0.02003"
"46356","278.10000","23.17514","0.02043"
"46406","278.40000","23.20019","0.02033"
"46456","278.70000","23.22524","0.01961"
"46506","279.00000","23.25012","0.01961"
"46556","279.30000","23.27517","0.02056"
"46606","279.60000","23.30010","0.02055"
"46656","279.90000","23.32515","0.02114"
"46706","280.20000","23.35008","0.02109"
"46756","280.50000","23.37514","0.02142"
"46806","280.80000","23.40007","0.02178"
"46856","281.10000","23.42512","0.02221"
"46906","281.40000","23.45017","0.02230"
"46956","281.70000","23.47510","0.02274"
"47006","282.00000","23.50022","0.02331"
"47056","282.30000","23.52515","0.02302"
"47106","282.60000","23.55020","0.02376"
"47156","282.90000","23.57513","0.02475"
"47206","283.20000","23.60018","0.02493"
"47256","283.50000","23.62512","0.02555"
"47306","283.80000","23.65017","0.02587"
"47356","284.10000","23.67516","0.02633"
"47406","284.40000","23.70015","0.02680"
"47456","284.70000","23.72520","0.02729"
"47506","285.00000","23.75014","0.02759"
"47556","285.30000","23.77519","0.02807"
"47606","285.60000","23.80012","0.02828"
"47656","285.90000","23.82517","0.02902"
"47706","286.20000","23.85016","0.02902"
"47756","286.50000","23.87515","0.02985"
"47806","286.80000","23.90021","0.03062"
"47856","287.10000","23.92514","0.03110"
"47906","287.40000","23.95019","0.03181"
"47956","287.70000","23.97512","0.03245"
"48006","288.00000","24.00018","0.03276"
"48056","288.30000","24.02517","0.03331"
"48106","288.60000","24.05016","0.03394"
"48156","288.90000","24.07521","0.03392"
"48206","289.20000","24.10020","0.03486"
"48256","289.50000","24.12520","0.03589"
"48306","289.80000","24.15013","0.03586"
"48356","290.10000","24.17518","0.03620"
"48406","290.40000","24.20005","0.03734"
"48456","290.70000","24.22523","0.03856"
"48506","291.00000","24.25016","0.03921"
"48556","291.30000","24.27521","0.03574"
"48606","291.60000","24.30014","0.03829"
"48656","291.90000","24.32519","0.03752"
"48706","292.20000","24.35024","0.03984"
"48756","292.50000","24.37518","0.03976"
"48806","292.80000","24.40017","0.04261"
"48856","293.10000","24.42516","0.04251"
"48906","293.40000","24.45021","0.04392"
"48956","293.70000","24.47508","0.04331"
"49006","294.00000","24.50008","0.04533"
"49056","294.30000","24.52519","0.04495"
"49106","294.60000","24.55012","0.04707"
"49156","294.90000","24.57517","0.04780"
"49206","295.20000","24.60010","0.04848"
"49256","295.50000","24.62522","0.04922"
"49306","295.80000","24.65015","0.05043"
"49356","296.10000","24.67514","0.05066"
"49406","296.40000","24.70019","0.05204"
"49456","296.70000","24.72518","0.05183"
"49506","297.00000","24.75018","0.05328"
"49556","297.30000","24.77511","0.05410"
"49606","297.60000","24.80016","0.05519"
"49656","297.90000","24.82515","0.05560"
"49706","298.20000","24.85020","0.05717"
"49756","298.50000","24.87514","0.05781"
"49806","298.80000","24.90019","0.05879"
"49856","299.10000","24.92518","0.05918"
"49906","299.40000","24.95023","0.06000"
"49956","299.70000","24.97517","0.06026"
"50006","300.00000","25.00015","0.06197"
"50056","300.30000","25.02515","0.06165"
"50106","300.60000","25.05008","0.06319"
"50156","300.90000","25.07513","0.06354"
"50206","301.20000","25.10007","0.06399"
"50256","301.50000","25.12518","0.06495"
"50306","301.80000","25.15017","0.06607"
"50356","302.10000","25.17516","0.06776"
"50406","302.40000","25.20015","0.06873"
"50456","302.70000","25.22514","0.06965"
"50506","303.00000","25.25014","0.07050"
"50556","303.30000","25.27513","0.07154"
"50606","303.60000","25.30018","0.07278"
"50656","303.90000","25.32511","0.07415"
"50706","304.20000","25.35016","0.07518"
"50756","304.50000","25.37516","0.07673"
"50806","304.80000","25.40015","0.07795"
"50856","305.10000","25.42520","0.07949"
"50906","305.40000","25.45019","0.08072"
"50956","305.70000","25.47518","0.08260"
"51006","306.00000","25.50011","0.08452"
"51056","306.30000","25.52517","0.08579"
"51106","306.60000","25.55016","0.08701"
"51156","306.90000","25.57515","0.08886"
"51206","307.20000","25.60014","0.09032"
"51256","307.50000","25.62514","0.09127"
"51306","307.80000","25.65019","0.09236"
"51356","308.10000","25.67512","0.09416"
"51406","308.40000","25.70017","0.09408"
"51456","308.70000","25.72516","0.09543"
"51506","309.00000","25.75022","0.09670"
"51556","309.30000","25.77521","0.09712"
"51606","309.60000","25.80020","0.09807"
"51656","309.90000","25.82519","0.09901"
"51706","310.20000","25.85018","0.09947"
"51756","310.50000","25.87523","0.10040"
"51806","310.80000","25.90011","0.10073"
"51856","311.10000","25.92516","0.10190"
"51906","311.40000","25.95009","0.10198"
"51956","311.70000","25.97515","0.10255"
"52006","312.00000","26.00014","0.10313"
"52056","312.30000","26.02519","0.10367"
"52106","312.60000","26.05024","0.10435"
"52156","312.90000","26.07517","0.10461"
"52206","313.20000","26.10017","0.10496"
"52256","313.50000","26.12510","0.10563"
"52306","313.80000","26.15021","0.10618"
"52356","314.10000","26.17514","0.10635"
"52406","314.40000","26.20019","0.10708"
"52456","314.70000","26.22519","0.10733"
"52506","315.00000","26.25018","0.10832"
"52556","315.30000","26.27517","0.10856"
"52606","315.60000","26.30010","0.10949"
"52656","315.90000","26.32521","0.11060"
"52706","316.20000","26.35014","0.11100"
"52756","316.50000","26.37519","0.11207"
"52806","316.80000","26.40013","0.11363"
"52856","317.10000","26.42518","0.11454"
"52906","317.40000","26.45017","0.11531"
"52956","317.70000","26.47516","0.11705"
"53006","318.00000","26.50016","0.11808"
"53056","318.30000","26.52515","0.11926"
"53106","318.60000","26.55020","0.12080"
"53156","318.90000","26.57513","0.12195"
"53206","319.20000","26.60018","0.12269"
"53256","319.50000","26.62518","0.12399"
"53306","319.80000","26.65017","0.12533"
"53356","320.10000","26.67516","0.12646"
"53406","320.40000","26.70015","0.12887"
"53456","320.70000","26.72514","0.13012"
"53506","321.00000","26.75014","0.13135"
"53556","321.30000","26.77513","0.13307"
"53606","321.60000","26.80012","0.13430"
"53656","321.90000","26.82517","0.13637"
"53706","322.20000","26.85016","0.13781"
"53756","322.50000","26.87522","0.13984"
"53806","322.80000","26.90021","0.14260"
"53856","323.10000","26.92520","0.14514"
"53906","323.40000","26.95025","0.14692"
"53956","323.70000","26.97512","0.14889"
"54006","324.00000","27.00018","0.14966"
"54056","324.30000","27.02511","0.14921"
"54106","324.60000","27.05022","0.15137"
"54156","324.90000","27.07515","0.15370"
"54206","325.20000","27.10020","0.15593"
"54256","325.50000","27.12520","0.15679"
"54306","325.80000","27.15019","0.15942"
"54356","326.10000","27.17518","0.16064"
"54406","326.40000","27.20011","0.16232"
"54456","326.70000","27.22516","0.16339"
"54506","327.00000","27.25016","0.16443"
"54556","327.30000","27.27521","0.16569"
"54606","327.60000","27.30014","0.16691"
"54656","327.90000","27.32513","0.16781"
"54706","328.20000","27.35019","0.16822"
"54756","328.50000","27.37518","0.16974"
"54806","328.80000","27.40023","0.17076"
"54856","329.10000","27.42516","0.17127"
"54906","329.40000","27.45021","0.17169"
"54956","329.70000","27.47514","0.04513"
"55006","330.00000","27.50014","0.03080"
"55056","330.30000","27.52513","0.03178"
"55106","330.60000","27.55018","0.03359"
"55156","330.90000","27.57517","0.03341"
"55206","331.20000","27.60016","0.03799"
"55256","331.50000","27.62522","0.03557"
"55306","331.80000","27.65015","0.04054"
"55356","332.10000","27.67520","0.03778"
"55406","332.40000","27.70013","0.04231"
"55456","332.70000","27.72518","0.03884"
"55506","333.00000","27.75012","0.04301"
"55556","333.30000","27.77517","0.04033"
"55606","333.60000","27.80022","0.04447"
"55656","333.90000","27.82515","0.04213"
"55706","334.20000","27.85014","0.04555"
"55756","334.50000","27.87514","0.04435"
"55806","334.80000","27.90019","0.04690"
"55856","335.10000","27.92512","0.04707"
"55906","335.40000","27.95017","0.04785"
"55956","335.70000","27.97523","0.04926"
"56006","336.00000","28.00022","0.04868"
"56056","336.30000","28.02515","0.05135"
"56106","336.60000","28.05014","0.04944"
"56156","336.90000","28.07519","0.05232"
"56206","337.20000","28.10007","0.04969"
"56256","337.50000","28.12518","0.05405"
"56306","337.80000","28.15011","0.05108"
"56356","338.10000","28.17522","0.05496"
"56406","338.40000","28.20015","0.05212"
"56456","338.70000","28.22515","0.05554"
"56506","339.00000","28.25020","0.05436"
"56556","339.30000","28.27513","0.05569"
"56606","339.60000","28.30018","0.05507"
"56656","339.90000","28.32511","0.05679"
"56706","340.20000","28.35022","0.05716"
"56756","340.50000","28.37510","0.05811"
"56806","340.80000","28.40015","0.05874"
"56856","341.10000","28.42514","0.05862"
"56906","341.40000","28.45013","0.06015"
"56956","341.70000","28.47519","0.05955"
"57006","342.00000","28.50018","0.06121"
"57056","342.30000","28.52517","0.06130"
"57106","342.60000","28.55016","0.06169"
"57156","342.90000","28.57521","0.06242"
"57206","343.20000","28.60014","0.06294"
"57256","343.50000","28.62520","0.06466"
"57306","343.80000","28.65019","0.06378"
"57356","344.10000","28.67518","0.06618"
"57406","344.40000","28.70017","0.06552"
"57456","344.70000","28.72516","0.06730"
"57506","345.00000","28.75022","0.06723"
"57556","345.30000","28.77521","0.06815"
"57606","345.60000","28.80014","0.06868"
"57656","345.90000","28.82513","0.06924"
"57706","346.20000","28.85012","0.07117"
"57756","346.50000","28.87512","0.07104"
"57806","346.80000","28.90011","0.07206"
"57856","347.10000","28.92516","0.07126"
"57906","347.40000","28.95009","0.07187"
"57956","347.70000","28.97514","0.07303"
"58006","348.00000","29.00014","0.07339"
"58056","348.30000","29.02519","0.07463"
"58106","348.60000","29.05018","0.07482"
"58156","348.90000","29.07517","0.07674"
"58206","349.20000","29.10022","0.07693"
"58256","349.50000","29.12516","0.07821"
"58306","349.80000","29.15015","0.07794"
"58356","350.10000","29.17514","0.07969"
"58406","350.40000","29.20019","0.08045"
"58456","350.70000","29.22507","0.08166"
"58506","351.00000","29.25018","0.08207"
"58556","351.30000","29.27517","0.08392"
"58606","351.60000","29.30016","0.08446"
"58656","351.90000","29.32509","0.08531"
"58706","352.20000","29.35008","0.08597"
"58756","352.50000","29.37514","0.08731"
"58806","352.80000","29.40013","0.08778"
"58856","353.10000","29.42518","0.08892"
"58906","353.40000","29.45011","0.09007"
"58956","353.70000","29.47517","0.09014"
"59006","354.00000","29.50015","0.09073"
"59056","354.30000","29.52509","0.09244"
"59106","354.60000","29.55020","0.09261"
"59156","354.90000","29.57513","0.09356"
"59206","355.20000","29.60018","0.09403"
"59256","355.50000","29.62512","0.09510"
"59306","355.80000","29.65023","0.09533"
"59356","356.10000","29.67516","0.09619"
"59406","356.40000","29.70015","0.09645"
"59456","356.70000","29.72514","0.09669"
"59506","357.00000","29.75014","0.09768"
"59556","357.30000","29.77519","0.09825"
"59606","357.60000","29.80012","0.09885"
"59656","357.90000","29.82517","0.09881"
"59706","358.20000","29.85010","0.09959"
"59756","358.50000","29.87522","0.09991"
"59806","358.80000","29.90015","0.10042"
"59856","359.10000","29.92520","0.10095"
"59906","359.40000","29.95013","0.10126"
"59956","359.70000","29.97519","0.10123"
"60006","360.00000","30.00018","0.10160"
"60056","360.30000","30.02505","-0.00021"
"60106","360.60000","30.05016","-0.00305"
"60156","360.90000","30.07509","0.00118"
"60206","361.20000","30.10021","0.00292"
"60256","361.50000","30.12514","0.00295"
"60306","361.80000","30.15019","0.00339"
"60356","362.10000","30.17518","0.00261"
"60406","362.40000","30.20017","0.00265"
"60456","362.70000","30.22523","0.00304"
"60506","363.00000","30.25010","0.00260"
"60556","363.30000","30.27521","0.00324"
"60606","363.60000","30.30020","0.00268"
"60656","363.90000","30.32519","0.00303"
"60706","364.20000","30.35013","0.00314"
"60756","364.50000","30.37518","0.00272"
"60806","364.80000","30.40023","0.00330"
"60856","365.10000","30.42516","0.00294"
"60906","365.40000","30.45021","0.00298"
"60956","365.70000","30.47515","0.00307"
"61006","366.00000","30.50020","0.00291"
"61056","366.30000","30.52507","0.00285"
"61106","366.60000","30.55018","0.00324"
"61156","366.90000","30.57517","0.00255"
"61206","367.20000","30.60017","0.00306"
"61256","367.50000","30.62515","0.00272"
"61306","367.80000","30.65015","0.00309"
"61356","368.10000","30.67520","0.00304"
"61406","368.40000","30.70013","0.00343"
"61456","368.70000","30.72519","0.00314"
"61484","368.86400","30.73888","0.00309"