File: Trajectories_together/161226_2Specimen_RawData_3.csv
"","V1","V2","V3"
"1","End date","12/26/2016",""
"2","Specimen label","11BG_81_2_run2",""
"3","Maximum Load","0.05442","N"
"4","Time","Extension","Load"
"5","(s)","(mm)","(N)"
"6","0.00000","35.15104","0.01063"
"36","0.18000","35.16187","0.01033"
"66","0.36000","35.18100","0.01043"
"96","0.54000","35.19630","0.01053"
"126","0.72000","35.21131","0.01087"
"156","0.90000","35.22620","0.01067"
"186","1.08000","35.24121","0.01110"
"216","1.26000","35.25628","0.01085"
"246","1.44000","35.27122","0.01079"
"276","1.62000","35.28617","0.01066"
"306","1.80000","35.30129","0.01082"
"336","1.98000","35.31624","0.01101"
"366","2.16000","35.33113","0.01090"
"396","2.34000","35.34626","0.01096"
"426","2.52000","35.36121","0.01089"
"456","2.70000","35.37615","0.01088"
"486","2.88000","35.39116","0.01131"
"516","3.06000","35.40622","0.01100"
"546","3.24000","35.42117","0.01122"
"576","3.42000","35.43618","0.01103"
"606","3.60000","35.45125","0.01148"
"636","3.78000","35.46619","0.01134"
"666","3.96000","35.48126","0.01126"
"696","4.14000","35.49621","0.01162"
"726","4.32000","35.51115","0.01124"
"756","4.50000","35.52622","0.01158"
"786","4.68000","35.54117","0.01145"
"816","4.86000","35.55618","0.01169"
"846","5.04000","35.57118","0.01176"
"876","5.22000","35.58619","0.01188"
"906","5.40000","35.60126","0.01176"
"936","5.58000","35.61621","0.01176"
"966","5.76000","35.63115","0.01186"
"996","5.94000","35.64622","0.01205"
"1026","6.12000","35.66123","0.01209"
"1056","6.30000","35.67617","0.01212"
"1086","6.48000","35.69118","0.01226"
"1116","6.66000","35.70625","0.01236"
"1146","6.84000","35.72120","0.01234"
"1176","7.02000","35.73620","0.01238"
"1206","7.20000","35.75121","0.01267"
"1236","7.38000","35.76622","0.01293"
"1266","7.56000","35.78123","0.01271"
"1296","7.74000","35.79617","0.01294"
"1326","7.92000","35.81118","0.01271"
"1356","8.10000","35.82619","0.01267"
"1386","8.28000","35.84119","0.01335"
"1416","8.46000","35.85620","0.01324"
"1446","8.64000","35.87121","0.01313"
"1476","8.82000","35.88622","0.01310"
"1506","9.00000","35.90116","0.01305"
"1536","9.18000","35.91617","0.01340"
"1566","9.36000","35.93124","0.01340"
"1596","9.54000","35.94618","0.01326"
"1626","9.72000","35.96119","0.01347"
"1656","9.90000","35.97620","0.01372"
"1686","10.08000","35.99115","0.01350"
"1716","10.26000","36.00621","0.01377"
"1746","10.44000","36.02122","0.01371"
"1776","10.62000","36.03617","0.01366"
"1806","10.80000","36.05118","0.01423"
"1836","10.98000","36.06624","0.01429"
"1866","11.16000","36.08119","0.01428"
"1896","11.34000","36.09620","0.01453"
"1926","11.52000","36.11120","0.01430"
"1956","11.70000","36.12621","0.01428"
"1986","11.88000","36.14122","0.01466"
"2016","12.06000","36.15623","0.01480"
"2046","12.24000","36.17117","0.01451"
"2076","12.42000","36.18618","0.01506"
"2106","12.60000","36.20119","0.01492"
"2136","12.78000","36.21619","0.01528"
"2166","12.96000","36.23114","0.01530"
"2196","13.14000","36.24627","0.01531"
"2226","13.32000","36.26122","0.01522"
"2256","13.50000","36.27616","0.01562"
"2286","13.68000","36.29123","0.01550"
"2316","13.86000","36.30624","0.01574"
"2346","14.04000","36.32113","0.01613"
"2376","14.22000","36.33619","0.01566"
"2406","14.40000","36.35120","0.01585"
"2436","14.58000","36.36621","0.01559"
"2466","14.76000","36.38128","0.01564"
"2496","14.94000","36.39616","0.01583"
"2526","15.12000","36.41123","0.01601"
"2556","15.30000","36.42617","0.01596"
"2586","15.48000","36.44118","0.01583"
"2616","15.66000","36.45619","0.01662"
"2646","15.84000","36.47120","0.01623"
"2676","16.02000","36.48615","0.01621"
"2706","16.20000","36.50121","0.01628"
"2736","16.38000","36.51628","0.01648"
"2766","16.56000","36.53117","0.01659"
"2796","16.74000","36.54623","0.01661"
"2826","16.92000","36.56124","0.01696"
"2856","17.10000","36.57619","0.01712"
"2886","17.28000","36.59119","0.01700"
"2916","17.46000","36.60626","0.01621"
"2946","17.64000","36.62115","0.01674"
"2976","17.82000","36.63615","0.01685"
"3006","18.00000","36.65122","0.01683"
"3036","18.18000","36.66617","0.01730"
"3066","18.36000","36.68118","0.01700"
"3096","18.54000","36.69624","0.01705"
"3126","18.72000","36.71119","0.01688"
"3156","18.90000","36.72620","0.01742"
"3186","19.08000","36.74120","0.01735"
"3216","19.26000","36.75615","0.01723"
"3246","19.44000","36.77122","0.01797"
"3276","19.62000","36.78623","0.01793"
"3306","19.80000","36.80124","0.01768"
"3336","19.98000","36.81618","0.01823"
"3366","20.16000","36.83125","0.01754"
"3396","20.34000","36.84614","0.01809"
"3426","20.52000","36.86120","0.01822"
"3456","20.70000","36.87621","0.01821"
"3486","20.88000","36.89122","0.01831"
"3516","21.06000","36.90616","0.01876"
"3546","21.24000","36.92117","0.01864"
"3576","21.42000","36.93618","0.01862"
"3606","21.60000","36.95119","0.01908"
"3636","21.78000","36.96619","0.01972"
"3666","21.96000","36.98120","0.01959"
"3696","22.14000","36.99627","0.01938"
"3726","22.32000","37.01122","0.01930"
"3756","22.50000","37.02617","0.01952"
"3786","22.68000","37.04117","0.01989"
"3816","22.86000","37.05618","0.01958"
"3846","23.04000","37.07118","0.02020"
"3876","23.22000","37.08619","0.02048"
"3906","23.40000","37.10120","0.02058"
"3936","23.58000","37.11615","0.02051"
"3966","23.76000","37.13121","0.02028"
"3996","23.94000","37.14628","0.02087"
"4026","24.12000","37.16117","0.02081"
"4056","24.30000","37.17624","0.02138"
"4086","24.48000","37.19124","0.02147"
"4116","24.66000","37.20619","0.02143"
"4146","24.84000","37.22120","0.02184"
"4176","25.02000","37.23626","0.02137"
"4206","25.20000","37.25115","0.02166"
"4236","25.38000","37.26622","0.02182"
"4266","25.56000","37.28123","0.02181"
"4296","25.74000","37.29611","0.02215"
"4326","25.92000","37.31124","0.02217"
"4356","26.10000","37.32625","0.02245"
"4386","26.28000","37.34113","0.02220"
"4416","26.46000","37.35620","0.02263"
"4446","26.64000","37.37127","0.02275"
"4476","26.82000","37.38616","0.02316"
"4506","27.00000","37.40116","0.02334"
"4536","27.18000","37.41623","0.02346"
"4566","27.36000","37.43118","0.02342"
"4596","27.54000","37.44619","0.02265"
"4626","27.72000","37.46119","0.02337"
"4656","27.90000","37.47614","0.02357"
"4686","28.08000","37.49121","0.02230"
"4716","28.26000","37.50621","0.02248"
"4746","28.44000","37.52116","0.02350"
"4776","28.62000","37.53617","0.02337"
"4806","28.80000","37.55117","0.02321"
"4836","28.98000","37.56612","0.02362"
"4866","29.16000","37.58125","0.02379"
"4896","29.34000","37.59620","0.02395"
"4926","29.52000","37.61115","0.02382"
"4956","29.70000","37.62621","0.02441"
"4986","29.88000","37.64122","0.02453"
"5016","30.06000","37.65623","0.02444"
"5046","30.24000","37.67123","0.02434"
"5076","30.42000","37.68618","0.02479"
"5106","30.60000","37.70119","0.02498"
"5136","30.78000","37.71626","0.02535"
"5166","30.96000","37.73120","0.02517"
"5196","31.14000","37.74615","0.02550"
"5226","31.32000","37.76122","0.02547"
"5256","31.50000","37.77623","0.02641"
"5286","31.68000","37.79117","0.02537"
"5316","31.86000","37.80618","0.02582"
"5346","32.04000","37.82124","0.02496"
"5376","32.22000","37.83619","0.02556"
"5406","32.40000","37.85126","0.02586"
"5436","32.58000","37.86620","0.02548"
"5466","32.76000","37.88115","0.02569"
"5496","32.94000","37.89622","0.02546"
"5526","33.12000","37.91117","0.02604"
"5556","33.30000","37.92617","0.02565"
"5586","33.48000","37.94118","0.02569"
"5616","33.66000","37.95625","0.02653"
"5646","33.84000","37.97120","0.02666"
"5676","34.02000","37.98620","0.02673"
"5706","34.20000","38.00121","0.02769"
"5736","34.38000","38.01616","0.02705"
"5766","34.56000","38.03122","0.02688"
"5796","34.74000","38.04617","0.02711"
"5826","34.92000","38.06118","0.02736"
"5856","35.10000","38.07625","0.02792"
"5886","35.28000","38.09119","0.02788"
"5916","35.46000","38.10614","0.02776"
"5946","35.64000","38.12121","0.02825"
"5976","35.82000","38.13622","0.02829"
"6006","36.00000","38.15110","0.02851"
"6036","36.18000","38.16617","0.02824"
"6066","36.36000","38.18124","0.02841"
"6096","36.54000","38.19618","0.02857"
"6126","36.72000","38.21125","0.02858"
"6156","36.90000","38.22626","0.02846"
"6186","37.08000","38.24115","0.02928"
"6216","37.26000","38.25621","0.02861"
"6246","37.44000","38.27122","0.02933"
"6276","37.62000","38.28617","0.02892"
"6306","37.80000","38.30123","0.02963"
"6336","37.98000","38.31624","0.02912"
"6366","38.16000","38.33113","0.02552"
"6396","38.34000","38.34620","0.00836"
"6426","38.52000","38.36120","0.01255"
"6456","38.70000","38.37621","0.00975"
"6486","38.88000","38.39122","0.00419"
"6516","39.06000","38.40623","0.00499"
"6546","39.24000","38.42117","0.00995"
"6576","39.42000","38.43624","0.00918"
"6606","39.60000","38.45119","0.00577"
"6636","39.78000","38.46613","0.00640"
"6666","39.96000","38.48126","0.00886"
"6696","40.14000","38.49621","0.00892"
"6726","40.32000","38.51122","0.00609"
"6756","40.50000","38.52622","0.00568"
"6786","40.68000","38.54123","0.00860"
"6816","40.86000","38.55618","0.00787"
"6846","41.04000","38.57125","0.00586"
"6876","41.22000","38.58619","0.00775"
"6906","41.40000","38.60120","0.00963"
"6936","41.58000","38.61626","0.00710"
"6966","41.76000","38.63115","0.00622"
"6996","41.94000","38.64610","0.00838"
"7026","42.12000","38.66129","0.00892"
"7056","42.30000","38.67624","0.00795"
"7086","42.48000","38.69112","0.00645"
"7116","42.66000","38.70625","0.00789"
"7146","42.84000","38.72126","0.00854"
"7176","43.02000","38.73614","0.00697"
"7206","43.20000","38.75121","0.00724"
"7236","43.38000","38.76622","0.00882"
"7266","43.56000","38.78117","0.00814"
"7296","43.74000","38.79623","0.00654"
"7326","43.92000","38.81118","0.00825"
"7356","44.10000","38.82613","0.00869"
"7386","44.28000","38.84119","0.00806"
"7416","44.46000","38.85620","0.00763"
"7446","44.64000","38.87115","0.00820"
"7476","44.82000","38.88622","0.00886"
"7506","45.00000","38.90123","0.00824"
"7536","45.18000","38.91617","0.00782"
"7566","45.36000","38.93124","0.00856"
"7596","45.54000","38.94619","0.00893"
"7626","45.72000","38.96119","0.00740"
"7656","45.90000","38.97620","0.00817"
"7686","46.08000","38.99121","0.00889"
"7716","46.26000","39.00615","0.00829"
"7746","46.44000","39.02128","0.00814"
"7776","46.62000","39.03617","0.00833"
"7806","46.80000","39.05112","0.00813"
"7836","46.98000","39.06624","0.00788"
"7866","47.16000","39.08125","0.00792"
"7896","47.34000","39.09613","0.00892"
"7926","47.52000","39.11121","0.00913"
"7956","47.70000","39.12627","0.00799"
"7986","47.88000","39.14122","0.00861"
"8016","48.06000","39.15622","0.00889"
"8046","48.24000","39.17117","0.00853"
"8076","48.42000","39.18618","0.00881"
"8106","48.60000","39.20119","0.00924"
"8136","48.78000","39.21613","0.00858"
"8166","48.96000","39.23114","0.00824"
"8196","49.14000","39.24621","0.00885"
"8226","49.32000","39.26121","0.00855"
"8256","49.50000","39.27617","0.00898"
"8286","49.68000","39.29123","0.00816"
"8316","49.86000","39.30624","0.00860"
"8346","50.04000","39.32118","0.00880"
"8376","50.22000","39.33619","0.00868"
"8406","50.40000","39.35120","0.00891"
"8436","50.58000","39.36621","0.00910"
"8466","50.76000","39.38121","0.00868"
"8496","50.94000","39.39621","0.00903"
"8526","51.12000","39.41111","0.00906"
"8556","51.30000","39.42624","0.00889"
"8586","51.48000","39.44124","0.00917"
"8616","51.66000","39.45613","0.00885"
"8646","51.84000","39.47120","0.00899"
"8676","52.02000","39.48620","0.00898"
"8706","52.20000","39.50115","0.00879"
"8736","52.38000","39.51622","0.00883"
"8766","52.56000","39.53116","0.00947"
"8796","52.74000","39.54617","0.00885"
"8826","52.92000","39.56118","0.00946"
"8856","53.10000","39.57618","0.00935"
"8886","53.28000","39.59113","0.00919"
"8916","53.46000","39.60620","0.00957"
"8946","53.64000","39.62120","0.00967"
"8976","53.82000","39.63616","0.00921"
"9006","54.00000","39.65122","0.00915"
"9036","54.18000","39.66623","0.00937"
"9066","54.36000","39.68118","0.00953"
"9096","54.54000","39.69612","0.00955"
"9126","54.72000","39.71119","0.00941"
"9156","54.90000","39.72620","0.00924"
"9186","55.08000","39.74121","0.00970"
"9216","55.26000","39.75621","0.00947"
"9246","55.44000","39.77116","0.00975"
"9276","55.62000","39.78623","0.00956"
"9306","55.80000","39.80123","0.00953"
"9336","55.98000","39.81618","0.00973"
"9366","56.16000","39.83125","0.00939"
"9396","56.34000","39.84619","0.01027"
"9426","56.52000","39.86120","0.01009"
"9456","56.70000","39.87621","0.00970"
"9486","56.88000","39.89116","0.00992"
"9516","57.06000","39.90617","0.00960"
"9546","57.24000","39.92117","0.00985"
"9576","57.42000","39.93618","0.01018"
"9606","57.60000","39.95119","0.00994"
"9636","57.78000","39.96619","0.00983"
"9666","57.96000","39.98114","0.00994"
"9696","58.14000","39.99621","0.01002"
"9726","58.32000","40.01122","0.01014"
"9756","58.50000","40.02622","0.01013"
"9786","58.68000","40.04117","0.01013"
"9816","58.86000","40.05618","0.00994"
"9846","59.04000","40.07118","0.01010"
"9876","59.22000","40.08625","0.01051"
"9906","59.40000","40.10120","0.01029"
"9936","59.58000","40.11615","0.01010"
"9966","59.76000","40.13121","0.01015"
"9996","59.94000","40.14622","0.01046"
"10026","60.12000","40.16122","0.01043"
"10056","60.30000","40.17617","0.01059"
"10086","60.48000","40.19130","0.01007"
"10116","60.66000","40.20619","0.01008"
"10146","60.84000","40.22113","0.01036"
"10176","61.02000","40.23621","0.01019"
"10206","61.20000","40.25121","0.01017"
"10236","61.38000","40.26616","0.01037"
"10266","61.56000","40.28122","0.01017"
"10296","61.74000","40.29617","0.01016"
"10326","61.92000","40.31118","0.01001"
"10356","62.10000","40.32619","0.01073"
"10386","62.28000","40.34119","0.01053"
"10416","62.46000","40.35614","0.01030"
"10446","62.64000","40.37127","0.01077"
"10476","62.82000","40.38621","0.01040"
"10506","63.00000","40.40117","0.01063"
"10536","63.18000","40.41623","0.01089"
"10566","63.36000","40.43118","0.01047"
"10596","63.54000","40.44619","0.01062"
"10626","63.72000","40.46125","0.01049"
"10656","63.90000","40.47620","0.01065"
"10686","64.08000","40.49120","0.01070"
"10716","64.26000","40.50621","0.01111"
"10746","64.44000","40.52116","0.01071"
"10776","64.62000","40.53623","0.01084"
"10806","64.80000","40.55129","0.01114"
"10836","64.98000","40.56618","0.01133"
"10866","65.16000","40.58119","0.01107"
"10896","65.34000","40.59620","0.01086"
"10926","65.52000","40.61120","0.01125"
"10956","65.70000","40.62615","0.01096"
"10986","65.88000","40.64122","0.01135"
"11016","66.06000","40.65617","0.01116"
"11046","66.24000","40.67117","0.01093"
"11076","66.42000","40.68618","0.01106"
"11106","66.60000","40.70113","0.01091"
"11136","66.78000","40.71625","0.01156"
"11166","66.96000","40.73126","0.01139"
"11196","67.14000","40.74615","0.01145"
"11226","67.32000","40.76122","0.01161"
"11256","67.50000","40.77622","0.01105"
"11286","67.68000","40.79117","0.01170"
"11316","67.86000","40.80618","0.01147"
"11346","68.04000","40.82124","0.01127"
"11376","68.22000","40.83619","0.01127"
"11406","68.40000","40.85120","0.01153"
"11436","68.58000","40.86627","0.01160"
"11466","68.76000","40.88115","0.01158"
"11496","68.94000","40.89622","0.01148"
"11526","69.12000","40.91123","0.01192"
"11556","69.30000","40.92617","0.01170"
"11586","69.48000","40.94118","0.01237"
"11616","69.66000","40.95625","0.01209"
"11646","69.84000","40.97120","0.01191"
"11676","70.02000","40.98614","0.01207"
"11706","70.20000","41.00121","0.01234"
"11736","70.38000","41.01621","0.01235"
"11766","70.56000","41.03123","0.01209"
"11796","70.74000","41.04623","0.01189"
"11826","70.92000","41.06118","0.01202"
"11856","71.10000","41.07625","0.01244"
"11886","71.28000","41.09126","0.01221"
"11916","71.46000","41.10614","0.01256"
"11946","71.64000","41.12121","0.01241"
"11976","71.82000","41.13622","0.01235"
"12006","72.00000","41.15116","0.01260"
"12036","72.18000","41.16623","0.01280"
"12066","72.36000","41.18118","0.01249"
"12096","72.54000","41.19618","0.01313"
"12126","72.72000","41.21119","0.01321"
"12156","72.90000","41.22620","0.01307"
"12186","73.08000","41.24120","0.01316"
"12216","73.26000","41.25621","0.01289"
"12246","73.44000","41.27122","0.01334"
"12276","73.62000","41.28617","0.01339"
"12306","73.80000","41.30124","0.01331"
"12336","73.98000","41.31618","0.01328"
"12366","74.16000","41.33119","0.01268"
"12396","74.34000","41.34614","0.01348"
"12426","74.52000","41.36121","0.01343"
"12456","74.70000","41.37615","0.01323"
"12486","74.88000","41.39122","0.01300"
"12516","75.06000","41.40623","0.01344"
"12546","75.24000","41.42117","0.01391"
"12576","75.42000","41.43629","0.01340"
"12606","75.60000","41.45124","0.01325"
"12636","75.78000","41.46619","0.01322"
"12666","75.96000","41.48120","0.01420"
"12696","76.14000","41.49627","0.01384"
"12726","76.32000","41.51115","0.01373"
"12756","76.50000","41.52617","0.01412"
"12786","76.68000","41.54123","0.01438"
"12816","76.86000","41.55618","0.01446"
"12846","77.04000","41.57119","0.01430"
"12876","77.22000","41.58625","0.01415"
"12906","77.40000","41.60120","0.01441"
"12936","77.58000","41.61626","0.01468"
"12966","77.76000","41.63121","0.01441"
"12996","77.94000","41.64616","0.01467"
"13026","78.12000","41.66123","0.01479"
"13056","78.30000","41.67624","0.01473"
"13086","78.48000","41.69118","0.01472"
"13116","78.66000","41.70619","0.01542"
"13146","78.84000","41.72126","0.01525"
"13176","79.02000","41.73615","0.01508"
"13206","79.20000","41.75121","0.01521"
"13236","79.38000","41.76622","0.01381"
"13266","79.56000","41.78117","0.01481"
"13296","79.74000","41.79617","0.01483"
"13326","79.92000","41.81124","0.01417"
"13356","80.10000","41.82613","0.01415"
"13386","80.28000","41.84119","0.01463"
"13416","80.46000","41.85620","0.01451"
"13446","80.64000","41.87115","0.01471"
"13476","80.82000","41.88622","0.01475"
"13506","81.00000","41.90117","0.01486"
"13536","81.18000","41.91617","0.01478"
"13566","81.36000","41.93124","0.01523"
"13596","81.54000","41.94618","0.01502"
"13626","81.72000","41.96119","0.01521"
"13656","81.90000","41.97620","0.01482"
"13686","82.08000","41.99121","0.01470"
"13716","82.26000","42.00615","0.01508"
"13746","82.44000","42.02122","0.01487"
"13776","82.62000","42.03617","0.01509"
"13806","82.80000","42.05111","0.01531"
"13836","82.98000","42.06618","0.01561"
"13866","83.16000","42.08118","0.01547"
"13896","83.34000","42.09614","0.01561"
"13926","83.52000","42.11120","0.01594"
"13956","83.70000","42.12627","0.01614"
"13986","83.88000","42.14116","0.01577"
"14016","84.06000","42.15623","0.01593"
"14046","84.24000","42.17117","0.01625"
"14076","84.42000","42.18612","0.01610"
"14106","84.60000","42.20125","0.01583"
"14136","84.78000","42.21619","0.01617"
"14166","84.96000","42.23114","0.01612"
"14196","85.14000","42.24621","0.01585"
"14226","85.32000","42.26128","0.01653"
"14256","85.50000","42.27616","0.01682"
"14286","85.68000","42.29123","0.01653"
"14316","85.86000","42.30624","0.01688"
"14346","86.04000","42.32118","0.01659"
"14376","86.22000","42.33625","0.01696"
"14406","86.40000","42.35119","0.01664"
"14436","86.58000","42.36615","0.01730"
"14466","86.76000","42.38121","0.01693"
"14496","86.94000","42.39622","0.01700"
"14526","87.12000","42.41111","0.01725"
"14556","87.30000","42.42624","0.01706"
"14586","87.48000","42.44124","0.01745"
"14616","87.66000","42.45619","0.01762"
"14646","87.84000","42.47120","0.01759"
"14676","88.02000","42.48627","0.01814"
"14706","88.20000","42.50115","0.01766"
"14736","88.38000","42.51628","0.01787"
"14766","88.56000","42.53123","0.01787"
"14796","88.74000","42.54617","0.01809"
"14826","88.92000","42.56124","0.01772"
"14856","89.10000","42.57619","0.01864"
"14886","89.28000","42.59114","0.01783"
"14916","89.46000","42.60620","0.01820"
"14946","89.64000","42.62121","0.01887"
"14976","89.82000","42.63615","0.01830"
"15006","90.00000","42.65116","0.01888"
"15036","90.18000","42.66617","0.01942"
"15066","90.36000","42.68118","0.01924"
"15096","90.54000","42.69619","0.01900"
"15126","90.72000","42.71119","0.01879"
"15156","90.90000","42.72620","0.01902"
"15186","91.08000","42.74126","0.01916"
"15216","91.26000","42.75616","0.01937"
"15246","91.44000","42.77110","0.01886"
"15276","91.62000","42.78629","0.01919"
"15306","91.80000","42.80117","0.01972"
"15336","91.98000","42.81618","0.01995"
"15366","92.16000","42.83119","0.02011"
"15396","92.34000","42.84620","0.02035"
"15426","92.52000","42.86115","0.02059"
"15456","92.70000","42.87621","0.02062"
"15486","92.88000","42.89122","0.02041"
"15516","93.06000","42.90622","0.01944"
"15546","93.24000","42.92123","0.02021"
"15576","93.42000","42.93618","0.01895"
"15606","93.60000","42.95113","0.01922"
"15636","93.78000","42.96626","0.01966"
"15666","93.96000","42.98120","0.01994"
"15696","94.14000","42.99615","0.01928"
"15726","94.32000","43.01122","0.02002"
"15756","94.50000","43.02628","0.01986"
"15786","94.68000","43.04111","0.02005"
"15816","94.86000","43.05624","0.02017"
"15846","95.04000","43.07118","0.02053"
"15876","95.22000","43.08619","0.02047"
"15906","95.40000","43.10126","0.02037"
"15936","95.58000","43.11614","0.02085"
"15966","95.76000","43.13115","0.02036"
"15996","95.94000","43.14622","0.02155"
"16026","96.12000","43.16123","0.02119"
"16056","96.30000","43.17617","0.02113"
"16086","96.48000","43.19124","0.02141"
"16116","96.66000","43.20625","0.02132"
"16146","96.84000","43.22114","0.02180"
"16176","97.02000","43.23620","0.02171"
"16206","97.20000","43.25121","0.02193"
"16236","97.38000","43.26616","0.02186"
"16266","97.56000","43.28116","0.02181"
"16296","97.74000","43.29617","0.02178"
"16326","97.92000","43.31112","0.02164"
"16356","98.10000","43.32619","0.02239"
"16386","98.28000","43.34119","0.02213"
"16416","98.46000","43.35614","0.02209"
"16446","98.64000","43.37127","0.02222"
"16476","98.82000","43.38622","0.02259"
"16506","99.00000","43.40116","0.02274"
"16536","99.18000","43.41617","0.02289"
"16566","99.36000","43.43124","0.02264"
"16596","99.54000","43.44618","0.02287"
"16626","99.72000","43.46119","0.02338"
"16656","99.90000","43.47614","0.02296"
"16686","100.08000","43.49115","0.02330"
"16716","100.26000","43.50621","0.02298"
"16746","100.44000","43.52116","0.02200"
"16776","100.62000","43.53617","0.02218"
"16806","100.80000","43.55124","0.02236"
"16836","100.98000","43.56624","0.02255"
"16866","101.16000","43.58119","0.02195"
"16896","101.34000","43.59620","0.02316"
"16926","101.52000","43.61120","0.02326"
"16956","101.70000","43.62615","0.02262"
"16986","101.88000","43.64122","0.02320"
"17016","102.06000","43.65616","0.02331"
"17046","102.24000","43.67117","0.02334"
"17076","102.42000","43.68618","0.02356"
"17106","102.60000","43.70112","0.02356"
"17136","102.78000","43.71614","0.02376"
"17166","102.96000","43.73126","0.02433"
"17196","103.14000","43.74620","0.02410"
"17226","103.32000","43.76110","0.02448"
"17256","103.50000","43.77622","0.02456"
"17286","103.68000","43.79123","0.02458"
"17316","103.86000","43.80618","0.02462"
"17346","104.04000","43.82119","0.02453"
"17376","104.22000","43.83619","0.02511"
"17406","104.40000","43.85120","0.02539"
"17436","104.58000","43.86621","0.02514"
"17466","104.76000","43.88116","0.02544"
"17496","104.94000","43.89616","0.02521"
"17526","105.12000","43.91122","0.02548"
"17556","105.30000","43.92624","0.02535"
"17586","105.48000","43.94118","0.02551"
"17616","105.66000","43.95619","0.02577"
"17646","105.84000","43.97126","0.02549"
"17676","106.02000","43.98620","0.02564"
"17706","106.20000","44.00115","0.02588"
"17736","106.38000","44.01622","0.02607"
"17766","106.56000","44.03122","0.02633"
"17796","106.74000","44.04623","0.02590"
"17826","106.92000","44.06118","0.02646"
"17856","107.10000","44.07619","0.02585"
"17886","107.28000","44.09126","0.02655"
"17916","107.46000","44.10620","0.02610"
"17946","107.64000","44.12115","0.02583"
"17976","107.82000","44.13622","0.02661"
"18006","108.00000","44.15123","0.02623"
"18036","108.18000","44.16617","0.02674"
"18066","108.36000","44.18118","0.02649"
"18096","108.54000","44.19618","0.02690"
"18126","108.72000","44.21119","0.02685"
"18156","108.90000","44.22620","0.02712"
"18186","109.08000","44.24120","0.02723"
"18216","109.26000","44.25621","0.02706"
"18246","109.44000","44.27122","0.02680"
"18276","109.62000","44.28617","0.02725"
"18306","109.80000","44.30117","0.02694"
"18336","109.98000","44.31624","0.02764"
"18366","110.16000","44.33118","0.02729"
"18396","110.34000","44.34620","0.02740"
"18426","110.52000","44.36120","0.02769"
"18456","110.70000","44.37614","0.02760"
"18486","110.88000","44.39122","0.02739"
"18516","111.06000","44.40617","0.02733"
"18546","111.24000","44.42117","0.02806"
"18576","111.42000","44.43623","0.02765"
"18606","111.60000","44.45131","0.02785"
"18636","111.78000","44.46619","0.02793"
"18666","111.96000","44.48114","0.02812"
"18696","112.14000","44.49627","0.02829"
"18726","112.32000","44.51122","0.02869"
"18756","112.50000","44.52617","0.02928"
"18786","112.68000","44.54123","0.02919"
"18816","112.86000","44.55618","0.02882"
"18846","113.04000","44.57118","0.02946"
"18876","113.22000","44.58625","0.02917"
"18906","113.40000","44.60120","0.02946"
"18936","113.58000","44.61620","0.02952"
"18966","113.76000","44.63121","0.02936"
"18996","113.94000","44.64616","0.03021"
"19026","114.12000","44.66117","0.03007"
"19056","114.30000","44.67629","0.03000"
"19086","114.48000","44.69112","0.03073"
"19116","114.66000","44.70619","0.03090"
"19146","114.84000","44.72120","0.03071"
"19176","115.02000","44.73620","0.03105"
"19206","115.20000","44.75121","0.03182"
"19236","115.38000","44.76622","0.03152"
"19266","115.56000","44.78123","0.03186"
"19296","115.74000","44.79617","0.03170"
"19326","115.92000","44.81124","0.03216"
"19356","116.10000","44.82619","0.03173"
"19386","116.28000","44.84119","0.03247"
"19416","116.46000","44.85620","0.03201"
"19446","116.64000","44.87114","0.03240"
"19476","116.82000","44.88621","0.03211"
"19506","117.00000","44.90122","0.03273"
"19536","117.18000","44.91617","0.03258"
"19566","117.36000","44.93112","0.03301"
"19596","117.54000","44.94619","0.03314"
"19626","117.72000","44.96119","0.03334"
"19656","117.90000","44.97620","0.03339"
"19686","118.08000","44.99121","0.03405"
"19716","118.26000","45.00621","0.03375"
"19746","118.44000","45.02122","0.03351"
"19776","118.62000","45.03629","0.03409"
"19806","118.80000","45.05117","0.03402"
"19836","118.98000","45.06618","0.03421"
"19866","119.16000","45.08119","0.03403"
"19896","119.34000","45.09620","0.03451"
"19926","119.52000","45.11120","0.03439"
"19956","119.70000","45.12621","0.03491"
"19986","119.88000","45.14122","0.03457"
"20016","120.06000","45.15622","0.03434"
"20046","120.24000","45.17123","0.03401"
"20076","120.42000","45.18618","0.03425"
"20106","120.60000","45.20124","0.03444"
"20136","120.78000","45.21626","0.03433"
"20166","120.96000","45.23120","0.03410"
"20196","121.14000","45.24615","0.03407"
"20226","121.32000","45.26122","0.03407"
"20256","121.50000","45.27617","0.03374"
"20286","121.68000","45.29117","0.03375"
"20316","121.86000","45.30624","0.03381"
"20346","122.04000","45.32118","0.03435"
"20376","122.22000","45.33619","0.03428"
"20406","122.40000","45.35126","0.03421"
"20436","122.58000","45.36614","0.03462"
"20466","122.76000","45.38121","0.03348"
"20496","122.94000","45.39622","0.03296"
"20526","123.12000","45.41117","0.03150"
"20556","123.30000","45.42617","0.02905"
"20586","123.48000","45.44124","0.02925"
"20616","123.66000","45.45613","0.02917"
"20646","123.84000","45.47120","0.02810"
"20676","124.02000","45.48621","0.02836"
"20706","124.20000","45.50121","0.02894"
"20736","124.38000","45.51622","0.02830"
"20766","124.56000","45.53122","0.02838"
"20796","124.74000","45.54623","0.02877"
"20826","124.92000","45.56123","0.02861"
"20856","125.10000","45.57625","0.02877"
"20886","125.28000","45.59113","0.02773"
"20916","125.46000","45.60620","0.02740"
"20946","125.64000","45.62121","0.02799"
"20976","125.82000","45.63615","0.02774"
"21006","126.00000","45.65122","0.02761"
"21036","126.18000","45.66623","0.02871"
"21066","126.36000","45.68118","0.02874"
"21096","126.54000","45.69624","0.02865"
"21126","126.72000","45.71119","0.02987"
"21156","126.90000","45.72620","0.02884"
"21186","127.08000","45.74127","0.02890"
"21216","127.26000","45.75621","0.02959"
"21246","127.44000","45.77116","0.02906"
"21276","127.62000","45.78617","0.02864"
"21306","127.80000","45.80124","0.02924"
"21336","127.98000","45.81612","0.02866"
"21366","128.16000","45.83119","0.02886"
"21396","128.34000","45.84626","0.02893"
"21426","128.52000","45.86114","0.02875"
"21456","128.70000","45.87621","0.02817"
"21486","128.88000","45.89122","0.02826"
"21516","129.06000","45.90616","0.02783"
"21546","129.24000","45.92123","0.02789"
"21576","129.42000","45.93618","0.02720"
"21606","129.60000","45.95119","0.02669"
"21636","129.78000","45.96619","0.02575"
"21666","129.96000","45.98120","0.02620"
"21696","130.14000","45.99614","0.02617"
"21726","130.32000","46.01116","0.02624"
"21756","130.50000","46.02622","0.02657"
"21786","130.68000","46.04117","0.02628"
"21816","130.86000","46.05618","0.02613"
"21846","131.04000","46.07119","0.02663"
"21876","131.22000","46.08619","0.02648"
"21906","131.40000","46.10120","0.02665"
"21936","131.58000","46.11621","0.02698"
"21966","131.76000","46.13109","0.02662"
"21996","131.94000","46.14628","0.02716"
"22026","132.12000","46.16123","0.02718"
"22056","132.30000","46.17617","0.02703"
"22086","132.48000","46.19118","0.02725"
"22116","132.66000","46.20625","0.02750"
"22146","132.84000","46.22120","0.02688"
"22176","133.02000","46.23620","0.02707"
"22206","133.20000","46.25115","0.02739"
"22236","133.38000","46.26621","0.02730"
"22266","133.56000","46.28122","0.02722"
"22296","133.74000","46.29623","0.02713"
"22326","133.92000","46.31118","0.02777"
"22356","134.10000","46.32624","0.02792"
"22386","134.28000","46.34119","0.02709"
"22416","134.46000","46.35614","0.02708"
"22446","134.64000","46.37121","0.02732"
"22476","134.82000","46.38622","0.02685"
"22506","135.00000","46.40116","0.02698"
"22536","135.18000","46.41617","0.02715"
"22566","135.36000","46.43118","0.02732"
"22596","135.54000","46.44618","0.02713"
"22626","135.72000","46.46119","0.02616"
"22656","135.90000","46.47620","0.02639"
"22686","136.08000","46.49114","0.02661"
"22716","136.26000","46.50627","0.02648"
"22746","136.44000","46.52116","0.02633"
"22776","136.62000","46.53611","0.02700"
"22806","136.80000","46.55123","0.02736"
"22836","136.98000","46.56630","0.02678"
"22866","137.16000","46.58113","0.02715"
"22896","137.34000","46.59625","0.02723"
"22926","137.52000","46.61121","0.02768"
"22956","137.70000","46.62609","0.02745"
"22986","137.88000","46.64122","0.02789"
"23016","138.06000","46.65622","0.02806"
"23046","138.24000","46.67117","0.02822"
"23076","138.42000","46.68624","0.02822"
"23106","138.60000","46.70119","0.02857"
"23136","138.78000","46.71613","0.02859"
"23166","138.96000","46.73120","0.02855"
"23196","139.14000","46.74627","0.02903"
"23226","139.32000","46.76110","0.02928"
"23256","139.50000","46.77622","0.02955"
"23286","139.68000","46.79129","0.02862"
"23316","139.86000","46.80618","0.02883"
"23346","140.04000","46.82119","0.02965"
"23376","140.22000","46.83619","0.02967"
"23406","140.40000","46.85114","0.02985"
"23436","140.58000","46.86620","0.02971"
"23466","140.76000","46.88121","0.03029"
"23496","140.94000","46.89610","0.03030"
"23526","141.12000","46.91122","0.03008"
"23556","141.30000","46.92617","0.03069"
"23586","141.48000","46.94118","0.03078"
"23616","141.66000","46.95618","0.03104"
"23646","141.84000","46.97120","0.03154"
"23676","142.02000","46.98614","0.03151"
"23706","142.20000","47.00121","0.03173"
"23736","142.38000","47.01616","0.03169"
"23766","142.56000","47.03116","0.03210"
"23796","142.74000","47.04623","0.03214"
"23826","142.92000","47.06118","0.03181"
"23856","143.10000","47.07613","0.03225"
"23886","143.28000","47.09125","0.03265"
"23916","143.46000","47.10614","0.03290"
"23946","143.64000","47.12114","0.03292"
"23976","143.82000","47.13622","0.03319"
"24006","144.00000","47.15122","0.03299"
"24036","144.18000","47.16617","0.03306"
"24066","144.36000","47.18123","0.03364"
"24096","144.54000","47.19618","0.03385"
"24126","144.72000","47.21119","0.03242"
"24156","144.90000","47.22619","0.03309"
"24186","145.08000","47.24121","0.03429"
"24216","145.26000","47.25615","0.03395"
"24246","145.44000","47.27122","0.03376"
"24276","145.62000","47.28623","0.03417"
"24306","145.80000","47.30117","0.03502"
"24336","145.98000","47.31624","0.03450"
"24366","146.16000","47.33125","0.03504"
"24396","146.34000","47.34613","0.03588"
"24426","146.52000","47.36120","0.03579"
"24456","146.70000","47.37621","0.03648"
"24486","146.88000","47.39116","0.03605"
"24516","147.06000","47.40622","0.03586"
"24546","147.24000","47.42117","0.03598"
"24576","147.42000","47.43618","0.03700"
"24606","147.60000","47.45124","0.03647"
"24636","147.78000","47.46620","0.03672"
"24666","147.96000","47.48114","0.03712"
"24696","148.14000","47.49620","0.03693"
"24726","148.32000","47.51122","0.03738"
"24756","148.50000","47.52616","0.03788"
"24786","148.68000","47.54117","0.03703"
"24816","148.86000","47.55624","0.03792"
"24846","149.04000","47.57118","0.03761"
"24876","149.22000","47.58619","0.03749"
"24906","149.40000","47.60120","0.03816"
"24936","149.58000","47.61614","0.03842"
"24966","149.76000","47.63127","0.03758"
"24996","149.94000","47.64616","0.03803"
"25026","150.12000","47.66110","0.03874"
"25056","150.30000","47.67623","0.03928"
"25086","150.48000","47.69118","0.03828"
"25116","150.66000","47.70613","0.03847"
"25146","150.84000","47.72119","0.03895"
"25176","151.02000","47.73621","0.03890"
"25206","151.20000","47.75115","0.03953"
"25236","151.38000","47.76622","0.03983"
"25266","151.56000","47.78117","0.03936"
"25296","151.74000","47.79617","0.03951"
"25326","151.92000","47.81124","0.03878"
"25356","152.10000","47.82613","0.03950"
"25386","152.28000","47.84119","0.03972"
"25416","152.46000","47.85625","0.03883"
"25446","152.64000","47.87115","0.03866"
"25476","152.82000","47.88622","0.03875"
"25506","153.00000","47.90122","0.03948"
"25536","153.18000","47.91617","0.03945"
"25566","153.36000","47.93118","0.03878"
"25596","153.54000","47.94618","0.03849"
"25626","153.72000","47.96119","0.03877"
"25656","153.90000","47.97620","0.03854"
"25686","154.08000","47.99120","0.03914"
"25716","154.26000","48.00621","0.03858"
"25746","154.44000","48.02116","0.03902"
"25776","154.62000","48.03622","0.03917"
"25806","154.80000","48.05124","0.03912"
"25836","154.98000","48.06618","0.03978"
"25866","155.16000","48.08118","0.03927"
"25896","155.34000","48.09620","0.03949"
"25926","155.52000","48.11120","0.04023"
"25956","155.70000","48.12621","0.04007"
"25986","155.88000","48.14116","0.04051"
"26016","156.06000","48.15616","0.04093"
"26046","156.24000","48.17117","0.04073"
"26076","156.42000","48.18618","0.04156"
"26106","156.60000","48.20119","0.04157"
"26136","156.78000","48.21619","0.04164"
"26166","156.96000","48.23120","0.04185"
"26196","157.14000","48.24620","0.04230"
"26226","157.32000","48.26115","0.04236"
"26256","157.50000","48.27622","0.04182"
"26286","157.68000","48.29116","0.04192"
"26316","157.86000","48.30618","0.04185"
"26346","158.04000","48.32118","0.04241"
"26376","158.22000","48.33613","0.04328"
"26406","158.40000","48.35120","0.04370"
"26436","158.58000","48.36626","0.04285"
"26466","158.76000","48.38121","0.04247"
"26496","158.94000","48.39622","0.04353"
"26526","159.12000","48.41117","0.04377"
"26556","159.30000","48.42617","0.04438"
"26586","159.48000","48.44124","0.04444"
"26616","159.66000","48.45625","0.04478"
"26646","159.84000","48.47120","0.04473"
"26676","160.02000","48.48620","0.04505"
"26706","160.20000","48.50121","0.04488"
"26736","160.38000","48.51621","0.04560"
"26766","160.56000","48.53122","0.04573"
"26796","160.74000","48.54617","0.04621"
"26826","160.92000","48.56118","0.04631"
"26856","161.10000","48.57624","0.04664"
"26886","161.28000","48.59119","0.04636"
"26916","161.46000","48.60620","0.04706"
"26946","161.64000","48.62120","0.04735"
"26976","161.82000","48.63616","0.04691"
"27006","162.00000","48.65116","0.04750"
"27036","162.18000","48.66623","0.04795"
"27066","162.36000","48.68118","0.04805"
"27096","162.54000","48.69625","0.04856"
"27126","162.72000","48.71125","0.04842"
"27156","162.90000","48.72620","0.04852"
"27186","163.08000","48.74121","0.04895"
"27216","163.26000","48.75627","0.04972"
"27246","163.44000","48.77116","0.04959"
"27276","163.62000","48.78616","0.04971"
"27306","163.80000","48.80123","0.04967"
"27336","163.98000","48.81618","0.05000"
"27366","164.16000","48.83113","0.05048"
"27396","164.34000","48.84619","0.05023"
"27426","164.52000","48.86121","0.05047"
"27456","164.70000","48.87615","0.05068"
"27486","164.88000","48.89122","0.05007"
"27516","165.06000","48.90617","0.05140"
"27546","165.24000","48.92123","0.05118"
"27576","165.42000","48.93624","0.05134"
"27606","165.60000","48.95119","0.05154"
"27636","165.78000","48.96619","0.05158"
"27666","165.96000","48.98120","0.05198"
"27696","166.14000","48.99615","0.05234"
"27726","166.32000","49.01122","0.05224"
"27756","166.50000","49.02622","0.05258"
"27786","166.68000","49.04117","0.05267"
"27816","166.86000","49.05617","0.05237"
"27846","167.04000","49.07118","0.05272"
"27876","167.22000","49.08619","0.05335"
"27906","167.40000","49.10120","0.05352"
"27936","167.58000","49.11620","0.05378"
"27966","167.76000","49.13121","0.05343"
"27996","167.94000","49.14622","0.05393"
"28026","168.12000","49.16129","0.05379"
"28056","168.30000","49.17617","0.05403"
"28086","168.48000","49.19118","0.05383"
"28116","168.66000","49.20618","0.05401"
"28146","168.84000","49.22120","0.05326"
"28176","169.02000","49.23620","0.02939"
"28206","169.20000","49.25121","0.02338"
"28236","169.38000","49.26616","0.02242"
"28266","169.56000","49.28122","0.02266"
"28296","169.74000","49.29623","0.02273"
"28326","169.92000","49.31118","0.02325"
"28356","170.10000","49.32625","0.02226"
"28386","170.28000","49.34119","0.02190"
"28416","170.46000","49.35620","0.02303"
"28446","170.64000","49.37120","0.02379"
"28476","170.82000","49.38621","0.02411"
"28506","171.00000","49.40117","0.02466"
"28536","171.18000","49.41623","0.02476"
"28566","171.36000","49.43124","0.02517"
"28596","171.54000","49.44619","0.02625"
"28626","171.72000","49.46125","0.02540"
"28656","171.90000","49.47620","0.02567"
"28686","172.08000","49.49121","0.02597"
"28716","172.26000","49.50621","0.02646"
"28746","172.44000","49.52122","0.02702"
"28776","172.62000","49.53623","0.02680"
"28806","172.80000","49.55117","0.02720"
"28836","172.98000","49.56624","0.02693"
"28866","173.16000","49.58113","0.02694"
"28896","173.34000","49.59620","0.02726"
"28926","173.52000","49.61126","0.02735"
"28956","173.70000","49.62615","0.02845"
"28986","173.88000","49.64116","0.02855"
"29016","174.06000","49.65622","0.02843"
"29046","174.24000","49.67117","0.02929"
"29076","174.42000","49.68618","0.02958"
"29106","174.60000","49.70124","0.02920"
"29136","174.78000","49.71613","0.02980"
"29166","174.96000","49.73120","0.03029"
"29196","175.14000","49.74620","0.03075"
"29226","175.32000","49.76122","0.03061"
"29256","175.50000","49.77622","0.03149"
"29286","175.68000","49.79117","0.03144"
"29316","175.86000","49.80624","0.03186"
"29346","176.04000","49.82118","0.03190"
"29376","176.22000","49.83619","0.03206"
"29406","176.40000","49.85120","0.03162"
"29436","176.58000","49.86621","0.03209"
"29466","176.76000","49.88121","0.03260"
"29496","176.94000","49.89616","0.03254"
"29526","177.12000","49.91122","0.03372"
"29556","177.30000","49.92623","0.03378"
"29586","177.48000","49.94118","0.03381"
"29616","177.66000","49.95625","0.03425"
"29646","177.84000","49.97119","0.03453"
"29676","178.02000","49.98620","0.03539"
"29706","178.20000","50.00121","0.03509"
"29736","178.38000","50.01616","0.03578"
"29766","178.56000","50.03117","0.03660"
"29796","178.74000","50.04623","0.03701"
"29826","178.92000","50.06118","0.03724"
"29856","179.10000","50.07613","0.03793"
"29886","179.28000","50.09126","0.03798"
"29916","179.46000","50.10620","0.03794"
"29946","179.64000","50.12115","0.03890"
"29976","179.82000","50.13622","0.03954"
"30006","180.00000","50.15122","0.03959"
"30036","180.18000","50.16617","0.03951"
"30066","180.36000","50.18123","0.03983"
"30096","180.54000","50.19618","0.03953"
"30126","180.72000","50.21119","0.03970"
"30156","180.90000","50.22626","0.04041"
"30186","181.08000","50.24120","0.04073"
"30216","181.26000","50.25621","0.04093"
"30246","181.44000","50.27116","0.04144"
"30276","181.62000","50.28617","0.04146"
"30306","181.80000","50.30117","0.04180"
"30336","181.98000","50.31618","0.04223"
"30366","182.16000","50.33125","0.04254"
"30396","182.34000","50.34620","0.04266"
"30426","182.52000","50.36120","0.04314"
"30456","182.70000","50.37621","0.04098"
"30486","182.88000","50.39122","0.04035"
"30516","183.06000","50.40622","0.04072"
"30546","183.24000","50.42123","0.03974"
"30576","183.42000","50.43618","0.04034"
"30606","183.60000","50.45125","0.04064"
"30636","183.78000","50.46625","0.04085"
"30666","183.96000","50.48114","0.04051"
"30696","184.14000","50.49620","0.04111"
"30726","184.32000","50.51121","0.04110"
"30756","184.50000","50.52617","0.04129"
"30786","184.68000","50.54123","0.04163"
"30816","184.86000","50.55624","0.04219"
"30846","185.04000","50.57119","0.04220"
"30876","185.22000","50.58619","0.04142"
"30906","185.40000","50.60125","0.04117"
"30936","185.58000","50.61620","0.04213"
"30966","185.76000","50.63128","0.04209"
"30996","185.94000","50.64622","0.04205"
"31026","186.12000","50.66117","0.04356"
"31056","186.30000","50.67624","0.04367"
"31086","186.48000","50.69118","0.04304"
"31116","186.66000","50.70619","0.04331"
"31146","186.84000","50.72120","0.04265"
"31176","187.02000","50.73620","0.04366"
"31206","187.20000","50.75115","0.04378"
"31236","187.38000","50.76622","0.04386"
"31266","187.56000","50.78117","0.04434"
"31296","187.74000","50.79617","0.04464"
"31326","187.92000","50.81124","0.04484"
"31356","188.10000","50.82624","0.04548"
"31386","188.28000","50.84113","0.04564"
"31416","188.46000","50.85620","0.04669"
"31446","188.64000","50.87127","0.04707"
"31476","188.82000","50.88609","0.04690"
"31506","189.00000","50.90122","0.04712"
"31536","189.18000","50.91623","0.04712"
"31566","189.36000","50.93112","0.04728"
"31596","189.54000","50.94624","0.04734"
"31626","189.72000","50.96119","0.04839"
"31656","189.90000","50.97620","0.04854"
"31686","190.08000","50.99127","0.04873"
"31716","190.26000","51.00621","0.04886"
"31746","190.44000","51.02116","0.04888"
"31776","190.62000","51.03622","0.04941"
"31806","190.80000","51.05123","0.04954"
"31836","190.98000","51.06618","0.04975"
"31866","191.16000","51.08125","0.05028"
"31896","191.34000","51.09625","0.05061"
"31926","191.52000","51.11114","0.05035"
"31956","191.70000","51.12621","0.04898"
"31986","191.88000","51.14121","0.03647"
"32016","192.06000","51.15623","0.02384"
"32046","192.24000","51.17123","0.02386"
"32076","192.42000","51.18624","0.02008"
"32106","192.60000","51.20113","0.01982"
"32136","192.78000","51.21626","0.02144"
"32166","192.96000","51.23120","0.02011"
"32196","193.14000","51.24614","0.01953"
"32226","193.32000","51.26122","0.02121"
"32256","193.50000","51.27622","0.02003"
"32286","193.68000","51.29117","0.01982"
"32316","193.86000","51.30623","0.02119"
"32346","194.04000","51.32118","0.02126"
"32376","194.22000","51.33613","0.01996"
"32406","194.40000","51.35120","0.02173"
"32436","194.58000","51.36615","0.02218"
"32466","194.76000","51.38115","0.02074"
"32496","194.94000","51.39622","0.02148"
"32526","195.12000","51.41117","0.02267"
"32556","195.30000","51.42611","0.02231"
"32586","195.48000","51.44118","0.02272"
"32616","195.66000","51.45625","0.02294"
"32646","195.84000","51.47120","0.02261"
"32676","196.02000","51.48620","0.02292"
"32706","196.20000","51.50121","0.02356"
"32736","196.38000","51.51622","0.02319"
"32766","196.56000","51.53123","0.02328"
"32796","196.74000","51.54617","0.02439"
"32826","196.92000","51.56112","0.02388"
"32856","197.10000","51.57624","0.02398"
"32886","197.28000","51.59119","0.02432"
"32916","197.46000","51.60614","0.02488"
"32946","197.64000","51.62120","0.02430"
"32976","197.82000","51.63621","0.02455"
"33006","198.00000","51.65117","0.02497"
"33036","198.18000","51.66623","0.02486"
"33066","198.36000","51.68118","0.02579"
"33096","198.54000","51.69619","0.02586"
"33126","198.72000","51.71119","0.02563"
"33156","198.90000","51.72620","0.02583"
"33186","199.08000","51.74115","0.02615"
"33216","199.26000","51.75621","0.02590"
"33246","199.44000","51.77116","0.02622"
"33276","199.62000","51.78611","0.02663"
"33306","199.80000","51.80124","0.02697"
"33336","199.98000","51.81624","0.02720"
"33366","200.16000","51.83119","0.02713"
"33396","200.34000","51.84620","0.02735"
"33426","200.52000","51.86120","0.02750"
"33456","200.70000","51.87621","0.02719"
"33486","200.88000","51.89122","0.02693"
"33516","201.06000","51.90622","0.02768"
"33546","201.24000","51.92117","0.02834"
"33576","201.42000","51.93624","0.02818"
"33606","201.60000","51.95118","0.02830"
"33636","201.78000","51.96613","0.02861"
"33666","201.96000","51.98126","0.02876"
"33696","202.14000","51.99620","0.02923"
"33726","202.32000","52.01115","0.02955"
"33756","202.50000","52.02622","0.02968"
"33786","202.68000","52.04123","0.02964"
"33816","202.86000","52.05624","0.02983"
"33846","203.04000","52.07118","0.02984"
"33876","203.22000","52.08619","0.02975"
"33906","203.40000","52.10120","0.02951"
"33936","203.58000","52.11621","0.02971"
"33966","203.76000","52.13115","0.02967"
"33996","203.94000","52.14616","0.02997"
"34026","204.12000","52.16122","0.02999"
"34056","204.30000","52.17624","0.02964"
"34086","204.48000","52.19118","0.03037"
"34116","204.66000","52.20618","0.03025"
"34146","204.84000","52.22125","0.03065"
"34176","205.02000","52.23620","0.03012"
"34206","205.20000","52.25121","0.03071"
"34236","205.38000","52.26616","0.03117"
"34266","205.56000","52.28117","0.03088"
"34296","205.74000","52.29623","0.03168"
"34326","205.92000","52.31124","0.03225"
"34356","206.10000","52.32619","0.03141"
"34386","206.28000","52.34125","0.03240"
"34416","206.46000","52.35620","0.03285"
"34446","206.64000","52.37114","0.03279"
"34476","206.82000","52.38622","0.03300"
"34506","207.00000","52.40122","0.03311"
"34536","207.18000","52.41617","0.03307"
"34566","207.36000","52.43118","0.03377"
"34596","207.54000","52.44618","0.03426"
"34626","207.72000","52.46119","0.03316"
"34656","207.90000","52.47620","0.03445"
"34686","208.08000","52.49115","0.03389"
"34716","208.26000","52.50615","0.03433"
"34746","208.44000","52.52128","0.03473"
"34776","208.62000","52.53617","0.03478"
"34806","208.80000","52.55118","0.03562"
"34836","208.98000","52.56618","0.03482"
"34866","209.16000","52.58125","0.03622"
"34896","209.34000","52.59620","0.03595"
"34926","209.52000","52.61120","0.03642"
"34956","209.70000","52.62615","0.03620"
"34986","209.88000","52.64115","0.03664"
"35016","210.06000","52.65616","0.03735"
"35046","210.24000","52.67123","0.03716"
"35076","210.42000","52.68618","0.03725"
"35106","210.60000","52.70124","0.03761"
"35136","210.78000","52.71619","0.03808"
"35166","210.96000","52.73120","0.03863"
"35196","211.14000","52.74627","0.03871"
"35226","211.32000","52.76121","0.03871"
"35256","211.50000","52.77617","0.03940"
"35286","211.68000","52.79117","0.03976"
"35316","211.86000","52.80618","0.03999"
"35346","212.04000","52.82124","0.03942"
"35376","212.22000","52.83619","0.04049"
"35406","212.40000","52.85114","0.04025"
"35436","212.58000","52.86621","0.03858"
"35466","212.76000","52.88121","0.03885"
"35496","212.94000","52.89616","0.03884"
"35526","213.12000","52.91123","0.03969"
"35556","213.30000","52.92624","0.03922"
"35586","213.48000","52.94118","0.03985"
"35616","213.66000","52.95619","0.03961"
"35646","213.84000","52.97119","0.04003"
"35676","214.02000","52.98620","0.04030"
"35706","214.20000","53.00121","0.04129"
"35736","214.38000","53.01622","0.04110"
"35766","214.56000","53.03117","0.04080"
"35796","214.74000","53.04623","0.04158"
"35826","214.92000","53.06118","0.04200"
"35856","215.10000","53.07619","0.04211"
"35886","215.28000","53.09119","0.04194"
"35916","215.46000","53.10626","0.04266"
"35946","215.64000","53.12120","0.04292"
"35976","215.82000","53.13615","0.04283"
"36006","216.00000","53.15122","0.04312"
"36036","216.18000","53.16617","0.04369"
"36066","216.36000","53.18124","0.04358"
"36096","216.54000","53.19618","0.04389"
"36126","216.72000","53.21119","0.04414"
"36156","216.90000","53.22620","0.04454"
"36186","217.08000","53.24121","0.04465"
"36216","217.26000","53.25621","0.04472"
"36246","217.44000","53.27116","0.04507"
"36276","217.62000","53.28622","0.04504"
"36306","217.80000","53.30117","0.04523"
"36336","217.98000","53.31624","0.04551"
"36366","218.16000","53.33118","0.04579"
"36396","218.34000","53.34620","0.04572"
"36426","218.52000","53.36114","0.04621"
"36456","218.70000","53.37621","0.04609"
"36486","218.88000","53.39122","0.04638"
"36516","219.06000","53.40623","0.04596"
"36546","219.24000","53.42123","0.04655"
"36576","219.42000","53.43618","0.04678"
"36578","219.42800","53.43684","0.04692"