File: Trajectories_together/161226_1Specimen_RawData_9.csv
"","V1","V2","V3"
"1","End date","12/26/2016",""
"2","Specimen label","13AT_2",""
"3","Maximum Load","0.10271","N"
"4","Time","Extension","Load"
"5","(s)","(mm)","(N)"
"6","0.00000","0.00000","0.00010"
"63","0.34200","0.02846","-0.00011"
"120","0.68400","0.05716","0.00080"
"177","1.02600","0.08574","0.00072"
"234","1.36800","0.11420","0.00089"
"291","1.71000","0.14266","0.00072"
"348","2.05200","0.17124","0.00026"
"405","2.39400","0.19964","0.00040"
"462","2.73600","0.22822","0.00054"
"519","3.07800","0.25674","0.00074"
"576","3.42000","0.28508","0.00071"
"633","3.76200","0.31372","0.00067"
"690","4.10400","0.34218","-0.00002"
"747","4.44600","0.37070","0.00044"
"804","4.78800","0.39921","0.00092"
"861","5.13000","0.42767","0.00047"
"918","5.47200","0.45613","0.00098"
"975","5.81400","0.48471","0.00082"
"1032","6.15600","0.51311","0.00119"
"1089","6.49800","0.54169","0.00093"
"1146","6.84000","0.57021","0.00075"
"1203","7.18200","0.59867","0.00161"
"1260","7.52400","0.62719","0.00133"
"1317","7.86600","0.65565","0.00125"
"1374","8.20800","0.68417","0.00086"
"1431","8.55000","0.71269","0.00141"
"1488","8.89200","0.74109","0.00156"
"1545","9.23400","0.76967","0.00110"
"1602","9.57600","0.79819","0.00127"
"1659","9.91800","0.82665","0.00168"
"1716","10.26000","0.85517","0.00098"
"1773","10.60200","0.88369","0.00010"
"1830","10.94400","0.91215","0.00032"
"1887","11.28600","0.94073","-0.00008"
"1944","11.62800","0.96919","0.00078"
"2001","11.97000","0.99765","0.00019"
"2058","12.31200","1.02617","0.00000"
"2115","12.65400","1.05463","0.00056"
"2172","12.99600","1.08321","0.00111"
"2229","13.33800","1.11173","0.00093"
"2286","13.68000","1.14013","0.00109"
"2343","14.02200","1.16871","0.00144"
"2400","14.36400","1.19717","0.00133"
"2457","14.70600","1.22563","0.00102"
"2514","15.04800","1.25420","0.00078"
"2571","15.39000","1.28266","0.00067"
"2628","15.73200","1.31118","0.00071"
"2685","16.07400","1.33964","0.00094"
"2742","16.41600","1.36816","0.00097"
"2799","16.75800","1.39668","0.00086"
"2856","17.10000","1.42520","0.00112"
"2913","17.44200","1.45360","0.00074"
"2970","17.78400","1.48224","0.00087"
"3027","18.12600","1.51070","0.00092"
"3084","18.46800","1.53916","0.00047"
"3141","18.81000","1.56768","0.00066"
"3198","19.15200","1.59620","0.00054"
"3255","19.49400","1.62466","0.00041"
"3312","19.83600","1.65318","0.00070"
"3369","20.17800","1.68164","0.00096"
"3426","20.52000","1.71016","0.00117"
"3483","20.86200","1.73874","0.00085"
"3540","21.20400","1.76714","0.00107"
"3597","21.54600","1.79572","0.00090"
"3654","21.88800","1.82424","0.00018"
"3711","22.23000","1.85264","0.00103"
"3768","22.57200","1.88122","0.00131"
"3825","22.91400","1.90962","0.00053"
"3882","23.25600","1.93814","0.00130"
"3939","23.59800","1.96672","0.00177"
"3996","23.94000","1.99518","0.00124"
"4053","24.28200","2.02364","0.00139"
"4110","24.62400","2.05216","0.00100"
"4167","24.96600","2.08062","0.00096"
"4224","25.30800","2.10920","0.00122"
"4281","25.65000","2.13772","0.00097"
"4338","25.99200","2.16617","0.00117"
"4395","26.33400","2.19475","0.00101"
"4452","26.67600","2.22315","0.00096"
"4509","27.01800","2.25167","0.00145"
"4566","27.36000","2.28019","0.00117"
"4623","27.70200","2.30865","0.00108"
"4680","28.04400","2.33723","0.00151"
"4737","28.38600","2.36575","0.00175"
"4794","28.72800","2.39415","0.00131"
"4851","29.07000","2.42267","0.00132"
"4908","29.41200","2.45119","0.00128"
"4965","29.75400","2.47965","0.00151"
"5022","30.09600","2.50823","0.00152"
"5079","30.43800","2.53663","0.00136"
"5136","30.78000","2.56521","0.00150"
"5193","31.12200","2.59367","0.00157"
"5250","31.46400","2.62213","0.00176"
"5307","31.80600","2.65071","0.00182"
"5364","32.14800","2.67917","0.00170"
"5421","32.49000","2.70763","0.00195"
"5478","32.83200","2.73621","0.00124"
"5535","33.17400","2.76467","0.00159"
"5592","33.51600","2.79319","0.00206"
"5649","33.85800","2.82171","0.00161"
"5706","34.20000","2.85017","0.00165"
"5763","34.54200","2.87869","0.00135"
"5820","34.88400","2.90715","0.00165"
"5877","35.22600","2.93567","0.00137"
"5934","35.56800","2.96419","0.00172"
"5991","35.91000","2.99271","0.00195"
"6048","36.25200","3.02122","0.00174"
"6105","36.59400","3.04968","0.00161"
"6162","36.93600","3.07820","0.00149"
"6219","37.27800","3.10660","0.00165"
"6276","37.62000","3.13518","0.00189"
"6333","37.96200","3.16364","0.00173"
"6390","38.30400","3.19222","0.00198"
"6447","38.64600","3.22074","0.00209"
"6504","38.98800","3.24908","0.00186"
"6561","39.33000","3.27766","0.00144"
"6618","39.67200","3.30624","0.00204"
"6675","40.01400","3.33464","0.00170"
"6732","40.35600","3.36322","0.00187"
"6789","40.69800","3.39168","0.00208"
"6846","41.04000","3.42014","0.00176"
"6903","41.38200","3.44872","0.00164"
"6960","41.72400","3.47712","0.00163"
"7017","42.06600","3.50564","0.00195"
"7074","42.40800","3.53422","0.00106"
"7131","42.75000","3.56262","0.00187"
"7188","43.09200","3.59120","0.00197"
"7245","43.43400","3.61972","0.00186"
"7302","43.77600","3.64812","0.00189"
"7359","44.11800","3.67670","0.00171"
"7416","44.46000","3.70510","0.00218"
"7473","44.80200","3.73362","0.00194"
"7530","45.14400","3.76220","0.00227"
"7587","45.48600","3.79066","0.00193"
"7644","45.82800","3.81918","0.00218"
"7701","46.17000","3.84776","0.00212"
"7758","46.51200","3.87616","0.00220"
"7815","46.85400","3.90474","0.00217"
"7872","47.19600","3.93319","0.00222"
"7929","47.53800","3.96165","0.00193"
"7986","47.88000","3.99023","0.00243"
"8043","48.22200","4.01863","0.00217"
"8100","48.56400","4.04715","0.00251"
"8157","48.90600","4.07567","0.00211"
"8214","49.24800","4.10413","0.00180"
"8271","49.59000","4.13265","0.00195"
"8328","49.93200","4.16123","0.00200"
"8385","50.27400","4.18963","0.00181"
"8442","50.61600","4.21821","0.00247"
"8499","50.95800","4.24667","0.00203"
"8556","51.30000","4.27519","0.00187"
"8613","51.64200","4.30365","0.00196"
"8670","51.98400","4.33217","0.00204"
"8727","52.32600","4.36069","0.00169"
"8784","52.66800","4.38915","0.00224"
"8841","53.01000","4.41761","0.00200"
"8898","53.35200","4.44613","0.00246"
"8955","53.69400","4.47471","0.00253"
"9012","54.03600","4.50311","0.00219"
"9069","54.37800","4.53169","0.00208"
"9126","54.72000","4.56021","0.00231"
"9183","55.06200","4.58867","0.00224"
"9240","55.40400","4.61719","0.00249"
"9297","55.74600","4.64571","0.00156"
"9354","56.08800","4.67417","0.00242"
"9411","56.43000","4.70269","0.00243"
"9468","56.77200","4.73121","0.00208"
"9525","57.11400","4.75967","0.00230"
"9582","57.45600","4.78819","0.00230"
"9639","57.79800","4.81664","0.00277"
"9696","58.14000","4.84516","0.00250"
"9753","58.48200","4.87368","0.00224"
"9810","58.82400","4.90214","0.00268"
"9867","59.16600","4.93072","0.00248"
"9924","59.50800","4.95918","0.00239"
"9981","59.85000","4.98764","0.00261"
"10038","60.19200","5.01622","0.00239"
"10095","60.53400","5.04462","0.00240"
"10152","60.87600","5.07320","0.00210"
"10209","61.21800","5.10172","0.00241"
"10266","61.56000","5.13018","0.00294"
"10323","61.90200","5.15870","0.00250"
"10380","62.24400","5.18722","0.00255"
"10437","62.58600","5.21562","0.00249"
"10494","62.92800","5.24420","0.00280"
"10551","63.27000","5.27266","0.00284"
"10608","63.61200","5.30112","0.00254"
"10665","63.95400","5.32970","0.00231"
"10722","64.29600","5.35810","0.00269"
"10779","64.63800","5.38674","0.00256"
"10836","64.98000","5.41526","0.00243"
"10893","65.32200","5.44366","0.00240"
"10950","65.66400","5.47224","0.00252"
"11007","66.00600","5.50064","0.00269"
"11064","66.34800","5.52916","0.00265"
"11121","66.69000","5.55768","0.00263"
"11178","67.03200","5.58614","0.00305"
"11235","67.37400","5.61472","0.00309"
"11292","67.71600","5.64312","0.00289"
"11349","68.05800","5.67158","0.00278"
"11406","68.40000","5.70021","0.00273"
"11463","68.74200","5.72867","0.00248"
"11520","69.08400","5.75713","0.00331"
"11577","69.42600","5.78571","0.00261"
"11634","69.76800","5.81417","0.00302"
"11691","70.11000","5.84263","0.00272"
"11748","70.45200","5.87121","0.00258"
"11805","70.79400","5.89961","0.00287"
"11862","71.13600","5.92819","0.00316"
"11919","71.47800","5.95665","0.00270"
"11976","71.82000","5.98517","0.00279"
"12033","72.16200","6.01369","0.00219"
"12090","72.50400","6.04221","0.00282"
"12147","72.84600","6.07061","0.00259"
"12204","73.18800","6.09919","0.00288"
"12261","73.53000","6.12771","0.00304"
"12318","73.87200","6.15617","0.00344"
"12375","74.21400","6.18469","0.00292"
"12432","74.55600","6.21315","0.00303"
"12489","74.89800","6.24167","0.00384"
"12546","75.24000","6.27019","0.00302"
"12603","75.58200","6.29865","0.00302"
"12660","75.92400","6.32717","0.00286"
"12717","76.26600","6.35575","0.00299"
"12774","76.60800","6.38415","0.00341"
"12831","76.95000","6.41267","0.00338"
"12888","77.29200","6.44119","0.00295"
"12945","77.63400","6.46965","0.00337"
"13002","77.97600","6.49823","0.00340"
"13059","78.31800","6.52669","0.00296"
"13116","78.66000","6.55514","0.00271"
"13173","79.00200","6.58372","0.00320"
"13230","79.34400","6.61212","0.00326"
"13287","79.68600","6.64070","0.00313"
"13344","80.02800","6.66922","0.00329"
"13401","80.37000","6.69756","0.00298"
"13458","80.71200","6.72620","0.00303"
"13515","81.05400","6.75466","0.00285"
"13572","81.39600","6.78312","0.00311"
"13629","81.73800","6.81170","0.00313"
"13686","82.08000","6.84016","0.00320"
"13743","82.42200","6.86868","0.00327"
"13800","82.76400","6.89720","0.00320"
"13857","83.10600","6.92560","0.00325"
"13914","83.44800","6.95424","0.00316"
"13971","83.79000","6.98270","0.00322"
"14028","84.13200","7.01116","0.00330"
"14085","84.47400","7.03974","0.00324"
"14142","84.81600","7.06814","0.00300"
"14199","85.15800","7.09666","0.00311"
"14256","85.50000","7.12518","0.00305"
"14313","85.84200","7.15364","0.00267"
"14370","86.18400","7.18216","0.00278"
"14427","86.52600","7.21068","0.00292"
"14484","86.86800","7.23914","0.00316"
"14541","87.21000","7.26766","0.00346"
"14598","87.55200","7.29618","0.00297"
"14655","87.89400","7.32470","0.00303"
"14712","88.23600","7.35322","0.00291"
"14769","88.57800","7.38168","0.00315"
"14826","88.92000","7.41020","0.00305"
"14883","89.26200","7.43865","0.00302"
"14940","89.60400","7.46712","0.00321"
"14997","89.94600","7.49569","0.00277"
"15054","90.28800","7.52421","0.00302"
"15111","90.63000","7.55267","0.00288"
"15168","90.97200","7.58119","0.00315"
"15225","91.31400","7.60965","0.00313"
"15282","91.65600","7.63811","0.00293"
"15339","91.99800","7.66669","0.00330"
"15396","92.34000","7.69515","0.00296"
"15453","92.68200","7.72367","0.00303"
"15510","93.02400","7.75219","0.00287"
"15567","93.36600","7.78065","0.00321"
"15624","93.70800","7.80923","0.00316"
"15681","94.05000","7.83775","0.00297"
"15738","94.39200","7.86615","0.00290"
"15795","94.73400","7.89467","0.00293"
"15852","95.07600","7.92319","0.00328"
"15909","95.41800","7.95165","0.00336"
"15966","95.76000","7.98017","0.00333"
"16023","96.10200","8.00863","0.00306"
"16080","96.44400","8.03709","0.00331"
"16137","96.78600","8.06573","0.00326"
"16194","97.12800","8.09419","0.00334"
"16251","97.47000","8.12271","0.00323"
"16308","97.81200","8.15123","0.00347"
"16365","98.15400","8.17963","0.00353"
"16422","98.49600","8.20821","0.00333"
"16479","98.83800","8.23667","0.00282"
"16536","99.18000","8.26513","0.00331"
"16593","99.52200","8.29370","0.00336"
"16650","99.86400","8.32216","0.00318"
"16707","100.20600","8.35063","0.00328"
"16764","100.54800","8.37920","0.00279"
"16821","100.89000","8.40760","0.00271"
"16878","101.23200","8.43618","0.00296"
"16935","101.57400","8.46470","0.00321"
"16992","101.91600","8.49316","0.00293"
"17049","102.25800","8.52168","0.00310"
"17106","102.60000","8.55020","0.00303"
"17163","102.94200","8.57866","0.00271"
"17220","103.28400","8.60718","0.00340"
"17277","103.62600","8.63564","0.00268"
"17334","103.96800","8.66422","0.00335"
"17391","104.31000","8.69268","0.00293"
"17448","104.65200","8.72114","0.00345"
"17505","104.99400","8.74966","0.00299"
"17562","105.33600","8.77818","0.00252"
"17619","105.67800","8.80670","0.00294"
"17676","106.02000","8.83516","0.00293"
"17733","106.36200","8.86368","0.00334"
"17790","106.70400","8.89214","0.00311"
"17847","107.04600","8.92072","0.00314"
"17904","107.38800","8.94918","0.00275"
"17961","107.73000","8.97764","0.00306"
"18018","108.07200","9.00622","0.00258"
"18075","108.41400","9.03468","0.00276"
"18132","108.75600","9.06320","0.00318"
"18189","109.09800","9.09166","0.00287"
"18246","109.44000","9.12012","0.00317"
"18303","109.78200","9.14870","0.00353"
"18360","110.12400","9.17715","0.00321"
"18417","110.46600","9.20568","0.00355"
"18474","110.80800","9.23419","0.00343"
"18531","111.15000","9.26271","0.00345"
"18588","111.49200","9.29117","0.00337"
"18645","111.83400","9.31969","0.00319"
"18702","112.17600","9.34815","0.00316"
"18759","112.51800","9.37667","0.00334"
"18816","112.86000","9.40519","0.00311"
"18873","113.20200","9.43359","0.00315"
"18930","113.54400","9.46217","0.00324"
"18987","113.88600","9.49063","0.00339"
"19044","114.22800","9.51915","0.00297"
"19101","114.57000","9.54767","0.00352"
"19158","114.91200","9.57619","0.00307"
"19215","115.25400","9.60465","0.00324"
"19272","115.59600","9.63323","0.00311"
"19329","115.93800","9.66163","0.00350"
"19386","116.28000","9.69021","0.00341"
"19443","116.62200","9.71873","0.00328"
"19500","116.96400","9.74713","0.00335"
"19557","117.30600","9.77571","0.00341"
"19614","117.64800","9.80417","0.00328"
"19671","117.99000","9.83269","0.00338"
"19728","118.33200","9.86115","0.00335"
"19785","118.67400","9.88967","0.00296"
"19842","119.01600","9.91819","0.00409"
"19899","119.35800","9.94671","0.00317"
"19956","119.70000","9.97511","0.00349"
"20013","120.04200","10.00369","0.00322"
"20070","120.38400","10.03215","0.00370"
"20127","120.72600","10.06066","0.00342"
"20184","121.06800","10.08918","0.00356"
"20241","121.41000","10.11764","0.00348"
"20298","121.75200","10.14610","0.00353"
"20355","122.09400","10.17468","0.00317"
"20412","122.43600","10.20314","0.00354"
"20469","122.77800","10.23172","0.00311"
"20526","123.12000","10.26024","0.00381"
"20583","123.46200","10.28864","0.00365"
"20640","123.80400","10.31716","0.00386"
"20697","124.14600","10.34568","0.00336"
"20754","124.48800","10.37414","0.00362"
"20811","124.83000","10.40266","0.00388"
"20868","125.17200","10.43118","0.00386"
"20925","125.51400","10.45964","0.00374"
"20982","125.85600","10.48822","0.00365"
"21039","126.19800","10.51662","0.00380"
"21096","126.54000","10.54514","0.00331"
"21153","126.88200","10.57366","0.00354"
"21210","127.22400","10.60218","0.00336"
"21267","127.56600","10.63070","0.00342"
"21324","127.90800","10.65916","0.00310"
"21381","128.25000","10.68762","0.00346"
"21438","128.59200","10.71614","0.00329"
"21495","128.93400","10.74472","0.00354"
"21552","129.27600","10.77318","0.00325"
"21609","129.61800","10.80176","0.00348"
"21666","129.96000","10.83016","0.00375"
"21723","130.30200","10.85862","0.00326"
"21780","130.64400","10.88725","0.00327"
"21837","130.98600","10.91566","0.00269"
"21894","131.32800","10.94418","0.00281"
"21951","131.67000","10.97269","0.00319"
"22008","132.01200","11.00109","0.00338"
"22065","132.35400","11.02973","0.00279"
"22122","132.69600","11.05819","0.00342"
"22179","133.03800","11.08665","0.00333"
"22236","133.38000","11.11523","0.00321"
"22293","133.72200","11.14363","0.00353"
"22350","134.06400","11.17215","0.00353"
"22407","134.40600","11.20073","0.00362"
"22464","134.74800","11.22907","0.00277"
"22521","135.09000","11.25771","0.00343"
"22578","135.43200","11.28623","0.00318"
"22635","135.77400","11.31463","0.00350"
"22692","136.11600","11.34321","0.00333"
"22749","136.45800","11.37161","0.00356"
"22806","136.80000","11.40019","0.00319"
"22863","137.14200","11.42871","0.00362"
"22920","137.48400","11.45711","0.00342"
"22977","137.82600","11.48569","0.00360"
"23034","138.16800","11.51421","0.00365"
"23091","138.51000","11.54261","0.00356"
"23148","138.85200","11.57113","0.00328"
"23205","139.19400","11.59965","0.00318"
"23262","139.53600","11.62817","0.00314"
"23319","139.87800","11.65669","0.00350"
"23376","140.22000","11.68515","0.00349"
"23433","140.56200","11.71373","0.00306"
"23490","140.90400","11.74219","0.00358"
"23547","141.24600","11.77059","0.00331"
"23604","141.58800","11.79922","0.00335"
"23661","141.93000","11.82769","0.00339"
"23718","142.27200","11.85614","0.00329"
"23775","142.61400","11.88472","0.00363"
"23832","142.95600","11.91318","0.00329"
"23889","143.29800","11.94164","0.00310"
"23946","143.64000","11.97016","0.00372"
"24003","143.98200","11.99868","0.00329"
"24060","144.32400","12.02714","0.00366"
"24117","144.66600","12.05566","0.00366"
"24174","145.00800","12.08412","0.00344"
"24231","145.35000","12.11264","0.00338"
"24288","145.69200","12.14122","0.00331"
"24345","146.03400","12.16968","0.00311"
"24402","146.37600","12.19820","0.00318"
"24459","146.71800","12.22666","0.00348"
"24516","147.06000","12.25518","0.00405"
"24573","147.40200","12.28364","0.00320"
"24630","147.74400","12.31216","0.00374"
"24687","148.08600","12.34062","0.00316"
"24744","148.42800","12.36920","0.00318"
"24801","148.77000","12.39766","0.00340"
"24858","149.11200","12.42618","0.00377"
"24915","149.45400","12.45476","0.00342"
"24972","149.79600","12.48316","0.00334"
"25029","150.13800","12.51168","0.00359"
"25086","150.48000","12.54014","0.00352"
"25143","150.82200","12.56866","0.00296"
"25200","151.16400","12.59724","0.00337"
"25257","151.50600","12.62564","0.00340"
"25314","151.84800","12.65410","0.00353"
"25371","152.19000","12.68274","0.00340"
"25428","152.53200","12.71108","0.00341"
"25485","152.87400","12.73972","0.00379"
"25542","153.21600","12.76817","0.00322"
"25599","153.55800","12.79663","0.00396"
"25656","153.90000","12.82521","0.00386"
"25713","154.24200","12.85367","0.00345"
"25770","154.58400","12.88213","0.00329"
"25827","154.92600","12.91071","0.00313"
"25884","155.26800","12.93911","0.00321"
"25941","155.61000","12.96769","0.00347"
"25998","155.95200","12.99621","0.00363"
"26055","156.29400","13.02461","0.00352"
"26112","156.63600","13.05319","0.00357"
"26169","156.97800","13.08165","0.00344"
"26226","157.32000","13.11011","0.00368"
"26283","157.66200","13.13875","0.00378"
"26340","158.00400","13.16721","0.00363"
"26397","158.34600","13.19567","0.00399"
"26454","158.68800","13.22419","0.00320"
"26511","159.03000","13.25265","0.00353"
"26568","159.37200","13.28117","0.00364"
"26625","159.71400","13.30975","0.00390"
"26682","160.05600","13.33815","0.00406"
"26739","160.39800","13.36667","0.00354"
"26796","160.74000","13.39519","0.00381"
"26853","161.08200","13.42371","0.00331"
"26910","161.42400","13.45223","0.00371"
"26967","161.76600","13.48069","0.00391"
"27024","162.10800","13.50915","0.00389"
"27081","162.45000","13.53767","0.00358"
"27138","162.79200","13.56618","0.00347"
"27195","163.13400","13.59471","0.00362"
"27252","163.47600","13.62316","0.00381"
"27309","163.81800","13.65168","0.00351"
"27366","164.16000","13.68020","0.00376"
"27423","164.50200","13.70872","0.00322"
"27480","164.84400","13.73712","0.00367"
"27537","165.18600","13.76564","0.00375"
"27594","165.52800","13.79416","0.00335"
"27651","165.87000","13.82268","0.00369"
"27708","166.21200","13.85120","0.00381"
"27765","166.55400","13.87966","0.00357"
"27822","166.89600","13.90818","0.00364"
"27879","167.23800","13.93670","0.00383"
"27936","167.58000","13.96516","0.00373"
"27993","167.92200","13.99368","0.00377"
"28050","168.26400","14.02220","0.00418"
"28107","168.60600","14.05066","0.00395"
"28164","168.94800","14.07924","0.00387"
"28221","169.29000","14.10764","0.00379"
"28278","169.63200","14.13616","0.00370"
"28335","169.97400","14.16468","0.00397"
"28392","170.31600","14.19314","0.00404"
"28449","170.65800","14.22166","0.00396"
"28506","171.00000","14.25018","0.00335"
"28563","171.34200","14.27864","0.00361"
"28620","171.68400","14.30722","0.00371"
"28677","172.02600","14.33568","0.00362"
"28734","172.36800","14.36414","0.00389"
"28791","172.71000","14.39272","0.00398"
"28848","173.05200","14.42112","0.00356"
"28905","173.39400","14.44964","0.00376"
"28962","173.73600","14.47822","0.00376"
"29019","174.07800","14.50662","0.00355"
"29076","174.42000","14.53519","0.00397"
"29133","174.76200","14.56371","0.00412"
"29190","175.10400","14.59211","0.00416"
"29247","175.44600","14.62069","0.00415"
"29304","175.78800","14.64915","0.00404"
"29361","176.13000","14.67761","0.00376"
"29418","176.47200","14.70619","0.00418"
"29475","176.81400","14.73459","0.00403"
"29532","177.15600","14.76317","0.00390"
"29589","177.49800","14.79163","0.00371"
"29646","177.84000","14.82015","0.00349"
"29703","178.18200","14.84867","0.00346"
"29760","178.52400","14.87719","0.00379"
"29817","178.86600","14.90565","0.00381"
"29874","179.20800","14.93423","0.00430"
"29931","179.55000","14.96263","0.00368"
"29988","179.89200","14.99115","0.00399"
"30045","180.23400","15.01973","0.00398"
"30102","180.57600","15.04819","0.00418"
"30159","180.91800","15.07671","0.00388"
"30216","181.26000","15.10517","0.00398"
"30273","181.60200","15.13369","0.00409"
"30330","181.94400","15.16215","0.00407"
"30387","182.28600","15.19067","0.00393"
"30444","182.62800","15.21913","0.00436"
"30501","182.97000","15.24771","0.00385"
"30558","183.31200","15.27623","0.00385"
"30615","183.65400","15.30463","0.00446"
"30672","183.99600","15.33315","0.00406"
"30729","184.33800","15.36166","0.00404"
"30786","184.68000","15.39018","0.00439"
"30843","185.02200","15.41876","0.00410"
"30900","185.36400","15.44710","0.00432"
"30957","185.70600","15.47569","0.00491"
"31014","186.04800","15.50420","0.00449"
"31071","186.39000","15.53266","0.00419"
"31128","186.73200","15.56124","0.00444"
"31185","187.07400","15.58970","0.00446"
"31242","187.41600","15.61810","0.00468"
"31299","187.75800","15.64674","0.00435"
"31356","188.10000","15.67514","0.00444"
"31413","188.44200","15.70366","0.00485"
"31470","188.78400","15.73224","0.00459"
"31527","189.12600","15.76064","0.00465"
"31584","189.46800","15.78916","0.00492"
"31641","189.81000","15.81768","0.00456"
"31698","190.15200","15.84614","0.00455"
"31755","190.49400","15.87466","0.00472"
"31812","190.83600","15.90312","0.00468"
"31869","191.17800","15.93164","0.00472"
"31926","191.52000","15.96022","0.00433"
"31983","191.86200","15.98862","0.00464"
"32040","192.20400","16.01720","0.00483"
"32097","192.54600","16.04572","0.00441"
"32154","192.88800","16.07406","0.00445"
"32211","193.23000","16.10275","0.00465"
"32268","193.57200","16.13116","0.00485"
"32325","193.91400","16.15962","0.00485"
"32382","194.25600","16.18819","0.00506"
"32439","194.59800","16.21665","0.00499"
"32496","194.94000","16.24517","0.00468"
"32553","195.28200","16.27369","0.00490"
"32610","195.62400","16.30215","0.00499"
"32667","195.96600","16.33068","0.00518"
"32724","196.30800","16.35919","0.00496"
"32781","196.65000","16.38765","0.00548"
"32838","196.99200","16.41617","0.00481"
"32895","197.33400","16.44469","0.00489"
"32952","197.67600","16.47315","0.00494"
"33009","198.01800","16.50173","0.00544"
"33066","198.36000","16.53019","0.00518"
"33123","198.70200","16.55865","0.00500"
"33180","199.04400","16.58717","0.00520"
"33237","199.38600","16.61569","0.00516"
"33294","199.72800","16.64421","0.00543"
"33351","200.07000","16.67267","0.00525"
"33408","200.41200","16.70113","0.00482"
"33465","200.75400","16.72965","0.00511"
"33522","201.09600","16.75823","0.00524"
"33579","201.43800","16.78663","0.00518"
"33636","201.78000","16.81521","0.00522"
"33693","202.12200","16.84373","0.00556"
"33750","202.46400","16.87213","0.00533"
"33807","202.80600","16.90071","0.00557"
"33864","203.14800","16.92911","0.00539"
"33921","203.49000","16.95763","0.00541"
"33978","203.83200","16.98621","0.00545"
"34035","204.17400","17.01467","0.00521"
"34092","204.51600","17.04319","0.00532"
"34149","204.85800","17.07170","0.00522"
"34206","205.20000","17.10011","0.00542"
"34263","205.54200","17.12868","0.00546"
"34320","205.88400","17.15714","0.00561"
"34377","206.22600","17.18566","0.00546"
"34434","206.56800","17.21424","0.00522"
"34491","206.91000","17.24264","0.00556"
"34548","207.25200","17.27116","0.00560"
"34605","207.59400","17.29974","0.00527"
"34662","207.93600","17.32808","0.00511"
"34719","208.27800","17.35666","0.00530"
"34776","208.62000","17.38512","0.00537"
"34833","208.96200","17.41364","0.00496"
"34890","209.30400","17.44222","0.00452"
"34947","209.64600","17.47068","0.00495"
"35004","209.98800","17.49914","0.00498"
"35061","210.33000","17.52766","0.00545"
"35118","210.67200","17.55612","0.00490"
"35175","211.01400","17.58470","0.00565"
"35232","211.35600","17.61322","0.00519"
"35289","211.69800","17.64162","0.00532"
"35346","212.04000","17.67020","0.00534"
"35403","212.38200","17.69866","0.00560"
"35460","212.72400","17.72718","0.00578"
"35517","213.06600","17.75570","0.00556"
"35574","213.40800","17.78416","0.00558"
"35631","213.75000","17.81268","0.00572"
"35688","214.09200","17.84114","0.00595"
"35745","214.43400","17.86966","0.00534"
"35802","214.77600","17.89818","0.00533"
"35859","215.11800","17.92669","0.00560"
"35916","215.46000","17.95516","0.00574"
"35973","215.80200","17.98368","0.00569"
"36030","216.14400","18.01213","0.00578"
"36087","216.48600","18.04066","0.00433"
"36144","216.82800","18.06917","0.00429"
"36201","217.17000","18.09769","0.00546"
"36258","217.51200","18.12615","0.00548"
"36315","217.85400","18.15467","0.00468"
"36372","218.19600","18.18313","0.00506"
"36429","218.53800","18.21171","0.00552"
"36486","218.88000","18.24017","0.00530"
"36543","219.22200","18.26863","0.00480"
"36600","219.56400","18.29721","0.00554"
"36657","219.90600","18.32573","0.00574"
"36714","220.24800","18.35413","0.00555"
"36771","220.59000","18.38265","0.00535"
"36828","220.93200","18.41117","0.00546"
"36885","221.27400","18.43963","0.00569"
"36942","221.61600","18.46821","0.00532"
"36999","221.95800","18.49661","0.00568"
"37056","222.30000","18.52519","0.00594"
"37113","222.64200","18.55365","0.00565"
"37170","222.98400","18.58211","0.00543"
"37227","223.32600","18.61069","0.00551"
"37284","223.66800","18.63921","0.00605"
"37341","224.01000","18.66767","0.00577"
"37398","224.35200","18.69619","0.00561"
"37455","224.69400","18.72465","0.00515"
"37512","225.03600","18.75311","0.00527"
"37569","225.37800","18.78175","0.00595"
"37626","225.72000","18.81009","0.00580"
"37683","226.06200","18.83873","0.00562"
"37740","226.40400","18.86719","0.00534"
"37797","226.74600","18.89565","0.00537"
"37854","227.08800","18.92422","0.00591"
"37911","227.43000","18.95268","0.00560"
"37968","227.77200","18.98114","0.00555"
"38025","228.11400","19.00972","0.00590"
"38082","228.45600","19.03812","0.00595"
"38139","228.79800","19.06670","0.00582"
"38196","229.14000","19.09516","0.00602"
"38253","229.48200","19.12362","0.00580"
"38310","229.82400","19.15220","0.00596"
"38367","230.16600","19.18066","0.00627"
"38424","230.50800","19.20912","0.00593"
"38481","230.85000","19.23770","0.00571"
"38538","231.19200","19.26616","0.00542"
"38595","231.53400","19.29462","0.00563"
"38652","231.87600","19.32320","0.00561"
"38709","232.21800","19.35166","0.00535"
"38766","232.56000","19.38018","0.00503"
"38823","232.90200","19.40870","0.00558"
"38880","233.24400","19.43716","0.00541"
"38937","233.58600","19.46562","0.00534"
"38994","233.92800","19.49414","0.00587"
"39051","234.27000","19.52266","0.00512"
"39108","234.61200","19.55124","0.00495"
"39165","234.95400","19.57970","0.00547"
"39222","235.29600","19.60816","0.00555"
"39279","235.63800","19.63667","0.00504"
"39336","235.98000","19.66514","0.00518"
"39393","236.32200","19.69366","0.00548"
"39450","236.66400","19.72217","0.00570"
"39507","237.00600","19.75064","0.00577"
"39564","237.34800","19.77915","0.00598"
"39621","237.69000","19.80767","0.00619"
"39678","238.03200","19.83614","0.00609"
"39735","238.37400","19.86471","0.00626"
"39792","238.71600","19.89323","0.00605"
"39849","239.05800","19.92163","0.00636"
"39906","239.40000","19.95015","0.00634"
"39963","239.74200","19.97867","0.00651"
"40020","240.08400","20.00713","0.00699"
"40077","240.42600","20.03577","0.00673"
"40134","240.76800","20.06411","0.00657"
"40191","241.11000","20.09269","0.00717"
"40248","241.45200","20.12115","0.00704"
"40305","241.79400","20.14967","0.00682"
"40362","242.13600","20.17819","0.00728"
"40419","242.47800","20.20665","0.00706"
"40476","242.82000","20.23511","0.00709"
"40533","243.16200","20.26363","0.00710"
"40590","243.50400","20.29215","0.00670"
"40647","243.84600","20.32067","0.00653"
"40704","244.18800","20.34925","0.00613"
"40761","244.53000","20.37759","0.00592"
"40818","244.87200","20.40623","0.00596"
"40875","245.21400","20.43469","0.00583"
"40932","245.55600","20.46315","0.00620"
"40989","245.89800","20.49172","0.00607"
"41046","246.24000","20.52007","0.00617"
"41103","246.58200","20.54865","0.00603"
"41160","246.92400","20.57716","0.00618"
"41217","247.26600","20.60563","0.00610"
"41274","247.60800","20.63421","0.00600"
"41331","247.95000","20.66267","0.00605"
"41388","248.29200","20.69112","0.00594"
"41445","248.63400","20.71970","0.00611"
"41502","248.97600","20.74817","0.00594"
"41559","249.31800","20.77668","0.00628"
"41616","249.66000","20.80514","0.00645"
"41673","250.00200","20.83360","0.00617"
"41730","250.34400","20.86218","0.00647"
"41787","250.68600","20.89064","0.00657"
"41844","251.02800","20.91916","0.00658"
"41901","251.37000","20.94768","0.00648"
"41958","251.71200","20.97614","0.00670"
"42015","252.05400","21.00466","0.00668"
"42072","252.39600","21.03318","0.00675"
"42129","252.73800","21.06170","0.00654"
"42186","253.08000","21.09016","0.00675"
"42243","253.42200","21.11868","0.00686"
"42300","253.76400","21.14720","0.00685"
"42357","254.10600","21.17566","0.00704"
"42414","254.44800","21.20418","0.00686"
"42471","254.79000","21.23264","0.00674"
"42528","255.13200","21.26122","0.00661"
"42585","255.47400","21.28974","0.00701"
"42642","255.81600","21.31814","0.00654"
"42699","256.15800","21.34672","0.00705"
"42756","256.50000","21.37518","0.00728"
"42813","256.84200","21.40369","0.00729"
"42870","257.18400","21.43216","0.00731"
"42927","257.52600","21.46067","0.00741"
"42984","257.86800","21.48919","0.00756"
"43041","258.21000","21.51771","0.00758"
"43098","258.55200","21.54618","0.00769"
"43155","258.89400","21.57470","0.00748"
"43212","259.23600","21.60321","0.00776"
"43269","259.57800","21.63161","0.00789"
"43326","259.92000","21.66019","0.00810"
"43383","260.26200","21.68865","0.00810"
"43440","260.60400","21.71711","0.00765"
"43497","260.94600","21.74569","0.00798"
"43554","261.28800","21.77415","0.00759"
"43611","261.63000","21.80261","0.00796"
"43668","261.97200","21.83125","0.00796"
"43725","262.31400","21.85959","0.00775"
"43782","262.65600","21.88817","0.00782"
"43839","262.99800","21.91669","0.00841"
"43896","263.34000","21.94515","0.00813"
"43953","263.68200","21.97373","0.00798"
"44010","264.02400","22.00219","0.00865"
"44067","264.36600","22.03065","0.00868"
"44124","264.70800","22.05923","0.00865"
"44181","265.05000","22.08763","0.00849"
"44238","265.39200","22.11621","0.00886"
"44295","265.73400","22.14467","0.00877"
"44352","266.07600","22.17313","0.00912"
"44409","266.41800","22.20171","0.00908"
"44466","266.76000","22.23017","0.00749"
"44523","267.10200","22.25869","0.00764"
"44580","267.44400","22.28720","0.00711"
"44637","267.78600","22.31566","0.00771"
"44694","268.12800","22.34413","0.00747"
"44751","268.47000","22.37271","0.00756"
"44808","268.81200","22.40117","0.00772"
"44865","269.15400","22.42962","0.00753"
"44922","269.49600","22.45815","0.00750"
"44979","269.83800","22.48666","0.00793"
"45036","270.18000","22.51518","0.00762"
"45093","270.52200","22.54364","0.00757"
"45150","270.86400","22.57216","0.00770"
"45207","271.20600","22.60068","0.00817"
"45264","271.54800","22.62914","0.00767"
"45321","271.89000","22.65766","0.00796"
"45378","272.23200","22.68618","0.00769"
"45435","272.57400","22.71470","0.00811"
"45492","272.91600","22.74316","0.00774"
"45549","273.25800","22.77174","0.00766"
"45606","273.60000","22.80020","0.00806"
"45663","273.94200","22.82872","0.00828"
"45720","274.28400","22.85718","0.00797"
"45777","274.62600","22.88558","0.00834"
"45834","274.96800","22.91416","0.00847"
"45891","275.31000","22.94262","0.00789"
"45948","275.65200","22.97120","0.00781"
"46005","275.99400","22.99966","0.00817"
"46062","276.33600","23.02818","0.00797"
"46119","276.67800","23.05664","0.00839"
"46176","277.02000","23.08522","0.00806"
"46233","277.36200","23.11362","0.00856"
"46290","277.70400","23.14220","0.00823"
"46347","278.04600","23.17072","0.00869"
"46404","278.38800","23.19912","0.00893"
"46461","278.73000","23.22775","0.00923"
"46518","279.07200","23.25616","0.00947"
"46575","279.41400","23.28468","0.00969"
"46632","279.75600","23.31319","0.01009"
"46689","280.09800","23.34160","0.01042"
"46746","280.44000","23.37023","0.01074"
"46803","280.78200","23.39869","0.01129"
"46860","281.12400","23.42715","0.01134"
"46917","281.46600","23.45573","0.01213"
"46974","281.80800","23.48419","0.01239"
"47031","282.15000","23.51265","0.01334"
"47088","282.49200","23.54123","0.01343"
"47145","282.83400","23.56963","0.01417"
"47202","283.17600","23.59815","0.01490"
"47259","283.51800","23.62667","0.01618"
"47316","283.86000","23.65513","0.01711"
"47373","284.20200","23.68371","0.00843"
"47430","284.54400","23.71217","0.00625"
"47487","284.88600","23.74063","0.00673"
"47544","285.22800","23.76915","0.00805"
"47601","285.57000","23.79767","0.00754"
"47658","285.91200","23.82613","0.00747"
"47715","286.25400","23.85465","0.00800"
"47772","286.59600","23.88323","0.00779"
"47829","286.93800","23.91169","0.00859"
"47886","287.28000","23.94020","0.00924"
"47943","287.62200","23.96867","0.00892"
"48000","287.96400","23.99719","0.01043"
"48057","288.30600","24.02571","0.01044"
"48114","288.64800","24.05411","0.01072"
"48171","288.99000","24.08269","0.01206"
"48228","289.33200","24.11115","0.01224"
"48285","289.67400","24.13960","0.01298"
"48342","290.01600","24.16825","0.01451"
"48399","290.35800","24.19665","0.01516"
"48456","290.70000","24.22516","0.01534"
"48513","291.04200","24.25368","0.01641"
"48570","291.38400","24.28214","0.00960"
"48627","291.72600","24.31066","0.01019"
"48684","292.06800","24.33924","0.01107"
"48741","292.41000","24.36764","0.01093"
"48798","292.75200","24.39610","0.01032"
"48855","293.09400","24.42468","0.01099"
"48912","293.43600","24.45314","0.01099"
"48969","293.77800","24.48166","0.01165"
"49026","294.12000","24.51018","0.01279"
"49083","294.46200","24.53864","0.01236"
"49140","294.80400","24.56722","0.01355"
"49197","295.14600","24.59562","0.01126"
"49254","295.48800","24.62420","0.01118"
"49311","295.83000","24.65278","0.01138"
"49368","296.17200","24.68112","0.01167"
"49425","296.51400","24.70970","0.01138"
"49482","296.85600","24.73816","0.01152"
"49539","297.19800","24.76662","0.01172"
"49596","297.54000","24.79520","0.01168"
"49653","297.88200","24.82360","0.01192"
"49710","298.22400","24.85212","0.01213"
"49767","298.56600","24.88070","0.01154"
"49824","298.90800","24.90915","0.01175"
"49881","299.25000","24.93767","0.01294"
"49938","299.59200","24.96620","0.01282"
"49995","299.93400","24.99466","0.01323"
"50052","300.27600","25.02324","0.01379"
"50109","300.61800","25.05169","0.01399"
"50166","300.96000","25.08015","0.01459"
"50223","301.30200","25.10873","0.01461"
"50280","301.64400","25.13713","0.01518"
"50337","301.98600","25.16571","0.01598"
"50394","302.32800","25.19417","0.01646"
"50451","302.67000","25.22264","0.01720"
"50508","303.01200","25.25115","0.01791"
"50565","303.35400","25.27967","0.01889"
"50622","303.69600","25.30813","0.01947"
"50679","304.03800","25.33671","0.02048"
"50736","304.38000","25.36517","0.02187"
"50793","304.72200","25.39363","0.02337"
"50850","305.06400","25.42215","0.02421"
"50907","305.40600","25.45067","0.02520"
"50964","305.74800","25.47919","0.02627"
"51021","306.09000","25.50771","0.02757"
"51078","306.43200","25.53617","0.02884"
"51135","306.77400","25.56469","0.02988"
"51192","307.11600","25.59315","0.03109"
"51249","307.45800","25.62161","0.03260"
"51306","307.80000","25.65019","0.03401"
"51363","308.14200","25.67871","0.03506"
"51420","308.48400","25.70717","0.01973"
"51477","308.82600","25.73563","0.01839"
"51534","309.16800","25.76421","0.01916"
"51591","309.51000","25.79267","0.02146"
"51648","309.85200","25.82125","0.02215"
"51705","310.19400","25.84965","0.02214"
"51762","310.53600","25.87817","0.02335"
"51819","310.87800","25.90675","0.02322"
"51876","311.22000","25.93514","0.02205"
"51933","311.56200","25.96373","0.02078"
"51990","311.90400","25.99212","0.02121"
"52047","312.24600","26.02064","0.01960"
"52104","312.58800","26.04917","0.02032"
"52161","312.93000","26.07763","0.02202"
"52218","313.27200","26.10614","0.02172"
"52275","313.61400","26.13472","0.02236"
"52332","313.95600","26.16306","0.02417"
"52389","314.29800","26.19170","0.02419"
"52446","314.64000","26.22022","0.02401"
"52503","314.98200","26.24862","0.02539"
"52560","315.32400","26.27720","0.02619"
"52617","315.66600","26.30566","0.02478"
"52674","316.00800","26.33412","0.02410"
"52731","316.35000","26.36270","0.02595"
"52788","316.69200","26.39110","0.02714"
"52845","317.03400","26.41968","0.02785"
"52902","317.37600","26.44814","0.02940"
"52959","317.71800","26.47654","0.03044"
"53016","318.06000","26.50524","0.03186"
"53073","318.40200","26.53364","0.03249"
"53130","318.74400","26.56216","0.02723"
"53187","319.08600","26.59068","0.02756"
"53244","319.42800","26.61920","0.03025"
"53301","319.77000","26.64766","0.03138"
"53358","320.11200","26.67618","0.03162"
"53415","320.45400","26.70464","0.03230"
"53472","320.79600","26.73322","0.03270"
"53529","321.13800","26.76174","0.03397"
"53586","321.48000","26.79014","0.03305"
"53643","321.82200","26.81865","0.03471"
"53700","322.16400","26.84718","0.03659"
"53757","322.50600","26.87563","0.03812"
"53814","322.84800","26.90421","0.03934"
"53871","323.19000","26.93268","0.04087"
"53928","323.53200","26.96119","0.04207"
"53985","323.87400","26.98965","0.04124"
"54042","324.21600","27.01817","0.04130"
"54099","324.55800","27.04669","0.04239"
"54156","324.90000","27.07521","0.04337"
"54213","325.24200","27.10367","0.04418"
"54270","325.58400","27.13219","0.04583"
"54327","325.92600","27.16065","0.04748"
"54384","326.26800","27.18911","0.04812"
"54441","326.61000","27.21769","0.04813"
"54498","326.95200","27.24615","0.04921"
"54555","327.29400","27.27467","0.05013"
"54612","327.63600","27.30319","0.05120"
"54669","327.97800","27.33165","0.05234"
"54726","328.32000","27.36011","0.05339"
"54783","328.66200","27.38869","0.05408"
"54840","329.00400","27.41715","0.05529"
"54897","329.34600","27.44567","0.05554"
"54954","329.68800","27.47425","0.05722"
"55011","330.03000","27.50265","0.05866"
"55068","330.37200","27.53117","0.05949"
"55125","330.71400","27.55969","0.06116"
"55182","331.05600","27.58815","0.06253"
"55239","331.39800","27.61667","0.06406"
"55296","331.74000","27.64513","0.06616"
"55353","332.08200","27.67365","0.06805"
"55410","332.42400","27.70216","0.06930"
"55467","332.76600","27.73062","0.07194"
"55524","333.10800","27.75920","0.07340"
"55581","333.45000","27.78766","0.07599"
"55638","333.79200","27.81612","0.07773"
"55695","334.13400","27.84476","0.08123"
"55752","334.47600","27.87316","0.07920"
"55809","334.81800","27.90168","0.06162"
"55866","335.16000","27.93020","0.06410"
"55923","335.50200","27.95860","0.06629"
"55980","335.84400","27.98718","0.06765"
"56037","336.18600","28.01570","0.07367"
"56094","336.52800","28.04410","0.07576"
"56151","336.87000","28.07268","0.07494"
"56208","337.21200","28.10114","0.07804"
"56265","337.55400","28.12966","0.08102"
"56322","337.89600","28.15818","0.08277"
"56379","338.23800","28.18664","0.08354"
"56436","338.58000","28.21522","0.08480"
"56493","338.92200","28.24368","0.08803"
"56550","339.26400","28.27208","0.08968"
"56607","339.60600","28.30072","0.08979"
"56664","339.94800","28.32924","0.09236"
"56721","340.29000","28.35764","0.09359"
"56778","340.63200","28.38622","0.09464"
"56835","340.97400","28.41462","0.09523"
"56892","341.31600","28.44320","0.09629"
"56949","341.65800","28.47166","0.09746"
"57006","342.00000","28.50018","0.09819"
"57063","342.34200","28.52869","0.09881"
"57120","342.68400","28.55722","0.09960"
"57177","343.02600","28.58568","0.10011"
"57234","343.36800","28.61419","0.10114"
"57291","343.71000","28.64271","0.10201"
"57348","344.05200","28.67112","0.03135"
"57405","344.39400","28.69969","0.00925"
"57462","344.73600","28.72821","0.03400"
"57519","345.07800","28.75667","0.01015"
"57576","345.42000","28.78513","0.01021"
"57633","345.76200","28.81365","0.00980"
"57690","346.10400","28.84211","0.00839"
"57747","346.44600","28.87075","0.00733"
"57804","346.78800","28.89915","0.00912"
"57861","347.13000","28.92767","0.01128"
"57918","347.47200","28.95625","0.01826"
"57975","347.81400","28.98465","0.01785"
"58032","348.15600","29.01323","0.01571"
"58089","348.49800","29.04169","0.01112"
"58146","348.84000","29.07015","0.01033"
"58203","349.18200","29.09873","0.01098"
"58260","349.52400","29.12713","0.01206"
"58317","349.86600","29.15565","0.01608"
"58374","350.20800","29.18423","0.01575"
"58431","350.55000","29.21257","0.01863"
"58488","350.89200","29.24121","0.01700"
"58545","351.23400","29.26973","0.01706"
"58602","351.57600","29.29813","0.01520"
"58659","351.91800","29.32671","0.01516"
"58716","352.26000","29.35517","0.01540"
"58773","352.60200","29.38369","0.01684"
"58830","352.94400","29.41221","0.01914"
"58887","353.28600","29.44067","0.01996"
"58944","353.62800","29.46919","0.02257"
"59001","353.97000","29.49771","0.02162"
"59058","354.31200","29.52610","0.02332"
"59115","354.65400","29.55468","0.02235"
"59172","354.99600","29.58315","0.02442"
"59229","355.33800","29.61166","0.02383"
"59286","355.68000","29.64018","0.02558"
"59343","356.02200","29.66870","0.02509"
"59400","356.36400","29.69716","0.02683"
"59457","356.70600","29.72568","0.02700"
"59514","357.04800","29.75414","0.02817"
"59571","357.39000","29.78266","0.02931"
"59628","357.73200","29.81118","0.03037"
"59685","358.07400","29.83964","0.03094"
"59742","358.41600","29.86822","0.03276"
"59799","358.75800","29.89662","0.03295"
"59856","359.10000","29.92514","0.03544"
"59913","359.44200","29.95372","0.03627"
"59970","359.78400","29.98218","0.03811"
"60027","360.12600","30.01070","0.03756"
"60084","360.46800","30.03916","0.04022"
"60141","360.81000","30.06762","0.04059"
"60198","361.15200","30.09620","0.04272"
"60255","361.49400","30.12466","0.04322"
"60312","361.83600","30.15312","0.04494"
"60369","362.17800","30.18170","0.04501"
"60426","362.52000","30.21022","0.04662"
"60483","362.86200","30.23868","0.04770"
"60540","363.20400","30.26720","0.04804"
"60597","363.54600","30.29565","0.04992"
"60654","363.88800","30.32418","0.05031"
"60711","364.23000","30.35264","0.05206"
"60768","364.57200","30.38116","0.05276"
"60825","364.91400","30.40961","0.05359"
"60882","365.25600","30.43819","0.05539"
"60939","365.59800","30.46665","0.05526"
"60996","365.94000","30.49517","0.05734"
"61053","366.28200","30.52369","0.05802"
"61110","366.62400","30.55215","0.05966"
"61167","366.96600","30.58073","0.06260"
"61224","367.30800","30.60913","0.06357"
"61281","367.65000","30.63765","0.00103"
"61338","367.99200","30.66623","0.00843"
"61395","368.33400","30.69463","0.01007"
"61452","368.67600","30.72315","0.00023"
"61509","369.01800","30.75161","0.00571"
"61566","369.36000","30.78007","0.00787"
"61623","369.70200","30.80871","0.00005"
"61680","370.04400","30.83723","0.00646"
"61737","370.38600","30.86569","0.00938"
"61794","370.72800","30.89427","0.00195"
"61851","371.07000","30.92261","0.00445"
"61908","371.41200","30.95113","0.01021"
"61965","371.75400","30.97971","0.00578"
"62022","372.09600","31.00811","0.00355"
"62079","372.43800","31.03669","0.00912"
"62136","372.78000","31.06521","0.00835"
"62193","373.12200","31.09367","0.00454"
"62250","373.46400","31.12225","0.00798"
"62307","373.80600","31.15065","0.01055"
"62364","374.14800","31.17917","0.00603"
"62421","374.49000","31.20769","0.00797"
"62478","374.83200","31.23615","0.01012"
"62535","375.17400","31.26472","0.00767"
"62592","375.51600","31.29318","0.00812"
"62649","375.85800","31.32158","0.00928"
"62706","376.20000","31.35022","0.01077"
"62763","376.54200","31.37874","0.00816"
"62820","376.88400","31.40714","0.00849"
"62877","377.22600","31.43572","0.01296"
"62934","377.56800","31.46418","0.00982"
"62991","377.91000","31.49264","0.00958"
"63048","378.25200","31.52116","0.01086"
"63105","378.59400","31.54962","0.01255"
"63162","378.93600","31.57814","0.01141"
"63219","379.27800","31.60666","0.01072"
"63276","379.62000","31.63518","0.01438"
"63333","379.96200","31.66370","0.01285"
"63390","380.30400","31.69216","0.01242"
"63447","380.64600","31.72068","0.01234"
"63504","380.98800","31.74920","0.01428"
"63561","381.33000","31.77772","0.01454"
"63618","381.67200","31.80612","0.01331"
"63675","382.01400","31.83470","0.01567"
"63732","382.35600","31.86322","0.01665"
"63789","382.69800","31.89168","0.01629"
"63846","383.04000","31.92019","0.01548"
"63903","383.38200","31.94860","0.01755"
"63960","383.72400","31.97718","0.01834"
"64017","384.06600","32.00570","0.01756"
"64074","384.40800","32.03416","0.00883"
"64131","384.75000","32.06268","0.01145"
"64188","385.09200","32.09119","0.01145"
"64245","385.43400","32.11966","0.01118"
"64302","385.77600","32.14824","0.01112"
"64359","386.11800","32.17663","0.01197"
"64416","386.46000","32.20515","0.01349"
"64473","386.80200","32.23373","0.01207"
"64530","387.14400","32.26207","0.01363"
"64587","387.48600","32.29071","0.01428"
"64644","387.82800","32.31917","0.01458"
"64701","388.17000","32.34769","0.01458"
"64758","388.51200","32.37621","0.01505"
"64815","388.85400","32.40461","0.01663"
"64872","389.19600","32.43313","0.01614"
"64929","389.53800","32.46171","0.01687"
"64986","389.88000","32.49017","0.01731"
"65043","390.22200","32.51869","0.01918"
"65100","390.56400","32.54721","0.01886"
"65157","390.90600","32.57561","0.01900"
"65214","391.24800","32.60425","0.01976"
"65271","391.59000","32.63271","0.02081"
"65328","391.93200","32.66111","0.02214"
"65385","392.27400","32.68969","0.02193"
"65442","392.61600","32.71815","0.02346"
"65499","392.95800","32.74667","0.02376"
"65556","393.30000","32.77518","0.02471"
"65613","393.64200","32.80365","0.02473"
"65670","393.98400","32.83223","0.02609"
"65727","394.32600","32.86068","0.02683"
"65784","394.66800","32.88914","0.02754"
"65841","395.01000","32.91772","0.02731"
"65898","395.35200","32.94613","0.02813"
"65955","395.69400","32.97464","0.02920"
"66012","396.03600","33.00316","0.02884"
"66069","396.37800","33.03162","0.02888"
"66126","396.72000","33.06015","0.03073"
"66183","397.06200","33.08866","0.03181"
"66240","397.40400","33.11712","0.03354"
"66297","397.74600","33.14565","0.03513"
"66354","398.08800","33.17416","0.03681"
"66411","398.43000","33.20268","0.03800"
"66468","398.77200","33.23120","0.04025"
"66525","399.11400","33.25972","0.04160"
"66582","399.45600","33.28812","0.04279"
"66639","399.79800","33.31670","0.04407"
"66696","400.14000","33.34522","0.04573"
"66753","400.48200","33.37362","0.04674"
"66810","400.82400","33.40220","0.04879"
"66867","401.16600","33.43066","0.04979"
"66924","401.50800","33.45918","0.05103"
"66981","401.85000","33.48776","0.05302"
"67038","402.19200","33.51610","0.05387"
"67095","402.53400","33.54468","0.05510"
"67152","402.87600","33.57320","0.05661"
"67209","403.21800","33.60160","0.05877"
"67266","403.56000","33.63018","0.06058"
"67323","403.90200","33.65870","0.06273"
"67380","404.24400","33.68716","0.06487"
"67437","404.58600","33.71568","0.06665"
"67494","404.92800","33.74413","0.06940"
"67551","405.27000","33.77266","0.07108"
"67608","405.61200","33.80124","0.07388"
"67665","405.95400","33.82957","0.07598"
"67722","406.29600","33.85822","0.07876"
"67779","406.63800","33.88667","0.08030"
"67836","406.98000","33.91513","0.08271"
"67893","407.32200","33.94365","0.08483"
"67950","407.66400","33.97218","0.08719"
"68007","408.00600","34.00063","0.08895"
"68064","408.34800","34.02921","0.09013"
"68121","408.69000","34.05761","0.09180"
"68178","409.03200","34.08619","0.09325"
"68235","409.37400","34.11477","0.09452"
"68292","409.71600","34.14311","0.09543"
"68349","410.05800","34.17169","0.09615"
"68406","410.40000","34.20015","0.09711"
"68463","410.74200","34.22867","0.09805"
"68520","411.08400","34.25719","0.09856"
"68577","411.42600","34.28565","0.09975"
"68634","411.76800","34.31417","0.09972"
"68691","412.11000","34.34269","0.01140"
"68748","412.45200","34.37109","0.01497"
"68805","412.79400","34.39967","0.01193"
"68862","413.13600","34.42819","0.01628"
"68919","413.47800","34.45671","0.02212"
"68976","413.82000","34.48523","0.01843"
"69033","414.16200","34.51369","0.01454"
"69090","414.50400","34.54215","0.01247"
"69147","414.84600","34.57067","0.01424"
"69204","415.18800","34.59919","0.01640"
"69261","415.53000","34.62770","0.01540"
"69318","415.87200","34.65617","0.01829"
"69375","416.21400","34.68462","0.01788"
"69432","416.55600","34.71320","0.01653"
"69489","416.89800","34.74166","0.01771"
"69546","417.24000","34.77012","0.01683"
"69591","417.50600","34.79237","0.01982"