File: Trajectories_together/161221_1Specimen_RawData_6.csv
"","V1","V2","V3"
"1","End date","12/21/2016",""
"2","Specimen label","24BG_94",""
"3","Maximum Load","0.28789","N"
"4","Time","Extension","Load"
"5","(s)","(mm)","(N)"
"6","0.00000","-0.00006","-0.00020"
"79","0.43800","0.03677","0.00189"
"152","0.87600","0.07324","0.00219"
"225","1.31400","0.10971","0.00280"
"298","1.75200","0.14619","0.00323"
"371","2.19000","0.18272","0.00354"
"444","2.62800","0.21919","0.00415"
"517","3.06600","0.25566","0.00453"
"590","3.50400","0.29219","0.00415"
"663","3.94200","0.32866","0.00445"
"736","4.38000","0.36507","0.00441"
"809","4.81800","0.40167","0.00446"
"882","5.25600","0.43814","0.00504"
"955","5.69400","0.47473","0.00508"
"1028","6.13200","0.51108","0.00489"
"1101","6.57000","0.54761","0.00543"
"1174","7.00800","0.58420","0.00502"
"1247","7.44600","0.62068","0.00517"
"1320","7.88400","0.65715","0.00541"
"1393","8.32200","0.69362","0.00521"
"1466","8.76000","0.73009","0.00552"
"1539","9.19800","0.76668","0.00554"
"1612","9.63600","0.80315","0.00540"
"1685","10.07400","0.83968","0.00560"
"1758","10.51200","0.87616","0.00557"
"1831","10.95000","0.91263","0.00529"
"1904","11.38800","0.94916","0.00538"
"1977","11.82600","0.98569","0.00541"
"2050","12.26400","1.02222","0.00545"
"2123","12.70200","1.05869","0.00600"
"2196","13.14000","1.09516","0.00603"
"2269","13.57800","1.13164","0.00556"
"2342","14.01600","1.16817","0.00601"
"2415","14.45400","1.20470","0.00590"
"2488","14.89200","1.24117","0.00568"
"2561","15.33000","1.27764","0.00527"
"2634","15.76800","1.31405","0.00589"
"2707","16.20600","1.35065","0.00608"
"2780","16.64400","1.38718","0.00549"
"2853","17.08200","1.42365","0.00610"
"2926","17.52000","1.46018","0.00565"
"2999","17.95800","1.49659","0.00566"
"3072","18.39600","1.53312","0.00576"
"3145","18.83400","1.56965","0.00595"
"3218","19.27200","1.60619","0.00591"
"3291","19.71000","1.64272","0.00551"
"3364","20.14800","1.67919","0.00579"
"3437","20.58600","1.71566","0.00581"
"3510","21.02400","1.75219","0.00597"
"3583","21.46200","1.78866","0.00575"
"3656","21.90000","1.82520","0.00594"
"3729","22.33800","1.86167","0.00589"
"3802","22.77600","1.89808","0.00600"
"3875","23.21400","1.93461","0.00578"
"3948","23.65200","1.97114","0.00598"
"4021","24.09000","2.00767","0.00574"
"4094","24.52800","2.04414","0.00601"
"4167","24.96600","2.08062","0.00607"
"4240","25.40400","2.11709","0.00613"
"4313","25.84200","2.15362","0.00583"
"4386","26.28000","2.19015","0.00576"
"4459","26.71800","2.22668","0.00629"
"4532","27.15600","2.26315","0.00570"
"4605","27.59400","2.29962","0.00572"
"4678","28.03200","2.33616","0.00581"
"4751","28.47000","2.37269","0.00628"
"4824","28.90800","2.40916","0.00594"
"4897","29.34600","2.44569","0.00594"
"4970","29.78400","2.48216","0.00574"
"5043","30.22200","2.51863","0.00586"
"5116","30.66000","2.55517","0.00586"
"5189","31.09800","2.59170","0.00591"
"5262","31.53600","2.62823","0.00583"
"5335","31.97400","2.66464","0.00559"
"5408","32.41200","2.70111","0.00581"
"5481","32.85000","2.73758","0.00569"
"5554","33.28800","2.77417","0.00568"
"5627","33.72600","2.81065","0.00549"
"5700","34.16400","2.84718","0.00523"
"5773","34.60200","2.88359","0.00519"
"5846","35.04000","2.92012","0.00554"
"5919","35.47800","2.95665","0.00549"
"5992","35.91600","2.99318","0.00536"
"6065","36.35400","3.02971","0.00527"
"6138","36.79200","3.06619","0.00579"
"6211","37.23000","3.10266","0.00556"
"6284","37.66800","3.13925","0.00519"
"6357","38.10600","3.17572","0.00546"
"6430","38.54400","3.21219","0.00539"
"6503","38.98200","3.24866","0.00516"
"6576","39.42000","3.28514","0.00592"
"6649","39.85800","3.32167","0.00488"
"6722","40.29600","3.35814","0.00537"
"6795","40.73400","3.39467","0.00509"
"6868","41.17200","3.43114","0.00500"
"6941","41.61000","3.46761","0.00496"
"7014","42.04800","3.50415","0.00504"
"7087","42.48600","3.54062","0.00503"
"7160","42.92400","3.57715","0.00539"
"7233","43.36200","3.61368","0.00550"
"7306","43.80000","3.65015","0.00510"
"7379","44.23800","3.68668","0.00523"
"7452","44.67600","3.72321","0.00489"
"7525","45.11400","3.75969","0.00495"
"7598","45.55200","3.79622","0.00482"
"7671","45.99000","3.83269","0.00547"
"7744","46.42800","3.86910","0.00521"
"7817","46.86600","3.90563","0.00494"
"7890","47.30400","3.94216","0.00532"
"7963","47.74200","3.97863","0.00533"
"8036","48.18000","4.01517","0.00515"
"8109","48.61800","4.05158","0.00510"
"8182","49.05600","4.08811","0.00498"
"8255","49.49400","4.12464","0.00461"
"8328","49.93200","4.16117","0.00461"
"8401","50.37000","4.19770","0.00521"
"8474","50.80800","4.23418","0.00499"
"8547","51.24600","4.27065","0.00467"
"8620","51.68400","4.30718","0.00489"
"8693","52.12200","4.34371","0.00487"
"8766","52.56000","4.38018","0.00507"
"8839","52.99800","4.41665","0.00503"
"8912","53.43600","4.45312","0.00499"
"8985","53.87400","4.48966","0.00512"
"9058","54.31200","4.52607","0.00504"
"9131","54.75000","4.56266","0.00493"
"9204","55.18800","4.59919","0.00495"
"9277","55.62600","4.63566","0.00481"
"9350","56.06400","4.67213","0.00496"
"9423","56.50200","4.70866","0.00527"
"9496","56.94000","4.74520","0.00482"
"9569","57.37800","4.78167","0.00475"
"9642","57.81600","4.81814","0.00504"
"9715","58.25400","4.85461","0.00521"
"9788","58.69200","4.89114","0.00521"
"9861","59.13000","4.92767","0.00534"
"9934","59.56800","4.96415","0.00544"
"10007","60.00600","5.00068","0.00494"
"10080","60.44400","5.03709","0.00507"
"10153","60.88200","5.07362","0.00489"
"10226","61.32000","5.11021","0.00514"
"10299","61.75800","5.14662","0.00493"
"10372","62.19600","5.18315","0.00490"
"10445","62.63400","5.21963","0.00501"
"10518","63.07200","5.25616","0.00565"
"10591","63.51000","5.29269","0.00546"
"10664","63.94800","5.32916","0.00564"
"10737","64.38600","5.36569","0.00525"
"10810","64.82400","5.40216","0.00541"
"10883","65.26200","5.43864","0.00505"
"10956","65.70000","5.47511","0.00526"
"11029","66.13800","5.51164","0.00542"
"11102","66.57600","5.54817","0.00515"
"11175","67.01400","5.58464","0.00533"
"11248","67.45200","5.62111","0.00539"
"11321","67.89000","5.65764","0.00527"
"11394","68.32800","5.69418","0.00513"
"11467","68.76600","5.73065","0.00516"
"11540","69.20400","5.76718","0.00525"
"11613","69.64200","5.80365","0.00550"
"11686","70.08000","5.84012","0.00518"
"11759","70.51800","5.87671","0.00487"
"11832","70.95600","5.91319","0.00539"
"11905","71.39400","5.94966","0.00541"
"11978","71.83200","5.98619","0.00539"
"12051","72.27000","6.02260","0.00536"
"12124","72.70800","6.05913","0.00554"
"12197","73.14600","6.09566","0.00531"
"12270","73.58400","6.13213","0.00546"
"12343","74.02200","6.16867","0.00529"
"12416","74.46000","6.20508","0.00514"
"12489","74.89800","6.24167","0.00548"
"12562","75.33600","6.27814","0.00572"
"12635","75.77400","6.31467","0.00550"
"12708","76.21200","6.35120","0.00538"
"12781","76.65000","6.38762","0.00543"
"12854","77.08800","6.42415","0.00530"
"12927","77.52600","6.46068","0.00543"
"13000","77.96400","6.49721","0.00540"
"13073","78.40200","6.53368","0.00538"
"13146","78.84000","6.57015","0.00561"
"13219","79.27800","6.60662","0.00530"
"13292","79.71600","6.64316","0.00546"
"13365","80.15400","6.67963","0.00567"
"13438","80.59200","6.71616","0.00570"
"13511","81.03000","6.75269","0.00553"
"13584","81.46800","6.78916","0.00498"
"13657","81.90600","6.82563","0.00533"
"13730","82.34400","6.86216","0.00492"
"13803","82.78200","6.89870","0.00506"
"13876","83.22000","6.93523","0.00537"
"13949","83.65800","6.97164","0.00513"
"14022","84.09600","7.00811","0.00515"
"14095","84.53400","7.04464","0.00548"
"14168","84.97200","7.08117","0.00529"
"14241","85.41000","7.11770","0.00544"
"14314","85.84800","7.15418","0.00541"
"14387","86.28600","7.19065","0.00528"
"14460","86.72400","7.22712","0.00525"
"14533","87.16200","7.26365","0.00530"
"14606","87.60000","7.30018","0.00554"
"14679","88.03800","7.33671","0.00560"
"14752","88.47600","7.37313","0.00550"
"14825","88.91400","7.40966","0.00556"
"14898","89.35200","7.44613","0.00548"
"14971","89.79000","7.48266","0.00566"
"15044","90.22800","7.51919","0.00545"
"15117","90.66600","7.55572","0.00558"
"15190","91.10400","7.59208","0.00559"
"15263","91.54200","7.62861","0.00547"
"15336","91.98000","7.66514","0.00559"
"15409","92.41800","7.70167","0.00561"
"15482","92.85600","7.73814","0.00545"
"15555","93.29400","7.77461","0.00539"
"15628","93.73200","7.81120","0.00552"
"15701","94.17000","7.84768","0.00576"
"15774","94.60800","7.88421","0.00551"
"15847","95.04600","7.92074","0.00571"
"15920","95.48400","7.95721","0.00562"
"15993","95.92200","7.99362","0.00533"
"16066","96.36000","8.03015","0.00563"
"16139","96.79800","8.06662","0.00571"
"16212","97.23600","8.10316","0.00547"
"16285","97.67400","8.13963","0.00568"
"16358","98.11200","8.17616","0.00586"
"16431","98.55000","8.21263","0.00548"
"16504","98.98800","8.24916","0.00568"
"16577","99.42600","8.28563","0.00533"
"16650","99.86400","8.32216","0.00538"
"16723","100.30200","8.35858","0.00526"
"16796","100.74000","8.39511","0.00568"
"16869","101.17800","8.43164","0.00561"
"16942","101.61600","8.46817","0.00568"
"17015","102.05400","8.50470","0.00570"
"17088","102.49200","8.54111","0.00549"
"17161","102.93000","8.57765","0.00559"
"17234","103.36800","8.61418","0.00556"
"17307","103.80600","8.65065","0.00577"
"17380","104.24400","8.68718","0.00532"
"17453","104.68200","8.72371","0.00532"
"17526","105.12000","8.76018","0.00536"
"17599","105.55800","8.79659","0.00564"
"17672","105.99600","8.83313","0.00555"
"17745","106.43400","8.86972","0.00578"
"17818","106.87200","8.90619","0.00542"
"17891","107.31000","8.94266","0.00548"
"17964","107.74800","8.97913","0.00553"
"18037","108.18600","9.01560","0.00525"
"18110","108.62400","9.05219","0.00548"
"18183","109.06200","9.08867","0.00530"
"18256","109.50000","9.12514","0.00568"
"18329","109.93800","9.16161","0.00571"
"18402","110.37600","9.19814","0.00565"
"18475","110.81400","9.23467","0.00553"
"18548","111.25200","9.27120","0.00575"
"18621","111.69000","9.30762","0.00541"
"18694","112.12800","9.34415","0.00591"
"18767","112.56600","9.38068","0.00570"
"18840","113.00400","9.41715","0.00557"
"18913","113.44200","9.45368","0.00565"
"18986","113.88000","9.49021","0.00581"
"19059","114.31800","9.52668","0.00595"
"19132","114.75600","9.56316","0.00593"
"19205","115.19400","9.59963","0.00616"
"19278","115.63200","9.63622","0.00557"
"19351","116.07000","9.67263","0.00585"
"19424","116.50800","9.70916","0.00622"
"19497","116.94600","9.74557","0.00585"
"19570","117.38400","9.78217","0.00570"
"19643","117.82200","9.81864","0.00584"
"19716","118.26000","9.85517","0.00640"
"19789","118.69800","9.89164","0.00625"
"19862","119.13600","9.92811","0.00599"
"19935","119.57400","9.96458","0.00620"
"20008","120.01200","10.00117","0.00591"
"20081","120.45000","10.03771","0.00588"
"20154","120.88800","10.07418","0.00627"
"20227","121.32600","10.11065","0.00649"
"20300","121.76400","10.14712","0.00590"
"20373","122.20200","10.18365","0.00613"
"20446","122.64000","10.22018","0.00598"
"20519","123.07800","10.25666","0.00588"
"20592","123.51600","10.29313","0.00627"
"20665","123.95400","10.32960","0.00621"
"20738","124.39200","10.36613","0.00613"
"20811","124.83000","10.40266","0.00585"
"20884","125.26800","10.43919","0.00614"
"20957","125.70600","10.47566","0.00620"
"21030","126.14400","10.51214","0.00632"
"21103","126.58200","10.54861","0.00608"
"21176","127.02000","10.58514","0.00619"
"21249","127.45800","10.62167","0.00596"
"21322","127.89600","10.65820","0.00654"
"21395","128.33400","10.69467","0.00642"
"21468","128.77200","10.73114","0.00624"
"21541","129.21000","10.76762","0.00629"
"21614","129.64800","10.80415","0.00646"
"21687","130.08600","10.84068","0.00671"
"21760","130.52400","10.87721","0.00638"
"21833","130.96200","10.91368","0.00639"
"21906","131.40000","10.95015","0.00649"
"21979","131.83800","10.98663","0.00600"
"22052","132.27600","11.02322","0.00629"
"22125","132.71400","11.05969","0.00630"
"22198","133.15200","11.09616","0.00593"
"22271","133.59000","11.13257","0.00614"
"22344","134.02800","11.16910","0.00630"
"22417","134.46600","11.20569","0.00631"
"22490","134.90400","11.24217","0.00636"
"22563","135.34200","11.27870","0.00650"
"22636","135.78000","11.31511","0.00619"
"22709","136.21800","11.35164","0.00644"
"22782","136.65600","11.38823","0.00643"
"22855","137.09400","11.42470","0.00672"
"22928","137.53200","11.46118","0.00655"
"23001","137.97000","11.49765","0.00650"
"23074","138.40800","11.53412","0.00655"
"23147","138.84600","11.57065","0.00702"
"23220","139.28400","11.60718","0.00676"
"23293","139.72200","11.64371","0.00688"
"23366","140.16000","11.68018","0.00653"
"23439","140.59800","11.71660","0.00699"
"23512","141.03600","11.75313","0.00661"
"23585","141.47400","11.78966","0.00665"
"23658","141.91200","11.82619","0.00662"
"23731","142.35000","11.86266","0.00706"
"23804","142.78800","11.89913","0.00692"
"23877","143.22600","11.93561","0.00682"
"23950","143.66400","11.97214","0.00654"
"24023","144.10200","12.00873","0.00714"
"24096","144.54000","12.04520","0.00681"
"24169","144.97800","12.08167","0.00681"
"24242","145.41600","12.11814","0.00668"
"24315","145.85400","12.15467","0.00713"
"24388","146.29200","12.19121","0.00726"
"24461","146.73000","12.22768","0.00697"
"24534","147.16800","12.26415","0.00667"
"24607","147.60600","12.30062","0.00723"
"24680","148.04400","12.33715","0.00715"
"24753","148.48200","12.37362","0.00689"
"24826","148.92000","12.41015","0.00727"
"24899","149.35800","12.44669","0.00713"
"24972","149.79600","12.48316","0.00734"
"25045","150.23400","12.51963","0.00709"
"25118","150.67200","12.55610","0.00711"
"25191","151.11000","12.59269","0.00719"
"25264","151.54800","12.62916","0.00704"
"25337","151.98600","12.66569","0.00717"
"25410","152.42400","12.70211","0.00692"
"25483","152.86200","12.73870","0.00704"
"25556","153.30000","12.77523","0.00734"
"25629","153.73800","12.81170","0.00758"
"25702","154.17600","12.84817","0.00788"
"25775","154.61400","12.88464","0.00741"
"25848","155.05200","12.92111","0.00767"
"25921","155.49000","12.95765","0.00780"
"25994","155.92800","12.99418","0.00744"
"26067","156.36600","13.03065","0.00773"
"26140","156.80400","13.06712","0.00779"
"26213","157.24200","13.10359","0.00760"
"26286","157.68000","13.14012","0.00755"
"26359","158.11800","13.17666","0.00725"
"26432","158.55600","13.21319","0.00761"
"26505","158.99400","13.24972","0.00734"
"26578","159.43200","13.28607","0.00774"
"26651","159.87000","13.32266","0.00804"
"26724","160.30800","13.35919","0.00772"
"26797","160.74600","13.39567","0.00768"
"26870","161.18400","13.43220","0.00786"
"26943","161.62200","13.46867","0.00837"
"27016","162.06000","13.50520","0.00797"
"27089","162.49800","13.54167","0.00795"
"27162","162.93600","13.57820","0.00781"
"27235","163.37400","13.61467","0.00814"
"27308","163.81200","13.65115","0.00795"
"27381","164.25000","13.68762","0.00764"
"27454","164.68800","13.72415","0.00776"
"27527","165.12600","13.76068","0.00729"
"27600","165.56400","13.79715","0.00787"
"27673","166.00200","13.83362","0.00776"
"27746","166.44000","13.87010","0.00767"
"27819","166.87800","13.90663","0.00784"
"27892","167.31600","13.94316","0.00816"
"27965","167.75400","13.97963","0.00808"
"28038","168.19200","14.01616","0.00815"
"28111","168.63000","14.05263","0.00790"
"28184","169.06800","14.08916","0.00789"
"28257","169.50600","14.12570","0.00813"
"28330","169.94400","14.16223","0.00797"
"28403","170.38200","14.19864","0.00800"
"28476","170.82000","14.23511","0.00813"
"28549","171.25800","14.27164","0.00812"
"28622","171.69600","14.30817","0.00823"
"28695","172.13400","14.34471","0.00845"
"28768","172.57200","14.38118","0.00828"
"28841","173.01000","14.41765","0.00805"
"28914","173.44800","14.45412","0.00839"
"28987","173.88600","14.49065","0.00796"
"29060","174.32400","14.52712","0.00831"
"29133","174.76200","14.56365","0.00852"
"29206","175.20000","14.60019","0.00883"
"29279","175.63800","14.63666","0.00836"
"29352","176.07600","14.67313","0.00880"
"29425","176.51400","14.70966","0.00863"
"29498","176.95200","14.74619","0.00849"
"29571","177.39000","14.78272","0.00884"
"29644","177.82800","14.81920","0.00863"
"29717","178.26600","14.85567","0.00860"
"29790","178.70400","14.89214","0.00914"
"29863","179.14200","14.92867","0.00893"
"29936","179.58000","14.96520","0.00898"
"30009","180.01800","15.00167","0.00874"
"30082","180.45600","15.03815","0.00940"
"30155","180.89400","15.07462","0.00926"
"30228","181.33200","15.11115","0.00926"
"30301","181.77000","15.14768","0.00930"
"30374","182.20800","15.18415","0.00886"
"30447","182.64600","15.22062","0.00903"
"30520","183.08400","15.25709","0.00976"
"30593","183.52200","15.29368","0.00935"
"30666","183.96000","15.33022","0.00973"
"30739","184.39800","15.36663","0.00976"
"30812","184.83600","15.40316","0.00977"
"30885","185.27400","15.43957","0.00928"
"30958","185.71200","15.47616","0.00949"
"31031","186.15000","15.51269","0.01003"
"31104","186.58800","15.54923","0.01030"
"31177","187.02600","15.58570","0.01019"
"31250","187.46400","15.62217","0.00985"
"31323","187.90200","15.65870","0.00991"
"31396","188.34000","15.69517","0.01033"
"31469","188.77800","15.73170","0.01001"
"31542","189.21600","15.76817","0.01040"
"31615","189.65400","15.80464","0.01007"
"31688","190.09200","15.84112","0.01026"
"31761","190.53000","15.87759","0.01068"
"31834","190.96800","15.91418","0.01047"
"31907","191.40600","15.95071","0.01062"
"31980","191.84400","15.98712","0.01138"
"32053","192.28200","16.02360","0.01125"
"32126","192.72000","16.06013","0.01144"
"32199","193.15800","16.09666","0.01109"
"32272","193.59600","16.13313","0.01135"
"32345","194.03400","16.16966","0.01163"
"32418","194.47200","16.20619","0.01140"
"32491","194.91000","16.24260","0.01151"
"32564","195.34800","16.27919","0.01185"
"32637","195.78600","16.31573","0.01261"
"32710","196.22400","16.35220","0.01256"
"32783","196.66200","16.38861","0.01255"
"32856","197.10000","16.42514","0.01269"
"32929","197.53800","16.46161","0.01290"
"33002","197.97600","16.49814","0.01257"
"33075","198.41400","16.53461","0.01313"
"33148","198.85200","16.57121","0.01316"
"33221","199.29000","16.60762","0.01299"
"33294","199.72800","16.64415","0.01377"
"33367","200.16600","16.68062","0.01300"
"33440","200.60400","16.71715","0.01335"
"33513","201.04200","16.75368","0.01387"
"33586","201.48000","16.79016","0.01413"
"33659","201.91800","16.82663","0.01455"
"33732","202.35600","16.86310","0.01445"
"33805","202.79400","16.89969","0.01465"
"33878","203.23200","16.93622","0.01540"
"33951","203.67000","16.97269","0.01512"
"34024","204.10800","17.00911","0.01534"
"34097","204.54600","17.04558","0.01522"
"34170","204.98400","17.08217","0.01523"
"34243","205.42200","17.11870","0.01498"
"34316","205.86000","17.15517","0.01549"
"34389","206.29800","17.19164","0.01565"
"34462","206.73600","17.22812","0.01613"
"34535","207.17400","17.26471","0.01615"
"34608","207.61200","17.30118","0.01698"
"34681","208.05000","17.33765","0.01715"
"34754","208.48800","17.37412","0.01731"
"34827","208.92600","17.41053","0.01769"
"34900","209.36400","17.44712","0.01774"
"34973","209.80200","17.48366","0.01730"
"35046","210.24000","17.52019","0.01756"
"35119","210.67800","17.55672","0.01767"
"35192","211.11600","17.59313","0.01761"
"35265","211.55400","17.62966","0.01808"
"35338","211.99200","17.66619","0.01871"
"35411","212.43000","17.70266","0.01877"
"35484","212.86800","17.73919","0.01939"
"35557","213.30600","17.77567","0.01932"
"35630","213.74400","17.81208","0.01984"
"35703","214.18200","17.84861","0.02073"
"35776","214.62000","17.88520","0.02079"
"35849","215.05800","17.92161","0.02126"
"35922","215.49600","17.95815","0.02162"
"35995","215.93400","17.99462","0.02228"
"36068","216.37200","18.03115","0.02305"
"36141","216.81000","18.06768","0.02382"
"36214","217.24800","18.10415","0.02392"
"36287","217.68600","18.14062","0.02476"
"36360","218.12400","18.17715","0.02489"
"36433","218.56200","18.21363","0.02448"
"36506","219.00000","18.25016","0.02553"
"36579","219.43800","18.28663","0.02492"
"36652","219.87600","18.32316","0.02538"
"36725","220.31400","18.35969","0.02631"
"36798","220.75200","18.39616","0.02751"
"36871","221.19000","18.43270","0.02778"
"36944","221.62800","18.46917","0.02814"
"37017","222.06600","18.50564","0.02934"
"37090","222.50400","18.54217","0.02945"
"37163","222.94200","18.57864","0.03049"
"37236","223.38000","18.61517","0.03026"
"37309","223.81800","18.65170","0.03123"
"37382","224.25600","18.68818","0.03248"
"37455","224.69400","18.72471","0.03304"
"37528","225.13200","18.76112","0.03392"
"37601","225.57000","18.79765","0.03443"
"37674","226.00800","18.83412","0.03506"
"37747","226.44600","18.87065","0.03638"
"37820","226.88400","18.90718","0.03726"
"37893","227.32200","18.94366","0.03813"
"37966","227.76000","18.98013","0.03841"
"38039","228.19800","19.01666","0.03949"
"38112","228.63600","19.05319","0.04089"
"38185","229.07400","19.08972","0.04191"
"38258","229.51200","19.12619","0.04370"
"38331","229.95000","19.16266","0.04397"
"38404","230.38800","19.19914","0.04511"
"38477","230.82600","19.23567","0.04578"
"38550","231.26400","19.27220","0.04672"
"38623","231.70200","19.30867","0.04748"
"38696","232.14000","19.34514","0.04776"
"38769","232.57800","19.38161","0.04870"
"38842","233.01600","19.41821","0.04958"
"38915","233.45400","19.45468","0.04980"
"38988","233.89200","19.49115","0.05061"
"39061","234.33000","19.52762","0.05071"
"39134","234.76800","19.56409","0.05089"
"39207","235.20600","19.60062","0.05097"
"39280","235.64400","19.63721","0.05162"
"39353","236.08200","19.67369","0.05170"
"39426","236.52000","19.71016","0.05231"
"39499","236.95800","19.74663","0.05245"
"39572","237.39600","19.78316","0.05265"
"39645","237.83400","19.81969","0.05288"
"39718","238.27200","19.85616","0.05306"
"39791","238.71000","19.89270","0.05140"
"39864","239.14800","19.92911","0.03906"
"39937","239.58600","19.96558","0.04032"
"40010","240.02400","20.00217","0.04051"
"40083","240.46200","20.03870","0.04118"
"40156","240.90000","20.07517","0.04267"
"40229","241.33800","20.11164","0.04310"
"40302","241.77600","20.14812","0.04302"
"40375","242.21400","20.18465","0.04162"
"40448","242.65200","20.22112","0.04070"
"40521","243.09000","20.25765","0.04178"
"40594","243.52800","20.29418","0.04243"
"40667","243.96600","20.33065","0.04139"
"40740","244.40400","20.36712","0.04011"
"40813","244.84200","20.40366","0.04007"
"40886","245.28000","20.44019","0.03956"
"40959","245.71800","20.47672","0.04026"
"41032","246.15600","20.51319","0.04106"
"41105","246.59400","20.54960","0.04194"
"41178","247.03200","20.58619","0.04288"
"41251","247.47000","20.62267","0.04350"
"41324","247.90800","20.65914","0.04433"
"41397","248.34600","20.69567","0.04525"
"41470","248.78400","20.73214","0.04643"
"41543","249.22200","20.76861","0.04642"
"41616","249.66000","20.80514","0.04728"
"41689","250.09800","20.84161","0.04852"
"41762","250.53600","20.87815","0.04804"
"41835","250.97400","20.91462","0.04586"
"41908","251.41200","20.95109","0.04628"
"41981","251.85000","20.98768","0.04547"
"42054","252.28800","21.02415","0.04528"
"42127","252.72600","21.06068","0.04279"
"42200","253.16400","21.09715","0.04341"
"42273","253.60200","21.13363","0.04430"
"42346","254.04000","21.17016","0.04548"
"42419","254.47800","21.20669","0.04645"
"42492","254.91600","21.24316","0.04719"
"42565","255.35400","21.27969","0.04730"
"42638","255.79200","21.31610","0.04786"
"42711","256.23000","21.35264","0.04792"
"42784","256.66800","21.38917","0.04874"
"42857","257.10600","21.42570","0.04902"
"42930","257.54400","21.46217","0.04838"
"43003","257.98200","21.49864","0.04908"
"43076","258.42000","21.53511","0.04868"
"43149","258.85800","21.57165","0.04878"
"43222","259.29600","21.60818","0.04911"
"43295","259.73400","21.64471","0.04981"
"43368","260.17200","21.68118","0.05148"
"43441","260.61000","21.71759","0.05260"
"43514","261.04800","21.75412","0.05252"
"43587","261.48600","21.79066","0.05286"
"43660","261.92400","21.82718","0.05362"
"43733","262.36200","21.86372","0.05433"
"43806","262.80000","21.90019","0.05553"
"43879","263.23800","21.93660","0.05568"
"43952","263.67600","21.97313","0.05664"
"44025","264.11400","22.00966","0.05716"
"44098","264.55200","22.04620","0.05552"
"44171","264.99000","22.08261","0.05608"
"44244","265.42800","22.11908","0.05514"
"44317","265.86600","22.15567","0.05634"
"44390","266.30400","22.19214","0.05738"
"44463","266.74200","22.22861","0.05779"
"44536","267.18000","22.26514","0.05888"
"44609","267.61800","22.30162","0.06011"
"44682","268.05600","22.33815","0.06158"
"44755","268.49400","22.37468","0.06258"
"44828","268.93200","22.41121","0.06431"
"44901","269.37000","22.44768","0.06339"
"44974","269.80800","22.48415","0.06348"
"45047","270.24600","22.52063","0.06177"
"45120","270.68400","22.55721","0.06447"
"45193","271.12200","22.59369","0.06706"
"45266","271.56000","22.63016","0.06495"
"45339","271.99800","22.66669","0.06139"
"45412","272.43600","22.70310","0.06391"
"45485","272.87400","22.73963","0.06561"
"45558","273.31200","22.77617","0.06582"
"45631","273.75000","22.81264","0.06634"
"45704","274.18800","22.84917","0.06837"
"45777","274.62600","22.88564","0.07111"
"45850","275.06400","22.92211","0.07401"
"45923","275.50200","22.95864","0.07579"
"45996","275.94000","22.99517","0.06106"
"46069","276.37800","23.03170","0.05913"
"46142","276.81600","23.06812","0.05931"
"46215","277.25400","23.10465","0.06001"
"46288","277.69200","23.14112","0.06231"
"46361","278.13000","23.17771","0.06409"
"46434","278.56800","23.21418","0.06242"
"46507","279.00600","23.25071","0.06660"
"46580","279.44400","23.28713","0.07002"
"46653","279.88200","23.32366","0.07183"
"46726","280.32000","23.36019","0.07452"
"46799","280.75800","23.39672","0.07712"
"46872","281.19600","23.43319","0.07859"
"46945","281.63400","23.46966","0.08079"
"47018","282.07200","23.50613","0.08181"
"47091","282.51000","23.54267","0.08344"
"47164","282.94800","23.57920","0.08498"
"47237","283.38600","23.61561","0.08710"
"47310","283.82400","23.65214","0.08852"
"47383","284.26200","23.68861","0.08951"
"47456","284.70000","23.72520","0.09113"
"47529","285.13800","23.76167","0.09385"
"47602","285.57600","23.79815","0.09655"
"47675","286.01400","23.83468","0.09867"
"47748","286.45200","23.87115","0.09887"
"47821","286.89000","23.90762","0.10104"
"47894","287.32800","23.94421","0.10235"
"47967","287.76600","23.98068","0.10411"
"48040","288.20400","24.01722","0.10520"
"48113","288.64200","24.05363","0.10703"
"48186","289.08000","24.09010","0.10930"
"48259","289.51800","24.12669","0.11221"
"48332","289.95600","24.16316","0.11579"
"48405","290.39400","24.19969","0.11983"
"48478","290.83200","24.23616","0.12426"
"48551","291.27000","24.27264","0.12740"
"48624","291.70800","24.30917","0.13004"
"48697","292.14600","24.34570","0.13270"
"48770","292.58400","24.38211","0.13549"
"48843","293.02200","24.41864","0.13768"
"48916","293.46000","24.45511","0.13812"
"48989","293.89800","24.49159","0.14031"
"49062","294.33600","24.52818","0.14316"
"49135","294.77400","24.56465","0.14610"
"49208","295.21200","24.60124","0.14917"
"49281","295.65000","24.63765","0.15188"
"49354","296.08800","24.67413","0.15337"
"49427","296.52600","24.71066","0.15449"
"49500","296.96400","24.74713","0.15599"
"49573","297.40200","24.78366","0.15812"
"49646","297.84000","24.82019","0.16115"
"49719","298.27800","24.85660","0.16507"
"49792","298.71600","24.89314","0.17016"
"49865","299.15400","24.92966","0.17357"
"49938","299.59200","24.96620","0.17943"
"50011","300.03000","25.00267","0.18344"
"50084","300.46800","25.03914","0.18727"
"50157","300.90600","25.07561","0.18962"
"50230","301.34400","25.11214","0.19327"
"50303","301.78200","25.14867","0.19517"
"50376","302.22000","25.18514","0.19759"
"50449","302.65800","25.22168","0.19877"
"50522","303.09600","25.25815","0.20168"
"50595","303.53400","25.29462","0.20538"
"50668","303.97200","25.33115","0.20809"
"50741","304.41000","25.36774","0.21104"
"50814","304.84800","25.40415","0.21418"
"50887","305.28600","25.44063","0.21666"
"50960","305.72400","25.47710","0.21900"
"51033","306.16200","25.51369","0.22312"
"51106","306.60000","25.55016","0.22621"
"51179","307.03800","25.58669","0.22899"
"51252","307.47600","25.62316","0.23093"
"51325","307.91400","25.65963","0.23391"
"51398","308.35200","25.69611","0.23576"
"51471","308.79000","25.73264","0.23850"
"51544","309.22800","25.76917","0.24149"
"51617","309.66600","25.80558","0.24579"
"51690","310.10400","25.84211","0.24951"
"51763","310.54200","25.87864","0.25378"
"51836","310.98000","25.91518","0.25668"
"51909","311.41800","25.95165","0.26170"
"51982","311.85600","25.98818","0.26479"
"52055","312.29400","26.02465","0.27042"
"52128","312.73200","26.06106","0.27668"
"52201","313.17000","26.09765","0.28289"
"52274","313.60800","26.13419","0.27045"
"52347","314.04600","26.17072","0.27069"
"52420","314.48400","26.20719","0.27561"
"52493","314.92200","26.24360","0.16622"
"52566","315.36000","26.28013","0.17137"
"52639","315.79800","26.31666","0.15704"
"52712","316.23600","26.35313","0.16844"
"52785","316.67400","26.38967","0.16506"
"52858","317.11200","26.42614","0.17111"
"52931","317.55000","26.46261","0.17849"
"53004","317.98800","26.49920","0.17874"
"53077","318.42600","26.53567","0.18770"
"53150","318.86400","26.57220","0.19005"
"53223","319.30200","26.60861","0.19177"
"53296","319.74000","26.64515","0.19732"
"53369","320.17800","26.68168","0.19939"
"53442","320.61600","26.71815","0.20366"
"53515","321.05400","26.75468","0.20863"
"53588","321.49200","26.79115","0.21090"
"53661","321.93000","26.82768","0.21275"
"53734","322.36800","26.86416","0.21618"
"53807","322.80600","26.90063","0.21886"
"53880","323.24400","26.93716","0.22094"
"53953","323.68200","26.97363","0.22038"
"54026","324.12000","27.01010","0.22517"
"54099","324.55800","27.04663","0.22730"
"54172","324.99600","27.08317","0.23047"
"54245","325.43400","27.11969","0.23347"
"54318","325.87200","27.15617","0.23537"
"54391","326.31000","27.19264","0.23752"
"54464","326.74800","27.22911","0.24096"
"54537","327.18600","27.26564","0.24528"
"54610","327.62400","27.30211","0.24851"
"54683","328.06200","27.33870","0.25091"
"54756","328.50000","27.37518","0.25394"
"54829","328.93800","27.41165","0.25679"
"54902","329.37600","27.44818","0.25936"
"54975","329.81400","27.48465","0.26381"
"55048","330.25200","27.52118","0.26646"
"55121","330.69000","27.55771","0.26924"
"55194","331.12800","27.59413","0.27333"
"55267","331.56600","27.63060","0.27710"
"55340","332.00400","27.66719","0.28069"
"55413","332.44200","27.70366","0.28354"
"55486","332.88000","27.74019","0.28575"
"55559","333.31800","27.77666","0.28640"
"55632","333.75600","27.81313","0.28751"
"55705","334.19400","27.84961","0.27715"
"55778","334.63200","27.88620","0.05887"
"55851","335.07000","27.92267","0.04211"
"55924","335.50800","27.95914","0.04656"
"55997","335.94600","27.99561","0.05585"
"56070","336.38400","28.03214","0.06473"
"56143","336.82200","28.06867","0.04768"
"56216","337.26000","28.10514","0.04711"
"56289","337.69800","28.14168","0.07953"
"56362","338.13600","28.17815","0.05074"
"56435","338.57400","28.21462","0.05202"
"56508","339.01200","28.25115","0.06555"
"56581","339.45000","28.28769","0.07467"
"56654","339.88800","28.32422","0.05828"
"56727","340.32600","28.36063","0.06020"
"56800","340.76400","28.39710","0.07842"
"56873","341.20200","28.43369","0.08224"
"56946","341.64000","28.47016","0.07292"
"57019","342.07800","28.50669","0.07566"
"57092","342.51600","28.54317","0.08233"
"57165","342.95400","28.57958","0.09075"
"57238","343.39200","28.61617","0.08715"
"57311","343.83000","28.65264","0.08461"
"57384","344.26800","28.68917","0.08511"
"57457","344.70600","28.72570","0.09068"
"57530","345.14400","28.76211","0.09695"
"57603","345.58200","28.79865","0.09598"
"57676","346.02000","28.83524","0.09505"
"57749","346.45800","28.87171","0.09538"
"57822","346.89600","28.90818","0.09796"
"57895","347.33400","28.94465","0.10388"
"57968","347.77200","28.98112","0.10735"
"58041","348.21000","29.01765","0.10749"
"58114","348.64800","29.05419","0.10706"
"58187","349.08600","29.09066","0.10731"
"58260","349.52400","29.12719","0.10901"
"58333","349.96200","29.16354","0.11167"
"58406","350.40000","29.20013","0.11552"
"58479","350.83800","29.23660","0.11958"
"58552","351.27600","29.27314","0.12160"
"58625","351.71400","29.30967","0.12228"
"58698","352.15200","29.34614","0.12292"
"58771","352.59000","29.38261","0.12351"
"58844","353.02800","29.41914","0.04394"
"58917","353.46600","29.45568","0.04367"
"58990","353.90400","29.49220","0.04303"
"59063","354.34200","29.52862","0.04157"
"59136","354.78000","29.56515","0.03774"
"59209","355.21800","29.60168","0.03888"
"59282","355.65600","29.63815","0.04394"
"59355","356.09400","29.67468","0.04481"
"59428","356.53200","29.71115","0.04651"
"59501","356.97000","29.74768","0.04702"
"59574","357.40800","29.78410","0.04626"
"59647","357.84600","29.82063","0.04560"
"59720","358.28400","29.85722","0.04761"
"59793","358.72200","29.89363","0.04960"
"59866","359.16000","29.93010","0.05046"
"59939","359.59800","29.96657","0.05150"
"60012","360.03600","30.00311","0.05301"
"60085","360.47400","30.03970","0.05348"
"60158","360.91200","30.07617","0.05235"
"60231","361.35000","30.11270","0.05333"
"60304","361.78800","30.14911","0.05521"
"60377","362.22600","30.18564","0.05545"
"60450","362.66400","30.22217","0.05638"
"60523","363.10200","30.25871","0.05809"
"60596","363.54000","30.29524","0.05927"
"60669","363.97800","30.33159","0.05903"
"60742","364.41600","30.36812","0.06009"
"60815","364.85400","30.40465","0.06192"
"60888","365.29200","30.44118","0.06202"
"60961","365.73000","30.47772","0.06341"
"61034","366.16800","30.51413","0.06471"
"61107","366.60600","30.55060","0.06696"
"61180","367.04400","30.58707","0.06840"
"61253","367.48200","30.62366","0.06936"
"61326","367.92000","30.66013","0.07137"
"61399","368.35800","30.69661","0.07299"
"61472","368.79600","30.73308","0.07516"
"61545","369.23400","30.76967","0.07617"
"61618","369.67200","30.80614","0.07698"
"61691","370.11000","30.84267","0.07882"
"61764","370.54800","30.87920","0.07945"
"61837","370.98600","30.91567","0.08126"
"61910","371.42400","30.95221","0.07108"
"61983","371.86200","30.98868","0.07433"
"62056","372.30000","31.02515","0.07643"
"62129","372.73800","31.06168","0.07891"
"62202","373.17600","31.09815","0.08084"
"62275","373.61400","31.13462","0.08299"
"62348","374.05200","31.17115","0.08339"
"62421","374.49000","31.20762","0.08409"
"62494","374.92800","31.24416","0.08475"
"62567","375.36600","31.28069","0.08586"
"62640","375.80400","31.31710","0.08659"
"62713","376.24200","31.35363","0.08789"
"62786","376.68000","31.39010","0.08849"
"62859","377.11800","31.42669","0.08950"
"62932","377.55600","31.46322","0.09090"
"63005","377.99400","31.49964","0.09195"
"63078","378.43200","31.53611","0.09293"
"63151","378.87000","31.57264","0.09368"
"63224","379.30800","31.60923","0.09513"
"63297","379.74600","31.64570","0.09611"
"63370","380.18400","31.68217","0.09715"
"63443","380.62200","31.71865","0.09822"
"63516","381.06000","31.75512","0.09909"
"63589","381.49800","31.79165","0.10024"
"63662","381.93600","31.82818","0.10107"
"63735","382.37400","31.86465","0.10023"
"63808","382.81200","31.90118","0.10060"
"63881","383.25000","31.93760","0.10192"
"63954","383.68800","31.97412","0.10305"
"64027","384.12600","32.01065","0.10342"
"64100","384.56400","32.04719","0.10401"
"64173","385.00200","32.08366","0.10523"
"64246","385.44000","32.12007","0.10485"
"64319","385.87800","32.15667","0.10570"
"64392","386.31600","32.19320","0.10666"
"64465","386.75400","32.22966","0.10758"
"64538","387.19200","32.26620","0.10777"
"64611","387.63000","32.30267","0.10892"
"64684","388.06800","32.33914","0.10938"
"64757","388.50600","32.37567","0.11017"
"64830","388.94400","32.41214","0.11081"
"64903","389.38200","32.44873","0.11190"
"64976","389.82000","32.48509","0.11171"
"65049","390.25800","32.52162","0.11158"
"65122","390.69600","32.55815","0.11218"
"65195","391.13400","32.59468","0.11409"
"65268","391.57200","32.63116","0.11453"
"65341","392.01000","32.66763","0.11545"
"65414","392.44800","32.70410","0.11610"
"65487","392.88600","32.74063","0.11689"
"65560","393.32400","32.77716","0.11765"
"65633","393.76200","32.81369","0.11818"
"65706","394.20000","32.85016","0.11944"
"65779","394.63800","32.88663","0.11986"
"65852","395.07600","32.92316","0.12070"
"65925","395.51400","32.95970","0.12118"
"65998","395.95200","32.99623","0.12219"
"66071","396.39000","33.03270","0.12324"
"66144","396.82800","33.06917","0.12403"
"66217","397.26600","33.10564","0.12510"
"66290","397.70400","33.14212","0.12657"
"66363","398.14200","33.17865","0.12733"
"66436","398.58000","33.21518","0.12828"
"66509","399.01800","33.25165","0.12935"
"66582","399.45600","33.28812","0.12937"
"66655","399.89400","33.32459","0.13019"
"66728","400.33200","33.36119","0.13047"
"66801","400.77000","33.39766","0.13192"
"66874","401.20800","33.43419","0.13256"
"66947","401.64600","33.47060","0.13286"
"67020","402.08400","33.50713","0.13333"
"67093","402.52200","33.54366","0.13399"
"67166","402.96000","33.58019","0.13312"
"67239","403.39800","33.61673","0.13432"
"67312","403.83600","33.65319","0.13481"
"67385","404.27400","33.68967","0.13481"
"67458","404.71200","33.72614","0.13536"
"67531","405.15000","33.76273","0.13537"
"67604","405.58800","33.79914","0.13602"
"67677","406.02600","33.83567","0.13669"
"67750","406.46400","33.87215","0.13708"
"67823","406.90200","33.90862","0.13747"
"67896","407.34000","33.94515","0.13789"
"67969","407.77800","33.98168","0.13814"
"68042","408.21600","34.01821","0.13801"
"68115","408.65400","34.05462","0.13941"
"68188","409.09200","34.09109","0.13981"
"68261","409.53000","34.12763","0.14101"
"68334","409.96800","34.16422","0.14128"
"68407","410.40600","34.20063","0.14207"
"68480","410.84400","34.23716","0.14331"
"68553","411.28200","34.27363","0.14378"
"68626","411.72000","34.31016","0.14498"
"68699","412.15800","34.34669","0.01318"
"68772","412.59600","34.38322","0.00836"
"68845","413.03400","34.41964","0.00594"
"68918","413.47200","34.45611","0.00610"
"68991","413.91000","34.49264","0.00684"
"69064","414.34800","34.52917","0.00601"
"69137","414.78600","34.56570","0.00699"
"69210","415.22400","34.60224","0.00668"
"69283","415.66200","34.63865","0.00655"
"69356","416.10000","34.67512","0.00727"
"69429","416.53800","34.71165","0.00611"
"69502","416.97600","34.74818","0.00649"
"69575","417.41400","34.78465","0.00670"
"69648","417.85200","34.82119","0.00619"
"69721","418.29000","34.85760","0.00675"
"69794","418.72800","34.89413","0.00680"
"69867","419.16600","34.93066","0.00580"
"69940","419.60400","34.96719","0.00688"
"70013","420.04200","35.00372","0.00614"
"70086","420.48000","35.04013","0.00623"
"70159","420.91800","35.07667","0.00657"
"70232","421.35600","35.11314","0.00605"
"70305","421.79400","35.14967","0.00633"
"70378","422.23200","35.18620","0.00690"
"70451","422.67000","35.22267","0.00592"
"70524","423.10800","35.25914","0.00610"
"70597","423.54600","35.29561","0.00610"
"70670","423.98400","35.33215","0.00571"
"70743","424.42200","35.36862","0.00624"
"70816","424.86000","35.40515","0.00596"
"70889","425.29800","35.44162","0.00651"
"70962","425.73600","35.47809","0.00666"
"71035","426.17400","35.51462","0.00628"
"71108","426.61200","35.55122","0.00668"
"71181","427.05000","35.58769","0.00655"
"71254","427.48800","35.62416","0.00622"
"71327","427.92600","35.66063","0.00650"
"71400","428.36400","35.69716","0.00672"
"71473","428.80200","35.73369","0.00673"
"71546","429.24000","35.77016","0.00637"
"71619","429.67800","35.80670","0.00640"
"71692","430.11600","35.84317","0.00667"
"71765","430.55400","35.87958","0.00641"
"71838","430.99200","35.91617","0.00575"
"71911","431.43000","35.95270","0.00679"
"71984","431.86800","35.98923","0.00640"
"72057","432.30600","36.02564","0.00622"
"72130","432.74400","36.06212","0.00672"
"72203","433.18200","36.09859","0.00626"
"72276","433.62000","36.13518","0.00656"
"72349","434.05800","36.17171","0.00672"
"72422","434.49600","36.20818","0.00650"
"72495","434.93400","36.24459","0.00638"
"72568","435.37200","36.28113","0.00651"
"72641","435.81000","36.31766","0.00623"
"72714","436.24800","36.35419","0.00648"
"72787","436.68600","36.39066","0.00643"
"72860","437.12400","36.42713","0.00652"
"72933","437.56200","36.46366","0.00648"
"73006","438.00000","36.50019","0.00677"
"73079","438.43800","36.53673","0.00634"
"73152","438.87600","36.57320","0.00679"
"73225","439.31400","36.60961","0.00663"
"73298","439.75200","36.64614","0.00646"
"73371","440.19000","36.68267","0.00640"
"73444","440.62800","36.71920","0.00646"
"73517","441.06600","36.75567","0.00651"
"73590","441.50400","36.79215","0.00667"
"73663","441.94200","36.82862","0.00679"
"73736","442.38000","36.86509","0.00656"
"73809","442.81800","36.90168","0.00685"
"73882","443.25600","36.93815","0.00678"
"73955","443.69400","36.97462","0.00703"
"74028","444.13200","37.01109","0.00624"
"74101","444.57000","37.04763","0.00657"
"74174","445.00800","37.08416","0.00720"
"74247","445.44600","37.12069","0.00681"
"74320","445.88400","37.15716","0.00693"
"74393","446.32200","37.19363","0.00678"
"74466","446.76000","37.23016","0.00689"
"74539","447.19800","37.26664","0.00705"
"74612","447.63600","37.30317","0.00699"
"74685","448.07400","37.33970","0.00666"
"74758","448.51200","37.37611","0.00683"
"74831","448.95000","37.41258","0.00685"
"74904","449.38800","37.44917","0.00715"
"74977","449.82600","37.48565","0.00671"
"75050","450.26400","37.52218","0.00711"
"75123","450.70200","37.55865","0.00696"
"75196","451.14000","37.59512","0.00714"
"75269","451.57800","37.63159","0.00737"
"75342","452.01600","37.66813","0.00734"
"75415","452.45400","37.70465","0.00714"
"75488","452.89200","37.74119","0.00708"
"75561","453.33000","37.77766","0.00720"
"75634","453.76800","37.81413","0.00744"
"75707","454.20600","37.85066","0.00691"
"75780","454.64400","37.88719","0.00742"
"75853","455.08200","37.92366","0.00736"
"75926","455.52000","37.96013","0.00740"
"75999","455.95800","37.99667","0.00736"
"76072","456.39600","38.03308","0.00708"
"76145","456.83400","38.06967","0.00748"
"76218","457.27200","38.10614","0.00720"
"76291","457.71000","38.14267","0.00741"
"76364","458.14800","38.17915","0.00750"
"76437","458.58600","38.21561","0.00730"
"76510","459.02400","38.25215","0.00732"
"76583","459.46200","38.28862","0.00772"
"76656","459.90000","38.32515","0.00762"
"76729","460.33800","38.36163","0.00718"
"76802","460.77600","38.39809","0.00761"
"76875","461.21400","38.43462","0.00731"
"76948","461.65200","38.47116","0.00751"
"77021","462.09000","38.50775","0.00779"
"77094","462.52800","38.54416","0.00786"
"77167","462.96600","38.58063","0.00765"
"77240","463.40400","38.61716","0.00760"
"77313","463.84200","38.65369","0.00771"
"77386","464.28000","38.69022","0.00758"
"77459","464.71800","38.72664","0.00794"
"77532","465.15600","38.76317","0.00758"
"77605","465.59400","38.79964","0.00796"
"77678","466.03200","38.83617","0.00788"
"77751","466.47000","38.87270","0.00763"
"77824","466.90800","38.90911","0.00780"
"77897","467.34600","38.94564","0.00800"
"77970","467.78400","38.98212","0.00810"
"78043","468.22200","39.01859","0.00790"
"78116","468.66000","39.05518","0.00781"
"78189","469.09800","39.09166","0.00790"
"78262","469.53600","39.12818","0.00804"
"78335","469.97400","39.16460","0.00777"
"78408","470.41200","39.20107","0.00777"
"78481","470.85000","39.23766","0.00796"
"78554","471.28800","39.27419","0.00803"
"78627","471.72600","39.31072","0.00769"
"78700","472.16400","39.34719","0.00762"
"78773","472.60200","39.38366","0.00760"
"78846","473.04000","39.42020","0.00744"
"78919","473.47800","39.45667","0.00744"
"78992","473.91600","39.49320","0.00752"
"79065","474.35400","39.52967","0.00718"
"79138","474.79200","39.56608","0.00767"
"79211","475.23000","39.60262","0.00771"
"79284","475.66800","39.63914","0.00755"
"79357","476.10600","39.67567","0.00767"
"79430","476.54400","39.71215","0.00768"
"79503","476.98200","39.74862","0.00747"
"79576","477.42000","39.78509","0.00767"
"79649","477.85800","39.82162","0.00778"
"79722","478.29600","39.85822","0.00779"
"79795","478.73400","39.89468","0.00786"
"79868","479.17200","39.93122","0.00810"
"79941","479.61000","39.96763","0.00787"
"80014","480.04800","40.00416","0.00796"
"80087","480.48600","40.04069","0.00782"
"80160","480.92400","40.07716","0.00841"
"80233","481.36200","40.11369","0.00767"
"80306","481.80000","40.15017","0.00823"
"80379","482.23800","40.18658","0.00783"
"80452","482.67600","40.22317","0.00819"
"80525","483.11400","40.25964","0.00847"
"80598","483.55200","40.29617","0.00825"
"80671","483.99000","40.33264","0.00824"
"80744","484.42800","40.36911","0.00783"
"80817","484.86600","40.40558","0.00791"
"80890","485.30400","40.44218","0.00790"
"80963","485.74200","40.47865","0.00857"
"81036","486.18000","40.51518","0.00842"
"81109","486.61800","40.55159","0.00835"
"81182","487.05600","40.58812","0.00796"
"81255","487.49400","40.62466","0.00817"
"81328","487.93200","40.66125","0.00780"
"81401","488.37000","40.69772","0.00835"
"81474","488.80800","40.73413","0.00825"
"81547","489.24600","40.77066","0.00860"
"81620","489.68400","40.80719","0.00822"
"81693","490.12200","40.84373","0.00854"
"81766","490.56000","40.88013","0.00839"
"81839","490.99800","40.91667","0.00820"
"81912","491.43600","40.95314","0.00820"
"81985","491.87400","40.98967","0.00843"
"82058","492.31200","41.02614","0.00857"
"82131","492.75000","41.06261","0.00838"
"82204","493.18800","41.09915","0.00793"
"82277","493.62600","41.13562","0.00821"
"82350","494.06400","41.17215","0.00810"
"82423","494.50200","41.20868","0.00843"
"82496","494.94000","41.24515","0.00834"
"82569","495.37800","41.28168","0.00834"
"82642","495.81600","41.31816","0.00797"
"82715","496.25400","41.35463","0.00848"
"82788","496.69200","41.39122","0.00836"
"82861","497.13000","41.42769","0.00839"
"82934","497.56800","41.46422","0.00848"
"83007","498.00600","41.50069","0.00873"
"83080","498.44400","41.53710","0.00851"
"83153","498.88200","41.57364","0.00879"
"83226","499.32000","41.61016","0.00883"
"83299","499.75800","41.64664","0.00846"
"83372","500.19600","41.68317","0.00824"
"83445","500.63400","41.71958","0.00830"
"83518","501.07200","41.75611","0.00822"
"83591","501.51000","41.79264","0.00789"
"83664","501.94800","41.82918","0.00870"
"83737","502.38600","41.86565","0.00841"
"83810","502.82400","41.90212","0.00858"
"83883","503.26200","41.93865","0.00810"
"83956","503.70000","41.97518","0.00854"
"84029","504.13800","42.01171","0.00883"
"84102","504.57600","42.04824","0.00854"
"84175","505.01400","42.08472","0.00883"
"84248","505.45200","42.12113","0.00875"
"84321","505.89000","42.15760","0.00892"
"84394","506.32800","42.19413","0.00897"
"84467","506.76600","42.23066","0.00911"
"84540","507.20400","42.26714","0.00928"
"84613","507.64200","42.30361","0.00931"
"84686","508.08000","42.34014","0.00930"
"84759","508.51800","42.37667","0.00910"
"84832","508.95600","42.41314","0.00956"
"84905","509.39400","42.44967","0.00922"
"84978","509.83200","42.48614","0.00924"
"85051","510.27000","42.52262","0.00919"
"85124","510.70800","42.55909","0.00891"
"85197","511.14600","42.59568","0.00933"
"85270","511.58400","42.63215","0.00930"
"85343","512.02200","42.66868","0.00899"
"85416","512.46000","42.70515","0.00883"
"85489","512.89800","42.74163","0.00891"
"85562","513.33600","42.77822","0.00883"
"85635","513.77400","42.81469","0.00894"
"85708","514.21200","42.85116","0.00927"
"85781","514.65000","42.88763","0.00915"
"85854","515.08800","42.92410","0.00883"
"85927","515.52600","42.96069","0.00862"
"86000","515.96400","42.99723","0.00849"
"86073","516.40200","43.03364","0.00863"
"86146","516.84000","43.07017","0.00867"
"86219","517.27800","43.10658","0.00883"
"86292","517.71600","43.14317","0.00896"
"86365","518.15400","43.17964","0.00869"
"86438","518.59200","43.21611","0.00861"
"86511","519.03000","43.25265","0.00902"
"86584","519.46800","43.28912","0.00852"
"86657","519.90600","43.32565","0.00899"
"86730","520.34400","43.36218","0.00898"
"86803","520.78200","43.39871","0.00917"
"86876","521.22000","43.43524","0.00953"
"86949","521.65800","43.47166","0.00881"
"87022","522.09600","43.50807","0.00879"
"87095","522.53400","43.54466","0.00888"
"87168","522.97200","43.58119","0.00901"
"87241","523.41000","43.61766","0.00932"
"87314","523.84800","43.65419","0.00933"
"87387","524.28600","43.69060","0.00922"
"87460","524.72400","43.72714","0.00964"
"87533","525.16200","43.76367","0.00954"
"87606","525.60000","43.80014","0.00927"
"87679","526.03800","43.83667","0.00955"
"87752","526.47600","43.87308","0.00920"
"87825","526.91400","43.90961","0.00916"
"87898","527.35200","43.94614","0.00967"
"87971","527.79000","43.98268","0.00916"
"88044","528.22800","44.01921","0.00935"
"88117","528.66600","44.05568","0.00889"
"88190","529.10400","44.09215","0.00964"
"88263","529.54200","44.12868","0.00959"
"88336","529.98000","44.16521","0.00956"
"88409","530.41800","44.20175","0.00971"
"88482","530.85600","44.23822","0.00982"
"88555","531.29400","44.27463","0.00971"
"88628","531.73200","44.31116","0.00973"
"88701","532.17000","44.34763","0.01040"
"88774","532.60800","44.38416","0.00981"
"88847","533.04600","44.42063","0.01020"
"88920","533.48400","44.45711","0.01022"
"88993","533.92200","44.49358","0.00968"
"89066","534.36000","44.53017","0.00993"
"89139","534.79800","44.56670","0.01008"
"89212","535.23600","44.60317","0.00984"
"89285","535.67400","44.63964","0.01025"
"89358","536.11200","44.67611","0.01007"
"89431","536.55000","44.71259","0.01021"
"89504","536.98800","44.74923","0.01030"
"89577","537.42600","44.78571","0.01029"
"89650","537.86400","44.82218","0.01087"
"89695","538.13200","44.84442","0.01084"