File: Trajectories_together/161223_3Specimen_RawData_2.csv
"","V1","V2","V3"
"1","End date","12/23/2016",""
"2","Specimen label","21CT_65",""
"3","Maximum Load","0.01464","N"
"4","Time","Extension","Load"
"5","(s)","(mm)","(N)"
"6","0.00000","0.00000","0.00208"
"33","0.16200","0.00975","0.00231"
"60","0.32400","0.02685","0.00270"
"87","0.48600","0.04084","0.00273"
"114","0.64800","0.05423","0.00286"
"141","0.81000","0.06768","0.00281"
"168","0.97200","0.08125","0.00319"
"195","1.13400","0.09477","0.00272"
"222","1.29600","0.10816","0.00279"
"249","1.45800","0.12167","0.00313"
"276","1.62000","0.13524","0.00346"
"303","1.78200","0.14870","0.00292"
"330","1.94400","0.16215","0.00321"
"357","2.10600","0.17572","0.00325"
"384","2.26800","0.18917","0.00341"
"411","2.43000","0.20263","0.00342"
"438","2.59200","0.21626","0.00319"
"465","2.75400","0.22971","0.00373"
"492","2.91600","0.24322","0.00375"
"519","3.07800","0.25668","0.00372"
"546","3.24000","0.27025","0.00371"
"573","3.40200","0.28370","0.00390"
"600","3.56400","0.29721","0.00355"
"627","3.72600","0.31073","0.00362"
"654","3.88800","0.32424","0.00386"
"681","4.05000","0.33763","0.00395"
"708","4.21200","0.35126","0.00397"
"735","4.37400","0.36472","0.00379"
"762","4.53600","0.37823","0.00412"
"789","4.69800","0.39174","0.00380"
"816","4.86000","0.40525","0.00381"
"843","5.02200","0.41871","0.00438"
"870","5.18400","0.43216","0.00455"
"897","5.34600","0.44567","0.00459"
"924","5.50800","0.45918","0.00445"
"951","5.67000","0.47264","0.00422"
"978","5.83200","0.48621","0.00424"
"1005","5.99400","0.49972","0.00437"
"1032","6.15600","0.51323","0.00460"
"1059","6.31800","0.52669","0.00421"
"1086","6.48000","0.54014","0.00426"
"1113","6.64200","0.55371","0.00420"
"1140","6.80400","0.56716","0.00444"
"1167","6.96600","0.58074","0.00449"
"1194","7.12800","0.59425","0.00413"
"1221","7.29000","0.60764","0.00443"
"1248","7.45200","0.62121","0.00493"
"1275","7.61400","0.63467","0.00423"
"1302","7.77600","0.64818","0.00457"
"1329","7.93800","0.66169","0.00408"
"1356","8.10000","0.67520","0.00433"
"1383","8.26200","0.68866","0.00446"
"1410","8.42400","0.70223","0.00477"
"1437","8.58600","0.71574","0.00446"
"1464","8.74800","0.72919","0.00494"
"1491","8.91000","0.74271","0.00441"
"1518","9.07200","0.75622","0.00456"
"1545","9.23400","0.76973","0.00472"
"1572","9.39600","0.78312","0.00444"
"1599","9.55800","0.79676","0.00461"
"1626","9.72000","0.81021","0.00484"
"1653","9.88200","0.82372","0.00486"
"1680","10.04400","0.83717","0.00465"
"1707","10.20600","0.85075","0.00491"
"1734","10.36800","0.86420","0.00441"
"1761","10.53000","0.87765","0.00504"
"1788","10.69200","0.89122","0.00493"
"1815","10.85400","0.90474","0.00464"
"1842","11.01600","0.91819","0.00499"
"1869","11.17800","0.93176","0.00510"
"1896","11.34000","0.94527","0.00505"
"1923","11.50200","0.95867","0.00467"
"1950","11.66400","0.97218","0.00494"
"1977","11.82600","0.98569","0.00502"
"2004","11.98800","0.99920","0.00473"
"2031","12.15000","1.01272","0.00475"
"2058","12.31200","1.02629","0.00504"
"2085","12.47400","1.03974","0.00524"
"2112","12.63600","1.05313","0.00523"
"2139","12.79800","1.06671","0.00554"
"2166","12.96000","1.08022","0.00542"
"2193","13.12200","1.09367","0.00535"
"2220","13.28400","1.10718","0.00501"
"2247","13.44600","1.12075","0.00523"
"2274","13.60800","1.13421","0.00539"
"2301","13.77000","1.14766","0.00526"
"2328","13.93200","1.16117","0.00553"
"2355","14.09400","1.17469","0.00551"
"2382","14.25600","1.18814","0.00557"
"2409","14.41800","1.20171","0.00519"
"2436","14.58000","1.21522","0.00555"
"2463","14.74200","1.22873","0.00547"
"2490","14.90400","1.24219","0.00560"
"2517","15.06600","1.25570","0.00548"
"2544","15.22800","1.26921","0.00534"
"2571","15.39000","1.28272","0.00576"
"2598","15.55200","1.29624","0.00581"
"2625","15.71400","1.30975","0.00524"
"2652","15.87600","1.32314","0.00557"
"2679","16.03800","1.33677","0.00544"
"2706","16.20000","1.35023","0.00534"
"2733","16.36200","1.36368","0.00559"
"2760","16.52400","1.37719","0.00522"
"2787","16.68600","1.39064","0.00570"
"2814","16.84800","1.40416","0.00561"
"2841","17.01000","1.41767","0.00546"
"2868","17.17200","1.43124","0.00586"
"2895","17.33400","1.44475","0.00545"
"2922","17.49600","1.45815","0.00575"
"2949","17.65800","1.47172","0.00590"
"2976","17.82000","1.48523","0.00598"
"3003","17.98200","1.49868","0.00590"
"3030","18.14400","1.51220","0.00593"
"3057","18.30600","1.52571","0.00595"
"3084","18.46800","1.53916","0.00577"
"3111","18.63000","1.55267","0.00598"
"3138","18.79200","1.56625","0.00611"
"3165","18.95400","1.57970","0.00600"
"3192","19.11600","1.59315","0.00646"
"3219","19.27800","1.60666","0.00586"
"3246","19.44000","1.62018","0.00622"
"3273","19.60200","1.63369","0.00638"
"3300","19.76400","1.64726","0.00596"
"3327","19.92600","1.66077","0.00618"
"3354","20.08800","1.67417","0.00618"
"3381","20.25000","1.68768","0.00631"
"3408","20.41200","1.70119","0.00588"
"3435","20.57400","1.71470","0.00629"
"3462","20.73600","1.72816","0.00631"
"3489","20.89800","1.74167","0.00673"
"3516","21.06000","1.75524","0.00622"
"3543","21.22200","1.76863","0.00631"
"3570","21.38400","1.78221","0.00627"
"3597","21.54600","1.79572","0.00602"
"3624","21.70800","1.80917","0.00596"
"3651","21.87000","1.82268","0.00594"
"3678","22.03200","1.83626","0.00612"
"3705","22.19400","1.84971","0.00618"
"3732","22.35600","1.86322","0.00607"
"3759","22.51800","1.87667","0.00627"
"3786","22.68000","1.89019","0.00619"
"3813","22.84200","1.90370","0.00634"
"3840","23.00400","1.91721","0.00607"
"3867","23.16600","1.93072","0.00632"
"3894","23.32800","1.94418","0.00601"
"3921","23.49000","1.95769","0.00609"
"3948","23.65200","1.97126","0.00637"
"3975","23.81400","1.98471","0.00642"
"4002","23.97600","1.99817","0.00691"
"4029","24.13800","2.01174","0.00651"
"4056","24.30000","2.02519","0.00639"
"4083","24.46200","2.03864","0.00623"
"4110","24.62400","2.05222","0.00602"
"4137","24.78600","2.06573","0.00674"
"4164","24.94800","2.07924","0.00646"
"4191","25.11000","2.09275","0.00657"
"4218","25.27200","2.10621","0.00650"
"4245","25.43400","2.11966","0.00639"
"4272","25.59600","2.13317","0.00638"
"4299","25.75800","2.14668","0.00664"
"4326","25.92000","2.16020","0.00685"
"4353","26.08200","2.17365","0.00701"
"4380","26.24400","2.18728","0.00626"
"4407","26.40600","2.20073","0.00667"
"4434","26.56800","2.21419","0.00639"
"4461","26.73000","2.22770","0.00689"
"4488","26.89200","2.24121","0.00618"
"4515","27.05400","2.25472","0.00662"
"4542","27.21600","2.26818","0.00649"
"4569","27.37800","2.28175","0.00655"
"4596","27.54000","2.29526","0.00658"
"4623","27.70200","2.30859","0.00654"
"4650","27.86400","2.32223","0.00678"
"4677","28.02600","2.33574","0.00686"
"4704","28.18800","2.34919","0.00655"
"4731","28.35000","2.36270","0.00662"
"4758","28.51200","2.37622","0.00668"
"4785","28.67400","2.38973","0.00648"
"4812","28.83600","2.40318","0.00683"
"4839","28.99800","2.41675","0.00694"
"4866","29.16000","2.43021","0.00711"
"4893","29.32200","2.44360","0.00706"
"4920","29.48400","2.45717","0.00682"
"4947","29.64600","2.47074","0.00682"
"4974","29.80800","2.48420","0.00717"
"5001","29.97000","2.49765","0.00703"
"5028","30.13200","2.51122","0.00695"
"5055","30.29400","2.52473","0.00683"
"5082","30.45600","2.53819","0.00698"
"5109","30.61800","2.55176","0.00736"
"5136","30.78000","2.56521","0.00721"
"5163","30.94200","2.57866","0.00669"
"5190","31.10400","2.59224","0.00746"
"5217","31.26600","2.60575","0.00689"
"5244","31.42800","2.61920","0.00728"
"5271","31.59000","2.63265","0.00688"
"5298","31.75200","2.64622","0.00700"
"5325","31.91400","2.65968","0.00704"
"5352","32.07600","2.67319","0.00714"
"5379","32.23800","2.68670","0.00728"
"5406","32.40000","2.70021","0.00692"
"5433","32.56200","2.71367","0.00700"
"5460","32.72400","2.72718","0.00715"
"5487","32.88600","2.74075","0.00721"
"5514","33.04800","2.75414","0.00699"
"5541","33.21000","2.76772","0.00731"
"5568","33.37200","2.78117","0.00717"
"5595","33.53400","2.79474","0.00746"
"5622","33.69600","2.80819","0.00737"
"5649","33.85800","2.82177","0.00712"
"5676","34.02000","2.83516","0.00700"
"5703","34.18200","2.84867","0.00704"
"5730","34.34400","2.86218","0.00700"
"5757","34.50600","2.87570","0.00751"
"5784","34.66800","2.88921","0.00713"
"5811","34.83000","2.90272","0.00742"
"5838","34.99200","2.91629","0.00692"
"5865","35.15400","2.92969","0.00780"
"5892","35.31600","2.94320","0.00707"
"5919","35.47800","2.95671","0.00761"
"5946","35.64000","2.97016","0.00675"
"5973","35.80200","2.98362","0.00738"
"6000","35.96400","2.99719","0.00719"
"6027","36.12600","3.01070","0.00737"
"6054","36.28800","3.02415","0.00765"
"6081","36.45000","3.03773","0.00780"
"6108","36.61200","3.05124","0.00762"
"6135","36.77400","3.06469","0.00743"
"6162","36.93600","3.07814","0.00786"
"6189","37.09800","3.09172","0.00791"
"6216","37.26000","3.10523","0.00794"
"6243","37.42200","3.11868","0.00757"
"6270","37.58400","3.13231","0.00778"
"6297","37.74600","3.14571","0.00839"
"6324","37.90800","3.15916","0.00783"
"6351","38.07000","3.17267","0.00812"
"6378","38.23200","3.18624","0.00743"
"6405","38.39400","3.19970","0.00726"
"6432","38.55600","3.21321","0.00768"
"6459","38.71800","3.22672","0.00791"
"6486","38.88000","3.24017","0.00740"
"6513","39.04200","3.25369","0.00754"
"6540","39.20400","3.26720","0.00773"
"6567","39.36600","3.28071","0.00741"
"6594","39.52800","3.29416","0.00756"
"6621","39.69000","3.30774","0.00793"
"6648","39.85200","3.32125","0.00750"
"6675","40.01400","3.33470","0.00770"
"6702","40.17600","3.34815","0.00779"
"6729","40.33800","3.36173","0.00746"
"6756","40.50000","3.37518","0.00772"
"6783","40.66200","3.38863","0.00781"
"6810","40.82400","3.40220","0.00781"
"6837","40.98600","3.41572","0.00825"
"6864","41.14800","3.42917","0.00816"
"6891","41.31000","3.44274","0.00788"
"6918","41.47200","3.45625","0.00765"
"6945","41.63400","3.46971","0.00766"
"6972","41.79600","3.48316","0.00788"
"6999","41.95800","3.49667","0.00806"
"7026","42.12000","3.51018","0.00761"
"7053","42.28200","3.52370","0.00826"
"7080","42.44400","3.53727","0.00837"
"7107","42.60600","3.55072","0.00804"
"7134","42.76800","3.56417","0.00787"
"7161","42.93000","3.57769","0.00835"
"7188","43.09200","3.59120","0.00795"
"7215","43.25400","3.60465","0.00757"
"7242","43.41600","3.61822","0.00788"
"7269","43.57800","3.63168","0.00787"
"7296","43.74000","3.64519","0.00765"
"7323","43.90200","3.65864","0.00769"
"7350","44.06400","3.67221","0.00775"
"7377","44.22600","3.68573","0.00796"
"7404","44.38800","3.69918","0.00771"
"7431","44.55000","3.71269","0.00810"
"7458","44.71200","3.72626","0.00783"
"7485","44.87400","3.73966","0.00754"
"7512","45.03600","3.75323","0.00822"
"7539","45.19800","3.76674","0.00821"
"7566","45.36000","3.78019","0.00785"
"7593","45.52200","3.79359","0.00764"
"7620","45.68400","3.80722","0.00796"
"7647","45.84600","3.82067","0.00823"
"7674","46.00800","3.83412","0.00789"
"7701","46.17000","3.84770","0.00804"
"7728","46.33200","3.86127","0.00821"
"7755","46.49400","3.87466","0.00851"
"7782","46.65600","3.88817","0.00773"
"7809","46.81800","3.90169","0.00807"
"7836","46.98000","3.91520","0.00777"
"7863","47.14200","3.92865","0.00808"
"7890","47.30400","3.94222","0.00815"
"7917","47.46600","3.95574","0.00822"
"7944","47.62800","3.96919","0.00758"
"7971","47.79000","3.98276","0.00796"
"7998","47.95200","3.99627","0.00789"
"8025","48.11400","4.00967","0.00725"
"8052","48.27600","4.02312","0.00736"
"8079","48.43800","4.03669","0.00733"
"8106","48.60000","4.05020","0.00739"
"8133","48.76200","4.06372","0.00747"
"8160","48.92400","4.07723","0.00766"
"8187","49.08600","4.09068","0.00716"
"8214","49.24800","4.10413","0.00752"
"8241","49.41000","4.11770","0.00731"
"8268","49.57200","4.13122","0.00719"
"8295","49.73400","4.14467","0.00729"
"8322","49.89600","4.15824","0.00781"
"8349","50.05800","4.17175","0.00749"
"8376","50.22000","4.18521","0.00757"
"8403","50.38200","4.19866","0.00776"
"8430","50.54400","4.21223","0.00743"
"8457","50.70600","4.22568","0.00726"
"8484","50.86800","4.23914","0.00757"
"8511","51.03000","4.25271","0.00729"
"8538","51.19200","4.26616","0.00749"
"8565","51.35400","4.27962","0.00717"
"8592","51.51600","4.29319","0.00774"
"8619","51.67800","4.30670","0.00754"
"8646","51.84000","4.32015","0.00755"
"8673","52.00200","4.33372","0.00785"
"8700","52.16400","4.34724","0.00715"
"8727","52.32600","4.36075","0.00738"
"8754","52.48800","4.37420","0.00721"
"8781","52.65000","4.38777","0.00746"
"8808","52.81200","4.40117","0.00712"
"8835","52.97400","4.41468","0.00733"
"8862","53.13600","4.42819","0.00754"
"8889","53.29800","4.44170","0.00710"
"8916","53.46000","4.45516","0.00769"
"8943","53.62200","4.46873","0.00756"
"8970","53.78400","4.48224","0.00742"
"8997","53.94600","4.49569","0.00755"
"9024","54.10800","4.50915","0.00752"
"9051","54.27000","4.52272","0.00754"
"9078","54.43200","4.53623","0.00712"
"9105","54.59400","4.54968","0.00742"
"9132","54.75600","4.56320","0.00763"
"9159","54.91800","4.57677","0.00720"
"9186","55.08000","4.59016","0.00707"
"9213","55.24200","4.60367","0.00743"
"9240","55.40400","4.61725","0.00763"
"9267","55.56600","4.63070","0.00778"
"9294","55.72800","4.64415","0.00736"
"9321","55.89000","4.65772","0.00720"
"9348","56.05200","4.67124","0.00772"
"9375","56.21400","4.68469","0.00721"
"9402","56.37600","4.69820","0.00753"
"9429","56.53800","4.71171","0.00766"
"9456","56.70000","4.72517","0.00709"
"9483","56.86200","4.73868","0.00714"
"9510","57.02400","4.75219","0.00759"
"9537","57.18600","4.76570","0.00748"
"9564","57.34800","4.77916","0.00756"
"9591","57.51000","4.79279","0.00778"
"9618","57.67200","4.80630","0.00723"
"9645","57.83400","4.81969","0.00738"
"9672","57.99600","4.83321","0.00772"
"9699","58.15800","4.84672","0.00739"
"9726","58.32000","4.86017","0.00708"
"9753","58.48200","4.87368","0.00767"
"9780","58.64400","4.88720","0.00763"
"9807","58.80600","4.90071","0.00769"
"9834","58.96800","4.91416","0.00748"
"9861","59.13000","4.92773","0.00762"
"9888","59.29200","4.94125","0.00804"
"9915","59.45400","4.95470","0.00791"
"9942","59.61600","4.96821","0.00766"
"9969","59.77800","4.98172","0.00772"
"9996","59.94000","4.99518","0.00766"
"10023","60.10200","5.00869","0.00763"
"10050","60.26400","5.02220","0.00738"
"10077","60.42600","5.03571","0.00728"
"10104","60.58800","5.04917","0.00786"
"10131","60.75000","5.06268","0.00752"
"10158","60.91200","5.07619","0.00777"
"10185","61.07400","5.08964","0.00759"
"10212","61.23600","5.10328","0.00770"
"10239","61.39800","5.11673","0.00845"
"10266","61.56000","5.13018","0.00774"
"10293","61.72200","5.14369","0.00805"
"10320","61.88400","5.15721","0.00745"
"10347","62.04600","5.17066","0.00759"
"10374","62.20800","5.18417","0.00741"
"10401","62.37000","5.19774","0.00781"
"10428","62.53200","5.21126","0.00746"
"10455","62.69400","5.22465","0.00771"
"10482","62.85600","5.23828","0.00726"
"10509","63.01800","5.25173","0.00765"
"10536","63.18000","5.26519","0.00723"
"10563","63.34200","5.27870","0.00768"
"10590","63.50400","5.29221","0.00789"
"10617","63.66600","5.30572","0.00830"
"10644","63.82800","5.31924","0.00794"
"10671","63.99000","5.33275","0.00801"
"10698","64.15200","5.34620","0.00804"
"10725","64.31400","5.35965","0.00753"
"10752","64.47600","5.37323","0.00767"
"10779","64.63800","5.38674","0.00824"
"10806","64.80000","5.40019","0.00763"
"10833","64.96200","5.41370","0.00796"
"10860","65.12400","5.42728","0.00759"
"10887","65.28600","5.44073","0.00823"
"10914","65.44800","5.45418","0.00805"
"10941","65.61000","5.46769","0.00774"
"10968","65.77200","5.48115","0.00761"
"10995","65.93400","5.49460","0.00823"
"11022","66.09600","5.50823","0.00789"
"11049","66.25800","5.52174","0.00811"
"11076","66.42000","5.53520","0.00807"
"11103","66.58200","5.54871","0.00757"
"11130","66.74400","5.56222","0.00763"
"11157","66.90600","5.57573","0.00763"
"11184","67.06800","5.58919","0.00800"
"11211","67.23000","5.60270","0.00791"
"11238","67.39200","5.61621","0.00784"
"11265","67.55400","5.62966","0.00746"
"11292","67.71600","5.64324","0.00807"
"11319","67.87800","5.65669","0.00764"
"11346","68.04000","5.67014","0.00794"
"11373","68.20200","5.68377","0.00793"
"11400","68.36400","5.69723","0.00757"
"11427","68.52600","5.71068","0.00754"
"11454","68.68800","5.72419","0.00751"
"11481","68.85000","5.73776","0.00749"
"11508","69.01200","5.75128","0.00753"
"11535","69.17400","5.76467","0.00755"
"11562","69.33600","5.77824","0.00722"
"11589","69.49800","5.79175","0.00747"
"11616","69.66000","5.80515","0.00757"
"11643","69.82200","5.81872","0.00760"
"11670","69.98400","5.83223","0.00751"
"11697","70.14600","5.84568","0.00705"
"11724","70.30800","5.85920","0.00708"
"11751","70.47000","5.87271","0.00744"
"11778","70.63200","5.88616","0.00721"
"11805","70.79400","5.89967","0.00769"
"11832","70.95600","5.91324","0.00747"
"11859","71.11800","5.92670","0.00704"
"11886","71.28000","5.94015","0.00710"
"11913","71.44200","5.95372","0.00708"
"11940","71.60400","5.96723","0.00719"
"11967","71.76600","5.98069","0.00794"
"11994","71.92800","5.99420","0.00711"
"12021","72.09000","6.00771","0.00734"
"12048","72.25200","6.02116","0.00735"
"12075","72.41400","6.03462","0.00751"
"12102","72.57600","6.04819","0.00697"
"12129","72.73800","6.06170","0.00723"
"12156","72.90000","6.07515","0.00741"
"12183","73.06200","6.08867","0.00695"
"12210","73.22400","6.10224","0.00761"
"12237","73.38600","6.11569","0.00752"
"12264","73.54800","6.12914","0.00758"
"12291","73.71000","6.14278","0.00733"
"12318","73.87200","6.15623","0.00754"
"12345","74.03400","6.16968","0.00718"
"12372","74.19600","6.18319","0.00727"
"12399","74.35800","6.19671","0.00713"
"12426","74.52000","6.21016","0.00747"
"12453","74.68200","6.22373","0.00739"
"12480","74.84400","6.23724","0.00746"
"12507","75.00600","6.25070","0.00739"
"12534","75.16800","6.26421","0.00768"
"12561","75.33000","6.27772","0.00731"
"12588","75.49200","6.29123","0.00710"
"12615","75.65400","6.30469","0.00776"
"12642","75.81600","6.31820","0.00738"
"12669","75.97800","6.33171","0.00764"
"12696","76.14000","6.34516","0.00728"
"12723","76.30200","6.35874","0.00726"
"12750","76.46400","6.37225","0.00761"
"12777","76.62600","6.38570","0.00745"
"12804","76.78800","6.39921","0.00728"
"12831","76.95000","6.41267","0.00739"
"12858","77.11200","6.42612","0.00728"
"12885","77.27400","6.43963","0.00754"
"12912","77.43600","6.45320","0.00760"
"12939","77.59800","6.46672","0.00739"
"12966","77.76000","6.48017","0.00779"
"12993","77.92200","6.49374","0.00779"
"13020","78.08400","6.50725","0.00782"
"13047","78.24600","6.52065","0.00767"
"13074","78.40800","6.53422","0.00739"
"13101","78.57000","6.54773","0.00802"
"13128","78.73200","6.56118","0.00755"
"13155","78.89400","6.57470","0.00777"
"13182","79.05600","6.58821","0.00729"
"13209","79.21800","6.60172","0.00763"
"13236","79.38000","6.61511","0.00772"
"13263","79.54200","6.62875","0.00784"
"13290","79.70400","6.64226","0.00763"
"13317","79.86600","6.65565","0.00787"
"13344","80.02800","6.66922","0.00738"
"13371","80.19000","6.68274","0.00762"
"13398","80.35200","6.69619","0.00764"
"13425","80.51400","6.70964","0.00739"
"13452","80.67600","6.72321","0.00787"
"13479","80.83800","6.73667","0.00742"
"13506","81.00000","6.75012","0.00751"
"13533","81.16200","6.76369","0.00779"
"13560","81.32400","6.77726","0.00727"
"13587","81.48600","6.79072","0.00723"
"13614","81.64800","6.80423","0.00784"
"13641","81.81000","6.81774","0.00787"
"13668","81.97200","6.83119","0.00802"
"13695","82.13400","6.84465","0.00765"
"13722","82.29600","6.85822","0.00774"
"13749","82.45800","6.87167","0.00766"
"13776","82.62000","6.88518","0.00761"
"13803","82.78200","6.89876","0.00762"
"13830","82.94400","6.91221","0.00785"
"13857","83.10600","6.92566","0.00742"
"13884","83.26800","6.93917","0.00732"
"13911","83.43000","6.95275","0.00755"
"13938","83.59200","6.96620","0.00762"
"13965","83.75400","6.97965","0.00734"
"13992","83.91600","6.99322","0.00764"
"14019","84.07800","7.00668","0.00776"
"14046","84.24000","7.02013","0.00779"
"14073","84.40200","7.03370","0.00753"
"14100","84.56400","7.04721","0.00804"
"14127","84.72600","7.06067","0.00769"
"14154","84.88800","7.07424","0.00771"
"14181","85.05000","7.08775","0.00766"
"14208","85.21200","7.10120","0.00766"
"14235","85.37400","7.11466","0.00776"
"14262","85.53600","7.12823","0.00766"
"14289","85.69800","7.14168","0.00791"
"14316","85.86000","7.15519","0.00820"
"14343","86.02200","7.16871","0.00775"
"14370","86.18400","7.18222","0.00776"
"14397","86.34600","7.19567","0.00788"
"14424","86.50800","7.20924","0.00781"
"14451","86.67000","7.22270","0.00750"
"14478","86.83200","7.23621","0.00747"
"14505","86.99400","7.24966","0.00755"
"14532","87.15600","7.26323","0.00766"
"14559","87.31800","7.27668","0.00745"
"14586","87.48000","7.29014","0.00796"
"14613","87.64200","7.30371","0.00774"
"14640","87.80400","7.31722","0.00736"
"14667","87.96600","7.33062","0.00739"
"14694","88.12800","7.34425","0.00753"
"14721","88.29000","7.35770","0.00761"
"14748","88.45200","7.37115","0.00775"
"14775","88.61400","7.38467","0.00733"
"14802","88.77600","7.39824","0.00733"
"14829","88.93800","7.41169","0.00754"
"14856","89.10000","7.42520","0.00815"
"14883","89.26200","7.43878","0.00757"
"14910","89.42400","7.45223","0.00753"
"14937","89.58600","7.46562","0.00830"
"14964","89.74800","7.47919","0.00764"
"14991","89.91000","7.49270","0.00760"
"15018","90.07200","7.50622","0.00795"
"15045","90.23400","7.51973","0.00755"
"15072","90.39600","7.53324","0.00802"
"15099","90.55800","7.54669","0.00778"
"15126","90.72000","7.56021","0.00799"
"15153","90.88200","7.57372","0.00800"
"15180","91.04400","7.58723","0.00770"
"15207","91.20600","7.60068","0.00766"
"15234","91.36800","7.61420","0.00789"
"15261","91.53000","7.62777","0.00747"
"15288","91.69200","7.64116","0.00768"
"15315","91.85400","7.65474","0.00773"
"15342","92.01600","7.66819","0.00751"
"15369","92.17800","7.68164","0.00781"
"15396","92.34000","7.69515","0.00771"
"15423","92.50200","7.70872","0.00771"
"15450","92.66400","7.72218","0.00800"
"15477","92.82600","7.73569","0.00776"
"15504","92.98800","7.74920","0.00761"
"15531","93.15000","7.76271","0.00799"
"15558","93.31200","7.77617","0.00787"
"15585","93.47400","7.78968","0.00760"
"15612","93.63600","7.80319","0.00761"
"15639","93.79800","7.81670","0.00785"
"15666","93.96000","7.83022","0.00775"
"15693","94.12200","7.84373","0.00775"
"15720","94.28400","7.85718","0.00748"
"15747","94.44600","7.87063","0.00800"
"15774","94.60800","7.88421","0.00766"
"15801","94.77000","7.89772","0.00800"
"15828","94.93200","7.91117","0.00813"
"15855","95.09400","7.92468","0.00809"
"15882","95.25600","7.93820","0.00707"
"15909","95.41800","7.95171","0.00775"
"15936","95.58000","7.96522","0.00751"
"15963","95.74200","7.97873","0.00806"
"15990","95.90400","7.99219","0.00756"
"16017","96.06600","8.00564","0.00780"
"16044","96.22800","8.01921","0.00766"
"16071","96.39000","8.03278","0.00798"
"16098","96.55200","8.04618","0.00758"
"16125","96.71400","8.05969","0.00798"
"16152","96.87600","8.07326","0.00774"
"16179","97.03800","8.08665","0.00815"
"16206","97.20000","8.10017","0.00807"
"16233","97.36200","8.11368","0.00832"
"16260","97.52400","8.12719","0.00810"
"16287","97.68600","8.14070","0.00808"
"16314","97.84800","8.15422","0.00812"
"16341","98.01000","8.16773","0.00807"
"16368","98.17200","8.18112","0.00801"
"16395","98.33400","8.19469","0.00815"
"16422","98.49600","8.20821","0.00806"
"16449","98.65800","8.22166","0.00771"
"16476","98.82000","8.23517","0.00763"
"16503","98.98200","8.24874","0.00753"
"16530","99.14400","8.26220","0.00763"
"16557","99.30600","8.27571","0.00765"
"16584","99.46800","8.28922","0.00809"
"16611","99.63000","8.30273","0.00789"
"16638","99.79200","8.31613","0.00816"
"16665","99.95400","8.32970","0.00798"
"16692","100.11600","8.34327","0.00789"
"16719","100.27800","8.35672","0.00780"
"16746","100.44000","8.37018","0.00824"
"16773","100.60200","8.38375","0.00796"
"16800","100.76400","8.39726","0.00839"
"16827","100.92600","8.41065","0.00825"
"16854","101.08800","8.42422","0.00801"
"16881","101.25000","8.43768","0.00789"
"16908","101.41200","8.45119","0.00803"
"16935","101.57400","8.46476","0.00803"
"16962","101.73600","8.47822","0.00846"
"16989","101.89800","8.49167","0.00823"
"17016","102.06000","8.50518","0.00819"
"17043","102.22200","8.51863","0.00810"
"17070","102.38400","8.53215","0.00806"
"17097","102.54600","8.54566","0.00825"
"17124","102.70800","8.55923","0.00815"
"17151","102.87000","8.57268","0.00840"
"17178","103.03200","8.58614","0.00839"
"17205","103.19400","8.59971","0.00816"
"17232","103.35600","8.61322","0.00842"
"17259","103.51800","8.62667","0.00786"
"17286","103.68000","8.64019","0.00835"
"17313","103.84200","8.65376","0.00846"
"17340","104.00400","8.66721","0.00839"
"17367","104.16600","8.68066","0.00788"
"17394","104.32800","8.69423","0.00799"
"17421","104.49000","8.70769","0.00819"
"17448","104.65200","8.72114","0.00825"
"17475","104.81400","8.73471","0.00817"
"17502","104.97600","8.74823","0.00842"
"17529","105.13800","8.76168","0.00819"
"17556","105.30000","8.77525","0.00818"
"17583","105.46200","8.78876","0.00819"
"17610","105.62400","8.80221","0.00824"
"17637","105.78600","8.81567","0.00846"
"17664","105.94800","8.82924","0.00821"
"17691","106.11000","8.84269","0.00780"
"17718","106.27200","8.85614","0.00815"
"17745","106.43400","8.86972","0.00854"
"17772","106.59600","8.88329","0.00834"
"17799","106.75800","8.89668","0.00834"
"17826","106.92000","8.91014","0.00790"
"17853","107.08200","8.92371","0.00855"
"17880","107.24400","8.93716","0.00843"
"17907","107.40600","8.95061","0.00821"
"17934","107.56800","8.96424","0.00806"
"17961","107.73000","8.97776","0.00785"
"17988","107.89200","8.99121","0.00808"
"18015","108.05400","9.00472","0.00822"
"18042","108.21600","9.01824","0.00804"
"18069","108.37800","9.03169","0.00844"
"18096","108.54000","9.04520","0.00864"
"18123","108.70200","9.05871","0.00831"
"18150","108.86400","9.07216","0.00811"
"18177","109.02600","9.08568","0.00803"
"18204","109.18800","9.09925","0.00810"
"18231","109.35000","9.11270","0.00783"
"18258","109.51200","9.12615","0.00810"
"18285","109.67400","9.13967","0.00771"
"18312","109.83600","9.15318","0.00828"
"18339","109.99800","9.16669","0.00837"
"18366","110.16000","9.18021","0.00812"
"18393","110.32200","9.19378","0.00832"
"18420","110.48400","9.20717","0.00827"
"18447","110.64600","9.22068","0.00825"
"18474","110.80800","9.23419","0.00831"
"18501","110.97000","9.24765","0.00850"
"18528","111.13200","9.26110","0.00846"
"18555","111.29400","9.27473","0.00829"
"18582","111.45600","9.28824","0.00809"
"18609","111.61800","9.30170","0.00869"
"18636","111.78000","9.31521","0.00894"
"18663","111.94200","9.32872","0.00853"
"18690","112.10400","9.34223","0.00857"
"18717","112.26600","9.35569","0.00850"
"18744","112.42800","9.36920","0.00834"
"18771","112.59000","9.38271","0.00873"
"18798","112.75200","9.39616","0.00847"
"18825","112.91400","9.40980","0.00861"
"18852","113.07600","9.42325","0.00863"
"18879","113.23800","9.43664","0.00890"
"18906","113.40000","9.45021","0.00901"
"18933","113.56200","9.46373","0.00861"
"18960","113.72400","9.47718","0.00861"
"18987","113.88600","9.49069","0.00868"
"19014","114.04800","9.50426","0.00875"
"19041","114.21000","9.51778","0.00873"
"19068","114.37200","9.53111","0.00866"
"19095","114.53400","9.54474","0.00893"
"19122","114.69600","9.55819","0.00822"
"19149","114.85800","9.57165","0.00849"
"19176","115.02000","9.58516","0.00850"
"19203","115.18200","9.59873","0.00853"
"19230","115.34400","9.61212","0.00845"
"19257","115.50600","9.62570","0.00893"
"19284","115.66800","9.63921","0.00887"
"19311","115.83000","9.65272","0.00864"
"19338","115.99200","9.66617","0.00873"
"19365","116.15400","9.67975","0.00919"
"19392","116.31600","9.69326","0.00847"
"19419","116.47800","9.70665","0.00868"
"19446","116.64000","9.72016","0.00865"
"19473","116.80200","9.73374","0.00858"
"19500","116.96400","9.74713","0.00856"
"19527","117.12600","9.76064","0.00844"
"19554","117.28800","9.77415","0.00875"
"19581","117.45000","9.78767","0.00850"
"19608","117.61200","9.80118","0.00842"
"19635","117.77400","9.81475","0.00878"
"19662","117.93600","9.82820","0.00885"
"19689","118.09800","9.84171","0.00908"
"19716","118.26000","9.85517","0.00891"
"19743","118.42200","9.86868","0.00862"
"19770","118.58400","9.88219","0.00872"
"19797","118.74600","9.89570","0.00891"
"19824","118.90800","9.90922","0.00882"
"19851","119.07000","9.92273","0.00885"
"19878","119.23200","9.93624","0.00896"
"19905","119.39400","9.94976","0.00862"
"19932","119.55600","9.96321","0.00837"
"19959","119.71800","9.97666","0.00855"
"19986","119.88000","9.99023","0.00848"
"20013","120.04200","10.00369","0.00858"
"20040","120.20400","10.01720","0.00866"
"20067","120.36600","10.03071","0.00848"
"20094","120.52800","10.04422","0.00862"
"20121","120.69000","10.05774","0.00852"
"20148","120.85200","10.07119","0.00881"
"20175","121.01400","10.08470","0.00856"
"20202","121.17600","10.09821","0.00887"
"20229","121.33800","10.11167","0.00811"
"20256","121.50000","10.12524","0.00836"
"20283","121.66200","10.13869","0.00811"
"20310","121.82400","10.15220","0.00830"
"20337","121.98600","10.16572","0.00832"
"20364","122.14800","10.17923","0.00902"
"20391","122.31000","10.19268","0.00878"
"20418","122.47200","10.20613","0.00854"
"20445","122.63400","10.21971","0.00844"
"20472","122.79600","10.23328","0.00892"
"20499","122.95800","10.24667","0.00913"
"20526","123.12000","10.26024","0.00825"
"20553","123.28200","10.27376","0.00890"
"20580","123.44400","10.28721","0.00900"
"20607","123.60600","10.30072","0.00845"
"20634","123.76800","10.31423","0.00859"
"20661","123.93000","10.32769","0.00870"
"20688","124.09200","10.34120","0.00860"
"20715","124.25400","10.35471","0.00855"
"20742","124.41600","10.36822","0.00891"
"20769","124.57800","10.38168","0.00856"
"20796","124.74000","10.39525","0.00901"
"20823","124.90200","10.40870","0.00872"
"20850","125.06400","10.42215","0.00876"
"20877","125.22600","10.43572","0.00852"
"20904","125.38800","10.44924","0.00917"
"20931","125.55000","10.46275","0.00884"
"20958","125.71200","10.47620","0.00863"
"20985","125.87400","10.48972","0.00874"
"21012","126.03600","10.50317","0.00862"
"21039","126.19800","10.51656","0.00902"
"21066","126.36000","10.53019","0.00874"
"21093","126.52200","10.54370","0.00857"
"21120","126.68400","10.55722","0.00914"
"21147","126.84600","10.57073","0.00914"
"21174","127.00800","10.58424","0.00860"
"21201","127.17000","10.59769","0.00897"
"21228","127.33200","10.61121","0.00927"
"21255","127.49400","10.62478","0.00891"
"21282","127.65600","10.63823","0.00884"
"21309","127.81800","10.65169","0.00900"
"21336","127.98000","10.66526","0.00866"
"21363","128.14200","10.67871","0.00911"
"21390","128.30400","10.69216","0.00894"
"21417","128.46600","10.70568","0.00893"
"21444","128.62800","10.71925","0.00883"
"21471","128.79000","10.73270","0.00877"
"21498","128.95200","10.74621","0.00888"
"21525","129.11400","10.75972","0.00891"
"21552","129.27600","10.77324","0.00892"
"21579","129.43800","10.78663","0.00917"
"21606","129.60000","10.80020","0.00875"
"21633","129.76200","10.81365","0.00882"
"21660","129.92400","10.82711","0.00865"
"21687","130.08600","10.84074","0.00861"
"21714","130.24800","10.85419","0.00928"
"21741","130.41000","10.86770","0.00890"
"21768","130.57200","10.88122","0.00866"
"21795","130.73400","10.89473","0.00914"
"21822","130.89600","10.90818","0.00944"
"21849","131.05800","10.92163","0.00902"
"21876","131.22000","10.93527","0.00883"
"21903","131.38200","10.94872","0.00857"
"21930","131.54400","10.96217","0.00910"
"21957","131.70600","10.97574","0.00894"
"21984","131.86800","10.98926","0.00868"
"22011","132.03000","11.00271","0.00952"
"22038","132.19200","11.01616","0.00919"
"22065","132.35400","11.02967","0.00884"
"22092","132.51600","11.04319","0.00918"
"22119","132.67800","11.05664","0.00903"
"22146","132.84000","11.07021","0.00926"
"22173","133.00200","11.08372","0.00909"
"22200","133.16400","11.09718","0.00922"
"22227","133.32600","11.11075","0.00920"
"22254","133.48800","11.12420","0.00881"
"22281","133.65000","11.13771","0.00881"
"22308","133.81200","11.15117","0.00919"
"22335","133.97400","11.16474","0.00856"
"22362","134.13600","11.17825","0.00885"
"22389","134.29800","11.19170","0.00912"
"22416","134.46000","11.20522","0.00846"
"22443","134.62200","11.21873","0.00862"
"22470","134.78400","11.23212","0.00861"
"22497","134.94600","11.24569","0.00926"
"22524","135.10800","11.25921","0.00873"
"22551","135.27000","11.27272","0.00856"
"22578","135.43200","11.28617","0.00951"
"22605","135.59400","11.29974","0.00938"
"22632","135.75600","11.31320","0.00954"
"22659","135.91800","11.32665","0.00887"
"22686","136.08000","11.34022","0.00906"
"22713","136.24200","11.35367","0.00888"
"22740","136.40400","11.36713","0.00912"
"22767","136.56600","11.38070","0.00897"
"22794","136.72800","11.39415","0.00938"
"22821","136.89000","11.40766","0.00963"
"22848","137.05200","11.42118","0.00927"
"22875","137.21400","11.43469","0.00919"
"22902","137.37600","11.44814","0.00936"
"22929","137.53800","11.46165","0.00964"
"22956","137.70000","11.47523","0.00933"
"22983","137.86200","11.48874","0.00919"
"23010","138.02400","11.50219","0.00902"
"23037","138.18600","11.51570","0.00930"
"23064","138.34800","11.52928","0.01004"
"23091","138.51000","11.54261","0.00966"
"23118","138.67200","11.55624","0.00935"
"23145","138.83400","11.56975","0.00912"
"23172","138.99600","11.58321","0.01004"
"23199","139.15800","11.59672","0.00904"
"23226","139.32000","11.61023","0.00948"
"23253","139.48200","11.62374","0.00923"
"23280","139.64400","11.63714","0.00923"
"23307","139.80600","11.65071","0.00933"
"23334","139.96800","11.66422","0.00911"
"23361","140.13000","11.67767","0.00916"
"23388","140.29200","11.69119","0.00906"
"23415","140.45400","11.70476","0.00931"
"23442","140.61600","11.71815","0.00930"
"23469","140.77800","11.73166","0.00967"
"23496","140.94000","11.74518","0.00955"
"23523","141.10200","11.75869","0.00932"
"23550","141.26400","11.77208","0.00955"
"23577","141.42600","11.78571","0.00958"
"23604","141.58800","11.79928","0.00942"
"23631","141.75000","11.81268","0.00940"
"23658","141.91200","11.82619","0.00948"
"23685","142.07400","11.83976","0.00934"
"23712","142.23600","11.85316","0.00972"
"23739","142.39800","11.86667","0.00973"
"23766","142.56000","11.88018","0.00953"
"23793","142.72200","11.89369","0.01002"
"23820","142.88400","11.90721","0.00983"
"23847","143.04600","11.92072","0.00973"
"23874","143.20800","11.93423","0.00964"
"23901","143.37000","11.94762","0.00907"
"23928","143.53200","11.96119","0.00961"
"23955","143.69400","11.97471","0.01017"
"23982","143.85600","11.98822","0.00989"
"24009","144.01800","12.00167","0.00958"
"24036","144.18000","12.01524","0.01012"
"24063","144.34200","12.02870","0.01000"
"24090","144.50400","12.04215","0.00947"
"24117","144.66600","12.05572","0.00989"
"24144","144.82800","12.06923","0.00975"
"24171","144.99000","12.08269","0.00955"
"24198","145.15200","12.09620","0.01001"
"24225","145.31400","12.10971","0.00981"
"24252","145.47600","12.12323","0.00989"
"24279","145.63800","12.13668","0.00991"
"24306","145.80000","12.15019","0.01013"
"24333","145.96200","12.16364","0.00984"
"24360","146.12400","12.17715","0.01019"
"24387","146.28600","12.19067","0.00956"
"24414","146.44800","12.20424","0.00990"
"24441","146.61000","12.21769","0.01018"
"24468","146.77200","12.23126","0.00985"
"24495","146.93400","12.24472","0.01002"
"24522","147.09600","12.25817","0.00992"
"24549","147.25800","12.27168","0.00986"
"24576","147.42000","12.28520","0.00984"
"24603","147.58200","12.29865","0.00976"
"24630","147.74400","12.31216","0.01030"
"24657","147.90600","12.32573","0.01012"
"24684","148.06800","12.33924","0.00984"
"24711","148.23000","12.35264","0.00990"
"24738","148.39200","12.36621","0.00981"
"24765","148.55400","12.37978","0.00988"
"24792","148.71600","12.39311","0.01027"
"24819","148.87800","12.40669","0.01014"
"24846","149.04000","12.42026","0.01058"
"24873","149.20200","12.43371","0.00967"
"24900","149.36400","12.44716","0.00979"
"24927","149.52600","12.46074","0.01023"
"24954","149.68800","12.47425","0.01065"
"24981","149.85000","12.48770","0.01009"
"25008","150.01200","12.50115","0.00996"
"25035","150.17400","12.51473","0.01064"
"25062","150.33600","12.52818","0.01001"
"25089","150.49800","12.54169","0.01054"
"25116","150.66000","12.55526","0.01045"
"25143","150.82200","12.56872","0.01087"
"25170","150.98400","12.58223","0.01022"
"25197","151.14600","12.59568","0.01057"
"25224","151.30800","12.60919","0.01074"
"25251","151.47000","12.62265","0.01065"
"25278","151.63200","12.63622","0.01095"
"25305","151.79400","12.64973","0.01054"
"25332","151.95600","12.66312","0.01065"
"25359","152.11800","12.67670","0.01059"
"25386","152.28000","12.69021","0.01075"
"25413","152.44200","12.70372","0.01072"
"25440","152.60400","12.71717","0.01049"
"25467","152.76600","12.73069","0.01079"
"25494","152.92800","12.74426","0.01053"
"25521","153.09000","12.75771","0.01039"
"25548","153.25200","12.77122","0.01071"
"25575","153.41400","12.78474","0.01121"
"25602","153.57600","12.79819","0.01079"
"25629","153.73800","12.81164","0.01070"
"25656","153.90000","12.82515","0.01046"
"25683","154.06200","12.83867","0.01083"
"25710","154.22400","12.85224","0.01060"
"25737","154.38600","12.86575","0.01070"
"25764","154.54800","12.87920","0.01081"
"25791","154.71000","12.89266","0.01118"
"25818","154.87200","12.90623","0.01074"
"25845","155.03400","12.91968","0.01128"
"25872","155.19600","12.93313","0.01124"
"25899","155.35800","12.94671","0.01055"
"25926","155.52000","12.96028","0.01116"
"25953","155.68200","12.97373","0.01101"
"25980","155.84400","12.98718","0.01140"
"26007","156.00600","13.00076","0.01072"
"26034","156.16800","13.01421","0.01131"
"26061","156.33000","13.02766","0.01094"
"26088","156.49200","13.04117","0.01152"
"26115","156.65400","13.05475","0.01125"
"26142","156.81600","13.06820","0.01115"
"26169","156.97800","13.08171","0.01108"
"26196","157.14000","13.09522","0.01128"
"26223","157.30200","13.10868","0.01105"
"26250","157.46400","13.12219","0.01110"
"26277","157.62600","13.13570","0.01102"
"26304","157.78800","13.14921","0.01141"
"26331","157.95000","13.16273","0.01136"
"26358","158.11200","13.17630","0.01123"
"26385","158.27400","13.18969","0.01129"
"26412","158.43600","13.20308","0.01154"
"26439","158.59800","13.21666","0.01127"
"26466","158.76000","13.23023","0.01144"
"26493","158.92200","13.24368","0.01122"
"26520","159.08400","13.25713","0.01119"
"26547","159.24600","13.27076","0.01150"
"26574","159.40800","13.28422","0.01092"
"26601","159.57000","13.29767","0.01143"
"26628","159.73200","13.31118","0.01126"
"26655","159.89400","13.32476","0.01129"
"26682","160.05600","13.33815","0.01146"
"26709","160.21800","13.35172","0.01105"
"26736","160.38000","13.36523","0.01134"
"26763","160.54200","13.37875","0.01158"
"26790","160.70400","13.39220","0.01129"
"26817","160.86600","13.40571","0.01099"
"26844","161.02800","13.41916","0.01157"
"26871","161.19000","13.43268","0.01149"
"26898","161.35200","13.44619","0.01193"
"26925","161.51400","13.45970","0.01172"
"26952","161.67600","13.47315","0.01155"
"26979","161.83800","13.48672","0.01134"
"27006","162.00000","13.50024","0.01206"
"27033","162.16200","13.51363","0.01173"
"27060","162.32400","13.52720","0.01170"
"27087","162.48600","13.54072","0.01143"
"27114","162.64800","13.55417","0.01177"
"27141","162.81000","13.56762","0.01140"
"27168","162.97200","13.58125","0.01171"
"27195","163.13400","13.59471","0.01204"
"27222","163.29600","13.60822","0.01131"
"27249","163.45800","13.62167","0.01194"
"27276","163.62000","13.63518","0.01169"
"27303","163.78200","13.64869","0.01191"
"27330","163.94400","13.66221","0.01189"
"27357","164.10600","13.67572","0.01158"
"27384","164.26800","13.68923","0.01175"
"27411","164.43000","13.70274","0.01192"
"27438","164.59200","13.71626","0.01191"
"27465","164.75400","13.72965","0.01227"
"27492","164.91600","13.74310","0.01182"
"27519","165.07800","13.75673","0.01192"
"27546","165.24000","13.77025","0.01153"
"27573","165.40200","13.78370","0.01182"
"27600","165.56400","13.79721","0.01201"
"27627","165.72600","13.81072","0.01218"
"27654","165.88800","13.82424","0.01204"
"27681","166.05000","13.83763","0.01265"
"27708","166.21200","13.85120","0.01195"
"27735","166.37400","13.86472","0.01207"
"27762","166.53600","13.87817","0.01178"
"27789","166.69800","13.89174","0.01192"
"27816","166.86000","13.90525","0.01219"
"27843","167.02200","13.91870","0.01225"
"27870","167.18400","13.93216","0.01186"
"27897","167.34600","13.94573","0.01200"
"27924","167.50800","13.95918","0.01215"
"27951","167.67000","13.97263","0.01244"
"27978","167.83200","13.98621","0.01219"
"28005","167.99400","13.99972","0.01246"
"28032","168.15600","14.01317","0.01271"
"28059","168.31800","14.02674","0.01265"
"28086","168.48000","14.04026","0.01235"
"28113","168.64200","14.05371","0.01271"
"28140","168.80400","14.06716","0.01238"
"28167","168.96600","14.08068","0.01249"
"28194","169.12800","14.09419","0.01272"
"28221","169.29000","14.10764","0.01259"
"28248","169.45200","14.12121","0.01232"
"28275","169.61400","14.13466","0.01252"
"28302","169.77600","14.14812","0.01286"
"28329","169.93800","14.16169","0.01305"
"28356","170.10000","14.17520","0.01260"
"28383","170.26200","14.18871","0.01294"
"28410","170.42400","14.20223","0.01285"
"28437","170.58600","14.21580","0.01300"
"28464","170.74800","14.22925","0.01262"
"28491","170.91000","14.24271","0.01305"
"28518","171.07200","14.25622","0.01333"
"28545","171.23400","14.26967","0.01258"
"28572","171.39600","14.28312","0.01326"
"28599","171.55800","14.29669","0.01304"
"28626","171.72000","14.31021","0.01289"
"28653","171.88200","14.32372","0.01309"
"28680","172.04400","14.33723","0.01291"
"28707","172.20600","14.35074","0.01311"
"28734","172.36800","14.36414","0.01277"
"28761","172.53000","14.37771","0.01332"
"28788","172.69200","14.39122","0.01314"
"28815","172.85400","14.40473","0.01323"
"28842","173.01600","14.41813","0.01302"
"28869","173.17800","14.43170","0.01296"
"28896","173.34000","14.44521","0.01373"
"28923","173.50200","14.45866","0.01342"
"28950","173.66400","14.47218","0.01297"
"28977","173.82600","14.48569","0.01297"
"29004","173.98800","14.49914","0.01326"
"29031","174.15000","14.51271","0.01378"
"29058","174.31200","14.52629","0.01346"
"29085","174.47400","14.53974","0.01350"
"29112","174.63600","14.55313","0.01342"
"29139","174.79800","14.56670","0.01359"
"29166","174.96000","14.58022","0.01358"
"29193","175.12200","14.59367","0.01374"
"29220","175.28400","14.60718","0.01357"
"29247","175.44600","14.62075","0.01360"
"29274","175.60800","14.63421","0.01312"
"29301","175.77000","14.64772","0.01307"
"29328","175.93200","14.66123","0.01360"
"29355","176.09400","14.67468","0.01317"
"29382","176.25600","14.68814","0.01312"
"29409","176.41800","14.70177","0.01334"
"29436","176.58000","14.71522","0.01353"
"29463","176.74200","14.72867","0.01308"
"29490","176.90400","14.74219","0.01355"
"29517","177.06600","14.75576","0.01371"
"29544","177.22800","14.76921","0.01349"
"29571","177.39000","14.78266","0.01348"
"29598","177.55200","14.79618","0.01371"
"29625","177.71400","14.80969","0.01336"
"29652","177.87600","14.82314","0.01397"
"29679","178.03800","14.83677","0.01369"
"29706","178.20000","14.85023","0.01359"
"29733","178.36200","14.86368","0.01314"
"29760","178.52400","14.87725","0.01352"
"29787","178.68600","14.89070","0.01358"
"29814","178.84800","14.90422","0.01321"
"29841","179.01000","14.91767","0.01385"
"29868","179.17200","14.93124","0.01340"
"29895","179.33400","14.94475","0.01336"
"29922","179.49600","14.95820","0.01421"
"29949","179.65800","14.97178","0.01373"
"29976","179.82000","14.98517","0.01386"
"30003","179.98200","14.99862","0.01451"
"30030","180.14400","15.01220","0.01413"
"30057","180.30600","15.02571","0.01436"
"30084","180.46800","15.03916","0.01378"
"30111","180.63000","15.05267","0.01395"
"30138","180.79200","15.06619","0.01372"
"30165","180.95400","15.07964","0.01414"
"30192","181.11600","15.09321","0.01398"
"30219","181.27800","15.10672","0.01375"
"30246","181.44000","15.12024","0.01394"
"30273","181.60200","15.13363","0.01429"
"30300","181.76400","15.14726","0.01405"
"30327","181.92600","15.16071","0.01343"
"30354","182.08800","15.17417","0.01408"
"30381","182.25000","15.18768","0.01403"
"30408","182.41200","15.20119","0.01396"
"30435","182.57400","15.21470","0.01332"
"30462","182.73600","15.22816","0.01371"
"30489","182.89800","15.24179","0.01382"
"30516","183.06000","15.25524","0.01360"
"30543","183.22200","15.26869","0.01349"
"30570","183.38400","15.28227","0.01415"
"30597","183.54600","15.29578","0.01342"
"30624","183.70800","15.30917","0.01360"
"30651","183.87000","15.32268","0.01347"
"30678","184.03200","15.33626","0.01383"
"30705","184.19400","15.34971","0.01393"
"30732","184.35600","15.36316","0.01231"
"30759","184.51800","15.37673","0.01259"
"30786","184.68000","15.39025","0.01209"
"30813","184.84200","15.40370","0.01227"
"30840","185.00400","15.41721","0.01233"
"30867","185.16600","15.43072","0.01233"
"30894","185.32800","15.44417","0.01263"
"30921","185.49000","15.45769","0.01246"
"30948","185.65200","15.47126","0.01276"
"30975","185.81400","15.48471","0.01249"
"31002","185.97600","15.49817","0.01312"
"31029","186.13800","15.51168","0.01261"
"31056","186.30000","15.52519","0.01293"
"31083","186.46200","15.53858","0.01264"
"31110","186.62400","15.55222","0.01246"
"31137","186.78600","15.56573","0.01285"
"31164","186.94800","15.57918","0.01331"
"31191","187.11000","15.59269","0.01327"
"31218","187.27200","15.60620","0.01281"
"31245","187.43400","15.61966","0.01257"
"31272","187.59600","15.63311","0.01307"
"31299","187.75800","15.64668","0.01273"
"31326","187.92000","15.66025","0.01258"
"31353","188.08200","15.67371","0.01255"
"31380","188.24400","15.68722","0.01217"
"31407","188.40600","15.70067","0.01186"
"31434","188.56800","15.71418","0.01234"
"31461","188.73000","15.72770","0.01293"
"31488","188.89200","15.74121","0.01270"
"31515","189.05400","15.75466","0.01282"
"31542","189.21600","15.76823","0.01274"
"31569","189.37800","15.78174","0.01281"
"31596","189.54000","15.79526","0.01280"
"31623","189.70200","15.80871","0.01273"
"31650","189.86400","15.82222","0.01281"
"31677","190.02600","15.83568","0.01300"
"31704","190.18800","15.84913","0.01288"
"31731","190.35000","15.86270","0.01311"
"31758","190.51200","15.87621","0.01272"
"31785","190.67400","15.88966","0.01249"
"31812","190.83600","15.90318","0.01309"
"31839","190.99800","15.91675","0.01349"
"31866","191.16000","15.93020","0.01320"
"31893","191.32200","15.94366","0.01293"
"31920","191.48400","15.95723","0.01255"
"31947","191.64600","15.97074","0.01297"
"31974","191.80800","15.98413","0.01285"
"32001","191.97000","15.99777","0.01256"
"32028","192.13200","16.01122","0.01327"
"32055","192.29400","16.02473","0.01334"
"32082","192.45600","16.03818","0.01287"
"32109","192.61800","16.05169","0.01337"
"32136","192.78000","16.06515","0.01315"
"32163","192.94200","16.07866","0.01316"
"32190","193.10400","16.09223","0.01283"
"32217","193.26600","16.10575","0.01322"
"32244","193.42800","16.11914","0.01331"
"32271","193.59000","16.13265","0.01311"
"32298","193.75200","16.14622","0.01299"
"32325","193.91400","16.15968","0.01319"
"32352","194.07600","16.17319","0.01331"
"32379","194.23800","16.18670","0.01352"
"32406","194.40000","16.20021","0.01310"
"32433","194.56200","16.21372","0.01222"
"32460","194.72400","16.22718","0.01303"
"32487","194.88600","16.24069","0.01132"
"32514","195.04800","16.25414","0.00835"
"32541","195.21000","16.26772","0.00601"
"32568","195.37200","16.28123","0.00525"
"32595","195.53400","16.29468","0.00507"
"32622","195.69600","16.30819","0.00537"
"32649","195.85800","16.32170","0.00427"
"32676","196.02000","16.33522","0.00456"
"32703","196.18200","16.34867","0.00479"
"32730","196.34400","16.36224","0.00525"
"32757","196.50600","16.37569","0.00569"
"32784","196.66800","16.38915","0.00483"
"32811","196.83000","16.40272","0.00455"
"32838","196.99200","16.41623","0.00463"
"32865","197.15400","16.42962","0.00503"
"32892","197.31600","16.44320","0.00561"
"32919","197.47800","16.45671","0.00509"
"32946","197.64000","16.47016","0.00488"
"32973","197.80200","16.48368","0.00503"
"33000","197.96400","16.49719","0.00497"
"33027","198.12600","16.51076","0.00563"
"33054","198.28800","16.52415","0.00537"
"33081","198.45000","16.53772","0.00511"
"33108","198.61200","16.55124","0.00467"
"33135","198.77400","16.56469","0.00540"
"33162","198.93600","16.57814","0.00573"
"33189","199.09800","16.59171","0.00540"
"33216","199.26000","16.60517","0.00543"
"33243","199.42200","16.61868","0.00549"
"33270","199.58400","16.63225","0.00550"
"33297","199.74600","16.64571","0.00522"
"33324","199.90800","16.65916","0.00546"
"33351","200.07000","16.67279","0.00518"
"33378","200.23200","16.68618","0.00529"
"33405","200.39400","16.69963","0.00530"
"33432","200.55600","16.71321","0.00556"
"33438","200.58800","16.71590","0.00569"