File: Trajectories_together/161218Specimen_RawData_8.csv
"","V1","V2","V3"
"1","End date","12/18/2016",""
"2","Specimen label","16CT_29",""
"3","Maximum Load","0.02810","N"
"4","Time","Extension","Load"
"5","(s)","(mm)","(N)"
"6","0.00000","0.00000","-0.00022"
"22","0.09600","0.00347","-0.00003"
"38","0.19200","0.01321","-0.00028"
"54","0.28800","0.02344","-0.00050"
"70","0.38400","0.03217","-0.00021"
"86","0.48000","0.04024","0.00025"
"102","0.57600","0.04831","0.00005"
"118","0.67200","0.05626","-0.00015"
"134","0.76800","0.06421","-0.00014"
"150","0.86400","0.07229","-0.00009"
"166","0.96000","0.08018","-0.00010"
"182","1.05600","0.08819","-0.00004"
"198","1.15200","0.09626","-0.00019"
"214","1.24800","0.10421","0.00031"
"230","1.34400","0.11222","-0.00004"
"246","1.44000","0.12024","0.00050"
"262","1.53600","0.12819","-0.00033"
"278","1.63200","0.13620","0.00036"
"294","1.72800","0.14421","0.00020"
"310","1.82400","0.15222","0.00009"
"326","1.92000","0.16030","0.00032"
"342","2.01600","0.16819","0.00003"
"358","2.11200","0.17614","0.00028"
"374","2.20800","0.18421","-0.00002"
"390","2.30400","0.19228","-0.00020"
"406","2.40000","0.20024","0.00011"
"422","2.49600","0.20819","0.00038"
"438","2.59200","0.21626","0.00015"
"454","2.68800","0.22415","0.00003"
"470","2.78400","0.23222","0.00000"
"486","2.88000","0.24023","0.00012"
"502","2.97600","0.24819","-0.00020"
"518","3.07200","0.25620","0.00016"
"534","3.16800","0.26421","0.00034"
"550","3.26400","0.27216","0.00041"
"566","3.36000","0.28023","-0.00010"
"582","3.45600","0.28819","0.00009"
"598","3.55200","0.29620","-0.00007"
"614","3.64800","0.30415","0.00011"
"630","3.74400","0.31216","0.00012"
"646","3.84000","0.32017","0.00033"
"662","3.93600","0.32818","0.00042"
"678","4.03200","0.33620","0.00049"
"694","4.12800","0.34415","0.00005"
"710","4.22400","0.35216","0.00002"
"726","4.32000","0.36017","0.00041"
"742","4.41600","0.36818","0.00047"
"758","4.51200","0.37620","-0.00012"
"774","4.60800","0.38421","0.00031"
"790","4.70400","0.39216","0.00002"
"806","4.80000","0.40017","0.00055"
"822","4.89600","0.40818","0.00006"
"838","4.99200","0.41619","0.00028"
"854","5.08800","0.42421","0.00030"
"870","5.18400","0.43222","-0.00009"
"886","5.28000","0.44017","0.00041"
"902","5.37600","0.44818","-0.00014"
"918","5.47200","0.45619","0.00018"
"934","5.56800","0.46421","0.00040"
"950","5.66400","0.47228","0.00008"
"966","5.76000","0.48017","0.00019"
"982","5.85600","0.48818","0.00064"
"998","5.95200","0.49619","-0.00020"
"1014","6.04800","0.50426","0.00030"
"1030","6.14400","0.51222","-0.00011"
"1046","6.24000","0.52023","-0.00007"
"1062","6.33600","0.52818","0.00039"
"1078","6.43200","0.53613","0.00008"
"1094","6.52800","0.54420","0.00035"
"1110","6.62400","0.55222","0.00018"
"1126","6.72000","0.56023","0.00034"
"1142","6.81600","0.56818","0.00013"
"1158","6.91200","0.57619","0.00010"
"1174","7.00800","0.58420","-0.00040"
"1190","7.10400","0.59222","0.00003"
"1206","7.20000","0.60023","0.00020"
"1222","7.29600","0.60818","0.00036"
"1238","7.39200","0.61619","0.00010"
"1254","7.48800","0.62420","0.00018"
"1270","7.58400","0.63215","0.00022"
"1286","7.68000","0.64023","0.00005"
"1302","7.77600","0.64824","0.00007"
"1318","7.87200","0.65619","-0.00007"
"1334","7.96800","0.66420","0.00035"
"1350","8.06400","0.67221","0.00039"
"1366","8.16000","0.68017","0.00015"
"1382","8.25600","0.68818","0.00006"
"1398","8.35200","0.69625","0.00010"
"1414","8.44800","0.70420","-0.00021"
"1430","8.54400","0.71215","0.00041"
"1446","8.64000","0.72016","0.00012"
"1462","8.73600","0.72818","-0.00028"
"1478","8.83200","0.73619","0.00023"
"1494","8.92800","0.74420","-0.00006"
"1510","9.02400","0.75215","0.00006"
"1526","9.12000","0.76016","0.00054"
"1542","9.21600","0.76818","0.00015"
"1558","9.31200","0.77625","0.00003"
"1574","9.40800","0.78420","-0.00016"
"1590","9.50400","0.79221","0.00009"
"1606","9.60000","0.80016","-0.00021"
"1622","9.69600","0.80818","0.00024"
"1638","9.79200","0.81619","0.00003"
"1654","9.88800","0.82420","0.00017"
"1670","9.98400","0.83221","0.00027"
"1686","10.08000","0.84016","-0.00013"
"1702","10.17600","0.84817","0.00009"
"1718","10.27200","0.85619","0.00004"
"1734","10.36800","0.86420","0.00013"
"1750","10.46400","0.87227","0.00049"
"1766","10.56000","0.88022","0.00061"
"1782","10.65600","0.88817","0.00025"
"1798","10.75200","0.89613","0.00029"
"1814","10.84800","0.90420","0.00036"
"1830","10.94400","0.91221","0.00019"
"1846","11.04000","0.92022","-0.00020"
"1862","11.13600","0.92823","0.00003"
"1878","11.23200","0.93618","0.00012"
"1894","11.32800","0.94420","-0.00002"
"1910","11.42400","0.95221","0.00002"
"1926","11.52000","0.96022","0.00024"
"1942","11.61600","0.96823","0.00009"
"1958","11.71200","0.97618","0.00032"
"1974","11.80800","0.98420","0.00024"
"1990","11.90400","0.99221","0.00033"
"2006","12.00000","1.00022","0.00014"
"2022","12.09600","1.00823","0.00022"
"2038","12.19200","1.01624","-0.00001"
"2054","12.28800","1.02419","0.00045"
"2070","12.38400","1.03221","0.00010"
"2086","12.48000","1.04028","0.00026"
"2102","12.57600","1.04817","0.00017"
"2118","12.67200","1.05618","0.00022"
"2134","12.76800","1.06419","-0.00002"
"2150","12.86400","1.07215","-0.00007"
"2166","12.96000","1.08016","0.00015"
"2182","13.05600","1.08823","0.00008"
"2198","13.15200","1.09618","0.00000"
"2214","13.24800","1.10419","0.00021"
"2230","13.34400","1.11215","0.00016"
"2246","13.44000","1.12016","0.00041"
"2262","13.53600","1.12817","0.00032"
"2278","13.63200","1.13624","0.00015"
"2294","13.72800","1.14425","0.00015"
"2310","13.82400","1.15220","0.00015"
"2326","13.92000","1.16022","0.00053"
"2342","14.01600","1.16817","-0.00001"
"2358","14.11200","1.17624","0.00033"
"2374","14.20800","1.18425","0.00022"
"2390","14.30400","1.19220","0.00021"
"2406","14.40000","1.20022","0.00027"
"2422","14.49600","1.20817","0.00026"
"2438","14.59200","1.21618","0.00018"
"2454","14.68800","1.22425","-0.00008"
"2470","14.78400","1.23226","0.00015"
"2486","14.88000","1.24015","0.00037"
"2502","14.97600","1.24823","0.00045"
"2518","15.07200","1.25618","-0.00002"
"2534","15.16800","1.26419","0.00023"
"2550","15.26400","1.27226","0.00038"
"2566","15.36000","1.28027","0.00030"
"2582","15.45600","1.28817","-0.00007"
"2598","15.55200","1.29618","0.00042"
"2614","15.64800","1.30425","0.00027"
"2630","15.74400","1.31220","0.00033"
"2646","15.84000","1.32021","0.00009"
"2662","15.93600","1.32822","0.00064"
"2678","16.03200","1.33612","0.00024"
"2694","16.12800","1.34413","0.00033"
"2710","16.22400","1.35226","0.00044"
"2726","16.32000","1.36021","0.00015"
"2742","16.41600","1.36822","0.00011"
"2758","16.51200","1.37624","0.00038"
"2774","16.60800","1.38413","0.00022"
"2790","16.70400","1.39220","0.00003"
"2806","16.80000","1.40021","0.00065"
"2822","16.89600","1.40822","0.00003"
"2838","16.99200","1.41623","0.00012"
"2854","17.08800","1.42419","0.00062"
"2870","17.18400","1.43214","-0.00007"
"2886","17.28000","1.44015","0.00019"
"2902","17.37600","1.44822","0.00031"
"2918","17.47200","1.45623","0.00005"
"2934","17.56800","1.46419","-0.00013"
"2950","17.66400","1.47220","0.00022"
"2966","17.76000","1.48015","0.00078"
"2982","17.85600","1.48822","0.00006"
"2998","17.95200","1.49629","0.00071"
"3014","18.04800","1.50424","0.00032"
"3030","18.14400","1.51220","0.00017"
"3046","18.24000","1.52021","0.00061"
"3062","18.33600","1.52822","0.00027"
"3078","18.43200","1.53623","-0.00002"
"3094","18.52800","1.54424","0.00060"
"3110","18.62400","1.55226","0.00011"
"3126","18.72000","1.56021","0.00047"
"3142","18.81600","1.56816","0.00046"
"3158","18.91200","1.57623","0.00018"
"3174","19.00800","1.58424","0.00035"
"3190","19.10400","1.59220","0.00047"
"3206","19.20000","1.60021","0.00048"
"3222","19.29600","1.60816","0.00018"
"3238","19.39200","1.61623","-0.00005"
"3254","19.48800","1.62424","0.00006"
"3270","19.58400","1.63219","0.00026"
"3286","19.68000","1.64027","0.00032"
"3302","19.77600","1.64822","0.00050"
"3318","19.87200","1.65617","-0.00005"
"3334","19.96800","1.66424","0.00018"
"3350","20.06400","1.67225","0.00062"
"3366","20.16000","1.68021","0.00025"
"3382","20.25600","1.68828","0.00049"
"3398","20.35200","1.69617","0.00025"
"3414","20.44800","1.70418","0.00018"
"3430","20.54400","1.71225","0.00030"
"3446","20.64000","1.72020","0.00043"
"3462","20.73600","1.72822","0.00034"
"3478","20.83200","1.73623","0.00032"
"3494","20.92800","1.74418","0.00051"
"3510","21.02400","1.75219","0.00047"
"3526","21.12000","1.76026","0.00077"
"3542","21.21600","1.76822","0.00055"
"3558","21.31200","1.77617","0.00016"
"3574","21.40800","1.78418","0.00028"
"3590","21.50400","1.79213","0.00052"
"3606","21.60000","1.80020","0.00085"
"3622","21.69600","1.80821","0.00004"
"3638","21.79200","1.81617","-0.00010"
"3654","21.88800","1.82418","0.00002"
"3670","21.98400","1.83219","0.00035"
"3686","22.08000","1.84020","0.00039"
"3702","22.17600","1.84821","0.00001"
"3718","22.27200","1.85617","0.00022"
"3734","22.36800","1.86424","-0.00006"
"3750","22.46400","1.87219","0.00050"
"3766","22.56000","1.88014","0.00029"
"3782","22.65600","1.88821","0.00048"
"3798","22.75200","1.89628","0.00021"
"3814","22.84800","1.90424","0.00033"
"3830","22.94400","1.91219","0.00075"
"3846","23.04000","1.92020","0.00052"
"3862","23.13600","1.92821","0.00046"
"3878","23.23200","1.93622","0.00062"
"3894","23.32800","1.94418","0.00032"
"3910","23.42400","1.95225","0.00029"
"3926","23.52000","1.96020","0.00032"
"3942","23.61600","1.96809","0.00010"
"3958","23.71200","1.97622","0.00048"
"3974","23.80800","1.98424","0.00018"
"3990","23.90400","1.99219","0.00008"
"4006","24.00000","2.00020","0.00043"
"4022","24.09600","2.00821","0.00059"
"4038","24.19200","2.01610","0.00028"
"4054","24.28800","2.02423","0.00095"
"4070","24.38400","2.03225","0.00026"
"4086","24.48000","2.04020","0.00016"
"4102","24.57600","2.04827","0.00039"
"4118","24.67200","2.05622","0.00058"
"4134","24.76800","2.06417","0.00028"
"4150","24.86400","2.07225","0.00022"
"4166","24.96000","2.08026","0.00034"
"4182","25.05600","2.08821","0.00030"
"4198","25.15200","2.09622","0.00014"
"4214","25.24800","2.10417","0.00060"
"4230","25.34400","2.11219","0.00019"
"4246","25.44000","2.12026","0.00023"
"4262","25.53600","2.12827","0.00013"
"4278","25.63200","2.13616","0.00054"
"4294","25.72800","2.14411","0.00016"
"4310","25.82400","2.15218","0.00034"
"4326","25.92000","2.16020","0.00043"
"4342","26.01600","2.16821","0.00036"
"4358","26.11200","2.17622","0.00068"
"4374","26.20800","2.18423","0.00065"
"4390","26.30400","2.19218","0.00077"
"4406","26.40000","2.20020","0.00056"
"4422","26.49600","2.20821","0.00007"
"4438","26.59200","2.21622","0.00069"
"4454","26.68800","2.22423","0.00056"
"4470","26.78400","2.23218","0.00094"
"4486","26.88000","2.24013","0.00085"
"4502","26.97600","2.24821","0.00032"
"4518","27.07200","2.25622","0.00041"
"4534","27.16800","2.26423","0.00063"
"4550","27.26400","2.27224","0.00032"
"4566","27.36000","2.28013","0.00039"
"4582","27.45600","2.28821","0.00023"
"4598","27.55200","2.29628","0.00047"
"4614","27.64800","2.30417","0.00071"
"4630","27.74400","2.31224","0.00042"
"4646","27.84000","2.32019","0.00051"
"4662","27.93600","2.32814","0.00038"
"4678","28.03200","2.33616","0.00026"
"4694","28.12800","2.34429","0.00032"
"4710","28.22400","2.35218","0.00058"
"4726","28.32000","2.36019","0.00067"
"4742","28.41600","2.36820","0.00070"
"4758","28.51200","2.37616","0.00005"
"4774","28.60800","2.38417","0.00049"
"4790","28.70400","2.39224","0.00056"
"4806","28.80000","2.40019","0.00048"
"4822","28.89600","2.40814","0.00070"
"4838","28.99200","2.41615","0.00040"
"4854","29.08800","2.42417","0.00029"
"4870","29.18400","2.43218","0.00073"
"4886","29.28000","2.44025","0.00036"
"4902","29.37600","2.44820","0.00042"
"4918","29.47200","2.45615","0.00034"
"4934","29.56800","2.46417","0.00030"
"4950","29.66400","2.47218","0.00068"
"4966","29.76000","2.48025","0.00053"
"4982","29.85600","2.48820","0.00033"
"4998","29.95200","2.49615","0.00059"
"5014","30.04800","2.50416","0.00054"
"5030","30.14400","2.51218","0.00036"
"5046","30.24000","2.52025","0.00075"
"5062","30.33600","2.52826","0.00074"
"5078","30.43200","2.53621","0.00064"
"5094","30.52800","2.54416","0.00086"
"5110","30.62400","2.55224","0.00072"
"5126","30.72000","2.56025","0.00066"
"5142","30.81600","2.56820","0.00080"
"5158","30.91200","2.57621","0.00059"
"5174","31.00800","2.58428","0.00048"
"5190","31.10400","2.59218","0.00017"
"5206","31.20000","2.60019","0.00061"
"5222","31.29600","2.60826","0.00049"
"5238","31.39200","2.61621","0.00048"
"5254","31.48800","2.62422","0.00043"
"5270","31.58400","2.63223","0.00088"
"5286","31.68000","2.64019","0.00057"
"5302","31.77600","2.64820","0.00073"
"5318","31.87200","2.65627","0.00055"
"5334","31.96800","2.66422","0.00092"
"5350","32.06400","2.67217","0.00042"
"5366","32.16000","2.68019","0.00024"
"5382","32.25600","2.68808","0.00067"
"5398","32.35200","2.69621","0.00089"
"5414","32.44800","2.70428","0.00061"
"5430","32.54400","2.71223","0.00055"
"5446","32.64000","2.72024","0.00016"
"5462","32.73600","2.72820","0.00073"
"5478","32.83200","2.73615","0.00040"
"5494","32.92800","2.74422","0.00051"
"5510","33.02400","2.75229","0.00036"
"5526","33.12000","2.76024","0.00056"
"5542","33.21600","2.76820","0.00035"
"5558","33.31200","2.77615","0.00040"
"5574","33.40800","2.78422","0.00032"
"5590","33.50400","2.79223","0.00033"
"5606","33.60000","2.80024","0.00058"
"5622","33.69600","2.80819","0.00052"
"5638","33.79200","2.81621","0.00107"
"5654","33.88800","2.82416","0.00048"
"5670","33.98400","2.83217","0.00067"
"5686","34.08000","2.84024","0.00056"
"5702","34.17600","2.84819","0.00058"
"5718","34.27200","2.85621","0.00064"
"5734","34.36800","2.86416","0.00053"
"5750","34.46400","2.87217","0.00046"
"5766","34.56000","2.88018","0.00031"
"5782","34.65600","2.88819","0.00050"
"5798","34.75200","2.89626","0.00044"
"5814","34.84800","2.90416","0.00033"
"5830","34.94400","2.91211","0.00049"
"5846","35.04000","2.92024","0.00037"
"5862","35.13600","2.92825","0.00079"
"5878","35.23200","2.93620","0.00070"
"5894","35.32800","2.94422","0.00032"
"5910","35.42400","2.95217","0.00038"
"5926","35.52000","2.96018","0.00087"
"5942","35.61600","2.96825","0.00079"
"5958","35.71200","2.97620","0.00071"
"5974","35.80800","2.98422","0.00095"
"5990","35.90400","2.99229","-0.00010"
"6006","36.00000","3.00018","0.00050"
"6022","36.09600","3.00813","0.00047"
"6038","36.19200","3.01626","0.00070"
"6054","36.28800","3.02421","0.00053"
"6070","36.38400","3.03217","0.00099"
"6086","36.48000","3.04018","0.00034"
"6102","36.57600","3.04813","0.00089"
"6118","36.67200","3.05620","0.00067"
"6134","36.76800","3.06421","0.00063"
"6150","36.86400","3.07223","0.00087"
"6166","36.96000","3.08018","0.00031"
"6182","37.05600","3.08819","0.00085"
"6198","37.15200","3.09620","0.00087"
"6214","37.24800","3.10421","0.00107"
"6230","37.34400","3.11222","0.00078"
"6246","37.44000","3.12024","0.00104"
"6262","37.53600","3.12819","0.00059"
"6278","37.63200","3.13620","0.00108"
"6294","37.72800","3.14421","0.00089"
"6310","37.82400","3.15228","0.00096"
"6326","37.92000","3.16024","0.00093"
"6342","38.01600","3.16825","0.00096"
"6358","38.11200","3.17626","0.00112"
"6374","38.20800","3.18421","0.00097"
"6390","38.30400","3.19222","0.00092"
"6406","38.40000","3.20017","0.00079"
"6422","38.49600","3.20819","0.00112"
"6438","38.59200","3.21620","0.00066"
"6454","38.68800","3.22415","0.00071"
"6470","38.78400","3.23216","0.00107"
"6486","38.88000","3.24023","0.00087"
"6502","38.97600","3.24825","0.00068"
"6518","39.07200","3.25620","0.00096"
"6534","39.16800","3.26415","0.00084"
"6550","39.26400","3.27216","0.00087"
"6566","39.36000","3.28017","0.00119"
"6582","39.45600","3.28819","0.00082"
"6598","39.55200","3.29626","0.00085"
"6614","39.64800","3.30421","0.00096"
"6630","39.74400","3.31216","0.00051"
"6646","39.84000","3.32017","0.00120"
"6662","39.93600","3.32824","0.00069"
"6678","40.03200","3.33626","0.00112"
"6694","40.12800","3.34421","0.00110"
"6710","40.22400","3.35222","0.00108"
"6726","40.32000","3.36017","0.00075"
"6742","40.41600","3.36818","0.00083"
"6758","40.51200","3.37626","0.00118"
"6774","40.60800","3.38427","0.00083"
"6790","40.70400","3.39216","0.00105"
"6806","40.80000","3.40011","0.00076"
"6822","40.89600","3.40818","0.00070"
"6838","40.99200","3.41619","0.00092"
"6854","41.08800","3.42421","0.00156"
"6870","41.18400","3.43228","0.00148"
"6886","41.28000","3.44017","0.00120"
"6902","41.37600","3.44812","0.00104"
"6918","41.47200","3.45619","0.00150"
"6934","41.56800","3.46421","0.00103"
"6950","41.66400","3.47216","0.00147"
"6966","41.76000","3.48017","0.00133"
"6982","41.85600","3.48818","0.00082"
"6998","41.95200","3.49613","0.00070"
"7014","42.04800","3.50420","0.00050"
"7030","42.14400","3.51222","0.00092"
"7046","42.24000","3.52023","0.00097"
"7062","42.33600","3.52824","0.00131"
"7078","42.43200","3.53619","0.00098"
"7094","42.52800","3.54414","0.00107"
"7110","42.62400","3.55228","0.00087"
"7126","42.72000","3.56017","0.00108"
"7142","42.81600","3.56818","0.00093"
"7158","42.91200","3.57619","0.00109"
"7174","43.00800","3.58414","0.00089"
"7190","43.10400","3.59222","0.00097"
"7206","43.20000","3.60023","0.00088"
"7222","43.29600","3.60824","0.00129"
"7238","43.39200","3.61619","0.00119"
"7254","43.48800","3.62420","0.00118"
"7270","43.58400","3.63209","0.00117"
"7286","43.68000","3.64029","0.00128"
"7302","43.77600","3.64824","0.00133"
"7318","43.87200","3.65625","0.00082"
"7334","43.96800","3.66420","0.00124"
"7350","44.06400","3.67221","0.00095"
"7366","44.16000","3.68017","0.00136"
"7382","44.25600","3.68824","0.00114"
"7398","44.35200","3.69625","0.00134"
"7414","44.44800","3.70420","0.00143"
"7430","44.54400","3.71221","0.00115"
"7446","44.64000","3.72016","0.00109"
"7462","44.73600","3.72818","0.00148"
"7478","44.83200","3.73619","0.00148"
"7494","44.92800","3.74426","0.00143"
"7510","45.02400","3.75215","0.00113"
"7526","45.12000","3.76016","0.00127"
"7542","45.21600","3.76824","0.00122"
"7558","45.31200","3.77619","0.00131"
"7574","45.40800","3.78426","0.00143"
"7590","45.50400","3.79221","0.00132"
"7606","45.60000","3.80022","0.00146"
"7622","45.69600","3.80817","0.00154"
"7638","45.79200","3.81619","0.00142"
"7654","45.88800","3.82420","0.00135"
"7670","45.98400","3.83221","0.00163"
"7686","46.08000","3.84022","0.00118"
"7702","46.17600","3.84817","0.00136"
"7718","46.27200","3.85619","0.00155"
"7734","46.36800","3.86420","0.00155"
"7750","46.46400","3.87221","0.00104"
"7766","46.56000","3.88022","0.00123"
"7782","46.65600","3.88823","0.00051"
"7798","46.75200","3.89613","0.00080"
"7814","46.84800","3.90420","0.00140"
"7830","46.94400","3.91221","0.00125"
"7846","47.04000","3.92016","0.00112"
"7862","47.13600","3.92817","0.00104"
"7878","47.23200","3.93612","0.00098"
"7894","47.32800","3.94414","0.00093"
"7910","47.42400","3.95221","0.00085"
"7926","47.52000","3.96022","0.00102"
"7942","47.61600","3.96823","0.00127"
"7958","47.71200","3.97618","0.00083"
"7974","47.80800","3.98420","0.00106"
"7990","47.90400","3.99215","0.00093"
"8006","48.00000","4.00022","0.00125"
"8022","48.09600","4.00823","0.00116"
"8038","48.19200","4.01618","0.00118"
"8054","48.28800","4.02413","0.00120"
"8070","48.38400","4.03221","0.00104"
"8086","48.48000","4.04022","0.00126"
"8102","48.57600","4.04823","0.00137"
"8118","48.67200","4.05630","0.00093"
"8134","48.76800","4.06419","0.00141"
"8150","48.86400","4.07215","0.00114"
"8166","48.96000","4.08022","0.00136"
"8182","49.05600","4.08823","0.00080"
"8198","49.15200","4.09618","0.00123"
"8214","49.24800","4.10419","0.00146"
"8230","49.34400","4.11214","0.00116"
"8246","49.44000","4.12016","0.00112"
"8262","49.53600","4.12817","0.00131"
"8278","49.63200","4.13624","0.00155"
"8294","49.72800","4.14419","0.00116"
"8310","49.82400","4.15226","0.00124"
"8326","49.92000","4.16016","0.00133"
"8342","50.01600","4.16817","0.00136"
"8358","50.11200","4.17624","0.00082"
"8374","50.20800","4.18425","0.00106"
"8390","50.30400","4.19226","0.00126"
"8406","50.40000","4.20021","0.00126"
"8422","50.49600","4.20817","0.00089"
"8438","50.59200","4.21618","0.00130"
"8454","50.68800","4.22425","0.00150"
"8470","50.78400","4.23226","0.00127"
"8486","50.88000","4.24027","0.00138"
"8502","50.97600","4.24817","0.00144"
"8518","51.07200","4.25618","0.00143"
"8534","51.16800","4.26419","0.00138"
"8550","51.26400","4.27220","0.00167"
"8566","51.36000","4.28021","0.00161"
"8582","51.45600","4.28823","0.00124"
"8598","51.55200","4.29618","0.00146"
"8614","51.64800","4.30419","0.00163"
"8630","51.74400","4.31220","0.00137"
"8646","51.84000","4.32021","0.00142"
"8662","51.93600","4.32828","0.00149"
"8678","52.03200","4.33618","0.00165"
"8694","52.12800","4.34419","0.00160"
"8710","52.22400","4.35220","0.00125"
"8726","52.32000","4.36021","0.00164"
"8742","52.41600","4.36822","0.00154"
"8758","52.51200","4.37624","0.00142"
"8774","52.60800","4.38419","0.00146"
"8790","52.70400","4.39220","0.00139"
"8806","52.80000","4.40021","0.00154"
"8822","52.89600","4.40816","0.00170"
"8838","52.99200","4.41623","0.00155"
"8854","53.08800","4.42425","0.00125"
"8870","53.18400","4.43214","0.00193"
"8886","53.28000","4.44021","0.00145"
"8902","53.37600","4.44822","0.00134"
"8918","53.47200","4.45617","0.00119"
"8934","53.56800","4.46425","0.00185"
"8950","53.66400","4.47220","0.00157"
"8966","53.76000","4.48009","0.00131"
"8982","53.85600","4.48822","0.00161"
"8998","53.95200","4.49629","0.00142"
"9014","54.04800","4.50418","0.00159"
"9030","54.14400","4.51220","0.00168"
"9046","54.24000","4.52021","0.00178"
"9062","54.33600","4.52816","0.00171"
"9078","54.43200","4.53617","0.00162"
"9094","54.52800","4.54418","0.00210"
"9110","54.62400","4.55226","0.00189"
"9126","54.72000","4.56021","0.00174"
"9142","54.81600","4.56816","0.00168"
"9158","54.91200","4.57617","0.00156"
"9174","55.00800","4.58424","0.00166"
"9190","55.10400","4.59219","0.00178"
"9206","55.20000","4.60021","0.00179"
"9222","55.29600","4.60816","0.00148"
"9238","55.39200","4.61617","0.00175"
"9254","55.48800","4.62418","0.00188"
"9270","55.58400","4.63225","0.00153"
"9286","55.68000","4.64021","0.00198"
"9302","55.77600","4.64816","0.00211"
"9318","55.87200","4.65617","0.00205"
"9334","55.96800","4.66418","0.00193"
"9350","56.06400","4.67219","0.00207"
"9366","56.16000","4.68021","0.00220"
"9382","56.25600","4.68822","0.00138"
"9398","56.35200","4.69611","0.00143"
"9414","56.44800","4.70418","0.00142"
"9430","56.54400","4.71225","0.00169"
"9446","56.64000","4.72020","0.00125"
"9462","56.73600","4.72822","0.00161"
"9478","56.83200","4.73629","0.00177"
"9494","56.92800","4.74412","0.00161"
"9510","57.02400","4.75213","0.00151"
"9526","57.12000","4.76026","0.00151"
"9542","57.21600","4.76822","0.00152"
"9558","57.31200","4.77623","0.00173"
"9574","57.40800","4.78424","0.00139"
"9590","57.50400","4.79213","0.00171"
"9606","57.60000","4.80014","0.00182"
"9622","57.69600","4.80827","0.00192"
"9638","57.79200","4.81617","0.00192"
"9654","57.88800","4.82418","0.00144"
"9670","57.98400","4.83219","0.00141"
"9686","58.08000","4.84014","0.00144"
"9702","58.17600","4.84821","0.00162"
"9718","58.27200","4.85629","0.00168"
"9734","58.36800","4.86424","0.00136"
"9750","58.46400","4.87219","0.00123"
"9766","58.56000","4.88020","0.00153"
"9782","58.65600","4.88815","0.00167"
"9798","58.75200","4.89622","0.00150"
"9814","58.84800","4.90424","0.00166"
"9830","58.94400","4.91225","0.00161"
"9846","59.04000","4.92020","0.00165"
"9862","59.13600","4.92815","0.00151"
"9878","59.23200","4.93616","0.00153"
"9894","59.32800","4.94424","0.00204"
"9910","59.42400","4.95225","0.00172"
"9926","59.52000","4.96020","0.00195"
"9942","59.61600","4.96815","0.00185"
"9958","59.71200","4.97622","0.00216"
"9974","59.80800","4.98418","0.00178"
"9990","59.90400","4.99219","0.00161"
"10006","60.00000","5.00026","0.00170"
"10022","60.09600","5.00815","0.00160"
"10038","60.19200","5.01616","0.00169"
"10054","60.28800","5.02417","0.00192"
"10070","60.38400","5.03219","0.00156"
"10086","60.48000","5.04020","0.00183"
"10102","60.57600","5.04827","0.00211"
"10118","60.67200","5.05616","0.00129"
"10134","60.76800","5.06411","0.00209"
"10150","60.86400","5.07224","0.00183"
"10166","60.96000","5.08020","0.00173"
"10182","61.05600","5.08821","0.00195"
"10198","61.15200","5.09622","0.00198"
"10214","61.24800","5.10417","0.00203"
"10230","61.34400","5.11218","0.00180"
"10246","61.44000","5.12020","0.00163"
"10262","61.53600","5.12821","0.00215"
"10278","61.63200","5.13622","0.00202"
"10294","61.72800","5.14423","0.00199"
"10310","61.82400","5.15218","0.00201"
"10326","61.92000","5.16014","0.00245"
"10342","62.01600","5.16821","0.00151"
"10358","62.11200","5.17616","0.00151"
"10374","62.20800","5.18417","0.00125"
"10390","62.30400","5.19212","0.00129"
"10406","62.40000","5.20014","0.00101"
"10422","62.49600","5.20821","0.00124"
"10438","62.59200","5.21622","0.00113"
"10454","62.68800","5.22423","0.00080"
"10470","62.78400","5.23224","0.00130"
"10486","62.88000","5.24019","0.00111"
"10502","62.97600","5.24815","0.00164"
"10518","63.07200","5.25622","0.00138"
"10534","63.16800","5.26423","0.00130"
"10550","63.26400","5.27224","0.00126"
"10566","63.36000","5.28019","0.00114"
"10582","63.45600","5.28821","0.00169"
"10598","63.55200","5.29622","0.00146"
"10614","63.64800","5.30423","0.00178"
"10630","63.74400","5.31224","0.00152"
"10646","63.84000","5.32019","0.00154"
"10662","63.93600","5.32814","0.00141"
"10678","64.03200","5.33616","0.00178"
"10694","64.12800","5.34417","0.00139"
"10710","64.22400","5.35218","0.00174"
"10726","64.32000","5.36025","0.00172"
"10742","64.41600","5.36820","0.00154"
"10758","64.51200","5.37616","0.00164"
"10774","64.60800","5.38423","0.00212"
"10790","64.70400","5.39224","0.00182"
"10806","64.80000","5.40019","0.00170"
"10822","64.89600","5.40826","0.00175"
"10838","64.99200","5.41621","0.00195"
"10854","65.08800","5.42417","0.00180"
"10870","65.18400","5.43224","0.00182"
"10886","65.28000","5.44025","0.00148"
"10902","65.37600","5.44820","0.00205"
"10918","65.47200","5.45621","0.00190"
"10934","65.56800","5.46417","0.00199"
"10950","65.66400","5.47218","0.00205"
"10966","65.76000","5.48025","0.00178"
"10982","65.85600","5.48820","0.00187"
"10998","65.95200","5.49621","0.00223"
"11014","66.04800","5.50416","0.00213"
"11030","66.14400","5.51212","0.00168"
"11046","66.24000","5.52019","0.00206"
"11062","66.33600","5.52826","0.00217"
"11078","66.43200","5.53621","0.00207"
"11094","66.52800","5.54422","0.00175"
"11110","66.62400","5.55218","0.00230"
"11126","66.72000","5.56019","0.00189"
"11142","66.81600","5.56820","0.00254"
"11158","66.91200","5.57621","0.00171"
"11174","67.00800","5.58422","0.00173"
"11190","67.10400","5.59218","0.00200"
"11206","67.20000","5.60013","0.00184"
"11222","67.29600","5.60820","0.00239"
"11238","67.39200","5.61621","0.00191"
"11254","67.48800","5.62422","0.00222"
"11270","67.58400","5.63223","0.00211"
"11286","67.68000","5.64019","0.00212"
"11302","67.77600","5.64814","0.00177"
"11318","67.87200","5.65621","0.00240"
"11334","67.96800","5.66422","0.00195"
"11350","68.06400","5.67223","0.00228"
"11366","68.16000","5.68024","0.00225"
"11382","68.25600","5.68820","0.00211"
"11398","68.35200","5.69615","0.00195"
"11414","68.44800","5.70422","0.00162"
"11430","68.54400","5.71223","0.00212"
"11446","68.64000","5.72024","0.00205"
"11462","68.73600","5.72820","0.00212"
"11478","68.83200","5.73615","0.00211"
"11494","68.92800","5.74422","0.00183"
"11510","69.02400","5.75229","0.00233"
"11526","69.12000","5.76018","0.00199"
"11542","69.21600","5.76820","0.00221"
"11558","69.31200","5.77621","0.00226"
"11574","69.40800","5.78416","0.00182"
"11590","69.50400","5.79217","0.00234"
"11606","69.60000","5.80024","0.00278"
"11622","69.69600","5.80819","0.00199"
"11638","69.79200","5.81621","0.00206"
"11654","69.88800","5.82416","0.00207"
"11670","69.98400","5.83217","0.00243"
"11686","70.08000","5.84024","0.00240"
"11702","70.17600","5.84819","0.00196"
"11718","70.27200","5.85627","0.00231"
"11734","70.36800","5.86416","0.00213"
"11750","70.46400","5.87211","0.00263"
"11766","70.56000","5.88018","0.00238"
"11782","70.65600","5.88819","0.00242"
"11798","70.75200","5.89626","0.00225"
"11814","70.84800","5.90422","0.00250"
"11830","70.94400","5.91217","0.00244"
"11846","71.04000","5.92024","0.00257"
"11862","71.13600","5.92825","0.00242"
"11878","71.23200","5.93620","0.00239"
"11894","71.32800","5.94428","0.00235"
"11910","71.42400","5.95223","0.00268"
"11926","71.52000","5.96018","0.00270"
"11942","71.61600","5.96819","0.00246"
"11958","71.71200","5.97620","0.00246"
"11974","71.80800","5.98422","0.00230"
"11990","71.90400","5.99223","0.00290"
"12006","72.00000","6.00018","0.00252"
"12022","72.09600","6.00819","0.00239"
"12038","72.19200","6.01620","0.00241"
"12054","72.28800","6.02415","0.00240"
"12070","72.38400","6.03223","0.00256"
"12086","72.48000","6.04024","0.00247"
"12102","72.57600","6.04813","0.00255"
"12118","72.67200","6.05620","0.00235"
"12134","72.76800","6.06427","0.00253"
"12150","72.86400","6.07217","0.00228"
"12166","72.96000","6.08018","0.00203"
"12182","73.05600","6.08819","0.00238"
"12198","73.15200","6.09614","0.00252"
"12214","73.24800","6.10421","0.00224"
"12230","73.34400","6.11228","0.00246"
"12246","73.44000","6.12018","0.00236"
"12262","73.53600","6.12819","0.00246"
"12278","73.63200","6.13620","0.00222"
"12294","73.72800","6.14415","0.00182"
"12310","73.82400","6.15216","0.00216"
"12326","73.92000","6.16024","0.00193"
"12342","74.01600","6.16819","0.00205"
"12358","74.11200","6.17620","0.00214"
"12374","74.20800","6.18415","0.00172"
"12390","74.30400","6.19222","0.00221"
"12406","74.40000","6.20029","0.00217"
"12422","74.49600","6.20825","0.00185"
"12438","74.59200","6.21620","0.00197"
"12454","74.68800","6.22415","0.00194"
"12470","74.78400","6.23222","0.00193"
"12486","74.88000","6.24023","0.00206"
"12502","74.97600","6.24819","0.00232"
"12518","75.07200","6.25620","0.00241"
"12534","75.16800","6.26421","0.00205"
"12550","75.26400","6.27216","0.00201"
"12566","75.36000","6.28017","0.00209"
"12582","75.45600","6.28824","0.00219"
"12598","75.55200","6.29626","0.00217"
"12614","75.64800","6.30421","0.00214"
"12630","75.74400","6.31222","0.00251"
"12646","75.84000","6.32017","0.00250"
"12662","75.93600","6.32824","0.00206"
"12678","76.03200","6.33626","0.00189"
"12694","76.12800","6.34427","0.00175"
"12710","76.22400","6.35228","0.00214"
"12726","76.32000","6.36017","0.00237"
"12742","76.41600","6.36812","0.00203"
"12758","76.51200","6.37625","0.00216"
"12774","76.60800","6.38421","0.00194"
"12790","76.70400","6.39222","0.00230"
"12806","76.80000","6.40023","0.00274"
"12822","76.89600","6.40812","0.00203"
"12838","76.99200","6.41613","0.00203"
"12854","77.08800","6.42427","0.00223"
"12870","77.18400","6.43222","0.00224"
"12886","77.28000","6.44017","0.00195"
"12902","77.37600","6.44818","0.00217"
"12918","77.47200","6.45613","0.00229"
"12934","77.56800","6.46415","0.00270"
"12950","77.66400","6.47222","0.00238"
"12966","77.76000","6.48023","0.00241"
"12982","77.85600","6.48818","0.00221"
"12998","77.95200","6.49613","0.00239"
"13014","78.04800","6.50420","0.00256"
"13030","78.14400","6.51222","0.00237"
"13046","78.24000","6.52023","0.00228"
"13062","78.33600","6.52824","0.00274"
"13078","78.43200","6.53619","0.00258"
"13094","78.52800","6.54420","0.00226"
"13110","78.62400","6.55222","0.00272"
"13126","78.72000","6.56023","0.00218"
"13142","78.81600","6.56824","0.00254"
"13158","78.91200","6.57619","0.00214"
"13174","79.00800","6.58420","0.00236"
"13190","79.10400","6.59215","0.00251"
"13206","79.20000","6.60017","0.00255"
"13222","79.29600","6.60818","0.00281"
"13238","79.39200","6.61619","0.00266"
"13254","79.48800","6.62414","0.00290"
"13270","79.58400","6.63215","0.00257"
"13286","79.68000","6.64017","0.00302"
"13302","79.77600","6.64824","0.00252"
"13318","79.87200","6.65625","0.00288"
"13334","79.96800","6.66420","0.00266"
"13350","80.06400","6.67221","0.00260"
"13366","80.16000","6.68010","0.00251"
"13382","80.25600","6.68818","0.00295"
"13398","80.35200","6.69625","0.00258"
"13414","80.44800","6.70420","0.00275"
"13430","80.54400","6.71215","0.00229"
"13446","80.64000","6.72016","0.00209"
"13462","80.73600","6.72818","0.00213"
"13478","80.83200","6.73625","0.00215"
"13494","80.92800","6.74426","0.00208"
"13510","81.02400","6.75221","0.00212"
"13526","81.12000","6.76022","0.00202"
"13542","81.21600","6.76824","0.00239"
"13558","81.31200","6.77619","0.00223"
"13574","81.40800","6.78426","0.00273"
"13590","81.50400","6.79227","0.00259"
"13606","81.60000","6.80022","0.00264"
"13622","81.69600","6.80817","0.00249"
"13638","81.79200","6.81619","0.00283"
"13654","81.88800","6.82420","0.00258"
"13670","81.98400","6.83221","0.00257"
"13686","82.08000","6.84022","0.00304"
"13702","82.17600","6.84817","0.00261"
"13718","82.27200","6.85619","0.00253"
"13734","82.36800","6.86426","0.00300"
"13750","82.46400","6.87221","0.00268"
"13766","82.56000","6.88022","0.00268"
"13782","82.65600","6.88823","0.00272"
"13798","82.75200","6.89612","0.00280"
"13814","82.84800","6.90420","0.00262"
"13830","82.94400","6.91221","0.00297"
"13846","83.04000","6.92022","0.00277"
"13862","83.13600","6.92823","0.00269"
"13878","83.23200","6.93618","0.00313"
"13894","83.32800","6.94420","0.00286"
"13910","83.42400","6.95221","0.00326"
"13926","83.52000","6.96022","0.00349"
"13942","83.61600","6.96823","0.00331"
"13958","83.71200","6.97624","0.00272"
"13974","83.80800","6.98420","0.00324"
"13990","83.90400","6.99215","0.00271"
"14006","84.00000","7.00022","0.00274"
"14022","84.09600","7.00829","0.00327"
"14038","84.19200","7.01624","0.00286"
"14054","84.28800","7.02419","0.00342"
"14070","84.38400","7.03215","0.00346"
"14086","84.48000","7.04016","0.00322"
"14102","84.57600","7.04823","0.00370"
"14118","84.67200","7.05624","0.00366"
"14134","84.76800","7.06419","0.00378"
"14150","84.86400","7.07214","0.00328"
"14166","84.96000","7.08016","0.00375"
"14182","85.05600","7.08811","0.00371"
"14198","85.15200","7.09624","0.00380"
"14214","85.24800","7.10425","0.00391"
"14230","85.34400","7.11214","0.00385"
"14246","85.44000","7.12016","0.00420"
"14262","85.53600","7.12817","0.00447"
"14278","85.63200","7.13618","0.00406"
"14294","85.72800","7.14419","0.00398"
"14310","85.82400","7.15226","0.00428"
"14326","85.92000","7.16016","0.00463"
"14342","86.01600","7.16817","0.00481"
"14358","86.11200","7.17624","0.00432"
"14374","86.20800","7.18419","0.00463"
"14390","86.30400","7.19220","0.00446"
"14406","86.40000","7.20027","0.00522"
"14422","86.49600","7.20817","0.00448"
"14438","86.59200","7.21612","0.00510"
"14454","86.68800","7.22425","0.00522"
"14470","86.78400","7.23220","0.00509"
"14486","86.88000","7.24027","0.00559"
"14502","86.97600","7.24823","0.00544"
"14518","87.07200","7.25618","0.00546"
"14534","87.16800","7.26419","0.00558"
"14550","87.26400","7.27220","0.00539"
"14566","87.36000","7.28021","0.00551"
"14582","87.45600","7.28828","0.00553"
"14598","87.55200","7.29624","0.00558"
"14614","87.64800","7.30419","0.00601"
"14630","87.74400","7.31220","0.00655"
"14646","87.84000","7.32021","0.00585"
"14662","87.93600","7.32822","0.00584"
"14678","88.03200","7.33624","0.00622"
"14694","88.12800","7.34419","0.00655"
"14710","88.22400","7.35214","0.00628"
"14726","88.32000","7.36021","0.00703"
"14742","88.41600","7.36828","0.00658"
"14758","88.51200","7.37624","0.00718"
"14774","88.60800","7.38419","0.00684"
"14790","88.70400","7.39220","0.00692"
"14806","88.80000","7.40015","0.00735"
"14822","88.89600","7.40822","0.00728"
"14838","88.99200","7.41623","0.00744"
"14854","89.08800","7.42419","0.00765"
"14870","89.18400","7.43220","0.00785"
"14886","89.28000","7.44021","0.00765"
"14902","89.37600","7.44816","0.00759"
"14918","89.47200","7.45623","0.00776"
"14934","89.56800","7.46425","0.00804"
"14950","89.66400","7.47214","0.00789"
"14966","89.76000","7.48015","0.00823"
"14982","89.85600","7.48816","0.00855"
"14998","89.95200","7.49617","0.00792"
"15014","90.04800","7.50418","0.00855"
"15030","90.14400","7.51220","0.00869"
"15046","90.24000","7.52015","0.00874"
"15062","90.33600","7.52816","0.00863"
"15078","90.43200","7.53617","0.00847"
"15094","90.52800","7.54424","0.00900"
"15110","90.62400","7.55226","0.00917"
"15126","90.72000","7.56021","0.00894"
"15142","90.81600","7.56816","0.00810"
"15158","90.91200","7.57617","0.00773"
"15174","91.00800","7.58418","0.00047"
"15190","91.10400","7.59220","0.00126"
"15206","91.20000","7.60027","0.00291"
"15222","91.29600","7.60816","0.00313"
"15238","91.39200","7.61617","0.00069"
"15254","91.48800","7.62418","0.00032"
"15270","91.58400","7.63219","0.00113"
"15286","91.68000","7.64021","0.00212"
"15302","91.77600","7.64822","0.00173"
"15318","91.87200","7.65623","0.00070"
"15334","91.96800","7.66418","0.00054"
"15350","92.06400","7.67219","0.00156"
"15366","92.16000","7.68026","0.00242"
"15382","92.25600","7.68822","0.00123"
"15398","92.35200","7.69617","0.00039"
"15414","92.44800","7.70418","0.00089"
"15430","92.54400","7.71213","0.00183"
"15446","92.64000","7.72020","0.00189"
"15462","92.73600","7.72822","0.00068"
"15478","92.83200","7.73623","0.00078"
"15494","92.92800","7.74418","0.00220"
"15510","93.02400","7.75213","0.00164"
"15526","93.12000","7.76020","0.00134"
"15542","93.21600","7.76822","0.00092"
"15558","93.31200","7.77629","0.00132"
"15574","93.40800","7.78424","0.00209"
"15590","93.50400","7.79219","0.00142"
"15606","93.60000","7.80014","0.00102"
"15622","93.69600","7.80821","0.00129"
"15638","93.79200","7.81623","0.00224"
"15654","93.88800","7.82424","0.00214"
"15670","93.98400","7.83225","0.00131"
"15686","94.08000","7.84014","0.00152"
"15702","94.17600","7.84821","0.00220"
"15718","94.27200","7.85622","0.00184"
"15734","94.36800","7.86424","0.00157"
"15750","94.46400","7.87225","0.00158"
"15766","94.56000","7.88020","0.00186"
"15782","94.65600","7.88815","0.00190"
"15798","94.75200","7.89616","0.00166"
"15814","94.84800","7.90424","0.00115"
"15830","94.94400","7.91225","0.00130"
"15846","95.04000","7.92020","0.00215"
"15862","95.13600","7.92815","0.00186"
"15878","95.23200","7.93622","0.00177"
"15894","95.32800","7.94418","0.00163"
"15910","95.42400","7.95225","0.00198"
"15926","95.52000","7.96020","0.00191"
"15942","95.61600","7.96821","0.00220"
"15958","95.71200","7.97616","0.00180"
"15974","95.80800","7.98417","0.00204"
"15990","95.90400","7.99219","0.00175"
"16006","96.00000","8.00026","0.00173"
"16022","96.09600","8.00821","0.00160"
"16038","96.19200","8.01616","0.00161"
"16054","96.28800","8.02417","0.00203"
"16070","96.38400","8.03219","0.00176"
"16086","96.48000","8.04020","0.00191"
"16102","96.57600","8.04827","0.00211"
"16118","96.67200","8.05622","0.00171"
"16134","96.76800","8.06417","0.00222"
"16150","96.86400","8.07224","0.00145"
"16166","96.96000","8.08020","0.00216"
"16182","97.05600","8.08821","0.00229"
"16198","97.15200","8.09622","0.00148"
"16214","97.24800","8.10417","0.00198"
"16230","97.34400","8.11218","0.00229"
"16246","97.44000","8.12020","0.00221"
"16262","97.53600","8.12821","0.00206"
"16278","97.63200","8.13622","0.00189"
"16294","97.72800","8.14423","0.00208"
"16310","97.82400","8.15212","0.00230"
"16326","97.92000","8.16013","0.00211"
"16342","98.01600","8.16821","0.00224"
"16358","98.11200","8.17616","0.00231"
"16374","98.20800","8.18417","0.00205"
"16390","98.30400","8.19218","0.00233"
"16406","98.40000","8.20019","0.00263"
"16422","98.49600","8.20821","0.00210"
"16438","98.59200","8.21622","0.00240"
"16454","98.68800","8.22423","0.00257"
"16470","98.78400","8.23218","0.00242"
"16486","98.88000","8.24019","0.00231"
"16502","98.97600","8.24815","0.00204"
"16518","99.07200","8.25616","0.00247"
"16534","99.16800","8.26423","0.00232"
"16550","99.26400","8.27218","0.00241"
"16566","99.36000","8.28013","0.00238"
"16582","99.45600","8.28820","0.00248"
"16598","99.55200","8.29616","0.00232"
"16614","99.64800","8.30423","0.00287"
"16630","99.74400","8.31224","0.00258"
"16646","99.84000","8.32025","0.00253"
"16662","99.93600","8.32820","0.00287"
"16678","100.03200","8.33622","0.00253"
"16694","100.12800","8.34417","0.00284"
"16710","100.22400","8.35224","0.00275"
"16726","100.32000","8.36025","0.00284"
"16742","100.41600","8.36820","0.00291"
"16758","100.51200","8.37615","0.00278"
"16774","100.60800","8.38417","0.00316"
"16790","100.70400","8.39218","0.00318"
"16806","100.80000","8.40019","0.00279"
"16822","100.89600","8.40826","0.00306"
"16838","100.99200","8.41615","0.00278"
"16854","101.08800","8.42417","0.00347"
"16870","101.18400","8.43224","0.00292"
"16886","101.28000","8.44019","0.00289"
"16902","101.37600","8.44820","0.00273"
"16918","101.47200","8.45627","0.00294"
"16934","101.56800","8.46416","0.00335"
"16950","101.66400","8.47212","0.00286"
"16966","101.76000","8.48025","0.00271"
"16982","101.85600","8.48820","0.00320"
"16998","101.95200","8.49627","0.00301"
"17014","102.04800","8.50422","0.00316"
"17030","102.14400","8.51218","0.00323"
"17046","102.24000","8.52013","0.00288"
"17062","102.33600","8.52826","0.00318"
"17078","102.43200","8.53621","0.00329"
"17094","102.52800","8.54422","0.00351"
"17110","102.62400","8.55223","0.00380"
"17126","102.72000","8.56013","0.00371"
"17142","102.81600","8.56820","0.00395"
"17158","102.91200","8.57627","0.00369"
"17174","103.00800","8.58422","0.00371"
"17190","103.10400","8.59217","0.00350"
"17206","103.20000","8.60019","0.00387"
"17222","103.29600","8.60814","0.00333"
"17238","103.39200","8.61615","0.00372"
"17254","103.48800","8.62422","0.00362"
"17270","103.58400","8.63223","0.00391"
"17286","103.68000","8.64019","0.00392"
"17302","103.77600","8.64814","0.00379"
"17318","103.87200","8.65621","0.00383"
"17334","103.96800","8.66422","0.00416"
"17350","104.06400","8.67217","0.00399"
"17366","104.16000","8.68024","0.00434"
"17382","104.25600","8.68820","0.00404"
"17398","104.35200","8.69621","0.00394"
"17414","104.44800","8.70416","0.00445"
"17430","104.54400","8.71223","0.00450"
"17446","104.64000","8.72024","0.00415"
"17462","104.73600","8.72820","0.00465"
"17478","104.83200","8.73615","0.00476"
"17494","104.92800","8.74422","0.00468"
"17510","105.02400","8.75217","0.00478"
"17526","105.12000","8.76018","0.00441"
"17542","105.21600","8.76826","0.00455"
"17558","105.31200","8.77621","0.00493"
"17574","105.40800","8.78410","0.00458"
"17590","105.50400","8.79217","0.00533"
"17606","105.60000","8.80024","0.00530"
"17622","105.69600","8.80813","0.00513"
"17638","105.79200","8.81621","0.00516"
"17654","105.88800","8.82416","0.00521"
"17670","105.98400","8.83211","0.00560"
"17686","106.08000","8.84018","0.00524"
"17702","106.17600","8.84819","0.00521"
"17718","106.27200","8.85620","0.00571"
"17734","106.36800","8.86416","0.00601"
"17750","106.46400","8.87217","0.00612"
"17766","106.56000","8.88018","0.00619"
"17782","106.65600","8.88819","0.00632"
"17798","106.75200","8.89620","0.00614"
"17814","106.84800","8.90422","0.00652"
"17830","106.94400","8.91223","0.00637"
"17846","107.04000","8.92018","0.00673"
"17862","107.13600","8.92819","0.00681"
"17878","107.23200","8.93626","0.00647"
"17894","107.32800","8.94421","0.00703"
"17910","107.42400","8.95217","0.00684"
"17926","107.52000","8.96018","0.00712"
"17942","107.61600","8.96819","0.00730"
"17958","107.71200","8.97626","0.00750"
"17974","107.80800","8.98421","0.00779"
"17990","107.90400","8.99223","0.00781"
"18006","108.00000","9.00018","0.00776"
"18022","108.09600","9.00819","0.00772"
"18038","108.19200","9.01620","0.00759"
"18054","108.28800","9.02421","0.00792"
"18070","108.38400","9.03223","0.00775"
"18086","108.48000","9.04024","0.00800"
"18102","108.57600","9.04813","0.00730"
"18118","108.67200","9.05614","0.00723"
"18134","108.76800","9.06421","0.00733"
"18150","108.86400","9.07222","0.00745"
"18166","108.96000","9.08024","0.00733"
"18182","109.05600","9.08825","0.00707"
"18198","109.15200","9.09614","0.00752"
"18214","109.24800","9.10421","0.00788"
"18230","109.34400","9.11228","0.00782"
"18246","109.44000","9.12018","0.00807"
"18262","109.53600","9.12825","0.00815"
"18278","109.63200","9.13620","0.00819"
"18294","109.72800","9.14415","0.00844"
"18310","109.82400","9.15222","0.00873"
"18326","109.92000","9.16029","0.00889"
"18342","110.01600","9.16825","0.00906"
"18358","110.11200","9.17626","0.00896"
"18374","110.20800","9.18421","0.00905"
"18390","110.30400","9.19216","0.00919"
"18406","110.40000","9.20023","0.00950"
"18422","110.49600","9.20819","0.00938"
"18438","110.59200","9.21620","0.00949"
"18454","110.68800","9.22421","0.00944"
"18470","110.78400","9.23216","0.01005"
"18486","110.88000","9.24017","0.00989"
"18502","110.97600","9.24824","0.01056"
"18518","111.07200","9.25626","0.01094"
"18534","111.16800","9.26421","0.01130"
"18550","111.26400","9.27216","0.01125"
"18566","111.36000","9.28017","0.01126"
"18582","111.45600","9.28818","0.01116"
"18598","111.55200","9.29620","0.01167"
"18614","111.64800","9.30421","0.01151"
"18630","111.74400","9.31216","0.01194"
"18646","111.84000","9.32017","0.01173"
"18662","111.93600","9.32818","0.01208"
"18678","112.03200","9.33619","0.01251"
"18694","112.12800","9.34421","0.01238"
"18710","112.22400","9.35222","0.01327"
"18726","112.32000","9.36017","0.01342"
"18742","112.41600","9.36818","0.01291"
"18758","112.51200","9.37619","0.01353"
"18774","112.60800","9.38421","0.01405"
"18790","112.70400","9.39222","0.01438"
"18806","112.80000","9.40023","0.01409"
"18822","112.89600","9.40818","0.01448"
"18838","112.99200","9.41613","0.01484"
"18854","113.08800","9.42421","0.01428"
"18870","113.18400","9.43222","0.01463"
"18886","113.28000","9.44023","0.01470"
"18902","113.37600","9.44824","0.01487"
"18918","113.47200","9.45613","0.01528"
"18934","113.56800","9.46414","0.01528"
"18950","113.66400","9.47228","0.01544"
"18966","113.76000","9.48017","0.01602"
"18982","113.85600","9.48824","0.01582"
"18998","113.95200","9.49619","0.01590"
"19014","114.04800","9.50414","0.01603"
"19030","114.14400","9.51222","0.01611"
"19046","114.24000","9.52029","0.01717"
"19062","114.33600","9.52824","0.01669"
"19078","114.43200","9.53619","0.01713"
"19094","114.52800","9.54426","0.01748"
"19110","114.62400","9.55216","0.01780"
"19126","114.72000","9.56023","0.01786"
"19142","114.81600","9.56824","0.01805"
"19158","114.91200","9.57619","0.01826"
"19174","115.00800","9.58420","0.01861"
"19190","115.10400","9.59221","0.01880"
"19206","115.20000","9.60017","0.01897"
"19222","115.29600","9.60818","0.01902"
"19238","115.39200","9.61625","0.01916"
"19254","115.48800","9.62414","0.01135"
"19270","115.58400","9.63221","0.01108"
"19286","115.68000","9.64017","0.01170"
"19302","115.77600","9.64818","0.00996"
"19318","115.87200","9.65619","0.01070"
"19334","115.96800","9.66420","0.01140"
"19350","116.06400","9.67221","0.01161"
"19366","116.16000","9.68017","0.01059"
"19382","116.25600","9.68824","0.01040"
"19398","116.35200","9.69619","0.01194"
"19414","116.44800","9.70420","0.01224"
"19430","116.54400","9.71221","0.01262"
"19446","116.64000","9.72016","0.01283"
"19462","116.73600","9.72818","0.01304"
"19478","116.83200","9.73619","0.01298"
"19494","116.92800","9.74420","0.01303"
"19510","117.02400","9.75221","0.01490"
"19526","117.12000","9.76022","0.01520"
"19542","117.21600","9.76818","0.01521"
"19558","117.31200","9.77619","0.01438"
"19574","117.40800","9.78426","0.01449"
"19590","117.50400","9.79221","0.01520"
"19606","117.60000","9.80022","0.01520"
"19622","117.69600","9.80817","0.01623"
"19638","117.79200","9.81613","0.01572"
"19654","117.88800","9.82420","0.01606"
"19670","117.98400","9.83227","0.01652"
"19686","118.08000","9.84022","0.01632"
"19702","118.17600","9.84817","0.01749"
"19718","118.27200","9.85618","0.01880"
"19734","118.36800","9.86414","0.01813"
"19750","118.46400","9.87221","0.01788"
"19766","118.56000","9.88022","0.01879"
"19782","118.65600","9.88823","0.01937"
"19798","118.75200","9.89618","0.01929"
"19814","118.84800","9.90414","0.01913"
"19830","118.94400","9.91221","0.01889"
"19846","119.04000","9.92028","0.01912"
"19862","119.13600","9.92823","0.01956"
"19878","119.23200","9.93624","0.02007"
"19894","119.32800","9.94425","0.02103"
"19910","119.42400","9.95215","0.02089"
"19926","119.52000","9.96022","0.02043"
"19942","119.61600","9.96829","0.02130"
"19958","119.71200","9.97624","0.02162"
"19974","119.80800","9.98419","0.02215"
"19990","119.90400","9.99221","0.02235"
"20006","120.00000","10.00016","0.02180"
"20022","120.09600","10.00817","0.02188"
"20038","120.19200","10.01618","0.02191"
"20054","120.28800","10.02425","0.02166"
"20070","120.38400","10.03221","0.02259"
"20086","120.48000","10.04016","0.02220"
"20102","120.57600","10.04823","0.02208"
"20118","120.67200","10.05618","0.02214"
"20134","120.76800","10.06419","0.02268"
"20150","120.86400","10.07220","0.02366"
"20166","120.96000","10.08016","0.02301"
"20182","121.05600","10.08811","0.02311"
"20198","121.15200","10.09624","0.02367"
"20214","121.24800","10.10425","0.02398"
"20230","121.34400","10.11220","0.02426"
"20246","121.44000","10.12022","0.02425"
"20262","121.53600","10.12817","0.02455"
"20278","121.63200","10.13612","0.02461"
"20294","121.72800","10.14419","0.02508"
"20310","121.82400","10.15220","0.02532"
"20326","121.92000","10.16022","0.02537"
"20342","122.01600","10.16823","0.02504"
"20358","122.11200","10.17618","0.02507"
"20374","122.20800","10.18419","0.02561"
"20390","122.30400","10.19226","0.02631"
"20406","122.40000","10.20027","0.02619"
"20422","122.49600","10.20817","0.02685"
"20438","122.59200","10.21618","0.02696"
"20454","122.68800","10.22419","0.02663"
"20470","122.78400","10.23220","0.02710"
"20486","122.88000","10.24021","0.02780"
"20502","122.97600","10.24823","0.02800"
"20518","123.06800","10.25588","0.02791"