File: Trajectories_together/161226_2Specimen_RawData_6.csv
"","V1","V2","V3"
"1","End date","12/26/2016",""
"2","Specimen label","14CG_13",""
"3","Maximum Load","0.82696","N"
"4","Time","Extension","Load"
"5","(s)","(mm)","(N)"
"6","0.00000","0.00000","0.00009"
"68","0.37200","0.03115","-0.00017"
"130","0.74400","0.06212","0.00053"
"192","1.11600","0.09327","0.00051"
"254","1.48800","0.12424","0.00085"
"316","1.86000","0.15521","0.00068"
"378","2.23200","0.18618","0.00114"
"440","2.60400","0.21722","0.00095"
"502","2.97600","0.24825","0.00111"
"564","3.34800","0.27916","0.00121"
"626","3.72000","0.31025","0.00140"
"688","4.09200","0.34116","0.00125"
"750","4.46400","0.37213","0.00116"
"812","4.83600","0.40322","0.00134"
"874","5.20800","0.43419","0.00173"
"936","5.58000","0.46516","0.00127"
"998","5.95200","0.49619","0.00194"
"1060","6.32400","0.52722","0.00150"
"1122","6.69600","0.55820","0.00130"
"1184","7.06800","0.58917","0.00221"
"1246","7.44000","0.62020","0.00193"
"1308","7.81200","0.65117","0.00171"
"1370","8.18400","0.68220","0.00212"
"1432","8.55600","0.71323","0.00197"
"1494","8.92800","0.74420","0.00150"
"1556","9.30000","0.77517","0.00213"
"1618","9.67200","0.80626","0.00242"
"1680","10.04400","0.83723","0.00205"
"1742","10.41600","0.86814","0.00195"
"1804","10.78800","0.89917","0.00249"
"1866","11.16000","0.93027","0.00206"
"1928","11.53200","0.96112","0.00203"
"1990","11.90400","0.99227","0.00202"
"2052","12.27600","1.02324","0.00249"
"2114","12.64800","1.05415","0.00194"
"2176","13.02000","1.08518","0.00240"
"2238","13.39200","1.11621","0.00255"
"2300","13.76400","1.14718","0.00190"
"2362","14.13600","1.17815","0.00198"
"2424","14.50800","1.20924","0.00216"
"2486","14.88000","1.24021","0.00232"
"2548","15.25200","1.27119","0.00228"
"2610","15.62400","1.30222","0.00270"
"2672","15.99600","1.33319","0.00213"
"2734","16.36800","1.36422","0.00221"
"2796","16.74000","1.39519","0.00234"
"2858","17.11200","1.42616","0.00259"
"2920","17.48400","1.45719","0.00215"
"2982","17.85600","1.48822","0.00226"
"3044","18.22800","1.51925","0.00244"
"3106","18.60000","1.55016","0.00251"
"3168","18.97200","1.58119","0.00222"
"3230","19.34400","1.61222","0.00227"
"3292","19.71600","1.64320","0.00245"
"3354","20.08800","1.67417","0.00201"
"3416","20.46000","1.70520","0.00218"
"3478","20.83200","1.73623","0.00258"
"3540","21.20400","1.76714","0.00266"
"3602","21.57600","1.79817","0.00277"
"3664","21.94800","1.82926","0.00252"
"3726","22.32000","1.86011","0.00258"
"3788","22.69200","1.89120","0.00261"
"3850","23.06400","1.92223","0.00288"
"3912","23.43600","1.95320","0.00312"
"3974","23.80800","1.98418","0.00303"
"4036","24.18000","2.01521","0.00304"
"4098","24.55200","2.04624","0.00265"
"4160","24.92400","2.07721","0.00291"
"4222","25.29600","2.10824","0.00289"
"4284","25.66800","2.13927","0.00267"
"4346","26.04000","2.17012","0.00247"
"4408","26.41200","2.20121","0.00316"
"4470","26.78400","2.23218","0.00324"
"4532","27.15600","2.26315","0.00340"
"4594","27.52800","2.29424","0.00338"
"4656","27.90000","2.32521","0.00271"
"4718","28.27200","2.35613","0.00275"
"4780","28.64400","2.38716","0.00300"
"4842","29.01600","2.41825","0.00352"
"4904","29.38800","2.44922","0.00334"
"4966","29.76000","2.48019","0.00349"
"5028","30.13200","2.51122","0.00329"
"5090","30.50400","2.54219","0.00329"
"5152","30.87600","2.57316","0.00300"
"5214","31.24800","2.60425","0.00317"
"5276","31.62000","2.63522","0.00273"
"5338","31.99200","2.66619","0.00314"
"5400","32.36400","2.69717","0.00354"
"5462","32.73600","2.72820","0.00367"
"5524","33.10800","2.75923","0.00347"
"5586","33.48000","2.79020","0.00384"
"5648","33.85200","2.82123","0.00340"
"5710","34.22400","2.85220","0.00323"
"5772","34.59600","2.88317","0.00383"
"5834","34.96800","2.91426","0.00342"
"5896","35.34000","2.94523","0.00334"
"5958","35.71200","2.97614","0.00336"
"6020","36.08400","3.00717","0.00335"
"6082","36.45600","3.03826","0.00345"
"6144","36.82800","3.06918","0.00354"
"6206","37.20000","3.10015","0.00389"
"6268","37.57200","3.13124","0.00415"
"6330","37.94400","3.16215","0.00383"
"6392","38.31600","3.19318","0.00340"
"6454","38.68800","3.22421","0.00343"
"6516","39.06000","3.25518","0.00363"
"6578","39.43200","3.28621","0.00410"
"6640","39.80400","3.31724","0.00424"
"6702","40.17600","3.34821","0.00384"
"6764","40.54800","3.37912","0.00400"
"6826","40.92000","3.41022","0.00399"
"6888","41.29200","3.44131","0.00382"
"6950","41.66400","3.47216","0.00439"
"7012","42.03600","3.50325","0.00404"
"7074","42.40800","3.53422","0.00408"
"7136","42.78000","3.56519","0.00416"
"7198","43.15200","3.59622","0.00360"
"7260","43.52400","3.62725","0.00392"
"7322","43.89600","3.65822","0.00421"
"7384","44.26800","3.68913","0.00436"
"7446","44.64000","3.72022","0.00327"
"7508","45.01200","3.75120","0.00415"
"7570","45.38400","3.78217","0.00436"
"7632","45.75600","3.81320","0.00390"
"7694","46.12800","3.84423","0.00411"
"7756","46.50000","3.87520","0.00431"
"7818","46.87200","3.90623","0.00486"
"7880","47.24400","3.93720","0.00443"
"7942","47.61600","3.96817","0.00417"
"8004","47.98800","3.99914","0.00397"
"8066","48.36000","4.03023","0.00362"
"8128","48.73200","4.06120","0.00410"
"8190","49.10400","4.09223","0.00435"
"8252","49.47600","4.12327","0.00442"
"8314","49.84800","4.15418","0.00438"
"8376","50.22000","4.18521","0.00438"
"8438","50.59200","4.21624","0.00507"
"8500","50.96400","4.24721","0.00480"
"8562","51.33600","4.27812","0.00469"
"8624","51.70800","4.30921","0.00498"
"8686","52.08000","4.34030","0.00507"
"8748","52.45200","4.37115","0.00497"
"8810","52.82400","4.40218","0.00502"
"8872","53.19600","4.43327","0.00495"
"8934","53.56800","4.46413","0.00449"
"8996","53.94000","4.49516","0.00475"
"9058","54.31200","4.52625","0.00471"
"9120","54.68400","4.55728","0.00513"
"9182","55.05600","4.58819","0.00490"
"9244","55.42800","4.61922","0.00525"
"9306","55.80000","4.65019","0.00484"
"9368","56.17200","4.68110","0.00532"
"9430","56.54400","4.71219","0.00494"
"9492","56.91600","4.74322","0.00540"
"9554","57.28800","4.77413","0.00535"
"9616","57.66000","4.80522","0.00496"
"9678","58.03200","4.83620","0.00489"
"9740","58.40400","4.86717","0.00518"
"9802","58.77600","4.89814","0.00526"
"9864","59.14800","4.92923","0.00547"
"9926","59.52000","4.96020","0.00547"
"9988","59.89200","4.99111","0.00512"
"10050","60.26400","5.02220","0.00549"
"10112","60.63600","5.05323","0.00543"
"10174","61.00800","5.08414","0.00583"
"10236","61.38000","5.11523","0.00570"
"10298","61.75200","5.14620","0.00611"
"10360","62.12400","5.17724","0.00561"
"10422","62.49600","5.20821","0.00613"
"10484","62.86800","5.23924","0.00588"
"10546","63.24000","5.27021","0.00538"
"10608","63.61200","5.30118","0.00604"
"10670","63.98400","5.33227","0.00614"
"10732","64.35600","5.36318","0.00590"
"10794","64.72800","5.39415","0.00621"
"10856","65.10000","5.42524","0.00597"
"10918","65.47200","5.45615","0.00577"
"10980","65.84400","5.48718","0.00593"
"11042","66.21600","5.51821","0.00622"
"11104","66.58800","5.54925","0.00633"
"11166","66.96000","5.58016","0.00595"
"11228","67.33200","5.61113","0.00592"
"11290","67.70400","5.64222","0.00625"
"11352","68.07600","5.67313","0.00601"
"11414","68.44800","5.70422","0.00606"
"11476","68.82000","5.73519","0.00662"
"11538","69.19200","5.76616","0.00631"
"11600","69.56400","5.79719","0.00651"
"11662","69.93600","5.82822","0.00643"
"11724","70.30800","5.85925","0.00666"
"11786","70.68000","5.89017","0.00665"
"11848","71.05200","5.92126","0.00670"
"11910","71.42400","5.95223","0.00685"
"11972","71.79600","5.98314","0.00681"
"12034","72.16800","6.01423","0.00720"
"12096","72.54000","6.04520","0.00666"
"12158","72.91200","6.07617","0.00707"
"12220","73.28400","6.10720","0.00715"
"12282","73.65600","6.13817","0.00734"
"12344","74.02800","6.16920","0.00733"
"12406","74.40000","6.20023","0.00726"
"12468","74.77200","6.23127","0.00751"
"12530","75.14400","6.26224","0.00727"
"12592","75.51600","6.29315","0.00731"
"12654","75.88800","6.32418","0.00754"
"12716","76.26000","6.35521","0.00740"
"12778","76.63200","6.38618","0.00748"
"12840","77.00400","6.41721","0.00787"
"12902","77.37600","6.44818","0.00766"
"12964","77.74800","6.47921","0.00752"
"13026","78.12000","6.51018","0.00769"
"13088","78.49200","6.54121","0.00807"
"13150","78.86400","6.57219","0.00799"
"13212","79.23600","6.60322","0.00764"
"13274","79.60800","6.63425","0.00835"
"13336","79.98000","6.66522","0.00821"
"13398","80.35200","6.69619","0.00797"
"13460","80.72400","6.72716","0.00815"
"13522","81.09600","6.75819","0.00838"
"13584","81.46800","6.78916","0.00850"
"13646","81.84000","6.82019","0.00843"
"13708","82.21200","6.85128","0.00856"
"13770","82.58400","6.88213","0.00861"
"13832","82.95600","6.91322","0.00820"
"13894","83.32800","6.94420","0.00821"
"13956","83.70000","6.97517","0.00851"
"14018","84.07200","7.00620","0.00852"
"14080","84.44400","7.03717","0.00859"
"14142","84.81600","7.06820","0.00850"
"14204","85.18800","7.09917","0.00859"
"14266","85.56000","7.13020","0.00871"
"14328","85.93200","7.16129","0.00882"
"14390","86.30400","7.19208","0.00849"
"14452","86.67600","7.22323","0.00906"
"14514","87.04800","7.25426","0.00881"
"14576","87.42000","7.28518","0.00877"
"14638","87.79200","7.31621","0.00887"
"14700","88.16400","7.34724","0.00878"
"14762","88.53600","7.37821","0.00862"
"14824","88.90800","7.40918","0.00914"
"14886","89.28000","7.44021","0.00876"
"14948","89.65200","7.47118","0.00909"
"15010","90.02400","7.50221","0.00922"
"15072","90.39600","7.53324","0.00903"
"15134","90.76800","7.56421","0.00892"
"15196","91.14000","7.59518","0.00885"
"15258","91.51200","7.62621","0.00871"
"15320","91.88400","7.65725","0.00885"
"15382","92.25600","7.68816","0.00911"
"15444","92.62800","7.71919","0.00895"
"15506","93.00000","7.75022","0.00897"
"15568","93.37200","7.78119","0.00881"
"15630","93.74400","7.81216","0.00879"
"15692","94.11600","7.84319","0.00919"
"15754","94.48800","7.87422","0.00911"
"15816","94.86000","7.90519","0.00897"
"15878","95.23200","7.93622","0.00914"
"15940","95.60400","7.96725","0.00949"
"16002","95.97600","7.99817","0.00901"
"16064","96.34800","8.02920","0.00935"
"16126","96.72000","8.06023","0.00903"
"16188","97.09200","8.09120","0.00914"
"16250","97.46400","8.12217","0.00845"
"16312","97.83600","8.15326","0.00853"
"16374","98.20800","8.18417","0.00888"
"16436","98.58000","8.21520","0.00873"
"16498","98.95200","8.24617","0.00868"
"16560","99.32400","8.27720","0.00888"
"16622","99.69600","8.30823","0.00886"
"16684","100.06800","8.33920","0.00880"
"16746","100.44000","8.37024","0.00901"
"16808","100.81200","8.40115","0.00911"
"16870","101.18400","8.43218","0.00896"
"16932","101.55600","8.46327","0.00922"
"16994","101.92800","8.49412","0.00914"
"17056","102.30000","8.52515","0.00924"
"17118","102.67200","8.55624","0.00932"
"17180","103.04400","8.58721","0.00920"
"17242","103.41600","8.61818","0.00904"
"17304","103.78800","8.64921","0.00887"
"17366","104.16000","8.68024","0.00928"
"17428","104.53200","8.71116","0.00946"
"17490","104.90400","8.74225","0.00905"
"17552","105.27600","8.77322","0.00931"
"17614","105.64800","8.80413","0.00942"
"17676","106.02000","8.83528","0.00954"
"17738","106.39200","8.86619","0.00935"
"17800","106.76400","8.89716","0.00940"
"17862","107.13600","8.92819","0.00937"
"17924","107.50800","8.95916","0.00946"
"17986","107.88000","8.99019","0.00944"
"18048","108.25200","9.02122","0.00961"
"18110","108.62400","9.05219","0.00972"
"18172","108.99600","9.08317","0.00926"
"18234","109.36800","9.11420","0.00984"
"18296","109.74000","9.14523","0.00966"
"18358","110.11200","9.17614","0.00945"
"18420","110.48400","9.20717","0.00990"
"18482","110.85600","9.23820","0.00996"
"18544","111.22800","9.26923","0.00989"
"18606","111.60000","9.30014","0.00983"
"18668","111.97200","9.33117","0.01029"
"18730","112.34400","9.36226","0.01026"
"18792","112.71600","9.39312","0.01045"
"18854","113.08800","9.42421","0.01043"
"18916","113.46000","9.45524","0.01059"
"18978","113.83200","9.48621","0.01089"
"19040","114.20400","9.51718","0.01087"
"19102","114.57600","9.54821","0.01081"
"19164","114.94800","9.57924","0.01094"
"19226","115.32000","9.61021","0.01095"
"19288","115.69200","9.64124","0.01110"
"19350","116.06400","9.67221","0.01125"
"19412","116.43600","9.70318","0.01107"
"19474","116.80800","9.73421","0.01132"
"19536","117.18000","9.76525","0.01055"
"19598","117.55200","9.79616","0.01120"
"19660","117.92400","9.82725","0.01114"
"19722","118.29600","9.85822","0.01156"
"19784","118.66800","9.88925","0.01160"
"19846","119.04000","9.92010","0.01182"
"19908","119.41200","9.95119","0.01142"
"19970","119.78400","9.98222","0.01208"
"20032","120.15600","10.01319","0.01218"
"20094","120.52800","10.04422","0.01214"
"20156","120.90000","10.07519","0.01263"
"20218","121.27200","10.10611","0.01275"
"20280","121.64400","10.13726","0.01341"
"20342","122.01600","10.16829","0.01314"
"20404","122.38800","10.19920","0.01312"
"20466","122.76000","10.23017","0.01336"
"20528","123.13200","10.26120","0.01425"
"20590","123.50400","10.29217","0.01434"
"20652","123.87600","10.32320","0.01424"
"20714","124.24800","10.35429","0.01483"
"20776","124.62000","10.38520","0.01515"
"20838","124.99200","10.41617","0.01536"
"20900","125.36400","10.44720","0.01559"
"20962","125.73600","10.47818","0.01546"
"21024","126.10800","10.50921","0.01608"
"21086","126.48000","10.54024","0.01601"
"21148","126.85200","10.57127","0.01654"
"21210","127.22400","10.60212","0.01677"
"21272","127.59600","10.63315","0.01675"
"21334","127.96800","10.66424","0.01767"
"21396","128.34000","10.69521","0.01796"
"21458","128.71200","10.72618","0.01803"
"21520","129.08400","10.75721","0.01884"
"21582","129.45600","10.78818","0.01894"
"21644","129.82800","10.81916","0.01932"
"21706","130.20000","10.85019","0.01967"
"21768","130.57200","10.88122","0.01979"
"21830","130.94400","10.91219","0.02044"
"21892","131.31600","10.94322","0.02100"
"21954","131.68800","10.97419","0.02114"
"22016","132.06000","11.00510","0.02179"
"22078","132.43200","11.03625","0.02205"
"22140","132.80400","11.06722","0.02221"
"22202","133.17600","11.09819","0.02251"
"22264","133.54800","11.12916","0.02288"
"22326","133.92000","11.16019","0.02273"
"22388","134.29200","11.19123","0.02294"
"22450","134.66400","11.22220","0.02350"
"22512","135.03600","11.25323","0.02345"
"22574","135.40800","11.28426","0.02424"
"22636","135.78000","11.31517","0.02422"
"22698","136.15200","11.34620","0.02535"
"22760","136.52400","11.37723","0.02496"
"22822","136.89600","11.40814","0.02452"
"22884","137.26800","11.43923","0.02421"
"22946","137.64000","11.47020","0.02483"
"23008","138.01200","11.50123","0.02509"
"23070","138.38400","11.53214","0.02529"
"23132","138.75600","11.56324","0.02584"
"23194","139.12800","11.59421","0.02598"
"23256","139.50000","11.62518","0.02671"
"23318","139.87200","11.65621","0.02703"
"23380","140.24400","11.68718","0.02700"
"23442","140.61600","11.71815","0.02187"
"23504","140.98800","11.74924","0.02221"
"23566","141.36000","11.78021","0.02216"
"23628","141.73200","11.81118","0.02345"
"23690","142.10400","11.84221","0.02442"
"23752","142.47600","11.87325","0.02515"
"23814","142.84800","11.90416","0.02555"
"23876","143.22000","11.93519","0.02534"
"23938","143.59200","11.96628","0.02669"
"24000","143.96400","11.99719","0.02740"
"24062","144.33600","12.02816","0.02758"
"24124","144.70800","12.05919","0.02731"
"24186","145.08000","12.09016","0.02631"
"24248","145.45200","12.12113","0.02569"
"24310","145.82400","12.15222","0.02641"
"24372","146.19600","12.18325","0.02709"
"24434","146.56800","12.21410","0.02760"
"24496","146.94000","12.24525","0.02749"
"24558","147.31200","12.27623","0.02749"
"24620","147.68400","12.30720","0.02727"
"24682","148.05600","12.33823","0.02582"
"24744","148.42800","12.36920","0.02593"
"24806","148.80000","12.40017","0.02694"
"24868","149.17200","12.43114","0.02817"
"24930","149.54400","12.46223","0.02859"
"24992","149.91600","12.49320","0.02906"
"25054","150.28800","12.52417","0.02920"
"25116","150.66000","12.55526","0.02842"
"25178","151.03200","12.58623","0.02787"
"25240","151.40400","12.61715","0.02856"
"25302","151.77600","12.64818","0.02921"
"25364","152.14800","12.67927","0.02901"
"25426","152.52000","12.71018","0.02929"
"25488","152.89200","12.74115","0.02954"
"25550","153.26400","12.77218","0.02944"
"25612","153.63600","12.80321","0.02984"
"25674","154.00800","12.83418","0.03036"
"25736","154.38000","12.86521","0.03150"
"25798","154.75200","12.89618","0.03117"
"25860","155.12400","12.92715","0.03208"
"25922","155.49600","12.95825","0.03262"
"25984","155.86800","12.98922","0.03244"
"26046","156.24000","13.02013","0.03329"
"26108","156.61200","13.05116","0.03384"
"26170","156.98400","13.08225","0.03464"
"26232","157.35600","13.11310","0.03473"
"26294","157.72800","13.14419","0.03469"
"26356","158.10000","13.17528","0.03561"
"26418","158.47200","13.20613","0.03568"
"26480","158.84400","13.23722","0.03680"
"26542","159.21600","13.26819","0.03669"
"26604","159.58800","13.29917","0.03745"
"26666","159.96000","13.33020","0.03778"
"26728","160.33200","13.36123","0.03902"
"26790","160.70400","13.39220","0.03930"
"26852","161.07600","13.42317","0.03948"
"26914","161.44800","13.45420","0.04065"
"26976","161.82000","13.48523","0.04099"
"27038","162.19200","13.51614","0.04200"
"27100","162.56400","13.54723","0.04244"
"27162","162.93600","13.57820","0.04259"
"27224","163.30800","13.60923","0.04372"
"27286","163.68000","13.64021","0.04488"
"27348","164.05200","13.67118","0.04504"
"27410","164.42400","13.70227","0.04671"
"27472","164.79600","13.73318","0.04652"
"27534","165.16800","13.76421","0.04760"
"27596","165.54000","13.79518","0.04798"
"27658","165.91200","13.82609","0.04870"
"27720","166.28400","13.85724","0.04958"
"27782","166.65600","13.88821","0.05032"
"27844","167.02800","13.91918","0.05079"
"27906","167.40000","13.95021","0.05143"
"27968","167.77200","13.98118","0.05153"
"28030","168.14400","14.01221","0.05200"
"28092","168.51600","14.04319","0.05265"
"28154","168.88800","14.07422","0.05371"
"28216","169.26000","14.10519","0.05390"
"28278","169.63200","14.13616","0.05472"
"28340","170.00400","14.16725","0.05520"
"28402","170.37600","14.19822","0.05588"
"28464","170.74800","14.22919","0.05650"
"28526","171.12000","14.26022","0.05747"
"28588","171.49200","14.29125","0.05813"
"28650","171.86400","14.32216","0.05888"
"28712","172.23600","14.35320","0.06002"
"28774","172.60800","14.38423","0.06064"
"28836","172.98000","14.41514","0.06098"
"28898","173.35200","14.44623","0.05968"
"28960","173.72400","14.47726","0.06030"
"29022","174.09600","14.50811","0.06100"
"29084","174.46800","14.53920","0.06144"
"29146","174.84000","14.57023","0.06112"
"29208","175.21200","14.60120","0.06133"
"29270","175.58400","14.63217","0.06050"
"29332","175.95600","14.66320","0.05596"
"29394","176.32800","14.69423","0.05715"
"29456","176.70000","14.72515","0.05606"
"29518","177.07200","14.75624","0.05561"
"29580","177.44400","14.78721","0.05569"
"29642","177.81600","14.81818","0.05529"
"29704","178.18800","14.84921","0.05516"
"29766","178.56000","14.88018","0.05631"
"29828","178.93200","14.91115","0.05631"
"29890","179.30400","14.94218","0.05261"
"29952","179.67600","14.97321","0.05376"
"30014","180.04800","15.00424","0.05376"
"30076","180.42000","15.03521","0.05425"
"30138","180.79200","15.06625","0.05533"
"30200","181.16400","15.09722","0.05666"
"30262","181.53600","15.12813","0.05762"
"30324","181.90800","15.15928","0.05778"
"30386","182.28000","15.19025","0.05849"
"30448","182.65200","15.22116","0.05834"
"30510","183.02400","15.25213","0.05942"
"30572","183.39600","15.28316","0.05828"
"30634","183.76800","15.31419","0.05831"
"30696","184.14000","15.34522","0.05869"
"30758","184.51200","15.37626","0.05885"
"30820","184.88400","15.40717","0.05966"
"30882","185.25600","15.43814","0.06047"
"30944","185.62800","15.46923","0.06054"
"31006","186.00000","15.50020","0.05991"
"31068","186.37200","15.53123","0.05452"
"31130","186.74400","15.56220","0.05392"
"31192","187.11600","15.59329","0.05212"
"31254","187.48800","15.62414","0.04938"
"31316","187.86000","15.65517","0.05056"
"31378","188.23200","15.68620","0.05150"
"31440","188.60400","15.71717","0.05277"
"31502","188.97600","15.74820","0.05360"
"31564","189.34800","15.77917","0.05448"
"31626","189.72000","15.81021","0.05587"
"31688","190.09200","15.84118","0.05632"
"31750","190.46400","15.87221","0.05649"
"31812","190.83600","15.90324","0.05709"
"31874","191.20800","15.93421","0.05812"
"31936","191.58000","15.96524","0.05900"
"31998","191.95200","15.99621","0.05987"
"32060","192.32400","16.02718","0.05974"
"32122","192.69600","16.05827","0.06026"
"32184","193.06800","16.08918","0.06108"
"32246","193.44000","16.12021","0.06207"
"32308","193.81200","16.15119","0.06313"
"32370","194.18400","16.18222","0.06407"
"32432","194.55600","16.21319","0.06444"
"32494","194.92800","16.24416","0.06429"
"32556","195.30000","16.27519","0.06503"
"32618","195.67200","16.30622","0.06620"
"32680","196.04400","16.33719","0.06726"
"32742","196.41600","16.36822","0.06851"
"32804","196.78800","16.39919","0.07033"
"32866","197.16000","16.43016","0.07201"
"32928","197.53200","16.46119","0.07296"
"32990","197.90400","16.49223","0.07446"
"33052","198.27600","16.52320","0.07581"
"33114","198.64800","16.55417","0.07718"
"33176","199.02000","16.58526","0.07910"
"33238","199.39200","16.61617","0.08016"
"33300","199.76400","16.64720","0.08092"
"33362","200.13600","16.67823","0.08306"
"33424","200.50800","16.70914","0.08482"
"33486","200.88000","16.74011","0.08643"
"33548","201.25200","16.77120","0.08829"
"33610","201.62400","16.80217","0.08941"
"33672","201.99600","16.83315","0.09068"
"33734","202.36800","16.86418","0.09138"
"33796","202.74000","16.89527","0.09304"
"33858","203.11200","16.92612","0.09420"
"33920","203.48400","16.95721","0.09531"
"33982","203.85600","16.98824","0.09650"
"34044","204.22800","17.01915","0.09724"
"34106","204.60000","17.05018","0.09821"
"34168","204.97200","17.08121","0.09930"
"34230","205.34400","17.11218","0.09652"
"34292","205.71600","17.14315","0.09558"
"34354","206.08800","17.17418","0.09619"
"34416","206.46000","17.20528","0.09727"
"34478","206.83200","17.23613","0.09830"
"34540","207.20400","17.26722","0.09906"
"34602","207.57600","17.29825","0.10000"
"34664","207.94800","17.32910","0.10085"
"34726","208.32000","17.36019","0.10189"
"34788","208.69200","17.39122","0.10318"
"34850","209.06400","17.42219","0.10408"
"34912","209.43600","17.45316","0.10576"
"34974","209.80800","17.48425","0.10856"
"35036","210.18000","17.51522","0.11055"
"35098","210.55200","17.54614","0.11313"
"35160","210.92400","17.57722","0.11578"
"35222","211.29600","17.60820","0.11859"
"35284","211.66800","17.63917","0.12134"
"35346","212.04000","17.67020","0.12573"
"35408","212.41200","17.70123","0.13011"
"35470","212.78400","17.73214","0.13283"
"35532","213.15600","17.76317","0.13787"
"35594","213.52800","17.79420","0.14210"
"35656","213.90000","17.82517","0.14606"
"35718","214.27200","17.85614","0.14936"
"35780","214.64400","17.88723","0.15298"
"35842","215.01600","17.91821","0.15589"
"35904","215.38800","17.94918","0.15873"
"35966","215.76000","17.98021","0.16093"
"36028","216.13200","18.01124","0.16326"
"36090","216.50400","18.04215","0.16553"
"36152","216.87600","18.07324","0.16811"
"36214","217.24800","18.10427","0.17046"
"36276","217.62000","18.13518","0.17316"
"36338","217.99200","18.16621","0.17601"
"36400","218.36400","18.19724","0.17922"
"36462","218.73600","18.22816","0.18253"
"36524","219.10800","18.25925","0.18617"
"36586","219.48000","18.29016","0.18772"
"36648","219.85200","18.32119","0.18823"
"36710","220.22400","18.35222","0.19106"
"36772","220.59600","18.38325","0.19392"
"36834","220.96800","18.41422","0.19642"
"36896","221.34000","18.44513","0.19946"
"36958","221.71200","18.47616","0.20143"
"37020","222.08400","18.50725","0.20325"
"37082","222.45600","18.53816","0.20416"
"37144","222.82800","18.56925","0.20581"
"37206","223.20000","18.60023","0.20694"
"37268","223.57200","18.63114","0.20773"
"37330","223.94400","18.66217","0.20707"
"37392","224.31600","18.69326","0.20290"
"37454","224.68800","18.72423","0.20325"
"37516","225.06000","18.75520","0.20392"
"37578","225.43200","18.78623","0.20615"
"37640","225.80400","18.81720","0.20645"
"37702","226.17600","18.84811","0.20598"
"37764","226.54800","18.87926","0.20502"
"37826","226.92000","18.91023","0.20311"
"37888","227.29200","18.94120","0.20535"
"37950","227.66400","18.97218","0.20708"
"38012","228.03600","19.00321","0.20733"
"38074","228.40800","19.03418","0.20905"
"38136","228.78000","19.06515","0.21109"
"38198","229.15200","19.09618","0.21416"
"38260","229.52400","19.12721","0.21828"
"38322","229.89600","19.15818","0.22176"
"38384","230.26800","19.18921","0.22592"
"38446","230.64000","19.22018","0.16997"
"38508","231.01200","19.25121","0.17114"
"38570","231.38400","19.28218","0.16986"
"38632","231.75600","19.31322","0.17544"
"38694","232.12800","19.34413","0.18436"
"38756","232.50000","19.37522","0.18639"
"38818","232.87200","19.40631","0.18973"
"38880","233.24400","19.43716","0.19608"
"38942","233.61600","19.46819","0.20114"
"39004","233.98800","19.49922","0.20338"
"39066","234.36000","19.53019","0.20717"
"39128","234.73200","19.56122","0.20972"
"39190","235.10400","19.59219","0.21237"
"39252","235.47600","19.62316","0.21555"
"39314","235.84800","19.65420","0.22021"
"39376","236.22000","19.68523","0.22369"
"39438","236.59200","19.71619","0.22727"
"39500","236.96400","19.74717","0.23197"
"39562","237.33600","19.77820","0.23681"
"39624","237.70800","19.80923","0.24198"
"39686","238.08000","19.84014","0.24553"
"39748","238.45200","19.87123","0.24932"
"39810","238.82400","19.90214","0.25313"
"39872","239.19600","19.93317","0.25699"
"39934","239.56800","19.96414","0.26074"
"39996","239.94000","19.99524","0.26515"
"40058","240.31200","20.02620","0.27130"
"40120","240.68400","20.05718","0.27790"
"40182","241.05600","20.08821","0.28303"
"40244","241.42800","20.11924","0.28522"
"40306","241.80000","20.15015","0.28943"
"40368","242.17200","20.18124","0.29581"
"40430","242.54400","20.21221","0.30141"
"40492","242.91600","20.24324","0.30666"
"40554","243.28800","20.27415","0.30949"
"40616","243.66000","20.30524","0.31217"
"40678","244.03200","20.33615","0.30714"
"40740","244.40400","20.36719","0.31028"
"40802","244.77600","20.39822","0.31379"
"40864","245.14800","20.42919","0.31508"
"40926","245.52000","20.46016","0.31618"
"40988","245.89200","20.49119","0.31785"
"41050","246.26400","20.52222","0.31969"
"41112","246.63600","20.55319","0.32338"
"41174","247.00800","20.58422","0.31900"
"41236","247.38000","20.61519","0.32318"
"41298","247.75200","20.64616","0.32776"
"41360","248.12400","20.67719","0.33605"
"41422","248.49600","20.70822","0.34282"
"41484","248.86800","20.73920","0.34995"
"41546","249.24000","20.77023","0.35614"
"41608","249.61200","20.80120","0.36074"
"41670","249.98400","20.83217","0.36661"
"41732","250.35600","20.86320","0.37147"
"41794","250.72800","20.89423","0.37571"
"41856","251.10000","20.92526","0.38019"
"41918","251.47200","20.95617","0.38451"
"41980","251.84400","20.98720","0.38824"
"42042","252.21600","21.01823","0.38341"
"42104","252.58800","21.04921","0.38906"
"42166","252.96000","21.08023","0.39434"
"42228","253.33200","21.11121","0.39746"
"42290","253.70400","21.14218","0.40085"
"42352","254.07600","21.17321","0.40443"
"42414","254.44800","21.20418","0.40770"
"42476","254.82000","21.23521","0.41058"
"42538","255.19200","21.26618","0.41476"
"42600","255.56400","21.29727","0.41824"
"42662","255.93600","21.32818","0.42216"
"42724","256.30800","21.35915","0.42663"
"42786","256.68000","21.39018","0.42513"
"42848","257.05200","21.42115","0.41641"
"42910","257.42400","21.45219","0.41891"
"42972","257.79600","21.48322","0.42344"
"43034","258.16800","21.51425","0.42529"
"43096","258.54000","21.54522","0.43238"
"43158","258.91200","21.57619","0.43742"
"43220","259.28400","21.60722","0.44258"
"43282","259.65600","21.63819","0.45002"
"43344","260.02800","21.66916","0.45393"
"43406","260.40000","21.70025","0.45835"
"43468","260.77200","21.73116","0.46230"
"43530","261.14400","21.76219","0.46508"
"43592","261.51600","21.79323","0.46968"
"43654","261.88800","21.82420","0.47498"
"43716","262.26000","21.85517","0.48087"
"43778","262.63200","21.88620","0.48914"
"43840","263.00400","21.91723","0.49654"
"43902","263.37600","21.94814","0.50310"
"43964","263.74800","21.97923","0.50977"
"44026","264.12000","22.01026","0.51470"
"44088","264.49200","22.04117","0.51882"
"44150","264.86400","22.07220","0.52136"
"44212","265.23600","22.10324","0.52460"
"44274","265.60800","22.13420","0.52734"
"44336","265.98000","22.16512","0.53071"
"44398","266.35200","22.19621","0.53480"
"44460","266.72400","22.22724","0.53991"
"44522","267.09600","22.25815","0.54684"
"44584","267.46800","22.28924","0.55354"
"44646","267.84000","22.32021","0.55979"
"44708","268.21200","22.35112","0.56611"
"44770","268.58400","22.38221","0.57091"
"44832","268.95600","22.41318","0.57643"
"44894","269.32800","22.44421","0.57876"
"44956","269.70000","22.47518","0.58521"
"45018","270.07200","22.50621","0.59122"
"45080","270.44400","22.53719","0.59947"
"45142","270.81600","22.56816","0.60424"
"45204","271.18800","22.59925","0.60846"
"45266","271.56000","22.63022","0.61186"
"45328","271.93200","22.66119","0.61426"
"45390","272.30400","22.69216","0.61755"
"45452","272.67600","22.72319","0.61948"
"45514","273.04800","22.75416","0.62285"
"45576","273.42000","22.78519","0.62727"
"45638","273.79200","22.81622","0.63239"
"45700","274.16400","22.84720","0.63929"
"45762","274.53600","22.87811","0.45457"
"45824","274.90800","22.90926","0.44132"
"45886","275.28000","22.94017","0.44880"
"45948","275.65200","22.97120","0.45480"
"46010","276.02400","23.00223","0.45909"
"46072","276.39600","23.03320","0.45512"
"46134","276.76800","23.06417","0.46604"
"46196","277.14000","23.09520","0.46815"
"46258","277.51200","23.12617","0.47109"
"46320","277.88400","23.15708","0.47518"
"46382","278.25600","23.18823","0.49162"
"46444","278.62800","23.21926","0.49173"
"46506","279.00000","23.25018","0.49667"
"46568","279.37200","23.28121","0.51315"
"46630","279.74400","23.31218","0.51037"
"46692","280.11600","23.34321","0.51679"
"46754","280.48800","23.37418","0.52209"
"46816","280.86000","23.40521","0.52140"
"46878","281.23200","23.43618","0.52590"
"46940","281.60400","23.46721","0.52934"
"47002","281.97600","23.49818","0.53038"
"47064","282.34800","23.52921","0.53717"
"47126","282.72000","23.56018","0.08360"
"47188","283.09200","23.59128","0.09690"
"47250","283.46400","23.62219","0.11578"
"47312","283.83600","23.65316","0.09934"
"47374","284.20800","23.68419","0.10019"
"47436","284.58000","23.71522","0.11190"
"47498","284.95200","23.74619","0.12526"
"47560","285.32400","23.77716","0.10498"
"47622","285.69600","23.80825","0.11017"
"47684","286.06800","23.83916","0.14078"
"47746","286.44000","23.87019","0.15948"
"47808","286.81200","23.90129","0.13707"
"47870","287.18400","23.93220","0.13864"
"47932","287.55600","23.96323","0.15559"
"47994","287.92800","23.99420","0.16807"
"48056","288.30000","24.02523","0.17168"
"48118","288.67200","24.05614","0.16775"
"48180","289.04400","24.08723","0.17461"
"48242","289.41600","24.11826","0.17809"
"48304","289.78800","24.14917","0.17825"
"48366","290.16000","24.18014","0.19178"
"48428","290.53200","24.21117","0.20062"
"48490","290.90400","24.24220","0.19897"
"48552","291.27600","24.27317","0.19682"
"48614","291.64800","24.30420","0.20276"
"48676","292.02000","24.33524","0.20649"
"48738","292.39200","24.36615","0.20799"
"48800","292.76400","24.39718","0.21134"
"48862","293.13600","24.42827","0.21811"
"48924","293.50800","24.45912","0.22337"
"48986","293.88000","24.49021","0.22592"
"49048","294.25200","24.52124","0.22827"
"49110","294.62400","24.55215","0.23295"
"49172","294.99600","24.58318","0.23566"
"49234","295.36800","24.61421","0.23849"
"49296","295.74000","24.64519","0.24429"
"49358","296.11200","24.67616","0.24871"
"49420","296.48400","24.70725","0.25075"
"49482","296.85600","24.73822","0.25541"
"49544","297.22800","24.76913","0.26082"
"49606","297.60000","24.80022","0.26516"
"49668","297.97200","24.83119","0.27079"
"49730","298.34400","24.86216","0.27856"
"49792","298.71600","24.89319","0.28710"
"49854","299.08800","24.92422","0.29251"
"49916","299.46000","24.95520","0.29888"
"49978","299.83200","24.98616","0.30405"
"50040","300.20400","25.01720","0.30770"
"50102","300.57600","25.04823","0.31077"
"50164","300.94800","25.07914","0.31313"
"50226","301.32000","25.11023","0.31422"
"50288","301.69200","25.14120","0.31507"
"50350","302.06400","25.17217","0.31605"
"50412","302.43600","25.20320","0.31774"
"50474","302.80800","25.23423","0.31915"
"50536","303.18000","25.26520","0.32180"
"50598","303.55200","25.29617","0.32465"
"50660","303.92400","25.32721","0.32701"
"50722","304.29600","25.35818","0.32986"
"50784","304.66800","25.38921","0.32770"
"50846","305.04000","25.42024","0.23185"
"50908","305.41200","25.45115","0.22121"
"50970","305.78400","25.48218","0.20821"
"51032","306.15600","25.51321","0.20881"
"51094","306.52800","25.54418","0.20905"
"51156","306.90000","25.57521","0.21017"
"51218","307.27200","25.60618","0.21060"
"51280","307.64400","25.63727","0.21178"
"51342","308.01600","25.66813","0.21323"
"51404","308.38800","25.69916","0.21580"
"51466","308.76000","25.73025","0.21825"
"51528","309.13200","25.76122","0.21984"
"51590","309.50400","25.79219","0.22185"
"51652","309.87600","25.82322","0.22319"
"51714","310.24800","25.85419","0.22467"
"51776","310.62000","25.88516","0.22642"
"51838","310.99200","25.91619","0.22826"
"51900","311.36400","25.94722","0.23046"
"51962","311.73600","25.97819","0.23222"
"52024","312.10800","26.00922","0.23425"
"52086","312.48000","26.04020","0.23633"
"52148","312.85200","26.07111","0.23900"
"52210","313.22400","26.10220","0.24094"
"52272","313.59600","26.13323","0.24342"
"52334","313.96800","26.16420","0.24443"
"52396","314.34000","26.19517","0.24647"
"52458","314.71200","26.22626","0.24804"
"52520","315.08400","26.25723","0.24893"
"52582","315.45600","26.28820","0.25090"
"52644","315.82800","26.31923","0.25277"
"52706","316.20000","26.35021","0.25408"
"52768","316.57200","26.38117","0.25579"
"52830","316.94400","26.41221","0.25547"
"52892","317.31600","26.44324","0.25735"
"52954","317.68800","26.47415","0.26038"
"53016","318.06000","26.50518","0.26249"
"53078","318.43200","26.53621","0.26492"
"53140","318.80400","26.56718","0.26812"
"53202","319.17600","26.59815","0.27250"
"53264","319.54800","26.62930","0.27449"
"53326","319.92000","26.66015","0.27814"
"53388","320.29200","26.69118","0.28232"
"53450","320.66400","26.72222","0.28697"
"53512","321.03600","26.75325","0.29034"
"53574","321.40800","26.78416","0.29345"
"53636","321.78000","26.81519","0.29690"
"53698","322.15200","26.84622","0.29959"
"53760","322.52400","26.87713","0.30263"
"53822","322.89600","26.90822","0.30464"
"53884","323.26800","26.93925","0.30739"
"53946","323.64000","26.97010","0.30906"
"54008","324.01200","27.00119","0.31078"
"54070","324.38400","27.03222","0.31233"
"54132","324.75600","27.06325","0.31337"
"54194","325.12800","27.09417","0.31442"
"54256","325.50000","27.12520","0.31480"
"54318","325.87200","27.15623","0.31514"
"54380","326.24400","27.18720","0.31603"
"54442","326.61600","27.21823","0.31658"
"54504","326.98800","27.24926","0.31737"
"54566","327.36000","27.28017","0.31821"
"54628","327.73200","27.31126","0.31773"
"54690","328.10400","27.34217","0.31908"
"54752","328.47600","27.37314","0.32023"
"54814","328.84800","27.40417","0.32138"
"54876","329.22000","27.43521","0.32347"
"54938","329.59200","27.46618","0.32561"
"55000","329.96400","27.49715","0.32824"
"55062","330.33600","27.52824","0.33106"
"55124","330.70800","27.55921","0.33366"
"55186","331.08000","27.59012","0.33782"
"55248","331.45200","27.62127","0.34210"
"55310","331.82400","27.65218","0.34471"
"55372","332.19600","27.68315","0.34887"
"55434","332.56800","27.71418","0.35138"
"55496","332.94000","27.74527","0.35414"
"55558","333.31200","27.77618","0.35694"
"55620","333.68400","27.80716","0.36008"
"55682","334.05600","27.83819","0.36239"
"55744","334.42800","27.86916","0.36518"
"55806","334.80000","27.90019","0.36769"
"55868","335.17200","27.93128","0.36965"
"55930","335.54400","27.96219","0.37299"
"55992","335.91600","27.99316","0.37525"
"56054","336.28800","28.02419","0.37768"
"56116","336.66000","28.05522","0.38066"
"56178","337.03200","28.08619","0.38354"
"56240","337.40400","28.11722","0.38608"
"56302","337.77600","28.14820","0.38950"
"56364","338.14800","28.17917","0.39189"
"56426","338.52000","28.21020","0.39456"
"56488","338.89200","28.24123","0.39661"
"56550","339.26400","28.27214","0.39811"
"56612","339.63600","28.30323","0.39963"
"56674","340.00800","28.33420","0.40199"
"56736","340.38000","28.36517","0.40386"
"56798","340.75200","28.39620","0.40605"
"56860","341.12400","28.42717","0.40802"
"56922","341.49600","28.45820","0.40948"
"56984","341.86800","28.48918","0.41178"
"57046","342.24000","28.52021","0.41396"
"57108","342.61200","28.55124","0.41617"
"57170","342.98400","28.58215","0.41808"
"57232","343.35600","28.61324","0.42054"
"57294","343.72800","28.64421","0.42356"
"57356","344.10000","28.67518","0.42596"
"57418","344.47200","28.70615","0.42870"
"57480","344.84400","28.73718","0.43146"
"57542","345.21600","28.76821","0.43498"
"57604","345.58800","28.79924","0.43778"
"57666","345.96000","28.83022","0.44134"
"57728","346.33200","28.86119","0.44459"
"57790","346.70400","28.89216","0.44801"
"57852","347.07600","28.92325","0.45091"
"57914","347.44800","28.95422","0.45341"
"57976","347.82000","28.98519","0.45600"
"58038","348.19200","29.01622","0.45807"
"58100","348.56400","29.04719","0.46007"
"58162","348.93600","29.07816","0.46159"
"58224","349.30800","29.10919","0.46329"
"58286","349.68000","29.14022","0.46561"
"58348","350.05200","29.17119","0.46775"
"58410","350.42400","29.20222","0.47066"
"58472","350.79600","29.23319","0.47372"
"58534","351.16800","29.26417","0.47555"
"58596","351.54000","29.29520","0.47802"
"58658","351.91200","29.32623","0.48167"
"58720","352.28400","29.35726","0.48616"
"58782","352.65600","29.38817","0.49063"
"58844","353.02800","29.41920","0.49490"
"58906","353.40000","29.45023","0.49906"
"58968","353.77200","29.48114","0.50313"
"59030","354.14400","29.51223","0.50760"
"59092","354.51600","29.54321","0.51110"
"59154","354.88800","29.57418","0.51407"
"59216","355.26000","29.60521","0.51702"
"59278","355.63200","29.63618","0.51947"
"59340","356.00400","29.66727","0.52135"
"59402","356.37600","29.69818","0.52309"
"59464","356.74800","29.72927","0.52512"
"59526","357.12000","29.76024","0.52652"
"59588","357.49200","29.79109","0.52793"
"59650","357.86400","29.82224","0.53038"
"59712","358.23600","29.85321","0.53291"
"59774","358.60800","29.88419","0.53535"
"59836","358.98000","29.91521","0.53840"
"59898","359.35200","29.94625","0.54281"
"59960","359.72400","29.97716","0.54702"
"60022","360.09600","30.00813","0.55138"
"60084","360.46800","30.03922","0.55664"
"60146","360.84000","30.07019","0.56094"
"60208","361.21200","30.10116","0.56473"
"60270","361.58400","30.13225","0.56800"
"60332","361.95600","30.16322","0.57098"
"60394","362.32800","30.19413","0.57306"
"60456","362.70000","30.22523","0.57631"
"60518","363.07200","30.25626","0.57997"
"60580","363.44400","30.28723","0.58318"
"60642","363.81600","30.31814","0.58707"
"60704","364.18800","30.34923","0.59173"
"60766","364.56000","30.38020","0.59599"
"60828","364.93200","30.41123","0.59931"
"60890","365.30400","30.44220","0.60325"
"60952","365.67600","30.47317","0.60565"
"61014","366.04800","30.50414","0.60840"
"61076","366.42000","30.53523","0.61063"
"61138","366.79200","30.56620","0.61270"
"61200","367.16400","30.59718","0.61419"
"61262","367.53600","30.62820","0.61583"
"61324","367.90800","30.65930","0.61722"
"61386","368.28000","30.69015","0.61920"
"61448","368.65200","30.72118","0.62099"
"61510","369.02400","30.75221","0.62422"
"61572","369.39600","30.78318","0.62736"
"61634","369.76800","30.81421","0.63126"
"61696","370.14000","30.84518","0.63601"
"61758","370.51200","30.87621","0.64009"
"61820","370.88400","30.90718","0.64637"
"61882","371.25600","30.93822","0.65180"
"61944","371.62800","30.96924","0.65679"
"62006","372.00000","31.00016","0.66096"
"62068","372.37200","31.03125","0.66500"
"62130","372.74400","31.06216","0.66883"
"62192","373.11600","31.09313","0.67150"
"62254","373.48800","31.12428","0.67435"
"62316","373.86000","31.15519","0.67712"
"62378","374.23200","31.18616","0.68039"
"62440","374.60400","31.21719","0.68411"
"62502","374.97600","31.24816","0.68801"
"62564","375.34800","31.27919","0.69320"
"62626","375.72000","31.31016","0.69706"
"62688","376.09200","31.34126","0.70246"
"62750","376.46400","31.37216","0.70659"
"62812","376.83600","31.40314","0.71003"
"62874","377.20800","31.43423","0.71316"
"62936","377.58000","31.46526","0.71569"
"62998","377.95200","31.49611","0.71801"
"63060","378.32400","31.52720","0.72007"
"63122","378.69600","31.55823","0.72191"
"63184","379.06800","31.58914","0.72329"
"63246","379.44000","31.62017","0.72465"
"63308","379.81200","31.65126","0.72585"
"63370","380.18400","31.68217","0.72750"
"63432","380.55600","31.71321","0.72944"
"63494","380.92800","31.74423","0.73072"
"63556","381.30000","31.77521","0.73342"
"63618","381.67200","31.80618","0.73591"
"63680","382.04400","31.83727","0.73814"
"63742","382.41600","31.86818","0.74165"
"63804","382.78800","31.89915","0.74499"
"63866","383.16000","31.93024","0.75330"
"63928","383.53200","31.96127","0.75994"
"63990","383.90400","31.99212","0.75226"
"64052","384.27600","32.02321","0.75864"
"64114","384.64800","32.05418","0.75999"
"64176","385.02000","32.08521","0.76515"
"64238","385.39200","32.11618","0.77121"
"64300","385.76400","32.14722","0.77324"
"64362","386.13600","32.17825","0.77641"
"64424","386.50800","32.20916","0.78307"
"64486","386.88000","32.24025","0.78859"
"64548","387.25200","32.27122","0.79257"
"64610","387.62400","32.30213","0.79909"
"64672","387.99600","32.33328","0.80655"
"64734","388.36800","32.36425","0.81161"
"64796","388.74000","32.39511","0.81581"
"64858","389.11200","32.42619","0.81963"
"64920","389.48400","32.45723","0.82329"
"64982","389.85600","32.48820","0.82584"
"65044","390.22800","32.51917","0.28071"
"65106","390.60000","32.55025","0.20550"
"65168","390.97200","32.58117","0.19881"
"65230","391.34400","32.61220","0.19998"
"65292","391.71600","32.64323","0.19607"
"65354","392.08800","32.67420","0.14389"
"65416","392.46000","32.70517","0.14323"
"65478","392.83200","32.73621","0.14508"
"65540","393.20400","32.76730","0.14687"
"65602","393.57600","32.79815","0.14925"
"65664","393.94800","32.82918","0.15142"
"65726","394.32000","32.86021","0.15200"
"65788","394.69200","32.89118","0.15298"
"65850","395.06400","32.92215","0.15376"
"65912","395.43600","32.95324","0.15622"
"65974","395.80800","32.98415","0.15909"
"66036","396.18000","33.01518","0.15888"
"66098","396.55200","33.04621","0.15979"
"66160","396.92400","33.07724","0.16023"
"66222","397.29600","33.10815","0.16223"
"66284","397.66800","33.13918","0.16319"
"66346","398.04000","33.17028","0.16339"
"66408","398.41200","33.20113","0.16398"
"66470","398.78400","33.23222","0.16499"
"66532","399.15600","33.26325","0.16698"
"66594","399.52800","33.29416","0.16704"
"66656","399.90000","33.32519","0.16896"
"66718","400.27200","33.35616","0.16972"
"66780","400.64400","33.38719","0.17028"
"66842","401.01600","33.41822","0.17109"
"66904","401.38800","33.44920","0.17325"
"66966","401.76000","33.48022","0.17526"
"67028","402.13200","33.51114","0.17829"
"67090","402.50400","33.54217","0.18077"
"67152","402.87600","33.57320","0.18110"
"67214","403.24800","33.60417","0.18312"
"67276","403.62000","33.63526","0.18467"
"67338","403.99200","33.66617","0.18704"
"67400","404.36400","33.69720","0.18792"
"67462","404.73600","33.72817","0.18998"
"67524","405.10800","33.75920","0.19183"
"67586","405.48000","33.79018","0.19408"
"67648","405.85200","33.82114","0.19416"
"67710","406.22400","33.85223","0.19624"
"67772","406.59600","33.88315","0.19809"
"67834","406.96800","33.91418","0.19971"
"67896","407.34000","33.94527","0.20158"
"67958","407.71200","33.97624","0.20270"
"68020","408.08400","34.00721","0.20280"
"68082","408.45600","34.03824","0.20323"
"68144","408.82800","34.06915","0.20454"
"68206","409.20000","34.10018","0.20601"
"68268","409.57200","34.13121","0.20708"
"68330","409.94400","34.16225","0.20779"
"68392","410.31600","34.19321","0.20786"
"68454","410.68800","34.22419","0.20859"
"68516","411.06000","34.25522","0.20985"
"68578","411.43200","34.28613","0.21163"
"68640","411.80400","34.31722","0.21316"
"68702","412.17600","34.34819","0.21527"
"68764","412.54800","34.37922","0.21652"
"68826","412.92000","34.41013","0.21802"
"68888","413.29200","34.44116","0.21993"
"68950","413.66400","34.47225","0.22151"
"69012","414.03600","34.50317","0.22340"
"69074","414.40800","34.53419","0.22572"
"69136","414.78000","34.56517","0.22780"
"69198","415.15200","34.59614","0.22990"
"69260","415.52400","34.62717","0.23272"
"69322","415.89600","34.65820","0.23434"
"69384","416.26800","34.68923","0.23498"
"69446","416.64000","34.72020","0.23738"
"69508","417.01200","34.75123","0.23944"
"69570","417.38400","34.78220","0.24148"
"69632","417.75600","34.81317","0.24335"
"69694","418.12800","34.84420","0.24439"
"69756","418.50000","34.87517","0.24584"
"69818","418.87200","34.90620","0.24728"
"69880","419.24400","34.93724","0.24889"
"69942","419.61600","34.96821","0.25194"
"70004","419.98800","34.99924","0.25392"
"70066","420.36000","35.03015","0.25498"
"70128","420.73200","35.06124","0.25723"
"70190","421.10400","35.09221","0.25877"
"70252","421.47600","35.12318","0.26039"
"70314","421.84800","35.15421","0.26096"
"70376","422.22000","35.18525","0.26270"
"70438","422.59200","35.21615","0.26613"
"70500","422.96400","35.24718","0.26942"
"70562","423.33600","35.27822","0.27264"
"70624","423.70800","35.30919","0.27570"
"70686","424.08000","35.34016","0.27733"
"70748","424.45200","35.37125","0.19133"
"70810","424.82400","35.40216","0.19042"
"70872","425.19600","35.43319","0.18716"
"70934","425.56800","35.46422","0.18554"
"70996","425.94000","35.49519","0.18721"
"71058","426.31200","35.52622","0.19245"
"71120","426.68400","35.55725","0.19556"
"71182","427.05600","35.58822","0.19645"
"71244","427.42800","35.61919","0.19915"
"71306","427.80000","35.65023","0.20204"
"71368","428.17200","35.68126","0.20395"
"71430","428.54400","35.71211","0.20493"
"71492","428.91600","35.74320","0.20645"
"71554","429.28800","35.77423","0.20766"
"71616","429.66000","35.80514","0.20950"
"71678","430.03200","35.83623","0.21154"
"71740","430.40400","35.86720","0.21148"
"71802","430.77600","35.89817","0.21199"
"71864","431.14800","35.92920","0.21233"
"71926","431.52000","35.96024","0.21328"
"71988","431.89200","35.99127","0.21612"
"72050","432.26400","36.02218","0.21778"
"72112","432.63600","36.05321","0.22005"
"72174","433.00800","36.08418","0.22051"
"72236","433.38000","36.11515","0.22239"
"72298","433.75200","36.14624","0.22431"
"72360","434.12400","36.17715","0.22598"
"72422","434.49600","36.20818","0.22730"
"72484","434.86800","36.23922","0.22878"
"72546","435.24000","36.27018","0.23078"
"72608","435.61200","36.30122","0.23234"
"72670","435.98400","36.33219","0.01218"
"72732","436.35600","36.36328","0.00329"
"72794","436.72800","36.39419","0.00213"
"72856","437.10000","36.42516","0.00126"
"72918","437.47200","36.45625","0.00191"
"72980","437.84400","36.48716","0.00223"
"73042","438.21600","36.51813","0.00174"
"73104","438.58800","36.54922","0.00144"
"73166","438.96000","36.58025","0.00131"
"73228","439.33200","36.61116","0.00110"
"73290","439.70400","36.64219","0.00114"
"73352","440.07600","36.67323","0.00122"
"73414","440.44800","36.70414","0.00024"
"73476","440.82000","36.73516","0.00072"
"73538","441.19200","36.76626","0.00220"
"73600","441.56400","36.79717","0.00101"
"73662","441.93600","36.82820","0.00082"
"73724","442.30800","36.85923","0.00225"
"73786","442.68000","36.89020","0.00140"
"73848","443.05200","36.92117","0.00099"
"73910","443.42400","36.95221","0.00218"
"73972","443.79600","36.98323","0.00101"
"74034","444.16800","37.01414","0.00202"
"74096","444.54000","37.04524","0.00177"
"74158","444.91200","37.07621","0.00152"
"74220","445.28400","37.10718","0.00115"
"74282","445.65600","37.13821","0.00083"
"74344","446.02800","37.16924","0.00141"
"74406","446.40000","37.20015","0.00170"
"74468","446.77200","37.23112","0.00138"
"74530","447.14400","37.26227","0.00152"
"74592","447.51600","37.29324","0.00146"
"74654","447.88800","37.32415","0.00123"
"74716","448.26000","37.35524","0.00154"
"74778","448.63200","37.38622","0.00128"
"74840","449.00400","37.41713","0.00079"
"74902","449.37600","37.44822","0.00140"
"74964","449.74800","37.47919","0.00127"
"75026","450.12000","37.51022","0.00068"
"75088","450.49200","37.54119","0.00205"
"75150","450.86400","37.57222","0.00083"
"75212","451.23600","37.60319","0.00095"
"75274","451.60800","37.63416","0.00153"
"75336","451.98000","37.66526","0.00049"
"75398","452.35200","37.69622","0.00072"
"75460","452.72400","37.72720","0.00112"
"75522","453.09600","37.75817","0.00086"
"75584","453.46800","37.78920","0.00049"
"75646","453.84000","37.82017","0.00100"
"75708","454.21200","37.85120","0.00122"
"75757","454.50600","37.87565","0.00056"