File: Trajectories_together/161217Specimen_RawData_3.csv
"","V1","V2","V3"
"1","End date","12/17/2016",""
"2","Specimen label","6CT_43",""
"3","Maximum Load","0.38913","N"
"4","Time","Extension","Load"
"5","(s)","(mm)","(N)"
"6","0.00000","0.00000","-0.00001"
"43","0.22200","0.01566","0.00040"
"80","0.44400","0.03725","0.00146"
"117","0.66600","0.05572","0.00197"
"154","0.88800","0.07414","0.00251"
"191","1.11000","0.09267","0.00260"
"228","1.33200","0.11121","0.00309"
"265","1.55400","0.12962","0.00274"
"302","1.77600","0.14822","0.00307"
"339","1.99800","0.16663","0.00327"
"376","2.22000","0.18523","0.00325"
"413","2.44200","0.20370","0.00361"
"450","2.66400","0.22218","0.00349"
"487","2.88600","0.24071","0.00370"
"524","3.10800","0.25913","0.00385"
"561","3.33000","0.27766","0.00395"
"598","3.55200","0.29620","0.00414"
"635","3.77400","0.31461","0.00408"
"672","3.99600","0.33315","0.00450"
"709","4.21800","0.35168","0.00417"
"746","4.44000","0.37022","0.00426"
"783","4.66200","0.38869","0.00445"
"820","4.88400","0.40717","0.00434"
"857","5.10600","0.42564","0.00419"
"894","5.32800","0.44406","0.00488"
"931","5.55000","0.46271","0.00418"
"968","5.77200","0.48113","0.00460"
"1005","5.99400","0.49966","0.00462"
"1042","6.21600","0.51820","0.00450"
"1079","6.43800","0.53661","0.00450"
"1116","6.66000","0.55515","0.00468"
"1153","6.88200","0.57362","0.00494"
"1190","7.10400","0.59216","0.00480"
"1227","7.32600","0.61063","0.00475"
"1264","7.54800","0.62917","0.00489"
"1301","7.77000","0.64764","0.00505"
"1338","7.99200","0.66612","0.00498"
"1375","8.21400","0.68465","0.00511"
"1412","8.43600","0.70312","0.00512"
"1449","8.65800","0.72166","0.00507"
"1486","8.88000","0.74019","0.00499"
"1523","9.10200","0.75867","0.00490"
"1560","9.32400","0.77714","0.00518"
"1597","9.54600","0.79562","0.00523"
"1634","9.76800","0.81415","0.00514"
"1671","9.99000","0.83269","0.00527"
"1708","10.21200","0.85110","0.00542"
"1745","10.43400","0.86970","0.00526"
"1782","10.65600","0.88811","0.00518"
"1819","10.87800","0.90665","0.00510"
"1856","11.10000","0.92518","0.00533"
"1893","11.32200","0.94366","0.00534"
"1930","11.54400","0.96219","0.00529"
"1967","11.76600","0.98061","0.00576"
"2004","11.98800","0.99920","0.00562"
"2041","12.21000","1.01768","0.00523"
"2078","12.43200","1.03615","0.00535"
"2115","12.65400","1.05463","0.00550"
"2152","12.87600","1.07310","0.00581"
"2189","13.09800","1.09164","0.00575"
"2226","13.32000","1.11017","0.00558"
"2263","13.54200","1.12865","0.00583"
"2300","13.76400","1.14712","0.00590"
"2337","13.98600","1.16560","0.00591"
"2374","14.20800","1.18413","0.00600"
"2411","14.43000","1.20261","0.00549"
"2448","14.65200","1.22114","0.00614"
"2485","14.87400","1.23974","0.00589"
"2522","15.09600","1.25815","0.00564"
"2559","15.31800","1.27669","0.00610"
"2596","15.54000","1.29510","0.00626"
"2633","15.76200","1.31370","0.00603"
"2670","15.98400","1.33211","0.00615"
"2707","16.20600","1.35065","0.00581"
"2744","16.42800","1.36918","0.00611"
"2781","16.65000","1.38760","0.00578"
"2818","16.87200","1.40619","0.00636"
"2855","17.09400","1.42461","0.00630"
"2892","17.31600","1.44320","0.00609"
"2929","17.53800","1.46161","0.00597"
"2966","17.76000","1.48015","0.00655"
"3003","17.98200","1.49868","0.00610"
"3040","18.20400","1.51710","0.00637"
"3077","18.42600","1.53563","0.00631"
"3114","18.64800","1.55417","0.00656"
"3151","18.87000","1.57270","0.00665"
"3188","19.09200","1.59118","0.00633"
"3225","19.31400","1.60965","0.00651"
"3262","19.53600","1.62819","0.00663"
"3299","19.75800","1.64666","0.00700"
"3336","19.98000","1.66514","0.00647"
"3373","20.20200","1.68367","0.00690"
"3410","20.42400","1.70209","0.00655"
"3447","20.64600","1.72062","0.00672"
"3484","20.86800","1.73916","0.00688"
"3521","21.09000","1.75769","0.00701"
"3558","21.31200","1.77617","0.00700"
"3595","21.53400","1.79464","0.00697"
"3632","21.75600","1.81324","0.00686"
"3669","21.97800","1.83165","0.00660"
"3706","22.20000","1.85019","0.00684"
"3743","22.42200","1.86860","0.00673"
"3780","22.64400","1.88714","0.00717"
"3817","22.86600","1.90567","0.00732"
"3854","23.08800","1.92415","0.00707"
"3891","23.31000","1.94268","0.00690"
"3928","23.53200","1.96116","0.00719"
"3965","23.75400","1.97969","0.00735"
"4002","23.97600","1.99817","0.00704"
"4039","24.19800","2.01664","0.00737"
"4076","24.42000","2.03512","0.00723"
"4113","24.64200","2.05359","0.00739"
"4150","24.86400","2.07219","0.00732"
"4187","25.08600","2.09066","0.00747"
"4224","25.30800","2.10914","0.00758"
"4261","25.53000","2.12767","0.00773"
"4298","25.75200","2.14615","0.00770"
"4335","25.97400","2.16468","0.00769"
"4372","26.19600","2.18321","0.00747"
"4409","26.41800","2.20157","0.00772"
"4446","26.64000","2.22022","0.00773"
"4483","26.86200","2.23858","0.00803"
"4520","27.08400","2.25717","0.00779"
"4557","27.30600","2.27565","0.00752"
"4594","27.52800","2.29412","0.00770"
"4631","27.75000","2.31266","0.00783"
"4668","27.97200","2.33113","0.00823"
"4705","28.19400","2.34973","0.00789"
"4742","28.41600","2.36808","0.00773"
"4779","28.63800","2.38668","0.00800"
"4816","28.86000","2.40515","0.00819"
"4853","29.08200","2.42363","0.00821"
"4890","29.30400","2.44210","0.00837"
"4927","29.52600","2.46064","0.00834"
"4964","29.74800","2.47917","0.00806"
"5001","29.97000","2.49765","0.00863"
"5038","30.19200","2.51618","0.00852"
"5075","30.41400","2.53472","0.00833"
"5112","30.63600","2.55313","0.00837"
"5149","30.85800","2.57161","0.00865"
"5186","31.08000","2.59014","0.00859"
"5223","31.30200","2.60874","0.00877"
"5260","31.52400","2.62715","0.00860"
"5297","31.74600","2.64569","0.00870"
"5334","31.96800","2.66422","0.00778"
"5371","32.19000","2.68264","0.00756"
"5408","32.41200","2.70117","0.00757"
"5445","32.63400","2.71965","0.00780"
"5482","32.85600","2.73812","0.00805"
"5519","33.07800","2.75666","0.00809"
"5556","33.30000","2.77507","0.00769"
"5593","33.52200","2.79373","0.00803"
"5630","33.74400","2.81214","0.00823"
"5667","33.96600","2.83068","0.00844"
"5704","34.18800","2.84915","0.00837"
"5741","34.41000","2.86763","0.00778"
"5778","34.63200","2.88616","0.00808"
"5815","34.85400","2.90464","0.00817"
"5852","35.07600","2.92317","0.00851"
"5889","35.29800","2.94165","0.00845"
"5926","35.52000","2.96012","0.00836"
"5963","35.74200","2.97865","0.00871"
"6000","35.96400","2.99713","0.00814"
"6037","36.18600","3.01566","0.00889"
"6074","36.40800","3.03420","0.00837"
"6111","36.63000","3.05267","0.00853"
"6148","36.85200","3.07121","0.00882"
"6185","37.07400","3.08962","0.00894"
"6222","37.29600","3.10816","0.00897"
"6259","37.51800","3.12663","0.00916"
"6296","37.74000","3.14511","0.00907"
"6333","37.96200","3.16370","0.00894"
"6370","38.18400","3.18206","0.00935"
"6407","38.40600","3.20065","0.00876"
"6444","38.62800","3.21913","0.00946"
"6481","38.85000","3.23766","0.00907"
"6518","39.07200","3.25614","0.00945"
"6555","39.29400","3.27467","0.00922"
"6592","39.51600","3.29315","0.00949"
"6629","39.73800","3.31162","0.00942"
"6666","39.96000","3.33022","0.00931"
"6703","40.18200","3.34863","0.00938"
"6740","40.40400","3.36717","0.00930"
"6777","40.62600","3.38570","0.00932"
"6814","40.84800","3.40412","0.00945"
"6851","41.07000","3.42265","0.01014"
"6888","41.29200","3.44119","0.00966"
"6925","41.51400","3.45966","0.00983"
"6962","41.73600","3.47820","0.00957"
"6999","41.95800","3.49661","0.00946"
"7036","42.18000","3.51515","0.01016"
"7073","42.40200","3.53362","0.01016"
"7110","42.62400","3.55216","0.01013"
"7147","42.84600","3.57069","0.01005"
"7184","43.06800","3.58917","0.01007"
"7221","43.29000","3.60776","0.01015"
"7258","43.51200","3.62612","0.00992"
"7295","43.73400","3.64471","0.01030"
"7332","43.95600","3.66313","0.01026"
"7369","44.17800","3.68166","0.01052"
"7406","44.40000","3.70019","0.01006"
"7443","44.62200","3.71861","0.01055"
"7480","44.84400","3.73720","0.01070"
"7517","45.06600","3.75562","0.01066"
"7554","45.28800","3.77421","0.01077"
"7591","45.51000","3.79269","0.01092"
"7628","45.73200","3.81116","0.01101"
"7665","45.95400","3.82964","0.01084"
"7702","46.17600","3.84817","0.01084"
"7739","46.39800","3.86665","0.01086"
"7776","46.62000","3.88518","0.01130"
"7813","46.84200","3.90366","0.01136"
"7850","47.06400","3.92213","0.01130"
"7887","47.28600","3.94067","0.01136"
"7924","47.50800","3.95914","0.01106"
"7961","47.73000","3.97768","0.01130"
"7998","47.95200","3.99615","0.01147"
"8035","48.17400","4.01463","0.01160"
"8072","48.39600","4.03310","0.01088"
"8109","48.61800","4.05164","0.01096"
"8146","48.84000","4.07011","0.01112"
"8183","49.06200","4.08865","0.01112"
"8220","49.28400","4.10718","0.01116"
"8257","49.50600","4.12560","0.01081"
"8294","49.72800","4.14419","0.01124"
"8331","49.95000","4.16261","0.01132"
"8368","50.17200","4.18126","0.01191"
"8405","50.39400","4.19962","0.01093"
"8442","50.61600","4.21815","0.01163"
"8479","50.83800","4.23669","0.01141"
"8516","51.06000","4.25510","0.01138"
"8553","51.28200","4.27370","0.01175"
"8590","51.50400","4.29211","0.01207"
"8627","51.72600","4.31065","0.01214"
"8664","51.94800","4.32918","0.01236"
"8701","52.17000","4.34766","0.01135"
"8738","52.39200","4.36613","0.01170"
"8775","52.61400","4.38467","0.01187"
"8812","52.83600","4.40314","0.01182"
"8849","53.05800","4.42173","0.01200"
"8886","53.28000","4.44009","0.01207"
"8923","53.50200","4.45868","0.01235"
"8960","53.72400","4.47716","0.01236"
"8997","53.94600","4.49569","0.01206"
"9034","54.16800","4.51417","0.01246"
"9071","54.39000","4.53264","0.01285"
"9108","54.61200","4.55118","0.01260"
"9145","54.83400","4.56953","0.01245"
"9182","55.05600","4.58819","0.01270"
"9219","55.27800","4.60666","0.01264"
"9256","55.50000","4.62514","0.01301"
"9293","55.72200","4.64367","0.01286"
"9330","55.94400","4.66215","0.01321"
"9367","56.16600","4.68068","0.01326"
"9404","56.38800","4.69916","0.01332"
"9441","56.61000","4.71769","0.01303"
"9478","56.83200","4.73611","0.01333"
"9515","57.05400","4.75464","0.01339"
"9552","57.27600","4.77318","0.01386"
"9589","57.49800","4.79165","0.01418"
"9626","57.72000","4.81013","0.01380"
"9663","57.94200","4.82866","0.01412"
"9700","58.16400","4.84714","0.01464"
"9737","58.38600","4.86567","0.01411"
"9774","58.60800","4.88409","0.01460"
"9811","58.83000","4.90268","0.01488"
"9848","59.05200","4.92116","0.01412"
"9885","59.27400","4.93963","0.01490"
"9922","59.49600","4.95817","0.01506"
"9959","59.71800","4.97658","0.01453"
"9996","59.94000","4.99518","0.01493"
"10033","60.16200","5.01365","0.01551"
"10070","60.38400","5.03219","0.01555"
"10107","60.60600","5.05066","0.01515"
"10144","60.82800","5.06914","0.01566"
"10181","61.05000","5.08767","0.01579"
"10218","61.27200","5.10615","0.01613"
"10255","61.49400","5.12468","0.01602"
"10292","61.71600","5.14316","0.01583"
"10329","61.93800","5.16169","0.01614"
"10366","62.16000","5.18017","0.01640"
"10403","62.38200","5.19864","0.01654"
"10440","62.60400","5.21712","0.01677"
"10477","62.82600","5.23565","0.01663"
"10514","63.04800","5.25412","0.01656"
"10551","63.27000","5.27266","0.01666"
"10588","63.49200","5.29113","0.01631"
"10625","63.71400","5.30967","0.01731"
"10662","63.93600","5.32814","0.01712"
"10699","64.15800","5.34668","0.01751"
"10736","64.38000","5.36521","0.01656"
"10773","64.60200","5.38363","0.01734"
"10810","64.82400","5.40222","0.01653"
"10847","65.04600","5.42064","0.01643"
"10884","65.26800","5.43917","0.01665"
"10921","65.49000","5.45765","0.01682"
"10958","65.71200","5.47618","0.01667"
"10995","65.93400","5.49472","0.01738"
"11032","66.15600","5.51307","0.01745"
"11069","66.37800","5.53167","0.01736"
"11106","66.60000","5.55014","0.01789"
"11143","66.82200","5.56868","0.01745"
"11180","67.04400","5.58715","0.01813"
"11217","67.26600","5.60563","0.01815"
"11254","67.48800","5.62416","0.01819"
"11291","67.71000","5.64264","0.01839"
"11328","67.93200","5.66117","0.01853"
"11365","68.15400","5.67965","0.01874"
"11402","68.37600","5.69818","0.01893"
"11439","68.59800","5.71666","0.01933"
"11476","68.82000","5.73513","0.01946"
"11513","69.04200","5.75367","0.01951"
"11550","69.26400","5.77214","0.01909"
"11587","69.48600","5.79062","0.01971"
"11624","69.70800","5.80915","0.01966"
"11661","69.93000","5.82763","0.01987"
"11698","70.15200","5.84616","0.02062"
"11735","70.37400","5.86464","0.02099"
"11772","70.59600","5.88311","0.02038"
"11809","70.81800","5.90170","0.02091"
"11846","71.04000","5.92012","0.02114"
"11883","71.26200","5.93866","0.02139"
"11920","71.48400","5.95707","0.02166"
"11957","71.70600","5.97572","0.02163"
"11994","71.92800","5.99414","0.02198"
"12031","72.15000","6.01261","0.02266"
"12068","72.37200","6.03115","0.02260"
"12105","72.59400","6.04962","0.02272"
"12142","72.81600","6.06816","0.02321"
"12179","73.03800","6.08669","0.02341"
"12216","73.26000","6.10517","0.02304"
"12253","73.48200","6.12364","0.02311"
"12290","73.70400","6.14218","0.02422"
"12327","73.92600","6.16065","0.02445"
"12364","74.14800","6.17913","0.02427"
"12401","74.37000","6.19766","0.02504"
"12438","74.59200","6.21614","0.02478"
"12475","74.81400","6.23467","0.02505"
"12512","75.03600","6.25321","0.02562"
"12549","75.25800","6.27162","0.02563"
"12586","75.48000","6.29022","0.02624"
"12623","75.70200","6.30869","0.02656"
"12660","75.92400","6.32717","0.02660"
"12697","76.14600","6.34564","0.02624"
"12734","76.36800","6.36406","0.02656"
"12771","76.59000","6.38271","0.02633"
"12808","76.81200","6.40113","0.02699"
"12845","77.03400","6.41966","0.02696"
"12882","77.25600","6.43820","0.02765"
"12919","77.47800","6.45655","0.02811"
"12956","77.70000","6.47521","0.02826"
"12993","77.92200","6.49362","0.02899"
"13030","78.14400","6.51222","0.02871"
"13067","78.36600","6.53063","0.02956"
"13104","78.58800","6.54917","0.03010"
"13141","78.81000","6.56764","0.03013"
"13178","79.03200","6.58612","0.03024"
"13215","79.25400","6.60465","0.03066"
"13252","79.47600","6.62313","0.03104"
"13289","79.69800","6.64166","0.03157"
"13326","79.92000","6.66019","0.03194"
"13363","80.14200","6.67861","0.03170"
"13400","80.36400","6.69715","0.03218"
"13437","80.58600","6.71562","0.03303"
"13474","80.80800","6.73416","0.03319"
"13511","81.03000","6.75263","0.03385"
"13548","81.25200","6.77111","0.03385"
"13585","81.47400","6.78970","0.03395"
"13622","81.69600","6.80811","0.03393"
"13659","81.91800","6.82671","0.03465"
"13696","82.14000","6.84518","0.03524"
"13733","82.36200","6.86366","0.03594"
"13770","82.58400","6.88219","0.03591"
"13807","82.80600","6.90067","0.03649"
"13844","83.02800","6.91920","0.03677"
"13881","83.25000","6.93762","0.03710"
"13918","83.47200","6.95615","0.03767"
"13955","83.69400","6.97463","0.03785"
"13992","83.91600","6.99310","0.03811"
"14029","84.13800","7.01164","0.03900"
"14066","84.36000","7.03011","0.03871"
"14103","84.58200","7.04865","0.04005"
"14140","84.80400","7.06718","0.03980"
"14177","85.02600","7.08566","0.03998"
"14214","85.24800","7.10413","0.04110"
"14251","85.47000","7.12261","0.04084"
"14288","85.69200","7.14120","0.04191"
"14325","85.91400","7.15968","0.04198"
"14362","86.13600","7.17809","0.04217"
"14399","86.35800","7.19669","0.04290"
"14436","86.58000","7.21510","0.04321"
"14473","86.80200","7.23364","0.04326"
"14510","87.02400","7.25211","0.04383"
"14547","87.24600","7.27065","0.04411"
"14584","87.46800","7.28918","0.04457"
"14621","87.69000","7.30760","0.04451"
"14658","87.91200","7.32613","0.04521"
"14695","88.13400","7.34467","0.04479"
"14732","88.35600","7.36314","0.04502"
"14769","88.57800","7.38168","0.04567"
"14806","88.80000","7.40015","0.04560"
"14843","89.02200","7.41868","0.04574"
"14880","89.24400","7.43710","0.04594"
"14917","89.46600","7.45570","0.04682"
"14954","89.68800","7.47417","0.04682"
"14991","89.91000","7.49270","0.04712"
"15028","90.13200","7.51112","0.04680"
"15065","90.35400","7.52965","0.04761"
"15102","90.57600","7.54813","0.04777"
"15139","90.79800","7.56666","0.04788"
"15176","91.02000","7.58514","0.04813"
"15213","91.24200","7.60361","0.04797"
"15250","91.46400","7.62209","0.04864"
"15287","91.68600","7.64068","0.04892"
"15324","91.90800","7.65910","0.04923"
"15361","92.13000","7.67763","0.04962"
"15398","92.35200","7.69617","0.04966"
"15435","92.57400","7.71464","0.04993"
"15472","92.79600","7.73324","0.05045"
"15509","93.01800","7.75159","0.05045"
"15546","93.24000","7.77019","0.05114"
"15583","93.46200","7.78860","0.05127"
"15620","93.68400","7.80714","0.05176"
"15657","93.90600","7.82567","0.05251"
"15694","94.12800","7.84409","0.05294"
"15731","94.35000","7.86274","0.05325"
"15768","94.57200","7.88110","0.05394"
"15805","94.79400","7.89969","0.05376"
"15842","95.01600","7.91817","0.05458"
"15879","95.23800","7.93664","0.05538"
"15916","95.46000","7.95518","0.05568"
"15953","95.68200","7.97359","0.05637"
"15990","95.90400","7.99213","0.05744"
"16027","96.12600","8.01066","0.05752"
"16064","96.34800","8.02914","0.05775"
"16101","96.57000","8.04767","0.05855"
"16138","96.79200","8.06615","0.05916"
"16175","97.01400","8.08462","0.06015"
"16212","97.23600","8.10316","0.06096"
"16249","97.45800","8.12169","0.06127"
"16286","97.68000","8.14023","0.06220"
"16323","97.90200","8.15858","0.06289"
"16360","98.12400","8.17718","0.06354"
"16397","98.34600","8.19565","0.06452"
"16434","98.56800","8.21413","0.06566"
"16471","98.79000","8.23266","0.06658"
"16508","99.01200","8.25107","0.06592"
"16545","99.23400","8.26967","0.05156"
"16582","99.45600","8.28814","0.05087"
"16619","99.67800","8.30668","0.05154"
"16656","99.90000","8.32515","0.05174"
"16693","100.12200","8.34363","0.05245"
"16730","100.34400","8.36216","0.05272"
"16767","100.56600","8.38064","0.05414"
"16804","100.78800","8.39917","0.05487"
"16841","101.01000","8.41765","0.05536"
"16878","101.23200","8.43618","0.05693"
"16915","101.45400","8.45466","0.05652"
"16952","101.67600","8.47313","0.05822"
"16989","101.89800","8.49161","0.05899"
"17026","102.12000","8.51014","0.06009"
"17063","102.34200","8.52868","0.06074"
"17100","102.56400","8.54721","0.06243"
"17137","102.78600","8.56563","0.06279"
"17174","103.00800","8.58416","0.06460"
"17211","103.23000","8.60264","0.06503"
"17248","103.45200","8.62123","0.06708"
"17285","103.67400","8.63965","0.06783"
"17322","103.89600","8.65818","0.06886"
"17359","104.11800","8.67672","0.06899"
"17396","104.34000","8.69507","0.06986"
"17433","104.56200","8.71373","0.07158"
"17470","104.78400","8.73214","0.07198"
"17507","105.00600","8.75062","0.07242"
"17544","105.22800","8.76921","0.05959"
"17581","105.45000","8.78763","0.05293"
"17618","105.67200","8.80616","0.03727"
"17655","105.89400","8.82458","0.03686"
"17692","106.11600","8.84317","0.03557"
"17729","106.33800","8.86165","0.03797"
"17766","106.56000","8.88018","0.03816"
"17803","106.78200","8.89866","0.03789"
"17840","107.00400","8.91713","0.03989"
"17877","107.22600","8.93567","0.03820"
"17914","107.44800","8.95414","0.04049"
"17951","107.67000","8.97262","0.03986"
"17988","107.89200","8.99115","0.03999"
"18025","108.11400","9.00962","0.04130"
"18062","108.33600","9.02816","0.04211"
"18099","108.55800","9.04663","0.04167"
"18136","108.78000","9.06517","0.04218"
"18173","109.00200","9.08364","0.04320"
"18210","109.22400","9.10212","0.04300"
"18247","109.44600","9.12065","0.04418"
"18284","109.66800","9.13907","0.04400"
"18321","109.89000","9.15766","0.04428"
"18358","110.11200","9.17620","0.04481"
"18395","110.33400","9.19461","0.04517"
"18432","110.55600","9.21321","0.04479"
"18469","110.77800","9.23162","0.04585"
"18506","111.00000","9.25022","0.04604"
"18543","111.22200","9.26869","0.04646"
"18580","111.44400","9.28717","0.04681"
"18617","111.66600","9.30570","0.04715"
"18654","111.88800","9.32412","0.04722"
"18691","112.11000","9.34265","0.04734"
"18728","112.33200","9.36113","0.04826"
"18765","112.55400","9.37960","0.04760"
"18802","112.77600","9.39814","0.04841"
"18839","112.99800","9.41661","0.04907"
"18876","113.22000","9.43521","0.04923"
"18913","113.44200","9.45362","0.04929"
"18950","113.66400","9.47216","0.05014"
"18987","113.88600","9.49069","0.04989"
"19024","114.10800","9.50905","0.05090"
"19061","114.33000","9.52770","0.05170"
"19098","114.55200","9.54606","0.05101"
"19135","114.77400","9.56465","0.05182"
"19172","114.99600","9.58313","0.05275"
"19209","115.21800","9.60166","0.05312"
"19246","115.44000","9.62020","0.05284"
"19283","115.66200","9.63861","0.05424"
"19320","115.88400","9.65720","0.05413"
"19357","116.10600","9.67562","0.05576"
"19394","116.32800","9.69416","0.05513"
"19431","116.55000","9.71269","0.05725"
"19468","116.77200","9.73116","0.05705"
"19505","116.99400","9.74964","0.05856"
"19542","117.21600","9.76812","0.05903"
"19579","117.43800","9.78671","0.06037"
"19616","117.66000","9.80512","0.06102"
"19653","117.88200","9.82366","0.06294"
"19690","118.10400","9.84213","0.06307"
"19727","118.32600","9.86061","0.06464"
"19764","118.54800","9.87914","0.06554"
"19801","118.77000","9.89762","0.06650"
"19838","118.99200","9.91615","0.06706"
"19875","119.21400","9.93463","0.06842"
"19912","119.43600","9.95310","0.06966"
"19949","119.65800","9.97164","0.07043"
"19986","119.88000","9.99011","0.07094"
"20023","120.10200","10.00871","0.07218"
"20060","120.32400","10.02718","0.07279"
"20097","120.54600","10.04560","0.07369"
"20134","120.76800","10.06419","0.07523"
"20171","120.99000","10.08267","0.07542"
"20208","121.21200","10.10120","0.06572"
"20245","121.43400","10.11962","0.06183"
"20282","121.65600","10.13815","0.06232"
"20319","121.87800","10.15669","0.06339"
"20356","122.10000","10.17510","0.06438"
"20393","122.32200","10.19370","0.06482"
"20430","122.54400","10.21211","0.06704"
"20467","122.76600","10.23065","0.06723"
"20504","122.98800","10.24918","0.06839"
"20541","123.21000","10.26766","0.06917"
"20578","123.43200","10.28613","0.07069"
"20615","123.65400","10.30461","0.07221"
"20652","123.87600","10.32314","0.07351"
"20689","124.09800","10.34168","0.07371"
"20726","124.32000","10.36015","0.07495"
"20763","124.54200","10.37869","0.07539"
"20800","124.76400","10.39710","0.07720"
"20837","124.98600","10.41570","0.07703"
"20874","125.20800","10.43417","0.07860"
"20911","125.43000","10.45265","0.07903"
"20948","125.65200","10.47118","0.08007"
"20985","125.87400","10.48959","0.08064"
"21022","126.09600","10.50819","0.08232"
"21059","126.31800","10.52660","0.08326"
"21096","126.54000","10.54514","0.08430"
"21133","126.76200","10.56367","0.08501"
"21170","126.98400","10.58209","0.08598"
"21207","127.20600","10.60068","0.08658"
"21244","127.42800","10.61910","0.08795"
"21281","127.65000","10.63769","0.08836"
"21318","127.87200","10.65617","0.08971"
"21355","128.09400","10.67464","0.08977"
"21392","128.31600","10.69318","0.09051"
"21429","128.53800","10.71159","0.09153"
"21466","128.76000","10.73019","0.09234"
"21503","128.98200","10.74866","0.09275"
"21540","129.20400","10.76714","0.09320"
"21577","129.42600","10.78573","0.09331"
"21614","129.64800","10.80415","0.09446"
"21651","129.87000","10.82262","0.09429"
"21688","130.09200","10.84116","0.07366"
"21725","130.31400","10.85957","0.07838"
"21762","130.53600","10.87823","0.07585"
"21799","130.75800","10.89658","0.07950"
"21836","130.98000","10.91518","0.07990"
"21873","131.20200","10.93365","0.08084"
"21910","131.42400","10.95219","0.08161"
"21947","131.64600","10.97066","0.08422"
"21984","131.86800","10.98914","0.08406"
"22021","132.09000","11.00767","0.08530"
"22058","132.31200","11.02609","0.08656"
"22095","132.53400","11.04474","0.08841"
"22132","132.75600","11.06310","0.08789"
"22169","132.97800","11.08169","0.08970"
"22206","133.20000","11.10017","0.09031"
"22243","133.42200","11.11864","0.09083"
"22280","133.64400","11.13718","0.09121"
"22317","133.86600","11.15565","0.09288"
"22354","134.08800","11.17419","0.09295"
"22391","134.31000","11.19260","0.09371"
"22428","134.53200","11.21114","0.09399"
"22465","134.75400","11.22961","0.09477"
"22502","134.97600","11.24815","0.09519"
"22539","135.19800","11.26668","0.09555"
"22576","135.42000","11.28515","0.09587"
"22613","135.64200","11.30369","0.09640"
"22650","135.86400","11.32216","0.09642"
"22687","136.08600","11.34064","0.09679"
"22724","136.30800","11.35917","0.09702"
"22761","136.53000","11.37765","0.09779"
"22798","136.75200","11.39618","0.09821"
"22835","136.97400","11.41472","0.09852"
"22872","137.19600","11.43313","0.09858"
"22909","137.41800","11.45167","0.09933"
"22946","137.64000","11.47008","0.09968"
"22983","137.86200","11.48868","0.10033"
"23020","138.08400","11.50715","0.10172"
"23057","138.30600","11.52563","0.10169"
"23094","138.52800","11.54416","0.10256"
"23131","138.75000","11.56258","0.10343"
"23168","138.97200","11.58117","0.10502"
"23205","139.19400","11.59965","0.10546"
"23242","139.41600","11.61812","0.10736"
"23279","139.63800","11.63666","0.10753"
"23316","139.86000","11.65513","0.10975"
"23353","140.08200","11.67367","0.11079"
"23390","140.30400","11.69214","0.11221"
"23427","140.52600","11.71068","0.11359"
"23464","140.74800","11.72915","0.11556"
"23501","140.97000","11.74763","0.11708"
"23538","141.19200","11.76616","0.11855"
"23575","141.41400","11.78464","0.12043"
"23612","141.63600","11.80317","0.12149"
"23649","141.85800","11.82171","0.12512"
"23686","142.08000","11.84012","0.12586"
"23723","142.30200","11.85872","0.12851"
"23760","142.52400","11.87713","0.12939"
"23797","142.74600","11.89573","0.13219"
"23834","142.96800","11.91414","0.13409"
"23871","143.19000","11.93262","0.13604"
"23908","143.41200","11.95115","0.13837"
"23945","143.63400","11.96963","0.13929"
"23982","143.85600","11.98816","0.14297"
"24019","144.07800","12.00658","0.14413"
"24056","144.30000","12.02523","0.14659"
"24093","144.52200","12.04364","0.14754"
"24130","144.74400","12.06212","0.14970"
"24167","144.96600","12.08066","0.15088"
"24204","145.18800","12.09913","0.15175"
"24241","145.41000","12.11766","0.15284"
"24278","145.63200","12.13620","0.15382"
"24315","145.85400","12.15467","0.15475"
"24352","146.07600","12.17321","0.15497"
"24389","146.29800","12.19162","0.15566"
"24426","146.52000","12.21016","0.15594"
"24463","146.74200","12.22869","0.15657"
"24500","146.96400","12.24717","0.15727"
"24537","147.18600","12.26570","0.15775"
"24574","147.40800","12.28406","0.15865"
"24611","147.63000","12.30265","0.15928"
"24648","147.85200","12.32113","0.16030"
"24685","148.07400","12.33966","0.16102"
"24722","148.29600","12.35820","0.16262"
"24759","148.51800","12.37667","0.16416"
"24796","148.74000","12.39521","0.16505"
"24833","148.96200","12.41368","0.16779"
"24870","149.18400","12.43216","0.16783"
"24907","149.40600","12.45063","0.17051"
"24944","149.62800","12.46917","0.17140"
"24981","149.85000","12.48764","0.17319"
"25018","150.07200","12.50612","0.17454"
"25055","150.29400","12.52465","0.17543"
"25092","150.51600","12.54313","0.17755"
"25129","150.73800","12.56166","0.17861"
"25166","150.96000","12.58014","0.18050"
"25203","151.18200","12.59867","0.18227"
"25240","151.40400","12.61715","0.18309"
"25277","151.62600","12.63562","0.18508"
"25314","151.84800","12.65416","0.18640"
"25351","152.07000","12.67269","0.18791"
"25388","152.29200","12.69116","0.18983"
"25425","152.51400","12.70970","0.18268"
"25462","152.73600","12.72812","0.17968"
"25499","152.95800","12.74671","0.18051"
"25536","153.18000","12.76519","0.18306"
"25573","153.40200","12.78366","0.18486"
"25610","153.62400","12.80219","0.18610"
"25647","153.84600","12.82055","0.18929"
"25684","154.06800","12.83920","0.18972"
"25721","154.29000","12.85762","0.19143"
"25758","154.51200","12.87621","0.19302"
"25795","154.73400","12.89463","0.19400"
"25832","154.95600","12.91304","0.19587"
"25869","155.17800","12.93170","0.19671"
"25906","155.40000","12.95012","0.19810"
"25943","155.62200","12.96865","0.19871"
"25980","155.84400","12.98712","0.19956"
"26017","156.06600","13.00566","0.20095"
"26054","156.28800","13.02419","0.20165"
"26091","156.51000","13.04261","0.20277"
"26128","156.73200","13.06114","0.20365"
"26165","156.95400","13.07968","0.20349"
"26202","157.17600","13.09809","0.20532"
"26239","157.39800","13.11669","0.20603"
"26276","157.62000","13.13510","0.20681"
"26313","157.84200","13.15364","0.20773"
"26350","158.06400","13.17211","0.20708"
"26387","158.28600","13.19059","0.20807"
"26424","158.50800","13.20918","0.20981"
"26461","158.73000","13.22760","0.20998"
"26498","158.95200","13.24619","0.21266"
"26535","159.17400","13.26467","0.21393"
"26572","159.39600","13.28314","0.21551"
"26609","159.61800","13.30168","0.21835"
"26646","159.84000","13.32015","0.21905"
"26683","160.06200","13.33863","0.22139"
"26720","160.28400","13.35710","0.22295"
"26757","160.50600","13.37564","0.22462"
"26794","160.72800","13.39411","0.22699"
"26831","160.95000","13.41265","0.22877"
"26868","161.17200","13.43112","0.23034"
"26905","161.39400","13.44966","0.23224"
"26942","161.61600","13.46819","0.23388"
"26979","161.83800","13.48660","0.23584"
"27016","162.06000","13.50520","0.23873"
"27053","162.28200","13.52367","0.23965"
"27090","162.50400","13.54215","0.24155"
"27127","162.72600","13.56063","0.24324"
"27164","162.94800","13.57916","0.24467"
"27201","163.17000","13.59770","0.24638"
"27238","163.39200","13.61623","0.24677"
"27275","163.61400","13.63458","0.24789"
"27312","163.83600","13.65318","0.24935"
"27349","164.05800","13.67165","0.25015"
"27386","164.28000","13.69019","0.25179"
"27423","164.50200","13.70860","0.25278"
"27460","164.72400","13.72714","0.25432"
"27497","164.94600","13.74573","0.25581"
"27534","165.16800","13.76409","0.25803"
"27571","165.39000","13.78268","0.25971"
"27608","165.61200","13.80110","0.26300"
"27645","165.83400","13.81963","0.26640"
"27682","166.05600","13.83817","0.26874"
"27719","166.27800","13.85664","0.27258"
"27756","166.50000","13.87512","0.27554"
"27793","166.72200","13.89359","0.27856"
"27830","166.94400","13.91219","0.28229"
"27867","167.16600","13.93066","0.28475"
"27904","167.38800","13.94914","0.28653"
"27941","167.61000","13.96767","0.28933"
"27978","167.83200","13.98615","0.29347"
"28015","168.05400","14.00474","0.29626"
"28052","168.27600","14.02316","0.29916"
"28089","168.49800","14.04163","0.30164"
"28126","168.72000","14.06017","0.30388"
"28163","168.94200","14.07858","0.30560"
"28200","169.16400","14.09718","0.30705"
"28237","169.38600","14.11559","0.30830"
"28274","169.60800","14.13413","0.30901"
"28311","169.83000","14.15266","0.30983"
"28348","170.05200","14.17114","0.31018"
"28385","170.27400","14.18967","0.31034"
"28422","170.49600","14.20809","0.31087"
"28459","170.71800","14.22674","0.31141"
"28496","170.94000","14.24516","0.31174"
"28533","171.16200","14.26363","0.31283"
"28570","171.38400","14.28217","0.31416"
"28607","171.60600","14.30058","0.31527"
"28644","171.82800","14.31918","0.31713"
"28681","172.05000","14.33771","0.32015"
"28718","172.27200","14.35618","0.32178"
"28755","172.49400","14.37466","0.32374"
"28792","172.71600","14.39319","0.32661"
"28829","172.93800","14.41161","0.32898"
"28866","173.16000","14.43008","0.33173"
"28903","173.38200","14.44862","0.33362"
"28940","173.60400","14.46715","0.33798"
"28977","173.82600","14.48563","0.34019"
"29014","174.04800","14.50416","0.34349"
"29051","174.27000","14.52264","0.34655"
"29088","174.49200","14.54117","0.35030"
"29125","174.71400","14.55971","0.35173"
"29162","174.93600","14.57812","0.35464"
"29199","175.15800","14.59672","0.35669"
"29236","175.38000","14.61507","0.23845"
"29273","175.60200","14.63367","0.23394"
"29310","175.82400","14.65214","0.22878"
"29347","176.04600","14.67062","0.23051"
"29384","176.26800","14.68909","0.23247"
"29421","176.49000","14.70763","0.23726"
"29458","176.71200","14.72622","0.24207"
"29495","176.93400","14.74464","0.24368"
"29532","177.15600","14.76317","0.24495"
"29569","177.37800","14.78165","0.24530"
"29606","177.60000","14.80012","0.24618"
"29643","177.82200","14.81866","0.24794"
"29680","178.04400","14.83713","0.24954"
"29717","178.26600","14.85561","0.25180"
"29754","178.48800","14.87408","0.25388"
"29791","178.71000","14.89268","0.25503"
"29828","178.93200","14.91121","0.25594"
"29865","179.15400","14.92963","0.25834"
"29902","179.37600","14.94816","0.26052"
"29939","179.59800","14.96663","0.26417"
"29976","179.82000","14.98517","0.26951"
"30013","180.04200","15.00371","0.27256"
"30050","180.26400","15.02212","0.27611"
"30087","180.48600","15.04072","0.27936"
"30124","180.70800","15.05913","0.28035"
"30161","180.93000","15.07773","0.28305"
"30198","181.15200","15.09614","0.28589"
"30235","181.37400","15.11468","0.28826"
"30272","181.59600","15.13321","0.29075"
"30309","181.81800","15.15163","0.29345"
"30346","182.04000","15.17022","0.29628"
"30383","182.26200","15.18863","0.29931"
"30420","182.48400","15.20717","0.30137"
"30457","182.70600","15.22564","0.30231"
"30494","182.92800","15.24412","0.30374"
"30531","183.15000","15.26265","0.30569"
"30568","183.37200","15.28113","0.30624"
"30605","183.59400","15.29966","0.30714"
"30642","183.81600","15.31820","0.30802"
"30679","184.03800","15.33661","0.30739"
"30716","184.26000","15.35515","0.23232"
"30753","184.48200","15.37368","0.23141"
"30790","184.70400","15.39216","0.23075"
"30827","184.92600","15.41063","0.23104"
"30864","185.14800","15.42917","0.23192"
"30901","185.37000","15.44764","0.23176"
"30938","185.59200","15.46612","0.23382"
"30975","185.81400","15.48465","0.23615"
"31012","186.03600","15.50313","0.23714"
"31049","186.25800","15.52160","0.23868"
"31086","186.48000","15.54014","0.23976"
"31123","186.70200","15.55861","0.24019"
"31160","186.92400","15.57721","0.24128"
"31197","187.14600","15.59562","0.24381"
"31234","187.36800","15.61422","0.24451"
"31271","187.59000","15.63269","0.24539"
"31308","187.81200","15.65117","0.24584"
"31345","188.03400","15.66970","0.07145"
"31382","188.25600","15.68812","0.07418"
"31419","188.47800","15.70671","0.07220"
"31456","188.70000","15.72518","0.07336"
"31493","188.92200","15.74360","0.08246"
"31530","189.14400","15.76225","0.07885"
"31567","189.36600","15.78061","0.08760"
"31604","189.58800","15.79914","0.08094"
"31641","189.81000","15.81762","0.08913"
"31678","190.03200","15.83610","0.08398"
"31715","190.25400","15.85469","0.09198"
"31752","190.47600","15.87310","0.08696"
"31789","190.69800","15.89164","0.09394"
"31826","190.92000","15.91011","0.08968"
"31863","191.14200","15.92865","0.09529"
"31900","191.36400","15.94718","0.09163"
"31937","191.58600","15.96566","0.09576"
"31974","191.80800","15.98425","0.09358"
"32011","192.03000","16.00261","0.09659"
"32048","192.25200","16.02114","0.09479"
"32085","192.47400","16.03968","0.09720"
"32122","192.69600","16.05815","0.09584"
"32159","192.91800","16.07663","0.09768"
"32196","193.14000","16.09510","0.09690"
"32233","193.36200","16.11370","0.09816"
"32270","193.58400","16.13211","0.09801"
"32307","193.80600","16.15065","0.09932"
"32344","194.02800","16.16912","0.10011"
"32381","194.25000","16.18760","0.09978"
"32418","194.47200","16.20613","0.10175"
"32455","194.69400","16.22461","0.10121"
"32492","194.91600","16.24314","0.10484"
"32529","195.13800","16.26162","0.10251"
"32566","195.36000","16.28015","0.10915"
"32603","195.58200","16.29863","0.10502"
"32640","195.80400","16.31710","0.11331"
"32677","196.02600","16.33570","0.10823"
"32714","196.24800","16.35417","0.11753"
"32751","196.47000","16.37264","0.11193"
"32788","196.69200","16.39118","0.11989"
"32825","196.91400","16.40960","0.11830"
"32862","197.13600","16.42813","0.12296"
"32899","197.35800","16.44666","0.12437"
"32936","197.58000","16.46520","0.12545"
"32973","197.80200","16.48368","0.13147"
"33010","198.02400","16.50209","0.12819"
"33047","198.24600","16.52069","0.13770"
"33084","198.46800","16.53916","0.13302"
"33121","198.69000","16.55770","0.14271"
"33158","198.91200","16.57611","0.13934"
"33195","199.13400","16.59470","0.14617"
"33232","199.35600","16.61318","0.14583"
"33269","199.57800","16.63165","0.14755"
"33306","199.80000","16.65019","0.15124"
"33343","200.02200","16.66866","0.15056"
"33380","200.24400","16.68714","0.15444"
"33417","200.46600","16.70567","0.15280"
"33454","200.68800","16.72415","0.15556"
"33491","200.91000","16.74262","0.15530"
"33528","201.13200","16.76116","0.15642"
"33565","201.35400","16.77963","0.15704"
"33602","201.57600","16.79817","0.15691"
"33639","201.79800","16.81664","0.15939"
"33676","202.02000","16.83512","0.15845"
"33713","202.24200","16.85365","0.16149"
"33750","202.46400","16.87219","0.16163"
"33787","202.68600","16.89066","0.16359"
"33824","202.90800","16.90914","0.16681"
"33861","203.13000","16.92773","0.16635"
"33898","203.35200","16.94609","0.17124"
"33935","203.57400","16.96468","0.16962"
"33972","203.79600","16.98310","0.17344"
"34009","204.01800","17.00163","0.17567"
"34046","204.24000","17.02017","0.17586"
"34083","204.46200","17.03864","0.17996"
"34120","204.68400","17.05718","0.17979"
"34157","204.90600","17.07559","0.18403"
"34194","205.12800","17.09425","0.18465"
"34231","205.35000","17.11266","0.18587"
"34268","205.57200","17.13114","0.19027"
"34305","205.79400","17.14967","0.18960"
"34342","206.01600","17.16809","0.19343"
"34379","206.23800","17.18668","0.19460"
"34416","206.46000","17.20522","0.19567"
"34453","206.68200","17.22363","0.19852"
"34490","206.90400","17.24216","0.19832"
"34527","207.12600","17.26064","0.20050"
"34564","207.34800","17.27917","0.20149"
"34601","207.57000","17.29765","0.20240"
"34638","207.79200","17.31613","0.20419"
"34675","208.01400","17.33466","0.20485"
"34712","208.23600","17.35308","0.20649"
"34749","208.45800","17.37167","0.20786"
"34786","208.68000","17.39014","0.20834"
"34823","208.90200","17.40868","0.21069"
"34860","209.12400","17.42715","0.21120"
"34897","209.34600","17.44563","0.21315"
"34934","209.56800","17.46416","0.21555"
"34971","209.79000","17.48264","0.21605"
"35008","210.01200","17.50117","0.21963"
"35045","210.23400","17.51965","0.22196"
"35082","210.45600","17.53818","0.22294"
"35119","210.67800","17.55666","0.22624"
"35156","210.90000","17.57513","0.22686"
"35193","211.12200","17.59367","0.22933"
"35230","211.34400","17.61214","0.23154"
"35267","211.56600","17.63068","0.23200"
"35304","211.78800","17.64915","0.23554"
"35341","212.01000","17.66763","0.23743"
"35378","212.23200","17.68616","0.23814"
"35415","212.45400","17.70464","0.24170"
"35452","212.67600","17.72317","0.24344"
"35489","212.89800","17.74171","0.24448"
"35526","213.12000","17.76012","0.24652"
"35563","213.34200","17.77866","0.24736"
"35600","213.56400","17.79713","0.24817"
"35637","213.78600","17.81567","0.24934"
"35674","214.00800","17.83414","0.25040"
"35711","214.23000","17.85262","0.25191"
"35748","214.45200","17.87121","0.25442"
"35785","214.67400","17.88957","0.25537"
"35822","214.89600","17.90822","0.25798"
"35859","215.11800","17.92664","0.26144"
"35896","215.34000","17.94517","0.26386"
"35933","215.56200","17.96365","0.26747"
"35970","215.78400","17.98218","0.27127"
"36007","216.00600","18.00065","0.27296"
"36044","216.22800","18.01907","0.27695"
"36081","216.45000","18.03767","0.28088"
"36118","216.67200","18.05614","0.28279"
"36155","216.89400","18.07467","0.28618"
"36192","217.11600","18.09321","0.28892"
"36229","217.33800","18.11162","0.29202"
"36266","217.56000","18.13016","0.29555"
"36303","217.78200","18.14869","0.29819"
"36340","218.00400","18.16717","0.30077"
"36377","218.22600","18.18570","0.30332"
"36414","218.44800","18.20406","0.30464"
"36451","218.67000","18.22265","0.29582"
"36488","218.89200","18.24119","0.22799"
"36525","219.11400","18.25966","0.22615"
"36562","219.33600","18.27820","0.22808"
"36599","219.55800","18.29661","0.23465"
"36636","219.78000","18.31521","0.23701"
"36673","220.00200","18.33362","0.24106"
"36710","220.22400","18.35222","0.24250"
"36747","220.44600","18.37057","0.24165"
"36784","220.66800","18.38911","0.24590"
"36821","220.89000","18.40764","0.24810"
"36858","221.11200","18.42612","0.24095"
"36895","221.33400","18.44465","0.24189"
"36932","221.55600","18.46313","0.23998"
"36969","221.77800","18.48166","0.24002"
"37006","222.00000","18.50020","0.24448"
"37043","222.22200","18.51861","0.24529"
"37080","222.44400","18.53715","0.24697"
"37117","222.66600","18.55562","0.24922"
"37154","222.88800","18.57416","0.24815"
"37191","223.11000","18.59269","0.24918"
"37228","223.33200","18.61111","0.25126"
"37265","223.55400","18.62970","0.25076"
"37302","223.77600","18.64818","0.25300"
"37339","223.99800","18.66665","0.25562"
"37376","224.22000","18.68519","0.25474"
"37413","224.44200","18.70360","0.25855"
"37450","224.66400","18.72214","0.26030"
"37487","224.88600","18.74055","0.26152"
"37524","225.10800","18.75915","0.26681"
"37561","225.33000","18.77762","0.27023"
"37598","225.55200","18.79616","0.27134"
"37635","225.77400","18.81469","0.27532"
"37672","225.99600","18.83311","0.27669"
"37709","226.21800","18.85170","0.27791"
"37746","226.44000","18.87012","0.28220"
"37783","226.66200","18.88871","0.28513"
"37820","226.88400","18.90712","0.28726"
"37857","227.10600","18.92566","0.29064"
"37894","227.32800","18.94414","0.28543"
"37931","227.55000","18.96261","0.28559"
"37968","227.77200","18.98120","0.28920"
"38005","227.99400","18.99962","0.29234"
"38042","228.21600","19.01815","0.29364"
"38079","228.43800","19.03663","0.29725"
"38116","228.66000","19.05510","0.30004"
"38153","228.88200","19.07370","0.30136"
"38190","229.10400","19.09211","0.30358"
"38227","229.32600","19.11059","0.30484"
"38264","229.54800","19.12918","0.30490"
"38301","229.77000","19.14760","0.30657"
"38338","229.99200","19.16619","0.30789"
"38375","230.21400","19.18467","0.30815"
"38412","230.43600","19.20320","0.30899"
"38449","230.65800","19.22168","0.30951"
"38486","230.88000","19.24015","0.30970"
"38523","231.10200","19.25869","0.30992"
"38560","231.32400","19.27710","0.31041"
"38597","231.54600","19.29576","0.31051"
"38634","231.76800","19.31411","0.31079"
"38671","231.99000","19.33265","0.31117"
"38708","232.21200","19.35118","0.31182"
"38745","232.43400","19.36960","0.31213"
"38782","232.65600","19.38819","0.31277"
"38819","232.87800","19.40667","0.31389"
"38856","233.10000","19.42514","0.31476"
"38893","233.32200","19.44368","0.31637"
"38930","233.54400","19.46215","0.31808"
"38967","233.76600","19.48068","0.31970"
"39004","233.98800","19.49910","0.32125"
"39041","234.21000","19.51770","0.32389"
"39078","234.43200","19.53617","0.32576"
"39115","234.65400","19.55465","0.32734"
"39152","234.87600","19.57318","0.33043"
"39189","235.09800","19.59160","0.33261"
"39226","235.32000","19.61013","0.33463"
"39263","235.54200","19.62860","0.33653"
"39300","235.76400","19.64714","0.34116"
"39337","235.98600","19.66568","0.34307"
"39374","236.20800","19.68409","0.34561"
"39411","236.43000","19.70268","0.34859"
"39448","236.65200","19.72116","0.35101"
"39485","236.87400","19.73963","0.35308"
"39522","237.09600","19.75811","0.35595"
"39559","237.31800","19.77658","0.35782"
"39596","237.54000","19.79512","0.35879"
"39633","237.76200","19.81359","0.36054"
"39670","237.98400","19.83219","0.36227"
"39707","238.20600","19.85066","0.36401"
"39744","238.42800","19.86913","0.36511"
"39781","238.65000","19.88767","0.36676"
"39818","238.87200","19.90609","0.36909"
"39855","239.09400","19.92462","0.37083"
"39892","239.31600","19.94316","0.37295"
"39929","239.53800","19.96163","0.37518"
"39966","239.76000","19.98017","0.37731"
"40003","239.98200","19.99858","0.37952"
"40040","240.20400","20.01718","0.38094"
"40077","240.42600","20.03565","0.38322"
"40114","240.64800","20.05424","0.38378"
"40151","240.87000","20.07272","0.38548"
"40188","241.09200","20.09108","0.38701"
"40225","241.31400","20.10973","0.38785"
"40262","241.53600","20.12815","0.38873"
"40299","241.75800","20.14668","0.31484"
"40336","241.98000","20.16510","0.31413"
"40373","242.20200","20.18363","0.31411"
"40410","242.42400","20.20222","0.31255"
"40447","242.64600","20.22064","0.31346"
"40484","242.86800","20.23923","0.31519"
"40521","243.09000","20.25765","0.31461"
"40558","243.31200","20.27619","0.31588"
"40595","243.53400","20.29466","0.31925"
"40632","243.75600","20.31314","0.31962"
"40669","243.97800","20.33161","0.32080"
"40706","244.20000","20.35015","0.32480"
"40743","244.42200","20.36868","0.32699"
"40780","244.64400","20.38715","0.32619"
"40817","244.86600","20.40563","0.33026"
"40854","245.08800","20.42417","0.33397"
"40891","245.31000","20.44264","0.33372"
"40928","245.53200","20.46117","0.33629"
"40965","245.75400","20.47965","0.34134"
"41002","245.97600","20.49812","0.34161"
"41039","246.19800","20.51666","0.34345"
"41076","246.42000","20.53507","0.34817"
"41113","246.64200","20.55367","0.35027"
"41150","246.86400","20.57215","0.35075"
"41187","247.08600","20.59062","0.35465"
"41224","247.30800","20.60915","0.35730"
"41261","247.53000","20.62763","0.35783"
"41298","247.75200","20.64622","0.35939"
"41335","247.97400","20.66458","0.36203"
"41372","248.19600","20.68323","0.36314"
"41409","248.41800","20.70159","0.36369"
"41446","248.64000","20.72018","0.36594"
"41483","248.86200","20.73866","0.36848"
"41520","249.08400","20.75713","0.36978"
"41557","249.30600","20.77573","0.37193"
"41594","249.52800","20.79414","0.37492"
"41631","249.75000","20.81268","0.37712"
"41668","249.97200","20.83121","0.37837"
"41705","250.19400","20.84969","0.38090"
"41742","250.41600","20.86816","0.38319"
"41779","250.63800","20.88664","0.20836"
"41816","250.86000","20.90511","0.21755"
"41853","251.08200","20.92371","0.19611"
"41890","251.30400","20.94212","0.22370"
"41927","251.52600","20.96066","0.19300"
"41964","251.74800","20.97913","0.22483"
"42001","251.97000","20.99767","0.19435"
"42038","252.19200","21.01620","0.21852"
"42075","252.41400","21.03461","0.20050"
"42112","252.63600","21.05321","0.20825"
"42149","252.85800","21.07157","0.21026"
"42186","253.08000","21.09016","0.20281"
"42223","253.30200","21.10863","0.22303"
"42260","253.52400","21.12717","0.20189"
"42297","253.74600","21.14564","0.22660"
"42334","253.96800","21.16412","0.20484"
"42371","254.19000","21.18271","0.21801"
"42408","254.41200","21.20113","0.21394"
"42445","254.63400","21.21967","0.21214"
"42482","254.85600","21.23808","0.23370"
"42519","255.07800","21.25667","0.21558"
"42556","255.30000","21.27515","0.24334"
"42593","255.52200","21.29362","0.22421"
"42630","255.74400","21.31216","0.23494"
"42667","255.96600","21.33069","0.23943"
"42704","256.18800","21.34917","0.23041"
"42741","256.41000","21.36764","0.25030"
"42778","256.63200","21.38606","0.23650"
"42815","256.85400","21.40465","0.24850"
"42852","257.07600","21.42313","0.24704"
"42889","257.29800","21.44166","0.24486"
"42926","257.52000","21.46014","0.25825"
"42963","257.74200","21.47861","0.24656"
"43000","257.96400","21.49721","0.25573"
"43037","258.18600","21.51562","0.25448"
"43074","258.40800","21.53416","0.25186"
"43111","258.63000","21.55263","0.27257"
"43148","258.85200","21.57111","0.25396"
"43185","259.07400","21.58964","0.26969"
"43222","259.29600","21.60806","0.27165"
"43259","259.51800","21.62671","0.26257"
"43296","259.74000","21.64513","0.28717"
"43333","259.96200","21.66366","0.27203"
"43370","260.18400","21.68214","0.28241"
"43407","260.40600","21.70067","0.29248"
"43444","260.62800","21.71915","0.27999"
"43481","260.85000","21.73762","0.29874"
"43518","261.07200","21.75615","0.29433"
"43555","261.29400","21.77469","0.29392"
"43592","261.51600","21.79311","0.30596"
"43629","261.73800","21.81170","0.29819"
"43666","261.96000","21.83018","0.30527"
"43703","262.18200","21.84871","0.30832"
"43740","262.40400","21.86719","0.30428"
"43777","262.62600","21.88560","0.30971"
"43814","262.84800","21.90419","0.30933"
"43851","263.07000","21.92261","0.30915"
"43888","263.29200","21.94121","0.31107"
"43925","263.51400","21.95962","0.31004"
"43962","263.73600","21.97815","0.31078"
"43999","263.95800","21.99669","0.31260"
"44036","264.18000","22.01510","0.30752"
"44073","264.40200","22.03370","0.30849"
"44110","264.62400","22.05211","0.30866"
"44147","264.84600","22.07065","0.30657"
"44184","265.06800","22.08918","0.30947"
"44221","265.29000","22.10766","0.30861"
"44258","265.51200","22.12619","0.30916"
"44295","265.73400","22.14461","0.31026"
"44332","265.95600","22.16320","0.30937"
"44369","266.17800","22.18168","0.30997"
"44406","266.40000","22.20015","0.31033"
"44443","266.62200","22.21869","0.30958"
"44480","266.84400","22.23710","0.01231"
"44517","267.06600","22.25564","0.02119"
"44554","267.28800","22.27417","0.00463"
"44591","267.51000","22.29259","0.00377"
"44628","267.73200","22.31118","0.01987"
"44665","267.95400","22.32960","0.00664"
"44702","268.17600","22.34813","0.00505"
"44739","268.39800","22.36666","0.01484"
"44776","268.62000","22.38514","0.00454"
"44813","268.84200","22.40368","0.01421"
"44850","269.06400","22.42215","0.00699"
"44887","269.28600","22.44069","0.00623"
"44924","269.50800","22.45910","0.01093"
"44961","269.73000","22.47764","0.00679"
"44998","269.95200","22.49617","0.00894"
"45035","270.17400","22.51465","0.00641"
"45072","270.39600","22.53318","0.00897"
"45109","270.61800","22.55165","0.00899"
"45146","270.84000","22.57019","0.00746"
"45183","271.06200","22.58861","0.00979"
"45220","271.28400","22.60720","0.00893"
"45257","271.50600","22.62562","0.00910"
"45294","271.72800","22.64415","0.00770"
"45331","271.95000","22.66262","0.01096"
"45368","272.17200","22.68116","0.00821"
"45405","272.39400","22.69963","0.00894"
"45442","272.61600","22.71811","0.00987"
"45479","272.83800","22.73664","0.00915"
"45516","273.06000","22.75518","0.00917"
"45553","273.28200","22.77365","0.00855"
"45590","273.50400","22.79219","0.01094"
"45627","273.72600","22.81072","0.00846"
"45664","273.94800","22.82914","0.00931"
"45701","274.17000","22.84767","0.01018"
"45738","274.39200","22.86609","0.00951"
"45775","274.61400","22.88468","0.00938"
"45812","274.83600","22.90316","0.00903"
"45849","275.05800","22.92163","0.01050"
"45886","275.28000","22.94017","0.00889"
"45923","275.50200","22.95858","0.00915"
"45960","275.72400","22.97718","0.01028"
"45997","275.94600","22.99559","0.00982"
"46000","275.96000","22.99679","0.00977"