File: Trajectories_together/161218_2Specimen_RawData_7.csv
"","V1","V2","V3"
"1","End date","12/18/2016",""
"2","Specimen label","16BG_30",""
"3","Maximum Load","0.63762","N"
"4","Time","Extension","Load"
"5","(s)","(mm)","(N)"
"6","0.00000","0.00000","0.00041"
"75","0.41400","0.03474","0.00652"
"144","0.82800","0.06912","0.00996"
"213","1.24200","0.10368","0.01163"
"282","1.65600","0.13823","0.01389"
"351","2.07000","0.17267","0.01496"
"420","2.48400","0.20717","0.01509"
"489","2.89800","0.24167","0.01665"
"558","3.31200","0.27617","0.01672"
"627","3.72600","0.31067","0.01718"
"696","4.14000","0.34511","0.01783"
"765","4.55400","0.37966","0.01861"
"834","4.96800","0.41416","0.01851"
"903","5.38200","0.44866","0.01929"
"972","5.79600","0.48316","0.01923"
"1041","6.21000","0.51766","0.01977"
"1110","6.62400","0.55222","0.01962"
"1179","7.03800","0.58671","0.01975"
"1248","7.45200","0.62115","0.01973"
"1317","7.86600","0.65559","0.02042"
"1386","8.28000","0.69009","0.02082"
"1455","8.69400","0.72465","0.02067"
"1524","9.10800","0.75921","0.02109"
"1593","9.52200","0.79359","0.02126"
"1662","9.93600","0.82814","0.02125"
"1731","10.35000","0.86270","0.02095"
"1800","10.76400","0.89720","0.02160"
"1869","11.17800","0.93170","0.02188"
"1938","11.59200","0.96614","0.02202"
"2007","12.00600","1.00070","0.02201"
"2076","12.42000","1.03520","0.02275"
"2145","12.83400","1.06969","0.02287"
"2214","13.24800","1.10413","0.02307"
"2283","13.66200","1.13863","0.02316"
"2352","14.07600","1.17319","0.02266"
"2421","14.49000","1.20769","0.02367"
"2490","14.90400","1.24213","0.02287"
"2559","15.31800","1.27663","0.02313"
"2628","15.73200","1.31118","0.02383"
"2697","16.14600","1.34568","0.02388"
"2766","16.56000","1.38018","0.02374"
"2835","16.97400","1.41462","0.02390"
"2904","17.38800","1.44918","0.02294"
"2973","17.80200","1.48368","0.02301"
"3042","18.21600","1.51818","0.02326"
"3111","18.63000","1.55261","0.02365"
"3180","19.04400","1.58717","0.02369"
"3249","19.45800","1.62167","0.02373"
"3318","19.87200","1.65617","0.02392"
"3387","20.28600","1.69067","0.02429"
"3456","20.70000","1.72517","0.02359"
"3525","21.11400","1.75973","0.02342"
"3594","21.52800","1.79416","0.02397"
"3663","21.94200","1.82866","0.02423"
"3732","22.35600","1.86310","0.02424"
"3801","22.77000","1.89760","0.02437"
"3870","23.18400","1.93216","0.02477"
"3939","23.59800","1.96672","0.02436"
"4008","24.01200","2.00116","0.02485"
"4077","24.42600","2.03565","0.02498"
"4146","24.84000","2.07021","0.02484"
"4215","25.25400","2.10471","0.02484"
"4284","25.66800","2.13915","0.02528"
"4353","26.08200","2.17365","0.02523"
"4422","26.49600","2.20815","0.02524"
"4491","26.91000","2.24265","0.02553"
"4560","27.32400","2.27720","0.02534"
"4629","27.73800","2.31164","0.02571"
"4698","28.15200","2.34626","0.02604"
"4767","28.56600","2.38070","0.02624"
"4836","28.98000","2.41514","0.02606"
"4905","29.39400","2.44958","0.02604"
"4974","29.80800","2.48414","0.02652"
"5043","30.22200","2.51869","0.02658"
"5112","30.63600","2.55319","0.02644"
"5181","31.05000","2.58763","0.02657"
"5250","31.46400","2.62213","0.02649"
"5319","31.87800","2.65669","0.02726"
"5388","32.29200","2.69119","0.02684"
"5457","32.70600","2.72569","0.02697"
"5526","33.12000","2.76012","0.02725"
"5595","33.53400","2.79462","0.02674"
"5664","33.94800","2.82918","0.02733"
"5733","34.36200","2.86368","0.02725"
"5802","34.77600","2.89818","0.02780"
"5871","35.19000","2.93268","0.02782"
"5940","35.60400","2.96724","0.02764"
"6009","36.01800","3.00167","0.02785"
"6078","36.43200","3.03611","0.02778"
"6147","36.84600","3.07067","0.02795"
"6216","37.26000","3.10517","0.02816"
"6285","37.67400","3.13967","0.02851"
"6354","38.08800","3.17417","0.02834"
"6423","38.50200","3.20866","0.02858"
"6492","38.91600","3.24322","0.02880"
"6561","39.33000","3.27766","0.02895"
"6630","39.74400","3.31216","0.02892"
"6699","40.15800","3.34660","0.02933"
"6768","40.57200","3.38110","0.02876"
"6837","40.98600","3.41572","0.02939"
"6906","41.40000","3.45016","0.02950"
"6975","41.81400","3.48465","0.02943"
"7044","42.22800","3.51915","0.02956"
"7113","42.64200","3.55371","0.02976"
"7182","43.05600","3.58821","0.03010"
"7251","43.47000","3.62265","0.03001"
"7320","43.88400","3.65709","0.03026"
"7389","44.29800","3.69165","0.03016"
"7458","44.71200","3.72620","0.03030"
"7527","45.12600","3.76070","0.03108"
"7596","45.54000","3.79514","0.03056"
"7665","45.95400","3.82970","0.03063"
"7734","46.36800","3.86420","0.03007"
"7803","46.78200","3.89870","0.03079"
"7872","47.19600","3.93314","0.03054"
"7941","47.61000","3.96763","0.03125"
"8010","48.02400","4.00213","0.03105"
"8079","48.43800","4.03669","0.03160"
"8148","48.85200","4.07119","0.03126"
"8217","49.26600","4.10563","0.03147"
"8286","49.68000","4.14025","0.03175"
"8355","50.09400","4.17468","0.03164"
"8424","50.50800","4.20918","0.03188"
"8493","50.92200","4.24362","0.03205"
"8562","51.33600","4.27812","0.03229"
"8631","51.75000","4.31268","0.03245"
"8700","52.16400","4.34718","0.03218"
"8769","52.57800","4.38162","0.03216"
"8838","52.99200","4.41611","0.03216"
"8907","53.40600","4.45067","0.03232"
"8976","53.82000","4.48523","0.03265"
"9045","54.23400","4.51967","0.03252"
"9114","54.64800","4.55411","0.03302"
"9183","55.06200","4.58873","0.03295"
"9252","55.47600","4.62317","0.03262"
"9321","55.89000","4.65766","0.03280"
"9390","56.30400","4.69216","0.03297"
"9459","56.71800","4.72666","0.03299"
"9528","57.13200","4.76122","0.03296"
"9597","57.54600","4.79566","0.03286"
"9666","57.96000","4.83016","0.03305"
"9735","58.37400","4.86466","0.03338"
"9804","58.78800","4.89921","0.03370"
"9873","59.20200","4.93365","0.03352"
"9942","59.61600","4.96821","0.03366"
"10011","60.03000","5.00259","0.03338"
"10080","60.44400","5.03721","0.03400"
"10149","60.85800","5.07171","0.03392"
"10218","61.27200","5.10620","0.03392"
"10287","61.68600","5.14058","0.03445"
"10356","62.10000","5.17514","0.03433"
"10425","62.51400","5.20970","0.03421"
"10494","62.92800","5.24414","0.03424"
"10563","63.34200","5.27870","0.03432"
"10632","63.75600","5.31314","0.03490"
"10701","64.17000","5.34770","0.03488"
"10770","64.58400","5.38219","0.03465"
"10839","64.99800","5.41663","0.03455"
"10908","65.41200","5.45107","0.03503"
"10977","65.82600","5.48563","0.03548"
"11046","66.24000","5.52019","0.03528"
"11115","66.65400","5.55475","0.03550"
"11184","67.06800","5.58919","0.03540"
"11253","67.48200","5.62362","0.03546"
"11322","67.89600","5.65818","0.03531"
"11391","68.31000","5.69268","0.03527"
"11460","68.72400","5.72712","0.03557"
"11529","69.13800","5.76162","0.03582"
"11598","69.55200","5.79612","0.03564"
"11667","69.96600","5.83068","0.03574"
"11736","70.38000","5.86517","0.03597"
"11805","70.79400","5.89967","0.03581"
"11874","71.20800","5.93417","0.03609"
"11943","71.62200","5.96867","0.03599"
"12012","72.03600","6.00317","0.03667"
"12081","72.45000","6.03761","0.03641"
"12150","72.86400","6.07211","0.03686"
"12219","73.27800","6.10666","0.03688"
"12288","73.69200","6.14122","0.03694"
"12357","74.10600","6.17566","0.03677"
"12426","74.52000","6.21016","0.03668"
"12495","74.93400","6.24472","0.03701"
"12564","75.34800","6.27916","0.03724"
"12633","75.76200","6.31371","0.03756"
"12702","76.17600","6.34815","0.03708"
"12771","76.59000","6.38265","0.03717"
"12840","77.00400","6.41715","0.03705"
"12909","77.41800","6.45171","0.03764"
"12978","77.83200","6.48615","0.03746"
"13047","78.24600","6.52065","0.03773"
"13116","78.66000","6.55520","0.03768"
"13185","79.07400","6.58970","0.03787"
"13254","79.48800","6.62420","0.03785"
"13323","79.90200","6.65864","0.03805"
"13392","80.31600","6.69314","0.03781"
"13461","80.73000","6.72770","0.03820"
"13530","81.14400","6.76220","0.03803"
"13599","81.55800","6.79669","0.03781"
"13668","81.97200","6.83119","0.03802"
"13737","82.38600","6.86569","0.03885"
"13806","82.80000","6.90019","0.03788"
"13875","83.21400","6.93463","0.03850"
"13944","83.62800","6.96913","0.03884"
"14013","84.04200","7.00369","0.03925"
"14082","84.45600","7.03818","0.03865"
"14151","84.87000","7.07268","0.03898"
"14220","85.28400","7.10712","0.03927"
"14289","85.69800","7.14168","0.03927"
"14358","86.11200","7.17618","0.03972"
"14427","86.52600","7.21068","0.03922"
"14496","86.94000","7.24512","0.03961"
"14565","87.35400","7.27967","0.03982"
"14634","87.76800","7.31417","0.03961"
"14703","88.18200","7.34867","0.03966"
"14772","88.59600","7.38317","0.03963"
"14841","89.01000","7.41767","0.03924"
"14910","89.42400","7.45223","0.03920"
"14979","89.83800","7.48667","0.03959"
"15048","90.25200","7.52110","0.03953"
"15117","90.66600","7.55566","0.03987"
"15186","91.08000","7.59016","0.04000"
"15255","91.49400","7.62466","0.04017"
"15324","91.90800","7.65916","0.04011"
"15393","92.32200","7.69366","0.04004"
"15462","92.73600","7.72822","0.04027"
"15531","93.15000","7.76271","0.04002"
"15600","93.56400","7.79715","0.04024"
"15669","93.97800","7.83165","0.04043"
"15738","94.39200","7.86615","0.04014"
"15807","94.80600","7.90071","0.04077"
"15876","95.22000","7.93521","0.04085"
"15945","95.63400","7.96965","0.04137"
"16014","96.04800","8.00408","0.04099"
"16083","96.46200","8.03870","0.04141"
"16152","96.87600","8.07320","0.04187"
"16221","97.29000","8.10764","0.04225"
"16290","97.70400","8.14208","0.04174"
"16359","98.11800","8.17664","0.04187"
"16428","98.53200","8.21114","0.04236"
"16497","98.94600","8.24569","0.04270"
"16566","99.36000","8.28013","0.04248"
"16635","99.77400","8.31463","0.04289"
"16704","100.18800","8.34919","0.04319"
"16773","100.60200","8.38369","0.04320"
"16842","101.01600","8.41819","0.04313"
"16911","101.43000","8.45263","0.04315"
"16980","101.84400","8.48712","0.04381"
"17049","102.25800","8.52168","0.04406"
"17118","102.67200","8.55618","0.04431"
"17187","103.08600","8.59056","0.04334"
"17256","103.50000","8.62518","0.04427"
"17325","103.91400","8.65968","0.04392"
"17394","104.32800","8.69418","0.04496"
"17463","104.74200","8.72861","0.04457"
"17532","105.15600","8.76317","0.04520"
"17601","105.57000","8.79767","0.04506"
"17670","105.98400","8.83217","0.04540"
"17739","106.39800","8.86667","0.04388"
"17808","106.81200","8.90117","0.04435"
"17877","107.22600","8.93573","0.04426"
"17946","107.64000","8.97022","0.04426"
"18015","108.05400","9.00466","0.04461"
"18084","108.46800","9.03910","0.04501"
"18153","108.88200","9.07360","0.04528"
"18222","109.29600","9.10816","0.04550"
"18291","109.71000","9.14272","0.04555"
"18360","110.12400","9.17715","0.04575"
"18429","110.53800","9.21165","0.04581"
"18498","110.95200","9.24621","0.04681"
"18567","111.36600","9.28071","0.04646"
"18636","111.78000","9.31515","0.04703"
"18705","112.19400","9.34965","0.04701"
"18774","112.60800","9.38415","0.04750"
"18843","113.02200","9.41864","0.04751"
"18912","113.43600","9.45320","0.04754"
"18981","113.85000","9.48764","0.04803"
"19050","114.26400","9.52220","0.04788"
"19119","114.67800","9.55670","0.04858"
"19188","115.09200","9.59114","0.04794"
"19257","115.50600","9.62564","0.04942"
"19326","115.92000","9.66014","0.04898"
"19395","116.33400","9.69463","0.04939"
"19464","116.74800","9.72919","0.04970"
"19533","117.16200","9.76363","0.05005"
"19602","117.57600","9.79819","0.05041"
"19671","117.99000","9.83269","0.05016"
"19740","118.40400","9.86719","0.05062"
"19809","118.81800","9.90168","0.05129"
"19878","119.23200","9.93612","0.05118"
"19947","119.64600","9.97068","0.05162"
"20016","120.06000","10.00518","0.05168"
"20085","120.47400","10.03974","0.05248"
"20154","120.88800","10.07412","0.05235"
"20223","121.30200","10.10862","0.05271"
"20292","121.71600","10.14323","0.05285"
"20361","122.13000","10.17773","0.05334"
"20430","122.54400","10.21217","0.05388"
"20499","122.95800","10.24667","0.05370"
"20568","123.37200","10.28117","0.05404"
"20637","123.78600","10.31567","0.05450"
"20706","124.20000","10.35017","0.05404"
"20775","124.61400","10.38466","0.05408"
"20844","125.02800","10.41922","0.05406"
"20913","125.44200","10.45372","0.05457"
"20982","125.85600","10.48822","0.05459"
"21051","126.27000","10.52266","0.05527"
"21120","126.68400","10.55710","0.05581"
"21189","127.09800","10.59172","0.05570"
"21258","127.51200","10.62621","0.05611"
"21327","127.92600","10.66065","0.05644"
"21396","128.34000","10.69509","0.05709"
"21465","128.75400","10.72965","0.05719"
"21534","129.16800","10.76421","0.05764"
"21603","129.58200","10.79865","0.05816"
"21672","129.99600","10.83309","0.05816"
"21741","130.41000","10.86765","0.05867"
"21810","130.82400","10.90220","0.05833"
"21879","131.23800","10.93670","0.05863"
"21948","131.65200","10.97114","0.05912"
"22017","132.06600","11.00564","0.05931"
"22086","132.48000","11.04014","0.05968"
"22155","132.89400","11.07470","0.06007"
"22224","133.30800","11.10913","0.06029"
"22293","133.72200","11.14357","0.06105"
"22362","134.13600","11.17813","0.06120"
"22431","134.55000","11.21269","0.06171"
"22500","134.96400","11.24719","0.06154"
"22569","135.37800","11.28163","0.06256"
"22638","135.79200","11.31618","0.06245"
"22707","136.20600","11.35069","0.06258"
"22776","136.62000","11.38518","0.06362"
"22845","137.03400","11.41962","0.06379"
"22914","137.44800","11.45412","0.06404"
"22983","137.86200","11.48868","0.06485"
"23052","138.27600","11.52318","0.06512"
"23121","138.69000","11.55762","0.06543"
"23190","139.10400","11.59211","0.06604"
"23259","139.51800","11.62667","0.06551"
"23328","139.93200","11.66117","0.06631"
"23397","140.34600","11.69567","0.06660"
"23466","140.76000","11.73011","0.06756"
"23535","141.17400","11.76467","0.06747"
"23604","141.58800","11.79917","0.06756"
"23673","142.00200","11.83366","0.06827"
"23742","142.41600","11.86816","0.06861"
"23811","142.83000","11.90266","0.06928"
"23880","143.24400","11.93722","0.06990"
"23949","143.65800","11.97172","0.06950"
"24018","144.07200","12.00616","0.07059"
"24087","144.48600","12.04066","0.07126"
"24156","144.90000","12.07515","0.07089"
"24225","145.31400","12.10965","0.07155"
"24294","145.72800","12.14421","0.07228"
"24363","146.14200","12.17859","0.07245"
"24432","146.55600","12.21321","0.07336"
"24501","146.97000","12.24771","0.07361"
"24570","147.38400","12.28215","0.07405"
"24639","147.79800","12.31664","0.07479"
"24708","148.21200","12.35114","0.07529"
"24777","148.62600","12.38570","0.07609"
"24846","149.04000","12.42014","0.07618"
"24915","149.45400","12.45464","0.07648"
"24984","149.86800","12.48914","0.07725"
"25053","150.28200","12.52369","0.07818"
"25122","150.69600","12.55819","0.07848"
"25191","151.11000","12.59269","0.07924"
"25260","151.52400","12.62707","0.07961"
"25329","151.93800","12.66163","0.07988"
"25398","152.35200","12.69619","0.08002"
"25467","152.76600","12.73069","0.08062"
"25536","153.18000","12.76519","0.08120"
"25605","153.59400","12.79968","0.08181"
"25674","154.00800","12.83424","0.08214"
"25743","154.42200","12.86868","0.08303"
"25812","154.83600","12.90318","0.08273"
"25881","155.25000","12.93762","0.08339"
"25950","155.66400","12.97218","0.08393"
"26019","156.07800","13.00667","0.08515"
"26088","156.49200","13.04117","0.08501"
"26157","156.90600","13.07561","0.08575"
"26226","157.32000","13.11017","0.08593"
"26295","157.73400","13.14473","0.08721"
"26364","158.14800","13.17923","0.08724"
"26433","158.56200","13.21361","0.08762"
"26502","158.97600","13.24817","0.08859"
"26571","159.39000","13.28272","0.08945"
"26640","159.80400","13.31722","0.09032"
"26709","160.21800","13.35166","0.09111"
"26778","160.63200","13.38616","0.09128"
"26847","161.04600","13.42072","0.09228"
"26916","161.46000","13.45522","0.09347"
"26985","161.87400","13.48971","0.09361"
"27054","162.28800","13.52409","0.09395"
"27123","162.70200","13.55865","0.09533"
"27192","163.11600","13.59321","0.09604"
"27261","163.53000","13.62771","0.09670"
"27330","163.94400","13.66215","0.09725"
"27399","164.35800","13.69665","0.09913"
"27468","164.77200","13.73114","0.09977"
"27537","165.18600","13.76570","0.10088"
"27606","165.60000","13.80014","0.10086"
"27675","166.01400","13.83464","0.10205"
"27744","166.42800","13.86914","0.10245"
"27813","166.84200","13.90370","0.10396"
"27882","167.25600","13.93814","0.10417"
"27951","167.67000","13.97263","0.10459"
"28020","168.08400","14.00719","0.10495"
"28089","168.49800","14.04169","0.10572"
"28158","168.91200","14.07619","0.10629"
"28227","169.32600","14.11063","0.10702"
"28296","169.74000","14.14507","0.10743"
"28365","170.15400","14.17969","0.10808"
"28434","170.56800","14.21418","0.10834"
"28503","170.98200","14.24862","0.10906"
"28572","171.39600","14.28312","0.10908"
"28641","171.81000","14.31768","0.10928"
"28710","172.22400","14.35218","0.11003"
"28779","172.63800","14.38662","0.11061"
"28848","173.05200","14.42112","0.11119"
"28917","173.46600","14.45562","0.11163"
"28986","173.88000","14.49017","0.11238"
"29055","174.29400","14.52461","0.11284"
"29124","174.70800","14.55917","0.11341"
"29193","175.12200","14.59361","0.11382"
"29262","175.53600","14.62823","0.11429"
"29331","175.95000","14.66272","0.11468"
"29400","176.36400","14.69716","0.11491"
"29469","176.77800","14.73166","0.11570"
"29538","177.19200","14.76610","0.11645"
"29607","177.60600","14.80066","0.11663"
"29676","178.02000","14.83516","0.11693"
"29745","178.43400","14.86966","0.11762"
"29814","178.84800","14.90416","0.11817"
"29883","179.26200","14.93871","0.11865"
"29952","179.67600","14.97321","0.11923"
"30021","180.09000","15.00759","0.11998"
"30090","180.50400","15.04215","0.12087"
"30159","180.91800","15.07665","0.12152"
"30228","181.33200","15.11115","0.12177"
"30297","181.74600","15.14565","0.12263"
"30366","182.16000","15.18008","0.12297"
"30435","182.57400","15.21470","0.12367"
"30504","182.98800","15.24926","0.12464"
"30573","183.40200","15.28370","0.12504"
"30642","183.81600","15.31814","0.12572"
"30711","184.23000","15.35270","0.12677"
"30780","184.64400","15.38714","0.12733"
"30849","185.05800","15.42169","0.12837"
"30918","185.47200","15.45613","0.12955"
"30987","185.88600","15.49063","0.13037"
"31056","186.30000","15.52519","0.13123"
"31125","186.71400","15.55969","0.13161"
"31194","187.12800","15.59419","0.13337"
"31263","187.54200","15.62862","0.13430"
"31332","187.95600","15.66318","0.13528"
"31401","188.37000","15.69762","0.13504"
"31470","188.78400","15.73218","0.13686"
"31539","189.19800","15.76662","0.13761"
"31608","189.61200","15.80118","0.13822"
"31677","190.02600","15.83574","0.13926"
"31746","190.44000","15.87023","0.14065"
"31815","190.85400","15.90461","0.14053"
"31884","191.26800","15.93917","0.14233"
"31953","191.68200","15.97373","0.14260"
"32022","192.09600","16.00811","0.14379"
"32091","192.51000","16.04267","0.14554"
"32160","192.92400","16.07711","0.14542"
"32229","193.33800","16.11166","0.14698"
"32298","193.75200","16.14622","0.14832"
"32367","194.16600","16.18072","0.15019"
"32436","194.58000","16.21510","0.15115"
"32505","194.99400","16.24966","0.15331"
"32574","195.40800","16.28422","0.15471"
"32643","195.82200","16.31872","0.15601"
"32712","196.23600","16.35316","0.15781"
"32781","196.65000","16.38759","0.15946"
"32850","197.06400","16.42215","0.16017"
"32919","197.47800","16.45671","0.16173"
"32988","197.89200","16.49121","0.16287"
"33057","198.30600","16.52565","0.16408"
"33126","198.72000","16.56015","0.16480"
"33195","199.13400","16.59470","0.16610"
"33264","199.54800","16.62914","0.16758"
"33333","199.96200","16.66364","0.16790"
"33402","200.37600","16.69814","0.16875"
"33471","200.79000","16.73270","0.17011"
"33540","201.20400","16.76720","0.17126"
"33609","201.61800","16.80170","0.17196"
"33678","202.03200","16.83613","0.17356"
"33747","202.44600","16.87063","0.17428"
"33816","202.86000","16.90513","0.17540"
"33885","203.27400","16.93963","0.17656"
"33954","203.68800","16.97413","0.17776"
"34023","204.10200","17.00869","0.17864"
"34092","204.51600","17.04313","0.17974"
"34161","204.93000","17.07768","0.18073"
"34230","205.34400","17.11206","0.18178"
"34299","205.75800","17.14662","0.18263"
"34368","206.17200","17.18118","0.18429"
"34437","206.58600","17.21568","0.18531"
"34506","207.00000","17.25012","0.18628"
"34575","207.41400","17.28461","0.18718"
"34644","207.82800","17.31917","0.18827"
"34713","208.24200","17.35367","0.18884"
"34782","208.65600","17.38817","0.19007"
"34851","209.07000","17.42267","0.19043"
"34920","209.48400","17.45717","0.19204"
"34989","209.89800","17.49167","0.19346"
"35058","210.31200","17.52617","0.19519"
"35127","210.72600","17.56067","0.19575"
"35196","211.14000","17.59516","0.19741"
"35265","211.55400","17.62966","0.19948"
"35334","211.96800","17.66422","0.20048"
"35403","212.38200","17.69866","0.20287"
"35472","212.79600","17.73310","0.20323"
"35541","213.21000","17.76765","0.20155"
"35610","213.62400","17.80215","0.20432"
"35679","214.03800","17.83665","0.20537"
"35748","214.45200","17.87109","0.20718"
"35817","214.86600","17.90565","0.20794"
"35886","215.28000","17.94021","0.20968"
"35955","215.69400","17.97465","0.21099"
"36024","216.10800","18.00908","0.21270"
"36093","216.52200","18.04364","0.21392"
"36162","216.93600","18.07820","0.21592"
"36231","217.35000","18.11270","0.21705"
"36300","217.76400","18.14714","0.21829"
"36369","218.17800","18.18158","0.21868"
"36438","218.59200","18.21620","0.22043"
"36507","219.00600","18.25069","0.22147"
"36576","219.42000","18.28514","0.22288"
"36645","219.83400","18.31963","0.22383"
"36714","220.24800","18.35413","0.22478"
"36783","220.66200","18.38869","0.22575"
"36852","221.07600","18.42319","0.22697"
"36921","221.49000","18.45763","0.22788"
"36990","221.90400","18.49218","0.22802"
"37059","222.31800","18.52668","0.22745"
"37128","222.73200","18.56124","0.22897"
"37197","223.14600","18.59568","0.22999"
"37266","223.56000","18.63012","0.23190"
"37335","223.97400","18.66468","0.23287"
"37404","224.38800","18.69918","0.23479"
"37473","224.80200","18.73362","0.23633"
"37542","225.21600","18.76811","0.23753"
"37611","225.63000","18.80267","0.23855"
"37680","226.04400","18.83723","0.23947"
"37749","226.45800","18.87167","0.24053"
"37818","226.87200","18.90611","0.24176"
"37887","227.28600","18.94067","0.24352"
"37956","227.70000","18.97516","0.24471"
"38025","228.11400","19.00966","0.24681"
"38094","228.52800","19.04410","0.24829"
"38163","228.94200","19.07860","0.24967"
"38232","229.35600","19.11316","0.25139"
"38301","229.77000","19.14766","0.25381"
"38370","230.18400","19.18222","0.25564"
"38439","230.59800","19.21666","0.25718"
"38508","231.01200","19.25109","0.25872"
"38577","231.42600","19.28565","0.26011"
"38646","231.84000","19.32021","0.26104"
"38715","232.25400","19.35459","0.26262"
"38784","232.66800","19.38915","0.26414"
"38853","233.08200","19.42365","0.26539"
"38922","233.49600","19.45815","0.26687"
"38991","233.91000","19.49264","0.26886"
"39060","234.32400","19.52714","0.26864"
"39129","234.73800","19.56164","0.27036"
"39198","235.15200","19.59614","0.27273"
"39267","235.56600","19.63070","0.27468"
"39336","235.98000","19.66514","0.27643"
"39405","236.39400","19.69969","0.27878"
"39474","236.80800","19.73425","0.28039"
"39543","237.22200","19.76869","0.28236"
"39612","237.63600","19.80313","0.28452"
"39681","238.05000","19.83763","0.28542"
"39750","238.46400","19.87219","0.28663"
"39819","238.87800","19.90663","0.28920"
"39888","239.29200","19.94118","0.29093"
"39957","239.70600","19.97562","0.29356"
"40026","240.12000","20.01024","0.29497"
"40095","240.53400","20.04468","0.29703"
"40164","240.94800","20.07918","0.30194"
"40233","241.36200","20.11362","0.30423"
"40302","241.77600","20.14812","0.30758"
"40371","242.19000","20.18267","0.30975"
"40440","242.60400","20.21717","0.31146"
"40509","243.01800","20.25161","0.31362"
"40578","243.43200","20.28617","0.31556"
"40647","243.84600","20.32073","0.31690"
"40716","244.26000","20.35523","0.31873"
"40785","244.67400","20.38967","0.32032"
"40854","245.08800","20.42417","0.32174"
"40923","245.50200","20.45866","0.32330"
"40992","245.91600","20.49316","0.32473"
"41061","246.33000","20.52766","0.32648"
"41130","246.74400","20.56210","0.32797"
"41199","247.15800","20.59666","0.32950"
"41268","247.57200","20.63122","0.33099"
"41337","247.98600","20.66571","0.33194"
"41406","248.40000","20.70009","0.33335"
"41475","248.81400","20.73465","0.33452"
"41544","249.22800","20.76915","0.33553"
"41613","249.64200","20.80371","0.33697"
"41682","250.05600","20.83815","0.33807"
"41751","250.47000","20.87259","0.33987"
"41820","250.88400","20.90720","0.34147"
"41889","251.29800","20.94170","0.34256"
"41958","251.71200","20.97620","0.34420"
"42027","252.12600","21.01064","0.34535"
"42096","252.54000","21.04520","0.34717"
"42165","252.95400","21.07970","0.34931"
"42234","253.36800","21.11420","0.35194"
"42303","253.78200","21.14863","0.35480"
"42372","254.19600","21.18313","0.35783"
"42441","254.61000","21.21769","0.35802"
"42510","255.02400","21.25225","0.36088"
"42579","255.43800","21.28669","0.36468"
"42648","255.85200","21.32113","0.36641"
"42717","256.26600","21.35568","0.36916"
"42786","256.68000","21.39018","0.37142"
"42855","257.09400","21.42468","0.37295"
"42924","257.50800","21.45912","0.37533"
"42993","257.92200","21.49368","0.37775"
"43062","258.33600","21.52818","0.38031"
"43131","258.75000","21.56268","0.38275"
"43200","259.16400","21.59711","0.38446"
"43269","259.57800","21.63167","0.38690"
"43338","259.99200","21.66617","0.38920"
"43407","260.40600","21.70067","0.39097"
"43476","260.82000","21.73517","0.39311"
"43545","261.23400","21.76961","0.39398"
"43614","261.64800","21.80416","0.39559"
"43683","262.06200","21.83872","0.39755"
"43752","262.47600","21.87322","0.39945"
"43821","262.89000","21.90766","0.40238"
"43890","263.30400","21.94210","0.40414"
"43959","263.71800","21.97672","0.40721"
"44028","264.13200","22.01116","0.41010"
"44097","264.54600","22.04565","0.41256"
"44166","264.96000","22.08015","0.41365"
"44235","265.37400","22.11465","0.41545"
"44304","265.78800","22.14921","0.41713"
"44373","266.20200","22.18365","0.41883"
"44442","266.61600","22.21809","0.42022"
"44511","267.03000","22.25265","0.42204"
"44580","267.44400","22.28715","0.42359"
"44649","267.85800","22.32164","0.42539"
"44718","268.27200","22.35608","0.42658"
"44787","268.68600","22.39070","0.42864"
"44856","269.10000","22.42520","0.43062"
"44925","269.51400","22.45964","0.43318"
"44994","269.92800","22.49414","0.43540"
"45063","270.34200","22.52864","0.43843"
"45132","270.75600","22.56314","0.44096"
"45201","271.17000","22.59769","0.44327"
"45270","271.58400","22.63213","0.44628"
"45339","271.99800","22.66663","0.44957"
"45408","272.41200","22.70119","0.45118"
"45477","272.82600","22.73569","0.45411"
"45546","273.24000","22.77019","0.45639"
"45615","273.65400","22.80462","0.45966"
"45684","274.06800","22.83912","0.46212"
"45753","274.48200","22.87368","0.46574"
"45822","274.89600","22.90818","0.46789"
"45891","275.31000","22.94256","0.47011"
"45960","275.72400","22.97718","0.47177"
"46029","276.13800","23.01173","0.47417"
"46098","276.55200","23.04618","0.47633"
"46167","276.96600","23.08061","0.47942"
"46236","277.38000","23.11511","0.48190"
"46305","277.79400","23.14967","0.48387"
"46374","278.20800","23.18417","0.48623"
"46443","278.62200","23.21867","0.48906"
"46512","279.03600","23.25311","0.49129"
"46581","279.45000","23.28766","0.49340"
"46650","279.86400","23.32222","0.49549"
"46719","280.27800","23.35672","0.49728"
"46788","280.69200","23.39116","0.49996"
"46857","281.10600","23.42566","0.50312"
"46926","281.52000","23.46016","0.50641"
"46995","281.93400","23.49466","0.50920"
"47064","282.34800","23.52916","0.51308"
"47133","282.76200","23.56359","0.51776"
"47202","283.17600","23.59821","0.52149"
"47271","283.59000","23.63271","0.52494"
"47340","284.00400","23.66721","0.52716"
"47409","284.41800","23.70165","0.53002"
"47478","284.83200","23.73615","0.53210"
"47547","285.24600","23.77070","0.53458"
"47616","285.66000","23.80520","0.53681"
"47685","286.07400","23.83964","0.53885"
"47754","286.48800","23.87414","0.54202"
"47823","286.90200","23.90876","0.54432"
"47892","287.31600","23.94320","0.54761"
"47961","287.73000","23.97770","0.55013"
"48030","288.14400","24.01220","0.55284"
"48099","288.55800","24.04669","0.55539"
"48168","288.97200","24.08113","0.55818"
"48237","289.38600","24.11563","0.56133"
"48306","289.80000","24.15013","0.56514"
"48375","290.21400","24.18463","0.56820"
"48444","290.62800","24.21918","0.56998"
"48513","291.04200","24.25374","0.57158"
"48582","291.45600","24.28818","0.57423"
"48651","291.87000","24.32262","0.57617"
"48720","292.28400","24.35718","0.57940"
"48789","292.69800","24.39168","0.52775"
"48858","293.11200","24.42612","0.52763"
"48927","293.52600","24.46061","0.52932"
"48996","293.94000","24.49517","0.53144"
"49065","294.35400","24.52967","0.53384"
"49134","294.76800","24.56417","0.53547"
"49203","295.18200","24.59867","0.53742"
"49272","295.59600","24.63317","0.53883"
"49341","296.01000","24.66767","0.54255"
"49410","296.42400","24.70222","0.54435"
"49479","296.83800","24.73666","0.54755"
"49548","297.25200","24.77116","0.54987"
"49617","297.66600","24.80566","0.55240"
"49686","298.08000","24.84022","0.55563"
"49755","298.49400","24.87472","0.55946"
"49824","298.90800","24.90910","0.56496"
"49893","299.32200","24.94365","0.56894"
"49962","299.73600","24.97816","0.57316"
"50031","300.15000","25.01265","0.57649"
"50100","300.56400","25.04709","0.58086"
"50169","300.97800","25.08171","0.58535"
"50238","301.39200","25.11621","0.59030"
"50307","301.80600","25.15065","0.59407"
"50376","302.22000","25.18514","0.59859"
"50445","302.63400","25.21964","0.60221"
"50514","303.04800","25.25420","0.60654"
"50583","303.46200","25.28864","0.61012"
"50652","303.87600","25.32314","0.61439"
"50721","304.29000","25.35758","0.61781"
"50790","304.70400","25.39219","0.62091"
"50859","305.11800","25.42663","0.62332"
"50928","305.53200","25.46113","0.62572"
"50997","305.94600","25.49563","0.62834"
"51066","306.36000","25.53013","0.63106"
"51135","306.77400","25.56469","0.63331"
"51204","307.18800","25.59919","0.63510"
"51273","307.60200","25.63363","0.63724"
"51342","308.01600","25.66813","0.38618"
"51411","308.43000","25.70268","0.38184"
"51480","308.84400","25.73718","0.38197"
"51549","309.25800","25.77162","0.38370"
"51618","309.67200","25.80612","0.38463"
"51687","310.08600","25.84068","0.38649"
"51756","310.50000","25.87518","0.38922"
"51825","310.91400","25.90962","0.38943"
"51894","311.32800","25.94411","0.05089"
"51963","311.74200","25.97867","0.05574"
"52032","312.15600","26.01323","0.05599"
"52101","312.57000","26.04767","0.06713"
"52170","312.98400","26.08211","0.06442"
"52239","313.39800","26.11667","0.05777"
"52308","313.81200","26.15117","0.06088"
"52377","314.22600","26.18566","0.06046"
"52446","314.64000","26.22010","0.06373"
"52515","315.05400","26.25466","0.07092"
"52584","315.46800","26.28916","0.06928"
"52653","315.88200","26.32366","0.06512"
"52722","316.29600","26.35822","0.06686"
"52791","316.71000","26.39266","0.06919"
"52860","317.12400","26.42715","0.07034"
"52929","317.53800","26.46171","0.07317"
"52998","317.95200","26.49621","0.07605"
"53067","318.36600","26.53065","0.07589"
"53136","318.78000","26.56515","0.07497"
"53205","319.19400","26.59971","0.07542"
"53274","319.60800","26.63420","0.07664"
"53343","320.02200","26.66870","0.07884"
"53412","320.43600","26.70314","0.08102"
"53481","320.85000","26.73770","0.08176"
"53550","321.26400","26.77214","0.08291"
"53619","321.67800","26.80664","0.08298"
"53688","322.09200","26.84114","0.08333"
"53757","322.50600","26.87563","0.08390"
"53826","322.92000","26.91019","0.08587"
"53895","323.33400","26.94469","0.08689"
"53964","323.74800","26.97919","0.08754"
"54033","324.16200","27.01369","0.08978"
"54102","324.57600","27.04819","0.09236"
"54171","324.99000","27.08269","0.09344"
"54240","325.40400","27.11719","0.09425"
"54309","325.81800","27.15162","0.09501"
"54378","326.23200","27.18618","0.09567"
"54447","326.64600","27.22068","0.09498"
"54516","327.06000","27.25524","0.09568"
"54585","327.47400","27.28962","0.09692"
"54654","327.88800","27.32412","0.09913"
"54723","328.30200","27.35873","0.10013"
"54792","328.71600","27.39317","0.10230"
"54861","329.13000","27.42761","0.10351"
"54930","329.54400","27.46217","0.10507"
"54999","329.95800","27.49667","0.10564"
"55068","330.37200","27.53123","0.10599"
"55137","330.78600","27.56567","0.10681"
"55206","331.20000","27.60016","0.10780"
"55275","331.61400","27.63466","0.10836"
"55344","332.02800","27.66916","0.10854"
"55413","332.44200","27.70366","0.10957"
"55482","332.85600","27.73810","0.11041"
"55551","333.27000","27.77260","0.11080"
"55620","333.68400","27.80721","0.11179"
"55689","334.09800","27.84171","0.11297"
"55758","334.51200","27.87615","0.11395"
"55827","334.92600","27.91065","0.11424"
"55896","335.34000","27.94515","0.11547"
"55965","335.75400","27.97971","0.11654"
"56034","336.16800","28.01414","0.11750"
"56103","336.58200","28.04864","0.11905"
"56172","336.99600","28.08320","0.11827"
"56241","337.41000","28.11764","0.11136"
"56310","337.82400","28.15214","0.11183"
"56379","338.23800","28.18664","0.11293"
"56448","338.65200","28.22114","0.11403"
"56517","339.06600","28.25570","0.11564"
"56586","339.48000","28.29020","0.11577"
"56655","339.89400","28.32463","0.11395"
"56724","340.30800","28.35919","0.11390"
"56793","340.72200","28.39363","0.11476"
"56862","341.13600","28.42819","0.11529"
"56931","341.55000","28.46263","0.11557"
"57000","341.96400","28.49713","0.11553"
"57069","342.37800","28.53168","0.11478"
"57138","342.79200","28.56618","0.11642"
"57207","343.20600","28.60068","0.11677"
"57276","343.62000","28.63506","0.11712"
"57345","344.03400","28.66962","0.11620"
"57414","344.44800","28.70424","0.11718"
"57483","344.86200","28.73868","0.11826"
"57552","345.27600","28.77312","0.11890"
"57621","345.69000","28.80761","0.11974"
"57690","346.10400","28.84217","0.11982"
"57759","346.51800","28.87667","0.12144"
"57828","346.93200","28.91117","0.12148"
"57897","347.34600","28.94561","0.12260"
"57966","347.76000","28.98022","0.12276"
"58035","348.17400","29.01467","0.12278"
"58104","348.58800","29.04922","0.12311"
"58173","349.00200","29.08360","0.12451"
"58242","349.41600","29.11816","0.12629"
"58311","349.83000","29.15266","0.12772"
"58380","350.24400","29.18716","0.12889"
"58449","350.65800","29.22166","0.13022"
"58518","351.07200","29.25616","0.13178"
"58587","351.48600","29.29065","0.13271"
"58656","351.90000","29.32521","0.13371"
"58725","352.31400","29.35971","0.13559"
"58794","352.72800","29.39415","0.13692"
"58863","353.14200","29.42865","0.13798"
"58932","353.55600","29.46315","0.14020"
"59001","353.97000","29.49765","0.14105"
"59070","354.38400","29.53214","0.14274"
"59139","354.79800","29.56664","0.14470"
"59208","355.21200","29.60120","0.14656"
"59277","355.62600","29.63570","0.14837"
"59346","356.04000","29.67020","0.14914"
"59415","356.45400","29.70464","0.14953"
"59484","356.86800","29.73919","0.15189"
"59553","357.28200","29.77369","0.15383"
"59622","357.69600","29.80813","0.15648"
"59691","358.11000","29.84263","0.15807"
"59760","358.52400","29.87719","0.15979"
"59829","358.93800","29.91169","0.16038"
"59898","359.35200","29.94625","0.16200"
"59967","359.76600","29.98062","0.16321"
"60036","360.18000","30.01518","0.16488"
"60105","360.59400","30.04968","0.16631"
"60174","361.00800","30.08418","0.16859"
"60243","361.42200","30.11862","0.17082"
"60312","361.83600","30.15318","0.17208"
"60381","362.25000","30.18768","0.17432"
"60450","362.66400","30.22217","0.17571"
"60519","363.07800","30.25667","0.17782"
"60588","363.49200","30.29117","0.17837"
"60657","363.90600","30.32567","0.17984"
"60726","364.32000","30.36011","0.18152"
"60795","364.73400","30.39467","0.18363"
"60864","365.14800","30.42911","0.18526"
"60933","365.56200","30.46366","0.18685"
"61002","365.97600","30.49822","0.18789"
"61071","366.39000","30.53266","0.18898"
"61140","366.80400","30.56716","0.18965"
"61209","367.21800","30.60166","0.19101"
"61278","367.63200","30.63616","0.19297"
"61347","368.04600","30.67066","0.19489"
"61416","368.46000","30.70516","0.19684"
"61485","368.87400","30.73959","0.19880"
"61554","369.28800","30.77415","0.20120"
"61623","369.70200","30.80865","0.20343"
"61692","370.11600","30.84315","0.20591"
"61761","370.53000","30.87765","0.20761"
"61830","370.94400","30.91215","0.20833"
"61899","371.35800","30.94665","0.21053"
"61968","371.77200","30.98114","0.21239"
"62037","372.18600","31.01564","0.21495"
"62106","372.60000","31.05014","0.21658"
"62175","373.01400","31.08470","0.21877"
"62244","373.42800","31.11914","0.22027"
"62313","373.84200","31.15364","0.22151"
"62382","374.25600","31.18813","0.22360"
"62451","374.67000","31.22269","0.22489"
"62520","375.08400","31.25719","0.22705"
"62589","375.49800","31.29169","0.22834"
"62658","375.91200","31.32613","0.23067"
"62727","376.32600","31.36063","0.23241"
"62796","376.74000","31.39513","0.23535"
"62865","377.15400","31.42968","0.23483"
"62934","377.56800","31.46412","0.23761"
"63003","377.98200","31.49862","0.23913"
"63072","378.39600","31.53318","0.23978"
"63141","378.81000","31.56768","0.24165"
"63210","379.22400","31.60211","0.24436"
"63279","379.63800","31.63661","0.24524"
"63348","380.05200","31.67117","0.24771"
"63417","380.46600","31.70567","0.25020"
"63486","380.88000","31.74017","0.25363"
"63555","381.29400","31.77461","0.25627"
"63624","381.70800","31.80917","0.25462"
"63693","382.12200","31.84367","0.25146"
"63762","382.53600","31.87823","0.25424"
"63831","382.95000","31.91266","0.25568"
"63900","383.36400","31.94716","0.25484"
"63969","383.77800","31.98166","0.25356"
"64038","384.19200","32.01616","0.11799"
"64107","384.60600","32.05072","0.11717"
"64176","385.02000","32.08509","0.11775"
"64245","385.43400","32.11966","0.12019"
"64314","385.84800","32.15421","0.12295"
"64383","386.26200","32.18865","0.12428"
"64452","386.67600","32.22309","0.12692"
"64521","387.09000","32.25765","0.12957"
"64590","387.50400","32.29221","0.13093"
"64659","387.91800","32.32671","0.13291"
"64728","388.33200","32.36114","0.13451"
"64797","388.74600","32.39564","0.13601"
"64866","389.16000","32.43020","0.13837"
"64935","389.57400","32.46464","0.13918"
"65004","389.98800","32.49914","0.13572"
"65073","390.40200","32.53364","0.13468"
"65142","390.81600","32.56820","0.13708"
"65211","391.23000","32.60270","0.12605"
"65280","391.64400","32.63720","0.12457"
"65349","392.05800","32.67169","0.12744"
"65418","392.47200","32.70619","0.12984"
"65487","392.88600","32.74068","0.13309"
"65556","393.30000","32.77518","0.13000"
"65625","393.71400","32.80963","0.13207"
"65694","394.12800","32.84412","0.13340"
"65763","394.54200","32.87868","0.12591"
"65832","394.95600","32.91318","0.12643"
"65901","395.37000","32.94768","0.12261"
"65970","395.78400","32.98212","0.12274"
"66039","396.19800","33.01668","0.12433"
"66108","396.61200","33.05117","0.12598"
"66177","397.02600","33.08561","0.12612"
"66246","397.44000","33.12011","0.12798"
"66315","397.85400","33.15467","0.12946"
"66384","398.26800","33.18917","0.13065"
"66453","398.68200","33.22367","0.13364"
"66522","399.09600","33.25817","0.13577"
"66591","399.51000","33.29267","0.13801"
"66660","399.92400","33.32716","0.14049"
"66729","400.33800","33.36166","0.14379"
"66798","400.75200","33.39616","0.14495"
"66867","401.16600","33.43060","0.14851"
"66936","401.58000","33.46516","0.15168"
"67005","401.99400","33.49966","0.15491"
"67074","402.40800","33.53421","0.15805"
"67143","402.82200","33.56865","0.15941"
"67212","403.23600","33.60315","0.16122"
"67281","403.65000","33.63771","0.16348"
"67350","404.06400","33.67221","0.16585"
"67419","404.47800","33.70658","0.16861"
"67488","404.89200","33.74115","0.17171"
"67557","405.30600","33.77571","0.17341"
"67626","405.72000","33.81014","0.17667"
"67695","406.13400","33.84464","0.17884"
"67764","406.54800","33.87914","0.18118"
"67833","406.96200","33.91364","0.18427"
"67902","407.37600","33.94814","0.18652"
"67971","407.79000","33.98264","0.18933"
"68040","408.20400","34.01714","0.19058"
"68109","408.61800","34.05164","0.19323"
"68178","409.03200","34.08619","0.19551"
"68247","409.44600","34.12075","0.19606"
"68316","409.86000","34.15513","0.20080"
"68385","410.27400","34.18969","0.20426"
"68454","410.68800","34.22419","0.20737"
"68523","411.10200","34.25869","0.21095"
"68592","411.51600","34.29318","0.21432"
"68661","411.93000","34.32762","0.21656"
"68730","412.34400","34.36218","0.21977"
"68799","412.75800","34.39668","0.22247"
"68868","413.17200","34.43124","0.22470"
"68937","413.58600","34.46561","0.22677"
"69006","414.00000","34.50011","0.22927"
"69075","414.41400","34.53468","0.23140"
"69144","414.82800","34.56923","0.23466"
"69213","415.24200","34.60367","0.23711"
"69282","415.65600","34.63817","0.23979"
"69351","416.07000","34.67266","0.24284"
"69420","416.48400","34.70716","0.24587"
"69489","416.89800","34.74166","0.24852"
"69558","417.31200","34.77616","0.25353"
"69627","417.72600","34.81066","0.25743"
"69696","418.14000","34.84516","0.26129"
"69765","418.55400","34.87966","0.26438"
"69834","418.96800","34.91416","0.26721"
"69903","419.38200","34.94865","0.27195"
"69972","419.79600","34.98315","0.27597"
"70041","420.21000","35.01772","0.28004"
"70110","420.62400","35.05221","0.28321"
"70179","421.03800","35.08665","0.28751"
"70248","421.45200","35.12115","0.29130"
"70317","421.86600","35.15570","0.29727"
"70386","422.28000","35.19009","0.30211"
"70455","422.69400","35.22458","0.30701"
"70524","423.10800","35.25920","0.31278"
"70593","423.52200","35.29370","0.31670"
"70662","423.93600","35.32820","0.31969"
"70731","424.35000","35.36270","0.32129"
"70800","424.76400","35.39720","0.32229"
"70869","425.17800","35.43169","0.32357"
"70938","425.59200","35.46619","0.32407"
"71007","426.00600","35.50063","0.32866"
"71076","426.42000","35.53519","0.33201"
"71145","426.83400","35.56969","0.33549"
"71214","427.24800","35.60419","0.33903"
"71283","427.66200","35.63869","0.34080"
"71352","428.07600","35.67313","0.34136"
"71421","428.49000","35.70768","0.34258"
"71490","428.90400","35.74218","0.27433"
"71559","429.31800","35.77668","0.26590"
"71628","429.73200","35.81112","0.26960"
"71697","430.14600","35.84562","0.27763"
"71766","430.56000","35.88018","0.28246"
"71835","430.97400","35.91467","0.28088"
"71904","431.38800","35.94917","0.28203"
"71973","431.80200","35.98367","0.28539"
"72042","432.21600","36.01817","0.28878"
"72111","432.63000","36.05267","0.29070"
"72180","433.04400","36.08717","0.29518"
"72249","433.45800","36.12160","0.29654"
"72318","433.87200","36.15617","0.29686"
"72387","434.28600","36.19066","0.30140"
"72456","434.70000","36.22516","0.30918"
"72525","435.11400","36.25966","0.31287"
"72594","435.52800","36.29416","0.31582"
"72663","435.94200","36.32872","0.28736"
"72732","436.35600","36.36316","0.29491"
"72801","436.77000","36.39759","0.30003"
"72870","437.18400","36.43216","0.30472"
"72939","437.59800","36.46666","0.30706"
"73008","438.01200","36.50121","0.31399"
"73077","438.42600","36.53565","0.31744"
"73146","438.84000","36.57015","0.31927"
"73215","439.25400","36.60471","0.32121"
"73284","439.66800","36.63914","0.32369"
"73353","440.08200","36.67364","0.32687"
"73422","440.49600","36.70808","0.32975"
"73491","440.91000","36.74264","0.33238"
"73560","441.32400","36.77720","0.33582"
"73629","441.73800","36.81170","0.33965"
"73698","442.15200","36.84614","0.34038"
"73767","442.56600","36.88063","0.34370"
"73836","442.98000","36.91520","0.34562"
"73905","443.39400","36.94963","0.34357"
"73974","443.80800","36.98413","0.34823"
"74043","444.22200","37.01857","0.35366"
"74112","444.63600","37.05313","0.35982"
"74181","445.05000","37.08768","0.36515"
"74250","445.46400","37.12218","0.36876"
"74319","445.87800","37.15662","0.37385"
"74388","446.29200","37.19112","0.37829"
"74457","446.70600","37.22574","0.38375"
"74526","447.12000","37.26018","0.38779"
"74595","447.53400","37.29462","0.39115"
"74664","447.94800","37.32918","0.39416"
"74733","448.36200","37.36367","0.39690"
"74802","448.77600","37.39817","0.40098"
"74871","449.19000","37.43261","0.40393"
"74940","449.60400","37.46717","0.40926"
"75009","450.01800","37.50167","0.41355"
"75078","450.43200","37.53617","0.41793"
"75147","450.84600","37.57067","0.42057"
"75216","451.26000","37.60517","0.41145"
"75285","451.67400","37.63966","0.41564"
"75354","452.08800","37.67422","0.36635"
"75423","452.50200","37.70872","0.37157"
"75492","452.91600","37.74316","0.37707"
"75561","453.33000","37.77766","0.37378"
"75630","453.74400","37.81215","0.37558"
"75699","454.15800","37.84665","0.37739"
"75768","454.57200","37.88121","0.38006"
"75837","454.98600","37.91559","0.38635"
"75906","455.40000","37.95015","0.38895"
"75975","455.81400","37.98471","0.39253"
"76044","456.22800","38.01921","0.39502"
"76113","456.64200","38.05365","0.39588"
"76182","457.05600","38.08815","0.39955"
"76251","457.47000","38.12270","0.40273"
"76320","457.88400","38.15720","0.40658"
"76389","458.29800","38.19164","0.41192"
"76458","458.71200","38.22620","0.41490"
"76527","459.12600","38.26070","0.41877"
"76596","459.54000","38.29514","0.42010"
"76665","459.95400","38.32969","0.42317"
"76734","460.36800","38.36414","0.42456"
"76803","460.78200","38.39869","0.42682"
"76872","461.19600","38.43319","0.42998"
"76941","461.61000","38.46769","0.43307"
"77010","462.02400","38.50213","0.43689"
"77079","462.43800","38.53663","0.43765"
"77148","462.85200","38.57119","0.44016"
"77217","463.26600","38.60574","0.44146"
"77286","463.68000","38.64018","0.25731"
"77355","464.09400","38.67462","0.25107"
"77424","464.50800","38.70918","0.24699"
"77493","464.92200","38.74368","0.24876"
"77562","465.33600","38.77811","0.25255"
"77631","465.75000","38.81261","0.25519"
"77700","466.16400","38.84711","0.25599"
"77769","466.57800","38.88167","0.26035"
"77838","466.99200","38.91617","0.26296"
"77907","467.40600","38.95067","0.26435"
"77976","467.82000","38.98517","0.26724"
"78045","468.23400","39.01966","0.27035"
"78114","468.64800","39.05416","0.27378"
"78183","469.06200","39.08860","0.27689"
"78252","469.47600","39.12316","0.28084"
"78321","469.89000","39.15760","0.28353"
"78390","470.30400","39.19216","0.28668"
"78459","470.71800","39.22666","0.29034"
"78528","471.13200","39.26110","0.29339"
"78597","471.54600","39.29571","0.29584"
"78666","471.96000","39.33015","0.30022"
"78735","472.37400","39.36471","0.30418"
"78804","472.78800","39.39909","0.30715"
"78873","473.20200","39.43365","0.22630"
"78942","473.61600","39.46821","0.22299"
"79011","474.03000","39.50270","0.22314"
"79080","474.44400","39.53714","0.22395"
"79149","474.85800","39.57164","0.22571"
"79218","475.27200","39.60620","0.22701"
"79287","475.68600","39.64064","0.22734"
"79356","476.10000","39.67514","0.22839"
"79425","476.51400","39.70958","0.23060"
"79494","476.92800","39.74419","0.23236"
"79563","477.34200","39.77869","0.23477"
"79632","477.75600","39.81319","0.23810"
"79701","478.17000","39.84763","0.23995"
"79770","478.58400","39.88213","0.11835"
"79839","478.99800","39.91669","0.12296"
"79908","479.41200","39.95119","0.12853"
"79977","479.82600","39.98563","0.12214"
"80046","480.24000","40.02012","0.12024"
"80115","480.65400","40.05462","0.12201"
"80184","481.06800","40.08918","0.12418"
"80253","481.48200","40.12368","0.12933"
"80322","481.89600","40.15812","0.13121"
"80391","482.31000","40.19268","0.12706"
"80460","482.72400","40.22717","0.12521"
"80529","483.13800","40.26167","0.12844"
"80598","483.55200","40.29611","0.13388"
"80667","483.96600","40.33067","0.13837"
"80736","484.38000","40.36523","0.13753"
"80805","484.79400","40.39966","0.13586"
"80874","485.20800","40.43417","0.13599"
"80943","485.62200","40.46867","0.13582"
"81012","486.03600","40.50316","0.13899"
"81081","486.45000","40.53766","0.14377"
"81150","486.86400","40.57216","0.14551"
"81219","487.27800","40.60660","0.14490"
"81288","487.69200","40.64116","0.14474"
"81357","488.10600","40.67566","0.14580"
"81426","488.52000","40.71021","0.14678"
"81495","488.93400","40.74466","0.14973"
"81564","489.34800","40.77915","0.15417"
"81633","489.76200","40.81371","0.15625"
"81702","490.17600","40.84815","0.15645"
"81771","490.59000","40.88259","0.15606"
"81840","491.00400","40.91714","0.15718"
"81909","491.41800","40.95171","0.15707"
"81978","491.83200","40.98620","0.15849"
"82047","492.24600","41.02064","0.16074"
"82116","492.66000","41.05514","0.16226"
"82185","493.07400","41.08969","0.16311"
"82254","493.48800","41.12420","0.16442"
"82323","493.90200","41.15870","0.16545"
"82392","494.31600","41.19307","0.16571"
"82461","494.73000","41.22763","0.16690"
"82530","495.14400","41.26225","0.16751"
"82599","495.55800","41.29669","0.16884"
"82668","495.97200","41.33119","0.11258"
"82737","496.38600","41.36568","0.02970"
"82806","496.80000","41.40019","0.03052"
"82875","497.21400","41.43468","0.03149"
"82944","497.62800","41.46924","0.03135"
"83013","498.04200","41.50356","0.03107"
"83082","498.45600","41.53818","0.03052"
"83151","498.87000","41.57273","0.03084"
"83220","499.28400","41.60717","0.03072"
"83289","499.69800","41.64162","0.03312"
"83358","500.11200","41.67617","0.03107"
"83427","500.52600","41.71074","0.03134"
"83496","500.94000","41.74517","0.03159"
"83565","501.35400","41.77961","0.03097"
"83634","501.76800","41.81411","0.03030"
"83703","502.18200","41.84867","0.03047"
"83772","502.59600","41.88316","0.03084"
"83841","503.01000","41.91767","0.03109"
"83910","503.42400","41.95210","0.03155"
"83979","503.83800","41.98672","0.03079"
"84048","504.25200","42.02122","0.03044"
"84117","504.66600","42.05566","0.03148"
"84186","505.08000","42.09016","0.03101"
"84255","505.49400","42.12460","0.03054"
"84324","505.90800","42.15915","0.03132"
"84393","506.32200","42.19365","0.03089"
"84462","506.73600","42.22809","0.03066"
"84531","507.15000","42.26259","0.03191"
"84600","507.56400","42.29721","0.03101"
"84669","507.97800","42.33171","0.03067"
"84738","508.39200","42.36615","0.03182"
"84784","508.66800","42.38911","0.03040"