File: Trajectories_together/161223_3Specimen_RawData_1.csv
"","V1","V2","V3"
"1","End date","12/23/2016",""
"2","Specimen label","21DG_67",""
"3","Maximum Load","0.99029","N"
"4","Time","Extension","Load"
"5","(s)","(mm)","(N)"
"6","0.00000","0.00006","-0.00037"
"72","0.39600","0.03324","-0.00020"
"138","0.79200","0.06619","0.00032"
"204","1.18800","0.09931","0.00020"
"270","1.58400","0.13225","0.00035"
"336","1.98000","0.16520","0.00029"
"402","2.37600","0.19820","0.00015"
"468","2.77200","0.23127","0.00008"
"534","3.16800","0.26421","-0.00028"
"600","3.56400","0.29721","-0.00019"
"666","3.96000","0.33016","0.00003"
"732","4.35600","0.36322","-0.00013"
"798","4.75200","0.39629","0.00000"
"864","5.14800","0.42923","0.00006"
"930","5.54400","0.46223","0.00053"
"996","5.94000","0.49524","0.00020"
"1062","6.33600","0.52824","0.00032"
"1128","6.73200","0.56124","0.00053"
"1194","7.12800","0.59425","0.00074"
"1260","7.52400","0.62725","0.00055"
"1326","7.92000","0.66020","0.00013"
"1392","8.31600","0.69320","0.00093"
"1458","8.71200","0.72626","0.00116"
"1524","9.10800","0.75921","0.00077"
"1590","9.50400","0.79221","0.00092"
"1656","9.90000","0.82527","0.00087"
"1722","10.29600","0.85828","0.00050"
"1788","10.69200","0.89128","0.00069"
"1854","11.08800","0.92423","0.00038"
"1920","11.48400","0.95729","0.00035"
"1986","11.88000","0.99029","0.00033"
"2052","12.27600","1.02318","0.00059"
"2118","12.67200","1.05618","0.00050"
"2184","13.06800","1.08925","0.00062"
"2250","13.46400","1.12225","0.00060"
"2316","13.86000","1.15519","0.00054"
"2382","14.25600","1.18820","0.00107"
"2448","14.65200","1.22126","0.00095"
"2514","15.04800","1.25426","0.00071"
"2580","15.44400","1.28715","0.00105"
"2646","15.84000","1.32021","0.00069"
"2712","16.23600","1.35328","0.00096"
"2778","16.63200","1.38628","0.00076"
"2844","17.02800","1.41916","0.00140"
"2910","17.42400","1.45217","0.00084"
"2976","17.82000","1.48523","0.00053"
"3042","18.21600","1.51824","0.00104"
"3108","18.61200","1.55118","0.00078"
"3174","19.00800","1.58424","0.00116"
"3240","19.40400","1.61725","0.00095"
"3306","19.80000","1.65025","0.00127"
"3372","20.19600","1.68319","0.00104"
"3438","20.59200","1.71626","0.00120"
"3504","20.98800","1.74926","0.00111"
"3570","21.38400","1.78227","0.00156"
"3636","21.78000","1.81521","0.00112"
"3702","22.17600","1.84821","0.00108"
"3768","22.57200","1.88128","0.00135"
"3834","22.96800","1.91422","0.00133"
"3900","23.36400","1.94723","0.00102"
"3966","23.76000","1.98029","0.00147"
"4032","24.15600","2.01329","0.00171"
"4098","24.55200","2.04618","0.00105"
"4164","24.94800","2.07924","0.00104"
"4230","25.34400","2.11224","0.00093"
"4296","25.74000","2.14519","0.00112"
"4362","26.13600","2.17819","0.00085"
"4428","26.53200","2.21126","0.00139"
"4494","26.92800","2.24426","0.00084"
"4560","27.32400","2.27720","0.00106"
"4626","27.72000","2.31021","0.00083"
"4692","28.11600","2.34327","0.00164"
"4758","28.51200","2.37622","0.00123"
"4824","28.90800","2.40916","0.00162"
"4890","29.30400","2.44222","0.00157"
"4956","29.70000","2.47523","0.00202"
"5022","30.09600","2.50823","0.00119"
"5088","30.49200","2.54117","0.00123"
"5154","30.88800","2.57418","0.00132"
"5220","31.28400","2.60724","0.00157"
"5286","31.68000","2.64025","0.00138"
"5352","32.07600","2.67319","0.00141"
"5418","32.47200","2.70619","0.00137"
"5484","32.86800","2.73932","0.00108"
"5550","33.26400","2.77226","0.00164"
"5616","33.66000","2.80521","0.00142"
"5682","34.05600","2.83821","0.00151"
"5748","34.45200","2.87127","0.00122"
"5814","34.84800","2.90422","0.00163"
"5880","35.24400","2.93722","0.00147"
"5946","35.64000","2.97028","0.00150"
"6012","36.03600","3.00323","0.00213"
"6078","36.43200","3.03623","0.00114"
"6144","36.82800","3.06924","0.00139"
"6210","37.22400","3.10224","0.00191"
"6276","37.62000","3.13524","0.00149"
"6342","38.01600","3.16819","0.00148"
"6408","38.41200","3.20119","0.00170"
"6474","38.80800","3.23426","0.00193"
"6540","39.20400","3.26720","0.00172"
"6606","39.60000","3.30014","0.00170"
"6672","39.99600","3.33321","0.00151"
"6738","40.39200","3.36621","0.00188"
"6804","40.78800","3.39921","0.00146"
"6870","41.18400","3.43222","0.00159"
"6936","41.58000","3.46522","0.00186"
"7002","41.97600","3.49823","0.00167"
"7068","42.37200","3.53123","0.00191"
"7134","42.76800","3.56423","0.00181"
"7200","43.16400","3.59724","0.00179"
"7266","43.56000","3.63024","0.00173"
"7332","43.95600","3.66319","0.00165"
"7398","44.35200","3.69619","0.00211"
"7464","44.74800","3.72925","0.00182"
"7530","45.14400","3.76226","0.00196"
"7596","45.54000","3.79520","0.00165"
"7662","45.93600","3.82820","0.00179"
"7728","46.33200","3.86121","0.00165"
"7794","46.72800","3.89427","0.00151"
"7860","47.12400","3.92722","0.00226"
"7926","47.52000","3.96022","0.00214"
"7992","47.91600","3.99328","0.00183"
"8058","48.31200","4.02623","0.00239"
"8124","48.70800","4.05917","0.00162"
"8190","49.10400","4.09223","0.00203"
"8256","49.50000","4.12530","0.00165"
"8322","49.89600","4.15818","0.00208"
"8388","50.29200","4.19119","0.00193"
"8454","50.68800","4.22425","0.00170"
"8520","51.08400","4.25725","0.00211"
"8586","51.48000","4.29020","0.00192"
"8652","51.87600","4.32320","0.00180"
"8718","52.27200","4.35627","0.00209"
"8784","52.66800","4.38921","0.00185"
"8850","53.06400","4.42221","0.00232"
"8916","53.46000","4.45522","0.00220"
"8982","53.85600","4.48822","0.00219"
"9048","54.25200","4.52122","0.00238"
"9114","54.64800","4.55423","0.00195"
"9180","55.04400","4.58723","0.00253"
"9246","55.44000","4.62024","0.00199"
"9312","55.83600","4.65324","0.00213"
"9378","56.23200","4.68624","0.00233"
"9444","56.62800","4.71925","0.00232"
"9510","57.02400","4.75225","0.00215"
"9576","57.42000","4.78520","0.00235"
"9642","57.81600","4.81820","0.00257"
"9708","58.21200","4.85126","0.00250"
"9774","58.60800","4.88427","0.00277"
"9840","59.00400","4.91715","0.00247"
"9906","59.40000","4.95027","0.00253"
"9972","59.79600","4.98328","0.00256"
"10038","60.19200","5.01622","0.00227"
"10104","60.58800","5.04917","0.00243"
"10170","60.98400","5.08229","0.00273"
"10236","61.38000","5.11529","0.00269"
"10302","61.77600","5.14824","0.00256"
"10368","62.17200","5.18118","0.00228"
"10434","62.56800","5.21424","0.00258"
"10500","62.96400","5.24731","0.00271"
"10566","63.36000","5.28019","0.00269"
"10632","63.75600","5.31320","0.00306"
"10698","64.15200","5.34626","0.00293"
"10764","64.54800","5.37926","0.00238"
"10830","64.94400","5.41221","0.00291"
"10896","65.34000","5.44521","0.00286"
"10962","65.73600","5.47828","0.00285"
"11028","66.13200","5.51128","0.00298"
"11094","66.52800","5.54416","0.00287"
"11160","66.92400","5.57723","0.00285"
"11226","67.32000","5.61023","0.00305"
"11292","67.71600","5.64324","0.00319"
"11358","68.11200","5.67618","0.00348"
"11424","68.50800","5.70918","0.00327"
"11490","68.90400","5.74225","0.00314"
"11556","69.30000","5.77525","0.00302"
"11622","69.69600","5.80819","0.00333"
"11688","70.09200","5.84126","0.00292"
"11754","70.48800","5.87426","0.00337"
"11820","70.88400","5.90721","0.00306"
"11886","71.28000","5.94021","0.00339"
"11952","71.67600","5.97327","0.00343"
"12018","72.07200","6.00628","0.00362"
"12084","72.46800","6.03922","0.00349"
"12150","72.86400","6.07223","0.00372"
"12216","73.26000","6.10523","0.00332"
"12282","73.65600","6.13823","0.00369"
"12348","74.05200","6.17124","0.00377"
"12414","74.44800","6.20424","0.00392"
"12480","74.84400","6.23724","0.00365"
"12546","75.24000","6.27025","0.00351"
"12612","75.63600","6.30313","0.00367"
"12678","76.03200","6.33626","0.00378"
"12744","76.42800","6.36926","0.00418"
"12810","76.82400","6.40220","0.00390"
"12876","77.22000","6.43515","0.00427"
"12942","77.61600","6.46827","0.00412"
"13008","78.01200","6.50127","0.00375"
"13074","78.40800","6.53416","0.00398"
"13140","78.80400","6.56722","0.00334"
"13206","79.20000","6.60029","0.00374"
"13272","79.59600","6.63323","0.00390"
"13338","79.99200","6.66617","0.00345"
"13404","80.38800","6.69924","0.00427"
"13470","80.78400","6.73230","0.00440"
"13536","81.18000","6.76525","0.00418"
"13602","81.57600","6.79813","0.00435"
"13668","81.97200","6.83119","0.00371"
"13734","82.36800","6.86426","0.00415"
"13800","82.76400","6.89726","0.00339"
"13866","83.16000","6.93020","0.00361"
"13932","83.55600","6.96321","0.00385"
"13998","83.95200","6.99627","0.00386"
"14064","84.34800","7.02922","0.00394"
"14130","84.74400","7.06216","0.00406"
"14196","85.14000","7.09522","0.00339"
"14262","85.53600","7.12829","0.00359"
"14328","85.93200","7.16123","0.00395"
"14394","86.32800","7.19418","0.00346"
"14460","86.72400","7.22730","0.00378"
"14526","87.12000","7.26024","0.00408"
"14592","87.51600","7.29325","0.00350"
"14658","87.91200","7.32619","0.00391"
"14724","88.30800","7.35926","0.00374"
"14790","88.70400","7.39220","0.00391"
"14856","89.10000","7.42520","0.00437"
"14922","89.49600","7.45821","0.00387"
"14988","89.89200","7.49121","0.00402"
"15054","90.28800","7.52415","0.00480"
"15120","90.68400","7.55722","0.00406"
"15186","91.08000","7.59022","0.00428"
"15252","91.47600","7.62323","0.00409"
"15318","91.87200","7.65623","0.00448"
"15384","92.26800","7.68923","0.00426"
"15450","92.66400","7.72230","0.00475"
"15516","93.06000","7.75524","0.00432"
"15582","93.45600","7.78819","0.00466"
"15648","93.85200","7.82125","0.00446"
"15714","94.24800","7.85431","0.00494"
"15780","94.64400","7.88720","0.00465"
"15846","95.04000","7.92014","0.00470"
"15912","95.43600","7.95326","0.00495"
"15978","95.83200","7.98627","0.00456"
"16044","96.22800","8.01927","0.00458"
"16110","96.62400","8.05216","0.00505"
"16176","97.02000","8.08528","0.00508"
"16242","97.41600","8.11828","0.00479"
"16308","97.81200","8.15123","0.00492"
"16374","98.20800","8.18423","0.00477"
"16440","98.60400","8.21723","0.00470"
"16506","99.00000","8.25030","0.00550"
"16572","99.39600","8.28318","0.00543"
"16638","99.79200","8.31625","0.00550"
"16704","100.18800","8.34925","0.00507"
"16770","100.58400","8.38231","0.00561"
"16836","100.98000","8.41514","0.00523"
"16902","101.37600","8.44820","0.00545"
"16968","101.77200","8.48127","0.00505"
"17034","102.16800","8.51427","0.00564"
"17100","102.56400","8.54721","0.00594"
"17166","102.96000","8.58016","0.00539"
"17232","103.35600","8.61322","0.00559"
"17298","103.75200","8.64616","0.00549"
"17364","104.14800","8.67923","0.00559"
"17430","104.54400","8.71223","0.00557"
"17496","104.94000","8.74524","0.00598"
"17562","105.33600","8.77824","0.00573"
"17628","105.73200","8.81124","0.00604"
"17694","106.12800","8.84425","0.00554"
"17760","106.52400","8.87725","0.00614"
"17826","106.92000","8.91025","0.00605"
"17892","107.31600","8.94320","0.00583"
"17958","107.71200","8.97620","0.00603"
"18024","108.10800","9.00921","0.00638"
"18090","108.50400","9.04221","0.00573"
"18156","108.90000","9.07527","0.00562"
"18222","109.29600","9.10822","0.00649"
"18288","109.69200","9.14122","0.00630"
"18354","110.08800","9.17417","0.00597"
"18420","110.48400","9.20729","0.00639"
"18486","110.88000","9.24029","0.00647"
"18552","111.27600","9.27324","0.00659"
"18618","111.67200","9.30618","0.00638"
"18684","112.06800","9.33930","0.00651"
"18750","112.46400","9.37225","0.00642"
"18816","112.86000","9.40519","0.00677"
"18882","113.25600","9.43826","0.00689"
"18948","113.65200","9.47126","0.00702"
"19014","114.04800","9.50420","0.00710"
"19080","114.44400","9.53715","0.00712"
"19146","114.84000","9.57027","0.00696"
"19212","115.23600","9.60328","0.00711"
"19278","115.63200","9.63628","0.00729"
"19344","116.02800","9.66916","0.00746"
"19410","116.42400","9.70223","0.00732"
"19476","116.82000","9.73523","0.00719"
"19542","117.21600","9.76823","0.00762"
"19608","117.61200","9.80118","0.00741"
"19674","118.00800","9.83424","0.00744"
"19740","118.40400","9.86725","0.00776"
"19806","118.80000","9.90025","0.00738"
"19872","119.19600","9.93325","0.00776"
"19938","119.59200","9.96626","0.00775"
"20004","119.98800","9.99926","0.00764"
"20070","120.38400","10.03221","0.00821"
"20136","120.78000","10.06521","0.00789"
"20202","121.17600","10.09827","0.00835"
"20268","121.57200","10.13128","0.00785"
"20334","121.96800","10.16422","0.00819"
"20400","122.36400","10.19722","0.00833"
"20466","122.76000","10.23023","0.00860"
"20532","123.15600","10.26323","0.00867"
"20598","123.55200","10.29624","0.00869"
"20664","123.94800","10.32924","0.00845"
"20730","124.34400","10.36224","0.00878"
"20796","124.74000","10.39519","0.00912"
"20862","125.13600","10.42819","0.00914"
"20928","125.53200","10.46125","0.00904"
"20994","125.92800","10.49420","0.00878"
"21060","126.32400","10.52720","0.00945"
"21126","126.72000","10.56021","0.00975"
"21192","127.11600","10.59327","0.00939"
"21258","127.51200","10.62627","0.00933"
"21324","127.90800","10.65922","0.00933"
"21390","128.30400","10.69222","0.00913"
"21456","128.70000","10.72529","0.00976"
"21522","129.09600","10.75823","0.00950"
"21588","129.49200","10.79117","0.00957"
"21654","129.88800","10.82424","0.00996"
"21720","130.28400","10.85730","0.01019"
"21786","130.68000","10.89024","0.01046"
"21852","131.07600","10.92313","0.00984"
"21918","131.47200","10.95625","0.01020"
"21984","131.86800","10.98926","0.01005"
"22050","132.26400","11.02220","0.01028"
"22116","132.66000","11.05520","0.00973"
"22182","133.05600","11.08821","0.01046"
"22248","133.45200","11.12127","0.01018"
"22314","133.84800","11.15422","0.01035"
"22380","134.24400","11.18716","0.01044"
"22446","134.64000","11.22028","0.01018"
"22512","135.03600","11.25329","0.01058"
"22578","135.43200","11.28617","0.01025"
"22644","135.82800","11.31923","0.01037"
"22710","136.22400","11.35230","0.01111"
"22776","136.62000","11.38530","0.01117"
"22842","137.01600","11.41819","0.01103"
"22908","137.41200","11.45119","0.01065"
"22974","137.80800","11.48425","0.01103"
"23040","138.20400","11.51726","0.01130"
"23106","138.60000","11.55026","0.01148"
"23172","138.99600","11.58321","0.01097"
"23238","139.39200","11.61621","0.01146"
"23304","139.78800","11.64921","0.01124"
"23370","140.18400","11.68216","0.01214"
"23436","140.58000","11.71522","0.01182"
"23502","140.97600","11.74822","0.01215"
"23568","141.37200","11.78117","0.01185"
"23634","141.76800","11.81423","0.01190"
"23700","142.16400","11.84724","0.01265"
"23766","142.56000","11.88024","0.01200"
"23832","142.95600","11.91318","0.01208"
"23898","143.35200","11.94625","0.01220"
"23964","143.74800","11.97925","0.01260"
"24030","144.14400","12.01225","0.01257"
"24096","144.54000","12.04514","0.01173"
"24162","144.93600","12.07826","0.01214"
"24228","145.33200","12.11127","0.01226"
"24294","145.72800","12.14421","0.01256"
"24360","146.12400","12.17715","0.01267"
"24426","146.52000","12.21028","0.01226"
"24492","146.91600","12.24328","0.01262"
"24558","147.31200","12.27623","0.01284"
"24624","147.70800","12.30923","0.01284"
"24690","148.10400","12.34223","0.01274"
"24756","148.50000","12.37530","0.01325"
"24822","148.89600","12.40818","0.01341"
"24888","149.29200","12.44125","0.01330"
"24954","149.68800","12.47425","0.01281"
"25020","150.08400","12.50731","0.01252"
"25086","150.48000","12.54014","0.01309"
"25152","150.87600","12.57314","0.01313"
"25218","151.27200","12.60627","0.01324"
"25284","151.66800","12.63927","0.01363"
"25350","152.06400","12.67215","0.01367"
"25416","152.46000","12.70522","0.01384"
"25482","152.85600","12.73822","0.01394"
"25548","153.25200","12.77122","0.01375"
"25614","153.64800","12.80417","0.01401"
"25680","154.04400","12.83723","0.01447"
"25746","154.44000","12.87024","0.01450"
"25812","154.83600","12.90324","0.01509"
"25878","155.23200","12.93618","0.01422"
"25944","155.62800","12.96925","0.01490"
"26010","156.02400","13.00225","0.01542"
"26076","156.42000","13.03520","0.01566"
"26142","156.81600","13.06820","0.01546"
"26208","157.21200","13.10126","0.01568"
"26274","157.60800","13.13421","0.01584"
"26340","158.00400","13.16721","0.01581"
"26406","158.40000","13.20027","0.01366"
"26472","158.79600","13.23322","0.01448"
"26538","159.19200","13.26616","0.01474"
"26604","159.58800","13.29923","0.01500"
"26670","159.98400","13.33229","0.01478"
"26736","160.38000","13.36523","0.01502"
"26802","160.77600","13.39824","0.01485"
"26868","161.17200","13.43118","0.01546"
"26934","161.56800","13.46430","0.01572"
"27000","161.96400","13.49725","0.01542"
"27066","162.36000","13.53013","0.01641"
"27132","162.75600","13.56320","0.01572"
"27198","163.15200","13.59632","0.01602"
"27264","163.54800","13.62920","0.01632"
"27330","163.94400","13.66215","0.01620"
"27396","164.34000","13.69521","0.01641"
"27462","164.73600","13.72827","0.01676"
"27528","165.13200","13.76122","0.01706"
"27594","165.52800","13.79416","0.01694"
"27660","165.92400","13.82723","0.01723"
"27726","166.32000","13.86023","0.01785"
"27792","166.71600","13.89323","0.01706"
"27858","167.11200","13.92618","0.01778"
"27924","167.50800","13.95918","0.01749"
"27990","167.90400","13.99225","0.01762"
"28056","168.30000","14.02519","0.01812"
"28122","168.69600","14.05819","0.01842"
"28188","169.09200","14.09126","0.01864"
"28254","169.48800","14.12432","0.01887"
"28320","169.88400","14.15721","0.01858"
"28386","170.28000","14.19021","0.01956"
"28452","170.67600","14.22327","0.01937"
"28518","171.07200","14.25628","0.01955"
"28584","171.46800","14.28922","0.01929"
"28650","171.86400","14.32216","0.01906"
"28716","172.26000","14.35529","0.01850"
"28782","172.65600","14.38823","0.01851"
"28848","173.05200","14.42124","0.01873"
"28914","173.44800","14.45424","0.01913"
"28980","173.84400","14.48718","0.01972"
"29046","174.24000","14.52025","0.01999"
"29112","174.63600","14.55319","0.02007"
"29178","175.03200","14.58625","0.02005"
"29244","175.42800","14.61926","0.02043"
"29310","175.82400","14.65226","0.02051"
"29376","176.22000","14.68521","0.02057"
"29442","176.61600","14.71827","0.02093"
"29508","177.01200","14.75121","0.02130"
"29574","177.40800","14.78422","0.02161"
"29640","177.80400","14.81722","0.02199"
"29706","178.20000","14.85028","0.02189"
"29772","178.59600","14.88323","0.02226"
"29838","178.99200","14.91617","0.02238"
"29904","179.38800","14.94924","0.02288"
"29970","179.78400","14.98224","0.02301"
"30036","180.18000","15.01524","0.02358"
"30102","180.57600","15.04819","0.02337"
"30168","180.97200","15.08125","0.02337"
"30234","181.36800","15.11426","0.02390"
"30300","181.76400","15.14720","0.02394"
"30366","182.16000","15.18020","0.02412"
"30432","182.55600","15.21327","0.02449"
"30498","182.95200","15.24633","0.02481"
"30564","183.34800","15.27921","0.02502"
"30630","183.74400","15.31228","0.02473"
"30696","184.14000","15.34528","0.02539"
"30762","184.53600","15.37829","0.02577"
"30828","184.93200","15.41117","0.02655"
"30894","185.32800","15.44423","0.02665"
"30960","185.72400","15.47724","0.02719"
"31026","186.12000","15.51030","0.02689"
"31092","186.51600","15.54319","0.02772"
"31158","186.91200","15.57619","0.02794"
"31224","187.30800","15.60925","0.02794"
"31290","187.70400","15.64226","0.02841"
"31356","188.10000","15.67520","0.02852"
"31422","188.49600","15.70820","0.02916"
"31488","188.89200","15.74127","0.02921"
"31554","189.28800","15.77421","0.02958"
"31620","189.68400","15.80722","0.03015"
"31686","190.08000","15.84022","0.03032"
"31752","190.47600","15.87322","0.03129"
"31818","190.87200","15.90623","0.03147"
"31884","191.26800","15.93923","0.03176"
"31950","191.66400","15.97224","0.03230"
"32016","192.06000","16.00524","0.03296"
"32082","192.45600","16.03818","0.03366"
"32148","192.85200","16.07125","0.03395"
"32214","193.24800","16.10425","0.03367"
"32280","193.64400","16.13719","0.03474"
"32346","194.04000","16.17020","0.03514"
"32412","194.43600","16.20326","0.03551"
"32478","194.83200","16.23621","0.03623"
"32544","195.22800","16.26921","0.03675"
"32610","195.62400","16.30221","0.03718"
"32676","196.02000","16.33528","0.03774"
"32742","196.41600","16.36828","0.03844"
"32808","196.81200","16.40123","0.03892"
"32874","197.20800","16.43423","0.03937"
"32940","197.60400","16.46723","0.04001"
"33006","198.00000","16.50024","0.04032"
"33072","198.39600","16.53318","0.04039"
"33138","198.79200","16.56618","0.04066"
"33204","199.18800","16.59925","0.04141"
"33270","199.58400","16.63219","0.04198"
"33336","199.98000","16.66514","0.04284"
"33402","200.37600","16.69820","0.04336"
"33468","200.77200","16.73120","0.04332"
"33534","201.16800","16.76427","0.04410"
"33600","201.56400","16.79721","0.04462"
"33666","201.96000","16.83022","0.04508"
"33732","202.35600","16.86322","0.04597"
"33798","202.75200","16.89628","0.04657"
"33864","203.14800","16.92917","0.04707"
"33930","203.54400","16.96223","0.04742"
"33996","203.94000","16.99523","0.04847"
"34062","204.33600","17.02818","0.04867"
"34128","204.73200","17.06124","0.04926"
"34194","205.12800","17.09425","0.04989"
"34260","205.52400","17.12725","0.05047"
"34326","205.92000","17.16019","0.05104"
"34392","206.31600","17.19320","0.05184"
"34458","206.71200","17.22626","0.05237"
"34524","207.10800","17.25926","0.05322"
"34590","207.50400","17.29221","0.05339"
"34656","207.90000","17.32521","0.05477"
"34722","208.29600","17.35822","0.05496"
"34788","208.69200","17.39122","0.05650"
"34854","209.08800","17.42422","0.05761"
"34920","209.48400","17.45723","0.05829"
"34986","209.88000","17.49023","0.05921"
"35052","210.27600","17.52324","0.06062"
"35118","210.67200","17.55618","0.06169"
"35184","211.06800","17.58924","0.06266"
"35250","211.46400","17.62225","0.06303"
"35316","211.86000","17.65525","0.06402"
"35382","212.25600","17.68819","0.06442"
"35448","212.65200","17.72126","0.06548"
"35514","213.04800","17.75426","0.06691"
"35580","213.44400","17.78715","0.06718"
"35646","213.84000","17.82021","0.06834"
"35712","214.23600","17.85328","0.06906"
"35778","214.63200","17.88616","0.06960"
"35844","215.02800","17.91916","0.07058"
"35910","215.42400","17.95223","0.07102"
"35976","215.82000","17.98523","0.07137"
"36042","216.21600","18.01823","0.07185"
"36108","216.61200","18.05118","0.07274"
"36174","217.00800","18.08424","0.07343"
"36240","217.40400","18.11724","0.07440"
"36306","217.80000","18.15019","0.07507"
"36372","218.19600","18.18319","0.07586"
"36438","218.59200","18.21626","0.07702"
"36504","218.98800","18.24932","0.07845"
"36570","219.38400","18.28221","0.07905"
"36636","219.78000","18.31521","0.08031"
"36702","220.17600","18.34827","0.08128"
"36768","220.57200","18.38128","0.08286"
"36834","220.96800","18.41422","0.08309"
"36900","221.36400","18.44716","0.08493"
"36966","221.76000","18.48029","0.08627"
"37032","222.15600","18.51323","0.08837"
"37098","222.55200","18.54618","0.08914"
"37164","222.94800","18.57924","0.09029"
"37230","223.34400","18.61224","0.09188"
"37296","223.74000","18.64519","0.09254"
"37362","224.13600","18.67819","0.09347"
"37428","224.53200","18.71125","0.09435"
"37494","224.92800","18.74426","0.09477"
"37560","225.32400","18.77720","0.09567"
"37626","225.72000","18.81021","0.09621"
"37692","226.11600","18.84321","0.09759"
"37758","226.51200","18.87621","0.09756"
"37824","226.90800","18.90922","0.09875"
"37890","227.30400","18.94222","0.09950"
"37956","227.70000","18.97522","0.10048"
"38022","228.09600","19.00823","0.10087"
"38088","228.49200","19.04117","0.10207"
"38154","228.88800","19.07424","0.10293"
"38220","229.28400","19.10724","0.10376"
"38286","229.68000","19.14018","0.10466"
"38352","230.07600","19.17319","0.10564"
"38418","230.47200","19.20625","0.10703"
"38484","230.86800","19.23932","0.10799"
"38550","231.26400","19.27220","0.10877"
"38616","231.66000","19.30520","0.10980"
"38682","232.05600","19.33827","0.11140"
"38748","232.45200","19.37121","0.11300"
"38814","232.84800","19.40415","0.11377"
"38880","233.24400","19.43722","0.11551"
"38946","233.64000","19.47028","0.11655"
"39012","234.03600","19.50329","0.11786"
"39078","234.43200","19.53617","0.11914"
"39144","234.82800","19.56917","0.12001"
"39210","235.22400","19.60224","0.12114"
"39276","235.62000","19.63524","0.12243"
"39342","236.01600","19.66818","0.12377"
"39408","236.41200","19.70119","0.12507"
"39474","236.80800","19.73425","0.12637"
"39540","237.20400","19.76726","0.12787"
"39606","237.60000","19.80020","0.12994"
"39672","237.99600","19.83321","0.13151"
"39738","238.39200","19.86627","0.13427"
"39804","238.78800","19.89927","0.13597"
"39870","239.18400","19.93221","0.13828"
"39936","239.58000","19.96528","0.14087"
"40002","239.97600","19.99828","0.14260"
"40068","240.37200","20.03117","0.14493"
"40134","240.76800","20.06423","0.14727"
"40200","241.16400","20.09729","0.14873"
"40266","241.56000","20.13024","0.15052"
"40332","241.95600","20.16318","0.15152"
"40398","242.35200","20.19624","0.15275"
"40464","242.74800","20.22919","0.15371"
"40530","243.14400","20.26219","0.15580"
"40596","243.54000","20.29520","0.15644"
"40662","243.93600","20.32826","0.15931"
"40728","244.33200","20.36127","0.16247"
"40794","244.72800","20.39421","0.16511"
"40860","245.12400","20.42721","0.16705"
"40926","245.52000","20.46022","0.16935"
"40992","245.91600","20.49322","0.17130"
"41058","246.31200","20.52622","0.12450"
"41124","246.70800","20.55923","0.12439"
"41190","247.10400","20.59223","0.12573"
"41256","247.50000","20.62530","0.12834"
"41322","247.89600","20.65818","0.12976"
"41388","248.29200","20.69124","0.13223"
"41454","248.68800","20.72425","0.13557"
"41520","249.08400","20.75725","0.14097"
"41586","249.48000","20.79020","0.14373"
"41652","249.87600","20.82326","0.14725"
"41718","250.27200","20.85626","0.14975"
"41784","250.66800","20.88921","0.15187"
"41850","251.06400","20.92221","0.15318"
"41916","251.46000","20.95522","0.15529"
"41982","251.85600","20.98822","0.15766"
"42048","252.25200","21.02122","0.15971"
"42114","252.64800","21.05423","0.16251"
"42180","253.04400","21.08723","0.16432"
"42246","253.44000","21.12024","0.16718"
"42312","253.83600","21.15318","0.17002"
"42378","254.23200","21.18618","0.17228"
"42444","254.62800","21.21925","0.17532"
"42510","255.02400","21.25225","0.17667"
"42576","255.42000","21.28519","0.17841"
"42642","255.81600","21.31820","0.17955"
"42708","256.21200","21.35126","0.18162"
"42774","256.60800","21.38420","0.18346"
"42840","257.00400","21.41721","0.18489"
"42906","257.40000","21.45021","0.18762"
"42972","257.79600","21.48322","0.18963"
"43038","258.19200","21.51622","0.19205"
"43104","258.58800","21.54922","0.19396"
"43170","258.98400","21.58229","0.19583"
"43236","259.38000","21.61523","0.19782"
"43302","259.77600","21.64818","0.19932"
"43368","260.17200","21.68118","0.20115"
"43434","260.56800","21.71424","0.20366"
"43500","260.96400","21.74725","0.20511"
"43566","261.36000","21.78019","0.20703"
"43632","261.75600","21.81319","0.20900"
"43698","262.15200","21.84626","0.21052"
"43764","262.54800","21.87920","0.21170"
"43830","262.94400","21.91215","0.21315"
"43896","263.34000","21.94521","0.21401"
"43962","263.73600","21.97827","0.21563"
"44028","264.13200","22.01122","0.21712"
"44094","264.52800","22.04416","0.21916"
"44160","264.92400","22.07722","0.22081"
"44226","265.32000","22.11029","0.22314"
"44292","265.71600","22.14323","0.22493"
"44358","266.11200","22.17618","0.22656"
"44424","266.50800","22.20924","0.22865"
"44490","266.90400","22.24230","0.23013"
"44556","267.30000","22.27519","0.23204"
"44622","267.69600","22.30819","0.23402"
"44688","268.09200","22.34126","0.23620"
"44754","268.48800","22.37426","0.23918"
"44820","268.88400","22.40720","0.24069"
"44886","269.28000","22.44027","0.24424"
"44952","269.67600","22.47321","0.24662"
"45018","270.07200","22.50628","0.24854"
"45084","270.46800","22.53922","0.25095"
"45150","270.86400","22.57216","0.25243"
"45216","271.26000","22.60523","0.25494"
"45282","271.65600","22.63823","0.25742"
"45348","272.05200","22.67118","0.26043"
"45414","272.44800","22.70424","0.26320"
"45480","272.84400","22.73724","0.26624"
"45546","273.24000","22.77024","0.25572"
"45612","273.63600","22.80319","0.25330"
"45678","274.03200","22.83625","0.25508"
"45744","274.42800","22.86926","0.25720"
"45810","274.82400","22.90220","0.25937"
"45876","275.22000","22.93521","0.26232"
"45942","275.61600","22.96827","0.26500"
"46008","276.01200","23.00121","0.26830"
"46074","276.40800","23.03422","0.27050"
"46140","276.80400","23.06722","0.27291"
"46206","277.20000","23.10023","0.27459"
"46272","277.59600","23.13323","0.27654"
"46338","277.99200","23.16623","0.27781"
"46404","278.38800","23.19924","0.25140"
"46470","278.78400","23.23224","0.24878"
"46536","279.18000","23.26518","0.24832"
"46602","279.57600","23.29819","0.24965"
"46668","279.97200","23.33125","0.24905"
"46734","280.36800","23.36426","0.25082"
"46800","280.76400","23.39720","0.25129"
"46866","281.16000","23.43014","0.25178"
"46932","281.55600","23.46321","0.25317"
"46998","281.95200","23.49627","0.25596"
"47064","282.34800","23.52921","0.25858"
"47130","282.74400","23.56222","0.26088"
"47196","283.14000","23.59522","0.26346"
"47262","283.53600","23.62829","0.26650"
"47328","283.93200","23.66117","0.26929"
"47394","284.32800","23.69423","0.27203"
"47460","284.72400","23.72724","0.27411"
"47526","285.12000","23.76024","0.27587"
"47592","285.51600","23.79318","0.27784"
"47658","285.91200","23.82619","0.28025"
"47724","286.30800","23.85925","0.28387"
"47790","286.70400","23.89226","0.28716"
"47856","287.10000","23.92520","0.29074"
"47922","287.49600","23.95820","0.29548"
"47988","287.89200","23.99127","0.29945"
"48054","288.28800","24.02421","0.30314"
"48120","288.68400","24.05722","0.30569"
"48186","289.08000","24.09022","0.30718"
"48252","289.47600","24.12328","0.30863"
"48318","289.87200","24.15617","0.31090"
"48384","290.26800","24.18923","0.31296"
"48450","290.66400","24.22224","0.31520"
"48516","291.06000","24.25524","0.31739"
"48582","291.45600","24.28818","0.31923"
"48648","291.85200","24.32125","0.32195"
"48714","292.24800","24.35425","0.32381"
"48780","292.64400","24.38719","0.32551"
"48846","293.04000","24.42020","0.32743"
"48912","293.43600","24.45326","0.32973"
"48978","293.83200","24.48627","0.33155"
"49044","294.22800","24.51921","0.33350"
"49110","294.62400","24.55215","0.33573"
"49176","295.02000","24.58528","0.33830"
"49242","295.41600","24.61828","0.34194"
"49308","295.81200","24.65122","0.34500"
"49374","296.20800","24.68423","0.34884"
"49440","296.60400","24.71723","0.35197"
"49506","297.00000","24.75023","0.35464"
"49572","297.39600","24.78318","0.27135"
"49638","297.79200","24.81618","0.25876"
"49704","298.18800","24.84931","0.25809"
"49770","298.58400","24.88225","0.26065"
"49836","298.98000","24.91513","0.26507"
"49902","299.37600","24.94820","0.26738"
"49968","299.77200","24.98132","0.27210"
"50034","300.16800","25.01421","0.27391"
"50100","300.56400","25.04721","0.27766"
"50166","300.96000","25.08022","0.28040"
"50232","301.35600","25.11322","0.28546"
"50298","301.75200","25.14622","0.29062"
"50364","302.14800","25.17916","0.29683"
"50430","302.54400","25.21229","0.30202"
"50496","302.94000","25.24517","0.30530"
"50562","303.33600","25.27824","0.30794"
"50628","303.73200","25.31124","0.31072"
"50694","304.12800","25.34425","0.31364"
"50760","304.52400","25.37725","0.31643"
"50826","304.92000","25.41019","0.32038"
"50892","305.31600","25.44320","0.32357"
"50958","305.71200","25.47626","0.32550"
"51024","306.10800","25.50920","0.32877"
"51090","306.50400","25.54221","0.33123"
"51156","306.90000","25.57527","0.33355"
"51222","307.29600","25.60822","0.33649"
"51288","307.69200","25.64122","0.34118"
"51354","308.08800","25.67422","0.34641"
"51420","308.48400","25.70729","0.35033"
"51486","308.88000","25.74023","0.35463"
"51552","309.27600","25.77324","0.35846"
"51618","309.67200","25.80624","0.36301"
"51684","310.06800","25.83930","0.36871"
"51750","310.46400","25.87225","0.37380"
"51816","310.86000","25.90519","0.37841"
"51882","311.25600","25.93819","0.38184"
"51948","311.65200","25.97126","0.38425"
"52014","312.04800","26.00420","0.38766"
"52080","312.44400","26.03715","0.39108"
"52146","312.84000","26.07021","0.39618"
"52212","313.23600","26.10328","0.40044"
"52278","313.63200","26.13622","0.20219"
"52344","314.02800","26.16916","0.20699"
"52410","314.42400","26.20216","0.20917"
"52476","314.82000","26.23523","0.21380"
"52542","315.21600","26.26823","0.21542"
"52608","315.61200","26.30118","0.22058"
"52674","316.00800","26.33424","0.22632"
"52740","316.40400","26.36731","0.23026"
"52806","316.80000","26.40019","0.23677"
"52872","317.19600","26.43319","0.24133"
"52938","317.59200","26.46625","0.24936"
"53004","317.98800","26.49920","0.25471"
"53070","318.38400","26.53214","0.26313"
"53136","318.78000","26.56521","0.26910"
"53202","319.17600","26.59827","0.27404"
"53268","319.57200","26.63127","0.27619"
"53334","319.96800","26.66416","0.28093"
"53400","320.36400","26.69722","0.28478"
"53466","320.76000","26.73023","0.29213"
"53532","321.15600","26.76323","0.29855"
"53598","321.55200","26.79623","0.30469"
"53664","321.94800","26.82918","0.30950"
"53730","322.34400","26.86224","0.31392"
"53796","322.74000","26.89524","0.31824"
"53862","323.13600","26.92825","0.32155"
"53928","323.53200","26.96125","0.32441"
"53994","323.92800","26.99426","0.32713"
"54060","324.32400","27.02726","0.33023"
"54126","324.72000","27.06020","0.33466"
"54192","325.11600","27.09327","0.34048"
"54258","325.51200","27.12627","0.34819"
"54324","325.90800","27.15922","0.35246"
"54390","326.30400","27.19222","0.35681"
"54456","326.70000","27.22528","0.36244"
"54522","327.09600","27.25823","0.37040"
"54588","327.49200","27.29117","0.37832"
"54654","327.88800","27.32430","0.38189"
"54720","328.28400","27.35724","0.38464"
"54786","328.68000","27.39018","0.38886"
"54852","329.07600","27.42319","0.39611"
"54918","329.47200","27.45619","0.40272"
"54984","329.86800","27.48925","0.40606"
"55050","330.26400","27.52220","0.40948"
"55116","330.66000","27.55520","0.41314"
"55182","331.05600","27.58827","0.41700"
"55248","331.45200","27.62127","0.42116"
"55314","331.84800","27.65421","0.42530"
"55380","332.24400","27.68716","0.43061"
"55446","332.64000","27.72022","0.43701"
"55512","333.03600","27.75328","0.44097"
"55578","333.43200","27.78617","0.44641"
"55644","333.82800","27.81923","0.45267"
"55710","334.22400","27.85224","0.45722"
"55776","334.62000","27.88524","0.46053"
"55842","335.01600","27.91818","0.46578"
"55908","335.41200","27.95119","0.47356"
"55974","335.80800","27.98425","0.47899"
"56040","336.20400","28.01726","0.48345"
"56106","336.60000","28.05020","0.48723"
"56172","336.99600","28.08320","0.49300"
"56238","337.39200","28.11627","0.49873"
"56304","337.78800","28.14921","0.50594"
"56370","338.18400","28.18221","0.51202"
"56436","338.58000","28.21522","0.51715"
"56502","338.97600","28.24822","0.52152"
"56568","339.37200","28.28123","0.52440"
"56634","339.76800","28.31423","0.52790"
"56700","340.16400","28.34718","0.53272"
"56766","340.56000","28.38024","0.53754"
"56832","340.95600","28.41318","0.54228"
"56898","341.35200","28.44625","0.54760"
"56964","341.74800","28.47925","0.55294"
"57030","342.14400","28.51220","0.55929"
"57096","342.54000","28.54520","0.56416"
"57162","342.93600","28.57826","0.57066"
"57228","343.33200","28.61121","0.57859"
"57294","343.72800","28.64421","0.58460"
"57360","344.12400","28.67721","0.59050"
"57426","344.52000","28.71028","0.59606"
"57492","344.91600","28.74322","0.60312"
"57558","345.31200","28.77622","0.60797"
"57624","345.70800","28.80917","0.61132"
"57690","346.10400","28.84229","0.61545"
"57756","346.50000","28.87524","0.62091"
"57822","346.89600","28.90818","0.62577"
"57888","347.29200","28.94124","0.63023"
"57954","347.68800","28.97425","0.63443"
"58020","348.08400","29.00725","0.63996"
"58086","348.48000","29.04020","0.64528"
"58152","348.87600","29.07320","0.65224"
"58218","349.27200","29.10626","0.65925"
"58284","349.66800","29.13927","0.66467"
"58350","350.06400","29.17221","0.66996"
"58416","350.46000","29.20521","0.67637"
"58482","350.85600","29.23828","0.68505"
"58548","351.25200","29.27122","0.69151"
"58614","351.64800","29.30417","0.69593"
"58680","352.04400","29.33723","0.70243"
"58746","352.44000","29.37029","0.70986"
"58812","352.83600","29.40318","0.71638"
"58878","353.23200","29.43618","0.72071"
"58944","353.62800","29.46924","0.72440"
"59010","354.02400","29.50219","0.72812"
"59076","354.42000","29.53519","0.73224"
"59142","354.81600","29.56825","0.73645"
"59208","355.21200","29.60120","0.74228"
"59274","355.60800","29.63427","0.74682"
"59340","356.00400","29.66727","0.75263"
"59406","356.40000","29.70021","0.75956"
"59472","356.79600","29.73322","0.76536"
"59538","357.19200","29.76622","0.77234"
"59604","357.58800","29.79922","0.78197"
"59670","357.98400","29.83229","0.79024"
"59736","358.38000","29.86523","0.79614"
"59802","358.77600","29.89823","0.80130"
"59868","359.17200","29.93124","0.80960"
"59934","359.56800","29.96430","0.81719"
"60000","359.96400","29.99725","0.82427"
"60066","360.36000","30.03013","0.82983"
"60132","360.75600","30.06325","0.83473"
"60198","361.15200","30.09626","0.83848"
"60264","361.54800","30.12920","0.84262"
"60330","361.94400","30.16221","0.84727"
"60396","362.34000","30.19521","0.85204"
"60462","362.73600","30.22827","0.85760"
"60528","363.13200","30.26122","0.86390"
"60594","363.52800","30.29416","0.86887"
"60660","363.92400","30.32722","0.87367"
"60726","364.32000","30.36029","0.88155"
"60792","364.71600","30.39317","0.87790"
"60858","365.11200","30.42618","0.88431"
"60924","365.50800","30.45924","0.89165"
"60990","365.90400","30.49224","0.89761"
"61056","366.30000","30.52519","0.61461"
"61122","366.69600","30.55819","0.60877"
"61188","367.09200","30.59126","0.61169"
"61254","367.48800","30.62426","0.61330"
"61320","367.88400","30.65720","0.61490"
"61386","368.28000","30.69021","0.61599"
"61452","368.67600","30.72327","0.61973"
"61518","369.07200","30.75628","0.62346"
"61584","369.46800","30.78922","0.62884"
"61650","369.86400","30.82222","0.63355"
"61716","370.26000","30.85523","0.63777"
"61782","370.65600","30.88823","0.64669"
"61848","371.05200","30.92123","0.65611"
"61914","371.44800","30.95418","0.66355"
"61980","371.84400","30.98724","0.66850"
"62046","372.24000","31.02025","0.58103"
"62112","372.63600","31.05325","0.44726"
"62178","373.03200","31.08619","0.45861"
"62244","373.42800","31.11926","0.45762"
"62310","373.82400","31.15220","0.46351"
"62376","374.22000","31.18526","0.48176"
"62442","374.61600","31.21827","0.48677"
"62508","375.01200","31.25127","0.48752"
"62574","375.40800","31.28415","0.49801"
"62640","375.80400","31.31728","0.51435"
"62706","376.20000","31.35022","0.51369"
"62772","376.59600","31.38323","0.52042"
"62838","376.99200","31.41617","0.52779"
"62904","377.38800","31.44923","0.52769"
"62970","377.78400","31.48230","0.53241"
"63036","378.18000","31.51518","0.54238"
"63102","378.57600","31.54819","0.54291"
"63168","378.97200","31.58125","0.55118"
"63234","379.36800","31.61425","0.56145"
"63300","379.76400","31.64714","0.56272"
"63366","380.16000","31.68026","0.57132"
"63432","380.55600","31.71327","0.57833"
"63498","380.95200","31.74627","0.58137"
"63564","381.34800","31.77915","0.58978"
"63630","381.74400","31.81222","0.59312"
"63696","382.14000","31.84528","0.60028"
"63762","382.53600","31.87823","0.60725"
"63828","382.93200","31.91117","0.60985"
"63894","383.32800","31.94423","0.61683"
"63960","383.72400","31.97729","0.62053"
"64026","384.12000","32.01024","0.62630"
"64092","384.51600","32.04318","0.63114"
"64158","384.91200","32.07625","0.63383"
"64224","385.30800","32.10925","0.64074"
"64290","385.70400","32.14225","0.64511"
"64356","386.10000","32.17520","0.65474"
"64422","386.49600","32.20826","0.66023"
"64488","386.89200","32.24126","0.66741"
"64554","387.28800","32.27427","0.67423"
"64620","387.68400","32.30722","0.68291"
"64686","388.08000","32.34028","0.69024"
"64752","388.47600","32.37322","0.69501"
"64818","388.87200","32.40623","0.70212"
"64884","389.26800","32.43923","0.70908"
"64950","389.66400","32.47223","0.71648"
"65016","390.06000","32.50524","0.71992"
"65082","390.45600","32.53818","0.72472"
"65148","390.85200","32.57124","0.72768"
"65214","391.24800","32.60419","0.73130"
"65280","391.64400","32.63720","0.73569"
"65346","392.04000","32.67020","0.74149"
"65412","392.43600","32.70326","0.74571"
"65478","392.83200","32.73621","0.75311"
"65544","393.22800","32.76921","0.75981"
"65610","393.62400","32.80221","0.76543"
"65676","394.02000","32.83527","0.77343"
"65742","394.41600","32.86828","0.78198"
"65808","394.81200","32.90117","0.79110"
"65874","395.20800","32.93423","0.79711"
"65940","395.60400","32.96729","0.80406"
"66006","396.00000","33.00023","0.81187"
"66072","396.39600","33.03318","0.82060"
"66138","396.79200","33.06618","0.82713"
"66204","397.18800","33.09930","0.83256"
"66270","397.58400","33.13225","0.83683"
"66336","397.98000","33.16520","0.84072"
"66402","398.37600","33.19826","0.84529"
"66468","398.77200","33.23126","0.85054"
"66534","399.16800","33.26421","0.85710"
"66600","399.56400","33.29721","0.86421"
"66666","399.96000","33.33021","0.86935"
"66732","400.35600","33.36327","0.87511"
"66798","400.75200","33.39622","0.88463"
"66864","401.14800","33.42916","0.89291"
"66930","401.54400","33.46223","0.89873"
"66996","401.94000","33.49529","0.90543"
"67062","402.33600","33.52818","0.91173"
"67128","402.73200","33.56118","0.91819"
"67194","403.12800","33.59430","0.92479"
"67260","403.52400","33.62725","0.93203"
"67326","403.92000","33.66019","0.93536"
"67392","404.31600","33.69320","0.93906"
"67458","404.71200","33.72620","0.52990"
"67524","405.10800","33.75920","0.52095"
"67590","405.50400","33.79221","0.53853"
"67656","405.90000","33.82527","0.55830"
"67722","406.29600","33.85822","0.54447"
"67788","406.69200","33.89122","0.56339"
"67854","407.08800","33.92422","0.57358"
"67920","407.48400","33.95723","0.58661"
"67986","407.88000","33.99023","0.59674"
"68052","408.27600","34.02323","0.54577"
"68118","408.67200","34.05624","0.54934"
"68184","409.06800","34.08924","0.56231"
"68250","409.46400","34.12224","0.55993"
"68316","409.86000","34.15519","0.56713"
"68382","410.25600","34.18825","0.57805"
"68448","410.65200","34.22126","0.58040"
"68514","411.04800","34.25426","0.59619"
"68580","411.44400","34.28720","0.59785"
"68646","411.84000","34.32027","0.60265"
"68712","412.23600","34.35327","0.61082"
"68778","412.63200","34.38615","0.61090"
"68844","413.02800","34.41916","0.62233"
"68910","413.42400","34.45222","0.62548"
"68976","413.82000","34.48523","0.63084"
"69042","414.21600","34.51817","0.63626"
"69108","414.61200","34.55123","0.63889"
"69174","415.00800","34.58424","0.64870"
"69240","415.40400","34.61724","0.65097"
"69306","415.80000","34.65019","0.66157"
"69372","416.19600","34.68319","0.66395"
"69438","416.59200","34.71625","0.67137"
"69504","416.98800","34.74926","0.67625"
"69570","417.38400","34.78220","0.68720"
"69636","417.78000","34.81515","0.69207"
"69702","418.17600","34.84821","0.69620"
"69768","418.57200","34.88121","0.70288"
"69834","418.96800","34.91416","0.70983"
"69900","419.36400","34.94722","0.71671"
"69966","419.76000","34.98022","0.72053"
"70032","420.15600","35.01329","0.72481"
"70098","420.55200","35.04623","0.72807"
"70164","420.94800","35.07924","0.73224"
"70230","421.34400","35.11224","0.73641"
"70296","421.74000","35.14524","0.74154"
"70362","422.13600","35.17825","0.74567"
"70428","422.53200","35.21125","0.75118"
"70494","422.92800","35.24426","0.75823"
"70560","423.32400","35.27720","0.76383"
"70626","423.72000","35.31020","0.77048"
"70692","424.11600","35.34321","0.77610"
"70758","424.51200","35.37621","0.78776"
"70824","424.90800","35.40921","0.79241"
"70890","425.30400","35.44228","0.79836"
"70956","425.70000","35.47516","0.80319"
"71022","426.09600","35.50823","0.81197"
"71088","426.49200","35.54117","0.81894"
"71154","426.88800","35.57423","0.82561"
"71220","427.28400","35.60724","0.83138"
"71286","427.68000","35.64024","0.83495"
"71352","428.07600","35.67319","0.83860"
"71418","428.47200","35.70631","0.84228"
"71484","428.86800","35.73925","0.84735"
"71550","429.26400","35.77214","0.85118"
"71616","429.66000","35.80520","0.85618"
"71682","430.05600","35.83826","0.86291"
"71748","430.45200","35.87121","0.86733"
"71814","430.84800","35.90416","0.87127"
"71880","431.24400","35.93722","0.87580"
"71946","431.64000","35.97028","0.88168"
"72012","432.03600","36.00322","0.88928"
"72078","432.43200","36.03611","0.89448"
"72144","432.82800","36.06923","0.89920"
"72210","433.22400","36.10223","0.90616"
"72276","433.62000","36.13524","0.91224"
"72342","434.01600","36.16824","0.91737"
"72408","434.41200","36.20124","0.91909"
"72474","434.80800","36.23425","0.92461"
"72540","435.20400","36.26725","0.93114"
"72606","435.60000","36.30020","0.93608"
"72672","435.99600","36.33320","0.93937"
"72738","436.39200","36.36626","0.94293"
"72804","436.78800","36.39921","0.94793"
"72870","437.18400","36.43221","0.95432"
"72936","437.58000","36.46527","0.96274"
"73002","437.97600","36.49828","0.97027"
"73068","438.37200","36.53122","0.97574"
"73134","438.76800","36.56417","0.98014"
"73200","439.16400","36.59729","0.98562"
"73266","439.56000","36.63023","0.37444"
"73332","439.95600","36.66318","0.37910"
"73398","440.35200","36.69624","0.15953"
"73464","440.74800","36.72919","0.15341"
"73530","441.14400","36.76219","0.16644"
"73596","441.54000","36.79520","0.18093"
"73662","441.93600","36.82820","0.19141"
"73728","442.33200","36.86126","0.19228"
"73794","442.72800","36.89421","0.18340"
"73860","443.12400","36.92721","0.17920"
"73926","443.52000","36.96021","0.18112"
"73992","443.91600","36.99322","0.18635"
"74058","444.31200","37.02617","0.19231"
"74124","444.70800","37.05923","0.20057"
"74190","445.10400","37.09229","0.20929"
"74256","445.50000","37.12523","0.21400"
"74322","445.89600","37.15818","0.21558"
"74388","446.29200","37.19124","0.21637"
"74454","446.68800","37.22430","0.21538"
"74520","447.08400","37.25725","0.21482"
"74586","447.48000","37.29019","0.21645"
"74652","447.87600","37.32326","0.21921"
"74718","448.27200","37.35626","0.22130"
"74784","448.66800","37.38920","0.22328"
"74850","449.06400","37.42215","0.03044"
"74916","449.46000","37.45521","0.03684"
"74982","449.85600","37.48828","0.05112"
"75048","450.25200","37.52122","0.03962"
"75114","450.64800","37.55422","0.02760"
"75180","451.04400","37.58729","0.03268"
"75246","451.44000","37.62023","0.04459"
"75312","451.83600","37.65318","0.02793"
"75378","452.23200","37.68618","0.03229"
"75444","452.62800","37.71924","0.03105"
"75510","453.02400","37.75225","0.03458"
"75576","453.42000","37.78519","0.02868"
"75642","453.81600","37.81819","0.03221"
"75708","454.21200","37.85126","0.03142"
"75774","454.60800","37.88426","0.03409"
"75840","455.00400","37.91715","0.03240"
"75906","455.40000","37.95027","0.03229"
"75972","455.79600","37.98328","0.03596"
"76038","456.19200","38.01622","0.03731"
"76104","456.58800","38.04922","0.04210"
"76170","456.98400","38.08229","0.04064"
"76236","457.38000","38.11523","0.04436"
"76302","457.77600","38.14817","0.04050"
"76368","458.17200","38.18124","0.04581"
"76434","458.56800","38.21424","0.04430"
"76500","458.96400","38.24725","0.04526"
"76566","459.36000","38.28019","0.04456"
"76632","459.75600","38.31325","0.04392"
"76698","460.15200","38.34626","0.04409"
"76764","460.54800","38.37926","0.04434"
"76830","460.94400","38.41220","0.04781"
"76896","461.34000","38.44527","0.04728"
"76962","461.73600","38.47827","0.04975"
"77028","462.13200","38.51122","0.04637"
"77094","462.52800","38.54416","0.05092"
"77160","462.92400","38.57722","0.05128"
"77226","463.32000","38.61023","0.05102"
"77292","463.71600","38.64317","0.05298"
"77358","464.11200","38.67618","0.05246"
"77424","464.50800","38.70924","0.05754"
"77490","464.90400","38.74230","0.05365"
"77556","465.30000","38.77519","0.05717"
"77622","465.69600","38.80819","0.05824"
"77688","466.09200","38.84126","0.06300"
"77754","466.48800","38.87426","0.06949"
"77820","466.88400","38.90714","0.06483"
"77886","467.28000","38.94020","0.05755"
"77952","467.67600","38.97321","0.06264"
"78018","468.07200","39.00621","0.05730"
"78084","468.46800","39.03922","0.05953"
"78150","468.86400","39.07215","0.06727"
"78216","469.26000","39.10522","0.06310"
"78282","469.65600","39.13823","0.06941"
"78348","470.05200","39.17117","0.06675"
"78414","470.44800","39.20429","0.06730"
"78480","470.84400","39.23724","0.07248"
"78546","471.24000","39.27024","0.06934"
"78612","471.63600","39.30319","0.07207"
"78678","472.03200","39.33625","0.07186"
"78744","472.42800","39.36932","0.07109"
"78810","472.82400","39.40225","0.07740"
"78876","473.22000","39.43520","0.07299"
"78942","473.61600","39.46821","0.07422"
"79008","474.01200","39.50121","0.08025"
"79074","474.40800","39.53421","0.07550"
"79140","474.80400","39.56722","0.08054"
"79206","475.20000","39.60022","0.08113"
"79272","475.59600","39.63322","0.07886"
"79338","475.99200","39.66623","0.08647"
"79404","476.38800","39.69923","0.08365"
"79470","476.78400","39.73223","0.08315"
"79536","477.18000","39.76518","0.09054"
"79602","477.57600","39.79818","0.08631"
"79668","477.97200","39.83125","0.08739"
"79734","478.36800","39.86419","0.09275"
"79800","478.76400","39.89719","0.08993"
"79866","479.16000","39.93020","0.09136"
"79932","479.55600","39.96326","0.09477"
"79998","479.95200","39.99627","0.09246"
"80064","480.34800","40.02915","0.09443"
"80130","480.74400","40.06221","0.09643"
"80196","481.14000","40.09528","0.09472"
"80262","481.53600","40.12822","0.09625"
"80328","481.93200","40.16117","0.09807"
"80394","482.32800","40.19423","0.09640"
"80460","482.72400","40.22729","0.09791"
"80526","483.12000","40.26024","-0.00319"
"80592","483.51600","40.29324","0.00285"
"80658","483.91200","40.32624","0.00106"
"80724","484.30800","40.35925","0.00167"
"80790","484.70400","40.39225","0.00146"
"80856","485.10000","40.42520","0.00089"
"80922","485.49600","40.45826","0.00129"
"80988","485.89200","40.49126","0.00081"
"81054","486.28800","40.52427","0.00138"
"81120","486.68400","40.55715","0.00121"
"81186","487.08000","40.59028","0.00120"
"81252","487.47600","40.62328","0.00158"
"81285","487.67000","40.63942","0.00124"