File: Trajectories_together/161221_2Specimen_RawData_2.csv
"","V1","V2","V3"
"1","End date","12/21/2016",""
"2","Specimen label","24T_90",""
"3","Maximum Load","1.06486","N"
"4","Time","Extension","Load"
"5","(s)","(mm)","(N)"
"6","0.00000","0.00000","0.00011"
"75","0.41400","0.03468","0.00051"
"144","0.82800","0.06918","0.00053"
"213","1.24200","0.10362","0.00122"
"282","1.65600","0.13811","0.00096"
"351","2.07000","0.17267","0.00157"
"420","2.48400","0.20717","0.00157"
"489","2.89800","0.24167","0.00102"
"558","3.31200","0.27617","0.00087"
"627","3.72600","0.31073","0.00137"
"696","4.14000","0.34516","0.00129"
"765","4.55400","0.37966","0.00190"
"834","4.96800","0.41416","0.00178"
"903","5.38200","0.44866","0.00178"
"972","5.79600","0.48310","0.00165"
"1041","6.21000","0.51766","0.00177"
"1110","6.62400","0.55216","0.00214"
"1179","7.03800","0.58665","0.00189"
"1248","7.45200","0.62115","0.00192"
"1317","7.86600","0.65559","0.00207"
"1386","8.28000","0.69003","0.00225"
"1455","8.69400","0.72465","0.00192"
"1524","9.10800","0.75921","0.00188"
"1593","9.52200","0.79365","0.00192"
"1662","9.93600","0.82814","0.00209"
"1731","10.35000","0.86264","0.00171"
"1800","10.76400","0.89720","0.00189"
"1869","11.17800","0.93170","0.00241"
"1938","11.59200","0.96608","0.00217"
"2007","12.00600","1.00058","0.00178"
"2076","12.42000","1.03520","0.00205"
"2145","12.83400","1.06963","0.00180"
"2214","13.24800","1.10413","0.00186"
"2283","13.66200","1.13863","0.00200"
"2352","14.07600","1.17319","0.00212"
"2421","14.49000","1.20769","0.00226"
"2490","14.90400","1.24219","0.00239"
"2559","15.31800","1.27663","0.00207"
"2628","15.73200","1.31112","0.00213"
"2697","16.14600","1.34562","0.00205"
"2766","16.56000","1.38018","0.00275"
"2835","16.97400","1.41462","0.00240"
"2904","17.38800","1.44912","0.00240"
"2973","17.80200","1.48368","0.00245"
"3042","18.21600","1.51812","0.00206"
"3111","18.63000","1.55267","0.00231"
"3180","19.04400","1.58705","0.00239"
"3249","19.45800","1.62161","0.00218"
"3318","19.87200","1.65617","0.00234"
"3387","20.28600","1.69067","0.00234"
"3456","20.70000","1.72511","0.00253"
"3525","21.11400","1.75961","0.00234"
"3594","21.52800","1.79416","0.00211"
"3663","21.94200","1.82866","0.00215"
"3732","22.35600","1.86310","0.00217"
"3801","22.77000","1.89754","0.00230"
"3870","23.18400","1.93210","0.00204"
"3939","23.59800","1.96666","0.00173"
"4008","24.01200","2.00116","0.00223"
"4077","24.42600","2.03559","0.00197"
"4146","24.84000","2.07015","0.00237"
"4215","25.25400","2.10465","0.00252"
"4284","25.66800","2.13915","0.00218"
"4353","26.08200","2.17365","0.00214"
"4422","26.49600","2.20809","0.00222"
"4491","26.91000","2.24265","0.00219"
"4560","27.32400","2.27714","0.00245"
"4629","27.73800","2.31164","0.00250"
"4698","28.15200","2.34608","0.00237"
"4767","28.56600","2.38064","0.00250"
"4836","28.98000","2.41514","0.00218"
"4905","29.39400","2.44964","0.00250"
"4974","29.80800","2.48402","0.00258"
"5043","30.22200","2.51863","0.00263"
"5112","30.63600","2.55319","0.00252"
"5181","31.05000","2.58763","0.00272"
"5250","31.46400","2.62213","0.00227"
"5319","31.87800","2.65663","0.00220"
"5388","32.29200","2.69119","0.00212"
"5457","32.70600","2.72569","0.00255"
"5526","33.12000","2.76018","0.00177"
"5595","33.53400","2.79462","0.00244"
"5664","33.94800","2.82912","0.00228"
"5733","34.36200","2.86368","0.00200"
"5802","34.77600","2.89812","0.00232"
"5871","35.19000","2.93262","0.00238"
"5940","35.60400","2.96712","0.00230"
"6009","36.01800","3.00167","0.00246"
"6078","36.43200","3.03617","0.00249"
"6147","36.84600","3.07061","0.00242"
"6216","37.26000","3.10511","0.00248"
"6285","37.67400","3.13967","0.00235"
"6354","38.08800","3.17417","0.00204"
"6423","38.50200","3.20861","0.00241"
"6492","38.91600","3.24316","0.00274"
"6561","39.33000","3.27766","0.00211"
"6630","39.74400","3.31216","0.00264"
"6699","40.15800","3.34666","0.00254"
"6768","40.57200","3.38110","0.00220"
"6837","40.98600","3.41566","0.00208"
"6906","41.40000","3.45016","0.00256"
"6975","41.81400","3.48465","0.00227"
"7044","42.22800","3.51915","0.00257"
"7113","42.64200","3.55365","0.00252"
"7182","43.05600","3.58821","0.00198"
"7251","43.47000","3.62265","0.00224"
"7320","43.88400","3.65715","0.00258"
"7389","44.29800","3.69159","0.00232"
"7458","44.71200","3.72614","0.00213"
"7527","45.12600","3.76064","0.00237"
"7596","45.54000","3.79520","0.00250"
"7665","45.95400","3.82964","0.00239"
"7734","46.36800","3.86414","0.00232"
"7803","46.78200","3.89870","0.00243"
"7872","47.19600","3.93314","0.00251"
"7941","47.61000","3.96757","0.00230"
"8010","48.02400","4.00207","0.00200"
"8079","48.43800","4.03663","0.00242"
"8148","48.85200","4.07113","0.00247"
"8217","49.26600","4.10563","0.00227"
"8286","49.68000","4.14013","0.00191"
"8355","50.09400","4.17462","0.00210"
"8424","50.50800","4.20912","0.00230"
"8493","50.92200","4.24362","0.00256"
"8562","51.33600","4.27806","0.00224"
"8631","51.75000","4.31262","0.00259"
"8700","52.16400","4.34718","0.00227"
"8769","52.57800","4.38168","0.00194"
"8838","52.99200","4.41611","0.00230"
"8907","53.40600","4.45061","0.00229"
"8976","53.82000","4.48517","0.00261"
"9045","54.23400","4.51967","0.00274"
"9114","54.64800","4.55411","0.00218"
"9183","55.06200","4.58855","0.00232"
"9252","55.47600","4.62311","0.00227"
"9321","55.89000","4.65766","0.00204"
"9390","56.30400","4.69216","0.00230"
"9459","56.71800","4.72660","0.00222"
"9528","57.13200","4.76116","0.00263"
"9597","57.54600","4.79566","0.00231"
"9666","57.96000","4.83016","0.00210"
"9735","58.37400","4.86466","0.00251"
"9804","58.78800","4.89909","0.00246"
"9873","59.20200","4.93359","0.00256"
"9942","59.61600","4.96815","0.00212"
"10011","60.03000","5.00265","0.00232"
"10080","60.44400","5.03709","0.00210"
"10149","60.85800","5.07165","0.00263"
"10218","61.27200","5.10615","0.00202"
"10287","61.68600","5.14064","0.00220"
"10356","62.10000","5.17508","0.00197"
"10425","62.51400","5.20958","0.00197"
"10494","62.92800","5.24414","0.00237"
"10563","63.34200","5.27870","0.00257"
"10632","63.75600","5.31314","0.00234"
"10701","64.17000","5.34758","0.00246"
"10770","64.58400","5.38219","0.00247"
"10839","64.99800","5.41669","0.00194"
"10908","65.41200","5.45107","0.00260"
"10977","65.82600","5.48557","0.00220"
"11046","66.24000","5.52013","0.00227"
"11115","66.65400","5.55463","0.00218"
"11184","67.06800","5.58919","0.00201"
"11253","67.48200","5.62362","0.00272"
"11322","67.89600","5.65812","0.00234"
"11391","68.31000","5.69262","0.00261"
"11460","68.72400","5.72712","0.00227"
"11529","69.13800","5.76162","0.00213"
"11598","69.55200","5.79612","0.00257"
"11667","69.96600","5.83068","0.00227"
"11736","70.38000","5.86511","0.00222"
"11805","70.79400","5.89967","0.00259"
"11874","71.20800","5.93411","0.00241"
"11943","71.62200","5.96867","0.00239"
"12012","72.03600","6.00317","0.00229"
"12081","72.45000","6.03761","0.00227"
"12150","72.86400","6.07205","0.00216"
"12219","73.27800","6.10666","0.00232"
"12288","73.69200","6.14116","0.00224"
"12357","74.10600","6.17560","0.00181"
"12426","74.52000","6.21010","0.00203"
"12495","74.93400","6.24466","0.00227"
"12564","75.34800","6.27916","0.00255"
"12633","75.76200","6.31365","0.00233"
"12702","76.17600","6.34815","0.00211"
"12771","76.59000","6.38259","0.00214"
"12840","77.00400","6.41715","0.00176"
"12909","77.41800","6.45171","0.00218"
"12978","77.83200","6.48615","0.00250"
"13047","78.24600","6.52059","0.00236"
"13116","78.66000","6.55514","0.00250"
"13185","79.07400","6.58964","0.00239"
"13254","79.48800","6.62420","0.00220"
"13323","79.90200","6.65858","0.00216"
"13392","80.31600","6.69308","0.00186"
"13461","80.73000","6.72764","0.00205"
"13530","81.14400","6.76220","0.00238"
"13599","81.55800","6.79663","0.00226"
"13668","81.97200","6.83113","0.00214"
"13737","82.38600","6.86563","0.00221"
"13806","82.80000","6.90019","0.00229"
"13875","83.21400","6.93469","0.00236"
"13944","83.62800","6.96907","0.00245"
"14013","84.04200","7.00357","0.00175"
"14082","84.45600","7.03813","0.00250"
"14151","84.87000","7.07268","0.00232"
"14220","85.28400","7.10712","0.00198"
"14289","85.69800","7.14162","0.00227"
"14358","86.11200","7.17618","0.00225"
"14427","86.52600","7.21068","0.00236"
"14496","86.94000","7.24512","0.00260"
"14565","87.35400","7.27955","0.00228"
"14634","87.76800","7.31411","0.00226"
"14703","88.18200","7.34867","0.00241"
"14772","88.59600","7.38317","0.00230"
"14841","89.01000","7.41761","0.00207"
"14910","89.42400","7.45217","0.00233"
"14979","89.83800","7.48667","0.00259"
"15048","90.25200","7.52116","0.00234"
"15117","90.66600","7.55560","0.00233"
"15186","91.08000","7.59010","0.00198"
"15255","91.49400","7.62460","0.00242"
"15324","91.90800","7.65910","0.00230"
"15393","92.32200","7.69360","0.00248"
"15462","92.73600","7.72810","0.00254"
"15531","93.15000","7.76271","0.00238"
"15600","93.56400","7.79715","0.00252"
"15669","93.97800","7.83165","0.00255"
"15738","94.39200","7.86609","0.00251"
"15807","94.80600","7.90059","0.00245"
"15876","95.22000","7.93515","0.00253"
"15945","95.63400","7.96965","0.00289"
"16014","96.04800","8.00414","0.00230"
"16083","96.46200","8.03864","0.00239"
"16152","96.87600","8.07320","0.00252"
"16221","97.29000","8.10770","0.00243"
"16290","97.70400","8.14214","0.00243"
"16359","98.11800","8.17658","0.00247"
"16428","98.53200","8.21114","0.00263"
"16497","98.94600","8.24563","0.00239"
"16566","99.36000","8.28013","0.00244"
"16635","99.77400","8.31463","0.00210"
"16704","100.18800","8.34913","0.00250"
"16773","100.60200","8.38363","0.00228"
"16842","101.01600","8.41819","0.00216"
"16911","101.43000","8.45263","0.00273"
"16980","101.84400","8.48712","0.00246"
"17049","102.25800","8.52162","0.00213"
"17118","102.67200","8.55612","0.00279"
"17187","103.08600","8.59062","0.00226"
"17256","103.50000","8.62512","0.00245"
"17325","103.91400","8.65968","0.00238"
"17394","104.32800","8.69418","0.00255"
"17463","104.74200","8.72867","0.00234"
"17532","105.15600","8.76311","0.00283"
"17601","105.57000","8.79767","0.00248"
"17670","105.98400","8.83217","0.00272"
"17739","106.39800","8.86667","0.00225"
"17808","106.81200","8.90111","0.00301"
"17877","107.22600","8.93561","0.00264"
"17946","107.64000","8.97016","0.00271"
"18015","108.05400","9.00466","0.00256"
"18084","108.46800","9.03910","0.00259"
"18153","108.88200","9.07354","0.00267"
"18222","109.29600","9.10810","0.00251"
"18291","109.71000","9.14266","0.00266"
"18360","110.12400","9.17715","0.00294"
"18429","110.53800","9.21159","0.00283"
"18498","110.95200","9.24615","0.00260"
"18567","111.36600","9.28065","0.00287"
"18636","111.78000","9.31515","0.00269"
"18705","112.19400","9.34965","0.00266"
"18774","112.60800","9.38409","0.00312"
"18843","113.02200","9.41864","0.00299"
"18912","113.43600","9.45314","0.00290"
"18981","113.85000","9.48764","0.00260"
"19050","114.26400","9.52208","0.00277"
"19119","114.67800","9.55664","0.00291"
"19188","115.09200","9.59120","0.00300"
"19257","115.50600","9.62564","0.00308"
"19326","115.92000","9.66008","0.00287"
"19395","116.33400","9.69463","0.00299"
"19464","116.74800","9.72913","0.00309"
"19533","117.16200","9.76363","0.00292"
"19602","117.57600","9.79813","0.00291"
"19671","117.99000","9.83263","0.00290"
"19740","118.40400","9.86713","0.00309"
"19809","118.81800","9.90168","0.00297"
"19878","119.23200","9.93612","0.00297"
"19947","119.64600","9.97056","0.00329"
"20016","120.06000","10.00506","0.00330"
"20085","120.47400","10.03968","0.00333"
"20154","120.88800","10.07418","0.00334"
"20223","121.30200","10.10862","0.00320"
"20292","121.71600","10.14311","0.00350"
"20361","122.13000","10.17767","0.00312"
"20430","122.54400","10.21217","0.00300"
"20499","122.95800","10.24661","0.00318"
"20568","123.37200","10.28111","0.00316"
"20637","123.78600","10.31561","0.00309"
"20706","124.20000","10.35011","0.00326"
"20775","124.61400","10.38466","0.00330"
"20844","125.02800","10.41910","0.00356"
"20913","125.44200","10.45366","0.00356"
"20982","125.85600","10.48816","0.00323"
"21051","126.27000","10.52266","0.00361"
"21120","126.68400","10.55710","0.00344"
"21189","127.09800","10.59160","0.00378"
"21258","127.51200","10.62615","0.00353"
"21327","127.92600","10.66065","0.00368"
"21396","128.34000","10.69509","0.00365"
"21465","128.75400","10.72959","0.00389"
"21534","129.16800","10.76421","0.00384"
"21603","129.58200","10.79865","0.00421"
"21672","129.99600","10.83315","0.00403"
"21741","130.41000","10.86758","0.00409"
"21810","130.82400","10.90208","0.00429"
"21879","131.23800","10.93664","0.00421"
"21948","131.65200","10.97120","0.00447"
"22017","132.06600","11.00564","0.00480"
"22086","132.48000","11.04014","0.00484"
"22155","132.89400","11.07470","0.00477"
"22224","133.30800","11.10919","0.00519"
"22293","133.72200","11.14363","0.00508"
"22362","134.13600","11.17813","0.00544"
"22431","134.55000","11.21263","0.00511"
"22500","134.96400","11.24707","0.00502"
"22569","135.37800","11.28169","0.00541"
"22638","135.79200","11.31613","0.00587"
"22707","136.20600","11.35069","0.00566"
"22776","136.62000","11.38518","0.00595"
"22845","137.03400","11.41968","0.00590"
"22914","137.44800","11.45406","0.00630"
"22983","137.86200","11.48862","0.00663"
"23052","138.27600","11.52318","0.00675"
"23121","138.69000","11.55762","0.00709"
"23190","139.10400","11.59211","0.00742"
"23259","139.51800","11.62661","0.00772"
"23328","139.93200","11.66123","0.00763"
"23397","140.34600","11.69567","0.00806"
"23466","140.76000","11.73011","0.00846"
"23535","141.17400","11.76455","0.00864"
"23604","141.58800","11.79917","0.00913"
"23673","142.00200","11.83366","0.00941"
"23742","142.41600","11.86816","0.00990"
"23811","142.83000","11.90260","0.01022"
"23880","143.24400","11.93716","0.01037"
"23949","143.65800","11.97166","0.01090"
"24018","144.07200","12.00616","0.01138"
"24087","144.48600","12.04060","0.01206"
"24156","144.90000","12.07509","0.01187"
"24225","145.31400","12.10959","0.01265"
"24294","145.72800","12.14415","0.01334"
"24363","146.14200","12.17859","0.01305"
"24432","146.55600","12.21309","0.01435"
"24501","146.97000","12.24765","0.01116"
"24570","147.38400","12.28215","0.01502"
"24639","147.79800","12.31664","0.01201"
"24708","148.21200","12.35108","0.01231"
"24777","148.62600","12.38558","0.01488"
"24846","149.04000","12.42020","0.01349"
"24915","149.45400","12.45470","0.01468"
"24984","149.86800","12.48908","0.01613"
"25053","150.28200","12.52357","0.01596"
"25122","150.69600","12.55819","0.01820"
"25191","151.11000","12.59269","0.01881"
"25260","151.52400","12.62713","0.01923"
"25329","151.93800","12.66151","0.02032"
"25398","152.35200","12.69613","0.02100"
"25467","152.76600","12.73063","0.02113"
"25536","153.18000","12.76519","0.00302"
"25605","153.59400","12.79962","0.00308"
"25674","154.00800","12.83412","0.00287"
"25743","154.42200","12.86862","0.00339"
"25812","154.83600","12.90318","0.00275"
"25881","155.25000","12.93762","0.00314"
"25950","155.66400","12.97206","0.00320"
"26019","156.07800","13.00661","0.00291"
"26088","156.49200","13.04117","0.00324"
"26157","156.90600","13.07567","0.00328"
"26226","157.32000","13.11005","0.00379"
"26295","157.73400","13.14467","0.00322"
"26364","158.14800","13.17917","0.00365"
"26433","158.56200","13.21361","0.00351"
"26502","158.97600","13.24804","0.00357"
"26571","159.39000","13.28260","0.00392"
"26640","159.80400","13.31716","0.00409"
"26709","160.21800","13.35160","0.00400"
"26778","160.63200","13.38616","0.00419"
"26847","161.04600","13.42060","0.00431"
"26916","161.46000","13.45516","0.00422"
"26985","161.87400","13.48965","0.00403"
"27054","162.28800","13.52415","0.00449"
"27123","162.70200","13.55853","0.00479"
"27192","163.11600","13.59309","0.00464"
"27261","163.53000","13.62765","0.00478"
"27330","163.94400","13.66215","0.00479"
"27399","164.35800","13.69659","0.00502"
"27468","164.77200","13.73108","0.00517"
"27537","165.18600","13.76570","0.00532"
"27606","165.60000","13.80020","0.00535"
"27675","166.01400","13.83464","0.00591"
"27744","166.42800","13.86908","0.00588"
"27813","166.84200","13.90358","0.00636"
"27882","167.25600","13.93814","0.00645"
"27951","167.67000","13.97263","0.00666"
"28020","168.08400","14.00713","0.00684"
"28089","168.49800","14.04163","0.00740"
"28158","168.91200","14.07619","0.00757"
"28227","169.32600","14.11069","0.00745"
"28296","169.74000","14.14507","0.00802"
"28365","170.15400","14.17963","0.00858"
"28434","170.56800","14.21418","0.00900"
"28503","170.98200","14.24862","0.00927"
"28572","171.39600","14.28312","0.00949"
"28641","171.81000","14.31762","0.01024"
"28710","172.22400","14.35224","0.01049"
"28779","172.63800","14.38662","0.01045"
"28848","173.05200","14.42118","0.01086"
"28917","173.46600","14.45555","0.01171"
"28986","173.88000","14.49011","0.01169"
"29055","174.29400","14.52467","0.01276"
"29124","174.70800","14.55917","0.01292"
"29193","175.12200","14.59361","0.01363"
"29262","175.53600","14.62811","0.01425"
"29331","175.95000","14.66267","0.01490"
"29400","176.36400","14.69716","0.01611"
"29469","176.77800","14.73160","0.01704"
"29538","177.19200","14.76610","0.01777"
"29607","177.60600","14.80066","0.01855"
"29676","178.02000","14.83516","0.01920"
"29745","178.43400","14.86966","0.02018"
"29814","178.84800","14.90410","0.02095"
"29883","179.26200","14.93865","0.01768"
"29952","179.67600","14.97315","0.01870"
"30021","180.09000","15.00765","0.02068"
"30090","180.50400","15.04209","0.02116"
"30159","180.91800","15.07659","0.02237"
"30228","181.33200","15.11115","0.02314"
"30297","181.74600","15.14565","0.02345"
"30366","182.16000","15.18014","0.02292"
"30435","182.57400","15.21458","0.02322"
"30504","182.98800","15.24914","0.02291"
"30573","183.40200","15.28370","0.02286"
"30642","183.81600","15.31814","0.02365"
"30711","184.23000","15.35258","0.02390"
"30780","184.64400","15.38714","0.02440"
"30849","185.05800","15.42169","0.02458"
"30918","185.47200","15.45619","0.02593"
"30987","185.88600","15.49063","0.02681"
"31056","186.30000","15.52513","0.02754"
"31125","186.71400","15.55969","0.02742"
"31194","187.12800","15.59419","0.02859"
"31263","187.54200","15.62862","0.02913"
"31332","187.95600","15.66306","0.03051"
"31401","188.37000","15.69762","0.03158"
"31470","188.78400","15.73212","0.03287"
"31539","189.19800","15.76662","0.03397"
"31608","189.61200","15.80112","0.03412"
"31677","190.02600","15.83562","0.03546"
"31746","190.44000","15.87011","0.03651"
"31815","190.85400","15.90467","0.03781"
"31884","191.26800","15.93911","0.03887"
"31953","191.68200","15.97361","0.04008"
"32022","192.09600","16.00811","0.04082"
"32091","192.51000","16.04267","0.04171"
"32160","192.92400","16.07711","0.04324"
"32229","193.33800","16.11160","0.04431"
"32298","193.75200","16.14616","0.04548"
"32367","194.16600","16.18072","0.04699"
"32436","194.58000","16.21510","0.04841"
"32505","194.99400","16.24954","0.04954"
"32574","195.40800","16.28410","0.05159"
"32643","195.82200","16.31866","0.05249"
"32712","196.23600","16.35316","0.05450"
"32781","196.65000","16.38759","0.05526"
"32850","197.06400","16.42209","0.05698"
"32919","197.47800","16.45665","0.05815"
"32988","197.89200","16.49121","0.06107"
"33057","198.30600","16.52565","0.06109"
"33126","198.72000","16.56009","0.06117"
"33195","199.13400","16.59464","0.06392"
"33264","199.54800","16.62914","0.06697"
"33333","199.96200","16.66364","0.05667"
"33402","200.37600","16.69808","0.06002"
"33471","200.79000","16.73264","0.05756"
"33540","201.20400","16.76720","0.05534"
"33609","201.61800","16.80164","0.05745"
"33678","202.03200","16.83607","0.05131"
"33747","202.44600","16.87063","0.05315"
"33816","202.86000","16.90513","0.05429"
"33885","203.27400","16.93963","0.05584"
"33954","203.68800","16.97413","0.05784"
"34023","204.10200","17.00863","0.05840"
"34092","204.51600","17.04319","0.06149"
"34161","204.93000","17.07768","0.06341"
"34230","205.34400","17.11218","0.06627"
"34299","205.75800","17.14656","0.06860"
"34368","206.17200","17.18112","0.07175"
"34437","206.58600","17.21568","0.07313"
"34506","207.00000","17.25018","0.07517"
"34575","207.41400","17.28461","0.07614"
"34644","207.82800","17.31911","0.07799"
"34713","208.24200","17.35373","0.07949"
"34782","208.65600","17.38823","0.08076"
"34851","209.07000","17.42261","0.08152"
"34920","209.48400","17.45711","0.08247"
"34989","209.89800","17.49161","0.08345"
"35058","210.31200","17.52617","0.08143"
"35127","210.72600","17.56067","0.05461"
"35196","211.14000","17.59510","0.05448"
"35265","211.55400","17.62966","0.05501"
"35334","211.96800","17.66416","0.05649"
"35403","212.38200","17.69872","0.05958"
"35472","212.79600","17.73310","0.06233"
"35541","213.21000","17.76760","0.06592"
"35610","213.62400","17.80215","0.06655"
"35679","214.03800","17.83665","0.06799"
"35748","214.45200","17.87109","0.06964"
"35817","214.86600","17.90559","0.06015"
"35886","215.28000","17.94021","0.05052"
"35955","215.69400","17.97471","0.05210"
"36024","216.10800","18.00920","0.05442"
"36093","216.52200","18.04358","0.05722"
"36162","216.93600","18.07808","0.06052"
"36231","217.35000","18.11264","0.06377"
"36300","217.76400","18.14720","0.06845"
"36369","218.17800","18.18164","0.06910"
"36438","218.59200","18.21608","0.07138"
"36507","219.00600","18.25069","0.07341"
"36576","219.42000","18.28514","0.07617"
"36645","219.83400","18.31963","0.07714"
"36714","220.24800","18.35407","0.07831"
"36783","220.66200","18.38857","0.07923"
"36852","221.07600","18.42313","0.08072"
"36921","221.49000","18.45769","0.08181"
"36990","221.90400","18.49207","0.08305"
"37059","222.31800","18.52662","0.08346"
"37128","222.73200","18.56112","0.08521"
"37197","223.14600","18.59568","0.08607"
"37266","223.56000","18.63012","0.08668"
"37335","223.97400","18.66456","0.08018"
"37404","224.38800","18.69912","0.08130"
"37473","224.80200","18.73362","0.08193"
"37542","225.21600","18.76811","0.08238"
"37611","225.63000","18.80261","0.05382"
"37680","226.04400","18.83717","0.05551"
"37749","226.45800","18.87173","0.05439"
"37818","226.87200","18.90611","0.05451"
"37887","227.28600","18.94061","0.05484"
"37956","227.70000","18.97511","0.05547"
"38025","228.11400","19.00966","0.05624"
"38094","228.52800","19.04416","0.05670"
"38163","228.94200","19.07860","0.05596"
"38232","229.35600","19.11310","0.05729"
"38301","229.77000","19.14766","0.05896"
"38370","230.18400","19.18222","0.05919"
"38439","230.59800","19.21666","0.05918"
"38508","231.01200","19.25109","0.05994"
"38577","231.42600","19.28559","0.06173"
"38646","231.84000","19.32009","0.06353"
"38715","232.25400","19.35465","0.06388"
"38784","232.66800","19.38909","0.06482"
"38853","233.08200","19.42359","0.06557"
"38922","233.49600","19.45815","0.06664"
"38991","233.91000","19.49270","0.06833"
"39060","234.32400","19.52714","0.06852"
"39129","234.73800","19.56158","0.06838"
"39198","235.15200","19.59614","0.07008"
"39267","235.56600","19.63064","0.07148"
"39336","235.98000","19.66508","0.07171"
"39405","236.39400","19.69958","0.07261"
"39474","236.80800","19.73413","0.07342"
"39543","237.22200","19.76869","0.07443"
"39612","237.63600","19.80313","0.07429"
"39681","238.05000","19.83757","0.07485"
"39750","238.46400","19.87213","0.07576"
"39819","238.87800","19.90663","0.07664"
"39888","239.29200","19.94118","0.07757"
"39957","239.70600","19.97562","0.07758"
"40026","240.12000","20.01012","0.07830"
"40095","240.53400","20.04462","0.07887"
"40164","240.94800","20.07918","0.07956"
"40233","241.36200","20.11368","0.07990"
"40302","241.77600","20.14806","0.08041"
"40371","242.19000","20.18262","0.08075"
"40440","242.60400","20.21717","0.08140"
"40509","243.01800","20.25167","0.08181"
"40578","243.43200","20.28605","0.08224"
"40647","243.84600","20.32061","0.08266"
"40716","244.26000","20.35517","0.08343"
"40785","244.67400","20.38967","0.08361"
"40854","245.08800","20.42410","0.08392"
"40923","245.50200","20.45860","0.08436"
"40992","245.91600","20.49316","0.08486"
"41061","246.33000","20.52760","0.08452"
"41130","246.74400","20.56216","0.08529"
"41199","247.15800","20.59660","0.08583"
"41268","247.57200","20.63116","0.08599"
"41337","247.98600","20.66566","0.08639"
"41406","248.40000","20.70015","0.08702"
"41475","248.81400","20.73459","0.08713"
"41544","249.22800","20.76909","0.08756"
"41613","249.64200","20.80365","0.08775"
"41682","250.05600","20.83821","0.08810"
"41751","250.47000","20.87264","0.08796"
"41820","250.88400","20.90709","0.08840"
"41889","251.29800","20.94170","0.08909"
"41958","251.71200","20.97620","0.08949"
"42027","252.12600","21.01064","0.09001"
"42096","252.54000","21.04508","0.09069"
"42165","252.95400","21.07958","0.09131"
"42234","253.36800","21.11414","0.09167"
"42303","253.78200","21.14863","0.09232"
"42372","254.19600","21.18313","0.09208"
"42441","254.61000","21.21763","0.09314"
"42510","255.02400","21.25213","0.09327"
"42579","255.43800","21.28669","0.09404"
"42648","255.85200","21.32113","0.09406"
"42717","256.26600","21.35563","0.09474"
"42786","256.68000","21.39013","0.09498"
"42855","257.09400","21.42462","0.09556"
"42924","257.50800","21.45912","0.09605"
"42993","257.92200","21.49362","0.09638"
"43062","258.33600","21.52812","0.09665"
"43131","258.75000","21.56268","0.09774"
"43200","259.16400","21.59718","0.09844"
"43269","259.57800","21.63155","0.09879"
"43338","259.99200","21.66611","0.09989"
"43407","260.40600","21.70067","0.10075"
"43476","260.82000","21.73517","0.10080"
"43545","261.23400","21.76961","0.10122"
"43614","261.64800","21.80411","0.10229"
"43683","262.06200","21.83867","0.10243"
"43752","262.47600","21.87322","0.10285"
"43821","262.89000","21.90760","0.10388"
"43890","263.30400","21.94210","0.10432"
"43959","263.71800","21.97660","0.10473"
"44028","264.13200","22.01110","0.10565"
"44097","264.54600","22.04565","0.10597"
"44166","264.96000","22.08010","0.10680"
"44235","265.37400","22.11459","0.10709"
"44304","265.78800","22.14915","0.10802"
"44373","266.20200","22.18371","0.10833"
"44442","266.61600","22.21809","0.10953"
"44511","267.03000","22.25259","0.10962"
"44580","267.44400","22.28715","0.10995"
"44649","267.85800","22.32158","0.11125"
"44718","268.27200","22.35614","0.11179"
"44787","268.68600","22.39058","0.11262"
"44856","269.10000","22.42520","0.11304"
"44925","269.51400","22.45970","0.11319"
"44994","269.92800","22.49414","0.11405"
"45063","270.34200","22.52858","0.11383"
"45132","270.75600","22.56314","0.11411"
"45201","271.17000","22.59769","0.11379"
"45270","271.58400","22.63219","0.11375"
"45339","271.99800","22.66663","0.11415"
"45408","272.41200","22.70113","0.11446"
"45477","272.82600","22.73569","0.11514"
"45546","273.24000","22.77019","0.11606"
"45615","273.65400","22.80462","0.11619"
"45684","274.06800","22.83912","0.11643"
"45753","274.48200","22.87362","0.11673"
"45822","274.89600","22.90812","0.11667"
"45891","275.31000","22.94262","0.11649"
"45960","275.72400","22.97706","0.11667"
"46029","276.13800","23.01162","0.01358"
"46098","276.55200","23.04612","0.00269"
"46167","276.96600","23.08073","0.00264"
"46236","277.38000","23.11511","0.00272"
"46305","277.79400","23.14955","0.00299"
"46374","278.20800","23.18417","0.00281"
"46443","278.62200","23.21867","0.00292"
"46512","279.03600","23.25317","0.00289"
"46581","279.45000","23.28761","0.00284"
"46650","279.86400","23.32216","0.00299"
"46719","280.27800","23.35666","0.00299"
"46788","280.69200","23.39116","0.00302"
"46857","281.10600","23.42560","0.00287"
"46926","281.52000","23.46010","0.00330"
"46995","281.93400","23.49466","0.00281"
"47064","282.34800","23.52916","0.00309"
"47133","282.76200","23.56359","0.00319"
"47202","283.17600","23.59809","0.00309"
"47271","283.59000","23.63265","0.00330"
"47340","284.00400","23.66715","0.00304"
"47409","284.41800","23.70165","0.00322"
"47478","284.83200","23.73609","0.00298"
"47547","285.24600","23.77058","0.00304"
"47616","285.66000","23.80514","0.00328"
"47685","286.07400","23.83970","0.00290"
"47754","286.48800","23.87408","0.00336"
"47823","286.90200","23.90864","0.00334"
"47892","287.31600","23.94314","0.00293"
"47961","287.73000","23.97764","0.00287"
"48030","288.14400","24.01213","0.00333"
"48099","288.55800","24.04663","0.00305"
"48168","288.97200","24.08113","0.00343"
"48237","289.38600","24.11563","0.00278"
"48306","289.80000","24.15013","0.00337"
"48375","290.21400","24.18463","0.00314"
"48444","290.62800","24.21918","0.00298"
"48513","291.04200","24.25368","0.00355"
"48582","291.45600","24.28818","0.00348"
"48651","291.87000","24.32262","0.00316"
"48720","292.28400","24.35712","0.00332"
"48789","292.69800","24.39162","0.00298"
"48858","293.11200","24.42612","0.00308"
"48927","293.52600","24.46061","0.00288"
"48996","293.94000","24.49512","0.00319"
"49065","294.35400","24.52967","0.00286"
"49134","294.76800","24.56423","0.00327"
"49203","295.18200","24.59867","0.00330"
"49272","295.59600","24.63311","0.00297"
"49341","296.01000","24.66761","0.00296"
"49410","296.42400","24.70217","0.00310"
"49479","296.83800","24.73666","0.00296"
"49548","297.25200","24.77110","0.00316"
"49617","297.66600","24.80560","0.00347"
"49686","298.08000","24.84016","0.00316"
"49755","298.49400","24.87472","0.00338"
"49824","298.90800","24.90910","0.00311"
"49893","299.32200","24.94359","0.00320"
"49962","299.73600","24.97816","0.00337"
"50031","300.15000","25.01259","0.00350"
"50100","300.56400","25.04709","0.00328"
"50169","300.97800","25.08159","0.00356"
"50238","301.39200","25.11615","0.00358"
"50307","301.80600","25.15065","0.00359"
"50376","302.22000","25.18521","0.00368"
"50445","302.63400","25.21958","0.00286"
"50514","303.04800","25.25414","0.00310"
"50583","303.46200","25.28864","0.00326"
"50652","303.87600","25.32314","0.00347"
"50721","304.29000","25.35758","0.00319"
"50790","304.70400","25.39208","0.00367"
"50859","305.11800","25.42669","0.00357"
"50928","305.53200","25.46119","0.00341"
"50997","305.94600","25.49563","0.00362"
"51066","306.36000","25.53007","0.00371"
"51135","306.77400","25.56463","0.00403"
"51204","307.18800","25.59913","0.00380"
"51273","307.60200","25.63363","0.00357"
"51342","308.01600","25.66807","0.00368"
"51411","308.43000","25.70262","0.00396"
"51480","308.84400","25.73712","0.00398"
"51549","309.25800","25.77168","0.00393"
"51618","309.67200","25.80612","0.00358"
"51687","310.08600","25.84056","0.00365"
"51756","310.50000","25.87512","0.00398"
"51825","310.91400","25.90962","0.00338"
"51894","311.32800","25.94417","0.00283"
"51963","311.74200","25.97855","0.00331"
"52032","312.15600","26.01317","0.00332"
"52101","312.57000","26.04767","0.00393"
"52170","312.98400","26.08223","0.00344"
"52239","313.39800","26.11661","0.00377"
"52308","313.81200","26.15111","0.00387"
"52377","314.22600","26.18566","0.00370"
"52446","314.64000","26.22016","0.00399"
"52515","315.05400","26.25466","0.00417"
"52584","315.46800","26.28910","0.00433"
"52653","315.88200","26.32366","0.00413"
"52722","316.29600","26.35816","0.00405"
"52791","316.71000","26.39266","0.00404"
"52860","317.12400","26.42709","0.00439"
"52929","317.53800","26.46159","0.00383"
"52998","317.95200","26.49615","0.00420"
"53067","318.36600","26.53059","0.00427"
"53136","318.78000","26.56509","0.00419"
"53205","319.19400","26.59959","0.00412"
"53274","319.60800","26.63415","0.00439"
"53343","320.02200","26.66864","0.00411"
"53412","320.43600","26.70314","0.00477"
"53481","320.85000","26.73758","0.00426"
"53550","321.26400","26.77208","0.00448"
"53619","321.67800","26.80664","0.00449"
"53688","322.09200","26.84114","0.00442"
"53757","322.50600","26.87558","0.00472"
"53826","322.92000","26.91013","0.00493"
"53895","323.33400","26.94469","0.00507"
"53964","323.74800","26.97913","0.00477"
"54033","324.16200","27.01357","0.00504"
"54102","324.57600","27.04813","0.00474"
"54171","324.99000","27.08263","0.00502"
"54240","325.40400","27.11712","0.00508"
"54309","325.81800","27.15156","0.00498"
"54378","326.23200","27.18612","0.00519"
"54447","326.64600","27.22056","0.00522"
"54516","327.06000","27.25518","0.00542"
"54585","327.47400","27.28968","0.00544"
"54654","327.88800","27.32412","0.00552"
"54723","328.30200","27.35862","0.00576"
"54792","328.71600","27.39317","0.00569"
"54861","329.13000","27.42767","0.00577"
"54930","329.54400","27.46205","0.00564"
"54999","329.95800","27.49661","0.00555"
"55068","330.37200","27.53117","0.00595"
"55137","330.78600","27.56567","0.00579"
"55206","331.20000","27.60016","0.00609"
"55275","331.61400","27.63460","0.00641"
"55344","332.02800","27.66916","0.00663"
"55413","332.44200","27.70360","0.00595"
"55482","332.85600","27.73810","0.00572"
"55551","333.27000","27.77260","0.00574"
"55620","333.68400","27.80716","0.00592"
"55689","334.09800","27.84166","0.00587"
"55758","334.51200","27.87621","0.00652"
"55827","334.92600","27.91059","0.00568"
"55896","335.34000","27.94515","0.00518"
"55965","335.75400","27.97965","0.00567"
"56034","336.16800","28.01414","0.00601"
"56103","336.58200","28.04864","0.00575"
"56172","336.99600","28.08308","0.00559"
"56241","337.41000","28.11770","0.00494"
"56310","337.82400","28.15220","0.00284"
"56379","338.23800","28.18664","0.00326"
"56448","338.65200","28.22114","0.00283"
"56517","339.06600","28.25564","0.00333"
"56586","339.48000","28.29020","0.00321"
"56655","339.89400","28.32463","0.00326"
"56724","340.30800","28.35907","0.00322"
"56793","340.72200","28.39363","0.00324"
"56862","341.13600","28.42813","0.00314"
"56931","341.55000","28.46269","0.00291"
"57000","341.96400","28.49713","0.00289"
"57069","342.37800","28.53163","0.00271"
"57138","342.79200","28.56612","0.00290"
"57207","343.20600","28.60068","0.00302"
"57276","343.62000","28.63512","0.00336"
"57345","344.03400","28.66956","0.00297"
"57414","344.44800","28.70412","0.00321"
"57483","344.86200","28.73868","0.00361"
"57552","345.27600","28.77317","0.00358"
"57621","345.69000","28.80761","0.00332"
"57690","346.10400","28.84211","0.00345"
"57759","346.51800","28.87667","0.00396"
"57828","346.93200","28.91117","0.00388"
"57897","347.34600","28.94561","0.00402"
"57966","347.76000","28.98005","0.00415"
"58035","348.17400","29.01467","0.00344"
"58104","348.58800","29.04911","0.00373"
"58173","349.00200","29.08366","0.00292"
"58242","349.41600","29.11816","0.00357"
"58311","349.83000","29.15260","0.00356"
"58380","350.24400","29.18716","0.00372"
"58449","350.65800","29.22166","0.00394"
"58518","351.07200","29.25616","0.00364"
"58587","351.48600","29.29059","0.00337"
"58656","351.90000","29.32515","0.00341"
"58725","352.31400","29.35965","0.00332"
"58794","352.72800","29.39409","0.00381"
"58863","353.14200","29.42859","0.00332"
"58932","353.55600","29.46315","0.00329"
"59001","353.97000","29.49758","0.00328"
"59070","354.38400","29.53214","0.00367"
"59139","354.79800","29.56658","0.00337"
"59208","355.21200","29.60114","0.00356"
"59277","355.62600","29.63564","0.00357"
"59346","356.04000","29.67014","0.00340"
"59415","356.45400","29.70458","0.00382"
"59484","356.86800","29.73913","0.00366"
"59553","357.28200","29.77363","0.00344"
"59622","357.69600","29.80813","0.00327"
"59691","358.11000","29.84263","0.00389"
"59760","358.52400","29.87707","0.00390"
"59829","358.93800","29.91163","0.00425"
"59898","359.35200","29.94619","0.00367"
"59967","359.76600","29.98062","0.00394"
"60036","360.18000","30.01512","0.00366"
"60105","360.59400","30.04962","0.00384"
"60174","361.00800","30.08412","0.00378"
"60243","361.42200","30.11862","0.00424"
"60312","361.83600","30.15306","0.00390"
"60381","362.25000","30.18756","0.00378"
"60450","362.66400","30.22212","0.00409"
"60519","363.07800","30.25667","0.00454"
"60588","363.49200","30.29111","0.00439"
"60657","363.90600","30.32555","0.00459"
"60726","364.32000","30.36011","0.00463"
"60795","364.73400","30.39467","0.00440"
"60864","365.14800","30.42911","0.00426"
"60933","365.56200","30.46354","0.00423"
"61002","365.97600","30.49810","0.00467"
"61071","366.39000","30.53266","0.00505"
"61140","366.80400","30.56716","0.00499"
"61209","367.21800","30.60160","0.00495"
"61278","367.63200","30.63616","0.00507"
"61347","368.04600","30.67066","0.00463"
"61416","368.46000","30.70516","0.00526"
"61485","368.87400","30.73965","0.00238"
"61554","369.28800","30.77409","0.00257"
"61623","369.70200","30.80859","0.00245"
"61692","370.11600","30.84321","0.00241"
"61761","370.53000","30.87771","0.00268"
"61830","370.94400","30.91209","0.00231"
"61899","371.35800","30.94658","0.00227"
"61968","371.77200","30.98114","0.00266"
"62037","372.18600","31.01564","0.00225"
"62106","372.60000","31.05002","0.00223"
"62175","373.01400","31.08458","0.00212"
"62244","373.42800","31.11920","0.00227"
"62313","373.84200","31.15370","0.00244"
"62382","374.25600","31.18813","0.00239"
"62451","374.67000","31.22263","0.00270"
"62520","375.08400","31.25713","0.00226"
"62589","375.49800","31.29163","0.00254"
"62658","375.91200","31.32613","0.00222"
"62727","376.32600","31.36057","0.00278"
"62796","376.74000","31.39519","0.00248"
"62865","377.15400","31.42962","0.00273"
"62934","377.56800","31.46418","0.00226"
"63003","377.98200","31.49862","0.00256"
"63072","378.39600","31.53312","0.00251"
"63141","378.81000","31.56768","0.00228"
"63210","379.22400","31.60217","0.00235"
"63279","379.63800","31.63667","0.00235"
"63348","380.05200","31.67111","0.00241"
"63417","380.46600","31.70567","0.00242"
"63486","380.88000","31.74023","0.00251"
"63555","381.29400","31.77467","0.00201"
"63624","381.70800","31.80911","0.00258"
"63693","382.12200","31.84361","0.00262"
"63762","382.53600","31.87816","0.00236"
"63831","382.95000","31.91260","0.00253"
"63900","383.36400","31.94710","0.00259"
"63969","383.77800","31.98160","0.00222"
"64038","384.19200","32.01616","0.00250"
"64107","384.60600","32.05066","0.00254"
"64176","385.02000","32.08509","0.00292"
"64245","385.43400","32.11959","0.00258"
"64314","385.84800","32.15416","0.00254"
"64383","386.26200","32.18859","0.00247"
"64452","386.67600","32.22315","0.00246"
"64521","387.09000","32.25759","0.00265"
"64590","387.50400","32.29209","0.00216"
"64659","387.91800","32.32664","0.00240"
"64728","388.33200","32.36120","0.00274"
"64797","388.74600","32.39558","0.00269"
"64866","389.16000","32.43014","0.00248"
"64935","389.57400","32.46464","0.00247"
"65004","389.98800","32.49914","0.00248"
"65073","390.40200","32.53358","0.00258"
"65142","390.81600","32.56807","0.00234"
"65211","391.23000","32.60270","0.00268"
"65280","391.64400","32.63720","0.00240"
"65349","392.05800","32.67157","0.00250"
"65418","392.47200","32.70607","0.00236"
"65487","392.88600","32.74063","0.00227"
"65556","393.30000","32.77513","0.00246"
"65625","393.71400","32.80963","0.00224"
"65694","394.12800","32.84406","0.00265"
"65763","394.54200","32.87862","0.00275"
"65832","394.95600","32.91312","0.00218"
"65901","395.37000","32.94768","0.00205"
"65970","395.78400","32.98212","0.00256"
"66039","396.19800","33.01656","0.00245"
"66108","396.61200","33.05117","0.00200"
"66177","397.02600","33.08561","0.00233"
"66246","397.44000","33.12011","0.00219"
"66315","397.85400","33.15455","0.00217"
"66384","398.26800","33.18911","0.00220"
"66453","398.68200","33.22367","0.00229"
"66522","399.09600","33.25822","0.00238"
"66591","399.51000","33.29261","0.00202"
"66660","399.92400","33.32710","0.00245"
"66729","400.33800","33.36166","0.00237"
"66798","400.75200","33.39616","0.00233"
"66867","401.16600","33.43060","0.00240"
"66936","401.58000","33.46510","0.00225"
"67005","401.99400","33.49966","0.00211"
"67074","402.40800","33.53415","0.00205"
"67143","402.82200","33.56865","0.00221"
"67212","403.23600","33.60315","0.00208"
"67281","403.65000","33.63759","0.00266"
"67350","404.06400","33.67215","0.00245"
"67419","404.47800","33.70665","0.00207"
"67488","404.89200","33.74109","0.00198"
"67557","405.30600","33.77559","0.00171"
"67626","405.72000","33.81014","0.00208"
"67695","406.13400","33.84464","0.00224"
"67764","406.54800","33.87920","0.00223"
"67833","406.96200","33.91358","0.00236"
"67902","407.37600","33.94814","0.00235"
"67971","407.79000","33.98270","0.00234"
"68040","408.20400","34.01714","0.00239"
"68109","408.61800","34.05157","0.00214"
"68178","409.03200","34.08613","0.00219"
"68247","409.44600","34.12069","0.00219"
"68316","409.86000","34.15519","0.00205"
"68385","410.27400","34.18962","0.00230"
"68454","410.68800","34.22412","0.00192"
"68523","411.10200","34.25863","0.00211"
"68592","411.51600","34.29318","0.00215"
"68661","411.93000","34.32762","0.00218"
"68730","412.34400","34.36212","0.00215"
"68799","412.75800","34.39662","0.00239"
"68868","413.17200","34.43112","0.00228"
"68937","413.58600","34.46568","0.00219"
"69006","414.00000","34.50018","0.00215"
"69075","414.41400","34.53461","0.00257"
"69144","414.82800","34.56917","0.00250"
"69213","415.24200","34.60367","0.00228"
"69282","415.65600","34.63811","0.00210"
"69351","416.07000","34.67261","0.00232"
"69420","416.48400","34.70716","0.00246"
"69489","416.89800","34.74166","0.00224"
"69558","417.31200","34.77616","0.00237"
"69627","417.72600","34.81060","0.00231"
"69696","418.14000","34.84516","0.00231"
"69765","418.55400","34.87966","0.00208"
"69834","418.96800","34.91410","0.00230"
"69903","419.38200","34.94859","0.00222"
"69972","419.79600","34.98315","0.00220"
"70041","420.21000","35.01765","0.00208"
"70110","420.62400","35.05215","0.00227"
"70179","421.03800","35.08659","0.00231"
"70248","421.45200","35.12115","0.00213"
"70317","421.86600","35.15559","0.00243"
"70386","422.28000","35.19009","0.00195"
"70455","422.69400","35.22464","0.00191"
"70524","423.10800","35.25908","0.00186"
"70593","423.52200","35.29364","0.00244"
"70662","423.93600","35.32820","0.00211"
"70731","424.35000","35.36270","0.00226"
"70800","424.76400","35.39714","0.00168"
"70869","425.17800","35.43163","0.00187"
"70938","425.59200","35.46613","0.00195"
"71007","426.00600","35.50063","0.00230"
"71076","426.42000","35.53507","0.00224"
"71145","426.83400","35.56957","0.00246"
"71214","427.24800","35.60413","0.00201"
"71283","427.66200","35.63869","0.00181"
"71352","428.07600","35.67313","0.00230"
"71421","428.49000","35.70756","0.00201"
"71490","428.90400","35.74218","0.00217"
"71559","429.31800","35.77662","0.00224"
"71628","429.73200","35.81106","0.00186"
"71697","430.14600","35.84556","0.00170"
"71766","430.56000","35.88012","0.00164"
"71835","430.97400","35.91467","0.00178"
"71904","431.38800","35.94917","0.00133"
"71973","431.80200","35.98367","0.00185"
"72042","432.21600","36.01811","0.00182"
"72111","432.63000","36.05261","0.00215"
"72180","433.04400","36.08717","0.00206"
"72249","433.45800","36.12160","0.00209"
"72318","433.87200","36.15611","0.00215"
"72387","434.28600","36.19066","0.00160"
"72456","434.70000","36.22516","0.00196"
"72525","435.11400","36.25960","0.00201"
"72594","435.52800","36.29416","0.00186"
"72663","435.94200","36.32860","0.00204"
"72732","436.35600","36.36316","0.00191"
"72801","436.77000","36.39766","0.00184"
"72870","437.18400","36.43209","0.00199"
"72939","437.59800","36.46659","0.00176"
"73008","438.01200","36.50115","0.00228"
"73077","438.42600","36.53565","0.00178"
"73146","438.84000","36.57015","0.00196"
"73215","439.25400","36.60459","0.00234"
"73284","439.66800","36.63914","0.00152"
"73353","440.08200","36.67364","0.00174"
"73422","440.49600","36.70814","0.00202"
"73491","440.91000","36.74252","0.00204"
"73560","441.32400","36.77714","0.00202"
"73629","441.73800","36.81164","0.00205"
"73698","442.15200","36.84620","0.00162"
"73767","442.56600","36.88063","0.00174"
"73836","442.98000","36.91513","0.00166"
"73905","443.39400","36.94963","0.00164"
"73974","443.80800","36.98413","0.00189"
"74043","444.22200","37.01863","0.00223"
"74112","444.63600","37.05307","0.00181"
"74181","445.05000","37.08768","0.00180"
"74250","445.46400","37.12218","0.00195"
"74319","445.87800","37.15662","0.00193"
"74388","446.29200","37.19112","0.00145"
"74457","446.70600","37.22568","0.00192"
"74526","447.12000","37.26012","0.00187"
"74595","447.53400","37.29462","0.00213"
"74664","447.94800","37.32906","0.00177"
"74733","448.36200","37.36356","0.00180"
"74802","448.77600","37.39811","0.00210"
"74871","449.19000","37.43267","0.00206"
"74940","449.60400","37.46717","0.00206"
"75009","450.01800","37.50161","0.00220"
"75078","450.43200","37.53617","0.00205"
"75147","450.84600","37.57067","0.00259"
"75216","451.26000","37.60511","0.00245"
"75285","451.67400","37.63960","0.00200"
"75354","452.08800","37.67410","0.00200"
"75423","452.50200","37.70866","0.00242"
"75492","452.91600","37.74316","0.00194"
"75561","453.33000","37.77766","0.00260"
"75630","453.74400","37.81210","0.00212"
"75699","454.15800","37.84665","0.00235"
"75768","454.57200","37.88115","0.00223"
"75837","454.98600","37.91559","0.00260"
"75906","455.40000","37.95009","0.00227"
"75975","455.81400","37.98459","0.00216"
"76044","456.22800","38.01915","0.00252"
"76113","456.64200","38.05365","0.00298"
"76182","457.05600","38.08809","0.00288"
"76251","457.47000","38.12258","0.00289"
"76320","457.88400","38.15720","0.00252"
"76389","458.29800","38.19164","0.00309"
"76458","458.71200","38.22602","0.00284"
"76527","459.12600","38.26064","0.00352"
"76596","459.54000","38.29514","0.00299"
"76665","459.95400","38.32964","0.00323"
"76734","460.36800","38.36419","0.00288"
"76803","460.78200","38.39857","0.00328"
"76872","461.19600","38.43313","0.00322"
"76941","461.61000","38.46763","0.00322"
"77010","462.02400","38.50213","0.00291"
"77079","462.43800","38.53657","0.00294"
"77148","462.85200","38.57113","0.00294"
"77217","463.26600","38.60568","0.00297"
"77286","463.68000","38.64024","0.00280"
"77355","464.09400","38.67462","0.00291"
"77424","464.50800","38.70906","0.00319"
"77493","464.92200","38.74362","0.00302"
"77562","465.33600","38.77811","0.00302"
"77631","465.75000","38.81261","0.00330"
"77700","466.16400","38.84705","0.00325"
"77769","466.57800","38.88161","0.00296"
"77838","466.99200","38.91617","0.00326"
"77907","467.40600","38.95067","0.00322"
"77976","467.82000","38.98517","0.00319"
"78045","468.23400","39.01966","0.00338"
"78114","468.64800","39.05416","0.00274"
"78183","469.06200","39.08860","0.00276"
"78252","469.47600","39.12310","0.00290"
"78321","469.89000","39.15760","0.00299"
"78390","470.30400","39.19216","0.00272"
"78459","470.71800","39.22666","0.00273"
"78528","471.13200","39.26110","0.00295"
"78597","471.54600","39.29565","0.00290"
"78666","471.96000","39.33015","0.00290"
"78735","472.37400","39.36465","0.00274"
"78804","472.78800","39.39909","0.00273"
"78873","473.20200","39.43358","0.00289"
"78942","473.61600","39.46809","0.00313"
"79011","474.03000","39.50265","0.00308"
"79080","474.44400","39.53720","0.00321"
"79149","474.85800","39.57164","0.00272"
"79218","475.27200","39.60614","0.00316"
"79287","475.68600","39.64064","0.00318"
"79356","476.10000","39.67514","0.00307"
"79425","476.51400","39.70964","0.00305"
"79494","476.92800","39.74408","-0.00826"
"79563","477.34200","39.77863","-0.01576"
"79632","477.75600","39.81319","0.07524"
"79701","478.17000","39.84763","0.14967"
"79770","478.58400","39.88213","-0.11059"
"79839","478.99800","39.91663","0.38401"
"79908","479.41200","39.95113","0.28739"
"79977","479.82600","39.98563","0.31281"
"80046","480.24000","40.02012","0.08244"
"80115","480.65400","40.05462","0.16418"
"80184","481.06800","40.08912","0.78156"
"80253","481.48200","40.12368","-0.24270"
"80322","481.89600","40.15812","-0.15245"
"80391","482.31000","40.19262","-0.26278"
"80460","482.72400","40.22717","-0.26800"
"80529","483.13800","40.26167","0.42814"
"80598","483.55200","40.29617","-0.15582"
"80667","483.96600","40.33055","-0.26738"
"80736","484.38000","40.36511","-0.26118"
"80805","484.79400","40.39960","-0.17856"
"80874","485.20800","40.43417","-0.16360"
"80943","485.62200","40.46861","-0.03445"
"81012","486.03600","40.50316","-0.00005"
"81081","486.45000","40.53766","0.00099"
"81150","486.86400","40.57216","0.00532"
"81219","487.27800","40.60660","-0.00053"
"81288","487.69200","40.64104","0.00349"
"81357","488.10600","40.67566","0.00106"
"81426","488.52000","40.71016","0.00087"
"81495","488.93400","40.74466","0.00103"
"81564","489.34800","40.77909","0.00068"
"81633","489.76200","40.81365","0.00105"
"81702","490.17600","40.84815","0.00084"
"81771","490.59000","40.88264","0.00081"
"81840","491.00400","40.91708","0.00082"
"81909","491.41800","40.95159","0.00115"
"81978","491.83200","40.98608","0.00056"
"82047","492.24600","41.02064","0.00117"
"82116","492.66000","41.05514","0.00132"
"82185","493.07400","41.08952","0.00108"
"82254","493.48800","41.12413","0.00079"
"82323","493.90200","41.15863","0.00128"
"82392","494.31600","41.19313","0.00126"
"82461","494.73000","41.22757","0.00040"
"82530","495.14400","41.26213","0.00051"
"82599","495.55800","41.29669","0.00079"
"82668","495.97200","41.33119","0.00109"
"82737","496.38600","41.36563","0.00068"
"82806","496.80000","41.40012","0.00120"
"82875","497.21400","41.43462","0.00063"
"82944","497.62800","41.46912","0.00078"
"83013","498.04200","41.50362","0.00126"
"83082","498.45600","41.53812","0.00114"
"83151","498.87000","41.57262","0.00129"
"83220","499.28400","41.60717","0.00051"
"83289","499.69800","41.64167","0.00118"
"83358","500.11200","41.67606","0.00115"
"83427","500.52600","41.71062","0.00135"
"83496","500.94000","41.74517","0.00103"
"83565","501.35400","41.77967","0.00131"
"83634","501.76800","41.81405","0.00108"
"83703","502.18200","41.84861","0.00099"
"83772","502.59600","41.88316","0.00069"
"83841","503.01000","41.91767","0.00056"
"83910","503.42400","41.95216","0.00129"
"83979","503.83800","41.98660","0.00087"
"84048","504.25200","42.02116","0.00128"
"84117","504.66600","42.05566","0.00107"
"84186","505.08000","42.09010","0.00117"
"84255","505.49400","42.12460","0.00164"
"84324","505.90800","42.15915","0.00072"
"84393","506.32200","42.19365","0.00118"
"84462","506.73600","42.22821","0.00069"
"84476","506.81600","42.23479","0.00114"