File: Trajectories_together/161223_2Specimen_RawData_2.csv
"","V1","V2","V3"
"1","End date","12/23/2016",""
"2","Specimen label","21AT_70",""
"3","Maximum Load","0.31666","N"
"4","Time","Extension","Load"
"5","(s)","(mm)","(N)"
"6","0.00000","0.00000","-0.00009"
"41","0.21000","0.01459","-0.00007"
"76","0.42000","0.03528","-0.00002"
"111","0.63000","0.05261","0.00033"
"146","0.84000","0.07019","0.00012"
"181","1.05000","0.08765","-0.00005"
"216","1.26000","0.10517","0.00030"
"251","1.47000","0.12269","0.00014"
"286","1.68000","0.14009","0.00021"
"321","1.89000","0.15766","0.00008"
"356","2.10000","0.17512","0.00044"
"391","2.31000","0.19258","-0.00005"
"426","2.52000","0.21010","-0.00009"
"461","2.73000","0.22762","0.00037"
"496","2.94000","0.24514","0.00004"
"531","3.15000","0.26266","0.00033"
"566","3.36000","0.28011","0.00048"
"601","3.57000","0.29757","0.00037"
"636","3.78000","0.31509","-0.00006"
"671","3.99000","0.33261","0.00053"
"706","4.20000","0.35007","0.00056"
"741","4.41000","0.36759","0.00044"
"776","4.62000","0.38510","0.00053"
"811","4.83000","0.40262","0.00005"
"846","5.04000","0.42014","0.00037"
"881","5.25000","0.43766","0.00071"
"916","5.46000","0.45512","0.00024"
"951","5.67000","0.47264","0.00042"
"986","5.88000","0.49009","-0.00011"
"1021","6.09000","0.50761","0.00042"
"1056","6.30000","0.52519","0.00021"
"1091","6.51000","0.54259","0.00017"
"1126","6.72000","0.56017","0.00000"
"1161","6.93000","0.57763","0.00028"
"1196","7.14000","0.59509","0.00028"
"1231","7.35000","0.61266","0.00015"
"1266","7.56000","0.63006","0.00060"
"1301","7.77000","0.64764","0.00047"
"1336","7.98000","0.66510","0.00057"
"1371","8.19000","0.68262","0.00042"
"1406","8.40000","0.70014","0.00033"
"1441","8.61000","0.71759","0.00007"
"1476","8.82000","0.73511","0.00058"
"1511","9.03000","0.75263","0.00038"
"1546","9.24000","0.77009","0.00013"
"1581","9.45000","0.78767","0.00051"
"1616","9.66000","0.80507","0.00060"
"1651","9.87000","0.82258","0.00034"
"1686","10.08000","0.84016","0.00096"
"1721","10.29000","0.85756","0.00034"
"1756","10.50000","0.87514","0.00042"
"1791","10.71000","0.89260","0.00010"
"1826","10.92000","0.91012","0.00081"
"1861","11.13000","0.92763","0.00028"
"1896","11.34000","0.94509","0.00051"
"1931","11.55000","0.96267","0.00071"
"1966","11.76000","0.98019","0.00043"
"2001","11.97000","0.99759","0.00034"
"2036","12.18000","1.01511","0.00051"
"2071","12.39000","1.03257","0.00073"
"2106","12.60000","1.05014","0.00033"
"2141","12.81000","1.06760","0.00037"
"2176","13.02000","1.08506","0.00069"
"2211","13.23000","1.10264","0.00060"
"2246","13.44000","1.12010","0.00033"
"2281","13.65000","1.13768","0.00040"
"2316","13.86000","1.15513","0.00066"
"2351","14.07000","1.17265","0.00051"
"2386","14.28000","1.19011","0.00032"
"2421","14.49000","1.20763","0.00073"
"2456","14.70000","1.22515","0.00091"
"2491","14.91000","1.24267","0.00038"
"2526","15.12000","1.26006","0.00081"
"2561","15.33000","1.27764","0.00066"
"2596","15.54000","1.29516","0.00046"
"2631","15.75000","1.31262","0.00047"
"2666","15.96000","1.33014","0.00020"
"2701","16.17000","1.34760","0.00065"
"2736","16.38000","1.36511","0.00075"
"2771","16.59000","1.38263","0.00069"
"2806","16.80000","1.40009","0.00080"
"2841","17.01000","1.41761","0.00102"
"2876","17.22000","1.43513","0.00078"
"2911","17.43000","1.45265","0.00070"
"2946","17.64000","1.47016","0.00089"
"2981","17.85000","1.48756","0.00092"
"3016","18.06000","1.50514","0.00061"
"3051","18.27000","1.52254","0.00054"
"3086","18.48000","1.54012","0.00049"
"3121","18.69000","1.55764","0.00091"
"3156","18.90000","1.57510","0.00094"
"3191","19.11000","1.59267","0.00073"
"3226","19.32000","1.61013","0.00096"
"3261","19.53000","1.62765","0.00083"
"3296","19.74000","1.64511","0.00122"
"3331","19.95000","1.66263","0.00097"
"3366","20.16000","1.68015","0.00094"
"3401","20.37000","1.69760","0.00069"
"3436","20.58000","1.71512","0.00095"
"3471","20.79000","1.73264","0.00060"
"3506","21.00000","1.75010","0.00086"
"3541","21.21000","1.76762","0.00052"
"3576","21.42000","1.78508","0.00091"
"3611","21.63000","1.80259","0.00122"
"3646","21.84000","1.82011","0.00077"
"3681","22.05000","1.83763","0.00086"
"3716","22.26000","1.85515","0.00092"
"3751","22.47000","1.87261","0.00081"
"3786","22.68000","1.89013","0.00113"
"3821","22.89000","1.90764","0.00050"
"3856","23.10000","1.92510","0.00087"
"3891","23.31000","1.94262","0.00049"
"3926","23.52000","1.96014","0.00087"
"3961","23.73000","1.97754","0.00092"
"3996","23.94000","1.99518","0.00089"
"4031","24.15000","2.01264","0.00088"
"4066","24.36000","2.03009","0.00105"
"4101","24.57000","2.04761","0.00135"
"4136","24.78000","2.06513","0.00068"
"4171","24.99000","2.08271","0.00079"
"4206","25.20000","2.10011","0.00081"
"4241","25.41000","2.11763","0.00114"
"4276","25.62000","2.13508","0.00163"
"4311","25.83000","2.15260","0.00115"
"4346","26.04000","2.17018","0.00110"
"4381","26.25000","2.18770","0.00120"
"4416","26.46000","2.20510","0.00123"
"4451","26.67000","2.22262","0.00094"
"4486","26.88000","2.24013","0.00054"
"4521","27.09000","2.25759","0.00114"
"4556","27.30000","2.27517","0.00089"
"4591","27.51000","2.29257","0.00116"
"4626","27.72000","2.31015","0.00092"
"4661","27.93000","2.32761","0.00144"
"4696","28.14000","2.34512","0.00117"
"4731","28.35000","2.36264","0.00118"
"4766","28.56000","2.38010","0.00129"
"4801","28.77000","2.39768","0.00075"
"4836","28.98000","2.41514","0.00111"
"4871","29.19000","2.43260","0.00072"
"4906","29.40000","2.45017","0.00129"
"4941","29.61000","2.46763","0.00097"
"4976","29.82000","2.48509","0.00153"
"5011","30.03000","2.50255","0.00170"
"5046","30.24000","2.52013","0.00129"
"5081","30.45000","2.53771","0.00146"
"5116","30.66000","2.55505","0.00123"
"5151","30.87000","2.57268","0.00118"
"5186","31.08000","2.59014","0.00133"
"5221","31.29000","2.60760","0.00163"
"5256","31.50000","2.62512","0.00127"
"5291","31.71000","2.64258","0.00133"
"5326","31.92000","2.66016","0.00135"
"5361","32.13000","2.67767","0.00108"
"5396","32.34000","2.69507","0.00179"
"5431","32.55000","2.71265","0.00148"
"5466","32.76000","2.73017","0.00150"
"5501","32.97000","2.74757","0.00144"
"5536","33.18000","2.76515","0.00146"
"5571","33.39000","2.78260","0.00155"
"5606","33.60000","2.80018","0.00130"
"5641","33.81000","2.81758","0.00132"
"5676","34.02000","2.83516","0.00181"
"5711","34.23000","2.85262","0.00174"
"5746","34.44000","2.87014","0.00171"
"5781","34.65000","2.88766","0.00147"
"5816","34.86000","2.90517","0.00125"
"5851","35.07000","2.92257","0.00166"
"5886","35.28000","2.94015","0.00159"
"5921","35.49000","2.95761","0.00194"
"5956","35.70000","2.97513","0.00172"
"5991","35.91000","2.99265","0.00153"
"6026","36.12000","3.01004","0.00124"
"6061","36.33000","3.02768","0.00166"
"6096","36.54000","3.04508","0.00153"
"6131","36.75000","3.06266","0.00163"
"6166","36.96000","3.08012","0.00136"
"6201","37.17000","3.09758","0.00183"
"6236","37.38000","3.11515","0.00210"
"6271","37.59000","3.13267","0.00164"
"6306","37.80000","3.15013","0.00155"
"6341","38.01000","3.16765","0.00186"
"6376","38.22000","3.18511","0.00181"
"6411","38.43000","3.20263","0.00205"
"6446","38.64000","3.22009","0.00184"
"6481","38.85000","3.23760","0.00173"
"6516","39.06000","3.25512","0.00151"
"6551","39.27000","3.27258","0.00199"
"6586","39.48000","3.29010","0.00186"
"6621","39.69000","3.30768","0.00162"
"6656","39.90000","3.32508","0.00125"
"6691","40.11000","3.34265","0.00154"
"6726","40.32000","3.36011","0.00138"
"6761","40.53000","3.37763","0.00192"
"6796","40.74000","3.39515","0.00162"
"6831","40.95000","3.41261","0.00171"
"6866","41.16000","3.43013","0.00133"
"6901","41.37000","3.44764","0.00136"
"6936","41.58000","3.46510","0.00123"
"6971","41.79000","3.48268","0.00123"
"7006","42.00000","3.50008","0.00138"
"7041","42.21000","3.51766","0.00156"
"7076","42.42000","3.53512","0.00189"
"7111","42.63000","3.55263","0.00201"
"7146","42.84000","3.57009","0.00155"
"7181","43.05000","3.58761","0.00216"
"7216","43.26000","3.60513","0.00238"
"7251","43.47000","3.62265","0.00210"
"7286","43.68000","3.64011","0.00161"
"7321","43.89000","3.65768","0.00219"
"7356","44.10000","3.67508","0.00154"
"7391","44.31000","3.69260","0.00223"
"7426","44.52000","3.71012","0.00185"
"7461","44.73000","3.72758","0.00222"
"7496","44.94000","3.74516","0.00216"
"7531","45.15000","3.76268","0.00183"
"7566","45.36000","3.78013","0.00214"
"7601","45.57000","3.79765","0.00226"
"7636","45.78000","3.81511","0.00243"
"7671","45.99000","3.83263","0.00215"
"7706","46.20000","3.85015","0.00185"
"7741","46.41000","3.86761","0.00181"
"7776","46.62000","3.88512","0.00218"
"7811","46.83000","3.90258","0.00233"
"7846","47.04000","3.92010","0.00230"
"7881","47.25000","3.93762","0.00216"
"7916","47.46000","3.95514","0.00212"
"7951","47.67000","3.97266","0.00233"
"7986","47.88000","3.99011","0.00245"
"8021","48.09000","4.00769","0.00175"
"8056","48.30000","4.02509","0.00189"
"8091","48.51000","4.04261","0.00225"
"8126","48.72000","4.06013","0.00214"
"8161","48.93000","4.07765","0.00249"
"8196","49.14000","4.09516","0.00230"
"8231","49.35000","4.11268","0.00180"
"8266","49.56000","4.13008","0.00210"
"8301","49.77000","4.14760","0.00218"
"8336","49.98000","4.16512","0.00238"
"8371","50.19000","4.18264","0.00206"
"8406","50.40000","4.20015","0.00220"
"8441","50.61000","4.21761","0.00220"
"8476","50.82000","4.23519","0.00219"
"8511","51.03000","4.25259","0.00265"
"8546","51.24000","4.27011","0.00249"
"8581","51.45000","4.28763","0.00218"
"8616","51.66000","4.30509","0.00234"
"8651","51.87000","4.32266","0.00262"
"8686","52.08000","4.34018","0.00280"
"8721","52.29000","4.35764","0.00245"
"8756","52.50000","4.37516","0.00280"
"8791","52.71000","4.39262","0.00233"
"8826","52.92000","4.41014","0.00290"
"8861","53.13000","4.42765","0.00265"
"8896","53.34000","4.44505","0.00305"
"8931","53.55000","4.46263","0.00297"
"8966","53.76000","4.48015","0.00256"
"9001","53.97000","4.49767","0.00263"
"9036","54.18000","4.51513","0.00276"
"9071","54.39000","4.53264","0.00292"
"9106","54.60000","4.55016","0.00305"
"9141","54.81000","4.56768","0.00301"
"9176","55.02000","4.58514","0.00262"
"9211","55.23000","4.60266","0.00303"
"9246","55.44000","4.62006","0.00319"
"9281","55.65000","4.63763","0.00336"
"9316","55.86000","4.65515","0.00332"
"9351","56.07000","4.67261","0.00340"
"9386","56.28000","4.69013","0.00333"
"9421","56.49000","4.70765","0.00301"
"9456","56.70000","4.72517","0.00320"
"9491","56.91000","4.74263","0.00343"
"9526","57.12000","4.76014","0.00324"
"9561","57.33000","4.77760","0.00337"
"9596","57.54000","4.79512","0.00348"
"9631","57.75000","4.81264","0.00324"
"9666","57.96000","4.83016","0.00361"
"9701","58.17000","4.84756","0.00358"
"9736","58.38000","4.86513","0.00367"
"9771","58.59000","4.88265","0.00326"
"9806","58.80000","4.90011","0.00390"
"9841","59.01000","4.91769","0.00366"
"9876","59.22000","4.93509","0.00382"
"9911","59.43000","4.95273","0.00262"
"9946","59.64000","4.97006","0.00318"
"9981","59.85000","4.98764","0.00278"
"10016","60.06000","5.00516","0.00279"
"10051","60.27000","5.02256","0.00263"
"10086","60.48000","5.04014","0.00308"
"10121","60.69000","5.05766","0.00347"
"10156","60.90000","5.07511","0.00263"
"10191","61.11000","5.09263","0.00336"
"10226","61.32000","5.11009","0.00346"
"10261","61.53000","5.12767","0.00363"
"10296","61.74000","5.14519","0.00351"
"10331","61.95000","5.16253","0.00301"
"10366","62.16000","5.18017","0.00348"
"10401","62.37000","5.19756","0.00322"
"10436","62.58000","5.21514","0.00348"
"10471","62.79000","5.23266","0.00385"
"10506","63.00000","5.25012","0.00378"
"10541","63.21000","5.26764","0.00352"
"10576","63.42000","5.28516","0.00398"
"10611","63.63000","5.30261","0.00387"
"10646","63.84000","5.32013","0.00374"
"10681","64.05000","5.33759","0.00366"
"10716","64.26000","5.35511","0.00324"
"10751","64.47000","5.37263","0.00416"
"10786","64.68000","5.39009","0.00394"
"10821","64.89000","5.40766","0.00298"
"10856","65.10000","5.42512","0.00370"
"10891","65.31000","5.44270","0.00389"
"10926","65.52000","5.46016","0.00408"
"10961","65.73000","5.47762","0.00361"
"10996","65.94000","5.49514","0.00379"
"11031","66.15000","5.51260","0.00413"
"11066","66.36000","5.53011","0.00267"
"11101","66.57000","5.54769","0.00278"
"11136","66.78000","5.56503","0.00312"
"11171","66.99000","5.58267","0.00317"
"11206","67.20000","5.60013","0.00257"
"11241","67.41000","5.61759","0.00252"
"11276","67.62000","5.63516","0.00340"
"11311","67.83000","5.65262","0.00324"
"11346","68.04000","5.67014","0.00283"
"11381","68.25000","5.68760","0.00369"
"11416","68.46000","5.70512","0.00317"
"11451","68.67000","5.72264","0.00338"
"11486","68.88000","5.74009","0.00374"
"11521","69.09000","5.75767","0.00373"
"11556","69.30000","5.77519","0.00399"
"11591","69.51000","5.79265","0.00359"
"11626","69.72000","5.81017","0.00336"
"11661","69.93000","5.82763","0.00426"
"11696","70.14000","5.84508","0.00415"
"11731","70.35000","5.86266","0.00379"
"11766","70.56000","5.88000","0.00377"
"11801","70.77000","5.89764","0.00381"
"11836","70.98000","5.91510","0.00441"
"11871","71.19000","5.93268","0.00399"
"11906","71.40000","5.95014","0.00445"
"11941","71.61000","5.96759","0.00401"
"11976","71.82000","5.98517","0.00444"
"12011","72.03000","6.00263","0.00458"
"12046","72.24000","6.02015","0.00484"
"12081","72.45000","6.03767","0.00487"
"12116","72.66000","6.05513","0.00488"
"12151","72.87000","6.07264","0.00499"
"12186","73.08000","6.09010","0.00497"
"12221","73.29000","6.10762","0.00461"
"12256","73.50000","6.12514","0.00479"
"12291","73.71000","6.14260","0.00470"
"12326","73.92000","6.16017","0.00483"
"12361","74.13000","6.17763","0.00513"
"12396","74.34000","6.19509","0.00465"
"12431","74.55000","6.21261","0.00468"
"12466","74.76000","6.23013","0.00454"
"12501","74.97000","6.24765","0.00449"
"12536","75.18000","6.26517","0.00447"
"12571","75.39000","6.28256","0.00479"
"12606","75.60000","6.30020","0.00481"
"12641","75.81000","6.31766","0.00444"
"12676","76.02000","6.33512","0.00458"
"12711","76.23000","6.35264","0.00483"
"12746","76.44000","6.37010","0.00452"
"12781","76.65000","6.38767","0.00493"
"12816","76.86000","6.40507","0.00495"
"12851","77.07000","6.42259","0.00557"
"12886","77.28000","6.44017","0.00547"
"12921","77.49000","6.45757","0.00576"
"12956","77.70000","6.47515","0.00542"
"12991","77.91000","6.49266","0.00554"
"13026","78.12000","6.51006","0.00608"
"13061","78.33000","6.52764","0.00604"
"13096","78.54000","6.54510","0.00588"
"13131","78.75000","6.56262","0.00594"
"13166","78.96000","6.58020","0.00616"
"13201","79.17000","6.59754","0.00611"
"13236","79.38000","6.61517","0.00644"
"13271","79.59000","6.63257","0.00632"
"13306","79.80000","6.65015","0.00643"
"13341","80.01000","6.66761","0.00658"
"13376","80.22000","6.68513","0.00729"
"13411","80.43000","6.70265","0.00668"
"13446","80.64000","6.72016","0.00742"
"13481","80.85000","6.73762","0.00732"
"13516","81.06000","6.75514","0.00767"
"13551","81.27000","6.77260","0.00753"
"13586","81.48000","6.79012","0.00808"
"13621","81.69000","6.80764","0.00790"
"13656","81.90000","6.82510","0.00718"
"13691","82.11000","6.84267","0.00792"
"13726","82.32000","6.86007","0.00777"
"13761","82.53000","6.87765","0.00766"
"13796","82.74000","6.89511","0.00800"
"13831","82.95000","6.91263","0.00790"
"13866","83.16000","6.93015","0.00823"
"13901","83.37000","6.94760","0.00911"
"13936","83.58000","6.96512","0.00888"
"13971","83.79000","6.98264","0.00915"
"14006","84.00000","7.00010","0.00944"
"14041","84.21000","7.01768","0.00946"
"14076","84.42000","7.03514","0.00952"
"14111","84.63000","7.05259","0.00989"
"14146","84.84000","7.07011","0.00983"
"14181","85.05000","7.08763","0.01011"
"14216","85.26000","7.10515","0.01054"
"14251","85.47000","7.12261","0.01098"
"14286","85.68000","7.14013","0.01115"
"14321","85.89000","7.15764","0.01117"
"14356","86.10000","7.17516","0.01175"
"14391","86.31000","7.19262","0.01186"
"14426","86.52000","7.21014","0.01272"
"14461","86.73000","7.22760","0.01287"
"14496","86.94000","7.24518","0.01311"
"14531","87.15000","7.26264","0.01347"
"14566","87.36000","7.28015","0.01337"
"14601","87.57000","7.29767","0.01389"
"14636","87.78000","7.31501","0.01418"
"14671","87.99000","7.33271","0.01463"
"14706","88.20000","7.35011","0.01495"
"14741","88.41000","7.36757","0.01528"
"14776","88.62000","7.38520","0.01567"
"14811","88.83000","7.40260","0.01613"
"14846","89.04000","7.42018","0.01629"
"14881","89.25000","7.43764","0.01652"
"14916","89.46000","7.45510","0.01657"
"14951","89.67000","7.47262","0.01763"
"14986","89.88000","7.49013","0.01786"
"15021","90.09000","7.50759","0.01814"
"15056","90.30000","7.52511","0.01943"
"15091","90.51000","7.54257","0.01951"
"15126","90.72000","7.56015","0.01974"
"15161","90.93000","7.57761","0.02032"
"15196","91.14000","7.59518","0.02114"
"15231","91.35000","7.61264","0.02130"
"15266","91.56000","7.63010","0.02079"
"15301","91.77000","7.64762","0.02157"
"15336","91.98000","7.66508","0.02242"
"15371","92.19000","7.68266","0.02302"
"15406","92.40000","7.70018","0.02334"
"15441","92.61000","7.71763","0.02332"
"15476","92.82000","7.73515","0.01526"
"15511","93.03000","7.75267","0.01601"
"15546","93.24000","7.77013","0.01758"
"15581","93.45000","7.78765","0.01893"
"15616","93.66000","7.80505","0.01880"
"15651","93.87000","7.82262","0.01829"
"15686","94.08000","7.84014","0.01836"
"15721","94.29000","7.85760","0.01906"
"15756","94.50000","7.87512","0.02033"
"15791","94.71000","7.89264","0.02154"
"15826","94.92000","7.91015","0.02269"
"15861","95.13000","7.92767","0.02255"
"15896","95.34000","7.94513","0.02258"
"15931","95.55000","7.96265","0.02265"
"15966","95.76000","7.98005","0.02340"
"16001","95.97000","7.99757","0.02482"
"16036","96.18000","8.01515","0.02619"
"16071","96.39000","8.03254","0.02710"
"16106","96.60000","8.05012","0.02685"
"16141","96.81000","8.06764","0.02568"
"16176","97.02000","8.08510","0.02698"
"16211","97.23000","8.10262","0.02800"
"16246","97.44000","8.12014","0.02854"
"16281","97.65000","8.13765","0.02955"
"16316","97.86000","8.15517","0.02918"
"16351","98.07000","8.17257","0.02694"
"16386","98.28000","8.19015","0.02842"
"16421","98.49000","8.20761","0.02969"
"16456","98.70000","8.22513","0.03098"
"16491","98.91000","8.24264","0.03148"
"16526","99.12000","8.26010","0.03205"
"16561","99.33000","8.27762","0.01218"
"16596","99.54000","8.29508","0.01400"
"16631","99.75000","8.31266","0.01682"
"16666","99.96000","8.33012","0.01995"
"16701","100.17000","8.34758","0.02075"
"16736","100.38000","8.36515","0.01882"
"16771","100.59000","8.38261","0.01745"
"16806","100.80000","8.40013","0.01695"
"16841","101.01000","8.41771","0.01948"
"16876","101.22000","8.43505","0.02171"
"16911","101.43000","8.45269","0.02513"
"16946","101.64000","8.47014","0.02630"
"16981","101.85000","8.48760","0.02538"
"17016","102.06000","8.50512","0.02469"
"17051","102.27000","8.52258","0.02418"
"17086","102.48000","8.54016","0.02603"
"17121","102.69000","8.55762","0.02861"
"17156","102.90000","8.57513","0.03117"
"17191","103.11000","8.59259","0.03298"
"17226","103.32000","8.61017","0.03180"
"17261","103.53000","8.62763","0.03210"
"17296","103.74000","8.64515","0.03153"
"17331","103.95000","8.66261","0.03350"
"17366","104.16000","8.68013","0.03656"
"17401","104.37000","8.69758","0.04001"
"17436","104.58000","8.71516","0.04039"
"17471","104.79000","8.73268","0.04078"
"17506","105.00000","8.75002","0.04055"
"17541","105.21000","8.76766","0.04088"
"17576","105.42000","8.78512","0.04360"
"17611","105.63000","8.80263","0.04472"
"17646","105.84000","8.82015","0.04649"
"17681","106.05000","8.83761","0.04733"
"17716","106.26000","8.85513","0.04794"
"17751","106.47000","8.87265","0.04828"
"17786","106.68000","8.89011","0.04949"
"17821","106.89000","8.90762","0.05114"
"17856","107.10000","8.92508","0.05322"
"17891","107.31000","8.94266","0.04651"
"17926","107.52000","8.96006","0.04816"
"17961","107.73000","8.97758","0.04842"
"17996","107.94000","8.99516","0.04904"
"18031","108.15000","9.01261","0.05016"
"18066","108.36000","9.03013","0.05118"
"18101","108.57000","9.04765","0.05287"
"18136","108.78000","9.06511","0.05539"
"18171","108.99000","9.08263","0.05638"
"18206","109.20000","9.10009","0.05836"
"18241","109.41000","9.11766","0.05954"
"18276","109.62000","9.13518","0.06147"
"18311","109.83000","9.15258","0.06383"
"18346","110.04000","9.17016","0.06548"
"18381","110.25000","9.18768","0.06694"
"18416","110.46000","9.20508","0.06863"
"18451","110.67000","9.22265","0.07021"
"18486","110.88000","9.24011","0.07112"
"18521","111.09000","9.25769","0.07212"
"18556","111.30000","9.27509","0.07329"
"18591","111.51000","9.29261","0.07495"
"18626","111.72000","9.31013","0.07647"
"18661","111.93000","9.32759","0.07763"
"18696","112.14000","9.34516","0.07990"
"18731","112.35000","9.36262","0.08195"
"18766","112.56000","9.38008","0.08468"
"18801","112.77000","9.39766","0.08696"
"18836","112.98000","9.41512","0.08936"
"18871","113.19000","9.43258","0.09104"
"18906","113.40000","9.45015","0.09301"
"18941","113.61000","9.46755","0.09494"
"18976","113.82000","9.48513","0.09619"
"19011","114.03000","9.50259","0.09708"
"19046","114.24000","9.52017","0.09817"
"19081","114.45000","9.53763","0.10034"
"19116","114.66000","9.55515","0.10144"
"19151","114.87000","9.57266","0.10232"
"19186","115.08000","9.59018","0.10334"
"19221","115.29000","9.60758","0.10486"
"19256","115.50000","9.62510","0.10661"
"19291","115.71000","9.64256","0.10823"
"19326","115.92000","9.66014","0.10927"
"19361","116.13000","9.67759","0.11162"
"19396","116.34000","9.69511","0.11263"
"19431","116.55000","9.71269","0.11395"
"19466","116.76000","9.73009","0.11526"
"19501","116.97000","9.74761","0.11687"
"19536","117.18000","9.76513","0.11899"
"19571","117.39000","9.78258","0.12111"
"19606","117.60000","9.80016","0.12231"
"19641","117.81000","9.81762","0.12432"
"19676","118.02000","9.83514","0.12602"
"19711","118.23000","9.85266","0.12815"
"19746","118.44000","9.87006","0.13089"
"19781","118.65000","9.88769","0.13356"
"19816","118.86000","9.90515","0.13796"
"19851","119.07000","9.92255","0.14082"
"19886","119.28000","9.94019","0.14461"
"19921","119.49000","9.95759","0.14777"
"19956","119.70000","9.97517","0.15005"
"19991","119.91000","9.99262","0.15229"
"20026","120.12000","10.01014","0.15432"
"20061","120.33000","10.02766","0.15641"
"20096","120.54000","10.04512","0.15850"
"20131","120.75000","10.06270","0.16105"
"20166","120.96000","10.08016","0.16498"
"20201","121.17000","10.09761","0.16791"
"20236","121.38000","10.11513","0.17137"
"20271","121.59000","10.13265","0.17376"
"20306","121.80000","10.15011","0.17582"
"20341","122.01000","10.16769","0.17776"
"20376","122.22000","10.18503","0.17892"
"20411","122.43000","10.20267","0.18154"
"20446","122.64000","10.22012","0.18318"
"20481","122.85000","10.23764","0.18446"
"20516","123.06000","10.25516","0.18643"
"20551","123.27000","10.27262","0.18831"
"20586","123.48000","10.29014","0.19058"
"20621","123.69000","10.30766","0.19219"
"20656","123.90000","10.32511","0.19485"
"20691","124.11000","10.34263","0.19684"
"20726","124.32000","10.36009","0.19908"
"20761","124.53000","10.37761","0.20205"
"20796","124.74000","10.39507","0.20451"
"20831","124.95000","10.41259","0.20660"
"20866","125.16000","10.43011","0.20815"
"20901","125.37000","10.44756","0.21046"
"20936","125.58000","10.46514","0.21233"
"20971","125.79000","10.48266","0.21420"
"21006","126.00000","10.50012","0.21555"
"21041","126.21000","10.51758","0.21722"
"21076","126.42000","10.53509","0.21886"
"21111","126.63000","10.55261","0.22150"
"21146","126.84000","10.57019","0.22331"
"21181","127.05000","10.58753","0.22622"
"21216","127.26000","10.60517","0.22814"
"21251","127.47000","10.62263","0.23045"
"21286","127.68000","10.64009","0.23281"
"21321","127.89000","10.65766","0.23490"
"21356","128.10000","10.67512","0.23729"
"21391","128.31000","10.69264","0.24065"
"21426","128.52000","10.71016","0.24394"
"21461","128.73000","10.72762","0.24658"
"21496","128.94000","10.74520","0.25007"
"21531","129.15000","10.76259","0.25267"
"21566","129.36000","10.78011","0.25528"
"21601","129.57000","10.79763","0.25747"
"21636","129.78000","10.81509","0.26039"
"21671","129.99000","10.83267","0.26282"
"21706","130.20000","10.85013","0.26715"
"21741","130.41000","10.86765","0.26983"
"21776","130.62000","10.88510","0.27237"
"21811","130.83000","10.90256","0.27575"
"21846","131.04000","10.92020","0.27772"
"21881","131.25000","10.93760","0.28059"
"21916","131.46000","10.95512","0.28312"
"21951","131.67000","10.97263","0.28724"
"21986","131.88000","10.99009","0.29155"
"22021","132.09000","11.00767","0.29586"
"22056","132.30000","11.02513","0.30022"
"22091","132.51000","11.04265","0.30303"
"22126","132.72000","11.06011","0.30594"
"22161","132.93000","11.07763","0.30782"
"22196","133.14000","11.09508","0.31014"
"22231","133.35000","11.11260","0.31192"
"22266","133.56000","11.13012","0.31449"
"22301","133.77000","11.14764","0.31619"
"22336","133.98000","11.16510","0.31402"
"22371","134.19000","11.18268","0.31529"
"22406","134.40000","11.20013","0.22924"
"22441","134.61000","11.21759","0.11078"
"22476","134.82000","11.23511","0.11248"
"22511","135.03000","11.25263","0.12045"
"22546","135.24000","11.27009","0.11390"
"22581","135.45000","11.28767","0.11476"
"22616","135.66000","11.30507","0.11489"
"22651","135.87000","11.32264","0.11501"
"22686","136.08000","11.34016","0.11665"
"22721","136.29000","11.35762","0.11899"
"22756","136.50000","11.37514","0.12070"
"22791","136.71000","11.39254","0.12613"
"22826","136.92000","11.41017","0.12159"
"22861","137.13000","11.42757","0.12538"
"22896","137.34000","11.44515","0.12630"
"22931","137.55000","11.46267","0.12772"
"22966","137.76000","11.48007","0.13207"
"23001","137.97000","11.49765","0.14021"
"23036","138.18000","11.51517","0.13957"
"23071","138.39000","11.53262","0.14435"
"23106","138.60000","11.55014","0.14668"
"23141","138.81000","11.56760","0.14470"
"23176","139.02000","11.58512","0.14849"
"23211","139.23000","11.60264","0.15286"
"23246","139.44000","11.62004","0.15419"
"23281","139.65000","11.63767","0.15501"
"23316","139.86000","11.65513","0.15994"
"23351","140.07000","11.67259","0.15823"
"23386","140.28000","11.69017","0.16070"
"23421","140.49000","11.70757","0.16164"
"23456","140.70000","11.72515","0.16438"
"23491","140.91000","11.74266","0.05379"
"23526","141.12000","11.76006","0.06438"
"23561","141.33000","11.77758","0.06022"
"23596","141.54000","11.79504","0.06156"
"23631","141.75000","11.81262","0.07245"
"23666","141.96000","11.83014","0.06243"
"23701","142.17000","11.84760","0.07363"
"23736","142.38000","11.86517","0.06723"
"23771","142.59000","11.88257","0.07452"
"23806","142.80000","11.90021","0.07253"
"23841","143.01000","11.91761","0.07591"
"23876","143.22000","11.93513","0.08318"
"23911","143.43000","11.95258","0.07755"
"23946","143.64000","11.97010","0.08863"
"23981","143.85000","11.98762","0.08119"
"24016","144.06000","12.00514","0.09099"
"24051","144.27000","12.02260","0.08932"
"24086","144.48000","12.04018","0.09431"
"24121","144.69000","12.05764","0.09304"
"24156","144.90000","12.07509","0.09773"
"24191","145.11000","12.09267","0.09533"
"24226","145.32000","12.11013","0.09756"
"24261","145.53000","12.12765","0.09836"
"24296","145.74000","12.14511","0.09832"
"24331","145.95000","12.16257","0.10201"
"24366","146.16000","12.18014","0.10111"
"24401","146.37000","12.19760","0.10517"
"24436","146.58000","12.21512","0.10458"
"24471","146.79000","12.23264","0.10839"
"24506","147.00000","12.25010","0.10719"
"24541","147.21000","12.26768","0.11215"
"24576","147.42000","12.28508","0.10988"
"24611","147.63000","12.30265","0.11523"
"24646","147.84000","12.32011","0.11429"
"24681","148.05000","12.33757","0.11879"
"24716","148.26000","12.35515","0.11819"
"24751","148.47000","12.37261","0.12230"
"24786","148.68000","12.39012","0.12097"
"24821","148.89000","12.40764","0.12511"
"24856","149.10000","12.42510","0.12407"
"24891","149.31000","12.44262","0.11424"
"24926","149.52000","12.46008","0.02734"
"24961","149.73000","12.47760","0.03821"
"24996","149.94000","12.49512","0.03149"
"25031","150.15000","12.51258","0.04282"
"25066","150.36000","12.53015","0.03472"
"25101","150.57000","12.54761","0.04386"
"25136","150.78000","12.56507","0.03920"
"25171","150.99000","12.58265","0.04420"
"25206","151.20000","12.60011","0.04382"
"25241","151.41000","12.61768","0.04613"
"25276","151.62000","12.63514","0.04916"
"25311","151.83000","12.65260","0.04875"
"25346","152.04000","12.67012","0.05325"
"25381","152.25000","12.68764","0.05165"
"25416","152.46000","12.70510","0.05689"
"25451","152.67000","12.72267","0.05486"
"25486","152.88000","12.74007","0.05870"
"25521","153.09000","12.75765","0.05940"
"25556","153.30000","12.77511","0.06344"
"25591","153.51000","12.79263","0.06475"
"25626","153.72000","12.81015","0.06830"
"25661","153.93000","12.82761","0.06943"
"25696","154.14000","12.84518","0.07042"
"25731","154.35000","12.86258","0.07140"
"25766","154.56000","12.88010","0.07288"
"25801","154.77000","12.89762","0.07406"
"25836","154.98000","12.91514","0.07559"
"25871","155.19000","12.93266","0.07901"
"25906","155.40000","12.95017","0.07922"
"25941","155.61000","12.96763","0.08391"
"25976","155.82000","12.98515","0.08421"
"26011","156.03000","13.00261","0.08723"
"26046","156.24000","13.02013","0.08781"
"26081","156.45000","13.03765","0.09148"
"26116","156.66000","13.05505","0.09190"
"26151","156.87000","13.07262","0.09419"
"26186","157.08000","13.09014","0.09475"
"26221","157.29000","13.10766","0.09671"
"26256","157.50000","13.12512","0.09723"
"26291","157.71000","13.14258","0.09924"
"26326","157.92000","13.16016","0.09956"
"26361","158.13000","13.17767","0.10099"
"26396","158.34000","13.19507","0.10179"
"26431","158.55000","13.21259","0.10316"
"26466","158.76000","13.23011","0.10367"
"26501","158.97000","13.24763","0.10581"
"26536","159.18000","13.26508","0.10669"
"26571","159.39000","13.28260","0.10841"
"26606","159.60000","13.30018","0.10974"
"26641","159.81000","13.31758","0.11204"
"26676","160.02000","13.33516","0.11394"
"26711","160.23000","13.35262","0.11616"
"26746","160.44000","13.37008","0.11729"
"26781","160.65000","13.38765","0.11920"
"26816","160.86000","13.40511","0.12111"
"26851","161.07000","13.42263","0.12289"
"26886","161.28000","13.44015","0.12458"
"26921","161.49000","13.45761","0.12612"
"26956","161.70000","13.47519","0.12901"
"26991","161.91000","13.49264","0.13214"
"27026","162.12000","13.51010","0.13434"
"27061","162.33000","13.52768","0.13835"
"27096","162.54000","13.54508","0.14229"
"27131","162.75000","13.56266","0.14487"
"27166","162.96000","13.58012","0.14807"
"27201","163.17000","13.59764","0.15062"
"27236","163.38000","13.61515","0.15261"
"27271","163.59000","13.63267","0.15439"
"27306","163.80000","13.65013","0.15687"
"27341","164.01000","13.66765","0.15921"
"27376","164.22000","13.68511","0.16246"
"27411","164.43000","13.70268","0.16611"
"27446","164.64000","13.72014","0.16900"
"27481","164.85000","13.73760","0.17203"
"27516","165.06000","13.75518","0.17449"
"27551","165.27000","13.77252","0.17691"
"27586","165.48000","13.79016","0.17849"
"27621","165.69000","13.80762","0.18058"
"27656","165.90000","13.82513","0.18284"
"27691","166.11000","13.84265","0.18445"
"27726","166.32000","13.86011","0.18698"
"27761","166.53000","13.87769","0.18912"
"27796","166.74000","13.89515","0.15945"
"27831","166.95000","13.91255","0.15804"
"27866","167.16000","13.93013","0.16045"
"27901","167.37000","13.94758","0.16377"
"27936","167.58000","13.96516","0.16711"
"27971","167.79000","13.98256","0.17088"
"28006","168.00000","14.00008","0.17289"
"28041","168.21000","14.01766","0.17590"
"28076","168.42000","14.03512","0.17777"
"28111","168.63000","14.05263","0.18047"
"28146","168.84000","14.07015","0.18253"
"28181","169.05000","14.08755","0.18517"
"28216","169.26000","14.10513","0.18788"
"28251","169.47000","14.12265","0.19008"
"28286","169.68000","14.14011","0.19284"
"28321","169.89000","14.15768","0.19460"
"28356","170.10000","14.17508","0.19757"
"28391","170.31000","14.19266","0.20011"
"28426","170.52000","14.21018","0.20190"
"28461","170.73000","14.22758","0.20403"
"28496","170.94000","14.24516","0.20578"
"28531","171.15000","14.26255","0.20856"
"28566","171.36000","14.28013","0.20999"
"28601","171.57000","14.29759","0.21185"
"28636","171.78000","14.31511","0.21328"
"28671","171.99000","14.33263","0.21545"
"28706","172.20000","14.35015","0.21638"
"28741","172.41000","14.36760","0.21818"
"28776","172.62000","14.38518","0.22101"
"28811","172.83000","14.40264","0.22324"
"28846","173.04000","14.42016","0.22564"
"28881","173.25000","14.43756","0.22798"
"28916","173.46000","14.45508","0.22941"
"28951","173.67000","14.47266","0.23179"
"28986","173.88000","14.49005","0.23392"
"29021","174.09000","14.50769","0.23625"
"29056","174.30000","14.52515","0.23953"
"29091","174.51000","14.54261","0.24171"
"29126","174.72000","14.56013","0.24262"
"29161","174.93000","14.57765","0.21111"
"29196","175.14000","14.59516","0.21182"
"29231","175.35000","14.61268","0.21310"
"29266","175.56000","14.63008","0.21512"
"29301","175.77000","14.64760","0.21647"
"29336","175.98000","14.66506","0.21850"
"29371","176.19000","14.68264","0.22010"
"29406","176.40000","14.70009","0.22216"
"29441","176.61000","14.71761","0.22486"
"29476","176.82000","14.73513","0.22733"
"29511","177.03000","14.75259","0.23015"
"29546","177.24000","14.77017","0.23202"
"29581","177.45000","14.78763","0.23374"
"29616","177.66000","14.80509","0.23612"
"29651","177.87000","14.82266","0.23785"
"29686","178.08000","14.84012","0.24168"
"29721","178.29000","14.85764","0.24355"
"29756","178.50000","14.87516","0.24613"
"29791","178.71000","14.89262","0.24928"
"29826","178.92000","14.91020","0.25124"
"29861","179.13000","14.92759","0.25317"
"29896","179.34000","14.94511","0.25542"
"29931","179.55000","14.96263","0.25801"
"29966","179.76000","14.98009","0.25978"
"30001","179.97000","14.99767","0.26283"
"30036","180.18000","15.01507","0.26618"
"30071","180.39000","15.03264","0.26926"
"30106","180.60000","15.05016","0.27137"
"30141","180.81000","15.06762","0.04285"
"30176","181.02000","15.08514","0.04239"
"30211","181.23000","15.10266","0.04144"
"30246","181.44000","15.12012","0.02792"
"30281","181.65000","15.13763","0.04350"
"30316","181.86000","15.15509","0.04182"
"30351","182.07000","15.17261","0.02590"
"30386","182.28000","15.19013","0.02927"
"30421","182.49000","15.20759","0.04922"
"30456","182.70000","15.22517","0.03408"
"30491","182.91000","15.24263","0.03178"
"30526","183.12000","15.26014","0.04524"
"30561","183.33000","15.27760","0.04695"
"30596","183.54000","15.29518","0.03591"
"30631","183.75000","15.31270","0.05361"
"30666","183.96000","15.33016","0.05602"
"30701","184.17000","15.34762","0.04581"
"30736","184.38000","15.36513","0.04795"
"30771","184.59000","15.38259","0.06257"
"30806","184.80000","15.40017","0.05855"
"30841","185.01000","15.41763","0.04840"
"30876","185.22000","15.43509","0.05706"
"30911","185.43000","15.45261","0.06638"
"30946","185.64000","15.47012","0.06565"
"30981","185.85000","15.48764","0.05837"
"31016","186.06000","15.50516","0.06627"
"31051","186.27000","15.52262","0.07503"
"31086","186.48000","15.54014","0.07236"
"31121","186.69000","15.55766","0.06826"
"31156","186.90000","15.57511","0.06948"
"31191","187.11000","15.59269","0.07624"
"31226","187.32000","15.61003","0.08324"
"31261","187.53000","15.62767","0.07642"
"31296","187.74000","15.64513","0.07567"
"31331","187.95000","15.66265","0.08112"
"31366","188.16000","15.68016","0.08663"
"31401","188.37000","15.69756","0.09459"
"31436","188.58000","15.71520","0.08716"
"31471","188.79000","15.73260","0.08818"
"31506","189.00000","15.75012","0.09068"
"31541","189.21000","15.76770","0.09470"
"31576","189.42000","15.78509","0.09906"
"31611","189.63000","15.80267","0.09736"
"31646","189.84000","15.82013","0.09935"
"31681","190.05000","15.83759","0.09737"
"31716","190.26000","15.85517","0.09938"
"31751","190.47000","15.87257","0.10315"
"31786","190.68000","15.89014","0.10312"
"31821","190.89000","15.90766","0.10734"
"31856","191.10000","15.92506","0.10502"
"31891","191.31000","15.94264","0.10749"
"31926","191.52000","15.96010","0.10664"
"31961","191.73000","15.97762","0.10887"
"31996","191.94000","15.99514","0.11334"
"32031","192.15000","16.01259","0.11344"
"32066","192.36000","16.03011","0.11913"
"32101","192.57000","16.04763","0.11699"
"32136","192.78000","16.06509","0.12170"
"32171","192.99000","16.08267","0.11934"
"32206","193.20000","16.10007","0.12256"
"32241","193.41000","16.11764","0.12263"
"32276","193.62000","16.13510","0.12512"
"32311","193.83000","16.15262","0.12836"
"32346","194.04000","16.17014","0.12946"
"32381","194.25000","16.18760","0.13726"
"32416","194.46000","16.20518","0.13600"
"32451","194.67000","16.22263","0.14522"
"32486","194.88000","16.24009","0.14293"
"32521","195.09000","16.25761","0.14972"
"32556","195.30000","16.27513","0.14813"
"32591","195.51000","16.29265","0.15365"
"32626","195.72000","16.31017","0.15242"
"32661","195.93000","16.32756","0.15656"
"32696","196.14000","16.34514","0.15565"
"32731","196.35000","16.36266","0.16017"
"32766","196.56000","16.38012","0.16125"
"32801","196.77000","16.39764","0.16522"
"32836","196.98000","16.41510","0.16758"
"32871","197.19000","16.43262","0.17143"
"32906","197.40000","16.45013","0.17425"
"32941","197.61000","16.46759","0.17562"
"32976","197.82000","16.48517","0.17822"
"33011","198.03000","16.50263","0.17974"
"33046","198.24000","16.52015","0.18184"
"33081","198.45000","16.53766","0.18296"
"33116","198.66000","16.55512","0.18552"
"33151","198.87000","16.57264","0.18743"
"33186","199.08000","16.59016","0.19034"
"33221","199.29000","16.60762","0.19219"
"33256","199.50000","16.62520","0.19505"
"33291","199.71000","16.64253","0.19694"
"33326","199.92000","16.66017","0.19934"
"33361","200.13000","16.67763","0.20165"
"33396","200.34000","16.69515","0.20321"
"33431","200.55000","16.71261","0.20614"
"33466","200.76000","16.73013","0.20760"
"33501","200.97000","16.74771","0.21035"
"33536","201.18000","16.76516","0.21128"
"33571","201.39000","16.78262","0.21338"
"33606","201.60000","16.80014","0.21415"
"33641","201.81000","16.81760","0.21635"
"33676","202.02000","16.83512","0.21721"
"33711","202.23000","16.85264","0.22060"
"33746","202.44000","16.87009","0.22142"
"33781","202.65000","16.88761","0.22483"
"33816","202.86000","16.90507","0.22584"
"33851","203.07000","16.92265","0.22905"
"33886","203.28000","16.94017","0.22979"
"33921","203.49000","16.95763","0.23248"
"33956","203.70000","16.97509","0.23384"
"33991","203.91000","16.99261","0.23598"
"34026","204.12000","17.01012","0.23947"
"34061","204.33000","17.02770","0.24119"
"34096","204.54000","17.04504","0.24433"
"34131","204.75000","17.06268","0.21984"
"34166","204.96000","17.08014","0.22093"
"34201","205.17000","17.09759","0.22290"
"34236","205.38000","17.11517","0.22548"
"34271","205.59000","17.13257","0.22719"
"34306","205.80000","17.15021","0.22939"
"34341","206.01000","17.16761","0.23119"
"34376","206.22000","17.18513","0.23152"
"34411","206.43000","17.20264","0.11021"
"34446","206.64000","17.22010","0.10430"
"34481","206.85000","17.23768","0.10538"
"34516","207.06000","17.25520","0.11580"
"34551","207.27000","17.27260","0.11276"
"34586","207.48000","17.29018","0.11432"
"34621","207.69000","17.30764","0.12561"
"34656","207.90000","17.32509","0.11969"
"34691","208.11000","17.34267","0.12393"
"34726","208.32000","17.36001","0.13136"
"34761","208.53000","17.37765","0.12965"
"34796","208.74000","17.39511","0.13822"
"34831","208.95000","17.41262","0.12547"
"34866","209.16000","17.43008","0.12508"
"34901","209.37000","17.44766","0.13119"
"34936","209.58000","17.46512","0.13720"
"34971","209.79000","17.48264","0.13625"
"35006","210.00000","17.50016","0.14553"
"35041","210.21000","17.51761","0.14533"
"35076","210.42000","17.53513","0.15041"
"35111","210.63000","17.55265","0.15195"
"35146","210.84000","17.57011","0.15744"
"35181","211.05000","17.58763","0.15870"
"35216","211.26000","17.60515","0.16830"
"35251","211.47000","17.62255","0.16997"
"35286","211.68000","17.64018","0.17482"
"35321","211.89000","17.65764","0.17608"
"35356","212.10000","17.67510","0.17988"
"35391","212.31000","17.69262","0.18013"
"35426","212.52000","17.71014","0.18354"
"35461","212.73000","17.72766","0.18572"
"35496","212.94000","17.74517","0.18960"
"35531","213.15000","17.76257","0.19160"
"35566","213.36000","17.78015","0.19714"
"35601","213.57000","17.79767","0.17878"
"35636","213.78000","17.81507","0.10005"
"35671","213.99000","17.83265","0.10221"
"35706","214.20000","17.85011","0.10298"
"35741","214.41000","17.86762","0.10454"
"35776","214.62000","17.88508","0.10903"
"35811","214.83000","17.90266","0.10867"
"35846","215.04000","17.92012","0.11254"
"35881","215.25000","17.93764","0.11158"
"35916","215.46000","17.95516","0.11530"
"35951","215.67000","17.97267","0.11478"
"35986","215.88000","17.99007","0.11823"
"36021","216.09000","18.00765","0.11961"
"36056","216.30000","18.02511","0.12161"
"36091","216.51000","18.04263","0.12452"
"36126","216.72000","18.06009","0.12457"
"36161","216.93000","18.07749","0.12892"
"36196","217.14000","18.09518","0.12879"
"36231","217.35000","18.11264","0.13319"
"36266","217.56000","18.13010","0.13240"
"36301","217.77000","18.14768","0.13826"
"36336","217.98000","18.16508","0.14001"
"36371","218.19000","18.18271","0.14342"
"36406","218.40000","18.20017","0.14805"
"36441","218.61000","18.21763","0.13118"
"36476","218.82000","18.23515","0.13271"
"36511","219.03000","18.25261","0.13410"
"36546","219.24000","18.27013","0.13957"
"36581","219.45000","18.28765","0.13908"
"36616","219.66000","18.30510","0.14215"
"36651","219.87000","18.32268","0.14463"
"36686","220.08000","18.34008","0.14711"
"36721","220.29000","18.35766","0.14962"
"36756","220.50000","18.37518","0.15150"
"36791","220.71000","18.39264","0.15223"
"36826","220.92000","18.41009","0.15453"
"36861","221.13000","18.42761","0.15580"
"36896","221.34000","18.44513","0.15654"
"36931","221.55000","18.46265","0.15971"
"36966","221.76000","18.48011","0.15978"
"37001","221.97000","18.49763","0.16296"
"37036","222.18000","18.51514","0.16420"
"37071","222.39000","18.53260","0.16802"
"37106","222.60000","18.55018","0.07972"
"37141","222.81000","18.56758","0.05473"
"37176","223.02000","18.58516","0.00327"
"37211","223.23000","18.60262","0.00412"
"37246","223.44000","18.62013","0.04160"
"37281","223.65000","18.63765","0.00420"
"37316","223.86000","18.65511","0.00974"
"37351","224.07000","18.67263","0.03921"
"37386","224.28000","18.69015","0.00801"
"37421","224.49000","18.70761","0.01726"
"37456","224.70000","18.72512","0.02128"
"37491","224.91000","18.74258","0.01653"
"37526","225.12000","18.76010","0.02897"
"37561","225.33000","18.77762","0.01592"
"37596","225.54000","18.79508","0.01698"
"37631","225.75000","18.81260","0.02741"
"37666","225.96000","18.83018","0.01293"
"37701","226.17000","18.84757","0.02818"
"37736","226.38000","18.86509","0.02128"
"37771","226.59000","18.88261","0.02482"
"37806","226.80000","18.90013","0.02626"
"37841","227.01000","18.91765","0.02164"
"37876","227.22000","18.93505","0.03145"
"37911","227.43000","18.95263","0.02370"
"37946","227.64000","18.97008","0.02610"
"37981","227.85000","18.98760","0.03069"
"38016","228.06000","19.00512","0.02702"
"38051","228.27000","19.02258","0.02810"
"38086","228.48000","19.04016","0.03231"
"38121","228.69000","19.05755","0.03063"
"38156","228.90000","19.07519","0.03184"
"38191","229.11000","19.09265","0.03113"
"38226","229.32000","19.11011","0.03633"
"38261","229.53000","19.12763","0.03407"
"38296","229.74000","19.14509","0.03193"
"38331","229.95000","19.16266","0.04312"
"38366","230.16000","19.18018","0.03315"
"38401","230.37000","19.19752","0.03930"
"38436","230.58000","19.21516","0.04026"
"38471","230.79000","19.23262","0.03844"
"38506","231.00000","19.25014","0.03939"
"38541","231.21000","19.26766","0.04423"
"38576","231.42000","19.28511","0.04229"
"38611","231.63000","19.30269","0.04063"
"38646","231.84000","19.32009","0.04892"
"38681","232.05000","19.33761","0.04294"
"38716","232.26000","19.35513","0.04753"
"38751","232.47000","19.37265","0.04942"
"38786","232.68000","19.39010","0.04871"
"38821","232.89000","19.40762","0.04900"
"38856","233.10000","19.42508","0.05448"
"38891","233.31000","19.44266","0.05094"
"38926","233.52000","19.46012","0.05404"
"38961","233.73000","19.47764","0.05790"
"38996","233.94000","19.49515","0.05503"
"39031","234.15000","19.51249","0.06128"
"39066","234.36000","19.53013","0.06039"
"39101","234.57000","19.54765","0.06092"
"39136","234.78000","19.56511","0.06592"
"39171","234.99000","19.58263","0.06516"
"39206","235.20000","19.60009","0.06631"
"39241","235.41000","19.61760","0.07067"
"39276","235.62000","19.63512","0.06799"
"39311","235.83000","19.65258","0.07195"
"39346","236.04000","19.67016","0.07240"
"39381","236.25000","19.68762","0.07248"
"39416","236.46000","19.70514","0.07529"
"39451","236.67000","19.72259","0.07512"
"39486","236.88000","19.74011","0.07683"
"39521","237.09000","19.75763","0.08065"
"39556","237.30000","19.77509","0.07805"
"39591","237.51000","19.79267","0.08418"
"39626","237.72000","19.81013","0.08294"
"39661","237.93000","19.82764","0.08611"
"39696","238.14000","19.84510","0.08917"
"39731","238.35000","19.86262","0.08858"
"39766","238.56000","19.88014","0.09150"
"39801","238.77000","19.89766","0.09266"
"39836","238.98000","19.91506","0.09364"
"39871","239.19000","19.93263","0.09554"
"39906","239.40000","19.95015","0.09496"
"39941","239.61000","19.96761","0.09743"
"39976","239.82000","19.98513","0.09738"
"40011","240.03000","20.00259","0.09864"
"40046","240.24000","20.02022","0.09984"
"40081","240.45000","20.03762","0.10017"
"40116","240.66000","20.05508","0.10172"
"40151","240.87000","20.07266","0.10261"
"40186","241.08000","20.09006","0.10313"
"40221","241.29000","20.10764","0.10500"
"40256","241.50000","20.12516","0.10472"
"40291","241.71000","20.14261","0.10689"
"40326","241.92000","20.16014","0.10680"
"40361","242.13000","20.17765","0.10908"
"40396","242.34000","20.19511","0.11003"
"40431","242.55000","20.21263","0.05340"
"40466","242.76000","20.23003","0.05789"
"40501","242.97000","20.24766","0.05918"
"40536","243.18000","20.26513","0.05531"
"40571","243.39000","20.28264","0.04699"
"40606","243.60000","20.30010","0.04758"
"40641","243.81000","20.31762","0.04546"
"40676","244.02000","20.33514","0.04654"
"40711","244.23000","20.35266","0.04874"
"40746","244.44000","20.37011","0.04767"
"40781","244.65000","20.38763","0.04840"
"40816","244.86000","20.40509","0.05048"
"40851","245.07000","20.42267","0.04897"
"40886","245.28000","20.44007","0.05037"
"40921","245.49000","20.45758","0.05242"
"40956","245.70000","20.47517","0.05130"
"40991","245.91000","20.49256","0.05325"
"41026","246.12000","20.51014","0.05426"
"41061","246.33000","20.52766","0.05356"
"41096","246.54000","20.54506","0.05592"
"41131","246.75000","20.56264","0.05699"
"41166","246.96000","20.58010","0.05644"
"41201","247.17000","20.59761","0.05815"
"41236","247.38000","20.61519","0.05900"
"41271","247.59000","20.63253","0.05831"
"41306","247.80000","20.65017","0.06027"
"41341","248.01000","20.66763","0.06121"
"41376","248.22000","20.68509","0.06164"
"41411","248.43000","20.70266","0.06353"
"41446","248.64000","20.72012","0.06360"
"41481","248.85000","20.73764","0.06449"
"41516","249.06000","20.75510","0.06580"
"41551","249.27000","20.77262","0.06597"
"41586","249.48000","20.79014","0.06694"
"41621","249.69000","20.80759","0.06854"
"41656","249.90000","20.82517","0.06898"
"41691","250.11000","20.84263","0.06981"
"41726","250.32000","20.86009","0.07035"
"41761","250.53000","20.87761","0.07052"
"41796","250.74000","20.89513","0.07152"
"41831","250.95000","20.91265","0.07163"
"41866","251.16000","20.93016","0.07211"
"41901","251.37000","20.94756","0.07355"
"41936","251.58000","20.96514","0.07350"
"41971","251.79000","20.98260","0.07385"
"42006","252.00000","21.00011","0.07524"
"42041","252.21000","21.01758","0.07490"
"42076","252.42000","21.03515","0.07628"
"42111","252.63000","21.05261","0.07711"
"42146","252.84000","21.07013","0.07759"
"42181","253.05000","21.08759","0.07923"
"42216","253.26000","21.10511","0.07932"
"42251","253.47000","21.12257","0.08006"
"42286","253.68000","21.14014","0.08149"
"42321","253.89000","21.15760","0.08167"
"42356","254.10000","21.17512","0.08384"
"42391","254.31000","21.19264","0.08450"
"42426","254.52000","21.21010","0.08479"
"42461","254.73000","21.22762","0.08700"
"42496","254.94000","21.24513","0.08817"
"42531","255.15000","21.26265","0.08860"
"42566","255.36000","21.28011","0.09100"
"42601","255.57000","21.29763","0.09061"
"42636","255.78000","21.31515","0.09159"
"42671","255.99000","21.33267","0.03073"
"42706","256.20000","21.35007","0.03072"
"42741","256.41000","21.36764","0.01646"
"42776","256.62000","21.38510","0.00744"
"42811","256.83000","21.40262","0.01848"
"42846","257.04000","21.42020","0.02584"
"42881","257.25000","21.43760","0.00858"
"42916","257.46000","21.45512","0.01531"
"42951","257.67000","21.47263","0.02720"
"42986","257.88000","21.49009","0.01122"
"43021","258.09000","21.50767","0.01585"
"43056","258.30000","21.52513","0.02666"
"43091","258.51000","21.54259","0.01501"
"43126","258.72000","21.56017","0.01669"
"43161","258.93000","21.57756","0.02661"
"43196","259.14000","21.59514","0.01750"
"43231","259.35000","21.61260","0.01826"
"43266","259.56000","21.63012","0.02689"
"43301","259.77000","21.64764","0.01783"
"43336","259.98000","21.66504","0.02163"
"43371","260.19000","21.68267","0.02632"
"43406","260.40000","21.70013","0.02179"
"43441","260.61000","21.71759","0.02212"
"43476","260.82000","21.73511","0.02787"
"43511","261.03000","21.75263","0.02197"
"43528","261.12800","21.76076","0.02399"