File: Trajectories_together/161226_1Specimen_RawData_10.csv
"","V1","V2","V3"
"1","End date","12/26/2016",""
"2","Specimen label","13AT_3",""
"3","Maximum Load","0.34805","N"
"4","Time","Extension","Load"
"5","(s)","(mm)","(N)"
"6","0.00000","0.00000","-0.00183"
"83","0.46200","0.03886","-0.00102"
"160","0.92400","0.07725","-0.00128"
"237","1.38600","0.11563","-0.00162"
"314","1.84800","0.15420","-0.00244"
"391","2.31000","0.19270","0.00436"
"468","2.77200","0.23121","0.00427"
"545","3.23400","0.26971","0.00435"
"622","3.69600","0.30822","0.00473"
"699","4.15800","0.34672","0.00472"
"776","4.62000","0.38516","0.00478"
"853","5.08200","0.42373","0.00516"
"930","5.54400","0.46217","0.00547"
"1007","6.00600","0.50074","0.00622"
"1084","6.46800","0.53924","0.00535"
"1161","6.93000","0.57769","0.00631"
"1238","7.39200","0.61619","0.00557"
"1315","7.85400","0.65464","0.00569"
"1392","8.31600","0.69320","0.00560"
"1469","8.77800","0.73170","0.00603"
"1546","9.24000","0.77021","0.00520"
"1623","9.70200","0.80865","0.00605"
"1700","10.16400","0.84722","0.00570"
"1777","10.62600","0.88572","0.00608"
"1854","11.08800","0.92411","0.00604"
"1931","11.55000","0.96267","0.00602"
"2008","12.01200","1.00118","0.00631"
"2085","12.47400","1.03974","0.00623"
"2162","12.93600","1.07818","0.00643"
"2239","13.39800","1.11675","0.00636"
"2316","13.86000","1.15519","0.00645"
"2393","14.32200","1.19364","0.00670"
"2470","14.78400","1.23220","0.00638"
"2547","15.24600","1.27071","0.00655"
"2624","15.70800","1.30921","0.00646"
"2701","16.17000","1.34772","0.00654"
"2778","16.63200","1.38622","0.00738"
"2855","17.09400","1.42466","0.00710"
"2932","17.55600","1.46317","0.00733"
"3009","18.01800","1.50167","0.00645"
"3086","18.48000","1.54018","0.00695"
"3163","18.94200","1.57880","0.00725"
"3240","19.40400","1.61719","0.00734"
"3317","19.86600","1.65575","0.00688"
"3394","20.32800","1.69420","0.00713"
"3471","20.79000","1.73264","0.00742"
"3548","21.25200","1.77115","0.00753"
"3625","21.71400","1.80971","0.00774"
"3702","22.17600","1.84821","0.00768"
"3779","22.63800","1.88672","0.00817"
"3856","23.10000","1.92528","0.00808"
"3933","23.56200","1.96373","0.00783"
"4010","24.02400","2.00217","0.00746"
"4087","24.48600","2.04068","0.00779"
"4164","24.94800","2.07918","0.00835"
"4241","25.41000","2.11769","0.00814"
"4318","25.87200","2.15625","0.00829"
"4395","26.33400","2.19469","0.00781"
"4472","26.79600","2.23320","0.00824"
"4549","27.25800","2.27170","0.00825"
"4626","27.72000","2.31009","0.00851"
"4703","28.18200","2.34871","0.00875"
"4780","28.64400","2.38722","0.00817"
"4857","29.10600","2.42572","0.00901"
"4934","29.56800","2.46423","0.00855"
"5011","30.03000","2.50273","0.00897"
"5088","30.49200","2.54117","0.00954"
"5165","30.95400","2.57968","0.00933"
"5242","31.41600","2.61824","0.00937"
"5319","31.87800","2.65675","0.00886"
"5396","32.34000","2.69519","0.00948"
"5473","32.80200","2.73376","0.00933"
"5550","33.26400","2.77220","0.00889"
"5627","33.72600","2.81065","0.00891"
"5704","34.18800","2.84915","0.00938"
"5781","34.65000","2.88766","0.00900"
"5858","35.11200","2.92616","0.00945"
"5935","35.57400","2.96472","0.00904"
"6012","36.03600","3.00323","0.00944"
"6089","36.49800","3.04173","0.00934"
"6166","36.96000","3.08018","0.00890"
"6243","37.42200","3.11862","0.00932"
"6320","37.88400","3.15719","0.00923"
"6397","38.34600","3.19569","0.00973"
"6474","38.80800","3.23419","0.00930"
"6551","39.27000","3.27270","0.00969"
"6628","39.73200","3.31120","0.00946"
"6705","40.19400","3.34971","0.00978"
"6782","40.65600","3.38815","0.00989"
"6859","41.11800","3.42672","0.00962"
"6936","41.58000","3.46522","0.01006"
"7013","42.04200","3.50373","0.01038"
"7090","42.50400","3.54223","0.00996"
"7167","42.96600","3.58068","0.01010"
"7244","43.42800","3.61918","0.00981"
"7321","43.89000","3.65768","0.01048"
"7398","44.35200","3.69619","0.01031"
"7475","44.81400","3.73469","0.00998"
"7552","45.27600","3.77326","0.01079"
"7629","45.73800","3.81176","0.01057"
"7706","46.20000","3.85021","0.01048"
"7783","46.66200","3.88865","0.01095"
"7860","47.12400","3.92716","0.01079"
"7937","47.58600","3.96566","0.01112"
"8014","48.04800","4.00422","0.01069"
"8091","48.51000","4.04273","0.01082"
"8168","48.97200","4.08123","0.01094"
"8245","49.43400","4.11974","0.01110"
"8322","49.89600","4.15824","0.01153"
"8399","50.35800","4.19669","0.01154"
"8476","50.82000","4.23519","0.01145"
"8553","51.28200","4.27364","0.01188"
"8630","51.74400","4.31220","0.01189"
"8707","52.20600","4.35076","0.01180"
"8784","52.66800","4.38921","0.01204"
"8861","53.13000","4.42771","0.01256"
"8938","53.59200","4.46610","0.01210"
"9015","54.05400","4.50472","0.01256"
"9092","54.51600","4.54323","0.01304"
"9169","54.97800","4.58173","0.01284"
"9246","55.44000","4.62018","0.01293"
"9323","55.90200","4.65868","0.01313"
"9400","56.36400","4.69719","0.01321"
"9477","56.82600","4.73563","0.01332"
"9554","57.28800","4.77413","0.01366"
"9631","57.75000","4.81270","0.01388"
"9708","58.21200","4.85120","0.01388"
"9785","58.67400","4.88977","0.01366"
"9862","59.13600","4.92821","0.01429"
"9939","59.59800","4.96672","0.01447"
"10016","60.06000","5.00516","0.01427"
"10093","60.52200","5.04367","0.01438"
"10170","60.98400","5.08223","0.01455"
"10247","61.44600","5.12067","0.01500"
"10324","61.90800","5.15924","0.01529"
"10401","62.37000","5.19774","0.01533"
"10478","62.83200","5.23625","0.01556"
"10555","63.29400","5.27469","0.01574"
"10632","63.75600","5.31320","0.01598"
"10709","64.21800","5.35170","0.01620"
"10786","64.68000","5.39021","0.01636"
"10863","65.14200","5.42877","0.01643"
"10940","65.60400","5.46721","0.01668"
"11017","66.06600","5.50572","0.01701"
"11094","66.52800","5.54416","0.01710"
"11171","66.99000","5.58273","0.01766"
"11248","67.45200","5.62123","0.01775"
"11325","67.91400","5.65974","0.01775"
"11402","68.37600","5.69824","0.01814"
"11479","68.83800","5.73669","0.01814"
"11556","69.30000","5.77519","0.01879"
"11633","69.76200","5.81369","0.01889"
"11710","70.22400","5.85220","0.01893"
"11787","70.68600","5.89064","0.01956"
"11864","71.14800","5.92921","0.01952"
"11941","71.61000","5.96777","0.01987"
"12018","72.07200","6.00622","0.02027"
"12095","72.53400","6.04466","0.02051"
"12172","72.99600","6.08317","0.02111"
"12249","73.45800","6.12167","0.02151"
"12326","73.92000","6.16024","0.02121"
"12403","74.38200","6.19868","0.02187"
"12480","74.84400","6.23724","0.02215"
"12557","75.30600","6.27575","0.02282"
"12634","75.76800","6.31419","0.02330"
"12711","76.23000","6.35264","0.02367"
"12788","76.69200","6.39114","0.02408"
"12865","77.15400","6.42965","0.02446"
"12942","77.61600","6.46821","0.02493"
"13019","78.07800","6.50672","0.02551"
"13096","78.54000","6.54522","0.02595"
"13173","79.00200","6.58366","0.02622"
"13250","79.46400","6.62217","0.02646"
"13327","79.92600","6.66067","0.02721"
"13404","80.38800","6.69918","0.02748"
"13481","80.85000","6.73768","0.02806"
"13558","81.31200","6.77625","0.02808"
"13635","81.77400","6.81469","0.02916"
"13712","82.23600","6.85320","0.02988"
"13789","82.69800","6.89170","0.03012"
"13866","83.16000","6.93015","0.03047"
"13943","83.62200","6.96871","0.03101"
"14020","84.08400","7.00721","0.03102"
"14097","84.54600","7.04572","0.03203"
"14174","85.00800","7.08422","0.03293"
"14251","85.47000","7.12267","0.03360"
"14328","85.93200","7.16123","0.03363"
"14405","86.39400","7.19968","0.03388"
"14482","86.85600","7.23818","0.03245"
"14559","87.31800","7.27668","0.03241"
"14636","87.78000","7.31525","0.03296"
"14713","88.24200","7.35375","0.03280"
"14790","88.70400","7.39226","0.03446"
"14867","89.16600","7.43070","0.03454"
"14944","89.62800","7.46915","0.03469"
"15021","90.09000","7.50765","0.03535"
"15098","90.55200","7.54622","0.03607"
"15175","91.01400","7.58472","0.03674"
"15252","91.47600","7.62317","0.03778"
"15329","91.93800","7.66173","0.03824"
"15406","92.40000","7.70018","0.03854"
"15483","92.86200","7.73868","0.03905"
"15560","93.32400","7.77718","0.03994"
"15637","93.78600","7.81569","0.04060"
"15714","94.24800","7.85419","0.04186"
"15791","94.71000","7.89270","0.04249"
"15868","95.17200","7.93120","0.04371"
"15945","95.63400","7.96971","0.04455"
"16022","96.09600","8.00815","0.04513"
"16099","96.55800","8.04671","0.04627"
"16176","97.02000","8.08522","0.04682"
"16253","97.48200","8.12372","0.04712"
"16330","97.94400","8.16223","0.04811"
"16407","98.40600","8.20073","0.04888"
"16484","98.86800","8.23918","0.04930"
"16561","99.33000","8.27768","0.05049"
"16638","99.79200","8.31613","0.05090"
"16715","100.25400","8.35469","0.05149"
"16792","100.71600","8.39325","0.05226"
"16869","101.17800","8.43176","0.05292"
"16946","101.64000","8.47020","0.05372"
"17023","102.10200","8.50871","0.05439"
"17100","102.56400","8.54715","0.05496"
"17177","103.02600","8.58572","0.05559"
"17254","103.48800","8.62416","0.05641"
"17331","103.95000","8.66273","0.05687"
"17408","104.41200","8.70117","0.05782"
"17485","104.87400","8.73973","0.05847"
"17562","105.33600","8.77818","0.05887"
"17639","105.79800","8.81668","0.05940"
"17716","106.26000","8.85519","0.06039"
"17793","106.72200","8.89369","0.06106"
"17870","107.18400","8.93226","0.06141"
"17947","107.64600","8.97070","0.06233"
"18024","108.10800","9.00921","0.06314"
"18101","108.57000","9.04771","0.06401"
"18178","109.03200","9.08615","0.06481"
"18255","109.49400","9.12466","0.06604"
"18332","109.95600","9.16322","0.06655"
"18409","110.41800","9.20167","0.06693"
"18486","110.88000","9.24023","0.06886"
"18563","111.34200","9.27874","0.06916"
"18640","111.80400","9.31718","0.06987"
"18717","112.26600","9.35569","0.07183"
"18794","112.72800","9.39413","0.07298"
"18871","113.19000","9.43270","0.07426"
"18948","113.65200","9.47120","0.07460"
"19025","114.11400","9.50970","0.07629"
"19102","114.57600","9.54821","0.07790"
"19179","115.03800","9.58665","0.07922"
"19256","115.50000","9.62522","0.08001"
"19333","115.96200","9.66366","0.08188"
"19410","116.42400","9.70217","0.08309"
"19487","116.88600","9.74073","0.08462"
"19564","117.34800","9.77924","0.08578"
"19641","117.81000","9.81780","0.08755"
"19718","118.27200","9.85618","0.08912"
"19795","118.73400","9.89469","0.09012"
"19872","119.19600","9.93319","0.09147"
"19949","119.65800","9.97170","0.09219"
"20026","120.12000","10.01020","0.09254"
"20103","120.58200","10.04871","0.09505"
"20180","121.04400","10.08721","0.09546"
"20257","121.50600","10.12572","0.09673"
"20334","121.96800","10.16422","0.09839"
"20411","122.43000","10.20267","0.09878"
"20488","122.89200","10.24117","0.09920"
"20565","123.35400","10.27967","0.09987"
"20642","123.81600","10.31824","0.10064"
"20719","124.27800","10.35674","0.10142"
"20796","124.74000","10.39519","0.10190"
"20873","125.20200","10.43369","0.10227"
"20950","125.66400","10.47220","0.10253"
"21027","126.12600","10.51070","0.10342"
"21104","126.58800","10.54920","0.10395"
"21181","127.05000","10.58771","0.10396"
"21258","127.51200","10.62621","0.10462"
"21335","127.97400","10.66472","0.10500"
"21412","128.43600","10.70316","0.10551"
"21489","128.89800","10.74167","0.10587"
"21566","129.36000","10.78017","0.10594"
"21643","129.82200","10.81868","0.10664"
"21720","130.28400","10.85718","0.10679"
"21797","130.74600","10.89575","0.10702"
"21874","131.20800","10.93425","0.10746"
"21951","131.67000","10.97269","0.10758"
"22028","132.13200","11.01114","0.10802"
"22105","132.59400","11.04970","0.10882"
"22182","133.05600","11.08821","0.10903"
"22259","133.51800","11.12671","0.10968"
"22336","133.98000","11.16522","0.11039"
"22413","134.44200","11.20366","0.11082"
"22490","134.90400","11.24217","0.11175"
"22567","135.36600","11.28061","0.11213"
"22644","135.82800","11.31917","0.11259"
"22721","136.29000","11.35774","0.11283"
"22798","136.75200","11.39618","0.11417"
"22875","137.21400","11.43469","0.11378"
"22952","137.67600","11.47319","0.11484"
"23029","138.13800","11.51170","0.11518"
"23106","138.60000","11.55020","0.00054"
"23183","139.06200","11.58871","0.00695"
"23260","139.52400","11.62721","0.00772"
"23337","139.98600","11.66572","0.00700"
"23414","140.44800","11.70422","0.00599"
"23491","140.91000","11.74272","0.00727"
"23568","141.37200","11.78117","0.00751"
"23645","141.83400","11.81967","0.00662"
"23722","142.29600","11.85818","0.00597"
"23799","142.75800","11.89668","0.00662"
"23876","143.22000","11.93525","0.00786"
"23953","143.68200","11.97369","0.00769"
"24030","144.14400","12.01219","0.00752"
"24107","144.60600","12.05070","0.00601"
"24184","145.06800","12.08920","0.00628"
"24261","145.53000","12.12765","0.00772"
"24338","145.99200","12.16615","0.00756"
"24415","146.45400","12.20472","0.00805"
"24492","146.91600","12.24322","0.00745"
"24569","147.37800","12.28179","0.00714"
"24646","147.84000","12.32017","0.00678"
"24723","148.30200","12.35861","0.00768"
"24800","148.76400","12.39718","0.00749"
"24877","149.22600","12.43575","0.00783"
"24954","149.68800","12.47419","0.00735"
"25031","150.15000","12.51269","0.00682"
"25108","150.61200","12.55120","0.00722"
"25185","151.07400","12.58970","0.00771"
"25262","151.53600","12.62821","0.00809"
"25339","151.99800","12.66665","0.00803"
"25416","152.46000","12.70516","0.00757"
"25493","152.92200","12.74372","0.00742"
"25570","153.38400","12.78223","0.00754"
"25647","153.84600","12.82079","0.00807"
"25724","154.30800","12.85917","0.00809"
"25801","154.77000","12.89768","0.00762"
"25878","155.23200","12.93612","0.00805"
"25955","155.69400","12.97469","0.00779"
"26032","156.15600","13.01319","0.00771"
"26109","156.61800","13.05170","0.00804"
"26186","157.08000","13.09026","0.00844"
"26263","157.54200","13.12871","0.00815"
"26340","158.00400","13.16721","0.00856"
"26417","158.46600","13.20566","0.00859"
"26494","158.92800","13.24416","0.00836"
"26571","159.39000","13.28272","0.00819"
"26648","159.85200","13.32129","0.00846"
"26725","160.31400","13.35967","0.00869"
"26802","160.77600","13.39818","0.00879"
"26879","161.23800","13.43668","0.00833"
"26956","161.70000","13.47525","0.00900"
"27033","162.16200","13.51369","0.00894"
"27110","162.62400","13.55220","0.00930"
"27187","163.08600","13.59070","0.00936"
"27264","163.54800","13.62920","0.00895"
"27341","164.01000","13.66777","0.00947"
"27418","164.47200","13.70621","0.00934"
"27495","164.93400","13.74466","0.00950"
"27572","165.39600","13.78316","0.00965"
"27649","165.85800","13.82173","0.00956"
"27726","166.32000","13.86023","0.00987"
"27803","166.78200","13.89873","0.00982"
"27880","167.24400","13.93718","0.01027"
"27957","167.70600","13.97562","0.01041"
"28034","168.16800","14.01419","0.01047"
"28111","168.63000","14.05269","0.01037"
"28188","169.09200","14.09120","0.01040"
"28265","169.55400","14.12970","0.01054"
"28342","170.01600","14.16821","0.01043"
"28419","170.47800","14.20671","0.01074"
"28496","170.94000","14.24522","0.01113"
"28573","171.40200","14.28366","0.01102"
"28650","171.86400","14.32216","0.01173"
"28727","172.32600","14.36079","0.01208"
"28804","172.78800","14.39923","0.01206"
"28881","173.25000","14.43768","0.01234"
"28958","173.71200","14.47618","0.01232"
"29035","174.17400","14.51469","0.01239"
"29112","174.63600","14.55313","0.01278"
"29189","175.09800","14.59164","0.01286"
"29266","175.56000","14.63020","0.01303"
"29343","176.02200","14.66876","0.01331"
"29420","176.48400","14.70727","0.01327"
"29497","176.94600","14.74571","0.01373"
"29574","177.40800","14.78416","0.01412"
"29651","177.87000","14.82266","0.01422"
"29728","178.33200","14.86117","0.01491"
"29805","178.79400","14.89973","0.01522"
"29882","179.25600","14.93824","0.01551"
"29959","179.71800","14.97668","0.01584"
"30036","180.18000","15.01518","0.01662"
"30113","180.64200","15.05369","0.01708"
"30190","181.10400","15.09213","0.01727"
"30267","181.56600","15.13070","0.01808"
"30344","182.02800","15.16920","0.01881"
"30421","182.49000","15.20777","0.01921"
"30498","182.95200","15.24627","0.01986"
"30575","183.41400","15.28472","0.02095"
"30652","183.87600","15.32316","0.02207"
"30729","184.33800","15.36161","0.02286"
"30806","184.80000","15.40023","0.02398"
"30883","185.26200","15.43874","0.02509"
"30960","185.72400","15.47724","0.02638"
"31037","186.18600","15.51568","0.02787"
"31114","186.64800","15.55419","0.02938"
"31191","187.11000","15.59269","0.03092"
"31268","187.57200","15.63120","0.03239"
"31345","188.03400","15.66964","0.03446"
"31422","188.49600","15.70815","0.03555"
"31499","188.95800","15.74671","0.03788"
"31576","189.42000","15.78521","0.04034"
"31653","189.88200","15.82378","0.04257"
"31730","190.34400","15.86222","0.04449"
"31807","190.80600","15.90061","0.04663"
"31884","191.26800","15.93917","0.04867"
"31961","191.73000","15.97774","0.05017"
"32038","192.19200","16.01618","0.05197"
"32115","192.65400","16.05475","0.05415"
"32192","193.11600","16.09319","0.05576"
"32269","193.57800","16.13169","0.05749"
"32346","194.04000","16.17014","0.05880"
"32423","194.50200","16.20870","0.06081"
"32500","194.96400","16.24715","0.06217"
"32577","195.42600","16.28571","0.06434"
"32654","195.88800","16.32422","0.06642"
"32731","196.35000","16.36272","0.06937"
"32808","196.81200","16.40117","0.07176"
"32885","197.27400","16.43967","0.07433"
"32962","197.73600","16.47818","0.07764"
"33039","198.19800","16.51668","0.08091"
"33116","198.66000","16.55524","0.08482"
"33193","199.12200","16.59375","0.08816"
"33270","199.58400","16.63225","0.09001"
"33347","200.04600","16.67076","0.09285"
"33424","200.50800","16.70914","0.09518"
"33501","200.97000","16.74765","0.09682"
"33578","201.43200","16.78615","0.09851"
"33655","201.89400","16.82477","0.09920"
"33732","202.35600","16.86322","0.10074"
"33809","202.81800","16.90172","0.10163"
"33886","203.28000","16.94017","0.10266"
"33963","203.74200","16.97867","0.10387"
"34040","204.20400","17.01718","0.10445"
"34117","204.66600","17.05574","0.10553"
"34194","205.12800","17.09418","0.10636"
"34271","205.59000","17.13269","0.10749"
"34348","206.05200","17.17126","0.10806"
"34425","206.51400","17.20970","0.10961"
"34502","206.97600","17.24820","0.11117"
"34579","207.43800","17.28665","0.11284"
"34656","207.90000","17.32515","0.11440"
"34733","208.36200","17.36378","0.11623"
"34810","208.82400","17.40222","0.11924"
"34887","209.28600","17.44073","0.12191"
"34964","209.74800","17.47917","0.12443"
"35041","210.21000","17.51768","0.12776"
"35118","210.67200","17.55618","0.13118"
"35195","211.13400","17.59468","0.13472"
"35272","211.59600","17.63325","0.13894"
"35349","212.05800","17.67169","0.14283"
"35426","212.52000","17.71026","0.14714"
"35503","212.98200","17.74864","0.15100"
"35580","213.44400","17.78715","0.15388"
"35657","213.90600","17.82565","0.15683"
"35734","214.36800","17.86416","0.15915"
"35811","214.83000","17.90272","0.16246"
"35888","215.29200","17.94123","0.16456"
"35965","215.75400","17.97973","0.16613"
"36042","216.21600","18.01823","0.16760"
"36119","216.67800","18.05668","0.16972"
"36196","217.14000","18.09518","0.02736"
"36273","217.60200","18.13369","0.01327"
"36350","218.06400","18.17219","0.00795"
"36427","218.52600","18.21076","0.00687"
"36504","218.98800","18.24920","0.01072"
"36581","219.45000","18.28770","0.01464"
"36658","219.91200","18.32621","0.01408"
"36735","220.37400","18.36465","0.01381"
"36812","220.83600","18.40322","0.01377"
"36889","221.29800","18.44172","0.01540"
"36966","221.76000","18.48023","0.01518"
"37043","222.22200","18.51867","0.01424"
"37120","222.68400","18.55724","0.01249"
"37197","223.14600","18.59568","0.01127"
"37274","223.60800","18.63419","0.01164"
"37351","224.07000","18.67263","0.01323"
"37428","224.53200","18.71119","0.01421"
"37505","224.99400","18.74970","0.01378"
"37582","225.45600","18.78820","0.01425"
"37659","225.91800","18.82683","0.01436"
"37736","226.38000","18.86515","0.01535"
"37813","226.84200","18.90366","0.01490"
"37890","227.30400","18.94210","0.01394"
"37967","227.76600","18.98072","0.01309"
"38044","228.22800","19.01923","0.01340"
"38121","228.69000","19.05773","0.01426"
"38198","229.15200","19.09624","0.01554"
"38275","229.61400","19.13468","0.01614"
"38352","230.07600","19.17313","0.01523"
"38429","230.53800","19.21163","0.01460"
"38506","231.00000","19.25020","0.01470"
"38583","231.46200","19.28870","0.01547"
"38660","231.92400","19.32721","0.01568"
"38737","232.38600","19.36571","0.01562"
"38814","232.84800","19.40421","0.01562"
"38891","233.31000","19.44266","0.01611"
"38968","233.77200","19.48116","0.01644"
"39045","234.23400","19.51973","0.01661"
"39122","234.69600","19.55823","0.01649"
"39199","235.15800","19.59674","0.01677"
"39276","235.62000","19.63524","0.01663"
"39353","236.08200","19.67369","0.01751"
"39430","236.54400","19.71213","0.01760"
"39507","237.00600","19.75064","0.01765"
"39584","237.46800","19.78926","0.01806"
"39661","237.93000","19.82771","0.01836"
"39738","238.39200","19.86621","0.01840"
"39815","238.85400","19.90471","0.01911"
"39892","239.31600","19.94321","0.01928"
"39969","239.77800","19.98172","0.02019"
"40046","240.24000","20.02017","0.01976"
"40123","240.70200","20.05867","0.01950"
"40200","241.16400","20.09723","0.02041"
"40277","241.62600","20.13574","0.02195"
"40354","242.08800","20.17424","0.02257"
"40431","242.55000","20.21269","0.02227"
"40508","243.01200","20.25113","0.02278"
"40585","243.47400","20.28970","0.02332"
"40662","243.93600","20.32820","0.02345"
"40739","244.39800","20.36670","0.02502"
"40816","244.86000","20.40521","0.02593"
"40893","245.32200","20.44372","0.02595"
"40970","245.78400","20.48222","0.02670"
"41047","246.24600","20.52066","0.02753"
"41124","246.70800","20.55917","0.02806"
"41201","247.17000","20.59767","0.03000"
"41278","247.63200","20.63618","0.03037"
"41355","248.09400","20.67474","0.03158"
"41432","248.55600","20.71325","0.03197"
"41509","249.01800","20.75169","0.03299"
"41586","249.48000","20.79014","0.03558"
"41663","249.94200","20.82864","0.03568"
"41740","250.40400","20.86720","0.03736"
"41817","250.86600","20.90571","0.03828"
"41894","251.32800","20.94421","0.04070"
"41971","251.79000","20.98272","0.04126"
"42048","252.25200","21.02122","0.04264"
"42125","252.71400","21.05967","0.04461"
"42202","253.17600","21.09811","0.04691"
"42279","253.63800","21.13667","0.04807"
"42356","254.10000","21.17524","0.04850"
"42433","254.56200","21.21374","0.05070"
"42510","255.02400","21.25219","0.05199"
"42587","255.48600","21.29075","0.05468"
"42664","255.94800","21.32920","0.05547"
"42741","256.41000","21.36770","0.05583"
"42818","256.87200","21.40621","0.05724"
"42895","257.33400","21.44465","0.05886"
"42972","257.79600","21.48322","0.06107"
"43049","258.25800","21.52172","0.06192"
"43126","258.72000","21.56023","0.06390"
"43203","259.18200","21.59867","0.06423"
"43280","259.64400","21.63712","0.06517"
"43357","260.10600","21.67568","0.06753"
"43434","260.56800","21.71424","0.07042"
"43511","261.03000","21.75275","0.07287"
"43588","261.49200","21.79119","0.07583"
"43665","261.95400","21.82964","0.07696"
"43742","262.41600","21.86814","0.07918"
"43819","262.87800","21.90665","0.08037"
"43896","263.34000","21.94515","0.08264"
"43973","263.80200","21.98371","0.08555"
"44050","264.26400","22.02222","0.08750"
"44127","264.72600","22.06072","0.09040"
"44204","265.18800","22.09917","0.09203"
"44281","265.65000","22.13761","0.09335"
"44358","266.11200","22.17612","0.09488"
"44435","266.57400","22.21462","0.09620"
"44512","267.03600","22.25325","0.09821"
"44589","267.49800","22.29175","0.09938"
"44666","267.96000","22.33019","0.10064"
"44743","268.42200","22.36870","0.10165"
"44820","268.88400","22.40720","0.10263"
"44897","269.34600","22.44565","0.10389"
"44974","269.80800","22.48421","0.10485"
"45051","270.27000","22.52266","0.10547"
"45128","270.73200","22.56122","0.10635"
"45205","271.19400","22.59973","0.10723"
"45282","271.65600","22.63823","0.10795"
"45359","272.11800","22.67668","0.10954"
"45436","272.58000","22.71512","0.11134"
"45513","273.04200","22.75368","0.11367"
"45590","273.50400","22.79219","0.11602"
"45667","273.96600","22.83069","0.11822"
"45744","274.42800","22.86920","0.12128"
"45821","274.89000","22.90770","0.12482"
"45898","275.35200","22.94621","0.12820"
"45975","275.81400","22.98465","0.13240"
"46052","276.27600","23.02316","0.13634"
"46129","276.73800","23.06172","0.14218"
"46206","277.20000","23.10023","0.14738"
"46283","277.66200","23.13873","0.15159"
"46360","278.12400","23.17723","0.15505"
"46437","278.58600","23.21568","0.15879"
"46514","279.04800","23.25412","0.16156"
"46591","279.51000","23.29269","0.16450"
"46668","279.97200","23.33119","0.16637"
"46745","280.43400","23.36975","0.16879"
"46822","280.89600","23.40814","0.17032"
"46899","281.35800","23.44670","0.17315"
"46976","281.82000","23.48521","0.17538"
"47053","282.28200","23.52371","0.17771"
"47130","282.74400","23.56222","0.18043"
"47207","283.20600","23.60066","0.18432"
"47284","283.66800","23.63923","0.18818"
"47361","284.13000","23.67767","0.19040"
"47438","284.59200","23.71624","0.19398"
"47515","285.05400","23.75468","0.19739"
"47592","285.51600","23.79312","0.19978"
"47669","285.97800","23.83163","0.20209"
"47746","286.44000","23.87019","0.20454"
"47823","286.90200","23.90870","0.20701"
"47900","287.36400","23.94720","0.20913"
"47977","287.82600","23.98571","0.21095"
"48054","288.28800","24.02421","0.21279"
"48131","288.75000","24.06266","0.21454"
"48208","289.21200","24.10116","0.21599"
"48285","289.67400","24.13972","0.21744"
"48362","290.13600","24.17823","0.21982"
"48439","290.59800","24.21667","0.22191"
"48516","291.06000","24.25518","0.22470"
"48593","291.52200","24.29368","0.22786"
"48670","291.98400","24.33219","0.23099"
"48747","292.44600","24.37075","0.23376"
"48824","292.90800","24.40920","0.23613"
"48901","293.37000","24.44770","0.23889"
"48978","293.83200","24.48620","0.24173"
"49055","294.29400","24.52471","0.24446"
"49132","294.75600","24.56321","0.24668"
"49209","295.21800","24.60166","0.24890"
"49286","295.68000","24.64017","0.25091"
"49363","296.14200","24.67867","0.25299"
"49440","296.60400","24.71723","0.25456"
"49517","297.06600","24.75574","0.25578"
"49594","297.52800","24.79418","0.25763"
"49671","297.99000","24.83269","0.25868"
"49748","298.45200","24.87119","0.26014"
"49825","298.91400","24.90969","0.26171"
"49902","299.37600","24.94820","0.26429"
"49979","299.83800","24.98676","0.26565"
"50056","300.30000","25.02521","0.26890"
"50133","300.76200","25.06371","0.27260"
"50210","301.22400","25.10222","0.27652"
"50287","301.68600","25.14066","0.28052"
"50364","302.14800","25.17916","0.28641"
"50441","302.61000","25.21767","0.29076"
"50518","303.07200","25.25624","0.29578"
"50595","303.53400","25.29474","0.30069"
"50672","303.99600","25.33324","0.30440"
"50749","304.45800","25.37169","0.26892"
"50826","304.92000","25.41019","0.25972"
"50903","305.38200","25.44864","0.25724"
"50980","305.84400","25.48714","0.06082"
"51057","306.30600","25.52571","0.05881"
"51134","306.76800","25.56421","0.05919"
"51211","307.23000","25.60272","0.06478"
"51288","307.69200","25.64122","0.06637"
"51365","308.15400","25.67966","0.06220"
"51442","308.61600","25.71817","0.05782"
"51519","309.07800","25.75667","0.05825"
"51596","309.54000","25.79524","0.06653"
"51673","310.00200","25.83368","0.07486"
"51750","310.46400","25.87219","0.07085"
"51827","310.92600","25.91075","0.06465"
"51904","311.38800","25.94920","0.06416"
"51981","311.85000","25.98764","0.07021"
"52058","312.31200","26.02621","0.07728"
"52135","312.77400","26.06471","0.07596"
"52212","313.23600","26.10321","0.07276"
"52289","313.69800","26.14172","0.07398"
"52366","314.16000","26.18022","0.07898"
"52443","314.62200","26.21867","0.08479"
"52520","315.08400","26.25717","0.08553"
"52597","315.54600","26.29568","0.08276"
"52674","316.00800","26.33418","0.07980"
"52751","316.47000","26.37269","0.08163"
"52828","316.93200","26.41119","0.08637"
"52905","317.39400","26.44975","0.09103"
"52982","317.85600","26.48820","0.09265"
"53059","318.31800","26.52670","0.09142"
"53136","318.78000","26.56515","0.09073"
"53213","319.24200","26.60371","0.09163"
"53290","319.70400","26.64221","0.09472"
"53367","320.16600","26.68072","0.09747"
"53444","320.62800","26.71922","0.09841"
"53521","321.09000","26.75767","0.09808"
"53598","321.55200","26.79617","0.09808"
"53675","322.01400","26.83468","0.09801"
"53752","322.47600","26.87318","0.09897"
"53829","322.93800","26.91175","0.10032"
"53906","323.40000","26.95019","0.10172"
"53983","323.86200","26.98870","0.10275"
"54060","324.32400","27.02720","0.10282"
"54137","324.78600","27.06565","0.10293"
"54214","325.24800","27.10421","0.10306"
"54291","325.71000","27.14272","0.10360"
"54368","326.17200","27.18122","0.10429"
"54445","326.63400","27.21972","0.10508"
"54522","327.09600","27.25817","0.10599"
"54599","327.55800","27.29673","0.10614"
"54676","328.02000","27.33518","0.10657"
"54753","328.48200","27.37362","0.10652"
"54830","328.94400","27.41219","0.10689"
"54907","329.40600","27.45069","0.10693"
"54984","329.86800","27.48925","0.10761"
"55061","330.33000","27.52770","0.10818"
"55138","330.79200","27.56614","0.10888"
"55215","331.25400","27.60465","0.10940"
"55292","331.71600","27.64321","0.11040"
"55369","332.17800","27.68172","0.11111"
"55446","332.64000","27.72028","0.11160"
"55523","333.10200","27.75872","0.11206"
"55600","333.56400","27.79723","0.11307"
"55677","334.02600","27.83568","0.11413"
"55754","334.48800","27.87412","0.11583"
"55831","334.95000","27.91269","0.11711"
"55908","335.41200","27.95119","0.11815"
"55985","335.87400","27.98969","0.12059"
"56062","336.33600","28.02826","0.12204"
"56139","336.79800","28.06676","0.12382"
"56216","337.26000","28.10521","0.12461"
"56293","337.72200","28.14359","0.12619"
"56370","338.18400","28.18216","0.12815"
"56447","338.64600","28.22072","0.12916"
"56524","339.10800","28.25922","0.13073"
"56601","339.57000","28.29773","0.13225"
"56678","340.03200","28.33617","0.13488"
"56755","340.49400","28.37468","0.13692"
"56832","340.95600","28.41318","0.13896"
"56909","341.41800","28.45163","0.14050"
"56986","341.88000","28.49019","0.14424"
"57063","342.34200","28.52869","0.14584"
"57140","342.80400","28.56726","0.14746"
"57217","343.26600","28.60576","0.15010"
"57294","343.72800","28.64421","0.15192"
"57371","344.19000","28.68265","0.15395"
"57448","344.65200","28.72116","0.15527"
"57525","345.11400","28.75972","0.15670"
"57602","345.57600","28.79817","0.15873"
"57679","346.03800","28.83673","0.16028"
"57756","346.50000","28.87524","0.16118"
"57833","346.96200","28.91374","0.16257"
"57910","347.42400","28.95218","0.16383"
"57987","347.88600","28.99063","0.16525"
"58064","348.34800","29.02919","0.16595"
"58141","348.81000","29.06770","0.16650"
"58218","349.27200","29.10626","0.16713"
"58295","349.73400","29.14465","0.16805"
"58372","350.19600","29.18321","0.16944"
"58449","350.65800","29.22166","0.17002"
"58526","351.12000","29.26016","0.17162"
"58603","351.58200","29.29873","0.17251"
"58680","352.04400","29.33717","0.17376"
"58757","352.50600","29.37574","0.17456"
"58834","352.96800","29.41424","0.17528"
"58911","353.43000","29.45274","0.17668"
"58988","353.89200","29.49119","0.17814"
"59065","354.35400","29.52957","0.17983"
"59142","354.81600","29.56814","0.18104"
"59219","355.27800","29.60676","0.18218"
"59296","355.74000","29.64521","0.18367"
"59373","356.20200","29.68371","0.18559"
"59450","356.66400","29.72221","0.18722"
"59527","357.12600","29.76066","0.18796"
"59604","357.58800","29.79922","0.19024"
"59681","358.05000","29.83761","0.19147"
"59758","358.51200","29.87623","0.19313"
"59835","358.97400","29.91468","0.19450"
"59912","359.43600","29.95324","0.19652"
"59989","359.89800","29.99169","0.19730"
"60066","360.36000","30.03019","0.19897"
"60143","360.82200","30.06863","0.20005"
"60220","361.28400","30.10720","0.20147"
"60297","361.74600","30.14576","0.20259"
"60374","362.20800","30.18427","0.20370"
"60451","362.67000","30.22271","0.20457"
"60528","363.13200","30.26122","0.20562"
"60605","363.59400","30.29972","0.20704"
"60682","364.05600","30.33817","0.20807"
"60759","364.51800","30.37667","0.20880"
"60836","364.98000","30.41518","0.20973"
"60913","365.44200","30.45374","0.21062"
"60990","365.90400","30.49224","0.21126"
"61067","366.36600","30.53075","0.21219"
"61144","366.82800","30.56919","0.21251"
"61221","367.29000","30.60758","0.21323"
"61298","367.75200","30.64620","0.21427"
"61375","368.21400","30.68471","0.21517"
"61452","368.67600","30.72321","0.21563"
"61529","369.13800","30.76171","0.21616"
"61606","369.60000","30.80022","0.21706"
"61683","370.06200","30.83873","0.21803"
"61760","370.52400","30.87717","0.21881"
"61837","370.98600","30.91567","0.21933"
"61914","371.44800","30.95418","0.22066"
"61991","371.91000","30.99274","0.22149"
"62068","372.37200","31.03125","0.22293"
"62145","372.83400","31.06975","0.22395"
"62222","373.29600","31.10814","0.22536"
"62299","373.75800","31.14664","0.22648"
"62376","374.22000","31.18521","0.22809"
"62453","374.68200","31.22371","0.22925"
"62530","375.14400","31.26221","0.23056"
"62607","375.60600","31.30072","0.23240"
"62684","376.06800","31.33922","0.23343"
"62761","376.53000","31.37773","0.23482"
"62838","376.99200","31.41617","0.23645"
"62915","377.45400","31.45468","0.23751"
"62992","377.91600","31.49318","0.23863"
"63069","378.37800","31.53168","0.23951"
"63146","378.84000","31.57025","0.24070"
"63223","379.30200","31.60875","0.24304"
"63300","379.76400","31.64720","0.24414"
"63377","380.22600","31.68564","0.24507"
"63454","380.68800","31.72421","0.24689"
"63531","381.15000","31.76271","0.24824"
"63608","381.61200","31.80122","0.24920"
"63685","382.07400","31.83972","0.24996"
"63762","382.53600","31.87823","0.25128"
"63839","382.99800","31.91667","0.25221"
"63916","383.46000","31.95517","0.25387"
"63993","383.92200","31.99362","0.25436"
"64070","384.38400","32.03218","0.25557"
"64147","384.84600","32.07069","0.25597"
"64224","385.30800","32.10919","0.25719"
"64301","385.77000","32.14769","0.25839"
"64378","386.23200","32.18620","0.25920"
"64455","386.69400","32.22470","0.26051"
"64532","387.15600","32.26315","0.26175"
"64609","387.61800","32.30171","0.26240"
"64686","388.08000","32.34022","0.26266"
"64763","388.54200","32.37872","0.26404"
"64840","389.00400","32.41722","0.26534"
"64917","389.46600","32.45573","0.26666"
"64994","389.92800","32.49412","0.26759"
"65071","390.39000","32.53262","0.26858"
"65148","390.85200","32.57119","0.26981"
"65225","391.31400","32.60975","0.27239"
"65302","391.77600","32.64825","0.27409"
"65379","392.23800","32.68670","0.27535"
"65456","392.70000","32.72520","0.27738"
"65533","393.16200","32.76371","0.27914"
"65610","393.62400","32.80221","0.28032"
"65687","394.08600","32.84072","0.28245"
"65764","394.54800","32.87916","0.28374"
"65841","395.01000","32.91766","0.28662"
"65918","395.47200","32.95623","0.28808"
"65995","395.93400","32.99467","0.28951"
"66072","396.39600","33.03318","0.29250"
"66149","396.85800","33.07168","0.29347"
"66226","397.32000","33.11019","0.29498"
"66303","397.78200","33.14875","0.29718"
"66380","398.24400","33.18719","0.29906"
"66457","398.70600","33.22570","0.30044"
"66534","399.16800","33.26414","0.30162"
"66611","399.63000","33.30271","0.30312"
"66688","400.09200","33.34116","0.30454"
"66765","400.55400","33.37972","0.30589"
"66842","401.01600","33.41816","0.30676"
"66919","401.47800","33.45673","0.30784"
"66996","401.94000","33.49523","0.30955"
"67073","402.40200","33.53374","0.31004"
"67150","402.86400","33.57218","0.31108"
"67227","403.32600","33.61063","0.31240"
"67304","403.78800","33.64919","0.31315"
"67381","404.25000","33.68769","0.31371"
"67458","404.71200","33.72626","0.31481"
"67535","405.17400","33.76471","0.31512"
"67612","405.63600","33.80321","0.31610"
"67689","406.09800","33.84171","0.31673"
"67766","406.56000","33.88010","0.31738"
"67843","407.02200","33.91866","0.31788"
"67920","407.48400","33.95723","0.31867"
"67997","407.94600","33.99573","0.31892"
"68074","408.40800","34.03423","0.31939"
"68151","408.87000","34.07274","0.31968"
"68228","409.33200","34.11112","0.31993"
"68305","409.79400","34.14969","0.32002"
"68382","410.25600","34.18819","0.32020"
"68459","410.71800","34.22670","0.32050"
"68536","411.18000","34.26520","0.32062"
"68613","411.64200","34.30376","0.32074"
"68690","412.10400","34.34221","0.32085"
"68767","412.56600","34.38066","0.32102"
"68844","413.02800","34.41916","0.32101"
"68921","413.49000","34.45766","0.32106"
"68998","413.95200","34.49623","0.32159"
"69075","414.41400","34.53473","0.32163"
"69152","414.87600","34.57324","0.32178"
"69229","415.33800","34.61174","0.32191"
"69306","415.80000","34.65019","0.32220"
"69383","416.26200","34.68869","0.32246"
"69460","416.72400","34.72714","0.32286"
"69537","417.18600","34.76570","0.32278"
"69614","417.64800","34.80420","0.32326"
"69691","418.11000","34.84271","0.32345"
"69768","418.57200","34.88121","0.32379"
"69845","419.03400","34.91972","0.32421"
"69922","419.49600","34.95816","0.32443"
"69999","419.95800","34.99673","0.32525"
"70076","420.42000","35.03523","0.32528"
"70153","420.88200","35.07368","0.32599"
"70230","421.34400","35.11224","0.32682"
"70307","421.80600","35.15068","0.32731"
"70384","422.26800","35.18925","0.32829"
"70461","422.73000","35.22770","0.32841"
"70538","423.19200","35.26614","0.32945"
"70615","423.65400","35.30470","0.32991"
"70692","424.11600","35.34321","0.33104"
"70769","424.57800","35.38171","0.33155"
"70846","425.04000","35.42022","0.33190"
"70923","425.50200","35.45866","0.33249"
"71000","425.96400","35.49711","0.33315"
"71077","426.42600","35.53567","0.33382"
"71154","426.88800","35.57423","0.33437"
"71231","427.35000","35.61274","0.33548"
"71308","427.81200","35.65118","0.33591"
"71385","428.27400","35.68975","0.33677"
"71462","428.73600","35.72820","0.33710"
"71539","429.19800","35.76669","0.33731"
"71616","429.66000","35.80520","0.33859"
"71693","430.12200","35.84364","0.33936"
"71770","430.58400","35.88221","0.33989"
"71847","431.04600","35.92071","0.34116"
"71924","431.50800","35.95922","0.34405"
"72001","431.97000","35.99766","0.34483"
"72078","432.43200","36.03617","0.34487"
"72155","432.89400","36.07467","0.34687"
"72232","433.35600","36.11324","0.34731"
"72309","433.81800","36.15168","0.00453"
"72386","434.28000","36.19025","0.00649"
"72463","434.74200","36.22869","0.00619"
"72540","435.20400","36.26725","0.00715"
"72617","435.66600","36.30570","0.00740"
"72694","436.12800","36.34414","0.00625"
"72771","436.59000","36.38271","0.01278"
"72848","437.05200","36.42122","0.00638"
"72925","437.51400","36.45978","0.00908"
"73002","437.97600","36.49828","0.00940"
"73079","438.43800","36.53673","0.00627"
"73156","438.90000","36.57517","0.00916"
"73233","439.36200","36.61368","0.00974"
"73310","439.82400","36.65224","0.00783"
"73387","440.28600","36.69075","0.00796"
"73464","440.74800","36.72925","0.00961"
"73541","441.21000","36.76775","0.00886"
"73618","441.67200","36.80619","0.00759"
"73695","442.13400","36.84464","0.00889"
"73772","442.59600","36.88314","0.00902"
"73849","443.05800","36.92165","0.00875"
"73926","443.52000","36.96021","0.00845"
"74003","443.98200","36.99872","0.00897"
"74080","444.44400","37.03722","0.00929"
"74157","444.90600","37.07573","0.00858"
"74234","445.36800","37.11417","0.00912"
"74311","445.83000","37.15268","0.00937"
"74388","446.29200","37.19118","0.00967"
"74465","446.75400","37.22969","0.00904"
"74542","447.21600","37.26819","0.00845"
"74619","447.67800","37.30676","0.00924"
"74696","448.14000","37.34526","0.00961"
"74773","448.60200","37.38371","0.00921"
"74850","449.06400","37.42215","0.00866"
"74927","449.52600","37.46072","0.00984"
"75004","449.98800","37.49922","0.00976"
"75081","450.45000","37.53772","0.00875"
"75158","450.91200","37.57623","0.00904"
"75235","451.37400","37.61467","0.01022"
"75312","451.83600","37.65318","0.00988"
"75389","452.29800","37.69168","0.00955"
"75466","452.76000","37.73018","0.00918"
"75543","453.22200","37.76869","0.00968"
"75620","453.68400","37.80719","0.00995"
"75697","454.14600","37.84576","0.00981"
"75774","454.60800","37.88426","0.00972"
"75851","455.07000","37.92265","0.01000"
"75928","455.53200","37.96115","0.01025"
"76005","455.99400","37.99971","0.00946"
"76082","456.45600","38.03822","0.00971"
"76159","456.91800","38.07673","0.01049"
"76236","457.38000","38.11523","0.01064"
"76313","457.84200","38.15368","0.01072"
"76390","458.30400","38.19224","0.01024"
"76467","458.76600","38.23068","0.01035"
"76544","459.22800","38.26913","0.01041"
"76621","459.69000","38.30769","0.01063"
"76698","460.15200","38.34626","0.01030"
"76775","460.61400","38.38470","0.01074"
"76852","461.07600","38.42321","0.01081"
"76929","461.53800","38.46165","0.01032"
"77006","462.00000","38.50010","0.01010"
"77083","462.46200","38.53872","0.01075"
"77160","462.92400","38.57722","0.01086"
"77237","463.38600","38.61573","0.01131"
"77314","463.84800","38.65417","0.01160"
"77391","464.31000","38.69268","0.01122"
"77468","464.77200","38.73118","0.01115"
"77545","465.23400","38.76963","0.01127"
"77622","465.69600","38.80819","0.01118"
"77699","466.15800","38.84669","0.01215"
"77776","466.62000","38.88520","0.01174"
"77853","467.08200","38.92376","0.01176"
"77930","467.54400","38.96227","0.01137"
"78007","468.00600","39.00071","0.01154"
"78084","468.46800","39.03916","0.01157"
"78161","468.93000","39.07766","0.01131"
"78238","469.39200","39.11622","0.01193"
"78315","469.85400","39.15473","0.01133"
"78392","470.31600","39.19318","0.01153"
"78469","470.77800","39.23180","0.01192"
"78546","471.24000","39.27018","0.01182"
"78623","471.70200","39.30863","0.01179"
"78700","472.16400","39.34719","0.01174"
"78777","472.62600","39.38570","0.01209"
"78854","473.08800","39.42420","0.01193"
"78931","473.55000","39.46271","0.01216"
"79008","474.01200","39.50121","0.01208"
"79085","474.47400","39.53966","0.01240"
"79162","474.93600","39.57816","0.01232"
"79239","475.39800","39.61666","0.01219"
"79316","475.86000","39.65523","0.01218"
"79393","476.32200","39.69373","0.01194"
"79470","476.78400","39.73223","0.01223"
"79547","477.24600","39.77074","0.01266"
"79624","477.70800","39.80918","0.01252"
"79701","478.17000","39.84763","0.01269"
"79778","478.63200","39.88613","0.01277"
"79855","479.09400","39.92470","0.01291"
"79932","479.55600","39.96326","0.01293"
"80009","480.01800","40.00171","0.01292"
"80086","480.48000","40.04021","0.01332"
"80163","480.94200","40.07866","0.01301"
"80240","481.40400","40.11722","0.01315"
"80317","481.86600","40.15573","0.01343"
"80394","482.32800","40.19417","0.01373"
"80471","482.79000","40.23267","0.01334"
"80548","483.25200","40.27124","0.01346"
"80625","483.71400","40.30975","0.01320"
"80702","484.17600","40.34819","0.01366"
"80779","484.63800","40.38658","0.01336"
"80856","485.10000","40.42514","0.01371"
"80933","485.56200","40.46364","0.01350"
"81010","486.02400","40.50221","0.01386"
"81087","486.48600","40.54071","0.01404"
"81164","486.94800","40.57915","0.01397"
"81241","487.41000","40.61772","0.01418"
"81318","487.87200","40.65617","0.01407"
"81395","488.33400","40.69466","0.01433"
"81472","488.79600","40.73317","0.01473"
"81549","489.25800","40.77168","0.01439"
"81626","489.72000","40.81024","0.01470"
"81703","490.18200","40.84874","0.01497"
"81780","490.64400","40.88719","0.01469"
"81857","491.10600","40.92563","0.01472"
"81934","491.56800","40.96414","0.01465"
"82011","492.03000","41.00270","0.01474"
"82088","492.49200","41.04127","0.01501"
"82165","492.95400","41.07977","0.01530"
"82242","493.41600","41.11822","0.01489"
"82319","493.87800","41.15672","0.01509"
"82396","494.34000","41.19517","0.01548"
"82473","494.80200","41.23362","0.01553"
"82550","495.26400","41.27218","0.01557"
"82627","495.72600","41.31074","0.01556"
"82704","496.18800","41.34925","0.01549"
"82781","496.65000","41.38775","0.01583"
"82858","497.11200","41.42620","0.01587"
"82935","497.57400","41.46464","0.01624"
"83012","498.03600","41.50314","0.01602"
"83089","498.49800","41.54170","0.01633"
"83166","498.96000","41.58015","0.01647"
"83243","499.42200","41.61872","0.01635"
"83320","499.88400","41.65716","0.01641"
"83397","500.34600","41.69572","0.01687"
"83474","500.80800","41.73417","0.01702"
"83551","501.27000","41.77267","0.01712"
"83628","501.73200","41.81118","0.01705"
"83705","502.19400","41.84969","0.01735"
"83782","502.65600","41.88825","0.01722"
"83859","503.11800","41.92669","0.01766"
"83936","503.58000","41.96519","0.01771"
"84013","504.04200","42.00370","0.01801"
"84090","504.50400","42.04214","0.01799"
"84167","504.96600","42.08065","0.01827"
"84244","505.42800","42.11916","0.01833"
"84321","505.89000","42.15766","0.01869"
"84398","506.35200","42.19622","0.01902"
"84475","506.81400","42.23479","0.01909"
"84552","507.27600","42.27317","0.01885"
"84629","507.73800","42.31162","0.01942"
"84706","508.20000","42.35012","0.01954"
"84783","508.66200","42.38874","0.01977"
"84860","509.12400","42.42725","0.02019"
"84937","509.58600","42.46570","0.02024"
"85014","510.04800","42.50420","0.02042"
"85091","510.51000","42.54264","0.02059"
"85168","510.97200","42.58121","0.02060"
"85245","511.43400","42.61965","0.02112"
"85322","511.89600","42.65822","0.02134"
"85399","512.35800","42.69672","0.02143"
"85476","512.82000","42.73523","0.02151"
"85553","513.28200","42.77367","0.02220"
"85630","513.74400","42.81218","0.02218"
"85707","514.20600","42.85068","0.02258"
"85784","514.66800","42.88919","0.02260"
"85861","515.13000","42.92775","0.02316"
"85938","515.59200","42.96619","0.02338"
"86015","516.05400","43.00470","0.02334"
"86092","516.51600","43.04320","0.02390"
"86169","516.97800","43.08171","0.02444"
"86246","517.44000","43.12015","0.02462"
"86323","517.90200","43.15872","0.02460"
"86400","518.36400","43.19716","0.02547"
"86477","518.82600","43.23567","0.02541"
"86554","519.28800","43.27423","0.02588"
"86631","519.75000","43.31274","0.02624"
"86708","520.21200","43.35118","0.02672"
"86785","520.67400","43.38962","0.02723"
"86862","521.13600","43.42818","0.02720"
"86939","521.59800","43.46669","0.02744"
"87016","522.06000","43.50525","0.02794"
"87093","522.52200","43.54364","0.02829"
"87170","522.98400","43.58220","0.02880"
"87247","523.44600","43.62071","0.02875"
"87324","523.90800","43.65915","0.02931"
"87401","524.37000","43.69766","0.02968"
"87478","524.83200","43.73616","0.02960"
"87555","525.29400","43.77473","0.03001"
"87632","525.75600","43.81323","0.03092"
"87709","526.21800","43.85174","0.03135"
"87786","526.68000","43.89018","0.03159"
"87863","527.14200","43.92857","0.03176"
"87940","527.60400","43.96719","0.03275"
"88017","528.06600","44.00576","0.03265"
"88094","528.52800","44.04420","0.03362"
"88171","528.99000","44.08276","0.03409"
"88248","529.45200","44.12120","0.03448"
"88325","529.91400","44.15971","0.03484"
"88402","530.37600","44.19822","0.03542"
"88479","530.83800","44.23666","0.03642"
"88556","531.30000","44.27517","0.03723"
"88633","531.76200","44.31367","0.03739"
"88710","532.22400","44.35223","0.03802"
"88787","532.68600","44.39074","0.03876"
"88864","533.14800","44.42918","0.03964"
"88941","533.61000","44.46763","0.04010"
"89018","534.07200","44.50619","0.04063"
"89095","534.53400","44.54470","0.04063"
"89172","534.99600","44.58320","0.04169"
"89249","535.45800","44.62170","0.04204"
"89326","535.92000","44.66021","0.04255"
"89403","536.38200","44.69878","0.04308"
"89480","536.84400","44.73716","0.04333"
"89557","537.30600","44.77567","0.04444"
"89634","537.76800","44.81417","0.04473"
"89711","538.23000","44.85273","0.04483"
"89788","538.69200","44.89124","0.04609"
"89865","539.15400","44.92968","0.04664"
"89942","539.61600","44.96819","0.04725"
"90019","540.07800","45.00669","0.04801"
"90096","540.54000","45.04520","0.04827"
"90173","541.00200","45.08370","0.04899"
"90250","541.46400","45.12215","0.04899"
"90327","541.92600","45.16071","0.04978"
"90404","542.38800","45.19921","0.04974"
"90481","542.85000","45.23778","0.04946"
"90558","543.31200","45.27610","0.05059"
"90635","543.77400","45.31460","0.05030"
"90712","544.23600","45.35317","0.05112"
"90789","544.69800","45.39174","0.05103"
"90866","545.16000","45.43024","0.05217"
"90943","545.62200","45.46868","0.05312"
"91020","546.08400","45.50713","0.05362"
"91097","546.54600","45.54569","0.05317"
"91174","547.00800","45.58420","0.05454"
"91251","547.47000","45.62270","0.05496"
"91328","547.93200","45.66121","0.05545"
"91405","548.39400","45.69971","0.05586"
"91482","548.85600","45.73822","0.05709"
"91559","549.31800","45.77666","0.05748"
"91636","549.78000","45.81517","0.05783"
"91713","550.24200","45.85367","0.05860"
"91790","550.70400","45.89217","0.05868"
"91867","551.16600","45.93068","0.05942"
"91944","551.62800","45.96925","0.06011"
"92021","552.09000","46.00769","0.06053"
"92098","552.55200","46.04619","0.06082"
"92175","553.01400","46.08469","0.06136"
"92252","553.47600","46.12314","0.06185"
"92329","553.93800","46.16171","0.06265"
"92406","554.40000","46.20015","0.06328"
"92483","554.86200","46.23877","0.06407"
"92560","555.32400","46.27728","0.06443"
"92637","555.78600","46.31572","0.06558"
"92714","556.24800","46.35416","0.06624"
"92791","556.71000","46.39261","0.06714"
"92868","557.17200","46.43118","0.06810"
"92945","557.63400","46.46968","0.06876"
"93022","558.09600","46.50824","0.06939"
"93099","558.55800","46.54663","0.07059"
"93176","559.02000","46.58519","0.07154"
"93253","559.48200","46.62370","0.07242"
"93330","559.94400","46.66214","0.07329"
"93407","560.40600","46.70071","0.07428"
"93484","560.86800","46.73915","0.07487"
"93561","561.33000","46.77778","0.07565"
"93638","561.79200","46.81622","0.07682"
"93715","562.25400","46.85479","0.07836"
"93792","562.71600","46.89317","0.07872"
"93869","563.17800","46.93167","0.08018"
"93946","563.64000","46.97018","0.08195"
"94023","564.10200","47.00869","0.08268"
"94100","564.56400","47.04719","0.08376"
"94170","564.98400","47.08216","0.08427"