File: Trajectories_together/161226_1Specimen_RawData_4.csv
"","V1","V2","V3"
"1","End date","12/26/2016",""
"2","Specimen label","10AT_60",""
"3","Maximum Load","0.01895","N"
"4","Time","Extension","Load"
"5","(s)","(mm)","(N)"
"6","0.00000","0.00000","0.00006"
"21","0.09000","0.00299","0.00013"
"36","0.18000","0.01172","0.00052"
"51","0.27000","0.02152","0.00018"
"66","0.36000","0.03001","0.00029"
"81","0.45000","0.03779","-0.00016"
"96","0.54000","0.04532","0.00011"
"111","0.63000","0.05273","0.00051"
"126","0.72000","0.06021","0.00055"
"141","0.81000","0.06768","0.00021"
"156","0.90000","0.07516","0.00034"
"171","0.99000","0.08269","0.00053"
"186","1.08000","0.09028","0.00021"
"201","1.17000","0.09770","0.00034"
"216","1.26000","0.10523","0.00050"
"231","1.35000","0.11270","0.00047"
"246","1.44000","0.12018","-0.00006"
"261","1.53000","0.12771","0.00021"
"276","1.62000","0.13518","0.00094"
"291","1.71000","0.14272","0.00055"
"306","1.80000","0.15019","0.00038"
"321","1.89000","0.15766","0.00060"
"336","1.98000","0.16514","0.00036"
"351","2.07000","0.17261","0.00054"
"366","2.16000","0.18021","0.00085"
"381","2.25000","0.18768","0.00064"
"396","2.34000","0.19521","0.00044"
"411","2.43000","0.20275","0.00029"
"426","2.52000","0.21016","0.00076"
"441","2.61000","0.21769","0.00066"
"456","2.70000","0.22523","0.00040"
"471","2.79000","0.23270","0.00046"
"486","2.88000","0.24023","0.00062"
"501","2.97000","0.24771","0.00114"
"516","3.06000","0.25512","0.00065"
"531","3.15000","0.26272","0.00074"
"546","3.24000","0.27025","0.00090"
"561","3.33000","0.27772","0.00063"
"576","3.42000","0.28526","0.00052"
"591","3.51000","0.29273","0.00042"
"606","3.60000","0.30020","0.00083"
"621","3.69000","0.30768","0.00071"
"636","3.78000","0.31521","0.00042"
"651","3.87000","0.32274","0.00051"
"666","3.96000","0.33022","0.00100"
"681","4.05000","0.33769","0.00047"
"696","4.14000","0.34516","0.00073"
"711","4.23000","0.35264","0.00064"
"726","4.32000","0.36023","0.00083"
"741","4.41000","0.36771","0.00041"
"756","4.50000","0.37524","0.00031"
"771","4.59000","0.38271","0.00056"
"786","4.68000","0.39019","0.00080"
"801","4.77000","0.39766","0.00055"
"816","4.86000","0.40519","0.00051"
"831","4.95000","0.41273","0.00023"
"846","5.04000","0.42020","0.00034"
"861","5.13000","0.42767","0.00058"
"876","5.22000","0.43515","0.00054"
"891","5.31000","0.44268","0.00046"
"906","5.40000","0.45016","0.00058"
"921","5.49000","0.45769","0.00012"
"936","5.58000","0.46522","0.00059"
"951","5.67000","0.47270","0.00062"
"966","5.76000","0.48017","0.00060"
"981","5.85000","0.48770","0.00025"
"996","5.94000","0.49524","0.00055"
"1011","6.03000","0.50277","0.00049"
"1026","6.12000","0.51024","0.00066"
"1041","6.21000","0.51772","0.00004"
"1056","6.30000","0.52519","0.00030"
"1071","6.39000","0.53261","0.00046"
"1086","6.48000","0.54020","0.00087"
"1101","6.57000","0.54773","0.00026"
"1116","6.66000","0.55521","0.00092"
"1131","6.75000","0.56274","0.00081"
"1146","6.84000","0.57015","0.00068"
"1161","6.93000","0.57763","0.00042"
"1176","7.02000","0.58522","0.00030"
"1191","7.11000","0.59263","0.00076"
"1206","7.20000","0.60023","0.00077"
"1221","7.29000","0.60764","0.00066"
"1236","7.38000","0.61511","0.00054"
"1251","7.47000","0.62271","0.00084"
"1266","7.56000","0.63018","0.00137"
"1281","7.65000","0.63772","0.00108"
"1296","7.74000","0.64525","0.00085"
"1311","7.83000","0.65272","0.00089"
"1326","7.92000","0.66020","0.00106"
"1341","8.01000","0.66773","0.00043"
"1356","8.10000","0.67520","0.00128"
"1371","8.19000","0.68274","0.00097"
"1386","8.28000","0.69021","0.00081"
"1401","8.37000","0.69768","0.00050"
"1416","8.46000","0.70522","0.00057"
"1431","8.55000","0.71269","0.00100"
"1446","8.64000","0.72028","0.00114"
"1461","8.73000","0.72776","0.00133"
"1476","8.82000","0.73523","0.00119"
"1491","8.91000","0.74271","0.00058"
"1506","9.00000","0.75018","0.00132"
"1521","9.09000","0.75771","0.00146"
"1536","9.18000","0.76525","0.00125"
"1551","9.27000","0.77272","0.00111"
"1566","9.36000","0.78019","0.00120"
"1581","9.45000","0.78767","0.00101"
"1596","9.54000","0.79514","0.00078"
"1611","9.63000","0.80267","0.00034"
"1626","9.72000","0.81021","0.00069"
"1641","9.81000","0.81768","0.00079"
"1656","9.90000","0.82522","0.00093"
"1671","9.99000","0.83269","0.00056"
"1686","10.08000","0.84016","0.00025"
"1701","10.17000","0.84770","0.00069"
"1716","10.26000","0.85523","0.00054"
"1731","10.35000","0.86270","0.00080"
"1746","10.44000","0.87024","0.00071"
"1761","10.53000","0.87771","0.00044"
"1776","10.62000","0.88518","0.00034"
"1791","10.71000","0.89272","0.00067"
"1806","10.80000","0.90025","0.00043"
"1821","10.89000","0.90772","0.00044"
"1836","10.98000","0.91520","0.00056"
"1851","11.07000","0.92273","0.00045"
"1866","11.16000","0.93015","0.00062"
"1881","11.25000","0.93768","0.00066"
"1896","11.34000","0.94527","0.00075"
"1911","11.43000","0.95269","0.00071"
"1926","11.52000","0.96022","0.00086"
"1941","11.61000","0.96769","0.00058"
"1956","11.70000","0.97511","0.00055"
"1971","11.79000","0.98270","0.00090"
"1986","11.88000","0.99023","0.00031"
"2001","11.97000","0.99771","0.00036"
"2016","12.06000","1.00524","0.00064"
"2031","12.15000","1.01266","0.00030"
"2046","12.24000","1.02013","0.00041"
"2061","12.33000","1.02772","0.00043"
"2076","12.42000","1.03526","0.00066"
"2091","12.51000","1.04267","0.00048"
"2106","12.60000","1.05020","0.00076"
"2121","12.69000","1.05768","0.00101"
"2136","12.78000","1.06515","0.00071"
"2151","12.87000","1.07268","0.00053"
"2166","12.96000","1.08022","0.00058"
"2181","13.05000","1.08775","0.00120"
"2196","13.14000","1.09522","0.00049"
"2211","13.23000","1.10270","0.00041"
"2226","13.32000","1.11017","0.00042"
"2241","13.41000","1.11765","0.00113"
"2256","13.50000","1.12524","0.00062"
"2271","13.59000","1.13271","0.00074"
"2286","13.68000","1.14019","0.00033"
"2301","13.77000","1.14766","0.00097"
"2316","13.86000","1.15513","0.00065"
"2331","13.95000","1.16267","0.00059"
"2346","14.04000","1.17020","0.00084"
"2361","14.13000","1.17773","0.00059"
"2376","14.22000","1.18521","0.00091"
"2391","14.31000","1.19268","0.00036"
"2406","14.40000","1.20016","0.00055"
"2421","14.49000","1.20775","0.00029"
"2436","14.58000","1.21522","0.00122"
"2451","14.67000","1.22276","0.00108"
"2466","14.76000","1.23023","0.00124"
"2481","14.85000","1.23764","0.00024"
"2496","14.94000","1.24518","0.00063"
"2511","15.03000","1.25271","0.00073"
"2526","15.12000","1.26018","0.00065"
"2541","15.21000","1.26778","0.00060"
"2556","15.30000","1.27519","0.00093"
"2571","15.39000","1.28272","0.00087"
"2586","15.48000","1.29020","0.00080"
"2601","15.57000","1.29767","0.00040"
"2616","15.66000","1.30521","0.00088"
"2631","15.75000","1.31268","0.00069"
"2646","15.84000","1.32021","0.00072"
"2661","15.93000","1.32769","0.00116"
"2676","16.02000","1.33510","0.00137"
"2691","16.11000","1.34269","0.00064"
"2706","16.20000","1.35029","0.00089"
"2721","16.29000","1.35770","0.00051"
"2736","16.38000","1.36523","0.00089"
"2751","16.47000","1.37271","0.00095"
"2766","16.56000","1.38018","0.00069"
"2781","16.65000","1.38771","0.00096"
"2796","16.74000","1.39525","0.00061"
"2811","16.83000","1.40266","0.00090"
"2826","16.92000","1.41026","0.00105"
"2841","17.01000","1.41767","0.00059"
"2856","17.10000","1.42520","0.00087"
"2871","17.19000","1.43274","0.00055"
"2886","17.28000","1.44021","0.00103"
"2901","17.37000","1.44780","0.00087"
"2916","17.46000","1.45522","0.00065"
"2931","17.55000","1.46269","0.00139"
"2946","17.64000","1.47016","0.00079"
"2961","17.73000","1.47770","0.00081"
"2976","17.82000","1.48523","0.00143"
"2991","17.91000","1.49265","0.00102"
"3006","18.00000","1.50018","0.00081"
"3021","18.09000","1.50765","0.00086"
"3036","18.18000","1.51513","0.00093"
"3051","18.27000","1.52266","0.00096"
"3066","18.36000","1.53025","0.00124"
"3081","18.45000","1.53773","0.00147"
"3096","18.54000","1.54520","0.00087"
"3111","18.63000","1.55267","0.00104"
"3126","18.72000","1.56015","0.00089"
"3141","18.81000","1.56768","0.00102"
"3156","18.90000","1.57522","0.00087"
"3171","18.99000","1.58269","0.00127"
"3186","19.08000","1.59022","0.00058"
"3201","19.17000","1.59764","0.00106"
"3216","19.26000","1.60517","0.00133"
"3231","19.35000","1.61276","0.00053"
"3246","19.44000","1.62018","0.00103"
"3261","19.53000","1.62777","0.00087"
"3276","19.62000","1.63518","0.00016"
"3291","19.71000","1.64260","0.00072"
"3306","19.80000","1.65019","0.00107"
"3321","19.89000","1.65772","0.00115"
"3336","19.98000","1.66520","0.00076"
"3351","20.07000","1.67267","0.00067"
"3366","20.16000","1.68021","0.00105"
"3381","20.25000","1.68762","0.00097"
"3396","20.34000","1.69515","0.00088"
"3411","20.43000","1.70275","0.00132"
"3426","20.52000","1.71022","0.00105"
"3441","20.61000","1.71775","0.00109"
"3456","20.70000","1.72523","0.00106"
"3471","20.79000","1.73270","0.00060"
"3486","20.88000","1.74011","0.00110"
"3501","20.97000","1.74771","0.00069"
"3516","21.06000","1.75524","0.00103"
"3531","21.15000","1.76271","0.00072"
"3546","21.24000","1.77025","0.00031"
"3561","21.33000","1.77766","0.00083"
"3576","21.42000","1.78520","0.00108"
"3591","21.51000","1.79273","0.00093"
"3606","21.60000","1.80020","0.00062"
"3621","21.69000","1.80774","0.00070"
"3636","21.78000","1.81521","0.00115"
"3651","21.87000","1.82268","0.00104"
"3666","21.96000","1.83016","0.00082"
"3681","22.05000","1.83769","0.00090"
"3696","22.14000","1.84522","0.00103"
"3711","22.23000","1.85276","0.00066"
"3726","22.32000","1.86017","0.00080"
"3741","22.41000","1.86765","0.00114"
"3756","22.50000","1.87518","0.00063"
"3771","22.59000","1.88271","0.00068"
"3786","22.68000","1.89025","0.00088"
"3801","22.77000","1.89772","0.00088"
"3816","22.86000","1.90519","0.00155"
"3831","22.95000","1.91273","0.00102"
"3846","23.04000","1.92014","0.00008"
"3861","23.13000","1.92773","0.00071"
"3876","23.22000","1.93527","0.00075"
"3891","23.31000","1.94274","0.00072"
"3906","23.40000","1.95022","0.00119"
"3921","23.49000","1.95769","0.00060"
"3936","23.58000","1.96516","0.00095"
"3951","23.67000","1.97276","0.00068"
"3966","23.76000","1.98017","0.00097"
"3981","23.85000","1.98776","0.00117"
"3996","23.94000","1.99524","0.00109"
"4011","24.03000","2.00265","0.00103"
"4026","24.12000","2.01018","0.00133"
"4041","24.21000","2.01766","0.00068"
"4056","24.30000","2.02513","0.00122"
"4071","24.39000","2.03272","0.00102"
"4086","24.48000","2.04014","0.00045"
"4101","24.57000","2.04761","0.00132"
"4116","24.66000","2.05521","0.00128"
"4131","24.75000","2.06268","0.00111"
"4146","24.84000","2.07027","0.00076"
"4161","24.93000","2.07769","0.00119"
"4176","25.02000","2.08522","0.00079"
"4191","25.11000","2.09269","0.00134"
"4206","25.20000","2.10017","0.00049"
"4221","25.29000","2.10770","0.00070"
"4236","25.38000","2.11523","0.00124"
"4251","25.47000","2.12277","0.00071"
"4266","25.56000","2.13018","0.00158"
"4281","25.65000","2.13766","0.00080"
"4296","25.74000","2.14519","0.00122"
"4311","25.83000","2.15266","0.00083"
"4326","25.92000","2.16020","0.00134"
"4341","26.01000","2.16773","0.00131"
"4356","26.10000","2.17520","0.00107"
"4371","26.19000","2.18268","0.00117"
"4386","26.28000","2.19021","0.00086"
"4401","26.37000","2.19774","0.00151"
"4416","26.46000","2.20516","0.00095"
"4431","26.55000","2.21269","0.00115"
"4446","26.64000","2.22016","0.00096"
"4461","26.73000","2.22764","0.00108"
"4476","26.82000","2.23517","0.00098"
"4491","26.91000","2.24265","0.00095"
"4506","27.00000","2.25024","0.00119"
"4521","27.09000","2.25771","0.00092"
"4536","27.18000","2.26513","0.00096"
"4551","27.27000","2.27272","0.00081"
"4566","27.36000","2.28019","0.00108"
"4581","27.45000","2.28773","0.00103"
"4596","27.54000","2.29526","0.00135"
"4611","27.63000","2.30273","0.00128"
"4626","27.72000","2.31021","0.00069"
"4641","27.81000","2.31768","0.00094"
"4656","27.90000","2.32516","0.00081"
"4671","27.99000","2.33275","0.00051"
"4686","28.08000","2.34016","0.00089"
"4701","28.17000","2.34776","0.00082"
"4716","28.26000","2.35523","0.00100"
"4731","28.35000","2.36264","0.00086"
"4746","28.44000","2.37018","0.00105"
"4761","28.53000","2.37777","0.00124"
"4776","28.62000","2.38518","0.00130"
"4791","28.71000","2.39272","0.00116"
"4806","28.80000","2.40019","0.00097"
"4821","28.89000","2.40766","0.00139"
"4836","28.98000","2.41520","0.00104"
"4851","29.07000","2.42273","0.00089"
"4866","29.16000","2.43021","0.00138"
"4881","29.25000","2.43774","0.00151"
"4896","29.34000","2.44521","0.00136"
"4911","29.43000","2.45269","0.00114"
"4926","29.52000","2.46016","0.00131"
"4941","29.61000","2.46775","0.00147"
"4956","29.70000","2.47523","0.00097"
"4971","29.79000","2.48270","0.00126"
"4986","29.88000","2.49023","0.00123"
"5001","29.97000","2.49765","0.00140"
"5016","30.06000","2.50512","0.00150"
"5031","30.15000","2.51277","0.00116"
"5046","30.24000","2.52025","0.00114"
"5061","30.33000","2.52766","0.00091"
"5076","30.42000","2.53526","0.00154"
"5091","30.51000","2.54267","0.00113"
"5106","30.60000","2.55014","0.00189"
"5121","30.69000","2.55774","0.00092"
"5136","30.78000","2.56521","0.00088"
"5151","30.87000","2.57268","0.00122"
"5166","30.96000","2.58016","0.00156"
"5181","31.05000","2.58769","0.00131"
"5196","31.14000","2.59516","0.00120"
"5211","31.23000","2.60270","0.00144"
"5226","31.32000","2.61023","0.00147"
"5241","31.41000","2.61777","0.00118"
"5256","31.50000","2.62518","0.00083"
"5271","31.59000","2.63265","0.00089"
"5286","31.68000","2.64019","0.00103"
"5301","31.77000","2.64772","0.00173"
"5316","31.86000","2.65525","0.00114"
"5331","31.95000","2.66273","0.00162"
"5346","32.04000","2.67020","0.00147"
"5361","32.13000","2.67773","0.00140"
"5376","32.22000","2.68515","0.00153"
"5391","32.31000","2.69268","0.00156"
"5406","32.40000","2.70021","0.00101"
"5421","32.49000","2.70769","0.00110"
"5436","32.58000","2.71522","0.00143"
"5451","32.67000","2.72264","0.00143"
"5466","32.76000","2.73017","0.00098"
"5481","32.85000","2.73770","0.00147"
"5496","32.94000","2.74518","0.00131"
"5511","33.03000","2.75271","0.00130"
"5526","33.12000","2.76018","0.00139"
"5541","33.21000","2.76766","0.00089"
"5556","33.30000","2.77519","0.00134"
"5571","33.39000","2.78272","0.00144"
"5586","33.48000","2.79020","0.00122"
"5601","33.57000","2.79773","0.00099"
"5616","33.66000","2.80521","0.00140"
"5631","33.75000","2.81268","0.00079"
"5646","33.84000","2.82021","0.00124"
"5661","33.93000","2.82775","0.00126"
"5676","34.02000","2.83522","0.00131"
"5691","34.11000","2.84269","0.00143"
"5706","34.20000","2.85023","0.00134"
"5721","34.29000","2.85770","0.00142"
"5736","34.38000","2.86517","0.00108"
"5751","34.47000","2.87271","0.00143"
"5766","34.56000","2.88024","0.00133"
"5781","34.65000","2.88771","0.00128"
"5796","34.74000","2.89519","0.00141"
"5811","34.83000","2.90266","0.00117"
"5826","34.92000","2.91014","0.00133"
"5841","35.01000","2.91773","0.00142"
"5856","35.10000","2.92514","0.00150"
"5871","35.19000","2.93268","0.00055"
"5886","35.28000","2.94021","0.00087"
"5901","35.37000","2.94762","0.00122"
"5916","35.46000","2.95522","0.00084"
"5931","35.55000","2.96269","0.00129"
"5946","35.64000","2.97016","0.00127"
"5961","35.73000","2.97776","0.00147"
"5976","35.82000","2.98517","0.00096"
"5991","35.91000","2.99271","0.00117"
"6006","36.00000","3.00024","0.00135"
"6021","36.09000","3.00771","0.00094"
"6036","36.18000","3.01519","0.00101"
"6051","36.27000","3.02272","0.00143"
"6066","36.36000","3.03019","0.00132"
"6081","36.45000","3.03767","0.00116"
"6096","36.54000","3.04520","0.00097"
"6111","36.63000","3.05273","0.00133"
"6126","36.72000","3.06027","0.00143"
"6141","36.81000","3.06768","0.00160"
"6156","36.90000","3.07522","0.00111"
"6171","36.99000","3.08269","0.00121"
"6186","37.08000","3.09022","0.00152"
"6201","37.17000","3.09776","0.00081"
"6216","37.26000","3.10523","0.00119"
"6231","37.35000","3.11270","0.00124"
"6246","37.44000","3.12018","0.00137"
"6261","37.53000","3.12765","0.00128"
"6276","37.62000","3.13518","0.00151"
"6291","37.71000","3.14272","0.00137"
"6306","37.80000","3.15019","0.00107"
"6321","37.89000","3.15772","0.00085"
"6336","37.98000","3.16514","0.00158"
"6351","38.07000","3.17261","0.00113"
"6366","38.16000","3.18021","0.00160"
"6381","38.25000","3.18774","0.00111"
"6396","38.34000","3.19521","0.00132"
"6411","38.43000","3.20275","0.00129"
"6426","38.52000","3.21022","0.00142"
"6441","38.61000","3.21763","0.00141"
"6456","38.70000","3.22517","0.00143"
"6471","38.79000","3.23276","0.00134"
"6486","38.88000","3.24023","0.00166"
"6501","38.97000","3.24771","0.00129"
"6516","39.06000","3.25518","0.00128"
"6531","39.15000","3.26265","0.00145"
"6546","39.24000","3.27013","0.00118"
"6561","39.33000","3.27772","0.00132"
"6576","39.42000","3.28520","0.00102"
"6591","39.51000","3.29267","0.00176"
"6606","39.60000","3.30014","0.00151"
"6621","39.69000","3.30762","0.00118"
"6636","39.78000","3.31515","0.00149"
"6651","39.87000","3.32274","0.00139"
"6666","39.96000","3.33022","0.00163"
"6681","40.05000","3.33775","0.00104"
"6696","40.14000","3.34516","0.00172"
"6711","40.23000","3.35264","0.00168"
"6726","40.32000","3.36017","0.00120"
"6741","40.41000","3.36771","0.00153"
"6756","40.50000","3.37518","0.00111"
"6771","40.59000","3.38271","0.00165"
"6786","40.68000","3.39019","0.00159"
"6801","40.77000","3.39766","0.00151"
"6816","40.86000","3.40519","0.00140"
"6831","40.95000","3.41273","0.00188"
"6846","41.04000","3.42020","0.00171"
"6861","41.13000","3.42773","0.00144"
"6876","41.22000","3.43515","0.00181"
"6891","41.31000","3.44268","0.00154"
"6906","41.40000","3.45021","0.00148"
"6921","41.49000","3.45775","0.00150"
"6936","41.58000","3.46522","0.00150"
"6951","41.67000","3.47270","0.00133"
"6966","41.76000","3.48023","0.00164"
"6981","41.85000","3.48764","0.00123"
"6996","41.94000","3.49518","0.00188"
"7011","42.03000","3.50277","0.00171"
"7026","42.12000","3.51018","0.00190"
"7041","42.21000","3.51772","0.00190"
"7056","42.30000","3.52519","0.00146"
"7071","42.39000","3.53266","0.00112"
"7086","42.48000","3.54020","0.00153"
"7101","42.57000","3.54773","0.00135"
"7116","42.66000","3.55521","0.00163"
"7131","42.75000","3.56274","0.00147"
"7146","42.84000","3.57021","0.00182"
"7161","42.93000","3.57769","0.00136"
"7176","43.02000","3.58522","0.00170"
"7191","43.11000","3.59269","0.00135"
"7206","43.20000","3.60029","0.00162"
"7221","43.29000","3.60770","0.00180"
"7236","43.38000","3.61517","0.00163"
"7251","43.47000","3.62271","0.00154"
"7266","43.56000","3.63018","0.00210"
"7281","43.65000","3.63771","0.00155"
"7296","43.74000","3.64519","0.00162"
"7311","43.83000","3.65266","0.00159"
"7326","43.92000","3.66020","0.00168"
"7341","44.01000","3.66761","0.00210"
"7356","44.10000","3.67520","0.00204"
"7371","44.19000","3.68280","0.00167"
"7386","44.28000","3.69021","0.00180"
"7401","44.37000","3.69768","0.00147"
"7416","44.46000","3.70522","0.00229"
"7431","44.55000","3.71269","0.00152"
"7446","44.64000","3.72022","0.00127"
"7461","44.73000","3.72770","0.00188"
"7476","44.82000","3.73523","0.00177"
"7491","44.91000","3.74271","0.00158"
"7506","45.00000","3.75018","0.00157"
"7521","45.09000","3.75765","0.00146"
"7536","45.18000","3.76519","0.00192"
"7551","45.27000","3.77266","0.00161"
"7566","45.36000","3.78019","0.00167"
"7581","45.45000","3.78767","0.00189"
"7596","45.54000","3.79514","0.00192"
"7611","45.63000","3.80267","0.00190"
"7626","45.72000","3.81021","0.00167"
"7641","45.81000","3.81768","0.00182"
"7656","45.90000","3.82521","0.00200"
"7671","45.99000","3.83269","0.00158"
"7686","46.08000","3.84016","0.00142"
"7701","46.17000","3.84764","0.00161"
"7716","46.26000","3.85523","0.00153"
"7731","46.35000","3.86270","0.00206"
"7746","46.44000","3.87024","0.00185"
"7761","46.53000","3.87771","0.00208"
"7776","46.62000","3.88518","0.00158"
"7791","46.71000","3.89266","0.00211"
"7806","46.80000","3.90019","0.00182"
"7821","46.89000","3.90772","0.00185"
"7836","46.98000","3.91520","0.00179"
"7851","47.07000","3.92279","0.00195"
"7866","47.16000","3.93015","0.00214"
"7881","47.25000","3.93762","0.00227"
"7896","47.34000","3.94527","0.00199"
"7911","47.43000","3.95275","0.00188"
"7926","47.52000","3.96022","0.00202"
"7941","47.61000","3.96775","0.00158"
"7956","47.70000","3.97517","0.00197"
"7971","47.79000","3.98270","0.00197"
"7986","47.88000","3.99017","0.00231"
"8001","47.97000","3.99771","0.00167"
"8016","48.06000","4.00524","0.00211"
"8031","48.15000","4.01265","0.00154"
"8046","48.24000","4.02019","0.00205"
"8061","48.33000","4.02766","0.00276"
"8076","48.42000","4.03520","0.00218"
"8091","48.51000","4.04273","0.00245"
"8106","48.60000","4.05026","0.00203"
"8121","48.69000","4.05768","0.00209"
"8136","48.78000","4.06515","0.00205"
"8151","48.87000","4.07262","0.00192"
"8166","48.96000","4.08016","0.00243"
"8181","49.05000","4.08775","0.00153"
"8196","49.14000","4.09522","0.00197"
"8211","49.23000","4.10270","0.00219"
"8226","49.32000","4.11017","0.00254"
"8241","49.41000","4.11770","0.00190"
"8256","49.50000","4.12524","0.00249"
"8271","49.59000","4.13271","0.00199"
"8286","49.68000","4.14025","0.00169"
"8301","49.77000","4.14772","0.00213"
"8316","49.86000","4.15519","0.00242"
"8331","49.95000","4.16267","0.00216"
"8346","50.04000","4.17020","0.00230"
"8361","50.13000","4.17767","0.00214"
"8376","50.22000","4.18521","0.00215"
"8391","50.31000","4.19268","0.00235"
"8406","50.40000","4.20015","0.00236"
"8421","50.49000","4.20763","0.00261"
"8436","50.58000","4.21522","0.00185"
"8451","50.67000","4.22270","0.00224"
"8466","50.76000","4.23023","0.00196"
"8481","50.85000","4.23770","0.00233"
"8496","50.94000","4.24524","0.00250"
"8511","51.03000","4.25265","0.00215"
"8526","51.12000","4.26018","0.00226"
"8541","51.21000","4.26778","0.00206"
"8556","51.30000","4.27519","0.00227"
"8571","51.39000","4.28272","0.00252"
"8586","51.48000","4.29020","0.00232"
"8601","51.57000","4.29767","0.00240"
"8616","51.66000","4.30521","0.00272"
"8631","51.75000","4.31268","0.00268"
"8646","51.84000","4.32021","0.00239"
"8661","51.93000","4.32775","0.00246"
"8676","52.02000","4.33516","0.00275"
"8691","52.11000","4.34269","0.00227"
"8706","52.20000","4.35023","0.00217"
"8721","52.29000","4.35770","0.00200"
"8736","52.38000","4.36523","0.00243"
"8751","52.47000","4.37265","0.00208"
"8766","52.56000","4.38018","0.00228"
"8781","52.65000","4.38771","0.00208"
"8796","52.74000","4.39519","0.00199"
"8811","52.83000","4.40272","0.00225"
"8826","52.92000","4.41020","0.00228"
"8841","53.01000","4.41767","0.00244"
"8856","53.10000","4.42520","0.00264"
"8871","53.19000","4.43268","0.00217"
"8886","53.28000","4.44021","0.00224"
"8901","53.37000","4.44774","0.00202"
"8916","53.46000","4.45522","0.00239"
"8931","53.55000","4.46269","0.00210"
"8946","53.64000","4.47016","0.00255"
"8961","53.73000","4.47770","0.00253"
"8976","53.82000","4.48523","0.00273"
"8991","53.91000","4.49271","0.00227"
"9006","54.00000","4.50024","0.00238"
"9021","54.09000","4.50771","0.00234"
"9036","54.18000","4.51519","0.00302"
"9051","54.27000","4.52272","0.00242"
"9066","54.36000","4.53025","0.00283"
"9081","54.45000","4.53773","0.00237"
"9096","54.54000","4.54526","0.00213"
"9111","54.63000","4.55267","0.00240"
"9126","54.72000","4.56015","0.00215"
"9141","54.81000","4.56774","0.00236"
"9156","54.90000","4.57521","0.00227"
"9171","54.99000","4.58275","0.00253"
"9186","55.08000","4.59022","0.00248"
"9201","55.17000","4.59764","0.00202"
"9216","55.26000","4.60517","0.00200"
"9231","55.35000","4.61270","0.00226"
"9246","55.44000","4.62024","0.00181"
"9261","55.53000","4.62777","0.00266"
"9276","55.62000","4.63518","0.00211"
"9291","55.71000","4.64266","0.00224"
"9306","55.80000","4.65019","0.00232"
"9321","55.89000","4.65760","0.00225"
"9336","55.98000","4.66526","0.00245"
"9351","56.07000","4.67273","0.00220"
"9366","56.16000","4.68021","0.00273"
"9381","56.25000","4.68774","0.00212"
"9396","56.34000","4.69521","0.00235"
"9411","56.43000","4.70269","0.00316"
"9426","56.52000","4.71022","0.00280"
"9441","56.61000","4.71769","0.00273"
"9456","56.70000","4.72523","0.00271"
"9471","56.79000","4.73270","0.00212"
"9486","56.88000","4.74017","0.00273"
"9501","56.97000","4.74771","0.00202"
"9516","57.06000","4.75518","0.00234"
"9531","57.15000","4.76271","0.00242"
"9546","57.24000","4.77031","0.00253"
"9561","57.33000","4.77766","0.00245"
"9576","57.42000","4.78520","0.00233"
"9591","57.51000","4.79267","0.00231"
"9606","57.60000","4.80026","0.00248"
"9621","57.69000","4.80768","0.00209"
"9636","57.78000","4.81521","0.00221"
"9651","57.87000","4.82268","0.00281"
"9666","57.96000","4.83016","0.00255"
"9681","58.05000","4.83769","0.00243"
"9696","58.14000","4.84522","0.00253"
"9711","58.23000","4.85270","0.00278"
"9726","58.32000","4.86023","0.00273"
"9741","58.41000","4.86770","0.00302"
"9756","58.50000","4.87518","0.00262"
"9771","58.59000","4.88265","0.00306"
"9786","58.68000","4.89019","0.00239"
"9801","58.77000","4.89766","0.00293"
"9816","58.86000","4.90525","0.00269"
"9831","58.95000","4.91273","0.00245"
"9846","59.04000","4.92014","0.00293"
"9861","59.13000","4.92767","0.00250"
"9876","59.22000","4.93521","0.00256"
"9891","59.31000","4.94274","0.00253"
"9906","59.40000","4.95027","0.00246"
"9921","59.49000","4.95769","0.00300"
"9936","59.58000","4.96516","0.00241"
"9951","59.67000","4.97269","0.00258"
"9966","59.76000","4.98023","0.00251"
"9981","59.85000","4.98770","0.00286"
"9996","59.94000","4.99518","0.00306"
"10011","60.03000","5.00271","0.00283"
"10026","60.12000","5.01018","0.00270"
"10041","60.21000","5.01766","0.00257"
"10056","60.30000","5.02519","0.00303"
"10071","60.39000","5.03272","0.00287"
"10086","60.48000","5.04020","0.00294"
"10101","60.57000","5.04773","0.00276"
"10116","60.66000","5.05514","0.00311"
"10131","60.75000","5.06262","0.00274"
"10146","60.84000","5.07027","0.00288"
"10161","60.93000","5.07769","0.00312"
"10176","61.02000","5.08516","0.00311"
"10191","61.11000","5.09269","0.00311"
"10206","61.20000","5.10017","0.00260"
"10221","61.29000","5.10764","0.00300"
"10236","61.38000","5.11523","0.00306"
"10251","61.47000","5.12271","0.00302"
"10266","61.56000","5.13018","0.00272"
"10281","61.65000","5.13765","0.00254"
"10296","61.74000","5.14519","0.00286"
"10311","61.83000","5.15266","0.00304"
"10326","61.92000","5.16026","0.00281"
"10341","62.01000","5.16773","0.00291"
"10356","62.10000","5.17520","0.00350"
"10371","62.19000","5.18268","0.00290"
"10386","62.28000","5.19015","0.00317"
"10401","62.37000","5.19774","0.00307"
"10416","62.46000","5.20522","0.00294"
"10431","62.55000","5.21275","0.00313"
"10446","62.64000","5.22022","0.00263"
"10461","62.73000","5.22770","0.00347"
"10476","62.82000","5.23517","0.00289"
"10491","62.91000","5.24270","0.00266"
"10506","63.00000","5.25030","0.00323"
"10521","63.09000","5.25771","0.00360"
"10536","63.18000","5.26519","0.00322"
"10551","63.27000","5.27266","0.00330"
"10566","63.36000","5.28007","0.00325"
"10581","63.45000","5.28767","0.00305"
"10596","63.54000","5.29526","0.00306"
"10611","63.63000","5.30267","0.00313"
"10626","63.72000","5.31027","0.00394"
"10641","63.81000","5.31768","0.00303"
"10656","63.90000","5.32515","0.00348"
"10671","63.99000","5.33275","0.00318"
"10686","64.08000","5.34022","0.00307"
"10701","64.17000","5.34775","0.00337"
"10716","64.26000","5.35523","0.00335"
"10731","64.35000","5.36270","0.00387"
"10746","64.44000","5.37018","0.00352"
"10761","64.53000","5.37765","0.00358"
"10776","64.62000","5.38524","0.00360"
"10791","64.71000","5.39278","0.00343"
"10806","64.80000","5.40019","0.00328"
"10821","64.89000","5.40772","0.00367"
"10836","64.98000","5.41520","0.00341"
"10851","65.07000","5.42273","0.00339"
"10866","65.16000","5.43026","0.00363"
"10881","65.25000","5.43774","0.00359"
"10896","65.34000","5.44521","0.00393"
"10911","65.43000","5.45269","0.00319"
"10926","65.52000","5.46016","0.00366"
"10941","65.61000","5.46769","0.00328"
"10956","65.70000","5.47523","0.00354"
"10971","65.79000","5.48276","0.00286"
"10986","65.88000","5.49023","0.00353"
"11001","65.97000","5.49771","0.00355"
"11016","66.06000","5.50518","0.00319"
"11031","66.15000","5.51271","0.00299"
"11046","66.24000","5.52019","0.00355"
"11061","66.33000","5.52772","0.00361"
"11076","66.42000","5.53525","0.00319"
"11091","66.51000","5.54267","0.00370"
"11106","66.60000","5.55020","0.00348"
"11121","66.69000","5.55768","0.00356"
"11136","66.78000","5.56521","0.00368"
"11151","66.87000","5.57274","0.00347"
"11166","66.96000","5.58022","0.00354"
"11181","67.05000","5.58769","0.00370"
"11196","67.14000","5.59522","0.00347"
"11211","67.23000","5.60270","0.00341"
"11226","67.32000","5.61023","0.00413"
"11241","67.41000","5.61776","0.00325"
"11256","67.50000","5.62518","0.00357"
"11271","67.59000","5.63271","0.00320"
"11286","67.68000","5.64013","0.00371"
"11301","67.77000","5.64772","0.00414"
"11316","67.86000","5.65525","0.00348"
"11331","67.95000","5.66267","0.00325"
"11346","68.04000","5.67026","0.00354"
"11361","68.13000","5.67767","0.00377"
"11376","68.22000","5.68515","0.00399"
"11391","68.31000","5.69268","0.00393"
"11406","68.40000","5.70021","0.00385"
"11421","68.49000","5.70769","0.00341"
"11436","68.58000","5.71522","0.00344"
"11451","68.67000","5.72264","0.00394"
"11466","68.76000","5.73017","0.00420"
"11481","68.85000","5.73770","0.00392"
"11496","68.94000","5.74524","0.00405"
"11511","69.03000","5.75271","0.00396"
"11526","69.12000","5.76018","0.00395"
"11541","69.21000","5.76772","0.00383"
"11556","69.30000","5.77519","0.00384"
"11571","69.39000","5.78272","0.00394"
"11586","69.48000","5.79020","0.00349"
"11601","69.57000","5.79767","0.00398"
"11616","69.66000","5.80520","0.00382"
"11631","69.75000","5.81268","0.00426"
"11646","69.84000","5.82021","0.00410"
"11661","69.93000","5.82775","0.00367"
"11676","70.02000","5.83528","0.00412"
"11691","70.11000","5.84275","0.00401"
"11706","70.20000","5.85017","0.00406"
"11721","70.29000","5.85770","0.00366"
"11736","70.38000","5.86511","0.00427"
"11751","70.47000","5.87271","0.00472"
"11766","70.56000","5.88024","0.00415"
"11781","70.65000","5.88771","0.00502"
"11796","70.74000","5.89519","0.00396"
"11811","70.83000","5.90266","0.00432"
"11826","70.92000","5.91020","0.00487"
"11841","71.01000","5.91773","0.00412"
"11856","71.10000","5.92520","0.00453"
"11871","71.19000","5.93274","0.00420"
"11886","71.28000","5.94021","0.00469"
"11901","71.37000","5.94768","0.00402"
"11916","71.46000","5.95522","0.00506"
"11931","71.55000","5.96269","0.00449"
"11946","71.64000","5.97022","0.00464"
"11961","71.73000","5.97776","0.00487"
"11976","71.82000","5.98517","0.00491"
"11991","71.91000","5.99270","0.00467"
"12006","72.00000","6.00018","0.00484"
"12021","72.09000","6.00771","0.00507"
"12036","72.18000","6.01531","0.00455"
"12051","72.27000","6.02272","0.00470"
"12066","72.36000","6.03019","0.00476"
"12081","72.45000","6.03767","0.00499"
"12096","72.54000","6.04514","0.00484"
"12111","72.63000","6.05267","0.00475"
"12126","72.72000","6.06027","0.00469"
"12141","72.81000","6.06774","0.00499"
"12156","72.90000","6.07521","0.00513"
"12171","72.99000","6.08263","0.00493"
"12186","73.08000","6.09010","0.00487"
"12201","73.17000","6.09769","0.00481"
"12216","73.26000","6.10523","0.00543"
"12231","73.35000","6.11270","0.00514"
"12246","73.44000","6.12018","0.00492"
"12261","73.53000","6.12771","0.00528"
"12276","73.62000","6.13518","0.00510"
"12291","73.71000","6.14272","0.00500"
"12306","73.80000","6.15025","0.00527"
"12321","73.89000","6.15778","0.00525"
"12336","73.98000","6.16520","0.00549"
"12351","74.07000","6.17267","0.00560"
"12366","74.16000","6.18020","0.00524"
"12381","74.25000","6.18768","0.00556"
"12396","74.34000","6.19521","0.00548"
"12411","74.43000","6.20275","0.00537"
"12426","74.52000","6.21022","0.00555"
"12441","74.61000","6.21769","0.00553"
"12456","74.70000","6.22517","0.00561"
"12471","74.79000","6.23270","0.00590"
"12486","74.88000","6.24023","0.00555"
"12501","74.97000","6.24777","0.00594"
"12516","75.06000","6.25524","0.00586"
"12531","75.15000","6.26271","0.00569"
"12546","75.24000","6.27019","0.00580"
"12561","75.33000","6.27772","0.00569"
"12576","75.42000","6.28520","0.00565"
"12591","75.51000","6.29273","0.00582"
"12606","75.60000","6.30020","0.00546"
"12621","75.69000","6.30768","0.00602"
"12636","75.78000","6.31521","0.00577"
"12651","75.87000","6.32268","0.00557"
"12666","75.96000","6.33016","0.00614"
"12681","76.05000","6.33775","0.00554"
"12696","76.14000","6.34516","0.00603"
"12711","76.23000","6.35264","0.00569"
"12726","76.32000","6.36023","0.00585"
"12741","76.41000","6.36770","0.00635"
"12756","76.50000","6.37524","0.00611"
"12771","76.59000","6.38271","0.00566"
"12786","76.68000","6.39019","0.00578"
"12801","76.77000","6.39772","0.00618"
"12816","76.86000","6.40519","0.00607"
"12831","76.95000","6.41273","0.00600"
"12846","77.04000","6.42020","0.00626"
"12861","77.13000","6.42773","0.00595"
"12876","77.22000","6.43521","0.00602"
"12891","77.31000","6.44268","0.00615"
"12906","77.40000","6.45021","0.00609"
"12921","77.49000","6.45769","0.00670"
"12936","77.58000","6.46522","0.00666"
"12951","77.67000","6.47275","0.00585"
"12966","77.76000","6.48029","0.00649"
"12981","77.85000","6.48770","0.00620"
"12996","77.94000","6.49518","0.00594"
"13011","78.03000","6.50271","0.00620"
"13026","78.12000","6.51018","0.00626"
"13041","78.21000","6.51772","0.00632"
"13056","78.30000","6.52519","0.00606"
"13071","78.39000","6.53266","0.00636"
"13086","78.48000","6.54020","0.00609"
"13101","78.57000","6.54773","0.00641"
"13116","78.66000","6.55520","0.00633"
"13131","78.75000","6.56268","0.00672"
"13146","78.84000","6.57015","0.00661"
"13161","78.93000","6.57769","0.00634"
"13176","79.02000","6.58516","0.00665"
"13191","79.11000","6.59275","0.00647"
"13206","79.20000","6.60023","0.00654"
"13221","79.29000","6.60770","0.00652"
"13236","79.38000","6.61517","0.00665"
"13251","79.47000","6.62265","0.00640"
"13266","79.56000","6.63018","0.00642"
"13281","79.65000","6.63777","0.00660"
"13296","79.74000","6.64519","0.00642"
"13311","79.83000","6.65272","0.00685"
"13326","79.92000","6.66025","0.00687"
"13341","80.01000","6.66767","0.00675"
"13356","80.10000","6.67520","0.00685"
"13371","80.19000","6.68280","0.00662"
"13386","80.28000","6.69021","0.00697"
"13401","80.37000","6.69774","0.00706"
"13416","80.46000","6.70522","0.00725"
"13431","80.55000","6.71263","0.00703"
"13446","80.64000","6.72022","0.00681"
"13461","80.73000","6.72770","0.00701"
"13476","80.82000","6.73523","0.00733"
"13491","80.91000","6.74276","0.00734"
"13506","81.00000","6.75024","0.00734"
"13521","81.09000","6.75765","0.00756"
"13536","81.18000","6.76519","0.00728"
"13551","81.27000","6.77272","0.00702"
"13566","81.36000","6.78019","0.00753"
"13581","81.45000","6.78773","0.00735"
"13596","81.54000","6.79520","0.00750"
"13611","81.63000","6.80267","0.00718"
"13626","81.72000","6.81009","0.00710"
"13641","81.81000","6.81774","0.00735"
"13656","81.90000","6.82527","0.00739"
"13671","81.99000","6.83269","0.00746"
"13686","82.08000","6.84022","0.00759"
"13701","82.17000","6.84770","0.00698"
"13716","82.26000","6.85517","0.00730"
"13731","82.35000","6.86270","0.00741"
"13746","82.44000","6.87024","0.00753"
"13761","82.53000","6.87771","0.00758"
"13776","82.62000","6.88518","0.00764"
"13791","82.71000","6.89272","0.00751"
"13806","82.80000","6.90019","0.00758"
"13821","82.89000","6.90766","0.00749"
"13836","82.98000","6.91520","0.00734"
"13851","83.07000","6.92273","0.00768"
"13866","83.16000","6.93015","0.00751"
"13881","83.25000","6.93768","0.00767"
"13896","83.34000","6.94515","0.00771"
"13911","83.43000","6.95269","0.00797"
"13926","83.52000","6.96022","0.00794"
"13941","83.61000","6.96763","0.00801"
"13956","83.70000","6.97517","0.00797"
"13971","83.79000","6.98264","0.00766"
"13986","83.88000","6.99011","0.00774"
"14001","83.97000","6.99771","0.00804"
"14016","84.06000","7.00524","0.00829"
"14031","84.15000","7.01271","0.00807"
"14046","84.24000","7.02019","0.00800"
"14061","84.33000","7.02766","0.00813"
"14076","84.42000","7.03519","0.00841"
"14091","84.51000","7.04279","0.00861"
"14106","84.60000","7.05020","0.00839"
"14121","84.69000","7.05774","0.00817"
"14136","84.78000","7.06527","0.00851"
"14151","84.87000","7.07262","0.00835"
"14166","84.96000","7.08022","0.00847"
"14181","85.05000","7.08775","0.00878"
"14196","85.14000","7.09522","0.00850"
"14211","85.23000","7.10276","0.00887"
"14226","85.32000","7.11023","0.00886"
"14241","85.41000","7.11770","0.00891"
"14256","85.50000","7.12518","0.00904"
"14271","85.59000","7.13271","0.00889"
"14286","85.68000","7.14025","0.00898"
"14301","85.77000","7.14772","0.00929"
"14316","85.86000","7.15519","0.00918"
"14331","85.95000","7.16267","0.00902"
"14346","86.04000","7.17014","0.00927"
"14361","86.13000","7.17767","0.00934"
"14376","86.22000","7.18521","0.00923"
"14391","86.31000","7.19274","0.00947"
"14406","86.40000","7.20015","0.00933"
"14421","86.49000","7.20763","0.00936"
"14436","86.58000","7.21522","0.00930"
"14451","86.67000","7.22270","0.00974"
"14466","86.76000","7.23023","0.00922"
"14481","86.85000","7.23770","0.00942"
"14496","86.94000","7.24518","0.00947"
"14511","87.03000","7.25265","0.00986"
"14526","87.12000","7.26024","0.00992"
"14541","87.21000","7.26772","0.00959"
"14556","87.30000","7.27519","0.00955"
"14571","87.39000","7.28272","0.00958"
"14586","87.48000","7.29020","0.00987"
"14601","87.57000","7.29767","0.00978"
"14616","87.66000","7.30521","0.01025"
"14631","87.75000","7.31268","0.01013"
"14646","87.84000","7.32021","0.00995"
"14661","87.93000","7.32769","0.01020"
"14676","88.02000","7.33516","0.01019"
"14691","88.11000","7.34269","0.01015"
"14706","88.20000","7.35017","0.01021"
"14721","88.29000","7.35770","0.01020"
"14736","88.38000","7.36523","0.01057"
"14751","88.47000","7.37271","0.01021"
"14766","88.56000","7.38018","0.01043"
"14781","88.65000","7.38765","0.01049"
"14796","88.74000","7.39519","0.01033"
"14811","88.83000","7.40278","0.01041"
"14826","88.92000","7.41020","0.01078"
"14841","89.01000","7.41767","0.01068"
"14856","89.10000","7.42520","0.01099"
"14871","89.19000","7.43262","0.01075"
"14886","89.28000","7.44021","0.01079"
"14901","89.37000","7.44774","0.01085"
"14916","89.46000","7.45522","0.01112"
"14931","89.55000","7.46275","0.01112"
"14946","89.64000","7.47016","0.01119"
"14961","89.73000","7.47764","0.01110"
"14976","89.82000","7.48523","0.01141"
"14991","89.91000","7.49276","0.01111"
"15006","90.00000","7.50024","0.01141"
"15021","90.09000","7.50771","0.01129"
"15036","90.18000","7.51519","0.01116"
"15051","90.27000","7.52260","0.01135"
"15066","90.36000","7.53019","0.01123"
"15081","90.45000","7.53779","0.01171"
"15096","90.54000","7.54520","0.01153"
"15111","90.63000","7.55273","0.01143"
"15126","90.72000","7.56021","0.01191"
"15141","90.81000","7.56768","0.01185"
"15156","90.90000","7.57515","0.01183"
"15171","90.99000","7.58275","0.01183"
"15186","91.08000","7.59022","0.01189"
"15201","91.17000","7.59769","0.01201"
"15216","91.26000","7.60523","0.01220"
"15231","91.35000","7.61264","0.01224"
"15246","91.44000","7.62018","0.01207"
"15261","91.53000","7.62771","0.01239"
"15276","91.62000","7.63518","0.01227"
"15291","91.71000","7.64272","0.01254"
"15306","91.80000","7.65019","0.01229"
"15321","91.89000","7.65760","0.01271"
"15336","91.98000","7.66526","0.01274"
"15351","92.07000","7.67273","0.01265"
"15366","92.16000","7.68021","0.01248"
"15381","92.25000","7.68774","0.01297"
"15396","92.34000","7.69515","0.01271"
"15411","92.43000","7.70269","0.01292"
"15426","92.52000","7.71016","0.01304"
"15441","92.61000","7.71769","0.01302"
"15456","92.70000","7.72523","0.01288"
"15471","92.79000","7.73270","0.01328"
"15486","92.88000","7.74017","0.01324"
"15501","92.97000","7.74771","0.01306"
"15516","93.06000","7.75518","0.01332"
"15531","93.15000","7.76271","0.01353"
"15546","93.24000","7.77019","0.01359"
"15561","93.33000","7.77766","0.01396"
"15576","93.42000","7.78520","0.01375"
"15591","93.51000","7.79261","0.01382"
"15606","93.60000","7.80020","0.01370"
"15621","93.69000","7.80774","0.01404"
"15636","93.78000","7.81521","0.01397"
"15651","93.87000","7.82268","0.01432"
"15666","93.96000","7.83016","0.01355"
"15681","94.05000","7.83769","0.01360"
"15696","94.14000","7.84516","0.01386"
"15711","94.23000","7.85270","0.01382"
"15726","94.32000","7.86023","0.01412"
"15741","94.41000","7.86770","0.01408"
"15756","94.50000","7.87518","0.01443"
"15771","94.59000","7.88265","0.01440"
"15786","94.68000","7.89019","0.01434"
"15801","94.77000","7.89772","0.01458"
"15816","94.86000","7.90525","0.01447"
"15831","94.95000","7.91267","0.01484"
"15846","95.04000","7.92020","0.01536"
"15861","95.13000","7.92773","0.01500"
"15876","95.22000","7.93521","0.01509"
"15891","95.31000","7.94274","0.01534"
"15906","95.40000","7.95021","0.01555"
"15921","95.49000","7.95769","0.01555"
"15936","95.58000","7.96516","0.01552"
"15951","95.67000","7.97264","0.01587"
"15966","95.76000","7.98017","0.01582"
"15981","95.85000","7.98776","0.01598"
"15996","95.94000","7.99524","0.01578"
"16011","96.03000","8.00265","0.01609"
"16026","96.12000","8.01018","0.01631"
"16041","96.21000","8.01760","0.01667"
"16056","96.30000","8.02519","0.01673"
"16071","96.39000","8.03272","0.01639"
"16086","96.48000","8.04020","0.01681"
"16101","96.57000","8.04773","0.01690"
"16116","96.66000","8.05515","0.01703"
"16131","96.75000","8.06268","0.01719"
"16146","96.84000","8.07021","0.01707"
"16161","96.93000","8.07769","0.01735"
"16176","97.02000","8.08522","0.01749"
"16191","97.11000","8.09275","0.01791"
"16206","97.20000","8.10017","0.01760"
"16221","97.29000","8.10770","0.01762"
"16236","97.38000","8.11523","0.01796"
"16251","97.47000","8.12271","0.01786"
"16266","97.56000","8.13024","0.01787"
"16281","97.65000","8.13771","0.01823"
"16296","97.74000","8.14513","0.01895"
"16311","97.83000","8.15266","0.01820"
"16326","97.92000","8.16025","0.01849"
"16341","98.01000","8.16773","0.01853"
"16356","98.10000","8.17526","0.01859"
"16371","98.19000","8.18268","0.01848"
"16386","98.28000","8.19015","0.01284"
"16401","98.37000","8.19762","0.01172"
"16416","98.46000","8.20522","0.01092"
"16431","98.55000","8.21275","0.01132"
"16446","98.64000","8.22022","0.01041"
"16461","98.73000","8.22776","0.01148"
"16476","98.82000","8.23517","0.01228"
"16491","98.91000","8.24264","0.01211"
"16506","99.00000","8.25024","0.01150"
"16521","99.09000","8.25771","0.01097"
"16536","99.18000","8.26524","0.01111"
"16551","99.27000","8.27272","0.01237"
"16566","99.36000","8.28019","0.01248"
"16581","99.45000","8.28773","0.01212"
"16596","99.54000","8.29520","0.01159"
"16611","99.63000","8.30273","0.01178"
"16626","99.72000","8.31027","0.01194"
"16641","99.81000","8.31768","0.01255"
"16656","99.90000","8.32515","0.01264"
"16671","99.99000","8.33275","0.01267"
"16686","100.08000","8.34016","0.01280"
"16701","100.17000","8.34775","0.01204"
"16716","100.26000","8.35523","0.01236"
"16731","100.35000","8.36270","0.01271"
"16746","100.44000","8.37018","0.01321"
"16761","100.53000","8.37765","0.01306"
"16776","100.62000","8.38524","0.01289"
"16791","100.71000","8.39278","0.01236"
"16806","100.80000","8.40025","0.01265"
"16821","100.89000","8.40772","0.01313"
"16836","100.98000","8.41520","0.01404"
"16851","101.07000","8.42267","0.01350"
"16866","101.16000","8.43020","0.01361"
"16881","101.25000","8.43768","0.01302"
"16896","101.34000","8.44527","0.01309"
"16911","101.43000","8.45275","0.01348"
"16926","101.52000","8.46022","0.01361"
"16941","101.61000","8.46769","0.01314"
"16956","101.70000","8.47517","0.01291"
"16971","101.79000","8.48264","0.01308"
"16986","101.88000","8.49023","0.01275"
"17001","101.97000","8.49771","0.01295"
"17016","102.06000","8.50518","0.01359"
"17031","102.15000","8.51265","0.01348"
"17046","102.24000","8.52019","0.01321"
"17061","102.33000","8.52772","0.01291"
"17076","102.42000","8.53520","0.01239"
"17091","102.51000","8.54267","0.01296"
"17106","102.60000","8.55020","0.01327"
"17121","102.69000","8.55762","0.01018"
"17136","102.78000","8.56521","0.01132"
"17151","102.87000","8.57274","0.01206"
"17166","102.96000","8.58022","0.01090"
"17181","103.05000","8.58769","0.01032"
"17196","103.14000","8.59522","0.01062"
"17211","103.23000","8.60270","0.01110"
"17226","103.32000","8.61023","0.01241"
"17241","103.41000","8.61770","0.01200"
"17256","103.50000","8.62524","0.01129"
"17271","103.59000","8.63277","0.01058"
"17286","103.68000","8.64019","0.01107"
"17301","103.77000","8.64766","0.01216"
"17316","103.86000","8.65525","0.01237"
"17331","103.95000","8.66273","0.01246"
"17346","104.04000","8.67020","0.01112"
"17361","104.13000","8.67767","0.01102"
"17376","104.22000","8.68515","0.01174"
"17391","104.31000","8.69268","0.01262"
"17406","104.40000","8.70015","0.01302"
"17421","104.49000","8.70775","0.01284"
"17436","104.58000","8.71522","0.01167"
"17451","104.67000","8.72264","0.01172"
"17466","104.76000","8.73023","0.01236"
"17481","104.85000","8.73770","0.01333"
"17496","104.94000","8.74518","0.01373"
"17511","105.03000","8.75277","0.01258"
"17526","105.12000","8.76024","0.01210"
"17541","105.21000","8.76766","0.01263"
"17556","105.30000","8.77519","0.01259"
"17571","105.39000","8.78272","0.01344"
"17586","105.48000","8.79020","0.01349"
"17601","105.57000","8.79773","0.01283"
"17616","105.66000","8.80526","0.01298"
"17631","105.75000","8.81268","0.01279"
"17646","105.84000","8.82015","0.01325"
"17661","105.93000","8.82769","0.01337"
"17676","106.02000","8.83528","0.01231"
"17691","106.11000","8.84275","0.00140"
"17706","106.20000","8.85023","0.00238"
"17721","106.29000","8.85770","0.00278"
"17736","106.38000","8.86511","0.00483"
"17751","106.47000","8.87271","0.00175"
"17766","106.56000","8.88024","0.00097"
"17781","106.65000","8.88771","0.00061"
"17796","106.74000","8.89525","0.00032"
"17811","106.83000","8.90272","0.00084"
"17826","106.92000","8.91020","0.00107"
"17841","107.01000","8.91767","0.00176"
"17856","107.10000","8.92520","0.00195"
"17871","107.19000","8.93274","0.00110"
"17886","107.28000","8.94021","0.00065"
"17901","107.37000","8.94768","0.00080"
"17916","107.46000","8.95516","0.00061"
"17931","107.55000","8.96263","0.00156"
"17946","107.64000","8.97022","0.00158"
"17961","107.73000","8.97770","0.00162"
"17976","107.82000","8.98517","0.00097"
"17991","107.91000","8.99270","0.00094"
"18006","108.00000","9.00018","0.00123"
"18021","108.09000","9.00771","0.00067"
"18036","108.18000","9.01525","0.00139"
"18051","108.27000","9.02272","0.00154"
"18066","108.36000","9.03025","0.00124"
"18081","108.45000","9.03767","0.00136"
"18096","108.54000","9.04514","0.00091"
"18111","108.63000","9.05273","0.00093"
"18126","108.72000","9.06021","0.00143"
"18141","108.81000","9.06768","0.00106"
"18156","108.90000","9.07527","0.00162"
"18171","108.99000","9.08263","0.00162"
"18186","109.08000","9.09016","0.00137"
"18201","109.17000","9.09770","0.00123"
"18216","109.26000","9.10523","0.00094"
"18231","109.35000","9.11270","0.00124"
"18246","109.44000","9.12018","0.00110"
"18261","109.53000","9.12771","0.00096"
"18276","109.62000","9.13518","0.00154"
"18291","109.71000","9.14272","0.00140"
"18306","109.80000","9.15019","0.00109"
"18321","109.89000","9.15772","0.00127"
"18336","109.98000","9.16526","0.00133"
"18351","110.07000","9.17273","0.00158"
"18366","110.16000","9.18021","0.00198"
"18381","110.25000","9.18768","0.00180"
"18396","110.34000","9.19521","0.00150"
"18411","110.43000","9.20269","0.00110"
"18426","110.52000","9.21022","0.00171"
"18441","110.61000","9.21769","0.00185"
"18456","110.70000","9.22517","0.00150"
"18471","110.79000","9.23270","0.00176"
"18486","110.88000","9.24023","0.00079"
"18501","110.97000","9.24771","0.00126"
"18516","111.06000","9.25524","0.00133"
"18531","111.15000","9.26271","0.00199"
"18546","111.24000","9.27019","0.00164"
"18561","111.33000","9.27766","0.00211"
"18576","111.42000","9.28519","0.00184"
"18591","111.51000","9.29273","0.00145"
"18606","111.60000","9.30020","0.00177"
"18621","111.69000","9.30768","0.00129"
"18636","111.78000","9.31515","0.00158"
"18651","111.87000","9.32268","0.00178"
"18666","111.96000","9.33028","0.00150"
"18681","112.05000","9.33775","0.00162"
"18696","112.14000","9.34522","0.00124"
"18711","112.23000","9.35270","0.00199"
"18726","112.32000","9.36017","0.00137"
"18741","112.41000","9.36765","0.00146"
"18756","112.50000","9.37530","0.00185"
"18771","112.59000","9.38265","0.00167"
"18786","112.68000","9.39019","0.00147"
"18801","112.77000","9.39772","0.00208"
"18816","112.86000","9.40513","0.00195"
"18831","112.95000","9.41267","0.00196"
"18846","113.04000","9.42020","0.00191"
"18861","113.13000","9.42773","0.00175"
"18876","113.22000","9.43521","0.00200"
"18891","113.31000","9.44268","0.00195"
"18906","113.40000","9.45021","0.00171"
"18921","113.49000","9.45775","0.00136"
"18936","113.58000","9.46522","0.00188"
"18951","113.67000","9.47270","0.00166"
"18966","113.76000","9.48023","0.00221"
"18981","113.85000","9.48764","0.00210"
"18996","113.94000","9.49518","0.00155"
"19011","114.03000","9.50271","0.00167"
"19026","114.12000","9.51024","0.00229"
"19041","114.21000","9.51772","0.00179"
"19056","114.30000","9.52519","0.00175"
"19066","114.35800","9.53003","0.00179"