File: Trajectories_together/161223Specimen_RawData_10.csv
"","V1","V2","V3"
"1","End date","12/23/2016",""
"2","Specimen label","17BC_36",""
"3","Maximum Load","1.60068","N"
"4","Time","Extension","Load"
"5","(s)","(mm)","(N)"
"6","0.00000","0.00000","-0.00063"
"52","0.27600","0.02212","0.00030"
"98","0.55200","0.04628","0.00144"
"144","0.82800","0.06930","0.00154"
"190","1.10400","0.09220","0.00219"
"236","1.38000","0.11521","0.00295"
"282","1.65600","0.13817","0.00332"
"328","1.93200","0.16119","0.00435"
"374","2.20800","0.18421","0.00466"
"420","2.48400","0.20723","0.00518"
"466","2.76000","0.23019","0.00555"
"512","3.03600","0.25327","0.00625"
"558","3.31200","0.27623","0.00682"
"604","3.58800","0.29925","0.00731"
"650","3.86400","0.32221","0.00803"
"696","4.14000","0.34522","0.00832"
"742","4.41600","0.36812","0.00837"
"788","4.69200","0.39120","0.00909"
"834","4.96800","0.41416","0.00958"
"880","5.24400","0.43718","0.00985"
"926","5.52000","0.46014","0.01028"
"972","5.79600","0.48328","0.01093"
"1018","6.07200","0.50618","0.01181"
"1064","6.34800","0.52920","0.01166"
"1110","6.62400","0.55222","0.01261"
"1156","6.90000","0.57529","0.01287"
"1202","7.17600","0.59825","0.01333"
"1248","7.45200","0.62127","0.01342"
"1294","7.72800","0.64423","0.01376"
"1340","8.00400","0.66725","0.01374"
"1386","8.28000","0.69021","0.01419"
"1432","8.55600","0.71323","0.01473"
"1478","8.83200","0.73619","0.01542"
"1524","9.10800","0.75921","0.01562"
"1570","9.38400","0.78223","0.01609"
"1616","9.66000","0.80519","0.01583"
"1662","9.93600","0.82826","0.01614"
"1708","10.21200","0.85128","0.01618"
"1754","10.48800","0.87430","0.01700"
"1800","10.76400","0.89726","0.01724"
"1846","11.04000","0.92028","0.01732"
"1892","11.31600","0.94324","0.01754"
"1938","11.59200","0.96626","0.01820"
"1984","11.86800","0.98922","0.01750"
"2030","12.14400","1.01230","0.01747"
"2076","12.42000","1.03526","0.01752"
"2122","12.69600","1.05821","0.01777"
"2168","12.97200","1.08117","0.01873"
"2214","13.24800","1.10425","0.01870"
"2260","13.52400","1.12715","0.01944"
"2306","13.80000","1.15023","0.02026"
"2352","14.07600","1.17319","0.02033"
"2398","14.35200","1.19621","0.02059"
"2444","14.62800","1.21923","0.02086"
"2490","14.90400","1.24225","0.01954"
"2536","15.18000","1.26521","0.01979"
"2582","15.45600","1.28823","0.02007"
"2628","15.73200","1.31118","0.02048"
"2674","16.00800","1.33420","0.02121"
"2720","16.28400","1.35716","0.02132"
"2766","16.56000","1.38024","0.02198"
"2812","16.83600","1.40320","0.02154"
"2858","17.11200","1.42622","0.02069"
"2904","17.38800","1.44924","0.02085"
"2950","17.66400","1.47226","0.02144"
"2996","17.94000","1.49522","0.02195"
"3042","18.21600","1.51830","0.02211"
"3088","18.49200","1.54125","0.02267"
"3134","18.76800","1.56427","0.02278"
"3180","19.04400","1.58717","0.02390"
"3226","19.32000","1.61019","0.02391"
"3272","19.59600","1.63321","0.02468"
"3318","19.87200","1.65623","0.02524"
"3364","20.14800","1.67925","0.02554"
"3410","20.42400","1.70221","0.02561"
"3456","20.70000","1.72523","0.02593"
"3502","20.97600","1.74819","0.02663"
"3548","21.25200","1.77121","0.02705"
"3594","21.52800","1.79416","0.02744"
"3640","21.80400","1.81724","0.02748"
"3686","22.08000","1.84020","0.02821"
"3732","22.35600","1.86322","0.02882"
"3778","22.63200","1.88612","0.02926"
"3824","22.90800","1.90920","0.02889"
"3870","23.18400","1.93216","0.02982"
"3916","23.46000","1.95524","0.03021"
"3962","23.73600","1.97820","0.03051"
"4008","24.01200","2.00128","0.03063"
"4054","24.28800","2.02417","0.03075"
"4100","24.56400","2.04731","0.03117"
"4146","24.84000","2.07021","0.03155"
"4192","25.11600","2.09323","0.03221"
"4238","25.39200","2.11619","0.03248"
"4284","25.66800","2.13921","0.03225"
"4330","25.94400","2.16217","0.03294"
"4376","26.22000","2.18525","0.03346"
"4422","26.49600","2.20815","0.03399"
"4468","26.77200","2.23123","0.03425"
"4514","27.04800","2.25418","0.03461"
"4560","27.32400","2.27726","0.03444"
"4606","27.60000","2.30022","0.03506"
"4652","27.87600","2.32324","0.03529"
"4698","28.15200","2.34626","0.03549"
"4744","28.42800","2.36922","0.03638"
"4790","28.70400","2.39218","0.03665"
"4836","28.98000","2.41520","0.03745"
"4882","29.25600","2.43822","0.03747"
"4928","29.53200","2.46124","0.03801"
"4974","29.80800","2.48420","0.03813"
"5020","30.08400","2.50721","0.03879"
"5066","30.36000","2.53017","0.03895"
"5112","30.63600","2.55313","0.03961"
"5158","30.91200","2.57621","0.04069"
"5204","31.18800","2.59923","0.04018"
"5250","31.46400","2.62225","0.04059"
"5296","31.74000","2.64521","0.04083"
"5342","32.01600","2.66829","0.04217"
"5388","32.29200","2.69119","0.04240"
"5434","32.56800","2.71427","0.04289"
"5480","32.84400","2.73722","0.04351"
"5526","33.12000","2.76024","0.04415"
"5572","33.39600","2.78314","0.04449"
"5618","33.67200","2.80622","0.04473"
"5664","33.94800","2.82918","0.04579"
"5710","34.22400","2.85220","0.04630"
"5756","34.50000","2.87516","0.04704"
"5802","34.77600","2.89824","0.04729"
"5848","35.05200","2.92114","0.04799"
"5894","35.32800","2.94428","0.04887"
"5940","35.60400","2.96724","0.04971"
"5986","35.88000","2.99031","0.05035"
"6032","36.15600","3.01321","0.05067"
"6078","36.43200","3.03623","0.05106"
"6124","36.70800","3.05919","0.05177"
"6170","36.98400","3.08221","0.05216"
"6216","37.26000","3.10517","0.05267"
"6262","37.53600","3.12825","0.05296"
"6308","37.81200","3.15121","0.05346"
"6354","38.08800","3.17423","0.05441"
"6400","38.36400","3.19719","0.05465"
"6446","38.64000","3.22020","0.05513"
"6492","38.91600","3.24328","0.05543"
"6538","39.19200","3.26630","0.05606"
"6584","39.46800","3.28926","0.05613"
"6630","39.74400","3.31228","0.05694"
"6676","40.02000","3.33524","0.05736"
"6722","40.29600","3.35826","0.05715"
"6768","40.57200","3.38122","0.05782"
"6814","40.84800","3.40424","0.05838"
"6860","41.12400","3.42720","0.05874"
"6906","41.40000","3.45016","0.05885"
"6952","41.67600","3.47323","0.05905"
"6998","41.95200","3.49619","0.05950"
"7044","42.22800","3.51927","0.05988"
"7090","42.50400","3.54223","0.06053"
"7136","42.78000","3.56525","0.06081"
"7182","43.05600","3.58815","0.06100"
"7228","43.33200","3.61129","0.06123"
"7274","43.60800","3.63419","0.06178"
"7320","43.88400","3.65727","0.06185"
"7366","44.16000","3.68022","0.06210"
"7412","44.43600","3.70324","0.06252"
"7458","44.71200","3.72620","0.06306"
"7504","44.98800","3.74922","0.06299"
"7550","45.26400","3.77218","0.06354"
"7596","45.54000","3.79526","0.06497"
"7642","45.81600","3.81816","0.06545"
"7688","46.09200","3.84124","0.06633"
"7734","46.36800","3.86420","0.06668"
"7780","46.64400","3.88728","0.06797"
"7826","46.92000","3.91018","0.06738"
"7872","47.19600","3.93325","0.06872"
"7918","47.47200","3.95615","0.06940"
"7964","47.74800","3.97923","0.06988"
"8010","48.02400","4.00219","0.07071"
"8056","48.30000","4.02521","0.07127"
"8102","48.57600","4.04817","0.07232"
"8148","48.85200","4.07125","0.07276"
"8194","49.12800","4.09421","0.07377"
"8240","49.40400","4.11717","0.07471"
"8286","49.68000","4.14019","0.07502"
"8332","49.95600","4.16320","0.07480"
"8378","50.23200","4.18622","0.07572"
"8424","50.50800","4.20930","0.07712"
"8470","50.78400","4.23226","0.07732"
"8516","51.06000","4.25522","0.07711"
"8562","51.33600","4.27818","0.07853"
"8608","51.61200","4.30120","0.07887"
"8654","51.88800","4.32422","0.07918"
"8700","52.16400","4.34724","0.08024"
"8746","52.44000","4.37026","0.08054"
"8792","52.71600","4.39322","0.08098"
"8838","52.99200","4.41623","0.08184"
"8884","53.26800","4.43925","0.08198"
"8930","53.54400","4.46227","0.08210"
"8976","53.82000","4.48517","0.08270"
"9022","54.09600","4.50825","0.08286"
"9068","54.37200","4.53121","0.08338"
"9114","54.64800","4.55423","0.08377"
"9160","54.92400","4.57719","0.08387"
"9206","55.20000","4.60021","0.08435"
"9252","55.47600","4.62317","0.08508"
"9298","55.75200","4.64618","0.08511"
"9344","56.02800","4.66920","0.08517"
"9390","56.30400","4.69222","0.08590"
"9436","56.58000","4.71518","0.08586"
"9482","56.85600","4.73826","0.08689"
"9528","57.13200","4.76116","0.08699"
"9574","57.40800","4.78424","0.08728"
"9620","57.68400","4.80714","0.08761"
"9666","57.96000","4.83022","0.08814"
"9712","58.23600","4.85318","0.08863"
"9758","58.51200","4.87626","0.08847"
"9804","58.78800","4.89915","0.08883"
"9850","59.06400","4.92223","0.08923"
"9896","59.34000","4.94513","0.08933"
"9942","59.61600","4.96821","0.09033"
"9988","59.89200","4.99117","0.09025"
"10034","60.16800","5.01425","0.09108"
"10080","60.44400","5.03721","0.09168"
"10126","60.72000","5.06023","0.09185"
"10172","60.99600","5.08325","0.09201"
"10218","61.27200","5.10627","0.09237"
"10264","61.54800","5.12922","0.09318"
"10310","61.82400","5.15224","0.09338"
"10356","62.10000","5.17520","0.09364"
"10402","62.37600","5.19816","0.09446"
"10448","62.65200","5.22124","0.09478"
"10494","62.92800","5.24420","0.09489"
"10540","63.20400","5.26722","0.09569"
"10586","63.48000","5.29024","0.09551"
"10632","63.75600","5.31326","0.09614"
"10678","64.03200","5.33622","0.09680"
"10724","64.30800","5.35929","0.09701"
"10770","64.58400","5.38219","0.09751"
"10816","64.86000","5.40527","0.09815"
"10862","65.13600","5.42817","0.09858"
"10908","65.41200","5.45125","0.09883"
"10954","65.68800","5.47415","0.09983"
"11000","65.96400","5.49717","0.10037"
"11046","66.24000","5.52013","0.10138"
"11092","66.51600","5.54321","0.10086"
"11138","66.79200","5.56617","0.10197"
"11184","67.06800","5.58919","0.10231"
"11230","67.34400","5.61214","0.10265"
"11276","67.62000","5.63528","0.10333"
"11322","67.89600","5.65818","0.10397"
"11368","68.17200","5.68126","0.10521"
"11414","68.44800","5.70422","0.10536"
"11460","68.72400","5.72730","0.10538"
"11506","69.00000","5.75020","0.10652"
"11552","69.27600","5.77322","0.10684"
"11598","69.55200","5.79618","0.10744"
"11644","69.82800","5.81920","0.10760"
"11690","70.10400","5.84215","0.10867"
"11736","70.38000","5.86523","0.10914"
"11782","70.65600","5.88819","0.10910"
"11828","70.93200","5.91121","0.10979"
"11874","71.20800","5.93423","0.10998"
"11920","71.48400","5.95725","0.11105"
"11966","71.76000","5.98021","0.11136"
"12012","72.03600","6.00323","0.11183"
"12058","72.31200","6.02625","0.11214"
"12104","72.58800","6.04921","0.11290"
"12150","72.86400","6.07223","0.11345"
"12196","73.14000","6.09518","0.11473"
"12242","73.41600","6.11820","0.11593"
"12288","73.69200","6.14110","0.11598"
"12334","73.96800","6.16424","0.11766"
"12380","74.24400","6.18720","0.11815"
"12426","74.52000","6.21028","0.11928"
"12472","74.79600","6.23324","0.12028"
"12518","75.07200","6.25626","0.12094"
"12564","75.34800","6.27922","0.12202"
"12610","75.62400","6.30229","0.12269"
"12656","75.90000","6.32519","0.12400"
"12702","76.17600","6.34827","0.12517"
"12748","76.45200","6.37117","0.12624"
"12794","76.72800","6.39425","0.12745"
"12840","77.00400","6.41715","0.12871"
"12886","77.28000","6.44023","0.13008"
"12932","77.55600","6.46319","0.13065"
"12978","77.83200","6.48621","0.13130"
"13024","78.10800","6.50917","0.13247"
"13070","78.38400","6.53225","0.13397"
"13116","78.66000","6.55520","0.13511"
"13162","78.93600","6.57828","0.13574"
"13208","79.21200","6.60118","0.13676"
"13254","79.48800","6.62426","0.13780"
"13300","79.76400","6.64716","0.13852"
"13346","80.04000","6.67024","0.13914"
"13392","80.31600","6.69320","0.14017"
"13438","80.59200","6.71622","0.14073"
"13484","80.86800","6.73918","0.14110"
"13530","81.14400","6.76226","0.14235"
"13576","81.42000","6.78516","0.14264"
"13622","81.69600","6.80817","0.14359"
"13668","81.97200","6.83125","0.14466"
"13714","82.24800","6.85421","0.14516"
"13760","82.52400","6.87723","0.14643"
"13806","82.80000","6.90025","0.14663"
"13852","83.07600","6.92327","0.14812"
"13898","83.35200","6.94623","0.14826"
"13944","83.62800","6.96925","0.14992"
"13990","83.90400","6.99215","0.15048"
"14036","84.18000","7.01523","0.15155"
"14082","84.45600","7.03818","0.15245"
"14128","84.73200","7.06126","0.15351"
"14174","85.00800","7.08422","0.15466"
"14220","85.28400","7.10724","0.15555"
"14266","85.56000","7.13020","0.15662"
"14312","85.83600","7.15322","0.15704"
"14358","86.11200","7.17618","0.15818"
"14404","86.38800","7.19920","0.15975"
"14450","86.66400","7.22216","0.16079"
"14496","86.94000","7.24524","0.16205"
"14542","87.21600","7.26820","0.16243"
"14588","87.49200","7.29121","0.16265"
"14634","87.76800","7.31417","0.16398"
"14680","88.04400","7.33719","0.16453"
"14726","88.32000","7.36021","0.16469"
"14772","88.59600","7.38323","0.16579"
"14818","88.87200","7.40619","0.16675"
"14864","89.14800","7.42921","0.16714"
"14910","89.42400","7.45217","0.16810"
"14956","89.70000","7.47525","0.16883"
"15002","89.97600","7.49821","0.16956"
"15048","90.25200","7.52122","0.17009"
"15094","90.52800","7.54418","0.17101"
"15140","90.80400","7.56720","0.17223"
"15186","91.08000","7.59016","0.17311"
"15232","91.35600","7.61324","0.17192"
"15278","91.63200","7.63620","0.17325"
"15324","91.90800","7.65922","0.17428"
"15370","92.18400","7.68224","0.17584"
"15416","92.46000","7.70520","0.17642"
"15462","92.73600","7.72822","0.17771"
"15508","93.01200","7.75124","0.17857"
"15554","93.28800","7.77419","0.17948"
"15600","93.56400","7.79721","0.18056"
"15646","93.84000","7.82023","0.18141"
"15692","94.11600","7.84325","0.18211"
"15738","94.39200","7.86621","0.18282"
"15784","94.66800","7.88917","0.18362"
"15830","94.94400","7.91219","0.18450"
"15876","95.22000","7.93521","0.18536"
"15922","95.49600","7.95823","0.18629"
"15968","95.77200","7.98118","0.18698"
"16014","96.04800","8.00426","0.18779"
"16060","96.32400","8.02722","0.18847"
"16106","96.60000","8.05024","0.18895"
"16152","96.87600","8.07320","0.19022"
"16198","97.15200","8.09622","0.19145"
"16244","97.42800","8.11918","0.19229"
"16290","97.70400","8.14220","0.19350"
"16336","97.98000","8.16522","0.19455"
"16382","98.25600","8.18824","0.19483"
"16428","98.53200","8.21119","0.19643"
"16474","98.80800","8.23421","0.19698"
"16520","99.08400","8.25717","0.19751"
"16566","99.36000","8.28019","0.19878"
"16612","99.63600","8.30321","0.19941"
"16658","99.91200","8.32623","0.19941"
"16704","100.18800","8.34919","0.20001"
"16750","100.46400","8.37221","0.20029"
"16796","100.74000","8.39517","0.20091"
"16842","101.01600","8.41825","0.20146"
"16888","101.29200","8.44115","0.20212"
"16934","101.56800","8.46428","0.20293"
"16980","101.84400","8.48718","0.20354"
"17026","102.12000","8.51020","0.20393"
"17072","102.39600","8.53316","0.20478"
"17118","102.67200","8.55624","0.20616"
"17164","102.94800","8.57920","0.20707"
"17210","103.22400","8.60222","0.20781"
"17256","103.50000","8.62518","0.20854"
"17302","103.77600","8.64826","0.20980"
"17348","104.05200","8.67122","0.21035"
"17394","104.32800","8.69423","0.21130"
"17440","104.60400","8.71725","0.21197"
"17486","104.88000","8.74027","0.21318"
"17532","105.15600","8.76323","0.21404"
"17578","105.43200","8.78619","0.21454"
"17624","105.70800","8.80921","0.21597"
"17670","105.98400","8.83217","0.21688"
"17716","106.26000","8.85525","0.21797"
"17762","106.53600","8.87821","0.21885"
"17808","106.81200","8.90129","0.21966"
"17854","107.08800","8.92419","0.22068"
"17900","107.36400","8.94732","0.22160"
"17946","107.64000","8.97022","0.22258"
"17992","107.91600","8.99330","0.22363"
"18038","108.19200","9.01626","0.22436"
"18084","108.46800","9.03922","0.22580"
"18130","108.74400","9.06218","0.22687"
"18176","109.02000","9.08526","0.22838"
"18222","109.29600","9.10816","0.22980"
"18268","109.57200","9.13124","0.23163"
"18314","109.84800","9.15414","0.23237"
"18360","110.12400","9.17722","0.23395"
"18406","110.40000","9.20017","0.23472"
"18452","110.67600","9.22325","0.23323"
"18498","110.95200","9.24615","0.23408"
"18544","111.22800","9.26923","0.23562"
"18590","111.50400","9.29219","0.23685"
"18636","111.78000","9.31527","0.23801"
"18682","112.05600","9.33817","0.23907"
"18728","112.33200","9.36131","0.24009"
"18774","112.60800","9.38421","0.24171"
"18820","112.88400","9.40722","0.24271"
"18866","113.16000","9.43019","0.24413"
"18912","113.43600","9.45326","0.24618"
"18958","113.71200","9.47616","0.24732"
"19004","113.98800","9.49924","0.24969"
"19050","114.26400","9.52220","0.25018"
"19096","114.54000","9.54522","0.25211"
"19142","114.81600","9.56818","0.25339"
"19188","115.09200","9.59126","0.25501"
"19234","115.36800","9.61428","0.25600"
"19280","115.64400","9.63724","0.25776"
"19326","115.92000","9.66026","0.25892"
"19372","116.19600","9.68321","0.25989"
"19418","116.47200","9.70617","0.26115"
"19464","116.74800","9.72919","0.26199"
"19510","117.02400","9.75221","0.26339"
"19556","117.30000","9.77517","0.26445"
"19602","117.57600","9.79825","0.26603"
"19648","117.85200","9.82121","0.26674"
"19694","118.12800","9.84429","0.26835"
"19740","118.40400","9.86719","0.27002"
"19786","118.68000","9.89026","0.27233"
"19832","118.95600","9.91323","0.27399"
"19878","119.23200","9.93630","0.27669"
"19924","119.50800","9.95920","0.27957"
"19970","119.78400","9.98222","0.28156"
"20016","120.06000","10.00518","0.28431"
"20062","120.33600","10.02820","0.28539"
"20108","120.61200","10.05116","0.28637"
"20154","120.88800","10.07424","0.28872"
"20200","121.16400","10.09714","0.29067"
"20246","121.44000","10.12022","0.29167"
"20292","121.71600","10.14318","0.29329"
"20338","121.99200","10.16625","0.29419"
"20384","122.26800","10.18921","0.29539"
"20430","122.54400","10.21223","0.29614"
"20476","122.82000","10.23519","0.29733"
"20522","123.09600","10.25821","0.29831"
"20568","123.37200","10.28117","0.29936"
"20614","123.64800","10.30419","0.30021"
"20660","123.92400","10.32721","0.30091"
"20706","124.20000","10.35023","0.30239"
"20752","124.47600","10.37318","0.30389"
"20798","124.75200","10.39620","0.30414"
"20844","125.02800","10.41922","0.30504"
"20890","125.30400","10.44224","0.30616"
"20936","125.58000","10.46520","0.30774"
"20982","125.85600","10.48822","0.30839"
"21028","126.13200","10.51124","0.30940"
"21074","126.40800","10.53426","0.31013"
"21120","126.68400","10.55728","0.31098"
"21166","126.96000","10.58018","0.31142"
"21212","127.23600","10.60320","0.31050"
"21258","127.51200","10.62621","0.31238"
"21304","127.78800","10.64923","0.31273"
"21350","128.06400","10.67219","0.31371"
"21396","128.34000","10.69527","0.31451"
"21442","128.61600","10.71823","0.31543"
"21488","128.89200","10.74125","0.31667"
"21534","129.16800","10.76415","0.31773"
"21580","129.44400","10.78723","0.31884"
"21626","129.72000","10.81019","0.31789"
"21672","129.99600","10.83321","0.31858"
"21718","130.27200","10.85622","0.31944"
"21764","130.54800","10.87924","0.31999"
"21810","130.82400","10.90214","0.32185"
"21856","131.10000","10.92516","0.32337"
"21902","131.37600","10.94812","0.32449"
"21948","131.65200","10.97120","0.32575"
"21994","131.92800","10.99416","0.32760"
"22040","132.20400","11.01724","0.33005"
"22086","132.48000","11.04020","0.33131"
"22132","132.75600","11.06328","0.33353"
"22178","133.03200","11.08624","0.33596"
"22224","133.30800","11.10925","0.33760"
"22270","133.58400","11.13221","0.31999"
"22316","133.86000","11.15523","0.32111"
"22362","134.13600","11.17819","0.32237"
"22408","134.41200","11.20121","0.32421"
"22454","134.68800","11.22423","0.32629"
"22500","134.96400","11.24725","0.32217"
"22546","135.24000","11.27027","0.32334"
"22592","135.51600","11.29323","0.31623"
"22638","135.79200","11.31618","0.31755"
"22684","136.06800","11.33926","0.31831"
"22730","136.34400","11.36222","0.31954"
"22776","136.62000","11.38530","0.32118"
"22822","136.89600","11.40826","0.32263"
"22868","137.17200","11.43122","0.32412"
"22914","137.44800","11.45418","0.32697"
"22960","137.72400","11.47720","0.32926"
"23006","138.00000","11.50022","0.33241"
"23052","138.27600","11.52318","0.33609"
"23098","138.55200","11.54626","0.33905"
"23144","138.82800","11.56921","0.34118"
"23190","139.10400","11.59223","0.34273"
"23236","139.38000","11.61525","0.34455"
"23282","139.65600","11.63827","0.34707"
"23328","139.93200","11.66117","0.34830"
"23374","140.20800","11.68425","0.35072"
"23420","140.48400","11.70721","0.35344"
"23466","140.76000","11.73023","0.35591"
"23512","141.03600","11.75325","0.35789"
"23558","141.31200","11.77627","0.35981"
"23604","141.58800","11.79922","0.36178"
"23650","141.86400","11.82224","0.36470"
"23696","142.14000","11.84514","0.36691"
"23742","142.41600","11.86822","0.36822"
"23788","142.69200","11.89118","0.37009"
"23834","142.96800","11.91426","0.37185"
"23880","143.24400","11.93716","0.37300"
"23926","143.52000","11.96024","0.37391"
"23972","143.79600","11.98320","0.37545"
"24018","144.07200","12.00628","0.37689"
"24064","144.34800","12.02924","0.35919"
"24110","144.62400","12.05225","0.36002"
"24156","144.90000","12.07521","0.36157"
"24202","145.17600","12.09823","0.36393"
"24248","145.45200","12.12119","0.36581"
"24294","145.72800","12.14421","0.36752"
"24340","146.00400","12.16717","0.36957"
"24386","146.28000","12.19025","0.37111"
"24432","146.55600","12.21321","0.37249"
"24478","146.83200","12.23623","0.37347"
"24524","147.10800","12.25925","0.37567"
"24570","147.38400","12.28226","0.37793"
"24616","147.66000","12.30528","0.37902"
"24662","147.93600","12.32824","0.38154"
"24708","148.21200","12.35120","0.38314"
"24754","148.48800","12.37422","0.38615"
"24800","148.76400","12.39724","0.38832"
"24846","149.04000","12.42020","0.38869"
"24892","149.31600","12.44322","0.39012"
"24938","149.59200","12.46618","0.39143"
"24984","149.86800","12.48926","0.39269"
"25030","150.14400","12.51222","0.39396"
"25076","150.42000","12.53523","0.39132"
"25122","150.69600","12.55819","0.39292"
"25168","150.97200","12.58121","0.39377"
"25214","151.24800","12.60423","0.39535"
"25260","151.52400","12.62725","0.39671"
"25306","151.80000","12.65021","0.39790"
"25352","152.07600","12.67323","0.39928"
"25398","152.35200","12.69619","0.40041"
"25444","152.62800","12.71921","0.40155"
"25490","152.90400","12.74217","0.40262"
"25536","153.18000","12.76525","0.40443"
"25582","153.45600","12.78814","0.40554"
"25628","153.73200","12.81128","0.40889"
"25674","154.00800","12.83418","0.41099"
"25720","154.28400","12.85726","0.41309"
"25766","154.56000","12.88022","0.41583"
"25812","154.83600","12.90324","0.41750"
"25858","155.11200","12.92620","0.41904"
"25904","155.38800","12.94928","0.42048"
"25950","155.66400","12.97218","0.42221"
"25996","155.94000","12.99526","0.42393"
"26042","156.21600","13.01821","0.42566"
"26088","156.49200","13.04123","0.42786"
"26134","156.76800","13.06419","0.42912"
"26180","157.04400","13.08721","0.43043"
"26226","157.32000","13.11017","0.43224"
"26272","157.59600","13.13319","0.43367"
"26318","157.87200","13.15621","0.43583"
"26364","158.14800","13.17917","0.43756"
"26410","158.42400","13.20219","0.43971"
"26456","158.70000","13.22521","0.44108"
"26502","158.97600","13.24822","0.43379"
"26548","159.25200","13.27118","0.43523"
"26594","159.52800","13.29420","0.43780"
"26640","159.80400","13.31716","0.43966"
"26686","160.08000","13.34018","0.44151"
"26732","160.35600","13.36320","0.44309"
"26778","160.63200","13.38622","0.44473"
"26824","160.90800","13.40918","0.44634"
"26870","161.18400","13.43226","0.44738"
"26916","161.46000","13.45522","0.44850"
"26962","161.73600","13.47824","0.44992"
"27008","162.01200","13.50119","0.45193"
"27054","162.28800","13.52427","0.45394"
"27100","162.56400","13.54717","0.45575"
"27146","162.84000","13.57025","0.45859"
"27192","163.11600","13.59315","0.46055"
"27238","163.39200","13.61623","0.46309"
"27284","163.66800","13.63913","0.46469"
"27330","163.94400","13.66221","0.46773"
"27376","164.22000","13.68517","0.46858"
"27422","164.49600","13.70825","0.47091"
"27468","164.77200","13.73120","0.47181"
"27514","165.04800","13.75428","0.47400"
"27560","165.32400","13.77724","0.47601"
"27606","165.60000","13.80026","0.47693"
"27652","165.87600","13.82316","0.48055"
"27698","166.15200","13.84618","0.48323"
"27744","166.42800","13.86920","0.48571"
"27790","166.70400","13.89222","0.48857"
"27836","166.98000","13.91518","0.49107"
"27882","167.25600","13.93820","0.49322"
"27928","167.53200","13.96115","0.49593"
"27974","167.80800","13.98417","0.49814"
"28020","168.08400","14.00725","0.50045"
"28066","168.36000","14.03021","0.50261"
"28112","168.63600","14.05323","0.50371"
"28158","168.91200","14.07625","0.50627"
"28204","169.18800","14.09927","0.50783"
"28250","169.46400","14.12223","0.50923"
"28296","169.74000","14.14525","0.51062"
"28342","170.01600","14.16821","0.51149"
"28388","170.29200","14.19123","0.51270"
"28434","170.56800","14.21418","0.51384"
"28480","170.84400","14.23726","0.51501"
"28526","171.12000","14.26022","0.51683"
"28572","171.39600","14.28324","0.51778"
"28618","171.67200","14.30620","0.51852"
"28664","171.94800","14.32928","0.52081"
"28710","172.22400","14.35212","0.52264"
"28756","172.50000","14.37526","0.52458"
"28802","172.77600","14.39822","0.52611"
"28848","173.05200","14.42130","0.52771"
"28894","173.32800","14.44419","0.52910"
"28940","173.60400","14.46721","0.53099"
"28986","173.88000","14.49017","0.53333"
"29032","174.15600","14.51319","0.53534"
"29078","174.43200","14.53615","0.53798"
"29124","174.70800","14.55923","0.53984"
"29170","174.98400","14.58219","0.54208"
"29216","175.26000","14.60527","0.54418"
"29262","175.53600","14.62823","0.54623"
"29308","175.81200","14.65125","0.54804"
"29354","176.08800","14.67421","0.54979"
"29400","176.36400","14.69728","0.55202"
"29446","176.64000","14.72024","0.55362"
"29492","176.91600","14.74320","0.55501"
"29538","177.19200","14.76622","0.53950"
"29584","177.46800","14.78924","0.54225"
"29630","177.74400","14.81220","0.54493"
"29676","178.02000","14.83522","0.54799"
"29722","178.29600","14.85824","0.54979"
"29768","178.57200","14.88120","0.55331"
"29814","178.84800","14.90422","0.55451"
"29860","179.12400","14.92723","0.55816"
"29906","179.40000","14.95025","0.55997"
"29952","179.67600","14.97327","0.56199"
"29998","179.95200","14.99629","0.56377"
"30044","180.22800","15.01925","0.56537"
"30090","180.50400","15.04221","0.53923"
"30136","180.78000","15.06523","0.54267"
"30182","181.05600","15.08819","0.54349"
"30228","181.33200","15.11121","0.54637"
"30274","181.60800","15.13423","0.54868"
"30320","181.88400","15.15719","0.55064"
"30366","182.16000","15.18020","0.55371"
"30412","182.43600","15.20322","0.55640"
"30458","182.71200","15.22624","0.55830"
"30504","182.98800","15.24920","0.56655"
"30550","183.26400","15.27222","0.56916"
"30596","183.54000","15.29524","0.57264"
"30642","183.81600","15.31826","0.57537"
"30688","184.09200","15.34122","0.57761"
"30734","184.36800","15.36424","0.57941"
"30780","184.64400","15.38720","0.58263"
"30826","184.92000","15.41021","0.58309"
"30872","185.19600","15.43317","0.58709"
"30918","185.47200","15.45625","0.59030"
"30964","185.74800","15.47915","0.59492"
"31010","186.02400","15.50223","0.59700"
"31056","186.30000","15.52519","0.59920"
"31102","186.57600","15.54827","0.60130"
"31148","186.85200","15.57117","0.60288"
"31194","187.12800","15.59425","0.60456"
"31240","187.40400","15.61721","0.60679"
"31286","187.68000","15.64028","0.60928"
"31332","187.95600","15.66324","0.61037"
"31378","188.23200","15.68626","0.61156"
"31424","188.50800","15.70916","0.61262"
"31470","188.78400","15.73218","0.61452"
"31516","189.06000","15.75520","0.61580"
"31562","189.33600","15.77822","0.61706"
"31608","189.61200","15.80118","0.61914"
"31654","189.88800","15.82420","0.62083"
"31700","190.16400","15.84727","0.62253"
"31746","190.44000","15.87023","0.62447"
"31792","190.71600","15.89319","0.62652"
"31838","190.99200","15.91627","0.62848"
"31884","191.26800","15.93923","0.63058"
"31930","191.54400","15.96219","0.63267"
"31976","191.82000","15.98527","0.63584"
"32022","192.09600","16.00823","0.63893"
"32068","192.37200","16.03125","0.64149"
"32114","192.64800","16.05421","0.64447"
"32160","192.92400","16.07723","0.64810"
"32206","193.20000","16.10019","0.65078"
"32252","193.47600","16.12326","0.65285"
"32298","193.75200","16.14616","0.65460"
"32344","194.02800","16.16924","0.65684"
"32390","194.30400","16.19214","0.66020"
"32436","194.58000","16.21522","0.66232"
"32482","194.85600","16.23818","0.66534"
"32528","195.13200","16.26126","0.66804"
"32574","195.40800","16.28416","0.67034"
"32620","195.68400","16.30724","0.67260"
"32666","195.96000","16.33014","0.67499"
"32712","196.23600","16.35321","0.67833"
"32758","196.51200","16.37611","0.67976"
"32804","196.78800","16.39925","0.68149"
"32850","197.06400","16.42215","0.68309"
"32896","197.34000","16.44529","0.68581"
"32942","197.61600","16.46825","0.68748"
"32988","197.89200","16.49127","0.69050"
"33034","198.16800","16.51423","0.69414"
"33080","198.44400","16.53725","0.69721"
"33126","198.72000","16.56021","0.70015"
"33172","198.99600","16.58323","0.70157"
"33218","199.27200","16.60618","0.70423"
"33264","199.54800","16.62926","0.70605"
"33310","199.82400","16.65222","0.70851"
"33356","200.10000","16.67518","0.71016"
"33402","200.37600","16.69820","0.71153"
"33448","200.65200","16.72122","0.71273"
"33494","200.92800","16.74418","0.71438"
"33540","201.20400","16.76720","0.71624"
"33586","201.48000","16.79028","0.71753"
"33632","201.75600","16.81324","0.71880"
"33678","202.03200","16.83625","0.72034"
"33724","202.30800","16.85921","0.72238"
"33770","202.58400","16.88223","0.72443"
"33816","202.86000","16.90519","0.72625"
"33862","203.13600","16.92821","0.72864"
"33908","203.41200","16.95117","0.73029"
"33954","203.68800","16.97425","0.73219"
"34000","203.96400","16.99721","0.73366"
"34046","204.24000","17.02023","0.73512"
"34092","204.51600","17.04319","0.73650"
"34138","204.79200","17.06627","0.73932"
"34184","205.06800","17.08922","0.74142"
"34230","205.34400","17.11230","0.74483"
"34276","205.62000","17.13514","0.74769"
"34322","205.89600","17.15828","0.75137"
"34368","206.17200","17.18118","0.75416"
"34414","206.44800","17.20420","0.75466"
"34460","206.72400","17.22716","0.75422"
"34506","207.00000","17.25024","0.75857"
"34552","207.27600","17.27320","0.76318"
"34598","207.55200","17.29627","0.76715"
"34644","207.82800","17.31917","0.77013"
"34690","208.10400","17.34225","0.77393"
"34736","208.38000","17.36521","0.77782"
"34782","208.65600","17.38823","0.78046"
"34828","208.93200","17.41125","0.78288"
"34874","209.20800","17.43427","0.78490"
"34920","209.48400","17.45723","0.78768"
"34966","209.76000","17.48025","0.79047"
"35012","210.03600","17.50321","0.79355"
"35058","210.31200","17.52623","0.79744"
"35104","210.58800","17.54918","0.80163"
"35150","210.86400","17.57214","0.80447"
"35196","211.14000","17.59522","0.80801"
"35242","211.41600","17.61824","0.81073"
"35288","211.69200","17.64126","0.81310"
"35334","211.96800","17.66422","0.81471"
"35380","212.24400","17.68724","0.81769"
"35426","212.52000","17.71026","0.81978"
"35472","212.79600","17.73328","0.82129"
"35518","213.07200","17.75618","0.82298"
"35564","213.34800","17.77925","0.82443"
"35610","213.62400","17.80221","0.82628"
"35656","213.90000","17.82523","0.82769"
"35702","214.17600","17.84819","0.82899"
"35748","214.45200","17.87127","0.83128"
"35794","214.72800","17.89423","0.83367"
"35840","215.00400","17.91725","0.83607"
"35886","215.28000","17.94021","0.83826"
"35932","215.55600","17.96323","0.84041"
"35978","215.83200","17.98625","0.84290"
"36024","216.10800","18.00927","0.84531"
"36070","216.38400","18.03222","0.84846"
"36116","216.66000","18.05530","0.85211"
"36162","216.93600","18.07814","0.85421"
"36208","217.21200","18.10116","0.85673"
"36254","217.48800","18.12412","0.85920"
"36300","217.76400","18.14726","0.86118"
"36346","218.04000","18.17022","0.86307"
"36392","218.31600","18.19324","0.86618"
"36438","218.59200","18.21620","0.86936"
"36484","218.86800","18.23927","0.87151"
"36530","219.14400","18.26217","0.87490"
"36576","219.42000","18.28525","0.87766"
"36622","219.69600","18.30821","0.88032"
"36668","219.97200","18.33123","0.88265"
"36714","220.24800","18.35419","0.88521"
"36760","220.52400","18.37721","0.88777"
"36806","220.80000","18.40023","0.89154"
"36852","221.07600","18.42319","0.89474"
"36898","221.35200","18.44621","0.89858"
"36944","221.62800","18.46917","0.90146"
"36990","221.90400","18.49218","0.90455"
"37036","222.18000","18.51521","0.90764"
"37082","222.45600","18.53822","0.90991"
"37128","222.73200","18.56124","0.91277"
"37174","223.00800","18.58420","0.91620"
"37220","223.28400","18.60722","0.91947"
"37266","223.56000","18.63024","0.92199"
"37312","223.83600","18.65320","0.92416"
"37358","224.11200","18.67622","0.92550"
"37404","224.38800","18.69924","0.92722"
"37450","224.66400","18.72219","0.92936"
"37496","224.94000","18.74521","0.93119"
"37542","225.21600","18.76823","0.93359"
"37588","225.49200","18.79119","0.93721"
"37634","225.76800","18.81415","0.93995"
"37680","226.04400","18.83717","0.94323"
"37726","226.32000","18.86025","0.94783"
"37772","226.59600","18.88321","0.95100"
"37818","226.87200","18.90623","0.95592"
"37864","227.14800","18.92919","0.95930"
"37910","227.42400","18.95226","0.96256"
"37956","227.70000","18.97522","0.96500"
"38002","227.97600","18.99824","0.96767"
"38048","228.25200","19.02114","0.97038"
"38094","228.52800","19.04422","0.97369"
"38140","228.80400","19.06718","0.97780"
"38186","229.08000","19.09026","0.96479"
"38232","229.35600","19.11316","0.91776"
"38278","229.63200","19.13618","0.92011"
"38324","229.90800","19.15914","0.92156"
"38370","230.18400","19.18222","0.92253"
"38416","230.46000","19.20518","0.92489"
"38462","230.73600","19.22825","0.92830"
"38508","231.01200","19.25121","0.93061"
"38554","231.28800","19.27423","0.93305"
"38600","231.56400","19.29719","0.93452"
"38646","231.84000","19.32021","0.93990"
"38692","232.11600","19.34317","0.94507"
"38738","232.39200","19.36619","0.95122"
"38784","232.66800","19.38921","0.95522"
"38830","232.94400","19.41223","0.95921"
"38876","233.22000","19.43525","0.96271"
"38922","233.49600","19.45826","0.96661"
"38968","233.77200","19.48122","0.97032"
"39014","234.04800","19.50424","0.97415"
"39060","234.32400","19.52720","0.97713"
"39106","234.60000","19.55022","0.98158"
"39152","234.87600","19.57324","0.98583"
"39198","235.15200","19.59620","0.98976"
"39244","235.42800","19.61922","0.99269"
"39290","235.70400","19.64224","0.99435"
"39336","235.98000","19.66526","0.99608"
"39382","236.25600","19.68822","0.99940"
"39428","236.53200","19.71123","1.00283"
"39474","236.80800","19.73419","1.00700"
"39520","237.08400","19.75727","1.01028"
"39566","237.36000","19.78023","1.01192"
"39612","237.63600","19.80325","1.01403"
"39658","237.91200","19.82615","1.01603"
"39704","238.18800","19.84923","1.01779"
"39750","238.46400","19.87213","1.01932"
"39796","238.74000","19.89527","1.02166"
"39842","239.01600","19.91817","1.02477"
"39888","239.29200","19.94124","1.02712"
"39934","239.56800","19.96414","1.02947"
"39980","239.84400","19.98728","1.03205"
"40026","240.12000","20.01018","1.02404"
"40072","240.39600","20.03326","1.02566"
"40118","240.67200","20.05622","1.02841"
"40164","240.94800","20.07924","1.03143"
"40210","241.22400","20.10225","1.03389"
"40256","241.50000","20.12528","1.03607"
"40302","241.77600","20.14818","1.03859"
"40348","242.05200","20.17126","1.04172"
"40394","242.32800","20.19421","1.04511"
"40440","242.60400","20.21723","1.05030"
"40486","242.88000","20.24019","1.05480"
"40532","243.15600","20.26321","1.05996"
"40578","243.43200","20.28623","1.06449"
"40624","243.70800","20.30925","1.06625"
"40670","243.98400","20.33221","1.06854"
"40716","244.26000","20.35517","1.07192"
"40762","244.53600","20.37825","1.07477"
"40808","244.81200","20.40127","1.07922"
"40854","245.08800","20.42428","1.08356"
"40900","245.36400","20.44718","1.08766"
"40946","245.64000","20.47020","1.09077"
"40992","245.91600","20.49316","1.09444"
"41038","246.19200","20.51624","1.09780"
"41084","246.46800","20.53920","1.10331"
"41130","246.74400","20.56222","1.10764"
"41176","247.02000","20.58518","1.11174"
"41222","247.29600","20.60826","1.11480"
"41268","247.57200","20.63122","1.11684"
"41314","247.84800","20.65424","1.11925"
"41360","248.12400","20.67719","1.12232"
"41406","248.40000","20.70027","1.12540"
"41452","248.67600","20.72317","1.12845"
"41498","248.95200","20.74625","1.13094"
"41544","249.22800","20.76915","1.13253"
"41590","249.50400","20.79223","1.13471"
"41636","249.78000","20.81519","1.13591"
"41682","250.05600","20.83827","1.13732"
"41728","250.33200","20.86111","1.13860"
"41774","250.60800","20.88424","1.14049"
"41820","250.88400","20.90720","1.14288"
"41866","251.16000","20.93028","1.14489"
"41912","251.43600","20.95318","1.14691"
"41958","251.71200","20.97626","1.15046"
"42004","251.98800","20.99922","1.15389"
"42050","252.26400","21.02224","1.15818"
"42096","252.54000","21.04520","1.16159"
"42142","252.81600","21.06821","1.16473"
"42188","253.09200","21.09118","1.16759"
"42234","253.36800","21.11420","1.17112"
"42280","253.64400","21.13716","1.17594"
"42326","253.92000","21.16017","1.18136"
"42372","254.19600","21.18319","1.18632"
"42418","254.47200","21.20621","1.18987"
"42464","254.74800","21.22923","1.19241"
"42510","255.02400","21.25225","1.19549"
"42556","255.30000","21.27527","1.19934"
"42602","255.57600","21.29823","1.19248"
"42648","255.85200","21.32131","1.19546"
"42694","256.12800","21.34420","1.20152"
"42740","256.40400","21.36728","1.20862"
"42786","256.68000","21.39018","1.21150"
"42832","256.95600","21.41326","1.21462"
"42878","257.23200","21.43622","1.21761"
"42924","257.50800","21.45924","1.22150"
"42970","257.78400","21.48220","1.22431"
"43016","258.06000","21.50522","1.22821"
"43062","258.33600","21.52812","1.23118"
"43108","258.61200","21.55120","1.23386"
"43154","258.88800","21.57415","1.23615"
"43200","259.16400","21.59723","1.23813"
"43246","259.44000","21.62020","1.24131"
"43292","259.71600","21.64327","1.24395"
"43338","259.99200","21.66617","1.24866"
"43384","260.26800","21.68919","1.25344"
"43430","260.54400","21.71215","1.25986"
"43476","260.82000","21.73517","1.26540"
"43522","261.09600","21.75813","1.27093"
"43568","261.37200","21.78121","1.27396"
"43614","261.64800","21.80416","1.27647"
"43660","261.92400","21.82724","1.27913"
"43706","262.20000","21.85020","1.27466"
"43752","262.47600","21.87322","1.27776"
"43798","262.75200","21.89618","1.27026"
"43844","263.02800","21.91920","1.27372"
"43890","263.30400","21.94222","1.27673"
"43936","263.58000","21.96524","1.27932"
"43982","263.85600","21.98820","1.28132"
"44028","264.13200","22.01122","1.28555"
"44074","264.40800","22.03424","1.28872"
"44120","264.68400","22.05719","1.29184"
"44166","264.96000","22.08022","1.29474"
"44212","265.23600","22.10317","1.29646"
"44258","265.51200","22.12625","1.29662"
"44304","265.78800","22.14921","1.29332"
"44350","266.06400","22.17223","1.29489"
"44396","266.34000","22.19519","1.29596"
"44442","266.61600","22.21821","1.29752"
"44488","266.89200","22.24123","1.30074"
"44534","267.16800","22.26425","1.30494"
"44580","267.44400","22.28720","1.30783"
"44626","267.72000","22.31022","1.31194"
"44672","267.99600","22.33318","1.31597"
"44718","268.27200","22.35620","1.31830"
"44764","268.54800","22.37916","1.32327"
"44810","268.82400","22.40224","1.32738"
"44856","269.10000","22.42520","1.33078"
"44902","269.37600","22.44822","1.33411"
"44948","269.65200","22.47118","1.33675"
"44994","269.92800","22.49426","1.31571"
"45040","270.20400","22.51722","1.31845"
"45086","270.48000","22.54023","1.32101"
"45132","270.75600","22.56319","1.32387"
"45178","271.03200","22.58621","1.32675"
"45224","271.30800","22.60917","1.32988"
"45270","271.58400","22.63225","1.33407"
"45316","271.86000","22.65521","1.33974"
"45362","272.13600","22.67829","1.34377"
"45408","272.41200","22.70119","1.32619"
"45454","272.68800","22.72427","1.32877"
"45500","272.96400","22.74717","1.33324"
"45546","273.24000","22.77024","1.33889"
"45592","273.51600","22.79326","1.34348"
"45638","273.79200","22.81628","1.34688"
"45684","274.06800","22.83924","1.35095"
"45730","274.34400","22.86220","1.35315"
"45776","274.62000","22.88522","1.35939"
"45822","274.89600","22.90824","1.36509"
"45868","275.17200","22.93120","1.37155"
"45914","275.44800","22.95422","1.37691"
"45960","275.72400","22.97718","1.37860"
"46006","276.00000","23.00026","1.38239"
"46052","276.27600","23.02322","1.38694"
"46098","276.55200","23.04623","1.39192"
"46144","276.82800","23.06925","1.39893"
"46190","277.10400","23.09227","1.40444"
"46236","277.38000","23.11523","1.40689"
"46282","277.65600","23.13825","1.41340"
"46328","277.93200","23.16121","1.41972"
"46374","278.20800","23.18423","1.42449"
"46420","278.48400","23.20725","1.42831"
"46466","278.76000","23.23021","1.43016"
"46512","279.03600","23.25323","1.43335"
"46558","279.31200","23.27618","1.43625"
"46604","279.58800","23.29926","1.43819"
"46650","279.86400","23.32222","1.43982"
"46696","280.14000","23.34524","1.44104"
"46742","280.41600","23.36820","1.44287"
"46788","280.69200","23.39128","1.44520"
"46834","280.96800","23.41418","1.44831"
"46880","281.24400","23.43726","1.45022"
"46926","281.52000","23.46016","1.45291"
"46972","281.79600","23.48324","1.45687"
"47018","282.07200","23.50613","1.46304"
"47064","282.34800","23.52921","1.46665"
"47110","282.62400","23.55217","1.47176"
"47156","282.90000","23.57525","1.47669"
"47202","283.17600","23.59821","1.48063"
"47248","283.45200","23.62123","1.48504"
"47294","283.72800","23.64419","1.47490"
"47340","284.00400","23.66727","1.48229"
"47386","284.28000","23.69023","1.48894"
"47432","284.55600","23.71331","1.49635"
"47478","284.83200","23.73621","1.50283"
"47524","285.10800","23.75922","1.50838"
"47570","285.38400","23.78224","1.51051"
"47616","285.66000","23.80526","1.51969"
"47662","285.93600","23.82822","1.52682"
"47708","286.21200","23.85118","1.52987"
"47754","286.48800","23.87420","1.53371"
"47800","286.76400","23.89722","1.53691"
"47846","287.04000","23.92024","1.54151"
"47892","287.31600","23.94320","1.54563"
"47938","287.59200","23.96622","1.54837"
"47984","287.86800","23.98923","1.43739"
"48030","288.14400","24.01231","1.43878"
"48076","288.42000","24.03521","1.44058"
"48122","288.69600","24.05823","1.44235"
"48168","288.97200","24.08119","1.44442"
"48214","289.24800","24.10421","1.44801"
"48260","289.52400","24.12717","1.45075"
"48306","289.80000","24.15019","1.45576"
"48352","290.07600","24.17321","1.45720"
"48398","290.35200","24.19623","1.46346"
"48444","290.62800","24.21918","1.46814"
"48490","290.90400","24.24220","1.47303"
"48536","291.18000","24.26522","1.48008"
"48582","291.45600","24.28824","1.48482"
"48628","291.73200","24.31120","1.48004"
"48674","292.00800","24.33428","1.48755"
"48720","292.28400","24.35718","1.48240"
"48766","292.56000","24.38026","1.44006"
"48812","292.83600","24.40316","1.44181"
"48858","293.11200","24.42624","1.44329"
"48904","293.38800","24.44914","1.44551"
"48950","293.66400","24.47221","1.44833"
"48996","293.94000","24.49517","1.45092"
"49042","294.21600","24.51825","1.45521"
"49088","294.49200","24.54121","1.45894"
"49134","294.76800","24.56423","1.46622"
"49180","295.04400","24.58719","1.47180"
"49226","295.32000","24.61021","1.47808"
"49272","295.59600","24.63323","1.48365"
"49318","295.87200","24.65625","1.49031"
"49364","296.14800","24.67921","1.49679"
"49410","296.42400","24.70217","1.49649"
"49456","296.70000","24.72518","1.50170"
"49502","296.97600","24.74814","1.50477"
"49548","297.25200","24.77122","1.51097"
"49594","297.52800","24.79418","1.51722"
"49640","297.80400","24.81720","1.52411"
"49686","298.08000","24.84022","1.52860"
"49732","298.35600","24.86324","1.53464"
"49778","298.63200","24.88620","1.53326"
"49824","298.90800","24.90928","1.53758"
"49870","299.18400","24.93223","1.54272"
"49916","299.46000","24.95525","1.54585"
"49962","299.73600","24.97821","1.54848"
"50008","300.01200","25.00123","1.55341"
"50054","300.28800","25.02419","1.55869"
"50100","300.56400","25.04727","1.56218"
"50146","300.84000","25.07023","1.56702"
"50192","301.11600","25.09319","1.56512"
"50238","301.39200","25.11609","1.56936"
"50284","301.66800","25.13923","1.57373"
"50330","301.94400","25.16225","1.58039"
"50376","302.22000","25.18526","1.58406"
"50422","302.49600","25.20816","1.58699"
"50468","302.77200","25.23124","1.59075"
"50514","303.04800","25.25414","1.59360"
"50560","303.32400","25.27722","1.59832"
"50606","303.60000","25.30012","1.42508"
"50652","303.87600","25.32320","1.42559"
"50698","304.15200","25.34616","1.43101"
"50744","304.42800","25.36924","1.42744"
"50790","304.70400","25.39219","1.43470"
"50836","304.98000","25.41527","1.43420"
"50882","305.25600","25.43824","1.43820"
"50928","305.53200","25.46119","1.43839"
"50974","305.80800","25.48421","1.44045"
"51020","306.08400","25.50723","1.44211"
"51066","306.36000","25.53025","1.44255"
"51112","306.63600","25.55321","1.44877"
"51158","306.91200","25.57623","1.44877"
"51204","307.18800","25.59925","1.45530"
"51250","307.46400","25.62227","1.45748"
"51296","307.74000","25.64522","1.46049"
"51342","308.01600","25.66825","1.47077"
"51388","308.29200","25.69126","1.47376"
"51434","308.56800","25.71428","1.48292"
"51480","308.84400","25.73724","1.48528"
"51526","309.12000","25.76026","1.48609"
"51572","309.39600","25.78322","1.49536"
"51618","309.67200","25.80630","1.49773"
"51664","309.94800","25.82920","1.50456"
"51710","310.22400","25.85222","1.50818"
"51756","310.50000","25.87518","1.51528"
"51802","310.77600","25.89826","1.52762"
"51848","311.05200","25.92115","1.52679"
"51894","311.32800","25.94423","1.53482"
"51940","311.60400","25.96719","1.53779"
"51986","311.88000","25.99021","1.54112"
"52032","312.15600","26.01317","1.54560"
"52078","312.43200","26.03625","1.54590"
"52124","312.70800","26.05921","1.54962"
"52170","312.98400","26.08223","1.55774"
"52216","313.26000","26.10525","1.55727"
"52262","313.53600","26.12826","0.48001"
"52308","313.81200","26.15122","0.25445"
"52354","314.08800","26.17424","0.25860"
"52400","314.36400","26.19720","0.26194"
"52446","314.64000","26.22022","0.25614"
"52492","314.91600","26.24318","0.25339"
"52538","315.19200","26.26626","0.26016"
"52584","315.46800","26.28928","0.27164"
"52630","315.74400","26.31230","0.26551"
"52676","316.02000","26.33520","0.27456"
"52722","316.29600","26.35822","0.27890"
"52768","316.57200","26.38124","0.28242"
"52814","316.84800","26.40425","0.29246"
"52860","317.12400","26.42727","0.29749"
"52906","317.40000","26.45023","0.29484"
"52952","317.67600","26.47325","0.29753"
"52998","317.95200","26.49621","0.30111"
"53044","318.22800","26.51917","0.30155"
"53090","318.50400","26.54219","0.30283"
"53136","318.78000","26.56515","0.30872"
"53182","319.05600","26.58823","0.31136"
"53228","319.33200","26.61125","0.31053"
"53274","319.60800","26.63420","0.31177"
"53320","319.88400","26.65722","0.31488"
"53366","320.16000","26.68024","0.31601"
"53412","320.43600","26.70326","0.31629"
"53458","320.71200","26.72622","0.31938"
"53504","320.98800","26.74930","0.32498"
"53550","321.26400","26.77226","0.32938"
"53596","321.54000","26.79528","0.33032"
"53642","321.81600","26.81824","0.32867"
"53688","322.09200","26.84120","0.33276"
"53734","322.36800","26.86416","0.33963"
"53780","322.64400","26.88723","0.34142"
"53826","322.92000","26.91019","0.33597"
"53872","323.19600","26.93327","0.33829"
"53918","323.47200","26.95617","0.34319"
"53964","323.74800","26.97919","0.34762"
"54010","324.02400","27.00215","0.34363"
"54056","324.30000","27.02529","0.34383"
"54102","324.57600","27.04819","0.34504"
"54148","324.85200","27.07121","0.34824"
"54194","325.12800","27.09417","0.35186"
"54240","325.40400","27.11724","0.35555"
"54286","325.68000","27.14014","0.35818"
"54332","325.95600","27.16322","0.36144"
"54378","326.23200","27.18618","0.36607"
"54424","326.50800","27.20926","0.36962"
"54470","326.78400","27.23222","0.37285"
"54516","327.06000","27.25524","0.37486"
"54562","327.33600","27.27820","0.37687"
"54608","327.61200","27.30128","0.37826"
"54654","327.88800","27.32417","0.38018"
"54700","328.16400","27.34725","0.38195"
"54746","328.44000","27.37021","0.38514"
"54792","328.71600","27.39323","0.38836"
"54838","328.99200","27.41619","0.39066"
"54884","329.26800","27.43915","0.39258"
"54930","329.54400","27.46223","0.39451"
"54976","329.82000","27.48525","0.39671"
"55022","330.09600","27.50821","0.39910"
"55068","330.37200","27.53117","0.40135"
"55114","330.64800","27.55425","0.40303"
"55160","330.92400","27.57721","0.40525"
"55206","331.20000","27.60023","0.40630"
"55252","331.47600","27.62318","0.40832"
"55298","331.75200","27.64626","0.40553"
"55344","332.02800","27.66916","0.40607"
"55390","332.30400","27.69224","0.40844"
"55436","332.58000","27.71520","0.41060"
"55482","332.85600","27.73822","0.41344"
"55528","333.13200","27.76118","0.41629"
"55574","333.40800","27.78419","0.41840"
"55620","333.68400","27.80716","0.42177"
"55666","333.96000","27.83024","0.42457"
"55712","334.23600","27.85320","0.41982"
"55758","334.51200","27.87627","0.42348"
"55804","334.78800","27.89917","0.42596"
"55850","335.06400","27.92225","0.42898"
"55896","335.34000","27.94521","0.43207"
"55942","335.61600","27.96823","0.43395"
"55988","335.89200","27.99119","0.43740"
"56034","336.16800","28.01427","0.44084"
"56080","336.44400","28.03717","0.44370"
"56126","336.72000","28.06025","0.44651"
"56153","336.88000","28.07352","0.44862"