File: Trajectories_together/161218Specimen_RawData_5.csv
"","V1","V2","V3"
"1","End date","12/18/2016",""
"2","Specimen label","16AT_Unk",""
"3","Maximum Load","0.14730","N"
"4","Time","Extension","Load"
"5","(s)","(mm)","(N)"
"6","0.00000","0.00000","-0.00013"
"90","0.50400","0.04233","0.00045"
"174","1.00800","0.08418","0.00018"
"258","1.51200","0.12622","0.00039"
"342","2.01600","0.16825","0.00009"
"426","2.52000","0.21028","0.00009"
"510","3.02400","0.25219","-0.00012"
"594","3.52800","0.29428","-0.00004"
"678","4.03200","0.33614","0.00016"
"762","4.53600","0.37817","-0.00006"
"846","5.04000","0.42014","-0.00006"
"930","5.54400","0.46217","0.00041"
"1014","6.04800","0.50421","0.00003"
"1098","6.55200","0.54624","0.00008"
"1182","7.05600","0.58821","0.00007"
"1266","7.56000","0.63024","0.00002"
"1350","8.06400","0.67221","0.00038"
"1434","8.56800","0.71431","0.00004"
"1518","9.07200","0.75616","0.00039"
"1602","9.57600","0.79825","0.00029"
"1686","10.08000","0.84022","-0.00001"
"1770","10.58400","0.88225","0.00021"
"1854","11.08800","0.92423","-0.00027"
"1938","11.59200","0.96620","0.00014"
"2022","12.09600","1.00817","-0.00003"
"2106","12.60000","1.05014","0.00021"
"2190","13.10400","1.09218","0.00039"
"2274","13.60800","1.13415","-0.00022"
"2358","14.11200","1.17618","0.00053"
"2442","14.61600","1.21821","0.00031"
"2526","15.12000","1.26024","0.00007"
"2610","15.62400","1.30222","0.00011"
"2694","16.12800","1.34425","0.00017"
"2778","16.63200","1.38622","0.00037"
"2862","17.13600","1.42825","0.00052"
"2946","17.64000","1.47028","0.00025"
"3030","18.14400","1.51226","0.00024"
"3114","18.64800","1.55423","0.00031"
"3198","19.15200","1.59626","0.00065"
"3282","19.65600","1.63817","0.00032"
"3366","20.16000","1.68021","0.00006"
"3450","20.66400","1.72218","0.00046"
"3534","21.16800","1.76415","0.00059"
"3618","21.67200","1.80618","0.00028"
"3702","22.17600","1.84821","0.00029"
"3786","22.68000","1.89025","0.00023"
"3870","23.18400","1.93228","0.00024"
"3954","23.68800","1.97425","0.00043"
"4038","24.19200","2.01628","0.00035"
"4122","24.69600","2.05825","0.00050"
"4206","25.20000","2.10029","0.00064"
"4290","25.70400","2.14220","0.00054"
"4374","26.20800","2.18423","0.00044"
"4458","26.71200","2.22620","0.00043"
"4542","27.21600","2.26824","0.00032"
"4626","27.72000","2.31021","0.00005"
"4710","28.22400","2.35224","0.00008"
"4794","28.72800","2.39409","0.00020"
"4878","29.23200","2.43618","0.00023"
"4962","29.73600","2.47816","0.00035"
"5046","30.24000","2.52019","-0.00009"
"5130","30.74400","2.56222","0.00019"
"5214","31.24800","2.60425","0.00026"
"5298","31.75200","2.64622","0.00047"
"5382","32.25600","2.68826","0.00036"
"5466","32.76000","2.73023","-0.00001"
"5550","33.26400","2.77226","0.00029"
"5634","33.76800","2.81423","0.00001"
"5718","34.27200","2.85621","0.00003"
"5802","34.77600","2.89824","0.00001"
"5886","35.28000","2.94021","-0.00002"
"5970","35.78400","2.98218","-0.00004"
"6054","36.29000","3.02433","0.00000"
"6138","36.79400","3.06631","0.00003"
"6222","37.29800","3.10834","0.00042"
"6306","37.80200","3.15037","-0.00016"
"6390","38.30600","3.19240","-0.00006"
"6474","38.81000","3.23443","0.00024"
"6558","39.31400","3.27635","0.00042"
"6642","39.81800","3.31844","0.00027"
"6726","40.32200","3.36041","0.00026"
"6810","40.82600","3.40244","0.00014"
"6894","41.33000","3.44436","0.00014"
"6978","41.83400","3.48639","0.00033"
"7062","42.33800","3.52842","0.00017"
"7146","42.84200","3.57039","0.00027"
"7230","43.34600","3.61230","0.00026"
"7314","43.85000","3.65440","0.00001"
"7398","44.35400","3.69631","0.00009"
"7482","44.85800","3.73834","0.00037"
"7566","45.36200","3.78037","0.00001"
"7650","45.86600","3.82234","0.00007"
"7734","46.37000","3.86432","0.00011"
"7818","46.87400","3.90641","0.00009"
"7902","47.37800","3.94838","-0.00031"
"7986","47.88200","3.99041","-0.00010"
"8070","48.38600","4.03239","0.00033"
"8154","48.89000","4.07442","0.00021"
"8238","49.39400","4.11639","-0.00014"
"8322","49.89800","4.15836","-0.00003"
"8406","50.40200","4.20039","-0.00006"
"8490","50.90600","4.24243","-0.00002"
"8574","51.41000","4.28440","-0.00004"
"8658","51.91400","4.32637","-0.00025"
"8742","52.41800","4.36828","-0.00009"
"8826","52.92200","4.41038","-0.00001"
"8910","53.42600","4.45235","0.00012"
"8994","53.93000","4.49432","-0.00011"
"9078","54.43400","4.53635","-0.00002"
"9162","54.93800","4.57838","0.00007"
"9246","55.44200","4.62042","-0.00017"
"9330","55.94600","4.66239","-0.00027"
"9414","56.45000","4.70442","0.00006"
"9498","56.95400","4.74639","0.00020"
"9582","57.45800","4.78842","0.00005"
"9666","57.96200","4.83040","0.00006"
"9750","58.46600","4.87237","0.00029"
"9834","58.97000","4.91440","-0.00013"
"9918","59.47400","4.95643","0.00002"
"10002","59.97800","4.99835","0.00037"
"10086","60.48200","5.04038","0.00037"
"10170","60.98600","5.08241","0.00025"
"10254","61.49000","5.12438","0.00039"
"10338","61.99400","5.16635","0.00034"
"10422","62.49800","5.20839","0.00017"
"10506","63.00200","5.25042","0.00028"
"10590","63.50600","5.29239","0.00044"
"10674","64.01000","5.33436","0.00042"
"10758","64.51400","5.37645","0.00041"
"10842","65.01800","5.41837","0.00052"
"10926","65.52200","5.46046","0.00048"
"11010","66.02600","5.50243","0.00030"
"11094","66.53000","5.54440","0.00029"
"11178","67.03400","5.58632","0.00053"
"11262","67.53800","5.62841","0.00026"
"11346","68.04200","5.67032","0.00032"
"11430","68.54600","5.71235","-0.00003"
"11514","69.05000","5.75432","0.00021"
"11598","69.55400","5.79636","0.00068"
"11682","70.05800","5.83833","0.00055"
"11766","70.56200","5.88036","0.00024"
"11850","71.06600","5.92239","0.00006"
"11934","71.57000","5.96436","0.00034"
"12018","72.07400","6.00640","0.00073"
"12102","72.57800","6.04843","0.00049"
"12186","73.08200","6.09040","0.00065"
"12270","73.58600","6.13243","0.00089"
"12354","74.09000","6.17441","0.00072"
"12438","74.59400","6.21638","0.00087"
"12522","75.09800","6.25835","0.00084"
"12606","75.60200","6.30038","0.00080"
"12690","76.10600","6.34229","0.00080"
"12774","76.61000","6.38433","0.00091"
"12858","77.11400","6.42636","0.00082"
"12942","77.61800","6.46839","0.00111"
"13026","78.12200","6.51036","0.00130"
"13110","78.62600","6.55233","0.00148"
"13194","79.13000","6.59443","0.00175"
"13278","79.63400","6.63640","0.00123"
"13362","80.13800","6.67837","0.00122"
"13446","80.64200","6.72040","0.00204"
"13530","81.14600","6.76244","0.00157"
"13614","81.65000","6.80447","0.00197"
"13698","82.15400","6.84638","0.00184"
"13782","82.65800","6.88835","0.00171"
"13866","83.16200","6.93038","0.00187"
"13950","83.66600","6.97236","0.00272"
"14034","84.17000","7.01439","0.00231"
"14118","84.67400","7.05630","0.00247"
"14202","85.17800","7.09839","0.00287"
"14286","85.68200","7.14037","0.00269"
"14370","86.18600","7.18246","0.00286"
"14454","86.69000","7.22437","0.00347"
"14538","87.19400","7.26640","0.00263"
"14622","87.69800","7.30837","0.00323"
"14706","88.20200","7.35047","0.00359"
"14790","88.70600","7.39238","0.00343"
"14874","89.21000","7.43441","0.00376"
"14958","89.71400","7.47644","0.00399"
"15042","90.21800","7.51841","0.00330"
"15126","90.72200","7.56033","0.00384"
"15210","91.22600","7.60236","0.00395"
"15294","91.73000","7.64433","0.00407"
"15378","92.23400","7.68636","0.00445"
"15462","92.73800","7.72834","0.00426"
"15546","93.24200","7.77037","0.00478"
"15630","93.74600","7.81240","0.00495"
"15714","94.25000","7.85443","0.00499"
"15798","94.75400","7.89634","0.00539"
"15882","95.25800","7.93844","0.00552"
"15966","95.76200","7.98041","0.00606"
"16050","96.26600","8.02238","0.00535"
"16134","96.77000","8.06435","0.00539"
"16218","97.27400","8.10638","0.00622"
"16302","97.77800","8.14842","0.00622"
"16386","98.28200","8.19039","0.00597"
"16470","98.78600","8.23242","0.00634"
"16554","99.29000","8.27433","0.00645"
"16638","99.79400","8.31637","0.00734"
"16722","100.29800","8.35828","0.00683"
"16806","100.80200","8.40037","0.00688"
"16890","101.30600","8.44240","0.00710"
"16974","101.81000","8.48437","0.00686"
"17058","102.31400","8.52641","0.00735"
"17142","102.81800","8.56838","0.00762"
"17226","103.32200","8.61041","0.00810"
"17310","103.82600","8.65244","0.00799"
"17394","104.33000","8.69441","0.00831"
"17478","104.83400","8.73645","0.00809"
"17562","105.33800","8.77842","0.00845"
"17646","105.84200","8.82045","0.00911"
"17730","106.34600","8.86242","0.00877"
"17814","106.85000","8.90440","0.00856"
"17898","107.35400","8.94631","0.00908"
"17982","107.85800","8.98834","0.00950"
"18066","108.36200","9.03031","0.00949"
"18150","108.86600","9.07234","0.01002"
"18234","109.37000","9.11432","0.00987"
"18318","109.87400","9.15635","0.00973"
"18402","110.37800","9.19838","0.00999"
"18486","110.88200","9.24041","0.00961"
"18570","111.38600","9.28238","0.00973"
"18654","111.89000","9.32442","0.00988"
"18738","112.39400","9.36639","0.01015"
"18822","112.89800","9.40842","0.01040"
"18906","113.40200","9.45039","0.00997"
"18990","113.90600","9.49242","0.01057"
"19074","114.41000","9.53440","0.01062"
"19158","114.91400","9.57637","0.01113"
"19242","115.41800","9.61834","0.01086"
"19326","115.92200","9.66031","0.01163"
"19410","116.42600","9.70235","0.01117"
"19494","116.93000","9.74432","0.01149"
"19578","117.43400","9.78635","0.01249"
"19662","117.93800","9.82838","0.01338"
"19746","118.44200","9.87035","0.01364"
"19830","118.94600","9.91239","0.01281"
"19914","119.45000","9.95442","0.01301"
"19998","119.95400","9.99639","0.01330"
"20082","120.45800","10.03842","0.01340"
"20166","120.96200","10.08040","0.01449"
"20250","121.46600","10.12243","0.01383"
"20334","121.97000","10.16440","0.01335"
"20418","122.47400","10.20643","0.01095"
"20502","122.97800","10.24834","0.01191"
"20586","123.48200","10.29038","0.01162"
"20670","123.98600","10.33235","0.01139"
"20754","124.49000","10.37438","0.01236"
"20838","124.99400","10.41635","0.01298"
"20922","125.49800","10.45839","0.01362"
"21006","126.00200","10.50036","0.01358"
"21090","126.50600","10.54245","0.01426"
"21174","127.01000","10.58442","0.01475"
"21258","127.51400","10.62645","0.01502"
"21342","128.01800","10.66837","0.01517"
"21426","128.52200","10.71040","0.01570"
"21510","129.02600","10.75237","0.01519"
"21594","129.53000","10.79446","0.01595"
"21678","130.03400","10.83638","0.01645"
"21762","130.53800","10.87841","0.01712"
"21846","131.04200","10.92038","0.01716"
"21930","131.54600","10.96235","0.01726"
"22014","132.05000","11.00432","0.01778"
"22098","132.55400","11.04636","0.01712"
"22182","133.05800","11.08833","0.01762"
"22266","133.56200","11.13042","0.01877"
"22350","134.06600","11.17233","0.01881"
"22434","134.57000","11.21442","0.01870"
"22518","135.07400","11.25640","0.01866"
"22602","135.57800","11.29843","0.01836"
"22686","136.08200","11.34040","0.01962"
"22770","136.58600","11.38237","0.02103"
"22854","137.09000","11.42440","0.02085"
"22938","137.59400","11.46638","0.02167"
"23022","138.09800","11.50841","0.02234"
"23106","138.60200","11.55038","0.02255"
"23190","139.10600","11.59235","0.02234"
"23274","139.61000","11.63433","0.02194"
"23358","140.11400","11.67630","0.02226"
"23442","140.61800","11.71833","0.02196"
"23526","141.12200","11.76036","0.01814"
"23610","141.62600","11.80239","0.01877"
"23694","142.13000","11.84443","0.01846"
"23778","142.63400","11.88640","0.01998"
"23862","143.13800","11.92843","0.01957"
"23946","143.64200","11.97040","0.02018"
"24030","144.14600","12.01238","0.02127"
"24114","144.65000","12.05435","0.02243"
"24198","145.15400","12.09644","0.02352"
"24282","145.65800","12.13841","0.02392"
"24366","146.16200","12.18044","0.02384"
"24450","146.66600","12.22236","0.02466"
"24534","147.17000","12.26439","0.02506"
"24618","147.67400","12.30636","0.02583"
"24702","148.17800","12.34833","0.02713"
"24786","148.68200","12.39031","0.02792"
"24870","149.18600","12.43234","0.02862"
"24954","149.69000","12.47437","0.02865"
"25038","150.19400","12.51640","0.02850"
"25122","150.69800","12.55837","0.02882"
"25206","151.20200","12.60040","0.02964"
"25290","151.70600","12.64238","0.02910"
"25374","152.21000","12.68441","0.03007"
"25458","152.71400","12.72638","0.03035"
"25542","153.21800","12.76841","0.03174"
"25626","153.72200","12.81039","0.03220"
"25710","154.22600","12.85236","0.03253"
"25794","154.73000","12.89433","0.03080"
"25878","155.23400","12.93636","0.03126"
"25962","155.73800","12.97833","0.03218"
"26046","156.24200","13.02037","0.03280"
"26130","156.74600","13.06228","0.03288"
"26214","157.25000","13.10437","0.03225"
"26298","157.75400","13.14640","0.03344"
"26382","158.25800","13.18838","0.03433"
"26466","158.76200","13.23041","0.03515"
"26550","159.26600","13.27238","0.03717"
"26634","159.77000","13.31441","0.03712"
"26718","160.27400","13.35639","0.03279"
"26802","160.77800","13.39842","0.03404"
"26886","161.28200","13.44039","0.03486"
"26970","161.78600","13.48236","0.03186"
"27054","162.29000","13.52439","0.03252"
"27138","162.79400","13.56637","0.03321"
"27222","163.29800","13.60840","0.03390"
"27306","163.80200","13.65037","0.03554"
"27390","164.30600","13.69234","0.03611"
"27474","164.81000","13.73437","0.03734"
"27558","165.31400","13.77635","0.03722"
"27642","165.81800","13.81844","0.03836"
"27726","166.32200","13.86035","0.03927"
"27810","166.82600","13.90238","0.03999"
"27894","167.33000","13.94447","0.04071"
"27978","167.83400","13.98645","0.04177"
"28062","168.33800","14.02836","0.04267"
"28146","168.84200","14.07039","0.04420"
"28230","169.34600","14.11236","0.04529"
"28314","169.85000","14.15439","0.04308"
"28398","170.35400","14.19637","0.04102"
"28482","170.85800","14.23834","0.04010"
"28566","171.36200","14.28031","0.04071"
"28650","171.86600","14.32240","0.04083"
"28734","172.37000","14.36438","0.04268"
"28818","172.87400","14.40635","0.04207"
"28902","173.37800","14.44832","0.04342"
"28986","173.88200","14.49041","0.04425"
"29070","174.38600","14.53239","0.04530"
"29154","174.89000","14.57436","0.04622"
"29238","175.39400","14.61639","0.04732"
"29322","175.89800","14.65842","0.04779"
"29406","176.40200","14.70039","0.04896"
"29490","176.90600","14.74243","0.05005"
"29574","177.41000","14.78440","0.05142"
"29658","177.91400","14.82637","0.05312"
"29742","178.41800","14.86840","0.05411"
"29826","178.92200","14.91037","0.05516"
"29910","179.42600","14.95235","0.05451"
"29994","179.93000","14.99438","0.05571"
"30078","180.43400","15.03635","0.05645"
"30162","180.93800","15.07838","0.05866"
"30246","181.44200","15.12041","0.06218"
"30330","181.94600","15.16233","0.06390"
"30414","182.45000","15.20442","0.06424"
"30498","182.95400","15.24645","0.06672"
"30582","183.45800","15.28836","0.06933"
"30666","183.96200","15.33039","0.07034"
"30750","184.46600","15.37243","0.07180"
"30834","184.97000","15.41440","0.07427"
"30918","185.47400","15.45643","0.07580"
"31002","185.97800","15.49834","0.07543"
"31086","186.48200","15.54038","0.07735"
"31170","186.98600","15.58235","0.07808"
"31254","187.49000","15.62432","0.07950"
"31338","187.99400","15.66635","0.08041"
"31422","188.49800","15.70838","0.08154"
"31506","189.00200","15.75036","0.08267"
"31590","189.50600","15.79245","0.08470"
"31674","190.01000","15.83436","0.08462"
"31758","190.51400","15.87639","0.08608"
"31842","191.01800","15.91842","0.08629"
"31926","191.52200","15.96040","0.08823"
"32010","192.02600","16.00243","0.08965"
"32094","192.53000","16.04446","0.09148"
"32178","193.03400","16.08643","0.09283"
"32262","193.53800","16.12841","0.09451"
"32346","194.04200","16.17038","0.09673"
"32430","194.54600","16.21235","0.09827"
"32514","195.05000","16.25432","0.10078"
"32598","195.55400","16.29635","0.10441"
"32682","196.05800","16.33839","0.10710"
"32766","196.56200","16.38030","0.10895"
"32850","197.06600","16.42239","0.11172"
"32934","197.57000","16.46442","0.11432"
"33018","198.07400","16.50639","0.11818"
"33102","198.57800","16.54831","0.12298"
"33186","199.08200","16.59040","0.12630"
"33270","199.58600","16.63237","0.13045"
"33354","200.09000","16.67440","0.12921"
"33438","200.59400","16.71644","0.13349"
"33522","201.09800","16.75841","0.13694"
"33606","201.60200","16.80038","0.13932"
"33690","202.10600","16.84235","0.14195"
"33774","202.61000","16.88438","0.14425"
"33858","203.11400","16.92636","0.14693"
"33942","203.61800","16.96839","-0.00022"
"34026","204.12200","17.01036","-0.00161"
"34110","204.62600","17.05233","-0.00159"
"34194","205.13000","17.09437","-0.00118"
"34278","205.63400","17.13634","-0.00118"
"34362","206.13800","17.17843","-0.00108"
"34446","206.64200","17.22040","-0.00123"
"34530","207.14600","17.26237","-0.00104"
"34614","207.65000","17.30435","-0.00073"
"34698","208.15400","17.34638","-0.00081"
"34782","208.65800","17.38841","-0.00087"
"34866","209.16200","17.43044","-0.00085"
"34950","209.66600","17.47235","-0.00078"
"35034","210.17000","17.51439","-0.00093"
"35118","210.67400","17.55636","-0.00108"
"35202","211.17800","17.59833","-0.00086"
"35286","211.68200","17.64030","-0.00076"
"35370","212.18600","17.68234","-0.00107"
"35454","212.69000","17.72437","-0.00053"
"35538","213.19400","17.76634","-0.00093"
"35622","213.69800","17.80831","-0.00052"
"35706","214.20200","17.85040","-0.00104"
"35790","214.70600","17.89238","-0.00100"
"35874","215.21000","17.93441","-0.00063"
"35958","215.71400","17.97638","-0.00067"
"36042","216.21800","18.01841","-0.00079"
"36126","216.72200","18.06038","-0.00083"
"36210","217.22600","18.10242","-0.00070"
"36294","217.73000","18.14439","-0.00109"
"36378","218.23400","18.18636","-0.00090"
"36462","218.73800","18.22839","-0.00061"
"36546","219.24200","18.27031","-0.00115"
"36630","219.74600","18.31234","-0.00077"
"36714","220.25000","18.35437","-0.00060"
"36798","220.75400","18.39634","-0.00106"
"36882","221.25800","18.43838","-0.00095"
"36966","221.76200","18.48041","-0.00106"
"37050","222.26600","18.52238","-0.00085"
"37134","222.77000","18.56441","-0.00092"
"37218","223.27400","18.60638","-0.00089"
"37302","223.77800","18.64842","-0.00076"
"37386","224.28200","18.69045","-0.00097"
"37470","224.78600","18.73242","-0.00102"
"37554","225.29000","18.77433","-0.00091"
"37638","225.79400","18.81643","-0.00069"
"37722","226.29800","18.85839","-0.00080"
"37806","226.80200","18.90037","-0.00103"
"37890","227.30600","18.94234","-0.00085"
"37974","227.81000","18.98431","-0.00042"
"38058","228.31400","19.02634","-0.00055"
"38142","228.81800","19.06838","-0.00072"
"38226","229.32200","19.11035","-0.00059"
"38310","229.82600","19.15244","-0.00053"
"38394","230.33000","19.19441","-0.00073"
"38478","230.83400","19.23639","-0.00076"
"38562","231.33800","19.27842","-0.00012"
"38646","231.84200","19.32039","-0.00064"
"38730","232.34600","19.36242","-0.00042"
"38814","232.85000","19.40445","-0.00066"
"38898","233.35400","19.44637","-0.00009"
"38982","233.85800","19.48840","-0.00068"
"39066","234.36200","19.53037","-0.00012"
"39150","234.86600","19.57234","-0.00038"
"39234","235.37000","19.61432","-0.00079"
"39318","235.87400","19.65635","-0.00060"
"39402","236.37800","19.69832","-0.00028"
"39486","236.88200","19.74035","-0.00026"
"39570","237.38600","19.78238","-0.00058"
"39654","237.89000","19.82441","-0.00019"
"39738","238.39400","19.86639","-0.00029"
"39822","238.89800","19.90842","-0.00036"
"39906","239.40200","19.95039","-0.00066"
"39990","239.90600","19.99242","-0.00055"
"40074","240.41000","20.03440","-0.00053"
"40158","240.91400","20.07643","-0.00043"
"40242","241.41800","20.11840","-0.00049"
"40326","241.92200","20.16037","-0.00020"
"40410","242.42600","20.20241","-0.00069"
"40494","242.93000","20.24438","-0.00062"
"40578","243.43400","20.28629","-0.00022"
"40662","243.93800","20.32832","-0.00011"
"40746","244.44200","20.37036","0.00001"
"40830","244.94600","20.41239","-0.00049"
"40914","245.45000","20.45442","-0.00048"
"40998","245.95400","20.49639","-0.00046"
"41082","246.45800","20.53842","-0.00021"
"41166","246.96200","20.58045","-0.00007"
"41250","247.46600","20.62243","-0.00007"
"41334","247.97000","20.66434","-0.00028"
"41418","248.47400","20.70643","0.00002"
"41502","248.97800","20.74840","-0.00030"
"41586","249.48200","20.79044","-0.00032"
"41670","249.98600","20.83235","0.00011"
"41754","250.49000","20.87438","-0.00013"
"41838","250.99400","20.91635","0.00035"
"41922","251.49800","20.95838","-0.00033"
"42006","252.00200","21.00036","-0.00026"
"42090","252.50600","21.04239","-0.00023"
"42174","253.01000","21.08436","-0.00011"
"42258","253.51400","21.12639","0.00011"
"42342","254.01800","21.16836","0.00011"
"42426","254.52200","21.21040","-0.00016"
"42510","255.02600","21.25243","0.00042"
"42594","255.53000","21.29446","0.00004"
"42678","256.03400","21.33637","0.00022"
"42762","256.53800","21.37840","-0.00020"
"42846","257.04200","21.42038","0.00000"
"42930","257.54600","21.46241","-0.00061"
"43014","258.05000","21.50438","-0.00084"
"43098","258.55400","21.54635","-0.00054"
"43182","259.05800","21.58833","-0.00092"
"43266","259.56200","21.63042","-0.00016"
"43350","260.06600","21.67239","0.00012"
"43434","260.57000","21.71436","-0.00055"
"43518","261.07400","21.75640","-0.00020"
"43602","261.57800","21.79837","-0.00030"
"43686","262.08200","21.84040","-0.00024"
"43770","262.58600","21.88243","-0.00019"
"43854","263.09000","21.92440","-0.00006"
"43938","263.59400","21.96638","-0.00036"
"44022","264.09800","22.00841","-0.00002"
"44106","264.60200","22.05038","0.00000"
"44190","265.10600","22.09241","-0.00031"
"44274","265.61000","22.13438","0.00007"
"44358","266.11400","22.17636","-0.00030"
"44442","266.61800","22.21833","-0.00015"
"44526","267.12200","22.26036","0.00009"
"44610","267.62600","22.30239","0.00032"
"44694","268.13000","22.34442","-0.00014"
"44778","268.63400","22.38634","-0.00001"
"44862","269.13800","22.42837","0.00044"
"44946","269.64200","22.47040","0.00029"
"45030","270.14600","22.51243","0.00020"
"45114","270.65000","22.55441","0.00022"
"45198","271.15400","22.59644","0.00061"
"45282","271.65800","22.63841","0.00019"
"45366","272.16200","22.68038","0.00015"
"45450","272.66600","22.72235","0.00058"
"45534","273.17000","22.76439","0.00045"
"45618","273.67400","22.80636","0.00070"
"45702","274.17800","22.84839","0.00041"
"45786","274.68200","22.89030","0.00045"
"45870","275.18600","22.93233","0.00113"
"45954","275.69000","22.97437","0.00088"
"46038","276.19400","23.01640","0.00108"
"46122","276.69800","23.05837","0.00125"
"46206","277.20200","23.10034","0.00081"
"46290","277.70600","23.14238","0.00086"
"46374","278.21000","23.18441","0.00065"
"46458","278.71400","23.22638","0.00105"
"46542","279.21800","23.26841","0.00109"
"46626","279.72200","23.31045","0.00130"
"46710","280.22600","23.35242","0.00136"
"46794","280.73000","23.39439","0.00095"
"46878","281.23400","23.43642","0.00145"
"46962","281.73800","23.47839","0.00158"
"47046","282.24200","23.52036","0.00176"
"47130","282.74600","23.56234","0.00168"
"47214","283.25000","23.60437","0.00151"
"47298","283.75400","23.64640","0.00236"
"47382","284.25800","23.68837","0.00171"
"47466","284.76200","23.73034","0.00195"
"47550","285.26600","23.77238","0.00207"
"47634","285.77000","23.81441","0.00206"
"47718","286.27400","23.85638","0.00205"
"47802","286.77800","23.89841","0.00230"
"47886","287.28200","23.94039","0.00180"
"47970","287.78600","23.98242","0.00292"
"48054","288.29000","24.02445","0.00243"
"48138","288.79400","24.06636","0.00273"
"48222","289.29800","24.10834","0.00271"
"48306","289.80200","24.15037","0.00208"
"48390","290.30600","24.19234","0.00184"
"48474","290.81000","24.23437","0.00248"
"48558","291.31400","24.27628","0.00243"
"48642","291.81800","24.31838","0.00239"
"48726","292.32200","24.36041","0.00273"
"48810","292.82600","24.40238","0.00274"
"48894","293.33000","24.44435","0.00275"
"48978","293.83400","24.48644","0.00320"
"49062","294.33800","24.52842","0.00345"
"49146","294.84200","24.57039","0.00302"
"49230","295.34600","24.61236","0.00346"
"49314","295.85000","24.65439","0.00352"
"49398","296.35400","24.69642","0.00316"
"49482","296.85800","24.73846","0.00334"
"49566","297.36200","24.78037","0.00331"
"49650","297.86600","24.82234","0.00338"
"49734","298.37000","24.86432","0.00347"
"49818","298.87400","24.90641","0.00373"
"49902","299.37800","24.94838","0.00445"
"49986","299.88200","24.99035","0.00433"
"50070","300.38600","25.03238","0.00408"
"50154","300.89000","25.07435","0.00429"
"50238","301.39400","25.11639","0.00431"
"50322","301.89800","25.15842","0.00389"
"50406","302.40200","25.20039","0.00396"
"50490","302.90600","25.24242","0.00401"
"50574","303.41000","25.28446","0.00401"
"50658","303.91400","25.32643","0.00404"
"50742","304.41800","25.36840","0.00425"
"50826","304.92200","25.41037","0.00396"
"50910","305.42600","25.45240","0.00408"
"50994","305.93000","25.49432","0.00427"
"51078","306.43400","25.53635","0.00439"
"51162","306.93800","25.57832","0.00515"
"51246","307.44200","25.62035","0.00447"
"51330","307.94600","25.66239","0.00493"
"51414","308.45000","25.70442","0.00491"
"51498","308.95400","25.74639","0.00440"
"51582","309.45800","25.78836","0.00379"
"51666","309.96200","25.83033","0.00331"
"51750","310.46600","25.87243","0.00329"
"51834","310.97000","25.91434","0.00338"
"51918","311.47400","25.95637","0.00358"
"52002","311.97800","25.99840","0.00396"
"52086","312.48200","26.04049","0.00418"
"52170","312.98600","26.08241","0.00439"
"52254","313.49000","26.12438","0.00403"
"52338","313.99400","26.16629","0.00395"
"52422","314.49800","26.20838","0.00401"
"52506","315.00200","26.25030","0.00406"
"52590","315.50600","26.29233","0.00468"
"52674","316.01000","26.33436","0.00462"
"52758","316.51400","26.37639","0.00484"
"52842","317.01800","26.41836","0.00503"
"52926","317.52200","26.46040","0.00508"
"53010","318.02600","26.50237","0.00529"
"53094","318.53000","26.54440","0.00540"
"53178","319.03400","26.58637","0.00496"
"53262","319.53800","26.62840","0.00492"
"53346","320.04200","26.67038","0.00510"
"53430","320.54600","26.71241","0.00516"
"53514","321.05000","26.75438","0.00557"
"53598","321.55400","26.79635","0.00532"
"53682","322.05800","26.83839","0.00528"
"53766","322.56200","26.88030","0.00502"
"53850","323.06600","26.92233","0.00545"
"53934","323.57000","26.96436","0.00572"
"54018","324.07400","27.00640","0.00516"
"54102","324.57800","27.04843","0.00552"
"54186","325.08200","27.09040","0.00508"
"54270","325.58600","27.13243","0.00556"
"54354","326.09000","27.17440","0.00580"
"54438","326.59400","27.21638","0.00599"
"54522","327.09800","27.25841","0.00609"
"54606","327.60200","27.30038","0.00564"
"54690","328.10600","27.34241","0.00613"
"54774","328.61000","27.38439","0.00613"
"54858","329.11400","27.42642","0.00621"
"54942","329.61800","27.46839","0.00651"
"55026","330.12200","27.51036","0.00691"
"55110","330.62600","27.55227","0.00698"
"55194","331.13000","27.59436","0.00674"
"55278","331.63400","27.63634","0.00731"
"55362","332.13800","27.67837","0.00776"
"55446","332.64200","27.72040","0.00832"
"55530","333.14600","27.76243","0.00793"
"55614","333.65000","27.80441","0.00811"
"55698","334.15400","27.84638","0.00858"
"55782","334.65800","27.88835","0.00872"
"55866","335.16200","27.93038","0.00157"
"55950","335.66600","27.97235","-0.00075"
"56034","336.17000","28.01439","0.00004"
"56118","336.67400","28.05636","-0.00018"
"56202","337.17800","28.09839","0.00011"
"56286","337.68200","28.14036","0.00048"
"56370","338.18600","28.18240","0.00014"
"56454","338.69000","28.22431","-0.00016"
"56538","339.19400","28.26634","0.00037"
"56622","339.69800","28.30837","0.00047"
"56706","340.20200","28.35034","0.00029"
"56790","340.70600","28.39232","0.00054"
"56874","341.21000","28.43435","0.00017"
"56958","341.71400","28.47644","0.00053"
"57042","342.21800","28.51841","0.00075"
"57126","342.72200","28.56044","0.00070"
"57210","343.22600","28.60236","0.00060"
"57294","343.73000","28.64439","0.00081"
"57378","344.23400","28.68642","0.00084"
"57462","344.73800","28.72839","0.00108"
"57546","345.24200","28.77043","0.00117"
"57630","345.74600","28.81234","0.00108"
"57714","346.25000","28.85431","0.00102"
"57798","346.75400","28.89634","0.00160"
"57882","347.25800","28.93832","0.00117"
"57966","347.76200","28.98035","0.00176"
"58050","348.26600","29.02232","0.00165"
"58134","348.77000","29.06441","0.00194"
"58218","349.27400","29.10638","0.00165"
"58302","349.77800","29.14841","0.00185"
"58386","350.28200","29.19039","0.00192"
"58470","350.78600","29.23248","0.00192"
"58554","351.29000","29.27433","0.00193"
"58638","351.79400","29.31642","0.00227"
"58722","352.29800","29.35840","0.00263"
"58806","352.80200","29.40037","0.00273"
"58890","353.30600","29.44240","0.00145"
"58974","353.81000","29.48437","0.00191"
"59058","354.31400","29.52634","-0.00023"
"59142","354.81800","29.56838","-0.00034"
"59226","355.32200","29.61029","-0.00058"
"59310","355.82600","29.65238","-0.00036"
"59394","356.33000","29.69436","-0.00016"
"59478","356.83400","29.73639","-0.00008"
"59562","357.33800","29.77836","0.00017"
"59646","357.84200","29.82039","-0.00022"
"59730","358.34600","29.86236","0.00008"
"59814","358.85000","29.90440","-0.00025"
"59898","359.35400","29.94637","-0.00004"
"59982","359.85800","29.98840","-0.00020"
"60066","360.36200","30.03037","0.00014"
"60150","360.86600","30.07234","-0.00024"
"60234","361.37000","30.11437","-0.00003"
"60318","361.87400","30.15635","0.00029"
"60402","362.37800","30.19832","0.00032"
"60486","362.88200","30.24035","0.00002"
"60570","363.38600","30.28232","0.00056"
"60654","363.89000","30.32436","0.00034"
"60738","364.39400","30.36639","0.00042"
"60822","364.89800","30.40842","0.00053"
"60906","365.40200","30.45039","0.00036"
"60990","365.90600","30.49242","0.00045"
"61074","366.41000","30.53440","0.00024"
"61158","366.91400","30.57637","0.00038"
"61242","367.41800","30.61846","0.00043"
"61326","367.92200","30.66043","0.00039"
"61410","368.42600","30.70240","0.00005"
"61494","368.93000","30.74438","0.00031"
"61578","369.43400","30.78641","0.00042"
"61662","369.93800","30.82838","0.00089"
"61746","370.44200","30.87041","0.00120"
"61830","370.94600","30.91233","0.00041"
"61914","371.45000","30.95436","0.00076"
"61998","371.95400","30.99633","0.00089"
"62082","372.45800","31.03836","0.00106"
"62166","372.96200","31.08039","0.00116"
"62250","373.46600","31.12243","0.00102"
"62334","373.97000","31.16446","0.00101"
"62418","374.47400","31.20643","0.00111"
"62502","374.97800","31.24834","0.00124"
"62586","375.48200","31.29043","0.00136"
"62670","375.98600","31.33240","0.00147"
"62754","376.49000","31.37438","0.00181"
"62838","376.99400","31.41635","0.00142"
"62922","377.49800","31.45838","0.00116"
"63006","378.00200","31.50035","0.00181"
"63090","378.50600","31.54233","0.00165"
"63174","379.01000","31.58430","0.00151"
"63258","379.51400","31.62633","0.00233"
"63342","380.01800","31.66836","0.00216"
"63426","380.52200","31.71039","0.00200"
"63510","381.02600","31.75237","0.00208"
"63594","381.53000","31.79440","0.00213"
"63678","382.03400","31.83637","0.00235"
"63762","382.53800","31.87846","0.00251"
"63846","383.04200","31.92038","0.00211"
"63930","383.54600","31.96241","0.00255"
"64014","384.05000","32.00432","0.00229"
"64098","384.55400","32.04641","0.00217"
"64182","385.05800","32.08838","0.00284"
"64266","385.56200","32.13042","0.00260"
"64350","386.06600","32.17233","0.00238"
"64434","386.57000","32.21430","0.00225"
"64518","387.07400","32.25639","0.00246"
"64602","387.57800","32.29836","0.00277"
"64686","388.08200","32.34034","0.00242"
"64770","388.58600","32.38237","0.00213"
"64854","389.09000","32.42440","0.00212"
"64938","389.59400","32.46643","0.00257"
"65022","390.09800","32.50841","0.00258"
"65106","390.60200","32.55038","0.00236"
"65190","391.10600","32.59247","0.00308"
"65274","391.61000","32.63444","0.00263"
"65358","392.11400","32.67641","0.00292"
"65442","392.61800","32.71839","0.00280"
"65526","393.12200","32.76036","0.00217"
"65610","393.62600","32.80233","0.00260"
"65694","394.13000","32.84443","0.00261"
"65778","394.63400","32.88633","0.00204"
"65862","395.13800","32.92842","0.00225"
"65946","395.64200","32.97040","0.00262"
"66030","396.14600","33.01243","0.00247"
"66114","396.65000","33.05434","0.00253"
"66198","397.15400","33.09638","0.00267"
"66282","397.65800","33.13841","0.00201"
"66366","398.16200","33.18044","0.00203"
"66450","398.66600","33.22235","0.00185"
"66534","399.17000","33.26439","0.00224"
"66618","399.67400","33.30642","0.00195"
"66702","400.17800","33.34845","0.00251"
"66786","400.68200","33.39036","0.00197"
"66870","401.18600","33.43233","0.00198"
"66954","401.69000","33.47437","0.00227"
"67038","402.19400","33.51633","0.00199"
"67122","402.69800","33.55837","0.00186"
"67206","403.20200","33.60034","0.00203"
"67290","403.70600","33.64237","0.00183"
"67374","404.21000","33.68441","0.00166"
"67458","404.71400","33.72638","0.00172"
"67542","405.21800","33.76841","0.00182"
"67626","405.72200","33.81044","0.00240"
"67710","406.22600","33.85241","0.00229"
"67794","406.73000","33.89439","0.00243"
"67878","407.23400","33.93636","0.00180"
"67962","407.73800","33.97845","0.00203"
"68046","408.24200","34.02042","0.00244"
"68130","408.74600","34.06240","0.00203"
"68214","409.25000","34.10431","0.00206"
"68298","409.75400","34.14640","0.00181"
"68382","410.25800","34.18831","0.00200"
"68466","410.76200","34.23040","0.00227"
"68550","411.26600","34.27238","0.00192"
"68634","411.77000","34.31441","0.00200"
"68718","412.27400","34.35638","0.00211"
"68802","412.77800","34.39841","0.00195"
"68886","413.28200","34.44038","0.00199"
"68970","413.78600","34.48236","0.00174"
"69054","414.29000","34.52439","0.00207"
"69138","414.79400","34.56642","0.00182"
"69222","415.29800","34.60833","0.00171"
"69306","415.80200","34.65049","0.00191"
"69390","416.30600","34.69240","0.00196"
"69474","416.81000","34.73443","0.00195"
"69558","417.31400","34.77628","0.00163"
"69642","417.81800","34.81837","0.00239"
"69726","418.32200","34.86029","0.00233"
"69810","418.82600","34.90238","0.00259"
"69894","419.33000","34.94435","0.00201"
"69978","419.83400","34.98639","0.00225"
"70062","420.33800","35.02836","0.00231"
"70146","420.84200","35.07045","0.00221"
"70230","421.34600","35.11242","0.00248"
"70314","421.85000","35.15439","0.00244"
"70398","422.35400","35.19637","0.00272"
"70482","422.85800","35.23840","0.00189"
"70566","423.36200","35.28043","0.00202"
"70650","423.86600","35.32246","0.00271"
"70734","424.37000","35.36437","0.00220"
"70818","424.87400","35.40635","0.00282"
"70902","425.37800","35.44838","0.00244"
"70986","425.88200","35.49029","0.00236"
"71070","426.38600","35.53232","0.00197"
"71154","426.89000","35.57436","0.00173"
"71238","427.39400","35.61639","0.00167"
"71322","427.89800","35.65836","0.00151"
"71406","428.40200","35.70039","0.00124"
"71490","428.90600","35.74242","0.00181"
"71574","429.41000","35.78439","0.00123"
"71658","429.91400","35.82637","0.00138"
"71742","430.41800","35.86840","0.00184"
"71826","430.92200","35.91037","0.00185"
"71910","431.42600","35.95247","0.00202"
"71994","431.93000","35.99437","0.00152"
"72078","432.43400","36.03641","0.00182"
"72162","432.93800","36.07838","0.00177"
"72246","433.44200","36.12035","0.00195"
"72330","433.94600","36.16232","0.00195"
"72414","434.45000","36.20430","0.00200"
"72498","434.95400","36.24639","0.00202"
"72582","435.45800","36.28830","0.00207"
"72666","435.96200","36.33033","0.00200"
"72750","436.46600","36.37242","0.00217"
"72834","436.97000","36.41446","0.00218"
"72918","437.47400","36.45643","0.00194"
"73002","437.97800","36.49840","0.00229"
"73086","438.48200","36.54043","0.00205"
"73170","438.98600","36.58235","0.00220"
"73254","439.49000","36.62444","0.00252"
"73338","439.99400","36.66635","0.00253"
"73422","440.49800","36.70838","0.00244"
"73506","441.00200","36.75035","0.00263"
"73590","441.50600","36.79239","0.00199"
"73674","442.01000","36.83430","0.00201"
"73758","442.51400","36.87633","0.00245"
"73842","443.01800","36.91837","0.00254"
"73926","443.52200","36.96039","0.00222"
"74010","444.02600","37.00237","0.00204"
"74094","444.53000","37.04440","0.00238"
"74178","445.03400","37.08637","0.00217"
"74262","445.53800","37.12840","0.00111"
"74346","446.04200","37.17038","0.00148"
"74430","446.54600","37.21241","0.00180"
"74514","447.05000","37.25444","0.00200"
"74598","447.55400","37.29641","0.00188"
"74682","448.05800","37.33844","0.00221"
"74766","448.56200","37.38036","0.00189"
"74850","449.06600","37.42239","0.00164"
"74934","449.57000","37.46436","0.00174"
"75018","450.07400","37.50628","0.00199"
"75102","450.57800","37.54836","0.00223"
"75186","451.08200","37.59040","0.00209"
"75270","451.58600","37.63237","0.00158"
"75354","452.09000","37.67440","0.00219"
"75438","452.59400","37.71637","0.00226"
"75522","453.09800","37.75841","0.00217"
"75606","453.60200","37.80038","0.00235"
"75690","454.10600","37.84241","0.00211"
"75774","454.61000","37.88432","0.00237"
"75858","455.11400","37.92641","0.00242"
"75942","455.61800","37.96839","0.00230"
"76026","456.12200","38.01036","0.00229"
"76110","456.62600","38.05239","0.00228"
"76194","457.13000","38.09436","0.00252"
"76278","457.63400","38.13634","0.00257"
"76362","458.13800","38.17831","0.00218"
"76446","458.64200","38.22034","0.00223"
"76530","459.14600","38.26237","0.00304"
"76614","459.65000","38.30434","0.00250"
"76698","460.15400","38.34637","0.00237"
"76782","460.65800","38.38835","0.00207"
"76866","461.16200","38.43038","0.00154"
"76950","461.66600","38.47241","0.00101"
"77034","462.17000","38.51444","0.00019"
"77118","462.67400","38.55635","0.00070"
"77202","463.17800","38.59839","0.00044"
"77286","463.68200","38.64042","0.00084"
"77370","464.18600","38.68233","0.00071"
"77454","464.69000","38.72437","0.00040"
"77538","465.19400","38.76640","0.00047"
"77622","465.69800","38.80831","0.00095"
"77706","466.20200","38.85034","0.00061"
"77790","466.70600","38.89237","0.00102"
"77874","467.21000","38.93435","0.00098"
"77958","467.71400","38.97632","0.00072"
"78042","468.21800","39.01841","0.00129"
"78126","468.72200","39.06038","0.00101"
"78210","469.22600","39.10242","0.00112"
"78294","469.73000","39.14444","0.00114"
"78378","470.23400","39.18636","0.00083"
"78462","470.73800","39.22839","0.00125"
"78546","471.24200","39.27036","0.00133"
"78630","471.74600","39.31240","0.00092"
"78714","472.25000","39.35437","0.00104"
"78798","472.75400","39.39640","0.00099"
"78882","473.25800","39.43837","0.00107"
"78966","473.76200","39.48040","0.00122"
"79050","474.26600","39.52232","0.00104"
"79134","474.77000","39.56435","0.00083"
"79218","475.27400","39.60632","0.00101"
"79302","475.77800","39.64841","0.00086"
"79386","476.28200","39.69033","0.00099"
"79470","476.78600","39.73242","0.00088"
"79554","477.29000","39.77439","0.00101"
"79638","477.79400","39.81642","0.00079"
"79722","478.29800","39.85839","0.00096"
"79806","478.80200","39.90036","0.00065"
"79890","479.30600","39.94240","0.00099"
"79974","479.81000","39.98443","0.00091"
"80058","480.31400","40.02641","0.00102"
"80142","480.81800","40.06837","0.00081"
"80226","481.32200","40.11028","0.00086"
"80310","481.82600","40.15232","0.00164"
"80394","482.33000","40.19435","0.00151"
"80478","482.83400","40.23638","0.00131"
"80562","483.33800","40.27835","0.00129"
"80646","483.84200","40.32038","0.00172"
"80730","484.34600","40.36242","0.00098"
"80814","484.85000","40.40439","0.00127"
"80898","485.35400","40.44642","0.00181"
"80982","485.85800","40.48840","0.00158"
"81066","486.36200","40.53043","0.00103"
"81150","486.86600","40.57246","0.00146"
"81234","487.37000","40.61443","0.00150"
"81318","487.87400","40.65641","0.00140"
"81402","488.37800","40.69837","0.00159"
"81486","488.88200","40.74035","0.00118"
"81570","489.38600","40.78238","0.00161"
"81654","489.89000","40.82435","0.00137"
"81738","490.39400","40.86633","0.00166"
"81822","490.89800","40.90836","0.00162"
"81906","491.40200","40.95039","0.00141"
"81990","491.90600","40.99230","0.00168"
"82074","492.41000","41.03439","0.00154"
"82158","492.91400","41.07636","0.00138"
"82242","493.41800","41.11840","0.00164"
"82326","493.92200","41.16043","0.00181"
"82410","494.42600","41.20240","0.00182"
"82494","494.93000","41.24437","0.00175"
"82578","495.43400","41.28646","0.00190"
"82662","495.93800","41.32832","0.00224"
"82746","496.44200","41.37041","0.00221"
"82830","496.94600","41.41232","0.00193"
"82914","497.45000","41.45436","0.00255"
"82998","497.95400","41.49627","0.00243"
"83082","498.45800","41.53836","0.00192"
"83166","498.96200","41.58039","0.00197"
"83250","499.46600","41.62236","0.00259"
"83334","499.97000","41.66434","0.00229"
"83418","500.47400","41.70637","0.00240"
"83502","500.97800","41.74840","0.00259"
"83586","501.48200","41.79043","0.00251"
"83670","501.98600","41.83241","0.00236"
"83754","502.49000","41.87438","0.00229"
"83838","502.99400","41.91641","0.00283"
"83922","503.49800","41.95844","0.00235"
"84006","504.00200","42.00035","0.00199"
"84090","504.50600","42.04238","0.00175"
"84174","505.01000","42.08436","0.00140"
"84258","505.51400","42.12633","0.00077"
"84342","506.01800","42.16837","0.00131"
"84426","506.52200","42.21034","0.00147"
"84510","507.02600","42.25236","0.00152"
"84594","507.53000","42.29434","0.00145"
"84678","508.03400","42.33643","0.00136"
"84762","508.53800","42.37835","0.00109"
"84846","509.04200","42.42037","0.00152"
"84930","509.54600","42.46241","0.00094"
"85014","510.05000","42.50438","0.00125"
"85098","510.55400","42.54641","0.00106"
"85182","511.05800","42.58838","0.00064"
"85266","511.56200","42.63036","0.00045"
"85350","512.06600","42.67239","0.00083"
"85434","512.57000","42.71436","0.00104"
"85518","513.07400","42.75639","0.00070"
"85602","513.57800","42.79830","0.00070"
"85686","514.08200","42.84034","0.00095"
"85770","514.58600","42.88237","0.00095"
"85854","515.09000","42.92440","0.00075"
"85938","515.59400","42.96637","0.00091"
"86022","516.09800","43.00841","0.00053"
"86106","516.60200","43.05038","0.00093"
"86190","517.10600","43.09241","0.00070"
"86274","517.61000","43.13438","0.00082"
"86358","518.11400","43.17635","0.00086"
"86442","518.61800","43.21838","0.00103"
"86526","519.12200","43.26048","0.00095"
"86610","519.62600","43.30239","0.00066"
"86694","520.13000","43.34442","0.00106"
"86778","520.63400","43.38634","0.00074"
"86862","521.13800","43.42837","0.00111"
"86946","521.64200","43.47034","0.00114"
"87030","522.14600","43.51231","0.00050"
"87114","522.65000","43.55434","0.00062"
"87198","523.15400","43.59637","0.00103"
"87282","523.65800","43.63841","0.00075"
"87366","524.16200","43.68038","0.00086"
"87450","524.66600","43.72235","0.00078"
"87534","525.17000","43.76445","0.00067"
"87618","525.67400","43.80635","0.00095"
"87702","526.17800","43.84838","0.00103"
"87786","526.68200","43.89036","0.00109"
"87870","527.18600","43.93239","0.00093"
"87954","527.69000","43.97443","0.00061"
"88038","528.19400","44.01640","0.00102"
"88122","528.69800","44.05837","0.00099"
"88206","529.20200","44.10034","0.00111"
"88290","529.70600","44.14231","0.00085"
"88374","530.21000","44.18435","0.00110"
"88458","530.71400","44.22638","0.00126"
"88542","531.21800","44.26835","0.00099"
"88626","531.72200","44.31044","0.00081"
"88710","532.22600","44.35236","0.00096"
"88794","532.73000","44.39439","0.00122"
"88878","533.23400","44.43642","0.00113"
"88962","533.73800","44.47845","0.00108"
"89046","534.24200","44.52042","0.00105"
"89130","534.74600","44.56245","0.00137"
"89214","535.25000","44.60437","0.00107"
"89298","535.75400","44.64646","0.00142"
"89382","536.25800","44.68837","0.00097"
"89466","536.76200","44.73040","0.00115"
"89550","537.26600","44.77231","0.00123"
"89634","537.77000","44.81435","0.00135"
"89718","538.27400","44.85638","0.00115"
"89802","538.77800","44.89835","0.00138"
"89886","539.28200","44.94032","0.00114"
"89970","539.78600","44.98242","0.00122"
"90054","540.29000","45.02439","0.00129"
"90138","540.79400","45.06642","0.00162"
"90222","541.29800","45.10839","0.00147"
"90306","541.80200","45.15036","0.00133"
"90390","542.30600","45.19239","0.00145"
"90474","542.81000","45.23443","0.00127"
"90558","543.31400","45.27634","0.00140"
"90642","543.81800","45.31837","0.00128"
"90726","544.32200","45.36040","0.00086"
"90810","544.82600","45.40238","0.00048"
"90894","545.33000","45.44429","0.00056"
"90978","545.83400","45.48632","0.00080"
"91062","546.33800","45.52835","0.00131"
"91146","546.84200","45.57039","0.00101"
"91230","547.34600","45.61236","0.00116"
"91314","547.85000","45.65433","0.00105"
"91398","548.35400","45.69642","0.00103"
"91482","548.85800","45.73845","0.00079"
"91566","549.36200","45.78043","0.00125"
"91650","549.86600","45.82234","0.00104"
"91734","550.37000","45.86443","0.00045"
"91818","550.87400","45.90640","0.00127"
"91902","551.37800","45.94844","0.00097"
"91986","551.88200","45.99035","0.00127"
"92070","552.38600","46.03238","0.00110"
"92154","552.89000","46.07435","0.00094"
"92238","553.39400","46.11638","0.00090"
"92322","553.89800","46.15836","0.00083"
"92406","554.40200","46.20039","0.00069"
"92490","554.90600","46.24236","0.00085"
"92574","555.41000","46.28439","0.00102"
"92658","555.91400","46.32637","0.00087"
"92742","556.41800","46.36846","0.00046"
"92826","556.92200","46.41043","0.00075"
"92910","557.42600","46.45246","0.00049"
"92994","557.93000","46.49438","0.00031"
"93078","558.43400","46.53635","0.00044"
"93162","558.93800","46.57844","0.00057"
"93246","559.44200","46.62041","0.00030"
"93330","559.94600","46.66232","0.00071"
"93414","560.45000","46.70441","0.00066"
"93498","560.95400","46.74633","0.00014"
"93582","561.45800","46.78836","0.00056"
"93666","561.96200","46.83039","0.00077"
"93750","562.46600","46.87237","0.00058"
"93834","562.97000","46.91433","0.00081"
"93918","563.47400","46.95643","0.00094"
"94002","563.97800","46.99840","0.00086"
"94086","564.48200","47.04043","0.00098"
"94170","564.98600","47.08240","0.00087"
"94254","565.49000","47.12438","0.00083"
"94338","565.99400","47.16641","0.00065"
"94422","566.49800","47.20839","0.00076"
"94506","567.00200","47.25041","0.00083"
"94590","567.50600","47.29238","0.00060"
"94674","568.01000","47.33442","0.00084"
"94758","568.51400","47.37639","0.00056"
"94842","569.01800","47.41836","0.00059"
"94926","569.52200","47.46039","0.00076"
"95010","570.02600","47.50231","0.00051"
"95094","570.53000","47.54433","0.00034"
"95178","571.03400","47.58637","0.00061"
"95262","571.53800","47.62840","0.00055"
"95346","572.04200","47.67044","0.00091"
"95430","572.54600","47.71241","0.00067"
"95514","573.05000","47.75444","0.00047"
"95598","573.55400","47.79641","0.00065"
"95682","574.05800","47.83839","0.00050"
"95766","574.56200","47.88036","0.00033"
"95850","575.06600","47.92239","0.00048"
"95934","575.57000","47.96436","0.00063"
"96018","576.07400","48.00639","0.00067"
"96102","576.57800","48.04837","0.00048"
"96186","577.08200","48.09040","0.00071"
"96270","577.58600","48.13237","0.00036"
"96354","578.09000","48.17440","0.00044"
"96438","578.59400","48.21631","0.00047"
"96522","579.09800","48.25834","0.00079"
"96606","579.60200","48.30038","0.00009"
"96690","580.10600","48.34247","0.00069"
"96774","580.61000","48.38438","0.00059"
"96858","581.11400","48.42641","0.00059"
"96942","581.61800","48.46839","0.00043"
"97026","582.12200","48.51036","0.00081"
"97110","582.62600","48.55239","0.00077"
"97194","583.13000","48.59442","0.00074"
"97278","583.63400","48.63633","0.00105"
"97362","584.13800","48.67837","0.00072"
"97446","584.64200","48.72034","0.00106"
"97530","585.14600","48.76237","0.00086"
"97614","585.65000","48.80434","0.00059"
"97698","586.15400","48.84637","0.00073"
"97782","586.65800","48.88834","0.00061"
"97866","587.16200","48.93032","0.00123"
"97950","587.66600","48.97235","0.00092"
"98034","588.17000","49.01439","0.00101"
"98118","588.67400","49.05642","0.00037"
"98202","589.17800","49.09845","0.00092"
"98286","589.68200","49.14042","0.00092"
"98370","590.18600","49.18245","0.00097"
"98454","590.69000","49.22437","0.00071"
"98538","591.19400","49.26633","0.00107"
"98622","591.69800","49.30843","0.00079"
"98706","592.20200","49.35040","0.00045"
"98790","592.70600","49.39238","0.00070"
"98874","593.21000","49.43434","0.00067"
"98958","593.71400","49.47638","0.00086"
"99042","594.21800","49.51841","0.00125"
"99126","594.72200","49.56038","0.00082"
"99210","595.22600","49.60235","0.00076"
"99294","595.73000","49.64445","0.00066"
"99378","596.23400","49.68636","0.00078"
"99462","596.73800","49.72845","0.00075"
"99546","597.24200","49.77042","0.00054"
"99630","597.74600","49.81245","0.00094"
"99714","598.25000","49.85442","0.00140"
"99798","598.75400","49.89640","0.00120"
"99882","599.25800","49.93837","0.00080"
"99966","599.76200","49.98034","0.00105"
"100050","600.26600","50.02238","0.00109"
"100134","600.77000","50.06440","0.00094"
"100218","601.27400","50.10632","0.00087"
"100302","601.77800","50.14835","0.00116"
"100386","602.28200","50.19038","0.00123"
"100470","602.78600","50.23241","0.00120"
"100554","603.29000","50.27433","0.00121"
"100638","603.79400","50.31636","0.00079"
"100722","604.29800","50.35839","0.00164"
"100806","604.80200","50.40036","0.00136"
"100890","605.30600","50.44240","0.00091"
"100974","605.81000","50.48442","0.00116"
"101058","606.31400","50.52640","0.00134"
"101142","606.81800","50.56843","0.00154"
"101226","607.32200","50.61034","0.00092"
"101310","607.82600","50.65238","0.00145"
"101394","608.33000","50.69435","0.00149"
"101478","608.83400","50.73632","0.00157"
"101562","609.33800","50.77830","0.00116"
"101646","609.84200","50.82033","0.00125"
"101730","610.34600","50.86236","0.00161"
"101814","610.85000","50.90439","0.00149"
"101898","611.35400","50.94636","0.00138"
"101982","611.85800","50.98839","0.00127"
"102066","612.36200","51.03042","0.00154"
"102150","612.86600","51.07240","0.00187"
"102234","613.37000","51.11443","0.00150"
"102318","613.87400","51.15640","0.00165"
"102402","614.37800","51.19843","0.00150"
"102403","614.38200","51.19879","0.00153"