File: Trajectories_together/161218_2Specimen_RawData_8.csv
"","V1","V2","V3"
"1","End date","12/18/2016",""
"2","Specimen label","16BG_29",""
"3","Maximum Load","0.30305","N"
"4","Time","Extension","Load"
"5","(s)","(mm)","(N)"
"6","0.00000","-0.00006","0.00015"
"86","0.48000","0.04030","0.00081"
"166","0.96000","0.08012","0.00136"
"246","1.44000","0.12018","0.00161"
"326","1.92000","0.16012","0.00211"
"406","2.40000","0.20012","0.00223"
"486","2.88000","0.24011","0.00359"
"566","3.36000","0.28011","0.00391"
"646","3.84000","0.32011","0.00424"
"726","4.32000","0.36017","0.00559"
"806","4.80000","0.40011","0.00637"
"886","5.28000","0.44011","0.00677"
"966","5.76000","0.48011","0.00794"
"1046","6.24000","0.52017","0.00902"
"1126","6.72000","0.56011","0.01037"
"1206","7.20000","0.60011","0.01095"
"1286","7.68000","0.64011","0.01234"
"1366","8.16000","0.68011","0.01442"
"1446","8.64000","0.72016","0.01624"
"1526","9.12000","0.76010","0.01734"
"1606","9.60000","0.80016","0.01901"
"1686","10.08000","0.84010","0.02079"
"1766","10.56000","0.88010","0.02271"
"1846","11.04000","0.92010","0.02484"
"1926","11.52000","0.96010","0.02707"
"2006","12.00000","1.00004","0.02921"
"2086","12.48000","1.04010","0.03226"
"2166","12.96000","1.08010","0.03612"
"2246","13.44000","1.12010","0.04223"
"2326","13.92000","1.16016","0.04852"
"2406","14.40000","1.20010","0.05485"
"2486","14.88000","1.24015","0.06187"
"2566","15.36000","1.28009","0.06986"
"2646","15.84000","1.32003","0.07967"
"2726","16.32000","1.36003","0.09059"
"2806","16.80000","1.40009","0.10516"
"2886","17.28000","1.44009","0.11462"
"2966","17.76000","1.48015","0.12702"
"3046","18.24000","1.52015","0.12833"
"3126","18.72000","1.56015","0.12855"
"3206","19.20000","1.60009","0.12856"
"3286","19.68000","1.64015","0.12866"
"3366","20.16000","1.68009","0.12876"
"3446","20.64000","1.72009","0.12891"
"3526","21.12000","1.76008","0.12890"
"3606","21.60000","1.80008","0.12894"
"3686","22.08000","1.84014","0.12906"
"3766","22.56000","1.88014","0.12929"
"3846","23.04000","1.92014","0.12928"
"3926","23.52000","1.96014","0.12934"
"4006","24.00000","2.00014","0.12950"
"4086","24.48000","2.04008","0.12936"
"4166","24.96000","2.08008","0.12934"
"4246","25.44000","2.12008","0.12949"
"4326","25.92000","2.16008","0.12937"
"4406","26.40000","2.20020","0.12986"
"4486","26.88000","2.24019","0.12954"
"4566","27.36000","2.28013","0.12968"
"4646","27.84000","2.32013","0.12988"
"4726","28.32000","2.36013","0.12918"
"4806","28.80000","2.40013","0.12975"
"4886","29.28000","2.44013","0.13012"
"4966","29.76000","2.48013","0.12981"
"5046","30.24000","2.52007","0.13041"
"5126","30.72000","2.56013","0.12983"
"5206","31.20000","2.60013","0.12970"
"5286","31.68000","2.64013","0.13024"
"5366","32.16000","2.68019","0.13009"
"5446","32.64000","2.72012","0.13000"
"5526","33.12000","2.76012","0.12971"
"5606","33.60000","2.80012","0.12991"
"5686","34.08000","2.84006","0.13037"
"5766","34.56000","2.88012","0.13054"
"5846","35.04000","2.92012","0.12998"
"5926","35.52000","2.96012","0.13075"
"6006","36.00000","3.00012","0.13059"
"6086","36.48000","3.04012","0.13043"
"6166","36.96000","3.08012","0.13048"
"6246","37.44000","3.12018","0.13043"
"6326","37.92000","3.16006","0.13042"
"6406","38.40000","3.20012","0.13022"
"6486","38.88000","3.24011","0.13041"
"6566","39.36000","3.28011","0.13071"
"6646","39.84000","3.32005","0.13064"
"6726","40.32000","3.36017","0.13087"
"6806","40.80000","3.40017","0.13096"
"6886","41.28000","3.44011","0.13086"
"6966","41.76000","3.48017","0.13052"
"7046","42.24000","3.52005","0.13018"
"7126","42.72000","3.56005","0.13062"
"7206","43.20000","3.60011","0.13048"
"7286","43.68000","3.64011","0.13023"
"7366","44.16000","3.68011","0.13048"
"7446","44.64000","3.72016","0.13061"
"7526","45.12000","3.76010","0.13042"
"7606","45.60000","3.80010","0.13069"
"7686","46.08000","3.84016","0.13083"
"7766","46.56000","3.88010","0.13049"
"7846","47.04000","3.92010","0.13089"
"7926","47.52000","3.96004","0.13083"
"8006","48.00000","4.00010","0.13094"
"8086","48.48000","4.04010","0.13054"
"8166","48.96000","4.08016","0.13096"
"8246","49.44000","4.12016","0.13097"
"8326","49.92000","4.16016","0.13103"
"8406","50.40000","4.20015","0.13074"
"8486","50.88000","4.24009","0.13079"
"8566","51.36000","4.28009","0.13112"
"8646","51.84000","4.32009","0.13065"
"8726","52.32000","4.36003","0.13148"
"8806","52.80000","4.40009","0.13047"
"8886","53.28000","4.44015","0.13173"
"8966","53.76000","4.48009","0.13124"
"9046","54.24000","4.52015","0.13164"
"9126","54.72000","4.56015","0.13157"
"9206","55.20000","4.60015","0.13143"
"9286","55.68000","4.64015","0.13124"
"9366","56.16000","4.68009","0.13135"
"9446","56.64000","4.72008","0.13156"
"9526","57.12000","4.76008","0.13132"
"9606","57.60000","4.80014","0.13154"
"9686","58.08000","4.84014","0.13177"
"9766","58.56000","4.88014","0.13149"
"9846","59.04000","4.92020","0.13173"
"9926","59.52000","4.96014","0.13172"
"10006","60.00000","5.00014","0.13194"
"10086","60.48000","5.04008","0.13191"
"10166","60.96000","5.08008","0.13149"
"10246","61.44000","5.12008","0.13219"
"10326","61.92000","5.16014","0.13216"
"10406","62.40000","5.20014","0.13190"
"10486","62.88000","5.24013","0.13200"
"10566","63.36000","5.28013","0.13194"
"10646","63.84000","5.32013","0.13201"
"10726","64.32000","5.36007","0.13205"
"10806","64.80000","5.40013","0.13259"
"10886","65.28000","5.44007","0.13208"
"10966","65.76000","5.48007","0.13213"
"11046","66.24000","5.52007","0.13220"
"11126","66.72000","5.56013","0.13277"
"11206","67.20000","5.60013","0.13266"
"11286","67.68000","5.64013","0.13275"
"11366","68.16000","5.68019","0.13262"
"11446","68.64000","5.72018","0.13269"
"11526","69.12000","5.76006","0.13273"
"11606","69.60000","5.80006","0.13307"
"11686","70.08000","5.84006","0.13288"
"11766","70.56000","5.88012","0.13311"
"11846","71.04000","5.92018","0.13347"
"11926","71.52000","5.96012","0.13321"
"12006","72.00000","6.00012","0.13354"
"12086","72.48000","6.04012","0.13350"
"12166","72.96000","6.08012","0.13335"
"12246","73.44000","6.12012","0.13372"
"12326","73.92000","6.16012","0.13415"
"12406","74.40000","6.20005","0.13371"
"12486","74.88000","6.24011","0.13375"
"12566","75.36000","6.28011","0.13372"
"12646","75.84000","6.32017","0.13419"
"12726","76.32000","6.36011","0.13395"
"12806","76.80000","6.40017","0.13422"
"12886","77.28000","6.44011","0.13414"
"12966","77.76000","6.48011","0.13403"
"13046","78.24000","6.52011","0.13389"
"13126","78.72000","6.56005","0.13435"
"13206","79.20000","6.60011","0.13460"
"13286","79.68000","6.64011","0.13433"
"13366","80.16000","6.68010","0.13447"
"13446","80.64000","6.72016","0.13430"
"13526","81.12000","6.76016","0.13432"
"13606","81.60000","6.80010","0.13441"
"13686","82.08000","6.84016","0.13465"
"13766","82.56000","6.88010","0.13470"
"13846","83.04000","6.92004","0.13470"
"13926","83.52000","6.96010","0.13511"
"14006","84.00000","7.00016","0.13463"
"14086","84.48000","7.04010","0.13475"
"14166","84.96000","7.08016","0.13481"
"14246","85.44000","7.12010","0.13522"
"14326","85.92000","7.16016","0.13547"
"14406","86.40000","7.20015","0.13531"
"14486","86.88000","7.24009","0.13564"
"14566","87.36000","7.28003","0.13561"
"14646","87.84000","7.32003","0.13626"
"14726","88.32000","7.36009","0.13612"
"14806","88.80000","7.40009","0.13621"
"14886","89.28000","7.44015","0.13621"
"14966","89.76000","7.48009","0.13669"
"15046","90.24000","7.52015","0.13618"
"15126","90.72000","7.56015","0.13679"
"15206","91.20000","7.60015","0.13684"
"15286","91.68000","7.64009","0.13689"
"15366","92.16000","7.68009","0.13664"
"15446","92.64000","7.72014","0.13719"
"15526","93.12000","7.76008","0.13713"
"15606","93.60000","7.80014","0.13730"
"15686","94.08000","7.84014","0.13735"
"15766","94.56000","7.88014","0.13721"
"15846","95.04000","7.92014","0.13798"
"15926","95.52000","7.96014","0.13809"
"16006","96.00000","8.00014","0.13796"
"16086","96.48000","8.04008","0.13818"
"16166","96.96000","8.08008","0.13810"
"16246","97.44000","8.12014","0.13814"
"16326","97.92000","8.16013","0.13904"
"16406","98.40000","8.20013","0.13880"
"16486","98.88000","8.24013","0.13954"
"16566","99.36000","8.28019","0.13888"
"16646","99.84000","8.32013","0.13876"
"16726","100.32000","8.36007","0.13916"
"16806","100.80000","8.40007","0.13969"
"16886","101.28000","8.44007","0.13992"
"16966","101.76000","8.48019","0.13939"
"17046","102.24000","8.52013","0.13989"
"17126","102.72000","8.56013","0.13989"
"17206","103.20000","8.60013","0.14043"
"17286","103.68000","8.64013","0.14097"
"17366","104.16000","8.68007","0.14128"
"17446","104.64000","8.72006","0.14126"
"17526","105.12000","8.76006","0.14128"
"17606","105.60000","8.80012","0.14161"
"17686","106.08000","8.84018","0.14078"
"17766","106.56000","8.88012","0.14041"
"17846","107.04000","8.92012","0.14054"
"17926","107.52000","8.96012","0.14095"
"18006","108.00000","9.00012","0.14113"
"18086","108.48000","9.04012","0.14116"
"18166","108.96000","9.08012","0.14158"
"18246","109.44000","9.12006","0.14217"
"18326","109.92000","9.16012","0.14216"
"18406","110.40000","9.20005","0.14276"
"18486","110.88000","9.24011","0.14249"
"18566","111.36000","9.28017","0.14306"
"18646","111.84000","9.32017","0.14310"
"18726","112.32000","9.36011","0.14364"
"18806","112.80000","9.40011","0.14314"
"18886","113.28000","9.44011","0.14371"
"18966","113.76000","9.48005","0.14395"
"19046","114.24000","9.52011","0.14405"
"19126","114.72000","9.56011","0.14450"
"19206","115.20000","9.60005","0.14428"
"19286","115.68000","9.64011","0.14500"
"19366","116.16000","9.68017","0.14577"
"19446","116.64000","9.72016","0.14558"
"19526","117.12000","9.76022","0.14548"
"19606","117.60000","9.80010","0.14500"
"19686","118.08000","9.84010","0.14513"
"19766","118.56000","9.88010","0.14541"
"19846","119.04000","9.92010","0.14590"
"19926","119.52000","9.96010","0.14617"
"20006","120.00000","10.00016","0.14592"
"20086","120.48000","10.04010","0.14585"
"20166","120.96000","10.08016","0.14612"
"20246","121.44000","10.12016","0.14615"
"20326","121.92000","10.16010","0.14677"
"20406","122.40000","10.20009","0.14719"
"20486","122.88000","10.24003","0.14720"
"20566","123.36000","10.28009","0.14707"
"20646","123.84000","10.32009","0.14794"
"20726","124.32000","10.36009","0.14826"
"20806","124.80000","10.40015","0.14849"
"20886","125.28000","10.44015","0.14810"
"20966","125.76000","10.48015","0.14886"
"21046","126.24000","10.52009","0.14864"
"21126","126.72000","10.56015","0.14924"
"21206","127.20000","10.60009","0.14901"
"21286","127.68000","10.64009","0.14977"
"21366","128.16000","10.68014","0.15032"
"21446","128.64000","10.72014","0.14980"
"21526","129.12000","10.76014","0.15037"
"21606","129.60000","10.80020","0.15081"
"21686","130.08000","10.84008","0.15035"
"21766","130.56000","10.88014","0.15101"
"21846","131.04000","10.92008","0.15133"
"21926","131.52000","10.96008","0.15169"
"22006","132.00000","11.00008","0.15204"
"22086","132.48000","11.04008","0.15174"
"22166","132.96000","11.08008","0.15227"
"22246","133.44000","11.12014","0.15271"
"22326","133.92000","11.16014","0.15282"
"22406","134.40000","11.20008","0.15235"
"22486","134.88000","11.24019","0.15214"
"22566","135.36000","11.28013","0.15316"
"22646","135.84000","11.32007","0.15316"
"22726","136.32000","11.36007","0.15327"
"22806","136.80000","11.40007","0.15365"
"22886","137.28000","11.44007","0.15363"
"22966","137.76000","11.48019","0.15324"
"23046","138.24000","11.52013","0.15401"
"23126","138.72000","11.56013","0.15369"
"23206","139.20000","11.60019","0.15448"
"23286","139.68000","11.64013","0.15437"
"23366","140.16000","11.68013","0.15486"
"23446","140.64000","11.72006","0.15511"
"23526","141.12000","11.76006","0.15557"
"23606","141.60000","11.80006","0.15545"
"23686","142.08000","11.84018","0.15604"
"23766","142.56000","11.88012","0.15674"
"23846","143.04000","11.92012","0.15625"
"23926","143.52000","11.96012","0.15689"
"24006","144.00000","12.00018","0.15732"
"24086","144.48000","12.04012","0.15733"
"24166","144.96000","12.08012","0.15777"
"24246","145.44000","12.12006","0.15832"
"24326","145.92000","12.16006","0.15769"
"24406","146.40000","12.20011","0.15826"
"24486","146.88000","12.24011","0.15884"
"24566","147.36000","12.28011","0.15910"
"24646","147.84000","12.32011","0.15953"
"24726","148.32000","12.36017","0.15972"
"24806","148.80000","12.40011","0.15988"
"24886","149.28000","12.44011","0.16055"
"24966","149.76000","12.48011","0.16103"
"25046","150.24000","12.52011","0.16138"
"25126","150.72000","12.56011","0.16142"
"25206","151.20000","12.60011","0.16219"
"25286","151.68000","12.64017","0.16224"
"25366","152.16000","12.68011","0.16335"
"25446","152.64000","12.72016","0.16337"
"25526","153.12000","12.76016","0.16393"
"25606","153.60000","12.80010","0.16440"
"25686","154.08000","12.84004","0.16504"
"25766","154.56000","12.88010","0.16538"
"25846","155.04000","12.92010","0.16675"
"25926","155.52000","12.96010","0.16721"
"26006","156.00000","13.00016","0.16754"
"26086","156.48000","13.04016","0.16718"
"26166","156.96000","13.08016","0.16788"
"26246","157.44000","13.12016","0.16887"
"26326","157.92000","13.16010","0.16955"
"26406","158.40000","13.20003","0.16924"
"26486","158.88000","13.24009","0.17029"
"26566","159.36000","13.28003","0.17097"
"26646","159.84000","13.32015","0.17113"
"26726","160.32000","13.36015","0.17178"
"26806","160.80000","13.40009","0.17234"
"26886","161.28000","13.44015","0.17238"
"26966","161.76000","13.48015","0.17321"
"27046","162.24000","13.52009","0.17420"
"27126","162.72000","13.56009","0.17462"
"27206","163.20000","13.60009","0.17588"
"27286","163.68000","13.64009","0.17587"
"27366","164.16000","13.68015","0.17666"
"27446","164.64000","13.72014","0.17701"
"27526","165.12000","13.76014","0.17739"
"27606","165.60000","13.80014","0.17841"
"27686","166.08000","13.84020","0.17854"
"27766","166.56000","13.88008","0.17904"
"27846","167.04000","13.92014","0.18032"
"27926","167.52000","13.96008","0.18114"
"28006","168.00000","14.00008","0.18181"
"28086","168.48000","14.04014","0.18213"
"28166","168.96000","14.08014","0.18252"
"28246","169.44000","14.12014","0.18241"
"28326","169.92000","14.16020","0.17160"
"28406","170.40000","14.20019","0.17250"
"28486","170.88000","14.24013","0.17415"
"28566","171.36000","14.28007","0.17581"
"28646","171.84000","14.32001","0.17737"
"28726","172.32000","14.36013","0.17804"
"28806","172.80000","14.40013","0.17894"
"28886","173.28000","14.44013","0.18056"
"28966","173.76000","14.48013","0.18154"
"29046","174.24000","14.52013","0.18238"
"29126","174.72000","14.56013","0.16670"
"29206","175.20000","14.60013","0.15363"
"29286","175.68000","14.64013","0.15460"
"29366","176.16000","14.68007","0.15583"
"29446","176.64000","14.72006","0.15695"
"29526","177.12000","14.76012","0.15791"
"29606","177.60000","14.80012","0.15833"
"29686","178.08000","14.84018","0.15806"
"29766","178.56000","14.88012","0.15874"
"29846","179.04000","14.92012","0.16036"
"29926","179.52000","14.96018","0.16059"
"30006","180.00000","15.00006","0.16133"
"30086","180.48000","15.04012","0.16312"
"30166","180.96000","15.08012","0.16411"
"30246","181.44000","15.12006","0.16489"
"30326","181.92000","15.16012","0.16630"
"30406","182.40000","15.20017","0.16732"
"30486","182.88000","15.24011","0.16845"
"30566","183.36000","15.28011","0.16980"
"30646","183.84000","15.32017","0.16986"
"30726","184.32000","15.36011","0.17022"
"30806","184.80000","15.40011","0.17137"
"30886","185.28000","15.44011","0.17204"
"30966","185.76000","15.48011","0.17275"
"31046","186.24000","15.52011","0.17368"
"31126","186.72000","15.56017","0.17452"
"31206","187.20000","15.60011","0.17473"
"31286","187.68000","15.64016","0.17543"
"31366","188.16000","15.68016","0.17619"
"31446","188.64000","15.72010","0.17754"
"31526","189.12000","15.76010","0.17739"
"31606","189.60000","15.80010","0.17835"
"31686","190.08000","15.84010","0.17916"
"31766","190.56000","15.88010","0.17962"
"31846","191.04000","15.92010","0.18054"
"31926","191.52000","15.96010","0.18128"
"32006","192.00000","16.00016","0.18135"
"32086","192.48000","16.04016","0.18169"
"32166","192.96000","16.08010","0.18294"
"32246","193.44000","16.12009","0.18314"
"32326","193.92000","16.16009","0.18304"
"32406","194.40000","16.20003","0.18193"
"32486","194.88000","16.24009","0.18270"
"32566","195.36000","16.28009","0.18350"
"32646","195.84000","16.32015","0.18407"
"32726","196.32000","16.36015","0.18461"
"32806","196.80000","16.40015","0.18554"
"32886","197.28000","16.44009","0.18633"
"32966","197.76000","16.48015","0.18681"
"33046","198.24000","16.52009","0.18769"
"33126","198.72000","16.56009","0.18869"
"33206","199.20000","16.60009","0.19027"
"33286","199.68000","16.64008","0.19030"
"33366","200.16000","16.68008","0.19203"
"33446","200.64000","16.72014","0.19208"
"33526","201.12000","16.76014","0.19361"
"33606","201.60000","16.80014","0.19586"
"33686","202.08000","16.84008","0.19666"
"33766","202.56000","16.88008","0.19805"
"33846","203.04000","16.92008","0.19890"
"33926","203.52000","16.96008","0.19983"
"34006","204.00000","17.00008","0.20109"
"34086","204.48000","17.04014","0.20189"
"34166","204.96000","17.08014","0.20123"
"34246","205.44000","17.12013","0.19956"
"34326","205.92000","17.16019","0.20146"
"34406","206.40000","17.20013","0.20217"
"34486","206.88000","17.24007","0.20298"
"34566","207.36000","17.28013","0.20383"
"34646","207.84000","17.32001","0.20463"
"34726","208.32000","17.36013","0.20473"
"34806","208.80000","17.40013","0.20577"
"34886","209.28000","17.44019","0.20580"
"34966","209.76000","17.48013","0.20665"
"35046","210.24000","17.52013","0.20718"
"35126","210.72000","17.56013","0.20782"
"35206","211.20000","17.60012","0.20867"
"35286","211.68000","17.64013","0.20958"
"35366","212.16000","17.68006","0.21062"
"35446","212.64000","17.72012","0.21128"
"35526","213.12000","17.76012","0.21169"
"35606","213.60000","17.80012","0.21306"
"35686","214.08000","17.84012","0.21290"
"35766","214.56000","17.88012","0.21335"
"35846","215.04000","17.92012","0.21372"
"35926","215.52000","17.96012","0.17633"
"36006","216.00000","18.00012","0.15057"
"36086","216.48000","18.04012","0.15182"
"36166","216.96000","18.08012","0.15257"
"36246","217.44000","18.12012","0.15377"
"36326","217.92000","18.16011","0.15475"
"36406","218.40000","18.20011","0.15547"
"36486","218.88000","18.24011","0.15721"
"36566","219.36000","18.28011","0.15806"
"36646","219.84000","18.32017","0.15948"
"36726","220.32000","18.36011","0.16029"
"36806","220.80000","18.40005","0.13547"
"36886","221.28000","18.44011","0.13494"
"36966","221.76000","18.48017","0.13490"
"37046","222.24000","18.52011","0.13563"
"37126","222.72000","18.56017","0.13587"
"37206","223.20000","18.60011","0.13662"
"37286","223.68000","18.64010","0.13675"
"37366","224.16000","18.68010","0.13621"
"37446","224.64000","18.72010","0.13705"
"37526","225.12000","18.76004","0.13748"
"37606","225.60000","18.80010","0.13772"
"37686","226.08000","18.84010","0.13839"
"37766","226.56000","18.88016","0.13851"
"37846","227.04000","18.92016","0.13886"
"37926","227.52000","18.96010","0.13911"
"38006","228.00000","19.00016","0.13947"
"38086","228.48000","19.04016","0.14008"
"38166","228.96000","19.08010","0.13949"
"38246","229.44000","19.12004","0.14013"
"38326","229.92000","19.16003","0.14020"
"38406","230.40000","19.20009","0.14078"
"38486","230.88000","19.24015","0.14092"
"38566","231.36000","19.28009","0.14149"
"38646","231.84000","19.32015","0.14187"
"38726","232.32000","19.36015","0.14146"
"38806","232.80000","19.40015","0.14192"
"38886","233.28000","19.44009","0.14211"
"38966","233.76000","19.48009","0.14190"
"39046","234.24000","19.52009","0.14214"
"39126","234.72000","19.56009","0.14212"
"39206","235.20000","19.60015","0.14244"
"39286","235.68000","19.64009","0.14272"
"39366","236.16000","19.68014","0.14314"
"39446","236.64000","19.72020","0.14430"
"39526","237.12000","19.76014","0.14359"
"39606","237.60000","19.80014","0.14488"
"39686","238.08000","19.84014","0.14507"
"39766","238.56000","19.88002","0.14516"
"39846","239.04000","19.92008","0.14620"
"39926","239.52000","19.96013","0.14535"
"40006","240.00000","20.00008","0.14650"
"40086","240.48000","20.04014","0.14691"
"40166","240.96000","20.08014","0.14750"
"40246","241.44000","20.12019","0.14826"
"40326","241.92000","20.16014","0.14860"
"40406","242.40000","20.20007","0.14858"
"40486","242.88000","20.24007","0.14925"
"40566","243.36000","20.28013","0.14984"
"40646","243.84000","20.32013","0.14903"
"40726","244.32000","20.36007","0.14936"
"40806","244.80000","20.40013","0.14894"
"40886","245.28000","20.44013","0.14892"
"40966","245.76000","20.48013","0.14999"
"41046","246.24000","20.52013","0.15044"
"41126","246.72000","20.56013","0.15137"
"41206","247.20000","20.60007","0.15205"
"41286","247.68000","20.64006","0.15245"
"41366","248.16000","20.68012","0.15260"
"41446","248.64000","20.72012","0.15402"
"41526","249.12000","20.76012","0.15482"
"41606","249.60000","20.80018","0.15486"
"41686","250.08000","20.84012","0.15495"
"41766","250.56000","20.88012","0.15596"
"41846","251.04000","20.92012","0.15540"
"41926","251.52000","20.96006","0.15609"
"42006","252.00000","21.00011","0.15655"
"42086","252.48000","21.04012","0.15756"
"42166","252.96000","21.08012","0.15801"
"42246","253.44000","21.12011","0.15851"
"42326","253.92000","21.16011","0.15900"
"42406","254.40000","21.20017","0.15944"
"42486","254.88000","21.24017","0.16052"
"42566","255.36000","21.28011","0.16082"
"42646","255.84000","21.32011","0.16121"
"42726","256.32000","21.36005","0.16174"
"42806","256.80000","21.40011","0.16247"
"42886","257.28000","21.44011","0.16239"
"42966","257.76000","21.48011","0.16296"
"43046","258.24000","21.52017","0.16273"
"43126","258.72000","21.56017","0.16362"
"43206","259.20000","21.60011","0.16430"
"43286","259.68000","21.64010","0.16258"
"43366","260.16000","21.68010","0.16330"
"43446","260.64000","21.72010","0.16422"
"43526","261.12000","21.76004","0.16378"
"43606","261.60000","21.80010","0.16534"
"43686","262.08000","21.84016","0.16587"
"43766","262.56000","21.88016","0.16642"
"43846","263.04000","21.92016","0.16387"
"43926","263.52000","21.96010","0.16531"
"44006","264.00000","22.00010","0.16629"
"44086","264.48000","22.04016","0.16649"
"44166","264.96000","22.08004","0.16790"
"44246","265.44000","22.12010","0.16899"
"44326","265.92000","22.16003","0.16949"
"44406","266.40000","22.20015","0.17070"
"44486","266.88000","22.24009","0.16926"
"44566","267.36000","22.28021","0.16981"
"44646","267.84000","22.32009","0.16992"
"44726","268.32000","22.36015","0.16970"
"44806","268.80000","22.40009","0.16917"
"44886","269.28000","22.44009","0.17131"
"44966","269.76000","22.48009","0.17167"
"45046","270.24000","22.52009","0.17160"
"45126","270.72000","22.56009","0.17279"
"45206","271.20000","22.60015","0.17363"
"45286","271.68000","22.64014","0.17556"
"45366","272.16000","22.68008","0.17667"
"45446","272.64000","22.72020","0.17736"
"45526","273.12000","22.76014","0.17817"
"45606","273.60000","22.80008","0.17975"
"45686","274.08000","22.84008","0.18026"
"45766","274.56000","22.88014","0.18147"
"45846","275.04000","22.92008","0.18265"
"45926","275.52000","22.96020","0.18388"
"46006","276.00000","23.00014","0.18403"
"46086","276.48000","23.04008","0.18448"
"46166","276.96000","23.08013","0.18475"
"46246","277.44000","23.12020","0.18595"
"46326","277.92000","23.16013","0.18762"
"46406","278.40000","23.20013","0.18847"
"46486","278.88000","23.24007","0.19015"
"46566","279.36000","23.28007","0.19141"
"46646","279.84000","23.32013","0.19319"
"46726","280.32000","23.36013","0.19529"
"46806","280.80000","23.40013","0.19702"
"46886","281.28000","23.44013","0.19836"
"46966","281.76000","23.48013","0.20094"
"47046","282.24000","23.52012","0.20224"
"47126","282.72000","23.56012","0.20382"
"47206","283.20000","23.60007","0.20373"
"47286","283.68000","23.64012","0.20464"
"47366","284.16000","23.68012","0.20171"
"47446","284.64000","23.72012","0.20272"
"47526","285.12000","23.76012","0.20492"
"47606","285.60000","23.80012","0.20568"
"47686","286.08000","23.84012","0.20660"
"47766","286.56000","23.88012","0.20763"
"47846","287.04000","23.92006","0.20863"
"47926","287.52000","23.96006","0.20931"
"48006","288.00000","24.00012","0.20933"
"48086","288.48000","24.04005","0.21026"
"48166","288.96000","24.08017","0.21138"
"48246","289.44000","24.12017","0.21239"
"48326","289.92000","24.16011","0.21347"
"48406","290.40000","24.20011","0.21184"
"48486","290.88000","24.24011","0.21242"
"48566","291.36000","24.28011","0.21322"
"48646","291.84000","24.32005","0.21375"
"48726","292.32000","24.36011","0.21553"
"48806","292.80000","24.40011","0.21586"
"48886","293.28000","24.44011","0.21701"
"48966","293.76000","24.48017","0.20949"
"49046","294.24000","24.52017","0.21112"
"49126","294.72000","24.56010","0.21186"
"49206","295.20000","24.60016","0.21229"
"49286","295.68000","24.64004","0.21266"
"49366","296.16000","24.68010","0.21385"
"49446","296.64000","24.72010","0.21419"
"49526","297.12000","24.76010","0.21552"
"49606","297.60000","24.80016","0.21512"
"49686","298.08000","24.84010","0.21576"
"49766","298.56000","24.88016","0.21685"
"49846","299.04000","24.92016","0.21778"
"49926","299.52000","24.96016","0.21790"
"50006","300.00000","25.00010","0.21821"
"50086","300.48000","25.04010","0.14669"
"50166","300.96000","25.08003","0.14430"
"50246","301.44000","25.12009","0.14544"
"50326","301.92000","25.16009","0.14572"
"50406","302.40000","25.20009","0.14571"
"50486","302.88000","25.24009","0.14717"
"50566","303.36000","25.28015","0.14781"
"50646","303.84000","25.32015","0.14934"
"50726","304.32000","25.36009","0.15082"
"50806","304.80000","25.40015","0.15185"
"50886","305.28000","25.44009","0.15185"
"50966","305.76000","25.48009","0.15328"
"51046","306.24000","25.52015","0.15406"
"51126","306.72000","25.56009","0.15483"
"51206","307.20000","25.60014","0.15287"
"51286","307.68000","25.64014","0.15456"
"51366","308.16000","25.68014","0.15545"
"51446","308.64000","25.72008","0.15575"
"51526","309.12000","25.76008","0.15686"
"51606","309.60000","25.80008","0.15701"
"51686","310.08000","25.84008","0.15800"
"51766","310.56000","25.88014","0.15845"
"51846","311.04000","25.92014","0.15937"
"51926","311.52000","25.96014","0.15955"
"52006","312.00000","26.00014","0.16080"
"52086","312.48000","26.04008","0.16003"
"52166","312.96000","26.08013","0.16134"
"52246","313.44000","26.12013","0.16168"
"52326","313.92000","26.16007","0.16288"
"52406","314.40000","26.20007","0.16256"
"52486","314.88000","26.24007","0.15429"
"52566","315.36000","26.28007","0.15556"
"52646","315.84000","26.32019","0.15246"
"52726","316.32000","26.36013","0.15359"
"52806","316.80000","26.40013","0.15401"
"52886","317.28000","26.44013","0.15509"
"52966","317.76000","26.48013","0.15652"
"53046","318.24000","26.52007","0.15764"
"53126","318.72000","26.56013","0.15790"
"53206","319.20000","26.60013","0.15906"
"53286","319.68000","26.64013","0.16017"
"53366","320.16000","26.68012","0.16041"
"53446","320.64000","26.72012","0.16142"
"53526","321.12000","26.76012","0.16252"
"53606","321.60000","26.80018","0.16260"
"53686","322.08000","26.84012","0.16362"
"53766","322.56000","26.88012","0.16419"
"53846","323.04000","26.92012","0.16532"
"53926","323.52000","26.96006","0.16623"
"54006","324.00000","27.00012","0.16714"
"54086","324.48000","27.04012","0.16764"
"54166","324.96000","27.08011","0.16773"
"54246","325.44000","27.12017","0.16936"
"54326","325.92000","27.16017","0.17008"
"54406","326.40000","27.20011","0.17101"
"54486","326.88000","27.24011","0.17169"
"54566","327.36000","27.28005","0.17299"
"54646","327.84000","27.32005","0.17411"
"54726","328.32000","27.36011","0.17299"
"54806","328.80000","27.40011","0.17271"
"54886","329.28000","27.44011","0.17409"
"54966","329.76000","27.48017","0.17509"
"55046","330.24000","27.52016","0.17613"
"55126","330.72000","27.56016","0.17728"
"55206","331.20000","27.60016","0.17871"
"55286","331.68000","27.64010","0.17878"
"55366","332.16000","27.68004","0.18016"
"55446","332.64000","27.72010","0.18161"
"55526","333.12000","27.76010","0.18264"
"55606","333.60000","27.80016","0.18276"
"55686","334.08000","27.84016","0.18388"
"55766","334.56000","27.88010","0.18443"
"55846","335.04000","27.92010","0.18239"
"55926","335.52000","27.96010","0.18384"
"56006","336.00000","28.00010","0.18476"
"56086","336.48000","28.04009","0.18603"
"56166","336.96000","28.08010","0.18758"
"56246","337.44000","28.12009","0.18876"
"56326","337.92000","28.16009","0.19056"
"56406","338.40000","28.20009","0.19235"
"56486","338.88000","28.24009","0.19320"
"56566","339.36000","28.28015","0.19505"
"56646","339.84000","28.32015","0.19633"
"56726","340.32000","28.36009","0.19836"
"56806","340.80000","28.40009","0.20073"
"56886","341.28000","28.44009","0.20219"
"56966","341.76000","28.48015","0.20391"
"57046","342.24000","28.52015","0.20481"
"57126","342.72000","28.56009","0.20633"
"57206","343.20000","28.60009","0.20724"
"57286","343.68000","28.64014","0.20813"
"57366","344.16000","28.68014","0.20949"
"57446","344.64000","28.72008","0.21021"
"57526","345.12000","28.76014","0.21083"
"57606","345.60000","28.80008","0.21210"
"57686","346.08000","28.84014","0.21347"
"57766","346.56000","28.88014","0.21469"
"57846","347.04000","28.92014","0.21599"
"57926","347.52000","28.96008","0.21697"
"58006","348.00000","29.00014","0.21856"
"58086","348.48000","29.04008","0.21976"
"58166","348.96000","29.08014","0.21983"
"58246","349.44000","29.12007","0.22127"
"58326","349.92000","29.16007","0.22302"
"58406","350.40000","29.20007","0.22409"
"58486","350.88000","29.24013","0.22603"
"58566","351.36000","29.28013","0.22769"
"58646","351.84000","29.32013","0.22934"
"58726","352.32000","29.36013","0.23050"
"58806","352.80000","29.40013","0.23266"
"58886","353.28000","29.44013","0.23434"
"58966","353.76000","29.48007","0.23596"
"59046","354.24000","29.52007","0.23762"
"59126","354.72000","29.56013","0.23961"
"59206","355.20000","29.60007","0.24102"
"59286","355.68000","29.64012","0.24403"
"59366","356.16000","29.68012","0.24624"
"59446","356.64000","29.72012","0.24904"
"59526","357.12000","29.76012","0.25147"
"59606","357.60000","29.80012","0.25437"
"59686","358.08000","29.84012","0.25630"
"59766","358.56000","29.88006","0.25781"
"59846","359.04000","29.92012","0.26046"
"59926","359.52000","29.96012","0.26218"
"60006","360.00000","30.00012","0.26378"
"60086","360.48000","30.04017","0.26598"
"60166","360.96000","30.08012","0.26837"
"60246","361.44000","30.12012","0.27043"
"60326","361.92000","30.16017","0.27203"
"60406","362.40000","30.20011","0.27407"
"60486","362.88000","30.24005","0.27582"
"60566","363.36000","30.28011","0.27822"
"60646","363.84000","30.32011","0.28026"
"60726","364.32000","30.36017","0.28183"
"60806","364.80000","30.40011","0.28405"
"60886","365.28000","30.44011","0.28600"
"60966","365.76000","30.48017","0.28804"
"61046","366.24000","30.52017","0.28898"
"61126","366.72000","30.56017","0.29084"
"61206","367.20000","30.60011","0.29219"
"61286","367.68000","30.64005","0.29362"
"61366","368.16000","30.68004","0.29550"
"61446","368.64000","30.72016","0.29780"
"61526","369.12000","30.76016","0.29930"
"61606","369.60000","30.80010","0.30123"
"61686","370.08000","30.84016","0.30195"
"61766","370.56000","30.88016","0.28301"
"61846","371.04000","30.92010","0.28373"
"61926","371.52000","30.96016","0.28386"
"62006","372.00000","31.00010","0.28492"
"62086","372.48000","31.04015","0.26256"
"62166","372.96000","31.08015","0.26468"
"62246","373.44000","31.12003","0.26644"
"62326","373.92000","31.16015","0.26946"
"62406","374.40000","31.20009","0.26945"
"62486","374.88000","31.24015","0.26880"
"62566","375.36000","31.28015","0.26797"
"62646","375.84000","31.32009","0.26738"
"62726","376.32000","31.36003","0.26937"
"62806","376.80000","31.40009","0.18444"
"62886","377.28000","31.44015","0.18305"
"62966","377.76000","31.48014","0.18328"
"63046","378.24000","31.52014","0.18334"
"63126","378.72000","31.56008","0.18425"
"63206","379.20000","31.60008","0.18426"
"63286","379.68000","31.64014","0.18449"
"63366","380.16000","31.68014","0.18477"
"63446","380.64000","31.72008","0.18565"
"63526","381.12000","31.76014","0.18602"
"63606","381.60000","31.80008","0.18671"
"63686","382.08000","31.84014","0.18689"
"63766","382.56000","31.88014","0.18672"
"63846","383.04000","31.92014","0.18745"
"63926","383.52000","31.96014","0.13541"
"64006","384.00000","32.00019","0.13635"
"64086","384.48000","32.04007","0.13621"
"64166","384.96000","32.08007","0.13677"
"64246","385.44000","32.12007","0.13678"
"64326","385.92000","32.16007","0.13749"
"64406","386.40000","32.20007","0.13686"
"64486","386.88000","32.24019","0.13736"
"64566","387.36000","32.28019","0.13774"
"64646","387.84000","32.32007","0.13784"
"64726","388.32000","32.36013","0.13782"
"64806","388.80000","32.40013","0.13796"
"64886","389.28000","32.44007","0.13814"
"64966","389.76000","32.48006","0.13768"
"65046","390.24000","32.52012","0.13820"
"65126","390.72000","32.56007","0.13808"
"65206","391.20000","32.60012","0.13869"
"65286","391.68000","32.64012","0.13839"
"65366","392.16000","32.68018","0.13942"
"65446","392.64000","32.72018","0.13915"
"65526","393.12000","32.76012","0.13919"
"65606","393.60000","32.80012","0.13890"
"65686","394.08000","32.84000","0.13931"
"65766","394.56000","32.88012","0.14012"
"65846","395.04000","32.92006","0.14026"
"65926","395.52000","32.96012","0.14100"
"66006","396.00000","33.00011","0.14081"
"66086","396.48000","33.04017","0.14012"
"66166","396.96000","33.08011","0.14035"
"66246","397.44000","33.12011","0.14093"
"66326","397.92000","33.16011","0.14091"
"66406","398.40000","33.20005","0.14108"
"66486","398.88000","33.24005","0.14125"
"66566","399.36000","33.28011","0.14173"
"66646","399.84000","33.32011","0.14226"
"66726","400.32000","33.36011","0.14252"
"66806","400.80000","33.40017","0.14312"
"66886","401.28000","33.44011","0.14298"
"66966","401.76000","33.48010","0.14312"
"67046","402.24000","33.52016","0.14326"
"67126","402.72000","33.56010","0.14306"
"67206","403.20000","33.60004","0.14378"
"67286","403.68000","33.64010","0.14394"
"67366","404.16000","33.68004","0.14330"
"67446","404.64000","33.72016","0.14348"
"67526","405.12000","33.76016","0.14360"
"67606","405.60000","33.80010","0.14357"
"67686","406.08000","33.84016","0.14286"
"67766","406.56000","33.88010","0.14318"
"67846","407.04000","33.92004","0.14305"
"67926","407.52000","33.96010","0.14316"
"68006","408.00000","34.00010","0.14357"
"68086","408.48000","34.04004","0.14377"
"68166","408.96000","34.08015","0.14376"
"68246","409.44000","34.12009","0.14353"
"68326","409.92000","34.16015","0.14470"
"68406","410.40000","34.20015","0.14441"
"68486","410.88000","34.24015","0.14506"
"68566","411.36000","34.28003","0.14520"
"68646","411.84000","34.32009","0.14510"
"68726","412.32000","34.36003","0.14546"
"68806","412.80000","34.40009","0.14641"
"68886","413.28000","34.44020","0.14525"
"68966","413.76000","34.48014","0.14355"
"69046","414.24000","34.52008","0.14472"
"69126","414.72000","34.56014","0.14478"
"69206","415.20000","34.60014","0.14563"
"69286","415.68000","34.64008","0.14475"
"69366","416.16000","34.68014","0.14526"
"69446","416.64000","34.72008","0.14512"
"69526","417.12000","34.76008","0.14521"
"69606","417.60000","34.80014","0.14477"
"69686","418.08000","34.84014","0.14495"
"69766","418.56000","34.88014","0.14479"
"69846","419.04000","34.92014","0.14467"
"69926","419.52000","34.96014","0.14486"
"70006","420.00000","35.00013","0.14317"
"70086","420.48000","35.04013","0.14339"
"70166","420.96000","35.08007","0.14363"
"70246","421.44000","35.12013","0.14352"
"70326","421.92000","35.16013","0.14370"
"70406","422.40000","35.20013","0.14407"
"70486","422.88000","35.24013","0.14431"
"70566","423.36000","35.28013","0.14447"
"70646","423.84000","35.32013","0.14520"
"70726","424.32000","35.36013","0.14470"
"70806","424.80000","35.40007","0.14364"
"70886","425.28000","35.44006","0.14406"
"70966","425.76000","35.48007","0.14402"
"71046","426.24000","35.52007","0.14441"
"71126","426.72000","35.56012","0.14393"
"71206","427.20000","35.60012","0.14406"
"71286","427.68000","35.64012","0.14439"
"71366","428.16000","35.68012","0.14341"
"71446","428.64000","35.72018","0.14397"
"71526","429.12000","35.76006","0.14365"
"71606","429.60000","35.80006","0.14392"
"71686","430.08000","35.84011","0.14446"
"71766","430.56000","35.88012","0.14421"
"71846","431.04000","35.92012","0.14351"
"71926","431.52000","35.96017","0.14304"
"72006","432.00000","36.00005","0.14342"
"72086","432.48000","36.04011","0.14349"
"72166","432.96000","36.08012","0.14370"
"72246","433.44000","36.12011","0.14393"
"72326","433.92000","36.16005","0.14358"
"72406","434.40000","36.20011","0.14385"
"72486","434.88000","36.24011","0.14393"
"72566","435.36000","36.28011","0.14442"
"72646","435.84000","36.32017","0.14467"
"72726","436.32000","36.36011","0.14451"
"72806","436.80000","36.40023","0.14474"
"72886","437.28000","36.44017","0.14480"
"72966","437.76000","36.48005","0.14434"
"73046","438.24000","36.52010","0.14510"
"73126","438.72000","36.56010","0.14464"
"73206","439.20000","36.60010","0.14514"
"73286","439.68000","36.64010","0.14571"
"73366","440.16000","36.68010","0.14450"
"73446","440.64000","36.72010","0.14462"
"73526","441.12000","36.76022","0.14535"
"73606","441.60000","36.80016","0.14561"
"73686","442.08000","36.84016","0.14596"
"73766","442.56000","36.88010","0.14653"
"73846","443.04000","36.92010","0.14634"
"73926","443.52000","36.96009","0.14647"
"74006","444.00000","37.00010","0.14617"
"74086","444.48000","37.04010","0.14661"
"74166","444.96000","37.08015","0.14615"
"74246","445.44000","37.12015","0.14640"
"74326","445.92000","37.16015","0.14659"
"74406","446.40000","37.20009","0.14647"
"74486","446.88000","37.24009","0.14627"
"74566","447.36000","37.28003","0.14683"
"74646","447.84000","37.32009","0.14700"
"74726","448.32000","37.36015","0.14764"
"74806","448.80000","37.40009","0.14773"
"74886","449.28000","37.44015","0.14830"
"74966","449.76000","37.48009","0.14763"
"75046","450.24000","37.52015","0.14781"
"75126","450.72000","37.56014","0.14813"
"75206","451.20000","37.60008","0.14814"
"75286","451.68000","37.64008","0.14846"
"75366","452.16000","37.68008","0.14893"
"75446","452.64000","37.72008","0.14884"
"75526","453.12000","37.76008","0.14933"
"75606","453.60000","37.80020","0.14896"
"75686","454.08000","37.84014","0.14965"
"75766","454.56000","37.88014","0.15067"
"75846","455.04000","37.92020","0.15019"
"75926","455.52000","37.96008","0.15035"
"76006","456.00000","38.00007","0.15010"
"76086","456.48000","38.04008","0.15009"
"76166","456.96000","38.08007","0.15001"
"76246","457.44000","38.12013","0.14981"
"76326","457.92000","38.16013","0.15005"
"76406","458.40000","38.20013","0.15075"
"76486","458.88000","38.24013","0.15125"
"76566","459.36000","38.28013","0.15162"
"76646","459.84000","38.32013","0.15208"
"76726","460.32000","38.36013","0.15248"
"76806","460.80000","38.40013","0.15289"
"76886","461.28000","38.44007","0.15331"
"76966","461.76000","38.48013","0.15362"
"77046","462.24000","38.52012","0.15384"
"77126","462.72000","38.56012","0.15385"
"77206","463.20000","38.60012","0.15408"
"77286","463.68000","38.64012","0.15421"
"77366","464.16000","38.68006","0.15488"
"77446","464.64000","38.72012","0.15444"
"77526","465.12000","38.76006","0.15497"
"77606","465.60000","38.80006","0.15514"
"77686","466.08000","38.84012","0.15540"
"77766","466.56000","38.88012","0.15567"
"77846","467.04000","38.92012","0.15534"
"77926","467.52000","38.96011","0.15349"
"78006","468.00000","39.00011","0.15455"
"78086","468.48000","39.04012","0.15401"
"78166","468.96000","39.08017","0.15487"
"78246","469.44000","39.12005","0.15465"
"78326","469.92000","39.16005","0.15496"
"78406","470.40000","39.20011","0.15476"
"78486","470.88000","39.24011","0.15519"
"78566","471.36000","39.28011","0.15522"
"78646","471.84000","39.32016","0.15536"
"78726","472.32000","39.36011","0.15509"
"78806","472.80000","39.40011","0.15533"
"78886","473.28000","39.44017","0.15428"
"78966","473.76000","39.48011","0.15456"
"79046","474.24000","39.52010","0.15453"
"79126","474.72000","39.56010","0.15439"
"79206","475.20000","39.60016","0.15389"
"79286","475.68000","39.64010","0.15432"
"79366","476.16000","39.68016","0.15450"
"79446","476.64000","39.72010","0.15429"
"79526","477.12000","39.76016","0.14591"
"79606","477.60000","39.80016","0.14656"
"79686","478.08000","39.84010","0.14736"
"79766","478.56000","39.88009","0.14788"
"79846","479.04000","39.92009","0.14769"
"79926","479.52000","39.96009","0.14816"
"80006","480.00000","40.00016","0.14800"
"80086","480.48000","40.04015","0.14757"
"80166","480.96000","40.08009","0.14809"
"80246","481.44000","40.12020","0.14831"
"80326","481.92000","40.16009","0.14926"
"80406","482.40000","40.20009","0.14847"
"80486","482.88000","40.24009","0.14855"
"80566","483.36000","40.28009","0.14898"
"80646","483.84000","40.32009","0.14931"
"80726","484.32000","40.36015","0.14901"
"80806","484.80000","40.40014","0.14881"
"80886","485.28000","40.44008","0.14942"
"80966","485.76000","40.48014","0.14887"
"81046","486.24000","40.52008","0.14928"
"81126","486.72000","40.56015","0.14949"
"81206","487.20000","40.60008","0.14956"
"81286","487.68000","40.64002","0.14940"
"81366","488.16000","40.68008","0.14997"
"81446","488.64000","40.72014","0.14969"
"81526","489.12000","40.76008","0.15088"
"81606","489.60000","40.80020","0.14998"
"81686","490.08000","40.84014","0.15045"
"81766","490.56000","40.88013","0.14955"
"81846","491.04000","40.92014","0.15000"
"81926","491.52000","40.96008","0.14845"
"82006","492.00000","41.00002","0.14852"
"82086","492.48000","41.04013","0.14856"
"82166","492.96000","41.08007","0.14830"
"82246","493.44000","41.12007","0.14817"
"82326","493.92000","41.16013","0.14836"
"82406","494.40000","41.20013","0.14850"
"82486","494.88000","41.24007","0.14914"
"82566","495.36000","41.28013","0.14947"
"82646","495.84000","41.32013","0.14922"
"82726","496.32000","41.36007","0.14871"
"82806","496.80000","41.40007","0.14937"
"82886","497.28000","41.44006","0.14940"
"82966","497.76000","41.48013","0.14973"
"83046","498.24000","41.52019","0.14895"
"83126","498.72000","41.56012","0.14885"
"83206","499.20000","41.60012","0.14949"
"83286","499.68000","41.64012","0.14904"
"83366","500.16000","41.68006","0.14898"
"83446","500.64000","41.72006","0.14860"
"83526","501.12000","41.76012","0.14853"
"83606","501.60000","41.80012","0.14883"
"83686","502.08000","41.84012","0.14833"
"83766","502.56000","41.88012","0.14765"
"83846","503.04000","41.92012","0.14779"
"83926","503.52000","41.96011","0.14769"
"84006","504.00000","42.00011","0.14741"
"84086","504.48000","42.04011","0.14738"
"84166","504.96000","42.08011","0.14777"
"84246","505.44000","42.12006","0.14762"
"84326","505.92000","42.16005","0.14841"
"84406","506.40000","42.20011","0.14743"
"84486","506.88000","42.24010","0.14683"
"84566","507.36000","42.28017","0.14700"
"84646","507.84000","42.32017","0.14696"
"84726","508.32000","42.36011","0.14671"
"84806","508.80000","42.40010","0.14691"
"84886","509.28000","42.44011","0.14695"
"84966","509.76000","42.48010","0.14706"
"85046","510.24000","42.52011","0.14650"
"85126","510.72000","42.56010","0.14647"
"85206","511.20000","42.60010","0.14660"
"85286","511.68000","42.64010","0.14690"
"85366","512.16000","42.68016","0.14719"
"85446","512.64000","42.72016","0.14760"
"85526","513.12000","42.76015","0.14721"
"85606","513.60000","42.80010","0.14744"
"85686","514.08000","42.84004","0.14771"
"85766","514.56000","42.88010","0.14798"
"85846","515.04000","42.92015","0.14819"
"85926","515.52000","42.96009","0.14868"
"86006","516.00000","43.00015","0.14833"
"86086","516.48000","43.04009","0.14851"
"86166","516.96000","43.08009","0.14858"
"86246","517.44000","43.12015","0.14936"
"86326","517.92000","43.16009","0.14893"
"86406","518.40000","43.20009","0.14875"
"86486","518.88000","43.24009","0.14899"
"86566","519.36000","43.28009","0.14949"
"86646","519.84000","43.32009","0.14891"
"86726","520.32000","43.36015","0.14910"
"86806","520.80000","43.40015","0.14909"
"86886","521.28000","43.44009","0.14904"
"86966","521.76000","43.48014","0.14937"
"87046","522.24000","43.52015","0.14932"
"87126","522.72000","43.56009","0.14879"
"87206","523.20000","43.60008","0.14916"
"87286","523.68000","43.64014","0.14929"
"87366","524.16000","43.68008","0.14926"
"87446","524.64000","43.72014","0.14896"
"87526","525.12000","43.76014","0.14928"
"87606","525.60000","43.80014","0.14905"
"87686","526.08000","43.84013","0.14943"
"87766","526.56000","43.88014","0.14987"
"87846","527.04000","43.92008","0.14989"
"87926","527.52000","43.96007","0.14993"
"88006","528.00000","44.00013","0.15000"
"88086","528.48000","44.04013","0.15017"
"88166","528.96000","44.08014","0.14964"
"88246","529.44000","44.12013","0.14963"
"88326","529.92000","44.16013","0.14951"
"88406","530.40000","44.20019","0.14984"
"88486","530.88000","44.24013","0.14762"
"88566","531.36000","44.28013","0.14865"
"88646","531.84000","44.32007","0.14907"
"88726","532.32000","44.36007","0.14916"
"88806","532.80000","44.40013","0.14882"
"88886","533.28000","44.44013","0.14922"
"88966","533.76000","44.48012","0.14928"
"89046","534.24000","44.52013","0.14960"
"89126","534.72000","44.56012","0.15005"
"89206","535.20000","44.60012","0.14992"
"89286","535.68000","44.64006","0.15010"
"89366","536.16000","44.68006","0.14975"
"89446","536.64000","44.72006","0.15044"
"89526","537.12000","44.76012","0.15075"
"89606","537.60000","44.80006","0.15041"
"89686","538.08000","44.84012","0.14976"
"89766","538.56000","44.88012","0.14973"
"89846","539.04000","44.92011","0.14937"
"89926","539.52000","44.96011","0.15016"
"90006","540.00000","45.00011","0.14987"
"90086","540.48000","45.04005","0.14998"
"90166","540.96000","45.08011","0.15009"
"90246","541.44000","45.12005","0.15003"
"90326","541.92000","45.16005","0.15011"
"90406","542.40000","45.20017","0.15009"
"90486","542.88000","45.24017","0.15055"
"90566","543.36000","45.28011","0.15052"
"90646","543.84000","45.32017","0.15059"
"90726","544.32000","45.36016","0.15063"
"90806","544.80000","45.40010","0.15109"
"90886","545.28000","45.44011","0.15062"
"90966","545.76000","45.48010","0.15114"
"91046","546.24000","45.52005","0.15084"
"91126","546.72000","45.56016","0.15074"
"91206","547.20000","45.60017","0.15121"
"91286","547.68000","45.64010","0.15078"
"91366","548.16000","45.68016","0.15140"
"91446","548.64000","45.72010","0.15132"
"91526","549.12000","45.76009","0.15172"
"91606","549.60000","45.80010","0.15158"
"91686","550.08000","45.84003","0.15169"
"91766","550.56000","45.88010","0.15237"
"91846","551.04000","45.92015","0.15088"
"91926","551.52000","45.96016","0.15108"
"92006","552.00000","46.00009","0.15139"
"92086","552.48000","46.04015","0.15161"
"92166","552.96000","46.08015","0.15068"
"92246","553.44000","46.12009","0.15148"
"92326","553.92000","46.16015","0.15163"
"92406","554.40000","46.20009","0.15152"
"92486","554.88000","46.24009","0.15161"
"92566","555.36000","46.28014","0.15185"
"92646","555.84000","46.32015","0.15068"
"92726","556.32000","46.36014","0.15106"
"92806","556.80000","46.40015","0.15111"
"92886","557.28000","46.44009","0.15152"
"92966","557.76000","46.48014","0.15165"
"93046","558.24000","46.52015","0.15144"
"93126","558.72000","46.56002","0.15226"
"93206","559.20000","46.60009","0.15147"
"93286","559.68000","46.64014","0.15088"
"93366","560.16000","46.68014","0.15015"
"93446","560.64000","46.72013","0.15022"
"93526","561.12000","46.76007","0.15106"
"93606","561.60000","46.80008","0.15109"
"93686","562.08000","46.84014","0.15105"
"93766","562.56000","46.88008","0.15132"
"93846","563.04000","46.92007","0.15125"
"93926","563.52000","46.96013","0.15137"
"94006","564.00000","47.00013","0.15144"
"94086","564.48000","47.04013","0.15221"
"94166","564.96000","47.08013","0.15216"
"94246","565.44000","47.12013","0.15209"
"94326","565.92000","47.16013","0.15206"
"94406","566.40000","47.20013","0.15238"
"94486","566.88000","47.24007","0.15263"
"94566","567.36000","47.28007","0.15250"
"94646","567.84000","47.32007","0.15191"
"94726","568.32000","47.36013","0.15298"
"94806","568.80000","47.40013","0.15285"
"94886","569.28000","47.44019","0.15310"
"94966","569.76000","47.48006","0.15345"
"95046","570.24000","47.52012","0.15371"
"95126","570.72000","47.56013","0.15366"
"95206","571.20000","47.60012","0.15320"
"95286","571.68000","47.64012","0.15293"
"95366","572.16000","47.68012","0.15318"
"95446","572.64000","47.72005","0.15298"
"95526","573.12000","47.76012","0.15363"
"95606","573.60000","47.80012","0.15359"
"95686","574.08000","47.84012","0.15207"
"95766","574.56000","47.88017","0.15201"
"95846","575.04000","47.92017","0.15174"
"95926","575.52000","47.96011","0.15159"
"96006","576.00000","48.00011","0.15096"
"96086","576.48000","48.04005","0.15110"
"96166","576.96000","48.08011","0.15148"
"96246","577.44000","48.12017","0.15126"
"96326","577.92000","48.16011","0.15164"
"96406","578.40000","48.20011","0.15207"
"96486","578.88000","48.24017","0.15239"
"96566","579.36000","48.28017","0.15208"
"96646","579.84000","48.32011","0.15218"
"96726","580.32000","48.36011","0.15226"
"96806","580.80000","48.40005","0.15220"
"96886","581.28000","48.44004","0.15180"
"96966","581.76000","48.48016","0.15233"
"97046","582.24000","48.52010","0.15219"
"97126","582.72000","48.56017","0.15214"
"97206","583.20000","48.60010","0.15292"
"97286","583.68000","48.64016","0.15280"
"97366","584.16000","48.68016","0.15233"
"97446","584.64000","48.72010","0.15168"
"97526","585.12000","48.76004","0.15187"
"97606","585.60000","48.80009","0.15186"
"97686","586.08000","48.84010","0.15224"
"97766","586.56000","48.88009","0.15199"
"97846","587.04000","48.92016","0.15257"
"97926","587.52000","48.96009","0.15256"
"98006","588.00000","49.00016","0.15289"
"98086","588.48000","49.04009","0.15207"
"98158","588.91200","49.07608","0.15303"