File: Trajectories_together/161223Specimen_RawData_6.csv
"","V1","V2","V3"
"1","End date","12/23/2016",""
"2","Specimen label","22BG_75",""
"3","Maximum Load","0.92771","N"
"4","Time","Extension","Load"
"5","(s)","(mm)","(N)"
"6","0.00000","0.00006","-0.00051"
"75","0.41400","0.03474","0.00027"
"144","0.82800","0.06918","0.00067"
"213","1.24200","0.10368","0.00071"
"282","1.65600","0.13817","0.00119"
"351","2.07000","0.17279","0.00082"
"420","2.48400","0.20717","0.00090"
"489","2.89800","0.24167","0.00120"
"558","3.31200","0.27617","0.00125"
"627","3.72600","0.31073","0.00158"
"696","4.14000","0.34522","0.00167"
"765","4.55400","0.37966","0.00162"
"834","4.96800","0.41410","0.00204"
"903","5.38200","0.44866","0.00189"
"972","5.79600","0.48322","0.00200"
"1041","6.21000","0.51772","0.00209"
"1110","6.62400","0.55210","0.00199"
"1179","7.03800","0.58665","0.00258"
"1248","7.45200","0.62121","0.00234"
"1317","7.86600","0.65565","0.00255"
"1386","8.28000","0.69009","0.00257"
"1455","8.69400","0.72465","0.00244"
"1524","9.10800","0.75921","0.00238"
"1593","9.52200","0.79371","0.00218"
"1662","9.93600","0.82820","0.00247"
"1731","10.35000","0.86264","0.00304"
"1800","10.76400","0.89720","0.00247"
"1869","11.17800","0.93170","0.00298"
"1938","11.59200","0.96620","0.00253"
"2007","12.00600","1.00064","0.00287"
"2076","12.42000","1.03520","0.00303"
"2145","12.83400","1.06969","0.00299"
"2214","13.24800","1.10425","0.00303"
"2283","13.66200","1.13869","0.00367"
"2352","14.07600","1.17319","0.00360"
"2421","14.49000","1.20769","0.00347"
"2490","14.90400","1.24219","0.00320"
"2559","15.31800","1.27663","0.00309"
"2628","15.73200","1.31112","0.00297"
"2697","16.14600","1.34568","0.00329"
"2766","16.56000","1.38024","0.00373"
"2835","16.97400","1.41468","0.00345"
"2904","17.38800","1.44918","0.00376"
"2973","17.80200","1.48368","0.00358"
"3042","18.21600","1.51818","0.00361"
"3111","18.63000","1.55267","0.00396"
"3180","19.04400","1.58717","0.00410"
"3249","19.45800","1.62167","0.00391"
"3318","19.87200","1.65623","0.00436"
"3387","20.28600","1.69073","0.00455"
"3456","20.70000","1.72517","0.00416"
"3525","21.11400","1.75967","0.00446"
"3594","21.52800","1.79416","0.00450"
"3663","21.94200","1.82866","0.00431"
"3732","22.35600","1.86316","0.00474"
"3801","22.77000","1.89760","0.00445"
"3870","23.18400","1.93216","0.00502"
"3939","23.59800","1.96672","0.00458"
"4008","24.01200","2.00128","0.00494"
"4077","24.42600","2.03565","0.00490"
"4146","24.84000","2.07015","0.00467"
"4215","25.25400","2.10471","0.00497"
"4284","25.66800","2.13921","0.00520"
"4353","26.08200","2.17359","0.00491"
"4422","26.49600","2.20815","0.00519"
"4491","26.91000","2.24271","0.00521"
"4560","27.32400","2.27720","0.00540"
"4629","27.73800","2.31170","0.00545"
"4698","28.15200","2.34614","0.00517"
"4767","28.56600","2.38064","0.00488"
"4836","28.98000","2.41520","0.00527"
"4905","29.39400","2.44970","0.00493"
"4974","29.80800","2.48414","0.00549"
"5043","30.22200","2.51869","0.00572"
"5112","30.63600","2.55313","0.00555"
"5181","31.05000","2.58775","0.00592"
"5250","31.46400","2.62219","0.00606"
"5319","31.87800","2.65663","0.00592"
"5388","32.29200","2.69119","0.00591"
"5457","32.70600","2.72569","0.00594"
"5526","33.12000","2.76018","0.00576"
"5595","33.53400","2.79462","0.00579"
"5664","33.94800","2.82918","0.00598"
"5733","34.36200","2.86374","0.00633"
"5802","34.77600","2.89818","0.00606"
"5871","35.19000","2.93268","0.00625"
"5940","35.60400","2.96712","0.00640"
"6009","36.01800","3.00167","0.00607"
"6078","36.43200","3.03617","0.00594"
"6147","36.84600","3.07061","0.00672"
"6216","37.26000","3.10511","0.00626"
"6285","37.67400","3.13973","0.00628"
"6354","38.08800","3.17423","0.00682"
"6423","38.50200","3.20866","0.00680"
"6492","38.91600","3.24316","0.00673"
"6561","39.33000","3.27766","0.00687"
"6630","39.74400","3.31222","0.00657"
"6699","40.15800","3.34672","0.00646"
"6768","40.57200","3.38116","0.00676"
"6837","40.98600","3.41566","0.00690"
"6906","41.40000","3.45016","0.00716"
"6975","41.81400","3.48471","0.00752"
"7044","42.22800","3.51921","0.00764"
"7113","42.64200","3.55365","0.00713"
"7182","43.05600","3.58815","0.00719"
"7251","43.47000","3.62265","0.00752"
"7320","43.88400","3.65721","0.00756"
"7389","44.29800","3.69165","0.00796"
"7458","44.71200","3.72614","0.00746"
"7527","45.12600","3.76070","0.00763"
"7596","45.54000","3.79514","0.00724"
"7665","45.95400","3.82970","0.00797"
"7734","46.36800","3.86414","0.00712"
"7803","46.78200","3.89864","0.00719"
"7872","47.19600","3.93319","0.00758"
"7941","47.61000","3.96769","0.00781"
"8010","48.02400","4.00219","0.00816"
"8079","48.43800","4.03663","0.00823"
"8148","48.85200","4.07119","0.00782"
"8217","49.26600","4.10569","0.00814"
"8286","49.68000","4.14019","0.00784"
"8355","50.09400","4.17462","0.00840"
"8424","50.50800","4.20918","0.00796"
"8493","50.92200","4.24368","0.00773"
"8562","51.33600","4.27812","0.00781"
"8631","51.75000","4.31268","0.00800"
"8700","52.16400","4.34724","0.00776"
"8769","52.57800","4.38168","0.00872"
"8838","52.99200","4.41617","0.00841"
"8907","53.40600","4.45067","0.00837"
"8976","53.82000","4.48517","0.00859"
"9045","54.23400","4.51961","0.00834"
"9114","54.64800","4.55417","0.00827"
"9183","55.06200","4.58861","0.00868"
"9252","55.47600","4.62317","0.00855"
"9321","55.89000","4.65772","0.00904"
"9390","56.30400","4.69222","0.00861"
"9459","56.71800","4.72666","0.00868"
"9528","57.13200","4.76116","0.00913"
"9597","57.54600","4.79572","0.00929"
"9666","57.96000","4.83016","0.00893"
"9735","58.37400","4.86466","0.00943"
"9804","58.78800","4.89909","0.00916"
"9873","59.20200","4.93371","0.00948"
"9942","59.61600","4.96821","0.00885"
"10011","60.03000","5.00271","0.00940"
"10080","60.44400","5.03715","0.00923"
"10149","60.85800","5.07165","0.00936"
"10218","61.27200","5.10620","0.00951"
"10287","61.68600","5.14070","0.00961"
"10356","62.10000","5.17514","0.00955"
"10425","62.51400","5.20964","0.00975"
"10494","62.92800","5.24420","0.01013"
"10563","63.34200","5.27870","0.00980"
"10632","63.75600","5.31320","0.00990"
"10701","64.17000","5.34764","0.01010"
"10770","64.58400","5.38219","0.00938"
"10839","64.99800","5.41669","0.00930"
"10908","65.41200","5.45119","0.00967"
"10977","65.82600","5.48563","0.00974"
"11046","66.24000","5.52019","0.01016"
"11115","66.65400","5.55475","0.00963"
"11184","67.06800","5.58924","0.01033"
"11253","67.48200","5.62368","0.01043"
"11322","67.89600","5.65818","0.01046"
"11391","68.31000","5.69268","0.01057"
"11460","68.72400","5.72724","0.01066"
"11529","69.13800","5.76162","0.01047"
"11598","69.55200","5.79618","0.01048"
"11667","69.96600","5.83068","0.01005"
"11736","70.38000","5.86517","0.00993"
"11805","70.79400","5.89973","0.00972"
"11874","71.20800","5.93417","0.01065"
"11943","71.62200","5.96867","0.01017"
"12012","72.03600","6.00317","0.00998"
"12081","72.45000","6.03767","0.01030"
"12150","72.86400","6.07211","0.01082"
"12219","73.27800","6.10666","0.01080"
"12288","73.69200","6.14116","0.01072"
"12357","74.10600","6.17572","0.01059"
"12426","74.52000","6.21022","0.01072"
"12495","74.93400","6.24466","0.01085"
"12564","75.34800","6.27916","0.01017"
"12633","75.76200","6.31371","0.01042"
"12702","76.17600","6.34821","0.01079"
"12771","76.59000","6.38265","0.01111"
"12840","77.00400","6.41715","0.01076"
"12909","77.41800","6.45171","0.01119"
"12978","77.83200","6.48627","0.01025"
"13047","78.24600","6.52071","0.01056"
"13116","78.66000","6.55514","0.00969"
"13185","79.07400","6.58970","0.01023"
"13254","79.48800","6.62420","0.01006"
"13323","79.90200","6.65864","0.01065"
"13392","80.31600","6.69314","0.01076"
"13461","80.73000","6.72770","0.01092"
"13530","81.14400","6.76220","0.01076"
"13599","81.55800","6.79669","0.01169"
"13668","81.97200","6.83119","0.01133"
"13737","82.38600","6.86569","0.01108"
"13806","82.80000","6.90019","0.01057"
"13875","83.21400","6.93469","0.01058"
"13944","83.62800","6.96919","0.01137"
"14013","84.04200","7.00363","0.01164"
"14082","84.45600","7.03818","0.01094"
"14151","84.87000","7.07274","0.01182"
"14220","85.28400","7.10718","0.01152"
"14289","85.69800","7.14162","0.01127"
"14358","86.11200","7.17618","0.01182"
"14427","86.52600","7.21068","0.01172"
"14496","86.94000","7.24518","0.01177"
"14565","87.35400","7.27967","0.01188"
"14634","87.76800","7.31417","0.01122"
"14703","88.18200","7.34873","0.01130"
"14772","88.59600","7.38317","0.01161"
"14841","89.01000","7.41761","0.01153"
"14910","89.42400","7.45217","0.01155"
"14979","89.83800","7.48667","0.01163"
"15048","90.25200","7.52116","0.01139"
"15117","90.66600","7.55566","0.01118"
"15186","91.08000","7.59016","0.01144"
"15255","91.49400","7.62466","0.01072"
"15324","91.90800","7.65922","0.00997"
"15393","92.32200","7.69372","0.01066"
"15462","92.73600","7.72816","0.01046"
"15531","93.15000","7.76266","0.01114"
"15600","93.56400","7.79721","0.01133"
"15669","93.97800","7.83171","0.01125"
"15738","94.39200","7.86609","0.01187"
"15807","94.80600","7.90065","0.01177"
"15876","95.22000","7.93521","0.01157"
"15945","95.63400","7.96971","0.01204"
"16014","96.04800","8.00420","0.01169"
"16083","96.46200","8.03870","0.01264"
"16152","96.87600","8.07320","0.01264"
"16221","97.29000","8.10770","0.01256"
"16290","97.70400","8.14220","0.01298"
"16359","98.11800","8.17664","0.01263"
"16428","98.53200","8.21114","0.01254"
"16497","98.94600","8.24569","0.01262"
"16566","99.36000","8.28025","0.01269"
"16635","99.77400","8.31469","0.01337"
"16704","100.18800","8.34919","0.01309"
"16773","100.60200","8.38369","0.01233"
"16842","101.01600","8.41819","0.01320"
"16911","101.43000","8.45269","0.01284"
"16980","101.84400","8.48712","0.01274"
"17049","102.25800","8.52168","0.01284"
"17118","102.67200","8.55618","0.01287"
"17187","103.08600","8.59074","0.01310"
"17256","103.50000","8.62518","0.01353"
"17325","103.91400","8.65968","0.01339"
"17394","104.32800","8.69423","0.01318"
"17463","104.74200","8.72867","0.01308"
"17532","105.15600","8.76311","0.01338"
"17601","105.57000","8.79761","0.01320"
"17670","105.98400","8.83217","0.01383"
"17739","106.39800","8.86673","0.01344"
"17808","106.81200","8.90117","0.01340"
"17877","107.22600","8.93567","0.01341"
"17946","107.64000","8.97016","0.01370"
"18015","108.05400","9.00466","0.01355"
"18084","108.46800","9.03916","0.01388"
"18153","108.88200","9.07366","0.01378"
"18222","109.29600","9.10816","0.01356"
"18291","109.71000","9.14272","0.01299"
"18360","110.12400","9.17722","0.01347"
"18429","110.53800","9.21171","0.01382"
"18498","110.95200","9.24615","0.01378"
"18567","111.36600","9.28071","0.01307"
"18636","111.78000","9.31521","0.01336"
"18705","112.19400","9.34965","0.01324"
"18774","112.60800","9.38415","0.01366"
"18843","113.02200","9.41870","0.01331"
"18912","113.43600","9.45320","0.01308"
"18981","113.85000","9.48770","0.01318"
"19050","114.26400","9.52214","0.01290"
"19119","114.67800","9.55670","0.01331"
"19188","115.09200","9.59114","0.01365"
"19257","115.50600","9.62570","0.01291"
"19326","115.92000","9.66014","0.01297"
"19395","116.33400","9.69469","0.01167"
"19464","116.74800","9.72919","0.01166"
"19533","117.16200","9.76369","0.01188"
"19602","117.57600","9.79819","0.01206"
"19671","117.99000","9.83263","0.01242"
"19740","118.40400","9.86719","0.01166"
"19809","118.81800","9.90168","0.01189"
"19878","119.23200","9.93618","0.01236"
"19947","119.64600","9.97062","0.01248"
"20016","120.06000","10.00518","0.01265"
"20085","120.47400","10.03968","0.01205"
"20154","120.88800","10.07424","0.01234"
"20223","121.30200","10.10868","0.01216"
"20292","121.71600","10.14318","0.01194"
"20361","122.13000","10.17773","0.01236"
"20430","122.54400","10.21217","0.01253"
"20499","122.95800","10.24661","0.01274"
"20568","123.37200","10.28111","0.01241"
"20637","123.78600","10.31567","0.01230"
"20706","124.20000","10.35023","0.01234"
"20775","124.61400","10.38472","0.01271"
"20844","125.02800","10.41910","0.01272"
"20913","125.44200","10.45366","0.01304"
"20982","125.85600","10.48816","0.01335"
"21051","126.27000","10.52266","0.01305"
"21120","126.68400","10.55716","0.01321"
"21189","127.09800","10.59166","0.01315"
"21258","127.51200","10.62621","0.01257"
"21327","127.92600","10.66065","0.01300"
"21396","128.34000","10.69521","0.01298"
"21465","128.75400","10.72965","0.01358"
"21534","129.16800","10.76421","0.01232"
"21603","129.58200","10.79871","0.01343"
"21672","129.99600","10.83315","0.01281"
"21741","130.41000","10.86758","0.01345"
"21810","130.82400","10.90214","0.01309"
"21879","131.23800","10.93670","0.01286"
"21948","131.65200","10.97120","0.01390"
"22017","132.06600","11.00570","0.01361"
"22086","132.48000","11.04020","0.01424"
"22155","132.89400","11.07470","0.01414"
"22224","133.30800","11.10919","0.01440"
"22293","133.72200","11.14369","0.01491"
"22362","134.13600","11.17813","0.01480"
"22431","134.55000","11.21263","0.01490"
"22500","134.96400","11.24719","0.01471"
"22569","135.37800","11.28175","0.01505"
"22638","135.79200","11.31618","0.01545"
"22707","136.20600","11.35069","0.01548"
"22776","136.62000","11.38518","0.01556"
"22845","137.03400","11.41968","0.01540"
"22914","137.44800","11.45412","0.01544"
"22983","137.86200","11.48862","0.01591"
"23052","138.27600","11.52318","0.01630"
"23121","138.69000","11.55768","0.01694"
"23190","139.10400","11.59217","0.01684"
"23259","139.51800","11.62667","0.01723"
"23328","139.93200","11.66117","0.01752"
"23397","140.34600","11.69567","0.01707"
"23466","140.76000","11.73017","0.01823"
"23535","141.17400","11.76467","0.01834"
"23604","141.58800","11.79917","0.01838"
"23673","142.00200","11.83372","0.01935"
"23742","142.41600","11.86822","0.01950"
"23811","142.83000","11.90272","0.02025"
"23880","143.24400","11.93716","0.02049"
"23949","143.65800","11.97166","0.02043"
"24018","144.07200","12.00616","0.02070"
"24087","144.48600","12.04072","0.02129"
"24156","144.90000","12.07509","0.02168"
"24225","145.31400","12.10971","0.02179"
"24294","145.72800","12.14415","0.02172"
"24363","146.14200","12.17871","0.02246"
"24432","146.55600","12.21321","0.02288"
"24501","146.97000","12.24765","0.02369"
"24570","147.38400","12.28226","0.02363"
"24639","147.79800","12.31670","0.02439"
"24708","148.21200","12.35114","0.02486"
"24777","148.62600","12.38564","0.02535"
"24846","149.04000","12.42020","0.02565"
"24915","149.45400","12.45470","0.02602"
"24984","149.86800","12.48920","0.02658"
"25053","150.28200","12.52369","0.02759"
"25122","150.69600","12.55819","0.02731"
"25191","151.11000","12.59269","0.02812"
"25260","151.52400","12.62713","0.02871"
"25329","151.93800","12.66163","0.02888"
"25398","152.35200","12.69619","0.02948"
"25467","152.76600","12.73075","0.03038"
"25536","153.18000","12.76525","0.03056"
"25605","153.59400","12.79962","0.03084"
"25674","154.00800","12.83412","0.03138"
"25743","154.42200","12.86874","0.03233"
"25812","154.83600","12.90318","0.03259"
"25881","155.25000","12.93762","0.03307"
"25950","155.66400","12.97212","0.03390"
"26019","156.07800","13.00667","0.03447"
"26088","156.49200","13.04117","0.03511"
"26157","156.90600","13.07573","0.03598"
"26226","157.32000","13.11017","0.03639"
"26295","157.73400","13.14467","0.03746"
"26364","158.14800","13.17917","0.03901"
"26433","158.56200","13.21367","0.03956"
"26502","158.97600","13.24811","0.04005"
"26571","159.39000","13.28266","0.04103"
"26640","159.80400","13.31716","0.04210"
"26709","160.21800","13.35172","0.04308"
"26778","160.63200","13.38622","0.04491"
"26847","161.04600","13.42060","0.04570"
"26916","161.46000","13.45516","0.04688"
"26985","161.87400","13.48971","0.04712"
"27054","162.28800","13.52421","0.04818"
"27123","162.70200","13.55859","0.04914"
"27192","163.11600","13.59315","0.05061"
"27261","163.53000","13.62765","0.05116"
"27330","163.94400","13.66221","0.05172"
"27399","164.35800","13.69665","0.05293"
"27468","164.77200","13.73114","0.05404"
"27537","165.18600","13.76570","0.05531"
"27606","165.60000","13.80020","0.05664"
"27675","166.01400","13.83464","0.05796"
"27744","166.42800","13.86908","0.05997"
"27813","166.84200","13.90370","0.06111"
"27882","167.25600","13.93820","0.06272"
"27951","167.67000","13.97269","0.06495"
"28020","168.08400","14.00713","0.06680"
"28089","168.49800","14.04163","0.06845"
"28158","168.91200","14.07619","0.06911"
"28227","169.32600","14.11069","0.07086"
"28296","169.74000","14.14519","0.07287"
"28365","170.15400","14.17963","0.07408"
"28434","170.56800","14.21412","0.07515"
"28503","170.98200","14.24868","0.07687"
"28572","171.39600","14.28318","0.07787"
"28641","171.81000","14.31768","0.07915"
"28710","172.22400","14.35218","0.08106"
"28779","172.63800","14.38668","0.08277"
"28848","173.05200","14.42118","0.08500"
"28917","173.46600","14.45567","0.08681"
"28986","173.88000","14.49011","0.08896"
"29055","174.29400","14.52473","0.09181"
"29124","174.70800","14.55917","0.09404"
"29193","175.12200","14.59373","0.09555"
"29262","175.53600","14.62817","0.09747"
"29331","175.95000","14.66267","0.09918"
"29400","176.36400","14.69716","0.10035"
"29469","176.77800","14.73172","0.10148"
"29538","177.19200","14.76610","0.10242"
"29607","177.60600","14.80066","0.10364"
"29676","178.02000","14.83522","0.10445"
"29745","178.43400","14.86972","0.10609"
"29814","178.84800","14.90416","0.10704"
"29883","179.26200","14.93865","0.10842"
"29952","179.67600","14.97321","0.11009"
"30021","180.09000","15.00771","0.11150"
"30090","180.50400","15.04215","0.11273"
"30159","180.91800","15.07665","0.11485"
"30228","181.33200","15.11121","0.11557"
"30297","181.74600","15.14571","0.11473"
"30366","182.16000","15.18014","0.10897"
"30435","182.57400","15.21464","0.10996"
"30504","182.98800","15.24920","0.11171"
"30573","183.40200","15.28370","0.11383"
"30642","183.81600","15.31814","0.11603"
"30711","184.23000","15.35264","0.11783"
"30780","184.64400","15.38720","0.11934"
"30849","185.05800","15.42169","0.12118"
"30918","185.47200","15.45625","0.12309"
"30987","185.88600","15.49069","0.12485"
"31056","186.30000","15.52519","0.12615"
"31125","186.71400","15.55969","0.12803"
"31194","187.12800","15.59419","0.12964"
"31263","187.54200","15.62862","0.13101"
"31332","187.95600","15.66312","0.13312"
"31401","188.37000","15.69768","0.13590"
"31470","188.78400","15.73218","0.13912"
"31539","189.19800","15.76674","0.14307"
"31608","189.61200","15.80118","0.14549"
"31677","190.02600","15.83562","0.14905"
"31746","190.44000","15.87023","0.15204"
"31815","190.85400","15.90467","0.15394"
"31884","191.26800","15.93911","0.15609"
"31953","191.68200","15.97361","0.15824"
"32022","192.09600","16.00817","0.16038"
"32091","192.51000","16.04267","0.16267"
"32160","192.92400","16.07717","0.16559"
"32229","193.33800","16.11166","0.16844"
"32298","193.75200","16.14616","0.17209"
"32367","194.16600","16.18066","0.17549"
"32436","194.58000","16.21516","0.17841"
"32505","194.99400","16.24960","0.18101"
"32574","195.40800","16.28410","0.18336"
"32643","195.82200","16.31872","0.18478"
"32712","196.23600","16.35321","0.18703"
"32781","196.65000","16.38771","0.18932"
"32850","197.06400","16.42215","0.19042"
"32919","197.47800","16.45671","0.19333"
"32988","197.89200","16.49121","0.19634"
"33057","198.30600","16.52565","0.19879"
"33126","198.72000","16.56009","0.20145"
"33195","199.13400","16.59464","0.20425"
"33264","199.54800","16.62920","0.20633"
"33333","199.96200","16.66370","0.20930"
"33402","200.37600","16.69820","0.21138"
"33471","200.79000","16.73264","0.21325"
"33540","201.20400","16.76720","0.21529"
"33609","201.61800","16.80170","0.21749"
"33678","202.03200","16.83613","0.21877"
"33747","202.44600","16.87063","0.22091"
"33816","202.86000","16.90513","0.22353"
"33885","203.27400","16.93969","0.22588"
"33954","203.68800","16.97419","0.22883"
"34023","204.10200","17.00869","0.23123"
"34092","204.51600","17.04319","0.23397"
"34161","204.93000","17.07768","0.23657"
"34230","205.34400","17.11218","0.23890"
"34299","205.75800","17.14668","0.24229"
"34368","206.17200","17.18118","0.24591"
"34437","206.58600","17.21574","0.24907"
"34506","207.00000","17.25024","0.25203"
"34575","207.41400","17.28468","0.25549"
"34644","207.82800","17.31917","0.25892"
"34713","208.24200","17.35373","0.26271"
"34782","208.65600","17.38817","0.26598"
"34851","209.07000","17.42267","0.27083"
"34920","209.48400","17.45711","0.27560"
"34989","209.89800","17.49167","0.27906"
"35058","210.31200","17.52617","0.28086"
"35127","210.72600","17.56072","0.28365"
"35196","211.14000","17.59516","0.28565"
"35265","211.55400","17.62966","0.04476"
"35334","211.96800","17.66422","0.04620"
"35403","212.38200","17.69866","0.05635"
"35472","212.79600","17.73322","0.05557"
"35541","213.21000","17.76765","0.05266"
"35610","213.62400","17.80221","0.05893"
"35679","214.03800","17.83671","0.07038"
"35748","214.45200","17.87115","0.07340"
"35817","214.86600","17.90565","0.07217"
"35886","215.28000","17.94021","0.07556"
"35955","215.69400","17.97471","0.07896"
"36024","216.10800","18.00920","0.08162"
"36093","216.52200","18.04364","0.08421"
"36162","216.93600","18.07814","0.08780"
"36231","217.35000","18.11270","0.09409"
"36300","217.76400","18.14714","0.09945"
"36369","218.17800","18.18164","0.10352"
"36438","218.59200","18.21620","0.10684"
"36507","219.00600","18.25069","0.11171"
"36576","219.42000","18.28519","0.11543"
"36645","219.83400","18.31963","0.11974"
"36714","220.24800","18.35413","0.12366"
"36783","220.66200","18.38863","0.12756"
"36852","221.07600","18.42319","0.13256"
"36921","221.49000","18.45769","0.13976"
"36990","221.90400","18.49218","0.14569"
"37059","222.31800","18.52668","0.15097"
"37128","222.73200","18.56124","0.15569"
"37197","223.14600","18.59568","0.15874"
"37266","223.56000","18.63012","0.16296"
"37335","223.97400","18.66462","0.16823"
"37404","224.38800","18.69918","0.17643"
"37473","224.80200","18.73368","0.18153"
"37542","225.21600","18.76823","0.18658"
"37611","225.63000","18.80267","0.19174"
"37680","226.04400","18.83717","0.19875"
"37749","226.45800","18.87173","0.20590"
"37818","226.87200","18.90623","0.21198"
"37887","227.28600","18.94061","0.21525"
"37956","227.70000","18.97516","0.21543"
"38025","228.11400","19.00972","0.21184"
"38094","228.52800","19.04416","0.21318"
"38163","228.94200","19.07866","0.20788"
"38232","229.35600","19.11316","0.20952"
"38301","229.77000","19.14772","0.21516"
"38370","230.18400","19.18216","0.21848"
"38439","230.59800","19.21666","0.22049"
"38508","231.01200","19.25109","0.22350"
"38577","231.42600","19.28571","0.22791"
"38646","231.84000","19.32015","0.23414"
"38715","232.25400","19.35471","0.23973"
"38784","232.66800","19.38915","0.24625"
"38853","233.08200","19.42365","0.25050"
"38922","233.49600","19.45820","0.25605"
"38991","233.91000","19.49270","0.26336"
"39060","234.32400","19.52714","0.27324"
"39129","234.73800","19.56158","0.27940"
"39198","235.15200","19.59614","0.28366"
"39267","235.56600","19.63070","0.29230"
"39336","235.98000","19.66514","0.30462"
"39405","236.39400","19.69969","0.31066"
"39474","236.80800","19.73419","0.31450"
"39543","237.22200","19.76869","0.31879"
"39612","237.63600","19.80319","0.32431"
"39681","238.05000","19.83769","0.32819"
"39750","238.46400","19.87213","0.33202"
"39819","238.87800","19.90674","0.33759"
"39888","239.29200","19.94118","0.34217"
"39957","239.70600","19.97568","0.34801"
"40026","240.12000","20.01012","0.35754"
"40095","240.53400","20.04474","0.36496"
"40164","240.94800","20.07918","0.37216"
"40233","241.36200","20.11368","0.38298"
"40302","241.77600","20.14812","0.38653"
"40371","242.19000","20.18267","0.39007"
"40440","242.60400","20.21717","0.39636"
"40509","243.01800","20.25167","0.40316"
"40578","243.43200","20.28617","0.41016"
"40647","243.84600","20.32067","0.41520"
"40716","244.26000","20.35523","0.41939"
"40785","244.67400","20.38967","0.42468"
"40854","245.08800","20.42417","0.43048"
"40923","245.50200","20.45866","0.43862"
"40992","245.91600","20.49310","0.44474"
"41061","246.33000","20.52766","0.45168"
"41130","246.74400","20.56216","0.45960"
"41199","247.15800","20.59660","0.46477"
"41268","247.57200","20.63122","0.47252"
"41337","247.98600","20.66571","0.48073"
"41406","248.40000","20.70021","0.48897"
"41475","248.81400","20.73465","0.49347"
"41544","249.22800","20.76915","0.50248"
"41613","249.64200","20.80371","0.51081"
"41682","250.05600","20.83821","0.51933"
"41751","250.47000","20.87271","0.49924"
"41820","250.88400","20.90720","0.48378"
"41889","251.29800","20.94170","0.48678"
"41958","251.71200","20.97620","0.49230"
"42027","252.12600","21.01064","0.49912"
"42096","252.54000","21.04508","0.50674"
"42165","252.95400","21.07964","0.51021"
"42234","253.36800","21.11414","0.51900"
"42303","253.78200","21.14869","0.52417"
"42372","254.19600","21.18319","0.52895"
"42441","254.61000","21.21763","0.53263"
"42510","255.02400","21.25219","0.53760"
"42579","255.43800","21.28669","0.54208"
"42648","255.85200","21.32119","0.54733"
"42717","256.26600","21.35563","0.55396"
"42786","256.68000","21.39018","0.56227"
"42855","257.09400","21.42468","0.56873"
"42924","257.50800","21.45918","0.57600"
"42993","257.92200","21.49362","0.58571"
"43062","258.33600","21.52818","0.59207"
"43131","258.75000","21.56268","0.59764"
"43200","259.16400","21.59718","0.60475"
"43269","259.57800","21.63161","0.61203"
"43338","259.99200","21.66617","0.61676"
"43407","260.40600","21.70073","0.62210"
"43476","260.82000","21.73511","0.62832"
"43545","261.23400","21.76967","0.63389"
"43614","261.64800","21.80423","0.63839"
"43683","262.06200","21.83867","0.64409"
"43752","262.47600","21.87317","0.65147"
"43821","262.89000","21.90772","0.66011"
"43890","263.30400","21.94210","0.66763"
"43959","263.71800","21.97660","0.67314"
"44028","264.13200","22.01122","0.68169"
"44097","264.54600","22.04572","0.41062"
"44166","264.96000","22.08015","0.42278"
"44235","265.37400","22.11465","0.43556"
"44304","265.78800","22.14921","0.44099"
"44373","266.20200","22.18365","0.44366"
"44442","266.61600","22.21815","0.45515"
"44511","267.03000","22.25265","0.46382"
"44580","267.44400","22.28720","0.47183"
"44649","267.85800","22.32170","0.48390"
"44718","268.27200","22.35620","0.49131"
"44787","268.68600","22.39064","0.50146"
"44856","269.10000","22.42520","0.51129"
"44925","269.51400","22.45970","0.52065"
"44994","269.92800","22.49420","0.52520"
"45063","270.34200","22.52864","0.53131"
"45132","270.75600","22.56314","0.53652"
"45201","271.17000","22.59769","0.54426"
"45270","271.58400","22.63219","0.55048"
"45339","271.99800","22.66669","0.56046"
"45408","272.41200","22.70119","0.56780"
"45477","272.82600","22.73575","0.57610"
"45546","273.24000","22.77024","0.58656"
"45615","273.65400","22.80468","0.59544"
"45684","274.06800","22.83912","0.60460"
"45753","274.48200","22.87362","0.61211"
"45822","274.89600","22.90818","0.61852"
"45891","275.31000","22.94274","0.62374"
"45960","275.72400","22.97718","0.63016"
"46029","276.13800","23.01162","0.63658"
"46098","276.55200","23.04623","0.64196"
"46167","276.96600","23.08073","0.64904"
"46236","277.38000","23.11517","0.65660"
"46305","277.79400","23.14967","0.66647"
"46374","278.20800","23.18417","0.67432"
"46443","278.62200","23.21867","0.68147"
"46512","279.03600","23.25317","0.69180"
"46581","279.45000","23.28766","0.69871"
"46650","279.86400","23.32222","0.70413"
"46719","280.27800","23.35672","0.71231"
"46788","280.69200","23.39122","0.72080"
"46857","281.10600","23.42566","0.72590"
"46926","281.52000","23.46016","0.73057"
"46995","281.93400","23.49466","0.73476"
"47064","282.34800","23.52921","0.73903"
"47133","282.76200","23.56365","0.74329"
"47202","283.17600","23.59815","0.74882"
"47271","283.59000","23.63271","0.75414"
"47340","284.00400","23.66721","0.76114"
"47409","284.41800","23.70165","0.76832"
"47478","284.83200","23.73609","0.77519"
"47547","285.24600","23.77070","0.78221"
"47616","285.66000","23.80520","0.79400"
"47685","286.07400","23.83970","0.80012"
"47754","286.48800","23.87414","0.80807"
"47823","286.90200","23.90864","0.81691"
"47892","287.31600","23.94320","0.82583"
"47961","287.73000","23.97770","0.83364"
"48030","288.14400","24.01213","0.83833"
"48099","288.55800","24.04663","0.84235"
"48168","288.97200","24.08113","0.84561"
"48237","289.38600","24.11569","0.85038"
"48306","289.80000","24.15019","0.85627"
"48375","290.21400","24.18463","0.86265"
"48444","290.62800","24.21918","0.87002"
"48513","291.04200","24.25368","0.87540"
"48582","291.45600","24.28818","0.87756"
"48651","291.87000","24.32262","0.88240"
"48720","292.28400","24.35712","0.88893"
"48789","292.69800","24.39168","0.89677"
"48858","293.11200","24.42618","0.90147"
"48927","293.52600","24.46067","0.90747"
"48996","293.94000","24.49512","0.91357"
"49065","294.35400","24.52973","0.92061"
"49134","294.76800","24.56423","0.92544"
"49203","295.18200","24.59867","0.32458"
"49272","295.59600","24.63311","0.29681"
"49341","296.01000","24.66767","0.31596"
"49410","296.42400","24.70217","0.32988"
"49479","296.83800","24.73666","0.32268"
"49548","297.25200","24.77116","0.33750"
"49617","297.66600","24.80566","0.34740"
"49686","298.08000","24.84016","0.33783"
"49755","298.49400","24.87472","0.36374"
"49824","298.90800","24.90915","0.36149"
"49893","299.32200","24.94359","0.38068"
"49962","299.73600","24.97816","0.38670"
"50031","300.15000","25.01265","0.38686"
"50100","300.56400","25.04715","0.39947"
"50169","300.97800","25.08165","0.40285"
"50238","301.39200","25.11621","0.41721"
"50307","301.80600","25.15071","0.41564"
"50376","302.22000","25.18514","0.42206"
"50445","302.63400","25.21964","0.42944"
"50514","303.04800","25.25414","0.43970"
"50583","303.46200","25.28870","0.44122"
"50652","303.87600","25.32314","0.44750"
"50721","304.29000","25.35770","0.46095"
"50790","304.70400","25.39214","0.46125"
"50859","305.11800","25.42669","0.46688"
"50928","305.53200","25.46119","0.47907"
"50997","305.94600","25.49569","0.48200"
"51066","306.36000","25.53013","0.48810"
"51135","306.77400","25.56457","0.49673"
"51204","307.18800","25.59919","0.49862"
"51273","307.60200","25.63369","0.50652"
"51342","308.01600","25.66818","0.51722"
"51411","308.43000","25.70268","0.51990"
"51480","308.84400","25.73724","0.52498"
"51549","309.25800","25.77174","0.52754"
"51618","309.67200","25.80618","0.52921"
"51687","310.08600","25.84062","0.53259"
"51756","310.50000","25.87518","0.53389"
"51825","310.91400","25.90967","0.53709"
"51894","311.32800","25.94417","0.54258"
"51963","311.74200","25.97867","0.54489"
"52032","312.15600","26.01317","0.23661"
"52101","312.57000","26.04773","0.23148"
"52170","312.98400","26.08223","0.23064"
"52239","313.39800","26.11667","0.23463"
"52308","313.81200","26.15122","0.23390"
"52377","314.22600","26.18572","0.23667"
"52446","314.64000","26.22016","0.23941"
"52515","315.05400","26.25466","0.24149"
"52584","315.46800","26.28916","0.24374"
"52653","315.88200","26.32372","0.24659"
"52722","316.29600","26.35822","0.24696"
"52791","316.71000","26.39266","0.24801"
"52860","317.12400","26.42709","0.25012"
"52929","317.53800","26.46165","0.25198"
"52998","317.95200","26.49621","0.25375"
"53067","318.36600","26.53071","0.25544"
"53136","318.78000","26.56515","0.25758"
"53205","319.19400","26.59965","0.25926"
"53274","319.60800","26.63420","0.26112"
"53343","320.02200","26.66870","0.26429"
"53412","320.43600","26.70314","0.26678"
"53481","320.85000","26.73758","0.26998"
"53550","321.26400","26.77220","0.27283"
"53619","321.67800","26.80670","0.27508"
"53688","322.09200","26.84120","0.27745"
"53757","322.50600","26.87563","0.27816"
"53826","322.92000","26.91019","0.27949"
"53895","323.33400","26.94469","0.28045"
"53964","323.74800","26.97919","0.28238"
"54033","324.16200","27.01369","0.28427"
"54102","324.57600","27.04813","0.28739"
"54171","324.99000","27.08269","0.28927"
"54240","325.40400","27.11719","0.29199"
"54309","325.81800","27.15168","0.29445"
"54378","326.23200","27.18612","0.29623"
"54447","326.64600","27.22068","0.29840"
"54516","327.06000","27.25518","0.30113"
"54585","327.47400","27.28968","0.30377"
"54654","327.88800","27.32412","0.30691"
"54723","328.30200","27.35862","0.30758"
"54792","328.71600","27.39317","0.01932"
"54861","329.13000","27.42767","0.01937"
"54930","329.54400","27.46211","0.02067"
"54999","329.95800","27.49667","0.02120"
"55068","330.37200","27.53117","0.02142"
"55137","330.78600","27.56573","0.02173"
"55206","331.20000","27.60023","0.02350"
"55275","331.61400","27.63466","0.02379"
"55344","332.02800","27.66916","0.02351"
"55413","332.44200","27.70366","0.02431"
"55482","332.85600","27.73816","0.02555"
"55551","333.27000","27.77266","0.02500"
"55620","333.68400","27.80721","0.02612"
"55689","334.09800","27.84171","0.02629"
"55758","334.51200","27.87621","0.02691"
"55827","334.92600","27.91065","0.02733"
"55896","335.34000","27.94515","0.02809"
"55965","335.75400","27.97971","0.02847"
"56034","336.16800","28.01421","0.02735"
"56103","336.58200","28.04864","0.02823"
"56172","336.99600","28.08315","0.02892"
"56241","337.41000","28.11770","0.02920"
"56310","337.82400","28.15220","0.03011"
"56379","338.23800","28.18670","0.03100"
"56448","338.65200","28.22108","0.02975"
"56517","339.06600","28.25564","0.02438"
"56586","339.48000","28.29020","0.02412"
"56655","339.89400","28.32470","0.02011"
"56724","340.30800","28.35913","0.02138"
"56793","340.72200","28.39363","0.02347"
"56862","341.13600","28.42819","0.02511"
"56931","341.55000","28.46275","0.02653"
"57000","341.96400","28.49718","0.02747"
"57069","342.37800","28.53163","0.02830"
"57138","342.79200","28.56618","0.02902"
"57207","343.20600","28.60068","0.02984"
"57276","343.62000","28.63518","0.02993"
"57345","344.03400","28.66962","0.03092"
"57414","344.44800","28.70424","0.03168"
"57483","344.86200","28.73874","0.03168"
"57552","345.27600","28.77317","0.03251"
"57621","345.69000","28.80767","0.03306"
"57690","346.10400","28.84217","0.03350"
"57759","346.51800","28.87667","0.03307"
"57828","346.93200","28.91111","0.03373"
"57897","347.34600","28.94567","0.03428"
"57966","347.76000","28.98017","0.03510"
"58035","348.17400","29.01472","0.03593"
"58104","348.58800","29.04922","0.03673"
"58173","349.00200","29.08372","0.03803"
"58242","349.41600","29.11810","0.03923"
"58311","349.83000","29.15266","0.03871"
"58380","350.24400","29.18722","0.03970"
"58449","350.65800","29.22172","0.04005"
"58518","351.07200","29.25621","0.04190"
"58587","351.48600","29.29065","0.04261"
"58656","351.90000","29.32527","0.04275"
"58725","352.31400","29.35977","0.04438"
"58794","352.72800","29.39415","0.04478"
"58863","353.14200","29.42859","0.04553"
"58932","353.55600","29.46315","0.04688"
"59001","353.97000","29.49771","0.04812"
"59070","354.38400","29.53220","0.04895"
"59139","354.79800","29.56664","0.04904"
"59208","355.21200","29.60114","0.04984"
"59277","355.62600","29.63570","0.05066"
"59346","356.04000","29.67020","0.05105"
"59415","356.45400","29.70464","0.05266"
"59484","356.86800","29.73913","0.05269"
"59553","357.28200","29.77369","0.05358"
"59622","357.69600","29.80819","0.05519"
"59691","358.11000","29.84269","0.05533"
"59760","358.52400","29.87719","0.05587"
"59829","358.93800","29.91169","0.05713"
"59898","359.35200","29.94619","0.05701"
"59967","359.76600","29.98069","0.05776"
"60036","360.18000","30.01512","0.05966"
"60105","360.59400","30.04962","0.06161"
"60174","361.00800","30.08418","0.06334"
"60243","361.42200","30.11874","0.06513"
"60312","361.83600","30.15318","0.06609"
"60381","362.25000","30.18762","0.06812"
"60450","362.66400","30.22217","0.07020"
"60519","363.07800","30.25667","0.07101"
"60588","363.49200","30.29117","0.07294"
"60657","363.90600","30.32561","0.07435"
"60726","364.32000","30.36017","0.07539"
"60795","364.73400","30.39467","0.07602"
"60864","365.14800","30.42917","0.07669"
"60933","365.56200","30.46361","0.05936"
"61002","365.97600","30.49822","0.06391"
"61071","366.39000","30.53272","0.05893"
"61140","366.80400","30.56722","0.06235"
"61209","367.21800","30.60166","0.06337"
"61278","367.63200","30.63610","0.06395"
"61347","368.04600","30.67072","0.05898"
"61416","368.46000","30.70521","0.06010"
"61485","368.87400","30.73965","0.06255"
"61554","369.28800","30.77415","0.06416"
"61623","369.70200","30.80877","0.06603"
"61692","370.11600","30.84321","0.06810"
"61761","370.53000","30.87765","0.06872"
"61830","370.94400","30.91215","0.01990"
"61899","371.35800","30.94665","0.01578"
"61968","371.77200","30.98120","0.03003"
"62037","372.18600","31.01564","0.02068"
"62106","372.60000","31.05014","0.01796"
"62175","373.01400","31.08464","0.02412"
"62244","373.42800","31.11920","0.02416"
"62313","373.84200","31.15370","0.02149"
"62382","374.25600","31.18820","0.02181"
"62451","374.67000","31.22263","0.02306"
"62520","375.08400","31.25713","0.02484"
"62589","375.49800","31.29169","0.02646"
"62658","375.91200","31.32619","0.02795"
"62727","376.32600","31.36063","0.02813"
"62796","376.74000","31.39519","0.02876"
"62865","377.15400","31.42974","0.03004"
"62934","377.56800","31.46424","0.03069"
"63003","377.98200","31.49868","0.03212"
"63072","378.39600","31.53318","0.03310"
"63141","378.81000","31.56768","0.03365"
"63210","379.22400","31.60217","0.03413"
"63279","379.63800","31.63667","0.03454"
"63348","380.05200","31.67117","0.03405"
"63417","380.46600","31.70573","0.03339"
"63486","380.88000","31.74023","0.03238"
"63555","381.29400","31.77467","0.03196"
"63624","381.70800","31.80911","0.03262"
"63693","382.12200","31.84367","0.03277"
"63762","382.53600","31.87816","0.03249"
"63831","382.95000","31.91266","0.03321"
"63900","383.36400","31.94716","0.03410"
"63969","383.77800","31.98160","0.03474"
"64038","384.19200","32.01616","0.03491"
"64107","384.60600","32.05078","0.03566"
"64176","385.02000","32.08521","0.03642"
"64245","385.43400","32.11959","0.03766"
"64314","385.84800","32.15416","0.03830"
"64383","386.26200","32.18865","0.04008"
"64452","386.67600","32.22321","0.04052"
"64521","387.09000","32.25765","0.04058"
"64590","387.50400","32.29214","0.04100"
"64659","387.91800","32.32671","0.04011"
"64728","388.33200","32.36120","0.04176"
"64797","388.74600","32.39564","0.04190"
"64866","389.16000","32.43014","0.04245"
"64935","389.57400","32.46470","0.04237"
"65004","389.98800","32.49914","0.04322"
"65073","390.40200","32.53370","0.04476"
"65142","390.81600","32.56813","0.04568"
"65211","391.23000","32.60263","0.04644"
"65280","391.64400","32.63720","0.04758"
"65349","392.05800","32.67175","0.04846"
"65418","392.47200","32.70613","0.04913"
"65487","392.88600","32.74063","0.05065"
"65556","393.30000","32.77518","0.05132"
"65625","393.71400","32.80975","0.05252"
"65694","394.12800","32.84418","0.05311"
"65763","394.54200","32.87868","0.05369"
"65832","394.95600","32.91318","0.05471"
"65901","395.37000","32.94774","0.05487"
"65970","395.78400","32.98218","0.04580"
"66039","396.19800","33.01662","0.03364"
"66108","396.61200","33.05117","0.03209"
"66177","397.02600","33.08574","0.03283"
"66246","397.44000","33.12017","0.01508"
"66315","397.85400","33.15467","0.01252"
"66384","398.26800","33.18917","0.01279"
"66453","398.68200","33.22372","0.01500"
"66522","399.09600","33.25817","0.01479"
"66591","399.51000","33.29267","0.01280"
"66660","399.92400","33.32716","0.01386"
"66729","400.33800","33.36166","0.01566"
"66798","400.75200","33.39616","0.01480"
"66867","401.16600","33.43066","0.01299"
"66936","401.58000","33.46516","0.01243"
"67005","401.99400","33.49972","0.01264"
"67074","402.40800","33.53421","0.01264"
"67143","402.82200","33.56871","0.00719"
"67212","403.23600","33.60315","0.00720"
"67281","403.65000","33.63765","0.00933"
"67350","404.06400","33.67221","0.00583"
"67419","404.47800","33.70671","0.00914"
"67488","404.89200","33.74115","0.00990"
"67557","405.30600","33.77559","0.00726"
"67626","405.72000","33.81020","0.00782"
"67695","406.13400","33.84470","0.00881"
"67764","406.54800","33.87914","0.00942"
"67833","406.96200","33.91364","0.00942"
"67902","407.37600","33.94814","0.00828"
"67971","407.79000","33.98270","0.00810"
"68040","408.20400","34.01719","0.00933"
"68109","408.61800","34.05164","0.01071"
"68178","409.03200","34.08613","0.00975"
"68247","409.44600","34.12075","0.00977"
"68316","409.86000","34.15525","0.00941"
"68385","410.27400","34.18969","0.01008"
"68454","410.68800","34.22412","0.01146"
"68523","411.10200","34.25869","0.01038"
"68592","411.51600","34.29318","0.01048"
"68661","411.93000","34.32768","0.01038"
"68730","412.34400","34.36212","0.01130"
"68799","412.75800","34.39674","0.01257"
"68868","413.17200","34.43124","0.01219"
"68937","413.58600","34.46574","0.01161"
"69006","414.00000","34.50011","0.01220"
"69075","414.41400","34.53468","0.01177"
"69144","414.82800","34.56923","0.01300"
"69213","415.24200","34.60367","0.01265"
"69282","415.65600","34.63817","0.01334"
"69351","416.07000","34.67261","0.01311"
"69420","416.48400","34.70723","0.01357"
"69489","416.89800","34.74173","0.01347"
"69558","417.31200","34.77622","0.01439"
"69627","417.72600","34.81066","0.01476"
"69696","418.14000","34.84516","0.01450"
"69765","418.55400","34.87972","0.01516"
"69834","418.96800","34.91416","0.01454"
"69903","419.38200","34.94865","0.01578"
"69972","419.79600","34.98315","0.01544"
"70041","420.21000","35.01772","0.01585"
"70110","420.62400","35.05221","0.01543"
"70179","421.03800","35.08671","0.01635"
"70248","421.45200","35.12115","0.01708"
"70317","421.86600","35.15565","0.01688"
"70386","422.28000","35.19020","0.01757"
"70455","422.69400","35.22464","0.01771"
"70524","423.10800","35.25914","0.01805"
"70593","423.52200","35.29370","0.01822"
"70662","423.93600","35.32820","0.01856"
"70731","424.35000","35.36270","0.01863"
"70800","424.76400","35.39714","0.01875"
"70869","425.17800","35.43169","0.01904"
"70938","425.59200","35.46619","0.01919"
"71007","426.00600","35.50069","0.01986"
"71076","426.42000","35.53513","0.01976"
"71145","426.83400","35.56963","0.02003"
"71214","427.24800","35.60419","0.02009"
"71283","427.66200","35.63869","0.02037"
"71352","428.07600","35.67319","0.02062"
"71421","428.49000","35.70762","0.02061"
"71490","428.90400","35.74218","0.02041"
"71559","429.31800","35.77668","0.02064"
"71628","429.73200","35.81118","0.02125"
"71697","430.14600","35.84562","0.02127"
"71766","430.56000","35.88018","0.02186"
"71835","430.97400","35.91473","0.02190"
"71904","431.38800","35.94917","0.02205"
"71973","431.80200","35.98367","0.02253"
"72042","432.21600","36.01817","0.02267"
"72111","432.63000","36.05267","0.02332"
"72180","433.04400","36.08717","0.02357"
"72249","433.45800","36.12167","0.02399"
"72318","433.87200","36.15617","0.02466"
"72387","434.28600","36.19066","0.02459"
"72456","434.70000","36.22516","0.02523"
"72525","435.11400","36.25972","0.02527"
"72594","435.52800","36.29416","0.02490"
"72663","435.94200","36.32866","0.02591"
"72732","436.35600","36.36322","0.02620"
"72801","436.77000","36.39771","0.02646"
"72870","437.18400","36.43216","0.02644"
"72939","437.59800","36.46666","0.02746"
"73008","438.01200","36.50121","0.02814"
"73077","438.42600","36.53571","0.02830"
"73146","438.84000","36.57021","0.02872"
"73215","439.25400","36.60464","0.02887"
"73284","439.66800","36.63909","0.02932"
"73353","440.08200","36.67370","0.02966"
"73422","440.49600","36.70820","0.02992"
"73491","440.91000","36.74264","0.02989"
"73560","441.32400","36.77714","0.03060"
"73629","441.73800","36.81176","0.03091"
"73698","442.15200","36.84626","0.03170"
"73767","442.56600","36.88070","0.03194"
"73836","442.98000","36.91520","0.03190"
"73905","443.39400","36.94970","0.03266"
"73974","443.80800","36.98419","0.03308"
"74043","444.22200","37.01869","0.03309"
"74112","444.63600","37.05313","0.03330"
"74181","445.05000","37.08768","0.03273"
"74250","445.46400","37.12218","0.03347"
"74319","445.87800","37.15674","0.03369"
"74388","446.29200","37.19112","0.03466"
"74457","446.70600","37.22568","0.03464"
"74526","447.12000","37.26018","0.03561"
"74595","447.53400","37.29474","0.03590"
"74664","447.94800","37.32918","0.03593"
"74733","448.36200","37.36367","0.03667"
"74802","448.77600","37.39817","0.03699"
"74871","449.19000","37.43273","0.03738"
"74940","449.60400","37.46717","0.03694"
"75009","450.01800","37.50161","0.03762"
"75078","450.43200","37.53617","0.03753"
"75147","450.84600","37.57067","0.03832"
"75216","451.26000","37.60517","0.03945"
"75285","451.67400","37.63966","0.04010"
"75354","452.08800","37.67416","0.03954"
"75423","452.50200","37.70866","0.04012"
"75492","452.91600","37.74328","0.04085"
"75561","453.33000","37.77772","0.04196"
"75630","453.74400","37.81215","0.04150"
"75699","454.15800","37.84671","0.04300"
"75768","454.57200","37.88115","0.04420"
"75837","454.98600","37.91565","0.04452"
"75906","455.40000","37.95009","0.04504"
"75975","455.81400","37.98471","0.04557"
"76044","456.22800","38.01921","0.04607"
"76113","456.64200","38.05371","0.04655"
"76182","457.05600","38.08815","0.04744"
"76251","457.47000","38.12264","0.04786"
"76320","457.88400","38.15720","0.04863"
"76389","458.29800","38.19170","0.04849"
"76458","458.71200","38.22614","0.04925"
"76527","459.12600","38.26064","0.04881"
"76596","459.54000","38.29519","0.04926"
"76665","459.95400","38.32969","0.05046"
"76734","460.36800","38.36419","0.05057"
"76803","460.78200","38.39863","0.05040"
"76872","461.19600","38.43313","0.05185"
"76941","461.61000","38.46769","0.05259"
"77010","462.02400","38.50213","0.05283"
"77079","462.43800","38.53663","0.05397"
"77148","462.85200","38.57113","0.05426"
"77217","463.26600","38.60568","0.05554"
"77286","463.68000","38.64018","0.05548"
"77355","464.09400","38.67468","0.05649"
"77424","464.50800","38.70918","0.05680"
"77493","464.92200","38.74368","0.05853"
"77562","465.33600","38.77811","0.05957"
"77631","465.75000","38.81268","0.05986"
"77700","466.16400","38.84711","0.06128"
"77769","466.57800","38.88167","0.06198"
"77838","466.99200","38.91623","0.06266"
"77907","467.40600","38.95073","0.06360"
"77976","467.82000","38.98517","0.06418"
"78045","468.23400","39.01966","0.06708"
"78114","468.64800","39.05416","0.06672"
"78183","469.06200","39.08872","0.06736"
"78252","469.47600","39.12316","0.06820"
"78321","469.89000","39.15760","0.06936"
"78390","470.30400","39.19216","0.06055"
"78459","470.71800","39.22672","0.06273"
"78528","471.13200","39.26115","0.06550"
"78597","471.54600","39.29565","0.06660"
"78666","471.96000","39.33015","0.06810"
"78735","472.37400","39.36471","0.06921"
"78804","472.78800","39.39921","0.07099"
"78873","473.20200","39.43365","0.07231"
"78942","473.61600","39.46815","0.07205"
"79011","474.03000","39.50276","0.07361"
"79080","474.44400","39.53720","0.07368"
"79149","474.85800","39.57170","0.07457"
"79218","475.27200","39.60614","0.07504"
"79287","475.68600","39.64064","0.07560"
"79356","476.10000","39.67514","0.07562"
"79425","476.51400","39.70970","0.07674"
"79494","476.92800","39.74414","0.07674"
"79563","477.34200","39.77869","0.07784"
"79632","477.75600","39.81319","0.07853"
"79701","478.17000","39.84775","0.07872"
"79770","478.58400","39.88213","0.07949"
"79839","478.99800","39.91663","0.08018"
"79908","479.41200","39.95119","0.08063"
"79977","479.82600","39.98569","0.08150"
"80046","480.24000","40.02012","0.08242"
"80115","480.65400","40.05468","0.08310"
"80184","481.06800","40.08918","0.08499"
"80253","481.48200","40.12374","0.08460"
"80322","481.89600","40.15824","0.08544"
"80391","482.31000","40.19262","0.08717"
"80460","482.72400","40.22712","0.08855"
"80529","483.13800","40.26167","0.08864"
"80598","483.55200","40.29617","0.09031"
"80667","483.96600","40.33061","0.09131"
"80736","484.38000","40.36517","0.09238"
"80805","484.79400","40.39966","0.09346"
"80874","485.20800","40.43423","0.09523"
"80943","485.62200","40.46867","0.09542"
"81012","486.03600","40.50316","0.09714"
"81081","486.45000","40.53766","0.09734"
"81150","486.86400","40.57216","0.09818"
"81219","487.27800","40.60666","0.09828"
"81288","487.69200","40.64116","0.09862"
"81357","488.10600","40.67566","0.09875"
"81426","488.52000","40.71021","0.09933"
"81495","488.93400","40.74471","0.09981"
"81564","489.34800","40.77915","0.10049"
"81633","489.76200","40.81365","0.10097"
"81702","490.17600","40.84821","0.10187"
"81771","490.59000","40.88271","0.10242"
"81840","491.00400","40.91714","0.10274"
"81909","491.41800","40.95159","0.10361"
"81978","491.83200","40.98620","0.10379"
"82047","492.24600","41.02064","0.10455"
"82116","492.66000","41.05514","0.10508"
"82185","493.07400","41.08964","0.10591"
"82254","493.48800","41.12420","0.10633"
"82323","493.90200","41.15863","0.10703"
"82392","494.31600","41.19320","0.10734"
"82461","494.73000","41.22763","0.10835"
"82530","495.14400","41.26213","0.10912"
"82599","495.55800","41.29669","0.10946"
"82668","495.97200","41.33119","0.11014"
"82737","496.38600","41.36568","0.11076"
"82806","496.80000","41.40012","0.11106"
"82875","497.21400","41.43468","0.11100"
"82944","497.62800","41.46918","0.11192"
"83013","498.04200","41.50368","0.11248"
"83082","498.45600","41.53806","0.11426"
"83151","498.87000","41.57268","0.11419"
"83220","499.28400","41.60717","0.11454"
"83289","499.69800","41.64167","0.11504"
"83358","500.11200","41.67611","0.11565"
"83427","500.52600","41.71067","0.11594"
"83496","500.94000","41.74517","0.11712"
"83565","501.35400","41.77967","0.11810"
"83634","501.76800","41.81411","0.00213"
"83703","502.18200","41.84861","0.00506"
"83772","502.59600","41.88316","0.00599"
"83841","503.01000","41.91767","0.00567"
"83910","503.42400","41.95216","0.00492"
"83979","503.83800","41.98666","0.00626"
"84048","504.25200","42.02116","0.00473"
"84117","504.66600","42.05572","0.00499"
"84186","505.08000","42.09021","0.00648"
"84255","505.49400","42.12466","0.00525"
"84324","505.90800","42.15915","0.00536"
"84393","506.32200","42.19371","0.00560"
"84462","506.73600","42.22827","0.00463"
"84531","507.15000","42.26271","0.00492"
"84600","507.56400","42.29715","0.00586"
"84668","507.97200","42.33117","0.00491"