File: Trajectories_together/161223_2Specimen_RawData_7.csv
"","V1","V2","V3"
"1","End date","12/23/2016",""
"2","Specimen label","21BG_65",""
"3","Maximum Load","0.28197","N"
"4","Time","Extension","Load"
"5","(s)","(mm)","(N)"
"6","0.00000","0.00006","0.00061"
"41","0.21000","0.01525","0.00064"
"76","0.42000","0.03528","0.00160"
"111","0.63000","0.05279","0.00194"
"146","0.84000","0.07019","0.00183"
"181","1.05000","0.08777","0.00211"
"216","1.26000","0.10523","0.00274"
"251","1.47000","0.12275","0.00244"
"286","1.68000","0.14027","0.00315"
"321","1.89000","0.15766","0.00307"
"356","2.10000","0.17524","0.00354"
"391","2.31000","0.19270","0.00373"
"426","2.52000","0.21016","0.00336"
"461","2.73000","0.22774","0.00401"
"496","2.94000","0.24520","0.00369"
"531","3.15000","0.26278","0.00426"
"566","3.36000","0.28029","0.00400"
"601","3.57000","0.29769","0.00458"
"636","3.78000","0.31527","0.00495"
"671","3.99000","0.33267","0.00483"
"706","4.20000","0.35025","0.00490"
"741","4.41000","0.36771","0.00491"
"776","4.62000","0.38516","0.00481"
"811","4.83000","0.40274","0.00517"
"846","5.04000","0.42020","0.00477"
"881","5.25000","0.43772","0.00539"
"916","5.46000","0.45524","0.00508"
"951","5.67000","0.47270","0.00549"
"986","5.88000","0.49021","0.00614"
"1021","6.09000","0.50773","0.00504"
"1056","6.30000","0.52519","0.00551"
"1091","6.51000","0.54271","0.00577"
"1126","6.72000","0.56017","0.00548"
"1161","6.93000","0.57775","0.00580"
"1196","7.14000","0.59520","0.00611"
"1231","7.35000","0.61266","0.00608"
"1266","7.56000","0.63024","0.00633"
"1301","7.77000","0.64770","0.00644"
"1336","7.98000","0.66522","0.00670"
"1371","8.19000","0.68274","0.00643"
"1406","8.40000","0.70020","0.00690"
"1441","8.61000","0.71771","0.00685"
"1476","8.82000","0.73523","0.00660"
"1511","9.03000","0.75269","0.00708"
"1546","9.24000","0.77027","0.00649"
"1581","9.45000","0.78767","0.00674"
"1616","9.66000","0.80525","0.00664"
"1651","9.87000","0.82270","0.00678"
"1686","10.08000","0.84022","0.00715"
"1721","10.29000","0.85774","0.00679"
"1756","10.50000","0.87520","0.00713"
"1791","10.71000","0.89272","0.00720"
"1826","10.92000","0.91024","0.00756"
"1861","11.13000","0.92775","0.00760"
"1896","11.34000","0.94521","0.00721"
"1931","11.55000","0.96273","0.00739"
"1966","11.76000","0.98025","0.00785"
"2001","11.97000","0.99777","0.00776"
"2036","12.18000","1.01523","0.00764"
"2071","12.39000","1.03274","0.00787"
"2106","12.60000","1.05020","0.00762"
"2141","12.81000","1.06772","0.00739"
"2176","13.02000","1.08524","0.00780"
"2211","13.23000","1.10264","0.00810"
"2246","13.44000","1.12028","0.00755"
"2281","13.65000","1.13768","0.00766"
"2316","13.86000","1.15519","0.00829"
"2351","14.07000","1.17271","0.00801"
"2386","14.28000","1.19017","0.00783"
"2421","14.49000","1.20769","0.00846"
"2456","14.70000","1.22527","0.00804"
"2491","14.91000","1.24273","0.00820"
"2526","15.12000","1.26024","0.00818"
"2561","15.33000","1.27770","0.00791"
"2596","15.54000","1.29522","0.00858"
"2631","15.75000","1.31274","0.00806"
"2666","15.96000","1.33020","0.00851"
"2701","16.17000","1.34778","0.00796"
"2736","16.38000","1.36517","0.00863"
"2771","16.59000","1.38275","0.00842"
"2806","16.80000","1.40021","0.00852"
"2841","17.01000","1.41773","0.00849"
"2876","17.22000","1.43525","0.00861"
"2911","17.43000","1.45277","0.00894"
"2946","17.64000","1.47022","0.00877"
"2981","17.85000","1.48774","0.00864"
"3016","18.06000","1.50520","0.00918"
"3051","18.27000","1.52272","0.00916"
"3086","18.48000","1.54024","0.00917"
"3121","18.69000","1.55770","0.00899"
"3156","18.90000","1.57527","0.00939"
"3191","19.11000","1.59267","0.00909"
"3226","19.32000","1.61025","0.00911"
"3261","19.53000","1.62771","0.00863"
"3296","19.74000","1.64523","0.00921"
"3331","19.95000","1.66275","0.00887"
"3366","20.16000","1.68027","0.00907"
"3401","20.37000","1.69772","0.00904"
"3436","20.58000","1.71530","0.00939"
"3471","20.79000","1.73270","0.00940"
"3506","21.00000","1.75028","0.00918"
"3541","21.21000","1.76774","0.00911"
"3576","21.42000","1.78526","0.00967"
"3611","21.63000","1.80271","0.00959"
"3646","21.84000","1.82017","0.00955"
"3681","22.05000","1.83775","0.00947"
"3716","22.26000","1.85515","0.00937"
"3751","22.47000","1.87273","0.00981"
"3786","22.68000","1.89025","0.00906"
"3821","22.89000","1.90764","0.00908"
"3856","23.10000","1.92528","0.00935"
"3891","23.31000","1.94274","0.00932"
"3926","23.52000","1.96026","0.00932"
"3961","23.73000","1.97778","0.00952"
"3996","23.94000","1.99518","0.00939"
"4031","24.15000","2.01275","0.00942"
"4066","24.36000","2.03021","0.00973"
"4101","24.57000","2.04767","0.00965"
"4136","24.78000","2.06525","0.00955"
"4171","24.99000","2.08271","0.00934"
"4206","25.20000","2.10029","0.01000"
"4241","25.41000","2.11769","0.00984"
"4276","25.62000","2.13520","0.00996"
"4311","25.83000","2.15272","0.01034"
"4346","26.04000","2.17018","0.01008"
"4381","26.25000","2.18770","0.00984"
"4416","26.46000","2.20528","0.01007"
"4451","26.67000","2.22262","0.01000"
"4486","26.88000","2.24025","0.01025"
"4521","27.09000","2.25777","0.00986"
"4556","27.30000","2.27523","0.01007"
"4591","27.51000","2.29275","0.00999"
"4626","27.72000","2.31021","0.00978"
"4661","27.93000","2.32773","0.00961"
"4696","28.14000","2.34518","0.01010"
"4731","28.35000","2.36270","0.00991"
"4766","28.56000","2.38022","0.01036"
"4801","28.77000","2.39774","0.01012"
"4836","28.98000","2.41526","0.01041"
"4871","29.19000","2.43278","0.00992"
"4906","29.40000","2.45017","0.01063"
"4941","29.61000","2.46775","0.01024"
"4976","29.82000","2.48521","0.01017"
"5011","30.03000","2.50273","0.01025"
"5046","30.24000","2.52019","0.01018"
"5081","30.45000","2.53765","0.01058"
"5116","30.66000","2.55523","0.01030"
"5151","30.87000","2.57268","0.01045"
"5186","31.08000","2.59020","0.01048"
"5221","31.29000","2.60778","0.01044"
"5256","31.50000","2.62518","0.01063"
"5291","31.71000","2.64276","0.00987"
"5326","31.92000","2.66028","0.01048"
"5361","32.13000","2.67773","0.01036"
"5396","32.34000","2.69525","0.01006"
"5431","32.55000","2.71265","0.00988"
"5466","32.76000","2.73029","0.00999"
"5501","32.97000","2.74775","0.01003"
"5536","33.18000","2.76521","0.00952"
"5571","33.39000","2.78278","0.00970"
"5606","33.60000","2.80018","0.01002"
"5641","33.81000","2.81776","0.00995"
"5676","34.02000","2.83522","0.00990"
"5711","34.23000","2.85274","0.01020"
"5746","34.44000","2.87020","0.00957"
"5781","34.65000","2.88771","0.00912"
"5816","34.86000","2.90523","0.00916"
"5851","35.07000","2.92275","0.00919"
"5886","35.28000","2.94021","0.00966"
"5921","35.49000","2.95779","0.00941"
"5956","35.70000","2.97519","0.00941"
"5991","35.91000","2.99271","0.00955"
"6026","36.12000","3.01022","0.00988"
"6061","36.33000","3.02774","0.00980"
"6096","36.54000","3.04526","0.01018"
"6131","36.75000","3.06272","0.00951"
"6166","36.96000","3.08024","0.00931"
"6201","37.17000","3.09770","0.00914"
"6236","37.38000","3.11521","0.01014"
"6271","37.59000","3.13273","0.01029"
"6306","37.80000","3.15025","0.00988"
"6341","38.01000","3.16771","0.01033"
"6376","38.22000","3.18523","0.01006"
"6411","38.43000","3.20269","0.01032"
"6446","38.64000","3.22026","0.00995"
"6481","38.85000","3.23772","0.01042"
"6516","39.06000","3.25518","0.01042"
"6551","39.27000","3.27276","0.01061"
"6586","39.48000","3.29016","0.01072"
"6621","39.69000","3.30774","0.01069"
"6656","39.90000","3.32525","0.01059"
"6691","40.11000","3.34271","0.01088"
"6726","40.32000","3.36023","0.01060"
"6761","40.53000","3.37775","0.01021"
"6796","40.74000","3.39521","0.01077"
"6831","40.95000","3.41279","0.01061"
"6866","41.16000","3.43019","0.01055"
"6901","41.37000","3.44776","0.01122"
"6936","41.58000","3.46522","0.01062"
"6971","41.79000","3.48274","0.01086"
"7006","42.00000","3.50026","0.01126"
"7041","42.21000","3.51766","0.01099"
"7076","42.42000","3.53530","0.01128"
"7111","42.63000","3.55269","0.01127"
"7146","42.84000","3.57021","0.01097"
"7181","43.05000","3.58773","0.01102"
"7216","43.26000","3.60525","0.01142"
"7251","43.47000","3.62271","0.01173"
"7286","43.68000","3.64029","0.01123"
"7321","43.89000","3.65768","0.01130"
"7356","44.10000","3.67526","0.01164"
"7391","44.31000","3.69272","0.01163"
"7426","44.52000","3.71024","0.01142"
"7461","44.73000","3.72776","0.01083"
"7496","44.94000","3.74522","0.01095"
"7531","45.15000","3.76273","0.01136"
"7566","45.36000","3.78019","0.01174"
"7601","45.57000","3.79771","0.01182"
"7636","45.78000","3.81523","0.01161"
"7671","45.99000","3.83269","0.01167"
"7706","46.20000","3.85027","0.01158"
"7741","46.41000","3.86773","0.01177"
"7776","46.62000","3.88524","0.01164"
"7811","46.83000","3.90276","0.01220"
"7846","47.04000","3.92022","0.01206"
"7881","47.25000","3.93774","0.01198"
"7916","47.46000","3.95520","0.01181"
"7951","47.67000","3.97266","0.01176"
"7986","47.88000","3.99023","0.01138"
"8021","48.09000","4.00769","0.01107"
"8056","48.30000","4.02521","0.01109"
"8091","48.51000","4.04273","0.01176"
"8126","48.72000","4.06019","0.01170"
"8161","48.93000","4.07771","0.01201"
"8196","49.14000","4.09528","0.01198"
"8231","49.35000","4.11268","0.01132"
"8266","49.56000","4.13026","0.01106"
"8301","49.77000","4.14766","0.01157"
"8336","49.98000","4.16524","0.01229"
"8371","50.19000","4.18276","0.01205"
"8406","50.40000","4.20021","0.01217"
"8441","50.61000","4.21773","0.01174"
"8476","50.82000","4.23519","0.01216"
"8511","51.03000","4.25277","0.01252"
"8546","51.24000","4.27023","0.01249"
"8581","51.45000","4.28769","0.01284"
"8616","51.66000","4.30526","0.01273"
"8651","51.87000","4.32266","0.01288"
"8686","52.08000","4.34018","0.01313"
"8721","52.29000","4.35776","0.01328"
"8756","52.50000","4.37516","0.01347"
"8791","52.71000","4.39280","0.01287"
"8826","52.92000","4.41026","0.01409"
"8861","53.13000","4.42771","0.01398"
"8896","53.34000","4.44529","0.01341"
"8931","53.55000","4.46269","0.01384"
"8966","53.76000","4.48021","0.01415"
"9001","53.97000","4.49773","0.01393"
"9036","54.18000","4.51525","0.01431"
"9071","54.39000","4.53276","0.01423"
"9106","54.60000","4.55028","0.01481"
"9141","54.81000","4.56774","0.01484"
"9176","55.02000","4.58526","0.01503"
"9211","55.23000","4.60272","0.01523"
"9246","55.44000","4.62024","0.01478"
"9281","55.65000","4.63769","0.01547"
"9316","55.86000","4.65521","0.01575"
"9351","56.07000","4.67273","0.01558"
"9386","56.28000","4.69013","0.01565"
"9421","56.49000","4.70777","0.01599"
"9456","56.70000","4.72517","0.01590"
"9491","56.91000","4.74269","0.01590"
"9526","57.12000","4.76020","0.01598"
"9561","57.33000","4.77772","0.01575"
"9596","57.54000","4.79524","0.01580"
"9631","57.75000","4.81276","0.01643"
"9666","57.96000","4.83022","0.01607"
"9701","58.17000","4.84774","0.01647"
"9736","58.38000","4.86513","0.01622"
"9771","58.59000","4.88277","0.01694"
"9806","58.80000","4.90023","0.01679"
"9841","59.01000","4.91769","0.01616"
"9876","59.22000","4.93521","0.01661"
"9911","59.43000","4.95273","0.01661"
"9946","59.64000","4.97024","0.01690"
"9981","59.85000","4.98776","0.01688"
"10016","60.06000","5.00522","0.01680"
"10051","60.27000","5.02274","0.01747"
"10086","60.48000","5.04026","0.01779"
"10121","60.69000","5.05766","0.01731"
"10156","60.90000","5.07529","0.01791"
"10191","61.11000","5.09263","0.01804"
"10226","61.32000","5.11027","0.01840"
"10261","61.53000","5.12767","0.01802"
"10296","61.74000","5.14519","0.01833"
"10331","61.95000","5.16271","0.01907"
"10366","62.16000","5.18017","0.01824"
"10401","62.37000","5.19774","0.01899"
"10436","62.58000","5.21520","0.01897"
"10471","62.79000","5.23272","0.01907"
"10506","63.00000","5.25024","0.01900"
"10541","63.21000","5.26770","0.01940"
"10576","63.42000","5.28522","0.01959"
"10611","63.63000","5.30273","0.01978"
"10646","63.84000","5.32013","0.01993"
"10681","64.05000","5.33777","0.02006"
"10716","64.26000","5.35523","0.02025"
"10751","64.47000","5.37275","0.02007"
"10786","64.68000","5.39021","0.02046"
"10821","64.89000","5.40766","0.02041"
"10856","65.10000","5.42524","0.02085"
"10891","65.31000","5.44270","0.02029"
"10926","65.52000","5.46022","0.02063"
"10961","65.73000","5.47774","0.02070"
"10996","65.94000","5.49520","0.02135"
"11031","66.15000","5.51271","0.02125"
"11066","66.36000","5.53029","0.02085"
"11101","66.57000","5.54769","0.02101"
"11136","66.78000","5.56527","0.02089"
"11171","66.99000","5.58273","0.02127"
"11206","67.20000","5.60025","0.02137"
"11241","67.41000","5.61771","0.02107"
"11276","67.62000","5.63516","0.02090"
"11311","67.83000","5.65274","0.02155"
"11346","68.04000","5.67020","0.02134"
"11381","68.25000","5.68778","0.02189"
"11416","68.46000","5.70524","0.02164"
"11451","68.67000","5.72270","0.02211"
"11486","68.88000","5.74021","0.02193"
"11521","69.09000","5.75773","0.02199"
"11556","69.30000","5.77519","0.02216"
"11591","69.51000","5.79277","0.02229"
"11626","69.72000","5.81017","0.02318"
"11661","69.93000","5.82781","0.02318"
"11696","70.14000","5.84520","0.02248"
"11731","70.35000","5.86272","0.02276"
"11766","70.56000","5.88030","0.02269"
"11801","70.77000","5.89770","0.02265"
"11836","70.98000","5.91522","0.02211"
"11871","71.19000","5.93274","0.02243"
"11906","71.40000","5.95025","0.02208"
"11941","71.61000","5.96771","0.02215"
"11976","71.82000","5.98523","0.02213"
"12011","72.03000","6.00275","0.02290"
"12046","72.24000","6.02021","0.02283"
"12081","72.45000","6.03773","0.02276"
"12116","72.66000","6.05525","0.02282"
"12151","72.87000","6.07270","0.02309"
"12186","73.08000","6.09022","0.02312"
"12221","73.29000","6.10768","0.02299"
"12256","73.50000","6.12514","0.02337"
"12291","73.71000","6.14278","0.02365"
"12326","73.92000","6.16017","0.02382"
"12361","74.13000","6.17769","0.02360"
"12396","74.34000","6.19527","0.02371"
"12431","74.55000","6.21267","0.02270"
"12466","74.76000","6.23025","0.02272"
"12501","74.97000","6.24771","0.02338"
"12536","75.18000","6.26529","0.02373"
"12571","75.39000","6.28280","0.02288"
"12606","75.60000","6.30014","0.02313"
"12641","75.81000","6.31778","0.02364"
"12676","76.02000","6.33524","0.02360"
"12711","76.23000","6.35270","0.02353"
"12746","76.44000","6.37028","0.02313"
"12781","76.65000","6.38767","0.02357"
"12816","76.86000","6.40525","0.02366"
"12851","77.07000","6.42271","0.02406"
"12886","77.28000","6.44023","0.02403"
"12921","77.49000","6.45775","0.02403"
"12956","77.70000","6.47521","0.02379"
"12991","77.91000","6.49272","0.02330"
"13026","78.12000","6.51024","0.02384"
"13061","78.33000","6.52770","0.02373"
"13096","78.54000","6.54528","0.02367"
"13131","78.75000","6.56274","0.02421"
"13166","78.96000","6.58020","0.02412"
"13201","79.17000","6.59778","0.02507"
"13236","79.38000","6.61517","0.02458"
"13271","79.59000","6.63269","0.02467"
"13306","79.80000","6.65021","0.02497"
"13341","80.01000","6.66767","0.02383"
"13376","80.22000","6.68525","0.02427"
"13411","80.43000","6.70271","0.02377"
"13446","80.64000","6.72022","0.02357"
"13481","80.85000","6.73774","0.02389"
"13516","81.06000","6.75520","0.02449"
"13551","81.27000","6.77278","0.02437"
"13586","81.48000","6.79024","0.02496"
"13621","81.69000","6.80776","0.02502"
"13656","81.90000","6.82521","0.02554"
"13691","82.11000","6.84267","0.02555"
"13726","82.32000","6.86025","0.02600"
"13761","82.53000","6.87771","0.02608"
"13796","82.74000","6.89523","0.02607"
"13831","82.95000","6.91275","0.02616"
"13866","83.16000","6.93026","0.02693"
"13901","83.37000","6.94772","0.02661"
"13936","83.58000","6.96524","0.02658"
"13971","83.79000","6.98270","0.02678"
"14006","84.00000","7.00028","0.02706"
"14041","84.21000","7.01774","0.02764"
"14076","84.42000","7.03525","0.02719"
"14111","84.63000","7.05271","0.02793"
"14146","84.84000","7.07017","0.02760"
"14181","85.05000","7.08775","0.02790"
"14216","85.26000","7.10521","0.02832"
"14251","85.47000","7.12279","0.02823"
"14286","85.68000","7.14025","0.02906"
"14321","85.89000","7.15776","0.02860"
"14356","86.10000","7.17522","0.02907"
"14391","86.31000","7.19274","0.02907"
"14426","86.52000","7.21020","0.02895"
"14461","86.73000","7.22778","0.02953"
"14496","86.94000","7.24512","0.02964"
"14531","87.15000","7.26275","0.02981"
"14566","87.36000","7.28021","0.02974"
"14601","87.57000","7.29773","0.03028"
"14636","87.78000","7.31525","0.03037"
"14671","87.99000","7.33271","0.03000"
"14706","88.20000","7.35023","0.03035"
"14741","88.41000","7.36774","0.03046"
"14776","88.62000","7.38520","0.03098"
"14811","88.83000","7.40272","0.03056"
"14846","89.04000","7.42024","0.03111"
"14881","89.25000","7.43770","0.03161"
"14916","89.46000","7.45528","0.03135"
"14951","89.67000","7.47268","0.03195"
"14986","89.88000","7.49025","0.03232"
"15021","90.09000","7.50771","0.03243"
"15056","90.30000","7.52523","0.03261"
"15091","90.51000","7.54269","0.03329"
"15126","90.72000","7.56015","0.03313"
"15161","90.93000","7.57773","0.03382"
"15196","91.14000","7.59518","0.03433"
"15231","91.35000","7.61270","0.03348"
"15266","91.56000","7.63022","0.03456"
"15301","91.77000","7.64768","0.03449"
"15336","91.98000","7.66526","0.03518"
"15371","92.19000","7.68278","0.03553"
"15406","92.40000","7.70018","0.03627"
"15441","92.61000","7.71775","0.03612"
"15476","92.82000","7.73515","0.03660"
"15511","93.03000","7.75273","0.03695"
"15546","93.24000","7.77025","0.03731"
"15581","93.45000","7.78771","0.03749"
"15616","93.66000","7.80522","0.03832"
"15651","93.87000","7.82274","0.03865"
"15686","94.08000","7.84026","0.03916"
"15721","94.29000","7.85772","0.03911"
"15756","94.50000","7.87524","0.03957"
"15791","94.71000","7.89270","0.04017"
"15826","94.92000","7.91021","0.04056"
"15861","95.13000","7.92773","0.04064"
"15896","95.34000","7.94525","0.04058"
"15931","95.55000","7.96271","0.04200"
"15966","95.76000","7.98023","0.04210"
"16001","95.97000","7.99775","0.04296"
"16036","96.18000","8.01521","0.04424"
"16071","96.39000","8.03278","0.04416"
"16106","96.60000","8.05018","0.04498"
"16141","96.81000","8.06776","0.04509"
"16176","97.02000","8.08522","0.04603"
"16211","97.23000","8.10274","0.04646"
"16246","97.44000","8.12020","0.04703"
"16281","97.65000","8.13777","0.04768"
"16316","97.86000","8.15523","0.04785"
"16351","98.07000","8.17275","0.04825"
"16386","98.28000","8.19021","0.04905"
"16421","98.49000","8.20773","0.04907"
"16456","98.70000","8.22519","0.04861"
"16491","98.91000","8.24276","0.04853"
"16526","99.12000","8.26022","0.04894"
"16561","99.33000","8.27768","0.04940"
"16596","99.54000","8.29526","0.04982"
"16631","99.75000","8.31266","0.05054"
"16666","99.96000","8.33018","0.05062"
"16701","100.17000","8.34769","0.05196"
"16736","100.38000","8.36521","0.05225"
"16771","100.59000","8.38273","0.05298"
"16806","100.80000","8.40025","0.05379"
"16841","101.01000","8.41771","0.05412"
"16876","101.22000","8.43523","0.05533"
"16911","101.43000","8.45269","0.05538"
"16946","101.64000","8.47026","0.05651"
"16981","101.85000","8.48772","0.05702"
"17016","102.06000","8.50518","0.05667"
"17051","102.27000","8.52276","0.05759"
"17086","102.48000","8.54022","0.05826"
"17121","102.69000","8.55774","0.05909"
"17156","102.90000","8.57525","0.06084"
"17191","103.11000","8.59271","0.06131"
"17226","103.32000","8.61029","0.06266"
"17261","103.53000","8.62769","0.06396"
"17296","103.74000","8.64521","0.06479"
"17331","103.95000","8.66279","0.06591"
"17366","104.16000","8.68018","0.06639"
"17401","104.37000","8.69776","0.06753"
"17436","104.58000","8.71522","0.06821"
"17471","104.79000","8.73268","0.06896"
"17506","105.00000","8.75026","0.06984"
"17541","105.21000","8.76766","0.07085"
"17576","105.42000","8.78523","0.07209"
"17611","105.63000","8.80269","0.07248"
"17646","105.84000","8.82021","0.07289"
"17681","106.05000","8.83773","0.07425"
"17716","106.26000","8.85525","0.07454"
"17751","106.47000","8.87271","0.07493"
"17786","106.68000","8.89029","0.07592"
"17821","106.89000","8.90768","0.07595"
"17856","107.10000","8.92526","0.07652"
"17891","107.31000","8.94272","0.07629"
"17926","107.52000","8.96024","0.07726"
"17961","107.73000","8.97776","0.07790"
"17996","107.94000","8.99516","0.07835"
"18031","108.15000","9.01273","0.07880"
"18066","108.36000","9.03019","0.07844"
"18101","108.57000","9.04771","0.07909"
"18136","108.78000","9.06523","0.07934"
"18171","108.99000","9.08269","0.08001"
"18206","109.20000","9.10021","0.07987"
"18241","109.41000","9.11778","0.08030"
"18276","109.62000","9.13518","0.08036"
"18311","109.83000","9.15276","0.07916"
"18346","110.04000","9.17010","0.07713"
"18381","110.25000","9.18774","0.07739"
"18416","110.46000","9.20520","0.07752"
"18451","110.67000","9.22272","0.07792"
"18486","110.88000","9.24023","0.07863"
"18521","111.09000","9.25775","0.07950"
"18556","111.30000","9.27527","0.08097"
"18591","111.51000","9.29273","0.08243"
"18626","111.72000","9.31025","0.08225"
"18661","111.93000","9.32771","0.08438"
"18696","112.14000","9.34522","0.08568"
"18731","112.35000","9.36274","0.08736"
"18766","112.56000","9.38026","0.08853"
"18801","112.77000","9.39766","0.09090"
"18836","112.98000","9.41530","0.09222"
"18871","113.19000","9.43276","0.09405"
"18906","113.40000","9.45021","0.09548"
"18941","113.61000","9.46773","0.09617"
"18976","113.82000","9.48519","0.09689"
"19011","114.03000","9.50277","0.09546"
"19046","114.24000","9.52023","0.05300"
"19081","114.45000","9.53775","0.05169"
"19116","114.66000","9.55520","0.05255"
"19151","114.87000","9.57272","0.04968"
"19186","115.08000","9.59024","0.04768"
"19221","115.29000","9.60776","0.05204"
"19256","115.50000","9.62522","0.05127"
"19291","115.71000","9.64280","0.05387"
"19326","115.92000","9.66019","0.05339"
"19361","116.13000","9.67771","0.05490"
"19396","116.34000","9.69523","0.04445"
"19431","116.55000","9.71263","0.04234"
"19466","116.76000","9.73021","0.04222"
"19501","116.97000","9.74767","0.04142"
"19536","117.18000","9.76519","0.04330"
"19571","117.39000","9.78270","0.04315"
"19606","117.60000","9.80022","0.04436"
"19641","117.81000","9.81774","0.04538"
"19676","118.02000","9.83526","0.04541"
"19711","118.23000","9.85272","0.04697"
"19746","118.44000","9.87024","0.04709"
"19781","118.65000","9.88769","0.04911"
"19816","118.86000","9.90527","0.04894"
"19851","119.07000","9.92273","0.05020"
"19886","119.28000","9.94019","0.05069"
"19921","119.49000","9.95777","0.05192"
"19956","119.70000","9.97517","0.05259"
"19991","119.91000","9.99274","0.05318"
"20026","120.12000","10.01020","0.05429"
"20061","120.33000","10.02772","0.05348"
"20096","120.54000","10.04524","0.05498"
"20131","120.75000","10.06270","0.05499"
"20166","120.96000","10.08016","0.05655"
"20201","121.17000","10.09779","0.05712"
"20236","121.38000","10.11519","0.05795"
"20271","121.59000","10.13277","0.05889"
"20306","121.80000","10.15023","0.05974"
"20341","122.01000","10.16769","0.06105"
"20376","122.22000","10.18527","0.06057"
"20411","122.43000","10.20267","0.06194"
"20446","122.64000","10.22024","0.06210"
"20481","122.85000","10.23770","0.06415"
"20516","123.06000","10.25522","0.06380"
"20551","123.27000","10.27268","0.06511"
"20586","123.48000","10.29026","0.06572"
"20621","123.69000","10.30778","0.06743"
"20656","123.90000","10.32523","0.06756"
"20691","124.11000","10.34269","0.06842"
"20726","124.32000","10.36021","0.07008"
"20761","124.53000","10.37773","0.07023"
"20796","124.74000","10.39525","0.07173"
"20831","124.95000","10.41271","0.07230"
"20866","125.16000","10.43016","0.07313"
"20901","125.37000","10.44774","0.07311"
"20936","125.58000","10.46514","0.07452"
"20971","125.79000","10.48278","0.07526"
"21006","126.00000","10.50030","0.07608"
"21041","126.21000","10.51770","0.07690"
"21076","126.42000","10.53522","0.07770"
"21111","126.63000","10.55273","0.07825"
"21146","126.84000","10.57019","0.07908"
"21181","127.05000","10.58777","0.08042"
"21216","127.26000","10.60517","0.08116"
"21251","127.47000","10.62275","0.08141"
"21286","127.68000","10.64027","0.08315"
"21321","127.89000","10.65766","0.08510"
"21356","128.10000","10.67524","0.08515"
"21391","128.31000","10.69270","0.08672"
"21426","128.52000","10.71028","0.08784"
"21461","128.73000","10.72774","0.09027"
"21496","128.94000","10.74520","0.09003"
"21531","129.15000","10.76271","0.09162"
"21566","129.36000","10.78023","0.09259"
"21601","129.57000","10.79769","0.09444"
"21636","129.78000","10.81527","0.09497"
"21671","129.99000","10.83267","0.09485"
"21706","130.20000","10.85030","0.09456"
"21741","130.41000","10.86770","0.09522"
"21776","130.62000","10.88522","0.09633"
"21811","130.83000","10.90280","0.09634"
"21846","131.04000","10.92020","0.09747"
"21881","131.25000","10.93772","0.09636"
"21916","131.46000","10.95524","0.09683"
"21951","131.67000","10.97269","0.09702"
"21986","131.88000","10.99021","0.09744"
"22021","132.09000","11.00767","0.09841"
"22056","132.30000","11.02525","0.09923"
"22091","132.51000","11.04277","0.10011"
"22126","132.72000","11.06017","0.10069"
"22161","132.93000","11.07780","0.10079"
"22196","133.14000","11.09520","0.10170"
"22231","133.35000","11.11272","0.10207"
"22266","133.56000","11.13024","0.10246"
"22301","133.77000","11.14764","0.10317"
"22336","133.98000","11.16522","0.10424"
"22371","134.19000","11.18268","0.10457"
"22406","134.40000","11.20025","0.10505"
"22441","134.61000","11.21771","0.10306"
"22476","134.82000","11.23523","0.10411"
"22511","135.03000","11.25275","0.10477"
"22546","135.24000","11.27027","0.10567"
"22581","135.45000","11.28773","0.10659"
"22616","135.66000","11.30524","0.10773"
"22651","135.87000","11.32264","0.10784"
"22686","136.08000","11.34028","0.10909"
"22721","136.29000","11.35774","0.10990"
"22756","136.50000","11.37520","0.11057"
"22791","136.71000","11.39272","0.11159"
"22826","136.92000","11.41023","0.11221"
"22861","137.13000","11.42775","0.11332"
"22896","137.34000","11.44527","0.11455"
"22931","137.55000","11.46273","0.11537"
"22966","137.76000","11.48025","0.11648"
"23001","137.97000","11.49771","0.11801"
"23036","138.18000","11.51523","0.11924"
"23071","138.39000","11.53280","0.11996"
"23106","138.60000","11.55014","0.12132"
"23141","138.81000","11.56778","0.12273"
"23176","139.02000","11.58524","0.12377"
"23211","139.23000","11.60270","0.12452"
"23246","139.44000","11.62028","0.12557"
"23281","139.65000","11.63767","0.12622"
"23316","139.86000","11.65525","0.12776"
"23351","140.07000","11.67271","0.12890"
"23386","140.28000","11.69023","0.13039"
"23421","140.49000","11.70775","0.13188"
"23456","140.70000","11.72521","0.13341"
"23491","140.91000","11.74272","0.13498"
"23526","141.12000","11.76024","0.13707"
"23561","141.33000","11.77770","0.13915"
"23596","141.54000","11.79522","0.14122"
"23631","141.75000","11.81268","0.14339"
"23666","141.96000","11.83026","0.14592"
"23701","142.17000","11.84771","0.14780"
"23736","142.38000","11.86517","0.14978"
"23771","142.59000","11.88275","0.15217"
"23806","142.80000","11.90021","0.15319"
"23841","143.01000","11.91773","0.15379"
"23876","143.22000","11.93525","0.15480"
"23911","143.43000","11.95271","0.15581"
"23946","143.64000","11.97022","0.15675"
"23981","143.85000","11.98774","0.15788"
"24016","144.06000","12.00520","0.15871"
"24051","144.27000","12.02278","0.13418"
"24086","144.48000","12.04018","0.13430"
"24121","144.69000","12.05775","0.13429"
"24156","144.90000","12.07521","0.12541"
"24191","145.11000","12.09267","0.05639"
"24226","145.32000","12.11025","0.06508"
"24261","145.53000","12.12771","0.06184"
"24296","145.74000","12.14529","0.06288"
"24331","145.95000","12.16269","0.07086"
"24366","146.16000","12.18020","0.07035"
"24401","146.37000","12.19772","0.06973"
"24436","146.58000","12.21524","0.07644"
"24471","146.79000","12.23270","0.07210"
"24506","147.00000","12.25028","0.07553"
"24541","147.21000","12.26768","0.07555"
"24576","147.42000","12.28525","0.07427"
"24611","147.63000","12.30271","0.07378"
"24646","147.84000","12.32017","0.07624"
"24681","148.05000","12.33775","0.07633"
"24716","148.26000","12.35521","0.07679"
"24751","148.47000","12.37273","0.08169"
"24786","148.68000","12.39019","0.08000"
"24821","148.89000","12.40770","0.08442"
"24856","149.10000","12.42522","0.08236"
"24891","149.31000","12.44274","0.08472"
"24926","149.52000","12.46020","0.08227"
"24961","149.73000","12.47778","0.08926"
"24996","149.94000","12.49518","0.08770"
"25031","150.15000","12.51275","0.09129"
"25066","150.36000","12.53021","0.09298"
"25101","150.57000","12.54779","0.09696"
"25136","150.78000","12.56519","0.09730"
"25171","150.99000","12.58265","0.09919"
"25206","151.20000","12.60029","0.10093"
"25241","151.41000","12.61768","0.10159"
"25276","151.62000","12.63526","0.10316"
"25311","151.83000","12.65278","0.10431"
"25346","152.04000","12.67018","0.10596"
"25381","152.25000","12.68776","0.10626"
"25416","152.46000","12.70522","0.10892"
"25451","152.67000","12.72273","0.10964"
"25486","152.88000","12.74025","0.11186"
"25521","153.09000","12.75765","0.11242"
"25556","153.30000","12.77523","0.11637"
"25591","153.51000","12.79269","0.11621"
"25626","153.72000","12.81021","0.11901"
"25661","153.93000","12.82773","0.11986"
"25696","154.14000","12.84518","0.12237"
"25731","154.35000","12.86276","0.12366"
"25766","154.56000","12.88022","0.12564"
"25801","154.77000","12.89774","0.12760"
"25836","154.98000","12.91526","0.12952"
"25871","155.19000","12.93272","0.13163"
"25906","155.40000","12.95023","0.13408"
"25941","155.61000","12.96775","0.13769"
"25976","155.82000","12.98515","0.14032"
"26011","156.03000","13.00279","0.14440"
"26046","156.24000","13.02025","0.14701"
"26081","156.45000","13.03777","0.15123"
"26116","156.66000","13.05528","0.15187"
"26151","156.87000","13.07268","0.15558"
"26186","157.08000","13.09026","0.15617"
"26221","157.29000","13.10772","0.15957"
"26256","157.50000","13.12524","0.15992"
"26291","157.71000","13.14276","0.16443"
"26326","157.92000","13.16027","0.16505"
"26361","158.13000","13.17773","0.16914"
"26396","158.34000","13.19525","0.17100"
"26431","158.55000","13.21271","0.17442"
"26466","158.76000","13.23029","0.17793"
"26501","158.97000","13.24769","0.17854"
"26536","159.18000","13.26527","0.18119"
"26571","159.39000","13.28266","0.18220"
"26606","159.60000","13.30012","0.18490"
"26641","159.81000","13.31770","0.18591"
"26676","160.02000","13.33516","0.18840"
"26711","160.23000","13.35268","0.18954"
"26746","160.44000","13.37026","0.19219"
"26781","160.65000","13.38765","0.19549"
"26816","160.86000","13.40529","0.19668"
"26851","161.07000","13.42275","0.20017"
"26886","161.28000","13.44021","0.20118"
"26921","161.49000","13.45773","0.20436"
"26956","161.70000","13.47519","0.20522"
"26991","161.91000","13.49282","0.20774"
"27026","162.12000","13.51028","0.20962"
"27061","162.33000","13.52768","0.21170"
"27096","162.54000","13.54532","0.21402"
"27131","162.75000","13.56272","0.21500"
"27166","162.96000","13.58024","0.21673"
"27201","163.17000","13.59770","0.21761"
"27236","163.38000","13.61521","0.21941"
"27271","163.59000","13.63273","0.22101"
"27306","163.80000","13.65019","0.22211"
"27341","164.01000","13.66777","0.22420"
"27376","164.22000","13.68529","0.22615"
"27411","164.43000","13.70268","0.22829"
"27446","164.64000","13.72026","0.23018"
"27481","164.85000","13.73766","0.23152"
"27516","165.06000","13.75518","0.23285"
"27551","165.27000","13.77276","0.23384"
"27586","165.48000","13.79022","0.23412"
"27621","165.69000","13.80773","0.23524"
"27656","165.90000","13.82519","0.23623"
"27691","166.11000","13.84271","0.23846"
"27726","166.32000","13.86023","0.23943"
"27761","166.53000","13.87775","0.24003"
"27796","166.74000","13.89521","0.23668"
"27831","166.95000","13.91279","0.23753"
"27866","167.16000","13.93018","0.23974"
"27901","167.37000","13.94776","0.24135"
"27936","167.58000","13.96522","0.24455"
"27971","167.79000","13.98274","0.24657"
"28006","168.00000","14.00020","0.24964"
"28041","168.21000","14.01766","0.25310"
"28076","168.42000","14.03524","0.25524"
"28111","168.63000","14.05269","0.25834"
"28146","168.84000","14.07027","0.26085"
"28181","169.05000","14.08773","0.26392"
"28216","169.26000","14.10519","0.22625"
"28251","169.47000","14.12271","0.16084"
"28286","169.68000","14.14028","0.15945"
"28321","169.89000","14.15768","0.16216"
"28356","170.10000","14.17526","0.15980"
"28391","170.31000","14.19266","0.13118"
"28426","170.52000","14.21024","0.12603"
"28461","170.73000","14.22776","0.12826"
"28496","170.94000","14.24522","0.13422"
"28531","171.15000","14.26279","0.13415"
"28566","171.36000","14.28013","0.13704"
"28601","171.57000","14.29777","0.14057"
"28636","171.78000","14.31523","0.14667"
"28671","171.99000","14.33275","0.14660"
"28706","172.20000","14.35021","0.15056"
"28741","172.41000","14.36772","0.15344"
"28776","172.62000","14.38518","0.15529"
"28811","172.83000","14.40276","0.15737"
"28846","173.04000","14.42022","0.15796"
"28881","173.25000","14.43774","0.16008"
"28916","173.46000","14.45520","0.16316"
"28951","173.67000","14.47271","0.16642"
"28986","173.88000","14.49023","0.16952"
"29021","174.09000","14.50769","0.17383"
"29056","174.30000","14.52521","0.17554"
"29091","174.51000","14.54267","0.17905"
"29126","174.72000","14.56025","0.18104"
"29161","174.93000","14.57770","0.18380"
"29196","175.14000","14.59522","0.18516"
"29231","175.35000","14.61280","0.18691"
"29266","175.56000","14.63026","0.18872"
"29301","175.77000","14.64772","0.18995"
"29336","175.98000","14.66524","0.19039"
"29371","176.19000","14.68270","0.19099"
"29406","176.40000","14.70021","0.19238"
"29441","176.61000","14.71773","0.19135"
"29476","176.82000","14.73513","0.19133"
"29511","177.03000","14.75271","0.19203"
"29546","177.24000","14.77023","0.18852"
"29581","177.45000","14.78774","0.19055"
"29616","177.66000","14.80520","0.19319"
"29651","177.87000","14.82266","0.19477"
"29686","178.08000","14.84024","0.19723"
"29721","178.29000","14.85776","0.19987"
"29756","178.50000","14.87516","0.20212"
"29791","178.71000","14.89274","0.20412"
"29826","178.92000","14.91013","0.20647"
"29861","179.13000","14.92777","0.20927"
"29896","179.34000","14.94523","0.21036"
"29931","179.55000","14.96269","0.21264"
"29966","179.76000","14.98027","0.21469"
"30001","179.97000","14.99767","0.21627"
"30036","180.18000","15.01524","0.21749"
"30071","180.39000","15.03270","0.21867"
"30106","180.60000","15.05016","0.22043"
"30141","180.81000","15.06774","0.22218"
"30176","181.02000","15.08520","0.22305"
"30211","181.23000","15.10272","0.16604"
"30246","181.44000","15.12024","0.16217"
"30281","181.65000","15.13769","0.16134"
"30316","181.86000","15.15527","0.16414"
"30351","182.07000","15.17273","0.16762"
"30386","182.28000","15.19019","0.16794"
"30421","182.49000","15.20777","0.17109"
"30456","182.70000","15.22517","0.17462"
"30491","182.91000","15.24268","0.17663"
"30526","183.12000","15.26020","0.17748"
"30561","183.33000","15.27772","0.18071"
"30596","183.54000","15.29524","0.18196"
"30631","183.75000","15.31276","0.18321"
"30666","183.96000","15.33028","0.18455"
"30701","184.17000","15.34774","0.18664"
"30736","184.38000","15.36519","0.18798"
"30771","184.59000","15.38277","0.18951"
"30806","184.80000","15.40023","0.19207"
"30841","185.01000","15.41769","0.19442"
"30876","185.22000","15.43521","0.19633"
"30911","185.43000","15.45266","0.19828"
"30946","185.64000","15.47024","0.20152"
"30981","185.85000","15.48770","0.20293"
"31016","186.06000","15.50522","0.20464"
"31051","186.27000","15.52274","0.20669"
"31086","186.48000","15.54020","0.20819"
"31121","186.69000","15.55772","0.20992"
"31156","186.90000","15.57523","0.21109"
"31191","187.11000","15.59275","0.21242"
"31226","187.32000","15.61027","0.21433"
"31261","187.53000","15.62767","0.21580"
"31296","187.74000","15.64525","0.21715"
"31331","187.95000","15.66277","0.21781"
"31366","188.16000","15.68022","0.21923"
"31401","188.37000","15.69774","0.22067"
"31436","188.58000","15.71520","0.22212"
"31471","188.79000","15.73278","0.22387"
"31506","189.00000","15.75024","0.22520"
"31541","189.21000","15.76770","0.22639"
"31576","189.42000","15.78521","0.22782"
"31611","189.63000","15.80273","0.23063"
"31646","189.84000","15.82019","0.23257"
"31681","190.05000","15.83777","0.23424"
"31716","190.26000","15.85517","0.23576"
"31751","190.47000","15.87274","0.23740"
"31786","190.68000","15.89020","0.23970"
"31821","190.89000","15.90772","0.24200"
"31856","191.10000","15.92524","0.24417"
"31891","191.31000","15.94270","0.24682"
"31926","191.52000","15.96022","0.24868"
"31961","191.73000","15.97768","0.25166"
"31996","191.94000","15.99520","0.25314"
"32031","192.15000","16.01277","0.25528"
"32066","192.36000","16.03023","0.25690"
"32101","192.57000","16.04775","0.25829"
"32136","192.78000","16.06527","0.25417"
"32171","192.99000","16.08273","0.25570"
"32206","193.20000","16.10030","0.25802"
"32241","193.41000","16.11770","0.25953"
"32276","193.62000","16.13522","0.26248"
"32311","193.83000","16.15268","0.26460"
"32346","194.04000","16.17014","0.26676"
"32381","194.25000","16.18778","0.26993"
"32416","194.46000","16.20523","0.27178"
"32451","194.67000","16.22275","0.27369"
"32486","194.88000","16.24027","0.27695"
"32521","195.09000","16.25773","0.27924"
"32556","195.30000","16.27525","0.28111"
"32591","195.51000","16.29277","0.27937"
"32626","195.72000","16.31017","0.15582"
"32661","195.93000","16.32774","0.15559"
"32696","196.14000","16.34520","0.15813"
"32731","196.35000","16.36272","0.16446"
"32766","196.56000","16.38024","0.16273"
"32801","196.77000","16.39770","0.16730"
"32836","196.98000","16.41522","0.17091"
"32871","197.19000","16.43267","0.17643"
"32906","197.40000","16.45025","0.17550"
"32941","197.61000","16.46771","0.18083"
"32976","197.82000","16.48523","0.18261"
"33011","198.03000","16.50269","0.18471"
"33046","198.24000","16.52021","0.18571"
"33081","198.45000","16.53766","0.18796"
"33116","198.66000","16.55530","0.19245"
"33151","198.87000","16.57264","0.19250"
"33186","199.08000","16.59028","0.19624"
"33221","199.29000","16.60774","0.19795"
"33256","199.50000","16.62520","0.20183"
"33291","199.71000","16.64277","0.20260"
"33326","199.92000","16.66017","0.20544"
"33361","200.13000","16.67775","0.20835"
"33396","200.34000","16.69521","0.21043"
"33431","200.55000","16.71273","0.21307"
"33466","200.76000","16.73025","0.21461"
"33501","200.97000","16.74776","0.21732"
"33536","201.18000","16.76522","0.21844"
"33571","201.39000","16.78274","0.22026"
"33606","201.60000","16.80020","0.22170"
"33641","201.81000","16.81772","0.22360"
"33676","202.02000","16.83524","0.22769"
"33711","202.23000","16.85275","0.22855"
"33746","202.44000","16.87021","0.23166"
"33781","202.65000","16.88767","0.23381"
"33816","202.86000","16.90525","0.23558"
"33851","203.07000","16.92265","0.23910"
"33886","203.28000","16.94017","0.24057"
"33921","203.49000","16.95775","0.24433"
"33956","203.70000","16.97515","0.24647"
"33991","203.91000","16.99278","0.24943"
"34026","204.12000","17.01018","0.25270"
"34061","204.33000","17.02776","0.25413"
"34096","204.54000","17.04528","0.25647"
"34131","204.75000","17.06268","0.10813"
"34166","204.96000","17.08026","0.11023"
"34201","205.17000","17.09777","0.11033"
"34236","205.38000","17.11517","0.03947"
"34271","205.59000","17.13275","0.02127"
"34306","205.80000","17.15015","0.02604"
"34341","206.01000","17.16779","0.02399"
"34376","206.22000","17.18518","0.02213"
"34411","206.43000","17.20270","0.02258"
"34446","206.64000","17.22022","0.02318"
"34481","206.85000","17.23774","0.02205"
"34516","207.06000","17.25520","0.02445"
"34551","207.27000","17.27278","0.02412"
"34586","207.48000","17.29018","0.02429"
"34621","207.69000","17.30775","0.02477"
"34656","207.90000","17.32521","0.02409"
"34691","208.11000","17.34273","0.02567"
"34726","208.32000","17.36025","0.02591"
"34761","208.53000","17.37771","0.02624"
"34796","208.74000","17.39517","0.02620"
"34831","208.95000","17.41269","0.02703"
"34866","209.16000","17.43020","0.02727"
"34901","209.37000","17.44778","0.02848"
"34936","209.58000","17.46524","0.02884"
"34971","209.79000","17.48276","0.02920"
"35006","210.00000","17.50028","0.02964"
"35041","210.21000","17.51768","0.02946"
"35076","210.42000","17.53525","0.03050"
"35111","210.63000","17.55271","0.03077"
"35146","210.84000","17.57023","0.03120"
"35181","211.05000","17.58769","0.03171"
"35216","211.26000","17.60515","0.03239"
"35251","211.47000","17.62273","0.03227"
"35286","211.68000","17.64018","0.03292"
"35321","211.89000","17.65770","0.03352"
"35356","212.10000","17.67528","0.03380"
"35391","212.31000","17.69274","0.03366"
"35426","212.52000","17.71020","0.03468"
"35461","212.73000","17.72778","0.03471"
"35496","212.94000","17.74517","0.03579"
"35531","213.15000","17.76275","0.03703"
"35566","213.36000","17.78021","0.03596"
"35601","213.57000","17.79773","0.03674"
"35636","213.78000","17.81525","0.03794"
"35671","213.99000","17.83271","0.03828"
"35706","214.20000","17.85028","0.03948"
"35741","214.41000","17.86768","0.04008"
"35776","214.62000","17.88526","0.04150"
"35811","214.83000","17.90272","0.04216"
"35846","215.04000","17.92024","0.04266"
"35881","215.25000","17.93770","0.04332"
"35916","215.46000","17.95522","0.04407"
"35951","215.67000","17.97267","0.04452"
"35986","215.88000","17.99031","0.04530"
"36021","216.09000","18.00765","0.04506"
"36056","216.30000","18.02529","0.04630"
"36091","216.51000","18.04269","0.04732"
"36126","216.72000","18.06021","0.04809"
"36161","216.93000","18.07778","0.04860"
"36196","217.14000","18.09518","0.04952"
"36231","217.35000","18.11276","0.05032"
"36266","217.56000","18.13022","0.05057"
"36301","217.77000","18.14774","0.05151"
"36336","217.98000","18.16520","0.05221"
"36371","218.19000","18.18271","0.05238"
"36406","218.40000","18.20023","0.05350"
"36441","218.61000","18.21781","0.05489"
"36476","218.82000","18.23521","0.05499"
"36511","219.03000","18.25279","0.04892"
"36546","219.24000","18.27019","0.04800"
"36581","219.45000","18.28770","0.04918"
"36616","219.66000","18.30516","0.04915"
"36651","219.87000","18.32268","0.05122"
"36686","220.08000","18.34026","0.05125"
"36721","220.29000","18.35766","0.05232"
"36756","220.50000","18.37524","0.05385"
"36791","220.71000","18.39276","0.05361"
"36826","220.92000","18.41015","0.05471"
"36861","221.13000","18.42773","0.05267"
"36896","221.34000","18.44525","0.05375"
"36931","221.55000","18.46265","0.05461"
"36966","221.76000","18.48023","0.05499"
"37001","221.97000","18.49768","0.05717"
"37036","222.18000","18.51526","0.05706"
"37071","222.39000","18.53272","0.05834"
"37106","222.60000","18.55018","0.05931"
"37141","222.81000","18.56776","0.05983"
"37176","223.02000","18.58522","0.06185"
"37211","223.23000","18.60280","0.06195"
"37246","223.44000","18.62020","0.06438"
"37281","223.65000","18.63771","0.06456"
"37316","223.86000","18.65523","0.06414"
"37351","224.07000","18.67269","0.06420"
"37386","224.28000","18.69021","0.06546"
"37421","224.49000","18.70773","0.06644"
"37456","224.70000","18.72519","0.06654"
"37491","224.91000","18.74276","0.06825"
"37526","225.12000","18.76022","0.06805"
"37561","225.33000","18.77768","0.06905"
"37596","225.54000","18.79526","0.06901"
"37631","225.75000","18.81266","0.07024"
"37666","225.96000","18.83024","0.07088"
"37701","226.17000","18.84769","0.07134"
"37736","226.38000","18.86521","0.07249"
"37771","226.59000","18.88273","0.07233"
"37806","226.80000","18.90025","0.06914"
"37841","227.01000","18.91771","0.06896"
"37876","227.22000","18.93523","0.07034"
"37911","227.43000","18.95268","0.07039"
"37946","227.64000","18.97026","0.07156"
"37981","227.85000","18.98772","0.07181"
"38016","228.06000","19.00524","0.07289"
"38051","228.27000","19.02276","0.07388"
"38086","228.48000","19.04016","0.06476"
"38121","228.69000","19.05773","0.06558"
"38156","228.90000","19.07519","0.06679"
"38191","229.11000","19.09271","0.06823"
"38226","229.32000","19.11023","0.06990"
"38261","229.53000","19.12769","0.06967"
"38296","229.74000","19.14521","0.06838"
"38331","229.95000","19.16273","0.06646"
"38366","230.16000","19.18024","0.06631"
"38401","230.37000","19.19776","0.06693"
"38436","230.58000","19.21516","0.06736"
"38471","230.79000","19.23280","0.06667"
"38506","231.00000","19.25026","0.06627"
"38541","231.21000","19.26772","0.06676"
"38576","231.42000","19.28523","0.06601"
"38611","231.63000","19.30269","0.04748"
"38646","231.84000","19.32027","0.04275"
"38681","232.05000","19.33773","0.00698"
"38716","232.26000","19.35519","0.00613"
"38751","232.47000","19.37276","0.00717"
"38786","232.68000","19.39016","0.00557"
"38821","232.89000","19.40774","0.00533"
"38856","233.10000","19.42526","0.00524"
"38891","233.31000","19.44266","0.00479"
"38926","233.52000","19.46030","0.00630"
"38961","233.73000","19.47770","0.00615"
"38996","233.94000","19.49521","0.00577"
"39031","234.15000","19.51279","0.00492"
"39066","234.36000","19.53019","0.00448"
"39101","234.57000","19.54777","0.00460"
"39136","234.78000","19.56517","0.00587"
"39171","234.99000","19.58274","0.00571"
"39206","235.20000","19.60020","0.00487"
"39241","235.41000","19.61772","0.00515"
"39276","235.62000","19.63524","0.00507"
"39311","235.83000","19.65276","0.00571"
"39346","236.04000","19.67022","0.00566"
"39381","236.25000","19.68780","0.00491"
"39416","236.46000","19.70526","0.00565"
"39451","236.67000","19.72277","0.00546"
"39486","236.88000","19.74023","0.00573"
"39521","237.09000","19.75769","0.00605"
"39556","237.30000","19.77521","0.00588"
"39591","237.51000","19.79273","0.00486"
"39626","237.72000","19.81018","0.00564"
"39661","237.93000","19.82776","0.00556"
"39696","238.14000","19.84516","0.00598"
"39731","238.35000","19.86274","0.00604"
"39766","238.56000","19.88026","0.00504"
"39801","238.77000","19.89772","0.00576"
"39836","238.98000","19.91524","0.00566"
"39871","239.19000","19.93263","0.00605"
"39906","239.40000","19.95027","0.00601"
"39941","239.61000","19.96773","0.00524"
"39976","239.82000","19.98519","0.00589"
"40011","240.03000","20.00271","0.00597"
"40046","240.24000","20.02022","0.00598"
"40081","240.45000","20.03774","0.00560"
"40116","240.66000","20.05526","0.00569"
"40151","240.87000","20.07272","0.00565"
"40186","241.08000","20.09024","0.00579"
"40221","241.29000","20.10770","0.00602"
"40256","241.50000","20.12522","0.00594"
"40291","241.71000","20.14280","0.00609"
"40326","241.92000","20.16019","0.00595"
"40361","242.13000","20.17777","0.00602"
"40396","242.34000","20.19523","0.00578"
"40431","242.55000","20.21269","0.00629"
"40466","242.76000","20.23021","0.00606"
"40501","242.97000","20.24766","0.00619"
"40536","243.18000","20.26524","0.00643"
"40571","243.39000","20.28270","0.00641"
"40606","243.60000","20.30022","0.00622"
"40641","243.81000","20.31774","0.00643"
"40676","244.02000","20.33520","0.00655"
"40711","244.23000","20.35277","0.00627"
"40746","244.44000","20.37029","0.00630"
"40781","244.65000","20.38769","0.00664"
"40816","244.86000","20.40527","0.00685"
"40851","245.07000","20.42273","0.00694"
"40886","245.28000","20.44025","0.00688"
"40921","245.49000","20.45771","0.00680"
"40956","245.70000","20.47517","0.00653"
"40991","245.91000","20.49274","0.00653"
"41026","246.12000","20.51020","0.00578"
"41061","246.33000","20.52772","0.00529"
"41096","246.54000","20.54524","0.00622"
"41131","246.75000","20.56270","0.00542"
"41166","246.96000","20.58022","0.00586"
"41201","247.17000","20.59773","0.00586"
"41236","247.38000","20.61519","0.00588"
"41271","247.59000","20.63277","0.00592"
"41306","247.80000","20.65017","0.00563"
"41341","248.01000","20.66775","0.00581"
"41376","248.22000","20.68526","0.00566"
"41411","248.43000","20.70272","0.00585"
"41446","248.64000","20.72030","0.00584"
"41481","248.85000","20.73764","0.00567"
"41516","249.06000","20.75528","0.00568"
"41551","249.27000","20.77268","0.00591"
"41586","249.48000","20.79020","0.00598"
"41621","249.69000","20.80771","0.00587"
"41656","249.90000","20.82523","0.00585"
"41691","250.11000","20.84269","0.00570"
"41726","250.32000","20.86027","0.00563"
"41761","250.53000","20.87767","0.00579"
"41796","250.74000","20.89525","0.00601"
"41831","250.95000","20.91270","0.00614"
"41866","251.16000","20.93022","0.00555"
"41901","251.37000","20.94780","0.00609"
"41936","251.58000","20.96520","0.00590"
"41971","251.79000","20.98272","0.00593"
"42006","252.00000","21.00018","0.00566"
"42041","252.21000","21.01775","0.00570"
"42076","252.42000","21.03521","0.00586"
"42111","252.63000","21.05273","0.00569"
"42146","252.84000","21.07025","0.00599"
"42181","253.05000","21.08771","0.00569"
"42216","253.26000","21.10523","0.00631"
"42251","253.47000","21.12275","0.00591"
"42286","253.68000","21.14021","0.00582"
"42321","253.89000","21.15778","0.00549"
"42356","254.10000","21.17524","0.00527"
"42391","254.31000","21.19270","0.00589"
"42426","254.52000","21.21022","0.00578"
"42461","254.73000","21.22767","0.00576"
"42496","254.94000","21.24525","0.00547"
"42531","255.15000","21.26277","0.00576"
"42566","255.36000","21.28017","0.00568"
"42601","255.57000","21.29775","0.00567"
"42636","255.78000","21.31527","0.00548"
"42671","255.99000","21.33273","0.00580"
"42706","256.20000","21.35031","0.00568"
"42741","256.41000","21.36770","0.00533"
"42776","256.62000","21.38528","0.00588"
"42811","256.83000","21.40274","0.00592"
"42846","257.04000","21.42020","0.00611"
"42881","257.25000","21.43778","0.00611"
"42916","257.46000","21.45518","0.00575"
"42951","257.67000","21.47275","0.00567"
"42986","257.88000","21.49021","0.00585"
"43021","258.09000","21.50773","0.00579"
"43056","258.30000","21.52525","0.00564"
"43091","258.51000","21.54271","0.00588"
"43126","258.72000","21.56017","0.00595"
"43161","258.93000","21.57780","0.00580"
"43196","259.14000","21.59514","0.00580"
"43231","259.35000","21.61278","0.00594"
"43266","259.56000","21.63018","0.00612"
"43301","259.77000","21.64770","0.00579"
"43336","259.98000","21.66528","0.00609"
"43371","260.19000","21.68267","0.00617"
"43406","260.40000","21.70019","0.00559"
"43441","260.61000","21.71771","0.00621"
"43476","260.82000","21.73517","0.00619"
"43511","261.03000","21.75275","0.00596"
"43546","261.24000","21.77021","0.00615"
"43581","261.45000","21.78773","0.00609"
"43585","261.47400","21.78970","0.00618"