File: Trajectories_together/170107_2Specimen_RawData_3.csv
"","V1","V2","V3"
"1","End date","1/7/2017",""
"2","Specimen label","17DG_35",""
"3","Maximum Load","0.39610","N"
"4","Time","Extension","Load"
"5","(s)","(mm)","(N)"
"6","0.00000","-0.00006","-0.00077"
"81","0.45000","0.03779","0.00007"
"156","0.90000","0.07516","0.00002"
"231","1.35000","0.11264","0.00048"
"306","1.80000","0.15013","0.00043"
"381","2.25000","0.18768","0.00065"
"456","2.70000","0.22517","0.00099"
"531","3.15000","0.26272","0.00103"
"606","3.60000","0.30014","0.00095"
"681","4.05000","0.33757","0.00116"
"756","4.50000","0.37512","0.00205"
"831","4.95000","0.41267","0.00170"
"906","5.40000","0.45016","0.00156"
"981","5.85000","0.48764","0.00155"
"1056","6.30000","0.52513","0.00186"
"1131","6.75000","0.56256","0.00145"
"1206","7.20000","0.60011","0.00187"
"1281","7.65000","0.63766","0.00221"
"1356","8.10000","0.67514","0.00177"
"1431","8.55000","0.71263","0.00218"
"1506","9.00000","0.75012","0.00254"
"1581","9.45000","0.78761","0.00274"
"1656","9.90000","0.82516","0.00253"
"1731","10.35000","0.86258","0.00266"
"1806","10.80000","0.90019","0.00265"
"1881","11.25000","0.93768","0.00294"
"1956","11.70000","0.97517","0.00330"
"2031","12.15000","1.01266","0.00311"
"2106","12.60000","1.05008","0.00290"
"2181","13.05000","1.08763","0.00341"
"2256","13.50000","1.12512","0.00379"
"2331","13.95000","1.16267","0.00359"
"2406","14.40000","1.20016","0.00444"
"2481","14.85000","1.23758","0.00430"
"2556","15.30000","1.27513","0.00447"
"2631","15.75000","1.31262","0.00421"
"2706","16.20000","1.35017","0.00467"
"2781","16.65000","1.38760","0.00506"
"2856","17.10000","1.42514","0.00527"
"2931","17.55000","1.46257","0.00512"
"3006","18.00000","1.50012","0.00603"
"3081","18.45000","1.53767","0.00529"
"3156","18.90000","1.57516","0.00559"
"3231","19.35000","1.61264","0.00599"
"3306","19.80000","1.65013","0.00631"
"3381","20.25000","1.68762","0.00636"
"3456","20.70000","1.72511","0.00644"
"3531","21.15000","1.76260","0.00701"
"3606","21.60000","1.80020","0.00668"
"3681","22.05000","1.83769","0.00687"
"3756","22.50000","1.87518","0.00723"
"3831","22.95000","1.91261","0.00693"
"3906","23.40000","1.95004","0.00723"
"3981","23.85000","1.98764","0.00689"
"4056","24.30000","2.02519","0.00696"
"4131","24.75000","2.06268","0.00717"
"4206","25.20000","2.10017","0.00717"
"4281","25.65000","2.13760","0.00710"
"4356","26.10000","2.17508","0.00702"
"4431","26.55000","2.21263","0.00739"
"4506","27.00000","2.25012","0.00773"
"4581","27.45000","2.28761","0.00769"
"4656","27.90000","2.32516","0.00763"
"4731","28.35000","2.36264","0.00788"
"4806","28.80000","2.40013","0.00779"
"4881","29.25000","2.43762","0.00778"
"4956","29.70000","2.47511","0.00833"
"5031","30.15000","2.51266","0.00812"
"5106","30.60000","2.55020","0.00777"
"5181","31.05000","2.58757","0.00850"
"5256","31.50000","2.62506","0.00825"
"5331","31.95000","2.66261","0.00863"
"5406","32.40000","2.70016","0.00777"
"5481","32.85000","2.73764","0.00797"
"5556","33.30000","2.77513","0.00773"
"5631","33.75000","2.81256","0.00770"
"5706","34.20000","2.85005","0.00848"
"5781","34.65000","2.88766","0.00838"
"5856","35.10000","2.92514","0.00899"
"5931","35.55000","2.96263","0.00819"
"6006","36.00000","3.00018","0.00818"
"6081","36.45000","3.03761","0.00835"
"6156","36.90000","3.07510","0.00843"
"6231","37.35000","3.11258","0.00888"
"6306","37.80000","3.15013","0.00886"
"6381","38.25000","3.18768","0.00882"
"6456","38.70000","3.22523","0.00955"
"6531","39.15000","3.26265","0.00905"
"6606","39.60000","3.30008","0.00866"
"6681","40.05000","3.33763","0.00962"
"6756","40.50000","3.37506","0.00963"
"6831","40.95000","3.41267","0.00940"
"6906","41.40000","3.45016","0.00892"
"6981","41.85000","3.48770","0.00926"
"7056","42.30000","3.52513","0.00899"
"7131","42.75000","3.56262","0.00939"
"7206","43.20000","3.60017","0.00908"
"7281","43.65000","3.63760","0.00956"
"7356","44.10000","3.67514","0.00944"
"7431","44.55000","3.71263","0.00981"
"7506","45.00000","3.75006","0.01023"
"7581","45.45000","3.78767","0.00984"
"7656","45.90000","3.82510","0.01001"
"7731","46.35000","3.86270","0.01009"
"7806","46.80000","3.90013","0.00984"
"7881","47.25000","3.93768","0.01026"
"7956","47.70000","3.97511","0.00970"
"8031","48.15000","4.01259","0.00992"
"8106","48.60000","4.05008","0.00998"
"8181","49.05000","4.08763","0.01048"
"8256","49.50000","4.12512","0.01048"
"8331","49.95000","4.16267","0.01031"
"8406","50.40000","4.20009","0.01050"
"8481","50.85000","4.23758","0.01060"
"8556","51.30000","4.27513","0.01022"
"8631","51.75000","4.31268","0.01023"
"8706","52.20000","4.35017","0.01088"
"8781","52.65000","4.38765","0.01087"
"8856","53.10000","4.42514","0.01032"
"8931","53.55000","4.46257","0.01065"
"9006","54.00000","4.50012","0.01107"
"9081","54.45000","4.53767","0.01089"
"9156","54.90000","4.57515","0.01129"
"9231","55.35000","4.61270","0.01186"
"9306","55.80000","4.65013","0.00998"
"9381","56.25000","4.68762","0.01041"
"9456","56.70000","4.72511","0.01051"
"9531","57.15000","4.76260","0.01064"
"9606","57.60000","4.80014","0.01089"
"9681","58.05000","4.83763","0.01056"
"9756","58.50000","4.87518","0.01065"
"9831","58.95000","4.91261","0.01112"
"9906","59.40000","4.95010","0.01043"
"9981","59.85000","4.98764","0.01105"
"10056","60.30000","5.02513","0.01074"
"10131","60.75000","5.06268","0.01076"
"10206","61.20000","5.10017","0.01084"
"10281","61.65000","5.13759","0.01036"
"10356","62.10000","5.17508","0.01086"
"10431","62.55000","5.21263","0.01148"
"10506","63.00000","5.25018","0.01115"
"10581","63.45000","5.28767","0.01115"
"10656","63.90000","5.32515","0.01125"
"10731","64.35000","5.36258","0.01159"
"10806","64.80000","5.40013","0.01107"
"10881","65.25000","5.43768","0.01093"
"10956","65.70000","5.47517","0.01107"
"11031","66.15000","5.51265","0.01149"
"11106","66.60000","5.55014","0.01118"
"11181","67.05000","5.58751","0.01162"
"11256","67.50000","5.62512","0.01164"
"11331","67.95000","5.66267","0.01151"
"11406","68.40000","5.70021","0.01128"
"11481","68.85000","5.73770","0.01168"
"11556","69.30000","5.77513","0.01164"
"11631","69.75000","5.81256","0.01189"
"11706","70.20000","5.85005","0.01214"
"11781","70.65000","5.88760","0.01244"
"11856","71.10000","5.92514","0.01199"
"11931","71.55000","5.96269","0.01208"
"12006","72.00000","6.00018","0.01229"
"12081","72.45000","6.03767","0.01268"
"12156","72.90000","6.07509","0.01266"
"12231","73.35000","6.11264","0.01276"
"12306","73.80000","6.15013","0.01257"
"12381","74.25000","6.18768","0.01147"
"12456","74.70000","6.22517","0.01145"
"12531","75.15000","6.26265","0.01149"
"12606","75.60000","6.30008","0.01148"
"12681","76.05000","6.33757","0.01119"
"12756","76.50000","6.37518","0.01131"
"12831","76.95000","6.41261","0.01125"
"12906","77.40000","6.45015","0.01152"
"12981","77.85000","6.48764","0.01157"
"13056","78.30000","6.52513","0.01119"
"13131","78.75000","6.56262","0.01183"
"13206","79.20000","6.60017","0.01200"
"13281","79.65000","6.63765","0.01187"
"13356","80.10000","6.67514","0.01205"
"13431","80.55000","6.71263","0.01202"
"13506","81.00000","6.75006","0.01174"
"13581","81.45000","6.78767","0.01147"
"13656","81.90000","6.82516","0.01240"
"13731","82.35000","6.86264","0.01226"
"13806","82.80000","6.90019","0.01157"
"13881","83.25000","6.93762","0.01236"
"13956","83.70000","6.97505","0.01212"
"14031","84.15000","7.01259","0.01197"
"14106","84.60000","7.05020","0.01256"
"14181","85.05000","7.08769","0.01233"
"14256","85.50000","7.12512","0.01273"
"14331","85.95000","7.16261","0.01248"
"14406","86.40000","7.20009","0.01223"
"14481","86.85000","7.23764","0.01280"
"14556","87.30000","7.27513","0.01297"
"14631","87.75000","7.31268","0.01291"
"14706","88.20000","7.35017","0.01362"
"14781","88.65000","7.38760","0.01272"
"14856","89.10000","7.42508","0.01309"
"14931","89.55000","7.46257","0.01287"
"15006","90.00000","7.50012","0.01326"
"15081","90.45000","7.53767","0.01301"
"15156","90.90000","7.57515","0.01301"
"15231","91.35000","7.61264","0.01315"
"15306","91.80000","7.65013","0.01323"
"15381","92.25000","7.68762","0.01263"
"15456","92.70000","7.72517","0.01255"
"15531","93.15000","7.76266","0.01292"
"15606","93.60000","7.80014","0.01235"
"15681","94.05000","7.83769","0.01338"
"15756","94.50000","7.87512","0.01265"
"15831","94.95000","7.91261","0.01267"
"15906","95.40000","7.95009","0.01362"
"15981","95.85000","7.98764","0.01318"
"16056","96.30000","8.02513","0.01309"
"16131","96.75000","8.06262","0.01351"
"16206","97.20000","8.10011","0.01335"
"16281","97.65000","8.13760","0.01370"
"16356","98.10000","8.17514","0.01344"
"16431","98.55000","8.21263","0.01270"
"16506","99.00000","8.25018","0.01279"
"16581","99.45000","8.28761","0.01284"
"16656","99.90000","8.32509","0.01239"
"16731","100.35000","8.36258","0.01311"
"16806","100.80000","8.40013","0.01282"
"16881","101.25000","8.43768","0.01307"
"16956","101.70000","8.47511","0.01302"
"17031","102.15000","8.51265","0.01319"
"17106","102.60000","8.55008","0.01320"
"17181","103.05000","8.58751","0.01277"
"17256","103.50000","8.62512","0.01304"
"17331","103.95000","8.66261","0.01356"
"17406","104.40000","8.70021","0.01349"
"17481","104.85000","8.73770","0.01345"
"17556","105.30000","8.77513","0.01380"
"17631","105.75000","8.81262","0.01403"
"17706","106.20000","8.85011","0.01397"
"17781","106.65000","8.88765","0.01427"
"17856","107.10000","8.92514","0.01431"
"17931","107.55000","8.96269","0.01413"
"18006","108.00000","9.00012","0.01453"
"18081","108.45000","9.03755","0.01428"
"18156","108.90000","9.07509","0.01439"
"18231","109.35000","9.11264","0.01489"
"18306","109.80000","9.15019","0.01502"
"18381","110.25000","9.18762","0.01511"
"18456","110.70000","9.22511","0.01519"
"18531","111.15000","9.26259","0.01478"
"18606","111.60000","9.30014","0.01488"
"18681","112.05000","9.33763","0.01555"
"18756","112.50000","9.37512","0.01495"
"18831","112.95000","9.41261","0.01536"
"18906","113.40000","9.45015","0.01578"
"18981","113.85000","9.48758","0.01603"
"19056","114.30000","9.52513","0.01585"
"19131","114.75000","9.56268","0.01598"
"19206","115.20000","9.60017","0.01626"
"19281","115.65000","9.63765","0.01597"
"19356","116.10000","9.67514","0.01623"
"19431","116.55000","9.71257","0.01622"
"19506","117.00000","9.75012","0.01612"
"19581","117.45000","9.78767","0.01625"
"19656","117.90000","9.82515","0.01656"
"19731","118.35000","9.86264","0.01683"
"19806","118.80000","9.90019","0.01679"
"19881","119.25000","9.93756","0.01582"
"19956","119.70000","9.97511","0.01617"
"20031","120.15000","10.01259","0.01595"
"20106","120.60000","10.05014","0.01595"
"20181","121.05000","10.08763","0.01578"
"20256","121.50000","10.12512","0.01632"
"20331","121.95000","10.16261","0.01484"
"20406","122.40000","10.20015","0.01569"
"20481","122.85000","10.23758","0.01565"
"20556","123.30000","10.27519","0.01562"
"20631","123.75000","10.31262","0.01585"
"20706","124.20000","10.35017","0.01594"
"20781","124.65000","10.38760","0.01621"
"20856","125.10000","10.42508","0.01604"
"20931","125.55000","10.46263","0.01649"
"21006","126.00000","10.50018","0.01726"
"21081","126.45000","10.53761","0.01629"
"21156","126.90000","10.57509","0.01684"
"21231","127.35000","10.61264","0.01721"
"21306","127.80000","10.65013","0.01695"
"21381","128.25000","10.68762","0.01729"
"21456","128.70000","10.72517","0.01740"
"21531","129.14999","10.76265","0.01750"
"21606","129.60001","10.80014","0.01792"
"21681","130.05000","10.83763","0.01814"
"21756","130.50000","10.87512","0.01789"
"21831","130.95000","10.91267","0.01780"
"21906","131.39999","10.95015","0.01800"
"21981","131.85001","10.98764","0.01795"
"22056","132.30000","11.02519","0.01844"
"22131","132.75000","11.06268","0.01849"
"22206","133.20000","11.10005","0.01536"
"22281","133.64999","11.13759","0.01665"
"22356","134.10001","11.17514","0.01625"
"22431","134.55000","11.21269","0.01624"
"22506","135.00000","11.25018","0.01647"
"22581","135.45000","11.28761","0.01667"
"22656","135.89999","11.32510","0.01699"
"22731","136.35001","11.36258","0.01681"
"22806","136.80000","11.40013","0.01709"
"22881","137.25000","11.43768","0.01786"
"22956","137.70000","11.47517","0.01762"
"23031","138.14999","11.51259","0.01780"
"23106","138.60001","11.55008","0.01750"
"23181","139.05000","11.58763","0.01794"
"23256","139.50000","11.62512","0.01808"
"23331","139.95000","11.66267","0.01838"
"23406","140.39999","11.70015","0.01851"
"23481","140.85001","11.73770","0.01829"
"23556","141.30000","11.77507","0.01880"
"23631","141.75000","11.81262","0.01899"
"23706","142.20000","11.85011","0.01881"
"23781","142.64999","11.88765","0.01883"
"23856","143.10001","11.92514","0.01930"
"23931","143.55000","11.96263","0.01955"
"24006","144.00000","12.00012","0.01963"
"24081","144.45000","12.03761","0.01976"
"24156","144.89999","12.07515","0.01965"
"24231","145.35001","12.11270","0.01967"
"24306","145.80000","12.15013","0.01997"
"24381","146.25000","12.18768","0.01977"
"24456","146.70000","12.22505","0.02048"
"24531","147.14999","12.26265","0.02035"
"24606","147.60001","12.30014","0.02030"
"24681","148.05000","12.33763","0.02020"
"24756","148.50000","12.37512","0.02032"
"24831","148.95000","12.41267","0.02066"
"24906","149.39999","12.45015","0.02089"
"24981","149.85001","12.48758","0.02090"
"25056","150.30000","12.52513","0.02144"
"25131","150.75000","12.56268","0.02120"
"25206","151.20000","12.60017","0.02122"
"25281","151.64999","12.63765","0.02130"
"25356","152.10001","12.67508","0.02165"
"25431","152.55000","12.71257","0.02198"
"25506","153.00000","12.75012","0.02144"
"25581","153.45000","12.78767","0.02197"
"25656","153.89999","12.82515","0.02163"
"25731","154.35001","12.86270","0.02199"
"25806","154.80000","12.90013","0.02217"
"25881","155.25000","12.93762","0.02270"
"25956","155.70000","12.97511","0.02242"
"26031","156.14999","13.01265","0.02279"
"26106","156.60001","13.05014","0.02311"
"26181","157.05000","13.08763","0.02314"
"26256","157.50000","13.12512","0.02321"
"26331","157.95000","13.16261","0.02370"
"26406","158.39999","13.20010","0.02374"
"26481","158.85001","13.23764","0.02416"
"26556","159.30000","13.27513","0.02440"
"26631","159.75000","13.31262","0.02442"
"26706","160.20000","13.35011","0.02475"
"26781","160.64999","13.38759","0.02488"
"26856","161.10001","13.42508","0.02538"
"26931","161.55000","13.46269","0.02497"
"27006","162.00000","13.50018","0.02572"
"27081","162.45000","13.53761","0.02564"
"27156","162.89999","13.57509","0.02575"
"27231","163.35001","13.61252","0.02556"
"27306","163.80000","13.65013","0.02605"
"27381","164.25000","13.68768","0.02581"
"27456","164.70000","13.72517","0.02542"
"27531","165.14999","13.76271","0.02611"
"27606","165.60001","13.80014","0.02651"
"27681","166.05000","13.83757","0.02687"
"27756","166.50000","13.87506","0.02629"
"27831","166.95000","13.91267","0.02672"
"27906","167.39999","13.95021","0.02718"
"27981","167.85001","13.98770","0.02745"
"28056","168.30000","14.02513","0.02758"
"28131","168.75000","14.06262","0.02790"
"28206","169.20000","14.10011","0.02778"
"28281","169.64999","14.13759","0.02838"
"28356","170.10001","14.17514","0.02845"
"28431","170.55000","14.21269","0.02876"
"28506","171.00000","14.25018","0.02877"
"28581","171.45000","14.28761","0.02910"
"28656","171.89999","14.32509","0.02991"
"28731","172.35001","14.36264","0.02930"
"28806","172.80000","14.40007","0.03000"
"28881","173.25000","14.43762","0.03036"
"28956","173.70000","14.47517","0.03075"
"29031","174.14999","14.51260","0.03094"
"29106","174.60001","14.55014","0.03053"
"29181","175.05000","14.58763","0.03038"
"29256","175.50000","14.62518","0.03048"
"29331","175.95000","14.66261","0.02938"
"29406","176.39999","14.70015","0.02895"
"29481","176.85001","14.73758","0.02976"
"29556","177.30000","14.77507","0.03046"
"29631","177.75000","14.81262","0.03010"
"29706","178.20000","14.85017","0.03136"
"29781","178.64999","14.88759","0.03186"
"29856","179.10001","14.92514","0.03201"
"29931","179.55000","14.96257","0.03210"
"30006","180.00000","15.00006","0.03247"
"30081","180.45000","15.03761","0.03320"
"30156","180.89999","15.07515","0.03329"
"30231","181.35001","15.11264","0.03346"
"30306","181.80000","15.15019","0.03460"
"30381","182.25000","15.18762","0.03566"
"30456","182.70000","15.22505","0.03541"
"30531","183.14999","15.26259","0.03576"
"30606","183.60001","15.30020","0.03580"
"30681","184.05000","15.33769","0.03692"
"30756","184.50000","15.37524","0.03769"
"30831","184.95000","15.41261","0.03786"
"30906","185.39999","15.45009","0.03834"
"30981","185.85001","15.48758","0.03868"
"31056","186.30000","15.52513","0.04001"
"31131","186.75000","15.56268","0.04079"
"31206","187.20000","15.60017","0.04091"
"31281","187.64999","15.63765","0.04130"
"31356","188.10001","15.67514","0.04139"
"31431","188.55000","15.71263","0.04246"
"31506","189.00000","15.75018","0.04241"
"31581","189.45000","15.78761","0.04281"
"31656","189.89999","15.82515","0.04341"
"31731","190.35001","15.86264","0.04353"
"31806","190.80000","15.90013","0.04081"
"31881","191.25000","15.93762","0.04111"
"31956","191.70000","15.97510","0.04285"
"32031","192.14999","16.01265","0.04257"
"32106","192.60001","16.05014","0.04286"
"32181","193.05000","16.08763","0.04340"
"32256","193.50000","16.12512","0.04422"
"32331","193.95000","16.16261","0.04503"
"32406","194.39999","16.20015","0.04571"
"32481","194.85001","16.23764","0.04702"
"32556","195.30000","16.27513","0.04789"
"32631","195.75000","16.31262","0.04875"
"32706","196.20000","16.35005","0.04984"
"32781","196.64999","16.38759","0.05069"
"32856","197.10001","16.42514","0.05170"
"32931","197.55000","16.46269","0.05310"
"33006","198.00000","16.50012","0.05373"
"33081","198.45000","16.53761","0.05460"
"33156","198.89999","16.57509","0.05584"
"33231","199.35001","16.61258","0.05695"
"33306","199.80000","16.65013","0.05806"
"33381","200.25000","16.68768","0.05897"
"33456","200.70000","16.72517","0.05982"
"33531","201.14999","16.76265","0.06050"
"33606","201.60001","16.80014","0.06191"
"33681","202.05000","16.83757","0.06190"
"33756","202.50000","16.87512","0.06238"
"33831","202.95000","16.91266","0.06417"
"33906","203.39999","16.95015","0.06519"
"33981","203.85001","16.98770","0.06606"
"34056","204.30000","17.02513","0.06704"
"34131","204.75000","17.06256","0.06714"
"34206","205.20000","17.10011","0.06803"
"34281","205.64999","17.13765","0.06865"
"34356","206.10001","17.17514","0.07020"
"34431","206.55000","17.21263","0.07042"
"34506","207.00000","17.25018","0.07056"
"34581","207.45000","17.28766","0.07165"
"34656","207.89999","17.32515","0.07199"
"34731","208.35001","17.36264","0.07259"
"34806","208.80000","17.40013","0.07323"
"34881","209.25000","17.43762","0.07350"
"34956","209.70000","17.47517","0.07439"
"35031","210.14999","17.51253","0.07523"
"35106","210.60001","17.55014","0.07606"
"35181","211.05000","17.58769","0.07667"
"35256","211.50000","17.62512","0.07756"
"35331","211.95000","17.66266","0.07860"
"35406","212.39999","17.70009","0.07954"
"35481","212.85001","17.73758","0.08027"
"35556","213.30000","17.77513","0.08169"
"35631","213.75000","17.81268","0.08286"
"35706","214.20000","17.85016","0.08381"
"35781","214.64999","17.88759","0.08432"
"35856","215.10001","17.92514","0.08588"
"35931","215.55000","17.96257","0.08672"
"36006","216.00000","18.00012","0.08600"
"36081","216.45000","18.03761","0.08748"
"36156","216.89999","18.07515","0.08955"
"36231","217.35001","18.11264","0.09158"
"36306","217.80000","18.15013","0.09307"
"36381","218.25000","18.18762","0.09559"
"36456","218.70000","18.22511","0.09780"
"36531","219.14999","18.26259","0.10024"
"36606","219.60001","18.30014","0.10215"
"36681","220.05000","18.33775","0.10469"
"36756","220.50000","18.37518","0.10787"
"36831","220.95000","18.41266","0.10979"
"36906","221.39999","18.45009","0.11201"
"36981","221.85001","18.48764","0.11401"
"37056","222.30000","18.52513","0.11670"
"37131","222.75000","18.56262","0.11912"
"37206","223.20000","18.60011","0.12195"
"37281","223.64999","18.63759","0.12365"
"37356","224.10001","18.67508","0.12577"
"37431","224.55000","18.71263","0.12852"
"37506","225.00000","18.75018","0.13164"
"37581","225.45000","18.78766","0.13267"
"37656","225.89999","18.82509","0.13493"
"37731","226.35001","18.86264","0.13690"
"37806","226.80000","18.90013","0.13848"
"37881","227.25000","18.93768","0.14049"
"37956","227.70000","18.97511","0.14185"
"38031","228.14999","19.01265","0.14337"
"38106","228.60001","19.05014","0.14494"
"38181","229.05000","19.08757","0.14677"
"38256","229.50000","19.12506","0.14917"
"38331","229.95000","19.16261","0.15036"
"38406","230.39999","19.20021","0.15288"
"38481","230.85001","19.23764","0.15362"
"38556","231.30000","19.27513","0.15605"
"38631","231.75000","19.31262","0.15872"
"38706","232.20000","19.35005","0.16089"
"38781","232.64999","19.38765","0.16316"
"38856","233.10001","19.42514","0.16483"
"38931","233.55000","19.46269","0.16793"
"39006","234.00000","19.50018","0.16918"
"39081","234.45000","19.53760","0.17092"
"39156","234.89999","19.57515","0.17344"
"39231","235.35001","19.61258","0.17545"
"39306","235.80000","19.65013","0.17758"
"39381","236.25000","19.68762","0.17887"
"39456","236.70000","19.72516","0.18018"
"39531","237.14999","19.76265","0.18170"
"39606","237.60001","19.80008","0.18294"
"39681","238.05000","19.83757","0.18443"
"39756","238.50000","19.87511","0.18482"
"39831","238.95000","19.91267","0.18541"
"39906","239.39999","19.95015","0.18640"
"39981","239.85001","19.98764","0.18806"
"40056","240.30000","20.02513","0.18899"
"40131","240.75000","20.06262","0.19107"
"40206","241.20000","20.10016","0.19274"
"40281","241.64999","20.13765","0.19420"
"40356","242.10001","20.17514","0.19695"
"40431","242.55000","20.21263","0.19907"
"40506","243.00000","20.25006","0.20149"
"40581","243.45000","20.28761","0.20429"
"40656","243.89999","20.32515","0.20704"
"40731","244.35001","20.36270","0.20685"
"40806","244.80000","20.40019","0.20503"
"40881","245.25000","20.43761","0.19502"
"40956","245.70000","20.47504","0.19784"
"41031","246.14999","20.51259","0.20182"
"41106","246.60001","20.55014","0.20573"
"41181","247.05000","20.58769","0.20825"
"41256","247.50000","20.62518","0.21244"
"41331","247.95000","20.66267","0.21577"
"41406","248.39999","20.70009","0.21999"
"41481","248.85001","20.73752","0.22292"
"41556","249.30000","20.77507","0.22607"
"41631","249.75000","20.81268","0.22796"
"41706","250.20000","20.85016","0.22402"
"41781","250.64999","20.88765","0.22807"
"41856","251.10001","20.92508","0.23176"
"41931","251.55000","20.96263","0.23553"
"42006","252.00000","21.00006","0.23947"
"42081","252.45000","21.03766","0.24332"
"42156","252.89999","21.07515","0.24565"
"42231","253.35001","21.11270","0.24917"
"42306","253.80000","21.15013","0.25255"
"42381","254.25000","21.18756","0.25716"
"42456","254.70000","21.22510","0.26159"
"42531","255.14999","21.26265","0.26705"
"42606","255.60001","21.30014","0.10246"
"42681","256.04999","21.33763","0.09631"
"42756","256.50000","21.37512","0.09439"
"42831","256.95001","21.41261","0.09921"
"42906","257.39999","21.45015","0.10501"
"42981","257.85001","21.48764","0.10356"
"43056","258.29999","21.52513","0.10332"
"43131","258.75000","21.56268","0.10564"
"43206","259.20001","21.60011","0.10932"
"43281","259.64999","21.63759","0.11089"
"43356","260.10001","21.67514","0.11241"
"43431","260.54999","21.71263","0.11703"
"43506","261.00000","21.75017","0.12017"
"43581","261.45001","21.78767","0.12316"
"43656","261.89999","21.82515","0.12588"
"43731","262.35001","21.86252","0.12946"
"43806","262.79999","21.90013","0.13228"
"43881","263.25000","21.93762","0.13347"
"43956","263.70001","21.97516","0.13514"
"44031","264.14999","22.01265","0.13596"
"44106","264.60001","22.05014","0.13672"
"44181","265.04999","22.08763","0.13809"
"44256","265.50000","22.12512","0.13978"
"44331","265.95001","22.16261","0.14179"
"44406","266.39999","22.20015","0.14335"
"44481","266.85001","22.23764","0.14542"
"44556","267.29999","22.27513","0.14780"
"44631","267.75000","22.31256","0.14857"
"44706","268.20001","22.35011","0.14951"
"44781","268.64999","22.38759","0.15064"
"44856","269.10001","22.42514","0.15200"
"44931","269.54999","22.46263","0.15464"
"45006","270.00000","22.50018","0.15674"
"45081","270.45001","22.53766","0.15979"
"45156","270.89999","22.57515","0.16201"
"45231","271.35001","22.61264","0.16233"
"45306","271.79999","22.65013","0.16179"
"45381","272.25000","22.68768","0.16241"
"45456","272.70001","22.72516","0.16387"
"45531","273.14999","22.76259","0.16531"
"45606","273.60001","22.80014","0.16839"
"45681","274.04999","22.83763","0.17012"
"45756","274.50000","22.87518","0.17099"
"45831","274.95001","22.91261","0.17267"
"45906","275.39999","22.95015","0.17477"
"45981","275.85001","22.98758","0.17654"
"46056","276.29999","23.02519","0.17848"
"46131","276.75000","23.06268","0.17867"
"46206","277.20001","23.10011","0.17986"
"46281","277.64999","23.13765","0.18094"
"46356","278.10001","23.17520","0.18163"
"46431","278.54999","23.21263","0.18298"
"46506","279.00000","23.25012","0.18425"
"46581","279.45001","23.28761","0.18527"
"46656","279.89999","23.32521","0.18626"
"46731","280.35001","23.36270","0.18658"
"46806","280.79999","23.40019","0.18823"
"46881","281.25000","23.43756","0.19008"
"46956","281.70001","23.47510","0.19136"
"47031","282.14999","23.51265","0.19289"
"47106","282.60001","23.55014","0.19481"
"47181","283.04999","23.58769","0.19726"
"47256","283.50000","23.62518","0.19967"
"47331","283.95001","23.66261","0.20088"
"47406","284.39999","23.70009","0.20290"
"47481","284.85001","23.73758","0.20462"
"47556","285.29999","23.77513","0.19924"
"47631","285.75000","23.81268","0.20048"
"47706","286.20001","23.85011","0.19822"
"47781","286.64999","23.88765","0.19983"
"47856","287.10001","23.92508","0.20113"
"47931","287.54999","23.96257","0.20264"
"48006","288.00000","24.00012","0.20251"
"48081","288.45001","24.03766","0.20331"
"48156","288.89999","24.07515","0.20567"
"48231","289.35001","24.11264","0.20734"
"48306","289.79999","24.15007","0.21103"
"48381","290.25000","24.18762","0.21395"
"48456","290.70001","24.22516","0.21712"
"48531","291.14999","24.26265","0.21998"
"48606","291.60001","24.30014","0.22209"
"48681","292.04999","24.33757","0.22433"
"48756","292.50000","24.37506","0.22712"
"48831","292.95001","24.41267","0.23006"
"48906","293.39999","24.45015","0.23280"
"48981","293.85001","24.48764","0.23518"
"49056","294.29999","24.52513","0.23723"
"49131","294.75000","24.56262","0.24094"
"49206","295.20001","24.60010","0.24325"
"49281","295.64999","24.63759","0.24615"
"49356","296.10001","24.67520","0.25003"
"49431","296.54999","24.71269","0.25339"
"49506","297.00000","24.75023","0.25693"
"49581","297.45001","24.78766","0.26108"
"49656","297.89999","24.82509","0.26516"
"49731","298.35001","24.86258","0.26889"
"49806","298.79999","24.90013","0.27251"
"49881","299.25000","24.93767","0.27497"
"49956","299.70001","24.97517","0.27777"
"50031","300.14999","25.01265","0.28025"
"50106","300.60001","25.05014","0.28281"
"50181","301.04999","25.08757","0.28527"
"50256","301.50000","25.12518","0.28729"
"50331","301.95001","25.16260","0.28964"
"50406","302.39999","25.20009","0.29118"
"50481","302.85001","25.23764","0.29237"
"50556","303.29999","25.27513","0.29341"
"50631","303.75000","25.31262","0.29423"
"50706","304.20001","25.35004","0.29521"
"50781","304.64999","25.38765","0.29661"
"50856","305.10001","25.42514","0.29825"
"50931","305.54999","25.46263","0.29975"
"51006","306.00000","25.50011","0.30179"
"51081","306.45001","25.53761","0.30416"
"51156","306.89999","25.57509","0.30675"
"51231","307.35001","25.61264","0.31008"
"51306","307.79999","25.65013","0.31404"
"51381","308.25000","25.68762","0.31835"
"51456","308.70001","25.72510","0.32194"
"51531","309.14999","25.76259","0.32455"
"51606","309.60001","25.80014","0.32680"
"51681","310.04999","25.83769","0.33012"
"51756","310.50000","25.87512","0.33208"
"51831","310.95001","25.91266","0.33580"
"51906","311.39999","25.95015","0.33985"
"51981","311.85001","25.98758","0.34349"
"52056","312.29999","26.02507","0.34628"
"52131","312.75000","26.06268","0.34936"
"52206","313.20001","26.10017","0.35155"
"52281","313.64999","26.13771","0.35420"
"52356","314.10001","26.17514","0.35724"
"52431","314.54999","26.21263","0.36035"
"52506","315.00000","26.25006","0.36466"
"52581","315.45001","26.28760","0.36679"
"52656","315.89999","26.32515","0.37002"
"52731","316.35001","26.36270","0.37213"
"52806","316.79999","26.40013","0.37472"
"52881","317.25000","26.43762","0.37722"
"52956","317.70001","26.47511","0.37947"
"53031","318.14999","26.51265","0.38197"
"53106","318.60001","26.55014","0.38413"
"53181","319.04999","26.58763","0.38639"
"53256","319.50000","26.62512","0.38778"
"53331","319.95001","26.66260","0.38990"
"53406","320.39999","26.70009","0.39189"
"53481","320.85001","26.73764","0.39408"
"53556","321.29999","26.77519","0.39537"
"53631","321.75000","26.81262","0.36969"
"53706","322.20001","26.85016","0.18181"
"53781","322.64999","26.88759","0.18194"
"53856","323.10001","26.92508","0.18668"
"53931","323.54999","26.96263","0.18807"
"54006","324.00000","27.00018","0.18990"
"54081","324.45001","27.03766","0.19301"
"54156","324.89999","27.07515","0.19895"
"54231","325.35001","27.11258","0.20256"
"54306","325.79999","27.15007","0.20503"
"54381","326.25000","27.18762","0.20823"
"54456","326.70001","27.22516","0.21347"
"54531","327.14999","27.26265","0.21769"
"54606","327.60001","27.30014","0.19177"
"54681","328.04999","27.33757","0.05648"
"54756","328.50000","27.37506","0.04528"
"54831","328.95001","27.41261","0.05512"
"54906","329.39999","27.45015","0.05365"
"54981","329.85001","27.48764","0.06041"
"55056","330.29999","27.52513","0.06282"
"55131","330.75000","27.56262","0.06215"
"55206","331.20001","27.60004","0.06408"
"55281","331.64999","27.63765","0.06620"
"55356","332.10001","27.67514","0.06688"
"55431","332.54999","27.71269","0.06783"
"55506","333.00000","27.75018","0.06908"
"55581","333.45001","27.78760","0.07019"
"55656","333.89999","27.82509","0.07049"
"55731","334.35001","27.86258","0.07171"
"55806","334.79999","27.90013","0.07246"
"55881","335.25000","27.93762","0.07369"
"55956","335.70001","27.97516","0.07417"
"56031","336.14999","28.01265","0.07509"
"56106","336.60001","28.05014","0.07607"
"56181","337.04999","28.08763","0.07662"
"56256","337.50000","28.12511","0.07807"
"56331","337.95001","28.16266","0.07904"
"56406","338.39999","28.20009","0.08018"
"56481","338.85001","28.23764","0.08138"
"56556","339.29999","28.27507","0.08257"
"56631","339.75000","28.31262","0.08360"
"56706","340.20001","28.35016","0.08521"
"56781","340.64999","28.38765","0.08646"
"56856","341.10001","28.42514","0.08853"
"56931","341.54999","28.46263","0.08866"
"57006","342.00000","28.50006","0.09033"
"57081","342.45001","28.53761","0.09258"
"57156","342.89999","28.57515","0.09418"
"57231","343.35001","28.61264","0.09390"
"57306","343.79999","28.65013","0.09770"
"57381","344.25000","28.68761","0.10039"
"57456","344.70001","28.72504","0.10374"
"57531","345.14999","28.76259","0.10607"
"57606","345.60001","28.80014","0.10887"
"57681","346.04999","28.83763","0.11191"
"57756","346.50000","28.87518","0.11389"
"57831","346.95001","28.91260","0.11669"
"57906","347.39999","28.95009","0.11831"
"57981","347.85001","28.98758","0.11954"
"58056","348.29999","29.02507","0.12089"
"58131","348.75000","29.06268","0.12361"
"58206","349.20001","29.10022","0.12641"
"58281","349.64999","29.13765","0.12853"
"58356","350.10001","29.17514","0.13020"
"58431","350.54999","29.21257","0.13284"
"58506","351.00000","29.25011","0.13478"
"58581","351.45001","29.28760","0.13745"
"58656","351.89999","29.32515","0.13833"
"58731","352.35001","29.36264","0.14028"
"58806","352.79999","29.40019","0.14242"
"58881","353.25000","29.43762","0.14389"
"58956","353.70001","29.47510","0.14598"
"59031","354.14999","29.51265","0.14829"
"59106","354.60001","29.55014","0.14981"
"59181","355.04999","29.58763","0.15144"
"59256","355.50000","29.62512","0.15371"
"59331","355.95001","29.66261","0.15608"
"59406","356.39999","29.70015","0.15808"
"59481","356.85001","29.73764","0.16045"
"59556","357.29999","29.77513","0.16297"
"59631","357.75000","29.81261","0.16543"
"59706","358.20001","29.85010","0.16760"
"59781","358.64999","29.88754","0.16920"
"59856","359.10001","29.92514","0.17076"
"59931","359.54999","29.96269","0.17342"
"60006","360.00000","30.00018","0.17489"
"60081","360.45001","30.03767","0.17637"
"60156","360.89999","30.07509","0.17858"
"60231","361.35001","30.11252","0.18027"
"60306","361.79999","30.15013","0.18174"
"60381","362.25000","30.18762","0.18325"
"60456","362.70001","30.22516","0.18423"
"60531","363.14999","30.26271","0.18537"
"60606","363.60001","30.30014","0.18692"
"60681","364.04999","30.33757","0.18869"
"60756","364.50000","30.37506","0.19025"
"60831","364.95001","30.41260","0.19193"
"60906","365.39999","30.45015","0.19321"
"60981","365.85001","30.48770","0.19595"
"61056","366.29999","30.52513","0.19789"
"61131","366.75000","30.56256","0.19937"
"61206","367.20001","30.60017","0.20119"
"61281","367.64999","30.63765","0.20352"
"61356","368.10001","30.67520","0.20657"
"61431","368.54999","30.71263","0.21033"
"61506","369.00000","30.75012","0.21357"
"61581","369.45001","30.78761","0.21523"
"61656","369.89999","30.82509","0.21809"
"61731","370.35001","30.86264","0.22050"
"61806","370.79999","30.90013","0.22268"
"61881","371.25000","30.93762","0.22484"
"61956","371.70001","30.97510","0.22767"
"62031","372.14999","31.01259","0.23019"
"62106","372.60001","31.05014","0.03796"
"62181","373.04999","31.08769","0.03968"
"62256","373.50000","31.12518","0.03643"
"62331","373.95001","31.16267","0.03506"
"62406","374.39999","31.20015","0.03526"
"62481","374.85001","31.23758","0.03551"
"62556","375.29999","31.27513","0.03631"
"62631","375.75000","31.31261","0.03838"
"62706","376.20001","31.35016","0.04119"
"62781","376.64999","31.38765","0.04222"
"62856","377.10001","31.42520","0.04289"
"62931","377.54999","31.46263","0.04287"
"63006","378.00000","31.50012","0.04275"
"63081","378.45001","31.53760","0.04343"
"63156","378.89999","31.57515","0.04311"
"63231","379.35001","31.61264","0.04424"
"63306","379.79999","31.65018","0.04520"
"63381","380.25000","31.68761","0.04624"
"63456","380.70001","31.72510","0.04749"
"63531","381.14999","31.76253","0.04838"
"63606","381.60001","31.80014","0.04990"
"63681","382.04999","31.83769","0.05054"
"63756","382.50000","31.87517","0.05055"
"63831","382.95001","31.91260","0.05061"
"63906","383.39999","31.95009","0.05050"
"63981","383.85001","31.98764","0.05133"
"64056","384.29999","32.02519","0.05203"
"64131","384.75000","32.06261","0.05317"
"64206","385.20001","32.10016","0.05340"
"64281","385.64999","32.13765","0.05376"
"64356","386.10001","32.17514","0.05496"
"64431","386.54999","32.21263","0.05572"
"64506","387.00000","32.25017","0.05674"
"64581","387.45001","32.28760","0.05735"
"64656","387.89999","32.32515","0.05820"
"64731","388.35001","32.36264","0.05923"
"64806","388.79999","32.40013","0.05932"
"64881","389.25000","32.43761","0.06010"
"64956","389.70001","32.47510","0.06030"
"65031","390.14999","32.51265","0.06065"
"65106","390.60001","32.55020","0.06065"
"65181","391.04999","32.58768","0.06108"
"65256","391.50000","32.62506","0.06134"
"65331","391.95001","32.66261","0.06167"
"65406","392.39999","32.70015","0.06169"
"65481","392.85001","32.73770","0.06228"
"65556","393.29999","32.77513","0.06311"
"65631","393.75000","32.81261","0.06261"
"65706","394.20001","32.85010","0.06318"
"65781","394.64999","32.88759","0.06425"
"65856","395.10001","32.92514","0.06514"
"65931","395.54999","32.96269","0.06471"
"66006","396.00000","33.00018","0.06501"
"66081","396.45001","33.03760","0.06557"
"66156","396.89999","33.07503","0.06619"
"66231","397.35001","33.11264","0.06704"
"66306","397.79999","33.15007","0.06715"
"66381","398.25000","33.18768","0.06808"
"66456","398.70001","33.22516","0.06813"
"66531","399.14999","33.26271","0.06690"
"66606","399.60001","33.30014","0.06757"
"66681","400.04999","33.33763","0.06800"
"66756","400.50000","33.37511","0.06770"
"66831","400.95001","33.41266","0.06668"
"66906","401.39999","33.45015","0.06713"
"66981","401.85001","33.48764","0.06803"
"67056","402.29999","33.52507","0.06811"
"67131","402.75000","33.56261","0.06875"
"67206","403.20001","33.60016","0.06906"
"67281","403.64999","33.63771","0.06932"
"67356","404.10001","33.67514","0.06959"
"67431","404.54999","33.71262","0.06915"
"67506","405.00000","33.75005","0.06970"
"67581","405.45001","33.78766","0.07030"
"67656","405.89999","33.82515","0.07054"
"67731","406.35001","33.86264","0.07092"
"67806","406.79999","33.90013","0.07120"
"67881","407.25000","33.93761","0.07147"
"67956","407.70001","33.97510","0.07219"
"68031","408.14999","34.01259","0.07235"
"68106","408.60001","34.05014","0.07288"
"68181","409.04999","34.08769","0.07335"
"68256","409.50000","34.12518","0.07353"
"68331","409.95001","34.16266","0.07372"
"68406","410.39999","34.20009","0.07380"
"68481","410.85001","34.23758","0.07449"
"68556","411.29999","34.27513","0.07456"
"68631","411.75000","34.31267","0.07507"
"68706","412.20001","34.35022","0.07413"
"68781","412.64999","34.38765","0.07413"
"68856","413.10001","34.42514","0.07435"
"68931","413.54999","34.46257","0.07465"
"69006","414.00000","34.50011","0.07519"
"69081","414.45001","34.53760","0.07548"
"69156","414.89999","34.57515","0.07582"
"69231","415.35001","34.61264","0.07607"
"69306","415.79999","34.65013","0.07687"
"69381","416.25000","34.68756","0.07683"
"69456","416.70001","34.72511","0.07751"
"69531","417.14999","34.76259","0.07760"
"69606","417.60001","34.80014","0.07835"
"69681","418.04999","34.83768","0.07864"
"69756","418.50000","34.87511","0.07896"
"69831","418.95001","34.91254","0.07963"
"69906","419.39999","34.95009","0.08026"
"69981","419.85001","34.98764","0.08098"
"70056","420.29999","35.02519","0.08168"
"70131","420.75000","35.06261","0.08265"
"70206","421.20001","35.10010","0.08353"
"70281","421.64999","35.13759","0.08427"
"70356","422.10001","35.17514","0.08505"
"70431","422.54999","35.21269","0.08598"
"70506","423.00000","35.25011","0.08444"
"70581","423.45001","35.28766","0.08529"
"70656","423.89999","35.32509","0.08569"
"70731","424.35001","35.36264","0.08559"
"70806","424.79999","35.40007","0.08538"
"70881","425.25000","35.43767","0.08656"
"70956","425.70001","35.47516","0.08711"
"71031","426.14999","35.51271","0.08805"
"71106","426.60001","35.55014","0.08949"
"71181","427.04999","35.58763","0.08950"
"71256","427.50000","35.62511","0.09070"
"71331","427.95001","35.66260","0.09143"
"71406","428.39999","35.70015","0.08967"
"71481","428.85001","35.73770","0.08995"
"71556","429.29999","35.77519","0.09087"
"71631","429.75000","35.81261","0.09083"
"71706","430.20001","35.85011","0.09168"
"71781","430.64999","35.88765","0.09240"
"71856","431.10001","35.92514","0.09323"
"71931","431.54999","35.96268","0.09474"
"72006","432.00000","36.00017","0.09558"
"72081","432.45001","36.03760","0.09664"
"72156","432.89999","36.07509","0.09808"
"72231","433.35001","36.11258","0.09916"
"72306","433.79999","36.15013","0.10058"
"72381","434.25000","36.18761","0.10264"
"72456","434.70001","36.22516","0.10295"
"72531","435.14999","36.26265","0.10258"
"72606","435.60001","36.30008","0.10132"
"72681","436.04999","36.33762","0.10283"
"72756","436.50000","36.37518","0.10388"
"72831","436.95001","36.41261","0.10331"
"72906","437.39999","36.45015","0.10470"
"72981","437.85001","36.48764","0.10645"
"73056","438.29999","36.52507","0.10827"
"73131","438.75000","36.56261","0.11079"
"73206","439.20001","36.60016","0.11283"
"73281","439.64999","36.63759","0.11411"
"73356","440.10001","36.67514","0.11504"
"73431","440.54999","36.71263","0.11656"
"73506","441.00000","36.75006","0.11824"
"73581","441.45001","36.78760","0.11888"
"73656","441.89999","36.82521","0.11976"
"73731","442.35001","36.86264","0.12066"
"73806","442.79999","36.90018","0.12270"
"73881","443.25000","36.93761","0.12221"
"73956","443.70001","36.97511","0.12421"
"74031","444.14999","37.01259","0.12495"
"74106","444.60001","37.05014","0.12699"
"74181","445.04999","37.08768","0.12873"
"74256","445.50000","37.12518","0.13019"
"74331","445.95001","37.16266","0.13045"
"74406","446.39999","37.20009","0.13157"
"74481","446.85001","37.23758","0.13300"
"74556","447.29999","37.27513","0.13377"
"74631","447.75000","37.31261","0.13497"
"74706","448.20001","37.35016","0.13633"
"74781","448.64999","37.38765","0.13716"
"74856","449.10001","37.42508","0.13604"
"74931","449.54999","37.46263","0.13705"
"75006","450.00000","37.50011","0.13770"
"75081","450.45001","37.53766","0.13914"
"75156","450.89999","37.57515","0.14039"
"75231","451.35001","37.61264","0.14210"
"75306","451.79999","37.65013","0.14236"
"75381","452.25000","37.68761","0.14361"
"75456","452.70001","37.72516","0.14378"
"75531","453.14999","37.76265","0.14528"
"75606","453.60001","37.80014","0.14566"
"75681","454.04999","37.83763","0.14641"
"75756","454.50000","37.87506","0.14603"
"75831","454.95001","37.91261","0.14621"
"75906","455.39999","37.95015","0.14507"
"75981","455.85001","37.98764","0.14097"
"76056","456.29999","38.02513","0.14125"
"76131","456.75000","38.06267","0.14072"
"76206","457.20001","38.10011","0.13993"
"76281","457.64999","38.13759","0.13955"
"76356","458.10001","38.17508","0.13950"
"76431","458.54999","38.21269","0.14100"
"76506","459.00000","38.25011","0.13989"
"76581","459.45001","38.28766","0.14113"
"76656","459.89999","38.32515","0.14208"
"76731","460.35001","38.36258","0.14164"
"76806","460.79999","38.40013","0.14345"
"76881","461.25000","38.43768","0.14441"
"76956","461.70001","38.47516","0.14458"
"77031","462.14999","38.51271","0.14494"
"77106","462.60001","38.55008","0.14614"
"77181","463.04999","38.58757","0.14806"
"77256","463.50000","38.62511","0.14962"
"77331","463.95001","38.66260","0.15093"
"77406","464.39999","38.70015","0.15255"
"77481","464.85001","38.73764","0.15117"
"77556","465.29999","38.77513","0.15270"
"77631","465.75000","38.81261","0.15289"
"77706","466.20001","38.85010","0.15326"
"77781","466.64999","38.88759","0.15483"
"77856","467.10001","38.92514","0.15638"
"77931","467.54999","38.96263","0.15707"
"78006","468.00000","39.00018","0.15839"
"78081","468.45001","39.03754","0.15711"
"78156","468.89999","39.07509","0.15874"
"78231","469.35001","39.11264","0.16071"
"78306","469.79999","39.15012","0.16236"
"78381","470.25000","39.18767","0.16344"
"78456","470.70001","39.22510","0.16412"
"78531","471.14999","39.26259","0.16533"
"78606","471.60001","39.30014","0.16665"
"78681","472.04999","39.33763","0.16763"
"78756","472.50000","39.37517","0.16867"
"78831","472.95001","39.41260","0.16924"
"78906","473.39999","39.45015","0.16972"
"78981","473.85001","39.48758","0.17099"
"79056","474.29999","39.52512","0.17325"
"79131","474.75000","39.56262","0.17372"
"79206","475.20001","39.60016","0.17428"
"79281","475.64999","39.63765","0.17457"
"79356","476.10001","39.67514","0.17562"
"79431","476.54999","39.71262","0.16708"
"79506","477.00000","39.75005","0.16425"
"79581","477.45001","39.78760","0.16483"
"79656","477.89999","39.82515","0.16011"
"79731","478.35001","39.86270","0.16244"
"79806","478.79999","39.90019","0.16406"
"79881","479.25000","39.93761","0.16609"
"79956","479.70001","39.97510","0.16791"
"80031","480.14999","40.01265","0.16887"
"80106","480.60001","40.05013","0.17088"
"80181","481.04999","40.08762","0.17336"
"80256","481.50000","40.12518","0.17430"
"80331","481.95001","40.16266","0.17653"
"80406","482.39999","40.20009","0.17764"
"80481","482.85001","40.23758","0.17885"
"80556","483.29999","40.27512","0.17987"
"80631","483.75000","40.31268","0.18091"
"80706","484.20001","40.35010","0.18245"
"80781","484.64999","40.38765","0.18287"
"80856","485.10001","40.42508","0.18392"
"80931","485.54999","40.46263","0.18445"
"81006","486.00000","40.50011","0.18531"
"81081","486.45001","40.53760","0.17213"
"81156","486.89999","40.57515","0.17369"
"81231","487.35001","40.61258","0.17578"
"81306","487.79999","40.65013","0.17778"
"81381","488.25000","40.68761","0.17919"
"81456","488.70001","40.72522","0.18048"
"81531","489.14999","40.76265","0.18106"
"81606","489.60001","40.80014","0.18243"
"81681","490.04999","40.83762","0.18327"
"81756","490.50000","40.87505","0.18460"
"81831","490.95001","40.91266","0.18515"
"81906","491.39999","40.95009","0.18606"
"81981","491.85001","40.98764","0.18772"
"82056","492.29999","41.02519","0.18930"
"82131","492.75000","41.06261","0.19112"
"82206","493.20001","41.10011","0.19248"
"82281","493.64999","41.13759","0.19367"
"82356","494.10001","41.17513","0.19443"
"82431","494.54999","41.21268","0.19585"
"82506","495.00000","41.25017","0.19751"
"82581","495.45001","41.28760","0.19922"
"82656","495.89999","41.32503","0.20043"
"82731","496.35001","41.36264","0.20107"
"82806","496.79999","41.40012","0.20197"
"82881","497.25000","41.43768","0.20336"
"82956","497.70001","41.47516","0.20484"
"83031","498.14999","41.51265","0.20614"
"83106","498.60001","41.55014","0.20827"
"83181","499.04999","41.58757","0.21101"
"83256","499.50000","41.62511","0.21228"
"83331","499.95001","41.66261","0.21249"
"83406","500.39999","41.70009","0.21529"
"83481","500.85001","41.73764","0.21743"
"83556","501.29999","41.77513","0.21919"
"83631","501.75000","41.81267","0.22112"
"83706","502.20001","41.85017","0.22209"
"83781","502.64999","41.88771","0.22387"
"83856","503.10001","41.92514","0.22553"
"83931","503.54999","41.96262","0.22727"
"84006","504.00000","42.00005","0.22846"
"84081","504.45001","42.03760","0.22992"
"84156","504.89999","42.07515","0.23228"
"84231","505.35001","42.11270","0.23396"
"84306","505.79999","42.15013","0.23445"
"84381","506.25000","42.18768","0.23684"
"84456","506.70001","42.22511","0.23851"
"84531","507.14999","42.26259","0.24093"
"84606","507.60001","42.30014","0.24334"
"84681","508.04999","42.33763","0.24498"
"84756","508.50000","42.37511","0.24693"
"84831","508.95001","42.41266","0.24925"
"84906","509.39999","42.45009","0.25108"
"84981","509.85001","42.48758","0.25375"
"85056","510.29999","42.52507","0.25665"
"85131","510.75000","42.56268","0.26027"
"85206","511.20001","42.60016","0.26068"
"85281","511.64999","42.63765","0.26257"
"85356","512.09998","42.67508","0.26595"
"85431","512.54999","42.71256","0.26660"
"85506","513.00000","42.75011","0.26949"
"85581","513.45001","42.78766","0.27141"
"85656","513.90002","42.82515","0.26892"
"85731","514.34998","42.86264","0.27645"
"85806","514.79999","42.90013","0.27716"
"85881","515.25000","42.93761","0.27820"
"85956","515.70001","42.97516","0.27978"
"86031","516.15002","43.01265","0.28050"
"86106","516.59998","43.05014","0.28241"
"86181","517.04999","43.08762","0.28447"
"86256","517.50000","43.12511","0.28125"
"86331","517.95001","43.16266","0.28260"
"86406","518.40002","43.20009","0.28495"
"86481","518.84998","43.23764","0.28600"
"86556","519.29999","43.27512","0.28738"
"86631","519.75000","43.31268","0.28669"
"86706","520.20001","43.35016","0.28837"
"86781","520.65002","43.38759","0.28932"
"86856","521.09998","43.42514","0.29051"
"86931","521.54999","43.46263","0.29156"
"87006","522.00000","43.50018","0.29223"
"87081","522.45001","43.53766","0.29309"
"87156","522.90002","43.57515","0.29403"
"87231","523.34998","43.61258","0.29494"
"87306","523.79999","43.65012","0.29580"
"87381","524.25000","43.68761","0.29597"
"87456","524.70001","43.72516","0.29688"
"87531","525.15002","43.76271","0.29838"
"87606","525.59998","43.80014","0.29895"
"87681","526.04999","43.83756","0.30007"
"87756","526.50000","43.87511","0.30159"
"87831","526.95001","43.91254","0.30394"
"87906","527.40002","43.95015","0.30443"
"87981","527.84998","43.98764","0.30732"
"88056","528.29999","44.02518","0.30861"
"88131","528.75000","44.06261","0.31101"
"88206","529.20001","44.10010","0.31331"
"88281","529.65002","44.13759","0.31625"
"88356","530.09998","44.17514","0.31864"
"88431","530.54999","44.21262","0.32144"
"88506","531.00000","44.25018","0.32411"
"88581","531.45001","44.28760","0.32663"
"88656","531.90002","44.32509","0.32865"
"88731","532.34998","44.36264","0.33022"
"88806","532.79999","44.40018","0.33251"
"88881","533.25000","44.43761","0.33437"
"88956","533.70001","44.47511","0.33717"
"89031","534.15002","44.51259","0.33941"
"89106","534.59998","44.55014","0.34188"
"89181","535.04999","44.58763","0.32477"
"89256","535.50000","44.62511","0.32686"
"89331","535.95001","44.66260","0.07984"
"89406","536.40002","44.70015","0.08854"
"89481","536.84998","44.73764","0.08867"
"89556","537.29999","44.77507","0.14481"
"89631","537.75000","44.81261","0.09597"
"89706","538.20001","44.85022","0.08697"
"89781","538.65002","44.88765","0.08814"
"89856","539.09998","44.92520","0.09090"
"89931","539.54999","44.96262","0.13104"
"90006","540.00000","45.00005","0.01465"
"90081","540.45001","45.03761","0.01440"
"90156","540.90002","45.07515","0.01724"
"90231","541.34998","45.11276","0.02117"
"90306","541.79999","45.15019","0.01559"
"90381","542.25000","45.18761","0.02037"
"90456","542.70001","45.22510","0.01812"
"90531","543.15002","45.26259","0.01664"
"90606","543.59998","45.30013","0.01320"
"90681","544.04999","45.33762","0.01590"
"90756","544.50000","45.37518","0.01745"
"90831","544.95001","45.41266","0.01535"
"90906","545.40002","45.45009","0.01857"
"90981","545.84998","45.48758","0.01848"
"91056","546.29999","45.52513","0.02037"
"91131","546.75000","45.56267","0.01812"
"91206","547.20001","45.60017","0.01985"
"91281","547.65002","45.63765","0.01794"
"91356","548.09998","45.67508","0.01926"
"91431","548.54999","45.71257","0.01792"
"91506","549.00000","45.75018","0.01796"
"91550","549.26398","45.77212","0.02000"