File: Trajectories_together/170108_2Specimen_RawData_1.csv
"","V1","V2","V3"
"1","End date","1/8/2017",""
"2","Specimen label","11DG_Unk2",""
"3","Maximum Load","0.18525","N"
"4","Time","Extension","Load"
"5","(s)","(mm)","(N)"
"6","0.00000","1.72068","-0.00531"
"65","0.35400","1.75022","-0.00455"
"124","0.70800","1.77999","-0.00469"
"183","1.06200","1.80941","-0.00436"
"242","1.41600","1.83895","-0.00452"
"301","1.77000","1.86848","-0.00420"
"360","2.12400","1.89790","-0.00421"
"419","2.47800","1.92744","-0.00477"
"478","2.83200","1.95691","-0.00411"
"537","3.18600","1.98639","-0.00391"
"596","3.54000","2.01592","-0.00419"
"655","3.89400","2.04540","-0.00345"
"714","4.24800","2.07488","-0.00409"
"773","4.60200","2.10447","-0.00408"
"832","4.95600","2.13389","-0.00374"
"891","5.31000","2.16336","-0.00329"
"950","5.66400","2.19290","-0.00396"
"1009","6.01800","2.22244","-0.00341"
"1068","6.37200","2.25185","-0.00316"
"1127","6.72600","2.28145","-0.00344"
"1186","7.08000","2.31087","-0.00310"
"1245","7.43400","2.34040","-0.00341"
"1304","7.78800","2.36994","-0.00348"
"1363","8.14200","2.39941","-0.00388"
"1422","8.49600","2.42889","-0.00290"
"1481","8.85000","2.45843","-0.00338"
"1540","9.20400","2.48790","-0.00317"
"1599","9.55800","2.51738","-0.00350"
"1658","9.91200","2.54691","-0.00279"
"1717","10.26600","2.57633","-0.00323"
"1776","10.62000","2.60593","-0.00292"
"1835","10.97400","2.63546","-0.00281"
"1894","11.32800","2.66494","-0.00322"
"1953","11.68200","2.69442","-0.00269"
"2012","12.03600","2.72395","-0.00263"
"2071","12.39000","2.75337","-0.00271"
"2130","12.74400","2.78296","-0.00312"
"2189","13.09800","2.81238","-0.00319"
"2248","13.45200","2.84180","-0.00255"
"2307","13.80600","2.87145","-0.00247"
"2366","14.16000","2.90093","-0.00284"
"2425","14.51400","2.93040","-0.00309"
"2484","14.86800","2.95994","-0.00293"
"2543","15.22200","2.98948","-0.00296"
"2602","15.57600","3.01883","-0.00349"
"2661","15.93000","3.04837","-0.00298"
"2720","16.28400","3.07797","-0.00292"
"2779","16.63800","3.10738","-0.00319"
"2838","16.99200","3.13698","-0.00267"
"2897","17.34600","3.16645","-0.00304"
"2956","17.70000","3.19581","-0.00348"
"3015","18.05400","3.22547","-0.00295"
"3074","18.40800","3.25488","-0.00323"
"3133","18.76200","3.28436","-0.00338"
"3192","19.11600","3.31395","-0.00293"
"3251","19.47000","3.34337","-0.00287"
"3310","19.82400","3.37285","-0.00330"
"3369","20.17800","3.40244","-0.00281"
"3428","20.53200","3.43192","-0.00291"
"3487","20.88600","3.46140","-0.00283"
"3546","21.24000","3.49099","-0.00218"
"3605","21.59400","3.52041","-0.00311"
"3664","21.94800","3.54994","-0.00259"
"3723","22.30200","3.57942","-0.00295"
"3782","22.65600","3.60890","-0.00288"
"3841","23.01000","3.63837","-0.00212"
"3900","23.36400","3.66791","-0.00314"
"3959","23.71800","3.69738","-0.00272"
"4018","24.07200","3.72686","-0.00264"
"4077","24.42600","3.75640","-0.00253"
"4136","24.78000","3.78587","-0.00224"
"4195","25.13400","3.81541","-0.00188"
"4254","25.48800","3.84489","-0.00245"
"4313","25.84200","3.87442","-0.00259"
"4372","26.19600","3.90384","-0.00207"
"4431","26.55000","3.93349","-0.00252"
"4490","26.90400","3.96285","-0.00178"
"4549","27.25800","3.99245","-0.00207"
"4608","27.61200","4.02198","-0.00162"
"4667","27.96600","4.05134","-0.00165"
"4726","28.32000","4.08093","-0.00227"
"4785","28.67400","4.11041","-0.00186"
"4844","29.02800","4.13983","-0.00204"
"4903","29.38200","4.16942","-0.00099"
"4962","29.73600","4.19890","-0.00136"
"5021","30.09000","4.22838","-0.00158"
"5080","30.44400","4.25797","-0.00156"
"5139","30.79800","4.28739","-0.00155"
"5198","31.15200","4.31686","-0.00170"
"5257","31.50600","4.34646","-0.00168"
"5316","31.86000","4.37588","-0.00136"
"5375","32.21400","4.40535","-0.00176"
"5434","32.56800","4.43495","-0.00161"
"5493","32.92200","4.46442","-0.00097"
"5552","33.27600","4.49390","-0.00147"
"5611","33.63000","4.52344","-0.00100"
"5670","33.98400","4.55297","-0.00099"
"5729","34.33800","4.58239","-0.00083"
"5788","34.69200","4.61193","-0.00063"
"5847","35.04600","4.64140","-0.00102"
"5906","35.40000","4.67088","-0.00095"
"5965","35.75400","4.70041","-0.00101"
"6024","36.10800","4.72989","-0.00086"
"6083","36.46200","4.75943","-0.00067"
"6142","36.81600","4.78896","-0.00088"
"6201","37.17000","4.81838","-0.00120"
"6260","37.52400","4.84791","-0.00022"
"6319","37.87800","4.87745","-0.00085"
"6378","38.23200","4.90687","-0.00083"
"6437","38.58600","4.93640","0.00012"
"6496","38.94000","4.96588","-0.00065"
"6555","39.29400","4.99536","-0.00132"
"6614","39.64800","5.02489","-0.00078"
"6673","40.00200","5.05443","-0.00031"
"6732","40.35600","5.08390","-0.00053"
"6791","40.71000","5.11338","-0.00022"
"6850","41.06400","5.14292","-0.00055"
"6909","41.41800","5.17233","-0.00064"
"6968","41.77200","5.20193","-0.00036"
"7027","42.12600","5.23140","-0.00029"
"7086","42.48000","5.26094","-0.00035"
"7145","42.83400","5.29042","0.00000"
"7204","43.18800","5.31995","0.00025"
"7263","43.54200","5.34931","-0.00092"
"7322","43.89600","5.37897","0.00002"
"7381","44.25000","5.40844","0.00015"
"7440","44.60400","5.43786","-0.00034"
"7499","44.95800","5.46745","-0.00011"
"7558","45.31200","5.49687","0.00044"
"7617","45.66600","5.52641","0.00061"
"7676","46.02000","5.55594","0.00041"
"7735","46.37400","5.58548","0.00059"
"7794","46.72800","5.61483","0.00057"
"7853","47.08200","5.64443","0.00113"
"7912","47.43600","5.67391","0.00065"
"7971","47.79000","5.70338","0.00096"
"8030","48.14400","5.73292","0.00087"
"8089","48.49800","5.76240","0.00106"
"8148","48.85200","5.79193","0.00104"
"8207","49.20600","5.82147","0.00097"
"8266","49.56000","5.85088","0.00016"
"8325","49.91400","5.88036","0.00152"
"8384","50.26800","5.90990","0.00105"
"8443","50.62200","5.93943","0.00115"
"8502","50.97600","5.96891","0.00079"
"8561","51.33000","5.99838","0.00102"
"8620","51.68400","6.02786","0.00126"
"8679","52.03800","6.05740","0.00173"
"8738","52.39200","6.08693","0.00107"
"8797","52.74600","6.11635","0.00186"
"8856","53.10000","6.14595","0.00137"
"8915","53.45400","6.17548","0.00161"
"8974","53.80800","6.20490","0.00195"
"9033","54.16200","6.23443","0.00107"
"9092","54.51600","6.26391","0.00177"
"9151","54.87000","6.29333","0.00161"
"9210","55.22400","6.32298","0.00152"
"9269","55.57800","6.35246","0.00242"
"9328","55.93200","6.38188","0.00197"
"9387","56.28600","6.41141","0.00202"
"9446","56.64000","6.44089","0.00244"
"9505","56.99400","6.47042","0.00305"
"9564","57.34800","6.49990","0.00221"
"9623","57.70200","6.52938","0.00239"
"9682","58.05600","6.55885","0.00276"
"9741","58.41000","6.58845","0.00254"
"9800","58.76400","6.61786","0.00211"
"9859","59.11800","6.64740","0.00258"
"9918","59.47200","6.67694","0.00263"
"9977","59.82600","6.70647","0.00303"
"10036","60.18000","6.73589","0.00260"
"10095","60.53400","6.76543","0.00370"
"10154","60.88800","6.79490","0.00301"
"10213","61.24200","6.82438","0.00289"
"10272","61.59600","6.85397","0.00365"
"10331","61.95000","6.88339","0.00351"
"10390","62.30400","6.91287","0.00315"
"10449","62.65800","6.94240","0.00349"
"10508","63.01200","6.97194","0.00335"
"10567","63.36600","7.00135","0.00413"
"10626","63.72000","7.03095","0.00406"
"10685","64.07400","7.06037","0.00359"
"10744","64.42800","7.08996","0.00370"
"10803","64.78200","7.11938","0.00369"
"10862","65.13600","7.14886","0.00400"
"10921","65.49000","7.17839","0.00393"
"10980","65.84400","7.20793","0.00377"
"11039","66.19800","7.23734","0.00421"
"11098","66.55200","7.26694","0.00437"
"11157","66.90600","7.29648","0.00462"
"11216","67.26000","7.32583","0.00465"
"11275","67.61400","7.35543","0.00459"
"11334","67.96800","7.38496","0.00470"
"11393","68.32200","7.41438","0.00469"
"11452","68.67600","7.44392","0.00499"
"11511","69.03000","7.47345","0.00444"
"11570","69.38400","7.50287","0.00492"
"11629","69.73800","7.53246","0.00514"
"11688","70.09200","7.56194","0.00521"
"11747","70.44600","7.59136","0.00519"
"11806","70.80000","7.62095","0.00579"
"11865","71.15400","7.65043","0.00503"
"11924","71.50800","7.67985","0.00541"
"11983","71.86200","7.70944","0.00533"
"12042","72.21600","7.73892","0.00546"
"12101","72.57000","7.76839","0.00581"
"12160","72.92400","7.79793","0.00582"
"12219","73.27800","7.82747","0.00599"
"12278","73.63200","7.85688","0.00577"
"12337","73.98600","7.88642","0.00618"
"12396","74.34000","7.91596","0.00637"
"12455","74.69400","7.94537","0.00651"
"12514","75.04800","7.97497","0.00649"
"12573","75.40200","8.00438","0.00678"
"12632","75.75600","8.03392","0.00701"
"12691","76.11000","8.06340","0.00713"
"12750","76.46400","8.09293","0.00666"
"12809","76.81800","8.12241","0.00745"
"12868","77.17200","8.15188","0.00642"
"12927","77.52600","8.18142","0.00691"
"12986","77.88000","8.21090","0.00688"
"13045","78.23400","8.24043","0.00758"
"13104","78.58800","8.26985","0.00741"
"13163","78.94200","8.29945","0.00763"
"13222","79.29600","8.32892","0.00714"
"13281","79.65000","8.35840","0.00728"
"13340","80.00400","8.38787","0.00754"
"13399","80.35800","8.41747","0.00772"
"13458","80.71200","8.44689","0.00849"
"13517","81.06600","8.47648","0.00810"
"13576","81.42000","8.50590","0.00848"
"13635","81.77400","8.53531","0.00834"
"13694","82.12800","8.56497","0.00837"
"13753","82.48200","8.59445","0.00586"
"13812","82.83600","8.62386","0.00636"
"13871","83.19000","8.65340","0.00626"
"13930","83.54400","8.68287","0.00686"
"13989","83.89800","8.71235","0.00692"
"14048","84.25200","8.74189","0.00679"
"14107","84.60600","8.77142","0.00754"
"14166","84.96000","8.80090","0.00712"
"14225","85.31400","8.83044","0.00632"
"14284","85.66800","8.85997","0.00776"
"14343","86.02200","8.88939","0.00775"
"14402","86.37600","8.91892","0.00713"
"14461","86.73000","8.94840","0.00757"
"14520","87.08400","8.97788","0.00793"
"14579","87.43800","9.00741","0.00810"
"14638","87.79200","9.03689","0.00759"
"14697","88.14600","9.06643","0.00881"
"14756","88.50000","9.09596","0.00760"
"14815","88.85400","9.12538","0.00812"
"14874","89.20800","9.15485","0.00796"
"14933","89.56200","9.18439","0.00701"
"14992","89.91600","9.21387","0.00713"
"15051","90.27000","9.24346","0.00707"
"15110","90.62400","9.27288","0.00807"
"15169","90.97800","9.30241","0.00799"
"15228","91.33200","9.33189","0.00747"
"15287","91.68600","9.36149","0.00723"
"15346","92.04000","9.39090","0.00820"
"15405","92.39400","9.42044","0.00862"
"15464","92.74800","9.44991","0.00752"
"15523","93.10200","9.47939","0.00858"
"15582","93.45600","9.50893","0.00816"
"15641","93.81000","9.53846","0.00885"
"15700","94.16400","9.56788","0.00804"
"15759","94.51800","9.59736","0.00868"
"15818","94.87200","9.62695","0.00859"
"15877","95.22600","9.65631","0.00885"
"15936","95.58000","9.68596","0.00903"
"15995","95.93400","9.71544","0.00923"
"16054","96.28800","9.74486","0.00900"
"16113","96.64200","9.77445","0.00968"
"16172","96.99600","9.80393","0.00936"
"16231","97.35000","9.83335","0.00889"
"16290","97.70400","9.86294","0.01014"
"16349","98.05800","9.89248","0.00929"
"16408","98.41200","9.92189","0.00977"
"16467","98.76600","9.95143","0.00833"
"16526","99.12000","9.98091","0.00805"
"16585","99.47400","10.01038","0.00878"
"16644","99.82800","10.03998","0.00830"
"16703","100.18200","10.06945","0.00883"
"16762","100.53600","10.09887","0.00854"
"16821","100.89000","10.12847","0.00931"
"16880","101.24400","10.15788","0.00915"
"16939","101.59800","10.18736","0.00884"
"16998","101.95200","10.21690","0.00904"
"17057","102.30600","10.24643","0.00945"
"17116","102.66000","10.27579","0.00952"
"17175","103.01400","10.30544","0.00919"
"17234","103.36800","10.33492","0.00862"
"17293","103.72200","10.36440","0.00866"
"17352","104.07600","10.39393","0.00944"
"17411","104.43000","10.42335","0.00946"
"17470","104.78400","10.45294","0.00963"
"17529","105.13800","10.48242","0.00999"
"17588","105.49200","10.51190","0.00970"
"17647","105.84600","10.54137","0.00984"
"17706","106.20000","10.57097","0.01073"
"17765","106.55400","10.60032","0.01039"
"17824","106.90800","10.62998","0.01070"
"17883","107.26200","10.65934","0.01049"
"17942","107.61600","10.68887","0.01130"
"18001","107.97000","10.71841","0.01070"
"18060","108.32400","10.74795","0.01061"
"18119","108.67800","10.77736","0.01106"
"18178","109.03200","10.80690","0.01112"
"18237","109.38600","10.83643","0.01120"
"18296","109.74000","10.86591","0.01150"
"18355","110.09400","10.89539","0.01154"
"18414","110.44800","10.92486","0.01146"
"18473","110.80200","10.95440","0.01129"
"18532","111.15600","10.98394","0.01164"
"18591","111.51000","11.01347","0.01202"
"18650","111.86400","11.04289","0.01101"
"18709","112.21800","11.07242","0.00947"
"18768","112.57200","11.10190","0.00986"
"18827","112.92600","11.13144","0.01011"
"18886","113.28000","11.16097","0.00798"
"18945","113.63400","11.19045","0.00920"
"19004","113.98800","11.21992","0.00864"
"19063","114.34200","11.24940","0.00856"
"19122","114.69600","11.27882","0.00868"
"19181","115.05000","11.30835","0.00901"
"19240","115.40400","11.33795","0.00863"
"19299","115.75800","11.36742","0.00881"
"19358","116.11200","11.39690","0.00945"
"19417","116.46600","11.42638","0.00937"
"19476","116.82000","11.45585","0.00951"
"19535","117.17400","11.48545","0.00971"
"19594","117.52800","11.51499","0.00946"
"19653","117.88200","11.54440","0.00936"
"19712","118.23600","11.57394","0.00989"
"19771","118.59000","11.60341","0.00979"
"19830","118.94400","11.63295","0.01011"
"19889","119.29800","11.66243","0.01026"
"19948","119.65200","11.69190","0.01033"
"20007","120.00600","11.72138","0.01084"
"20066","120.36000","11.75092","0.01019"
"20125","120.71400","11.78045","0.01065"
"20184","121.06800","11.80981","0.01026"
"20243","121.42200","11.83946","0.01114"
"20302","121.77600","11.86894","0.01070"
"20361","122.13000","11.89836","0.01081"
"20420","122.48400","11.92795","0.01112"
"20479","122.83800","11.95743","0.01138"
"20538","123.19200","11.98684","0.01139"
"20597","123.54600","12.01644","0.01128"
"20656","123.90000","12.04592","0.01163"
"20715","124.25400","12.07539","0.01169"
"20774","124.60800","12.10493","0.01188"
"20833","124.96200","12.13441","0.01231"
"20892","125.31600","12.16388","0.01218"
"20951","125.67000","12.19342","0.01218"
"21010","126.02400","12.22289","0.01209"
"21069","126.37800","12.25237","0.01261"
"21128","126.73200","12.28197","0.01217"
"21187","127.08600","12.31138","0.01259"
"21246","127.44000","12.34086","0.01279"
"21305","127.79400","12.37039","0.01268"
"21364","128.14800","12.39993","0.01301"
"21423","128.50200","12.42935","0.01211"
"21482","128.85600","12.45894","0.01266"
"21541","129.21000","12.48842","0.01290"
"21600","129.56400","12.51790","0.01291"
"21659","129.91800","12.54743","0.01305"
"21718","130.27200","12.57691","0.01333"
"21777","130.62600","12.60638","0.01326"
"21836","130.98000","12.63592","0.01310"
"21895","131.33400","12.66534","0.01271"
"21954","131.68800","12.69487","0.01334"
"22013","132.04200","12.72441","0.01371"
"22072","132.39600","12.75389","0.01374"
"22131","132.75000","12.78342","0.01340"
"22190","133.10400","12.81290","0.01380"
"22249","133.45800","12.84237","0.01419"
"22308","133.81200","12.87191","0.01414"
"22367","134.16600","12.90145","0.01394"
"22426","134.52000","12.93086","0.01427"
"22485","134.87400","12.96046","0.01412"
"22544","135.22800","12.98993","0.01484"
"22603","135.58200","13.01941","0.01486"
"22662","135.93600","13.04889","0.01442"
"22721","136.29000","13.07842","0.01457"
"22780","136.64400","13.10790","0.01455"
"22839","136.99800","13.13744","0.01465"
"22898","137.35200","13.16691","0.01511"
"22957","137.70600","13.19633","0.01519"
"23016","138.06000","13.22592","0.01516"
"23075","138.41400","13.25546","0.01549"
"23134","138.76800","13.28487","0.01510"
"23193","139.12200","13.31441","0.01569"
"23252","139.47600","13.34395","0.01545"
"23311","139.83000","13.37336","0.01548"
"23370","140.18400","13.40296","0.01553"
"23429","140.53800","13.43238","0.01563"
"23488","140.89200","13.46185","0.01599"
"23547","141.24600","13.49145","0.01605"
"23606","141.60000","13.52092","0.01609"
"23665","141.95400","13.55040","0.01609"
"23724","142.30800","13.57988","0.01627"
"23783","142.66200","13.60941","0.01637"
"23842","143.01600","13.63889","0.01629"
"23901","143.37000","13.66843","0.01645"
"23960","143.72400","13.69784","0.01642"
"24019","144.07800","13.72744","0.01666"
"24078","144.43200","13.75692","0.01673"
"24137","144.78600","13.78645","0.01689"
"24196","145.14000","13.81593","0.01689"
"24255","145.49400","13.84540","0.01696"
"24314","145.84800","13.87488","0.01725"
"24373","146.20200","13.90447","0.01719"
"24432","146.55600","13.93395","0.01713"
"24491","146.91000","13.96337","0.01727"
"24550","147.26400","13.99296","0.01720"
"24609","147.61800","14.02244","0.01742"
"24668","147.97200","14.05186","0.01741"
"24727","148.32600","14.08139","0.01742"
"24786","148.68000","14.11093","0.01773"
"24845","149.03400","14.14035","0.01751"
"24904","149.38800","14.17000","0.01792"
"24963","149.74200","14.19942","0.01795"
"25022","150.09600","14.22889","0.01796"
"25081","150.45000","14.25843","0.01781"
"25140","150.80400","14.28796","0.01781"
"25199","151.15800","14.31732","0.01827"
"25258","151.51200","14.34692","0.01789"
"25317","151.86600","14.37633","0.01807"
"25376","152.22000","14.40587","0.01831"
"25435","152.57400","14.43541","0.01844"
"25494","152.92800","14.46494","0.01837"
"25553","153.28200","14.49436","0.01829"
"25612","153.63600","14.52389","0.01856"
"25671","153.99000","14.55343","0.01874"
"25730","154.34400","14.58291","0.01819"
"25789","154.69800","14.61244","0.01882"
"25848","155.05200","14.64192","0.01898"
"25907","155.40600","14.67139","0.01930"
"25966","155.76000","14.70093","0.01906"
"26025","156.11400","14.73041","0.01934"
"26084","156.46800","14.75988","0.01923"
"26143","156.82200","14.78948","0.01928"
"26202","157.17600","14.81890","0.01920"
"26261","157.53000","14.84843","0.01942"
"26320","157.88400","14.87791","0.01985"
"26379","158.23800","14.90738","0.01929"
"26438","158.59200","14.93686","0.01974"
"26497","158.94600","14.96640","0.01970"
"26556","159.30000","14.99593","0.01992"
"26615","159.65400","15.02541","0.01986"
"26674","160.00800","15.05501","0.02022"
"26733","160.36200","15.08436","0.02015"
"26792","160.71600","15.11396","0.02030"
"26851","161.07000","15.14343","0.01999"
"26910","161.42400","15.17291","0.02039"
"26969","161.77800","15.20239","0.02095"
"27028","162.13200","15.23192","0.02030"
"27087","162.48600","15.26140","0.02106"
"27146","162.84000","15.29093","0.02096"
"27205","163.19400","15.32047","0.02143"
"27264","163.54800","15.34989","0.02073"
"27323","163.90200","15.37942","0.02120"
"27382","164.25600","15.40896","0.02162"
"27441","164.61000","15.43838","0.02184"
"27500","164.96400","15.46791","0.02178"
"27559","165.31800","15.49745","0.02184"
"27618","165.67200","15.52692","0.02216"
"27677","166.02600","15.55646","0.02240"
"27736","166.38000","15.58588","0.02237"
"27795","166.73400","15.61541","0.02295"
"27854","167.08800","15.64495","0.02310"
"27913","167.44200","15.67442","0.02316"
"27972","167.79600","15.70384","0.02318"
"28031","168.15000","15.73344","0.02362"
"28090","168.50400","15.76291","0.02374"
"28149","168.85800","15.79245","0.02409"
"28208","169.21200","15.82192","0.02402"
"28267","169.56600","15.85140","0.02443"
"28326","169.92000","15.88088","0.02445"
"28385","170.27400","15.91041","0.02535"
"28444","170.62800","15.93995","0.02570"
"28503","170.98200","15.96937","0.02585"
"28562","171.33600","15.99890","0.02588"
"28621","171.69000","16.02838","0.02558"
"28680","172.04400","16.05791","0.02730"
"28739","172.39800","16.08745","0.02722"
"28798","172.75200","16.11687","0.02749"
"28857","173.10600","16.14640","0.02764"
"28916","173.46000","16.17594","0.02800"
"28975","173.81400","16.20535","0.02843"
"29034","174.16800","16.23489","0.02838"
"29093","174.52200","16.26449","0.02965"
"29152","174.87600","16.29384","0.02930"
"29211","175.23000","16.32344","0.02771"
"29270","175.58400","16.35292","0.02901"
"29329","175.93800","16.38239","0.02912"
"29388","176.29200","16.41193","0.02971"
"29447","176.64600","16.44146","0.03006"
"29506","177.00000","16.47082","0.03036"
"29565","177.35400","16.50042","0.03085"
"29624","177.70800","16.52989","0.03159"
"29683","178.06200","16.55937","0.03134"
"29742","178.41600","16.58890","0.03180"
"29801","178.77000","16.61844","0.03346"
"29860","179.12400","16.64786","0.03302"
"29919","179.47800","16.67745","0.03346"
"29978","179.83200","16.70693","0.03317"
"30037","180.18600","16.73635","0.03486"
"30096","180.54000","16.76588","0.03520"
"30155","180.89400","16.79542","0.03413"
"30214","181.24800","16.82483","0.03536"
"30273","181.60200","16.85443","0.03610"
"30332","181.95600","16.88391","0.03606"
"30391","182.31000","16.91338","0.03655"
"30450","182.66400","16.94298","0.03266"
"30509","183.01800","16.97239","0.03244"
"30568","183.37200","17.00187","0.03275"
"30627","183.72600","17.03135","0.03375"
"30686","184.08000","17.06088","0.03430"
"30745","184.43400","17.09042","0.03478"
"30804","184.78800","17.11996","0.03592"
"30863","185.14200","17.14937","0.03617"
"30922","185.49600","17.17891","0.03659"
"30981","185.85000","17.20844","0.03732"
"31040","186.20400","17.23780","0.03777"
"31099","186.55800","17.26740","0.03876"
"31158","186.91200","17.29693","0.03875"
"31217","187.26600","17.32641","0.03933"
"31276","187.62000","17.35588","0.03958"
"31335","187.97400","17.38548","0.03987"
"31394","188.32800","17.41490","0.04071"
"31453","188.68200","17.44443","0.04072"
"31512","189.03600","17.47397","0.04093"
"31571","189.39000","17.50333","0.04176"
"31630","189.74400","17.53292","0.04214"
"31689","190.09800","17.56246","0.04272"
"31748","190.45200","17.59188","0.04298"
"31807","190.80600","17.62141","0.04292"
"31866","191.16000","17.65095","0.04374"
"31925","191.51400","17.68036","0.04404"
"31984","191.86800","17.70996","0.04460"
"32043","192.22200","17.73944","0.04414"
"32102","192.57600","17.76891","0.04493"
"32161","192.93000","17.79845","0.04526"
"32220","193.28400","17.82792","0.04562"
"32279","193.63800","17.85740","0.04639"
"32338","193.99200","17.88693","0.04618"
"32397","194.34600","17.91641","0.04659"
"32456","194.70000","17.94589","0.04709"
"32515","195.05400","17.97536","0.04702"
"32574","195.40800","18.00490","0.04724"
"32633","195.76200","18.03444","0.01802"
"32692","196.11600","18.06391","0.01919"
"32751","196.47000","18.09339","0.01881"
"32810","196.82400","18.12287","0.01911"
"32869","197.17800","18.15240","0.01896"
"32928","197.53200","18.18188","0.01942"
"32987","197.88600","18.21141","0.01977"
"33046","198.24000","18.24089","0.01957"
"33105","198.59400","18.27043","0.02006"
"33164","198.94800","18.29990","0.02028"
"33223","199.30200","18.32950","0.02012"
"33282","199.65600","18.35885","0.02033"
"33341","200.01000","18.38845","0.02036"
"33400","200.36400","18.41793","0.02037"
"33459","200.71800","18.44734","0.02119"
"33518","201.07200","18.47694","0.02095"
"33577","201.42600","18.50641","0.02084"
"33636","201.78000","18.53589","0.02144"
"33695","202.13400","18.56543","0.02159"
"33754","202.48800","18.59496","0.02217"
"33813","202.84200","18.62438","0.02215"
"33872","203.19600","18.65398","0.02276"
"33931","203.55000","18.68345","0.02303"
"33990","203.90400","18.71293","0.02209"
"34049","204.25800","18.74240","0.02156"
"34108","204.61200","18.77188","0.02172"
"34167","204.96600","18.80136","0.02193"
"34226","205.32000","18.83095","0.02191"
"34285","205.67400","18.86043","0.02206"
"34344","206.02800","18.88985","0.02287"
"34403","206.38200","18.91944","0.02258"
"34462","206.73600","18.94892","0.02332"
"34521","207.09000","18.97840","0.02346"
"34580","207.44400","19.00793","0.02441"
"34639","207.79800","19.03747","0.02493"
"34698","208.15200","19.06688","0.02532"
"34757","208.50600","19.09648","0.02245"
"34816","208.86000","19.12589","0.02160"
"34875","209.21400","19.15537","0.00696"
"34934","209.56800","19.18491","0.00581"
"34993","209.92200","19.21438","0.00625"
"35052","210.27600","19.24392","0.00536"
"35111","210.63000","19.27345","0.00511"
"35170","210.98400","19.30287","0.00489"
"35229","211.33800","19.33241","0.00524"
"35288","211.69200","19.36194","0.00643"
"35347","212.04600","19.39136","0.00460"
"35406","212.40000","19.42090","0.00479"
"35465","212.75400","19.45043","0.00418"
"35524","213.10800","19.47991","0.00074"
"35583","213.46200","19.50938","-0.00057"
"35642","213.81600","19.53892","0.00052"
"35701","214.17000","19.56840","0.00007"
"35760","214.52400","19.59799","0.00050"
"35819","214.87800","19.62741","0.00062"
"35878","215.23200","19.65689","0.00007"
"35937","215.58600","19.68636","-0.00026"
"35996","215.94000","19.71596","-0.00005"
"36055","216.29400","19.74531","-0.00033"
"36114","216.64800","19.77497","-0.00013"
"36173","217.00200","19.80445","0.00003"
"36232","217.35600","19.83386","-0.00064"
"36291","217.71000","19.86340","0.00020"
"36350","218.06400","19.89288","0.00010"
"36409","218.41800","19.92235","-0.00064"
"36468","218.77200","19.95195","0.00026"
"36527","219.12600","19.98142","0.00042"
"36586","219.48000","20.01090","0.00000"
"36645","219.83400","20.04043","0.00010"
"36704","220.18800","20.06991","0.00049"
"36763","220.54200","20.09939","0.00115"
"36822","220.89600","20.12893","0.00001"
"36881","221.25000","20.15846","0.00065"
"36940","221.60400","20.18788","0.00005"
"36999","221.95800","20.21741","-0.00013"
"37058","222.31200","20.24689","0.00016"
"37117","222.66600","20.27636","0.00019"
"37176","223.02000","20.30590","0.00007"
"37235","223.37400","20.33544","0.00090"
"37294","223.72800","20.36491","0.00079"
"37353","224.08200","20.39439","0.00022"
"37412","224.43600","20.42393","0.00025"
"37471","224.79000","20.45334","0.00093"
"37530","225.14400","20.48293","0.00043"
"37589","225.49800","20.51235","0.00089"
"37648","225.85200","20.54195","0.00083"
"37707","226.20600","20.57143","0.00058"
"37766","226.56000","20.60090","0.00040"
"37825","226.91400","20.63044","0.00053"
"37884","227.26800","20.65991","0.00067"
"37943","227.62200","20.68939","0.00074"
"38002","227.97600","20.71893","0.00065"
"38061","228.33000","20.74846","0.00079"
"38120","228.68400","20.77782","0.00032"
"38179","229.03800","20.80742","0.00058"
"38238","229.39200","20.83689","0.00116"
"38297","229.74600","20.86643","0.00102"
"38356","230.10000","20.89590","0.00129"
"38415","230.45400","20.92544","0.00134"
"38474","230.80800","20.95492","0.00135"
"38533","231.16200","20.98445","0.00119"
"38592","231.51600","21.01387","0.00123"
"38651","231.87000","21.04340","0.00125"
"38710","232.22400","21.07294","0.00198"
"38769","232.57800","21.10242","0.00177"
"38828","232.93200","21.13183","0.00221"
"38887","233.28600","21.16143","0.00171"
"38946","233.64000","21.19091","0.00168"
"39005","233.99400","21.22038","0.00221"
"39064","234.34800","21.24992","0.00257"
"39123","234.70200","21.27939","0.00235"
"39182","235.05600","21.30887","0.00271"
"39241","235.41000","21.33841","0.00227"
"39300","235.76400","21.36794","0.00192"
"39359","236.11800","21.39736","0.00248"
"39418","236.47200","21.42696","0.00240"
"39477","236.82600","21.45643","0.00255"
"39536","237.18000","21.48585","0.00299"
"39595","237.53400","21.51538","0.00258"
"39654","237.88800","21.54486","0.00270"
"39713","238.24200","21.57440","0.00277"
"39772","238.59600","21.60393","0.00331"
"39831","238.95000","21.63341","0.00315"
"39890","239.30400","21.66288","0.00367"
"39949","239.65800","21.69242","0.00298"
"40008","240.01200","21.72190","0.00320"
"40067","240.36600","21.75149","0.00317"
"40126","240.72000","21.78091","0.00381"
"40185","241.07400","21.81038","0.00246"
"40244","241.42800","21.83986","0.00262"
"40303","241.78200","21.86946","0.00278"
"40362","242.13600","21.89887","0.00220"
"40421","242.49000","21.92841","0.00235"
"40480","242.84400","21.95794","0.00237"
"40539","243.19800","21.98736","0.00234"
"40598","243.55200","22.01690","0.00273"
"40657","243.90600","22.04637","0.00181"
"40716","244.26000","22.07585","0.00204"
"40775","244.61400","22.10545","0.00268"
"40834","244.96800","22.13492","0.00271"
"40893","245.32200","22.16434","0.00210"
"40952","245.67600","22.19394","0.00201"
"41011","246.03000","22.22341","0.00331"
"41070","246.38400","22.25289","0.00271"
"41129","246.73800","22.28242","0.00256"
"41188","247.09200","22.31196","0.00302"
"41247","247.44600","22.34138","0.00279"
"41306","247.80000","22.37091","0.00325"
"41365","248.15400","22.40045","0.00358"
"41424","248.50800","22.42992","0.00336"
"41483","248.86200","22.45940","0.00340"
"41542","249.21600","22.48894","0.00348"
"41601","249.57000","22.51841","0.00431"
"41660","249.92400","22.54795","0.00423"
"41719","250.27800","22.57742","0.00471"
"41778","250.63200","22.60684","0.00398"
"41837","250.98600","22.63644","0.00356"
"41896","251.34000","22.66586","0.00348"
"41955","251.69400","22.69545","0.00372"
"42014","252.04800","22.72492","0.00307"
"42073","252.40200","22.75440","0.00366"
"42132","252.75600","22.78388","0.00378"
"42191","253.11000","22.81342","0.00405"
"42250","253.46400","22.84289","0.00336"
"42309","253.81800","22.87243","0.00413"
"42368","254.17200","22.90190","0.00386"
"42427","254.52600","22.93132","0.00426"
"42486","254.88000","22.96092","0.00442"
"42545","255.23400","22.99039","0.00449"
"42604","255.58800","23.01987","0.00477"
"42663","255.94200","23.04940","0.00505"
"42722","256.29600","23.07900","0.00513"
"42781","256.65000","23.10836","0.00514"
"42840","257.00400","23.13795","0.00476"
"42899","257.35800","23.16743","0.00513"
"42958","257.71200","23.19684","0.00563"
"43017","258.06600","23.22644","0.00530"
"43076","258.42000","23.25597","0.00511"
"43135","258.77400","23.28533","0.00575"
"43194","259.12800","23.31493","0.00547"
"43253","259.48200","23.34447","0.00605"
"43312","259.83600","23.37388","0.00639"
"43371","260.19000","23.40342","0.00658"
"43430","260.54400","23.43283","0.00653"
"43489","260.89800","23.46243","0.00635"
"43548","261.25200","23.49196","0.00632"
"43607","261.60600","23.52138","0.00671"
"43666","261.96000","23.55086","0.00712"
"43725","262.31400","23.58045","0.00662"
"43784","262.66800","23.60987","0.00698"
"43843","263.02200","23.63941","0.00782"
"43902","263.37600","23.66894","0.00743"
"43961","263.73000","23.69842","0.00685"
"44020","264.08400","23.72789","0.00689"
"44079","264.43800","23.75743","0.00750"
"44138","264.79200","23.78691","0.00682"
"44197","265.14600","23.81639","0.00759"
"44256","265.50000","23.84592","0.00767"
"44315","265.85400","23.87539","0.00676"
"44374","266.20800","23.90493","0.00694"
"44433","266.56200","23.93441","0.00723"
"44492","266.91600","23.96382","0.00757"
"44551","267.27000","23.99342","0.00752"
"44610","267.62400","24.02295","0.00726"
"44669","267.97800","24.05231","0.00660"
"44728","268.33200","24.08197","0.00705"
"44787","268.68600","24.11145","0.00732"
"44846","269.04000","24.14092","0.00736"
"44905","269.39400","24.17040","0.00562"
"44964","269.74800","24.19993","0.00432"
"45023","270.10200","24.22935","0.00399"
"45082","270.45600","24.25895","0.00420"
"45141","270.81000","24.28842","0.00459"
"45200","271.16400","24.31790","0.00461"
"45259","271.51800","24.34749","0.00435"
"45318","271.87200","24.37691","0.00499"
"45377","272.22600","24.40644","0.00475"
"45436","272.58000","24.43592","0.00515"
"45495","272.93400","24.46540","0.00570"
"45554","273.28800","24.49487","0.00602"
"45613","273.64200","24.52447","0.00602"
"45672","273.99600","24.55389","0.00641"
"45731","274.35000","24.58336","0.00694"
"45790","274.70400","24.61296","0.00681"
"45849","275.05800","24.64243","0.00665"
"45908","275.41200","24.67185","0.00726"
"45967","275.76600","24.70139","0.00768"
"46026","276.12000","24.73092","0.00727"
"46085","276.47400","24.76034","0.00686"
"46144","276.82800","24.79000","0.00723"
"46203","277.18200","24.81935","0.00714"
"46262","277.53600","24.84889","0.00727"
"46321","277.89000","24.87842","0.00778"
"46380","278.24400","24.90790","0.00763"
"46439","278.59800","24.93744","0.00756"
"46498","278.95200","24.96697","0.00858"
"46557","279.30600","24.99633","0.00799"
"46616","279.66000","25.02592","0.00883"
"46675","280.01400","25.05540","0.00927"
"46734","280.36800","25.08482","0.00932"
"46793","280.72200","25.11442","0.00924"
"46852","281.07600","25.14389","0.00920"
"46911","281.43000","25.17337","0.00604"
"46970","281.78400","25.20290","0.00643"
"47029","282.13800","25.23244","0.00718"
"47088","282.49200","25.26185","0.00687"
"47147","282.84600","25.29145","0.00746"
"47206","283.20000","25.32093","0.00723"
"47265","283.55400","25.35040","0.00766"
"47324","283.90800","25.37994","0.00757"
"47383","284.26200","25.40948","0.00685"
"47442","284.61600","25.43883","0.00790"
"47501","284.97000","25.46849","0.00742"
"47560","285.32400","25.49791","0.00774"
"47619","285.67800","25.52738","0.00861"
"47678","286.03200","25.55692","0.00869"
"47737","286.38600","25.58639","0.00887"
"47796","286.74000","25.61587","0.00889"
"47855","287.09400","25.64547","0.00903"
"47914","287.44800","25.67488","0.00885"
"47973","287.80200","25.70436","0.00866"
"48032","288.15600","25.73395","0.00894"
"48091","288.51000","25.76337","0.00911"
"48150","288.86400","25.79290","0.00911"
"48209","289.21800","25.82238","0.00870"
"48268","289.57200","25.85192","0.00944"
"48327","289.92600","25.88145","0.00944"
"48386","290.28000","25.91093","0.00916"
"48445","290.63400","25.94035","0.00975"
"48504","290.98800","25.96988","0.01012"
"48563","291.34200","25.99942","0.01018"
"48622","291.69600","26.02889","0.01088"
"48681","292.05000","26.05843","0.01099"
"48740","292.40400","26.08791","0.01058"
"48799","292.75800","26.11738","0.01121"
"48858","293.11200","26.14686","0.01092"
"48917","293.46600","26.17646","0.01109"
"48976","293.82000","26.20587","0.01187"
"49035","294.17400","26.23541","0.01217"
"49094","294.52800","26.26495","0.01190"
"49153","294.88200","26.29442","0.01203"
"49212","295.23600","26.32390","0.01048"
"49271","295.59000","26.35343","0.01120"
"49330","295.94400","26.38291","0.01119"
"49389","296.29800","26.41245","0.01145"
"49448","296.65200","26.44186","0.01198"
"49507","297.00600","26.47134","0.01221"
"49566","297.36000","26.50093","0.01290"
"49625","297.71400","26.53041","0.01333"
"49684","298.06800","26.55995","0.01313"
"49743","298.42200","26.58942","0.01336"
"49802","298.77600","26.61890","0.01354"
"49861","299.13000","26.64838","0.01403"
"49920","299.48400","26.67791","0.01405"
"49979","299.83800","26.70739","0.01446"
"50038","300.19200","26.73692","0.01428"
"50097","300.54600","26.76640","0.01451"
"50156","300.90000","26.79594","0.01500"
"50215","301.25400","26.82535","0.01478"
"50274","301.60800","26.85489","0.01505"
"50333","301.96200","26.88442","0.01547"
"50392","302.31600","26.91390","0.01535"
"50451","302.67000","26.94344","0.01525"
"50510","303.02400","26.97291","0.01533"
"50569","303.37800","27.00239","0.01545"
"50628","303.73200","27.03193","0.01539"
"50687","304.08600","27.06140","0.01550"
"50746","304.44000","27.09088","0.01557"
"50805","304.79400","27.12047","0.01607"
"50864","305.14800","27.14983","0.01598"
"50923","305.50200","27.17942","0.01655"
"50982","305.85600","27.20884","0.01670"
"51041","306.21000","27.23838","0.01721"
"51100","306.56400","27.26791","0.01717"
"51159","306.91800","27.29739","0.01730"
"51218","307.27200","27.32687","0.01737"
"51277","307.62600","27.35640","0.01790"
"51336","307.98000","27.38594","0.01790"
"51395","308.33400","27.41535","0.01812"
"51454","308.68800","27.44489","0.01823"
"51513","309.04200","27.47443","0.01861"
"51572","309.39600","27.50390","0.01849"
"51631","309.75000","27.53338","0.01888"
"51690","310.10400","27.56292","0.01883"
"51749","310.45800","27.59239","0.01921"
"51808","310.81200","27.62193","0.01943"
"51867","311.16600","27.65146","0.01939"
"51926","311.52000","27.68088","0.01983"
"51985","311.87400","27.71048","0.02033"
"52044","312.22800","27.73995","0.02010"
"52103","312.58200","27.76937","0.02050"
"52162","312.93600","27.79896","0.02137"
"52221","313.29000","27.82844","0.02125"
"52280","313.64400","27.85792","0.01951"
"52339","313.99800","27.88745","0.02014"
"52398","314.35200","27.91693","0.02011"
"52457","314.70600","27.94635","0.02144"
"52516","315.06000","27.97594","0.02123"
"52575","315.41400","28.00548","0.02142"
"52634","315.76800","28.03489","0.02198"
"52693","316.12200","28.06443","0.02293"
"52752","316.47600","28.09385","0.02323"
"52811","316.83000","28.12338","0.02343"
"52870","317.18400","28.15292","0.02453"
"52929","317.53800","28.18240","0.02443"
"52988","317.89200","28.21187","0.02623"
"53047","318.24600","28.24141","0.02633"
"53106","318.60000","28.27088","0.02776"
"53165","318.95400","28.30042","0.02853"
"53224","319.30800","28.32996","0.02959"
"53283","319.66200","28.35931","0.02932"
"53342","320.01600","28.38891","0.03096"
"53401","320.37000","28.41838","0.03134"
"53460","320.72400","28.44792","0.03234"
"53519","321.07800","28.47739","0.03298"
"53578","321.43200","28.50699","0.02335"
"53637","321.78600","28.53641","0.02479"
"53696","322.14000","28.56594","0.02681"
"53755","322.49400","28.59542","0.02716"
"53814","322.84800","28.62490","0.02918"
"53873","323.20200","28.65443","0.03069"
"53932","323.55600","28.68397","0.03212"
"53991","323.91000","28.71338","0.03250"
"54050","324.26400","28.74286","0.03214"
"54109","324.61800","28.77246","0.03508"
"54168","324.97200","28.80188","0.03574"
"54227","325.32600","28.83141","0.03724"
"54286","325.68000","28.86089","0.03808"
"54345","326.03400","28.89036","0.03908"
"54404","326.38800","28.91996","0.03988"
"54463","326.74200","28.94944","0.04097"
"54522","327.09600","28.97885","0.04239"
"54581","327.45000","29.00839","0.04307"
"54640","327.80400","29.03792","0.04329"
"54699","328.15800","29.06740","0.03871"
"54758","328.51200","29.09694","0.04140"
"54817","328.86600","29.12641","0.04212"
"54876","329.22000","29.15589","0.04318"
"54935","329.57400","29.18542","0.04455"
"54994","329.92800","29.21490","0.04630"
"55053","330.28200","29.24438","0.04723"
"55112","330.63600","29.27397","0.04779"
"55171","330.99000","29.30339","0.04918"
"55230","331.34400","29.33286","0.05024"
"55289","331.69800","29.36240","0.05142"
"55348","332.05200","29.39194","0.05209"
"55407","332.40600","29.42141","0.05353"
"55466","332.76000","29.45095","0.05382"
"55525","333.11400","29.48037","0.05372"
"55584","333.46800","29.50990","0.05571"
"55643","333.82200","29.53944","0.05714"
"55702","334.17600","29.56886","0.05823"
"55761","334.53000","29.59845","0.05950"
"55820","334.88400","29.62793","0.06005"
"55879","335.23800","29.65734","0.06150"
"55938","335.59200","29.68694","0.06192"
"55997","335.94600","29.71647","0.06261"
"56056","336.30000","29.74583","0.06305"
"56115","336.65400","29.77549","0.06408"
"56174","337.00800","29.80490","0.06445"
"56233","337.36200","29.83432","0.06496"
"56292","337.71600","29.86392","0.06484"
"56351","338.07000","29.89345","0.06557"
"56410","338.42400","29.92287","0.06615"
"56469","338.77800","29.95246","0.06643"
"56528","339.13200","29.98194","0.06695"
"56587","339.48600","30.01136","0.06747"
"56646","339.84000","30.04095","0.06804"
"56705","340.19400","30.07043","0.06828"
"56764","340.54800","30.09984","0.06952"
"56823","340.90200","30.12944","0.06974"
"56882","341.25600","30.15892","0.07105"
"56941","341.61000","30.18839","0.07322"
"57000","341.96400","30.21793","0.07493"
"57059","342.31800","30.24741","0.07750"
"57118","342.67200","30.27688","0.07823"
"57177","343.02600","30.30648","0.08092"
"57236","343.38000","30.33590","0.08431"
"57295","343.73400","30.36537","0.08712"
"57354","344.08800","30.39491","0.08965"
"57413","344.44200","30.42444","0.09385"
"57472","344.79600","30.45386","0.09698"
"57531","345.15000","30.48340","0.10030"
"57590","345.50400","30.51287","0.09199"
"57649","345.85800","30.54241","0.09414"
"57708","346.21200","30.57195","0.09194"
"57767","346.56600","30.60136","0.09521"
"57826","346.92000","30.63090","0.09837"
"57885","347.27400","30.66043","0.10196"
"57944","347.62800","30.68985","0.10662"
"58003","347.98200","30.71944","0.11111"
"58062","348.33600","30.74886","0.11504"
"58121","348.69000","30.77840","0.11821"
"58180","349.04400","30.80793","0.12131"
"58239","349.39800","30.83747","0.12355"
"58298","349.75200","30.86682","0.12400"
"58357","350.10600","30.89642","0.12524"
"58416","350.46000","30.92590","0.12614"
"58475","350.81400","30.95537","0.12726"
"58534","351.16800","30.98491","0.12764"
"58593","351.52200","31.01439","0.12902"
"58652","351.87600","31.04386","0.13051"
"58711","352.23000","31.07346","0.13370"
"58770","352.58400","31.10299","0.13807"
"58829","352.93800","31.13235","0.14084"
"58888","353.29200","31.16195","0.14303"
"58947","353.64600","31.19142","0.14331"
"59006","354.00000","31.22090","0.14643"
"59065","354.35400","31.25043","0.14840"
"59124","354.70800","31.27991","0.15079"
"59183","355.06200","31.30939","0.15327"
"59242","355.41600","31.33892","0.15665"
"59301","355.77000","31.36840","0.15877"
"59360","356.12400","31.39787","0.16189"
"59419","356.47800","31.42741","0.16330"
"59478","356.83200","31.45689","0.16566"
"59537","357.18600","31.48642","0.16724"
"59596","357.54000","31.51590","0.16840"
"59655","357.89400","31.54537","0.16875"
"59714","358.24800","31.57491","0.17066"
"59773","358.60200","31.60445","0.16792"
"59832","358.95600","31.63387","0.16975"
"59891","359.31000","31.66346","0.17184"
"59950","359.66400","31.69294","0.17323"
"60009","360.01800","31.72241","0.17466"
"60068","360.37200","31.75189","0.17611"
"60127","360.72600","31.78142","0.17752"
"60186","361.08000","31.81090","0.17890"
"60245","361.43400","31.84044","0.18029"
"60304","361.78800","31.86997","0.18237"
"60363","362.14200","31.89933","0.18462"
"60422","362.49600","31.92893","0.01096"
"60481","362.85000","31.95840","0.00141"
"60540","363.20400","31.98782","0.02336"
"60599","363.55800","32.01741","0.00707"
"60658","363.91200","32.04689","0.01880"
"60717","364.26600","32.07631","0.01304"
"60776","364.62000","32.10602","0.01748"
"60835","364.97400","32.13544","0.00426"
"60894","365.32800","32.16492","0.01601"
"60953","365.68200","32.19445","0.01493"
"61012","366.03600","32.22393","0.01061"
"61071","366.39000","32.25335","0.01600"
"61130","366.74400","32.28288","0.01614"
"61189","367.09800","32.31242","0.01730"
"61248","367.45200","32.34189","0.01219"
"61307","367.80600","32.37143","0.02034"
"61366","368.16000","32.40090","0.01495"
"61425","368.51400","32.43038","0.01832"
"61484","368.86800","32.45992","0.01638"
"61543","369.22200","32.48945","0.02017"
"61602","369.57600","32.51881","0.01460"
"61661","369.93000","32.54847","0.01929"
"61720","370.28400","32.57788","0.01787"
"61779","370.63800","32.60736","0.01936"
"61838","370.99200","32.63695","0.01664"
"61897","371.34600","32.66637","0.02074"
"61956","371.70000","32.69590","0.01827"
"62015","372.05400","32.72544","0.01938"
"62074","372.40800","32.75492","0.01869"
"62133","372.76200","32.78439","0.02231"
"62192","373.11600","32.81393","0.01899"
"62251","373.47000","32.84335","0.02054"
"62310","373.82400","32.87294","0.02111"
"62369","374.17800","32.90236","0.02283"
"62428","374.53200","32.93195","0.02057"
"62487","374.88600","32.96143","0.02266"
"62546","375.24000","32.99091","0.02410"
"62605","375.59400","33.02032","0.02338"
"62664","375.94800","33.04992","0.02360"
"62723","376.30200","33.07940","0.02487"
"62782","376.65600","33.10887","0.02747"
"62841","377.01000","33.13835","0.02585"
"62900","377.36400","33.16794","0.02729"
"62959","377.71800","33.19736","0.02842"
"63018","378.07200","33.22696","0.03031"
"63077","378.42600","33.25644","0.02835"
"63136","378.78000","33.28591","0.03070"
"63195","379.13400","33.31539","0.03276"
"63254","379.48800","33.34492","0.03272"
"63313","379.84200","33.37440","0.03138"
"63372","380.19600","33.40393","0.03316"
"63431","380.55000","33.43341","0.03538"
"63490","380.90400","33.46289","0.03420"
"63549","381.25800","33.49242","0.01989"
"63608","381.61200","33.52190","0.01868"
"63667","381.96600","33.55137","0.01917"
"63726","382.32000","33.58091","0.01923"
"63785","382.67400","33.61039","0.02055"
"63844","383.02800","33.63986","0.01954"
"63903","383.38200","33.66940","0.02103"
"63962","383.73600","33.69888","0.02140"
"64021","384.09000","33.72841","0.02212"
"64080","384.44400","33.75795","0.02200"
"64139","384.79800","33.78736","0.02310"
"64198","385.15200","33.81696","0.02358"
"64257","385.50600","33.84637","0.02388"
"64316","385.86000","33.87591","0.02416"
"64375","386.21400","33.90539","0.02592"
"64434","386.56800","33.93493","0.02696"
"64493","386.92200","33.96440","0.02738"
"64552","387.27600","33.99394","0.02844"
"64611","387.63000","34.02341","0.02956"
"64670","387.98400","34.05283","0.03116"
"64729","388.33800","34.08242","0.03126"
"64788","388.69200","34.11196","0.03235"
"64847","389.04600","34.14132","0.03383"
"64906","389.40000","34.17091","0.03401"
"64965","389.75400","34.20045","0.03503"
"65024","390.10800","34.22981","0.03638"
"65083","390.46200","34.25946","0.03738"
"65142","390.81600","34.28894","0.03789"
"65201","391.17000","34.31841","0.03867"
"65260","391.52400","34.34795","0.03860"
"65319","391.87800","34.37743","0.03992"
"65378","392.23200","34.40690","0.04066"
"65437","392.58600","34.43644","0.04156"
"65496","392.94000","34.46592","0.04145"
"65555","393.29400","34.49539","0.04287"
"65614","393.64800","34.52493","0.04407"
"65673","394.00200","34.55440","0.04459"
"65732","394.35600","34.58388","0.04604"
"65791","394.71000","34.61341","0.04641"
"65850","395.06400","34.64295","0.04715"
"65909","395.41800","34.67237","0.04701"
"65968","395.77200","34.70190","0.04761"
"66027","396.12600","34.73144","0.04872"
"66086","396.48000","34.76086","0.05004"
"66145","396.83400","34.79039","0.05064"
"66204","397.18800","34.81993","0.05114"
"66263","397.54200","34.84940","0.05206"
"66322","397.89600","34.87900","0.05329"
"66381","398.25000","34.90836","0.05408"
"66440","398.60400","34.93789","0.05426"
"66499","398.95800","34.96743","0.05484"
"66558","399.31200","34.99685","0.05520"
"66617","399.66600","35.02638","0.05647"
"66676","400.02000","35.05592","0.05787"
"66735","400.37400","35.08540","0.05858"
"66794","400.72800","35.11487","0.05950"
"66853","401.08200","35.14447","0.06015"
"66912","401.43600","35.17382","0.05989"
"66971","401.79000","35.20342","0.06136"
"67030","402.14400","35.23289","0.06151"
"67089","402.49800","35.26237","0.06226"
"67148","402.85200","35.29185","0.06266"
"67207","403.20600","35.32145","0.06347"
"67266","403.56000","35.35086","0.06354"
"67325","403.91400","35.38040","0.06404"
"67384","404.26800","35.40993","0.06403"
"67443","404.62200","35.43935","0.06454"
"67502","404.97600","35.46888","0.06455"
"67561","405.33000","35.49842","0.06492"
"67620","405.68400","35.52790","0.06551"
"67679","406.03800","35.55743","0.06566"
"67738","406.39200","35.58697","0.06577"
"67797","406.74600","35.61639","0.06607"
"67856","407.10000","35.64592","0.06646"
"67915","407.45400","35.67540","0.06676"
"67974","407.80800","35.70487","0.06704"
"68033","408.16200","35.73441","0.06770"
"68092","408.51600","35.76389","0.06817"
"68151","408.87000","35.79337","0.06840"
"68210","409.22400","35.82290","0.06886"
"68269","409.57800","35.85244","0.06976"
"68328","409.93200","35.88191","0.07008"
"68387","410.28600","35.91139","0.07069"
"68446","410.64000","35.94086","0.07114"
"68505","410.99400","35.97040","0.07272"
"68564","411.34800","35.99994","0.07327"
"68623","411.70200","36.02942","0.07433"
"68682","412.05600","36.05883","0.07562"
"68741","412.41000","36.08842","0.07675"
"68800","412.76400","36.11790","0.07823"
"68859","413.11800","36.14744","0.07872"
"68918","413.47200","36.17691","0.08032"
"68977","413.82600","36.20639","0.08220"
"69036","414.18000","36.23592","0.08411"
"69095","414.53400","36.26546","0.08516"
"69154","414.88800","36.29488","0.08659"
"69213","415.24200","36.32435","0.08827"
"69272","415.59600","36.35395","0.09010"
"69331","415.95000","36.38330","0.09283"
"69390","416.30400","36.41296","0.09414"
"69449","416.65800","36.44244","0.09537"
"69508","417.01200","36.47192","0.09743"
"69567","417.36600","36.50145","0.10033"
"69626","417.72000","36.53093","0.10131"
"69685","418.07400","36.56034","0.10315"
"69744","418.42800","36.58994","0.10551"
"69803","418.78200","36.61942","0.10712"
"69862","419.13600","36.64889","0.10854"
"69921","419.49000","36.67842","0.10958"
"69980","419.84400","36.70790","0.11067"
"70039","420.19800","36.73738","0.11331"
"70098","420.55200","36.76692","0.11584"
"70157","420.90600","36.79639","0.11712"
"70216","421.26000","36.82587","0.11898"
"70275","421.61400","36.85540","0.12010"
"70334","421.96800","36.88488","0.12168"
"70393","422.32200","36.91442","0.12248"
"70452","422.67600","36.94395","0.12350"
"70511","423.03000","36.97343","0.12278"
"70570","423.38400","37.00291","0.12362"
"70629","423.73800","37.03250","0.12466"
"70688","424.09200","37.06186","0.12521"
"70747","424.44600","37.09134","0.12547"
"70806","424.80000","37.12093","0.12602"
"70865","425.15400","37.15041","0.12673"
"70924","425.50800","37.17994","0.12682"
"70983","425.86200","37.20948","0.12750"
"71042","426.21600","37.23890","0.12754"
"71101","426.57000","37.26837","0.12703"
"71160","426.92400","37.29797","-0.00003"
"71219","427.27800","37.32732","-0.00104"
"71278","427.63200","37.35692","-0.00682"
"71337","427.98600","37.38639","-0.00459"
"71396","428.34000","37.41587","-0.00421"
"71455","428.69400","37.44535","-0.00221"
"71514","429.04800","37.47501","-0.00599"
"71573","429.40200","37.50436","-0.00362"
"71632","429.75600","37.53389","-0.00356"
"71691","430.11000","37.56343","-0.00418"
"71750","430.46400","37.59285","-0.00377"
"71809","430.81800","37.62238","-0.00491"
"71868","431.17200","37.65192","-0.00323"
"71927","431.52600","37.68134","-0.00275"
"71986","431.88000","37.71093","-0.00463"
"72045","432.23400","37.74047","-0.00399"
"72104","432.58800","37.76988","-0.00359"
"72163","432.94200","37.79942","-0.00388"
"72222","433.29600","37.82890","-0.00464"
"72277","433.62400","37.85622","-0.00381"