File: Trajectories_together/170108_1Specimen_RawData_5.csv
"","V1","V2","V3"
"1","End date","1/8/2017",""
"2","Specimen label","11AT_NL",""
"3","Maximum Load","0.06823","N"
"4","Time","Extension","Load"
"5","(s)","(mm)","(N)"
"6","0.00000","0.00000","-0.00002"
"30","0.14400","0.00777","-0.00035"
"54","0.28800","0.02338","-0.00001"
"78","0.43200","0.03623","-0.00007"
"102","0.57600","0.04837","0.00001"
"126","0.72000","0.06027","0.00011"
"150","0.86400","0.07223","0.00043"
"174","1.00800","0.08424","-0.00025"
"198","1.15200","0.09626","-0.00039"
"222","1.29600","0.10822","0.00054"
"246","1.44000","0.12024","0.00003"
"270","1.58400","0.13225","-0.00005"
"294","1.72800","0.14427","-0.00024"
"318","1.87200","0.15623","-0.00023"
"342","2.01600","0.16819","-0.00025"
"366","2.16000","0.18021","0.00025"
"390","2.30400","0.19222","-0.00045"
"414","2.44800","0.20418","0.00030"
"438","2.59200","0.21620","0.00032"
"462","2.73600","0.22822","0.00030"
"486","2.88000","0.24017","-0.00006"
"510","3.02400","0.25219","0.00022"
"534","3.16800","0.26421","0.00028"
"558","3.31200","0.27629","-0.00021"
"582","3.45600","0.28819","0.00055"
"606","3.60000","0.30014","0.00022"
"630","3.74400","0.31222","0.00015"
"654","3.88800","0.32424","0.00001"
"678","4.03200","0.33626","-0.00016"
"702","4.17600","0.34815","0.00042"
"726","4.32000","0.36029","0.00048"
"750","4.46400","0.37219","0.00007"
"774","4.60800","0.38421","0.00037"
"798","4.75200","0.39623","-0.00004"
"822","4.89600","0.40824","0.00053"
"846","5.04000","0.42026","0.00002"
"870","5.18400","0.43216","0.00001"
"894","5.32800","0.44424","0.00023"
"918","5.47200","0.45631","0.00032"
"942","5.61600","0.46827","0.00048"
"966","5.76000","0.48017","0.00042"
"990","5.90400","0.49219","0.00010"
"1014","6.04800","0.50421","0.00013"
"1038","6.19200","0.51622","0.00078"
"1062","6.33600","0.52812","0.00020"
"1086","6.48000","0.54026","0.00036"
"1110","6.62400","0.55228","0.00032"
"1134","6.76800","0.56423","0.00026"
"1158","6.91200","0.57619","0.00023"
"1182","7.05600","0.58827","0.00040"
"1206","7.20000","0.60023","0.00081"
"1230","7.34400","0.61219","0.00021"
"1254","7.48800","0.62420","0.00069"
"1278","7.63200","0.63622","0.00064"
"1302","7.77600","0.64824","0.00018"
"1326","7.92000","0.66020","0.00046"
"1350","8.06400","0.67221","-0.00010"
"1374","8.20800","0.68423","-0.00001"
"1398","8.35200","0.69625","0.00056"
"1422","8.49600","0.70815","0.00031"
"1446","8.64000","0.72022","0.00062"
"1470","8.78400","0.73224","0.00033"
"1494","8.92800","0.74426","0.00002"
"1518","9.07200","0.75616","0.00035"
"1542","9.21600","0.76824","0.00040"
"1566","9.36000","0.78025","0.00095"
"1590","9.50400","0.79215","0.00074"
"1614","9.64800","0.80423","0.00040"
"1638","9.79200","0.81625","0.00042"
"1662","9.93600","0.82826","0.00085"
"1686","10.08000","0.84022","0.00055"
"1710","10.22400","0.85224","0.00125"
"1734","10.36800","0.86420","0.00078"
"1758","10.51200","0.87628","0.00029"
"1782","10.65600","0.88823","0.00079"
"1806","10.80000","0.90019","0.00042"
"1830","10.94400","0.91221","0.00069"
"1854","11.08800","0.92417","0.00092"
"1878","11.23200","0.93618","0.00103"
"1902","11.37600","0.94826","0.00029"
"1926","11.52000","0.96016","0.00073"
"1950","11.66400","0.97218","0.00099"
"1974","11.80800","0.98420","0.00016"
"1998","11.95200","0.99621","0.00074"
"2022","12.09600","1.00817","0.00078"
"2046","12.24000","1.02019","0.00065"
"2070","12.38400","1.03221","0.00071"
"2094","12.52800","1.04422","0.00073"
"2118","12.67200","1.05618","0.00037"
"2142","12.81600","1.06820","0.00100"
"2166","12.96000","1.08022","0.00041"
"2190","13.10400","1.09229","0.00106"
"2214","13.24800","1.10413","0.00031"
"2238","13.39200","1.11621","0.00096"
"2262","13.53600","1.12823","0.00072"
"2286","13.68000","1.14019","0.00099"
"2310","13.82400","1.15214","0.00078"
"2334","13.96800","1.16422","0.00114"
"2358","14.11200","1.17624","0.00139"
"2382","14.25600","1.18826","0.00054"
"2406","14.40000","1.20016","0.00116"
"2430","14.54400","1.21223","0.00101"
"2454","14.68800","1.22425","0.00158"
"2478","14.83200","1.23621","0.00057"
"2502","14.97600","1.24817","0.00119"
"2526","15.12000","1.26024","0.00142"
"2550","15.26400","1.27226","0.00121"
"2574","15.40800","1.28422","0.00118"
"2598","15.55200","1.29624","0.00088"
"2622","15.69600","1.30820","0.00143"
"2646","15.84000","1.32021","0.00112"
"2670","15.98400","1.33217","0.00114"
"2694","16.12800","1.34419","0.00077"
"2718","16.27200","1.35621","0.00127"
"2742","16.41600","1.36822","0.00165"
"2766","16.56000","1.38018","0.00098"
"2790","16.70400","1.39220","0.00166"
"2814","16.84800","1.40422","0.00098"
"2838","16.99200","1.41617","0.00179"
"2862","17.13600","1.42813","0.00112"
"2886","17.28000","1.44021","0.00112"
"2910","17.42400","1.45229","0.00144"
"2934","17.56800","1.46419","0.00116"
"2958","17.71200","1.47620","0.00134"
"2982","17.85600","1.48816","0.00072"
"3006","18.00000","1.50024","0.00121"
"3030","18.14400","1.51214","0.00065"
"3054","18.28800","1.52421","0.00097"
"3078","18.43200","1.53617","0.00098"
"3102","18.57600","1.54819","0.00084"
"3126","18.72000","1.56015","0.00191"
"3150","18.86400","1.57223","0.00121"
"3174","19.00800","1.58424","0.00110"
"3198","19.15200","1.59620","0.00125"
"3222","19.29600","1.60816","0.00129"
"3246","19.44000","1.62024","0.00156"
"3270","19.58400","1.63225","0.00141"
"3294","19.72800","1.64415","0.00139"
"3318","19.87200","1.65617","0.00142"
"3342","20.01600","1.66819","0.00135"
"3366","20.16000","1.68015","0.00112"
"3390","20.30400","1.69216","0.00171"
"3414","20.44800","1.70418","0.00166"
"3438","20.59200","1.71620","0.00216"
"3462","20.73600","1.72816","0.00132"
"3486","20.88000","1.74017","0.00149"
"3510","21.02400","1.75219","0.00196"
"3534","21.16800","1.76421","0.00164"
"3558","21.31200","1.77617","0.00188"
"3582","21.45600","1.78819","0.00185"
"3606","21.60000","1.80020","0.00200"
"3630","21.74400","1.81222","0.00174"
"3654","21.88800","1.82418","0.00224"
"3678","22.03200","1.83620","0.00217"
"3702","22.17600","1.84821","0.00216"
"3726","22.32000","1.86017","0.00198"
"3750","22.46400","1.87213","0.00243"
"3774","22.60800","1.88421","0.00247"
"3798","22.75200","1.89628","0.00229"
"3822","22.89600","1.90824","0.00295"
"3846","23.04000","1.92020","0.00221"
"3870","23.18400","1.93228","0.00252"
"3894","23.32800","1.94424","0.00240"
"3918","23.47200","1.95619","0.00297"
"3942","23.61600","1.96815","0.00246"
"3966","23.76000","1.98023","0.00256"
"3990","23.90400","1.99219","0.00295"
"4014","24.04800","2.00420","0.00336"
"4038","24.19200","2.01616","0.00321"
"4062","24.33600","2.02818","0.00306"
"4086","24.48000","2.04020","0.00351"
"4110","24.62400","2.05216","0.00386"
"4134","24.76800","2.06417","0.00276"
"4158","24.91200","2.07625","0.00323"
"4182","25.05600","2.08815","0.00267"
"4206","25.20000","2.10011","0.00362"
"4230","25.34400","2.11219","0.00329"
"4254","25.48800","2.12426","0.00350"
"4278","25.63200","2.13616","0.00338"
"4302","25.77600","2.14818","0.00391"
"4326","25.92000","2.16020","0.00367"
"4350","26.06400","2.17221","0.00402"
"4374","26.20800","2.18417","0.00429"
"4398","26.35200","2.19619","0.00440"
"4422","26.49600","2.20821","0.00403"
"4446","26.64000","2.22016","0.00481"
"4470","26.78400","2.23212","0.00412"
"4494","26.92800","2.24426","0.00461"
"4518","27.07200","2.25622","0.00454"
"4542","27.21600","2.26824","0.00483"
"4566","27.36000","2.28019","0.00445"
"4590","27.50400","2.29221","0.00475"
"4614","27.64800","2.30417","0.00480"
"4638","27.79200","2.31619","0.00553"
"4662","27.93600","2.32820","0.00534"
"4686","28.08000","2.34022","0.00557"
"4710","28.22400","2.35224","0.00556"
"4734","28.36800","2.36414","0.00588"
"4758","28.51200","2.37622","0.00633"
"4782","28.65600","2.38817","0.00598"
"4806","28.80000","2.40013","0.00612"
"4830","28.94400","2.41215","0.00667"
"4854","29.08800","2.42423","0.00663"
"4878","29.23200","2.43624","0.00637"
"4902","29.37600","2.44820","0.00727"
"4926","29.52000","2.46016","0.00713"
"4950","29.66400","2.47224","0.00766"
"4974","29.80800","2.48420","0.00693"
"4998","29.95200","2.49615","0.00718"
"5022","30.09600","2.50823","0.00759"
"5046","30.24000","2.52019","0.00746"
"5070","30.38400","2.53221","0.00807"
"5094","30.52800","2.54416","0.00841"
"5118","30.67200","2.55624","0.00830"
"5142","30.81600","2.56820","0.00884"
"5166","30.96000","2.58022","0.00911"
"5190","31.10400","2.59212","0.00948"
"5214","31.24800","2.60419","0.00918"
"5238","31.39200","2.61627","0.00940"
"5262","31.53600","2.62817","0.00965"
"5286","31.68000","2.64019","0.00977"
"5310","31.82400","2.65226","0.01040"
"5334","31.96800","2.66422","0.01020"
"5358","32.11200","2.67618","0.01056"
"5382","32.25600","2.68820","0.01091"
"5406","32.40000","2.70021","0.01132"
"5430","32.54400","2.71223","0.01179"
"5454","32.68800","2.72419","0.01184"
"5478","32.83200","2.73621","0.01250"
"5502","32.97600","2.74829","0.01308"
"5526","33.12000","2.76018","0.01292"
"5550","33.26400","2.77214","0.01289"
"5574","33.40800","2.78422","0.01388"
"5598","33.55200","2.79624","0.01328"
"5622","33.69600","2.80819","0.01453"
"5646","33.84000","2.82021","0.01428"
"5670","33.98400","2.83223","0.01514"
"5694","34.12800","2.84425","0.01496"
"5718","34.27200","2.85621","0.01561"
"5742","34.41600","2.86822","0.01571"
"5766","34.56000","2.88024","0.01538"
"5790","34.70400","2.89220","0.01265"
"5814","34.84800","2.90416","0.01117"
"5838","34.99200","2.91623","0.00966"
"5862","35.13600","2.92819","0.00991"
"5886","35.28000","2.94021","0.01110"
"5910","35.42400","2.95217","0.01218"
"5934","35.56800","2.96425","0.01200"
"5958","35.71200","2.97626","0.01187"
"5982","35.85600","2.98822","0.01157"
"6006","36.00000","3.00018","0.01190"
"6030","36.14400","3.01220","0.01265"
"6054","36.28800","3.02421","0.01240"
"6078","36.43200","3.03617","0.01238"
"6102","36.57600","3.04819","0.01330"
"6126","36.72000","3.06021","0.01382"
"6150","36.86400","3.07223","0.01391"
"6174","37.00800","3.08418","0.01384"
"6198","37.15200","3.09620","0.01347"
"6222","37.29600","3.10822","0.01489"
"6246","37.44000","3.12018","0.01558"
"6270","37.58400","3.13219","0.01584"
"6294","37.72800","3.14427","0.01552"
"6318","37.87200","3.15623","0.01629"
"6342","38.01600","3.16819","0.01680"
"6366","38.16000","3.18021","0.01693"
"6390","38.30400","3.19222","0.01746"
"6414","38.44800","3.20424","0.01751"
"6438","38.59200","3.21620","0.01857"
"6462","38.73600","3.22822","0.01860"
"6486","38.88000","3.24023","0.01893"
"6510","39.02400","3.25225","0.01954"
"6534","39.16800","3.26415","0.02018"
"6558","39.31200","3.27629","0.01993"
"6582","39.45600","3.28824","0.01992"
"6606","39.60000","3.30020","0.02025"
"6630","39.74400","3.31216","0.02096"
"6654","39.88800","3.32424","0.02192"
"6678","40.03200","3.33626","0.02315"
"6702","40.17600","3.34821","0.02299"
"6726","40.32000","3.36023","0.02394"
"6750","40.46400","3.37225","0.02440"
"6774","40.60800","3.38427","0.02404"
"6798","40.75200","3.39617","0.02524"
"6822","40.89600","3.40824","0.02519"
"6846","41.04000","3.42026","0.02576"
"6870","41.18400","3.43228","0.02599"
"6894","41.32800","3.44418","0.02724"
"6918","41.47200","3.45625","0.02749"
"6942","41.61600","3.46827","0.02804"
"6966","41.76000","3.48023","0.02867"
"6990","41.90400","3.49225","0.02871"
"7014","42.04800","3.50426","0.02961"
"7038","42.19200","3.51622","0.03037"
"7062","42.33600","3.52818","0.03089"
"7086","42.48000","3.54020","0.03085"
"7110","42.62400","3.55222","0.03160"
"7134","42.76800","3.56423","0.03234"
"7158","42.91200","3.57619","0.03235"
"7182","43.05600","3.58821","0.03259"
"7206","43.20000","3.60029","0.03318"
"7230","43.34400","3.61224","0.03331"
"7254","43.48800","3.62414","0.03386"
"7278","43.63200","3.63622","0.03381"
"7302","43.77600","3.64824","0.03418"
"7326","43.92000","3.66014","0.03457"
"7350","44.06400","3.67215","0.03474"
"7374","44.20800","3.68423","0.03487"
"7398","44.35200","3.69625","0.03509"
"7422","44.49600","3.70821","0.03558"
"7446","44.64000","3.72022","0.03558"
"7470","44.78400","3.73224","0.03616"
"7494","44.92800","3.74426","0.03653"
"7518","45.07200","3.75622","0.03682"
"7542","45.21600","3.76824","0.03686"
"7566","45.36000","3.78025","0.03666"
"7590","45.50400","3.79227","0.03607"
"7614","45.64800","3.80423","0.03667"
"7638","45.79200","3.81631","0.03727"
"7662","45.93600","3.82820","0.03747"
"7686","46.08000","3.84022","0.03779"
"7710","46.22400","3.85218","0.03814"
"7734","46.36800","3.86426","0.03886"
"7758","46.51200","3.87622","0.03845"
"7782","46.65600","3.88823","0.03907"
"7806","46.80000","3.90025","0.03950"
"7830","46.94400","3.91227","0.03937"
"7854","47.08800","3.92423","0.04045"
"7878","47.23200","3.93612","0.04103"
"7902","47.37600","3.94826","0.04201"
"7926","47.52000","3.96022","0.04236"
"7950","47.66400","3.97218","0.04218"
"7974","47.80800","3.98414","0.04379"
"7998","47.95200","3.99627","0.04383"
"8022","48.09600","4.00823","0.04358"
"8046","48.24000","4.02019","0.04501"
"8070","48.38400","4.03221","0.04535"
"8094","48.52800","4.04428","0.04624"
"8118","48.67200","4.05624","0.04784"
"8142","48.81600","4.06820","0.04787"
"8166","48.96000","4.08022","0.04879"
"8190","49.10400","4.09223","0.04813"
"8214","49.24800","4.10425","0.04940"
"8238","49.39200","4.11615","0.04931"
"8262","49.53600","4.12823","0.05134"
"8286","49.68000","4.14025","0.05169"
"8310","49.82400","4.15220","0.05269"
"8334","49.96800","4.16416","0.05410"
"8358","50.11200","4.17624","0.05392"
"8382","50.25600","4.18820","0.05555"
"8406","50.40000","4.20015","0.05586"
"8430","50.54400","4.21217","0.05659"
"8454","50.68800","4.22425","0.05736"
"8478","50.83200","4.23627","0.05787"
"8502","50.97600","4.24817","0.05704"
"8526","51.12000","4.26024","0.05687"
"8550","51.26400","4.27220","0.05732"
"8574","51.40800","4.28422","0.05531"
"8598","51.55200","4.29618","0.05406"
"8622","51.69600","4.30825","0.05355"
"8646","51.84000","4.32027","0.05447"
"8670","51.98400","4.33223","0.05574"
"8694","52.12800","4.34419","0.05729"
"8718","52.27200","4.35621","0.05739"
"8742","52.41600","4.36822","0.05778"
"8766","52.56000","4.38018","0.05751"
"8790","52.70400","4.39220","0.05849"
"8814","52.84800","4.40422","0.05862"
"8838","52.99200","4.41623","0.05923"
"8862","53.13600","4.42819","0.05962"
"8886","53.28000","4.44027","0.05975"
"8910","53.42400","4.45217","0.06045"
"8934","53.56800","4.46425","0.06088"
"8958","53.71200","4.47620","0.06197"
"8982","53.85600","4.48822","0.06255"
"9006","54.00000","4.50024","0.06287"
"9030","54.14400","4.51220","0.06330"
"9054","54.28800","4.52415","0.06405"
"9078","54.43200","4.53623","0.06429"
"9102","54.57600","4.54819","0.06449"
"9126","54.72000","4.56021","0.06557"
"9150","54.86400","4.57217","0.06400"
"9174","55.00800","4.58424","0.06364"
"9198","55.15200","4.59620","0.06450"
"9222","55.29600","4.60816","0.06486"
"9246","55.44000","4.62018","0.06509"
"9270","55.58400","4.63225","0.06634"
"9294","55.72800","4.64415","0.06655"
"9318","55.87200","4.65617","0.06707"
"9342","56.01600","4.66825","0.06783"
"9366","56.16000","4.68026","0.06802"
"9390","56.30400","4.69216","0.06726"
"9414","56.44800","4.70418","0.06295"
"9438","56.59200","4.71626","0.05997"
"9462","56.73600","4.72816","0.05668"
"9486","56.88000","4.74017","0.05571"
"9510","57.02400","4.75219","0.05291"
"9534","57.16800","4.76421","0.04705"
"9558","57.31200","4.77623","0.04344"
"9582","57.45600","4.78813","0.04172"
"9606","57.60000","4.80020","0.04236"
"9630","57.74400","4.81222","0.04087"
"9654","57.88800","4.82418","0.03991"
"9678","58.03200","4.83614","0.03879"
"9702","58.17600","4.84827","0.03849"
"9726","58.32000","4.86023","0.03856"
"9750","58.46400","4.87219","0.03826"
"9774","58.60800","4.88421","0.03819"
"9798","58.75200","4.89622","0.03925"
"9822","58.89600","4.90824","0.04017"
"9846","59.04000","4.92020","0.04083"
"9870","59.18400","4.93222","0.04023"
"9894","59.32800","4.94430","0.03853"
"9918","59.47200","4.95625","0.03831"
"9942","59.61600","4.96815","0.03871"
"9966","59.76000","4.98023","0.03782"
"9990","59.90400","4.99225","0.03778"
"10014","60.04800","5.00414","0.03691"
"10038","60.19200","5.01616","0.03666"
"10062","60.33600","5.02818","0.03692"
"10086","60.48000","5.04026","0.03718"
"10110","60.62400","5.05216","0.03711"
"10134","60.76800","5.06417","0.03734"
"10158","60.91200","5.07619","0.03184"
"10182","61.05600","5.08821","0.00850"
"10206","61.20000","5.10017","0.01004"
"10230","61.34400","5.11224","0.01132"
"10254","61.48800","5.12420","0.01034"
"10278","61.63200","5.13622","0.00995"
"10302","61.77600","5.14818","0.01084"
"10326","61.92000","5.16020","0.01075"
"10350","62.06400","5.17221","0.01319"
"10374","62.20800","5.18417","0.01375"
"10398","62.35200","5.19613","0.01298"
"10422","62.49600","5.20821","0.01226"
"10446","62.64000","5.22022","0.01384"
"10470","62.78400","5.23224","0.01537"
"10494","62.92800","5.24420","0.01582"
"10518","63.07200","5.25622","0.01483"
"10542","63.21600","5.26824","0.01473"
"10566","63.36000","5.28019","0.01603"
"10590","63.50400","5.29221","0.01813"
"10614","63.64800","5.30423","0.01830"
"10638","63.79200","5.31619","0.01797"
"10662","63.93600","5.32814","0.01824"
"10686","64.08000","5.34022","0.01910"
"10710","64.22400","5.35224","0.02047"
"10734","64.36800","5.36420","0.02044"
"10758","64.51200","5.37621","0.02110"
"10782","64.65600","5.38823","0.02132"
"10806","64.80000","5.40019","0.02318"
"10830","64.94400","5.41215","0.02441"
"10854","65.08800","5.42423","0.02373"
"10878","65.23200","5.43618","0.02390"
"10902","65.37600","5.44814","0.02528"
"10926","65.52000","5.46016","0.02787"
"10950","65.66400","5.47224","0.02759"
"10974","65.80800","5.48425","0.02782"
"10998","65.95200","5.49621","0.02833"
"11022","66.09600","5.50817","0.02911"
"11046","66.24000","5.52025","0.03017"
"11070","66.38400","5.53221","0.03054"
"11094","66.52800","5.54416","0.03077"
"11118","66.67200","5.55618","0.03150"
"11142","66.81600","5.56826","0.03252"
"11166","66.96000","5.58022","0.03233"
"11190","67.10400","5.59218","0.03272"
"11214","67.24800","5.60419","0.03325"
"11238","67.39200","5.61621","0.03396"
"11262","67.53600","5.62817","0.03417"
"11286","67.68000","5.64013","0.03435"
"11310","67.82400","5.65220","0.03446"
"11334","67.96800","5.66422","0.03478"
"11358","68.11200","5.67618","0.03533"
"11382","68.25600","5.68814","0.03564"
"11406","68.40000","5.70021","0.03585"
"11430","68.54400","5.71223","0.03626"
"11454","68.68800","5.72419","0.03670"
"11478","68.83200","5.73621","0.03677"
"11502","68.97600","5.74823","0.03717"
"11526","69.12000","5.76018","0.03769"
"11550","69.26400","5.77214","0.03859"
"11574","69.40800","5.78422","0.03930"
"11598","69.55200","5.79618","0.03945"
"11622","69.69600","5.80819","0.04073"
"11646","69.84000","5.82009","0.04145"
"11670","69.98400","5.83223","0.04191"
"11694","70.12800","5.84419","0.04288"
"11718","70.27200","5.85621","0.04378"
"11742","70.41600","5.86816","0.04492"
"11766","70.56000","5.88024","0.04567"
"11790","70.70400","5.89220","0.04720"
"11814","70.84800","5.90422","0.04820"
"11838","70.99200","5.91617","0.04905"
"11862","71.13600","5.92819","0.04924"
"11886","71.28000","5.94021","0.05055"
"11910","71.42400","5.95217","0.05143"
"11934","71.56800","5.96419","0.05222"
"11958","71.71200","5.97620","0.05321"
"11982","71.85600","5.98816","0.05376"
"12006","72.00000","6.00018","0.05515"
"12030","72.14400","6.01226","0.05544"
"12054","72.28800","6.02421","0.05597"
"12078","72.43200","6.03617","0.05732"
"12102","72.57600","6.04819","0.05790"
"12126","72.72000","6.06021","0.05837"
"12150","72.86400","6.07223","0.05899"
"12174","73.00800","6.08412","0.05894"
"12198","73.15200","6.09626","0.06020"
"12222","73.29600","6.10822","0.06065"
"12246","73.44000","6.12024","0.06087"
"12270","73.58400","6.13219","0.06192"
"12294","73.72800","6.14427","0.06266"
"12318","73.87200","6.15623","0.06327"
"12342","74.01600","6.16819","0.06348"
"12366","74.16000","6.18020","0.06388"
"12390","74.30400","6.19222","0.01549"
"12414","74.44800","6.20424","0.01487"
"12438","74.59200","6.21620","0.01289"
"12462","74.73600","6.22816","0.01489"
"12486","74.88000","6.24023","0.01592"
"12510","75.02400","6.25225","0.01575"
"12534","75.16800","6.26415","0.01530"
"12558","75.31200","6.27623","0.01507"
"12582","75.45600","6.28824","0.01537"
"12606","75.60000","6.30020","0.01639"
"12630","75.74400","6.31216","0.01619"
"12654","75.88800","6.32418","0.01606"
"12678","76.03200","6.33626","0.01622"
"12702","76.17600","6.34815","0.01709"
"12726","76.32000","6.36017","0.01752"
"12750","76.46400","6.37225","0.01684"
"12774","76.60800","6.38427","0.01723"
"12798","76.75200","6.39616","0.01718"
"12822","76.89600","6.40818","0.01824"
"12846","77.04000","6.42026","0.01798"
"12870","77.18400","6.43228","0.01845"
"12894","77.32800","6.44418","0.01859"
"12918","77.47200","6.45619","0.01826"
"12942","77.61600","6.46827","0.01909"
"12966","77.76000","6.48023","0.01923"
"12990","77.90400","6.49219","0.01916"
"13014","78.04800","6.50426","0.01889"
"13038","78.19200","6.51628","0.01904"
"13062","78.33600","6.52824","0.01948"
"13086","78.48000","6.54020","0.02050"
"13110","78.62400","6.55228","0.02015"
"13134","78.76800","6.56423","0.01964"
"13158","78.91200","6.57625","0.01953"
"13182","79.05600","6.58821","0.01974"
"13206","79.20000","6.60029","0.02074"
"13230","79.34400","6.61218","0.01989"
"13254","79.48800","6.62420","0.02044"
"13278","79.63200","6.63622","0.01991"
"13302","79.77600","6.64824","0.02039"
"13326","79.92000","6.66019","0.02118"
"13350","80.06400","6.67215","0.02072"
"13374","80.20800","6.68423","0.02086"
"13398","80.35200","6.69625","0.02130"
"13422","80.49600","6.70821","0.02119"
"13446","80.64000","6.72022","0.02114"
"13470","80.78400","6.73224","0.02163"
"13494","80.92800","6.74426","0.02180"
"13518","81.07200","6.75622","0.02150"
"13542","81.21600","6.76824","0.02196"
"13566","81.36000","6.78025","0.02220"
"13590","81.50400","6.79227","0.02148"
"13614","81.64800","6.80417","0.02214"
"13638","81.79200","6.81625","0.02240"
"13662","81.93600","6.82826","0.02213"
"13686","82.08000","6.84022","0.02195"
"13710","82.22400","6.85218","0.02212"
"13734","82.36800","6.86426","0.02258"
"13758","82.51200","6.87622","0.02339"
"13782","82.65600","6.88823","0.02327"
"13806","82.80000","6.90025","0.02346"
"13830","82.94400","6.91227","0.02293"
"13854","83.08800","6.92429","0.02411"
"13878","83.23200","6.93618","0.02318"
"13902","83.37600","6.94820","0.02408"
"13926","83.52000","6.96022","0.02403"
"13950","83.66400","6.97224","0.02389"
"13974","83.80800","6.98413","0.02477"
"13998","83.95200","6.99621","0.01899"
"14022","84.09600","7.00823","0.01594"
"14046","84.24000","7.02025","0.01088"
"14070","84.38400","7.03221","0.00988"
"14094","84.52800","7.04428","0.00994"
"14118","84.67200","7.05624","0.01051"
"14142","84.81600","7.06820","0.01087"
"14166","84.96000","7.08022","0.01046"
"14190","85.10400","7.09223","0.01090"
"14214","85.24800","7.10425","0.01135"
"14238","85.39200","7.11615","0.01144"
"14262","85.53600","7.12823","0.01108"
"14286","85.68000","7.14025","0.01126"
"14310","85.82400","7.15220","0.01114"
"14334","85.96800","7.16422","0.01188"
"14358","86.11200","7.17624","0.01184"
"14382","86.25600","7.18826","0.01270"
"14406","86.40000","7.20027","0.01246"
"14430","86.54400","7.21223","0.01188"
"14454","86.68800","7.22425","0.01273"
"14478","86.83200","7.23627","0.01289"
"14502","86.97600","7.24817","0.01314"
"14526","87.12000","7.26018","0.01321"
"14550","87.26400","7.27220","0.01318"
"14574","87.40800","7.28422","0.01349"
"14598","87.55200","7.29618","0.01410"
"14622","87.69600","7.30819","0.01396"
"14646","87.84000","7.32021","0.01399"
"14670","87.98400","7.33223","0.01382"
"14694","88.12800","7.34419","0.01381"
"14718","88.27200","7.35620","0.01458"
"14742","88.41600","7.36822","0.01454"
"14766","88.56000","7.38024","0.01493"
"14790","88.70400","7.39220","0.01500"
"14814","88.84800","7.40428","0.01501"
"14838","88.99200","7.41623","0.01489"
"14862","89.13600","7.42819","0.01502"
"14886","89.28000","7.44021","0.01464"
"14910","89.42400","7.45223","0.01518"
"14934","89.56800","7.46418","0.01536"
"14958","89.71200","7.47620","0.01462"
"14982","89.85600","7.48822","0.01497"
"15006","90.00000","7.50024","0.01520"
"15030","90.14400","7.51220","0.01561"
"15054","90.28800","7.52421","0.01574"
"15078","90.43200","7.53623","0.01594"
"15102","90.57600","7.54819","0.01602"
"15126","90.72000","7.56021","0.01541"
"15150","90.86400","7.57216","0.01495"
"15174","91.00800","7.58424","0.01462"
"15198","91.15200","7.59620","0.01463"
"15222","91.29600","7.60816","0.01469"
"15246","91.44000","7.62018","0.01480"
"15270","91.58400","7.63219","0.01539"
"15294","91.72800","7.64421","0.01541"
"15318","91.87200","7.65611","0.01511"
"15342","92.01600","7.66825","0.01562"
"15366","92.16000","7.68021","0.01534"
"15390","92.30400","7.69222","0.01532"
"15414","92.44800","7.70418","0.01548"
"15438","92.59200","7.71626","0.01564"
"15462","92.73600","7.72822","0.01633"
"15486","92.88000","7.74017","0.01606"
"15510","93.02400","7.75219","0.01667"
"15534","93.16800","7.76427","0.01654"
"15558","93.31200","7.77623","0.01615"
"15582","93.45600","7.78813","0.01635"
"15606","93.60000","7.80020","0.01724"
"15630","93.74400","7.81222","0.01664"
"15654","93.88800","7.82424","0.01709"
"15678","94.03200","7.83614","0.01728"
"15702","94.17600","7.84821","0.01738"
"15726","94.32000","7.86023","0.01716"
"15750","94.46400","7.87219","0.01749"
"15774","94.60800","7.88415","0.01745"
"15798","94.75200","7.89622","0.01779"
"15822","94.89600","7.90824","0.01813"
"15846","95.04000","7.92020","0.01830"
"15870","95.18400","7.93222","0.01854"
"15894","95.32800","7.94423","0.01877"
"15918","95.47200","7.95625","0.01875"
"15942","95.61600","7.96821","0.01951"
"15966","95.76000","7.98023","0.01905"
"15990","95.90400","7.99225","0.01883"
"16014","96.04800","8.00420","0.01946"
"16038","96.19200","8.01616","0.01923"
"16062","96.33600","8.02824","0.01975"
"16086","96.48000","8.04020","0.01948"
"16110","96.62400","8.05221","0.01997"
"16134","96.76800","8.06417","0.02002"
"16158","96.91200","8.07625","0.01984"
"16182","97.05600","8.08827","0.02006"
"16206","97.20000","8.10017","0.01955"
"16230","97.34400","8.11218","0.00228"
"16254","97.48800","8.12420","-0.00121"
"16278","97.63200","8.13616","0.00132"
"16302","97.77600","8.14818","-0.00022"
"16326","97.92000","8.16020","-0.00072"
"16350","98.06400","8.17221","-0.00054"
"16374","98.20800","8.18417","-0.00015"
"16398","98.35200","8.19619","-0.00145"
"16422","98.49600","8.20821","-0.00044"
"16446","98.64000","8.22022","-0.00005"
"16470","98.78400","8.23212","-0.00079"
"16494","98.92800","8.24420","-0.00078"
"16518","99.07200","8.25628","-0.00092"
"16542","99.21600","8.26830","-0.00006"
"16566","99.36000","8.28019","-0.00111"
"16590","99.50400","8.29221","-0.00106"
"16614","99.64800","8.30423","-0.00089"
"16638","99.79200","8.31619","-0.00038"
"16662","99.93600","8.32814","-0.00008"
"16686","100.08000","8.34022","-0.00100"
"16710","100.22400","8.35224","-0.00111"
"16734","100.36800","8.36420","-0.00066"
"16758","100.51200","8.37615","-0.00043"
"16782","100.65600","8.38823","-0.00101"
"16806","100.80000","8.40025","-0.00087"
"16830","100.94400","8.41215","-0.00054"
"16854","101.08800","8.42417","0.00008"
"16878","101.23200","8.43624","-0.00048"
"16902","101.37600","8.44820","-0.00032"
"16926","101.52000","8.46016","-0.00106"
"16950","101.66400","8.47218","-0.00123"
"16974","101.80800","8.48419","-0.00090"
"16998","101.95200","8.49615","-0.00096"
"17022","102.09600","8.50817","-0.00095"
"17046","102.24000","8.52019","0.00000"
"17070","102.38400","8.53221","-0.00047"
"17094","102.52800","8.54422","-0.00079"
"17118","102.67200","8.55618","-0.00119"
"17142","102.81600","8.56826","-0.00092"
"17166","102.96000","8.58028","-0.00085"
"17190","103.10400","8.59217","-0.00066"
"17214","103.24800","8.60419","-0.00124"
"17238","103.39200","8.61621","-0.00080"
"17262","103.53600","8.62823","-0.00072"
"17286","103.68000","8.64019","-0.00053"
"17310","103.82400","8.65220","-0.00051"
"17334","103.96800","8.66416","-0.00065"
"17358","104.11200","8.67624","-0.00082"
"17382","104.25600","8.68814","-0.00102"
"17406","104.40000","8.70027","-0.00046"
"17430","104.54400","8.71223","-0.00078"
"17454","104.68800","8.72425","-0.00050"
"17478","104.83200","8.73615","-0.00060"
"17502","104.97600","8.74823","-0.00029"
"17526","105.12000","8.76018","-0.00063"
"17550","105.26400","8.77214","-0.00065"
"17574","105.40800","8.78416","-0.00055"
"17598","105.55200","8.79624","-0.00056"
"17622","105.69600","8.80819","-0.00068"
"17646","105.84000","8.82021","-0.00092"
"17670","105.98400","8.83217","-0.00066"
"17694","106.12800","8.84419","-0.00038"
"17718","106.27200","8.85620","-0.00051"
"17742","106.41600","8.86810","-0.00062"
"17766","106.56000","8.88018","-0.00066"
"17790","106.70400","8.89220","-0.00046"
"17814","106.84800","8.90416","-0.00110"
"17838","106.99200","8.91617","-0.00079"
"17862","107.13600","8.92819","-0.00072"
"17886","107.28000","8.94021","-0.00065"
"17910","107.42400","8.95217","-0.00076"
"17934","107.56800","8.96418","0.00001"
"17958","107.71200","8.97620","-0.00090"
"17982","107.85600","8.98822","-0.00051"
"18006","108.00000","9.00012","-0.00086"
"18030","108.14400","9.01220","-0.00044"
"18054","108.28800","9.02421","-0.00086"
"18078","108.43200","9.03617","-0.00065"
"18102","108.57600","9.04813","-0.00077"
"18126","108.72000","9.06021","-0.00054"
"18150","108.86400","9.07222","-0.00036"
"18174","109.00800","9.08418","-0.00067"
"18198","109.15200","9.09614","-0.00081"
"18222","109.29600","9.10822","-0.00075"
"18246","109.44000","9.12024","-0.00092"
"18270","109.58400","9.13219","-0.00070"
"18294","109.72800","9.14415","-0.00045"
"18318","109.87200","9.15623","-0.00083"
"18342","110.01600","9.16819","-0.00049"
"18366","110.16000","9.18014","-0.00085"
"18390","110.30400","9.19222","-0.00048"
"18414","110.44800","9.20424","-0.00089"
"18438","110.59200","9.21620","-0.00036"
"18462","110.73600","9.22816","-0.00081"
"18486","110.88000","9.24017","-0.00078"
"18510","111.02400","9.25225","-0.00085"
"18534","111.16800","9.26415","-0.00015"
"18558","111.31200","9.27617","-0.00056"
"18582","111.45600","9.28818","-0.00057"
"18606","111.60000","9.30020","-0.00060"
"18630","111.74400","9.31222","-0.00097"
"18654","111.88800","9.32418","-0.00085"
"18678","112.03200","9.33619","-0.00074"
"18702","112.17600","9.34821","-0.00089"
"18726","112.32000","9.36017","-0.00068"
"18750","112.46400","9.37219","-0.00024"
"18774","112.60800","9.38421","0.00004"
"18798","112.75200","9.39622","-0.00031"
"18822","112.89600","9.40812","-0.00014"
"18846","113.04000","9.42026","-0.00090"
"18870","113.18400","9.43222","-0.00108"
"18894","113.32800","9.44423","-0.00071"
"18918","113.47200","9.45619","-0.00102"
"18942","113.61600","9.46821","-0.00035"
"18966","113.76000","9.48017","-0.00008"
"18990","113.90400","9.49219","-0.00082"
"19014","114.04800","9.50420","-0.00077"
"19038","114.19200","9.51622","-0.00091"
"19062","114.33600","9.52824","-0.00093"
"19086","114.48000","9.54020","-0.00082"
"19110","114.62400","9.55222","-0.00092"
"19134","114.76800","9.56417","-0.00062"
"19158","114.91200","9.57619","-0.00029"
"19182","115.05600","9.58815","-0.00012"
"19206","115.20000","9.60023","-0.00041"
"19230","115.34400","9.61224","-0.00098"
"19254","115.48800","9.62420","-0.00071"
"19278","115.63200","9.63622","-0.00071"
"19302","115.77600","9.64824","-0.00110"
"19326","115.92000","9.66026","-0.00116"
"19350","116.06400","9.67215","-0.00070"
"19374","116.20800","9.68423","-0.00032"
"19398","116.35200","9.69625","-0.00049"
"19422","116.49600","9.70821","-0.00065"
"19446","116.64000","9.72016","-0.00049"
"19470","116.78400","9.73230","-0.00063"
"19494","116.92800","9.74426","-0.00094"
"19518","117.07200","9.75622","-0.00110"
"19542","117.21600","9.76818","-0.00037"
"19566","117.36000","9.78025","-0.00051"
"19590","117.50400","9.79221","-0.00075"
"19614","117.64800","9.80417","-0.00075"
"19638","117.79200","9.81619","-0.00042"
"19662","117.93600","9.82826","-0.00097"
"19686","118.08000","9.84028","-0.00077"
"19710","118.22400","9.85218","-0.00103"
"19734","118.36800","9.86426","-0.00039"
"19758","118.51200","9.87627","-0.00057"
"19782","118.65600","9.88823","-0.00003"
"19806","118.80000","9.90019","-0.00063"
"19830","118.94400","9.91221","-0.00065"
"19854","119.08800","9.92423","-0.00077"
"19878","119.23200","9.93618","-0.00078"
"19902","119.37600","9.94820","-0.00035"
"19926","119.52000","9.96022","-0.00074"
"19950","119.66400","9.97223","-0.00057"
"19974","119.80800","9.98419","-0.00016"
"19998","119.95200","9.99615","0.00013"
"20022","120.09600","10.00823","-0.00033"
"20046","120.24000","10.02025","-0.00073"
"20070","120.38400","10.03221","-0.00045"
"20094","120.52800","10.04422","-0.00095"
"20118","120.67200","10.05624","-0.00070"
"20142","120.81600","10.06826","-0.00083"
"20166","120.96000","10.08016","-0.00038"
"20190","121.10400","10.09223","-0.00044"
"20214","121.24800","10.10425","-0.00046"
"20238","121.39200","10.11621","-0.00092"
"20262","121.53600","10.12817","-0.00041"
"20286","121.68000","10.14031","-0.00066"
"20310","121.82400","10.15226","-0.00033"
"20334","121.96800","10.16422","-0.00029"
"20358","122.11200","10.17624","-0.00029"
"20382","122.25600","10.18826","0.00022"
"20406","122.40000","10.20027","-0.00001"
"20430","122.54400","10.21223","-0.00024"
"20454","122.68800","10.22425","-0.00058"
"20478","122.83200","10.23627","-0.00079"
"20502","122.97600","10.24823","-0.00051"
"20526","123.12000","10.26018","-0.00081"
"20550","123.26400","10.27226","-0.00059"
"20574","123.40800","10.28422","-0.00026"
"20598","123.55200","10.29618","0.00039"
"20622","123.69600","10.30819","-0.00017"
"20646","123.84000","10.32021","-0.00052"
"20670","123.98400","10.33223","-0.00066"
"20694","124.12800","10.34419","-0.00100"
"20718","124.27200","10.35620","-0.00082"
"20742","124.41600","10.36822","-0.00061"
"20766","124.56000","10.38024","-0.00047"
"20790","124.70400","10.39220","-0.00043"
"20814","124.84800","10.40428","-0.00002"
"20838","124.99200","10.41629","-0.00057"
"20862","125.13600","10.42819","-0.00075"
"20886","125.28000","10.44021","-0.00074"
"20910","125.42400","10.45229","-0.00084"
"20934","125.56800","10.46424","-0.00056"
"20958","125.71200","10.47620","-0.00051"
"20982","125.85600","10.48822","0.00023"
"21006","126.00000","10.50024","0.00006"
"21030","126.14400","10.51226","-0.00073"
"21054","126.28800","10.52415","-0.00084"
"21078","126.43200","10.53623","-0.00058"
"21102","126.57600","10.54825","-0.00048"
"21126","126.72000","10.56027","-0.00084"
"21150","126.86400","10.57217","-0.00027"
"21174","127.00800","10.58424","-0.00011"
"21198","127.15200","10.59626","-0.00058"
"21222","127.29600","10.60822","-0.00028"
"21246","127.44000","10.62018","-0.00048"
"21270","127.58400","10.63219","-0.00078"
"21294","127.72800","10.64421","-0.00099"
"21318","127.87200","10.65617","-0.00081"
"21342","128.01600","10.66819","-0.00073"
"21366","128.16000","10.68020","-0.00023"
"21390","128.30400","10.69228","0.00007"
"21414","128.44800","10.70418","-0.00030"
"21438","128.59200","10.71626","-0.00018"
"21462","128.73600","10.72822","-0.00066"
"21486","128.88000","10.74023","-0.00038"
"21510","129.02400","10.75219","-0.00064"
"21534","129.16800","10.76427","-0.00073"
"21558","129.31200","10.77623","-0.00007"
"21582","129.45600","10.78824","-0.00056"
"21606","129.60000","10.80020","-0.00031"
"21630","129.74400","10.81228","-0.00024"
"21654","129.88800","10.82424","-0.00042"
"21678","130.03200","10.83619","-0.00046"
"21702","130.17600","10.84821","-0.00088"
"21726","130.32000","10.86023","-0.00019"
"21750","130.46400","10.87219","-0.00015"
"21774","130.60800","10.88415","-0.00043"
"21798","130.75200","10.89622","-0.00011"
"21822","130.89600","10.90824","-0.00021"
"21846","131.04000","10.92026","-0.00037"
"21870","131.18400","10.93222","-0.00083"
"21894","131.32800","10.94423","-0.00028"
"21918","131.47200","10.95625","-0.00028"
"21942","131.61600","10.96821","-0.00031"
"21966","131.76000","10.98023","-0.00070"
"21990","131.90400","10.99225","-0.00028"
"22014","132.04800","11.00420","-0.00051"
"22038","132.19200","11.01622","-0.00068"
"22062","132.33600","11.02818","-0.00083"
"22086","132.48000","11.04020","-0.00026"
"22110","132.62400","11.05222","-0.00075"
"22134","132.76800","11.06417","0.00060"
"22158","132.91200","11.07619","-0.00059"
"22182","133.05600","11.08821","-0.00052"
"22206","133.20000","11.10017","-0.00060"
"22230","133.34400","11.11218","-0.00030"
"22254","133.48800","11.12426","-0.00027"
"22278","133.63200","11.13622","-0.00053"
"22302","133.77600","11.14818","-0.00001"
"22326","133.92000","11.16019","-0.00040"
"22350","134.06400","11.17221","-0.00029"
"22374","134.20800","11.18423","-0.00039"
"22398","134.35200","11.19613","-0.00044"
"22422","134.49600","11.20821","-0.00058"
"22446","134.64000","11.22022","-0.00045"
"22470","134.78400","11.23224","0.00018"
"22494","134.92800","11.24414","-0.00043"
"22518","135.07200","11.25622","-0.00045"
"22542","135.21600","11.26824","-0.00101"
"22566","135.36000","11.28025","-0.00077"
"22590","135.50400","11.29215","0.00027"
"22614","135.64800","11.30429","-0.00015"
"22638","135.79200","11.31625","0.00040"
"22662","135.93600","11.32820","0.00014"
"22686","136.08000","11.34016","-0.00002"
"22710","136.22400","11.35224","-0.00031"
"22734","136.36800","11.36420","-0.00016"
"22758","136.51200","11.37615","-0.00051"
"22782","136.65600","11.38817","-0.00049"
"22806","136.80000","11.40025","-0.00012"
"22830","136.94400","11.41221","0.00037"
"22854","137.08800","11.42417","0.00013"
"22878","137.23200","11.43624","-0.00012"
"22902","137.37600","11.44826","-0.00030"
"22926","137.52000","11.46022","-0.00017"
"22950","137.66400","11.47218","-0.00052"
"22974","137.80800","11.48425","-0.00021"
"22998","137.95200","11.49621","-0.00042"
"23022","138.09600","11.50817","0.00002"
"23046","138.24000","11.52013","0.00019"
"23070","138.38400","11.53221","-0.00007"
"23094","138.52800","11.54422","-0.00002"
"23118","138.67200","11.55612","-0.00020"
"23142","138.81600","11.56820","0.00012"
"23166","138.96000","11.58022","-0.00003"
"23190","139.10400","11.59223","-0.00012"
"23214","139.24800","11.60413","-0.00015"
"23238","139.39200","11.61621","-0.00009"
"23262","139.53600","11.62817","-0.00003"
"23286","139.68000","11.64019","0.00048"
"23310","139.82400","11.65214","0.00000"
"23334","139.96800","11.66422","-0.00003"
"23358","140.11200","11.67624","-0.00014"
"23382","140.25600","11.68820","-0.00011"
"23406","140.40000","11.70021","-0.00009"
"23430","140.54400","11.71223","-0.00039"
"23454","140.68800","11.72425","0.00034"
"23478","140.83200","11.73621","0.00050"
"23502","140.97600","11.74822","0.00037"
"23526","141.12000","11.76024","0.00021"
"23550","141.26400","11.77214","0.00030"
"23574","141.40800","11.78416","-0.00001"
"23598","141.55200","11.79618","-0.00007"
"23622","141.69600","11.80819","0.00073"
"23646","141.84000","11.82015","0.00033"
"23670","141.98400","11.83217","0.00058"
"23694","142.12800","11.84419","0.00050"
"23718","142.27200","11.85626","0.00034"
"23742","142.41600","11.86816","0.00009"
"23766","142.56200","11.88036","0.00003"
"23790","142.70600","11.89238","0.00008"
"23814","142.85000","11.90439","-0.00028"
"23838","142.99400","11.91635","0.00018"
"23862","143.13800","11.92837","0.00020"
"23886","143.28200","11.94039","-0.00018"
"23910","143.42600","11.95235","0.00051"
"23934","143.57000","11.96430","-0.00004"
"23958","143.71400","11.97638","-0.00014"
"23982","143.85800","11.98840","0.00049"
"24006","144.00200","12.00036","0.00013"
"24030","144.14600","12.01231","0.00024"
"24054","144.29000","12.02439","0.00026"
"24078","144.43400","12.03641","0.00020"
"24102","144.57800","12.04837","0.00009"
"24126","144.72200","12.06038","0.00041"
"24150","144.86600","12.07240","0.00026"
"24174","145.01000","12.08436","-0.00049"
"24198","145.15400","12.09632","0.00042"
"24222","145.29800","12.10834","0.00002"
"24246","145.44200","12.12035","0.00023"
"24270","145.58600","12.13237","-0.00022"
"24294","145.73000","12.14433","0.00039"
"24318","145.87400","12.15641","0.00045"
"24342","146.01800","12.16843","0.00047"
"24366","146.16200","12.18032","0.00008"
"24390","146.30600","12.19234","0.00023"
"24414","146.45000","12.20436","0.00031"
"24438","146.59400","12.21638","0.00026"
"24462","146.73800","12.22834","0.00038"
"24486","146.88200","12.24035","0.00007"
"24510","147.02600","12.25237","0.00014"
"24534","147.17000","12.26439","0.00017"
"24558","147.31400","12.27629","0.00047"
"24582","147.45800","12.28836","-0.00045"
"24606","147.60200","12.30038","0.00005"
"24630","147.74600","12.31234","0.00049"
"24654","147.89000","12.32430","0.00041"
"24678","148.03400","12.33643","0.00047"
"24702","148.17800","12.34839","0.00026"
"24726","148.32200","12.36035","0.00044"
"24750","148.46600","12.37237","0.00064"
"24774","148.61000","12.38439","0.00050"
"24798","148.75400","12.39640","0.00068"
"24822","148.89800","12.40836","0.00036"
"24846","149.04200","12.42038","0.00038"
"24870","149.18600","12.43234","-0.00018"
"24894","149.33000","12.44436","-0.00009"
"24918","149.47400","12.45631","-0.00031"
"24942","149.61800","12.46833","0.00033"
"24966","149.76200","12.48041","0.00030"
"24990","149.90600","12.49230","0.00066"
"25014","150.05000","12.50432","0.00040"
"25038","150.19400","12.51634","-0.00013"
"25062","150.33800","12.52842","0.00033"
"25086","150.48200","12.54032","0.00016"
"25110","150.62600","12.55239","0.00090"
"25134","150.77000","12.56435","0.00019"
"25158","150.91400","12.57637","0.00050"
"25182","151.05800","12.58833","0.00026"
"25206","151.20200","12.60040","-0.00015"
"25230","151.34600","12.61236","0.00084"
"25254","151.49000","12.62432","0.00002"
"25278","151.63400","12.63628","0.00026"
"25302","151.77800","12.64836","0.00015"
"25326","151.92200","12.66043","0.00024"
"25350","152.06600","12.67239","0.00029"
"25374","152.21000","12.68429","0.00023"
"25398","152.35400","12.69637","0.00073"
"25422","152.49800","12.70839","0.00024"
"25446","152.64200","12.72034","0.00013"
"25470","152.78600","12.73236","0.00014"
"25494","152.93000","12.74438","0.00026"
"25518","153.07400","12.75640","0.00053"
"25542","153.21800","12.76835","0.00054"
"25566","153.36200","12.78037","0.00024"
"25590","153.50600","12.79239","0.00048"
"25614","153.65000","12.80435","0.00060"
"25638","153.79400","12.81630","0.00028"
"25662","153.93800","12.82838","0.00064"
"25686","154.08200","12.84040","0.00045"
"25710","154.22600","12.85236","0.00093"
"25734","154.37000","12.86432","0.00010"
"25758","154.51400","12.87639","0.00040"
"25782","154.65800","12.88841","0.00053"
"25806","154.80200","12.90037","-0.00016"
"25830","154.94600","12.91233","0.00010"
"25854","155.09000","12.92441","0.00033"
"25878","155.23400","12.93642","0.00046"
"25902","155.37800","12.94832","0.00023"
"25926","155.52200","12.96040","0.00056"
"25950","155.66600","12.97235","-0.00001"
"25974","155.81000","12.98437","0.00077"
"25998","155.95400","12.99633","0.00024"
"26022","156.09800","13.00841","0.00029"
"26046","156.24200","13.02037","-0.00005"
"26070","156.38600","13.03238","0.00066"
"26094","156.53000","13.04434","0.00015"
"26118","156.67400","13.05642","0.00022"
"26142","156.81800","13.06838","0.00030"
"26166","156.96200","13.08040","0.00079"
"26190","157.10600","13.09241","0.00050"
"26214","157.25000","13.10443","-0.00014"
"26238","157.39400","13.11639","0.00048"
"26262","157.53800","13.12835","0.00029"
"26286","157.68200","13.14036","0.00090"
"26310","157.82600","13.15238","0.00082"
"26334","157.97000","13.16434","0.00005"
"26358","158.11400","13.17636","0.00037"
"26382","158.25800","13.18838","0.00027"
"26406","158.40200","13.20039","0.00052"
"26430","158.54600","13.21235","0.00029"
"26454","158.69000","13.22437","0.00040"
"26478","158.83400","13.23639","0.00099"
"26502","158.97800","13.24840","0.00013"
"26526","159.12200","13.26030","0.00068"
"26550","159.26600","13.27244","0.00038"
"26574","159.41000","13.28440","0.00052"
"26598","159.55400","13.29641","0.00080"
"26622","159.69800","13.30837","0.00068"
"26646","159.84200","13.32045","0.00101"
"26670","159.98600","13.33241","0.00027"
"26694","160.13000","13.34437","0.00051"
"26718","160.27400","13.35632","0.00078"
"26742","160.41800","13.36840","0.00041"
"26766","160.56200","13.38042","0.00075"
"26790","160.70600","13.39238","0.00081"
"26814","160.85000","13.40440","0.00021"
"26838","160.99400","13.41641","0.00017"
"26862","161.13800","13.42843","0.00058"
"26886","161.28200","13.44033","0.00083"
"26910","161.42600","13.45240","0.00069"
"26934","161.57000","13.46442","0.00047"
"26958","161.71400","13.47638","0.00047"
"26982","161.85800","13.48840","0.00068"
"27006","162.00200","13.50042","0.00037"
"27030","162.14600","13.51243","0.00049"
"27054","162.29000","13.52433","0.00074"
"27078","162.43400","13.53641","0.00070"
"27102","162.57800","13.54843","0.00074"
"27126","162.72200","13.56045","0.00052"
"27150","162.86600","13.57240","0.00033"
"27174","163.01000","13.58436","0.00089"
"27198","163.15400","13.59644","0.00026"
"27222","163.29800","13.60846","0.00098"
"27246","163.44200","13.62036","0.00113"
"27270","163.58600","13.63237","0.00059"
"27294","163.73000","13.64439","0.00018"
"27318","163.87400","13.65635","0.00041"
"27342","164.01800","13.66831","0.00096"
"27366","164.16200","13.68038","0.00073"
"27390","164.30600","13.69240","0.00086"
"27414","164.45000","13.70436","0.00115"
"27438","164.59400","13.71638","0.00065"
"27462","164.73800","13.72845","0.00085"
"27486","164.88200","13.74041","0.00092"
"27510","165.02600","13.75237","0.00044"
"27534","165.17000","13.76439","0.00042"
"27558","165.31400","13.77640","0.00109"
"27582","165.45800","13.78842","0.00055"
"27606","165.60200","13.80038","0.00053"
"27630","165.74600","13.81240","0.00073"
"27654","165.89000","13.82442","0.00119"
"27678","166.03400","13.83637","0.00082"
"27702","166.17800","13.84839","0.00100"
"27726","166.32200","13.86041","0.00077"
"27750","166.46600","13.87243","0.00052"
"27774","166.61000","13.88439","0.00071"
"27798","166.75400","13.89640","0.00113"
"27822","166.89800","13.90842","0.00091"
"27846","167.04200","13.92038","0.00046"
"27870","167.18600","13.93234","0.00064"
"27894","167.33000","13.94435","0.00113"
"27918","167.47400","13.95643","0.00122"
"27942","167.61800","13.96845","0.00072"
"27966","167.76200","13.98035","0.00015"
"27990","167.90600","13.99242","0.00107"
"28014","168.05000","14.00444","0.00153"
"28038","168.19400","14.01640","0.00057"
"28062","168.33800","14.02836","0.00108"
"28086","168.48200","14.04050","0.00041"
"28110","168.62600","14.05239","0.00074"
"28134","168.77000","14.06435","0.00106"
"28158","168.91400","14.07631","0.00046"
"28182","169.05800","14.08839","0.00074"
"28206","169.20200","14.10041","0.00016"
"28230","169.34600","14.11230","0.00065"
"28254","169.49000","14.12438","0.00100"
"28278","169.63400","14.13640","0.00087"
"28302","169.77800","14.14842","0.00082"
"28326","169.92200","14.16031","0.00075"
"28350","170.06600","14.17245","0.00115"
"28374","170.21000","14.18441","0.00062"
"28398","170.35400","14.19637","0.00098"
"28422","170.49800","14.20832","0.00085"
"28446","170.64200","14.22046","0.00077"
"28470","170.78600","14.23242","0.00079"
"28494","170.93000","14.24438","0.00067"
"28518","171.07400","14.25634","0.00086"
"28542","171.21800","14.26835","0.00012"
"28566","171.36200","14.28037","0.00101"
"28590","171.50600","14.29233","0.00142"
"28614","171.65000","14.30435","0.00071"
"28638","171.79400","14.31637","0.00098"
"28662","171.93800","14.32838","0.00028"
"28686","172.08200","14.34034","0.00098"
"28710","172.22600","14.35242","0.00114"
"28734","172.37000","14.36438","0.00075"
"28758","172.51400","14.37639","0.00119"
"28782","172.65800","14.38835","0.00080"
"28806","172.80200","14.40037","0.00111"
"28830","172.94600","14.41245","0.00036"
"28854","173.09000","14.42434","0.00100"
"28878","173.23400","14.43636","0.00087"
"28902","173.37800","14.44838","0.00101"
"28926","173.52200","14.46040","0.00127"
"28950","173.66600","14.47236","0.00093"
"28974","173.81000","14.48437","0.00094"
"28998","173.95400","14.49639","0.00064"
"29022","174.09800","14.50835","0.00073"
"29046","174.24200","14.52037","0.00095"
"29070","174.38600","14.53244","0.00093"
"29094","174.53000","14.54440","0.00116"
"29118","174.67400","14.55636","0.00069"
"29142","174.81800","14.56832","0.00060"
"29166","174.96200","14.58039","0.00079"
"29190","175.10600","14.59235","0.00054"
"29214","175.25000","14.60431","0.00069"
"29238","175.39400","14.61633","0.00075"
"29262","175.53800","14.62841","0.00064"
"29286","175.68200","14.64031","0.00054"
"29310","175.82600","14.65238","0.00082"
"29334","175.97000","14.66440","0.00087"
"29358","176.11400","14.67642","0.00082"
"29382","176.25800","14.68837","0.00115"
"29406","176.40200","14.70033","0.00066"
"29430","176.54600","14.71241","0.00103"
"29454","176.69000","14.72443","0.00111"
"29478","176.83400","14.73639","0.00073"
"29502","176.97800","14.74835","0.00059"
"29526","177.12200","14.76042","0.00083"
"29550","177.26600","14.77238","0.00073"
"29574","177.41000","14.78434","0.00070"
"29598","177.55400","14.79636","0.00117"
"29622","177.69800","14.80837","0.00066"
"29646","177.84200","14.82039","0.00057"
"29670","177.98600","14.83229","0.00076"
"29694","178.13000","14.84443","0.00075"
"29718","178.27400","14.85638","0.00146"
"29727","178.32600","14.86069","0.00062"