File: Trajectories_together/170108_2Specimen_RawData_10.csv
"","V1","V2","V3"
"1","End date","1/8/2017",""
"2","Specimen label","2DG_13",""
"3","Maximum Load","0.07742","N"
"4","Time","Extension","Load"
"5","(s)","(mm)","(N)"
"6","0.00000","0.00000","0.00295"
"54","0.28800","0.02338","0.00561"
"102","0.57600","0.04831","0.00830"
"150","0.86400","0.07223","0.01101"
"198","1.15200","0.09632","0.01317"
"246","1.44000","0.12024","0.01521"
"294","1.72800","0.14427","0.01614"
"342","2.01600","0.16819","0.01893"
"390","2.30400","0.19222","0.01928"
"438","2.59200","0.21614","0.02072"
"486","2.88000","0.24023","0.02119"
"534","3.16800","0.26421","0.02249"
"582","3.45600","0.28825","0.02291"
"630","3.74400","0.31222","0.02346"
"678","4.03200","0.33626","0.02409"
"726","4.32000","0.36023","0.02502"
"774","4.60800","0.38421","0.02537"
"822","4.89600","0.40824","0.02546"
"870","5.18400","0.43222","0.02608"
"918","5.47200","0.45625","0.02617"
"966","5.76000","0.48023","0.02690"
"1014","6.04800","0.50421","0.02710"
"1062","6.33600","0.52818","0.02741"
"1110","6.62400","0.55222","0.02782"
"1158","6.91200","0.57619","0.02816"
"1206","7.20000","0.60023","0.02820"
"1254","7.48800","0.62420","0.02891"
"1302","7.77600","0.64824","0.02890"
"1350","8.06400","0.67221","0.02926"
"1398","8.35200","0.69625","0.02920"
"1446","8.64000","0.72022","0.02970"
"1494","8.92800","0.74426","0.02968"
"1542","9.21600","0.76824","0.02987"
"1590","9.50400","0.79215","0.02979"
"1638","9.79200","0.81625","0.03029"
"1686","10.08000","0.84022","0.03070"
"1734","10.36800","0.86432","0.03099"
"1782","10.65600","0.88817","0.03132"
"1830","10.94400","0.91227","0.03170"
"1878","11.23200","0.93618","0.03168"
"1926","11.52000","0.96028","0.03227"
"1974","11.80800","0.98426","0.03212"
"2022","12.09600","1.00823","0.03272"
"2070","12.38400","1.03227","0.03282"
"2118","12.67200","1.05624","0.03308"
"2166","12.96000","1.08022","0.03352"
"2214","13.24800","1.10425","0.03351"
"2262","13.53600","1.12829","0.03402"
"2310","13.82400","1.15226","0.03439"
"2358","14.11200","1.17630","0.03513"
"2406","14.40000","1.20022","0.03507"
"2454","14.68800","1.22431","0.03551"
"2502","14.97600","1.24823","0.03534"
"2550","15.26400","1.27226","0.03609"
"2598","15.55200","1.29618","0.03617"
"2646","15.84000","1.32021","0.03668"
"2694","16.12800","1.34419","0.03696"
"2742","16.41600","1.36822","0.03717"
"2790","16.70400","1.39226","0.03764"
"2838","16.99200","1.41629","0.03772"
"2886","17.28000","1.44033","0.03808"
"2934","17.56800","1.46425","0.03860"
"2982","17.85600","1.48828","0.03882"
"3030","18.14400","1.51220","0.03942"
"3078","18.43200","1.53629","0.03957"
"3126","18.72000","1.56027","0.03989"
"3174","19.00800","1.58424","0.04047"
"3222","19.29600","1.60822","0.04053"
"3270","19.58400","1.63225","0.04130"
"3318","19.87200","1.65623","0.04125"
"3366","20.16000","1.68027","0.04183"
"3414","20.44800","1.70424","0.04192"
"3462","20.73600","1.72828","0.04238"
"3510","21.02400","1.75225","0.04276"
"3558","21.31200","1.77623","0.04316"
"3606","21.60000","1.80026","0.04353"
"3654","21.88800","1.82424","0.04396"
"3702","22.17600","1.84827","0.04353"
"3750","22.46400","1.87219","0.04446"
"3798","22.75200","1.89628","0.04461"
"3846","23.04000","1.92020","0.04475"
"3894","23.32800","1.94424","0.04488"
"3942","23.61600","1.96821","0.04523"
"3990","23.90400","1.99225","0.04596"
"4038","24.19200","2.01622","0.04552"
"4086","24.48000","2.04026","0.04572"
"4134","24.76800","2.06423","0.04645"
"4182","25.05600","2.08827","0.04623"
"4230","25.34400","2.11224","0.04661"
"4278","25.63200","2.13622","0.04638"
"4326","25.92000","2.16032","0.04676"
"4374","26.20800","2.18417","0.04678"
"4422","26.49600","2.20827","0.04685"
"4470","26.78400","2.23224","0.04735"
"4518","27.07200","2.25628","0.04718"
"4566","27.36000","2.28013","0.04710"
"4614","27.64800","2.30429","0.04797"
"4662","27.93600","2.32826","0.04781"
"4710","28.22400","2.35224","0.04784"
"4758","28.51200","2.37616","0.04771"
"4806","28.80000","2.40025","0.04853"
"4854","29.08800","2.42423","0.04776"
"4902","29.37600","2.44820","0.04775"
"4950","29.66400","2.47224","0.04842"
"4998","29.95200","2.49621","0.04827"
"5046","30.24000","2.52019","0.04892"
"5094","30.52800","2.54416","0.04869"
"5142","30.81600","2.56820","0.04838"
"5190","31.10400","2.59218","0.04848"
"5238","31.39200","2.61627","0.04863"
"5286","31.68000","2.64019","0.04914"
"5334","31.96800","2.66422","0.04918"
"5382","32.25600","2.68820","0.04935"
"5430","32.54400","2.71223","0.04946"
"5478","32.83200","2.73627","0.04958"
"5526","33.12000","2.76024","0.04908"
"5574","33.40800","2.78422","0.04922"
"5622","33.69600","2.80819","0.04958"
"5670","33.98400","2.83229","0.04966"
"5718","34.27200","2.85621","0.04957"
"5766","34.56000","2.88024","0.05001"
"5814","34.84800","2.90416","0.04996"
"5862","35.13600","2.92825","0.05043"
"5910","35.42400","2.95217","0.05018"
"5958","35.71200","2.97626","0.05013"
"6006","36.00000","3.00018","0.05054"
"6054","36.28800","3.02421","0.05086"
"6102","36.57600","3.04819","0.05053"
"6150","36.86400","3.07223","0.05026"
"6198","37.15200","3.09620","0.05081"
"6246","37.44000","3.12024","0.05056"
"6294","37.72800","3.14421","0.05082"
"6342","38.01600","3.16819","0.05081"
"6390","38.30400","3.19222","0.05105"
"6438","38.59200","3.21614","0.05139"
"6486","38.88000","3.24023","0.05108"
"6534","39.16800","3.26415","0.05083"
"6582","39.45600","3.28824","0.05098"
"6630","39.74400","3.31216","0.05148"
"6678","40.03200","3.33626","0.05165"
"6726","40.32000","3.36023","0.05179"
"6774","40.60800","3.38427","0.05174"
"6822","40.89600","3.40824","0.05143"
"6870","41.18400","3.43222","0.05172"
"6918","41.47200","3.45625","0.05178"
"6966","41.76000","3.48017","0.05210"
"7014","42.04800","3.50426","0.05189"
"7062","42.33600","3.52818","0.05170"
"7110","42.62400","3.55222","0.05241"
"7158","42.91200","3.57613","0.05217"
"7206","43.20000","3.60023","0.05240"
"7254","43.48800","3.62414","0.05101"
"7302","43.77600","3.64824","0.05110"
"7350","44.06400","3.67215","0.05114"
"7398","44.35200","3.69625","0.05153"
"7446","44.64000","3.72022","0.05219"
"7494","44.92800","3.74426","0.05235"
"7542","45.21600","3.76818","0.05159"
"7590","45.50400","3.79215","0.05229"
"7638","45.79200","3.81619","0.05228"
"7686","46.08000","3.84016","0.05216"
"7734","46.36800","3.86426","0.05252"
"7782","46.65600","3.88817","0.05257"
"7830","46.94400","3.91221","0.05333"
"7878","47.23200","3.93618","0.05294"
"7926","47.52000","3.96022","0.05281"
"7974","47.80800","3.98414","0.05307"
"8022","48.09600","4.00823","0.05258"
"8070","48.38400","4.03221","0.05312"
"8118","48.67200","4.05624","0.05311"
"8166","48.96000","4.08022","0.05292"
"8214","49.24800","4.10419","0.05362"
"8262","49.53600","4.12823","0.05301"
"8310","49.82400","4.15220","0.05316"
"8358","50.11200","4.17624","0.05304"
"8406","50.40000","4.20021","0.05320"
"8454","50.68800","4.22425","0.05307"
"8502","50.97600","4.24817","0.05312"
"8550","51.26400","4.27226","0.05329"
"8598","51.55200","4.29618","0.05321"
"8646","51.84000","4.32027","0.05369"
"8694","52.12800","4.34419","0.05407"
"8742","52.41600","4.36822","0.05352"
"8790","52.70400","4.39220","0.05344"
"8838","52.99200","4.41623","0.05358"
"8886","53.28000","4.44021","0.05338"
"8934","53.56800","4.46425","0.05302"
"8982","53.85600","4.48828","0.05374"
"9030","54.14400","4.51220","0.05406"
"9078","54.43200","4.53623","0.05396"
"9126","54.72000","4.56021","0.05392"
"9174","55.00800","4.58430","0.05370"
"9222","55.29600","4.60822","0.05404"
"9270","55.58400","4.63225","0.05413"
"9318","55.87200","4.65623","0.05430"
"9366","56.16000","4.68026","0.05384"
"9414","56.44800","4.70424","0.05411"
"9462","56.73600","4.72828","0.05426"
"9510","57.02400","4.75225","0.05406"
"9558","57.31200","4.77623","0.05489"
"9606","57.60000","4.80020","0.05380"
"9654","57.88800","4.82424","0.05420"
"9702","58.17600","4.84827","0.05432"
"9750","58.46400","4.87219","0.05402"
"9798","58.75200","4.89628","0.05420"
"9846","59.04000","4.92020","0.05396"
"9894","59.32800","4.94430","0.05373"
"9942","59.61600","4.96815","0.05369"
"9990","59.90400","4.99225","0.05275"
"10038","60.19200","5.01622","0.05355"
"10086","60.48000","5.04026","0.05326"
"10134","60.76800","5.06423","0.05312"
"10182","61.05600","5.08827","0.05342"
"10230","61.34400","5.11224","0.05313"
"10278","61.63200","5.13628","0.05332"
"10326","61.92000","5.16026","0.05364"
"10374","62.20800","5.18423","0.05413"
"10422","62.49600","5.20827","0.05383"
"10470","62.78400","5.23224","0.05350"
"10518","63.07200","5.25628","0.05379"
"10566","63.36000","5.28019","0.05360"
"10614","63.64800","5.30423","0.05385"
"10662","63.93600","5.32820","0.05373"
"10710","64.22400","5.35224","0.05287"
"10758","64.51200","5.37627","0.05295"
"10806","64.80000","5.40025","0.05304"
"10854","65.08800","5.42417","0.05308"
"10902","65.37600","5.44820","0.05330"
"10950","65.66400","5.47218","0.05321"
"10998","65.95200","5.49627","0.05367"
"11046","66.24000","5.52031","0.05310"
"11094","66.52800","5.54422","0.05373"
"11142","66.81600","5.56832","0.05358"
"11190","67.10400","5.59218","0.05339"
"11238","67.39200","5.61621","0.05189"
"11286","67.68000","5.64019","0.05066"
"11334","67.96800","5.66428","0.05052"
"11382","68.25600","5.68820","0.04961"
"11430","68.54400","5.71223","0.04927"
"11478","68.83200","5.73621","0.04917"
"11526","69.12000","5.76024","0.04919"
"11574","69.40800","5.78422","0.04931"
"11622","69.69600","5.80825","0.04898"
"11670","69.98400","5.83223","0.04905"
"11718","70.27200","5.85621","0.04948"
"11766","70.56000","5.88030","0.04991"
"11814","70.84800","5.90422","0.04912"
"11862","71.13600","5.92825","0.04905"
"11910","71.42400","5.95217","0.04941"
"11958","71.71200","5.97626","0.04985"
"12006","72.00000","6.00018","0.04927"
"12054","72.28800","6.02427","0.04975"
"12102","72.57600","6.04819","0.05018"
"12150","72.86400","6.07228","0.04926"
"12198","73.15200","6.09626","0.04950"
"12246","73.44000","6.12024","0.04962"
"12294","73.72800","6.14421","0.04977"
"12342","74.01600","6.16825","0.04945"
"12390","74.30400","6.19228","0.04982"
"12438","74.59200","6.21620","0.04977"
"12486","74.88000","6.24023","0.05003"
"12534","75.16800","6.26421","0.05024"
"12582","75.45600","6.28819","0.05017"
"12630","75.74400","6.31216","0.05016"
"12678","76.03200","6.33620","0.05005"
"12726","76.32000","6.36017","0.05052"
"12774","76.60800","6.38421","0.05008"
"12822","76.89600","6.40818","0.04932"
"12870","77.18400","6.43228","0.05047"
"12918","77.47200","6.45619","0.05009"
"12966","77.76000","6.48023","0.05020"
"13014","78.04800","6.50426","0.05072"
"13062","78.33600","6.52824","0.05009"
"13110","78.62400","6.55228","0.05093"
"13158","78.91200","6.57625","0.05089"
"13206","79.20000","6.60029","0.05028"
"13254","79.48800","6.62420","0.05068"
"13302","79.77600","6.64824","0.05047"
"13350","80.06400","6.67215","0.05054"
"13398","80.35200","6.69631","0.05042"
"13446","80.64000","6.72022","0.05092"
"13494","80.92800","6.74432","0.05107"
"13542","81.21600","6.76818","0.05073"
"13590","81.50400","6.79221","0.05063"
"13638","81.79200","6.81619","0.05107"
"13686","82.08000","6.84022","0.05138"
"13734","82.36800","6.86420","0.05094"
"13782","82.65600","6.88817","0.05142"
"13830","82.94400","6.91227","0.05111"
"13878","83.23200","6.93618","0.05090"
"13926","83.52000","6.96022","0.05085"
"13974","83.80800","6.98420","0.05061"
"14022","84.09600","7.00823","0.05077"
"14070","84.38400","7.03215","0.05104"
"14118","84.67200","7.05630","0.05075"
"14166","84.96000","7.08022","0.05143"
"14214","85.24800","7.10425","0.05088"
"14262","85.53600","7.12817","0.05127"
"14310","85.82400","7.15226","0.05126"
"14358","86.11200","7.17624","0.05095"
"14406","86.40000","7.20021","0.05115"
"14454","86.68800","7.22425","0.05129"
"14502","86.97600","7.24823","0.05145"
"14550","87.26400","7.27226","0.05126"
"14598","87.55200","7.29618","0.05157"
"14646","87.84000","7.32027","0.05154"
"14694","88.12800","7.34419","0.05149"
"14742","88.41600","7.36828","0.05125"
"14790","88.70400","7.39214","0.05125"
"14838","88.99200","7.41629","0.05148"
"14886","89.28000","7.44021","0.05073"
"14934","89.56800","7.46425","0.05165"
"14982","89.85600","7.48822","0.05109"
"15030","90.14400","7.51226","0.05159"
"15078","90.43200","7.53623","0.05182"
"15126","90.72000","7.56021","0.05183"
"15174","91.00800","7.58424","0.05194"
"15222","91.29600","7.60822","0.05161"
"15270","91.58400","7.63225","0.05135"
"15318","91.87200","7.65623","0.05127"
"15366","92.16000","7.68026","0.05189"
"15414","92.44800","7.70418","0.05184"
"15462","92.73600","7.72822","0.05193"
"15510","93.02400","7.75219","0.05184"
"15558","93.31200","7.77629","0.05166"
"15606","93.60000","7.80020","0.05203"
"15654","93.88800","7.82424","0.05222"
"15702","94.17600","7.84827","0.05189"
"15750","94.46400","7.87225","0.05216"
"15798","94.75200","7.89628","0.05161"
"15846","95.04000","7.92020","0.05236"
"15894","95.32800","7.94430","0.05191"
"15942","95.61600","7.96821","0.05232"
"15990","95.90400","7.99225","0.05227"
"16038","96.19200","8.01616","0.05196"
"16086","96.48000","8.04026","0.05195"
"16134","96.76800","8.06423","0.05219"
"16182","97.05600","8.08827","0.05177"
"16230","97.34400","8.11224","0.05262"
"16278","97.63200","8.13628","0.05216"
"16326","97.92000","8.16025","0.05198"
"16374","98.20800","8.18429","0.05276"
"16422","98.49600","8.20827","0.05198"
"16470","98.78400","8.23230","0.05207"
"16518","99.07200","8.25628","0.05187"
"16566","99.36000","8.28025","0.05202"
"16614","99.64800","8.30429","0.05254"
"16662","99.93600","8.32826","0.05242"
"16710","100.22400","8.35230","0.05228"
"16758","100.51200","8.37621","0.05203"
"16806","100.80000","8.40031","0.05252"
"16854","101.08800","8.42417","0.05211"
"16902","101.37600","8.44820","0.05236"
"16950","101.66400","8.47218","0.05235"
"16998","101.95200","8.49621","0.05215"
"17046","102.24000","8.52025","0.05145"
"17094","102.52800","8.54422","0.05251"
"17142","102.81600","8.56832","0.05250"
"17190","103.10400","8.59223","0.05198"
"17238","103.39200","8.61633","0.05259"
"17286","103.68000","8.64019","0.05213"
"17334","103.96800","8.66428","0.05246"
"17382","104.25600","8.68826","0.05206"
"17430","104.54400","8.71229","0.05257"
"17478","104.83200","8.73621","0.05235"
"17526","105.12000","8.76024","0.05202"
"17574","105.40800","8.78422","0.05225"
"17622","105.69600","8.80825","0.05225"
"17670","105.98400","8.83223","0.05299"
"17718","106.27200","8.85627","0.05274"
"17766","106.56000","8.88024","0.05260"
"17814","106.84800","8.90428","0.05267"
"17862","107.13600","8.92825","0.05252"
"17910","107.42400","8.95223","0.05248"
"17958","107.71200","8.97620","0.05226"
"18006","108.00000","9.00018","0.05282"
"18054","108.28800","9.02427","0.05261"
"18102","108.57600","9.04819","0.05234"
"18150","108.86400","9.07222","0.05248"
"18198","109.15200","9.09614","0.05267"
"18246","109.44000","9.12024","0.05223"
"18294","109.72800","9.14421","0.05211"
"18342","110.01600","9.16825","0.05234"
"18390","110.30400","9.19222","0.05220"
"18438","110.59200","9.21626","0.05221"
"18486","110.88000","9.24023","0.05271"
"18534","111.16800","9.26421","0.05241"
"18582","111.45600","9.28830","0.05256"
"18630","111.74400","9.31222","0.05274"
"18678","112.03200","9.33626","0.05195"
"18726","112.32000","9.36023","0.05257"
"18774","112.60800","9.38427","0.05278"
"18822","112.89600","9.40818","0.05232"
"18870","113.18400","9.43228","0.05212"
"18918","113.47200","9.45613","0.05199"
"18966","113.76000","9.48023","0.05207"
"19014","114.04800","9.50420","0.05238"
"19062","114.33600","9.52824","0.05243"
"19110","114.62400","9.55216","0.05222"
"19158","114.91200","9.57625","0.05187"
"19206","115.20000","9.60023","0.05223"
"19254","115.48800","9.62420","0.05263"
"19302","115.77600","9.64824","0.05264"
"19350","116.06400","9.67221","0.05279"
"19398","116.35200","9.69625","0.05287"
"19446","116.64000","9.72022","0.05238"
"19494","116.92800","9.74426","0.05235"
"19542","117.21600","9.76818","0.05253"
"19590","117.50400","9.79221","0.05251"
"19638","117.79200","9.81619","0.05256"
"19686","118.08000","9.84028","0.05282"
"19734","118.36800","9.86414","0.05203"
"19782","118.65600","9.88817","0.05212"
"19830","118.94400","9.91221","0.05205"
"19878","119.23200","9.93618","0.05243"
"19926","119.52000","9.96022","0.05215"
"19974","119.80800","9.98419","0.05195"
"20022","120.09600","10.00823","0.05228"
"20070","120.38400","10.03226","0.05248"
"20118","120.67200","10.05630","0.05235"
"20166","120.96000","10.08016","0.05194"
"20214","121.24800","10.10425","0.05211"
"20262","121.53600","10.12817","0.05220"
"20310","121.82400","10.15226","0.05253"
"20358","122.11200","10.17618","0.05229"
"20406","122.40000","10.20021","0.05292"
"20454","122.68800","10.22419","0.05235"
"20502","122.97600","10.24823","0.05221"
"20550","123.26400","10.27220","0.05207"
"20598","123.55200","10.29618","0.05281"
"20646","123.84000","10.32021","0.05207"
"20694","124.12800","10.34419","0.05246"
"20742","124.41600","10.36822","0.05272"
"20790","124.70400","10.39220","0.05213"
"20838","124.99200","10.41617","0.05255"
"20886","125.28000","10.44015","0.05256"
"20934","125.56800","10.46424","0.05247"
"20982","125.85600","10.48822","0.05266"
"21030","126.14400","10.51226","0.05234"
"21078","126.43200","10.53617","0.05248"
"21126","126.72000","10.56021","0.05288"
"21174","127.00800","10.58418","0.05233"
"21222","127.29600","10.60816","0.05238"
"21270","127.58400","10.63225","0.05259"
"21318","127.87200","10.65617","0.05317"
"21366","128.16000","10.68020","0.05251"
"21414","128.44800","10.70418","0.05283"
"21462","128.73600","10.72822","0.05247"
"21510","129.02400","10.75213","0.05269"
"21558","129.31200","10.77623","0.05284"
"21606","129.60000","10.80014","0.05267"
"21654","129.88800","10.82424","0.05260"
"21702","130.17600","10.84821","0.05266"
"21750","130.46400","10.87225","0.05283"
"21798","130.75200","10.89616","0.05264"
"21846","131.04000","10.92020","0.05245"
"21894","131.32800","10.94418","0.05267"
"21942","131.61600","10.96821","0.05291"
"21990","131.90400","10.99225","0.05300"
"22038","132.19200","11.01622","0.05283"
"22086","132.48000","11.04026","0.05288"
"22134","132.76800","11.06417","0.05303"
"22182","133.05600","11.08827","0.05258"
"22230","133.34400","11.11218","0.05266"
"22278","133.63200","11.13622","0.05274"
"22326","133.92000","11.16014","0.05233"
"22374","134.20800","11.18423","0.05263"
"22422","134.49600","11.20821","0.05223"
"22470","134.78400","11.23224","0.05213"
"22518","135.07200","11.25622","0.05265"
"22566","135.36000","11.28025","0.05238"
"22614","135.64800","11.30429","0.05237"
"22662","135.93600","11.32820","0.05288"
"22710","136.22400","11.35224","0.05265"
"22758","136.51200","11.37621","0.05275"
"22806","136.80000","11.40025","0.05252"
"22854","137.08800","11.42417","0.05271"
"22902","137.37600","11.44820","0.05271"
"22950","137.66400","11.47218","0.05288"
"22998","137.95200","11.49627","0.05280"
"23046","138.24000","11.52025","0.05269"
"23094","138.52800","11.54428","0.05224"
"23142","138.81600","11.56826","0.05271"
"23190","139.10400","11.59223","0.05279"
"23238","139.39200","11.61627","0.05287"
"23286","139.68000","11.64025","0.05254"
"23334","139.96800","11.66422","0.05277"
"23382","140.25600","11.68820","0.05135"
"23430","140.54400","11.71229","0.05107"
"23478","140.83200","11.73621","0.05139"
"23526","141.12000","11.76024","0.05165"
"23574","141.40800","11.78416","0.05075"
"23622","141.69600","11.80825","0.05144"
"23670","141.98400","11.83217","0.05209"
"23718","142.27200","11.85632","0.05169"
"23766","142.56000","11.88024","0.05180"
"23814","142.84800","11.90428","0.05161"
"23862","143.13600","11.92825","0.05239"
"23910","143.42400","11.95229","0.05207"
"23958","143.71200","11.97620","0.05225"
"24006","144.00000","12.00024","0.05187"
"24054","144.28800","12.02433","0.05195"
"24102","144.57600","12.04825","0.05225"
"24150","144.86400","12.07228","0.05158"
"24198","145.15200","12.09614","0.05188"
"24246","145.44000","12.12018","0.05185"
"24294","145.72800","12.14415","0.05249"
"24342","146.01600","12.16831","0.05221"
"24390","146.30400","12.19222","0.05249"
"24438","146.59200","12.21620","0.05204"
"24486","146.88000","12.24023","0.05228"
"24534","147.16800","12.26427","0.05240"
"24582","147.45600","12.28824","0.05193"
"24630","147.74400","12.31222","0.05223"
"24678","148.03200","12.33625","0.05222"
"24726","148.32000","12.36023","0.05239"
"24774","148.60800","12.38427","0.05224"
"24822","148.89600","12.40818","0.05211"
"24870","149.18400","12.43222","0.05237"
"24918","149.47200","12.45619","0.05248"
"24966","149.76000","12.48029","0.05237"
"25014","150.04800","12.50420","0.05250"
"25062","150.33600","12.52830","0.05241"
"25110","150.62400","12.55221","0.05201"
"25158","150.91200","12.57625","0.05246"
"25206","151.20000","12.60023","0.05187"
"25254","151.48800","12.62426","0.05236"
"25302","151.77600","12.64818","0.05293"
"25350","152.06400","12.67221","0.05237"
"25398","152.35200","12.69625","0.05279"
"25446","152.64000","12.72022","0.05249"
"25494","152.92800","12.74426","0.05256"
"25542","153.21600","12.76817","0.05237"
"25590","153.50400","12.79221","0.05287"
"25638","153.79200","12.81619","0.05210"
"25686","154.08000","12.84022","0.05258"
"25734","154.36800","12.86420","0.05267"
"25782","154.65600","12.88823","0.05272"
"25830","154.94400","12.91221","0.05229"
"25878","155.23200","12.93618","0.05217"
"25926","155.52000","12.96022","0.05287"
"25974","155.80800","12.98425","0.05312"
"26022","156.09600","13.00823","0.05297"
"26070","156.38400","13.03221","0.05306"
"26118","156.67200","13.05630","0.05275"
"26166","156.96000","13.08022","0.05325"
"26214","157.24800","13.10425","0.05276"
"26262","157.53600","13.12817","0.05262"
"26310","157.82400","13.15226","0.05290"
"26358","158.11200","13.17618","0.05281"
"26406","158.40000","13.20027","0.05265"
"26454","158.68800","13.22419","0.05282"
"26502","158.97600","13.24829","0.05240"
"26550","159.26400","13.27220","0.05342"
"26598","159.55200","13.29624","0.05358"
"26646","159.84000","13.32021","0.05317"
"26694","160.12800","13.34425","0.05296"
"26742","160.41600","13.36822","0.05291"
"26790","160.70400","13.39226","0.05292"
"26838","160.99200","13.41623","0.05312"
"26886","161.28000","13.44021","0.05293"
"26934","161.56800","13.46424","0.05251"
"26982","161.85600","13.48816","0.05275"
"27030","162.14400","13.51226","0.05312"
"27078","162.43200","13.53617","0.05337"
"27126","162.72000","13.56021","0.05322"
"27174","163.00800","13.58418","0.05363"
"27222","163.29600","13.60822","0.05300"
"27270","163.58400","13.63219","0.05286"
"27318","163.87200","13.65623","0.05360"
"27366","164.16000","13.68026","0.05367"
"27414","164.44800","13.70424","0.05323"
"27462","164.73600","13.72827","0.05346"
"27510","165.02400","13.75219","0.05348"
"27558","165.31200","13.77629","0.05330"
"27606","165.60000","13.80020","0.05367"
"27654","165.88800","13.82424","0.05352"
"27702","166.17600","13.84815","0.05332"
"27750","166.46400","13.87225","0.05375"
"27798","166.75200","13.89616","0.05368"
"27846","167.04000","13.92026","0.05364"
"27894","167.32800","13.94417","0.05351"
"27942","167.61600","13.96821","0.05365"
"27990","167.90400","13.99225","0.05364"
"28038","168.19200","14.01622","0.05370"
"28086","168.48000","14.04026","0.05389"
"28134","168.76800","14.06423","0.05399"
"28182","169.05600","14.08821","0.05377"
"28230","169.34400","14.11218","0.05407"
"28278","169.63200","14.13616","0.05436"
"28326","169.92000","14.16020","0.05347"
"28374","170.20800","14.18423","0.05389"
"28422","170.49600","14.20815","0.05401"
"28470","170.78400","14.23224","0.05412"
"28518","171.07200","14.25616","0.05423"
"28566","171.36000","14.28025","0.05414"
"28614","171.64800","14.30423","0.05465"
"28662","171.93600","14.32826","0.05441"
"28710","172.22400","14.35230","0.05410"
"28758","172.51200","14.37615","0.05397"
"28806","172.80000","14.40025","0.05432"
"28854","173.08800","14.42422","0.05396"
"28902","173.37600","14.44826","0.05448"
"28950","173.66400","14.47218","0.05462"
"28998","173.95200","14.49627","0.05456"
"29046","174.24000","14.52019","0.05459"
"29094","174.52800","14.54428","0.05454"
"29142","174.81600","14.56820","0.05431"
"29190","175.10400","14.59229","0.05500"
"29238","175.39200","14.61621","0.05500"
"29286","175.68000","14.64025","0.05467"
"29334","175.96800","14.66422","0.05453"
"29382","176.25600","14.68826","0.05444"
"29430","176.54400","14.71223","0.05534"
"29478","176.83200","14.73621","0.05470"
"29526","177.12000","14.76024","0.05470"
"29574","177.40800","14.78422","0.05435"
"29622","177.69600","14.80825","0.05437"
"29670","177.98400","14.83223","0.05471"
"29718","178.27200","14.85626","0.05444"
"29766","178.56000","14.88018","0.05468"
"29814","178.84800","14.90428","0.05508"
"29862","179.13600","14.92825","0.05495"
"29910","179.42400","14.95229","0.05511"
"29958","179.71200","14.97626","0.05522"
"30006","180.00000","15.00024","0.05498"
"30054","180.28800","15.02427","0.05531"
"30102","180.57600","15.04831","0.05549"
"30150","180.86400","15.07228","0.05549"
"30198","181.15200","15.09620","0.05503"
"30246","181.44000","15.12024","0.05510"
"30294","181.72800","15.14421","0.05506"
"30342","182.01600","15.16825","0.05507"
"30390","182.30400","15.19216","0.05594"
"30438","182.59200","15.21626","0.05539"
"30486","182.88000","15.24023","0.05565"
"30534","183.16800","15.26427","0.05572"
"30582","183.45600","15.28824","0.05578"
"30630","183.74400","15.31228","0.05569"
"30678","184.03200","15.33626","0.05417"
"30726","184.32000","15.36029","0.05444"
"30774","184.60800","15.38427","0.05439"
"30822","184.89600","15.40824","0.05443"
"30870","185.18400","15.43228","0.05421"
"30918","185.47200","15.45619","0.05447"
"30966","185.76000","15.48029","0.05476"
"31014","186.04800","15.50426","0.05502"
"31062","186.33600","15.52824","0.05505"
"31110","186.62400","15.55222","0.05502"
"31158","186.91200","15.57625","0.05536"
"31206","187.20000","15.60023","0.05507"
"31254","187.48800","15.62426","0.05542"
"31302","187.77600","15.64824","0.05556"
"31350","188.06400","15.67221","0.05563"
"31398","188.35200","15.69625","0.05597"
"31446","188.64000","15.72022","0.05557"
"31494","188.92800","15.74426","0.05597"
"31542","189.21600","15.76823","0.05604"
"31590","189.50400","15.79227","0.05579"
"31638","189.79200","15.81618","0.05661"
"31686","190.08000","15.84028","0.05638"
"31734","190.36800","15.86419","0.05646"
"31782","190.65600","15.88829","0.05585"
"31830","190.94400","15.91215","0.05662"
"31878","191.23200","15.93624","0.05648"
"31926","191.52000","15.96022","0.05684"
"31974","191.80800","15.98425","0.05693"
"32022","192.09600","16.00823","0.05689"
"32070","192.38400","16.03226","0.05722"
"32118","192.67200","16.05624","0.05727"
"32166","192.96000","16.08022","0.05750"
"32214","193.24800","16.10425","0.05746"
"32262","193.53600","16.12823","0.05797"
"32310","193.82400","16.15220","0.05801"
"32358","194.11200","16.17618","0.05819"
"32406","194.40000","16.20021","0.05784"
"32454","194.68800","16.22419","0.05855"
"32502","194.97600","16.24822","0.05843"
"32550","195.26400","16.27214","0.05846"
"32598","195.55200","16.29623","0.05845"
"32646","195.84000","16.32021","0.05893"
"32694","196.12800","16.34419","0.05906"
"32742","196.41600","16.36816","0.05900"
"32790","196.70400","16.39220","0.05920"
"32838","196.99200","16.41623","0.05919"
"32886","197.28000","16.44021","0.05957"
"32934","197.56800","16.46424","0.05993"
"32982","197.85600","16.48822","0.06014"
"33030","198.14400","16.51225","0.05955"
"33078","198.43200","16.53623","0.06016"
"33126","198.72000","16.56027","0.06046"
"33174","199.00800","16.58412","0.06078"
"33222","199.29600","16.60828","0.06111"
"33270","199.58400","16.63219","0.06115"
"33318","199.87200","16.65623","0.06104"
"33366","200.16000","16.68020","0.06132"
"33414","200.44800","16.70424","0.06161"
"33462","200.73600","16.72816","0.06218"
"33510","201.02400","16.75219","0.06233"
"33558","201.31200","16.77622","0.06215"
"33606","201.60000","16.80020","0.06273"
"33654","201.88800","16.82424","0.06335"
"33702","202.17600","16.84821","0.06365"
"33750","202.46400","16.87225","0.06334"
"33798","202.75200","16.89616","0.06305"
"33846","203.04000","16.92020","0.06312"
"33894","203.32800","16.94417","0.05625"
"33942","203.61600","16.96821","0.05727"
"33990","203.90400","16.99219","0.05914"
"34038","204.19200","17.01622","0.05838"
"34086","204.48000","17.04020","0.05896"
"34134","204.76800","17.06417","0.05994"
"34182","205.05600","17.08821","0.06010"
"34230","205.34400","17.11218","0.06014"
"34278","205.63200","17.13622","0.05968"
"34326","205.92000","17.16019","0.06072"
"34374","206.20800","17.18429","0.06231"
"34422","206.49600","17.20821","0.06148"
"34470","206.78400","17.23218","0.06308"
"34518","207.07200","17.25616","0.06301"
"34566","207.36000","17.28025","0.06327"
"34614","207.64800","17.30417","0.06395"
"34662","207.93600","17.32820","0.05812"
"34710","208.22400","17.35218","0.05532"
"34758","208.51200","17.37621","0.05389"
"34806","208.80000","17.40019","0.05407"
"34854","209.08800","17.42416","0.05474"
"34902","209.37600","17.44820","0.05442"
"34950","209.66400","17.47223","0.05483"
"34998","209.95200","17.49621","0.05497"
"35046","210.24000","17.52019","0.05541"
"35094","210.52800","17.54422","0.05538"
"35142","210.81600","17.56814","0.05615"
"35190","211.10400","17.59223","0.05551"
"35238","211.39200","17.61615","0.05602"
"35286","211.68000","17.64018","0.05518"
"35334","211.96800","17.66416","0.05567"
"35382","212.25600","17.68826","0.05560"
"35430","212.54400","17.71223","0.05632"
"35478","212.83200","17.73621","0.05596"
"35526","213.12000","17.76024","0.05590"
"35574","213.40800","17.78422","0.05684"
"35622","213.69600","17.80825","0.05705"
"35670","213.98400","17.83217","0.05624"
"35718","214.27200","17.85620","0.05697"
"35766","214.56000","17.88018","0.05766"
"35814","214.84800","17.90427","0.05712"
"35862","215.13600","17.92813","0.05747"
"35910","215.42400","17.95223","0.05724"
"35958","215.71200","17.97614","0.05799"
"36006","216.00000","18.00024","0.05812"
"36054","216.28800","18.02421","0.05813"
"36102","216.57600","18.04825","0.05834"
"36150","216.86400","18.07222","0.05837"
"36198","217.15200","18.09626","0.05871"
"36246","217.44000","18.12024","0.05967"
"36294","217.72800","18.14421","0.05933"
"36342","218.01600","18.16825","0.05923"
"36390","218.30400","18.19222","0.05918"
"36438","218.59200","18.21626","0.06014"
"36486","218.88000","18.24023","0.05979"
"36534","219.16800","18.26427","0.06029"
"36582","219.45600","18.28818","0.06028"
"36630","219.74400","18.31228","0.06063"
"36678","220.03200","18.33619","0.06117"
"36726","220.32000","18.36023","0.06105"
"36774","220.60800","18.38420","0.06173"
"36822","220.89600","18.40830","0.06124"
"36870","221.18400","18.43228","0.06193"
"36918","221.47200","18.45625","0.06175"
"36966","221.76000","18.48029","0.06228"
"37014","222.04800","18.50420","0.06265"
"37062","222.33600","18.52830","0.06131"
"37110","222.62400","18.55221","0.06084"
"37158","222.91200","18.57625","0.06083"
"37206","223.20000","18.60017","0.06220"
"37254","223.48800","18.62426","0.06197"
"37302","223.77600","18.64824","0.06323"
"37350","224.06400","18.67227","0.06300"
"37398","224.35200","18.69625","0.06313"
"37446","224.64000","18.72028","0.06320"
"37494","224.92800","18.74426","0.06350"
"37542","225.21600","18.76823","0.06446"
"37590","225.50400","18.79227","0.06419"
"37638","225.79200","18.81624","0.06510"
"37686","226.08000","18.84028","0.06524"
"37734","226.36800","18.86419","0.06521"
"37782","226.65600","18.88823","0.06595"
"37830","226.94400","18.91221","0.06527"
"37878","227.23200","18.93624","0.06650"
"37926","227.52000","18.96022","0.06653"
"37974","227.80800","18.98431","0.06731"
"38022","228.09600","19.00823","0.06752"
"38070","228.38400","19.03232","0.06791"
"38118","228.67200","19.05624","0.06828"
"38166","228.96000","19.08022","0.06825"
"38214","229.24800","19.10425","0.06802"
"38262","229.53600","19.12828","0.06903"
"38310","229.82400","19.15226","0.06898"
"38358","230.11200","19.17624","0.06929"
"38406","230.40000","19.20027","0.06967"
"38454","230.68800","19.22419","0.06996"
"38502","230.97600","19.24822","0.07076"
"38550","231.26400","19.27220","0.07048"
"38598","231.55200","19.29623","0.07072"
"38646","231.84000","19.32021","0.07087"
"38694","232.12800","19.34431","0.07111"
"38742","232.41600","19.36822","0.07140"
"38790","232.70400","19.39220","0.07204"
"38838","232.99200","19.41623","0.07151"
"38886","233.28000","19.44027","0.07231"
"38934","233.56800","19.46424","0.07256"
"38982","233.85600","19.48828","0.07306"
"39030","234.14400","19.51231","0.07301"
"39078","234.43200","19.53617","0.07312"
"39126","234.72000","19.56027","0.07339"
"39174","235.00800","19.58418","0.07374"
"39222","235.29600","19.60822","0.07369"
"39270","235.58400","19.63219","0.07448"
"39318","235.87200","19.65629","0.07433"
"39366","236.16000","19.68020","0.07471"
"39414","236.44800","19.70430","0.07490"
"39462","236.73600","19.72821","0.07517"
"39510","237.02400","19.75225","0.07516"
"39558","237.31200","19.77623","0.05522"
"39606","237.60000","19.80020","0.05237"
"39654","237.88800","19.82424","0.05074"
"39702","238.17600","19.84827","0.05384"
"39750","238.46400","19.87231","0.05080"
"39798","238.75200","19.89622","0.05308"
"39846","239.04000","19.92026","0.05087"
"39894","239.32800","19.94417","0.05173"
"39942","239.61600","19.96821","0.05126"
"39990","239.90400","19.99218","0.05162"
"40038","240.19200","20.01622","0.05209"
"40086","240.48000","20.04020","0.05205"
"40134","240.76800","20.06423","0.05205"
"40182","241.05600","20.08821","0.05172"
"40230","241.34400","20.11218","0.05237"
"40278","241.63200","20.13628","0.05228"
"40326","241.92000","20.16025","0.05228"
"40374","242.20800","20.18429","0.05232"
"40422","242.49600","20.20820","0.05225"
"40470","242.78400","20.23230","0.05217"
"40518","243.07200","20.25616","0.05307"
"40566","243.36000","20.28025","0.05268"
"40614","243.64800","20.30416","0.05262"
"40662","243.93600","20.32826","0.05317"
"40710","244.22400","20.35217","0.05311"
"40758","244.51200","20.37627","0.05331"
"40806","244.80000","20.40019","0.05373"
"40854","245.08800","20.42422","0.05347"
"40902","245.37600","20.44820","0.05356"
"40950","245.66400","20.47224","0.05353"
"40998","245.95200","20.49627","0.05364"
"41046","246.24000","20.52024","0.05337"
"41094","246.52800","20.54428","0.05341"
"41142","246.81600","20.56820","0.05359"
"41190","247.10400","20.59223","0.05407"
"41238","247.39200","20.61621","0.05418"
"41286","247.68000","20.64018","0.05395"
"41334","247.96800","20.66416","0.05381"
"41382","248.25600","20.68819","0.05383"
"41430","248.54400","20.71217","0.05413"
"41478","248.83200","20.73621","0.05432"
"41526","249.12000","20.76018","0.05457"
"41574","249.40800","20.78422","0.05428"
"41622","249.69600","20.80825","0.05452"
"41670","249.98400","20.83223","0.05420"
"41718","250.27200","20.85626","0.05433"
"41766","250.56000","20.88018","0.05462"
"41814","250.84800","20.90427","0.05477"
"41862","251.13600","20.92825","0.05448"
"41910","251.42400","20.95223","0.05485"
"41958","251.71200","20.97620","0.05483"
"42006","252.00000","21.00024","0.05464"
"42054","252.28800","21.02415","0.05488"
"42102","252.57600","21.04825","0.05527"
"42150","252.86400","21.07216","0.05483"
"42198","253.15200","21.09626","0.05537"
"42246","253.44000","21.12024","0.05513"
"42294","253.72800","21.14427","0.05533"
"42342","254.01600","21.16825","0.05544"
"42390","254.30400","21.19222","0.05575"
"42438","254.59200","21.21626","0.05522"
"42486","254.88000","21.24023","0.05571"
"42534","255.16800","21.26427","0.05571"
"42582","255.45600","21.28818","0.05528"
"42630","255.74400","21.31222","0.05531"
"42678","256.03200","21.33619","0.05552"
"42726","256.32000","21.36023","0.05549"
"42774","256.60800","21.38420","0.05503"
"42822","256.89600","21.40824","0.05578"
"42870","257.18400","21.43222","0.05511"
"42918","257.47200","21.45625","0.05580"
"42966","257.76000","21.48023","0.05548"
"43014","258.04800","21.50426","0.05553"
"43062","258.33600","21.52830","0.05560"
"43110","258.62400","21.55221","0.05550"
"43158","258.91200","21.57625","0.05547"
"43206","259.20000","21.60022","0.05551"
"43254","259.48800","21.62426","0.05537"
"43302","259.77600","21.64824","0.05597"
"43350","260.06400","21.67227","0.05541"
"43398","260.35200","21.69619","0.05557"
"43446","260.64000","21.72028","0.05620"
"43494","260.92800","21.74420","0.05613"
"43542","261.21600","21.76823","0.05576"
"43590","261.50400","21.79221","0.05570"
"43638","261.79200","21.81624","0.05618"
"43686","262.08000","21.84022","0.05514"
"43734","262.36800","21.86425","0.05536"
"43782","262.65600","21.88823","0.05636"
"43830","262.94400","21.91221","0.05605"
"43878","263.23200","21.93624","0.05563"
"43926","263.52000","21.96022","0.05597"
"43974","263.80800","21.98431","0.05659"
"44022","264.09600","22.00823","0.05632"
"44070","264.38400","22.03226","0.05622"
"44118","264.67200","22.05624","0.05634"
"44166","264.96000","22.08027","0.05630"
"44214","265.24800","22.10419","0.05577"
"44262","265.53600","22.12823","0.05621"
"44310","265.82400","22.15226","0.05626"
"44358","266.11200","22.17630","0.05643"
"44406","266.40000","22.20027","0.05594"
"44454","266.68800","22.22425","0.05628"
"44502","266.97600","22.24828","0.05617"
"44550","267.26400","22.27220","0.05581"
"44598","267.55200","22.29629","0.05629"
"44646","267.84000","22.32021","0.05615"
"44694","268.12800","22.34431","0.05647"
"44742","268.41600","22.36822","0.05647"
"44790","268.70400","22.39232","0.05697"
"44838","268.99200","22.41623","0.05634"
"44886","269.28000","22.44027","0.05670"
"44934","269.56800","22.46424","0.05635"
"44982","269.85600","22.48828","0.05679"
"45030","270.14400","22.51225","0.05664"
"45078","270.43200","22.53623","0.05721"
"45126","270.72000","22.56026","0.05676"
"45174","271.00800","22.58424","0.05666"
"45222","271.29600","22.60822","0.05671"
"45270","271.58400","22.63219","0.05593"
"45318","271.87200","22.65623","0.05657"
"45366","272.16000","22.68020","0.05580"
"45414","272.44800","22.70424","0.05598"
"45462","272.73600","22.72821","0.05599"
"45510","273.02400","22.75225","0.05633"
"45558","273.31200","22.77617","0.05596"
"45606","273.60000","22.80020","0.05563"
"45654","273.88800","22.82417","0.05597"
"45702","274.17600","22.84821","0.05590"
"45750","274.46400","22.87225","0.05560"
"45798","274.75200","22.89616","0.05576"
"45846","275.04000","22.92026","0.05606"
"45894","275.32800","22.94417","0.05590"
"45942","275.61600","22.96827","0.05632"
"45990","275.90400","22.99218","0.05608"
"46038","276.19200","23.01622","0.05663"
"46086","276.48000","23.04014","0.05652"
"46134","276.76800","23.06429","0.05686"
"46182","277.05600","23.08815","0.05704"
"46230","277.34400","23.11224","0.05664"
"46278","277.63200","23.13622","0.05654"
"46326","277.92000","23.16025","0.05667"
"46374","278.20800","23.18423","0.05641"
"46422","278.49600","23.20826","0.05658"
"46470","278.78400","23.23224","0.05640"
"46518","279.07200","23.25622","0.05654"
"46566","279.36000","23.28025","0.05640"
"46614","279.64800","23.30417","0.05650"
"46662","279.93600","23.32820","0.05703"
"46710","280.22400","23.35212","0.05677"
"46758","280.51200","23.37621","0.05736"
"46806","280.80000","23.40019","0.05699"
"46854","281.08800","23.42422","0.05750"
"46902","281.37600","23.44814","0.05734"
"46950","281.66400","23.47223","0.05772"
"46998","281.95200","23.49627","0.05748"
"47046","282.24000","23.52024","0.05671"
"47094","282.52800","23.54422","0.05665"
"47142","282.81600","23.56820","0.05729"
"47190","283.10400","23.59229","0.05753"
"47238","283.39200","23.61621","0.05725"
"47286","283.68000","23.64024","0.05616"
"47334","283.96800","23.66416","0.05893"
"47382","284.25600","23.68819","0.05366"
"47430","284.54400","23.71217","0.05350"
"47478","284.83200","23.73627","0.05446"
"47526","285.12000","23.76018","0.05605"
"47574","285.40800","23.78428","0.05409"
"47622","285.69600","23.80813","0.05455"
"47670","285.98400","23.83223","0.05497"
"47718","286.27200","23.85620","0.05588"
"47766","286.56000","23.88018","0.05421"
"47814","286.84800","23.90421","0.05534"
"47862","287.13600","23.92819","0.05520"
"47910","287.42400","23.95222","0.05527"
"47958","287.71200","23.97620","0.05491"
"48006","288.00000","24.00024","0.05576"
"48054","288.28800","24.02421","0.05618"
"48102","288.57600","24.04819","0.05577"
"48150","288.86400","24.07216","0.05518"
"48198","289.15200","24.09620","0.05640"
"48246","289.44000","24.12017","0.05638"
"48294","289.72800","24.14427","0.05662"
"48342","290.01600","24.16825","0.05586"
"48390","290.30400","24.19222","0.05635"
"48438","290.59200","24.21620","0.05645"
"48486","290.88000","24.24017","0.05708"
"48534","291.16800","24.26421","0.05651"
"48582","291.45600","24.28818","0.05721"
"48630","291.74400","24.31222","0.05663"
"48678","292.03200","24.33619","0.05726"
"48726","292.32000","24.36023","0.05662"
"48774","292.60800","24.38414","0.05739"
"48822","292.89600","24.40824","0.05636"
"48870","293.18400","24.43216","0.05647"
"48918","293.47200","24.45625","0.05617"
"48966","293.76000","24.48017","0.05670"
"49014","294.04800","24.50420","0.05698"
"49062","294.33600","24.52824","0.05650"
"49110","294.62400","24.55222","0.05654"
"49158","294.91200","24.57619","0.05726"
"49206","295.20000","24.60016","0.05693"
"49254","295.48800","24.62420","0.05673"
"49302","295.77600","24.64823","0.05742"
"49350","296.06400","24.67227","0.05767"
"49398","296.35200","24.69619","0.05728"
"49446","296.64000","24.72022","0.05716"
"49494","296.92800","24.74414","0.05764"
"49542","297.21600","24.76823","0.05781"
"49590","297.50400","24.79215","0.05821"
"49638","297.79200","24.81624","0.05766"
"49686","298.08000","24.84022","0.05877"
"49734","298.36800","24.86425","0.05834"
"49782","298.65600","24.88823","0.05859"
"49830","298.94400","24.91221","0.05849"
"49878","299.23200","24.93624","0.05958"
"49926","299.52000","24.96022","0.05861"
"49974","299.80800","24.98425","0.05861"
"50022","300.09600","25.00817","0.05825"
"50070","300.38400","25.03226","0.05820"
"50118","300.67200","25.05624","0.05863"
"50166","300.96000","25.08027","0.05839"
"50214","301.24800","25.10419","0.05864"
"50262","301.53600","25.12823","0.05853"
"50310","301.82400","25.15220","0.05853"
"50358","302.11200","25.17630","0.05825"
"50406","302.40000","25.20021","0.05868"
"50454","302.68800","25.22425","0.05930"
"50502","302.97600","25.24822","0.05912"
"50550","303.26400","25.27226","0.05937"
"50598","303.55200","25.29623","0.05927"
"50646","303.84000","25.32021","0.05932"
"50694","304.12800","25.34425","0.06017"
"50742","304.41600","25.36822","0.05989"
"50790","304.70400","25.39231","0.06010"
"50838","304.99200","25.41623","0.05978"
"50886","305.28000","25.44027","0.05988"
"50934","305.56800","25.46424","0.06046"
"50982","305.85600","25.48828","0.05982"
"51030","306.14400","25.51219","0.06025"
"51078","306.43200","25.53623","0.06066"
"51126","306.72000","25.56020","0.06097"
"51174","307.00800","25.58424","0.06061"
"51222","307.29600","25.60828","0.06155"
"51270","307.58400","25.63225","0.06056"
"51318","307.87200","25.65629","0.06024"
"51366","308.16000","25.68020","0.06099"
"51414","308.44800","25.70430","0.06028"
"51462","308.73600","25.72821","0.06032"
"51510","309.02400","25.75231","0.06079"
"51558","309.31200","25.77622","0.06114"
"51606","309.60000","25.80026","0.06065"
"51654","309.88800","25.82423","0.06084"
"51702","310.17600","25.84827","0.06127"
"51750","310.46400","25.87219","0.06154"
"51798","310.75200","25.89622","0.06217"
"51846","311.04000","25.92026","0.06169"
"51894","311.32800","25.94423","0.06246"
"51942","311.61600","25.96827","0.06242"
"51990","311.90400","25.99224","0.06311"
"52038","312.19200","26.01628","0.06315"
"52086","312.48000","26.04020","0.06297"
"52134","312.76800","26.06423","0.06332"
"52182","313.05600","26.08815","0.06303"
"52230","313.34400","26.11224","0.06346"
"52278","313.63200","26.13622","0.06352"
"52326","313.92000","26.16025","0.06354"
"52374","314.20800","26.18423","0.06400"
"52422","314.49600","26.20827","0.06376"
"52470","314.78400","26.23224","0.06436"
"52518","315.07200","26.25628","0.06387"
"52566","315.36000","26.28025","0.06484"
"52614","315.64800","26.30423","0.06456"
"52662","315.93600","26.32826","0.06455"
"52710","316.22400","26.35218","0.06432"
"52758","316.51200","26.37627","0.06490"
"52806","316.80000","26.40019","0.06556"
"52854","317.08800","26.42429","0.06534"
"52902","317.37600","26.44820","0.06616"
"52950","317.66400","26.47223","0.06585"
"52998","317.95200","26.49621","0.06652"
"53046","318.24000","26.52030","0.06644"
"53094","318.52800","26.54422","0.06680"
"53142","318.81600","26.56826","0.06672"
"53190","319.10400","26.59223","0.06703"
"53238","319.39200","26.61627","0.06743"
"53286","319.68000","26.64024","0.06707"
"53334","319.96800","26.66422","0.06766"
"53382","320.25600","26.68831","0.06789"
"53430","320.54400","26.71217","0.06763"
"53478","320.83200","26.73620","0.06790"
"53526","321.12000","26.76018","0.06848"
"53574","321.40800","26.78422","0.06844"
"53622","321.69600","26.80819","0.06874"
"53670","321.98400","26.83229","0.06878"
"53718","322.27200","26.85620","0.06913"
"53766","322.56000","26.88024","0.06943"
"53814","322.84800","26.90421","0.06973"
"53862","323.13600","26.92825","0.07009"
"53910","323.42400","26.95229","0.07044"
"53958","323.71200","26.97626","0.07028"
"54006","324.00000","27.00023","0.07096"
"54054","324.28800","27.02415","0.07044"
"54102","324.57600","27.04825","0.07144"
"54150","324.86400","27.07222","0.07140"
"54198","325.15200","27.09620","0.07210"
"54246","325.44000","27.12017","0.07179"
"54294","325.72800","27.14427","0.07257"
"54342","326.01600","27.16819","0.07211"
"54390","326.30400","27.19228","0.07258"
"54438","326.59200","27.21620","0.07284"
"54486","326.88000","27.24023","0.07313"
"54534","327.16800","27.26427","0.07320"
"54582","327.45600","27.28818","0.07317"
"54630","327.74400","27.31228","0.07311"
"54678","328.03200","27.33619","0.07349"
"54726","328.32000","27.36023","0.07348"
"54774","328.60800","27.38420","0.07386"
"54822","328.89600","27.40824","0.07404"
"54870","329.18400","27.43216","0.07430"
"54918","329.47200","27.45619","0.07444"
"54966","329.76000","27.48017","0.07444"
"55014","330.04800","27.50426","0.07464"
"55062","330.33600","27.52818","0.07486"
"55110","330.62400","27.55227","0.07498"
"55158","330.91200","27.57619","0.07515"
"55206","331.20000","27.60028","0.07538"
"55254","331.48800","27.62426","0.07568"
"55302","331.77600","27.64824","0.07570"
"55350","332.06400","27.67221","0.07600"
"55398","332.35200","27.69618","0.07614"
"55446","332.64000","27.72022","0.07634"
"55494","332.92800","27.74420","0.07643"
"55542","333.21600","27.76823","0.07681"
"55590","333.50400","27.79215","0.07680"
"55638","333.79200","27.81624","0.07736"
"55686","334.08000","27.84016","0.07528"
"55734","334.36800","27.86426","0.06950"
"55782","334.65600","27.88823","0.05925"
"55830","334.94400","27.91227","0.05706"
"55878","335.23200","27.93624","0.06243"
"55926","335.52000","27.96022","0.06219"
"55974","335.80800","27.98425","0.06159"
"56022","336.09600","28.00817","0.06356"
"56070","336.38400","28.03226","0.06158"
"56118","336.67200","28.05618","0.06117"
"56166","336.96000","28.08027","0.06349"
"56214","337.24800","28.10419","0.06373"
"56262","337.53600","28.12829","0.06333"
"56310","337.82400","28.15220","0.06337"
"56358","338.11200","28.17624","0.06403"
"56406","338.40000","28.20015","0.06295"
"56454","338.68800","28.22425","0.06379"
"56502","338.97600","28.24822","0.06596"
"56550","339.26400","28.27226","0.06516"
"56598","339.55200","28.29623","0.06365"
"56646","339.84000","28.32027","0.06635"
"56694","340.12800","28.34424","0.06535"
"56742","340.41600","28.36822","0.06491"
"56790","340.70400","28.39226","0.06663"
"56838","340.99200","28.41623","0.06669"
"56886","341.28000","28.44027","0.06625"
"56934","341.56800","28.46418","0.06720"
"56982","341.85600","28.48822","0.06771"
"57030","342.14400","28.51225","0.06814"
"57078","342.43200","28.53623","0.06778"
"57126","342.72000","28.56021","0.06840"
"57174","343.00800","28.58424","0.06919"
"57222","343.29600","28.60822","0.06892"
"57270","343.58400","28.63225","0.06926"
"57318","343.87200","28.65628","0.06894"
"57366","344.16000","28.68026","0.06974"
"57414","344.44800","28.70430","0.06989"
"57462","344.73600","28.72821","0.06996"
"57510","345.02400","28.75231","0.07038"
"57558","345.31200","28.77622","0.07038"
"57606","345.60000","28.80026","0.07051"
"57654","345.88800","28.82424","0.07117"
"57702","346.17600","28.84827","0.07055"
"57750","346.46400","28.87219","0.07135"
"57798","346.75200","28.89622","0.07189"
"57846","347.04000","28.92020","0.07164"
"57894","347.32800","28.94429","0.07218"
"57942","347.61600","28.96827","0.07224"
"57990","347.90400","28.99224","0.07241"
"58038","348.19200","29.01622","0.07251"
"58086","348.48000","29.04026","0.07283"
"58134","348.76800","29.06429","0.07296"
"58182","349.05600","29.08821","0.07317"
"58230","349.34400","29.11230","0.07313"
"58278","349.63200","29.13622","0.07366"
"58326","349.92000","29.16025","0.07349"
"58374","350.20800","29.18423","0.07359"
"58422","350.49600","29.20827","0.07387"
"58470","350.78400","29.23224","0.07422"
"58518","351.07200","29.25621","0.07428"
"58566","351.36000","29.28019","0.07447"
"58614","351.64800","29.30423","0.07482"
"58662","351.93600","29.32820","0.07469"
"58710","352.22400","29.35224","0.07492"
"58758","352.51200","29.37627","0.07454"
"58806","352.80000","29.40025","0.07286"
"58854","353.08800","29.42428","0.04791"
"58902","353.37600","29.44814","0.04514"
"58950","353.66400","29.47230","0.04446"
"58998","353.95200","29.49615","0.04464"
"59046","354.24000","29.52024","0.04482"
"59094","354.52800","29.54416","0.04511"
"59142","354.81600","29.56825","0.04460"
"59190","355.10400","29.59223","0.04491"
"59238","355.39200","29.61627","0.04487"
"59261","355.52600","29.62739","0.04494"