File: Trajectories_together/170107_1Specimen_RawData_3.csv
"","V1","V2","V3"
"1","End date","1/7/2017",""
"2","Specimen label","18_CTNT2",""
"3","Maximum Load","0.07079","N"
"4","Time","Extension","Load"
"5","(s)","(mm)","(N)"
"6","0.00000","0.00006","-0.00038"
"43","0.22200","0.01632","-0.00044"
"80","0.44400","0.03725","-0.00032"
"117","0.66600","0.05572","0.00018"
"154","0.88800","0.07420","-0.00020"
"191","1.11000","0.09267","0.00014"
"228","1.33200","0.11115","0.00009"
"265","1.55400","0.12968","0.00011"
"302","1.77600","0.14822","0.00036"
"339","1.99800","0.16669","0.00032"
"376","2.22000","0.18517","0.00027"
"413","2.44200","0.20370","0.00020"
"450","2.66400","0.22212","0.00014"
"487","2.88600","0.24071","-0.00029"
"524","3.10800","0.25919","0.00011"
"561","3.33000","0.27766","0.00026"
"598","3.55200","0.29620","0.00053"
"635","3.77400","0.31467","0.00041"
"672","3.99600","0.33315","0.00028"
"709","4.21800","0.35162","0.00036"
"746","4.44000","0.37016","0.00057"
"783","4.66200","0.38869","0.00025"
"820","4.88400","0.40711","0.00029"
"857","5.10600","0.42564","0.00084"
"894","5.32800","0.44412","0.00056"
"931","5.55000","0.46271","0.00044"
"968","5.77200","0.48119","0.00037"
"1005","5.99400","0.49966","0.00076"
"1042","6.21600","0.51826","0.00048"
"1079","6.43800","0.53661","0.00049"
"1116","6.66000","0.55527","-0.00014"
"1153","6.88200","0.57368","0.00101"
"1190","7.10400","0.59222","0.00053"
"1227","7.32600","0.61063","0.00069"
"1264","7.54800","0.62917","0.00053"
"1301","7.77000","0.64770","0.00061"
"1338","7.99200","0.66618","0.00015"
"1375","8.21400","0.68471","0.00040"
"1412","8.43600","0.70312","0.00054"
"1449","8.65800","0.72166","0.00031"
"1486","8.88000","0.74019","0.00039"
"1523","9.10200","0.75861","0.00081"
"1560","9.32400","0.77720","0.00001"
"1597","9.54600","0.79568","0.00070"
"1634","9.76800","0.81415","0.00029"
"1671","9.99000","0.83269","0.00073"
"1708","10.21200","0.85110","0.00031"
"1745","10.43400","0.86970","0.00026"
"1782","10.65600","0.88817","0.00021"
"1819","10.87800","0.90665","0.00068"
"1856","11.10000","0.92524","0.00023"
"1893","11.32200","0.94360","0.00038"
"1930","11.54400","0.96225","0.00025"
"1967","11.76600","0.98061","0.00054"
"2004","11.98800","0.99920","0.00047"
"2041","12.21000","1.01768","0.00021"
"2078","12.43200","1.03615","0.00037"
"2115","12.65400","1.05475","0.00033"
"2152","12.87600","1.07310","0.00062"
"2189","13.09800","1.09164","0.00074"
"2226","13.32000","1.11017","0.00024"
"2263","13.54200","1.12865","0.00026"
"2300","13.76400","1.14718","0.00020"
"2337","13.98600","1.16566","0.00028"
"2374","14.20800","1.18413","0.00007"
"2411","14.43000","1.20267","0.00062"
"2448","14.65200","1.22114","0.00047"
"2485","14.87400","1.23968","0.00004"
"2522","15.09600","1.25809","0.00063"
"2559","15.31800","1.27669","0.00065"
"2596","15.54000","1.29516","0.00027"
"2633","15.76200","1.31364","0.00056"
"2670","15.98400","1.33217","0.00033"
"2707","16.20600","1.35059","0.00057"
"2744","16.42800","1.36918","0.00106"
"2781","16.65000","1.38766","0.00071"
"2818","16.87200","1.40625","0.00089"
"2855","17.09400","1.42466","0.00057"
"2892","17.31600","1.44314","0.00079"
"2929","17.53800","1.46167","0.00065"
"2966","17.76000","1.48009","0.00064"
"3003","17.98200","1.49868","0.00100"
"3040","18.20400","1.51716","0.00024"
"3077","18.42600","1.53569","0.00013"
"3114","18.64800","1.55417","0.00049"
"3151","18.87000","1.57270","0.00064"
"3188","19.09200","1.59118","0.00029"
"3225","19.31400","1.60965","0.00017"
"3262","19.53600","1.62819","0.00069"
"3299","19.75800","1.64666","0.00059"
"3336","19.98000","1.66514","0.00020"
"3373","20.20200","1.68373","0.00059"
"3410","20.42400","1.70215","0.00072"
"3447","20.64600","1.72074","0.00118"
"3484","20.86800","1.73916","0.00022"
"3521","21.09000","1.75763","0.00063"
"3558","21.31200","1.77623","0.00012"
"3595","21.53400","1.79458","0.00014"
"3632","21.75600","1.81318","0.00116"
"3669","21.97800","1.83165","0.00011"
"3706","22.20000","1.85019","0.00072"
"3743","22.42200","1.86872","0.00000"
"3780","22.64400","1.88714","0.00096"
"3817","22.86600","1.90573","0.00079"
"3854","23.08800","1.92415","0.00047"
"3891","23.31000","1.94268","0.00105"
"3928","23.53200","1.96116","0.00035"
"3965","23.75400","1.97969","0.00019"
"4002","23.97600","1.99817","0.00088"
"4039","24.19800","2.01658","0.00106"
"4076","24.42000","2.03524","0.00061"
"4113","24.64200","2.05365","0.00084"
"4150","24.86400","2.07213","0.00052"
"4187","25.08600","2.09066","0.00054"
"4224","25.30800","2.10914","0.00042"
"4261","25.53000","2.12767","0.00037"
"4298","25.75200","2.14609","0.00067"
"4335","25.97400","2.16468","0.00030"
"4372","26.19600","2.18315","0.00039"
"4409","26.41800","2.20163","0.00103"
"4446","26.64000","2.22016","0.00058"
"4483","26.86200","2.23864","0.00009"
"4520","27.08400","2.25717","0.00073"
"4557","27.30600","2.27571","0.00070"
"4594","27.52800","2.29412","0.00063"
"4631","27.75000","2.31272","0.00089"
"4668","27.97200","2.33107","0.00054"
"4705","28.19400","2.34967","0.00078"
"4742","28.41600","2.36814","0.00071"
"4779","28.63800","2.38668","0.00051"
"4816","28.86000","2.40521","0.00001"
"4853","29.08200","2.42357","0.00080"
"4890","29.30400","2.44222","0.00035"
"4927","29.52600","2.46064","0.00071"
"4964","29.74800","2.47917","0.00070"
"5001","29.97000","2.49765","0.00101"
"5038","30.19200","2.51612","0.00120"
"5075","30.41400","2.53472","0.00058"
"5112","30.63600","2.55313","0.00115"
"5149","30.85800","2.57167","0.00098"
"5186","31.08000","2.59020","0.00078"
"5223","31.30200","2.60862","0.00073"
"5260","31.52400","2.62721","0.00093"
"5297","31.74600","2.64563","0.00072"
"5334","31.96800","2.66416","0.00044"
"5371","32.19000","2.68270","0.00083"
"5408","32.41200","2.70117","0.00063"
"5445","32.63400","2.71971","0.00069"
"5482","32.85600","2.73806","0.00140"
"5519","33.07800","2.75672","0.00072"
"5556","33.30000","2.77513","0.00047"
"5593","33.52200","2.79367","0.00072"
"5630","33.74400","2.81214","0.00074"
"5667","33.96600","2.83068","0.00111"
"5704","34.18800","2.84921","0.00041"
"5741","34.41000","2.86763","0.00103"
"5778","34.63200","2.88622","0.00093"
"5815","34.85400","2.90464","0.00072"
"5852","35.07600","2.92317","0.00047"
"5889","35.29800","2.94165","0.00128"
"5926","35.52000","2.96012","0.00088"
"5963","35.74200","2.97865","0.00124"
"6000","35.96400","2.99713","0.00087"
"6037","36.18600","3.01572","0.00097"
"6074","36.40800","3.03414","0.00141"
"6111","36.63000","3.05267","0.00107"
"6148","36.85200","3.07115","0.00119"
"6185","37.07400","3.08968","0.00090"
"6222","37.29600","3.10822","0.00098"
"6259","37.51800","3.12669","0.00081"
"6296","37.74000","3.14517","0.00122"
"6333","37.96200","3.16370","0.00069"
"6370","38.18400","3.18212","0.00117"
"6407","38.40600","3.20071","0.00076"
"6444","38.62800","3.21913","0.00101"
"6481","38.85000","3.23766","0.00068"
"6518","39.07200","3.25626","0.00089"
"6555","39.29400","3.27461","0.00131"
"6592","39.51600","3.29327","0.00172"
"6629","39.73800","3.31162","0.00142"
"6666","39.96000","3.33016","0.00164"
"6703","40.18200","3.34869","0.00142"
"6740","40.40400","3.36717","0.00087"
"6777","40.62600","3.38564","0.00131"
"6814","40.84800","3.40412","0.00132"
"6851","41.07000","3.42271","0.00032"
"6888","41.29200","3.44119","0.00150"
"6925","41.51400","3.45966","0.00119"
"6962","41.73600","3.47820","0.00124"
"6999","41.95800","3.49667","0.00107"
"7036","42.18000","3.51521","0.00161"
"7073","42.40200","3.53368","0.00134"
"7110","42.62400","3.55222","0.00072"
"7147","42.84600","3.57069","0.00116"
"7184","43.06800","3.58911","0.00100"
"7221","43.29000","3.60764","0.00103"
"7258","43.51200","3.62612","0.00143"
"7295","43.73400","3.64465","0.00175"
"7332","43.95600","3.66319","0.00123"
"7369","44.17800","3.68166","0.00106"
"7406","44.40000","3.70019","0.00129"
"7443","44.62200","3.71861","0.00111"
"7480","44.84400","3.73720","0.00134"
"7517","45.06600","3.75568","0.00172"
"7554","45.28800","3.77415","0.00153"
"7591","45.51000","3.79269","0.00177"
"7628","45.73200","3.81110","0.00133"
"7665","45.95400","3.82976","0.00149"
"7702","46.17600","3.84817","0.00156"
"7739","46.39800","3.86671","0.00144"
"7776","46.62000","3.88518","0.00169"
"7813","46.84200","3.90366","0.00136"
"7850","47.06400","3.92219","0.00115"
"7887","47.28600","3.94061","0.00136"
"7924","47.50800","3.95914","0.00173"
"7961","47.73000","3.97768","0.00155"
"7998","47.95200","3.99615","0.00096"
"8035","48.17400","4.01469","0.00139"
"8072","48.39600","4.03316","0.00131"
"8109","48.61800","4.05170","0.00115"
"8146","48.84000","4.07023","0.00182"
"8183","49.06200","4.08871","0.00184"
"8220","49.28400","4.10724","0.00160"
"8257","49.50600","4.12560","0.00182"
"8294","49.72800","4.14419","0.00103"
"8331","49.95000","4.16267","0.00210"
"8368","50.17200","4.18120","0.00125"
"8405","50.39400","4.19968","0.00109"
"8442","50.61600","4.21815","0.00213"
"8479","50.83800","4.23669","0.00157"
"8516","51.06000","4.25516","0.00169"
"8553","51.28200","4.27376","0.00159"
"8590","51.50400","4.29211","0.00146"
"8627","51.72600","4.31065","0.00208"
"8664","51.94800","4.32918","0.00208"
"8701","52.17000","4.34766","0.00163"
"8738","52.39200","4.36619","0.00121"
"8775","52.61400","4.38461","0.00152"
"8812","52.83600","4.40320","0.00191"
"8849","53.05800","4.42173","0.00152"
"8886","53.28000","4.44009","0.00147"
"8923","53.50200","4.45868","0.00178"
"8960","53.72400","4.47716","0.00198"
"8997","53.94600","4.49569","0.00171"
"9034","54.16800","4.51423","0.00208"
"9071","54.39000","4.53264","0.00208"
"9108","54.61200","4.55118","0.00164"
"9145","54.83400","4.56959","0.00159"
"9182","55.05600","4.58825","0.00235"
"9219","55.27800","4.60666","0.00221"
"9256","55.50000","4.62514","0.00177"
"9293","55.72200","4.64373","0.00223"
"9330","55.94400","4.66209","0.00175"
"9367","56.16600","4.68068","0.00193"
"9404","56.38800","4.69910","0.00146"
"9441","56.61000","4.71763","0.00200"
"9478","56.83200","4.73623","0.00195"
"9515","57.05400","4.75464","0.00208"
"9552","57.27600","4.77318","0.00230"
"9589","57.49800","4.79165","0.00112"
"9626","57.72000","4.81019","0.00202"
"9663","57.94200","4.82866","0.00195"
"9700","58.16400","4.84714","0.00194"
"9737","58.38600","4.86567","0.00191"
"9774","58.60800","4.88415","0.00216"
"9811","58.83000","4.90268","0.00189"
"9848","59.05200","4.92122","0.00165"
"9885","59.27400","4.93963","0.00212"
"9922","59.49600","4.95817","0.00184"
"9959","59.71800","4.97664","0.00195"
"9996","59.94000","4.99518","0.00202"
"10033","60.16200","5.01365","0.00185"
"10070","60.38400","5.03213","0.00203"
"10107","60.60600","5.05072","0.00173"
"10144","60.82800","5.06914","0.00195"
"10181","61.05000","5.08773","0.00214"
"10218","61.27200","5.10615","0.00218"
"10255","61.49400","5.12474","0.00231"
"10292","61.71600","5.14316","0.00210"
"10329","61.93800","5.16169","0.00168"
"10366","62.16000","5.18017","0.00217"
"10403","62.38200","5.19870","0.00224"
"10440","62.60400","5.21718","0.00197"
"10477","62.82600","5.23565","0.00170"
"10514","63.04800","5.25418","0.00211"
"10551","63.27000","5.27266","0.00201"
"10588","63.49200","5.29113","0.00197"
"10625","63.71400","5.30967","0.00201"
"10662","63.93600","5.32820","0.00231"
"10699","64.15800","5.34668","0.00196"
"10736","64.38000","5.36515","0.00246"
"10773","64.60200","5.38363","0.00267"
"10810","64.82400","5.40216","0.00172"
"10847","65.04600","5.42064","0.00202"
"10884","65.26800","5.43917","0.00242"
"10921","65.49000","5.45771","0.00245"
"10958","65.71200","5.47612","0.00255"
"10995","65.93400","5.49466","0.00236"
"11032","66.15600","5.51313","0.00244"
"11069","66.37800","5.53167","0.00211"
"11106","66.60000","5.55014","0.00218"
"11143","66.82200","5.56862","0.00184"
"11180","67.04400","5.58715","0.00154"
"11217","67.26600","5.60563","0.00197"
"11254","67.48800","5.62422","0.00176"
"11291","67.71000","5.64264","0.00131"
"11328","67.93200","5.66117","0.00217"
"11365","68.15400","5.67965","0.00135"
"11402","68.37600","5.69818","0.00181"
"11439","68.59800","5.71666","0.00179"
"11476","68.82000","5.73513","0.00200"
"11513","69.04200","5.75367","0.00191"
"11550","69.26400","5.77214","0.00144"
"11587","69.48600","5.79068","0.00205"
"11624","69.70800","5.80921","0.00236"
"11661","69.93000","5.82763","0.00179"
"11698","70.15200","5.84622","0.00210"
"11735","70.37400","5.86470","0.00184"
"11772","70.59600","5.88317","0.00202"
"11809","70.81800","5.90170","0.00190"
"11846","71.04000","5.92006","0.00230"
"11883","71.26200","5.93866","0.00179"
"11920","71.48400","5.95713","0.00159"
"11957","71.70600","5.97572","0.00241"
"11994","71.92800","5.99420","0.00200"
"12031","72.15000","6.01261","0.00230"
"12068","72.37200","6.03121","0.00178"
"12105","72.59400","6.04962","0.00237"
"12142","72.81600","6.06822","0.00196"
"12179","73.03800","6.08663","0.00245"
"12216","73.26000","6.10517","0.00238"
"12253","73.48200","6.12370","0.00281"
"12290","73.70400","6.14212","0.00251"
"12327","73.92600","6.16065","0.00262"
"12364","74.14800","6.17919","0.00231"
"12401","74.37000","6.19766","0.00242"
"12438","74.59200","6.21620","0.00224"
"12475","74.81400","6.23467","0.00251"
"12512","75.03600","6.25315","0.00290"
"12549","75.25800","6.27168","0.00249"
"12586","75.48000","6.29016","0.00208"
"12623","75.70200","6.30869","0.00228"
"12660","75.92400","6.32711","0.00267"
"12697","76.14600","6.34570","0.00236"
"12734","76.36800","6.36412","0.00328"
"12771","76.59000","6.38265","0.00216"
"12808","76.81200","6.40119","0.00273"
"12845","77.03400","6.41966","0.00279"
"12882","77.25600","6.43820","0.00176"
"12919","77.47800","6.45661","0.00207"
"12956","77.70000","6.47521","0.00332"
"12993","77.92200","6.49362","0.00274"
"13030","78.14400","6.51216","0.00298"
"13067","78.36600","6.53069","0.00268"
"13104","78.58800","6.54911","0.00257"
"13141","78.81000","6.56770","0.00287"
"13178","79.03200","6.58612","0.00128"
"13215","79.25400","6.60471","0.00122"
"13252","79.47600","6.62319","0.00188"
"13289","79.69800","6.64172","0.00125"
"13326","79.92000","6.66019","0.00171"
"13363","80.14200","6.67867","0.00179"
"13400","80.36400","6.69721","0.00125"
"13437","80.58600","6.71568","0.00176"
"13474","80.80800","6.73416","0.00145"
"13511","81.03000","6.75269","0.00152"
"13548","81.25200","6.77111","0.00138"
"13585","81.47400","6.78970","0.00143"
"13622","81.69600","6.80811","0.00139"
"13659","81.91800","6.82665","0.00155"
"13696","82.14000","6.84524","0.00111"
"13733","82.36200","6.86360","0.00193"
"13770","82.58400","6.88219","0.00199"
"13807","82.80600","6.90061","0.00167"
"13844","83.02800","6.91920","0.00151"
"13881","83.25000","6.93774","0.00178"
"13918","83.47200","6.95615","0.00163"
"13955","83.69400","6.97469","0.00155"
"13992","83.91600","6.99310","0.00158"
"14029","84.13800","7.01176","0.00216"
"14066","84.36000","7.03017","0.00206"
"14103","84.58200","7.04871","0.00213"
"14140","84.80400","7.06718","0.00204"
"14177","85.02600","7.08566","0.00211"
"14214","85.24800","7.10425","0.00231"
"14251","85.47000","7.12267","0.00226"
"14288","85.69200","7.14120","0.00245"
"14325","85.91400","7.15968","0.00208"
"14362","86.13600","7.17815","0.00209"
"14399","86.35800","7.19669","0.00236"
"14436","86.58000","7.21516","0.00207"
"14473","86.80200","7.23370","0.00246"
"14510","87.02400","7.25217","0.00251"
"14547","87.24600","7.27065","0.00243"
"14584","87.46800","7.28918","0.00289"
"14621","87.69000","7.30760","0.00294"
"14658","87.91200","7.32619","0.00339"
"14695","88.13400","7.34467","0.00258"
"14732","88.35600","7.36320","0.00284"
"14769","88.57800","7.38174","0.00287"
"14806","88.80000","7.40009","0.00286"
"14843","89.02200","7.41868","0.00304"
"14880","89.24400","7.43716","0.00281"
"14917","89.46600","7.45570","0.00303"
"14954","89.68800","7.47417","0.00356"
"14991","89.91000","7.49264","0.00246"
"15028","90.13200","7.51118","0.00362"
"15065","90.35400","7.52959","0.00338"
"15102","90.57600","7.54819","0.00296"
"15139","90.79800","7.56666","0.00347"
"15176","91.02000","7.58520","0.00340"
"15213","91.24200","7.60367","0.00355"
"15250","91.46400","7.62215","0.00289"
"15287","91.68600","7.64062","0.00316"
"15324","91.90800","7.65922","0.00404"
"15361","92.13000","7.67763","0.00361"
"15398","92.35200","7.69623","0.00338"
"15435","92.57400","7.71458","0.00394"
"15472","92.79600","7.73318","0.00329"
"15509","93.01800","7.75171","0.00334"
"15546","93.24000","7.77019","0.00375"
"15583","93.46200","7.78872","0.00361"
"15620","93.68400","7.80714","0.00389"
"15657","93.90600","7.82573","0.00371"
"15694","94.12800","7.84415","0.00393"
"15731","94.35000","7.86268","0.00342"
"15768","94.57200","7.88110","0.00392"
"15805","94.79400","7.89963","0.00394"
"15842","95.01600","7.91817","0.00419"
"15879","95.23800","7.93664","0.00380"
"15916","95.46000","7.95524","0.00399"
"15953","95.68200","7.97359","0.00363"
"15990","95.90400","7.99219","0.00425"
"16027","96.12600","8.01066","0.00376"
"16064","96.34800","8.02914","0.00433"
"16101","96.57000","8.04761","0.00428"
"16138","96.79200","8.06609","0.00451"
"16175","97.01400","8.08468","0.00427"
"16212","97.23600","8.10322","0.00447"
"16249","97.45800","8.12163","0.00481"
"16286","97.68000","8.14023","0.00484"
"16323","97.90200","8.15864","0.00464"
"16360","98.12400","8.17723","0.00505"
"16397","98.34600","8.19565","0.00469"
"16434","98.56800","8.21418","0.00433"
"16471","98.79000","8.23272","0.00375"
"16508","99.01200","8.25107","0.00439"
"16545","99.23400","8.26967","0.00403"
"16582","99.45600","8.28814","0.00435"
"16619","99.67800","8.30668","0.00456"
"16656","99.90000","8.32515","0.00523"
"16693","100.12200","8.34363","0.00406"
"16730","100.34400","8.36222","0.00527"
"16767","100.56600","8.38064","0.00454"
"16804","100.78800","8.39917","0.00490"
"16841","101.01000","8.41765","0.00472"
"16878","101.23200","8.43618","0.00501"
"16915","101.45400","8.45466","0.00506"
"16952","101.67600","8.47313","0.00534"
"16989","101.89800","8.49167","0.00469"
"17026","102.12000","8.51014","0.00491"
"17063","102.34200","8.52868","0.00527"
"17100","102.56400","8.54721","0.00513"
"17137","102.78600","8.56563","0.00540"
"17174","103.00800","8.58416","0.00556"
"17211","103.23000","8.60270","0.00563"
"17248","103.45200","8.62117","0.00572"
"17285","103.67400","8.63971","0.00591"
"17322","103.89600","8.65812","0.00516"
"17359","104.11800","8.67672","0.00583"
"17396","104.34000","8.69513","0.00561"
"17433","104.56200","8.71373","0.00543"
"17470","104.78400","8.73220","0.00562"
"17507","105.00600","8.75068","0.00529"
"17544","105.22800","8.76921","0.00600"
"17581","105.45000","8.78763","0.00559"
"17618","105.67200","8.80622","0.00550"
"17655","105.89400","8.82470","0.00610"
"17692","106.11600","8.84317","0.00577"
"17729","106.33800","8.86171","0.00666"
"17766","106.56000","8.88012","0.00584"
"17803","106.78200","8.89872","0.00606"
"17840","107.00400","8.91713","0.00648"
"17877","107.22600","8.93567","0.00459"
"17914","107.44800","8.95414","0.00441"
"17951","107.67000","8.97267","0.00512"
"17988","107.89200","8.99121","0.00475"
"18025","108.11400","9.00968","0.00468"
"18062","108.33600","9.02816","0.00559"
"18099","108.55800","9.04669","0.00576"
"18136","108.78000","9.06511","0.00493"
"18173","109.00200","9.08370","0.00581"
"18210","109.22400","9.10212","0.00540"
"18247","109.44600","9.12065","0.00562"
"18284","109.66800","9.13913","0.00564"
"18321","109.89000","9.15766","0.00587"
"18358","110.11200","9.17620","0.00557"
"18395","110.33400","9.19461","0.00592"
"18432","110.55600","9.21321","0.00634"
"18469","110.77800","9.23162","0.00632"
"18506","111.00000","9.25016","0.00588"
"18543","111.22200","9.26869","0.00607"
"18580","111.44400","9.28711","0.00600"
"18617","111.66600","9.30564","0.00644"
"18654","111.88800","9.32412","0.00624"
"18691","112.11000","9.34271","0.00637"
"18728","112.33200","9.36113","0.00635"
"18765","112.55400","9.37972","0.00655"
"18802","112.77600","9.39814","0.00698"
"18839","112.99800","9.41661","0.00708"
"18876","113.22000","9.43515","0.00683"
"18913","113.44200","9.45368","0.00682"
"18950","113.66400","9.47216","0.00704"
"18987","113.88600","9.49069","0.00717"
"19024","114.10800","9.50911","0.00675"
"19061","114.33000","9.52770","0.00753"
"19098","114.55200","9.54618","0.00749"
"19135","114.77400","9.56471","0.00741"
"19172","114.99600","9.58325","0.00805"
"19209","115.21800","9.60166","0.00823"
"19246","115.44000","9.62020","0.00788"
"19283","115.66200","9.63861","0.00853"
"19320","115.88400","9.65720","0.00813"
"19357","116.10600","9.67562","0.00788"
"19394","116.32800","9.69416","0.00744"
"19431","116.55000","9.71275","0.00857"
"19468","116.77200","9.73116","0.00812"
"19505","116.99400","9.74970","0.00836"
"19542","117.21600","9.76812","0.00818"
"19579","117.43800","9.78665","0.00865"
"19616","117.66000","9.80524","0.00875"
"19653","117.88200","9.82366","0.00829"
"19690","118.10400","9.84213","0.00837"
"19727","118.32600","9.86067","0.00926"
"19764","118.54800","9.87920","0.00890"
"19801","118.77000","9.89768","0.00911"
"19838","118.99200","9.91615","0.00927"
"19875","119.21400","9.93469","0.00919"
"19912","119.43600","9.95316","0.00934"
"19949","119.65800","9.97164","0.00940"
"19986","119.88000","9.99017","0.00982"
"20023","120.10200","10.00859","0.00960"
"20060","120.32400","10.02718","0.01020"
"20097","120.54600","10.04560","0.01039"
"20134","120.76800","10.06419","0.01011"
"20171","120.99000","10.08261","0.01009"
"20208","121.21200","10.10114","0.01044"
"20245","121.43400","10.11968","0.01063"
"20282","121.65600","10.13815","0.01033"
"20319","121.87800","10.15669","0.01074"
"20356","122.10000","10.17510","0.01033"
"20393","122.32200","10.19376","0.01082"
"20430","122.54400","10.21217","0.01100"
"20467","122.76600","10.23065","0.01139"
"20504","122.98800","10.24924","0.01121"
"20541","123.21000","10.26760","0.01156"
"20578","123.43200","10.28619","0.01174"
"20615","123.65400","10.30467","0.01140"
"20652","123.87600","10.32320","0.01138"
"20689","124.09800","10.34168","0.01164"
"20726","124.32000","10.36015","0.01190"
"20763","124.54200","10.37869","0.01193"
"20800","124.76400","10.39716","0.01186"
"20837","124.98600","10.41564","0.01222"
"20874","125.20800","10.43423","0.01214"
"20911","125.43000","10.45265","0.01238"
"20948","125.65200","10.47118","0.01225"
"20985","125.87400","10.48965","0.01179"
"21022","126.09600","10.50819","0.01186"
"21059","126.31800","10.52666","0.01200"
"21096","126.54000","10.54514","0.01275"
"21133","126.76200","10.56367","0.01267"
"21170","126.98400","10.58209","0.01269"
"21207","127.20600","10.60068","0.01322"
"21244","127.42800","10.61916","0.01296"
"21281","127.65000","10.63769","0.01329"
"21318","127.87200","10.65617","0.01275"
"21355","128.09400","10.67464","0.01357"
"21392","128.31600","10.69318","0.01335"
"21429","128.53800","10.71165","0.01351"
"21466","128.76000","10.73025","0.01401"
"21503","128.98200","10.74866","0.01374"
"21540","129.20400","10.76714","0.01414"
"21577","129.42600","10.78573","0.01434"
"21614","129.64800","10.80415","0.01465"
"21651","129.87000","10.82262","0.01501"
"21688","130.09200","10.84116","0.01433"
"21725","130.31400","10.85969","0.01488"
"21762","130.53600","10.87823","0.01456"
"21799","130.75800","10.89658","0.01432"
"21836","130.98000","10.91518","0.01437"
"21873","131.20200","10.93365","0.01477"
"21910","131.42400","10.95219","0.01480"
"21947","131.64600","10.97072","0.01501"
"21984","131.86800","10.98908","0.01501"
"22021","132.09000","11.00767","0.01530"
"22058","132.31200","11.02609","0.01540"
"22095","132.53400","11.04474","0.01545"
"22132","132.75600","11.06316","0.01554"
"22169","132.97800","11.08163","0.01606"
"22206","133.20000","11.10023","0.01627"
"22243","133.42200","11.11864","0.01581"
"22280","133.64400","11.13724","0.01608"
"22317","133.86600","11.15565","0.01680"
"22354","134.08800","11.17419","0.01637"
"22391","134.31000","11.19272","0.01686"
"22428","134.53200","11.21114","0.01695"
"22465","134.75400","11.22967","0.01661"
"22502","134.97600","11.24815","0.01678"
"22539","135.19800","11.26668","0.01751"
"22576","135.42000","11.28515","0.01776"
"22613","135.64200","11.30363","0.01743"
"22650","135.86400","11.32216","0.01779"
"22687","136.08600","11.34070","0.01774"
"22724","136.30800","11.35917","0.01774"
"22761","136.53000","11.37771","0.01792"
"22798","136.75200","11.39612","0.01835"
"22835","136.97400","11.41472","0.01867"
"22872","137.19600","11.43313","0.01789"
"22909","137.41800","11.45173","0.01866"
"22946","137.64000","11.47014","0.01895"
"22983","137.86200","11.48862","0.01908"
"23020","138.08400","11.50715","0.01824"
"23057","138.30600","11.52569","0.01900"
"23094","138.52800","11.54416","0.01969"
"23131","138.75000","11.56264","0.01932"
"23168","138.97200","11.58117","0.01992"
"23205","139.19400","11.59965","0.01982"
"23242","139.41600","11.61812","0.01905"
"23279","139.63800","11.63666","0.01970"
"23316","139.86000","11.65513","0.01988"
"23353","140.08200","11.67373","0.01987"
"23390","140.30400","11.69220","0.02059"
"23427","140.52600","11.71068","0.02041"
"23464","140.74800","11.72921","0.02101"
"23501","140.97000","11.74763","0.02075"
"23538","141.19200","11.76616","0.02075"
"23575","141.41400","11.78470","0.02095"
"23612","141.63600","11.80317","0.02114"
"23649","141.85800","11.82171","0.02111"
"23686","142.08000","11.84012","0.02099"
"23723","142.30200","11.85872","0.02141"
"23760","142.52400","11.87713","0.02194"
"23797","142.74600","11.89567","0.02202"
"23834","142.96800","11.91420","0.02195"
"23871","143.19000","11.93262","0.02234"
"23908","143.41200","11.95127","0.02254"
"23945","143.63400","11.96963","0.02224"
"23982","143.85600","11.98816","0.02188"
"24019","144.07800","12.00663","0.02241"
"24056","144.30000","12.02517","0.02235"
"24093","144.52200","12.04370","0.02246"
"24130","144.74400","12.06212","0.02292"
"24167","144.96600","12.08072","0.02316"
"24204","145.18800","12.09907","0.02348"
"24241","145.41000","12.11772","0.02364"
"24278","145.63200","12.13614","0.02370"
"24315","145.85400","12.15461","0.02344"
"24352","146.07600","12.17315","0.02385"
"24389","146.29800","12.19162","0.02418"
"24426","146.52000","12.21016","0.02456"
"24463","146.74200","12.22863","0.02465"
"24500","146.96400","12.24717","0.02461"
"24537","147.18600","12.26570","0.02475"
"24574","147.40800","12.28412","0.02510"
"24611","147.63000","12.30271","0.02542"
"24648","147.85200","12.32119","0.02561"
"24685","148.07400","12.33966","0.02552"
"24722","148.29600","12.35820","0.02570"
"24759","148.51800","12.37661","0.02600"
"24796","148.74000","12.39521","0.02636"
"24833","148.96200","12.41362","0.02639"
"24870","149.18400","12.43216","0.02689"
"24907","149.40600","12.45069","0.02692"
"24944","149.62800","12.46911","0.02720"
"24981","149.85000","12.48770","0.02723"
"25018","150.07200","12.50618","0.02764"
"25055","150.29400","12.52471","0.02834"
"25092","150.51600","12.54313","0.02861"
"25129","150.73800","12.56166","0.02806"
"25166","150.96000","12.58026","0.02856"
"25203","151.18200","12.59861","0.02870"
"25240","151.40400","12.61721","0.02908"
"25277","151.62600","12.63568","0.02951"
"25314","151.84800","12.65416","0.03003"
"25351","152.07000","12.67269","0.02997"
"25388","152.29200","12.69116","0.02949"
"25425","152.51400","12.70958","0.03057"
"25462","152.73600","12.72812","0.03045"
"25499","152.95800","12.74665","0.03111"
"25536","153.18000","12.76525","0.03124"
"25573","153.40200","12.78366","0.03149"
"25610","153.62400","12.80214","0.03192"
"25647","153.84600","12.82067","0.03233"
"25684","154.06800","12.83920","0.03241"
"25721","154.29000","12.85768","0.03251"
"25758","154.51200","12.87615","0.03276"
"25795","154.73400","12.89469","0.03349"
"25832","154.95600","12.91310","0.03382"
"25869","155.17800","12.93164","0.03362"
"25906","155.40000","12.95012","0.03389"
"25943","155.62200","12.96865","0.03415"
"25980","155.84400","12.98718","0.03455"
"26017","156.06600","13.00560","0.03487"
"26054","156.28800","13.02419","0.03560"
"26091","156.51000","13.04267","0.03621"
"26128","156.73200","13.06120","0.03607"
"26165","156.95400","13.07968","0.03662"
"26202","157.17600","13.09815","0.03722"
"26239","157.39800","13.11669","0.03732"
"26276","157.62000","13.13516","0.03774"
"26313","157.84200","13.15370","0.03795"
"26350","158.06400","13.17223","0.03853"
"26387","158.28600","13.19065","0.03798"
"26424","158.50800","13.20918","0.03814"
"26461","158.73000","13.22760","0.03883"
"26498","158.95200","13.24619","0.03804"
"26535","159.17400","13.26467","0.03867"
"26572","159.39600","13.28320","0.03895"
"26609","159.61800","13.30174","0.03903"
"26646","159.84000","13.32009","0.03956"
"26683","160.06200","13.33869","0.03978"
"26720","160.28400","13.35710","0.03982"
"26757","160.50600","13.37570","0.04086"
"26794","160.72800","13.39417","0.04114"
"26831","160.95000","13.41265","0.04154"
"26868","161.17200","13.43118","0.04163"
"26905","161.39400","13.44966","0.04217"
"26942","161.61600","13.46825","0.04305"
"26979","161.83800","13.48666","0.04320"
"27016","162.06000","13.50520","0.04368"
"27053","162.28200","13.52367","0.04442"
"27090","162.50400","13.54215","0.04422"
"27127","162.72600","13.56063","0.04535"
"27164","162.94800","13.57910","0.04563"
"27201","163.17000","13.59764","0.04632"
"27238","163.39200","13.61611","0.04693"
"27275","163.61400","13.63458","0.04743"
"27312","163.83600","13.65318","0.04773"
"27349","164.05800","13.67165","0.04758"
"27386","164.28000","13.69019","0.04863"
"27423","164.50200","13.70872","0.04892"
"27460","164.72400","13.72714","0.04940"
"27497","164.94600","13.74573","0.05025"
"27534","165.16800","13.76409","0.05057"
"27571","165.39000","13.78274","0.05088"
"27608","165.61200","13.80116","0.05136"
"27645","165.83400","13.81969","0.05200"
"27682","166.05600","13.83823","0.05255"
"27719","166.27800","13.85658","0.05283"
"27756","166.50000","13.87518","0.05316"
"27793","166.72200","13.89371","0.05347"
"27830","166.94400","13.91219","0.05374"
"27867","167.16600","13.93066","0.05387"
"27904","167.38800","13.94914","0.05415"
"27941","167.61000","13.96767","0.05424"
"27978","167.83200","13.98615","0.05532"
"28015","168.05400","14.00462","0.05570"
"28052","168.27600","14.02316","0.05620"
"28089","168.49800","14.04169","0.05640"
"28126","168.72000","14.06017","0.05699"
"28163","168.94200","14.07864","0.05765"
"28200","169.16400","14.09718","0.05777"
"28237","169.38600","14.11571","0.05814"
"28274","169.60800","14.13419","0.05894"
"28311","169.83000","14.15272","0.05928"
"28348","170.05200","14.17108","0.01732"
"28385","170.27400","14.18967","0.02064"
"28422","170.49600","14.20815","0.01790"
"28459","170.71800","14.22668","0.02040"
"28496","170.94000","14.24516","0.01871"
"28533","171.16200","14.26363","0.02118"
"28570","171.38400","14.28222","0.01930"
"28607","171.60600","14.30064","0.02056"
"28644","171.82800","14.31923","0.01957"
"28681","172.05000","14.33765","0.02062"
"28718","172.27200","14.35612","0.01877"
"28755","172.49400","14.37472","0.01975"
"28792","172.71600","14.39313","0.01967"
"28829","172.93800","14.41167","0.01969"
"28866","173.16000","14.43015","0.02046"
"28903","173.38200","14.44868","0.02015"
"28940","173.60400","14.46715","0.02044"
"28977","173.82600","14.48569","0.02077"
"29014","174.04800","14.50416","0.02115"
"29051","174.27000","14.52258","0.02060"
"29088","174.49200","14.54123","0.02169"
"29125","174.71400","14.55971","0.02070"
"29162","174.93600","14.57812","0.02174"
"29199","175.15800","14.59666","0.02136"
"29236","175.38000","14.61513","0.02209"
"29273","175.60200","14.63373","0.02182"
"29310","175.82400","14.65220","0.02288"
"29347","176.04600","14.67062","0.02229"
"29384","176.26800","14.68921","0.02256"
"29421","176.49000","14.70757","0.02244"
"29458","176.71200","14.72622","0.02365"
"29495","176.93400","14.74464","0.02333"
"29532","177.15600","14.76317","0.02421"
"29569","177.37800","14.78171","0.02392"
"29606","177.60000","14.80012","0.02455"
"29643","177.82200","14.81866","0.02451"
"29680","178.04400","14.83719","0.02428"
"29717","178.26600","14.85567","0.02429"
"29754","178.48800","14.87420","0.02439"
"29791","178.71000","14.89268","0.02542"
"29828","178.93200","14.91115","0.02532"
"29865","179.15400","14.92963","0.02560"
"29902","179.37600","14.94822","0.02507"
"29939","179.59800","14.96670","0.02596"
"29976","179.82000","14.98517","0.02585"
"30013","180.04200","15.00371","0.02681"
"30050","180.26400","15.02212","0.02680"
"30087","180.48600","15.04066","0.02702"
"30124","180.70800","15.05913","0.02721"
"30161","180.93000","15.07767","0.02778"
"30198","181.15200","15.09620","0.02760"
"30235","181.37400","15.11462","0.02837"
"30272","181.59600","15.13321","0.02788"
"30309","181.81800","15.15163","0.02780"
"30346","182.04000","15.17022","0.02902"
"30383","182.26200","15.18869","0.02901"
"30420","182.48400","15.20717","0.02935"
"30457","182.70600","15.22564","0.02978"
"30494","182.92800","15.24406","0.03036"
"30531","183.15000","15.26271","0.03080"
"30568","183.37200","15.28119","0.03112"
"30605","183.59400","15.29966","0.03045"
"30642","183.81600","15.31820","0.03119"
"30679","184.03800","15.33661","0.03230"
"30716","184.26000","15.35521","0.03227"
"30753","184.48200","15.37368","0.03285"
"30790","184.70400","15.39216","0.03327"
"30827","184.92600","15.41069","0.03362"
"30864","185.14800","15.42917","0.03360"
"30901","185.37000","15.44764","0.03393"
"30938","185.59200","15.46612","0.03402"
"30975","185.81400","15.48471","0.03460"
"31012","186.03600","15.50319","0.03509"
"31049","186.25800","15.52166","0.03545"
"31086","186.48000","15.54020","0.03552"
"31123","186.70200","15.55861","0.03637"
"31160","186.92400","15.57715","0.03699"
"31197","187.14600","15.59568","0.03727"
"31234","187.36800","15.61416","0.03810"
"31271","187.59000","15.63269","0.03827"
"31308","187.81200","15.65110","0.03919"
"31345","188.03400","15.66970","0.03961"
"31382","188.25600","15.68812","0.03986"
"31419","188.47800","15.70671","0.04013"
"31456","188.70000","15.72512","0.04110"
"31493","188.92200","15.74366","0.04145"
"31530","189.14400","15.76214","0.04228"
"31567","189.36600","15.78061","0.04335"
"31604","189.58800","15.79914","0.04344"
"31641","189.81000","15.81762","0.04440"
"31678","190.03200","15.83622","0.04495"
"31715","190.25400","15.85469","0.04542"
"31752","190.47600","15.87316","0.04524"
"31789","190.69800","15.89164","0.04664"
"31826","190.92000","15.91017","0.04725"
"31863","191.14200","15.92871","0.04768"
"31900","191.36400","15.94718","0.04867"
"31937","191.58600","15.96560","0.04849"
"31974","191.80800","15.98419","0.04929"
"32011","192.03000","16.00267","0.04946"
"32048","192.25200","16.02120","0.05042"
"32085","192.47400","16.03974","0.05072"
"32122","192.69600","16.05815","0.05186"
"32159","192.91800","16.07675","0.05202"
"32196","193.14000","16.09510","0.05244"
"32233","193.36200","16.11370","0.05375"
"32270","193.58400","16.13211","0.05355"
"32307","193.80600","16.15065","0.05462"
"32344","194.02800","16.16918","0.05513"
"32381","194.25000","16.18760","0.05568"
"32418","194.47200","16.20619","0.05593"
"32455","194.69400","16.22467","0.05664"
"32492","194.91600","16.24314","0.05706"
"32529","195.13800","16.26174","0.05802"
"32566","195.36000","16.28015","0.05842"
"32603","195.58200","16.29869","0.05901"
"32640","195.80400","16.31710","0.05934"
"32677","196.02600","16.33570","0.05988"
"32714","196.24800","16.35423","0.06041"
"32751","196.47000","16.37264","0.06071"
"32788","196.69200","16.39118","0.06124"
"32825","196.91400","16.40966","0.06167"
"32862","197.13600","16.42813","0.06198"
"32899","197.35800","16.44672","0.06235"
"32936","197.58000","16.46514","0.06262"
"32973","197.80200","16.48368","0.06299"
"33010","198.02400","16.50209","0.06358"
"33047","198.24600","16.52069","0.06388"
"33084","198.46800","16.53910","0.06426"
"33121","198.69000","16.55763","0.06448"
"33158","198.91200","16.57617","0.06473"
"33195","199.13400","16.59464","0.06543"
"33232","199.35600","16.61318","0.06543"
"33269","199.57800","16.63171","0.06584"
"33306","199.80000","16.65025","0.06610"
"33343","200.02200","16.66866","0.06632"
"33380","200.24400","16.68720","0.06669"
"33417","200.46600","16.70567","0.06679"
"33454","200.68800","16.72415","0.06706"
"33491","200.91000","16.74268","0.06786"
"33528","201.13200","16.76122","0.06778"
"33565","201.35400","16.77969","0.06823"
"33602","201.57600","16.79823","0.06828"
"33639","201.79800","16.81664","0.06388"
"33676","202.02000","16.83518","0.06401"
"33713","202.24200","16.85365","0.06430"
"33750","202.46400","16.87219","0.06457"
"33787","202.68600","16.89066","0.06466"
"33824","202.90800","16.90914","0.06494"
"33861","203.13000","16.92767","0.06260"
"33898","203.35200","16.94615","0.06276"
"33935","203.57400","16.96468","0.06287"
"33972","203.79600","16.98316","0.06360"
"34009","204.01800","17.00163","0.06352"
"34046","204.24000","17.02017","0.06406"
"34083","204.46200","17.03864","0.06418"
"34120","204.68400","17.05724","0.06467"
"34157","204.90600","17.07559","0.06474"
"34194","205.12800","17.09418","0.06487"
"34231","205.35000","17.11266","0.06491"
"34268","205.57200","17.13120","0.06559"
"34305","205.79400","17.14967","0.06573"
"34342","206.01600","17.16815","0.06576"
"34379","206.23800","17.18668","0.06610"
"34416","206.46000","17.20515","0.06639"
"34453","206.68200","17.22369","0.06632"
"34490","206.90400","17.24216","0.06660"
"34527","207.12600","17.26064","0.06709"
"34564","207.34800","17.27917","0.06707"
"34601","207.57000","17.29771","0.06720"
"34638","207.79200","17.31618","0.06725"
"34675","208.01400","17.33472","0.06794"
"34712","208.23600","17.35313","0.06801"
"34749","208.45800","17.37167","0.06854"
"34786","208.68000","17.39014","0.06878"
"34823","208.90200","17.40868","0.06913"
"34860","209.12400","17.42721","0.06922"
"34897","209.34600","17.44557","0.06946"
"34934","209.56800","17.46422","0.06969"
"34971","209.79000","17.48264","0.06993"
"35008","210.01200","17.50123","0.07014"
"35045","210.23400","17.51971","0.07054"
"35082","210.45600","17.53812","0.07065"
"35119","210.67800","17.55672","0.00196"
"35156","210.90000","17.57513","0.00208"
"35193","211.12200","17.59367","0.00029"
"35230","211.34400","17.61214","0.00070"
"35267","211.56600","17.63068","-0.00033"
"35304","211.78800","17.64921","-0.00067"
"35341","212.01000","17.66763","0.00339"
"35378","212.23200","17.68616","-0.00049"
"35415","212.45400","17.70470","-0.00028"
"35452","212.67600","17.72317","-0.00008"
"35489","212.89800","17.74171","0.00139"
"35526","213.12000","17.76012","-0.00009"
"35563","213.34200","17.77866","-0.00087"
"35600","213.56400","17.79719","0.00151"
"35637","213.78600","17.81567","-0.00028"
"35674","214.00800","17.83420","-0.00054"
"35711","214.23000","17.85268","0.00022"
"35748","214.45200","17.87121","0.00057"
"35785","214.67400","17.88963","0.00032"
"35822","214.89600","17.90822","0.00029"
"35859","215.11800","17.92664","0.00157"
"35896","215.34000","17.94511","0.00000"
"35933","215.56200","17.96371","-0.00027"
"35970","215.78400","17.98212","0.00058"
"36007","216.00600","18.00065","0.00026"
"36044","216.22800","18.01913","-0.00002"
"36081","216.45000","18.03773","0.00059"
"36118","216.67200","18.05614","-0.00017"
"36155","216.89400","18.07467","-0.00013"
"36192","217.11600","18.09315","0.00078"
"36229","217.33800","18.11162","0.00031"
"36266","217.56000","18.13016","0.00014"
"36303","217.78200","18.14869","0.00099"
"36340","218.00400","18.16717","0.00045"
"36377","218.22600","18.18570","0.00031"
"36414","218.44800","18.20412","0.00065"
"36451","218.67000","18.22271","0.00022"
"36488","218.89200","18.24119","0.00058"
"36525","219.11400","18.25960","0.00074"
"36562","219.33600","18.27820","0.00091"
"36599","219.55800","18.29661","0.00072"
"36636","219.78000","18.31515","0.00099"
"36673","220.00200","18.33362","0.00099"
"36710","220.22400","18.35222","0.00029"
"36747","220.44600","18.37069","0.00073"
"36784","220.66800","18.38917","0.00107"
"36821","220.89000","18.40770","0.00079"
"36858","221.11200","18.42618","0.00062"
"36895","221.33400","18.44471","0.00070"
"36932","221.55600","18.46313","0.00162"
"36969","221.77800","18.48166","0.00097"
"37006","222.00000","18.50020","0.00088"
"37043","222.22200","18.51861","0.00104"
"37080","222.44400","18.53721","0.00135"
"37117","222.66600","18.55568","0.00111"
"37154","222.88800","18.57421","0.00101"
"37191","223.11000","18.59269","0.00131"
"37228","223.33200","18.61117","0.00091"
"37265","223.55400","18.62970","0.00117"
"37302","223.77600","18.64818","0.00120"
"37339","223.99800","18.66665","0.00147"
"37376","224.22000","18.68513","0.00141"
"37413","224.44200","18.70366","0.00115"
"37450","224.66400","18.72219","0.00166"
"37487","224.88600","18.74061","0.00118"
"37524","225.10800","18.75921","0.00166"
"37561","225.33000","18.77768","0.00120"
"37598","225.55200","18.79616","0.00156"
"37635","225.77400","18.81469","0.00104"
"37672","225.99600","18.83311","0.00160"
"37709","226.21800","18.85170","0.00099"
"37746","226.44000","18.87012","0.00163"
"37783","226.66200","18.88871","0.00140"
"37820","226.88400","18.90718","0.00167"
"37857","227.10600","18.92560","0.00167"
"37894","227.32800","18.94419","0.00165"
"37931","227.55000","18.96267","0.00187"
"37968","227.77200","18.98114","0.00142"
"38005","227.99400","18.99968","0.00199"
"38042","228.21600","19.01815","0.00186"
"38079","228.43800","19.03669","0.00161"
"38116","228.66000","19.05510","0.00183"
"38153","228.88200","19.07370","0.00206"
"38190","229.10400","19.09217","0.00237"
"38227","229.32600","19.11065","0.00153"
"38264","229.54800","19.12924","0.00171"
"38301","229.77000","19.14766","0.00164"
"38338","229.99200","19.16613","0.00203"
"38375","230.21400","19.18467","0.00144"
"38412","230.43600","19.20314","0.00187"
"38449","230.65800","19.22168","0.00214"
"38486","230.88000","19.24009","0.00188"
"38523","231.10200","19.25869","0.00198"
"38560","231.32400","19.27716","0.00204"
"38597","231.54600","19.29570","0.00199"
"38634","231.76800","19.31417","0.00199"
"38671","231.99000","19.33265","0.00193"
"38708","232.21200","19.35118","0.00231"
"38745","232.43400","19.36966","0.00174"
"38782","232.65600","19.38819","0.00218"
"38819","232.87800","19.40660","0.00259"
"38856","233.10000","19.42520","0.00193"
"38893","233.32200","19.44374","0.00209"
"38930","233.54400","19.46215","0.00266"
"38967","233.76600","19.48068","0.00215"
"39004","233.98800","19.49916","0.00192"
"39041","234.21000","19.51770","0.00265"
"39078","234.43200","19.53611","0.00228"
"39115","234.65400","19.55465","0.00283"
"39152","234.87600","19.57318","0.00279"
"39189","235.09800","19.59160","0.00268"
"39226","235.32000","19.61025","0.00208"
"39263","235.54200","19.62866","0.00287"
"39300","235.76400","19.64714","0.00286"
"39337","235.98600","19.66574","0.00236"
"39374","236.20800","19.68415","0.00279"
"39411","236.43000","19.70268","0.00239"
"39448","236.65200","19.72116","0.00296"
"39485","236.87400","19.73963","0.00292"
"39522","237.09600","19.75823","0.00286"
"39559","237.31800","19.77658","0.00298"
"39596","237.54000","19.79524","0.00292"
"39633","237.76200","19.81365","0.00317"
"39670","237.98400","19.83219","0.00311"
"39707","238.20600","19.85066","0.00303"
"39744","238.42800","19.86920","0.00299"
"39781","238.65000","19.88767","0.00291"
"39818","238.87200","19.90615","0.00329"
"39855","239.09400","19.92468","0.00321"
"39892","239.31600","19.94316","0.00322"
"39929","239.53800","19.96163","0.00402"
"39966","239.76000","19.98017","0.00294"
"40003","239.98200","19.99870","0.00373"
"40040","240.20400","20.01718","0.00296"
"40077","240.42600","20.03565","0.00377"
"40114","240.64800","20.05413","0.00329"
"40151","240.87000","20.07272","0.00362"
"40188","241.09200","20.09108","0.00330"
"40225","241.31400","20.10967","0.00358"
"40262","241.53600","20.12815","0.00411"
"40299","241.75800","20.14668","0.00375"
"40336","241.98000","20.16522","0.00383"
"40373","242.20200","20.18363","0.00301"
"40410","242.42400","20.20217","0.00352"
"40447","242.64600","20.22064","0.00334"
"40484","242.86800","20.23923","0.00387"
"40521","243.09000","20.25771","0.00410"
"40558","243.31200","20.27612","0.00420"
"40595","243.53400","20.29472","0.00404"
"40632","243.75600","20.31307","0.00402"
"40669","243.97800","20.33173","0.00414"
"40706","244.20000","20.35020","0.00449"
"40743","244.42200","20.36868","0.00405"
"40780","244.64400","20.38715","0.00369"
"40817","244.86600","20.40569","0.00469"
"40854","245.08800","20.42417","0.00461"
"40891","245.31000","20.44258","0.00423"
"40928","245.53200","20.46117","0.00446"
"40965","245.75400","20.47971","0.00460"
"41002","245.97600","20.49812","0.00412"
"41039","246.19800","20.51672","0.00495"
"41076","246.42000","20.53513","0.00434"
"41113","246.64200","20.55373","0.00455"
"41150","246.86400","20.57220","0.00470"
"41187","247.08600","20.59068","0.00444"
"41224","247.30800","20.60921","0.00491"
"41261","247.53000","20.62757","0.00471"
"41298","247.75200","20.64616","0.00498"
"41335","247.97400","20.66464","0.00501"
"41372","248.19600","20.68317","0.00425"
"41409","248.41800","20.70165","0.00545"
"41446","248.64000","20.72012","0.00576"
"41483","248.86200","20.73872","0.00529"
"41520","249.08400","20.75713","0.00473"
"41557","249.30600","20.77573","0.00548"
"41594","249.52800","20.79414","0.00493"
"41631","249.75000","20.81268","0.00539"
"41668","249.97200","20.83115","0.00505"
"41705","250.19400","20.84969","0.00512"
"41742","250.41600","20.86816","0.00541"
"41779","250.63800","20.88670","0.00566"
"41816","250.86000","20.90517","0.00506"
"41853","251.08200","20.92371","0.00581"
"41890","251.30400","20.94212","0.00547"
"41927","251.52600","20.96066","0.00547"
"41964","251.74800","20.97913","0.00550"
"42001","251.97000","20.99767","0.00564"
"42038","252.19200","21.01620","0.00549"
"42075","252.41400","21.03461","0.00585"
"42112","252.63600","21.05321","0.00549"
"42149","252.85800","21.07162","0.00523"
"42186","253.08000","21.09022","0.00551"
"42223","253.30200","21.10869","0.00565"
"42260","253.52400","21.12711","0.00568"
"42297","253.74600","21.14570","0.00570"
"42334","253.96800","21.16412","0.00514"
"42371","254.19000","21.18271","0.00524"
"42408","254.41200","21.20113","0.00496"
"42445","254.63400","21.21967","0.00546"
"42482","254.85600","21.23820","0.00551"
"42519","255.07800","21.25661","0.00555"
"42556","255.30000","21.27515","0.00543"
"42593","255.52200","21.29368","0.00554"
"42630","255.74400","21.31216","0.00558"
"42667","255.96600","21.33069","0.00581"
"42704","256.18800","21.34911","0.00605"
"42741","256.41000","21.36770","0.00534"
"42778","256.63200","21.38618","0.00574"
"42815","256.85400","21.40465","0.00569"
"42852","257.07600","21.42319","0.00589"
"42889","257.29800","21.44166","0.00590"
"42926","257.52000","21.46020","0.00623"
"42963","257.74200","21.47867","0.00651"
"43000","257.96400","21.49721","0.00639"
"43037","258.18600","21.51562","0.00655"
"43074","258.40800","21.53416","0.00635"
"43111","258.63000","21.55269","0.00646"
"43148","258.85200","21.57111","0.00661"
"43185","259.07400","21.58976","0.00693"
"43222","259.29600","21.60812","0.00625"
"43259","259.51800","21.62671","0.00683"
"43296","259.74000","21.64519","0.00641"
"43333","259.96200","21.66366","0.00691"
"43370","260.18400","21.68220","0.00696"
"43407","260.40600","21.70061","0.00690"
"43444","260.62800","21.71921","0.00642"
"43481","260.85000","21.73762","0.00770"
"43518","261.07200","21.75621","0.00721"
"43555","261.29400","21.77469","0.00749"
"43592","261.51600","21.79317","0.00711"
"43629","261.73800","21.81164","0.00713"
"43666","261.96000","21.83018","0.00714"
"43703","262.18200","21.84865","0.00752"
"43740","262.40400","21.86719","0.00739"
"43777","262.62600","21.88560","0.00757"
"43814","262.84800","21.90413","0.00760"
"43851","263.07000","21.92267","0.00725"
"43888","263.29200","21.94121","0.00691"
"43925","263.51400","21.95968","0.00774"
"43962","263.73600","21.97815","0.00784"
"43999","263.95800","21.99669","0.00773"
"44036","264.18000","22.01516","0.00798"
"44073","264.40200","22.03370","0.00787"
"44110","264.62400","22.05217","0.00803"
"44147","264.84600","22.07065","0.00835"
"44184","265.06800","22.08918","0.00807"
"44221","265.29000","22.10760","0.00867"
"44258","265.51200","22.12625","0.00876"
"44295","265.73400","22.14467","0.00868"
"44332","265.95600","22.16320","0.00829"
"44369","266.17800","22.18168","0.00845"
"44406","266.40000","22.20015","0.00912"
"44443","266.62200","22.21863","0.00828"
"44480","266.84400","22.23716","0.00848"
"44517","267.06600","22.25570","0.00897"
"44554","267.28800","22.27417","0.00840"
"44591","267.51000","22.29265","0.00875"
"44628","267.73200","22.31124","0.00836"
"44665","267.95400","22.32960","0.00949"
"44702","268.17600","22.34819","0.00921"
"44739","268.39800","22.36666","0.00908"
"44776","268.62000","22.38520","0.00923"
"44813","268.84200","22.40368","0.00920"
"44850","269.06400","22.42209","0.00117"
"44887","269.28600","22.44069","0.00085"
"44924","269.50800","22.45910","0.00104"
"44961","269.73000","22.47770","0.00083"
"44998","269.95200","22.49617","0.00017"
"45035","270.17400","22.51459","0.00125"
"45072","270.39600","22.53324","-0.00021"
"45109","270.61800","22.55165","0.00167"
"45146","270.84000","22.57019","0.00075"
"45183","271.06200","22.58867","-0.00015"
"45220","271.28400","22.60714","0.00196"
"45257","271.50600","22.62573","-0.00015"
"45294","271.72800","22.64415","0.00037"
"45331","271.95000","22.66275","0.00190"
"45368","272.17200","22.68116","0.00026"
"45405","272.39400","22.69970","0.00121"
"45442","272.61600","22.71823","0.00183"
"45479","272.83800","22.73664","0.00047"
"45516","273.06000","22.75512","0.00124"
"45553","273.28200","22.77360","0.00133"
"45590","273.50400","22.79219","0.00050"
"45627","273.72600","22.81072","0.00154"
"45664","273.94800","22.82914","0.00015"
"45701","274.17000","22.84767","0.00050"
"45738","274.39200","22.86615","0.00120"
"45775","274.61400","22.88468","0.00019"
"45812","274.83600","22.90322","0.00084"
"45826","274.92000","22.91021","0.00179"