File: Trajectories_together/170122_2Specimen_RawData_1.csv
"","V1","V2","V3"
"1","End date","1/22/2017",""
"2","Specimen label","3CT_17",""
"3","Maximum Load","0.70951","N"
"4","Time","Extension","Load"
"5","(s)","(mm)","(N)"
"6","0.00000","0.00000","0.00575"
"28","0.13200","0.00664","0.00607"
"50","0.26400","0.02099","0.00724"
"72","0.39600","0.03324","0.00833"
"94","0.52800","0.04424","0.00930"
"116","0.66000","0.05519","0.01000"
"138","0.79200","0.06631","0.00999"
"160","0.92400","0.07725","0.01058"
"182","1.05600","0.08819","0.01044"
"204","1.18800","0.09925","0.01162"
"226","1.32000","0.11025","0.01162"
"248","1.45200","0.12125","0.01165"
"270","1.58400","0.13219","0.01181"
"292","1.71600","0.14320","0.01225"
"314","1.84800","0.15420","0.01253"
"336","1.98000","0.16526","0.01289"
"358","2.11200","0.17620","0.01242"
"380","2.24400","0.18714","0.01343"
"402","2.37600","0.19820","0.01373"
"424","2.50800","0.20926","0.01441"
"446","2.64000","0.22020","0.01397"
"468","2.77200","0.23121","0.01422"
"490","2.90400","0.24221","0.01440"
"512","3.03600","0.25327","0.01452"
"534","3.16800","0.26421","0.01475"
"556","3.30000","0.27521","0.01462"
"578","3.43200","0.28621","0.01490"
"600","3.56400","0.29721","0.01550"
"622","3.69600","0.30822","0.01483"
"644","3.82800","0.31910","0.01562"
"666","3.96000","0.33022","0.01585"
"688","4.09200","0.34116","0.01594"
"710","4.22400","0.35222","0.01616"
"732","4.35600","0.36316","0.01567"
"754","4.48800","0.37416","0.01632"
"776","4.62000","0.38522","0.01636"
"798","4.75200","0.39617","0.01720"
"820","4.88400","0.40717","0.01683"
"842","5.01600","0.41817","0.01640"
"864","5.14800","0.42917","0.01729"
"886","5.28000","0.44017","0.01688"
"908","5.41200","0.45117","0.01716"
"930","5.54400","0.46217","0.01764"
"952","5.67600","0.47317","0.01780"
"974","5.80800","0.48418","0.01741"
"996","5.94000","0.49518","0.01827"
"1018","6.07200","0.50618","0.01785"
"1040","6.20400","0.51724","0.01838"
"1062","6.33600","0.52824","0.01912"
"1084","6.46800","0.53918","0.01874"
"1106","6.60000","0.55018","0.01891"
"1128","6.73200","0.56124","0.01897"
"1150","6.86400","0.57219","0.01940"
"1172","6.99600","0.58313","0.01941"
"1194","7.12800","0.59413","0.01999"
"1216","7.26000","0.60519","0.01904"
"1238","7.39200","0.61625","0.01952"
"1260","7.52400","0.62719","0.01987"
"1282","7.65600","0.63819","0.02037"
"1304","7.78800","0.64925","0.02012"
"1326","7.92000","0.66026","0.02007"
"1348","8.05200","0.67120","0.02011"
"1370","8.18400","0.68220","0.02069"
"1392","8.31600","0.69326","0.02072"
"1414","8.44800","0.70420","0.02033"
"1436","8.58000","0.71520","0.02124"
"1458","8.71200","0.72614","0.02085"
"1480","8.84400","0.73726","0.02104"
"1502","8.97600","0.74827","0.02164"
"1524","9.10800","0.75921","0.02211"
"1546","9.24000","0.77015","0.02178"
"1568","9.37200","0.78127","0.02220"
"1590","9.50400","0.79227","0.02225"
"1612","9.63600","0.80321","0.02247"
"1634","9.76800","0.81421","0.02272"
"1656","9.90000","0.82522","0.02280"
"1678","10.03200","0.83622","0.02261"
"1700","10.16400","0.84722","0.02339"
"1722","10.29600","0.85816","0.02316"
"1744","10.42800","0.86916","0.02334"
"1766","10.56000","0.88022","0.02381"
"1788","10.69200","0.89116","0.02350"
"1810","10.82400","0.90210","0.02359"
"1832","10.95600","0.91323","0.02397"
"1854","11.08800","0.92423","0.02348"
"1876","11.22000","0.93523","0.02379"
"1898","11.35200","0.94617","0.02448"
"1920","11.48400","0.95723","0.02433"
"1942","11.61600","0.96823","0.02439"
"1964","11.74800","0.97923","0.02539"
"1986","11.88000","0.99017","0.02509"
"2008","12.01200","1.00124","0.02517"
"2030","12.14400","1.01224","0.02480"
"2052","12.27600","1.02324","0.02600"
"2074","12.40800","1.03418","0.02543"
"2096","12.54000","1.04518","0.02568"
"2118","12.67200","1.05618","0.02588"
"2140","12.80400","1.06718","0.02582"
"2162","12.93600","1.07818","0.02605"
"2184","13.06800","1.08919","0.02642"
"2206","13.20000","1.10025","0.02651"
"2228","13.33200","1.11119","0.02656"
"2250","13.46400","1.12219","0.02677"
"2272","13.59600","1.13319","0.02676"
"2294","13.72800","1.14419","0.02666"
"2316","13.86000","1.15519","0.02728"
"2338","13.99200","1.16619","0.02768"
"2360","14.12400","1.17720","0.02786"
"2382","14.25600","1.18826","0.02777"
"2404","14.38800","1.19920","0.02810"
"2426","14.52000","1.21020","0.02770"
"2448","14.65200","1.22126","0.02786"
"2470","14.78400","1.23226","0.02850"
"2492","14.91600","1.24326","0.02861"
"2514","15.04800","1.25415","0.02889"
"2536","15.18000","1.26515","0.02902"
"2558","15.31200","1.27621","0.02927"
"2580","15.44400","1.28721","0.02916"
"2602","15.57600","1.29815","0.02938"
"2624","15.70800","1.30915","0.02941"
"2646","15.84000","1.32021","0.02931"
"2668","15.97200","1.33121","0.02999"
"2690","16.10400","1.34222","0.02990"
"2712","16.23600","1.35316","0.03050"
"2734","16.36800","1.36422","0.03004"
"2756","16.50000","1.37522","0.03072"
"2778","16.63200","1.38622","0.03057"
"2800","16.76400","1.39716","0.03105"
"2822","16.89600","1.40822","0.03080"
"2844","17.02800","1.41922","0.03130"
"2866","17.16000","1.43017","0.03083"
"2888","17.29200","1.44111","0.03093"
"2910","17.42400","1.45223","0.03181"
"2932","17.55600","1.46323","0.03151"
"2954","17.68800","1.47423","0.03173"
"2976","17.82000","1.48517","0.03198"
"2998","17.95200","1.49623","0.03190"
"3020","18.08400","1.50723","0.03207"
"3042","18.21600","1.51818","0.03241"
"3064","18.34800","1.52918","0.03245"
"3086","18.48000","1.54018","0.03284"
"3108","18.61200","1.55124","0.03226"
"3130","18.74400","1.56218","0.03266"
"3152","18.87600","1.57318","0.03279"
"3174","19.00800","1.58418","0.03309"
"3196","19.14000","1.59518","0.03300"
"3218","19.27200","1.60619","0.03332"
"3240","19.40400","1.61719","0.03349"
"3262","19.53600","1.62819","0.03370"
"3284","19.66800","1.63925","0.03392"
"3306","19.80000","1.65025","0.03425"
"3328","19.93200","1.66119","0.03394"
"3350","20.06400","1.67219","0.03406"
"3372","20.19600","1.68319","0.03418"
"3394","20.32800","1.69426","0.03471"
"3416","20.46000","1.70520","0.03461"
"3438","20.59200","1.71620","0.03437"
"3460","20.72400","1.72720","0.03449"
"3482","20.85600","1.73820","0.03461"
"3504","20.98800","1.74920","0.03493"
"3526","21.12000","1.76020","0.03503"
"3548","21.25200","1.77126","0.03490"
"3570","21.38400","1.78227","0.03533"
"3592","21.51600","1.79321","0.03537"
"3614","21.64800","1.80421","0.03538"
"3636","21.78000","1.81521","0.03536"
"3658","21.91200","1.82621","0.03573"
"3680","22.04400","1.83715","0.03581"
"3702","22.17600","1.84815","0.03567"
"3724","22.30800","1.85922","0.03621"
"3746","22.44000","1.87022","0.03630"
"3768","22.57200","1.88122","0.03642"
"3790","22.70400","1.89222","0.03625"
"3812","22.83600","1.90328","0.03652"
"3834","22.96800","1.91422","0.03662"
"3856","23.10000","1.92522","0.03680"
"3878","23.23200","1.93616","0.03658"
"3900","23.36400","1.94723","0.03712"
"3922","23.49600","1.95823","0.03696"
"3944","23.62800","1.96917","0.03709"
"3966","23.76000","1.98017","0.03708"
"3988","23.89200","1.99117","0.03693"
"4010","24.02400","2.00223","0.03776"
"4032","24.15600","2.01317","0.03727"
"4054","24.28800","2.02411","0.03776"
"4076","24.42000","2.03524","0.03771"
"4098","24.55200","2.04624","0.03801"
"4120","24.68400","2.05724","0.03792"
"4142","24.81600","2.06818","0.03821"
"4164","24.94800","2.07924","0.03831"
"4186","25.08000","2.09018","0.03823"
"4208","25.21200","2.10118","0.03838"
"4230","25.34400","2.11213","0.03857"
"4252","25.47600","2.12325","0.03839"
"4274","25.60800","2.13425","0.03831"
"4296","25.74000","2.14525","0.03866"
"4318","25.87200","2.15613","0.03868"
"4340","26.00400","2.16719","0.03874"
"4362","26.13600","2.17825","0.03845"
"4384","26.26800","2.18925","0.03922"
"4406","26.40000","2.20020","0.03875"
"4428","26.53200","2.21120","0.03919"
"4450","26.66400","2.22226","0.03917"
"4472","26.79600","2.23320","0.03909"
"4494","26.92800","2.24420","0.03960"
"4516","27.06000","2.25514","0.03936"
"4538","27.19200","2.26620","0.03952"
"4560","27.32400","2.27720","0.03965"
"4582","27.45600","2.28821","0.03995"
"4604","27.58800","2.29921","0.03990"
"4626","27.72000","2.31021","0.03997"
"4648","27.85200","2.32127","0.03996"
"4670","27.98400","2.33215","0.04004"
"4692","28.11600","2.34321","0.04029"
"4714","28.24800","2.35421","0.04051"
"4736","28.38000","2.36521","0.04064"
"4758","28.51200","2.37616","0.04075"
"4780","28.64400","2.38716","0.04099"
"4802","28.77600","2.39816","0.04127"
"4824","28.90800","2.40922","0.04065"
"4846","29.04000","2.42016","0.04090"
"4868","29.17200","2.43116","0.04098"
"4890","29.30400","2.44222","0.04108"
"4912","29.43600","2.45322","0.04122"
"4934","29.56800","2.46417","0.04161"
"4956","29.70000","2.47517","0.02051"
"4978","29.83200","2.48623","0.01919"
"5000","29.96400","2.49723","0.01920"
"5022","30.09600","2.50823","0.02128"
"5044","30.22800","2.51911","0.02111"
"5066","30.36000","2.53017","0.02060"
"5088","30.49200","2.54123","0.02185"
"5110","30.62400","2.55218","0.02341"
"5132","30.75600","2.56318","0.02365"
"5154","30.88800","2.57424","0.02398"
"5176","31.02000","2.58524","0.02384"
"5198","31.15200","2.59624","0.02352"
"5220","31.28400","2.60718","0.02475"
"5242","31.41600","2.61824","0.02404"
"5264","31.54800","2.62919","0.02393"
"5286","31.68000","2.64019","0.02467"
"5308","31.81200","2.65119","0.02579"
"5330","31.94400","2.66219","0.02562"
"5352","32.07600","2.67319","0.02570"
"5374","32.20800","2.68413","0.02597"
"5396","32.34000","2.69513","0.02685"
"5418","32.47200","2.70619","0.02634"
"5440","32.60400","2.71725","0.02626"
"5462","32.73600","2.72826","0.02791"
"5484","32.86800","2.73914","0.02762"
"5506","33.00000","2.75026","0.02738"
"5528","33.13200","2.76120","0.02802"
"5550","33.26400","2.77220","0.02837"
"5572","33.39600","2.78320","0.02838"
"5594","33.52800","2.79426","0.02845"
"5616","33.66000","2.80526","0.02866"
"5638","33.79200","2.81621","0.02949"
"5660","33.92400","2.82715","0.02965"
"5682","34.05600","2.83821","0.02934"
"5704","34.18800","2.84927","0.03036"
"5726","34.32000","2.86021","0.03005"
"5748","34.45200","2.87115","0.03035"
"5770","34.58400","2.88221","0.02982"
"5792","34.71600","2.89322","0.03061"
"5814","34.84800","2.90422","0.03145"
"5836","34.98000","2.91516","0.03093"
"5858","35.11200","2.92610","0.03094"
"5880","35.24400","2.93722","0.03170"
"5902","35.37600","2.94822","0.03183"
"5924","35.50800","2.95916","0.03174"
"5946","35.64000","2.97016","0.03210"
"5968","35.77200","2.98123","0.03237"
"5990","35.90400","2.99223","0.03231"
"6012","36.03600","3.00317","0.03237"
"6034","36.16800","3.01423","0.03221"
"6056","36.30000","3.02523","0.03322"
"6078","36.43200","3.03623","0.03284"
"6100","36.56400","3.04717","0.03286"
"6122","36.69600","3.05812","0.03353"
"6144","36.82800","3.06924","0.03390"
"6166","36.96000","3.08024","0.03372"
"6188","37.09200","3.09118","0.03355"
"6210","37.22400","3.10218","0.03414"
"6232","37.35600","3.11324","0.03447"
"6254","37.48800","3.12424","0.03412"
"6276","37.62000","3.13524","0.03468"
"6298","37.75200","3.14618","0.03448"
"6320","37.88400","3.15725","0.03500"
"6342","38.01600","3.16825","0.03484"
"6364","38.14800","3.17919","0.03531"
"6386","38.28000","3.19013","0.03580"
"6408","38.41200","3.20119","0.03503"
"6430","38.54400","3.21219","0.03547"
"6452","38.67600","3.22319","0.03598"
"6474","38.80800","3.23414","0.03604"
"6496","38.94000","3.24520","0.03640"
"6518","39.07200","3.25620","0.03592"
"6540","39.20400","3.26720","0.03662"
"6562","39.33600","3.27820","0.03677"
"6584","39.46800","3.28920","0.03667"
"6606","39.60000","3.30026","0.03655"
"6628","39.73200","3.31120","0.03724"
"6650","39.86400","3.32215","0.03665"
"6672","39.99600","3.33321","0.03710"
"6694","40.12800","3.34421","0.03714"
"6716","40.26000","3.35515","0.03772"
"6738","40.39200","3.36615","0.03723"
"6760","40.52400","3.37715","0.03742"
"6782","40.65600","3.38821","0.03775"
"6804","40.78800","3.39921","0.03784"
"6826","40.92000","3.41016","0.03774"
"6848","41.05200","3.42116","0.03757"
"6870","41.18400","3.43222","0.03843"
"6892","41.31600","3.44322","0.03778"
"6914","41.44800","3.45416","0.03781"
"6936","41.58000","3.46522","0.03849"
"6958","41.71200","3.47622","0.03856"
"6980","41.84400","3.48722","0.03870"
"7002","41.97600","3.49817","0.03885"
"7024","42.10800","3.50923","0.03915"
"7046","42.24000","3.52023","0.03868"
"7068","42.37200","3.53123","0.03896"
"7090","42.50400","3.54217","0.03909"
"7112","42.63600","3.55323","0.03931"
"7134","42.76800","3.56429","0.03933"
"7156","42.90000","3.57523","0.03933"
"7178","43.03200","3.58618","0.03976"
"7200","43.16400","3.59718","0.03963"
"7222","43.29600","3.60824","0.03993"
"7244","43.42800","3.61924","0.04024"
"7266","43.56000","3.63018","0.04016"
"7288","43.69200","3.64112","0.04054"
"7310","43.82400","3.65224","0.04037"
"7332","43.95600","3.66325","0.04030"
"7354","44.08800","3.67419","0.04078"
"7376","44.22000","3.68519","0.04102"
"7398","44.35200","3.69625","0.04060"
"7420","44.48400","3.70725","0.04111"
"7442","44.61600","3.71819","0.04139"
"7464","44.74800","3.72913","0.04152"
"7486","44.88000","3.74019","0.04186"
"7508","45.01200","3.75120","0.04187"
"7530","45.14400","3.76220","0.04180"
"7552","45.27600","3.77320","0.04186"
"7574","45.40800","3.78420","0.04259"
"7596","45.54000","3.79520","0.04229"
"7618","45.67200","3.80620","0.04241"
"7640","45.80400","3.81720","0.04308"
"7662","45.93600","3.82820","0.04321"
"7684","46.06800","3.83927","0.04401"
"7706","46.20000","3.85021","0.04484"
"7728","46.33200","3.86115","0.04410"
"7750","46.46400","3.87221","0.04451"
"7772","46.59600","3.88321","0.04457"
"7794","46.72800","3.89421","0.04492"
"7816","46.86000","3.90515","0.04579"
"7838","46.99200","3.91621","0.04529"
"7860","47.12400","3.92722","0.04582"
"7882","47.25600","3.93822","0.04594"
"7904","47.38800","3.94916","0.04627"
"7926","47.52000","3.96016","0.04665"
"7948","47.65200","3.97128","0.04679"
"7970","47.78400","3.98222","0.04748"
"7992","47.91600","3.99316","0.04781"
"8014","48.04800","4.00416","0.04767"
"8036","48.18000","4.01523","0.04824"
"8058","48.31200","4.02623","0.04929"
"8080","48.44400","4.03723","0.04917"
"8102","48.57600","4.04817","0.04933"
"8124","48.70800","4.05923","0.04958"
"8146","48.84000","4.07017","0.05011"
"8168","48.97200","4.08117","0.05082"
"8190","49.10400","4.09218","0.05103"
"8212","49.23600","4.10324","0.05183"
"8234","49.36800","4.11424","0.05208"
"8256","49.50000","4.12518","0.05199"
"8278","49.63200","4.13618","0.05268"
"8300","49.76400","4.14718","0.05316"
"8322","49.89600","4.15818","0.05361"
"8344","50.02800","4.16912","0.05364"
"8366","50.16000","4.18013","0.05497"
"8388","50.29200","4.19125","0.05508"
"8410","50.42400","4.20225","0.05542"
"8432","50.55600","4.21319","0.05574"
"8454","50.68800","4.22419","0.05682"
"8476","50.82000","4.23531","0.05652"
"8498","50.95200","4.24625","0.05692"
"8520","51.08400","4.25719","0.05790"
"8542","51.21600","4.26820","0.05785"
"8564","51.34800","4.27920","0.05850"
"8586","51.48000","4.29020","0.05928"
"8608","51.61200","4.30120","0.05951"
"8630","51.74400","4.31214","0.05949"
"8652","51.87600","4.32320","0.06031"
"8674","52.00800","4.33426","0.06149"
"8696","52.14000","4.34520","0.06135"
"8718","52.27200","4.35615","0.06205"
"8740","52.40400","4.36727","0.06247"
"8762","52.53600","4.37827","0.06328"
"8784","52.66800","4.38921","0.06348"
"8806","52.80000","4.40015","0.06437"
"8828","52.93200","4.41121","0.06481"
"8850","53.06400","4.42221","0.06475"
"8872","53.19600","4.43315","0.06535"
"8894","53.32800","4.44416","0.06596"
"8916","53.46000","4.45516","0.06636"
"8938","53.59200","4.46622","0.06682"
"8960","53.72400","4.47722","0.06712"
"8982","53.85600","4.48816","0.06775"
"9004","53.98800","4.49916","0.06771"
"9026","54.12000","4.51022","0.06858"
"9048","54.25200","4.52122","0.06918"
"9070","54.38400","4.53217","0.06939"
"9092","54.51600","4.54323","0.06978"
"9114","54.64800","4.55423","0.07038"
"9136","54.78000","4.56523","0.07100"
"9158","54.91200","4.57617","0.07141"
"9180","55.04400","4.58717","0.07178"
"9202","55.17600","4.59817","0.07202"
"9224","55.30800","4.60924","0.07246"
"9246","55.44000","4.62018","0.07256"
"9268","55.57200","4.63124","0.07326"
"9290","55.70400","4.64224","0.07320"
"9312","55.83600","4.65324","0.07365"
"9334","55.96800","4.66424","0.07450"
"9356","56.10000","4.67518","0.07543"
"9378","56.23200","4.68624","0.07551"
"9400","56.36400","4.69719","0.07578"
"9422","56.49600","4.70819","0.07674"
"9444","56.62800","4.71919","0.07760"
"9466","56.76000","4.73025","0.07778"
"9488","56.89200","4.74119","0.07811"
"9510","57.02400","4.75219","0.07925"
"9532","57.15600","4.76319","0.07930"
"9554","57.28800","4.77425","0.08008"
"9576","57.42000","4.78520","0.08076"
"9598","57.55200","4.79620","0.08137"
"9620","57.68400","4.80720","0.08212"
"9642","57.81600","4.81820","0.08349"
"9664","57.94800","4.82920","0.08318"
"9686","58.08000","4.84014","0.08358"
"9708","58.21200","4.85114","0.08454"
"9730","58.34400","4.86220","0.08479"
"9752","58.47600","4.87321","0.08538"
"9774","58.60800","4.88421","0.08560"
"9796","58.74000","4.89515","0.08610"
"9818","58.87200","4.90621","0.08673"
"9840","59.00400","4.91727","0.08688"
"9862","59.13600","4.92827","0.08731"
"9884","59.26800","4.93921","0.08770"
"9906","59.40000","4.95027","0.08794"
"9928","59.53200","4.96122","0.08826"
"9950","59.66400","4.97216","0.08816"
"9972","59.79600","4.98310","0.08865"
"9994","59.92800","4.99422","0.08881"
"10016","60.06000","5.00522","0.08940"
"10038","60.19200","5.01622","0.08962"
"10060","60.32400","5.02716","0.08994"
"10082","60.45600","5.03823","0.09013"
"10104","60.58800","5.04923","0.09020"
"10126","60.72000","5.06029","0.09033"
"10148","60.85200","5.07117","0.09057"
"10170","60.98400","5.08223","0.09061"
"10192","61.11600","5.09329","0.09090"
"10214","61.24800","5.10417","0.09099"
"10236","61.38000","5.11517","0.09095"
"10258","61.51200","5.12618","0.09104"
"10280","61.64400","5.13724","0.09132"
"10302","61.77600","5.14824","0.09156"
"10324","61.90800","5.15918","0.09140"
"10346","62.04000","5.17018","0.09170"
"10368","62.17200","5.18118","0.09177"
"10390","62.30400","5.19224","0.09197"
"10412","62.43600","5.20318","0.09222"
"10434","62.56800","5.21419","0.09231"
"10456","62.70000","5.22525","0.09273"
"10478","62.83200","5.23625","0.09257"
"10500","62.96400","5.24719","0.09297"
"10522","63.09600","5.25819","0.09352"
"10544","63.22800","5.26919","0.09370"
"10566","63.36000","5.28025","0.09456"
"10588","63.49200","5.29113","0.09447"
"10610","63.62400","5.30220","0.09499"
"10632","63.75600","5.31320","0.09498"
"10654","63.88800","5.32426","0.09638"
"10676","64.02000","5.33526","0.09691"
"10698","64.15200","5.34620","0.09750"
"10720","64.28400","5.35726","0.09832"
"10742","64.41600","5.36820","0.09844"
"10764","64.54800","5.37920","0.09953"
"10786","64.68000","5.39015","0.10073"
"10808","64.81200","5.40121","0.10127"
"10830","64.94400","5.41221","0.10165"
"10852","65.07600","5.42321","0.10295"
"10874","65.20800","5.43421","0.10390"
"10896","65.34000","5.44521","0.10464"
"10918","65.47200","5.45627","0.10571"
"10940","65.60400","5.46721","0.10610"
"10962","65.73600","5.47816","0.10668"
"10984","65.86800","5.48922","0.10830"
"11006","66.00000","5.50022","0.10849"
"11028","66.13200","5.51122","0.10917"
"11050","66.26400","5.52216","0.11047"
"11072","66.39600","5.53322","0.11111"
"11094","66.52800","5.54422","0.11174"
"11116","66.66000","5.55516","0.11241"
"11138","66.79200","5.56617","0.11292"
"11160","66.92400","5.57717","0.11360"
"11182","67.05600","5.58817","0.11408"
"11204","67.18800","5.59923","0.11526"
"11226","67.32000","5.61017","0.11604"
"11248","67.45200","5.62123","0.11644"
"11270","67.58400","5.63223","0.11766"
"11292","67.71600","5.64324","0.11800"
"11314","67.84800","5.65412","0.11864"
"11336","67.98000","5.66524","0.11864"
"11358","68.11200","5.67618","0.11942"
"11380","68.24400","5.68718","0.12011"
"11402","68.37600","5.69818","0.12105"
"11424","68.50800","5.70918","0.12129"
"11446","68.64000","5.72018","0.12160"
"11468","68.77200","5.73125","0.12183"
"11490","68.90400","5.74213","0.12252"
"11512","69.03600","5.75319","0.12266"
"11534","69.16800","5.76419","0.12329"
"11556","69.30000","5.77519","0.12402"
"11578","69.43200","5.78613","0.12407"
"11600","69.56400","5.79719","0.12438"
"11622","69.69600","5.80825","0.12465"
"11644","69.82800","5.81926","0.12552"
"11666","69.96000","5.83020","0.12531"
"11688","70.09200","5.84114","0.12587"
"11710","70.22400","5.85226","0.12609"
"11732","70.35600","5.86320","0.12628"
"11754","70.48800","5.87420","0.12687"
"11776","70.62000","5.88520","0.12706"
"11798","70.75200","5.89626","0.12733"
"11820","70.88400","5.90727","0.12758"
"11842","71.01600","5.91815","0.12786"
"11864","71.14800","5.92915","0.12798"
"11886","71.28000","5.94021","0.12837"
"11908","71.41200","5.95121","0.12883"
"11930","71.54400","5.96215","0.12912"
"11952","71.67600","5.97315","0.12958"
"11974","71.80800","5.98422","0.12972"
"11996","71.94000","5.99522","0.13016"
"12018","72.07200","6.00622","0.13009"
"12040","72.20400","6.01722","0.13120"
"12062","72.33600","6.02822","0.13135"
"12084","72.46800","6.03922","0.13162"
"12106","72.60000","6.05022","0.13221"
"12128","72.73200","6.06116","0.13235"
"12150","72.86400","6.07223","0.13315"
"12172","72.99600","6.08323","0.13358"
"12194","73.12800","6.09417","0.13414"
"12216","73.26000","6.10517","0.13404"
"12238","73.39200","6.11623","0.13443"
"12260","73.52400","6.12723","0.13493"
"12282","73.65600","6.13823","0.13527"
"12304","73.78800","6.14917","0.13578"
"12326","73.92000","6.16024","0.13587"
"12348","74.05200","6.17124","0.13637"
"12370","74.18400","6.18224","0.13704"
"12392","74.31600","6.19312","0.13710"
"12414","74.44800","6.20418","0.13748"
"12436","74.58000","6.21518","0.13828"
"12458","74.71200","6.22618","0.13828"
"12480","74.84400","6.23712","0.13887"
"12502","74.97600","6.24819","0.13887"
"12524","75.10800","6.25919","0.13940"
"12546","75.24000","6.27013","0.13992"
"12568","75.37200","6.28119","0.13994"
"12590","75.50400","6.29219","0.14060"
"12612","75.63600","6.30325","0.14064"
"12634","75.76800","6.31425","0.14121"
"12656","75.90000","6.32519","0.14147"
"12678","76.03200","6.33626","0.14192"
"12700","76.16400","6.34720","0.14211"
"12722","76.29600","6.35820","0.14250"
"12744","76.42800","6.36914","0.14315"
"12766","76.56000","6.38020","0.14334"
"12788","76.69200","6.39120","0.14340"
"12810","76.82400","6.40220","0.14410"
"12832","76.95600","6.41315","0.14450"
"12854","77.08800","6.42415","0.14507"
"12876","77.22000","6.43521","0.14510"
"12898","77.35200","6.44621","0.14577"
"12920","77.48400","6.45715","0.14651"
"12942","77.61600","6.46821","0.14692"
"12964","77.74800","6.47921","0.14791"
"12986","77.88000","6.49021","0.14822"
"13008","78.01200","6.50121","0.14877"
"13030","78.14400","6.51216","0.15011"
"13052","78.27600","6.52322","0.15040"
"13074","78.40800","6.53428","0.15062"
"13096","78.54000","6.54516","0.15228"
"13118","78.67200","6.55616","0.15236"
"13140","78.80400","6.56722","0.15352"
"13162","78.93600","6.57822","0.15421"
"13184","79.06800","6.58917","0.15555"
"13206","79.20000","6.60017","0.15581"
"13228","79.33200","6.61117","0.15708"
"13250","79.46400","6.62223","0.15830"
"13272","79.59600","6.63317","0.15942"
"13294","79.72800","6.64411","0.16035"
"13316","79.86000","6.65523","0.16149"
"13338","79.99200","6.66623","0.16228"
"13360","80.12400","6.67724","0.16399"
"13382","80.25600","6.68818","0.16586"
"13404","80.38800","6.69924","0.16698"
"13426","80.52000","6.71024","0.16954"
"13448","80.65200","6.72124","0.16944"
"13470","80.78400","6.73218","0.17171"
"13492","80.91600","6.74318","0.17336"
"13514","81.04800","6.75418","0.17467"
"13536","81.18000","6.76525","0.17586"
"13558","81.31200","6.77613","0.17736"
"13580","81.44400","6.78719","0.17880"
"13602","81.57600","6.79819","0.18110"
"13624","81.70800","6.80919","0.18190"
"13646","81.84000","6.82019","0.18453"
"13668","81.97200","6.83119","0.18473"
"13690","82.10400","6.84219","0.18602"
"13712","82.23600","6.85320","0.18707"
"13734","82.36800","6.86420","0.18762"
"13756","82.50000","6.87520","0.18676"
"13778","82.63200","6.88620","0.18734"
"13800","82.76400","6.89720","0.18913"
"13822","82.89600","6.90820","0.18971"
"13844","83.02800","6.91920","0.19074"
"13866","83.16000","6.93020","0.19071"
"13888","83.29200","6.94115","0.19172"
"13910","83.42400","6.95215","0.19103"
"13932","83.55600","6.96315","0.19253"
"13954","83.68800","6.97427","0.19302"
"13976","83.82000","6.98521","0.19368"
"13998","83.95200","6.99621","0.19411"
"14020","84.08400","7.00721","0.19460"
"14042","84.21600","7.01822","0.19520"
"14064","84.34800","7.02922","0.19522"
"14086","84.48000","7.04016","0.19647"
"14108","84.61200","7.05122","0.19607"
"14130","84.74400","7.06222","0.19663"
"14152","84.87600","7.07328","0.19724"
"14174","85.00800","7.08416","0.19810"
"14196","85.14000","7.09522","0.19904"
"14218","85.27200","7.10623","0.20005"
"14240","85.40400","7.11723","0.20056"
"14262","85.53600","7.12823","0.20137"
"14284","85.66800","7.13923","0.20229"
"14306","85.80000","7.15023","0.20267"
"14328","85.93200","7.16123","0.20482"
"14350","86.06400","7.17217","0.20580"
"14372","86.19600","7.18317","0.20693"
"14394","86.32800","7.19424","0.20800"
"14416","86.46000","7.20530","0.20819"
"14438","86.59200","7.21618","0.21005"
"14460","86.72400","7.22712","0.21123"
"14482","86.85600","7.23824","0.21289"
"14504","86.98800","7.24924","0.21291"
"14526","87.12000","7.26024","0.21411"
"14548","87.25200","7.27124","0.21512"
"14570","87.38400","7.28219","0.21655"
"14592","87.51600","7.29325","0.21774"
"14614","87.64800","7.30419","0.21815"
"14636","87.78000","7.31513","0.21964"
"14658","87.91200","7.32619","0.22101"
"14680","88.04400","7.33719","0.22161"
"14702","88.17600","7.34819","0.22284"
"14724","88.30800","7.35919","0.22397"
"14746","88.44000","7.37020","0.22500"
"14768","88.57200","7.38120","0.22590"
"14790","88.70400","7.39226","0.22677"
"14812","88.83600","7.40320","0.22775"
"14834","88.96800","7.41420","0.22836"
"14856","89.10000","7.42526","0.22948"
"14878","89.23200","7.43626","0.23052"
"14900","89.36400","7.44714","0.23093"
"14922","89.49600","7.45821","0.23194"
"14944","89.62800","7.46921","0.23280"
"14966","89.76000","7.48021","0.23369"
"14988","89.89200","7.49115","0.23417"
"15010","90.02400","7.50221","0.23503"
"15032","90.15600","7.51321","0.23567"
"15054","90.28800","7.52421","0.23591"
"15076","90.42000","7.53521","0.23678"
"15098","90.55200","7.54622","0.23708"
"15120","90.68400","7.55722","0.23764"
"15142","90.81600","7.56822","0.23811"
"15164","90.94800","7.57916","0.23821"
"15186","91.08000","7.59016","0.23855"
"15208","91.21200","7.60122","0.23903"
"15230","91.34400","7.61222","0.23927"
"15252","91.47600","7.62323","0.23974"
"15274","91.60800","7.63423","0.23989"
"15296","91.74000","7.64529","0.24011"
"15318","91.87200","7.65617","0.24038"
"15340","92.00400","7.66723","0.24051"
"15362","92.13600","7.67823","0.24073"
"15384","92.26800","7.68923","0.24101"
"15406","92.40000","7.70018","0.24125"
"15428","92.53200","7.71112","0.24165"
"15450","92.66400","7.72218","0.24196"
"15472","92.79600","7.73318","0.24207"
"15494","92.92800","7.74424","0.24251"
"15516","93.06000","7.75518","0.24256"
"15538","93.19200","7.76618","0.24306"
"15560","93.32400","7.77724","0.24360"
"15582","93.45600","7.78824","0.24384"
"15604","93.58800","7.79919","0.24428"
"15626","93.72000","7.81019","0.24438"
"15648","93.85200","7.82125","0.24466"
"15670","93.98400","7.83225","0.24510"
"15692","94.11600","7.84319","0.24550"
"15714","94.24800","7.85413","0.24562"
"15736","94.38000","7.86519","0.24594"
"15758","94.51200","7.87625","0.24692"
"15780","94.64400","7.88720","0.24757"
"15802","94.77600","7.89814","0.24835"
"15824","94.90800","7.90920","0.24916"
"15846","95.04000","7.92020","0.24975"
"15868","95.17200","7.93120","0.25091"
"15890","95.30400","7.94214","0.25199"
"15912","95.43600","7.95326","0.25293"
"15934","95.56800","7.96426","0.25428"
"15956","95.70000","7.97521","0.25545"
"15978","95.83200","7.98615","0.25692"
"16000","95.96400","7.99715","0.25767"
"16022","96.09600","8.00815","0.25951"
"16044","96.22800","8.01915","0.26077"
"16066","96.36000","8.03015","0.26245"
"16088","96.49200","8.04115","0.26349"
"16110","96.62400","8.05221","0.26491"
"16132","96.75600","8.06328","0.26602"
"16154","96.88800","8.07416","0.26688"
"16176","97.02000","8.08522","0.26833"
"16198","97.15200","8.09628","0.26946"
"16220","97.28400","8.10722","0.27105"
"16242","97.41600","8.11816","0.27267"
"16264","97.54800","8.12922","0.27308"
"16286","97.68000","8.14023","0.27394"
"16308","97.81200","8.15129","0.27491"
"16330","97.94400","8.16223","0.27526"
"16352","98.07600","8.17323","0.27751"
"16374","98.20800","8.18423","0.27844"
"16396","98.34000","8.19523","0.27994"
"16418","98.47200","8.20617","0.28071"
"16440","98.60400","8.21723","0.28261"
"16462","98.73600","8.22824","0.28375"
"16484","98.86800","8.23924","0.28483"
"16506","99.00000","8.25024","0.28590"
"16528","99.13200","8.26118","0.28655"
"16550","99.26400","8.27218","0.28717"
"16572","99.39600","8.28318","0.28754"
"16594","99.52800","8.29418","0.28858"
"16616","99.66000","8.30513","0.28887"
"16638","99.79200","8.31619","0.28959"
"16660","99.92400","8.32725","0.29009"
"16682","100.05600","8.33819","0.29091"
"16704","100.18800","8.34919","0.29129"
"16726","100.32000","8.36025","0.29227"
"16748","100.45200","8.37119","0.29327"
"16770","100.58400","8.38219","0.29448"
"16792","100.71600","8.39314","0.29594"
"16814","100.84800","8.40420","0.29758"
"16836","100.98000","8.41520","0.29893"
"16858","101.11200","8.42614","0.30078"
"16880","101.24400","8.43720","0.30291"
"16902","101.37600","8.44826","0.30551"
"16924","101.50800","8.45920","0.30806"
"16946","101.64000","8.47020","0.30978"
"16968","101.77200","8.48114","0.31356"
"16990","101.90400","8.49221","0.31493"
"17012","102.03600","8.50321","0.31763"
"17034","102.16800","8.51421","0.31946"
"17056","102.30000","8.52515","0.32089"
"17078","102.43200","8.53621","0.32386"
"17100","102.56400","8.54721","0.32547"
"17122","102.69600","8.55815","0.32772"
"17144","102.82800","8.56910","0.32909"
"17166","102.96000","8.58022","0.33142"
"17188","103.09200","8.59122","0.33312"
"17210","103.22400","8.60222","0.33449"
"17232","103.35600","8.61316","0.33625"
"17254","103.48800","8.62422","0.33741"
"17276","103.62000","8.63528","0.33880"
"17298","103.75200","8.64628","0.34055"
"17320","103.88400","8.65717","0.34138"
"17342","104.01600","8.66823","0.34203"
"17364","104.14800","8.67923","0.34334"
"17386","104.28000","8.69017","0.34401"
"17408","104.41200","8.70117","0.34502"
"17430","104.54400","8.71217","0.34576"
"17452","104.67600","8.72317","0.34643"
"17474","104.80800","8.73423","0.34703"
"17496","104.94000","8.74512","0.34745"
"17518","105.07200","8.75618","0.34806"
"17540","105.20400","8.76724","0.34841"
"17562","105.33600","8.77824","0.34865"
"17584","105.46800","8.78918","0.34912"
"17606","105.60000","8.80018","0.34912"
"17628","105.73200","8.81124","0.34963"
"17650","105.86400","8.82224","0.34980"
"17672","105.99600","8.83319","0.35018"
"17694","106.12800","8.84419","0.35040"
"17716","106.26000","8.85525","0.35062"
"17738","106.39200","8.86625","0.35129"
"17760","106.52400","8.87719","0.35148"
"17782","106.65600","8.88819","0.35162"
"17804","106.78800","8.89925","0.35221"
"17826","106.92000","8.91025","0.35308"
"17848","107.05200","8.92120","0.35326"
"17870","107.18400","8.93220","0.35360"
"17892","107.31600","8.94326","0.35445"
"17914","107.44800","8.95420","0.35512"
"17936","107.58000","8.96520","0.35554"
"17958","107.71200","8.97614","0.35616"
"17980","107.84400","8.98720","0.35661"
"18002","107.97600","8.99821","0.35719"
"18024","108.10800","9.00921","0.35794"
"18046","108.24000","9.02015","0.35829"
"18068","108.37200","9.03121","0.35951"
"18090","108.50400","9.04227","0.36053"
"18112","108.63600","9.05321","0.36107"
"18134","108.76800","9.06415","0.36238"
"18156","108.90000","9.07521","0.36310"
"18178","109.03200","9.08615","0.36373"
"18200","109.16400","9.09716","0.36490"
"18222","109.29600","9.10816","0.36645"
"18244","109.42800","9.11928","0.36797"
"18266","109.56000","9.13022","0.36891"
"18288","109.69200","9.14122","0.36950"
"18310","109.82400","9.15222","0.37073"
"18332","109.95600","9.16322","0.37254"
"18354","110.08800","9.17423","0.37410"
"18376","110.22000","9.18529","0.37595"
"18398","110.35200","9.19617","0.37742"
"18420","110.48400","9.20723","0.37906"
"18442","110.61600","9.21823","0.38074"
"18464","110.74800","9.22923","0.38254"
"18486","110.88000","9.24017","0.38452"
"18508","111.01200","9.25123","0.38453"
"18530","111.14400","9.26218","0.38624"
"18552","111.27600","9.27318","0.38802"
"18574","111.40800","9.28418","0.38948"
"18596","111.54000","9.29524","0.39067"
"18618","111.67200","9.30624","0.39171"
"18640","111.80400","9.31724","0.39314"
"18662","111.93600","9.32818","0.39411"
"18684","112.06800","9.33918","0.39504"
"18706","112.20000","9.35025","0.39576"
"18728","112.33200","9.36119","0.39658"
"18750","112.46400","9.37213","0.39714"
"18772","112.59600","9.38313","0.39788"
"18794","112.72800","9.39425","0.39820"
"18816","112.86000","9.40525","0.39893"
"18838","112.99200","9.41619","0.39970"
"18860","113.12400","9.42713","0.40031"
"18882","113.25600","9.43826","0.40119"
"18904","113.38800","9.44920","0.40240"
"18926","113.52000","9.46014","0.40396"
"18948","113.65200","9.47114","0.40487"
"18970","113.78400","9.48220","0.40675"
"18992","113.91600","9.49326","0.40831"
"19014","114.04800","9.50414","0.41015"
"19036","114.18000","9.51515","0.41184"
"19058","114.31200","9.52621","0.41311"
"19080","114.44400","9.53721","0.41470"
"19102","114.57600","9.54821","0.41648"
"19124","114.70800","9.55921","0.41736"
"19146","114.84000","9.57021","0.41876"
"19168","114.97200","9.58121","0.42028"
"19190","115.10400","9.59227","0.42106"
"19212","115.23600","9.60316","0.42260"
"19234","115.36800","9.61422","0.42415"
"19256","115.50000","9.62522","0.42465"
"19278","115.63200","9.63616","0.42587"
"19300","115.76400","9.64710","0.42690"
"19322","115.89600","9.65816","0.42796"
"19344","116.02800","9.66922","0.42921"
"19366","116.16000","9.68022","0.42989"
"19388","116.29200","9.69117","0.43133"
"19410","116.42400","9.70223","0.43199"
"19432","116.55600","9.71323","0.43280"
"19454","116.68800","9.72423","0.43334"
"19476","116.82000","9.73517","0.43409"
"19498","116.95200","9.74623","0.43440"
"19520","117.08400","9.75723","0.43517"
"19542","117.21600","9.76823","0.43547"
"19564","117.34800","9.77918","0.43596"
"19586","117.48000","9.79018","0.43642"
"19608","117.61200","9.80118","0.43687"
"19630","117.74400","9.81218","0.43701"
"19652","117.87600","9.82318","0.43774"
"19674","118.00800","9.83418","0.43802"
"19696","118.14000","9.84524","0.43911"
"19718","118.27200","9.85618","0.43961"
"19740","118.40400","9.86719","0.44000"
"19762","118.53600","9.87825","0.44074"
"19784","118.66800","9.88925","0.44156"
"19806","118.80000","9.90025","0.44247"
"19828","118.93200","9.91119","0.44364"
"19850","119.06400","9.92219","0.44433"
"19872","119.19600","9.93319","0.44562"
"19894","119.32800","9.94419","0.44688"
"19916","119.46000","9.95520","0.44758"
"19938","119.59200","9.96620","0.44864"
"19960","119.72400","9.97726","0.44957"
"19982","119.85600","9.98826","0.45068"
"20004","119.98800","9.99914","0.45191"
"20026","120.12000","10.01020","0.23080"
"20048","120.25200","10.02126","0.21191"
"20070","120.38400","10.03226","0.20636"
"20092","120.51600","10.04315","0.21005"
"20114","120.64800","10.05415","0.19674"
"20136","120.78000","10.06527","0.21610"
"20158","120.91200","10.07621","0.22423"
"20180","121.04400","10.08721","0.20594"
"20202","121.17600","10.09815","0.21015"
"20224","121.30800","10.10921","0.23672"
"20246","121.44000","10.12022","0.20068"
"20268","121.57200","10.13122","0.21898"
"20290","121.70400","10.14216","0.23873"
"20312","121.83600","10.15322","0.21577"
"20334","121.96800","10.16422","0.23181"
"20356","122.10000","10.17522","0.23976"
"20378","122.23200","10.18616","0.22472"
"20400","122.36400","10.19716","0.24011"
"20422","122.49600","10.20823","0.23958"
"20444","122.62800","10.21923","0.23383"
"20466","122.76000","10.23017","0.24484"
"20488","122.89200","10.24123","0.24020"
"20510","123.02400","10.25223","0.23933"
"20532","123.15600","10.26323","0.25494"
"20554","123.28800","10.27423","0.24179"
"20576","123.42000","10.28523","0.24124"
"20598","123.55200","10.29624","0.27494"
"20620","123.68400","10.30724","0.24208"
"20642","123.81600","10.31818","0.24425"
"20664","123.94800","10.32918","0.28531"
"20686","124.08000","10.34018","0.24539"
"20708","124.21200","10.35118","0.25302"
"20730","124.34400","10.36212","0.28268"
"20752","124.47600","10.37318","0.25345"
"20774","124.60800","10.38425","0.27635"
"20796","124.74000","10.39525","0.27485"
"20818","124.87200","10.40619","0.26531"
"20840","125.00400","10.41719","0.29310"
"20862","125.13600","10.42825","0.27347"
"20884","125.26800","10.43919","0.27455"
"20906","125.40000","10.45019","0.31323"
"20928","125.53200","10.46119","0.27893"
"20950","125.66400","10.47220","0.28786"
"20972","125.79600","10.48320","0.30771"
"20994","125.92800","10.49420","0.28757"
"21016","126.06000","10.50520","0.31592"
"21038","126.19200","10.51620","0.29367"
"21060","126.32400","10.52720","0.29246"
"21082","126.45600","10.53814","0.34120"
"21104","126.58800","10.54915","0.29696"
"21126","126.72000","10.56027","0.31270"
"21148","126.85200","10.57121","0.33841"
"21170","126.98400","10.58221","0.31198"
"21192","127.11600","10.59321","0.34490"
"21214","127.24800","10.60421","0.32832"
"21236","127.38000","10.61521","0.32984"
"21258","127.51200","10.62615","0.34986"
"21280","127.64400","10.63716","0.33488"
"21302","127.77600","10.64822","0.34634"
"21324","127.90800","10.65928","0.34738"
"21346","128.04000","10.67022","0.34325"
"21368","128.17200","10.68122","0.35330"
"21390","128.30400","10.69228","0.34656"
"21412","128.43600","10.70322","0.34902"
"21434","128.56800","10.71416","0.35354"
"21456","128.70000","10.72517","0.34894"
"21478","128.83200","10.73623","0.35786"
"21500","128.96400","10.74723","0.35038"
"21522","129.09600","10.75817","0.35244"
"21544","129.22800","10.76911","0.36148"
"21566","129.36000","10.78023","0.35271"
"21588","129.49200","10.79129","0.36389"
"21610","129.62400","10.80223","0.35601"
"21632","129.75600","10.81318","0.35737"
"21654","129.88800","10.82424","0.37351"
"21676","130.02000","10.83524","0.35823"
"21698","130.15200","10.84618","0.37538"
"21720","130.28400","10.85718","0.36430"
"21742","130.41600","10.86818","0.36558"
"21764","130.54800","10.87924","0.38841"
"21786","130.68000","10.89019","0.36727"
"21808","130.81200","10.90113","0.39137"
"21830","130.94400","10.91219","0.37617"
"21852","131.07600","10.92319","0.38047"
"21874","131.20800","10.93419","0.39628"
"21896","131.34000","10.94519","0.38355"
"21918","131.47200","10.95619","0.39908"
"21940","131.60400","10.96725","0.39103"
"21962","131.73600","10.97825","0.39554"
"21984","131.86800","10.98920","0.40049"
"22006","132.00000","11.00020","0.39530"
"22028","132.13200","11.01120","0.40953"
"22050","132.26400","11.02220","0.39771"
"22072","132.39600","11.03314","0.40466"
"22094","132.52800","11.04420","0.40632"
"22116","132.66000","11.05514","0.40185"
"22138","132.79200","11.06621","0.42117"
"22160","132.92400","11.07715","0.40526"
"22182","133.05600","11.08821","0.42037"
"22204","133.18800","11.09927","0.41419"
"22226","133.32000","11.11027","0.41610"
"22248","133.45200","11.12121","0.42782"
"22270","133.58400","11.13215","0.41718"
"22292","133.71600","11.14322","0.43219"
"22314","133.84800","11.15422","0.42200"
"22336","133.98000","11.16522","0.42899"
"22358","134.11200","11.17622","0.43118"
"22380","134.24400","11.18722","0.42817"
"22402","134.37600","11.19822","0.43648"
"22424","134.50800","11.20916","0.43013"
"22446","134.64000","11.22016","0.43669"
"22468","134.77200","11.23123","0.43393"
"22490","134.90400","11.24223","0.43561"
"22512","135.03600","11.25323","0.43784"
"22534","135.16800","11.26423","0.43565"
"22556","135.30000","11.27523","0.44212"
"22578","135.43200","11.28617","0.43644"
"22600","135.56400","11.29711","0.44170"
"22622","135.69600","11.30811","0.43912"
"22644","135.82800","11.31917","0.44035"
"22666","135.96000","11.33024","0.44600"
"22688","136.09200","11.34118","0.44046"
"22710","136.22400","11.35218","0.45145"
"22732","136.35600","11.36324","0.44232"
"22754","136.48800","11.37424","0.45109"
"22776","136.62000","11.38524","0.44753"
"22798","136.75200","11.39618","0.44933"
"22820","136.88400","11.40724","0.45485"
"22842","137.01600","11.41819","0.44980"
"22864","137.14800","11.42919","0.46174"
"22886","137.28000","11.44013","0.45227"
"22908","137.41200","11.45119","0.46185"
"22930","137.54400","11.46225","0.45671"
"22952","137.67600","11.47325","0.46061"
"22974","137.80800","11.48419","0.46459"
"22996","137.94000","11.49519","0.46000"
"23018","138.07200","11.50620","0.47300"
"23040","138.20400","11.51720","0.46212"
"23062","138.33600","11.52814","0.47576"
"23084","138.46800","11.53926","0.46429"
"23106","138.60000","11.55026","0.47443"
"23128","138.73200","11.56120","0.47658"
"23150","138.86400","11.57214","0.47511"
"23172","138.99600","11.58315","0.48308"
"23194","139.12800","11.59421","0.47745"
"23216","139.26000","11.60521","0.48765"
"23238","139.39200","11.61615","0.48056"
"23260","139.52400","11.62715","0.48852"
"23282","139.65600","11.63821","0.48452"
"23304","139.78800","11.64927","0.48790"
"23326","139.92000","11.66021","0.49028"
"23348","140.05200","11.67122","0.48715"
"23370","140.18400","11.68222","0.49555"
"23392","140.31600","11.69322","0.49022"
"23414","140.44800","11.70416","0.49708"
"23436","140.58000","11.71516","0.49294"
"23458","140.71200","11.72616","0.49767"
"23480","140.84400","11.73722","0.49611"
"23502","140.97600","11.74816","0.49719"
"23524","141.10800","11.75917","0.49857"
"23546","141.24000","11.77017","0.49742"
"23568","141.37200","11.78123","0.49990"
"23590","141.50400","11.79211","0.49810"
"23612","141.63600","11.80317","0.50241"
"23634","141.76800","11.81423","0.49907"
"23656","141.90000","11.82523","0.50262"
"23678","142.03200","11.83623","0.50092"
"23700","142.16400","11.84718","0.50304"
"23722","142.29600","11.85824","0.50542"
"23744","142.42800","11.86924","0.50354"
"23766","142.56000","11.88018","0.51215"
"23788","142.69200","11.89118","0.50515"
"23810","142.82400","11.90218","0.51838"
"23832","142.95600","11.91324","0.50981"
"23854","143.08800","11.92418","0.52110"
"23876","143.22000","11.93519","0.51514"
"23898","143.35200","11.94625","0.52167"
"23920","143.48400","11.95719","0.52231"
"23942","143.61600","11.96819","0.52272"
"23964","143.74800","11.97913","0.52800"
"23986","143.88000","11.99019","0.52431"
"24008","144.01200","12.00119","0.53263"
"24030","144.14400","12.01219","0.52717"
"24052","144.27600","12.02320","0.53563"
"24074","144.40800","12.03420","0.53108"
"24096","144.54000","12.04520","0.53720"
"24118","144.67200","12.05626","0.53523"
"24140","144.80400","12.06720","0.53828"
"24162","144.93600","12.07826","0.53913"
"24184","145.06800","12.08926","0.53894"
"24206","145.20000","12.10020","0.54285"
"24228","145.33200","12.11115","0.54023"
"24250","145.46400","12.12221","0.54565"
"24272","145.59600","12.13321","0.54300"
"24294","145.72800","12.14421","0.54727"
"24316","145.86000","12.15515","0.54453"
"24338","145.99200","12.16621","0.54835"
"24360","146.12400","12.17721","0.54722"
"24382","146.25600","12.18822","0.54884"
"24404","146.38800","12.19916","0.54938"
"24426","146.52000","12.21022","0.55047"
"24448","146.65200","12.22128","0.55165"
"24470","146.78400","12.23222","0.55132"
"24492","146.91600","12.24316","0.55446"
"24514","147.04800","12.25416","0.55239"
"24536","147.18000","12.26523","0.55625"
"24558","147.31200","12.27623","0.55454"
"24580","147.44400","12.28717","0.55740"
"24602","147.57600","12.29817","0.55601"
"24624","147.70800","12.30923","0.55821"
"24646","147.84000","12.32023","0.55768"
"24668","147.97200","12.33111","0.55893"
"24690","148.10400","12.34223","0.55962"
"24712","148.23600","12.35324","0.55929"
"24734","148.36800","12.36424","0.56080"
"24756","148.50000","12.37518","0.56023"
"24778","148.63200","12.38612","0.56147"
"24800","148.76400","12.39724","0.56080"
"24822","148.89600","12.40824","0.56260"
"24844","149.02800","12.41918","0.56156"
"24866","149.16000","12.43018","0.56350"
"24888","149.29200","12.44125","0.56242"
"24910","149.42400","12.45225","0.56442"
"24932","149.55600","12.46319","0.56352"
"24954","149.68800","12.47419","0.56525"
"24976","149.82000","12.48519","0.56521"
"24998","149.95200","12.49625","0.56632"
"25020","150.08400","12.50719","0.56797"
"25042","150.21600","12.51814","0.56761"
"25064","150.34800","12.52925","0.57064"
"25086","150.48000","12.54020","0.57018"
"25108","150.61200","12.55120","0.57455"
"25130","150.74400","12.56220","0.57216"
"25152","150.87600","12.57320","0.57861"
"25174","151.00800","12.58420","0.57605"
"25196","151.14000","12.59526","0.58321"
"25218","151.27200","12.60620","0.57963"
"25240","151.40400","12.61721","0.58614"
"25262","151.53600","12.62827","0.58431"
"25284","151.66800","12.63921","0.58959"
"25306","151.80000","12.65015","0.58787"
"25328","151.93200","12.66121","0.59275"
"25350","152.06400","12.67215","0.59435"
"25372","152.19600","12.68321","0.59529"
"25394","152.32800","12.69415","0.59758"
"25416","152.46000","12.70522","0.59730"
"25438","152.59200","12.71622","0.59966"
"25460","152.72400","12.72722","0.59891"
"25482","152.85600","12.73822","0.60132"
"25504","152.98800","12.74922","0.60099"
"25526","153.12000","12.76022","0.60336"
"25548","153.25200","12.77122","0.60247"
"25570","153.38400","12.78216","0.60513"
"25592","153.51600","12.79317","0.60389"
"25614","153.64800","12.80417","0.60719"
"25636","153.78000","12.81523","0.60601"
"25658","153.91200","12.82611","0.60971"
"25680","154.04400","12.83717","0.60885"
"25702","154.17600","12.84823","0.61311"
"25724","154.30800","12.85917","0.61273"
"25746","154.44000","12.87017","0.61721"
"25768","154.57200","12.88118","0.61698"
"25790","154.70400","12.89224","0.62074"
"25812","154.83600","12.90324","0.62291"
"25834","154.96800","12.91418","0.62395"
"25856","155.10000","12.92518","0.62679"
"25878","155.23200","12.93624","0.62838"
"25900","155.36400","12.94724","0.63145"
"25922","155.49600","12.95819","0.63192"
"25944","155.62800","12.96913","0.63470"
"25966","155.76000","12.98025","0.63462"
"25988","155.89200","12.99125","0.63806"
"26010","156.02400","13.00219","0.63728"
"26032","156.15600","13.01319","0.64046"
"26054","156.28800","13.02425","0.63986"
"26076","156.42000","13.03525","0.64262"
"26098","156.55200","13.04620","0.64195"
"26120","156.68400","13.05714","0.64447"
"26142","156.81600","13.06820","0.64408"
"26164","156.94800","13.07926","0.64619"
"26186","157.08000","13.09020","0.64538"
"26208","157.21200","13.10114","0.64699"
"26230","157.34400","13.11220","0.64678"
"26252","157.47600","13.12321","0.64815"
"26274","157.60800","13.13421","0.64774"
"26296","157.74000","13.14521","0.64892"
"26318","157.87200","13.15627","0.64848"
"26340","158.00400","13.16727","0.64942"
"26362","158.13600","13.17821","0.64925"
"26384","158.26800","13.18915","0.64978"
"26406","158.40000","13.20021","0.64972"
"26428","158.53200","13.21122","0.65039"
"26450","158.66400","13.22216","0.65050"
"26472","158.79600","13.23316","0.65113"
"26494","158.92800","13.24422","0.65108"
"26516","159.06000","13.25522","0.65188"
"26538","159.19200","13.26616","0.65219"
"26560","159.32400","13.27716","0.65268"
"26582","159.45600","13.28822","0.65280"
"26604","159.58800","13.29929","0.65395"
"26626","159.72000","13.31023","0.65427"
"26648","159.85200","13.32117","0.65513"
"26670","159.98400","13.33217","0.65590"
"26692","160.11600","13.34317","0.65668"
"26714","160.24800","13.35417","0.65718"
"26736","160.38000","13.36517","0.65824"
"26758","160.51200","13.37617","0.65892"
"26780","160.64400","13.38724","0.65946"
"26802","160.77600","13.39824","0.66045"
"26824","160.90800","13.40918","0.66116"
"26846","161.04000","13.42018","0.66241"
"26868","161.17200","13.43124","0.66292"
"26890","161.30400","13.44218","0.66457"
"26912","161.43600","13.45324","0.66503"
"26934","161.56800","13.46424","0.66703"
"26956","161.70000","13.47525","0.66844"
"26978","161.83200","13.48625","0.67042"
"27000","161.96400","13.49719","0.67130"
"27022","162.09600","13.50819","0.67332"
"27044","162.22800","13.51925","0.67451"
"27066","162.36000","13.53025","0.67593"
"27088","162.49200","13.54119","0.67749"
"27110","162.62400","13.55220","0.67955"
"27132","162.75600","13.56326","0.68106"
"27154","162.88800","13.57426","0.68267"
"27176","163.02000","13.58520","0.68375"
"27198","163.15200","13.59620","0.68479"
"27220","163.28400","13.60726","0.68629"
"27242","163.41600","13.61826","0.68875"
"27264","163.54800","13.62914","0.68981"
"27286","163.68000","13.64015","0.69204"
"27308","163.81200","13.65127","0.69322"
"27330","163.94400","13.66221","0.69661"
"27352","164.07600","13.67321","0.69783"
"27374","164.20800","13.68415","0.69983"
"27396","164.34000","13.69527","0.70180"
"27418","164.47200","13.70627","0.70303"
"27440","164.60400","13.71721","0.70465"
"27462","164.73600","13.72816","0.70591"
"27484","164.86800","13.73922","0.70652"
"27506","165.00000","13.75022","0.70764"
"27528","165.13200","13.76116","0.70766"
"27550","165.26400","13.77216","0.70856"
"27572","165.39600","13.78316","0.70872"
"27594","165.52800","13.79422","0.70894"
"27616","165.66000","13.80522","0.70950"
"27619","165.67400","13.80636","0.70951"