File: Trajectories_together/170108_2Specimen_RawData_2.csv
"","V1","V2","V3"
"1","End date","1/8/2017",""
"2","Specimen label","11DG_unk1",""
"3","Maximum Load","0.74045","N"
"4","Time","Extension","Load"
"5","(s)","(mm)","(N)"
"6","0.00000","0.00000","0.00059"
"72","0.39600","0.03318","0.00163"
"138","0.79200","0.06625","0.00186"
"204","1.18800","0.09925","0.00279"
"270","1.58400","0.13213","0.00335"
"336","1.98000","0.16526","0.00415"
"402","2.37600","0.19826","0.00445"
"468","2.77200","0.23127","0.00417"
"534","3.16800","0.26415","0.00460"
"600","3.56400","0.29721","0.00496"
"666","3.96000","0.33022","0.00491"
"732","4.35600","0.36322","0.00488"
"798","4.75200","0.39617","0.00541"
"864","5.14800","0.42923","0.00555"
"930","5.54400","0.46223","0.00603"
"996","5.94000","0.49518","0.00615"
"1062","6.33600","0.52818","0.00603"
"1128","6.73200","0.56118","0.00634"
"1194","7.12800","0.59425","0.00612"
"1260","7.52400","0.62713","0.00600"
"1326","7.92000","0.66020","0.00632"
"1392","8.31600","0.69320","0.00581"
"1458","8.71200","0.72620","0.00629"
"1524","9.10800","0.75921","0.00642"
"1590","9.50400","0.79221","0.00655"
"1656","9.90000","0.82522","0.00693"
"1722","10.29600","0.85816","0.00736"
"1788","10.69200","0.89116","0.00650"
"1854","11.08800","0.92417","0.00710"
"1920","11.48400","0.95723","0.00728"
"1986","11.88000","0.99023","0.00689"
"2052","12.27600","1.02324","0.00734"
"2118","12.67200","1.05624","0.00705"
"2184","13.06800","1.08919","0.00718"
"2250","13.46400","1.12219","0.00746"
"2316","13.86000","1.15519","0.00723"
"2382","14.25600","1.18820","0.00794"
"2448","14.65200","1.22126","0.00775"
"2514","15.04800","1.25420","0.00760"
"2580","15.44400","1.28721","0.00792"
"2646","15.84000","1.32027","0.00795"
"2712","16.23600","1.35322","0.00812"
"2778","16.63200","1.38616","0.00785"
"2844","17.02800","1.41922","0.00818"
"2910","17.42400","1.45223","0.00752"
"2976","17.82000","1.48517","0.00784"
"3042","18.21600","1.51818","0.00830"
"3108","18.61200","1.55118","0.00783"
"3174","19.00800","1.58418","0.00876"
"3240","19.40400","1.61719","0.00807"
"3306","19.80000","1.65019","0.00837"
"3372","20.19600","1.68319","0.00854"
"3438","20.59200","1.71626","0.00834"
"3504","20.98800","1.74920","0.00876"
"3570","21.38400","1.78215","0.00893"
"3636","21.78000","1.81521","0.00851"
"3702","22.17600","1.84827","0.00880"
"3768","22.57200","1.88116","0.00915"
"3834","22.96800","1.91422","0.00873"
"3900","23.36400","1.94723","0.00883"
"3966","23.76000","1.98023","0.00890"
"4032","24.15600","2.01317","0.00934"
"4098","24.55200","2.04618","0.00926"
"4164","24.94800","2.07918","0.00942"
"4230","25.34400","2.11224","0.00943"
"4296","25.74000","2.14519","0.00925"
"4362","26.13600","2.17819","0.00955"
"4428","26.53200","2.21120","0.00942"
"4494","26.92800","2.24420","0.00937"
"4560","27.32400","2.27726","0.00972"
"4626","27.72000","2.31021","0.00945"
"4692","28.11600","2.34321","0.00979"
"4758","28.51200","2.37622","0.00988"
"4824","28.90800","2.40916","0.00940"
"4890","29.30400","2.44222","0.00984"
"4956","29.70000","2.47523","0.01005"
"5022","30.09600","2.50817","0.01013"
"5088","30.49200","2.54123","0.01035"
"5154","30.88800","2.57424","0.01027"
"5220","31.28400","2.60724","0.01020"
"5286","31.68000","2.64019","0.01046"
"5352","32.07600","2.67325","0.01069"
"5418","32.47200","2.70625","0.01014"
"5484","32.86800","2.73920","0.01058"
"5550","33.26400","2.77214","0.01086"
"5616","33.66000","2.80526","0.01043"
"5682","34.05600","2.83821","0.01069"
"5748","34.45200","2.87115","0.01128"
"5814","34.84800","2.90416","0.01085"
"5880","35.24400","2.93728","0.01120"
"5946","35.64000","2.97022","0.01138"
"6012","36.03600","3.00317","0.01055"
"6078","36.43200","3.03617","0.01156"
"6144","36.82800","3.06924","0.01120"
"6210","37.22400","3.10224","0.01092"
"6276","37.62000","3.13512","0.01163"
"6342","38.01600","3.16819","0.01170"
"6408","38.41200","3.20125","0.01153"
"6474","38.80800","3.23426","0.01162"
"6540","39.20400","3.26714","0.01177"
"6606","39.60000","3.30020","0.01223"
"6672","39.99600","3.33321","0.01188"
"6738","40.39200","3.36621","0.01215"
"6804","40.78800","3.39915","0.01282"
"6870","41.18400","3.43222","0.01207"
"6936","41.58000","3.46522","0.01249"
"7002","41.97600","3.49817","0.01181"
"7068","42.37200","3.53117","0.01252"
"7134","42.76800","3.56423","0.01249"
"7200","43.16400","3.59724","0.01285"
"7266","43.56000","3.63018","0.01252"
"7332","43.95600","3.66319","0.01310"
"7398","44.35200","3.69619","0.01263"
"7464","44.74800","3.72925","0.01280"
"7530","45.14400","3.76226","0.01305"
"7596","45.54000","3.79520","0.01347"
"7662","45.93600","3.82820","0.01322"
"7728","46.33200","3.86121","0.01338"
"7794","46.72800","3.89421","0.01346"
"7860","47.12400","3.92722","0.01355"
"7926","47.52000","3.96022","0.01326"
"7992","47.91600","3.99322","0.01359"
"8058","48.31200","4.02617","0.01354"
"8124","48.70800","4.05923","0.01312"
"8190","49.10400","4.09223","0.01329"
"8256","49.50000","4.12512","0.01370"
"8322","49.89600","4.15818","0.01350"
"8388","50.29200","4.19125","0.01378"
"8454","50.68800","4.22419","0.01374"
"8520","51.08400","4.25719","0.01437"
"8586","51.48000","4.29020","0.01452"
"8652","51.87600","4.32326","0.01418"
"8718","52.27200","4.35621","0.01492"
"8784","52.66800","4.38915","0.01430"
"8850","53.06400","4.42221","0.01394"
"8916","53.46000","4.45528","0.01305"
"8982","53.85600","4.48822","0.01319"
"9048","54.25200","4.52116","0.01252"
"9114","54.64800","4.55423","0.01288"
"9180","55.04400","4.58723","0.01194"
"9246","55.44000","4.62024","0.01300"
"9312","55.83600","4.65318","0.01337"
"9378","56.23200","4.68624","0.01305"
"9444","56.62800","4.71931","0.01291"
"9510","57.02400","4.75219","0.01323"
"9576","57.42000","4.78520","0.01296"
"9642","57.81600","4.81820","0.01368"
"9708","58.21200","4.85126","0.01305"
"9774","58.60800","4.88415","0.01333"
"9840","59.00400","4.91721","0.01357"
"9906","59.40000","4.95021","0.01356"
"9972","59.79600","4.98322","0.01288"
"10038","60.19200","5.01616","0.01315"
"10104","60.58800","5.04923","0.01328"
"10170","60.98400","5.08217","0.01342"
"10236","61.38000","5.11517","0.01390"
"10302","61.77600","5.14824","0.01385"
"10368","62.17200","5.18118","0.01394"
"10434","62.56800","5.21424","0.01393"
"10500","62.96400","5.24719","0.01422"
"10566","63.36000","5.28019","0.01426"
"10632","63.75600","5.31326","0.01368"
"10698","64.15200","5.34626","0.01433"
"10764","64.54800","5.37915","0.01369"
"10830","64.94400","5.41221","0.01447"
"10896","65.34000","5.44521","0.01406"
"10962","65.73600","5.47822","0.01319"
"11028","66.13200","5.51116","0.01323"
"11094","66.52800","5.54422","0.01351"
"11160","66.92400","5.57729","0.01307"
"11226","67.32000","5.61017","0.01388"
"11292","67.71600","5.64312","0.01423"
"11358","68.11200","5.67624","0.01426"
"11424","68.50800","5.70924","0.01383"
"11490","68.90400","5.74219","0.01389"
"11556","69.30000","5.77519","0.01439"
"11622","69.69600","5.80825","0.01457"
"11688","70.09200","5.84126","0.01470"
"11754","70.48800","5.87420","0.01520"
"11820","70.88400","5.90721","0.01477"
"11886","71.28000","5.94027","0.01495"
"11952","71.67600","5.97321","0.01554"
"12018","72.07200","6.00616","0.01556"
"12084","72.46800","6.03916","0.01543"
"12150","72.86400","6.07223","0.01535"
"12216","73.26000","6.10523","0.01604"
"12282","73.65600","6.13817","0.01556"
"12348","74.05200","6.17118","0.01625"
"12414","74.44800","6.20424","0.01610"
"12480","74.84400","6.23724","0.01608"
"12546","75.24000","6.27019","0.01568"
"12612","75.63600","6.30319","0.01683"
"12678","76.03200","6.33620","0.01722"
"12744","76.42800","6.36920","0.01671"
"12810","76.82400","6.40220","0.01699"
"12876","77.22000","6.43521","0.01748"
"12942","77.61600","6.46821","0.01745"
"13008","78.01200","6.50121","0.01782"
"13074","78.40800","6.53422","0.01849"
"13140","78.80400","6.56716","0.01760"
"13206","79.20000","6.60023","0.01795"
"13272","79.59600","6.63317","0.01813"
"13338","79.99200","6.66623","0.01799"
"13404","80.38800","6.69918","0.01828"
"13470","80.78400","6.73218","0.01869"
"13536","81.18000","6.76519","0.01852"
"13602","81.57600","6.79831","0.01842"
"13668","81.97200","6.83119","0.01901"
"13734","82.36800","6.86420","0.01971"
"13800","82.76400","6.89720","0.01926"
"13866","83.16000","6.93026","0.01979"
"13932","83.55600","6.96321","0.01984"
"13998","83.95200","6.99615","0.01987"
"14064","84.34800","7.02922","0.02026"
"14130","84.74400","7.06222","0.01983"
"14196","85.14000","7.09522","0.02057"
"14262","85.53600","7.12811","0.02032"
"14328","85.93200","7.16117","0.02037"
"14394","86.32800","7.19429","0.02038"
"14460","86.72400","7.22724","0.02058"
"14526","87.12000","7.26012","0.02060"
"14592","87.51600","7.29325","0.02105"
"14658","87.91200","7.32625","0.02053"
"14724","88.30800","7.35919","0.02070"
"14790","88.70400","7.39220","0.02131"
"14856","89.10000","7.42520","0.02160"
"14922","89.49600","7.45827","0.02201"
"14988","89.89200","7.49121","0.02256"
"15054","90.28800","7.52415","0.02293"
"15120","90.68400","7.55722","0.02257"
"15186","91.08000","7.59022","0.02230"
"15252","91.47600","7.62317","0.02210"
"15318","91.87200","7.65617","0.02275"
"15384","92.26800","7.68923","0.02276"
"15450","92.66400","7.72224","0.02201"
"15516","93.06000","7.75524","0.02278"
"15582","93.45600","7.78819","0.02302"
"15648","93.85200","7.82119","0.02344"
"15714","94.24800","7.85419","0.02305"
"15780","94.64400","7.88720","0.02354"
"15846","95.04000","7.92020","0.02468"
"15912","95.43600","7.95320","0.02460"
"15978","95.83200","7.98621","0.02391"
"16044","96.22800","8.01921","0.02372"
"16110","96.62400","8.05221","0.02446"
"16176","97.02000","8.08516","0.02432"
"16242","97.41600","8.11816","0.02505"
"16308","97.81200","8.15117","0.02478"
"16374","98.20800","8.18423","0.02503"
"16440","98.60400","8.21723","0.02515"
"16506","99.00000","8.25018","0.02537"
"16572","99.39600","8.28318","0.02526"
"16638","99.79200","8.31619","0.02559"
"16704","100.18800","8.34925","0.02608"
"16770","100.58400","8.38219","0.02591"
"16836","100.98000","8.41526","0.02622"
"16902","101.37600","8.44826","0.02654"
"16968","101.77200","8.48114","0.02610"
"17034","102.16800","8.51415","0.02673"
"17100","102.56400","8.54721","0.02645"
"17166","102.96000","8.58022","0.02643"
"17232","103.35600","8.61316","0.02703"
"17298","103.75200","8.64622","0.02722"
"17364","104.14800","8.67923","0.02723"
"17430","104.54400","8.71223","0.02751"
"17496","104.94000","8.74518","0.02751"
"17562","105.33600","8.77818","0.02777"
"17628","105.73200","8.81124","0.02719"
"17694","106.12800","8.84425","0.02768"
"17760","106.52400","8.87719","0.02751"
"17826","106.92000","8.91020","0.02783"
"17892","107.31600","8.94320","0.02813"
"17958","107.71200","8.97626","0.02806"
"18024","108.10800","9.00915","0.02843"
"18090","108.50400","9.04221","0.02828"
"18156","108.90000","9.07521","0.02836"
"18222","109.29600","9.10822","0.02830"
"18288","109.69200","9.14122","0.02871"
"18354","110.08800","9.17417","0.02868"
"18420","110.48400","9.20717","0.02858"
"18486","110.88000","9.24017","0.02902"
"18552","111.27600","9.27318","0.02898"
"18618","111.67200","9.30624","0.02908"
"18684","112.06800","9.33924","0.02923"
"18750","112.46400","9.37219","0.02946"
"18816","112.86000","9.40519","0.02932"
"18882","113.25600","9.43826","0.02934"
"18948","113.65200","9.47120","0.02913"
"19014","114.04800","9.50420","0.02958"
"19080","114.44400","9.53721","0.02947"
"19146","114.84000","9.57021","0.02959"
"19212","115.23600","9.60322","0.02963"
"19278","115.63200","9.63616","0.02963"
"19344","116.02800","9.66916","0.03026"
"19410","116.42400","9.70223","0.02986"
"19476","116.82000","9.73523","0.03022"
"19542","117.21600","9.76812","0.03027"
"19608","117.61200","9.80124","0.03064"
"19674","118.00800","9.83424","0.03054"
"19740","118.40400","9.86719","0.03038"
"19806","118.80000","9.90019","0.03078"
"19872","119.19600","9.93319","0.03115"
"19938","119.59200","9.96626","0.03128"
"20004","119.98800","9.99920","0.03139"
"20070","120.38400","10.03221","0.03155"
"20136","120.78000","10.06527","0.03178"
"20202","121.17600","10.09821","0.03186"
"20268","121.57200","10.13110","0.03173"
"20334","121.96800","10.16416","0.03240"
"20400","122.36400","10.19722","0.03228"
"20466","122.76000","10.23023","0.03258"
"20532","123.15600","10.26317","0.03272"
"20598","123.55200","10.29624","0.03296"
"20664","123.94800","10.32918","0.03340"
"20730","124.34400","10.36218","0.03408"
"20796","124.74000","10.39519","0.03380"
"20862","125.13600","10.42825","0.03409"
"20928","125.53200","10.46125","0.03388"
"20994","125.92800","10.49420","0.03485"
"21060","126.32400","10.52720","0.03529"
"21126","126.72000","10.56021","0.03520"
"21192","127.11600","10.59327","0.03531"
"21258","127.51200","10.62621","0.03463"
"21324","127.90800","10.65922","0.03556"
"21390","128.30400","10.69222","0.03616"
"21456","128.70000","10.72517","0.03653"
"21522","129.09600","10.75817","0.03652"
"21588","129.49200","10.79123","0.03700"
"21654","129.88800","10.82418","0.03755"
"21720","130.28400","10.85724","0.03833"
"21786","130.68000","10.89019","0.03857"
"21852","131.07600","10.92319","0.03899"
"21918","131.47200","10.95625","0.03935"
"21984","131.86800","10.98920","0.04031"
"22050","132.26400","11.02220","0.03971"
"22116","132.66000","11.05526","0.03994"
"22182","133.05600","11.08821","0.03970"
"22248","133.45200","11.12121","0.04002"
"22314","133.84800","11.15422","0.04100"
"22380","134.24400","11.18728","0.04126"
"22446","134.64000","11.22028","0.04203"
"22512","135.03600","11.25317","0.04238"
"22578","135.43200","11.28623","0.04356"
"22644","135.82800","11.31929","0.04455"
"22710","136.22400","11.35218","0.04462"
"22776","136.62000","11.38518","0.04550"
"22842","137.01600","11.41819","0.04593"
"22908","137.41200","11.45125","0.04682"
"22974","137.80800","11.48419","0.04780"
"23040","138.20400","11.51714","0.04805"
"23106","138.60000","11.55020","0.04870"
"23172","138.99600","11.58327","0.04931"
"23238","139.39200","11.61621","0.04979"
"23304","139.78800","11.64915","0.05018"
"23370","140.18400","11.68228","0.05117"
"23436","140.58000","11.71522","0.05165"
"23502","140.97600","11.74822","0.05064"
"23568","141.37200","11.78117","0.05069"
"23634","141.76800","11.81417","0.05158"
"23700","142.16400","11.84724","0.05244"
"23766","142.56000","11.88018","0.05317"
"23832","142.95600","11.91318","0.05330"
"23898","143.35200","11.94619","0.05390"
"23964","143.74800","11.97925","0.05380"
"24030","144.14400","12.01214","0.05502"
"24096","144.54000","12.04520","0.05534"
"24162","144.93600","12.07820","0.05647"
"24228","145.33200","12.11121","0.05684"
"24294","145.72800","12.14415","0.05757"
"24360","146.12400","12.17727","0.05777"
"24426","146.52000","12.21022","0.05875"
"24492","146.91600","12.24316","0.05964"
"24558","147.31200","12.27623","0.06038"
"24624","147.70800","12.30923","0.06074"
"24690","148.10400","12.34223","0.06103"
"24756","148.50000","12.37518","0.06098"
"24822","148.89600","12.40824","0.06225"
"24888","149.29200","12.44125","0.06275"
"24954","149.68800","12.47419","0.06211"
"25020","150.08400","12.50713","0.06283"
"25086","150.48000","12.54020","0.06357"
"25152","150.87600","12.57326","0.06458"
"25218","151.27200","12.60620","0.06522"
"25284","151.66800","12.63915","0.06588"
"25350","152.06400","12.67221","0.06685"
"25416","152.46000","12.70522","0.06693"
"25482","152.85600","12.73816","0.06725"
"25548","153.25200","12.77122","0.06809"
"25614","153.64800","12.80423","0.06814"
"25680","154.04400","12.83723","0.06863"
"25746","154.44000","12.87017","0.06930"
"25812","154.83600","12.90318","0.06993"
"25878","155.23200","12.93624","0.07040"
"25944","155.62800","12.96919","0.07052"
"26010","156.02400","13.00213","0.07085"
"26076","156.42000","13.03520","0.07177"
"26142","156.81600","13.06820","0.07176"
"26208","157.21200","13.10120","0.07220"
"26274","157.60800","13.13421","0.07243"
"26340","158.00400","13.16715","0.07312"
"26406","158.40000","13.20021","0.07390"
"26472","158.79600","13.23322","0.07435"
"26538","159.19200","13.26616","0.07402"
"26604","159.58800","13.29923","0.07463"
"26670","159.98400","13.33223","0.07512"
"26736","160.38000","13.36523","0.07570"
"26802","160.77600","13.39818","0.07582"
"26868","161.17200","13.43118","0.07590"
"26934","161.56800","13.46424","0.07619"
"27000","161.96400","13.49719","0.07636"
"27066","162.36000","13.53019","0.07642"
"27132","162.75600","13.56326","0.07674"
"27198","163.15200","13.59626","0.07692"
"27264","163.54800","13.62920","0.07742"
"27330","163.94400","13.66221","0.07743"
"27396","164.34000","13.69521","0.07765"
"27462","164.73600","13.72822","0.07733"
"27528","165.13200","13.76116","0.07770"
"27594","165.52800","13.79422","0.07776"
"27660","165.92400","13.82729","0.07836"
"27726","166.32000","13.86017","0.07864"
"27792","166.71600","13.89317","0.07892"
"27858","167.11200","13.92618","0.07917"
"27924","167.50800","13.95924","0.07865"
"27990","167.90400","13.99219","0.07944"
"28056","168.30000","14.02519","0.07976"
"28122","168.69600","14.05819","0.08042"
"28188","169.09200","14.09126","0.08046"
"28254","169.48800","14.12414","0.08084"
"28320","169.88400","14.15721","0.08029"
"28386","170.28000","14.19027","0.08126"
"28452","170.67600","14.22321","0.08206"
"28518","171.07200","14.25616","0.08277"
"28584","171.46800","14.28922","0.08350"
"28650","171.86400","14.32222","0.08430"
"28716","172.26000","14.35523","0.08395"
"28782","172.65600","14.38817","0.08507"
"28848","173.05200","14.42124","0.08634"
"28914","173.44800","14.45418","0.08756"
"28980","173.84400","14.48724","0.08858"
"29046","174.24000","14.52019","0.09083"
"29112","174.63600","14.55319","0.09337"
"29178","175.03200","14.58619","0.09444"
"29244","175.42800","14.61926","0.09723"
"29310","175.82400","14.65220","0.09865"
"29376","176.22000","14.68527","0.10017"
"29442","176.61600","14.71827","0.10232"
"29508","177.01200","14.75121","0.10459"
"29574","177.40800","14.78422","0.10661"
"29640","177.80400","14.81722","0.10799"
"29706","178.20000","14.85023","0.10853"
"29772","178.59600","14.88317","0.11087"
"29838","178.99200","14.91623","0.11273"
"29904","179.38800","14.94918","0.11331"
"29970","179.78400","14.98218","0.11546"
"30036","180.18000","15.01513","0.11715"
"30102","180.57600","15.04825","0.11943"
"30168","180.97200","15.08119","0.12296"
"30234","181.36800","15.11420","0.12504"
"30300","181.76400","15.14720","0.12676"
"30366","182.16000","15.18026","0.12788"
"30432","182.55600","15.21327","0.13105"
"30498","182.95200","15.24615","0.13228"
"30564","183.34800","15.27921","0.13358"
"30630","183.74400","15.31222","0.13492"
"30696","184.14000","15.34522","0.13584"
"30762","184.53600","15.37817","0.13634"
"30828","184.93200","15.41123","0.13692"
"30894","185.32800","15.44429","0.13713"
"30960","185.72400","15.47724","0.13752"
"31026","186.12000","15.51012","0.13800"
"31092","186.51600","15.54325","0.13846"
"31158","186.91200","15.57625","0.13902"
"31224","187.30800","15.60919","0.14006"
"31290","187.70400","15.64220","0.14170"
"31356","188.10000","15.67520","0.14272"
"31422","188.49600","15.70826","0.14404"
"31488","188.89200","15.74121","0.14620"
"31554","189.28800","15.77415","0.14814"
"31620","189.68400","15.80722","0.15093"
"31686","190.08000","15.84022","0.15357"
"31752","190.47600","15.87316","0.15451"
"31818","190.87200","15.90617","0.15549"
"31884","191.26800","15.93923","0.15692"
"31950","191.66400","15.97230","0.15824"
"32016","192.06000","16.00518","0.16136"
"32082","192.45600","16.03812","0.16202"
"32148","192.85200","16.07119","0.16162"
"32214","193.24800","16.10419","0.16371"
"32280","193.64400","16.13719","0.16553"
"32346","194.04000","16.17020","0.16688"
"32412","194.43600","16.20314","0.16846"
"32478","194.83200","16.23621","0.17026"
"32544","195.22800","16.26915","0.17133"
"32610","195.62400","16.30221","0.17287"
"32676","196.02000","16.33528","0.17395"
"32742","196.41600","16.36816","0.17517"
"32808","196.81200","16.40117","0.17656"
"32874","197.20800","16.43423","0.17801"
"32940","197.60400","16.46723","0.17946"
"33006","198.00000","16.50018","0.18084"
"33072","198.39600","16.53324","0.18196"
"33138","198.79200","16.56624","0.18254"
"33204","199.18800","16.59919","0.18381"
"33270","199.58400","16.63219","0.18491"
"33336","199.98000","16.66526","0.18613"
"33402","200.37600","16.69826","0.18692"
"33468","200.77200","16.73120","0.18802"
"33534","201.16800","16.76421","0.18871"
"33600","201.56400","16.79721","0.18956"
"33666","201.96000","16.83027","0.19078"
"33732","202.35600","16.86322","0.19176"
"33798","202.75200","16.89610","0.19379"
"33864","203.14800","16.92923","0.19524"
"33930","203.54400","16.96223","0.19754"
"33996","203.94000","16.99517","0.19995"
"34062","204.33600","17.02818","0.20261"
"34128","204.73200","17.06124","0.20474"
"34194","205.12800","17.09418","0.20747"
"34260","205.52400","17.12719","0.20966"
"34326","205.92000","17.16019","0.21090"
"34392","206.31600","17.19326","0.21250"
"34458","206.71200","17.22620","0.21489"
"34524","207.10800","17.25915","0.21731"
"34590","207.50400","17.29221","0.21952"
"34656","207.90000","17.32521","0.22154"
"34722","208.29600","17.35816","0.22423"
"34788","208.69200","17.39122","0.22572"
"34854","209.08800","17.42422","0.22722"
"34920","209.48400","17.45723","0.22879"
"34986","209.88000","17.49023","0.23006"
"35052","210.27600","17.52317","0.23190"
"35118","210.67200","17.55624","0.23362"
"35184","211.06800","17.58924","0.23695"
"35250","211.46400","17.62219","0.24011"
"35316","211.86000","17.65519","0.24354"
"35382","212.25600","17.68819","0.24731"
"35448","212.65200","17.72126","0.25180"
"35514","213.04800","17.75414","0.25468"
"35580","213.44400","17.78727","0.25817"
"35646","213.84000","17.82021","0.26175"
"35712","214.23600","17.85315","0.26353"
"35778","214.63200","17.88616","0.26704"
"35844","215.02800","17.91928","0.26969"
"35910","215.42400","17.95223","0.27179"
"35976","215.82000","17.98523","0.27576"
"36042","216.21600","18.01817","0.28109"
"36108","216.61200","18.05124","0.28409"
"36174","217.00800","18.08424","0.28714"
"36240","217.40400","18.11719","0.28831"
"36306","217.80000","18.15019","0.28952"
"36372","218.19600","18.18319","0.29008"
"36438","218.59200","18.21620","0.29062"
"36504","218.98800","18.24914","0.29077"
"36570","219.38400","18.28221","0.29112"
"36636","219.78000","18.31527","0.29129"
"36702","220.17600","18.34827","0.29187"
"36768","220.57200","18.38116","0.29337"
"36834","220.96800","18.41422","0.29371"
"36900","221.36400","18.44722","0.29476"
"36966","221.76000","18.48023","0.29718"
"37032","222.15600","18.51317","0.30066"
"37098","222.55200","18.54623","0.30414"
"37164","222.94800","18.57924","0.30517"
"37230","223.34400","18.61218","0.30902"
"37296","223.74000","18.64519","0.31272"
"37362","224.13600","18.67825","0.31588"
"37428","224.53200","18.71119","0.31917"
"37494","224.92800","18.74420","0.32347"
"37560","225.32400","18.77720","0.32870"
"37626","225.72000","18.81021","0.33303"
"37692","226.11600","18.84321","0.33645"
"37758","226.51200","18.87621","0.33882"
"37824","226.90800","18.90922","0.34095"
"37890","227.30400","18.94222","0.34216"
"37956","227.70000","18.97522","0.34219"
"38022","228.09600","19.00817","0.34403"
"38088","228.49200","19.04123","0.34709"
"38154","228.88800","19.07418","0.35140"
"38220","229.28400","19.10718","0.35488"
"38286","229.68000","19.14013","0.35814"
"38352","230.07600","19.17325","0.36036"
"38418","230.47200","19.20625","0.36330"
"38484","230.86800","19.23914","0.36556"
"38550","231.26400","19.27220","0.36777"
"38616","231.66000","19.30526","0.36984"
"38682","232.05600","19.33821","0.37138"
"38748","232.45200","19.37115","0.37314"
"38814","232.84800","19.40421","0.37540"
"38880","233.24400","19.43722","0.37742"
"38946","233.64000","19.47022","0.37975"
"39012","234.03600","19.50317","0.38163"
"39078","234.43200","19.53623","0.38397"
"39144","234.82800","19.56929","0.38632"
"39210","235.22400","19.60218","0.38879"
"39276","235.62000","19.63518","0.39057"
"39342","236.01600","19.66813","0.39303"
"39408","236.41200","19.70131","0.39537"
"39474","236.80800","19.73419","0.39851"
"39540","237.20400","19.76719","0.40168"
"39606","237.60000","19.80020","0.40628"
"39672","237.99600","19.83326","0.41009"
"39738","238.39200","19.86621","0.41447"
"39804","238.78800","19.89915","0.41905"
"39870","239.18400","19.93221","0.42266"
"39936","239.58000","19.96528","0.42599"
"40002","239.97600","19.99816","0.42958"
"40068","240.37200","20.03117","0.43352"
"40134","240.76800","20.06429","0.43677"
"40200","241.16400","20.09723","0.43799"
"40266","241.56000","20.13018","0.43892"
"40332","241.95600","20.16318","0.43965"
"40398","242.35200","20.19619","0.44073"
"40464","242.74800","20.22925","0.44557"
"40530","243.14400","20.26219","0.45234"
"40596","243.54000","20.29520","0.45962"
"40662","243.93600","20.32820","0.46538"
"40728","244.33200","20.36121","0.46309"
"40794","244.72800","20.39415","0.46772"
"40860","245.12400","20.42721","0.47002"
"40926","245.52000","20.46022","0.45225"
"40992","245.91600","20.49322","0.45647"
"41058","246.31200","20.52617","0.46110"
"41124","246.70800","20.55923","0.46424"
"41190","247.10400","20.59223","0.46977"
"41256","247.50000","20.62518","0.47428"
"41322","247.89600","20.65824","0.47938"
"41388","248.29200","20.69124","0.48400"
"41454","248.68800","20.72425","0.48762"
"41520","249.08400","20.75719","0.49074"
"41586","249.48000","20.79026","0.49397"
"41652","249.87600","20.82320","0.49682"
"41718","250.27200","20.85620","0.49966"
"41784","250.66800","20.88915","0.50127"
"41850","251.06400","20.92227","0.50215"
"41916","251.46000","20.95522","0.50377"
"41982","251.85600","20.98816","0.50522"
"42048","252.25200","21.02122","0.50851"
"42114","252.64800","21.05423","0.51197"
"42180","253.04400","21.08723","0.51644"
"42246","253.44000","21.12017","0.52042"
"42312","253.83600","21.15324","0.52565"
"42378","254.23200","21.18624","0.53080"
"42444","254.62800","21.21931","0.53585"
"42510","255.02400","21.25213","0.54049"
"42576","255.42000","21.28519","0.54309"
"42642","255.81600","21.31825","0.54661"
"42708","256.21200","21.35126","0.54958"
"42774","256.60800","21.38415","0.55420"
"42840","257.00400","21.41721","0.55894"
"42906","257.40000","21.45021","0.56429"
"42972","257.79600","21.48322","0.56832"
"43038","258.19200","21.51616","0.57253"
"43104","258.58800","21.54922","0.55953"
"43170","258.98400","21.58223","0.56053"
"43236","259.38000","21.61523","0.56374"
"43302","259.77600","21.64818","0.56850"
"43368","260.17200","21.68124","0.57323"
"43434","260.56800","21.71424","0.57828"
"43500","260.96400","21.74718","0.58262"
"43566","261.36000","21.78013","0.58617"
"43632","261.75600","21.81325","0.58886"
"43698","262.15200","21.84626","0.59043"
"43764","262.54800","21.87914","0.59104"
"43830","262.94400","21.91227","0.59216"
"43896","263.34000","21.94521","0.59367"
"43962","263.73600","21.97821","0.59625"
"44028","264.13200","22.01116","0.59872"
"44094","264.52800","22.04422","0.60048"
"44160","264.92400","22.07728","0.59353"
"44226","265.32000","22.11023","0.59729"
"44292","265.71600","22.14317","0.60293"
"44358","266.11200","22.17630","0.61041"
"44424","266.50800","22.20924","0.61797"
"44490","266.90400","22.24218","0.62556"
"44556","267.30000","22.27513","0.63216"
"44622","267.69600","22.30825","0.64074"
"44688","268.09200","22.34126","0.64671"
"44754","268.48800","22.37414","0.64931"
"44820","268.88400","22.40720","0.65046"
"44886","269.28000","22.44021","0.65177"
"44952","269.67600","22.47321","0.65309"
"45018","270.07200","22.50610","0.65881"
"45084","270.46800","22.53916","0.66560"
"45150","270.86400","22.57222","0.67158"
"45216","271.26000","22.60523","0.67673"
"45282","271.65600","22.63811","0.68154"
"45348","272.05200","22.67118","0.68581"
"45414","272.44800","22.70424","0.68958"
"45480","272.84400","22.73724","0.69372"
"45546","273.24000","22.77019","0.69661"
"45612","273.63600","22.80325","0.69941"
"45678","274.03200","22.83625","0.70201"
"45744","274.42800","22.86920","0.70389"
"45810","274.82400","22.90220","0.70529"
"45876","275.22000","22.93521","0.70918"
"45942","275.61600","22.96821","0.71539"
"46008","276.01200","23.00121","0.72153"
"46074","276.40800","23.03416","0.72702"
"46140","276.80400","23.06722","0.73306"
"46206","277.20000","23.10023","0.73901"
"46272","277.59600","23.13317","0.54369"
"46338","277.99200","23.16623","0.53816"
"46404","278.38800","23.19917","0.51049"
"46470","278.78400","23.23218","0.51380"
"46536","279.18000","23.26524","0.51288"
"46602","279.57600","23.29825","0.51898"
"46668","279.97200","23.33119","0.52102"
"46734","280.36800","23.36414","0.52990"
"46800","280.76400","23.39714","0.53264"
"46866","281.16000","23.43026","0.54019"
"46932","281.55600","23.46321","0.54217"
"46998","281.95200","23.49609","0.54541"
"47064","282.34800","23.52921","0.54681"
"47130","282.74400","23.56222","0.55127"
"47196","283.14000","23.59516","0.55295"
"47262","283.53600","23.62817","0.55985"
"47328","283.93200","23.66123","0.56247"
"47394","284.32800","23.69423","0.56972"
"47460","284.72400","23.72724","0.56983"
"47526","285.12000","23.76012","0.31906"
"47592","285.51600","23.79324","0.29163"
"47658","285.91200","23.82625","0.29680"
"47724","286.30800","23.85919","0.29479"
"47790","286.70400","23.89220","0.29455"
"47856","287.10000","23.92520","0.29900"
"47922","287.49600","23.95826","0.30521"
"47988","287.89200","23.99121","0.30663"
"48054","288.28800","24.02415","0.30798"
"48120","288.68400","24.05727","0.31236"
"48186","289.08000","24.09028","0.31790"
"48252","289.47600","24.12316","0.32885"
"48318","289.87200","24.15617","0.33165"
"48384","290.26800","24.18929","0.33686"
"48450","290.66400","24.22224","0.34024"
"48516","291.06000","24.25518","0.34280"
"48582","291.45600","24.28818","0.34327"
"48648","291.85200","24.32119","0.34569"
"48714","292.24800","24.35419","0.35169"
"48780","292.64400","24.38719","0.35931"
"48846","293.04000","24.42026","0.36296"
"48912","293.43600","24.45314","0.36553"
"48978","293.83200","24.48620","0.36980"
"49044","294.22800","24.51921","0.37300"
"49110","294.62400","24.55215","0.37524"
"49176","295.02000","24.58522","0.37795"
"49242","295.41600","24.61822","0.38203"
"49308","295.81200","24.65122","0.38426"
"49374","296.20800","24.68423","0.38743"
"49440","296.60400","24.71723","0.39082"
"49506","297.00000","24.75018","0.39312"
"49572","297.39600","24.78324","0.39577"
"49638","297.79200","24.81624","0.39983"
"49704","298.18800","24.84925","0.40437"
"49770","298.58400","24.88219","0.40697"
"49836","298.98000","24.91525","0.40627"
"49902","299.37600","24.94826","0.37212"
"49968","299.77200","24.98120","0.37183"
"50034","300.16800","25.01415","0.37231"
"50100","300.56400","25.04727","0.37436"
"50166","300.96000","25.08022","0.37299"
"50232","301.35600","25.11316","0.37421"
"50298","301.75200","25.14616","0.37652"
"50364","302.14800","25.17923","0.37758"
"50430","302.54400","25.21223","0.37968"
"50496","302.94000","25.24512","0.38102"
"50562","303.33600","25.27818","0.38282"
"50628","303.73200","25.31124","0.38428"
"50694","304.12800","25.34425","0.38656"
"50760","304.52400","25.37713","0.38847"
"50826","304.92000","25.41019","0.38972"
"50892","305.31600","25.44326","0.39138"
"50958","305.71200","25.47626","0.39320"
"51024","306.10800","25.50920","0.39479"
"51090","306.50400","25.54221","0.39671"
"51156","306.90000","25.57521","0.39881"
"51222","307.29600","25.60828","0.40112"
"51288","307.69200","25.64116","0.40412"
"51354","308.08800","25.67422","0.40562"
"51420","308.48400","25.70723","0.40743"
"51486","308.88000","25.74023","0.40983"
"51552","309.27600","25.77318","0.41309"
"51618","309.67200","25.80624","0.41645"
"51684","310.06800","25.83924","0.41944"
"51750","310.46400","25.87219","0.42203"
"51816","310.86000","25.90519","0.42477"
"51882","311.25600","25.93819","0.42889"
"51948","311.65200","25.97120","0.42907"
"52014","312.04800","26.00420","0.43225"
"52080","312.44400","26.03721","0.43496"
"52146","312.84000","26.07021","0.43663"
"52212","313.23600","26.10321","0.43818"
"52278","313.63200","26.13622","0.43878"
"52344","314.02800","26.16922","0.43917"
"52410","314.42400","26.20216","0.43979"
"52476","314.82000","26.23523","0.44041"
"52542","315.21600","26.26817","0.44254"
"52608","315.61200","26.30129","0.44494"
"52674","316.00800","26.33424","0.44975"
"52740","316.40400","26.36712","0.45424"
"52806","316.80000","26.40019","0.45847"
"52872","317.19600","26.43319","0.46333"
"52938","317.59200","26.46619","0.46686"
"53004","317.98800","26.49914","0.47037"
"53070","318.38400","26.53221","0.47425"
"53136","318.78000","26.56521","0.47819"
"53202","319.17600","26.59821","0.48025"
"53268","319.57200","26.63109","0.48382"
"53334","319.96800","26.66422","0.48672"
"53400","320.36400","26.69722","0.48933"
"53466","320.76000","26.73017","0.49108"
"53532","321.15600","26.76323","0.49364"
"53598","321.55200","26.79617","0.49543"
"53664","321.94800","26.82924","0.49707"
"53730","322.34400","26.86224","0.49899"
"53796","322.74000","26.89518","0.50042"
"53862","323.13600","26.92819","0.50142"
"53928","323.53200","26.96125","0.50233"
"53994","323.92800","26.99420","0.50323"
"54060","324.32400","27.02720","0.38537"
"54126","324.72000","27.06020","0.38157"
"54192","325.11600","27.09321","0.38283"
"54258","325.51200","27.12621","0.38210"
"54324","325.90800","27.15922","0.38313"
"54390","326.30400","27.19228","0.38548"
"54456","326.70000","27.22522","0.38619"
"54522","327.09600","27.25817","0.38753"
"54588","327.49200","27.29123","0.38996"
"54654","327.88800","27.32417","0.39141"
"54720","328.28400","27.35724","0.39267"
"54786","328.68000","27.39018","0.39489"
"54852","329.07600","27.42319","0.39681"
"54918","329.47200","27.45619","0.39871"
"54984","329.86800","27.48920","0.40126"
"55050","330.26400","27.52220","0.40445"
"55116","330.66000","27.55526","0.40647"
"55182","331.05600","27.58821","0.41004"
"55248","331.45200","27.62121","0.41362"
"55314","331.84800","27.65421","0.41728"
"55380","332.24400","27.68722","0.42074"
"55446","332.64000","27.72022","0.42431"
"55512","333.03600","27.75311","0.42676"
"55578","333.43200","27.78623","0.42996"
"55644","333.82800","27.81923","0.43267"
"55710","334.22400","27.85218","0.43522"
"55776","334.62000","27.88512","0.43678"
"55842","335.01600","27.91825","0.43817"
"55908","335.41200","27.95125","0.43859"
"55974","335.80800","27.98419","0.43905"
"56040","336.20400","28.01720","0.43921"
"56106","336.60000","28.05020","0.43979"
"56172","336.99600","28.08332","0.44079"
"56238","337.39200","28.11615","0.44308"
"56304","337.78800","28.14921","0.44546"
"56370","338.18400","28.18221","0.44870"
"56436","338.58000","28.21528","0.45277"
"56502","338.97600","28.24817","0.45736"
"56568","339.37200","28.28117","0.46026"
"56634","339.76800","28.31423","0.46387"
"56700","340.16400","28.34723","0.46771"
"56766","340.56000","28.38018","0.47096"
"56832","340.95600","28.41312","0.47442"
"56898","341.35200","28.44625","0.47709"
"56964","341.74800","28.47919","0.48024"
"57030","342.14400","28.51220","0.48338"
"57096","342.54000","28.54520","0.47076"
"57162","342.93600","28.57820","0.47309"
"57228","343.33200","28.61121","0.47533"
"57294","343.72800","28.64421","0.47795"
"57360","344.12400","28.67721","0.47973"
"57426","344.52000","28.71016","0.46669"
"57492","344.91600","28.74322","0.47129"
"57558","345.31200","28.77616","0.47578"
"57624","345.70800","28.80923","0.47929"
"57690","346.10400","28.84223","0.48345"
"57756","346.50000","28.87518","0.48672"
"57822","346.89600","28.90818","0.48917"
"57888","347.29200","28.94118","0.36044"
"57954","347.68800","28.97419","0.28988"
"58020","348.08400","29.00719","0.29007"
"58086","348.48000","29.04026","0.29077"
"58152","348.87600","29.07320","0.29076"
"58218","349.27200","29.10620","0.29083"
"58284","349.66800","29.13915","0.29083"
"58350","350.06400","29.17227","0.29090"
"58416","350.46000","29.20527","0.29102"
"58482","350.85600","29.23816","0.29109"
"58548","351.25200","29.27116","0.29126"
"58614","351.64800","29.30423","0.29161"
"58680","352.04400","29.33723","0.29230"
"58746","352.44000","29.37011","0.29315"
"58812","352.83600","29.40318","0.29358"
"58878","353.23200","29.43624","0.29531"
"58944","353.62800","29.46924","0.29684"
"59010","354.02400","29.50213","0.29874"
"59076","354.42000","29.53525","0.30058"
"59142","354.81600","29.56825","0.30361"
"59208","355.21200","29.60120","0.30639"
"59274","355.60800","29.63420","0.30851"
"59340","356.00400","29.66715","0.31152"
"59406","356.40000","29.70021","0.31399"
"59472","356.79600","29.73322","0.31625"
"59538","357.19200","29.76616","0.30985"
"59604","357.58800","29.79922","0.31393"
"59670","357.98400","29.83223","0.31696"
"59736","358.38000","29.86517","0.32128"
"59802","358.77600","29.89817","0.32609"
"59868","359.17200","29.93124","0.33033"
"59934","359.56800","29.96430","0.32911"
"60000","359.96400","29.99719","0.33323"
"60066","360.36000","30.03019","0.33580"
"60132","360.75600","30.06325","0.33869"
"60198","361.15200","30.09620","0.34023"
"60264","361.54800","30.12920","0.34228"
"60330","361.94400","30.16221","0.34394"
"60396","362.34000","30.19521","0.34669"
"60462","362.73600","30.22821","0.34916"
"60528","363.13200","30.26122","0.35285"
"60594","363.52800","30.29422","0.35635"
"60660","363.92400","30.32722","0.36029"
"60726","364.32000","30.36017","0.36246"
"60792","364.71600","30.39317","0.36451"
"60858","365.11200","30.42624","0.36645"
"60924","365.50800","30.45918","0.36697"
"60990","365.90400","30.49224","0.36853"
"61056","366.30000","30.52519","0.37043"
"61122","366.69600","30.55819","0.37325"
"61188","367.09200","30.59126","0.37523"
"61254","367.48800","30.62414","0.37700"
"61320","367.88400","30.65720","0.37933"
"61386","368.28000","30.69027","0.38147"
"61452","368.67600","30.72321","0.38395"
"61518","369.07200","30.75616","0.38622"
"61584","369.46800","30.78922","0.38890"
"61650","369.86400","30.82222","0.38982"
"61716","370.26000","30.85523","0.39226"
"61782","370.65600","30.88817","0.39386"
"61848","371.05200","30.92123","0.39602"
"61914","371.44800","30.95424","0.39664"
"61980","371.84400","30.98718","0.39273"
"62046","372.24000","31.02019","0.39465"
"62112","372.63600","31.05325","0.39658"
"62178","373.03200","31.08625","0.39896"
"62244","373.42800","31.11920","0.40211"
"62310","373.82400","31.15220","0.40457"
"62376","374.22000","31.18526","0.40665"
"62442","374.61600","31.21827","0.40900"
"62508","375.01200","31.25115","0.41152"
"62574","375.40800","31.28415","0.41329"
"62640","375.80400","31.31722","0.41526"
"62706","376.20000","31.35022","0.41940"
"62772","376.59600","31.38317","0.42229"
"62838","376.99200","31.41623","0.42504"
"62904","377.38800","31.44917","0.42756"
"62970","377.78400","31.48218","0.43208"
"63036","378.18000","31.51518","0.43469"
"63102","378.57600","31.54819","0.43648"
"63168","378.97200","31.58125","0.43775"
"63234","379.36800","31.61419","0.43870"
"63300","379.76400","31.64720","0.43903"
"63366","380.16000","31.68020","0.43907"
"63432","380.55600","31.71321","0.43938"
"63498","380.95200","31.74615","0.44054"
"63564","381.34800","31.77921","0.44176"
"63630","381.74400","31.81222","0.44408"
"63696","382.14000","31.84516","0.44772"
"63762","382.53600","31.87816","0.45140"
"63828","382.93200","31.91123","0.45548"
"63894","383.32800","31.94423","0.45895"
"63960","383.72400","31.97718","0.46219"
"64026","384.12000","32.01018","0.46628"
"64092","384.51600","32.04324","0.47024"
"64158","384.91200","32.07625","0.44705"
"64224","385.30800","32.10913","0.44851"
"64290","385.70400","32.14220","0.45156"
"64356","386.10000","32.17526","0.45569"
"64422","386.49600","32.20826","0.45867"
"64488","386.89200","32.24121","0.46203"
"64554","387.28800","32.27421","0.46596"
"64620","387.68400","32.30727","0.46903"
"64686","388.08000","32.34022","0.47123"
"64752","388.47600","32.37310","0.47530"
"64818","388.87200","32.40623","0.47851"
"64884","389.26800","32.43917","0.48240"
"64950","389.66400","32.47223","0.48387"
"65016","390.06000","32.50518","0.48577"
"65082","390.45600","32.53818","0.48870"
"65148","390.85200","32.57119","0.48972"
"65214","391.24800","32.60419","0.49149"
"65280","391.64400","32.63713","0.49384"
"65346","392.04000","32.67020","0.49581"
"65412","392.43600","32.70320","0.49772"
"65478","392.83200","32.73621","0.49862"
"65544","393.22800","32.76915","0.49941"
"65610","393.62400","32.80221","0.50054"
"65676","394.02000","32.83527","0.50114"
"65742","394.41600","32.86816","0.50197"
"65808","394.81200","32.90117","0.50226"
"65874","395.20800","32.93423","0.50304"
"65940","395.60400","32.96723","0.50334"
"66006","396.00000","33.00018","0.50402"
"66072","396.39600","33.03324","0.50472"
"66138","396.79200","33.06618","0.50609"
"66204","397.18800","33.09925","0.50664"
"66270","397.58400","33.13219","0.50815"
"66336","397.98000","33.16525","0.50933"
"66402","398.37600","33.19820","0.51157"
"66468","398.77200","33.23120","0.51300"
"66534","399.16800","33.26414","0.51310"
"66600","399.56400","33.29721","0.03859"
"66666","399.96000","33.33021","0.06500"
"66732","400.35600","33.36316","0.05350"
"66798","400.75200","33.39616","0.04107"
"66864","401.14800","33.42923","0.05674"
"66930","401.54400","33.46223","0.06765"
"66996","401.94000","33.49511","0.04857"
"67062","402.33600","33.52824","0.05198"
"67128","402.73200","33.56124","0.06354"
"67194","403.12800","33.59418","0.05590"
"67260","403.52400","33.62712","0.05857"
"67326","403.92000","33.66019","0.06046"
"67392","404.31600","33.69325","0.05945"
"67458","404.71200","33.72620","0.06249"
"67524","405.10800","33.75914","0.06125"
"67590","405.50400","33.79221","0.06560"
"67656","405.90000","33.82521","0.06555"
"67722","406.29600","33.85822","0.06282"
"67788","406.69200","33.89122","0.06870"
"67854","407.08800","33.92422","0.06800"
"67920","407.48400","33.95723","0.06571"
"67986","407.88000","33.99023","0.07065"
"68052","408.27600","34.02317","0.06859"
"68118","408.67200","34.05624","0.06936"
"68184","409.06800","34.08924","0.07264"
"68250","409.46400","34.12218","0.07077"
"68316","409.86000","34.15519","0.07176"
"68382","410.25600","34.18825","0.07455"
"68448","410.65200","34.22126","0.07393"
"68514","411.04800","34.25414","0.07361"
"68580","411.44400","34.28720","0.07523"
"68646","411.84000","34.32021","0.07547"
"68712","412.23600","34.35321","0.07532"
"68778","412.63200","34.38622","0.07616"
"68844","413.02800","34.41928","0.07649"
"68910","413.42400","34.45222","0.07649"
"68976","413.82000","34.48523","0.07677"
"69042","414.21600","34.51817","0.07724"
"69108","414.61200","34.55123","0.07735"
"69174","415.00800","34.58424","0.07736"
"69240","415.40400","34.61718","0.07803"
"69306","415.80000","34.65025","0.07862"
"69372","416.19600","34.68319","0.07875"
"69438","416.59200","34.71619","0.07910"
"69504","416.98800","34.74914","0.08002"
"69570","417.38400","34.78220","0.08061"
"69636","417.78000","34.81521","0.08142"
"69702","418.17600","34.84821","0.08189"
"69768","418.57200","34.88115","0.08331"
"69834","418.96800","34.91422","0.08493"
"69900","419.36400","34.94728","0.08533"
"69966","419.76000","34.98022","0.08658"
"70032","420.15600","35.01317","0.08796"
"70098","420.55200","35.04623","0.08974"
"70164","420.94800","35.07924","0.09119"
"70230","421.34400","35.11224","0.09218"
"70296","421.74000","35.14519","0.09358"
"70362","422.13600","35.17825","0.09557"
"70428","422.53200","35.21119","0.09708"
"70494","422.92800","35.24414","0.09840"
"70560","423.32400","35.27720","0.10023"
"70626","423.72000","35.31020","0.10113"
"70692","424.11600","35.34327","0.10393"
"70758","424.51200","35.37621","0.10450"
"70824","424.90800","35.40916","0.10637"
"70890","425.30400","35.44222","0.10733"
"70956","425.70000","35.47516","0.10901"
"71022","426.09600","35.50823","0.11047"
"71088","426.49200","35.54123","0.11191"
"71154","426.88800","35.57423","0.11410"
"71220","427.28400","35.60718","0.11540"
"71286","427.68000","35.64018","0.11660"
"71352","428.07600","35.67324","0.11751"
"71418","428.47200","35.70625","0.11930"
"71484","428.86800","35.73919","0.11965"
"71550","429.26400","35.77220","0.12123"
"71616","429.66000","35.80526","0.12228"
"71682","430.05600","35.83821","0.12424"
"71748","430.45200","35.87115","0.12556"
"71814","430.84800","35.90416","0.12760"
"71880","431.24400","35.93722","0.12860"
"71946","431.64000","35.97022","0.12946"
"72012","432.03600","36.00317","0.13154"
"72078","432.43200","36.03623","0.13206"
"72144","432.82800","36.06923","0.13373"
"72210","433.22400","36.10218","0.13412"
"72276","433.62000","36.13512","0.13413"
"72342","434.01600","36.16824","0.13550"
"72408","434.41200","36.20124","0.13584"
"72474","434.80800","36.23419","0.13588"
"72540","435.20400","36.26720","0.13602"
"72606","435.60000","36.30026","0.13640"
"72672","435.99600","36.33326","0.13671"
"72738","436.39200","36.36615","0.13687"
"72804","436.78800","36.39921","0.13697"
"72870","437.18400","36.43221","0.13756"
"72936","437.58000","36.46522","0.13753"
"73002","437.97600","36.49816","0.13786"
"73068","438.37200","36.53122","0.13805"
"73134","438.76800","36.56423","0.13818"
"73200","439.16400","36.59723","0.13856"
"73266","439.56000","36.63012","0.13848"
"73332","439.95600","36.66324","0.13880"
"73398","440.35200","36.69624","0.13910"
"73464","440.74800","36.72925","0.13933"
"73530","441.14400","36.76219","0.13983"
"73596","441.54000","36.79520","0.14034"
"73662","441.93600","36.82826","0.14088"
"73728","442.33200","36.86120","0.14124"
"73794","442.72800","36.89415","0.14171"
"73860","443.12400","36.92721","0.14230"
"73926","443.52000","36.96021","0.14310"
"73992","443.91600","36.99322","0.14330"
"74058","444.31200","37.02622","0.14411"
"74124","444.70800","37.05923","0.14419"
"74190","445.10400","37.09223","0.14520"
"74256","445.50000","37.12518","0.14556"
"74322","445.89600","37.15824","0.14693"
"74388","446.29200","37.19124","0.14773"
"74454","446.68800","37.22419","0.14773"
"74520","447.08400","37.25713","0.14786"
"74586","447.48000","37.29025","0.14920"
"74652","447.87600","37.32314","0.14956"
"74718","448.27200","37.35614","0.15073"
"74784","448.66800","37.38920","0.15089"
"74850","449.06400","37.42221","0.15196"
"74916","449.46000","37.45521","0.15151"
"74982","449.85600","37.48822","0.15293"
"75048","450.25200","37.52122","0.15284"
"75114","450.64800","37.55422","0.15410"
"75180","451.04400","37.58723","0.15514"
"75246","451.44000","37.62017","0.15576"
"75312","451.83600","37.65324","0.15618"
"75378","452.23200","37.68624","0.15758"
"75444","452.62800","37.71924","0.15683"
"75510","453.02400","37.75213","0.15758"
"75576","453.42000","37.78519","0.15818"
"75642","453.81600","37.81826","0.15893"
"75708","454.21200","37.85120","0.15980"
"75774","454.60800","37.88414","0.16009"
"75840","455.00400","37.91721","0.15873"
"75906","455.40000","37.95027","0.15809"
"75972","455.79600","37.98321","0.15277"
"76038","456.19200","38.01616","0.14951"
"76104","456.58800","38.04922","0.14990"
"76170","456.98400","38.08223","0.15002"
"76236","457.38000","38.11517","0.15029"
"76302","457.77600","38.14817","0.15108"
"76368","458.17200","38.18118","0.15236"
"76434","458.56800","38.21424","0.15355"
"76500","458.96400","38.24719","0.15467"
"76566","459.36000","38.28019","0.15669"
"76632","459.75600","38.31325","0.15738"
"76698","460.15200","38.34620","0.15866"
"76764","460.54800","38.37920","0.15921"
"76830","460.94400","38.41220","0.16110"
"76896","461.34000","38.44521","0.16171"
"76962","461.73600","38.47821","0.15336"
"77028","462.13200","38.51122","0.15036"
"77094","462.52800","38.54422","0.15512"
"77160","462.92400","38.57722","0.15630"
"77226","463.32000","38.61023","0.15359"
"77292","463.71600","38.64317","0.15540"
"77358","464.11200","38.67630","0.16052"
"77424","464.50800","38.70924","0.16321"
"77490","464.90400","38.74218","0.16160"
"77556","465.30000","38.77519","0.03680"
"77622","465.69600","38.80819","0.02540"
"77688","466.09200","38.84126","0.02547"
"77754","466.48800","38.87414","0.01772"
"77820","466.88400","38.90720","0.02078"
"77886","467.28000","38.94020","0.02025"
"77952","467.67600","38.97321","0.02251"
"78018","468.07200","39.00615","0.02366"
"78084","468.46800","39.03922","0.02437"
"78150","468.86400","39.07222","0.02482"
"78216","469.26000","39.10522","0.02496"
"78282","469.65600","39.13816","0.02520"
"78348","470.05200","39.17117","0.02413"
"78414","470.44800","39.20423","0.02459"
"78480","470.84400","39.23718","0.02368"
"78546","471.24000","39.27018","0.02454"
"78612","471.63600","39.30319","0.02484"
"78678","472.03200","39.33625","0.02533"
"78744","472.42800","39.36919","0.02540"
"78810","472.82400","39.40214","0.02634"
"78876","473.22000","39.43526","0.02610"
"78942","473.61600","39.46821","0.02632"
"79008","474.01200","39.50115","0.02628"
"79074","474.40800","39.53421","0.02581"
"79140","474.80400","39.56716","0.02647"
"79206","475.20000","39.60022","0.02617"
"79272","475.59600","39.63322","0.02629"
"79338","475.99200","39.66617","0.02610"
"79404","476.38800","39.69923","0.02667"
"79470","476.78400","39.73223","0.02650"
"79536","477.18000","39.76518","0.02659"
"79602","477.57600","39.79824","0.02663"
"79668","477.97200","39.83125","0.02694"
"79734","478.36800","39.86419","0.02695"
"79800","478.76400","39.89719","0.02699"
"79866","479.16000","39.93026","0.02717"
"79932","479.55600","39.96320","0.02758"
"79998","479.95200","39.99615","0.02748"
"80064","480.34800","40.02921","0.02754"
"80130","480.74400","40.06221","0.02793"
"80196","481.14000","40.09522","0.02781"
"80262","481.53600","40.12822","0.02789"
"80328","481.93200","40.16122","0.02778"
"80394","482.32800","40.19423","0.02764"
"80460","482.72400","40.22723","0.02790"
"80526","483.12000","40.26018","0.02784"
"80569","483.37800","40.28176","0.02846"