File: Trajectories_together/170108_2Specimen_RawData_9.csv
"","V1","V2","V3"
"1","End date","1/8/2017",""
"2","Specimen label","9BT_78",""
"3","Maximum Load","0.08908","N"
"4","Time","Extension","Load"
"5","(s)","(mm)","(N)"
"6","0.00000","0.00000","-0.00030"
"41","0.21000","0.01435","0.00104"
"76","0.42000","0.03522","0.00171"
"111","0.63000","0.05273","0.00221"
"146","0.84000","0.07025","0.00297"
"181","1.05000","0.08771","0.00318"
"216","1.26000","0.10523","0.00388"
"251","1.47000","0.12269","0.00360"
"286","1.68000","0.14021","0.00419"
"321","1.89000","0.15772","0.00476"
"356","2.10000","0.17518","0.00473"
"391","2.31000","0.19264","0.00480"
"426","2.52000","0.21022","0.00516"
"461","2.73000","0.22762","0.00530"
"496","2.94000","0.24520","0.00603"
"531","3.15000","0.26266","0.00526"
"566","3.36000","0.28017","0.00614"
"601","3.57000","0.29769","0.00624"
"636","3.78000","0.31521","0.00658"
"671","3.99000","0.33267","0.00682"
"706","4.20000","0.35025","0.00648"
"741","4.41000","0.36765","0.00684"
"776","4.62000","0.38516","0.00715"
"811","4.83000","0.40262","0.00707"
"846","5.04000","0.42014","0.00753"
"881","5.25000","0.43766","0.00758"
"916","5.46000","0.45512","0.00753"
"951","5.67000","0.47270","0.00745"
"986","5.88000","0.49021","0.00823"
"1021","6.09000","0.50761","0.00812"
"1056","6.30000","0.52513","0.00809"
"1091","6.51000","0.54265","0.00797"
"1126","6.72000","0.56017","0.00829"
"1161","6.93000","0.57775","0.00842"
"1196","7.14000","0.59515","0.00842"
"1231","7.35000","0.61272","0.00870"
"1266","7.56000","0.63018","0.00919"
"1301","7.77000","0.64770","0.00842"
"1336","7.98000","0.66522","0.00901"
"1371","8.19000","0.68268","0.00921"
"1406","8.40000","0.70026","0.00930"
"1441","8.61000","0.71765","0.00916"
"1476","8.82000","0.73517","0.00930"
"1511","9.03000","0.75269","0.00942"
"1546","9.24000","0.77009","0.00942"
"1581","9.45000","0.78767","0.00966"
"1616","9.66000","0.80513","0.00977"
"1651","9.87000","0.82264","0.00969"
"1686","10.08000","0.84016","0.01025"
"1721","10.29000","0.85762","0.01015"
"1756","10.50000","0.87520","0.00984"
"1791","10.71000","0.89266","0.01022"
"1826","10.92000","0.91012","0.01090"
"1861","11.13000","0.92769","0.01022"
"1896","11.34000","0.94515","0.01083"
"1931","11.55000","0.96267","0.01015"
"1966","11.76000","0.98019","0.01046"
"2001","11.97000","0.99765","0.01031"
"2036","12.18000","1.01517","0.01066"
"2071","12.39000","1.03268","0.01115"
"2106","12.60000","1.05014","0.01116"
"2141","12.81000","1.06772","0.01086"
"2176","13.02000","1.08512","0.01079"
"2211","13.23000","1.10264","0.01057"
"2246","13.44000","1.12022","0.01099"
"2281","13.65000","1.13768","0.01083"
"2316","13.86000","1.15519","0.01095"
"2351","14.07000","1.17265","0.01103"
"2386","14.28000","1.19017","0.01146"
"2421","14.49000","1.20769","0.01153"
"2456","14.70000","1.22515","0.01068"
"2491","14.91000","1.24267","0.01143"
"2526","15.12000","1.26018","0.01157"
"2561","15.33000","1.27770","0.01125"
"2596","15.54000","1.29522","0.01130"
"2631","15.75000","1.31262","0.01185"
"2666","15.96000","1.33020","0.01132"
"2701","16.17000","1.34766","0.01151"
"2736","16.38000","1.36517","0.01189"
"2771","16.59000","1.38269","0.01196"
"2806","16.80000","1.40015","0.01232"
"2841","17.01000","1.41773","0.01180"
"2876","17.22000","1.43519","0.01194"
"2911","17.43000","1.45265","0.01204"
"2946","17.64000","1.47016","0.01222"
"2981","17.85000","1.48768","0.01206"
"3016","18.06000","1.50514","0.01237"
"3051","18.27000","1.52272","0.01196"
"3086","18.48000","1.54012","0.01239"
"3121","18.69000","1.55770","0.01259"
"3156","18.90000","1.57516","0.01234"
"3191","19.11000","1.59273","0.01218"
"3226","19.32000","1.61013","0.01240"
"3261","19.53000","1.62759","0.01256"
"3296","19.74000","1.64523","0.01286"
"3331","19.95000","1.66269","0.01258"
"3366","20.16000","1.68021","0.01229"
"3401","20.37000","1.69766","0.01306"
"3436","20.58000","1.71512","0.01302"
"3471","20.79000","1.73270","0.01282"
"3506","21.00000","1.75022","0.01277"
"3541","21.21000","1.76768","0.01308"
"3576","21.42000","1.78526","0.01340"
"3611","21.63000","1.80259","0.01338"
"3646","21.84000","1.82017","0.01299"
"3681","22.05000","1.83769","0.01346"
"3716","22.26000","1.85515","0.01356"
"3751","22.47000","1.87267","0.01317"
"3786","22.68000","1.89019","0.01369"
"3821","22.89000","1.90764","0.01346"
"3856","23.10000","1.92516","0.01422"
"3891","23.31000","1.94268","0.01342"
"3926","23.52000","1.96014","0.01377"
"3961","23.73000","1.97766","0.01369"
"3996","23.94000","1.99518","0.01361"
"4031","24.15000","2.01275","0.01342"
"4066","24.36000","2.03015","0.01351"
"4101","24.57000","2.04773","0.01399"
"4136","24.78000","2.06519","0.01447"
"4171","24.99000","2.08265","0.01448"
"4206","25.20000","2.10017","0.01383"
"4241","25.41000","2.11763","0.01396"
"4276","25.62000","2.13520","0.01453"
"4311","25.83000","2.15266","0.01444"
"4346","26.04000","2.17018","0.01430"
"4381","26.25000","2.18770","0.01396"
"4416","26.46000","2.20516","0.01456"
"4451","26.67000","2.22268","0.01426"
"4486","26.88000","2.24025","0.01428"
"4521","27.09000","2.25765","0.01480"
"4556","27.30000","2.27523","0.01520"
"4591","27.51000","2.29263","0.01469"
"4626","27.72000","2.31021","0.01491"
"4661","27.93000","2.32767","0.01440"
"4696","28.14000","2.34512","0.01463"
"4731","28.35000","2.36264","0.01521"
"4766","28.56000","2.38016","0.01449"
"4801","28.77000","2.39768","0.01516"
"4836","28.98000","2.41520","0.01478"
"4871","29.19000","2.43266","0.01527"
"4906","29.40000","2.45023","0.01517"
"4941","29.61000","2.46769","0.01511"
"4976","29.82000","2.48515","0.01514"
"5011","30.03000","2.50273","0.01501"
"5046","30.24000","2.52013","0.01500"
"5081","30.45000","2.53765","0.01516"
"5116","30.66000","2.55517","0.01488"
"5151","30.87000","2.57262","0.01563"
"5186","31.08000","2.59020","0.01555"
"5221","31.29000","2.60766","0.01501"
"5256","31.50000","2.62518","0.01495"
"5291","31.71000","2.64264","0.01550"
"5326","31.92000","2.66016","0.01562"
"5361","32.13000","2.67767","0.01566"
"5396","32.34000","2.69519","0.01490"
"5431","32.55000","2.71271","0.01522"
"5466","32.76000","2.73023","0.01567"
"5501","32.97000","2.74763","0.01498"
"5536","33.18000","2.76521","0.01590"
"5571","33.39000","2.78266","0.01559"
"5606","33.60000","2.80018","0.01533"
"5641","33.81000","2.81770","0.01603"
"5676","34.02000","2.83510","0.01618"
"5711","34.23000","2.85268","0.01571"
"5746","34.44000","2.87014","0.01568"
"5781","34.65000","2.88766","0.01575"
"5816","34.86000","2.90517","0.01558"
"5851","35.07000","2.92269","0.01603"
"5886","35.28000","2.94021","0.01627"
"5921","35.49000","2.95773","0.01594"
"5956","35.70000","2.97513","0.01604"
"5991","35.91000","2.99271","0.01672"
"6026","36.12000","3.01016","0.01680"
"6061","36.33000","3.02774","0.01620"
"6096","36.54000","3.04514","0.01624"
"6131","36.75000","3.06260","0.01569"
"6166","36.96000","3.08018","0.01687"
"6201","37.17000","3.09764","0.01602"
"6236","37.38000","3.11521","0.01692"
"6271","37.59000","3.13273","0.01644"
"6306","37.80000","3.15007","0.01638"
"6341","38.01000","3.16771","0.01676"
"6376","38.22000","3.18517","0.01670"
"6411","38.43000","3.20263","0.01673"
"6446","38.64000","3.22026","0.01650"
"6481","38.85000","3.23760","0.01672"
"6516","39.06000","3.25518","0.01666"
"6551","39.27000","3.27264","0.01672"
"6586","39.48000","3.29016","0.01673"
"6621","39.69000","3.30768","0.01733"
"6656","39.90000","3.32513","0.01620"
"6691","40.11000","3.34265","0.01742"
"6726","40.32000","3.36023","0.01680"
"6761","40.53000","3.37769","0.01705"
"6796","40.74000","3.39515","0.01663"
"6831","40.95000","3.41267","0.01686"
"6866","41.16000","3.43019","0.01682"
"6901","41.37000","3.44770","0.01679"
"6936","41.58000","3.46516","0.01718"
"6971","41.79000","3.48268","0.01713"
"7006","42.00000","3.50020","0.01728"
"7041","42.21000","3.51772","0.01771"
"7076","42.42000","3.53524","0.01745"
"7111","42.63000","3.55263","0.01746"
"7146","42.84000","3.57021","0.01745"
"7181","43.05000","3.58761","0.01783"
"7216","43.26000","3.60519","0.01758"
"7251","43.47000","3.62265","0.01733"
"7286","43.68000","3.64017","0.01787"
"7321","43.89000","3.65768","0.01743"
"7356","44.10000","3.67520","0.01740"
"7391","44.31000","3.69266","0.01786"
"7426","44.52000","3.71018","0.01811"
"7461","44.73000","3.72764","0.01851"
"7496","44.94000","3.74522","0.01756"
"7531","45.15000","3.76268","0.01786"
"7566","45.36000","3.78007","0.01759"
"7601","45.57000","3.79765","0.01775"
"7636","45.78000","3.81517","0.01808"
"7671","45.99000","3.83269","0.01790"
"7706","46.20000","3.85015","0.01786"
"7741","46.41000","3.86767","0.01821"
"7776","46.62000","3.88518","0.01829"
"7811","46.83000","3.90270","0.01811"
"7846","47.04000","3.92016","0.01833"
"7881","47.25000","3.93768","0.01830"
"7916","47.46000","3.95508","0.01838"
"7951","47.67000","3.97272","0.01797"
"7986","47.88000","3.99017","0.01907"
"8021","48.09000","4.00763","0.01866"
"8056","48.30000","4.02521","0.01882"
"8091","48.51000","4.04267","0.01858"
"8126","48.72000","4.06019","0.01866"
"8161","48.93000","4.07771","0.01898"
"8196","49.14000","4.09516","0.01816"
"8231","49.35000","4.11262","0.01862"
"8266","49.56000","4.13014","0.01857"
"8301","49.77000","4.14766","0.01872"
"8336","49.98000","4.16524","0.01873"
"8371","50.19000","4.18264","0.01899"
"8406","50.40000","4.20021","0.01923"
"8441","50.61000","4.21767","0.01914"
"8476","50.82000","4.23519","0.01890"
"8511","51.03000","4.25271","0.01907"
"8546","51.24000","4.27017","0.01983"
"8581","51.45000","4.28775","0.01905"
"8616","51.66000","4.30509","0.01923"
"8651","51.87000","4.32266","0.01891"
"8686","52.08000","4.34018","0.01903"
"8721","52.29000","4.35770","0.01902"
"8756","52.50000","4.37516","0.01934"
"8791","52.71000","4.39268","0.01934"
"8826","52.92000","4.41020","0.01968"
"8861","53.13000","4.42771","0.01966"
"8896","53.34000","4.44517","0.01947"
"8931","53.55000","4.46269","0.02003"
"8966","53.76000","4.48015","0.01994"
"9001","53.97000","4.49761","0.01920"
"9036","54.18000","4.51519","0.01962"
"9071","54.39000","4.53264","0.02006"
"9106","54.60000","4.55022","0.02009"
"9141","54.81000","4.56768","0.02006"
"9176","55.02000","4.58514","0.02005"
"9211","55.23000","4.60266","0.01974"
"9246","55.44000","4.62018","0.02044"
"9281","55.65000","4.63763","0.02033"
"9316","55.86000","4.65521","0.01993"
"9351","56.07000","4.67261","0.02012"
"9386","56.28000","4.69019","0.02058"
"9421","56.49000","4.70771","0.01998"
"9456","56.70000","4.72517","0.02061"
"9491","56.91000","4.74269","0.02050"
"9526","57.12000","4.76014","0.02060"
"9561","57.33000","4.77766","0.02067"
"9596","57.54000","4.79518","0.02071"
"9631","57.75000","4.81270","0.02081"
"9666","57.96000","4.83016","0.02072"
"9701","58.17000","4.84768","0.02078"
"9736","58.38000","4.86519","0.02103"
"9771","58.59000","4.88265","0.02090"
"9806","58.80000","4.90011","0.02068"
"9841","59.01000","4.91769","0.02099"
"9876","59.22000","4.93515","0.02128"
"9911","59.43000","4.95267","0.02112"
"9946","59.64000","4.97018","0.02158"
"9981","59.85000","4.98764","0.02114"
"10016","60.06000","5.00522","0.02154"
"10051","60.27000","5.02262","0.02074"
"10086","60.48000","5.04014","0.02143"
"10121","60.69000","5.05772","0.02178"
"10156","60.90000","5.07517","0.02179"
"10191","61.11000","5.09269","0.02161"
"10226","61.32000","5.11027","0.02218"
"10261","61.53000","5.12761","0.02222"
"10296","61.74000","5.14519","0.02192"
"10331","61.95000","5.16271","0.02204"
"10366","62.16000","5.18023","0.02197"
"10401","62.37000","5.19768","0.02218"
"10436","62.58000","5.21508","0.02219"
"10471","62.79000","5.23266","0.02204"
"10506","63.00000","5.25012","0.02192"
"10541","63.21000","5.26770","0.02231"
"10576","63.42000","5.28522","0.02279"
"10611","63.63000","5.30261","0.02305"
"10646","63.84000","5.32019","0.02251"
"10681","64.05000","5.33771","0.02259"
"10716","64.26000","5.35517","0.02289"
"10751","64.47000","5.37269","0.02306"
"10786","64.68000","5.39015","0.02283"
"10821","64.89000","5.40766","0.02308"
"10856","65.10000","5.42518","0.02266"
"10891","65.31000","5.44264","0.02320"
"10926","65.52000","5.46022","0.02325"
"10961","65.73000","5.47768","0.02318"
"10996","65.94000","5.49514","0.02321"
"11031","66.15000","5.51271","0.02340"
"11066","66.36000","5.53017","0.02294"
"11101","66.57000","5.54769","0.02339"
"11136","66.78000","5.56515","0.02376"
"11171","66.99000","5.58267","0.02337"
"11206","67.20000","5.60025","0.02382"
"11241","67.41000","5.61759","0.02423"
"11276","67.62000","5.63522","0.02401"
"11311","67.83000","5.65262","0.02368"
"11346","68.04000","5.67020","0.02465"
"11381","68.25000","5.68772","0.02419"
"11416","68.46000","5.70512","0.02420"
"11451","68.67000","5.72270","0.02452"
"11486","68.88000","5.74015","0.02419"
"11521","69.09000","5.75767","0.02453"
"11556","69.30000","5.77519","0.02470"
"11591","69.51000","5.79265","0.02441"
"11626","69.72000","5.81023","0.02458"
"11661","69.93000","5.82769","0.02538"
"11696","70.14000","5.84514","0.02455"
"11731","70.35000","5.86272","0.02479"
"11766","70.56000","5.88018","0.02484"
"11801","70.77000","5.89770","0.02523"
"11836","70.98000","5.91522","0.02472"
"11871","71.19000","5.93256","0.02516"
"11906","71.40000","5.95019","0.02502"
"11941","71.61000","5.96765","0.02546"
"11976","71.82000","5.98523","0.02512"
"12011","72.03000","6.00269","0.02589"
"12046","72.24000","6.02015","0.02562"
"12081","72.45000","6.03773","0.02535"
"12116","72.66000","6.05518","0.02564"
"12151","72.87000","6.07264","0.02577"
"12186","73.08000","6.09022","0.02613"
"12221","73.29000","6.10756","0.02637"
"12256","73.50000","6.12520","0.02613"
"12291","73.71000","6.14272","0.02651"
"12326","73.92000","6.16017","0.02676"
"12361","74.13000","6.17769","0.02644"
"12396","74.34000","6.19515","0.02660"
"12431","74.55000","6.21267","0.02722"
"12466","74.76000","6.23019","0.02694"
"12501","74.97000","6.24765","0.02699"
"12536","75.18000","6.26517","0.02696"
"12571","75.39000","6.28268","0.02754"
"12606","75.60000","6.30014","0.02731"
"12641","75.81000","6.31772","0.02790"
"12676","76.02000","6.33506","0.02790"
"12711","76.23000","6.35276","0.02752"
"12746","76.44000","6.37016","0.02769"
"12781","76.65000","6.38767","0.02709"
"12816","76.86000","6.40519","0.02835"
"12851","77.07000","6.42265","0.02837"
"12886","77.28000","6.44023","0.02858"
"12921","77.49000","6.45763","0.02850"
"12956","77.70000","6.47515","0.02845"
"12991","77.91000","6.49272","0.02855"
"13026","78.12000","6.51018","0.02878"
"13061","78.33000","6.52764","0.02890"
"13096","78.54000","6.54528","0.02915"
"13131","78.75000","6.56262","0.02907"
"13166","78.96000","6.58020","0.02975"
"13201","79.17000","6.59766","0.02971"
"13236","79.38000","6.61523","0.02898"
"13271","79.59000","6.63269","0.02872"
"13306","79.80000","6.65009","0.02897"
"13341","80.01000","6.66773","0.02904"
"13376","80.22000","6.68519","0.02907"
"13411","80.43000","6.70271","0.02905"
"13446","80.64000","6.72016","0.02978"
"13481","80.85000","6.73762","0.03010"
"13516","81.06000","6.75520","0.02982"
"13551","81.27000","6.77272","0.03022"
"13586","81.48000","6.79018","0.02983"
"13621","81.69000","6.80770","0.03043"
"13656","81.90000","6.82510","0.02993"
"13691","82.11000","6.84267","0.03041"
"13726","82.32000","6.86019","0.03044"
"13761","82.53000","6.87765","0.03061"
"13796","82.74000","6.89517","0.03076"
"13831","82.95000","6.91263","0.03064"
"13866","83.16000","6.93020","0.03130"
"13901","83.37000","6.94766","0.03199"
"13936","83.58000","6.96518","0.03142"
"13971","83.79000","6.98264","0.03239"
"14006","84.00000","7.00016","0.03230"
"14041","84.21000","7.01768","0.03217"
"14076","84.42000","7.03519","0.03227"
"14111","84.63000","7.05259","0.03299"
"14146","84.84000","7.07023","0.03299"
"14181","85.05000","7.08769","0.03277"
"14216","85.26000","7.10515","0.03328"
"14251","85.47000","7.12267","0.03356"
"14286","85.68000","7.14019","0.03381"
"14321","85.89000","7.15770","0.03383"
"14356","86.10000","7.17516","0.03413"
"14391","86.31000","7.19268","0.03434"
"14426","86.52000","7.21020","0.03426"
"14461","86.73000","7.22766","0.03452"
"14496","86.94000","7.24518","0.03467"
"14531","87.15000","7.26269","0.03450"
"14566","87.36000","7.28015","0.03526"
"14601","87.57000","7.29767","0.03508"
"14636","87.78000","7.31513","0.03420"
"14671","87.99000","7.33271","0.03452"
"14706","88.20000","7.35017","0.03483"
"14741","88.41000","7.36763","0.03545"
"14776","88.62000","7.38520","0.03500"
"14811","88.83000","7.40260","0.03539"
"14846","89.04000","7.42018","0.03547"
"14881","89.25000","7.43770","0.03552"
"14916","89.46000","7.45510","0.03636"
"14951","89.67000","7.47273","0.03626"
"14986","89.88000","7.49019","0.03655"
"15021","90.09000","7.50759","0.03618"
"15056","90.30000","7.52517","0.03702"
"15091","90.51000","7.54263","0.03699"
"15126","90.72000","7.56021","0.03668"
"15161","90.93000","7.57773","0.03729"
"15196","91.14000","7.59512","0.03680"
"15231","91.35000","7.61270","0.03733"
"15266","91.56000","7.63016","0.03672"
"15301","91.77000","7.64768","0.03745"
"15336","91.98000","7.66520","0.03808"
"15371","92.19000","7.68266","0.03820"
"15406","92.40000","7.70011","0.03815"
"15441","92.61000","7.71769","0.03843"
"15476","92.82000","7.73515","0.03845"
"15511","93.03000","7.75273","0.03867"
"15546","93.24000","7.77019","0.03839"
"15581","93.45000","7.78771","0.03822"
"15616","93.66000","7.80517","0.03815"
"15651","93.87000","7.82268","0.03758"
"15686","94.08000","7.84020","0.03834"
"15721","94.29000","7.85766","0.03808"
"15756","94.50000","7.87524","0.03828"
"15791","94.71000","7.89264","0.03849"
"15826","94.92000","7.91010","0.03850"
"15861","95.13000","7.92767","0.03862"
"15896","95.34000","7.94519","0.03860"
"15931","95.55000","7.96265","0.03888"
"15966","95.76000","7.98017","0.03899"
"16001","95.97000","7.99763","0.03892"
"16036","96.18000","8.01526","0.03962"
"16071","96.39000","8.03260","0.03914"
"16106","96.60000","8.05024","0.03970"
"16141","96.81000","8.06764","0.03978"
"16176","97.02000","8.08510","0.03968"
"16211","97.23000","8.10268","0.04003"
"16246","97.44000","8.12014","0.04017"
"16281","97.65000","8.13771","0.03966"
"16316","97.86000","8.15517","0.03948"
"16351","98.07000","8.17263","0.03975"
"16386","98.28000","8.19021","0.04018"
"16421","98.49000","8.20767","0.04026"
"16456","98.70000","8.22519","0.04046"
"16491","98.91000","8.24271","0.04058"
"16526","99.12000","8.26010","0.04056"
"16561","99.33000","8.27768","0.04048"
"16596","99.54000","8.29520","0.04084"
"16631","99.75000","8.31266","0.04067"
"16666","99.96000","8.33024","0.04042"
"16701","100.17000","8.34764","0.04111"
"16736","100.38000","8.36521","0.04109"
"16771","100.59000","8.38267","0.04107"
"16806","100.80000","8.40013","0.04127"
"16841","101.01000","8.41765","0.04142"
"16876","101.22000","8.43517","0.04165"
"16911","101.43000","8.45269","0.04180"
"16946","101.64000","8.47020","0.04191"
"16981","101.85000","8.48760","0.04178"
"17016","102.06000","8.50518","0.04205"
"17051","102.27000","8.52270","0.04232"
"17086","102.48000","8.54016","0.04211"
"17121","102.69000","8.55768","0.04247"
"17156","102.90000","8.57513","0.04244"
"17191","103.11000","8.59277","0.04295"
"17226","103.32000","8.61011","0.04334"
"17261","103.53000","8.62769","0.04288"
"17296","103.74000","8.64515","0.04303"
"17331","103.95000","8.66267","0.04315"
"17366","104.16000","8.68018","0.04341"
"17401","104.37000","8.69776","0.04362"
"17436","104.58000","8.71510","0.04338"
"17471","104.79000","8.73268","0.04356"
"17506","105.00000","8.75014","0.04364"
"17541","105.21000","8.76772","0.04330"
"17576","105.42000","8.78518","0.04330"
"17611","105.63000","8.80263","0.04298"
"17646","105.84000","8.82021","0.04306"
"17681","106.05000","8.83767","0.04320"
"17716","106.26000","8.85513","0.04336"
"17751","106.47000","8.87271","0.04317"
"17786","106.68000","8.89011","0.04349"
"17821","106.89000","8.90768","0.04360"
"17856","107.10000","8.92520","0.04381"
"17891","107.31000","8.94266","0.04386"
"17926","107.52000","8.96024","0.04439"
"17961","107.73000","8.97764","0.04422"
"17996","107.94000","8.99516","0.04470"
"18031","108.15000","9.01267","0.04446"
"18066","108.36000","9.03013","0.04542"
"18101","108.57000","9.04771","0.04504"
"18136","108.78000","9.06517","0.04557"
"18171","108.99000","9.08269","0.04561"
"18206","109.20000","9.10015","0.04569"
"18241","109.41000","9.11766","0.04578"
"18276","109.62000","9.13518","0.04654"
"18311","109.83000","9.15264","0.04730"
"18346","110.04000","9.17022","0.04747"
"18381","110.25000","9.18768","0.04777"
"18416","110.46000","9.20514","0.04783"
"18451","110.67000","9.22272","0.04772"
"18486","110.88000","9.24017","0.04810"
"18521","111.09000","9.25769","0.04871"
"18556","111.30000","9.27521","0.04874"
"18591","111.51000","9.29267","0.04946"
"18626","111.72000","9.31025","0.04945"
"18661","111.93000","9.32765","0.05089"
"18696","112.14000","9.34522","0.05007"
"18731","112.35000","9.36268","0.05080"
"18766","112.56000","9.38020","0.05142"
"18801","112.77000","9.39766","0.05176"
"18836","112.98000","9.41524","0.05229"
"18871","113.19000","9.43264","0.05185"
"18906","113.40000","9.45021","0.05248"
"18941","113.61000","9.46767","0.05270"
"18976","113.82000","9.48519","0.05328"
"19011","114.03000","9.50271","0.02052"
"19046","114.24000","9.52011","0.02290"
"19081","114.45000","9.53769","0.02007"
"19116","114.66000","9.55515","0.02098"
"19151","114.87000","9.57272","0.01931"
"19186","115.08000","9.59018","0.02073"
"19221","115.29000","9.60764","0.02074"
"19256","115.50000","9.62522","0.01974"
"19291","115.71000","9.64274","0.02208"
"19326","115.92000","9.66014","0.01969"
"19361","116.13000","9.67771","0.02173"
"19396","116.34000","9.69511","0.02133"
"19431","116.55000","9.71269","0.02130"
"19466","116.76000","9.73015","0.02156"
"19501","116.97000","9.74767","0.02137"
"19536","117.18000","9.76519","0.02210"
"19571","117.39000","9.78264","0.02150"
"19606","117.60000","9.80016","0.02294"
"19641","117.81000","9.81768","0.02169"
"19676","118.02000","9.83514","0.02278"
"19711","118.23000","9.85266","0.02210"
"19746","118.44000","9.87018","0.02263"
"19781","118.65000","9.88769","0.02259"
"19816","118.86000","9.90521","0.02249"
"19851","119.07000","9.92267","0.02294"
"19886","119.28000","9.94019","0.02360"
"19921","119.49000","9.95771","0.02338"
"19956","119.70000","9.97517","0.02280"
"19991","119.91000","9.99274","0.02326"
"20026","120.12000","10.01014","0.02334"
"20061","120.33000","10.02772","0.02365"
"20096","120.54000","10.04512","0.02304"
"20131","120.75000","10.06270","0.02416"
"20166","120.96000","10.08016","0.02363"
"20201","121.17000","10.09768","0.02378"
"20236","121.38000","10.11513","0.02344"
"20271","121.59000","10.13271","0.02357"
"20306","121.80000","10.15017","0.02356"
"20341","122.01000","10.16775","0.02349"
"20376","122.22000","10.18509","0.02392"
"20411","122.43000","10.20272","0.02388"
"20446","122.64000","10.22012","0.02406"
"20481","122.85000","10.23758","0.02407"
"20516","123.06000","10.25522","0.02392"
"20551","123.27000","10.27268","0.02414"
"20586","123.48000","10.29020","0.02416"
"20621","123.69000","10.30772","0.02392"
"20656","123.90000","10.32511","0.02386"
"20691","124.11000","10.34269","0.02424"
"20726","124.32000","10.36021","0.02437"
"20761","124.53000","10.37761","0.02448"
"20796","124.74000","10.39525","0.02430"
"20831","124.95000","10.41265","0.02456"
"20866","125.16000","10.43016","0.02475"
"20901","125.37000","10.44768","0.02409"
"20936","125.58000","10.46514","0.02418"
"20971","125.79000","10.48266","0.02451"
"21006","126.00000","10.50012","0.02346"
"21041","126.21000","10.51770","0.02368"
"21076","126.42000","10.53515","0.02403"
"21111","126.63000","10.55261","0.02392"
"21146","126.84000","10.57013","0.02368"
"21181","127.05000","10.58765","0.02394"
"21216","127.26000","10.60517","0.02407"
"21251","127.47000","10.62269","0.02392"
"21286","127.68000","10.64009","0.02454"
"21321","127.89000","10.65772","0.02426"
"21356","128.10000","10.67512","0.02465"
"21391","128.31000","10.69270","0.02430"
"21426","128.52000","10.71022","0.02426"
"21461","128.73000","10.72762","0.02448"
"21496","128.94000","10.74520","0.02502"
"21531","129.15000","10.76265","0.02518"
"21566","129.36000","10.78017","0.02576"
"21601","129.57000","10.79769","0.02512"
"21636","129.78000","10.81515","0.02520"
"21671","129.99000","10.83267","0.02549"
"21706","130.20000","10.85025","0.02519"
"21741","130.41000","10.86770","0.02526"
"21776","130.62000","10.88516","0.02572"
"21811","130.83000","10.90268","0.02611"
"21846","131.04000","10.92020","0.02610"
"21881","131.25000","10.93766","0.02608"
"21916","131.46000","10.95512","0.02617"
"21951","131.67000","10.97269","0.02623"
"21986","131.88000","10.99009","0.02639"
"22021","132.09000","11.00773","0.02664"
"22056","132.30000","11.02519","0.02649"
"22091","132.51000","11.04265","0.02645"
"22126","132.72000","11.06017","0.02644"
"22161","132.93000","11.07769","0.02596"
"22196","133.14000","11.09508","0.02682"
"22231","133.35000","11.11272","0.02681"
"22266","133.56000","11.13012","0.02666"
"22301","133.77000","11.14770","0.02712"
"22336","133.98000","11.16516","0.02695"
"22371","134.19000","11.18262","0.02695"
"22406","134.40000","11.20019","0.02761"
"22441","134.61000","11.21765","0.02741"
"22476","134.82000","11.23517","0.02673"
"22511","135.03000","11.25269","0.02768"
"22546","135.24000","11.27015","0.02732"
"22581","135.45000","11.28767","0.02754"
"22616","135.66000","11.30519","0.02743"
"22651","135.87000","11.32270","0.02738"
"22686","136.08000","11.34022","0.02684"
"22721","136.29000","11.35762","0.02713"
"22756","136.50000","11.37526","0.02765"
"22791","136.71000","11.39266","0.02781"
"22826","136.92000","11.41017","0.02768"
"22861","137.13000","11.42769","0.02810"
"22896","137.34000","11.44515","0.02838"
"22931","137.55000","11.46273","0.02815"
"22966","137.76000","11.48013","0.02858"
"23001","137.97000","11.49765","0.02834"
"23036","138.18000","11.51523","0.02899"
"23071","138.39000","11.53262","0.02964"
"23106","138.60000","11.55020","0.02951"
"23141","138.81000","11.56766","0.02957"
"23176","139.02000","11.58518","0.02988"
"23211","139.23000","11.60270","0.03027"
"23246","139.44000","11.62010","0.03023"
"23281","139.65000","11.63773","0.03040"
"23316","139.86000","11.65513","0.03042"
"23351","140.07000","11.67259","0.03064"
"23386","140.28000","11.69017","0.03086"
"23421","140.49000","11.70763","0.03147"
"23456","140.70000","11.72521","0.03073"
"23491","140.91000","11.74266","0.03111"
"23526","141.12000","11.76012","0.03177"
"23561","141.33000","11.77770","0.03172"
"23596","141.54000","11.79522","0.03147"
"23631","141.75000","11.81268","0.03220"
"23666","141.96000","11.83020","0.03244"
"23701","142.17000","11.84765","0.03221"
"23736","142.38000","11.86517","0.03263"
"23771","142.59000","11.88269","0.03311"
"23806","142.80000","11.90015","0.03258"
"23841","143.01000","11.91773","0.03313"
"23876","143.22000","11.93513","0.03348"
"23911","143.43000","11.95271","0.03407"
"23946","143.64000","11.97022","0.03366"
"23981","143.85000","11.98768","0.03331"
"24016","144.06000","12.00520","0.03419"
"24051","144.27000","12.02272","0.03402"
"24086","144.48000","12.04018","0.03470"
"24121","144.69000","12.05775","0.03459"
"24156","144.90000","12.07509","0.03518"
"24191","145.11000","12.09273","0.03524"
"24226","145.32000","12.11013","0.03521"
"24261","145.53000","12.12765","0.03554"
"24296","145.74000","12.14517","0.03558"
"24331","145.95000","12.16269","0.03589"
"24366","146.16000","12.18020","0.03582"
"24401","146.37000","12.19766","0.03591"
"24436","146.58000","12.21518","0.03634"
"24471","146.79000","12.23270","0.03582"
"24506","147.00000","12.25016","0.03679"
"24541","147.21000","12.26768","0.03684"
"24576","147.42000","12.28525","0.03695"
"24611","147.63000","12.30265","0.03717"
"24646","147.84000","12.32023","0.03717"
"24681","148.05000","12.33769","0.03742"
"24716","148.26000","12.35521","0.03786"
"24751","148.47000","12.37267","0.03744"
"24786","148.68000","12.39012","0.03810"
"24821","148.89000","12.40770","0.03796"
"24856","149.10000","12.42516","0.03821"
"24891","149.31000","12.44268","0.03817"
"24926","149.52000","12.46020","0.03864"
"24961","149.73000","12.47760","0.03900"
"24996","149.94000","12.49523","0.03884"
"25031","150.15000","12.51269","0.03919"
"25066","150.36000","12.53015","0.03909"
"25101","150.57000","12.54773","0.03969"
"25136","150.78000","12.56513","0.03951"
"25171","150.99000","12.58271","0.03966"
"25206","151.20000","12.60017","0.03998"
"25241","151.41000","12.61762","0.03997"
"25276","151.62000","12.63520","0.03991"
"25311","151.83000","12.65266","0.04027"
"25346","152.04000","12.67018","0.04002"
"25381","152.25000","12.68770","0.04031"
"25416","152.46000","12.70516","0.04036"
"25451","152.67000","12.72262","0.04064"
"25486","152.88000","12.74019","0.04068"
"25521","153.09000","12.75765","0.04109"
"25556","153.30000","12.77523","0.04090"
"25591","153.51000","12.79263","0.04122"
"25626","153.72000","12.81021","0.04147"
"25661","153.93000","12.82766","0.04131"
"25696","154.14000","12.84518","0.04173"
"25731","154.35000","12.86270","0.04148"
"25766","154.56000","12.88016","0.04179"
"25801","154.77000","12.89774","0.04191"
"25836","154.98000","12.91514","0.04184"
"25871","155.19000","12.93272","0.04229"
"25906","155.40000","12.95017","0.04233"
"25941","155.61000","12.96769","0.04253"
"25976","155.82000","12.98521","0.04279"
"26011","156.03000","13.00273","0.04290"
"26046","156.24000","13.02013","0.04320"
"26081","156.45000","13.03771","0.04329"
"26116","156.66000","13.05516","0.04353"
"26151","156.87000","13.07274","0.04368"
"26186","157.08000","13.09020","0.04433"
"26221","157.29000","13.10760","0.04370"
"26256","157.50000","13.12518","0.04413"
"26291","157.71000","13.14264","0.04426"
"26326","157.92000","13.16016","0.04446"
"26361","158.13000","13.17767","0.04440"
"26396","158.34000","13.19513","0.04498"
"26431","158.55000","13.21271","0.04528"
"26466","158.76000","13.23023","0.04519"
"26501","158.97000","13.24763","0.04588"
"26536","159.18000","13.26520","0.04639"
"26571","159.39000","13.28266","0.04694"
"26606","159.60000","13.30018","0.04726"
"26641","159.81000","13.31770","0.04761"
"26676","160.02000","13.33516","0.04813"
"26711","160.23000","13.35268","0.04800"
"26746","160.44000","13.37014","0.04858"
"26781","160.65000","13.38771","0.04985"
"26816","160.86000","13.40517","0.04961"
"26851","161.07000","13.42269","0.05058"
"26886","161.28000","13.44015","0.05052"
"26921","161.49000","13.45773","0.05103"
"26956","161.70000","13.47519","0.05183"
"26991","161.91000","13.49276","0.05276"
"27026","162.12000","13.51010","0.05359"
"27061","162.33000","13.52774","0.05467"
"27096","162.54000","13.54514","0.05505"
"27131","162.75000","13.56266","0.05613"
"27166","162.96000","13.58024","0.05661"
"27201","163.17000","13.59764","0.05782"
"27236","163.38000","13.61521","0.05752"
"27271","163.59000","13.63267","0.05837"
"27306","163.80000","13.65019","0.05818"
"27341","164.01000","13.66765","0.05846"
"27376","164.22000","13.68517","0.05945"
"27411","164.43000","13.70268","0.06006"
"27446","164.64000","13.72020","0.06072"
"27481","164.85000","13.73760","0.06089"
"27516","165.06000","13.75524","0.05944"
"27551","165.27000","13.77264","0.06048"
"27586","165.48000","13.79022","0.06170"
"27621","165.69000","13.80768","0.06267"
"27656","165.90000","13.82507","0.06323"
"27691","166.11000","13.84265","0.06436"
"27726","166.32000","13.86017","0.06491"
"27761","166.53000","13.87769","0.06560"
"27796","166.74000","13.89521","0.06610"
"27831","166.95000","13.91261","0.06666"
"27866","167.16000","13.93024","0.06696"
"27901","167.37000","13.94770","0.06759"
"27936","167.58000","13.96516","0.06809"
"27971","167.79000","13.98274","0.06915"
"28006","168.00000","14.00014","0.06633"
"28041","168.21000","14.01772","0.06690"
"28076","168.42000","14.03518","0.06593"
"28111","168.63000","14.05269","0.06576"
"28146","168.84000","14.07015","0.06648"
"28181","169.05000","14.08761","0.06710"
"28216","169.26000","14.10519","0.06733"
"28251","169.47000","14.12271","0.06776"
"28286","169.68000","14.14016","0.06755"
"28321","169.89000","14.15768","0.06808"
"28356","170.10000","14.17514","0.06853"
"28391","170.31000","14.19266","0.06877"
"28426","170.52000","14.21018","0.06950"
"28461","170.73000","14.22764","0.06993"
"28496","170.94000","14.24522","0.07075"
"28531","171.15000","14.26267","0.07098"
"28566","171.36000","14.28019","0.07134"
"28601","171.57000","14.29771","0.07213"
"28636","171.78000","14.31511","0.07278"
"28671","171.99000","14.33269","0.07340"
"28706","172.20000","14.35015","0.07397"
"28741","172.41000","14.36766","0.07481"
"28776","172.62000","14.38518","0.07494"
"28811","172.83000","14.40270","0.07587"
"28846","173.04000","14.42016","0.07647"
"28881","173.25000","14.43768","0.07637"
"28916","173.46000","14.45514","0.07654"
"28951","173.67000","14.47271","0.07735"
"28986","173.88000","14.49017","0.07790"
"29021","174.09000","14.50769","0.07884"
"29056","174.30000","14.52521","0.07916"
"29091","174.51000","14.54261","0.07942"
"29126","174.72000","14.56019","0.08033"
"29161","174.93000","14.57765","0.08059"
"29196","175.14000","14.59516","0.08175"
"29231","175.35000","14.61262","0.08181"
"29266","175.56000","14.63014","0.07860"
"29301","175.77000","14.64772","0.08001"
"29336","175.98000","14.66518","0.08072"
"29371","176.19000","14.68264","0.07974"
"29406","176.40000","14.70021","0.08020"
"29441","176.61000","14.71761","0.08057"
"29476","176.82000","14.73519","0.08182"
"29511","177.03000","14.75271","0.08180"
"29546","177.24000","14.77017","0.08211"
"29581","177.45000","14.78769","0.08320"
"29616","177.66000","14.80514","0.08339"
"29651","177.87000","14.82272","0.08420"
"29686","178.08000","14.84018","0.08508"
"29721","178.29000","14.85764","0.08500"
"29756","178.50000","14.87516","0.08573"
"29791","178.71000","14.89268","0.08530"
"29826","178.92000","14.91020","0.08605"
"29861","179.13000","14.92771","0.08632"
"29896","179.34000","14.94511","0.08566"
"29931","179.55000","14.96275","0.08601"
"29966","179.76000","14.98021","0.08605"
"30001","179.97000","14.99767","0.08595"
"30036","180.18000","15.01518","0.08607"
"30071","180.39000","15.03264","0.08671"
"30106","180.60000","15.05022","0.08714"
"30141","180.81000","15.06762","0.08698"
"30176","181.02000","15.08514","0.08731"
"30211","181.23000","15.10266","0.08652"
"30246","181.44000","15.12018","0.08675"
"30281","181.65000","15.13763","0.08708"
"30316","181.86000","15.15521","0.08752"
"30351","182.07000","15.17267","0.08771"
"30386","182.28000","15.19019","0.08797"
"30421","182.49000","15.20765","0.08807"
"30456","182.70000","15.22523","0.08836"
"30491","182.91000","15.24263","0.08847"
"30526","183.12000","15.26008","0.08867"
"30561","183.33000","15.27772","0.08887"
"30596","183.54000","15.29518","0.08879"
"30631","183.75000","15.31270","0.07663"
"30666","183.96000","15.33016","0.07265"
"30701","184.17000","15.34762","0.07461"
"30736","184.38000","15.36519","0.07572"
"30771","184.59000","15.38271","0.07699"
"30806","184.80000","15.40017","0.07787"
"30841","185.01000","15.41775","0.07829"
"30876","185.22000","15.43509","0.06751"
"30911","185.43000","15.45273","0.06847"
"30946","185.64000","15.47018","0.06925"
"30981","185.85000","15.48770","0.06965"
"31016","186.06000","15.50522","0.07106"
"31051","186.27000","15.52268","0.07231"
"31086","186.48000","15.54020","0.07338"
"31121","186.69000","15.55772","0.07393"
"31156","186.90000","15.57517","0.07473"
"31191","187.11000","15.59263","0.07614"
"31226","187.32000","15.61015","0.07661"
"31261","187.53000","15.62773","0.07766"
"31296","187.74000","15.64519","0.07876"
"31331","187.95000","15.66258","0.07937"
"31366","188.16000","15.68022","0.08030"
"31401","188.37000","15.69762","0.08154"
"31436","188.58000","15.71520","0.08212"
"31471","188.79000","15.73266","0.08261"
"31506","189.00000","15.75012","0.08340"
"31541","189.21000","15.76770","0.08480"
"31576","189.42000","15.78515","0.08503"
"31611","189.63000","15.80267","0.07455"
"31646","189.84000","15.82019","0.07534"
"31681","190.05000","15.83765","0.07542"
"31716","190.26000","15.85517","0.07603"
"31751","190.47000","15.87274","0.07568"
"31786","190.68000","15.89014","0.07602"
"31821","190.89000","15.90772","0.07662"
"31856","191.10000","15.92518","0.07762"
"31891","191.31000","15.94270","0.07828"
"31926","191.52000","15.96016","0.07867"
"31961","191.73000","15.97762","0.07907"
"31996","191.94000","15.99520","0.07857"
"32031","192.15000","16.01265","0.07987"
"32066","192.36000","16.03017","0.07824"
"32101","192.57000","16.04769","0.07692"
"32136","192.78000","16.06515","0.07615"
"32171","192.99000","16.08273","0.07713"
"32206","193.20000","16.10019","0.07793"
"32241","193.41000","16.11764","0.07823"
"32276","193.62000","16.13522","0.07832"
"32311","193.83000","16.15262","0.07928"
"32346","194.04000","16.17014","0.08015"
"32381","194.25000","16.18772","0.08043"
"32416","194.46000","16.20518","0.08141"
"32451","194.67000","16.22269","0.08206"
"32486","194.88000","16.24015","0.08274"
"32521","195.09000","16.25767","0.08328"
"32556","195.30000","16.27519","0.08355"
"32591","195.51000","16.29265","0.08421"
"32626","195.72000","16.31017","0.08501"
"32661","195.93000","16.32768","0.08534"
"32696","196.14000","16.34520","0.08569"
"32731","196.35000","16.36272","0.08555"
"32766","196.56000","16.38012","0.08589"
"32801","196.77000","16.39770","0.08666"
"32836","196.98000","16.41516","0.08690"
"32871","197.19000","16.43267","0.08717"
"32906","197.40000","16.45019","0.08724"
"32941","197.61000","16.46765","0.08766"
"32976","197.82000","16.48523","0.08788"
"33011","198.03000","16.50263","0.08819"
"33046","198.24000","16.52021","0.08812"
"33081","198.45000","16.53766","0.08841"
"33116","198.66000","16.55518","0.08879"
"33151","198.87000","16.57264","0.08690"
"33186","199.08000","16.59016","0.07368"
"33221","199.29000","16.60768","0.07474"
"33256","199.50000","16.62520","0.07505"
"33291","199.71000","16.64266","0.07592"
"33326","199.92000","16.66023","0.07656"
"33361","200.13000","16.67769","0.07609"
"33396","200.34000","16.69509","0.07635"
"33431","200.55000","16.71267","0.07240"
"33466","200.76000","16.73013","0.07366"
"33501","200.97000","16.74771","0.07401"
"33536","201.18000","16.76516","0.07504"
"33571","201.39000","16.78262","0.04080"
"33606","201.60000","16.80026","0.02414"
"33641","201.81000","16.81772","0.02269"
"33676","202.02000","16.83512","0.02236"
"33711","202.23000","16.85275","0.02334"
"33746","202.44000","16.87009","0.02209"
"33781","202.65000","16.88767","0.02254"
"33816","202.86000","16.90519","0.02409"
"33851","203.07000","16.92265","0.02335"
"33886","203.28000","16.94017","0.02387"
"33921","203.49000","16.95763","0.02455"
"33956","203.70000","16.97515","0.02504"
"33991","203.91000","16.99266","0.02491"
"34026","204.12000","17.01018","0.02501"
"34061","204.33000","17.02764","0.02575"
"34096","204.54000","17.04516","0.02442"
"34131","204.75000","17.06268","0.02474"
"34166","204.96000","17.08019","0.02673"
"34201","205.17000","17.09759","0.02667"
"34236","205.38000","17.11523","0.02634"
"34271","205.59000","17.13263","0.02726"
"34306","205.80000","17.15021","0.02798"
"34341","206.01000","17.16773","0.02808"
"34376","206.22000","17.18513","0.02860"
"34411","206.43000","17.20270","0.02963"
"34446","206.64000","17.22016","0.02998"
"34481","206.85000","17.23768","0.02948"
"34516","207.06000","17.25520","0.01601"
"34551","207.27000","17.27266","0.01188"
"34586","207.48000","17.29012","0.04492"
"34621","207.69000","17.30775","0.01691"
"34656","207.90000","17.32515","0.03800"
"34691","208.11000","17.34273","0.00941"
"34726","208.32000","17.36013","0.01256"
"34761","208.53000","17.37771","0.01976"
"34796","208.74000","17.39517","0.02537"
"34831","208.95000","17.41262","0.01138"
"34866","209.16000","17.43014","0.00806"
"34901","209.37000","17.44766","0.01337"
"34936","209.58000","17.46518","0.02422"
"34971","209.79000","17.48270","0.01014"
"35006","210.00000","17.50010","0.00787"
"35041","210.21000","17.51773","0.00784"
"35076","210.42000","17.53519","-0.00377"
"35111","210.63000","17.55265","0.02228"
"35146","210.84000","17.57017","0.01456"
"35181","211.05000","17.58763","0.01335"
"35216","211.26000","17.60521","0.01163"
"35251","211.47000","17.62267","0.01306"
"35286","211.68000","17.64018","0.01450"
"35321","211.89000","17.65770","0.01294"
"35356","212.10000","17.67516","0.01410"
"35391","212.31000","17.69268","0.01450"
"35426","212.52000","17.71014","0.01337"
"35461","212.73000","17.72766","0.01303"
"35496","212.94000","17.74512","0.01380"
"35531","213.15000","17.76263","0.01329"
"35566","213.36000","17.78015","0.01469"
"35601","213.57000","17.79767","0.01553"
"35636","213.78000","17.81507","0.01413"
"35671","213.99000","17.83271","0.01470"
"35706","214.20000","17.85016","0.01419"
"35741","214.41000","17.86768","0.01419"
"35776","214.62000","17.88520","0.01489"
"35811","214.83000","17.90266","0.01374"
"35846","215.04000","17.92018","0.01469"
"35881","215.25000","17.93764","0.01456"
"35916","215.46000","17.95516","0.01513"
"35951","215.67000","17.97267","0.01504"
"35986","215.88000","17.99013","0.01452"
"36021","216.09000","18.00771","0.01522"
"36056","216.30000","18.02523","0.01513"
"36091","216.51000","18.04263","0.01563"
"36126","216.72000","18.06021","0.01489"
"36161","216.93000","18.07760","0.01505"
"36196","217.14000","18.09518","0.01549"
"36231","217.35000","18.11270","0.01576"
"36266","217.56000","18.13010","0.01564"
"36301","217.77000","18.14768","0.01587"
"36336","217.98000","18.16514","0.01541"
"36371","218.19000","18.18271","0.01568"
"36406","218.40000","18.20017","0.01589"
"36441","218.61000","18.21763","0.01595"
"36476","218.82000","18.23521","0.01558"
"36511","219.03000","18.25273","0.01698"
"36546","219.24000","18.27013","0.01675"
"36581","219.45000","18.28770","0.01673"
"36616","219.66000","18.30510","0.01659"
"36651","219.87000","18.32268","0.01616"
"36686","220.08000","18.34020","0.01592"
"36721","220.29000","18.35766","0.01660"
"36756","220.50000","18.37518","0.01710"
"36791","220.71000","18.39269","0.01677"
"36826","220.92000","18.41021","0.01705"
"36861","221.13000","18.42767","0.01710"
"36896","221.34000","18.44519","0.01758"
"36931","221.55000","18.46265","0.01788"
"36966","221.76000","18.48017","0.01724"
"37001","221.97000","18.49768","0.01750"
"37036","222.18000","18.51521","0.01722"
"37071","222.39000","18.53266","0.01739"
"37106","222.60000","18.55018","0.01758"
"37141","222.81000","18.56770","0.01819"
"37176","223.02000","18.58516","0.01786"
"37211","223.23000","18.60268","0.01787"
"37246","223.44000","18.62013","0.01853"
"37281","223.65000","18.63771","0.01784"
"37316","223.86000","18.65517","0.01785"
"37351","224.07000","18.67263","0.01830"
"37386","224.28000","18.69021","0.01864"
"37421","224.49000","18.70767","0.01823"
"37456","224.70000","18.72512","0.01855"
"37491","224.91000","18.74270","0.01866"
"37526","225.12000","18.76016","0.01869"
"37561","225.33000","18.77774","0.01835"
"37596","225.54000","18.79514","0.01890"
"37631","225.75000","18.81278","0.01899"
"37666","225.96000","18.83018","0.01931"
"37701","226.17000","18.84757","0.01936"
"37736","226.38000","18.86515","0.01940"
"37771","226.59000","18.88261","0.01997"
"37806","226.80000","18.90019","0.01946"
"37841","227.01000","18.91771","0.01955"
"37876","227.22000","18.93517","0.02044"
"37911","227.43000","18.95268","0.02037"
"37946","227.64000","18.97014","0.01996"
"37981","227.85000","18.98766","0.01993"
"38016","228.06000","19.00518","0.02067"
"38051","228.27000","19.02264","0.02065"
"38086","228.48000","19.04022","0.02082"
"38121","228.69000","19.05767","0.02071"
"38156","228.90000","19.07513","0.02052"
"38191","229.11000","19.09271","0.02097"
"38226","229.32000","19.11017","0.02090"
"38261","229.53000","19.12769","0.02099"
"38296","229.74000","19.14521","0.02140"
"38331","229.95000","19.16266","0.02142"
"38366","230.16000","19.18018","0.02111"
"38401","230.37000","19.19764","0.02209"
"38436","230.58000","19.21516","0.02178"
"38471","230.79000","19.23274","0.02186"
"38506","231.00000","19.25008","0.02230"
"38541","231.21000","19.26772","0.02212"
"38576","231.42000","19.28517","0.02188"
"38611","231.63000","19.30263","0.02276"
"38646","231.84000","19.32021","0.02273"
"38681","232.05000","19.33767","0.02292"
"38716","232.26000","19.35519","0.02279"
"38751","232.47000","19.37265","0.02219"
"38786","232.68000","19.39016","0.02250"
"38821","232.89000","19.40768","0.02326"
"38856","233.10000","19.42514","0.02304"
"38891","233.31000","19.44266","0.02331"
"38926","233.52000","19.46024","0.02371"
"38961","233.73000","19.47764","0.02385"
"38996","233.94000","19.49521","0.02368"
"39031","234.15000","19.51261","0.02357"
"39066","234.36000","19.53019","0.02400"
"39101","234.57000","19.54765","0.02464"
"39136","234.78000","19.56511","0.02436"
"39171","234.99000","19.58269","0.02531"
"39206","235.20000","19.60015","0.02529"
"39241","235.41000","19.61766","0.02480"
"39276","235.62000","19.63518","0.02521"
"39311","235.83000","19.65264","0.02504"
"39346","236.04000","19.67016","0.02505"
"39381","236.25000","19.68768","0.02582"
"39416","236.46000","19.70514","0.02626"
"39451","236.67000","19.72271","0.02605"
"39486","236.88000","19.74011","0.02653"
"39521","237.09000","19.75769","0.02698"
"39556","237.30000","19.77515","0.02678"
"39591","237.51000","19.79267","0.02739"
"39626","237.72000","19.81025","0.02751"
"39661","237.93000","19.82764","0.02770"
"39696","238.14000","19.84516","0.02805"
"39731","238.35000","19.86268","0.02832"
"39766","238.56000","19.88020","0.02802"
"39801","238.77000","19.89766","0.02873"
"39836","238.98000","19.91512","0.02923"
"39871","239.19000","19.93270","0.02923"
"39906","239.40000","19.95015","0.02990"
"39941","239.61000","19.96761","0.02948"
"39976","239.82000","19.98525","0.03008"
"40011","240.03000","20.00265","0.03032"
"40046","240.24000","20.02017","0.03058"
"40081","240.45000","20.03774","0.03097"
"40116","240.66000","20.05514","0.03087"
"40151","240.87000","20.07272","0.03135"
"40186","241.08000","20.09012","0.03193"
"40221","241.29000","20.10770","0.03237"
"40256","241.50000","20.12516","0.03268"
"40291","241.71000","20.14267","0.03325"
"40326","241.92000","20.16014","0.03287"
"40361","242.13000","20.17771","0.03349"
"40396","242.34000","20.19511","0.03380"
"40431","242.55000","20.21269","0.03414"
"40466","242.76000","20.23021","0.03461"
"40501","242.97000","20.24773","0.03476"
"40536","243.18000","20.26518","0.03438"
"40571","243.39000","20.28258","0.03490"
"40606","243.60000","20.30016","0.03532"
"40641","243.81000","20.31762","0.03614"
"40676","244.02000","20.33520","0.03625"
"40711","244.23000","20.35272","0.03680"
"40746","244.44000","20.37011","0.03668"
"40781","244.65000","20.38769","0.03724"
"40816","244.86000","20.40521","0.03763"
"40851","245.07000","20.42261","0.03792"
"40886","245.28000","20.44019","0.03765"
"40921","245.49000","20.45758","0.03825"
"40956","245.70000","20.47522","0.03860"
"40991","245.91000","20.49268","0.03892"
"41026","246.12000","20.51014","0.03916"
"41061","246.33000","20.52772","0.03947"
"41096","246.54000","20.54518","0.03963"
"41131","246.75000","20.56270","0.03996"
"41166","246.96000","20.58015","0.04009"
"41201","247.17000","20.59767","0.04026"
"41236","247.38000","20.61513","0.04027"
"41271","247.59000","20.63271","0.04078"
"41306","247.80000","20.65017","0.04065"
"41341","248.01000","20.66769","0.04123"
"41376","248.22000","20.68514","0.04140"
"41411","248.43000","20.70272","0.04138"
"41446","248.64000","20.72018","0.04168"
"41481","248.85000","20.73770","0.04170"
"41516","249.06000","20.75522","0.04230"
"41551","249.27000","20.77262","0.04218"
"41586","249.48000","20.79020","0.04285"
"41621","249.69000","20.80766","0.04278"
"41656","249.90000","20.82517","0.04317"
"41691","250.11000","20.84263","0.04390"
"41726","250.32000","20.86015","0.04399"
"41761","250.53000","20.87767","0.04438"
"41796","250.74000","20.89519","0.04478"
"41831","250.95000","20.91265","0.04510"
"41866","251.16000","20.93022","0.04632"
"41901","251.37000","20.94762","0.04639"
"41936","251.58000","20.96526","0.04748"
"41971","251.79000","20.98266","0.04821"
"42006","252.00000","21.00011","0.04880"
"42041","252.21000","21.01769","0.04920"
"42076","252.42000","21.03521","0.05002"
"42111","252.63000","21.05273","0.05066"
"42146","252.84000","21.07019","0.05198"
"42181","253.05000","21.08765","0.05397"
"42216","253.26000","21.10517","0.05420"
"42251","253.47000","21.12269","0.05487"
"42286","253.68000","21.14008","0.05530"
"42321","253.89000","21.15772","0.05727"
"42356","254.10000","21.17512","0.05810"
"42391","254.31000","21.19270","0.05981"
"42426","254.52000","21.21016","0.05968"
"42461","254.73000","21.22762","0.06061"
"42496","254.94000","21.24519","0.06174"
"42531","255.15000","21.26265","0.06227"
"42566","255.36000","21.28017","0.06322"
"42601","255.57000","21.29769","0.06433"
"42636","255.78000","21.31515","0.06490"
"42671","255.99000","21.33267","0.06557"
"42706","256.20000","21.35012","0.06651"
"42741","256.41000","21.36770","0.06758"
"42776","256.62000","21.38516","0.06835"
"42811","256.83000","21.40262","0.06883"
"42846","257.04000","21.42026","0.06977"
"42881","257.25000","21.43766","0.07055"
"42916","257.46000","21.45518","0.07134"
"42951","257.67000","21.47269","0.07188"
"42986","257.88000","21.49015","0.07286"
"43021","258.09000","21.50773","0.07329"
"43056","258.30000","21.52513","0.07437"
"43091","258.51000","21.54265","0.07519"
"43092","258.51400","21.54295","0.07528"