File: Trajectories_together/170108_2Specimen_RawData_5.csv
"","V1","V2","V3"
"1","End date","1/8/2017",""
"2","Specimen label","13DG_5",""
"3","Maximum Load","0.54248","N"
"4","Time","Extension","Load"
"5","(s)","(mm)","(N)"
"6","0.00000","0.00000","0.00040"
"58","0.31200","0.02565","0.00072"
"110","0.62400","0.05220","0.00195"
"162","0.93600","0.07826","0.00251"
"214","1.24800","0.10427","0.00236"
"266","1.56000","0.13028","0.00284"
"318","1.87200","0.15629","0.00364"
"370","2.18400","0.18218","0.00432"
"422","2.49600","0.20825","0.00399"
"474","2.80800","0.23414","0.00406"
"526","3.12000","0.26026","0.00471"
"578","3.43200","0.28627","0.00496"
"630","3.74400","0.31222","0.00525"
"682","4.05600","0.33829","0.00514"
"734","4.36800","0.36424","0.00570"
"786","4.68000","0.39025","0.00558"
"838","4.99200","0.41619","0.00630"
"890","5.30400","0.44226","0.00495"
"942","5.61600","0.46821","0.00611"
"994","5.92800","0.49416","0.00599"
"1046","6.24000","0.52023","0.00675"
"1098","6.55200","0.54618","0.00667"
"1150","6.86400","0.57225","0.00669"
"1202","7.17600","0.59819","0.00725"
"1254","7.48800","0.62420","0.00709"
"1306","7.80000","0.65027","0.00721"
"1358","8.11200","0.67622","0.00744"
"1410","8.42400","0.70223","0.00778"
"1462","8.73600","0.72824","0.00760"
"1514","9.04800","0.75424","0.00741"
"1566","9.36000","0.78019","0.00767"
"1618","9.67200","0.80614","0.00778"
"1670","9.98400","0.83221","0.00787"
"1722","10.29600","0.85822","0.00842"
"1774","10.60800","0.88429","0.00817"
"1826","10.92000","0.91018","0.00853"
"1878","11.23200","0.93624","0.00828"
"1930","11.54400","0.96225","0.00899"
"1982","11.85600","0.98820","0.00858"
"2034","12.16800","1.01427","0.00877"
"2086","12.48000","1.04022","0.00867"
"2138","12.79200","1.06623","0.00847"
"2190","13.10400","1.09218","0.00865"
"2242","13.41600","1.11818","0.00873"
"2294","13.72800","1.14425","0.00913"
"2346","14.04000","1.17020","0.00913"
"2398","14.35200","1.19627","0.00889"
"2450","14.66400","1.22216","0.00942"
"2502","14.97600","1.24823","0.00902"
"2554","15.28800","1.27423","0.00938"
"2606","15.60000","1.30024","0.00965"
"2658","15.91200","1.32631","0.00976"
"2710","16.22400","1.35226","0.00915"
"2762","16.53600","1.37821","0.00958"
"2814","16.84800","1.40422","0.00952"
"2866","17.16000","1.43023","0.00995"
"2918","17.47200","1.45623","0.01000"
"2970","17.78400","1.48218","0.00975"
"3022","18.09600","1.50825","0.00958"
"3074","18.40800","1.53420","0.00961"
"3126","18.72000","1.56027","0.00982"
"3178","19.03200","1.58622","0.00993"
"3230","19.34400","1.61222","0.01014"
"3282","19.65600","1.63829","0.01009"
"3334","19.96800","1.66418","0.01004"
"3386","20.28000","1.69019","0.01024"
"3438","20.59200","1.71620","0.00987"
"3490","20.90400","1.74221","0.01021"
"3542","21.21600","1.76828","0.01020"
"3594","21.52800","1.79422","0.01052"
"3646","21.84000","1.82023","0.01026"
"3698","22.15200","1.84618","0.01011"
"3750","22.46400","1.87225","0.01019"
"3802","22.77600","1.89826","0.01057"
"3854","23.08800","1.92427","0.01025"
"3906","23.40000","1.95022","0.01049"
"3958","23.71200","1.97622","0.01069"
"4010","24.02400","2.00223","0.01114"
"4062","24.33600","2.02818","0.01059"
"4114","24.64800","2.05425","0.01081"
"4166","24.96000","2.08020","0.01047"
"4218","25.27200","2.10621","0.01066"
"4270","25.58400","2.13227","0.01072"
"4322","25.89600","2.15816","0.01114"
"4374","26.20800","2.18417","0.01066"
"4426","26.52000","2.21018","0.01042"
"4478","26.83200","2.23625","0.01076"
"4530","27.14400","2.26226","0.01136"
"4582","27.45600","2.28821","0.01094"
"4634","27.76800","2.31421","0.01082"
"4686","28.08000","2.34016","0.01069"
"4738","28.39200","2.36623","0.01133"
"4790","28.70400","2.39218","0.01128"
"4842","29.01600","2.41825","0.01107"
"4894","29.32800","2.44426","0.01091"
"4946","29.64000","2.47014","0.01122"
"4998","29.95200","2.49627","0.01147"
"5050","30.26400","2.52222","0.01162"
"5102","30.57600","2.54823","0.01106"
"5154","30.88800","2.57418","0.01118"
"5206","31.20000","2.60019","0.01095"
"5258","31.51200","2.62626","0.01136"
"5310","31.82400","2.65220","0.01179"
"5362","32.13600","2.67827","0.01144"
"5414","32.44800","2.70422","0.01136"
"5466","32.76000","2.73023","0.01196"
"5518","33.07200","2.75624","0.01127"
"5570","33.38400","2.78225","0.01169"
"5622","33.69600","2.80825","0.01101"
"5674","34.00800","2.83426","0.01151"
"5726","34.32000","2.86027","0.01108"
"5778","34.63200","2.88622","0.01158"
"5830","34.94400","2.91217","0.01179"
"5882","35.25600","2.93824","0.01155"
"5934","35.56800","2.96425","0.01150"
"5986","35.88000","2.99025","0.01180"
"6038","36.19200","3.01614","0.01168"
"6090","36.50400","3.04227","0.01156"
"6142","36.81600","3.06828","0.01147"
"6194","37.12800","3.09423","0.01195"
"6246","37.44000","3.12030","0.01192"
"6298","37.75200","3.14618","0.01163"
"6350","38.06400","3.17225","0.01214"
"6402","38.37600","3.19814","0.01107"
"6454","38.68800","3.22421","0.01207"
"6506","39.00000","3.25022","0.01157"
"6558","39.31200","3.27617","0.01231"
"6610","39.62400","3.30224","0.01224"
"6662","39.93600","3.32818","0.01187"
"6714","40.24800","3.35425","0.01185"
"6766","40.56000","3.38020","0.01202"
"6818","40.87200","3.40621","0.01237"
"6870","41.18400","3.43228","0.01232"
"6922","41.49600","3.45817","0.01176"
"6974","41.80800","3.48423","0.01230"
"7026","42.12000","3.51012","0.01185"
"7078","42.43200","3.53625","0.01187"
"7130","42.74400","3.56226","0.01230"
"7182","43.05600","3.58827","0.01237"
"7234","43.36800","3.61422","0.01293"
"7286","43.68000","3.64017","0.01266"
"7338","43.99200","3.66623","0.01272"
"7390","44.30400","3.69224","0.01227"
"7442","44.61600","3.71831","0.01186"
"7494","44.92800","3.74426","0.01236"
"7546","45.24000","3.77021","0.01262"
"7598","45.55200","3.79622","0.01193"
"7650","45.86400","3.82211","0.01243"
"7702","46.17600","3.84829","0.01227"
"7754","46.48800","3.87424","0.01198"
"7806","46.80000","3.90025","0.01230"
"7858","47.11200","3.92626","0.01295"
"7910","47.42400","3.95221","0.01252"
"7962","47.73600","3.97828","0.01285"
"8014","48.04800","4.00416","0.01256"
"8066","48.36000","4.03029","0.01267"
"8118","48.67200","4.05624","0.01224"
"8170","48.98400","4.08219","0.01288"
"8222","49.29600","4.10820","0.01251"
"8274","49.60800","4.13421","0.01282"
"8326","49.92000","4.16027","0.01229"
"8378","50.23200","4.18622","0.01278"
"8430","50.54400","4.21223","0.01287"
"8482","50.85600","4.23824","0.01289"
"8534","51.16800","4.26419","0.01230"
"8586","51.48000","4.29026","0.01246"
"8638","51.79200","4.31621","0.01250"
"8690","52.10400","4.34221","0.01231"
"8742","52.41600","4.36822","0.01235"
"8794","52.72800","4.39423","0.01290"
"8846","53.04000","4.42024","0.01230"
"8898","53.35200","4.44619","0.01274"
"8950","53.66400","4.47220","0.01219"
"9002","53.97600","4.49821","0.01297"
"9054","54.28800","4.52421","0.01314"
"9106","54.60000","4.55022","0.01289"
"9158","54.91200","4.57617","0.01313"
"9210","55.22400","4.60224","0.01275"
"9262","55.53600","4.62813","0.01309"
"9314","55.84800","4.65426","0.01286"
"9366","56.16000","4.68015","0.01308"
"9418","56.47200","4.70615","0.01344"
"9470","56.78400","4.73222","0.01307"
"9522","57.09600","4.75823","0.01291"
"9574","57.40800","4.78424","0.01264"
"9626","57.72000","4.81019","0.01269"
"9678","58.03200","4.83626","0.01308"
"9730","58.34400","4.86220","0.01357"
"9782","58.65600","4.88821","0.01301"
"9834","58.96800","4.91428","0.01269"
"9886","59.28000","4.94023","0.01345"
"9938","59.59200","4.96624","0.01298"
"9990","59.90400","4.99219","0.01317"
"10042","60.21600","5.01819","0.01311"
"10094","60.52800","5.04420","0.01309"
"10146","60.84000","5.07015","0.01325"
"10198","61.15200","5.09622","0.01306"
"10250","61.46400","5.12217","0.01340"
"10302","61.77600","5.14824","0.01273"
"10354","62.08800","5.17425","0.01330"
"10406","62.40000","5.20025","0.01313"
"10458","62.71200","5.22626","0.01291"
"10510","63.02400","5.25215","0.01338"
"10562","63.33600","5.27822","0.01287"
"10614","63.64800","5.30417","0.01336"
"10666","63.96000","5.33024","0.01346"
"10718","64.27200","5.35625","0.01381"
"10770","64.58400","5.38219","0.01332"
"10822","64.89600","5.40820","0.01332"
"10874","65.20800","5.43415","0.01372"
"10926","65.52000","5.46028","0.01349"
"10978","65.83200","5.48623","0.01387"
"11030","66.14400","5.51224","0.01310"
"11082","66.45600","5.53824","0.01315"
"11134","66.76800","5.56419","0.01359"
"11186","67.08000","5.59020","0.01302"
"11238","67.39200","5.61615","0.01355"
"11290","67.70400","5.64222","0.01396"
"11342","68.01600","5.66817","0.01374"
"11394","68.32800","5.69424","0.01323"
"11446","68.64000","5.72024","0.01355"
"11498","68.95200","5.74619","0.01336"
"11550","69.26400","5.77220","0.01370"
"11602","69.57600","5.79821","0.01384"
"11654","69.88800","5.82428","0.01384"
"11706","70.20000","5.85029","0.01355"
"11758","70.51200","5.87617","0.01350"
"11810","70.82400","5.90218","0.01391"
"11862","71.13600","5.92813","0.01357"
"11914","71.44800","5.95426","0.01352"
"11966","71.76000","5.98021","0.01381"
"12018","72.07200","6.00628","0.01345"
"12070","72.38400","6.03229","0.01361"
"12122","72.69600","6.05817","0.01330"
"12174","73.00800","6.08430","0.01380"
"12226","73.32000","6.11025","0.01399"
"12278","73.63200","6.13620","0.01377"
"12330","73.94400","6.16215","0.01372"
"12382","74.25600","6.18816","0.01355"
"12434","74.56800","6.21422","0.01347"
"12486","74.88000","6.24023","0.01373"
"12538","75.19200","6.26630","0.01376"
"12590","75.50400","6.29219","0.01347"
"12642","75.81600","6.31826","0.01387"
"12694","76.12800","6.34427","0.01391"
"12746","76.44000","6.37022","0.01365"
"12798","76.75200","6.39628","0.01394"
"12850","77.06400","6.42223","0.01327"
"12902","77.37600","6.44824","0.01383"
"12954","77.68800","6.47419","0.01392"
"13006","78.00000","6.50020","0.01358"
"13058","78.31200","6.52627","0.01397"
"13110","78.62400","6.55228","0.01420"
"13162","78.93600","6.57822","0.01394"
"13214","79.24800","6.60417","0.01368"
"13266","79.56000","6.63024","0.01407"
"13318","79.87200","6.65625","0.01380"
"13370","80.18400","6.68220","0.01405"
"13422","80.49600","6.70827","0.01305"
"13474","80.80800","6.73416","0.01313"
"13526","81.12000","6.76028","0.01252"
"13578","81.43200","6.78623","0.01274"
"13630","81.74400","6.81218","0.01289"
"13682","82.05600","6.83825","0.01263"
"13734","82.36800","6.86420","0.01303"
"13786","82.68000","6.89021","0.01312"
"13838","82.99200","6.91615","0.01278"
"13890","83.30400","6.94222","0.01251"
"13942","83.61600","6.96823","0.01330"
"13994","83.92800","6.99424","0.01316"
"14046","84.24000","7.02025","0.01336"
"14098","84.55200","7.04620","0.01283"
"14150","84.86400","7.07227","0.01336"
"14202","85.17600","7.09821","0.01290"
"14254","85.48800","7.12422","0.01312"
"14306","85.80000","7.15023","0.01321"
"14358","86.11200","7.17624","0.01360"
"14410","86.42400","7.20219","0.01293"
"14462","86.73600","7.22814","0.01386"
"14514","87.04800","7.25420","0.01314"
"14566","87.36000","7.28021","0.01351"
"14618","87.67200","7.30628","0.01312"
"14670","87.98400","7.33229","0.01345"
"14722","88.29600","7.35818","0.01347"
"14774","88.60800","7.38419","0.01457"
"14826","88.92000","7.41014","0.01424"
"14878","89.23200","7.43626","0.01360"
"14930","89.54400","7.46221","0.01359"
"14982","89.85600","7.48822","0.01376"
"15034","90.16800","7.51429","0.01370"
"15086","90.48000","7.54018","0.01407"
"15138","90.79200","7.56625","0.01409"
"15190","91.10400","7.59225","0.01383"
"15242","91.41600","7.61826","0.01405"
"15294","91.72800","7.64421","0.01375"
"15346","92.04000","7.67016","0.01433"
"15398","92.35200","7.69617","0.01419"
"15450","92.66400","7.72218","0.01425"
"15502","92.97600","7.74825","0.01373"
"15554","93.28800","7.77419","0.01418"
"15606","93.60000","7.80020","0.01397"
"15658","93.91200","7.82621","0.01437"
"15710","94.22400","7.85222","0.01407"
"15762","94.53600","7.87829","0.01443"
"15814","94.84800","7.90424","0.01403"
"15866","95.16000","7.93018","0.01465"
"15918","95.47200","7.95625","0.01466"
"15970","95.78400","7.98220","0.01485"
"16022","96.09600","8.00821","0.01411"
"16074","96.40800","8.03416","0.01446"
"16126","96.72000","8.06023","0.01475"
"16178","97.03200","8.08624","0.01451"
"16230","97.34400","8.11218","0.01430"
"16282","97.65600","8.13825","0.01496"
"16334","97.96800","8.16414","0.01442"
"16386","98.28000","8.19027","0.01474"
"16438","98.59200","8.21616","0.01451"
"16490","98.90400","8.24223","0.01398"
"16542","99.21600","8.26818","0.01427"
"16594","99.52800","8.29418","0.01460"
"16646","99.84000","8.32025","0.01429"
"16698","100.15200","8.34620","0.01429"
"16750","100.46400","8.37221","0.01420"
"16802","100.77600","8.39822","0.01485"
"16854","101.08800","8.42422","0.01467"
"16906","101.40000","8.45023","0.01432"
"16958","101.71200","8.47624","0.01472"
"17010","102.02400","8.50231","0.01452"
"17062","102.33600","8.52820","0.01478"
"17114","102.64800","8.55421","0.01439"
"17166","102.96000","8.58016","0.01482"
"17218","103.27200","8.60623","0.01443"
"17270","103.58400","8.63229","0.01481"
"17322","103.89600","8.65824","0.01466"
"17374","104.20800","8.68425","0.01513"
"17426","104.52000","8.71020","0.01505"
"17478","104.83200","8.73621","0.01453"
"17530","105.14400","8.76222","0.01431"
"17582","105.45600","8.78828","0.01530"
"17634","105.76800","8.81429","0.01493"
"17686","106.08000","8.84018","0.01540"
"17738","106.39200","8.86619","0.01506"
"17790","106.70400","8.89214","0.01462"
"17842","107.01600","8.91821","0.01506"
"17894","107.32800","8.94427","0.01446"
"17946","107.64000","8.97022","0.01508"
"17998","107.95200","8.99623","0.01463"
"18050","108.26400","9.02218","0.01547"
"18102","108.57600","9.04825","0.01472"
"18154","108.88800","9.07420","0.01501"
"18206","109.20000","9.10027","0.01606"
"18258","109.51200","9.12621","0.01554"
"18310","109.82400","9.15222","0.01541"
"18362","110.13600","9.17823","0.01504"
"18414","110.44800","9.20418","0.01581"
"18466","110.76000","9.23025","0.01387"
"18518","111.07200","9.25620","0.01396"
"18570","111.38400","9.28221","0.01387"
"18622","111.69600","9.30821","0.01408"
"18674","112.00800","9.33422","0.01412"
"18726","112.32000","9.36023","0.01487"
"18778","112.63200","9.38618","0.01387"
"18830","112.94400","9.41219","0.01429"
"18882","113.25600","9.43826","0.01431"
"18934","113.56800","9.46420","0.01405"
"18986","113.88000","9.49021","0.01440"
"19038","114.19200","9.51616","0.01468"
"19090","114.50400","9.54223","0.01427"
"19142","114.81600","9.56818","0.01457"
"19194","115.12800","9.59419","0.01491"
"19246","115.44000","9.62026","0.01452"
"19298","115.75200","9.64620","0.01442"
"19350","116.06400","9.67227","0.01486"
"19402","116.37600","9.69822","0.01456"
"19454","116.68800","9.72423","0.01489"
"19506","117.00000","9.75018","0.01460"
"19558","117.31200","9.77619","0.01478"
"19610","117.62400","9.80225","0.01423"
"19662","117.93600","9.82820","0.01432"
"19714","118.24800","9.85427","0.01436"
"19766","118.56000","9.88022","0.01493"
"19818","118.87200","9.90623","0.01449"
"19870","119.18400","9.93224","0.01543"
"19922","119.49600","9.95825","0.01487"
"19974","119.80800","9.98425","0.01503"
"20026","120.12000","10.01020","0.01518"
"20078","120.43200","10.03627","0.01530"
"20130","120.74400","10.06222","0.01512"
"20182","121.05600","10.08817","0.01511"
"20234","121.36800","10.11424","0.01451"
"20286","121.68000","10.14019","0.01514"
"20338","121.99200","10.16619","0.01546"
"20390","122.30400","10.19214","0.01496"
"20442","122.61600","10.21821","0.01494"
"20494","122.92800","10.24422","0.01535"
"20546","123.24000","10.27023","0.01559"
"20598","123.55200","10.29630","0.01520"
"20650","123.86400","10.32218","0.01559"
"20702","124.17600","10.34825","0.01623"
"20754","124.48800","10.37420","0.01565"
"20806","124.80000","10.40021","0.01532"
"20858","125.11200","10.42622","0.01564"
"20910","125.42400","10.45217","0.01524"
"20962","125.73600","10.47824","0.01612"
"21014","126.04800","10.50418","0.01563"
"21066","126.36000","10.53025","0.01550"
"21118","126.67200","10.55626","0.01571"
"21170","126.98400","10.58221","0.01633"
"21222","127.29600","10.60828","0.01518"
"21274","127.60800","10.63417","0.01621"
"21326","127.92000","10.66023","0.01578"
"21378","128.23200","10.68618","0.01630"
"21430","128.54400","10.71219","0.01585"
"21482","128.85600","10.73820","0.01613"
"21534","129.16800","10.76421","0.01691"
"21586","129.48000","10.79022","0.01650"
"21638","129.79200","10.81617","0.01654"
"21690","130.10400","10.84223","0.01620"
"21742","130.41600","10.86824","0.01631"
"21794","130.72800","10.89425","0.01688"
"21846","131.04000","10.92026","0.01637"
"21898","131.35200","10.94615","0.01640"
"21950","131.66400","10.97222","0.01625"
"22002","131.97600","10.99817","0.01642"
"22054","132.28800","11.02429","0.01624"
"22106","132.60000","11.05024","0.01729"
"22158","132.91200","11.07625","0.01691"
"22210","133.22400","11.10226","0.01727"
"22262","133.53600","11.12821","0.01711"
"22314","133.84800","11.15427","0.01749"
"22366","134.16000","11.18022","0.01694"
"22418","134.47200","11.20623","0.01731"
"22470","134.78400","11.23224","0.01718"
"22522","135.09600","11.25819","0.01746"
"22574","135.40800","11.28420","0.01758"
"22626","135.72000","11.31021","0.01805"
"22678","136.03200","11.33627","0.01715"
"22730","136.34400","11.36216","0.01797"
"22782","136.65600","11.38823","0.01741"
"22834","136.96800","11.41424","0.01781"
"22886","137.28000","11.44019","0.01761"
"22938","137.59200","11.46626","0.01830"
"22990","137.90400","11.49221","0.01810"
"23042","138.21600","11.51822","0.01816"
"23094","138.52800","11.54422","0.01817"
"23146","138.84000","11.57017","0.01871"
"23198","139.15200","11.59624","0.01834"
"23250","139.46400","11.62219","0.01865"
"23302","139.77600","11.64820","0.01831"
"23354","140.08800","11.67420","0.01896"
"23406","140.40000","11.70021","0.01713"
"23458","140.71200","11.72628","0.01763"
"23510","141.02400","11.75217","0.01737"
"23562","141.33600","11.77830","0.01687"
"23614","141.64800","11.80419","0.01787"
"23666","141.96000","11.83026","0.01814"
"23718","142.27200","11.85620","0.01811"
"23770","142.58400","11.88221","0.01800"
"23822","142.89600","11.90828","0.01819"
"23874","143.20800","11.93417","0.01812"
"23926","143.52000","11.96024","0.01858"
"23978","143.83200","11.98619","0.01853"
"24030","144.14400","12.01225","0.01935"
"24082","144.45600","12.03821","0.01879"
"24134","144.76800","12.06421","0.01935"
"24186","145.08000","12.09028","0.01890"
"24238","145.39200","12.11617","0.01916"
"24290","145.70400","12.14224","0.01974"
"24342","146.01600","12.16825","0.01990"
"24394","146.32800","12.19425","0.01928"
"24446","146.64000","12.22026","0.01987"
"24498","146.95200","12.24621","0.01947"
"24550","147.26400","12.27222","0.02044"
"24602","147.57600","12.29817","0.02038"
"24654","147.88800","12.32424","0.01996"
"24706","148.20000","12.35025","0.02063"
"24758","148.51200","12.37625","0.02025"
"24810","148.82400","12.40226","0.02014"
"24862","149.13600","12.42815","0.02024"
"24914","149.44800","12.45422","0.02037"
"24966","149.76000","12.48017","0.02063"
"25018","150.07200","12.50624","0.01993"
"25070","150.38400","12.53224","0.02121"
"25122","150.69600","12.55819","0.02109"
"25174","151.00800","12.58420","0.02138"
"25226","151.32000","12.61015","0.02136"
"25278","151.63200","12.63628","0.02138"
"25330","151.94400","12.66223","0.02151"
"25382","152.25600","12.68824","0.02242"
"25434","152.56800","12.71424","0.02207"
"25486","152.88000","12.74019","0.02247"
"25538","153.19200","12.76620","0.02123"
"25590","153.50400","12.79221","0.02125"
"25642","153.81600","12.81822","0.02171"
"25694","154.12800","12.84417","0.02241"
"25746","154.44000","12.87017","0.02193"
"25798","154.75200","12.89624","0.02215"
"25850","155.06400","12.92219","0.02241"
"25902","155.37600","12.94826","0.02272"
"25954","155.68800","12.97427","0.02273"
"26006","156.00000","13.00022","0.02262"
"26058","156.31200","13.02623","0.02261"
"26110","156.62400","13.05217","0.02262"
"26162","156.93600","13.07824","0.02237"
"26214","157.24800","13.10419","0.02265"
"26266","157.56000","13.13020","0.02289"
"26318","157.87200","13.15621","0.02347"
"26370","158.18400","13.18222","0.02364"
"26422","158.49600","13.20823","0.02356"
"26474","158.80800","13.23417","0.02343"
"26526","159.12000","13.26030","0.02358"
"26578","159.43200","13.28619","0.02470"
"26630","159.74400","13.31220","0.02399"
"26682","160.05600","13.33815","0.02456"
"26734","160.36800","13.36416","0.02463"
"26786","160.68000","13.39023","0.02488"
"26838","160.99200","13.41623","0.02543"
"26890","161.30400","13.44230","0.02603"
"26942","161.61600","13.46819","0.02612"
"26994","161.92800","13.49426","0.02666"
"27046","162.24000","13.52027","0.02684"
"27098","162.55200","13.54622","0.02710"
"27150","162.86400","13.57222","0.02719"
"27202","163.17600","13.59817","0.02732"
"27254","163.48800","13.62424","0.02736"
"27306","163.80000","13.65019","0.02829"
"27358","164.11200","13.67620","0.02825"
"27410","164.42400","13.70227","0.02862"
"27462","164.73600","13.72827","0.02904"
"27514","165.04800","13.75422","0.02912"
"27566","165.36000","13.78023","0.02947"
"27618","165.67200","13.80624","0.02967"
"27670","165.98400","13.83225","0.03008"
"27722","166.29600","13.85826","0.02979"
"27774","166.60800","13.88426","0.03017"
"27826","166.92000","13.91015","0.02831"
"27878","167.23200","13.93622","0.02868"
"27930","167.54400","13.96223","0.02937"
"27982","167.85600","13.98824","0.02928"
"28034","168.16800","14.01425","0.02965"
"28086","168.48000","14.04014","0.02962"
"28138","168.79200","14.06621","0.02986"
"28190","169.10400","14.09221","0.03040"
"28242","169.41600","14.11822","0.03062"
"28294","169.72800","14.14423","0.03045"
"28346","170.04000","14.17024","0.03116"
"28398","170.35200","14.19625","0.03096"
"28450","170.66400","14.22220","0.03110"
"28502","170.97600","14.24821","0.03183"
"28554","171.28800","14.27415","0.03180"
"28606","171.60000","14.30022","0.03225"
"28658","171.91200","14.32623","0.03279"
"28710","172.22400","14.35218","0.03238"
"28762","172.53600","14.37825","0.03316"
"28814","172.84800","14.40420","0.03404"
"28866","173.16000","14.43020","0.03440"
"28918","173.47200","14.45621","0.03472"
"28970","173.78400","14.48228","0.03335"
"29022","174.09600","14.50823","0.03339"
"29074","174.40800","14.53418","0.03440"
"29126","174.72000","14.56019","0.03522"
"29178","175.03200","14.58619","0.03483"
"29230","175.34400","14.61232","0.03556"
"29282","175.65600","14.63827","0.03691"
"29334","175.96800","14.66422","0.03859"
"29386","176.28000","14.69023","0.03951"
"29438","176.59200","14.71618","0.04067"
"29490","176.90400","14.74224","0.04175"
"29542","177.21600","14.76820","0.04270"
"29594","177.52800","14.79426","0.04400"
"29646","177.84000","14.82021","0.04633"
"29698","178.15200","14.84622","0.04602"
"29750","178.46400","14.87223","0.04748"
"29802","178.77600","14.89818","0.05022"
"29854","179.08800","14.92430","0.05122"
"29906","179.40000","14.95019","0.05207"
"29958","179.71200","14.97620","0.05378"
"30010","180.02400","15.00221","0.05545"
"30062","180.33600","15.02822","0.05627"
"30114","180.64800","15.05423","0.05786"
"30166","180.96000","15.08024","0.05930"
"30218","181.27200","15.10624","0.06072"
"30270","181.58400","15.13219","0.06249"
"30322","181.89600","15.15820","0.06299"
"30374","182.20800","15.18427","0.06479"
"30426","182.52000","15.21016","0.06568"
"30478","182.83200","15.23623","0.06727"
"30530","183.14400","15.26218","0.06937"
"30582","183.45600","15.28818","0.07031"
"30634","183.76800","15.31425","0.07190"
"30686","184.08000","15.34020","0.07291"
"30738","184.39200","15.36627","0.07445"
"30790","184.70400","15.39216","0.07505"
"30842","185.01600","15.41823","0.07617"
"30894","185.32800","15.44417","0.07700"
"30946","185.64000","15.47018","0.07749"
"30998","185.95200","15.49625","0.07840"
"31050","186.26400","15.52214","0.07897"
"31102","186.57600","15.54827","0.07930"
"31154","186.88800","15.57416","0.07972"
"31206","187.20000","15.60023","0.08093"
"31258","187.51200","15.62623","0.08314"
"31310","187.82400","15.65224","0.08518"
"31362","188.13600","15.67825","0.08714"
"31414","188.44800","15.70420","0.08575"
"31466","188.76000","15.73021","0.08954"
"31518","189.07200","15.75622","0.09316"
"31570","189.38400","15.78222","0.09729"
"31622","189.69600","15.80823","0.10217"
"31674","190.00800","15.83424","0.10707"
"31726","190.32000","15.86025","0.11003"
"31778","190.63200","15.88620","0.11567"
"31830","190.94400","15.91227","0.11946"
"31882","191.25600","15.93827","0.12113"
"31934","191.56800","15.96422","0.12065"
"31986","191.88000","15.99023","0.12618"
"32038","192.19200","16.01618","0.13161"
"32090","192.50400","16.04225","0.13536"
"32142","192.81600","16.06820","0.13735"
"32194","193.12800","16.09426","0.13854"
"32246","193.44000","16.12027","0.13978"
"32298","193.75200","16.14622","0.14153"
"32350","194.06400","16.17223","0.14210"
"32402","194.37600","16.19812","0.14487"
"32454","194.68800","16.22431","0.14893"
"32506","195.00000","16.25026","0.15333"
"32558","195.31200","16.27621","0.15632"
"32610","195.62400","16.30221","0.15963"
"32662","195.93600","16.32816","0.16330"
"32714","196.24800","16.35423","0.16804"
"32766","196.56000","16.38024","0.17182"
"32818","196.87200","16.40625","0.17511"
"32870","197.18400","16.43220","0.17792"
"32922","197.49600","16.45826","0.18024"
"32974","197.80800","16.48427","0.18255"
"33026","198.12000","16.51022","0.18532"
"33078","198.43200","16.53623","0.18750"
"33130","198.74400","16.56218","0.18955"
"33182","199.05600","16.58819","0.19164"
"33234","199.36800","16.61425","0.19442"
"33286","199.68000","16.64014","0.19833"
"33338","199.99200","16.66621","0.20340"
"33390","200.30400","16.69222","0.20788"
"33442","200.61600","16.71823","0.21176"
"33494","200.92800","16.74424","0.21579"
"33546","201.24000","16.77024","0.22012"
"33598","201.55200","16.79626","0.22464"
"33650","201.86400","16.82220","0.22749"
"33702","202.17600","16.84827","0.23050"
"33754","202.48800","16.87422","0.23260"
"33806","202.80000","16.90023","0.23683"
"33858","203.11200","16.92618","0.24318"
"33910","203.42400","16.95219","0.25087"
"33962","203.73600","16.97825","0.25749"
"34014","204.04800","17.00420","0.26315"
"34066","204.36000","17.03027","0.26832"
"34118","204.67200","17.05622","0.27513"
"34170","204.98400","17.08223","0.28076"
"34222","205.29600","17.10824","0.28602"
"34274","205.60800","17.13419","0.28948"
"34326","205.92000","17.16025","0.29122"
"34378","206.23200","17.18620","0.29186"
"34430","206.54400","17.21221","0.29224"
"34482","206.85600","17.23822","0.29296"
"34534","207.16800","17.26423","0.29508"
"34586","207.48000","17.29024","0.29723"
"34638","207.79200","17.31618","0.30138"
"34690","208.10400","17.34225","0.30652"
"34742","208.41600","17.36820","0.31127"
"34794","208.72800","17.39421","0.31727"
"34846","209.04000","17.42028","0.32422"
"34898","209.35200","17.44617","0.33141"
"34950","209.66400","17.47223","0.33731"
"35002","209.97600","17.49813","0.34160"
"35054","210.28800","17.52425","0.34411"
"35106","210.60000","17.55020","0.34635"
"35158","210.91200","17.57627","0.34742"
"35210","211.22400","17.60228","0.34849"
"35262","211.53600","17.62817","0.35010"
"35314","211.84800","17.65423","0.35651"
"35366","212.16000","17.68012","0.36324"
"35418","212.47200","17.70625","0.36697"
"35470","212.78400","17.73220","0.37065"
"35522","213.09600","17.75821","0.37384"
"35574","213.40800","17.78422","0.37708"
"35626","213.72000","17.81017","0.38037"
"35678","214.03200","17.83623","0.38355"
"35730","214.34400","17.86218","0.38687"
"35782","214.65600","17.88825","0.39054"
"35834","214.96800","17.91420","0.39432"
"35886","215.28000","17.94015","0.39781"
"35938","215.59200","17.96622","0.40252"
"35990","215.90400","17.99216","0.40781"
"36042","216.21600","18.01823","0.41353"
"36094","216.52800","18.04424","0.41977"
"36146","216.84000","18.07025","0.42636"
"36198","217.15200","18.09626","0.43185"
"36250","217.46400","18.12215","0.43689"
"36302","217.77600","18.14822","0.43928"
"36354","218.08800","18.17416","0.44052"
"36406","218.40000","18.20023","0.44151"
"36458","218.71200","18.22624","0.44485"
"36510","219.02400","18.25219","0.44843"
"36562","219.33600","18.27826","0.45529"
"36614","219.64800","18.30415","0.46356"
"36666","219.96000","18.33027","0.47050"
"36718","220.27200","18.35616","0.47757"
"36770","220.58400","18.38223","0.48341"
"36822","220.89600","18.40824","0.48830"
"36874","221.20800","18.43419","0.49212"
"36926","221.52000","18.46026","0.49631"
"36978","221.83200","18.48621","0.49857"
"37030","222.14400","18.51228","0.50052"
"37082","222.45600","18.53822","0.50251"
"37134","222.76800","18.56417","0.50411"
"37186","223.08000","18.59024","0.50571"
"37238","223.39200","18.61625","0.50804"
"37290","223.70400","18.64226","0.50155"
"37342","224.01600","18.66821","0.50327"
"37394","224.32800","18.69421","0.50470"
"37446","224.64000","18.72022","0.50628"
"37498","224.95200","18.74623","0.50998"
"37550","225.26400","18.77230","0.51412"
"37602","225.57600","18.79819","0.51751"
"37654","225.88800","18.82426","0.52258"
"37706","226.20000","18.85021","0.52858"
"37758","226.51200","18.87621","0.53484"
"37810","226.82400","18.90222","0.53986"
"37862","227.13600","18.92823","0.54237"
"37914","227.44800","18.95424","0.52619"
"37966","227.76000","18.98013","0.50890"
"38018","228.07200","19.00620","0.07619"
"38070","228.38400","19.03220","0.05873"
"38122","228.69600","19.05821","0.05909"
"38174","229.00800","19.08428","0.07858"
"38226","229.32000","19.11017","0.05761"
"38278","229.63200","19.13630","0.07128"
"38330","229.94400","19.16225","0.07533"
"38382","230.25600","19.18826","0.05707"
"38434","230.56800","19.21426","0.07314"
"38486","230.88000","19.24021","0.06392"
"38538","231.19200","19.26622","0.06127"
"38590","231.50400","19.29217","0.07625"
"38642","231.81600","19.31824","0.06540"
"38694","232.12800","19.34419","0.07037"
"38746","232.44000","19.37020","0.07680"
"38798","232.75200","19.39632","0.06962"
"38850","233.06400","19.42215","0.07579"
"38902","233.37600","19.44822","0.07754"
"38954","233.68800","19.47423","0.07446"
"39006","234.00000","19.50024","0.07809"
"39058","234.31200","19.52625","0.07888"
"39110","234.62400","19.55219","0.07758"
"39162","234.93600","19.57826","0.08009"
"39214","235.24800","19.60415","0.08199"
"39266","235.56000","19.63022","0.07993"
"39318","235.87200","19.65623","0.08428"
"39370","236.18400","19.68224","0.08706"
"39422","236.49600","19.70824","0.08452"
"39474","236.80800","19.73419","0.09129"
"39526","237.12000","19.76026","0.09467"
"39578","237.43200","19.78615","0.09307"
"39630","237.74400","19.81228","0.09906"
"39682","238.05600","19.83822","0.10414"
"39734","238.36800","19.86423","0.10186"
"39786","238.68000","19.89024","0.10623"
"39838","238.99200","19.91619","0.11081"
"39890","239.30400","19.94220","0.11169"
"39942","239.61600","19.96821","0.11439"
"39994","239.92800","19.99428","0.12057"
"40046","240.24000","20.02017","0.12196"
"40098","240.55200","20.04618","0.12597"
"40150","240.86400","20.07224","0.13160"
"40202","241.17600","20.09819","0.13296"
"40254","241.48800","20.12420","0.07101"
"40306","241.80000","20.15021","0.06271"
"40358","242.11200","20.17622","0.07007"
"40410","242.42400","20.20222","0.06041"
"40462","242.73600","20.22817","0.07484"
"40514","243.04800","20.25424","0.07195"
"40566","243.36000","20.28019","0.07004"
"40618","243.67200","20.30620","0.07679"
"40670","243.98400","20.33221","0.07405"
"40722","244.29600","20.35822","0.07673"
"40774","244.60800","20.38428","0.07790"
"40826","244.92000","20.41018","0.07676"
"40878","245.23200","20.43624","0.07896"
"40930","245.54400","20.46219","0.07908"
"40982","245.85600","20.48820","0.07822"
"41034","246.16800","20.51421","0.08111"
"41086","246.48000","20.54015","0.08172"
"41138","246.79200","20.56623","0.08125"
"41190","247.10400","20.59217","0.08674"
"41242","247.41600","20.61824","0.08827"
"41294","247.72800","20.64419","0.08814"
"41346","248.04000","20.67020","0.09620"
"41398","248.35200","20.69627","0.09902"
"41450","248.66400","20.72222","0.09969"
"41502","248.97600","20.74822","0.10542"
"41554","249.28800","20.77423","0.10801"
"41606","249.60000","20.80024","0.10791"
"41658","249.91200","20.82619","0.11200"
"41710","250.22400","20.85220","0.11588"
"41762","250.53600","20.87827","0.11698"
"41814","250.84800","20.90421","0.12287"
"41866","251.16000","20.93022","0.12725"
"41918","251.47200","20.95617","0.12875"
"41970","251.78400","20.98224","0.13170"
"42022","252.09600","21.00831","0.13368"
"42074","252.40800","21.03420","0.13485"
"42126","252.72000","21.06020","0.13672"
"42178","253.03200","21.08621","0.13794"
"42230","253.34400","21.11222","0.13862"
"42282","253.65600","21.13823","0.13907"
"42334","253.96800","21.16424","0.13992"
"42386","254.28000","21.19025","0.14119"
"42438","254.59200","21.21620","0.14214"
"42490","254.90400","21.24226","0.14364"
"42542","255.21600","21.26821","0.14315"
"42594","255.52800","21.29428","0.14454"
"42646","255.84000","21.32023","0.14591"
"42698","256.15200","21.34618","0.14818"
"42750","256.46400","21.37219","0.15059"
"42802","256.77600","21.39813","0.14615"
"42854","257.08800","21.42420","0.14978"
"42906","257.40000","21.45021","0.15139"
"42958","257.71200","21.47622","0.15407"
"43010","258.02400","21.50223","0.15736"
"43062","258.33600","21.52824","0.16015"
"43114","258.64800","21.55425","0.16186"
"43166","258.96000","21.58013","0.16477"
"43218","259.27200","21.60626","0.16720"
"43270","259.58400","21.63221","0.16892"
"43322","259.89600","21.65822","0.17057"
"43374","260.20800","21.68423","0.17253"
"43426","260.52000","21.71018","0.17430"
"43478","260.83200","21.73619","0.17559"
"43530","261.14400","21.76225","0.17639"
"43582","261.45600","21.78826","0.17507"
"43634","261.76800","21.81427","0.17655"
"43686","262.08000","21.84022","0.17693"
"43738","262.39200","21.86623","0.17825"
"43790","262.70400","21.89218","0.17947"
"43842","263.01600","21.91825","0.18142"
"43894","263.32800","21.94419","0.18200"
"43946","263.64000","21.97020","0.18324"
"43998","263.95200","21.99621","0.18367"
"44050","264.26400","22.02222","0.18519"
"44102","264.57600","22.04823","0.18669"
"44154","264.88800","22.07424","0.18725"
"44206","265.20000","22.10025","0.18862"
"44258","265.51200","22.12619","0.18996"
"44310","265.82400","22.15220","0.19141"
"44362","266.13600","22.17821","0.19362"
"44414","266.44800","22.20422","0.19514"
"44466","266.76000","22.23029","0.19659"
"44518","267.07200","22.25624","0.19902"
"44570","267.38400","22.28218","0.20192"
"44622","267.69600","22.30825","0.20410"
"44674","268.00800","22.33420","0.20710"
"44726","268.32000","22.36027","0.20932"
"44778","268.63200","22.38622","0.21166"
"44830","268.94400","22.41223","0.21358"
"44882","269.25600","22.43818","0.21596"
"44934","269.56800","22.46418","0.21758"
"44986","269.88000","22.49025","0.21978"
"45038","270.19200","22.51614","0.22253"
"45090","270.50400","22.54221","0.22496"
"45142","270.81600","22.56816","0.22667"
"45194","271.12800","22.59422","0.22854"
"45246","271.44000","22.62024","0.22960"
"45298","271.75200","22.64618","0.23057"
"45350","272.06400","22.67225","0.23251"
"45402","272.37600","22.69814","0.23475"
"45454","272.68800","22.72427","0.23775"
"45506","273.00000","22.75016","0.24193"
"45558","273.31200","22.77622","0.24535"
"45610","273.62400","22.80223","0.24934"
"45662","273.93600","22.82818","0.25441"
"45714","274.24800","22.85425","0.25835"
"45766","274.56000","22.88020","0.26203"
"45818","274.87200","22.90621","0.26516"
"45870","275.18400","22.93222","0.26898"
"45922","275.49600","22.95822","0.27250"
"45974","275.80800","22.98429","0.27615"
"46026","276.12000","23.01018","0.27939"
"46078","276.43200","23.03625","0.28127"
"46130","276.74400","23.06220","0.28460"
"46182","277.05600","23.08827","0.28652"
"46234","277.36800","23.11422","0.28835"
"46286","277.68000","23.14016","0.28956"
"46338","277.99200","23.16623","0.29073"
"46390","278.30400","23.19212","0.29131"
"46442","278.61600","23.21825","0.29176"
"46494","278.92800","23.24420","0.29187"
"46546","279.24000","23.27020","0.29215"
"46598","279.55200","23.29627","0.29235"
"46650","279.86400","23.32216","0.29292"
"46702","280.17600","23.34823","0.29333"
"46754","280.48800","23.37418","0.29482"
"46806","280.80000","23.40031","0.29616"
"46858","281.11200","23.42620","0.29798"
"46910","281.42400","23.45220","0.30014"
"46962","281.73600","23.47821","0.30308"
"47014","282.04800","23.50416","0.30504"
"47066","282.36000","23.53023","0.30746"
"47118","282.67200","23.55618","0.31027"
"47170","282.98400","23.58225","0.31139"
"47222","283.29600","23.60825","0.31423"
"47274","283.60800","23.63420","0.31720"
"47326","283.92000","23.66021","0.31896"
"47378","284.23200","23.68622","0.32300"
"47430","284.54400","23.71223","0.32794"
"47482","284.85600","23.73818","0.33224"
"47534","285.16800","23.76418","0.33611"
"47586","285.48000","23.79025","0.33875"
"47638","285.79200","23.81614","0.34120"
"47690","286.10400","23.84227","0.34286"
"47742","286.41600","23.86822","0.34474"
"47794","286.72800","23.89423","0.34625"
"47846","287.04000","23.92024","0.34928"
"47898","287.35200","23.94625","0.35135"
"47950","287.66400","23.97225","0.35481"
"48002","287.97600","23.99821","0.35748"
"48054","288.28800","24.02427","0.35609"
"48106","288.60000","24.05022","0.35207"
"48158","288.91200","24.07623","0.34939"
"48210","289.22400","24.10218","0.34891"
"48262","289.53600","24.12819","0.35067"
"48314","289.84800","24.15431","0.35297"
"48366","290.16000","24.18020","0.35482"
"48418","290.47200","24.20627","0.35746"
"48470","290.78400","24.23222","0.35844"
"48522","291.09600","24.25823","0.36027"
"48574","291.40800","24.28430","0.35868"
"48626","291.72000","24.31025","0.35899"
"48678","292.03200","24.33625","0.36003"
"48730","292.34400","24.36220","0.36048"
"48782","292.65600","24.38821","0.36113"
"48834","292.96800","24.41422","0.34561"
"48886","293.28000","24.44023","0.34545"
"48938","293.59200","24.46624","0.34269"
"48990","293.90400","24.49218","0.34079"
"49042","294.21600","24.51825","0.31545"
"49094","294.52800","24.54420","0.29202"
"49146","294.84000","24.57027","0.24181"
"49198","295.15200","24.59628","0.20773"
"49250","295.46400","24.62223","0.19169"
"49302","295.77600","24.64823","0.17483"
"49354","296.08800","24.67413","0.15670"
"49406","296.40000","24.70025","0.13508"
"49458","296.71200","24.72626","0.09662"
"49510","297.02400","24.75227","0.07928"
"49562","297.33600","24.77828","0.07919"
"49614","297.64800","24.80416","0.07814"
"49666","297.96000","24.83029","0.07952"
"49718","298.27200","24.85618","0.08028"
"49770","298.58400","24.88225","0.07985"
"49822","298.89600","24.90826","0.08078"
"49874","299.20800","24.93421","0.08217"
"49926","299.52000","24.96022","0.08107"
"49978","299.83200","24.98616","0.08154"
"50030","300.14400","25.01223","0.08319"
"50082","300.45600","25.03824","0.08296"
"50134","300.76800","25.06425","0.08440"
"50186","301.08000","25.09020","0.08653"
"50238","301.39200","25.11621","0.08392"
"50290","301.70400","25.14222","0.08404"
"50342","302.01600","25.16816","0.08432"
"50394","302.32800","25.19423","0.08521"
"50446","302.64000","25.22024","0.08482"
"50498","302.95200","25.24619","0.08555"
"50550","303.26400","25.27220","0.08768"
"50602","303.57600","25.29815","0.08750"
"50654","303.88800","25.32422","0.08918"
"50706","304.20000","25.35022","0.09096"
"50758","304.51200","25.37629","0.09137"
"50810","304.82400","25.40230","0.09274"
"50862","305.13600","25.42819","0.09464"
"50914","305.44800","25.45426","0.09510"
"50966","305.76000","25.48021","0.09605"
"51018","306.07200","25.50622","0.09720"
"51070","306.38400","25.53216","0.09872"
"51122","306.69600","25.55823","0.09840"
"51174","307.00800","25.58424","0.10127"
"51226","307.32000","25.61019","0.10300"
"51278","307.63200","25.63626","0.10560"
"51330","307.94400","25.66220","0.10598"
"51382","308.25600","25.68828","0.10812"
"51434","308.56800","25.71422","0.10883"
"51486","308.88000","25.74023","0.11050"
"51538","309.19200","25.76624","0.11241"
"51590","309.50400","25.79219","0.11424"
"51642","309.81600","25.81825","0.11590"
"51694","310.12800","25.84421","0.11893"
"51746","310.44000","25.87016","0.12076"
"51798","310.75200","25.89622","0.12389"
"51850","311.06400","25.92223","0.12599"
"51902","311.37600","25.94824","0.12913"
"51954","311.68800","25.97419","0.13091"
"52006","312.00000","26.00026","0.13202"
"52058","312.31200","26.02621","0.13349"
"52110","312.62400","26.05221","0.13524"
"52162","312.93600","26.07828","0.13683"
"52214","313.24800","26.10417","0.13724"
"52266","313.56000","26.13024","0.13776"
"52318","313.87200","26.15613","0.13875"
"52370","314.18400","26.18225","0.13960"
"52422","314.49600","26.20827","0.13985"
"52474","314.80800","26.23421","0.13890"
"52526","315.12000","26.26028","0.13976"
"52578","315.43200","26.28623","0.14036"
"52630","315.74400","26.31224","0.14109"
"52682","316.05600","26.33819","0.14199"
"52734","316.36800","26.36425","0.14306"
"52786","316.68000","26.39026","0.14320"
"52838","316.99200","26.41621","0.14445"
"52890","317.30400","26.44222","0.14471"
"52942","317.61600","26.46817","0.14541"
"52994","317.92800","26.49424","0.14739"
"53046","318.24000","26.52025","0.14881"
"53098","318.55200","26.54625","0.14976"
"53150","318.86400","26.57226","0.15209"
"53202","319.17600","26.59821","0.15393"
"53254","319.48800","26.62422","0.14407"
"53306","319.80000","26.65023","0.14192"
"53358","320.11200","26.67624","0.14263"
"53410","320.42400","26.70225","0.14621"
"53462","320.73600","26.72819","0.14803"
"53514","321.04800","26.75420","0.14906"
"53566","321.36000","26.78015","0.15148"
"53618","321.67200","26.80622","0.15522"
"53670","321.98400","26.83223","0.15691"
"53722","322.29600","26.85823","0.15845"
"53774","322.60800","26.88424","0.15925"
"53826","322.92000","26.91025","0.15999"
"53878","323.23200","26.93626","0.16074"
"53930","323.54400","26.96221","0.16079"
"53982","323.85600","26.98828","0.16191"
"54034","324.16800","27.01423","0.12997"
"54086","324.48000","27.04018","0.11740"
"54138","324.79200","27.06618","0.11793"
"54190","325.10400","27.09213","0.12702"
"54242","325.41600","27.11826","0.12165"
"54294","325.72800","27.14427","0.12443"
"54346","326.04000","27.17022","0.13138"
"54398","326.35200","27.19622","0.13025"
"54450","326.66400","27.22223","0.13101"
"54502","326.97600","27.24825","0.13582"
"54554","327.28800","27.27419","0.13572"
"54606","327.60000","27.30026","0.13589"
"54658","327.91200","27.32615","0.13764"
"54710","328.22400","27.35216","0.13778"
"54762","328.53600","27.37822","0.02460"
"54814","328.84800","27.40417","0.03221"
"54866","329.16000","27.43024","0.02852"
"54918","329.47200","27.45619","0.03168"
"54970","329.78400","27.48220","0.02997"
"55022","330.09600","27.50821","0.03212"
"55074","330.40800","27.53422","0.03042"
"55126","330.72000","27.56028","0.03211"
"55178","331.03200","27.58618","0.03125"
"55230","331.34400","27.61224","0.03293"
"55282","331.65600","27.63819","0.03233"
"55334","331.96800","27.66420","0.03352"
"55386","332.28000","27.69021","0.03324"
"55438","332.59200","27.71622","0.03413"
"55490","332.90400","27.74223","0.03408"
"55542","333.21600","27.76818","0.03446"
"55594","333.52800","27.79424","0.03527"
"55646","333.84000","27.82025","0.03567"
"55698","334.15200","27.84620","0.03539"
"55750","334.46400","27.87221","0.03606"
"55802","334.77600","27.89816","0.03597"
"55854","335.08800","27.92422","0.03681"
"55906","335.40000","27.95017","0.03663"
"55958","335.71200","27.97624","0.03659"
"56010","336.02400","28.00225","0.03671"
"56062","336.33600","28.02820","0.03772"
"56114","336.64800","28.05427","0.03746"
"56166","336.96000","28.08021","0.03636"
"56218","337.27200","28.10622","0.03635"
"56270","337.58400","28.13223","0.03733"
"56322","337.89600","28.15824","0.03745"
"56374","338.20800","28.18431","0.03713"
"56426","338.52000","28.21020","0.03718"
"56478","338.83200","28.23621","0.03789"
"56530","339.14400","28.26216","0.03887"
"56582","339.45600","28.28822","0.03964"
"56634","339.76800","28.31429","0.04099"
"56686","340.08000","28.34024","0.04160"
"56738","340.39200","28.36625","0.03539"
"56790","340.70400","28.39214","0.03439"
"56842","341.01600","28.41826","0.03367"
"56894","341.32800","28.44421","0.03365"
"56946","341.64000","28.47022","0.03349"
"56998","341.95200","28.49617","0.03372"
"57050","342.26400","28.52218","0.03298"
"57102","342.57600","28.54819","0.03335"
"57154","342.88800","28.57413","0.03313"
"57206","343.20000","28.60026","0.03288"
"57258","343.51200","28.62621","0.03329"
"57310","343.82400","28.65222","0.03325"
"57362","344.13600","28.67823","0.03388"
"57414","344.44800","28.70418","0.03389"
"57466","344.76000","28.73019","0.03458"
"57518","345.07200","28.75620","0.03489"
"57570","345.38400","28.78226","0.03566"
"57622","345.69600","28.80821","0.03573"
"57674","346.00800","28.83422","0.03564"
"57726","346.32000","28.86023","0.03696"
"57778","346.63200","28.88618","0.03655"
"57830","346.94400","28.91225","0.03761"
"57882","347.25600","28.93819","0.03859"
"57934","347.56800","28.96426","0.03863"
"57986","347.88000","28.99027","0.03990"
"58038","348.19200","29.01622","0.03928"
"58090","348.50400","29.04223","0.04157"
"58142","348.81600","29.06818","0.04107"
"58194","349.12800","29.09425","0.04239"
"58246","349.44000","29.12019","0.04196"
"58298","349.75200","29.14626","0.04271"
"58350","350.06400","29.17221","0.04212"
"58402","350.37600","29.19822","0.04284"
"58454","350.68800","29.22429","0.04429"
"58506","351.00000","29.25018","0.04417"
"58558","351.31200","29.27630","0.04383"
"58610","351.62400","29.30225","0.04296"
"58662","351.93600","29.32826","0.03940"
"58714","352.24800","29.35427","0.04193"
"58766","352.56000","29.38022","0.02767"
"58818","352.87200","29.40623","0.02516"
"58870","353.18400","29.43218","0.02933"
"58922","353.49600","29.45818","0.02531"
"58974","353.80800","29.48425","0.02981"
"59026","354.12000","29.51020","0.02430"
"59078","354.43200","29.53627","0.03022"
"59130","354.74400","29.56216","0.02560"
"59182","355.05600","29.58829","0.03036"
"59234","355.36800","29.61423","0.02684"
"59286","355.68000","29.64018","0.03063"
"59338","355.99200","29.66631","0.02821"
"59390","356.30400","29.69220","0.03099"
"59442","356.61600","29.71821","0.02927"
"59494","356.92800","29.74416","0.03104"
"59546","357.24000","29.77023","0.02992"
"59598","357.55200","29.79618","0.03121"
"59650","357.86400","29.82224","0.03062"
"59702","358.17600","29.84825","0.03151"
"59754","358.48800","29.87414","0.03112"
"59806","358.80000","29.90027","0.03196"
"59858","359.11200","29.92622","0.03192"
"59910","359.42400","29.95228","0.03218"
"59962","359.73600","29.97823","0.03284"
"60014","360.04800","30.00418","0.03284"
"60066","360.36000","30.03025","0.03357"
"60118","360.67200","30.05614","0.03290"
"60170","360.98400","30.08221","0.03456"
"60222","361.29600","30.10822","0.03363"
"60274","361.60800","30.13423","0.03500"
"60326","361.92000","30.16029","0.03480"
"60378","362.23200","30.18618","0.03650"
"60430","362.54400","30.21225","0.03545"
"60482","362.85600","30.23820","0.03773"
"60534","363.16800","30.26421","0.03721"
"60586","363.48000","30.29028","0.03766"
"60638","363.79200","30.31616","0.03800"
"60690","364.10400","30.34223","0.03928"
"60742","364.41600","30.36812","0.03961"
"60794","364.72800","30.39425","0.04019"
"60846","365.04000","30.42026","0.04084"
"60898","365.35200","30.44621","0.04162"
"60950","365.66400","30.47227","0.04237"
"61002","365.97600","30.49816","0.04449"
"61054","366.28800","30.52423","0.04489"
"61106","366.60000","30.55018","0.04649"
"61158","366.91200","30.57625","0.04738"
"61210","367.22400","30.60220","0.04798"
"61262","367.53600","30.62815","0.04861"
"61314","367.84800","30.65421","0.04976"
"61366","368.16000","30.68016","0.05024"
"61418","368.47200","30.70623","0.05124"
"61470","368.78400","30.73224","0.05167"
"61522","369.09600","30.75825","0.05322"
"61574","369.40800","30.78420","0.05339"
"61626","369.72000","30.81014","0.05441"
"61678","370.03200","30.83621","0.05498"
"61730","370.34400","30.86222","0.05612"
"61782","370.65600","30.88823","0.05684"
"61834","370.96800","30.91418","0.05793"
"61886","371.28000","30.94019","0.05754"
"61938","371.59200","30.96620","0.05861"
"61990","371.90400","30.99221","0.05922"
"62042","372.21600","31.01827","0.06054"
"62094","372.52800","31.04422","0.06037"
"62146","372.84000","31.07017","0.06153"
"62198","373.15200","31.09618","0.06221"
"62250","373.46400","31.12218","0.06330"
"62302","373.77600","31.14825","0.06345"
"62354","374.08800","31.17414","0.06390"
"62406","374.40000","31.20027","0.06496"
"62458","374.71200","31.22622","0.06583"
"62510","375.02400","31.25217","0.06640"
"62562","375.33600","31.27817","0.06740"
"62614","375.64800","31.30418","0.06814"
"62666","375.96000","31.33025","0.06802"
"62718","376.27200","31.35620","0.06915"
"62770","376.58400","31.38227","0.06945"
"62822","376.89600","31.40822","0.06977"
"62874","377.20800","31.43423","0.07019"
"62926","377.52000","31.46030","0.07137"
"62978","377.83200","31.48618","0.07140"
"63030","378.14400","31.51225","0.07277"
"63082","378.45600","31.53820","0.07276"
"63134","378.76800","31.56421","0.07194"
"63186","379.08000","31.59022","0.06370"
"63238","379.39200","31.61617","0.00364"
"63290","379.70400","31.64224","0.00727"
"63342","380.01600","31.66818","0.00694"
"63394","380.32800","31.69425","0.00595"
"63446","380.64000","31.72026","0.00551"
"63498","380.95200","31.74627","0.00694"
"63550","381.26400","31.77228","0.00675"
"63602","381.57600","31.79816","0.00598"
"63654","381.88800","31.82423","0.00599"
"63706","382.20000","31.85018","0.00728"
"63758","382.51200","31.87625","0.00538"
"63810","382.82400","31.90226","0.00599"
"63862","383.13600","31.92821","0.00629"
"63914","383.44800","31.95428","0.00689"
"63966","383.76000","31.98022","0.00601"
"64018","384.07200","32.00623","0.00588"
"64066","384.35600","32.02985","0.00635"