File: Trajectories_together/170107_1Specimen_RawData_10.csv
"","V1","V2","V3"
"1","End date","1/7/2017",""
"2","Specimen label","18AT_47/49",""
"3","Maximum Load","0.18800","N"
"4","Time","Extension","Load"
"5","(s)","(mm)","(N)"
"6","0.00000","0.00000","-0.00070"
"44","0.22800","0.01704","-0.00054"
"82","0.45600","0.03827","-0.00054"
"120","0.68400","0.05722","-0.00015"
"158","0.91200","0.07617","-0.00074"
"196","1.14000","0.09524","-0.00065"
"234","1.36800","0.11414","-0.00020"
"272","1.59600","0.13327","0.00010"
"310","1.82400","0.15216","-0.00087"
"348","2.05200","0.17118","-0.00018"
"386","2.28000","0.19025","0.00028"
"424","2.50800","0.20914","-0.00016"
"462","2.73600","0.22822","-0.00014"
"500","2.96400","0.24717","-0.00023"
"538","3.19200","0.26624","-0.00006"
"576","3.42000","0.28526","-0.00010"
"614","3.64800","0.30415","-0.00038"
"652","3.87600","0.32322","-0.00065"
"690","4.10400","0.34212","-0.00006"
"728","4.33200","0.36119","-0.00051"
"766","4.56000","0.38014","-0.00012"
"804","4.78800","0.39921","-0.00064"
"842","5.01600","0.41823","-0.00099"
"880","5.24400","0.43712","-0.00047"
"918","5.47200","0.45625","-0.00057"
"956","5.70000","0.47515","-0.00019"
"994","5.92800","0.49422","-0.00019"
"1032","6.15600","0.51317","-0.00033"
"1070","6.38400","0.53219","-0.00054"
"1108","6.61200","0.55120","-0.00006"
"1146","6.84000","0.57015","-0.00050"
"1184","7.06800","0.58923","-0.00004"
"1222","7.29600","0.60818","-0.00064"
"1260","7.52400","0.62719","-0.00022"
"1298","7.75200","0.64621","-0.00018"
"1336","7.98000","0.66516","-0.00012"
"1374","8.20800","0.68423","-0.00033"
"1412","8.43600","0.70318","0.00000"
"1450","8.66400","0.72220","-0.00070"
"1488","8.89200","0.74121","-0.00023"
"1526","9.12000","0.76016","-0.00019"
"1564","9.34800","0.77918","0.00021"
"1602","9.57600","0.79819","-0.00072"
"1640","9.80400","0.81726","-0.00066"
"1678","10.03200","0.83616","0.00011"
"1716","10.26000","0.85517","-0.00023"
"1754","10.48800","0.87412","0.00003"
"1792","10.71600","0.89320","-0.00009"
"1830","10.94400","0.91215","0.00032"
"1868","11.17200","0.93122","-0.00019"
"1906","11.40000","0.95018","-0.00050"
"1944","11.62800","0.96919","-0.00023"
"1982","11.85600","0.98820","0.00016"
"2020","12.08400","1.00715","0.00024"
"2058","12.31200","1.02623","0.00012"
"2096","12.54000","1.04518","0.00036"
"2134","12.76800","1.06419","0.00007"
"2172","12.99600","1.08321","0.00027"
"2210","13.22400","1.10216","-0.00008"
"2248","13.45200","1.12117","0.00020"
"2286","13.68000","1.14019","0.00019"
"2324","13.90800","1.15920","0.00039"
"2362","14.13600","1.17821","-0.00007"
"2400","14.36400","1.19723","0.00032"
"2438","14.59200","1.21624","-0.00020"
"2476","14.82000","1.23513","0.00015"
"2514","15.04800","1.25426","-0.00031"
"2552","15.27600","1.27322","0.00015"
"2590","15.50400","1.29223","0.00048"
"2628","15.73200","1.31118","-0.00013"
"2666","15.96000","1.33014","0.00005"
"2704","16.18800","1.34921","0.00054"
"2742","16.41600","1.36816","0.00021"
"2780","16.64400","1.38730","0.00060"
"2818","16.87200","1.40613","0.00041"
"2856","17.10000","1.42514","0.00033"
"2894","17.32800","1.44422","0.00082"
"2932","17.55600","1.46317","0.00049"
"2970","17.78400","1.48218","0.00055"
"3008","18.01200","1.50114","0.00084"
"3046","18.24000","1.52021","0.00055"
"3084","18.46800","1.53922","0.00088"
"3122","18.69600","1.55817","0.00027"
"3160","18.92400","1.57719","0.00083"
"3198","19.15200","1.59608","0.00106"
"3236","19.38000","1.61521","0.00029"
"3274","19.60800","1.63417","0.00078"
"3312","19.83600","1.65318","0.00100"
"3350","20.06400","1.67219","0.00091"
"3388","20.29200","1.69115","0.00029"
"3426","20.52000","1.71022","0.00106"
"3464","20.74800","1.72911","0.00072"
"3502","20.97600","1.74819","0.00067"
"3540","21.20400","1.76720","0.00088"
"3578","21.43200","1.78621","0.00083"
"3616","21.66000","1.80523","0.00098"
"3654","21.88800","1.82418","0.00123"
"3692","22.11600","1.84325","0.00101"
"3730","22.34400","1.86220","0.00035"
"3768","22.57200","1.88122","0.00056"
"3806","22.80000","1.90023","0.00085"
"3844","23.02800","1.91918","-0.00006"
"3882","23.25600","1.93820","0.00070"
"3920","23.48400","1.95709","0.00072"
"3958","23.71200","1.97622","0.00022"
"3996","23.94000","1.99518","0.00050"
"4034","24.16800","2.01419","0.00021"
"4072","24.39600","2.03320","0.00024"
"4110","24.62400","2.05216","0.00087"
"4148","24.85200","2.07123","0.00073"
"4186","25.08000","2.09012","0.00015"
"4224","25.30800","2.10920","0.00114"
"4262","25.53600","2.12821","0.00053"
"4300","25.76400","2.14716","0.00036"
"4338","25.99200","2.16617","0.00068"
"4376","26.22000","2.18519","0.00055"
"4414","26.44800","2.20420","0.00040"
"4452","26.67600","2.22315","0.00040"
"4490","26.90400","2.24217","0.00104"
"4528","27.13200","2.26124","0.00090"
"4566","27.36000","2.28025","0.00069"
"4604","27.58800","2.29915","0.00054"
"4642","27.81600","2.31822","0.00078"
"4680","28.04400","2.33717","0.00064"
"4718","28.27200","2.35619","0.00065"
"4756","28.50000","2.37520","0.00124"
"4794","28.72800","2.39415","0.00057"
"4832","28.95600","2.41323","0.00054"
"4870","29.18400","2.43218","0.00084"
"4908","29.41200","2.45119","0.00100"
"4946","29.64000","2.47020","0.00068"
"4984","29.86800","2.48916","0.00110"
"5022","30.09600","2.50817","0.00095"
"5060","30.32400","2.52718","0.00140"
"5098","30.55200","2.54620","0.00146"
"5136","30.78000","2.56521","0.00103"
"5174","31.00800","2.58416","0.00127"
"5212","31.23600","2.60318","0.00111"
"5250","31.46400","2.62213","0.00139"
"5288","31.69200","2.64120","0.00086"
"5326","31.92000","2.66016","0.00147"
"5364","32.14800","2.67923","0.00148"
"5402","32.37600","2.69818","0.00150"
"5440","32.60400","2.71714","0.00096"
"5478","32.83200","2.73621","0.00129"
"5516","33.06000","2.75522","0.00120"
"5554","33.28800","2.77417","0.00230"
"5592","33.51600","2.79319","0.00153"
"5630","33.74400","2.81214","0.00201"
"5668","33.97200","2.83121","0.00135"
"5706","34.20000","2.85017","0.00134"
"5744","34.42800","2.86918","0.00192"
"5782","34.65600","2.88819","0.00073"
"5820","34.88400","2.90721","0.00136"
"5858","35.11200","2.92628","0.00145"
"5896","35.34000","2.94511","0.00194"
"5934","35.56800","2.96425","0.00153"
"5972","35.79600","2.98320","0.00230"
"6010","36.02400","3.00227","0.00168"
"6048","36.25200","3.02117","0.00161"
"6086","36.48000","3.04018","0.00192"
"6124","36.70800","3.05925","0.00123"
"6162","36.93600","3.07814","0.00172"
"6200","37.16400","3.09722","0.00153"
"6238","37.39200","3.11617","0.00187"
"6276","37.62000","3.13524","0.00173"
"6314","37.84800","3.15420","0.00180"
"6352","38.07600","3.17315","0.00219"
"6390","38.30400","3.19222","0.00192"
"6428","38.53200","3.21112","0.00199"
"6466","38.76000","3.23019","0.00162"
"6504","38.98800","3.24914","0.00163"
"6542","39.21600","3.26816","0.00144"
"6580","39.44400","3.28723","0.00179"
"6618","39.67200","3.30612","0.00223"
"6656","39.90000","3.32525","0.00201"
"6694","40.12800","3.34409","0.00219"
"6732","40.35600","3.36316","0.00196"
"6770","40.58400","3.38223","0.00236"
"6808","40.81200","3.40119","0.00184"
"6846","41.04000","3.42026","0.00200"
"6884","41.26800","3.43909","0.00148"
"6922","41.49600","3.45823","0.00214"
"6960","41.72400","3.47718","0.00224"
"6998","41.95200","3.49619","0.00232"
"7036","42.18000","3.51521","0.00224"
"7074","42.40800","3.53416","0.00216"
"7112","42.63600","3.55317","0.00225"
"7150","42.86400","3.57213","0.00207"
"7188","43.09200","3.59120","0.00213"
"7226","43.32000","3.61021","0.00235"
"7264","43.54800","3.62916","0.00167"
"7302","43.77600","3.64824","0.00230"
"7340","44.00400","3.66719","0.00172"
"7378","44.23200","3.68620","0.00198"
"7416","44.46000","3.70516","0.00213"
"7454","44.68800","3.72417","0.00187"
"7492","44.91600","3.74318","0.00220"
"7530","45.14400","3.76220","0.00151"
"7568","45.37200","3.78121","0.00193"
"7606","45.60000","3.80022","0.00156"
"7644","45.82800","3.81924","0.00164"
"7682","46.05600","3.83807","0.00166"
"7720","46.28400","3.85720","0.00212"
"7758","46.51200","3.87622","0.00227"
"7796","46.74000","3.89517","0.00199"
"7834","46.96800","3.91418","0.00198"
"7872","47.19600","3.93319","0.00204"
"7910","47.42400","3.95221","0.00215"
"7948","47.65200","3.97116","0.00190"
"7986","47.88000","3.99023","0.00238"
"8024","48.10800","4.00919","0.00250"
"8062","48.33600","4.02820","0.00217"
"8100","48.56400","4.04721","0.00171"
"8138","48.79200","4.06617","0.00238"
"8176","49.02000","4.08518","0.00275"
"8214","49.24800","4.10413","0.00185"
"8252","49.47600","4.12321","0.00224"
"8290","49.70400","4.14222","0.00221"
"8328","49.93200","4.16117","0.00200"
"8366","50.16000","4.18024","0.00227"
"8404","50.38800","4.19920","0.00181"
"8442","50.61600","4.21821","0.00246"
"8480","50.84400","4.23716","0.00205"
"8518","51.07200","4.25624","0.00234"
"8556","51.30000","4.27513","0.00204"
"8594","51.52800","4.29420","0.00198"
"8632","51.75600","4.31322","0.00205"
"8670","51.98400","4.33211","0.00215"
"8708","52.21200","4.35124","0.00250"
"8746","52.44000","4.37014","0.00234"
"8784","52.66800","4.38927","0.00214"
"8822","52.89600","4.40822","0.00204"
"8860","53.12400","4.42718","0.00208"
"8898","53.35200","4.44625","0.00240"
"8936","53.58000","4.46514","0.00225"
"8974","53.80800","4.48421","0.00217"
"9012","54.03600","4.50317","0.00323"
"9050","54.26400","4.52224","0.00227"
"9088","54.49200","4.54125","0.00212"
"9126","54.72000","4.56015","0.00230"
"9164","54.94800","4.57928","0.00208"
"9202","55.17600","4.59817","0.00157"
"9240","55.40400","4.61725","0.00136"
"9278","55.63200","4.63614","0.00159"
"9316","55.86000","4.65515","0.00181"
"9354","56.08800","4.67429","0.00121"
"9392","56.31600","4.69312","0.00134"
"9430","56.54400","4.71225","0.00182"
"9468","56.77200","4.73115","0.00090"
"9506","57.00000","4.75022","0.00210"
"9544","57.22800","4.76923","0.00142"
"9582","57.45600","4.78819","0.00154"
"9620","57.68400","4.80726","0.00121"
"9658","57.91200","4.82609","0.00231"
"9696","58.14000","4.84522","0.00173"
"9734","58.36800","4.86418","0.00175"
"9772","58.59600","4.88319","0.00125"
"9810","58.82400","4.90220","0.00178"
"9848","59.05200","4.92116","0.00157"
"9886","59.28000","4.94023","0.00188"
"9924","59.50800","4.95918","0.00203"
"9962","59.73600","4.97820","0.00171"
"10000","59.96400","4.99715","0.00162"
"10038","60.19200","5.01616","0.00176"
"10076","60.42000","5.03517","0.00146"
"10114","60.64800","5.05419","0.00164"
"10152","60.87600","5.07320","0.00175"
"10190","61.10400","5.09215","0.00189"
"10228","61.33200","5.11123","0.00207"
"10266","61.56000","5.13018","0.00052"
"10304","61.78800","5.14919","0.00160"
"10342","62.01600","5.16821","0.00153"
"10380","62.24400","5.18716","0.00144"
"10418","62.47200","5.20617","0.00094"
"10456","62.70000","5.22519","0.00123"
"10494","62.92800","5.24426","0.00146"
"10532","63.15600","5.26321","0.00143"
"10570","63.38400","5.28217","0.00138"
"10608","63.61200","5.30118","0.00117"
"10646","63.84000","5.32019","0.00133"
"10684","64.06800","5.33921","0.00160"
"10722","64.29600","5.35816","0.00111"
"10760","64.52400","5.37717","0.00159"
"10798","64.75200","5.39618","0.00148"
"10836","64.98000","5.41520","0.00156"
"10874","65.20800","5.43427","0.00137"
"10912","65.43600","5.45316","0.00124"
"10950","65.66400","5.47218","0.00116"
"10988","65.89200","5.49113","0.00178"
"11026","66.12000","5.51026","0.00140"
"11064","66.34800","5.52922","0.00105"
"11102","66.57600","5.54817","0.00155"
"11140","66.80400","5.56718","0.00181"
"11178","67.03200","5.58614","0.00116"
"11216","67.26000","5.60521","0.00170"
"11254","67.48800","5.62416","0.00166"
"11292","67.71600","5.64324","0.00191"
"11330","67.94400","5.66219","0.00158"
"11368","68.17200","5.68120","0.00152"
"11406","68.40000","5.70015","0.00179"
"11444","68.62800","5.71917","0.00166"
"11482","68.85600","5.73824","0.00179"
"11520","69.08400","5.75719","0.00165"
"11558","69.31200","5.77621","0.00109"
"11596","69.54000","5.79522","0.00171"
"11634","69.76800","5.81417","0.00200"
"11672","69.99600","5.83325","0.00149"
"11710","70.22400","5.85214","0.00160"
"11748","70.45200","5.87127","0.00138"
"11786","70.68000","5.89017","0.00141"
"11824","70.90800","5.90918","0.00192"
"11862","71.13600","5.92825","0.00180"
"11900","71.36400","5.94715","0.00165"
"11938","71.59200","5.96628","0.00131"
"11976","71.82000","5.98511","0.00129"
"12014","72.04800","6.00424","0.00170"
"12052","72.27600","6.02320","0.00174"
"12090","72.50400","6.04221","0.00152"
"12128","72.73200","6.06122","0.00154"
"12166","72.96000","6.08018","0.00178"
"12204","73.18800","6.09925","0.00212"
"12242","73.41600","6.11814","0.00160"
"12280","73.64400","6.13722","0.00163"
"12318","73.87200","6.15623","0.00125"
"12356","74.10000","6.17518","0.00185"
"12394","74.32800","6.19420","0.00131"
"12432","74.55600","6.21315","0.00154"
"12470","74.78400","6.23222","0.00169"
"12508","75.01200","6.25117","0.00125"
"12546","75.24000","6.27019","0.00221"
"12584","75.46800","6.28926","0.00167"
"12622","75.69600","6.30809","0.00159"
"12660","75.92400","6.32723","0.00186"
"12698","76.15200","6.34618","0.00186"
"12736","76.38000","6.36519","0.00193"
"12774","76.60800","6.38421","0.00190"
"12812","76.83600","6.40316","0.00191"
"12850","77.06400","6.42217","0.00231"
"12888","77.29200","6.44113","0.00205"
"12926","77.52000","6.46014","0.00217"
"12964","77.74800","6.47915","0.00223"
"13002","77.97600","6.49823","0.00250"
"13040","78.20400","6.51724","0.00246"
"13078","78.43200","6.53619","0.00240"
"13116","78.66000","6.55520","0.00172"
"13154","78.88800","6.57416","0.00225"
"13192","79.11600","6.59317","0.00242"
"13230","79.34400","6.61218","0.00196"
"13268","79.57200","6.63120","0.00218"
"13306","79.80000","6.65021","0.00275"
"13344","80.02800","6.66916","0.00206"
"13382","80.25600","6.68818","0.00258"
"13420","80.48400","6.70719","0.00237"
"13458","80.71200","6.72626","0.00201"
"13496","80.94000","6.74522","0.00277"
"13534","81.16800","6.76417","0.00240"
"13572","81.39600","6.78318","0.00256"
"13610","81.62400","6.80220","0.00240"
"13648","81.85200","6.82127","0.00203"
"13686","82.08000","6.84016","0.00271"
"13724","82.30800","6.85923","0.00220"
"13762","82.53600","6.87819","0.00196"
"13800","82.76400","6.89720","0.00277"
"13838","82.99200","6.91621","0.00267"
"13876","83.22000","6.93523","0.00226"
"13914","83.44800","6.95418","0.00243"
"13952","83.67600","6.97313","0.00225"
"13990","83.90400","6.99221","0.00267"
"14028","84.13200","7.01116","0.00156"
"14066","84.36000","7.03017","0.00156"
"14104","84.58800","7.04919","0.00169"
"14142","84.81600","7.06820","0.00177"
"14180","85.04400","7.08715","0.00170"
"14218","85.27200","7.10617","0.00187"
"14256","85.50000","7.12524","0.00158"
"14294","85.72800","7.14419","0.00223"
"14332","85.95600","7.16314","0.00290"
"14370","86.18400","7.18222","0.00262"
"14408","86.41200","7.20117","0.00264"
"14446","86.64000","7.22024","0.00193"
"14484","86.86800","7.23914","0.00293"
"14522","87.09600","7.25827","0.00231"
"14560","87.32400","7.27722","0.00228"
"14598","87.55200","7.29618","0.00218"
"14636","87.78000","7.31519","0.00288"
"14674","88.00800","7.33414","0.00258"
"14712","88.23600","7.35328","0.00211"
"14750","88.46400","7.37217","0.00274"
"14788","88.69200","7.39124","0.00265"
"14826","88.92000","7.41020","0.00285"
"14864","89.14800","7.42909","0.00235"
"14902","89.37600","7.44822","0.00259"
"14940","89.60400","7.46717","0.00275"
"14978","89.83200","7.48619","0.00259"
"15016","90.06000","7.50514","0.00300"
"15054","90.28800","7.52415","0.00282"
"15092","90.51600","7.54323","0.00285"
"15130","90.74400","7.56212","0.00349"
"15168","90.97200","7.58125","0.00269"
"15206","91.20000","7.60015","0.00313"
"15244","91.42800","7.61922","0.00322"
"15282","91.65600","7.63823","0.00320"
"15320","91.88400","7.65713","0.00314"
"15358","92.11200","7.67626","0.00312"
"15396","92.34000","7.69509","0.00308"
"15434","92.56800","7.71422","0.00283"
"15472","92.79600","7.73318","0.00303"
"15510","93.02400","7.75219","0.00294"
"15548","93.25200","7.77126","0.00320"
"15586","93.48000","7.79016","0.00278"
"15624","93.70800","7.80923","0.00259"
"15662","93.93600","7.82818","0.00278"
"15700","94.16400","7.84726","0.00285"
"15738","94.39200","7.86615","0.00279"
"15776","94.62000","7.88516","0.00323"
"15814","94.84800","7.90424","0.00340"
"15852","95.07600","7.92319","0.00297"
"15890","95.30400","7.94220","0.00342"
"15928","95.53200","7.96116","0.00376"
"15966","95.76000","7.98023","0.00312"
"16004","95.98800","7.99924","0.00360"
"16042","96.21600","8.01820","0.00353"
"16080","96.44400","8.03721","0.00308"
"16118","96.67200","8.05616","0.00326"
"16156","96.90000","8.07517","0.00363"
"16194","97.12800","8.09413","0.00253"
"16232","97.35600","8.11320","0.00307"
"16270","97.58400","8.13221","0.00351"
"16308","97.81200","8.15117","0.00359"
"16346","98.04000","8.17024","0.00345"
"16384","98.26800","8.18919","0.00337"
"16422","98.49600","8.20821","0.00383"
"16460","98.72400","8.22716","0.00314"
"16498","98.95200","8.24617","0.00344"
"16536","99.18000","8.26519","0.00366"
"16574","99.40800","8.28420","0.00285"
"16612","99.63600","8.30321","0.00360"
"16650","99.86400","8.32216","0.00303"
"16688","100.09200","8.34118","0.00353"
"16726","100.32000","8.36019","0.00379"
"16764","100.54800","8.37920","0.00412"
"16802","100.77600","8.39822","0.00368"
"16840","101.00400","8.41717","0.00336"
"16878","101.23200","8.43624","0.00327"
"16916","101.46000","8.45520","0.00412"
"16954","101.68800","8.47421","0.00388"
"16992","101.91600","8.49316","0.00397"
"17030","102.14400","8.51218","0.00348"
"17068","102.37200","8.53119","0.00395"
"17106","102.60000","8.55014","0.00350"
"17144","102.82800","8.56916","0.00408"
"17182","103.05600","8.58811","0.00412"
"17220","103.28400","8.60724","0.00414"
"17258","103.51200","8.62613","0.00355"
"17296","103.74000","8.64521","0.00431"
"17334","103.96800","8.66422","0.00398"
"17372","104.19600","8.68317","0.00398"
"17410","104.42400","8.70219","0.00435"
"17448","104.65200","8.72114","0.00445"
"17486","104.88000","8.74027","0.00493"
"17524","105.10800","8.75917","0.00469"
"17562","105.33600","8.77818","0.00457"
"17600","105.56400","8.79725","0.00397"
"17638","105.79200","8.81615","0.00472"
"17676","106.02000","8.83528","0.00414"
"17714","106.24800","8.85417","0.00436"
"17752","106.47600","8.87319","0.00473"
"17790","106.70400","8.89220","0.00482"
"17828","106.93200","8.91115","0.00353"
"17866","107.16000","8.93022","0.00424"
"17904","107.38800","8.94912","0.00481"
"17942","107.61600","8.96825","0.00403"
"17980","107.84400","8.98714","0.00402"
"18018","108.07200","9.00616","0.00423"
"18056","108.30000","9.02523","0.00469"
"18094","108.52800","9.04418","0.00406"
"18132","108.75600","9.06326","0.00439"
"18170","108.98400","9.08215","0.00442"
"18208","109.21200","9.10122","0.00378"
"18246","109.44000","9.12018","0.00466"
"18284","109.66800","9.13919","0.00517"
"18322","109.89600","9.15820","0.00490"
"18360","110.12400","9.17710","0.00498"
"18398","110.35200","9.19623","0.00502"
"18436","110.58000","9.21518","0.00481"
"18474","110.80800","9.23419","0.00511"
"18512","111.03600","9.25321","0.00513"
"18550","111.26400","9.27216","0.00505"
"18588","111.49200","9.29123","0.00487"
"18626","111.72000","9.31013","0.00487"
"18664","111.94800","9.32920","0.00508"
"18702","112.17600","9.34815","0.00573"
"18740","112.40400","9.36723","0.00548"
"18778","112.63200","9.38624","0.00513"
"18816","112.86000","9.40513","0.00552"
"18854","113.08800","9.42421","0.00620"
"18892","113.31600","9.44316","0.00564"
"18930","113.54400","9.46217","0.00570"
"18968","113.77200","9.48118","0.00513"
"19006","114.00000","9.50020","0.00493"
"19044","114.22800","9.51921","0.00525"
"19082","114.45600","9.53816","0.00569"
"19120","114.68400","9.55724","0.00599"
"19158","114.91200","9.57613","0.00588"
"19196","115.14000","9.59520","0.00611"
"19234","115.36800","9.61422","0.00555"
"19272","115.59600","9.63317","0.00580"
"19310","115.82400","9.65218","0.00572"
"19348","116.05200","9.67114","0.00612"
"19386","116.28000","9.69021","0.00613"
"19424","116.50800","9.70916","0.00614"
"19462","116.73600","9.72818","0.00649"
"19500","116.96400","9.74719","0.00587"
"19538","117.19200","9.76614","0.00679"
"19576","117.42000","9.78521","0.00599"
"19614","117.64800","9.80423","0.00617"
"19652","117.87600","9.82318","0.00616"
"19690","118.10400","9.84213","0.00670"
"19728","118.33200","9.86121","0.00647"
"19766","118.56000","9.88022","0.00654"
"19804","118.78800","9.89917","0.00646"
"19842","119.01600","9.91819","0.00670"
"19880","119.24400","9.93720","0.00674"
"19918","119.47200","9.95621","0.00740"
"19956","119.70000","9.97517","0.00702"
"19994","119.92800","9.99418","0.00674"
"20032","120.15600","10.01313","0.00647"
"20070","120.38400","10.03221","0.00745"
"20108","120.61200","10.05122","0.00743"
"20146","120.84000","10.07017","0.00702"
"20184","121.06800","10.08918","0.00726"
"20222","121.29600","10.10814","0.00768"
"20260","121.52400","10.12721","0.00723"
"20298","121.75200","10.14622","0.00741"
"20336","121.98000","10.16518","0.00778"
"20374","122.20800","10.18419","0.00752"
"20412","122.43600","10.20314","0.00798"
"20450","122.66400","10.22222","0.00723"
"20488","122.89200","10.24117","0.00801"
"20526","123.12000","10.26024","0.00791"
"20564","123.34800","10.27920","0.00824"
"20602","123.57600","10.29815","0.00806"
"20640","123.80400","10.31722","0.00832"
"20678","124.03200","10.33618","0.00749"
"20716","124.26000","10.35525","0.00780"
"20754","124.48800","10.37414","0.00850"
"20792","124.71600","10.39321","0.00834"
"20830","124.94400","10.41223","0.00832"
"20868","125.17200","10.43112","0.00824"
"20906","125.40000","10.45025","0.00837"
"20944","125.62800","10.46921","0.00845"
"20982","125.85600","10.48822","0.00842"
"21020","126.08400","10.50723","0.00847"
"21058","126.31200","10.52619","0.00906"
"21096","126.54000","10.54526","0.00910"
"21134","126.76800","10.56415","0.00898"
"21172","126.99600","10.58322","0.00867"
"21210","127.22400","10.60218","0.00888"
"21248","127.45200","10.62113","0.00900"
"21286","127.68000","10.64020","0.00917"
"21324","127.90800","10.65916","0.00898"
"21362","128.13600","10.67823","0.00943"
"21400","128.36400","10.69712","0.00984"
"21438","128.59200","10.71620","0.01007"
"21476","128.82000","10.73515","0.00938"
"21514","129.04800","10.75416","0.00931"
"21552","129.27600","10.77324","0.00979"
"21590","129.50400","10.79219","0.01047"
"21628","129.73200","10.81120","0.01026"
"21666","129.96000","10.83016","0.01008"
"21704","130.18800","10.84923","0.01045"
"21742","130.41600","10.86824","0.01016"
"21780","130.64400","10.88720","0.01041"
"21818","130.87200","10.90615","0.01024"
"21856","131.10000","10.92510","0.01112"
"21894","131.32800","10.94423","0.01022"
"21932","131.55600","10.96319","0.00993"
"21970","131.78400","10.98226","0.01012"
"22008","132.01200","11.00127","0.01050"
"22046","132.24000","11.02017","0.01073"
"22084","132.46800","11.03924","0.01049"
"22122","132.69600","11.05813","0.01097"
"22160","132.92400","11.07721","0.01106"
"22198","133.15200","11.09622","0.01142"
"22236","133.38000","11.11517","0.01131"
"22274","133.60800","11.13425","0.01117"
"22312","133.83600","11.15314","0.01130"
"22350","134.06400","11.17221","0.01048"
"22388","134.29200","11.19116","0.01061"
"22426","134.52000","11.21018","0.01129"
"22464","134.74800","11.22919","0.01126"
"22502","134.97600","11.24815","0.01103"
"22540","135.20400","11.26722","0.00707"
"22578","135.43200","11.28611","0.00778"
"22616","135.66000","11.30524","0.00758"
"22654","135.88800","11.32420","0.00770"
"22692","136.11600","11.34321","0.00937"
"22730","136.34400","11.36216","0.00914"
"22768","136.57200","11.38118","0.00964"
"22806","136.80000","11.40019","0.00578"
"22844","137.02800","11.41920","0.00531"
"22882","137.25600","11.43822","0.00589"
"22920","137.48400","11.45717","0.00503"
"22958","137.71200","11.47618","0.00544"
"22996","137.94000","11.49514","0.00465"
"23034","138.16800","11.51421","0.00479"
"23072","138.39600","11.53322","0.00502"
"23110","138.62400","11.55212","0.00534"
"23148","138.85200","11.57119","0.00507"
"23186","139.08000","11.59014","0.00518"
"23224","139.30800","11.60921","0.00596"
"23262","139.53600","11.62823","0.00506"
"23300","139.76400","11.64724","0.00656"
"23338","139.99200","11.66619","0.00494"
"23376","140.22000","11.68515","0.00569"
"23414","140.44800","11.70422","0.00616"
"23452","140.67600","11.72317","0.00637"
"23490","140.90400","11.74225","0.00690"
"23528","141.13200","11.76114","0.00624"
"23566","141.36000","11.78015","0.00729"
"23604","141.58800","11.79922","0.00627"
"23642","141.81600","11.81812","0.00727"
"23680","142.04400","11.83725","0.00702"
"23718","142.27200","11.85614","0.00722"
"23756","142.50000","11.87522","0.00732"
"23794","142.72800","11.89423","0.00726"
"23832","142.95600","11.91318","0.00833"
"23870","143.18400","11.93220","0.00810"
"23908","143.41200","11.95121","0.00844"
"23946","143.64000","11.97022","0.00887"
"23984","143.86800","11.98918","0.00904"
"24022","144.09600","12.00819","0.00904"
"24060","144.32400","12.02726","0.00904"
"24098","144.55200","12.04610","0.01045"
"24136","144.78000","12.06523","0.01019"
"24174","145.00800","12.08418","0.01093"
"24212","145.23600","12.10319","0.01006"
"24250","145.46400","12.12221","0.01061"
"24288","145.69200","12.14110","0.01074"
"24326","145.92000","12.16023","0.01094"
"24364","146.14800","12.17913","0.01094"
"24402","146.37600","12.19820","0.01078"
"24440","146.60400","12.21715","0.01121"
"24478","146.83200","12.23617","0.01190"
"24516","147.06000","12.25518","0.01213"
"24554","147.28800","12.27419","0.01195"
"24592","147.51600","12.29327","0.01210"
"24630","147.74400","12.31216","0.01210"
"24668","147.97200","12.33123","0.01294"
"24706","148.20000","12.35018","0.01261"
"24744","148.42800","12.36920","0.01294"
"24782","148.65600","12.38827","0.01262"
"24820","148.88400","12.40711","0.01364"
"24858","149.11200","12.42624","0.01356"
"24896","149.34000","12.44513","0.01355"
"24934","149.56800","12.46426","0.01424"
"24972","149.79600","12.48322","0.01414"
"25010","150.02400","12.50217","0.01433"
"25048","150.25200","12.52124","0.01417"
"25086","150.48000","12.54014","0.01416"
"25124","150.70800","12.55921","0.01495"
"25162","150.93600","12.57816","0.01525"
"25200","151.16400","12.59718","0.01508"
"25238","151.39200","12.61625","0.01514"
"25276","151.62000","12.63514","0.01562"
"25314","151.84800","12.65421","0.01578"
"25352","152.07600","12.67317","0.01533"
"25390","152.30400","12.69218","0.01566"
"25428","152.53200","12.71119","0.01643"
"25466","152.76000","12.73021","0.01640"
"25504","152.98800","12.74922","0.01615"
"25542","153.21600","12.76817","0.01651"
"25580","153.44400","12.78719","0.01708"
"25618","153.67200","12.80620","0.01677"
"25656","153.90000","12.82515","0.01719"
"25694","154.12800","12.84417","0.01725"
"25732","154.35600","12.86318","0.01748"
"25770","154.58400","12.88219","0.01764"
"25808","154.81200","12.90121","0.01803"
"25846","155.04000","12.92022","0.01825"
"25884","155.26800","12.93917","0.01863"
"25922","155.49600","12.95819","0.01825"
"25960","155.72400","12.97720","0.01837"
"25998","155.95200","12.99621","0.01918"
"26036","156.18000","13.01517","0.01931"
"26074","156.40800","13.03418","0.01934"
"26112","156.63600","13.05319","0.01963"
"26150","156.86400","13.07215","0.02007"
"26188","157.09200","13.09122","0.01993"
"26226","157.32000","13.11017","0.02057"
"26264","157.54800","13.12924","0.02107"
"26302","157.77600","13.14820","0.02055"
"26340","158.00400","13.16709","0.02064"
"26378","158.23200","13.18622","0.02153"
"26416","158.46000","13.20518","0.02131"
"26454","158.68800","13.22419","0.02109"
"26492","158.91600","13.24314","0.02168"
"26530","159.14400","13.26216","0.02196"
"26568","159.37200","13.28123","0.02242"
"26606","159.60000","13.30012","0.02274"
"26644","159.82800","13.31919","0.02282"
"26682","160.05600","13.33815","0.02286"
"26720","160.28400","13.35722","0.02365"
"26758","160.51200","13.37617","0.02372"
"26796","160.74000","13.39519","0.02411"
"26834","160.96800","13.41420","0.02425"
"26872","161.19600","13.43309","0.02451"
"26910","161.42400","13.45229","0.02451"
"26948","161.65200","13.47118","0.02479"
"26986","161.88000","13.49019","0.02531"
"27024","162.10800","13.50921","0.02556"
"27062","162.33600","13.52822","0.02639"
"27100","162.56400","13.54723","0.02654"
"27138","162.79200","13.56612","0.02697"
"27176","163.02000","13.58526","0.02738"
"27214","163.24800","13.60415","0.02781"
"27252","163.47600","13.62322","0.02796"
"27290","163.70400","13.64218","0.02840"
"27328","163.93200","13.66113","0.02896"
"27366","164.16000","13.68020","0.02941"
"27404","164.38800","13.69910","0.02969"
"27442","164.61600","13.71823","0.02957"
"27480","164.84400","13.73724","0.03028"
"27518","165.07200","13.75620","0.03134"
"27556","165.30000","13.77521","0.03184"
"27594","165.52800","13.79410","0.03219"
"27632","165.75600","13.81324","0.03223"
"27670","165.98400","13.83219","0.03266"
"27708","166.21200","13.85120","0.03290"
"27746","166.44000","13.87022","0.03283"
"27784","166.66800","13.88911","0.03351"
"27822","166.89600","13.90818","0.03416"
"27860","167.12400","13.92714","0.03410"
"27898","167.35200","13.94621","0.03460"
"27936","167.58000","13.96516","0.03569"
"27974","167.80800","13.98417","0.03514"
"28012","168.03600","14.00325","0.03591"
"28050","168.26400","14.02214","0.03654"
"28088","168.49200","14.04121","0.03732"
"28126","168.72000","14.06017","0.03780"
"28164","168.94800","14.07918","0.03766"
"28202","169.17600","14.09819","0.03789"
"28240","169.40400","14.11721","0.03863"
"28278","169.63200","14.13622","0.03904"
"28316","169.86000","14.15517","0.03917"
"28354","170.08800","14.17418","0.03958"
"28392","170.31600","14.19320","0.03949"
"28430","170.54400","14.21221","0.04020"
"28468","170.77200","14.23123","0.04073"
"28506","171.00000","14.25018","0.04098"
"28544","171.22800","14.26925","0.04139"
"28582","171.45600","14.28815","0.04209"
"28620","171.68400","14.30716","0.04242"
"28658","171.91200","14.32617","0.04233"
"28696","172.14000","14.34518","0.04345"
"28734","172.36800","14.36414","0.04406"
"28772","172.59600","14.38321","0.04370"
"28810","172.82400","14.40222","0.04491"
"28848","173.05200","14.42118","0.04485"
"28886","173.28000","14.44019","0.04573"
"28924","173.50800","14.45914","0.04619"
"28962","173.73600","14.47822","0.04691"
"29000","173.96400","14.49717","0.04780"
"29038","174.19200","14.51618","0.04804"
"29076","174.42000","14.53519","0.04879"
"29114","174.64800","14.55415","0.04882"
"29152","174.87600","14.57322","0.05034"
"29190","175.10400","14.59223","0.05022"
"29228","175.33200","14.61119","0.05180"
"29266","175.56000","14.63020","0.05204"
"29304","175.78800","14.64915","0.05267"
"29342","176.01600","14.66823","0.05349"
"29380","176.24400","14.68718","0.05368"
"29418","176.47200","14.70619","0.05443"
"29456","176.70000","14.72515","0.05435"
"29494","176.92800","14.74422","0.05564"
"29532","177.15600","14.76323","0.05650"
"29570","177.38400","14.78218","0.05742"
"29608","177.61200","14.80120","0.05802"
"29646","177.84000","14.82015","0.05822"
"29684","178.06800","14.83922","0.05917"
"29722","178.29600","14.85818","0.05937"
"29760","178.52400","14.87719","0.06018"
"29798","178.75200","14.89620","0.06057"
"29836","178.98000","14.91516","0.06094"
"29874","179.20800","14.93417","0.06164"
"29912","179.43600","14.95318","0.06214"
"29950","179.66400","14.97220","0.06271"
"29988","179.89200","14.99121","0.06311"
"30026","180.12000","15.01016","0.06357"
"30064","180.34800","15.02924","0.06411"
"30102","180.57600","15.04819","0.06437"
"30140","180.80400","15.06726","0.06488"
"30178","181.03200","15.08615","0.06533"
"30216","181.26000","15.10517","0.06601"
"30254","181.48800","15.12424","0.06615"
"30292","181.71600","15.14314","0.06662"
"30330","181.94400","15.16221","0.06701"
"30368","182.17200","15.18116","0.06731"
"30406","182.40000","15.20017","0.06778"
"30444","182.62800","15.21919","0.06796"
"30482","182.85600","15.23820","0.06872"
"30520","183.08400","15.25721","0.06894"
"30558","183.31200","15.27617","0.06930"
"30596","183.54000","15.29524","0.06940"
"30634","183.76800","15.31419","0.06985"
"30672","183.99600","15.33327","0.07004"
"30710","184.22400","15.35222","0.07050"
"30748","184.45200","15.37117","0.07110"
"30786","184.68000","15.39018","0.07134"
"30824","184.90800","15.40914","0.07170"
"30862","185.13600","15.42821","0.07212"
"30900","185.36400","15.44716","0.07233"
"30938","185.59200","15.46624","0.07305"
"30976","185.82000","15.48525","0.07337"
"31014","186.04800","15.50414","0.07402"
"31052","186.27600","15.52322","0.07357"
"31090","186.50400","15.54217","0.07486"
"31128","186.73200","15.56118","0.07550"
"31166","186.96000","15.58020","0.07600"
"31204","187.18800","15.59921","0.07671"
"31242","187.41600","15.61822","0.07743"
"31280","187.64400","15.63717","0.07837"
"31318","187.87200","15.65619","0.07883"
"31356","188.10000","15.67520","0.07975"
"31394","188.32800","15.69427","0.08025"
"31432","188.55600","15.71323","0.08111"
"31470","188.78400","15.73218","0.08198"
"31508","189.01200","15.75113","0.08221"
"31546","189.24000","15.77015","0.08341"
"31584","189.46800","15.78916","0.08412"
"31622","189.69600","15.80817","0.08507"
"31660","189.92400","15.82719","0.08643"
"31698","190.15200","15.84614","0.08674"
"31736","190.38000","15.86521","0.08787"
"31774","190.60800","15.88422","0.08864"
"31812","190.83600","15.90318","0.08927"
"31850","191.06400","15.92219","0.09051"
"31888","191.29200","15.94120","0.09164"
"31926","191.52000","15.96022","0.09222"
"31964","191.74800","15.97923","0.09383"
"32002","191.97600","15.99818","0.09540"
"32040","192.20400","16.01720","0.09561"
"32078","192.43200","16.03615","0.09729"
"32116","192.66000","16.05522","0.09797"
"32154","192.88800","16.07418","0.09962"
"32192","193.11600","16.09319","0.10054"
"32230","193.34400","16.11214","0.10152"
"32268","193.57200","16.13121","0.10361"
"32306","193.80000","16.15023","0.10507"
"32344","194.02800","16.16918","0.10728"
"32382","194.25600","16.18819","0.10878"
"32420","194.48400","16.20715","0.10949"
"32458","194.71200","16.22616","0.11047"
"32496","194.94000","16.24517","0.11239"
"32534","195.16800","16.26419","0.11384"
"32572","195.39600","16.28320","0.11488"
"32610","195.62400","16.30215","0.11645"
"32648","195.85200","16.32123","0.11796"
"32686","196.08000","16.34024","0.11837"
"32724","196.30800","16.35919","0.11926"
"32762","196.53600","16.37815","0.12075"
"32800","196.76400","16.39710","0.12145"
"32838","196.99200","16.41623","0.12380"
"32876","197.22000","16.43519","0.12456"
"32914","197.44800","16.45426","0.12596"
"32952","197.67600","16.47315","0.12655"
"32990","197.90400","16.49217","0.12757"
"33028","198.13200","16.51124","0.12916"
"33066","198.36000","16.53013","0.13022"
"33104","198.58800","16.54920","0.13160"
"33142","198.81600","16.56816","0.13324"
"33180","199.04400","16.58723","0.13421"
"33218","199.27200","16.60618","0.13453"
"33256","199.50000","16.62520","0.13700"
"33294","199.72800","16.64421","0.13736"
"33332","199.95600","16.66316","0.13908"
"33370","200.18400","16.68224","0.13936"
"33408","200.41200","16.70119","0.14066"
"33446","200.64000","16.72020","0.14234"
"33484","200.86800","16.73922","0.14308"
"33522","201.09600","16.75817","0.14319"
"33560","201.32400","16.77724","0.14358"
"33598","201.55200","16.79613","0.14547"
"33636","201.78000","16.81521","0.14599"
"33674","202.00800","16.83416","0.14755"
"33712","202.23600","16.85312","0.14819"
"33750","202.46400","16.87225","0.14913"
"33788","202.69200","16.89108","0.15070"
"33826","202.92000","16.91021","0.15150"
"33864","203.14800","16.92923","0.15337"
"33902","203.37600","16.94824","0.15443"
"33940","203.60400","16.96719","0.15575"
"33978","203.83200","16.98621","0.15732"
"34016","204.06000","17.00522","0.15873"
"34054","204.28800","17.02411","0.15972"
"34092","204.51600","17.04313","0.16101"
"34130","204.74400","17.06220","0.16214"
"34168","204.97200","17.08121","0.16329"
"34206","205.20000","17.10016","0.16442"
"34244","205.42800","17.11918","0.16536"
"34282","205.65600","17.13825","0.16569"
"34320","205.88400","17.15720","0.16712"
"34358","206.11200","17.17616","0.16786"
"34396","206.34000","17.19517","0.16875"
"34434","206.56800","17.21418","0.16968"
"34472","206.79600","17.23320","0.17090"
"34510","207.02400","17.25221","0.17229"
"34548","207.25200","17.27122","0.17343"
"34586","207.48000","17.29012","0.17447"
"34624","207.70800","17.30925","0.17555"
"34662","207.93600","17.32820","0.17627"
"34700","208.16400","17.34722","0.17714"
"34738","208.39200","17.36623","0.17785"
"34776","208.62000","17.38518","0.17850"
"34814","208.84800","17.40420","0.17896"
"34852","209.07600","17.42315","0.17959"
"34890","209.30400","17.44222","0.18056"
"34928","209.53200","17.46124","0.18064"
"34966","209.76000","17.48025","0.18167"
"35004","209.98800","17.49920","0.18218"
"35042","210.21600","17.51815","0.18278"
"35080","210.44400","17.53717","0.18395"
"35118","210.67200","17.55612","0.18497"
"35156","210.90000","17.57519","0.18580"
"35194","211.12800","17.59421","0.18743"
"35232","211.35600","17.61316","0.08215"
"35270","211.58400","17.63223","0.07876"
"35308","211.81200","17.65119","0.07874"
"35346","212.04000","17.67020","0.08101"
"35384","212.26800","17.68915","0.07922"
"35422","212.49600","17.70823","0.08305"
"35460","212.72400","17.72718","0.08367"
"35498","212.95200","17.74619","0.08504"
"35536","213.18000","17.76520","0.08316"
"35574","213.40800","17.78416","0.08371"
"35612","213.63600","17.80323","0.08843"
"35650","213.86400","17.82218","0.06183"
"35688","214.09200","17.84120","0.01693"
"35726","214.32000","17.86021","0.01164"
"35764","214.54800","17.87922","0.01555"
"35802","214.77600","17.89824","0.01968"
"35840","215.00400","17.91713","0.01639"
"35878","215.23200","17.93620","0.01284"
"35916","215.46000","17.95510","0.02268"
"35954","215.68800","17.97417","0.01191"
"35992","215.91600","17.99318","0.02108"
"36030","216.14400","18.01213","0.01598"
"36068","216.37200","18.03127","0.01614"
"36106","216.60000","18.05016","0.02211"
"36144","216.82800","18.06923","0.01375"
"36182","217.05600","18.08819","0.02401"
"36220","217.28400","18.10720","0.01627"
"36258","217.51200","18.12627","0.02154"
"36296","217.74000","18.14511","0.01937"
"36334","217.96800","18.16424","0.01926"
"36372","218.19600","18.18313","0.02194"
"36410","218.42400","18.20226","0.01911"
"36448","218.65200","18.22122","0.02311"
"36486","218.88000","18.24017","0.01955"
"36524","219.10800","18.25918","0.02344"
"36562","219.33600","18.27814","0.02108"
"36600","219.56400","18.29721","0.02359"
"36638","219.79200","18.31616","0.02240"
"36676","220.02000","18.33518","0.02411"
"36714","220.24800","18.35419","0.02432"
"36752","220.47600","18.37314","0.02438"
"36790","220.70400","18.39222","0.02507"
"36828","220.93200","18.41111","0.02544"
"36866","221.16000","18.43018","0.02563"
"36904","221.38800","18.44920","0.02579"
"36942","221.61600","18.46821","0.02691"
"36980","221.84400","18.48722","0.02703"
"37018","222.07200","18.50611","0.02821"
"37056","222.30000","18.52519","0.02761"
"37094","222.52800","18.54420","0.02980"
"37132","222.75600","18.56327","0.02859"
"37170","222.98400","18.58223","0.03149"
"37208","223.21200","18.60118","0.02954"
"37246","223.44000","18.62020","0.03168"
"37284","223.66800","18.63915","0.03089"
"37322","223.89600","18.65816","0.03281"
"37360","224.12400","18.67717","0.03266"
"37398","224.35200","18.69619","0.03340"
"37436","224.58000","18.71520","0.03363"
"37474","224.80800","18.73421","0.03521"
"37512","225.03600","18.75317","0.03499"
"37550","225.26400","18.77218","0.03592"
"37588","225.49200","18.79113","0.03633"
"37626","225.72000","18.81015","0.03746"
"37664","225.94800","18.82916","0.03733"
"37702","226.17600","18.84817","0.03871"
"37740","226.40400","18.86719","0.03865"
"37778","226.63200","18.88626","0.03890"
"37816","226.86000","18.90515","0.03951"
"37854","227.08800","18.92422","0.04058"
"37892","227.31600","18.94318","0.04082"
"37930","227.54400","18.96219","0.04183"
"37968","227.77200","18.98120","0.04261"
"38006","228.00000","19.00016","0.04398"
"38044","228.22800","19.01923","0.04377"
"38082","228.45600","19.03812","0.04470"
"38120","228.68400","19.05725","0.04542"
"38158","228.91200","19.07621","0.04645"
"38196","229.14000","19.09522","0.04739"
"38234","229.36800","19.11418","0.04834"
"38272","229.59600","19.13319","0.04929"
"38310","229.82400","19.15220","0.05013"
"38348","230.05200","19.17116","0.05092"
"38386","230.28000","19.19023","0.05144"
"38424","230.50800","19.20918","0.05304"
"38462","230.73600","19.22819","0.05387"
"38500","230.96400","19.24715","0.05457"
"38538","231.19200","19.26616","0.05555"
"38576","231.42000","19.28523","0.05695"
"38614","231.64800","19.30419","0.05753"
"38652","231.87600","19.32320","0.05837"
"38690","232.10400","19.34221","0.05957"
"38728","232.33200","19.36117","0.06030"
"38766","232.56000","19.38018","0.06184"
"38804","232.78800","19.39913","0.06169"
"38842","233.01600","19.41821","0.06267"
"38880","233.24400","19.43710","0.06325"
"38918","233.47200","19.45623","0.06448"
"38956","233.70000","19.47518","0.06509"
"38994","233.92800","19.49414","0.06588"
"39032","234.15600","19.51321","0.06659"
"39070","234.38400","19.53210","0.06670"
"39108","234.61200","19.55124","0.06705"
"39146","234.84000","19.57013","0.06789"
"39184","235.06800","19.58920","0.06821"
"39222","235.29600","19.60822","0.06845"
"39260","235.52400","19.62717","0.06917"
"39298","235.75200","19.64624","0.06936"
"39336","235.98000","19.66514","0.07060"
"39374","236.20800","19.68421","0.07069"
"39412","236.43600","19.70316","0.07121"
"39450","236.66400","19.72217","0.06611"
"39488","236.89200","19.74125","0.06750"
"39526","237.12000","19.76014","0.06436"
"39564","237.34800","19.77921","0.06800"
"39602","237.57600","19.79817","0.06604"
"39640","237.80400","19.81718","0.06784"
"39678","238.03200","19.83619","0.06709"
"39716","238.26000","19.85521","0.06817"
"39754","238.48800","19.87422","0.06835"
"39792","238.71600","19.89311","0.06841"
"39830","238.94400","19.91225","0.06989"
"39868","239.17200","19.93120","0.06892"
"39906","239.40000","19.95021","0.07096"
"39944","239.62800","19.96917","0.06996"
"39982","239.85600","19.98818","0.07214"
"40020","240.08400","20.00725","0.07039"
"40058","240.31200","20.02620","0.07246"
"40096","240.54000","20.04522","0.07150"
"40134","240.76800","20.06423","0.07320"
"40172","240.99600","20.08313","0.07270"
"40210","241.22400","20.10220","0.07390"
"40248","241.45200","20.12115","0.07388"
"40286","241.68000","20.14022","0.07490"
"40324","241.90800","20.15918","0.07481"
"40362","242.13600","20.17819","0.07590"
"40400","242.36400","20.19720","0.07676"
"40438","242.59200","20.21622","0.07725"
"40476","242.82000","20.23517","0.07798"
"40514","243.04800","20.25412","0.07860"
"40552","243.27600","20.27325","0.07989"
"40590","243.50400","20.29215","0.08021"
"40628","243.73200","20.31122","0.08189"
"40666","243.96000","20.33018","0.08220"
"40704","244.18800","20.34919","0.08400"
"40742","244.41600","20.36820","0.08372"
"40780","244.64400","20.38715","0.08550"
"40818","244.87200","20.40623","0.08528"
"40856","245.10000","20.42518","0.08811"
"40894","245.32800","20.44413","0.08829"
"40932","245.55600","20.46315","0.09051"
"40970","245.78400","20.48222","0.08986"
"41008","246.01200","20.50123","0.09284"
"41046","246.24000","20.52019","0.09304"
"41084","246.46800","20.53920","0.09578"
"41122","246.69600","20.55815","0.09651"
"41160","246.92400","20.57723","0.09818"
"41198","247.15200","20.59624","0.09890"
"41236","247.38000","20.61519","0.10143"
"41274","247.60800","20.63421","0.10329"
"41312","247.83600","20.65316","0.10557"
"41350","248.06400","20.67223","0.10748"
"41388","248.29200","20.69118","0.10974"
"41426","248.52000","20.71020","0.11007"
"41464","248.74800","20.72921","0.11264"
"41502","248.97600","20.74817","0.11392"
"41540","249.20400","20.76717","0.11620"
"41578","249.43200","20.78613","0.11768"
"41616","249.66000","20.80526","0.11892"
"41654","249.88800","20.82416","0.12014"
"41692","250.11600","20.84323","0.12152"
"41730","250.34400","20.86218","0.12283"
"41768","250.57200","20.88114","0.12465"
"41806","250.80000","20.90021","0.12545"
"41844","251.02800","20.91922","0.12737"
"41882","251.25600","20.93823","0.12911"
"41920","251.48400","20.95719","0.13035"
"41958","251.71200","20.97620","0.13115"
"41996","251.94000","20.99521","0.13289"
"42034","252.16800","21.01410","0.13372"
"42072","252.39600","21.03324","0.13495"
"42110","252.62400","21.05219","0.13645"
"42148","252.85200","21.07121","0.13755"
"42186","253.08000","21.09016","0.13925"
"42224","253.30800","21.10917","0.14000"
"42262","253.53600","21.12825","0.14081"
"42300","253.76400","21.14708","0.14225"
"42338","253.99200","21.16621","0.14357"
"42376","254.22000","21.18517","0.14455"
"42414","254.44800","21.20418","0.14537"
"42452","254.67600","21.22319","0.14652"
"42490","254.90400","21.24215","0.14722"
"42528","255.13200","21.26122","0.14839"
"42566","255.36000","21.28017","0.14956"
"42604","255.58800","21.29918","0.15043"
"42642","255.81600","21.31820","0.15212"
"42680","256.04400","21.33715","0.15383"
"42718","256.27200","21.35616","0.04129"
"42756","256.50000","21.37512","0.07749"
"42794","256.72800","21.39419","0.06254"
"42832","256.95600","21.41320","0.05226"
"42870","257.18400","21.43222","0.06631"
"42908","257.41200","21.45123","0.04415"
"42946","257.64000","21.47018","0.06784"
"42984","257.86800","21.48919","0.05720"
"43022","258.09600","21.50809","0.04766"
"43060","258.32400","21.52716","0.07184"
"43098","258.55200","21.54618","0.05141"
"43136","258.78000","21.56519","0.06504"
"43174","259.00800","21.58426","0.05671"
"43212","259.23600","21.60321","0.05141"
"43250","259.46400","21.62223","0.07246"
"43288","259.69200","21.64112","0.05923"
"43326","259.92000","21.66019","0.06197"
"43364","260.14800","21.67914","0.06626"
"43402","260.37600","21.69822","0.05672"
"43440","260.60400","21.71723","0.07289"
"43478","260.83200","21.73619","0.06221"
"43516","261.06000","21.75526","0.06510"
"43554","261.28800","21.77415","0.06921"
"43592","261.51600","21.79323","0.06514"
"43630","261.74400","21.81218","0.07480"
"43668","261.97200","21.83113","0.06417"
"43706","262.20000","21.85020","0.06810"
"43744","262.42800","21.86916","0.07015"
"43782","262.65600","21.88823","0.06632"
"43820","262.88400","21.90713","0.07869"
"43858","263.11200","21.92620","0.06731"
"43896","263.34000","21.94515","0.07046"
"43934","263.56800","21.96416","0.07147"
"43972","263.79600","21.98324","0.06893"
"44010","264.02400","22.00219","0.07986"
"44048","264.25200","22.02120","0.06903"
"44086","264.48000","22.04016","0.07547"
"44124","264.70800","22.05923","0.07176"
"44162","264.93600","22.07818","0.07037"
"44200","265.16400","22.09719","0.08096"
"44238","265.39200","22.11621","0.07176"
"44276","265.62000","22.13516","0.08165"
"44314","265.84800","22.15423","0.07227"
"44352","266.07600","22.17319","0.07398"
"44390","266.30400","22.19226","0.07953"
"44428","266.53200","22.21115","0.07369"
"44466","266.76000","22.23017","0.08656"
"44504","266.98800","22.24924","0.07442"
"44542","267.21600","22.26813","0.08129"
"44580","267.44400","22.28727","0.07764"
"44618","267.67200","22.30616","0.07685"
"44656","267.90000","22.32523","0.08699"
"44694","268.12800","22.34419","0.07674"
"44732","268.35600","22.36314","0.08928"
"44770","268.58400","22.38221","0.07793"
"44808","268.81200","22.40110","0.08271"
"44846","269.04000","22.42024","0.08257"
"44884","269.26800","22.43913","0.07919"
"44922","269.49600","22.45820","0.09079"
"44960","269.72400","22.47722","0.07911"
"44998","269.95200","22.49611","0.09118"
"45036","270.18000","22.51530","0.08061"
"45074","270.40800","22.53414","0.08538"
"45112","270.63600","22.55321","0.08638"
"45150","270.86400","22.57216","0.08196"
"45188","271.09200","22.59118","0.09261"
"45226","271.32000","22.61025","0.08177"
"45264","271.54800","22.62908","0.09284"
"45302","271.77600","22.64822","0.08319"
"45340","272.00400","22.66717","0.08723"
"45378","272.23200","22.68624","0.08832"
"45416","272.46000","22.70520","0.08422"
"45454","272.68800","22.72415","0.09608"
"45492","272.91600","22.74328","0.08428"
"45530","273.14400","22.76211","0.09571"
"45568","273.37200","22.78125","0.08617"
"45606","273.60000","22.80020","0.09126"
"45644","273.82800","22.81921","0.09073"
"45682","274.05600","22.83823","0.08719"
"45720","274.28400","22.85712","0.09856"
"45758","274.51200","22.87625","0.08735"
"45796","274.74000","22.89515","0.09949"
"45834","274.96800","22.91422","0.08832"
"45872","275.19600","22.93317","0.09497"
"45910","275.42400","22.95219","0.09307"
"45948","275.65200","22.97114","0.09120"
"45986","275.88000","22.99015","0.09936"
"46024","276.10800","23.00923","0.09068"
"46062","276.33600","23.02812","0.10433"
"46100","276.56400","23.04719","0.09115"
"46138","276.79200","23.06620","0.10025"
"46176","277.02000","23.08522","0.09454"
"46214","277.24800","23.10417","0.09655"
"46252","277.47600","23.12312","-0.00952"
"46290","277.70400","23.14220","0.00943"
"46328","277.93200","23.16121","0.00156"
"46366","278.16000","23.18022","0.00022"
"46404","278.38800","23.19917","0.00523"
"46442","278.61600","23.21813","0.00072"
"46480","278.84400","23.23720","0.00006"
"46518","279.07200","23.25622","0.00316"
"46556","279.30000","23.27517","0.00099"
"46594","279.52800","23.29418","0.00098"
"46632","279.75600","23.31319","0.00254"
"46670","279.98400","23.33221","0.00105"
"46708","280.21200","23.35122","0.00145"
"46732","280.35400","23.36306","0.00234"