File: Trajectories_together/170122_1Specimen_RawData_8.csv
"","V1","V2","V3"
"1","End date","1/22/2017",""
"2","Specimen label","18BG_46 run 2",""
"3","Maximum Load","0.06005","N"
"4","Time","Extension","Load"
"5","(s)","(mm)","(N)"
"6","0.00000","29.39702","0.04281"
"35","0.17400","29.40706","0.04283"
"64","0.34800","29.42584","0.04377"
"93","0.52200","29.44085","0.04488"
"122","0.69600","29.45520","0.04509"
"151","0.87000","29.46972","0.04520"
"180","1.04400","29.48425","0.04544"
"209","1.21800","29.49872","0.04627"
"238","1.39200","29.51319","0.04665"
"267","1.56600","29.52766","0.04660"
"296","1.74000","29.54225","0.04751"
"325","1.91400","29.55666","0.04726"
"354","2.08800","29.57119","0.04655"
"383","2.26200","29.58572","0.04732"
"412","2.43600","29.60018","0.04744"
"441","2.61000","29.61472","0.04757"
"470","2.78400","29.62924","0.04763"
"499","2.95800","29.64371","0.04745"
"528","3.13200","29.65818","0.04817"
"557","3.30600","29.67271","0.04800"
"586","3.48000","29.68718","0.04839"
"615","3.65400","29.70165","0.04857"
"644","3.82800","29.71618","0.04869"
"673","4.00200","29.73070","0.04875"
"702","4.17600","29.74517","0.04853"
"731","4.35000","29.75964","0.04852"
"760","4.52400","29.77417","0.04907"
"789","4.69800","29.78858","0.04894"
"818","4.87200","29.80323","0.04928"
"847","5.04600","29.81770","0.04927"
"876","5.22000","29.83217","0.04922"
"905","5.39400","29.84670","0.04909"
"934","5.56800","29.86117","0.04913"
"963","5.74200","29.87564","0.04975"
"992","5.91600","29.89022","0.05028"
"1021","6.09000","29.90469","0.05022"
"1050","6.26400","29.91916","0.05013"
"1079","6.43800","29.93363","0.05054"
"1108","6.61200","29.94816","0.04998"
"1137","6.78600","29.96269","0.05063"
"1166","6.96000","29.97716","0.05097"
"1195","7.13400","29.99169","0.05096"
"1224","7.30800","30.00615","0.05117"
"1253","7.48200","30.02068","0.05061"
"1282","7.65600","30.03515","0.05091"
"1311","7.83000","30.04962","0.05097"
"1340","8.00400","30.06409","0.05127"
"1369","8.17800","30.07868","0.05140"
"1398","8.35200","30.09321","0.05176"
"1427","8.52600","30.10768","0.05153"
"1456","8.70000","30.12221","0.05173"
"1485","8.87400","30.13662","0.05221"
"1514","9.04800","30.15108","0.05125"
"1543","9.22200","30.16573","0.05219"
"1572","9.39600","30.18020","0.05194"
"1601","9.57000","30.19461","0.05174"
"1630","9.74400","30.20920","0.05212"
"1659","9.91800","30.22373","0.05228"
"1688","10.09200","30.23814","0.05220"
"1717","10.26600","30.25273","0.05203"
"1746","10.44000","30.26714","0.05189"
"1775","10.61400","30.28161","0.05247"
"1804","10.78800","30.29619","0.05254"
"1833","10.96200","30.31072","0.05233"
"1862","11.13600","30.32513","0.05277"
"1891","11.31000","30.33966","0.05287"
"1920","11.48400","30.35419","0.05245"
"1949","11.65800","30.36866","0.05316"
"1978","11.83200","30.38319","0.05305"
"2007","12.00600","30.39772","0.05302"
"2036","12.18000","30.41212","0.05353"
"2065","12.35400","30.42665","0.05349"
"2094","12.52800","30.44118","0.05322"
"2123","12.70200","30.45565","0.05375"
"2152","12.87600","30.47018","0.05375"
"2181","13.05000","30.48465","0.05332"
"2210","13.22400","30.49912","0.05336"
"2239","13.39800","30.51365","0.05379"
"2268","13.57200","30.52818","0.05346"
"2297","13.74600","30.54265","0.05350"
"2326","13.92000","30.55712","0.05375"
"2355","14.09400","30.57170","0.05381"
"2384","14.26800","30.58617","0.05369"
"2413","14.44200","30.60064","0.05384"
"2442","14.61600","30.61517","0.05392"
"2471","14.79000","30.62970","0.05429"
"2500","14.96400","30.64417","0.05423"
"2529","15.13800","30.65870","0.05427"
"2558","15.31200","30.67311","0.05426"
"2587","15.48600","30.68758","0.05370"
"2616","15.66000","30.70222","0.05416"
"2645","15.83400","30.71670","0.05436"
"2674","16.00800","30.73116","0.05348"
"2703","16.18200","30.74569","0.05337"
"2732","16.35600","30.76022","0.05338"
"2761","16.53000","30.77463","0.05361"
"2790","16.70400","30.78922","0.05308"
"2819","16.87800","30.80375","0.05351"
"2848","17.05200","30.81816","0.05425"
"2877","17.22600","30.83269","0.05374"
"2906","17.40000","30.84721","0.05376"
"2935","17.57400","30.86163","0.05380"
"2964","17.74800","30.87615","0.05358"
"2993","17.92200","30.89068","0.05419"
"3022","18.09600","30.90515","0.05396"
"3051","18.27000","30.91968","0.05404"
"3080","18.44400","30.93421","0.05421"
"3109","18.61800","30.94868","0.05378"
"3138","18.79200","30.96321","0.05397"
"3167","18.96600","30.97767","0.05404"
"3196","19.14000","30.99221","0.05434"
"3225","19.31400","31.00661","0.05400"
"3254","19.48800","31.02114","0.05458"
"3283","19.66200","31.03561","0.05447"
"3312","19.83600","31.05020","0.05462"
"3341","20.01000","31.06467","0.05479"
"3370","20.18400","31.07920","0.05432"
"3399","20.35800","31.09367","0.05470"
"3428","20.53200","31.10819","0.05474"
"3457","20.70600","31.12267","0.05478"
"3486","20.88000","31.13713","0.05464"
"3515","21.05400","31.15166","0.05471"
"3544","21.22800","31.16619","0.05469"
"3573","21.40200","31.18066","0.05474"
"3602","21.57600","31.19519","0.05480"
"3631","21.75000","31.20966","0.05491"
"3660","21.92400","31.22413","0.05521"
"3689","22.09800","31.23872","0.05486"
"3718","22.27200","31.25324","0.05526"
"3747","22.44600","31.26765","0.05531"
"3776","22.62000","31.28218","0.05480"
"3805","22.79400","31.29665","0.05494"
"3834","22.96800","31.31118","0.05535"
"3863","23.14200","31.32571","0.05519"
"3892","23.31600","31.34018","0.05531"
"3921","23.49000","31.35465","0.05524"
"3950","23.66400","31.36917","0.05523"
"3979","23.83800","31.38371","0.05533"
"4008","24.01200","31.39817","0.05543"
"4037","24.18600","31.41270","0.05549"
"4066","24.36000","31.42723","0.05588"
"4095","24.53400","31.44164","0.05570"
"4124","24.70800","31.45623","0.05541"
"4153","24.88200","31.47070","0.05566"
"4182","25.05600","31.48511","0.05571"
"4211","25.23000","31.49964","0.05595"
"4240","25.40400","31.51416","0.05602"
"4269","25.57800","31.52869","0.05598"
"4298","25.75200","31.54316","0.05594"
"4327","25.92600","31.55763","0.05570"
"4356","26.10000","31.57216","0.05577"
"4385","26.27400","31.58663","0.05612"
"4414","26.44800","31.60122","0.05612"
"4443","26.62200","31.61569","0.05636"
"4472","26.79600","31.63010","0.05612"
"4501","26.97000","31.64469","0.05567"
"4530","27.14400","31.65922","0.05648"
"4559","27.31800","31.67363","0.05618"
"4588","27.49200","31.68821","0.05597"
"4617","27.66600","31.70268","0.05645"
"4646","27.84000","31.71709","0.05622"
"4675","28.01400","31.73168","0.05619"
"4704","28.18800","31.74621","0.05612"
"4733","28.36200","31.76068","0.05601"
"4762","28.53600","31.77515","0.05625"
"4791","28.71000","31.78974","0.05639"
"4820","28.88400","31.80414","0.05639"
"4849","29.05800","31.81867","0.05667"
"4878","29.23200","31.83320","0.05629"
"4907","29.40600","31.84767","0.05630"
"4936","29.58000","31.86220","0.05647"
"4965","29.75400","31.87667","0.05217"
"4994","29.92800","31.89114","0.05179"
"5023","30.10200","31.90561","0.05231"
"5052","30.27600","31.92014","0.05198"
"5081","30.45000","31.93466","0.05248"
"5110","30.62400","31.94913","0.05303"
"5139","30.79800","31.96366","0.05238"
"5168","30.97200","31.97813","0.05263"
"5197","31.14600","31.99266","0.05315"
"5226","31.32000","32.00719","0.05341"
"5255","31.49400","32.02166","0.05337"
"5284","31.66800","32.03619","0.05320"
"5313","31.84200","32.05072","0.05339"
"5342","32.01600","32.06519","0.05309"
"5371","32.19000","32.07965","0.05306"
"5400","32.36400","32.09418","0.05350"
"5429","32.53800","32.10865","0.05374"
"5458","32.71200","32.12312","0.05364"
"5487","32.88600","32.13777","0.05349"
"5516","33.06000","32.15218","0.05340"
"5545","33.23400","32.16665","0.05339"
"5574","33.40800","32.18118","0.05333"
"5603","33.58200","32.19571","0.05331"
"5632","33.75600","32.21011","0.05341"
"5661","33.93000","32.22470","0.05371"
"5690","34.10400","32.23917","0.05348"
"5719","34.27800","32.25358","0.05385"
"5748","34.45200","32.26823","0.05346"
"5777","34.62600","32.28270","0.05374"
"5806","34.80000","32.29711","0.05350"
"5835","34.97400","32.31170","0.05417"
"5864","35.14800","32.32623","0.05365"
"5893","35.32200","32.34063","0.05388"
"5922","35.49600","32.35523","0.05406"
"5951","35.67000","32.36969","0.05404"
"5980","35.84400","32.38416","0.05394"
"6009","36.01800","32.39863","0.05362"
"6038","36.19200","32.41322","0.05415"
"6067","36.36600","32.42763","0.05393"
"6096","36.54000","32.44216","0.05430"
"6125","36.71400","32.45669","0.05355"
"6154","36.88800","32.47116","0.05355"
"6183","37.06200","32.48563","0.05387"
"6212","37.23600","32.50016","0.05383"
"6241","37.41000","32.51468","0.05419"
"6270","37.58400","32.52909","0.05338"
"6299","37.75800","32.54368","0.05410"
"6328","37.93200","32.55821","0.05368"
"6357","38.10600","32.57262","0.05419"
"6386","38.28000","32.58715","0.05430"
"6415","38.45400","32.60168","0.05458"
"6444","38.62800","32.61615","0.05462"
"6473","38.80200","32.63068","0.05466"
"6502","38.97600","32.64520","0.05473"
"6531","39.15000","32.65955","0.05465"
"6560","39.32400","32.67420","0.05449"
"6589","39.49800","32.68873","0.05476"
"6618","39.67200","32.70314","0.05480"
"6647","39.84600","32.71767","0.05462"
"6676","40.02000","32.73214","0.05468"
"6705","40.19400","32.74667","0.05492"
"6734","40.36800","32.76120","0.05497"
"6763","40.54200","32.77567","0.05549"
"6792","40.71600","32.79013","0.05532"
"6821","40.89000","32.80466","0.05511"
"6850","41.06400","32.81919","0.05522"
"6879","41.23800","32.83366","0.05505"
"6908","41.41200","32.84819","0.05524"
"6937","41.58600","32.86266","0.05549"
"6966","41.76000","32.87713","0.05531"
"6995","41.93400","32.89172","0.05528"
"7024","42.10800","32.90619","0.05590"
"7053","42.28200","32.92060","0.05564"
"7082","42.45600","32.93518","0.05567"
"7111","42.63000","32.94971","0.05582"
"7140","42.80400","32.96418","0.05547"
"7169","42.97800","32.97865","0.05543"
"7198","43.15200","32.99318","0.05530"
"7227","43.32600","33.00765","0.05506"
"7256","43.50000","33.02212","0.05575"
"7285","43.67400","33.03671","0.05549"
"7314","43.84800","33.05117","0.05546"
"7343","44.02200","33.06564","0.05555"
"7372","44.19600","33.08023","0.05619"
"7401","44.37000","33.09470","0.05577"
"7430","44.54400","33.10911","0.05563"
"7459","44.71800","33.12370","0.05592"
"7488","44.89200","33.13817","0.05591"
"7517","45.06600","33.15264","0.05608"
"7546","45.24000","33.16717","0.05619"
"7575","45.41400","33.18170","0.05600"
"7604","45.58800","33.19611","0.05577"
"7633","45.76200","33.21069","0.05652"
"7662","45.93600","33.22522","0.05635"
"7691","46.11000","33.23963","0.05640"
"7720","46.28400","33.25416","0.05640"
"7749","46.45800","33.26869","0.05649"
"7778","46.63200","33.28316","0.05635"
"7807","46.80600","33.29769","0.05690"
"7836","46.98000","33.31222","0.05689"
"7865","47.15400","33.32663","0.05703"
"7894","47.32800","33.34116","0.05687"
"7923","47.50200","33.35568","0.05660"
"7952","47.67600","33.37015","0.05640"
"7981","47.85000","33.38468","0.05690"
"8010","48.02400","33.39915","0.05667"
"8039","48.19800","33.41368","0.05688"
"8068","48.37200","33.42815","0.05700"
"8097","48.54600","33.44268","0.05685"
"8126","48.72000","33.45715","0.05707"
"8155","48.89400","33.47161","0.05711"
"8184","49.06800","33.48614","0.05698"
"8213","49.24200","33.50067","0.05712"
"8242","49.41600","33.51520","0.05704"
"8271","49.59000","33.52967","0.05691"
"8300","49.76400","33.54414","0.05745"
"8329","49.93800","33.55861","0.05712"
"8358","50.11200","33.57320","0.05725"
"8387","50.28600","33.58773","0.05711"
"8416","50.46000","33.60208","0.05728"
"8445","50.63400","33.61666","0.05708"
"8474","50.80800","33.63120","0.05727"
"8503","50.98200","33.64566","0.05674"
"8532","51.15600","33.66019","0.05737"
"8561","51.33000","33.67466","0.05717"
"8590","51.50400","33.68913","0.05744"
"8619","51.67800","33.70372","0.05696"
"8648","51.85200","33.71819","0.05763"
"8677","52.02600","33.73265","0.05715"
"8706","52.20000","33.74718","0.05728"
"8735","52.37400","33.76165","0.05735"
"8764","52.54800","33.77618","0.05739"
"8793","52.72200","33.79065","0.05717"
"8822","52.89600","33.80524","0.05756"
"8851","53.07000","33.81959","0.05753"
"8880","53.24400","33.83418","0.05762"
"8909","53.41800","33.84871","0.05769"
"8938","53.59200","33.86317","0.05782"
"8967","53.76600","33.87764","0.05795"
"8996","53.94000","33.89217","0.05786"
"9025","54.11400","33.90664","0.05780"
"9054","54.28800","33.92117","0.05823"
"9083","54.46200","33.93570","0.05802"
"9112","54.63600","33.95011","0.05823"
"9141","54.81000","33.96464","0.05823"
"9170","54.98400","33.97923","0.05831"
"9199","55.15800","33.99370","0.05812"
"9228","55.33200","34.00817","0.05857"
"9257","55.50600","34.02264","0.05851"
"9286","55.68000","34.03717","0.05877"
"9315","55.85400","34.05169","0.05883"
"9344","56.02800","34.06616","0.05868"
"9373","56.20200","34.08069","0.05875"
"9402","56.37600","34.09510","0.05849"
"9431","56.55000","34.10969","0.05852"
"9460","56.72400","34.12416","0.05846"
"9489","56.89800","34.13863","0.05860"
"9518","57.07200","34.15316","0.05878"
"9547","57.24600","34.16763","0.05868"
"9576","57.42000","34.18215","0.05865"
"9605","57.59400","34.19668","0.05887"
"9634","57.76800","34.21121","0.05865"
"9663","57.94200","34.22562","0.05884"
"9692","58.11600","34.24015","0.05801"
"9721","58.29000","34.25468","0.05843"
"9750","58.46400","34.26915","0.05849"
"9779","58.63800","34.28368","0.05814"
"9808","58.81200","34.29820","0.05853"
"9837","58.98600","34.31261","0.05860"
"9866","59.16000","34.32721","0.05864"
"9895","59.33400","34.34167","0.05863"
"9924","59.50800","34.35614","0.05880"
"9953","59.68200","34.37067","0.05884"
"9982","59.85600","34.38520","0.05879"
"10011","60.03000","34.39967","0.05876"
"10040","60.20400","34.41414","0.05889"
"10069","60.37800","34.42867","0.05895"
"10098","60.55200","34.44320","0.05882"
"10127","60.72600","34.45766","0.05920"
"10156","60.90000","34.47219","0.05925"
"10185","61.07400","34.48666","0.05947"
"10214","61.24800","34.50107","0.05886"
"10243","61.42200","34.51566","0.05881"
"10272","61.59600","34.53019","0.05846"
"10301","61.77000","34.54460","0.05841"
"10330","61.94400","34.55919","0.05831"
"10359","62.11800","34.57365","0.05836"
"10388","62.29200","34.58818","0.05845"
"10417","62.46600","34.60271","0.05814"
"10446","62.64000","34.61718","0.05816"
"10475","62.81400","34.63159","0.05844"
"10504","62.98800","34.64618","0.05832"
"10533","63.16200","34.66077","0.05875"
"10562","63.33600","34.67518","0.05859"
"10591","63.51000","34.68965","0.05828"
"10620","63.68400","34.70417","0.05821"
"10649","63.85800","34.71864","0.05830"
"10678","64.03200","34.73311","0.05865"
"10707","64.20600","34.74770","0.05843"
"10736","64.38000","34.76217","0.05891"
"10765","64.55400","34.77670","0.05866"
"10794","64.72800","34.79117","0.05876"
"10823","64.90200","34.80570","0.05911"
"10852","65.07600","34.82017","0.05892"
"10881","65.25000","34.83464","0.05937"
"10910","65.42400","34.84917","0.05948"
"10939","65.59800","34.86370","0.05971"
"10968","65.77200","34.87817","0.05956"
"10997","65.94600","34.89269","0.05961"
"11026","66.12000","34.90710","0.05954"
"11055","66.29400","34.92163","0.05926"
"11084","66.46800","34.93616","0.05932"
"11113","66.64200","34.95069","0.05952"
"11142","66.81600","34.96516","0.05970"
"11171","66.99000","34.97963","0.05960"
"11200","67.16400","34.99416","0.05945"
"11229","67.33800","35.00874","0.05946"
"11258","67.51200","35.02315","0.05943"
"11287","67.68600","35.03762","0.05960"
"11316","67.86000","35.05215","0.05966"
"11345","68.03400","35.06668","0.05969"
"11374","68.20800","35.08115","0.05966"
"11403","68.38200","35.09574","0.05940"
"11432","68.55600","35.11021","0.05912"
"11461","68.73000","35.12461","0.05953"
"11490","68.90400","35.13927","0.05954"
"11519","69.07800","35.15368","0.05946"
"11548","69.25200","35.16814","0.05930"
"11577","69.42600","35.18267","0.05985"
"11606","69.60000","35.19720","0.05963"
"11635","69.77400","35.21161","0.05999"
"11664","69.94800","35.22620","0.05913"
"11693","70.12200","35.24067","0.04435"
"11722","70.29600","35.25514","0.04685"
"11751","70.47000","35.26966","0.04333"
"11780","70.64400","35.28419","0.04555"
"11809","70.81800","35.29866","0.04337"
"11838","70.99200","35.31313","0.04135"
"11867","71.16600","35.32766","0.04162"
"11896","71.34000","35.34213","0.04347"
"11925","71.51400","35.35666","0.04402"
"11954","71.68800","35.37119","0.04270"
"11983","71.86200","35.38566","0.04290"
"12012","72.03600","35.40013","0.04353"
"12041","72.21000","35.41471","0.04344"
"12070","72.38400","35.42918","0.04308"
"12099","72.55800","35.44365","0.04311"
"12128","72.73200","35.45818","0.04328"
"12157","72.90600","35.47271","0.04322"
"12186","73.08000","35.48712","0.04295"
"12215","73.25400","35.50171","0.04336"
"12244","73.42800","35.51618","0.04411"
"12273","73.60200","35.53059","0.04455"
"12302","73.77600","35.54518","0.04509"
"12331","73.95000","35.55971","0.04428"
"12360","74.12400","35.57412","0.04440"
"12389","74.29800","35.58865","0.04454"
"12418","74.47200","35.60317","0.04445"
"12447","74.64600","35.61770","0.04463"
"12476","74.82000","35.63223","0.04409"
"12505","74.99400","35.64670","0.04406"
"12534","75.16800","35.66117","0.04395"
"12563","75.34200","35.67570","0.04362"
"12592","75.51600","35.69017","0.04397"
"12621","75.69000","35.70464","0.04395"
"12650","75.86400","35.71916","0.04411"
"12679","76.03800","35.73369","0.04380"
"12708","76.21200","35.74816","0.04328"
"12737","76.38600","35.76269","0.04450"
"12766","76.56000","35.77716","0.04435"
"12795","76.73400","35.79163","0.04384"
"12824","76.90800","35.80616","0.04441"
"12853","77.08200","35.82069","0.04437"
"12882","77.25600","35.83516","0.04278"
"12911","77.43000","35.84968","0.04243"
"12940","77.60400","35.86421","0.04313"
"12969","77.77800","35.87862","0.04311"
"12998","77.95200","35.89321","0.04333"
"13027","78.12600","35.90774","0.04336"
"13056","78.30000","35.92215","0.04356"
"13085","78.47400","35.93662","0.04383"
"13114","78.64800","35.95121","0.04385"
"13143","78.82200","35.96568","0.04470"
"13172","78.99600","35.98009","0.04518"
"13201","79.17000","35.99467","0.04534"
"13230","79.34400","36.00914","0.04513"
"13259","79.51800","36.02367","0.04547"
"13288","79.69200","36.03820","0.04621"
"13317","79.86600","36.05267","0.04609"
"13346","80.04000","36.06708","0.04672"
"13375","80.21400","36.08167","0.04669"
"13404","80.38800","36.09620","0.04663"
"13433","80.56200","36.11066","0.04694"
"13462","80.73600","36.12519","0.04723"
"13491","80.91000","36.13966","0.04716"
"13520","81.08400","36.15413","0.04717"
"13549","81.25800","36.16866","0.04770"
"13578","81.43200","36.18319","0.04812"
"13607","81.60600","36.19766","0.04859"
"13636","81.78000","36.21219","0.04817"
"13665","81.95400","36.22672","0.04838"
"13694","82.12800","36.24113","0.04867"
"13723","82.30200","36.25565","0.04900"
"13752","82.47600","36.27018","0.04887"
"13781","82.65000","36.28465","0.04945"
"13810","82.82400","36.29918","0.04978"
"13839","82.99800","36.31365","0.04971"
"13868","83.17200","36.32818","0.04977"
"13897","83.34600","36.34265","0.05010"
"13926","83.52000","36.35718","0.05022"
"13955","83.69400","36.37171","0.05047"
"13984","83.86800","36.38612","0.05037"
"14013","84.04200","36.40071","0.05049"
"14042","84.21600","36.41512","0.05105"
"14071","84.39000","36.42964","0.05109"
"14100","84.56400","36.44417","0.05101"
"14129","84.73800","36.45864","0.05146"
"14158","84.91200","36.47317","0.05165"
"14187","85.08600","36.48770","0.05160"
"14216","85.26000","36.50217","0.05222"
"14245","85.43400","36.51664","0.05235"
"14274","85.60800","36.53117","0.05200"
"14303","85.78200","36.54569","0.05233"
"14332","85.95600","36.56010","0.05240"
"14361","86.13000","36.57475","0.05290"
"14390","86.30400","36.58916","0.05317"
"14419","86.47800","36.60357","0.05322"
"14448","86.65200","36.61816","0.05323"
"14477","86.82600","36.63269","0.05350"
"14506","87.00000","36.64716","0.05351"
"14535","87.17400","36.66169","0.05336"
"14564","87.34800","36.67621","0.05361"
"14593","87.52200","36.69062","0.05367"
"14622","87.69600","36.70522","0.05409"
"14651","87.87000","36.71974","0.05405"
"14680","88.04400","36.73415","0.05419"
"14709","88.21800","36.74868","0.05430"
"14738","88.39200","36.76321","0.05440"
"14767","88.56600","36.77768","0.05473"
"14796","88.74000","36.79215","0.05453"
"14825","88.91400","36.80667","0.05458"
"14854","89.08800","36.82114","0.05466"
"14883","89.26200","36.83567","0.05451"
"14912","89.43600","36.85020","0.05478"
"14941","89.61000","36.86467","0.05510"
"14970","89.78400","36.87914","0.05483"
"14999","89.95800","36.89367","0.05532"
"15028","90.13200","36.90820","0.05484"
"15057","90.30600","36.92267","0.05546"
"15086","90.48000","36.93714","0.05533"
"15115","90.65400","36.95166","0.05573"
"15144","90.82800","36.96608","0.05537"
"15173","91.00200","36.98078","0.05557"
"15202","91.17600","36.99519","0.05583"
"15231","91.35000","37.00960","0.05565"
"15260","91.52400","37.02413","0.05553"
"15289","91.69800","37.03866","0.05564"
"15318","91.87200","37.05319","0.05520"
"15347","92.04600","37.06771","0.05529"
"15376","92.22000","37.08218","0.05521"
"15405","92.39400","37.09666","0.05504"
"15434","92.56800","37.11119","0.05314"
"15463","92.74200","37.12566","0.05322"
"15492","92.91600","37.14018","0.05313"
"15521","93.09000","37.15465","0.05324"
"15550","93.26400","37.16918","0.05289"
"15579","93.43800","37.18365","0.05320"
"15608","93.61200","37.19818","0.05341"
"15637","93.78600","37.21265","0.05343"
"15666","93.96000","37.22718","0.05352"
"15695","94.13400","37.24165","0.05355"
"15724","94.30800","37.25617","0.05341"
"15753","94.48200","37.27064","0.05349"
"15782","94.65600","37.28517","0.05379"
"15811","94.83000","37.29964","0.05383"
"15840","95.00400","37.31417","0.05358"
"15869","95.17800","37.32870","0.05423"
"15898","95.35200","37.34317","0.05396"
"15927","95.52600","37.35764","0.05383"
"15956","95.70000","37.37217","0.05404"
"15985","95.87400","37.38675","0.05417"
"16014","96.04800","37.40116","0.05406"
"16043","96.22200","37.41557","0.05429"
"16072","96.39600","37.43022","0.05398"
"16101","96.57000","37.44463","0.05415"
"16130","96.74400","37.45916","0.05420"
"16159","96.91800","37.47369","0.05448"
"16188","97.09200","37.48816","0.05251"
"16217","97.26600","37.50256","0.05227"
"16246","97.44000","37.51715","0.05292"
"16275","97.61400","37.53175","0.05272"
"16304","97.78800","37.54609","0.05249"
"16333","97.96200","37.56068","0.05270"
"16362","98.13600","37.57521","0.05331"
"16391","98.31000","37.58962","0.05312"
"16420","98.48400","37.60415","0.05277"
"16449","98.65800","37.61874","0.05283"
"16478","98.83200","37.63315","0.05306"
"16507","99.00600","37.64767","0.05367"
"16536","99.18000","37.66220","0.05363"
"16565","99.35400","37.67667","0.05345"
"16594","99.52800","37.69114","0.05359"
"16623","99.70200","37.70567","0.05156"
"16652","99.87600","37.72014","0.05247"
"16681","100.05000","37.73467","0.05258"
"16710","100.22400","37.74914","0.05149"
"16739","100.39800","37.76367","0.05180"
"16768","100.57200","37.77819","0.05215"
"16797","100.74600","37.79272","0.05241"
"16826","100.92000","37.80719","0.05223"
"16855","101.09400","37.82160","0.05207"
"16884","101.26800","37.83613","0.05166"
"16913","101.44200","37.85060","0.05175"
"16942","101.61600","37.86513","0.05194"
"16971","101.79000","37.87966","0.05198"
"17000","101.96400","37.89413","0.05236"
"17029","102.13800","37.90860","0.05220"
"17058","102.31200","37.92319","0.05204"
"17087","102.48600","37.93772","0.05201"
"17116","102.66000","37.95213","0.05195"
"17145","102.83400","37.96671","0.05220"
"17174","103.00800","37.98118","0.05242"
"17203","103.18200","37.99565","0.05202"
"17232","103.35600","38.01024","0.05230"
"17261","103.53000","38.02465","0.05226"
"17290","103.70400","38.03912","0.05233"
"17319","103.87800","38.05371","0.05287"
"17348","104.05200","38.06818","0.05273"
"17377","104.22600","38.08265","0.05213"
"17406","104.40000","38.09717","0.05288"
"17435","104.57400","38.11170","0.05259"
"17464","104.74800","38.12611","0.05260"
"17493","104.92200","38.14070","0.05300"
"17522","105.09600","38.15517","0.05294"
"17551","105.27000","38.16970","0.05289"
"17580","105.44400","38.18417","0.05281"
"17609","105.61800","38.19870","0.05288"
"17638","105.79200","38.21310","0.05290"
"17667","105.96600","38.22763","0.05289"
"17696","106.14000","38.24222","0.05322"
"17725","106.31400","38.25663","0.05329"
"17754","106.48800","38.27116","0.05252"
"17783","106.66200","38.28575","0.05307"
"17812","106.83600","38.30016","0.05308"
"17841","107.01000","38.31463","0.05309"
"17870","107.18400","38.32916","0.05301"
"17899","107.35800","38.34369","0.05372"
"17928","107.53200","38.35815","0.05335"
"17957","107.70600","38.37262","0.05305"
"17986","107.88000","38.38715","0.05416"
"18015","108.05400","38.40162","0.05392"
"18044","108.22800","38.41621","0.05389"
"18073","108.40200","38.43068","0.05350"
"18102","108.57600","38.44509","0.05421"
"18131","108.75000","38.45968","0.05394"
"18160","108.92400","38.47421","0.05390"
"18189","109.09800","38.48867","0.05363"
"18218","109.27200","38.50314","0.05452"
"18247","109.44600","38.51767","0.05395"
"18276","109.62000","38.53214","0.05412"
"18305","109.79400","38.54667","0.05419"
"18334","109.96800","38.56114","0.05430"
"18363","110.14200","38.57561","0.05412"
"18392","110.31600","38.59014","0.05415"
"18421","110.49000","38.60466","0.05424"
"18450","110.66400","38.61919","0.05440"
"18479","110.83800","38.63366","0.05422"
"18508","111.01200","38.64819","0.05461"
"18537","111.18600","38.66260","0.05462"
"18566","111.36000","38.67719","0.05463"
"18595","111.53400","38.69172","0.05448"
"18624","111.70800","38.70613","0.05448"
"18653","111.88200","38.72066","0.05486"
"18682","112.05600","38.73519","0.05463"
"18711","112.23000","38.74966","0.05471"
"18740","112.40400","38.76419","0.05477"
"18769","112.57800","38.77866","0.05444"
"18798","112.75200","38.79318","0.05535"
"18827","112.92600","38.80765","0.05483"
"18856","113.10000","38.82218","0.05480"
"18885","113.27400","38.83671","0.05512"
"18914","113.44800","38.85118","0.05525"
"18943","113.62200","38.86571","0.05483"
"18972","113.79600","38.88018","0.05510"
"19001","113.97000","38.89465","0.05481"
"19030","114.14400","38.90923","0.05550"
"19059","114.31800","38.92365","0.05488"
"19088","114.49200","38.93811","0.05495"
"19117","114.66600","38.95264","0.05532"
"19146","114.84000","38.96717","0.05566"
"19175","115.01400","38.98158","0.05499"
"19204","115.18800","38.99617","0.05528"
"19233","115.36200","39.01070","0.05538"
"19262","115.53600","39.02517","0.05553"
"19291","115.71000","39.03969","0.05524"
"19320","115.88400","39.05423","0.05563"
"19349","116.05800","39.06863","0.05516"
"19378","116.23200","39.08316","0.05562"
"19407","116.40600","39.09769","0.05602"
"19436","116.58000","39.11216","0.05541"
"19465","116.75400","39.12669","0.05575"
"19494","116.92800","39.14116","0.05616"
"19523","117.10200","39.15563","0.05602"
"19552","117.27600","39.17016","0.05575"
"19581","117.45000","39.18468","0.05572"
"19610","117.62400","39.19915","0.05589"
"19639","117.79800","39.21362","0.05608"
"19668","117.97200","39.22821","0.05574"
"19697","118.14600","39.24268","0.05583"
"19726","118.32000","39.25715","0.05626"
"19755","118.49400","39.27168","0.05585"
"19784","118.66800","39.28615","0.05581"
"19813","118.84200","39.30068","0.05592"
"19842","119.01600","39.31520","0.05597"
"19871","119.19000","39.32961","0.05609"
"19900","119.36400","39.34414","0.05597"
"19929","119.53800","39.35867","0.05600"
"19958","119.71200","39.37320","0.05620"
"19987","119.88600","39.38766","0.05624"
"20016","120.06000","39.40219","0.05612"
"20045","120.23400","39.41667","0.05621"
"20074","120.40800","39.43114","0.05639"
"20103","120.58200","39.44572","0.05649"
"20132","120.75600","39.46014","0.05646"
"20161","120.93000","39.47461","0.05642"
"20190","121.10400","39.48919","0.05643"
"20219","121.27800","39.50372","0.05644"
"20248","121.45200","39.51813","0.05684"
"20277","121.62600","39.53272","0.05704"
"20306","121.80000","39.54719","0.05695"
"20335","121.97400","39.56166","0.05671"
"20364","122.14800","39.57618","0.05676"
"20393","122.32200","39.59071","0.05717"
"20422","122.49600","39.60513","0.05671"
"20451","122.67000","39.61966","0.05687"
"20480","122.84400","39.63418","0.05699"
"20509","123.01800","39.64859","0.05701"
"20538","123.19200","39.66318","0.05697"
"20567","123.36600","39.67771","0.05681"
"20596","123.54000","39.69212","0.05690"
"20625","123.71400","39.70671","0.05637"
"20654","123.88800","39.72117","0.05624"
"20683","124.06200","39.73565","0.05650"
"20712","124.23600","39.75011","0.05654"
"20741","124.41000","39.76470","0.05654"
"20770","124.58400","39.77923","0.05675"
"20799","124.75800","39.79364","0.05663"
"20828","124.93200","39.80817","0.05682"
"20857","125.10600","39.82270","0.05676"
"20886","125.28000","39.83710","0.05671"
"20915","125.45400","39.85176","0.05677"
"20944","125.62800","39.86617","0.05686"
"20973","125.80200","39.88063","0.05651"
"21002","125.97600","39.89522","0.05686"
"21031","126.15000","39.90969","0.05673"
"21060","126.32400","39.92416","0.05694"
"21089","126.49800","39.93869","0.05669"
"21118","126.67200","39.95316","0.05683"
"21147","126.84600","39.96763","0.05690"
"21176","127.02000","39.98222","0.05728"
"21205","127.19400","39.99662","0.05729"
"21234","127.36800","40.01115","0.05728"
"21263","127.54200","40.02562","0.05712"
"21292","127.71600","40.04015","0.05702"
"21321","127.89000","40.05468","0.05683"
"21350","128.06400","40.06915","0.05713"
"21379","128.23800","40.08368","0.05713"
"21408","128.41200","40.09809","0.05704"
"21437","128.58600","40.11268","0.05702"
"21466","128.76000","40.12715","0.05728"
"21495","128.93400","40.14161","0.05708"
"21524","129.10800","40.15620","0.05704"
"21553","129.28200","40.17067","0.05729"
"21582","129.45600","40.18514","0.05676"
"21611","129.63000","40.19967","0.04510"
"21640","129.80400","40.21420","0.04450"
"21669","129.97800","40.22861","0.04179"
"21698","130.15200","40.24314","0.04240"
"21727","130.32600","40.25772","0.04047"
"21756","130.50000","40.27220","0.04054"
"21785","130.67400","40.28661","0.04217"
"21814","130.84800","40.30120","0.04131"
"21843","131.02200","40.31572","0.04160"
"21872","131.19600","40.33019","0.04184"
"21901","131.37000","40.34466","0.04046"
"21930","131.54400","40.35913","0.03991"
"21959","131.71800","40.37360","0.04171"
"21988","131.89200","40.38819","0.04222"
"22017","132.06600","40.40271","0.04057"
"22046","132.24000","40.41713","0.03980"
"22075","132.41400","40.43166","0.04178"
"22104","132.58800","40.44619","0.04113"
"22133","132.76200","40.46066","0.03925"
"22162","132.93600","40.47518","0.03900"
"22191","133.11000","40.48971","0.04019"
"22220","133.28400","40.50412","0.04075"
"22249","133.45800","40.51871","0.04083"
"22278","133.63200","40.53324","0.03904"
"22307","133.80600","40.54759","0.03981"
"22336","133.98000","40.56223","0.04029"
"22365","134.15400","40.57670","0.04064"
"22394","134.32800","40.59117","0.03981"
"22423","134.50200","40.60564","0.04024"
"22452","134.67600","40.62017","0.04064"
"22481","134.85000","40.63464","0.04094"
"22510","135.02400","40.64917","0.04012"
"22539","135.19800","40.66370","0.04090"
"22568","135.37200","40.67817","0.04062"
"22597","135.54600","40.69263","0.04111"
"22626","135.72000","40.70711","0.04080"
"22655","135.89400","40.72164","0.04087"
"22684","136.06800","40.73616","0.04070"
"22713","136.24200","40.75063","0.04084"
"22742","136.41600","40.76516","0.04096"
"22771","136.59000","40.77963","0.04174"
"22800","136.76400","40.79416","0.04168"
"22829","136.93800","40.80869","0.04111"
"22858","137.11200","40.82315","0.04147"
"22887","137.28600","40.83768","0.04171"
"22916","137.46000","40.85215","0.04206"
"22945","137.63400","40.86662","0.04151"
"22974","137.80800","40.88121","0.04165"
"23003","137.98200","40.89568","0.04199"
"23032","138.15600","40.91009","0.04168"
"23061","138.33000","40.92468","0.04174"
"23090","138.50400","40.93921","0.04194"
"23119","138.67800","40.95368","0.04223"
"23148","138.85200","40.96820","0.04214"
"23177","139.02600","40.98267","0.04245"
"23206","139.20000","40.99714","0.04252"
"23235","139.37400","41.01173","0.04252"
"23264","139.54800","41.02614","0.04271"
"23293","139.72200","41.04062","0.04377"
"23322","139.89600","41.05514","0.04288"
"23351","140.07000","41.06973","0.04308"
"23380","140.24400","41.08414","0.04352"
"23409","140.41800","41.09861","0.04305"
"23438","140.59200","41.11314","0.04378"
"23467","140.76600","41.12761","0.04392"
"23496","140.94000","41.14220","0.04315"
"23525","141.11400","41.15672","0.04368"
"23554","141.28800","41.17113","0.04418"
"23583","141.46200","41.18560","0.04362"
"23612","141.63600","41.20019","0.04445"
"23641","141.81000","41.21466","0.04490"
"23670","141.98400","41.22919","0.04432"
"23699","142.15800","41.24366","0.04455"
"23728","142.33200","41.25819","0.04505"
"23757","142.50600","41.27266","0.04479"
"23786","142.68000","41.28719","0.04511"
"23815","142.85400","41.30171","0.04548"
"23844","143.02800","41.31612","0.04549"
"23873","143.20200","41.33071","0.04577"
"23902","143.37600","41.34524","0.04563"
"23931","143.55000","41.35965","0.04578"
"23960","143.72400","41.37418","0.04598"
"23989","143.89800","41.38865","0.04559"
"24018","144.07200","41.40311","0.04607"
"24047","144.24600","41.41771","0.04515"
"24076","144.42000","41.43217","0.04629"
"24105","144.59400","41.44664","0.04608"
"24134","144.76800","41.46117","0.04600"
"24163","144.94200","41.47570","0.04682"
"24192","145.11600","41.49017","0.04644"
"24221","145.29000","41.50470","0.04621"
"24250","145.46400","41.51923","0.04680"
"24279","145.63800","41.53364","0.04687"
"24308","145.81200","41.54817","0.04680"
"24337","145.98600","41.56269","0.04700"
"24366","146.16000","41.57716","0.04657"
"24395","146.33400","41.59163","0.04756"
"24424","146.50800","41.60622","0.04753"
"24453","146.68200","41.62063","0.04759"
"24482","146.85600","41.63515","0.04759"
"24511","147.03000","41.64968","0.04740"
"24540","147.20400","41.66415","0.04783"
"24569","147.37800","41.67868","0.04792"
"24598","147.55200","41.69321","0.04846"
"24627","147.72600","41.70768","0.04784"
"24656","147.90000","41.72209","0.04797"
"24685","148.07400","41.73668","0.04833"
"24714","148.24800","41.75121","0.04786"
"24743","148.42200","41.76561","0.04846"
"24772","148.59600","41.78014","0.04886"
"24801","148.77000","41.79461","0.04851"
"24830","148.94400","41.80909","0.04913"
"24859","149.11800","41.82368","0.04940"
"24888","149.29200","41.83821","0.04951"
"24917","149.46600","41.85262","0.04919"
"24946","149.64000","41.86720","0.04967"
"24975","149.81400","41.88167","0.04983"
"25004","149.98800","41.89614","0.05010"
"25033","150.16200","41.91067","0.04998"
"25062","150.33600","41.92520","0.04992"
"25091","150.51000","41.93961","0.04975"
"25120","150.68400","41.95420","0.04985"
"25149","150.85800","41.96873","0.04994"
"25178","151.03200","41.98313","0.05024"
"25207","151.20600","41.99766","0.05025"
"25236","151.38000","42.01219","0.05037"
"25265","151.55400","42.02666","0.05070"
"25294","151.72800","42.04113","0.05053"
"25323","151.90200","42.05566","0.04944"
"25352","152.07600","42.07013","0.04972"
"25381","152.25000","42.08466","0.04898"
"25410","152.42400","42.09919","0.04962"
"25439","152.59800","42.11366","0.04972"
"25468","152.77200","42.12812","0.05002"
"25497","152.94600","42.14265","0.04996"
"25526","153.12000","42.15712","0.04990"
"25555","153.29400","42.17165","0.05038"
"25584","153.46800","42.18618","0.05005"
"25613","153.64200","42.20065","0.05046"
"25642","153.81600","42.21518","0.05092"
"25671","153.99000","42.22976","0.05059"
"25700","154.16400","42.24424","0.05088"
"25729","154.33800","42.25865","0.05105"
"25758","154.51200","42.27317","0.05066"
"25787","154.68600","42.28770","0.05048"
"25816","154.86000","42.30217","0.05066"
"25845","155.03400","42.31670","0.05103"
"25874","155.20800","42.33117","0.05057"
"25903","155.38200","42.34558","0.05133"
"25932","155.55600","42.36023","0.05102"
"25961","155.73000","42.37469","0.05101"
"25990","155.90400","42.38911","0.05143"
"26019","156.07800","42.40369","0.05138"
"26048","156.25200","42.41816","0.05101"
"26077","156.42600","42.43263","0.05111"
"26106","156.60000","42.44722","0.05182"
"26135","156.77400","42.46169","0.05182"
"26164","156.94800","42.47615","0.05176"
"26193","157.12200","42.49068","0.05145"
"26222","157.29600","42.50521","0.05178"
"26251","157.47000","42.51963","0.05182"
"26280","157.64400","42.53415","0.05157"
"26309","157.81800","42.54868","0.05172"
"26338","157.99200","42.56315","0.05084"
"26367","158.16600","42.57768","0.03203"
"26396","158.34000","42.59221","0.03490"
"26425","158.51400","42.60668","0.03519"
"26454","158.68800","42.62115","0.03270"
"26483","158.86200","42.63568","0.03108"
"26512","159.03600","42.65021","0.03104"
"26541","159.21000","42.66462","0.03144"
"26570","159.38400","42.67915","0.03365"
"26599","159.55800","42.69361","0.03318"
"26628","159.73200","42.70815","0.03207"
"26657","159.90600","42.72267","0.03117"
"26686","160.08000","42.73714","0.03133"
"26715","160.25400","42.75161","0.03247"
"26744","160.42800","42.76620","0.03323"
"26773","160.60200","42.78067","0.03242"
"26802","160.77600","42.79513","0.03148"
"26831","160.95000","42.80972","0.03182"
"26860","161.12400","42.82413","0.03201"
"26889","161.29800","42.83860","0.03260"
"26918","161.47200","42.85325","0.03328"
"26947","161.64600","42.86766","0.03251"
"26976","161.82000","42.88207","0.03217"
"27005","161.99400","42.89666","0.03237"
"27034","162.16800","42.91119","0.03302"
"27063","162.34200","42.92566","0.03272"
"27092","162.51600","42.94019","0.03188"
"27121","162.69000","42.95471","0.03161"
"27150","162.86400","42.96912","0.03184"
"27179","163.03800","42.98371","0.03183"
"27208","163.21200","42.99818","0.03206"
"27237","163.38600","43.01265","0.03226"
"27266","163.56000","43.02718","0.03201"
"27295","163.73400","43.04171","0.03164"
"27324","163.90800","43.05612","0.03198"
"27353","164.08200","43.07071","0.03224"
"27382","164.25600","43.08518","0.03245"
"27411","164.43000","43.09964","0.03251"
"27440","164.60400","43.11417","0.03237"
"27469","164.77800","43.12870","0.03271"
"27498","164.95200","43.14317","0.03201"
"27527","165.12600","43.15764","0.03248"
"27556","165.30000","43.17217","0.03212"
"27585","165.47400","43.18670","0.03275"
"27614","165.64800","43.20117","0.03221"
"27643","165.82200","43.21564","0.03241"
"27672","165.99600","43.23016","0.03243"
"27701","166.17000","43.24463","0.03239"
"27730","166.34400","43.25916","0.03272"
"27759","166.51800","43.27369","0.03286"
"27788","166.69200","43.28815","0.03278"
"27817","166.86600","43.30268","0.03265"
"27846","167.04000","43.31721","0.03268"
"27875","167.21400","43.33169","0.03246"
"27904","167.38800","43.34616","0.03257"
"27933","167.56200","43.36068","0.03258"
"27962","167.73600","43.37515","0.03287"
"27991","167.91000","43.38969","0.03275"
"28020","168.08400","43.40421","0.03292"
"28049","168.25800","43.41862","0.03319"
"28078","168.43200","43.43315","0.03220"
"28107","168.60600","43.44768","0.03292"
"28136","168.78000","43.46221","0.03294"
"28165","168.95400","43.47667","0.03259"
"28194","169.12800","43.49115","0.03275"
"28223","169.30200","43.50568","0.03289"
"28252","169.47600","43.52021","0.03244"
"28281","169.65000","43.53473","0.03288"
"28310","169.82400","43.54914","0.03276"
"28339","169.99800","43.56367","0.03277"
"28368","170.17200","43.57820","0.03279"
"28397","170.34600","43.59261","0.03286"
"28426","170.52000","43.60714","0.03323"
"28455","170.69400","43.62166","0.03308"
"28484","170.86800","43.63614","0.03292"
"28513","171.04200","43.65067","0.03290"
"28542","171.21600","43.66519","0.03308"
"28571","171.39000","43.67966","0.03267"
"28600","171.56400","43.69413","0.03316"
"28629","171.73800","43.70866","0.03278"
"28658","171.91200","43.72319","0.03292"
"28687","172.08600","43.73766","0.03297"
"28716","172.26000","43.75219","0.03270"
"28745","172.43400","43.76665","0.03276"
"28774","172.60800","43.78106","0.03281"
"28803","172.78200","43.79571","0.03251"
"28832","172.95600","43.81024","0.03293"
"28861","173.13000","43.82465","0.03283"
"28890","173.30400","43.83918","0.03278"
"28919","173.47800","43.85365","0.03256"
"28948","173.65200","43.86812","0.03295"
"28977","173.82600","43.88265","0.03302"
"29006","174.00000","43.89718","0.03340"
"29035","174.17400","43.91164","0.03295"
"29064","174.34800","43.92617","0.03355"
"29093","174.52200","43.94070","0.03350"
"29122","174.69600","43.95517","0.03255"
"29151","174.87000","43.96964","0.03235"
"29180","175.04400","43.98417","0.03181"
"29209","175.21800","43.99864","0.03163"
"29238","175.39200","44.01317","0.03139"
"29267","175.56600","44.02770","0.03211"
"29296","175.74000","44.04210","0.03234"
"29325","175.91400","44.05663","0.03203"
"29354","176.08800","44.07122","0.03241"
"29383","176.26200","44.08563","0.03216"
"29412","176.43600","44.10016","0.03208"
"29441","176.61000","44.11463","0.03210"
"29470","176.78400","44.12916","0.03188"
"29499","176.95800","44.14369","0.03250"
"29528","177.13200","44.15822","0.03239"
"29557","177.30600","44.17269","0.03213"
"29586","177.48000","44.18716","0.03243"
"29615","177.65400","44.20169","0.03240"
"29644","177.82800","44.21616","0.03231"
"29673","178.00200","44.23063","0.03221"
"29702","178.17600","44.24521","0.03237"
"29731","178.35000","44.25968","0.03267"
"29760","178.52400","44.27415","0.03200"
"29789","178.69800","44.28874","0.03247"
"29818","178.87200","44.30315","0.03235"
"29847","179.04600","44.31762","0.03231"
"29876","179.22000","44.33215","0.03289"
"29905","179.39400","44.34668","0.03251"
"29934","179.56800","44.36115","0.03292"
"29963","179.74200","44.37567","0.03264"
"29992","179.91600","44.39014","0.03280"
"30021","180.09000","44.40461","0.03308"
"30050","180.26400","44.41926","0.03284"
"30079","180.43800","44.43367","0.03276"
"30108","180.61200","44.44814","0.03301"
"30137","180.78600","44.46267","0.03219"
"30166","180.96000","44.47720","0.03280"
"30195","181.13400","44.49166","0.03349"
"30224","181.30800","44.50619","0.03310"
"30253","181.48200","44.52072","0.03189"
"30282","181.65600","44.53519","0.03253"
"30311","181.83000","44.54966","0.03211"
"30340","182.00400","44.56419","0.03294"
"30369","182.17800","44.57866","0.03214"
"30398","182.35200","44.59312","0.03259"
"30427","182.52600","44.60772","0.03246"
"30456","182.70000","44.62224","0.03239"
"30485","182.87400","44.63665","0.03248"
"30514","183.04800","44.65112","0.03286"
"30543","183.22200","44.66565","0.03264"
"30572","183.39600","44.68012","0.03250"
"30601","183.57000","44.69471","0.03244"
"30630","183.74400","44.70918","0.03266"
"30659","183.91800","44.72359","0.03284"
"30688","184.09200","44.73817","0.03275"
"30717","184.26600","44.75270","0.03305"
"30746","184.44000","44.76717","0.03274"
"30775","184.61400","44.78164","0.03273"
"30804","184.78800","44.79617","0.03272"
"30833","184.96200","44.81064","0.03229"
"30862","185.13600","44.82517","0.03314"
"30891","185.31000","44.83970","0.03328"
"30920","185.48400","44.85410","0.03331"
"30949","185.65800","44.86870","0.03267"
"30978","185.83200","44.88316","0.03313"
"31007","186.00600","44.89763","0.03299"
"31036","186.18000","44.91216","0.03289"
"31065","186.35400","44.92669","0.03308"
"31094","186.52800","44.94116","0.03318"
"31123","186.70200","44.95563","0.03334"
"31152","186.87600","44.97016","0.03319"
"31181","187.05000","44.98463","0.03241"
"31210","187.22400","44.99910","0.03302"
"31239","187.39800","45.01369","0.03256"
"31268","187.57200","45.02816","0.03303"
"31297","187.74600","45.04269","0.03344"
"31326","187.92000","45.05716","0.03343"
"31355","188.09400","45.07162","0.03347"
"31384","188.26800","45.08615","0.03310"
"31413","188.44200","45.10068","0.03296"
"31442","188.61600","45.11521","0.03304"
"31471","188.79000","45.12962","0.03270"
"31500","188.96400","45.14415","0.03343"
"31529","189.13800","45.15868","0.03294"
"31558","189.31200","45.17315","0.03318"
"31587","189.48600","45.18773","0.03335"
"31616","189.66000","45.20220","0.03339"
"31645","189.83400","45.21661","0.03322"
"31674","190.00800","45.23120","0.03334"
"31703","190.18200","45.24573","0.03326"
"31732","190.35600","45.26008","0.03337"
"31761","190.53000","45.27467","0.03304"
"31790","190.70400","45.28920","0.03290"
"31819","190.87800","45.30360","0.03315"
"31848","191.05200","45.31820","0.03304"
"31877","191.22600","45.33266","0.03365"
"31906","191.40000","45.34713","0.03337"
"31935","191.57400","45.36166","0.03330"
"31964","191.74800","45.37619","0.03282"
"31993","191.92200","45.39054","0.03333"
"32022","192.09600","45.40519","0.03341"
"32051","192.27000","45.41972","0.03300"
"32080","192.44400","45.43419","0.03327"
"32109","192.61800","45.44866","0.03355"
"32138","192.79200","45.46318","0.03329"
"32167","192.96600","45.47765","0.03309"
"32196","193.14000","45.49218","0.03368"
"32225","193.31400","45.50671","0.03340"
"32254","193.48800","45.52112","0.03335"
"32283","193.66200","45.53564","0.03251"
"32312","193.83600","45.55011","0.03310"
"32341","194.01000","45.56464","0.03331"
"32370","194.18400","45.57917","0.03351"
"32399","194.35800","45.59370","0.03396"
"32428","194.53200","45.60817","0.03343"
"32457","194.70600","45.62264","0.03315"
"32486","194.88000","45.63717","0.03433"
"32515","195.05400","45.65170","0.03353"
"32544","195.22800","45.66611","0.03390"
"32573","195.40200","45.68063","0.03357"
"32602","195.57600","45.69516","0.03364"
"32631","195.75000","45.70963","0.03359"
"32660","195.92400","45.72423","0.03374"
"32689","196.09800","45.73863","0.03348"
"32718","196.27200","45.75310","0.03396"
"32747","196.44600","45.76769","0.03333"
"32776","196.62000","45.78222","0.03353"
"32805","196.79400","45.79669","0.03314"
"32834","196.96800","45.81116","0.03364"
"32863","197.14200","45.82569","0.03371"
"32892","197.31600","45.84016","0.03415"
"32921","197.49000","45.85469","0.03375"
"32950","197.66400","45.86922","0.03337"
"32979","197.83800","45.88362","0.03299"
"33008","198.01200","45.89821","0.03362"
"33037","198.18600","45.91268","0.03341"
"33066","198.36000","45.92709","0.03319"
"33095","198.53400","45.94168","0.03350"
"33124","198.70800","45.95621","0.03332"
"33153","198.88200","45.97062","0.03400"
"33182","199.05600","45.98521","0.03327"
"33211","199.23000","45.99968","0.03398"
"33240","199.40400","46.01414","0.03353"
"33269","199.57800","46.02861","0.03333"
"33298","199.75200","46.04320","0.03365"
"33327","199.92600","46.05773","0.03338"
"33356","200.10000","46.07214","0.03329"
"33385","200.27400","46.08667","0.03363"
"33414","200.44800","46.10114","0.03360"
"33443","200.62200","46.11567","0.03362"
"33472","200.79600","46.13020","0.03353"
"33501","200.97000","46.14467","0.03365"
"33530","201.14400","46.15914","0.03347"
"33559","201.31800","46.17373","0.03405"
"33588","201.49200","46.18819","0.03368"
"33617","201.66600","46.20266","0.03335"
"33646","201.84000","46.21713","0.03288"
"33675","202.01400","46.23166","0.03334"
"33704","202.18800","46.24613","0.03366"
"33733","202.36200","46.26066","0.03374"
"33762","202.53600","46.27519","0.03350"
"33791","202.71000","46.28966","0.03358"
"33820","202.88400","46.30418","0.03341"
"33849","203.05800","46.31865","0.03410"
"33878","203.23200","46.33312","0.03221"
"33907","203.40600","46.34765","0.03243"
"33936","203.58000","46.36217","0.03299"
"33965","203.75400","46.37664","0.03245"
"33994","203.92800","46.39117","0.03273"
"34023","204.10200","46.40570","0.03244"
"34052","204.27600","46.42012","0.03298"
"34081","204.45000","46.43464","0.03253"
"34110","204.62400","46.44917","0.03237"
"34139","204.79800","46.46364","0.03279"
"34168","204.97200","46.47817","0.03283"
"34197","205.14600","46.49270","0.03258"
"34226","205.32000","46.50711","0.03241"
"34255","205.49400","46.52170","0.03263"
"34284","205.66800","46.53623","0.03321"
"34313","205.84200","46.55064","0.03299"
"34342","206.01600","46.56516","0.03326"
"34371","206.19000","46.57964","0.03296"
"34400","206.36400","46.59417","0.03297"
"34429","206.53800","46.60863","0.03296"
"34458","206.71200","46.62322","0.03262"
"34487","206.88600","46.63763","0.03322"
"34516","207.06000","46.65210","0.03305"
"34545","207.23400","46.66675","0.03306"
"34574","207.40800","46.68122","0.03326"
"34603","207.58200","46.69557","0.03300"
"34632","207.75600","46.71022","0.03288"
"34661","207.93000","46.72468","0.03299"
"34690","208.10400","46.73915","0.03274"
"34719","208.27800","46.75368","0.03253"
"34748","208.45200","46.76815","0.03320"
"34777","208.62600","46.78262","0.03307"
"34806","208.80000","46.79715","0.03233"
"34835","208.97400","46.81168","0.03345"
"34864","209.14800","46.82608","0.03282"
"34893","209.32200","46.84061","0.03313"
"34922","209.49600","46.85521","0.03260"
"34951","209.67000","46.86967","0.03270"
"34980","209.84400","46.88420","0.03283"
"35009","210.01800","46.89873","0.03290"
"35038","210.19200","46.91314","0.03281"
"35067","210.36600","46.92767","0.03266"
"35096","210.54000","46.94220","0.03344"
"35125","210.71400","46.95667","0.03260"
"35154","210.88800","46.97114","0.03317"
"35183","211.06200","46.98567","0.03313"
"35212","211.23600","47.00013","0.03343"
"35241","211.41000","47.01466","0.03299"
"35270","211.58400","47.02919","0.03211"
"35299","211.75800","47.04366","0.03374"
"35328","211.93200","47.05813","0.03299"
"35357","212.10600","47.07272","0.03314"
"35386","212.28000","47.08718","0.03290"
"35389","212.29800","47.08868","0.03310"