File: Trajectories_together/170122_2Specimen_RawData_9.csv
"","V1","V2","V3"
"1","End date","1/22/2017",""
"2","Specimen label","14BT_10",""
"3","Maximum Load","0.08602","N"
"4","Time","Extension","Load"
"5","(s)","(mm)","(N)"
"6","0.00000","0.00000","0.00011"
"72","0.39600","0.03324","0.00142"
"138","0.79200","0.06619","0.00115"
"204","1.18800","0.09925","0.00248"
"270","1.58400","0.13219","0.00357"
"336","1.98000","0.16520","0.00432"
"402","2.37600","0.19814","0.00403"
"468","2.77200","0.23121","0.00468"
"534","3.16800","0.26421","0.00452"
"600","3.56400","0.29721","0.00505"
"666","3.96000","0.33016","0.00602"
"732","4.35600","0.36328","0.00582"
"798","4.75200","0.39623","0.00584"
"864","5.14800","0.42917","0.00628"
"930","5.54400","0.46217","0.00669"
"996","5.94000","0.49524","0.00661"
"1062","6.33600","0.52824","0.00638"
"1128","6.73200","0.56112","0.00703"
"1194","7.12800","0.59419","0.00759"
"1260","7.52400","0.62719","0.00795"
"1326","7.92000","0.66020","0.00796"
"1392","8.31600","0.69308","0.00763"
"1458","8.71200","0.72614","0.00772"
"1524","9.10800","0.75921","0.00788"
"1590","9.50400","0.79221","0.00927"
"1656","9.90000","0.82516","0.00870"
"1722","10.29600","0.85816","0.00885"
"1788","10.69200","0.89116","0.00886"
"1854","11.08800","0.92417","0.00921"
"1920","11.48400","0.95717","0.00946"
"1986","11.88000","0.99017","0.00912"
"2052","12.27600","1.02324","0.00980"
"2118","12.67200","1.05618","0.01028"
"2184","13.06800","1.08913","0.01032"
"2250","13.46400","1.12225","0.00949"
"2316","13.86000","1.15513","0.00995"
"2382","14.25600","1.18820","0.01042"
"2448","14.65200","1.22120","0.01034"
"2514","15.04800","1.25420","0.01114"
"2580","15.44400","1.28721","0.01140"
"2646","15.84000","1.32015","0.01056"
"2712","16.23600","1.35316","0.01233"
"2778","16.63200","1.38616","0.01178"
"2844","17.02800","1.41922","0.01191"
"2910","17.42400","1.45223","0.01216"
"2976","17.82000","1.48523","0.01164"
"3042","18.21600","1.51818","0.01210"
"3108","18.61200","1.55124","0.01305"
"3174","19.00800","1.58418","0.01309"
"3240","19.40400","1.61725","0.01360"
"3306","19.80000","1.65025","0.01344"
"3372","20.19600","1.68314","0.01370"
"3438","20.59200","1.71620","0.01345"
"3504","20.98800","1.74926","0.01365"
"3570","21.38400","1.78221","0.01442"
"3636","21.78000","1.81515","0.01437"
"3702","22.17600","1.84821","0.01494"
"3768","22.57200","1.88122","0.01484"
"3834","22.96800","1.91416","0.01443"
"3900","23.36400","1.94711","0.01451"
"3966","23.76000","1.98023","0.01513"
"4032","24.15600","2.01323","0.01506"
"4098","24.55200","2.04618","0.01521"
"4164","24.94800","2.07912","0.01556"
"4230","25.34400","2.11219","0.01572"
"4296","25.74000","2.14525","0.01565"
"4362","26.13600","2.17819","0.01677"
"4428","26.53200","2.21114","0.01591"
"4494","26.92800","2.24426","0.01607"
"4560","27.32400","2.27726","0.01627"
"4626","27.72000","2.31015","0.01646"
"4692","28.11600","2.34321","0.01689"
"4758","28.51200","2.37622","0.01666"
"4824","28.90800","2.40922","0.01709"
"4890","29.30400","2.44216","0.01718"
"4956","29.70000","2.47517","0.01741"
"5022","30.09600","2.50817","0.01716"
"5088","30.49200","2.54117","0.01750"
"5154","30.88800","2.57412","0.01735"
"5220","31.28400","2.60718","0.01478"
"5286","31.68000","2.64019","0.01546"
"5352","32.07600","2.67313","0.01568"
"5418","32.47200","2.70619","0.01525"
"5484","32.86800","2.73920","0.01552"
"5550","33.26400","2.77220","0.01635"
"5616","33.66000","2.80521","0.01645"
"5682","34.05600","2.83821","0.01488"
"5748","34.45200","2.87121","0.01615"
"5814","34.84800","2.90422","0.01618"
"5880","35.24400","2.93716","0.01648"
"5946","35.64000","2.97016","0.01700"
"6012","36.03600","3.00323","0.01645"
"6078","36.43200","3.03617","0.01700"
"6144","36.82800","3.06912","0.01668"
"6210","37.22400","3.10224","0.01781"
"6276","37.62000","3.13524","0.01703"
"6342","38.01600","3.16813","0.01815"
"6408","38.41200","3.20113","0.01812"
"6474","38.80800","3.23426","0.01840"
"6540","39.20400","3.26720","0.01852"
"6606","39.60000","3.30014","0.01909"
"6672","39.99600","3.33321","0.01854"
"6738","40.39200","3.36627","0.01896"
"6804","40.78800","3.39921","0.01879"
"6870","41.18400","3.43210","0.01962"
"6936","41.58000","3.46516","0.01966"
"7002","41.97600","3.49823","0.02021"
"7068","42.37200","3.53123","0.02040"
"7134","42.76800","3.56411","0.02130"
"7200","43.16400","3.59718","0.02143"
"7266","43.56000","3.63018","0.02249"
"7332","43.95600","3.66325","0.02270"
"7398","44.35200","3.69613","0.02235"
"7464","44.74800","3.72913","0.02350"
"7530","45.14400","3.76220","0.02386"
"7596","45.54000","3.79520","0.02427"
"7662","45.93600","3.82814","0.02471"
"7728","46.33200","3.86121","0.02533"
"7794","46.72800","3.89421","0.02566"
"7860","47.12400","3.92716","0.02708"
"7926","47.52000","3.96016","0.02739"
"7992","47.91600","3.99322","0.02732"
"8058","48.31200","4.02617","0.02686"
"8124","48.70800","4.05917","0.02801"
"8190","49.10400","4.09223","0.02810"
"8256","49.50000","4.12518","0.02858"
"8322","49.89600","4.15812","0.02968"
"8388","50.29200","4.19113","0.02975"
"8454","50.68800","4.22419","0.03118"
"8520","51.08400","4.25719","0.03168"
"8586","51.48000","4.29020","0.03317"
"8652","51.87600","4.32320","0.03321"
"8718","52.27200","4.35621","0.03283"
"8784","52.66800","4.38921","0.03279"
"8850","53.06400","4.42215","0.03301"
"8916","53.46000","4.45516","0.02546"
"8982","53.85600","4.48822","0.02202"
"9048","54.25200","4.52122","0.02228"
"9114","54.64800","4.55411","0.02251"
"9180","55.04400","4.58723","0.02305"
"9246","55.44000","4.62024","0.02365"
"9312","55.83600","4.65318","0.02396"
"9378","56.23200","4.68612","0.02376"
"9444","56.62800","4.71919","0.02447"
"9510","57.02400","4.75225","0.02471"
"9576","57.42000","4.78520","0.02496"
"9642","57.81600","4.81808","0.02513"
"9708","58.21200","4.85120","0.02593"
"9774","58.60800","4.88421","0.02583"
"9840","59.00400","4.91721","0.02626"
"9906","59.40000","4.95015","0.02655"
"9972","59.79600","4.98316","0.02640"
"10038","60.19200","5.01622","0.02676"
"10104","60.58800","5.04917","0.02774"
"10170","60.98400","5.08217","0.02676"
"10236","61.38000","5.11517","0.02653"
"10302","61.77600","5.14824","0.02759"
"10368","62.17200","5.18118","0.02801"
"10434","62.56800","5.21419","0.02770"
"10500","62.96400","5.24719","0.02762"
"10566","63.36000","5.28025","0.02834"
"10632","63.75600","5.31320","0.02864"
"10698","64.15200","5.34620","0.02893"
"10764","64.54800","5.37920","0.02899"
"10830","64.94400","5.41215","0.02852"
"10896","65.34000","5.44515","0.02883"
"10962","65.73600","5.47816","0.02918"
"11028","66.13200","5.51116","0.02974"
"11094","66.52800","5.54416","0.02871"
"11160","66.92400","5.57723","0.02958"
"11226","67.32000","5.61017","0.02926"
"11292","67.71600","5.64318","0.02915"
"11358","68.11200","5.67618","0.03068"
"11424","68.50800","5.70918","0.03099"
"11490","68.90400","5.74219","0.03096"
"11556","69.30000","5.77519","0.03167"
"11622","69.69600","5.80814","0.03127"
"11688","70.09200","5.84120","0.03183"
"11754","70.48800","5.87420","0.03154"
"11820","70.88400","5.90721","0.03274"
"11886","71.28000","5.94009","0.03308"
"11952","71.67600","5.97321","0.03384"
"12018","72.07200","6.00622","0.03260"
"12084","72.46800","6.03916","0.03312"
"12150","72.86400","6.07211","0.03401"
"12216","73.26000","6.10523","0.03374"
"12282","73.65600","6.13829","0.03370"
"12348","74.05200","6.17118","0.03393"
"12414","74.44800","6.20418","0.03490"
"12480","74.84400","6.23724","0.03540"
"12546","75.24000","6.27025","0.03582"
"12612","75.63600","6.30313","0.03622"
"12678","76.03200","6.33620","0.03668"
"12744","76.42800","6.36920","0.03642"
"12810","76.82400","6.40226","0.03662"
"12876","77.22000","6.43515","0.03737"
"12942","77.61600","6.46815","0.03762"
"13008","78.01200","6.50121","0.03798"
"13074","78.40800","6.53422","0.03935"
"13140","78.80400","6.56710","0.03748"
"13206","79.20000","6.60023","0.03822"
"13272","79.59600","6.63317","0.03866"
"13338","79.99200","6.66623","0.03983"
"13404","80.38800","6.69918","0.03960"
"13470","80.78400","6.73218","0.03972"
"13536","81.18000","6.76519","0.04064"
"13602","81.57600","6.79819","0.03953"
"13668","81.97200","6.83119","0.03995"
"13734","82.36800","6.86420","0.04050"
"13800","82.76400","6.89720","0.04153"
"13866","83.16000","6.93015","0.04167"
"13932","83.55600","6.96321","0.04192"
"13998","83.95200","6.99621","0.04236"
"14064","84.34800","7.02922","0.04316"
"14130","84.74400","7.06216","0.04430"
"14196","85.14000","7.09522","0.04467"
"14262","85.53600","7.12817","0.04521"
"14328","85.93200","7.16117","0.04581"
"14394","86.32800","7.19418","0.04636"
"14460","86.72400","7.22718","0.04674"
"14526","87.12000","7.26018","0.04727"
"14592","87.51600","7.29319","0.04803"
"14658","87.91200","7.32613","0.04771"
"14724","88.30800","7.35926","0.01669"
"14790","88.70400","7.39226","0.02068"
"14856","89.10000","7.42514","0.01626"
"14922","89.49600","7.45815","0.01784"
"14988","89.89200","7.49127","0.01790"
"15054","90.28800","7.52421","0.01800"
"15120","90.68400","7.55716","0.02015"
"15186","91.08000","7.59022","0.02118"
"15252","91.47600","7.62323","0.02110"
"15318","91.87200","7.65623","0.02098"
"15384","92.26800","7.68911","0.02178"
"15450","92.66400","7.72224","0.02259"
"15516","93.06000","7.75524","0.02146"
"15582","93.45600","7.78824","0.02230"
"15648","93.85200","7.82113","0.02357"
"15714","94.24800","7.85413","0.02411"
"15780","94.64400","7.88720","0.02350"
"15846","95.04000","7.92020","0.02501"
"15912","95.43600","7.95314","0.02561"
"15978","95.83200","7.98621","0.02544"
"16044","96.22800","8.01921","0.02542"
"16110","96.62400","8.05216","0.02558"
"16176","97.02000","8.08522","0.02648"
"16242","97.41600","8.11822","0.02729"
"16308","97.81200","8.15123","0.02740"
"16374","98.20800","8.18417","0.02455"
"16440","98.60400","8.21717","0.02492"
"16506","99.00000","8.25024","0.02464"
"16572","99.39600","8.28318","0.02431"
"16638","99.79200","8.31619","0.02520"
"16704","100.18800","8.34919","0.02578"
"16770","100.58400","8.38219","0.02570"
"16836","100.98000","8.41520","0.02565"
"16902","101.37600","8.44820","0.02670"
"16968","101.77200","8.48120","0.02745"
"17034","102.16800","8.51421","0.02754"
"17100","102.56400","8.54715","0.02791"
"17166","102.96000","8.58016","0.02776"
"17232","103.35600","8.61322","0.02857"
"17298","103.75200","8.64622","0.02890"
"17364","104.14800","8.67923","0.02964"
"17430","104.54400","8.71217","0.02878"
"17496","104.94000","8.74524","0.02946"
"17562","105.33600","8.77818","0.02892"
"17628","105.73200","8.81112","0.02959"
"17694","106.12800","8.84419","0.02990"
"17760","106.52400","8.87725","0.02441"
"17826","106.92000","8.91014","0.02331"
"17892","107.31600","8.94314","0.02401"
"17958","107.71200","8.97620","0.02479"
"18024","108.10800","9.00921","0.02551"
"18090","108.50400","9.04221","0.02529"
"18156","108.90000","9.07509","0.02587"
"18222","109.29600","9.10822","0.02599"
"18288","109.69200","9.14128","0.02571"
"18354","110.08800","9.17417","0.02623"
"18420","110.48400","9.20717","0.02567"
"18486","110.88000","9.24023","0.02532"
"18552","111.27600","9.27324","0.02571"
"18618","111.67200","9.30618","0.02657"
"18684","112.06800","9.33918","0.02727"
"18750","112.46400","9.37219","0.02782"
"18816","112.86000","9.40519","0.02810"
"18882","113.25600","9.43814","0.02813"
"18948","113.65200","9.47114","0.02882"
"19014","114.04800","9.50420","0.02975"
"19080","114.44400","9.53721","0.02991"
"19146","114.84000","9.57015","0.02960"
"19212","115.23600","9.60322","0.02986"
"19278","115.63200","9.63622","0.03028"
"19344","116.02800","9.66916","0.03004"
"19410","116.42400","9.70217","0.03028"
"19476","116.82000","9.73523","0.03043"
"19542","117.21600","9.76818","0.03025"
"19608","117.61200","9.80118","0.03100"
"19674","118.00800","9.83418","0.03145"
"19740","118.40400","9.86719","0.03217"
"19806","118.80000","9.90019","0.03285"
"19872","119.19600","9.93319","0.03323"
"19938","119.59200","9.96620","0.03427"
"20004","119.98800","9.99920","0.03442"
"20070","120.38400","10.03215","0.03498"
"20136","120.78000","10.06515","0.03595"
"20202","121.17600","10.09821","0.03466"
"20268","121.57200","10.13122","0.03560"
"20334","121.96800","10.16416","0.03524"
"20400","122.36400","10.19710","0.03636"
"20466","122.76000","10.23023","0.03660"
"20532","123.15600","10.26323","0.03684"
"20598","123.55200","10.29618","0.03764"
"20664","123.94800","10.32912","0.03842"
"20730","124.34400","10.36218","0.03939"
"20796","124.74000","10.39525","0.03879"
"20862","125.13600","10.42813","0.03899"
"20928","125.53200","10.46119","0.03819"
"20994","125.92800","10.49420","0.03891"
"21060","126.32400","10.52720","0.03871"
"21126","126.72000","10.56015","0.03916"
"21192","127.11600","10.59321","0.03860"
"21258","127.51200","10.62615","0.03856"
"21324","127.90800","10.65922","0.03860"
"21390","128.30400","10.69216","0.03915"
"21456","128.70000","10.72517","0.04010"
"21522","129.09600","10.75817","0.03793"
"21588","129.49200","10.79123","0.03512"
"21654","129.88800","10.82412","0.03635"
"21720","130.28400","10.85718","0.03592"
"21786","130.68000","10.89019","0.03660"
"21852","131.07600","10.92319","0.03722"
"21918","131.47200","10.95619","0.03809"
"21984","131.86800","10.98920","0.03701"
"22050","132.26400","11.02226","0.03657"
"22116","132.66000","11.05514","0.03758"
"22182","133.05600","11.08815","0.03833"
"22248","133.45200","11.12121","0.03871"
"22314","133.84800","11.15422","0.03920"
"22380","134.24400","11.18716","0.03910"
"22446","134.64000","11.22022","0.03904"
"22512","135.03600","11.25317","0.04007"
"22578","135.43200","11.28617","0.04037"
"22644","135.82800","11.31917","0.04088"
"22710","136.22400","11.35218","0.04191"
"22776","136.62000","11.38524","0.04183"
"22842","137.01600","11.41819","0.04289"
"22908","137.41200","11.45119","0.04165"
"22974","137.80800","11.48425","0.04046"
"23040","138.20400","11.51720","0.04060"
"23106","138.60000","11.55014","0.04155"
"23172","138.99600","11.58315","0.04167"
"23238","139.39200","11.61621","0.04241"
"23304","139.78800","11.64921","0.04403"
"23370","140.18400","11.68216","0.04390"
"23436","140.58000","11.71522","0.04393"
"23502","140.97600","11.74822","0.04373"
"23568","141.37200","11.78117","0.04443"
"23634","141.76800","11.81411","0.04474"
"23700","142.16400","11.84718","0.04520"
"23766","142.56000","11.88024","0.04588"
"23832","142.95600","11.91318","0.04613"
"23898","143.35200","11.94613","0.04706"
"23964","143.74800","11.97919","0.04594"
"24030","144.14400","12.01219","0.04714"
"24096","144.54000","12.04520","0.04744"
"24162","144.93600","12.07820","0.04699"
"24228","145.33200","12.11121","0.04775"
"24294","145.72800","12.14421","0.04785"
"24360","146.12400","12.17721","0.04896"
"24426","146.52000","12.21016","0.04896"
"24492","146.91600","12.24322","0.04435"
"24558","147.31200","12.27623","0.04405"
"24624","147.70800","12.30917","0.04381"
"24690","148.10400","12.34217","0.04549"
"24756","148.50000","12.37518","0.04610"
"24822","148.89600","12.40824","0.04674"
"24888","149.29200","12.44112","0.04725"
"24954","149.68800","12.47419","0.04842"
"25020","150.08400","12.50719","0.04940"
"25086","150.48000","12.54020","0.05024"
"25152","150.87600","12.57320","0.05117"
"25218","151.27200","12.60620","0.05191"
"25284","151.66800","12.63921","0.05266"
"25350","152.06400","12.67215","0.05287"
"25416","152.46000","12.70516","0.05371"
"25482","152.85600","12.73822","0.05400"
"25548","153.25200","12.77116","0.05473"
"25614","153.64800","12.80417","0.05515"
"25680","154.04400","12.83717","0.05557"
"25746","154.44000","12.87024","0.05581"
"25812","154.83600","12.90318","0.05599"
"25878","155.23200","12.93618","0.05574"
"25944","155.62800","12.96919","0.05676"
"26010","156.02400","13.00219","0.05762"
"26076","156.42000","13.03520","0.05759"
"26142","156.81600","13.06814","0.05731"
"26208","157.21200","13.10120","0.05805"
"26274","157.60800","13.13421","0.05828"
"26340","158.00400","13.16715","0.05849"
"26406","158.40000","13.20015","0.05706"
"26472","158.79600","13.23316","0.05760"
"26538","159.19200","13.26622","0.05823"
"26604","159.58800","13.29917","0.05838"
"26670","159.98400","13.33217","0.05849"
"26736","160.38000","13.36523","0.05909"
"26802","160.77600","13.39818","0.05968"
"26868","161.17200","13.43112","0.06007"
"26934","161.56800","13.46419","0.06018"
"27000","161.96400","13.49719","0.05877"
"27066","162.36000","13.53019","0.05637"
"27132","162.75600","13.56320","0.05720"
"27198","163.15200","13.59614","0.05754"
"27264","163.54800","13.62920","0.05915"
"27330","163.94400","13.66221","0.05970"
"27396","164.34000","13.69515","0.06111"
"27462","164.73600","13.72822","0.06213"
"27528","165.13200","13.76122","0.06340"
"27594","165.52800","13.79422","0.06480"
"27660","165.92400","13.82717","0.06627"
"27726","166.32000","13.86017","0.06638"
"27792","166.71600","13.89323","0.06731"
"27858","167.11200","13.92618","0.06838"
"27924","167.50800","13.95918","0.06972"
"27990","167.90400","13.99225","0.07117"
"28056","168.30000","14.02525","0.07251"
"28122","168.69600","14.05813","0.07398"
"28188","169.09200","14.09120","0.07549"
"28254","169.48800","14.12420","0.07740"
"28320","169.88400","14.15721","0.07899"
"28386","170.28000","14.19015","0.08043"
"28452","170.67600","14.22321","0.08240"
"28518","171.07200","14.25622","0.08401"
"28584","171.46800","14.28916","0.08539"
"28650","171.86400","14.32216","0.08267"
"28716","172.26000","14.35517","0.08043"
"28782","172.65600","14.38823","0.07946"
"28848","173.05200","14.42118","0.07785"
"28914","173.44800","14.45418","0.07524"
"28980","173.84400","14.48718","0.07580"
"29046","174.24000","14.52025","0.07087"
"29112","174.63600","14.55313","0.05631"
"29178","175.03200","14.58614","0.05658"
"29244","175.42800","14.61926","0.05785"
"29310","175.82400","14.65220","0.05819"
"29376","176.22000","14.68509","0.05994"
"29442","176.61600","14.71821","0.06060"
"29508","177.01200","14.75121","0.06219"
"29574","177.40800","14.78422","0.06365"
"29640","177.80400","14.81716","0.06460"
"29706","178.20000","14.85023","0.06605"
"29772","178.59600","14.88323","0.06791"
"29838","178.99200","14.91617","0.06936"
"29904","179.38800","14.94912","0.04611"
"29970","179.78400","14.98218","0.04401"
"30036","180.18000","15.01518","0.04440"
"30102","180.57600","15.04819","0.02807"
"30168","180.97200","15.08113","0.02896"
"30234","181.36800","15.11420","0.02920"
"30300","181.76400","15.14720","0.02988"
"30366","182.16000","15.18020","0.03108"
"30432","182.55600","15.21321","0.03222"
"30498","182.95200","15.24621","0.03434"
"30564","183.34800","15.27916","0.02619"
"30630","183.74400","15.31216","0.02630"
"30696","184.14000","15.34516","0.02406"
"30762","184.53600","15.37817","0.01963"
"30828","184.93200","15.41117","0.02018"
"30894","185.32800","15.44411","0.02088"
"30960","185.72400","15.47724","0.02055"
"31026","186.12000","15.51018","0.02152"
"31092","186.51600","15.54313","0.02124"
"31158","186.91200","15.57613","0.02157"
"31224","187.30800","15.60925","0.02214"
"31290","187.70400","15.64220","0.02265"
"31356","188.10000","15.67514","0.02285"
"31422","188.49600","15.70820","0.02300"
"31488","188.89200","15.74121","0.02316"
"31554","189.28800","15.77421","0.02319"
"31620","189.68400","15.80716","0.02364"
"31686","190.08000","15.84016","0.02437"
"31752","190.47600","15.87322","0.02414"
"31818","190.87200","15.90623","0.02444"
"31884","191.26800","15.93911","0.02476"
"31950","191.66400","15.97224","0.02473"
"32016","192.06000","16.00518","0.02477"
"32082","192.45600","16.03824","0.02579"
"32148","192.85200","16.07119","0.02595"
"32214","193.24800","16.10419","0.02621"
"32280","193.64400","16.13719","0.02690"
"32346","194.04000","16.17020","0.02732"
"32412","194.43600","16.20314","0.02795"
"32478","194.83200","16.23621","0.02833"
"32544","195.22800","16.26921","0.02915"
"32610","195.62400","16.30215","0.02953"
"32676","196.02000","16.33522","0.02966"
"32742","196.41600","16.36822","0.03046"
"32808","196.81200","16.40117","0.03088"
"32874","197.20800","16.43417","0.03188"
"32940","197.60400","16.46717","0.03281"
"33006","198.00000","16.50018","0.03338"
"33072","198.39600","16.53318","0.03444"
"33138","198.79200","16.56618","0.03532"
"33204","199.18800","16.59919","0.03691"
"33270","199.58400","16.63219","0.03751"
"33336","199.98000","16.66520","0.03880"
"33402","200.37600","16.69814","0.03927"
"33468","200.77200","16.73120","0.04041"
"33534","201.16800","16.76427","0.03981"
"33600","201.56400","16.79715","0.04126"
"33666","201.96000","16.83016","0.04114"
"33732","202.35600","16.86322","0.04257"
"33798","202.75200","16.89622","0.04256"
"33864","203.14800","16.92917","0.04450"
"33930","203.54400","16.96223","0.04444"
"33996","203.94000","16.99523","0.04631"
"34062","204.33600","17.02818","0.04763"
"34128","204.73200","17.06112","0.04774"
"34194","205.12800","17.09418","0.04879"
"34260","205.52400","17.12725","0.04996"
"34326","205.92000","17.16019","0.05058"
"34392","206.31600","17.19320","0.05130"
"34458","206.71200","17.22614","0.05211"
"34524","207.10800","17.25926","0.05252"
"34590","207.50400","17.29221","0.05260"
"34656","207.90000","17.32515","0.05366"
"34722","208.29600","17.35822","0.05049"
"34788","208.69200","17.39122","0.04854"
"34854","209.08800","17.42416","0.04957"
"34920","209.48400","17.45717","0.05009"
"34986","209.88000","17.49023","0.05174"
"35052","210.27600","17.52324","0.05177"
"35118","210.67200","17.55618","0.05189"
"35184","211.06800","17.58918","0.04837"
"35250","211.46400","17.62219","0.04911"
"35316","211.86000","17.65519","0.05000"
"35382","212.25600","17.68814","0.05074"
"35448","212.65200","17.72120","0.05129"
"35514","213.04800","17.75420","0.05279"
"35580","213.44400","17.78721","0.05267"
"35646","213.84000","17.82021","0.05339"
"35712","214.23600","17.85321","0.05419"
"35778","214.63200","17.88622","0.05460"
"35844","215.02800","17.91916","0.05482"
"35910","215.42400","17.95217","0.05560"
"35976","215.82000","17.98523","0.05622"
"36042","216.21600","18.01823","0.05668"
"36108","216.61200","18.05118","0.05742"
"36174","217.00800","18.08418","0.05790"
"36240","217.40400","18.11719","0.05835"
"36306","217.80000","18.15025","0.05896"
"36372","218.19600","18.18313","0.04339"
"36438","218.59200","18.21626","0.04188"
"36504","218.98800","18.24926","0.04137"
"36570","219.38400","18.28221","0.04364"
"36636","219.78000","18.31515","0.04561"
"36702","220.17600","18.34821","0.04590"
"36768","220.57200","18.38116","0.04583"
"36834","220.96800","18.41416","0.04709"
"36900","221.36400","18.44716","0.04853"
"36966","221.76000","18.48017","0.04856"
"37032","222.15600","18.51323","0.04909"
"37098","222.55200","18.54612","0.05000"
"37164","222.94800","18.57918","0.05146"
"37230","223.34400","18.61218","0.05203"
"37296","223.74000","18.64519","0.05265"
"37362","224.13600","18.67813","0.05257"
"37428","224.53200","18.71113","0.05419"
"37494","224.92800","18.74420","0.05424"
"37560","225.32400","18.77720","0.05501"
"37626","225.72000","18.81015","0.05517"
"37692","226.11600","18.84321","0.05572"
"37758","226.51200","18.87621","0.05691"
"37824","226.90800","18.90922","0.05754"
"37890","227.30400","18.94210","0.05858"
"37956","227.70000","18.97516","0.05962"
"38022","228.09600","19.00823","0.06022"
"38088","228.49200","19.04123","0.06099"
"38154","228.88800","19.07418","0.06096"
"38220","229.28400","19.10724","0.06219"
"38286","229.68000","19.14018","0.06332"
"38352","230.07600","19.17319","0.06477"
"38418","230.47200","19.20619","0.06639"
"38484","230.86800","19.23914","0.06573"
"38550","231.26400","19.27220","0.06733"
"38616","231.66000","19.30520","0.06888"
"38682","232.05600","19.33815","0.07009"
"38748","232.45200","19.37121","0.06931"
"38814","232.84800","19.40421","0.07086"
"38880","233.24400","19.43710","0.07260"
"38946","233.64000","19.47022","0.07422"
"39012","234.03600","19.50317","0.07565"
"39078","234.43200","19.53617","0.07732"
"39144","234.82800","19.56917","0.07578"
"39210","235.22400","19.60224","0.07775"
"39276","235.62000","19.63524","0.07982"
"39342","236.01600","19.66813","0.08156"
"39408","236.41200","19.70113","0.05863"
"39474","236.80800","19.73425","0.05807"
"39540","237.20400","19.76719","0.05740"
"39606","237.60000","19.80014","0.05938"
"39672","237.99600","19.83315","0.05961"
"39738","238.39200","19.86621","0.01902"
"39804","238.78800","19.89915","0.01332"
"39870","239.18400","19.93216","0.00846"
"39936","239.58000","19.96516","0.01246"
"40002","239.97600","19.99822","0.01095"
"40068","240.37200","20.03123","0.01111"
"40134","240.76800","20.06411","0.01385"
"40200","241.16400","20.09718","0.01238"
"40266","241.56000","20.13018","0.01435"
"40332","241.95600","20.16318","0.00900"
"40398","242.35200","20.19613","0.01371"
"40464","242.74800","20.22919","0.01561"
"40530","243.14400","20.26225","0.01000"
"40596","243.54000","20.29520","0.01649"
"40662","243.93600","20.32814","0.01269"
"40728","244.33200","20.36121","0.01213"
"40794","244.72800","20.39421","0.01457"
"40860","245.12400","20.42715","0.01326"
"40926","245.52000","20.46016","0.01519"
"40992","245.91600","20.49322","0.01223"
"41058","246.31200","20.52622","0.01574"
"41124","246.70800","20.55917","0.01412"
"41190","247.10400","20.59217","0.01339"
"41256","247.50000","20.62518","0.01574"
"41322","247.89600","20.65818","0.01450"
"41388","248.29200","20.69118","0.01413"
"41454","248.68800","20.72419","0.01441"
"41520","249.08400","20.75719","0.01586"
"41586","249.48000","20.79014","0.01549"
"41652","249.87600","20.82314","0.01484"
"41718","250.27200","20.85620","0.01652"
"41784","250.66800","20.88921","0.01524"
"41850","251.06400","20.92215","0.01569"
"41916","251.46000","20.95515","0.01570"
"41982","251.85600","20.98822","0.01590"
"42048","252.25200","21.02122","0.01491"
"42114","252.64800","21.05417","0.01577"
"42180","253.04400","21.08723","0.01647"
"42246","253.44000","21.12017","0.01615"
"42312","253.83600","21.15318","0.01712"
"42378","254.23200","21.18612","0.01624"
"42444","254.62800","21.21925","0.01727"
"42510","255.02400","21.25225","0.01716"
"42576","255.42000","21.28513","0.01739"
"42642","255.81600","21.31808","0.01786"
"42708","256.21200","21.35120","0.01832"
"42774","256.60800","21.38420","0.01748"
"42840","257.00400","21.41715","0.01828"
"42906","257.40000","21.45021","0.01814"
"42972","257.79600","21.48315","0.01889"
"43038","258.19200","21.51622","0.01880"
"43104","258.58800","21.54917","0.01942"
"43170","258.98400","21.58211","0.01849"
"43236","259.38000","21.61523","0.01939"
"43302","259.77600","21.64829","0.01894"
"43368","260.17200","21.68112","0.02006"
"43434","260.56800","21.71418","0.01994"
"43500","260.96400","21.74725","0.02010"
"43566","261.36000","21.78019","0.02001"
"43632","261.75600","21.81314","0.02050"
"43698","262.15200","21.84620","0.02086"
"43764","262.54800","21.87920","0.02141"
"43830","262.94400","21.91221","0.02127"
"43896","263.34000","21.94515","0.02169"
"43962","263.73600","21.97821","0.02117"
"44028","264.13200","22.01116","0.02196"
"44094","264.52800","22.04422","0.02256"
"44160","264.92400","22.07717","0.02305"
"44226","265.32000","22.11023","0.02309"
"44292","265.71600","22.14323","0.02233"
"44358","266.11200","22.17618","0.02332"
"44424","266.50800","22.20918","0.02215"
"44490","266.90400","22.24218","0.02180"
"44556","267.30000","22.27519","0.02294"
"44622","267.69600","22.30819","0.02194"
"44688","268.09200","22.34126","0.02266"
"44754","268.48800","22.37420","0.02314"
"44820","268.88400","22.40720","0.02348"
"44886","269.28000","22.44015","0.02409"
"44952","269.67600","22.47321","0.02380"
"45018","270.07200","22.50621","0.02375"
"45084","270.46800","22.53916","0.02456"
"45150","270.86400","22.57216","0.02317"
"45216","271.26000","22.60523","0.02384"
"45282","271.65600","22.63823","0.02457"
"45348","272.05200","22.67118","0.02441"
"45414","272.44800","22.70412","0.02449"
"45480","272.84400","22.73718","0.02483"
"45546","273.24000","22.77019","0.02504"
"45612","273.63600","22.80313","0.02449"
"45678","274.03200","22.83619","0.02485"
"45744","274.42800","22.86926","0.02488"
"45810","274.82400","22.90220","0.02542"
"45876","275.22000","22.93509","0.02545"
"45942","275.61600","22.96815","0.02508"
"46008","276.01200","23.00121","0.02557"
"46074","276.40800","23.03422","0.02617"
"46140","276.80400","23.06716","0.02640"
"46206","277.20000","23.10023","0.02618"
"46272","277.59600","23.13323","0.02685"
"46338","277.99200","23.16623","0.02703"
"46404","278.38800","23.19917","0.02726"
"46470","278.78400","23.23224","0.02714"
"46536","279.18000","23.26524","0.02690"
"46602","279.57600","23.29819","0.02801"
"46668","279.97200","23.33113","0.02769"
"46734","280.36800","23.36419","0.02762"
"46800","280.76400","23.39720","0.02767"
"46866","281.16000","23.43014","0.02814"
"46932","281.55600","23.46321","0.02796"
"46998","281.95200","23.49621","0.02814"
"47064","282.34800","23.52921","0.02779"
"47130","282.74400","23.56222","0.02789"
"47196","283.14000","23.59522","0.02893"
"47262","283.53600","23.62817","0.02886"
"47328","283.93200","23.66117","0.02912"
"47394","284.32800","23.69417","0.02926"
"47460","284.72400","23.72724","0.03040"
"47526","285.12000","23.76018","0.02939"
"47592","285.51600","23.79318","0.03043"
"47658","285.91200","23.82613","0.03098"
"47724","286.30800","23.85919","0.03138"
"47790","286.70400","23.89226","0.03142"
"47856","287.10000","23.92514","0.03079"
"47922","287.49600","23.95820","0.03112"
"47988","287.89200","23.99121","0.03028"
"48054","288.28800","24.02415","0.03135"
"48120","288.68400","24.05716","0.03156"
"48186","289.08000","24.09016","0.03063"
"48252","289.47600","24.12322","0.03195"
"48318","289.87200","24.15617","0.03178"
"48384","290.26800","24.18917","0.03224"
"48450","290.66400","24.22218","0.03179"
"48516","291.06000","24.25524","0.03228"
"48582","291.45600","24.28818","0.03339"
"48648","291.85200","24.32119","0.03355"
"48714","292.24800","24.35413","0.03272"
"48780","292.64400","24.38725","0.03364"
"48846","293.04000","24.42020","0.03362"
"48912","293.43600","24.45314","0.03389"
"48978","293.83200","24.48627","0.03465"
"49044","294.22800","24.51921","0.03423"
"49110","294.62400","24.55215","0.03412"
"49176","295.02000","24.58516","0.03452"
"49242","295.41600","24.61822","0.03512"
"49308","295.81200","24.65122","0.03394"
"49374","296.20800","24.68417","0.02655"
"49440","296.60400","24.71717","0.02565"
"49506","297.00000","24.75018","0.02506"
"49572","297.39600","24.78324","0.02009"
"49638","297.79200","24.81618","0.01904"
"49704","298.18800","24.84919","0.01807"
"49770","298.58400","24.88219","0.01931"
"49836","298.98000","24.91513","0.01988"
"49902","299.37600","24.94820","0.01785"
"49968","299.77200","24.98114","0.01078"
"50034","300.16800","25.01421","0.01030"
"50100","300.56400","25.04715","0.01227"
"50166","300.96000","25.08015","0.01064"
"50232","301.35600","25.11322","0.01194"
"50298","301.75200","25.14616","0.01139"
"50364","302.14800","25.17916","0.01247"
"50430","302.54400","25.21223","0.01292"
"50496","302.94000","25.24517","0.01237"
"50562","303.33600","25.27818","0.01230"
"50628","303.73200","25.31112","0.01343"
"50694","304.12800","25.34418","0.01328"
"50760","304.52400","25.37719","0.01437"
"50826","304.92000","25.41013","0.01420"
"50892","305.31600","25.44314","0.01399"
"50958","305.71200","25.47626","0.01414"
"51024","306.10800","25.50920","0.01482"
"51090","306.50400","25.54215","0.01588"
"51156","306.90000","25.57515","0.01577"
"51222","307.29600","25.60822","0.01633"
"51288","307.69200","25.64128","0.01683"
"51354","308.08800","25.67410","0.01680"
"51420","308.48400","25.70717","0.01603"
"51486","308.88000","25.74017","0.01678"
"51552","309.27600","25.77324","0.01740"
"51618","309.67200","25.80612","0.01782"
"51684","310.06800","25.83912","0.01737"
"51750","310.46400","25.87219","0.01876"
"51816","310.86000","25.90519","0.01857"
"51882","311.25600","25.93814","0.01880"
"51948","311.65200","25.97114","0.01949"
"52014","312.04800","26.00420","0.01928"
"52080","312.44400","26.03721","0.01947"
"52146","312.84000","26.07015","0.02017"
"52212","313.23600","26.10321","0.02028"
"52278","313.63200","26.13622","0.02015"
"52344","314.02800","26.16916","0.02095"
"52410","314.42400","26.20216","0.02147"
"52476","314.82000","26.23523","0.02197"
"52542","315.21600","26.26817","0.02172"
"52608","315.61200","26.30118","0.02179"
"52674","316.00800","26.33418","0.02165"
"52740","316.40400","26.36719","0.02209"
"52806","316.80000","26.40019","0.02209"
"52872","317.19600","26.43313","0.02242"
"52938","317.59200","26.46625","0.02243"
"53004","317.98800","26.49914","0.02264"
"53070","318.38400","26.53221","0.02336"
"53136","318.78000","26.56515","0.02337"
"53202","319.17600","26.59821","0.02329"
"53268","319.57200","26.63116","0.02404"
"53334","319.96800","26.66416","0.02374"
"53400","320.36400","26.69716","0.02466"
"53466","320.76000","26.73023","0.02476"
"53532","321.15600","26.76323","0.02491"
"53598","321.55200","26.79612","0.02577"
"53664","321.94800","26.82918","0.02600"
"53730","322.34400","26.86218","0.02665"
"53796","322.74000","26.89518","0.02632"
"53862","323.13600","26.92813","0.02645"
"53928","323.53200","26.96119","0.02663"
"53994","323.92800","26.99426","0.02684"
"54060","324.32400","27.02720","0.02688"
"54126","324.72000","27.06008","0.02690"
"54192","325.11600","27.09321","0.02809"
"54258","325.51200","27.12621","0.02699"
"54324","325.90800","27.15916","0.02744"
"54390","326.30400","27.19216","0.02798"
"54456","326.70000","27.22516","0.02767"
"54522","327.09600","27.25823","0.02774"
"54588","327.49200","27.29123","0.02759"
"54654","327.88800","27.32417","0.02878"
"54720","328.28400","27.35718","0.02944"
"54786","328.68000","27.39024","0.02954"
"54852","329.07600","27.42319","0.02597"
"54918","329.47200","27.45619","0.02497"
"54984","329.86800","27.48920","0.02561"
"55050","330.26400","27.52220","0.02611"
"55116","330.66000","27.55514","0.02676"
"55182","331.05600","27.58815","0.02731"
"55248","331.45200","27.62121","0.02698"
"55314","331.84800","27.65421","0.02714"
"55380","332.24400","27.68722","0.02750"
"55446","332.64000","27.72016","0.02716"
"55512","333.03600","27.75311","0.02699"
"55578","333.43200","27.78617","0.02793"
"55644","333.82800","27.81917","0.02729"
"55710","334.22400","27.85218","0.02751"
"55776","334.62000","27.88518","0.02450"
"55842","335.01600","27.91813","0.02545"
"55908","335.41200","27.95119","0.02568"
"55974","335.80800","27.98425","0.02601"
"56040","336.20400","28.01720","0.02675"
"56106","336.60000","28.05014","0.02741"
"56172","336.99600","28.08320","0.02780"
"56238","337.39200","28.11621","0.02839"
"56304","337.78800","28.14921","0.02867"
"56370","338.18400","28.18216","0.02921"
"56436","338.58000","28.21522","0.02898"
"56502","338.97600","28.24822","0.02935"
"56568","339.37200","28.28117","0.02974"
"56634","339.76800","28.31411","0.02271"
"56700","340.16400","28.34723","0.01870"
"56766","340.56000","28.38024","0.01752"
"56832","340.95600","28.41312","0.01918"
"56898","341.35200","28.44619","0.01778"
"56964","341.74800","28.47925","0.02032"
"57030","342.14400","28.51225","0.01980"
"57096","342.54000","28.54514","0.02052"
"57162","342.93600","28.57820","0.02134"
"57228","343.33200","28.61121","0.02144"
"57294","343.72800","28.64427","0.02362"
"57360","344.12400","28.67715","0.02290"
"57426","344.52000","28.71016","0.02375"
"57492","344.91600","28.74322","0.02404"
"57558","345.31200","28.77616","0.02540"
"57624","345.70800","28.80911","0.02501"
"57690","346.10400","28.84217","0.02626"
"57756","346.50000","28.87524","0.02616"
"57822","346.89600","28.90818","0.02699"
"57888","347.29200","28.94112","0.02635"
"57954","347.68800","28.97419","0.02733"
"58020","348.08400","29.00719","0.02773"
"58086","348.48000","29.04020","0.02866"
"58152","348.87600","29.07320","0.02855"
"58218","349.27200","29.10620","0.02914"
"58284","349.66800","29.13921","0.02970"
"58350","350.06400","29.17221","0.03009"
"58416","350.46000","29.20521","0.02994"
"58482","350.85600","29.23822","0.03077"
"58548","351.25200","29.27122","0.03110"
"58614","351.64800","29.30417","0.03085"
"58680","352.04400","29.33723","0.03169"
"58746","352.44000","29.37017","0.03196"
"58812","352.83600","29.40318","0.03157"
"58878","353.23200","29.43612","0.03205"
"58944","353.62800","29.46924","0.03183"
"59010","354.02400","29.50219","0.03254"
"59076","354.42000","29.53519","0.03277"
"59142","354.81600","29.56820","0.02889"
"59208","355.21200","29.60126","0.02962"
"59274","355.60800","29.63420","0.02903"
"59340","356.00400","29.66715","0.03011"
"59406","356.40000","29.70015","0.03092"
"59472","356.79600","29.73322","0.03133"
"59538","357.19200","29.76622","0.03172"
"59604","357.58800","29.79910","0.03147"
"59670","357.98400","29.83217","0.03276"
"59736","358.38000","29.86517","0.03225"
"59802","358.77600","29.89817","0.03330"
"59868","359.17200","29.93112","0.03302"
"59934","359.56800","29.96418","0.03381"
"60000","359.96400","29.99719","0.03353"
"60066","360.36000","30.03019","0.03433"
"60132","360.75600","30.06313","0.03470"
"60198","361.15200","30.09614","0.03566"
"60264","361.54800","30.12920","0.03618"
"60330","361.94400","30.16221","0.03684"
"60396","362.34000","30.19515","0.03710"
"60462","362.73600","30.22821","0.03744"
"60528","363.13200","30.26122","0.03784"
"60594","363.52800","30.29422","0.03930"
"60660","363.92400","30.32716","0.04012"
"60726","364.32000","30.36017","0.04146"
"60792","364.71600","30.39323","0.04148"
"60858","365.11200","30.42618","0.04305"
"60924","365.50800","30.45918","0.04354"
"60990","365.90400","30.49224","0.04384"
"61056","366.30000","30.52519","0.04568"
"61122","366.69600","30.55813","0.04509"
"61188","367.09200","30.59120","0.04316"
"61254","367.48800","30.62414","0.04366"
"61320","367.88400","30.65720","0.04537"
"61386","368.28000","30.69021","0.04559"
"61452","368.67600","30.72321","0.04655"
"61518","369.07200","30.75616","0.04763"
"61584","369.46800","30.78916","0.04804"
"61650","369.86400","30.82216","0.04866"
"61716","370.26000","30.85523","0.04845"
"61782","370.65600","30.88823","0.04935"
"61848","371.05200","30.92118","0.04457"
"61914","371.44800","30.95412","0.04404"
"61980","371.84400","30.98724","0.04311"
"62046","372.24000","31.02019","0.04336"
"62112","372.63600","31.05307","0.04367"
"62178","373.03200","31.08619","0.04483"
"62244","373.42800","31.11920","0.04536"
"62310","373.82400","31.15220","0.04681"
"62376","374.22000","31.18515","0.04732"
"62442","374.61600","31.21821","0.04854"
"62508","375.01200","31.25121","0.04384"
"62574","375.40800","31.28415","0.04476"
"62640","375.80400","31.31716","0.04509"
"62706","376.20000","31.35022","0.04580"
"62772","376.59600","31.38323","0.04626"
"62838","376.99200","31.41617","0.04606"
"62904","377.38800","31.44917","0.04771"
"62970","377.78400","31.48224","0.04779"
"63036","378.18000","31.51524","0.04850"
"63102","378.57600","31.54819","0.04922"
"63168","378.97200","31.58119","0.04956"
"63234","379.36800","31.61419","0.04981"
"63300","379.76400","31.64726","0.04979"
"63366","380.16000","31.68020","0.04965"
"63432","380.55600","31.71315","0.04737"
"63498","380.95200","31.74621","0.04875"
"63564","381.34800","31.77921","0.03940"
"63630","381.74400","31.81216","0.04053"
"63696","382.14000","31.84522","0.04034"
"63762","382.53600","31.87816","0.04449"
"63828","382.93200","31.91117","0.04345"
"63894","383.32800","31.94417","0.04472"
"63960","383.72400","31.97718","0.04658"
"64026","384.12000","32.01018","0.04595"
"64092","384.51600","32.04312","0.04682"
"64158","384.91200","32.07619","0.04511"
"64224","385.30800","32.10919","0.04398"
"64290","385.70400","32.14220","0.03841"
"64356","386.10000","32.17514","0.03118"
"64422","386.49600","32.20820","0.02790"
"64488","386.89200","32.24121","0.02900"
"64554","387.28800","32.27421","0.02949"
"64620","387.68400","32.30716","0.03019"
"64686","388.08000","32.34016","0.03059"
"64752","388.47600","32.37322","0.03104"
"64818","388.87200","32.40617","0.03233"
"64884","389.26800","32.43911","0.03349"
"64950","389.66400","32.47223","0.03152"
"65016","390.06000","32.50524","0.02905"
"65082","390.45600","32.53812","0.02731"
"65148","390.85200","32.57119","0.02709"
"65214","391.24800","32.60419","0.02811"
"65280","391.64400","32.63725","0.02727"
"65346","392.04000","32.67014","0.02813"
"65412","392.43600","32.70314","0.02898"
"65478","392.83200","32.73621","0.02876"
"65544","393.22800","32.76921","0.02727"
"65610","393.62400","32.80209","0.02870"
"65676","394.02000","32.83522","0.02895"
"65742","394.41600","32.86816","0.02959"
"65808","394.81200","32.90117","0.02901"
"65874","395.20800","32.93417","0.01860"
"65940","395.60400","32.96717","0.01809"
"66006","396.00000","33.00018","0.01847"
"66072","396.39600","33.03324","0.01892"
"66138","396.79200","33.06612","0.01973"
"66204","397.18800","33.09919","0.01904"
"66270","397.58400","33.13219","0.01986"
"66336","397.98000","33.16520","0.01977"
"66402","398.37600","33.19820","0.01989"
"66468","398.77200","33.23120","0.02023"
"66534","399.16800","33.26426","0.02030"
"66600","399.56400","33.29721","0.02034"
"66666","399.96000","33.33021","0.02102"
"66732","400.35600","33.36322","0.02052"
"66798","400.75200","33.39622","0.02138"
"66864","401.14800","33.42916","0.02150"
"66930","401.54400","33.46223","0.02241"
"66996","401.94000","33.49523","0.02200"
"67062","402.33600","33.52818","0.02260"
"67128","402.73200","33.56118","0.02245"
"67194","403.12800","33.59424","0.02316"
"67260","403.52400","33.62719","0.02348"
"67326","403.92000","33.66013","0.02360"
"67392","404.31600","33.69320","0.02400"
"67458","404.71200","33.72626","0.02410"
"67524","405.10800","33.75920","0.02424"
"67590","405.50400","33.79214","0.02404"
"67656","405.90000","33.82521","0.02439"
"67722","406.29600","33.85822","0.02462"
"67788","406.69200","33.89122","0.02415"
"67854","407.08800","33.92410","0.02468"
"67920","407.48400","33.95716","0.02495"
"67986","407.88000","33.99023","0.02482"
"68052","408.27600","34.02317","0.02533"
"68118","408.67200","34.05611","0.02575"
"68184","409.06800","34.08918","0.02579"
"68250","409.46400","34.12224","0.02612"
"68316","409.86000","34.15519","0.02619"
"68382","410.25600","34.18819","0.02592"
"68448","410.65200","34.22120","0.02629"
"68514","411.04800","34.25420","0.02636"
"68580","411.44400","34.28720","0.02672"
"68646","411.84000","34.32015","0.02653"
"68712","412.23600","34.35321","0.02723"
"68778","412.63200","34.38622","0.02765"
"68844","413.02800","34.41922","0.02726"
"68910","413.42400","34.45216","0.02781"
"68976","413.82000","34.48523","0.02745"
"69042","414.21600","34.51823","0.02844"
"69108","414.61200","34.55117","0.02869"
"69174","415.00800","34.58418","0.02926"
"69240","415.40400","34.61724","0.02921"
"69306","415.80000","34.65025","0.02936"
"69372","416.19600","34.68319","0.02874"
"69438","416.59200","34.71619","0.02944"
"69504","416.98800","34.74920","0.02955"
"69570","417.38400","34.78214","0.02922"
"69636","417.78000","34.81515","0.02855"
"69702","418.17600","34.84821","0.02905"
"69768","418.57200","34.88121","0.01907"
"69834","418.96800","34.91416","0.02230"
"69900","419.36400","34.94710","0.01690"
"69966","419.76000","34.98022","0.02143"
"70032","420.15600","35.01317","0.01966"
"70098","420.55200","35.04611","0.02066"
"70164","420.94800","35.07924","0.02288"
"70230","421.34400","35.11218","0.02090"
"70296","421.74000","35.14519","0.02375"
"70362","422.13600","35.17813","0.02278"
"70428","422.53200","35.21113","0.02293"
"70494","422.92800","35.24420","0.02402"
"70560","423.32400","35.27720","0.02353"
"70626","423.72000","35.31014","0.02389"
"70692","424.11600","35.34321","0.02397"
"70758","424.51200","35.37627","0.02422"
"70824","424.90800","35.40916","0.02455"
"70890","425.30400","35.44216","0.02553"
"70956","425.70000","35.47522","0.02295"
"71022","426.09600","35.50823","0.02282"
"71088","426.49200","35.54117","0.02340"
"71154","426.88800","35.57418","0.02395"
"71220","427.28400","35.60724","0.02355"
"71286","427.68000","35.64024","0.02359"
"71352","428.07600","35.67319","0.02315"
"71418","428.47200","35.70619","0.02322"
"71484","428.86800","35.73919","0.02412"
"71550","429.26400","35.77220","0.02459"
"71616","429.66000","35.80514","0.02424"
"71682","430.05600","35.83815","0.02451"
"71748","430.45200","35.87121","0.02462"
"71814","430.84800","35.90416","0.02480"
"71880","431.24400","35.93716","0.02474"
"71946","431.64000","35.97022","0.02493"
"72012","432.03600","36.00317","0.02492"
"72078","432.43200","36.03617","0.02544"
"72144","432.82800","36.06917","0.02550"
"72210","433.22400","36.10218","0.02611"
"72276","433.62000","36.13518","0.02572"
"72342","434.01600","36.16818","0.02629"
"72408","434.41200","36.20119","0.02639"
"72474","434.80800","36.23419","0.02664"
"72540","435.20400","36.26714","0.02613"
"72606","435.60000","36.30014","0.02561"
"72672","435.99600","36.33320","0.02567"
"72738","436.39200","36.36621","0.02529"
"72804","436.78800","36.39921","0.02309"
"72870","437.18400","36.43216","0.02356"
"72936","437.58000","36.46522","0.02333"
"73002","437.97600","36.49822","0.02352"
"73068","438.37200","36.53122","0.02455"
"73134","438.76800","36.56417","0.02471"
"73200","439.16400","36.59723","0.02489"
"73266","439.56000","36.63018","0.02533"
"73332","439.95600","36.66318","0.02289"
"73398","440.35200","36.69619","0.02150"
"73464","440.74800","36.72919","0.02185"
"73530","441.14400","36.76225","0.02198"
"73596","441.54000","36.79514","0.02263"
"73662","441.93600","36.82820","0.01858"
"73728","442.33200","36.86120","0.01894"
"73794","442.72800","36.89421","0.01912"
"73860","443.12400","36.92709","0.02025"
"73926","443.52000","36.96016","0.01931"
"73992","443.91600","36.99322","0.01994"
"74058","444.31200","37.02622","0.01982"
"74124","444.70800","37.05917","0.01995"
"74190","445.10400","37.09217","0.02013"
"74256","445.50000","37.12518","0.02006"
"74322","445.89600","37.15818","0.02057"
"74388","446.29200","37.19118","0.02073"
"74454","446.68800","37.22419","0.02031"
"74520","447.08400","37.25719","0.02054"
"74586","447.48000","37.29019","0.02042"
"74652","447.87600","37.32314","0.02128"
"74718","448.27200","37.35620","0.02129"
"74784","448.66800","37.38920","0.02142"
"74850","449.06400","37.42221","0.02142"
"74916","449.46000","37.45521","0.02214"
"74982","449.85600","37.48822","0.02240"
"75048","450.25200","37.52122","0.02271"
"75114","450.64800","37.55410","0.02251"
"75180","451.04400","37.58723","0.02242"
"75246","451.44000","37.62023","0.02253"
"75312","451.83600","37.65318","0.02307"
"75378","452.23200","37.68618","0.02336"
"75444","452.62800","37.71924","0.02332"
"75510","453.02400","37.75219","0.02269"
"75576","453.42000","37.78519","0.02191"
"75642","453.81600","37.81813","0.02262"
"75708","454.21200","37.85120","0.02333"
"75774","454.60800","37.88420","0.02257"
"75840","455.00400","37.91715","0.02345"
"75906","455.40000","37.95015","0.02432"
"75972","455.79600","37.98321","0.02010"
"76038","456.19200","38.01622","0.01879"
"76104","456.58800","38.04916","0.01281"
"76170","456.98400","38.08217","0.01518"
"76236","457.38000","38.11523","0.01560"
"76302","457.77600","38.14823","0.01424"
"76368","458.17200","38.18112","0.01651"
"76434","458.56800","38.21418","0.01480"
"76500","458.96400","38.24719","0.01490"
"76566","459.36000","38.28019","0.01669"
"76632","459.75600","38.31319","0.01505"
"76698","460.15200","38.34614","0.01782"
"76764","460.54800","38.37920","0.01559"
"76830","460.94400","38.41220","0.01679"
"76896","461.34000","38.44515","0.01734"
"76962","461.73600","38.47821","0.01632"
"77028","462.13200","38.51122","0.01836"
"77094","462.52800","38.54416","0.01689"
"77160","462.92400","38.57710","0.01821"
"77226","463.32000","38.61023","0.01774"
"77292","463.71600","38.64323","0.01748"
"77358","464.11200","38.67624","0.01872"
"77424","464.50800","38.70918","0.01843"
"77490","464.90400","38.74218","0.01869"
"77556","465.30000","38.77519","0.01822"
"77622","465.69600","38.80819","0.01915"
"77688","466.09200","38.84119","0.01946"
"77754","466.48800","38.87420","0.01928"
"77820","466.88400","38.90720","0.01903"
"77886","467.28000","38.94015","0.01947"
"77952","467.67600","38.97321","0.01956"
"78018","468.07200","39.00621","0.01995"
"78084","468.46800","39.03916","0.01944"
"78150","468.86400","39.07215","0.01985"
"78216","469.26000","39.10522","0.02019"
"78282","469.65600","39.13823","0.01990"
"78348","470.05200","39.17112","0.01900"
"78414","470.44800","39.20418","0.02009"
"78480","470.84400","39.23724","0.02036"
"78546","471.24000","39.27018","0.01996"
"78612","471.63600","39.30312","0.01992"
"78678","472.03200","39.33619","0.02011"
"78744","472.42800","39.36919","0.02040"
"78810","472.82400","39.40219","0.02038"
"78876","473.22000","39.43515","0.02114"
"78942","473.61600","39.46815","0.02048"
"79008","474.01200","39.50127","0.02126"
"79074","474.40800","39.53421","0.02096"
"79140","474.80400","39.56716","0.02089"
"79206","475.20000","39.60016","0.02111"
"79272","475.59600","39.63322","0.02228"
"79338","475.99200","39.66617","0.02141"
"79404","476.38800","39.69917","0.02196"
"79470","476.78400","39.73223","0.02206"
"79536","477.18000","39.76524","0.02337"
"79602","477.57600","39.79813","0.02239"
"79668","477.97200","39.83112","0.02278"
"79734","478.36800","39.86419","0.02311"
"79800","478.76400","39.89719","0.02331"
"79866","479.16000","39.93020","0.02345"
"79932","479.55600","39.96320","0.02305"
"79998","479.95200","39.99621","0.02278"
"80064","480.34800","40.02915","0.02362"
"80130","480.74400","40.06221","0.02305"
"80196","481.14000","40.09516","0.02349"
"80262","481.53600","40.12816","0.02311"
"80328","481.93200","40.16117","0.02022"
"80394","482.32800","40.19417","0.01720"
"80460","482.72400","40.22717","0.01921"
"80526","483.12000","40.26018","0.01840"
"80592","483.51600","40.29318","0.01886"
"80658","483.91200","40.32619","0.01952"
"80724","484.30800","40.35925","0.01948"
"80790","484.70400","40.39219","0.02001"
"80856","485.10000","40.42514","0.01950"
"80922","485.49600","40.45820","0.02026"
"80988","485.89200","40.49120","0.01955"
"81054","486.28800","40.52415","0.02047"
"81120","486.68400","40.55715","0.02027"
"81186","487.08000","40.59022","0.02085"
"81252","487.47600","40.62316","0.02011"
"81277","487.62400","40.63554","0.02023"