File: Trajectories_together/170108_1Specimen_RawData_3.csv
"","V1","V2","V3"
"1","End date","1/8/2017",""
"2","Specimen label","20DT_UNK",""
"3","Maximum Load","0.19153","N"
"4","Time","Extension","Load"
"5","(s)","(mm)","(N)"
"6","0.00000","0.00000","-0.00038"
"87","0.48600","0.04078","-0.00009"
"168","0.97200","0.08113","0.00130"
"249","1.45800","0.12167","0.00171"
"330","1.94400","0.16221","0.00292"
"411","2.43000","0.20269","0.00325"
"492","2.91600","0.24322","0.00388"
"573","3.40200","0.28370","0.00398"
"654","3.88800","0.32424","0.00427"
"735","4.37400","0.36466","0.00514"
"816","4.86000","0.40519","0.00528"
"897","5.34600","0.44567","0.00565"
"978","5.83200","0.48615","0.00620"
"1059","6.31800","0.52669","0.00659"
"1140","6.80400","0.56716","0.00688"
"1221","7.29000","0.60764","0.00716"
"1302","7.77600","0.64818","0.00831"
"1383","8.26200","0.68872","0.00836"
"1464","8.74800","0.72919","0.00929"
"1545","9.23400","0.76973","0.00828"
"1626","9.72000","0.81021","0.00824"
"1707","10.20600","0.85069","0.00814"
"1788","10.69200","0.89110","0.00872"
"1869","11.17800","0.93170","0.00945"
"1950","11.66400","0.97218","0.01023"
"2031","12.15000","1.01266","0.01229"
"2112","12.63600","1.05325","0.01298"
"2193","13.12200","1.09367","0.01482"
"2274","13.60800","1.13415","0.01565"
"2355","14.09400","1.17474","0.01684"
"2436","14.58000","1.21522","0.01706"
"2517","15.06600","1.25570","0.01938"
"2598","15.55200","1.29618","0.02053"
"2679","16.03800","1.33665","0.02193"
"2760","16.52400","1.37719","0.02350"
"2841","17.01000","1.41767","0.02506"
"2922","17.49600","1.45821","0.02630"
"3003","17.98200","1.49868","0.02758"
"3084","18.46800","1.53922","0.02805"
"3165","18.95400","1.57976","0.02995"
"3246","19.44000","1.62024","0.03066"
"3327","19.92600","1.66065","0.03230"
"3408","20.41200","1.70119","0.03371"
"3489","20.89800","1.74161","0.03476"
"3570","21.38400","1.78215","0.03521"
"3651","21.87000","1.82268","0.03660"
"3732","22.35600","1.86322","0.03796"
"3813","22.84200","1.90370","0.03902"
"3894","23.32800","1.94418","0.04031"
"3975","23.81400","1.98471","0.04183"
"4056","24.30000","2.02525","0.04226"
"4137","24.78600","2.06567","0.04419"
"4218","25.27200","2.10621","0.04440"
"4299","25.75800","2.14668","0.04542"
"4380","26.24400","2.18716","0.04665"
"4461","26.73000","2.22770","0.04763"
"4542","27.21600","2.26818","0.04859"
"4623","27.70200","2.30871","0.04941"
"4704","28.18800","2.34919","0.04998"
"4785","28.67400","2.38967","0.05116"
"4866","29.16000","2.43021","0.05137"
"4947","29.64600","2.47068","0.05215"
"5028","30.13200","2.51116","0.05254"
"5109","30.61800","2.55170","0.05271"
"5190","31.10400","2.59212","0.05311"
"5271","31.59000","2.63265","0.05369"
"5352","32.07600","2.67319","0.05425"
"5433","32.56200","2.71367","0.05495"
"5514","33.04800","2.75420","0.05570"
"5595","33.53400","2.79468","0.05694"
"5676","34.02000","2.83522","0.05855"
"5757","34.50600","2.87570","0.05962"
"5838","34.99200","2.91617","0.02519"
"5919","35.47800","2.95665","0.01273"
"6000","35.96400","2.99713","0.01173"
"6081","36.45000","3.03767","0.01298"
"6162","36.93600","3.07820","0.01417"
"6243","37.42200","3.11868","0.01563"
"6324","37.90800","3.15922","0.01662"
"6405","38.39400","3.19970","0.01755"
"6486","38.88000","3.24017","0.01701"
"6567","39.36600","3.28071","0.01612"
"6648","39.85200","3.32119","0.01657"
"6729","40.33800","3.36173","0.01854"
"6810","40.82400","3.40214","0.01890"
"6891","41.31000","3.44262","0.02045"
"6972","41.79600","3.48316","0.02175"
"7053","42.28200","3.52364","0.02324"
"7134","42.76800","3.56417","0.02474"
"7215","43.25400","3.60471","0.02645"
"7296","43.74000","3.64519","0.02835"
"7377","44.22600","3.68573","0.02913"
"7458","44.71200","3.72620","-0.00390"
"7539","45.19800","3.76668","-0.00250"
"7620","45.68400","3.80716","-0.00100"
"7701","46.17000","3.84764","-0.00057"
"7782","46.65600","3.88817","0.00103"
"7863","47.14200","3.92865","0.00207"
"7944","47.62800","3.96919","0.00267"
"8025","48.11400","4.00973","0.00369"
"8106","48.60000","4.05014","0.00382"
"8187","49.08600","4.09074","0.00421"
"8268","49.57200","4.13116","0.00466"
"8349","50.05800","4.17164","0.00537"
"8430","50.54400","4.21217","0.00559"
"8511","51.03000","4.25271","0.00630"
"8592","51.51600","4.29319","0.00668"
"8673","52.00200","4.33366","-0.00629"
"8754","52.48800","4.37414","-0.00396"
"8835","52.97400","4.41474","-0.00307"
"8916","53.46000","4.45516","-0.00140"
"8997","53.94600","4.49569","-0.00019"
"9078","54.43200","4.53623","0.00081"
"9159","54.91800","4.57665","0.00149"
"9240","55.40400","4.61719","0.00233"
"9321","55.89000","4.65766","0.00277"
"9402","56.37600","4.69814","0.00307"
"9483","56.86200","4.73862","0.00356"
"9564","57.34800","4.77916","0.00422"
"9645","57.83400","4.81969","-0.00935"
"9726","58.32000","4.86017","-0.01018"
"9807","58.80600","4.90065","-0.00942"
"9888","59.29200","4.94125","-0.00808"
"9969","59.77800","4.98172","-0.00779"
"10050","60.26400","5.02220","-0.00665"
"10131","60.75000","5.06268","-0.00649"
"10212","61.23600","5.10310","-0.00590"
"10293","61.72200","5.14363","-0.00416"
"10374","62.20800","5.18417","-0.00431"
"10455","62.69400","5.22465","-0.00323"
"10536","63.18000","5.26519","-0.00240"
"10617","63.66600","5.30572","-0.02597"
"10698","64.15200","5.34620","-0.02240"
"10779","64.63800","5.38668","-0.02099"
"10860","65.12400","5.42716","-0.02155"
"10941","65.61000","5.46769","-0.02142"
"11022","66.09600","5.50817","-0.02078"
"11103","66.58200","5.54865","-0.02075"
"11184","67.06800","5.58919","-0.02014"
"11265","67.55400","5.62966","-0.02024"
"11346","68.04000","5.67020","-0.02004"
"11427","68.52600","5.71068","-0.01954"
"11508","69.01200","5.75115","-0.01987"
"11589","69.49800","5.79175","-0.01898"
"11670","69.98400","5.83223","-0.01933"
"11751","70.47000","5.87271","-0.01848"
"11832","70.95600","5.91313","-0.01869"
"11913","71.44200","5.95366","-0.01857"
"11994","71.92800","5.99414","-0.01800"
"12075","72.41400","6.03468","-0.01795"
"12156","72.90000","6.07521","-0.01806"
"12237","73.38600","6.11575","-0.01710"
"12318","73.87200","6.15617","-0.01706"
"12399","74.35800","6.19677","-0.01751"
"12480","74.84400","6.23718","-0.01653"
"12561","75.33000","6.27772","-0.01617"
"12642","75.81600","6.31820","-0.01643"
"12723","76.30200","6.35862","-0.01579"
"12804","76.78800","6.39915","-0.01552"
"12885","77.27400","6.43969","-0.01495"
"12966","77.76000","6.48017","-0.01434"
"13047","78.24600","6.52071","-0.01461"
"13128","78.73200","6.56124","-0.01405"
"13209","79.21800","6.60172","-0.01353"
"13290","79.70400","6.64226","-0.01310"
"13371","80.19000","6.68268","-0.01272"
"13452","80.67600","6.72315","-0.01235"
"13533","81.16200","6.76363","-0.01237"
"13614","81.64800","6.80417","-0.01096"
"13695","82.13400","6.84471","-0.01049"
"13776","82.62000","6.88518","-0.01093"
"13857","83.10600","6.92566","-0.00937"
"13938","83.59200","6.96620","-0.00864"
"14019","84.07800","7.00674","-0.00783"
"14100","84.56400","7.04721","-0.00713"
"14181","85.05000","7.08769","-0.00593"
"14262","85.53600","7.12817","-0.00465"
"14343","86.02200","7.16865","-0.00387"
"14424","86.50800","7.20912","-0.00243"
"14505","86.99400","7.24966","-0.00170"
"14586","87.48000","7.29020","-0.00122"
"14667","87.96600","7.33068","0.00027"
"14748","88.45200","7.37121","0.00145"
"14829","88.93800","7.41169","0.00220"
"14910","89.42400","7.45223","0.00323"
"14991","89.91000","7.49264","0.00379"
"15072","90.39600","7.53318","0.00445"
"15153","90.88200","7.57366","0.00524"
"15234","91.36800","7.61414","0.00547"
"15315","91.85400","7.65468","0.00619"
"15396","92.34000","7.69521","-0.00379"
"15477","92.82600","7.73569","-0.00376"
"15558","93.31200","7.77617","-0.00162"
"15639","93.79800","7.81670","-0.00080"
"15720","94.28400","7.85718","-0.00315"
"15801","94.77000","7.89772","-0.00399"
"15882","95.25600","7.93820","-0.00568"
"15963","95.74200","7.97867","-0.00615"
"16044","96.22800","8.01915","-0.00516"
"16125","96.71400","8.05963","-0.00403"
"16206","97.20000","8.10017","-0.00200"
"16287","97.68600","8.14064","-0.00070"
"16368","98.17200","8.18124","-0.00026"
"16449","98.65800","8.22166","0.00106"
"16530","99.14400","8.26220","0.00176"
"16611","99.63000","8.30267","0.00273"
"16692","100.11600","8.34321","0.00336"
"16773","100.60200","8.38369","0.00371"
"16854","101.08800","8.42417","0.00425"
"16935","101.57400","8.46464","0.00465"
"17016","102.06000","8.50518","0.00546"
"17097","102.54600","8.54566","0.00598"
"17178","103.03200","8.58619","0.00652"
"17259","103.51800","8.62673","0.00713"
"17340","104.00400","8.66721","0.00739"
"17421","104.49000","8.70775","0.00822"
"17502","104.97600","8.74823","0.00942"
"17583","105.46200","8.78864","0.01081"
"17664","105.94800","8.82918","0.01211"
"17745","106.43400","8.86960","0.01322"
"17826","106.92000","8.91020","-0.00872"
"17907","107.40600","8.95073","-0.00680"
"17988","107.89200","8.99121","-0.00558"
"18069","108.37800","9.03175","-0.00492"
"18150","108.86400","9.07216","-0.00160"
"18231","109.35000","9.11276","-0.00068"
"18312","109.83600","9.15318","0.00072"
"18393","110.32200","9.19366","0.00138"
"18474","110.80800","9.23419","0.00095"
"18555","111.29400","9.27467","0.00234"
"18636","111.78000","9.31509","0.00236"
"18717","112.26600","9.35569","0.00391"
"18798","112.75200","9.39616","0.00424"
"18879","113.23800","9.43670","0.00565"
"18960","113.72400","9.47724","0.00632"
"19041","114.21000","9.51772","0.00707"
"19122","114.69600","9.55825","0.00812"
"19203","115.18200","9.59873","0.00977"
"19284","115.66800","9.63921","0.00798"
"19365","116.15400","9.67963","0.00768"
"19446","116.64000","9.72016","0.00961"
"19527","117.12600","9.76070","0.01219"
"19608","117.61200","9.80118","0.01601"
"19689","118.09800","9.84166","0.01952"
"19770","118.58400","9.88219","0.02257"
"19851","119.07000","9.92267","0.02513"
"19932","119.55600","9.96321","0.02887"
"20013","120.04200","10.00375","0.03008"
"20094","120.52800","10.04416","0.03153"
"20175","121.01400","10.08470","0.03420"
"20256","121.50000","10.12512","0.00209"
"20337","121.98600","10.16572","0.00286"
"20418","122.47200","10.20619","0.00363"
"20499","122.95800","10.24667","0.00444"
"20580","123.44400","10.28727","0.00465"
"20661","123.93000","10.32769","0.00615"
"20742","124.41600","10.36822","0.00696"
"20823","124.90200","10.40870","0.00829"
"20904","125.38800","10.44918","0.00905"
"20985","125.87400","10.48972","0.01014"
"21066","126.36000","10.53013","0.01164"
"21147","126.84600","10.57067","0.01277"
"21228","127.33200","10.61121","-0.01618"
"21309","127.81800","10.65162","-0.01596"
"21390","128.30400","10.69216","-0.01317"
"21471","128.79000","10.73270","-0.01211"
"21552","129.27600","10.77318","-0.01335"
"21633","129.76200","10.81377","-0.01302"
"21714","130.24800","10.85419","-0.00979"
"21795","130.73400","10.89467","-0.00934"
"21876","131.22000","10.93509","-0.01045"
"21957","131.70600","10.97568","-0.00977"
"22038","132.19200","11.01610","-0.00829"
"22119","132.67800","11.05670","-0.00604"
"22200","133.16400","11.09724","-0.00729"
"22281","133.65000","11.13771","-0.00663"
"22362","134.13600","11.17813","-0.00516"
"22443","134.62200","11.21873","-0.00357"
"22524","135.10800","11.25921","-0.00299"
"22605","135.59400","11.29968","-0.00255"
"22686","136.08000","11.34016","-0.00217"
"22767","136.56600","11.38064","-0.00031"
"22848","137.05200","11.42118","-0.00080"
"22929","137.53800","11.46165","0.00049"
"23010","138.02400","11.50219","0.00073"
"23091","138.51000","11.54267","0.00178"
"23172","138.99600","11.58321","0.00305"
"23253","139.48200","11.62368","0.00390"
"23334","139.96800","11.66422","0.00461"
"23415","140.45400","11.70464","0.00464"
"23496","140.94000","11.74518","0.00524"
"23577","141.42600","11.78559","0.00550"
"23658","141.91200","11.82613","0.00633"
"23739","142.39800","11.86673","0.00691"
"23820","142.88400","11.90715","0.00749"
"23901","143.37000","11.94768","0.00907"
"23982","143.85600","11.98822","0.01099"
"24063","144.34200","12.02870","0.01348"
"24144","144.82800","12.06923","0.01439"
"24225","145.31400","12.10965","0.01709"
"24306","145.80000","12.15019","0.01963"
"24387","146.28600","12.19067","0.02285"
"24468","146.77200","12.23114","0.02527"
"24549","147.25800","12.27162","0.02799"
"24630","147.74400","12.31216","0.03058"
"24711","148.23000","12.35270","0.03308"
"24792","148.71600","12.39323","0.03423"
"24873","149.20200","12.43365","0.00996"
"24954","149.68800","12.47425","0.01000"
"25035","150.17400","12.51473","0.01289"
"25116","150.66000","12.55514","0.01662"
"25197","151.14600","12.59562","0.01986"
"25278","151.63200","12.63610","0.02078"
"25359","152.11800","12.67670","0.01838"
"25440","152.60400","12.71717","0.01983"
"25521","153.09000","12.75771","0.02296"
"25602","153.57600","12.79819","0.02425"
"25683","154.06200","12.83867","0.02671"
"25764","154.54800","12.87920","0.02915"
"25845","155.03400","12.91974","0.03114"
"25926","155.52000","12.96022","0.03274"
"26007","156.00600","13.00070","0.03232"
"26088","156.49200","13.04111","0.03466"
"26169","156.97800","13.08165","0.03769"
"26250","157.46400","13.12219","0.03966"
"26331","157.95000","13.16267","0.04177"
"26412","158.43600","13.20326","0.04416"
"26493","158.92200","13.24368","0.04529"
"26574","159.40800","13.28416","0.04705"
"26655","159.89400","13.32469","0.04798"
"26736","160.38000","13.36523","0.04898"
"26817","160.86600","13.40565","0.05011"
"26898","161.35200","13.44613","0.05122"
"26979","161.83800","13.48666","0.05191"
"27060","162.32400","13.52720","0.05261"
"27141","162.81000","13.56768","0.05297"
"27222","163.29600","13.60822","0.05396"
"27303","163.78200","13.64869","0.05472"
"27384","164.26800","13.68923","0.05584"
"27465","164.75400","13.72971","0.05743"
"27546","165.24000","13.77019","0.05954"
"27627","165.72600","13.81067","0.06186"
"27708","166.21200","13.85120","0.06454"
"27789","166.69800","13.89162","0.06817"
"27870","167.18400","13.93216","0.07173"
"27951","167.67000","13.97269","0.07478"
"28032","168.15600","14.01323","0.07936"
"28113","168.64200","14.05371","0.08497"
"28194","169.12800","14.09413","0.08834"
"28275","169.61400","14.13472","0.09324"
"28356","170.10000","14.17514","0.09817"
"28437","170.58600","14.21568","0.10257"
"28518","171.07200","14.25622","0.10659"
"28599","171.55800","14.29669","0.10906"
"28680","172.04400","14.33711","0.11130"
"28761","172.53000","14.37771","0.11206"
"28842","173.01600","14.41813","0.11219"
"28923","173.50200","14.45872","0.11350"
"29004","173.98800","14.49920","0.11482"
"29085","174.47400","14.53974","0.11582"
"29166","174.96000","14.58022","-0.00992"
"29247","175.44600","14.62063","-0.00455"
"29328","175.93200","14.66117","-0.00460"
"29409","176.41800","14.70165","-0.00469"
"29490","176.90400","14.74213","-0.00301"
"29571","177.39000","14.78272","-0.00135"
"29652","177.87600","14.82320","0.00138"
"29733","178.36200","14.86368","0.00300"
"29814","178.84800","14.90422","0.00421"
"29895","179.33400","14.94469","0.00448"
"29976","179.82000","14.98523","0.00521"
"30057","180.30600","15.02565","0.00593"
"30138","180.79200","15.06619","0.00673"
"30219","181.27800","15.10666","0.00757"
"30300","181.76400","15.14714","0.00961"
"30381","182.25000","15.18768","0.01175"
"30462","182.73600","15.22821","0.01544"
"30543","183.22200","15.26869","0.01959"
"30624","183.70800","15.30917","0.02351"
"30705","184.19400","15.34971","0.02454"
"30786","184.68000","15.39018","0.02775"
"30867","185.16600","15.43072","0.03074"
"30948","185.65200","15.47114","0.03357"
"31029","186.13800","15.51168","0.03526"
"31110","186.62400","15.55210","0.03802"
"31191","187.11000","15.59269","0.03992"
"31272","187.59600","15.63317","0.04149"
"31353","188.08200","15.67365","0.04453"
"31434","188.56800","15.71424","0.04614"
"31515","189.05400","15.75472","0.02114"
"31596","189.54000","15.79520","0.02732"
"31677","190.02600","15.83574","0.03060"
"31758","190.51200","15.87621","0.03467"
"31839","190.99800","15.91669","0.03771"
"31920","191.48400","15.95717","0.04094"
"32001","191.97000","15.99765","0.04308"
"32082","192.45600","16.03818","0.04585"
"32163","192.94200","16.07872","0.04787"
"32244","193.42800","16.11920","0.04960"
"32325","193.91400","16.15973","0.05085"
"32406","194.40000","16.20015","0.05183"
"32487","194.88600","16.24075","0.05277"
"32568","195.37200","16.28117","0.05343"
"32649","195.85800","16.32165","0.05475"
"32730","196.34400","16.36212","0.05612"
"32811","196.83000","16.40266","0.05774"
"32892","197.31600","16.44314","0.05998"
"32973","197.80200","16.48368","0.06254"
"33054","198.28800","16.52415","0.06580"
"33135","198.77400","16.56469","0.06200"
"33216","199.26000","16.60517","0.06423"
"33297","199.74600","16.64577","0.06774"
"33378","200.23200","16.68624","0.07174"
"33459","200.71800","16.72672","0.07517"
"33540","201.20400","16.76720","0.07972"
"33621","201.69000","16.80761","0.08404"
"33702","202.17600","16.84815","0.08889"
"33783","202.66200","16.88869","0.09261"
"33864","203.14800","16.92917","0.09604"
"33945","203.63400","16.96971","0.10051"
"34026","204.12000","17.01018","0.10472"
"34107","204.60600","17.05072","0.10826"
"34188","205.09200","17.09126","0.11098"
"34269","205.57800","17.13167","0.11212"
"34350","206.06400","17.17221","0.11352"
"34431","206.55000","17.21263","0.11467"
"34512","207.03600","17.25311","0.11676"
"34593","207.52200","17.29370","0.11953"
"34674","208.00800","17.33418","0.12247"
"34755","208.49400","17.37472","0.12640"
"34836","208.98000","17.41520","0.12892"
"34917","209.46600","17.45567","0.13358"
"34998","209.95200","17.49621","0.13692"
"35079","210.43800","17.53669","0.14008"
"35160","210.92400","17.57717","0.14423"
"35241","211.41000","17.61770","0.14774"
"35322","211.89600","17.65818","0.15062"
"35403","212.38200","17.69866","0.15315"
"35484","212.86800","17.73919","0.15519"
"35565","213.35400","17.77967","0.15732"
"35646","213.84000","17.82021","0.15910"
"35727","214.32600","17.86069","0.16041"
"35808","214.81200","17.90117","0.16267"
"35889","215.29800","17.94170","0.16432"
"35970","215.78400","17.98218","0.16613"
"36051","216.27000","18.02266","0.16895"
"36132","216.75600","18.06314","0.17037"
"36213","217.24200","18.10367","0.17418"
"36294","217.72800","18.14421","0.17717"
"36375","218.21400","18.18469","0.17986"
"36456","218.70000","18.22523","0.18241"
"36537","219.18600","18.26570","0.18557"
"36618","219.67200","18.30618","0.18361"
"36699","220.15800","18.34672","0.18634"
"36780","220.64400","18.38720","0.18959"
"36861","221.13000","18.42767","0.03561"
"36942","221.61600","18.46815","0.03725"
"37023","222.10200","18.50863","0.04179"
"37104","222.58800","18.54916","0.04425"
"37185","223.07400","18.58964","0.04669"
"37266","223.56000","18.63018","0.04806"
"37347","224.04600","18.67072","0.05021"
"37428","224.53200","18.71113","0.04831"
"37509","225.01800","18.75173","0.04531"
"37590","225.50400","18.79221","0.04677"
"37671","225.99000","18.83263","0.04807"
"37752","226.47600","18.87317","0.04832"
"37833","226.96200","18.91364","0.04927"
"37914","227.44800","18.95412","0.05039"
"37995","227.93400","18.99466","0.00704"
"38076","228.42000","19.03519","0.00828"
"38157","228.90600","19.07573","0.00846"
"38238","229.39200","19.11621","0.01153"
"38319","229.87800","19.15675","0.01538"
"38400","230.36400","19.19722","0.00677"
"38481","230.85000","19.23764","0.00139"
"38562","231.33600","19.27812","0.00225"
"38643","231.82200","19.31866","0.00514"
"38724","232.30800","19.35913","0.00602"
"38805","232.79400","19.39967","0.00675"
"38886","233.28000","19.44021","0.00677"
"38967","233.76600","19.48075","0.00721"
"39048","234.25200","19.52122","0.00845"
"39129","234.73800","19.56170","0.00886"
"39210","235.22400","19.60218","0.01044"
"39291","235.71000","19.64265","0.01128"
"39372","236.19600","19.68319","0.01384"
"39453","236.68200","19.72367","0.01751"
"39534","237.16800","19.76415","0.02358"
"39615","237.65400","19.80468","0.02529"
"39696","238.14000","19.84516","0.02744"
"39777","238.62600","19.88564","0.03032"
"39858","239.11200","19.92624","0.03285"
"39939","239.59800","19.96665","0.03306"
"40020","240.08400","20.00719","0.03584"
"40101","240.57000","20.04767","0.03804"
"40182","241.05600","20.08821","0.03875"
"40263","241.54200","20.12868","0.04194"
"40344","242.02800","20.16910","-0.01562"
"40425","242.51400","20.20970","-0.02161"
"40506","243.00000","20.25018","-0.01061"
"40587","243.48600","20.29065","-0.01136"
"40668","243.97200","20.33125","-0.01390"
"40749","244.45800","20.37173","-0.01586"
"40830","244.94400","20.41226","-0.01418"
"40911","245.43000","20.45268","-0.01354"
"40992","245.91600","20.49316","-0.01342"
"41073","246.40200","20.53370","-0.01282"
"41154","246.88800","20.57412","-0.01279"
"41235","247.37400","20.61465","-0.01186"
"41316","247.86000","20.65519","-0.01085"
"41397","248.34600","20.69567","-0.01095"
"41478","248.83200","20.73621","-0.01209"
"41559","249.31800","20.77668","-0.01032"
"41640","249.80400","20.81716","-0.00832"
"41721","250.29000","20.85776","-0.00686"
"41802","250.77600","20.89817","-0.00811"
"41883","251.26200","20.93865","-0.00768"
"41964","251.74800","20.97913","-0.00672"
"42045","252.23400","21.01967","-0.00542"
"42126","252.72000","21.06020","-0.00481"
"42207","253.20600","21.10068","-0.00303"
"42288","253.69200","21.14122","-0.00258"
"42369","254.17800","21.18176","-0.00302"
"42450","254.66400","21.22218","-0.00178"
"42531","255.15000","21.26277","-0.00101"
"42612","255.63600","21.30319","-0.00088"
"42693","256.12200","21.34367","0.00038"
"42774","256.60800","21.38420","0.00096"
"42855","257.09400","21.42462","0.00208"
"42936","257.58000","21.46516","0.00243"
"43017","258.06600","21.50570","0.00274"
"43098","258.55200","21.54618","0.00285"
"43179","259.03800","21.58671","0.00121"
"43260","259.52400","21.62719","0.00097"
"43341","260.01000","21.66773","0.00207"
"43422","260.49600","21.70821","0.00252"
"43503","260.98200","21.74868","0.00330"
"43584","261.46800","21.78916","0.00390"
"43665","261.95400","21.82964","0.00416"
"43746","262.44000","21.87018","0.00403"
"43827","262.92600","21.91071","0.00457"
"43908","263.41200","21.95119","0.00553"
"43989","263.89800","21.99173","0.00579"
"44070","264.38400","22.03221","0.00666"
"44151","264.87000","22.07262","0.00704"
"44232","265.35600","22.11322","0.00803"
"44313","265.84200","22.15370","0.00897"
"44394","266.32800","22.19417","0.01031"
"44475","266.81400","22.23465","0.01107"
"44556","267.30000","22.27513","0.01219"
"44637","267.78600","22.31566","0.01411"
"44718","268.27200","22.35620","0.01496"
"44799","268.75800","22.39674","0.00160"
"44880","269.24400","22.43722","0.00307"
"44961","269.73000","22.47770","0.00410"
"45042","270.21600","22.51817","-0.02345"
"45123","270.70200","22.55871","-0.02746"
"45204","271.18800","22.59913","-0.02506"
"45285","271.67400","22.63967","-0.02218"
"45366","272.16000","22.68008","-0.02458"
"45447","272.64600","22.72068","-0.02711"
"45528","273.13200","22.76122","-0.02457"
"45609","273.61800","22.80169","-0.02172"
"45690","274.10400","22.84223","-0.02304"
"45771","274.59000","22.88271","-0.02410"
"45852","275.07600","22.92325","-0.02451"
"45933","275.56200","22.96372","-0.02269"
"46014","276.04800","23.00420","-0.02236"
"46095","276.53400","23.04462","-0.02274"
"46176","277.02000","23.08516","-0.02361"
"46257","277.50600","23.12564","-0.02343"
"46338","277.99200","23.16617","-0.02276"
"46419","278.47800","23.20665","-0.02182"
"46500","278.96400","23.24725","-0.02205"
"46581","279.45000","23.28766","-0.02230"
"46662","279.93600","23.32814","-0.02273"
"46743","280.42200","23.36868","-0.02197"
"46824","280.90800","23.40922","-0.02141"
"46905","281.39400","23.44970","-0.02127"
"46986","281.88000","23.49017","-0.02202"
"47067","282.36600","23.53065","-0.02199"
"47148","282.85200","23.57119","-0.02200"
"47229","283.33800","23.61166","-0.02172"
"47310","283.82400","23.65220","-0.02112"
"47391","284.31000","23.69268","-0.02137"
"47472","284.79600","23.73316","-0.02098"
"47553","285.28200","23.77375","-0.02159"
"47634","285.76800","23.81417","-0.02112"
"47715","286.25400","23.85465","-0.02101"
"47796","286.74000","23.89519","-0.02052"
"47877","287.22600","23.93560","-0.02067"
"47958","287.71200","23.97620","-0.02091"
"48039","288.19800","24.01668","-0.02055"
"48120","288.68400","24.05722","-0.02066"
"48201","289.17000","24.09775","-0.02015"
"48282","289.65600","24.13817","-0.02037"
"48363","290.14200","24.17871","-0.01973"
"48444","290.62800","24.21925","-0.02027"
"48525","291.11400","24.25966","-0.02015"
"48606","291.60000","24.30020","-0.01961"
"48687","292.08600","24.34062","-0.01963"
"48768","292.57200","24.38116","-0.01946"
"48849","293.05800","24.42169","-0.01962"
"48930","293.54400","24.46217","-0.01932"
"49011","294.03000","24.50271","-0.01959"
"49092","294.51600","24.54325","-0.01915"
"49173","295.00200","24.58366","-0.01950"
"49254","295.48800","24.62420","-0.01907"
"49335","295.97400","24.66462","-0.01893"
"49416","296.46000","24.70515","-0.01849"
"49497","296.94600","24.74563","-0.01865"
"49578","297.43200","24.78617","-0.01881"
"49659","297.91800","24.82671","-0.01814"
"49740","298.40400","24.86718","-0.01833"
"49821","298.89000","24.90766","-0.01799"
"49902","299.37600","24.94826","-0.01798"
"49983","299.86200","24.98868","-0.01742"
"50064","300.34800","25.02921","-0.01748"
"50145","300.83400","25.06969","-0.01807"
"50226","301.32000","25.11017","-0.01792"
"50307","301.80600","25.15065","-0.01759"
"50388","302.29200","25.19112","-0.01745"
"50469","302.77800","25.23166","-0.01734"
"50550","303.26400","25.27220","-0.01724"
"50631","303.75000","25.31268","-0.01649"
"50712","304.23600","25.35321","-0.01631"
"50793","304.72200","25.39369","-0.01630"
"50874","305.20800","25.43423","-0.01626"
"50955","305.69400","25.47471","-0.01652"
"51036","306.18000","25.51518","-0.01587"
"51117","306.66600","25.55566","-0.01574"
"51198","307.15200","25.59614","-0.01584"
"51279","307.63800","25.63667","-0.01582"
"51360","308.12400","25.67721","-0.01520"
"51441","308.61000","25.71769","-0.01561"
"51522","309.09600","25.75817","-0.01511"
"51603","309.58200","25.79871","-0.01520"
"51684","310.06800","25.83918","-0.01506"
"51765","310.55400","25.87978","-0.01444"
"51846","311.04000","25.92020","-0.01445"
"51927","311.52600","25.96067","-0.01431"
"52008","312.01200","26.00115","-0.01453"
"52089","312.49800","26.04169","-0.01369"
"52170","312.98400","26.08217","-0.01449"
"52251","313.47000","26.12270","-0.01428"
"52332","313.95600","26.16318","-0.01575"
"52413","314.44200","26.20372","-0.01601"
"52494","314.92800","26.24414","-0.01609"
"52575","315.41400","26.28473","-0.01709"
"52656","315.90000","26.32521","-0.01594"
"52737","316.38600","26.36569","-0.01633"
"52818","316.87200","26.40617","-0.01633"
"52899","317.35800","26.44665","-0.01582"
"52980","317.84400","26.48718","-0.01574"
"53061","318.33000","26.52772","-0.01532"
"53142","318.81600","26.56820","-0.01521"
"53223","319.30200","26.60873","-0.01503"
"53304","319.78800","26.64921","-0.01533"
"53385","320.27400","26.68969","-0.01547"
"53466","320.76000","26.73023","-0.01470"
"53547","321.24600","26.77064","-0.01484"
"53628","321.73200","26.81118","-0.01405"
"53709","322.21800","26.85166","-0.01440"
"53790","322.70400","26.89214","-0.01430"
"53871","323.19000","26.93273","-0.01383"
"53952","323.67600","26.97315","-0.01407"
"54033","324.16200","27.01369","-0.01310"
"54114","324.64800","27.05417","-0.01380"
"54195","325.13400","27.09464","-0.01293"
"54276","325.62000","27.13518","-0.01272"
"54357","326.10600","27.17566","-0.01254"
"54438","326.59200","27.21614","-0.01227"
"54519","327.07800","27.25667","-0.01197"
"54600","327.56400","27.29715","-0.01225"
"54681","328.05000","27.33769","-0.01165"
"54762","328.53600","27.37822","-0.01155"
"54843","329.02200","27.41870","-0.01088"
"54924","329.50800","27.45918","-0.01126"
"55005","329.99400","27.49966","-0.01103"
"55086","330.48000","27.54020","-0.01165"
"55167","330.96600","27.58067","-0.01229"
"55248","331.45200","27.62115","-0.01150"
"55329","331.93800","27.66169","-0.01326"
"55410","332.42400","27.70211","-0.01347"
"55491","332.91000","27.74270","-0.01382"
"55572","333.39600","27.78318","-0.01360"
"55653","333.88200","27.82372","-0.01309"
"55734","334.36800","27.86419","-0.01276"
"55815","334.85400","27.90467","-0.01142"
"55896","335.34000","27.94521","-0.01180"
"55977","335.82600","27.98575","-0.01189"
"56058","336.31200","28.02622","-0.01104"
"56139","336.79800","28.06664","-0.01113"
"56220","337.28400","28.10718","-0.01044"
"56301","337.77000","28.14766","-0.01038"
"56382","338.25600","28.18826","-0.01006"
"56463","338.74200","28.22867","-0.00940"
"56544","339.22800","28.26927","-0.00863"
"56625","339.71400","28.30969","-0.00822"
"56706","340.20000","28.35016","-0.00756"
"56787","340.68600","28.39070","-0.00768"
"56868","341.17200","28.43118","-0.00654"
"56949","341.65800","28.47166","-0.00682"
"57030","342.14400","28.51220","-0.00595"
"57111","342.63000","28.55267","-0.00552"
"57192","343.11600","28.59315","-0.00512"
"57273","343.60200","28.63369","-0.00440"
"57354","344.08800","28.67417","-0.00360"
"57435","344.57400","28.71470","-0.00426"
"57516","345.06000","28.75524","-0.00376"
"57597","345.54600","28.79572","-0.00297"
"57678","346.03200","28.83619","-0.00281"
"57759","346.51800","28.87667","-0.00262"
"57840","347.00400","28.91721","-0.00298"
"57921","347.49000","28.95757","-0.00607"
"58002","347.97600","28.99816","-0.00805"
"58083","348.46200","29.03864","-0.00692"
"58164","348.94800","29.07924","-0.00630"
"58245","349.43400","29.11972","-0.00549"
"58326","349.92000","29.16019","-0.00575"
"58407","350.40600","29.20067","-0.00458"
"58488","350.89200","29.24121","-0.00398"
"58569","351.37800","29.28168","-0.00350"
"58650","351.86400","29.32216","-0.00254"
"58731","352.35000","29.36264","-0.00234"
"58812","352.83600","29.40312","-0.00173"
"58893","353.32200","29.44372","-0.00091"
"58974","353.80800","29.48419","-0.00068"
"59055","354.29400","29.52467","-0.00024"
"59136","354.78000","29.56521","-0.00004"
"59217","355.26600","29.60568","0.00037"
"59298","355.75200","29.64622","0.00018"
"59379","356.23800","29.68664","0.00081"
"59460","356.72400","29.72718","0.00083"
"59541","357.21000","29.76765","0.00117"
"59622","357.69600","29.80819","0.00146"
"59703","358.18200","29.84867","0.00086"
"59784","358.66800","29.88915","0.00179"
"59865","359.15400","29.92968","0.00169"
"59946","359.64000","29.97022","0.00234"
"60027","360.12600","30.01070","0.00262"
"60108","360.61200","30.05118","0.00259"
"60189","361.09800","30.09165","0.00292"
"60270","361.58400","30.13219","0.00345"
"60351","362.07000","30.17261","0.00398"
"60432","362.55600","30.21315","0.00411"
"60513","363.04200","30.25368","0.00448"
"60594","363.52800","30.29422","0.00481"
"60675","364.01400","30.33464","0.00475"
"60756","364.50000","30.37523","0.00515"
"60837","364.98600","30.41571","0.00496"
"60918","365.47200","30.45619","-0.00932"
"60999","365.95800","30.49667","-0.00819"
"61080","366.44400","30.53715","-0.01157"
"61161","366.93000","30.57768","-0.01410"
"61242","367.41600","30.61810","-0.01472"
"61323","367.90200","30.65870","-0.01372"
"61404","368.38800","30.69918","-0.01322"
"61485","368.87400","30.73965","-0.01120"
"61566","369.36000","30.78019","-0.00995"
"61647","369.84600","30.82067","-0.00878"
"61728","370.33200","30.86115","-0.00828"
"61809","370.81800","30.90174","-0.00947"
"61890","371.30400","30.94216","-0.00918"
"61971","371.79000","30.98264","-0.00833"
"62052","372.27600","31.02317","-0.00804"
"62133","372.76200","31.06365","-0.00575"
"62214","373.24800","31.10413","-0.00400"
"62295","373.73400","31.14473","-0.00212"
"62376","374.22000","31.18515","-0.00172"
"62457","374.70600","31.22574","-0.00177"
"62538","375.19200","31.26616","-0.00223"
"62619","375.67800","31.30676","-0.00185"
"62700","376.16400","31.34711","-0.00101"
"62781","376.65000","31.38765","0.00030"
"62862","377.13600","31.42813","0.00048"
"62943","377.62200","31.46867","0.00035"
"63024","378.10800","31.50914","-0.00063"
"63105","378.59400","31.54968","-0.00008"
"63186","379.08000","31.59016","0.00081"
"63267","379.56600","31.63070","0.00041"
"63348","380.05200","31.67117","0.00148"
"63429","380.53800","31.71171","0.00148"
"63510","381.02400","31.75219","0.00162"
"63591","381.51000","31.79267","0.00223"
"63672","381.99600","31.83314","0.00203"
"63753","382.48200","31.87362","-0.00290"
"63834","382.96800","31.91416","-0.02836"
"63915","383.45400","31.95469","-0.05260"
"63996","383.94000","31.99517","0.05346"
"64077","384.42600","32.03571","-0.00515"
"64158","384.91200","32.07619","-0.02141"
"64239","385.39800","32.11673","-0.03994"
"64320","385.88400","32.15726","-0.03285"
"64401","386.37000","32.19768","-0.02946"
"64482","386.85600","32.23816","-0.01884"
"64563","387.34200","32.27863","-0.02000"
"64644","387.82800","32.31911","-0.02724"
"64725","388.31400","32.35971","-0.02866"
"64806","388.80000","32.40019","-0.02097"
"64887","389.28600","32.44066","-0.01958"
"64968","389.77200","32.48126","-0.02398"
"65049","390.25800","32.52174","-0.02634"
"65130","390.74400","32.56221","-0.02428"
"65211","391.23000","32.60263","-0.02064"
"65292","391.71600","32.64311","-0.02056"
"65373","392.20200","32.68365","-0.02107"
"65454","392.68800","32.72413","-0.02377"
"65535","393.17400","32.76466","-0.02387"
"65616","393.66000","32.80520","-0.02332"
"65697","394.14600","32.84568","-0.02234"
"65778","394.63200","32.88622","-0.02018"
"65859","395.11800","32.92669","-0.02004"
"65940","395.60400","32.96717","-0.02069"
"66021","396.09000","33.00771","-0.02120"
"66102","396.57600","33.04819","-0.02119"
"66183","397.06200","33.08866","-0.02130"
"66264","397.54800","33.12908","-0.02076"
"66345","398.03400","33.16968","-0.01937"
"66426","398.52000","33.21016","-0.01931"
"66507","399.00600","33.25063","-0.01921"
"66588","399.49200","33.29123","-0.01875"
"66669","399.97800","33.33171","-0.01918"
"66750","400.46400","33.37218","-0.01927"
"66831","400.95000","33.41272","-0.01870"
"66912","401.43600","33.45320","-0.01876"
"66993","401.92200","33.49362","-0.01817"
"67074","402.40800","33.53415","-0.01755"
"67155","402.89400","33.57463","-0.01663"
"67236","403.38000","33.61517","-0.01662"
"67317","403.86600","33.65565","-0.01693"
"67398","404.35200","33.69619","-0.01624"
"67479","404.83800","33.73672","-0.01593"
"67560","405.32400","33.77720","-0.01582"
"67641","405.81000","33.81774","-0.01523"
"67722","406.29600","33.85822","-0.01572"
"67803","406.78200","33.89863","-0.01468"
"67884","407.26800","33.93917","-0.01479"
"67965","407.75400","33.97959","-0.01373"
"68046","408.24000","34.02013","-0.01372"
"68127","408.72600","34.06072","-0.01289"
"68208","409.21200","34.10120","-0.01262"
"68289","409.69800","34.14167","-0.01197"
"68370","410.18400","34.18221","-0.01159"
"68451","410.67000","34.22275","-0.01122"
"68532","411.15600","34.26323","-0.01027"
"68613","411.64200","34.30365","-0.00969"
"68694","412.12800","34.34412","-0.00889"
"68775","412.61400","34.38466","-0.00878"
"68856","413.10000","34.42514","-0.00813"
"68937","413.58600","34.46568","-0.00799"
"69018","414.07200","34.50615","-0.00720"
"69099","414.55800","34.54669","-0.00703"
"69180","415.04400","34.58723","-0.00566"
"69261","415.53000","34.62770","-0.00483"
"69342","416.01600","34.66819","-0.00448"
"69423","416.50200","34.70866","-0.00257"
"69504","416.98800","34.74920","-0.00247"
"69585","417.47400","34.78967","-0.00164"
"69666","417.96000","34.83009","-0.00073"
"69747","418.44600","34.87069","0.00046"
"69828","418.93200","34.91123","0.00090"
"69909","419.41800","34.95164","0.00124"
"69990","419.90400","34.99224","0.00240"
"70071","420.39000","35.03266","0.00271"
"70152","420.87600","35.07320","0.00315"
"70233","421.36200","35.11367","0.00382"
"70314","421.84800","35.15415","0.00427"
"70395","422.33400","35.19463","0.00442"
"70476","422.82000","35.23517","0.00473"
"70557","423.30600","35.27570","0.00521"
"70638","423.79200","35.31618","0.00575"
"70719","424.27800","35.35666","0.00623"
"70800","424.76400","35.39726","0.00644"
"70881","425.25000","35.43767","0.00677"
"70962","425.73600","35.47821","0.00688"
"71043","426.22200","35.51869","0.00691"
"71124","426.70800","35.55917","0.00741"
"71205","427.19400","35.59964","0.00781"
"71286","427.68000","35.64012","0.00876"
"71367","428.16600","35.68066","0.00951"
"71448","428.65200","35.72120","0.00720"
"71529","429.13800","35.76167","0.00740"
"71610","429.62400","35.80221","0.00857"
"71691","430.11000","35.84269","0.00953"
"71772","430.59600","35.88322","0.01118"
"71853","431.08200","35.92371","0.01116"
"71934","431.56800","35.96418","0.01116"
"72015","432.05400","36.00466","0.01122"
"72096","432.54000","36.04514","0.01230"
"72177","433.02600","36.08567","0.01394"
"72258","433.51200","36.12615","0.01426"
"72339","433.99800","36.16669","0.01732"
"72420","434.48400","36.20723","0.01868"
"72501","434.97000","36.24770","0.02020"
"72582","435.45600","36.28818","0.02071"
"72663","435.94200","36.32872","0.02206"
"72744","436.42800","36.36920","0.02401"
"72825","436.91400","36.40961","0.02503"
"72906","437.40000","36.45021","0.02622"
"72987","437.88600","36.49063","0.02703"
"73068","438.37200","36.53117","0.02793"
"73149","438.85800","36.57170","0.02875"
"73230","439.34400","36.61218","0.02932"
"73311","439.83000","36.65272","0.03006"
"73392","440.31600","36.69320","0.03054"
"73473","440.80200","36.73373","0.03205"
"73554","441.28800","36.77427","0.03291"
"73635","441.77400","36.81469","0.03347"
"73716","442.26000","36.85511","0.03511"
"73797","442.74600","36.89565","0.03584"
"73878","443.23200","36.93618","0.03680"
"73959","443.71800","36.97672","0.03779"
"74040","444.20400","37.01720","0.03957"
"74121","444.69000","37.05767","0.04016"
"74202","445.17600","37.09821","0.04047"
"74283","445.66200","37.13874","0.04171"
"74364","446.14800","37.17923","0.04225"
"74445","446.63400","37.21964","0.04310"
"74526","447.12000","37.26018","0.04436"
"74607","447.60600","37.30066","0.04441"
"74688","448.09200","37.34113","0.04541"
"74769","448.57800","37.38167","0.04571"
"74850","449.06400","37.42221","0.04550"
"74931","449.55000","37.46268","0.04648"
"75012","450.03600","37.50322","0.04691"
"75093","450.52200","37.54370","0.04735"
"75174","451.00800","37.58418","0.04755"
"75255","451.49400","37.62472","0.04793"
"75336","451.98000","37.66513","0.04873"
"75417","452.46600","37.70567","0.04903"
"75498","452.95200","37.74609","0.04946"
"75579","453.43800","37.78669","0.04947"
"75660","453.92400","37.82722","0.04925"
"75741","454.41000","37.86770","0.04962"
"75822","454.89600","37.90818","0.05020"
"75903","455.38200","37.94866","0.05023"
"75984","455.86800","37.98919","0.05123"
"76065","456.35400","38.02973","0.05133"
"76146","456.84000","38.07015","0.05205"
"76227","457.32600","38.11063","0.05241"
"76308","457.81200","38.15110","0.05260"
"76389","458.29800","38.19164","0.05260"
"76470","458.78400","38.23218","0.05302"
"76551","459.27000","38.27272","0.05349"
"76632","459.75600","38.31325","0.05364"
"76713","460.24200","38.35373","0.05443"
"76794","460.72800","38.39415","0.05488"
"76875","461.21400","38.43468","0.05541"
"76956","461.70000","38.47516","0.05568"
"77037","462.18600","38.51564","0.05650"
"77118","462.67200","38.55612","0.05714"
"77199","463.15800","38.59666","0.05753"
"77280","463.64400","38.63719","0.05817"
"77361","464.13000","38.67767","0.05859"
"77442","464.61600","38.71821","0.06009"
"77523","465.10200","38.75868","0.06252"
"77604","465.58800","38.79916","0.05396"
"77685","466.07400","38.83970","0.05366"
"77766","466.56000","38.88018","0.05473"
"77847","467.04600","38.92060","0.05574"
"77928","467.53200","38.96119","0.05719"
"78009","468.01800","39.00161","0.05821"
"78090","468.50400","39.04215","0.05941"
"78171","468.99000","39.08268","0.06104"
"78252","469.47600","39.12316","0.06241"
"78333","469.96200","39.16370","0.06502"
"78414","470.44800","39.20418","0.06699"
"78495","470.93400","39.24471","0.06936"
"78576","471.42000","39.28519","0.07216"
"78657","471.90600","39.32567","0.07441"
"78738","472.39200","39.36615","0.07616"
"78819","472.87800","39.40668","0.07722"
"78900","473.36400","39.44710","0.06902"
"78981","473.85000","39.48770","0.07077"
"79062","474.33600","39.52818","0.07168"
"79143","474.82200","39.56871","0.07276"
"79224","475.30800","39.60919","0.07470"
"79305","475.79400","39.64973","0.07726"
"79386","476.28000","39.69020","0.07949"
"79467","476.76600","39.73068","0.08105"
"79548","477.25200","39.77110","0.08303"
"79629","477.73800","39.81164","0.08485"
"79710","478.22400","39.85217","0.08804"
"79791","478.71000","39.89272","0.08943"
"79872","479.19600","39.93319","0.09154"
"79953","479.68200","39.97367","0.09456"
"80034","480.16800","40.01427","0.09766"
"80115","480.65400","40.05468","0.09918"
"80196","481.14000","40.09522","0.10114"
"80277","481.62600","40.13570","0.10280"
"80358","482.11200","40.17617","0.10406"
"80439","482.59800","40.21666","0.10280"
"80520","483.08400","40.25713","0.03369"
"80601","483.57000","40.29766","0.03477"
"80682","484.05600","40.33826","0.03783"
"80763","484.54200","40.37868","0.04083"
"80844","485.02800","40.41928","0.04174"
"80925","485.51400","40.45969","0.04186"
"81006","486.00000","40.50024","0.04319"
"81087","486.48600","40.54071","0.04510"
"81168","486.97200","40.58119","0.04617"
"81249","487.45800","40.62161","0.04810"
"81330","487.94400","40.66214","0.04988"
"81411","488.43000","40.70262","0.05124"
"81492","488.91600","40.74322","0.05182"
"81573","489.40200","40.78364","0.05284"
"81654","489.88800","40.82417","0.05301"
"81735","490.37400","40.86471","0.05373"
"81816","490.86000","40.90519","0.05407"
"81897","491.34600","40.94573","0.05435"
"81978","491.83200","40.98620","0.05461"
"82059","492.31800","41.02668","0.05508"
"82140","492.80400","41.06716","0.05604"
"82221","493.29000","41.10763","0.05673"
"82302","493.77600","41.14817","0.05804"
"82383","494.26200","41.18871","0.05951"
"82464","494.74800","41.22919","0.06111"
"82545","495.23400","41.26973","0.06323"
"82626","495.72000","41.31014","0.06455"
"82707","496.20600","41.35074","0.06589"
"82788","496.69200","41.39122","0.06803"
"82869","497.17800","41.43164","0.07034"
"82950","497.66400","41.47217","0.07208"
"83031","498.15000","41.51265","0.07431"
"83112","498.63600","41.55312","0.07708"
"83193","499.12200","41.59367","0.07903"
"83274","499.60800","41.63420","0.08085"
"83355","500.09400","41.67468","0.08283"
"83436","500.58000","41.71515","0.08346"
"83517","501.06600","41.75576","0.08391"
"83598","501.55200","41.79623","0.08616"
"83679","502.03800","41.83671","0.08885"
"83760","502.52400","41.87713","0.09062"
"83841","503.01000","41.91767","0.09325"
"83922","503.49600","41.95814","0.09511"
"84003","503.98200","41.99874","0.09834"
"84084","504.46800","42.03915","0.10079"
"84165","504.95400","42.07969","0.10355"
"84246","505.44000","42.12023","0.10470"
"84327","505.92600","42.16064","0.10469"
"84408","506.41200","42.20125","0.10638"
"84489","506.89800","42.24160","0.10790"
"84570","507.38400","42.28214","0.10964"
"84651","507.87000","42.32262","0.11035"
"84732","508.35600","42.36315","0.11129"
"84813","508.84200","42.40363","0.11222"
"84894","509.32800","42.44417","0.11270"
"84975","509.81400","42.48470","0.11280"
"85056","510.30000","42.52525","0.11321"
"85137","510.78600","42.56566","0.11356"
"85218","511.27200","42.60620","0.11418"
"85299","511.75800","42.64668","0.11496"
"85380","512.24400","42.68716","0.11538"
"85461","512.73000","42.72770","0.11656"
"85542","513.21600","42.76811","0.11692"
"85623","513.70200","42.80871","0.11866"
"85704","514.18800","42.84919","0.12076"
"85785","514.67400","42.88972","0.12368"
"85866","515.16000","42.93020","0.12518"
"85947","515.64600","42.97068","0.12732"
"86028","516.13200","43.01122","0.12867"
"86109","516.61800","43.05175","0.13016"
"86190","517.10400","43.09217","0.13225"
"86271","517.59000","43.13264","0.13408"
"86352","518.07600","43.17313","0.13570"
"86433","518.56200","43.21366","0.13810"
"86514","519.04800","43.25426","0.13974"
"86595","519.53400","43.29467","0.14240"
"86676","520.02000","43.33521","0.14384"
"86757","520.50600","43.37569","0.14611"
"86838","520.99200","43.41617","0.14784"
"86919","521.47800","43.45671","0.14927"
"87000","521.96400","43.49718","0.15068"
"87081","522.45000","43.53760","0.15221"
"87162","522.93600","43.57814","0.15351"
"87243","523.42200","43.61874","0.15496"
"87324","523.90800","43.65915","0.15612"
"87405","524.39400","43.69969","0.15691"
"87486","524.88000","43.74017","0.15814"
"87567","525.36600","43.78071","0.15884"
"87648","525.85200","43.82119","0.02713"
"87729","526.33800","43.86172","0.02397"
"87810","526.82400","43.90219","0.04272"
"87891","527.31000","43.94268","0.03225"
"87972","527.79600","43.98315","0.02504"
"88053","528.28200","44.02363","0.02596"
"88134","528.76800","44.06417","0.03324"
"88215","529.25400","44.10470","0.04185"
"88296","529.74000","44.14518","0.04656"
"88377","530.22600","44.18572","0.04611"
"88458","530.71200","44.22620","0.04491"
"88539","531.19800","44.26668","0.04451"
"88620","531.68400","44.30721","0.04638"
"88701","532.17000","44.34769","0.04915"
"88782","532.65600","44.38817","0.05096"
"88863","533.14200","44.42865","0.05232"
"88944","533.62800","44.46912","0.05385"
"89025","534.11400","44.50972","0.05474"
"89106","534.60000","44.55019","0.05577"
"89187","535.08600","44.59074","0.05708"
"89268","535.57200","44.63121","0.05792"
"89349","536.05800","44.67169","0.05903"
"89430","536.54400","44.71222","0.06186"
"89511","537.03000","44.75264","0.06388"
"89592","537.51600","44.79312","0.06669"
"89673","538.00200","44.83366","0.03119"
"89754","538.48800","44.87420","-0.01040"
"89835","538.97400","44.91467","-0.02949"
"89916","539.46000","44.95521","-0.00864"
"89997","539.94600","44.99563","-0.02009"
"90078","540.43200","45.03623","-0.02825"
"90159","540.91800","45.07671","-0.00551"
"90240","541.40400","45.11718","-0.01506"
"90321","541.89000","45.15771","-0.01759"
"90402","542.37600","45.19820","-0.00739"
"90483","542.86200","45.23867","-0.01678"
"90564","543.34800","45.27915","-0.01745"
"90645","543.83400","45.31969","-0.01008"
"90726","544.32000","45.36016","-0.01399"
"90807","544.80600","45.40070","-0.01958"
"90888","545.29200","45.44124","-0.01815"
"90969","545.77800","45.48166","-0.01626"
"91050","546.26400","45.52219","-0.01849"
"91131","546.75000","45.56267","-0.01899"
"91212","547.23600","45.60315","-0.01803"
"91293","547.72200","45.64357","-0.01691"
"91374","548.20800","45.68417","-0.01648"
"91455","548.69400","45.72464","-0.01670"
"91536","549.18000","45.76524","-0.01674"
"91617","549.66600","45.80566","-0.01448"
"91698","550.15200","45.84620","-0.01394"
"91779","550.63800","45.88667","-0.01428"
"91860","551.12400","45.92721","-0.01399"
"91941","551.61000","45.96769","-0.01168"
"92022","552.09600","46.00816","-0.01160"
"92103","552.58200","46.04865","-0.01184"
"92184","553.06800","46.08912","-0.01247"
"92265","553.55400","46.12966","-0.01037"
"92346","554.04000","46.17014","-0.01030"
"92427","554.52600","46.21073","-0.01018"
"92508","555.01200","46.25121","-0.01101"
"92589","555.49800","46.29169","-0.00912"
"92670","555.98400","46.33216","-0.00926"
"92751","556.47000","46.37270","-0.00951"
"92832","556.95600","46.41318","-0.00948"
"92913","557.44200","46.45359","-0.00795"
"92994","557.92800","46.49420","-0.00690"
"93075","558.41400","46.53461","-0.00671"
"93156","558.90000","46.57515","-0.00618"
"93237","559.38600","46.61569","-0.00432"
"93318","559.87200","46.65622","-0.00250"
"93399","560.35800","46.69670","-0.00237"
"93480","560.84400","46.73718","-0.00160"
"93561","561.33000","46.77772","-0.00151"
"93642","561.81600","46.81820","-0.00065"
"93723","562.30200","46.85861","-0.00058"
"93804","562.78800","46.89915","-0.00019"
"93885","563.27400","46.93962","-0.00080"
"93966","563.76000","46.98016","-0.00071"
"94047","564.24600","47.02070","0.00032"
"94128","564.73200","47.06118","0.00083"
"94209","565.21800","47.10166","0.00239"
"94290","565.70400","47.14219","0.00220"
"94371","566.19000","47.18267","0.00256"
"94452","566.67600","47.22321","0.00220"
"94533","567.16200","47.26369","-0.00029"
"94614","567.64800","47.30416","-0.00299"
"94695","568.13400","47.34464","-0.00154"
"94776","568.62000","47.38512","-0.00360"
"94857","569.10600","47.42566","-0.00279"
"94938","569.59200","47.46625","-0.00059"
"95019","570.07800","47.50667","-0.00040"
"95100","570.56400","47.54726","-0.00053"
"95181","571.05000","47.58775","0.00021"
"95262","571.53600","47.62817","0.00070"
"95343","572.02200","47.66870","0.00040"
"95424","572.50800","47.70912","0.00066"
"95505","572.99400","47.74960","0.00057"
"95586","573.48000","47.79013","0.00054"
"95667","573.96600","47.83067","0.00100"
"95748","574.45200","47.87121","0.00123"
"95829","574.93800","47.91174","0.00237"
"95910","575.42400","47.95222","0.00209"
"95991","575.91000","47.99270","0.00266"
"96072","576.39600","48.03318","0.00239"
"96153","576.88200","48.07372","0.00262"
"96234","577.36800","48.11413","0.00262"
"96315","577.85400","48.15461","0.00338"
"96396","578.34000","48.19509","0.00356"
"96477","578.82600","48.23568","0.00311"
"96558","579.31200","48.27622","0.00405"
"96639","579.79800","48.31670","0.00373"
"96720","580.28400","48.35723","0.00411"
"96801","580.77000","48.39771","0.00380"
"96882","581.25600","48.43819","0.00416"
"96963","581.74200","48.47873","0.00430"
"97044","582.22800","48.51921","0.00422"
"97125","582.71400","48.55962","0.00499"
"97206","583.20000","48.60016","0.00464"
"97287","583.68600","48.64064","0.00506"
"97368","584.17200","48.68112","0.00485"
"97449","584.65800","48.72166","0.00493"
"97530","585.14400","48.76219","0.00537"
"97611","585.63000","48.80273","0.00547"
"97692","586.11600","48.84321","0.00575"
"97773","586.60200","48.88374","0.00542"
"97854","587.08800","48.92422","0.00574"
"97935","587.57400","48.96464","0.00609"
"98016","588.06000","49.00517","0.00597"
"98097","588.54600","49.04565","0.00646"
"98167","588.96600","49.08069","0.00620"