File: Trajectories_together/170108_2Specimen_RawData_3.csv
"","V1","V2","V3"
"1","End date","1/8/2017",""
"2","Specimen label","11DG_85",""
"3","Maximum Load","0.06319","N"
"4","Time","Extension","Load"
"5","(s)","(mm)","(N)"
"6","0.00000","0.00000","0.00068"
"82","0.45600","0.03827","0.00234"
"158","0.91200","0.07623","0.00380"
"234","1.36800","0.11420","0.00480"
"310","1.82400","0.15216","0.00614"
"386","2.28000","0.19013","0.00663"
"462","2.73600","0.22816","0.00700"
"538","3.19200","0.26612","0.00716"
"614","3.64800","0.30415","0.00770"
"690","4.10400","0.34224","0.00874"
"766","4.56000","0.38020","0.00897"
"842","5.01600","0.41817","0.00903"
"918","5.47200","0.45613","0.00958"
"994","5.92800","0.49416","0.00981"
"1070","6.38400","0.53225","0.01041"
"1146","6.84000","0.57021","0.01006"
"1222","7.29600","0.60824","0.01021"
"1298","7.75200","0.64615","0.01054"
"1374","8.20800","0.68411","0.01053"
"1450","8.66400","0.72214","0.01135"
"1526","9.12000","0.76022","0.01118"
"1602","9.57600","0.79819","0.01140"
"1678","10.03200","0.83622","0.01163"
"1754","10.48800","0.87418","0.01160"
"1830","10.94400","0.91215","0.01179"
"1906","11.40000","0.95012","0.01184"
"1982","11.85600","0.98814","0.01215"
"2058","12.31200","1.02623","0.01222"
"2134","12.76800","1.06419","0.01287"
"2210","13.22400","1.10228","0.01282"
"2286","13.68000","1.14019","0.01326"
"2362","14.13600","1.17815","0.01340"
"2438","14.59200","1.21612","0.01285"
"2514","15.04800","1.25420","0.01362"
"2590","15.50400","1.29217","0.01354"
"2666","15.96000","1.33014","0.01382"
"2742","16.41600","1.36816","0.01414"
"2818","16.87200","1.40619","0.01355"
"2894","17.32800","1.44416","0.01394"
"2970","17.78400","1.48218","0.01391"
"3046","18.24000","1.52021","0.01386"
"3122","18.69600","1.55817","0.01430"
"3198","19.15200","1.59620","0.01428"
"3274","19.60800","1.63423","0.01496"
"3350","20.06400","1.67219","0.01447"
"3426","20.52000","1.71016","0.01461"
"3502","20.97600","1.74819","0.01491"
"3578","21.43200","1.78621","0.01480"
"3654","21.88800","1.82424","0.01498"
"3730","22.34400","1.86215","0.01523"
"3806","22.80000","1.90017","0.01488"
"3882","23.25600","1.93814","0.01491"
"3958","23.71200","1.97616","0.01557"
"4034","24.16800","2.01413","0.01555"
"4110","24.62400","2.05222","0.01497"
"4186","25.08000","2.09024","0.01532"
"4262","25.53600","2.12815","0.01606"
"4338","25.99200","2.16617","0.01579"
"4414","26.44800","2.20420","0.01632"
"4490","26.90400","2.24217","0.01596"
"4566","27.36000","2.28019","0.01631"
"4642","27.81600","2.31822","0.01628"
"4718","28.27200","2.35625","0.01626"
"4794","28.72800","2.39421","0.01642"
"4870","29.18400","2.43206","0.01642"
"4946","29.64000","2.47014","0.01591"
"5022","30.09600","2.50817","0.01629"
"5098","30.55200","2.54620","0.01623"
"5174","31.00800","2.58422","0.01654"
"5250","31.46400","2.62213","0.01622"
"5326","31.92000","2.66016","0.01665"
"5402","32.37600","2.69818","0.01681"
"5478","32.83200","2.73621","0.01710"
"5554","33.28800","2.77423","0.01700"
"5630","33.74400","2.81220","0.01727"
"5706","34.20000","2.85017","0.01663"
"5782","34.65600","2.88819","0.01769"
"5858","35.11200","2.92616","0.01674"
"5934","35.56800","2.96419","0.01652"
"6010","36.02400","3.00215","0.01715"
"6086","36.48000","3.04024","0.01727"
"6162","36.93600","3.07820","0.01700"
"6238","37.39200","3.11623","0.01720"
"6314","37.84800","3.15414","0.01703"
"6390","38.30400","3.19210","0.01691"
"6466","38.76000","3.23019","0.01746"
"6542","39.21600","3.26822","0.01739"
"6618","39.67200","3.30618","0.01773"
"6694","40.12800","3.34421","0.01788"
"6770","40.58400","3.38223","0.01720"
"6846","41.04000","3.42014","0.01687"
"6922","41.49600","3.45823","0.01775"
"6998","41.95200","3.49619","0.01771"
"7074","42.40800","3.53422","0.01763"
"7150","42.86400","3.57225","0.01765"
"7226","43.32000","3.61021","0.01773"
"7302","43.77600","3.64818","0.01791"
"7378","44.23200","3.68614","0.01820"
"7454","44.68800","3.72411","0.01779"
"7530","45.14400","3.76220","0.01825"
"7606","45.60000","3.80022","0.01807"
"7682","46.05600","3.83819","0.01833"
"7758","46.51200","3.87616","0.01825"
"7834","46.96800","3.91412","0.01823"
"7910","47.42400","3.95215","0.01841"
"7986","47.88000","3.99017","0.01864"
"8062","48.33600","4.02826","0.01850"
"8138","48.79200","4.06617","0.01840"
"8214","49.24800","4.10419","0.01886"
"8290","49.70400","4.14216","0.01933"
"8366","50.16000","4.18018","0.01906"
"8442","50.61600","4.21821","0.01849"
"8518","51.07200","4.25618","0.01899"
"8594","51.52800","4.29420","0.01857"
"8670","51.98400","4.33217","0.01887"
"8746","52.44000","4.37020","0.01909"
"8822","52.89600","4.40816","0.01899"
"8898","53.35200","4.44619","0.01930"
"8974","53.80800","4.48421","0.01924"
"9050","54.26400","4.52218","0.01897"
"9126","54.72000","4.56021","0.01940"
"9202","55.17600","4.59817","0.01984"
"9278","55.63200","4.63620","0.01895"
"9354","56.08800","4.67411","0.01879"
"9430","56.54400","4.71219","0.01900"
"9506","57.00000","4.75016","0.01911"
"9582","57.45600","4.78824","0.01876"
"9658","57.91200","4.82621","0.01927"
"9734","58.36800","4.86418","0.01913"
"9810","58.82400","4.90214","0.01867"
"9886","59.28000","4.94011","0.01912"
"9962","59.73600","4.97820","0.01924"
"10038","60.19200","5.01616","0.01924"
"10114","60.64800","5.05425","0.01914"
"10190","61.10400","5.09221","0.01897"
"10266","61.56000","5.13018","0.01926"
"10342","62.01600","5.16815","0.01954"
"10418","62.47200","5.20617","0.01976"
"10494","62.92800","5.24420","0.01931"
"10570","63.38400","5.28229","0.01949"
"10646","63.84000","5.32025","0.01925"
"10722","64.29600","5.35822","0.01957"
"10798","64.75200","5.39612","0.01959"
"10874","65.20800","5.43415","0.01969"
"10950","65.66400","5.47212","0.01939"
"11026","66.12000","5.51020","0.01957"
"11102","66.57600","5.54823","0.01964"
"11178","67.03200","5.58620","0.01962"
"11254","67.48800","5.62416","0.01963"
"11330","67.94400","5.66213","0.01975"
"11406","68.40000","5.70021","0.02044"
"11482","68.85600","5.73818","0.01995"
"11558","69.31200","5.77621","0.01983"
"11634","69.76800","5.81417","0.02019"
"11710","70.22400","5.85220","0.02002"
"11786","70.68000","5.89017","0.02017"
"11862","71.13600","5.92819","0.02022"
"11938","71.59200","5.96616","0.02038"
"12014","72.04800","6.00418","0.02026"
"12090","72.50400","6.04221","0.01987"
"12166","72.96000","6.08024","0.02054"
"12242","73.41600","6.11820","0.02023"
"12318","73.87200","6.15611","0.02018"
"12394","74.32800","6.19414","0.02026"
"12470","74.78400","6.23216","0.02064"
"12546","75.24000","6.27019","0.02031"
"12622","75.69600","6.30815","0.02002"
"12698","76.15200","6.34624","0.02027"
"12774","76.60800","6.38415","0.02005"
"12850","77.06400","6.42211","0.02048"
"12926","77.52000","6.46020","0.02088"
"13002","77.97600","6.49817","0.02028"
"13078","78.43200","6.53619","0.02041"
"13154","78.88800","6.57428","0.01990"
"13230","79.34400","6.61218","0.02049"
"13306","79.80000","6.65015","0.02062"
"13382","80.25600","6.68812","0.01998"
"13458","80.71200","6.72614","0.02035"
"13534","81.16800","6.76423","0.02073"
"13610","81.62400","6.80220","0.02038"
"13686","82.08000","6.84022","0.02085"
"13762","82.53600","6.87813","0.02063"
"13838","82.99200","6.91609","0.02096"
"13914","83.44800","6.95418","0.02099"
"13990","83.90400","6.99221","0.02109"
"14066","84.36000","7.03023","0.02070"
"14142","84.81600","7.06814","0.02012"
"14218","85.27200","7.10617","0.02057"
"14294","85.72800","7.14419","0.02043"
"14370","86.18400","7.18216","0.02061"
"14446","86.64000","7.22024","0.02070"
"14522","87.09600","7.25815","0.02065"
"14598","87.55200","7.29618","0.02019"
"14674","88.00800","7.33414","0.02023"
"14750","88.46400","7.37223","0.02078"
"14826","88.92000","7.41014","0.02082"
"14902","89.37600","7.44816","0.02086"
"14978","89.83200","7.48619","0.02089"
"15054","90.28800","7.52421","0.02068"
"15130","90.74400","7.56218","0.02052"
"15206","91.20000","7.60015","0.02010"
"15282","91.65600","7.63817","0.02045"
"15358","92.11200","7.67614","0.02057"
"15434","92.56800","7.71417","0.02063"
"15510","93.02400","7.75225","0.02016"
"15586","93.48000","7.79016","0.02028"
"15662","93.93600","7.82824","0.02033"
"15738","94.39200","7.86615","0.02049"
"15814","94.84800","7.90412","0.02040"
"15890","95.30400","7.94214","0.02062"
"15966","95.76000","7.98011","0.02045"
"16042","96.21600","8.01820","0.02108"
"16118","96.67200","8.05622","0.02075"
"16194","97.12800","8.09425","0.02062"
"16270","97.58400","8.13215","0.02062"
"16346","98.04000","8.17012","0.02098"
"16422","98.49600","8.20821","0.02074"
"16498","98.95200","8.24617","0.02056"
"16574","99.40800","8.28426","0.02118"
"16650","99.86400","8.32216","0.02111"
"16726","100.32000","8.36013","0.02152"
"16802","100.77600","8.39810","0.02140"
"16878","101.23200","8.43612","0.02164"
"16954","101.68800","8.47421","0.02088"
"17030","102.14400","8.51218","0.02171"
"17106","102.60000","8.55020","0.02127"
"17182","103.05600","8.58823","0.02138"
"17258","103.51200","8.62619","0.02203"
"17334","103.96800","8.66416","0.02180"
"17410","104.42400","8.70219","0.02185"
"17486","104.88000","8.74021","0.02105"
"17562","105.33600","8.77818","0.02084"
"17638","105.79200","8.81621","0.02106"
"17714","106.24800","8.85423","0.02163"
"17790","106.70400","8.89214","0.02125"
"17866","107.16000","8.93016","0.02152"
"17942","107.61600","8.96819","0.02124"
"18018","108.07200","9.00622","0.02138"
"18094","108.52800","9.04418","0.02121"
"18170","108.98400","9.08221","0.02139"
"18246","109.44000","9.12018","0.02103"
"18322","109.89600","9.15814","0.02131"
"18398","110.35200","9.19617","0.02135"
"18474","110.80800","9.23419","0.02162"
"18550","111.26400","9.27222","0.02096"
"18626","111.72000","9.31019","0.02141"
"18702","112.17600","9.34815","0.02113"
"18778","112.63200","9.38618","0.02167"
"18854","113.08800","9.42415","0.02156"
"18930","113.54400","9.46211","0.02106"
"19006","114.00000","9.50020","0.02134"
"19082","114.45600","9.53822","0.02181"
"19158","114.91200","9.57631","0.02213"
"19234","115.36800","9.61416","0.02241"
"19310","115.82400","9.65212","0.02140"
"19386","116.28000","9.69015","0.02180"
"19462","116.73600","9.72818","0.02236"
"19538","117.19200","9.76626","0.02161"
"19614","117.64800","9.80423","0.02226"
"19690","118.10400","9.84219","0.02252"
"19766","118.56000","9.88010","0.02239"
"19842","119.01600","9.91813","0.02281"
"19918","119.47200","9.95615","0.02242"
"19994","119.92800","9.99418","0.02218"
"20070","120.38400","10.03221","0.02223"
"20146","120.84000","10.07023","0.02247"
"20222","121.29600","10.10820","0.02221"
"20298","121.75200","10.14616","0.02279"
"20374","122.20800","10.18419","0.02258"
"20450","122.66400","10.22222","0.02200"
"20526","123.12000","10.26018","0.02239"
"20602","123.57600","10.29821","0.02223"
"20678","124.03200","10.33624","0.02252"
"20754","124.48800","10.37420","0.02171"
"20830","124.94400","10.41217","0.02304"
"20906","125.40000","10.45013","0.02189"
"20982","125.85600","10.48816","0.02168"
"21058","126.31200","10.52619","0.02228"
"21134","126.76800","10.56421","0.02215"
"21210","127.22400","10.60218","0.02245"
"21286","127.68000","10.64015","0.02256"
"21362","128.13600","10.67811","0.02226"
"21438","128.59200","10.71620","0.02251"
"21514","129.04800","10.75416","0.02249"
"21590","129.50400","10.79219","0.02192"
"21666","129.96000","10.83022","0.02220"
"21742","130.41600","10.86818","0.02213"
"21818","130.87200","10.90615","0.02224"
"21894","131.32800","10.94412","0.02314"
"21970","131.78400","10.98220","0.02264"
"22046","132.24000","11.02017","0.02270"
"22122","132.69600","11.05825","0.02274"
"22198","133.15200","11.09622","0.02240"
"22274","133.60800","11.13413","0.02297"
"22350","134.06400","11.17215","0.02246"
"22426","134.52000","11.21018","0.02234"
"22502","134.97600","11.24826","0.02268"
"22578","135.43200","11.28623","0.02197"
"22654","135.88800","11.32420","0.02251"
"22730","136.34400","11.36216","0.02263"
"22806","136.80000","11.40013","0.02283"
"22882","137.25600","11.43816","0.02245"
"22958","137.71200","11.47618","0.02205"
"23034","138.16800","11.51421","0.02258"
"23110","138.62400","11.55218","0.02271"
"23186","139.08000","11.59014","0.02265"
"23262","139.53600","11.62817","0.02277"
"23338","139.99200","11.66613","0.02310"
"23414","140.44800","11.70422","0.02288"
"23490","140.90400","11.74219","0.02257"
"23566","141.36000","11.78021","0.02315"
"23642","141.81600","11.81818","0.02289"
"23718","142.27200","11.85614","0.02258"
"23794","142.72800","11.89417","0.02293"
"23870","143.18400","11.93214","0.02322"
"23946","143.64000","11.97022","0.02264"
"24022","144.09600","12.00819","0.02272"
"24098","144.55200","12.04616","0.02242"
"24174","145.00800","12.08418","0.02326"
"24250","145.46400","12.12221","0.02332"
"24326","145.92000","12.16018","0.02315"
"24402","146.37600","12.19820","0.02309"
"24478","146.83200","12.23623","0.02320"
"24554","147.28800","12.27419","0.02329"
"24630","147.74400","12.31222","0.02325"
"24706","148.20000","12.35018","0.02356"
"24782","148.65600","12.38815","0.02335"
"24858","149.11200","12.42618","0.02272"
"24934","149.56800","12.46415","0.02337"
"25010","150.02400","12.50223","0.02322"
"25086","150.48000","12.54020","0.02360"
"25162","150.93600","12.57822","0.02336"
"25238","151.39200","12.61613","0.02357"
"25314","151.84800","12.65416","0.02365"
"25390","152.30400","12.69218","0.02359"
"25466","152.76000","12.73021","0.02385"
"25542","153.21600","12.76824","0.02356"
"25618","153.67200","12.80620","0.02374"
"25694","154.12800","12.84417","0.02353"
"25770","154.58400","12.88213","0.02330"
"25846","155.04000","12.92016","0.02317"
"25922","155.49600","12.95819","0.02341"
"25998","155.95200","12.99621","0.02316"
"26074","156.40800","13.03418","0.02350"
"26150","156.86400","13.07215","0.02305"
"26226","157.32000","13.11017","0.02343"
"26302","157.77600","13.14814","0.02331"
"26378","158.23200","13.18616","0.02401"
"26454","158.68800","13.22425","0.02340"
"26530","159.14400","13.26221","0.02341"
"26606","159.60000","13.30024","0.02342"
"26682","160.05600","13.33815","0.02361"
"26758","160.51200","13.37617","0.02287"
"26834","160.96800","13.41414","0.02308"
"26910","161.42400","13.45217","0.02392"
"26986","161.88000","13.49019","0.02277"
"27062","162.33600","13.52816","0.02270"
"27138","162.79200","13.56618","0.02253"
"27214","163.24800","13.60415","0.02269"
"27290","163.70400","13.64218","0.02299"
"27366","164.16000","13.68020","0.02290"
"27442","164.61600","13.71817","0.02345"
"27518","165.07200","13.75620","0.02367"
"27594","165.52800","13.79422","0.02283"
"27670","165.98400","13.83225","0.02308"
"27746","166.44000","13.87016","0.02309"
"27822","166.89600","13.90812","0.02311"
"27898","167.35200","13.94621","0.02263"
"27974","167.80800","13.98417","0.02183"
"28050","168.26400","14.02220","0.02191"
"28126","168.72000","14.06023","0.02175"
"28202","169.17600","14.09819","0.02180"
"28278","169.63200","14.13610","0.02113"
"28354","170.08800","14.17412","0.02218"
"28430","170.54400","14.21221","0.02117"
"28506","171.00000","14.25018","0.02157"
"28582","171.45600","14.28826","0.02191"
"28658","171.91200","14.32617","0.02235"
"28734","172.36800","14.36414","0.02180"
"28810","172.82400","14.40216","0.02203"
"28886","173.28000","14.44019","0.02211"
"28962","173.73600","14.47822","0.02173"
"29038","174.19200","14.51618","0.02163"
"29114","174.64800","14.55421","0.02202"
"29190","175.10400","14.59223","0.02173"
"29266","175.56000","14.63008","0.02165"
"29342","176.01600","14.66817","0.02169"
"29418","176.47200","14.70619","0.02165"
"29494","176.92800","14.74422","0.02177"
"29570","177.38400","14.78218","0.02202"
"29646","177.84000","14.82015","0.02185"
"29722","178.29600","14.85818","0.02175"
"29798","178.75200","14.89620","0.02182"
"29874","179.20800","14.93417","0.02171"
"29950","179.66400","14.97220","0.02237"
"30026","180.12000","15.01022","0.02193"
"30102","180.57600","15.04819","0.02252"
"30178","181.03200","15.08622","0.02224"
"30254","181.48800","15.12418","0.02171"
"30330","181.94400","15.16215","0.02206"
"30406","182.40000","15.20012","0.02216"
"30482","182.85600","15.23820","0.02232"
"30558","183.31200","15.27617","0.02233"
"30634","183.76800","15.31419","0.02213"
"30710","184.22400","15.35216","0.02255"
"30786","184.68000","15.39013","0.02240"
"30862","185.13600","15.42815","0.02251"
"30938","185.59200","15.46618","0.02188"
"31014","186.04800","15.50420","0.02219"
"31090","186.50400","15.54223","0.02223"
"31166","186.96000","15.58020","0.02263"
"31242","187.41600","15.61816","0.02237"
"31318","187.87200","15.65619","0.02196"
"31394","188.32800","15.69421","0.02226"
"31470","188.78400","15.73218","0.02200"
"31546","189.24000","15.77021","0.02250"
"31622","189.69600","15.80817","0.02235"
"31698","190.15200","15.84614","0.02219"
"31774","190.60800","15.88410","0.02171"
"31850","191.06400","15.92213","0.02267"
"31926","191.52000","15.96022","0.02247"
"32002","191.97600","15.99824","0.02241"
"32078","192.43200","16.03621","0.02212"
"32154","192.88800","16.07418","0.02222"
"32230","193.34400","16.11208","0.02260"
"32306","193.80000","16.15017","0.02252"
"32382","194.25600","16.18819","0.02240"
"32458","194.71200","16.22622","0.02231"
"32534","195.16800","16.26419","0.02185"
"32610","195.62400","16.30221","0.02197"
"32686","196.08000","16.34018","0.02269"
"32762","196.53600","16.37815","0.02223"
"32838","196.99200","16.41617","0.02188"
"32914","197.44800","16.45420","0.02172"
"32990","197.90400","16.49217","0.02250"
"33066","198.36000","16.53013","0.02212"
"33142","198.81600","16.56822","0.02150"
"33218","199.27200","16.60618","0.02174"
"33294","199.72800","16.64415","0.02190"
"33370","200.18400","16.68218","0.02222"
"33446","200.64000","16.72020","0.02177"
"33522","201.09600","16.75817","0.02225"
"33598","201.55200","16.79620","0.02160"
"33674","202.00800","16.83416","0.02176"
"33750","202.46400","16.87213","0.02222"
"33826","202.92000","16.91015","0.02204"
"33902","203.37600","16.94818","0.02174"
"33978","203.83200","16.98621","0.02196"
"34054","204.28800","17.02423","0.02213"
"34130","204.74400","17.06220","0.02233"
"34206","205.20000","17.10016","0.02212"
"34282","205.65600","17.13813","0.02191"
"34358","206.11200","17.17616","0.02195"
"34434","206.56800","17.21424","0.02199"
"34510","207.02400","17.25227","0.02228"
"34586","207.48000","17.29024","0.02277"
"34662","207.93600","17.32814","0.02236"
"34738","208.39200","17.36617","0.02230"
"34814","208.84800","17.40413","0.02250"
"34890","209.30400","17.44222","0.02257"
"34966","209.76000","17.48025","0.02225"
"35042","210.21600","17.51821","0.02244"
"35118","210.67200","17.55624","0.02260"
"35194","211.12800","17.59414","0.02251"
"35270","211.58400","17.63217","0.02288"
"35346","212.04000","17.67014","0.02289"
"35422","212.49600","17.70823","0.02343"
"35498","212.95200","17.74619","0.02275"
"35574","213.40800","17.78422","0.02314"
"35650","213.86400","17.82218","0.02242"
"35726","214.32000","17.86015","0.02206"
"35802","214.77600","17.89818","0.02191"
"35878","215.23200","17.93620","0.02289"
"35954","215.68800","17.97417","0.02219"
"36030","216.14400","18.01219","0.02249"
"36106","216.60000","18.05016","0.02263"
"36182","217.05600","18.08819","0.02237"
"36258","217.51200","18.12615","0.02323"
"36334","217.96800","18.16418","0.02319"
"36410","218.42400","18.20221","0.02342"
"36486","218.88000","18.24017","0.02332"
"36562","219.33600","18.27826","0.02313"
"36638","219.79200","18.31616","0.02356"
"36714","220.24800","18.35419","0.02343"
"36790","220.70400","18.39216","0.02250"
"36866","221.16000","18.43018","0.02297"
"36942","221.61600","18.46821","0.02285"
"37018","222.07200","18.50618","0.02270"
"37094","222.52800","18.54420","0.02282"
"37170","222.98400","18.58217","0.02249"
"37246","223.44000","18.62008","0.02221"
"37322","223.89600","18.65822","0.02273"
"37398","224.35200","18.69619","0.02328"
"37474","224.80800","18.73421","0.02251"
"37550","225.26400","18.77218","0.02224"
"37626","225.72000","18.81021","0.02308"
"37702","226.17600","18.84817","0.02319"
"37778","226.63200","18.88614","0.02277"
"37854","227.08800","18.92416","0.02368"
"37930","227.54400","18.96219","0.02334"
"38006","228.00000","19.00022","0.02347"
"38082","228.45600","19.03824","0.02381"
"38158","228.91200","19.07615","0.02338"
"38234","229.36800","19.11412","0.02361"
"38310","229.82400","19.15214","0.02353"
"38386","230.28000","19.19023","0.02308"
"38462","230.73600","19.22825","0.02335"
"38538","231.19200","19.26616","0.02351"
"38614","231.64800","19.30419","0.02334"
"38690","232.10400","19.34215","0.02270"
"38766","232.56000","19.38018","0.02288"
"38842","233.01600","19.41815","0.02305"
"38918","233.47200","19.45617","0.02365"
"38994","233.92800","19.49420","0.02305"
"39070","234.38400","19.53216","0.02352"
"39146","234.84000","19.57019","0.02304"
"39222","235.29600","19.60816","0.02292"
"39298","235.75200","19.64612","0.02280"
"39374","236.20800","19.68421","0.02265"
"39450","236.66400","19.72223","0.02296"
"39526","237.12000","19.76020","0.02281"
"39602","237.57600","19.79817","0.02266"
"39678","238.03200","19.83619","0.02255"
"39754","238.48800","19.87416","0.02347"
"39830","238.94400","19.91219","0.02266"
"39906","239.40000","19.95021","0.02297"
"39982","239.85600","19.98818","0.02304"
"40058","240.31200","20.02620","0.02279"
"40134","240.76800","20.06417","0.02341"
"40210","241.22400","20.10214","0.02366"
"40286","241.68000","20.14010","0.02336"
"40362","242.13600","20.17813","0.02326"
"40438","242.59200","20.21622","0.02331"
"40514","243.04800","20.25418","0.02346"
"40590","243.50400","20.29221","0.02310"
"40666","243.96000","20.33018","0.02357"
"40742","244.41600","20.36808","0.02339"
"40818","244.87200","20.40617","0.02367"
"40894","245.32800","20.44425","0.02361"
"40970","245.78400","20.48222","0.02375"
"41046","246.24000","20.52024","0.02336"
"41122","246.69600","20.55815","0.02395"
"41198","247.15200","20.59612","0.02372"
"41274","247.60800","20.63414","0.02390"
"41350","248.06400","20.67223","0.02396"
"41426","248.52000","20.71020","0.02376"
"41502","248.97600","20.74817","0.02382"
"41578","249.43200","20.78619","0.02374"
"41654","249.88800","20.82416","0.02420"
"41730","250.34400","20.86218","0.02393"
"41806","250.80000","20.90015","0.02388"
"41882","251.25600","20.93817","0.02414"
"41958","251.71200","20.97620","0.02423"
"42034","252.16800","21.01423","0.02413"
"42110","252.62400","21.05219","0.02377"
"42186","253.08000","21.09016","0.02379"
"42262","253.53600","21.12813","0.02387"
"42338","253.99200","21.16615","0.02373"
"42414","254.44800","21.20418","0.02331"
"42490","254.90400","21.24220","0.02414"
"42566","255.36000","21.28017","0.02404"
"42642","255.81600","21.31820","0.02410"
"42718","256.27200","21.35616","0.02404"
"42794","256.72800","21.39419","0.02429"
"42870","257.18400","21.43216","0.02476"
"42946","257.64000","21.47018","0.02429"
"43022","258.09600","21.50827","0.02444"
"43098","258.55200","21.54618","0.02373"
"43174","259.00800","21.58414","0.02430"
"43250","259.46400","21.62211","0.02441"
"43326","259.92000","21.66019","0.02415"
"43402","260.37600","21.69822","0.02422"
"43478","260.83200","21.73625","0.02443"
"43554","261.28800","21.77427","0.02376"
"43630","261.74400","21.81218","0.02382"
"43706","262.20000","21.85008","0.02381"
"43782","262.65600","21.88811","0.02371"
"43858","263.11200","21.92620","0.02368"
"43934","263.56800","21.96422","0.02410"
"44010","264.02400","22.00219","0.02434"
"44086","264.48000","22.04022","0.02462"
"44162","264.93600","22.07812","0.02437"
"44238","265.39200","22.11615","0.02426"
"44314","265.84800","22.15417","0.02458"
"44390","266.30400","22.19220","0.02415"
"44466","266.76000","22.23022","0.02390"
"44542","267.21600","22.26819","0.02435"
"44618","267.67200","22.30622","0.02386"
"44694","268.12800","22.34413","0.02408"
"44770","268.58400","22.38215","0.02379"
"44846","269.04000","22.42024","0.02433"
"44922","269.49600","22.45820","0.02403"
"44998","269.95200","22.49617","0.02372"
"45074","270.40800","22.53420","0.02352"
"45150","270.86400","22.57216","0.02351"
"45226","271.32000","22.61013","0.02394"
"45302","271.77600","22.64816","0.02426"
"45378","272.23200","22.68618","0.02387"
"45454","272.68800","22.72421","0.02491"
"45530","273.14400","22.76218","0.02415"
"45606","273.60000","22.80020","0.02425"
"45682","274.05600","22.83817","0.02392"
"45758","274.51200","22.87613","0.02484"
"45834","274.96800","22.91422","0.02520"
"45910","275.42400","22.95219","0.02463"
"45986","275.88000","22.99021","0.02480"
"46062","276.33600","23.02824","0.02511"
"46138","276.79200","23.06620","0.02459"
"46214","277.24800","23.10417","0.02521"
"46290","277.70400","23.14214","0.02494"
"46366","278.16000","23.18016","0.02478"
"46442","278.61600","23.21819","0.02455"
"46518","279.07200","23.25622","0.02496"
"46594","279.52800","23.29418","0.02546"
"46670","279.98400","23.33209","0.02554"
"46746","280.44000","23.37017","0.02545"
"46822","280.89600","23.40814","0.02523"
"46898","281.35200","23.44622","0.02512"
"46974","281.80800","23.48425","0.02577"
"47050","282.26400","23.52216","0.02498"
"47126","282.72000","23.56018","0.02525"
"47202","283.17600","23.59809","0.02594"
"47278","283.63200","23.63618","0.02604"
"47354","284.08800","23.67420","0.02591"
"47430","284.54400","23.71223","0.02604"
"47506","285.00000","23.75020","0.02542"
"47582","285.45600","23.78816","0.02540"
"47658","285.91200","23.82613","0.02570"
"47734","286.36800","23.86415","0.02602"
"47810","286.82400","23.90218","0.02628"
"47886","287.28000","23.94015","0.02600"
"47962","287.73600","23.97817","0.02624"
"48038","288.19200","24.01626","0.02659"
"48114","288.64800","24.05417","0.02639"
"48190","289.10400","24.09219","0.02735"
"48266","289.56000","24.13016","0.02662"
"48342","290.01600","24.16818","0.02649"
"48418","290.47200","24.20621","0.02665"
"48494","290.92800","24.24418","0.02725"
"48570","291.38400","24.28220","0.02716"
"48646","291.84000","24.32017","0.02715"
"48722","292.29600","24.35814","0.02684"
"48798","292.75200","24.39616","0.02667"
"48874","293.20800","24.43419","0.02786"
"48950","293.66400","24.47216","0.02751"
"49026","294.12000","24.51024","0.02752"
"49102","294.57600","24.54821","0.02775"
"49178","295.03200","24.58617","0.02822"
"49254","295.48800","24.62414","0.02790"
"49330","295.94400","24.66217","0.02769"
"49406","296.40000","24.70019","0.02796"
"49482","296.85600","24.73822","0.02762"
"49558","297.31200","24.77625","0.02731"
"49634","297.76800","24.81415","0.02816"
"49710","298.22400","24.85212","0.02768"
"49786","298.68000","24.89014","0.02795"
"49862","299.13600","24.92823","0.02759"
"49938","299.59200","24.96620","0.02795"
"50014","300.04800","25.00416","0.02824"
"50090","300.50400","25.04219","0.02839"
"50166","300.96000","25.08010","0.02820"
"50242","301.41600","25.11818","0.02849"
"50318","301.87200","25.15621","0.02882"
"50394","302.32800","25.19417","0.02789"
"50470","302.78400","25.23220","0.02925"
"50546","303.24000","25.27016","0.02952"
"50622","303.69600","25.30819","0.02738"
"50698","304.15200","25.34610","0.02729"
"50774","304.60800","25.38418","0.02744"
"50850","305.06400","25.42221","0.02790"
"50926","305.52000","25.46024","0.02815"
"51002","305.97600","25.49820","0.02793"
"51078","306.43200","25.53617","0.02764"
"51154","306.88800","25.57419","0.02800"
"51230","307.34400","25.61216","0.02843"
"51306","307.80000","25.65019","0.02609"
"51382","308.25600","25.68821","0.02492"
"51458","308.71200","25.72618","0.02618"
"51534","309.16800","25.76421","0.02535"
"51610","309.62400","25.80217","0.02515"
"51686","310.08000","25.84014","0.02519"
"51762","310.53600","25.87817","0.02476"
"51838","310.99200","25.91613","0.02467"
"51914","311.44800","25.95422","0.02469"
"51990","311.90400","25.99219","0.02431"
"52066","312.36000","26.03021","0.02416"
"52142","312.81600","26.06817","0.02514"
"52218","313.27200","26.10614","0.02490"
"52294","313.72800","26.14417","0.02256"
"52370","314.18400","26.18220","0.02322"
"52446","314.64000","26.22028","0.02219"
"52522","315.09600","26.25825","0.02278"
"52598","315.55200","26.29615","0.02304"
"52674","316.00800","26.33412","0.02299"
"52750","316.46400","26.37215","0.02360"
"52826","316.92000","26.41017","0.02402"
"52902","317.37600","26.44820","0.02371"
"52978","317.83200","26.48623","0.02400"
"53054","318.28800","26.52419","0.02401"
"53130","318.74400","26.56216","0.02423"
"53206","319.20000","26.60013","0.02458"
"53282","319.65600","26.63815","0.02384"
"53358","320.11200","26.67624","0.02407"
"53434","320.56800","26.71420","0.02426"
"53510","321.02400","26.75223","0.02440"
"53586","321.48000","26.79019","0.02454"
"53662","321.93600","26.82810","0.02434"
"53738","322.39200","26.86619","0.02480"
"53814","322.84800","26.90421","0.02397"
"53890","323.30400","26.94224","0.02469"
"53966","323.76000","26.98021","0.02448"
"54042","324.21600","27.01817","0.02533"
"54118","324.67200","27.05614","0.02534"
"54194","325.12800","27.09417","0.02527"
"54270","325.58400","27.13213","0.02489"
"54346","326.04000","27.17022","0.02551"
"54422","326.49600","27.20818","0.02520"
"54498","326.95200","27.24621","0.02487"
"54574","327.40800","27.28424","0.02476"
"54650","327.86400","27.32220","0.02478"
"54726","328.32000","27.36017","0.02526"
"54802","328.77600","27.39813","0.02538"
"54878","329.23200","27.43616","0.02589"
"54954","329.68800","27.47419","0.02496"
"55030","330.14400","27.51227","0.02546"
"55106","330.60000","27.55018","0.02560"
"55182","331.05600","27.58809","0.02571"
"55258","331.51200","27.62611","0.02551"
"55334","331.96800","27.66420","0.02554"
"55410","332.42400","27.70222","0.02520"
"55486","332.88000","27.74025","0.02558"
"55562","333.33600","27.77822","0.02580"
"55638","333.79200","27.81618","0.02626"
"55714","334.24800","27.85415","0.02571"
"55790","334.70400","27.89218","0.02590"
"55866","335.16000","27.93020","0.02622"
"55942","335.61600","27.96823","0.02605"
"56018","336.07200","28.00620","0.02654"
"56094","336.52800","28.04416","0.02668"
"56170","336.98400","28.08213","0.02668"
"56246","337.44000","28.12015","0.02675"
"56322","337.89600","28.15818","0.02661"
"56398","338.35200","28.19621","0.02696"
"56474","338.80800","28.23417","0.02653"
"56550","339.26400","28.27220","0.02684"
"56626","339.72000","28.31017","0.02690"
"56702","340.17600","28.34813","0.02727"
"56778","340.63200","28.38622","0.02719"
"56854","341.08800","28.42418","0.02648"
"56930","341.54400","28.46221","0.02695"
"57006","342.00000","28.50018","0.02675"
"57082","342.45600","28.53814","0.02697"
"57158","342.91200","28.57617","0.02615"
"57234","343.36800","28.61413","0.02625"
"57310","343.82400","28.65222","0.02588"
"57386","344.28000","28.69019","0.02618"
"57462","344.73600","28.72821","0.02657"
"57538","345.19200","28.76618","0.02600"
"57614","345.64800","28.80415","0.02612"
"57690","346.10400","28.84217","0.02654"
"57766","346.56000","28.88014","0.02718"
"57842","347.01600","28.91816","0.02619"
"57918","347.47200","28.95619","0.02612"
"57994","347.92800","28.99422","0.02701"
"58070","348.38400","29.03218","0.02678"
"58146","348.84000","29.07015","0.02646"
"58222","349.29600","29.10818","0.02716"
"58298","349.75200","29.14614","0.02665"
"58374","350.20800","29.18423","0.02709"
"58450","350.66400","29.22226","0.02735"
"58526","351.12000","29.26022","0.02763"
"58602","351.57600","29.29819","0.02715"
"58678","352.03200","29.33609","0.02711"
"58754","352.48800","29.37418","0.02736"
"58830","352.94400","29.41215","0.02744"
"58906","353.40000","29.45017","0.02748"
"58982","353.85600","29.48826","0.02735"
"59058","354.31200","29.52617","0.02793"
"59134","354.76800","29.56413","0.02813"
"59210","355.22400","29.60216","0.02757"
"59286","355.68000","29.64024","0.02853"
"59362","356.13600","29.67821","0.02810"
"59438","356.59200","29.71623","0.02753"
"59514","357.04800","29.75426","0.02812"
"59590","357.50400","29.79211","0.02788"
"59666","357.96000","29.83013","0.02818"
"59742","358.41600","29.86816","0.02744"
"59818","358.87200","29.90625","0.02821"
"59894","359.32800","29.94422","0.02910"
"59970","359.78400","29.98218","0.02861"
"60046","360.24000","30.02020","0.02854"
"60122","360.69600","30.05811","0.02893"
"60198","361.15200","30.09614","0.02921"
"60274","361.60800","30.13416","0.02893"
"60350","362.06400","30.17219","0.02876"
"60426","362.52000","30.21016","0.02943"
"60502","362.97600","30.24818","0.02936"
"60578","363.43200","30.28621","0.02896"
"60654","363.88800","30.32418","0.02874"
"60730","364.34400","30.36220","0.02889"
"60806","364.80000","30.40023","0.02935"
"60882","365.25600","30.43826","0.02869"
"60958","365.71200","30.47622","0.02967"
"61034","366.16800","30.51419","0.02960"
"61110","366.62400","30.55215","0.02919"
"61186","367.08000","30.59012","0.02893"
"61262","367.53600","30.62815","0.02931"
"61338","367.99200","30.66617","0.02956"
"61414","368.44800","30.70420","0.02987"
"61490","368.90400","30.74222","0.02983"
"61566","369.36000","30.78019","0.02959"
"61642","369.81600","30.81816","0.03018"
"61718","370.27200","30.85618","0.03025"
"61794","370.72800","30.89421","0.02952"
"61870","371.18400","30.93217","0.02784"
"61946","371.64000","30.97020","0.02840"
"62022","372.09600","31.00817","0.02861"
"62098","372.55200","31.04613","0.02856"
"62174","373.00800","31.08410","0.02914"
"62250","373.46400","31.12213","0.02935"
"62326","373.92000","31.16021","0.02925"
"62402","374.37600","31.19818","0.03002"
"62478","374.83200","31.23627","0.02973"
"62554","375.28800","31.27411","0.03030"
"62630","375.74400","31.31208","0.03025"
"62706","376.20000","31.35016","0.02972"
"62782","376.65600","31.38819","0.03005"
"62858","377.11200","31.42621","0.03063"
"62934","377.56800","31.46418","0.03050"
"63010","378.02400","31.50221","0.02983"
"63086","378.48000","31.54017","0.03009"
"63162","378.93600","31.57820","0.03004"
"63238","379.39200","31.61623","0.03064"
"63314","379.84800","31.65413","0.02986"
"63390","380.30400","31.69222","0.03096"
"63466","380.76000","31.73019","0.03109"
"63542","381.21600","31.76821","0.03085"
"63618","381.67200","31.80612","0.03112"
"63694","382.12800","31.84414","0.03096"
"63770","382.58400","31.88217","0.03088"
"63846","383.04000","31.92014","0.03153"
"63922","383.49600","31.95822","0.03130"
"63998","383.95200","31.99619","0.03154"
"64074","384.40800","32.03416","0.03201"
"64150","384.86400","32.07212","0.03167"
"64226","385.32000","32.11021","0.03183"
"64302","385.77600","32.14817","0.03212"
"64378","386.23200","32.18620","0.03215"
"64454","386.68800","32.22423","0.03267"
"64530","387.14400","32.26219","0.03122"
"64606","387.60000","32.30016","0.03125"
"64682","388.05600","32.33812","0.03041"
"64758","388.51200","32.37615","0.03048"
"64834","388.96800","32.41418","0.03039"
"64910","389.42400","32.45214","0.03135"
"64986","389.88000","32.49023","0.03104"
"65062","390.33600","32.52819","0.03143"
"65138","390.79200","32.56610","0.03140"
"65214","391.24800","32.60413","0.03087"
"65290","391.70400","32.64222","0.03184"
"65366","392.16000","32.68024","0.03222"
"65442","392.61600","32.71815","0.03170"
"65518","393.07200","32.75623","0.03197"
"65594","393.52800","32.79414","0.03141"
"65670","393.98400","32.83216","0.03275"
"65746","394.44000","32.87019","0.03267"
"65822","394.89600","32.90822","0.03238"
"65898","395.35200","32.94619","0.03273"
"65974","395.80800","32.98415","0.03263"
"66050","396.26400","33.02217","0.03334"
"66126","396.72000","33.06015","0.03372"
"66202","397.17600","33.09817","0.03295"
"66278","397.63200","33.13614","0.03343"
"66354","398.08800","33.17422","0.03358"
"66430","398.54400","33.21219","0.03355"
"66506","399.00000","33.25021","0.03365"
"66582","399.45600","33.28818","0.03404"
"66658","399.91200","33.32615","0.03413"
"66734","400.36800","33.36417","0.03362"
"66810","400.82400","33.40214","0.03488"
"66886","401.28000","33.44017","0.03481"
"66962","401.73600","33.47825","0.03496"
"67038","402.19200","33.51616","0.03523"
"67114","402.64800","33.55418","0.03559"
"67190","403.10400","33.59215","0.03572"
"67266","403.56000","33.63018","0.03577"
"67342","404.01600","33.66814","0.03575"
"67418","404.47200","33.70623","0.03621"
"67494","404.92800","33.74426","0.03600"
"67570","405.38400","33.78210","0.03622"
"67646","405.84000","33.82013","0.03645"
"67722","406.29600","33.85815","0.03646"
"67798","406.75200","33.89624","0.03650"
"67874","407.20800","33.93420","0.03661"
"67950","407.66400","33.97223","0.03662"
"68026","408.12000","34.01020","0.03699"
"68102","408.57600","34.04811","0.03740"
"68178","409.03200","34.08613","0.03714"
"68254","409.48800","34.12422","0.03717"
"68330","409.94400","34.16219","0.03681"
"68406","410.40000","34.20021","0.03732"
"68482","410.85600","34.23818","0.03734"
"68558","411.31200","34.27614","0.03759"
"68634","411.76800","34.31411","0.03760"
"68710","412.22400","34.35220","0.03743"
"68786","412.68000","34.39022","0.03760"
"68862","413.13600","34.42819","0.03762"
"68938","413.59200","34.46616","0.03776"
"69014","414.04800","34.50418","0.03756"
"69090","414.50400","34.54215","0.03805"
"69166","414.96000","34.58017","0.03811"
"69242","415.41600","34.61820","0.03845"
"69318","415.87200","34.65623","0.03842"
"69394","416.32800","34.69419","0.03874"
"69470","416.78400","34.73222","0.03867"
"69546","417.24000","34.77018","0.03853"
"69622","417.69600","34.80815","0.03879"
"69698","418.15200","34.84618","0.03906"
"69774","418.60800","34.88414","0.03931"
"69850","419.06400","34.92223","0.03943"
"69926","419.52000","34.96025","0.03942"
"70002","419.97600","34.99822","0.03937"
"70078","420.43200","35.03613","0.03960"
"70154","420.88800","35.07415","0.03985"
"70230","421.34400","35.11218","0.03980"
"70306","421.80000","35.15015","0.03988"
"70382","422.25600","35.18823","0.04017"
"70458","422.71200","35.22626","0.04036"
"70534","423.16800","35.26416","0.04009"
"70610","423.62400","35.30213","0.04053"
"70686","424.08000","35.34010","0.04070"
"70762","424.53600","35.37819","0.04066"
"70838","424.99200","35.41621","0.04056"
"70914","425.44800","35.45418","0.04083"
"70990","425.90400","35.49220","0.04128"
"71066","426.36000","35.53011","0.04079"
"71142","426.81600","35.56814","0.03969"
"71218","427.27200","35.60616","0.03966"
"71294","427.72800","35.64425","0.03992"
"71370","428.18400","35.68221","0.04036"
"71446","428.64000","35.72018","0.04046"
"71522","429.09600","35.75814","0.04046"
"71598","429.55200","35.79611","0.04062"
"71674","430.00800","35.83420","0.04056"
"71750","430.46400","35.87222","0.04086"
"71826","430.92000","35.91019","0.04088"
"71902","431.37600","35.94816","0.04133"
"71978","431.83200","35.98618","0.04146"
"72054","432.28800","36.02421","0.04184"
"72130","432.74400","36.06212","0.04176"
"72206","433.20000","36.10014","0.04187"
"72282","433.65600","36.13823","0.04225"
"72358","434.11200","36.17619","0.04261"
"72434","434.56800","36.21422","0.04277"
"72510","435.02400","36.25219","0.04309"
"72586","435.48000","36.29021","0.04295"
"72662","435.93600","36.32812","0.04331"
"72738","436.39200","36.36615","0.04340"
"72814","436.84800","36.40423","0.04411"
"72890","437.30400","36.44220","0.04407"
"72966","437.76000","36.48022","0.04448"
"73042","438.21600","36.51813","0.04503"
"73118","438.67200","36.55616","0.04491"
"73194","439.12800","36.59412","0.04586"
"73270","439.58400","36.63221","0.04567"
"73346","440.04000","36.67017","0.04674"
"73422","440.49600","36.70826","0.04708"
"73498","440.95200","36.74617","0.04840"
"73574","441.40800","36.78419","0.04885"
"73650","441.86400","36.82216","0.04930"
"73726","442.32000","36.86013","0.04924"
"73802","442.77600","36.89822","0.05060"
"73878","443.23200","36.93624","0.05248"
"73954","443.68800","36.97421","0.05191"
"74030","444.14400","37.01211","0.05254"
"74106","444.60000","37.05014","0.05392"
"74182","445.05600","37.08816","0.05532"
"74258","445.51200","37.12625","0.05527"
"74334","445.96800","37.16416","0.05662"
"74410","446.42400","37.20218","0.05822"
"74486","446.88000","37.24021","0.05863"
"74562","447.33600","37.27811","0.05830"
"74638","447.79200","37.31620","0.05918"
"74714","448.24800","37.35423","0.06075"
"74790","448.70400","37.39220","0.06192"
"74866","449.16000","37.43016","0.06161"
"74942","449.61600","37.46825","0.06220"
"75018","450.07200","37.50615","0.06293"
"75094","450.52800","37.54412","0.03644"
"75170","450.98400","37.58215","0.02542"
"75246","451.44000","37.62023","0.03197"
"75322","451.89600","37.65820","0.02815"
"75398","452.35200","37.69622","0.02856"
"75474","452.80800","37.73413","0.03217"
"75550","453.26400","37.77222","0.02890"
"75626","453.72000","37.81012","0.03066"
"75702","454.17600","37.84821","0.03267"
"75778","454.63200","37.88618","0.03049"
"75854","455.08800","37.92414","0.03154"
"75930","455.54400","37.96223","0.03313"
"76006","456.00000","38.00019","0.03210"
"76082","456.45600","38.03816","0.03308"
"76158","456.91200","38.07613","0.03343"
"76234","457.36800","38.11415","0.03305"
"76310","457.82400","38.15218","0.03341"
"76386","458.28000","38.19020","0.03399"
"76462","458.73600","38.22823","0.03384"
"76538","459.19200","38.26620","0.03410"
"76614","459.64800","38.30410","0.03402"
"76690","460.10400","38.34213","0.03457"
"76766","460.56000","38.38022","0.03441"
"76842","461.01600","38.41824","0.03481"
"76918","461.47200","38.45621","0.03508"
"76994","461.92800","38.49418","0.03482"
"77070","462.38400","38.53214","0.03555"
"77146","462.84000","38.57017","0.03560"
"77222","463.29600","38.60819","0.03488"
"77298","463.75200","38.64622","0.03505"
"77374","464.20800","38.68419","0.03583"
"77450","464.66400","38.72215","0.03596"
"77526","465.12000","38.76018","0.03712"
"77602","465.57600","38.79815","0.03651"
"77678","466.03200","38.83617","0.03549"
"77754","466.48800","38.87414","0.03691"
"77830","466.94400","38.91222","0.03688"
"77906","467.40000","38.95019","0.03698"
"77982","467.85600","38.98816","0.03636"
"78058","468.31200","39.02618","0.03439"
"78134","468.76800","39.06415","0.03563"
"78210","469.22400","39.10217","0.03558"
"78286","469.68000","39.14020","0.03589"
"78362","470.13600","39.17817","0.03644"
"78438","470.59200","39.21619","0.03600"
"78514","471.04800","39.25416","0.02653"
"78590","471.50400","39.29213","0.02509"
"78666","471.96000","39.33015","0.02749"
"78742","472.41600","39.36818","0.02474"
"78818","472.87200","39.40620","0.02744"
"78894","473.32800","39.44423","0.02722"
"78970","473.78400","39.48220","0.02681"
"79046","474.24000","39.52016","0.02771"
"79122","474.69600","39.55819","0.02894"
"79198","475.15200","39.59615","0.02863"
"79274","475.60800","39.63418","0.02925"
"79350","476.06400","39.67221","0.03007"
"79426","476.52000","39.71029","0.02960"
"79502","476.97600","39.74820","0.03061"
"79578","477.43200","39.78610","0.03085"
"79654","477.88800","39.82413","0.03052"
"79730","478.34400","39.86216","0.03092"
"79806","478.80000","39.90025","0.03066"
"79882","479.25600","39.93821","0.03085"
"79958","479.71200","39.97618","0.03186"
"80034","480.16800","40.01414","0.03195"
"80110","480.62400","40.05211","0.03110"
"80186","481.08000","40.09014","0.03153"
"80262","481.53600","40.12822","0.03151"
"80338","481.99200","40.16619","0.03167"
"80414","482.44800","40.20421","0.03250"
"80490","482.90400","40.24218","0.03235"
"80566","483.36000","40.28015","0.03215"
"80642","483.81600","40.31818","0.03207"
"80718","484.27200","40.35626","0.03266"
"80794","484.72800","40.39417","0.03297"
"80870","485.18400","40.43219","0.03270"
"80946","485.64000","40.47021","0.03294"
"81022","486.09600","40.50819","0.03265"
"81098","486.55200","40.54609","0.03335"
"81174","487.00800","40.58418","0.03399"
"81250","487.46400","40.62220","0.03351"
"81326","487.92000","40.66023","0.03375"
"81402","488.37600","40.69820","0.03387"
"81478","488.83200","40.73616","0.03359"
"81554","489.28800","40.77419","0.03445"
"81630","489.74400","40.81216","0.03414"
"81706","490.20000","40.85018","0.03512"
"81782","490.65600","40.88821","0.03466"
"81858","491.11200","40.92617","0.03480"
"81934","491.56800","40.96420","0.03501"
"82010","492.02400","41.00222","0.03438"
"82086","492.48000","41.04013","0.03512"
"82162","492.93600","41.07816","0.03498"
"82238","493.39200","41.11618","0.03477"
"82314","493.84800","41.15421","0.03523"
"82390","494.30400","41.19223","0.03531"
"82466","494.76000","41.23021","0.03545"
"82542","495.21600","41.26811","0.03516"
"82618","495.67200","41.30613","0.03554"
"82694","496.12800","41.34416","0.03499"
"82770","496.58400","41.38224","0.03515"
"82846","497.04000","41.42022","0.03561"
"82922","497.49600","41.45818","0.03512"
"82998","497.95200","41.49615","0.03533"
"83074","498.40800","41.53411","0.03568"
"83150","498.86400","41.57220","0.03619"
"83226","499.32000","41.61023","0.03628"
"83302","499.77600","41.64825","0.03617"
"83378","500.23200","41.68622","0.03540"
"83454","500.68800","41.72419","0.03522"
"83530","501.14400","41.76215","0.03519"
"83606","501.60000","41.80012","0.03561"
"83682","502.05600","41.83821","0.03556"
"83758","502.51200","41.87617","0.03587"
"83834","502.96800","41.91420","0.03579"
"83910","503.42400","41.95222","0.03616"
"83986","503.88000","41.99013","0.03608"
"84062","504.33600","42.02815","0.03597"
"84138","504.79200","42.06618","0.03593"
"84214","505.24800","42.10420","0.03537"
"84290","505.70400","42.14223","0.03552"
"84366","506.16000","42.18014","0.03568"
"84442","506.61600","42.21816","0.03601"
"84518","507.07200","42.25613","0.03565"
"84594","507.52800","42.29416","0.03601"
"84670","507.98400","42.33213","0.03637"
"84746","508.44000","42.37015","0.03612"
"84822","508.89600","42.40818","0.03504"
"84898","509.35200","42.44621","0.03418"
"84974","509.80800","42.48423","0.03424"
"85050","510.26400","42.52214","0.03499"
"85126","510.72000","42.56016","0.03469"
"85202","511.17600","42.59819","0.03470"
"85278","511.63200","42.63621","0.03454"
"85354","512.08800","42.67424","0.03498"
"85430","512.54400","42.71221","0.03536"
"85506","513.00000","42.75011","0.03493"
"85582","513.45600","42.78814","0.03517"
"85658","513.91200","42.82616","0.03521"
"85734","514.36800","42.86419","0.03536"
"85810","514.82400","42.90222","0.03408"
"85886","515.28000","42.94024","0.03427"
"85962","515.73600","42.97815","0.03417"
"86038","516.19200","43.01612","0.03477"
"86114","516.64800","43.05415","0.03523"
"86190","517.10400","43.09217","0.03506"
"86266","517.56000","43.13020","0.03507"
"86342","518.01600","43.16822","0.03477"
"86418","518.47200","43.20618","0.03586"
"86494","518.92800","43.24422","0.03580"
"86570","519.38400","43.28212","0.03638"
"86646","519.84000","43.32021","0.03594"
"86722","520.29600","43.35823","0.03631"
"86798","520.75200","43.39620","0.03659"
"86874","521.20800","43.43417","0.03671"
"86950","521.66400","43.47219","0.03659"
"87026","522.12000","43.51016","0.03677"
"87102","522.57600","43.54818","0.03624"
"87178","523.03200","43.58621","0.03632"
"87254","523.48800","43.62423","0.03637"
"87330","523.94400","43.66220","0.03552"
"87406","524.40000","43.70023","0.03623"
"87482","524.85600","43.73813","0.03557"
"87558","525.31200","43.77616","0.03608"
"87634","525.76800","43.81413","0.03648"
"87710","526.22400","43.85221","0.03612"
"87786","526.68000","43.89018","0.03575"
"87862","527.13600","43.92821","0.03600"
"87938","527.59200","43.96618","0.03661"
"88014","528.04800","44.00420","0.03644"
"88090","528.50400","44.04210","0.03585"
"88166","528.96000","44.08014","0.03663"
"88242","529.41600","44.11816","0.03643"
"88318","529.87200","44.15624","0.03677"
"88394","530.32800","44.19421","0.03692"
"88470","530.78400","44.23218","0.03760"
"88546","531.24000","44.27014","0.03690"
"88622","531.69600","44.30817","0.03744"
"88698","532.15200","44.34620","0.03688"
"88774","532.60800","44.38422","0.03696"
"88850","533.06400","44.42225","0.03769"
"88926","533.52000","44.46015","0.03776"
"89002","533.97600","44.49812","0.03799"
"89078","534.43200","44.53615","0.03768"
"89154","534.88800","44.57418","0.03640"
"89230","535.34400","44.61220","0.03550"
"89306","535.80000","44.65023","0.03629"
"89382","536.25600","44.68819","0.03712"
"89458","536.71200","44.72622","0.03739"
"89534","537.16800","44.76412","0.03655"
"89610","537.62400","44.80215","0.03705"
"89686","538.08000","44.84024","0.03725"
"89762","538.53600","44.87820","0.03704"
"89838","538.99200","44.91623","0.03804"
"89914","539.44800","44.95420","0.03756"
"89990","539.90400","44.99216","0.03769"
"90066","540.36000","45.03012","0.03817"
"90142","540.81600","45.06821","0.03834"
"90218","541.27200","45.10612","0.03817"
"90294","541.72800","45.14415","0.03758"
"90370","542.18400","45.18224","0.03825"
"90446","542.64000","45.22014","0.03848"
"90522","543.09600","45.25816","0.03835"
"90598","543.55200","45.29613","0.03860"
"90674","544.00800","45.33416","0.03879"
"90750","544.46400","45.37218","0.03859"
"90826","544.92000","45.41015","0.03790"
"90902","545.37600","45.44823","0.03725"
"90978","545.83200","45.48621","0.03714"
"91054","546.28800","45.52411","0.03669"
"91130","546.74400","45.56213","0.03707"
"91206","547.20000","45.60017","0.03717"
"91282","547.65600","45.63825","0.03743"
"91358","548.11200","45.67622","0.03751"
"91434","548.56800","45.71424","0.03776"
"91510","549.02400","45.75215","0.03738"
"91586","549.48000","45.79017","0.03738"
"91662","549.93600","45.82814","0.03736"
"91738","550.39200","45.86623","0.03719"
"91814","550.84800","45.90419","0.03766"
"91890","551.30400","45.94222","0.03570"
"91966","551.76000","45.98018","0.03464"
"92042","552.21600","46.01809","0.03377"
"92118","552.67200","46.05618","0.03458"
"92194","553.12800","46.09420","0.03485"
"92270","553.58400","46.13217","0.03577"
"92346","554.04000","46.17020","0.03522"
"92422","554.49600","46.20822","0.03554"
"92498","554.95200","46.24613","0.03601"
"92574","555.40800","46.28415","0.03609"
"92650","555.86400","46.32218","0.03600"
"92726","556.32000","46.36020","0.03622"
"92802","556.77600","46.39817","0.03621"
"92878","557.23200","46.43620","0.03622"
"92954","557.68800","46.47417","0.03651"
"93030","558.14400","46.51213","0.03677"
"93106","558.60000","46.55016","0.03634"
"93182","559.05600","46.58818","0.03645"
"93258","559.51200","46.62615","0.03734"
"93334","559.96800","46.66418","0.03675"
"93410","560.42400","46.70220","0.03670"
"93486","560.88000","46.74017","0.03688"
"93558","561.30800","46.77587","0.03709"