File: Trajectories_together/170108_2Specimen_RawData_7.csv
"","V1","V2","V3"
"1","End date","1/8/2017",""
"2","Specimen label","9BT_74",""
"3","Maximum Load","0.29177","N"
"4","Time","Extension","Load"
"5","(s)","(mm)","(N)"
"6","0.00000","0.00000","-0.00173"
"35","0.17400","0.00993","-0.00094"
"64","0.34800","0.02882","0.00014"
"93","0.52200","0.04377","0.00096"
"122","0.69600","0.05818","0.00192"
"151","0.87000","0.07276","0.00222"
"180","1.04400","0.08717","0.00272"
"209","1.21800","0.10170","0.00299"
"238","1.39200","0.11623","0.00292"
"267","1.56600","0.13070","0.00390"
"296","1.74000","0.14517","0.00330"
"325","1.91400","0.15970","0.00374"
"354","2.08800","0.17417","0.00379"
"383","2.26200","0.18870","0.00412"
"412","2.43600","0.20316","0.00418"
"441","2.61000","0.21769","0.00492"
"470","2.78400","0.23216","0.00490"
"499","2.95800","0.24675","0.00478"
"528","3.13200","0.26122","0.00492"
"557","3.30600","0.27563","0.00481"
"586","3.48000","0.29022","0.00521"
"615","3.65400","0.30469","0.00539"
"644","3.82800","0.31916","0.00549"
"673","4.00200","0.33369","0.00485"
"702","4.17600","0.34821","0.00577"
"731","4.35000","0.36262","0.00550"
"760","4.52400","0.37715","0.00525"
"789","4.69800","0.39168","0.00543"
"818","4.87200","0.40615","0.00573"
"847","5.04600","0.42068","0.00600"
"876","5.22000","0.43521","0.00590"
"905","5.39400","0.44968","0.00588"
"934","5.56800","0.46421","0.00559"
"963","5.74200","0.47873","0.00576"
"992","5.91600","0.49314","0.00606"
"1021","6.09000","0.50767","0.00591"
"1050","6.26400","0.52220","0.00606"
"1079","6.43800","0.53667","0.00628"
"1108","6.61200","0.55120","0.00592"
"1137","6.78600","0.56567","0.00668"
"1166","6.96000","0.58014","0.00622"
"1195","7.13400","0.59467","0.00643"
"1224","7.30800","0.60920","0.00616"
"1253","7.48200","0.62366","0.00647"
"1282","7.65600","0.63813","0.00662"
"1311","7.83000","0.65266","0.00644"
"1340","8.00400","0.66719","0.00631"
"1369","8.17800","0.68166","0.00670"
"1398","8.35200","0.69619","0.00667"
"1427","8.52600","0.71066","0.00700"
"1456","8.70000","0.72513","0.00728"
"1485","8.87400","0.73972","0.00724"
"1514","9.04800","0.75413","0.00690"
"1543","9.22200","0.76865","0.00688"
"1572","9.39600","0.78318","0.00692"
"1601","9.57000","0.79771","0.00706"
"1630","9.74400","0.81218","0.00671"
"1659","9.91800","0.82671","0.00711"
"1688","10.09200","0.84118","0.00744"
"1717","10.26600","0.85565","0.00771"
"1746","10.44000","0.87024","0.00739"
"1775","10.61400","0.88471","0.00718"
"1804","10.78800","0.89917","0.00737"
"1833","10.96200","0.91370","0.00730"
"1862","11.13600","0.92823","0.00750"
"1891","11.31000","0.94270","0.00743"
"1920","11.48400","0.95717","0.00745"
"1949","11.65800","0.97176","0.00777"
"1978","11.83200","0.98617","0.00844"
"2007","12.00600","1.00070","0.00767"
"2036","12.18000","1.01523","0.00792"
"2065","12.35400","1.02970","0.00780"
"2094","12.52800","1.04416","0.00769"
"2123","12.70200","1.05875","0.00819"
"2152","12.87600","1.07316","0.00802"
"2181","13.05000","1.08763","0.00814"
"2210","13.22400","1.10222","0.00820"
"2239","13.39800","1.11669","0.00816"
"2268","13.57200","1.13116","0.00830"
"2297","13.74600","1.14575","0.00828"
"2326","13.92000","1.16016","0.00816"
"2355","14.09400","1.17463","0.00882"
"2384","14.26800","1.18915","0.00793"
"2413","14.44200","1.20368","0.00868"
"2442","14.61600","1.21821","0.00834"
"2471","14.79000","1.23268","0.00834"
"2500","14.96400","1.24715","0.00869"
"2529","15.13800","1.26156","0.00874"
"2558","15.31200","1.27627","0.00867"
"2587","15.48600","1.29074","0.00885"
"2616","15.66000","1.30515","0.00889"
"2645","15.83400","1.31973","0.00888"
"2674","16.00800","1.33420","0.00922"
"2703","16.18200","1.34867","0.00911"
"2732","16.35600","1.36320","0.00908"
"2761","16.53000","1.37767","0.00887"
"2790","16.70400","1.39214","0.00916"
"2819","16.87800","1.40673","0.00913"
"2848","17.05200","1.42120","0.00910"
"2877","17.22600","1.43567","0.00886"
"2906","17.40000","1.45020","0.00917"
"2935","17.57400","1.46466","0.00910"
"2964","17.74800","1.47919","0.00902"
"2993","17.92200","1.49372","0.00915"
"3022","18.09600","1.50819","0.00981"
"3051","18.27000","1.52266","0.00974"
"3080","18.44400","1.53719","0.00969"
"3109","18.61800","1.55172","0.00949"
"3138","18.79200","1.56619","0.00946"
"3167","18.96600","1.58066","0.00933"
"3196","19.14000","1.59518","0.00970"
"3225","19.31400","1.60965","0.00960"
"3254","19.48800","1.62418","0.00985"
"3283","19.66200","1.63871","0.00986"
"3312","19.83600","1.65318","0.00987"
"3341","20.01000","1.66765","0.00992"
"3370","20.18400","1.68224","0.00966"
"3399","20.35800","1.69671","0.00954"
"3428","20.53200","1.71112","0.01015"
"3457","20.70600","1.72571","0.01013"
"3486","20.88000","1.74017","0.00985"
"3515","21.05400","1.75464","0.01036"
"3544","21.22800","1.76923","0.01069"
"3573","21.40200","1.78370","0.01054"
"3602","21.57600","1.79811","0.01020"
"3631","21.75000","1.81270","0.01053"
"3660","21.92400","1.82723","0.01018"
"3689","22.09800","1.84164","0.01063"
"3718","22.27200","1.85617","0.01012"
"3747","22.44600","1.87069","0.01061"
"3776","22.62000","1.88516","0.01103"
"3805","22.79400","1.89969","0.01069"
"3834","22.96800","1.91422","0.01079"
"3863","23.14200","1.92863","0.01043"
"3892","23.31600","1.94322","0.01069"
"3921","23.49000","1.95775","0.01050"
"3950","23.66400","1.97216","0.01082"
"3979","23.83800","1.98669","0.01039"
"4008","24.01200","2.00122","0.01117"
"4037","24.18600","2.01568","0.01106"
"4066","24.36000","2.03015","0.01133"
"4095","24.53400","2.04468","0.01110"
"4124","24.70800","2.05915","0.01129"
"4153","24.88200","2.07368","0.01093"
"4182","25.05600","2.08821","0.01109"
"4211","25.23000","2.10268","0.01094"
"4240","25.40400","2.11721","0.01111"
"4269","25.57800","2.13168","0.01076"
"4298","25.75200","2.14615","0.01109"
"4327","25.92600","2.16067","0.01118"
"4356","26.10000","2.17526","0.01133"
"4385","26.27400","2.18967","0.01166"
"4414","26.44800","2.20414","0.01175"
"4443","26.62200","2.21873","0.01137"
"4472","26.79600","2.23326","0.01144"
"4501","26.97000","2.24767","0.01145"
"4530","27.14400","2.26220","0.01143"
"4559","27.31800","2.27667","0.01147"
"4588","27.49200","2.29114","0.01100"
"4617","27.66600","2.30578","0.01116"
"4646","27.84000","2.32019","0.01199"
"4675","28.01400","2.33460","0.01131"
"4704","28.18800","2.34919","0.01161"
"4733","28.36200","2.36372","0.01162"
"4762","28.53600","2.37813","0.01168"
"4791","28.71000","2.39272","0.01147"
"4820","28.88400","2.40725","0.01190"
"4849","29.05800","2.42166","0.01196"
"4878","29.23200","2.43618","0.01165"
"4907","29.40600","2.45071","0.01149"
"4936","29.58000","2.46518","0.01221"
"4965","29.75400","2.47965","0.01146"
"4994","29.92800","2.49418","0.01204"
"5023","30.10200","2.50865","0.01233"
"5052","30.27600","2.52318","0.01189"
"5081","30.45000","2.53771","0.01225"
"5110","30.62400","2.55212","0.01218"
"5139","30.79800","2.56670","0.01193"
"5168","30.97200","2.58123","0.01179"
"5197","31.14600","2.59564","0.01195"
"5226","31.32000","2.61011","0.01241"
"5255","31.49400","2.62470","0.01161"
"5284","31.66800","2.63923","0.01196"
"5313","31.84200","2.65370","0.01219"
"5342","32.01600","2.66817","0.01258"
"5371","32.19000","2.68264","0.01265"
"5400","32.36400","2.69711","0.01195"
"5429","32.53800","2.71175","0.01211"
"5458","32.71200","2.72616","0.01240"
"5487","32.88600","2.74063","0.01222"
"5516","33.06000","2.75522","0.01223"
"5545","33.23400","2.76969","0.01231"
"5574","33.40800","2.78422","0.01187"
"5603","33.58200","2.79875","0.01068"
"5632","33.75600","2.81322","0.01180"
"5661","33.93000","2.82763","0.01166"
"5690","34.10400","2.84222","0.01174"
"5719","34.27800","2.85668","0.01176"
"5748","34.45200","2.87115","0.01142"
"5777","34.62600","2.88568","0.01152"
"5806","34.80000","2.90021","0.01214"
"5835","34.97400","2.91468","0.01201"
"5864","35.14800","2.92921","0.01127"
"5893","35.32200","2.94374","0.01101"
"5922","35.49600","2.95815","0.01074"
"5951","35.67000","2.97274","0.01094"
"5980","35.84400","2.98720","0.01085"
"6009","36.01800","3.00167","0.01132"
"6038","36.19200","3.01614","0.01134"
"6067","36.36600","3.03067","0.01126"
"6096","36.54000","3.04514","0.01119"
"6125","36.71400","3.05967","0.01171"
"6154","36.88800","3.07420","0.01102"
"6183","37.06200","3.08867","0.01182"
"6212","37.23600","3.10314","0.01167"
"6241","37.41000","3.11773","0.01151"
"6270","37.58400","3.13225","0.01159"
"6299","37.75800","3.14660","0.01160"
"6328","37.93200","3.16119","0.01210"
"6357","38.10600","3.17572","0.01215"
"6386","38.28000","3.19019","0.01132"
"6415","38.45400","3.20472","0.01139"
"6444","38.62800","3.21919","0.01095"
"6473","38.80200","3.23360","0.01114"
"6502","38.97600","3.24819","0.01092"
"6531","39.15000","3.26271","0.01109"
"6560","39.32400","3.27712","0.01128"
"6589","39.49800","3.29171","0.01130"
"6618","39.67200","3.30618","0.01149"
"6647","39.84600","3.32065","0.01211"
"6676","40.02000","3.33518","0.01168"
"6705","40.19400","3.34971","0.01121"
"6734","40.36800","3.36418","0.01171"
"6763","40.54200","3.37871","0.01187"
"6792","40.71600","3.39324","0.01164"
"6821","40.89000","3.40764","0.01192"
"6850","41.06400","3.42217","0.01282"
"6879","41.23800","3.43670","0.01253"
"6908","41.41200","3.45117","0.01265"
"6937","41.58600","3.46570","0.01242"
"6966","41.76000","3.48017","0.01229"
"6995","41.93400","3.49470","0.01184"
"7024","42.10800","3.50917","0.01250"
"7053","42.28200","3.52370","0.01216"
"7082","42.45600","3.53822","0.01256"
"7111","42.63000","3.55263","0.01224"
"7140","42.80400","3.56722","0.01237"
"7169","42.97800","3.58163","0.01243"
"7198","43.15200","3.59616","0.01237"
"7227","43.32600","3.61075","0.01273"
"7256","43.50000","3.62516","0.01248"
"7285","43.67400","3.63963","0.01259"
"7314","43.84800","3.65422","0.01305"
"7343","44.02200","3.66869","0.01273"
"7372","44.19600","3.68315","0.01262"
"7401","44.37000","3.69774","0.01271"
"7430","44.54400","3.71221","0.01289"
"7459","44.71800","3.72662","0.01273"
"7488","44.89200","3.74127","0.01292"
"7517","45.06600","3.75568","0.01246"
"7546","45.24000","3.77009","0.01333"
"7575","45.41400","3.78468","0.01282"
"7604","45.58800","3.79921","0.01274"
"7633","45.76200","3.81368","0.01261"
"7662","45.93600","3.82820","0.01268"
"7691","46.11000","3.84273","0.01258"
"7720","46.28400","3.85714","0.01295"
"7749","46.45800","3.87173","0.01273"
"7778","46.63200","3.88620","0.01283"
"7807","46.80600","3.90067","0.01325"
"7836","46.98000","3.91514","0.01324"
"7865","47.15400","3.92973","0.01281"
"7894","47.32800","3.94420","0.01352"
"7923","47.50200","3.95866","0.01344"
"7952","47.67600","3.97319","0.01323"
"7981","47.85000","3.98766","0.01324"
"8010","48.02400","4.00219","0.01386"
"8039","48.19800","4.01672","0.01316"
"8068","48.37200","4.03119","0.01325"
"8097","48.54600","4.04566","0.01340"
"8126","48.72000","4.06019","0.01207"
"8155","48.89400","4.07472","0.01261"
"8184","49.06800","4.08919","0.01248"
"8213","49.24200","4.10365","0.01195"
"8242","49.41600","4.11818","0.01196"
"8271","49.59000","4.13265","0.01252"
"8300","49.76400","4.14718","0.01173"
"8329","49.93800","4.16171","0.01216"
"8358","50.11200","4.17612","0.01195"
"8387","50.28600","4.19071","0.01170"
"8416","50.46000","4.20524","0.01193"
"8445","50.63400","4.21971","0.01236"
"8474","50.80800","4.23423","0.01214"
"8503","50.98200","4.24864","0.01287"
"8532","51.15600","4.26311","0.01259"
"8561","51.33000","4.27776","0.01249"
"8590","51.50400","4.29217","0.01235"
"8619","51.67800","4.30664","0.01268"
"8648","51.85200","4.32117","0.01306"
"8677","52.02600","4.33570","0.01319"
"8706","52.20000","4.35017","0.01302"
"8735","52.37400","4.36470","0.01317"
"8764","52.54800","4.37922","0.01330"
"8793","52.72200","4.39363","0.01298"
"8822","52.89600","4.40822","0.01308"
"8851","53.07000","4.42269","0.01296"
"8880","53.24400","4.43716","0.01246"
"8909","53.41800","4.45169","0.01267"
"8938","53.59200","4.46622","0.01283"
"8967","53.76600","4.48069","0.01279"
"8996","53.94000","4.49516","0.01264"
"9025","54.11400","4.50969","0.01311"
"9054","54.28800","4.52415","0.01306"
"9083","54.46200","4.53868","0.01320"
"9112","54.63600","4.55327","0.01394"
"9141","54.81000","4.56768","0.01372"
"9170","54.98400","4.58209","0.01360"
"9199","55.15800","4.59674","0.01362"
"9228","55.33200","4.61121","0.01387"
"9257","55.50600","4.62568","0.01419"
"9286","55.68000","4.64021","0.01382"
"9315","55.85400","4.65468","0.01405"
"9344","56.02800","4.66914","0.01394"
"9373","56.20200","4.68373","0.01404"
"9402","56.37600","4.69826","0.01374"
"9431","56.55000","4.71261","0.01436"
"9460","56.72400","4.72720","0.01392"
"9489","56.89800","4.74173","0.01373"
"9518","57.07200","4.75614","0.01402"
"9547","57.24600","4.77067","0.01454"
"9576","57.42000","4.78526","0.01477"
"9605","57.59400","4.79966","0.01468"
"9634","57.76800","4.81419","0.01464"
"9663","57.94200","4.82872","0.01464"
"9692","58.11600","4.84313","0.01498"
"9721","58.29000","4.85766","0.01452"
"9750","58.46400","4.87219","0.01489"
"9779","58.63800","4.88666","0.01468"
"9808","58.81200","4.90125","0.01523"
"9837","58.98600","4.91572","0.01533"
"9866","59.16000","4.93018","0.01487"
"9895","59.33400","4.94465","0.01525"
"9924","59.50800","4.95924","0.01559"
"9953","59.68200","4.97365","0.01558"
"9982","59.85600","4.98812","0.01537"
"10011","60.03000","5.00265","0.01603"
"10040","60.20400","5.01718","0.01603"
"10069","60.37800","5.03171","0.01591"
"10098","60.55200","5.04618","0.01589"
"10127","60.72600","5.06065","0.01556"
"10156","60.90000","5.07511","0.01548"
"10185","61.07400","5.08970","0.01585"
"10214","61.24800","5.10417","0.01528"
"10243","61.42200","5.11864","0.01651"
"10272","61.59600","5.13323","0.01593"
"10301","61.77000","5.14770","0.01616"
"10330","61.94400","5.16217","0.01662"
"10359","62.11800","5.17676","0.01675"
"10388","62.29200","5.19123","0.01667"
"10417","62.46600","5.20558","0.01748"
"10446","62.64000","5.22016","0.01665"
"10475","62.81400","5.23475","0.01697"
"10504","62.98800","5.24916","0.01700"
"10533","63.16200","5.26375","0.01748"
"10562","63.33600","5.27816","0.01703"
"10591","63.51000","5.29269","0.01788"
"10620","63.68400","5.30722","0.01796"
"10649","63.85800","5.32169","0.01833"
"10678","64.03200","5.33616","0.01717"
"10707","64.20600","5.35063","0.01779"
"10736","64.38000","5.36521","0.01774"
"10765","64.55400","5.37962","0.01779"
"10794","64.72800","5.39415","0.01821"
"10823","64.90200","5.40874","0.01818"
"10852","65.07600","5.42315","0.01798"
"10881","65.25000","5.43762","0.01900"
"10910","65.42400","5.45215","0.01909"
"10939","65.59800","5.46668","0.01839"
"10968","65.77200","5.48115","0.01846"
"10997","65.94600","5.49573","0.01966"
"11026","66.12000","5.51020","0.01895"
"11055","66.29400","5.52467","0.01908"
"11084","66.46800","5.53920","0.01909"
"11113","66.64200","5.55367","0.01956"
"11142","66.81600","5.56814","0.01944"
"11171","66.99000","5.58273","0.02014"
"11200","67.16400","5.59720","0.01986"
"11229","67.33800","5.61161","0.02019"
"11258","67.51200","5.62619","0.01990"
"11287","67.68600","5.64072","0.02098"
"11316","67.86000","5.65519","0.02059"
"11345","68.03400","5.66972","0.02100"
"11374","68.20800","5.68419","0.02122"
"11403","68.38200","5.69866","0.02148"
"11432","68.55600","5.71319","0.02133"
"11461","68.73000","5.72772","0.02152"
"11490","68.90400","5.74213","0.02155"
"11519","69.07800","5.75672","0.02180"
"11548","69.25200","5.77118","0.02232"
"11577","69.42600","5.78565","0.02218"
"11606","69.60000","5.80018","0.02193"
"11635","69.77400","5.81471","0.02186"
"11664","69.94800","5.82912","0.02220"
"11693","70.12200","5.84371","0.02308"
"11722","70.29600","5.85824","0.02258"
"11751","70.47000","5.87265","0.02331"
"11780","70.64400","5.88718","0.02214"
"11809","70.81800","5.90170","0.02275"
"11838","70.99200","5.91617","0.02236"
"11867","71.16600","5.93070","0.02282"
"11896","71.34000","5.94517","0.02260"
"11925","71.51400","5.95970","0.02315"
"11954","71.68800","5.97417","0.02344"
"11983","71.86200","5.98876","0.02300"
"12012","72.03600","6.00323","0.02308"
"12041","72.21000","6.01758","0.02351"
"12070","72.38400","6.03223","0.02361"
"12099","72.55800","6.04670","0.02379"
"12128","72.73200","6.06110","0.02392"
"12157","72.90600","6.07575","0.02424"
"12186","73.08000","6.09016","0.02496"
"12215","73.25400","6.10457","0.02470"
"12244","73.42800","6.11922","0.02520"
"12273","73.60200","6.13375","0.02516"
"12302","73.77600","6.14810","0.02548"
"12331","73.95000","6.16269","0.02566"
"12360","74.12400","6.17722","0.02569"
"12389","74.29800","6.19168","0.02552"
"12418","74.47200","6.20621","0.02630"
"12447","74.64600","6.22074","0.02644"
"12476","74.82000","6.23515","0.02653"
"12505","74.99400","6.24968","0.02683"
"12534","75.16800","6.26421","0.02641"
"12563","75.34200","6.27862","0.02645"
"12592","75.51600","6.29315","0.02702"
"12621","75.69000","6.30768","0.02716"
"12650","75.86400","6.32220","0.02688"
"12679","76.03800","6.33673","0.02727"
"12708","76.21200","6.35120","0.02716"
"12737","76.38600","6.36567","0.02765"
"12766","76.56000","6.38020","0.02770"
"12795","76.73400","6.39473","0.02799"
"12824","76.90800","6.40920","0.02819"
"12853","77.08200","6.42367","0.02809"
"12882","77.25600","6.43820","0.02864"
"12911","77.43000","6.45267","0.02852"
"12940","77.60400","6.46719","0.02841"
"12969","77.77800","6.48172","0.02869"
"12998","77.95200","6.49619","0.02882"
"13027","78.12600","6.51066","0.02900"
"13056","78.30000","6.52519","0.02917"
"13085","78.47400","6.53966","0.02924"
"13114","78.64800","6.55413","0.02925"
"13143","78.82200","6.56866","0.02976"
"13172","78.99600","6.58319","0.02980"
"13201","79.17000","6.59766","0.02990"
"13230","79.34400","6.61224","0.03005"
"13259","79.51800","6.62671","0.03025"
"13288","79.69200","6.64106","0.03034"
"13317","79.86600","6.65571","0.03037"
"13346","80.04000","6.67024","0.03063"
"13375","80.21400","6.68459","0.03046"
"13404","80.38800","6.69924","0.03078"
"13433","80.56200","6.71371","0.03080"
"13462","80.73600","6.72818","0.03084"
"13491","80.91000","6.74271","0.03110"
"13520","81.08400","6.75717","0.03119"
"13549","81.25800","6.77164","0.03153"
"13578","81.43200","6.78617","0.03168"
"13607","81.60600","6.80070","0.03214"
"13636","81.78000","6.81511","0.03224"
"13665","81.95400","6.82970","0.03269"
"13694","82.12800","6.84423","0.03268"
"13723","82.30200","6.85870","0.03309"
"13752","82.47600","6.87323","0.03308"
"13781","82.65000","6.88769","0.03329"
"13810","82.82400","6.90216","0.03365"
"13839","82.99800","6.91663","0.03424"
"13868","83.17200","6.93122","0.03460"
"13897","83.34600","6.94575","0.03555"
"13926","83.52000","6.96016","0.03409"
"13955","83.69400","6.97463","0.03511"
"13984","83.86800","6.98916","0.03502"
"14013","84.04200","7.00369","0.03641"
"14042","84.21600","7.01822","0.03693"
"14071","84.39000","7.03268","0.03696"
"14100","84.56400","7.04715","0.03836"
"14129","84.73800","7.06168","0.03824"
"14158","84.91200","7.07621","0.03923"
"14187","85.08600","7.09068","0.03969"
"14216","85.26000","7.10521","0.04082"
"14245","85.43400","7.11968","0.04101"
"14274","85.60800","7.13415","0.04260"
"14303","85.78200","7.14874","0.04302"
"14332","85.95600","7.16314","0.04385"
"14361","86.13000","7.17761","0.04474"
"14390","86.30400","7.19220","0.04507"
"14419","86.47800","7.20667","0.04543"
"14448","86.65200","7.22120","0.04770"
"14477","86.82600","7.23567","0.04823"
"14506","87.00000","7.25020","0.04809"
"14535","87.17400","7.26461","0.04958"
"14564","87.34800","7.27926","0.04989"
"14593","87.52200","7.29379","0.05002"
"14622","87.69600","7.30814","0.05118"
"14651","87.87000","7.32272","0.05191"
"14680","88.04400","7.33719","0.05276"
"14709","88.21800","7.35166","0.05321"
"14738","88.39200","7.36619","0.05363"
"14767","88.56600","7.38072","0.05386"
"14796","88.74000","7.39519","0.05504"
"14825","88.91400","7.40966","0.05565"
"14854","89.08800","7.42425","0.05619"
"14883","89.26200","7.43865","0.05695"
"14912","89.43600","7.45312","0.05750"
"14941","89.61000","7.46771","0.05851"
"14970","89.78400","7.48218","0.05858"
"14999","89.95800","7.49665","0.05907"
"15028","90.13200","7.51118","0.05967"
"15057","90.30600","7.52565","0.06026"
"15086","90.48000","7.54012","0.06090"
"15115","90.65400","7.55477","0.06128"
"15144","90.82800","7.56924","0.06216"
"15173","91.00200","7.58365","0.06298"
"15202","91.17600","7.59817","0.06340"
"15231","91.35000","7.61270","0.06463"
"15260","91.52400","7.62717","0.06511"
"15289","91.69800","7.64170","0.06527"
"15318","91.87200","7.65623","0.06629"
"15347","92.04600","7.67064","0.06668"
"15376","92.22000","7.68523","0.06730"
"15405","92.39400","7.69970","0.06754"
"15434","92.56800","7.71417","0.06795"
"15463","92.74200","7.72869","0.06789"
"15492","92.91600","7.74316","0.06879"
"15521","93.09000","7.75769","0.06947"
"15550","93.26400","7.77216","0.06942"
"15579","93.43800","7.78669","0.07072"
"15608","93.61200","7.80116","0.07140"
"15637","93.78600","7.81569","0.07148"
"15666","93.96000","7.83016","0.07219"
"15695","94.13400","7.84469","0.07293"
"15724","94.30800","7.85921","0.07276"
"15753","94.48200","7.87368","0.07344"
"15782","94.65600","7.88821","0.07397"
"15811","94.83000","7.90268","0.07430"
"15840","95.00400","7.91721","0.07489"
"15869","95.17800","7.93162","0.07493"
"15898","95.35200","7.94615","0.07518"
"15927","95.52600","7.96074","0.07562"
"15956","95.70000","7.97521","0.07584"
"15985","95.87400","7.98967","0.07616"
"16014","96.04800","8.00414","0.07639"
"16043","96.22200","8.01867","0.07651"
"16072","96.39600","8.03314","0.07663"
"16101","96.57000","8.04773","0.07717"
"16130","96.74400","8.06214","0.07708"
"16159","96.91800","8.07661","0.07748"
"16188","97.09200","8.09120","0.07762"
"16217","97.26600","8.10573","0.07781"
"16246","97.44000","8.12014","0.07827"
"16275","97.61400","8.13472","0.07848"
"16304","97.78800","8.14919","0.07858"
"16333","97.96200","8.16366","0.07899"
"16362","98.13600","8.17825","0.07905"
"16391","98.31000","8.19266","0.07955"
"16420","98.48400","8.20713","0.07952"
"16449","98.65800","8.22166","0.08012"
"16478","98.83200","8.23625","0.08084"
"16507","99.00600","8.25066","0.08064"
"16536","99.18000","8.26513","0.08152"
"16565","99.35400","8.27971","0.08167"
"16594","99.52800","8.29412","0.08294"
"16623","99.70200","8.30871","0.08353"
"16652","99.87600","8.32324","0.08411"
"16681","100.05000","8.33765","0.08536"
"16710","100.22400","8.35212","0.08527"
"16739","100.39800","8.36677","0.08651"
"16768","100.57200","8.38118","0.08714"
"16797","100.74600","8.39565","0.08776"
"16826","100.92000","8.41018","0.08971"
"16855","101.09400","8.42470","0.09127"
"16884","101.26800","8.43911","0.09122"
"16913","101.44200","8.45370","0.09288"
"16942","101.61600","8.46823","0.09454"
"16971","101.79000","8.48264","0.09576"
"17000","101.96400","8.49723","0.09785"
"17029","102.13800","8.51176","0.09931"
"17058","102.31200","8.52617","0.09981"
"17087","102.48600","8.54070","0.10137"
"17116","102.66000","8.55522","0.10296"
"17145","102.83400","8.56963","0.10431"
"17174","103.00800","8.58422","0.10577"
"17203","103.18200","8.59869","0.10714"
"17232","103.35600","8.61310","0.10860"
"17261","103.53000","8.62769","0.10973"
"17290","103.70400","8.64222","0.11106"
"17319","103.87800","8.65669","0.11353"
"17348","104.05200","8.67116","0.11430"
"17377","104.22600","8.68569","0.11505"
"17406","104.40000","8.70009","0.11699"
"17435","104.57400","8.71474","0.11937"
"17464","104.74800","8.72921","0.12021"
"17493","104.92200","8.74368","0.12182"
"17522","105.09600","8.75821","0.12405"
"17551","105.27000","8.77268","0.12534"
"17580","105.44400","8.78715","0.12671"
"17609","105.61800","8.80168","0.12806"
"17638","105.79200","8.81615","0.12889"
"17667","105.96600","8.83068","0.13019"
"17696","106.14000","8.84520","0.13101"
"17725","106.31400","8.85973","0.13230"
"17754","106.48800","8.87420","0.13192"
"17783","106.66200","8.88867","0.12339"
"17812","106.83600","8.90320","0.12552"
"17841","107.01000","8.91773","0.12745"
"17870","107.18400","8.93220","0.12959"
"17899","107.35800","8.94673","0.13082"
"17928","107.53200","8.96114","0.13259"
"17957","107.70600","8.97566","0.13281"
"17986","107.88000","8.99025","0.13429"
"18015","108.05400","9.00466","0.13454"
"18044","108.22800","9.01913","0.13537"
"18073","108.40200","9.03366","0.13599"
"18102","108.57600","9.04819","0.11169"
"18131","108.75000","9.06266","0.07611"
"18160","108.92400","9.07719","0.07668"
"18189","109.09800","9.09172","0.07717"
"18218","109.27200","9.10613","0.07743"
"18247","109.44600","9.12071","0.07830"
"18276","109.62000","9.13524","0.07851"
"18305","109.79400","9.14965","0.07852"
"18334","109.96800","9.16418","0.07938"
"18363","110.14200","9.17871","0.07960"
"18392","110.31600","9.19318","0.08043"
"18421","110.49000","9.20765","0.08082"
"18450","110.66400","9.22218","0.08117"
"18479","110.83800","9.23665","0.08308"
"18508","111.01200","9.25117","0.08290"
"18537","111.18600","9.26576","0.08533"
"18566","111.36000","9.28017","0.08657"
"18595","111.53400","9.29464","0.08776"
"18624","111.70800","9.30917","0.08942"
"18653","111.88200","9.32370","0.09013"
"18682","112.05600","9.33823","0.09311"
"18711","112.23000","9.35270","0.09398"
"18740","112.40400","9.36717","0.09539"
"18769","112.57800","9.38170","0.09866"
"18798","112.75200","9.39622","0.09888"
"18827","112.92600","9.41069","0.10132"
"18856","113.10000","9.42516","0.10214"
"18885","113.27400","9.43969","0.10424"
"18914","113.44800","9.45422","0.10617"
"18943","113.62200","9.46869","0.10625"
"18972","113.79600","9.48322","0.10870"
"19001","113.97000","9.49769","0.10831"
"19030","114.14400","9.51210","0.06095"
"19059","114.31800","9.52674","0.06346"
"19088","114.49200","9.54121","0.06157"
"19117","114.66600","9.55562","0.06448"
"19146","114.84000","9.57021","0.06305"
"19175","115.01400","9.58468","0.06402"
"19204","115.18800","9.59915","0.06628"
"19233","115.36200","9.61374","0.06603"
"19262","115.53600","9.62821","0.06706"
"19291","115.71000","9.64268","0.06844"
"19320","115.88400","9.65715","0.06694"
"19349","116.05800","9.67173","0.06879"
"19378","116.23200","9.68614","0.06839"
"19407","116.40600","9.70067","0.06718"
"19436","116.58000","9.71520","0.06467"
"19465","116.75400","9.72967","0.06229"
"19494","116.92800","9.74420","0.06203"
"19523","117.10200","9.75873","0.06350"
"19552","117.27600","9.77314","0.06053"
"19581","117.45000","9.78767","0.06190"
"19610","117.62400","9.80219","0.06272"
"19639","117.79800","9.81666","0.06219"
"19668","117.97200","9.83113","0.06387"
"19697","118.14600","9.84566","0.06316"
"19726","118.32000","9.86013","0.06126"
"19755","118.49400","9.87466","0.06446"
"19784","118.66800","9.88919","0.06342"
"19813","118.84200","9.90366","0.06379"
"19842","119.01600","9.91813","0.06551"
"19871","119.19000","9.93271","0.06465"
"19900","119.36400","9.94724","0.06635"
"19929","119.53800","9.96165","0.06712"
"19958","119.71200","9.97618","0.06619"
"19987","119.88600","9.99071","0.06809"
"20016","120.06000","10.00518","0.06792"
"20045","120.23400","10.01977","0.06756"
"20074","120.40800","10.03418","0.06960"
"20103","120.58200","10.04865","0.06827"
"20132","120.75600","10.06318","0.06911"
"20161","120.93000","10.07771","0.06990"
"20190","121.10400","10.09217","0.06953"
"20219","121.27800","10.10664","0.07132"
"20248","121.45200","10.12117","0.07145"
"20277","121.62600","10.13564","0.07130"
"20306","121.80000","10.15023","0.07261"
"20335","121.97400","10.16470","0.07206"
"20364","122.14800","10.17917","0.07281"
"20393","122.32200","10.19370","0.07382"
"20422","122.49600","10.20817","0.07343"
"20451","122.67000","10.22264","0.07444"
"20480","122.84400","10.23716","0.07446"
"20509","123.01800","10.25169","0.07398"
"20538","123.19200","10.26610","0.07522"
"20567","123.36600","10.28069","0.07495"
"20596","123.54000","10.29522","0.07553"
"20625","123.71400","10.30963","0.07581"
"20654","123.88800","10.32410","0.07569"
"20683","124.06200","10.33875","0.07612"
"20712","124.23600","10.35322","0.07650"
"20741","124.41000","10.36762","0.07620"
"20770","124.58400","10.38215","0.07669"
"20799","124.75800","10.39662","0.07676"
"20828","124.93200","10.41115","0.07693"
"20857","125.10600","10.42574","0.07727"
"20886","125.28000","10.44021","0.07722"
"20915","125.45400","10.45462","0.07766"
"20944","125.62800","10.46921","0.07772"
"20973","125.80200","10.48374","0.07789"
"21002","125.97600","10.49815","0.07825"
"21031","126.15000","10.51273","0.07821"
"21060","126.32400","10.52720","0.07847"
"21089","126.49800","10.54161","0.07888"
"21118","126.67200","10.55620","0.07902"
"21147","126.84600","10.57073","0.07995"
"21176","127.02000","10.58514","0.07999"
"21205","127.19400","10.59973","0.08036"
"21234","127.36800","10.61426","0.08140"
"21263","127.54200","10.62872","0.08100"
"21292","127.71600","10.64319","0.08206"
"21321","127.89000","10.65766","0.08233"
"21350","128.06400","10.67219","0.08259"
"21379","128.23800","10.68666","0.08373"
"21408","128.41200","10.70125","0.08415"
"21437","128.58600","10.71566","0.08547"
"21466","128.76000","10.73013","0.08579"
"21495","128.93400","10.74466","0.08564"
"21524","129.10800","10.75919","0.08775"
"21553","129.28200","10.77366","0.08794"
"21582","129.45600","10.78818","0.08982"
"21611","129.63000","10.80265","0.09079"
"21640","129.80400","10.81718","0.09181"
"21669","129.97800","10.83165","0.09392"
"21698","130.15200","10.84612","0.09387"
"21727","130.32600","10.86065","0.09622"
"21756","130.50000","10.87518","0.09737"
"21785","130.67400","10.88971","0.09817"
"21814","130.84800","10.90418","0.10073"
"21843","131.02200","10.91870","0.10137"
"21872","131.19600","10.93317","0.10283"
"21901","131.37000","10.94758","0.10400"
"21930","131.54400","10.96223","0.10474"
"21959","131.71800","10.97676","0.10647"
"21988","131.89200","10.99111","0.10722"
"22017","132.06600","11.00570","0.10991"
"22046","132.24000","11.02017","0.11089"
"22075","132.41400","11.03464","0.11193"
"22104","132.58800","11.04923","0.11475"
"22133","132.76200","11.06369","0.11416"
"22162","132.93600","11.07816","0.11785"
"22191","133.11000","11.09269","0.11873"
"22220","133.28400","11.10722","0.12148"
"22249","133.45800","11.12163","0.12238"
"22278","133.63200","11.13622","0.12503"
"22307","133.80600","11.15075","0.12737"
"22336","133.98000","11.16516","0.12820"
"22365","134.15400","11.17969","0.12966"
"22394","134.32800","11.19421","0.13219"
"22423","134.50200","11.20862","0.13299"
"22452","134.67600","11.22315","0.13424"
"22481","134.85000","11.23774","0.13467"
"22510","135.02400","11.25215","0.13573"
"22539","135.19800","11.26668","0.13593"
"22568","135.37200","11.28115","0.13649"
"22597","135.54600","11.29568","0.13684"
"22626","135.72000","11.31021","0.08236"
"22655","135.89400","11.32468","0.08119"
"22684","136.06800","11.33914","0.08026"
"22713","136.24200","11.35361","0.08285"
"22742","136.41600","11.36820","0.08204"
"22771","136.59000","11.38267","0.08326"
"22800","136.76400","11.39708","0.08542"
"22829","136.93800","11.41167","0.08453"
"22858","137.11200","11.42620","0.08916"
"22887","137.28600","11.44067","0.08863"
"22916","137.46000","11.45520","0.09004"
"22945","137.63400","11.46967","0.09321"
"22974","137.80800","11.48413","0.09236"
"23003","137.98200","11.49866","0.09726"
"23032","138.15600","11.51325","0.09689"
"23061","138.33000","11.52766","0.10086"
"23090","138.50400","11.54219","0.10403"
"23119","138.67800","11.55672","0.10329"
"23148","138.85200","11.57119","0.10839"
"23177","139.02600","11.58572","0.10777"
"23206","139.20000","11.60019","0.11115"
"23235","139.37400","11.61466","0.11296"
"23264","139.54800","11.62918","0.11369"
"23293","139.72200","11.64371","0.11866"
"23322","139.89600","11.65818","0.11901"
"23351","140.07000","11.67265","0.12150"
"23380","140.24400","11.68718","0.12320"
"23409","140.41800","11.70165","0.12466"
"23438","140.59200","11.71618","0.12913"
"23467","140.76600","11.73071","0.12885"
"23496","140.94000","11.74518","0.13293"
"23525","141.11400","11.75964","0.13320"
"23554","141.28800","11.77423","0.13439"
"23583","141.46200","11.78870","0.13540"
"23612","141.63600","11.80317","0.13566"
"23641","141.81000","11.81770","0.13708"
"23670","141.98400","11.83217","0.13721"
"23699","142.15800","11.84670","0.13786"
"23728","142.33200","11.86123","0.13813"
"23757","142.50600","11.87570","0.13884"
"23786","142.68000","11.89011","0.13967"
"23815","142.85400","11.90469","0.14011"
"23844","143.02800","11.91922","0.14171"
"23873","143.20200","11.93369","0.14118"
"23902","143.37600","11.94822","0.14314"
"23931","143.55000","11.96269","0.14391"
"23960","143.72400","11.97716","0.14505"
"23989","143.89800","11.99169","0.14627"
"24018","144.07200","12.00622","0.14665"
"24047","144.24600","12.02063","0.14903"
"24076","144.42000","12.03522","0.14496"
"24105","144.59400","12.04974","0.14762"
"24134","144.76800","12.06415","0.14755"
"24163","144.94200","12.07868","0.14867"
"24192","145.11600","12.09321","0.15140"
"24221","145.29000","12.10768","0.15129"
"24250","145.46400","12.12215","0.15489"
"24279","145.63800","12.13674","0.15459"
"24308","145.81200","12.15121","0.15692"
"24337","145.98600","12.16568","0.15679"
"24366","146.16000","12.18014","0.15829"
"24395","146.33400","12.19467","0.15983"
"24424","146.50800","12.20920","0.16031"
"24453","146.68200","12.22373","0.16209"
"24482","146.85600","12.23814","0.16276"
"24511","147.03000","12.25267","0.16470"
"24540","147.20400","12.26720","0.16559"
"24569","147.37800","12.28167","0.16774"
"24598","147.55200","12.29614","0.16836"
"24627","147.72600","12.31066","0.16987"
"24656","147.90000","12.32525","0.17113"
"24685","148.07400","12.33972","0.17183"
"24714","148.24800","12.35419","0.17315"
"24743","148.42200","12.36866","0.17356"
"24772","148.59600","12.38313","0.17527"
"24801","148.77000","12.39772","0.17550"
"24830","148.94400","12.41225","0.17664"
"24859","149.11800","12.42666","0.17768"
"24888","149.29200","12.44125","0.17856"
"24917","149.46600","12.45571","0.17918"
"24946","149.64000","12.47012","0.17975"
"24975","149.81400","12.48471","0.18095"
"25004","149.98800","12.49918","0.18129"
"25033","150.16200","12.51365","0.18201"
"25062","150.33600","12.52812","0.18205"
"25091","150.51000","12.54271","0.18302"
"25120","150.68400","12.55718","0.18295"
"25149","150.85800","12.57171","0.18344"
"25178","151.03200","12.58623","0.18439"
"25207","151.20600","12.60070","0.18465"
"25236","151.38000","12.61517","0.18511"
"25265","151.55400","12.62970","0.18575"
"25294","151.72800","12.64417","0.18698"
"25323","151.90200","12.65864","0.18671"
"25352","152.07600","12.67323","0.18791"
"25381","152.25000","12.68764","0.18789"
"25410","152.42400","12.70217","0.18893"
"25439","152.59800","12.71670","0.18929"
"25468","152.77200","12.73123","0.19000"
"25497","152.94600","12.74569","0.19046"
"25526","153.12000","12.76016","0.19138"
"25555","153.29400","12.77469","0.19218"
"25584","153.46800","12.78916","0.19320"
"25613","153.64200","12.80375","0.19345"
"25642","153.81600","12.81822","0.19468"
"25671","153.99000","12.83263","0.19615"
"25700","154.16400","12.84716","0.19634"
"25729","154.33800","12.86163","0.19810"
"25758","154.51200","12.87615","0.19856"
"25787","154.68600","12.89068","0.20120"
"25816","154.86000","12.90515","0.20128"
"25845","155.03400","12.91962","0.20270"
"25874","155.20800","12.93421","0.20248"
"25903","155.38200","12.94874","0.20535"
"25932","155.55600","12.96315","0.20552"
"25961","155.73000","12.97768","0.20795"
"25990","155.90400","12.99221","0.20773"
"26019","156.07800","13.00667","0.20859"
"26048","156.25200","13.02120","0.20982"
"26077","156.42600","13.03573","0.21146"
"26106","156.60000","13.05008","0.21251"
"26135","156.77400","13.06473","0.21351"
"26164","156.94800","13.07920","0.21458"
"26193","157.12200","13.09367","0.21572"
"26222","157.29600","13.10820","0.21696"
"26251","157.47000","13.12273","0.21709"
"26280","157.64400","13.13714","0.21964"
"26309","157.81800","13.15172","0.22037"
"26338","157.99200","13.16619","0.22197"
"26367","158.16600","13.18072","0.22285"
"26396","158.34000","13.19519","0.22429"
"26425","158.51400","13.20972","0.22553"
"26454","158.68800","13.22419","0.22681"
"26483","158.86200","13.23866","0.22669"
"26512","159.03600","13.25319","0.22805"
"26541","159.21000","13.26766","0.22830"
"26570","159.38400","13.28219","0.22958"
"26599","159.55800","13.29671","0.22965"
"26628","159.73200","13.31118","0.23080"
"26657","159.90600","13.32565","0.23143"
"26686","160.08000","13.34018","0.23196"
"26715","160.25400","13.35477","0.23321"
"26744","160.42800","13.36918","0.23528"
"26773","160.60200","13.38371","0.23592"
"26802","160.77600","13.39818","0.23794"
"26831","160.95000","13.41265","0.23878"
"26860","161.12400","13.42724","0.24151"
"26889","161.29800","13.44170","0.24274"
"26918","161.47200","13.45611","0.24480"
"26947","161.64600","13.47070","0.24674"
"26976","161.82000","13.48517","0.24940"
"27005","161.99400","13.49964","0.25106"
"27034","162.16800","13.51417","0.25292"
"27063","162.34200","13.52870","0.25430"
"27092","162.51600","13.54317","0.25683"
"27121","162.69000","13.55770","0.25822"
"27150","162.86400","13.57222","0.26134"
"27179","163.03800","13.58663","0.26206"
"27208","163.21200","13.60116","0.26391"
"27237","163.38600","13.61569","0.26533"
"27266","163.56000","13.63016","0.26727"
"27295","163.73400","13.64463","0.26795"
"27324","163.90800","13.65922","0.27079"
"27353","164.08200","13.67363","0.27189"
"27382","164.25600","13.68822","0.27430"
"27411","164.43000","13.70274","0.27550"
"27440","164.60400","13.71715","0.27727"
"27469","164.77800","13.73162","0.27832"
"27498","164.95200","13.74615","0.28021"
"27527","165.12600","13.76074","0.27858"
"27556","165.30000","13.77515","0.28087"
"27585","165.47400","13.78968","0.28102"
"27614","165.64800","13.80421","0.28274"
"27643","165.82200","13.81868","0.28305"
"27672","165.99600","13.83321","0.28491"
"27701","166.17000","13.84768","0.28535"
"27730","166.34400","13.86214","0.28609"
"27759","166.51800","13.87667","0.28747"
"27788","166.69200","13.89120","0.28807"
"27817","166.86600","13.90561","0.28880"
"27846","167.04000","13.92026","0.28886"
"27875","167.21400","13.93473","0.28962"
"27904","167.38800","13.94914","0.29009"
"27933","167.56200","13.96373","0.29014"
"27962","167.73600","13.97819","0.29036"
"27991","167.91000","13.99261","0.29060"
"28020","168.08400","14.00713","0.29077"
"28049","168.25800","14.02172","0.29093"
"28078","168.43200","14.03619","0.29094"
"28107","168.60600","14.05072","0.29108"
"28136","168.78000","14.06519","0.29123"
"28165","168.95400","14.07966","0.29130"
"28194","169.12800","14.09425","0.29131"
"28223","169.30200","14.10872","0.29149"
"28252","169.47600","14.12319","0.29155"
"28281","169.65000","14.13765","0.29174"
"28310","169.82400","14.15218","0.29004"
"28339","169.99800","14.16665","0.19955"
"28368","170.17200","14.18118","0.20705"
"28397","170.34600","14.19571","0.20471"
"28426","170.52000","14.21018","0.21195"
"28455","170.69400","14.22465","0.21172"
"28484","170.86800","14.23924","0.21511"
"28513","171.04200","14.25371","0.21641"
"28542","171.21600","14.26817","0.21904"
"28571","171.39000","14.28270","0.22264"
"28600","171.56400","14.29723","0.22257"
"28629","171.73800","14.31170","0.22566"
"28658","171.91200","14.32623","0.22601"
"28687","172.08600","14.34064","0.22832"
"28716","172.26000","14.35511","0.22815"
"28745","172.43400","14.36976","0.23158"
"28774","172.60800","14.38423","0.23022"
"28803","172.78200","14.39863","0.23487"
"28832","172.95600","14.41317","0.23327"
"28861","173.13000","14.42769","0.23992"
"28890","173.30400","14.44216","0.23684"
"28919","173.47800","14.45675","0.24811"
"28948","173.65200","14.47122","0.24343"
"28977","173.82600","14.48569","0.25383"
"29006","174.00000","14.50022","0.25089"
"29035","174.17400","14.51469","0.26052"
"29064","174.34800","14.52916","0.25734"
"29093","174.52200","14.54374","0.26449"
"29122","174.69600","14.55821","0.26278"
"29151","174.87000","14.57268","0.22168"
"29180","175.04400","14.58721","0.19346"
"29209","175.21800","14.60174","0.19715"
"29238","175.39200","14.61615","0.19102"
"29267","175.56600","14.63062","0.18998"
"29296","175.74000","14.64527","0.18929"
"29325","175.91400","14.65968","0.19032"
"29354","176.08800","14.67421","0.19042"
"29383","176.26200","14.68867","0.19192"
"29412","176.43600","14.70314","0.19251"
"29441","176.61000","14.71773","0.19212"
"29470","176.78400","14.73220","0.19446"
"29499","176.95800","14.74667","0.19423"
"29528","177.13200","14.76120","0.19722"
"29557","177.30600","14.77573","0.19670"
"29586","177.48000","14.79020","0.20080"
"29615","177.65400","14.80467","0.19866"
"29644","177.82800","14.81920","0.20282"
"29673","178.00200","14.83372","0.20146"
"29702","178.17600","14.84819","0.20405"
"29731","178.35000","14.86272","0.20215"
"29760","178.52400","14.87719","0.20438"
"29789","178.69800","14.89160","0.20497"
"29818","178.87200","14.90625","0.20581"
"29847","179.04600","14.92066","0.20713"
"29876","179.22000","14.93519","0.20487"
"29905","179.39400","14.94972","0.19344"
"29934","179.56800","14.96418","0.18935"
"29963","179.74200","14.97865","0.18939"
"29992","179.91600","14.99324","0.18945"
"30021","180.09000","15.00771","0.19025"
"30050","180.26400","15.02218","0.18961"
"30079","180.43800","15.03671","0.19060"
"30108","180.61200","15.05118","0.19052"
"30137","180.78600","15.06571","0.19120"
"30166","180.96000","15.08012","0.19159"
"30195","181.13400","15.09470","0.19234"
"30224","181.30800","15.10912","0.19208"
"30253","181.48200","15.12370","0.19250"
"30282","181.65600","15.13817","0.19378"
"30311","181.83000","15.15264","0.19324"
"30340","182.00400","15.16717","0.19462"
"30369","182.17800","15.18170","0.19472"
"30398","182.35200","15.19617","0.19596"
"30427","182.52600","15.21070","0.19543"
"30456","182.70000","15.22523","0.19707"
"30485","182.87400","15.23964","0.19580"
"30514","183.04800","15.25410","0.19746"
"30543","183.22200","15.26875","0.19704"
"30572","183.39600","15.28322","0.19758"
"30601","183.57000","15.29763","0.19789"
"30630","183.74400","15.31222","0.19817"
"30659","183.91800","15.32675","0.19865"
"30688","184.09200","15.34116","0.19915"
"30717","184.26600","15.35575","0.20095"
"30746","184.44000","15.37016","0.20054"
"30775","184.61400","15.38462","0.20181"
"30804","184.78800","15.39921","0.20222"
"30833","184.96200","15.41374","0.20333"
"30862","185.13600","15.42815","0.20331"
"30891","185.31000","15.44262","0.20481"
"30920","185.48400","15.45721","0.20457"
"30949","185.65800","15.47168","0.20569"
"30978","185.83200","15.48621","0.20622"
"31007","186.00600","15.50074","0.20718"
"31036","186.18000","15.51515","0.20652"
"31065","186.35400","15.52967","0.20651"
"31094","186.52800","15.54420","0.20713"
"31123","186.70200","15.55867","0.20782"
"31152","186.87600","15.57320","0.20844"
"31181","187.05000","15.58767","0.20806"
"31210","187.22400","15.60220","0.21011"
"31239","187.39800","15.61667","0.20976"
"31268","187.57200","15.63114","0.21078"
"31297","187.74600","15.64566","0.21025"
"31326","187.92000","15.66019","0.21144"
"31355","188.09400","15.67472","0.21133"
"31384","188.26800","15.68919","0.21322"
"31413","188.44200","15.70366","0.21268"
"31442","188.61600","15.71819","0.21451"
"31471","188.79000","15.73272","0.21440"
"31500","188.96400","15.74719","0.21524"
"31529","189.13800","15.76172","0.21578"
"31558","189.31200","15.77619","0.21706"
"31587","189.48600","15.79060","0.21721"
"31616","189.66000","15.80524","0.21760"
"31645","189.83400","15.81971","0.21903"
"31674","190.00800","15.83418","0.22014"
"31703","190.18200","15.84865","0.22041"
"31732","190.35600","15.86318","0.22130"
"31761","190.53000","15.87759","0.22187"
"31790","190.70400","15.89224","0.22233"
"31819","190.87800","15.90671","0.22323"
"31848","191.05200","15.92118","0.22415"
"31877","191.22600","15.93576","0.22509"
"31906","191.40000","15.95023","0.22505"
"31935","191.57400","15.96464","0.22649"
"31964","191.74800","15.97917","0.22609"
"31993","191.92200","15.99370","0.22676"
"32022","192.09600","16.00817","0.22674"
"32051","192.27000","16.02270","0.22771"
"32080","192.44400","16.03717","0.22752"
"32109","192.61800","16.05169","0.22768"
"32138","192.79200","16.06616","0.22803"
"32167","192.96600","16.08075","0.22821"
"32196","193.14000","16.09516","0.22859"
"32225","193.31400","16.10963","0.22880"
"32254","193.48800","16.12416","0.22931"
"32283","193.66200","16.13863","0.22984"
"32312","193.83600","16.15322","0.23023"
"32341","194.01000","16.16769","0.23077"
"32370","194.18400","16.18222","0.23104"
"32399","194.35800","16.19669","0.23170"
"32428","194.53200","16.21121","0.23226"
"32457","194.70600","16.22568","0.23284"
"32486","194.88000","16.24015","0.23367"
"32515","195.05400","16.25468","0.23515"
"32544","195.22800","16.26921","0.23521"
"32573","195.40200","16.28368","0.23585"
"32602","195.57600","16.29821","0.23789"
"32631","195.75000","16.31274","0.23772"
"32660","195.92400","16.32715","0.23850"
"32689","196.09800","16.34173","0.23912"
"32718","196.27200","16.35620","0.24118"
"32747","196.44600","16.37067","0.24193"
"32776","196.62000","16.38520","0.24385"
"32805","196.79400","16.39967","0.24524"
"32834","196.96800","16.41420","0.24541"
"32863","197.14200","16.42873","0.24574"
"32892","197.31600","16.44326","0.24847"
"32921","197.49000","16.45761","0.24994"
"32950","197.66400","16.47220","0.25109"
"32979","197.83800","16.48667","0.25195"
"33008","198.01200","16.50113","0.25274"
"33037","198.18600","16.51572","0.25382"
"33066","198.36000","16.53019","0.25491"
"33095","198.53400","16.54466","0.25597"
"33124","198.70800","16.55919","0.25638"
"33153","198.88200","16.57372","0.25734"
"33182","199.05600","16.58813","0.25828"
"33211","199.23000","16.60266","0.25842"
"33240","199.40400","16.61718","0.25982"
"33269","199.57800","16.63171","0.26106"
"33298","199.75200","16.64618","0.26245"
"33327","199.92600","16.66065","0.26349"
"33356","200.10000","16.67518","0.26510"
"33385","200.27400","16.68965","0.26728"
"33414","200.44800","16.70418","0.26757"
"33443","200.62200","16.71871","0.26918"
"33472","200.79600","16.73306","0.27096"
"33501","200.97000","16.74771","0.27038"
"33530","201.14400","16.76223","0.27095"
"33559","201.31800","16.77664","0.27072"
"33588","201.49200","16.79123","0.27206"
"33617","201.66600","16.80570","0.27254"
"33646","201.84000","16.82011","0.27284"
"33675","202.01400","16.83470","0.27326"
"33704","202.18800","16.84917","0.27388"
"33733","202.36200","16.86364","0.27407"
"33762","202.53600","16.87817","0.27411"
"33791","202.71000","16.89276","0.07428"
"33820","202.88400","16.90717","0.07987"
"33849","203.05800","16.92169","0.07601"
"33878","203.23200","16.93622","0.08230"
"33907","203.40600","16.95063","0.07733"
"33936","203.58000","16.96516","0.07895"
"33965","203.75400","16.97975","0.08101"
"33994","203.92800","16.99422","0.07929"
"34023","204.10200","17.00869","0.08105"
"34052","204.27600","17.02316","0.08592"
"34081","204.45000","17.03768","0.08173"
"34110","204.62400","17.05215","0.08815"
"34139","204.79800","17.06668","0.08294"
"34168","204.97200","17.08115","0.08419"
"34197","205.14600","17.09568","0.09574"
"34226","205.32000","17.11021","0.08570"
"34255","205.49400","17.12468","0.10020"
"34284","205.66800","17.13921","0.08994"
"34313","205.84200","17.15374","0.09389"
"34342","206.01600","17.16821","0.10347"
"34371","206.19000","17.18267","0.09357"
"34400","206.36400","17.19720","0.10635"
"34429","206.53800","17.21167","0.09707"
"34458","206.71200","17.22614","0.10086"
"34487","206.88600","17.24073","0.10771"
"34516","207.06000","17.25514","0.10183"
"34545","207.23400","17.26961","0.11381"
"34574","207.40800","17.28420","0.10639"
"34603","207.58200","17.29867","0.11125"
"34632","207.75600","17.31314","0.11626"
"34661","207.93000","17.32772","0.11152"
"34690","208.10400","17.34219","0.12373"
"34719","208.27800","17.35660","0.11551"
"34748","208.45200","17.37125","0.12454"
"34777","208.62600","17.38572","0.12552"
"34806","208.80000","17.40013","0.12493"
"34835","208.97400","17.41472","0.13287"
"34864","209.14800","17.42925","0.12677"
"34893","209.32200","17.44366","0.13470"
"34922","209.49600","17.45819","0.13134"
"34951","209.67000","17.47271","0.13399"
"34980","209.84400","17.48718","0.13673"
"35009","210.01800","17.50165","0.13375"
"35038","210.19200","17.51624","0.13802"
"35067","210.36600","17.53065","0.13527"
"35096","210.54000","17.54512","0.13774"
"35125","210.71400","17.55971","0.13735"
"35154","210.88800","17.57418","0.13629"
"35183","211.06200","17.58865","0.13971"
"35212","211.23600","17.60317","0.13694"
"35241","211.41000","17.61764","0.14046"
"35270","211.58400","17.63211","0.13899"
"35299","211.75800","17.64676","0.13991"
"35328","211.93200","17.66123","0.14263"
"35357","212.10600","17.67564","0.14024"
"35386","212.28000","17.69017","0.14760"
"35415","212.45400","17.70470","0.14249"
"35444","212.62800","17.71917","0.14921"
"35473","212.80200","17.73369","0.14619"
"35502","212.97600","17.74822","0.14949"
"35531","213.15000","17.76257","0.15202"
"35560","213.32400","17.77722","0.14981"
"35589","213.49800","17.79169","0.15627"
"35618","213.67200","17.80616","0.15235"
"35647","213.84600","17.82069","0.15940"
"35676","214.02000","17.83516","0.15628"
"35705","214.19400","17.84969","0.16048"
"35734","214.36800","17.86422","0.16001"
"35763","214.54200","17.87868","0.15984"
"35768","214.57000","17.88102","0.16100"