File: Trajectories_together/170107_2Specimen_RawData_5.csv
"","V1","V2","V3"
"1","End date","1/7/2017",""
"2","Specimen label","3AG_24",""
"3","Maximum Load","0.03907","N"
"4","Time","Extension","Load"
"5","(s)","(mm)","(N)"
"6","0.00000","0.00006","0.00018"
"48","0.25200","0.01973","0.00114"
"90","0.50400","0.04227","0.00140"
"132","0.75600","0.06320","0.00183"
"174","1.00800","0.08418","0.00186"
"216","1.26000","0.10523","0.00173"
"258","1.51200","0.12610","0.00257"
"300","1.76400","0.14720","0.00238"
"342","2.01600","0.16813","0.00230"
"384","2.26800","0.18923","0.00283"
"426","2.52000","0.21016","0.00281"
"468","2.77200","0.23121","0.00319"
"510","3.02400","0.25219","0.00346"
"552","3.27600","0.27318","0.00341"
"594","3.52800","0.29416","0.00317"
"636","3.78000","0.31515","0.00360"
"678","4.03200","0.33620","0.00393"
"720","4.28400","0.35712","0.00362"
"762","4.53600","0.37817","0.00392"
"804","4.78800","0.39910","0.00408"
"846","5.04000","0.42026","0.00410"
"888","5.29200","0.44113","0.00421"
"930","5.54400","0.46217","0.00408"
"972","5.79600","0.48316","0.00516"
"1014","6.04800","0.50421","0.00444"
"1056","6.30000","0.52519","0.00475"
"1098","6.55200","0.54618","0.00492"
"1140","6.80400","0.56716","0.00477"
"1182","7.05600","0.58815","0.00507"
"1224","7.30800","0.60920","0.00523"
"1266","7.56000","0.63018","0.00467"
"1308","7.81200","0.65117","0.00531"
"1350","8.06400","0.67215","0.00497"
"1392","8.31600","0.69320","0.00560"
"1434","8.56800","0.71413","0.00609"
"1476","8.82000","0.73517","0.00554"
"1518","9.07200","0.75616","0.00571"
"1560","9.32400","0.77720","0.00587"
"1602","9.57600","0.79813","0.00577"
"1644","9.82800","0.81918","0.00512"
"1686","10.08000","0.84016","0.00576"
"1728","10.33200","0.86121","0.00563"
"1770","10.58400","0.88213","0.00641"
"1812","10.83600","0.90324","0.00580"
"1854","11.08800","0.92417","0.00569"
"1896","11.34000","0.94515","0.00573"
"1938","11.59200","0.96620","0.00666"
"1980","11.84400","0.98713","0.00703"
"2022","12.09600","1.00817","0.00631"
"2064","12.34800","1.02916","0.00705"
"2106","12.60000","1.05020","0.00648"
"2148","12.85200","1.07113","0.00731"
"2190","13.10400","1.09218","0.00676"
"2232","13.35600","1.11316","0.00725"
"2274","13.60800","1.13421","0.00727"
"2316","13.86000","1.15513","0.00691"
"2358","14.11200","1.17618","0.00715"
"2400","14.36400","1.19711","0.00713"
"2442","14.61600","1.21821","0.00750"
"2484","14.86800","1.23914","0.00733"
"2526","15.12000","1.26018","0.00758"
"2568","15.37200","1.28117","0.00769"
"2610","15.62400","1.30222","0.00721"
"2652","15.87600","1.32314","0.00757"
"2694","16.12800","1.34413","0.00712"
"2736","16.38000","1.36517","0.00719"
"2778","16.63200","1.38616","0.00785"
"2820","16.88400","1.40721","0.00696"
"2862","17.13600","1.42813","0.00793"
"2904","17.38800","1.44918","0.00786"
"2946","17.64000","1.47016","0.00775"
"2988","17.89200","1.49121","0.00761"
"3030","18.14400","1.51214","0.00799"
"3072","18.39600","1.53318","0.00776"
"3114","18.64800","1.55411","0.00808"
"3156","18.90000","1.57522","0.00799"
"3198","19.15200","1.59614","0.00837"
"3240","19.40400","1.61719","0.00804"
"3282","19.65600","1.63823","0.00809"
"3324","19.90800","1.65916","0.00812"
"3366","20.16000","1.68021","0.00797"
"3408","20.41200","1.70119","0.00821"
"3450","20.66400","1.72218","0.00848"
"3492","20.91600","1.74310","0.00815"
"3534","21.16800","1.76415","0.00856"
"3576","21.42000","1.78508","0.00837"
"3618","21.67200","1.80624","0.00833"
"3660","21.92400","1.82717","0.00850"
"3702","22.17600","1.84815","0.00892"
"3744","22.42800","1.86920","0.00834"
"3786","22.68000","1.89019","0.00811"
"3828","22.93200","1.91117","0.00874"
"3870","23.18400","1.93216","0.00867"
"3912","23.43600","1.95314","0.00828"
"3954","23.68800","1.97419","0.00845"
"3996","23.94000","1.99518","0.00860"
"4038","24.19200","2.01616","0.00826"
"4080","24.44400","2.03721","0.00869"
"4122","24.69600","2.05819","0.00906"
"4164","24.94800","2.07918","0.00871"
"4206","25.20000","2.10011","0.00811"
"4248","25.45200","2.12115","0.00874"
"4290","25.70400","2.14214","0.00877"
"4332","25.95600","2.16325","0.00880"
"4374","26.20800","2.18411","0.00840"
"4416","26.46000","2.20522","0.00846"
"4458","26.71200","2.22614","0.00877"
"4500","26.96400","2.24719","0.00889"
"4542","27.21600","2.26812","0.00841"
"4584","27.46800","2.28916","0.00805"
"4626","27.72000","2.31021","0.00869"
"4668","27.97200","2.33113","0.00900"
"4710","28.22400","2.35218","0.00913"
"4752","28.47600","2.37311","0.00830"
"4794","28.72800","2.39421","0.00870"
"4836","28.98000","2.41520","0.00874"
"4878","29.23200","2.43618","0.00852"
"4920","29.48400","2.45711","0.00831"
"4962","29.73600","2.47816","0.00874"
"5004","29.98800","2.49920","0.00871"
"5046","30.24000","2.52019","0.00878"
"5088","30.49200","2.54117","0.00970"
"5130","30.74400","2.56222","0.00892"
"5172","30.99600","2.58321","0.00868"
"5214","31.24800","2.60419","0.00909"
"5256","31.50000","2.62518","0.00877"
"5298","31.75200","2.64616","0.00873"
"5340","32.00400","2.66715","0.00922"
"5382","32.25600","2.68814","0.00893"
"5424","32.50800","2.70918","0.00859"
"5466","32.76000","2.73011","0.00901"
"5508","33.01200","2.75122","0.00924"
"5550","33.26400","2.77214","0.00895"
"5592","33.51600","2.79313","0.00947"
"5634","33.76800","2.81411","0.00911"
"5676","34.02000","2.83522","0.00953"
"5718","34.27200","2.85615","0.00878"
"5760","34.52400","2.87719","0.00948"
"5802","34.77600","2.89818","0.00926"
"5844","35.02800","2.91922","0.00931"
"5886","35.28000","2.94021","0.00923"
"5928","35.53200","2.96120","0.00929"
"5970","35.78400","2.98218","0.00891"
"6012","36.03600","3.00317","0.00935"
"6054","36.28800","3.02421","0.00949"
"6096","36.54000","3.04508","0.00919"
"6138","36.79200","3.06619","0.00930"
"6180","37.04400","3.08711","0.00938"
"6222","37.29600","3.10822","0.00926"
"6264","37.54800","3.12914","0.00901"
"6306","37.80000","3.15019","0.00932"
"6348","38.05200","3.17112","0.00939"
"6390","38.30400","3.19222","0.00909"
"6432","38.55600","3.21315","0.00951"
"6474","38.80800","3.23419","0.00972"
"6516","39.06000","3.25518","0.00965"
"6558","39.31200","3.27617","0.00987"
"6600","39.56400","3.29721","0.00921"
"6642","39.81600","3.31820","0.00929"
"6684","40.06800","3.33919","0.00909"
"6726","40.32000","3.36017","0.00926"
"6768","40.57200","3.38116","0.00931"
"6810","40.82400","3.40208","0.00997"
"6852","41.07600","3.42319","0.00912"
"6894","41.32800","3.44418","0.00920"
"6936","41.58000","3.46522","0.00866"
"6978","41.83200","3.48615","0.00919"
"7020","42.08400","3.50713","0.00947"
"7062","42.33600","3.52812","0.00867"
"7104","42.58800","3.54917","0.00904"
"7146","42.84000","3.57009","0.00943"
"7188","43.09200","3.59120","0.00944"
"7230","43.34400","3.61218","0.00938"
"7272","43.59600","3.63317","0.00958"
"7314","43.84800","3.65422","0.00968"
"7356","44.10000","3.67514","0.00906"
"7398","44.35200","3.69619","0.00907"
"7440","44.60400","3.71718","0.00907"
"7482","44.85600","3.73822","0.00914"
"7524","45.10800","3.75909","0.00851"
"7566","45.36000","3.78019","0.00985"
"7608","45.61200","3.80118","0.00917"
"7650","45.86400","3.82223","0.01014"
"7692","46.11600","3.84315","0.00968"
"7734","46.36800","3.86420","0.00944"
"7776","46.62000","3.88512","0.00929"
"7818","46.87200","3.90617","0.00938"
"7860","47.12400","3.92722","0.00940"
"7902","47.37600","3.94814","0.00896"
"7944","47.62800","3.96919","0.00902"
"7986","47.88000","3.99017","0.00915"
"8028","48.13200","4.01116","0.00931"
"8070","48.38400","4.03215","0.00970"
"8112","48.63600","4.05319","0.00933"
"8154","48.88800","4.07412","0.00950"
"8196","49.14000","4.09516","0.00942"
"8238","49.39200","4.11615","0.00882"
"8280","49.64400","4.13720","0.00969"
"8322","49.89600","4.15812","0.00893"
"8364","50.14800","4.17917","0.00980"
"8406","50.40000","4.20015","0.00931"
"8448","50.65200","4.22120","0.00972"
"8490","50.90400","4.24213","0.00956"
"8532","51.15600","4.26323","0.00896"
"8574","51.40800","4.28416","0.00940"
"8616","51.66000","4.30521","0.00928"
"8658","51.91200","4.32619","0.00946"
"8700","52.16400","4.34712","0.00922"
"8742","52.41600","4.36822","0.00952"
"8784","52.66800","4.38915","0.00929"
"8826","52.92000","4.41020","0.00924"
"8868","53.17200","4.43106","0.00933"
"8910","53.42400","4.45217","0.00962"
"8952","53.67600","4.47315","0.00945"
"8994","53.92800","4.49420","0.00905"
"9036","54.18000","4.51513","0.00859"
"9078","54.43200","4.53623","0.00866"
"9120","54.68400","4.55716","0.00872"
"9162","54.93600","4.57814","0.00844"
"9204","55.18800","4.59913","0.00811"
"9246","55.44000","4.62018","0.00851"
"9288","55.69200","4.64122","0.00891"
"9330","55.94400","4.66221","0.00870"
"9372","56.19600","4.68319","0.00818"
"9414","56.44800","4.70418","0.00827"
"9456","56.70000","4.72523","0.00826"
"9498","56.95200","4.74615","0.00839"
"9540","57.20400","4.76714","0.00835"
"9582","57.45600","4.78807","0.00878"
"9624","57.70800","4.80917","0.00868"
"9666","57.96000","4.83022","0.00844"
"9708","58.21200","4.85120","0.00839"
"9750","58.46400","4.87219","0.00886"
"9792","58.71600","4.89323","0.00846"
"9834","58.96800","4.91416","0.00849"
"9876","59.22000","4.93521","0.00867"
"9918","59.47200","4.95613","0.00858"
"9960","59.72400","4.97712","0.00811"
"10002","59.97600","4.99817","0.00859"
"10044","60.22800","5.01915","0.00861"
"10086","60.48000","5.04020","0.00910"
"10128","60.73200","5.06112","0.00840"
"10170","60.98400","5.08217","0.00896"
"10212","61.23600","5.10310","0.00872"
"10254","61.48800","5.12414","0.00878"
"10296","61.74000","5.14507","0.00884"
"10338","61.99200","5.16623","0.00850"
"10380","62.24400","5.18710","0.00832"
"10422","62.49600","5.20821","0.00822"
"10464","62.74800","5.22919","0.00901"
"10506","63.00000","5.25018","0.00892"
"10548","63.25200","5.27116","0.00846"
"10590","63.50400","5.29215","0.00865"
"10632","63.75600","5.31320","0.00883"
"10674","64.00800","5.33418","0.00817"
"10716","64.26000","5.35523","0.00861"
"10758","64.51200","5.37609","0.00876"
"10800","64.76400","5.39720","0.00838"
"10842","65.01600","5.41819","0.00888"
"10884","65.26800","5.43917","0.00845"
"10926","65.52000","5.46010","0.00875"
"10968","65.77200","5.48115","0.00804"
"11010","66.02400","5.50213","0.00886"
"11052","66.27600","5.52324","0.00895"
"11094","66.52800","5.54416","0.00881"
"11136","66.78000","5.56521","0.00851"
"11178","67.03200","5.58620","0.00886"
"11220","67.28400","5.60718","0.00873"
"11262","67.53600","5.62817","0.00879"
"11304","67.78800","5.64915","0.00869"
"11346","68.04000","5.67014","0.00887"
"11388","68.29200","5.69113","0.00878"
"11430","68.54400","5.71217","0.00840"
"11472","68.79600","5.73316","0.00862"
"11514","69.04800","5.75420","0.00833"
"11556","69.30000","5.77519","0.00870"
"11598","69.55200","5.79618","0.00824"
"11640","69.80400","5.81710","0.00869"
"11682","70.05600","5.83821","0.00925"
"11724","70.30800","5.85913","0.00828"
"11766","70.56000","5.88024","0.00818"
"11808","70.81200","5.90117","0.00813"
"11850","71.06400","5.92221","0.00861"
"11892","71.31600","5.94320","0.00848"
"11934","71.56800","5.96413","0.00886"
"11976","71.82000","5.98523","0.00872"
"12018","72.07200","6.00616","0.00836"
"12060","72.32400","6.02720","0.00853"
"12102","72.57600","6.04813","0.00879"
"12144","72.82800","6.06918","0.00904"
"12186","73.08000","6.09010","0.00853"
"12228","73.33200","6.11121","0.00851"
"12270","73.58400","6.13213","0.00858"
"12312","73.83600","6.15312","0.00830"
"12354","74.08800","6.17411","0.00919"
"12396","74.34000","6.19515","0.00884"
"12438","74.59200","6.21614","0.00826"
"12480","74.84400","6.23718","0.00907"
"12522","75.09600","6.25817","0.00884"
"12564","75.34800","6.27916","0.00904"
"12606","75.60000","6.30014","0.00919"
"12648","75.85200","6.32119","0.00915"
"12690","76.10400","6.34223","0.00896"
"12732","76.35600","6.36316","0.00942"
"12774","76.60800","6.38421","0.00875"
"12816","76.86000","6.40513","0.00825"
"12858","77.11200","6.42618","0.00921"
"12900","77.36400","6.44717","0.00854"
"12942","77.61600","6.46821","0.00890"
"12984","77.86800","6.48914","0.00854"
"13026","78.12000","6.51018","0.00854"
"13068","78.37200","6.53117","0.00858"
"13110","78.62400","6.55222","0.00866"
"13152","78.87600","6.57314","0.00838"
"13194","79.12800","6.59419","0.00865"
"13236","79.38000","6.61517","0.00932"
"13278","79.63200","6.63616","0.00908"
"13320","79.88400","6.65721","0.00910"
"13362","80.13600","6.67807","0.00940"
"13404","80.38800","6.69918","0.00909"
"13446","80.64000","6.72016","0.00916"
"13488","80.89200","6.74115","0.00870"
"13530","81.14400","6.76214","0.00905"
"13572","81.39600","6.78318","0.00931"
"13614","81.64800","6.80417","0.00902"
"13656","81.90000","6.82521","0.00895"
"13698","82.15200","6.84614","0.00872"
"13740","82.40400","6.86719","0.00889"
"13782","82.65600","6.88817","0.00842"
"13824","82.90800","6.90916","0.00906"
"13866","83.16000","6.93015","0.00855"
"13908","83.41200","6.95119","0.00909"
"13950","83.66400","6.97218","0.00902"
"13992","83.91600","6.99316","0.00864"
"14034","84.16800","7.01415","0.00907"
"14076","84.42000","7.03514","0.00949"
"14118","84.67200","7.05624","0.00954"
"14160","84.92400","7.07717","0.00896"
"14202","85.17600","7.09815","0.00900"
"14244","85.42800","7.11914","0.00950"
"14286","85.68000","7.14019","0.00910"
"14328","85.93200","7.16117","0.00938"
"14370","86.18400","7.18216","0.00901"
"14412","86.43600","7.20314","0.00943"
"14454","86.68800","7.22425","0.00903"
"14496","86.94000","7.24518","0.00933"
"14538","87.19200","7.26616","0.00914"
"14580","87.44400","7.28721","0.00956"
"14622","87.69600","7.30814","0.00936"
"14664","87.94800","7.32924","0.00920"
"14706","88.20000","7.35011","0.00976"
"14748","88.45200","7.37121","0.01013"
"14790","88.70400","7.39214","0.00943"
"14832","88.95600","7.41324","0.00997"
"14874","89.20800","7.43417","0.00969"
"14916","89.46000","7.45516","0.00938"
"14958","89.71200","7.47608","0.00991"
"15000","89.96400","7.49725","0.00925"
"15042","90.21600","7.51812","0.00942"
"15084","90.46800","7.53916","0.01017"
"15126","90.72000","7.56015","0.00991"
"15168","90.97200","7.58113","0.00979"
"15210","91.22400","7.60218","0.00967"
"15252","91.47600","7.62317","0.00966"
"15294","91.72800","7.64415","0.00937"
"15336","91.98000","7.66520","0.00973"
"15378","92.23200","7.68618","0.00973"
"15420","92.48400","7.70711","0.00933"
"15462","92.73600","7.72816","0.00919"
"15504","92.98800","7.74914","0.01005"
"15546","93.24000","7.77013","0.00941"
"15588","93.49200","7.79111","0.00946"
"15630","93.74400","7.81216","0.00985"
"15672","93.99600","7.83315","0.00962"
"15714","94.24800","7.85419","0.01008"
"15756","94.50000","7.87512","0.00973"
"15798","94.75200","7.89616","0.00953"
"15840","95.00400","7.91721","0.00995"
"15882","95.25600","7.93820","0.01041"
"15924","95.50800","7.95918","0.01056"
"15966","95.76000","7.98017","0.00978"
"16008","96.01200","8.00115","0.01028"
"16050","96.26400","8.02214","0.00992"
"16092","96.51600","8.04319","0.00968"
"16134","96.76800","8.06411","0.01041"
"16176","97.02000","8.08522","0.01030"
"16218","97.27200","8.10614","0.00973"
"16260","97.52400","8.12719","0.00748"
"16302","97.77600","8.14812","0.01115"
"16344","98.02800","8.16922","0.00847"
"16386","98.28000","8.19021","0.00965"
"16428","98.53200","8.21119","0.00876"
"16470","98.78400","8.23218","0.00863"
"16512","99.03600","8.25317","0.00954"
"16554","99.28800","8.27421","0.00890"
"16596","99.54000","8.29514","0.00970"
"16638","99.79200","8.31619","0.00917"
"16680","100.04400","8.33711","0.00886"
"16722","100.29600","8.35816","0.01001"
"16764","100.54800","8.37908","0.00942"
"16806","100.80000","8.40019","0.00886"
"16848","101.05200","8.42118","0.00888"
"16890","101.30400","8.44222","0.00968"
"16932","101.55600","8.46315","0.00973"
"16974","101.80800","8.48419","0.00689"
"17016","102.06000","8.50518","0.00870"
"17058","102.31200","8.52623","0.00819"
"17100","102.56400","8.54715","0.00879"
"17142","102.81600","8.56820","0.00760"
"17184","103.06800","8.58913","0.00863"
"17226","103.32000","8.61017","0.00774"
"17268","103.57200","8.63122","0.00808"
"17310","103.82400","8.65220","0.00490"
"17352","104.07600","8.67319","0.00588"
"17394","104.32800","8.69411","0.00487"
"17436","104.58000","8.71516","0.00553"
"17478","104.83200","8.73615","0.00502"
"17520","105.08400","8.75719","0.00475"
"17562","105.33600","8.77812","0.00541"
"17604","105.58800","8.79922","0.00501"
"17646","105.84000","8.82015","0.00477"
"17688","106.09200","8.84120","0.00514"
"17730","106.34400","8.86212","0.00541"
"17772","106.59600","8.88317","0.00573"
"17814","106.84800","8.90416","0.00538"
"17856","107.10000","8.92514","0.00555"
"17898","107.35200","8.94619","0.00598"
"17940","107.60400","8.96717","0.00554"
"17982","107.85600","8.98822","0.00549"
"18024","108.10800","9.00915","0.00599"
"18066","108.36000","9.03019","0.00591"
"18108","108.61200","9.05112","0.00612"
"18150","108.86400","9.07216","0.00434"
"18192","109.11600","9.09309","0.00617"
"18234","109.36800","9.11420","0.00496"
"18276","109.62000","9.13518","0.00619"
"18318","109.87200","9.15617","0.00561"
"18360","110.12400","9.17715","0.00560"
"18402","110.37600","9.19820","0.00550"
"18444","110.62800","9.21919","0.00582"
"18486","110.88000","9.24017","0.00677"
"18528","111.13200","9.26110","0.00613"
"18570","111.38400","9.28215","0.00627"
"18612","111.63600","9.30313","0.00544"
"18654","111.88800","9.32418","0.00601"
"18696","112.14000","9.34522","0.00581"
"18738","112.39200","9.36615","0.00615"
"18780","112.64400","9.38726","0.00625"
"18822","112.89600","9.40812","0.00664"
"18864","113.14800","9.42917","0.00664"
"18906","113.40000","9.45010","0.00616"
"18948","113.65200","9.47120","0.00712"
"18990","113.90400","9.49213","0.00616"
"19032","114.15600","9.51323","0.00647"
"19074","114.40800","9.53416","0.00647"
"19116","114.66000","9.55520","0.00715"
"19158","114.91200","9.57619","0.00721"
"19200","115.16400","9.59718","0.00711"
"19242","115.41600","9.61816","0.00692"
"19284","115.66800","9.63915","0.00764"
"19326","115.92000","9.66019","0.00755"
"19368","116.17200","9.68112","0.00742"
"19410","116.42400","9.70223","0.00710"
"19452","116.67600","9.72315","0.00754"
"19494","116.92800","9.74420","0.00775"
"19536","117.18000","9.76513","0.00733"
"19578","117.43200","9.78617","0.00765"
"19620","117.68400","9.80716","0.00795"
"19662","117.93600","9.82826","0.00790"
"19704","118.18800","9.84919","0.00781"
"19746","118.44000","9.87012","0.00755"
"19788","118.69200","9.89116","0.00778"
"19830","118.94400","9.91221","0.00835"
"19872","119.19600","9.93313","0.00763"
"19914","119.44800","9.95418","0.00788"
"19956","119.70000","9.97517","0.00764"
"19998","119.95200","9.99615","0.00820"
"20040","120.20400","10.01720","0.00841"
"20082","120.45600","10.03812","0.00807"
"20124","120.70800","10.05917","0.00823"
"20166","120.96000","10.08016","0.00771"
"20208","121.21200","10.10120","0.00823"
"20250","121.46400","10.12213","0.00841"
"20292","121.71600","10.14323","0.00813"
"20334","121.96800","10.16416","0.00854"
"20376","122.22000","10.18521","0.00792"
"20418","122.47200","10.20613","0.00782"
"20460","122.72400","10.22718","0.00846"
"20502","122.97600","10.24823","0.00813"
"20544","123.22800","10.26915","0.00758"
"20586","123.48000","10.29020","0.00842"
"20628","123.73200","10.31118","0.00884"
"20670","123.98400","10.33223","0.00772"
"20712","124.23600","10.35316","0.00847"
"20754","124.48800","10.37420","0.00814"
"20796","124.74000","10.39513","0.00834"
"20838","124.99200","10.41617","0.00862"
"20880","125.24400","10.43716","0.00811"
"20922","125.49600","10.45815","0.00874"
"20964","125.74800","10.47913","0.00908"
"21006","126.00000","10.50018","0.00879"
"21048","126.25200","10.52116","0.00865"
"21090","126.50400","10.54215","0.00870"
"21132","126.75600","10.56320","0.00880"
"21174","127.00800","10.58418","0.00870"
"21216","127.26000","10.60517","0.00881"
"21258","127.51200","10.62615","0.00902"
"21300","127.76400","10.64720","0.00922"
"21342","128.01601","10.66813","0.00891"
"21384","128.26801","10.68917","0.00868"
"21426","128.52000","10.71010","0.00883"
"21468","128.77200","10.73120","0.00884"
"21510","129.02400","10.75213","0.00923"
"21552","129.27600","10.77318","0.00940"
"21594","129.52800","10.79410","0.00936"
"21636","129.78000","10.81521","0.00955"
"21678","130.03200","10.83619","0.00911"
"21720","130.28400","10.85724","0.00937"
"21762","130.53600","10.87817","0.00948"
"21804","130.78799","10.89921","0.00958"
"21846","131.03999","10.92020","0.00930"
"21888","131.29201","10.94119","0.00987"
"21930","131.54401","10.96217","0.00957"
"21972","131.79601","10.98310","0.00953"
"22014","132.04800","11.00420","0.01065"
"22056","132.30000","11.02513","0.01008"
"22098","132.55200","11.04618","0.01022"
"22140","132.80400","11.06716","0.01031"
"22182","133.05600","11.08821","0.01007"
"22224","133.30800","11.10919","0.01014"
"22266","133.56000","11.13018","0.01009"
"22308","133.81200","11.15117","0.01040"
"22350","134.06400","11.17215","0.01048"
"22392","134.31599","11.19320","0.01090"
"22434","134.56799","11.21418","0.01039"
"22476","134.82001","11.23517","0.01095"
"22518","135.07201","11.25622","0.01056"
"22560","135.32401","11.27720","0.01082"
"22602","135.57600","11.29819","0.01087"
"22644","135.82800","11.31917","0.01134"
"22686","136.08000","11.34016","0.01112"
"22728","136.33200","11.36121","0.01084"
"22770","136.58400","11.38213","0.01086"
"22812","136.83600","11.40318","0.01111"
"22854","137.08800","11.42411","0.01136"
"22896","137.34000","11.44521","0.01108"
"22938","137.59200","11.46614","0.01083"
"22980","137.84399","11.48718","0.01076"
"23022","138.09599","11.50817","0.01116"
"23064","138.34801","11.52922","0.01024"
"23106","138.60001","11.55020","0.01033"
"23148","138.85201","11.57119","0.00997"
"23190","139.10400","11.59211","0.01022"
"23232","139.35600","11.61316","0.01044"
"23274","139.60800","11.63421","0.00975"
"23316","139.86000","11.65513","0.01010"
"23358","140.11200","11.67624","0.01101"
"23400","140.36400","11.69711","0.01093"
"23442","140.61600","11.71821","0.01094"
"23484","140.86800","11.73914","0.01072"
"23526","141.12000","11.76018","0.01113"
"23568","141.37199","11.78117","0.01053"
"23610","141.62399","11.80221","0.01036"
"23652","141.87601","11.82314","0.01021"
"23694","142.12801","11.84419","0.00845"
"23736","142.38000","11.86517","0.00784"
"23778","142.63200","11.88622","0.00851"
"23820","142.88400","11.90721","0.00782"
"23862","143.13600","11.92813","0.00841"
"23904","143.38800","11.94918","0.00804"
"23946","143.64000","11.97016","0.00840"
"23988","143.89200","11.99115","0.00895"
"24030","144.14400","12.01214","0.00859"
"24072","144.39600","12.03318","0.00885"
"24114","144.64799","12.05411","0.00910"
"24156","144.89999","12.07521","0.00867"
"24198","145.15199","12.09614","0.00887"
"24240","145.40401","12.11719","0.00916"
"24282","145.65601","12.13817","0.00872"
"24324","145.90800","12.15922","0.00893"
"24366","146.16000","12.18014","0.00876"
"24408","146.41200","12.20119","0.00923"
"24450","146.66400","12.22218","0.00951"
"24492","146.91600","12.24322","0.00942"
"24534","147.16800","12.26415","0.00865"
"24576","147.42000","12.28513","0.00926"
"24618","147.67200","12.30618","0.00971"
"24660","147.92400","12.32717","0.00988"
"24702","148.17599","12.34821","0.00974"
"24744","148.42799","12.36914","0.00955"
"24786","148.67999","12.39019","0.00885"
"24828","148.93201","12.41117","0.00931"
"24870","149.18401","12.43222","0.00944"
"24912","149.43600","12.45314","0.00944"
"24954","149.68800","12.47419","0.00937"
"24996","149.94000","12.49512","0.00963"
"25038","150.19200","12.51616","0.00899"
"25080","150.44400","12.53715","0.00996"
"25122","150.69600","12.55819","0.00910"
"25164","150.94800","12.57924","0.00898"
"25206","151.20000","12.60017","0.00979"
"25248","151.45200","12.62121","0.00950"
"25290","151.70399","12.64214","0.00957"
"25332","151.95599","12.66318","0.00926"
"25374","152.20799","12.68411","0.00985"
"25416","152.46001","12.70516","0.00978"
"25458","152.71201","12.72614","0.00909"
"25500","152.96400","12.74719","0.00939"
"25542","153.21600","12.76817","0.00939"
"25584","153.46800","12.78922","0.00955"
"25626","153.72000","12.81015","0.00911"
"25668","153.97200","12.83125","0.00871"
"25710","154.22400","12.85218","0.00961"
"25752","154.47600","12.87316","0.00902"
"25794","154.72800","12.89409","0.00936"
"25836","154.98000","12.91520","0.00896"
"25878","155.23199","12.93618","0.00910"
"25920","155.48399","12.95723","0.00979"
"25962","155.73599","12.97822","0.00932"
"26004","155.98801","12.99914","0.00928"
"26046","156.24001","13.02019","0.00936"
"26088","156.49200","13.04111","0.00991"
"26130","156.74400","13.06216","0.00952"
"26172","156.99600","13.08315","0.00993"
"26214","157.24800","13.10419","0.00967"
"26256","157.50000","13.12512","0.00968"
"26298","157.75200","13.14622","0.00923"
"26340","158.00400","13.16715","0.00970"
"26382","158.25600","13.18820","0.00992"
"26424","158.50800","13.20912","0.00985"
"26466","158.75999","13.23017","0.00966"
"26508","159.01199","13.25121","0.00939"
"26550","159.26401","13.27214","0.00415"
"26592","159.51601","13.29319","0.00612"
"26634","159.76801","13.31417","0.00881"
"26676","160.02000","13.33522","0.00892"
"26718","160.27200","13.35614","0.00933"
"26760","160.52400","13.37719","0.00722"
"26802","160.77600","13.39812","0.00917"
"26844","161.02800","13.41922","0.00887"
"26886","161.28000","13.44015","0.00913"
"26928","161.53200","13.46120","0.00882"
"26970","161.78400","13.48212","0.00887"
"27012","162.03600","13.50323","0.00951"
"27054","162.28799","13.52421","0.00897"
"27096","162.53999","13.54520","0.00865"
"27138","162.79201","13.56612","0.00886"
"27180","163.04401","13.58711","0.00993"
"27222","163.29601","13.60822","0.00922"
"27264","163.54800","13.62914","0.00910"
"27306","163.80000","13.65019","0.00955"
"27348","164.05200","13.67112","0.01016"
"27390","164.30400","13.69222","0.00987"
"27432","164.55600","13.71309","0.00965"
"27474","164.80800","13.73419","0.00986"
"27516","165.06000","13.75518","0.01009"
"27558","165.31200","13.77623","0.00959"
"27600","165.56400","13.79715","0.01055"
"27642","165.81599","13.81820","0.01023"
"27684","166.06799","13.83913","0.01016"
"27726","166.32001","13.86023","0.01047"
"27768","166.57201","13.88122","0.01025"
"27810","166.82401","13.90214","0.01053"
"27852","167.07600","13.92319","0.01122"
"27894","167.32800","13.94412","0.01088"
"27936","167.58000","13.96522","0.01064"
"27978","167.83200","13.98609","0.01086"
"28020","168.08400","14.00719","0.01114"
"28062","168.33600","14.02818","0.01098"
"28104","168.58800","14.04922","0.01130"
"28146","168.84000","14.07015","0.01116"
"28188","169.09200","14.09120","0.01127"
"28230","169.34399","14.11212","0.01131"
"28272","169.59599","14.13323","0.01181"
"28314","169.84801","14.15416","0.01150"
"28356","170.10001","14.17520","0.01200"
"28398","170.35201","14.19619","0.01168"
"28440","170.60400","14.21717","0.01208"
"28482","170.85600","14.23816","0.01070"
"28524","171.10800","14.25915","0.01102"
"28566","171.36000","14.28019","0.01126"
"28608","171.61200","14.30118","0.01118"
"28650","171.86400","14.32216","0.01067"
"28692","172.11600","14.34315","0.01138"
"28734","172.36800","14.36414","0.01111"
"28776","172.62000","14.38512","0.01158"
"28818","172.87199","14.40617","0.01213"
"28860","173.12399","14.42716","0.01196"
"28902","173.37601","14.44820","0.01167"
"28944","173.62801","14.46919","0.01169"
"28986","173.88000","14.49017","0.01181"
"29028","174.13200","14.51116","0.01227"
"29070","174.38400","14.53220","0.01187"
"29112","174.63600","14.55325","0.01196"
"29154","174.88800","14.57418","0.01192"
"29196","175.14000","14.59516","0.01190"
"29238","175.39200","14.61615","0.01221"
"29280","175.64400","14.63720","0.01253"
"29322","175.89600","14.65812","0.01228"
"29364","176.14799","14.67923","0.01189"
"29406","176.39999","14.70015","0.01293"
"29448","176.65199","14.72120","0.01183"
"29490","176.90401","14.74219","0.01200"
"29532","177.15601","14.76317","0.01218"
"29574","177.40800","14.78410","0.01267"
"29616","177.66000","14.80520","0.01224"
"29658","177.91200","14.82619","0.01260"
"29700","178.16400","14.84718","0.01265"
"29742","178.41600","14.86816","0.01243"
"29784","178.66800","14.88915","0.01247"
"29826","178.92000","14.91020","0.01241"
"29868","179.17200","14.93112","0.01204"
"29910","179.42400","14.95223","0.01249"
"29952","179.67599","14.97315","0.01255"
"29994","179.92799","14.99420","0.01274"
"30036","180.17999","15.01513","0.01293"
"30078","180.43201","15.03617","0.01207"
"30120","180.68401","15.05716","0.01307"
"30162","180.93600","15.07820","0.01281"
"30204","181.18800","15.09913","0.01257"
"30246","181.44000","15.12018","0.01253"
"30288","181.69200","15.14116","0.01260"
"30330","181.94400","15.16227","0.01345"
"30372","182.19600","15.18313","0.01346"
"30414","182.44800","15.20418","0.01270"
"30456","182.70000","15.22523","0.01332"
"30498","182.95200","15.24621","0.01349"
"30540","183.20399","15.26720","0.01313"
"30582","183.45599","15.28813","0.01340"
"30624","183.70799","15.30917","0.01370"
"30666","183.96001","15.33016","0.01367"
"30708","184.21201","15.35120","0.01381"
"30750","184.46400","15.37213","0.01348"
"30792","184.71600","15.39317","0.01397"
"30834","184.96800","15.41410","0.01377"
"30876","185.22000","15.43521","0.01449"
"30918","185.47200","15.45613","0.01379"
"30960","185.72400","15.47718","0.01429"
"31002","185.97600","15.49822","0.01452"
"31044","186.22800","15.51921","0.01445"
"31086","186.48000","15.54014","0.01442"
"31128","186.73199","15.56118","0.01455"
"31170","186.98399","15.58217","0.01423"
"31212","187.23599","15.60316","0.01471"
"31254","187.48801","15.62420","0.01484"
"31296","187.74001","15.64519","0.01486"
"31338","187.99200","15.66617","0.01446"
"31380","188.24400","15.68716","0.01459"
"31422","188.49600","15.70820","0.01474"
"31464","188.74800","15.72913","0.01503"
"31506","189.00000","15.75018","0.01520"
"31548","189.25200","15.77116","0.01525"
"31590","189.50400","15.79221","0.01530"
"31632","189.75600","15.81313","0.01534"
"31674","190.00800","15.83418","0.01518"
"31716","190.25999","15.85517","0.01479"
"31758","190.51199","15.87615","0.01547"
"31800","190.76401","15.89714","0.01516"
"31842","191.01601","15.91819","0.01521"
"31884","191.26801","15.93923","0.01559"
"31926","191.52000","15.96010","0.01585"
"31968","191.77200","15.98120","0.01562"
"32010","192.02400","16.00213","0.01588"
"32052","192.27600","16.02324","0.01538"
"32094","192.52800","16.04410","0.01563"
"32136","192.78000","16.06515","0.01609"
"32178","193.03200","16.08614","0.01611"
"32220","193.28400","16.10718","0.01595"
"32262","193.53600","16.12811","0.01613"
"32304","193.78799","16.14921","0.01649"
"32346","194.03999","16.17020","0.01632"
"32388","194.29201","16.19124","0.01658"
"32430","194.54401","16.21217","0.01687"
"32472","194.79601","16.23316","0.01637"
"32514","195.04800","16.25420","0.01705"
"32556","195.30000","16.27519","0.01728"
"32598","195.55200","16.29618","0.01675"
"32640","195.80400","16.31710","0.01722"
"32682","196.05600","16.33815","0.01725"
"32724","196.30800","16.35919","0.01729"
"32766","196.56000","16.38024","0.01750"
"32808","196.81200","16.40117","0.01789"
"32850","197.06400","16.42221","0.01822"
"32892","197.31599","16.44314","0.01774"
"32934","197.56799","16.46418","0.01810"
"32976","197.82001","16.48511","0.01830"
"33018","198.07201","16.50616","0.01827"
"33060","198.32401","16.52714","0.01837"
"33102","198.57600","16.54825","0.01836"
"33144","198.82800","16.56918","0.01910"
"33186","199.08000","16.59016","0.01882"
"33228","199.33200","16.61121","0.01900"
"33270","199.58400","16.63213","0.01914"
"33312","199.83600","16.65318","0.01920"
"33354","200.08800","16.67410","0.01946"
"33396","200.34000","16.69521","0.01885"
"33438","200.59200","16.71614","0.01906"
"33480","200.84399","16.73718","0.01896"
"33522","201.09599","16.75817","0.01882"
"33564","201.34801","16.77921","0.01916"
"33606","201.60001","16.80014","0.01923"
"33648","201.85201","16.82119","0.01862"
"33690","202.10400","16.84211","0.01903"
"33732","202.35600","16.86316","0.01917"
"33774","202.60800","16.88421","0.01989"
"33816","202.86000","16.90513","0.02006"
"33858","203.11200","16.92618","0.02007"
"33900","203.36400","16.94716","0.01957"
"33942","203.61600","16.96821","0.01988"
"33984","203.86800","16.98908","0.02060"
"34026","204.12000","17.01018","0.02079"
"34068","204.37199","17.03111","0.02098"
"34110","204.62399","17.05221","0.02129"
"34152","204.87601","17.07320","0.02109"
"34194","205.12801","17.09425","0.02154"
"34236","205.38000","17.11517","0.02152"
"34278","205.63200","17.13622","0.02142"
"34320","205.88400","17.15714","0.02161"
"34362","206.13600","17.17813","0.02183"
"34404","206.38800","17.19912","0.02245"
"34446","206.64000","17.22022","0.02252"
"34488","206.89200","17.24121","0.02258"
"34530","207.14400","17.26213","0.02275"
"34572","207.39600","17.28318","0.02373"
"34614","207.64799","17.30417","0.02363"
"34656","207.89999","17.32521","0.02414"
"34698","208.15199","17.34608","0.02404"
"34740","208.40401","17.36719","0.02462"
"34782","208.65601","17.38811","0.02433"
"34824","208.90800","17.40922","0.02440"
"34866","209.16000","17.43014","0.02526"
"34908","209.41200","17.45125","0.02564"
"34950","209.66400","17.47218","0.02598"
"34992","209.91600","17.49322","0.02611"
"35034","210.16800","17.51415","0.02641"
"35076","210.42000","17.53513","0.02691"
"35118","210.67200","17.55618","0.02729"
"35160","210.92400","17.57722","0.02767"
"35202","211.17599","17.59821","0.02799"
"35244","211.42799","17.61914","0.02762"
"35286","211.67999","17.64024","0.02818"
"35328","211.93201","17.66117","0.02819"
"35370","212.18401","17.68222","0.02899"
"35412","212.43600","17.70314","0.02923"
"35454","212.68800","17.72419","0.02960"
"35496","212.94000","17.74512","0.03026"
"35538","213.19200","17.76616","0.03053"
"35580","213.44400","17.78715","0.03107"
"35622","213.69600","17.80819","0.03126"
"35664","213.94800","17.82918","0.03042"
"35706","214.20000","17.85016","0.03070"
"35748","214.45200","17.87115","0.03024"
"35790","214.70399","17.89220","0.03183"
"35832","214.95599","17.91324","0.03224"
"35874","215.20799","17.93411","0.03312"
"35916","215.46001","17.95516","0.03309"
"35958","215.71201","17.97608","0.03348"
"36000","215.96400","17.99719","0.03443"
"36042","216.21600","18.01811","0.03484"
"36084","216.46800","18.03916","0.03541"
"36126","216.72000","18.06015","0.03613"
"36168","216.97200","18.08119","0.03707"
"36210","217.22400","18.10218","0.03686"
"36252","217.47600","18.12322","0.03757"
"36294","217.72800","18.14421","0.03772"
"36336","217.98000","18.16520","0.03865"
"36378","218.23199","18.18618","0.03873"
"36420","218.48399","18.20711","0.03783"
"36462","218.73599","18.22816","0.01941"
"36504","218.98801","18.24920","0.01570"
"36546","219.24001","18.27025","0.02126"
"36588","219.49200","18.29111","0.01707"
"36630","219.74400","18.31222","0.01879"
"36672","219.99600","18.33315","0.01961"
"36714","220.24800","18.35419","0.01749"
"36756","220.50000","18.37512","0.01442"
"36798","220.75200","18.39616","0.01330"
"36840","221.00400","18.41715","0.01232"
"36882","221.25600","18.43820","0.01229"
"36924","221.50800","18.45912","0.01339"
"36966","221.75999","18.48017","0.01262"
"37008","222.01199","18.50121","0.01309"
"37050","222.26401","18.52220","0.01279"
"37092","222.51601","18.54319","0.01291"
"37134","222.76801","18.56417","0.01365"
"37176","223.02000","18.58516","0.01246"
"37218","223.27200","18.60620","0.01337"
"37260","223.52400","18.62713","0.01340"
"37302","223.77600","18.64812","0.01329"
"37344","224.02800","18.66922","0.01365"
"37386","224.28000","18.69015","0.01359"
"37428","224.53200","18.71119","0.01363"
"37470","224.78400","18.73212","0.01459"
"37512","225.03600","18.75323","0.01409"
"37554","225.28799","18.77415","0.01404"
"37596","225.53999","18.79520","0.01429"
"37638","225.79201","18.81618","0.01397"
"37680","226.04401","18.83723","0.01443"
"37722","226.29601","18.85828","0.01448"
"37764","226.54800","18.87920","0.01497"
"37806","226.80000","18.90013","0.01485"
"37848","227.05200","18.92111","0.01473"
"37890","227.30400","18.94222","0.01516"
"37932","227.55600","18.96315","0.01494"
"37974","227.80800","18.98419","0.01472"
"38016","228.06000","19.00512","0.00933"
"38058","228.31200","19.02617","0.01096"
"38100","228.56400","19.04715","0.01046"
"38142","228.81599","19.06814","0.01159"
"38184","229.06799","19.08918","0.01174"
"38226","229.32001","19.11017","0.01111"
"38268","229.57201","19.13116","0.01047"
"38310","229.82401","19.15214","0.01259"
"38352","230.07600","19.17313","0.01178"
"38394","230.32800","19.19417","0.01078"
"38436","230.58000","19.21522","0.01118"
"38478","230.83200","19.23615","0.01209"
"38520","231.08400","19.25713","0.01179"
"38562","231.33600","19.27818","0.01065"
"38604","231.58800","19.29922","0.01130"
"38646","231.84000","19.32009","0.01160"
"38688","232.09200","19.34120","0.01163"
"38730","232.34399","19.36218","0.01031"
"38772","232.59599","19.38323","0.01204"
"38814","232.84801","19.40415","0.01177"
"38856","233.10001","19.42520","0.01169"
"38898","233.35201","19.44613","0.01136"
"38940","233.60400","19.46717","0.01223"
"38982","233.85600","19.48816","0.01194"
"39024","234.10800","19.50915","0.01225"
"39066","234.36000","19.53019","0.01211"
"39108","234.61200","19.55118","0.01210"
"39150","234.86400","19.57216","0.01222"
"39192","235.11600","19.59309","0.01181"
"39234","235.36800","19.61419","0.01237"
"39276","235.62000","19.63518","0.01292"
"39318","235.87199","19.65617","0.01233"
"39360","236.12399","19.67710","0.01164"
"39402","236.37601","19.69820","0.01259"
"39444","236.62801","19.71913","0.01140"
"39486","236.88000","19.74017","0.01115"
"39528","237.13200","19.76116","0.01159"
"39570","237.38400","19.78220","0.01138"
"39612","237.63600","19.80319","0.01176"
"39654","237.88800","19.82418","0.01139"
"39696","238.14000","19.84516","0.01196"
"39738","238.39200","19.86615","0.01226"
"39780","238.64400","19.88719","0.01219"
"39822","238.89600","19.90818","0.01195"
"39864","239.14799","19.92917","0.01159"
"39906","239.39999","19.95015","0.01126"
"39948","239.65199","19.97126","0.00588"
"39990","239.90401","19.99213","0.00770"
"40032","240.15601","20.01317","0.00496"
"40074","240.40800","20.03410","0.00530"
"40116","240.66000","20.05520","0.00580"
"40158","240.91200","20.07613","0.00553"
"40200","241.16400","20.09718","0.00485"
"40242","241.41600","20.11810","0.00457"
"40284","241.66800","20.13921","0.00539"
"40326","241.92000","20.16019","0.00628"
"40368","242.17200","20.18118","0.00541"
"40410","242.42400","20.20217","0.00556"
"40452","242.67599","20.22315","0.00593"
"40494","242.92799","20.24426","0.00554"
"40536","243.17999","20.26513","0.00494"
"40578","243.43201","20.28617","0.00523"
"40620","243.68401","20.30716","0.00548"
"40662","243.93600","20.32820","0.00546"
"40704","244.18800","20.34913","0.00566"
"40746","244.44000","20.37017","0.00535"
"40788","244.69200","20.39116","0.00561"
"40830","244.94400","20.41221","0.00528"
"40872","245.19600","20.43313","0.00589"
"40914","245.44800","20.45418","0.00548"
"40956","245.70000","20.47517","0.00552"
"40998","245.95200","20.49621","0.00585"
"41040","246.20399","20.51714","0.00577"
"41082","246.45599","20.53818","0.00503"
"41124","246.70799","20.55917","0.00544"
"41166","246.96001","20.58022","0.00562"
"41208","247.21201","20.60120","0.00546"
"41250","247.46400","20.62213","0.00568"
"41292","247.71600","20.64317","0.00484"
"41334","247.96800","20.66416","0.00466"
"41376","248.22000","20.68521","0.00556"
"41418","248.47200","20.70619","0.00496"
"41460","248.72400","20.72724","0.00504"
"41502","248.97600","20.74817","0.00521"
"41544","249.22800","20.76921","0.00538"
"41586","249.48000","20.79007","0.00498"
"41628","249.73199","20.81118","0.00582"
"41670","249.98399","20.83223","0.00506"
"41712","250.23599","20.85321","0.00501"
"41754","250.48801","20.87414","0.00542"
"41796","250.74001","20.89513","0.00531"
"41838","250.99200","20.91617","0.00448"
"41880","251.24400","20.93716","0.00553"
"41922","251.49600","20.95821","0.00523"
"41964","251.74800","20.97913","0.00470"
"42006","252.00000","21.00024","0.00509"
"42048","252.25200","21.02110","0.00506"
"42090","252.50400","21.04221","0.00498"
"42132","252.75600","21.06314","0.00527"
"42174","253.00800","21.08424","0.00518"
"42216","253.25999","21.10517","0.00536"
"42258","253.51199","21.12615","0.00529"
"42300","253.76401","21.14714","0.00593"
"42342","254.01601","21.16818","0.00551"
"42384","254.26801","21.18917","0.00530"
"42426","254.52000","21.21016","0.00542"
"42468","254.77200","21.23120","0.00550"
"42510","255.02400","21.25219","0.00500"
"42552","255.27600","21.27324","0.00494"
"42594","255.52800","21.29410","0.00563"
"42636","255.78000","21.31515","0.00530"
"42678","256.03201","21.33613","0.00568"
"42720","256.28400","21.35718","0.00559"
"42762","256.53601","21.37817","0.00516"
"42804","256.78799","21.39915","0.00524"
"42846","257.04001","21.42014","0.00534"
"42888","257.29199","21.44124","0.00548"
"42930","257.54401","21.46211","0.00561"
"42972","257.79599","21.48315","0.00550"
"43014","258.04800","21.50414","0.00526"
"43056","258.29999","21.52519","0.00487"
"43098","258.55200","21.54618","0.00535"
"43140","258.80399","21.56716","0.00502"
"43182","259.05600","21.58815","0.00523"
"43224","259.30801","21.60919","0.00542"
"43266","259.56000","21.63018","0.00552"
"43308","259.81201","21.65111","0.00540"
"43350","260.06400","21.67215","0.00587"
"43392","260.31601","21.69314","0.00582"
"43434","260.56799","21.71418","0.00572"
"43476","260.82001","21.73517","0.00558"
"43518","261.07199","21.75621","0.00616"
"43560","261.32401","21.77714","0.00557"
"43602","261.57599","21.79819","0.00614"
"43644","261.82800","21.81911","0.00576"
"43686","262.07999","21.84016","0.00607"
"43728","262.33200","21.86121","0.00551"
"43770","262.58401","21.88219","0.00606"
"43812","262.83600","21.90318","0.00530"
"43854","263.08801","21.92416","0.00618"
"43896","263.34000","21.94521","0.00641"
"43938","263.59201","21.96614","0.00615"
"43980","263.84399","21.98712","0.00574"
"44022","264.09601","22.00811","0.00578"
"44064","264.34799","22.02915","0.00655"
"44106","264.60001","22.05020","0.00636"
"44148","264.85199","22.07119","0.00638"
"44190","265.10400","22.09211","0.00601"
"44232","265.35599","22.11316","0.00590"
"44274","265.60800","22.13415","0.00619"
"44316","265.85999","22.15513","0.00649"
"44358","266.11200","22.17612","0.00627"
"44400","266.36401","22.19716","0.00621"
"44442","266.61600","22.21821","0.00645"
"44484","266.86801","22.23914","0.00717"
"44526","267.12000","22.26018","0.00675"
"44568","267.37201","22.28111","0.00655"
"44610","267.62399","22.30221","0.00622"
"44652","267.87601","22.32314","0.00663"
"44694","268.12799","22.34413","0.00655"
"44736","268.38000","22.36511","0.00660"
"44778","268.63199","22.38622","0.00712"
"44820","268.88400","22.40714","0.00719"
"44862","269.13599","22.42825","0.00706"
"44904","269.38800","22.44918","0.00654"
"44946","269.64001","22.47016","0.00662"
"44988","269.89200","22.49121","0.00675"
"45030","270.14401","22.51213","0.00510"
"45072","270.39600","22.53318","0.00620"
"45114","270.64801","22.55417","0.00547"
"45156","270.89999","22.57521","0.00436"
"45198","271.15201","22.59614","0.00460"
"45240","271.40399","22.61719","0.00552"
"45282","271.65601","22.63817","0.00454"
"45324","271.90799","22.65916","0.00447"
"45366","272.16000","22.68008","0.00461"
"45408","272.41199","22.70113","0.00489"
"45450","272.66400","22.72211","0.00410"
"45492","272.91599","22.74322","0.00480"
"45534","273.16800","22.76415","0.00474"
"45576","273.42001","22.78525","0.00465"
"45618","273.67200","22.80618","0.00454"
"45660","273.92401","22.82723","0.00454"
"45702","274.17599","22.84815","0.00440"
"45744","274.42801","22.86914","0.00466"
"45786","274.67999","22.89012","0.00453"
"45828","274.93201","22.91117","0.00493"
"45870","275.18399","22.93222","0.00473"
"45912","275.43600","22.95314","0.00459"
"45954","275.68799","22.97425","0.00443"
"45996","275.94000","22.99517","0.00424"
"46038","276.19199","23.01616","0.00521"
"46080","276.44400","23.03715","0.00474"
"46122","276.69601","23.05813","0.00538"
"46164","276.94800","23.07912","0.00469"
"46206","277.20001","23.10023","0.00497"
"46248","277.45200","23.12115","0.00511"
"46290","277.70401","23.14220","0.00517"
"46332","277.95599","23.16318","0.00454"
"46374","278.20801","23.18417","0.00446"
"46416","278.45999","23.20515","0.00507"
"46458","278.71201","23.22614","0.00488"
"46500","278.96399","23.24719","0.00465"
"46542","279.21600","23.26818","0.00502"
"46584","279.46799","23.28916","0.00524"
"46626","279.72000","23.31008","0.00512"
"46668","279.97198","23.33119","0.00533"
"46710","280.22400","23.35218","0.00478"
"46752","280.47601","23.37316","0.00482"
"46794","280.72800","23.39421","0.00476"
"46836","280.98001","23.41520","0.00469"
"46878","281.23199","23.43618","0.00463"
"46920","281.48401","23.45717","0.00477"
"46962","281.73599","23.47815","0.00480"
"47004","281.98801","23.49920","0.00452"
"47046","282.23999","23.52019","0.00423"
"47088","282.49200","23.54111","0.00480"
"47130","282.74399","23.56222","0.00548"
"47172","282.99600","23.58315","0.00503"
"47214","283.24799","23.60419","0.00499"
"47256","283.50000","23.62512","0.00452"
"47298","283.75201","23.64616","0.00486"
"47340","284.00400","23.66715","0.00490"
"47382","284.25601","23.68826","0.00422"
"47424","284.50800","23.70912","0.00456"
"47466","284.76001","23.73023","0.00508"
"47508","285.01199","23.75115","0.00511"
"47550","285.26401","23.77220","0.00474"
"47592","285.51599","23.79318","0.00523"
"47634","285.76801","23.81417","0.00470"
"47676","286.01999","23.83522","0.00420"
"47718","286.27200","23.85620","0.00509"
"47760","286.52399","23.87719","0.00479"
"47802","286.77600","23.89812","0.00566"
"47844","287.02802","23.91922","0.00467"
"47886","287.28000","23.94015","0.00504"
"47928","287.53201","23.96119","0.00520"
"47970","287.78400","23.98206","0.00492"
"48012","288.03601","24.00316","0.00462"
"48054","288.28799","24.02415","0.00490"
"48096","288.54001","24.04520","0.00445"
"48138","288.79199","24.06612","0.00469"
"48180","289.04401","24.08717","0.00501"
"48222","289.29599","24.10816","0.00452"
"48264","289.54800","24.12920","0.00430"
"48306","289.79999","24.15013","0.00462"
"48348","290.05200","24.17117","0.00423"
"48390","290.30399","24.19216","0.00418"
"48432","290.55600","24.21315","0.00479"
"48474","290.80801","24.23413","0.00448"
"48516","291.06000","24.25512","0.00430"
"48558","291.31201","24.27616","0.00433"
"48600","291.56400","24.29715","0.00421"
"48642","291.81601","24.31814","0.00472"
"48684","292.06799","24.33912","0.00454"
"48726","292.32001","24.36017","0.00446"
"48768","292.57199","24.38109","0.00416"
"48810","292.82401","24.40214","0.00440"
"48852","293.07599","24.42313","0.00498"
"48894","293.32800","24.44423","0.00410"
"48936","293.57999","24.46522","0.00416"
"48978","293.83200","24.48620","0.00453"
"49020","294.08401","24.50719","0.00490"
"49062","294.33600","24.52818","0.00470"
"49104","294.58801","24.54922","0.00431"
"49146","294.84000","24.57015","0.00472"
"49188","295.09201","24.59120","0.00502"
"49230","295.34399","24.61212","0.00450"
"49272","295.59601","24.63323","0.00483"
"49314","295.84799","24.65409","0.00530"
"49356","296.10001","24.67514","0.00463"
"49398","296.35199","24.69613","0.00457"
"49440","296.60400","24.71717","0.00432"
"49482","296.85599","24.73810","0.00416"
"49524","297.10800","24.75920","0.00459"
"49566","297.35999","24.78013","0.00423"
"49608","297.61200","24.80112","0.00420"
"49650","297.86401","24.82216","0.00437"
"49692","298.11600","24.84315","0.00409"
"49734","298.36801","24.86419","0.00481"
"49776","298.62000","24.88518","0.00481"
"49818","298.87201","24.90617","0.00503"
"49860","299.12399","24.92709","0.00529"
"49902","299.37601","24.94820","0.00487"
"49944","299.62799","24.96919","0.00492"
"49986","299.88000","24.99023","0.00444"
"50028","300.13199","25.01116","0.00508"
"50070","300.38400","25.03214","0.00495"
"50112","300.63599","25.05313","0.00450"
"50154","300.88800","25.07424","0.00465"
"50196","301.14001","25.09510","0.00536"
"50238","301.39200","25.11621","0.00461"
"50280","301.64401","25.13720","0.00486"
"50322","301.89600","25.15818","0.00469"
"50364","302.14801","25.17916","0.00355"
"50406","302.39999","25.20015","0.00348"
"50448","302.65201","25.22120","0.00349"
"50490","302.90399","25.24219","0.00378"
"50532","303.15601","25.26317","0.00341"
"50574","303.40799","25.28410","0.00330"
"50616","303.66000","25.30520","0.00308"
"50658","303.91199","25.32613","0.00382"
"50700","304.16400","25.34717","0.00311"
"50742","304.41599","25.36816","0.00327"
"50784","304.66800","25.38921","0.00313"
"50826","304.92001","25.41013","0.00337"
"50868","305.17200","25.43118","0.00352"
"50910","305.42401","25.45217","0.00354"
"50952","305.67599","25.47315","0.00305"
"50994","305.92801","25.49414","0.00342"
"51036","306.17999","25.51518","0.00362"
"51078","306.43201","25.53617","0.00401"
"51120","306.68399","25.55716","0.00314"
"51162","306.93600","25.57820","0.00354"
"51204","307.18799","25.59913","0.00359"
"51235","307.37000","25.61444","0.00368"