File: Trajectories_together/170108_1Specimen_RawData_1.csv
"","V1","V2","V3"
"1","End date","1/8/2017",""
"2","Specimen label","2DG_15",""
"3","Maximum Load","0.19619","N"
"4","Time","Extension","Load"
"5","(s)","(mm)","(N)"
"6","0.00000","0.00000","0.00000"
"68","0.37200","0.03115","-0.00020"
"130","0.74400","0.06218","-0.00014"
"192","1.11600","0.09315","0.00023"
"254","1.48800","0.12424","0.00083"
"316","1.86000","0.15521","0.00041"
"378","2.23200","0.18612","0.00057"
"440","2.60400","0.21716","0.00095"
"502","2.97600","0.24819","0.00082"
"564","3.34800","0.27916","0.00083"
"626","3.72000","0.31019","0.00117"
"688","4.09200","0.34116","0.00093"
"750","4.46400","0.37219","0.00091"
"812","4.83600","0.40316","0.00134"
"874","5.20800","0.43419","0.00116"
"936","5.58000","0.46516","0.00118"
"998","5.95200","0.49613","0.00166"
"1060","6.32400","0.52716","0.00175"
"1122","6.69600","0.55820","0.00144"
"1184","7.06800","0.58917","0.00154"
"1246","7.44000","0.62026","0.00193"
"1308","7.81200","0.65117","0.00234"
"1370","8.18400","0.68214","0.00158"
"1432","8.55600","0.71317","0.00220"
"1494","8.92800","0.74420","0.00240"
"1556","9.30000","0.77517","0.00210"
"1618","9.67200","0.80614","0.00270"
"1680","10.04400","0.83723","0.00243"
"1742","10.41600","0.86814","0.00236"
"1804","10.78800","0.89912","0.00224"
"1866","11.16000","0.93021","0.00268"
"1928","11.53200","0.96118","0.00266"
"1990","11.90400","0.99215","0.00279"
"2052","12.27600","1.02318","0.00298"
"2114","12.64800","1.05421","0.00367"
"2176","13.02000","1.08512","0.00341"
"2238","13.39200","1.11615","0.00276"
"2300","13.76400","1.14724","0.00342"
"2362","14.13600","1.17815","0.00376"
"2424","14.50800","1.20918","0.00416"
"2486","14.88000","1.24021","0.00403"
"2548","15.25200","1.27119","0.00382"
"2610","15.62400","1.30216","0.00388"
"2672","15.99600","1.33325","0.00393"
"2734","16.36800","1.36422","0.00371"
"2796","16.74000","1.39513","0.00411"
"2858","17.11200","1.42616","0.00353"
"2920","17.48400","1.45725","0.00461"
"2982","17.85600","1.48810","0.00439"
"3044","18.22800","1.51919","0.00466"
"3106","18.60000","1.55022","0.00486"
"3168","18.97200","1.58113","0.00483"
"3230","19.34400","1.61216","0.00504"
"3292","19.71600","1.64320","0.00493"
"3354","20.08800","1.67423","0.00507"
"3416","20.46000","1.70514","0.00454"
"3478","20.83200","1.73623","0.00497"
"3540","21.20400","1.76720","0.00567"
"3602","21.57600","1.79811","0.00531"
"3664","21.94800","1.82920","0.00532"
"3726","22.32000","1.86023","0.00569"
"3788","22.69200","1.89114","0.00529"
"3850","23.06400","1.92217","0.00574"
"3912","23.43600","1.95320","0.00579"
"3974","23.80800","1.98418","0.00595"
"4036","24.18000","2.01515","0.00588"
"4098","24.55200","2.04618","0.00571"
"4160","24.92400","2.07721","0.00626"
"4222","25.29600","2.10812","0.00651"
"4284","25.66800","2.13921","0.00571"
"4346","26.04000","2.17018","0.00616"
"4408","26.41200","2.20109","0.00565"
"4470","26.78400","2.23218","0.00593"
"4532","27.15600","2.26327","0.00560"
"4594","27.52800","2.29418","0.00602"
"4656","27.90000","2.32516","0.00588"
"4718","28.27200","2.35625","0.00618"
"4780","28.64400","2.38716","0.00648"
"4842","29.01600","2.41819","0.00646"
"4904","29.38800","2.44922","0.00647"
"4966","29.76000","2.48019","0.00659"
"5028","30.13200","2.51116","0.00655"
"5090","30.50400","2.54219","0.00581"
"5152","30.87600","2.57322","0.00683"
"5214","31.24800","2.60419","0.00654"
"5276","31.62000","2.63522","0.00711"
"5338","31.99200","2.66625","0.00682"
"5400","32.36400","2.69711","0.00652"
"5462","32.73600","2.72814","0.00695"
"5524","33.10800","2.75923","0.00736"
"5586","33.48000","2.79014","0.00763"
"5648","33.85200","2.82117","0.00714"
"5710","34.22400","2.85220","0.00772"
"5772","34.59600","2.88317","0.00765"
"5834","34.96800","2.91420","0.00714"
"5896","35.34000","2.94523","0.00789"
"5958","35.71200","2.97620","0.00764"
"6020","36.08400","3.00711","0.00764"
"6082","36.45600","3.03820","0.00805"
"6144","36.82800","3.06918","0.00840"
"6206","37.20000","3.10015","0.00829"
"6268","37.57200","3.13124","0.00834"
"6330","37.94400","3.16215","0.00887"
"6392","38.31600","3.19318","0.00876"
"6454","38.68800","3.22415","0.00871"
"6516","39.06000","3.25518","0.00877"
"6578","39.43200","3.28615","0.00861"
"6640","39.80400","3.31718","0.00889"
"6702","40.17600","3.34821","0.00883"
"6764","40.54800","3.37918","0.00884"
"6826","40.92000","3.41016","0.00881"
"6888","41.29200","3.44119","0.00885"
"6950","41.66400","3.47222","0.00903"
"7012","42.03600","3.50319","0.00949"
"7074","42.40800","3.53416","0.00925"
"7136","42.78000","3.56525","0.00869"
"7198","43.15200","3.59610","0.00936"
"7260","43.52400","3.62719","0.00942"
"7322","43.89600","3.65822","0.00930"
"7384","44.26800","3.68913","0.00965"
"7446","44.64000","3.72016","0.00989"
"7508","45.01200","3.75120","0.00980"
"7570","45.38400","3.78211","0.00931"
"7632","45.75600","3.81320","0.00907"
"7694","46.12800","3.84423","0.00995"
"7756","46.50000","3.87520","0.00985"
"7818","46.87200","3.90617","0.01011"
"7880","47.24400","3.93720","0.00992"
"7942","47.61600","3.96823","0.00973"
"8004","47.98800","3.99914","0.01011"
"8066","48.36000","4.03023","0.01004"
"8128","48.73200","4.06120","0.01019"
"8190","49.10400","4.09211","0.00983"
"8252","49.47600","4.12315","0.00982"
"8314","49.84800","4.15418","0.00986"
"8376","50.22000","4.18515","0.00996"
"8438","50.59200","4.21618","0.01019"
"8500","50.96400","4.24721","0.01046"
"8562","51.33600","4.27824","0.01033"
"8624","51.70800","4.30909","0.01010"
"8686","52.08000","4.34024","0.01056"
"8748","52.45200","4.37121","0.01050"
"8810","52.82400","4.40212","0.01061"
"8872","53.19600","4.43321","0.01074"
"8934","53.56800","4.46419","0.01067"
"8996","53.94000","4.49522","0.01037"
"9058","54.31200","4.52619","0.01008"
"9120","54.68400","4.55722","0.01107"
"9182","55.05600","4.58819","0.01066"
"9244","55.42800","4.61910","0.01093"
"9306","55.80000","4.65025","0.01044"
"9368","56.17200","4.68116","0.01075"
"9430","56.54400","4.71219","0.01055"
"9492","56.91600","4.74316","0.01086"
"9554","57.28800","4.77419","0.01099"
"9616","57.66000","4.80517","0.01070"
"9678","58.03200","4.83620","0.01125"
"9740","58.40400","4.86717","0.01098"
"9802","58.77600","4.89814","0.01092"
"9864","59.14800","4.92917","0.01087"
"9926","59.52000","4.96020","0.01104"
"9988","59.89200","4.99123","0.01161"
"10050","60.26400","5.02220","0.01138"
"10112","60.63600","5.05323","0.01113"
"10174","61.00800","5.08426","0.01094"
"10236","61.38000","5.11517","0.01111"
"10298","61.75200","5.14620","0.01110"
"10360","62.12400","5.17718","0.01138"
"10422","62.49600","5.20815","0.01148"
"10484","62.86800","5.23918","0.01133"
"10546","63.24000","5.27021","0.01126"
"10608","63.61200","5.30118","0.01138"
"10670","63.98400","5.33227","0.01107"
"10732","64.35600","5.36312","0.01148"
"10794","64.72800","5.39415","0.01148"
"10856","65.10000","5.42518","0.01072"
"10918","65.47200","5.45621","0.01097"
"10980","65.84400","5.48718","0.01200"
"11042","66.21600","5.51821","0.01155"
"11104","66.58800","5.54919","0.01178"
"11166","66.96000","5.58016","0.01102"
"11228","67.33200","5.61119","0.01160"
"11290","67.70400","5.64222","0.01136"
"11352","68.07600","5.67319","0.01218"
"11414","68.44800","5.70416","0.01102"
"11476","68.82000","5.73519","0.01141"
"11538","69.19200","5.76616","0.01180"
"11600","69.56400","5.79719","0.01166"
"11662","69.93600","5.82816","0.01172"
"11724","70.30800","5.85925","0.01031"
"11786","70.68000","5.89017","0.01074"
"11848","71.05200","5.92114","0.01102"
"11910","71.42400","5.95223","0.01126"
"11972","71.79600","5.98320","0.01091"
"12034","72.16800","6.01417","0.01115"
"12096","72.54000","6.04520","0.01096"
"12158","72.91200","6.07617","0.01108"
"12220","73.28400","6.10714","0.01110"
"12282","73.65600","6.13817","0.01142"
"12344","74.02800","6.16920","0.01110"
"12406","74.40000","6.20011","0.01175"
"12468","74.77200","6.23115","0.01170"
"12530","75.14400","6.26218","0.01144"
"12592","75.51600","6.29315","0.01172"
"12654","75.88800","6.32418","0.01145"
"12716","76.26000","6.35521","0.01209"
"12778","76.63200","6.38624","0.01184"
"12840","77.00400","6.41709","0.01212"
"12902","77.37600","6.44818","0.01209"
"12964","77.74800","6.47921","0.01107"
"13026","78.12000","6.51012","0.01095"
"13088","78.49200","6.54121","0.01167"
"13150","78.86400","6.57219","0.01181"
"13212","79.23600","6.60316","0.01195"
"13274","79.60800","6.63413","0.01155"
"13336","79.98000","6.66522","0.01181"
"13398","80.35200","6.69619","0.01197"
"13460","80.72400","6.72716","0.01204"
"13522","81.09600","6.75825","0.01205"
"13584","81.46800","6.78916","0.01227"
"13646","81.84000","6.82013","0.01213"
"13708","82.21200","6.85122","0.01232"
"13770","82.58400","6.88219","0.01205"
"13832","82.95600","6.91311","0.01200"
"13894","83.32800","6.94420","0.01226"
"13956","83.70000","6.97517","0.01244"
"14018","84.07200","7.00620","0.01207"
"14080","84.44400","7.03711","0.01256"
"14142","84.81600","7.06820","0.01293"
"14204","85.18800","7.09917","0.01233"
"14266","85.56000","7.13014","0.01230"
"14328","85.93200","7.16123","0.01238"
"14390","86.30400","7.19220","0.01256"
"14452","86.67600","7.22317","0.01299"
"14514","87.04800","7.25420","0.01297"
"14576","87.42000","7.28524","0.01293"
"14638","87.79200","7.31615","0.01256"
"14700","88.16400","7.34718","0.01296"
"14762","88.53600","7.37821","0.01296"
"14824","88.90800","7.40912","0.01266"
"14886","89.28000","7.44015","0.01300"
"14948","89.65200","7.47124","0.01279"
"15010","90.02400","7.50215","0.01342"
"15072","90.39600","7.53312","0.01267"
"15134","90.76800","7.56421","0.01315"
"15196","91.14000","7.59518","0.01317"
"15258","91.51200","7.62621","0.01285"
"15320","91.88400","7.65725","0.01344"
"15382","92.25600","7.68822","0.01297"
"15444","92.62800","7.71913","0.01359"
"15506","93.00000","7.75022","0.01294"
"15568","93.37200","7.78119","0.01318"
"15630","93.74400","7.81216","0.01299"
"15692","94.11600","7.84319","0.01326"
"15754","94.48800","7.87422","0.01337"
"15816","94.86000","7.90513","0.01291"
"15878","95.23200","7.93616","0.01336"
"15940","95.60400","7.96719","0.01355"
"16002","95.97600","7.99823","0.01347"
"16064","96.34800","8.02920","0.01351"
"16126","96.72000","8.06023","0.01317"
"16188","97.09200","8.09114","0.01342"
"16250","97.46400","8.12217","0.01370"
"16312","97.83600","8.15320","0.01337"
"16374","98.20800","8.18417","0.01349"
"16436","98.58000","8.21514","0.01343"
"16498","98.95200","8.24617","0.01377"
"16560","99.32400","8.27720","0.01384"
"16622","99.69600","8.30817","0.01378"
"16684","100.06800","8.33920","0.01417"
"16746","100.44000","8.37024","0.01379"
"16808","100.81200","8.40115","0.01417"
"16870","101.18400","8.43212","0.01391"
"16932","101.55600","8.46321","0.01224"
"16994","101.92800","8.49418","0.01315"
"17056","102.30000","8.52515","0.01304"
"17118","102.67200","8.55618","0.01310"
"17180","103.04400","8.58721","0.01269"
"17242","103.41600","8.61812","0.01300"
"17304","103.78800","8.64921","0.01268"
"17366","104.16000","8.68024","0.01328"
"17428","104.53200","8.71110","0.01264"
"17490","104.90400","8.74219","0.01359"
"17552","105.27600","8.77322","0.01344"
"17614","105.64800","8.80413","0.01298"
"17676","106.02000","8.83516","0.01347"
"17738","106.39200","8.86619","0.01311"
"17800","106.76400","8.89722","0.01404"
"17862","107.13600","8.92813","0.01330"
"17924","107.50800","8.95922","0.01286"
"17986","107.88000","8.99025","0.01330"
"18048","108.25200","9.02110","0.01308"
"18110","108.62400","9.05219","0.01269"
"18172","108.99600","9.08317","0.01312"
"18234","109.36800","9.11420","0.01304"
"18296","109.74000","9.14517","0.01379"
"18358","110.11200","9.17620","0.01331"
"18420","110.48400","9.20723","0.01401"
"18482","110.85600","9.23814","0.01381"
"18544","111.22800","9.26923","0.01369"
"18606","111.60000","9.30020","0.01363"
"18668","111.97200","9.33111","0.01377"
"18730","112.34400","9.36220","0.01426"
"18792","112.71600","9.39324","0.01380"
"18854","113.08800","9.42415","0.01426"
"18916","113.46000","9.45518","0.01447"
"18978","113.83200","9.48621","0.01385"
"19040","114.20400","9.51718","0.01415"
"19102","114.57600","9.54815","0.01438"
"19164","114.94800","9.57918","0.01473"
"19226","115.32000","9.61021","0.01463"
"19288","115.69200","9.64118","0.01510"
"19350","116.06400","9.67227","0.01468"
"19412","116.43600","9.70318","0.01499"
"19474","116.80800","9.73415","0.01559"
"19536","117.18000","9.76513","0.01523"
"19598","117.55200","9.79616","0.01502"
"19660","117.92400","9.82713","0.01515"
"19722","118.29600","9.85816","0.01481"
"19784","118.66800","9.88925","0.01521"
"19846","119.04000","9.92016","0.01588"
"19908","119.41200","9.95113","0.01598"
"19970","119.78400","9.98222","0.01585"
"20032","120.15600","10.01319","0.01531"
"20094","120.52800","10.04416","0.01642"
"20156","120.90000","10.07519","0.01561"
"20218","121.27200","10.10623","0.01572"
"20280","121.64400","10.13714","0.01560"
"20342","122.01600","10.16817","0.01542"
"20404","122.38800","10.19920","0.01518"
"20466","122.76000","10.23011","0.01560"
"20528","123.13200","10.26120","0.01588"
"20590","123.50400","10.29223","0.01614"
"20652","123.87600","10.32314","0.01575"
"20714","124.24800","10.35423","0.01599"
"20776","124.62000","10.38514","0.01625"
"20838","124.99200","10.41623","0.01638"
"20900","125.36400","10.44714","0.01584"
"20962","125.73600","10.47818","0.01652"
"21024","126.10800","10.50921","0.01617"
"21086","126.48000","10.54018","0.01599"
"21148","126.85200","10.57115","0.01623"
"21210","127.22400","10.60218","0.01609"
"21272","127.59600","10.63315","0.01648"
"21334","127.96800","10.66424","0.01631"
"21396","128.34000","10.69521","0.01590"
"21458","128.71200","10.72618","0.01594"
"21520","129.08400","10.75715","0.01602"
"21582","129.45600","10.78818","0.01612"
"21644","129.82800","10.81916","0.01658"
"21706","130.20000","10.85019","0.01627"
"21768","130.57200","10.88122","0.01641"
"21830","130.94400","10.91219","0.01660"
"21892","131.31600","10.94316","0.01658"
"21954","131.68800","10.97425","0.01692"
"22016","132.06000","11.00522","0.01699"
"22078","132.43200","11.03613","0.01690"
"22140","132.80400","11.06716","0.01781"
"22202","133.17600","11.09819","0.01710"
"22264","133.54800","11.12910","0.01704"
"22326","133.92000","11.16019","0.01711"
"22388","134.29200","11.19123","0.01711"
"22450","134.66400","11.22220","0.01667"
"22512","135.03600","11.25323","0.01746"
"22574","135.40800","11.28414","0.01778"
"22636","135.78000","11.31523","0.01770"
"22698","136.15200","11.34620","0.01767"
"22760","136.52400","11.37717","0.01823"
"22822","136.89600","11.40826","0.01890"
"22884","137.26800","11.43911","0.01874"
"22946","137.64000","11.47020","0.01858"
"23008","138.01200","11.50123","0.01908"
"23070","138.38400","11.53214","0.01807"
"23132","138.75600","11.56324","0.01879"
"23194","139.12800","11.59421","0.01796"
"23256","139.50000","11.62512","0.01712"
"23318","139.87200","11.65615","0.01766"
"23380","140.24400","11.68718","0.01721"
"23442","140.61600","11.71821","0.01795"
"23504","140.98800","11.74912","0.01783"
"23566","141.36000","11.78021","0.01724"
"23628","141.73200","11.81124","0.01753"
"23690","142.10400","11.84215","0.01773"
"23752","142.47600","11.87325","0.01629"
"23814","142.84800","11.90422","0.01646"
"23876","143.22000","11.93513","0.01782"
"23938","143.59200","11.96616","0.01814"
"24000","143.96400","11.99725","0.01738"
"24062","144.33600","12.02816","0.01722"
"24124","144.70800","12.05913","0.01752"
"24186","145.08000","12.09022","0.01771"
"24248","145.45200","12.12119","0.01767"
"24310","145.82400","12.15210","0.01815"
"24372","146.19600","12.18319","0.01857"
"24434","146.56800","12.21416","0.01889"
"24496","146.94000","12.24514","0.01887"
"24558","147.31200","12.27623","0.01852"
"24620","147.68400","12.30726","0.01933"
"24682","148.05600","12.33817","0.01865"
"24744","148.42800","12.36914","0.01952"
"24806","148.80000","12.40023","0.01949"
"24868","149.17200","12.43114","0.01983"
"24930","149.54400","12.46217","0.01933"
"24992","149.91600","12.49320","0.02016"
"25054","150.28800","12.52417","0.01984"
"25116","150.66000","12.55514","0.02016"
"25178","151.03200","12.58623","0.02044"
"25240","151.40400","12.61715","0.01991"
"25302","151.77600","12.64818","0.02054"
"25364","152.14800","12.67921","0.01987"
"25426","152.52000","12.71030","0.01957"
"25488","152.89200","12.74115","0.01997"
"25550","153.26400","12.77218","0.02005"
"25612","153.63600","12.80321","0.02009"
"25674","154.00800","12.83418","0.02004"
"25736","154.38000","12.86521","0.02083"
"25798","154.75200","12.89618","0.01991"
"25860","155.12400","12.92715","0.02009"
"25922","155.49600","12.95819","0.02091"
"25984","155.86800","12.98916","0.02123"
"26046","156.24000","13.02019","0.02024"
"26108","156.61200","13.05116","0.02141"
"26170","156.98400","13.08225","0.02101"
"26232","157.35600","13.11316","0.02086"
"26294","157.72800","13.14407","0.02170"
"26356","158.10000","13.17522","0.02158"
"26418","158.47200","13.20619","0.02187"
"26480","158.84400","13.23716","0.02201"
"26542","159.21600","13.26819","0.02190"
"26604","159.58800","13.29923","0.02210"
"26666","159.96000","13.33020","0.02176"
"26728","160.33200","13.36123","0.02172"
"26790","160.70400","13.39226","0.02212"
"26852","161.07600","13.42317","0.02250"
"26914","161.44800","13.45414","0.02225"
"26976","161.82000","13.48517","0.02032"
"27038","162.19200","13.51614","0.02024"
"27100","162.56400","13.54711","0.02030"
"27162","162.93600","13.57826","0.01988"
"27224","163.30800","13.60923","0.02025"
"27286","163.68000","13.64015","0.01980"
"27348","164.05200","13.67118","0.01934"
"27410","164.42400","13.70221","0.01933"
"27472","164.79600","13.73312","0.01976"
"27534","165.16800","13.76421","0.01964"
"27596","165.54000","13.79518","0.02017"
"27658","165.91200","13.82615","0.02043"
"27720","166.28400","13.85718","0.02027"
"27782","166.65600","13.88821","0.02024"
"27844","167.02800","13.91918","0.02031"
"27906","167.40000","13.95015","0.02131"
"27968","167.77200","13.98118","0.02074"
"28030","168.14400","14.01221","0.02130"
"28092","168.51600","14.04313","0.02109"
"28154","168.88800","14.07422","0.02108"
"28216","169.26000","14.10519","0.02196"
"28278","169.63200","14.13616","0.02164"
"28340","170.00400","14.16719","0.02228"
"28402","170.37600","14.19822","0.02249"
"28464","170.74800","14.22919","0.02259"
"28526","171.12000","14.26010","0.02256"
"28588","171.49200","14.29119","0.02220"
"28650","171.86400","14.32222","0.02363"
"28712","172.23600","14.35320","0.02256"
"28774","172.60800","14.38423","0.02370"
"28836","172.98000","14.41520","0.02349"
"28898","173.35200","14.44617","0.02338"
"28960","173.72400","14.47714","0.02237"
"29022","174.09600","14.50817","0.02208"
"29084","174.46800","14.53914","0.02225"
"29146","174.84000","14.57011","0.02263"
"29208","175.21200","14.60120","0.02263"
"29270","175.58400","14.63217","0.02265"
"29332","175.95600","14.66314","0.02292"
"29394","176.32800","14.69417","0.02318"
"29456","176.70000","14.72521","0.02371"
"29518","177.07200","14.75618","0.02362"
"29580","177.44400","14.78715","0.02432"
"29642","177.81600","14.81818","0.02405"
"29704","178.18800","14.84915","0.02464"
"29766","178.56000","14.88018","0.02478"
"29828","178.93200","14.91121","0.02517"
"29890","179.30400","14.94212","0.02566"
"29952","179.67600","14.97321","0.02559"
"30014","180.04800","15.00418","0.02593"
"30076","180.42000","15.03521","0.02540"
"30138","180.79200","15.06619","0.02653"
"30200","181.16400","15.09722","0.02476"
"30262","181.53600","15.12825","0.02436"
"30324","181.90800","15.15916","0.02415"
"30386","182.28000","15.19019","0.02336"
"30448","182.65200","15.22122","0.02251"
"30510","183.02400","15.25213","0.02289"
"30572","183.39600","15.28316","0.02378"
"30634","183.76800","15.31419","0.02406"
"30696","184.14000","15.34516","0.02459"
"30758","184.51200","15.37619","0.02468"
"30820","184.88400","15.40717","0.02521"
"30882","185.25600","15.43820","0.02504"
"30944","185.62800","15.46917","0.02554"
"31006","186.00000","15.50020","0.02543"
"31068","186.37200","15.53123","0.02532"
"31130","186.74400","15.56214","0.02540"
"31192","187.11600","15.59317","0.02627"
"31254","187.48800","15.62420","0.02717"
"31316","187.86000","15.65517","0.02663"
"31378","188.23200","15.68620","0.02749"
"31440","188.60400","15.71717","0.02823"
"31502","188.97600","15.74814","0.02780"
"31564","189.34800","15.77917","0.02822"
"31626","189.72000","15.81021","0.02851"
"31688","190.09200","15.84118","0.02857"
"31750","190.46400","15.87221","0.02864"
"31812","190.83600","15.90324","0.02885"
"31874","191.20800","15.93415","0.02908"
"31936","191.58000","15.96512","0.02911"
"31998","191.95200","15.99621","0.02983"
"32060","192.32400","16.02718","0.02986"
"32122","192.69600","16.05815","0.02999"
"32184","193.06800","16.08918","0.03025"
"32246","193.44000","16.12021","0.03028"
"32308","193.81200","16.15113","0.03036"
"32370","194.18400","16.18216","0.03080"
"32432","194.55600","16.21325","0.03060"
"32494","194.92800","16.24416","0.03013"
"32556","195.30000","16.27519","0.03049"
"32618","195.67200","16.30616","0.03094"
"32680","196.04400","16.33713","0.03097"
"32742","196.41600","16.36816","0.03065"
"32804","196.78800","16.39925","0.03149"
"32866","197.16000","16.43022","0.03112"
"32928","197.53200","16.46113","0.03190"
"32990","197.90400","16.49223","0.03192"
"33052","198.27600","16.52325","0.03202"
"33114","198.64800","16.55411","0.03102"
"33176","199.02000","16.58520","0.03153"
"33238","199.39200","16.61617","0.03203"
"33300","199.76400","16.64720","0.03226"
"33362","200.13600","16.67817","0.03286"
"33424","200.50800","16.70920","0.03281"
"33486","200.88000","16.74017","0.03345"
"33548","201.25200","16.77120","0.03359"
"33610","201.62400","16.80223","0.03406"
"33672","201.99600","16.83315","0.03423"
"33734","202.36800","16.86411","0.03499"
"33796","202.74000","16.89521","0.03493"
"33858","203.11200","16.92618","0.03500"
"33920","203.48400","16.95721","0.03502"
"33982","203.85600","16.98818","0.03477"
"34044","204.22800","17.01921","0.03550"
"34106","204.60000","17.05018","0.03338"
"34168","204.97200","17.08109","0.03394"
"34230","205.34400","17.11218","0.03374"
"34292","205.71600","17.14321","0.03451"
"34354","206.08800","17.17413","0.03544"
"34416","206.46000","17.20522","0.03595"
"34478","206.83200","17.23619","0.03697"
"34540","207.20400","17.26716","0.03753"
"34602","207.57600","17.29819","0.03814"
"34664","207.94800","17.32928","0.03882"
"34726","208.32000","17.36013","0.03952"
"34788","208.69200","17.39116","0.04098"
"34850","209.06400","17.42225","0.04227"
"34912","209.43600","17.45310","0.04331"
"34974","209.80800","17.48419","0.04428"
"35036","210.18000","17.51516","0.04387"
"35098","210.55200","17.54614","0.04547"
"35160","210.92400","17.57717","0.04713"
"35222","211.29600","17.60820","0.04694"
"35284","211.66800","17.63917","0.04019"
"35346","212.04000","17.67014","0.03435"
"35408","212.41200","17.70123","0.03475"
"35470","212.78400","17.73226","0.03622"
"35532","213.15600","17.76311","0.03617"
"35594","213.52800","17.79420","0.03694"
"35656","213.90000","17.82517","0.03714"
"35718","214.27200","17.85614","0.03822"
"35780","214.64400","17.88723","0.03875"
"35842","215.01600","17.91815","0.03310"
"35904","215.38800","17.94918","0.03209"
"35966","215.76000","17.98021","0.03211"
"36028","216.13200","18.01124","0.03247"
"36090","216.50400","18.04221","0.03226"
"36152","216.87600","18.07312","0.03218"
"36214","217.24800","18.10421","0.03180"
"36276","217.62000","18.13518","0.02957"
"36338","217.99200","18.16609","0.02848"
"36400","218.36400","18.19724","0.02717"
"36462","218.73600","18.22816","0.02754"
"36524","219.10800","18.25918","0.02729"
"36586","219.48000","18.29022","0.02748"
"36648","219.85200","18.32113","0.02648"
"36710","220.22400","18.35216","0.02595"
"36772","220.59600","18.38319","0.02482"
"36834","220.96800","18.41422","0.02505"
"36896","221.34000","18.44513","0.02466"
"36958","221.71200","18.47616","0.02165"
"37020","222.08400","18.50719","0.02204"
"37082","222.45600","18.53816","0.02160"
"37144","222.82800","18.56913","0.02085"
"37206","223.20000","18.60017","0.01861"
"37268","223.57200","18.63126","0.01762"
"37330","223.94400","18.66211","0.01843"
"37392","224.31600","18.69320","0.01963"
"37454","224.68800","18.72423","0.01976"
"37516","225.06000","18.75514","0.01987"
"37578","225.43200","18.78617","0.01845"
"37640","225.80400","18.81720","0.01968"
"37702","226.17600","18.84817","0.02052"
"37764","226.54800","18.87920","0.02086"
"37826","226.92000","18.91023","0.02062"
"37888","227.29200","18.94114","0.02151"
"37950","227.66400","18.97212","0.02169"
"38012","228.03600","19.00321","0.02208"
"38074","228.40800","19.03424","0.02227"
"38136","228.78000","19.06515","0.02305"
"38198","229.15200","19.09618","0.02364"
"38260","229.52400","19.12715","0.02391"
"38322","229.89600","19.15818","0.02420"
"38384","230.26800","19.18915","0.02369"
"38446","230.64000","19.22018","0.02433"
"38508","231.01200","19.25121","0.02462"
"38570","231.38400","19.28218","0.02419"
"38632","231.75600","19.31322","0.02464"
"38694","232.12800","19.34425","0.02487"
"38756","232.50000","19.37510","0.02527"
"38818","232.87200","19.40619","0.02508"
"38880","233.24400","19.43722","0.02532"
"38942","233.61600","19.46813","0.02607"
"39004","233.98800","19.49916","0.02606"
"39066","234.36000","19.53019","0.02637"
"39128","234.73200","19.56116","0.02667"
"39190","235.10400","19.59213","0.02648"
"39252","235.47600","19.62316","0.02676"
"39314","235.84800","19.65413","0.02695"
"39376","236.22000","19.68516","0.02668"
"39438","236.59200","19.71619","0.02779"
"39500","236.96400","19.74717","0.02777"
"39562","237.33600","19.77820","0.02776"
"39624","237.70800","19.80917","0.02851"
"39686","238.08000","19.84026","0.02827"
"39748","238.45200","19.87117","0.02858"
"39810","238.82400","19.90214","0.02876"
"39872","239.19600","19.93323","0.02901"
"39934","239.56800","19.96414","0.02850"
"39996","239.94000","19.99517","0.02916"
"40058","240.31200","20.02615","0.02852"
"40120","240.68400","20.05718","0.02876"
"40182","241.05600","20.08821","0.02888"
"40244","241.42800","20.11918","0.02956"
"40306","241.80000","20.15021","0.02936"
"40368","242.17200","20.18118","0.02897"
"40430","242.54400","20.21221","0.02953"
"40492","242.91600","20.24324","0.02980"
"40554","243.28800","20.27415","0.02996"
"40616","243.66000","20.30518","0.03009"
"40678","244.03200","20.33621","0.02999"
"40740","244.40400","20.36719","0.03024"
"40802","244.77600","20.39822","0.03031"
"40864","245.14800","20.42913","0.03098"
"40926","245.52000","20.46016","0.03069"
"40988","245.89200","20.49119","0.03091"
"41050","246.26400","20.52216","0.03119"
"41112","246.63600","20.55319","0.03130"
"41174","247.00800","20.58416","0.03134"
"41236","247.38000","20.61519","0.03180"
"41298","247.75200","20.64616","0.03175"
"41360","248.12400","20.67713","0.03226"
"41422","248.49600","20.70816","0.03221"
"41484","248.86800","20.73920","0.03265"
"41546","249.24000","20.77017","0.03277"
"41608","249.61200","20.80114","0.03315"
"41670","249.98400","20.83217","0.03234"
"41732","250.35600","20.86314","0.03280"
"41794","250.72800","20.89417","0.03240"
"41856","251.10000","20.92526","0.03229"
"41918","251.47200","20.95617","0.03211"
"41980","251.84400","20.98714","0.03211"
"42042","252.21600","21.01823","0.03226"
"42104","252.58800","21.04921","0.03231"
"42166","252.96000","21.08017","0.03245"
"42228","253.33200","21.11121","0.03248"
"42290","253.70400","21.14218","0.03224"
"42352","254.07600","21.17309","0.03213"
"42414","254.44800","21.20418","0.03251"
"42476","254.82000","21.23521","0.03313"
"42538","255.19200","21.26612","0.03361"
"42600","255.56400","21.29721","0.03389"
"42662","255.93600","21.32824","0.03411"
"42724","256.30800","21.35915","0.03466"
"42786","256.68000","21.39018","0.03567"
"42848","257.05200","21.42121","0.03620"
"42910","257.42400","21.45219","0.03716"
"42972","257.79600","21.48310","0.03821"
"43034","258.16800","21.51419","0.03839"
"43096","258.54000","21.54522","0.03961"
"43158","258.91200","21.57613","0.04139"
"43220","259.28400","21.60722","0.04085"
"43282","259.65600","21.63825","0.03895"
"43344","260.02800","21.66916","0.04044"
"43406","260.40000","21.70013","0.04075"
"43468","260.77200","21.73116","0.04363"
"43530","261.14400","21.76219","0.04384"
"43592","261.51600","21.79317","0.04602"
"43654","261.88800","21.82420","0.04715"
"43716","262.26000","21.85517","0.04810"
"43778","262.63200","21.88614","0.04905"
"43840","263.00400","21.91723","0.05004"
"43902","263.37600","21.94826","0.05058"
"43964","263.74800","21.97917","0.05158"
"44026","264.12000","22.01020","0.05164"
"44088","264.49200","22.04123","0.04143"
"44150","264.86400","22.07220","0.04274"
"44212","265.23600","22.10317","0.03858"
"44274","265.60800","22.13420","0.03615"
"44336","265.98000","22.16518","0.03738"
"44398","266.35200","22.19615","0.03825"
"44460","266.72400","22.22718","0.04034"
"44522","267.09600","22.25821","0.04178"
"44584","267.46800","22.28912","0.04265"
"44646","267.84000","22.32021","0.04348"
"44708","268.21200","22.35124","0.04425"
"44770","268.58400","22.38215","0.04492"
"44832","268.95600","22.41318","0.04490"
"44894","269.32800","22.44421","0.04563"
"44956","269.70000","22.47512","0.04361"
"45018","270.07200","22.50621","0.04465"
"45080","270.44400","22.53724","0.04472"
"45142","270.81600","22.56816","0.04092"
"45204","271.18800","22.59919","0.04268"
"45266","271.56000","22.63016","0.04333"
"45328","271.93200","22.66119","0.04450"
"45390","272.30400","22.69216","0.04516"
"45452","272.67600","22.72325","0.04571"
"45514","273.04800","22.75416","0.04711"
"45576","273.42000","22.78514","0.04693"
"45638","273.79200","22.81622","0.04844"
"45700","274.16400","22.84720","0.04930"
"45762","274.53600","22.87816","0.05049"
"45824","274.90800","22.90920","0.05146"
"45886","275.28000","22.94017","0.05258"
"45948","275.65200","22.97120","0.05372"
"46010","276.02400","23.00217","0.05365"
"46072","276.39600","23.03320","0.05447"
"46134","276.76800","23.06417","0.05512"
"46196","277.14000","23.09514","0.05601"
"46258","277.51200","23.12623","0.05559"
"46320","277.88400","23.15714","0.05658"
"46382","278.25600","23.18812","0.05683"
"46444","278.62800","23.21921","0.05749"
"46506","279.00000","23.25018","0.05702"
"46568","279.37200","23.28115","0.05735"
"46630","279.74400","23.31218","0.05829"
"46692","280.11600","23.34321","0.05943"
"46754","280.48800","23.37418","0.06014"
"46816","280.86000","23.40515","0.06029"
"46878","281.23200","23.43624","0.06117"
"46940","281.60400","23.46715","0.06218"
"47002","281.97600","23.49812","0.06336"
"47064","282.34800","23.52921","0.06471"
"47126","282.72000","23.56018","0.06542"
"47188","283.09200","23.59116","0.06674"
"47250","283.46400","23.62219","0.06704"
"47312","283.83600","23.65322","0.06811"
"47374","284.20800","23.68413","0.06880"
"47436","284.58000","23.71522","0.07028"
"47498","284.95200","23.74625","0.07058"
"47560","285.32400","23.77710","0.07132"
"47622","285.69600","23.80819","0.07166"
"47684","286.06800","23.83916","0.06976"
"47746","286.44000","23.87013","0.07131"
"47808","286.81200","23.90117","0.07182"
"47870","287.18400","23.93220","0.07312"
"47932","287.55600","23.96323","0.07381"
"47994","287.92800","23.99420","0.07414"
"48056","288.30000","24.02523","0.07305"
"48118","288.67200","24.05620","0.07271"
"48180","289.04400","24.08717","0.03999"
"48242","289.41600","24.11820","0.03942"
"48304","289.78800","24.14923","0.03626"
"48366","290.16000","24.18014","0.03360"
"48428","290.53200","24.21117","0.03466"
"48490","290.90400","24.24220","0.04173"
"48552","291.27600","24.27324","0.04359"
"48614","291.64800","24.30409","0.04232"
"48676","292.02000","24.33524","0.04588"
"48738","292.39200","24.36621","0.05074"
"48800","292.76400","24.39712","0.05085"
"48862","293.13600","24.42821","0.04931"
"48924","293.50800","24.45924","0.05199"
"48986","293.88000","24.49015","0.05501"
"49048","294.25200","24.52118","0.05616"
"49110","294.62400","24.55215","0.05485"
"49172","294.99600","24.58318","0.05652"
"49234","295.36800","24.61415","0.05709"
"49296","295.74000","24.64519","0.05787"
"49358","296.11200","24.67616","0.05822"
"49420","296.48400","24.70713","0.05960"
"49482","296.85600","24.73822","0.06187"
"49544","297.22800","24.76919","0.06384"
"49606","297.60000","24.80016","0.06410"
"49668","297.97200","24.83113","0.06438"
"49730","298.34400","24.86222","0.06623"
"49792","298.71600","24.89314","0.06832"
"49854","299.08800","24.92416","0.06929"
"49916","299.46000","24.95520","0.06860"
"49978","299.83200","24.98616","0.06906"
"50040","300.20400","25.01720","0.07053"
"50102","300.57600","25.04817","0.07145"
"50164","300.94800","25.07920","0.06716"
"50226","301.32000","25.11017","0.06754"
"50288","301.69200","25.14126","0.06863"
"50350","302.06400","25.17223","0.06976"
"50412","302.43600","25.20314","0.07152"
"50474","302.80800","25.23417","0.07103"
"50536","303.18000","25.26520","0.07252"
"50598","303.55200","25.29612","0.07356"
"50660","303.92400","25.32726","0.07441"
"50722","304.29600","25.35818","0.07544"
"50784","304.66800","25.38915","0.07544"
"50846","305.04000","25.42018","0.07558"
"50908","305.41200","25.45121","0.07558"
"50970","305.78400","25.48218","0.07650"
"51032","306.15600","25.51315","0.07678"
"51094","306.52800","25.54418","0.07705"
"51156","306.90000","25.57521","0.07741"
"51218","307.27200","25.60612","0.07642"
"51280","307.64400","25.63715","0.07733"
"51342","308.01600","25.66818","0.07809"
"51404","308.38800","25.69921","0.07809"
"51466","308.76000","25.73019","0.07867"
"51528","309.13200","25.76128","0.07909"
"51590","309.50400","25.79213","0.07949"
"51652","309.87600","25.82316","0.07981"
"51714","310.24800","25.85425","0.08003"
"51776","310.62000","25.88516","0.08044"
"51838","310.99200","25.91619","0.08092"
"51900","311.36400","25.94722","0.08155"
"51962","311.73600","25.97813","0.08220"
"52024","312.10800","26.00910","0.08250"
"52086","312.48000","26.04025","0.08343"
"52148","312.85200","26.07117","0.08315"
"52210","313.22400","26.10214","0.08428"
"52272","313.59600","26.13323","0.08631"
"52334","313.96800","26.16420","0.08712"
"52396","314.34000","26.19511","0.08909"
"52458","314.71200","26.22620","0.08971"
"52520","315.08400","26.25723","0.09135"
"52582","315.45600","26.28815","0.09367"
"52644","315.82800","26.31923","0.09428"
"52706","316.20000","26.35021","0.09687"
"52768","316.57200","26.38117","0.09845"
"52830","316.94400","26.41214","0.10090"
"52892","317.31600","26.44318","0.10309"
"52954","317.68800","26.47421","0.10455"
"53016","318.06000","26.50512","0.10701"
"53078","318.43200","26.53615","0.10897"
"53140","318.80400","26.56724","0.11063"
"53202","319.17600","26.59809","0.11261"
"53264","319.54800","26.62924","0.11563"
"53326","319.92000","26.66021","0.11418"
"53388","320.29200","26.69113","0.11719"
"53450","320.66400","26.72215","0.11941"
"53512","321.03600","26.75319","0.12247"
"53574","321.40800","26.78422","0.12443"
"53636","321.78000","26.81513","0.12741"
"53698","322.15200","26.84622","0.12928"
"53760","322.52400","26.87719","0.13157"
"53822","322.89600","26.90816","0.13223"
"53884","323.26800","26.93919","0.13354"
"53946","323.64000","26.97016","0.13475"
"54008","324.01200","27.00119","0.13527"
"54070","324.38400","27.03216","0.13600"
"54132","324.75600","27.06319","0.13743"
"54194","325.12800","27.09417","0.13818"
"54256","325.50000","27.12514","0.13891"
"54318","325.87200","27.15617","0.13918"
"54380","326.24400","27.18720","0.13975"
"54442","326.61600","27.21817","0.14058"
"54504","326.98800","27.24920","0.14111"
"54566","327.36000","27.28023","0.14174"
"54628","327.73200","27.31114","0.14290"
"54690","328.10400","27.34217","0.14389"
"54752","328.47600","27.37320","0.14538"
"54814","328.84800","27.40417","0.14832"
"54876","329.22000","27.43521","0.14973"
"54938","329.59200","27.46618","0.15196"
"55000","329.96400","27.49709","0.15296"
"55062","330.33600","27.52824","0.15548"
"55124","330.70800","27.55921","0.15733"
"55186","331.08000","27.59018","0.15884"
"55248","331.45200","27.62121","0.16093"
"55310","331.82400","27.65218","0.16254"
"55372","332.19600","27.68321","0.16370"
"55434","332.56800","27.71418","0.16632"
"55496","332.94000","27.74521","0.16751"
"55558","333.31200","27.77618","0.16877"
"55620","333.68400","27.80716","0.17116"
"55682","334.05600","27.83819","0.17289"
"55744","334.42800","27.86916","0.17382"
"55806","334.80000","27.90019","0.17481"
"55868","335.17200","27.93122","0.17637"
"55930","335.54400","27.96219","0.17709"
"55992","335.91600","27.99316","0.17810"
"56054","336.28800","28.02413","0.17907"
"56116","336.66000","28.05522","0.17991"
"56178","337.03200","28.08619","0.18090"
"56240","337.40400","28.11722","0.18166"
"56302","337.77600","28.14820","0.18262"
"56364","338.14800","28.17917","0.18371"
"56426","338.52000","28.21014","0.18464"
"56488","338.89200","28.24123","0.18566"
"56550","339.26400","28.27220","0.18619"
"56612","339.63600","28.30317","0.18714"
"56674","340.00800","28.33414","0.18715"
"56736","340.38000","28.36523","0.18825"
"56798","340.75200","28.39614","0.18911"
"56860","341.12400","28.42717","0.19052"
"56922","341.49600","28.45820","0.19064"
"56984","341.86800","28.48918","0.19179"
"57046","342.24000","28.52015","0.19263"
"57108","342.61200","28.55124","0.19377"
"57170","342.98400","28.58221","0.19497"
"57232","343.35600","28.61312","0.19581"
"57294","343.72800","28.64421","0.07372"
"57356","344.10000","28.67530","0.07136"
"57418","344.47200","28.70609","0.07534"
"57480","344.84400","28.73718","0.07249"
"57542","345.21600","28.76821","0.06820"
"57604","345.58800","28.79906","0.07790"
"57666","345.96000","28.83022","0.06997"
"57728","346.33200","28.86119","0.07155"
"57790","346.70400","28.89216","0.07742"
"57852","347.07600","28.92313","0.07439"
"57914","347.44800","28.95422","0.07425"
"57976","347.82000","28.98519","0.07770"
"58038","348.19200","29.01616","0.07617"
"58100","348.56400","29.04719","0.07663"
"58162","348.93600","29.07816","0.07808"
"58224","349.30800","29.10913","0.07591"
"58286","349.68000","29.14022","0.07790"
"58348","350.05200","29.17119","0.07852"
"58410","350.42400","29.20217","0.07702"
"58472","350.79600","29.23314","0.07827"
"58534","351.16800","29.26417","0.07911"
"58596","351.54000","29.29520","0.07831"
"58658","351.91200","29.32617","0.07901"
"58720","352.28400","29.35720","0.07984"
"58782","352.65600","29.38823","0.07914"
"58844","353.02800","29.41914","0.07964"
"58906","353.40000","29.45023","0.08030"
"58968","353.77200","29.48120","0.07965"
"59030","354.14400","29.51211","0.07995"
"59092","354.51600","29.54321","0.08110"
"59154","354.88800","29.57418","0.08072"
"59216","355.26000","29.60521","0.08044"
"59278","355.63200","29.63612","0.08169"
"59340","356.00400","29.66721","0.08194"
"59402","356.37600","29.69818","0.08139"
"59464","356.74800","29.72915","0.08218"
"59526","357.12000","29.76018","0.08338"
"59588","357.49200","29.79115","0.08316"
"59650","357.86400","29.82218","0.08337"
"59712","358.23600","29.85315","0.08413"
"59774","358.60800","29.88419","0.08539"
"59836","358.98000","29.91515","0.08494"
"59898","359.35200","29.94619","0.08604"
"59960","359.72400","29.97728","0.08702"
"60022","360.09600","30.00813","0.08701"
"60084","360.46800","30.03916","0.08770"
"60146","360.84000","30.07019","0.08814"
"60208","361.21200","30.10116","0.08982"
"60270","361.58400","30.13213","0.08978"
"60332","361.95600","30.16322","0.09092"
"60394","362.32800","30.19419","0.09181"
"60456","362.70000","30.22516","0.09307"
"60518","363.07200","30.25620","0.09331"
"60580","363.44400","30.28723","0.09419"
"60642","363.81600","30.31814","0.09583"
"60704","364.18800","30.34923","0.09638"
"60766","364.56000","30.38020","0.09687"
"60828","364.93200","30.41117","0.09787"
"60890","365.30400","30.44220","0.09919"
"60952","365.67600","30.47317","0.10018"
"61014","366.04800","30.50414","0.10035"
"61076","366.42000","30.53517","0.10022"
"61138","366.79200","30.56620","0.10101"
"61200","367.16400","30.59718","0.10291"
"61262","367.53600","30.62815","0.10335"
"61324","367.90800","30.65918","0.10405"
"61386","368.28000","30.69021","0.10470"
"61448","368.65200","30.72118","0.10471"
"61510","369.02400","30.75221","0.10598"
"61572","369.39600","30.78324","0.10636"
"61634","369.76800","30.81409","0.10825"
"61696","370.14000","30.84518","0.10920"
"61758","370.51200","30.87621","0.11003"
"61820","370.88400","30.90718","0.11067"
"61882","371.25600","30.93815","0.11145"
"61944","371.62800","30.96924","0.11341"
"62006","372.00000","31.00016","0.11424"
"62068","372.37200","31.03113","0.11436"
"62130","372.74400","31.06222","0.11549"
"62192","373.11600","31.09325","0.11669"
"62254","373.48800","31.12416","0.11623"
"62316","373.86000","31.15519","0.11725"
"62378","374.23200","31.18622","0.11859"
"62440","374.60400","31.21707","0.11866"
"62502","374.97600","31.24822","0.12082"
"62564","375.34800","31.27925","0.12118"
"62626","375.72000","31.31016","0.12301"
"62688","376.09200","31.34119","0.12398"
"62750","376.46400","31.37216","0.12416"
"62812","376.83600","31.40314","0.12585"
"62874","377.20800","31.43417","0.12712"
"62936","377.58000","31.46520","0.12807"
"62998","377.95200","31.49623","0.12920"
"63060","378.32400","31.52708","0.12985"
"63122","378.69600","31.55817","0.13049"
"63184","379.06800","31.58920","0.13145"
"63246","379.44000","31.62011","0.13293"
"63308","379.81200","31.65120","0.13417"
"63370","380.18400","31.68223","0.13408"
"63432","380.55600","31.71315","0.13482"
"63494","380.92800","31.74417","0.13529"
"63556","381.30000","31.77521","0.13601"
"63618","381.67200","31.80618","0.13639"
"63680","382.04400","31.83715","0.13632"
"63742","382.41600","31.86824","0.13682"
"63804","382.78800","31.89915","0.01514"
"63866","383.16000","31.93012","0.00946"
"63928","383.53200","31.96121","0.01792"
"63990","383.90400","31.99218","0.00635"
"64052","384.27600","32.02316","0.00411"
"64114","384.64800","32.05418","0.01452"
"64176","385.02000","32.08521","0.00804"
"64238","385.39200","32.11613","0.00560"
"64300","385.76400","32.14710","0.00959"
"64362","386.13600","32.17819","0.01468"
"64424","386.50800","32.20916","0.00999"
"64486","386.88000","32.24019","0.00638"
"64548","387.25200","32.27122","0.01040"
"64610","387.62400","32.30213","0.01390"
"64672","387.99600","32.33316","0.00759"
"64734","388.36800","32.36419","0.00742"
"64796","388.74000","32.39523","0.01156"
"64858","389.11200","32.42613","0.01202"
"64920","389.48400","32.45716","0.00848"
"64982","389.85600","32.48826","0.00841"
"65044","390.22800","32.51911","0.01278"
"65106","390.60000","32.55020","0.01148"
"65168","390.97200","32.58117","0.00926"
"65230","391.34400","32.61214","0.01039"
"65292","391.71600","32.64317","0.01100"
"65354","392.08800","32.67414","0.01165"
"65416","392.46000","32.70517","0.01055"
"65478","392.83200","32.73621","0.01081"
"65540","393.20400","32.76723","0.01106"
"65602","393.57600","32.79821","0.01073"
"65664","393.94800","32.82912","0.01159"
"65726","394.32000","32.86021","0.01123"
"65788","394.69200","32.89118","0.01080"
"65850","395.06400","32.92215","0.01181"
"65912","395.43600","32.95324","0.01177"
"65974","395.80800","32.98415","0.01093"
"66036","396.18000","33.01518","0.01062"
"66098","396.55200","33.04615","0.01186"
"66160","396.92400","33.07718","0.01165"
"66222","397.29600","33.10822","0.01134"
"66284","397.66800","33.13918","0.01172"
"66346","398.04000","33.17022","0.01201"
"66408","398.41200","33.20119","0.01200"
"66470","398.78400","33.23215","0.01212"
"66532","399.15600","33.26319","0.01199"
"66594","399.52800","33.29416","0.01174"
"66656","399.90000","33.32513","0.01236"
"66718","400.27200","33.35616","0.01133"
"66780","400.64400","33.38719","0.01244"
"66842","401.01600","33.41816","0.01233"
"66904","401.38800","33.44920","0.01205"
"66966","401.76000","33.48022","0.01253"
"67028","402.13200","33.51120","0.01266"
"67090","402.50400","33.54217","0.01276"
"67152","402.87600","33.57320","0.01248"
"67214","403.24800","33.60417","0.01265"
"67276","403.62000","33.63520","0.01298"
"67338","403.99200","33.66617","0.01303"
"67400","404.36400","33.69726","0.01246"
"67462","404.73600","33.72805","0.01311"
"67524","405.10800","33.75920","0.01344"
"67586","405.48000","33.79023","0.01311"
"67648","405.85200","33.82114","0.01330"
"67710","406.22400","33.85218","0.01275"
"67772","406.59600","33.88321","0.01341"
"67834","406.96800","33.91418","0.01311"
"67896","407.34000","33.94515","0.01361"
"67958","407.71200","33.97618","0.01368"
"68020","408.08400","34.00721","0.01364"
"68082","408.45600","34.03812","0.01337"
"68144","408.82800","34.06921","0.01406"
"68206","409.20000","34.10024","0.01421"
"68268","409.57200","34.13115","0.01379"
"68330","409.94400","34.16219","0.01434"
"68392","410.31600","34.19321","0.01458"
"68454","410.68800","34.22419","0.01423"
"68516","411.06000","34.25516","0.01463"
"68578","411.43200","34.28619","0.01486"
"68640","411.80400","34.31722","0.01514"
"68702","412.17600","34.34813","0.01470"
"68764","412.54800","34.37916","0.01473"
"68826","412.92000","34.41019","0.01491"
"68888","413.29200","34.44116","0.01562"
"68950","413.66400","34.47219","0.01546"
"69012","414.03600","34.50322","0.01579"
"69074","414.40800","34.53413","0.01548"
"69136","414.78000","34.56522","0.01577"
"69198","415.15200","34.59620","0.01583"
"69260","415.52400","34.62717","0.01570"
"69322","415.89600","34.65814","0.01633"
"69384","416.26800","34.68923","0.01610"
"69446","416.64000","34.72014","0.01662"
"69508","417.01200","34.75117","0.01667"
"69570","417.38400","34.78220","0.01674"
"69632","417.75600","34.81317","0.01653"
"69694","418.12800","34.84420","0.01711"
"69756","418.50000","34.87523","0.01653"
"69818","418.87200","34.90620","0.01698"
"69880","419.24400","34.93718","0.01732"
"69942","419.61600","34.96815","0.01717"
"70004","419.98800","34.99924","0.01765"
"70066","420.36000","35.03015","0.01743"
"70128","420.73200","35.06118","0.01824"
"70190","421.10400","35.09221","0.01847"
"70252","421.47600","35.12318","0.01871"
"70314","421.84800","35.15421","0.01849"
"70376","422.22000","35.18518","0.01882"
"70438","422.59200","35.21615","0.01876"
"70500","422.96400","35.24712","0.01866"
"70562","423.33600","35.27822","0.01892"
"70624","423.70800","35.30919","0.01855"
"70686","424.08000","35.34010","0.01956"
"70748","424.45200","35.37125","0.01954"
"70810","424.82400","35.40216","0.02031"
"70872","425.19600","35.43319","0.02002"
"70934","425.56800","35.46422","0.02084"
"70996","425.94000","35.49513","0.02033"
"71058","426.31200","35.52617","0.02112"
"71120","426.68400","35.55719","0.02105"
"71182","427.05600","35.58817","0.02030"
"71244","427.42800","35.61914","0.02141"
"71306","427.80000","35.65017","0.02074"
"71368","428.17200","35.68119","0.02114"
"71430","428.54400","35.71217","0.02087"
"71492","428.91600","35.74314","0.02234"
"71554","429.28800","35.77423","0.02224"
"71616","429.66000","35.80520","0.02222"
"71678","430.03200","35.83611","0.02278"
"71740","430.40400","35.86714","0.02236"
"71802","430.77600","35.89824","0.02320"
"71864","431.14800","35.92914","0.02304"
"71926","431.52000","35.96017","0.02354"
"71988","431.89200","35.99121","0.02329"
"72050","432.26400","36.02212","0.02416"
"72112","432.63600","36.05315","0.02447"
"72174","433.00800","36.08424","0.02424"
"72236","433.38000","36.11521","0.02487"
"72298","433.75200","36.14618","0.02409"
"72360","434.12400","36.17721","0.02467"
"72422","434.49600","36.20818","0.02415"
"72484","434.86800","36.23909","0.02427"
"72546","435.24000","36.27024","0.02485"
"72608","435.61200","36.30122","0.02447"
"72670","435.98400","36.33213","0.02478"
"72732","436.35600","36.36322","0.02506"
"72794","436.72800","36.39419","0.02535"
"72856","437.10000","36.42516","0.02535"
"72918","437.47200","36.45619","0.02521"
"72980","437.84400","36.48722","0.02564"
"73042","438.21600","36.51819","0.02522"
"73104","438.58800","36.54910","0.02558"
"73166","438.96000","36.58019","0.02645"
"73228","439.33200","36.61123","0.02618"
"73290","439.70400","36.64207","0.02696"
"73352","440.07600","36.67323","0.02703"
"73414","440.44800","36.70426","0.02726"
"73476","440.82000","36.73516","0.02761"
"73538","441.19200","36.76614","0.02811"
"73600","441.56400","36.79717","0.02779"
"73662","441.93600","36.82814","0.02805"
"73724","442.30800","36.85917","0.02814"
"73786","442.68000","36.89026","0.02813"
"73848","443.05200","36.92117","0.02899"
"73910","443.42400","36.95214","0.02889"
"73972","443.79600","36.98317","0.02884"
"74034","444.16800","37.01421","0.02890"
"74096","444.54000","37.04518","0.02920"
"74158","444.91200","37.07621","0.02919"
"74220","445.28400","37.10718","0.02966"
"74282","445.65600","37.13815","0.02971"
"74344","446.02800","37.16912","0.02963"
"74406","446.40000","37.20021","0.03011"
"74468","446.77200","37.23118","0.02993"
"74530","447.14400","37.26215","0.03006"
"74592","447.51600","37.29319","0.03031"
"74654","447.88800","37.32421","0.03045"
"74716","448.26000","37.35519","0.03033"
"74778","448.63200","37.38622","0.03030"
"74840","449.00400","37.41725","0.02991"
"74902","449.37600","37.44816","0.03058"
"74964","449.74800","37.47919","0.03036"
"75026","450.12000","37.51022","0.03035"
"75088","450.49200","37.54113","0.03074"
"75150","450.86400","37.57222","0.03070"
"75212","451.23600","37.60313","0.03085"
"75274","451.60800","37.63411","0.03090"
"75336","451.98000","37.66519","0.03088"
"75398","452.35200","37.69616","0.03122"
"75460","452.72400","37.72720","0.03108"
"75522","453.09600","37.75817","0.03086"
"75584","453.46800","37.78920","0.02942"
"75646","453.84000","37.82023","0.00759"
"75708","454.21200","37.85114","0.00303"
"75770","454.58400","37.88217","0.00241"
"75832","454.95600","37.91320","0.00222"
"75894","455.32800","37.94411","0.00619"
"75956","455.70000","37.97520","0.00210"
"76018","456.07200","38.00611","0.00240"
"76080","456.44400","38.03720","0.00772"
"76142","456.81600","38.06818","0.00240"
"76152","456.87400","38.07302","0.00248"