File: Trajectories_together/170108_1Specimen_RawData_2.csv
"","V1","V2","V3"
"1","End date","1/8/2017",""
"2","Specimen label","2DG_11",""
"3","Maximum Load","0.19822","N"
"4","Time","Extension","Load"
"5","(s)","(mm)","(N)"
"6","0.00000","0.00000","-0.00003"
"58","0.31200","0.02565","0.00036"
"110","0.62400","0.05226","0.00067"
"162","0.93600","0.07820","0.00100"
"214","1.24800","0.10421","0.00128"
"266","1.56000","0.13022","0.00128"
"318","1.87200","0.15629","0.00185"
"370","2.18400","0.18212","0.00262"
"422","2.49600","0.20825","0.00239"
"474","2.80800","0.23420","0.00274"
"526","3.12000","0.26020","0.00268"
"578","3.43200","0.28621","0.00341"
"630","3.74400","0.31216","0.00350"
"682","4.05600","0.33823","0.00360"
"734","4.36800","0.36418","0.00428"
"786","4.68000","0.39019","0.00421"
"838","4.99200","0.41619","0.00464"
"890","5.30400","0.44220","0.00410"
"942","5.61600","0.46821","0.00474"
"994","5.92800","0.49416","0.00505"
"1046","6.24000","0.52023","0.00500"
"1098","6.55200","0.54618","0.00563"
"1150","6.86400","0.57219","0.00521"
"1202","7.17600","0.59825","0.00596"
"1254","7.48800","0.62420","0.00586"
"1306","7.80000","0.65021","0.00647"
"1358","8.11200","0.67616","0.00667"
"1410","8.42400","0.70223","0.00690"
"1462","8.73600","0.72824","0.00758"
"1514","9.04800","0.75430","0.00745"
"1566","9.36000","0.78025","0.00760"
"1618","9.67200","0.80614","0.00796"
"1670","9.98400","0.83221","0.00795"
"1722","10.29600","0.85816","0.00786"
"1774","10.60800","0.88423","0.00824"
"1826","10.92000","0.91030","0.00875"
"1878","11.23200","0.93618","0.00860"
"1930","11.54400","0.96225","0.00904"
"1982","11.85600","0.98814","0.00905"
"2034","12.16800","1.01427","0.00930"
"2086","12.48000","1.04022","0.00955"
"2138","12.79200","1.06623","0.00998"
"2190","13.10400","1.09218","0.01003"
"2242","13.41600","1.11812","0.00965"
"2294","13.72800","1.14419","0.00973"
"2346","14.04000","1.17014","0.01012"
"2398","14.35200","1.19627","0.00977"
"2450","14.66400","1.22222","0.01043"
"2502","14.97600","1.24823","0.01051"
"2554","15.28800","1.27417","0.01078"
"2606","15.60000","1.30018","0.01100"
"2658","15.91200","1.32625","0.01118"
"2710","16.22400","1.35220","0.01091"
"2762","16.53600","1.37821","0.01081"
"2814","16.84800","1.40422","0.01155"
"2866","17.16000","1.43017","0.01182"
"2918","17.47200","1.45617","0.01189"
"2970","17.78400","1.48218","0.01229"
"3022","18.09600","1.50825","0.01248"
"3074","18.40800","1.53420","0.01255"
"3126","18.72000","1.56021","0.01248"
"3178","19.03200","1.58628","0.01262"
"3230","19.34400","1.61216","0.01316"
"3282","19.65600","1.63823","0.01294"
"3334","19.96800","1.66418","0.01309"
"3386","20.28000","1.69025","0.01305"
"3438","20.59200","1.71620","0.01324"
"3490","20.90400","1.74215","0.01406"
"3542","21.21600","1.76822","0.01374"
"3594","21.52800","1.79416","0.01412"
"3646","21.84000","1.82023","0.01377"
"3698","22.15200","1.84618","0.01363"
"3750","22.46400","1.87219","0.01389"
"3802","22.77600","1.89820","0.01490"
"3854","23.08800","1.92421","0.01463"
"3906","23.40000","1.95022","0.01440"
"3958","23.71200","1.97616","0.01470"
"4010","24.02400","2.00223","0.01471"
"4062","24.33600","2.02818","0.01544"
"4114","24.64800","2.05419","0.01540"
"4166","24.96000","2.08026","0.01511"
"4218","25.27200","2.10621","0.01577"
"4270","25.58400","2.13227","0.01584"
"4322","25.89600","2.15816","0.01549"
"4374","26.20800","2.18417","0.01626"
"4426","26.52000","2.21024","0.01586"
"4478","26.83200","2.23619","0.01688"
"4530","27.14400","2.26220","0.01642"
"4582","27.45600","2.28815","0.01660"
"4634","27.76800","2.31421","0.01635"
"4686","28.08000","2.34016","0.01702"
"4738","28.39200","2.36623","0.01628"
"4790","28.70400","2.39224","0.01726"
"4842","29.01600","2.41819","0.01738"
"4894","29.32800","2.44420","0.01726"
"4946","29.64000","2.47014","0.01755"
"4998","29.95200","2.49621","0.01795"
"5050","30.26400","2.52222","0.01805"
"5102","30.57600","2.54823","0.01770"
"5154","30.88800","2.57424","0.01792"
"5206","31.20000","2.60013","0.01825"
"5258","31.51200","2.62620","0.01825"
"5310","31.82400","2.65220","0.01915"
"5362","32.13600","2.67821","0.01841"
"5414","32.44800","2.70422","0.01934"
"5466","32.76000","2.73023","0.01867"
"5518","33.07200","2.75624","0.01934"
"5570","33.38400","2.78213","0.01961"
"5622","33.69600","2.80819","0.01985"
"5674","34.00800","2.83420","0.01983"
"5726","34.32000","2.86021","0.01988"
"5778","34.63200","2.88622","0.02010"
"5830","34.94400","2.91217","0.01987"
"5882","35.25600","2.93824","0.02033"
"5934","35.56800","2.96419","0.02037"
"5986","35.88000","2.99025","0.02091"
"6038","36.19200","3.01626","0.02061"
"6090","36.50400","3.04221","0.02060"
"6142","36.81600","3.06822","0.02078"
"6194","37.12800","3.09417","0.02135"
"6246","37.44000","3.12024","0.02116"
"6298","37.75200","3.14618","0.02147"
"6350","38.06400","3.17225","0.02157"
"6402","38.37600","3.19820","0.02171"
"6454","38.68800","3.22421","0.02149"
"6506","39.00000","3.25022","0.02210"
"6558","39.31200","3.27623","0.02217"
"6610","39.62400","3.30224","0.02198"
"6662","39.93600","3.32818","0.02265"
"6714","40.24800","3.35425","0.02259"
"6766","40.56000","3.38020","0.02287"
"6818","40.87200","3.40621","0.02297"
"6870","41.18400","3.43228","0.02318"
"6922","41.49600","3.45823","0.02294"
"6974","41.80800","3.48418","0.02296"
"7026","42.12000","3.51018","0.02377"
"7078","42.43200","3.53619","0.02362"
"7130","42.74400","3.56226","0.02401"
"7182","43.05600","3.58821","0.02330"
"7234","43.36800","3.61422","0.02406"
"7286","43.68000","3.64023","0.02401"
"7338","43.99200","3.66617","0.02454"
"7390","44.30400","3.69218","0.02498"
"7442","44.61600","3.71819","0.02518"
"7494","44.92800","3.74426","0.02512"
"7546","45.24000","3.77015","0.02503"
"7598","45.55200","3.79622","0.02493"
"7650","45.86400","3.82217","0.02500"
"7702","46.17600","3.84817","0.02557"
"7754","46.48800","3.87424","0.02574"
"7806","46.80000","3.90019","0.02599"
"7858","47.11200","3.92626","0.02612"
"7910","47.42400","3.95221","0.02617"
"7962","47.73600","3.97822","0.02658"
"8014","48.04800","4.00422","0.02694"
"8066","48.36000","4.03023","0.02736"
"8118","48.67200","4.05624","0.02716"
"8170","48.98400","4.08219","0.02742"
"8222","49.29600","4.10820","0.02792"
"8274","49.60800","4.13421","0.02795"
"8326","49.92000","4.16022","0.02839"
"8378","50.23200","4.18628","0.02842"
"8430","50.54400","4.21217","0.02846"
"8482","50.85600","4.23818","0.02918"
"8534","51.16800","4.26419","0.02853"
"8586","51.48000","4.29026","0.02928"
"8638","51.79200","4.31621","0.02972"
"8690","52.10400","4.34221","0.02978"
"8742","52.41600","4.36828","0.02987"
"8794","52.72800","4.39411","0.03020"
"8846","53.04000","4.42024","0.03041"
"8898","53.35200","4.44619","0.03106"
"8950","53.66400","4.47226","0.03104"
"9002","53.97600","4.49827","0.03167"
"9054","54.28800","4.52421","0.03091"
"9106","54.60000","4.55022","0.03163"
"9158","54.91200","4.57611","0.03215"
"9210","55.22400","4.60224","0.03258"
"9262","55.53600","4.62819","0.03279"
"9314","55.84800","4.65420","0.03319"
"9366","56.16000","4.68021","0.03372"
"9418","56.47200","4.70615","0.03415"
"9470","56.78400","4.73222","0.03424"
"9522","57.09600","4.75817","0.03376"
"9574","57.40800","4.78424","0.03427"
"9626","57.72000","4.81019","0.03449"
"9678","58.03200","4.83620","0.03541"
"9730","58.34400","4.86220","0.03514"
"9782","58.65600","4.88815","0.03515"
"9834","58.96800","4.91422","0.03558"
"9886","59.28000","4.94023","0.03576"
"9938","59.59200","4.96624","0.03593"
"9990","59.90400","4.99219","0.03645"
"10042","60.21600","5.01819","0.03637"
"10094","60.52800","5.04420","0.03739"
"10146","60.84000","5.07015","0.03729"
"10198","61.15200","5.09622","0.03762"
"10250","61.46400","5.12223","0.03759"
"10302","61.77600","5.14824","0.03764"
"10354","62.08800","5.17425","0.03796"
"10406","62.40000","5.20019","0.03845"
"10458","62.71200","5.22626","0.03864"
"10510","63.02400","5.25215","0.03854"
"10562","63.33600","5.27822","0.03863"
"10614","63.64800","5.30417","0.03902"
"10666","63.96000","5.33018","0.03921"
"10718","64.27200","5.35625","0.03930"
"10770","64.58400","5.38219","0.03994"
"10822","64.89600","5.40826","0.03996"
"10874","65.20800","5.43415","0.04031"
"10926","65.52000","5.46016","0.03996"
"10978","65.83200","5.48623","0.04039"
"11030","66.14400","5.51224","0.04045"
"11082","66.45600","5.53824","0.04060"
"11134","66.76800","5.56419","0.04078"
"11186","67.08000","5.59026","0.04098"
"11238","67.39200","5.61621","0.04108"
"11290","67.70400","5.64222","0.04136"
"11342","68.01600","5.66829","0.04106"
"11394","68.32800","5.69418","0.04149"
"11446","68.64000","5.72024","0.04160"
"11498","68.95200","5.74619","0.04166"
"11550","69.26400","5.77220","0.04200"
"11602","69.57600","5.79827","0.04204"
"11654","69.88800","5.82422","0.04195"
"11706","70.20000","5.85029","0.04231"
"11758","70.51200","5.87611","0.04241"
"11810","70.82400","5.90224","0.04271"
"11862","71.13600","5.92819","0.04258"
"11914","71.44800","5.95426","0.04228"
"11966","71.76000","5.98027","0.04270"
"12018","72.07200","6.00616","0.04232"
"12070","72.38400","6.03223","0.04261"
"12122","72.69600","6.05811","0.04260"
"12174","73.00800","6.08424","0.04278"
"12226","73.32000","6.11025","0.04283"
"12278","73.63200","6.13626","0.04298"
"12330","73.94400","6.16221","0.04366"
"12382","74.25600","6.18810","0.04347"
"12434","74.56800","6.21422","0.04372"
"12486","74.88000","6.24023","0.04375"
"12538","75.19200","6.26618","0.04394"
"12590","75.50400","6.29219","0.04401"
"12642","75.81600","6.31820","0.04388"
"12694","76.12800","6.34421","0.04429"
"12746","76.44000","6.37016","0.04442"
"12798","76.75200","6.39622","0.04486"
"12850","77.06400","6.42223","0.04562"
"12902","77.37600","6.44818","0.04520"
"12954","77.68800","6.47425","0.04598"
"13006","78.00000","6.50014","0.04647"
"13058","78.31200","6.52621","0.04635"
"13110","78.62400","6.55216","0.04692"
"13162","78.93600","6.57828","0.04643"
"13214","79.24800","6.60423","0.04665"
"13266","79.56000","6.63018","0.04697"
"13318","79.87200","6.65625","0.04694"
"13370","80.18400","6.68220","0.04724"
"13422","80.49600","6.70821","0.04784"
"13474","80.80800","6.73421","0.04823"
"13526","81.12000","6.76022","0.04881"
"13578","81.43200","6.78623","0.04936"
"13630","81.74400","6.81218","0.05048"
"13682","82.05600","6.83819","0.05054"
"13734","82.36800","6.86420","0.05085"
"13786","82.68000","6.89027","0.05199"
"13838","82.99200","6.91621","0.05201"
"13890","83.30400","6.94222","0.05211"
"13942","83.61600","6.96823","0.05414"
"13994","83.92800","6.99418","0.05353"
"14046","84.24000","7.02019","0.05512"
"14098","84.55200","7.04620","0.05498"
"14150","84.86400","7.07221","0.05650"
"14202","85.17600","7.09815","0.05664"
"14254","85.48800","7.12416","0.05743"
"14306","85.80000","7.15023","0.05912"
"14358","86.11200","7.17618","0.05955"
"14410","86.42400","7.20225","0.06045"
"14462","86.73600","7.22820","0.06094"
"14514","87.04800","7.25420","0.06139"
"14566","87.36000","7.28021","0.06189"
"14618","87.67200","7.30622","0.06249"
"14670","87.98400","7.33223","0.06309"
"14722","88.29600","7.35812","0.06390"
"14774","88.60800","7.38419","0.06424"
"14826","88.92000","7.41020","0.06533"
"14878","89.23200","7.43620","0.06544"
"14930","89.54400","7.46221","0.06616"
"14982","89.85600","7.48816","0.06660"
"15034","90.16800","7.51423","0.06797"
"15086","90.48000","7.54018","0.06872"
"15138","90.79200","7.56619","0.06911"
"15190","91.10400","7.59220","0.06969"
"15242","91.41600","7.61814","0.07065"
"15294","91.72800","7.64421","0.07076"
"15346","92.04000","7.67016","0.07220"
"15398","92.35200","7.69623","0.07216"
"15450","92.66400","7.72218","0.07304"
"15502","92.97600","7.74825","0.07352"
"15554","93.28800","7.77425","0.07369"
"15606","93.60000","7.80020","0.07463"
"15658","93.91200","7.82621","0.07527"
"15710","94.22400","7.85216","0.07617"
"15762","94.53600","7.87823","0.07706"
"15814","94.84800","7.90424","0.07740"
"15866","95.16000","7.93024","0.07644"
"15918","95.47200","7.95625","0.07853"
"15970","95.78400","7.98214","0.07941"
"16022","96.09600","8.00821","0.07990"
"16074","96.40800","8.03416","0.08122"
"16126","96.72000","8.06023","0.08180"
"16178","97.03200","8.08624","0.08224"
"16230","97.34400","8.11218","0.08255"
"16282","97.65600","8.13825","0.08318"
"16334","97.96800","8.16414","0.08370"
"16386","98.28000","8.19027","0.08424"
"16438","98.59200","8.21622","0.08492"
"16490","98.90400","8.24223","0.08548"
"16542","99.21600","8.26823","0.08558"
"16594","99.52800","8.29418","0.08658"
"16646","99.84000","8.32019","0.08661"
"16698","100.15200","8.34620","0.08702"
"16750","100.46400","8.37227","0.08712"
"16802","100.77600","8.39822","0.08744"
"16854","101.08800","8.42422","0.08761"
"16906","101.40000","8.45017","0.01174"
"16958","101.71200","8.47618","0.01640"
"17010","102.02400","8.50225","0.01100"
"17062","102.33600","8.52820","0.01123"
"17114","102.64800","8.55421","0.01252"
"17166","102.96000","8.58022","0.01167"
"17218","103.27200","8.60616","0.01234"
"17270","103.58400","8.63223","0.01185"
"17322","103.89600","8.65818","0.01320"
"17374","104.20800","8.68419","0.01205"
"17426","104.52000","8.71020","0.01349"
"17478","104.83200","8.73621","0.01248"
"17530","105.14400","8.76222","0.01409"
"17582","105.45600","8.78822","0.01291"
"17634","105.76800","8.81423","0.01345"
"17686","106.08000","8.84018","0.01365"
"17738","106.39200","8.86619","0.01373"
"17790","106.70400","8.89220","0.01372"
"17842","107.01600","8.91821","0.01376"
"17894","107.32800","8.94421","0.01416"
"17946","107.64000","8.97016","0.01465"
"17998","107.95200","8.99623","0.01404"
"18050","108.26400","9.02218","0.01407"
"18102","108.57600","9.04819","0.01505"
"18154","108.88800","9.07426","0.01466"
"18206","109.20000","9.10021","0.01502"
"18258","109.51200","9.12621","0.01496"
"18310","109.82400","9.15216","0.01544"
"18362","110.13600","9.17823","0.01550"
"18414","110.44800","9.20418","0.01548"
"18466","110.76000","9.23019","0.01566"
"18518","111.07200","9.25626","0.01623"
"18570","111.38400","9.28221","0.01593"
"18622","111.69600","9.30821","0.01586"
"18674","112.00800","9.33422","0.01644"
"18726","112.32000","9.36023","0.01690"
"18778","112.63200","9.38624","0.01684"
"18830","112.94400","9.41219","0.01675"
"18882","113.25600","9.43826","0.01737"
"18934","113.56800","9.46414","0.01717"
"18986","113.88000","9.49021","0.01738"
"19038","114.19200","9.51616","0.01742"
"19090","114.50400","9.54223","0.01820"
"19142","114.81600","9.56824","0.01749"
"19194","115.12800","9.59419","0.01761"
"19246","115.44000","9.62020","0.01804"
"19298","115.75200","9.64614","0.01845"
"19350","116.06400","9.67227","0.01846"
"19402","116.37600","9.69822","0.01847"
"19454","116.68800","9.72423","0.01883"
"19506","117.00000","9.75018","0.01907"
"19558","117.31200","9.77613","0.01921"
"19610","117.62400","9.80225","0.01882"
"19662","117.93600","9.82820","0.01965"
"19714","118.24800","9.85421","0.01929"
"19766","118.56000","9.88022","0.01884"
"19818","118.87200","9.90617","0.01903"
"19870","119.18400","9.93218","0.01955"
"19922","119.49600","9.95813","0.01944"
"19974","119.80800","9.98419","0.01920"
"20026","120.12000","10.01014","0.02007"
"20078","120.43200","10.03615","0.01932"
"20130","120.74400","10.06222","0.01927"
"20182","121.05600","10.08817","0.01959"
"20234","121.36800","10.11424","0.01993"
"20286","121.68000","10.14019","0.01921"
"20338","121.99200","10.16625","0.01933"
"20390","122.30400","10.19226","0.02013"
"20442","122.61600","10.21815","0.02015"
"20494","122.92800","10.24422","0.02055"
"20546","123.24000","10.27023","0.02046"
"20598","123.55200","10.29624","0.02034"
"20650","123.86400","10.32218","0.02009"
"20702","124.17600","10.34825","0.02076"
"20754","124.48800","10.37420","0.02055"
"20806","124.80000","10.40021","0.02065"
"20858","125.11200","10.42622","0.02048"
"20910","125.42400","10.45223","0.02043"
"20962","125.73600","10.47824","0.02138"
"21014","126.04800","10.50418","0.02057"
"21066","126.36000","10.53019","0.02048"
"21118","126.67200","10.55620","0.02012"
"21170","126.98400","10.58215","0.02078"
"21222","127.29600","10.60822","0.02094"
"21274","127.60800","10.63417","0.01986"
"21326","127.92000","10.66023","0.02021"
"21378","128.23200","10.68618","0.02051"
"21430","128.54400","10.71213","0.02035"
"21482","128.85600","10.73826","0.02101"
"21534","129.16800","10.76421","0.02063"
"21586","129.48000","10.79022","0.02096"
"21638","129.79200","10.81617","0.02112"
"21690","130.10400","10.84217","0.02184"
"21742","130.41600","10.86824","0.02194"
"21794","130.72800","10.89419","0.02142"
"21846","131.04000","10.92026","0.02194"
"21898","131.35200","10.94615","0.02180"
"21950","131.66400","10.97222","0.02214"
"22002","131.97600","10.99817","0.02232"
"22054","132.28800","11.02423","0.02220"
"22106","132.60000","11.05024","0.02194"
"22158","132.91200","11.07613","0.02186"
"22210","133.22400","11.10226","0.02156"
"22262","133.53600","11.12821","0.02189"
"22314","133.84800","11.15422","0.02254"
"22366","134.16000","11.18022","0.02166"
"22418","134.47200","11.20617","0.02259"
"22470","134.78400","11.23224","0.02229"
"22522","135.09600","11.25813","0.02253"
"22574","135.40800","11.28420","0.02279"
"22626","135.72000","11.31021","0.02314"
"22678","136.03200","11.33627","0.02333"
"22730","136.34400","11.36228","0.02351"
"22782","136.65600","11.38817","0.02311"
"22834","136.96800","11.41424","0.02332"
"22886","137.28000","11.44019","0.02404"
"22938","137.59200","11.46626","0.02409"
"22990","137.90400","11.49227","0.02408"
"23042","138.21600","11.51822","0.02456"
"23094","138.52800","11.54422","0.02519"
"23146","138.84000","11.57011","0.02450"
"23198","139.15200","11.59624","0.02485"
"23250","139.46400","11.62219","0.02578"
"23302","139.77600","11.64826","0.02574"
"23354","140.08800","11.67426","0.02532"
"23406","140.40000","11.70021","0.02619"
"23458","140.71200","11.72622","0.02646"
"23510","141.02400","11.75217","0.02652"
"23562","141.33600","11.77824","0.02651"
"23614","141.64800","11.80419","0.02694"
"23666","141.96000","11.83026","0.02747"
"23718","142.27200","11.85620","0.02821"
"23770","142.58400","11.88215","0.02811"
"23822","142.89600","11.90822","0.02766"
"23874","143.20800","11.93423","0.02853"
"23926","143.52000","11.96024","0.02757"
"23978","143.83200","11.98619","0.02810"
"24030","144.14400","12.01219","0.02863"
"24082","144.45600","12.03814","0.02876"
"24134","144.76800","12.06415","0.02829"
"24186","145.08000","12.09022","0.02881"
"24238","145.39200","12.11623","0.02911"
"24290","145.70400","12.14218","0.02964"
"24342","146.01600","12.16819","0.03009"
"24394","146.32800","12.19420","0.03055"
"24446","146.64000","12.22026","0.03057"
"24498","146.95200","12.24621","0.03095"
"24550","147.26400","12.27222","0.03137"
"24602","147.57600","12.29823","0.03191"
"24654","147.88800","12.32418","0.03149"
"24706","148.20000","12.35025","0.03143"
"24758","148.51200","12.37613","0.03235"
"24810","148.82400","12.40220","0.03299"
"24862","149.13600","12.42815","0.03288"
"24914","149.44800","12.45416","0.03378"
"24966","149.76000","12.48017","0.03456"
"25018","150.07200","12.50618","0.03423"
"25070","150.38400","12.53224","0.03445"
"25122","150.69600","12.55819","0.03498"
"25174","151.00800","12.58420","0.03476"
"25226","151.32000","12.61021","0.03544"
"25278","151.63200","12.63616","0.03621"
"25330","151.94400","12.66223","0.03567"
"25382","152.25600","12.68818","0.03626"
"25434","152.56800","12.71424","0.03631"
"25486","152.88000","12.74019","0.03656"
"25538","153.19200","12.76620","0.03609"
"25590","153.50400","12.79221","0.03636"
"25642","153.81600","12.81822","0.03607"
"25694","154.12800","12.84429","0.03629"
"25746","154.44000","12.87017","0.03631"
"25798","154.75200","12.89624","0.03593"
"25850","155.06400","12.92219","0.03660"
"25902","155.37600","12.94820","0.03741"
"25954","155.68800","12.97427","0.03789"
"26006","156.00000","13.00016","0.03767"
"26058","156.31200","13.02623","0.03826"
"26110","156.62400","13.05217","0.03860"
"26162","156.93600","13.07818","0.03878"
"26214","157.24800","13.10419","0.03926"
"26266","157.56000","13.13020","0.03865"
"26318","157.87200","13.15627","0.03883"
"26370","158.18400","13.18216","0.03908"
"26422","158.49600","13.20823","0.03918"
"26474","158.80800","13.23411","0.03936"
"26526","159.12000","13.26024","0.03983"
"26578","159.43200","13.28625","0.04018"
"26630","159.74400","13.31220","0.04022"
"26682","160.05600","13.33821","0.04070"
"26734","160.36800","13.36410","0.04004"
"26786","160.68000","13.39023","0.04044"
"26838","160.99200","13.41623","0.04077"
"26890","161.30400","13.44224","0.04104"
"26942","161.61600","13.46825","0.04121"
"26994","161.92800","13.49420","0.04136"
"27046","162.24000","13.52021","0.04179"
"27098","162.55200","13.54616","0.04183"
"27150","162.86400","13.57222","0.04151"
"27202","163.17600","13.59817","0.04171"
"27254","163.48800","13.62412","0.04227"
"27306","163.80000","13.65025","0.04180"
"27358","164.11200","13.67620","0.04204"
"27410","164.42400","13.70221","0.04253"
"27462","164.73600","13.72822","0.04224"
"27514","165.04800","13.75428","0.04255"
"27566","165.36000","13.78023","0.04289"
"27618","165.67200","13.80618","0.04311"
"27670","165.98400","13.83219","0.04309"
"27722","166.29600","13.85820","0.04344"
"27774","166.60800","13.88426","0.04368"
"27826","166.92000","13.91022","0.04374"
"27878","167.23200","13.93622","0.04425"
"27930","167.54400","13.96223","0.04453"
"27982","167.85600","13.98818","0.04485"
"28034","168.16800","14.01425","0.04527"
"28086","168.48000","14.04020","0.04592"
"28138","168.79200","14.06621","0.04650"
"28190","169.10400","14.09221","0.04611"
"28242","169.41600","14.11822","0.04696"
"28294","169.72800","14.14423","0.04790"
"28346","170.04000","14.17018","0.04945"
"28398","170.35200","14.19625","0.05020"
"28450","170.66400","14.22220","0.05239"
"28502","170.97600","14.24821","0.05366"
"28554","171.28800","14.27415","0.05627"
"28606","171.60000","14.30016","0.05741"
"28658","171.91200","14.32623","0.05845"
"28710","172.22400","14.35218","0.06122"
"28762","172.53600","14.37825","0.06286"
"28814","172.84800","14.40420","0.06481"
"28866","173.16000","14.43015","0.06627"
"28918","173.47200","14.45621","0.06861"
"28970","173.78400","14.48222","0.06977"
"29022","174.09600","14.50829","0.07104"
"29074","174.40800","14.53412","0.07228"
"29126","174.72000","14.56019","0.07401"
"29178","175.03200","14.58619","0.07572"
"29230","175.34400","14.61220","0.07679"
"29282","175.65600","14.63827","0.07855"
"29334","175.96800","14.66416","0.08001"
"29386","176.28000","14.69023","0.06508"
"29438","176.59200","14.71618","0.05839"
"29490","176.90400","14.74224","0.05310"
"29542","177.21600","14.76820","0.05107"
"29594","177.52800","14.79420","0.05344"
"29646","177.84000","14.82021","0.05703"
"29698","178.15200","14.84616","0.05865"
"29750","178.46400","14.87217","0.06160"
"29802","178.77600","14.89824","0.06237"
"29854","179.08800","14.92424","0.06415"
"29906","179.40000","14.95025","0.06773"
"29958","179.71200","14.97614","0.06833"
"30010","180.02400","15.00221","0.07020"
"30062","180.33600","15.02822","0.07169"
"30114","180.64800","15.05423","0.07251"
"30166","180.96000","15.08024","0.07515"
"30218","181.27200","15.10618","0.07654"
"30270","181.58400","15.13219","0.07780"
"30322","181.89600","15.15814","0.07952"
"30374","182.20800","15.18421","0.08077"
"30426","182.52000","15.21022","0.08157"
"30478","182.83200","15.23629","0.08338"
"30530","183.14400","15.26230","0.08435"
"30582","183.45600","15.28818","0.08494"
"30634","183.76800","15.31419","0.08638"
"30686","184.08000","15.34014","0.08720"
"30738","184.39200","15.36621","0.08807"
"30790","184.70400","15.39216","0.08867"
"30842","185.01600","15.41823","0.08915"
"30894","185.32800","15.44417","0.08956"
"30946","185.64000","15.47012","0.09003"
"30998","185.95200","15.49619","0.09059"
"31050","186.26400","15.52220","0.09100"
"31102","186.57600","15.54821","0.09176"
"31154","186.88800","15.57422","0.09203"
"31206","187.20000","15.60017","0.09267"
"31258","187.51200","15.62617","0.09392"
"31310","187.82400","15.65218","0.09499"
"31362","188.13600","15.67819","0.09603"
"31414","188.44800","15.70420","0.09667"
"31466","188.76000","15.73021","0.09652"
"31518","189.07200","15.75616","0.09731"
"31570","189.38400","15.78216","0.02727"
"31622","189.69600","15.80829","0.01944"
"31674","190.00800","15.83418","0.02784"
"31726","190.32000","15.86019","0.02274"
"31778","190.63200","15.88620","0.03196"
"31830","190.94400","15.91221","0.02597"
"31882","191.25600","15.93822","0.02651"
"31934","191.56800","15.96422","0.03145"
"31986","191.88000","15.99023","0.02693"
"32038","192.19200","16.01618","0.03209"
"32090","192.50400","16.04219","0.03105"
"32142","192.81600","16.06820","0.03373"
"32194","193.12800","16.09421","0.03402"
"32246","193.44000","16.12027","0.03724"
"32298","193.75200","16.14622","0.03645"
"32350","194.06400","16.17229","0.03699"
"32402","194.37600","16.19818","0.03634"
"32454","194.68800","16.22419","0.03477"
"32506","195.00000","16.25026","0.03771"
"32558","195.31200","16.27621","0.03839"
"32610","195.62400","16.30221","0.03737"
"32662","195.93600","16.32822","0.03959"
"32714","196.24800","16.35423","0.03970"
"32766","196.56000","16.38024","0.04072"
"32818","196.87200","16.40619","0.04090"
"32870","197.18400","16.43225","0.04144"
"32922","197.49600","16.45815","0.04209"
"32974","197.80800","16.48427","0.04211"
"33026","198.12000","16.51022","0.04297"
"33078","198.43200","16.53623","0.04358"
"33130","198.74400","16.56224","0.04412"
"33182","199.05600","16.58819","0.04425"
"33234","199.36800","16.61419","0.04455"
"33286","199.68000","16.64014","0.04543"
"33338","199.99200","16.66621","0.04632"
"33390","200.30400","16.69222","0.04798"
"33442","200.61600","16.71823","0.04848"
"33494","200.92800","16.74430","0.05055"
"33546","201.24000","16.77019","0.05371"
"33598","201.55200","16.79626","0.05523"
"33650","201.86400","16.82214","0.05660"
"33702","202.17600","16.84827","0.05771"
"33754","202.48800","16.87428","0.06001"
"33806","202.80000","16.90023","0.06277"
"33858","203.11200","16.92618","0.06453"
"33910","203.42400","16.95213","0.06633"
"33962","203.73600","16.97825","0.06868"
"34014","204.04800","17.00420","0.06944"
"34066","204.36000","17.03027","0.07113"
"34118","204.67200","17.05622","0.07263"
"34170","204.98400","17.08217","0.07353"
"34222","205.29600","17.10824","0.07529"
"34274","205.60800","17.13413","0.07583"
"34326","205.92000","17.16019","0.07782"
"34378","206.23200","17.18620","0.07898"
"34430","206.54400","17.21215","0.08089"
"34482","206.85600","17.23822","0.08228"
"34534","207.16800","17.26417","0.08331"
"34586","207.48000","17.29024","0.08407"
"34638","207.79200","17.31618","0.08342"
"34690","208.10400","17.34225","0.02469"
"34742","208.41600","17.36826","0.02218"
"34794","208.72800","17.39421","0.02455"
"34846","209.04000","17.42022","0.02318"
"34898","209.35200","17.44617","0.02291"
"34950","209.66400","17.47223","0.02565"
"35002","209.97600","17.49818","0.02498"
"35054","210.28800","17.52419","0.02459"
"35106","210.60000","17.55020","0.02724"
"35158","210.91200","17.57621","0.02481"
"35210","211.22400","17.60222","0.02613"
"35262","211.53600","17.62817","0.02654"
"35314","211.84800","17.65423","0.02617"
"35366","212.16000","17.68024","0.02675"
"35418","212.47200","17.70619","0.02736"
"35470","212.78400","17.73226","0.02606"
"35522","213.09600","17.75815","0.02819"
"35574","213.40800","17.78422","0.02791"
"35626","213.72000","17.81023","0.02749"
"35678","214.03200","17.83617","0.02838"
"35730","214.34400","17.86218","0.02778"
"35782","214.65600","17.88819","0.02708"
"35834","214.96800","17.91426","0.02763"
"35886","215.28000","17.94021","0.02827"
"35938","215.59200","17.96622","0.02804"
"35990","215.90400","17.99222","0.02929"
"36042","216.21600","18.01817","0.02805"
"36094","216.52800","18.04424","0.02857"
"36146","216.84000","18.07019","0.02928"
"36198","217.15200","18.09626","0.02872"
"36250","217.46400","18.12215","0.02892"
"36302","217.77600","18.14822","0.02929"
"36354","218.08800","18.17416","0.02980"
"36406","218.40000","18.20023","0.03003"
"36458","218.71200","18.22624","0.02987"
"36510","219.02400","18.25213","0.02924"
"36562","219.33600","18.27826","0.02872"
"36614","219.64800","18.30421","0.02833"
"36666","219.96000","18.33022","0.02847"
"36718","220.27200","18.35622","0.02866"
"36770","220.58400","18.38217","0.02953"
"36822","220.89600","18.40818","0.03015"
"36874","221.20800","18.43419","0.02953"
"36926","221.52000","18.46020","0.02914"
"36978","221.83200","18.48627","0.02982"
"37030","222.14400","18.51221","0.02997"
"37082","222.45600","18.53828","0.02916"
"37134","222.76800","18.56417","0.02906"
"37186","223.08000","18.59024","0.02890"
"37238","223.39200","18.61619","0.02962"
"37290","223.70400","18.64226","0.02976"
"37342","224.01600","18.66827","0.03022"
"37394","224.32800","18.69421","0.03011"
"37446","224.64000","18.72028","0.02787"
"37498","224.95200","18.74611","0.02702"
"37550","225.26400","18.77224","0.02775"
"37602","225.57600","18.79825","0.02757"
"37654","225.88800","18.82426","0.02772"
"37706","226.20000","18.85027","0.02823"
"37758","226.51200","18.87621","0.02864"
"37810","226.82400","18.90222","0.02795"
"37862","227.13600","18.92817","0.02835"
"37914","227.44800","18.95424","0.02866"
"37966","227.76000","18.98019","0.02845"
"38018","228.07200","19.00620","0.02856"
"38070","228.38400","19.03226","0.02801"
"38122","228.69600","19.05815","0.02941"
"38174","229.00800","19.08422","0.02913"
"38226","229.32000","19.11023","0.02917"
"38278","229.63200","19.13618","0.02889"
"38330","229.94400","19.16219","0.02896"
"38382","230.25600","19.18820","0.02967"
"38434","230.56800","19.21420","0.02933"
"38486","230.88000","19.24021","0.02957"
"38538","231.19200","19.26622","0.02952"
"38590","231.50400","19.29223","0.03020"
"38642","231.81600","19.31818","0.02993"
"38694","232.12800","19.34425","0.03095"
"38746","232.44000","19.37020","0.03017"
"38798","232.75200","19.39626","0.02909"
"38850","233.06400","19.42221","0.02931"
"38902","233.37600","19.44822","0.02973"
"38954","233.68800","19.47423","0.02920"
"39006","234.00000","19.50024","0.03017"
"39058","234.31200","19.52625","0.02990"
"39110","234.62400","19.55219","0.03009"
"39162","234.93600","19.57826","0.02994"
"39214","235.24800","19.60415","0.03092"
"39266","235.56000","19.63016","0.03015"
"39318","235.87200","19.65617","0.03075"
"39370","236.18400","19.68218","0.03094"
"39422","236.49600","19.70824","0.03064"
"39474","236.80800","19.73419","0.03077"
"39526","237.12000","19.76026","0.03086"
"39578","237.43200","19.78621","0.03155"
"39630","237.74400","19.81222","0.03109"
"39682","238.05600","19.83822","0.03189"
"39734","238.36800","19.86418","0.03159"
"39786","238.68000","19.89024","0.03174"
"39838","238.99200","19.91619","0.03267"
"39890","239.30400","19.94220","0.03266"
"39942","239.61600","19.96827","0.03257"
"39994","239.92800","19.99416","0.03299"
"40046","240.24000","20.02022","0.03251"
"40098","240.55200","20.04618","0.03219"
"40150","240.86400","20.07224","0.03263"
"40202","241.17600","20.09825","0.03321"
"40254","241.48800","20.12420","0.03308"
"40306","241.80000","20.15027","0.03394"
"40358","242.11200","20.17616","0.03381"
"40410","242.42400","20.20222","0.03381"
"40462","242.73600","20.22811","0.03417"
"40514","243.04800","20.25424","0.03384"
"40566","243.36000","20.28025","0.03373"
"40618","243.67200","20.30620","0.03393"
"40670","243.98400","20.33221","0.03351"
"40722","244.29600","20.35815","0.03424"
"40774","244.60800","20.38423","0.03418"
"40826","244.92000","20.41018","0.03269"
"40878","245.23200","20.43624","0.03244"
"40930","245.54400","20.46225","0.03385"
"40982","245.85600","20.48820","0.03347"
"41034","246.16800","20.51421","0.03379"
"41086","246.48000","20.54010","0.03443"
"41138","246.79200","20.56623","0.03259"
"41190","247.10400","20.59223","0.03246"
"41242","247.41600","20.61824","0.03245"
"41294","247.72800","20.64425","0.03308"
"41346","248.04000","20.67020","0.03230"
"41398","248.35200","20.69621","0.03370"
"41450","248.66400","20.72215","0.03328"
"41502","248.97600","20.74817","0.03356"
"41554","249.28800","20.77417","0.03342"
"41606","249.60000","20.80018","0.03457"
"41658","249.91200","20.82619","0.03413"
"41710","250.22400","20.85214","0.03452"
"41762","250.53600","20.87820","0.03429"
"41814","250.84800","20.90421","0.03415"
"41866","251.16000","20.93028","0.03474"
"41918","251.47200","20.95623","0.03464"
"41970","251.78400","20.98218","0.03471"
"42022","252.09600","21.00825","0.03521"
"42074","252.40800","21.03420","0.03579"
"42126","252.72000","21.06020","0.03622"
"42178","253.03200","21.08621","0.03663"
"42230","253.34400","21.11222","0.03637"
"42282","253.65600","21.13823","0.03612"
"42334","253.96800","21.16418","0.03718"
"42386","254.28000","21.19025","0.03698"
"42438","254.59200","21.21620","0.03719"
"42490","254.90400","21.24220","0.03767"
"42542","255.21600","21.26821","0.03768"
"42594","255.52800","21.29422","0.03725"
"42646","255.84000","21.32023","0.03811"
"42698","256.15200","21.34618","0.03757"
"42750","256.46400","21.37219","0.03862"
"42802","256.77600","21.39820","0.03789"
"42854","257.08800","21.42420","0.03855"
"42906","257.40000","21.45021","0.03858"
"42958","257.71200","21.47622","0.03910"
"43010","258.02400","21.50223","0.03969"
"43062","258.33600","21.52818","0.03947"
"43114","258.64800","21.55425","0.03943"
"43166","258.96000","21.58019","0.03951"
"43218","259.27200","21.60614","0.03983"
"43270","259.58400","21.63227","0.04031"
"43322","259.89600","21.65822","0.03984"
"43374","260.20800","21.68423","0.04072"
"43426","260.52000","21.71012","0.04098"
"43478","260.83200","21.73619","0.04108"
"43530","261.14400","21.76219","0.04108"
"43582","261.45600","21.78820","0.04142"
"43634","261.76800","21.81421","0.04039"
"43686","262.08000","21.84016","0.04132"
"43738","262.39200","21.86629","0.04103"
"43790","262.70400","21.89218","0.04125"
"43842","263.01600","21.91825","0.04192"
"43894","263.32800","21.94425","0.04186"
"43946","263.64000","21.97014","0.04228"
"43998","263.95200","21.99615","0.04254"
"44050","264.26400","22.02216","0.04285"
"44102","264.57600","22.04823","0.04273"
"44154","264.88800","22.07424","0.04291"
"44206","265.20000","22.10025","0.04302"
"44258","265.51200","22.12625","0.04274"
"44310","265.82400","22.15214","0.04276"
"44362","266.13600","22.17821","0.04281"
"44414","266.44800","22.20422","0.04304"
"44466","266.76000","22.23022","0.04323"
"44518","267.07200","22.25624","0.04326"
"44570","267.38400","22.28218","0.04116"
"44622","267.69600","22.30819","0.04044"
"44674","268.00800","22.33414","0.04138"
"44726","268.32000","22.36027","0.03412"
"44778","268.63200","22.38622","0.02913"
"44830","268.94400","22.41223","0.03337"
"44882","269.25600","22.43824","0.03253"
"44934","269.56800","22.46418","0.03117"
"44986","269.88000","22.49025","0.03362"
"45038","270.19200","22.51614","0.03364"
"45090","270.50400","22.54227","0.03395"
"45142","270.81600","22.56822","0.03473"
"45194","271.12800","22.59417","0.03540"
"45246","271.44000","22.62017","0.03543"
"45298","271.75200","22.64612","0.03607"
"45350","272.06400","22.67225","0.03679"
"45402","272.37600","22.69820","0.03620"
"45454","272.68800","22.72421","0.03646"
"45506","273.00000","22.75022","0.03727"
"45558","273.31200","22.77617","0.03717"
"45610","273.62400","22.80217","0.03733"
"45662","273.93600","22.82812","0.03824"
"45714","274.24800","22.85419","0.03861"
"45766","274.56000","22.88020","0.03818"
"45818","274.87200","22.90615","0.03861"
"45870","275.18400","22.93222","0.03899"
"45922","275.49600","22.95816","0.03900"
"45974","275.80800","22.98423","0.03942"
"46026","276.12000","23.01024","0.03969"
"46078","276.43200","23.03619","0.03961"
"46130","276.74400","23.06220","0.04034"
"46182","277.05600","23.08821","0.03985"
"46234","277.36800","23.11427","0.04113"
"46286","277.68000","23.14016","0.04096"
"46338","277.99200","23.16623","0.04113"
"46390","278.30400","23.19212","0.04095"
"46442","278.61600","23.21819","0.04158"
"46494","278.92800","23.24420","0.04125"
"46546","279.24000","23.27020","0.04159"
"46598","279.55200","23.29627","0.04207"
"46650","279.86400","23.32216","0.04207"
"46702","280.17600","23.34817","0.04249"
"46754","280.48800","23.37418","0.04237"
"46806","280.80000","23.40019","0.04234"
"46858","281.11200","23.42626","0.04271"
"46910","281.42400","23.45220","0.04277"
"46962","281.73600","23.47821","0.04286"
"47014","282.04800","23.50416","0.04312"
"47066","282.36000","23.53017","0.04342"
"47118","282.67200","23.55624","0.04364"
"47170","282.98400","23.58219","0.04381"
"47222","283.29600","23.60825","0.04424"
"47274","283.60800","23.63415","0.04432"
"47326","283.92000","23.66021","0.04442"
"47378","284.23200","23.68622","0.04459"
"47430","284.54400","23.71223","0.04511"
"47482","284.85600","23.73824","0.04454"
"47534","285.16800","23.76418","0.04333"
"47586","285.48000","23.79025","0.04346"
"47638","285.79200","23.81614","0.04289"
"47690","286.10400","23.84221","0.03848"
"47742","286.41600","23.86822","0.03916"
"47794","286.72800","23.89417","0.03776"
"47846","287.04000","23.92024","0.04099"
"47898","287.35200","23.94613","0.03655"
"47950","287.66400","23.97225","0.04023"
"48002","287.97600","23.99821","0.03981"
"48054","288.28800","24.02427","0.04127"
"48106","288.60000","24.05022","0.04088"
"48158","288.91200","24.07623","0.04106"
"48210","289.22400","24.10218","0.04203"
"48262","289.53600","24.12813","0.04083"
"48314","289.84800","24.15425","0.03712"
"48366","290.16000","24.18026","0.03538"
"48418","290.47200","24.20621","0.03569"
"48470","290.78400","24.23228","0.03685"
"48522","291.09600","24.25817","0.03713"
"48574","291.40800","24.28418","0.03705"
"48626","291.72000","24.31018","0.03879"
"48678","292.03200","24.33625","0.03894"
"48730","292.34400","24.36220","0.03945"
"48782","292.65600","24.38815","0.04010"
"48834","292.96800","24.41422","0.04024"
"48886","293.28000","24.44017","0.04021"
"48938","293.59200","24.46624","0.04092"
"48990","293.90400","24.49224","0.04088"
"49042","294.21600","24.51825","0.04100"
"49094","294.52800","24.54426","0.04129"
"49146","294.84000","24.57015","0.04145"
"49198","295.15200","24.59622","0.04162"
"49250","295.46400","24.62223","0.04161"
"49302","295.77600","24.64823","0.04206"
"49354","296.08800","24.67418","0.04261"
"49406","296.40000","24.70019","0.04255"
"49458","296.71200","24.72626","0.04284"
"49510","297.02400","24.75215","0.04314"
"49562","297.33600","24.77822","0.04352"
"49614","297.64800","24.80416","0.04339"
"49666","297.96000","24.83023","0.04368"
"49718","298.27200","24.85624","0.04402"
"49770","298.58400","24.88219","0.04447"
"49822","298.89600","24.90826","0.04427"
"49874","299.20800","24.93415","0.04485"
"49926","299.52000","24.96022","0.04545"
"49978","299.83200","24.98616","0.04610"
"50030","300.14400","25.01217","0.04609"
"50082","300.45600","25.03818","0.04670"
"50134","300.76800","25.06419","0.04681"
"50186","301.08000","25.09020","0.04736"
"50238","301.39200","25.11615","0.04762"
"50290","301.70400","25.14222","0.04817"
"50342","302.01600","25.16822","0.04877"
"50394","302.32800","25.19417","0.04884"
"50446","302.64000","25.22024","0.04915"
"50498","302.95200","25.24619","0.05021"
"50550","303.26400","25.27226","0.04817"
"50602","303.57600","25.29815","0.04898"
"50654","303.88800","25.32422","0.04425"
"50706","304.20000","25.35022","0.04306"
"50758","304.51200","25.37617","0.04367"
"50810","304.82400","25.40224","0.04772"
"50862","305.13600","25.42813","0.04540"
"50914","305.44800","25.45420","0.04624"
"50966","305.76000","25.48021","0.05004"
"51018","306.07200","25.50622","0.04852"
"51070","306.38400","25.53222","0.04907"
"51122","306.69600","25.55817","0.05185"
"51174","307.00800","25.58418","0.05175"
"51226","307.32000","25.61013","0.05355"
"51278","307.63200","25.63626","0.05502"
"51330","307.94400","25.66227","0.05487"
"51382","308.25600","25.68821","0.05652"
"51434","308.56800","25.71422","0.05691"
"51486","308.88000","25.74017","0.05494"
"51538","309.19200","25.76624","0.04931"
"51590","309.50400","25.79219","0.05728"
"51642","309.81600","25.81825","0.05476"
"51694","310.12800","25.84427","0.05601"
"51746","310.44000","25.87016","0.05652"
"51798","310.75200","25.89622","0.05950"
"51850","311.06400","25.92211","0.05921"
"51902","311.37600","25.94824","0.06310"
"51954","311.68800","25.97425","0.06107"
"52006","312.00000","26.00026","0.06430"
"52058","312.31200","26.02627","0.06370"
"52110","312.62400","26.05221","0.06482"
"52162","312.93600","26.07822","0.06509"
"52214","313.24800","26.10423","0.06666"
"52266","313.56000","26.13024","0.06703"
"52318","313.87200","26.15625","0.05992"
"52370","314.18400","26.18220","0.06029"
"52422","314.49600","26.20820","0.06329"
"52474","314.80800","26.23415","0.06171"
"52526","315.12000","26.26022","0.02675"
"52578","315.43200","26.28617","0.02146"
"52630","315.74400","26.31224","0.03116"
"52682","316.05600","26.33825","0.02297"
"52734","316.36800","26.36420","0.03051"
"52786","316.68000","26.39020","0.02238"
"52838","316.99200","26.41621","0.03229"
"52890","317.30400","26.44222","0.02281"
"52942","317.61600","26.46823","0.03192"
"52994","317.92800","26.49418","0.02542"
"53046","318.24000","26.52019","0.02942"
"53098","318.55200","26.54620","0.03027"
"53150","318.86400","26.57226","0.02736"
"53202","319.17600","26.59821","0.03276"
"53254","319.48800","26.62422","0.02765"
"53306","319.80000","26.65023","0.03369"
"53358","320.11200","26.67624","0.03132"
"53410","320.42400","26.70225","0.03258"
"53462","320.73600","26.72813","0.03509"
"53514","321.04800","26.75420","0.03186"
"53566","321.36000","26.78015","0.03584"
"53618","321.67200","26.80622","0.03350"
"53670","321.98400","26.83223","0.03580"
"53722","322.29600","26.85818","0.03576"
"53774","322.60800","26.88424","0.03592"
"53826","322.92000","26.91019","0.03748"
"53878","323.23200","26.93620","0.03685"
"53930","323.54400","26.96221","0.03856"
"53982","323.85600","26.98822","0.03813"
"54034","324.16800","27.01429","0.03826"
"54086","324.48000","27.04018","0.03963"
"54138","324.79200","27.06624","0.03967"
"54190","325.10400","27.09219","0.03998"
"54242","325.41600","27.11820","0.04020"
"54294","325.72800","27.14421","0.04073"
"54346","326.04000","27.17016","0.04067"
"54398","326.35200","27.19622","0.04135"
"54450","326.66400","27.22218","0.04154"
"54502","326.97600","27.24825","0.04171"
"54554","327.28800","27.27425","0.04184"
"54606","327.60000","27.30026","0.04197"
"54658","327.91200","27.32627","0.04264"
"54710","328.22400","27.35210","0.04251"
"54762","328.53600","27.37822","0.04281"
"54814","328.84800","27.40417","0.04297"
"54866","329.16000","27.43018","0.04337"
"54918","329.47200","27.45625","0.04387"
"54970","329.78400","27.48220","0.04406"
"55022","330.09600","27.50821","0.04439"
"55074","330.40800","27.53416","0.04460"
"55126","330.72000","27.56028","0.04512"
"55178","331.03200","27.58623","0.04515"
"55230","331.34400","27.61224","0.04621"
"55282","331.65600","27.63825","0.04621"
"55334","331.96800","27.66420","0.04715"
"55386","332.28000","27.69021","0.04699"
"55438","332.59200","27.71616","0.04768"
"55490","332.90400","27.74223","0.04857"
"55542","333.21600","27.76823","0.04929"
"55594","333.52800","27.79424","0.05009"
"55646","333.84000","27.82019","0.05109"
"55698","334.15200","27.84620","0.05179"
"55750","334.46400","27.87221","0.05305"
"55802","334.77600","27.89816","0.05391"
"55854","335.08800","27.92422","0.05443"
"55906","335.40000","27.95017","0.05607"
"55958","335.71200","27.97612","0.05713"
"56010","336.02400","28.00219","0.05880"
"56062","336.33600","28.02814","0.05995"
"56114","336.64800","28.05421","0.06079"
"56166","336.96000","28.08021","0.06184"
"56218","337.27200","28.10622","0.06291"
"56270","337.58400","28.13223","0.06370"
"56322","337.89600","28.15818","0.06489"
"56374","338.20800","28.18425","0.06570"
"56426","338.52000","28.21020","0.06703"
"56478","338.83200","28.23621","0.06792"
"56530","339.14400","28.26221","0.06833"
"56582","339.45600","28.28816","0.06935"
"56634","339.76800","28.31423","0.07019"
"56686","340.08000","28.34024","0.07097"
"56738","340.39200","28.36631","0.07093"
"56790","340.70400","28.39220","0.07250"
"56842","341.01600","28.41821","0.07335"
"56894","341.32800","28.44421","0.07415"
"56946","341.64000","28.47022","0.07547"
"56998","341.95200","28.49623","0.07574"
"57050","342.26400","28.52212","0.07688"
"57102","342.57600","28.54825","0.07781"
"57154","342.88800","28.57420","0.07827"
"57206","343.20000","28.60020","0.07874"
"57258","343.51200","28.62621","0.07974"
"57310","343.82400","28.65222","0.08092"
"57362","344.13600","28.67823","0.08148"
"57414","344.44800","28.70418","0.08244"
"57466","344.76000","28.73025","0.08309"
"57518","345.07200","28.75625","0.08441"
"57570","345.38400","28.78220","0.08437"
"57622","345.69600","28.80827","0.08527"
"57674","346.00800","28.83422","0.08573"
"57726","346.32000","28.86029","0.08627"
"57778","346.63200","28.88612","0.08672"
"57830","346.94400","28.91225","0.08063"
"57882","347.25600","28.93825","0.08401"
"57934","347.56800","28.96420","0.08231"
"57986","347.88000","28.99021","0.08700"
"58038","348.19200","29.01616","0.08502"
"58090","348.50400","29.04223","0.08682"
"58142","348.81600","29.06818","0.08769"
"58194","349.12800","29.09425","0.08789"
"58246","349.44000","29.12019","0.08854"
"58298","349.75200","29.14620","0.08846"
"58350","350.06400","29.17221","0.08897"
"58402","350.37600","29.19816","0.08982"
"58454","350.68800","29.22423","0.08948"
"58506","351.00000","29.25023","0.09002"
"58558","351.31200","29.27618","0.09030"
"58610","351.62400","29.30219","0.09043"
"58662","351.93600","29.32814","0.09151"
"58714","352.24800","29.35421","0.09120"
"58766","352.56000","29.38022","0.09162"
"58818","352.87200","29.40623","0.09218"
"58870","353.18400","29.43224","0.09194"
"58922","353.49600","29.45824","0.09324"
"58974","353.80800","29.48425","0.09335"
"59026","354.12000","29.51014","0.09435"
"59078","354.43200","29.53627","0.09510"
"59130","354.74400","29.56222","0.09533"
"59182","355.05600","29.58823","0.09664"
"59234","355.36800","29.61423","0.09848"
"59286","355.68000","29.64018","0.09952"
"59338","355.99200","29.66625","0.10045"
"59390","356.30400","29.69220","0.10245"
"59442","356.61600","29.71827","0.10284"
"59494","356.92800","29.74416","0.10526"
"59546","357.24000","29.77017","0.10699"
"59598","357.55200","29.79623","0.10736"
"59650","357.86400","29.82218","0.11011"
"59702","358.17600","29.84825","0.11194"
"59754","358.48800","29.87420","0.11370"
"59806","358.80000","29.90027","0.11573"
"59858","359.11200","29.92622","0.11630"
"59910","359.42400","29.95217","0.11875"
"59962","359.73600","29.97823","0.12027"
"60014","360.04800","30.00424","0.12190"
"60066","360.36000","30.03019","0.12315"
"60118","360.67200","30.05620","0.12569"
"60170","360.98400","30.08215","0.12765"
"60222","361.29600","30.10822","0.12886"
"60274","361.60800","30.13416","0.13196"
"60326","361.92000","30.16023","0.13421"
"60378","362.23200","30.18618","0.13576"
"60430","362.54400","30.21219","0.13821"
"60482","362.85600","30.23826","0.13965"
"60534","363.16800","30.26421","0.14122"
"60586","363.48000","30.29028","0.14432"
"60638","363.79200","30.31616","0.14495"
"60690","364.10400","30.34223","0.14640"
"60742","364.41600","30.36812","0.14726"
"60794","364.72800","30.39419","0.14842"
"60846","365.04000","30.42026","0.14883"
"60898","365.35200","30.44615","0.14968"
"60950","365.66400","30.47221","0.14996"
"61002","365.97600","30.49816","0.15026"
"61054","366.28800","30.52423","0.15092"
"61106","366.60000","30.55018","0.15137"
"61158","366.91200","30.57619","0.15214"
"61210","367.22400","30.60220","0.15263"
"61262","367.53600","30.62815","0.15325"
"61314","367.84800","30.65421","0.15395"
"61366","368.16000","30.68016","0.15436"
"61418","368.47200","30.70623","0.15541"
"61470","368.78400","30.73224","0.15650"
"61522","369.09600","30.75819","0.15874"
"61574","369.40800","30.78420","0.15971"
"61626","369.72000","30.81014","0.16114"
"61678","370.03200","30.83621","0.16311"
"61730","370.34400","30.86222","0.16442"
"61782","370.65600","30.88823","0.16573"
"61834","370.96800","30.91424","0.16805"
"61886","371.28000","30.94019","0.16877"
"61938","371.59200","30.96625","0.17084"
"61990","371.90400","30.99221","0.17213"
"62042","372.21600","31.01821","0.17328"
"62094","372.52800","31.04428","0.17416"
"62146","372.84000","31.07017","0.17618"
"62198","373.15200","31.09624","0.17740"
"62250","373.46400","31.12213","0.17945"
"62302","373.77600","31.14825","0.18088"
"62354","374.08800","31.17421","0.18148"
"62406","374.40000","31.20021","0.18303"
"62458","374.71200","31.22622","0.18415"
"62510","375.02400","31.25223","0.18493"
"62562","375.33600","31.27817","0.18591"
"62614","375.64800","31.30412","0.18654"
"62666","375.96000","31.33025","0.18765"
"62718","376.27200","31.35626","0.18868"
"62770","376.58400","31.38221","0.18951"
"62822","376.89600","31.40822","0.18997"
"62874","377.20800","31.43417","0.19134"
"62926","377.52000","31.46024","0.19225"
"62978","377.83200","31.48618","0.19296"
"63030","378.14400","31.51219","0.19380"
"63082","378.45600","31.53820","0.19433"
"63134","378.76800","31.56415","0.19517"
"63186","379.08000","31.59016","0.19605"
"63238","379.39200","31.61617","0.19669"
"63290","379.70400","31.64224","0.19749"
"63342","380.01600","31.66818","0.19791"
"63394","380.32800","31.69419","0.19758"
"63446","380.64000","31.72026","0.01634"
"63498","380.95200","31.74621","0.01669"
"63550","381.26400","31.77228","0.01061"
"63602","381.57600","31.79823","0.01290"
"63654","381.88800","31.82423","0.00953"
"63706","382.20000","31.85024","0.01149"
"63758","382.51200","31.87619","0.01132"
"63803","382.78200","31.89867","0.01068"