File: Trajectories_together/170122_1Specimen_RawData_7.csv
"","V1","V2","V3"
"1","End date","1/22/2017",""
"2","Specimen label","18BG_46",""
"3","Maximum Load","0.05879","N"
"4","Time","Extension","Load"
"5","(s)","(mm)","(N)"
"6","0.00000","0.00000","-0.00024"
"54","0.28800","0.02332","0.00117"
"102","0.57600","0.04819","0.00277"
"150","0.86400","0.07223","0.00391"
"198","1.15200","0.09620","0.00557"
"246","1.44000","0.12024","0.00636"
"294","1.72800","0.14415","0.00762"
"342","2.01600","0.16819","0.00801"
"390","2.30400","0.19210","0.01033"
"438","2.59200","0.21620","0.00939"
"486","2.88000","0.24005","0.01205"
"534","3.16800","0.26415","0.01167"
"582","3.45600","0.28813","0.01187"
"630","3.74400","0.31216","0.01251"
"678","4.03200","0.33614","0.01413"
"726","4.32000","0.36017","0.01358"
"774","4.60800","0.38415","0.01468"
"822","4.89600","0.40812","0.01455"
"870","5.18400","0.43216","0.01509"
"918","5.47200","0.45613","0.01530"
"966","5.76000","0.48017","0.01749"
"1014","6.04800","0.50415","0.01619"
"1062","6.33600","0.52818","0.01769"
"1110","6.62400","0.55216","0.01700"
"1158","6.91200","0.57619","0.01731"
"1206","7.20000","0.60017","0.01844"
"1254","7.48800","0.62420","0.01846"
"1302","7.77600","0.64818","0.01842"
"1350","8.06400","0.67215","0.01857"
"1398","8.35200","0.69619","0.01844"
"1446","8.64000","0.72016","0.01929"
"1494","8.92800","0.74420","0.01900"
"1542","9.21600","0.76818","0.01883"
"1590","9.50400","0.79221","0.01928"
"1638","9.79200","0.81613","0.01938"
"1686","10.08000","0.84016","0.01913"
"1734","10.36800","0.86414","0.02029"
"1782","10.65600","0.88817","0.02019"
"1830","10.94400","0.91209","0.02064"
"1878","11.23200","0.93618","0.02019"
"1926","11.52000","0.96010","0.02064"
"1974","11.80800","0.98420","0.02067"
"2022","12.09600","1.00811","0.02103"
"2070","12.38400","1.03221","0.02091"
"2118","12.67200","1.05618","0.02047"
"2166","12.96000","1.08016","0.02130"
"2214","13.24800","1.10419","0.02157"
"2262","13.53600","1.12817","0.02169"
"2310","13.82400","1.15220","0.02125"
"2358","14.11200","1.17618","0.02186"
"2406","14.40000","1.20016","0.02133"
"2454","14.68800","1.22413","0.02221"
"2502","14.97600","1.24817","0.02216"
"2550","15.26400","1.27214","0.02266"
"2598","15.55200","1.29618","0.02161"
"2646","15.84000","1.32015","0.02217"
"2694","16.12800","1.34419","0.02230"
"2742","16.41600","1.36816","0.02187"
"2790","16.70400","1.39220","0.02190"
"2838","16.99200","1.41623","0.02267"
"2886","17.28000","1.44015","0.02248"
"2934","17.56800","1.46419","0.02298"
"2982","17.85600","1.48816","0.02302"
"3030","18.14400","1.51220","0.02292"
"3078","18.43200","1.53611","0.02301"
"3126","18.72000","1.56021","0.02279"
"3174","19.00800","1.58412","0.02353"
"3222","19.29600","1.60822","0.02268"
"3270","19.58400","1.63213","0.02318"
"3318","19.87200","1.65623","0.02327"
"3366","20.16000","1.68021","0.02374"
"3414","20.44800","1.70418","0.02382"
"3462","20.73600","1.72816","0.02315"
"3510","21.02400","1.75219","0.02385"
"3558","21.31200","1.77623","0.02397"
"3606","21.60000","1.80014","0.02326"
"3654","21.88800","1.82418","0.02409"
"3702","22.17600","1.84815","0.02363"
"3750","22.46400","1.87225","0.02352"
"3798","22.75200","1.89617","0.02354"
"3846","23.04000","1.92020","0.02401"
"3894","23.32800","1.94418","0.02377"
"3942","23.61600","1.96821","0.02388"
"3990","23.90400","1.99219","0.02440"
"4038","24.19200","2.01622","0.02434"
"4086","24.48000","2.04020","0.02438"
"4134","24.76800","2.06423","0.02482"
"4182","25.05600","2.08821","0.02471"
"4230","25.34400","2.11219","0.02431"
"4278","25.63200","2.13622","0.02440"
"4326","25.92000","2.16014","0.02441"
"4374","26.20800","2.18417","0.02435"
"4422","26.49600","2.20815","0.02502"
"4470","26.78400","2.23224","0.02472"
"4518","27.07200","2.25610","0.02512"
"4566","27.36000","2.28019","0.02443"
"4614","27.64800","2.30417","0.02500"
"4662","27.93600","2.32820","0.02503"
"4710","28.22400","2.35218","0.02487"
"4758","28.51200","2.37622","0.02523"
"4806","28.80000","2.40013","0.02501"
"4854","29.08800","2.42417","0.02533"
"4902","29.37600","2.44814","0.02513"
"4950","29.66400","2.47212","0.02558"
"4998","29.95200","2.49621","0.02611"
"5046","30.24000","2.52019","0.02610"
"5094","30.52800","2.54422","0.02564"
"5142","30.81600","2.56814","0.02633"
"5190","31.10400","2.59218","0.02600"
"5238","31.39200","2.61615","0.02564"
"5286","31.68000","2.64025","0.02631"
"5334","31.96800","2.66416","0.02643"
"5382","32.25600","2.68820","0.02597"
"5430","32.54400","2.71217","0.02622"
"5478","32.83200","2.73615","0.02597"
"5526","33.12000","2.76018","0.02626"
"5574","33.40800","2.78416","0.02713"
"5622","33.69600","2.80819","0.02639"
"5670","33.98400","2.83211","0.02677"
"5718","34.27200","2.85621","0.02658"
"5766","34.56000","2.88012","0.02666"
"5814","34.84800","2.90416","0.02643"
"5862","35.13600","2.92813","0.02685"
"5910","35.42400","2.95217","0.02687"
"5958","35.71200","2.97608","0.02716"
"6006","36.00000","3.00018","0.02705"
"6054","36.28800","3.02415","0.02757"
"6102","36.57600","3.04813","0.02678"
"6150","36.86400","3.07211","0.02747"
"6198","37.15200","3.09614","0.02766"
"6246","37.44000","3.12018","0.02737"
"6294","37.72800","3.14415","0.02716"
"6342","38.01600","3.16819","0.02757"
"6390","38.30400","3.19216","0.02791"
"6438","38.59200","3.21620","0.02765"
"6486","38.88000","3.24011","0.02747"
"6534","39.16800","3.26421","0.02725"
"6582","39.45600","3.28813","0.02741"
"6630","39.74400","3.31216","0.02772"
"6678","40.03200","3.33614","0.02806"
"6726","40.32000","3.36017","0.02812"
"6774","40.60800","3.38415","0.02812"
"6822","40.89600","3.40818","0.02806"
"6870","41.18400","3.43216","0.02828"
"6918","41.47200","3.45607","0.02866"
"6966","41.76200","3.48035","0.02803"
"7014","42.05000","3.50432","0.02807"
"7062","42.33800","3.52842","0.02860"
"7110","42.62600","3.55234","0.02844"
"7158","42.91400","3.57637","0.02918"
"7206","43.20200","3.60029","0.02813"
"7254","43.49000","3.62432","0.02834"
"7302","43.77800","3.64824","0.02860"
"7350","44.06600","3.67233","0.02833"
"7398","44.35400","3.69625","0.02820"
"7446","44.64200","3.72034","0.02887"
"7494","44.93000","3.74432","0.02907"
"7542","45.21800","3.76830","0.02919"
"7590","45.50600","3.79233","0.02931"
"7638","45.79400","3.81631","0.02938"
"7686","46.08200","3.84040","0.02901"
"7734","46.37000","3.86432","0.02921"
"7782","46.65800","3.88829","0.02957"
"7830","46.94600","3.91233","0.02920"
"7878","47.23400","3.93630","0.02983"
"7926","47.52200","3.96028","0.02921"
"7974","47.81000","3.98437","0.02967"
"8022","48.09800","4.00829","0.02957"
"8070","48.38600","4.03233","0.02925"
"8118","48.67400","4.05630","0.02998"
"8166","48.96200","4.08034","0.03021"
"8214","49.25000","4.10431","0.02994"
"8262","49.53800","4.12829","0.03026"
"8310","49.82600","4.15232","0.03026"
"8358","50.11400","4.17630","0.02994"
"8406","50.40200","4.20033","0.03015"
"8454","50.69000","4.22431","0.03095"
"8502","50.97800","4.24835","0.03048"
"8550","51.26600","4.27226","0.03074"
"8598","51.55400","4.29636","0.03046"
"8646","51.84200","4.32027","0.03106"
"8694","52.13000","4.34437","0.03082"
"8742","52.41800","4.36828","0.03082"
"8790","52.70600","4.39232","0.03096"
"8838","52.99400","4.41629","0.03089"
"8886","53.28200","4.44033","0.03147"
"8934","53.57000","4.46430","0.03118"
"8982","53.85800","4.48834","0.03084"
"9030","54.14600","4.51232","0.03145"
"9078","54.43400","4.53629","0.03192"
"9126","54.72200","4.56033","0.03161"
"9174","55.01000","4.58436","0.03168"
"9222","55.29800","4.60834","0.03130"
"9270","55.58600","4.63231","0.03159"
"9318","55.87400","4.65635","0.03156"
"9366","56.16200","4.68026","0.03150"
"9414","56.45000","4.70436","0.03220"
"9462","56.73800","4.72828","0.03157"
"9510","57.02600","4.75237","0.03152"
"9558","57.31400","4.77635","0.03179"
"9606","57.60200","4.80038","0.03279"
"9654","57.89000","4.82436","0.03240"
"9702","58.17800","4.84833","0.03237"
"9750","58.46600","4.87231","0.03260"
"9798","58.75400","4.89628","0.03279"
"9846","59.04200","4.92032","0.03271"
"9894","59.33000","4.94430","0.03241"
"9942","59.61800","4.96839","0.03283"
"9990","59.90600","4.99231","0.03304"
"10038","60.19400","5.01640","0.03366"
"10086","60.48200","5.04032","0.03221"
"10134","60.77000","5.06441","0.03238"
"10182","61.05800","5.08833","0.03240"
"10230","61.34600","5.11236","0.03361"
"10278","61.63400","5.13634","0.03290"
"10326","61.92200","5.16031","0.03371"
"10374","62.21000","5.18435","0.03331"
"10422","62.49800","5.20833","0.03335"
"10470","62.78600","5.23236","0.03314"
"10518","63.07400","5.25628","0.03375"
"10566","63.36200","5.28037","0.03411"
"10614","63.65000","5.30435","0.03394"
"10662","63.93800","5.32838","0.03375"
"10710","64.22600","5.35236","0.03373"
"10758","64.51400","5.37639","0.03399"
"10806","64.80200","5.40037","0.03414"
"10854","65.09000","5.42441","0.03393"
"10902","65.37800","5.44832","0.03386"
"10950","65.66600","5.47236","0.03433"
"10998","65.95400","5.49633","0.03450"
"11046","66.24200","5.52037","0.03446"
"11094","66.53000","5.54440","0.03447"
"11142","66.81800","5.56826","0.03488"
"11190","67.10600","5.59235","0.03480"
"11238","67.39400","5.61633","0.03465"
"11286","67.68200","5.64036","0.03435"
"11334","67.97000","5.66434","0.03503"
"11382","68.25800","5.68838","0.03523"
"11430","68.54600","5.71235","0.03494"
"11478","68.83400","5.73639","0.03532"
"11526","69.12200","5.76036","0.03580"
"11574","69.41000","5.78440","0.03601"
"11622","69.69800","5.80837","0.03586"
"11670","69.98600","5.83241","0.03580"
"11718","70.27400","5.85638","0.03561"
"11766","70.56200","5.88036","0.03538"
"11814","70.85000","5.90434","0.03624"
"11862","71.13800","5.92825","0.03619"
"11910","71.42600","5.95235","0.03599"
"11958","71.71400","5.97632","0.03630"
"12006","72.00200","6.00036","0.03639"
"12054","72.29000","6.02433","0.03568"
"12102","72.57800","6.04843","0.03685"
"12150","72.86600","6.07234","0.03627"
"12198","73.15400","6.09638","0.03631"
"12246","73.44200","6.12036","0.03573"
"12294","73.73000","6.14439","0.03644"
"12342","74.01800","6.16831","0.03654"
"12390","74.30600","6.19234","0.03599"
"12438","74.59400","6.21638","0.03601"
"12486","74.88200","6.24035","0.03617"
"12534","75.17000","6.26439","0.03670"
"12582","75.45800","6.28830","0.03677"
"12630","75.74600","6.31234","0.03670"
"12678","76.03400","6.33626","0.03674"
"12726","76.32200","6.36035","0.03689"
"12774","76.61000","6.38427","0.03683"
"12822","76.89800","6.40836","0.03655"
"12870","77.18600","6.43234","0.03756"
"12918","77.47400","6.45631","0.03718"
"12966","77.76200","6.48035","0.03684"
"13014","78.05000","6.50438","0.03686"
"13062","78.33800","6.52836","0.03722"
"13110","78.62600","6.55233","0.03628"
"13158","78.91400","6.57643","0.03536"
"13206","79.20200","6.60035","0.03587"
"13254","79.49000","6.62438","0.03603"
"13302","79.77800","6.64830","0.03590"
"13350","80.06600","6.67233","0.03613"
"13398","80.35400","6.69625","0.03437"
"13446","80.64200","6.72034","0.03508"
"13494","80.93000","6.74432","0.03510"
"13542","81.21800","6.76835","0.03548"
"13590","81.50600","6.79233","0.03571"
"13638","81.79400","6.81637","0.03555"
"13686","82.08200","6.84034","0.03559"
"13734","82.37000","6.86432","0.03603"
"13782","82.65800","6.88835","0.03519"
"13830","82.94600","6.91233","0.03583"
"13878","83.23400","6.93636","0.03639"
"13926","83.52200","6.96034","0.03645"
"13974","83.81000","6.98431","0.03638"
"14022","84.09800","7.00829","0.03606"
"14070","84.38600","7.03233","0.03703"
"14118","84.67400","7.05624","0.03689"
"14166","84.96200","7.08040","0.03684"
"14214","85.25000","7.10431","0.03712"
"14262","85.53800","7.12835","0.03675"
"14310","85.82600","7.15232","0.03668"
"14358","86.11400","7.17636","0.03757"
"14406","86.40200","7.20039","0.03737"
"14454","86.69000","7.22437","0.03704"
"14502","86.97800","7.24834","0.03746"
"14550","87.26600","7.27232","0.03719"
"14598","87.55400","7.29636","0.03746"
"14646","87.84200","7.32027","0.03760"
"14694","88.13000","7.34431","0.03731"
"14742","88.41800","7.36822","0.03729"
"14790","88.70600","7.39238","0.03817"
"14838","88.99400","7.41629","0.03744"
"14886","89.28200","7.44033","0.03748"
"14934","89.57000","7.46430","0.03804"
"14982","89.85800","7.48834","0.03743"
"15030","90.14600","7.51232","0.03749"
"15078","90.43400","7.53635","0.03834"
"15126","90.72200","7.56033","0.03851"
"15174","91.01000","7.58436","0.03792"
"15222","91.29800","7.60834","0.03828"
"15270","91.58600","7.63237","0.03848"
"15318","91.87400","7.65635","0.03615"
"15366","92.16200","7.68032","0.03715"
"15414","92.45000","7.70430","0.03748"
"15462","92.73800","7.72828","0.03774"
"15510","93.02600","7.75231","0.03847"
"15558","93.31400","7.77629","0.03854"
"15606","93.60200","7.80038","0.03858"
"15654","93.89000","7.82436","0.03794"
"15702","94.17800","7.84839","0.03881"
"15750","94.46600","7.87237","0.03722"
"15798","94.75400","7.89628","0.03723"
"15846","95.04200","7.92038","0.03765"
"15894","95.33000","7.94430","0.03785"
"15942","95.61800","7.96839","0.03728"
"15990","95.90600","7.99231","0.03791"
"16038","96.19400","8.01634","0.03761"
"16086","96.48200","8.04032","0.03795"
"16134","96.77000","8.06435","0.03799"
"16182","97.05800","8.08827","0.03843"
"16230","97.34600","8.11236","0.03843"
"16278","97.63400","8.13634","0.03830"
"16326","97.92200","8.16037","0.03832"
"16374","98.21000","8.18435","0.03895"
"16422","98.49800","8.20839","0.03916"
"16470","98.78600","8.23236","0.03907"
"16518","99.07400","8.25634","0.03979"
"16566","99.36200","8.28037","0.03962"
"16614","99.65000","8.30435","0.03881"
"16662","99.93800","8.32838","0.03911"
"16710","100.22600","8.35236","0.03874"
"16758","100.51400","8.37639","0.03988"
"16806","100.80200","8.40031","0.04004"
"16854","101.09000","8.42435","0.03956"
"16902","101.37800","8.44832","0.03983"
"16950","101.66600","8.47236","0.04036"
"16998","101.95400","8.49633","0.04016"
"17046","102.24200","8.52037","0.04024"
"17094","102.53000","8.54434","0.04009"
"17142","102.81800","8.56838","0.04053"
"17190","103.10600","8.59235","0.04023"
"17238","103.39400","8.61633","0.04077"
"17286","103.68200","8.64036","0.04035"
"17334","103.97000","8.66434","0.04036"
"17382","104.25800","8.68838","0.04029"
"17430","104.54600","8.71229","0.04117"
"17478","104.83400","8.73639","0.04112"
"17526","105.12200","8.76036","0.04153"
"17574","105.41000","8.78434","0.04056"
"17622","105.69800","8.80831","0.04137"
"17670","105.98600","8.83241","0.04129"
"17718","106.27400","8.85638","0.04182"
"17766","106.56200","8.88036","0.04187"
"17814","106.85000","8.90434","0.04200"
"17862","107.13800","8.92837","0.04189"
"17910","107.42600","8.95235","0.04175"
"17958","107.71400","8.97632","0.04297"
"18006","108.00200","9.00042","0.04260"
"18054","108.29000","9.02433","0.04339"
"18102","108.57800","9.04837","0.04244"
"18150","108.86600","9.07234","0.04288"
"18198","109.15400","9.09638","0.04252"
"18246","109.44200","9.12030","0.04317"
"18294","109.73000","9.14433","0.04275"
"18342","110.01800","9.16837","0.04377"
"18390","110.30600","9.19234","0.04355"
"18438","110.59400","9.21632","0.04315"
"18486","110.88200","9.24035","0.04369"
"18534","111.17000","9.26439","0.04378"
"18582","111.45800","9.28836","0.04446"
"18630","111.74600","9.31240","0.04382"
"18678","112.03400","9.33632","0.04425"
"18726","112.32200","9.36035","0.04426"
"18774","112.61000","9.38433","0.04378"
"18822","112.89800","9.40836","0.04433"
"18870","113.18600","9.43228","0.04389"
"18918","113.47400","9.45637","0.04485"
"18966","113.76200","9.48035","0.04395"
"19014","114.05000","9.50438","0.04467"
"19062","114.33800","9.52830","0.04439"
"19110","114.62600","9.55233","0.04431"
"19158","114.91400","9.57631","0.04417"
"19206","115.20200","9.60035","0.04421"
"19254","115.49000","9.62438","0.04425"
"19302","115.77800","9.64830","0.04484"
"19350","116.06600","9.67233","0.04559"
"19398","116.35400","9.69631","0.04553"
"19446","116.64200","9.72034","0.04531"
"19494","116.93000","9.74432","0.04513"
"19542","117.21800","9.76835","0.04578"
"19590","117.50600","9.79233","0.04583"
"19638","117.79400","9.81636","0.04568"
"19686","118.08200","9.84034","0.04658"
"19734","118.37000","9.86438","0.04565"
"19782","118.65800","9.88835","0.04640"
"19830","118.94600","9.91233","0.04679"
"19878","119.23400","9.93636","0.04690"
"19926","119.52200","9.96034","0.04640"
"19974","119.81000","9.98431","0.04681"
"20022","120.09800","10.00829","0.04654"
"20070","120.38600","10.03232","0.04687"
"20118","120.67400","10.05624","0.04639"
"20166","120.96200","10.08034","0.04656"
"20214","121.25000","10.10425","0.04700"
"20262","121.53800","10.12835","0.04715"
"20310","121.82600","10.15226","0.04736"
"20358","122.11400","10.17636","0.04717"
"20406","122.40200","10.20027","0.04693"
"20454","122.69000","10.22437","0.04694"
"20502","122.97800","10.24828","0.04731"
"20550","123.26600","10.27232","0.04720"
"20598","123.55400","10.29636","0.04755"
"20646","123.84200","10.32033","0.04705"
"20694","124.13000","10.34437","0.04705"
"20742","124.41800","10.36834","0.04701"
"20790","124.70600","10.39232","0.04746"
"20838","124.99400","10.41623","0.04745"
"20886","125.28200","10.44033","0.04732"
"20934","125.57000","10.46430","0.04790"
"20982","125.85800","10.48834","0.04704"
"21030","126.14600","10.51231","0.04756"
"21078","126.43400","10.53635","0.04766"
"21126","126.72200","10.56033","0.04712"
"21174","127.01000","10.58430","0.04718"
"21222","127.29800","10.60834","0.04695"
"21270","127.58600","10.63231","0.04752"
"21318","127.87400","10.65635","0.04771"
"21366","128.16200","10.68032","0.04748"
"21414","128.45000","10.70436","0.04708"
"21462","128.73800","10.72828","0.04745"
"21510","129.02600","10.75231","0.04780"
"21558","129.31400","10.77623","0.04746"
"21606","129.60200","10.80038","0.04739"
"21654","129.89000","10.82430","0.04784"
"21702","130.17800","10.84839","0.04769"
"21750","130.46600","10.87231","0.04805"
"21798","130.75400","10.89634","0.04805"
"21846","131.04200","10.92026","0.04775"
"21894","131.33000","10.94429","0.04825"
"21942","131.61800","10.96833","0.04787"
"21990","131.90600","10.99231","0.04861"
"22038","132.19400","11.01634","0.04873"
"22086","132.48200","11.04032","0.04880"
"22134","132.77000","11.06435","0.04888"
"22182","133.05800","11.08833","0.04774"
"22230","133.34600","11.11230","0.04781"
"22278","133.63400","11.13628","0.04794"
"22326","133.92200","11.16037","0.04815"
"22374","134.21000","11.18429","0.04868"
"22422","134.49800","11.20833","0.04854"
"22470","134.78600","11.23230","0.04884"
"22518","135.07400","11.25634","0.04836"
"22566","135.36200","11.28031","0.04823"
"22614","135.65000","11.30429","0.04862"
"22662","135.93800","11.32838","0.04875"
"22710","136.22600","11.35230","0.04863"
"22758","136.51400","11.37633","0.04902"
"22806","136.80200","11.40025","0.04853"
"22854","137.09000","11.42434","0.04925"
"22902","137.37800","11.44826","0.04883"
"22950","137.66600","11.47236","0.04876"
"22998","137.95400","11.49627","0.04858"
"23046","138.24200","11.52037","0.04872"
"23094","138.53000","11.54434","0.04889"
"23142","138.81800","11.56838","0.04871"
"23190","139.10600","11.59235","0.04956"
"23238","139.39400","11.61633","0.04886"
"23286","139.68200","11.64030","0.04960"
"23334","139.97000","11.66428","0.04962"
"23382","140.25800","11.68838","0.03671"
"23430","140.54600","11.71235","0.03924"
"23478","140.83400","11.73639","0.03713"
"23526","141.12200","11.76036","0.03921"
"23574","141.41000","11.78440","0.03870"
"23622","141.69800","11.80831","0.03930"
"23670","141.98600","11.83235","0.04032"
"23718","142.27400","11.85632","0.04019"
"23766","142.56200","11.88036","0.04116"
"23814","142.85000","11.90434","0.04149"
"23862","143.13800","11.92831","0.04102"
"23910","143.42600","11.95235","0.04263"
"23958","143.71400","11.97638","0.04243"
"24006","144.00200","12.00036","0.04241"
"24054","144.29000","12.02433","0.04254"
"24102","144.57800","12.04837","0.04274"
"24150","144.86600","12.07234","0.04405"
"24198","145.15400","12.09638","0.04336"
"24246","145.44200","12.12035","0.04469"
"24294","145.73000","12.14439","0.04409"
"24342","146.01800","12.16831","0.04521"
"24390","146.30600","12.19240","0.04494"
"24438","146.59400","12.21632","0.04491"
"24486","146.88200","12.24035","0.04468"
"24534","147.17000","12.26433","0.04545"
"24582","147.45800","12.28836","0.04571"
"24630","147.74600","12.31240","0.04604"
"24678","148.03400","12.33637","0.04425"
"24726","148.32200","12.36035","0.04427"
"24774","148.61000","12.38433","0.04434"
"24822","148.89800","12.40836","0.04554"
"24870","149.18600","12.43234","0.04556"
"24918","149.47400","12.45637","0.04545"
"24966","149.76200","12.48035","0.04539"
"25014","150.05000","12.50438","0.04551"
"25062","150.33800","12.52836","0.04555"
"25110","150.62600","12.55233","0.04617"
"25158","150.91400","12.57631","0.04555"
"25206","151.20200","12.60035","0.04441"
"25254","151.49000","12.62432","0.04450"
"25302","151.77800","12.64836","0.04472"
"25350","152.06600","12.67233","0.04448"
"25398","152.35400","12.69637","0.04513"
"25446","152.64200","12.72040","0.04505"
"25494","152.93000","12.74432","0.04545"
"25542","153.21800","12.76835","0.04567"
"25590","153.50600","12.79233","0.04611"
"25638","153.79400","12.81636","0.04576"
"25686","154.08200","12.84034","0.04635"
"25734","154.37000","12.86438","0.04657"
"25782","154.65800","12.88829","0.04678"
"25830","154.94600","12.91233","0.04665"
"25878","155.23400","12.93630","0.04709"
"25926","155.52200","12.96034","0.04704"
"25974","155.81000","12.98437","0.04711"
"26022","156.09800","13.00835","0.04735"
"26070","156.38600","13.03232","0.04751"
"26118","156.67400","13.05630","0.04745"
"26166","156.96200","13.08034","0.04714"
"26214","157.25000","13.10425","0.04753"
"26262","157.53800","13.12835","0.04812"
"26310","157.82600","13.15232","0.04851"
"26358","158.11400","13.17636","0.04880"
"26406","158.40200","13.20033","0.04859"
"26454","158.69000","13.22437","0.04805"
"26502","158.97800","13.24829","0.04870"
"26550","159.26600","13.27232","0.04852"
"26598","159.55400","13.29630","0.04822"
"26646","159.84200","13.32033","0.04910"
"26694","160.13000","13.34431","0.04842"
"26742","160.41800","13.36834","0.04875"
"26790","160.70600","13.39232","0.04839"
"26838","160.99400","13.41629","0.04888"
"26886","161.28200","13.44033","0.04933"
"26934","161.57000","13.46430","0.04937"
"26982","161.85800","13.48834","0.04902"
"27030","162.14600","13.51231","0.04918"
"27078","162.43400","13.53635","0.04913"
"27126","162.72200","13.56033","0.04937"
"27174","163.01000","13.58436","0.04918"
"27222","163.29800","13.60834","0.04943"
"27270","163.58600","13.63231","0.04953"
"27318","163.87400","13.65635","0.04954"
"27366","164.16200","13.68032","0.05026"
"27414","164.45000","13.70436","0.05035"
"27462","164.73800","13.72834","0.04999"
"27510","165.02600","13.75237","0.05010"
"27558","165.31400","13.77629","0.05004"
"27606","165.60200","13.80032","0.05003"
"27654","165.89000","13.82430","0.05020"
"27702","166.17800","13.84839","0.05055"
"27750","166.46600","13.87225","0.05059"
"27798","166.75400","13.89634","0.05047"
"27846","167.04200","13.92032","0.05074"
"27894","167.33000","13.94435","0.05083"
"27942","167.61800","13.96833","0.05068"
"27990","167.90600","13.99237","0.05093"
"28038","168.19400","14.01634","0.05111"
"28086","168.48200","14.04032","0.05137"
"28134","168.77000","14.06435","0.05103"
"28182","169.05800","14.08827","0.05170"
"28230","169.34600","14.11236","0.05181"
"28278","169.63400","14.13634","0.05194"
"28326","169.92200","14.16037","0.05193"
"28374","170.21000","14.18429","0.05136"
"28422","170.49800","14.20839","0.04886"
"28470","170.78600","14.23230","0.04846"
"28518","171.07400","14.25640","0.04992"
"28566","171.36200","14.28037","0.04945"
"28614","171.65000","14.30435","0.05021"
"28662","171.93800","14.32838","0.05040"
"28710","172.22600","14.35236","0.05024"
"28758","172.51400","14.37639","0.05056"
"28806","172.80200","14.40031","0.05086"
"28854","173.09000","14.42434","0.05041"
"28902","173.37800","14.44826","0.05052"
"28950","173.66600","14.47236","0.05100"
"28998","173.95400","14.49627","0.05093"
"29046","174.24200","14.52031","0.05141"
"29094","174.53000","14.54428","0.05094"
"29142","174.81800","14.56832","0.05151"
"29190","175.10600","14.59223","0.05104"
"29238","175.39400","14.61639","0.05153"
"29286","175.68200","14.64036","0.05186"
"29334","175.97000","14.66434","0.05183"
"29382","176.25800","14.68832","0.05211"
"29430","176.54600","14.71229","0.05203"
"29478","176.83400","14.73639","0.05217"
"29526","177.12200","14.76036","0.05176"
"29574","177.41000","14.78440","0.05260"
"29622","177.69800","14.80831","0.05227"
"29670","177.98600","14.83235","0.05270"
"29718","178.27400","14.85626","0.05273"
"29766","178.56200","14.88030","0.05301"
"29814","178.85000","14.90428","0.05295"
"29862","179.13800","14.92837","0.05213"
"29910","179.42600","14.95235","0.05335"
"29958","179.71400","14.97638","0.05335"
"30006","180.00200","15.00036","0.05295"
"30054","180.29000","15.02439","0.05363"
"30102","180.57800","15.04837","0.05327"
"30150","180.86600","15.07228","0.05299"
"30198","181.15400","15.09638","0.05359"
"30246","181.44200","15.12030","0.05347"
"30294","181.73000","15.14439","0.05346"
"30342","182.01800","15.16831","0.05332"
"30390","182.30600","15.19240","0.05365"
"30438","182.59400","15.21638","0.05369"
"30486","182.88200","15.24035","0.05376"
"30534","183.17000","15.26433","0.05387"
"30582","183.45800","15.28836","0.05405"
"30630","183.74600","15.31234","0.05364"
"30678","184.03400","15.33637","0.05333"
"30726","184.32200","15.36035","0.05246"
"30774","184.61000","15.38439","0.05313"
"30822","184.89800","15.40836","0.05317"
"30870","185.18600","15.43234","0.05348"
"30918","185.47400","15.45643","0.05329"
"30966","185.76200","15.48035","0.05289"
"31014","186.05000","15.50438","0.05305"
"31062","186.33800","15.52830","0.05280"
"31110","186.62600","15.55233","0.05282"
"31158","186.91400","15.57631","0.05275"
"31206","187.20200","15.60035","0.05317"
"31254","187.49000","15.62432","0.05345"
"31302","187.77800","15.64836","0.05292"
"31350","188.06600","15.67233","0.05347"
"31398","188.35400","15.69637","0.05225"
"31446","188.64200","15.72034","0.05325"
"31494","188.93000","15.74438","0.05319"
"31542","189.21800","15.76841","0.05333"
"31590","189.50600","15.79233","0.05276"
"31638","189.79400","15.81642","0.05334"
"31686","190.08200","15.84034","0.05310"
"31734","190.37000","15.86437","0.05324"
"31782","190.65800","15.88829","0.05281"
"31830","190.94600","15.91233","0.05297"
"31878","191.23400","15.93630","0.05357"
"31926","191.52200","15.96034","0.05353"
"31974","191.81000","15.98431","0.05306"
"32022","192.09800","16.00841","0.05325"
"32070","192.38600","16.03232","0.05363"
"32118","192.67400","16.05636","0.05362"
"32166","192.96200","16.08034","0.05337"
"32214","193.25000","16.10437","0.05358"
"32262","193.53800","16.12835","0.05392"
"32310","193.82600","16.15232","0.05364"
"32358","194.11400","16.17636","0.05365"
"32406","194.40200","16.20033","0.05386"
"32454","194.69000","16.22431","0.05372"
"32502","194.97800","16.24828","0.05358"
"32550","195.26600","16.27238","0.05393"
"32598","195.55400","16.29635","0.05409"
"32646","195.84200","16.32033","0.05343"
"32694","196.13000","16.34436","0.05396"
"32742","196.41800","16.36834","0.05387"
"32790","196.70600","16.39238","0.05365"
"32838","196.99400","16.41635","0.05368"
"32886","197.28200","16.44039","0.05334"
"32934","197.57000","16.46430","0.05414"
"32982","197.85800","16.48840","0.05352"
"33030","198.14600","16.51231","0.05341"
"33078","198.43400","16.53635","0.05368"
"33126","198.72200","16.56027","0.05278"
"33174","199.01000","16.58430","0.05302"
"33222","199.29800","16.60822","0.05340"
"33270","199.58600","16.63237","0.05374"
"33318","199.87400","16.65629","0.05359"
"33366","200.16200","16.68032","0.05381"
"33414","200.45000","16.70430","0.05388"
"33462","200.73800","16.72833","0.05323"
"33510","201.02600","16.75231","0.04445"
"33558","201.31400","16.77635","0.04124"
"33606","201.60200","16.80032","0.04276"
"33654","201.89000","16.82430","0.04120"
"33702","202.17800","16.84833","0.04130"
"33750","202.46600","16.87231","0.04186"
"33798","202.75400","16.89634","0.04180"
"33846","203.04200","16.92032","0.04250"
"33894","203.33000","16.94435","0.04194"
"33942","203.61800","16.96833","0.04282"
"33990","203.90600","16.99242","0.04218"
"34038","204.19400","17.01634","0.04267"
"34086","204.48200","17.04037","0.04257"
"34134","204.77000","17.06435","0.04316"
"34182","205.05800","17.08833","0.04333"
"34230","205.34600","17.11236","0.04344"
"34278","205.63400","17.13634","0.04368"
"34326","205.92200","17.16037","0.04470"
"34374","206.21000","17.18429","0.04436"
"34422","206.49800","17.20832","0.04466"
"34470","206.78600","17.23224","0.04459"
"34518","207.07400","17.25633","0.04497"
"34566","207.36200","17.28025","0.04489"
"34614","207.65000","17.30441","0.04397"
"34662","207.93800","17.32832","0.04401"
"34710","208.22600","17.35236","0.04384"
"34758","208.51400","17.37627","0.04413"
"34806","208.80200","17.40031","0.04461"
"34854","209.09000","17.42428","0.04498"
"34902","209.37800","17.44832","0.04504"
"34950","209.66600","17.47235","0.04488"
"34998","209.95400","17.49627","0.04525"
"35046","210.24200","17.52031","0.04566"
"35094","210.53000","17.54428","0.04529"
"35142","210.81800","17.56832","0.04629"
"35190","211.10600","17.59229","0.04624"
"35238","211.39400","17.61639","0.04590"
"35286","211.68200","17.64030","0.04605"
"35334","211.97000","17.66434","0.04638"
"35382","212.25800","17.68826","0.04635"
"35430","212.54600","17.71229","0.04587"
"35478","212.83400","17.73632","0.04600"
"35526","213.12200","17.76030","0.04600"
"35574","213.41000","17.78434","0.04661"
"35622","213.69800","17.80831","0.04709"
"35670","213.98600","17.83235","0.04769"
"35718","214.27400","17.85626","0.04744"
"35766","214.56200","17.88036","0.04790"
"35814","214.85000","17.90427","0.04761"
"35862","215.13800","17.92831","0.04814"
"35910","215.42600","17.95229","0.04819"
"35958","215.71400","17.97638","0.04825"
"36006","216.00200","18.00030","0.04859"
"36054","216.29000","18.02433","0.04867"
"36102","216.57800","18.04831","0.04981"
"36150","216.86600","18.07234","0.04981"
"36198","217.15400","18.09632","0.04983"
"36246","217.44200","18.12029","0.05041"
"36294","217.73000","18.14433","0.05029"
"36342","218.01800","18.16831","0.05082"
"36390","218.30600","18.19234","0.05143"
"36438","218.59400","18.21632","0.05133"
"36486","218.88200","18.24035","0.05130"
"36534","219.17000","18.26427","0.05241"
"36582","219.45800","18.28830","0.05189"
"36630","219.74600","18.31228","0.05233"
"36678","220.03400","18.33637","0.05296"
"36726","220.32200","18.36029","0.05257"
"36774","220.61000","18.38433","0.05178"
"36822","220.89800","18.40836","0.05194"
"36870","221.18600","18.43234","0.05216"
"36918","221.47400","18.45637","0.05273"
"36966","221.76200","18.48035","0.05294"
"37014","222.05000","18.50438","0.05259"
"37062","222.33800","18.52836","0.05324"
"37110","222.62600","18.55239","0.05277"
"37158","222.91400","18.57631","0.05310"
"37206","223.20200","18.60035","0.05351"
"37254","223.49000","18.62426","0.05402"
"37302","223.77800","18.64836","0.05443"
"37350","224.06600","18.67233","0.05398"
"37398","224.35400","18.69637","0.05453"
"37446","224.64200","18.72034","0.05505"
"37494","224.93000","18.74438","0.05525"
"37542","225.21800","18.76835","0.05553"
"37590","225.50600","18.79239","0.05573"
"37638","225.79400","18.81636","0.05552"
"37686","226.08200","18.84034","0.05596"
"37734","226.37000","18.86437","0.05608"
"37782","226.65800","18.88835","0.05580"
"37830","226.94600","18.91233","0.05648"
"37878","227.23400","18.93630","0.05653"
"37926","227.52200","18.96040","0.05671"
"37974","227.81000","18.98437","0.05730"
"38022","228.09800","19.00841","0.05708"
"38070","228.38600","19.03232","0.05738"
"38118","228.67400","19.05636","0.05718"
"38166","228.96200","19.08034","0.05721"
"38214","229.25000","19.10437","0.05764"
"38262","229.53800","19.12835","0.05767"
"38310","229.82600","19.15238","0.05790"
"38358","230.11400","19.17642","0.05759"
"38406","230.40200","19.20033","0.05817"
"38454","230.69000","19.22437","0.05797"
"38502","230.97800","19.24829","0.05825"
"38550","231.26600","19.27232","0.05815"
"38598","231.55400","19.29635","0.05794"
"38646","231.84200","19.32039","0.05781"
"38694","232.13000","19.34431","0.05783"
"38742","232.41800","19.36834","0.05792"
"38790","232.70600","19.39232","0.05805"
"38838","232.99400","19.41635","0.05828"
"38886","233.28200","19.44033","0.05800"
"38934","233.57000","19.46436","0.05773"
"38982","233.85800","19.48840","0.05782"
"39030","234.14600","19.51237","0.05769"
"39078","234.43400","19.53641","0.05801"
"39126","234.72200","19.56033","0.05838"
"39174","235.01000","19.58436","0.05745"
"39222","235.29800","19.60827","0.05750"
"39270","235.58600","19.63237","0.05772"
"39318","235.87400","19.65629","0.05778"
"39366","236.16200","19.68038","0.05541"
"39414","236.45000","19.70436","0.05302"
"39462","236.73800","19.72833","0.05273"
"39510","237.02600","19.75231","0.05254"
"39558","237.31400","19.77634","0.05252"
"39606","237.60200","19.80038","0.05267"
"39654","237.89000","19.82436","0.05296"
"39702","238.17800","19.84833","0.05323"
"39750","238.46600","19.87231","0.05336"
"39798","238.75400","19.89640","0.05383"
"39846","239.04200","19.92032","0.05401"
"39894","239.33000","19.94435","0.05399"
"39942","239.61800","19.96833","0.05420"
"39990","239.90600","19.99236","0.05421"
"40038","240.19400","20.01628","0.05407"
"40086","240.48200","20.04038","0.05381"
"40134","240.77000","20.06435","0.05440"
"40182","241.05800","20.08839","0.05463"
"40230","241.34600","20.11230","0.05484"
"40278","241.63400","20.13634","0.05498"
"40326","241.92200","20.16037","0.05463"
"40374","242.21000","20.18435","0.05441"
"40422","242.49800","20.20839","0.05459"
"40470","242.78600","20.23236","0.05544"
"40518","243.07400","20.25633","0.05495"
"40566","243.36200","20.28025","0.05490"
"40614","243.65000","20.30434","0.04933"
"40662","243.93800","20.32832","0.04778"
"40710","244.22600","20.35236","0.05029"
"40758","244.51400","20.37627","0.04923"
"40806","244.80200","20.40037","0.05047"
"40854","245.09000","20.42434","0.05047"
"40902","245.37800","20.44838","0.05132"
"40950","245.66600","20.47230","0.05160"
"40998","245.95400","20.49633","0.05154"
"41046","246.24200","20.52037","0.05200"
"41094","246.53000","20.54434","0.05190"
"41142","246.81800","20.56832","0.05239"
"41190","247.10600","20.59229","0.05187"
"41238","247.39400","20.61633","0.05182"
"41286","247.68200","20.64030","0.05181"
"41334","247.97000","20.66440","0.05227"
"41382","248.25800","20.68831","0.05104"
"41430","248.54600","20.71235","0.05153"
"41478","248.83400","20.73627","0.05162"
"41526","249.12200","20.76036","0.05183"
"41574","249.41000","20.78434","0.05197"
"41622","249.69800","20.80831","0.05221"
"41670","249.98600","20.83235","0.05218"
"41718","250.27400","20.85632","0.05159"
"41766","250.56200","20.88036","0.05229"
"41814","250.85000","20.90434","0.05272"
"41862","251.13800","20.92837","0.05213"
"41910","251.42600","20.95234","0.05229"
"41958","251.71400","20.97638","0.05194"
"42006","252.00200","21.00030","0.05243"
"42054","252.29000","21.02433","0.05240"
"42102","252.57800","21.04825","0.05032"
"42150","252.86600","21.07234","0.04990"
"42198","253.15400","21.09632","0.05001"
"42246","253.44200","21.12035","0.04916"
"42294","253.73000","21.14427","0.04773"
"42342","254.01800","21.16830","0.04817"
"42390","254.30600","21.19234","0.04851"
"42438","254.59400","21.21631","0.04827"
"42486","254.88200","21.24029","0.04895"
"42534","255.17000","21.26433","0.04950"
"42582","255.45800","21.28836","0.05001"
"42630","255.74600","21.31234","0.04997"
"42678","256.03400","21.33631","0.05062"
"42726","256.32200","21.36029","0.05030"
"42774","256.61000","21.38438","0.05046"
"42822","256.89800","21.40830","0.05087"
"42870","257.18600","21.43234","0.05033"
"42918","257.47400","21.45631","0.05019"
"42966","257.76200","21.48034","0.05003"
"43014","258.05000","21.50438","0.05058"
"43062","258.33800","21.52830","0.05051"
"43110","258.62600","21.55233","0.05117"
"43158","258.91400","21.57631","0.05158"
"43206","259.20200","21.60040","0.05117"
"43254","259.49000","21.62432","0.05185"
"43302","259.77800","21.64835","0.05229"
"43350","260.06600","21.67233","0.05153"
"43398","260.35400","21.69637","0.05240"
"43446","260.64200","21.72034","0.05236"
"43494","260.93000","21.74438","0.05254"
"43542","261.21800","21.76829","0.05333"
"43590","261.50600","21.79233","0.05272"
"43638","261.79400","21.81636","0.05329"
"43686","262.08200","21.84034","0.05379"
"43734","262.37000","21.86432","0.05362"
"43782","262.65800","21.88835","0.05305"
"43830","262.94600","21.91238","0.05361"
"43878","263.23400","21.93636","0.05336"
"43926","263.52200","21.96034","0.05338"
"43974","263.81000","21.98431","0.05323"
"44022","264.09800","22.00835","0.04819"
"44070","264.38600","22.03232","0.04937"
"44118","264.67400","22.05636","0.05000"
"44166","264.96200","22.08034","0.05052"
"44214","265.25000","22.10431","0.05056"
"44262","265.53800","22.12835","0.05100"
"44310","265.82600","22.15238","0.05161"
"44358","266.11400","22.17641","0.05142"
"44406","266.40200","22.20039","0.05207"
"44454","266.69000","22.22443","0.05156"
"44502","266.97800","22.24834","0.05184"
"44550","267.26600","22.27238","0.05203"
"44598","267.55400","22.29635","0.05263"
"44646","267.84200","22.32039","0.05246"
"44694","268.13000","22.34431","0.05278"
"44742","268.41800","22.36840","0.05321"
"44790","268.70600","22.39232","0.05302"
"44838","268.99400","22.41641","0.05298"
"44886","269.28200","22.44033","0.05353"
"44934","269.57000","22.46442","0.05326"
"44982","269.85800","22.48834","0.05380"
"45030","270.14600","22.51237","0.05390"
"45078","270.43400","22.53635","0.05400"
"45126","270.72200","22.56032","0.05384"
"45174","271.01000","22.58436","0.05373"
"45222","271.29800","22.60828","0.05432"
"45270","271.58600","22.63243","0.05408"
"45318","271.87400","22.65635","0.05444"
"45366","272.16200","22.68038","0.05452"
"45414","272.45000","22.70430","0.05459"
"45462","272.73800","22.72833","0.05449"
"45510","273.02600","22.75237","0.05432"
"45558","273.31400","22.77641","0.05453"
"45606","273.60200","22.80032","0.05441"
"45654","273.89000","22.82435","0.05486"
"45702","274.17800","22.84833","0.05472"
"45750","274.46600","22.87237","0.05474"
"45798","274.75400","22.89640","0.05499"
"45846","275.04200","22.92032","0.05500"
"45894","275.33000","22.94441","0.05502"
"45942","275.61800","22.96833","0.05519"
"45990","275.90600","22.99236","0.05559"
"46038","276.19400","23.01628","0.05499"
"46086","276.48200","23.04037","0.05540"
"46134","276.77000","23.06429","0.05575"
"46182","277.05800","23.08838","0.05562"
"46230","277.34600","23.11230","0.05552"
"46278","277.63400","23.13634","0.05589"
"46326","277.92200","23.16031","0.05587"
"46374","278.21000","23.18435","0.05560"
"46422","278.49800","23.20838","0.05633"
"46470","278.78600","23.23236","0.05625"
"46518","279.07400","23.25634","0.05580"
"46566","279.36200","23.28031","0.05543"
"46614","279.65000","23.30435","0.05561"
"46662","279.93800","23.32832","0.05538"
"46710","280.22600","23.35230","0.05561"
"46758","280.51400","23.37627","0.05567"
"46806","280.80200","23.40031","0.05550"
"46854","281.09000","23.42435","0.05551"
"46902","281.37800","23.44838","0.05539"
"46950","281.66600","23.47229","0.05552"
"46998","281.95400","23.49633","0.05581"
"47046","282.24200","23.52036","0.05588"
"47094","282.53000","23.54434","0.05622"
"47142","282.81800","23.56832","0.05635"
"47190","283.10600","23.59235","0.05620"
"47238","283.39400","23.61639","0.05605"
"47286","283.68200","23.64036","0.05608"
"47334","283.97000","23.66434","0.05633"
"47382","284.25800","23.68826","0.05637"
"47430","284.54600","23.71235","0.05648"
"47478","284.83400","23.73627","0.05619"
"47526","285.12200","23.76036","0.05661"
"47574","285.41000","23.78428","0.05649"
"47622","285.69800","23.80837","0.05664"
"47670","285.98600","23.83228","0.05661"
"47718","286.27400","23.85632","0.05673"
"47766","286.56200","23.88030","0.05685"
"47814","286.85000","23.90433","0.05699"
"47862","287.13800","23.92831","0.05704"
"47910","287.42600","23.95235","0.05667"
"47958","287.71400","23.97638","0.05709"
"48006","288.00200","24.00035","0.05658"
"48054","288.29000","24.02433","0.05635"
"48102","288.57800","24.04831","0.05666"
"48150","288.86600","24.07234","0.05662"
"48198","289.15400","24.09632","0.05713"
"48246","289.44200","24.12035","0.05691"
"48294","289.73000","24.14433","0.05721"
"48342","290.01800","24.16836","0.05727"
"48390","290.30600","24.19234","0.05699"
"48438","290.59400","24.21631","0.05723"
"48486","290.88200","24.24035","0.05707"
"48534","291.17000","24.26427","0.05733"
"48582","291.45800","24.28836","0.05722"
"48630","291.74600","24.31234","0.05706"
"48678","292.03400","24.33631","0.05704"
"48726","292.32200","24.36029","0.05727"
"48774","292.61000","24.38433","0.05742"
"48822","292.89800","24.40824","0.05752"
"48870","293.18600","24.43239","0.05778"
"48918","293.47400","24.45631","0.05771"
"48966","293.76200","24.48034","0.05804"
"49014","294.05000","24.50426","0.05642"
"49062","294.33800","24.52830","0.05669"
"49110","294.62600","24.55227","0.05693"
"49158","294.91400","24.57631","0.05736"
"49206","295.20200","24.60028","0.05732"
"49254","295.49000","24.62432","0.05707"
"49302","295.77800","24.64836","0.05704"
"49350","296.06600","24.67233","0.05706"
"49398","296.35400","24.69631","0.05709"
"49446","296.64200","24.72028","0.05598"
"49494","296.93000","24.74432","0.05565"
"49542","297.21800","24.76823","0.05582"
"49590","297.50600","24.79239","0.05605"
"49638","297.79400","24.81630","0.05623"
"49686","298.08200","24.84034","0.05666"
"49734","298.37000","24.86432","0.05661"
"49782","298.65800","24.88835","0.05680"
"49830","298.94600","24.91232","0.05710"
"49878","299.23400","24.93630","0.05745"
"49926","299.52200","24.96034","0.05708"
"49974","299.81000","24.98431","0.05705"
"50022","300.09800","25.00835","0.05673"
"50070","300.38600","25.03232","0.05715"
"50118","300.67400","25.05630","0.05727"
"50166","300.96200","25.08027","0.05690"
"50214","301.25000","25.10437","0.05715"
"50262","301.53800","25.12828","0.05725"
"50310","301.82600","25.15238","0.05773"
"50358","302.11400","25.17630","0.05750"
"50406","302.40200","25.20033","0.05759"
"50454","302.69000","25.22437","0.05777"
"50502","302.97800","25.24834","0.05791"
"50550","303.26600","25.27232","0.05779"
"50598","303.55400","25.29630","0.05796"
"50646","303.84200","25.32039","0.05829"
"50694","304.13000","25.34436","0.05790"
"50742","304.41800","25.36840","0.05800"
"50790","304.70600","25.39231","0.05834"
"50838","304.99400","25.41635","0.05841"
"50886","305.28200","25.44033","0.05820"
"50934","305.57000","25.46436","0.05818"
"50982","305.85800","25.48834","0.05757"
"51030","306.14600","25.51237","0.05816"
"51078","306.43400","25.53635","0.05789"
"51126","306.72200","25.56038","0.05793"
"51174","307.01000","25.58436","0.05720"
"51222","307.29800","25.60839","0.05735"
"51270","307.58600","25.63237","0.05801"
"51318","307.87400","25.65635","0.05774"
"51366","308.16200","25.68038","0.05742"
"51414","308.45000","25.70430","0.05766"
"51462","308.73800","25.72833","0.05764"
"51510","309.02600","25.75225","0.05749"
"51558","309.31400","25.77640","0.05793"
"51606","309.60200","25.80032","0.05753"
"51654","309.89000","25.82435","0.05763"
"51702","310.17800","25.84833","0.05766"
"51750","310.46600","25.87243","0.05753"
"51798","310.75400","25.89640","0.05774"
"51846","311.04200","25.92038","0.05780"
"51894","311.33000","25.94435","0.05776"
"51942","311.61800","25.96839","0.05809"
"51990","311.90600","25.99236","0.05772"
"52038","312.19400","26.01634","0.05795"
"52086","312.48200","26.04037","0.05757"
"52134","312.77000","26.06435","0.05723"
"52182","313.05800","26.08838","0.05764"
"52230","313.34600","26.11236","0.05617"
"52278","313.63400","26.13640","0.05668"
"52326","313.92200","26.16031","0.05688"
"52374","314.21000","26.18435","0.05635"
"52422","314.49800","26.20832","0.05602"
"52470","314.78600","26.23242","0.05460"
"52518","315.07400","26.25633","0.05461"
"52566","315.36200","26.28037","0.05495"
"52614","315.65000","26.30441","0.05548"
"52662","315.93800","26.32838","0.05497"
"52710","316.22600","26.35242","0.05518"
"52758","316.51400","26.37627","0.05527"
"52806","316.80200","26.40037","0.05515"
"52854","317.09000","26.42434","0.05529"
"52902","317.37800","26.44832","0.05597"
"52950","317.66600","26.47229","0.05548"
"52998","317.95400","26.49639","0.05535"
"53046","318.24200","26.52030","0.05613"
"53094","318.53000","26.54434","0.05587"
"53142","318.81800","26.56832","0.05577"
"53190","319.10600","26.59235","0.05588"
"53238","319.39400","26.61633","0.05588"
"53286","319.68200","26.64036","0.05577"
"53334","319.97000","26.66440","0.05623"
"53382","320.25800","26.68831","0.05570"
"53430","320.54600","26.71235","0.05603"
"53478","320.83400","26.73632","0.05618"
"53526","321.12200","26.76036","0.05622"
"53574","321.41000","26.78428","0.05625"
"53622","321.69800","26.80837","0.05487"
"53670","321.98600","26.83235","0.05420"
"53718","322.27400","26.85638","0.05345"
"53766","322.56200","26.88030","0.05338"
"53814","322.85000","26.90434","0.05379"
"53862","323.13800","26.92837","0.05373"
"53910","323.42600","26.95234","0.05447"
"53958","323.71400","26.97632","0.05478"
"54006","324.00200","27.00035","0.05524"
"54054","324.29000","27.02439","0.05539"
"54102","324.57800","27.04831","0.05565"
"54150","324.86600","27.07234","0.05584"
"54198","325.15400","27.09632","0.05581"
"54246","325.44200","27.12035","0.05500"
"54294","325.73000","27.14433","0.05561"
"54342","326.01800","27.16837","0.05605"
"54390","326.30600","27.19228","0.05593"
"54438","326.59400","27.21638","0.05637"
"54486","326.88200","27.24029","0.05656"
"54534","327.17000","27.26433","0.05647"
"54582","327.45800","27.28836","0.05672"
"54630","327.74600","27.31234","0.05704"
"54678","328.03400","27.33637","0.05694"
"54726","328.32200","27.36029","0.05690"
"54774","328.61000","27.38439","0.05750"
"54822","328.89800","27.40836","0.05747"
"54870","329.18600","27.43240","0.05744"
"54918","329.47400","27.45631","0.05745"
"54966","329.76200","27.48035","0.05779"
"55014","330.05000","27.50426","0.05767"
"55062","330.33800","27.52836","0.05725"
"55110","330.62600","27.55227","0.05732"
"55158","330.91400","27.57631","0.05750"
"55206","331.20200","27.60034","0.05738"
"55254","331.49000","27.62432","0.05750"
"55302","331.77800","27.64836","0.05747"
"55350","332.06600","27.67233","0.05751"
"55398","332.35400","27.69637","0.05756"
"55446","332.64200","27.72034","0.05742"
"55494","332.93000","27.74432","0.05716"
"55542","333.21800","27.76829","0.05767"
"55590","333.50600","27.79233","0.05739"
"55638","333.79400","27.81624","0.05714"
"55686","334.08200","27.84034","0.05749"
"55734","334.37000","27.86432","0.05772"
"55782","334.65800","27.88835","0.05780"
"55830","334.94600","27.91232","0.05767"
"55878","335.23400","27.93636","0.05786"
"55926","335.52200","27.96034","0.05757"
"55974","335.81000","27.98431","0.05815"
"56022","336.09800","28.00835","0.05789"
"56070","336.38600","28.03232","0.05795"
"56118","336.67400","28.05636","0.05797"
"56166","336.96200","28.08034","0.05777"
"56214","337.25000","28.10437","0.05809"
"56262","337.53800","28.12829","0.05783"
"56310","337.82600","28.15238","0.05834"
"56358","338.11400","28.17630","0.05826"
"56406","338.40200","28.20039","0.05805"
"56454","338.69000","28.22431","0.05771"
"56502","338.97800","28.24834","0.05815"
"56550","339.26600","28.27232","0.05778"
"56598","339.55400","28.29635","0.05794"
"56646","339.84200","28.32033","0.05803"
"56694","340.13000","28.34430","0.05856"
"56742","340.41800","28.36834","0.05832"
"56790","340.70600","28.39232","0.05845"
"56838","340.99400","28.41635","0.05844"
"56886","341.28200","28.44033","0.05847"
"56934","341.57000","28.46436","0.05835"
"56982","341.85800","28.48828","0.05850"
"57030","342.14600","28.51231","0.05850"
"57078","342.43400","28.53629","0.05855"
"57126","342.72200","28.56038","0.05879"
"57174","343.01000","28.58436","0.05841"
"57222","343.29800","28.60839","0.05803"
"57270","343.58600","28.63237","0.05807"
"57318","343.87400","28.65635","0.05797"
"57366","344.16200","28.68032","0.05806"
"57414","344.45000","28.70430","0.05809"
"57462","344.73800","28.72833","0.05818"
"57510","345.02600","28.75231","0.05822"
"57558","345.31400","28.77641","0.05777"
"57606","345.60200","28.80032","0.05824"
"57654","345.89000","28.82436","0.05827"
"57702","346.17800","28.84833","0.05818"
"57750","346.46600","28.87237","0.05794"
"57798","346.75400","28.89634","0.05813"
"57846","347.04200","28.92038","0.05776"
"57894","347.33000","28.94435","0.05751"
"57942","347.61800","28.96839","0.05790"
"57990","347.90600","28.99236","0.04829"
"58038","348.19400","29.01634","0.04774"
"58086","348.48200","29.04031","0.04813"
"58134","348.77000","29.06435","0.04856"
"58182","349.05800","29.08839","0.04816"
"58230","349.34600","29.11236","0.04891"
"58278","349.63400","29.13640","0.04788"
"58326","349.92200","29.16031","0.04892"
"58374","350.21000","29.18435","0.04815"
"58422","350.49800","29.20832","0.04907"
"58470","350.78600","29.23236","0.04931"
"58518","351.07400","29.25633","0.04903"
"58566","351.36200","29.28037","0.04910"
"58614","351.65000","29.30434","0.04927"
"58662","351.93800","29.32838","0.04951"
"58710","352.22600","29.35236","0.04971"
"58758","352.51400","29.37633","0.04918"
"58787","352.68400","29.39050","0.04940"