File: Trajectories_together/170107_2Specimen_RawData_8.csv
"","V1","V2","V3"
"1","End date","1/7/2017",""
"2","Specimen label","20CG_58",""
"3","Maximum Load","0.70788","N"
"4","Time","Extension","Load"
"5","(s)","(mm)","(N)"
"6","0.00000","0.00000","-0.00020"
"72","0.39600","0.03318","0.00051"
"138","0.79200","0.06625","0.00188"
"204","1.18800","0.09925","0.00218"
"270","1.58400","0.13219","0.00199"
"336","1.98000","0.16520","0.00244"
"402","2.37600","0.19820","0.00252"
"468","2.77200","0.23127","0.00306"
"534","3.16800","0.26421","0.00354"
"600","3.56400","0.29721","0.00374"
"666","3.96000","0.33022","0.00378"
"732","4.35600","0.36322","0.00394"
"798","4.75200","0.39623","0.00448"
"864","5.14800","0.42923","0.00465"
"930","5.54400","0.46223","0.00413"
"996","5.94000","0.49530","0.00471"
"1062","6.33600","0.52818","0.00470"
"1128","6.73200","0.56124","0.00488"
"1194","7.12800","0.59425","0.00561"
"1260","7.52400","0.62719","0.00516"
"1326","7.92000","0.66014","0.00509"
"1392","8.31600","0.69326","0.00523"
"1458","8.71200","0.72620","0.00540"
"1524","9.10800","0.75921","0.00493"
"1590","9.50400","0.79215","0.00527"
"1656","9.90000","0.82522","0.00546"
"1722","10.29600","0.85822","0.00517"
"1788","10.69200","0.89122","0.00602"
"1854","11.08800","0.92417","0.00527"
"1920","11.48400","0.95723","0.00540"
"1986","11.88000","0.99029","0.00515"
"2052","12.27600","1.02318","0.00531"
"2118","12.67200","1.05618","0.00546"
"2184","13.06800","1.08925","0.00615"
"2250","13.46400","1.12225","0.00616"
"2316","13.86000","1.15519","0.00564"
"2382","14.25600","1.18826","0.00604"
"2448","14.65200","1.22120","0.00624"
"2514","15.04800","1.25426","0.00620"
"2580","15.44400","1.28721","0.00726"
"2646","15.84000","1.32021","0.00660"
"2712","16.23600","1.35328","0.00740"
"2778","16.63200","1.38622","0.00648"
"2844","17.02800","1.41922","0.00682"
"2910","17.42400","1.45223","0.00756"
"2976","17.82000","1.48523","0.00705"
"3042","18.21600","1.51824","0.00666"
"3108","18.61200","1.55124","0.00680"
"3174","19.00800","1.58424","0.00744"
"3240","19.40400","1.61725","0.00691"
"3306","19.80000","1.65019","0.00720"
"3372","20.19600","1.68319","0.00745"
"3438","20.59200","1.71620","0.00729"
"3504","20.98800","1.74920","0.00733"
"3570","21.38400","1.78221","0.00729"
"3636","21.78000","1.81521","0.00684"
"3702","22.17600","1.84821","0.00757"
"3768","22.57200","1.88122","0.00635"
"3834","22.96800","1.91422","0.00625"
"3900","23.36400","1.94723","0.00681"
"3966","23.76000","1.98023","0.00651"
"4032","24.15600","2.01323","0.00681"
"4098","24.55200","2.04618","0.00679"
"4164","24.94800","2.07924","0.00689"
"4230","25.34400","2.11224","0.00707"
"4296","25.74000","2.14519","0.00668"
"4362","26.13600","2.17819","0.00729"
"4428","26.53200","2.21132","0.00680"
"4494","26.92800","2.24426","0.00728"
"4560","27.32400","2.27720","0.00740"
"4626","27.72000","2.31021","0.00748"
"4692","28.11600","2.34327","0.00802"
"4758","28.51200","2.37628","0.00770"
"4824","28.90800","2.40916","0.00778"
"4890","29.30400","2.44222","0.00815"
"4956","29.70000","2.47523","0.00827"
"5022","30.09600","2.50823","0.00834"
"5088","30.49200","2.54117","0.00840"
"5154","30.88800","2.57424","0.00834"
"5220","31.28400","2.60724","0.00762"
"5286","31.68000","2.64025","0.00790"
"5352","32.07600","2.67319","0.00887"
"5418","32.47200","2.70625","0.00793"
"5484","32.86800","2.73926","0.00766"
"5550","33.26400","2.77220","0.00822"
"5616","33.66000","2.80521","0.00900"
"5682","34.05600","2.83827","0.00875"
"5748","34.45200","2.87121","0.00888"
"5814","34.84800","2.90416","0.00855"
"5880","35.24400","2.93722","0.00873"
"5946","35.64000","2.97022","0.00885"
"6012","36.03600","3.00323","0.00791"
"6078","36.43200","3.03623","0.00774"
"6144","36.82800","3.06924","0.00748"
"6210","37.22400","3.10218","0.00759"
"6276","37.62000","3.13518","0.00764"
"6342","38.01600","3.16825","0.00788"
"6408","38.41200","3.20125","0.00826"
"6474","38.80800","3.23426","0.00837"
"6540","39.20400","3.26720","0.00871"
"6606","39.60000","3.30020","0.00916"
"6672","39.99600","3.33321","0.00879"
"6738","40.39200","3.36627","0.00921"
"6804","40.78800","3.39915","0.00931"
"6870","41.18400","3.43228","0.00906"
"6936","41.58000","3.46528","0.00929"
"7002","41.97600","3.49823","0.00881"
"7068","42.37200","3.53123","0.00918"
"7134","42.76800","3.56423","0.00790"
"7200","43.16400","3.59730","0.00923"
"7266","43.56000","3.63024","0.00892"
"7332","43.95600","3.66319","0.00894"
"7398","44.35200","3.69625","0.00915"
"7464","44.74800","3.72925","0.00908"
"7530","45.14400","3.76220","0.00922"
"7596","45.54000","3.79520","0.00954"
"7662","45.93600","3.82826","0.00906"
"7728","46.33200","3.86127","0.00924"
"7794","46.72800","3.89421","0.00965"
"7860","47.12400","3.92722","0.00958"
"7926","47.52000","3.96028","0.00970"
"7992","47.91600","3.99328","0.00970"
"8058","48.31200","4.02617","0.00923"
"8124","48.70800","4.05923","0.00968"
"8190","49.10400","4.09223","0.00978"
"8256","49.50000","4.12530","0.00996"
"8322","49.89600","4.15818","0.01040"
"8388","50.29200","4.19125","0.00992"
"8454","50.68800","4.22425","0.01019"
"8520","51.08400","4.25725","0.01028"
"8586","51.48000","4.29020","0.01064"
"8652","51.87600","4.32326","0.01025"
"8718","52.27200","4.35621","0.01078"
"8784","52.66800","4.38921","0.01121"
"8850","53.06400","4.42221","0.01090"
"8916","53.46000","4.45522","0.01105"
"8982","53.85600","4.48828","0.01122"
"9048","54.25200","4.52122","0.01173"
"9114","54.64800","4.55423","0.01154"
"9180","55.04400","4.58723","0.01123"
"9246","55.44000","4.62024","0.01197"
"9312","55.83600","4.65318","0.01236"
"9378","56.23200","4.68630","0.01230"
"9444","56.62800","4.71925","0.01211"
"9510","57.02400","4.75225","0.01234"
"9576","57.42000","4.78514","0.01276"
"9642","57.81600","4.81820","0.01267"
"9708","58.21200","4.85126","0.01296"
"9774","58.60800","4.88415","0.01259"
"9840","59.00400","4.91715","0.01308"
"9906","59.40000","4.95027","0.01322"
"9972","59.79600","4.98328","0.01327"
"10038","60.19200","5.01616","0.01353"
"10104","60.58800","5.04923","0.01345"
"10170","60.98400","5.08229","0.01346"
"10236","61.38000","5.11523","0.01375"
"10302","61.77600","5.14818","0.01367"
"10368","62.17200","5.18124","0.01354"
"10434","62.56800","5.21430","0.01370"
"10500","62.96400","5.24725","0.01429"
"10566","63.36000","5.28019","0.01404"
"10632","63.75600","5.31320","0.01379"
"10698","64.15200","5.34626","0.01427"
"10764","64.54800","5.37926","0.01411"
"10830","64.94400","5.41215","0.01456"
"10896","65.34000","5.44521","0.01469"
"10962","65.73600","5.47822","0.01488"
"11028","66.13200","5.51122","0.01536"
"11094","66.52800","5.54416","0.01489"
"11160","66.92400","5.57723","0.01510"
"11226","67.32000","5.61023","0.01543"
"11292","67.71600","5.64324","0.01578"
"11358","68.11200","5.67618","0.01599"
"11424","68.50800","5.70924","0.01620"
"11490","68.90400","5.74225","0.01517"
"11556","69.30000","5.77519","0.01550"
"11622","69.69600","5.80825","0.01532"
"11688","70.09200","5.84120","0.01563"
"11754","70.48800","5.87420","0.01585"
"11820","70.88400","5.90715","0.01645"
"11886","71.28000","5.94021","0.01615"
"11952","71.67600","5.97321","0.01604"
"12018","72.07200","6.00622","0.01657"
"12084","72.46800","6.03922","0.01677"
"12150","72.86400","6.07228","0.01753"
"12216","73.26000","6.10517","0.01751"
"12282","73.65600","6.13817","0.01767"
"12348","74.05200","6.17124","0.01768"
"12414","74.44800","6.20424","0.01738"
"12480","74.84400","6.23724","0.01774"
"12546","75.24000","6.27013","0.01838"
"12612","75.63600","6.30325","0.01781"
"12678","76.03200","6.33626","0.01875"
"12744","76.42800","6.36920","0.01902"
"12810","76.82400","6.40214","0.01975"
"12876","77.22000","6.43521","0.01941"
"12942","77.61600","6.46827","0.01991"
"13008","78.01200","6.50121","0.02027"
"13074","78.40800","6.53416","0.02060"
"13140","78.80400","6.56728","0.02026"
"13206","79.20000","6.60029","0.01988"
"13272","79.59600","6.63323","0.02039"
"13338","79.99200","6.66617","0.02001"
"13404","80.38800","6.69918","0.02053"
"13470","80.78400","6.73230","0.01911"
"13536","81.18000","6.76519","0.02028"
"13602","81.57600","6.79819","0.02056"
"13668","81.97200","6.83125","0.02029"
"13734","82.36800","6.86426","0.02077"
"13800","82.76400","6.89720","0.02035"
"13866","83.16000","6.93020","0.02154"
"13932","83.55600","6.96327","0.02066"
"13998","83.95200","6.99627","0.02122"
"14064","84.34800","7.02922","0.02090"
"14130","84.74400","7.06222","0.02166"
"14196","85.14000","7.09522","0.02184"
"14262","85.53600","7.12817","0.02229"
"14328","85.93200","7.16117","0.02050"
"14394","86.32800","7.19424","0.02151"
"14460","86.72400","7.22718","0.02176"
"14526","87.12000","7.26024","0.02159"
"14592","87.51600","7.29319","0.02213"
"14658","87.91200","7.32619","0.02208"
"14724","88.30800","7.35919","0.02306"
"14790","88.70400","7.39220","0.02281"
"14856","89.10000","7.42520","0.02311"
"14922","89.49600","7.45827","0.02371"
"14988","89.89200","7.49121","0.02378"
"15054","90.28800","7.52421","0.02469"
"15120","90.68400","7.55722","0.02517"
"15186","91.08000","7.59022","0.02524"
"15252","91.47600","7.62329","0.02633"
"15318","91.87200","7.65617","0.02638"
"15384","92.26800","7.68929","0.02648"
"15450","92.66400","7.72224","0.02662"
"15516","93.06000","7.75518","0.02453"
"15582","93.45600","7.78819","0.02354"
"15648","93.85200","7.82125","0.02426"
"15714","94.24800","7.85425","0.02456"
"15780","94.64400","7.88720","0.02545"
"15846","95.04000","7.92026","0.02539"
"15912","95.43600","7.95326","0.02669"
"15978","95.83200","7.98627","0.02704"
"16044","96.22800","8.01915","0.02783"
"16110","96.62400","8.05221","0.02746"
"16176","97.02000","8.08528","0.02855"
"16242","97.41600","8.11828","0.02811"
"16308","97.81200","8.15117","0.02867"
"16374","98.20800","8.18417","0.02822"
"16440","98.60400","8.21723","0.02796"
"16506","99.00000","8.25024","0.02864"
"16572","99.39600","8.28318","0.02948"
"16638","99.79200","8.31625","0.03016"
"16704","100.18800","8.34925","0.02791"
"16770","100.58400","8.38225","0.02830"
"16836","100.98000","8.41520","0.02928"
"16902","101.37600","8.44820","0.03018"
"16968","101.77200","8.48120","0.03082"
"17034","102.16800","8.51421","0.03156"
"17100","102.56400","8.54721","0.03169"
"17166","102.96000","8.58028","0.03225"
"17232","103.35600","8.61328","0.03320"
"17298","103.75200","8.64622","0.03335"
"17364","104.14800","8.67923","0.03375"
"17430","104.54400","8.71223","0.03423"
"17496","104.94000","8.74524","0.03492"
"17562","105.33600","8.77818","0.03598"
"17628","105.73200","8.81124","0.03598"
"17694","106.12800","8.84419","0.03654"
"17760","106.52400","8.87719","0.03713"
"17826","106.92000","8.91020","0.03816"
"17892","107.31600","8.94320","0.03838"
"17958","107.71200","8.97620","0.03957"
"18024","108.10800","9.00921","0.04004"
"18090","108.50400","9.04215","0.04036"
"18156","108.90000","9.07527","0.04129"
"18222","109.29600","9.10828","0.04152"
"18288","109.69200","9.14116","0.04356"
"18354","110.08800","9.17423","0.04302"
"18420","110.48400","9.20729","0.04379"
"18486","110.88000","9.24023","0.04440"
"18552","111.27600","9.27318","0.04567"
"18618","111.67200","9.30618","0.04619"
"18684","112.06800","9.33924","0.04704"
"18750","112.46400","9.37225","0.04772"
"18816","112.86000","9.40513","0.04830"
"18882","113.25600","9.43820","0.04928"
"18948","113.65200","9.47120","0.05081"
"19014","114.04800","9.50420","0.05189"
"19080","114.44400","9.53721","0.05040"
"19146","114.84000","9.57021","0.05189"
"19212","115.23600","9.60322","0.05238"
"19278","115.63200","9.63628","0.05380"
"19344","116.02800","9.66922","0.05449"
"19410","116.42400","9.70223","0.05529"
"19476","116.82000","9.73529","0.05552"
"19542","117.21600","9.76823","0.05703"
"19608","117.61200","9.80118","0.05797"
"19674","118.00800","9.83424","0.05835"
"19740","118.40400","9.86731","0.05925"
"19806","118.80000","9.90019","0.06019"
"19872","119.19600","9.93319","0.06077"
"19938","119.59200","9.96626","0.06045"
"20004","119.98800","9.99920","0.06172"
"20070","120.38400","10.03221","0.06236"
"20136","120.78000","10.06521","0.06312"
"20202","121.17600","10.09815","0.06339"
"20268","121.57200","10.13122","0.06419"
"20334","121.96800","10.16422","0.06472"
"20400","122.36400","10.19722","0.06528"
"20466","122.76000","10.23023","0.06510"
"20532","123.15600","10.26317","0.06584"
"20598","123.55200","10.29618","0.06645"
"20664","123.94800","10.32924","0.06760"
"20730","124.34400","10.36218","0.06801"
"20796","124.74000","10.39519","0.06895"
"20862","125.13600","10.42825","0.06900"
"20928","125.53200","10.46125","0.07022"
"20994","125.92800","10.49426","0.07131"
"21060","126.32400","10.52714","0.07177"
"21126","126.72000","10.56027","0.07310"
"21192","127.11600","10.59327","0.07408"
"21258","127.51200","10.62621","0.07497"
"21324","127.90800","10.65922","0.07582"
"21390","128.30400","10.69222","0.07623"
"21456","128.70000","10.72529","0.07818"
"21522","129.09599","10.75817","0.07863"
"21588","129.49200","10.79111","0.08033"
"21654","129.88800","10.82424","0.08251"
"21720","130.28400","10.85730","0.08387"
"21786","130.67999","10.89019","0.08550"
"21852","131.07600","10.92319","0.08787"
"21918","131.47200","10.95625","0.08991"
"21984","131.86800","10.98926","0.09258"
"22050","132.26401","11.02220","0.09600"
"22116","132.66000","11.05520","0.09628"
"22182","133.05600","11.08821","0.09841"
"22248","133.45200","11.12127","0.10194"
"22314","133.84801","11.15416","0.10471"
"22380","134.24400","11.18716","0.10686"
"22446","134.64000","11.22022","0.10844"
"22512","135.03600","11.25323","0.11073"
"22578","135.43201","11.28617","0.11211"
"22644","135.82800","11.31923","0.11441"
"22710","136.22400","11.35230","0.11589"
"22776","136.62000","11.38518","0.11743"
"22842","137.01601","11.41819","0.11922"
"22908","137.41200","11.45125","0.12076"
"22974","137.80800","11.48425","0.12134"
"23040","138.20399","11.51720","0.11933"
"23106","138.60001","11.55020","0.07897"
"23172","138.99600","11.58327","0.08436"
"23238","139.39200","11.61621","0.08895"
"23304","139.78799","11.64915","0.09447"
"23370","140.18401","11.68228","0.10199"
"23436","140.58000","11.71522","0.10819"
"23502","140.97600","11.74822","0.11253"
"23568","141.37199","11.78117","0.11621"
"23634","141.76801","11.81429","0.12052"
"23700","142.16400","11.84724","0.12403"
"23766","142.56000","11.88024","0.12760"
"23832","142.95599","11.91318","0.12987"
"23898","143.35201","11.94625","0.13305"
"23964","143.74800","11.97925","0.13460"
"24030","144.14400","12.01214","0.13680"
"24096","144.53999","12.04520","0.13816"
"24162","144.93600","12.07826","0.14095"
"24228","145.33200","12.11127","0.14262"
"24294","145.72800","12.14415","0.14483"
"24360","146.12399","12.17721","0.14683"
"24426","146.52000","12.21028","0.14943"
"24492","146.91600","12.24322","0.15180"
"24558","147.31200","12.27617","0.15400"
"24624","147.70799","12.30923","0.15599"
"24690","148.10400","12.34223","0.15783"
"24756","148.50000","12.37524","0.15958"
"24822","148.89600","12.40818","0.16225"
"24888","149.29201","12.44118","0.16388"
"24954","149.68800","12.47425","0.16623"
"25020","150.08400","12.50725","0.16802"
"25086","150.48000","12.54020","0.16937"
"25152","150.87601","12.57326","0.17092"
"25218","151.27200","12.60627","0.17257"
"25284","151.66800","12.63927","0.17315"
"25350","152.06400","12.67221","0.17413"
"25416","152.46001","12.70522","0.17539"
"25482","152.85600","12.73828","0.17671"
"25548","153.25200","12.77122","0.17791"
"25614","153.64799","12.80423","0.17970"
"25680","154.04401","12.83723","0.18083"
"25746","154.44000","12.87024","0.18268"
"25812","154.83600","12.90318","0.18428"
"25878","155.23199","12.93624","0.18639"
"25944","155.62801","12.96919","0.18807"
"26010","156.02400","13.00225","0.19001"
"26076","156.42000","13.03520","0.19207"
"26142","156.81599","13.06820","0.19360"
"26208","157.21201","13.10120","0.19530"
"26274","157.60800","13.13421","0.19845"
"26340","158.00400","13.16721","0.20044"
"26406","158.39999","13.20027","0.20349"
"26472","158.79601","13.23322","0.20618"
"26538","159.19200","13.26616","0.20845"
"26604","159.58800","13.29923","0.21110"
"26670","159.98399","13.33223","0.21268"
"26736","160.38000","13.36523","0.21404"
"26802","160.77600","13.39818","0.21629"
"26868","161.17200","13.43118","0.21875"
"26934","161.56799","13.46430","0.22141"
"27000","161.96400","13.49725","0.22418"
"27066","162.36000","13.53013","0.22699"
"27132","162.75600","13.56320","0.22882"
"27198","163.15199","13.59632","0.23236"
"27264","163.54800","13.62920","0.23447"
"27330","163.94400","13.66221","0.23778"
"27396","164.34000","13.69521","0.23926"
"27462","164.73599","13.72827","0.24305"
"27528","165.13200","13.76122","0.24585"
"27594","165.52800","13.79416","0.24842"
"27660","165.92400","13.82723","0.25165"
"27726","166.32001","13.86023","0.25433"
"27792","166.71600","13.89323","0.25653"
"27858","167.11200","13.92618","0.26032"
"27924","167.50800","13.95924","0.26317"
"27990","167.90401","13.99225","0.26611"
"28056","168.30000","14.02519","0.26765"
"28122","168.69600","14.05819","0.26938"
"28188","169.09200","14.09126","0.27219"
"28254","169.48801","14.12426","0.27444"
"28320","169.88400","14.15721","0.27615"
"28386","170.28000","14.19021","0.27810"
"28452","170.67599","14.22321","0.27909"
"28518","171.07201","14.25622","0.28036"
"28584","171.46800","14.28916","0.28142"
"28650","171.86400","14.32228","0.28228"
"28716","172.25999","14.35523","0.28292"
"28782","172.65601","14.38817","0.28373"
"28848","173.05200","14.42124","0.28473"
"28914","173.44800","14.45424","0.28604"
"28980","173.84399","14.48724","0.28703"
"29046","174.24001","14.52019","0.28764"
"29112","174.63600","14.55325","0.28887"
"29178","175.03200","14.58625","0.28956"
"29244","175.42799","14.61920","0.29132"
"29310","175.82401","14.65220","0.29250"
"29376","176.22000","14.68527","0.29493"
"29442","176.61600","14.71827","0.29681"
"29508","177.01199","14.75127","0.29963"
"29574","177.40800","14.78416","0.30189"
"29640","177.80400","14.81728","0.30506"
"29706","178.20000","14.85028","0.30722"
"29772","178.59599","14.88317","0.31028"
"29838","178.99200","14.91623","0.31340"
"29904","179.38800","14.94924","0.31584"
"29970","179.78400","14.98224","0.31846"
"30036","180.17999","15.01518","0.32147"
"30102","180.57600","15.04819","0.32440"
"30168","180.97200","15.08125","0.32789"
"30234","181.36800","15.11426","0.33139"
"30300","181.76401","15.14714","0.33479"
"30366","182.16000","15.18020","0.33801"
"30432","182.55600","15.21321","0.34133"
"30498","182.95200","15.24621","0.34350"
"30564","183.34801","15.27921","0.34558"
"30630","183.74400","15.31216","0.34756"
"30696","184.14000","15.34522","0.35035"
"30762","184.53600","15.37823","0.35362"
"30828","184.93201","15.41117","0.35586"
"30894","185.32800","15.44423","0.35868"
"30960","185.72400","15.47724","0.36065"
"31026","186.12000","15.51024","0.36306"
"31092","186.51601","15.54319","0.36420"
"31158","186.91200","15.57625","0.36563"
"31224","187.30800","15.60931","0.36755"
"31290","187.70399","15.64220","0.36941"
"31356","188.10001","15.67520","0.37112"
"31422","188.49600","15.70826","0.37325"
"31488","188.89200","15.74127","0.37486"
"31554","189.28799","15.77421","0.37646"
"31620","189.68401","15.80728","0.37803"
"31686","190.08000","15.84022","0.37982"
"31752","190.47600","15.87322","0.38151"
"31818","190.87199","15.90617","0.38371"
"31884","191.26801","15.93923","0.38600"
"31950","191.66400","15.97224","0.38787"
"32016","192.06000","16.00524","0.39116"
"32082","192.45599","16.03818","0.39224"
"32148","192.85201","16.07119","0.39583"
"32214","193.24800","16.10425","0.39867"
"32280","193.64400","16.13719","0.40206"
"32346","194.03999","16.17020","0.40494"
"32412","194.43600","16.20320","0.40762"
"32478","194.83200","16.23621","0.41056"
"32544","195.22800","16.26915","0.41405"
"32610","195.62399","16.30221","0.41610"
"32676","196.02000","16.33522","0.41845"
"32742","196.41600","16.36816","0.42071"
"32808","196.81200","16.40117","0.42239"
"32874","197.20799","16.43423","0.42413"
"32940","197.60400","16.46729","0.42648"
"33006","198.00000","16.50024","0.42849"
"33072","198.39600","16.53318","0.43154"
"33138","198.79201","16.56618","0.43411"
"33204","199.18800","16.59925","0.43684"
"33270","199.58400","16.63219","0.44038"
"33336","199.98000","16.66520","0.44424"
"33402","200.37601","16.69826","0.44728"
"33468","200.77200","16.73126","0.44989"
"33534","201.16800","16.76421","0.45461"
"33600","201.56400","16.79715","0.45905"
"33666","201.96001","16.83027","0.46299"
"33732","202.35600","16.86322","0.46823"
"33798","202.75200","16.89622","0.47371"
"33864","203.14799","16.92917","0.47787"
"33930","203.54401","16.96223","0.48131"
"33996","203.94000","16.99523","0.48384"
"34062","204.33600","17.02818","0.48628"
"34128","204.73199","17.06124","0.48844"
"34194","205.12801","17.09425","0.49066"
"34260","205.52400","17.12719","0.49328"
"34326","205.92000","17.16019","0.49500"
"34392","206.31599","17.19326","0.49841"
"34458","206.71201","17.22620","0.50080"
"34524","207.10800","17.25920","0.50172"
"34590","207.50400","17.29215","0.50505"
"34656","207.89999","17.32521","0.50899"
"34722","208.29601","17.35822","0.51338"
"34788","208.69200","17.39122","0.51786"
"34854","209.08800","17.42416","0.52209"
"34920","209.48399","17.45723","0.52639"
"34986","209.88000","17.49023","0.53130"
"35052","210.27600","17.52317","0.53683"
"35118","210.67200","17.55624","0.54051"
"35184","211.06799","17.58924","0.54531"
"35250","211.46400","17.62225","0.54875"
"35316","211.86000","17.65519","0.55299"
"35382","212.25600","17.68826","0.55691"
"35448","212.65199","17.72126","0.56063"
"35514","213.04800","17.75420","0.56448"
"35580","213.44400","17.78721","0.56778"
"35646","213.84000","17.82021","0.56996"
"35712","214.23599","17.85328","0.57221"
"35778","214.63200","17.88622","0.57465"
"35844","215.02800","17.91922","0.57751"
"35910","215.42400","17.95229","0.57943"
"35976","215.82001","17.98523","0.58137"
"36042","216.21600","18.01817","0.58383"
"36108","216.61200","18.05118","0.58532"
"36174","217.00800","18.08424","0.58672"
"36240","217.40401","18.11724","0.58858"
"36306","217.80000","18.15025","0.59126"
"36372","218.19600","18.18319","0.59409"
"36438","218.59200","18.21620","0.59724"
"36504","218.98801","18.24920","0.60092"
"36570","219.38400","18.28221","0.60519"
"36636","219.78000","18.31521","0.61234"
"36702","220.17599","18.34821","0.61925"
"36768","220.57201","18.38122","0.62451"
"36834","220.96800","18.41416","0.62806"
"36900","221.36400","18.44728","0.63170"
"36966","221.75999","18.48023","0.63578"
"37032","222.15601","18.51317","0.64115"
"37098","222.55200","18.54623","0.64516"
"37164","222.94800","18.57924","0.65081"
"37230","223.34399","18.61224","0.65454"
"37296","223.74001","18.64519","0.65813"
"37362","224.13600","18.67825","0.66252"
"37428","224.53200","18.71125","0.66757"
"37494","224.92799","18.74426","0.67172"
"37560","225.32401","18.77720","0.67673"
"37626","225.72000","18.81026","0.68009"
"37692","226.11600","18.84327","0.68290"
"37758","226.51199","18.87621","0.68564"
"37824","226.90800","18.90916","0.68811"
"37890","227.30400","18.94222","0.69031"
"37956","227.70000","18.97528","0.69271"
"38022","228.09599","19.00823","0.69570"
"38088","228.49200","19.04117","0.69784"
"38154","228.88800","19.07424","0.70037"
"38220","229.28400","19.10724","0.70193"
"38286","229.67999","19.14018","0.70398"
"38352","230.07600","19.17319","0.70622"
"38418","230.47200","19.20625","0.70762"
"38484","230.86800","19.23926","0.24530"
"38550","231.26401","19.27214","-0.00147"
"38616","231.66000","19.30514","-0.00299"
"38682","232.05600","19.33827","-0.00188"
"38748","232.45200","19.37121","0.00072"
"38814","232.84801","19.40421","0.00414"
"38880","233.24400","19.43722","-0.00012"
"38946","233.64000","19.47022","-0.00021"
"39012","234.03600","19.50329","-0.00074"
"39078","234.43201","19.53623","0.00031"
"39144","234.82800","19.56923","0.00196"
"39210","235.22400","19.60224","-0.00013"
"39276","235.62000","19.63518","0.00037"
"39342","236.01601","19.66818","-0.00040"
"39408","236.41200","19.70125","0.00002"
"39474","236.80800","19.73425","0.00146"
"39540","237.20399","19.76719","-0.00024"
"39606","237.60001","19.80020","0.00057"
"39672","237.99600","19.83321","-0.00004"
"39738","238.39200","19.86627","0.00036"
"39804","238.78799","19.89915","0.00075"
"39870","239.18401","19.93221","-0.00002"
"39936","239.58000","19.96522","0.00035"
"40002","239.97600","19.99828","0.00003"
"40068","240.37199","20.03123","0.00080"
"40134","240.76801","20.06429","0.00107"
"40200","241.16400","20.09723","0.00107"
"40266","241.56000","20.13024","0.00069"
"40332","241.95599","20.16312","0.00073"
"40398","242.35201","20.19631","0.00161"
"40464","242.74800","20.22925","0.00129"
"40530","243.14400","20.26213","0.00107"
"40596","243.53999","20.29526","0.00187"
"40662","243.93600","20.32820","0.00173"
"40728","244.33200","20.36121","0.00165"
"40794","244.72800","20.39415","0.00170"
"40860","245.12399","20.42721","0.00153"
"40926","245.52000","20.46028","0.00227"
"40992","245.91600","20.49328","0.00154"
"41058","246.31200","20.52611","0.00231"
"41124","246.70799","20.55923","0.00176"
"41190","247.10400","20.59229","0.00237"
"41256","247.50000","20.62524","0.00196"
"41322","247.89600","20.65818","0.00180"
"41388","248.29201","20.69124","0.00198"
"41454","248.68800","20.72425","0.00245"
"41520","249.08400","20.75719","0.00203"
"41586","249.48000","20.79020","0.00255"
"41652","249.87601","20.82326","0.00286"
"41718","250.27200","20.85626","0.00209"
"41784","250.66800","20.88927","0.00307"
"41850","251.06400","20.92221","0.00256"
"41916","251.46001","20.95522","0.00295"
"41982","251.85600","20.98822","0.00333"
"42048","252.25200","21.02116","0.00291"
"42114","252.64799","21.05417","0.00344"
"42180","253.04401","21.08723","0.00338"
"42246","253.44000","21.12024","0.00351"
"42312","253.83600","21.15318","0.00312"
"42378","254.23199","21.18618","0.00292"
"42444","254.62801","21.21919","0.00277"
"42510","255.02400","21.25225","0.00293"
"42576","255.42000","21.28519","0.00272"
"42642","255.81599","21.31825","0.00300"
"42708","256.21201","21.35126","0.00242"
"42774","256.60800","21.38420","0.00250"
"42840","257.00400","21.41715","0.00280"
"42906","257.39999","21.45027","0.00290"
"42972","257.79599","21.48322","0.00250"
"43038","258.19199","21.51616","0.00281"
"43104","258.58801","21.54922","0.00281"
"43170","258.98401","21.58223","0.00260"
"43236","259.38000","21.61523","0.00273"
"43302","259.77600","21.64818","0.00286"
"43368","260.17200","21.68124","0.00299"
"43434","260.56799","21.71424","0.00283"
"43500","260.96399","21.74718","0.00288"
"43566","261.35999","21.78013","0.00254"
"43632","261.75601","21.81319","0.00277"
"43698","262.15201","21.84626","0.00273"
"43764","262.54800","21.87920","0.00299"
"43830","262.94400","21.91215","0.00281"
"43896","263.34000","21.94521","0.00299"
"43962","263.73599","21.97827","0.00318"
"44028","264.13199","22.01122","0.00314"
"44094","264.52802","22.04422","0.00318"
"44160","264.92401","22.07728","0.00289"
"44226","265.32001","22.11029","0.00266"
"44292","265.71600","22.14317","0.00294"
"44358","266.11200","22.17618","0.00313"
"44424","266.50800","22.20924","0.00356"
"44490","266.90399","22.24224","0.00303"
"44556","267.29999","22.27519","0.00267"
"44622","267.69601","22.30819","0.00308"
"44688","268.09201","22.34126","0.00340"
"44754","268.48801","22.37420","0.00313"
"44820","268.88400","22.40720","0.00319"
"44886","269.28000","22.44021","0.00239"
"44952","269.67599","22.47321","0.00305"
"45018","270.07199","22.50616","0.00306"
"45084","270.46799","22.53922","0.00312"
"45150","270.86401","22.57222","0.00323"
"45216","271.26001","22.60523","0.00304"
"45282","271.65601","22.63817","0.00385"
"45348","272.05200","22.67118","0.00297"
"45414","272.44800","22.70430","0.00317"
"45480","272.84399","22.73724","0.00332"
"45546","273.23999","22.77019","0.00306"
"45612","273.63599","22.80325","0.00288"
"45678","274.03201","22.83619","0.00307"
"45744","274.42801","22.86920","0.00320"
"45810","274.82401","22.90214","0.00381"
"45876","275.22000","22.93526","0.00374"
"45942","275.61600","22.96821","0.00332"
"46008","276.01199","23.00121","0.00381"
"46074","276.40799","23.03416","0.00325"
"46140","276.80399","23.06728","0.00342"
"46206","277.20001","23.10028","0.00390"
"46272","277.59601","23.13323","0.00387"
"46338","277.99200","23.16623","0.00400"
"46404","278.38800","23.19924","0.00402"
"46470","278.78400","23.23230","0.00383"
"46536","279.17999","23.26518","0.00380"
"46602","279.57599","23.29813","0.00431"
"46668","279.97198","23.33125","0.00393"
"46734","280.36801","23.36426","0.00444"
"46800","280.76401","23.39714","0.00428"
"46866","281.16000","23.43020","0.00451"
"46932","281.55600","23.46327","0.00430"
"46998","281.95200","23.49627","0.00431"
"47064","282.34799","23.52921","0.00462"
"47130","282.74399","23.56222","0.00495"
"47196","283.14001","23.59522","0.00510"
"47262","283.53601","23.62822","0.00397"
"47328","283.93201","23.66117","0.00470"
"47394","284.32800","23.69423","0.00522"
"47460","284.72400","23.72718","0.00487"
"47526","285.12000","23.76018","0.00487"
"47592","285.51599","23.79324","0.00463"
"47658","285.91199","23.82619","0.00493"
"47724","286.30801","23.85925","0.00482"
"47790","286.70401","23.89226","0.00523"
"47856","287.10001","23.92520","0.00538"
"47922","287.49600","23.95826","0.00491"
"47988","287.89200","23.99121","0.00466"
"48054","288.28799","24.02421","0.00461"
"48120","288.68399","24.05722","0.00546"
"48186","289.07999","24.09022","0.00579"
"48252","289.47601","24.12322","0.00515"
"48318","289.87201","24.15623","0.00574"
"48384","290.26801","24.18929","0.00539"
"48450","290.66400","24.22224","0.00499"
"48516","291.06000","24.25518","0.00598"
"48582","291.45599","24.28818","0.00506"
"48648","291.85199","24.32125","0.00508"
"48714","292.24799","24.35425","0.00533"
"48780","292.64401","24.38719","0.00449"
"48846","293.04001","24.42020","0.00508"
"48912","293.43600","24.45326","0.00456"
"48978","293.83200","24.48627","0.00467"
"49044","294.22800","24.51915","0.00467"
"49110","294.62399","24.55222","0.00507"
"49176","295.01999","24.58528","0.00520"
"49242","295.41599","24.61822","0.00553"
"49308","295.81201","24.65117","0.00488"
"49374","296.20801","24.68423","0.00536"
"49440","296.60400","24.71723","0.00518"
"49506","297.00000","24.75023","0.00516"
"49572","297.39600","24.78318","0.00490"
"49638","297.79199","24.81624","0.00514"
"49704","298.18799","24.84925","0.00545"
"49770","298.58401","24.88225","0.00570"
"49836","298.98001","24.91520","0.00550"
"49902","299.37601","24.94826","0.00589"
"49968","299.77200","24.98126","0.00571"
"50034","300.16800","25.01421","0.00584"
"50100","300.56400","25.04721","0.00590"
"50166","300.95999","25.08027","0.00551"
"50232","301.35599","25.11322","0.00617"
"50298","301.75201","25.14622","0.00602"
"50364","302.14801","25.17923","0.00619"
"50430","302.54401","25.21223","0.00532"
"50496","302.94000","25.24523","0.00634"
"50562","303.33600","25.27818","0.00634"
"50628","303.73199","25.31124","0.00649"
"50694","304.12799","25.34425","0.00652"
"50760","304.52399","25.37719","0.00651"
"50826","304.92001","25.41019","0.00660"
"50892","305.31601","25.44320","0.00606"
"50958","305.71201","25.47620","0.00689"
"51024","306.10800","25.50920","0.00676"
"51090","306.50400","25.54221","0.00665"
"51156","306.89999","25.57527","0.00722"
"51222","307.29599","25.60828","0.00741"
"51288","307.69199","25.64116","0.00701"
"51354","308.08801","25.67422","0.00711"
"51420","308.48401","25.70729","0.00714"
"51486","308.88000","25.74023","0.00714"
"51552","309.27600","25.77318","0.00706"
"51618","309.67200","25.80624","0.00725"
"51684","310.06799","25.83924","0.00706"
"51750","310.46399","25.87219","0.00724"
"51816","310.85999","25.90513","0.00716"
"51882","311.25601","25.93826","0.00735"
"51948","311.65201","25.97126","0.00675"
"52014","312.04800","26.00420","0.00748"
"52080","312.44400","26.03721","0.00728"
"52146","312.84000","26.07021","0.00760"
"52212","313.23599","26.10328","0.00735"
"52278","313.63199","26.13622","0.00741"
"52344","314.02802","26.16916","0.00709"
"52410","314.42401","26.20222","0.00806"
"52476","314.82001","26.23529","0.00779"
"52542","315.21600","26.26817","0.00748"
"52608","315.61200","26.30118","0.00767"
"52674","316.00800","26.33424","0.00816"
"52740","316.40399","26.36724","0.00722"
"52806","316.79999","26.40019","0.00854"
"52872","317.19601","26.43319","0.00798"
"52938","317.59201","26.46625","0.00795"
"53004","317.98801","26.49926","0.00790"
"53070","318.38400","26.53221","0.00792"
"53136","318.78000","26.56521","0.00775"
"53202","319.17599","26.59821","0.00795"
"53268","319.57199","26.63122","0.00789"
"53334","319.96799","26.66422","0.00776"
"53400","320.36401","26.69716","0.00748"
"53466","320.76001","26.73023","0.00758"
"53532","321.15601","26.76323","0.00788"
"53598","321.55200","26.79623","0.00778"
"53664","321.94800","26.82924","0.00766"
"53730","322.34399","26.86224","0.00787"
"53796","322.73999","26.89518","0.00764"
"53862","323.13599","26.92825","0.00816"
"53928","323.53201","26.96119","0.00776"
"53994","323.92801","26.99426","0.00876"
"54060","324.32401","27.02714","0.00840"
"54126","324.72000","27.06027","0.00801"
"54192","325.11600","27.09327","0.00846"
"54258","325.51199","27.12621","0.00864"
"54324","325.90799","27.15916","0.00846"
"54390","326.30399","27.19228","0.00894"
"54456","326.70001","27.22522","0.00858"
"54522","327.09601","27.25817","0.00892"
"54588","327.49200","27.29117","0.00895"
"54654","327.88800","27.32424","0.00893"
"54720","328.28400","27.35730","0.00939"
"54786","328.67999","27.39012","0.00950"
"54852","329.07599","27.42325","0.00942"
"54918","329.47198","27.45625","0.00897"
"54984","329.86801","27.48932","0.00915"
"55050","330.26401","27.52214","0.00953"
"55116","330.66000","27.55520","0.00959"
"55182","331.05600","27.58827","0.00973"
"55248","331.45200","27.62127","0.00988"
"55314","331.84799","27.65415","0.01006"
"55380","332.24399","27.68722","0.00999"
"55446","332.64001","27.72022","0.01011"
"55512","333.03601","27.75323","0.01016"
"55578","333.43201","27.78617","0.01043"
"55644","333.82800","27.81923","0.00979"
"55710","334.22400","27.85224","0.01008"
"55776","334.62000","27.88524","0.00967"
"55842","335.01599","27.91818","0.01016"
"55908","335.41199","27.95125","0.01003"
"55974","335.80801","27.98419","0.01025"
"56040","336.20401","28.01726","0.01000"
"56106","336.60001","28.05020","0.01056"
"56172","336.99600","28.08320","0.01034"
"56238","337.39200","28.11627","0.01055"
"56304","337.78799","28.14921","0.01051"
"56370","338.18399","28.18221","0.01058"
"56436","338.57999","28.21522","0.01059"
"56502","338.97601","28.24822","0.01045"
"56568","339.37201","28.28123","0.01122"
"56634","339.76801","28.31429","0.01062"
"56700","340.16400","28.34723","0.01117"
"56766","340.56000","28.38024","0.01086"
"56832","340.95599","28.41318","0.01083"
"56898","341.35199","28.44625","0.01101"
"56964","341.74799","28.47925","0.01159"
"57030","342.14401","28.51220","0.01139"
"57096","342.54001","28.54526","0.01128"
"57162","342.93600","28.57826","0.01156"
"57228","343.33200","28.61121","0.01183"
"57294","343.72800","28.64415","0.01186"
"57360","344.12399","28.67721","0.01181"
"57426","344.51999","28.71022","0.01173"
"57492","344.91599","28.74322","0.01161"
"57558","345.31201","28.77616","0.01244"
"57624","345.70801","28.80923","0.01230"
"57690","346.10400","28.84223","0.01242"
"57756","346.50000","28.87518","0.01229"
"57822","346.89600","28.90818","0.01282"
"57888","347.29199","28.94118","0.01283"
"57954","347.68799","28.97431","0.01287"
"58020","348.08401","29.00725","0.01286"
"58086","348.48001","29.04014","0.01295"
"58152","348.87601","29.07326","0.01335"
"58218","349.27200","29.10633","0.01305"
"58284","349.66800","29.13915","0.01287"
"58350","350.06400","29.17221","0.01315"
"58416","350.45999","29.20527","0.01334"
"58482","350.85599","29.23828","0.01343"
"58548","351.25201","29.27116","0.01360"
"58614","351.64801","29.30417","0.01321"
"58680","352.04401","29.33723","0.01346"
"58746","352.44000","29.37024","0.01371"
"58812","352.83600","29.40324","0.01361"
"58878","353.23199","29.43624","0.01338"
"58944","353.62799","29.46919","0.01375"
"59010","354.02399","29.50219","0.01392"
"59076","354.42001","29.53519","0.01348"
"59142","354.81601","29.56820","0.01416"
"59208","355.21201","29.60126","0.01408"
"59274","355.60800","29.63420","0.01403"
"59340","356.00400","29.66721","0.01404"
"59406","356.39999","29.70021","0.01464"
"59472","356.79599","29.73322","0.01417"
"59538","357.19199","29.76622","0.01401"
"59604","357.58801","29.79922","0.01472"
"59670","357.98401","29.83223","0.01469"
"59736","358.38000","29.86523","0.01480"
"59802","358.77600","29.89817","0.01474"
"59868","359.17200","29.93124","0.01413"
"59934","359.56799","29.96430","0.01456"
"60000","359.96399","29.99719","0.01520"
"60066","360.35999","30.03019","0.01478"
"60132","360.75601","30.06325","0.01603"
"60198","361.15201","30.09626","0.01596"
"60264","361.54800","30.12920","0.01552"
"60330","361.94400","30.16221","0.01592"
"60396","362.34000","30.19527","0.01579"
"60462","362.73599","30.22827","0.01646"
"60528","363.13199","30.26116","0.01678"
"60594","363.52802","30.29422","0.01633"
"60660","363.92401","30.32729","0.01647"
"60726","364.32001","30.36023","0.01616"
"60792","364.71600","30.39317","0.01630"
"60858","365.11200","30.42624","0.01588"
"60924","365.50800","30.45924","0.01258"
"60990","365.90399","30.49224","0.01138"
"61056","366.29999","30.52513","0.00979"
"61122","366.69601","30.55819","0.01071"
"61188","367.09201","30.59126","0.01095"
"61254","367.48801","30.62426","0.01068"
"61320","367.88400","30.65720","0.01030"
"61386","368.28000","30.69021","0.01073"
"61452","368.67599","30.72321","0.01061"
"61518","369.07199","30.75622","0.01018"
"61584","369.46799","30.78916","0.01035"
"61650","369.86401","30.82222","0.01092"
"61716","370.26001","30.85523","0.01088"
"61782","370.65601","30.88823","0.01070"
"61848","371.05200","30.92123","0.01090"
"61914","371.44800","30.95418","0.01111"
"61980","371.84399","30.98718","0.01080"
"62046","372.23999","31.02019","0.01107"
"62112","372.63599","31.05325","0.01070"
"62178","373.03201","31.08625","0.01121"
"62244","373.42801","31.11920","0.01093"
"62310","373.82401","31.15220","0.01119"
"62376","374.22000","31.18526","0.01164"
"62442","374.61600","31.21821","0.01156"
"62508","375.01199","31.25121","0.01156"
"62574","375.40799","31.28415","0.01133"
"62640","375.80399","31.31728","0.01125"
"62706","376.20001","31.35028","0.01139"
"62772","376.59601","31.38317","0.01161"
"62838","376.99200","31.41623","0.01167"
"62904","377.38800","31.44929","0.01139"
"62970","377.78400","31.48224","0.01151"
"63036","378.17999","31.51518","0.01174"
"63102","378.57599","31.54825","0.01144"
"63168","378.97198","31.58131","0.01152"
"63234","379.36801","31.61425","0.01171"
"63300","379.76401","31.64714","0.01234"
"63366","380.16000","31.68020","0.01151"
"63432","380.55600","31.71321","0.01211"
"63498","380.95200","31.74627","0.01212"
"63564","381.34799","31.77915","0.01225"
"63630","381.74399","31.81222","0.01218"
"63696","382.14001","31.84522","0.01247"
"63762","382.53601","31.87816","0.01257"
"63828","382.93201","31.91117","0.01236"
"63894","383.32800","31.94423","0.01261"
"63960","383.72400","31.97729","0.01266"
"64026","384.12000","32.01024","0.01219"
"64092","384.51599","32.04318","0.01259"
"64158","384.91199","32.07619","0.01276"
"64224","385.30801","32.10925","0.01314"
"64290","385.70401","32.14220","0.01288"
"64356","386.10001","32.17520","0.01293"
"64422","386.49600","32.20826","0.01283"
"64488","386.89200","32.24121","0.01277"
"64554","387.28799","32.27421","0.01256"
"64620","387.68399","32.30722","0.01322"
"64686","388.07999","32.34022","0.01232"
"64752","388.47601","32.37322","0.01254"
"64818","388.87201","32.40623","0.01310"
"64884","389.26801","32.43923","0.01333"
"64950","389.66400","32.47218","0.01309"
"65016","390.06000","32.50524","0.01301"
"65082","390.45599","32.53818","0.01281"
"65148","390.85199","32.57124","0.01292"
"65214","391.24799","32.60425","0.01304"
"65280","391.64401","32.63720","0.01379"
"65346","392.04001","32.67020","0.01405"
"65412","392.43600","32.70320","0.01339"
"65478","392.83200","32.73626","0.01337"
"65544","393.22800","32.76915","0.01314"
"65610","393.62399","32.80221","0.01325"
"65676","394.01999","32.83527","0.01331"
"65742","394.41599","32.86816","0.01311"
"65808","394.81201","32.90117","0.01358"
"65874","395.20801","32.93423","0.01352"
"65940","395.60400","32.96729","0.01379"
"66006","396.00000","33.00023","0.01379"
"66072","396.39600","33.03318","0.01373"
"66138","396.79199","33.06630","0.01414"
"66204","397.18799","33.09925","0.01381"
"66270","397.58401","33.13219","0.01426"
"66336","397.98001","33.16520","0.01367"
"66402","398.37601","33.19826","0.01400"
"66468","398.77200","33.23126","0.01416"
"66534","399.16800","33.26421","0.01391"
"66600","399.56400","33.29715","0.01429"
"66666","399.95999","33.33027","0.01434"
"66732","400.35599","33.36327","0.01514"
"66798","400.75201","33.39616","0.01443"
"66864","401.14801","33.42923","0.01435"
"66930","401.54401","33.46223","0.01445"
"66996","401.94000","33.49523","0.01484"
"67062","402.33600","33.52818","0.01456"
"67128","402.73199","33.56124","0.01525"
"67194","403.12799","33.59424","0.01508"
"67260","403.52399","33.62725","0.01525"
"67326","403.92001","33.66019","0.01564"
"67392","404.31601","33.69325","0.01542"
"67458","404.71201","33.72626","0.01558"
"67524","405.10800","33.75920","0.01535"
"67590","405.50400","33.79214","0.01568"
"67656","405.89999","33.82521","0.01521"
"67722","406.29599","33.85827","0.01588"
"67788","406.69199","33.89122","0.01585"
"67854","407.08801","33.92422","0.01654"
"67920","407.48401","33.95723","0.01622"
"67986","407.88000","33.99017","0.01619"
"68052","408.27600","34.02323","0.01602"
"68118","408.67200","34.05624","0.01639"
"68184","409.06799","34.08924","0.01653"
"68250","409.46399","34.12224","0.01639"
"68316","409.85999","34.15519","0.01654"
"68382","410.25601","34.18825","0.01669"
"68448","410.65201","34.22126","0.01667"
"68514","411.04800","34.25420","0.01707"
"68580","411.44400","34.28720","0.01712"
"68646","411.84000","34.32027","0.01668"
"68712","412.23599","34.35327","0.01734"
"68778","412.63199","34.38622","0.01762"
"68844","413.02802","34.41922","0.01754"
"68910","413.42401","34.45228","0.01744"
"68976","413.82001","34.48529","0.01763"
"69042","414.21600","34.51817","0.01739"
"69108","414.61200","34.55123","0.01755"
"69174","415.00800","34.58424","0.01812"
"69240","415.40399","34.61724","0.01808"
"69306","415.79999","34.65019","0.01812"
"69372","416.19601","34.68319","0.01838"
"69438","416.59201","34.71619","0.01853"
"69504","416.98801","34.74926","0.01865"
"69570","417.38400","34.78220","0.01856"
"69636","417.78000","34.81521","0.01861"
"69702","418.17599","34.84821","0.01823"
"69768","418.57199","34.88121","0.01888"
"69834","418.96799","34.91422","0.01887"
"69900","419.36401","34.94722","0.01903"
"69966","419.76001","34.98022","0.01929"
"70032","420.15601","35.01323","0.01985"
"70098","420.55200","35.04623","0.01981"
"70164","420.94800","35.07930","0.02017"
"70230","421.34399","35.11224","0.01988"
"70296","421.73999","35.14519","0.01996"
"70362","422.13599","35.17825","0.02014"
"70428","422.53201","35.21125","0.02036"
"70494","422.92801","35.24420","0.02009"
"70560","423.32401","35.27720","0.02024"
"70626","423.72000","35.31026","0.02030"
"70692","424.11600","35.34321","0.02017"
"70758","424.51199","35.37621","0.02051"
"70824","424.90799","35.40916","0.02070"
"70890","425.30399","35.44228","0.02111"
"70956","425.70001","35.47522","0.02124"
"71022","426.09601","35.50823","0.02149"
"71088","426.49200","35.54123","0.02132"
"71154","426.88800","35.57430","0.02140"
"71220","427.28400","35.60724","0.02218"
"71286","427.67999","35.64012","0.02189"
"71352","428.07599","35.67324","0.02239"
"71418","428.47198","35.70625","0.02195"
"71484","428.86801","35.73919","0.02207"
"71550","429.26401","35.77214","0.02233"
"71616","429.66000","35.80526","0.02316"
"71682","430.05600","35.83826","0.02276"
"71748","430.45200","35.87121","0.02316"
"71814","430.84799","35.90416","0.02353"
"71880","431.24399","35.93722","0.02313"
"71946","431.64001","35.97028","0.02375"
"72012","432.03601","36.00322","0.02386"
"72078","432.43201","36.03623","0.02362"
"72144","432.82800","36.06923","0.02417"
"72210","433.22400","36.10229","0.02378"
"72276","433.62000","36.13518","0.02387"
"72342","434.01599","36.16818","0.02337"
"72408","434.41199","36.20124","0.02377"
"72474","434.80801","36.23425","0.02445"
"72540","435.20401","36.26720","0.02481"
"72606","435.60001","36.30020","0.02445"
"72672","435.99600","36.33320","0.02365"
"72738","436.39200","36.36626","0.02440"
"72804","436.78799","36.39921","0.02432"
"72870","437.18399","36.43221","0.02494"
"72936","437.57999","36.46527","0.02535"
"73002","437.97601","36.49816","0.02220"
"73068","438.37201","36.53117","0.01995"
"73134","438.76801","36.56429","0.01686"
"73200","439.16400","36.59717","0.01702"
"73266","439.56000","36.63018","0.01723"
"73332","439.95599","36.66324","0.01402"
"73398","440.35199","36.69624","0.01265"
"73464","440.74799","36.72925","0.01350"
"73530","441.14401","36.76219","0.01209"
"73596","441.54001","36.79520","0.01312"
"73662","441.93600","36.82826","0.01207"
"73728","442.33200","36.86120","0.01154"
"73794","442.72800","36.89421","0.01194"
"73860","443.12399","36.92721","0.01246"
"73926","443.51999","36.96021","0.01181"
"73992","443.91599","36.99322","0.01117"
"74058","444.31201","37.02617","0.01162"
"74124","444.70801","37.05923","0.01183"
"74190","445.10400","37.09229","0.01134"
"74256","445.50000","37.12518","0.01176"
"74322","445.89600","37.15818","0.01200"
"74388","446.29199","37.19124","0.01180"
"74454","446.68799","37.22424","0.01218"
"74520","447.08401","37.25719","0.01215"
"74586","447.48001","37.29019","0.01238"
"74652","447.87601","37.32326","0.01194"
"74718","448.27200","37.35626","0.01178"
"74784","448.66800","37.38914","0.01253"
"74850","449.06400","37.42221","0.01247"
"74916","449.45999","37.45521","0.01229"
"74982","449.85599","37.48822","0.01257"
"75048","450.25201","37.52116","0.01236"
"75114","450.64801","37.55422","0.01253"
"75180","451.04401","37.58723","0.01266"
"75246","451.44000","37.62023","0.01301"
"75312","451.83600","37.65318","0.01313"
"75378","452.23199","37.68624","0.01305"
"75444","452.62799","37.71924","0.01301"
"75510","453.02399","37.75219","0.01285"
"75576","453.42001","37.78519","0.01340"
"75642","453.81601","37.81819","0.01321"
"75708","454.21201","37.85126","0.01302"
"75774","454.60800","37.88420","0.01364"
"75840","455.00400","37.91721","0.01332"
"75906","455.39999","37.95027","0.01312"
"75972","455.79599","37.98328","0.01353"
"76038","456.19199","38.01616","0.01338"
"76104","456.58801","38.04922","0.01357"
"76170","456.98401","38.08223","0.01414"
"76236","457.38000","38.11523","0.01355"
"76302","457.77600","38.14817","0.01383"
"76368","458.17200","38.18118","0.01390"
"76434","458.56799","38.21418","0.01395"
"76500","458.96399","38.24719","0.01429"
"76566","459.35999","38.28019","0.01465"
"76632","459.75601","38.31325","0.01461"
"76698","460.15201","38.34626","0.01478"
"76764","460.54800","38.37920","0.01491"
"76830","460.94400","38.41220","0.01446"
"76896","461.34000","38.44521","0.01484"
"76962","461.73599","38.47827","0.01505"
"77028","462.13199","38.51116","0.01557"
"77094","462.52802","38.54422","0.01497"
"77160","462.92401","38.57722","0.01509"
"77226","463.32001","38.61023","0.01567"
"77292","463.71600","38.64317","0.01533"
"77358","464.11200","38.67618","0.01565"
"77424","464.50800","38.70930","0.01582"
"77490","464.90399","38.74224","0.01557"
"77556","465.29999","38.77519","0.01573"
"77622","465.69601","38.80825","0.01629"
"77688","466.09201","38.84119","0.01591"
"77754","466.48801","38.87420","0.01642"
"77820","466.88400","38.90720","0.01657"
"77886","467.28000","38.94027","0.01676"
"77952","467.67599","38.97327","0.01689"
"78018","468.07199","39.00628","0.01692"
"78084","468.46799","39.03922","0.01666"
"78150","468.86401","39.07222","0.01675"
"78216","469.26001","39.10529","0.01724"
"78282","469.65601","39.13816","0.01764"
"78348","470.05200","39.17123","0.01728"
"78414","470.44800","39.20423","0.01814"
"78480","470.84399","39.23724","0.01824"
"78546","471.23999","39.27013","0.01758"
"78612","471.63599","39.30319","0.01783"
"78678","472.03201","39.33625","0.01828"
"78744","472.42801","39.36926","0.01802"
"78810","472.82401","39.40219","0.01789"
"78876","473.22000","39.43526","0.01798"
"78942","473.61600","39.46821","0.01807"
"79008","474.01199","39.50121","0.01763"
"79074","474.40799","39.53421","0.01757"
"79140","474.80399","39.56728","0.01766"
"79206","475.20001","39.60022","0.01835"
"79272","475.59601","39.63316","0.01817"
"79338","475.99200","39.66617","0.01834"
"79404","476.38800","39.69923","0.01845"
"79470","476.78400","39.73223","0.01814"
"79536","477.17999","39.76518","0.01864"
"79602","477.57599","39.79824","0.01871"
"79668","477.97198","39.83125","0.01897"
"79734","478.36801","39.86425","0.01908"
"79800","478.76401","39.89714","0.01974"
"79866","479.16000","39.93026","0.01981"
"79932","479.55600","39.96326","0.01983"
"79998","479.95200","39.99621","0.01574"
"80064","480.34799","40.02915","0.01459"
"80130","480.74399","40.06221","0.01338"
"80196","481.14001","40.09522","0.01316"
"80262","481.53601","40.12822","0.01517"
"80328","481.93201","40.16117","0.01356"
"80394","482.32800","40.19423","0.01435"
"80460","482.72400","40.22729","0.01464"
"80526","483.12000","40.26018","0.01406"
"80592","483.51599","40.29324","0.01419"
"80658","483.91199","40.32624","0.01427"
"80724","484.30801","40.35925","0.01427"
"80767","484.56601","40.38071","0.01450"