File: Trajectories_together/170121_1Specimen_RawData_1.csv
"","V1","V2","V3"
"1","End date","1/21/2017",""
"2","Specimen label","19DT_NT",""
"3","Maximum Load","0.07495","N"
"4","Time","Extension","Load"
"5","(s)","(mm)","(N)"
"6","0.00000","0.00000","-0.00688"
"37","0.18600","0.01160","-0.00661"
"68","0.37200","0.03109","-0.00694"
"99","0.55800","0.04682","-0.00590"
"130","0.74400","0.06212","-0.00596"
"161","0.93000","0.07773","-0.00683"
"192","1.11600","0.09321","-0.00556"
"223","1.30200","0.10870","-0.00616"
"254","1.48800","0.12424","-0.00600"
"285","1.67400","0.13967","-0.00524"
"316","1.86000","0.15515","-0.00512"
"347","2.04600","0.17076","-0.00508"
"378","2.23200","0.18618","-0.00439"
"409","2.41800","0.20161","-0.00432"
"440","2.60400","0.21728","-0.00489"
"471","2.79000","0.23270","-0.00440"
"502","2.97600","0.24813","-0.00481"
"533","3.16200","0.26373","-0.00419"
"564","3.34800","0.27922","-0.00463"
"595","3.53400","0.29464","-0.00444"
"626","3.72000","0.31019","-0.00428"
"657","3.90600","0.32567","-0.00406"
"688","4.09200","0.34116","-0.00414"
"719","4.27800","0.35664","-0.00360"
"750","4.46400","0.37219","-0.00395"
"781","4.65000","0.38768","-0.00394"
"812","4.83600","0.40316","-0.00428"
"843","5.02200","0.41865","-0.00392"
"874","5.20800","0.43413","-0.00355"
"905","5.39400","0.44968","-0.00371"
"936","5.58000","0.46516","-0.00369"
"967","5.76600","0.48065","-0.00317"
"998","5.95200","0.49619","-0.00342"
"1029","6.13800","0.51162","-0.00324"
"1060","6.32400","0.52722","-0.00352"
"1091","6.51000","0.54271","-0.00360"
"1122","6.69600","0.55808","-0.00308"
"1153","6.88200","0.57368","-0.00325"
"1184","7.06800","0.58917","-0.00276"
"1215","7.25400","0.60465","-0.00220"
"1246","7.44000","0.62014","-0.00304"
"1277","7.62600","0.63562","-0.00294"
"1308","7.81200","0.65111","-0.00212"
"1339","7.99800","0.66665","-0.00256"
"1370","8.18400","0.68220","-0.00264"
"1401","8.37000","0.69768","-0.00264"
"1432","8.55600","0.71317","-0.00249"
"1463","8.74200","0.72866","-0.00233"
"1494","8.92800","0.74414","-0.00221"
"1525","9.11400","0.75969","-0.00227"
"1556","9.30000","0.77517","-0.00171"
"1587","9.48600","0.79072","-0.00182"
"1618","9.67200","0.80620","-0.00241"
"1649","9.85800","0.82169","-0.00189"
"1680","10.04400","0.83717","-0.00236"
"1711","10.23000","0.85272","-0.00188"
"1742","10.41600","0.86814","-0.00133"
"1773","10.60200","0.88363","-0.00194"
"1804","10.78800","0.89923","-0.00168"
"1835","10.97400","0.91460","-0.00146"
"1866","11.16000","0.93015","-0.00150"
"1897","11.34600","0.94575","-0.00131"
"1928","11.53200","0.96112","-0.00145"
"1959","11.71800","0.97666","-0.00123"
"1990","11.90400","0.99221","-0.00079"
"2021","12.09000","1.00763","-0.00095"
"2052","12.27600","1.02318","-0.00088"
"2083","12.46200","1.03866","-0.00164"
"2114","12.64800","1.05415","-0.00133"
"2145","12.83400","1.06963","-0.00079"
"2176","13.02000","1.08518","-0.00137"
"2207","13.20600","1.10061","-0.00080"
"2238","13.39200","1.11615","-0.00075"
"2269","13.57800","1.13164","-0.00101"
"2300","13.76400","1.14712","-0.00123"
"2331","13.95000","1.16273","-0.00037"
"2362","14.13600","1.17815","-0.00041"
"2393","14.32200","1.19364","-0.00075"
"2424","14.50800","1.20924","-0.00070"
"2455","14.69400","1.22467","-0.00024"
"2486","14.88000","1.24015","-0.00029"
"2517","15.06600","1.25570","-0.00136"
"2548","15.25200","1.27113","-0.00071"
"2579","15.43800","1.28667","-0.00007"
"2610","15.62400","1.30222","-0.00051"
"2641","15.81000","1.31764","-0.00062"
"2672","15.99600","1.33319","-0.00012"
"2703","16.18200","1.34873","-0.00012"
"2734","16.36800","1.36410","-0.00006"
"2765","16.55400","1.37970","0.00023"
"2796","16.74000","1.39519","-0.00025"
"2827","16.92600","1.41061","0.00015"
"2858","17.11200","1.42622","0.00016"
"2889","17.29800","1.44170","0.00014"
"2920","17.48400","1.45707","0.00053"
"2951","17.67000","1.47274","0.00006"
"2982","17.85600","1.48816","0.00043"
"3013","18.04200","1.50359","-0.00009"
"3044","18.22800","1.51919","0.00061"
"3075","18.41400","1.53468","-0.00006"
"3106","18.60000","1.55010","0.00051"
"3137","18.78600","1.56571","0.00050"
"3168","18.97200","1.58125","0.00016"
"3199","19.15800","1.59662","0.00015"
"3230","19.34400","1.61216","0.00103"
"3261","19.53000","1.62765","0.00040"
"3292","19.71600","1.64320","0.00033"
"3323","19.90200","1.65868","0.00097"
"3354","20.08800","1.67411","0.00109"
"3385","20.27400","1.68971","0.00084"
"3416","20.46000","1.70520","0.00187"
"3447","20.64600","1.72062","0.00083"
"3478","20.83200","1.73617","0.00125"
"3509","21.01800","1.75171","0.00106"
"3540","21.20400","1.76714","0.00130"
"3571","21.39000","1.78268","0.00086"
"3602","21.57600","1.79823","0.00108"
"3633","21.76200","1.81360","0.00099"
"3664","21.94800","1.82920","0.00124"
"3695","22.13400","1.84475","0.00139"
"3726","22.32000","1.86017","0.00152"
"3757","22.50600","1.87566","0.00127"
"3788","22.69200","1.89120","0.00180"
"3819","22.87800","1.90663","0.00139"
"3850","23.06400","1.92211","0.00133"
"3881","23.25000","1.93766","0.00155"
"3912","23.43600","1.95314","0.00170"
"3943","23.62200","1.96869","0.00165"
"3974","23.80800","1.98412","0.00124"
"4005","23.99400","1.99966","0.00198"
"4036","24.18000","2.01521","0.00206"
"4067","24.36600","2.03063","0.00133"
"4098","24.55200","2.04618","0.00155"
"4129","24.73800","2.06166","0.00203"
"4160","24.92400","2.07715","0.00166"
"4191","25.11000","2.09269","0.00174"
"4222","25.29600","2.10824","0.00204"
"4253","25.48200","2.12360","0.00216"
"4284","25.66800","2.13921","0.00194"
"4315","25.85400","2.15470","0.00200"
"4346","26.04000","2.17012","0.00177"
"4377","26.22600","2.18567","0.00228"
"4408","26.41200","2.20121","0.00246"
"4439","26.59800","2.21664","0.00201"
"4470","26.78400","2.23218","0.00192"
"4501","26.97000","2.24767","0.00221"
"4532","27.15600","2.26315","0.00223"
"4563","27.34200","2.27870","0.00243"
"4594","27.52800","2.29412","0.00211"
"4625","27.71400","2.30967","0.00215"
"4656","27.90000","2.32521","0.00266"
"4687","28.08600","2.34070","0.00275"
"4718","28.27200","2.35613","0.00241"
"4749","28.45800","2.37167","0.00280"
"4780","28.64400","2.38716","0.00263"
"4811","28.83000","2.40264","0.00238"
"4842","29.01600","2.41819","0.00276"
"4873","29.20200","2.43361","0.00273"
"4904","29.38800","2.44916","0.00263"
"4935","29.57400","2.46470","0.00233"
"4966","29.76000","2.48013","0.00234"
"4997","29.94600","2.49567","0.00257"
"5028","30.13200","2.51122","0.00370"
"5059","30.31800","2.52665","0.00310"
"5090","30.50400","2.54219","0.00276"
"5121","30.69000","2.55762","0.00274"
"5152","30.87600","2.57316","0.00182"
"5183","31.06200","2.58865","0.00242"
"5214","31.24800","2.60419","0.00210"
"5245","31.43400","2.61968","0.00261"
"5276","31.62000","2.63522","0.00243"
"5307","31.80600","2.65071","0.00186"
"5338","31.99200","2.66613","0.00187"
"5369","32.17800","2.68174","0.00203"
"5400","32.36400","2.69717","0.00197"
"5431","32.55000","2.71265","0.00222"
"5462","32.73600","2.72820","0.00237"
"5493","32.92200","2.74362","0.00250"
"5524","33.10800","2.75911","0.00212"
"5555","33.29400","2.77465","0.00211"
"5586","33.48000","2.79014","0.00274"
"5617","33.66600","2.80568","0.00274"
"5648","33.85200","2.82123","0.00240"
"5679","34.03800","2.83671","0.00278"
"5710","34.22400","2.85220","0.00247"
"5741","34.41000","2.86763","0.00280"
"5772","34.59600","2.88317","0.00392"
"5803","34.78200","2.89866","0.00292"
"5834","34.96800","2.91420","0.00352"
"5865","35.15400","2.92969","0.00316"
"5896","35.34000","2.94517","0.00368"
"5927","35.52600","2.96072","0.00324"
"5958","35.71200","2.97614","0.00350"
"5989","35.89800","2.99169","0.00308"
"6020","36.08400","3.00717","0.00344"
"6051","36.27000","3.02266","0.00316"
"6082","36.45600","3.03815","0.00347"
"6113","36.64200","3.05369","0.00319"
"6144","36.82800","3.06912","0.00349"
"6175","37.01400","3.08466","0.00345"
"6206","37.20000","3.10027","0.00340"
"6237","37.38600","3.11557","0.00391"
"6268","37.57200","3.13118","0.00333"
"6299","37.75800","3.14672","0.00310"
"6330","37.94400","3.16215","0.00366"
"6361","38.13000","3.17763","0.00375"
"6392","38.31600","3.19318","0.00380"
"6423","38.50200","3.20866","0.00349"
"6454","38.68800","3.22415","0.00366"
"6485","38.87400","3.23970","0.00454"
"6516","39.06000","3.25518","0.00375"
"6547","39.24600","3.27067","0.00298"
"6578","39.43200","3.28615","0.00360"
"6609","39.61800","3.30170","0.00390"
"6640","39.80400","3.31718","0.00399"
"6671","39.99000","3.33267","0.00419"
"6702","40.17600","3.34815","0.00448"
"6733","40.36200","3.36370","0.00445"
"6764","40.54800","3.37912","0.00458"
"6795","40.73400","3.39467","0.00390"
"6826","40.92000","3.41022","0.00445"
"6857","41.10600","3.42564","0.00472"
"6888","41.29200","3.44119","0.00470"
"6919","41.47800","3.45667","0.00517"
"6950","41.66400","3.47216","0.00509"
"6981","41.85000","3.48770","0.00499"
"7012","42.03600","3.50325","0.00460"
"7043","42.22200","3.51861","0.00495"
"7074","42.40800","3.53422","0.00468"
"7105","42.59400","3.54970","0.00500"
"7136","42.78000","3.56513","0.00479"
"7167","42.96600","3.58068","0.00568"
"7198","43.15200","3.59616","0.00480"
"7229","43.33800","3.61165","0.00496"
"7260","43.52400","3.62719","0.00452"
"7291","43.71000","3.64268","0.00492"
"7322","43.89600","3.65810","0.00426"
"7353","44.08200","3.67371","0.00476"
"7384","44.26800","3.68919","0.00453"
"7415","44.45400","3.70468","0.00409"
"7446","44.64000","3.72022","0.00447"
"7477","44.82600","3.73565","0.00459"
"7508","45.01200","3.75114","0.00487"
"7539","45.19800","3.76668","0.00472"
"7570","45.38400","3.78211","0.00433"
"7601","45.57000","3.79765","0.00475"
"7632","45.75600","3.81320","0.00520"
"7663","45.94200","3.82862","0.00521"
"7694","46.12800","3.84417","0.00513"
"7725","46.31400","3.85971","0.00556"
"7756","46.50000","3.87514","0.00587"
"7787","46.68600","3.89068","0.00547"
"7818","46.87200","3.90617","0.00641"
"7849","47.05800","3.92160","0.00578"
"7880","47.24400","3.93720","0.00551"
"7911","47.43000","3.95269","0.00573"
"7942","47.61600","3.96811","0.00619"
"7973","47.80200","3.98372","0.00567"
"8004","47.98800","3.99920","0.00557"
"8035","48.17400","4.01463","0.00533"
"8066","48.36000","4.03023","0.00586"
"8097","48.54600","4.04572","0.00610"
"8128","48.73200","4.06114","0.00581"
"8159","48.91800","4.07669","0.00618"
"8190","49.10400","4.09218","0.00639"
"8221","49.29000","4.10772","0.00650"
"8252","49.47600","4.12321","0.00653"
"8283","49.66200","4.13863","0.00617"
"8314","49.84800","4.15418","0.00610"
"8345","50.03400","4.16966","0.00647"
"8376","50.22000","4.18515","0.00699"
"8407","50.40600","4.20069","0.00663"
"8438","50.59200","4.21618","0.00700"
"8469","50.77800","4.23160","0.00706"
"8500","50.96400","4.24721","0.00642"
"8531","51.15000","4.26269","0.00647"
"8562","51.33600","4.27812","0.00746"
"8593","51.52200","4.29373","0.00814"
"8624","51.70800","4.30915","0.00750"
"8655","51.89400","4.32464","0.00763"
"8686","52.08000","4.34018","0.00805"
"8717","52.26600","4.35573","0.00787"
"8748","52.45200","4.37109","0.00774"
"8779","52.63800","4.38670","0.00745"
"8810","52.82400","4.40218","0.00772"
"8841","53.01000","4.41761","0.00844"
"8872","53.19600","4.43321","0.00812"
"8903","53.38200","4.44870","0.00843"
"8934","53.56800","4.46419","0.00862"
"8965","53.75400","4.47967","0.00852"
"8996","53.94000","4.49516","0.00862"
"9027","54.12600","4.51064","0.00817"
"9058","54.31200","4.52613","0.00740"
"9089","54.49800","4.54161","0.00757"
"9120","54.68400","4.55722","0.00824"
"9151","54.87000","4.57270","0.00822"
"9182","55.05600","4.58813","0.00857"
"9213","55.24200","4.60367","0.00731"
"9244","55.42800","4.61922","0.00744"
"9275","55.61400","4.63465","0.00729"
"9306","55.80000","4.65013","0.00828"
"9337","55.98600","4.66574","0.00825"
"9368","56.17200","4.68116","0.00833"
"9399","56.35800","4.69665","0.00820"
"9430","56.54400","4.71219","0.00873"
"9461","56.73000","4.72762","0.00867"
"9492","56.91600","4.74322","0.00908"
"9523","57.10200","4.75865","0.00937"
"9554","57.28800","4.77413","0.00889"
"9585","57.47400","4.78974","0.00898"
"9616","57.66000","4.80517","0.00943"
"9647","57.84600","4.82065","0.00876"
"9678","58.03200","4.83620","0.00882"
"9709","58.21800","4.85162","0.00997"
"9740","58.40400","4.86711","0.00961"
"9771","58.59000","4.88271","0.00988"
"9802","58.77600","4.89808","0.00999"
"9833","58.96200","4.91368","0.01002"
"9864","59.14800","4.92923","0.01035"
"9895","59.33400","4.94465","0.01045"
"9926","59.52000","4.96020","0.01060"
"9957","59.70600","4.97568","0.01016"
"9988","59.89200","4.99117","0.01016"
"10019","60.07800","5.00666","0.01070"
"10050","60.26400","5.02220","0.01072"
"10081","60.45000","5.03763","0.01129"
"10112","60.63600","5.05317","0.01165"
"10143","60.82200","5.06872","0.01185"
"10174","61.00800","5.08408","0.01189"
"10205","61.19400","5.09969","0.01205"
"10236","61.38000","5.11517","0.01221"
"10267","61.56600","5.13066","0.01267"
"10298","61.75200","5.14620","0.01259"
"10329","61.93800","5.16175","0.01251"
"10360","62.12400","5.17712","0.01295"
"10391","62.31000","5.19272","0.01293"
"10422","62.49600","5.20821","0.01335"
"10453","62.68200","5.22363","0.01335"
"10484","62.86800","5.23918","0.01416"
"10515","63.05400","5.25466","0.01395"
"10546","63.24000","5.27009","0.01429"
"10577","63.42600","5.28575","0.01453"
"10608","63.61200","5.30118","0.01472"
"10639","63.79800","5.31660","0.01490"
"10670","63.98400","5.33215","0.01517"
"10701","64.17000","5.34770","0.01596"
"10732","64.35600","5.36318","0.01575"
"10763","64.54200","5.37867","0.01573"
"10794","64.72800","5.39415","0.01600"
"10825","64.91400","5.40964","0.01686"
"10856","65.10000","5.42518","0.01673"
"10887","65.28600","5.44067","0.01731"
"10918","65.47200","5.45621","0.01764"
"10949","65.65800","5.47164","0.01767"
"10980","65.84400","5.48718","0.01746"
"11011","66.03000","5.50267","0.01656"
"11042","66.21600","5.51821","0.01841"
"11073","66.40200","5.53364","0.01834"
"11104","66.58800","5.54919","0.01855"
"11135","66.77400","5.56467","0.01982"
"11166","66.96000","5.58010","0.01966"
"11197","67.14600","5.59564","0.01949"
"11228","67.33200","5.61125","0.02033"
"11259","67.51800","5.62667","0.02073"
"11290","67.70400","5.64216","0.02115"
"11321","67.89000","5.65770","0.02195"
"11352","68.07600","5.67313","0.02227"
"11383","68.26200","5.68867","0.02233"
"11414","68.44800","5.70422","0.02288"
"11445","68.63400","5.71965","0.02331"
"11476","68.82000","5.73519","0.02395"
"11507","69.00600","5.75062","0.02456"
"11538","69.19200","5.76616","0.02519"
"11569","69.37800","5.78165","0.02594"
"11600","69.56400","5.79719","0.02657"
"11631","69.75000","5.81262","0.02575"
"11662","69.93600","5.82822","0.02671"
"11693","70.12200","5.84365","0.02753"
"11724","70.30800","5.85913","0.02876"
"11755","70.49400","5.87468","0.02839"
"11786","70.68000","5.89017","0.03009"
"11817","70.86600","5.90565","0.03042"
"11848","71.05200","5.92120","0.03146"
"11879","71.23800","5.93662","0.03191"
"11910","71.42400","5.95217","0.03227"
"11941","71.61000","5.96771","0.03347"
"11972","71.79600","5.98314","0.03382"
"12003","71.98200","5.99868","0.03541"
"12034","72.16800","6.01423","0.03576"
"12065","72.35400","6.02965","0.03706"
"12096","72.54000","6.04520","0.03730"
"12127","72.72600","6.06069","0.03853"
"12158","72.91200","6.07617","0.03950"
"12189","73.09800","6.09166","0.04059"
"12220","73.28400","6.10714","0.04108"
"12251","73.47000","6.12263","0.04289"
"12282","73.65600","6.13817","0.04306"
"12313","73.84200","6.15372","0.04417"
"12344","74.02800","6.16914","0.04489"
"12375","74.21400","6.18475","0.04656"
"12406","74.40000","6.20017","0.04759"
"12437","74.58600","6.21566","0.04815"
"12468","74.77200","6.23120","0.04860"
"12499","74.95800","6.24669","0.05009"
"12530","75.14400","6.26218","0.05051"
"12561","75.33000","6.27766","0.05227"
"12592","75.51600","6.29315","0.05243"
"12623","75.70200","6.30863","0.05362"
"12654","75.88800","6.32418","0.05457"
"12685","76.07400","6.33966","0.05476"
"12716","76.26000","6.35515","0.05553"
"12747","76.44600","6.37069","0.05720"
"12778","76.63200","6.38618","0.05774"
"12809","76.81800","6.40173","0.05848"
"12840","77.00400","6.41721","0.05894"
"12871","77.19000","6.43264","0.05958"
"12902","77.37600","6.44824","0.06039"
"12933","77.56200","6.46367","0.06080"
"12964","77.74800","6.47909","0.06076"
"12995","77.93400","6.49470","0.06192"
"13026","78.12000","6.51018","0.06296"
"13057","78.30600","6.52561","0.06313"
"13088","78.49200","6.54121","0.06436"
"13119","78.67800","6.55670","0.06493"
"13150","78.86400","6.57212","0.06543"
"13181","79.05000","6.58767","0.06623"
"13212","79.23600","6.60322","0.06537"
"13243","79.42200","6.61864","0.06702"
"13274","79.60800","6.63413","0.06796"
"13305","79.79400","6.64967","0.06879"
"13336","79.98000","6.66516","0.06924"
"13367","80.16600","6.68070","0.07040"
"13398","80.35200","6.69613","0.07094"
"13429","80.53800","6.71173","0.07136"
"13460","80.72400","6.72722","0.07156"
"13491","80.91000","6.74265","0.07241"
"13522","81.09600","6.75813","0.07231"
"13553","81.28200","6.77368","0.07312"
"13584","81.46800","6.78916","0.07319"
"13615","81.65400","6.80465","0.07312"
"13646","81.84000","6.82019","0.07342"
"13677","82.02600","6.83562","0.07395"
"13708","82.21200","6.85116","0.07419"
"13739","82.39800","6.86677","0.07481"
"13770","82.58400","6.88213","0.01896"
"13801","82.77000","6.89768","0.02560"
"13832","82.95600","6.91322","0.02243"
"13863","83.14200","6.92871","0.02270"
"13894","83.32800","6.94420","0.02365"
"13925","83.51400","6.95968","0.02284"
"13956","83.70000","6.97517","0.02471"
"13987","83.88600","6.99059","0.02607"
"14018","84.07200","7.00614","0.02704"
"14049","84.25800","7.02168","0.02683"
"14080","84.44400","7.03717","0.02777"
"14111","84.63000","7.05259","0.02750"
"14142","84.81600","7.06814","0.02799"
"14173","85.00200","7.08368","0.02944"
"14204","85.18800","7.09917","0.02973"
"14235","85.37400","7.11466","0.03018"
"14266","85.56000","7.13020","0.03118"
"14297","85.74600","7.14569","0.03221"
"14328","85.93200","7.16117","0.03071"
"14359","86.11800","7.17672","0.03180"
"14390","86.30400","7.19208","0.03227"
"14421","86.49000","7.20769","0.03274"
"14452","86.67600","7.22317","0.03281"
"14483","86.86200","7.23866","0.03293"
"14514","87.04800","7.25420","0.03367"
"14545","87.23400","7.26969","0.03377"
"14576","87.42000","7.28512","0.03441"
"14607","87.60600","7.30072","0.03514"
"14638","87.79200","7.31621","0.03468"
"14669","87.97800","7.33169","0.03577"
"14700","88.16400","7.34724","0.03570"
"14731","88.35000","7.36266","0.03514"
"14762","88.53600","7.37815","0.03518"
"14793","88.72200","7.39363","0.03484"
"14824","88.90800","7.40918","0.03541"
"14855","89.09400","7.42460","0.03580"
"14886","89.28000","7.44015","0.03552"
"14917","89.46600","7.45564","0.03442"
"14948","89.65200","7.47112","0.03377"
"14979","89.83800","7.48673","0.03350"
"15010","90.02400","7.50215","0.03398"
"15041","90.21000","7.51764","0.02844"
"15072","90.39600","7.53318","0.02909"
"15103","90.58200","7.54861","0.03056"
"15134","90.76800","7.56415","0.03159"
"15165","90.95400","7.57970","0.03167"
"15196","91.14000","7.59518","0.03301"
"15227","91.32600","7.61067","0.03255"
"15258","91.51200","7.62616","0.03346"
"15289","91.69800","7.64164","0.03348"
"15320","91.88400","7.65719","0.03442"
"15351","92.07000","7.67267","0.03512"
"15382","92.25600","7.68816","0.03600"
"15413","92.44200","7.70370","0.03583"
"15444","92.62800","7.71919","0.03654"
"15475","92.81400","7.73461","0.03634"
"15506","93.00000","7.75022","0.03531"
"15537","93.18600","7.76570","0.03556"
"15568","93.37200","7.78119","0.03610"
"15599","93.55800","7.79667","0.03532"
"15630","93.74400","7.81222","0.03489"
"15661","93.93000","7.82765","0.03586"
"15692","94.11600","7.84313","0.03583"
"15723","94.30200","7.85874","0.03620"
"15754","94.48800","7.87416","0.03662"
"15785","94.67400","7.88965","0.03607"
"15816","94.86000","7.90513","0.03613"
"15847","95.04600","7.92068","0.03658"
"15878","95.23200","7.93616","0.03741"
"15909","95.41800","7.95165","0.03765"
"15940","95.60400","7.96719","0.03740"
"15971","95.79000","7.98268","0.03784"
"16002","95.97600","7.99811","0.03796"
"16033","96.16200","8.01371","0.03718"
"16064","96.34800","8.02920","0.03736"
"16095","96.53400","8.04468","0.03678"
"16126","96.72000","8.06011","0.03457"
"16157","96.90600","8.07565","0.03485"
"16188","97.09200","8.09108","0.03449"
"16219","97.27800","8.10662","0.03381"
"16250","97.46400","8.12223","0.03278"
"16281","97.65000","8.13760","0.03183"
"16312","97.83600","8.15320","0.03099"
"16343","98.02200","8.16868","0.03068"
"16374","98.20800","8.18411","0.02780"
"16405","98.39400","8.19966","0.02489"
"16436","98.58000","8.21520","0.02408"
"16467","98.76600","8.23063","0.02338"
"16498","98.95200","8.24617","0.02181"
"16529","99.13800","8.26166","0.02163"
"16560","99.32400","8.27714","0.02027"
"16591","99.51000","8.29263","0.01917"
"16622","99.69600","8.30817","0.01941"
"16653","99.88200","8.32366","0.01879"
"16684","100.06800","8.33920","0.01900"
"16715","100.25400","8.35469","0.01917"
"16746","100.44000","8.37018","0.01920"
"16777","100.62600","8.38572","0.01925"
"16808","100.81200","8.40121","0.01943"
"16839","100.99800","8.41669","0.01972"
"16870","101.18400","8.43218","0.02021"
"16901","101.37000","8.44760","0.01981"
"16932","101.55600","8.46315","0.01969"
"16963","101.74200","8.47869","0.01984"
"16994","101.92800","8.49412","0.01969"
"17025","102.11400","8.50972","0.01998"
"17056","102.30000","8.52521","0.02109"
"17087","102.48600","8.54064","0.02066"
"17118","102.67200","8.55618","0.02087"
"17149","102.85800","8.57167","0.02154"
"17180","103.04400","8.58715","0.02130"
"17211","103.23000","8.60270","0.02244"
"17242","103.41600","8.61818","0.02215"
"17273","103.60200","8.63361","0.02229"
"17304","103.78800","8.64921","0.02315"
"17335","103.97400","8.66464","0.02308"
"17366","104.16000","8.68013","0.02315"
"17397","104.34600","8.69567","0.02457"
"17428","104.53200","8.71116","0.02408"
"17459","104.71800","8.72664","0.02498"
"17490","104.90400","8.74225","0.02568"
"17521","105.09000","8.75767","0.02572"
"17552","105.27600","8.77316","0.02586"
"17583","105.46200","8.78870","0.02640"
"17614","105.64800","8.80413","0.02693"
"17645","105.83400","8.81967","0.02686"
"17676","106.02000","8.83522","0.02754"
"17707","106.20600","8.85064","0.02860"
"17738","106.39200","8.86619","0.02893"
"17769","106.57800","8.88167","0.02887"
"17800","106.76400","8.89716","0.02907"
"17831","106.95000","8.91271","0.02990"
"17862","107.13600","8.92819","0.02975"
"17893","107.32200","8.94362","0.03093"
"17924","107.50800","8.95922","0.03065"
"17955","107.69400","8.97471","0.03118"
"17986","107.88000","8.99007","0.03099"
"18017","108.06600","9.00574","0.03033"
"18048","108.25200","9.02122","0.02957"
"18079","108.43800","9.03665","0.02789"
"18110","108.62400","9.05219","0.02597"
"18141","108.81000","9.06768","0.02333"
"18172","108.99600","9.08311","0.02224"
"18203","109.18200","9.09865","0.02186"
"18234","109.36800","9.11420","0.02209"
"18265","109.55400","9.12962","0.02214"
"18296","109.74000","9.14511","0.02159"
"18327","109.92600","9.16059","0.02143"
"18358","110.11200","9.17614","0.02203"
"18389","110.29800","9.19168","0.02218"
"18420","110.48400","9.20717","0.02217"
"18451","110.67000","9.22272","0.02264"
"18482","110.85600","9.23820","0.02326"
"18513","111.04200","9.25357","0.02273"
"18544","111.22800","9.26923","0.02259"
"18575","111.41400","9.28472","0.02302"
"18606","111.60000","9.30014","0.02313"
"18637","111.78600","9.31575","0.02322"
"18668","111.97200","9.33117","0.02241"
"18699","112.15800","9.34660","0.02284"
"18730","112.34400","9.36220","0.02243"
"18761","112.53000","9.37775","0.02333"
"18792","112.71600","9.39312","0.02293"
"18823","112.90200","9.40872","0.02368"
"18854","113.08800","9.42421","0.02276"
"18885","113.27400","9.43963","0.02325"
"18916","113.46000","9.45524","0.02342"
"18947","113.64600","9.47066","0.02286"
"18978","113.83200","9.48615","0.02246"
"19009","114.01800","9.50169","0.02272"
"19040","114.20400","9.51712","0.02274"
"19071","114.39000","9.53266","0.02319"
"19102","114.57600","9.54815","0.02316"
"19133","114.76200","9.56363","0.02332"
"19164","114.94800","9.57918","0.02238"
"19195","115.13400","9.59467","0.02206"
"19226","115.32000","9.61009","0.02122"
"19257","115.50600","9.62570","0.02099"
"19288","115.69200","9.64124","0.02105"
"19319","115.87800","9.65661","0.02087"
"19350","116.06400","9.67215","0.02157"
"19381","116.25000","9.68770","0.02143"
"19412","116.43600","9.70312","0.02163"
"19443","116.62200","9.71867","0.02163"
"19474","116.80800","9.73415","0.02217"
"19505","116.99400","9.74970","0.02198"
"19536","117.18000","9.76519","0.02298"
"19567","117.36600","9.78067","0.02269"
"19598","117.55200","9.79616","0.02289"
"19629","117.73800","9.81170","0.02254"
"19660","117.92400","9.82719","0.02293"
"19691","118.11000","9.84267","0.02242"
"19722","118.29600","9.85822","0.02293"
"19753","118.48200","9.87364","0.02237"
"19784","118.66800","9.88913","0.02258"
"19815","118.85400","9.90473","0.02207"
"19846","119.04000","9.92016","0.02286"
"19877","119.22600","9.93565","0.02290"
"19908","119.41200","9.95119","0.02404"
"19939","119.59800","9.96667","0.02322"
"19970","119.78400","9.98216","0.02394"
"20001","119.97000","9.99771","0.02356"
"20032","120.15600","10.01319","0.02348"
"20063","120.34200","10.02868","0.02326"
"20094","120.52800","10.04416","0.02346"
"20125","120.71400","10.05971","0.02317"
"20156","120.90000","10.07519","0.02357"
"20187","121.08600","10.09074","0.02380"
"20218","121.27200","10.10616","0.02372"
"20249","121.45800","10.12165","0.02417"
"20280","121.64400","10.13726","0.02436"
"20311","121.83000","10.15262","0.02403"
"20342","122.01600","10.16817","0.02391"
"20373","122.20200","10.18365","0.02408"
"20404","122.38800","10.19908","0.02339"
"20435","122.57400","10.21468","0.02313"
"20466","122.76000","10.23017","0.02277"
"20497","122.94600","10.24559","0.02266"
"20528","123.13200","10.26120","0.02268"
"20559","123.31800","10.27668","0.02363"
"20590","123.50400","10.29211","0.02386"
"20621","123.69000","10.30766","0.02437"
"20652","123.87600","10.32320","0.02457"
"20683","124.06200","10.33869","0.02555"
"20714","124.24800","10.35417","0.02485"
"20745","124.43400","10.36972","0.02588"
"20776","124.62000","10.38514","0.02643"
"20807","124.80600","10.40063","0.02657"
"20838","124.99200","10.41617","0.02661"
"20869","125.17800","10.43166","0.02646"
"20900","125.36400","10.44720","0.02721"
"20931","125.55000","10.46269","0.02698"
"20962","125.73600","10.47824","0.02646"
"20993","125.92200","10.49366","0.02538"
"21024","126.10800","10.50915","0.02588"
"21055","126.29400","10.52469","0.02454"
"21086","126.48000","10.54024","0.02355"
"21117","126.66600","10.55566","0.02244"
"21148","126.85200","10.57115","0.02183"
"21179","127.03800","10.58669","0.02219"
"21210","127.22400","10.60212","0.02213"
"21241","127.41000","10.61767","0.02132"
"21272","127.59600","10.63321","0.02139"
"21303","127.78200","10.64863","0.02098"
"21334","127.96800","10.66418","0.02085"
"21365","128.15400","10.67973","0.02052"
"21396","128.34000","10.69509","0.02066"
"21427","128.52600","10.71070","0.02056"
"21458","128.71200","10.72618","0.01923"
"21489","128.89800","10.74161","0.01808"
"21520","129.08400","10.75721","0.01831"
"21551","129.27000","10.77270","0.01804"
"21582","129.45600","10.78813","0.01475"
"21613","129.64200","10.80367","0.01452"
"21644","129.82800","10.81916","0.01569"
"21675","130.01400","10.83470","0.01412"
"21706","130.20000","10.85019","0.01510"
"21737","130.38600","10.86567","0.01547"
"21768","130.57200","10.88116","0.01497"
"21799","130.75800","10.89670","0.01482"
"21830","130.94400","10.91219","0.01462"
"21861","131.13000","10.92767","0.01571"
"21892","131.31600","10.94322","0.01491"
"21923","131.50200","10.95858","0.01527"
"21954","131.68800","10.97419","0.01526"
"21985","131.87400","10.98973","0.01605"
"22016","132.06000","11.00516","0.01526"
"22047","132.24600","11.02065","0.01629"
"22078","132.43200","11.03619","0.01614"
"22109","132.61800","11.05162","0.01544"
"22140","132.80400","11.06716","0.01561"
"22171","132.99000","11.08271","0.01591"
"22202","133.17600","11.09807","0.01598"
"22233","133.36200","11.11368","0.01562"
"22264","133.54800","11.12916","0.01605"
"22295","133.73400","11.14465","0.01651"
"22326","133.92000","11.16019","0.01631"
"22357","134.10600","11.17568","0.01673"
"22388","134.29200","11.19116","0.01640"
"22419","134.47800","11.20665","0.01638"
"22450","134.66400","11.22214","0.01685"
"22481","134.85000","11.23762","0.01645"
"22512","135.03600","11.25317","0.01686"
"22543","135.22200","11.26865","0.01689"
"22574","135.40800","11.28414","0.01655"
"22605","135.59400","11.29962","0.01721"
"22636","135.78000","11.31517","0.01715"
"22667","135.96600","11.33071","0.01704"
"22698","136.15200","11.34620","0.01722"
"22729","136.33800","11.36168","0.01687"
"22760","136.52400","11.37717","0.01704"
"22791","136.71000","11.39272","0.01728"
"22822","136.89600","11.40814","0.01709"
"22853","137.08200","11.42369","0.01719"
"22884","137.26800","11.43923","0.01733"
"22915","137.45400","11.45460","0.01742"
"22946","137.64000","11.47026","0.01671"
"22977","137.82600","11.48563","0.01775"
"23008","138.01200","11.50111","0.01756"
"23039","138.19800","11.51672","0.01835"
"23070","138.38400","11.53221","0.01764"
"23101","138.57000","11.54763","0.01788"
"23132","138.75600","11.56318","0.01820"
"23163","138.94200","11.57872","0.01827"
"23194","139.12800","11.59409","0.01801"
"23225","139.31400","11.60969","0.01820"
"23256","139.50000","11.62518","0.01848"
"23287","139.68600","11.64060","0.01812"
"23318","139.87200","11.65615","0.01843"
"23349","140.05800","11.67163","0.01904"
"23380","140.24400","11.68718","0.01898"
"23411","140.43000","11.70267","0.01868"
"23442","140.61600","11.71815","0.01890"
"23473","140.80200","11.73370","0.01891"
"23504","140.98800","11.74918","0.01888"
"23535","141.17400","11.76461","0.01908"
"23566","141.36000","11.78015","0.01945"
"23597","141.54600","11.79570","0.01916"
"23628","141.73200","11.81118","0.01921"
"23659","141.91800","11.82667","0.01967"
"23690","142.10400","11.84215","0.01985"
"23721","142.29000","11.85764","0.01897"
"23752","142.47600","11.87319","0.01984"
"23783","142.66200","11.88867","0.01975"
"23814","142.84800","11.90410","0.01942"
"23845","143.03400","11.91964","0.01972"
"23876","143.22000","11.93519","0.01962"
"23907","143.40600","11.95067","0.02004"
"23938","143.59200","11.96616","0.02035"
"23969","143.77800","11.98170","0.01981"
"24000","143.96400","11.99719","0.02067"
"24031","144.15000","12.01267","0.02099"
"24062","144.33600","12.02816","0.02071"
"24093","144.52200","12.04364","0.02064"
"24124","144.70800","12.05919","0.02037"
"24155","144.89400","12.07462","0.02075"
"24186","145.08000","12.09016","0.02127"
"24217","145.26600","12.10571","0.02085"
"24248","145.45200","12.12113","0.02109"
"24279","145.63800","12.13668","0.02114"
"24310","145.82400","12.15216","0.02105"
"24341","146.01000","12.16765","0.02181"
"24372","146.19600","12.18319","0.02147"
"24403","146.38200","12.19868","0.02104"
"24434","146.56800","12.21410","0.02202"
"24465","146.75400","12.22971","0.02221"
"24496","146.94000","12.24520","0.02194"
"24527","147.12600","12.26062","0.02290"
"24558","147.31200","12.27623","0.02243"
"24589","147.49800","12.29165","0.02254"
"24620","147.68400","12.30714","0.02220"
"24651","147.87000","12.32268","0.02293"
"24682","148.05600","12.33817","0.02286"
"24713","148.24200","12.35365","0.02256"
"24744","148.42800","12.36920","0.02302"
"24775","148.61400","12.38463","0.02326"
"24806","148.80000","12.40017","0.02326"
"24837","148.98600","12.41571","0.02392"
"24868","149.17200","12.43114","0.02402"
"24899","149.35800","12.44663","0.02464"
"24930","149.54400","12.46217","0.02430"
"24961","149.73000","12.47766","0.02461"
"24992","149.91600","12.49320","0.02505"
"25023","150.10200","12.50863","0.02489"
"25054","150.28800","12.52417","0.02544"
"25085","150.47400","12.53966","0.02512"
"25116","150.66000","12.55520","0.02574"
"25147","150.84600","12.57063","0.02531"
"25178","151.03200","12.58612","0.02604"
"25209","151.21800","12.60172","0.02588"
"25240","151.40400","12.61721","0.02647"
"25271","151.59000","12.63269","0.02556"
"25302","151.77600","12.64818","0.02661"
"25333","151.96200","12.66366","0.02662"
"25364","152.14800","12.67915","0.02628"
"25395","152.33400","12.69469","0.02726"
"25426","152.52000","12.71012","0.02711"
"25457","152.70600","12.72572","0.02739"
"25488","152.89200","12.74115","0.02802"
"25519","153.07800","12.75658","0.02810"
"25550","153.26400","12.77224","0.02803"
"25581","153.45000","12.78767","0.02893"
"25612","153.63600","12.80315","0.02909"
"25643","153.82200","12.81870","0.02932"
"25674","154.00800","12.83418","0.02966"
"25705","154.19400","12.84967","0.02999"
"25736","154.38000","12.86515","0.02976"
"25767","154.56600","12.88070","0.02979"
"25798","154.75200","12.89612","0.03060"
"25829","154.93800","12.91167","0.03011"
"25860","155.12400","12.92715","0.03089"
"25891","155.31000","12.94264","0.03109"
"25922","155.49600","12.95819","0.03123"
"25953","155.68200","12.97361","0.03128"
"25984","155.86800","12.98922","0.03218"
"26015","156.05400","13.00470","0.03273"
"26046","156.24000","13.02013","0.03267"
"26077","156.42600","13.03567","0.03288"
"26108","156.61200","13.05122","0.03293"
"26139","156.79800","13.06664","0.03273"
"26170","156.98400","13.08219","0.03343"
"26201","157.17000","13.09773","0.03288"
"26232","157.35600","13.11316","0.01923"
"26263","157.54200","13.12864","0.01950"
"26294","157.72800","13.14419","0.01457"
"26325","157.91400","13.15962","0.02164"
"26356","158.10000","13.17516","0.01384"
"26387","158.28600","13.19071","0.02059"
"26418","158.47200","13.20613","0.01600"
"26449","158.65800","13.22162","0.01891"
"26480","158.84400","13.23716","0.01740"
"26511","159.03000","13.25271","0.01789"
"26542","159.21600","13.26813","0.01911"
"26573","159.40200","13.28368","0.01681"
"26604","159.58800","13.29917","0.02032"
"26635","159.77400","13.31471","0.01767"
"26666","159.96000","13.33014","0.02049"
"26697","160.14600","13.34562","0.01718"
"26728","160.33200","13.36117","0.02036"
"26759","160.51800","13.37659","0.01842"
"26790","160.70400","13.39214","0.01998"
"26821","160.89000","13.40768","0.01827"
"26852","161.07600","13.42317","0.01933"
"26883","161.26200","13.43865","0.01851"
"26914","161.44800","13.45420","0.01881"
"26945","161.63400","13.46969","0.01999"
"26976","161.82000","13.48517","0.01878"
"27007","162.00600","13.50072","0.02007"
"27038","162.19200","13.51614","0.01887"
"27069","162.37800","13.53169","0.01985"
"27100","162.56400","13.54717","0.01857"
"27131","162.75000","13.56266","0.01932"
"27162","162.93600","13.57820","0.01824"
"27193","163.12200","13.59369","0.01978"
"27224","163.30800","13.60911","0.01868"
"27255","163.49400","13.62472","0.01924"
"27286","163.68000","13.64015","0.01950"
"27317","163.86600","13.65563","0.01832"
"27348","164.05200","13.67124","0.01875"
"27379","164.23800","13.68666","0.01923"
"27410","164.42400","13.70215","0.01885"
"27441","164.61000","13.71775","0.01891"
"27472","164.79600","13.73318","0.01884"
"27503","164.98200","13.74860","0.01954"
"27534","165.16800","13.76421","0.01942"
"27565","165.35400","13.77963","0.01908"
"27596","165.54000","13.79518","0.01930"
"27627","165.72600","13.81067","0.02029"
"27658","165.91200","13.82615","0.01998"
"27689","166.09800","13.84164","0.02039"
"27720","166.28400","13.85724","0.01954"
"27751","166.47000","13.87261","0.01982"
"27782","166.65600","13.88815","0.01999"
"27813","166.84200","13.90370","0.02030"
"27844","167.02800","13.91912","0.02090"
"27875","167.21400","13.93467","0.02033"
"27906","167.40000","13.95021","0.02048"
"27937","167.58600","13.96564","0.02067"
"27968","167.77200","13.98118","0.02010"
"27999","167.95800","13.99673","0.02058"
"28030","168.14400","14.01210","0.02022"
"28061","168.33000","14.02776","0.02064"
"28092","168.51600","14.04325","0.02035"
"28123","168.70200","14.05861","0.02013"
"28154","168.88800","14.07422","0.02027"
"28185","169.07400","14.08970","0.02022"
"28216","169.26000","14.10519","0.02090"
"28247","169.44600","14.12067","0.02077"
"28278","169.63200","14.13622","0.02145"
"28309","169.81800","14.15164","0.02022"
"28340","170.00400","14.16713","0.02070"
"28371","170.19000","14.18262","0.02121"
"28402","170.37600","14.19816","0.02122"
"28433","170.56200","14.21371","0.02122"
"28464","170.74800","14.22913","0.02058"
"28495","170.93400","14.24468","0.02111"
"28526","171.12000","14.26016","0.02149"
"28557","171.30600","14.27565","0.02171"
"28588","171.49200","14.29119","0.02138"
"28619","171.67800","14.30668","0.02200"
"28650","171.86400","14.32216","0.02216"
"28681","172.05000","14.33771","0.02190"
"28712","172.23600","14.35320","0.02208"
"28743","172.42200","14.36856","0.02205"
"28774","172.60800","14.38423","0.02271"
"28805","172.79400","14.39971","0.02214"
"28836","172.98000","14.41514","0.02251"
"28867","173.16600","14.43068","0.02220"
"28898","173.35200","14.44617","0.02292"
"28929","173.53800","14.46153","0.02258"
"28960","173.72400","14.47720","0.02253"
"28991","173.91000","14.49268","0.02304"
"29022","174.09600","14.50817","0.02262"
"29053","174.28200","14.52372","0.02321"
"29084","174.46800","14.53914","0.02322"
"29115","174.65400","14.55469","0.02195"
"29146","174.84000","14.57017","0.02277"
"29177","175.02600","14.58566","0.02308"
"29208","175.21200","14.60114","0.02317"
"29239","175.39800","14.61669","0.02390"
"29270","175.58400","14.63217","0.02418"
"29301","175.77000","14.64766","0.02368"
"29332","175.95600","14.66320","0.02351"
"29363","176.14200","14.67863","0.02318"
"29394","176.32800","14.69417","0.02362"
"29425","176.51400","14.70972","0.02417"
"29456","176.70000","14.72515","0.02445"
"29487","176.88600","14.74069","0.02434"
"29518","177.07200","14.75624","0.02501"
"29549","177.25800","14.77166","0.02497"
"29580","177.44400","14.78721","0.02470"
"29611","177.63000","14.80269","0.02538"
"29642","177.81600","14.81812","0.02483"
"29673","178.00200","14.83366","0.02471"
"29704","178.18800","14.84915","0.02445"
"29735","178.37400","14.86463","0.02542"
"29766","178.56000","14.88018","0.02509"
"29797","178.74600","14.89567","0.02552"
"29828","178.93200","14.91109","0.02555"
"29859","179.11800","14.92670","0.02507"
"29890","179.30400","14.94212","0.02543"
"29921","179.49000","14.95761","0.02591"
"29952","179.67600","14.97321","0.02633"
"29983","179.86200","14.98864","0.02626"
"30014","180.04800","15.00412","0.02580"
"30045","180.23400","15.01967","0.02631"
"30076","180.42000","15.03516","0.02637"
"30107","180.60600","15.05070","0.02647"
"30138","180.79200","15.06619","0.02643"
"30169","180.97800","15.08167","0.02677"
"30200","181.16400","15.09716","0.02727"
"30231","181.35000","15.11264","0.02752"
"30262","181.53600","15.12819","0.02695"
"30293","181.72200","15.14367","0.02791"
"30324","181.90800","15.15922","0.02793"
"30355","182.09400","15.17464","0.02848"
"30386","182.28000","15.19019","0.02844"
"30417","182.46600","15.20573","0.02896"
"30448","182.65200","15.22116","0.02939"
"30479","182.83800","15.23671","0.02918"
"30510","183.02400","15.25213","0.02935"
"30541","183.21000","15.26762","0.02888"
"30572","183.39600","15.28316","0.02971"
"30603","183.58200","15.29871","0.02954"
"30634","183.76800","15.31407","0.02975"
"30665","183.95400","15.32968","0.03003"
"30696","184.14000","15.34522","0.03022"
"30727","184.32600","15.36065","0.02957"
"30758","184.51200","15.37613","0.03060"
"30789","184.69800","15.39174","0.03014"
"30820","184.88400","15.40717","0.03119"
"30851","185.07000","15.42265","0.03176"
"30882","185.25600","15.43814","0.03099"
"30913","185.44200","15.45362","0.03155"
"30944","185.62800","15.46917","0.03137"
"30975","185.81400","15.48465","0.03156"
"31006","186.00000","15.50014","0.03225"
"31037","186.18600","15.51562","0.03188"
"31068","186.37200","15.53111","0.03235"
"31099","186.55800","15.54665","0.03252"
"31130","186.74400","15.56220","0.03213"
"31161","186.93000","15.57763","0.03265"
"31192","187.11600","15.59323","0.03156"
"31223","187.30200","15.60865","0.03295"
"31254","187.48800","15.62414","0.03312"
"31285","187.67400","15.63968","0.03354"
"31316","187.86000","15.65523","0.03398"
"31347","188.04600","15.67066","0.03323"
"31378","188.23200","15.68614","0.03328"
"31409","188.41800","15.70169","0.03410"
"31440","188.60400","15.71717","0.03407"
"31471","188.79000","15.73272","0.03480"
"31502","188.97600","15.74820","0.03495"
"31533","189.16200","15.76369","0.03525"
"31564","189.34800","15.77917","0.03561"
"31595","189.53400","15.79466","0.03584"
"31626","189.72000","15.81015","0.03624"
"31657","189.90600","15.82569","0.03367"
"31688","190.09200","15.84118","0.03637"
"31719","190.27800","15.85666","0.03411"
"31750","190.46400","15.87221","0.03484"
"31781","190.65000","15.88763","0.03597"
"31812","190.83600","15.90312","0.03536"
"31843","191.02200","15.91872","0.03569"
"31874","191.20800","15.93415","0.03812"
"31905","191.39400","15.94963","0.03674"
"31936","191.58000","15.96518","0.03742"
"31967","191.76600","15.98061","0.03916"
"31998","191.95200","15.99615","0.03799"
"32029","192.13800","16.01175","0.03935"
"32060","192.32400","16.02712","0.03951"
"32091","192.51000","16.04267","0.03958"
"32122","192.69600","16.05815","0.03979"
"32153","192.88200","16.07364","0.03676"
"32184","193.06800","16.08918","0.03715"
"32215","193.25400","16.10467","0.03724"
"32246","193.44000","16.12009","0.03784"
"32277","193.62600","16.13564","0.03883"
"32308","193.81200","16.15119","0.03891"
"32339","193.99800","16.16661","0.03911"
"32370","194.18400","16.18222","0.03925"
"32401","194.37000","16.19770","0.03833"
"32432","194.55600","16.21307","0.03982"
"32463","194.74200","16.22873","0.03849"
"32494","194.92800","16.24422","0.03888"
"32525","195.11400","16.25964","0.03961"
"32556","195.30000","16.27519","0.03961"
"32587","195.48600","16.29067","0.04058"
"32618","195.67200","16.30616","0.03998"
"32649","195.85800","16.32165","0.04022"
"32680","196.04400","16.33713","0.03959"
"32711","196.23000","16.35262","0.04136"
"32742","196.41600","16.36816","0.04100"
"32773","196.60200","16.38365","0.04157"
"32804","196.78800","16.39913","0.04280"
"32835","196.97400","16.41468","0.04251"
"32866","197.16000","16.43010","0.04223"
"32897","197.34600","16.44571","0.04316"
"32928","197.53200","16.46119","0.04303"
"32959","197.71800","16.47662","0.02764"
"32990","197.90400","16.49223","0.02977"
"33021","198.09000","16.50765","0.02582"
"33052","198.27600","16.52308","0.02778"
"33083","198.46200","16.53874","0.02749"
"33114","198.64800","16.55417","0.02530"
"33145","198.83400","16.56959","0.03062"
"33176","199.02000","16.58520","0.02572"
"33207","199.20600","16.60068","0.03106"
"33238","199.39200","16.61611","0.02422"
"33269","199.57800","16.63171","0.02984"
"33300","199.76400","16.64720","0.02854"
"33331","199.95000","16.66269","0.02851"
"33362","200.13600","16.67817","0.02923"
"33393","200.32200","16.69366","0.02581"
"33424","200.50800","16.70914","0.03201"
"33455","200.69400","16.72469","0.02645"
"33486","200.88000","16.74017","0.03334"
"33517","201.06600","16.75566","0.02622"
"33548","201.25200","16.77120","0.03389"
"33579","201.43800","16.78663","0.02881"
"33610","201.62400","16.80217","0.03254"
"33641","201.81000","16.81772","0.02934"
"33672","201.99600","16.83315","0.03195"
"33703","202.18200","16.84869","0.03349"
"33734","202.36800","16.86423","0.03077"
"33765","202.55400","16.87960","0.03416"
"33796","202.74000","16.89521","0.03185"
"33827","202.92600","16.91069","0.03640"
"33858","203.11200","16.92612","0.03074"
"33889","203.29800","16.94166","0.03615"
"33920","203.48400","16.95715","0.03361"
"33951","203.67000","16.97263","0.03537"
"33982","203.85600","16.98818","0.03310"
"34013","204.04200","17.00366","0.03471"
"34044","204.22800","17.01915","0.03458"
"34075","204.41400","17.03464","0.03445"
"34106","204.60000","17.05012","0.03510"
"34137","204.78600","17.06567","0.03417"
"34168","204.97200","17.08115","0.03696"
"34199","205.15800","17.09664","0.03487"
"34230","205.34400","17.11218","0.03749"
"34261","205.53000","17.12767","0.03593"
"34292","205.71600","17.14315","0.03850"
"34323","205.90200","17.15870","0.03758"
"34354","206.08800","17.17418","0.03803"
"34385","206.27400","17.18967","0.03738"
"34416","206.46000","17.20515","0.03733"
"34447","206.64600","17.22064","0.03777"
"34478","206.83200","17.23613","0.03750"
"34509","207.01800","17.25173","0.03922"
"34540","207.20400","17.26722","0.03771"
"34571","207.39000","17.28264","0.03843"
"34602","207.57600","17.29819","0.03938"
"34633","207.76200","17.31367","0.03914"
"34664","207.94800","17.32916","0.03922"
"34695","208.13400","17.34470","0.03970"
"34726","208.32000","17.36013","0.04011"
"34757","208.50600","17.37562","0.04091"
"34788","208.69200","17.39122","0.04112"
"34819","208.87800","17.40665","0.04098"
"34850","209.06400","17.42213","0.04102"
"34881","209.25000","17.43768","0.04110"
"34912","209.43600","17.45316","0.04130"
"34943","209.62200","17.46859","0.04186"
"34974","209.80800","17.48419","0.04084"
"35005","209.99400","17.49968","0.04169"
"35036","210.18000","17.51516","0.04284"
"35067","210.36600","17.53071","0.04281"
"35098","210.55200","17.54620","0.04266"
"35129","210.73800","17.56168","0.04255"
"35160","210.92400","17.57717","0.04434"
"35191","211.11000","17.59265","0.04336"
"35222","211.29600","17.60820","0.04461"
"35253","211.48200","17.62362","0.04455"
"35284","211.66800","17.63917","0.04406"
"35315","211.85400","17.65465","0.04588"
"35346","212.04000","17.67014","0.04484"
"35377","212.22600","17.68568","0.04729"
"35408","212.41200","17.70117","0.04482"
"35439","212.59800","17.71671","0.04642"
"35470","212.78400","17.73214","0.04708"
"35501","212.97000","17.74775","0.04730"
"35532","213.15600","17.76317","0.04732"
"35563","213.34200","17.77860","0.04853"
"35594","213.52800","17.79420","0.04858"
"35625","213.71400","17.80969","0.04758"
"35656","213.90000","17.82517","0.04834"
"35687","214.08600","17.84066","0.04781"
"35718","214.27200","17.85614","0.04766"
"35749","214.45800","17.87169","0.04795"
"35780","214.64400","17.88717","0.04833"
"35811","214.83000","17.90266","0.04829"
"35842","215.01600","17.91815","0.04827"
"35873","215.20200","17.93363","0.04941"
"35904","215.38800","17.94918","0.04937"
"35935","215.57400","17.96466","0.04981"
"35966","215.76000","17.98015","0.05035"
"35997","215.94600","17.99563","0.05018"
"36028","216.13200","18.01124","0.05076"
"36059","216.31800","18.02666","0.05103"
"36090","216.50400","18.04215","0.05136"
"36121","216.69000","18.05770","0.05204"
"36152","216.87600","18.07318","0.05275"
"36183","217.06200","18.08867","0.05253"
"36214","217.24800","18.10415","0.05278"
"36245","217.43400","18.11970","0.05374"
"36276","217.62000","18.13512","0.05426"
"36307","217.80600","18.15067","0.05441"
"36338","217.99200","18.16621","0.05469"
"36369","218.17800","18.18164","0.05451"
"36400","218.36400","18.19718","0.05504"
"36431","218.55000","18.21267","0.05604"
"36462","218.73600","18.22816","0.05609"
"36493","218.92200","18.24364","0.05654"
"36524","219.10800","18.25918","0.05603"
"36555","219.29400","18.27467","0.05648"
"36586","219.48000","18.29016","0.05736"
"36617","219.66600","18.30564","0.05749"
"36648","219.85200","18.32113","0.05799"
"36679","220.03800","18.33667","0.05846"
"36710","220.22400","18.35216","0.05848"
"36741","220.41000","18.36765","0.05812"
"36772","220.59600","18.38319","0.05899"
"36803","220.78200","18.39867","0.05879"
"36834","220.96800","18.41416","0.05949"
"36865","221.15400","18.42971","0.05981"
"36896","221.34000","18.44513","0.06043"
"36927","221.52600","18.46068","0.06043"
"36958","221.71200","18.47622","0.06097"
"36989","221.89800","18.49165","0.06223"
"37020","222.08400","18.50725","0.06214"
"37051","222.27000","18.52268","0.06295"
"37082","222.45600","18.53816","0.06274"
"37113","222.64200","18.55365","0.06337"
"37144","222.82800","18.56919","0.06385"
"37175","223.01400","18.58468","0.06400"
"37206","223.20000","18.60017","0.06467"
"37237","223.38600","18.61571","0.06521"
"37268","223.57200","18.63114","0.06484"
"37299","223.75800","18.64674","0.06508"
"37330","223.94400","18.66217","0.06508"
"37361","224.13000","18.67759","0.06574"
"37392","224.31600","18.69320","0.06636"
"37423","224.50200","18.70868","0.02893"
"37454","224.68800","18.72405","0.01508"
"37485","224.87400","18.73971","0.02079"
"37516","225.06000","18.75520","0.01616"
"37547","225.24600","18.77063","0.01632"
"37578","225.43200","18.78623","0.01733"
"37609","225.61800","18.80172","0.01605"
"37640","225.80400","18.81714","0.01582"
"37671","225.99000","18.83269","0.01641"
"37702","226.17600","18.84811","0.01694"
"37733","226.36200","18.86366","0.01611"
"37764","226.54800","18.87920","0.01591"
"37795","226.73400","18.89469","0.01640"
"37826","226.92000","18.91017","0.01566"
"37857","227.10600","18.92572","0.01617"
"37888","227.29200","18.94114","0.01611"
"37919","227.47800","18.95669","0.01670"
"37950","227.66400","18.97223","0.01727"
"37981","227.85000","18.98766","0.01627"
"38012","228.03600","19.00321","0.01560"
"38043","228.22200","19.01869","0.01611"
"38074","228.40800","19.03406","0.01651"
"38105","228.59400","19.04972","0.01640"
"38136","228.78000","19.06521","0.01640"
"38167","228.96600","19.08057","0.01655"
"38198","229.15200","19.09618","0.01665"
"38229","229.33800","19.11167","0.01626"
"38260","229.52400","19.12715","0.01629"
"38291","229.71000","19.14269","0.01593"
"38322","229.89600","19.15818","0.01605"
"38353","230.08200","19.17367","0.01631"
"38384","230.26800","19.18921","0.01713"
"38415","230.45400","19.20470","0.01646"
"38446","230.64000","19.22012","0.01678"
"38477","230.82600","19.23567","0.01648"
"38508","231.01200","19.25115","0.01593"
"38539","231.19800","19.26670","0.01614"
"38570","231.38400","19.28218","0.01676"
"38601","231.57000","19.29761","0.01658"
"38626","231.72000","19.31017","0.01642"