File: Trajectories_together/170108_1Specimen_RawData_4.csv
"","V1","V2","V3"
"1","End date","1/8/2017",""
"2","Specimen label","11AT_86",""
"3","Maximum Load","0.17094","N"
"4","Time","Extension","Load"
"5","(s)","(mm)","(N)"
"6","0.00000","0.00000","-0.00013"
"40","0.20400","0.01441","0.00017"
"74","0.40800","0.03408","0.00039"
"108","0.61200","0.05124","0.00018"
"142","0.81600","0.06816","0.00073"
"176","1.02000","0.08508","0.00058"
"210","1.22400","0.10218","0.00032"
"244","1.42800","0.11910","0.00061"
"278","1.63200","0.13614","0.00041"
"312","1.83600","0.15312","0.00057"
"346","2.04000","0.17010","0.00029"
"380","2.24400","0.18714","0.00085"
"414","2.44800","0.20412","0.00031"
"448","2.65200","0.22110","0.00036"
"482","2.85600","0.23814","0.00046"
"516","3.06000","0.25512","0.00075"
"550","3.26400","0.27210","0.00088"
"584","3.46800","0.28914","0.00110"
"618","3.67200","0.30606","0.00090"
"652","3.87600","0.32310","0.00048"
"686","4.08000","0.34014","0.00032"
"720","4.28400","0.35706","0.00089"
"754","4.48800","0.37416","0.00103"
"788","4.69200","0.39108","0.00064"
"822","4.89600","0.40806","0.00065"
"856","5.10000","0.42516","0.00092"
"890","5.30400","0.44208","0.00089"
"924","5.50800","0.45912","0.00123"
"958","5.71200","0.47610","0.00106"
"992","5.91600","0.49308","0.00093"
"1026","6.12000","0.51012","0.00090"
"1060","6.32400","0.52710","0.00112"
"1094","6.52800","0.54403","0.00119"
"1128","6.73200","0.56112","0.00127"
"1162","6.93600","0.57810","0.00114"
"1196","7.14000","0.59515","0.00137"
"1230","7.34400","0.61213","0.00078"
"1264","7.54800","0.62911","0.00104"
"1298","7.75200","0.64615","0.00108"
"1332","7.95600","0.66307","0.00134"
"1366","8.16000","0.68011","0.00099"
"1400","8.36400","0.69715","0.00102"
"1434","8.56800","0.71407","0.00175"
"1468","8.77200","0.73111","0.00137"
"1502","8.97600","0.74815","0.00177"
"1536","9.18000","0.76513","0.00184"
"1570","9.38400","0.78217","0.00185"
"1604","9.58800","0.79909","0.00168"
"1638","9.79200","0.81619","0.00155"
"1672","9.99600","0.83311","0.00161"
"1706","10.20000","0.85003","0.00168"
"1740","10.40400","0.86713","0.00130"
"1774","10.60800","0.88411","0.00192"
"1808","10.81200","0.90115","0.00172"
"1842","11.01600","0.91813","0.00196"
"1876","11.22000","0.93511","0.00213"
"1910","11.42400","0.95215","0.00193"
"1944","11.62800","0.96913","0.00190"
"1978","11.83200","0.98611","0.00221"
"2012","12.03600","1.00315","0.00222"
"2046","12.24000","1.02013","0.00205"
"2080","12.44400","1.03705","0.00180"
"2114","12.64800","1.05415","0.00193"
"2148","12.85200","1.07107","0.00220"
"2182","13.05600","1.08817","0.00199"
"2216","13.26000","1.10515","0.00181"
"2250","13.46400","1.12207","0.00219"
"2284","13.66800","1.13917","0.00199"
"2318","13.87200","1.15609","0.00228"
"2352","14.07600","1.17313","0.00254"
"2386","14.28000","1.19017","0.00222"
"2420","14.48400","1.20703","0.00221"
"2454","14.68800","1.22419","0.00193"
"2488","14.89200","1.24111","0.00269"
"2522","15.09600","1.25809","0.00224"
"2556","15.30000","1.27513","0.00271"
"2590","15.50400","1.29211","0.00280"
"2624","15.70800","1.30909","0.00195"
"2658","15.91200","1.32613","0.00243"
"2692","16.11600","1.34311","0.00239"
"2726","16.32000","1.36015","0.00273"
"2760","16.52400","1.37713","0.00284"
"2794","16.72800","1.39411","0.00247"
"2828","16.93200","1.41109","0.00230"
"2862","17.13600","1.42807","0.00238"
"2896","17.34000","1.44511","0.00255"
"2930","17.54400","1.46215","0.00239"
"2964","17.74800","1.47907","0.00271"
"2998","17.95200","1.49611","0.00246"
"3032","18.15600","1.51309","0.00278"
"3066","18.36000","1.53007","0.00286"
"3100","18.56400","1.54717","0.00286"
"3134","18.76800","1.56403","0.00300"
"3168","18.97200","1.58113","0.00293"
"3202","19.17600","1.59811","0.00353"
"3236","19.38000","1.61503","0.00311"
"3270","19.58400","1.63213","0.00299"
"3304","19.78800","1.64911","0.00296"
"3338","19.99200","1.66615","0.00301"
"3372","20.19600","1.68314","0.00350"
"3406","20.40000","1.70006","0.00360"
"3440","20.60400","1.71716","0.00308"
"3474","20.80800","1.73408","0.00346"
"3508","21.01200","1.75112","0.00376"
"3542","21.21600","1.76816","0.00305"
"3576","21.42000","1.78508","0.00370"
"3610","21.62400","1.80212","0.00364"
"3644","21.82800","1.81916","0.00332"
"3678","22.03200","1.83608","0.00304"
"3712","22.23600","1.85312","0.00309"
"3746","22.44000","1.87016","0.00301"
"3780","22.64400","1.88708","0.00345"
"3814","22.84800","1.90418","0.00281"
"3848","23.05200","1.92110","0.00328"
"3882","23.25600","1.93814","0.00289"
"3916","23.46000","1.95512","0.00346"
"3950","23.66400","1.97204","0.00372"
"3984","23.86800","1.98920","0.00350"
"4018","24.07200","2.00612","0.00337"
"4052","24.27600","2.02310","0.00360"
"4086","24.48000","2.04014","0.00405"
"4120","24.68400","2.05706","0.00389"
"4154","24.88800","2.07416","0.00378"
"4188","25.09200","2.09108","0.00376"
"4222","25.29600","2.10812","0.00420"
"4256","25.50000","2.12510","0.00349"
"4290","25.70400","2.14208","0.00400"
"4324","25.90800","2.15912","0.00447"
"4358","26.11200","2.17610","0.00448"
"4392","26.31600","2.19308","0.00387"
"4426","26.52000","2.21012","0.00414"
"4460","26.72400","2.22716","0.00300"
"4494","26.92800","2.24408","0.00306"
"4528","27.13200","2.26112","0.00371"
"4562","27.33600","2.27810","0.00405"
"4596","27.54000","2.29514","0.00401"
"4630","27.74400","2.31218","0.00367"
"4664","27.94800","2.32904","0.00344"
"4698","28.15200","2.34614","0.00389"
"4732","28.35600","2.36312","0.00437"
"4766","28.56000","2.38010","0.00368"
"4800","28.76400","2.39714","0.00370"
"4834","28.96800","2.41412","0.00374"
"4868","29.17200","2.43116","0.00411"
"4902","29.37600","2.44808","0.00427"
"4936","29.58000","2.46506","0.00400"
"4970","29.78400","2.48210","0.00408"
"5004","29.98800","2.49908","0.00409"
"5038","30.19200","2.51618","0.00400"
"5072","30.39600","2.53316","0.00418"
"5106","30.60000","2.55008","0.00416"
"5140","30.80400","2.56712","0.00462"
"5174","31.00800","2.58416","0.00417"
"5208","31.21200","2.60108","0.00458"
"5242","31.41600","2.61806","0.00504"
"5276","31.62000","2.63510","0.00425"
"5310","31.82400","2.65208","0.00433"
"5344","32.02800","2.66912","0.00439"
"5378","32.23200","2.68610","0.00459"
"5412","32.43600","2.70314","0.00443"
"5446","32.64000","2.72012","0.00391"
"5480","32.84400","2.73710","0.00377"
"5514","33.04800","2.75414","0.00391"
"5548","33.25200","2.77107","0.00388"
"5582","33.45600","2.78811","0.00438"
"5616","33.66000","2.80509","0.00376"
"5650","33.86400","2.82201","0.00473"
"5684","34.06800","2.83917","0.00451"
"5718","34.27200","2.85603","0.00439"
"5752","34.47600","2.87313","0.00389"
"5786","34.68000","2.89011","0.00208"
"5820","34.88400","2.90709","0.00256"
"5854","35.08800","2.92413","0.00304"
"5888","35.29200","2.94111","0.00275"
"5922","35.49600","2.95809","0.00277"
"5956","35.70000","2.97513","0.00250"
"5990","35.90400","2.99211","0.00291"
"6024","36.10800","3.00909","0.00315"
"6058","36.31200","3.02613","0.00301"
"6092","36.51600","3.04305","0.00271"
"6126","36.72000","3.06015","0.00371"
"6160","36.92400","3.07719","0.00285"
"6194","37.12800","3.09405","0.00326"
"6228","37.33200","3.11115","0.00318"
"6262","37.53600","3.12813","0.00311"
"6296","37.74000","3.14511","0.00365"
"6330","37.94400","3.16215","0.00303"
"6364","38.14800","3.17907","0.00337"
"6398","38.35200","3.19617","0.00395"
"6432","38.55600","3.21309","0.00398"
"6466","38.76000","3.23007","0.00384"
"6500","38.96400","3.24717","0.00353"
"6534","39.16800","3.26409","0.00410"
"6568","39.37200","3.28113","0.00370"
"6602","39.57600","3.29817","0.00410"
"6636","39.78000","3.31503","0.00374"
"6670","39.98400","3.33213","0.00441"
"6704","40.18800","3.34911","0.00393"
"6738","40.39200","3.36609","0.00341"
"6772","40.59600","3.38313","0.00334"
"6806","40.80000","3.40011","0.00300"
"6840","41.00400","3.41715","0.00335"
"6874","41.20800","3.43413","0.00349"
"6908","41.41200","3.45111","0.00404"
"6942","41.61600","3.46815","0.00422"
"6976","41.82000","3.48513","0.00331"
"7010","42.02400","3.50211","0.00267"
"7044","42.22800","3.51915","0.00320"
"7078","42.43200","3.53607","0.00293"
"7112","42.63600","3.55311","0.00319"
"7146","42.84000","3.57009","0.00317"
"7180","43.04400","3.58707","0.00328"
"7214","43.24800","3.60417","0.00336"
"7248","43.45200","3.62109","0.00292"
"7282","43.65600","3.63813","0.00349"
"7316","43.86000","3.65517","0.00364"
"7350","44.06400","3.67209","0.00364"
"7384","44.26800","3.68919","0.00379"
"7418","44.47200","3.70605","0.00411"
"7452","44.67600","3.72309","0.00365"
"7486","44.88000","3.74013","0.00397"
"7520","45.08400","3.75711","0.00442"
"7554","45.28800","3.77415","0.00436"
"7588","45.49200","3.79113","0.00430"
"7622","45.69600","3.80812","0.00384"
"7656","45.90000","3.82515","0.00453"
"7690","46.10400","3.84214","0.00465"
"7724","46.30800","3.85912","0.00417"
"7758","46.51200","3.87616","0.00498"
"7792","46.71600","3.89308","0.00486"
"7826","46.92000","3.91012","0.00433"
"7860","47.12400","3.92716","0.00595"
"7894","47.32800","3.94408","0.00525"
"7928","47.53200","3.96112","0.00555"
"7962","47.73600","3.97810","0.00522"
"7996","47.94000","3.99508","0.00531"
"8030","48.14400","4.01218","0.00532"
"8064","48.34800","4.02910","0.00435"
"8098","48.55200","4.04614","0.00477"
"8132","48.75600","4.06312","0.00533"
"8166","48.96000","4.08004","0.00524"
"8200","49.16400","4.09714","0.00608"
"8234","49.36800","4.11412","0.00593"
"8268","49.57200","4.13110","0.00617"
"8302","49.77600","4.14814","0.00614"
"8336","49.98000","4.16512","0.00569"
"8370","50.18400","4.18216","0.00590"
"8404","50.38800","4.19914","0.00640"
"8438","50.59200","4.21612","0.00659"
"8472","50.79600","4.23310","0.00707"
"8506","51.00000","4.25014","0.00700"
"8540","51.20400","4.26706","0.00644"
"8574","51.40800","4.28410","0.00635"
"8608","51.61200","4.30108","0.00719"
"8642","51.81600","4.31812","0.00766"
"8676","52.02000","4.33516","0.00729"
"8710","52.22400","4.35208","0.00715"
"8744","52.42800","4.36918","0.00781"
"8778","52.63200","4.38610","0.00803"
"8812","52.83600","4.40314","0.00794"
"8846","53.04000","4.42012","0.00817"
"8880","53.24400","4.43704","0.00803"
"8914","53.44800","4.45414","0.00848"
"8948","53.65200","4.47106","0.00859"
"8982","53.85600","4.48816","0.00870"
"9016","54.06000","4.50514","0.00887"
"9050","54.26400","4.52206","0.00925"
"9084","54.46800","4.53916","0.00913"
"9118","54.67200","4.55614","0.00978"
"9152","54.87600","4.57312","0.00993"
"9186","55.08000","4.59010","0.01045"
"9220","55.28400","4.60714","0.01029"
"9254","55.48800","4.62406","0.01091"
"9288","55.69200","4.64116","0.01068"
"9322","55.89600","4.65808","0.01113"
"9356","56.10000","4.67512","0.01108"
"9390","56.30400","4.69216","0.01140"
"9424","56.50800","4.70908","0.01029"
"9458","56.71200","4.72612","0.01114"
"9492","56.91600","4.74310","0.01187"
"9526","57.12000","4.76014","0.01218"
"9560","57.32400","4.77712","0.01221"
"9594","57.52800","4.79404","0.00977"
"9628","57.73200","4.81114","0.00998"
"9662","57.93600","4.82812","0.01044"
"9696","58.14000","4.84510","0.01109"
"9730","58.34400","4.86214","0.01065"
"9764","58.54800","4.87913","0.01161"
"9798","58.75200","4.89611","0.01119"
"9832","58.95600","4.91308","0.01132"
"9866","59.16000","4.93007","0.01177"
"9900","59.36400","4.94711","0.01227"
"9934","59.56800","4.96409","0.01224"
"9968","59.77200","4.98113","0.01265"
"10002","59.97600","4.99811","0.01143"
"10036","60.18000","5.01509","0.01177"
"10070","60.38400","5.03213","0.01208"
"10104","60.58800","5.04917","0.01260"
"10138","60.79200","5.06609","0.01280"
"10172","60.99600","5.08313","0.01247"
"10206","61.20000","5.10011","0.01381"
"10240","61.40400","5.11709","0.01324"
"10274","61.60800","5.13419","0.01443"
"10308","61.81200","5.15105","0.01384"
"10342","62.01600","5.16815","0.01461"
"10376","62.22000","5.18513","0.01463"
"10410","62.42400","5.20205","0.01487"
"10444","62.62800","5.21915","0.01523"
"10478","62.83200","5.23613","0.01567"
"10512","63.03600","5.25317","0.01617"
"10546","63.24000","5.27015","0.01590"
"10580","63.44400","5.28707","0.01628"
"10614","63.64800","5.30417","0.01635"
"10648","63.85200","5.32109","0.01674"
"10682","64.05600","5.33813","0.01680"
"10716","64.26000","5.35517","0.01741"
"10750","64.46400","5.37209","0.01817"
"10784","64.66800","5.38913","0.01830"
"10818","64.87200","5.40617","0.01904"
"10852","65.07600","5.42309","0.01939"
"10886","65.28000","5.44013","0.01943"
"10920","65.48400","5.45711","0.01957"
"10954","65.68800","5.47409","0.02045"
"10988","65.89200","5.49113","0.02106"
"11022","66.09600","5.50805","0.02130"
"11056","66.30000","5.52509","0.02138"
"11090","66.50400","5.54213","0.02229"
"11124","66.70800","5.55905","0.02227"
"11158","66.91200","5.57615","0.02346"
"11192","67.11600","5.59307","0.02339"
"11226","67.32000","5.61011","0.02408"
"11260","67.52400","5.62715","0.02408"
"11294","67.72800","5.64407","0.02462"
"11328","67.93200","5.66117","0.02503"
"11362","68.13600","5.67809","0.02565"
"11396","68.34000","5.69507","0.02568"
"11430","68.54400","5.71211","0.02639"
"11464","68.74800","5.72909","0.02714"
"11498","68.95200","5.74613","0.02758"
"11532","69.15600","5.76311","0.02834"
"11566","69.36000","5.78009","0.02836"
"11600","69.56400","5.79713","0.02921"
"11634","69.76800","5.81411","0.02977"
"11668","69.97200","5.83109","0.03037"
"11702","70.17600","5.84807","0.03042"
"11736","70.38000","5.86505","0.03120"
"11770","70.58400","5.88215","0.03179"
"11804","70.78800","5.89919","0.03165"
"11838","70.99200","5.91599","0.03236"
"11872","71.19600","5.93315","0.03240"
"11906","71.40000","5.95014","0.03252"
"11940","71.60400","5.96706","0.03280"
"11974","71.80800","5.98416","0.02470"
"12008","72.01200","6.00108","0.02683"
"12042","72.21600","6.01812","0.02764"
"12076","72.42000","6.03510","0.02836"
"12110","72.62400","6.05202","0.02837"
"12144","72.82800","6.06912","0.02886"
"12178","73.03200","6.08610","0.02976"
"12212","73.23600","6.10314","0.02989"
"12246","73.44000","6.12012","0.03046"
"12280","73.64400","6.13710","0.03105"
"12314","73.84800","6.15414","0.03166"
"12348","74.05200","6.17112","0.03131"
"12382","74.25600","6.18810","0.03178"
"12416","74.46000","6.20508","0.03231"
"12450","74.66400","6.22212","0.03259"
"12484","74.86800","6.23910","0.03279"
"12518","75.07200","6.25614","0.03307"
"12552","75.27600","6.27306","0.03328"
"12586","75.48000","6.29010","0.03370"
"12620","75.68400","6.30714","0.03394"
"12654","75.88800","6.32412","0.03426"
"12688","76.09200","6.34116","0.03459"
"12722","76.29600","6.35814","0.03470"
"12756","76.50000","6.37512","0.03476"
"12790","76.70400","6.39210","0.03491"
"12824","76.90800","6.40902","0.03529"
"12858","77.11200","6.42618","0.03545"
"12892","77.31600","6.44310","0.03551"
"12926","77.52000","6.46014","0.03611"
"12960","77.72400","6.47712","0.03616"
"12994","77.92800","6.49404","0.03642"
"13028","78.13200","6.51114","0.03644"
"13062","78.33600","6.52812","0.03672"
"13096","78.54000","6.54510","0.03706"
"13130","78.74400","6.56208","0.03699"
"13164","78.94800","6.57912","0.03751"
"13198","79.15200","6.59610","0.03761"
"13232","79.35600","6.61314","0.03842"
"13266","79.56000","6.63006","0.03865"
"13300","79.76400","6.64716","0.03888"
"13334","79.96800","6.66414","0.03901"
"13368","80.17200","6.68106","0.03893"
"13402","80.37600","6.69816","0.04007"
"13436","80.58000","6.71514","0.04102"
"13470","80.78400","6.73206","0.04033"
"13504","80.98800","6.74910","0.04256"
"13538","81.19200","6.76602","0.04255"
"13572","81.39600","6.78312","0.04300"
"13606","81.60000","6.80016","0.04441"
"13640","81.80400","6.81708","0.04558"
"13674","82.00800","6.83412","0.04613"
"13708","82.21200","6.85110","0.04664"
"13742","82.41600","6.86814","0.04802"
"13776","82.62000","6.88512","0.04901"
"13810","82.82400","6.90204","0.04990"
"13844","83.02800","6.91908","0.05023"
"13878","83.23200","6.93606","0.05173"
"13912","83.43600","6.95310","0.05327"
"13946","83.64000","6.97014","0.05348"
"13980","83.84400","6.98712","0.05433"
"14014","84.04800","7.00416","0.05542"
"14048","84.25200","7.02108","0.05608"
"14082","84.45600","7.03813","0.05723"
"14116","84.66000","7.05511","0.05816"
"14150","84.86400","7.07214","0.05904"
"14184","85.06800","7.08913","0.05963"
"14218","85.27200","7.10611","0.06060"
"14252","85.47600","7.12309","0.06064"
"14286","85.68000","7.14013","0.06119"
"14320","85.88400","7.15711","0.06041"
"14354","86.08800","7.17409","0.06123"
"14388","86.29200","7.19119","0.06162"
"14422","86.49600","7.20805","0.06186"
"14456","86.70000","7.22515","0.06355"
"14490","86.90400","7.24219","0.06392"
"14524","87.10800","7.25905","0.06433"
"14558","87.31200","7.27621","0.06517"
"14592","87.51600","7.29307","0.06645"
"14626","87.72000","7.31011","0.06764"
"14660","87.92400","7.32715","0.06837"
"14694","88.12800","7.34413","0.06872"
"14728","88.33200","7.36111","0.06904"
"14762","88.53600","7.37815","0.06972"
"14796","88.74000","7.39507","0.07054"
"14830","88.94400","7.41217","0.07113"
"14864","89.14800","7.42909","0.07157"
"14898","89.35200","7.44613","0.07239"
"14932","89.55600","7.46311","0.07064"
"14966","89.76000","7.48009","0.07114"
"15000","89.96400","7.49707","0.07177"
"15034","90.16800","7.51423","0.07197"
"15068","90.37200","7.53103","0.07279"
"15102","90.57600","7.54813","0.07344"
"15136","90.78000","7.56511","0.07418"
"15170","90.98400","7.58209","0.07479"
"15204","91.18800","7.59919","0.07526"
"15238","91.39200","7.61605","0.07637"
"15272","91.59600","7.63315","0.07639"
"15306","91.80000","7.65013","0.07767"
"15340","92.00400","7.66705","0.07748"
"15374","92.20800","7.68415","0.07839"
"15408","92.41200","7.70113","0.07903"
"15442","92.61600","7.71805","0.07912"
"15476","92.82000","7.73515","0.08001"
"15510","93.02400","7.75207","0.08085"
"15544","93.22800","7.76917","0.08094"
"15578","93.43200","7.78609","0.08129"
"15612","93.63600","7.80313","0.08174"
"15646","93.84000","7.82005","0.08200"
"15680","94.04400","7.83709","0.08238"
"15714","94.24800","7.85413","0.08247"
"15748","94.45200","7.87117","0.04003"
"15782","94.65600","7.88809","0.03793"
"15816","94.86000","7.90513","0.03904"
"15850","95.06400","7.92217","0.03878"
"15884","95.26800","7.93909","0.04190"
"15918","95.47200","7.95613","0.04108"
"15952","95.67600","7.97305","0.04369"
"15986","95.88000","7.99015","0.04535"
"16020","96.08400","8.00713","0.04648"
"16054","96.28800","8.02405","0.04995"
"16088","96.49200","8.04115","0.04835"
"16122","96.69600","8.05813","0.05326"
"16156","96.90000","8.07511","0.05243"
"16190","97.10400","8.09215","0.05540"
"16224","97.30800","8.10907","0.05843"
"16258","97.51200","8.12617","0.05843"
"16292","97.71600","8.14310","0.06195"
"16326","97.92000","8.16013","0.06045"
"16360","98.12400","8.17712","0.06296"
"16394","98.32800","8.19410","0.06309"
"16428","98.53200","8.21108","0.06419"
"16462","98.73600","8.22818","0.06537"
"16496","98.94000","8.24510","0.06578"
"16530","99.14400","8.26208","0.06819"
"16564","99.34800","8.27918","0.06793"
"16598","99.55200","8.29610","0.07071"
"16632","99.75600","8.31314","0.07117"
"16666","99.96000","8.33012","0.07358"
"16700","100.16400","8.34710","0.07410"
"16734","100.36800","8.36414","0.07584"
"16768","100.57200","8.38106","0.07674"
"16802","100.77600","8.39816","0.07671"
"16836","100.98000","8.41514","0.07849"
"16870","101.18400","8.43212","0.07843"
"16904","101.38800","8.44916","0.07999"
"16938","101.59200","8.46608","0.08019"
"16972","101.79600","8.48312","0.08101"
"17006","102.00000","8.50016","0.08163"
"17040","102.20400","8.51708","0.08230"
"17074","102.40800","8.53412","0.08253"
"17108","102.61200","8.55110","0.08158"
"17142","102.81600","8.56814","0.08217"
"17176","103.02000","8.58512","0.08231"
"17210","103.22400","8.60210","0.08302"
"17244","103.42800","8.61908","0.08318"
"17278","103.63200","8.63618","0.08380"
"17312","103.83600","8.65304","0.08375"
"17346","104.04000","8.67008","0.08470"
"17380","104.24400","8.68712","0.08496"
"17414","104.44800","8.70410","0.08605"
"17448","104.65200","8.72114","0.08640"
"17482","104.85600","8.73806","0.08769"
"17516","105.06000","8.75516","0.08888"
"17550","105.26400","8.77214","0.09060"
"17584","105.46800","8.78900","0.09139"
"17618","105.67200","8.80616","0.09274"
"17652","105.87600","8.82314","0.09573"
"17686","106.08000","8.84012","0.09708"
"17720","106.28400","8.85716","0.10001"
"17754","106.48800","8.87408","0.10181"
"17788","106.69200","8.89118","0.10582"
"17822","106.89600","8.90810","0.10725"
"17856","107.10000","8.92514","0.11195"
"17890","107.30400","8.94212","0.11328"
"17924","107.50800","8.95910","0.11751"
"17958","107.71200","8.97608","0.11873"
"17992","107.91600","8.99312","0.12287"
"18026","108.12000","9.01010","0.12433"
"18060","108.32400","9.02714","0.13024"
"18094","108.52800","9.04412","0.13039"
"18128","108.73200","9.06110","0.13583"
"18162","108.93600","9.07808","0.13582"
"18196","109.14000","9.09512","0.13848"
"18230","109.34400","9.11216","0.13893"
"18264","109.54800","9.12914","0.14074"
"18298","109.75200","9.14606","0.14091"
"18332","109.95600","9.16316","0.14251"
"18366","110.16000","9.18014","0.14288"
"18400","110.36400","9.19707","0.14366"
"18434","110.56800","9.21416","0.14363"
"18468","110.77200","9.23103","0.14440"
"18502","110.97600","9.24813","0.14492"
"18536","111.18000","9.26511","0.14618"
"18570","111.38400","9.28209","0.14666"
"18604","111.58800","9.29913","0.14946"
"18638","111.79200","9.31605","0.14961"
"18672","111.99600","9.33309","0.15339"
"18706","112.20000","9.35007","0.15424"
"18740","112.40400","9.36705","0.15199"
"18774","112.60800","9.38415","0.15031"
"18808","112.81200","9.40113","0.15333"
"18842","113.01600","9.41811","0.15463"
"18876","113.22000","9.43509","0.15703"
"18910","113.42400","9.45207","0.15836"
"18944","113.62800","9.46911","0.16007"
"18978","113.83200","9.48615","0.16148"
"19012","114.03600","9.50313","0.16395"
"19046","114.24000","9.52017","0.16547"
"19080","114.44400","9.53715","0.16736"
"19114","114.64800","9.55407","0.16880"
"19148","114.85200","9.57117","0.17016"
"19182","115.05600","9.58809","0.04841"
"19216","115.26000","9.60513","0.01241"
"19250","115.46400","9.62211","0.02068"
"19284","115.66800","9.63903","0.02183"
"19318","115.87200","9.65613","0.01564"
"19352","116.07600","9.67311","0.02029"
"19386","116.28000","9.69009","0.01636"
"19420","116.48400","9.70713","0.02648"
"19454","116.68800","9.72405","0.02690"
"19488","116.89200","9.74115","0.02227"
"19522","117.09600","9.75813","0.02638"
"19556","117.30000","9.77511","0.03213"
"19590","117.50400","9.79209","0.02298"
"19624","117.70800","9.80907","0.03375"
"19658","117.91200","9.82611","0.03024"
"19692","118.11600","9.84315","0.03026"
"19726","118.32000","9.86007","0.03562"
"19760","118.52400","9.87711","0.02873"
"19794","118.72800","9.89415","0.03809"
"19828","118.93200","9.91107","0.03215"
"19862","119.13600","9.92817","0.03626"
"19896","119.34000","9.94509","0.03654"
"19930","119.54400","9.96213","0.03548"
"19964","119.74800","9.97911","0.04058"
"19998","119.95200","9.99609","0.03650"
"20032","120.15600","10.01313","0.04167"
"20066","120.36000","10.03005","0.03963"
"20100","120.56400","10.04715","0.04173"
"20134","120.76800","10.06413","0.04505"
"20168","120.97200","10.08105","0.04513"
"20202","121.17600","10.09815","0.04908"
"20236","121.38000","10.11519","0.05166"
"20270","121.58400","10.13205","0.04938"
"20304","121.78800","10.14915","0.05706"
"20338","121.99200","10.16607","0.05182"
"20372","122.19600","10.18312","0.06152"
"20406","122.40000","10.20015","0.05688"
"20440","122.60400","10.21713","0.06351"
"20474","122.80800","10.23411","0.06105"
"20508","123.01200","10.25115","0.06479"
"20542","123.21600","10.26802","0.06640"
"20576","123.42000","10.28517","0.06710"
"20610","123.62400","10.30210","0.07016"
"20644","123.82800","10.31907","0.06980"
"20678","124.03200","10.33618","0.07288"
"20712","124.23600","10.35304","0.07334"
"20746","124.44000","10.37014","0.07500"
"20780","124.64400","10.38712","0.07635"
"20814","124.84800","10.40404","0.07644"
"20848","125.05200","10.42114","0.07833"
"20882","125.25600","10.43812","0.07844"
"20916","125.46000","10.45516","0.08063"
"20950","125.66400","10.47214","0.08024"
"20984","125.86800","10.48906","0.08140"
"21018","126.07200","10.50610","0.08178"
"21052","126.27600","10.52308","0.08198"
"21086","126.48000","10.54012","0.08271"
"21120","126.68400","10.55716","0.08324"
"21154","126.88800","10.57414","0.08388"
"21188","127.09200","10.59112","0.08383"
"21222","127.29600","10.60810","0.08500"
"21256","127.50000","10.62514","0.08518"
"21290","127.70400","10.64212","0.08671"
"21324","127.90800","10.65916","0.08671"
"21358","128.11200","10.67608","0.08951"
"21392","128.31600","10.69312","0.08925"
"21426","128.52000","10.71010","0.09283"
"21460","128.72400","10.72714","0.09238"
"21494","128.92800","10.74412","0.09687"
"21528","129.13200","10.76110","0.09716"
"21562","129.33600","10.77808","0.10032"
"21596","129.54000","10.79506","0.10098"
"21630","129.74400","10.81210","0.10383"
"21664","129.94800","10.82914","0.10616"
"21698","130.15200","10.84606","0.10852"
"21732","130.35600","10.86316","0.11034"
"21766","130.56000","10.88008","0.11058"
"21800","130.76400","10.89712","0.11031"
"21834","130.96800","10.91410","0.10317"
"21868","131.17200","10.93108","0.00837"
"21902","131.37600","10.94812","0.02517"
"21936","131.58000","10.96510","0.00747"
"21970","131.78400","10.98208","0.01522"
"22004","131.98800","10.99912","0.01896"
"22038","132.19200","11.01610","0.00933"
"22072","132.39600","11.03308","0.01917"
"22106","132.60000","11.05012","0.01896"
"22140","132.80400","11.06704","0.01136"
"22174","133.00800","11.08414","0.02404"
"22208","133.21200","11.10118","0.01681"
"22242","133.41600","11.11810","0.01579"
"22276","133.62000","11.13514","0.02641"
"22310","133.82400","11.15212","0.01681"
"22344","134.02800","11.16904","0.02165"
"22378","134.23200","11.18614","0.02615"
"22412","134.43600","11.20306","0.02012"
"22446","134.64000","11.22010","0.02872"
"22480","134.84400","11.23714","0.02462"
"22514","135.04800","11.25406","0.02702"
"22548","135.25200","11.27116","0.03055"
"22582","135.45600","11.28808","0.02791"
"22616","135.66000","11.30507","0.03245"
"22650","135.86400","11.32211","0.03049"
"22684","136.06800","11.33909","0.03237"
"22718","136.27200","11.35612","0.03324"
"22752","136.47600","11.37311","0.03308"
"22786","136.68000","11.39009","0.03482"
"22820","136.88400","11.40713","0.03433"
"22854","137.08800","11.42411","0.03515"
"22888","137.29200","11.44109","0.03538"
"22922","137.49600","11.45813","0.01684"
"22956","137.70000","11.47511","0.01399"
"22990","137.90400","11.49215","0.00966"
"23024","138.10800","11.50913","0.00959"
"23058","138.31200","11.52611","0.01078"
"23092","138.51600","11.54315","0.01369"
"23126","138.72000","11.56007","0.01367"
"23160","138.92400","11.57717","0.01025"
"23194","139.12800","11.59409","0.01190"
"23228","139.33200","11.61101","0.01618"
"23262","139.53600","11.62823","0.01154"
"23296","139.74000","11.64509","0.01347"
"23330","139.94400","11.66213","0.01574"
"23364","140.14800","11.67917","0.01601"
"23398","140.35200","11.69609","0.01458"
"23432","140.55600","11.71313","0.01410"
"23466","140.76000","11.73011","0.01755"
"23500","140.96400","11.74709","0.01530"
"23534","141.16800","11.76413","0.01511"
"23568","141.37200","11.78111","0.01871"
"23602","141.57600","11.79803","0.01662"
"23636","141.78000","11.81519","0.01712"
"23670","141.98400","11.83205","0.01832"
"23704","142.18800","11.84909","0.01907"
"23738","142.39200","11.86613","0.01923"
"23772","142.59600","11.88311","0.01842"
"23806","142.80000","11.90015","0.02163"
"23840","143.00400","11.91707","0.02010"
"23874","143.20800","11.93411","0.01918"
"23908","143.41200","11.95115","0.02319"
"23942","143.61600","11.96801","0.02086"
"23976","143.82000","11.98517","0.02300"
"24010","144.02400","12.00215","0.02361"
"24044","144.22800","12.01907","0.02377"
"24078","144.43200","12.03611","0.02476"
"24112","144.63600","12.05309","0.02452"
"24146","144.84000","12.07013","0.02662"
"24180","145.04400","12.08711","0.02563"
"24214","145.24800","12.10409","0.02685"
"24248","145.45200","12.12113","0.02907"
"24282","145.65600","12.13805","0.02634"
"24316","145.86000","12.15509","0.03001"
"24350","146.06400","12.17213","0.02989"
"24384","146.26800","12.18911","0.02969"
"24418","146.47200","12.20609","0.03173"
"24452","146.67600","12.22313","0.03134"
"24486","146.88000","12.24005","0.03282"
"24520","147.08400","12.25709","0.03260"
"24554","147.28800","12.27413","0.03355"
"24588","147.49200","12.29111","0.03357"
"24622","147.69600","12.30815","0.03364"
"24656","147.90000","12.32507","0.03459"
"24690","148.10400","12.34217","0.03432"
"24724","148.30800","12.35915","0.03553"
"24758","148.51200","12.37607","0.03516"
"24792","148.71600","12.39311","0.03547"
"24826","148.92000","12.41010","0.03621"
"24860","149.12400","12.42714","0.03587"
"24894","149.32800","12.44411","0.03690"
"24928","149.53200","12.46110","0.03659"
"24962","149.73600","12.47808","0.03736"
"24996","149.94000","12.49512","0.03768"
"25030","150.14400","12.51210","0.03769"
"25064","150.34800","12.52914","0.03933"
"25098","150.55200","12.54606","0.03922"
"25132","150.75600","12.56310","0.04104"
"25166","150.96000","12.58008","0.04065"
"25200","151.16400","12.59706","0.04225"
"25234","151.36800","12.61410","0.04267"
"25268","151.57200","12.63114","0.04390"
"25302","151.77600","12.64812","0.04498"
"25336","151.98000","12.66510","0.04561"
"25370","152.18400","12.68208","0.04778"
"25404","152.38800","12.69912","0.04630"
"25438","152.59200","12.71616","0.04791"
"25472","152.79600","12.73302","0.04870"
"25506","153.00000","12.75018","0.05023"
"25540","153.20400","12.76710","0.05205"
"25574","153.40800","12.78408","0.05296"
"25608","153.61200","12.80118","0.05493"
"25642","153.81600","12.81810","0.05453"
"25676","154.02000","12.83514","0.05728"
"25710","154.22400","12.85212","0.05724"
"25744","154.42800","12.86904","0.05880"
"25778","154.63200","12.88614","0.05863"
"25812","154.83600","12.90306","0.06055"
"25846","155.04000","12.92010","0.06182"
"25880","155.24400","12.93714","0.06226"
"25914","155.44800","12.95412","0.06414"
"25948","155.65200","12.97116","0.06410"
"25982","155.85600","12.98814","0.06635"
"26016","156.06000","13.00512","0.06627"
"26050","156.26400","13.02210","0.06819"
"26084","156.46800","13.03914","0.06843"
"26118","156.67200","13.05612","0.07026"
"26152","156.87600","13.07316","0.07092"
"26186","157.08000","13.09002","0.07151"
"26220","157.28400","13.10712","0.07280"
"26254","157.48800","13.12410","0.07309"
"26288","157.69200","13.14108","0.07514"
"26322","157.89600","13.15812","0.07537"
"26356","158.10000","13.17510","0.07626"
"26390","158.30400","13.19208","0.07680"
"26424","158.50800","13.20912","0.07769"
"26458","158.71200","13.22604","0.07784"
"26492","158.91600","13.24314","0.07903"
"26526","159.12000","13.26006","0.07914"
"26560","159.32400","13.27716","0.08002"
"26594","159.52800","13.29414","0.08047"
"26628","159.73200","13.31106","0.08064"
"26662","159.93600","13.32810","0.08136"
"26696","160.14000","13.34514","0.08165"
"26730","160.34400","13.36212","0.08227"
"26764","160.54800","13.37910","0.08221"
"26798","160.75200","13.39608","0.08251"
"26832","160.95600","13.41306","0.08247"
"26866","161.16000","13.43017","0.08322"
"26900","161.36400","13.44709","0.08343"
"26934","161.56800","13.46412","0.08392"
"26968","161.77200","13.48116","0.08411"
"27002","161.97600","13.49809","0.08463"
"27036","162.18000","13.51519","0.08508"
"27070","162.38400","13.53211","0.08543"
"27104","162.58800","13.54909","0.08638"
"27138","162.79200","13.56612","0.08690"
"27172","162.99600","13.58305","0.08780"
"27206","163.20000","13.60021","0.08894"
"27240","163.40400","13.61707","0.09000"
"27274","163.60800","13.63411","0.09071"
"27308","163.81200","13.65115","0.09308"
"27342","164.01600","13.66807","0.09377"
"27376","164.22000","13.68517","0.08957"
"27410","164.42400","13.70209","0.09054"
"27444","164.62800","13.71907","0.08967"
"27478","164.83200","13.73611","0.09061"
"27512","165.03600","13.75309","0.09005"
"27546","165.24000","13.77007","0.00710"
"27580","165.44400","13.78717","0.01034"
"27614","165.64800","13.80403","0.00413"
"27648","165.85200","13.82113","0.01049"
"27682","166.05600","13.83811","0.00403"
"27716","166.26000","13.85503","0.00584"
"27750","166.46400","13.87213","0.00113"
"27784","166.66800","13.88911","0.00144"
"27818","166.87200","13.90609","0.00316"
"27852","167.07600","13.92313","0.00039"
"27886","167.28000","13.94005","0.00361"
"27920","167.48400","13.95715","0.00056"
"27954","167.68800","13.97413","0.00097"
"27988","167.89200","13.99105","0.00143"
"28022","168.09600","14.00815","0.00078"
"28056","168.30000","14.02507","0.00141"
"28090","168.50400","14.04217","0.00196"
"28124","168.70800","14.05915","0.00037"
"28158","168.91200","14.07607","0.00069"
"28192","169.11600","14.09311","0.00015"
"28226","169.32000","14.11015","0.00126"
"28260","169.52400","14.12713","0.00175"
"28294","169.72800","14.14417","0.00266"
"28328","169.93200","14.16109","0.00073"
"28362","170.13600","14.17813","0.00197"
"28396","170.34000","14.19511","0.00070"
"28430","170.54400","14.21209","0.00049"
"28464","170.74800","14.22913","0.00495"
"28498","170.95200","14.24617","0.00375"
"28532","171.15600","14.26309","0.00022"
"28566","171.36000","14.28013","0.00117"
"28600","171.56400","14.29711","0.00091"
"28634","171.76800","14.31409","0.00072"
"28668","171.97200","14.33113","0.00340"
"28702","172.17600","14.34805","0.00056"
"28736","172.38000","14.36515","0.00058"
"28770","172.58400","14.38207","0.00237"
"28804","172.78800","14.39917","0.00044"
"28838","172.99200","14.41615","0.00182"
"28872","173.19600","14.43307","0.00392"
"28906","173.40000","14.45017","0.00028"
"28940","173.60400","14.46710","0.00179"
"28974","173.80800","14.48407","0.00229"
"29008","174.01200","14.50111","0.00066"
"29042","174.21600","14.51809","0.00445"
"29076","174.42000","14.53513","0.00332"
"29110","174.62400","14.55212","0.00085"
"29144","174.82800","14.56903","0.00311"
"29178","175.03200","14.58614","0.00123"
"29212","175.23600","14.60312","0.00119"
"29246","175.44000","14.62010","0.00433"
"29280","175.64400","14.63714","0.00108"
"29314","175.84800","14.65406","0.00134"
"29348","176.05200","14.67110","0.00205"
"29382","176.25600","14.68820","0.00100"
"29416","176.46000","14.70506","0.00471"
"29450","176.66400","14.72216","0.00337"
"29484","176.86800","14.73914","0.00113"
"29518","177.07200","14.75612","0.00294"
"29552","177.27600","14.77316","0.00159"
"29586","177.48000","14.79008","0.00398"
"29620","177.68400","14.80718","0.00522"
"29654","177.88800","14.82410","0.00187"
"29688","178.09200","14.84102","0.00333"
"29722","178.29600","14.85812","0.00247"
"29756","178.50000","14.87516","0.00358"
"29790","178.70400","14.89208","0.00621"
"29824","178.90800","14.90912","0.00322"
"29858","179.11200","14.92610","0.00305"
"29892","179.31600","14.94314","0.00309"
"29926","179.52000","14.96012","0.00370"
"29960","179.72400","14.97710","0.00704"
"29994","179.92800","14.99408","0.00441"
"30028","180.13200","15.01112","0.00381"
"30062","180.33600","15.02804","0.00371"
"30096","180.54000","15.04514","0.00534"
"30130","180.74400","15.06206","0.00707"
"30164","180.94800","15.07910","0.00488"
"30198","181.15200","15.09614","0.00402"
"30232","181.35600","15.11306","0.00426"
"30266","181.56000","15.13010","0.00645"
"30300","181.76400","15.14708","0.00789"
"30334","181.96800","15.16412","0.00556"
"30368","182.17200","15.18110","0.00521"
"30402","182.37600","15.19808","0.00565"
"30436","182.58000","15.21518","0.00847"
"30470","182.78400","15.23210","0.00841"
"30504","182.98800","15.24914","0.00632"
"30538","183.19200","15.26612","0.00617"
"30572","183.39600","15.28304","0.00776"
"30606","183.60000","15.30014","0.00979"
"30640","183.80400","15.31712","0.00879"
"30674","184.00800","15.33410","0.00772"
"30708","184.21200","15.35114","0.00864"
"30742","184.41600","15.36812","0.01062"
"30776","184.62000","15.38510","0.01115"
"30810","184.82400","15.40214","0.00992"
"30844","185.02800","15.41912","0.01004"
"30878","185.23200","15.43610","0.01176"
"30912","185.43600","15.45314","0.01319"
"30946","185.64000","15.47006","0.01165"
"30980","185.84400","15.48710","0.01099"
"31014","186.04800","15.50408","0.01242"
"31048","186.25200","15.52112","0.01412"
"31082","186.45600","15.53816","0.01332"
"31116","186.66000","15.55508","0.01256"
"31150","186.86400","15.57212","0.01409"
"31184","187.06800","15.58910","0.01526"
"31218","187.27200","15.60603","0.01527"
"31252","187.47600","15.62312","0.01414"
"31286","187.68000","15.64004","0.01533"
"31320","187.88400","15.65714","0.01682"
"31354","188.08800","15.67413","0.01691"
"31388","188.29200","15.69110","0.01613"
"31422","188.49600","15.70815","0.01688"
"31456","188.70000","15.72507","0.01884"
"31490","188.90400","15.74217","0.01825"
"31524","189.10800","15.75915","0.01818"
"31558","189.31200","15.77613","0.01888"
"31592","189.51600","15.79311","0.02043"
"31626","189.72000","15.81009","0.01892"
"31660","189.92400","15.82701","0.00144"
"31694","190.12800","15.84411","0.00093"
"31728","190.33200","15.86115","0.00091"
"31762","190.53600","15.87813","0.00108"
"31796","190.74000","15.89517","0.00142"
"31830","190.94400","15.91209","0.00130"
"31864","191.14800","15.92913","0.00051"
"31898","191.35200","15.94617","0.00076"
"31932","191.55600","15.96303","0.00126"
"31966","191.76000","15.98019","0.00239"
"32000","191.96400","15.99711","0.00068"
"32034","192.16800","16.01415","0.00086"
"32068","192.37200","16.03113","0.00172"
"32102","192.57600","16.04805","0.00111"
"32136","192.78000","16.06515","0.00112"
"32170","192.98400","16.08207","0.00122"
"32204","193.18800","16.09911","0.00101"
"32238","193.39200","16.11615","0.00127"
"32272","193.59600","16.13307","0.00191"
"32306","193.80000","16.15005","0.00134"
"32340","194.00400","16.16715","0.00097"
"32374","194.20800","16.18407","0.00211"
"32408","194.41200","16.20111","0.00172"
"32442","194.61600","16.21815","0.00072"
"32476","194.82000","16.23507","0.00146"
"32510","195.02400","16.25211","0.00178"
"32544","195.22800","16.26909","0.00097"
"32578","195.43200","16.28613","0.00195"
"32612","195.63600","16.30311","0.00230"
"32646","195.84000","16.32003","0.00081"
"32680","196.04400","16.33719","0.00137"
"32714","196.24800","16.35411","0.00187"
"32748","196.45200","16.37109","0.00079"
"32782","196.65600","16.38819","0.00137"
"32816","196.86000","16.40505","0.00168"
"32850","197.06400","16.42215","0.00163"
"32884","197.26800","16.43913","0.00184"
"32918","197.47200","16.45605","0.00236"
"32952","197.67600","16.47309","0.00181"
"32986","197.88000","16.49007","0.00183"
"33020","198.08400","16.50711","0.00189"
"33054","198.28800","16.52409","0.00173"
"33088","198.49200","16.54107","0.00149"
"33122","198.69600","16.55817","0.00218"
"33156","198.90000","16.57509","0.00177"
"33190","199.10400","16.59207","0.00220"
"33224","199.30800","16.60911","0.00216"
"33258","199.51200","16.62609","0.00162"
"33292","199.71600","16.64307","0.00210"
"33326","199.92000","16.66017","0.00269"
"33360","200.12400","16.67703","0.00138"
"33394","200.32800","16.69413","0.00185"
"33428","200.53200","16.71117","0.00234"
"33462","200.73600","16.72803","0.00167"
"33496","200.94000","16.74520","0.00224"
"33530","201.14400","16.76212","0.00279"
"33564","201.34800","16.77909","0.00230"
"33598","201.55200","16.79613","0.00207"
"33632","201.75600","16.81306","0.00275"
"33666","201.96000","16.83016","0.00147"
"33700","202.16400","16.84714","0.00305"
"33734","202.36800","16.86411","0.00267"
"33768","202.57200","16.88116","0.00166"
"33802","202.77600","16.89808","0.00304"
"33836","202.98000","16.91512","0.00302"
"33870","203.18400","16.93210","0.00211"
"33904","203.38800","16.94908","0.00271"
"33938","203.59200","16.96612","0.00292"
"33972","203.79600","16.98310","0.00217"
"34006","204.00000","17.00008","0.00274"
"34040","204.20400","17.01712","0.00287"
"34074","204.40800","17.03410","0.00196"
"34108","204.61200","17.05114","0.00376"
"34142","204.81600","17.06812","0.00312"
"34176","205.02000","17.08510","0.00198"
"34210","205.22400","17.10214","0.00380"
"34244","205.42800","17.11912","0.00308"
"34278","205.63200","17.13610","0.00288"
"34312","205.83600","17.15314","0.00315"
"34346","206.04000","17.17006","0.00293"
"34380","206.24400","17.18716","0.00254"
"34414","206.44800","17.20408","0.00393"
"34448","206.65200","17.22106","0.00302"
"34482","206.85600","17.23810","0.00338"
"34516","207.06000","17.25508","0.00424"
"34550","207.26400","17.27218","0.00255"
"34584","207.46800","17.28910","0.00316"
"34618","207.67200","17.30608","0.00355"
"34652","207.87600","17.32312","0.00305"
"34686","208.08000","17.34010","0.00367"
"34720","208.28400","17.35714","0.00342"
"34754","208.48800","17.37412","0.00314"
"34788","208.69200","17.39104","0.00418"
"34822","208.89600","17.40814","0.00298"
"34856","209.10000","17.42518","0.00333"
"34890","209.30400","17.44204","0.00482"
"34924","209.50800","17.45914","0.00391"
"34958","209.71200","17.47612","0.00422"
"34992","209.91600","17.49304","0.00411"
"35026","210.12000","17.51014","0.00306"
"35060","210.32400","17.52706","0.00421"
"35094","210.52800","17.54410","0.00469"
"35128","210.73200","17.56114","0.00330"
"35162","210.93600","17.57800","0.00411"
"35196","211.14000","17.59516","0.00380"
"35230","211.34400","17.61208","0.00373"
"35264","211.54800","17.62912","0.00417"
"35298","211.75200","17.64616","0.00372"
"35332","211.95600","17.66308","0.00446"
"35366","212.16000","17.68012","0.00450"
"35400","212.36400","17.69710","0.00353"
"35434","212.56800","17.71408","0.00442"
"35468","212.77200","17.73112","0.00491"
"35502","212.97600","17.74810","0.00439"
"35536","213.18000","17.76514","0.00499"
"35570","213.38400","17.78212","0.00503"
"35604","213.58800","17.79910","0.00475"
"35638","213.79200","17.81614","0.00489"
"35672","213.99600","17.83312","0.00486"
"35706","214.20000","17.85011","0.00487"
"35740","214.40400","17.86715","0.00545"
"35774","214.60800","17.88413","0.00429"
"35808","214.81200","17.90111","0.00507"
"35842","215.01600","17.91815","0.00500"
"35876","215.22000","17.93507","0.00490"
"35910","215.42400","17.95217","0.00563"
"35944","215.62800","17.96909","0.00434"
"35978","215.83200","17.98619","0.00454"
"36012","216.03600","18.00317","0.00557"
"36046","216.24000","18.02003","0.00477"
"36080","216.44400","18.03719","0.00548"
"36114","216.64800","18.05411","0.00523"
"36148","216.85200","18.07103","0.00566"
"36182","217.05600","18.08813","0.00559"
"36216","217.26000","18.10505","0.00547"
"36250","217.46400","18.12215","0.00563"
"36284","217.66800","18.13913","0.00570"
"36318","217.87200","18.15611","0.00579"
"36352","218.07600","18.17315","0.00583"
"36386","218.28000","18.19007","0.00598"
"36420","218.48400","18.20711","0.00612"
"36454","218.68800","18.22415","0.00523"
"36488","218.89200","18.24107","0.00597"
"36522","219.09600","18.25811","0.00522"
"36556","219.30000","18.27521","0.00546"
"36590","219.50400","18.29207","0.00599"
"36624","219.70800","18.30911","0.00606"
"36658","219.91200","18.32609","0.00631"
"36692","220.11600","18.34307","0.00598"
"36726","220.32000","18.36017","0.00640"
"36760","220.52400","18.37709","0.00645"
"36794","220.72800","18.39413","0.00633"
"36828","220.93200","18.41111","0.00677"
"36862","221.13600","18.42803","0.00626"
"36896","221.34000","18.44519","0.00642"
"36930","221.54400","18.46211","0.00656"
"36964","221.74800","18.47909","0.00608"
"36998","221.95200","18.49613","0.00657"
"37032","222.15600","18.51311","0.00675"
"37066","222.36000","18.53009","0.00627"
"37100","222.56400","18.54713","0.00668"
"37134","222.76800","18.56411","0.00626"
"37168","222.97200","18.58109","0.00631"
"37202","223.17600","18.59813","0.00684"
"37236","223.38000","18.61511","0.00710"
"37270","223.58400","18.63215","0.00691"
"37304","223.78800","18.64907","0.00672"
"37338","223.99200","18.66611","0.00636"
"37372","224.19600","18.68321","0.00694"
"37406","224.40000","18.70007","0.00670"
"37440","224.60400","18.71711","0.00687"
"37474","224.80800","18.73409","0.00735"
"37508","225.01200","18.75113","0.00734"
"37542","225.21600","18.76811","0.00747"
"37576","225.42000","18.78510","0.00710"
"37610","225.62400","18.80213","0.00744"
"37644","225.82800","18.81911","0.00739"
"37678","226.03200","18.83609","0.00724"
"37712","226.23600","18.85314","0.00779"
"37746","226.44000","18.87006","0.00713"
"37780","226.64400","18.88716","0.00760"
"37814","226.84800","18.90408","0.00747"
"37848","227.05200","18.92111","0.00735"
"37882","227.25600","18.93810","0.00761"
"37916","227.46000","18.95508","0.00756"
"37950","227.66400","18.97206","0.00692"
"37984","227.86800","18.98915","0.00803"
"38018","228.07200","19.00607","0.00747"
"38052","228.27600","19.02312","0.00736"
"38086","228.48000","19.04016","0.00796"
"38120","228.68400","19.05714","0.00819"
"38154","228.88800","19.07412","0.00790"
"38188","229.09200","19.09110","0.00755"
"38222","229.29600","19.10814","0.00828"
"38256","229.50000","19.12518","0.00857"
"38290","229.70400","19.14210","0.00769"
"38324","229.90800","19.15914","0.00890"
"38358","230.11200","19.17612","0.00844"
"38392","230.31600","19.19310","0.00823"
"38426","230.52000","19.21014","0.00820"
"38460","230.72400","19.22712","0.00874"
"38494","230.92800","19.24416","0.00904"
"38528","231.13200","19.26120","0.00926"
"38562","231.33600","19.27806","0.00853"
"38596","231.54000","19.29516","0.00921"
"38630","231.74400","19.31208","0.00849"
"38664","231.94800","19.32912","0.00908"
"38698","232.15200","19.34610","0.00917"
"38732","232.35600","19.36308","0.00891"
"38766","232.56000","19.38012","0.00938"
"38800","232.76400","19.39710","0.00904"
"38834","232.96800","19.41408","0.00957"
"38868","233.17200","19.43112","0.00999"
"38902","233.37600","19.44810","0.01018"
"38936","233.58000","19.46514","0.00946"
"38970","233.78400","19.48212","0.01000"
"39004","233.98800","19.49904","0.00978"
"39038","234.19200","19.51614","0.01008"
"39072","234.39600","19.53318","0.01051"
"39106","234.60000","19.55004","0.01030"
"39140","234.80400","19.56720","0.01060"
"39174","235.00800","19.58412","0.01052"
"39208","235.21200","19.60110","0.01041"
"39242","235.41600","19.61814","0.01105"
"39276","235.62000","19.63506","0.01082"
"39310","235.82400","19.65216","0.01104"
"39344","236.02800","19.66908","0.01119"
"39378","236.23200","19.68612","0.01162"
"39412","236.43600","19.70310","0.01155"
"39446","236.64000","19.72008","0.01162"
"39480","236.84400","19.73712","0.01124"
"39514","237.04800","19.75416","0.01194"
"39548","237.25200","19.77108","0.01170"
"39582","237.45600","19.78812","0.01243"
"39616","237.66000","19.80510","0.01213"
"39650","237.86400","19.82208","0.01210"
"39684","238.06800","19.83912","0.01227"
"39718","238.27200","19.85610","0.01212"
"39752","238.47600","19.87314","0.01224"
"39786","238.68000","19.89012","0.01265"
"39820","238.88400","19.90710","0.01243"
"39854","239.08800","19.92414","0.01350"
"39888","239.29200","19.94113","0.01297"
"39922","239.49600","19.95811","0.01320"
"39956","239.70000","19.97515","0.01328"
"39990","239.90400","19.99207","0.01396"
"40024","240.10800","20.00916","0.01390"
"40058","240.31200","20.02615","0.01384"
"40092","240.51600","20.04307","0.01402"
"40126","240.72000","20.06010","0.01390"
"40160","240.92400","20.07709","0.01462"
"40194","241.12800","20.09412","0.01395"
"40228","241.33200","20.11117","0.01486"
"40262","241.53600","20.12809","0.01445"
"40296","241.74000","20.14519","0.01475"
"40330","241.94400","20.16211","0.01467"
"40364","242.14800","20.17915","0.01518"
"40398","242.35200","20.19613","0.01572"
"40432","242.55600","20.21305","0.01570"
"40466","242.76000","20.23009","0.01533"
"40500","242.96400","20.24713","0.01629"
"40534","243.16800","20.26405","0.01597"
"40568","243.37200","20.28115","0.01615"
"40602","243.57600","20.29819","0.01651"
"40636","243.78000","20.31505","0.01631"
"40670","243.98400","20.33215","0.01661"
"40704","244.18800","20.34907","0.01727"
"40738","244.39200","20.36605","0.01697"
"40772","244.59600","20.38315","0.01696"
"40806","244.80000","20.40001","0.01742"
"40840","245.00400","20.41717","0.01777"
"40874","245.20800","20.43409","0.01804"
"40908","245.41200","20.45113","0.01808"
"40942","245.61600","20.46811","0.01823"
"40976","245.82000","20.48509","0.01848"
"41010","246.02400","20.50213","0.01851"
"41044","246.22800","20.51911","0.01914"
"41078","246.43200","20.53609","0.01910"
"41112","246.63600","20.55313","0.01940"
"41146","246.84000","20.57011","0.01955"
"41180","247.04400","20.58709","0.02000"
"41214","247.24800","20.60413","0.01932"
"41248","247.45200","20.62111","0.01939"
"41282","247.65600","20.63815","0.01999"
"41316","247.86000","20.65513","0.02019"
"41350","248.06400","20.67205","0.02081"
"41384","248.26800","20.68915","0.02112"
"41418","248.47200","20.70613","0.02105"
"41452","248.67600","20.72311","0.02129"
"41486","248.88000","20.74015","0.02135"
"41520","249.08400","20.75707","0.02147"
"41554","249.28800","20.77411","0.02203"
"41588","249.49200","20.79109","0.02207"
"41622","249.69600","20.80807","0.01590"
"41656","249.90000","20.82517","0.00215"
"41690","250.10400","20.84203","0.00165"
"41724","250.30800","20.85913","0.00322"
"41758","250.51200","20.87617","0.00120"
"41792","250.71600","20.89303","0.00100"
"41826","250.92000","20.91013","0.00060"
"41860","251.12400","20.92711","0.00131"
"41894","251.32800","20.94409","0.00115"
"41928","251.53200","20.96113","0.00184"
"41962","251.73600","20.97805","0.00092"
"41996","251.94000","20.99516","0.00073"
"42030","252.14400","21.01213","0.00045"
"42064","252.34800","21.02905","0.00038"
"42098","252.55200","21.04616","0.00100"
"42132","252.75600","21.06314","0.00182"
"42142","252.81400","21.06792","0.00214"