File: Trajectories_together/170108_1Specimen_RawData_7.csv
"","V1","V2","V3"
"1","End date","1/8/2017",""
"2","Specimen label","10DG_59",""
"3","Maximum Load","0.72436","N"
"4","Time","Extension","Load"
"5","(s)","(mm)","(N)"
"6","0.00000","0.00000","-0.00017"
"63","0.34200","0.02852","0.00010"
"120","0.68400","0.05722","0.00038"
"177","1.02600","0.08568","-0.00064"
"234","1.36800","0.11414","-0.00008"
"291","1.71000","0.14266","-0.00026"
"348","2.05200","0.17118","0.00034"
"405","2.39400","0.19964","0.00043"
"462","2.73600","0.22816","0.00002"
"519","3.07800","0.25668","0.00001"
"576","3.42000","0.28514","0.00022"
"633","3.76200","0.31366","-0.00005"
"690","4.10400","0.34218","0.00028"
"747","4.44600","0.37070","0.00029"
"804","4.78800","0.39915","0.00038"
"861","5.13000","0.42767","0.00043"
"918","5.47200","0.45613","0.00009"
"975","5.81400","0.48465","0.00065"
"1032","6.15600","0.51317","0.00089"
"1089","6.49800","0.54163","0.00049"
"1146","6.84000","0.57015","0.00073"
"1203","7.18200","0.59867","0.00021"
"1260","7.52400","0.62713","0.00032"
"1317","7.86600","0.65571","0.00072"
"1374","8.20800","0.68411","0.00077"
"1431","8.55000","0.71269","0.00033"
"1488","8.89200","0.74121","0.00060"
"1545","9.23400","0.76967","0.00030"
"1602","9.57600","0.79819","0.00065"
"1659","9.91800","0.82677","0.00023"
"1716","10.26000","0.85511","0.00055"
"1773","10.60200","0.88369","0.00098"
"1830","10.94400","0.91221","0.00042"
"1887","11.28600","0.94067","0.00047"
"1944","11.62800","0.96919","0.00091"
"2001","11.97000","0.99765","0.00067"
"2058","12.31200","1.02617","0.00050"
"2115","12.65400","1.05475","0.00028"
"2172","12.99600","1.08315","0.00076"
"2229","13.33800","1.11173","0.00051"
"2286","13.68000","1.14025","0.00116"
"2343","14.02200","1.16859","0.00095"
"2400","14.36400","1.19723","0.00077"
"2457","14.70600","1.22575","0.00093"
"2514","15.04800","1.25409","0.00048"
"2571","15.39000","1.28272","0.00076"
"2628","15.73200","1.31118","0.00075"
"2685","16.07400","1.33964","0.00109"
"2742","16.41600","1.36816","0.00109"
"2799","16.75800","1.39662","0.00109"
"2856","17.10000","1.42520","0.00122"
"2913","17.44200","1.45366","0.00126"
"2970","17.78400","1.48212","0.00131"
"3027","18.12600","1.51070","0.00122"
"3084","18.46800","1.53916","0.00152"
"3141","18.81000","1.56768","0.00093"
"3198","19.15200","1.59620","0.00164"
"3255","19.49400","1.62466","0.00112"
"3312","19.83600","1.65318","0.00093"
"3369","20.17800","1.68170","0.00094"
"3426","20.52000","1.71016","0.00117"
"3483","20.86200","1.73868","0.00114"
"3540","21.20400","1.76720","0.00106"
"3597","21.54600","1.79560","0.00176"
"3654","21.88800","1.82418","0.00158"
"3711","22.23000","1.85270","0.00172"
"3768","22.57200","1.88110","0.00093"
"3825","22.91400","1.90968","0.00129"
"3882","23.25600","1.93814","0.00177"
"3939","23.59800","1.96666","0.00172"
"3996","23.94000","1.99518","0.00084"
"4053","24.28200","2.02364","0.00122"
"4110","24.62400","2.05216","0.00147"
"4167","24.96600","2.08068","0.00142"
"4224","25.30800","2.10914","0.00131"
"4281","25.65000","2.13766","0.00170"
"4338","25.99200","2.16617","0.00170"
"4395","26.33400","2.19469","0.00155"
"4452","26.67600","2.22315","0.00159"
"4509","27.01800","2.25167","0.00182"
"4566","27.36000","2.28019","0.00173"
"4623","27.70200","2.30871","0.00163"
"4680","28.04400","2.33717","0.00179"
"4737","28.38600","2.36569","0.00185"
"4794","28.72800","2.39421","0.00190"
"4851","29.07000","2.42267","0.00166"
"4908","29.41200","2.45119","0.00204"
"4965","29.75400","2.47965","0.00155"
"5022","30.09600","2.50811","0.00147"
"5079","30.43800","2.53675","0.00169"
"5136","30.78000","2.56515","0.00181"
"5193","31.12200","2.59361","0.00166"
"5250","31.46400","2.62225","0.00140"
"5307","31.80600","2.65059","0.00120"
"5364","32.14800","2.67917","0.00163"
"5421","32.49000","2.70775","0.00137"
"5478","32.83200","2.73615","0.00134"
"5535","33.17400","2.76473","0.00185"
"5592","33.51600","2.79319","0.00147"
"5649","33.85800","2.82165","0.00138"
"5706","34.20000","2.85023","0.00184"
"5763","34.54200","2.87863","0.00179"
"5820","34.88400","2.90721","0.00175"
"5877","35.22600","2.93561","0.00167"
"5934","35.56800","2.96407","0.00193"
"5991","35.91000","2.99271","0.00167"
"6048","36.25200","3.02117","0.00182"
"6105","36.59400","3.04963","0.00163"
"6162","36.93600","3.07820","0.00188"
"6219","37.27800","3.10666","0.00153"
"6276","37.62000","3.13518","0.00111"
"6333","37.96200","3.16370","0.00065"
"6390","38.30400","3.19216","0.00094"
"6447","38.64600","3.22068","0.00124"
"6504","38.98800","3.24920","0.00110"
"6561","39.33000","3.27766","0.00134"
"6618","39.67200","3.30618","0.00140"
"6675","40.01400","3.33470","0.00093"
"6732","40.35600","3.36316","0.00165"
"6789","40.69800","3.39174","0.00181"
"6846","41.04000","3.42020","0.00115"
"6903","41.38200","3.44866","0.00100"
"6960","41.72400","3.47718","0.00114"
"7017","42.06600","3.50564","0.00134"
"7074","42.40800","3.53416","0.00150"
"7131","42.75000","3.56268","0.00184"
"7188","43.09200","3.59120","0.00174"
"7245","43.43400","3.61972","0.00156"
"7302","43.77600","3.64818","0.00146"
"7359","44.11800","3.67658","0.00198"
"7416","44.46000","3.70522","0.00188"
"7473","44.80200","3.73368","0.00189"
"7530","45.14400","3.76214","0.00149"
"7587","45.48600","3.79072","0.00201"
"7644","45.82800","3.81918","0.00175"
"7701","46.17000","3.84764","0.00152"
"7758","46.51200","3.87622","0.00122"
"7815","46.85400","3.90462","0.00176"
"7872","47.19600","3.93319","0.00091"
"7929","47.53800","3.96171","0.00118"
"7986","47.88000","3.99017","0.00134"
"8043","48.22200","4.01869","0.00118"
"8100","48.56400","4.04715","0.00148"
"8157","48.90600","4.07561","0.00126"
"8214","49.24800","4.10425","0.00145"
"8271","49.59000","4.13265","0.00137"
"8328","49.93200","4.16117","0.00110"
"8385","50.27400","4.18969","0.00103"
"8442","50.61600","4.21809","0.00192"
"8499","50.95800","4.24673","0.00159"
"8556","51.30000","4.27513","0.00137"
"8613","51.64200","4.30365","0.00151"
"8670","51.98400","4.33217","0.00161"
"8727","52.32600","4.36063","0.00131"
"8784","52.66800","4.38915","0.00212"
"8841","53.01000","4.41773","0.00182"
"8898","53.35200","4.44613","0.00191"
"8955","53.69400","4.47471","0.00200"
"9012","54.03600","4.50317","0.00174"
"9069","54.37800","4.53163","0.00197"
"9126","54.72000","4.56015","0.00155"
"9183","55.06200","4.58867","0.00143"
"9240","55.40400","4.61719","0.00180"
"9297","55.74600","4.64571","0.00209"
"9354","56.08800","4.67417","0.00174"
"9411","56.43000","4.70269","0.00165"
"9468","56.77200","4.73115","0.00189"
"9525","57.11400","4.75961","0.00183"
"9582","57.45600","4.78819","0.00205"
"9639","57.79800","4.81670","0.00209"
"9696","58.14000","4.84516","0.00234"
"9753","58.48200","4.87368","0.00166"
"9810","58.82400","4.90214","0.00208"
"9867","59.16600","4.93066","0.00251"
"9924","59.50800","4.95918","0.00197"
"9981","59.85000","4.98770","0.00222"
"10038","60.19200","5.01616","0.00182"
"10095","60.53400","5.04462","0.00233"
"10152","60.87600","5.07314","0.00234"
"10209","61.21800","5.10172","0.00216"
"10266","61.56000","5.13018","0.00211"
"10323","61.90200","5.15864","0.00207"
"10380","62.24400","5.18722","0.00229"
"10437","62.58600","5.21574","0.00249"
"10494","62.92800","5.24420","0.00195"
"10551","63.27000","5.27272","0.00237"
"10608","63.61200","5.30118","0.00229"
"10665","63.95400","5.32964","0.00232"
"10722","64.29600","5.35822","0.00176"
"10779","64.63800","5.38662","0.00223"
"10836","64.98000","5.41520","0.00217"
"10893","65.32200","5.44372","0.00222"
"10950","65.66400","5.47212","0.00272"
"11007","66.00600","5.50070","0.00223"
"11064","66.34800","5.52922","0.00195"
"11121","66.69000","5.55762","0.00152"
"11178","67.03200","5.58626","0.00177"
"11235","67.37400","5.61460","0.00149"
"11292","67.71600","5.64312","0.00151"
"11349","68.05800","5.67169","0.00175"
"11406","68.40000","5.70010","0.00237"
"11463","68.74200","5.72873","0.00202"
"11520","69.08400","5.75719","0.00219"
"11577","69.42600","5.78559","0.00164"
"11634","69.76800","5.81423","0.00140"
"11691","70.11000","5.84269","0.00153"
"11748","70.45200","5.87115","0.00183"
"11805","70.79400","5.89967","0.00133"
"11862","71.13600","5.92813","0.00170"
"11919","71.47800","5.95665","0.00171"
"11976","71.82000","5.98523","0.00229"
"12033","72.16200","6.01357","0.00160"
"12090","72.50400","6.04215","0.00179"
"12147","72.84600","6.07073","0.00202"
"12204","73.18800","6.09913","0.00172"
"12261","73.53000","6.12771","0.00169"
"12318","73.87200","6.15617","0.00187"
"12375","74.21400","6.18463","0.00204"
"12432","74.55600","6.21315","0.00215"
"12489","74.89800","6.24167","0.00212"
"12546","75.24000","6.27019","0.00200"
"12603","75.58200","6.29871","0.00232"
"12660","75.92400","6.32717","0.00182"
"12717","76.26600","6.35569","0.00259"
"12774","76.60800","6.38421","0.00208"
"12831","76.95000","6.41267","0.00256"
"12888","77.29200","6.44119","0.00229"
"12945","77.63400","6.46965","0.00236"
"13002","77.97600","6.49817","0.00220"
"13059","78.31800","6.52669","0.00219"
"13116","78.66000","6.55520","0.00205"
"13173","79.00200","6.58366","0.00260"
"13230","79.34400","6.61218","0.00232"
"13287","79.68600","6.64064","0.00241"
"13344","80.02800","6.66916","0.00212"
"13401","80.37000","6.69768","0.00256"
"13458","80.71200","6.72614","0.00270"
"13515","81.05400","6.75466","0.00292"
"13572","81.39600","6.78318","0.00243"
"13629","81.73800","6.81164","0.00302"
"13686","82.08000","6.84022","0.00282"
"13743","82.42200","6.86868","0.00278"
"13800","82.76400","6.89714","0.00255"
"13857","83.10600","6.92578","0.00262"
"13914","83.44800","6.95412","0.00256"
"13971","83.79000","6.98270","0.00280"
"14028","84.13200","7.01122","0.00326"
"14085","84.47400","7.03968","0.00310"
"14142","84.81600","7.06820","0.00334"
"14199","85.15800","7.09660","0.00329"
"14256","85.50000","7.12512","0.00324"
"14313","85.84200","7.15370","0.00304"
"14370","86.18400","7.18216","0.00314"
"14427","86.52600","7.21068","0.00329"
"14484","86.86800","7.23920","0.00325"
"14541","87.21000","7.26760","0.00332"
"14598","87.55200","7.29624","0.00309"
"14655","87.89400","7.32470","0.00355"
"14712","88.23600","7.35316","0.00306"
"14769","88.57800","7.38174","0.00300"
"14826","88.92000","7.41014","0.00281"
"14883","89.26200","7.43865","0.00389"
"14940","89.60400","7.46717","0.00353"
"14997","89.94600","7.49563","0.00356"
"15054","90.28800","7.52421","0.00325"
"15111","90.63000","7.55267","0.00356"
"15168","90.97200","7.58113","0.00360"
"15225","91.31400","7.60971","0.00365"
"15282","91.65600","7.63817","0.00346"
"15339","91.99800","7.66663","0.00397"
"15396","92.34000","7.69515","0.00330"
"15453","92.68200","7.72361","0.00439"
"15510","93.02400","7.75219","0.00432"
"15567","93.36600","7.78071","0.00406"
"15624","93.70800","7.80911","0.00425"
"15681","94.05000","7.83769","0.00464"
"15738","94.39200","7.86615","0.00438"
"15795","94.73400","7.89467","0.00406"
"15852","95.07600","7.92319","0.00370"
"15909","95.41800","7.95171","0.00451"
"15966","95.76000","7.98017","0.00472"
"16023","96.10200","8.00869","0.00449"
"16080","96.44400","8.03715","0.00449"
"16137","96.78600","8.06567","0.00462"
"16194","97.12800","8.09413","0.00489"
"16251","97.47000","8.12265","0.00485"
"16308","97.81200","8.15117","0.00564"
"16365","98.15400","8.17969","0.00467"
"16422","98.49600","8.20815","0.00518"
"16479","98.83800","8.23667","0.00480"
"16536","99.18000","8.26524","0.00509"
"16593","99.52200","8.29358","0.00477"
"16650","99.86400","8.32216","0.00506"
"16707","100.20600","8.35068","0.00482"
"16764","100.54800","8.37914","0.00449"
"16821","100.89000","8.40772","0.00445"
"16878","101.23200","8.43612","0.00456"
"16935","101.57400","8.46470","0.00438"
"16992","101.91600","8.49322","0.00480"
"17049","102.25800","8.52162","0.00508"
"17106","102.60000","8.55020","0.00486"
"17163","102.94200","8.57872","0.00411"
"17220","103.28400","8.60712","0.00478"
"17277","103.62600","8.63570","0.00515"
"17334","103.96800","8.66416","0.00463"
"17391","104.31000","8.69268","0.00437"
"17448","104.65200","8.72120","0.00416"
"17505","104.99400","8.74966","0.00423"
"17562","105.33600","8.77818","0.00424"
"17619","105.67800","8.80670","0.00439"
"17676","106.02000","8.83516","0.00405"
"17733","106.36200","8.86374","0.00386"
"17790","106.70400","8.89214","0.00435"
"17847","107.04600","8.92066","0.00408"
"17904","107.38800","8.94924","0.00374"
"17961","107.73000","8.97764","0.00381"
"18018","108.07200","9.00622","0.00444"
"18075","108.41400","9.03468","0.00461"
"18132","108.75600","9.06314","0.00459"
"18189","109.09800","9.09172","0.00447"
"18246","109.44000","9.12018","0.00476"
"18303","109.78200","9.14864","0.00416"
"18360","110.12400","9.17722","0.00491"
"18417","110.46600","9.20562","0.00438"
"18474","110.80800","9.23413","0.00481"
"18531","111.15000","9.26265","0.00452"
"18588","111.49200","9.29117","0.00476"
"18645","111.83400","9.31969","0.00499"
"18702","112.17600","9.34815","0.00483"
"18759","112.51800","9.37661","0.00449"
"18816","112.86000","9.40519","0.00455"
"18873","113.20200","9.43365","0.00451"
"18930","113.54400","9.46217","0.00517"
"18987","113.88600","9.49063","0.00470"
"19044","114.22800","9.51921","0.00535"
"19101","114.57000","9.54767","0.00528"
"19158","114.91200","9.57613","0.00516"
"19215","115.25400","9.60465","0.00553"
"19272","115.59600","9.63311","0.00530"
"19329","115.93800","9.66169","0.00528"
"19386","116.28000","9.69015","0.00497"
"19443","116.62200","9.71873","0.00545"
"19500","116.96400","9.74719","0.00537"
"19557","117.30600","9.77559","0.00572"
"19614","117.64800","9.80417","0.00561"
"19671","117.99000","9.83269","0.00569"
"19728","118.33200","9.86115","0.00572"
"19785","118.67400","9.88973","0.00543"
"19842","119.01600","9.91819","0.00567"
"19899","119.35800","9.94665","0.00613"
"19956","119.70000","9.97522","0.00613"
"20013","120.04200","10.00363","0.00562"
"20070","120.38400","10.03221","0.00652"
"20127","120.72600","10.06066","0.00592"
"20184","121.06800","10.08913","0.00696"
"20241","121.41000","10.11770","0.00695"
"20298","121.75200","10.14616","0.00650"
"20355","122.09400","10.17468","0.00638"
"20412","122.43600","10.20320","0.00700"
"20469","122.77800","10.23160","0.00698"
"20526","123.12000","10.26018","0.00683"
"20583","123.46200","10.28870","0.00693"
"20640","123.80400","10.31710","0.00735"
"20697","124.14600","10.34568","0.00675"
"20754","124.48800","10.37420","0.00668"
"20811","124.83000","10.40266","0.00714"
"20868","125.17200","10.43118","0.00719"
"20925","125.51400","10.45970","0.00721"
"20982","125.85600","10.48816","0.00713"
"21039","126.19800","10.51674","0.00759"
"21096","126.54000","10.54508","0.00793"
"21153","126.88200","10.57372","0.00772"
"21210","127.22400","10.60224","0.00836"
"21267","127.56600","10.63064","0.00779"
"21324","127.90800","10.65922","0.00764"
"21381","128.25000","10.68762","0.00776"
"21438","128.59200","10.71614","0.00810"
"21495","128.93400","10.74466","0.00786"
"21552","129.27600","10.77318","0.00796"
"21609","129.61800","10.80164","0.00807"
"21666","129.96000","10.83016","0.00805"
"21723","130.30200","10.85868","0.00758"
"21780","130.64400","10.88720","0.00799"
"21837","130.98600","10.91566","0.00805"
"21894","131.32800","10.94418","0.00799"
"21951","131.67000","10.97269","0.00827"
"22008","132.01200","11.00115","0.00832"
"22065","132.35400","11.02962","0.00782"
"22122","132.69600","11.05813","0.00838"
"22179","133.03800","11.08665","0.00821"
"22236","133.38000","11.11517","0.00842"
"22293","133.72200","11.14369","0.00672"
"22350","134.06400","11.17215","0.00712"
"22407","134.40600","11.20067","0.00717"
"22464","134.74800","11.22919","0.00728"
"22521","135.09000","11.25759","0.00713"
"22578","135.43200","11.28617","0.00622"
"22635","135.77400","11.31469","0.00723"
"22692","136.11600","11.34315","0.00761"
"22749","136.45800","11.37167","0.00646"
"22806","136.80000","11.40019","0.00632"
"22863","137.14200","11.42865","0.00676"
"22920","137.48400","11.45717","0.00642"
"22977","137.82600","11.48563","0.00674"
"23034","138.16800","11.51415","0.00684"
"23091","138.51000","11.54273","0.00704"
"23148","138.85200","11.57113","0.00719"
"23205","139.19400","11.59971","0.00758"
"23262","139.53600","11.62817","0.00700"
"23319","139.87800","11.65669","0.00786"
"23376","140.22000","11.68521","0.00731"
"23433","140.56200","11.71367","0.00711"
"23490","140.90400","11.74213","0.00738"
"23547","141.24600","11.77071","0.00746"
"23604","141.58800","11.79917","0.00779"
"23661","141.93000","11.82775","0.00722"
"23718","142.27200","11.85620","0.00745"
"23775","142.61400","11.88461","0.00689"
"23832","142.95600","11.91318","0.00680"
"23889","143.29800","11.94164","0.00725"
"23946","143.64000","11.97016","0.00699"
"24003","143.98200","11.99868","0.00734"
"24060","144.32400","12.02714","0.00749"
"24117","144.66600","12.05566","0.00771"
"24174","145.00800","12.08418","0.00781"
"24231","145.35000","12.11264","0.00771"
"24288","145.69200","12.14122","0.00843"
"24345","146.03400","12.16968","0.00760"
"24402","146.37600","12.19814","0.00795"
"24459","146.71800","12.22672","0.00830"
"24516","147.06000","12.25512","0.00794"
"24573","147.40200","12.28364","0.00852"
"24630","147.74400","12.31216","0.00832"
"24687","148.08600","12.34062","0.00883"
"24744","148.42800","12.36920","0.00892"
"24801","148.77000","12.39772","0.00857"
"24858","149.11200","12.42612","0.00912"
"24915","149.45400","12.45464","0.00904"
"24972","149.79600","12.48316","0.00862"
"25029","150.13800","12.51162","0.00917"
"25086","150.48000","12.54026","0.00925"
"25143","150.82200","12.56866","0.00904"
"25200","151.16400","12.59718","0.00942"
"25257","151.50600","12.62564","0.00970"
"25314","151.84800","12.65421","0.01018"
"25371","152.19000","12.68268","0.01018"
"25428","152.53200","12.71119","0.00998"
"25485","152.87400","12.73960","0.00942"
"25542","153.21600","12.76817","0.01028"
"25599","153.55800","12.79669","0.01009"
"25656","153.90000","12.82509","0.01011"
"25713","154.24200","12.85367","0.01109"
"25770","154.58400","12.88219","0.01092"
"25827","154.92600","12.91065","0.01069"
"25884","155.26800","12.93917","0.01101"
"25941","155.61000","12.96763","0.01147"
"25998","155.95200","12.99615","0.01087"
"26055","156.29400","13.02473","0.01180"
"26112","156.63600","13.05313","0.01186"
"26169","156.97800","13.08165","0.01174"
"26226","157.32000","13.11017","0.01207"
"26283","157.66200","13.13863","0.01208"
"26340","158.00400","13.16721","0.01282"
"26397","158.34600","13.19567","0.01290"
"26454","158.68800","13.22413","0.01238"
"26511","159.03000","13.25271","0.01303"
"26568","159.37200","13.28117","0.01363"
"26625","159.71400","13.30969","0.01319"
"26682","160.05600","13.33821","0.01348"
"26739","160.39800","13.36661","0.01388"
"26796","160.74000","13.39519","0.01413"
"26853","161.08200","13.42371","0.01439"
"26910","161.42400","13.45211","0.01444"
"26967","161.76600","13.48069","0.01465"
"27024","162.10800","13.50921","0.01479"
"27081","162.45000","13.53767","0.01522"
"27138","162.79200","13.56618","0.01495"
"27195","163.13400","13.59459","0.01498"
"27252","163.47600","13.62322","0.01554"
"27309","163.81800","13.65168","0.01609"
"27366","164.16000","13.68015","0.01570"
"27423","164.50200","13.70866","0.01668"
"27480","164.84400","13.73718","0.01647"
"27537","165.18600","13.76570","0.01632"
"27594","165.52800","13.79422","0.01671"
"27651","165.87000","13.82262","0.01726"
"27708","166.21200","13.85120","0.01722"
"27765","166.55400","13.87966","0.01795"
"27822","166.89600","13.90812","0.01805"
"27879","167.23800","13.93664","0.01810"
"27936","167.58000","13.96516","0.01829"
"27993","167.92200","13.99368","0.01863"
"28050","168.26400","14.02220","0.01904"
"28107","168.60600","14.05066","0.01886"
"28164","168.94800","14.07918","0.01959"
"28221","169.29000","14.10770","0.01976"
"28278","169.63200","14.13616","0.02060"
"28335","169.97400","14.16468","0.01979"
"28392","170.31600","14.19320","0.02000"
"28449","170.65800","14.22166","0.02152"
"28506","171.00000","14.25018","0.02128"
"28563","171.34200","14.27870","0.02135"
"28620","171.68400","14.30710","0.02155"
"28677","172.02600","14.33568","0.02177"
"28734","172.36800","14.36420","0.02230"
"28791","172.71000","14.39266","0.02196"
"28848","173.05200","14.42118","0.02271"
"28905","173.39400","14.44964","0.02321"
"28962","173.73600","14.47815","0.02324"
"29019","174.07800","14.50673","0.02399"
"29076","174.42000","14.53519","0.02339"
"29133","174.76200","14.56365","0.02380"
"29190","175.10400","14.59223","0.02402"
"29247","175.44600","14.62063","0.02482"
"29304","175.78800","14.64921","0.02365"
"29361","176.13000","14.67767","0.02351"
"29418","176.47200","14.70613","0.02230"
"29475","176.81400","14.73471","0.02283"
"29532","177.15600","14.76317","0.02347"
"29589","177.49800","14.79169","0.02327"
"29646","177.84000","14.82021","0.02337"
"29703","178.18200","14.84855","0.02376"
"29760","178.52400","14.87725","0.02427"
"29817","178.86600","14.90571","0.02475"
"29874","179.20800","14.93411","0.02528"
"29931","179.55000","14.96269","0.02566"
"29988","179.89200","14.99115","0.02562"
"30045","180.23400","15.01967","0.02557"
"30102","180.57600","15.04819","0.02735"
"30159","180.91800","15.07665","0.02625"
"30216","181.26000","15.10517","0.02752"
"30273","181.60200","15.13363","0.02765"
"30330","181.94400","15.16209","0.02768"
"30387","182.28600","15.19067","0.02817"
"30444","182.62800","15.21919","0.02954"
"30501","182.97000","15.24771","0.02886"
"30558","183.31200","15.27623","0.02739"
"30615","183.65400","15.30463","0.02767"
"30672","183.99600","15.33315","0.02784"
"30729","184.33800","15.36161","0.02888"
"30786","184.68000","15.39018","0.02869"
"30843","185.02200","15.41871","0.02863"
"30900","185.36400","15.44716","0.02887"
"30957","185.70600","15.47569","0.02976"
"31014","186.04800","15.50414","0.02956"
"31071","186.39000","15.53272","0.01601"
"31128","186.73200","15.56112","0.01694"
"31185","187.07400","15.58970","0.01878"
"31242","187.41600","15.61822","0.01946"
"31299","187.75800","15.64662","0.02056"
"31356","188.10000","15.67520","0.02127"
"31413","188.44200","15.70366","0.02270"
"31470","188.78400","15.73218","0.02411"
"31527","189.12600","15.76070","0.02419"
"31584","189.46800","15.78916","0.02598"
"31641","189.81000","15.81768","0.02715"
"31698","190.15200","15.84614","0.02734"
"31755","190.49400","15.87466","0.02824"
"31812","190.83600","15.90318","0.02890"
"31869","191.17800","15.93170","0.02983"
"31926","191.52000","15.96016","0.03020"
"31983","191.86200","15.98868","0.03032"
"32040","192.20400","16.01714","0.03085"
"32097","192.54600","16.04566","0.03176"
"32154","192.88800","16.07418","0.03165"
"32211","193.23000","16.10264","0.03102"
"32268","193.57200","16.13121","0.02965"
"32325","193.91400","16.15973","0.02918"
"32382","194.25600","16.18814","0.03079"
"32439","194.59800","16.21671","0.02698"
"32496","194.94000","16.24512","0.02797"
"32553","195.28200","16.27363","0.02904"
"32610","195.62400","16.30221","0.02828"
"32667","195.96600","16.33061","0.01443"
"32724","196.30800","16.35919","0.01553"
"32781","196.65000","16.38765","0.01645"
"32838","196.99200","16.41605","0.01699"
"32895","197.33400","16.44469","0.01658"
"32952","197.67600","16.47321","0.01627"
"33009","198.01800","16.50167","0.01715"
"33066","198.36000","16.53019","0.01777"
"33123","198.70200","16.55865","0.01816"
"33180","199.04400","16.58717","0.01865"
"33237","199.38600","16.61569","0.01844"
"33294","199.72800","16.64409","0.01932"
"33351","200.07000","16.67267","0.01929"
"33408","200.41200","16.70119","0.02043"
"33465","200.75400","16.72959","0.02002"
"33522","201.09600","16.75817","0.02084"
"33579","201.43800","16.78669","0.02083"
"33636","201.78000","16.81509","0.02160"
"33693","202.12200","16.84373","0.02137"
"33750","202.46400","16.87219","0.02199"
"33807","202.80600","16.90065","0.02217"
"33864","203.14800","16.92917","0.02342"
"33921","203.49000","16.95763","0.02381"
"33978","203.83200","16.98621","0.02433"
"34035","204.17400","17.01472","0.02589"
"34092","204.51600","17.04313","0.02661"
"34149","204.85800","17.07165","0.02720"
"34206","205.20000","17.10016","0.02746"
"34263","205.54200","17.12862","0.02916"
"34320","205.88400","17.15720","0.03009"
"34377","206.22600","17.18572","0.03050"
"34434","206.56800","17.21412","0.03106"
"34491","206.91000","17.24270","0.03209"
"34548","207.25200","17.27116","0.03276"
"34605","207.59400","17.29968","0.03293"
"34662","207.93600","17.32826","0.03360"
"34719","208.27800","17.35660","0.03476"
"34776","208.62000","17.38512","0.03500"
"34833","208.96200","17.41370","0.03531"
"34890","209.30400","17.44216","0.03517"
"34947","209.64600","17.47068","0.03546"
"35004","209.98800","17.49914","0.03579"
"35061","210.33000","17.52760","0.03613"
"35118","210.67200","17.55624","0.03639"
"35175","211.01400","17.58464","0.03713"
"35232","211.35600","17.61316","0.03769"
"35289","211.69800","17.64174","0.03813"
"35346","212.04000","17.67008","0.03835"
"35403","212.38200","17.69872","0.03892"
"35460","212.72400","17.72718","0.03957"
"35517","213.06800","17.75582","0.03882"
"35574","213.41000","17.78434","0.03855"
"35631","213.75200","17.81285","0.03964"
"35688","214.09400","17.84132","0.04073"
"35745","214.43600","17.86983","0.04253"
"35802","214.77800","17.89829","0.04319"
"35859","215.12000","17.92688","0.04439"
"35916","215.46200","17.95534","0.04487"
"35973","215.80400","17.98380","0.04545"
"36030","216.14600","18.01237","0.03802"
"36087","216.48800","18.04083","0.03862"
"36144","216.83000","18.06935","0.03808"
"36201","217.17200","18.09787","0.03795"
"36258","217.51400","18.12633","0.03986"
"36315","217.85600","18.15491","0.04041"
"36372","218.19800","18.18337","0.03989"
"36429","218.54000","18.21177","0.04027"
"36486","218.88200","18.24035","0.04132"
"36543","219.22400","18.26887","0.04107"
"36600","219.56600","18.29727","0.04181"
"36657","219.90800","18.32585","0.04191"
"36714","220.25000","18.35431","0.04439"
"36771","220.59200","18.38277","0.04615"
"36828","220.93400","18.41135","0.04130"
"36885","221.27600","18.43987","0.04117"
"36942","221.61800","18.46839","0.04170"
"36999","221.96000","18.49685","0.04361"
"37056","222.30200","18.52531","0.04538"
"37113","222.64400","18.55383","0.04805"
"37170","222.98600","18.58235","0.04870"
"37227","223.32800","18.61087","0.05043"
"37284","223.67000","18.63939","0.05249"
"37341","224.01200","18.66785","0.05513"
"37398","224.35400","18.69625","0.05323"
"37455","224.69600","18.72483","0.04347"
"37512","225.03800","18.75329","0.04642"
"37569","225.38000","18.78181","0.04847"
"37626","225.72200","18.81039","0.04833"
"37683","226.06400","18.83879","0.05164"
"37740","226.40600","18.86730","0.05444"
"37797","226.74800","18.89582","0.05570"
"37854","227.09000","18.92428","0.05699"
"37911","227.43200","18.95286","0.05895"
"37968","227.77400","18.98132","0.05701"
"38025","228.11600","19.00978","0.05970"
"38082","228.45800","19.03836","0.05998"
"38139","228.80000","19.06682","0.06256"
"38196","229.14200","19.09528","0.06408"
"38253","229.48400","19.12392","0.06563"
"38310","229.82600","19.15226","0.06633"
"38367","230.16800","19.18084","0.06692"
"38424","230.51000","19.20936","0.06780"
"38481","230.85200","19.23782","0.06887"
"38538","231.19400","19.26640","0.07132"
"38595","231.53600","19.29480","0.07297"
"38652","231.87800","19.32332","0.07339"
"38709","232.22000","19.35190","0.07525"
"38766","232.56200","19.38030","0.07678"
"38823","232.90400","19.40882","0.07720"
"38880","233.24600","19.43734","0.07890"
"38937","233.58800","19.46574","0.07931"
"38994","233.93000","19.49438","0.07999"
"39051","234.27200","19.52290","0.07740"
"39108","234.61400","19.55136","0.07912"
"39165","234.95600","19.57988","0.08103"
"39222","235.29800","19.60834","0.08156"
"39279","235.64000","19.63680","0.08242"
"39336","235.98200","19.66537","0.08239"
"39393","236.32400","19.69383","0.08341"
"39450","236.66600","19.72235","0.08388"
"39507","237.00800","19.75081","0.08415"
"39564","237.35000","19.77927","0.08441"
"39621","237.69200","19.80786","0.08518"
"39678","238.03400","19.83637","0.08537"
"39735","238.37600","19.86477","0.08597"
"39792","238.71800","19.89335","0.08758"
"39849","239.06000","19.92181","0.08999"
"39906","239.40200","19.95033","0.09097"
"39963","239.74400","19.97885","0.09349"
"40020","240.08600","20.00737","0.09641"
"40077","240.42800","20.03583","0.09761"
"40134","240.77000","20.06435","0.09737"
"40191","241.11200","20.09281","0.10103"
"40248","241.45400","20.12133","0.10482"
"40305","241.79600","20.14985","0.10696"
"40362","242.13800","20.17831","0.11016"
"40419","242.48000","20.20683","0.11265"
"40476","242.82200","20.23535","0.11626"
"40533","243.16400","20.26387","0.12133"
"40590","243.50600","20.29233","0.12662"
"40647","243.84800","20.32079","0.12955"
"40704","244.19000","20.34931","0.13474"
"40761","244.53200","20.37789","0.13721"
"40818","244.87400","20.40629","0.14003"
"40875","245.21600","20.43487","0.14112"
"40932","245.55800","20.46333","0.14205"
"40989","245.90000","20.49179","0.14385"
"41046","246.24200","20.52037","0.14460"
"41103","246.58400","20.54882","0.14558"
"41160","246.92600","20.57734","0.14684"
"41217","247.26800","20.60592","0.14919"
"41274","247.61000","20.63426","0.15102"
"41331","247.95200","20.66278","0.15205"
"41388","248.29400","20.69136","0.15324"
"41445","248.63600","20.71976","0.15885"
"41502","248.97800","20.74840","0.16188"
"41559","249.32000","20.77686","0.16599"
"41616","249.66200","20.80532","0.17047"
"41673","250.00400","20.83390","0.17379"
"41730","250.34600","20.86230","0.17718"
"41787","250.68800","20.89082","0.18022"
"41844","251.03000","20.91934","0.18298"
"41901","251.37200","20.94780","0.18488"
"41958","251.71400","20.97638","0.18439"
"42015","252.05600","21.00490","0.18518"
"42072","252.39800","21.03330","0.18587"
"42129","252.74000","21.06188","0.18876"
"42186","253.08200","21.09028","0.19045"
"42243","253.42400","21.11880","0.19252"
"42300","253.76600","21.14738","0.19481"
"42357","254.10800","21.17584","0.19640"
"42414","254.45000","21.20436","0.19826"
"42471","254.79200","21.23288","0.20125"
"42528","255.13400","21.26128","0.20490"
"42585","255.47600","21.28992","0.20894"
"42642","255.81800","21.31838","0.21393"
"42699","256.16000","21.34684","0.21815"
"42756","256.50200","21.37535","0.22025"
"42813","256.84400","21.40382","0.22388"
"42870","257.18600","21.43228","0.22772"
"42927","257.52800","21.46086","0.23172"
"42984","257.87000","21.48932","0.23348"
"43041","258.21200","21.51784","0.23540"
"43098","258.55400","21.54635","0.23715"
"43155","258.89600","21.57475","0.23953"
"43212","259.23800","21.60333","0.24344"
"43269","259.58000","21.63191","0.24871"
"43326","259.92200","21.66031","0.25663"
"43383","260.26400","21.68883","0.26188"
"43440","260.60600","21.71735","0.26496"
"43497","260.94800","21.74581","0.26807"
"43554","261.29000","21.77433","0.27159"
"43611","261.63200","21.80285","0.27179"
"43668","261.97400","21.83131","0.20095"
"43725","262.31600","21.85983","0.19716"
"43782","262.65800","21.88829","0.19817"
"43839","263.00000","21.91687","0.20328"
"43896","263.34200","21.94539","0.21186"
"43953","263.68400","21.97379","0.21667"
"44010","264.02600","22.00237","0.21844"
"44067","264.36800","22.03089","0.22284"
"44124","264.71000","22.05935","0.22177"
"44181","265.05200","22.08787","0.21428"
"44238","265.39400","22.11633","0.18007"
"44295","265.73600","22.14479","0.17990"
"44352","266.07800","22.17337","0.18289"
"44409","266.42000","22.20183","0.18595"
"44466","266.76200","22.23035","0.18773"
"44523","267.10400","22.25887","0.18790"
"44580","267.44600","22.28727","0.18897"
"44637","267.78800","22.31585","0.19042"
"44694","268.13000","22.34431","0.19224"
"44751","268.47200","22.37283","0.19399"
"44808","268.81400","22.40135","0.19542"
"44865","269.15600","22.42981","0.19623"
"44922","269.49800","22.45838","0.19785"
"44979","269.84000","22.48684","0.19986"
"45036","270.18200","22.51530","0.20322"
"45093","270.52400","22.54382","0.20578"
"45150","270.86600","22.57234","0.20903"
"45207","271.20800","22.60080","0.21250"
"45264","271.55000","22.62938","0.21548"
"45321","271.89200","22.65784","0.21767"
"45378","272.23400","22.68630","0.22012"
"45435","272.57600","22.71482","0.22219"
"45492","272.91800","22.74328","0.22488"
"45549","273.26000","22.77192","0.22777"
"45606","273.60200","22.80038","0.23011"
"45663","273.94400","22.82878","0.23262"
"45720","274.28600","22.85736","0.23445"
"45777","274.62800","22.88582","0.23536"
"45834","274.97000","22.91434","0.23670"
"45891","275.31200","22.94286","0.23833"
"45948","275.65400","22.97132","0.24150"
"46005","275.99600","22.99984","0.24437"
"46062","276.33800","23.02830","0.24758"
"46119","276.68000","23.05682","0.25190"
"46176","277.02200","23.08534","0.25550"
"46233","277.36400","23.11385","0.26098"
"46290","277.70600","23.14231","0.26166"
"46347","278.04800","23.17084","0.26559"
"46404","278.39000","23.19936","0.26920"
"46461","278.73200","23.22782","0.27308"
"46518","279.07400","23.25634","0.27703"
"46575","279.41600","23.28485","0.28275"
"46632","279.75800","23.31332","0.28839"
"46689","280.10000","23.34183","0.29168"
"46746","280.44200","23.37029","0.29424"
"46803","280.78400","23.39881","0.29538"
"46860","281.12600","23.42745","0.29500"
"46917","281.46800","23.45579","0.29685"
"46974","281.81000","23.48431","0.29723"
"47031","282.15200","23.51283","0.29739"
"47088","282.49400","23.54135","0.29775"
"47145","282.83600","23.56987","0.29829"
"47202","283.17800","23.59833","0.29865"
"47259","283.52000","23.62685","0.30008"
"47316","283.86200","23.65537","0.30174"
"47373","284.20400","23.68377","0.30383"
"47430","284.54600","23.71235","0.30600"
"47487","284.88800","23.74087","0.30879"
"47544","285.23000","23.76921","0.31185"
"47601","285.57200","23.79785","0.31554"
"47658","285.91400","23.82637","0.31980"
"47715","286.25600","23.85483","0.32458"
"47772","286.59800","23.88341","0.32916"
"47829","286.94000","23.91181","0.33525"
"47886","287.28200","23.94033","0.33861"
"47943","287.62400","23.96885","0.34214"
"48000","287.96600","23.99730","0.34432"
"48057","288.30800","24.02589","0.34615"
"48114","288.65000","24.05435","0.34756"
"48171","288.99200","24.08281","0.34928"
"48228","289.33400","24.11133","0.35082"
"48285","289.67600","24.13984","0.35373"
"48342","290.01800","24.16830","0.35699"
"48399","290.36000","24.19694","0.36036"
"48456","290.70200","24.22528","0.36588"
"48513","291.04400","24.25380","0.36933"
"48570","291.38600","24.28232","0.37202"
"48627","291.72800","24.31078","0.37381"
"48684","292.07000","24.33936","0.37658"
"48741","292.41200","24.36782","0.37893"
"48798","292.75400","24.39634","0.38049"
"48855","293.09600","24.42486","0.38268"
"48912","293.43800","24.45332","0.38506"
"48969","293.78000","24.48178","0.38734"
"49026","294.12200","24.51036","0.38869"
"49083","294.46400","24.53882","0.39116"
"49140","294.80600","24.56734","0.39441"
"49197","295.14800","24.59586","0.39578"
"49254","295.49000","24.62438","0.39863"
"49311","295.83200","24.65284","0.40097"
"49368","296.17400","24.68136","0.40347"
"49425","296.51600","24.70982","0.40583"
"49482","296.85800","24.73834","0.40940"
"49539","297.20000","24.76686","0.41271"
"49596","297.54200","24.79532","0.41565"
"49653","297.88400","24.82384","0.41957"
"49710","298.22600","24.85230","0.42279"
"49767","298.56800","24.88082","0.42703"
"49824","298.91000","24.90940","0.43048"
"49881","299.25200","24.93774","0.43337"
"49938","299.59400","24.96632","0.43621"
"49995","299.93600","24.99483","0.44034"
"50052","300.27800","25.02330","0.44378"
"50109","300.62000","25.05187","0.44442"
"50166","300.96200","25.08033","0.44538"
"50223","301.30400","25.10879","0.44581"
"50280","301.64600","25.13737","0.44640"
"50337","301.98800","25.16583","0.44725"
"50394","302.33000","25.19435","0.44832"
"50451","302.67200","25.22281","0.45060"
"50508","303.01400","25.25127","0.45687"
"50565","303.35600","25.27985","0.46521"
"50622","303.69800","25.30837","0.47188"
"50679","304.04000","25.33677","0.47893"
"50736","304.38200","25.36535","0.48382"
"50793","304.72400","25.39387","0.49005"
"50850","305.06600","25.42233","0.49413"
"50907","305.40800","25.45085","0.49848"
"50964","305.75000","25.47931","0.50190"
"51021","306.09200","25.50789","0.50558"
"51078","306.43400","25.53635","0.50769"
"51135","306.77600","25.56475","0.50894"
"51192","307.11800","25.59339","0.50991"
"51249","307.46000","25.62185","0.51178"
"51306","307.80200","25.65031","0.51449"
"51363","308.14400","25.67889","0.51700"
"51420","308.48600","25.70729","0.52084"
"51477","308.82800","25.73581","0.52532"
"51534","309.17000","25.76433","0.52152"
"51591","309.51200","25.79279","0.52796"
"51648","309.85400","25.82131","0.53401"
"51705","310.19600","25.84983","0.54084"
"51762","310.53800","25.87829","0.54743"
"51819","310.88000","25.90686","0.55083"
"51876","311.22200","25.93538","0.55317"
"51933","311.56400","25.96384","0.55634"
"51990","311.90600","25.99236","0.56052"
"52047","312.24800","26.02082","0.56709"
"52104","312.59000","26.04934","0.57292"
"52161","312.93200","26.07780","0.57861"
"52218","313.27400","26.10638","0.58384"
"52275","313.61600","26.13484","0.58600"
"52332","313.95800","26.16330","0.58984"
"52389","314.30000","26.19176","0.59405"
"52446","314.64200","26.22034","0.59578"
"52503","314.98400","26.24892","0.59686"
"52560","315.32600","26.27726","0.59748"
"52617","315.66800","26.30584","0.59798"
"52674","316.01000","26.33436","0.59909"
"52731","316.35200","26.36282","0.60054"
"52788","316.69400","26.39134","0.60352"
"52845","317.03600","26.41980","0.60720"
"52902","317.37800","26.44832","0.61201"
"52959","317.72000","26.47690","0.61630"
"53016","318.06200","26.50530","0.61930"
"53073","318.40400","26.53388","0.62259"
"53130","318.74600","26.56240","0.62686"
"53187","319.08800","26.59086","0.63121"
"53244","319.43000","26.61938","0.63641"
"53301","319.77200","26.64784","0.64234"
"53358","320.11400","26.67636","0.64631"
"53415","320.45600","26.70487","0.64922"
"53472","320.79800","26.73328","0.65355"
"53529","321.14000","26.76185","0.65543"
"53586","321.48200","26.79037","0.65660"
"53643","321.82400","26.81883","0.65722"
"53700","322.16600","26.84735","0.65831"
"53757","322.50800","26.87581","0.66036"
"53814","322.85000","26.90427","0.66345"
"53871","323.19200","26.93285","0.66799"
"53928","323.53400","26.96137","0.67317"
"53985","323.87600","26.98983","0.67827"
"54042","324.21800","27.01835","0.68095"
"54099","324.56000","27.04675","0.68434"
"54156","324.90200","27.07539","0.68697"
"54213","325.24400","27.10391","0.68968"
"54270","325.58600","27.13231","0.69267"
"54327","325.92800","27.16089","0.69572"
"54384","326.27000","27.18929","0.69889"
"54441","326.61200","27.21781","0.70127"
"54498","326.95400","27.24639","0.70285"
"54555","327.29600","27.27485","0.70431"
"54612","327.63800","27.30337","0.70541"
"54669","327.98000","27.33183","0.70625"
"54726","328.32200","27.36029","0.70711"
"54783","328.66400","27.38881","0.70858"
"54840","329.00600","27.41733","0.71024"
"54897","329.34800","27.44585","0.71172"
"54954","329.69000","27.47437","0.71379"
"55011","330.03200","27.50283","0.71622"
"55068","330.37400","27.53135","0.72010"
"55125","330.71600","27.55987","0.59093"
"55182","331.05800","27.58833","0.59569"
"55239","331.40000","27.61679","0.59323"
"55296","331.74200","27.64536","0.59551"
"55353","332.08400","27.67382","0.59602"
"55410","332.42600","27.70228","0.59667"
"55467","332.76800","27.73092","0.59784"
"55524","333.11000","27.75933","0.59801"
"55581","333.45200","27.78784","0.60032"
"55638","333.79400","27.81636","0.59980"
"55695","334.13600","27.84482","0.60355"
"55752","334.47800","27.87334","0.60469"
"55809","334.82000","27.90180","0.60994"
"55866","335.16200","27.93032","0.61297"
"55923","335.50400","27.95884","0.61805"
"55980","335.84600","27.98730","0.62088"
"56037","336.18800","28.01582","0.62484"
"56094","336.53000","28.04434","0.62942"
"56151","336.87200","28.07274","0.63278"
"56208","337.21400","28.10138","0.63737"
"56265","337.55600","28.12978","0.63949"
"56322","337.89800","28.15830","0.64240"
"56379","338.24000","28.18688","0.64531"
"56436","338.58200","28.21534","0.64847"
"56493","338.92400","28.24386","0.65238"
"56550","339.26600","28.27238","0.65376"
"56607","339.60800","28.30078","0.65531"
"56664","339.95000","28.32936","0.65643"
"56721","340.29200","28.35788","0.65672"
"56778","340.63400","28.38628","0.65721"
"56835","340.97600","28.41486","0.65752"
"56892","341.31800","28.44332","0.65776"
"56949","341.66000","28.47183","0.65805"
"57006","342.00200","28.50035","0.65925"
"57063","342.34400","28.52881","0.66044"
"57120","342.68600","28.55733","0.66108"
"57177","343.02800","28.58586","0.66104"
"57234","343.37000","28.61425","0.66155"
"57291","343.71200","28.64289","0.66238"
"57348","344.05400","28.67135","0.66454"
"57405","344.39600","28.69981","0.66744"
"57462","344.73800","28.72839","0.67188"
"57519","345.08000","28.75685","0.67531"
"57576","345.42200","28.78531","0.67747"
"57633","345.76400","28.81377","0.67932"
"57690","346.10600","28.84229","0.68076"
"57747","346.44800","28.87081","0.68331"
"57804","346.79000","28.89939","0.68583"
"57861","347.13200","28.92779","0.68886"
"57918","347.47400","28.95631","0.68892"
"57975","347.81600","28.98483","0.69200"
"58032","348.15800","29.01329","0.69528"
"58089","348.50000","29.04181","0.69795"
"58146","348.84200","29.07039","0.69996"
"58203","349.18400","29.09885","0.70165"
"58260","349.52600","29.12731","0.70264"
"58317","349.86800","29.15583","0.70408"
"58374","350.21000","29.18435","0.70561"
"58431","350.55200","29.21287","0.70640"
"58488","350.89400","29.24127","0.70689"
"58545","351.23600","29.26985","0.70794"
"58602","351.57800","29.29831","0.70856"
"58659","351.92000","29.32683","0.70902"
"58716","352.26200","29.35534","0.70919"
"58773","352.60400","29.38380","0.70940"
"58830","352.94600","29.41232","0.70986"
"58887","353.28800","29.44090","0.71042"
"58944","353.63000","29.46930","0.71052"
"59001","353.97200","29.49782","0.71120"
"59058","354.31400","29.52641","0.71206"
"59115","354.65600","29.55480","0.71296"
"59172","354.99800","29.58332","0.71457"
"59229","355.34000","29.61185","0.71593"
"59286","355.68200","29.64030","0.71634"
"59343","356.02400","29.66888","0.71943"
"59400","356.36600","29.69734","0.72266"
"59457","356.70800","29.72580","0.32663"
"59514","357.05000","29.75438","0.30399"
"59571","357.39200","29.78278","0.29890"
"59628","357.73400","29.81136","0.29971"
"59685","358.07600","29.83988","0.30476"
"59742","358.41800","29.86822","0.31181"
"59799","358.76000","29.89692","0.31005"
"59856","359.10200","29.92538","0.30455"
"59913","359.44400","29.95384","0.30488"
"59970","359.78600","29.98236","0.30957"
"60027","360.12800","30.01076","0.31566"
"60084","360.47000","30.03928","0.31591"
"60141","360.81200","30.06786","0.31407"
"60198","361.15400","30.09626","0.31530"
"60255","361.49600","30.12490","0.32028"
"60312","361.83800","30.15336","0.32435"
"60369","362.18000","30.18182","0.32356"
"60426","362.52200","30.21040","0.32342"
"60483","362.86400","30.23886","0.32574"
"60540","363.20600","30.26731","0.32964"
"60597","363.54800","30.29583","0.33056"
"60654","363.89000","30.32430","0.33063"
"60711","364.23200","30.35287","0.33465"
"60768","364.57400","30.38133","0.33771"
"60825","364.91600","30.40980","0.33873"
"60882","365.25800","30.43831","0.33969"
"60939","365.60000","30.46683","0.34174"
"60996","365.94200","30.49536","0.34338"
"61053","366.28400","30.52382","0.34397"
"61110","366.62600","30.55239","0.34529"
"61167","366.96800","30.58080","0.34609"
"61224","367.31000","30.60937","0.34710"
"61281","367.65200","30.63783","0.34799"
"61338","367.99400","30.66635","0.34764"
"61395","368.33600","30.69487","0.34820"
"61452","368.67800","30.72333","0.34931"
"61509","369.02000","30.75185","0.35120"
"61566","369.36200","30.78037","0.35182"
"61623","369.70400","30.80877","0.35287"
"61680","370.04600","30.83735","0.35663"
"61737","370.38800","30.86587","0.36039"
"61794","370.73000","30.89433","0.36192"
"61851","371.07200","30.92285","0.36459"
"61908","371.41400","30.95131","0.36566"
"61965","371.75600","30.97983","0.36761"
"62022","372.09800","31.00841","0.37036"
"62079","372.44000","31.03681","0.37156"
"62136","372.78200","31.06533","0.37364"
"62193","373.12400","31.09391","0.37428"
"62250","373.46600","31.12231","0.37542"
"62307","373.80800","31.15083","0.37678"
"62364","374.15000","31.17935","0.37763"
"62421","374.49200","31.20781","0.37897"
"62478","374.83400","31.23633","0.38008"
"62535","375.17600","31.26484","0.38128"
"62592","375.51800","31.29330","0.38117"
"62649","375.86000","31.32188","0.38191"
"62706","376.20200","31.35028","0.38282"
"62763","376.54400","31.37886","0.38304"
"62820","376.88600","31.40744","0.38323"
"62877","377.22800","31.43578","0.38484"
"62934","377.57000","31.46436","0.38577"
"62991","377.91200","31.49282","0.38601"
"63048","378.25400","31.52134","0.38680"
"63105","378.59600","31.54986","0.38679"
"63162","378.93800","31.57832","0.38804"
"63219","379.28000","31.60684","0.38865"
"63276","379.62200","31.63530","0.38999"
"63333","379.96400","31.66376","0.39121"
"63390","380.30600","31.69234","0.39264"
"63447","380.64800","31.72086","0.39357"
"63504","380.99000","31.74938","0.39429"
"63561","381.33200","31.77784","0.39481"
"63618","381.67400","31.80630","0.39544"
"63675","382.01600","31.83482","0.39625"
"63732","382.35800","31.86333","0.19015"
"63789","382.70000","31.89186","0.08808"
"63846","383.04200","31.92038","0.08162"
"63903","383.38400","31.94884","0.09722"
"63960","383.72600","31.97729","0.10365"
"64017","384.06800","32.00581","0.08133"
"64074","384.41000","32.03433","0.09831"
"64131","384.75200","32.06285","0.10988"
"64188","385.09400","32.09137","0.08392"
"64245","385.43600","32.11983","0.10016"
"64302","385.77800","32.14829","0.11545"
"64359","386.12000","32.17681","0.09114"
"64416","386.46200","32.20533","0.10528"
"64473","386.80400","32.23385","0.10585"
"64530","387.14600","32.26237","0.12087"
"64587","387.48800","32.29083","0.11178"
"64644","387.83000","32.31935","0.09965"
"64701","388.17200","32.34787","0.13551"
"64758","388.51400","32.37627","0.12527"
"64815","388.85600","32.40479","0.10499"
"64872","389.19800","32.43337","0.13092"
"64929","389.54000","32.46183","0.13649"
"64986","389.88200","32.49041","0.12223"
"65043","390.22400","32.51881","0.13416"
"65100","390.56600","32.54733","0.13154"
"65157","390.90800","32.57585","0.13801"
"65214","391.25000","32.60431","0.14300"
"65271","391.59200","32.63289","0.13458"
"65328","391.93400","32.66141","0.13744"
"65385","392.27600","32.68981","0.14494"
"65442","392.61800","32.71839","0.14269"
"65499","392.96000","32.74685","0.13959"
"65556","393.30200","32.77531","0.14457"
"65613","393.64400","32.80389","0.14457"
"65670","393.98600","32.83229","0.14421"
"65727","394.32800","32.86086","0.14578"
"65784","394.67000","32.88939","0.14504"
"65841","395.01200","32.91779","0.14493"
"65898","395.35400","32.94636","0.14798"
"65955","395.69600","32.97482","0.14963"
"66012","396.03800","33.00335","0.14559"
"66069","396.38000","33.03192","0.14754"
"66126","396.72200","33.06032","0.15154"
"66183","397.06400","33.08878","0.14929"
"66240","397.40600","33.11736","0.14970"
"66297","397.74800","33.14576","0.15346"
"66354","398.09000","33.17434","0.15075"
"66411","398.43200","33.20280","0.15289"
"66468","398.77400","33.23126","0.15723"
"66525","399.11600","33.25984","0.15741"
"66582","399.45800","33.28836","0.15541"
"66639","399.80000","33.31682","0.15861"
"66696","400.14200","33.34534","0.16120"
"66753","400.48400","33.37380","0.16001"
"66810","400.82600","33.40232","0.16199"
"66867","401.16800","33.43084","0.16497"
"66924","401.51000","33.45930","0.16426"
"66981","401.85200","33.48788","0.16376"
"67038","402.19400","33.51633","0.16685"
"67095","402.53600","33.54486","0.16882"
"67152","402.87800","33.57338","0.16868"
"67209","403.22000","33.60184","0.16952"
"67266","403.56200","33.63029","0.17213"
"67323","403.90400","33.65888","0.17260"
"67380","404.24600","33.68734","0.17298"
"67437","404.58800","33.71585","0.17524"
"67494","404.93000","33.74432","0.17646"
"67551","405.27200","33.77277","0.17676"
"67608","405.61400","33.80130","0.17767"
"67665","405.95600","33.82988","0.17916"
"67722","406.29800","33.85827","0.18006"
"67779","406.64000","33.88685","0.18023"
"67836","406.98200","33.91537","0.18083"
"67893","407.32400","33.94383","0.18213"
"67950","407.66600","33.97235","0.18265"
"68007","408.00800","34.00081","0.18299"
"68064","408.35000","34.02933","0.18359"
"68121","408.69200","34.05785","0.18452"
"68178","409.03400","34.08631","0.18463"
"68235","409.37600","34.11483","0.18497"
"68292","409.71800","34.14341","0.18595"
"68349","410.06000","34.17175","0.18607"
"68406","410.40200","34.20039","0.18635"
"68463","410.74400","34.22885","0.18678"
"68520","411.08600","34.25731","0.18742"
"68577","411.42800","34.28589","0.18754"
"68634","411.77000","34.31429","0.18760"
"68691","412.11200","34.34281","0.18779"
"68748","412.45400","34.37139","0.18832"
"68805","412.79600","34.39979","0.18881"
"68862","413.13800","34.42836","0.18941"
"68919","413.48000","34.45683","0.18970"
"68976","413.82200","34.48529","0.19047"
"69033","414.16400","34.51387","0.19083"
"69090","414.50600","34.54232","0.19129"
"69147","414.84800","34.57085","0.19148"
"69204","415.19000","34.59937","0.19239"
"69261","415.53200","34.62777","0.19254"
"69318","415.87400","34.65635","0.19283"
"69375","416.21600","34.68486","0.19334"
"69432","416.55800","34.71326","0.19361"
"69489","416.90000","34.74184","0.19388"
"69546","417.24200","34.77030","0.19365"
"69603","417.58400","34.79882","0.19399"
"69660","417.92600","34.82740","0.19424"
"69717","418.26800","34.85586","0.19479"
"69774","418.61000","34.88432","0.19431"
"69831","418.95200","34.91284","0.00081"
"69888","419.29400","34.94130","0.00573"
"69945","419.63600","34.96982","0.00284"
"70002","419.97800","34.99834","0.00149"
"70059","420.32000","35.02680","0.00105"
"70116","420.66200","35.05538","0.00170"
"70173","421.00400","35.08384","0.00083"
"70230","421.34600","35.11230","0.00039"
"70287","421.68800","35.14088","0.00039"
"70344","422.03000","35.16934","-0.00011"
"70401","422.37200","35.19780","-0.00008"
"70408","422.41200","35.20109","0.00047"