File: Trajectories_together/170107_1Specimen_RawData_6.csv
"","V1","V2","V3"
"1","End date","1/7/2017",""
"2","Specimen label","18DT_47",""
"3","Maximum Load","0.09977","N"
"4","Time","Extension","Load"
"5","(s)","(mm)","(N)"
"6","0.00000","0.00000","-0.00002"
"59","0.31800","0.02619","-0.00009"
"112","0.63600","0.05321","-0.00001"
"165","0.95400","0.07976","-0.00008"
"218","1.27200","0.10619","-0.00031"
"271","1.59000","0.13273","0.00025"
"324","1.90800","0.15916","0.00022"
"377","2.22600","0.18571","-0.00006"
"430","2.54400","0.21225","0.00009"
"483","2.86200","0.23862","0.00065"
"536","3.18000","0.26517","0.00012"
"589","3.49800","0.29165","0.00090"
"642","3.81600","0.31820","0.00071"
"695","4.13400","0.34475","0.00031"
"748","4.45200","0.37117","0.00045"
"801","4.77000","0.39766","0.00086"
"854","5.08800","0.42409","0.00072"
"907","5.40600","0.45075","0.00064"
"960","5.72400","0.47724","0.00050"
"1013","6.04200","0.50373","0.00102"
"1066","6.36000","0.53021","0.00077"
"1119","6.67800","0.55664","0.00067"
"1172","6.99600","0.58325","0.00131"
"1225","7.31400","0.60967","0.00124"
"1278","7.63200","0.63622","0.00147"
"1331","7.95000","0.66271","0.00165"
"1384","8.26800","0.68919","0.00115"
"1437","8.58600","0.71574","0.00148"
"1490","8.90400","0.74217","0.00172"
"1543","9.22200","0.76871","0.00175"
"1596","9.54000","0.79520","0.00116"
"1649","9.85800","0.82169","0.00111"
"1702","10.17600","0.84823","0.00194"
"1755","10.49400","0.87466","0.00175"
"1808","10.81200","0.90121","0.00181"
"1861","11.13000","0.92775","0.00221"
"1914","11.44800","0.95418","0.00218"
"1967","11.76600","0.98073","0.00206"
"2020","12.08400","1.00721","0.00198"
"2073","12.40200","1.03370","0.00234"
"2126","12.72000","1.06025","0.00169"
"2179","13.03800","1.08667","0.00183"
"2232","13.35600","1.11316","0.00242"
"2285","13.67400","1.13959","0.00249"
"2338","13.99200","1.16625","0.00159"
"2391","14.31000","1.19268","0.00196"
"2444","14.62800","1.21923","0.00231"
"2497","14.94600","1.24571","0.00237"
"2550","15.26400","1.27214","0.00255"
"2603","15.58200","1.29875","0.00220"
"2656","15.90000","1.32518","0.00262"
"2709","16.21800","1.35172","0.00251"
"2762","16.53600","1.37821","0.00292"
"2815","16.85400","1.40464","0.00270"
"2868","17.17200","1.43118","0.00312"
"2921","17.49000","1.45767","0.00296"
"2974","17.80800","1.48416","0.00265"
"3027","18.12600","1.51070","0.00316"
"3080","18.44400","1.53719","0.00294"
"3133","18.76200","1.56374","0.00278"
"3186","19.08000","1.59016","0.00202"
"3239","19.39800","1.61671","0.00293"
"3292","19.71600","1.64320","0.00359"
"3345","20.03400","1.66968","0.00283"
"3398","20.35200","1.69623","0.00355"
"3451","20.67000","1.72266","0.00325"
"3504","20.98800","1.74920","0.00290"
"3557","21.30600","1.77569","0.00282"
"3610","21.62400","1.80224","0.00334"
"3663","21.94200","1.82872","0.00313"
"3716","22.26000","1.85509","0.00287"
"3769","22.57800","1.88170","0.00328"
"3822","22.89600","1.90818","0.00317"
"3875","23.21400","1.93467","0.00276"
"3928","23.53200","1.96122","0.00331"
"3981","23.85000","1.98770","0.00315"
"4034","24.16800","2.01419","0.00404"
"4087","24.48600","2.04068","0.00411"
"4140","24.80400","2.06722","0.00369"
"4193","25.12200","2.09377","0.00427"
"4246","25.44000","2.12014","0.00414"
"4299","25.75800","2.14668","0.00389"
"4352","26.07600","2.17317","0.00426"
"4405","26.39400","2.19972","0.00370"
"4458","26.71200","2.22620","0.00395"
"4511","27.03000","2.25269","0.00379"
"4564","27.34800","2.27924","0.00417"
"4617","27.66600","2.30572","0.00339"
"4670","27.98400","2.33221","0.00383"
"4723","28.30200","2.35870","0.00385"
"4776","28.62000","2.38512","0.00366"
"4829","28.93800","2.41173","0.00415"
"4882","29.25600","2.43822","0.00382"
"4935","29.57400","2.46476","0.00386"
"4988","29.89200","2.49119","0.00377"
"5041","30.21000","2.51774","0.00411"
"5094","30.52800","2.54428","0.00398"
"5147","30.84600","2.57065","0.00394"
"5200","31.16400","2.59720","0.00447"
"5253","31.48200","2.62368","0.00429"
"5306","31.80000","2.65023","0.00389"
"5359","32.11800","2.67672","0.00459"
"5412","32.43600","2.70320","0.00483"
"5465","32.75400","2.72969","0.00440"
"5518","33.07200","2.75612","0.00411"
"5571","33.39000","2.78278","0.00429"
"5624","33.70800","2.80921","0.00512"
"5677","34.02600","2.83564","0.00429"
"5730","34.34400","2.86218","0.00426"
"5783","34.66200","2.88867","0.00417"
"5836","34.98000","2.91522","0.00423"
"5889","35.29800","2.94170","0.00516"
"5942","35.61600","2.96819","0.00522"
"5995","35.93400","2.99474","0.00515"
"6048","36.25200","3.02117","0.00497"
"6101","36.57000","3.04771","0.00485"
"6154","36.88800","3.07420","0.00504"
"6207","37.20600","3.10063","0.00514"
"6260","37.52400","3.12717","0.00486"
"6313","37.84200","3.15372","0.00541"
"6366","38.16000","3.18021","0.00575"
"6419","38.47800","3.20663","0.00513"
"6472","38.79600","3.23318","0.00491"
"6525","39.11400","3.25973","0.00505"
"6578","39.43200","3.28621","0.00527"
"6631","39.75000","3.31270","0.00527"
"6684","40.06800","3.33919","0.00392"
"6737","40.38600","3.36567","0.00451"
"6790","40.70400","3.39222","0.00437"
"6843","41.02200","3.41871","0.00413"
"6896","41.34000","3.44519","0.00434"
"6949","41.65800","3.47162","0.00468"
"7002","41.97600","3.49823","0.00417"
"7055","42.29400","3.52471","0.00463"
"7108","42.61200","3.55120","0.00453"
"7161","42.93000","3.57769","0.00444"
"7214","43.24800","3.60417","0.00497"
"7267","43.56600","3.63072","0.00495"
"7320","43.88400","3.65715","0.00422"
"7373","44.20200","3.68375","0.00496"
"7426","44.52000","3.71024","0.00477"
"7479","44.83800","3.73667","0.00440"
"7532","45.15600","3.76321","0.00488"
"7585","45.47400","3.78964","0.00487"
"7638","45.79200","3.81613","0.00447"
"7691","46.11000","3.84267","0.00495"
"7744","46.42800","3.86916","0.00479"
"7797","46.74600","3.89571","0.00461"
"7850","47.06400","3.92213","0.00467"
"7903","47.38200","3.94874","0.00530"
"7956","47.70000","3.97523","0.00461"
"8009","48.01800","4.00171","0.00526"
"8062","48.33600","4.02820","0.00508"
"8115","48.65400","4.05463","0.00564"
"8168","48.97200","4.08123","0.00549"
"8221","49.29000","4.10766","0.00483"
"8274","49.60800","4.13427","0.00537"
"8327","49.92600","4.16075","0.00546"
"8380","50.24400","4.18712","0.00585"
"8433","50.56200","4.21373","0.00518"
"8486","50.88000","4.24021","0.00542"
"8539","51.19800","4.26670","0.00580"
"8592","51.51600","4.29319","0.00556"
"8645","51.83400","4.31967","0.00589"
"8698","52.15200","4.34616","0.00651"
"8751","52.47000","4.37271","0.00593"
"8804","52.78800","4.39925","0.00563"
"8857","53.10600","4.42568","0.00646"
"8910","53.42400","4.45217","0.00600"
"8963","53.74200","4.47865","0.00605"
"9016","54.06000","4.50520","0.00589"
"9069","54.37800","4.53169","0.00648"
"9122","54.69600","4.55817","0.00653"
"9175","55.01400","4.58466","0.00586"
"9228","55.33200","4.61121","0.00641"
"9281","55.65000","4.63763","0.00635"
"9334","55.96800","4.66424","0.00625"
"9387","56.28600","4.69067","0.00682"
"9440","56.60400","4.71715","0.00657"
"9493","56.92200","4.74370","0.00698"
"9546","57.24000","4.77013","0.00657"
"9599","57.55800","4.79673","0.00634"
"9652","57.87600","4.82310","0.00696"
"9705","58.19400","4.84971","0.00696"
"9758","58.51200","4.87626","0.00699"
"9811","58.83000","4.90268","0.00663"
"9864","59.14800","4.92923","0.00681"
"9917","59.46600","4.95566","0.00683"
"9970","59.78400","4.98220","0.00744"
"10023","60.10200","5.00869","0.00740"
"10076","60.42000","5.03517","0.00693"
"10129","60.73800","5.06166","0.00716"
"10182","61.05600","5.08809","0.00766"
"10235","61.37400","5.11470","0.00710"
"10288","61.69200","5.14118","0.00734"
"10341","62.01000","5.16767","0.00743"
"10394","62.32800","5.19422","0.00753"
"10447","62.64600","5.22070","0.00682"
"10500","62.96400","5.24719","0.00685"
"10553","63.28200","5.27368","0.00739"
"10606","63.60000","5.30016","0.00744"
"10659","63.91800","5.32665","0.00733"
"10712","64.23600","5.35314","0.00763"
"10765","64.55400","5.37968","0.00714"
"10818","64.87200","5.40617","0.00715"
"10871","65.19000","5.43272","0.00754"
"10924","65.50800","5.45920","0.00718"
"10977","65.82600","5.48569","0.00770"
"11030","66.14400","5.51224","0.00749"
"11083","66.46200","5.53860","0.00800"
"11136","66.78000","5.56515","0.00693"
"11189","67.09800","5.59170","0.00741"
"11242","67.41600","5.61818","0.00781"
"11295","67.73400","5.64473","0.00742"
"11348","68.05200","5.67110","0.00742"
"11401","68.37000","5.69770","0.00793"
"11454","68.68800","5.72419","0.00862"
"11507","69.00600","5.75068","0.00790"
"11560","69.32400","5.77716","0.00816"
"11613","69.64200","5.80359","0.00777"
"11666","69.96000","5.83026","0.00823"
"11719","70.27800","5.85674","0.00811"
"11772","70.59600","5.88323","0.00855"
"11825","70.91400","5.90972","0.00818"
"11878","71.23200","5.93614","0.00770"
"11931","71.55000","5.96269","0.00753"
"11984","71.86800","5.98918","0.00693"
"12037","72.18600","6.01566","0.00700"
"12090","72.50400","6.04221","0.00751"
"12143","72.82200","6.06864","0.00780"
"12196","73.14000","6.09524","0.00760"
"12249","73.45800","6.12167","0.00732"
"12302","73.77600","6.14816","0.00799"
"12355","74.09400","6.17470","0.00731"
"12408","74.41200","6.20119","0.00758"
"12461","74.73000","6.22774","0.00810"
"12514","75.04800","6.25411","0.00763"
"12567","75.36600","6.28071","0.00800"
"12620","75.68400","6.30720","0.00803"
"12673","76.00200","6.33368","0.00813"
"12726","76.32000","6.36023","0.00817"
"12779","76.63800","6.38666","0.00744"
"12832","76.95600","6.41320","0.00799"
"12885","77.27400","6.43969","0.00769"
"12938","77.59200","6.46624","0.00740"
"12991","77.91000","6.49266","0.00790"
"13044","78.22800","6.51915","0.00769"
"13097","78.54600","6.54570","0.00794"
"13150","78.86400","6.57212","0.00694"
"13203","79.18200","6.59873","0.00743"
"13256","79.50000","6.62522","0.00731"
"13309","79.81800","6.65165","0.00724"
"13362","80.13600","6.67819","0.00776"
"13415","80.45400","6.70468","0.00732"
"13468","80.77200","6.73123","0.00784"
"13521","81.09000","6.75771","0.00696"
"13574","81.40800","6.78414","0.00670"
"13627","81.72600","6.81069","0.00711"
"13680","82.04400","6.83717","0.00734"
"13733","82.36200","6.86366","0.00731"
"13786","82.68000","6.89015","0.00753"
"13839","82.99800","6.91663","0.00771"
"13892","83.31600","6.94324","0.00774"
"13945","83.63400","6.96967","0.00828"
"13998","83.95200","6.99621","0.00782"
"14051","84.27000","7.02270","0.00829"
"14104","84.58800","7.04919","0.00812"
"14157","84.90600","7.07573","0.00820"
"14210","85.22400","7.10216","0.00841"
"14263","85.54200","7.12871","0.00796"
"14316","85.86000","7.15519","0.00797"
"14369","86.17800","7.18174","0.00798"
"14422","86.49600","7.20823","0.00786"
"14475","86.81400","7.23465","0.00877"
"14528","87.13200","7.26120","0.00889"
"14581","87.45000","7.28763","0.00867"
"14634","87.76800","7.31417","0.00851"
"14687","88.08600","7.34072","0.00841"
"14740","88.40400","7.36715","0.00862"
"14793","88.72200","7.39369","0.00860"
"14846","89.04000","7.42012","0.00812"
"14899","89.35800","7.44667","0.00862"
"14952","89.67600","7.47315","0.00937"
"15005","89.99400","7.49964","0.00870"
"15058","90.31200","7.52619","0.00897"
"15111","90.63000","7.55267","0.00936"
"15164","90.94800","7.57922","0.00906"
"15217","91.26600","7.60565","0.00929"
"15270","91.58400","7.63219","0.00944"
"15323","91.90200","7.65868","0.00964"
"15376","92.22000","7.68517","0.00945"
"15429","92.53800","7.71171","0.01018"
"15482","92.85600","7.73814","0.00965"
"15535","93.17400","7.76469","0.01004"
"15588","93.49200","7.79123","0.00958"
"15641","93.81000","7.81766","0.00957"
"15694","94.12800","7.84421","0.00869"
"15747","94.44600","7.87063","0.00801"
"15800","94.76400","7.89718","0.00785"
"15853","95.08200","7.92373","0.00844"
"15906","95.40000","7.95021","0.00795"
"15959","95.71800","7.97670","0.00872"
"16012","96.03600","8.00313","0.00876"
"16065","96.35400","8.02967","0.00825"
"16118","96.67200","8.05616","0.00909"
"16171","96.99000","8.08265","0.00906"
"16224","97.30800","8.10919","0.00907"
"16277","97.62600","8.13562","0.00926"
"16330","97.94400","8.16223","0.00917"
"16383","98.26200","8.18871","0.00878"
"16436","98.58000","8.21520","0.00933"
"16489","98.89800","8.24169","0.00835"
"16542","99.21600","8.26812","0.00757"
"16595","99.53400","8.29466","0.00809"
"16648","99.85200","8.32121","0.00845"
"16701","100.17000","8.34769","0.00784"
"16754","100.48800","8.37424","0.00801"
"16807","100.80600","8.40067","0.00796"
"16860","101.12400","8.42721","0.00875"
"16913","101.44200","8.45370","0.00799"
"16966","101.76000","8.48019","0.00919"
"17019","102.07800","8.50668","0.00841"
"17072","102.39600","8.53316","0.00836"
"17125","102.71400","8.55971","0.00817"
"17178","103.03200","8.58614","0.00855"
"17231","103.35000","8.61274","0.00899"
"17284","103.66800","8.63917","0.00921"
"17337","103.98600","8.66566","0.00861"
"17390","104.30400","8.69220","0.00994"
"17443","104.62200","8.71863","0.00921"
"17496","104.94000","8.74524","0.00834"
"17549","105.25800","8.77166","0.00737"
"17602","105.57600","8.79821","0.00781"
"17655","105.89400","8.82476","0.00839"
"17708","106.21200","8.85118","0.00824"
"17761","106.53000","8.87773","0.00827"
"17814","106.84800","8.90422","0.00863"
"17867","107.16600","8.93070","0.00862"
"17920","107.48400","8.95725","0.00877"
"17973","107.80200","8.98362","0.00829"
"18026","108.12000","9.01016","0.00806"
"18079","108.43800","9.03665","0.00817"
"18132","108.75600","9.06320","0.00858"
"18185","109.07400","9.08974","0.00863"
"18238","109.39200","9.11617","0.00868"
"18291","109.71000","9.14272","0.00925"
"18344","110.02800","9.16914","0.00906"
"18397","110.34600","9.19569","0.00874"
"18450","110.66400","9.22218","0.00923"
"18503","110.98200","9.24866","0.00930"
"18556","111.30000","9.27527","0.00899"
"18609","111.61800","9.30170","0.00874"
"18662","111.93600","9.32824","0.00974"
"18715","112.25400","9.35467","0.00927"
"18768","112.57200","9.38116","0.00952"
"18821","112.89000","9.40776","0.01022"
"18874","113.20800","9.43419","0.00959"
"18927","113.52600","9.46068","0.00962"
"18980","113.84400","9.48722","0.01018"
"19033","114.16200","9.51371","0.00906"
"19086","114.48000","9.54026","0.00959"
"19139","114.79800","9.56668","0.00967"
"19192","115.11600","9.59317","0.00962"
"19245","115.43400","9.61966","0.00966"
"19298","115.75200","9.64620","0.00959"
"19351","116.07000","9.67275","0.01021"
"19404","116.38800","9.69918","0.00971"
"19457","116.70600","9.72567","0.00986"
"19510","117.02400","9.75215","0.01046"
"19563","117.34200","9.77876","0.01017"
"19616","117.66000","9.80518","0.01057"
"19669","117.97800","9.83161","0.01037"
"19722","118.29600","9.85822","0.01057"
"19775","118.61400","9.88470","0.01085"
"19828","118.93200","9.91125","0.01040"
"19881","119.25000","9.93768","0.01114"
"19934","119.56800","9.96417","0.01127"
"19987","119.88600","9.99071","0.01082"
"20040","120.20400","10.01714","0.01121"
"20093","120.52200","10.04375","0.01094"
"20146","120.84000","10.07017","0.01101"
"20199","121.15800","10.09666","0.01107"
"20252","121.47600","10.12321","0.01139"
"20305","121.79400","10.14969","0.01178"
"20358","122.11200","10.17618","0.01171"
"20411","122.43000","10.20261","0.01168"
"20464","122.74800","10.22915","0.01174"
"20517","123.06600","10.25576","0.01204"
"20570","123.38400","10.28218","0.01147"
"20623","123.70200","10.30873","0.01213"
"20676","124.02000","10.33516","0.01204"
"20729","124.33800","10.36170","0.01190"
"20782","124.65600","10.38825","0.01264"
"20835","124.97400","10.41468","0.01188"
"20888","125.29200","10.44123","0.01231"
"20941","125.61000","10.46759","0.01161"
"20994","125.92800","10.49420","0.01265"
"21047","126.24600","10.52069","0.01257"
"21100","126.56400","10.54717","0.01253"
"21153","126.88200","10.57372","0.01274"
"21206","127.20000","10.60015","0.01237"
"21259","127.51800","10.62669","0.01317"
"21312","127.83600","10.65318","0.01336"
"21365","128.15400","10.67973","0.01357"
"21418","128.47200","10.70621","0.01311"
"21471","128.79000","10.73270","0.01367"
"21524","129.10800","10.75925","0.01321"
"21577","129.42600","10.78567","0.01336"
"21630","129.74400","10.81222","0.01428"
"21683","130.06200","10.83871","0.01436"
"21736","130.38000","10.86519","0.01365"
"21789","130.69800","10.89174","0.01381"
"21842","131.01600","10.91817","0.01401"
"21895","131.33400","10.94471","0.01414"
"21948","131.65200","10.97120","0.01397"
"22001","131.97000","10.99769","0.01407"
"22054","132.28800","11.02423","0.01409"
"22107","132.60600","11.05072","0.01420"
"22160","132.92400","11.07721","0.01445"
"22213","133.24200","11.10369","0.01366"
"22266","133.56000","11.13024","0.01340"
"22319","133.87800","11.15673","0.01366"
"22372","134.19600","11.18315","0.01370"
"22425","134.51400","11.20970","0.01365"
"22478","134.83200","11.23619","0.01421"
"22531","135.15000","11.26273","0.01430"
"22584","135.46800","11.28928","0.01404"
"22637","135.78600","11.31571","0.01391"
"22690","136.10400","11.34219","0.01460"
"22743","136.42200","11.36868","0.01444"
"22796","136.74000","11.39517","0.01424"
"22849","137.05800","11.42171","0.01419"
"22902","137.37600","11.44820","0.01452"
"22955","137.69400","11.47475","0.01405"
"23008","138.01200","11.50117","0.01475"
"23061","138.33000","11.52772","0.01442"
"23114","138.64800","11.55415","0.01485"
"23167","138.96600","11.58063","0.01400"
"23220","139.28400","11.60724","0.01486"
"23273","139.60200","11.63367","0.01455"
"23326","139.92000","11.66021","0.01459"
"23379","140.23800","11.68670","0.01473"
"23432","140.55600","11.71313","0.01457"
"23485","140.87400","11.73973","0.01523"
"23538","141.19200","11.76616","0.01539"
"23591","141.51000","11.79271","0.01556"
"23644","141.82800","11.81919","0.01529"
"23697","142.14600","11.84574","0.01516"
"23750","142.46400","11.87229","0.01533"
"23803","142.78200","11.89860","0.01560"
"23856","143.10000","11.92520","0.01594"
"23909","143.41800","11.95163","0.01605"
"23962","143.73600","11.97823","0.01600"
"24015","144.05400","12.00478","0.01618"
"24068","144.37200","12.03121","0.01674"
"24121","144.69000","12.05775","0.01626"
"24174","145.00800","12.08418","0.01606"
"24227","145.32600","12.11079","0.01639"
"24280","145.64400","12.13721","0.01634"
"24333","145.96200","12.16364","0.01643"
"24386","146.28000","12.19019","0.01605"
"24439","146.59800","12.21667","0.01623"
"24492","146.91600","12.24328","0.01707"
"24545","147.23400","12.26965","0.01698"
"24598","147.55200","12.29614","0.01731"
"24651","147.87000","12.32268","0.01755"
"24704","148.18800","12.34917","0.01745"
"24757","148.50600","12.37572","0.01767"
"24810","148.82400","12.40220","0.01751"
"24863","149.14200","12.42863","0.01757"
"24916","149.46000","12.45524","0.01811"
"24969","149.77800","12.48166","0.01818"
"25022","150.09600","12.50821","0.01823"
"25075","150.41400","12.53470","0.01845"
"25128","150.73200","12.56118","0.01890"
"25181","151.05000","12.58773","0.01873"
"25234","151.36800","12.61416","0.01810"
"25287","151.68600","12.64070","0.01817"
"25340","152.00400","12.66713","0.01849"
"25393","152.32200","12.69374","0.01883"
"25446","152.64000","12.72022","0.01891"
"25499","152.95800","12.74665","0.01897"
"25552","153.27600","12.77320","0.01901"
"25605","153.59400","12.79962","0.01922"
"25658","153.91200","12.82623","0.01952"
"25711","154.23000","12.85272","0.01957"
"25764","154.54800","12.87920","0.01996"
"25817","154.86600","12.90569","0.02024"
"25870","155.18400","12.93212","0.02000"
"25923","155.50200","12.95872","0.01987"
"25976","155.82000","12.98521","0.02014"
"26029","156.13800","13.01170","0.02029"
"26082","156.45600","13.03818","0.02011"
"26135","156.77400","13.06473","0.02044"
"26188","157.09200","13.09128","0.02036"
"26241","157.41000","13.11770","0.02112"
"26294","157.72800","13.14425","0.02167"
"26347","158.04600","13.17074","0.02174"
"26400","158.36400","13.19716","0.02212"
"26453","158.68200","13.22371","0.02202"
"26506","159.00000","13.25020","0.02245"
"26559","159.31800","13.27668","0.02301"
"26612","159.63600","13.30323","0.02302"
"26665","159.95400","13.32966","0.02324"
"26718","160.27200","13.35620","0.02336"
"26771","160.59000","13.38263","0.02331"
"26824","160.90800","13.40924","0.02419"
"26877","161.22600","13.43566","0.02441"
"26930","161.54400","13.46215","0.02462"
"26983","161.86200","13.48870","0.02475"
"27036","162.18000","13.51513","0.02517"
"27089","162.49800","13.54173","0.02556"
"27142","162.81600","13.56822","0.02615"
"27195","163.13400","13.59471","0.02659"
"27248","163.45200","13.62119","0.02645"
"27301","163.77000","13.64762","0.02634"
"27354","164.08800","13.67423","0.02545"
"27407","164.40600","13.70071","0.02598"
"27460","164.72400","13.72720","0.02624"
"27513","165.04200","13.75375","0.02691"
"27566","165.36000","13.78017","0.02693"
"27619","165.67800","13.80672","0.02792"
"27672","165.99600","13.83321","0.02833"
"27725","166.31400","13.85963","0.02818"
"27778","166.63200","13.88612","0.02912"
"27831","166.95000","13.91261","0.02905"
"27884","167.26800","13.93921","0.02907"
"27937","167.58600","13.96570","0.02957"
"27990","167.90400","13.99219","0.03014"
"28043","168.22200","14.01867","0.03026"
"28096","168.54000","14.04516","0.03056"
"28149","168.85800","14.07171","0.03071"
"28202","169.17600","14.09813","0.03158"
"28255","169.49400","14.12480","0.03190"
"28308","169.81200","14.15117","0.03151"
"28361","170.13000","14.17771","0.03099"
"28414","170.44800","14.20420","0.03168"
"28467","170.76600","14.23069","0.03245"
"28520","171.08400","14.25717","0.03348"
"28573","171.40200","14.28366","0.03341"
"28626","171.72000","14.31027","0.03417"
"28679","172.03800","14.33669","0.03468"
"28732","172.35600","14.36318","0.03514"
"28785","172.67400","14.38967","0.03614"
"28838","172.99200","14.41615","0.03638"
"28891","173.31000","14.44270","0.03690"
"28944","173.62800","14.46919","0.03715"
"28997","173.94600","14.49567","0.03836"
"29050","174.26400","14.52222","0.03890"
"29103","174.58200","14.54865","0.03960"
"29156","174.90000","14.57525","0.03978"
"29209","175.21800","14.60168","0.04115"
"29262","175.53600","14.62811","0.04149"
"29315","175.85400","14.65471","0.03946"
"29368","176.17200","14.68114","0.03875"
"29421","176.49000","14.70775","0.03895"
"29474","176.80800","14.73417","0.04056"
"29527","177.12600","14.76072","0.04172"
"29580","177.44400","14.78721","0.04184"
"29633","177.76200","14.81369","0.04186"
"29686","178.08000","14.84018","0.04363"
"29739","178.39800","14.86667","0.04405"
"29792","178.71600","14.89315","0.04407"
"29845","179.03400","14.91970","0.04606"
"29898","179.35200","14.94613","0.04538"
"29951","179.67000","14.97268","0.04458"
"30004","179.98800","14.99910","0.04519"
"30057","180.30600","15.02571","0.04683"
"30110","180.62400","15.05219","0.04728"
"30163","180.94200","15.07868","0.04685"
"30216","181.26000","15.10517","0.04854"
"30269","181.57800","15.13159","0.04840"
"30322","181.89600","15.15820","0.04916"
"30375","182.21400","15.18463","0.05101"
"30428","182.53200","15.21117","0.05062"
"30481","182.85000","15.23766","0.05223"
"30534","183.16800","15.26415","0.05287"
"30587","183.48600","15.29076","0.05343"
"30640","183.80400","15.31718","0.05375"
"30693","184.12200","15.34361","0.05516"
"30746","184.44000","15.37022","0.05547"
"30799","184.75800","15.39664","0.05652"
"30852","185.07600","15.42325","0.05687"
"30905","185.39400","15.44967","0.05787"
"30958","185.71200","15.47616","0.05791"
"31011","186.03000","15.50271","0.05877"
"31064","186.34800","15.52919","0.05944"
"31117","186.66600","15.55574","0.05936"
"31170","186.98400","15.58211","0.06060"
"31223","187.30200","15.60865","0.06036"
"31276","187.62000","15.63514","0.06080"
"31329","187.93800","15.66169","0.06138"
"31382","188.25600","15.68818","0.06147"
"31435","188.57400","15.71460","0.06227"
"31488","188.89200","15.74121","0.06243"
"31541","189.21000","15.76764","0.06318"
"31594","189.52800","15.79418","0.06319"
"31647","189.84600","15.82073","0.06282"
"31700","190.16400","15.84716","0.06295"
"31753","190.48200","15.87370","0.06090"
"31806","190.80000","15.90019","0.06168"
"31859","191.11800","15.92674","0.06216"
"31912","191.43600","15.95322","0.06244"
"31965","191.75400","15.97965","0.06444"
"32018","192.07200","16.00620","0.06388"
"32071","192.39000","16.03262","0.06408"
"32124","192.70800","16.05917","0.06572"
"32177","193.02600","16.08566","0.06583"
"32230","193.34400","16.11214","0.06583"
"32283","193.66200","16.13869","0.01082"
"32336","193.98000","16.16512","0.00852"
"32389","194.29800","16.19172","0.00923"
"32442","194.61600","16.21815","0.00891"
"32495","194.93400","16.24464","0.01035"
"32548","195.25200","16.27124","0.01092"
"32601","195.57000","16.29767","0.01018"
"32654","195.88800","16.32422","0.01157"
"32707","196.20600","16.35064","0.01041"
"32760","196.52400","16.37719","0.01232"
"32813","196.84200","16.40368","0.01205"
"32866","197.16000","16.43016","0.01187"
"32919","197.47800","16.45677","0.01284"
"32972","197.79600","16.48320","0.01180"
"33025","198.11400","16.50968","0.01268"
"33078","198.43200","16.53623","0.01338"
"33131","198.75000","16.56260","0.01333"
"33184","199.06800","16.58920","0.01407"
"33237","199.38600","16.61563","0.01413"
"33290","199.70400","16.64224","0.01437"
"33343","200.02200","16.66872","0.01538"
"33396","200.34000","16.69521","0.01458"
"33449","200.65800","16.72170","0.01520"
"33502","200.97600","16.74813","0.01581"
"33555","201.29400","16.77467","0.01567"
"33608","201.61200","16.80122","0.01608"
"33661","201.93000","16.82764","0.01704"
"33714","202.24800","16.85419","0.01648"
"33767","202.56600","16.88068","0.01672"
"33820","202.88400","16.90717","0.01728"
"33873","203.20200","16.93365","0.01748"
"33926","203.52000","16.96014","0.01846"
"33979","203.83800","16.98674","0.01799"
"34032","204.15600","17.01317","0.01843"
"34085","204.47400","17.03972","0.01867"
"34138","204.79200","17.06620","0.01919"
"34191","205.11000","17.09269","0.01936"
"34244","205.42800","17.11918","0.02008"
"34297","205.74600","17.14567","0.02002"
"34350","206.06400","17.17221","0.01995"
"34403","206.38200","17.19864","0.02011"
"34456","206.70000","17.22519","0.02038"
"34509","207.01800","17.25173","0.02104"
"34562","207.33600","17.27810","0.02078"
"34615","207.65400","17.30470","0.02102"
"34668","207.97200","17.33113","0.02134"
"34721","208.29000","17.35774","0.02144"
"34774","208.60800","17.38423","0.02198"
"34827","208.92600","17.41071","0.02199"
"34880","209.24400","17.43726","0.02168"
"34933","209.56200","17.46363","0.02226"
"34986","209.88000","17.49023","0.02221"
"35039","210.19800","17.51672","0.02254"
"35092","210.51600","17.54321","0.02305"
"35145","210.83400","17.56969","0.02272"
"35198","211.15200","17.59612","0.02287"
"35251","211.47000","17.62273","0.02360"
"35304","211.78800","17.64915","0.02325"
"35357","212.10600","17.67570","0.02306"
"35410","212.42400","17.70219","0.02405"
"35463","212.74200","17.72867","0.02356"
"35516","213.06000","17.75522","0.02398"
"35569","213.37800","17.78165","0.02420"
"35622","213.69600","17.80819","0.02417"
"35675","214.01400","17.83462","0.02350"
"35728","214.33200","17.86117","0.02401"
"35781","214.65000","17.88771","0.02429"
"35834","214.96800","17.91414","0.02415"
"35887","215.28600","17.94069","0.02427"
"35940","215.60400","17.96717","0.02294"
"35993","215.92200","17.99372","0.02352"
"36046","216.24000","18.02021","0.02329"
"36099","216.55800","18.04663","0.02373"
"36152","216.87600","18.07318","0.02375"
"36205","217.19400","18.09967","0.02396"
"36258","217.51200","18.12621","0.02431"
"36311","217.83000","18.15270","0.02405"
"36364","218.14800","18.17913","0.02499"
"36417","218.46600","18.20568","0.02457"
"36470","218.78400","18.23216","0.02561"
"36523","219.10200","18.25871","0.02537"
"36576","219.42000","18.28519","0.02575"
"36629","219.73800","18.31162","0.02595"
"36682","220.05600","18.33817","0.02582"
"36735","220.37400","18.36465","0.02627"
"36788","220.69200","18.39120","0.02616"
"36841","221.01000","18.41775","0.02658"
"36894","221.32800","18.44418","0.02697"
"36947","221.64600","18.47078","0.02740"
"37000","221.96400","18.49715","0.02759"
"37053","222.28200","18.52369","0.02801"
"37106","222.60000","18.55018","0.02841"
"37159","222.91800","18.57667","0.02776"
"37212","223.23600","18.60321","0.02766"
"37265","223.55400","18.62964","0.02847"
"37318","223.87200","18.65619","0.02672"
"37371","224.19000","18.68268","0.02725"
"37424","224.50800","18.70916","0.02808"
"37477","224.82600","18.73577","0.02754"
"37530","225.14400","18.76213","0.02787"
"37583","225.46200","18.78868","0.02798"
"37636","225.78000","18.81517","0.02851"
"37689","226.09800","18.84166","0.02920"
"37742","226.41600","18.86820","0.02979"
"37795","226.73400","18.89469","0.02985"
"37848","227.05200","18.92118","0.02850"
"37901","227.37000","18.94766","0.02934"
"37954","227.68800","18.97421","0.02995"
"38007","228.00600","19.00076","0.03031"
"38060","228.32400","19.02712","0.03064"
"38113","228.64200","19.05367","0.03120"
"38166","228.96000","19.08015","0.03138"
"38219","229.27800","19.10676","0.03143"
"38272","229.59600","19.13325","0.03115"
"38325","229.91400","19.15968","0.03216"
"38378","230.23200","19.18622","0.03101"
"38431","230.55000","19.21271","0.03142"
"38484","230.86800","19.23920","0.03239"
"38537","231.18600","19.26568","0.03227"
"38590","231.50400","19.29217","0.03171"
"38643","231.82200","19.31872","0.03135"
"38696","232.14000","19.34520","0.03012"
"38749","232.45800","19.37169","0.03007"
"38802","232.77600","19.39817","0.03077"
"38855","233.09400","19.42466","0.03136"
"38908","233.41200","19.45121","0.03179"
"38961","233.73000","19.47770","0.03268"
"39014","234.04800","19.50424","0.03341"
"39067","234.36600","19.53067","0.03385"
"39120","234.68400","19.55722","0.03460"
"39173","235.00200","19.58370","0.03502"
"39226","235.32000","19.61013","0.03529"
"39279","235.63800","19.63667","0.03581"
"39332","235.95600","19.66316","0.03636"
"39385","236.27400","19.68971","0.03692"
"39438","236.59200","19.71619","0.03723"
"39491","236.91000","19.74268","0.03756"
"39544","237.22800","19.76917","0.03861"
"39597","237.54600","19.79560","0.03752"
"39650","237.86400","19.82220","0.03832"
"39703","238.18200","19.84875","0.03871"
"39756","238.50000","19.87518","0.03929"
"39809","238.81800","19.90172","0.04015"
"39862","239.13600","19.92815","0.04045"
"39915","239.45400","19.95476","0.04034"
"39968","239.77200","19.98118","0.04114"
"40021","240.09000","20.00767","0.04117"
"40074","240.40800","20.03422","0.04093"
"40127","240.72600","20.06064","0.04071"
"40180","241.04400","20.08725","0.04171"
"40233","241.36200","20.11368","0.04202"
"40286","241.68000","20.14022","0.04265"
"40339","241.99800","20.16671","0.04183"
"40392","242.31600","20.19326","0.04300"
"40445","242.63400","20.21968","0.04329"
"40498","242.95200","20.24617","0.04388"
"40551","243.27000","20.27271","0.04511"
"40604","243.58800","20.29920","0.04439"
"40657","243.90600","20.32569","0.04277"
"40710","244.22400","20.35224","0.04380"
"40763","244.54200","20.37866","0.04347"
"40816","244.86000","20.40521","0.04505"
"40869","245.17800","20.43170","0.04436"
"40922","245.49600","20.45818","0.04394"
"40975","245.81400","20.48467","0.04504"
"41028","246.13200","20.51110","0.04541"
"41081","246.45000","20.53776","0.04614"
"41134","246.76800","20.56419","0.04744"
"41187","247.08600","20.59068","0.04806"
"41240","247.40400","20.61722","0.04868"
"41293","247.72200","20.64365","0.03996"
"41346","248.04000","20.67020","0.03368"
"41399","248.35800","20.69668","0.03167"
"41452","248.67600","20.72323","0.03080"
"41505","248.99400","20.74972","0.02823"
"41558","249.31200","20.77615","0.02800"
"41611","249.63000","20.80269","0.02957"
"41664","249.94800","20.82918","0.02972"
"41717","250.26600","20.85567","0.02965"
"41770","250.58400","20.88221","0.03043"
"41823","250.90200","20.90870","0.03018"
"41876","251.22000","20.93525","0.02957"
"41929","251.53800","20.96161","0.02969"
"41982","251.85600","20.98816","0.03088"
"42035","252.17400","21.01471","0.03034"
"42088","252.49200","21.04113","0.03169"
"42141","252.81000","21.06774","0.03230"
"42194","253.12800","21.09417","0.03218"
"42247","253.44600","21.12071","0.03322"
"42300","253.76400","21.14720","0.03421"
"42353","254.08200","21.17375","0.03449"
"42406","254.40000","21.20023","0.03413"
"42459","254.71800","21.22666","0.03563"
"42512","255.03600","21.25321","0.03594"
"42565","255.35400","21.27969","0.03594"
"42618","255.67200","21.30624","0.03629"
"42671","255.99000","21.33273","0.03713"
"42724","256.30800","21.35915","0.03637"
"42777","256.62600","21.38570","0.03644"
"42830","256.94400","21.41213","0.03589"
"42883","257.26200","21.43873","0.03650"
"42936","257.58000","21.46522","0.03762"
"42989","257.89800","21.49165","0.03792"
"43042","258.21600","21.51819","0.03882"
"43095","258.53400","21.54462","0.03977"
"43148","258.85200","21.57117","0.04079"
"43201","259.17000","21.59771","0.04101"
"43254","259.48800","21.62420","0.04151"
"43307","259.80600","21.65069","0.04226"
"43360","260.12400","21.67723","0.04292"
"43413","260.44200","21.70372","0.04286"
"43466","260.76000","21.73015","0.04367"
"43519","261.07800","21.75663","0.04461"
"43572","261.39600","21.78324","0.04451"
"43625","261.71400","21.80973","0.04467"
"43678","262.03200","21.83621","0.04446"
"43731","262.35000","21.86270","0.04201"
"43784","262.66800","21.88925","0.04212"
"43837","262.98600","21.91579","0.04066"
"43890","263.30400","21.94216","0.04007"
"43943","263.62200","21.96871","0.04059"
"43996","263.94000","21.99513","0.03898"
"44049","264.25800","22.02174","0.04180"
"44102","264.57600","22.04823","0.04130"
"44155","264.89400","22.07471","0.04230"
"44208","265.21200","22.10120","0.04433"
"44261","265.53000","22.12763","0.04498"
"44314","265.84800","22.15423","0.04547"
"44367","266.16600","22.18066","0.04641"
"44420","266.48400","22.20721","0.04784"
"44473","266.80200","22.23369","0.04819"
"44526","267.12000","22.26012","0.04970"
"44579","267.43800","22.28673","0.05097"
"44632","267.75600","22.31316","0.05214"
"44685","268.07400","22.33970","0.05278"
"44738","268.39200","22.36619","0.05392"
"44791","268.71000","22.39268","0.05407"
"44844","269.02800","22.41922","0.05459"
"44897","269.34600","22.44571","0.05545"
"44950","269.66400","22.47219","0.05642"
"45003","269.98200","22.49868","0.05734"
"45056","270.30000","22.52517","0.05847"
"45109","270.61800","22.55172","0.05852"
"45162","270.93600","22.57814","0.05934"
"45215","271.25400","22.60469","0.05962"
"45268","271.57200","22.63123","0.06048"
"45321","271.89000","22.65766","0.06154"
"45374","272.20800","22.68421","0.06250"
"45427","272.52600","22.71058","0.06293"
"45480","272.84400","22.73718","0.06383"
"45533","273.16200","22.76373","0.06430"
"45586","273.48000","22.79015","0.06476"
"45639","273.79800","22.81670","0.06547"
"45692","274.11600","22.84313","0.06615"
"45745","274.43400","22.86974","0.06640"
"45798","274.75200","22.89622","0.06741"
"45851","275.07000","22.92271","0.06779"
"45904","275.38800","22.94920","0.06832"
"45957","275.70600","22.97562","0.06953"
"46010","276.02400","23.00223","0.06995"
"46063","276.34200","23.02866","0.07075"
"46116","276.66000","23.05520","0.07150"
"46169","276.97800","23.08169","0.07208"
"46222","277.29600","23.10818","0.07272"
"46275","277.61400","23.13472","0.07352"
"46328","277.93200","23.16115","0.07473"
"46381","278.25000","23.18770","0.07639"
"46434","278.56800","23.21418","0.07778"
"46487","278.88600","23.24067","0.07876"
"46540","279.20400","23.26716","0.08033"
"46593","279.52200","23.29364","0.08155"
"46646","279.84000","23.32019","0.08356"
"46699","280.15800","23.34674","0.08581"
"46752","280.47600","23.37316","0.08764"
"46805","280.79400","23.39977","0.08967"
"46858","281.11200","23.42608","0.09235"
"46911","281.43000","23.45268","0.09548"
"46964","281.74800","23.47917","0.09738"
"47017","282.06600","23.50572","0.09836"
"47070","282.38400","23.53226","0.05400"
"47123","282.70200","23.55863","0.03635"
"47176","283.02000","23.58524","0.04012"
"47229","283.33800","23.61166","0.03726"
"47282","283.65600","23.63821","0.00900"
"47335","283.97400","23.66470","0.00081"
"47388","284.29200","23.69118","0.01202"
"47441","284.61000","23.71767","-0.00031"
"47494","284.92800","23.74416","0.00649"
"47547","285.24600","23.77070","-0.00068"
"47600","285.56400","23.79719","0.00845"
"47653","285.88200","23.82368","0.00426"
"47706","286.20000","23.85016","0.00140"
"47759","286.51800","23.87665","0.01031"
"47812","286.83600","23.90320","-0.00016"
"47865","287.15400","23.92968","0.00722"
"47918","287.47200","23.95617","0.00418"
"47971","287.79000","23.98272","0.00322"
"48024","288.10800","24.00920","0.00553"
"48077","288.42600","24.03575","0.00290"
"48130","288.74400","24.06218","0.00613"
"48183","289.06200","24.08867","0.00341"
"48236","289.38000","24.11527","0.00476"
"48289","289.69800","24.14164","0.00476"
"48342","290.01600","24.16825","0.00464"
"48395","290.33400","24.19461","0.00383"
"48448","290.65200","24.22116","0.00614"
"48501","290.97000","24.24764","0.00512"
"48554","291.28800","24.27413","0.00316"
"48607","291.60600","24.30068","0.00790"
"48660","291.92400","24.32710","0.00318"
"48713","292.24200","24.35371","0.00438"
"48766","292.56000","24.38020","0.00697"
"48819","292.87800","24.40669","0.00320"
"48872","293.19600","24.43317","0.00660"
"48925","293.51400","24.45960","0.00442"
"48978","293.83200","24.48620","0.00543"
"49031","294.15000","24.51269","0.00571"
"49084","294.46800","24.53918","0.00422"
"49137","294.78600","24.56573","0.00736"
"49190","295.10400","24.59215","0.00451"
"49243","295.42200","24.61870","0.00609"
"49296","295.74000","24.64513","0.00658"
"49349","296.05800","24.67161","0.00461"
"49402","296.37600","24.69822","0.00579"
"49455","296.69400","24.72465","0.00568"
"49508","297.01200","24.75119","0.00553"
"49561","297.33000","24.77768","0.00540"
"49614","297.64800","24.80416","0.00673"
"49667","297.96600","24.83071","0.00646"
"49720","298.28400","24.85720","0.00458"
"49773","298.60200","24.88369","0.00788"
"49826","298.92000","24.91011","0.00561"
"49879","299.23800","24.93666","0.00589"
"49932","299.55600","24.96321","0.00797"
"49985","299.87400","24.98969","0.00547"
"50038","300.19200","25.01618","0.00732"
"50091","300.51000","25.04261","0.00736"
"50144","300.82800","25.06921","0.00646"
"50197","301.14600","25.09570","0.00666"
"50250","301.46400","25.12219","0.00691"
"50303","301.78200","25.14867","0.00708"
"50356","302.10000","25.17516","0.00634"
"50409","302.41800","25.20171","0.00746"
"50462","302.73600","25.22820","0.00786"
"50515","303.05400","25.25468","0.00675"
"50568","303.37200","25.28117","0.00842"
"50621","303.69000","25.30766","0.00719"
"50674","304.00800","25.33420","0.00726"
"50727","304.32600","25.36069","0.00919"
"50780","304.64400","25.38717","0.00714"
"50833","304.96200","25.41372","0.00812"
"50886","305.28000","25.44015","0.00855"
"50939","305.59800","25.46675","0.00774"
"50992","305.91600","25.49318","0.00916"
"51045","306.23400","25.51973","0.00835"
"51098","306.55200","25.54622","0.00850"
"51151","306.87000","25.57270","0.00853"
"51204","307.18800","25.59925","0.00876"
"51257","307.50600","25.62562","0.00919"
"51310","307.82400","25.65222","0.00838"
"51363","308.14200","25.67865","0.00903"
"51416","308.46000","25.70514","0.00905"
"51469","308.77800","25.73174","0.00901"
"51522","309.09600","25.75817","0.00970"
"51575","309.41400","25.78472","0.00897"
"51628","309.73200","25.81114","0.00973"
"51681","310.05000","25.83769","0.00925"
"51734","310.36800","25.86423","0.00972"
"51787","310.68600","25.89066","0.01007"
"51840","311.00400","25.91721","0.00952"
"51893","311.32200","25.94370","0.00951"
"51946","311.64000","25.97018","0.00994"
"51999","311.95800","25.99667","0.00976"
"52052","312.27600","26.02316","0.01042"
"52105","312.59400","26.04964","0.00989"
"52158","312.91200","26.07619","0.01060"
"52211","313.23000","26.10268","0.01060"
"52264","313.54800","26.12916","0.00998"
"52317","313.86600","26.15565","0.01053"
"52370","314.18400","26.18220","0.01062"
"52423","314.50200","26.20868","0.01094"
"52476","314.82000","26.23517","0.01077"
"52529","315.13800","26.26171","0.01128"
"52582","315.45600","26.28820","0.01088"
"52635","315.77400","26.31469","0.01122"
"52688","316.09200","26.34112","0.01145"
"52741","316.41000","26.36772","0.01117"
"52794","316.72800","26.39409","0.01016"
"52847","317.04600","26.42064","0.01097"
"52900","317.36400","26.44724","0.01119"
"52953","317.68200","26.47367","0.01100"
"53006","318.00000","26.50022","0.01112"
"53059","318.31800","26.52665","0.01143"
"53112","318.63600","26.55319","0.01138"
"53165","318.95400","26.57974","0.01116"
"53218","319.27200","26.60616","0.01132"
"53271","319.59000","26.63271","0.01165"
"53324","319.90800","26.65914","0.01213"
"53377","320.22600","26.68575","0.01234"
"53430","320.54400","26.71223","0.01240"
"53483","320.86200","26.73866","0.01220"
"53536","321.18000","26.76521","0.01227"
"53589","321.49800","26.79163","0.01273"
"53642","321.81600","26.81818","0.01274"
"53695","322.13400","26.84467","0.01234"
"53748","322.45200","26.87109","0.01224"
"53801","322.77000","26.89770","0.01290"
"53854","323.08800","26.92412","0.01272"
"53907","323.40600","26.95073","0.01282"
"53960","323.72400","26.97716","0.01335"
"54013","324.04200","27.00364","0.01316"
"54066","324.36000","27.03019","0.01333"
"54119","324.67800","27.05668","0.01334"
"54172","324.99600","27.08322","0.01349"
"54225","325.31400","27.10965","0.01370"
"54278","325.63200","27.13620","0.01341"
"54331","325.95000","27.16268","0.01401"
"54384","326.26800","27.18917","0.01367"
"54437","326.58600","27.21572","0.01358"
"54490","326.90400","27.24221","0.01386"
"54543","327.22200","27.26875","0.01390"
"54596","327.54000","27.29524","0.01337"
"54649","327.85800","27.32173","0.01372"
"54702","328.17600","27.34821","0.01391"
"54755","328.49400","27.37464","0.01378"
"54808","328.81200","27.40119","0.01418"
"54861","329.13000","27.42773","0.01423"
"54914","329.44800","27.45422","0.01403"
"54967","329.76600","27.48071","0.01386"
"55020","330.08400","27.50713","0.01464"
"55073","330.40200","27.53368","0.01414"
"55126","330.72000","27.56016","0.01415"
"55179","331.03800","27.58665","0.01420"
"55232","331.35600","27.61320","0.01442"
"55285","331.67400","27.63962","0.01495"
"55338","331.99200","27.66617","0.01427"
"55391","332.31000","27.69272","0.01488"
"55444","332.62800","27.71921","0.01502"
"55497","332.94600","27.74575","0.01491"
"55550","333.26400","27.77218","0.01496"
"55603","333.58200","27.79873","0.01553"
"55656","333.90000","27.82515","0.01520"
"55709","334.21800","27.85170","0.01497"
"55762","334.53600","27.87818","0.01556"
"55815","334.85400","27.90461","0.01514"
"55868","335.17200","27.93116","0.01511"
"55921","335.49000","27.95764","0.01555"
"55974","335.80800","27.98425","0.01545"
"56027","336.12600","28.01068","0.01524"
"56080","336.44400","28.03717","0.01614"
"56133","336.76200","28.06371","0.01646"
"56186","337.08000","28.09014","0.01608"
"56239","337.39800","28.11668","0.01659"
"56292","337.71600","28.14317","0.01615"
"56345","338.03400","28.16972","0.01678"
"56398","338.35200","28.19627","0.01635"
"56451","338.67000","28.22269","0.01616"
"56504","338.98800","28.24924","0.01683"
"56557","339.30600","28.27567","0.01648"
"56610","339.62400","28.30221","0.01607"
"56663","339.94200","28.32876","0.01651"
"56716","340.26000","28.35513","0.01675"
"56769","340.57800","28.38167","0.01657"
"56822","340.89600","28.40822","0.01701"
"56875","341.21400","28.43471","0.01701"
"56928","341.53200","28.46119","0.01743"
"56981","341.85000","28.48768","0.01722"
"57034","342.16800","28.51423","0.01715"
"57087","342.48600","28.54065","0.01691"
"57140","342.80400","28.56720","0.01711"
"57193","343.12200","28.59369","0.01743"
"57246","343.44000","28.62017","0.01753"
"57299","343.75800","28.64672","0.01823"
"57352","344.07600","28.67315","0.01790"
"57405","344.39400","28.69969","0.01815"
"57458","344.71200","28.72618","0.01797"
"57511","345.03000","28.75267","0.01868"
"57564","345.34800","28.77921","0.01821"
"57617","345.66600","28.80564","0.01755"
"57670","345.98400","28.83219","0.01826"
"57723","346.30200","28.85873","0.01783"
"57776","346.62000","28.88522","0.01785"
"57829","346.93800","28.91177","0.01681"
"57882","347.25600","28.93813","0.01755"
"57935","347.57400","28.96468","0.01788"
"57988","347.89200","28.99111","0.01761"
"58041","348.21000","29.01771","0.01767"
"58094","348.52800","29.04426","0.01749"
"58147","348.84600","29.07069","0.01775"
"58200","349.16400","29.09717","0.01729"
"58253","349.48200","29.12366","0.01789"
"58306","349.80000","29.15021","0.01879"
"58359","350.11800","29.17669","0.01890"
"58412","350.43600","29.20318","0.01846"
"58465","350.75400","29.22973","0.01862"
"58518","351.07200","29.25616","0.01874"
"58571","351.39000","29.28270","0.01905"
"58624","351.70800","29.30919","0.01868"
"58677","352.02600","29.33567","0.01943"
"58730","352.34400","29.36216","0.01912"
"58783","352.66200","29.38865","0.02025"
"58836","352.98000","29.41525","0.02015"
"58889","353.29800","29.44168","0.02043"
"58942","353.61600","29.46817","0.02050"
"58995","353.93400","29.49472","0.02034"
"59048","354.25200","29.52120","0.02040"
"59101","354.57000","29.54769","0.02088"
"59154","354.88800","29.57418","0.02068"
"59207","355.20600","29.60066","0.02119"
"59260","355.52400","29.62721","0.02065"
"59313","355.84200","29.65364","0.02118"
"59366","356.16000","29.68018","0.02118"
"59419","356.47800","29.70661","0.02159"
"59472","356.79600","29.73322","0.02185"
"59525","357.11400","29.75970","0.02193"
"59578","357.43200","29.78619","0.02199"
"59631","357.75000","29.81273","0.02172"
"59684","358.06800","29.83910","0.02162"
"59737","358.38600","29.86571","0.02179"
"59790","358.70400","29.89219","0.02240"
"59843","359.02200","29.91868","0.02266"
"59896","359.34000","29.94523","0.02281"
"59949","359.65800","29.97165","0.02312"
"60002","359.97600","29.99820","0.02364"
"60055","360.29400","30.02469","0.02336"
"60108","360.61200","30.05112","0.02357"
"60161","360.93000","30.07772","0.02337"
"60214","361.24800","30.10415","0.02388"
"60267","361.56600","30.13075","0.02325"
"60320","361.88400","30.15718","0.02335"
"60373","362.20200","30.18373","0.02350"
"60426","362.52000","30.21022","0.02389"
"60479","362.83800","30.23670","0.01942"
"60532","363.15600","30.26319","0.02000"
"60585","363.47400","30.28968","0.02124"
"60638","363.79200","30.31623","0.02173"
"60691","364.11000","30.34271","0.02038"
"60744","364.42800","30.36920","0.02285"
"60797","364.74600","30.39574","0.02114"
"60850","365.06400","30.42217","0.02202"
"60903","365.38200","30.44872","0.02256"
"60956","365.70000","30.47520","0.02096"
"61009","366.01800","30.50175","0.02039"
"61062","366.33600","30.52824","0.02164"
"61115","366.65400","30.55466","0.02098"
"61168","366.97200","30.58121","0.02174"
"61221","367.29000","30.60770","0.02237"
"61274","367.60800","30.63424","0.02094"
"61327","367.92600","30.66073","0.02199"
"61380","368.24400","30.68722","0.02193"
"61433","368.56200","30.71371","0.02166"
"61486","368.88000","30.74019","0.02122"
"61539","369.19800","30.76674","0.02097"
"61592","369.51600","30.79322","0.01943"
"61645","369.83400","30.81965","0.02100"
"61698","370.15200","30.84620","0.02038"
"61751","370.47000","30.87268","0.02146"
"61804","370.78800","30.89923","0.02057"
"61857","371.10600","30.92572","0.02115"
"61910","371.42400","30.95221","0.02125"
"61963","371.74200","30.97875","0.02182"
"62016","372.06000","31.00518","0.02223"
"62069","372.37800","31.03172","0.02258"
"62122","372.69600","31.05815","0.02258"
"62175","373.01400","31.08464","0.02288"
"62228","373.33200","31.11124","0.02299"
"62281","373.65000","31.13767","0.02337"
"62334","373.96800","31.16422","0.02390"
"62387","374.28600","31.19070","0.02379"
"62440","374.60400","31.21719","0.02430"
"62493","374.92200","31.24374","0.02458"
"62546","375.24000","31.27016","0.02477"
"62599","375.55800","31.29665","0.02489"
"62652","375.87600","31.32314","0.02482"
"62705","376.19400","31.34969","0.02466"
"62758","376.51200","31.37623","0.02528"
"62811","376.83000","31.40266","0.02534"
"62864","377.14800","31.42920","0.02592"
"62917","377.46600","31.45563","0.02634"
"62970","377.78400","31.48224","0.02579"
"63023","378.10200","31.50867","0.02637"
"63076","378.42000","31.53521","0.02690"
"63129","378.73800","31.56170","0.02649"
"63182","379.05600","31.58819","0.02682"
"63235","379.37400","31.61473","0.02745"
"63288","379.69200","31.64116","0.02790"
"63341","380.01000","31.66771","0.02794"
"63394","380.32800","31.69419","0.02907"
"63447","380.64600","31.72068","0.02694"
"63500","380.96400","31.74722","0.02630"
"63553","381.28200","31.77365","0.02833"
"63606","381.60000","31.80014","0.02673"
"63659","381.91800","31.82669","0.02677"
"63712","382.23600","31.85317","0.02837"
"63765","382.55400","31.87972","0.02719"
"63818","382.87200","31.90615","0.02800"
"63871","383.19000","31.93269","0.02710"
"63924","383.50800","31.95924","0.01566"
"63977","383.82600","31.98567","0.00194"
"64030","384.14400","32.01221","0.00590"
"64083","384.46200","32.03864","0.00008"
"64136","384.78000","32.06519","-0.00035"
"64189","385.09800","32.09173","0.00324"
"64242","385.41600","32.11816","0.00154"
"64295","385.73400","32.14471","-0.00101"
"64348","386.05200","32.17113","0.00135"
"64401","386.37000","32.19774","-0.00025"
"64454","386.68800","32.22423","0.00085"
"64507","387.00600","32.25071","-0.00041"
"64560","387.32400","32.27720","0.00366"
"64613","387.64200","32.30369","-0.00130"
"64666","387.96000","32.33023","0.00264"
"64719","388.27800","32.35666","0.00045"
"64772","388.59600","32.38321","0.00064"
"64825","388.91400","32.40969","-0.00125"
"64878","389.23200","32.43618","0.00122"
"64931","389.55000","32.46273","-0.00096"
"64984","389.86800","32.48915","0.00091"
"65037","390.18600","32.51570","-0.00047"
"65059","390.31800","32.52664","0.00240"