File: Trajectories_together/170122_1Specimen_RawData_1.csv
"","V1","V2","V3"
"1","End date","1/22/2017",""
"2","Specimen label","3BT_18",""
"3","Maximum Load","0.23093","N"
"4","Time","Extension","Load"
"5","(s)","(mm)","(N)"
"6","0.00000","0.00000","-0.00007"
"49","0.25800","0.01967","-0.00006"
"92","0.51600","0.04335","0.00034"
"135","0.77400","0.06463","0.00067"
"178","1.03200","0.08628","0.00064"
"221","1.29000","0.10768","0.00081"
"264","1.54800","0.12921","0.00088"
"307","1.80600","0.15067","0.00117"
"350","2.06400","0.17219","0.00126"
"393","2.32200","0.19366","0.00127"
"436","2.58000","0.21524","0.00144"
"479","2.83800","0.23665","0.00107"
"522","3.09600","0.25823","0.00193"
"565","3.35400","0.27970","0.00183"
"608","3.61200","0.30122","0.00195"
"651","3.87000","0.32262","0.00251"
"694","4.12800","0.34421","0.00290"
"737","4.38600","0.36567","0.00190"
"780","4.64400","0.38726","0.00223"
"823","4.90200","0.40872","0.00253"
"866","5.16000","0.43019","0.00233"
"909","5.41800","0.45165","0.00314"
"952","5.67600","0.47323","0.00264"
"995","5.93400","0.49470","0.00269"
"1038","6.19200","0.51622","0.00291"
"1081","6.45000","0.53769","0.00304"
"1124","6.70800","0.55915","0.00374"
"1167","6.96600","0.58068","0.00338"
"1210","7.22400","0.60214","0.00297"
"1253","7.48200","0.62366","0.00278"
"1296","7.74000","0.64513","0.00339"
"1339","7.99800","0.66671","0.00338"
"1382","8.25600","0.68812","0.00379"
"1425","8.51400","0.70964","0.00395"
"1468","8.77200","0.73111","0.00371"
"1511","9.03000","0.75269","0.00357"
"1554","9.28800","0.77415","0.00396"
"1597","9.54600","0.79568","0.00411"
"1640","9.80400","0.81714","0.00497"
"1683","10.06200","0.83873","0.00452"
"1726","10.32000","0.86019","0.00417"
"1769","10.57800","0.88172","0.00457"
"1812","10.83600","0.90318","0.00490"
"1855","11.09400","0.92465","0.00509"
"1898","11.35200","0.94617","0.00527"
"1941","11.61000","0.96769","0.00575"
"1984","11.86800","0.98922","0.00509"
"2027","12.12600","1.01068","0.00588"
"2070","12.38400","1.03221","0.00552"
"2113","12.64200","1.05373","0.00553"
"2156","12.90000","1.07514","0.00582"
"2199","13.15800","1.09666","0.00572"
"2242","13.41600","1.11824","0.00632"
"2285","13.67400","1.13965","0.00596"
"2328","13.93200","1.16123","0.00620"
"2371","14.19000","1.18258","0.00645"
"2414","14.44800","1.20416","0.00645"
"2457","14.70600","1.22563","0.00652"
"2500","14.96400","1.24721","0.00634"
"2543","15.22200","1.26861","0.00646"
"2586","15.48000","1.29020","0.00646"
"2629","15.73800","1.31172","0.00638"
"2672","15.99600","1.33325","0.00679"
"2715","16.25400","1.35465","0.00664"
"2758","16.51200","1.37624","0.00652"
"2801","16.77000","1.39764","0.00682"
"2844","17.02800","1.41916","0.00703"
"2887","17.28600","1.44069","0.00736"
"2930","17.54400","1.46221","0.00713"
"2973","17.80200","1.48374","0.00738"
"3016","18.06000","1.50514","0.00737"
"3059","18.31800","1.52667","0.00754"
"3102","18.57600","1.54819","0.00781"
"3145","18.83400","1.56971","0.00742"
"3188","19.09200","1.59112","0.00781"
"3231","19.35000","1.61270","0.00741"
"3274","19.60800","1.63417","0.00837"
"3317","19.86600","1.65569","0.00698"
"3360","20.12400","1.67716","0.00786"
"3403","20.38200","1.69868","0.00763"
"3446","20.64000","1.72014","0.00710"
"3489","20.89800","1.74167","0.00801"
"3532","21.15600","1.76307","0.00728"
"3575","21.41400","1.78466","0.00747"
"3618","21.67200","1.80612","0.00786"
"3661","21.93000","1.82765","0.00796"
"3704","22.18800","1.84917","0.00784"
"3747","22.44600","1.87075","0.00814"
"3790","22.70400","1.89222","0.00844"
"3833","22.96200","1.91368","0.00862"
"3876","23.22000","1.93515","0.00925"
"3919","23.47800","1.95673","0.00890"
"3962","23.73600","1.97814","0.00870"
"4005","23.99400","1.99972","0.00962"
"4048","24.25200","2.02119","0.00977"
"4091","24.51000","2.04265","0.01015"
"4134","24.76800","2.06417","0.00974"
"4177","25.02600","2.08564","0.00981"
"4220","25.28400","2.10728","0.01064"
"4263","25.54200","2.12863","0.01101"
"4306","25.80000","2.15021","0.01131"
"4349","26.05800","2.17162","0.01112"
"4392","26.31600","2.19320","0.01057"
"4435","26.57400","2.21472","0.01027"
"4478","26.83200","2.23625","0.01028"
"4521","27.09000","2.25765","0.01048"
"4564","27.34800","2.27918","0.01323"
"4607","27.60600","2.30064","0.00981"
"4650","27.86400","2.32223","0.01034"
"4693","28.12200","2.34369","0.00985"
"4736","28.38000","2.36515","0.00974"
"4779","28.63800","2.38662","0.01036"
"4822","28.89600","2.40820","0.01093"
"4865","29.15400","2.42967","0.01054"
"4908","29.41200","2.45119","0.01021"
"4951","29.67000","2.47266","0.01107"
"4994","29.92800","2.49418","0.01136"
"5037","30.18600","2.51570","0.01187"
"5080","30.44400","2.53723","0.01172"
"5123","30.70200","2.55869","0.01182"
"5166","30.96000","2.58016","0.01229"
"5209","31.21800","2.60168","0.01261"
"5252","31.47600","2.62315","0.01287"
"5295","31.73400","2.64473","0.01315"
"5338","31.99200","2.66613","0.01308"
"5381","32.25000","2.68772","0.01290"
"5424","32.50800","2.70912","0.01236"
"5467","32.76600","2.73071","-0.01644"
"5510","33.02400","2.75217","0.00513"
"5553","33.28200","2.77376","0.00683"
"5596","33.54000","2.79510","0.01082"
"5639","33.79800","2.81668","0.00594"
"5682","34.05600","2.83815","0.00672"
"5725","34.31400","2.85973","0.01196"
"5768","34.57200","2.88114","0.01199"
"5811","34.83000","2.90272","0.00712"
"5854","35.08800","2.92413","0.00699"
"5897","35.34600","2.94571","0.01131"
"5940","35.60400","2.96724","0.00924"
"5983","35.86200","2.98870","0.01025"
"6026","36.12000","3.01016","0.00985"
"6069","36.37800","3.03169","0.00715"
"6112","36.63600","3.05315","0.00831"
"6155","36.89400","3.07468","0.01409"
"6198","37.15200","3.09614","0.01333"
"6241","37.41000","3.11767","0.00969"
"6284","37.66800","3.13919","0.01028"
"6327","37.92600","3.16071","0.01053"
"6370","38.18400","3.18218","0.01339"
"6413","38.44200","3.20364","0.01472"
"6456","38.70000","3.22517","0.01258"
"6499","38.95800","3.24663","0.01018"
"6542","39.21600","3.26822","0.01331"
"6585","39.47400","3.28968","0.01443"
"6628","39.73200","3.31114","0.01482"
"6671","39.99000","3.33261","0.00632"
"6714","40.24800","3.35419","0.01665"
"6757","40.50600","3.37566","0.02069"
"6800","40.76400","3.39724","0.01890"
"6843","41.02200","3.41865","0.01495"
"6886","41.28000","3.44017","0.01353"
"6929","41.53800","3.46169","0.01690"
"6972","41.79600","3.48328","0.02050"
"7015","42.05400","3.50468","0.01703"
"7058","42.31200","3.52615","0.01413"
"7101","42.57000","3.54767","0.01710"
"7144","42.82800","3.56920","0.02315"
"7187","43.08600","3.59072","0.02095"
"7230","43.34400","3.61218","0.02000"
"7273","43.60200","3.63365","0.02371"
"7316","43.86000","3.65517","0.02543"
"7359","44.11800","3.67670","0.01690"
"7402","44.37600","3.69816","0.01856"
"7445","44.63400","3.71969","0.02137"
"7488","44.89200","3.74115","0.02095"
"7531","45.15000","3.76268","0.02452"
"7574","45.40800","3.78414","0.02686"
"7617","45.66600","3.80572","0.02799"
"7660","45.92400","3.82719","0.02708"
"7703","46.18200","3.84865","0.02719"
"7746","46.44000","3.87018","0.02738"
"7789","46.69800","3.89164","0.02659"
"7832","46.95600","3.91317","0.02697"
"7875","47.21400","3.93469","0.02705"
"7918","47.47200","3.95615","0.02744"
"7961","47.73000","3.97774","0.02713"
"8004","47.98800","3.99914","0.02756"
"8047","48.24600","4.02073","0.02760"
"8090","48.50400","4.04213","0.02794"
"8133","48.76200","4.06372","0.02798"
"8176","49.02000","4.08518","0.02008"
"8219","49.27800","4.10670","0.02001"
"8262","49.53600","4.12823","0.01754"
"8305","49.79400","4.14969","0.01630"
"8348","50.05200","4.17116","0.02500"
"8391","50.31000","4.19262","0.03022"
"8434","50.56800","4.21421","0.03044"
"8477","50.82600","4.23567","0.03102"
"8520","51.08400","4.25719","0.03185"
"8563","51.34200","4.27860","0.03247"
"8606","51.60000","4.30018","0.03235"
"8649","51.85800","4.32165","0.03232"
"8692","52.11600","4.34323","0.03271"
"8735","52.37400","4.36464","0.03148"
"8778","52.63200","4.38616","0.03122"
"8821","52.89000","4.40762","0.03135"
"8864","53.14800","4.42921","0.03163"
"8907","53.40600","4.45067","0.03138"
"8950","53.66400","4.47220","0.03187"
"8993","53.92200","4.49366","0.03194"
"9036","54.18000","4.51519","0.03232"
"9079","54.43800","4.53671","0.03245"
"9122","54.69600","4.55823","0.03274"
"9165","54.95400","4.57964","0.03330"
"9208","55.21200","4.60116","0.03309"
"9251","55.47000","4.62269","0.03351"
"9294","55.72800","4.64415","0.03360"
"9337","55.98600","4.66568","0.03400"
"9380","56.24400","4.68720","0.03392"
"9423","56.50200","4.70866","0.03464"
"9466","56.76000","4.73019","0.03458"
"9509","57.01800","4.75165","0.03479"
"9552","57.27600","4.77318","0.03489"
"9595","57.53400","4.79470","0.03522"
"9638","57.79200","4.81611","0.03551"
"9681","58.05000","4.83775","0.03557"
"9724","58.30800","4.85916","0.03584"
"9767","58.56600","4.88074","0.03571"
"9810","58.82400","4.90214","0.03592"
"9853","59.08200","4.92373","0.03605"
"9896","59.34000","4.94513","0.03594"
"9939","59.59800","4.96666","0.03571"
"9982","59.85600","4.98812","0.03606"
"10025","60.11400","5.00971","0.03599"
"10068","60.37200","5.03117","0.03583"
"10111","60.63000","5.05269","0.03613"
"10154","60.88800","5.07416","0.03539"
"10197","61.14600","5.09568","0.03522"
"10240","61.40400","5.11715","0.03454"
"10283","61.66200","5.13867","0.03388"
"10326","61.92000","5.16020","0.03355"
"10369","62.17800","5.18166","0.03377"
"10412","62.43600","5.20318","0.03336"
"10455","62.69400","5.22465","0.03374"
"10498","62.95200","5.24623","0.03374"
"10541","63.21000","5.26764","0.03374"
"10584","63.46800","5.28916","0.03370"
"10627","63.72600","5.31069","0.03365"
"10670","63.98400","5.33215","0.03381"
"10713","64.24200","5.35361","0.03376"
"10756","64.50000","5.37514","0.03398"
"10799","64.75800","5.39660","0.03390"
"10842","65.01600","5.41819","0.03440"
"10885","65.27400","5.43965","0.01535"
"10928","65.53200","5.46118","-0.00143"
"10971","65.79000","5.48264","-0.00296"
"11014","66.04800","5.50422","-0.00212"
"11057","66.30600","5.52569","-0.00241"
"11100","66.56400","5.54721","-0.00216"
"11143","66.82200","5.56862","-0.00253"
"11186","67.08000","5.59026","-0.00201"
"11229","67.33800","5.61173","-0.00280"
"11272","67.59600","5.63319","-0.00239"
"11315","67.85400","5.65465","-0.00269"
"11358","68.11200","5.67612","-0.00260"
"11401","68.37000","5.69770","-0.00300"
"11444","68.62800","5.71917","-0.00177"
"11487","68.88600","5.74069","-0.00310"
"11530","69.14400","5.76216","-0.00195"
"11573","69.40200","5.78374","-0.00276"
"11616","69.66000","5.80520","-0.00207"
"11659","69.91800","5.82673","-0.00257"
"11702","70.17600","5.84813","-0.00263"
"11745","70.43400","5.86966","-0.00250"
"11788","70.69200","5.89112","-0.00215"
"11831","70.95000","5.91265","-0.00211"
"11874","71.20800","5.93411","-0.00196"
"11917","71.46600","5.95570","-0.00210"
"11960","71.72400","5.97710","-0.00168"
"12003","71.98200","5.99868","-0.00203"
"12046","72.24000","6.02009","-0.00227"
"12089","72.49800","6.04167","-0.00214"
"12132","72.75600","6.06314","-0.00202"
"12175","73.01400","6.08466","-0.00205"
"12218","73.27200","6.10619","-0.00237"
"12261","73.53000","6.12771","-0.00269"
"12304","73.78800","6.14923","-0.00210"
"12347","74.04600","6.17070","-0.00249"
"12390","74.30400","6.19216","-0.00242"
"12433","74.56200","6.21369","-0.00180"
"12476","74.82000","6.23521","-0.00164"
"12519","75.07800","6.25668","-0.00218"
"12562","75.33600","6.27820","-0.00163"
"12605","75.59400","6.29960","-0.00208"
"12648","75.85200","6.32119","-0.00227"
"12691","76.11000","6.34265","-0.00218"
"12734","76.36800","6.36424","-0.00115"
"12777","76.62600","6.38558","-0.00172"
"12820","76.88400","6.40723","-0.00185"
"12863","77.14200","6.42863","-0.00219"
"12906","77.40000","6.45021","-0.00210"
"12949","77.65800","6.47168","-0.00184"
"12992","77.91600","6.49320","-0.00202"
"13035","78.17400","6.51461","-0.00187"
"13078","78.43200","6.53613","-0.00191"
"13121","78.69000","6.55766","-0.00171"
"13164","78.94800","6.57924","-0.00203"
"13207","79.20600","6.60065","-0.00156"
"13250","79.46400","6.62217","-0.00173"
"13293","79.72200","6.64363","-0.00163"
"13336","79.98000","6.66516","-0.00190"
"13379","80.23800","6.68668","-0.00204"
"13422","80.49600","6.70821","-0.00170"
"13465","80.75400","6.72967","-0.00133"
"13508","81.01200","6.75119","-0.00192"
"13551","81.27000","6.77266","-0.00126"
"13594","81.52800","6.79418","-0.00135"
"13637","81.78600","6.81571","-0.00178"
"13680","82.04400","6.83711","-0.00144"
"13723","82.30200","6.85870","-0.00106"
"13766","82.56000","6.88016","-0.00110"
"13809","82.81800","6.90175","-0.00159"
"13852","83.07600","6.92309","-0.00190"
"13895","83.33400","6.94467","-0.00159"
"13938","83.59200","6.96614","-0.00104"
"13981","83.85000","6.98766","-0.00198"
"14024","84.10800","7.00913","-0.00177"
"14067","84.36600","7.03071","-0.00175"
"14110","84.62400","7.05218","-0.00151"
"14153","84.88200","7.07370","-0.00141"
"14196","85.14000","7.09516","-0.00163"
"14239","85.39800","7.11669","-0.00138"
"14282","85.65600","7.13815","-0.00122"
"14325","85.91400","7.15968","-0.00132"
"14368","86.17200","7.18114","-0.00121"
"14411","86.43000","7.20267","-0.00136"
"14454","86.68800","7.22419","-0.00155"
"14497","86.94600","7.24565","-0.00124"
"14540","87.20400","7.26718","-0.00090"
"14583","87.46200","7.28864","-0.00107"
"14626","87.72000","7.31017","-0.00115"
"14669","87.97800","7.33163","-0.00121"
"14712","88.23600","7.35316","-0.00095"
"14755","88.49400","7.37468","-0.00142"
"14798","88.75200","7.39620","-0.00093"
"14841","89.01000","7.41767","-0.00131"
"14884","89.26800","7.43919","-0.00070"
"14927","89.52600","7.46060","-0.00078"
"14970","89.78400","7.48218","-0.00078"
"15013","90.04200","7.50365","-0.00088"
"15056","90.30000","7.52523","-0.00064"
"15099","90.55800","7.54669","-0.00142"
"15142","90.81600","7.56816","-0.00030"
"15185","91.07400","7.58962","-0.00124"
"15228","91.33200","7.61121","-0.00109"
"15271","91.59000","7.63261","-0.00127"
"15314","91.84800","7.65420","-0.00095"
"15357","92.10600","7.67566","-0.00086"
"15400","92.36400","7.69719","-0.00049"
"15443","92.62200","7.71871","-0.00100"
"15486","92.88000","7.74023","-0.00016"
"15529","93.13800","7.76170","-0.00061"
"15572","93.39600","7.78316","-0.00036"
"15615","93.65400","7.80469","-0.00103"
"15658","93.91200","7.82615","-0.00140"
"15701","94.17000","7.84773","-0.00096"
"15744","94.42800","7.86920","-0.00081"
"15787","94.68600","7.89066","-0.00095"
"15830","94.94400","7.91213","-0.00097"
"15873","95.20200","7.93371","-0.00091"
"15916","95.46000","7.95518","-0.00085"
"15959","95.71800","7.97670","-0.00049"
"16002","95.97600","7.99811","-0.00037"
"16045","96.23400","8.01969","-0.00055"
"16088","96.49200","8.04115","-0.00090"
"16131","96.75000","8.06268","-0.00079"
"16174","97.00800","8.08420","-0.00044"
"16217","97.26600","8.10573","-0.00054"
"16260","97.52400","8.12719","-0.00078"
"16303","97.78200","8.14872","-0.00045"
"16346","98.04000","8.17012","-0.00149"
"16389","98.29800","8.19170","-0.00035"
"16432","98.55600","8.21311","-0.00050"
"16475","98.81400","8.23469","-0.00102"
"16518","99.07200","8.25616","-0.00033"
"16561","99.33000","8.27768","-0.00085"
"16604","99.58800","8.29921","-0.00010"
"16647","99.84600","8.32073","-0.00036"
"16690","100.10400","8.34213","-0.00048"
"16733","100.36200","8.36366","-0.00071"
"16776","100.62000","8.38524","0.00039"
"16819","100.87800","8.40665","-0.00046"
"16862","101.13600","8.42823","-0.00054"
"16905","101.39400","8.44964","-0.00072"
"16948","101.65200","8.47122","-0.00054"
"16991","101.91000","8.49274","-0.00063"
"17034","102.16800","8.51421","-0.00066"
"17077","102.42600","8.53561","-0.00049"
"17120","102.68400","8.55714","0.00002"
"17163","102.94200","8.57866","-0.00039"
"17206","103.20000","8.60019","-0.00043"
"17249","103.45800","8.62165","0.00020"
"17292","103.71600","8.64317","-0.00072"
"17335","103.97400","8.66464","-0.00036"
"17378","104.23200","8.68616","-0.00067"
"17421","104.49000","8.70769","0.00018"
"17464","104.74800","8.72921","-0.00043"
"17507","105.00600","8.75068","0.00015"
"17550","105.26400","8.77220","0.00033"
"17593","105.52200","8.79366","0.00005"
"17636","105.78000","8.81519","-0.00039"
"17679","106.03800","8.83671","0.00025"
"17722","106.29600","8.85818","-0.00017"
"17765","106.55400","8.87964","-0.00043"
"17808","106.81200","8.90117","0.00034"
"17851","107.07000","8.92269","-0.00050"
"17894","107.32800","8.94416","-0.00050"
"17937","107.58600","8.96568","-0.00016"
"17980","107.84400","8.98714","-0.00045"
"18023","108.10200","9.00867","0.00035"
"18066","108.36000","9.03013","0.00019"
"18109","108.61800","9.05166","-0.00001"
"18152","108.87600","9.07312","0.00009"
"18195","109.13400","9.09471","0.00011"
"18238","109.39200","9.11617","0.00049"
"18281","109.65000","9.13775","-0.00021"
"18324","109.90800","9.15910","0.00014"
"18367","110.16600","9.18068","0.00011"
"18410","110.42400","9.20215","-0.00007"
"18453","110.68200","9.22367","0.00002"
"18496","110.94000","9.24514","0.00044"
"18539","111.19800","9.26666","0.00040"
"18582","111.45600","9.28818","-0.00036"
"18625","111.71400","9.30965","-0.00008"
"18668","111.97200","9.33117","0.00001"
"18711","112.23000","9.35270","0.00043"
"18754","112.48800","9.37422","0.00008"
"18797","112.74600","9.39569","0.00032"
"18840","113.00400","9.41721","0.00057"
"18883","113.26200","9.43867","0.00099"
"18926","113.52000","9.46020","0.00044"
"18969","113.77800","9.48160","0.00047"
"19012","114.03600","9.50319","-0.00008"
"19055","114.29400","9.52465","0.00011"
"19098","114.55200","9.54624","0.00023"
"19141","114.81000","9.56764","-0.00004"
"19184","115.06800","9.58916","0.00001"
"19227","115.32600","9.61063","0.00037"
"19270","115.58400","9.63215","-0.00017"
"19313","115.84200","9.65368","0.00095"
"19356","116.10000","9.67520","0.00008"
"19399","116.35800","9.69667","0.00024"
"19442","116.61600","9.71825","0.00078"
"19485","116.87400","9.73966","0.00064"
"19528","117.13200","9.76124","0.00048"
"19571","117.39000","9.78264","0.00053"
"19614","117.64800","9.80417","0.00059"
"19657","117.90600","9.82569","0.00050"
"19700","118.16400","9.84722","0.00080"
"19743","118.42200","9.86874","0.00042"
"19786","118.68000","9.89020","0.00036"
"19829","118.93800","9.91167","0.00058"
"19872","119.19600","9.93313","0.00064"
"19915","119.45400","9.95472","0.00127"
"19958","119.71200","9.97618","0.00083"
"20001","119.97000","9.99771","0.00046"
"20044","120.22800","10.01917","0.00074"
"20087","120.48600","10.04076","0.00043"
"20130","120.74400","10.06216","0.00046"
"20173","121.00200","10.08374","0.00200"
"20216","121.26000","10.10515","0.00077"
"20259","121.51800","10.12667","0.00065"
"20302","121.77600","10.14814","0.00107"
"20345","122.03400","10.16966","0.00098"
"20388","122.29200","10.19118","0.00107"
"20431","122.55000","10.21271","0.00040"
"20474","122.80800","10.23417","0.00074"
"20517","123.06600","10.25570","0.00121"
"20560","123.32400","10.27716","0.00075"
"20603","123.58200","10.29869","0.00131"
"20646","123.84000","10.32015","0.00069"
"20689","124.09800","10.34168","0.00106"
"20732","124.35600","10.36314","0.00120"
"20775","124.61400","10.38466","0.00121"
"20818","124.87200","10.40625","0.00086"
"20861","125.13000","10.42771","0.00128"
"20904","125.38800","10.44918","0.00184"
"20947","125.64600","10.47070","0.00096"
"20990","125.90400","10.49217","0.00135"
"21033","126.16200","10.51369","0.00127"
"21076","126.42000","10.53522","0.00092"
"21119","126.67800","10.55662","0.00156"
"21162","126.93600","10.57820","0.00133"
"21205","127.19400","10.59961","0.00126"
"21248","127.45200","10.62125","0.00205"
"21291","127.71000","10.64266","0.00185"
"21334","127.96800","10.66424","0.00128"
"21377","128.22600","10.68559","0.00185"
"21420","128.48400","10.70717","0.00161"
"21463","128.74200","10.72869","0.00164"
"21506","129.00000","10.75022","0.00174"
"21549","129.25800","10.77168","0.00244"
"21592","129.51600","10.79321","0.00181"
"21635","129.77400","10.81473","0.00144"
"21678","130.03200","10.83619","0.00216"
"21721","130.29000","10.85766","0.00238"
"21764","130.54800","10.87918","0.00235"
"21807","130.80600","10.90065","0.00232"
"21850","131.06400","10.92217","0.00208"
"21893","131.32200","10.94370","0.00265"
"21936","131.58000","10.96516","0.00226"
"21979","131.83800","10.98669","0.00241"
"22022","132.09600","11.00815","0.00242"
"22065","132.35400","11.02967","0.00287"
"22108","132.61200","11.05120","0.00265"
"22151","132.87000","11.07272","0.00272"
"22194","133.12800","11.09413","0.00286"
"22237","133.38600","11.11571","0.00266"
"22280","133.64400","11.13711","0.00291"
"22323","133.90200","11.15870","0.00250"
"22366","134.16000","11.18010","0.00297"
"22409","134.41800","11.20163","0.00287"
"22452","134.67600","11.22309","0.00326"
"22495","134.93400","11.24474","0.00308"
"22538","135.19200","11.26614","0.00318"
"22581","135.45000","11.28773","0.00295"
"22624","135.70800","11.30919","0.00323"
"22667","135.96600","11.33071","0.00342"
"22710","136.22400","11.35212","0.00338"
"22753","136.48200","11.37370","0.00321"
"22796","136.74000","11.39517","0.00347"
"22839","136.99800","11.41669","0.00352"
"22882","137.25600","11.43822","0.00354"
"22925","137.51400","11.45968","0.00343"
"22968","137.77200","11.48120","0.00371"
"23011","138.03000","11.50267","0.00425"
"23054","138.28800","11.52419","0.00342"
"23097","138.54600","11.54560","0.00398"
"23140","138.80400","11.56724","0.00395"
"23183","139.06200","11.58865","0.00420"
"23226","139.32000","11.61023","0.00376"
"23269","139.57800","11.63164","0.00403"
"23312","139.83600","11.65316","0.00440"
"23355","140.09400","11.67468","0.00451"
"23398","140.35200","11.69621","0.00448"
"23441","140.61000","11.71767","0.00460"
"23484","140.86800","11.73914","0.00445"
"23527","141.12600","11.76060","0.00485"
"23570","141.38400","11.78219","0.00439"
"23613","141.64200","11.80365","0.00498"
"23656","141.90000","11.82517","0.00462"
"23699","142.15800","11.84664","0.00467"
"23742","142.41600","11.86816","0.00461"
"23785","142.67400","11.88969","0.00502"
"23828","142.93200","11.91127","0.00468"
"23871","143.19000","11.93262","0.00515"
"23914","143.44800","11.95420","0.00520"
"23957","143.70600","11.97572","0.00487"
"24000","143.96400","11.99719","0.00510"
"24043","144.22200","12.01871","0.00498"
"24086","144.48000","12.04018","0.00526"
"24129","144.73800","12.06176","0.00601"
"24172","144.99600","12.08317","0.00569"
"24215","145.25400","12.10469","0.00554"
"24258","145.51200","12.12615","0.00591"
"24301","145.77000","12.14768","0.00573"
"24344","146.02800","12.16914","0.00646"
"24387","146.28600","12.19073","0.00648"
"24430","146.54400","12.21219","0.00614"
"24473","146.80200","12.23372","0.00601"
"24516","147.06000","12.25512","0.00610"
"24559","147.31800","12.27664","0.00682"
"24602","147.57600","12.29817","0.00687"
"24645","147.83400","12.31975","0.00640"
"24688","148.09200","12.34122","0.00662"
"24731","148.35000","12.36274","0.00679"
"24774","148.60800","12.38421","0.00636"
"24817","148.86600","12.40567","0.00692"
"24860","149.12400","12.42719","0.00687"
"24903","149.38200","12.44866","0.00731"
"24946","149.64000","12.47012","0.00734"
"24989","149.89800","12.49165","0.00704"
"25032","150.15600","12.51317","0.00726"
"25075","150.41400","12.53470","0.00789"
"25118","150.67200","12.55622","0.00767"
"25161","150.93000","12.57763","0.00799"
"25204","151.18800","12.59921","0.00778"
"25247","151.44600","12.62067","0.00774"
"25290","151.70400","12.64220","0.00765"
"25333","151.96200","12.66366","0.00785"
"25376","152.22000","12.68525","0.00845"
"25419","152.47800","12.70665","0.00750"
"25462","152.73600","12.72818","0.00824"
"25505","152.99400","12.74964","0.00813"
"25548","153.25200","12.77122","0.00875"
"25591","153.51000","12.79263","0.00920"
"25634","153.76800","12.81415","0.00908"
"25677","154.02600","12.83562","0.00905"
"25720","154.28400","12.85720","0.00896"
"25763","154.54200","12.87866","0.00932"
"25806","154.80000","12.90019","0.00979"
"25849","155.05800","12.92165","0.00977"
"25892","155.31600","12.94318","0.00948"
"25935","155.57400","12.96470","0.01033"
"25978","155.83200","12.98617","0.00959"
"26021","156.09000","13.00769","0.00950"
"26064","156.34800","13.02922","0.01024"
"26107","156.60600","13.05068","0.01014"
"26150","156.86400","13.07215","0.00974"
"26193","157.12200","13.09367","0.01003"
"26236","157.38000","13.11513","0.01081"
"26279","157.63800","13.13672","0.01033"
"26322","157.89600","13.15818","0.01090"
"26365","158.15400","13.17971","0.01042"
"26408","158.41200","13.20111","0.01113"
"26451","158.67000","13.22269","0.01163"
"26494","158.92800","13.24416","0.01107"
"26537","159.18600","13.26568","0.01210"
"26580","159.44400","13.28715","0.01211"
"26623","159.70200","13.30873","0.01137"
"26666","159.96000","13.33014","0.01236"
"26709","160.21800","13.35172","0.01185"
"26752","160.47600","13.37313","0.01194"
"26795","160.73400","13.39471","0.01286"
"26838","160.99200","13.41611","0.01330"
"26881","161.25000","13.43770","0.01301"
"26924","161.50800","13.45916","0.01273"
"26967","161.76600","13.48069","0.01358"
"27010","162.02400","13.50221","0.01313"
"27053","162.28200","13.52361","0.01436"
"27096","162.54000","13.54514","0.01348"
"27139","162.79800","13.56666","0.01369"
"27182","163.05600","13.58825","0.01393"
"27225","163.31400","13.60965","0.01484"
"27268","163.57200","13.63118","0.01428"
"27311","163.83000","13.65264","0.01475"
"27354","164.08800","13.67423","0.01538"
"27397","164.34600","13.69563","0.01539"
"27440","164.60400","13.71721","0.01555"
"27483","164.86200","13.73862","0.01596"
"27526","165.12000","13.76020","0.01574"
"27569","165.37800","13.78167","0.01559"
"27612","165.63600","13.80319","0.01527"
"27655","165.89400","13.82465","0.01616"
"27698","166.15200","13.84612","0.01643"
"27741","166.41000","13.86764","0.01661"
"27784","166.66800","13.88917","0.01690"
"27827","166.92600","13.91063","0.01651"
"27870","167.18400","13.93222","0.01693"
"27913","167.44200","13.95362","0.01761"
"27956","167.70000","13.97515","0.01792"
"27999","167.95800","13.99667","0.01816"
"28042","168.21600","14.01819","0.01779"
"28085","168.47400","14.03972","0.01848"
"28128","168.73200","14.06118","0.01847"
"28171","168.99000","14.08265","0.01889"
"28214","169.24800","14.10417","0.01894"
"28257","169.50600","14.12570","0.01977"
"28300","169.76400","14.14716","0.02020"
"28343","170.02200","14.16868","0.02023"
"28386","170.28000","14.19009","0.02030"
"28429","170.53800","14.21173","0.02059"
"28472","170.79600","14.23314","0.02055"
"28515","171.05400","14.25472","0.02142"
"28558","171.31200","14.27607","0.02117"
"28601","171.57000","14.29771","0.02240"
"28644","171.82800","14.31911","0.02171"
"28687","172.08600","14.34070","0.02204"
"28730","172.34400","14.36216","0.02254"
"28773","172.60200","14.38369","0.02290"
"28816","172.86000","14.40515","0.02322"
"28859","173.11800","14.42668","0.02391"
"28902","173.37600","14.44814","0.02415"
"28945","173.63400","14.46972","0.02429"
"28988","173.89200","14.49119","0.02476"
"29031","174.15000","14.51265","0.02507"
"29074","174.40800","14.53412","0.02522"
"29117","174.66600","14.55570","0.02558"
"29160","174.92400","14.57723","0.02575"
"29203","175.18200","14.59863","0.02527"
"29246","175.44000","14.62016","0.02578"
"29289","175.69800","14.64168","0.02603"
"29332","175.95600","14.66320","0.02570"
"29375","176.21400","14.68467","0.02612"
"29418","176.47200","14.70619","0.02644"
"29461","176.73000","14.72766","0.02662"
"29504","176.98800","14.74918","0.02715"
"29547","177.24600","14.77059","0.02736"
"29590","177.50400","14.79217","0.02782"
"29633","177.76200","14.81363","0.02763"
"29676","178.02000","14.83522","0.02826"
"29719","178.27800","14.85662","0.02854"
"29762","178.53600","14.87821","0.02897"
"29805","178.79400","14.89967","0.02908"
"29848","179.05200","14.92120","0.02937"
"29891","179.31000","14.94260","0.02924"
"29934","179.56800","14.96418","0.02951"
"29977","179.82600","14.98565","0.02995"
"30020","180.08400","15.00717","0.03007"
"30063","180.34200","15.02864","0.03047"
"30106","180.60000","15.05022","0.03036"
"30149","180.85800","15.07169","0.03060"
"30192","181.11600","15.09321","0.03112"
"30235","181.37400","15.11468","0.03125"
"30278","181.63200","15.13614","0.03153"
"30321","181.89000","15.15772","0.03174"
"30364","182.14800","15.17913","0.03179"
"30407","182.40600","15.20071","0.03202"
"30450","182.66400","15.22212","0.03213"
"30493","182.92200","15.24364","0.03268"
"30536","183.18000","15.26517","0.03300"
"30579","183.43800","15.28675","0.03296"
"30622","183.69600","15.30815","0.03304"
"30665","183.95400","15.32962","0.03354"
"30708","184.21200","15.35108","0.03371"
"30751","184.47000","15.37267","0.03373"
"30794","184.72800","15.39413","0.03413"
"30837","184.98600","15.41566","0.03411"
"30880","185.24400","15.43712","0.03423"
"30923","185.50200","15.45864","0.03447"
"30966","185.76000","15.48017","0.03498"
"31009","186.01800","15.50175","0.03547"
"31052","186.27600","15.52316","0.03609"
"31095","186.53400","15.54468","0.03634"
"31138","186.79200","15.56614","0.03624"
"31181","187.05000","15.58767","0.03707"
"31224","187.30800","15.60913","0.03708"
"31267","187.56600","15.63072","0.03793"
"31310","187.82400","15.65218","0.03836"
"31353","188.08200","15.67371","0.03925"
"31396","188.34000","15.69523","0.03915"
"31439","188.59800","15.71663","0.03990"
"31482","188.85600","15.73822","0.04071"
"31525","189.11400","15.75968","0.04117"
"31568","189.37200","15.78121","0.04152"
"31611","189.63000","15.80261","0.04279"
"31654","189.88800","15.82420","0.04343"
"31697","190.14600","15.84566","0.04409"
"31740","190.40400","15.86718","0.04452"
"31783","190.66200","15.88859","0.04608"
"31826","190.92000","15.91017","0.04669"
"31869","191.17800","15.93170","0.04705"
"31912","191.43600","15.95322","0.04195"
"31955","191.69400","15.97463","0.03547"
"31998","191.95200","15.99615","0.04028"
"32041","192.21000","16.01762","0.04010"
"32084","192.46800","16.03920","0.03878"
"32127","192.72600","16.06066","0.04533"
"32170","192.98400","16.08213","0.04176"
"32213","193.24200","16.10359","0.04363"
"32256","193.50000","16.12518","0.04570"
"32299","193.75800","16.14670","0.04385"
"32342","194.01600","16.16817","0.04697"
"32385","194.27400","16.18969","0.04905"
"32428","194.53200","16.21115","0.03400"
"32471","194.79000","16.23268","0.02895"
"32514","195.04800","16.25420","0.03174"
"32557","195.30600","16.27573","0.03151"
"32600","195.56400","16.29713","0.03106"
"32643","195.82200","16.31872","0.03270"
"32686","196.08000","16.34012","0.03272"
"32729","196.33800","16.36170","0.03194"
"32772","196.59600","16.38311","0.03356"
"32815","196.85400","16.40469","0.03363"
"32858","197.11200","16.42610","0.03412"
"32901","197.37000","16.44768","0.03436"
"32944","197.62800","16.46915","0.03467"
"32987","197.88600","16.49073","0.03546"
"33030","198.14400","16.51213","0.03518"
"33073","198.40200","16.53372","0.03657"
"33116","198.66000","16.55512","0.03682"
"33159","198.91800","16.57671","0.03662"
"33202","199.17600","16.59817","0.03840"
"33245","199.43400","16.61970","0.03866"
"33288","199.69200","16.64116","0.03931"
"33331","199.95000","16.66263","0.04096"
"33374","200.20800","16.68415","0.04156"
"33417","200.46600","16.70567","0.04269"
"33460","200.72400","16.72720","0.04403"
"33503","200.98200","16.74866","0.04526"
"33546","201.24000","16.77019","0.04686"
"33589","201.49800","16.79171","0.04833"
"33632","201.75600","16.81318","0.04999"
"33675","202.01400","16.83464","0.05102"
"33718","202.27200","16.85616","0.05261"
"33761","202.53000","16.87763","0.05420"
"33804","202.78800","16.89921","0.05597"
"33847","203.04600","16.92062","0.05732"
"33890","203.30400","16.94214","0.05860"
"33933","203.56200","16.96360","0.05954"
"33976","203.82000","16.98519","0.06145"
"34019","204.07800","17.00665","0.06263"
"34062","204.33600","17.02818","0.06416"
"34105","204.59400","17.04964","0.06508"
"34148","204.85200","17.07117","0.06601"
"34191","205.11000","17.09269","0.06744"
"34234","205.36800","17.11415","0.06880"
"34277","205.62600","17.13562","0.07035"
"34320","205.88400","17.15720","0.07186"
"34363","206.14200","17.17867","0.07410"
"34406","206.40000","17.20019","0.07557"
"34449","206.65800","17.22172","0.07705"
"34492","206.91600","17.24312","0.07820"
"34535","207.17400","17.26464","0.07207"
"34578","207.43200","17.28617","0.07146"
"34621","207.69000","17.30770","0.07349"
"34664","207.94800","17.32916","0.07125"
"34707","208.20600","17.35068","0.07165"
"34750","208.46400","17.37215","0.07417"
"34793","208.72200","17.39367","0.07467"
"34836","208.98000","17.41514","0.07378"
"34879","209.23800","17.43672","0.07547"
"34922","209.49600","17.45812","0.07821"
"34965","209.75400","17.47971","0.07843"
"35008","210.01200","17.50117","0.07936"
"35051","210.27000","17.52270","0.08063"
"35094","210.52800","17.54416","0.08195"
"35137","210.78600","17.56569","0.08257"
"35180","211.04400","17.58715","0.08359"
"35223","211.30200","17.60868","0.08428"
"35266","211.56000","17.63014","0.08465"
"35309","211.81800","17.65172","0.08481"
"35352","212.07600","17.67313","0.08524"
"35395","212.33400","17.69471","0.08558"
"35438","212.59200","17.71618","0.08591"
"35481","212.85000","17.73764","0.08654"
"35524","213.10800","17.75916","0.08703"
"35567","213.36600","17.78069","0.08780"
"35610","213.62400","17.80221","0.08873"
"35653","213.88200","17.82362","0.08960"
"35696","214.14000","17.84520","0.09068"
"35739","214.39800","17.86667","0.09283"
"35782","214.65600","17.88819","0.09236"
"35825","214.91400","17.90960","0.09125"
"35868","215.17200","17.93118","0.09404"
"35911","215.43000","17.95264","0.09248"
"35954","215.68800","17.97423","0.09257"
"35997","215.94600","17.99563","0.09431"
"36040","216.20400","18.01716","0.09665"
"36083","216.46200","18.03862","0.09821"
"36126","216.72000","18.06021","0.09909"
"36169","216.97800","18.08167","0.10029"
"36212","217.23600","18.10313","0.10209"
"36255","217.49400","18.12460","0.10357"
"36298","217.75200","18.14618","-0.00331"
"36341","218.01000","18.16771","0.02753"
"36384","218.26800","18.18923","0.02144"
"36427","218.52600","18.21064","0.00682"
"36470","218.78400","18.23216","0.02198"
"36513","219.04200","18.25362","0.02256"
"36556","219.30000","18.27521","0.01855"
"36599","219.55800","18.29673","0.01709"
"36642","219.81600","18.31820","0.02178"
"36685","220.07400","18.33966","0.02047"
"36728","220.33200","18.36113","0.01833"
"36771","220.59000","18.38271","0.02310"
"36814","220.84800","18.40412","0.02051"
"36857","221.10600","18.42576","0.01930"
"36900","221.36400","18.44716","0.02107"
"36943","221.62200","18.46869","0.02217"
"36986","221.88000","18.49015","0.02233"
"37029","222.13800","18.51168","0.02087"
"37072","222.39600","18.53314","0.02389"
"37115","222.65400","18.55466","0.02257"
"37158","222.91200","18.57613","0.02259"
"37201","223.17000","18.59772","0.02295"
"37244","223.42800","18.61918","0.02374"
"37287","223.68600","18.64070","0.02412"
"37330","223.94400","18.66217","0.02381"
"37373","224.20200","18.68369","0.02516"
"37416","224.46000","18.70522","0.02478"
"37459","224.71800","18.72668","0.02558"
"37502","224.97600","18.74820","0.02502"
"37545","225.23400","18.76967","0.02630"
"37588","225.49200","18.79119","0.02631"
"37631","225.75000","18.81272","0.02619"
"37674","226.00800","18.83418","0.02671"
"37717","226.26600","18.85571","0.02654"
"37760","226.52400","18.87723","0.02778"
"37803","226.78200","18.89863","0.02709"
"37846","227.04000","18.92022","0.02800"
"37889","227.29800","18.94162","0.02787"
"37932","227.55600","18.96315","0.02847"
"37975","227.81400","18.98461","0.02849"
"38018","228.07200","19.00620","0.02859"
"38061","228.33000","19.02760","0.02900"
"38104","228.58800","19.04918","0.02897"
"38147","228.84600","19.07065","0.02971"
"38190","229.10400","19.09217","0.02946"
"38233","229.36200","19.11364","0.03076"
"38276","229.62000","19.13522","0.03003"
"38319","229.87800","19.15669","0.03053"
"38362","230.13600","19.17821","0.03067"
"38405","230.39400","19.19967","0.03118"
"38448","230.65200","19.22120","0.03138"
"38491","230.91000","19.24272","0.03133"
"38534","231.16800","19.26419","0.03176"
"38577","231.42600","19.28565","0.03228"
"38620","231.68400","19.30718","0.03230"
"38663","231.94200","19.32870","0.03259"
"38706","232.20000","19.35017","0.03273"
"38749","232.45800","19.37169","0.03299"
"38792","232.71600","19.39315","0.03345"
"38835","232.97400","19.41474","0.03359"
"38878","233.23200","19.43620","0.03414"
"38921","233.49000","19.45773","0.03388"
"38964","233.74800","19.47913","0.03447"
"39007","234.00600","19.50072","0.03466"
"39050","234.26400","19.52212","0.03502"
"39093","234.52200","19.54370","0.03531"
"39136","234.78000","19.56517","0.03572"
"39179","235.03800","19.58669","0.03642"
"39222","235.29600","19.60816","0.03629"
"39265","235.55400","19.62968","0.03675"
"39308","235.81200","19.65114","0.03734"
"39351","236.07000","19.67273","0.03766"
"39394","236.32800","19.69413","0.03854"
"39437","236.58600","19.71566","0.03929"
"39480","236.84400","19.73712","0.03987"
"39523","237.10200","19.75871","0.04056"
"39566","237.36000","19.78023","0.04108"
"39609","237.61800","19.80169","0.04238"
"39652","237.87600","19.82316","0.04304"
"39695","238.13400","19.84468","0.04404"
"39738","238.39200","19.86621","0.04458"
"39781","238.65000","19.88767","0.04598"
"39824","238.90800","19.90920","0.04641"
"39867","239.16600","19.93066","0.04821"
"39910","239.42400","19.95218","0.04909"
"39953","239.68200","19.97365","0.04989"
"39996","239.94000","19.99524","0.05131"
"40039","240.19800","20.01664","0.05280"
"40082","240.45600","20.03822","0.05306"
"40125","240.71400","20.05963","0.05415"
"40168","240.97200","20.08121","0.05566"
"40211","241.23000","20.10267","0.05670"
"40254","241.48800","20.12420","0.05766"
"40297","241.74600","20.14566","0.05926"
"40340","242.00400","20.16719","0.05981"
"40383","242.26200","20.18865","0.06109"
"40426","242.52000","20.21024","0.06203"
"40469","242.77800","20.23164","0.05576"
"40512","243.03600","20.25317","0.05444"
"40555","243.29400","20.27463","0.05423"
"40598","243.55200","20.29615","0.05823"
"40641","243.81000","20.31768","0.05668"
"40684","244.06800","20.33914","0.05876"
"40727","244.32600","20.36067","0.05787"
"40770","244.58400","20.38219","0.06130"
"40813","244.84200","20.40372","0.06074"
"40856","245.10000","20.42518","0.06401"
"40899","245.35800","20.44670","0.06371"
"40942","245.61600","20.46817","0.06537"
"40985","245.87400","20.48975","0.06553"
"41028","246.13200","20.51116","0.06731"
"41071","246.39000","20.53274","0.06789"
"41114","246.64800","20.55409","0.07071"
"41157","246.90600","20.57567","0.07118"
"41200","247.16400","20.59713","0.07429"
"41243","247.42200","20.61872","0.07459"
"41286","247.68000","20.64018","0.07749"
"41329","247.93800","20.66171","0.07733"
"41372","248.19600","20.68317","0.07985"
"41415","248.45400","20.70470","0.08138"
"41458","248.71200","20.72610","0.08159"
"41501","248.97000","20.74769","0.08262"
"41544","249.22800","20.76915","0.08369"
"41587","249.48600","20.79067","0.08412"
"41630","249.74400","20.81220","0.08451"
"41673","250.00200","20.83366","0.08515"
"41716","250.26000","20.85518","0.08536"
"41759","250.51800","20.87671","0.08584"
"41802","250.77600","20.89824","0.08630"
"41845","251.03400","20.91964","0.08677"
"41888","251.29200","20.94122","0.08727"
"41931","251.55000","20.96269","0.08882"
"41974","251.80800","20.98415","0.08566"
"42017","252.06600","21.00567","0.08670"
"42060","252.32400","21.02720","0.08656"
"42103","252.58200","21.04873","0.08781"
"42146","252.84000","21.07019","0.08740"
"42189","253.09800","21.09166","0.08663"
"42232","253.35600","21.11324","0.08857"
"42275","253.61400","21.13464","0.09016"
"42318","253.87200","21.15623","0.09166"
"42361","254.13000","21.17763","0.09396"
"42404","254.38800","21.19916","0.09713"
"42447","254.64600","21.22062","0.09775"
"42490","254.90400","21.24220","0.10167"
"42533","255.16200","21.26367","0.10069"
"42576","255.42000","21.28519","0.10194"
"42619","255.67800","21.30666","0.10581"
"42662","255.93600","21.32818","0.10608"
"42705","256.19400","21.34971","0.10737"
"42748","256.45200","21.37123","0.10947"
"42791","256.71000","21.39270","0.11127"
"42834","256.96800","21.41416","0.11190"
"42877","257.22600","21.43568","0.11465"
"42920","257.48400","21.45715","0.11555"
"42963","257.74200","21.47873","0.11636"
"43006","258.00000","21.50014","0.11768"
"43049","258.25800","21.52172","0.11865"
"43092","258.51600","21.54319","0.11986"
"43135","258.77400","21.56471","0.12118"
"43178","259.03200","21.58617","0.12202"
"43221","259.29000","21.60770","0.12239"
"43264","259.54800","21.62904","0.12324"
"43307","259.80600","21.65069","0.12431"
"43350","260.06400","21.67215","0.12497"
"43393","260.32200","21.69368","0.12634"
"43436","260.58000","21.71520","0.12752"
"43479","260.83800","21.73672","0.12866"
"43522","261.09600","21.75819","0.12966"
"43565","261.35400","21.77971","0.13071"
"43608","261.61200","21.80118","0.13186"
"43651","261.87000","21.82270","0.13226"
"43694","262.12800","21.84416","0.13372"
"43737","262.38600","21.86569","0.08023"
"43780","262.64400","21.88721","0.06455"
"43823","262.90200","21.90874","0.08474"
"43866","263.16000","21.93014","0.06776"
"43909","263.41800","21.95167","0.08047"
"43952","263.67600","21.97319","0.08235"
"43995","263.93400","21.99466","0.07312"
"44038","264.19200","22.01624","0.08463"
"44081","264.45000","22.03765","0.07694"
"44124","264.70800","22.05923","0.08326"
"44167","264.96600","22.08063","0.08298"
"44210","265.22400","22.10222","0.08093"
"44253","265.48200","22.12368","0.08435"
"44296","265.74000","22.14520","0.08224"
"44339","265.99800","22.16661","0.08424"
"44382","266.25600","22.18819","0.08457"
"44425","266.51400","22.20966","0.08390"
"44468","266.77200","22.23124","0.08541"
"44511","267.03000","22.25265","0.08489"
"44554","267.28800","22.27417","0.08481"
"44597","267.54600","22.29570","0.08586"
"44640","267.80400","22.31722","0.08551"
"44683","268.06200","22.33868","0.08635"
"44726","268.32000","22.36015","0.08721"
"44769","268.57800","22.38167","0.08639"
"44812","268.83600","22.40320","0.08738"
"44855","269.09400","22.42472","0.08805"
"44898","269.35200","22.44619","0.08816"
"44941","269.61000","22.46765","0.08975"
"44984","269.86800","22.48918","0.09073"
"45027","270.12600","22.51064","0.09275"
"45070","270.38400","22.53210","0.09297"
"45113","270.64200","22.55369","0.09283"
"45156","270.90000","22.57515","0.09456"
"45199","271.15800","22.59668","0.09618"
"45242","271.41600","22.61820","0.09650"
"45285","271.67400","22.63972","0.09958"
"45328","271.93200","22.66113","0.10007"
"45371","272.19000","22.68266","0.09889"
"45414","272.44800","22.70412","0.10235"
"45457","272.70600","22.72570","0.10284"
"45500","272.96400","22.74717","0.10372"
"45543","273.22200","22.76875","0.10653"
"45586","273.48000","22.79015","0.10672"
"45629","273.73800","22.81174","0.10670"
"45672","273.99600","22.83315","0.10782"
"45715","274.25400","22.85467","0.10967"
"45758","274.51200","22.87619","0.11016"
"45801","274.77000","22.89766","0.11184"
"45844","275.02800","22.91918","0.11288"
"45887","275.28600","22.94065","0.11351"
"45930","275.54400","22.96223","0.11406"
"45973","275.80200","22.98369","0.11464"
"46016","276.06000","23.00522","0.11528"
"46059","276.31800","23.02668","0.11652"
"46102","276.57600","23.04815","0.11716"
"46145","276.83400","23.06967","0.11778"
"46188","277.09200","23.09120","0.11884"
"46231","277.35000","23.11266","0.11897"
"46274","277.60800","23.13424","0.11987"
"46317","277.86600","23.15565","0.12022"
"46360","278.12400","23.17718","0.12083"
"46403","278.38200","23.19864","0.12068"
"46446","278.64000","23.22016","0.12150"
"46489","278.89800","23.24163","0.12164"
"46532","279.15600","23.26315","0.12215"
"46575","279.41400","23.28468","0.12324"
"46618","279.67200","23.30620","0.12314"
"46661","279.93000","23.32760","0.12271"
"46704","280.18800","23.34919","0.12395"
"46747","280.44600","23.37065","0.12434"
"46790","280.70400","23.39224","0.12513"
"46833","280.96200","23.41364","0.12569"
"46876","281.22000","23.43517","0.12664"
"46919","281.47800","23.45669","0.12717"
"46962","281.73600","23.47815","0.12789"
"47005","281.99400","23.49968","0.12899"
"47048","282.25200","23.52120","0.12958"
"47091","282.51000","23.54267","0.13001"
"47134","282.76800","23.56413","0.13063"
"47177","283.02600","23.58566","0.13111"
"47220","283.28400","23.60718","0.13160"
"47263","283.54200","23.62870","0.13234"
"47306","283.80000","23.65011","0.13300"
"47349","284.05800","23.67169","0.13323"
"47392","284.31600","23.69316","0.13382"
"47435","284.57400","23.71474","0.13427"
"47478","284.83200","23.73615","0.13516"
"47521","285.09000","23.75767","0.13574"
"47564","285.34800","23.77913","0.13624"
"47607","285.60600","23.80066","0.13286"
"47650","285.86400","23.82212","0.13076"
"47693","286.12200","23.84371","0.13371"
"47736","286.38000","23.86517","0.13291"
"47779","286.63800","23.88670","0.13206"
"47822","286.89600","23.90816","0.13351"
"47865","287.15400","23.92968","0.13454"
"47908","287.41200","23.95115","0.13336"
"47951","287.67000","23.97267","0.13379"
"47994","287.92800","23.99414","0.13564"
"48037","288.18600","24.01566","0.13535"
"48080","288.44400","24.03718","0.13504"
"48123","288.70200","24.05871","0.13652"
"48166","288.96000","24.08017","0.13695"
"48209","289.21800","24.10170","0.13688"
"48252","289.47600","24.12316","0.13776"
"48295","289.73400","24.14463","0.13893"
"48338","289.99200","24.16621","0.13966"
"48381","290.25000","24.18762","0.14001"
"48424","290.50800","24.20920","0.14046"
"48467","290.76600","24.23061","0.14099"
"48510","291.02400","24.25225","0.14149"
"48553","291.28200","24.27365","0.14189"
"48596","291.54000","24.29518","0.14321"
"48639","291.79800","24.31658","0.14376"
"48682","292.05600","24.33822","0.14422"
"48725","292.31400","24.35969","0.14594"
"48768","292.57200","24.38116","0.14677"
"48811","292.83000","24.40268","0.14682"
"48854","293.08800","24.42420","0.14852"
"48897","293.34600","24.44567","0.14953"
"48940","293.60400","24.46719","0.15083"
"48983","293.86200","24.48866","0.15316"
"49026","294.12000","24.51018","0.15512"
"49069","294.37800","24.53171","0.15678"
"49112","294.63600","24.55317","0.15754"
"49155","294.89400","24.57470","0.16026"
"49198","295.15200","24.59616","0.16062"
"49241","295.41000","24.61768","0.16380"
"49284","295.66800","24.63915","0.16517"
"49327","295.92600","24.66073","0.16527"
"49370","296.18400","24.68219","0.16750"
"49413","296.44200","24.70366","0.17100"
"49456","296.70000","24.72512","0.17150"
"49499","296.95800","24.74671","0.17325"
"49542","297.21600","24.76817","0.17476"
"49585","297.47400","24.78970","0.17645"
"49628","297.73200","24.81110","0.17693"
"49671","297.99000","24.83269","0.17927"
"49714","298.24800","24.85409","0.18015"
"49757","298.50600","24.87568","0.18144"
"49800","298.76400","24.89714","0.18252"
"49843","299.02200","24.91872","0.18379"
"49886","299.28000","24.94019","0.18379"
"49929","299.53800","24.96171","0.18535"
"49972","299.79600","24.98323","0.18573"
"50015","300.05400","25.00470","0.18663"
"50058","300.31200","25.02617","0.18728"
"50101","300.57000","25.04763","0.18745"
"50144","300.82800","25.06915","0.18806"
"50187","301.08600","25.09068","0.18804"
"50230","301.34400","25.11220","0.18848"
"50273","301.60200","25.13361","0.18892"
"50316","301.86000","25.15519","0.18916"
"50359","302.11800","25.17665","0.18964"
"50402","302.37600","25.19818","0.18996"
"50445","302.63400","25.21958","0.19023"
"50488","302.89200","25.24123","0.19092"
"50531","303.15000","25.26263","0.19126"
"50574","303.40800","25.28422","0.19200"
"50617","303.66600","25.30568","0.19220"
"50660","303.92400","25.32721","0.19314"
"50703","304.18200","25.34861","0.19404"
"50746","304.44000","25.37020","0.19484"
"50789","304.69800","25.39166","0.19645"
"50832","304.95600","25.41324","0.19728"
"50875","305.21400","25.43471","0.19792"
"50918","305.47200","25.45617","0.19906"
"50961","305.73000","25.47763","0.20130"
"51004","305.98800","25.49922","0.20196"
"51047","306.24600","25.52068","0.20362"
"51090","306.50400","25.54221","0.20472"
"51133","306.76200","25.56367","0.20607"
"51176","307.02000","25.58513","0.20722"
"51219","307.27800","25.60672","0.20897"
"51262","307.53600","25.62819","0.20974"
"51305","307.79400","25.64971","0.21062"
"51348","308.05200","25.67112","0.21196"
"51391","308.31000","25.69270","0.21245"
"51434","308.56800","25.71416","0.21416"
"51477","308.82600","25.73575","0.21471"
"51520","309.08400","25.75709","0.21588"
"51563","309.34200","25.77868","0.21699"
"51606","309.60000","25.80014","0.21780"
"51649","309.85800","25.82172","0.21875"
"51692","310.11600","25.84313","0.21999"
"51735","310.37400","25.86465","0.22140"
"51778","310.63200","25.88618","0.22228"
"51821","310.89000","25.90764","0.22246"
"51864","311.14800","25.92911","0.22403"
"51907","311.40600","25.95075","0.22425"
"51950","311.66400","25.97216","0.22528"
"51993","311.92200","25.99368","0.22623"
"52036","312.18000","26.01520","0.22721"
"52079","312.43800","26.03667","0.22753"
"52122","312.69600","26.05819","0.22862"
"52165","312.95400","26.07966","0.22944"
"52208","313.21200","26.10112","0.23004"
"52251","313.47000","26.12265","0.23072"
"52294","313.72800","26.14417","0.23062"
"52337","313.98600","26.16563","-0.00875"
"52380","314.24400","26.18722","-0.01156"
"52423","314.50200","26.20868","-0.00052"
"52466","314.76000","26.23021","-0.00704"
"52509","315.01800","26.25167","-0.00763"
"52552","315.27600","26.27320","-0.00458"
"52595","315.53400","26.29460","-0.00399"
"52638","315.79200","26.31618","-0.00609"
"52681","316.05000","26.33765","-0.00512"
"52724","316.30800","26.35923","-0.00433"
"52767","316.56600","26.38064","-0.00465"
"52810","316.82400","26.40216","-0.00447"
"52853","317.08200","26.42363","-0.00572"
"52857","317.10200","26.42530","-0.00586"