File: Trajectories_together/170108_0Specimen_RawData_1.csv
"","V1","V2","V3"
"1","End date","1/8/2017",""
"2","Specimen label","20CG_57",""
"3","Maximum Load","0.01203","N"
"4","Time","Extension","Load"
"5","(s)","(mm)","(N)"
"6","0.00000","0.00000","-0.00065"
"37","0.18600","0.01244","-0.00010"
"68","0.37200","0.03115","0.00088"
"99","0.55800","0.04676","0.00085"
"130","0.74400","0.06230","0.00216"
"161","0.93000","0.07773","0.00105"
"192","1.11600","0.09321","0.00150"
"223","1.30200","0.10876","0.00128"
"254","1.48800","0.12424","0.00194"
"285","1.67400","0.13967","0.00207"
"316","1.86000","0.15527","0.00196"
"347","2.04600","0.17076","0.00234"
"378","2.23200","0.18618","0.00219"
"409","2.41800","0.20173","0.00266"
"440","2.60400","0.21722","0.00265"
"471","2.79000","0.23270","0.00290"
"502","2.97600","0.24819","0.00307"
"533","3.16200","0.26373","0.00290"
"564","3.34800","0.27916","0.00280"
"595","3.53400","0.29470","0.00328"
"626","3.72000","0.31019","0.00315"
"657","3.90600","0.32567","0.00313"
"688","4.09200","0.34128","0.00353"
"719","4.27800","0.35670","0.00379"
"750","4.46400","0.37219","0.00370"
"781","4.65000","0.38774","0.00336"
"812","4.83600","0.40322","0.00375"
"843","5.02200","0.41871","0.00399"
"874","5.20800","0.43425","0.00402"
"905","5.39400","0.44974","0.00395"
"936","5.58000","0.46522","0.00395"
"967","5.76600","0.48071","0.00447"
"998","5.95200","0.49619","0.00374"
"1029","6.13800","0.51168","0.00401"
"1060","6.32400","0.52722","0.00402"
"1091","6.51000","0.54271","0.00382"
"1122","6.69600","0.55825","0.00418"
"1153","6.88200","0.57374","0.00464"
"1184","7.06800","0.58917","0.00405"
"1215","7.25400","0.60477","0.00439"
"1246","7.44000","0.62026","0.00398"
"1277","7.62600","0.63568","0.00452"
"1308","7.81200","0.65123","0.00401"
"1339","7.99800","0.66671","0.00446"
"1370","8.18400","0.68220","0.00425"
"1401","8.37000","0.69774","0.00419"
"1432","8.55600","0.71323","0.00479"
"1463","8.74200","0.72866","0.00455"
"1494","8.92800","0.74426","0.00423"
"1525","9.11400","0.75975","0.00476"
"1556","9.30000","0.77517","0.00441"
"1587","9.48600","0.79072","0.00469"
"1618","9.67200","0.80620","0.00446"
"1649","9.85800","0.82169","0.00409"
"1680","10.04400","0.83723","0.00488"
"1711","10.23000","0.85272","0.00439"
"1742","10.41600","0.86826","0.00461"
"1773","10.60200","0.88375","0.00460"
"1804","10.78800","0.89917","0.00508"
"1835","10.97400","0.91472","0.00467"
"1866","11.16000","0.93027","0.00462"
"1897","11.34600","0.94569","0.00455"
"1928","11.53200","0.96124","0.00396"
"1959","11.71800","0.97678","0.00421"
"1990","11.90400","0.99215","0.00488"
"2021","12.09000","1.00769","0.00451"
"2052","12.27600","1.02330","0.00457"
"2083","12.46200","1.03866","0.00463"
"2114","12.64800","1.05427","0.00508"
"2145","12.83400","1.06975","0.00458"
"2176","13.02000","1.08518","0.00488"
"2207","13.20600","1.10073","0.00438"
"2238","13.39200","1.11621","0.00491"
"2269","13.57800","1.13176","0.00464"
"2300","13.76400","1.14718","0.00468"
"2331","13.95000","1.16267","0.00474"
"2362","14.13600","1.17827","0.00491"
"2393","14.32200","1.19370","0.00486"
"2424","14.50800","1.20918","0.00503"
"2455","14.69400","1.22473","0.00468"
"2486","14.88000","1.24021","0.00521"
"2517","15.06600","1.25570","0.00505"
"2548","15.25200","1.27119","0.00446"
"2579","15.43800","1.28673","0.00472"
"2610","15.62400","1.30216","0.00533"
"2641","15.81000","1.31770","0.00482"
"2672","15.99600","1.33325","0.00486"
"2703","16.18200","1.34867","0.00487"
"2734","16.36800","1.36422","0.00491"
"2765","16.55400","1.37970","0.00550"
"2796","16.74000","1.39519","0.00480"
"2827","16.92600","1.41073","0.00510"
"2858","17.11200","1.42628","0.00485"
"2889","17.29800","1.44170","0.00543"
"2920","17.48400","1.45725","0.00559"
"2951","17.67000","1.47274","0.00544"
"2982","17.85600","1.48822","0.00519"
"3013","18.04200","1.50377","0.00554"
"3044","18.22800","1.51919","0.00534"
"3075","18.41400","1.53468","0.00557"
"3106","18.60000","1.55028","0.00516"
"3137","18.78600","1.56571","0.00518"
"3168","18.97200","1.58119","0.00493"
"3199","19.15800","1.59674","0.00501"
"3230","19.34400","1.61222","0.00561"
"3261","19.53000","1.62765","0.00529"
"3292","19.71600","1.64326","0.00562"
"3323","19.90200","1.65868","0.00502"
"3354","20.08800","1.67417","0.00513"
"3385","20.27400","1.68977","0.00528"
"3416","20.46000","1.70514","0.00531"
"3447","20.64600","1.72068","0.00561"
"3478","20.83200","1.73623","0.00534"
"3509","21.01800","1.75171","0.00510"
"3540","21.20400","1.76720","0.00521"
"3571","21.39000","1.78274","0.00508"
"3602","21.57600","1.79817","0.00548"
"3633","21.76200","1.81372","0.00551"
"3664","21.94800","1.82920","0.00518"
"3695","22.13400","1.84463","0.00477"
"3726","22.32000","1.86029","0.00514"
"3757","22.50600","1.87572","0.00550"
"3788","22.69200","1.89114","0.00501"
"3819","22.87800","1.90681","0.00519"
"3850","23.06400","1.92223","0.00535"
"3881","23.25000","1.93766","0.00549"
"3912","23.43600","1.95326","0.00551"
"3943","23.62200","1.96875","0.00516"
"3974","23.80800","1.98418","0.00576"
"4005","23.99400","1.99966","0.00505"
"4036","24.18000","2.01521","0.00529"
"4067","24.36600","2.03069","0.00536"
"4098","24.55200","2.04624","0.00512"
"4129","24.73800","2.06166","0.00510"
"4160","24.92400","2.07721","0.00604"
"4191","25.11000","2.09269","0.00592"
"4222","25.29600","2.10818","0.00583"
"4253","25.48200","2.12372","0.00536"
"4284","25.66800","2.13921","0.00560"
"4315","25.85400","2.15470","0.00541"
"4346","26.04000","2.17024","0.00562"
"4377","26.22600","2.18579","0.00605"
"4408","26.41200","2.20115","0.00553"
"4439","26.59800","2.21676","0.00589"
"4470","26.78400","2.23224","0.00551"
"4501","26.97000","2.24767","0.00451"
"4532","27.15600","2.26321","0.00480"
"4563","27.34200","2.27876","0.00503"
"4594","27.52800","2.29412","0.00477"
"4625","27.71400","2.30979","0.00487"
"4656","27.90000","2.32521","0.00530"
"4687","28.08600","2.34064","0.00472"
"4718","28.27200","2.35631","0.00486"
"4749","28.45800","2.37173","0.00481"
"4780","28.64400","2.38722","0.00536"
"4811","28.83000","2.40276","0.00507"
"4842","29.01600","2.41813","0.00483"
"4873","29.20200","2.43367","0.00512"
"4904","29.38800","2.44922","0.00525"
"4935","29.57400","2.46470","0.00545"
"4966","29.76000","2.48025","0.00459"
"4997","29.94600","2.49573","0.00458"
"5028","30.13200","2.51116","0.00556"
"5059","30.31800","2.52671","0.00561"
"5090","30.50400","2.54225","0.00510"
"5121","30.69000","2.55768","0.00511"
"5152","30.87600","2.57322","0.00506"
"5183","31.06200","2.58877","0.00530"
"5214","31.24800","2.60419","0.00559"
"5245","31.43400","2.61974","0.00517"
"5276","31.62000","2.63522","0.00538"
"5307","31.80600","2.65071","0.00481"
"5338","31.99200","2.66625","0.00539"
"5369","32.17800","2.68174","0.00547"
"5400","32.36400","2.69723","0.00523"
"5431","32.55000","2.71277","0.00556"
"5462","32.73600","2.72820","0.00565"
"5493","32.92200","2.74368","0.00535"
"5524","33.10800","2.75929","0.00519"
"5555","33.29400","2.77471","0.00457"
"5586","33.48000","2.79020","0.00493"
"5617","33.66600","2.80574","0.00486"
"5648","33.85200","2.82117","0.00512"
"5679","34.03800","2.83671","0.00492"
"5710","34.22400","2.85226","0.00501"
"5741","34.41000","2.86769","0.00504"
"5772","34.59600","2.88317","0.00529"
"5803","34.78200","2.89872","0.00529"
"5834","34.96800","2.91420","0.00524"
"5865","35.15400","2.92969","0.00458"
"5896","35.34000","2.94523","0.00540"
"5927","35.52600","2.96066","0.00548"
"5958","35.71200","2.97626","0.00487"
"5989","35.89800","2.99175","0.00504"
"6020","36.08400","3.00717","0.00477"
"6051","36.27000","3.02272","0.00531"
"6082","36.45600","3.03820","0.00446"
"6113","36.64200","3.05369","0.00494"
"6144","36.82800","3.06924","0.00459"
"6175","37.01400","3.08478","0.00503"
"6206","37.20000","3.10021","0.00481"
"6237","37.38600","3.11575","0.00485"
"6268","37.57200","3.13124","0.00521"
"6299","37.75800","3.14666","0.00512"
"6330","37.94400","3.16221","0.00498"
"6361","38.13000","3.17775","0.00539"
"6392","38.31600","3.19318","0.00524"
"6423","38.50200","3.20878","0.00501"
"6454","38.68800","3.22427","0.00518"
"6485","38.87400","3.23970","0.00504"
"6516","39.06000","3.25524","0.00471"
"6547","39.24600","3.27079","0.00566"
"6578","39.43200","3.28621","0.00537"
"6609","39.61800","3.30170","0.00497"
"6640","39.80400","3.31718","0.00513"
"6671","39.99000","3.33273","0.00492"
"6702","40.17600","3.34821","0.00478"
"6733","40.36200","3.36370","0.00594"
"6764","40.54800","3.37924","0.00521"
"6795","40.73400","3.39473","0.00448"
"6826","40.92000","3.41022","0.00511"
"6857","41.10600","3.42570","0.00499"
"6888","41.29200","3.44125","0.00471"
"6919","41.47800","3.45673","0.00500"
"6950","41.66400","3.47222","0.00467"
"6981","41.85000","3.48770","0.00549"
"7012","42.03600","3.50319","0.00493"
"7043","42.22200","3.51873","0.00435"
"7074","42.40800","3.53422","0.00439"
"7105","42.59400","3.54970","0.00444"
"7136","42.78000","3.56519","0.00436"
"7167","42.96600","3.58074","0.00492"
"7198","43.15200","3.59616","0.00478"
"7229","43.33800","3.61177","0.00434"
"7260","43.52400","3.62725","0.00477"
"7291","43.71000","3.64274","0.00467"
"7322","43.89600","3.65822","0.00445"
"7353","44.08200","3.67371","0.00432"
"7384","44.26800","3.68925","0.00470"
"7415","44.45400","3.70474","0.00433"
"7446","44.64000","3.72022","0.00417"
"7477","44.82600","3.73571","0.00474"
"7508","45.01200","3.75126","0.00422"
"7539","45.19800","3.76668","0.00508"
"7570","45.38400","3.78223","0.00455"
"7601","45.57000","3.79777","0.00387"
"7632","45.75600","3.81320","0.00464"
"7663","45.94200","3.82868","0.00522"
"7694","46.12800","3.84429","0.00403"
"7725","46.31400","3.85965","0.00444"
"7756","46.50000","3.87520","0.00436"
"7787","46.68600","3.89074","0.00398"
"7818","46.87200","3.90623","0.00506"
"7849","47.05800","3.92172","0.00480"
"7880","47.24400","3.93726","0.00417"
"7911","47.43000","3.95263","0.00526"
"7942","47.61600","3.96823","0.00476"
"7973","47.80200","3.98372","0.00470"
"8004","47.98800","3.99920","0.00473"
"8035","48.17400","4.01475","0.00487"
"8066","48.36000","4.03023","0.00440"
"8097","48.54600","4.04566","0.00459"
"8128","48.73200","4.06120","0.00498"
"8159","48.91800","4.07675","0.00417"
"8190","49.10400","4.09218","0.00480"
"8221","49.29000","4.10778","0.00446"
"8252","49.47600","4.12321","0.00432"
"8283","49.66200","4.13863","0.00448"
"8314","49.84800","4.15424","0.00432"
"8345","50.03400","4.16972","0.00473"
"8376","50.22000","4.18521","0.00491"
"8407","50.40600","4.20069","0.00515"
"8438","50.59200","4.21624","0.00452"
"8469","50.77800","4.23166","0.00468"
"8500","50.96400","4.24721","0.00490"
"8531","51.15000","4.26269","0.00475"
"8562","51.33600","4.27824","0.00441"
"8593","51.52200","4.29379","0.00439"
"8624","51.70800","4.30921","0.00483"
"8655","51.89400","4.32476","0.00432"
"8686","52.08000","4.34024","0.00490"
"8717","52.26600","4.35567","0.00533"
"8748","52.45200","4.37127","0.00474"
"8779","52.63800","4.38670","0.00444"
"8810","52.82400","4.40212","0.00409"
"8841","53.01000","4.41773","0.00555"
"8872","53.19600","4.43327","0.00409"
"8903","53.38200","4.44864","0.00511"
"8934","53.56800","4.46425","0.00445"
"8965","53.75400","4.47973","0.00430"
"8996","53.94000","4.49516","0.00491"
"9027","54.12600","4.51076","0.00430"
"9058","54.31200","4.52631","0.00497"
"9089","54.49800","4.54173","0.00445"
"9120","54.68400","4.55722","0.00444"
"9151","54.87000","4.57270","0.00510"
"9182","55.05600","4.58819","0.00450"
"9213","55.24200","4.60373","0.00473"
"9244","55.42800","4.61916","0.00416"
"9275","55.61400","4.63477","0.00491"
"9306","55.80000","4.65025","0.00495"
"9337","55.98600","4.66568","0.00448"
"9368","56.17200","4.68122","0.00464"
"9399","56.35800","4.69677","0.00481"
"9430","56.54400","4.71219","0.00433"
"9461","56.73000","4.72774","0.00520"
"9492","56.91600","4.74322","0.00530"
"9523","57.10200","4.75865","0.00528"
"9554","57.28800","4.77425","0.00508"
"9585","57.47400","4.78980","0.00497"
"9616","57.66000","4.80517","0.00512"
"9647","57.84600","4.82077","0.00490"
"9678","58.03200","4.83626","0.00505"
"9709","58.21800","4.85168","0.00530"
"9740","58.40400","4.86723","0.00538"
"9771","58.59000","4.88271","0.00520"
"9802","58.77600","4.89820","0.00462"
"9833","58.96200","4.91374","0.00505"
"9864","59.14800","4.92917","0.00545"
"9895","59.33400","4.94471","0.00475"
"9926","59.52000","4.96020","0.00487"
"9957","59.70600","4.97568","0.00525"
"9988","59.89200","4.99123","0.00491"
"10019","60.07800","5.00672","0.00478"
"10050","60.26400","5.02220","0.00536"
"10081","60.45000","5.03769","0.00511"
"10112","60.63600","5.05323","0.00514"
"10143","60.82200","5.06872","0.00565"
"10174","61.00800","5.08426","0.00548"
"10205","61.19400","5.09975","0.00514"
"10236","61.38000","5.11517","0.00503"
"10267","61.56600","5.13072","0.00526"
"10298","61.75200","5.14626","0.00497"
"10329","61.93800","5.16169","0.00523"
"10360","62.12400","5.17729","0.00561"
"10391","62.31000","5.19272","0.00500"
"10422","62.49600","5.20815","0.00519"
"10453","62.68200","5.22375","0.00498"
"10484","62.86800","5.23924","0.00497"
"10515","63.05400","5.25472","0.00477"
"10546","63.24000","5.27027","0.00490"
"10577","63.42600","5.28569","0.00519"
"10608","63.61200","5.30118","0.00475"
"10639","63.79800","5.31672","0.00491"
"10670","63.98400","5.33221","0.00508"
"10701","64.17000","5.34770","0.00522"
"10732","64.35600","5.36318","0.00532"
"10763","64.54200","5.37873","0.00536"
"10794","64.72800","5.39415","0.00513"
"10825","64.91400","5.40976","0.00521"
"10856","65.10000","5.42518","0.00546"
"10887","65.28600","5.44067","0.00543"
"10918","65.47200","5.45621","0.00494"
"10949","65.65800","5.47170","0.00491"
"10980","65.84400","5.48718","0.00551"
"11011","66.03000","5.50267","0.00518"
"11042","66.21600","5.51821","0.00512"
"11073","66.40200","5.53370","0.00514"
"11104","66.58800","5.54919","0.00532"
"11135","66.77400","5.56467","0.00484"
"11166","66.96000","5.58022","0.00547"
"11197","67.14600","5.59576","0.00534"
"11228","67.33200","5.61119","0.00519"
"11259","67.51800","5.62673","0.00514"
"11290","67.70400","5.64222","0.00529"
"11321","67.89000","5.65764","0.00596"
"11352","68.07600","5.67325","0.00520"
"11383","68.26200","5.68874","0.00556"
"11414","68.44800","5.70422","0.00548"
"11445","68.63400","5.71977","0.00523"
"11476","68.82000","5.73525","0.00562"
"11507","69.00600","5.75068","0.00524"
"11538","69.19200","5.76622","0.00539"
"11569","69.37800","5.78177","0.00495"
"11600","69.56400","5.79725","0.00581"
"11631","69.75000","5.81268","0.00570"
"11662","69.93600","5.82822","0.00532"
"11693","70.12200","5.84377","0.00545"
"11724","70.30800","5.85920","0.00563"
"11755","70.49400","5.87468","0.00526"
"11786","70.68000","5.89023","0.00558"
"11817","70.86600","5.90571","0.00529"
"11848","71.05200","5.92114","0.00578"
"11879","71.23800","5.93674","0.00519"
"11910","71.42400","5.95223","0.00528"
"11941","71.61000","5.96771","0.00581"
"11972","71.79600","5.98320","0.00571"
"12003","71.98200","5.99874","0.00517"
"12034","72.16800","6.01417","0.00582"
"12065","72.35400","6.02972","0.00520"
"12096","72.54000","6.04526","0.00568"
"12127","72.72600","6.06069","0.00545"
"12158","72.91200","6.07623","0.00581"
"12189","73.09800","6.09172","0.00580"
"12220","73.28400","6.10714","0.00568"
"12251","73.47000","6.12269","0.00538"
"12282","73.65600","6.13823","0.00553"
"12313","73.84200","6.15372","0.00542"
"12344","74.02800","6.16920","0.00557"
"12375","74.21400","6.18469","0.00520"
"12406","74.40000","6.20017","0.00547"
"12437","74.58600","6.21572","0.00498"
"12468","74.77200","6.23120","0.00557"
"12499","74.95800","6.24675","0.00503"
"12530","75.14400","6.26224","0.00553"
"12561","75.33000","6.27772","0.00520"
"12592","75.51600","6.29321","0.00533"
"12623","75.70200","6.30875","0.00555"
"12654","75.88800","6.32424","0.00570"
"12685","76.07400","6.33972","0.00520"
"12716","76.26000","6.35521","0.00531"
"12747","76.44600","6.37069","0.00502"
"12778","76.63200","6.38618","0.00523"
"12809","76.81800","6.40179","0.00506"
"12840","77.00400","6.41721","0.00508"
"12871","77.19000","6.43276","0.00505"
"12902","77.37600","6.44824","0.00532"
"12933","77.56200","6.46367","0.00514"
"12964","77.74800","6.47921","0.00540"
"12995","77.93400","6.49470","0.00540"
"13026","78.12000","6.51018","0.00576"
"13057","78.30600","6.52579","0.00546"
"13088","78.49200","6.54121","0.00548"
"13119","78.67800","6.55664","0.00506"
"13150","78.86400","6.57230","0.00544"
"13181","79.05000","6.58773","0.00541"
"13212","79.23600","6.60316","0.00523"
"13243","79.42200","6.61876","0.00516"
"13274","79.60800","6.63425","0.00502"
"13305","79.79400","6.64967","0.00509"
"13336","79.98000","6.66528","0.00443"
"13367","80.16600","6.68070","0.00500"
"13398","80.35200","6.69619","0.00492"
"13429","80.53800","6.71173","0.00473"
"13460","80.72400","6.72716","0.00519"
"13491","80.91000","6.74271","0.00520"
"13522","81.09600","6.75825","0.00493"
"13553","81.28200","6.77368","0.00478"
"13584","81.46800","6.78928","0.00458"
"13615","81.65400","6.80471","0.00520"
"13646","81.84000","6.82019","0.00503"
"13677","82.02600","6.83574","0.00528"
"13708","82.21200","6.85122","0.00492"
"13739","82.39800","6.86671","0.00502"
"13770","82.58400","6.88225","0.00510"
"13801","82.77000","6.89774","0.00506"
"13832","82.95600","6.91311","0.00493"
"13863","83.14200","6.92877","0.00532"
"13894","83.32800","6.94426","0.00553"
"13925","83.51400","6.95968","0.00514"
"13956","83.70000","6.97523","0.00502"
"13987","83.88600","6.99071","0.00515"
"14018","84.07200","7.00614","0.00506"
"14049","84.25800","7.02174","0.00567"
"14080","84.44400","7.03723","0.00485"
"14111","84.63000","7.05271","0.00579"
"14142","84.81600","7.06826","0.00539"
"14173","85.00200","7.08368","0.00544"
"14204","85.18800","7.09917","0.00546"
"14235","85.37400","7.11472","0.00552"
"14266","85.56000","7.13014","0.00517"
"14297","85.74600","7.14569","0.00579"
"14328","85.93200","7.16123","0.00603"
"14359","86.11800","7.17660","0.00558"
"14390","86.30400","7.19226","0.00572"
"14421","86.49000","7.20781","0.00583"
"14452","86.67600","7.22317","0.00509"
"14483","86.86200","7.23878","0.00550"
"14514","87.04800","7.25420","0.00562"
"14545","87.23400","7.26963","0.00596"
"14576","87.42000","7.28524","0.00541"
"14607","87.60600","7.30078","0.00604"
"14638","87.79200","7.31615","0.00624"
"14669","87.97800","7.33175","0.00562"
"14700","88.16400","7.34724","0.00556"
"14731","88.35000","7.36266","0.00592"
"14762","88.53600","7.37827","0.00519"
"14793","88.72200","7.39369","0.00574"
"14824","88.90800","7.40924","0.00592"
"14855","89.09400","7.42472","0.00536"
"14886","89.28000","7.44021","0.00531"
"14917","89.46600","7.45575","0.00539"
"14948","89.65200","7.47124","0.00596"
"14979","89.83800","7.48667","0.00589"
"15010","90.02400","7.50221","0.00595"
"15041","90.21000","7.51776","0.00570"
"15072","90.39600","7.53318","0.00595"
"15103","90.58200","7.54873","0.00598"
"15134","90.76800","7.56427","0.00608"
"15165","90.95400","7.57970","0.00622"
"15196","91.14000","7.59518","0.00590"
"15227","91.32600","7.61073","0.00622"
"15258","91.51200","7.62616","0.00617"
"15289","91.69800","7.64170","0.00576"
"15320","91.88400","7.65725","0.00648"
"15351","92.07000","7.67267","0.00588"
"15382","92.25600","7.68822","0.00602"
"15413","92.44200","7.70370","0.00512"
"15444","92.62800","7.71913","0.00612"
"15475","92.81400","7.73473","0.00550"
"15506","93.00000","7.75022","0.00602"
"15537","93.18600","7.76570","0.00586"
"15568","93.37200","7.78125","0.00636"
"15599","93.55800","7.79667","0.00586"
"15630","93.74400","7.81216","0.00583"
"15661","93.93000","7.82777","0.00558"
"15692","94.11600","7.84319","0.00586"
"15723","94.30200","7.85868","0.00523"
"15754","94.48800","7.87428","0.00566"
"15785","94.67400","7.88971","0.00576"
"15816","94.86000","7.90519","0.00611"
"15847","95.04600","7.92074","0.00596"
"15878","95.23200","7.93622","0.00569"
"15909","95.41800","7.95171","0.00553"
"15940","95.60400","7.96719","0.00537"
"15971","95.79000","7.98268","0.00532"
"16002","95.97600","7.99823","0.00528"
"16033","96.16200","8.01377","0.00525"
"16064","96.34800","8.02920","0.00572"
"16095","96.53400","8.04468","0.00549"
"16126","96.72000","8.06023","0.00633"
"16157","96.90600","8.07565","0.00509"
"16188","97.09200","8.09126","0.00531"
"16219","97.27800","8.10674","0.00569"
"16250","97.46400","8.12217","0.00574"
"16281","97.65000","8.13777","0.00554"
"16312","97.83600","8.15326","0.00556"
"16343","98.02200","8.16868","0.00529"
"16374","98.20800","8.18423","0.00527"
"16405","98.39400","8.19978","0.00526"
"16436","98.58000","8.21514","0.00571"
"16467","98.76600","8.23075","0.00553"
"16498","98.95200","8.24623","0.00521"
"16529","99.13800","8.26172","0.00551"
"16560","99.32400","8.27720","0.00531"
"16591","99.51000","8.29275","0.00564"
"16622","99.69600","8.30817","0.00539"
"16653","99.88200","8.32372","0.00526"
"16684","100.06800","8.33920","0.00570"
"16715","100.25400","8.35469","0.00557"
"16746","100.44000","8.37024","0.00527"
"16777","100.62600","8.38572","0.00511"
"16808","100.81200","8.40127","0.00521"
"16839","100.99800","8.41675","0.00525"
"16870","101.18400","8.43218","0.00524"
"16901","101.37000","8.44772","0.00507"
"16932","101.55600","8.46327","0.00506"
"16963","101.74200","8.47869","0.00505"
"16994","101.92800","8.49424","0.00510"
"17025","102.11400","8.50972","0.00514"
"17056","102.30000","8.52515","0.00554"
"17087","102.48600","8.54076","0.00521"
"17118","102.67200","8.55630","0.00500"
"17149","102.85800","8.57173","0.00506"
"17180","103.04400","8.58721","0.00491"
"17211","103.23000","8.60276","0.00511"
"17242","103.41600","8.61818","0.00455"
"17273","103.60200","8.63373","0.00426"
"17304","103.78800","8.64927","0.00456"
"17335","103.97400","8.66470","0.00461"
"17366","104.16000","8.68024","0.00491"
"17397","104.34600","8.69573","0.00471"
"17428","104.53200","8.71122","0.00459"
"17459","104.71800","8.72670","0.00497"
"17490","104.90400","8.74219","0.00458"
"17521","105.09000","8.75773","0.00449"
"17552","105.27600","8.77322","0.00503"
"17583","105.46200","8.78870","0.00452"
"17614","105.64800","8.80419","0.00422"
"17645","105.83400","8.81979","0.00451"
"17676","106.02000","8.83522","0.00454"
"17707","106.20600","8.85070","0.00434"
"17738","106.39200","8.86625","0.00511"
"17769","106.57800","8.88162","0.00443"
"17800","106.76400","8.89722","0.00454"
"17831","106.95000","8.91277","0.00503"
"17862","107.13600","8.92825","0.00430"
"17893","107.32200","8.94374","0.00450"
"17924","107.50800","8.95922","0.00450"
"17955","107.69400","8.97471","0.00480"
"17986","107.88000","8.99025","0.00479"
"18017","108.06600","9.00574","0.00442"
"18048","108.25200","9.02116","0.00477"
"18079","108.43800","9.03671","0.00475"
"18110","108.62400","9.05219","0.00467"
"18141","108.81000","9.06768","0.00448"
"18172","108.99600","9.08329","0.00402"
"18203","109.18200","9.09871","0.00446"
"18234","109.36800","9.11420","0.00477"
"18265","109.55400","9.12974","0.00480"
"18296","109.74000","9.14523","0.00443"
"18327","109.92600","9.16071","0.00442"
"18358","110.11200","9.17626","0.00463"
"18389","110.29800","9.19174","0.00510"
"18420","110.48400","9.20723","0.00513"
"18451","110.67000","9.22272","0.00513"
"18482","110.85600","9.23820","0.00472"
"18513","111.04200","9.25375","0.00413"
"18544","111.22800","9.26917","0.00460"
"18575","111.41400","9.28472","0.00455"
"18606","111.60000","9.30020","0.00432"
"18637","111.78600","9.31569","0.00476"
"18668","111.97200","9.33117","0.00461"
"18699","112.15800","9.34678","0.00528"
"18730","112.34400","9.36226","0.00471"
"18761","112.53000","9.37763","0.00446"
"18792","112.71600","9.39329","0.00544"
"18823","112.90200","9.40866","0.00473"
"18854","113.08800","9.42415","0.00464"
"18885","113.27400","9.43975","0.00479"
"18916","113.46000","9.45524","0.00493"
"18947","113.64600","9.47066","0.00489"
"18978","113.83200","9.48627","0.00457"
"19009","114.01800","9.50175","0.00496"
"19040","114.20400","9.51712","0.00511"
"19071","114.39000","9.53272","0.00537"
"19102","114.57600","9.54827","0.00491"
"19133","114.76200","9.56363","0.00507"
"19164","114.94800","9.57924","0.00462"
"19195","115.13400","9.59473","0.00469"
"19226","115.32000","9.61021","0.00455"
"19257","115.50600","9.62576","0.00517"
"19288","115.69200","9.64118","0.00493"
"19319","115.87800","9.65673","0.00466"
"19350","116.06400","9.67221","0.00469"
"19381","116.25000","9.68764","0.00486"
"19412","116.43600","9.70324","0.00503"
"19443","116.62200","9.71879","0.00556"
"19474","116.80800","9.73421","0.00471"
"19505","116.99400","9.74970","0.00495"
"19536","117.18000","9.76525","0.00471"
"19567","117.36600","9.78067","0.00519"
"19598","117.55200","9.79622","0.00495"
"19629","117.73800","9.81176","0.00517"
"19660","117.92400","9.82719","0.00553"
"19691","118.11000","9.84273","0.00476"
"19722","118.29600","9.85828","0.00473"
"19753","118.48200","9.87370","0.00605"
"19784","118.66800","9.88925","0.00538"
"19815","118.85400","9.90473","0.00528"
"19846","119.04000","9.92022","0.00540"
"19877","119.22600","9.93570","0.00559"
"19908","119.41200","9.95119","0.00583"
"19939","119.59800","9.96674","0.00592"
"19970","119.78400","9.98222","0.00567"
"20001","119.97000","9.99765","0.00553"
"20032","120.15600","10.01325","0.00560"
"20063","120.34200","10.02874","0.00530"
"20094","120.52800","10.04416","0.00510"
"20125","120.71400","10.05971","0.00559"
"20156","120.90000","10.07519","0.00509"
"20187","121.08600","10.09068","0.00504"
"20218","121.27200","10.10623","0.00546"
"20249","121.45800","10.12171","0.00527"
"20280","121.64400","10.13720","0.00524"
"20311","121.83000","10.15274","0.00517"
"20342","122.01600","10.16823","0.00539"
"20373","122.20200","10.18365","0.00513"
"20404","122.38800","10.19926","0.00568"
"20435","122.57400","10.21474","0.00542"
"20466","122.76000","10.23017","0.00541"
"20497","122.94600","10.24577","0.00558"
"20528","123.13200","10.26120","0.00548"
"20559","123.31800","10.27668","0.00559"
"20590","123.50400","10.29223","0.00512"
"20621","123.69000","10.30772","0.00547"
"20652","123.87600","10.32314","0.00563"
"20683","124.06200","10.33875","0.00507"
"20714","124.24800","10.35417","0.00606"
"20745","124.43400","10.36966","0.00637"
"20776","124.62000","10.38526","0.00516"
"20807","124.80600","10.40075","0.00493"
"20838","124.99200","10.41623","0.00518"
"20869","125.17800","10.43172","0.00555"
"20900","125.36400","10.44726","0.00520"
"20931","125.55000","10.46269","0.00541"
"20962","125.73600","10.47824","0.00541"
"20993","125.92200","10.49372","0.00508"
"21024","126.10800","10.50921","0.00549"
"21055","126.29400","10.52475","0.00509"
"21086","126.48000","10.54024","0.00510"
"21117","126.66600","10.55572","0.00532"
"21148","126.85200","10.57121","0.00543"
"21179","127.03800","10.58669","0.00559"
"21210","127.22400","10.60224","0.00507"
"21241","127.41000","10.61772","0.00577"
"21272","127.59600","10.63315","0.00571"
"21303","127.78200","10.64876","0.00568"
"21334","127.96800","10.66418","0.00601"
"21365","128.15401","10.67967","0.00564"
"21396","128.34000","10.69527","0.00587"
"21427","128.52600","10.71070","0.00600"
"21458","128.71201","10.72618","0.00582"
"21489","128.89799","10.74173","0.00579"
"21520","129.08400","10.75721","0.00566"
"21551","129.27000","10.77270","0.00550"
"21582","129.45599","10.78818","0.00555"
"21613","129.64200","10.80373","0.00556"
"21644","129.82800","10.81922","0.00551"
"21675","130.01401","10.83470","0.00613"
"21706","130.20000","10.85019","0.00593"
"21737","130.38600","10.86573","0.00603"
"21768","130.57201","10.88122","0.00529"
"21799","130.75800","10.89664","0.00562"
"21830","130.94400","10.91225","0.00551"
"21861","131.13000","10.92773","0.00607"
"21892","131.31599","10.94316","0.00605"
"21923","131.50200","10.95870","0.00552"
"21954","131.68800","10.97425","0.00573"
"21985","131.87399","10.98968","0.00572"
"22016","132.06000","11.00522","0.00608"
"22047","132.24600","11.02076","0.00570"
"22078","132.43201","11.03619","0.00615"
"22109","132.61800","11.05174","0.00597"
"22140","132.80400","11.06728","0.00610"
"22171","132.99001","11.08271","0.00593"
"22202","133.17599","11.09825","0.00588"
"22233","133.36200","11.11374","0.00640"
"22264","133.54800","11.12922","0.00585"
"22295","133.73399","11.14471","0.00551"
"22326","133.92000","11.16025","0.00638"
"22357","134.10600","11.17574","0.00616"
"22388","134.29201","11.19116","0.00598"
"22419","134.47800","11.20671","0.00617"
"22450","134.66400","11.22220","0.00632"
"22481","134.85001","11.23774","0.00589"
"22512","135.03600","11.25323","0.00595"
"22543","135.22200","11.26871","0.00601"
"22574","135.40800","11.28426","0.00614"
"22605","135.59399","11.29962","0.00605"
"22636","135.78000","11.31517","0.00609"
"22667","135.96600","11.33077","0.00582"
"22698","136.15199","11.34620","0.00636"
"22729","136.33800","11.36174","0.00645"
"22760","136.52400","11.37717","0.00632"
"22791","136.71001","11.39266","0.00608"
"22822","136.89600","11.40820","0.00648"
"22853","137.08200","11.42369","0.00609"
"22884","137.26801","11.43923","0.00583"
"22915","137.45399","11.45472","0.00604"
"22946","137.64000","11.47026","0.00591"
"22977","137.82600","11.48569","0.00603"
"23008","138.01199","11.50123","0.00630"
"23039","138.19800","11.51672","0.00657"
"23070","138.38400","11.53214","0.00589"
"23101","138.57001","11.54775","0.00636"
"23132","138.75600","11.56318","0.00677"
"23163","138.94200","11.57866","0.00671"
"23194","139.12801","11.59433","0.00625"
"23225","139.31400","11.60969","0.00600"
"23256","139.50000","11.62518","0.00613"
"23287","139.68600","11.64078","0.00645"
"23318","139.87199","11.65621","0.00599"
"23349","140.05800","11.67163","0.00621"
"23380","140.24400","11.68724","0.00638"
"23411","140.42999","11.70273","0.00629"
"23442","140.61600","11.71821","0.00663"
"23473","140.80200","11.73376","0.00620"
"23504","140.98801","11.74918","0.00649"
"23535","141.17400","11.76467","0.00619"
"23566","141.36000","11.78027","0.00616"
"23597","141.54601","11.79570","0.00627"
"23628","141.73199","11.81118","0.00621"
"23659","141.91800","11.82673","0.00586"
"23690","142.10400","11.84221","0.00617"
"23721","142.28999","11.85770","0.00582"
"23752","142.47600","11.87325","0.00607"
"23783","142.66200","11.88867","0.00603"
"23814","142.84801","11.90422","0.00632"
"23845","143.03400","11.91976","0.00639"
"23876","143.22000","11.93513","0.00628"
"23907","143.40601","11.95079","0.00618"
"23938","143.59200","11.96628","0.00634"
"23969","143.77800","11.98164","0.00648"
"24000","143.96400","11.99725","0.00604"
"24031","144.14999","12.01273","0.00697"
"24062","144.33600","12.02822","0.00653"
"24093","144.52200","12.04370","0.00657"
"24124","144.70799","12.05925","0.00632"
"24155","144.89400","12.07468","0.00631"
"24186","145.08000","12.09016","0.00639"
"24217","145.26601","12.10571","0.00661"
"24248","145.45200","12.12119","0.00590"
"24279","145.63800","12.13674","0.00654"
"24310","145.82401","12.15222","0.00595"
"24341","146.00999","12.16771","0.00594"
"24372","146.19600","12.18319","0.00641"
"24403","146.38200","12.19868","0.00618"
"24434","146.56799","12.21428","0.00646"
"24465","146.75400","12.22977","0.00631"
"24496","146.94000","12.24520","0.00595"
"24527","147.12601","12.26074","0.00679"
"24558","147.31200","12.27629","0.00638"
"24589","147.49800","12.29165","0.00673"
"24620","147.68401","12.30726","0.00648"
"24651","147.87000","12.32274","0.00627"
"24682","148.05600","12.33817","0.00595"
"24713","148.24200","12.35377","0.00639"
"24744","148.42799","12.36926","0.00664"
"24775","148.61400","12.38463","0.00596"
"24806","148.80000","12.40023","0.00668"
"24837","148.98599","12.41571","0.00613"
"24868","149.17200","12.43120","0.00660"
"24899","149.35800","12.44674","0.00565"
"24930","149.54401","12.46217","0.00648"
"24961","149.73000","12.47766","0.00598"
"24992","149.91600","12.49320","0.00580"
"25023","150.10201","12.50869","0.00650"
"25054","150.28799","12.52423","0.00570"
"25085","150.47400","12.53978","0.00660"
"25116","150.66000","12.55520","0.00610"
"25147","150.84599","12.57069","0.00644"
"25178","151.03200","12.58629","0.00675"
"25209","151.21800","12.60166","0.00628"
"25240","151.40401","12.61721","0.00650"
"25271","151.59000","12.63275","0.00639"
"25302","151.77600","12.64818","0.00651"
"25333","151.96201","12.66372","0.00663"
"25364","152.14799","12.67921","0.00650"
"25395","152.33400","12.69469","0.00650"
"25426","152.52000","12.71024","0.00647"
"25457","152.70599","12.72572","0.00659"
"25488","152.89200","12.74121","0.00679"
"25519","153.07800","12.75675","0.00605"
"25550","153.26401","12.77224","0.00606"
"25581","153.45000","12.78767","0.00633"
"25612","153.63600","12.80327","0.00607"
"25643","153.82201","12.81870","0.00559"
"25674","154.00800","12.83418","0.00573"
"25705","154.19400","12.84979","0.00535"
"25736","154.38000","12.86515","0.00595"
"25767","154.56599","12.88064","0.00561"
"25798","154.75200","12.89624","0.00508"
"25829","154.93800","12.91167","0.00559"
"25860","155.12399","12.92715","0.00476"
"25891","155.31000","12.94276","0.00555"
"25922","155.49600","12.95819","0.00515"
"25953","155.68201","12.97373","0.00481"
"25984","155.86800","12.98922","0.00551"
"26015","156.05400","13.00470","0.00545"
"26046","156.24001","13.02025","0.00517"
"26077","156.42599","13.03573","0.00575"
"26108","156.61200","13.05122","0.00508"
"26139","156.79800","13.06670","0.00497"
"26170","156.98399","13.08225","0.00591"
"26201","157.17000","13.09767","0.00581"
"26232","157.35600","13.11322","0.00541"
"26263","157.54201","13.12877","0.00562"
"26294","157.72800","13.14419","0.00522"
"26325","157.91400","13.15980","0.00542"
"26356","158.10001","13.17522","0.00545"
"26387","158.28600","13.19065","0.00539"
"26418","158.47200","13.20625","0.00550"
"26449","158.65800","13.22174","0.00563"
"26480","158.84399","13.23716","0.00566"
"26511","159.03000","13.25277","0.00538"
"26542","159.21600","13.26825","0.00587"
"26573","159.40199","13.28368","0.00544"
"26604","159.58800","13.29923","0.00594"
"26635","159.77400","13.31477","0.00571"
"26666","159.96001","13.33020","0.00594"
"26697","160.14600","13.34568","0.00575"
"26728","160.33200","13.36117","0.00546"
"26759","160.51801","13.37671","0.00593"
"26790","160.70399","13.39226","0.00581"
"26821","160.89000","13.40768","0.00568"
"26852","161.07600","13.42317","0.00576"
"26883","161.26199","13.43871","0.00555"
"26914","161.44800","13.45420","0.00576"
"26945","161.63400","13.46975","0.00607"
"26976","161.82001","13.48529","0.00591"
"27007","162.00600","13.50072","0.00587"
"27038","162.19200","13.51626","0.00523"
"27069","162.37801","13.53169","0.00619"
"27100","162.56400","13.54717","0.00561"
"27131","162.75000","13.56272","0.00566"
"27162","162.93600","13.57826","0.00603"
"27193","163.12199","13.59369","0.00608"
"27224","163.30800","13.60923","0.00574"
"27255","163.49400","13.62472","0.00602"
"27286","163.67999","13.64021","0.00558"
"27317","163.86600","13.65575","0.00641"
"27348","164.05200","13.67124","0.00627"
"27379","164.23801","13.68672","0.00561"
"27410","164.42400","13.70221","0.00583"
"27441","164.61000","13.71769","0.00614"
"27472","164.79601","13.73318","0.00562"
"27503","164.98199","13.74872","0.00558"
"27534","165.16800","13.76421","0.00629"
"27565","165.35400","13.77969","0.00599"
"27596","165.53999","13.79524","0.00598"
"27627","165.72600","13.81067","0.00569"
"27658","165.91200","13.82621","0.00641"
"27689","166.09801","13.84175","0.00655"
"27720","166.28400","13.85718","0.00633"
"27751","166.47000","13.87273","0.00597"
"27782","166.65601","13.88821","0.00594"
"27813","166.84200","13.90364","0.00624"
"27844","167.02800","13.91918","0.00594"
"27875","167.21400","13.93473","0.00620"
"27906","167.39999","13.95015","0.00601"
"27937","167.58600","13.96576","0.00603"
"27968","167.77200","13.98124","0.00590"
"27999","167.95799","13.99673","0.00619"
"28030","168.14400","14.01227","0.00629"
"28061","168.33000","14.02770","0.00606"
"28092","168.51601","14.04319","0.00695"
"28123","168.70200","14.05873","0.00639"
"28154","168.88800","14.07428","0.00576"
"28185","169.07401","14.08964","0.00646"
"28216","169.25999","14.10531","0.00570"
"28247","169.44600","14.12073","0.00597"
"28278","169.63200","14.13616","0.00667"
"28309","169.81799","14.15176","0.00582"
"28340","170.00400","14.16725","0.00614"
"28371","170.19000","14.18267","0.00627"
"28402","170.37601","14.19822","0.00639"
"28433","170.56200","14.21371","0.00612"
"28464","170.74800","14.22919","0.00605"
"28495","170.93401","14.24468","0.00607"
"28526","171.12000","14.26022","0.00668"
"28557","171.30600","14.27571","0.00653"
"28588","171.49200","14.29119","0.00643"
"28619","171.67799","14.30674","0.00648"
"28650","171.86400","14.32222","0.00623"
"28681","172.05000","14.33777","0.00613"
"28712","172.23599","14.35314","0.00649"
"28743","172.42200","14.36874","0.00617"
"28774","172.60800","14.38429","0.00628"
"28805","172.79401","14.39965","0.00639"
"28836","172.98000","14.41526","0.00633"
"28867","173.16600","14.43068","0.00662"
"28898","173.35201","14.44611","0.00651"
"28929","173.53799","14.46177","0.00629"
"28960","173.72400","14.47726","0.00587"
"28991","173.91000","14.49268","0.00631"
"29022","174.09599","14.50823","0.00633"
"29053","174.28200","14.52372","0.00662"
"29084","174.46800","14.53920","0.00644"
"29115","174.65401","14.55475","0.00666"
"29146","174.84000","14.57023","0.00626"
"29177","175.02600","14.58572","0.00650"
"29208","175.21201","14.60120","0.00676"
"29239","175.39799","14.61669","0.00633"
"29270","175.58400","14.63223","0.00642"
"29301","175.77000","14.64772","0.00651"
"29332","175.95599","14.66320","0.00632"
"29363","176.14200","14.67875","0.00658"
"29394","176.32800","14.69423","0.00637"
"29425","176.51401","14.70972","0.00722"
"29456","176.70000","14.72521","0.00630"
"29487","176.88600","14.74075","0.00706"
"29518","177.07201","14.75618","0.00637"
"29549","177.25800","14.77178","0.00667"
"29580","177.44400","14.78727","0.00632"
"29611","177.63000","14.80269","0.00675"
"29642","177.81599","14.81824","0.00618"
"29673","178.00200","14.83372","0.00688"
"29704","178.18800","14.84915","0.00660"
"29735","178.37399","14.86475","0.00693"
"29766","178.56000","14.88018","0.00662"
"29797","178.74600","14.89567","0.00645"
"29828","178.93201","14.91127","0.00689"
"29859","179.11800","14.92670","0.00680"
"29890","179.30400","14.94224","0.00731"
"29921","179.49001","14.95773","0.00627"
"29952","179.67599","14.97315","0.00630"
"29983","179.86200","14.98870","0.00728"
"30014","180.04800","15.00418","0.00711"
"30045","180.23399","15.01967","0.00636"
"30076","180.42000","15.03521","0.00737"
"30107","180.60600","15.05070","0.00694"
"30138","180.79201","15.06619","0.00650"
"30169","180.97800","15.08173","0.00693"
"30200","181.16400","15.09728","0.00646"
"30231","181.35001","15.11270","0.00703"
"30262","181.53600","15.12825","0.00695"
"30293","181.72200","15.14373","0.00626"
"30324","181.90800","15.15922","0.00644"
"30355","182.09399","15.17476","0.00676"
"30386","182.28000","15.19025","0.00646"
"30417","182.46600","15.20573","0.00690"
"30448","182.65199","15.22122","0.00723"
"30479","182.83800","15.23671","0.00717"
"30510","183.02400","15.25219","0.00694"
"30541","183.21001","15.26779","0.00693"
"30572","183.39600","15.28322","0.00717"
"30603","183.58200","15.29871","0.00733"
"30634","183.76801","15.31425","0.00724"
"30665","183.95399","15.32974","0.00687"
"30696","184.14000","15.34516","0.00663"
"30727","184.32600","15.36077","0.00693"
"30758","184.51199","15.37619","0.00736"
"30789","184.69800","15.39162","0.00704"
"30820","184.88400","15.40728","0.00688"
"30851","185.07001","15.42271","0.00749"
"30882","185.25600","15.43820","0.00711"
"30913","185.44200","15.45374","0.00690"
"30944","185.62801","15.46923","0.00696"
"30975","185.81400","15.48471","0.00717"
"31006","186.00000","15.50020","0.00752"
"31037","186.18600","15.51568","0.00756"
"31068","186.37199","15.53123","0.00749"
"31099","186.55800","15.54671","0.00740"
"31130","186.74400","15.56226","0.00718"
"31161","186.92999","15.57774","0.00745"
"31192","187.11600","15.59323","0.00724"
"31223","187.30200","15.60872","0.00738"
"31254","187.48801","15.62426","0.00769"
"31285","187.67400","15.63975","0.00767"
"31316","187.86000","15.65517","0.00746"
"31347","188.04601","15.67072","0.00792"
"31378","188.23199","15.68620","0.00845"
"31409","188.41800","15.70163","0.00748"
"31440","188.60400","15.71723","0.00781"
"31471","188.78999","15.73272","0.00712"
"31502","188.97600","15.74820","0.00760"
"31533","189.16200","15.76369","0.00723"
"31564","189.34801","15.77923","0.00811"
"31595","189.53400","15.79466","0.00760"
"31626","189.72000","15.81021","0.00748"
"31657","189.90601","15.82575","0.00756"
"31688","190.09200","15.84118","0.00697"
"31719","190.27800","15.85672","0.00755"
"31750","190.46400","15.87221","0.00759"
"31781","190.64999","15.88775","0.00741"
"31812","190.83600","15.90324","0.00741"
"31843","191.02200","15.91872","0.00738"
"31874","191.20799","15.93427","0.00795"
"31905","191.39400","15.94969","0.00765"
"31936","191.58000","15.96518","0.00828"
"31967","191.76601","15.98079","0.00770"
"31998","191.95200","15.99627","0.00766"
"32029","192.13800","16.01170","0.00761"
"32060","192.32401","16.02718","0.00804"
"32091","192.50999","16.04273","0.00823"
"32122","192.69600","16.05815","0.00784"
"32153","192.88200","16.07370","0.00760"
"32184","193.06799","16.08924","0.00764"
"32215","193.25400","16.10467","0.00790"
"32246","193.44000","16.12021","0.00783"
"32277","193.62601","16.13576","0.00758"
"32308","193.81200","16.15119","0.00791"
"32339","193.99800","16.16673","0.00782"
"32370","194.18401","16.18222","0.00817"
"32401","194.37000","16.19770","0.00737"
"32432","194.55600","16.21319","0.00809"
"32463","194.74200","16.22867","0.00797"
"32494","194.92799","16.24422","0.00818"
"32525","195.11400","16.25970","0.00776"
"32556","195.30000","16.27519","0.00828"
"32587","195.48599","16.29067","0.00745"
"32618","195.67200","16.30628","0.00773"
"32649","195.85800","16.32170","0.00847"
"32680","196.04401","16.33719","0.00825"
"32711","196.23000","16.35279","0.00803"
"32742","196.41600","16.36816","0.00786"
"32773","196.60201","16.38371","0.00852"
"32804","196.78799","16.39925","0.00795"
"32835","196.97400","16.41468","0.00857"
"32866","197.16000","16.43028","0.00823"
"32897","197.34599","16.44571","0.00806"
"32928","197.53200","16.46119","0.00843"
"32959","197.71800","16.47668","0.00809"
"32990","197.90401","16.49223","0.00852"
"33021","198.09000","16.50771","0.00838"
"33052","198.27600","16.52325","0.00784"
"33083","198.46201","16.53874","0.00907"
"33114","198.64799","16.55417","0.00835"
"33145","198.83400","16.56977","0.00842"
"33176","199.02000","16.58520","0.00881"
"33207","199.20599","16.60062","0.00816"
"33238","199.39200","16.61629","0.00822"
"33269","199.57800","16.63177","0.00848"
"33300","199.76401","16.64714","0.00868"
"33331","199.95000","16.66280","0.00845"
"33362","200.13600","16.67823","0.00869"
"33393","200.32201","16.69366","0.00895"
"33424","200.50800","16.70926","0.00828"
"33455","200.69400","16.72469","0.00904"
"33486","200.88000","16.74017","0.00863"
"33517","201.06599","16.75572","0.00911"
"33548","201.25200","16.77120","0.00847"
"33579","201.43800","16.78669","0.00875"
"33610","201.62399","16.80223","0.00880"
"33641","201.81000","16.81772","0.00843"
"33672","201.99600","16.83320","0.00883"
"33703","202.18201","16.84875","0.00878"
"33734","202.36800","16.86423","0.00867"
"33765","202.55400","16.87972","0.00829"
"33796","202.74001","16.89527","0.00884"
"33827","202.92599","16.91069","0.00904"
"33858","203.11200","16.92624","0.00854"
"33889","203.29800","16.94178","0.00883"
"33920","203.48399","16.95715","0.00889"
"33951","203.67000","16.97275","0.00854"
"33982","203.85600","16.98824","0.00847"
"34013","204.04201","17.00360","0.00879"
"34044","204.22800","17.01927","0.00868"
"34075","204.41400","17.03476","0.00856"
"34106","204.60001","17.05024","0.00902"
"34137","204.78600","17.06579","0.00866"
"34168","204.97200","17.08121","0.00932"
"34199","205.15800","17.09670","0.00866"
"34230","205.34399","17.11224","0.00917"
"34261","205.53000","17.12773","0.00891"
"34292","205.71600","17.14321","0.00882"
"34323","205.90199","17.15870","0.00898"
"34354","206.08800","17.17418","0.00862"
"34385","206.27400","17.18973","0.00916"
"34416","206.46001","17.20522","0.00973"
"34447","206.64600","17.22070","0.00910"
"34478","206.83200","17.23625","0.00928"
"34509","207.01801","17.25173","0.00907"
"34540","207.20399","17.26716","0.00910"
"34571","207.39000","17.28270","0.00903"
"34602","207.57600","17.29825","0.00834"
"34633","207.76199","17.31361","0.00847"
"34664","207.94800","17.32922","0.00855"
"34695","208.13400","17.34476","0.00907"
"34726","208.32001","17.36013","0.00945"
"34757","208.50600","17.37574","0.00912"
"34788","208.69200","17.39122","0.00903"
"34819","208.87801","17.40665","0.00912"
"34850","209.06400","17.42225","0.00932"
"34881","209.25000","17.43774","0.00914"
"34912","209.43600","17.45322","0.00919"
"34943","209.62199","17.46877","0.00857"
"34974","209.80800","17.48419","0.00898"
"35005","209.99400","17.49974","0.00865"
"35036","210.17999","17.51522","0.00870"
"35067","210.36600","17.53071","0.00911"
"35098","210.55200","17.54620","0.00900"
"35129","210.73801","17.56174","0.00889"
"35160","210.92400","17.57722","0.00891"
"35191","211.11000","17.59271","0.00863"
"35222","211.29601","17.60826","0.00924"
"35253","211.48199","17.62368","0.00901"
"35284","211.66800","17.63917","0.00860"
"35315","211.85400","17.65477","0.00895"
"35346","212.03999","17.67020","0.00922"
"35377","212.22600","17.68568","0.00963"
"35408","212.41200","17.70123","0.00897"
"35439","212.59801","17.71671","0.00910"
"35470","212.78400","17.73220","0.00900"
"35501","212.97000","17.74768","0.00943"
"35532","213.15601","17.76323","0.00909"
"35563","213.34200","17.77872","0.00947"
"35594","213.52800","17.79420","0.00917"
"35625","213.71400","17.80963","0.00942"
"35656","213.89999","17.82523","0.00950"
"35687","214.08600","17.84072","0.00926"
"35718","214.27200","17.85614","0.00912"
"35749","214.45799","17.87175","0.00984"
"35780","214.64400","17.88717","0.00935"
"35811","214.83000","17.90266","0.00978"
"35842","215.01601","17.91826","0.00927"
"35873","215.20200","17.93369","0.00988"
"35904","215.38800","17.94918","0.00979"
"35935","215.57401","17.96472","0.00972"
"35966","215.75999","17.98021","0.00950"
"35997","215.94600","17.99569","0.01014"
"36028","216.13200","18.01124","0.00971"
"36059","216.31799","18.02672","0.00948"
"36090","216.50400","18.04221","0.01030"
"36121","216.69000","18.05775","0.00977"
"36152","216.87601","18.07318","0.00929"
"36183","217.06200","18.08872","0.01004"
"36214","217.24800","18.10427","0.01005"
"36245","217.43401","18.11970","0.01000"
"36276","217.62000","18.13524","0.00968"
"36307","217.80600","18.15079","0.01000"
"36338","217.99200","18.16621","0.00982"
"36369","218.17799","18.18170","0.00981"
"36400","218.36400","18.19724","0.01022"
"36431","218.55000","18.21261","0.01061"
"36462","218.73599","18.22827","0.00987"
"36493","218.92200","18.24376","0.01013"
"36524","219.10800","18.25912","0.01056"
"36555","219.29401","18.27473","0.01006"
"36586","219.48000","18.29028","0.00992"
"36617","219.66600","18.30570","0.01045"
"36648","219.85201","18.32119","0.00974"
"36679","220.03799","18.33673","0.01012"
"36710","220.22400","18.35222","0.01069"
"36741","220.41000","18.36770","0.01099"
"36772","220.59599","18.38319","0.01068"
"36803","220.78200","18.39873","0.00983"
"36834","220.96800","18.41422","0.01061"
"36865","221.15401","18.42971","0.01022"
"36896","221.34000","18.44519","0.01073"
"36927","221.52600","18.46074","0.01080"
"36958","221.71201","18.47622","0.01089"
"36989","221.89799","18.49171","0.01015"
"37020","222.08400","18.50725","0.01118"
"37051","222.27000","18.52274","0.01062"
"37082","222.45599","18.53822","0.01076"
"37113","222.64200","18.55371","0.01016"
"37144","222.82800","18.56919","0.01130"
"37175","223.01401","18.58468","0.01085"
"37206","223.20000","18.60023","0.01092"
"37237","223.38600","18.61571","0.01103"
"37268","223.57201","18.63120","0.01158"
"37299","223.75800","18.64674","0.01109"
"37330","223.94400","18.66217","0.01128"
"37361","224.13000","18.67771","0.01164"
"37392","224.31599","18.69320","0.01109"
"37423","224.50200","18.70868","0.01146"
"37454","224.68800","18.72423","0.01181"
"37485","224.87399","18.73965","0.01113"
"37516","225.06000","18.75520","0.01124"
"37547","225.24600","18.77074","0.01112"
"37578","225.43201","18.78623","0.01120"
"37609","225.61800","18.80172","0.01116"
"37640","225.80400","18.81726","0.00949"
"37671","225.99001","18.83275","0.00924"
"37702","226.17599","18.84817","0.00823"
"37733","226.36200","18.86378","0.00777"
"37764","226.54800","18.87920","0.00835"
"37795","226.73399","18.89469","0.00790"
"37826","226.92000","18.91023","0.00916"
"37857","227.10600","18.92572","0.00828"
"37888","227.29201","18.94120","0.00896"
"37919","227.47800","18.95675","0.00879"
"37950","227.66400","18.97218","0.00888"
"37981","227.85001","18.98772","0.00830"
"38012","228.03600","19.00327","0.00891"
"38043","228.22200","19.01869","0.00848"
"38074","228.40800","19.03424","0.00909"
"38105","228.59399","19.04972","0.00839"
"38136","228.78000","19.06521","0.00845"
"38167","228.96600","19.08075","0.00879"
"38198","229.15199","19.09624","0.00873"
"38229","229.33800","19.11167","0.00932"
"38260","229.52400","19.12721","0.00906"
"38291","229.71001","19.14269","0.00872"
"38322","229.89600","19.15818","0.00921"
"38353","230.08200","19.17379","0.00915"
"38384","230.26801","19.18921","0.00862"
"38415","230.45399","19.20470","0.00938"
"38446","230.64000","19.22024","0.00976"
"38477","230.82600","19.23573","0.00942"
"38508","231.01199","19.25115","0.00923"
"38539","231.19800","19.26670","0.00950"
"38550","231.25999","19.27190","0.00935"