File: Trajectories_together/170122_2Specimen_RawData_6.csv
"","V1","V2","V3"
"1","End date","1/22/2017",""
"2","Specimen label","3CT_94",""
"3","Maximum Load","1.27545","N"
"4","Time","Extension","Load"
"5","(s)","(mm)","(N)"
"6","0.00000","37.82035","0.06402"
"47","0.24600","37.83900","0.06419"
"88","0.49200","37.86160","0.06453"
"129","0.73800","37.88199","0.06480"
"170","0.98400","37.90256","0.06522"
"211","1.23000","37.92294","0.06517"
"252","1.47600","37.94358","0.06551"
"293","1.72200","37.96396","0.06591"
"334","1.96800","37.98453","0.06608"
"375","2.21400","38.00510","0.06660"
"416","2.46000","38.02549","0.06688"
"457","2.70600","38.04605","0.06697"
"498","2.95200","38.06650","0.06700"
"539","3.19800","38.08701","0.06724"
"580","3.44400","38.10746","0.06794"
"621","3.69000","38.12803","0.06809"
"662","3.93600","38.14848","0.06831"
"703","4.18200","38.16904","0.06859"
"744","4.42800","38.18943","0.06916"
"785","4.67400","38.21000","0.06967"
"826","4.92000","38.23050","0.07021"
"867","5.16600","38.25095","0.07077"
"908","5.41200","38.27152","0.07146"
"949","5.65800","38.29197","0.07125"
"990","5.90400","38.31248","0.07216"
"1031","6.15000","38.33292","0.07285"
"1072","6.39600","38.35349","0.07328"
"1113","6.64200","38.37394","0.07367"
"1154","6.88800","38.39451","0.07432"
"1195","7.13400","38.41502","0.07531"
"1236","7.38000","38.43552","0.07588"
"1277","7.62600","38.45603","0.07694"
"1318","7.87200","38.47654","0.07683"
"1359","8.11800","38.49699","0.07798"
"1400","8.36400","38.51756","0.07915"
"1441","8.61000","38.53800","0.07959"
"1482","8.85600","38.55845","0.07996"
"1523","9.10200","38.57902","0.08057"
"1564","9.34800","38.59946","0.08182"
"1605","9.59400","38.62003","0.08270"
"1646","9.84000","38.64048","0.08306"
"1687","10.08600","38.66105","0.08438"
"1728","10.33200","38.68150","0.08521"
"1769","10.57800","38.70200","0.08562"
"1810","10.82400","38.72251","0.08645"
"1851","11.07000","38.74296","0.08710"
"1892","11.31600","38.76353","0.08796"
"1933","11.56200","38.78392","0.08907"
"1974","11.80800","38.80454","0.08997"
"2015","12.05400","38.82499","0.09060"
"2056","12.30000","38.84550","0.09086"
"2097","12.54600","38.86595","0.09178"
"2138","12.79200","38.88651","0.09263"
"2179","13.03800","38.90702","0.09326"
"2220","13.28400","38.92753","0.09338"
"2261","13.53000","38.94804","0.09486"
"2302","13.77600","38.96848","0.09488"
"2343","14.02200","38.98905","0.09582"
"2384","14.26800","39.00950","0.09658"
"2425","14.51400","39.03001","0.09701"
"2466","14.76000","39.05040","0.09796"
"2507","15.00600","39.07102","0.09883"
"2548","15.25200","39.09153","0.09945"
"2589","15.49800","39.11204","0.09984"
"2630","15.74400","39.13249","0.10146"
"2671","15.99000","39.15300","0.10205"
"2712","16.23600","39.17351","0.10261"
"2753","16.48200","39.19401","0.10395"
"2794","16.72800","39.21446","0.10454"
"2835","16.97400","39.23497","0.10582"
"2876","17.22000","39.25547","0.10610"
"2917","17.46600","39.27592","0.10751"
"2958","17.71200","39.29649","0.10847"
"2999","17.95800","39.31694","0.10929"
"3040","18.20400","39.33751","0.11026"
"3081","18.45000","39.35796","0.11149"
"3122","18.69600","39.37852","0.11262"
"3163","18.94200","39.39897","0.11337"
"3204","19.18800","39.41948","0.11408"
"3245","19.43400","39.44004","0.11380"
"3286","19.68000","39.46049","0.11495"
"3327","19.92600","39.48106","0.11543"
"3368","20.17200","39.50145","0.11557"
"3409","20.41800","39.52208","0.11573"
"3450","20.66400","39.54247","0.11588"
"3491","20.91000","39.56297","0.11619"
"3532","21.15600","39.58348","0.11650"
"3573","21.40200","39.60405","0.11672"
"3614","21.64800","39.62450","0.11677"
"3655","21.89400","39.64500","0.11717"
"3696","22.14000","39.66551","0.11744"
"3737","22.38600","39.68596","0.11774"
"3778","22.63200","39.70653","0.11794"
"3819","22.87800","39.72704","0.11880"
"3860","23.12400","39.74754","0.11894"
"3901","23.37000","39.76793","0.11932"
"3942","23.61600","39.78850","0.12023"
"3983","23.86200","39.80901","0.12105"
"4024","24.10800","39.82951","0.12223"
"4065","24.35400","39.84996","0.12312"
"4106","24.60000","39.87053","0.12458"
"4147","24.84600","39.89104","0.12582"
"4188","25.09200","39.91149","0.12847"
"4229","25.33800","39.93199","0.12966"
"4270","25.58400","39.95250","0.13067"
"4311","25.83000","39.97301","0.13236"
"4352","26.07600","39.99345","0.13465"
"4393","26.32200","40.01402","0.13575"
"4434","26.56800","40.03447","0.13691"
"4475","26.81400","40.05498","0.13835"
"4516","27.06000","40.07549","0.13924"
"4557","27.30600","40.09605","0.14092"
"4598","27.55200","40.11644","0.14187"
"4639","27.79800","40.13701","0.14288"
"4680","28.04400","40.15752","0.14409"
"4721","28.29000","40.17802","0.14581"
"4762","28.53600","40.19853","0.14660"
"4803","28.78200","40.21892","0.14783"
"4844","29.02800","40.23955","0.14837"
"4885","29.27400","40.25994","0.14912"
"4926","29.52000","40.28051","0.14975"
"4967","29.76600","40.30095","0.15081"
"5008","30.01200","40.32152","0.15132"
"5049","30.25800","40.34197","0.15217"
"5090","30.50400","40.36254","0.15266"
"5131","30.75000","40.38305","0.15333"
"5172","30.99600","40.40350","0.15372"
"5213","31.24200","40.42406","0.15512"
"5254","31.48800","40.44451","0.15563"
"5295","31.73400","40.46502","0.15685"
"5336","31.98000","40.48541","0.15742"
"5377","32.22600","40.50597","0.15795"
"5418","32.47200","40.52648","0.15921"
"5459","32.71800","40.54699","0.15988"
"5500","32.96400","40.56750","0.16103"
"5541","33.21000","40.58801","0.16180"
"5582","33.45600","40.60851","0.16290"
"5623","33.70200","40.62902","0.16336"
"5664","33.94800","40.64947","0.16431"
"5705","34.19400","40.66998","0.16462"
"5746","34.44000","40.69049","0.16558"
"5787","34.68600","40.71099","0.16636"
"5828","34.93200","40.73150","0.16711"
"5869","35.17800","40.75195","0.16824"
"5910","35.42400","40.77252","0.16898"
"5951","35.67000","40.79296","0.17038"
"5992","35.91600","40.81359","0.17169"
"6033","36.16200","40.83398","0.17297"
"6074","36.40800","40.85448","0.17455"
"6115","36.65400","40.87505","0.17610"
"6156","36.90000","40.89550","0.17929"
"6197","37.14600","40.91601","0.18112"
"6238","37.39200","40.93640","0.17820"
"6279","37.63800","40.95708","0.18281"
"6320","37.88400","40.97747","0.18458"
"6361","38.13000","40.99798","0.18516"
"6402","38.37600","41.01843","0.19067"
"6443","38.62200","41.03899","0.19206"
"6484","38.86800","41.05950","0.19669"
"6525","39.11400","41.08001","0.20054"
"6566","39.36000","41.10052","0.20198"
"6607","39.60600","41.12097","0.20771"
"6648","39.85200","41.14153","0.20876"
"6689","40.09800","41.16198","0.21145"
"6730","40.34400","41.18249","0.21379"
"6771","40.59000","41.20294","0.21532"
"6812","40.83600","41.22351","0.21731"
"6853","41.08200","41.24401","0.21802"
"6894","41.32800","41.26452","0.21898"
"6935","41.57400","41.28497","0.22035"
"6976","41.82000","41.30548","0.22050"
"7017","42.06600","41.32605","0.22159"
"7058","42.31200","41.34649","0.22120"
"7099","42.55800","41.36700","0.22250"
"7140","42.80400","41.38745","0.22332"
"7181","43.05000","41.40802","0.22451"
"7222","43.29600","41.42853","0.22631"
"7263","43.54200","41.44904","0.22798"
"7304","43.78800","41.46942","0.23079"
"7345","44.03400","41.48999","0.23441"
"7386","44.28000","41.51044","0.23550"
"7427","44.52600","41.53107","0.23873"
"7468","44.77200","41.55146","0.24146"
"7509","45.01800","41.57202","0.24356"
"7550","45.26400","41.59253","0.24562"
"7591","45.51000","41.61298","0.24519"
"7632","45.75600","41.63354","0.24865"
"7673","46.00200","41.65393","0.25044"
"7714","46.24800","41.67456","0.25258"
"7755","46.49400","41.69495","0.25472"
"7796","46.74000","41.71558","0.25642"
"7837","46.98600","41.73596","0.25851"
"7878","47.23200","41.75647","0.26024"
"7919","47.47800","41.77698","0.26176"
"7960","47.72400","41.79755","0.26279"
"8001","47.97000","41.81799","0.26361"
"8042","48.21600","41.83844","0.26445"
"8083","48.46200","41.85901","0.26516"
"8124","48.70800","41.87946","0.26560"
"8165","48.95400","41.90002","0.26626"
"8206","49.20000","41.92042","0.26676"
"8247","49.44600","41.94104","0.26739"
"8288","49.69200","41.96149","0.26766"
"8329","49.93800","41.98199","0.26848"
"8370","50.18400","42.00250","0.26906"
"8411","50.43000","42.02301","0.26993"
"8452","50.67600","42.04352","0.27091"
"8493","50.92200","42.06397","0.27185"
"8534","51.16800","42.08448","0.27345"
"8575","51.41400","42.10504","0.27376"
"8616","51.66000","42.12549","0.27537"
"8657","51.90600","42.14594","0.27742"
"8698","52.15200","42.16651","0.27872"
"8739","52.39800","42.18696","0.28112"
"8780","52.64400","42.20747","0.28408"
"8821","52.89000","42.22797","0.28616"
"8862","53.13600","42.24854","0.28906"
"8903","53.38200","42.26899","0.29165"
"8944","53.62800","42.28950","0.29243"
"8985","53.87400","42.31006","0.29608"
"9026","54.12000","42.33051","0.29800"
"9067","54.36600","42.35102","0.30015"
"9108","54.61200","42.37141","0.30263"
"9149","54.85800","42.39203","0.30537"
"9190","55.10400","42.41248","0.30808"
"9231","55.35000","42.43299","0.31051"
"9272","55.59600","42.45344","0.31184"
"9313","55.84200","42.47401","0.31287"
"9354","56.08800","42.49445","0.31420"
"9395","56.33400","42.51508","0.31516"
"9436","56.58000","42.53553","0.31593"
"9477","56.82600","42.55597","0.31772"
"9518","57.07200","42.57655","0.31995"
"9559","57.31800","42.59699","0.32261"
"9600","57.56400","42.61750","0.32627"
"9641","57.81000","42.63789","0.33133"
"9682","58.05600","42.65852","0.33643"
"9723","58.30200","42.67903","0.34150"
"9764","58.54800","42.69954","0.34552"
"9805","58.79400","42.71998","0.34928"
"9846","59.04000","42.74049","0.35375"
"9887","59.28600","42.76100","0.35738"
"9928","59.53200","42.78150","0.36061"
"9969","59.77800","42.80195","0.36340"
"10010","60.02400","42.82246","0.36633"
"10051","60.27000","42.84303","0.36832"
"10092","60.51600","42.86347","0.37029"
"10133","60.76200","42.88404","0.37159"
"10174","61.00800","42.90443","0.37247"
"10215","61.25400","42.92500","0.37345"
"10256","61.50000","42.94545","0.37421"
"10297","61.74600","42.96608","0.37504"
"10338","61.99200","42.98647","0.37548"
"10379","62.23800","43.00703","0.37597"
"10420","62.48400","43.02753","0.37693"
"10461","62.73000","43.04799","0.37750"
"10502","62.97600","43.06849","0.37897"
"10543","63.22200","43.08894","0.38004"
"10584","63.46800","43.10951","0.38164"
"10625","63.71400","43.12996","0.38293"
"10666","63.96000","43.15052","0.38381"
"10707","64.20600","43.17091","0.38640"
"10748","64.45200","43.19154","0.38724"
"10789","64.69800","43.21199","0.38931"
"10830","64.94400","43.23250","0.39111"
"10871","65.19000","43.25306","0.39366"
"10912","65.43600","43.27345","0.39605"
"10953","65.68200","43.29402","0.39940"
"10994","65.92800","43.31447","0.40335"
"11035","66.17400","43.33504","0.40888"
"11076","66.42000","43.35542","0.41173"
"11117","66.66600","43.37605","0.41549"
"11158","66.91200","43.39656","0.41868"
"11199","67.15800","43.41701","0.41997"
"11240","67.40400","43.43752","0.42138"
"11281","67.65000","43.45796","0.42288"
"11322","67.89600","43.47853","0.42441"
"11363","68.14200","43.49898","0.42619"
"11404","68.38800","43.51948","0.42831"
"11445","68.63400","43.53999","0.43129"
"11486","68.88000","43.56050","0.43394"
"11527","69.12600","43.58094","0.43752"
"11568","69.37200","43.60151","0.44050"
"11609","69.61800","43.62196","0.44358"
"11650","69.86400","43.64247","0.44585"
"11691","70.11000","43.66298","0.44878"
"11732","70.35600","43.68354","0.45152"
"11773","70.60200","43.70394","0.45432"
"11814","70.84800","43.72450","0.45584"
"11855","71.09400","43.74501","0.45811"
"11896","71.34000","43.76546","0.45957"
"11937","71.58600","43.78609","0.46104"
"11978","71.83200","43.80642","0.46208"
"12019","72.07800","43.82704","0.46338"
"12060","72.32400","43.84743","0.46417"
"12101","72.57000","43.86800","0.46574"
"12142","72.81600","43.88845","0.46719"
"12183","73.06200","43.90901","0.46945"
"12224","73.30800","43.92947","0.47177"
"12265","73.55400","43.95003","0.47427"
"12306","73.80000","43.97054","0.47675"
"12347","74.04600","43.99099","0.47933"
"12388","74.29200","44.01155","0.48216"
"12429","74.53800","44.03201","0.48513"
"12470","74.78400","44.05251","0.48827"
"12511","75.03000","44.07296","0.49115"
"12552","75.27600","44.09347","0.49488"
"12593","75.52200","44.11398","0.49904"
"12634","75.76800","44.13454","0.50250"
"12675","76.01400","44.15499","0.50568"
"12716","76.26000","44.17550","0.50805"
"12757","76.50600","44.19601","0.51063"
"12798","76.75200","44.21645","0.51313"
"12839","76.99800","44.23702","0.51655"
"12880","77.24400","44.25753","0.51905"
"12921","77.49000","44.27804","0.52109"
"12962","77.73600","44.29848","0.52265"
"13003","77.98200","44.31905","0.52348"
"13044","78.22800","44.33950","0.52428"
"13085","78.47400","44.36001","0.52541"
"13126","78.72000","44.38052","0.52720"
"13167","78.96600","44.40102","0.53058"
"13208","79.21200","44.42153","0.53486"
"13249","79.45800","44.44204","0.54011"
"13290","79.70400","44.46255","0.54465"
"13331","79.95000","44.48299","0.54948"
"13372","80.19600","44.50350","0.55290"
"13413","80.44200","44.52395","0.55690"
"13454","80.68800","44.54458","0.56026"
"13495","80.93400","44.56496","0.56395"
"13536","81.18000","44.58553","0.56737"
"13577","81.42600","44.60592","0.56985"
"13618","81.67200","44.62655","0.57275"
"13659","81.91800","44.64694","0.57477"
"13700","82.16400","44.66745","0.57734"
"13741","82.41000","44.68801","0.57976"
"13782","82.65600","44.70846","0.58142"
"13823","82.90200","44.72902","0.58286"
"13864","83.14800","44.74948","0.58494"
"13905","83.39400","44.76999","0.58601"
"13946","83.64000","44.79043","0.58691"
"13987","83.88600","44.81100","0.58831"
"14028","84.13200","44.83151","0.58973"
"14069","84.37800","44.85202","0.59105"
"14110","84.62400","44.87246","0.59325"
"14151","84.87000","44.89303","0.59624"
"14192","85.11600","44.91348","0.59973"
"14233","85.36200","44.93399","0.60368"
"14274","85.60800","44.95450","0.60839"
"14315","85.85400","44.97501","0.61361"
"14356","86.10000","44.99551","0.61954"
"14397","86.34600","45.01596","0.62295"
"14438","86.59200","45.03653","0.62587"
"14479","86.83800","45.05698","0.62807"
"14520","87.08400","45.07748","0.63025"
"14561","87.33000","45.09793","0.63325"
"14602","87.57600","45.11861","0.63662"
"14643","87.82200","45.13895","0.64076"
"14684","88.06800","45.15952","0.64736"
"14725","88.31400","45.18002","0.65307"
"14766","88.56000","45.20053","0.65863"
"14807","88.80600","45.22104","0.66237"
"14848","89.05200","45.24142","0.66576"
"14889","89.29800","45.26205","0.66851"
"14930","89.54400","45.28244","0.67101"
"14971","89.79000","45.30301","0.67244"
"15012","90.03600","45.32345","0.67370"
"15053","90.28200","45.34402","0.67448"
"15094","90.52800","45.36447","0.67509"
"15135","90.77400","45.38498","0.67610"
"15176","91.02000","45.40555","0.67679"
"15217","91.26600","45.42593","0.67850"
"15258","91.51200","45.44650","0.68004"
"15299","91.75800","45.46695","0.68175"
"15340","92.00400","45.48751","0.68348"
"15381","92.25000","45.50797","0.68531"
"15422","92.49600","45.52847","0.68805"
"15463","92.74200","45.54898","0.69206"
"15504","92.98800","45.56955","0.69635"
"15545","93.23400","45.59000","0.70119"
"15586","93.48000","45.61056","0.70565"
"15627","93.72600","45.63101","0.70998"
"15668","93.97200","45.65152","0.71452"
"15709","94.21800","45.67197","0.71878"
"15750","94.46400","45.69248","0.72377"
"15791","94.71000","45.71299","0.72845"
"15832","94.95600","45.73343","0.73141"
"15873","95.20200","45.75400","0.73415"
"15914","95.44800","45.77445","0.73505"
"15955","95.69400","45.79502","0.73580"
"15996","95.94000","45.81546","0.73713"
"16037","96.18600","45.83603","0.73999"
"16078","96.43200","45.85648","0.74437"
"16119","96.67800","45.87699","0.74920"
"16160","96.92400","45.89756","0.75454"
"16201","97.17000","45.91800","0.75908"
"16242","97.41600","45.93851","0.76403"
"16283","97.66200","45.95896","0.76858"
"16324","97.90800","45.97958","0.77287"
"16365","98.15400","45.99997","0.77609"
"16406","98.40000","46.02048","0.77864"
"16447","98.64600","46.04093","0.78187"
"16488","98.89200","46.06150","0.78443"
"16529","99.13800","46.08194","0.78650"
"16570","99.38400","46.10258","0.78817"
"16611","99.63000","46.12302","0.78925"
"16652","99.87600","46.14347","0.79036"
"16693","100.12200","46.16404","0.79222"
"16734","100.36800","46.18449","0.79369"
"16775","100.61400","46.20499","0.79687"
"16816","100.86000","46.22544","0.79936"
"16857","101.10600","46.24601","0.80362"
"16898","101.35200","46.26652","0.80667"
"16939","101.59800","46.28703","0.81072"
"16980","101.84400","46.30748","0.81500"
"17021","102.09000","46.32798","0.81957"
"17062","102.33600","46.34849","0.82420"
"17103","102.58200","46.36900","0.82609"
"17144","102.82800","46.38944","0.82821"
"17185","103.07400","46.41001","0.83046"
"17226","103.32000","46.43052","0.83432"
"17267","103.56600","46.45097","0.83983"
"17308","103.81200","46.47147","0.84505"
"17349","104.05800","46.49192","0.72598"
"17390","104.30400","46.51249","0.73205"
"17431","104.55000","46.53294","0.73328"
"17472","104.79600","46.55357","0.73258"
"17513","105.04200","46.57396","0.73340"
"17554","105.28800","46.59452","0.73517"
"17595","105.53400","46.61503","0.73651"
"17636","105.78000","46.63554","0.73735"
"17677","106.02600","46.65599","0.73898"
"17718","106.27200","46.67643","0.74105"
"17759","106.51800","46.69706","0.74811"
"17800","106.76400","46.71745","0.75418"
"17841","107.01000","46.73802","0.75981"
"17882","107.25600","46.75846","0.76396"
"17923","107.50200","46.77903","0.77003"
"17964","107.74800","46.79948","0.77644"
"18005","107.99400","46.82005","0.77927"
"18046","108.24000","46.84056","0.78253"
"18087","108.48600","46.86100","0.78456"
"18128","108.73200","46.88151","0.78707"
"18169","108.97800","46.90202","0.78831"
"18210","109.22400","46.92253","0.78929"
"18251","109.47000","46.94291","0.79061"
"18292","109.71600","46.96354","0.79233"
"18333","109.96200","46.98399","0.79413"
"18374","110.20800","47.00450","0.79627"
"18415","110.45400","47.02494","0.79871"
"18456","110.70000","47.04557","0.80241"
"18497","110.94600","47.06602","0.80544"
"18538","111.19200","47.08653","0.80869"
"18579","111.43800","47.10698","0.81251"
"18620","111.68400","47.12749","0.81614"
"18661","111.93000","47.14799","0.82113"
"18702","112.17600","47.16844","0.82355"
"18743","112.42200","47.18900","0.82562"
"18784","112.66800","47.20945","0.82844"
"18825","112.91400","47.23003","0.83188"
"18866","113.16000","47.25047","0.83714"
"18907","113.40600","47.27104","0.84204"
"18948","113.65200","47.29149","0.84875"
"18989","113.89800","47.31200","0.85505"
"19030","114.14400","47.33257","0.86091"
"19071","114.39000","47.35302","0.86719"
"19112","114.63600","47.37352","0.87152"
"19153","114.88200","47.39391","0.87686"
"19194","115.12800","47.41454","0.88084"
"19235","115.37400","47.43498","0.88419"
"19276","115.62000","47.45549","0.88589"
"19317","115.86600","47.47600","0.88727"
"19358","116.11200","47.49651","0.88786"
"19399","116.35800","47.51695","0.88818"
"19440","116.60400","47.53746","0.88930"
"19481","116.85000","47.55803","0.89087"
"19522","117.09600","47.57848","0.89328"
"19563","117.34200","47.59904","0.89494"
"19604","117.58800","47.61955","0.89691"
"19645","117.83400","47.64006","0.89988"
"19686","118.08000","47.66045","0.90280"
"19727","118.32600","47.68096","0.90732"
"19768","118.57200","47.70152","0.91127"
"19809","118.81800","47.72203","0.91572"
"19850","119.06400","47.74248","0.91963"
"19891","119.31000","47.76299","0.92291"
"19932","119.55600","47.78350","0.92735"
"19973","119.80200","47.80395","0.93174"
"20014","120.04800","47.82451","0.80370"
"20055","120.29400","47.84502","0.80076"
"20096","120.54000","47.86547","0.79907"
"20137","120.78600","47.88597","0.79872"
"20178","121.03200","47.90648","0.80044"
"20219","121.27800","47.92693","0.80187"
"20260","121.52400","47.94750","0.80219"
"20301","121.77000","47.96801","0.80329"
"20342","122.01600","47.98857","0.80436"
"20383","122.26200","48.00896","0.80636"
"20424","122.50800","48.02953","0.80903"
"20465","122.75400","48.05004","0.81245"
"20506","123.00000","48.07048","0.81705"
"20547","123.24600","48.09100","0.82077"
"20588","123.49200","48.11138","0.82350"
"20629","123.73800","48.13207","0.77826"
"20670","123.98400","48.15245","0.78078"
"20711","124.23000","48.17303","0.78450"
"20752","124.47600","48.19347","0.78803"
"20793","124.72200","48.21404","0.79035"
"20834","124.96800","48.23449","0.79151"
"20875","125.21400","48.25499","0.79316"
"20916","125.46000","48.27556","0.79613"
"20957","125.70600","48.29595","0.80119"
"20998","125.95200","48.31646","0.80515"
"21039","126.19800","48.33696","0.80788"
"21080","126.44400","48.35753","0.81008"
"21121","126.69000","48.37792","0.81394"
"21162","126.93600","48.39849","0.81947"
"21203","127.18200","48.41900","0.82352"
"21244","127.42800","48.43951","0.82557"
"21285","127.67400","48.45995","0.82733"
"21326","127.92000","48.48052","0.83065"
"21367","128.16600","48.50103","0.83609"
"21408","128.41200","48.52154","0.84138"
"21449","128.65800","48.54198","0.84763"
"21490","128.90400","48.56255","0.85439"
"21531","129.15000","48.58300","0.86077"
"21572","129.39600","48.60345","0.86566"
"21613","129.64200","48.62402","0.74316"
"21654","129.88800","48.64447","0.74300"
"21695","130.13400","48.66497","0.74556"
"21736","130.38000","48.68548","0.75045"
"21777","130.62600","48.70611","0.75728"
"21818","130.87200","48.72644","0.76525"
"21859","131.11800","48.74701","0.77232"
"21900","131.36400","48.76757","0.77602"
"21941","131.61000","48.78802","0.77885"
"21982","131.85600","48.80853","0.78065"
"22023","132.10200","48.82898","0.78213"
"22064","132.34800","48.84954","0.78409"
"22105","132.59400","48.87000","0.78603"
"22146","132.84000","48.89050","0.78730"
"22187","133.08600","48.91101","0.78859"
"22228","133.33200","48.93152","0.78983"
"22269","133.57800","48.95196","0.79217"
"22310","133.82400","48.97253","0.79495"
"22351","134.07000","48.99304","0.79873"
"22392","134.31600","49.01349","0.80192"
"22433","134.56200","49.03399","0.80663"
"22474","134.80800","49.05450","0.81019"
"22515","135.05400","49.07501","0.81510"
"22556","135.30000","49.09539","0.81906"
"22597","135.54600","49.11602","0.82200"
"22638","135.79200","49.13647","0.82458"
"22679","136.03800","49.15698","0.82697"
"22720","136.28400","49.17749","0.82908"
"22761","136.53000","49.19799","0.83155"
"22802","136.77600","49.21857","0.83636"
"22843","137.02200","49.23895","0.84231"
"22884","137.26800","49.25946","0.84725"
"22925","137.51400","49.28003","0.85444"
"22966","137.76000","49.30053","0.86126"
"23007","138.00600","49.32093","0.86677"
"23048","138.25200","49.34155","0.87244"
"23089","138.49800","49.36200","0.87679"
"23130","138.74400","49.38250","0.88145"
"23171","138.99000","49.40295","0.88492"
"23212","139.23600","49.42352","0.88648"
"23253","139.48200","49.44397","0.88746"
"23294","139.72800","49.46453","0.88808"
"23335","139.97400","49.48499","0.88840"
"23376","140.22000","49.50549","0.88913"
"23417","140.46600","49.52600","0.89062"
"23458","140.71200","49.54645","0.89212"
"23499","140.95800","49.56702","0.89434"
"23540","141.20400","49.58747","0.89651"
"23581","141.45000","49.60798","0.89844"
"23622","141.69600","49.62849","0.90111"
"23663","141.94200","49.64905","0.90340"
"23704","142.18800","49.66944","0.90698"
"23745","142.43400","49.69001","0.91057"
"23786","142.68000","49.71051","0.91444"
"23827","142.92600","49.73102","0.91759"
"23868","143.17200","49.75153","0.92137"
"23909","143.41800","49.77198","0.92627"
"23950","143.66400","49.79255","0.92984"
"23991","143.91000","49.81287","0.93374"
"24032","144.15600","49.83356","0.93661"
"24073","144.40200","49.85401","0.93838"
"24114","144.64800","49.87452","0.93990"
"24155","144.89400","49.89497","0.94202"
"24196","145.14000","49.91547","0.94453"
"24237","145.38600","49.93604","0.94819"
"24278","145.63200","49.95649","0.95365"
"24319","145.87800","49.97700","0.95815"
"24360","146.12400","49.99750","0.96213"
"24401","146.37000","50.01801","0.96514"
"24442","146.61600","50.03846","0.96837"
"24483","146.86200","50.05903","0.97137"
"24524","147.10800","50.07947","0.97360"
"24565","147.35400","50.10004","0.97535"
"24606","147.60000","50.12049","0.97681"
"24647","147.84600","50.14106","0.97894"
"24688","148.09200","50.16150","0.98157"
"24729","148.33800","50.18201","0.98372"
"24770","148.58400","50.20252","0.98641"
"24811","148.83000","50.22297","0.98920"
"24852","149.07600","50.24353","0.99156"
"24893","149.32200","50.26398","0.99417"
"24934","149.56800","50.28455","0.99632"
"24975","149.81400","50.30494","0.99894"
"25016","150.06000","50.32550","1.00245"
"25057","150.30600","50.34596","1.00609"
"25098","150.55200","50.36652","1.01095"
"25139","150.79800","50.38697","1.01458"
"25180","151.04400","50.40748","1.01853"
"25221","151.29000","50.42799","1.02349"
"25262","151.53600","50.44850","1.02794"
"25303","151.78200","50.46900","1.03317"
"25344","152.02800","50.48951","1.03727"
"25385","152.27400","50.51002","1.04051"
"25426","152.52000","50.53040","1.04270"
"25467","152.76600","50.55098","1.04625"
"25508","153.01200","50.57148","1.05055"
"25549","153.25800","50.59205","1.05665"
"25590","153.50400","50.61250","1.06167"
"25631","153.75000","50.63306","1.06616"
"25672","153.99600","50.65351","1.07023"
"25713","154.24200","50.67396","1.07381"
"25754","154.48800","50.69447","1.07673"
"25795","154.73400","50.71504","1.07983"
"25836","154.98000","50.73555","1.08279"
"25877","155.22600","50.75593","1.08434"
"25918","155.47200","50.77650","1.08606"
"25959","155.71800","50.79695","1.08730"
"26000","155.96400","50.81746","1.08865"
"26041","156.21000","50.83796","1.08992"
"26082","156.45600","50.85854","1.09049"
"26123","156.70200","50.87898","1.09175"
"26164","156.94800","50.89955","1.09304"
"26205","157.19400","50.92006","1.09527"
"26246","157.44000","50.94051","1.09850"
"26287","157.68600","50.96101","1.10120"
"26328","157.93200","50.98146","1.10421"
"26369","158.17800","51.00209","1.10839"
"26410","158.42400","51.02247","1.11222"
"26451","158.67000","51.04298","1.11593"
"26492","158.91600","51.06343","1.11999"
"26533","159.16200","51.08400","1.12690"
"26574","159.40800","51.10445","1.13330"
"26615","159.65400","51.12501","1.14091"
"26656","159.90000","51.14552","1.14560"
"26697","160.14600","51.16597","1.14862"
"26738","160.39200","51.18653","1.15220"
"26779","160.63800","51.20699","1.15519"
"26820","160.88400","51.22755","0.98484"
"26861","161.13000","51.24794","0.98224"
"26902","161.37600","51.26845","0.98199"
"26943","161.62200","51.28901","0.98204"
"26984","161.86800","51.30947","0.98366"
"27025","162.11400","51.32998","0.98719"
"27066","162.36000","51.35048","0.99008"
"27107","162.60600","51.37099","0.99206"
"27148","162.85200","51.39150","0.99510"
"27189","163.09800","51.41201","0.99850"
"27230","163.34400","51.43251","1.00274"
"27271","163.59000","51.45302","1.00811"
"27312","163.83600","51.47347","1.01284"
"27353","164.08200","51.49398","1.01770"
"27394","164.32800","51.51442","1.02295"
"27435","164.57400","51.53505","1.02904"
"27476","164.82000","51.55550","1.03383"
"27517","165.06600","51.57607","1.03706"
"27558","165.31200","51.59645","1.04048"
"27599","165.55800","51.61696","1.04334"
"27640","165.80400","51.63753","1.04604"
"27681","166.05000","51.65804","1.04951"
"27722","166.29600","51.67849","1.05335"
"27763","166.54200","51.69893","1.05922"
"27804","166.78800","51.71956","1.06297"
"27845","167.03400","51.73994","1.06726"
"27886","167.28000","51.76052","1.07098"
"27927","167.52600","51.78096","1.07451"
"27968","167.77200","51.80147","1.07836"
"28009","168.01800","51.82198","1.08177"
"28050","168.26400","51.84248","1.08435"
"28091","168.51000","51.86299","1.08619"
"28132","168.75600","51.88350","1.08774"
"28173","169.00200","51.90401","1.08885"
"28214","169.24800","51.92452","1.08986"
"28255","169.49400","51.94503","1.09088"
"28296","169.74000","51.96542","1.09194"
"28337","169.98600","51.98598","1.09333"
"28378","170.23200","52.00649","1.09514"
"28419","170.47800","52.02700","1.09796"
"28460","170.72400","52.04745","1.10113"
"28501","170.97000","52.06801","1.10490"
"28542","171.21600","52.08852","1.10881"
"28583","171.46200","52.10897","1.11269"
"28624","171.70800","52.12948","1.11673"
"28665","171.95400","52.14999","1.12111"
"28706","172.20000","52.17049","1.12799"
"28747","172.44600","52.19100","1.13571"
"28788","172.69200","52.21151","1.14225"
"28829","172.93800","52.23196","1.14774"
"28870","173.18400","52.25253","1.15161"
"28911","173.43000","52.27298","1.15492"
"28952","173.67600","52.29360","1.16036"
"28993","173.92200","52.31399","1.16454"
"29034","174.16800","52.33450","1.17008"
"29075","174.41400","52.35506","1.17518"
"29116","174.66000","52.37551","1.18040"
"29157","174.90600","52.39602","1.18587"
"29198","175.15200","52.41640","1.18997"
"29239","175.39800","52.43709","1.19436"
"29280","175.64400","52.45749","0.97085"
"29321","175.89000","52.47805","0.97216"
"29362","176.13600","52.49844","0.97460"
"29403","176.38200","52.51901","0.97496"
"29444","176.62800","52.53945","0.97547"
"29485","176.87400","52.56002","0.97785"
"29526","177.12000","52.58053","0.97965"
"29567","177.36600","52.60098","0.98172"
"29608","177.61200","52.62155","0.98570"
"29649","177.85800","52.64199","0.98777"
"29690","178.10400","52.66250","0.98948"
"29731","178.35000","52.68289","0.99173"
"29772","178.59600","52.70351","0.99383"
"29813","178.84200","52.72403","0.99656"
"29854","179.08800","52.74453","1.00076"
"29895","179.33400","52.76498","1.00574"
"29936","179.58000","52.78548","1.00991"
"29977","179.82600","52.80606","1.01472"
"30018","180.07200","52.82650","1.01833"
"30059","180.31800","52.84701","1.02224"
"30100","180.56400","52.86752","1.02712"
"30141","180.81000","52.88802","1.03116"
"30182","181.05600","52.90847","1.03536"
"30223","181.30200","52.92904","1.03874"
"30264","181.54800","52.94949","1.04132"
"30305","181.79400","52.97000","1.04311"
"30346","182.04000","52.99045","1.04660"
"30387","182.28600","53.01107","1.04934"
"30428","182.53200","53.03146","1.05295"
"30469","182.77800","53.05203","1.05743"
"30510","183.02400","53.07254","1.06055"
"30551","183.27000","53.09299","1.06427"
"30592","183.51600","53.11355","1.06780"
"30633","183.76200","53.13395","1.07128"
"30674","184.00800","53.15457","1.07443"
"30715","184.25400","53.17496","1.07715"
"30756","184.50000","53.19547","1.07939"
"30797","184.74600","53.21592","1.08192"
"30838","184.99200","53.23654","1.08453"
"30879","185.23800","53.25699","1.08598"
"30920","185.48400","53.27756","1.08711"
"30961","185.73000","53.29807","1.08841"
"31002","185.97600","53.31845","1.08923"
"31043","186.22200","53.33902","1.08999"
"31084","186.46800","53.35947","1.09065"
"31125","186.71400","53.38004","1.09153"
"31166","186.96000","53.40043","1.09177"
"31207","187.20600","53.42105","1.09325"
"31248","187.45200","53.44150","1.09470"
"31289","187.69800","53.46201","1.09692"
"31330","187.94400","53.48252","1.09888"
"31371","188.19000","53.50303","1.10113"
"31412","188.43600","53.52353","1.10386"
"31453","188.68200","53.54398","1.10683"
"31494","188.92800","53.56449","1.11041"
"31535","189.17400","53.58493","1.11329"
"31576","189.42000","53.60550","1.11664"
"31617","189.66600","53.62595","1.12113"
"31658","189.91200","53.64652","1.12622"
"31699","190.15800","53.66697","1.13155"
"31740","190.40400","53.68747","1.13655"
"31781","190.65000","53.70792","1.14100"
"31822","190.89600","53.72861","1.14533"
"31863","191.14200","53.74894","1.14838"
"31904","191.38800","53.76950","1.15027"
"31945","191.63400","53.79001","1.15320"
"31986","191.88000","53.81052","1.15510"
"32027","192.12600","53.83102","1.15812"
"32068","192.37200","53.85147","1.16292"
"32109","192.61800","53.87204","1.16735"
"32150","192.86400","53.89249","1.17245"
"32191","193.11000","53.91300","1.17625"
"32232","193.35600","53.93351","1.18156"
"32273","193.60200","53.95401","1.18635"
"32314","193.84800","53.97446","1.19107"
"32355","194.09400","53.99497","1.19476"
"32396","194.34000","54.01554","1.19773"
"32437","194.58600","54.03599","1.19925"
"32478","194.83200","54.05655","1.20078"
"32519","195.07800","54.07700","1.20178"
"32560","195.32400","54.09751","1.20307"
"32601","195.57000","54.11790","1.20454"
"32642","195.81600","54.13847","1.20561"
"32683","196.06200","54.15897","1.20696"
"32724","196.30800","54.17954","1.20833"
"32765","196.55400","54.20005","1.21032"
"32806","196.80000","54.22056","1.21238"
"32847","197.04600","54.24101","1.21639"
"32888","197.29200","54.26152","1.22014"
"32929","197.53800","54.28202","1.22521"
"32970","197.78400","54.30253","1.23039"
"33011","198.03000","54.32298","1.23358"
"33052","198.27600","54.34343","1.23663"
"33093","198.52200","54.36406","1.00971"
"33134","198.76800","54.38450","0.98273"
"33175","199.01400","54.40501","0.98090"
"33216","199.26000","54.42546","0.98434"
"33257","199.50600","54.44609","0.98562"
"33298","199.75200","54.46647","0.98553"
"33339","199.99800","54.48698","0.98892"
"33380","200.24400","54.50749","0.99142"
"33421","200.49000","54.52800","0.99284"
"33462","200.73600","54.54850","0.99611"
"33503","200.98200","54.56895","0.99973"
"33544","201.22800","54.58958","1.00302"
"33585","201.47400","54.60997","1.00837"
"33626","201.72000","54.63047","1.01474"
"33667","201.96600","54.65098","1.01950"
"33708","202.21200","54.67149","1.02476"
"33749","202.45800","54.69194","1.03242"
"33790","202.70400","54.71251","1.03726"
"33831","202.95000","54.73301","1.04010"
"33872","203.19600","54.75346","1.04286"
"33913","203.44200","54.77403","1.04556"
"33954","203.68800","54.79448","1.04831"
"33995","203.93400","54.81498","1.05218"
"34036","204.18000","54.83549","1.05724"
"34077","204.42600","54.85600","1.06192"
"34118","204.67200","54.87645","1.06630"
"34159","204.91800","54.89701","1.06982"
"34200","205.16400","54.91747","1.07230"
"34241","205.41000","54.93803","1.07556"
"34282","205.65600","54.95854","1.07942"
"34323","205.90200","54.97899","1.08247"
"34364","206.14800","54.99950","1.08459"
"34405","206.39400","55.02000","1.08641"
"34446","206.64000","55.04051","1.08778"
"34487","206.88600","55.06096","1.08914"
"34528","207.13200","55.08153","1.08992"
"34569","207.37800","55.10197","1.09105"
"34610","207.62400","55.12248","1.09230"
"34651","207.87000","55.14299","1.09421"
"34692","208.11600","55.16356","1.09711"
"34733","208.36200","55.18401","1.10007"
"34774","208.60800","55.20451","1.10392"
"34815","208.85400","55.22502","1.10784"
"34856","209.10000","55.24553","1.11149"
"34897","209.34600","55.26604","1.11489"
"34938","209.59200","55.28648","1.11938"
"34979","209.83800","55.30705","1.12459"
"35020","210.08400","55.32744","1.12949"
"35061","210.33000","55.34801","1.13766"
"35102","210.57600","55.36839","1.14336"
"35143","210.82200","55.38903","1.14802"
"35184","211.06800","55.40948","1.15257"
"35225","211.31400","55.42998","1.15628"
"35266","211.56000","55.45055","1.16119"
"35307","211.80600","55.47100","1.16579"
"35348","212.05200","55.49157","1.17023"
"35389","212.29800","55.51201","1.17432"
"35430","212.54400","55.53252","1.17876"
"35471","212.79000","55.55291","1.18291"
"35512","213.03600","55.57347","1.18686"
"35553","213.28200","55.59398","1.19111"
"35594","213.52800","55.61449","1.19415"
"35635","213.77400","55.63500","1.19641"
"35676","214.02000","55.65551","1.19799"
"35717","214.26600","55.67601","1.19960"
"35758","214.51200","55.69646","1.20100"
"35799","214.75800","55.71697","1.20213"
"35840","215.00400","55.73754","1.20306"
"35881","215.25000","55.75798","1.20442"
"35922","215.49600","55.77843","1.20517"
"35963","215.74200","55.79900","1.20611"
"36004","215.98800","55.81945","1.20701"
"36045","216.23400","55.83996","1.00713"
"36086","216.48000","55.86047","0.99929"
"36127","216.72600","55.88109","0.99429"
"36168","216.97200","55.90148","0.99355"
"36209","217.21800","55.92205","0.99386"
"36250","217.46400","55.94250","0.99505"
"36291","217.71000","55.96301","0.99567"
"36332","217.95600","55.98351","0.99587"
"36373","218.20200","56.00390","0.99766"
"36414","218.44800","56.02453","0.99919"
"36455","218.69400","56.04498","1.00110"
"36496","218.94000","56.06548","1.00411"
"36537","219.18600","56.08599","1.00585"
"36578","219.43200","56.10656","1.00923"
"36619","219.67800","56.12701","1.01217"
"36660","219.92400","56.14751","1.01547"
"36701","220.17000","56.16802","1.01829"
"36742","220.41600","56.18847","1.02209"
"36783","220.66200","56.20904","1.02639"
"36824","220.90800","56.22949","1.03063"
"36865","221.15400","56.24999","1.03392"
"36906","221.40000","56.27044","1.03760"
"36947","221.64600","56.29101","1.03995"
"36988","221.89200","56.31145","1.04219"
"37029","222.13800","56.33202","1.04375"
"37070","222.38400","56.35247","1.04579"
"37111","222.63000","56.37304","1.04881"
"37152","222.87600","56.39355","1.05215"
"37193","223.12200","56.41399","1.05651"
"37234","223.36800","56.43450","1.06116"
"37275","223.61400","56.45495","1.06414"
"37316","223.86000","56.47546","1.06706"
"37357","224.10600","56.49596","1.06962"
"37398","224.35200","56.51654","1.07206"
"37439","224.59800","56.53698","1.07484"
"37480","224.84400","56.55755","1.07777"
"37521","225.09000","56.57800","1.08001"
"37562","225.33600","56.59851","1.08249"
"37603","225.58200","56.61895","1.08441"
"37644","225.82800","56.63946","1.08608"
"37685","226.07400","56.66003","1.08765"
"37726","226.32000","56.68054","1.08852"
"37767","226.56600","56.70098","1.08927"
"37808","226.81200","56.72144","1.09004"
"37849","227.05800","56.74206","1.09074"
"37890","227.30400","56.76245","1.09181"
"37931","227.55000","56.78302","1.09276"
"37972","227.79600","56.80347","1.09424"
"38013","228.04200","56.82403","1.09539"
"38054","228.28800","56.84443","1.09696"
"38095","228.53400","56.86505","1.09814"
"38136","228.78000","56.88550","1.10013"
"38177","229.02600","56.90601","1.10222"
"38218","229.27200","56.92651","1.10498"
"38259","229.51800","56.94702","1.10851"
"38300","229.76400","56.96753","1.11147"
"38341","230.01000","56.98792","1.11493"
"38382","230.25600","57.00854","1.11789"
"38423","230.50200","57.02900","1.12344"
"38464","230.74800","57.04956","1.12996"
"38505","230.99400","57.07001","1.13646"
"38546","231.24000","57.09052","1.14192"
"38587","231.48600","57.11102","1.14657"
"38628","231.73200","57.13147","1.14972"
"38669","231.97800","57.15198","1.15295"
"38710","232.22400","57.17249","1.15683"
"38751","232.47000","57.19300","1.16110"
"38792","232.71600","57.21350","1.16651"
"38833","232.96200","57.23401","1.17188"
"38874","233.20800","57.25446","1.17746"
"38915","233.45400","57.27496","1.18249"
"38956","233.70000","57.29541","1.18743"
"38997","233.94600","57.31610","1.19144"
"39038","234.19200","57.33643","1.19506"
"39079","234.43800","57.35699","1.19727"
"39120","234.68400","57.37756","1.19875"
"39161","234.93000","57.39801","1.20032"
"39202","235.17600","57.41852","1.20182"
"39243","235.42200","57.43891","1.20309"
"39284","235.66800","57.45953","1.20431"
"39325","235.91400","57.47998","1.20527"
"39366","236.16000","57.50049","1.20633"
"39407","236.40600","57.52094","1.20739"
"39448","236.65200","57.54150","1.20853"
"39489","236.89800","57.56195","1.21033"
"39530","237.14400","57.58246","1.21174"
"39571","237.39000","57.60303","1.21429"
"39612","237.63600","57.62348","1.21703"
"39653","237.88200","57.64404","1.22128"
"39694","238.12800","57.66449","1.22633"
"39735","238.37400","57.68506","1.23160"
"39776","238.62000","57.70539","1.23488"
"39817","238.86600","57.72602","1.23854"
"39858","239.11200","57.74652","1.24063"
"39899","239.35800","57.76703","1.24263"
"39940","239.60400","57.78749","1.24403"
"39981","239.85000","57.80805","1.24581"
"40022","240.09600","57.82850","1.24869"
"40063","240.34200","57.84901","1.25328"
"40104","240.58800","57.86951","1.25783"
"40145","240.83400","57.89002","1.26467"
"40186","241.08000","57.91053","1.26886"
"40227","241.32600","57.93098","1.27281"
"40268","241.57200","57.95149","1.20481"
"40309","241.81800","57.97200","1.08500"
"40350","242.06400","57.99250","0.80911"
"40391","242.31000","58.01295","0.65134"
"40432","242.55600","58.03358","0.65842"
"40473","242.80200","58.05396","0.65667"
"40514","243.04800","58.07447","0.66822"
"40555","243.29400","58.09504","0.68233"
"40596","243.54000","58.11549","0.67341"
"40637","243.78600","58.13606","0.66815"
"40678","244.03200","58.15644","0.67117"
"40719","244.27800","58.17701","0.67351"
"40760","244.52400","58.19746","0.68437"
"40801","244.77000","58.21796","0.68635"
"40842","245.01600","58.23847","0.67741"
"40883","245.26200","58.25898","0.67676"
"40924","245.50800","58.27949","0.67727"
"40965","245.75400","58.30000","0.68236"
"41006","246.00000","58.32050","0.69571"
"41047","246.24600","58.34101","0.69508"
"41088","246.49200","58.36152","0.68789"
"41129","246.73800","58.38203","0.68641"
"41170","246.98400","58.40253","0.68991"
"41211","247.23000","58.42293","0.69770"
"41252","247.47600","58.44349","0.71174"
"41293","247.72200","58.46400","0.71838"
"41334","247.96800","58.48450","0.71449"
"41375","248.21400","58.50501","0.71122"
"41416","248.46000","58.52552","0.71323"
"41457","248.70600","58.54603","0.72046"
"41498","248.95200","58.56648","0.73131"
"41539","249.19800","58.58699","0.73504"
"41580","249.44400","58.60750","0.73610"
"41621","249.69000","58.62800","0.73514"
"41662","249.93600","58.64845","0.73501"
"41703","250.18200","58.66902","0.73563"
"41744","250.42800","58.68947","0.73704"
"41785","250.67400","58.70998","0.74340"
"41826","250.92000","58.73048","0.75100"
"41867","251.16600","58.75105","0.75452"
"41908","251.41200","58.77144","0.75352"
"41949","251.65800","58.79201","0.75309"
"41990","251.90400","58.81252","0.75523"
"42031","252.15000","58.83302","0.76046"
"42072","252.39600","58.85353","0.76718"
"42113","252.64200","58.87391","0.77266"
"42154","252.88800","58.89460","0.77677"
"42195","253.13400","58.91500","0.77856"
"42236","253.38000","58.93556","0.77897"
"42277","253.62600","58.95595","0.77936"
"42318","253.87200","58.97652","0.78128"
"42359","254.11800","58.99697","0.78355"
"42400","254.36400","59.01747","0.78604"
"42441","254.61000","59.03804","0.78803"
"42482","254.85600","59.05849","0.78957"
"42523","255.10200","59.07900","0.79104"
"42564","255.34800","59.09950","0.79216"
"42605","255.59400","59.12008","0.79230"
"42646","255.84000","59.14046","0.79378"
"42687","256.08600","59.16096","0.79541"
"42728","256.33200","59.18153","0.79767"
"42769","256.57800","59.20205","0.50946"
"42810","256.82400","59.22249","0.36636"
"42851","257.07000","59.24300","0.33797"
"42892","257.31600","59.26350","0.33009"
"42933","257.56200","59.28401","0.29433"
"42974","257.80800","59.30452","0.27089"
"43015","258.05400","59.32503","0.29143"
"43056","258.30000","59.34548","0.27168"
"43097","258.54600","59.36593","0.28567"
"43138","258.79200","59.38649","0.27239"
"43179","259.03800","59.40700","0.28399"
"43220","259.28400","59.42745","0.27269"
"43261","259.53000","59.44796","0.27312"
"43302","259.77600","59.46858","0.28506"
"43343","260.02200","59.48898","0.27085"
"43384","260.26800","59.50948","0.29065"
"43425","260.51400","59.53004","0.27549"
"43466","260.76000","59.55050","0.29116"
"43507","261.00600","59.57106","0.27300"
"43548","261.25200","59.59145","0.28568"
"43589","261.49800","59.61202","0.28029"
"43630","261.74400","59.63247","0.27366"
"43671","261.99000","59.65304","0.29358"
"43712","262.23600","59.67348","0.27900"
"43753","262.48200","59.69405","0.29533"
"43794","262.72800","59.71444","0.02886"
"43835","262.97400","59.73501","0.07186"
"43876","263.22000","59.75557","0.04179"
"43917","263.46600","59.77596","0.06238"
"43958","263.71200","59.79653","0.05392"
"43999","263.95800","59.81698","0.05217"
"44040","264.20400","59.83748","0.06119"
"44081","264.45000","59.85793","0.06387"
"44122","264.69600","59.87850","0.05217"
"44163","264.94200","59.89894","0.06317"
"44204","265.18800","59.91945","0.05435"
"44245","265.43400","59.93996","0.06389"
"44286","265.68000","59.96053","0.05607"
"44327","265.92600","59.98104","0.06198"
"44368","266.17200","60.00148","0.06026"
"44409","266.41800","60.02199","0.05841"
"44450","266.66400","60.04251","0.06379"
"44491","266.91000","60.06301","0.05256"
"44532","267.15600","60.08346","0.06498"
"44573","267.40200","60.10403","0.05275"
"44614","267.64800","60.12448","0.06375"
"44655","267.89400","60.14498","0.05746"
"44696","268.14000","60.16549","0.06201"
"44737","268.38600","60.18606","0.06140"
"44778","268.63200","60.20650","0.05749"
"44819","268.87800","60.22701","0.06361"
"44860","269.12400","60.24752","0.05577"
"44901","269.37000","60.26803","0.06485"
"44942","269.61600","60.28848","0.05650"
"44983","269.86200","60.30893","0.06383"
"45024","270.10800","60.32955","0.05878"
"45065","270.35400","60.34995","0.06204"
"45106","270.60000","60.37045","0.06219"
"45147","270.84600","60.39096","0.05988"
"45188","271.09200","60.41153","0.06365"
"45229","271.33800","60.43198","0.05746"
"45270","271.58400","60.45254","0.06434"
"45311","271.83000","60.47305","0.05750"
"45352","272.07600","60.49350","0.06403"
"45393","272.32200","60.51401","0.06017"
"45434","272.56800","60.53445","0.06274"
"45475","272.81400","60.55502","0.06209"
"45516","273.06000","60.57541","0.06062"
"45557","273.30600","60.59604","0.06402"
"45598","273.55200","60.61655","0.05938"
"45639","273.79800","60.63705","0.06454"
"45680","274.04400","60.65750","0.05976"
"45721","274.29000","60.67801","0.06409"
"45762","274.53600","60.69852","0.06107"
"45803","274.78200","60.71896","0.06243"
"45844","275.02800","60.73947","0.06301"
"45885","275.27400","60.75998","0.06105"
"45926","275.52000","60.78049","0.06394"
"45967","275.76600","60.80093","0.06068"
"46008","276.01200","60.82150","0.06456"
"46049","276.25800","60.84195","0.06074"
"46090","276.50400","60.86252","0.06392"
"46131","276.75000","60.88297","0.06281"
"46172","276.99600","60.90353","0.06234"
"46213","277.24200","60.92398","0.06369"
"46254","277.48800","60.94448","0.06154"
"46295","277.73400","60.96505","0.06465"
"46336","277.98000","60.98550","0.06158"
"46377","278.22600","61.00601","0.06434"
"46418","278.47200","61.02646","0.06307"
"46459","278.71800","61.04702","0.06354"
"46500","278.96400","61.06747","0.06389"
"46541","279.21000","61.08798","0.06237"
"46582","279.45600","61.10843","0.06458"
"46623","279.70200","61.12906","0.06248"
"46664","279.94800","61.14945","0.06451"
"46705","280.19400","61.17002","0.06306"
"46746","280.44000","61.19053","0.06405"
"46787","280.68600","61.21097","0.06381"
"46828","280.93200","61.23154","0.06312"
"46869","281.17800","61.25199","0.06498"
"46910","281.42400","61.27255","0.06307"
"46951","281.67000","61.29295","0.06488"
"46992","281.91600","61.31351","0.06380"
"47033","282.16200","61.33402","0.06462"
"47074","282.40800","61.35453","0.06429"
"47115","282.65400","61.37498","0.06390"
"47156","282.90000","61.39554","0.06526"
"47197","283.14600","61.41599","0.06359"
"47238","283.39200","61.43650","0.06553"
"47279","283.63800","61.45695","0.06443"
"47320","283.88400","61.47752","0.06506"
"47361","284.13000","61.49802","0.06466"
"47402","284.37600","61.51847","0.06415"
"47443","284.62200","61.53904","0.06604"
"47484","284.86800","61.55949","0.06392"
"47525","285.11400","61.57999","0.06519"
"47566","285.36000","61.60044","0.06521"
"47607","285.60600","61.62107","0.06501"
"47648","285.85200","61.64146","0.06542"
"47689","286.09800","61.66203","0.06455"
"47730","286.34400","61.68253","0.06622"
"47771","286.59000","61.70298","0.06466"
"47812","286.83600","61.72348","0.06552"
"47853","287.08200","61.74393","0.06575"
"47894","287.32800","61.76456","0.06528"
"47935","287.57400","61.78495","0.06618"
"47976","287.82000","61.80546","0.06528"
"48017","288.06600","61.82597","0.06616"
"48058","288.31200","61.84653","0.06538"
"48099","288.55800","61.86692","0.06556"
"48140","288.80400","61.88749","0.06683"
"48181","289.05000","61.90806","0.06560"
"48222","289.29600","61.92850","0.06616"
"48263","289.54200","61.94901","0.06639"
"48304","289.78800","61.96946","0.06630"
"48345","290.03400","61.99002","0.06657"
"48386","290.28000","62.01042","0.06599"
"48427","290.52600","62.03098","0.06728"
"48468","290.77200","62.05149","0.06595"
"48509","291.01800","62.07200","0.06624"
"48550","291.26400","62.09251","0.06712"
"48591","291.51000","62.11301","0.06628"
"48632","291.75600","62.13352","0.06695"
"48673","292.00200","62.15397","0.06660"
"48714","292.24800","62.17448","0.06741"
"48755","292.49400","62.19505","0.06714"
"48796","292.74000","62.21550","0.06659"
"48837","292.98600","62.23594","0.06783"
"48878","293.23200","62.25645","0.06693"
"48919","293.47800","62.27696","0.06732"
"48960","293.72400","62.29753","0.06798"
"49001","293.97000","62.31797","0.06715"
"49042","294.21600","62.33854","0.06785"
"49083","294.46200","62.35899","0.06777"
"49124","294.70800","62.37950","0.06794"
"49165","294.95400","62.40001","0.06832"
"49206","295.20000","62.42052","0.06787"
"49247","295.44600","62.44102","0.06924"
"49288","295.69200","62.46141","0.06831"
"49329","295.93800","62.48204","0.06832"
"49370","296.18400","62.50248","0.06980"
"49411","296.43000","62.52299","0.06818"
"49452","296.67600","62.54344","0.06870"
"49493","296.92200","62.56401","0.06985"
"49534","297.16800","62.58451","0.06891"
"49575","297.41400","62.60502","0.06937"
"49616","297.66000","62.62547","0.06958"
"49657","297.90600","62.64598","0.07037"
"49698","298.15200","62.66648","0.06991"
"49739","298.39800","62.68700","0.06977"
"49776","298.61800","62.70535","0.07145"