File: Trajectories_together/170107_2Specimen_RawData_6.csv
"","V1","V2","V3"
"1","End date","1/7/2017",""
"2","Specimen label","3AG_19",""
"3","Maximum Load","0.51913","N"
"4","Time","Extension","Load"
"5","(s)","(mm)","(N)"
"6","0.00000","0.00000","-0.00025"
"45","0.23400","0.01782","0.00025"
"84","0.46800","0.03928","0.00124"
"123","0.70200","0.05871","0.00168"
"162","0.93600","0.07820","0.00236"
"201","1.17000","0.09770","0.00293"
"240","1.40400","0.11719","0.00355"
"279","1.63800","0.13668","0.00392"
"318","1.87200","0.15623","0.00437"
"357","2.10600","0.17566","0.00433"
"396","2.34000","0.19521","0.00511"
"435","2.57400","0.21470","0.00566"
"474","2.80800","0.23414","0.00580"
"513","3.04200","0.25369","0.00630"
"552","3.27600","0.27318","0.00665"
"591","3.51000","0.29267","0.00659"
"630","3.74400","0.31216","0.00706"
"669","3.97800","0.33171","0.00726"
"708","4.21200","0.35120","0.00753"
"747","4.44600","0.37070","0.00766"
"786","4.68000","0.39019","0.00860"
"825","4.91400","0.40962","0.00860"
"864","5.14800","0.42923","0.00883"
"903","5.38200","0.44866","0.00935"
"942","5.61600","0.46821","0.00971"
"981","5.85000","0.48764","0.00991"
"1020","6.08400","0.50719","0.00983"
"1059","6.31800","0.52675","0.00975"
"1098","6.55200","0.54612","0.01071"
"1137","6.78600","0.56573","0.01010"
"1176","7.02000","0.58516","0.01020"
"1215","7.25400","0.60465","0.01119"
"1254","7.48800","0.62414","0.01102"
"1293","7.72200","0.64375","0.01130"
"1332","7.95600","0.66319","0.01160"
"1371","8.19000","0.68268","0.01088"
"1410","8.42400","0.70217","0.01095"
"1449","8.65800","0.72160","0.01158"
"1488","8.89200","0.74121","0.01160"
"1527","9.12600","0.76064","0.01230"
"1566","9.36000","0.78019","0.01181"
"1605","9.59400","0.79969","0.01226"
"1644","9.82800","0.81918","0.01254"
"1683","10.06200","0.83867","0.01294"
"1722","10.29600","0.85810","0.01307"
"1761","10.53000","0.87765","0.01331"
"1800","10.76400","0.89720","0.01290"
"1839","10.99800","0.91669","0.01302"
"1878","11.23200","0.93618","0.01347"
"1917","11.46600","0.95574","0.01267"
"1956","11.70000","0.97517","0.01355"
"1995","11.93400","0.99466","0.01348"
"2034","12.16800","1.01421","0.01376"
"2073","12.40200","1.03364","0.01301"
"2112","12.63600","1.05319","0.01414"
"2151","12.87000","1.07262","0.01371"
"2190","13.10400","1.09224","0.01380"
"2229","13.33800","1.11167","0.01396"
"2268","13.57200","1.13116","0.01456"
"2307","13.80600","1.15071","0.01373"
"2346","14.04000","1.17014","0.01444"
"2385","14.27400","1.18969","0.01414"
"2424","14.50800","1.20918","0.01422"
"2463","14.74200","1.22867","0.01458"
"2502","14.97600","1.24817","0.01449"
"2541","15.21000","1.26772","0.01535"
"2580","15.44400","1.28721","0.01453"
"2619","15.67800","1.30664","0.01484"
"2658","15.91200","1.32625","0.01432"
"2697","16.14600","1.34562","0.01506"
"2736","16.38000","1.36523","0.01494"
"2775","16.61400","1.38467","0.01496"
"2814","16.84800","1.40416","0.01535"
"2853","17.08200","1.42371","0.01514"
"2892","17.31600","1.44320","0.01508"
"2931","17.55000","1.46275","0.01489"
"2970","17.78400","1.48218","0.01565"
"3009","18.01800","1.50167","0.01527"
"3048","18.25200","1.52117","0.01465"
"3087","18.48600","1.54072","0.01566"
"3126","18.72000","1.56015","0.01512"
"3165","18.95400","1.57970","0.01567"
"3204","19.18800","1.59919","0.01593"
"3243","19.42200","1.61862","0.01546"
"3282","19.65600","1.63823","0.01511"
"3321","19.89000","1.65761","0.01548"
"3360","20.12400","1.67722","0.01620"
"3399","20.35800","1.69671","0.01565"
"3438","20.59200","1.71620","0.01596"
"3477","20.82600","1.73569","0.01650"
"3516","21.06000","1.75512","0.01654"
"3555","21.29400","1.77467","0.01606"
"3594","21.52800","1.79410","0.01624"
"3633","21.76200","1.81372","0.01609"
"3672","21.99600","1.83321","0.01610"
"3711","22.23000","1.85270","0.01587"
"3750","22.46400","1.87219","0.01651"
"3789","22.69800","1.89168","0.01677"
"3828","22.93200","1.91123","0.01633"
"3867","23.16600","1.93060","0.01676"
"3906","23.40000","1.95022","0.01681"
"3945","23.63400","1.96965","0.01658"
"3984","23.86800","1.98920","0.01638"
"4023","24.10200","2.00875","0.01704"
"4062","24.33600","2.02818","0.01736"
"4101","24.57000","2.04773","0.01644"
"4140","24.80400","2.06716","0.01735"
"4179","25.03800","2.08665","0.01786"
"4218","25.27200","2.10615","0.01738"
"4257","25.50600","2.12570","0.01712"
"4296","25.74000","2.14519","0.01750"
"4335","25.97400","2.16474","0.01687"
"4374","26.20800","2.18417","0.01731"
"4413","26.44200","2.20366","0.01692"
"4452","26.67600","2.22321","0.01745"
"4491","26.91000","2.24265","0.01742"
"4530","27.14400","2.26226","0.01794"
"4569","27.37800","2.28169","0.01815"
"4608","27.61200","2.30118","0.01778"
"4647","27.84600","2.32067","0.01791"
"4686","28.08000","2.34016","0.01767"
"4725","28.31400","2.35971","0.01776"
"4764","28.54800","2.37914","0.01817"
"4803","28.78200","2.39870","0.01829"
"4842","29.01600","2.41819","0.01799"
"4881","29.25000","2.43774","0.01838"
"4920","29.48400","2.45717","0.01842"
"4959","29.71800","2.47672","0.01753"
"4998","29.95200","2.49621","0.01745"
"5037","30.18600","2.51564","0.01797"
"5076","30.42000","2.53526","0.01803"
"5115","30.65400","2.55463","0.01758"
"5154","30.88800","2.57424","0.01747"
"5193","31.12200","2.59367","0.01723"
"5232","31.35600","2.61316","0.01748"
"5271","31.59000","2.63271","0.01746"
"5310","31.82400","2.65214","0.01787"
"5349","32.05800","2.67164","0.01800"
"5388","32.29200","2.69119","0.01820"
"5427","32.52600","2.71068","0.01780"
"5466","32.76000","2.73017","0.01839"
"5505","32.99400","2.74972","0.01819"
"5544","33.22800","2.76921","0.01817"
"5583","33.46200","2.78870","0.01778"
"5622","33.69600","2.80819","0.01817"
"5661","33.93000","2.82763","0.01795"
"5700","34.16400","2.84718","0.01789"
"5739","34.39800","2.86667","0.01724"
"5778","34.63200","2.88616","0.01765"
"5817","34.86600","2.90571","0.01823"
"5856","35.10000","2.92514","0.01805"
"5895","35.33400","2.94469","0.01716"
"5934","35.56800","2.96419","0.01823"
"5973","35.80200","2.98368","0.01816"
"6012","36.03600","3.00317","0.01785"
"6051","36.27000","3.02266","0.01786"
"6090","36.50400","3.04215","0.01798"
"6129","36.73800","3.06170","0.01810"
"6168","36.97200","3.08119","0.01804"
"6207","37.20600","3.10063","0.01814"
"6246","37.44000","3.12024","0.01796"
"6285","37.67400","3.13967","0.01748"
"6324","37.90800","3.15922","0.01746"
"6363","38.14200","3.17871","0.01751"
"6402","38.37600","3.19820","0.01766"
"6441","38.61000","3.21769","0.01748"
"6480","38.84400","3.23712","0.01776"
"6519","39.07800","3.25668","0.01764"
"6558","39.31200","3.27617","0.01748"
"6597","39.54600","3.29572","0.01797"
"6636","39.78000","3.31515","0.01761"
"6675","40.01400","3.33470","0.01705"
"6714","40.24800","3.35413","0.01712"
"6753","40.48200","3.37362","0.01727"
"6792","40.71600","3.39324","0.01711"
"6831","40.95000","3.41261","0.01776"
"6870","41.18400","3.43222","0.01768"
"6909","41.41800","3.45165","0.01738"
"6948","41.65200","3.47120","0.01801"
"6987","41.88600","3.49069","0.01783"
"7026","42.12000","3.51018","0.01724"
"7065","42.35400","3.52973","0.01765"
"7104","42.58800","3.54911","0.01805"
"7143","42.82200","3.56866","0.01744"
"7182","43.05600","3.58821","0.01758"
"7221","43.29000","3.60770","0.01794"
"7260","43.52400","3.62713","0.01812"
"7299","43.75800","3.64668","0.01772"
"7338","43.99200","3.66617","0.01842"
"7377","44.22600","3.68567","0.01707"
"7416","44.46000","3.70516","0.01797"
"7455","44.69400","3.72459","0.01850"
"7494","44.92800","3.74420","0.01694"
"7533","45.16200","3.76363","0.01724"
"7572","45.39600","3.78318","0.01727"
"7611","45.63000","3.80273","0.01678"
"7650","45.86400","3.82217","0.01742"
"7689","46.09800","3.84172","0.01759"
"7728","46.33200","3.86115","0.01747"
"7767","46.56600","3.88070","0.01732"
"7806","46.80000","3.90013","0.01720"
"7845","47.03400","3.91968","0.01774"
"7884","47.26800","3.93917","0.01760"
"7923","47.50200","3.95872","0.01729"
"7962","47.73600","3.97822","0.01755"
"8001","47.97000","3.99759","0.01773"
"8040","48.20400","4.01726","0.01775"
"8079","48.43800","4.03663","0.01730"
"8118","48.67200","4.05624","0.01784"
"8157","48.90600","4.07567","0.01750"
"8196","49.14000","4.09516","0.02047"
"8235","49.37400","4.11472","0.01629"
"8274","49.60800","4.13415","0.01526"
"8313","49.84200","4.15376","0.01497"
"8352","50.07600","4.17319","0.01558"
"8391","50.31000","4.19268","0.01541"
"8430","50.54400","4.21217","0.01559"
"8469","50.77800","4.23172","0.01595"
"8508","51.01200","4.25121","0.01543"
"8547","51.24600","4.27071","0.01610"
"8586","51.48000","4.29020","0.01625"
"8625","51.71400","4.30963","0.01655"
"8664","51.94800","4.32924","0.01606"
"8703","52.18200","4.34867","0.01561"
"8742","52.41600","4.36822","0.01606"
"8781","52.65000","4.38771","0.01622"
"8820","52.88400","4.40715","0.01624"
"8859","53.11800","4.42670","0.01620"
"8898","53.35200","4.44613","0.01655"
"8937","53.58600","4.46574","0.01683"
"8976","53.82000","4.48517","0.01597"
"9015","54.05400","4.50472","0.01643"
"9054","54.28800","4.52415","0.01626"
"9093","54.52200","4.54377","0.01622"
"9132","54.75600","4.56320","0.01682"
"9171","54.99000","4.58269","0.01637"
"9210","55.22400","4.60218","0.01641"
"9249","55.45800","4.62161","0.01607"
"9288","55.69200","4.64122","0.01545"
"9327","55.92600","4.66065","0.01670"
"9366","56.16000","4.68021","0.01660"
"9405","56.39400","4.69976","0.01591"
"9444","56.62800","4.71913","0.01637"
"9483","56.86200","4.73868","0.01697"
"9522","57.09600","4.75811","0.01640"
"9561","57.33000","4.77772","0.01671"
"9600","57.56400","4.79715","0.01664"
"9639","57.79800","4.81670","0.01669"
"9678","58.03200","4.83614","0.01744"
"9717","58.26600","4.85569","0.01667"
"9756","58.50000","4.87524","0.01705"
"9795","58.73400","4.89467","0.01731"
"9834","58.96800","4.91422","0.01742"
"9873","59.20200","4.93365","0.01664"
"9912","59.43600","4.95320","0.01689"
"9951","59.67000","4.97269","0.01712"
"9990","59.90400","4.99219","0.01686"
"10029","60.13800","5.01174","0.01676"
"10068","60.37200","5.03117","0.01684"
"10107","60.60600","5.05072","0.01702"
"10146","60.84000","5.07015","0.01694"
"10185","61.07400","5.08976","0.01714"
"10224","61.30800","5.10914","0.01699"
"10263","61.54200","5.12869","0.01696"
"10302","61.77600","5.14812","0.01725"
"10341","62.01000","5.16767","0.01741"
"10380","62.24400","5.18722","0.01729"
"10419","62.47800","5.20665","0.01741"
"10458","62.71200","5.22620","0.01725"
"10497","62.94600","5.24564","0.01759"
"10536","63.18000","5.26525","0.01812"
"10575","63.41400","5.28474","0.01733"
"10614","63.64800","5.30417","0.01784"
"10653","63.88200","5.32372","0.01773"
"10692","64.11600","5.34315","0.01786"
"10731","64.35000","5.36270","0.01735"
"10770","64.58400","5.38213","0.01804"
"10809","64.81800","5.40175","0.01698"
"10848","65.05200","5.42118","0.01781"
"10887","65.28600","5.44067","0.01777"
"10926","65.52000","5.46016","0.01847"
"10965","65.75400","5.47965","0.01789"
"11004","65.98800","5.49920","0.01814"
"11043","66.22200","5.51863","0.01853"
"11082","66.45600","5.53824","0.01833"
"11121","66.69000","5.55768","0.01875"
"11160","66.92400","5.57723","0.01839"
"11199","67.15800","5.59672","0.01839"
"11238","67.39200","5.61615","0.01842"
"11277","67.62600","5.63570","0.01842"
"11316","67.86000","5.65519","0.01813"
"11355","68.09400","5.67468","0.01863"
"11394","68.32800","5.69418","0.01905"
"11433","68.56200","5.71373","0.01791"
"11472","68.79600","5.73316","0.01895"
"11511","69.03000","5.75271","0.01857"
"11550","69.26400","5.77220","0.01843"
"11589","69.49800","5.79163","0.01868"
"11628","69.73200","5.81124","0.01800"
"11667","69.96600","5.83068","0.01864"
"11706","70.20000","5.85023","0.01896"
"11745","70.43400","5.86960","0.01919"
"11784","70.66800","5.88921","0.01946"
"11823","70.90200","5.90864","0.01910"
"11862","71.13600","5.92819","0.01909"
"11901","71.37000","5.94768","0.01911"
"11940","71.60400","5.96717","0.01989"
"11979","71.83800","5.98667","0.01913"
"12018","72.07200","6.00616","0.01917"
"12057","72.30600","6.02577","0.01936"
"12096","72.54000","6.04514","0.01967"
"12135","72.77400","6.06469","0.01927"
"12174","73.00800","6.08424","0.01921"
"12213","73.24200","6.10361","0.01976"
"12252","73.47600","6.12323","0.01933"
"12291","73.71000","6.14266","0.01890"
"12330","73.94400","6.16227","0.01955"
"12369","74.17800","6.18164","0.01967"
"12408","74.41200","6.20119","0.01997"
"12447","74.64600","6.22068","0.01948"
"12486","74.88000","6.24017","0.01959"
"12525","75.11400","6.25967","0.02041"
"12564","75.34800","6.27916","0.01972"
"12603","75.58200","6.29871","0.01997"
"12642","75.81600","6.31814","0.02023"
"12681","76.05000","6.33769","0.02008"
"12720","76.28400","6.35718","0.01978"
"12759","76.51800","6.37667","0.01957"
"12798","76.75200","6.39616","0.02019"
"12837","76.98600","6.41554","0.01934"
"12876","77.22000","6.43521","0.01934"
"12915","77.45400","6.45464","0.02034"
"12954","77.68800","6.47419","0.01975"
"12993","77.92200","6.49362","0.02038"
"13032","78.15600","6.51317","0.02006"
"13071","78.39000","6.53272","0.02050"
"13110","78.62400","6.55216","0.02017"
"13149","78.85800","6.57165","0.02041"
"13188","79.09200","6.59120","0.01980"
"13227","79.32600","6.61069","0.02023"
"13266","79.56000","6.63012","0.02008"
"13305","79.79400","6.64973","0.02057"
"13344","80.02800","6.66922","0.02020"
"13383","80.26200","6.68866","0.02030"
"13422","80.49600","6.70821","0.02084"
"13461","80.73000","6.72764","0.02068"
"13500","80.96400","6.74725","0.02079"
"13539","81.19800","6.76668","0.02050"
"13578","81.43200","6.78617","0.02075"
"13617","81.66600","6.80572","0.02082"
"13656","81.90000","6.82516","0.02081"
"13695","82.13400","6.84471","0.02076"
"13734","82.36800","6.86414","0.02039"
"13773","82.60200","6.88369","0.02115"
"13812","82.83600","6.90318","0.02050"
"13851","83.07000","6.92267","0.02116"
"13890","83.30400","6.94216","0.02122"
"13929","83.53800","6.96165","0.02170"
"13968","83.77200","6.98126","0.02106"
"14007","84.00600","7.00064","0.02127"
"14046","84.24000","7.02025","0.02129"
"14085","84.47400","7.03962","0.02140"
"14124","84.70800","7.05917","0.02132"
"14163","84.94200","7.07872","0.02132"
"14202","85.17600","7.09815","0.02127"
"14241","85.41000","7.11770","0.02178"
"14280","85.64400","7.13714","0.02124"
"14319","85.87800","7.15669","0.02158"
"14358","86.11200","7.17618","0.02158"
"14397","86.34600","7.19573","0.02194"
"14436","86.58000","7.21516","0.02163"
"14475","86.81400","7.23471","0.02151"
"14514","87.04800","7.25420","0.02198"
"14553","87.28200","7.27364","0.02218"
"14592","87.51600","7.29319","0.02140"
"14631","87.75000","7.31262","0.02112"
"14670","87.98400","7.33223","0.02196"
"14709","88.21800","7.35166","0.02177"
"14748","88.45200","7.37115","0.02158"
"14787","88.68600","7.39076","0.02157"
"14826","88.92000","7.41020","0.02189"
"14865","89.15400","7.42975","0.02188"
"14904","89.38800","7.44912","0.02182"
"14943","89.62200","7.46867","0.02184"
"14982","89.85600","7.48810","0.02192"
"15021","90.09000","7.50771","0.02192"
"15060","90.32400","7.52714","0.02229"
"15099","90.55800","7.54675","0.02170"
"15138","90.79200","7.56619","0.02180"
"15177","91.02600","7.58562","0.02243"
"15216","91.26000","7.60523","0.02250"
"15255","91.49400","7.62466","0.02211"
"15294","91.72800","7.64421","0.02231"
"15333","91.96200","7.66364","0.02246"
"15372","92.19600","7.68319","0.02262"
"15411","92.43000","7.70275","0.02269"
"15450","92.66400","7.72212","0.02262"
"15489","92.89800","7.74173","0.02250"
"15528","93.13200","7.76116","0.02286"
"15567","93.36600","7.78071","0.02224"
"15606","93.60000","7.80014","0.02259"
"15645","93.83400","7.81969","0.02275"
"15684","94.06800","7.83919","0.02263"
"15723","94.30200","7.85868","0.02274"
"15762","94.53600","7.87823","0.02313"
"15801","94.77000","7.89766","0.02290"
"15840","95.00400","7.91721","0.02299"
"15879","95.23800","7.93664","0.02271"
"15918","95.47200","7.95619","0.02290"
"15957","95.70600","7.97568","0.02299"
"15996","95.94000","7.99512","0.02288"
"16035","96.17400","8.01467","0.02291"
"16074","96.40800","8.03416","0.02346"
"16113","96.64200","8.05371","0.02306"
"16152","96.87600","8.07320","0.02329"
"16191","97.11000","8.09269","0.02323"
"16230","97.34400","8.11218","0.02326"
"16269","97.57800","8.13173","0.02286"
"16308","97.81200","8.15117","0.02324"
"16347","98.04600","8.17066","0.02317"
"16386","98.28000","8.19021","0.02325"
"16425","98.51400","8.20964","0.02355"
"16464","98.74800","8.22919","0.02365"
"16503","98.98200","8.24868","0.02330"
"16542","99.21600","8.26823","0.02332"
"16581","99.45000","8.28773","0.02354"
"16620","99.68400","8.30716","0.02388"
"16659","99.91800","8.32671","0.02392"
"16698","100.15200","8.34614","0.02425"
"16737","100.38600","8.36569","0.02380"
"16776","100.62000","8.38518","0.02384"
"16815","100.85400","8.40467","0.02405"
"16854","101.08800","8.42417","0.02403"
"16893","101.32200","8.44366","0.02418"
"16932","101.55600","8.46321","0.02417"
"16971","101.79000","8.48264","0.02427"
"17010","102.02400","8.50219","0.02457"
"17049","102.25800","8.52162","0.02460"
"17088","102.49200","8.54117","0.02435"
"17127","102.72600","8.56067","0.02439"
"17166","102.96000","8.58016","0.02461"
"17205","103.19400","8.59971","0.02475"
"17244","103.42800","8.61920","0.02475"
"17283","103.66200","8.63869","0.02495"
"17322","103.89600","8.65818","0.02531"
"17361","104.13000","8.67767","0.02561"
"17400","104.36400","8.69717","0.02536"
"17439","104.59800","8.71672","0.02518"
"17478","104.83200","8.73615","0.02558"
"17517","105.06600","8.75564","0.02559"
"17556","105.30000","8.77519","0.02566"
"17595","105.53400","8.79462","0.02573"
"17634","105.76800","8.81423","0.02647"
"17673","106.00200","8.83366","0.02616"
"17712","106.23600","8.85322","0.02594"
"17751","106.47000","8.87265","0.02635"
"17790","106.70400","8.89220","0.02633"
"17829","106.93800","8.91169","0.02676"
"17868","107.17200","8.93118","0.02639"
"17907","107.40600","8.95073","0.02649"
"17946","107.64000","8.97010","0.02697"
"17985","107.87400","8.98971","0.02666"
"18024","108.10800","9.00915","0.02728"
"18063","108.34200","9.02876","0.02671"
"18102","108.57600","9.04813","0.02741"
"18141","108.81000","9.06762","0.02785"
"18180","109.04400","9.08723","0.02716"
"18219","109.27800","9.10666","0.02806"
"18258","109.51200","9.12621","0.02802"
"18297","109.74600","9.14565","0.02815"
"18336","109.98000","9.16526","0.02818"
"18375","110.21400","9.18469","0.02832"
"18414","110.44800","9.20418","0.02841"
"18453","110.68200","9.22373","0.02835"
"18492","110.91600","9.24316","0.02862"
"18531","111.15000","9.26265","0.02812"
"18570","111.38400","9.28215","0.02847"
"18609","111.61800","9.30176","0.02830"
"18648","111.85200","9.32119","0.02852"
"18687","112.08600","9.34074","0.02841"
"18726","112.32000","9.36017","0.02898"
"18765","112.55400","9.37966","0.02887"
"18804","112.78800","9.39921","0.02918"
"18843","113.02200","9.41864","0.02973"
"18882","113.25600","9.43820","0.02941"
"18921","113.49000","9.45769","0.03029"
"18960","113.72400","9.47718","0.03077"
"18999","113.95800","9.49667","0.03007"
"19038","114.19200","9.51616","0.03049"
"19077","114.42600","9.53571","0.03101"
"19116","114.66000","9.55515","0.03119"
"19155","114.89400","9.57470","0.03121"
"19194","115.12800","9.59413","0.03144"
"19233","115.36200","9.61374","0.03154"
"19272","115.59600","9.63311","0.03223"
"19311","115.83000","9.65266","0.03239"
"19350","116.06400","9.67221","0.03267"
"19389","116.29800","9.69158","0.03298"
"19428","116.53200","9.71126","0.03367"
"19467","116.76600","9.73063","0.03331"
"19506","117.00000","9.75024","0.03386"
"19545","117.23400","9.76973","0.03432"
"19584","117.46800","9.78916","0.03468"
"19623","117.70200","9.80871","0.03406"
"19662","117.93600","9.82814","0.03564"
"19701","118.17000","9.84775","0.03529"
"19740","118.40400","9.86713","0.03536"
"19779","118.63800","9.88674","0.03622"
"19818","118.87200","9.90617","0.03581"
"19857","119.10600","9.92572","0.03667"
"19896","119.34000","9.94521","0.03736"
"19935","119.57400","9.96464","0.03754"
"19974","119.80800","9.98419","0.03733"
"20013","120.04200","10.00357","0.03834"
"20052","120.27600","10.02324","0.03864"
"20091","120.51000","10.04267","0.03884"
"20130","120.74400","10.06216","0.03923"
"20169","120.97800","10.08171","0.03967"
"20208","121.21200","10.10114","0.03978"
"20247","121.44600","10.12069","0.03957"
"20286","121.68000","10.14012","0.04049"
"20325","121.91400","10.15968","0.04024"
"20364","122.14800","10.17917","0.04086"
"20403","122.38200","10.19872","0.04079"
"20442","122.61600","10.21815","0.04111"
"20481","122.85000","10.23770","0.04201"
"20520","123.08400","10.25725","0.04218"
"20559","123.31800","10.27668","0.04238"
"20598","123.55200","10.29618","0.04276"
"20637","123.78600","10.31561","0.04295"
"20676","124.02000","10.33522","0.04283"
"20715","124.25400","10.35465","0.04361"
"20754","124.48800","10.37420","0.04376"
"20793","124.72200","10.39369","0.04476"
"20832","124.95600","10.41318","0.04479"
"20871","125.19000","10.43274","0.04534"
"20910","125.42400","10.45211","0.04551"
"20949","125.65800","10.47172","0.04620"
"20988","125.89200","10.49121","0.04624"
"21027","126.12600","10.51070","0.04702"
"21066","126.36000","10.53013","0.04746"
"21105","126.59400","10.54962","0.04760"
"21144","126.82800","10.56923","0.04802"
"21183","127.06200","10.58867","0.04857"
"21222","127.29600","10.60816","0.04939"
"21261","127.53000","10.62765","0.04904"
"21300","127.76400","10.64720","0.04995"
"21339","127.99800","10.66669","0.05034"
"21378","128.23199","10.68618","0.05084"
"21417","128.46600","10.70568","0.05133"
"21456","128.70000","10.72517","0.05226"
"21495","128.93401","10.74466","0.05281"
"21534","129.16800","10.76415","0.05348"
"21573","129.40199","10.78370","0.05393"
"21612","129.63600","10.80319","0.05318"
"21651","129.87000","10.82268","0.05424"
"21690","130.10400","10.84217","0.05500"
"21729","130.33800","10.86167","0.05584"
"21768","130.57201","10.88122","0.05634"
"21807","130.80600","10.90065","0.05702"
"21846","131.03999","10.92020","0.05771"
"21885","131.27400","10.93969","0.05865"
"21924","131.50800","10.95918","0.05837"
"21963","131.74200","10.97867","0.05840"
"22002","131.97600","10.99823","0.05921"
"22041","132.21001","11.01772","0.06003"
"22080","132.44400","11.03721","0.06099"
"22119","132.67799","11.05670","0.06243"
"22158","132.91200","11.07613","0.06280"
"22197","133.14600","11.09574","0.06277"
"22236","133.38000","11.11517","0.06342"
"22275","133.61400","11.13466","0.06441"
"22314","133.84801","11.15422","0.06480"
"22353","134.08200","11.17359","0.06529"
"22392","134.31599","11.19326","0.06585"
"22431","134.55000","11.21263","0.06673"
"22470","134.78400","11.23224","0.06681"
"22509","135.01801","11.25161","0.06744"
"22548","135.25200","11.27116","0.06791"
"22587","135.48599","11.29072","0.06828"
"22626","135.72000","11.31021","0.06857"
"22665","135.95399","11.32970","0.06946"
"22704","136.18800","11.34913","0.06982"
"22743","136.42200","11.36868","0.06946"
"22782","136.65601","11.38811","0.07013"
"22821","136.89000","11.40778","0.07035"
"22860","137.12399","11.42722","0.07093"
"22899","137.35800","11.44670","0.07149"
"22938","137.59200","11.46620","0.07174"
"22977","137.82600","11.48563","0.07067"
"23016","138.06000","11.50524","0.07107"
"23055","138.29401","11.52467","0.07109"
"23094","138.52800","11.54416","0.07169"
"23133","138.76199","11.56365","0.07191"
"23172","138.99600","11.58315","0.07260"
"23211","139.23000","11.60270","0.07297"
"23250","139.46400","11.62219","0.07362"
"23289","139.69800","11.64168","0.07356"
"23328","139.93201","11.66117","0.07417"
"23367","140.16600","11.68072","0.07412"
"23406","140.39999","11.70015","0.07444"
"23445","140.63400","11.71971","0.07491"
"23484","140.86800","11.73920","0.07531"
"23523","141.10201","11.75869","0.07558"
"23562","141.33600","11.77818","0.07586"
"23601","141.57001","11.79761","0.07557"
"23640","141.80400","11.81716","0.07539"
"23679","142.03799","11.83665","0.07527"
"23718","142.27200","11.85620","0.07527"
"23757","142.50600","11.87570","0.07486"
"23796","142.74001","11.89519","0.07208"
"23835","142.97400","11.91474","0.07161"
"23874","143.20799","11.93417","0.07137"
"23913","143.44200","11.95372","0.07155"
"23952","143.67599","11.97315","0.07247"
"23991","143.91000","11.99270","0.07167"
"24030","144.14400","12.01214","0.07196"
"24069","144.37801","12.03175","0.07261"
"24108","144.61200","12.05124","0.07284"
"24147","144.84599","12.07061","0.07324"
"24186","145.08000","12.09022","0.07345"
"24225","145.31400","12.10965","0.07339"
"24264","145.54800","12.12920","0.07390"
"24303","145.78200","12.14864","0.07437"
"24342","146.01601","12.16819","0.07467"
"24381","146.25000","12.18768","0.07540"
"24420","146.48399","12.20717","0.07585"
"24459","146.71800","12.22672","0.07606"
"24498","146.95200","12.24615","0.07624"
"24537","147.18600","12.26570","0.07638"
"24576","147.42000","12.28513","0.07702"
"24615","147.65401","12.30481","0.07647"
"24654","147.88800","12.32418","0.07452"
"24693","148.12199","12.34367","0.07064"
"24732","148.35600","12.36322","0.07185"
"24771","148.59000","12.38265","0.07245"
"24810","148.82401","12.40220","0.07320"
"24849","149.05800","12.42163","0.07381"
"24888","149.29201","12.44125","0.07421"
"24927","149.52600","12.46074","0.07515"
"24966","149.75999","12.48023","0.07522"
"25005","149.99400","12.49972","0.07557"
"25044","150.22800","12.51915","0.07621"
"25083","150.46201","12.53876","0.07661"
"25122","150.69600","12.55813","0.07700"
"25161","150.92999","12.57774","0.07749"
"25200","151.16400","12.59718","0.07802"
"25239","151.39799","12.61673","0.07838"
"25278","151.63200","12.63616","0.07916"
"25317","151.86600","12.65565","0.07926"
"25356","152.10001","12.67520","0.07909"
"25395","152.33400","12.69457","0.07953"
"25434","152.56799","12.71418","0.07939"
"25473","152.80200","12.73368","0.08023"
"25512","153.03600","12.75323","0.08083"
"25551","153.27000","12.77272","0.08161"
"25590","153.50400","12.79221","0.08197"
"25629","153.73801","12.81170","0.08259"
"25668","153.97200","12.83113","0.08326"
"25707","154.20599","12.85068","0.08406"
"25746","154.44000","12.87017","0.08450"
"25785","154.67400","12.88973","0.08545"
"25824","154.90800","12.90916","0.08611"
"25863","155.14200","12.92871","0.08695"
"25902","155.37601","12.94820","0.08779"
"25941","155.61000","12.96763","0.08853"
"25980","155.84399","12.98724","0.08902"
"26019","156.07800","13.00667","0.08984"
"26058","156.31200","13.02623","0.09138"
"26097","156.54601","13.04566","0.09186"
"26136","156.78000","13.06515","0.09285"
"26175","157.01401","13.08464","0.09345"
"26214","157.24800","13.10419","0.09395"
"26253","157.48199","13.12368","0.09562"
"26292","157.71600","13.14311","0.09669"
"26331","157.95000","13.16273","0.09776"
"26370","158.18401","13.18216","0.09864"
"26409","158.41800","13.20171","0.10002"
"26448","158.65199","13.22114","0.10119"
"26487","158.88600","13.24069","0.10257"
"26526","159.12000","13.26024","0.10387"
"26565","159.35400","13.27962","0.10528"
"26604","159.58800","13.29923","0.07401"
"26643","159.82201","13.31860","0.07117"
"26682","160.05600","13.33821","0.06881"
"26721","160.28999","13.35770","0.06964"
"26760","160.52400","13.37713","0.07151"
"26799","160.75800","13.39668","0.07195"
"26838","160.99200","13.41617","0.07327"
"26877","161.22600","13.43573","0.07388"
"26916","161.46001","13.45516","0.07462"
"26955","161.69400","13.47471","0.07521"
"26994","161.92799","13.49414","0.07642"
"27033","162.16200","13.51369","0.07653"
"27072","162.39600","13.53324","0.07742"
"27111","162.63000","13.55267","0.07812"
"27150","162.86400","13.57222","0.07860"
"27189","163.09801","13.59160","0.07907"
"27228","163.33200","13.61121","0.07998"
"27267","163.56599","13.63070","0.08101"
"27306","163.80000","13.65019","0.08134"
"27345","164.03400","13.66968","0.08239"
"27384","164.26801","13.68917","0.08366"
"27423","164.50200","13.70866","0.08437"
"27462","164.73599","13.72816","0.08538"
"27501","164.97000","13.74765","0.08668"
"27540","165.20399","13.76714","0.08780"
"27579","165.43800","13.78675","0.08908"
"27618","165.67200","13.80618","0.09046"
"27657","165.90601","13.82567","0.09160"
"27696","166.14000","13.84522","0.09287"
"27735","166.37399","13.86466","0.09482"
"27774","166.60800","13.88421","0.09553"
"27813","166.84200","13.90358","0.09723"
"27852","167.07600","13.92319","0.09805"
"27891","167.31000","13.94268","0.10000"
"27930","167.54401","13.96217","0.10182"
"27969","167.77800","13.98172","0.10343"
"28008","168.01199","14.00121","0.10456"
"28047","168.24600","14.02071","0.10612"
"28086","168.48000","14.04014","0.10526"
"28125","168.71400","14.05969","0.10707"
"28164","168.94800","14.07912","0.10922"
"28203","169.18201","14.09873","0.11098"
"28242","169.41600","14.11816","0.11354"
"28281","169.64999","14.13765","0.11530"
"28320","169.88400","14.15721","0.11634"
"28359","170.11800","14.17658","0.11911"
"28398","170.35201","14.19625","0.12059"
"28437","170.58600","14.21568","0.12241"
"28476","170.82001","14.23523","0.12371"
"28515","171.05400","14.25466","0.12526"
"28554","171.28799","14.27421","0.12585"
"28593","171.52200","14.29370","0.12799"
"28632","171.75600","14.31320","0.12945"
"28671","171.99001","14.33263","0.13088"
"28710","172.22400","14.35212","0.13338"
"28749","172.45799","14.37173","0.13378"
"28788","172.69200","14.39116","0.12683"
"28827","172.92599","14.41071","0.12683"
"28866","173.16000","14.43020","0.12663"
"28905","173.39400","14.44970","0.12867"
"28944","173.62801","14.46919","0.12972"
"28983","173.86200","14.48862","0.13183"
"29022","174.09599","14.50817","0.13444"
"29061","174.33000","14.52766","0.13531"
"29100","174.56400","14.54715","0.13720"
"29139","174.79800","14.56670","0.13877"
"29178","175.03200","14.58619","0.13907"
"29217","175.26601","14.60575","0.14098"
"29256","175.50000","14.62518","0.14272"
"29295","175.73399","14.64467","0.14396"
"29334","175.96800","14.66416","0.14536"
"29373","176.20200","14.68377","0.14634"
"29412","176.43600","14.70314","0.14784"
"29451","176.67000","14.72276","0.14871"
"29490","176.90401","14.74219","0.15011"
"29529","177.13800","14.76162","0.15096"
"29568","177.37199","14.78123","0.15222"
"29607","177.60600","14.80066","0.15342"
"29646","177.84000","14.82021","0.15404"
"29685","178.07401","14.83964","0.15505"
"29724","178.30800","14.85919","0.15601"
"29763","178.54201","14.87868","0.15758"
"29802","178.77600","14.89818","0.15900"
"29841","179.00999","14.91773","0.16086"
"29880","179.24400","14.93716","0.16288"
"29919","179.47800","14.95671","0.16421"
"29958","179.71201","14.97608","0.16592"
"29997","179.94600","14.99569","0.16710"
"30036","180.17999","15.01518","0.16764"
"30075","180.41400","15.03468","0.16838"
"30114","180.64799","15.05423","0.16874"
"30153","180.88200","15.07360","0.16978"
"30192","181.11600","15.09321","0.17075"
"30231","181.35001","15.11270","0.17174"
"30270","181.58400","15.13219","0.14846"
"30309","181.81799","15.15168","0.15055"
"30348","182.05200","15.17118","0.15203"
"30387","182.28600","15.19073","0.15278"
"30426","182.52000","15.21016","0.15570"
"30465","182.75400","15.22971","0.15522"
"30504","182.98801","15.24914","0.15802"
"30543","183.22200","15.26869","0.15896"
"30582","183.45599","15.28813","0.15937"
"30621","183.69000","15.30773","0.16231"
"30660","183.92400","15.32723","0.16270"
"30699","184.15800","15.34672","0.16415"
"30738","184.39200","15.36621","0.15569"
"30777","184.62601","15.38558","0.15752"
"30816","184.86000","15.40513","0.16036"
"30855","185.09399","15.42468","0.16153"
"30894","185.32800","15.44417","0.16293"
"30933","185.56200","15.46373","0.15389"
"30972","185.79601","15.48322","0.15558"
"31011","186.03000","15.50271","0.15761"
"31050","186.26401","15.52214","0.15897"
"31089","186.49800","15.54175","0.15856"
"31128","186.73199","15.56112","0.14895"
"31167","186.96600","15.58073","0.15074"
"31206","187.20000","15.60011","0.15323"
"31245","187.43401","15.61972","0.15559"
"31284","187.66800","15.63921","0.15754"
"31323","187.90199","15.65864","0.16093"
"31362","188.13600","15.67819","0.16259"
"31401","188.37000","15.69762","0.16575"
"31440","188.60400","15.71717","0.16733"
"31479","188.83800","15.73666","0.16923"
"31518","189.07201","15.75616","0.17128"
"31557","189.30600","15.77571","0.17280"
"31596","189.53999","15.79520","0.17469"
"31635","189.77400","15.81469","0.17694"
"31674","190.00800","15.83418","0.17736"
"31713","190.24200","15.85373","0.18011"
"31752","190.47600","15.87322","0.18099"
"31791","190.71001","15.89272","0.18194"
"31830","190.94400","15.91215","0.18280"
"31869","191.17799","15.93164","0.18393"
"31908","191.41200","15.95119","0.18522"
"31947","191.64600","15.97062","0.18575"
"31986","191.88000","15.99023","0.18627"
"32025","192.11400","16.00966","0.18625"
"32064","192.34801","16.02921","0.16699"
"32103","192.58200","16.04865","0.14961"
"32142","192.81599","16.06820","0.15280"
"32181","193.05000","16.08769","0.15444"
"32220","193.28400","16.10718","0.15554"
"32259","193.51801","16.12667","0.15932"
"32298","193.75200","16.14610","0.16020"
"32337","193.98599","16.16571","0.16268"
"32376","194.22000","16.18521","0.16485"
"32415","194.45399","16.20470","0.16639"
"32454","194.68800","16.22419","0.16791"
"32493","194.92200","16.24362","0.16954"
"32532","195.15601","16.26323","0.17087"
"32571","195.39000","16.28260","0.17274"
"32610","195.62399","16.30221","0.17317"
"32649","195.85800","16.32165","0.17411"
"32688","196.09200","16.34126","0.17550"
"32727","196.32600","16.36075","0.17711"
"32766","196.56000","16.38024","0.17797"
"32805","196.79401","16.39967","0.17842"
"32844","197.02800","16.41922","0.17993"
"32883","197.26199","16.43871","0.18107"
"32922","197.49600","16.45808","0.18238"
"32961","197.73000","16.47776","0.18377"
"33000","197.96400","16.49719","0.18375"
"33039","198.19800","16.51668","0.18439"
"33078","198.43201","16.53617","0.18552"
"33117","198.66600","16.55560","0.18618"
"33156","198.89999","16.57521","0.18661"
"33195","199.13400","16.59464","0.18758"
"33234","199.36800","16.61419","0.18820"
"33273","199.60201","16.63369","0.18900"
"33312","199.83600","16.65318","0.18866"
"33351","200.07001","16.67267","0.18725"
"33390","200.30400","16.69222","0.18534"
"33429","200.53799","16.71171","0.18619"
"33468","200.77200","16.73120","0.18718"
"33507","201.00600","16.75069","0.18745"
"33546","201.24001","16.77013","0.18817"
"33585","201.47400","16.78974","0.18950"
"33624","201.70799","16.80917","0.19028"
"33663","201.94200","16.82866","0.19051"
"33702","202.17599","16.84821","0.19069"
"33741","202.41000","16.86758","0.19139"
"33780","202.64400","16.88725","0.19202"
"33819","202.87801","16.90663","0.19191"
"33858","203.11200","16.92624","0.19250"
"33897","203.34599","16.94567","0.19272"
"33936","203.58000","16.96516","0.19089"
"33975","203.81400","16.98471","0.18894"
"34014","204.04800","17.00420","0.18987"
"34053","204.28200","17.02369","0.19069"
"34092","204.51601","17.04313","0.19047"
"34131","204.75000","17.06274","0.07786"
"34170","204.98399","17.08217","0.07594"
"34209","205.21800","17.10172","0.07976"
"34248","205.45200","17.12121","0.07617"
"34287","205.68600","17.14064","0.08197"
"34326","205.92000","17.16019","0.07703"
"34365","206.15401","17.17957","0.08302"
"34404","206.38800","17.19918","0.07866"
"34443","206.62199","17.21867","0.08386"
"34482","206.85600","17.23822","0.08103"
"34521","207.09000","17.25771","0.08593"
"34560","207.32401","17.27720","0.08274"
"34599","207.55800","17.29669","0.08629"
"34638","207.79201","17.31618","0.08647"
"34677","208.02600","17.33568","0.08761"
"34716","208.25999","17.35511","0.08998"
"34755","208.49400","17.37472","0.08911"
"34794","208.72800","17.39409","0.09490"
"34833","208.96201","17.41370","0.09086"
"34872","209.19600","17.43325","0.09821"
"34911","209.42999","17.45268","0.09275"
"34950","209.66400","17.47223","0.10023"
"34989","209.89799","17.49161","0.09591"
"35028","210.13200","17.51116","0.10259"
"35067","210.36600","17.53065","0.10063"
"35106","210.60001","17.55020","0.10530"
"35145","210.83400","17.56969","0.10710"
"35184","211.06799","17.58912","0.10659"
"35223","211.30200","17.60874","0.11333"
"35262","211.53600","17.62811","0.11087"
"35301","211.77000","17.64772","0.11836"
"35340","212.00400","17.66715","0.11553"
"35379","212.23801","17.68670","0.12238"
"35418","212.47200","17.70613","0.11924"
"35457","212.70599","17.72562","0.12437"
"35496","212.94000","17.74523","0.12518"
"35535","213.17400","17.76461","0.12578"
"35574","213.40800","17.78422","0.12915"
"35613","213.64200","17.80365","0.12886"
"35652","213.87601","17.82314","0.13258"
"35691","214.11000","17.84269","0.13172"
"35730","214.34399","17.86218","0.13604"
"35769","214.57800","17.88167","0.13596"
"35808","214.81200","17.90117","0.13813"
"35847","215.04601","17.92072","0.14056"
"35886","215.28000","17.94015","0.14053"
"35925","215.51401","17.95970","0.14312"
"35964","215.74800","17.97919","0.14337"
"36003","215.98199","17.99868","0.14557"
"36042","216.21600","18.01817","0.14103"
"36081","216.45000","18.03767","0.14395"
"36120","216.68401","18.05722","0.14656"
"36159","216.91800","18.07659","0.14636"
"36198","217.15199","18.09614","0.14946"
"36237","217.38600","18.11569","0.14944"
"36276","217.62000","18.13518","0.15207"
"36315","217.85400","18.15467","0.15339"
"36354","218.08800","18.17422","0.15477"
"36393","218.32201","18.19366","0.15735"
"36432","218.55600","18.21315","0.15792"
"36471","218.78999","18.23270","0.16089"
"36510","219.02400","18.25213","0.16191"
"36549","219.25800","18.27174","0.16453"
"36588","219.49200","18.29111","0.16654"
"36627","219.72600","18.31072","0.16761"
"36666","219.96001","18.33022","0.17007"
"36705","220.19400","18.34965","0.17139"
"36744","220.42799","18.36920","0.17260"
"36783","220.66200","18.38863","0.17438"
"36822","220.89600","18.40818","0.17606"
"36861","221.13000","18.42761","0.17830"
"36900","221.36400","18.44722","0.17900"
"36939","221.59801","18.46666","0.18063"
"36978","221.83200","18.48621","0.18209"
"37017","222.06599","18.50570","0.18323"
"37056","222.30000","18.52513","0.18431"
"37095","222.53400","18.54468","0.18519"
"37134","222.76801","18.56417","0.18608"
"37173","223.00200","18.58372","0.12643"
"37212","223.23599","18.60316","0.12560"
"37251","223.47000","18.62265","0.12633"
"37290","223.70399","18.64220","0.12941"
"37329","223.93800","18.66163","0.12666"
"37368","224.17200","18.68118","0.13636"
"37407","224.40601","18.70067","0.13258"
"37446","224.64000","18.72016","0.13756"
"37485","224.87399","18.73971","0.13635"
"37524","225.10800","18.75921","0.14082"
"37563","225.34200","18.77870","0.14424"
"37602","225.57600","18.79819","0.14496"
"37641","225.81000","18.81768","0.14916"
"37680","226.04401","18.83717","0.14867"
"37719","226.27800","18.85672","0.15314"
"37758","226.51199","18.87615","0.15364"
"37797","226.74600","18.89570","0.15588"
"37836","226.98000","18.91520","0.15965"
"37875","227.21400","18.93469","0.16030"
"37914","227.44800","18.95418","0.16598"
"37953","227.68201","18.97361","0.16674"
"37992","227.91600","18.99322","0.16925"
"38031","228.14999","19.01265","0.17150"
"38070","228.38400","19.03220","0.17242"
"38109","228.61800","19.05169","0.17632"
"38148","228.85201","19.07125","0.17729"
"38187","229.08600","19.09068","0.17930"
"38226","229.32001","19.11017","0.18120"
"38265","229.55400","19.12972","0.18173"
"38304","229.78799","19.14915","0.18427"
"38343","230.02200","19.16870","0.18535"
"38382","230.25600","19.18814","0.18648"
"38421","230.49001","19.20769","0.18772"
"38460","230.72400","19.22724","0.18773"
"38499","230.95799","19.24661","0.18950"
"38538","231.19200","19.26622","0.19030"
"38577","231.42599","19.28565","0.19130"
"38616","231.66000","19.30520","0.19335"
"38655","231.89400","19.32463","0.19479"
"38694","232.12801","19.34419","0.19653"
"38733","232.36200","19.36368","0.19877"
"38772","232.59599","19.38317","0.19978"
"38811","232.83000","19.40266","0.20201"
"38850","233.06400","19.42215","0.20355"
"38889","233.29800","19.44170","0.20535"
"38928","233.53200","19.46113","0.20437"
"38967","233.76601","19.48075","0.15408"
"39006","234.00000","19.50012","0.16220"
"39045","234.23399","19.51967","0.16295"
"39084","234.46800","19.53922","0.16141"
"39123","234.70200","19.55865","0.16732"
"39162","234.93600","19.57820","0.17181"
"39201","235.17000","19.59764","0.17043"
"39240","235.40401","19.61719","0.17215"
"39279","235.63800","19.63667","0.17936"
"39318","235.87199","19.65617","0.17876"
"39357","236.10600","19.67572","0.17888"
"39396","236.34000","19.69521","0.18248"
"39435","236.57401","19.71470","0.18438"
"39474","236.80800","19.73413","0.18486"
"39513","237.04201","19.75374","0.18594"
"39552","237.27600","19.77312","0.18749"
"39591","237.50999","19.79273","0.18946"
"39630","237.74400","19.81222","0.18932"
"39669","237.97800","19.83165","0.19061"
"39708","238.21201","19.85120","0.19250"
"39747","238.44600","19.87063","0.19478"
"39786","238.67999","19.89018","0.19589"
"39825","238.91400","19.90968","0.19763"
"39864","239.14799","19.92922","0.20001"
"39903","239.38200","19.94872","0.20268"
"39942","239.61600","19.96821","0.20372"
"39981","239.85001","19.98770","0.20510"
"40020","240.08400","20.00719","0.20741"
"40059","240.31799","20.02668","0.20948"
"40098","240.55200","20.04612","0.21159"
"40137","240.78600","20.06573","0.21379"
"40176","241.02000","20.08516","0.21591"
"40215","241.25400","20.10471","0.21937"
"40254","241.48801","20.12420","0.22094"
"40293","241.72200","20.14363","0.22383"
"40332","241.95599","20.16324","0.22484"
"40371","242.19000","20.18267","0.22547"
"40410","242.42400","20.20217","0.22806"
"40449","242.65800","20.22166","0.23033"
"40488","242.89200","20.24121","0.23199"
"40527","243.12601","20.26070","0.23434"
"40566","243.36000","20.28013","0.23656"
"40605","243.59399","20.29974","0.23827"
"40644","243.82800","20.31918","0.24112"
"40683","244.06200","20.33873","0.24375"
"40722","244.29601","20.35810","0.24603"
"40761","244.53000","20.37777","0.24870"
"40800","244.76401","20.39714","0.25090"
"40839","244.99800","20.41669","0.25407"
"40878","245.23199","20.43624","0.25718"
"40917","245.46600","20.45561","0.26052"
"40956","245.70000","20.47522","0.26458"
"40995","245.93401","20.49466","0.26836"
"41034","246.16800","20.51421","0.27090"
"41073","246.40199","20.53364","0.27365"
"41112","246.63600","20.55319","0.27451"
"41151","246.87000","20.57268","0.27686"
"41190","247.10400","20.59217","0.27917"
"41229","247.33800","20.61172","0.28179"
"41268","247.57201","20.63116","0.28328"
"41307","247.80600","20.65077","0.28405"
"41346","248.03999","20.67014","0.28566"
"41385","248.27400","20.68969","0.28694"
"41424","248.50800","20.70918","0.28916"
"41463","248.74200","20.72867","0.29074"
"41502","248.97600","20.74822","0.29216"
"41541","249.21001","20.76760","0.29380"
"41580","249.44400","20.78720","0.29497"
"41619","249.67799","20.80664","0.29574"
"41658","249.91200","20.82619","0.29631"
"41697","250.14600","20.84568","0.29737"
"41736","250.38000","20.86517","0.29802"
"41775","250.61400","20.88472","0.29912"
"41814","250.84801","20.90415","0.29988"
"41853","251.08200","20.92371","0.30113"
"41892","251.31599","20.94314","0.30298"
"41931","251.55000","20.96269","0.30425"
"41970","251.78400","20.98212","0.30591"
"42009","252.01801","21.00173","0.30825"
"42048","252.25200","21.02122","0.31156"
"42087","252.48599","21.04065","0.31398"
"42126","252.72000","21.06020","0.31725"
"42165","252.95399","21.07964","0.32135"
"42204","253.18800","21.09919","0.31549"
"42243","253.42200","21.11868","0.31978"
"42282","253.65601","21.13817","0.32300"
"42321","253.89000","21.15766","0.32702"
"42360","254.12399","21.17721","0.33010"
"42399","254.35800","21.19670","0.33271"
"42438","254.59200","21.21614","0.33608"
"42477","254.82600","21.23575","0.33875"
"42516","255.06000","21.25512","0.34115"
"42555","255.29401","21.27473","0.34372"
"42594","255.52800","21.29416","0.34696"
"42633","255.76199","21.31365","0.34982"
"42672","255.99600","21.33320","0.35235"
"42711","256.23001","21.35264","0.35442"
"42750","256.46399","21.37225","0.35654"
"42789","256.69800","21.39168","0.35822"
"42828","256.93201","21.41117","0.35999"
"42867","257.16599","21.43066","0.36272"
"42906","257.39999","21.45021","0.36488"
"42945","257.63400","21.46964","0.36778"
"42984","257.86801","21.48919","0.36825"
"43023","258.10199","21.50869","0.37078"
"43062","258.33600","21.52812","0.37267"
"43101","258.57001","21.54773","0.37516"
"43140","258.80399","21.56716","0.37671"
"43179","259.03799","21.58671","0.37882"
"43218","259.27200","21.60620","0.38031"
"43257","259.50601","21.62564","0.38201"
"43296","259.73999","21.64519","0.38318"
"43335","259.97400","21.66462","0.37921"
"43374","260.20801","21.68423","0.37984"
"43413","260.44199","21.70366","0.37688"
"43452","260.67599","21.72321","0.37755"
"43491","260.91000","21.74270","0.37920"
"43530","261.14401","21.76225","0.38092"
"43569","261.37799","21.78169","0.38218"
"43608","261.61200","21.80118","0.38429"
"43647","261.84601","21.82067","0.38597"
"43686","262.07999","21.84010","0.38751"
"43725","262.31400","21.85971","0.38847"
"43764","262.54800","21.87920","0.38932"
"43803","262.78201","21.89875","0.39025"
"43842","263.01599","21.91818","0.39168"
"43881","263.25000","21.93762","0.39243"
"43920","263.48401","21.95723","0.39405"
"43959","263.71799","21.97666","0.39575"
"43998","263.95200","21.99621","0.39764"
"44037","264.18600","22.01558","0.39939"
"44076","264.42001","22.03519","0.40000"
"44115","264.65399","22.05469","0.40142"
"44154","264.88800","22.07424","0.39776"
"44193","265.12201","22.09373","0.40041"
"44232","265.35599","22.11316","0.40171"
"44271","265.59000","22.13277","0.40400"
"44310","265.82401","22.15214","0.40570"
"44349","266.05801","22.17169","0.40776"
"44388","266.29199","22.19118","0.41080"
"44427","266.52600","22.21068","0.41272"
"44466","266.76001","22.23022","0.41468"
"44505","266.99399","22.24966","0.41744"
"44544","267.22800","22.26921","0.41971"
"44583","267.46201","22.28864","0.42279"
"44622","267.69601","22.30819","0.42574"
"44661","267.92999","22.32762","0.42789"
"44700","268.16400","22.34718","0.42997"
"44739","268.39801","22.36666","0.43117"
"44778","268.63199","22.38616","0.43377"
"44817","268.86600","22.40565","0.43518"
"44856","269.10001","22.42514","0.43733"
"44895","269.33401","22.44475","0.43928"
"44934","269.56799","22.46412","0.44051"
"44973","269.80200","22.48373","0.44362"
"45012","270.03601","22.50323","0.44570"
"45051","270.26999","22.52272","0.44804"
"45090","270.50400","22.54221","0.45055"
"45129","270.73801","22.56164","0.45213"
"45168","270.97198","22.58119","0.45483"
"45207","271.20599","22.60062","0.45717"
"45246","271.44000","22.62024","0.45917"
"45285","271.67401","22.63967","0.46180"
"45324","271.90799","22.65916","0.46527"
"45363","272.14200","22.67871","0.46854"
"45402","272.37601","22.69814","0.47294"
"45441","272.60999","22.71769","0.47694"
"45480","272.84399","22.73712","0.47944"
"45519","273.07800","22.75673","0.47329"
"45558","273.31201","22.77617","0.47545"
"45597","273.54599","22.79572","0.47882"
"45636","273.78000","22.81527","0.48308"
"45675","274.01401","22.83464","0.48596"
"45714","274.24799","22.85419","0.48926"
"45753","274.48199","22.87362","0.49173"
"45792","274.71600","22.89311","0.49446"
"45831","274.95001","22.91266","0.49516"
"45870","275.18399","22.93222","0.48993"
"45909","275.41800","22.95171","0.49148"
"45948","275.65201","22.97120","0.49356"
"45987","275.88599","22.99069","0.49513"
"46026","276.12000","23.01018","0.49663"
"46065","276.35400","23.02973","0.49788"
"46104","276.58801","23.04916","0.49921"
"46143","276.82199","23.06871","0.50023"
"46182","277.05600","23.08815","0.50203"
"46221","277.29001","23.10764","0.50283"
"46260","277.52399","23.12719","0.50490"
"46299","277.75800","23.14668","0.50625"
"46338","277.99200","23.16623","0.50846"
"46377","278.22601","23.18567","0.50998"
"46416","278.45999","23.20522","0.51123"
"46455","278.69400","23.22471","0.51320"
"46494","278.92801","23.24420","0.51519"
"46533","279.16199","23.26369","0.51745"
"46572","279.39600","23.28318","0.34309"
"46611","279.63000","23.30273","0.33541"
"46650","279.86401","23.32216","0.01930"
"46689","280.09799","23.34177","0.01399"
"46728","280.33200","23.36115","0.04523"
"46767","280.56601","23.38076","0.01814"
"46806","280.79999","23.40019","0.02665"
"46845","281.03400","23.41962","0.02553"
"46884","281.26801","23.43917","0.01770"
"46923","281.50201","23.45860","0.03546"
"46962","281.73599","23.47815","0.01898"
"47001","281.97000","23.49764","0.02982"
"47040","282.20401","23.51720","0.02513"
"47079","282.43799","23.53669","0.02468"
"47118","282.67200","23.55618","0.02934"
"47157","282.90601","23.57573","0.02233"
"47196","283.14001","23.59516","0.03125"
"47235","283.37399","23.61471","0.02357"
"47274","283.60800","23.63408","0.03030"
"47313","283.84201","23.65376","0.02493"
"47352","284.07599","23.67319","0.02807"
"47391","284.31000","23.69274","0.02713"
"47430","284.54401","23.71217","0.02731"
"47469","284.77802","23.73166","0.02877"
"47508","285.01199","23.75121","0.02731"
"47547","285.24600","23.77065","0.02946"
"47586","285.48001","23.79020","0.02719"
"47625","285.71399","23.80969","0.03096"
"47664","285.94800","23.82924","0.02746"
"47703","286.18201","23.84861","0.03050"
"47742","286.41599","23.86822","0.02850"
"47781","286.64999","23.88771","0.03080"
"47820","286.88400","23.90714","0.02988"
"47859","287.11801","23.92669","0.03091"
"47898","287.35199","23.94613","0.03097"
"47937","287.58600","23.96568","0.03077"
"47976","287.82001","23.98517","0.03175"
"48015","288.05399","24.00472","0.02993"
"48054","288.28799","24.02421","0.03245"
"48093","288.52200","24.04364","0.03179"
"48132","288.75601","24.06325","0.03315"
"48171","288.98999","24.08262","0.03253"
"48179","289.03799","24.08663","0.03270"