File: Trajectories_together/170107_2Specimen_RawData_7.csv
"","V1","V2","V3"
"1","End date","1/7/2017",""
"2","Specimen label","3AG_22",""
"3","Maximum Load","0.73679","N"
"4","Time","Extension","Load"
"5","(s)","(mm)","(N)"
"6","0.00000","0.00000","0.00005"
"71","0.39000","0.03270","0.00212"
"136","0.78000","0.06523","0.00430"
"201","1.17000","0.09770","0.00658"
"266","1.56000","0.13016","0.00788"
"331","1.95000","0.16269","0.01033"
"396","2.34000","0.19515","0.01186"
"461","2.73000","0.22768","0.01302"
"526","3.12000","0.26014","0.01466"
"591","3.51000","0.29267","0.01637"
"656","3.90000","0.32520","0.01737"
"721","4.29000","0.35766","0.01820"
"786","4.68000","0.39019","0.01939"
"851","5.07000","0.42265","0.01964"
"916","5.46000","0.45512","0.02107"
"981","5.85000","0.48764","0.02186"
"1046","6.24000","0.52017","0.02236"
"1111","6.63000","0.55275","0.02271"
"1176","7.02000","0.58516","0.02392"
"1241","7.41000","0.61763","0.02436"
"1306","7.80000","0.65021","0.02518"
"1371","8.19000","0.68274","0.02497"
"1436","8.58000","0.71514","0.02123"
"1501","8.97000","0.74767","0.02038"
"1566","9.36000","0.78019","0.01924"
"1631","9.75000","0.81272","0.01972"
"1696","10.14000","0.84513","0.02087"
"1761","10.53000","0.87771","0.02240"
"1826","10.92000","0.91024","0.02284"
"1891","11.31000","0.94264","0.02382"
"1956","11.70000","0.97517","0.02451"
"2021","12.09000","1.00769","0.02437"
"2086","12.48000","1.04016","0.02476"
"2151","12.87000","1.07262","0.02472"
"2216","13.26000","1.10521","0.02485"
"2281","13.65000","1.13774","0.02505"
"2346","14.04000","1.17014","0.02540"
"2411","14.43000","1.20267","0.02532"
"2476","14.82000","1.23519","0.02545"
"2541","15.21000","1.26772","0.02583"
"2606","15.60000","1.30006","0.02558"
"2671","15.99000","1.33265","0.02644"
"2736","16.38000","1.36517","0.02692"
"2801","16.77000","1.39770","0.02764"
"2866","17.16000","1.43017","0.02835"
"2931","17.55000","1.46269","0.02869"
"2996","17.94000","1.49522","0.02927"
"3061","18.33000","1.52762","0.02989"
"3126","18.72000","1.56015","0.03009"
"3191","19.11000","1.59273","0.03053"
"3256","19.50000","1.62520","0.03078"
"3321","19.89000","1.65761","0.03117"
"3386","20.28000","1.69019","0.03138"
"3451","20.67000","1.72266","0.03207"
"3516","21.06000","1.75518","0.03255"
"3581","21.45000","1.78765","0.03279"
"3646","21.84000","1.82023","0.03360"
"3711","22.23000","1.85276","0.03388"
"3776","22.62000","1.88510","0.03409"
"3841","23.01000","1.91763","0.03551"
"3906","23.40000","1.95022","0.03601"
"3971","23.79000","1.98268","0.03734"
"4036","24.18000","2.01515","0.03772"
"4101","24.57000","2.04767","0.03898"
"4166","24.96000","2.08026","0.03972"
"4231","25.35000","2.11266","0.04139"
"4296","25.74000","2.14513","0.04219"
"4361","26.13000","2.17771","0.04342"
"4426","26.52000","2.21024","0.04475"
"4491","26.91000","2.24259","0.04570"
"4556","27.30000","2.27523","0.04735"
"4621","27.69000","2.30776","0.04847"
"4686","28.08000","2.34016","0.04949"
"4751","28.47000","2.37263","0.05089"
"4816","28.86000","2.40521","0.05250"
"4881","29.25000","2.43774","0.05415"
"4946","29.64000","2.47014","0.05560"
"5011","30.03000","2.50267","0.05698"
"5076","30.42000","2.53520","0.05913"
"5141","30.81000","2.56766","0.06173"
"5206","31.20000","2.60013","0.06389"
"5271","31.59000","2.63271","0.06635"
"5336","31.98000","2.66524","0.06797"
"5401","32.37000","2.69764","0.07091"
"5466","32.76000","2.73011","0.07254"
"5531","33.15000","2.76270","0.07415"
"5596","33.54000","2.79516","0.07568"
"5661","33.93000","2.82769","0.07769"
"5726","34.32000","2.86015","0.07846"
"5791","34.71000","2.89268","0.08039"
"5856","35.10000","2.92520","0.08155"
"5921","35.49000","2.95761","0.08307"
"5986","35.88000","2.99019","0.08538"
"6051","36.27000","3.02272","0.08601"
"6116","36.66000","3.05513","0.08776"
"6181","37.05000","3.08759","0.08923"
"6246","37.44000","3.12024","0.09179"
"6311","37.83000","3.15270","0.09266"
"6376","38.22000","3.18511","0.09383"
"6441","38.61000","3.21769","0.09606"
"6506","39.00000","3.25022","0.09743"
"6571","39.39000","3.28268","0.09896"
"6636","39.78000","3.31515","0.09992"
"6701","40.17000","3.34774","0.10191"
"6766","40.56000","3.38020","0.10295"
"6831","40.95000","3.41267","0.10377"
"6896","41.34000","3.44513","0.10559"
"6961","41.73000","3.47766","0.10680"
"7026","42.12000","3.51018","0.10827"
"7091","42.51000","3.54265","0.11017"
"7156","42.90000","3.57523","0.11193"
"7221","43.29000","3.60764","0.11362"
"7286","43.68000","3.64023","0.11492"
"7351","44.07000","3.67263","0.11649"
"7416","44.46000","3.70522","0.11787"
"7481","44.85000","3.73768","0.10582"
"7546","45.24000","3.77015","0.10659"
"7611","45.63000","3.80267","0.10873"
"7676","46.02000","3.83520","0.11064"
"7741","46.41000","3.86767","0.11234"
"7806","46.80000","3.90019","0.11526"
"7871","47.19000","3.93272","0.11660"
"7936","47.58000","3.96518","0.11939"
"8001","47.97000","3.99771","0.12088"
"8066","48.36000","4.03017","0.12135"
"8131","48.75000","4.06270","0.12392"
"8196","49.14000","4.09522","0.12569"
"8261","49.53000","4.12769","0.12739"
"8326","49.92000","4.16016","0.12920"
"8391","50.31000","4.19268","0.13060"
"8456","50.70000","4.22521","0.13224"
"8521","51.09000","4.25767","0.13396"
"8586","51.48000","4.29020","0.13443"
"8651","51.87000","4.32266","0.13585"
"8716","52.26000","4.35519","0.13686"
"8781","52.65000","4.38765","0.13768"
"8846","53.04000","4.42018","0.13713"
"8911","53.43000","4.45277","0.12214"
"8976","53.82000","4.48517","0.12441"
"9041","54.21000","4.51764","0.12566"
"9106","54.60000","4.55022","0.12724"
"9171","54.99000","4.58275","0.12798"
"9236","55.38000","4.61515","0.12980"
"9301","55.77000","4.64768","0.13096"
"9366","56.16000","4.68015","0.13250"
"9431","56.55000","4.71261","0.13413"
"9496","56.94000","4.74514","0.13563"
"9561","57.33000","4.77766","0.13647"
"9626","57.72000","4.81019","0.13708"
"9691","58.11000","4.84265","0.13040"
"9756","58.50000","4.87512","0.13224"
"9821","58.89000","4.90764","0.13391"
"9886","59.28000","4.94017","0.13490"
"9951","59.67000","4.97264","0.13627"
"10016","60.06000","5.00522","0.13663"
"10081","60.45000","5.03775","0.13752"
"10146","60.84000","5.07015","0.13837"
"10211","61.23000","5.10262","0.13911"
"10276","61.62000","5.13520","0.14029"
"10341","62.01000","5.16773","0.14083"
"10406","62.40000","5.20014","0.14184"
"10471","62.79000","5.23266","0.14308"
"10536","63.18000","5.26519","0.14444"
"10601","63.57000","5.29771","0.14569"
"10666","63.96000","5.33018","0.14330"
"10731","64.35000","5.36270","0.14329"
"10796","64.74000","5.39523","0.14454"
"10861","65.13000","5.42763","0.14648"
"10926","65.52000","5.46016","0.14692"
"10991","65.91000","5.49268","0.14861"
"11056","66.30000","5.52515","0.15037"
"11121","66.69000","5.55762","0.15164"
"11186","67.08000","5.59014","0.15316"
"11251","67.47000","5.62273","0.15520"
"11316","67.86000","5.65519","0.15773"
"11381","68.25000","5.68766","0.15891"
"11446","68.64000","5.72024","0.16053"
"11511","69.03000","5.75277","0.16196"
"11576","69.42000","5.78512","0.16362"
"11641","69.81000","5.81770","0.16711"
"11706","70.20000","5.85023","0.16944"
"11771","70.59000","5.88269","0.17201"
"11836","70.98000","5.91510","0.16096"
"11901","71.37000","5.94762","0.16185"
"11966","71.76000","5.98021","0.16416"
"12031","72.15000","6.01267","0.16672"
"12096","72.54000","6.04514","0.16864"
"12161","72.93000","6.07773","0.17054"
"12226","73.32000","6.11019","0.17138"
"12291","73.71000","6.14260","0.17417"
"12356","74.10000","6.17512","0.17629"
"12421","74.49000","6.20771","0.17813"
"12486","74.88000","6.24017","0.17946"
"12551","75.27000","6.27264","0.18136"
"12616","75.66000","6.30517","0.18320"
"12681","76.05000","6.33775","0.15562"
"12746","76.44000","6.37016","0.15717"
"12811","76.83000","6.40262","0.13923"
"12876","77.22000","6.43521","0.13929"
"12941","77.61000","6.46773","0.14007"
"13006","78.00000","6.50014","0.14143"
"13071","78.39000","6.53266","0.14123"
"13136","78.78000","6.56525","0.14148"
"13201","79.17000","6.59766","0.14148"
"13266","79.56000","6.63012","0.14282"
"13331","79.95000","6.66271","0.14371"
"13396","80.34000","6.69523","0.14459"
"13461","80.73000","6.72764","0.09943"
"13526","81.12000","6.76022","0.10150"
"13591","81.51000","6.79269","0.10400"
"13656","81.90000","6.82516","0.10570"
"13721","82.29000","6.85762","0.10771"
"13786","82.68000","6.89021","0.11078"
"13851","83.07000","6.92273","0.11232"
"13916","83.46000","6.95514","0.11551"
"13981","83.85000","6.98766","0.11785"
"14046","84.24000","7.02019","0.12092"
"14111","84.63000","7.05271","0.12305"
"14176","85.02000","7.08518","0.12633"
"14241","85.41000","7.11764","0.12908"
"14306","85.80000","7.15023","0.13166"
"14371","86.19000","7.18270","0.13384"
"14436","86.58000","7.21510","0.13536"
"14501","86.97000","7.24775","0.13763"
"14566","87.36000","7.28021","0.13849"
"14631","87.75000","7.31262","0.13959"
"14696","88.14000","7.34514","0.14055"
"14761","88.53000","7.37773","0.14156"
"14826","88.92000","7.41020","0.14268"
"14891","89.31000","7.44266","0.14417"
"14956","89.70000","7.47519","0.14537"
"15021","90.09000","7.50771","0.14683"
"15086","90.48000","7.54018","0.14818"
"15151","90.87000","7.57264","0.14934"
"15216","91.26000","7.60523","0.15153"
"15281","91.65000","7.63769","0.15346"
"15346","92.04000","7.67010","0.15516"
"15411","92.43000","7.70269","0.15674"
"15476","92.82000","7.73515","0.15766"
"15541","93.21000","7.76768","0.15966"
"15606","93.60000","7.80014","0.16172"
"15671","93.99000","7.83273","0.16358"
"15736","94.38000","7.86519","0.16607"
"15801","94.77000","7.89766","0.16713"
"15866","95.16000","7.93013","0.16942"
"15931","95.55000","7.96271","0.17250"
"15996","95.94000","7.99518","0.17504"
"16061","96.33000","8.02758","0.17625"
"16126","96.72000","8.06017","0.17799"
"16191","97.11000","8.09269","0.18006"
"16256","97.50000","8.12516","0.18251"
"16321","97.89000","8.15762","0.18526"
"16386","98.28000","8.19021","0.18739"
"16451","98.67000","8.22268","0.19058"
"16516","99.06000","8.25514","0.19295"
"16581","99.45000","8.28767","0.19644"
"16646","99.84000","8.32019","0.19757"
"16711","100.23000","8.35272","0.19849"
"16776","100.62000","8.38518","0.20215"
"16841","101.01000","8.41771","0.20421"
"16906","101.40000","8.45011","0.20758"
"16971","101.79000","8.48270","0.19616"
"17036","102.18000","8.51517","0.19747"
"17101","102.57000","8.54769","0.20007"
"17166","102.96000","8.58022","0.20253"
"17231","103.35000","8.61268","0.20644"
"17296","103.74000","8.64521","0.21031"
"17361","104.13000","8.67767","0.21449"
"17426","104.52000","8.71020","0.21457"
"17491","104.91000","8.74260","0.21026"
"17556","105.30000","8.77519","0.21469"
"17621","105.69000","8.80772","0.21947"
"17686","106.08000","8.84018","0.22370"
"17751","106.47000","8.87265","0.22664"
"17816","106.86000","8.90517","0.22773"
"17881","107.25000","8.93770","0.23049"
"17946","107.64000","8.97016","0.23158"
"18011","108.03000","9.00269","0.23388"
"18076","108.42000","9.03521","0.23678"
"18141","108.81000","9.06768","0.23855"
"18206","109.20000","9.10015","0.24013"
"18271","109.59000","9.13267","0.24211"
"18336","109.98000","9.16520","0.24406"
"18401","110.37000","9.19766","0.24530"
"18466","110.76000","9.23019","0.24662"
"18531","111.15000","9.26271","0.24665"
"18596","111.54000","9.29524","0.24778"
"18661","111.93000","9.32765","0.24868"
"18726","112.32000","9.36017","0.24997"
"18791","112.71000","9.39270","0.25122"
"18856","113.10000","9.42516","0.25245"
"18921","113.49000","9.45763","0.25323"
"18986","113.88000","9.49021","0.25325"
"19051","114.27000","9.52274","0.25467"
"19116","114.66000","9.55520","0.25623"
"19181","115.05000","9.58767","0.25817"
"19246","115.44000","9.62020","0.26004"
"19311","115.83000","9.65272","0.26231"
"19376","116.22000","9.68513","0.26416"
"19441","116.61000","9.71765","0.26708"
"19506","117.00000","9.75018","0.27046"
"19571","117.39000","9.78264","0.27359"
"19636","117.78000","9.81517","0.27751"
"19701","118.17000","9.84769","0.28009"
"19766","118.56000","9.88022","0.28271"
"19831","118.95000","9.91269","0.28564"
"19896","119.34000","9.94515","0.29075"
"19961","119.73000","9.97774","0.29614"
"20026","120.12000","10.01020","0.29942"
"20091","120.51000","10.04261","0.30112"
"20156","120.90000","10.07519","0.30392"
"20221","121.29000","10.10772","0.30711"
"20286","121.68000","10.14019","0.30866"
"20351","122.07000","10.17265","0.29086"
"20416","122.46000","10.20524","0.29416"
"20481","122.85000","10.23770","0.29709"
"20546","123.24000","10.27017","0.30115"
"20611","123.63000","10.30263","0.30466"
"20676","124.02000","10.33522","0.30710"
"20741","124.41000","10.36768","0.30951"
"20806","124.80000","10.40015","0.31128"
"20871","125.19000","10.43274","0.31359"
"20936","125.58000","10.46520","0.31562"
"21001","125.97000","10.49767","0.31834"
"21066","126.36000","10.53019","0.32109"
"21131","126.75000","10.56272","0.32406"
"21196","127.14000","10.59524","0.32616"
"21261","127.53000","10.62759","0.32887"
"21326","127.92000","10.66011","0.33124"
"21391","128.31000","10.69270","0.33362"
"21456","128.70000","10.72523","0.33589"
"21521","129.09000","10.75763","0.33846"
"21586","129.48000","10.79016","0.34007"
"21651","129.87000","10.82274","0.34243"
"21716","130.25999","10.85515","0.34378"
"21781","130.64999","10.88761","0.34566"
"21846","131.03999","10.92020","0.34836"
"21911","131.42999","10.95273","0.35068"
"21976","131.82001","10.98507","0.35364"
"22041","132.21001","11.01766","0.35693"
"22106","132.60001","11.05018","0.35980"
"22171","132.99001","11.08265","0.36130"
"22236","133.38000","11.11511","0.36450"
"22301","133.77000","11.14770","0.36713"
"22366","134.16000","11.18022","0.37260"
"22431","134.55000","11.21263","0.37725"
"22496","134.94000","11.24516","0.38187"
"22561","135.33000","11.27774","0.38509"
"22626","135.72000","11.31021","0.36107"
"22691","136.11000","11.34261","0.36280"
"22756","136.50000","11.37520","0.36411"
"22821","136.89000","11.40766","0.36722"
"22886","137.28000","11.44019","0.36953"
"22951","137.67000","11.47266","0.37305"
"23016","138.06000","11.50518","0.37587"
"23081","138.45000","11.53771","0.37950"
"23146","138.84000","11.57011","0.38307"
"23211","139.23000","11.60264","0.38590"
"23276","139.62000","11.63528","0.38813"
"23341","140.00999","11.66763","0.39090"
"23406","140.39999","11.70009","0.39335"
"23471","140.78999","11.73274","0.39230"
"23536","141.17999","11.76520","0.39435"
"23601","141.57001","11.79767","0.39736"
"23666","141.96001","11.83014","0.40075"
"23731","142.35001","11.86272","0.40412"
"23796","142.74001","11.89519","0.40745"
"23861","143.13000","11.92759","0.41010"
"23926","143.52000","11.96018","0.41337"
"23991","143.91000","11.99270","0.41661"
"24056","144.30000","12.02517","0.42074"
"24121","144.69000","12.05764","0.42582"
"24186","145.08000","12.09022","0.43485"
"24251","145.47000","12.12269","0.43943"
"24316","145.86000","12.15515","0.44256"
"24381","146.25000","12.18768","0.44560"
"24446","146.64000","12.22020","0.44791"
"24511","147.03000","12.25267","0.44989"
"24576","147.42000","12.28513","0.45196"
"24641","147.81000","12.31772","0.45327"
"24706","148.20000","12.35025","0.45661"
"24771","148.59000","12.38265","0.45909"
"24836","148.98000","12.41512","0.46184"
"24901","149.37000","12.44770","0.46412"
"24966","149.75999","12.48017","0.42276"
"25031","150.14999","12.51263","0.42241"
"25096","150.53999","12.54516","0.42674"
"25161","150.92999","12.57768","0.43475"
"25226","151.32001","12.61015","0.44018"
"25291","151.71001","12.64268","0.44489"
"25356","152.10001","12.67520","0.44856"
"25421","152.49001","12.70767","0.45044"
"25486","152.88000","12.74013","0.45310"
"25551","153.27000","12.77260","0.45517"
"25616","153.66000","12.80518","0.45740"
"25681","154.05000","12.83765","0.37871"
"25746","154.44000","12.87012","0.34793"
"25811","154.83000","12.90270","0.34838"
"25876","155.22000","12.93517","0.35395"
"25941","155.61000","12.96769","0.35760"
"26006","156.00000","13.00010","0.36349"
"26071","156.39000","13.03274","0.36722"
"26136","156.78000","13.06521","0.37147"
"26201","157.17000","13.09767","0.37781"
"26266","157.56000","13.13014","0.38372"
"26331","157.95000","13.16267","0.38510"
"26396","158.34000","13.19519","0.38849"
"26461","158.73000","13.22766","0.39075"
"26526","159.12000","13.26018","0.39221"
"26591","159.50999","13.29265","0.39680"
"26656","159.89999","13.32517","0.39958"
"26721","160.28999","13.35764","0.40413"
"26786","160.67999","13.39023","0.40980"
"26851","161.07001","13.42275","0.41222"
"26916","161.46001","13.45516","0.41825"
"26981","161.85001","13.48768","0.42137"
"27046","162.24001","13.52021","0.42645"
"27111","162.63000","13.55267","0.43259"
"27176","163.02000","13.58514","0.43541"
"27241","163.41000","13.61766","0.44114"
"27306","163.80000","13.65013","0.44362"
"27371","164.19000","13.68272","0.44590"
"27436","164.58000","13.71512","0.44845"
"27501","164.97000","13.74771","0.45004"
"27566","165.36000","13.78023","0.45226"
"27631","165.75000","13.81264","0.45306"
"27696","166.14000","13.84516","0.45503"
"27761","166.53000","13.87769","0.45666"
"27826","166.92000","13.91022","0.45881"
"27891","167.31000","13.94268","0.46085"
"27956","167.70000","13.97520","0.46322"
"28021","168.09000","14.00767","0.46657"
"28086","168.48000","14.04020","0.46819"
"28151","168.87000","14.07266","0.47150"
"28216","169.25999","14.10513","0.47538"
"28281","169.64999","14.13771","0.48255"
"28346","170.03999","14.17018","0.48551"
"28411","170.42999","14.20265","0.48912"
"28476","170.82001","14.23517","0.49399"
"28541","171.21001","14.26764","0.49849"
"28606","171.60001","14.30016","0.45540"
"28671","171.99001","14.33269","0.42092"
"28736","172.38000","14.36521","0.41935"
"28801","172.77000","14.39768","0.41756"
"28866","173.16000","14.43015","0.42080"
"28931","173.55000","14.46273","0.39619"
"28996","173.94000","14.49520","0.39661"
"29061","174.33000","14.52766","0.39704"
"29126","174.72000","14.56019","0.40012"
"29191","175.11000","14.59265","0.40308"
"29256","175.50000","14.62518","0.40584"
"29321","175.89000","14.65764","0.41072"
"29386","176.28000","14.69023","0.41475"
"29451","176.67000","14.72269","0.42012"
"29516","177.06000","14.75516","0.42486"
"29581","177.45000","14.78769","0.42809"
"29646","177.84000","14.82021","0.43302"
"29711","178.23000","14.85268","0.43563"
"29776","178.62000","14.88514","0.43982"
"29841","179.00999","14.91767","0.44346"
"29906","179.39999","14.95019","0.44657"
"29971","179.78999","14.98272","0.44969"
"30036","180.17999","15.01513","0.45100"
"30101","180.57001","15.04771","0.45299"
"30166","180.96001","15.08024","0.45458"
"30231","181.35001","15.11258","0.45671"
"30296","181.74001","15.14517","0.45817"
"30361","182.13000","15.17769","0.45975"
"30426","182.52000","15.21022","0.46208"
"30491","182.91000","15.24263","0.46390"
"30556","183.30000","15.27515","0.46608"
"30621","183.69000","15.30768","0.46860"
"30686","184.08000","15.34014","0.47171"
"30751","184.47000","15.37261","0.47536"
"30816","184.86000","15.40525","0.47960"
"30881","185.25000","15.43772","0.48262"
"30946","185.64000","15.47012","0.48788"
"31011","186.03000","15.50271","0.49043"
"31076","186.42000","15.53517","0.49166"
"31141","186.81000","15.56770","0.49725"
"31206","187.20000","15.60011","0.50148"
"31271","187.59000","15.63269","0.50414"
"31336","187.98000","15.66522","0.50593"
"31401","188.37000","15.69762","0.50921"
"31466","188.75999","15.73015","0.51082"
"31531","189.14999","15.76273","0.51380"
"31596","189.53999","15.79520","0.51601"
"31661","189.92999","15.82760","0.51865"
"31726","190.32001","15.86019","0.52214"
"31791","190.71001","15.89272","0.52651"
"31856","191.10001","15.92518","0.52967"
"31921","191.49001","15.95765","0.53349"
"31986","191.88000","15.99017","0.53529"
"32051","192.27000","16.02276","0.53790"
"32116","192.66000","16.05510","0.53970"
"32181","193.05000","16.08769","0.54173"
"32246","193.44000","16.12021","0.54339"
"32311","193.83000","16.15268","0.54582"
"32376","194.22000","16.18509","0.54712"
"32441","194.61000","16.21767","0.54909"
"32506","195.00000","16.25020","0.55042"
"32571","195.39000","16.28266","0.55166"
"32636","195.78000","16.31513","0.55318"
"32701","196.17000","16.34771","0.55392"
"32766","196.56000","16.38018","0.55515"
"32831","196.95000","16.41265","0.55684"
"32896","197.34000","16.44517","0.55843"
"32961","197.73000","16.47770","0.55997"
"33026","198.12000","16.51022","0.56187"
"33091","198.50999","16.54263","0.56455"
"33156","198.89999","16.57521","0.56709"
"33221","199.28999","16.60774","0.57041"
"33286","199.67999","16.64014","0.57454"
"33351","200.07001","16.67267","0.57740"
"33416","200.46001","16.70526","0.57609"
"33481","200.85001","16.73766","0.57992"
"33546","201.24001","16.77013","0.58309"
"33611","201.63000","16.80265","0.51039"
"33676","202.02000","16.83518","0.51057"
"33741","202.41000","16.86764","0.51028"
"33806","202.80000","16.90017","0.51092"
"33871","203.19000","16.93269","0.50646"
"33936","203.58000","16.96522","0.31836"
"34001","203.97000","16.99763","0.31376"
"34066","204.36000","17.03021","0.31515"
"34131","204.75000","17.06268","0.32131"
"34196","205.14000","17.09520","0.32024"
"34261","205.53000","17.12767","0.31839"
"34326","205.92000","17.16025","0.32320"
"34391","206.31000","17.19266","0.32809"
"34456","206.70000","17.22519","0.32765"
"34521","207.09000","17.25765","0.32881"
"34586","207.48000","17.29018","0.33256"
"34651","207.87000","17.32270","0.33459"
"34716","208.25999","17.35511","0.33474"
"34781","208.64999","17.38769","0.33830"
"34846","209.03999","17.42016","0.34177"
"34911","209.42999","17.45268","0.34201"
"34976","209.82001","17.48515","0.34445"
"35041","210.21001","17.51768","0.34939"
"35106","210.60001","17.55014","0.35033"
"35171","210.99001","17.58267","0.35234"
"35236","211.38000","17.61513","0.35908"
"35301","211.77000","17.64772","0.36071"
"35366","212.16000","17.68018","0.36328"
"35431","212.55000","17.71265","0.36953"
"35496","212.94000","17.74517","0.37132"
"35561","213.33000","17.77764","0.37354"
"35626","213.72000","17.81017","0.37987"
"35691","214.11000","17.84263","0.38090"
"35756","214.50000","17.87516","0.38332"
"35821","214.89000","17.90768","0.38786"
"35886","215.28000","17.94015","0.38901"
"35951","215.67000","17.97267","0.39223"
"36016","216.06000","18.00520","0.10132"
"36081","216.45000","18.03773","0.10549"
"36146","216.84000","18.07013","0.10947"
"36211","217.23000","18.10266","0.11660"
"36276","217.62000","18.13518","0.12266"
"36341","218.00999","18.16765","0.12776"
"36406","218.39999","18.20017","0.13107"
"36471","218.78999","18.23270","0.13424"
"36536","219.17999","18.26516","0.13684"
"36601","219.57001","18.29763","0.13851"
"36666","219.96001","18.33015","0.14009"
"36731","220.35001","18.36268","0.14116"
"36796","220.74001","18.39515","0.14279"
"36861","221.13000","18.42767","0.14407"
"36926","221.52000","18.46020","0.14580"
"36991","221.91000","18.49272","0.14759"
"37056","222.30000","18.52513","0.14982"
"37121","222.69000","18.55766","0.15201"
"37186","223.08000","18.59024","0.15460"
"37251","223.47000","18.62271","0.15720"
"37316","223.86000","18.65517","0.15962"
"37381","224.25000","18.68764","0.16249"
"37446","224.64000","18.72016","0.16635"
"37511","225.03000","18.75269","0.16657"
"37576","225.42000","18.78515","0.17168"
"37641","225.81000","18.81768","0.17678"
"37706","226.20000","18.85021","0.18082"
"37771","226.59000","18.88267","0.18483"
"37836","226.98000","18.91514","0.18856"
"37901","227.37000","18.94772","0.16951"
"37966","227.75999","18.98019","0.17221"
"38031","228.14999","19.01265","0.17428"
"38096","228.53999","19.04512","0.17614"
"38161","228.92999","19.07764","0.17913"
"38226","229.32001","19.11017","0.18216"
"38291","229.71001","19.14269","0.18505"
"38356","230.10001","19.17516","0.18858"
"38421","230.49001","19.20769","0.19218"
"38486","230.88000","19.24015","0.19759"
"38551","231.27000","19.27268","0.20329"
"38616","231.66000","19.30520","0.20880"
"38681","232.05000","19.33773","0.21318"
"38746","232.44000","19.37013","0.21807"
"38811","232.83000","19.40260","0.22113"
"38876","233.22000","19.43519","0.22486"
"38941","233.61000","19.46771","0.22942"
"39006","234.00000","19.50012","0.23250"
"39071","234.39000","19.53270","0.23649"
"39136","234.78000","19.56517","0.23974"
"39201","235.17000","19.59764","0.24297"
"39266","235.56000","19.63016","0.24482"
"39331","235.95000","19.66274","0.24625"
"39396","236.34000","19.69521","0.24787"
"39461","236.73000","19.72761","0.24928"
"39526","237.12000","19.76014","0.25115"
"39591","237.50999","19.79267","0.25272"
"39656","237.89999","19.82519","0.25401"
"39721","238.28999","19.85766","0.25546"
"39786","238.67999","19.89024","0.25642"
"39851","239.07001","19.92271","0.25852"
"39916","239.46001","19.95512","0.25828"
"39981","239.85001","19.98764","0.26144"
"40046","240.24001","20.02017","0.26590"
"40111","240.63000","20.05275","0.27111"
"40176","241.02000","20.08510","0.27463"
"40241","241.41000","20.11762","0.27826"
"40306","241.80000","20.15021","0.28204"
"40371","242.19000","20.18267","0.28539"
"40436","242.58000","20.21520","0.28900"
"40501","242.97000","20.24766","0.29288"
"40566","243.36000","20.28019","0.29714"
"40631","243.75000","20.31260","0.30133"
"40696","244.14000","20.34518","0.30533"
"40761","244.53000","20.37771","0.30752"
"40826","244.92000","20.41018","0.30955"
"40891","245.31000","20.44264","0.30335"
"40956","245.70000","20.47517","0.30532"
"41021","246.09000","20.50769","0.30796"
"41086","246.48000","20.54015","0.30986"
"41151","246.87000","20.57268","0.31253"
"41216","247.25999","20.60521","0.31544"
"41281","247.64999","20.63767","0.31826"
"41346","248.03999","20.67014","0.32052"
"41411","248.42999","20.70266","0.32300"
"41476","248.82001","20.73525","0.32475"
"41541","249.21001","20.76765","0.32808"
"41606","249.60001","20.80012","0.33040"
"41671","249.99001","20.83271","0.33219"
"41736","250.38000","20.86523","0.33463"
"41801","250.77000","20.89764","0.33519"
"41866","251.16000","20.93016","0.33722"
"41931","251.55000","20.96269","0.33892"
"41996","251.94000","20.99516","0.34020"
"42061","252.33000","21.02762","0.34125"
"42126","252.72000","21.06020","0.34273"
"42191","253.11000","21.09273","0.34410"
"42256","253.50000","21.12514","0.34553"
"42321","253.89000","21.15772","0.34836"
"42386","254.28000","21.19025","0.35015"
"42451","254.67000","21.22271","0.35296"
"42516","255.06000","21.25512","0.35565"
"42581","255.45000","21.28771","0.35812"
"42646","255.84000","21.32017","0.36135"
"42711","256.23001","21.35264","0.36084"
"42776","256.62000","21.38510","0.36423"
"42841","257.01001","21.41768","0.36819"
"42906","257.39999","21.45021","0.37214"
"42971","257.79001","21.48268","0.37588"
"43036","258.17999","21.51514","0.37951"
"43101","258.57001","21.54767","0.38276"
"43166","258.95999","21.58019","0.38501"
"43231","259.35001","21.61266","0.38726"
"43296","259.73999","21.64519","0.38954"
"43361","260.13000","21.67771","0.39196"
"43426","260.51999","21.71012","0.39458"
"43491","260.91000","21.74264","0.39739"
"43556","261.29999","21.77523","0.40078"
"43621","261.69000","21.80769","0.40350"
"43686","262.07999","21.84016","0.40602"
"43751","262.47000","21.87269","0.40887"
"43816","262.85999","21.90521","0.41107"
"43881","263.25000","21.93773","0.41403"
"43946","263.64001","21.97014","0.41728"
"44011","264.03000","22.00273","0.42017"
"44076","264.42001","22.03519","0.42462"
"44141","264.81000","22.06766","0.42789"
"44206","265.20001","22.10012","0.43266"
"44271","265.59000","22.13271","0.39060"
"44336","265.98001","22.16518","0.39200"
"44401","266.37000","22.19764","0.39299"
"44466","266.76001","22.23022","0.39484"
"44531","267.14999","22.26269","0.39738"
"44596","267.54001","22.29522","0.40026"
"44661","267.92999","22.32768","0.40344"
"44726","268.32001","22.36021","0.40533"
"44791","268.70999","22.39268","0.40815"
"44856","269.10001","22.42514","0.41164"
"44921","269.48999","22.45767","0.41406"
"44986","269.88000","22.49019","0.41779"
"45051","270.26999","22.52266","0.42159"
"45116","270.66000","22.55512","0.42586"
"45181","271.04999","22.58765","0.42938"
"45246","271.44000","22.62017","0.43313"
"45311","271.82999","22.65270","0.43737"
"45376","272.22000","22.68517","0.43979"
"45441","272.60999","22.71769","0.44108"
"45506","273.00000","22.75016","0.44373"
"45571","273.39001","22.78262","0.44533"
"45636","273.78000","22.81515","0.44724"
"45701","274.17001","22.84767","0.44905"
"45766","274.56000","22.88020","0.44384"
"45831","274.95001","22.91261","0.44641"
"45896","275.34000","22.94519","0.44877"
"45961","275.73001","22.97766","0.45071"
"46026","276.12000","23.01018","0.45236"
"46091","276.51001","23.04264","0.45286"
"46156","276.89999","23.07517","0.45447"
"46221","277.29001","23.10776","0.45645"
"46286","277.67999","23.14016","0.45796"
"46351","278.07001","23.17263","0.45983"
"46416","278.45999","23.20522","0.46305"
"46481","278.85001","23.23768","0.46405"
"46546","279.23999","23.27015","0.46658"
"46611","279.63000","23.30267","0.46910"
"46676","280.01999","23.33514","0.47126"
"46741","280.41000","23.36766","0.47389"
"46806","280.79999","23.40019","0.47707"
"46871","281.19000","23.43266","0.48073"
"46936","281.57999","23.46518","0.48397"
"47001","281.97000","23.49771","0.48651"
"47066","282.35999","23.53017","0.48985"
"47131","282.75000","23.56270","0.49149"
"47196","283.14001","23.59516","0.49507"
"47261","283.53000","23.62763","0.49721"
"47326","283.92001","23.66015","0.50041"
"47391","284.31000","23.69268","0.50484"
"47456","284.70001","23.72520","0.50740"
"47521","285.09000","23.75767","0.51088"
"47586","285.48001","23.79020","0.51336"
"47651","285.87000","23.82272","0.51551"
"47716","286.26001","23.85513","0.51807"
"47781","286.64999","23.88765","0.52071"
"47846","287.04001","23.92018","0.52420"
"47911","287.42999","23.95270","0.52725"
"47976","287.82001","23.98511","0.52996"
"48041","288.20999","24.01769","0.53291"
"48106","288.60001","24.05016","0.53461"
"48171","288.98999","24.08269","0.53702"
"48236","289.38000","24.11515","0.53885"
"48301","289.76999","24.14774","0.53986"
"48366","290.16000","24.18020","0.54190"
"48431","290.54999","24.21267","0.54363"
"48496","290.94000","24.24514","0.54520"
"48561","291.32999","24.27766","0.54688"
"48626","291.72000","24.31018","0.54871"
"48691","292.10999","24.34265","0.55021"
"48756","292.50000","24.37518","0.55253"
"48821","292.89001","24.40770","0.55444"
"48886","293.28000","24.44017","0.55611"
"48951","293.67001","24.47263","0.55747"
"49016","294.06000","24.50516","0.55960"
"49081","294.45001","24.53768","0.56120"
"49146","294.84000","24.57015","0.56434"
"49211","295.23001","24.60267","0.56674"
"49276","295.62000","24.63520","0.56931"
"49341","296.01001","24.66767","0.57111"
"49406","296.39999","24.70013","0.57215"
"49471","296.79001","24.73272","0.57409"
"49536","297.17999","24.76518","0.57813"
"49601","297.57001","24.79759","0.58189"
"49666","297.95999","24.83018","0.58541"
"49731","298.35001","24.86270","0.58888"
"49796","298.73999","24.89516","0.59157"
"49861","299.13000","24.92763","0.59449"
"49926","299.51999","24.96016","0.59642"
"49991","299.91000","24.99274","0.60164"
"50056","300.29999","25.02515","0.60463"
"50121","300.69000","25.05762","0.60840"
"50186","301.07999","25.09020","0.61176"
"50251","301.47000","25.12272","0.61434"
"50316","301.85999","25.15507","0.61744"
"50381","302.25000","25.18772","0.62013"
"50446","302.64001","25.22024","0.62286"
"50511","303.03000","25.25265","0.62603"
"50576","303.42001","25.28517","0.62960"
"50641","303.81000","25.31770","0.63272"
"50706","304.20001","25.35022","0.63561"
"50771","304.59000","25.38263","0.63882"
"50836","304.98001","25.41516","0.64216"
"50901","305.37000","25.44774","0.64569"
"50966","305.76001","25.48015","0.64766"
"51031","306.14999","25.51255","0.64995"
"51096","306.54001","25.54520","0.65198"
"51161","306.92999","25.57766","0.65396"
"51226","307.32001","25.61013","0.65554"
"51291","307.70999","25.64265","0.65711"
"51356","308.10001","25.67518","0.65829"
"51421","308.48999","25.70765","0.65994"
"51486","308.88000","25.74011","0.66219"
"51551","309.26999","25.77264","0.66394"
"51616","309.66000","25.80522","0.66593"
"51681","310.04999","25.83769","0.66813"
"51746","310.44000","25.87016","0.66757"
"51811","310.82999","25.90268","0.65313"
"51876","311.22000","25.93521","0.65543"
"51941","311.60999","25.96761","0.65739"
"52006","312.00000","26.00014","0.65913"
"52071","312.39001","26.03272","0.66052"
"52136","312.78000","26.06519","0.65900"
"52201","313.17001","26.09759","0.66023"
"52266","313.56000","26.13018","0.66236"
"52331","313.95001","26.16270","0.66439"
"52396","314.34000","26.19517","0.66509"
"52461","314.73001","26.22764","0.66726"
"52526","315.12000","26.26016","0.66956"
"52591","315.51001","26.29269","0.67108"
"52656","315.89999","26.32515","0.67361"
"52721","316.29001","26.35768","0.67672"
"52786","316.67999","26.39020","0.68024"
"52851","317.07001","26.42267","0.67964"
"52916","317.45999","26.45513","0.68088"
"52981","317.85001","26.48772","0.63798"
"53046","318.23999","26.52019","0.60380"
"53111","318.63000","26.55271","0.60732"
"53176","319.01999","26.58512","0.60945"
"53241","319.41000","26.61770","0.61504"
"53306","319.79999","26.65017","0.61952"
"53371","320.19000","26.68263","0.62467"
"53436","320.57999","26.71522","0.63106"
"53501","320.97000","26.74769","0.63790"
"53566","321.35999","26.78021","0.64379"
"53631","321.75000","26.81262","0.64811"
"53696","322.14001","26.84520","0.65194"
"53761","322.53000","26.87767","0.65344"
"53826","322.92001","26.91019","0.65585"
"53891","323.31000","26.94266","0.65528"
"53956","323.70001","26.97524","0.62688"
"54021","324.09000","27.00771","0.63107"
"54086","324.48001","27.04012","0.63762"
"54151","324.87000","27.07270","0.64182"
"54216","325.26001","27.10517","0.64566"
"54281","325.64999","27.13769","0.64966"
"54346","326.04001","27.17016","0.65191"
"54411","326.42999","27.20268","0.65469"
"54476","326.82001","27.23515","0.65643"
"54541","327.20999","27.26767","0.65889"
"54606","327.60001","27.30014","0.66045"
"54671","327.98999","27.33273","0.66264"
"54736","328.38000","27.36519","0.66500"
"54801","328.76999","27.39760","0.66689"
"54866","329.16000","27.43018","0.66968"
"54931","329.54999","27.46265","0.67137"
"54996","329.94000","27.49511","0.67558"
"55061","330.32999","27.52764","0.66615"
"55126","330.72000","27.56016","0.66804"
"55191","331.10999","27.59269","0.67024"
"55256","331.50000","27.62515","0.67221"
"55321","331.89001","27.65762","0.67569"
"55386","332.28000","27.69021","0.67736"
"55451","332.67001","27.72267","0.68040"
"55516","333.06000","27.75520","0.68387"
"55581","333.45001","27.78766","0.68672"
"55646","333.84000","27.82019","0.69016"
"55711","334.23001","27.85265","0.69294"
"55776","334.62000","27.88518","0.69603"
"55841","335.01001","27.91765","0.69878"
"55906","335.39999","27.95023","0.70113"
"55971","335.79001","27.98264","0.70440"
"56036","336.17999","28.01516","0.70566"
"56101","336.57001","28.04769","0.70748"
"56166","336.95999","28.08021","0.70964"
"56231","337.35001","28.11262","0.71288"
"56296","337.73999","28.14515","0.71580"
"56361","338.13000","28.17767","0.71782"
"56426","338.51999","28.21020","0.72043"
"56491","338.91000","28.24266","0.72259"
"56556","339.29999","28.27519","0.72557"
"56621","339.69000","28.30772","0.72783"
"56686","340.07999","28.34012","0.72960"
"56751","340.47000","28.37265","0.73160"
"56816","340.85999","28.40517","0.73390"
"56881","341.25000","28.43769","0.72362"
"56946","341.64001","28.47016","0.72131"
"57011","342.03000","28.50263","0.72295"
"57076","342.42001","28.53521","0.72604"
"57141","342.81000","28.56768","0.72899"
"57206","343.20001","28.60014","0.73288"
"57271","343.59000","28.63273","0.73627"
"57336","343.98001","28.66520","0.61223"
"57401","344.37000","28.69760","0.56948"
"57466","344.76001","28.73013","0.56966"
"57531","345.14999","28.76265","0.57132"
"57596","345.54001","28.79518","0.57824"
"57661","345.92999","28.82764","0.58188"
"57726","346.32001","28.86017","0.58776"
"57791","346.70999","28.89270","0.59128"
"57856","347.10001","28.92516","0.59680"
"57921","347.48999","28.95763","0.59997"
"57986","347.88000","28.99015","0.60363"
"58051","348.26999","29.02268","0.60618"
"58116","348.66000","29.05514","0.60995"
"58181","349.04999","29.08767","0.61341"
"58246","349.44000","29.12019","0.61715"
"58311","349.82999","29.15266","0.61947"
"58376","350.22000","29.18513","0.62185"
"58441","350.60999","29.21771","0.62426"
"58506","351.00000","29.25018","0.62663"
"58571","351.39001","29.28264","0.62748"
"58636","351.78000","29.31511","0.63057"
"58701","352.17001","29.34763","0.63173"
"58766","352.56000","29.38022","0.63341"
"58831","352.95001","29.41262","0.63509"
"58896","353.34000","29.44515","0.63698"
"58961","353.73001","29.47774","0.63797"
"59026","354.12000","29.51014","0.63963"
"59091","354.51001","29.54261","0.64155"
"59156","354.89999","29.57519","0.64177"
"59221","355.29001","29.60766","0.64327"
"59286","355.67999","29.64012","0.64406"
"59351","356.07001","29.67265","0.64491"
"59416","356.45999","29.70518","0.64583"
"59481","356.85001","29.73770","0.64752"
"59546","357.23999","29.77017","0.64795"
"59611","357.63000","29.80269","0.64918"
"59676","358.01999","29.83522","0.65004"
"59741","358.41000","29.86762","0.65137"
"59806","358.79999","29.90021","0.65230"
"59871","359.19000","29.93274","0.65377"
"59936","359.57999","29.96520","0.65430"
"60001","359.97000","29.99760","0.65547"
"60066","360.35999","30.03019","0.65602"
"60131","360.75000","30.06265","0.65653"
"60196","361.14001","30.09518","0.65727"
"60261","361.53000","30.12765","0.65812"
"60326","361.92001","30.16017","0.65856"
"60391","362.31000","30.19276","0.65935"
"60456","362.70001","30.22511","0.65976"
"60521","363.09000","30.25769","0.66104"
"60586","363.48001","30.29028","0.66170"
"60651","363.87000","30.32268","0.66240"
"60716","364.26001","30.35515","0.66387"
"60781","364.64999","30.38767","0.66482"
"60846","365.04001","30.42020","0.66596"
"60911","365.42999","30.45261","0.66681"
"60976","365.82001","30.48513","0.66790"
"61041","366.20999","30.51772","0.66920"
"61106","366.60001","30.55018","0.67046"
"61171","366.98999","30.58258","0.67170"
"61236","367.38000","30.61517","0.67263"
"61301","367.76999","30.64770","0.67461"
"61366","368.16000","30.68016","0.67697"
"61431","368.54999","30.71263","0.67896"
"61496","368.94000","30.74521","0.68039"
"61561","369.32999","30.77768","0.68254"
"61626","369.72000","30.81014","0.68409"
"61691","370.10999","30.84261","0.68673"
"61756","370.50000","30.87520","0.68881"
"61821","370.89001","30.90772","0.69011"
"61886","371.28000","30.94007","0.69135"
"61951","371.67001","30.97271","0.69290"
"62016","372.06000","31.00524","0.69464"
"62081","372.45001","31.03765","0.69647"
"62146","372.84000","31.07017","0.69835"
"62211","373.23001","31.10270","0.69979"
"62276","373.62000","31.13522","0.70175"
"62341","374.01001","31.16763","0.70356"
"62406","374.39999","31.20021","0.70516"
"62471","374.79001","31.23274","0.70701"
"62536","375.17999","31.26514","0.70974"
"62601","375.57001","31.29761","0.71188"
"62666","375.95999","31.33019","0.71411"
"62731","376.35001","31.36272","0.71580"
"62796","376.73999","31.39513","0.71731"
"62861","377.13000","31.42765","0.71807"
"62926","377.51999","31.46024","0.71992"
"62991","377.91000","31.49264","0.72215"
"63056","378.29999","31.52517","0.72398"
"63121","378.69000","31.55769","0.72659"
"63186","379.07999","31.59016","0.72833"
"63251","379.47000","31.62268","0.60011"
"63316","379.85999","31.65515","0.57652"
"63381","380.25000","31.68773","0.57913"
"63446","380.64001","31.72020","0.58942"
"63511","381.03000","31.75266","0.58466"
"63576","381.42001","31.78513","0.58856"
"63641","381.81000","31.81771","0.59685"
"63706","382.20001","31.85024","0.56690"
"63771","382.59000","31.88265","0.57696"
"63836","382.98001","31.91523","0.57698"
"63901","383.37000","31.94764","0.51454"
"63966","383.76001","31.98022","0.52857"
"64031","384.14999","32.01269","0.52123"
"64096","384.54001","32.04515","0.53545"
"64161","384.92999","32.07768","0.53592"
"64226","385.32001","32.11015","0.53767"
"64291","385.70999","32.14267","0.54488"
"64356","386.10001","32.17514","0.54296"
"64421","386.48999","32.20766","0.54832"
"64486","386.88000","32.24013","0.54892"
"64551","387.26999","32.27272","0.55065"
"64616","387.66000","32.30518","0.55393"
"64681","388.04999","32.33765","0.55294"
"64746","388.44000","32.37017","0.55776"
"64811","388.82999","32.40270","0.55699"
"64876","389.22000","32.43522","0.56169"
"64941","389.60999","32.46769","0.56235"
"65006","390.00000","32.50016","0.56457"
"65071","390.39001","32.53268","0.57051"
"65136","390.78000","32.56520","0.56891"
"65201","391.17001","32.59767","0.57636"
"65266","391.56000","32.63020","0.57514"
"65331","391.95001","32.66266","0.58113"
"65396","392.34000","32.69513","0.58277"
"65461","392.73001","32.72765","0.58563"
"65526","393.12000","32.76018","0.58881"
"65591","393.51001","32.79271","0.58953"
"65656","393.89999","32.82517","0.59348"
"65721","394.29001","32.85764","0.59326"
"65786","394.67999","32.89022","0.59683"
"65851","395.07001","32.92263","0.59589"
"65916","395.45999","32.95515","0.59957"
"65981","395.85001","32.98768","0.59978"
"66046","396.23999","33.02021","0.60218"
"66111","396.63000","33.05267","0.60366"
"66176","397.01999","33.08519","0.60362"
"66241","397.41000","33.11772","0.60477"
"66306","397.79999","33.15025","0.60511"
"66371","398.19000","33.18265","0.60755"
"66436","398.57999","33.21518","0.60814"
"66501","398.97000","33.24770","0.61051"
"66566","399.35999","33.28023","0.61161"
"66631","399.75000","33.31263","0.61344"
"66696","400.14001","33.34522","0.61451"
"66761","400.53000","33.37769","0.61673"
"66826","400.92001","33.41021","0.61776"
"66891","401.31000","33.44268","0.61967"
"66956","401.70001","33.47520","0.62150"
"67021","402.09000","33.50767","0.62380"
"67086","402.48001","33.54013","0.62554"
"67151","402.87000","33.57266","0.62693"
"67216","403.26001","33.60513","0.62944"
"67281","403.64999","33.63765","0.63068"
"67346","404.04001","33.67012","0.63302"
"67411","404.42999","33.70270","0.63473"
"67476","404.82001","33.73523","0.63707"
"67541","405.20999","33.76763","0.63795"
"67606","405.60001","33.80016","0.64107"
"67671","405.98999","33.83268","0.64184"
"67736","406.38000","33.86521","0.64404"
"67801","406.76999","33.89762","0.64471"
"67866","407.16000","33.93020","0.64596"
"67931","407.54999","33.96267","0.64708"
"67996","407.94000","33.99513","0.64887"
"68061","408.32999","34.02766","0.64948"
"68126","408.72000","34.06018","0.65119"
"68191","409.10999","34.09271","0.65208"
"68256","409.50000","34.12511","0.65173"
"68321","409.89001","34.15770","0.65208"
"68386","410.28000","34.19023","0.65304"
"68451","410.67001","34.22269","0.65330"
"68516","411.06000","34.25510","0.65414"
"68581","411.45001","34.28769","0.65463"
"68646","411.84000","34.32015","0.65531"
"68711","412.23001","34.35268","0.65573"
"68776","412.62000","34.38514","0.65677"
"68841","413.01001","34.41772","0.65691"
"68906","413.39999","34.45025","0.65747"
"68971","413.79001","34.48260","0.65799"
"69036","414.17999","34.51518","0.65913"
"69101","414.57001","34.54771","0.65923"
"69166","414.95999","34.58017","0.35724"
"69231","415.35001","34.61264","0.35728"
"69296","415.73999","34.64516","0.36351"
"69361","416.13000","34.67769","0.37104"
"69426","416.51999","34.71016","0.38938"
"69491","416.91000","34.74268","0.40476"
"69556","417.29999","34.77520","0.40157"
"69621","417.69000","34.80767","0.39313"
"69686","418.07999","34.84008","0.38768"
"69751","418.47000","34.87266","0.38851"
"69816","418.85999","34.90519","0.39149"
"69881","419.25000","34.93765","0.39788"
"69946","419.64001","34.97018","0.41028"
"70011","420.03000","35.00270","0.42810"
"70076","420.42001","35.03523","0.43069"
"70141","420.81000","35.06764","0.41519"
"70206","421.20001","35.10016","0.40937"
"70271","421.59000","35.13269","0.40856"
"70336","421.98001","35.16521","0.41200"
"70401","422.37000","35.19762","0.42024"
"70466","422.76001","35.23021","0.43392"
"70531","423.14999","35.26273","0.43774"
"70596","423.54001","35.29514","0.42926"
"70661","423.92999","35.32760","0.41885"
"70726","424.32001","35.36019","0.41762"
"70791","424.70999","35.39265","0.42032"
"70856","425.10001","35.42512","0.42880"
"70921","425.48999","35.45770","0.43892"
"70986","425.88000","35.49023","0.44285"
"71051","426.26999","35.52264","0.43872"
"71116","426.66000","35.55510","0.43205"
"71181","427.04999","35.58769","0.43084"
"71246","427.44000","35.62021","0.43396"
"71311","427.82999","35.65262","0.44113"
"71376","428.22000","35.68520","0.44699"
"71441","428.60999","35.71767","0.44816"
"71506","429.00000","35.75019","0.44445"
"71571","429.39001","35.78266","0.44146"
"71636","429.78000","35.81519","0.44177"
"71701","430.17001","35.84765","0.44580"
"71766","430.56000","35.88018","0.44998"
"71831","430.95001","35.91264","0.45282"
"71896","431.34000","35.94523","0.45027"
"71961","431.73001","35.97770","0.44863"
"72026","432.12000","36.01010","0.44850"
"72091","432.51001","36.04269","0.45705"
"72156","432.89999","36.07521","0.45551"
"72221","433.29001","36.10768","0.44663"
"72286","433.67999","36.14014","0.44306"
"72351","434.07001","36.17273","0.44385"
"72416","434.45999","36.20513","0.45048"
"72481","434.85001","36.23766","0.45328"
"72546","435.23999","36.27018","0.45290"
"72611","435.63000","36.30271","0.45458"
"72676","436.01999","36.33523","0.45162"
"72741","436.41000","36.36764","0.45319"
"72806","436.79999","36.40017","0.45415"
"72871","437.19000","36.43263","0.45631"
"72936","437.57999","36.46510","0.45689"
"73001","437.97000","36.49768","0.45819"
"73066","438.35999","36.53027","0.45732"
"73131","438.75000","36.56268","0.45925"
"73196","439.14001","36.59514","0.45966"
"73261","439.53000","36.62767","0.46261"
"73326","439.92001","36.66019","0.46303"
"73391","440.31000","36.69271","0.46357"
"73456","440.70001","36.72512","0.46357"
"73521","441.09000","36.75771","0.46425"
"73586","441.48001","36.79017","0.46601"
"73651","441.87000","36.82264","0.46700"
"73716","442.26001","36.85516","0.46832"
"73781","442.64999","36.88769","0.46796"
"73846","443.04001","36.92015","0.46865"
"73911","443.42999","36.95268","0.46960"
"73976","443.82001","36.98515","0.47184"
"74041","444.20999","37.01767","0.47329"
"74106","444.60001","37.05020","0.47432"
"74171","444.98999","37.08266","0.47435"
"74236","445.38000","37.11519","0.47517"
"74301","445.76999","37.14766","0.47729"
"74366","446.16000","37.18018","0.47981"
"74431","446.54999","37.21271","0.47997"
"74496","446.94000","37.24517","0.48060"
"74561","447.32999","37.27770","0.48161"
"74626","447.72000","37.31017","0.48256"
"74691","448.10999","37.34269","0.48510"
"74756","448.50000","37.37521","0.48563"
"74821","448.89001","37.40768","0.48607"
"74886","449.28000","37.44015","0.48671"
"74951","449.67001","37.47267","0.48780"
"75016","450.06000","37.50520","0.48938"
"75081","450.45001","37.53766","0.49051"
"75146","450.84000","37.57019","0.49163"
"75211","451.23001","37.60271","0.49221"
"75276","451.62000","37.63518","0.49382"
"75341","452.01001","37.66765","0.49591"
"75406","452.39999","37.70017","0.49710"
"75471","452.79001","37.73270","0.49817"
"75536","453.17999","37.76516","0.49746"
"75601","453.57001","37.79763","0.49922"
"75666","453.95999","37.83015","0.50010"
"75731","454.35001","37.86268","0.50046"
"75796","454.73999","37.89520","0.49862"
"75861","455.13000","37.92767","0.49378"
"75926","455.51999","37.96019","-0.01793"
"75991","455.91000","37.99272","-0.03329"
"76056","456.29999","38.02513","-0.02618"
"76121","456.69000","38.05765","-0.02146"
"76186","457.07999","38.09018","-0.02936"
"76251","457.47000","38.12270","-0.02664"
"76316","457.85999","38.15511","-0.02311"
"76381","458.25000","38.18769","-0.02531"
"76446","458.64001","38.22028","-0.02583"
"76511","459.03000","38.25269","-0.02328"
"76576","459.42001","38.28515","-0.02515"
"76641","459.81000","38.31768","-0.02562"
"76706","460.20001","38.35020","-0.02442"
"76771","460.59000","38.38261","-0.02317"
"76836","460.98001","38.41519","-0.02472"
"76901","461.37000","38.44772","-0.02511"
"76966","461.76199","38.48036","-0.02367"
"77031","462.15201","38.51277","-0.02337"
"77096","462.54199","38.54536","-0.02418"
"77161","462.93201","38.57788","-0.02432"
"77226","463.32199","38.61035","-0.02338"
"77291","463.71201","38.64281","-0.02309"
"77356","464.10199","38.67534","-0.02384"
"77421","464.49200","38.70786","-0.02378"
"77486","464.88199","38.74027","-0.02317"
"77551","465.27200","38.77285","-0.02290"
"77616","465.66199","38.80538","-0.02366"
"77681","466.05200","38.83784","-0.02318"
"77746","466.44199","38.87025","-0.02258"
"77811","466.83200","38.90284","-0.02284"
"77876","467.22198","38.93536","-0.02285"
"77941","467.61200","38.96777","-0.02323"
"78006","468.00201","39.00029","-0.02270"
"78071","468.39200","39.03282","-0.02234"
"78136","468.78201","39.06535","-0.02256"
"78201","469.17200","39.09781","-0.02288"
"78266","469.56201","39.13034","-0.02204"
"78331","469.95200","39.16286","-0.02207"
"78396","470.34201","39.19527","-0.02206"
"78461","470.73199","39.22785","-0.02209"
"78526","471.12201","39.26044","-0.02175"
"78591","471.51199","39.29290","-0.02276"
"78656","471.90201","39.32525","-0.02152"
"78721","472.29199","39.35784","-0.02219"
"78786","472.68201","39.39036","-0.02170"
"78851","473.07199","39.42283","-0.02207"
"78916","473.46201","39.45529","-0.02207"
"78981","473.85199","39.48788","-0.02196"
"79046","474.24200","39.52040","-0.02140"
"79111","474.63199","39.55281","-0.02182"
"79176","475.02200","39.58527","-0.02143"
"79241","475.41199","39.61786","-0.02166"
"79306","475.80200","39.65032","-0.02143"
"79371","476.19199","39.68279","-0.02158"
"79397","476.34399","39.69552","-0.02148"