File: Trajectories_together/170107_1Specimen_RawData_9.csv
"","V1","V2","V3"
"1","End date","1/7/2017",""
"2","Specimen label","18AT_41",""
"3","Maximum Load","0.04672","N"
"4","Time","Extension","Load"
"5","(s)","(mm)","(N)"
"6","0.00000","0.00000","-0.00032"
"75","0.41400","0.03468","0.00441"
"144","0.82800","0.06912","0.00652"
"213","1.24200","0.10373","0.00761"
"282","1.65600","0.13817","0.00909"
"351","2.07000","0.17267","0.00916"
"420","2.48400","0.20717","0.00981"
"489","2.89800","0.24173","0.00982"
"558","3.31200","0.27623","0.01026"
"627","3.72600","0.31067","0.01029"
"696","4.14000","0.34516","0.01111"
"765","4.55400","0.37966","0.01079"
"834","4.96800","0.41422","0.01073"
"903","5.38200","0.44872","0.01103"
"972","5.79600","0.48316","0.01129"
"1041","6.21000","0.51766","0.01160"
"1110","6.62400","0.55222","0.01130"
"1179","7.03800","0.58665","0.01128"
"1248","7.45200","0.62121","0.01111"
"1317","7.86600","0.65559","0.01131"
"1386","8.28000","0.69021","0.01138"
"1455","8.69400","0.72471","0.01168"
"1524","9.10800","0.75921","0.01157"
"1593","9.52200","0.79359","0.01189"
"1662","9.93600","0.82820","0.01165"
"1731","10.35000","0.86276","0.01172"
"1800","10.76400","0.89720","0.01174"
"1869","11.17800","0.93164","0.01142"
"1938","11.59200","0.96614","0.01137"
"2007","12.00600","1.00070","0.01153"
"2076","12.42000","1.03520","0.01146"
"2145","12.83400","1.06969","0.01171"
"2214","13.24800","1.10407","0.01168"
"2283","13.66200","1.13863","0.01184"
"2352","14.07600","1.17319","0.01237"
"2421","14.49000","1.20775","0.01184"
"2490","14.90400","1.24219","0.01197"
"2559","15.31800","1.27669","0.01197"
"2628","15.73200","1.31124","0.01174"
"2697","16.14600","1.34568","0.01168"
"2766","16.56000","1.38012","0.01207"
"2835","16.97400","1.41462","0.01137"
"2904","17.38800","1.44918","0.01185"
"2973","17.80200","1.48368","0.01124"
"3042","18.21600","1.51818","0.01208"
"3111","18.63000","1.55267","0.01185"
"3180","19.04400","1.58717","0.01152"
"3249","19.45800","1.62173","0.01155"
"3318","19.87200","1.65617","0.01162"
"3387","20.28600","1.69061","0.01211"
"3456","20.70000","1.72517","0.01239"
"3525","21.11400","1.75967","0.01240"
"3594","21.52800","1.79422","0.01206"
"3663","21.94200","1.82866","0.01207"
"3732","22.35600","1.86316","0.01178"
"3801","22.77000","1.89772","0.01228"
"3870","23.18400","1.93216","0.01209"
"3939","23.59800","1.96672","0.01162"
"4008","24.01200","2.00110","0.01205"
"4077","24.42600","2.03565","0.01268"
"4146","24.84000","2.07021","0.01239"
"4215","25.25400","2.10471","0.01220"
"4284","25.66800","2.13915","0.01226"
"4353","26.08200","2.17365","0.01252"
"4422","26.49600","2.20821","0.01266"
"4491","26.91000","2.24271","0.01230"
"4560","27.32400","2.27714","0.01217"
"4629","27.73800","2.31164","0.01281"
"4698","28.15200","2.34620","0.01225"
"4767","28.56600","2.38070","0.01334"
"4836","28.98000","2.41520","0.01300"
"4905","29.39400","2.44964","0.01239"
"4974","29.80800","2.48420","0.01239"
"5043","30.22200","2.51869","0.01311"
"5112","30.63600","2.55319","0.01272"
"5181","31.05000","2.58763","0.01305"
"5250","31.46400","2.62213","0.01351"
"5319","31.87800","2.65669","0.01260"
"5388","32.29200","2.69119","0.01333"
"5457","32.70600","2.72569","0.01344"
"5526","33.12000","2.76018","0.01379"
"5595","33.53400","2.79468","0.01372"
"5664","33.94800","2.82924","0.01407"
"5733","34.36200","2.86368","0.01374"
"5802","34.77600","2.89812","0.01441"
"5871","35.19000","2.93268","0.01398"
"5940","35.60400","2.96724","0.01358"
"6009","36.01800","3.00167","0.01422"
"6078","36.43200","3.03617","0.01402"
"6147","36.84600","3.07067","0.01434"
"6216","37.26000","3.10523","0.01404"
"6285","37.67400","3.13973","0.01403"
"6354","38.08800","3.17417","0.01476"
"6423","38.50200","3.20866","0.01463"
"6492","38.91600","3.24322","0.01459"
"6561","39.33000","3.27766","0.01478"
"6630","39.74400","3.31216","0.01518"
"6699","40.15800","3.34666","0.01498"
"6768","40.57200","3.38122","0.01457"
"6837","40.98600","3.41572","0.01498"
"6906","41.40000","3.45021","0.01451"
"6975","41.81400","3.48465","0.01458"
"7044","42.22800","3.51915","0.01446"
"7113","42.64200","3.55371","0.01498"
"7182","43.05600","3.58821","0.01494"
"7251","43.47000","3.62265","0.01505"
"7320","43.88400","3.65709","0.01535"
"7389","44.29800","3.69170","0.01505"
"7458","44.71200","3.72620","0.01499"
"7527","45.12600","3.76070","0.01509"
"7596","45.54000","3.79508","0.01536"
"7665","45.95400","3.82970","0.01514"
"7734","46.36800","3.86420","0.01484"
"7803","46.78200","3.89870","0.01495"
"7872","47.19600","3.93314","0.01464"
"7941","47.61000","3.96763","0.01545"
"8010","48.02400","4.00219","0.01566"
"8079","48.43800","4.03669","0.01547"
"8148","48.85200","4.07119","0.01481"
"8217","49.26600","4.10563","0.01511"
"8286","49.68000","4.14013","0.01515"
"8355","50.09400","4.17468","0.01546"
"8424","50.50800","4.20924","0.01546"
"8493","50.92200","4.24362","0.01521"
"8562","51.33600","4.27818","0.01538"
"8631","51.75000","4.31274","0.01504"
"8700","52.16400","4.34718","0.01493"
"8769","52.57800","4.38162","0.01467"
"8838","52.99200","4.41611","0.01548"
"8907","53.40600","4.45073","0.01508"
"8976","53.82000","4.48517","0.01520"
"9045","54.23400","4.51967","0.01488"
"9114","54.64800","4.55417","0.01543"
"9183","55.06200","4.58873","0.01500"
"9252","55.47600","4.62323","0.01537"
"9321","55.89000","4.65766","0.01524"
"9390","56.30400","4.69210","0.01463"
"9459","56.71800","4.72660","0.01484"
"9528","57.13200","4.76116","0.01544"
"9597","57.54600","4.79572","0.01479"
"9666","57.96000","4.83022","0.01524"
"9735","58.37400","4.86466","0.01485"
"9804","58.78800","4.89927","0.01467"
"9873","59.20200","4.93371","0.01555"
"9942","59.61600","4.96815","0.01500"
"10011","60.03000","5.00265","0.01455"
"10080","60.44400","5.03715","0.01442"
"10149","60.85800","5.07171","0.01513"
"10218","61.27200","5.10620","0.01449"
"10287","61.68600","5.14064","0.01524"
"10356","62.10000","5.17520","0.01504"
"10425","62.51400","5.20970","0.01489"
"10494","62.92800","5.24420","0.01527"
"10563","63.34200","5.27864","0.01490"
"10632","63.75600","5.31320","0.01475"
"10701","64.17000","5.34770","0.01506"
"10770","64.58400","5.38219","0.01520"
"10839","64.99800","5.41663","0.01530"
"10908","65.41200","5.45113","0.01420"
"10977","65.82600","5.48569","0.01489"
"11046","66.24000","5.52019","0.01490"
"11115","66.65400","5.55475","0.01511"
"11184","67.06800","5.58913","0.01491"
"11253","67.48200","5.62362","0.01512"
"11322","67.89600","5.65818","0.01498"
"11391","68.31000","5.69274","0.01499"
"11460","68.72400","5.72718","0.01527"
"11529","69.13800","5.76162","0.01550"
"11598","69.55200","5.79624","0.01502"
"11667","69.96600","5.83074","0.01523"
"11736","70.38000","5.86517","0.01518"
"11805","70.79400","5.89967","0.01539"
"11874","71.20800","5.93423","0.01534"
"11943","71.62200","5.96867","0.01530"
"12012","72.03600","6.00323","0.01538"
"12081","72.45000","6.03761","0.01540"
"12150","72.86400","6.07223","0.01482"
"12219","73.27800","6.10672","0.01486"
"12288","73.69200","6.14122","0.01542"
"12357","74.10600","6.17566","0.01542"
"12426","74.52000","6.21016","0.01555"
"12495","74.93400","6.24472","0.01514"
"12564","75.34800","6.27922","0.01490"
"12633","75.76200","6.31365","0.01499"
"12702","76.17600","6.34815","0.01535"
"12771","76.59000","6.38271","0.01520"
"12840","77.00400","6.41721","0.01488"
"12909","77.41800","6.45165","0.01502"
"12978","77.83200","6.48609","0.01496"
"13047","78.24600","6.52065","0.01507"
"13116","78.66000","6.55520","0.01482"
"13185","79.07400","6.58970","0.01526"
"13254","79.48800","6.62420","0.01509"
"13323","79.90200","6.65864","0.01553"
"13392","80.31600","6.69320","0.01538"
"13461","80.73000","6.72770","0.01536"
"13530","81.14400","6.76220","0.01556"
"13599","81.55800","6.79663","0.01524"
"13668","81.97200","6.83113","0.01549"
"13737","82.38600","6.86569","0.01546"
"13806","82.80000","6.90019","0.01559"
"13875","83.21400","6.93463","0.01571"
"13944","83.62800","6.96919","0.01542"
"14013","84.04200","7.00369","0.01609"
"14082","84.45600","7.03818","0.01538"
"14151","84.87000","7.07262","0.01569"
"14220","85.28400","7.10712","0.01564"
"14289","85.69800","7.14168","0.01567"
"14358","86.11200","7.17618","0.01569"
"14427","86.52600","7.21062","0.01482"
"14496","86.94000","7.24518","0.01541"
"14565","87.35400","7.27973","0.01521"
"14634","87.76800","7.31423","0.01541"
"14703","88.18200","7.34867","0.01528"
"14772","88.59600","7.38311","0.01540"
"14841","89.01000","7.41767","0.01516"
"14910","89.42400","7.45217","0.01511"
"14979","89.83800","7.48667","0.01568"
"15048","90.25200","7.52116","0.01542"
"15117","90.66600","7.55566","0.01541"
"15186","91.08000","7.59016","0.01518"
"15255","91.49400","7.62466","0.01495"
"15324","91.90800","7.65922","0.01462"
"15393","92.32200","7.69366","0.01553"
"15462","92.73600","7.72816","0.01549"
"15531","93.15000","7.76271","0.01569"
"15600","93.56400","7.79721","0.01539"
"15669","93.97800","7.83159","0.01510"
"15738","94.39200","7.86621","0.01498"
"15807","94.80600","7.90077","0.01565"
"15876","95.22000","7.93521","0.01580"
"15945","95.63400","7.96965","0.01527"
"16014","96.04800","8.00414","0.01534"
"16083","96.46200","8.03870","0.01532"
"16152","96.87600","8.07320","0.01588"
"16221","97.29000","8.10764","0.01533"
"16290","97.70400","8.14214","0.01627"
"16359","98.11800","8.17670","0.01558"
"16428","98.53200","8.21119","0.01557"
"16497","98.94600","8.24569","0.01570"
"16566","99.36000","8.28013","0.01590"
"16635","99.77400","8.31463","0.01552"
"16704","100.18800","8.34919","0.01583"
"16773","100.60200","8.38369","0.01524"
"16842","101.01600","8.41819","0.01642"
"16911","101.43000","8.45263","0.01546"
"16980","101.84400","8.48724","0.01561"
"17049","102.25800","8.52174","0.01586"
"17118","102.67200","8.55618","0.01567"
"17187","103.08600","8.59062","0.01534"
"17256","103.50000","8.62518","0.01606"
"17325","103.91400","8.65968","0.01567"
"17394","104.32800","8.69418","0.01588"
"17463","104.74200","8.72867","0.01611"
"17532","105.15600","8.76323","0.01562"
"17601","105.57000","8.79773","0.01564"
"17670","105.98400","8.83223","0.01572"
"17739","106.39800","8.86667","0.01611"
"17808","106.81200","8.90117","0.01544"
"17877","107.22600","8.93573","0.01582"
"17946","107.64000","8.97022","0.01602"
"18015","108.05400","9.00460","0.01624"
"18084","108.46800","9.03916","0.01594"
"18153","108.88200","9.07366","0.01630"
"18222","109.29600","9.10822","0.01613"
"18291","109.71000","9.14272","0.01628"
"18360","110.12400","9.17710","0.01580"
"18429","110.53800","9.21165","0.01605"
"18498","110.95200","9.24621","0.01634"
"18567","111.36600","9.28071","0.01662"
"18636","111.78000","9.31515","0.01693"
"18705","112.19400","9.34959","0.01634"
"18774","112.60800","9.38421","0.01625"
"18843","113.02200","9.41870","0.01649"
"18912","113.43600","9.45320","0.01594"
"18981","113.85000","9.48764","0.01657"
"19050","114.26400","9.52220","0.01664"
"19119","114.67800","9.55676","0.01653"
"19188","115.09200","9.59120","0.01709"
"19257","115.50600","9.62564","0.01688"
"19326","115.92000","9.66019","0.01714"
"19395","116.33400","9.69463","0.01713"
"19464","116.74800","9.72925","0.01685"
"19533","117.16200","9.76369","0.01720"
"19602","117.57600","9.79807","0.01700"
"19671","117.99000","9.83269","0.01639"
"19740","118.40400","9.86719","0.01705"
"19809","118.81800","9.90168","0.01631"
"19878","119.23200","9.93612","0.01601"
"19947","119.64600","9.97068","0.01637"
"20016","120.06000","10.00524","0.01693"
"20085","120.47400","10.03968","0.01695"
"20154","120.88800","10.07418","0.01696"
"20223","121.30200","10.10862","0.01683"
"20292","121.71600","10.14318","0.01635"
"20361","122.13000","10.17767","0.01676"
"20430","122.54400","10.21217","0.01716"
"20499","122.95800","10.24667","0.01731"
"20568","123.37200","10.28123","0.01729"
"20637","123.78600","10.31573","0.01730"
"20706","124.20000","10.35017","0.01678"
"20775","124.61400","10.38466","0.01682"
"20844","125.02800","10.41910","0.01796"
"20913","125.44200","10.45366","0.01774"
"20982","125.85600","10.48822","0.01663"
"21051","126.27000","10.52266","0.01783"
"21120","126.68400","10.55722","0.01721"
"21189","127.09800","10.59172","0.01807"
"21258","127.51200","10.62621","0.01768"
"21327","127.92600","10.66065","0.01769"
"21396","128.34000","10.69515","0.01800"
"21465","128.75400","10.72965","0.01800"
"21534","129.16800","10.76415","0.01866"
"21603","129.58200","10.79865","0.01839"
"21672","129.99600","10.83315","0.01869"
"21741","130.41000","10.86770","0.01877"
"21810","130.82400","10.90220","0.01870"
"21879","131.23800","10.93670","0.01840"
"21948","131.65200","10.97114","0.01911"
"22017","132.06600","11.00570","0.01901"
"22086","132.48000","11.04020","0.01897"
"22155","132.89400","11.07470","0.01941"
"22224","133.30800","11.10913","0.01974"
"22293","133.72200","11.14363","0.01936"
"22362","134.13600","11.17819","0.01969"
"22431","134.55000","11.21269","0.01920"
"22500","134.96400","11.24719","0.01973"
"22569","135.37800","11.28163","0.01994"
"22638","135.79200","11.31618","0.01953"
"22707","136.20600","11.35069","0.02061"
"22776","136.62000","11.38524","0.02053"
"22845","137.03400","11.41962","0.01945"
"22914","137.44800","11.45418","0.01964"
"22983","137.86200","11.48874","0.02059"
"23052","138.27600","11.52324","0.02011"
"23121","138.69000","11.55768","0.01991"
"23190","139.10400","11.59217","0.02008"
"23259","139.51800","11.62673","0.02057"
"23328","139.93200","11.66117","0.02118"
"23397","140.34600","11.69567","0.02113"
"23466","140.76000","11.73011","0.02081"
"23535","141.17400","11.76467","0.02100"
"23604","141.58800","11.79922","0.02155"
"23673","142.00200","11.83372","0.02167"
"23742","142.41600","11.86810","0.02148"
"23811","142.83000","11.90266","0.02182"
"23880","143.24400","11.93722","0.02198"
"23949","143.65800","11.97172","0.02177"
"24018","144.07200","12.00616","0.02123"
"24087","144.48600","12.04066","0.02166"
"24156","144.90000","12.07521","0.02141"
"24225","145.31400","12.10977","0.02212"
"24294","145.72800","12.14421","0.02111"
"24363","146.14200","12.17865","0.02181"
"24432","146.55600","12.21315","0.02161"
"24501","146.97000","12.24771","0.02225"
"24570","147.38400","12.28215","0.02220"
"24639","147.79800","12.31664","0.02222"
"24708","148.21200","12.35120","0.02206"
"24777","148.62600","12.38570","0.02220"
"24846","149.04000","12.42020","0.02242"
"24915","149.45400","12.45470","0.02229"
"24984","149.86800","12.48914","0.02269"
"25053","150.28200","12.52369","0.02265"
"25122","150.69600","12.55819","0.02312"
"25191","151.11000","12.59269","0.02310"
"25260","151.52400","12.62719","0.02245"
"25329","151.93800","12.66169","0.02334"
"25398","152.35200","12.69619","0.02273"
"25467","152.76600","12.73069","0.02307"
"25536","153.18000","12.76513","0.02288"
"25605","153.59400","12.79962","0.02375"
"25674","154.00800","12.83418","0.02384"
"25743","154.42200","12.86874","0.02427"
"25812","154.83600","12.90312","0.02352"
"25881","155.25000","12.93762","0.02408"
"25950","155.66400","12.97224","0.02409"
"26019","156.07800","13.00667","0.02373"
"26088","156.49200","13.04117","0.02405"
"26157","156.90600","13.07561","0.02438"
"26226","157.32000","13.11017","0.02422"
"26295","157.73400","13.14473","0.02487"
"26364","158.14800","13.17923","0.02474"
"26433","158.56200","13.21367","0.02420"
"26502","158.97600","13.24817","0.02434"
"26571","159.39000","13.28272","0.02486"
"26640","159.80400","13.31722","0.02490"
"26709","160.21800","13.35166","0.02452"
"26778","160.63200","13.38610","0.02457"
"26847","161.04600","13.42072","0.02450"
"26916","161.46000","13.45516","0.02516"
"26985","161.87400","13.48965","0.02530"
"27054","162.28800","13.52409","0.02495"
"27123","162.70200","13.55865","0.02560"
"27192","163.11600","13.59327","0.02561"
"27261","163.53000","13.62771","0.02611"
"27330","163.94400","13.66215","0.02587"
"27399","164.35800","13.69665","0.02628"
"27468","164.77200","13.73120","0.02606"
"27537","165.18600","13.76564","0.02680"
"27606","165.60000","13.80014","0.02676"
"27675","166.01400","13.83464","0.02597"
"27744","166.42800","13.86920","0.02677"
"27813","166.84200","13.90370","0.02649"
"27882","167.25600","13.93820","0.02597"
"27951","167.67000","13.97263","0.02683"
"28020","168.08400","14.00713","0.02712"
"28089","168.49800","14.04169","0.02769"
"28158","168.91200","14.07619","0.02740"
"28227","169.32600","14.11069","0.02731"
"28296","169.74000","14.14519","0.02795"
"28365","170.15400","14.17969","0.02739"
"28434","170.56800","14.21424","0.02769"
"28503","170.98200","14.24868","0.02824"
"28572","171.39600","14.28318","0.02824"
"28641","171.81000","14.31768","0.02863"
"28710","172.22400","14.35218","0.02813"
"28779","172.63800","14.38662","0.02822"
"28848","173.05200","14.42112","0.02825"
"28917","173.46600","14.45567","0.02910"
"28986","173.88000","14.49023","0.02924"
"29055","174.29400","14.52467","0.02903"
"29124","174.70800","14.55911","0.02882"
"29193","175.12200","14.59367","0.02847"
"29262","175.53600","14.62817","0.02881"
"29331","175.95000","14.66272","0.02928"
"29400","176.36400","14.69716","0.02936"
"29469","176.77800","14.73166","0.02916"
"29538","177.19200","14.76622","0.02948"
"29607","177.60600","14.80066","0.02949"
"29676","178.02000","14.83522","0.02914"
"29745","178.43400","14.86966","0.02976"
"29814","178.84800","14.90416","0.02981"
"29883","179.26200","14.93871","0.02996"
"29952","179.67600","14.97321","0.02961"
"30021","180.09000","15.00759","0.03022"
"30090","180.50400","15.04215","0.03011"
"30159","180.91800","15.07671","0.03022"
"30228","181.33200","15.11121","0.03053"
"30297","181.74600","15.14571","0.03014"
"30366","182.16000","15.18014","0.02990"
"30435","182.57400","15.21470","0.03094"
"30504","182.98800","15.24914","0.03047"
"30573","183.40200","15.28370","0.03086"
"30642","183.81600","15.31814","0.03099"
"30711","184.23000","15.35270","0.03085"
"30780","184.64400","15.38720","0.03086"
"30849","185.05800","15.42169","0.03097"
"30918","185.47200","15.45613","0.03101"
"30987","185.88600","15.49063","0.03083"
"31056","186.30000","15.52519","0.03110"
"31125","186.71400","15.55969","0.03122"
"31194","187.12800","15.59419","0.03183"
"31263","187.54200","15.62862","0.03204"
"31332","187.95600","15.66324","0.03225"
"31401","188.37000","15.69768","0.03215"
"31470","188.78400","15.73218","0.03266"
"31539","189.19800","15.76668","0.03262"
"31608","189.61200","15.80112","0.03244"
"31677","190.02600","15.83568","0.03280"
"31746","190.44000","15.87017","0.03294"
"31815","190.85400","15.90461","0.03368"
"31884","191.26800","15.93923","0.03369"
"31953","191.68200","15.97373","0.03400"
"32022","192.09600","16.00823","0.03435"
"32091","192.51000","16.04267","0.03435"
"32160","192.92400","16.07717","0.03498"
"32229","193.33800","16.11166","0.03045"
"32298","193.75200","16.14616","0.02889"
"32367","194.16600","16.18066","0.02998"
"32436","194.58000","16.21516","0.02985"
"32505","194.99400","16.24966","0.03022"
"32574","195.40800","16.28422","0.03078"
"32643","195.82200","16.31872","0.03091"
"32712","196.23600","16.35316","0.03134"
"32781","196.65000","16.38765","0.03194"
"32850","197.06400","16.42215","0.03267"
"32919","197.47800","16.45671","0.03285"
"32988","197.89200","16.49115","0.03276"
"33057","198.30600","16.52559","0.03384"
"33126","198.72000","16.56021","0.03281"
"33195","199.13400","16.59470","0.03373"
"33264","199.54800","16.62920","0.03419"
"33333","199.96200","16.66364","0.03469"
"33402","200.37600","16.69820","0.03467"
"33471","200.79000","16.73270","0.03463"
"33540","201.20400","16.76720","0.03526"
"33609","201.61800","16.80164","0.03577"
"33678","202.03200","16.83619","0.03564"
"33747","202.44600","16.87069","0.03601"
"33816","202.86000","16.90525","0.03678"
"33885","203.27400","16.93969","0.03727"
"33954","203.68800","16.97413","0.03695"
"34023","204.10200","17.00869","0.03774"
"34092","204.51600","17.04319","0.03787"
"34161","204.93000","17.07768","0.03700"
"34230","205.34400","17.11212","0.03758"
"34299","205.75800","17.14668","0.03821"
"34368","206.17200","17.18124","0.03818"
"34437","206.58600","17.21574","0.03885"
"34506","207.00000","17.25018","0.03853"
"34575","207.41400","17.28468","0.03848"
"34644","207.82800","17.31917","0.03869"
"34713","208.24200","17.35367","0.03903"
"34782","208.65600","17.38817","0.03877"
"34851","209.07000","17.42261","0.03934"
"34920","209.48400","17.45717","0.03875"
"34989","209.89800","17.49173","0.03896"
"35058","210.31200","17.52623","0.03915"
"35127","210.72600","17.56067","0.03974"
"35196","211.14000","17.59516","0.03965"
"35265","211.55400","17.62972","0.04074"
"35334","211.96800","17.66422","0.02058"
"35403","212.38200","17.69866","0.02141"
"35472","212.79600","17.73316","0.02325"
"35541","213.21000","17.76765","0.02390"
"35610","213.62400","17.80221","0.02417"
"35679","214.03800","17.83671","0.02476"
"35748","214.45200","17.87115","0.02491"
"35817","214.86600","17.90565","0.02574"
"35886","215.28000","17.94015","0.02598"
"35955","215.69400","17.97465","0.02586"
"36024","216.10800","18.00908","0.02658"
"36093","216.52200","18.04370","0.02669"
"36162","216.93600","18.07820","0.02728"
"36231","217.35000","18.11270","0.02751"
"36300","217.76400","18.14714","0.02778"
"36369","218.17800","18.18170","0.02819"
"36438","218.59200","18.21614","0.02832"
"36507","219.00600","18.25069","0.02869"
"36576","219.42000","18.28514","0.02888"
"36645","219.83400","18.31963","0.02872"
"36714","220.24800","18.35419","0.02944"
"36783","220.66200","18.38869","0.02999"
"36852","221.07600","18.42325","0.03006"
"36921","221.49000","18.45763","0.03007"
"36990","221.90400","18.49218","0.03028"
"37059","222.31800","18.52668","0.03006"
"37128","222.73200","18.56124","0.02997"
"37197","223.14600","18.59562","0.03049"
"37266","223.56000","18.63018","0.03057"
"37335","223.97400","18.66474","0.03077"
"37404","224.38800","18.69918","0.03104"
"37473","224.80200","18.73368","0.03116"
"37542","225.21600","18.76818","0.03138"
"37611","225.63000","18.80267","0.03107"
"37680","226.04400","18.83717","0.03119"
"37749","226.45800","18.87167","0.03160"
"37818","226.87200","18.90611","0.03179"
"37887","227.28600","18.94067","0.03235"
"37956","227.70000","18.97522","0.03234"
"38025","228.11600","19.00990","0.02620"
"38094","228.53000","19.04434","0.02695"
"38163","228.94400","19.07878","0.02652"
"38232","229.35800","19.11334","0.02666"
"38301","229.77200","19.14784","0.02728"
"38370","230.18600","19.18233","0.02765"
"38439","230.60000","19.21677","0.02736"
"38508","231.01600","19.25157","0.02793"
"38577","231.43000","19.28601","0.02790"
"38646","231.84400","19.32057","0.02851"
"38715","232.25800","19.35501","0.02815"
"38784","232.67200","19.38951","0.02842"
"38853","233.08600","19.42406","0.02861"
"38922","233.50000","19.45850","0.02868"
"38991","233.91400","19.49300","0.02950"
"39060","234.32800","19.52750","0.02908"
"39129","234.74200","19.56206","0.02969"
"39198","235.15600","19.59656","0.02949"
"39267","235.57000","19.63100","0.02985"
"39336","235.98400","19.66549","0.03034"
"39405","236.39800","19.70000","0.03036"
"39474","236.81200","19.73455","0.03069"
"39543","237.22600","19.76899","0.03129"
"39612","237.64000","19.80349","0.03116"
"39681","238.05400","19.83799","0.03179"
"39750","238.46800","19.87255","0.03262"
"39819","238.88200","19.90710","0.03266"
"39888","239.29600","19.94154","0.03300"
"39957","239.71000","19.97598","0.03295"
"40026","240.12400","20.01054","0.03285"
"40095","240.53800","20.04504","0.03306"
"40164","240.95200","20.07942","0.03323"
"40233","241.36600","20.11391","0.03341"
"40302","241.78000","20.14853","0.03419"
"40371","242.19400","20.18309","0.03386"
"40440","242.60800","20.21759","0.03389"
"40509","243.02200","20.25197","0.03357"
"40578","243.43600","20.28653","0.03416"
"40647","243.85000","20.32103","0.03424"
"40716","244.26400","20.35553","0.03470"
"40785","244.67800","20.38997","0.03528"
"40854","245.09200","20.42452","0.03592"
"40923","245.50600","20.45902","0.03596"
"40992","245.92000","20.49352","0.03679"
"41061","246.33400","20.52802","0.03671"
"41130","246.74800","20.56246","0.03738"
"41199","247.16200","20.59702","0.03670"
"41268","247.57600","20.63151","0.03747"
"41337","247.99000","20.66607","0.03789"
"41406","248.40400","20.70045","0.03849"
"41475","248.81800","20.73501","0.03931"
"41544","249.23200","20.76957","0.03941"
"41613","249.64600","20.80401","0.04118"
"41682","250.06000","20.83851","0.04092"
"41751","250.47400","20.87300","0.04144"
"41820","250.88800","20.90750","0.04215"
"41889","251.30200","20.94194","0.04270"
"41958","251.71600","20.97650","0.04370"
"42027","252.13000","21.01094","0.04408"
"42096","252.54400","21.04550","0.04398"
"42165","252.95800","21.08006","0.04198"
"42234","253.37200","21.11449","0.04211"
"42303","253.78600","21.14899","0.04279"
"42372","254.20000","21.18349","0.04404"
"42441","254.61400","21.21805","0.04404"
"42510","255.02800","21.25249","0.04572"
"42579","255.44200","21.28699","0.04563"
"42648","255.85600","21.32149","0.04660"
"42717","256.27000","21.35604","0.04572"
"42786","256.68400","21.39054","0.04571"
"42855","257.09800","21.42498","0.04585"
"42924","257.51200","21.45948","0.04522"
"42993","257.92600","21.49404","0.03506"
"43062","258.34000","21.52854","0.03548"
"43131","258.75400","21.56298","0.03610"
"43200","259.16800","21.59742","0.03611"
"43269","259.58200","21.63203","0.03585"
"43338","259.99600","21.66659","0.03650"
"43407","260.41000","21.70103","0.03726"
"43476","260.82400","21.73547","0.03728"
"43545","261.23800","21.77003","0.03831"
"43614","261.65200","21.80453","0.03824"
"43683","262.06600","21.83902","0.03874"
"43752","262.48000","21.87346","0.03876"
"43821","262.89400","21.90796","0.03880"
"43890","263.30800","21.94252","0.03858"
"43959","263.72200","21.97702","0.03878"
"44028","264.13600","22.01158","0.03867"
"44097","264.55000","22.04595","0.03914"
"44166","264.96400","22.08051","0.03912"
"44235","265.37800","22.11507","0.03926"
"44304","265.79200","22.14957","0.02745"
"44373","266.20600","22.18395","0.02874"
"44442","266.62000","22.21851","0.02980"
"44511","267.03400","22.25300","0.03056"
"44580","267.44800","22.28757","0.03075"
"44649","267.86200","22.32200","0.03167"
"44718","268.27600","22.35650","0.02846"
"44787","268.69000","22.39100","0.02352"
"44856","269.10400","22.42550","0.02388"
"44925","269.51800","22.46000","0.02417"
"44994","269.93200","22.49450","0.02361"
"45063","270.34600","22.52899","0.02383"
"45132","270.76000","22.56355","0.02461"
"45201","271.17400","22.59811","0.02475"
"45270","271.58800","22.63249","0.02494"
"45339","272.00200","22.66699","0.02509"
"45408","272.41600","22.70155","0.02505"
"45477","272.83000","22.73599","0.02549"
"45546","273.24400","22.77054","0.02559"
"45615","273.65800","22.80498","0.02590"
"45684","274.07200","22.83954","0.02605"
"45753","274.48600","22.87404","0.02625"
"45822","274.90000","22.90854","0.02647"
"45891","275.31400","22.94298","0.02661"
"45960","275.72800","22.97748","0.02661"
"46029","276.14200","23.01203","0.02723"
"46098","276.55600","23.04653","0.02677"
"46167","276.97000","23.08097","0.02740"
"46236","277.38400","23.11553","0.02743"
"46305","277.79800","23.15003","0.02777"
"46374","278.21400","23.18471","0.02792"
"46443","278.62800","23.21921","0.02779"
"46512","279.04200","23.25364","0.02789"
"46581","279.45600","23.28820","0.02789"
"46650","279.87000","23.32270","0.02801"
"46719","280.28400","23.35714","0.02806"
"46788","280.69800","23.39164","0.02814"
"46857","281.11200","23.42614","0.02798"
"46926","281.52600","23.46070","0.02814"
"46995","281.94000","23.49525","0.02833"
"47064","282.35400","23.52969","0.02796"
"47133","282.76800","23.56413","0.02808"
"47202","283.18200","23.59869","0.02808"
"47271","283.59600","23.63319","0.02810"
"47340","284.01000","23.66763","0.02859"
"47409","284.42400","23.70212","0.02890"
"47478","284.83800","23.73668","0.02815"
"47547","285.25200","23.77118","0.02840"
"47616","285.66600","23.80568","0.02788"
"47685","286.08000","23.84018","0.02852"
"47754","286.49400","23.87468","0.02830"
"47823","286.90800","23.90918","0.02879"
"47892","287.32200","23.94367","0.02913"
"47961","287.73600","23.97811","0.02919"
"48030","288.15000","24.01267","0.02916"
"48099","288.56400","24.04717","0.02885"
"48168","288.97800","24.08167","0.02970"
"48237","289.39200","24.11617","0.02914"
"48306","289.80600","24.15061","0.02953"
"48375","290.22000","24.18522","0.02973"
"48444","290.63400","24.21966","0.02957"
"48513","291.04800","24.25416","0.02953"
"48582","291.46200","24.28860","0.03013"
"48651","291.87600","24.32316","0.03040"
"48720","292.29000","24.35772","0.03047"
"48789","292.70400","24.39222","0.03005"
"48858","293.11800","24.42665","0.03056"
"48927","293.53200","24.46115","0.03107"
"48996","293.94600","24.49571","0.03108"
"49065","294.36000","24.53015","0.03085"
"49134","294.77400","24.56465","0.03096"
"49203","295.18800","24.59903","0.03128"
"49272","295.60200","24.63371","0.03059"
"49341","296.01600","24.66820","0.03111"
"49410","296.43000","24.70270","0.03139"
"49479","296.84400","24.73714","0.03147"
"49548","297.25800","24.77164","0.03106"
"49617","297.67200","24.80620","0.03101"
"49686","298.08600","24.84070","0.03156"
"49755","298.50000","24.87514","0.03216"
"49824","298.91400","24.90969","0.03313"
"49893","299.32800","24.94413","0.03287"
"49962","299.74200","24.97869","0.03367"
"50031","300.15600","25.01319","0.03369"
"50100","300.57000","25.04763","0.03396"
"50169","300.98400","25.08219","0.03436"
"50238","301.39800","25.11669","0.03430"
"50307","301.81200","25.15113","0.03443"
"50376","302.22600","25.18563","0.03418"
"50445","302.64000","25.22018","0.03402"
"50514","303.05400","25.25474","0.03337"
"50583","303.46800","25.28918","0.03124"
"50652","303.88200","25.32368","0.03058"
"50721","304.29600","25.35818","0.03043"
"50790","304.71000","25.39268","0.03177"
"50859","305.12400","25.42717","0.03130"
"50928","305.53800","25.46167","0.03062"
"50997","305.95200","25.49617","0.02866"
"51066","306.36600","25.53067","0.02697"
"51135","306.78000","25.56523","0.02703"
"51204","307.19600","25.59991","0.02715"
"51273","307.61000","25.63434","0.02756"
"51342","308.02400","25.66878","0.02880"
"51411","308.43800","25.70340","0.02837"
"51480","308.85200","25.73790","0.02911"
"51549","309.26600","25.77228","0.02943"
"51618","309.68000","25.80684","0.02967"
"51687","310.09400","25.84134","0.02983"
"51756","310.50800","25.87583","0.02992"
"51825","310.92200","25.91033","0.03018"
"51894","311.33600","25.94483","0.03044"
"51963","311.75000","25.97939","0.03025"
"52032","312.16400","26.01383","0.03045"
"52101","312.57800","26.04839","0.03049"
"52170","312.99200","26.08277","0.03053"
"52239","313.40600","26.11732","0.03098"
"52308","313.82000","26.15188","0.03079"
"52377","314.23400","26.18638","0.03081"
"52446","314.64800","26.22088","0.03040"
"52515","315.06200","26.25538","0.03036"
"52584","315.47600","26.28988","0.03054"
"52653","315.89000","26.32432","0.03046"
"52722","316.30400","26.35887","0.03063"
"52791","316.71800","26.39325","0.03039"
"52860","317.13200","26.42787","0.03081"
"52929","317.54600","26.46237","0.03070"
"52998","317.96000","26.49687","0.03145"
"53067","318.37400","26.53137","0.03138"
"53136","318.78800","26.56586","0.03168"
"53205","319.20200","26.60042","0.03104"
"53274","319.61600","26.63486","0.03150"
"53343","320.03000","26.66930","0.03069"
"53412","320.44400","26.70386","0.03004"
"53481","320.85800","26.73836","0.03095"
"53550","321.27200","26.77286","0.03120"
"53619","321.68600","26.80736","0.03146"
"53688","322.10000","26.84185","0.03195"
"53757","322.51400","26.87635","0.03101"
"53826","322.92800","26.91085","0.03127"
"53895","323.34200","26.94535","0.03114"
"53964","323.75600","26.97979","0.03115"
"54033","324.17000","27.01429","0.03118"
"54102","324.58400","27.04885","0.03185"
"54171","324.99800","27.08340","0.03175"
"54240","325.41200","27.11784","0.03217"
"54309","325.82600","27.15228","0.03068"
"54378","326.24000","27.18690","0.03009"
"54447","326.65400","27.22140","0.03039"
"54516","327.06800","27.25583","0.03033"
"54585","327.48200","27.29028","0.03106"
"54654","327.89600","27.32483","0.03079"
"54723","328.31000","27.35939","0.03087"
"54792","328.72400","27.39389","0.03139"
"54861","329.13800","27.42833","0.03172"
"54930","329.55200","27.46283","0.03208"
"54999","329.96600","27.49739","0.03171"
"55068","330.38000","27.53189","0.03223"
"55137","330.79400","27.56632","0.01910"
"55206","331.20800","27.60082","0.01711"
"55275","331.62200","27.63532","0.01839"
"55344","332.03600","27.66988","0.01593"
"55413","332.45000","27.70438","0.01886"
"55482","332.86400","27.73876","0.01661"
"55551","333.27800","27.77337","0.01725"
"55620","333.69200","27.80787","0.01856"
"55689","334.10600","27.84237","0.01680"
"55758","334.52000","27.87681","0.01879"
"55827","334.93400","27.91131","0.01719"
"55896","335.34800","27.94587","0.01818"
"55965","335.76200","27.98037","0.01926"
"56034","336.17600","28.01486","0.01839"
"56103","336.59000","28.04930","0.01955"
"56172","337.00400","28.08386","0.01914"
"56241","337.41800","28.11836","0.01957"
"56310","337.83200","28.15280","0.01913"
"56379","338.24600","28.18730","0.02001"
"56448","338.66000","28.22191","0.02011"
"56517","339.07400","28.25636","0.01999"
"56586","339.48800","28.29085","0.02075"
"56655","339.90200","28.32535","0.02103"
"56724","340.31600","28.35985","0.02094"
"56793","340.73000","28.39435","0.02106"
"56862","341.14400","28.42885","0.02129"
"56931","341.55800","28.46329","0.02203"
"57000","341.97200","28.49784","0.02170"
"57069","342.38600","28.53240","0.02128"
"57138","342.80000","28.56690","0.02188"
"57207","343.21400","28.60134","0.02240"
"57276","343.62800","28.63578","0.02196"
"57345","344.04200","28.67040","0.02208"
"57414","344.45600","28.70490","0.02207"
"57483","344.87000","28.73933","0.02232"
"57552","345.28400","28.77377","0.02249"
"57621","345.69800","28.80833","0.02239"
"57690","346.11200","28.84289","0.02296"
"57759","346.52600","28.87733","0.02195"
"57828","346.94000","28.91189","0.02205"
"57897","347.35400","28.94638","0.02221"
"57966","347.76800","28.98088","0.02162"
"58035","348.18200","29.01538","0.02238"
"58104","348.59600","29.04982","0.02239"
"58173","349.01000","29.08432","0.02244"
"58242","349.42400","29.11882","0.02219"
"58311","349.83800","29.15338","0.02228"
"58380","350.25200","29.18788","0.02217"
"58449","350.66600","29.22231","0.02229"
"58518","351.08000","29.25681","0.02243"
"58587","351.49400","29.29137","0.02206"
"58656","351.90800","29.32587","0.02236"
"58725","352.32200","29.36031","0.02189"
"58794","352.73600","29.39481","0.02203"
"58863","353.15000","29.42937","0.02220"
"58932","353.56400","29.46386","0.02251"
"59001","353.97800","29.49830","0.02203"
"59070","354.39200","29.53280","0.02212"
"59139","354.80600","29.56742","0.02229"
"59208","355.22000","29.60186","0.02222"
"59277","355.63400","29.63636","0.02225"
"59346","356.04800","29.67074","0.02232"
"59415","356.46200","29.70530","0.02286"
"59484","356.87600","29.73985","0.02295"
"59553","357.29000","29.77441","0.02330"
"59622","357.70400","29.80885","0.02219"
"59691","358.11800","29.84335","0.02316"
"59760","358.53200","29.87785","0.02248"
"59829","358.94600","29.91235","0.02280"
"59898","359.36000","29.94684","0.02252"
"59967","359.77400","29.98128","0.02244"
"60036","360.18800","30.01584","0.02291"
"60105","360.60200","30.05034","0.02246"
"60174","361.01600","30.08490","0.02253"
"60243","361.43000","30.11928","0.02235"
"60312","361.84400","30.15384","0.02264"
"60381","362.25800","30.18839","0.02258"
"60450","362.67200","30.22289","0.02285"
"60519","363.08600","30.25727","0.02326"
"60588","363.50000","30.29183","0.02290"
"60657","363.91400","30.32633","0.02262"
"60726","364.32800","30.36089","0.02251"
"60795","364.74200","30.39539","0.02274"
"60864","365.15600","30.42982","0.02246"
"60933","365.57000","30.46438","0.02285"
"61002","365.98400","30.49882","0.02322"
"61071","366.39800","30.53332","0.02300"
"61140","366.81200","30.56782","0.02273"
"61209","367.22600","30.60232","0.02231"
"61278","367.64000","30.63688","0.02280"
"61347","368.05400","30.67138","0.02301"
"61416","368.46800","30.70587","0.02337"
"61485","368.88200","30.74031","0.02275"
"61554","369.29600","30.77487","0.02286"
"61623","369.71000","30.80937","0.02331"
"61692","370.12400","30.84381","0.02312"
"61761","370.53800","30.87831","0.02373"
"61830","370.95200","30.91286","0.02338"
"61899","371.36600","30.94736","0.02384"
"61968","371.78000","30.98186","0.02364"
"62037","372.19400","31.01636","0.02351"
"62106","372.60800","31.05086","0.02408"
"62175","373.02200","31.08536","0.02404"
"62244","373.43600","31.11986","0.02398"
"62313","373.85000","31.15429","0.02442"
"62382","374.26400","31.18885","0.02381"
"62451","374.67800","31.22335","0.02419"
"62520","375.09200","31.25785","0.02473"
"62589","375.50600","31.29235","0.02415"
"62658","375.92000","31.32685","0.02437"
"62727","376.33400","31.36134","0.02419"
"62796","376.74800","31.39584","0.02483"
"62865","377.16200","31.43034","0.02513"
"62934","377.57600","31.46478","0.02453"
"63003","377.99000","31.49934","0.02484"
"63072","378.40400","31.53390","0.02457"
"63141","378.81800","31.56833","0.02496"
"63210","379.23200","31.60283","0.02513"
"63279","379.64600","31.63733","0.02457"
"63348","380.06000","31.67189","0.02505"
"63417","380.47400","31.70639","0.02527"
"63486","380.88800","31.74083","0.02462"
"63555","381.30200","31.77521","0.02484"
"63624","381.71600","31.80983","0.02512"
"63693","382.13000","31.84432","0.02502"
"63762","382.54400","31.87888","0.02505"
"63831","382.95800","31.91338","0.02524"
"63900","383.37200","31.94782","0.02540"
"63969","383.78600","31.98238","0.02533"
"64038","384.20000","32.01688","0.02537"
"64107","384.61400","32.05132","0.02549"
"64176","385.02800","32.08582","0.02571"
"64245","385.44200","32.12031","0.02547"
"64314","385.85600","32.15487","0.02633"
"64383","386.27000","32.18937","0.02635"
"64452","386.68400","32.22380","0.02618"
"64521","387.09800","32.25837","0.02602"
"64590","387.51200","32.29287","0.02604"
"64659","387.92600","32.32736","0.02627"
"64728","388.34000","32.36180","0.02634"
"64797","388.75400","32.39630","0.02545"
"64866","389.16800","32.43086","0.02428"
"64935","389.58200","32.46536","0.02497"
"65004","389.99600","32.49980","0.02481"
"65073","390.41000","32.53429","0.02469"
"65142","390.82400","32.56885","0.02406"
"65211","391.23800","32.60335","0.02406"
"65280","391.65200","32.63785","0.02453"
"65349","392.06600","32.67229","0.02462"
"65418","392.48000","32.70679","0.02432"
"65487","392.89400","32.74134","0.02426"
"65556","393.30800","32.77591","0.02464"
"65625","393.72200","32.81034","0.01852"
"65694","394.13600","32.84484","0.01761"
"65763","394.55000","32.87940","0.01959"
"65832","394.96400","32.91390","0.02003"
"65901","395.37800","32.94834","0.01869"
"65970","395.79200","32.98284","0.01944"
"66039","396.20600","33.01733","0.01984"
"66108","396.62000","33.05183","0.01891"
"66177","397.03400","33.08633","0.01910"
"66246","397.44800","33.12077","0.02008"
"66315","397.86200","33.15533","0.02041"
"66384","398.27600","33.18988","0.01979"
"66453","398.69000","33.22438","0.02047"
"66522","399.10400","33.25883","0.02103"
"66591","399.51800","33.29332","0.01964"
"66660","399.93200","33.32788","0.02037"
"66729","400.34600","33.36238","0.02072"
"66798","400.76000","33.39688","0.02019"
"66867","401.17400","33.43132","0.02002"
"66936","401.58800","33.46581","0.02132"
"67005","402.00200","33.50037","0.02087"
"67074","402.41600","33.53487","0.02106"
"67143","402.83000","33.56925","0.02108"
"67212","403.24400","33.60387","0.02122"
"67281","403.65800","33.63837","0.02180"
"67350","404.07200","33.67287","0.02097"
"67419","404.48600","33.70731","0.02158"
"67488","404.90000","33.74187","0.02084"
"67557","405.31400","33.77636","0.02204"
"67626","405.72800","33.81086","0.02144"
"67695","406.14200","33.84530","0.02205"
"67764","406.55600","33.87986","0.02164"
"67833","406.97000","33.91442","0.02264"
"67902","407.38400","33.94885","0.02160"
"67971","407.79800","33.98335","0.02155"
"68040","408.21200","34.01785","0.02217"
"68109","408.62600","34.05241","0.02188"
"68178","409.04000","34.08685","0.02204"
"68247","409.45400","34.12135","0.02189"
"68316","409.86800","34.15578","0.02249"
"68385","410.28200","34.19028","0.02210"
"68454","410.69600","34.22491","0.02151"
"68523","411.11000","34.25940","0.02194"
"68592","411.52400","34.29390","0.02238"
"68661","411.93800","34.32828","0.02251"
"68730","412.35200","34.36290","0.02278"
"68799","412.76600","34.39740","0.02195"
"68868","413.18000","34.43184","0.02225"
"68937","413.59400","34.46627","0.02304"
"69006","414.00800","34.50084","0.02297"
"69075","414.42200","34.53539","0.02230"
"69144","414.83600","34.56989","0.02248"
"69213","415.25000","34.60433","0.02277"
"69282","415.66400","34.63882","0.02238"
"69351","416.07800","34.67339","0.02269"
"69420","416.49200","34.70789","0.02250"
"69489","416.90600","34.74232","0.02294"
"69558","417.32000","34.77682","0.02299"
"69627","417.73400","34.81132","0.02310"
"69696","418.14800","34.84582","0.02309"
"69765","418.56200","34.88032","0.02308"
"69834","418.97600","34.91481","0.02337"
"69903","419.39000","34.94938","0.02358"
"69972","419.80400","34.98387","0.02289"
"70041","420.21800","35.01837","0.02363"
"70110","420.63200","35.05275","0.02344"
"70179","421.04600","35.08731","0.02387"
"70248","421.46000","35.12186","0.02365"
"70317","421.87400","35.15636","0.02381"
"70386","422.28800","35.19080","0.02347"
"70455","422.70200","35.22530","0.02381"
"70524","423.11600","35.25986","0.02348"
"70593","423.53000","35.29436","0.02411"
"70662","423.94400","35.32886","0.02356"
"70731","424.35800","35.36324","0.02335"
"70800","424.77200","35.39785","0.02408"
"70869","425.18600","35.43235","0.02393"
"70938","425.60000","35.46691","0.02433"
"71007","426.01400","35.50135","0.02477"
"71076","426.42800","35.53585","0.02416"
"71145","426.84200","35.57041","0.02422"
"71214","427.25600","35.60485","0.02460"
"71283","427.67000","35.63935","0.02513"
"71352","428.08400","35.67378","0.02481"
"71421","428.49800","35.70828","0.02476"
"71490","428.91200","35.74284","0.02526"
"71559","429.32600","35.77734","0.02518"
"71628","429.74000","35.81178","0.02543"
"71697","430.15400","35.84634","0.02567"
"71766","430.56800","35.88089","0.02534"
"71835","430.98200","35.91533","0.02593"
"71904","431.39600","35.94983","0.02600"
"71973","431.81000","35.98433","0.02596"
"72042","432.22400","36.01889","0.02584"
"72111","432.63800","36.05333","0.02619"
"72180","433.05200","36.08789","0.02600"
"72249","433.46600","36.12233","0.02625"
"72318","433.88000","36.15682","0.02693"
"72387","434.29400","36.19138","0.02644"
"72456","434.70800","36.22582","0.02652"
"72525","435.12200","36.26026","0.02641"
"72594","435.53600","36.29482","0.02693"
"72663","435.95000","36.32932","0.02698"
"72732","436.36400","36.36387","0.02703"
"72801","436.77800","36.39832","0.02678"
"72870","437.19200","36.43287","0.02726"
"72939","437.60600","36.46737","0.02797"
"73008","438.02000","36.50187","0.02701"
"73077","438.43400","36.53630","0.02718"
"73146","438.84800","36.57080","0.02701"
"73215","439.26200","36.60537","0.02772"
"73284","439.67600","36.63986","0.02727"
"73353","440.09000","36.67436","0.02734"
"73422","440.50400","36.70880","0.02718"
"73491","440.91800","36.74336","0.02534"
"73560","441.33200","36.77792","0.02292"
"73629","441.74600","36.81242","0.02533"
"73698","442.16000","36.84679","0.02548"
"73767","442.57400","36.88129","0.02391"
"73836","442.98800","36.91591","0.02549"
"73905","443.40200","36.95035","0.02547"
"73974","443.81600","36.98485","0.02495"
"74043","444.23000","37.01934","0.02584"
"74112","444.64400","37.05391","0.02549"
"74181","445.05800","37.08841","0.02517"
"74250","445.47200","37.12290","0.02527"
"74319","445.88600","37.15728","0.02532"
"74388","446.30000","37.19184","0.02564"
"74457","446.71400","37.22640","0.02622"
"74526","447.12800","37.26090","0.02658"
"74595","447.54200","37.29533","0.02652"
"74664","447.95600","37.32983","0.02668"
"74733","448.37000","37.36440","0.02611"
"74802","448.78400","37.39889","0.02674"
"74871","449.19800","37.43333","0.02652"
"74940","449.61200","37.46777","0.02664"
"75009","450.02600","37.50233","0.02700"
"75078","450.44000","37.53688","0.02698"
"75147","450.85400","37.57133","0.02649"
"75216","451.26800","37.60582","0.02665"
"75285","451.68200","37.64038","0.02736"
"75354","452.09600","37.67488","0.02693"
"75423","452.51000","37.70938","0.02709"
"75492","452.92400","37.74382","0.02692"
"75561","453.33800","37.77831","0.02766"
"75630","453.75200","37.81281","0.02714"
"75699","454.16600","37.84737","0.02793"
"75768","454.58000","37.88181","0.02789"
"75837","454.99400","37.91631","0.02822"
"75906","455.40800","37.95087","0.02792"
"75975","455.82200","37.98537","0.02794"
"76044","456.23600","38.01987","0.02769"
"76113","456.65000","38.05430","0.02818"
"76182","457.06400","38.08880","0.02827"
"76251","457.47800","38.12336","0.02798"
"76320","457.89200","38.15786","0.02822"
"76389","458.30600","38.19230","0.02880"
"76458","458.72000","38.22680","0.02884"
"76527","459.13400","38.26141","0.02908"
"76596","459.54800","38.29591","0.02941"
"76665","459.96200","38.33035","0.02945"
"76734","460.37600","38.36479","0.02963"
"76803","460.79000","38.39929","0.02911"
"76872","461.20400","38.43379","0.02980"
"76941","461.61800","38.46835","0.02935"
"77010","462.03200","38.50278","0.03027"
"77079","462.44600","38.53734","0.02977"
"77148","462.86000","38.57190","0.02999"
"77217","463.27400","38.60640","0.03008"
"77286","463.68800","38.64078","0.03027"
"77355","464.10200","38.67528","0.03042"
"77424","464.51600","38.70984","0.02981"
"77493","464.93000","38.74434","0.03015"
"77562","465.34400","38.77884","0.03055"
"77631","465.75800","38.81334","0.03086"
"77700","466.17200","38.84789","0.03079"
"77769","466.58600","38.88239","0.02987"
"77838","467.00000","38.91682","0.03050"
"77907","467.41400","38.95127","0.03060"
"77976","467.82800","38.98589","0.03084"
"78045","468.24200","39.02032","0.03097"
"78114","468.65600","39.05494","0.03107"
"78183","469.07000","39.08938","0.03122"
"78252","469.48400","39.12388","0.03136"
"78321","469.89800","39.15837","0.03128"
"78390","470.31200","39.19288","0.03125"
"78459","470.72600","39.22738","0.03123"
"78528","471.14000","39.26175","0.03176"
"78597","471.55400","39.29631","0.03196"
"78666","471.96800","39.33087","0.03187"
"78735","472.38200","39.36537","0.02870"
"78804","472.79600","39.39981","0.02708"
"78873","473.21000","39.43436","0.02785"
"78942","473.62400","39.46886","0.02943"
"79011","474.03800","39.50330","0.02827"
"79080","474.45200","39.53780","0.02868"
"79149","474.86600","39.57230","0.02843"
"79218","475.28000","39.60686","0.02893"
"79287","475.69400","39.64136","0.02873"
"79356","476.10800","39.67585","0.02881"
"79425","476.52200","39.71029","0.02886"
"79494","476.93600","39.74492","0.02939"
"79563","477.35000","39.77942","0.02937"
"79632","477.76400","39.81385","0.02970"
"79701","478.17800","39.84829","0.02968"
"79770","478.59200","39.88279","0.02981"
"79839","479.00600","39.91740","0.02973"
"79908","479.42000","39.95190","0.03000"
"79977","479.83400","39.98634","0.02992"
"80046","480.24800","40.02084","0.03008"
"80115","480.66200","40.05540","0.03063"
"80184","481.07600","40.08996","0.03128"
"80253","481.49000","40.12434","0.03065"
"80322","481.90400","40.15878","0.03045"
"80391","482.31800","40.19333","0.03058"
"80460","482.73200","40.22789","0.03083"
"80529","483.14600","40.26233","0.03097"
"80598","483.56000","40.29683","0.03148"
"80667","483.97400","40.33139","0.03106"
"80736","484.38800","40.36583","0.03152"
"80805","484.80200","40.40039","0.03180"
"80874","485.21600","40.43483","0.03167"
"80943","485.63000","40.46932","0.03170"
"81012","486.04400","40.50388","0.03162"
"81081","486.45800","40.53838","0.03183"
"81150","486.87200","40.57281","0.03221"
"81219","487.28600","40.60732","0.03211"
"81288","487.70000","40.64193","0.03274"
"81357","488.11400","40.67637","0.03196"
"81426","488.52800","40.71087","0.03235"
"81495","488.94200","40.74525","0.03225"
"81564","489.35600","40.77981","0.03232"
"81633","489.77000","40.81437","0.03291"
"81702","490.18400","40.84893","0.03278"
"81771","490.59800","40.88330","0.03279"
"81840","491.01200","40.91780","0.03309"
"81909","491.42600","40.95242","0.03271"
"81978","491.84000","40.98686","0.03278"
"82047","492.25400","41.02130","0.03338"
"82116","492.66800","41.05579","0.03373"
"82185","493.08200","41.09029","0.03360"
"82254","493.49600","41.12486","0.03363"
"82323","493.91000","41.15936","0.03410"
"82392","494.32400","41.19386","0.03377"
"82461","494.73800","41.22835","0.03386"
"82530","495.15200","41.26285","0.03430"
"82599","495.56600","41.29741","0.03450"
"82668","495.98000","41.33178","0.03432"
"82737","496.39400","41.36629","0.03379"
"82806","496.80800","41.40084","0.03493"
"82875","497.22200","41.43534","0.03487"
"82944","497.63600","41.46984","0.03430"
"83013","498.05000","41.50428","0.03473"
"83082","498.46400","41.53883","0.03506"
"83151","498.87800","41.57340","0.03515"
"83220","499.29200","41.60783","0.03517"
"83289","499.70600","41.64227","0.03588"
"83358","500.12000","41.67683","0.03609"
"83427","500.53400","41.71139","0.03548"
"83496","500.94800","41.74583","0.03654"
"83565","501.36200","41.78033","0.03517"
"83634","501.77600","41.81482","0.03612"
"83703","502.19000","41.84932","0.03594"
"83772","502.60400","41.88388","0.03621"
"83841","503.01800","41.91832","0.03572"
"83910","503.43200","41.95282","0.03651"
"83979","503.84600","41.98732","0.03603"
"84048","504.26000","42.02187","0.03670"
"84117","504.67400","42.05632","0.03688"
"84186","505.08800","42.09081","0.03717"
"84255","505.50200","42.12531","0.03684"
"84317","505.87400","42.15635","0.03784"