File: Trajectories_together/170121_1Specimen_RawData_7.csv
"","V1","V2","V3"
"1","End date","1/21/2017",""
"2","Specimen label","19CG_NoLabel1",""
"3","Maximum Load","0.03045","N"
"4","Time","Extension","Load"
"5","(s)","(mm)","(N)"
"6","0.00000","0.00000","-0.00038"
"20","0.08400","0.00263","-0.00084"
"34","0.16800","0.01052","0.00050"
"48","0.25200","0.01967","0.00103"
"62","0.33600","0.02786","0.00160"
"76","0.42000","0.03522","0.00236"
"90","0.50400","0.04227","0.00277"
"104","0.58800","0.04927","0.00339"
"118","0.67200","0.05620","0.00342"
"132","0.75600","0.06320","0.00417"
"146","0.84000","0.07019","0.00497"
"160","0.92400","0.07719","0.00514"
"174","1.00800","0.08418","0.00494"
"188","1.09200","0.09124","0.00575"
"202","1.17600","0.09823","0.00711"
"216","1.26000","0.10523","0.00633"
"230","1.34400","0.11222","0.00690"
"244","1.42800","0.11916","0.00717"
"258","1.51200","0.12616","0.00795"
"272","1.59600","0.13321","0.00786"
"286","1.68000","0.14021","0.00862"
"300","1.76400","0.14720","0.00847"
"314","1.84800","0.15426","0.00898"
"328","1.93200","0.16119","0.00868"
"342","2.01600","0.16813","0.00965"
"356","2.10000","0.17512","0.00982"
"370","2.18400","0.18224","0.01030"
"384","2.26800","0.18923","0.01057"
"398","2.35200","0.19617","0.01149"
"412","2.43600","0.20322","0.01088"
"426","2.52000","0.21016","0.01149"
"440","2.60400","0.21716","0.01167"
"454","2.68800","0.22415","0.01176"
"468","2.77200","0.23121","0.01192"
"482","2.85600","0.23826","0.01216"
"496","2.94000","0.24520","0.01248"
"510","3.02400","0.25219","0.01215"
"524","3.10800","0.25913","0.01262"
"538","3.19200","0.26612","0.01295"
"552","3.27600","0.27318","0.01319"
"566","3.36000","0.28017","0.01421"
"580","3.44400","0.28723","0.01409"
"594","3.52800","0.29416","0.01413"
"608","3.61200","0.30110","0.01447"
"622","3.69600","0.30816","0.01442"
"636","3.78000","0.31515","0.01450"
"650","3.86400","0.32221","0.01502"
"664","3.94800","0.32920","0.01535"
"678","4.03200","0.33620","0.01471"
"692","4.11600","0.34313","0.01524"
"706","4.20000","0.35007","0.01552"
"720","4.28400","0.35718","0.01609"
"734","4.36800","0.36424","0.01587"
"748","4.45200","0.37117","0.01620"
"762","4.53600","0.37817","0.01593"
"776","4.62000","0.38516","0.01655"
"790","4.70400","0.39210","0.01696"
"804","4.78800","0.39915","0.01692"
"818","4.87200","0.40621","0.01735"
"832","4.95600","0.41321","0.01756"
"846","5.04000","0.42026","0.01758"
"860","5.12400","0.42720","0.01688"
"874","5.20800","0.43419","0.01716"
"888","5.29200","0.44113","0.01787"
"902","5.37600","0.44812","0.01826"
"916","5.46000","0.45524","0.01796"
"930","5.54400","0.46217","0.01779"
"944","5.62800","0.46923","0.01853"
"958","5.71200","0.47616","0.01838"
"972","5.79600","0.48310","0.01845"
"986","5.88000","0.49021","0.01824"
"1000","5.96400","0.49721","0.01880"
"1014","6.04800","0.50421","0.01914"
"1028","6.13200","0.51120","0.01840"
"1042","6.21600","0.51820","0.01936"
"1056","6.30000","0.52519","0.01909"
"1070","6.38400","0.53213","0.01931"
"1084","6.46800","0.53918","0.01981"
"1098","6.55200","0.54618","0.01991"
"1112","6.63600","0.55317","0.01952"
"1126","6.72000","0.56017","0.01991"
"1140","6.80400","0.56716","0.01988"
"1154","6.88800","0.57416","0.01943"
"1168","6.97200","0.58109","0.02000"
"1182","7.05600","0.58821","0.01982"
"1196","7.14000","0.59520","0.02030"
"1210","7.22400","0.60220","0.02029"
"1224","7.30800","0.60920","0.02059"
"1238","7.39200","0.61619","0.02038"
"1252","7.47600","0.62319","0.02056"
"1266","7.56000","0.63018","0.02048"
"1280","7.64400","0.63724","0.02033"
"1294","7.72800","0.64417","0.02048"
"1308","7.81200","0.65111","0.02067"
"1322","7.89600","0.65816","0.02130"
"1336","7.98000","0.66510","0.02045"
"1350","8.06400","0.67215","0.02070"
"1364","8.14800","0.67921","0.02096"
"1378","8.23200","0.68620","0.02088"
"1392","8.31600","0.69314","0.02079"
"1406","8.40000","0.70014","0.02111"
"1420","8.48400","0.70713","0.02110"
"1434","8.56800","0.71419","0.02116"
"1448","8.65200","0.72118","0.02129"
"1462","8.73600","0.72818","0.02139"
"1476","8.82000","0.73523","0.02134"
"1490","8.90400","0.74217","0.02117"
"1504","8.98800","0.74910","0.02096"
"1518","9.07200","0.75616","0.02238"
"1532","9.15600","0.76321","0.02197"
"1546","9.24000","0.77021","0.02143"
"1560","9.32400","0.77720","0.02160"
"1574","9.40800","0.78420","0.02139"
"1588","9.49200","0.79119","0.02186"
"1602","9.57600","0.79813","0.02115"
"1616","9.66000","0.80519","0.02163"
"1630","9.74400","0.81224","0.02148"
"1644","9.82800","0.81918","0.02196"
"1658","9.91200","0.82617","0.02193"
"1672","9.99600","0.83317","0.02138"
"1686","10.08000","0.84016","0.02214"
"1700","10.16400","0.84716","0.02184"
"1714","10.24800","0.85415","0.02186"
"1728","10.33200","0.86121","0.02213"
"1742","10.41600","0.86814","0.02226"
"1756","10.50000","0.87520","0.02148"
"1770","10.58400","0.88213","0.02187"
"1784","10.66800","0.88907","0.02213"
"1798","10.75200","0.89619","0.02188"
"1812","10.83600","0.90318","0.02200"
"1826","10.92000","0.91024","0.02213"
"1840","11.00400","0.91717","0.02190"
"1854","11.08800","0.92417","0.02184"
"1868","11.17200","0.93116","0.02219"
"1882","11.25600","0.93810","0.02225"
"1896","11.34000","0.94521","0.02237"
"1910","11.42400","0.95215","0.02193"
"1924","11.50800","0.95920","0.02240"
"1938","11.59200","0.96620","0.02155"
"1952","11.67600","0.97313","0.02234"
"1966","11.76000","0.98019","0.02237"
"1980","11.84400","0.98718","0.02207"
"1994","11.92800","0.99424","0.02267"
"2008","12.01200","1.00124","0.02263"
"2022","12.09600","1.00823","0.02260"
"2036","12.18000","1.01517","0.02230"
"2050","12.26400","1.02216","0.02219"
"2064","12.34800","1.02916","0.02215"
"2078","12.43200","1.03621","0.02263"
"2092","12.51600","1.04321","0.02274"
"2106","12.60000","1.05020","0.02185"
"2120","12.68400","1.05720","0.02231"
"2134","12.76800","1.06413","0.02229"
"2148","12.85200","1.07113","0.02247"
"2162","12.93600","1.07818","0.02223"
"2176","13.02000","1.08518","0.02222"
"2190","13.10400","1.09224","0.02222"
"2204","13.18800","1.09923","0.02241"
"2218","13.27200","1.10611","0.02256"
"2232","13.35600","1.11316","0.02216"
"2246","13.44000","1.12016","0.02272"
"2260","13.52400","1.12715","0.02245"
"2274","13.60800","1.13421","0.02264"
"2288","13.69200","1.14120","0.02299"
"2302","13.77600","1.14820","0.02289"
"2316","13.86000","1.15513","0.02322"
"2330","13.94400","1.16219","0.02318"
"2344","14.02800","1.16918","0.02313"
"2358","14.11200","1.17618","0.02288"
"2372","14.19600","1.18323","0.02258"
"2386","14.28000","1.19017","0.02301"
"2400","14.36400","1.19717","0.02195"
"2414","14.44800","1.20410","0.02276"
"2428","14.53200","1.21116","0.02280"
"2442","14.61600","1.21827","0.02324"
"2456","14.70000","1.22521","0.02296"
"2470","14.78400","1.23220","0.02329"
"2484","14.86800","1.23914","0.02320"
"2498","14.95200","1.24613","0.02298"
"2512","15.03600","1.25313","0.02325"
"2526","15.12000","1.26012","0.02319"
"2540","15.20400","1.26724","0.02296"
"2554","15.28800","1.27417","0.02246"
"2568","15.37200","1.28123","0.02349"
"2582","15.45600","1.28817","0.02324"
"2596","15.54000","1.29510","0.02266"
"2610","15.62400","1.30222","0.02298"
"2624","15.70800","1.30921","0.02311"
"2638","15.79200","1.31621","0.02318"
"2652","15.87600","1.32320","0.02307"
"2666","15.96000","1.33020","0.02359"
"2680","16.04400","1.33713","0.02323"
"2694","16.12800","1.34419","0.02327"
"2708","16.21200","1.35124","0.02351"
"2722","16.29600","1.35818","0.02356"
"2736","16.38000","1.36517","0.02353"
"2750","16.46400","1.37217","0.02367"
"2764","16.54800","1.37917","0.02317"
"2778","16.63200","1.38616","0.02378"
"2792","16.71600","1.39316","0.02320"
"2806","16.80000","1.40021","0.02289"
"2820","16.88400","1.40715","0.02356"
"2834","16.96800","1.41414","0.02324"
"2848","17.05200","1.42114","0.02359"
"2862","17.13600","1.42813","0.02274"
"2876","17.22000","1.43519","0.02343"
"2890","17.30400","1.44218","0.02299"
"2904","17.38800","1.44918","0.02341"
"2918","17.47200","1.45617","0.02378"
"2932","17.55600","1.46317","0.02256"
"2946","17.64000","1.47016","0.02337"
"2960","17.72400","1.47716","0.02326"
"2974","17.80800","1.48416","0.02370"
"2988","17.89200","1.49121","0.02335"
"3002","17.97600","1.49821","0.02339"
"3016","18.06000","1.50526","0.02314"
"3030","18.14400","1.51214","0.02307"
"3044","18.22800","1.51919","0.02350"
"3058","18.31200","1.52619","0.02317"
"3072","18.39600","1.53324","0.02343"
"3086","18.48000","1.54018","0.02309"
"3100","18.56400","1.54717","0.02318"
"3114","18.64800","1.55417","0.02295"
"3128","18.73200","1.56110","0.02381"
"3142","18.81600","1.56816","0.02356"
"3156","18.90000","1.57516","0.02301"
"3170","18.98400","1.58221","0.02345"
"3184","19.06800","1.58927","0.02328"
"3198","19.15200","1.59614","0.02328"
"3212","19.23600","1.60320","0.02344"
"3226","19.32000","1.61013","0.02375"
"3240","19.40400","1.61719","0.02354"
"3254","19.48800","1.62418","0.02357"
"3268","19.57200","1.63118","0.02378"
"3282","19.65600","1.63817","0.02346"
"3296","19.74000","1.64511","0.02374"
"3310","19.82400","1.65210","0.02387"
"3324","19.90800","1.65916","0.02355"
"3338","19.99200","1.66627","0.02352"
"3352","20.07600","1.67321","0.02305"
"3366","20.16000","1.68021","0.02351"
"3380","20.24400","1.68714","0.02414"
"3394","20.32800","1.69408","0.02429"
"3408","20.41200","1.70119","0.02307"
"3422","20.49600","1.70819","0.02383"
"3436","20.58000","1.71518","0.02367"
"3450","20.66400","1.72224","0.02292"
"3464","20.74800","1.72917","0.02394"
"3478","20.83200","1.73617","0.02337"
"3492","20.91600","1.74316","0.02367"
"3506","21.00000","1.75016","0.02352"
"3520","21.08400","1.75721","0.02394"
"3534","21.16800","1.76421","0.02355"
"3548","21.25200","1.77121","0.02328"
"3562","21.33600","1.77814","0.02352"
"3576","21.42000","1.78514","0.02373"
"3590","21.50400","1.79213","0.02371"
"3604","21.58800","1.79919","0.02381"
"3618","21.67200","1.80618","0.02364"
"3632","21.75600","1.81318","0.02350"
"3646","21.84000","1.82017","0.02339"
"3660","21.92400","1.82717","0.02393"
"3674","22.00800","1.83416","0.02386"
"3688","22.09200","1.84122","0.02419"
"3702","22.17600","1.84815","0.02399"
"3716","22.26000","1.85521","0.02345"
"3730","22.34400","1.86220","0.02345"
"3744","22.42800","1.86914","0.02402"
"3758","22.51200","1.87620","0.02380"
"3772","22.59600","1.88319","0.02414"
"3786","22.68000","1.89025","0.02360"
"3800","22.76400","1.89718","0.02335"
"3814","22.84800","1.90424","0.02380"
"3828","22.93200","1.91117","0.02370"
"3842","23.01600","1.91811","0.02382"
"3856","23.10000","1.92522","0.02348"
"3870","23.18400","1.93222","0.02430"
"3884","23.26800","1.93921","0.02379"
"3898","23.35200","1.94615","0.02415"
"3912","23.43600","1.95320","0.02370"
"3926","23.52000","1.96020","0.02401"
"3940","23.60400","1.96714","0.02436"
"3954","23.68800","1.97419","0.02378"
"3968","23.77200","1.98119","0.02344"
"3982","23.85600","1.98818","0.02385"
"3996","23.94000","1.99518","0.02333"
"4010","24.02400","2.00217","0.02400"
"4024","24.10800","2.00917","0.02389"
"4038","24.19200","2.01616","0.02395"
"4052","24.27600","2.02316","0.02391"
"4066","24.36000","2.03015","0.02389"
"4080","24.44400","2.03715","0.02361"
"4094","24.52800","2.04420","0.02366"
"4108","24.61200","2.05114","0.02379"
"4122","24.69600","2.05819","0.02384"
"4136","24.78000","2.06513","0.02371"
"4150","24.86400","2.07225","0.02345"
"4164","24.94800","2.07918","0.02370"
"4178","25.03200","2.08618","0.02403"
"4192","25.11600","2.09311","0.02358"
"4206","25.20000","2.10011","0.02375"
"4220","25.28400","2.10716","0.02326"
"4234","25.36800","2.11422","0.02363"
"4248","25.45200","2.12121","0.02386"
"4262","25.53600","2.12815","0.02401"
"4276","25.62000","2.13514","0.02373"
"4290","25.70400","2.14214","0.02380"
"4304","25.78800","2.14913","0.02387"
"4318","25.87200","2.15619","0.02399"
"4332","25.95600","2.16319","0.02383"
"4346","26.04000","2.17018","0.02435"
"4360","26.12400","2.17724","0.02387"
"4374","26.20800","2.18411","0.02415"
"4388","26.29200","2.19111","0.02400"
"4402","26.37600","2.19822","0.02422"
"4416","26.46000","2.20516","0.02347"
"4430","26.54400","2.21221","0.02362"
"4444","26.62800","2.21921","0.02388"
"4458","26.71200","2.22620","0.02395"
"4472","26.79600","2.23314","0.02398"
"4486","26.88000","2.24013","0.02408"
"4500","26.96400","2.24725","0.02453"
"4514","27.04800","2.25413","0.02376"
"4528","27.13200","2.26124","0.02402"
"4542","27.21600","2.26818","0.02380"
"4556","27.30000","2.27511","0.02361"
"4570","27.38400","2.28217","0.02391"
"4584","27.46800","2.28916","0.02417"
"4598","27.55200","2.29622","0.02404"
"4612","27.63600","2.30321","0.02371"
"4626","27.72000","2.31021","0.02412"
"4640","27.80400","2.31714","0.02423"
"4654","27.88800","2.32414","0.02346"
"4668","27.97200","2.33119","0.02373"
"4682","28.05600","2.33825","0.02405"
"4696","28.14000","2.34518","0.02381"
"4710","28.22400","2.35218","0.02380"
"4724","28.30800","2.35918","0.02380"
"4738","28.39200","2.36617","0.02409"
"4752","28.47600","2.37311","0.02392"
"4766","28.56000","2.38022","0.02374"
"4780","28.64400","2.38722","0.02424"
"4794","28.72800","2.39421","0.02440"
"4808","28.81200","2.40115","0.02370"
"4822","28.89600","2.40814","0.02386"
"4836","28.98000","2.41514","0.02396"
"4850","29.06400","2.42213","0.02396"
"4864","29.14800","2.42919","0.02411"
"4878","29.23200","2.43618","0.02447"
"4892","29.31600","2.44318","0.02362"
"4906","29.40000","2.45012","0.02376"
"4920","29.48400","2.45711","0.02409"
"4934","29.56800","2.46417","0.02400"
"4948","29.65200","2.47116","0.02386"
"4962","29.73600","2.47816","0.02389"
"4976","29.82000","2.48521","0.02372"
"4990","29.90400","2.49215","0.02412"
"5004","29.98800","2.49914","0.02428"
"5018","30.07200","2.50608","0.02385"
"5032","30.15600","2.51313","0.02421"
"5046","30.24000","2.52019","0.02391"
"5060","30.32400","2.52718","0.02450"
"5074","30.40800","2.53424","0.02391"
"5088","30.49200","2.54117","0.02390"
"5102","30.57600","2.54817","0.02410"
"5116","30.66000","2.55517","0.02403"
"5130","30.74400","2.56222","0.02381"
"5144","30.82800","2.56922","0.02400"
"5158","30.91200","2.57621","0.02386"
"5172","30.99600","2.58321","0.02378"
"5186","31.08000","2.59008","0.02403"
"5200","31.16400","2.59714","0.02416"
"5214","31.24800","2.60419","0.02421"
"5228","31.33200","2.61113","0.02395"
"5242","31.41600","2.61824","0.02400"
"5256","31.50000","2.62518","0.02462"
"5270","31.58400","2.63217","0.02391"
"5284","31.66800","2.63911","0.02421"
"5298","31.75200","2.64616","0.02444"
"5312","31.83600","2.65322","0.02437"
"5326","31.92000","2.66016","0.02403"
"5340","32.00400","2.66721","0.02422"
"5354","32.08800","2.67415","0.02452"
"5368","32.17200","2.68114","0.02346"
"5382","32.25600","2.68814","0.02395"
"5396","32.34000","2.69519","0.02453"
"5410","32.42400","2.70225","0.02431"
"5424","32.50800","2.70918","0.02417"
"5438","32.59200","2.71624","0.02387"
"5452","32.67600","2.72317","0.02451"
"5466","32.76000","2.73017","0.02400"
"5480","32.84400","2.73716","0.02457"
"5494","32.92800","2.74416","0.02417"
"5508","33.01200","2.75122","0.02434"
"5522","33.09600","2.75821","0.02430"
"5536","33.18000","2.76515","0.02450"
"5550","33.26400","2.77214","0.02460"
"5564","33.34800","2.77920","0.02436"
"5578","33.43200","2.78619","0.02425"
"5592","33.51600","2.79319","0.02421"
"5606","33.60000","2.80018","0.02384"
"5620","33.68400","2.80718","0.02433"
"5634","33.76800","2.81417","0.02412"
"5648","33.85200","2.82117","0.02455"
"5662","33.93600","2.82816","0.02396"
"5676","34.02000","2.83522","0.02410"
"5690","34.10400","2.84216","0.02454"
"5704","34.18800","2.84915","0.02423"
"5718","34.27200","2.85615","0.02404"
"5732","34.35600","2.86308","0.02416"
"5746","34.44000","2.87020","0.02403"
"5760","34.52400","2.87713","0.02444"
"5774","34.60800","2.88419","0.02456"
"5788","34.69200","2.89118","0.02421"
"5802","34.77600","2.89812","0.02456"
"5816","34.86000","2.90517","0.02427"
"5830","34.94400","2.91211","0.02476"
"5844","35.02800","2.91922","0.02444"
"5858","35.11200","2.92616","0.02401"
"5872","35.19600","2.93321","0.02468"
"5886","35.28000","2.94021","0.02483"
"5900","35.36400","2.94715","0.02462"
"5914","35.44800","2.95414","0.02456"
"5928","35.53200","2.96120","0.02425"
"5942","35.61600","2.96825","0.02417"
"5956","35.70000","2.97519","0.02483"
"5970","35.78400","2.98218","0.02438"
"5984","35.86800","2.98918","0.02462"
"5998","35.95200","2.99611","0.02437"
"6012","36.03600","3.00323","0.02410"
"6026","36.12000","3.01022","0.02445"
"6040","36.20400","3.01716","0.02388"
"6054","36.28800","3.02421","0.02362"
"6068","36.37200","3.03115","0.02368"
"6082","36.45600","3.03815","0.02336"
"6096","36.54000","3.04514","0.02381"
"6110","36.62400","3.05220","0.02408"
"6124","36.70800","3.05919","0.02452"
"6138","36.79200","3.06625","0.02394"
"6152","36.87600","3.07318","0.02407"
"6166","36.96000","3.08018","0.02364"
"6180","37.04400","3.08711","0.02366"
"6194","37.12800","3.09417","0.02406"
"6208","37.21200","3.10122","0.02363"
"6222","37.29600","3.10822","0.02459"
"6236","37.38000","3.11521","0.02385"
"6250","37.46400","3.12215","0.02378"
"6264","37.54800","3.12914","0.02360"
"6278","37.63200","3.13614","0.02432"
"6292","37.71600","3.14320","0.02365"
"6306","37.80000","3.15019","0.02369"
"6320","37.88400","3.15725","0.02410"
"6334","37.96800","3.16412","0.02375"
"6348","38.05200","3.17118","0.02372"
"6362","38.13600","3.17811","0.02384"
"6376","38.22000","3.18517","0.02366"
"6390","38.30400","3.19222","0.02401"
"6404","38.38800","3.19916","0.02387"
"6418","38.47200","3.20621","0.02408"
"6432","38.55600","3.21315","0.02384"
"6446","38.64000","3.22009","0.02429"
"6460","38.72400","3.22720","0.02390"
"6474","38.80800","3.23419","0.02428"
"6488","38.89200","3.24125","0.02409"
"6502","38.97600","3.24819","0.02413"
"6516","39.06000","3.25518","0.02394"
"6530","39.14400","3.26218","0.02381"
"6544","39.22800","3.26917","0.02397"
"6558","39.31200","3.27623","0.02410"
"6572","39.39600","3.28316","0.02426"
"6586","39.48000","3.29022","0.02401"
"6600","39.56400","3.29721","0.02402"
"6614","39.64800","3.30421","0.02382"
"6628","39.73200","3.31114","0.02417"
"6642","39.81600","3.31814","0.02448"
"6656","39.90000","3.32525","0.02389"
"6670","39.98400","3.33219","0.02419"
"6684","40.06800","3.33925","0.02425"
"6698","40.15200","3.34618","0.02413"
"6712","40.23600","3.35312","0.02362"
"6726","40.32000","3.36017","0.02443"
"6740","40.40400","3.36717","0.02395"
"6754","40.48800","3.37416","0.02402"
"6768","40.57200","3.38116","0.02438"
"6782","40.65600","3.38815","0.02427"
"6796","40.74000","3.39515","0.02430"
"6810","40.82400","3.40214","0.02425"
"6824","40.90800","3.40914","0.02409"
"6838","40.99200","3.41619","0.02399"
"6852","41.07600","3.42319","0.02428"
"6866","41.16000","3.43019","0.02406"
"6880","41.24400","3.43718","0.02395"
"6894","41.32800","3.44418","0.02424"
"6908","41.41200","3.45117","0.02404"
"6922","41.49600","3.45823","0.02438"
"6936","41.58000","3.46522","0.02385"
"6950","41.66400","3.47222","0.02436"
"6964","41.74800","3.47921","0.02394"
"6978","41.83200","3.48615","0.02433"
"6992","41.91600","3.49320","0.02385"
"7006","42.00000","3.50014","0.02388"
"7020","42.08400","3.50719","0.02419"
"7034","42.16800","3.51419","0.02413"
"7048","42.25200","3.52113","0.02408"
"7062","42.33600","3.52818","0.02409"
"7076","42.42000","3.53512","0.02444"
"7090","42.50400","3.54211","0.02443"
"7104","42.58800","3.54917","0.02395"
"7118","42.67200","3.55616","0.02379"
"7132","42.75600","3.56316","0.02448"
"7146","42.84000","3.57009","0.02397"
"7160","42.92400","3.57715","0.02446"
"7174","43.00800","3.58414","0.02465"
"7188","43.09200","3.59120","0.02450"
"7202","43.17600","3.59825","0.02415"
"7216","43.26000","3.60519","0.02389"
"7230","43.34400","3.61218","0.02402"
"7244","43.42800","3.61912","0.02399"
"7258","43.51200","3.62618","0.02429"
"7272","43.59600","3.63323","0.02384"
"7286","43.68000","3.64023","0.02449"
"7300","43.76400","3.64722","0.02346"
"7314","43.84800","3.65416","0.02425"
"7328","43.93200","3.66121","0.02436"
"7342","44.01600","3.66809","0.02428"
"7356","44.10000","3.67514","0.02379"
"7370","44.18400","3.68220","0.02394"
"7384","44.26800","3.68919","0.02436"
"7398","44.35200","3.69619","0.02397"
"7412","44.43600","3.70318","0.02396"
"7426","44.52000","3.71018","0.02384"
"7440","44.60400","3.71718","0.02463"
"7454","44.68800","3.72423","0.02433"
"7468","44.77200","3.73117","0.02412"
"7482","44.85600","3.73822","0.02424"
"7496","44.94000","3.74516","0.02438"
"7510","45.02400","3.75215","0.02415"
"7524","45.10800","3.75909","0.02445"
"7538","45.19200","3.76620","0.02399"
"7552","45.27600","3.77320","0.02423"
"7566","45.36000","3.78019","0.02415"
"7580","45.44400","3.78719","0.02423"
"7594","45.52800","3.79418","0.02412"
"7608","45.61200","3.80118","0.02434"
"7622","45.69600","3.80812","0.02455"
"7636","45.78000","3.81523","0.02415"
"7650","45.86400","3.82223","0.02427"
"7664","45.94800","3.82922","0.02401"
"7678","46.03200","3.83622","0.02402"
"7692","46.11600","3.84315","0.02436"
"7706","46.20000","3.85015","0.02464"
"7720","46.28400","3.85714","0.02460"
"7734","46.36800","3.86426","0.02394"
"7748","46.45200","3.87119","0.02450"
"7762","46.53600","3.87819","0.02445"
"7776","46.62000","3.88518","0.02423"
"7790","46.70400","3.89212","0.02437"
"7804","46.78800","3.89917","0.02387"
"7818","46.87200","3.90617","0.02429"
"7832","46.95600","3.91317","0.02432"
"7846","47.04000","3.92022","0.02439"
"7860","47.12400","3.92716","0.02411"
"7874","47.20800","3.93415","0.02448"
"7888","47.29200","3.94109","0.02415"
"7902","47.37600","3.94820","0.02398"
"7916","47.46000","3.95520","0.02456"
"7930","47.54400","3.96219","0.02389"
"7944","47.62800","3.96925","0.02430"
"7958","47.71200","3.97618","0.02446"
"7972","47.79600","3.98318","0.02442"
"7986","47.88000","3.99017","0.02440"
"8000","47.96400","3.99723","0.02401"
"8014","48.04800","4.00422","0.02445"
"8028","48.13200","4.01122","0.02454"
"8042","48.21600","4.01822","0.02446"
"8056","48.30000","4.02515","0.02422"
"8070","48.38400","4.03215","0.02441"
"8084","48.46800","4.03920","0.02407"
"8098","48.55200","4.04620","0.02360"
"8112","48.63600","4.05319","0.02440"
"8126","48.72000","4.06025","0.02407"
"8140","48.80400","4.06712","0.02405"
"8154","48.88800","4.07406","0.02410"
"8168","48.97200","4.08117","0.02388"
"8182","49.05600","4.08823","0.02431"
"8196","49.14000","4.09516","0.02449"
"8210","49.22400","4.10222","0.02487"
"8224","49.30800","4.10916","0.02440"
"8238","49.39200","4.11615","0.02460"
"8252","49.47600","4.12315","0.02426"
"8266","49.56000","4.13020","0.02411"
"8280","49.64400","4.13720","0.02426"
"8294","49.72800","4.14413","0.02439"
"8308","49.81200","4.15119","0.02449"
"8322","49.89600","4.15812","0.02446"
"8336","49.98000","4.16512","0.02439"
"8350","50.06400","4.17217","0.02401"
"8364","50.14800","4.17917","0.02434"
"8378","50.23200","4.18622","0.02463"
"8392","50.31600","4.19316","0.02446"
"8406","50.40000","4.20015","0.02428"
"8420","50.48400","4.20715","0.02391"
"8434","50.56800","4.21415","0.02412"
"8448","50.65200","4.22126","0.02408"
"8462","50.73600","4.22820","0.02442"
"8476","50.82000","4.23519","0.02468"
"8490","50.90400","4.24213","0.02460"
"8504","50.98800","4.24918","0.02377"
"8518","51.07200","4.25618","0.02441"
"8532","51.15600","4.26317","0.02435"
"8546","51.24000","4.27023","0.02402"
"8560","51.32400","4.27716","0.02446"
"8574","51.40800","4.28416","0.02424"
"8588","51.49200","4.29115","0.02459"
"8602","51.57600","4.29815","0.02426"
"8616","51.66000","4.30521","0.02489"
"8630","51.74400","4.31220","0.02371"
"8644","51.82800","4.31920","0.02445"
"8658","51.91200","4.32619","0.02451"
"8672","51.99600","4.33313","0.02425"
"8686","52.08000","4.34012","0.02399"
"8700","52.16400","4.34718","0.02473"
"8714","52.24800","4.35417","0.02436"
"8728","52.33200","4.36117","0.02422"
"8742","52.41600","4.36822","0.02468"
"8756","52.50000","4.37522","0.02443"
"8770","52.58400","4.38215","0.02444"
"8784","52.66800","4.38915","0.02439"
"8798","52.75200","4.39620","0.02437"
"8812","52.83600","4.40320","0.02459"
"8826","52.92000","4.41020","0.02408"
"8840","53.00400","4.41713","0.02399"
"8854","53.08800","4.42419","0.02432"
"8868","53.17200","4.43106","0.02442"
"8882","53.25600","4.43818","0.02462"
"8896","53.34000","4.44523","0.02458"
"8910","53.42400","4.45217","0.02450"
"8924","53.50800","4.45922","0.02433"
"8938","53.59200","4.46616","0.02475"
"8952","53.67600","4.47315","0.02397"
"8966","53.76000","4.48015","0.02462"
"8980","53.84400","4.48720","0.02477"
"8994","53.92800","4.49426","0.02480"
"9008","54.01200","4.50125","0.02407"
"9022","54.09600","4.50819","0.02432"
"9036","54.18000","4.51513","0.02414"
"9050","54.26400","4.52212","0.02427"
"9064","54.34800","4.52918","0.02412"
"9078","54.43200","4.53623","0.02468"
"9092","54.51600","4.54323","0.02484"
"9106","54.60000","4.55016","0.02423"
"9120","54.68400","4.55722","0.02427"
"9134","54.76800","4.56415","0.02427"
"9148","54.85200","4.57121","0.02461"
"9162","54.93600","4.57820","0.02477"
"9176","55.02000","4.58514","0.02463"
"9190","55.10400","4.59225","0.02449"
"9204","55.18800","4.59913","0.02429"
"9218","55.27200","4.60613","0.02489"
"9232","55.35600","4.61312","0.02443"
"9246","55.44000","4.62018","0.02406"
"9260","55.52400","4.62723","0.02452"
"9274","55.60800","4.63417","0.02411"
"9288","55.69200","4.64116","0.02469"
"9302","55.77600","4.64816","0.02473"
"9316","55.86000","4.65515","0.02441"
"9330","55.94400","4.66221","0.02472"
"9344","56.02800","4.66920","0.02442"
"9358","56.11200","4.67620","0.02443"
"9372","56.19600","4.68325","0.02443"
"9386","56.28000","4.69019","0.02480"
"9400","56.36400","4.69719","0.02442"
"9414","56.44800","4.70418","0.02469"
"9428","56.53200","4.71118","0.02443"
"9442","56.61600","4.71817","0.02459"
"9456","56.70000","4.72523","0.02483"
"9470","56.78400","4.73222","0.02462"
"9484","56.86800","4.73916","0.02469"
"9498","56.95200","4.74615","0.02445"
"9512","57.03600","4.75315","0.02411"
"9526","57.12000","4.76020","0.02469"
"9540","57.20400","4.76720","0.02496"
"9554","57.28800","4.77419","0.02420"
"9568","57.37200","4.78119","0.02438"
"9582","57.45600","4.78813","0.02470"
"9596","57.54000","4.79512","0.02444"
"9610","57.62400","4.80218","0.02432"
"9624","57.70800","4.80923","0.02461"
"9638","57.79200","4.81617","0.02421"
"9652","57.87600","4.82322","0.02494"
"9666","57.96000","4.83016","0.02423"
"9680","58.04400","4.83709","0.02470"
"9694","58.12800","4.84415","0.02478"
"9708","58.21200","4.85120","0.02463"
"9722","58.29600","4.85820","0.02448"
"9736","58.38000","4.86519","0.02457"
"9750","58.46400","4.87219","0.02472"
"9764","58.54800","4.87918","0.02469"
"9778","58.63200","4.88612","0.02425"
"9792","58.71600","4.89323","0.02473"
"9806","58.80000","4.90023","0.02445"
"9820","58.88400","4.90717","0.02435"
"9834","58.96800","4.91422","0.02446"
"9848","59.05200","4.92116","0.02428"
"9862","59.13600","4.92821","0.02494"
"9876","59.22000","4.93521","0.02463"
"9890","59.30400","4.94220","0.02501"
"9904","59.38800","4.94920","0.02397"
"9918","59.47200","4.95613","0.02480"
"9932","59.55600","4.96319","0.02472"
"9946","59.64000","4.97012","0.02492"
"9960","59.72400","4.97712","0.02498"
"9974","59.80800","4.98418","0.02473"
"9988","59.89200","4.99117","0.02428"
"10002","59.97600","4.99823","0.02450"
"10016","60.06000","5.00510","0.02479"
"10030","60.14400","5.01216","0.02489"
"10044","60.22800","5.01915","0.02479"
"10058","60.31200","5.02615","0.02448"
"10072","60.39600","5.03320","0.02453"
"10086","60.48000","5.04020","0.02484"
"10100","60.56400","5.04719","0.02432"
"10114","60.64800","5.05413","0.02446"
"10128","60.73200","5.06112","0.02484"
"10142","60.81600","5.06818","0.02463"
"10156","60.90000","5.07517","0.02443"
"10170","60.98400","5.08223","0.02497"
"10184","61.06800","5.08917","0.02442"
"10198","61.15200","5.09616","0.02484"
"10212","61.23600","5.10310","0.02457"
"10226","61.32000","5.11015","0.02438"
"10240","61.40400","5.11721","0.02471"
"10254","61.48800","5.12420","0.02487"
"10268","61.57200","5.13120","0.02486"
"10282","61.65600","5.13813","0.02474"
"10296","61.74000","5.14519","0.02472"
"10310","61.82400","5.15212","0.02490"
"10324","61.90800","5.15918","0.02464"
"10338","61.99200","5.16617","0.02458"
"10352","62.07600","5.17317","0.02483"
"10366","62.16000","5.18023","0.02466"
"10380","62.24400","5.18716","0.02480"
"10394","62.32800","5.19410","0.02471"
"10408","62.41200","5.20115","0.02457"
"10422","62.49600","5.20815","0.02451"
"10436","62.58000","5.21520","0.02462"
"10450","62.66400","5.22220","0.02464"
"10464","62.74800","5.22913","0.02486"
"10478","62.83200","5.23613","0.02470"
"10492","62.91600","5.24312","0.02457"
"10506","63.00000","5.25024","0.02417"
"10520","63.08400","5.25717","0.02429"
"10534","63.16800","5.26417","0.02466"
"10548","63.25200","5.27122","0.02447"
"10562","63.33600","5.27816","0.02467"
"10576","63.42000","5.28516","0.02496"
"10590","63.50400","5.29215","0.02450"
"10604","63.58800","5.29921","0.02423"
"10618","63.67200","5.30620","0.02424"
"10632","63.75600","5.31320","0.02451"
"10646","63.84000","5.32013","0.02473"
"10660","63.92400","5.32713","0.02459"
"10674","64.00800","5.33418","0.02486"
"10688","64.09200","5.34118","0.02448"
"10702","64.17600","5.34823","0.02504"
"10716","64.26000","5.35523","0.02450"
"10730","64.34400","5.36216","0.02484"
"10744","64.42800","5.36916","0.02478"
"10758","64.51200","5.37609","0.02480"
"10772","64.59600","5.38321","0.02457"
"10786","64.68000","5.39021","0.02470"
"10800","64.76400","5.39720","0.02506"
"10814","64.84800","5.40426","0.02500"
"10828","64.93200","5.41119","0.02488"
"10842","65.01600","5.41819","0.02485"
"10856","65.10000","5.42518","0.02459"
"10870","65.18400","5.43218","0.02465"
"10884","65.26800","5.43923","0.02496"
"10898","65.35200","5.44623","0.02477"
"10912","65.43600","5.45322","0.02502"
"10926","65.52000","5.46016","0.02503"
"10940","65.60400","5.46721","0.02489"
"10954","65.68800","5.47421","0.02477"
"10968","65.77200","5.48121","0.02510"
"10982","65.85600","5.48820","0.02477"
"10996","65.94000","5.49520","0.02469"
"11010","66.02400","5.50219","0.02485"
"11024","66.10800","5.50913","0.02432"
"11038","66.19200","5.51618","0.02493"
"11052","66.27600","5.52324","0.02456"
"11066","66.36000","5.53017","0.02482"
"11080","66.44400","5.53729","0.02481"
"11094","66.52800","5.54416","0.02427"
"11108","66.61200","5.55116","0.02470"
"11122","66.69600","5.55815","0.02474"
"11136","66.78000","5.56521","0.02498"
"11150","66.86400","5.57227","0.02473"
"11164","66.94800","5.57920","0.02516"
"11178","67.03200","5.58620","0.02545"
"11192","67.11600","5.59319","0.02481"
"11206","67.20000","5.60019","0.02516"
"11220","67.28400","5.60718","0.02486"
"11234","67.36800","5.61418","0.02486"
"11248","67.45200","5.62123","0.02469"
"11262","67.53600","5.62817","0.02487"
"11276","67.62000","5.63516","0.02475"
"11290","67.70400","5.64216","0.02453"
"11304","67.78800","5.64915","0.02504"
"11318","67.87200","5.65621","0.02496"
"11332","67.95600","5.66315","0.02498"
"11346","68.04000","5.67014","0.02434"
"11360","68.12400","5.67714","0.02494"
"11374","68.20800","5.68407","0.02481"
"11388","68.29200","5.69119","0.02437"
"11402","68.37600","5.69818","0.02460"
"11416","68.46000","5.70518","0.02465"
"11430","68.54400","5.71217","0.02486"
"11444","68.62800","5.71917","0.02456"
"11458","68.71200","5.72616","0.02455"
"11472","68.79600","5.73316","0.02467"
"11486","68.88000","5.74015","0.02476"
"11500","68.96400","5.74715","0.02480"
"11514","69.04800","5.75414","0.02481"
"11528","69.13200","5.76120","0.02479"
"11542","69.21600","5.76820","0.02468"
"11556","69.30000","5.77513","0.02492"
"11570","69.38400","5.78219","0.02499"
"11584","69.46800","5.78918","0.02474"
"11598","69.55200","5.79618","0.02493"
"11612","69.63600","5.80323","0.02494"
"11626","69.72000","5.81023","0.02486"
"11640","69.80400","5.81716","0.02511"
"11654","69.88800","5.82416","0.02470"
"11668","69.97200","5.83121","0.02459"
"11682","70.05600","5.83821","0.02479"
"11696","70.14000","5.84520","0.02468"
"11710","70.22400","5.85220","0.02507"
"11724","70.30800","5.85920","0.02510"
"11738","70.39200","5.86607","0.02480"
"11752","70.47600","5.87319","0.02445"
"11766","70.56000","5.88018","0.02514"
"11780","70.64400","5.88718","0.02489"
"11794","70.72800","5.89423","0.02453"
"11808","70.81200","5.90117","0.02450"
"11822","70.89600","5.90816","0.02479"
"11836","70.98000","5.91510","0.02536"
"11850","71.06400","5.92221","0.02475"
"11864","71.14800","5.92927","0.02469"
"11878","71.23200","5.93620","0.02511"
"11892","71.31600","5.94326","0.02473"
"11906","71.40000","5.95019","0.02488"
"11920","71.48400","5.95713","0.02443"
"11934","71.56800","5.96419","0.02496"
"11948","71.65200","5.97124","0.02481"
"11962","71.73600","5.97824","0.02515"
"11976","71.82000","5.98517","0.02532"
"11990","71.90400","5.99223","0.02459"
"12004","71.98800","5.99916","0.02492"
"12018","72.07200","6.00616","0.02464"
"12032","72.15600","6.01321","0.02497"
"12046","72.24000","6.02015","0.02528"
"12060","72.32400","6.02720","0.02463"
"12074","72.40800","6.03414","0.02516"
"12088","72.49200","6.04113","0.02486"
"12102","72.57600","6.04813","0.02441"
"12116","72.66000","6.05513","0.02520"
"12130","72.74400","6.06218","0.02448"
"12144","72.82800","6.06924","0.02488"
"12158","72.91200","6.07617","0.02498"
"12172","72.99600","6.08317","0.02517"
"12186","73.08000","6.09016","0.02478"
"12200","73.16400","6.09716","0.02479"
"12214","73.24800","6.10421","0.02520"
"12228","73.33200","6.11121","0.02498"
"12242","73.41600","6.11820","0.02552"
"12256","73.50000","6.12520","0.02505"
"12270","73.58400","6.13213","0.02501"
"12284","73.66800","6.13919","0.02482"
"12298","73.75200","6.14618","0.02466"
"12312","73.83600","6.15318","0.02509"
"12326","73.92000","6.16024","0.02496"
"12340","74.00400","6.16717","0.02513"
"12354","74.08800","6.17417","0.02447"
"12368","74.17200","6.18116","0.02502"
"12382","74.25600","6.18816","0.02474"
"12396","74.34000","6.19521","0.02544"
"12410","74.42400","6.20215","0.02499"
"12424","74.50800","6.20920","0.02468"
"12438","74.59200","6.21614","0.02452"
"12452","74.67600","6.22313","0.02509"
"12466","74.76000","6.23019","0.02502"
"12480","74.84400","6.23718","0.02462"
"12494","74.92800","6.24418","0.02484"
"12508","75.01200","6.25117","0.02522"
"12522","75.09600","6.25817","0.02540"
"12536","75.18000","6.26517","0.02505"
"12550","75.26400","6.27210","0.02536"
"12564","75.34800","6.27916","0.02481"
"12578","75.43200","6.28621","0.02546"
"12592","75.51600","6.29315","0.02502"
"12606","75.60000","6.30020","0.02493"
"12620","75.68400","6.30714","0.02511"
"12634","75.76800","6.31419","0.02481"
"12648","75.85200","6.32119","0.02490"
"12662","75.93600","6.32818","0.02506"
"12676","76.02000","6.33524","0.02473"
"12690","76.10400","6.34223","0.02511"
"12704","76.18800","6.34923","0.02521"
"12718","76.27200","6.35617","0.02496"
"12732","76.35600","6.36322","0.02505"
"12746","76.44000","6.37022","0.02455"
"12760","76.52400","6.37721","0.02507"
"12774","76.60800","6.38421","0.02521"
"12788","76.69200","6.39120","0.02512"
"12802","76.77600","6.39814","0.02426"
"12816","76.86000","6.40513","0.02411"
"12830","76.94400","6.41219","0.02470"
"12844","77.02800","6.41918","0.02505"
"12858","77.11200","6.42624","0.02408"
"12872","77.19600","6.43317","0.02492"
"12886","77.28000","6.44011","0.02507"
"12900","77.36400","6.44717","0.02480"
"12914","77.44800","6.45416","0.02493"
"12928","77.53200","6.46116","0.02523"
"12942","77.61600","6.46821","0.02513"
"12956","77.70000","6.47521","0.02480"
"12970","77.78400","6.48226","0.02530"
"12984","77.86800","6.48914","0.02501"
"12998","77.95200","6.49613","0.02485"
"13012","78.03600","6.50319","0.02497"
"13026","78.12000","6.51018","0.02531"
"13040","78.20400","6.51724","0.02469"
"13054","78.28800","6.52417","0.02514"
"13068","78.37200","6.53117","0.02522"
"13082","78.45600","6.53811","0.02495"
"13096","78.54000","6.54516","0.02501"
"13110","78.62400","6.55222","0.02539"
"13124","78.70800","6.55915","0.02490"
"13138","78.79200","6.56621","0.02499"
"13152","78.87600","6.57314","0.02485"
"13166","78.96000","6.58014","0.02521"
"13180","79.04400","6.58713","0.02508"
"13194","79.12800","6.59419","0.02517"
"13208","79.21200","6.60124","0.02482"
"13222","79.29600","6.60818","0.02494"
"13236","79.38000","6.61523","0.02549"
"13250","79.46400","6.62217","0.02543"
"13264","79.54800","6.62911","0.02500"
"13278","79.63200","6.63622","0.02554"
"13292","79.71600","6.64321","0.02523"
"13306","79.80000","6.65021","0.02490"
"13320","79.88400","6.65721","0.02477"
"13334","79.96800","6.66420","0.02523"
"13348","80.05200","6.67114","0.02434"
"13362","80.13600","6.67807","0.02469"
"13376","80.22000","6.68525","0.02496"
"13390","80.30400","6.69218","0.02499"
"13404","80.38800","6.69918","0.02474"
"13418","80.47200","6.70617","0.02511"
"13432","80.55600","6.71317","0.02513"
"13446","80.64000","6.72016","0.02523"
"13460","80.72400","6.72716","0.02489"
"13474","80.80800","6.73421","0.02540"
"13488","80.89200","6.74121","0.02501"
"13502","80.97600","6.74815","0.02495"
"13516","81.06000","6.75514","0.02470"
"13530","81.14400","6.76214","0.02535"
"13544","81.22800","6.76913","0.02494"
"13558","81.31200","6.77619","0.02515"
"13572","81.39600","6.78318","0.02492"
"13586","81.48000","6.79024","0.02510"
"13600","81.56400","6.79717","0.02515"
"13614","81.64800","6.80417","0.02520"
"13628","81.73200","6.81110","0.02524"
"13642","81.81600","6.81822","0.02499"
"13656","81.90000","6.82521","0.02531"
"13670","81.98400","6.83221","0.02537"
"13684","82.06800","6.83921","0.02489"
"13698","82.15200","6.84614","0.02506"
"13712","82.23600","6.85314","0.02480"
"13726","82.32000","6.86019","0.02504"
"13740","82.40400","6.86719","0.02503"
"13754","82.48800","6.87418","0.02503"
"13768","82.57200","6.88124","0.02565"
"13782","82.65600","6.88823","0.02532"
"13796","82.74000","6.89517","0.02525"
"13810","82.82400","6.90216","0.02584"
"13824","82.90800","6.90916","0.02504"
"13838","82.99200","6.91615","0.02517"
"13852","83.07600","6.92321","0.02519"
"13866","83.16000","6.93015","0.02518"
"13880","83.24400","6.93714","0.02553"
"13894","83.32800","6.94408","0.02527"
"13908","83.41200","6.95113","0.02503"
"13922","83.49600","6.95825","0.02501"
"13936","83.58000","6.96518","0.02536"
"13950","83.66400","6.97224","0.02538"
"13964","83.74800","6.97917","0.02483"
"13978","83.83200","6.98617","0.02523"
"13992","83.91600","6.99316","0.02510"
"14006","84.00000","7.00022","0.02573"
"14020","84.08400","7.00721","0.02545"
"14034","84.16800","7.01421","0.02531"
"14048","84.25200","7.02120","0.02515"
"14062","84.33600","7.02820","0.02496"
"14076","84.42000","7.03519","0.02536"
"14090","84.50400","7.04219","0.02537"
"14104","84.58800","7.04925","0.02523"
"14118","84.67200","7.05624","0.02529"
"14132","84.75600","7.06318","0.02516"
"14146","84.84000","7.07017","0.02523"
"14160","84.92400","7.07717","0.02523"
"14174","85.00800","7.08416","0.02490"
"14188","85.09200","7.09122","0.02523"
"14202","85.17600","7.09815","0.02537"
"14216","85.26000","7.10521","0.02561"
"14230","85.34400","7.11214","0.02528"
"14244","85.42800","7.11914","0.02532"
"14258","85.51200","7.12620","0.02505"
"14272","85.59600","7.13319","0.02487"
"14286","85.68000","7.14019","0.02540"
"14300","85.76400","7.14718","0.02487"
"14314","85.84800","7.15418","0.02512"
"14328","85.93200","7.16117","0.02537"
"14342","86.01600","7.16811","0.02522"
"14356","86.10000","7.17516","0.02544"
"14370","86.18400","7.18216","0.02539"
"14384","86.26800","7.18915","0.02531"
"14398","86.35200","7.19621","0.02533"
"14412","86.43600","7.20314","0.02518"
"14426","86.52000","7.21014","0.02498"
"14440","86.60400","7.21714","0.02511"
"14454","86.68800","7.22425","0.02517"
"14468","86.77200","7.23119","0.02514"
"14482","86.85600","7.23818","0.02539"
"14496","86.94000","7.24524","0.02546"
"14510","87.02400","7.25211","0.02542"
"14524","87.10800","7.25917","0.02522"
"14538","87.19200","7.26616","0.02496"
"14552","87.27600","7.27322","0.02521"
"14566","87.36000","7.28021","0.02530"
"14580","87.44400","7.28721","0.02551"
"14594","87.52800","7.29414","0.02507"
"14608","87.61200","7.30108","0.02545"
"14622","87.69600","7.30819","0.02489"
"14636","87.78000","7.31519","0.02540"
"14650","87.86400","7.32218","0.02525"
"14664","87.94800","7.32924","0.02551"
"14678","88.03200","7.33612","0.02505"
"14692","88.11600","7.34311","0.02528"
"14706","88.20000","7.35011","0.02491"
"14720","88.28400","7.35716","0.02520"
"14734","88.36800","7.36422","0.02542"
"14748","88.45200","7.37121","0.02542"
"14762","88.53600","7.37821","0.02577"
"14776","88.62000","7.38520","0.02515"
"14790","88.70400","7.39214","0.02515"
"14804","88.78800","7.39919","0.02541"
"14818","88.87200","7.40625","0.02543"
"14832","88.95600","7.41324","0.02514"
"14846","89.04000","7.42018","0.02534"
"14860","89.12400","7.42718","0.02557"
"14874","89.20800","7.43417","0.02511"
"14888","89.29200","7.44117","0.02494"
"14902","89.37600","7.44822","0.02539"
"14916","89.46000","7.45516","0.02524"
"14930","89.54400","7.46221","0.02520"
"14944","89.62800","7.46915","0.02498"
"14958","89.71200","7.47614","0.02427"
"14972","89.79600","7.48314","0.02530"
"14986","89.88000","7.49019","0.02525"
"15000","89.96400","7.49719","0.02522"
"15014","90.04800","7.50424","0.02511"
"15028","90.13200","7.51118","0.02516"
"15042","90.21600","7.51818","0.02574"
"15056","90.30000","7.52517","0.02568"
"15070","90.38400","7.53217","0.02524"
"15084","90.46800","7.53922","0.02543"
"15098","90.55200","7.54622","0.02509"
"15112","90.63600","7.55321","0.02517"
"15126","90.72000","7.56021","0.02543"
"15140","90.80400","7.56714","0.02504"
"15154","90.88800","7.57414","0.02531"
"15168","90.97200","7.58119","0.02542"
"15182","91.05600","7.58819","0.02537"
"15196","91.14000","7.59518","0.02461"
"15210","91.22400","7.60218","0.02541"
"15224","91.30800","7.60918","0.02507"
"15238","91.39200","7.61617","0.02549"
"15252","91.47600","7.62317","0.02518"
"15266","91.56000","7.63022","0.02540"
"15280","91.64400","7.63716","0.02518"
"15294","91.72800","7.64421","0.02565"
"15308","91.81200","7.65121","0.02537"
"15322","91.89600","7.65814","0.02510"
"15336","91.98000","7.66520","0.02498"
"15350","92.06400","7.67219","0.02474"
"15364","92.14800","7.67925","0.02484"
"15378","92.23200","7.68618","0.02528"
"15392","92.31600","7.69318","0.02531"
"15406","92.40000","7.70018","0.02547"
"15420","92.48400","7.70717","0.02499"
"15434","92.56800","7.71417","0.02549"
"15448","92.65200","7.72122","0.02565"
"15462","92.73600","7.72816","0.02541"
"15476","92.82000","7.73515","0.02540"
"15490","92.90400","7.74215","0.02564"
"15504","92.98800","7.74914","0.02499"
"15518","93.07200","7.75614","0.02488"
"15532","93.15600","7.76319","0.02534"
"15546","93.24000","7.77019","0.02525"
"15560","93.32400","7.77718","0.02529"
"15574","93.40800","7.78418","0.02532"
"15588","93.49200","7.79117","0.02525"
"15602","93.57600","7.79811","0.02513"
"15616","93.66000","7.80517","0.02547"
"15630","93.74400","7.81216","0.02513"
"15644","93.82800","7.81916","0.02536"
"15658","93.91200","7.82615","0.02518"
"15672","93.99600","7.83315","0.02529"
"15686","94.08000","7.84014","0.02522"
"15700","94.16400","7.84714","0.02541"
"15714","94.24800","7.85419","0.02497"
"15728","94.33200","7.86119","0.02500"
"15742","94.41600","7.86818","0.02533"
"15756","94.50000","7.87512","0.02533"
"15770","94.58400","7.88217","0.02547"
"15784","94.66800","7.88917","0.02535"
"15798","94.75200","7.89616","0.02564"
"15812","94.83600","7.90322","0.02537"
"15826","94.92000","7.91021","0.02546"
"15840","95.00400","7.91715","0.02571"
"15854","95.08800","7.92409","0.02521"
"15868","95.17200","7.93120","0.02532"
"15882","95.25600","7.93820","0.02543"
"15896","95.34000","7.94519","0.02552"
"15910","95.42400","7.95225","0.02562"
"15924","95.50800","7.95918","0.02546"
"15938","95.59200","7.96618","0.02531"
"15952","95.67600","7.97311","0.02519"
"15966","95.76000","7.98017","0.02583"
"15980","95.84400","7.98728","0.02552"
"15994","95.92800","7.99416","0.02529"
"16008","96.01200","8.00115","0.02547"
"16022","96.09600","8.00815","0.02506"
"16036","96.18000","8.01515","0.02565"
"16050","96.26400","8.02214","0.02532"
"16064","96.34800","8.02920","0.02504"
"16078","96.43200","8.03619","0.02583"
"16092","96.51600","8.04319","0.02554"
"16106","96.60000","8.05018","0.02533"
"16120","96.68400","8.05718","0.02551"
"16134","96.76800","8.06411","0.02544"
"16148","96.85200","8.07117","0.02555"
"16162","96.93600","8.07822","0.02565"
"16176","97.02000","8.08522","0.02574"
"16190","97.10400","8.09221","0.02556"
"16204","97.18800","8.09915","0.02505"
"16218","97.27200","8.10614","0.02564"
"16232","97.35600","8.11314","0.02536"
"16246","97.44000","8.12020","0.02588"
"16260","97.52400","8.12719","0.02545"
"16274","97.60800","8.13419","0.02530"
"16288","97.69200","8.14118","0.02557"
"16302","97.77600","8.14818","0.02556"
"16316","97.86000","8.15517","0.02521"
"16330","97.94400","8.16223","0.02555"
"16344","98.02800","8.16916","0.02597"
"16358","98.11200","8.17616","0.02598"
"16372","98.19600","8.18315","0.02524"
"16386","98.28000","8.19015","0.02522"
"16400","98.36400","8.19709","0.02556"
"16414","98.44800","8.20414","0.02538"
"16428","98.53200","8.21114","0.02564"
"16442","98.61600","8.21819","0.02570"
"16456","98.70000","8.22525","0.02523"
"16470","98.78400","8.23212","0.02561"
"16484","98.86800","8.23918","0.02567"
"16498","98.95200","8.24611","0.02607"
"16512","99.03600","8.25317","0.02581"
"16526","99.12000","8.26022","0.02565"
"16540","99.20400","8.26722","0.02565"
"16554","99.28800","8.27421","0.02546"
"16568","99.37200","8.28115","0.02618"
"16582","99.45600","8.28814","0.02542"
"16596","99.54000","8.29514","0.02558"
"16610","99.62400","8.30219","0.02593"
"16624","99.70800","8.30919","0.02566"
"16638","99.79200","8.31625","0.02552"
"16652","99.87600","8.32318","0.02549"
"16666","99.96000","8.33012","0.02548"
"16680","100.04400","8.33717","0.02552"
"16694","100.12800","8.34417","0.02630"
"16708","100.21200","8.35116","0.02571"
"16722","100.29600","8.35822","0.02460"
"16736","100.38000","8.36515","0.02701"
"16750","100.46400","8.37209","0.02720"
"16764","100.54800","8.37908","0.02493"
"16778","100.63200","8.38620","0.02572"
"16792","100.71600","8.39325","0.02601"
"16806","100.80000","8.40013","0.02618"
"16820","100.88400","8.40725","0.02580"
"16834","100.96800","8.41418","0.02571"
"16848","101.05200","8.42112","0.02759"
"16862","101.13600","8.42811","0.02776"
"16876","101.22000","8.43523","0.02563"
"16890","101.30400","8.44222","0.02540"
"16904","101.38800","8.44922","0.03004"
"16918","101.47200","8.45615","0.02906"
"16932","101.55600","8.46321","0.02560"
"16946","101.64000","8.47020","0.02480"
"16960","101.72400","8.47720","0.02396"
"16974","101.80800","8.48425","0.02471"
"16988","101.89200","8.49119","0.02560"
"17002","101.97600","8.49819","0.02396"
"17016","102.06000","8.50518","0.02499"
"17030","102.14400","8.51218","0.02534"
"17044","102.22800","8.51917","0.02465"
"17058","102.31200","8.52629","0.02454"
"17072","102.39600","8.53316","0.02435"
"17086","102.48000","8.54016","0.02496"
"17100","102.56400","8.54715","0.02432"
"17114","102.64800","8.55415","0.02377"
"17128","102.73200","8.56120","0.02457"
"17142","102.81600","8.56814","0.02454"
"17156","102.90000","8.57519","0.02461"
"17170","102.98400","8.58219","0.02516"
"17184","103.06800","8.58913","0.02480"
"17198","103.15200","8.59612","0.02461"
"17212","103.23600","8.60312","0.02476"
"17226","103.32000","8.61023","0.02465"
"17240","103.40400","8.61717","0.02497"
"17254","103.48800","8.62422","0.02501"
"17268","103.57200","8.63122","0.02473"
"17282","103.65600","8.63815","0.02459"
"17296","103.74000","8.64515","0.02534"
"17310","103.82400","8.65214","0.02488"
"17324","103.90800","8.65926","0.02543"
"17338","103.99200","8.66613","0.02462"
"17352","104.07600","8.67319","0.02482"
"17366","104.16000","8.68018","0.02528"
"17380","104.24400","8.68712","0.02511"
"17394","104.32800","8.69418","0.02506"
"17408","104.41200","8.70117","0.02495"
"17422","104.49600","8.70817","0.02442"
"17436","104.58000","8.71516","0.02475"
"17450","104.66400","8.72216","0.02499"
"17464","104.74800","8.72915","0.02453"
"17478","104.83200","8.73609","0.02519"
"17492","104.91600","8.74314","0.02488"
"17506","105.00000","8.75020","0.02463"
"17520","105.08400","8.75719","0.02452"
"17534","105.16800","8.76419","0.02527"
"17548","105.25200","8.77118","0.02517"
"17562","105.33600","8.77818","0.02502"
"17576","105.42000","8.78512","0.02492"
"17590","105.50400","8.79217","0.02527"
"17604","105.58800","8.79917","0.02479"
"17618","105.67200","8.80622","0.02498"
"17632","105.75600","8.81316","0.02485"
"17646","105.84000","8.82015","0.02493"
"17660","105.92400","8.82709","0.02467"
"17674","106.00800","8.83420","0.02521"
"17676","106.02000","8.83516","0.02538"