File: Trajectories_together/170122_1Specimen_RawData_10.csv
"","V1","V2","V3"
"1","End date","1/22/2017",""
"2","Specimen label","12DT_90",""
"3","Maximum Load","0.03407","N"
"4","Time","Extension","Load"
"5","(s)","(mm)","(N)"
"6","0.00000","0.00006","-0.00067"
"57","0.30600","0.02511","0.00033"
"108","0.61200","0.05124","0.00119"
"159","0.91800","0.07671","0.00013"
"210","1.22400","0.10218","0.00214"
"261","1.53000","0.12771","0.00177"
"312","1.83600","0.15324","0.00258"
"363","2.14200","0.17865","0.00268"
"414","2.44800","0.20424","0.00311"
"465","2.75400","0.22971","0.00355"
"516","3.06000","0.25518","0.00341"
"567","3.36600","0.28071","0.00448"
"618","3.67200","0.30618","0.00405"
"669","3.97800","0.33177","0.00385"
"720","4.28400","0.35712","0.00467"
"771","4.59000","0.38271","0.00497"
"822","4.89600","0.40818","0.00575"
"873","5.20200","0.43365","0.00545"
"924","5.50800","0.45918","0.00608"
"975","5.81400","0.48471","0.00592"
"1026","6.12000","0.51024","0.00604"
"1077","6.42600","0.53565","0.00566"
"1128","6.73200","0.56118","0.00589"
"1179","7.03800","0.58665","0.00678"
"1230","7.34400","0.61219","0.00675"
"1281","7.65000","0.63766","0.00693"
"1332","7.95600","0.66319","0.00702"
"1383","8.26200","0.68872","0.00691"
"1434","8.56800","0.71419","0.00739"
"1485","8.87400","0.73972","0.00751"
"1536","9.18000","0.76513","0.00809"
"1587","9.48600","0.79072","0.00740"
"1638","9.79200","0.81619","0.00838"
"1689","10.09800","0.84172","0.00814"
"1740","10.40400","0.86725","0.00809"
"1791","10.71000","0.89272","0.00893"
"1842","11.01600","0.91825","0.00751"
"1893","11.32200","0.94366","0.00812"
"1944","11.62800","0.96919","0.00772"
"1995","11.93400","0.99472","0.00761"
"2046","12.24000","1.02019","0.00794"
"2097","12.54600","1.04572","0.00864"
"2148","12.85200","1.07119","0.00892"
"2199","13.15800","1.09678","0.00920"
"2250","13.46400","1.12213","0.00857"
"2301","13.77000","1.14772","0.00904"
"2352","14.07600","1.17319","0.00938"
"2403","14.38200","1.19866","0.00831"
"2454","14.68800","1.22419","0.00931"
"2505","14.99400","1.24972","0.00936"
"2556","15.30000","1.27525","0.00914"
"2607","15.60600","1.30066","0.00911"
"2658","15.91200","1.32625","0.00930"
"2709","16.21800","1.35172","0.00959"
"2760","16.52400","1.37719","0.00920"
"2811","16.83000","1.40272","0.00949"
"2862","17.13600","1.42819","0.00998"
"2913","17.44200","1.45372","0.01004"
"2964","17.74800","1.47913","0.00980"
"3015","18.05400","1.50466","0.00991"
"3066","18.36000","1.53019","0.01050"
"3117","18.66600","1.55566","0.01084"
"3168","18.97200","1.58113","0.01109"
"3219","19.27800","1.60666","0.01060"
"3270","19.58400","1.63219","0.01060"
"3321","19.89000","1.65766","0.01066"
"3372","20.19600","1.68325","0.01052"
"3423","20.50200","1.70872","0.01077"
"3474","20.80800","1.73420","0.01162"
"3525","21.11400","1.75973","0.01114"
"3576","21.42000","1.78520","0.01104"
"3627","21.72600","1.81073","0.01156"
"3678","22.03200","1.83614","0.01015"
"3729","22.33800","1.86179","0.01048"
"3780","22.64400","1.88720","0.01047"
"3831","22.95000","1.91273","0.00929"
"3882","23.25600","1.93814","0.00939"
"3933","23.56200","1.96367","0.00982"
"3984","23.86800","1.98920","0.00974"
"4035","24.17400","2.01467","0.00983"
"4086","24.48000","2.04026","0.01011"
"4137","24.78600","2.06573","0.01042"
"4188","25.09200","2.09126","0.01070"
"4239","25.39800","2.11673","0.01083"
"4290","25.70400","2.14226","0.01069"
"4341","26.01000","2.16773","0.01065"
"4392","26.31600","2.19314","0.01129"
"4443","26.62200","2.21873","0.01014"
"4494","26.92800","2.24420","0.01027"
"4545","27.23400","2.26973","0.01017"
"4596","27.54000","2.29526","0.01040"
"4647","27.84600","2.32067","0.01049"
"4698","28.15200","2.34620","0.01103"
"4749","28.45800","2.37161","0.01091"
"4800","28.76400","2.39720","0.01100"
"4851","29.07000","2.42267","0.01113"
"4902","29.37600","2.44820","0.01100"
"4953","29.68200","2.47367","0.01184"
"5004","29.98800","2.49920","0.01179"
"5055","30.29400","2.52473","0.01167"
"5106","30.60000","2.55020","0.01166"
"5157","30.90600","2.57573","0.01199"
"5208","31.21200","2.60114","0.01162"
"5259","31.51800","2.62679","0.01186"
"5310","31.82400","2.65220","0.01230"
"5361","32.13000","2.67767","0.01273"
"5412","32.43600","2.70314","0.01245"
"5463","32.74200","2.72867","0.01276"
"5514","33.04800","2.75420","0.01245"
"5565","33.35400","2.77968","0.01328"
"5616","33.66000","2.80526","0.01282"
"5667","33.96600","2.83074","0.01308"
"5718","34.27200","2.85621","0.01335"
"5769","34.57800","2.88168","0.01353"
"5820","34.88400","2.90715","0.01333"
"5871","35.19000","2.93268","0.01383"
"5922","35.49600","2.95815","0.01283"
"5973","35.80200","2.98374","0.01298"
"6024","36.10800","3.00921","0.01276"
"6075","36.41400","3.03474","0.01335"
"6126","36.72000","3.06021","0.01356"
"6177","37.02600","3.08568","0.01402"
"6228","37.33200","3.11121","0.01389"
"6279","37.63800","3.13662","0.01309"
"6330","37.94400","3.16221","0.01377"
"6381","38.25000","3.18768","0.01386"
"6432","38.55600","3.21321","0.01447"
"6483","38.86200","3.23874","0.01477"
"6534","39.16800","3.26421","0.01485"
"6585","39.47400","3.28974","0.01451"
"6636","39.78000","3.31515","0.01530"
"6687","40.08600","3.34074","0.01520"
"6738","40.39200","3.36615","0.01542"
"6789","40.69800","3.39174","0.01565"
"6840","41.00400","3.41721","0.01555"
"6891","41.31000","3.44268","0.01538"
"6942","41.61600","3.46821","0.01569"
"6993","41.92200","3.49368","0.01622"
"7044","42.22800","3.51921","0.01555"
"7095","42.53400","3.54462","0.01555"
"7146","42.84000","3.57021","0.01573"
"7197","43.14600","3.59574","0.01646"
"7248","43.45200","3.62121","0.01652"
"7299","43.75800","3.64674","0.01630"
"7350","44.06400","3.67215","0.01711"
"7401","44.37000","3.69768","0.01706"
"7452","44.67600","3.72315","0.01699"
"7503","44.98200","3.74868","0.01749"
"7554","45.28800","3.77421","0.01734"
"7605","45.59400","3.79974","0.01835"
"7656","45.90000","3.82521","0.01802"
"7707","46.20600","3.85069","0.01799"
"7758","46.51200","3.87622","0.01838"
"7809","46.81800","3.90163","0.01887"
"7860","47.12400","3.92722","0.01845"
"7911","47.43000","3.95269","0.01915"
"7962","47.73600","3.97828","0.01913"
"8013","48.04200","4.00375","0.01891"
"8064","48.34800","4.02916","0.01909"
"8115","48.65400","4.05469","0.01910"
"8166","48.96000","4.08016","0.01970"
"8217","49.26600","4.10569","0.01985"
"8268","49.57200","4.13116","0.02006"
"8319","49.87800","4.15669","0.01994"
"8370","50.18400","4.18216","0.02059"
"8421","50.49000","4.20769","0.01986"
"8472","50.79600","4.23316","0.02004"
"8523","51.10200","4.25863","0.02040"
"8574","51.40800","4.28422","0.02094"
"8625","51.71400","4.30969","0.02081"
"8676","52.02000","4.33522","0.02122"
"8727","52.32600","4.36069","0.02135"
"8778","52.63200","4.38622","0.02114"
"8829","52.93800","4.41175","0.02114"
"8880","53.24400","4.43716","0.02075"
"8931","53.55000","4.46275","0.01993"
"8982","53.85600","4.48822","0.02039"
"9033","54.16200","4.51369","0.02078"
"9084","54.46800","4.53922","0.02054"
"9135","54.77400","4.56475","0.02095"
"9186","55.08000","4.59028","0.02131"
"9237","55.38600","4.61563","0.02097"
"9288","55.69200","4.64116","0.02120"
"9339","55.99800","4.66663","0.02108"
"9390","56.30400","4.69222","0.02184"
"9441","56.61000","4.71769","0.02166"
"9492","56.91600","4.74322","0.02128"
"9543","57.22200","4.76875","0.02150"
"9594","57.52800","4.79422","0.02191"
"9645","57.83400","4.81975","0.02236"
"9696","58.14000","4.84516","0.02262"
"9747","58.44600","4.87069","0.02245"
"9798","58.75200","4.89622","0.02280"
"9849","59.05800","4.92175","0.02251"
"9900","59.36400","4.94723","0.02332"
"9951","59.67000","4.97269","0.02295"
"10002","59.97600","4.99817","0.02366"
"10053","60.28200","5.02364","0.02337"
"10104","60.58800","5.04917","0.02438"
"10155","60.89400","5.07470","0.02386"
"10206","61.20000","5.10023","0.02400"
"10257","61.50600","5.12570","0.02439"
"10308","61.81200","5.15117","0.02457"
"10359","62.11800","5.17670","0.02506"
"10410","62.42400","5.20217","0.02517"
"10461","62.73000","5.22770","0.02499"
"10512","63.03600","5.25317","0.02565"
"10563","63.34200","5.27876","0.02575"
"10614","63.64800","5.30423","0.02546"
"10665","63.95400","5.32970","0.02557"
"10716","64.26000","5.35523","0.02612"
"10767","64.56600","5.38064","0.02646"
"10818","64.87200","5.40623","0.02630"
"10869","65.17800","5.43164","0.02592"
"10920","65.48400","5.45717","0.02659"
"10971","65.79000","5.48270","0.02714"
"11022","66.09600","5.50823","0.02703"
"11073","66.40200","5.53370","0.02744"
"11124","66.70800","5.55917","0.02771"
"11175","67.01400","5.58476","0.02727"
"11226","67.32000","5.61017","0.02758"
"11277","67.62600","5.63570","0.02799"
"11328","67.93200","5.66123","0.02772"
"11379","68.23800","5.68670","0.02815"
"11430","68.54400","5.71223","0.02803"
"11481","68.85000","5.73764","0.02862"
"11532","69.15600","5.76317","0.02840"
"11583","69.46200","5.78870","0.02880"
"11634","69.76800","5.81417","0.02785"
"11685","70.07400","5.83970","0.02850"
"11736","70.38000","5.86517","0.02871"
"11787","70.68600","5.89070","0.02927"
"11838","70.99200","5.91617","0.02885"
"11889","71.29800","5.94170","0.02935"
"11940","71.60400","5.96717","0.02943"
"11991","71.91000","5.99270","0.02933"
"12042","72.21600","6.01817","0.02969"
"12093","72.52200","6.04371","0.02974"
"12144","72.82800","6.06924","0.02970"
"12195","73.13400","6.09465","0.02972"
"12246","73.44000","6.12018","0.02972"
"12297","73.74600","6.14559","0.02983"
"12348","74.05200","6.17118","0.02991"
"12399","74.35800","6.19665","0.03009"
"12450","74.66400","6.22218","0.03060"
"12501","74.97000","6.24771","0.03029"
"12552","75.27600","6.27318","0.03079"
"12603","75.58200","6.29877","0.03082"
"12654","75.88800","6.32418","0.03097"
"12705","76.19400","6.34971","0.03132"
"12756","76.50000","6.37518","0.03181"
"12807","76.80600","6.40071","0.03138"
"12858","77.11200","6.42624","0.03143"
"12909","77.41800","6.45171","0.03141"
"12960","77.72400","6.47724","0.03181"
"13011","78.03000","6.50265","0.03165"
"13062","78.33600","6.52824","0.03156"
"13113","78.64200","6.55371","0.03178"
"13164","78.94800","6.57918","0.03213"
"13215","79.25400","6.60471","0.03236"
"13266","79.56000","6.63018","0.03223"
"13317","79.86600","6.65577","0.03250"
"13368","80.17200","6.68118","0.03291"
"13419","80.47800","6.70671","0.03295"
"13470","80.78400","6.73218","0.03317"
"13521","81.09000","6.75771","0.03320"
"13572","81.39600","6.78324","0.03310"
"13623","81.70200","6.80865","0.03326"
"13674","82.00800","6.83424","0.03354"
"13725","82.31400","6.85959","0.03356"
"13776","82.62000","6.88524","0.03371"
"13827","82.92600","6.91065","0.03380"
"13878","83.23200","6.93618","0.03379"
"13929","83.53800","6.96165","0.03382"
"13980","83.84400","6.98718","0.00643"
"14031","84.15000","7.01271","0.00846"
"14082","84.45600","7.03818","0.00707"
"14133","84.76200","7.06371","0.00918"
"14184","85.06800","7.08919","0.00725"
"14235","85.37400","7.11472","0.00805"
"14286","85.68000","7.14019","0.00735"
"14337","85.98600","7.16566","0.00853"
"14388","86.29200","7.19119","0.00780"
"14439","86.59800","7.21672","0.00791"
"14490","86.90400","7.24225","0.00780"
"14541","87.21000","7.26772","0.00809"
"14592","87.51600","7.29319","0.00861"
"14643","87.82200","7.31872","0.00797"
"14694","88.12800","7.34413","0.00897"
"14745","88.43400","7.36972","0.00808"
"14796","88.74000","7.39519","0.00903"
"14847","89.04600","7.42072","0.00859"
"14898","89.35200","7.44619","0.00846"
"14949","89.65800","7.47172","0.00864"
"15000","89.96400","7.49719","0.00920"
"15051","90.27000","7.52272","0.00921"
"15102","90.57600","7.54825","0.00912"
"15153","90.88200","7.57366","0.00932"
"15204","91.18800","7.59925","0.00835"
"15255","91.49400","7.62466","0.00871"
"15306","91.80000","7.65025","0.00904"
"15357","92.10600","7.67566","0.00944"
"15408","92.41200","7.70119","0.00969"
"15459","92.71800","7.72672","0.00950"
"15510","93.02400","7.75219","0.00971"
"15561","93.33000","7.77772","0.00944"
"15612","93.63600","7.80319","0.00978"
"15663","93.94200","7.82872","0.00983"
"15714","94.24800","7.85419","0.00992"
"15765","94.55400","7.87972","0.00981"
"15816","94.86000","7.90525","0.01084"
"15867","95.16600","7.93072","0.01001"
"15918","95.47200","7.95619","0.01028"
"15969","95.77800","7.98166","0.01016"
"16020","96.08400","8.00719","0.01044"
"16071","96.39000","8.03266","0.01069"
"16122","96.69600","8.05813","0.01009"
"16173","97.00200","8.08366","0.01043"
"16224","97.30800","8.10913","0.01058"
"16275","97.61400","8.13472","0.01067"
"16326","97.92000","8.16013","0.01090"
"16377","98.22600","8.18572","0.01042"
"16428","98.53200","8.21119","0.01032"
"16479","98.83800","8.23673","0.00991"
"16530","99.14400","8.26220","0.01023"
"16581","99.45000","8.28767","0.01062"
"16632","99.75600","8.31320","0.01043"
"16683","100.06200","8.33867","0.01067"
"16734","100.36800","8.36426","0.01013"
"16785","100.67400","8.38973","0.01039"
"16836","100.98000","8.41526","0.01077"
"16887","101.28600","8.44067","0.01063"
"16938","101.59200","8.46620","0.01088"
"16989","101.89800","8.49173","0.01052"
"17040","102.20400","8.51714","0.01095"
"17091","102.51000","8.54273","0.01047"
"17142","102.81600","8.56814","0.01092"
"17193","103.12200","8.59367","0.01018"
"17244","103.42800","8.61920","0.01075"
"17295","103.73400","8.64467","0.01149"
"17346","104.04000","8.67020","0.01115"
"17397","104.34600","8.69567","0.01118"
"17448","104.65200","8.72120","0.01127"
"17499","104.95800","8.74661","0.01149"
"17550","105.26400","8.77220","0.01150"
"17601","105.57000","8.79767","0.01173"
"17652","105.87600","8.82320","0.01160"
"17703","106.18200","8.84873","0.01157"
"17754","106.48800","8.87414","0.01143"
"17805","106.79400","8.89973","0.01149"
"17856","107.10000","8.92514","0.01202"
"17907","107.40600","8.95073","0.01262"
"17958","107.71200","8.97620","0.01256"
"18009","108.01800","9.00173","0.01312"
"18060","108.32400","9.02726","0.01220"
"18111","108.63000","9.05267","0.01320"
"18162","108.93600","9.07820","0.01338"
"18213","109.24200","9.10361","0.01350"
"18264","109.54800","9.12926","0.01345"
"18315","109.85400","9.15473","0.01275"
"18366","110.16000","9.18021","0.01358"
"18417","110.46600","9.20568","0.01436"
"18468","110.77200","9.23120","0.01401"
"18519","111.07800","9.25674","0.01423"
"18570","111.38400","9.28215","0.01396"
"18621","111.69000","9.30768","0.01411"
"18672","111.99600","9.33321","0.01429"
"18723","112.30200","9.35874","0.01499"
"18774","112.60800","9.38421","0.01494"
"18825","112.91400","9.40968","0.01480"
"18876","113.22000","9.43521","0.01493"
"18927","113.52600","9.46062","0.01541"
"18978","113.83200","9.48621","0.01575"
"19029","114.13800","9.51168","0.01570"
"19080","114.44400","9.53721","0.01594"
"19131","114.75000","9.56274","0.01584"
"19182","115.05600","9.58821","0.01624"
"19233","115.36200","9.61374","0.01724"
"19284","115.66800","9.63909","0.01682"
"19335","115.97400","9.66474","0.01730"
"19386","116.28000","9.69015","0.01733"
"19437","116.58600","9.71574","0.01762"
"19488","116.89200","9.74127","0.01758"
"19539","117.19800","9.76674","0.01828"
"19590","117.50400","9.79221","0.01815"
"19641","117.81000","9.81762","0.01874"
"19692","118.11600","9.84327","0.01951"
"19743","118.42200","9.86868","0.01937"
"19794","118.72800","9.89421","0.01999"
"19845","119.03400","9.91968","0.02084"
"19896","119.34000","9.94521","0.02080"
"19947","119.64600","9.97074","0.02104"
"19998","119.95200","9.99621","0.02088"
"20049","120.25800","10.02168","0.02090"
"20100","120.56400","10.04709","0.02095"
"20151","120.87000","10.07268","0.02112"
"20202","121.17600","10.09821","0.02177"
"20253","121.48200","10.12374","0.02178"
"20304","121.78800","10.14921","0.02277"
"20355","122.09400","10.17462","0.02215"
"20406","122.40000","10.20021","0.02335"
"20457","122.70600","10.22568","0.01990"
"20508","123.01200","10.25121","0.02016"
"20559","123.31800","10.27668","0.01986"
"20610","123.62400","10.30221","0.02056"
"20661","123.93000","10.32774","0.02067"
"20712","124.23600","10.35316","0.02200"
"20763","124.54200","10.37869","0.02147"
"20814","124.84800","10.40409","0.02245"
"20865","125.15400","10.42969","0.02282"
"20916","125.46000","10.45516","0.02275"
"20967","125.76600","10.48075","0.02335"
"21018","126.07200","10.50622","0.02379"
"21069","126.37800","10.53163","0.02407"
"21120","126.68400","10.55722","0.02469"
"21171","126.99000","10.58263","0.02526"
"21222","127.29600","10.60822","0.02167"
"21273","127.60200","10.63369","0.02281"
"21324","127.90800","10.65916","0.02355"
"21375","128.21400","10.68469","0.02315"
"21426","128.52000","10.71016","0.02242"
"21477","128.82600","10.73575","0.02333"
"21528","129.13200","10.76116","0.02342"
"21579","129.43800","10.78669","0.02406"
"21630","129.74400","10.81222","0.02448"
"21681","130.05000","10.83769","0.02482"
"21732","130.35600","10.86316","0.02449"
"21783","130.66200","10.88869","0.02434"
"21834","130.96800","10.91428","0.02515"
"21885","131.27400","10.93963","0.02484"
"21936","131.58000","10.96522","0.02522"
"21987","131.88600","10.99069","0.02599"
"22038","132.19200","11.01622","0.02630"
"22089","132.49800","11.04175","0.02647"
"22140","132.80400","11.06716","0.02699"
"22191","133.11000","11.09275","0.02674"
"22242","133.41600","11.11810","0.02669"
"22293","133.72200","11.14369","0.02746"
"22344","134.02800","11.16916","0.02728"
"22395","134.33400","11.19469","0.02774"
"22446","134.64000","11.22016","0.02557"
"22497","134.94600","11.24569","0.02509"
"22548","135.25200","11.27122","0.02534"
"22599","135.55800","11.29669","0.02612"
"22650","135.86400","11.32222","0.02704"
"22701","136.17000","11.34764","0.02694"
"22752","136.47600","11.37322","0.02671"
"22803","136.78200","11.39863","0.02772"
"22854","137.08800","11.42417","0.02773"
"22905","137.39400","11.44975","0.02696"
"22956","137.70000","11.47523","0.02668"
"23007","138.00600","11.50076","0.02758"
"23058","138.31200","11.52617","0.02780"
"23109","138.61800","11.55170","0.02810"
"23160","138.92400","11.57723","0.02787"
"23211","139.23000","11.60270","0.02842"
"23262","139.53600","11.62823","0.02891"
"23313","139.84200","11.65370","0.02898"
"23364","140.14800","11.67929","0.02897"
"23415","140.45400","11.70470","0.02893"
"23466","140.76000","11.73023","0.02859"
"23517","141.06600","11.75570","0.02928"
"23568","141.37200","11.78117","0.03025"
"23619","141.67800","11.80670","0.03002"
"23670","141.98400","11.83217","0.03018"
"23721","142.29000","11.85776","0.03033"
"23772","142.59600","11.88317","0.03072"
"23823","142.90200","11.90870","0.03065"
"23874","143.20800","11.93417","0.03042"
"23925","143.51400","11.95970","0.03010"
"23976","143.82000","11.98517","0.03038"
"24027","144.12600","12.01064","0.03038"
"24078","144.43200","12.03629","0.03082"
"24129","144.73800","12.06170","0.03096"
"24180","145.04400","12.08723","0.03110"
"24231","145.35000","12.11270","0.01957"
"24282","145.65600","12.13823","0.02098"
"24333","145.96200","12.16370","0.02061"
"24384","146.26800","12.18923","0.02090"
"24435","146.57400","12.21476","0.02011"
"24486","146.88000","12.24017","0.01983"
"24537","147.18600","12.26570","0.01870"
"24588","147.49200","12.29117","0.01865"
"24639","147.79800","12.31670","0.01909"
"24690","148.10400","12.34217","0.01809"
"24741","148.41000","12.36758","0.01250"
"24792","148.71600","12.39318","0.00785"
"24843","149.02200","12.41865","0.01181"
"24894","149.32800","12.44423","0.00831"
"24945","149.63400","12.46971","0.01179"
"24996","149.94000","12.49518","0.00812"
"25047","150.24600","12.52071","0.01086"
"25098","150.55200","12.54624","0.00914"
"25149","150.85800","12.57171","0.01097"
"25200","151.16400","12.59718","0.01071"
"25251","151.47000","12.62277","0.00985"
"25302","151.77600","12.64824","0.01178"
"25353","152.08200","12.67371","0.00984"
"25404","152.38800","12.69912","0.01231"
"25455","152.69400","12.72465","0.01070"
"25506","153.00000","12.75018","0.01232"
"25557","153.30600","12.77565","0.01089"
"25608","153.61200","12.80124","0.01271"
"25659","153.91800","12.82671","0.01213"
"25710","154.22400","12.85218","0.01187"
"25761","154.53000","12.87765","0.01235"
"25812","154.83600","12.90324","0.01171"
"25863","155.14200","12.92871","0.01275"
"25914","155.44800","12.95418","0.01167"
"25965","155.75400","12.97971","0.01355"
"26016","156.06000","13.00518","0.01231"
"26067","156.36600","13.03071","0.01358"
"26118","156.67200","13.05624","0.01303"
"26169","156.97800","13.08171","0.01329"
"26220","157.28400","13.10718","0.01405"
"26271","157.59000","13.13265","0.01353"
"26322","157.89600","13.15824","0.01469"
"26373","158.20200","13.18365","0.01418"
"26424","158.50800","13.20918","0.01489"
"26475","158.81400","13.23471","0.01391"
"26526","159.12000","13.26018","0.01520"
"26577","159.42600","13.28571","0.01509"
"26628","159.73200","13.31118","0.01577"
"26679","160.03800","13.33671","0.01600"
"26730","160.34400","13.36212","0.01543"
"26781","160.65000","13.38777","0.01553"
"26832","160.95600","13.41324","0.01556"
"26883","161.26200","13.43871","0.01600"
"26934","161.56800","13.46419","0.01607"
"26985","161.87400","13.48971","0.01653"
"27036","162.18000","13.51519","0.01712"
"27087","162.48600","13.54066","0.01673"
"27138","162.79200","13.56618","0.01740"
"27189","163.09800","13.59172","0.01666"
"27240","163.40400","13.61725","0.01812"
"27291","163.71000","13.64272","0.01775"
"27342","164.01600","13.66819","0.01792"
"27393","164.32200","13.69366","0.01803"
"27444","164.62800","13.71913","0.01843"
"27495","164.93400","13.74472","0.01901"
"27546","165.24000","13.77019","0.01818"
"27597","165.54600","13.79572","0.01818"
"27648","165.85200","13.82119","0.01869"
"27699","166.15800","13.84672","0.01899"
"27750","166.46400","13.87225","0.01913"
"27801","166.77000","13.89760","0.01920"
"27852","167.07600","13.92319","0.01987"
"27903","167.38200","13.94866","0.02004"
"27954","167.68800","13.97419","0.01989"
"28005","167.99400","13.99972","0.02023"
"28056","168.30000","14.02525","0.02088"
"28107","168.60600","14.05072","0.02054"
"28158","168.91200","14.07613","0.02048"
"28209","169.21800","14.10172","0.02144"
"28260","169.52400","14.12713","0.02127"
"28311","169.83000","14.15272","0.02125"
"28362","170.13600","14.17819","0.02200"
"28413","170.44200","14.20372","0.01881"
"28464","170.74800","14.22919","0.01944"
"28515","171.05400","14.25472","0.01970"
"28566","171.36000","14.28019","0.02027"
"28617","171.66600","14.30560","0.02040"
"28668","171.97200","14.33119","0.02081"
"28719","172.27800","14.35672","0.02092"
"28770","172.58400","14.38219","0.02119"
"28821","172.89000","14.40772","0.02204"
"28872","173.19600","14.43319","0.02148"
"28923","173.50200","14.45866","0.02206"
"28974","173.80800","14.48413","0.02174"
"29025","174.11400","14.50972","0.02255"
"29076","174.42000","14.53519","0.02283"
"29127","174.72600","14.56073","0.02308"
"29178","175.03200","14.58619","0.02338"
"29229","175.33800","14.61166","0.02375"
"29280","175.64400","14.63720","0.02374"
"29331","175.95000","14.66267","0.01320"
"29382","176.25600","14.68826","0.01657"
"29433","176.56200","14.71367","0.01753"
"29484","176.86800","14.73925","0.01623"
"29535","177.17400","14.76473","0.01842"
"29586","177.48000","14.79014","0.01696"
"29637","177.78600","14.81567","0.01729"
"29688","178.09200","14.84114","0.01339"
"29739","178.39800","14.86673","0.01379"
"29790","178.70400","14.89214","0.01371"
"29841","179.01000","14.91773","0.01257"
"29892","179.31600","14.94320","0.01246"
"29943","179.62200","14.96873","0.01462"
"29994","179.92800","14.99420","0.01246"
"30045","180.23400","15.01961","0.01369"
"30096","180.54000","15.04520","0.01301"
"30147","180.84600","15.07061","0.01327"
"30198","181.15200","15.09620","0.01336"
"30249","181.45800","15.12173","0.01302"
"30300","181.76400","15.14726","0.01501"
"30351","182.07000","15.17279","0.01315"
"30402","182.37600","15.19814","0.01471"
"30453","182.68200","15.22373","0.01363"
"30504","182.98800","15.24920","0.01353"
"30555","183.29400","15.27473","0.01474"
"30606","183.60000","15.30026","0.01411"
"30657","183.90600","15.32573","0.01536"
"30708","184.21200","15.35126","0.01527"
"30759","184.51800","15.37667","0.01513"
"30810","184.82400","15.40214","0.01553"
"30861","185.13000","15.42761","0.01485"
"30912","185.43600","15.45320","0.01491"
"30963","185.74200","15.47867","0.01412"
"31014","186.04800","15.50426","0.01601"
"31065","186.35400","15.52973","0.01586"
"31116","186.66000","15.55515","0.01631"
"31167","186.96600","15.58073","0.01637"
"31218","187.27200","15.60614","0.01588"
"31269","187.57800","15.63173","0.01604"
"31320","187.88400","15.65714","0.01537"
"31371","188.19000","15.68273","0.01641"
"31422","188.49600","15.70820","0.01638"
"31473","188.80200","15.73367","0.01701"
"31524","189.10800","15.75921","0.01710"
"31575","189.41400","15.78468","0.01777"
"31626","189.72000","15.81021","0.01747"
"31677","190.02600","15.83568","0.01749"
"31728","190.33200","15.86121","0.01770"
"31779","190.63800","15.88674","0.01745"
"31830","190.94400","15.91221","0.01790"
"31881","191.25000","15.93768","0.01799"
"31932","191.55600","15.96315","0.01805"
"31983","191.86200","15.98874","0.01857"
"32034","192.16800","16.01421","0.01787"
"32085","192.47400","16.03968","0.01842"
"32136","192.78000","16.06521","0.01768"
"32187","193.08600","16.09068","0.01805"
"32238","193.39200","16.11627","0.01862"
"32289","193.69800","16.14168","0.01886"
"32340","194.00400","16.16727","0.01890"
"32391","194.31000","16.19262","0.01944"
"32442","194.61600","16.21821","0.02016"
"32493","194.92200","16.24368","0.01996"
"32544","195.22800","16.26921","0.02017"
"32595","195.53400","16.29474","0.02017"
"32646","195.84000","16.32015","0.02030"
"32697","196.14600","16.34574","0.02084"
"32748","196.45200","16.37121","0.02109"
"32799","196.75800","16.39668","0.02161"
"32850","197.06400","16.42215","0.02201"
"32901","197.37000","16.44768","0.02202"
"32952","197.67600","16.47327","0.02190"
"33003","197.98200","16.49868","0.02162"
"33054","198.28800","16.52415","0.02223"
"33105","198.59400","16.54968","0.02278"
"33156","198.90000","16.57521","0.02326"
"33207","199.20600","16.60068","0.02370"
"33258","199.51200","16.62615","0.02395"
"33309","199.81800","16.65174","0.02378"
"33360","200.12400","16.67721","0.02460"
"33411","200.43000","16.70268","0.02453"
"33462","200.73600","16.72816","0.02536"
"33513","201.04200","16.75374","0.02523"
"33564","201.34800","16.77915","0.02529"
"33615","201.65400","16.80469","0.02565"
"33666","201.96000","16.83022","0.02559"
"33717","202.26600","16.85568","0.02594"
"33768","202.57200","16.88122","0.02647"
"33819","202.87800","16.90657","0.02692"
"33870","203.18400","16.93221","0.02739"
"33921","203.49000","16.95769","0.02733"
"33972","203.79600","16.98316","0.02746"
"34023","204.10200","17.00869","0.02771"
"34074","204.40800","17.03416","0.02826"
"34125","204.71400","17.05975","0.02801"
"34176","205.02000","17.08516","0.02830"
"34227","205.32600","17.11075","0.02887"
"34278","205.63200","17.13616","0.02924"
"34329","205.93800","17.16169","0.02977"
"34380","206.24400","17.18722","0.02936"
"34431","206.55000","17.21269","0.02919"
"34482","206.85600","17.23828","0.02887"
"34533","207.16200","17.26369","0.02885"
"34584","207.46800","17.28922","0.01935"
"34635","207.77400","17.31469","0.02205"
"34686","208.08000","17.34022","0.02103"
"34737","208.38600","17.36569","0.02148"
"34788","208.69200","17.39116","0.02410"
"34839","208.99800","17.41675","0.02417"
"34890","209.30400","17.44216","0.02441"
"34941","209.61000","17.46775","0.02540"
"34992","209.91600","17.49322","0.02602"
"35043","210.22200","17.51869","0.02553"
"35094","210.52800","17.54422","0.02548"
"35145","210.83400","17.56969","0.02653"
"35196","211.14000","17.59522","0.02608"
"35247","211.44600","17.62063","0.02659"
"35298","211.75200","17.64622","0.02662"
"35349","212.05800","17.67169","0.02676"
"35400","212.36400","17.69716","0.02738"
"35451","212.67000","17.72269","0.02830"
"35502","212.97600","17.74816","0.02833"
"35553","213.28200","17.77369","0.02886"
"35604","213.58800","17.79917","0.02862"
"35655","213.89400","17.82475","0.02946"
"35706","214.20000","17.85022","0.02916"
"35757","214.50600","17.87576","0.02997"
"35808","214.81200","17.90117","0.03056"
"35859","215.11800","17.92669","0.02938"
"35910","215.42400","17.95217","0.02890"
"35961","215.73000","17.97764","0.02870"
"36012","216.03600","18.00323","0.02858"
"36063","216.34200","18.02870","0.02873"
"36114","216.64800","18.05423","0.02855"
"36165","216.95400","18.07970","0.02912"
"36216","217.26000","18.10517","0.02958"
"36267","217.56600","18.13070","0.02961"
"36318","217.87200","18.15617","0.02992"
"36369","218.17800","18.18170","0.03036"
"36420","218.48400","18.20717","0.03066"
"36471","218.79000","18.23270","0.03071"
"36522","219.09600","18.25823","0.03055"
"36573","219.40200","18.28370","0.03084"
"36624","219.70800","18.30923","0.03089"
"36675","220.01400","18.33464","0.02447"
"36726","220.32000","18.36023","0.02585"
"36777","220.62600","18.38564","0.02504"
"36828","220.93200","18.41123","0.02676"
"36879","221.23800","18.43670","0.02667"
"36930","221.54400","18.46223","0.02640"
"36981","221.85000","18.48770","0.02669"
"37032","222.15600","18.51317","0.02707"
"37083","222.46200","18.53870","0.02753"
"37134","222.76800","18.56411","0.02798"
"37185","223.07400","18.58970","0.02830"
"37236","223.38000","18.61517","0.02790"
"37287","223.68600","18.64070","0.02646"
"37338","223.99200","18.66623","0.02722"
"37389","224.29800","18.69170","0.02636"
"37440","224.60400","18.71723","0.02604"
"37491","224.91000","18.74264","0.02652"
"37542","225.21600","18.76823","0.02611"
"37593","225.52200","18.79370","0.02650"
"37644","225.82800","18.81917","0.02632"
"37695","226.13400","18.84464","0.02659"
"37746","226.44000","18.87012","0.02709"
"37797","226.74600","18.89570","0.02642"
"37848","227.05200","18.92118","0.02814"
"37899","227.35800","18.94670","0.02744"
"37950","227.66400","18.97223","0.02761"
"38001","227.97000","18.99777","0.02813"
"38052","228.27600","19.02324","0.02800"
"38103","228.58200","19.04871","0.02801"
"38154","228.88800","19.07424","0.02748"
"38205","229.19400","19.09965","0.02808"
"38256","229.50000","19.12524","0.02776"
"38307","229.80600","19.15071","0.02769"
"38358","230.11200","19.17630","0.02873"
"38409","230.41800","19.20171","0.02872"
"38460","230.72400","19.22718","0.02895"
"38511","231.03000","19.25271","0.02942"
"38562","231.33600","19.27818","0.02933"
"38613","231.64200","19.30371","0.02946"
"38664","231.94800","19.32912","0.02991"
"38715","232.25400","19.35471","0.03032"
"38766","232.56000","19.38018","0.03087"
"38817","232.86600","19.40565","0.03054"
"38868","233.17200","19.43124","0.03081"
"38919","233.47800","19.45671","0.03063"
"38970","233.78400","19.48218","0.03129"
"39021","234.09000","19.50765","0.03091"
"39072","234.39600","19.53324","0.03139"
"39123","234.70200","19.55871","0.02935"
"39174","235.00800","19.58418","0.02938"
"39225","235.31400","19.60971","0.02941"
"39276","235.62000","19.63518","0.02523"
"39327","235.92600","19.66071","0.02583"
"39378","236.23200","19.68612","0.02579"
"39429","236.53800","19.71171","0.02559"
"39480","236.84400","19.73718","0.02709"
"39531","237.15000","19.76277","0.02705"
"39582","237.45600","19.78824","0.02729"
"39633","237.76200","19.81365","0.02701"
"39684","238.06800","19.83924","0.02650"
"39735","238.37400","19.86465","0.02738"
"39786","238.68000","19.89024","0.02691"
"39837","238.98600","19.91571","0.01937"
"39888","239.29200","19.94124","0.02050"
"39939","239.59800","19.96671","0.02078"
"39990","239.90400","19.99218","0.02037"
"40041","240.21000","20.01772","0.02199"
"40092","240.51600","20.04313","0.02223"
"40143","240.82200","20.06866","0.02225"
"40194","241.12800","20.09419","0.02317"
"40245","241.43400","20.11971","0.02281"
"40296","241.74000","20.14524","0.02308"
"40347","242.04600","20.17072","0.02372"
"40398","242.35200","20.19619","0.02432"
"40449","242.65800","20.22166","0.02420"
"40500","242.96400","20.24719","0.02474"
"40551","243.27000","20.27266","0.02522"
"40602","243.57600","20.29825","0.02536"
"40653","243.88200","20.32372","0.02573"
"40704","244.18800","20.34919","0.02579"
"40755","244.49400","20.37478","0.02633"
"40806","244.80000","20.40013","0.02610"
"40857","245.10600","20.42572","0.02607"
"40908","245.41200","20.45113","0.02638"
"40959","245.71800","20.47672","0.02641"
"41010","246.02400","20.50225","0.02722"
"41061","246.33000","20.52778","0.02707"
"41112","246.63600","20.55325","0.02750"
"41163","246.94200","20.57860","0.02778"
"41214","247.24800","20.60425","0.02717"
"41265","247.55400","20.62966","0.02758"
"41316","247.86000","20.65519","0.02768"
"41367","248.16600","20.68066","0.02768"
"41418","248.47200","20.70619","0.02813"
"41469","248.77800","20.73172","0.02784"
"41520","249.08400","20.75719","0.02814"
"41571","249.39000","20.78272","0.02835"
"41622","249.69600","20.80813","0.02851"
"41673","250.00200","20.83366","0.02858"
"41724","250.30800","20.85919","0.02861"
"41775","250.61400","20.88472","0.02923"
"41826","250.92000","20.91025","0.02954"
"41877","251.22600","20.93566","0.02938"
"41928","251.53200","20.96119","0.02944"
"41979","251.83800","20.98667","0.02980"
"42030","252.14400","21.01219","0.02964"
"42081","252.45000","21.03772","0.02981"
"42132","252.75600","21.06319","0.01008"
"42183","253.06200","21.08879","0.01260"
"42234","253.36800","21.11420","0.00760"
"42285","253.67400","21.13973","0.00837"
"42336","253.98000","21.16514","0.00893"
"42387","254.28600","21.19066","0.00718"
"42438","254.59200","21.21614","0.01202"
"42489","254.89800","21.24173","0.00697"
"42540","255.20400","21.26720","0.00789"
"42591","255.51000","21.29267","0.01142"
"42642","255.81600","21.31820","0.00689"
"42693","256.12200","21.34361","0.00924"
"42744","256.42800","21.36926","0.01040"
"42795","256.73400","21.39467","0.00803"
"42846","257.04000","21.42020","0.01000"
"42897","257.34600","21.44573","0.00843"
"42948","257.65200","21.47120","0.01006"
"42999","257.95800","21.49673","0.00995"
"43050","258.26400","21.52214","0.00840"
"43101","258.57000","21.54767","0.01109"
"43152","258.87600","21.57320","0.00894"
"43203","259.18200","21.59873","0.00994"
"43254","259.48800","21.62420","0.01061"
"43305","259.79400","21.64973","0.01036"
"43356","260.10000","21.67526","0.01102"
"43407","260.40600","21.70067","0.00976"
"43458","260.71200","21.72620","0.01087"
"43509","261.01800","21.75167","0.01108"
"43560","261.32400","21.77720","0.01074"
"43611","261.63000","21.80267","0.01083"
"43662","261.93600","21.82820","0.01091"
"43713","262.24200","21.85373","0.01128"
"43764","262.54800","21.87914","0.01096"
"43815","262.85400","21.90473","0.01122"
"43866","263.16000","21.93014","0.01191"
"43917","263.46600","21.95573","0.01179"
"43968","263.77200","21.98114","0.01173"
"44019","264.07800","22.00673","0.01177"
"44070","264.38400","22.03221","0.01207"
"44121","264.69000","22.05767","0.01251"
"44172","264.99600","22.08320","0.01222"
"44223","265.30200","22.10868","0.01231"
"44274","265.60800","22.13420","0.01289"
"44325","265.91400","22.15968","0.01288"
"44376","266.22000","22.18521","0.01263"
"44427","266.52600","22.21068","0.01231"
"44478","266.83200","22.23620","0.01307"
"44529","267.13800","22.26167","0.01342"
"44580","267.44400","22.28720","0.01345"
"44631","267.75000","22.31274","0.01379"
"44682","268.05600","22.33821","0.01377"
"44733","268.36200","22.36368","0.01397"
"44784","268.66800","22.38921","0.01369"
"44835","268.97400","22.41468","0.01422"
"44886","269.28000","22.44021","0.01342"
"44937","269.58600","22.46568","0.01463"
"44988","269.89200","22.49127","0.01438"
"45039","270.19800","22.51668","0.01439"
"45090","270.50400","22.54221","0.01400"
"45141","270.81000","22.56774","0.01449"
"45192","271.11600","22.59315","0.01479"
"45243","271.42200","22.61880","0.01550"
"45294","271.72800","22.64415","0.01523"
"45345","272.03400","22.66974","0.01454"
"45396","272.34000","22.69521","0.01511"
"45447","272.64600","22.72074","0.01549"
"45498","272.95200","22.74615","0.01537"
"45549","273.25800","22.77168","0.01571"
"45600","273.56400","22.79721","0.01529"
"45651","273.87000","22.82268","0.01621"
"45702","274.17600","22.84827","0.01613"
"45753","274.48200","22.87368","0.01598"
"45804","274.78800","22.89921","0.01599"
"45855","275.09400","22.92468","0.01713"
"45906","275.40000","22.95021","0.01714"
"45957","275.70600","22.97574","0.01637"
"46008","276.01200","23.00115","0.01696"
"46059","276.31800","23.02668","0.01718"
"46110","276.62400","23.05221","0.01674"
"46161","276.93000","23.07768","0.01699"
"46212","277.23600","23.10315","0.01753"
"46263","277.54200","23.12863","0.01695"
"46314","277.84800","23.15421","0.01776"
"46365","278.15400","23.17969","0.01730"
"46416","278.46000","23.20522","0.01732"
"46467","278.76600","23.23068","0.01738"
"46518","279.07200","23.25622","0.01768"
"46569","279.37800","23.28169","0.01752"
"46620","279.68400","23.30721","0.01779"
"46671","279.99000","23.33274","0.01869"
"46722","280.29600","23.35816","0.01782"
"46773","280.60200","23.38375","0.01787"
"46824","280.90800","23.40916","0.01772"
"46875","281.21400","23.43475","0.01856"
"46926","281.52000","23.46016","0.01772"
"46977","281.82600","23.48569","0.01784"
"47028","282.13200","23.51122","0.01836"
"47079","282.43800","23.53663","0.01849"
"47130","282.74400","23.56222","0.01923"
"47181","283.05000","23.58769","0.01919"
"47232","283.35600","23.61322","0.01856"
"47283","283.66200","23.63863","0.01894"
"47334","283.96800","23.66422","0.01896"
"47385","284.27400","23.68969","0.01887"
"47436","284.58000","23.71516","0.01933"
"47487","284.88600","23.74069","0.01984"
"47538","285.19200","23.76616","0.01997"
"47589","285.49800","23.79175","0.01975"
"47640","285.80400","23.81722","0.02012"
"47691","286.11000","23.84269","0.02047"
"47742","286.41600","23.86822","0.02069"
"47793","286.72200","23.89363","0.02024"
"47844","287.02800","23.91916","0.02099"
"47895","287.33400","23.94463","0.02041"
"47946","287.64000","23.97022","0.02121"
"47997","287.94600","23.99569","0.02166"
"48048","288.25200","24.02122","0.02164"
"48099","288.55800","24.04675","0.02203"
"48150","288.86400","24.07222","0.02101"
"48201","289.17000","24.09775","0.02223"
"48252","289.47600","24.12316","0.02177"
"48303","289.78200","24.14875","0.02194"
"48354","290.08800","24.17422","0.02179"
"48405","290.39400","24.19975","0.02229"
"48456","290.70000","24.22516","0.02265"
"48507","291.00600","24.25069","0.02275"
"48558","291.31200","24.27622","0.02279"
"48609","291.61800","24.30170","0.02240"
"48660","291.92400","24.32723","0.02289"
"48711","292.23000","24.35270","0.02264"
"48762","292.53600","24.37823","0.02362"
"48813","292.84200","24.40370","0.02332"
"48864","293.14800","24.42922","0.02384"
"48915","293.45400","24.45470","0.02384"
"48966","293.76000","24.48011","0.02354"
"49017","294.06600","24.50570","0.02422"
"49068","294.37200","24.53117","0.02451"
"49119","294.67800","24.55670","0.02393"
"49170","294.98400","24.58223","0.02378"
"49221","295.29000","24.60776","0.02409"
"49272","295.59600","24.63323","0.02476"
"49323","295.90200","24.65864","0.02520"
"49374","296.20800","24.68417","0.02503"
"49425","296.51400","24.70964","0.02507"
"49476","296.82000","24.73523","0.02539"
"49527","297.12600","24.76070","0.02525"
"49578","297.43200","24.78623","0.02499"
"49629","297.73800","24.81176","0.02545"
"49680","298.04400","24.83717","0.02514"
"49731","298.35000","24.86270","0.02554"
"49782","298.65600","24.88811","0.02507"
"49833","298.96200","24.91376","0.02486"
"49884","299.26800","24.93917","0.02450"
"49935","299.57400","24.96476","0.02430"
"49986","299.88000","24.99023","0.02414"
"50037","300.18600","25.01570","0.02509"
"50088","300.49200","25.04117","0.02539"
"50139","300.79800","25.06664","0.02577"
"50190","301.10400","25.09223","0.02545"
"50241","301.41000","25.11770","0.02587"
"50292","301.71600","25.14323","0.02520"
"50343","302.02200","25.16870","0.02510"
"50394","302.32800","25.19417","0.02467"
"50445","302.63400","25.21970","0.02473"
"50496","302.94000","25.24517","0.02441"
"50547","303.24600","25.27070","0.02490"
"50598","303.55200","25.29623","0.02442"
"50649","303.85800","25.32176","0.02530"
"50700","304.16400","25.34723","0.02562"
"50751","304.47000","25.37271","0.02548"
"50802","304.77600","25.39824","0.02583"
"50853","305.08200","25.42365","0.02621"
"50904","305.38800","25.44917","0.02652"
"50955","305.69400","25.47465","0.02683"
"51006","306.00000","25.50024","0.02701"
"51057","306.30600","25.52571","0.02735"
"51108","306.61200","25.55118","0.02669"
"51159","306.91800","25.57671","0.02735"
"51210","307.22400","25.60212","0.02739"
"51261","307.53000","25.62771","0.02782"
"51312","307.83600","25.65312","0.02750"
"51363","308.14200","25.67871","0.02770"
"51414","308.44800","25.70424","0.02520"
"51465","308.75400","25.72971","0.02694"
"51516","309.06000","25.75518","0.02703"
"51567","309.36600","25.78059","0.02555"
"51618","309.67200","25.80618","0.02720"
"51669","309.97800","25.83165","0.02751"
"51720","310.28400","25.85718","0.02662"
"51771","310.59000","25.88271","0.02672"
"51822","310.89600","25.90824","0.02760"
"51873","311.20200","25.93377","0.02723"
"51924","311.50800","25.95918","0.02814"
"51975","311.81400","25.98471","0.02543"
"52026","312.12000","26.01018","0.02534"
"52077","312.42600","26.03571","0.02375"
"52128","312.73200","26.06118","0.02412"
"52179","313.03800","26.08671","0.02386"
"52230","313.34400","26.11224","0.02376"
"52281","313.65000","26.13765","0.02335"
"52332","313.95600","26.16318","0.02445"
"52383","314.26200","26.18865","0.02521"
"52434","314.56800","26.21418","0.02499"
"52485","314.87400","26.23965","0.02482"
"52536","315.18000","26.26518","0.02515"
"52587","315.48600","26.29071","0.02533"
"52638","315.79200","26.31618","0.02523"
"52689","316.09800","26.34171","0.02521"
"52740","316.40400","26.36719","0.02618"
"52791","316.71000","26.39271","0.02566"
"52842","317.01600","26.41818","0.02562"
"52893","317.32200","26.44371","0.02602"
"52944","317.62800","26.46925","0.02597"
"52995","317.93400","26.49471","0.02662"
"53046","318.24000","26.52025","0.02623"
"53097","318.54600","26.54565","0.02593"
"53148","318.85200","26.57125","0.02651"
"53199","319.15800","26.59666","0.02675"
"53250","319.46400","26.62219","0.02702"
"53301","319.77000","26.64772","0.02642"
"53352","320.07600","26.67319","0.02710"
"53403","320.38200","26.69872","0.02671"
"53454","320.68800","26.72419","0.02671"
"53505","320.99400","26.74972","0.02643"
"53556","321.30000","26.77519","0.02677"
"53607","321.60600","26.80066","0.02717"
"53658","321.91200","26.82625","0.02709"
"53709","322.21800","26.85166","0.02735"
"53760","322.52400","26.87725","0.02731"
"53811","322.83000","26.90266","0.02717"
"53862","323.13600","26.92825","0.02763"
"53913","323.44200","26.95366","0.02714"
"53964","323.74800","26.97919","0.02781"
"54015","324.05400","27.00466","0.02784"
"54066","324.36000","27.03019","0.02751"
"54117","324.66600","27.05572","0.02793"
"54168","324.97200","27.08113","0.02755"
"54219","325.27800","27.10672","0.02804"
"54270","325.58400","27.13219","0.02856"
"54321","325.89000","27.15772","0.02884"
"54372","326.19600","27.18319","0.02850"
"54423","326.50200","27.20866","0.02897"
"54474","326.80800","27.23425","0.02949"
"54525","327.11400","27.25972","0.02883"
"54576","327.42000","27.28519","0.02921"
"54627","327.72600","27.31066","0.02956"
"54678","328.03200","27.33625","0.02978"
"54729","328.33800","27.36166","0.02961"
"54780","328.64400","27.38719","0.03009"
"54831","328.95000","27.41273","0.02997"
"54882","329.25600","27.43820","0.03009"
"54933","329.56200","27.46366","0.03005"
"54984","329.86800","27.48914","0.03016"
"55035","330.17400","27.51472","0.03045"
"55086","330.48000","27.54020","0.03015"
"55137","330.78600","27.56567","0.03062"
"55188","331.09200","27.59126","0.03019"
"55239","331.39800","27.61667","0.02954"
"55290","331.70400","27.64226","0.03020"
"55341","332.01000","27.66761","0.02989"
"55392","332.31600","27.69320","0.02940"
"55443","332.62200","27.71867","0.02992"
"55494","332.92800","27.74420","0.03001"
"55545","333.23400","27.76967","0.03020"
"55596","333.54000","27.79514","0.03065"
"55647","333.84600","27.82073","0.03035"
"55698","334.15200","27.84620","0.03024"
"55749","334.45800","27.87173","0.03068"
"55800","334.76400","27.89720","0.03067"
"55851","335.07000","27.92267","0.03156"
"55902","335.37600","27.94820","0.03098"
"55953","335.68200","27.97373","0.03124"
"56004","335.98800","27.99926","0.03164"
"56055","336.29400","28.02467","0.03132"
"56106","336.60000","28.05026","0.03124"
"56157","336.90600","28.07573","0.03150"
"56208","337.21200","28.10120","0.03139"
"56259","337.51800","28.12667","0.03144"
"56310","337.82400","28.15220","0.03164"
"56361","338.13000","28.17773","0.03152"
"56412","338.43600","28.20320","0.03180"
"56463","338.74200","28.22873","0.03204"
"56514","339.04800","28.25420","0.03249"
"56565","339.35400","28.27967","0.03198"
"56616","339.66000","28.30520","0.01866"
"56667","339.96600","28.33068","0.01228"
"56718","340.27200","28.35626","0.01420"
"56769","340.57800","28.38167","0.01574"
"56820","340.88400","28.40720","0.02149"
"56871","341.19000","28.43267","0.01351"
"56922","341.49600","28.45820","0.01052"
"56973","341.80200","28.48367","0.01255"
"57024","342.10800","28.50914","0.01288"
"57075","342.41400","28.53474","0.01061"
"57126","342.72000","28.56014","0.01120"
"57177","343.02600","28.58574","0.00721"
"57228","343.33200","28.61114","0.00825"
"57279","343.63800","28.63673","0.01068"
"57330","343.94400","28.66221","0.00727"
"57381","344.25000","28.68774","0.00624"
"57432","344.55600","28.71327","0.00922"
"57483","344.86200","28.73868","0.01126"
"57534","345.16800","28.76421","0.00822"
"57585","345.47400","28.78968","0.00735"
"57636","345.78000","28.81521","0.00917"
"57687","346.08600","28.84068","0.00947"
"57738","346.39200","28.86615","0.00874"
"57789","346.69800","28.89168","0.00959"
"57840","347.00400","28.91715","0.00757"
"57891","347.31000","28.94274","0.00814"
"57942","347.61600","28.96815","0.01072"
"57993","347.92200","28.99374","0.01043"
"58044","348.22800","29.01915","0.00812"
"58095","348.53400","29.04474","0.00889"
"58146","348.84000","29.07021","0.00952"
"58197","349.14600","29.09568","0.00917"
"58248","349.45200","29.12121","0.01003"
"58299","349.75800","29.14668","0.00984"
"58350","350.06400","29.17221","0.00919"
"58401","350.37000","29.19774","0.00973"
"58452","350.67600","29.22321","0.01080"
"58503","350.98200","29.24874","0.00971"
"58554","351.28800","29.27415","0.00998"
"58605","351.59400","29.29968","0.01038"
"58656","351.90000","29.32515","0.01029"
"58707","352.20600","29.35074","0.01104"
"58758","352.51200","29.37615","0.01142"
"58809","352.81800","29.40174","0.01002"
"58860","353.12400","29.42721","0.01074"
"58911","353.43000","29.45268","0.01121"
"58962","353.73600","29.47821","0.00977"
"59013","354.04200","29.50362","0.01114"
"59064","354.34800","29.52921","0.01181"
"59115","354.65400","29.55468","0.01099"
"59166","354.96000","29.58021","0.01133"
"59217","355.26600","29.60568","0.01162"
"59268","355.57200","29.63116","0.01171"
"59319","355.87800","29.65675","0.01180"
"59370","356.18400","29.68216","0.01245"
"59421","356.49000","29.70769","0.01167"
"59472","356.79600","29.73315","0.01207"
"59523","357.10200","29.75875","0.01276"
"59574","357.40800","29.78422","0.01199"
"59625","357.71400","29.80969","0.01279"
"59676","358.02000","29.83528","0.01263"
"59727","358.32600","29.86069","0.01198"
"59778","358.63200","29.88616","0.01310"
"59829","358.93800","29.91163","0.01366"
"59880","359.24400","29.93728","0.01340"
"59931","359.55000","29.96269","0.01408"
"59982","359.85600","29.98822","0.01305"
"60033","360.16200","30.01369","0.01346"
"60084","360.46800","30.03916","0.01355"
"60135","360.77400","30.06469","0.01397"
"60186","361.08000","30.09010","0.01447"
"60237","361.38600","30.11575","0.01405"
"60288","361.69200","30.14122","0.01393"
"60339","361.99800","30.16675","0.01464"
"60390","362.30400","30.19222","0.01474"
"60441","362.61000","30.21769","0.01431"
"60492","362.91600","30.24316","0.01502"
"60543","363.22200","30.26863","0.01480"
"60594","363.52800","30.29422","0.01455"
"60645","363.83400","30.31969","0.01574"
"60696","364.14000","30.34522","0.01504"
"60747","364.44600","30.37069","0.01518"
"60798","364.75200","30.39616","0.01509"
"60849","365.05800","30.42175","0.01527"
"60900","365.36400","30.44716","0.01527"
"60951","365.67000","30.47275","0.01622"
"61002","365.97600","30.49816","0.01566"
"61053","366.28200","30.52375","0.01575"
"61104","366.58800","30.54922","0.01593"
"61155","366.89400","30.57469","0.01570"
"61206","367.20000","30.60022","0.01531"
"61257","367.50600","30.62563","0.01615"
"61308","367.81200","30.65122","0.01560"
"61359","368.11800","30.67664","0.01619"
"61410","368.42400","30.70222","0.01609"
"61461","368.73000","30.72769","0.01641"
"61512","369.03600","30.75317","0.01672"
"61563","369.34200","30.77869","0.01637"
"61614","369.64800","30.80416","0.01687"
"61665","369.95400","30.82970","0.01679"
"61716","370.26000","30.85511","0.01504"
"61767","370.56600","30.88070","0.01608"
"61818","370.87200","30.90623","0.01580"
"61869","371.17800","30.93170","0.01636"
"61920","371.48400","30.95723","0.01620"
"61971","371.79000","30.98264","0.01654"
"62022","372.09600","31.00817","0.01635"
"62073","372.40200","31.03364","0.01569"
"62124","372.70800","31.05923","0.00245"
"62175","373.01400","31.08470","0.00137"
"62226","373.32000","31.11023","0.00238"
"62277","373.62600","31.13576","0.00203"
"62328","373.93200","31.16117","0.00135"
"62379","374.23800","31.18670","0.00163"
"62430","374.54400","31.21211","0.00176"
"62481","374.85000","31.23770","0.00211"
"62532","375.15600","31.26323","0.00242"
"62583","375.46200","31.28876","0.00157"
"62634","375.76800","31.31423","0.00197"
"62661","375.92600","31.32738","0.00155"