File: Trajectories_together/170107_2Specimen_RawData_1.csv
"","V1","V2","V3"
"1","End date","1/7/2017",""
"2","Specimen label","17DG_39",""
"3","Maximum Load","1.63142","N"
"4","Time","Extension","Load"
"5","(s)","(mm)","(N)"
"6","0.00000","0.00000","0.00025"
"75","0.41400","0.03462","0.00052"
"144","0.82800","0.06912","0.00038"
"213","1.24200","0.10368","0.00068"
"282","1.65600","0.13817","0.00103"
"351","2.07000","0.17255","0.00157"
"420","2.48400","0.20711","0.00124"
"489","2.89800","0.24161","0.00194"
"558","3.31200","0.27611","0.00180"
"627","3.72600","0.31061","0.00238"
"696","4.14000","0.34511","0.00231"
"765","4.55400","0.37960","0.00248"
"834","4.96800","0.41410","0.00242"
"903","5.38200","0.44860","0.00281"
"972","5.79600","0.48304","0.00295"
"1041","6.21000","0.51760","0.00336"
"1110","6.62400","0.55210","0.00302"
"1179","7.03800","0.58665","0.00378"
"1248","7.45200","0.62109","0.00407"
"1317","7.86600","0.65559","0.00314"
"1386","8.28000","0.69015","0.00353"
"1455","8.69400","0.72465","0.00403"
"1524","9.10800","0.75915","0.00458"
"1593","9.52200","0.79359","0.00440"
"1662","9.93600","0.82809","0.00389"
"1731","10.35000","0.86264","0.00324"
"1800","10.76400","0.89720","0.00310"
"1869","11.17800","0.93158","0.00395"
"1938","11.59200","0.96608","0.00349"
"2007","12.00600","1.00064","0.00406"
"2076","12.42000","1.03514","0.00436"
"2145","12.83400","1.06963","0.00421"
"2214","13.24800","1.10413","0.00482"
"2283","13.66200","1.13863","0.00511"
"2352","14.07600","1.17313","0.00448"
"2421","14.49000","1.20763","0.00531"
"2490","14.90400","1.24213","0.00530"
"2559","15.31800","1.27663","0.00556"
"2628","15.73200","1.31112","0.00569"
"2697","16.14600","1.34562","0.00580"
"2766","16.56000","1.38012","0.00645"
"2835","16.97400","1.41456","0.00681"
"2904","17.38800","1.44918","0.00691"
"2973","17.80200","1.48368","0.00714"
"3042","18.21600","1.51812","0.00700"
"3111","18.63000","1.55261","0.00731"
"3180","19.04400","1.58711","0.00810"
"3249","19.45800","1.62161","0.00842"
"3318","19.87200","1.65611","0.00815"
"3387","20.28600","1.69061","0.00843"
"3456","20.70000","1.72517","0.00904"
"3525","21.11400","1.75967","0.00881"
"3594","21.52800","1.79410","0.00910"
"3663","21.94200","1.82860","0.00935"
"3732","22.35600","1.86310","0.00992"
"3801","22.77000","1.89760","0.00976"
"3870","23.18400","1.93210","0.01093"
"3939","23.59800","1.96654","0.01110"
"4008","24.01200","2.00110","0.01102"
"4077","24.42600","2.03559","0.01172"
"4146","24.84000","2.07009","0.01180"
"4215","25.25400","2.10459","0.01237"
"4284","25.66800","2.13909","0.01262"
"4353","26.08200","2.17365","0.01310"
"4422","26.49600","2.20815","0.01312"
"4491","26.91000","2.24259","0.01404"
"4560","27.32400","2.27702","0.01431"
"4629","27.73800","2.31158","0.01447"
"4698","28.15200","2.34614","0.01482"
"4767","28.56600","2.38070","0.01501"
"4836","28.98000","2.41514","0.01566"
"4905","29.39400","2.44958","0.01563"
"4974","29.80800","2.48414","0.01626"
"5043","30.22200","2.51863","0.01603"
"5112","30.63600","2.55313","0.01682"
"5181","31.05000","2.58751","0.01718"
"5250","31.46400","2.62213","0.01769"
"5319","31.87800","2.65663","0.01765"
"5388","32.29200","2.69113","0.01809"
"5457","32.70600","2.72563","0.01826"
"5526","33.12000","2.76006","0.01856"
"5595","33.53400","2.79462","0.01887"
"5664","33.94800","2.82912","0.01941"
"5733","34.36200","2.86356","0.01952"
"5802","34.77600","2.89812","0.01974"
"5871","35.19000","2.93262","0.02001"
"5940","35.60400","2.96712","0.02047"
"6009","36.01800","3.00161","0.02066"
"6078","36.43200","3.03611","0.02098"
"6147","36.84600","3.07061","0.02119"
"6216","37.26000","3.10517","0.02134"
"6285","37.67400","3.13961","0.02176"
"6354","38.08800","3.17405","0.02208"
"6423","38.50200","3.20855","0.02257"
"6492","38.91600","3.24316","0.02296"
"6561","39.33000","3.27766","0.02301"
"6630","39.74400","3.31210","0.02307"
"6699","40.15800","3.34666","0.02356"
"6768","40.57200","3.38110","0.02389"
"6837","40.98600","3.41560","0.02452"
"6906","41.40000","3.45010","0.02479"
"6975","41.81400","3.48453","0.02465"
"7044","42.22800","3.51909","0.02587"
"7113","42.64200","3.55365","0.02582"
"7182","43.05600","3.58815","0.02603"
"7251","43.47000","3.62259","0.02685"
"7320","43.88400","3.65709","0.02741"
"7389","44.29800","3.69165","0.02740"
"7458","44.71200","3.72614","0.02771"
"7527","45.12600","3.76064","0.02820"
"7596","45.54000","3.79508","0.02853"
"7665","45.95400","3.82958","0.02909"
"7734","46.36800","3.86414","0.02970"
"7803","46.78200","3.89864","0.03025"
"7872","47.19600","3.93314","0.03049"
"7941","47.61000","3.96763","0.03032"
"8010","48.02400","4.00213","0.03106"
"8079","48.43800","4.03663","0.03187"
"8148","48.85200","4.07107","0.03238"
"8217","49.26600","4.10563","0.03233"
"8286","49.68000","4.14013","0.03334"
"8355","50.09400","4.17468","0.03396"
"8424","50.50800","4.20912","0.03369"
"8493","50.92200","4.24362","0.03435"
"8562","51.33600","4.27812","0.03450"
"8631","51.75000","4.31262","0.03536"
"8700","52.16400","4.34712","0.03390"
"8769","52.57800","4.38156","0.03535"
"8838","52.99200","4.41611","0.03502"
"8907","53.40600","4.45061","0.03641"
"8976","53.82000","4.48517","0.03663"
"9045","54.23400","4.51961","0.03671"
"9114","54.64800","4.55411","0.03746"
"9183","55.06200","4.58867","0.03831"
"9252","55.47600","4.62317","0.03874"
"9321","55.89000","4.65760","0.03647"
"9390","56.30400","4.69216","0.03699"
"9459","56.71800","4.72666","0.03732"
"9528","57.13200","4.76116","0.03844"
"9597","57.54600","4.79566","0.03861"
"9666","57.96000","4.83010","0.03827"
"9735","58.37400","4.86466","0.03929"
"9804","58.78800","4.89909","0.03928"
"9873","59.20200","4.93359","0.04036"
"9942","59.61600","4.96809","0.04054"
"10011","60.03000","5.00259","0.04104"
"10080","60.44400","5.03715","0.04103"
"10149","60.85800","5.07165","0.04189"
"10218","61.27200","5.10615","0.04245"
"10287","61.68600","5.14064","0.04258"
"10356","62.10000","5.17514","0.04341"
"10425","62.51400","5.20964","0.04418"
"10494","62.92800","5.24408","0.04415"
"10563","63.34200","5.27852","0.04534"
"10632","63.75600","5.31308","0.04608"
"10701","64.17000","5.34764","0.04600"
"10770","64.58400","5.38219","0.04694"
"10839","64.99800","5.41663","0.04593"
"10908","65.41200","5.45113","0.04709"
"10977","65.82600","5.48563","0.04782"
"11046","66.24000","5.52013","0.04860"
"11115","66.65400","5.55457","0.04910"
"11184","67.06800","5.58913","0.04895"
"11253","67.48200","5.62356","0.04938"
"11322","67.89600","5.65812","0.05073"
"11391","68.31000","5.69262","0.05096"
"11460","68.72400","5.72712","0.05177"
"11529","69.13800","5.76168","0.05256"
"11598","69.55200","5.79612","0.05381"
"11667","69.96600","5.83062","0.05481"
"11736","70.38000","5.86505","0.05519"
"11805","70.79400","5.89955","0.05615"
"11874","71.20800","5.93417","0.05607"
"11943","71.62200","5.96867","0.05730"
"12012","72.03600","6.00311","0.05728"
"12081","72.45000","6.03761","0.05840"
"12150","72.86400","6.07217","0.05908"
"12219","73.27800","6.10660","0.06021"
"12288","73.69200","6.14110","0.06121"
"12357","74.10600","6.17554","0.06163"
"12426","74.52000","6.21010","0.06206"
"12495","74.93400","6.24466","0.06174"
"12564","75.34800","6.27916","0.06175"
"12633","75.76200","6.31359","0.06247"
"12702","76.17600","6.34809","0.06329"
"12771","76.59000","6.38259","0.06412"
"12840","77.00400","6.41709","0.06456"
"12909","77.41800","6.45159","0.06570"
"12978","77.83200","6.48609","0.06560"
"13047","78.24600","6.52065","0.06599"
"13116","78.66000","6.55514","0.06684"
"13185","79.07400","6.58964","0.06771"
"13254","79.48800","6.62408","0.06825"
"13323","79.90200","6.65864","0.06879"
"13392","80.31600","6.69314","0.06917"
"13461","80.73000","6.72764","0.06988"
"13530","81.14400","6.76208","0.07017"
"13599","81.55800","6.79663","0.07061"
"13668","81.97200","6.83113","0.07127"
"13737","82.38600","6.86563","0.07130"
"13806","82.80000","6.90007","0.07193"
"13875","83.21400","6.93463","0.07229"
"13944","83.62800","6.96913","0.07266"
"14013","84.04200","7.00363","0.07304"
"14082","84.45600","7.03813","0.07300"
"14151","84.87000","7.07256","0.07341"
"14220","85.28400","7.10706","0.07346"
"14289","85.69800","7.14162","0.07402"
"14358","86.11200","7.17612","0.07444"
"14427","86.52600","7.21062","0.07475"
"14496","86.94000","7.24512","0.07506"
"14565","87.35400","7.27967","0.07526"
"14634","87.76800","7.31417","0.07564"
"14703","88.18200","7.34855","0.07591"
"14772","88.59600","7.38311","0.07638"
"14841","89.01000","7.41761","0.07659"
"14910","89.42400","7.45211","0.07713"
"14979","89.83800","7.48661","0.07771"
"15048","90.25200","7.52104","0.07776"
"15117","90.66600","7.55566","0.07867"
"15186","91.08000","7.59010","0.07882"
"15255","91.49400","7.62460","0.07957"
"15324","91.90800","7.65904","0.07998"
"15393","92.32200","7.69360","0.08029"
"15462","92.73600","7.72816","0.08091"
"15531","93.15000","7.76266","0.07975"
"15600","93.56400","7.79709","0.08035"
"15669","93.97800","7.83159","0.08103"
"15738","94.39200","7.86615","0.08226"
"15807","94.80600","7.90065","0.08287"
"15876","95.22000","7.93509","0.08354"
"15945","95.63400","7.96953","0.08405"
"16014","96.04800","8.00408","0.08468"
"16083","96.46200","8.03864","0.08589"
"16152","96.87600","8.07314","0.08662"
"16221","97.29000","8.10764","0.08725"
"16290","97.70400","8.14208","0.08793"
"16359","98.11800","8.17664","0.08910"
"16428","98.53200","8.21114","0.09039"
"16497","98.94600","8.24557","0.09052"
"16566","99.36000","8.28007","0.09144"
"16635","99.77400","8.31457","0.09259"
"16704","100.18800","8.34913","0.09227"
"16773","100.60200","8.38363","0.09403"
"16842","101.01600","8.41813","0.09451"
"16911","101.43000","8.45269","0.09633"
"16980","101.84400","8.48712","0.09783"
"17049","102.25800","8.52162","0.09904"
"17118","102.67200","8.55612","0.09898"
"17187","103.08600","8.59056","0.10139"
"17256","103.50000","8.62518","0.10298"
"17325","103.91400","8.65962","0.10415"
"17394","104.32800","8.69411","0.10558"
"17463","104.74200","8.72861","0.10661"
"17532","105.15600","8.76317","0.10824"
"17601","105.57000","8.79761","0.11014"
"17670","105.98400","8.83211","0.11106"
"17739","106.39800","8.86655","0.11276"
"17808","106.81200","8.90111","0.11458"
"17877","107.22600","8.93567","0.11571"
"17946","107.64000","8.97016","0.11700"
"18015","108.05400","9.00460","0.11699"
"18084","108.46800","9.03910","0.11814"
"18153","108.88200","9.07360","0.11996"
"18222","109.29600","9.10816","0.12056"
"18291","109.71000","9.14260","0.12237"
"18360","110.12400","9.17710","0.12377"
"18429","110.53800","9.21159","0.12436"
"18498","110.95200","9.24609","0.12664"
"18567","111.36600","9.28065","0.12766"
"18636","111.78000","9.31509","0.12869"
"18705","112.19400","9.34965","0.12967"
"18774","112.60800","9.38415","0.13143"
"18843","113.02200","9.41864","0.13287"
"18912","113.43600","9.45308","0.13413"
"18981","113.85000","9.48758","0.13532"
"19050","114.26400","9.52214","0.13628"
"19119","114.67800","9.55658","0.13727"
"19188","115.09200","9.59108","0.13843"
"19257","115.50600","9.62558","0.13979"
"19326","115.92000","9.66014","0.14068"
"19395","116.33400","9.69463","0.14215"
"19464","116.74800","9.72907","0.14327"
"19533","117.16200","9.76357","0.14425"
"19602","117.57600","9.79813","0.14529"
"19671","117.99000","9.83263","0.14649"
"19740","118.40400","9.86713","0.14700"
"19809","118.81800","9.90162","0.14777"
"19878","119.23200","9.93612","0.14898"
"19947","119.64600","9.97068","0.15032"
"20016","120.06000","10.00512","0.15143"
"20085","120.47400","10.03962","0.15328"
"20154","120.88800","10.07412","0.15412"
"20223","121.30200","10.10862","0.15531"
"20292","121.71600","10.14311","0.15704"
"20361","122.13000","10.17767","0.15773"
"20430","122.54400","10.21205","0.15949"
"20499","122.95800","10.24667","0.16008"
"20568","123.37200","10.28117","0.16188"
"20637","123.78600","10.31567","0.16295"
"20706","124.20000","10.35005","0.16365"
"20775","124.61400","10.38461","0.16477"
"20844","125.02800","10.41916","0.16615"
"20913","125.44200","10.45360","0.16737"
"20982","125.85600","10.48810","0.16881"
"21051","126.27000","10.52260","0.17006"
"21120","126.68400","10.55710","0.17149"
"21189","127.09800","10.59160","0.17281"
"21258","127.51200","10.62609","0.17442"
"21327","127.92600","10.66053","0.17561"
"21396","128.34000","10.69509","0.17657"
"21465","128.75400","10.72965","0.17769"
"21534","129.16800","10.76415","0.17841"
"21603","129.58200","10.79865","0.17928"
"21672","129.99600","10.83309","0.18057"
"21741","130.41000","10.86765","0.18144"
"21810","130.82401","10.90214","0.18174"
"21879","131.23801","10.93658","0.18269"
"21948","131.65199","10.97108","0.18345"
"22017","132.06599","11.00558","0.18407"
"22086","132.48000","11.04014","0.18470"
"22155","132.89400","11.07464","0.18554"
"22224","133.30800","11.10907","0.18644"
"22293","133.72200","11.14363","0.18694"
"22362","134.13600","11.17813","0.18768"
"22431","134.55000","11.21263","0.18904"
"22500","134.96400","11.24707","0.18953"
"22569","135.37801","11.28157","0.19080"
"22638","135.79201","11.31613","0.19206"
"22707","136.20599","11.35062","0.19323"
"22776","136.62000","11.38512","0.19479"
"22845","137.03400","11.41962","0.19612"
"22914","137.44800","11.45412","0.19697"
"22983","137.86200","11.48862","0.19844"
"23052","138.27600","11.52318","0.19986"
"23121","138.69000","11.55756","0.20084"
"23190","139.10400","11.59205","0.20263"
"23259","139.51801","11.62661","0.20395"
"23328","139.93201","11.66117","0.20542"
"23397","140.34599","11.69561","0.20685"
"23466","140.75999","11.73005","0.20847"
"23535","141.17400","11.76467","0.21075"
"23604","141.58800","11.79911","0.21289"
"23673","142.00200","11.83360","0.21435"
"23742","142.41600","11.86810","0.21718"
"23811","142.83000","11.90260","0.21889"
"23880","143.24400","11.93710","0.22020"
"23949","143.65800","11.97166","0.22130"
"24018","144.07201","12.00610","0.22261"
"24087","144.48599","12.04066","0.22397"
"24156","144.89999","12.07515","0.22538"
"24225","145.31400","12.10965","0.22758"
"24294","145.72800","12.14409","0.22945"
"24363","146.14200","12.17859","0.23053"
"24432","146.55600","12.21315","0.23280"
"24501","146.97000","12.24765","0.23420"
"24570","147.38400","12.28209","0.23648"
"24639","147.79800","12.31658","0.23815"
"24708","148.21201","12.35114","0.23932"
"24777","148.62601","12.38564","0.24186"
"24846","149.03999","12.42008","0.24142"
"24915","149.45399","12.45458","0.24259"
"24984","149.86800","12.48908","0.24404"
"25053","150.28200","12.52363","0.24649"
"25122","150.69600","12.55813","0.24764"
"25191","151.11000","12.59263","0.25100"
"25260","151.52400","12.62713","0.25401"
"25329","151.93800","12.66169","0.25720"
"25398","152.35201","12.69613","0.26107"
"25467","152.76601","12.73057","0.26412"
"25536","153.17999","12.76507","0.26755"
"25605","153.59399","12.79962","0.27055"
"25674","154.00800","12.83412","0.27387"
"25743","154.42200","12.86862","0.27634"
"25812","154.83600","12.90306","0.27825"
"25881","155.25000","12.93762","0.28010"
"25950","155.66400","12.97218","0.28275"
"26019","156.07800","13.00661","0.28365"
"26088","156.49200","13.04105","0.28540"
"26157","156.90601","13.07555","0.28709"
"26226","157.32001","13.11011","0.28787"
"26295","157.73399","13.14461","0.28969"
"26364","158.14799","13.17905","0.29045"
"26433","158.56200","13.21355","0.29160"
"26502","158.97600","13.24817","0.29265"
"26571","159.39000","13.28266","0.29314"
"26640","159.80400","13.31710","0.29411"
"26709","160.21800","13.35154","0.29505"
"26778","160.63200","13.38610","0.29613"
"26847","161.04601","13.42066","0.29753"
"26916","161.46001","13.45516","0.29860"
"26985","161.87399","13.48959","0.29986"
"27054","162.28799","13.52409","0.30104"
"27123","162.70200","13.55859","0.30277"
"27192","163.11600","13.59309","0.30503"
"27261","163.53000","13.62765","0.30725"
"27330","163.94400","13.66209","0.31124"
"27399","164.35800","13.69659","0.31366"
"27468","164.77200","13.73114","0.31795"
"27537","165.18600","13.76558","0.32094"
"27606","165.60001","13.80002","0.32410"
"27675","166.01401","13.83464","0.32748"
"27744","166.42799","13.86914","0.32993"
"27813","166.84200","13.90364","0.33251"
"27882","167.25600","13.93808","0.33600"
"27951","167.67000","13.97258","0.33829"
"28020","168.08400","14.00713","0.34150"
"28089","168.49800","14.04157","0.34508"
"28158","168.91200","14.07613","0.34713"
"28227","169.32600","14.11063","0.35005"
"28296","169.74001","14.14513","0.35218"
"28365","170.15401","14.17963","0.35391"
"28434","170.56799","14.21412","0.35613"
"28503","170.98199","14.24850","0.35826"
"28572","171.39600","14.28306","0.36116"
"28641","171.81000","14.31762","0.36402"
"28710","172.22400","14.35212","0.36719"
"28779","172.63800","14.38662","0.36916"
"28848","173.05200","14.42112","0.37203"
"28917","173.46600","14.45567","0.37408"
"28986","173.88000","14.49017","0.37603"
"29055","174.29401","14.52461","0.37808"
"29124","174.70799","14.55911","0.38030"
"29193","175.12199","14.59355","0.38224"
"29262","175.53600","14.62811","0.38409"
"29331","175.95000","14.66261","0.38601"
"29400","176.36400","14.69710","0.38770"
"29469","176.77800","14.73166","0.38949"
"29538","177.19200","14.76616","0.39203"
"29607","177.60600","14.80066","0.39471"
"29676","178.02000","14.83510","0.39738"
"29745","178.43401","14.86960","0.40079"
"29814","178.84801","14.90410","0.40339"
"29883","179.26199","14.93865","0.40703"
"29952","179.67599","14.97309","0.41049"
"30021","180.09000","15.00759","0.41337"
"30090","180.50400","15.04215","0.41689"
"30159","180.91800","15.07665","0.41982"
"30228","181.33200","15.11115","0.42350"
"30297","181.74600","15.14559","0.42671"
"30366","182.16000","15.18008","0.42954"
"30435","182.57401","15.21464","0.43146"
"30504","182.98801","15.24920","0.43356"
"30573","183.40199","15.28358","0.43573"
"30642","183.81599","15.31808","0.43820"
"30711","184.23000","15.35270","0.44110"
"30780","184.64400","15.38720","0.44410"
"30849","185.05800","15.42157","0.44722"
"30918","185.47200","15.45607","0.45051"
"30987","185.88600","15.49063","0.45392"
"31056","186.30000","15.52513","0.45718"
"31125","186.71400","15.55963","0.46106"
"31194","187.12801","15.59413","0.46490"
"31263","187.54201","15.62862","0.46979"
"31332","187.95599","15.66318","0.47402"
"31401","188.37000","15.69762","0.47766"
"31470","188.78400","15.73206","0.48270"
"31539","189.19800","15.76656","0.48591"
"31608","189.61200","15.80118","0.48981"
"31677","190.02600","15.83562","0.49266"
"31746","190.44000","15.87011","0.49460"
"31815","190.85400","15.90455","0.49641"
"31884","191.26801","15.93911","0.49836"
"31953","191.68201","15.97367","0.50023"
"32022","192.09599","16.00811","0.50318"
"32091","192.50999","16.04255","0.50579"
"32160","192.92400","16.07711","0.50894"
"32229","193.33800","16.11166","0.51159"
"32298","193.75200","16.14616","0.51454"
"32367","194.16600","16.18060","0.51853"
"32436","194.58000","16.21510","0.52204"
"32505","194.99400","16.24960","0.52623"
"32574","195.40800","16.28410","0.52990"
"32643","195.82201","16.31860","0.53336"
"32712","196.23599","16.35309","0.51177"
"32781","196.64999","16.38759","0.51080"
"32850","197.06400","16.42215","0.51669"
"32919","197.47800","16.45659","0.52264"
"32988","197.89200","16.49109","0.52884"
"33057","198.30600","16.52559","0.53433"
"33126","198.72000","16.56009","0.54091"
"33195","199.13400","16.59464","0.54537"
"33264","199.54800","16.62908","0.55069"
"33333","199.96201","16.66358","0.55417"
"33402","200.37601","16.69814","0.55928"
"33471","200.78999","16.73264","0.56428"
"33540","201.20399","16.76708","0.56971"
"33609","201.61800","16.80157","0.57400"
"33678","202.03200","16.83613","0.57866"
"33747","202.44600","16.87063","0.58135"
"33816","202.86000","16.90513","0.58395"
"33885","203.27400","16.93957","0.58689"
"33954","203.68800","16.97407","0.58953"
"34023","204.10201","17.00857","0.59222"
"34092","204.51601","17.04313","0.59436"
"34161","204.92999","17.07756","0.59735"
"34230","205.34399","17.11212","0.59936"
"34299","205.75800","17.14662","0.60280"
"34368","206.17200","17.18112","0.60727"
"34437","206.58600","17.21562","0.61170"
"34506","207.00000","17.25012","0.61687"
"34575","207.41400","17.28461","0.62382"
"34644","207.82800","17.31911","0.62957"
"34713","208.24200","17.35367","0.63506"
"34782","208.65601","17.38805","0.64064"
"34851","209.07001","17.42261","0.64451"
"34920","209.48399","17.45717","0.64773"
"34989","209.89799","17.49161","0.65182"
"35058","210.31200","17.52611","0.65704"
"35127","210.72600","17.56060","0.66118"
"35196","211.14000","17.59510","0.66463"
"35265","211.55400","17.62960","0.66965"
"35334","211.96800","17.66410","0.67396"
"35403","212.38200","17.69860","0.67967"
"35472","212.79601","17.73316","0.68435"
"35541","213.21001","17.76765","0.68972"
"35610","213.62399","17.80215","0.69310"
"35679","214.03799","17.83653","0.69635"
"35748","214.45200","17.87103","0.59418"
"35817","214.86600","17.90565","0.59537"
"35886","215.28000","17.94015","0.59715"
"35955","215.69400","17.97459","0.60027"
"36024","216.10800","18.00908","0.60416"
"36093","216.52200","18.04370","0.60884"
"36162","216.93600","18.07814","0.61444"
"36231","217.35001","18.11258","0.62077"
"36300","217.76401","18.14708","0.62854"
"36369","218.17799","18.18164","0.63497"
"36438","218.59200","18.21614","0.63913"
"36507","219.00600","18.25064","0.64268"
"36576","219.42000","18.28507","0.64696"
"36645","219.83400","18.31963","0.65263"
"36714","220.24800","18.35419","0.65705"
"36783","220.66200","18.38863","0.66176"
"36852","221.07600","18.42307","0.66670"
"36921","221.49001","18.45763","0.67278"
"36990","221.90401","18.49218","0.67778"
"37059","222.31799","18.52668","0.68160"
"37128","222.73199","18.56106","0.68765"
"37197","223.14600","18.59556","0.69206"
"37266","223.56000","18.63012","0.69523"
"37335","223.97400","18.66468","0.69797"
"37404","224.38800","18.69918","0.70016"
"37473","224.80200","18.73355","0.70245"
"37542","225.21600","18.76805","0.70490"
"37611","225.63000","18.80261","0.70797"
"37680","226.04401","18.83717","0.71112"
"37749","226.45799","18.87161","0.71342"
"37818","226.87199","18.90605","0.71730"
"37887","227.28600","18.94061","0.72036"
"37956","227.70000","18.97516","0.72534"
"38025","228.11400","19.00960","0.73106"
"38094","228.52800","19.04410","0.73572"
"38163","228.94200","19.07860","0.69514"
"38232","229.35600","19.11316","0.69912"
"38301","229.77000","19.14760","0.70166"
"38370","230.18401","19.18210","0.70475"
"38439","230.59801","19.21666","0.70927"
"38508","231.01199","19.25109","0.71326"
"38577","231.42599","19.28565","0.71663"
"38646","231.84000","19.32009","0.72227"
"38715","232.25400","19.35453","0.72814"
"38784","232.66800","19.38915","0.73407"
"38853","233.08200","19.42359","0.73829"
"38922","233.49600","19.45809","0.74372"
"38991","233.91000","19.49258","0.75029"
"39060","234.32401","19.52714","0.75670"
"39129","234.73801","19.56164","0.76282"
"39198","235.15199","19.59608","0.76987"
"39267","235.56599","19.63058","0.77433"
"39336","235.98000","19.66508","0.77561"
"39405","236.39400","19.69963","0.69850"
"39474","236.80800","19.73413","0.70158"
"39543","237.22200","19.76863","0.70441"
"39612","237.63600","19.80307","0.70827"
"39681","238.05000","19.83763","0.71125"
"39750","238.46400","19.87213","0.71598"
"39819","238.87801","19.90663","0.72269"
"39888","239.29201","19.94113","0.72998"
"39957","239.70599","19.97556","0.73704"
"40026","240.12000","20.01006","0.74236"
"40095","240.53400","20.04462","0.71783"
"40164","240.94800","20.07912","0.72378"
"40233","241.36200","20.11362","0.73166"
"40302","241.77600","20.14812","0.73550"
"40371","242.19000","20.18267","0.74123"
"40440","242.60400","20.21705","0.74498"
"40509","243.01801","20.25155","0.74967"
"40578","243.43201","20.28611","0.75476"
"40647","243.84599","20.32061","0.75968"
"40716","244.25999","20.35505","0.76649"
"40785","244.67400","20.38955","0.77242"
"40854","245.08800","20.42417","0.77649"
"40923","245.50200","20.45866","0.78440"
"40992","245.91600","20.49310","0.78963"
"41061","246.33000","20.52754","0.79405"
"41130","246.74400","20.56210","0.79802"
"41199","247.15800","20.59660","0.80015"
"41268","247.57201","20.63116","0.80475"
"41337","247.98599","20.66559","0.80708"
"41406","248.39999","20.70009","0.80919"
"41475","248.81400","20.73465","0.81101"
"41544","249.22800","20.76915","0.81186"
"41613","249.64200","20.80365","0.81603"
"41682","250.05600","20.83809","0.81964"
"41751","250.47000","20.87264","0.82412"
"41820","250.88400","20.90709","0.82822"
"41889","251.29800","20.94164","0.83383"
"41958","251.71201","20.97602","0.83868"
"42027","252.12601","21.01058","0.84377"
"42096","252.53999","21.04514","0.84861"
"42165","252.95399","21.07970","0.85400"
"42234","253.36800","21.11407","0.85921"
"42303","253.78200","21.14857","0.86399"
"42372","254.19600","21.18313","0.86996"
"42441","254.61000","21.21757","0.87576"
"42510","255.02400","21.25207","0.87979"
"42579","255.43800","21.28657","0.87275"
"42648","255.85201","21.32113","0.87873"
"42717","256.26599","21.35568","0.88485"
"42786","256.67999","21.39018","0.88985"
"42855","257.09399","21.42456","0.89364"
"42924","257.50800","21.45906","0.89821"
"42993","257.92200","21.49362","0.90161"
"43062","258.33600","21.52818","0.90474"
"43131","258.75000","21.56262","0.90904"
"43200","259.16400","21.59706","0.91436"
"43269","259.57800","21.63161","0.91914"
"43338","259.99200","21.66617","0.92562"
"43407","260.40601","21.70061","0.93229"
"43476","260.82001","21.73505","0.73619"
"43545","261.23401","21.76955","0.73657"
"43614","261.64801","21.80411","0.74533"
"43683","262.06201","21.83860","0.75339"
"43752","262.47601","21.87304","0.75714"
"43821","262.89001","21.90760","0.75776"
"43890","263.30399","21.94216","0.76390"
"43959","263.71799","21.97666","0.76786"
"44028","264.13199","22.01110","0.77613"
"44097","264.54599","22.04560","0.75765"
"44166","264.95999","22.08010","0.76447"
"44235","265.37399","22.11459","0.77174"
"44304","265.78799","22.14909","0.77511"
"44373","266.20200","22.18359","0.75885"
"44442","266.61600","22.21815","0.41818"
"44511","267.03000","22.25259","0.42420"
"44580","267.44400","22.28715","0.42711"
"44649","267.85800","22.32153","0.43025"
"44718","268.27200","22.35608","0.42862"
"44787","268.68600","22.39058","0.43195"
"44856","269.10001","22.42514","0.43446"
"44925","269.51401","22.45958","0.43918"
"44994","269.92801","22.49402","0.44272"
"45063","270.34201","22.52864","0.44675"
"45132","270.75601","22.56314","0.45240"
"45201","271.17001","22.59763","0.45549"
"45270","271.58401","22.63207","0.46191"
"45339","271.99799","22.66657","0.46654"
"45408","272.41199","22.70113","0.47385"
"45477","272.82599","22.73563","0.47885"
"45546","273.23999","22.77007","0.48455"
"45615","273.65399","22.80462","0.48961"
"45684","274.06799","22.83912","0.49300"
"45753","274.48199","22.87368","0.49601"
"45822","274.89600","22.90812","0.49830"
"45891","275.31000","22.94256","0.50102"
"45960","275.72400","22.97712","0.50411"
"46029","276.13800","23.01162","0.50780"
"46098","276.55200","23.04612","0.51168"
"46167","276.96600","23.08055","0.51666"
"46236","277.38000","23.11511","0.51926"
"46305","277.79401","23.14967","0.52522"
"46374","278.20801","23.18411","0.53086"
"46443","278.62201","23.21855","0.53725"
"46512","279.03601","23.25311","0.54343"
"46581","279.45001","23.28766","0.54885"
"46650","279.86401","23.32210","0.55554"
"46719","280.27802","23.35660","0.56085"
"46788","280.69199","23.39104","0.56597"
"46857","281.10599","23.42566","0.57185"
"46926","281.51999","23.46022","0.57824"
"46995","281.93399","23.49466","0.58112"
"47064","282.34799","23.52909","0.58452"
"47133","282.76199","23.56359","0.58798"
"47202","283.17599","23.59809","0.59029"
"47271","283.59000","23.63265","0.59336"
"47340","284.00400","23.66709","0.59547"
"47409","284.41800","23.70165","0.59810"
"47478","284.83200","23.73615","0.60069"
"47547","285.24600","23.77070","0.60414"
"47616","285.66000","23.80508","0.61032"
"47685","286.07401","23.83958","0.61625"
"47754","286.48801","23.87408","0.62378"
"47823","286.90201","23.90858","0.63014"
"47892","287.31601","23.94302","0.63653"
"47961","287.73001","23.97757","0.64095"
"48030","288.14401","24.01213","0.64454"
"48099","288.55801","24.04663","0.65045"
"48168","288.97198","24.08113","0.65529"
"48237","289.38599","24.11557","0.66004"
"48306","289.79999","24.15013","0.66438"
"48375","290.21399","24.18463","0.67079"
"48444","290.62799","24.21913","0.67582"
"48513","291.04199","24.25357","0.68172"
"48582","291.45599","24.28806","0.68582"
"48651","291.87000","24.32262","0.68644"
"48720","292.28400","24.35712","0.68858"
"48789","292.69800","24.39168","0.69357"
"48858","293.11200","24.42606","0.69755"
"48927","293.52600","24.46055","0.70039"
"48996","293.94000","24.49512","0.70281"
"49065","294.35400","24.52967","0.70529"
"49134","294.76801","24.56399","0.70855"
"49203","295.18201","24.59861","0.71239"
"49272","295.59601","24.63311","0.71643"
"49341","296.01001","24.66761","0.72093"
"49410","296.42401","24.70210","0.72667"
"49479","296.83801","24.73660","0.73288"
"49548","297.25201","24.77110","0.73728"
"49617","297.66599","24.80554","0.74258"
"49686","298.07999","24.84010","0.74857"
"49755","298.49399","24.87460","0.75573"
"49824","298.90799","24.90910","0.76192"
"49893","299.32199","24.94365","0.76864"
"49962","299.73599","24.97809","0.77683"
"50031","300.14999","25.01259","0.78496"
"50100","300.56400","25.04703","0.79250"
"50169","300.97800","25.08159","0.79813"
"50238","301.39200","25.11609","0.80237"
"50307","301.80600","25.15065","0.80625"
"50376","302.22000","25.18509","0.80893"
"50445","302.63400","25.21970","0.81086"
"50514","303.04800","25.25414","0.81427"
"50583","303.46201","25.28864","0.81913"
"50652","303.87601","25.32308","0.82354"
"50721","304.29001","25.35758","0.82861"
"50790","304.70401","25.39214","0.83385"
"50859","305.11801","25.42663","0.83935"
"50928","305.53201","25.46107","0.84375"
"50997","305.94601","25.49563","0.84840"
"51066","306.35999","25.53013","0.85515"
"51135","306.77399","25.56463","0.86284"
"51204","307.18799","25.59913","0.86778"
"51273","307.60199","25.63363","0.86863"
"51342","308.01599","25.66807","0.87402"
"51411","308.42999","25.70256","0.88192"
"51480","308.84399","25.73712","0.88831"
"51549","309.25800","25.77156","0.89327"
"51618","309.67200","25.80612","0.89826"
"51687","310.08600","25.84062","0.90223"
"51756","310.50000","25.87518","0.90649"
"51825","310.91400","25.90955","0.91085"
"51894","311.32800","25.94411","0.91542"
"51963","311.74200","25.97861","0.92121"
"52032","312.15601","26.01317","0.92657"
"52101","312.57001","26.04761","0.93175"
"52170","312.98401","26.08205","0.93890"
"52239","313.39801","26.11667","0.94624"
"52308","313.81201","26.15117","0.95346"
"52377","314.22601","26.18560","0.96066"
"52446","314.64001","26.22010","0.96857"
"52515","315.05399","26.25460","0.97389"
"52584","315.46799","26.28910","0.97916"
"52653","315.88199","26.32366","0.98612"
"52722","316.29599","26.35810","0.99145"
"52791","316.70999","26.39259","0.99626"
"52860","317.12399","26.42715","0.99997"
"52929","317.53799","26.46171","1.00262"
"52998","317.95200","26.49615","1.00455"
"53067","318.36600","26.53059","1.00636"
"53136","318.78000","26.56515","1.00919"
"53205","319.19400","26.59959","1.01378"
"53274","319.60800","26.63415","1.01858"
"53343","320.02200","26.66858","1.02503"
"53412","320.43600","26.70308","1.03398"
"53481","320.85001","26.73764","1.04364"
"53550","321.26401","26.77214","1.05093"
"53619","321.67801","26.80658","1.05786"
"53688","322.09201","26.84108","1.06474"
"53757","322.50601","26.87569","1.06009"
"53826","322.92001","26.91013","1.06410"
"53895","323.33401","26.94457","1.06327"
"53964","323.74799","26.97907","0.90369"
"54033","324.16199","27.01363","0.90890"
"54102","324.57599","27.04813","0.91394"
"54171","324.98999","27.08263","0.92303"
"54240","325.40399","27.11712","0.93001"
"54309","325.81799","27.15156","0.94209"
"54378","326.23199","27.18612","0.94897"
"54447","326.64600","27.22062","0.95891"
"54516","327.06000","27.25506","0.96807"
"54585","327.47400","27.28962","0.97512"
"54654","327.88800","27.32412","0.98309"
"54723","328.30200","27.35867","0.99029"
"54792","328.71600","27.39311","0.99583"
"54861","329.13000","27.42755","1.00097"
"54930","329.54401","27.46211","1.00345"
"54999","329.95801","27.49661","1.00679"
"55068","330.37201","27.53111","1.01085"
"55137","330.78601","27.56555","1.01611"
"55206","331.20001","27.60011","1.02189"
"55275","331.61401","27.63460","1.02982"
"55344","332.02802","27.66910","1.04104"
"55413","332.44199","27.70360","1.04969"
"55482","332.85599","27.73810","1.05850"
"55551","333.26999","27.77260","1.06596"
"55620","333.68399","27.80709","1.07504"
"55689","334.09799","27.84159","1.08433"
"55758","334.51199","27.87609","1.09555"
"55827","334.92599","27.91065","1.10388"
"55896","335.34000","27.94509","1.10997"
"55965","335.75400","27.97965","1.11523"
"56034","336.16800","28.01409","1.11702"
"56103","336.58200","28.04859","1.11994"
"56172","336.99600","28.08315","1.12243"
"56241","337.41000","28.11764","1.12500"
"56310","337.82401","28.15202","1.07791"
"56379","338.23801","28.18664","1.08148"
"56448","338.65201","28.22114","1.08895"
"56517","339.06601","28.25564","1.09722"
"56586","339.48001","28.29008","1.10545"
"56655","339.89401","28.32457","1.11177"
"56724","340.30801","28.35913","1.11661"
"56793","340.72198","28.39357","1.11961"
"56862","341.13599","28.42807","1.12194"
"56931","341.54999","28.46257","1.12570"
"57000","341.96399","28.49713","1.13049"
"57069","342.37799","28.53168","1.13796"
"57138","342.79199","28.56612","1.14609"
"57207","343.20599","28.60056","1.15415"
"57276","343.62000","28.63506","1.16269"
"57345","344.03400","28.66962","1.17120"
"57414","344.44800","28.70412","1.18010"
"57483","344.86200","28.73862","1.19181"
"57552","345.27600","28.77305","1.20142"
"57621","345.69000","28.80767","1.18380"
"57690","346.10400","28.84217","1.19442"
"57759","346.51801","28.87667","1.20272"
"57828","346.93201","28.91111","1.20916"
"57897","347.34601","28.94561","1.21372"
"57966","347.76001","28.98017","1.21784"
"58035","348.17401","29.01461","1.22411"
"58104","348.58801","29.04911","1.23144"
"58173","349.00201","29.08360","1.23924"
"58242","349.41599","29.11816","1.25029"
"58311","349.82999","29.15266","1.25946"
"58380","350.24399","29.18716","1.26509"
"58449","350.65799","29.22160","1.27127"
"58518","351.07199","29.25609","1.24349"
"58587","351.48599","29.29059","1.25381"
"58656","351.89999","29.32509","1.26169"
"58725","352.31400","29.35959","1.26876"
"58794","352.72800","29.39409","1.27293"
"58863","353.14200","29.42865","1.27870"
"58932","353.55600","29.46315","1.28596"
"59001","353.97000","29.49758","1.29453"
"59070","354.38400","29.53208","1.30116"
"59139","354.79800","29.56664","1.30869"
"59208","355.21201","29.60114","1.31630"
"59277","355.62601","29.63558","1.32368"
"59346","356.04001","29.67008","1.33137"
"59415","356.45401","29.70464","1.34266"
"59484","356.86801","29.73913","1.35384"
"59553","357.28201","29.77363","1.36340"
"59622","357.69601","29.80807","1.37176"
"59691","358.10999","29.84263","1.38154"
"59760","358.52399","29.87713","1.39300"
"59829","358.93799","29.91169","1.40345"
"59898","359.35199","29.94607","1.41318"
"59967","359.76599","29.98057","1.41820"
"60036","360.17999","30.01512","1.42130"
"60105","360.59399","30.04968","1.42270"
"60174","361.00800","30.08412","1.42441"
"60243","361.42200","30.11856","1.42817"
"60312","361.83600","30.15312","1.43366"
"60381","362.25000","30.18762","1.44321"
"60450","362.66400","30.22212","1.45445"
"60519","363.07800","30.25655","1.46552"
"60588","363.49200","30.29111","1.47474"
"60657","363.90601","30.32561","1.48327"
"60726","364.32001","30.36011","1.49201"
"60795","364.73401","30.39461","1.50234"
"60864","365.14801","30.42911","1.51131"
"60933","365.56201","30.46361","1.51717"
"61002","365.97601","30.49810","1.52338"
"61071","366.39001","30.53260","1.53008"
"61140","366.80399","30.56704","1.53730"
"61209","367.21799","30.60166","1.54422"
"61278","367.63199","30.63610","1.54901"
"61347","368.04599","30.67060","1.55542"
"61416","368.45999","30.70509","1.56424"
"61485","368.87399","30.73959","1.57034"
"61554","369.28799","30.77415","1.57556"
"61623","369.70200","30.80859","1.58109"
"61692","370.11600","30.84303","1.58536"
"61761","370.53000","30.87759","1.59316"
"61830","370.94400","30.91215","1.60300"
"61899","371.35800","30.94665","1.61165"
"61968","371.77200","30.98108","1.61795"
"62037","372.18600","31.01558","1.62489"
"62106","372.60001","31.05014","1.62999"
"62175","373.01401","31.08464","1.07322"
"62244","373.42801","31.11908","1.00862"
"62313","373.84201","31.15358","1.00452"
"62382","374.25601","31.18807","0.89330"
"62451","374.67001","31.22269","0.78174"
"62520","375.08401","31.25713","0.79396"
"62589","375.49799","31.29157","0.79555"
"62658","375.91199","31.32613","0.80215"
"62727","376.32599","31.36057","0.80552"
"62796","376.73999","31.39513","0.80302"
"62865","377.15399","31.42956","0.80758"
"62934","377.56799","31.46406","0.81544"
"63003","377.98199","31.49862","0.81220"
"63072","378.39600","31.53312","0.81342"
"63141","378.81000","31.56768","0.82511"
"63210","379.22400","31.60205","0.82982"
"63279","379.63800","31.63661","0.82798"
"63348","380.05200","31.67111","0.83914"
"63417","380.46600","31.70561","0.85087"
"63486","380.88000","31.74011","0.84928"
"63555","381.29401","31.77461","0.85465"
"63624","381.70801","31.80917","0.86809"
"63693","382.12201","31.84367","0.87270"
"63762","382.53601","31.87810","0.87563"
"63831","382.95001","31.91260","0.88560"
"63900","383.36401","31.94716","0.89288"
"63969","383.77802","31.98160","0.90056"
"64038","384.19199","32.01610","0.90344"
"64107","384.60599","32.05060","0.90624"
"64176","385.01999","32.08509","0.91536"
"64245","385.43399","32.11966","0.92387"
"64314","385.84799","32.15416","0.92962"
"64383","386.26199","32.18865","0.93889"
"64452","386.67599","32.22309","0.94595"
"64521","387.09000","32.25759","0.95876"
"64590","387.50400","32.29214","0.96547"
"64659","387.91800","32.32664","0.97194"
"64728","388.33200","32.36108","0.97650"
"64797","388.74600","32.39564","0.98247"
"64866","389.16000","32.43014","0.99248"
"64935","389.57401","32.46464","0.99800"
"65004","389.98801","32.49908","1.00228"
"65073","390.40201","32.53358","1.00390"
"65142","390.81601","32.56813","1.00699"
"65211","391.23001","32.60263","1.00972"
"65280","391.64401","32.63707","1.01604"
"65349","392.05801","32.67163","1.02282"
"65418","392.47198","32.70613","1.03490"
"65487","392.88599","32.74063","1.04460"
"65556","393.29999","32.77513","1.05328"
"65625","393.71399","32.80963","1.06073"
"65694","394.12799","32.84412","1.07064"
"65763","394.54199","32.87862","1.08064"
"65832","394.95599","32.91312","1.09159"
"65901","395.37000","32.94756","1.10038"
"65970","395.78400","32.98206","1.10824"
"66039","396.19800","33.01662","1.11467"
"66108","396.61200","33.05117","0.94559"
"66177","397.02600","33.08561","0.41294"
"66246","397.44000","33.12011","0.42728"
"66315","397.85400","33.15455","0.42131"
"66384","398.26801","33.18917","0.43121"
"66453","398.68201","33.22355","0.44201"
"66522","399.09601","33.25805","0.44358"
"66591","399.51001","33.29261","0.44446"
"66660","399.92401","33.32710","0.45361"
"66729","400.33801","33.36160","0.45676"
"66798","400.75201","33.39610","0.46947"
"66867","401.16599","33.43060","0.47555"
"66936","401.57999","33.46516","0.47390"
"67005","401.99399","33.49966","0.48462"
"67074","402.40799","33.53410","0.49060"
"67143","402.82199","33.56860","0.49450"
"67212","403.23599","33.60309","0.49974"
"67281","403.64999","33.63765","0.49872"
"67350","404.06400","33.67209","0.50190"
"67419","404.47800","33.70658","0.50840"
"67488","404.89200","33.74115","0.50958"
"67557","405.30600","33.77559","0.51792"
"67626","405.72000","33.81014","0.52300"
"67695","406.13400","33.84452","0.52892"
"67764","406.54800","33.87908","0.53845"
"67833","406.96201","33.91370","0.53919"
"67902","407.37601","33.94814","0.54894"
"67971","407.79001","33.98257","0.55077"
"68040","408.20401","34.01707","0.55821"
"68109","408.61801","34.05164","0.56279"
"68178","409.03201","34.08613","0.56856"
"68247","409.44601","34.12063","0.57670"
"68316","409.85999","34.15507","0.57854"
"68385","410.27399","34.18962","0.44961"
"68454","410.68799","34.22412","0.44899"
"68523","411.10199","34.25863","0.45365"
"68592","411.51599","34.29312","0.45774"
"68661","411.92999","34.32762","0.46566"
"68730","412.34399","34.36212","0.47623"
"68799","412.75800","34.39662","0.48105"
"68868","413.17200","34.43112","0.48499"
"68937","413.58600","34.46561","0.49110"
"69006","414.00000","34.50011","0.49350"
"69075","414.41400","34.53468","0.49633"
"69144","414.82800","34.56911","0.50033"
"69213","415.24200","34.60355","0.50268"
"69282","415.65601","34.63811","0.50619"
"69351","416.07001","34.67261","0.50993"
"69420","416.48401","34.70711","0.51183"
"69489","416.89801","34.74154","0.51683"
"69558","417.31201","34.77610","0.52185"
"69627","417.72601","34.81066","0.52753"
"69696","418.14001","34.84516","0.53490"
"69765","418.55399","34.87966","0.53914"
"69834","418.96799","34.91410","0.54634"
"69903","419.38199","34.94859","0.55137"
"69972","419.79599","34.98315","0.55652"
"70041","420.20999","35.01759","0.56272"
"70110","420.62399","35.05209","0.56826"
"70179","421.03799","35.08659","0.57532"
"70248","421.45200","35.12109","0.57942"
"70317","421.86600","35.15570","0.58379"
"70386","422.28000","35.19009","0.58659"
"70455","422.69400","35.22464","0.59018"
"70524","423.10800","35.25914","0.59332"
"70593","423.52200","35.29364","0.59546"
"70662","423.93600","35.32802","0.59906"
"70731","424.35001","35.36258","0.60233"
"70800","424.76401","35.39714","0.60703"
"70869","425.17801","35.43163","0.61270"
"70938","425.59201","35.46613","0.61998"
"71007","426.00601","35.50063","0.62703"
"71076","426.42001","35.53513","0.63484"
"71145","426.83401","35.56957","0.63959"
"71214","427.24799","35.60413","0.64515"
"71283","427.66199","35.63857","0.65044"
"71352","428.07599","35.67313","0.65732"
"71421","428.48999","35.70762","0.66184"
"71490","428.90399","35.74212","0.66809"
"71559","429.31799","35.77662","0.67354"
"71628","429.73199","35.81112","0.68121"
"71697","430.14600","35.84562","0.68657"
"71766","430.56000","35.88012","0.69179"
"71835","430.97400","35.91462","0.69573"
"71904","431.38800","35.94905","0.69889"
"71973","431.80200","35.98362","0.70147"
"72042","432.21600","36.01811","0.70444"
"72111","432.63000","36.05261","0.70866"
"72180","433.04401","36.08711","0.71228"
"72249","433.45801","36.12155","0.71659"
"72318","433.87201","36.15617","0.72167"
"72387","434.28601","36.19060","0.72891"
"72456","434.70001","36.22504","0.73778"
"72525","435.11401","36.25960","0.74477"
"72594","435.52802","36.29416","0.75124"
"72663","435.94199","36.32860","0.75665"
"72732","436.35599","36.36310","0.76350"
"72801","436.76999","36.39759","0.77082"
"72870","437.18399","36.43209","0.78016"
"72939","437.59799","36.46659","0.78756"
"73008","438.01199","36.50109","0.79349"
"73077","438.42599","36.53553","0.79857"
"73146","438.84000","36.57009","0.80343"
"73215","439.25400","36.60459","0.80680"
"73284","439.66800","36.63914","0.80945"
"73353","440.08200","36.67358","0.81319"
"73422","440.49600","36.70808","0.81701"
"73491","440.91000","36.74258","0.82162"
"73560","441.32401","36.77714","0.82678"
"73629","441.73801","36.81158","0.83301"
"73698","442.15201","36.84608","0.83878"
"73767","442.56601","36.88063","0.84419"
"73836","442.98001","36.91513","0.84920"
"73905","443.39401","36.94963","0.85449"
"73974","443.80801","36.98407","0.86121"
"74043","444.22198","37.01857","0.86772"
"74112","444.63599","37.05313","0.87504"
"74181","445.04999","37.08763","0.88337"
"74250","445.46399","37.12207","0.88908"
"74319","445.87799","37.15656","0.89497"
"74388","446.29199","37.19106","0.89963"
"74457","446.70599","37.22562","0.90415"
"74526","447.12000","37.26012","0.90847"
"74595","447.53400","37.29462","0.91333"
"74664","447.94800","37.32918","0.91950"
"74733","448.36200","37.36361","0.92678"
"74802","448.77600","37.39811","0.93624"
"74871","449.19000","37.43255","0.94512"
"74940","449.60400","37.46711","0.95184"
"75009","450.01801","37.50167","0.95971"
"75078","450.43201","37.53611","0.96701"
"75147","450.84601","37.57061","0.97395"
"75216","451.26001","37.60511","0.98072"
"75285","451.67401","37.63960","0.98807"
"75354","452.08801","37.67410","0.99388"
"75423","452.50201","37.70860","0.99869"
"75492","452.91599","37.74304","1.00176"
"75561","453.32999","37.77766","1.00443"
"75630","453.74399","37.81210","1.00823"
"75699","454.15799","37.84665","1.01225"
"75768","454.57199","37.88115","1.01651"
"75837","454.98599","37.91565","1.02264"
"75906","455.39999","37.95015","1.03072"
"75975","455.81400","37.98465","1.04094"
"76044","456.22800","38.01909","1.04547"
"76113","456.64200","38.05359","1.05173"
"76182","457.05600","38.08815","1.05776"
"76251","457.47000","38.12264","1.06583"
"76320","457.88400","38.15714","1.07482"
"76389","458.29800","38.19158","1.08421"
"76458","458.71201","38.22614","1.09570"
"76527","459.12601","38.26058","1.10410"
"76596","459.54001","38.29502","1.11122"
"76665","459.95401","38.32952","1.11622"
"76734","460.36801","38.36414","1.11962"
"76803","460.78201","38.39863","1.12170"
"76872","461.19601","38.43313","1.12470"
"76941","461.60999","38.46763","1.12787"
"77010","462.02399","38.50213","1.13327"
"77079","462.43799","38.53663","1.13998"
"77148","462.85199","38.57113","1.14605"
"77217","463.26599","38.60562","1.15352"
"77286","463.67999","38.64006","1.16136"
"77355","464.09399","38.67462","1.16940"
"77424","464.50800","38.70912","1.17651"
"77493","464.92200","38.74362","1.18762"
"77562","465.33600","38.77806","1.19911"
"77631","465.75000","38.81261","1.20624"
"77700","466.16400","38.84711","1.21177"
"77769","466.57800","38.88161","1.21653"
"77838","466.99200","38.91605","1.21555"
"77907","467.40601","38.95061","1.22084"
"77976","467.82001","38.98517","1.22777"
"78045","468.23401","39.01961","1.23500"
"78114","468.64801","39.05404","1.24391"
"78183","469.06201","39.08860","1.25513"
"78252","469.47601","39.12310","1.26188"
"78321","469.89001","39.15760","1.26662"
"78390","470.30399","39.19210","1.27100"
"78459","470.71799","39.22654","1.27673"
"78528","471.13199","39.26110","1.28315"
"78597","471.54599","39.29565","1.29329"
"78666","471.95999","39.33015","1.30081"
"78735","472.37399","39.36459","1.30663"
"78804","472.78799","39.39909","1.31339"
"78873","473.20200","39.43365","1.31996"
"78942","473.61600","39.46815","1.32567"
"79011","474.03000","39.50265","1.33169"
"79080","474.44400","39.53703","1.34053"
"79149","474.85800","39.57164","1.35015"
"79218","475.27200","39.60614","1.31314"
"79287","475.68600","39.64070","1.31794"
"79356","476.10001","39.67508","1.32386"
"79425","476.51401","39.70958","1.32973"
"79494","476.92801","39.74414","1.33805"
"79563","477.34201","39.77863","1.34959"
"79632","477.75601","39.81307","1.35935"
"79701","478.17001","39.84757","1.36743"
"79770","478.58401","39.88213","1.37440"
"79839","478.99799","39.91663","1.38362"
"79908","479.41199","39.95113","1.39308"
"79977","479.82599","39.98563","1.40204"
"80046","480.23999","40.02012","1.41007"
"80115","480.65399","40.05462","1.41528"
"80184","481.06799","40.08912","1.41953"
"80253","481.48199","40.12356","1.42189"
"80322","481.89600","40.15812","1.42235"
"80391","482.31000","40.19262","1.42358"
"80460","482.72400","40.22717","1.42629"
"80529","483.13800","40.26162","1.43119"
"80598","483.55200","40.29605","1.43732"
"80667","483.96600","40.33061","1.44707"
"80736","484.38000","40.36511","1.45687"
"80805","484.79401","40.39955","1.46517"
"80874","485.20801","40.43404","1.47428"
"80943","485.62201","40.46861","1.48174"
"81012","486.03601","40.50316","1.49044"
"81081","486.45001","40.53766","1.49938"
"81150","486.86401","40.57210","1.50847"
"81219","487.27802","40.60660","1.22564"
"81288","487.69199","40.64116","1.23209"
"81357","488.10599","40.67566","0.61998"
"81426","488.51999","40.71009","0.60901"
"81495","488.93399","40.74459","0.62312"
"81564","489.34799","40.77909","0.61077"
"81633","489.76199","40.81359","0.61987"
"81702","490.17599","40.84815","0.65816"
"81771","490.59000","40.88259","0.64501"
"81840","491.00400","40.91714","0.68619"
"81909","491.41800","40.95159","0.66238"
"81978","491.83200","40.98614","0.68388"
"82047","492.24600","41.02052","0.67681"
"82116","492.66000","41.05508","0.68987"
"82185","493.07401","41.08964","0.69927"
"82254","493.48801","41.12413","0.70085"
"82323","493.90201","41.15863","0.71177"
"82392","494.31601","41.19313","0.70845"
"82461","494.73001","41.22763","0.72830"
"82530","495.14401","41.26213","0.72462"
"82599","495.55801","41.29663","0.74672"
"82668","495.97198","41.33101","0.73987"
"82737","496.38599","41.36563","0.76360"
"82806","496.79999","41.40012","0.76313"
"82875","497.21399","41.43456","0.77752"
"82944","497.62799","41.46912","0.78660"
"83013","498.04199","41.50362","0.79441"
"83082","498.45599","41.53818","0.80632"
"83151","498.87000","41.57262","0.80461"
"83220","499.28400","41.60712","0.81861"
"83289","499.69800","41.64156","0.81301"
"83358","500.11200","41.67606","0.82925"
"83427","500.52600","41.71067","0.82482"
"83496","500.94000","41.74511","0.83569"
"83565","501.35400","41.77955","0.84579"
"83634","501.76801","41.81417","0.84536"
"83703","502.18201","41.84861","0.86697"
"83772","502.59601","41.88311","0.86057"
"83841","503.01001","41.91755","0.87369"
"83910","503.42401","41.95205","0.88717"
"83979","503.83801","41.98666","0.88743"
"84048","504.25201","42.02116","0.90215"
"84117","504.66599","42.05554","0.90176"
"84186","505.07999","42.09010","0.90641"
"84255","505.49399","42.12466","0.92224"
"84324","505.90799","42.15910","0.92023"
"84393","506.32199","42.19359","0.92999"
"84462","506.73599","42.22803","0.94641"
"84531","507.14999","42.26259","0.94470"
"84600","507.56400","42.29709","0.95545"
"84669","507.97800","42.33165","0.97222"
"84738","508.39200","42.36609","0.97194"
"84807","508.80600","42.40059","0.97980"
"84858","509.11200","42.42618","0.98514"