File: Trajectories_together/170107_1Specimen_RawData_5.csv
"","V1","V2","V3"
"1","End date","1/7/2017",""
"2","Specimen label","DT18_41",""
"3","Maximum Load","0.02543","N"
"4","Time","Extension","Load"
"5","(s)","(mm)","(N)"
"6","0.00000","0.00000","-0.00006"
"76","0.42000","0.03528","0.00044"
"146","0.84000","0.07019","0.00039"
"216","1.26000","0.10529","0.00030"
"286","1.68000","0.14027","0.00042"
"356","2.10000","0.17524","0.00061"
"426","2.52000","0.21022","0.00025"
"496","2.94000","0.24520","0.00070"
"566","3.36000","0.28023","0.00046"
"636","3.78000","0.31521","0.00070"
"706","4.20000","0.35019","0.00075"
"776","4.62000","0.38522","0.00139"
"846","5.04000","0.42020","0.00050"
"916","5.46000","0.45518","0.00100"
"986","5.88000","0.49021","0.00124"
"1056","6.30000","0.52519","0.00095"
"1126","6.72000","0.56023","0.00095"
"1196","7.14000","0.59520","0.00108"
"1266","7.56000","0.63024","0.00082"
"1336","7.98000","0.66522","0.00074"
"1406","8.40000","0.70020","0.00096"
"1476","8.82000","0.73523","0.00110"
"1546","9.24000","0.77027","0.00112"
"1616","9.66000","0.80519","0.00102"
"1686","10.08000","0.84016","0.00104"
"1756","10.50000","0.87520","0.00085"
"1826","10.92000","0.91030","0.00180"
"1896","11.34000","0.94527","0.00133"
"1966","11.76000","0.98019","0.00125"
"2036","12.18000","1.01523","0.00205"
"2106","12.60000","1.05026","0.00127"
"2176","13.02000","1.08530","0.00159"
"2246","13.44000","1.12028","0.00162"
"2316","13.86000","1.15519","0.00187"
"2386","14.28000","1.19017","0.00107"
"2456","14.70000","1.22527","0.00116"
"2526","15.12000","1.26024","0.00189"
"2596","15.54000","1.29522","0.00171"
"2666","15.96000","1.33014","0.00128"
"2736","16.38000","1.36523","0.00148"
"2806","16.80000","1.40021","0.00144"
"2876","17.22000","1.43531","0.00211"
"2946","17.64000","1.47022","0.00214"
"3016","18.06000","1.50514","0.00191"
"3086","18.48000","1.54024","0.00159"
"3156","18.90000","1.57522","0.00151"
"3226","19.32000","1.61025","0.00154"
"3296","19.74000","1.64517","0.00229"
"3366","20.16000","1.68021","0.00162"
"3436","20.58000","1.71524","0.00176"
"3506","21.00000","1.75022","0.00215"
"3576","21.42000","1.78520","0.00216"
"3646","21.84000","1.82017","0.00263"
"3716","22.26000","1.85521","0.00218"
"3786","22.68000","1.89025","0.00222"
"3856","23.10000","1.92522","0.00229"
"3926","23.52000","1.96020","0.00244"
"3996","23.94000","1.99524","0.00232"
"4066","24.36000","2.03021","0.00262"
"4136","24.78000","2.06531","0.00279"
"4206","25.20000","2.10023","0.00257"
"4276","25.62000","2.13520","0.00303"
"4346","26.04000","2.17024","0.00237"
"4416","26.46000","2.20528","0.00273"
"4486","26.88000","2.24019","0.00275"
"4556","27.30000","2.27517","0.00240"
"4626","27.72000","2.31021","0.00271"
"4696","28.14000","2.34524","0.00288"
"4766","28.56000","2.38022","0.00253"
"4836","28.98000","2.41520","0.00293"
"4906","29.40000","2.45017","0.00279"
"4976","29.82000","2.48527","0.00308"
"5046","30.24000","2.52025","0.00334"
"5116","30.66000","2.55529","0.00370"
"5186","31.08000","2.59020","0.00392"
"5256","31.50200","2.62536","0.00339"
"5326","31.92200","2.66040","0.00400"
"5396","32.34200","2.69537","0.00389"
"5466","32.76200","2.73041","0.00376"
"5536","33.18200","2.76527","0.00380"
"5606","33.60200","2.80036","0.00386"
"5676","34.02200","2.83540","0.00456"
"5746","34.44200","2.87044","0.00432"
"5816","34.86200","2.90535","0.00446"
"5886","35.28200","2.94033","0.00363"
"5956","35.70200","2.97543","0.00439"
"6026","36.12200","3.01046","0.00417"
"6096","36.54200","3.04544","0.00473"
"6166","36.96200","3.08036","0.00432"
"6236","37.38200","3.11539","0.00451"
"6306","37.80200","3.15043","0.00473"
"6376","38.22200","3.18541","0.00496"
"6446","38.64200","3.22032","0.00469"
"6516","39.06200","3.25536","0.00479"
"6586","39.48200","3.29034","0.00495"
"6656","39.90200","3.32537","0.00510"
"6726","40.32200","3.36041","0.00566"
"6796","40.74200","3.39539","0.00443"
"6866","41.16200","3.43042","0.00578"
"6936","41.58200","3.46540","0.00558"
"7006","42.00200","3.50044","0.00569"
"7076","42.42200","3.53541","0.00558"
"7146","42.84200","3.57033","0.00536"
"7216","43.26200","3.60537","0.00600"
"7286","43.68200","3.64041","0.00524"
"7356","44.10200","3.67538","0.00567"
"7426","44.52200","3.71036","0.00568"
"7496","44.94200","3.74534","0.00608"
"7566","45.36200","3.78043","0.00644"
"7636","45.78200","3.81535","0.00570"
"7706","46.20200","3.85039","0.00629"
"7776","46.62200","3.88536","0.00560"
"7846","47.04200","3.92040","0.00623"
"7916","47.46200","3.95538","0.00606"
"7986","47.88200","3.99047","0.00612"
"8056","48.30200","4.02539","0.00588"
"8126","48.72200","4.06037","0.00648"
"8196","49.14200","4.09546","0.00611"
"8266","49.56200","4.13038","0.00633"
"8336","49.98200","4.16542","0.00683"
"8406","50.40200","4.20033","0.00660"
"8476","50.82200","4.23543","0.00720"
"8546","51.24200","4.27047","0.00684"
"8616","51.66200","4.30544","0.00715"
"8686","52.08200","4.34036","0.00629"
"8756","52.50200","4.37534","0.00730"
"8826","52.92200","4.41049","0.00707"
"8896","53.34200","4.44541","0.00727"
"8966","53.76200","4.48039","0.00661"
"9036","54.18200","4.51537","0.00758"
"9106","54.60200","4.55040","0.00741"
"9176","55.02200","4.58538","0.00778"
"9246","55.44200","4.62042","0.00778"
"9316","55.86200","4.65539","0.00703"
"9386","56.28200","4.69037","0.00779"
"9456","56.70200","4.72535","0.00750"
"9526","57.12200","4.76038","0.00811"
"9596","57.54200","4.79542","0.00765"
"9666","57.96200","4.83034","0.00785"
"9736","58.38200","4.86537","0.00818"
"9806","58.80200","4.90041","0.00779"
"9876","59.22200","4.93545","0.00837"
"9946","59.64200","4.97042","0.00875"
"10016","60.06200","5.00540","0.00771"
"10086","60.48200","5.04038","0.00830"
"10156","60.90200","5.07541","0.00871"
"10226","61.32200","5.11039","0.00834"
"10296","61.74200","5.14531","0.00854"
"10366","62.16200","5.18034","0.00879"
"10436","62.58200","5.21544","0.00819"
"10506","63.00200","5.25036","0.00851"
"10576","63.42200","5.28539","0.00866"
"10646","63.84200","5.32037","0.00869"
"10716","64.26200","5.35541","0.00862"
"10786","64.68200","5.39044","0.00901"
"10856","65.10200","5.42542","0.00833"
"10926","65.52200","5.46040","0.00938"
"10996","65.94200","5.49544","0.00924"
"11066","66.36200","5.53041","0.00891"
"11136","66.78200","5.56539","0.00924"
"11206","67.20200","5.60043","0.00936"
"11276","67.62200","5.63528","0.00941"
"11346","68.04200","5.67044","0.00885"
"11416","68.46200","5.70542","0.00958"
"11486","68.88200","5.74045","0.00968"
"11556","69.30200","5.77537","0.00887"
"11626","69.72200","5.81041","0.00940"
"11696","70.14200","5.84544","0.00991"
"11766","70.56200","5.88042","0.00998"
"11836","70.98200","5.91540","0.00897"
"11906","71.40200","5.95037","0.00842"
"11976","71.82200","5.98535","0.00901"
"12046","72.24200","6.02039","0.00906"
"12116","72.66200","6.05542","0.00929"
"12186","73.08200","6.09034","0.00885"
"12256","73.50200","6.12538","0.00948"
"12326","73.92200","6.16041","0.00883"
"12396","74.34200","6.19545","0.00931"
"12466","74.76200","6.23037","0.00912"
"12536","75.18200","6.26535","0.00897"
"12606","75.60200","6.30038","0.00926"
"12676","76.02200","6.33542","0.00931"
"12746","76.44200","6.37051","0.00946"
"12816","76.86200","6.40543","0.00916"
"12886","77.28200","6.44035","0.00896"
"12956","77.70200","6.47539","0.00972"
"13026","78.12200","6.51042","0.00941"
"13096","78.54200","6.54540","0.00950"
"13166","78.96200","6.58032","0.00993"
"13236","79.38200","6.61541","0.00928"
"13306","79.80200","6.65045","0.00941"
"13376","80.22200","6.68537","0.00949"
"13446","80.64200","6.72034","0.00950"
"13516","81.06200","6.75538","0.00937"
"13586","81.48200","6.79042","0.00951"
"13656","81.90200","6.82539","0.00950"
"13726","82.32200","6.86049","0.01007"
"13796","82.74200","6.89535","0.00992"
"13866","83.16200","6.93038","0.00936"
"13936","83.58200","6.96542","0.01012"
"14006","84.00200","7.00040","0.01002"
"14076","84.42200","7.03543","0.00930"
"14146","84.84200","7.07029","0.00959"
"14216","85.26200","7.10539","0.00906"
"14286","85.68200","7.14042","0.00977"
"14356","86.10200","7.17546","0.00914"
"14426","86.52200","7.21038","0.00828"
"14496","86.94200","7.24536","0.00883"
"14566","87.36200","7.28045","0.00795"
"14636","87.78200","7.31543","0.00896"
"14706","88.20200","7.35041","0.00907"
"14776","88.62200","7.38538","0.00910"
"14846","89.04200","7.42042","0.00886"
"14916","89.46200","7.45540","0.00824"
"14986","89.88200","7.49037","0.00892"
"15056","90.30200","7.52535","0.00909"
"15126","90.72200","7.56033","0.00871"
"15196","91.14200","7.59536","0.00851"
"15266","91.56200","7.63040","0.00874"
"15336","91.98200","7.66544","0.00923"
"15406","92.40200","7.70041","0.00931"
"15476","92.82200","7.73539","0.00877"
"15546","93.24200","7.77043","0.00843"
"15616","93.66200","7.80546","0.00875"
"15686","94.08200","7.84044","0.00899"
"15756","94.50200","7.87536","0.00920"
"15826","94.92200","7.91039","0.00946"
"15896","95.34200","7.94543","0.00929"
"15966","95.76200","7.98035","0.00908"
"16036","96.18200","8.01533","0.00912"
"16106","96.60200","8.05036","0.00917"
"16176","97.02200","8.08546","0.00978"
"16246","97.44200","8.12037","0.00951"
"16316","97.86200","8.15541","0.00938"
"16386","98.28200","8.19039","0.00962"
"16456","98.70200","8.22537","0.00983"
"16526","99.12200","8.26046","0.00961"
"16596","99.54200","8.29544","0.00969"
"16666","99.96200","8.33042","0.00969"
"16736","100.38200","8.36533","0.00955"
"16806","100.80200","8.40043","0.00980"
"16876","101.22200","8.43541","0.01018"
"16946","101.64200","8.47038","0.00961"
"17016","102.06200","8.50530","0.01020"
"17086","102.48200","8.54040","0.01042"
"17156","102.90200","8.57537","0.01025"
"17226","103.32200","8.61041","0.00966"
"17296","103.74200","8.64533","0.00991"
"17366","104.16200","8.68036","0.00976"
"17436","104.58200","8.71546","0.01023"
"17506","105.00200","8.75044","0.00924"
"17576","105.42200","8.78541","0.00997"
"17646","105.84200","8.82039","0.01068"
"17716","106.26200","8.85543","0.01016"
"17786","106.68200","8.89040","0.01057"
"17856","107.10200","8.92544","0.01008"
"17926","107.52200","8.96036","0.01019"
"17996","107.94200","8.99539","0.01048"
"18066","108.36200","9.03037","0.01037"
"18136","108.78200","9.06535","0.01047"
"18206","109.20200","9.10038","0.01040"
"18276","109.62200","9.13536","0.00930"
"18346","110.04200","9.17040","0.00963"
"18416","110.46200","9.20538","0.01036"
"18486","110.88200","9.24047","0.01000"
"18556","111.30200","9.27539","0.01031"
"18626","111.72200","9.31037","0.01047"
"18696","112.14200","9.34540","0.01063"
"18766","112.56200","9.38044","0.01012"
"18836","112.98200","9.41536","0.01049"
"18906","113.40200","9.45033","0.01019"
"18976","113.82200","9.48537","0.01031"
"19046","114.24200","9.52041","0.01020"
"19116","114.66200","9.55538","0.01019"
"19186","115.08200","9.59036","0.01005"
"19256","115.50200","9.62534","0.01072"
"19326","115.92200","9.66043","0.01044"
"19396","116.34200","9.69541","0.01048"
"19466","116.76200","9.73045","0.01020"
"19536","117.18200","9.76542","0.01101"
"19606","117.60200","9.80040","0.01032"
"19676","118.02200","9.83544","0.01076"
"19746","118.44200","9.87041","0.01072"
"19816","118.86200","9.90539","0.01085"
"19886","119.28200","9.94037","0.01058"
"19956","119.70200","9.97541","0.01041"
"20026","120.12200","10.01038","0.01132"
"20096","120.54200","10.04548","0.01107"
"20166","120.96200","10.08040","0.00979"
"20236","121.38200","10.11537","0.01019"
"20306","121.80200","10.15047","0.01014"
"20376","122.22200","10.18545","0.01126"
"20446","122.64200","10.22042","0.01096"
"20516","123.06200","10.25534","0.01078"
"20586","123.48200","10.29038","0.01109"
"20656","123.90200","10.32541","0.01036"
"20726","124.32200","10.36045","0.01117"
"20796","124.74200","10.39537","0.01141"
"20866","125.16200","10.43034","0.01162"
"20936","125.58200","10.46532","0.01116"
"21006","126.00200","10.50042","0.01139"
"21076","126.42200","10.53539","0.01100"
"21146","126.84200","10.57037","0.01160"
"21216","127.26200","10.60541","0.01156"
"21286","127.68200","10.64038","0.01143"
"21356","128.10200","10.67548","0.01174"
"21426","128.52200","10.71040","0.01206"
"21496","128.94200","10.74531","0.01161"
"21566","129.36200","10.78041","0.01182"
"21636","129.78200","10.81545","0.01161"
"21706","130.20200","10.85043","0.01191"
"21776","130.62200","10.88534","0.01118"
"21846","131.04200","10.92038","0.01240"
"21916","131.46200","10.95547","0.01244"
"21986","131.88200","10.99039","0.01227"
"22056","132.30200","11.02543","0.01225"
"22126","132.72200","11.06035","0.01177"
"22196","133.14200","11.09538","0.01249"
"22266","133.56200","11.13042","0.01228"
"22336","133.98200","11.16546","0.01264"
"22406","134.40200","11.20037","0.01294"
"22476","134.82200","11.23535","0.01239"
"22546","135.24200","11.27039","0.01255"
"22616","135.66200","11.30536","0.01354"
"22686","136.08200","11.34040","0.01324"
"22756","136.50200","11.37532","0.01244"
"22826","136.92200","11.41035","0.01241"
"22896","137.34200","11.44539","0.01253"
"22966","137.76200","11.48043","0.01248"
"23036","138.18200","11.51540","0.01285"
"23106","138.60200","11.55032","0.01214"
"23176","139.02200","11.58542","0.01308"
"23246","139.44200","11.62045","0.01314"
"23316","139.86200","11.65543","0.01300"
"23386","140.28200","11.69035","0.01300"
"23456","140.70200","11.72538","0.01347"
"23526","141.12200","11.76036","0.01347"
"23596","141.54200","11.79540","0.01350"
"23666","141.96200","11.83032","0.01386"
"23736","142.38200","11.86541","0.01411"
"23806","142.80200","11.90039","0.01399"
"23876","143.22200","11.93537","0.01421"
"23946","143.64200","11.97040","0.01437"
"24016","144.06200","12.00532","0.01467"
"24086","144.48200","12.04042","0.01453"
"24156","144.90200","12.07545","0.01521"
"24226","145.32200","12.11049","0.01548"
"24296","145.74200","12.14541","0.01530"
"24366","146.16200","12.18038","0.01545"
"24436","146.58200","12.21542","0.01563"
"24506","147.00200","12.25040","0.01585"
"24576","147.42200","12.28537","0.01619"
"24646","147.84200","12.32035","0.01608"
"24716","148.26200","12.35539","0.01641"
"24786","148.68200","12.39042","0.01648"
"24856","149.10200","12.42540","0.01659"
"24926","149.52200","12.46038","0.01641"
"24996","149.94200","12.49535","0.01655"
"25066","150.36200","12.53039","0.01613"
"25136","150.78200","12.56543","0.01693"
"25206","151.20200","12.60046","0.01608"
"25276","151.62200","12.63538","0.01690"
"25346","152.04200","12.67036","0.01661"
"25416","152.46200","12.70540","0.01709"
"25486","152.88200","12.74043","0.01683"
"25556","153.30200","12.77541","0.01691"
"25626","153.72200","12.81033","0.01672"
"25696","154.14200","12.84536","0.01715"
"25766","154.56200","12.88040","0.01687"
"25836","154.98200","12.91544","0.01676"
"25906","155.40200","12.95035","0.01707"
"25976","155.82200","12.98539","0.01683"
"26046","156.24200","13.02043","0.01178"
"26116","156.66200","13.05540","0.01281"
"26186","157.08200","13.09038","0.01211"
"26256","157.50200","13.12536","0.01228"
"26326","157.92200","13.16039","0.01188"
"26396","158.34200","13.19537","0.01260"
"26466","158.76200","13.23041","0.01246"
"26536","159.18200","13.26538","0.01302"
"26606","159.60200","13.30042","0.01244"
"26676","160.02200","13.33534","0.01282"
"26746","160.44200","13.37037","0.01354"
"26816","160.86200","13.40541","0.01355"
"26886","161.28200","13.44033","0.01398"
"26956","161.70200","13.47537","0.01422"
"27026","162.12200","13.51046","0.01397"
"27096","162.54200","13.54544","0.01416"
"27166","162.96200","13.58042","0.01477"
"27236","163.38200","13.61539","0.01482"
"27306","163.80200","13.65043","0.01539"
"27376","164.22200","13.68541","0.01559"
"27446","164.64200","13.72038","0.01569"
"27516","165.06200","13.75530","0.01618"
"27586","165.48200","13.79040","0.01584"
"27656","165.90200","13.82543","0.01635"
"27726","166.32200","13.86041","0.01615"
"27796","166.74200","13.89539","0.01674"
"27866","167.16200","13.93036","0.01695"
"27936","167.58200","13.96540","0.01735"
"28006","168.00200","14.00044","0.01731"
"28076","168.42200","14.03541","0.01786"
"28146","168.84200","14.07039","0.01764"
"28216","169.26200","14.10537","0.01792"
"28286","169.68200","14.14040","0.01810"
"28356","170.10200","14.17538","0.01829"
"28426","170.52200","14.21042","0.01905"
"28496","170.94200","14.24533","0.01857"
"28566","171.36200","14.28037","0.01843"
"28636","171.78200","14.31541","0.01848"
"28706","172.20200","14.35044","0.01887"
"28776","172.62200","14.38536","0.01914"
"28846","173.04200","14.42034","0.01949"
"28916","173.46200","14.45543","0.01960"
"28986","173.88200","14.49041","0.01937"
"29056","174.30200","14.52539","0.01896"
"29126","174.72200","14.56037","0.01264"
"29196","175.14200","14.59540","0.01124"
"29266","175.56200","14.63038","0.01004"
"29336","175.98200","14.66542","0.01065"
"29406","176.40200","14.70039","0.01125"
"29476","176.82200","14.73537","0.01061"
"29546","177.24200","14.77035","0.01074"
"29616","177.66200","14.80538","0.01125"
"29686","178.08200","14.84042","0.01027"
"29756","178.50200","14.87534","0.01105"
"29826","178.92200","14.91037","0.01162"
"29896","179.34200","14.94541","0.01133"
"29966","179.76200","14.98045","0.01154"
"30036","180.18200","15.01536","0.01215"
"30106","180.60200","15.05034","0.01202"
"30176","181.02200","15.08544","0.01157"
"30246","181.44200","15.12041","0.01219"
"30316","181.86400","15.15551","0.01182"
"30386","182.28400","15.19049","0.01210"
"30456","182.70400","15.22552","0.01154"
"30526","183.12600","15.26074","0.01195"
"30596","183.54600","15.29572","0.01259"
"30666","183.96600","15.33075","0.01192"
"30736","184.38600","15.36567","0.01231"
"30806","184.80600","15.40071","0.01200"
"30876","185.22600","15.43575","0.01236"
"30946","185.64600","15.47078","0.01284"
"31016","186.06600","15.50576","0.01266"
"31086","186.48600","15.54074","0.01317"
"31156","186.90600","15.57577","0.01302"
"31226","187.32600","15.61075","0.01266"
"31296","187.74600","15.64579","0.01285"
"31366","188.16600","15.68064","0.01302"
"31436","188.58600","15.71568","0.01305"
"31506","189.00600","15.75078","0.01303"
"31576","189.42600","15.78575","0.01300"
"31646","189.84600","15.82067","0.01240"
"31716","190.26600","15.85565","0.01297"
"31786","190.68600","15.89074","0.01355"
"31856","191.10600","15.92578","0.01372"
"31926","191.52600","15.96070","0.01329"
"31996","191.94600","15.99573","0.01370"
"32066","192.36600","16.03071","0.01359"
"32136","192.78600","16.06569","0.01402"
"32206","193.20600","16.10072","0.01400"
"32276","193.62600","16.13570","0.01411"
"32346","194.04600","16.17068","0.01374"
"32416","194.46600","16.20571","0.01467"
"32486","194.88600","16.24069","0.01434"
"32556","195.30600","16.27573","0.01422"
"32626","195.72600","16.31070","0.01468"
"32696","196.14600","16.34574","0.01448"
"32766","196.56600","16.38072","0.01467"
"32836","196.98600","16.41575","0.01483"
"32906","197.40600","16.45073","0.01463"
"32976","197.82600","16.48571","0.01503"
"33046","198.24600","16.52074","0.01458"
"33116","198.66600","16.55578","0.01518"
"33186","199.08600","16.59070","0.01532"
"33256","199.50600","16.62568","0.01516"
"33326","199.92600","16.66071","0.01554"
"33396","200.34600","16.69575","0.01521"
"33466","200.76600","16.73073","0.01533"
"33536","201.18600","16.76570","0.01573"
"33606","201.60600","16.80074","0.01570"
"33676","202.02600","16.83572","0.01586"
"33746","202.44600","16.87075","0.01571"
"33816","202.86600","16.90579","0.01579"
"33886","203.28600","16.94071","0.01599"
"33956","203.70600","16.97574","0.01634"
"34026","204.12600","17.01078","0.01585"
"34096","204.54600","17.04570","0.01644"
"34166","204.96600","17.08073","0.01675"
"34236","205.38600","17.11565","0.01687"
"34306","205.80600","17.15069","0.01674"
"34376","206.22600","17.18572","0.01677"
"34446","206.64600","17.22076","0.01685"
"34516","207.06600","17.25568","0.01727"
"34586","207.48600","17.29065","0.01691"
"34656","207.90600","17.32575","0.01700"
"34726","208.32600","17.36073","0.01763"
"34796","208.74600","17.39570","0.01733"
"34866","209.16600","17.43068","0.01719"
"34936","209.58600","17.46572","0.01692"
"35006","210.00600","17.50076","0.01682"
"35076","210.42600","17.53579","0.01735"
"35146","210.84600","17.57071","0.01679"
"35216","211.26600","17.60568","0.01712"
"35286","211.68600","17.64066","0.01728"
"35356","212.10600","17.67576","0.01756"
"35426","212.52600","17.71074","0.01791"
"35496","212.94600","17.74571","0.01795"
"35566","213.36600","17.78069","0.01793"
"35636","213.78600","17.81573","0.01770"
"35706","214.20600","17.85076","0.01826"
"35776","214.62600","17.88574","0.01843"
"35846","215.04600","17.92072","0.01883"
"35916","215.46600","17.95575","0.01893"
"35986","215.88600","17.99079","0.01889"
"36056","216.30600","18.02577","0.01866"
"36126","216.72600","18.06074","0.01824"
"36196","217.14600","18.09566","0.01814"
"36266","217.56600","18.13076","0.01851"
"36336","217.98600","18.16573","0.01859"
"36406","218.40600","18.20071","0.01875"
"36476","218.82600","18.23569","0.01915"
"36546","219.24600","18.27073","0.01957"
"36616","219.66600","18.30570","0.01952"
"36686","220.08600","18.34074","0.01947"
"36756","220.50600","18.37572","0.02040"
"36826","220.92600","18.41069","0.02033"
"36896","221.34600","18.44579","0.02004"
"36966","221.76600","18.48076","0.02059"
"37036","222.18600","18.51574","0.02082"
"37106","222.60600","18.55066","0.02115"
"37176","223.02600","18.58570","0.02157"
"37246","223.44600","18.62079","0.02156"
"37316","223.86600","18.65583","0.02161"
"37386","224.28600","18.69075","0.02193"
"37456","224.70600","18.72566","0.02135"
"37526","225.12600","18.76076","0.02016"
"37596","225.54600","18.79574","0.01956"
"37666","225.96600","18.83077","0.01889"
"37736","226.38600","18.86569","0.01907"
"37806","226.80600","18.90073","0.01948"
"37876","227.22600","18.93576","0.01926"
"37946","227.64600","18.97074","0.01992"
"38016","228.06600","19.00572","0.01992"
"38086","228.48600","19.04070","0.02071"
"38156","228.90600","19.07567","0.02045"
"38226","229.32600","19.11071","0.02049"
"38296","229.74600","19.14574","0.02119"
"38366","230.16600","19.18066","0.02138"
"38436","230.58600","19.21570","0.02216"
"38506","231.00600","19.25074","0.02071"
"38576","231.42600","19.28577","0.02060"
"38646","231.84600","19.32075","0.02135"
"38716","232.26600","19.35567","0.02134"
"38786","232.68600","19.39076","0.02183"
"38856","233.10600","19.42574","0.02176"
"38926","233.52600","19.46072","0.02190"
"38996","233.94600","19.49569","0.02283"
"39066","234.36600","19.53067","0.02249"
"39136","234.78600","19.56571","0.02228"
"39206","235.20600","19.60068","0.02320"
"39276","235.62600","19.63572","0.02364"
"39346","236.04600","19.67070","0.02380"
"39416","236.46600","19.70573","0.02394"
"39486","236.88600","19.74077","0.02460"
"39556","237.30600","19.77575","0.02433"
"39626","237.72600","19.81072","0.02388"
"39696","238.14600","19.84576","0.02284"
"39766","238.56600","19.88074","0.01978"
"39836","238.98600","19.91571","0.01964"
"39906","239.40600","19.95075","0.02048"
"39976","239.82600","19.98567","0.02027"
"40046","240.24600","20.02070","0.02104"
"40116","240.66600","20.05580","0.02090"
"40186","241.08600","20.09078","0.02110"
"40256","241.50600","20.12569","0.02082"
"40326","241.92600","20.16073","0.02144"
"40396","242.34600","20.19577","0.02106"
"40466","242.76600","20.23075","0.02213"
"40536","243.18600","20.26572","0.02311"
"40606","243.60600","20.30070","0.02311"
"40676","244.02600","20.33567","0.02211"
"40746","244.44600","20.37077","0.02334"
"40816","244.86600","20.40575","0.02338"
"40886","245.28600","20.44073","0.02404"
"40956","245.70600","20.47570","0.02071"
"41026","246.12600","20.51068","0.02163"
"41096","246.54600","20.54572","0.02095"
"41166","246.96600","20.58075","0.02150"
"41236","247.38600","20.61567","0.02170"
"41306","247.80600","20.65071","0.02157"
"41376","248.22600","20.68568","0.02150"
"41446","248.64600","20.72072","0.02214"
"41516","249.06600","20.75575","0.02195"
"41586","249.48600","20.79067","0.02303"
"41656","249.90600","20.82571","0.02309"
"41726","250.32600","20.86075","0.02331"
"41796","250.74600","20.89572","0.02409"
"41866","251.16600","20.93070","0.02412"
"41936","251.58600","20.96568","0.02449"
"42006","252.00600","21.00077","0.02478"
"42076","252.42600","21.03569","0.02494"
"42146","252.84600","21.07073","0.01945"
"42216","253.26600","21.10571","0.01892"
"42286","253.68600","21.14074","0.01735"
"42356","254.10600","21.17572","0.01687"
"42426","254.52600","21.21082","0.01745"
"42496","254.94600","21.24573","0.01675"
"42566","255.36600","21.28071","0.01760"
"42636","255.78600","21.31575","0.01886"
"42706","256.20600","21.35072","0.01832"
"42776","256.62600","21.38570","0.01905"
"42846","257.04600","21.42062","0.01941"
"42916","257.46600","21.45572","0.01985"
"42986","257.88600","21.49075","0.01964"
"43056","258.30600","21.52579","0.01988"
"43126","258.72600","21.56071","0.02029"
"43196","259.14600","21.59568","0.02006"
"43266","259.56600","21.63078","0.02037"
"43336","259.98600","21.66575","0.01950"
"43406","260.40600","21.70073","0.02004"
"43476","260.82600","21.73571","0.01802"
"43546","261.24600","21.77075","0.01725"
"43616","261.66600","21.80578","0.01742"
"43686","262.08600","21.84076","0.01751"
"43756","262.50600","21.87568","0.01826"
"43826","262.92600","21.91065","0.01854"
"43896","263.34600","21.94569","0.01864"
"43966","263.76600","21.98072","0.01923"
"44036","264.18600","22.01576","0.01923"
"44106","264.60600","22.05068","0.01966"
"44176","265.02600","22.08571","0.01976"
"44246","265.44600","22.12075","0.01979"
"44316","265.86600","22.15579","0.02027"
"44386","266.28600","22.19077","0.01972"
"44456","266.70600","22.22568","0.02027"
"44526","267.12600","22.26078","0.01971"
"44596","267.54600","22.29575","0.02030"
"44666","267.96600","22.33073","0.02029"
"44736","268.38600","22.36565","0.02063"
"44806","268.80600","22.40068","0.02074"
"44876","269.22600","22.43578","0.01933"
"44946","269.64600","22.47070","0.01966"
"45016","270.06600","22.50574","0.01970"
"45086","270.48600","22.54071","0.02055"
"45156","270.90600","22.57575","0.02090"
"45226","271.32600","22.61079","0.02062"
"45296","271.74600","22.64576","0.02129"
"45366","272.16600","22.68074","0.02170"
"45436","272.58600","22.71572","0.02199"
"45506","273.00600","22.75081","0.02250"
"45576","273.42600","22.78573","0.02227"
"45646","273.84600","22.82077","0.02306"
"45716","274.26600","22.85563","0.02301"
"45786","274.68600","22.89072","0.02320"
"45856","275.10600","22.92570","0.02335"
"45926","275.52600","22.96079","0.02165"
"45996","275.94600","22.99565","0.01598"
"46066","276.36600","23.03063","0.01692"
"46136","276.78600","23.06573","0.01671"
"46206","277.20600","23.10076","0.01704"
"46276","277.62600","23.13574","0.01752"
"46346","278.04600","23.17072","0.01730"
"46416","278.46600","23.20569","0.01779"
"46486","278.88600","23.24073","0.01786"
"46556","279.30600","23.27576","0.01845"
"46626","279.72600","23.31068","0.01869"
"46696","280.14600","23.34566","0.01884"
"46766","280.56600","23.38070","0.01884"
"46836","280.98600","23.41579","0.01897"
"46906","281.40600","23.45071","0.01954"
"46976","281.82600","23.48569","0.01923"
"47046","282.24600","23.52066","0.02030"
"47116","282.66600","23.55570","0.02044"
"47186","283.08600","23.59080","0.02029"
"47256","283.50600","23.62577","0.02048"
"47326","283.92600","23.66069","0.01959"
"47396","284.34600","23.69573","0.02012"
"47466","284.76600","23.73077","0.02016"
"47536","285.18600","23.76574","0.02000"
"47606","285.60600","23.80066","0.02046"
"47676","286.02600","23.83570","0.02056"
"47746","286.44600","23.87067","0.02066"
"47816","286.86600","23.90571","0.02022"
"47886","287.28600","23.94075","0.02080"
"47956","287.70600","23.97572","0.02052"
"48026","288.12600","24.01076","0.02096"
"48096","288.54600","24.04574","0.02137"
"48166","288.96600","24.08077","0.02123"
"48236","289.38600","24.11569","0.02143"
"48306","289.80600","24.15073","0.02149"
"48376","290.22600","24.18576","0.02150"
"48446","290.64600","24.22074","0.01664"
"48516","291.06600","24.25578","0.01397"
"48586","291.48600","24.29063","0.01502"
"48656","291.90600","24.32567","0.01405"
"48726","292.32600","24.36077","0.01463"
"48796","292.74600","24.39574","0.01493"
"48866","293.16600","24.43066","0.01471"
"48936","293.58600","24.46570","0.01515"
"49006","294.00600","24.50073","0.01593"
"49076","294.42600","24.53577","0.01550"
"49146","294.84600","24.57075","0.01577"
"49216","295.26600","24.60572","0.01627"
"49286","295.68600","24.64076","0.01612"
"49356","296.10600","24.67574","0.01583"
"49426","296.52600","24.71077","0.01688"
"49496","296.94600","24.74569","0.01580"
"49566","297.36600","24.78073","0.01583"
"49636","297.78600","24.81570","0.01639"
"49706","298.20600","24.85074","0.01634"
"49776","298.62600","24.88572","0.01645"
"49846","299.04600","24.92069","0.01648"
"49916","299.46600","24.95567","0.01674"
"49986","299.88600","24.99071","0.01681"
"50056","300.30600","25.02575","0.01661"
"50126","300.72600","25.06072","0.01697"
"50196","301.14600","25.09570","0.01693"
"50266","301.56600","25.13074","0.01737"
"50336","301.98600","25.16571","0.01723"
"50406","302.40600","25.20075","0.01747"
"50476","302.82600","25.23567","0.01779"
"50546","303.24600","25.27070","0.01766"
"50616","303.66600","25.30574","0.01826"
"50686","304.08600","25.34072","0.01870"
"50756","304.50600","25.37576","0.01823"
"50826","304.92600","25.41067","0.01856"
"50896","305.34600","25.44571","0.01878"
"50966","305.76600","25.48074","0.01850"
"51036","306.18600","25.51584","0.01925"
"51106","306.60600","25.55070","0.01955"
"51176","307.02600","25.58568","0.01953"
"51246","307.44600","25.62077","0.01911"
"51316","307.86600","25.65575","0.01942"
"51386","308.28600","25.69078","0.01945"
"51456","308.70600","25.72564","0.01965"
"51526","309.12600","25.76074","0.02042"
"51596","309.54600","25.79577","0.01474"
"51666","309.96600","25.83075","0.01540"
"51736","310.38600","25.86573","0.01517"
"51806","310.80600","25.90071","0.01544"
"51876","311.22600","25.93574","0.01644"
"51946","311.64600","25.97078","0.01618"
"52016","312.06600","26.00570","0.01619"
"52086","312.48600","26.04073","0.01625"
"52156","312.90600","26.07571","0.01635"
"52226","313.32600","26.11075","0.01641"
"52296","313.74600","26.14573","0.01684"
"52366","314.16600","26.18070","0.01695"
"52436","314.58600","26.21568","0.01663"
"52506","315.00600","26.25065","0.01756"
"52576","315.42600","26.28575","0.01750"
"52646","315.84600","26.32073","0.01799"
"52716","316.26600","26.35565","0.01774"
"52786","316.68600","26.39074","0.01763"
"52856","317.10600","26.42572","0.01728"
"52926","317.52600","26.46076","0.01741"
"52996","317.94600","26.49573","0.01751"
"53066","318.36600","26.53065","0.01759"
"53136","318.78600","26.56574","0.01741"
"53206","319.20600","26.60072","0.01751"
"53276","319.62600","26.63576","0.01739"
"53346","320.04600","26.67068","0.01827"
"53416","320.46600","26.70565","0.01737"
"53486","320.88600","26.74075","0.01796"
"53556","321.30600","26.77573","0.01788"
"53626","321.72600","26.81070","0.01866"
"53696","322.14600","26.84568","0.01851"
"53766","322.56600","26.88072","0.01880"
"53836","322.98600","26.91575","0.01874"
"53906","323.40600","26.95079","0.01878"
"53976","323.82600","26.98577","0.01920"
"54046","324.24600","27.02074","0.01941"
"54116","324.66600","27.05572","0.01866"
"54186","325.08600","27.09076","0.01883"
"54256","325.50600","27.12580","0.01823"
"54326","325.92600","27.16065","0.01883"
"54396","326.34600","27.19575","0.01860"
"54466","326.76600","27.23073","0.01875"
"54536","327.18600","27.26576","0.01902"
"54606","327.60600","27.30062","0.01881"
"54676","328.02600","27.33571","0.01788"
"54746","328.44600","27.37075","0.01844"
"54816","328.86600","27.40573","0.01838"
"54886","329.28600","27.44077","0.01716"
"54956","329.70600","27.47568","0.01804"
"55026","330.12600","27.51072","0.01790"
"55096","330.54600","27.54576","0.01777"
"55166","330.96600","27.58079","0.01817"
"55236","331.38600","27.61571","0.01867"
"55306","331.80600","27.65069","0.01789"
"55376","332.22600","27.68572","0.01913"
"55446","332.64600","27.72076","0.01870"
"55516","333.06600","27.75568","0.01891"
"55586","333.48600","27.79071","0.01796"
"55656","333.90600","27.82569","0.01827"
"55726","334.32600","27.86073","0.01828"
"55796","334.74600","27.89577","0.01805"
"55866","335.16600","27.93074","0.01790"
"55936","335.58600","27.96572","0.01729"
"56006","336.00600","28.00075","0.01814"
"56076","336.42600","28.03573","0.01824"
"56146","336.84600","28.07071","0.01846"
"56216","337.26600","28.10569","0.01668"
"56286","337.68600","28.14072","0.01752"
"56356","338.10600","28.17576","0.01683"
"56426","338.52600","28.21067","0.01770"
"56496","338.94600","28.24571","0.01803"
"56566","339.36600","28.28069","0.01807"
"56636","339.78600","28.31578","0.01376"
"56706","340.20600","28.35076","0.01275"
"56776","340.62600","28.38580","0.01283"
"56846","341.04600","28.42072","0.01181"
"56916","341.46600","28.45569","0.01207"
"56986","341.88600","28.49073","0.01343"
"57056","342.30600","28.52571","0.01298"
"57126","342.72600","28.56074","0.01285"
"57196","343.14600","28.59566","0.01345"
"57266","343.56600","28.63070","0.01364"
"57336","343.98600","28.66574","0.01292"
"57406","344.40600","28.70077","0.01337"
"57476","344.82600","28.73569","0.01376"
"57546","345.24600","28.77073","0.01354"
"57616","345.66600","28.80576","0.01300"
"57686","346.08600","28.84068","0.01417"
"57756","346.50600","28.87578","0.01438"
"57826","346.92600","28.91075","0.01424"
"57896","347.34600","28.94573","0.01448"
"57966","347.76600","28.98077","0.01442"
"58036","348.18600","29.01574","0.01451"
"58106","348.60600","29.05072","0.01462"
"58176","349.02600","29.08575","0.01419"
"58246","349.44600","29.12073","0.01482"
"58316","349.86600","29.15571","0.01430"
"58386","350.28600","29.19074","0.01437"
"58456","350.70600","29.22572","0.01475"
"58526","351.12600","29.26070","0.01482"
"58596","351.54600","29.29574","0.01490"
"58666","351.96600","29.33077","0.01495"
"58736","352.38600","29.36575","0.01477"
"58806","352.80600","29.40067","0.01485"
"58876","353.22600","29.43570","0.01517"
"58946","353.64600","29.47074","0.01536"
"59016","354.06600","29.50572","0.01488"
"59086","354.48600","29.54070","0.01558"
"59156","354.90600","29.57567","0.01519"
"59226","355.32600","29.61071","0.01579"
"59296","355.74600","29.64568","0.01539"
"59366","356.16600","29.68072","0.01566"
"59436","356.58600","29.71564","0.01576"
"59506","357.00600","29.75073","0.01629"
"59576","357.42600","29.78577","0.01595"
"59646","357.84600","29.82081","0.01658"
"59716","358.26600","29.85572","0.01625"
"59786","358.68600","29.89070","0.01627"
"59856","359.10600","29.92574","0.01611"
"59926","359.52600","29.96078","0.01645"
"59996","359.94600","29.99575","0.01684"
"60066","360.36600","30.03067","0.01639"
"60136","360.78600","30.06570","0.01620"
"60206","361.20600","30.10074","0.01628"
"60276","361.62600","30.13578","0.01632"
"60346","362.04600","30.17070","0.01630"
"60416","362.46600","30.20568","0.01674"
"60486","362.88600","30.24071","0.01725"
"60556","363.30600","30.27575","0.01722"
"60626","363.72600","30.31072","0.01730"
"60696","364.14600","30.34570","0.01738"
"60766","364.56600","30.38074","0.01735"
"60836","364.98600","30.41578","0.01764"
"60906","365.40600","30.45075","0.01765"
"60976","365.82600","30.48573","0.01742"
"61046","366.24600","30.52071","0.01796"
"61116","366.66600","30.55568","0.01805"
"61186","367.08600","30.59072","0.01763"
"61256","367.50600","30.62575","0.01818"
"61326","367.92600","30.66067","0.01823"
"61396","368.34600","30.69565","0.01818"
"61466","368.76600","30.73074","0.01872"
"61536","369.18600","30.76578","0.01870"
"61606","369.60600","30.80076","0.01861"
"61676","370.02600","30.83568","0.01858"
"61746","370.44600","30.87077","0.01827"
"61816","370.86600","30.90575","0.01881"
"61886","371.28600","30.94073","0.01890"
"61956","371.70600","30.97564","0.01853"
"62026","372.12600","31.01068","0.01800"
"62096","372.54600","31.04578","0.01804"
"62166","372.96600","31.08069","0.01883"
"62236","373.38600","31.11573","0.01888"
"62306","373.80600","31.15071","0.01869"
"62376","374.22600","31.18575","0.01877"
"62446","374.64600","31.22078","0.01876"
"62516","375.06600","31.25582","0.01899"
"62586","375.48600","31.29073","0.01913"
"62656","375.90600","31.32571","0.01887"
"62726","376.32600","31.36074","0.01943"
"62796","376.74600","31.39572","0.01917"
"62866","377.16600","31.43076","0.01919"
"62936","377.58600","31.46568","0.01936"
"63006","378.00600","31.50071","0.01943"
"63076","378.42600","31.53569","0.01943"
"63146","378.84600","31.57072","0.01920"
"63216","379.26600","31.60570","0.01942"
"63286","379.68600","31.64068","0.01977"
"63356","380.10600","31.67578","0.01990"
"63426","380.52600","31.71075","0.01989"
"63496","380.94600","31.74573","0.01977"
"63566","381.36600","31.78071","0.02019"
"63636","381.78600","31.81569","0.02018"
"63706","382.20600","31.85078","0.02052"
"63776","382.62600","31.88576","0.02029"
"63846","383.04600","31.92073","0.02049"
"63916","383.46600","31.95571","0.02080"
"63986","383.88600","31.99069","0.02048"
"64056","384.30600","32.02567","0.02078"
"64126","384.72600","32.06070","0.01989"
"64196","385.14600","32.09574","0.02024"
"64266","385.56600","32.13071","0.01994"
"64336","385.98600","32.16575","0.01958"
"64406","386.40600","32.20073","0.01951"
"64476","386.82600","32.23570","0.01974"
"64546","387.24600","32.27068","0.01991"
"64616","387.66600","32.30578","0.02009"
"64686","388.08600","32.34082","0.02035"
"64756","388.50600","32.37573","0.01952"
"64826","388.92600","32.41071","0.01866"
"64896","389.34600","32.44569","0.01779"
"64966","389.76600","32.48079","0.01841"
"65036","390.18600","32.51570","0.01871"
"65106","390.60600","32.55074","0.01806"
"65176","391.02600","32.58566","0.01873"
"65246","391.44600","32.62069","0.01821"
"65316","391.86600","32.65573","0.01900"
"65386","392.28600","32.69077","0.01844"
"65456","392.70600","32.72574","0.01847"
"65526","393.12600","32.76072","0.01849"
"65596","393.54600","32.79575","0.01882"
"65666","393.96600","32.83073","0.01877"
"65736","394.38600","32.86576","0.01867"
"65806","394.80600","32.90062","0.01930"
"65876","395.22600","32.93572","0.01927"
"65946","395.64600","32.97076","0.01933"
"66016","396.06600","33.00574","0.01840"
"66086","396.48600","33.04071","0.01833"
"66156","396.90600","33.07569","0.01841"
"66226","397.32600","33.11073","0.01860"
"66296","397.74600","33.14576","0.01848"
"66366","398.16600","33.18068","0.01883"
"66436","398.58600","33.21566","0.01864"
"66506","399.00600","33.25075","0.01924"
"66576","399.42600","33.28573","0.01883"
"66646","399.84600","33.32077","0.01951"
"66716","400.26600","33.35574","0.01928"
"66786","400.68600","33.39072","0.01855"
"66856","401.10600","33.42570","0.01886"
"66926","401.52600","33.46073","0.01917"
"66996","401.94600","33.49577","0.01918"
"67066","402.36600","33.53069","0.01900"
"67136","402.78600","33.56572","0.01938"
"67206","403.20600","33.60076","0.01919"
"67276","403.62600","33.63574","0.01983"
"67346","404.04600","33.67078","0.01959"
"67416","404.46600","33.70569","0.01931"
"67486","404.88600","33.74079","0.01935"
"67556","405.30600","33.77576","0.01911"
"67626","405.72600","33.81074","0.01969"
"67696","406.14600","33.84572","0.01973"
"67766","406.56600","33.88070","0.01967"
"67836","406.98600","33.91573","0.01958"
"67906","407.40600","33.95071","0.01976"
"67976","407.82600","33.98569","0.01970"
"68046","408.24600","34.02072","0.02059"
"68116","408.66600","34.05570","0.01979"
"68186","409.08600","34.09079","0.02037"
"68256","409.50600","34.12577","0.02049"
"68326","409.92600","34.16069","0.02103"
"68396","410.34600","34.19572","0.02063"
"68466","410.76600","34.23076","0.02126"
"68536","411.18600","34.26574","0.02038"
"68606","411.60600","34.30078","0.02111"
"68676","412.02600","34.33564","0.02087"
"68746","412.44600","34.37073","0.02121"
"68816","412.86600","34.40577","0.02134"
"68886","413.28600","34.44075","0.02148"
"68956","413.70600","34.47572","0.02158"
"69026","414.12600","34.51070","0.02192"
"69096","414.54600","34.54573","0.02174"
"69166","414.96600","34.58077","0.02170"
"69236","415.38600","34.61575","0.02176"
"69306","415.80600","34.65067","0.02223"
"69376","416.22600","34.68576","0.02209"
"69446","416.64600","34.72074","0.02217"
"69516","417.06600","34.75571","0.02155"
"69586","417.48600","34.79069","0.02214"
"69656","417.90600","34.82573","0.02153"
"69726","418.32600","34.86070","0.02237"
"69796","418.74600","34.89574","0.02176"
"69866","419.16600","34.93072","0.02093"
"69936","419.58600","34.96570","0.01869"
"70006","420.00600","35.00068","0.01730"
"70076","420.42600","35.03577","0.01721"
"70146","420.84600","35.07081","0.01712"
"70216","421.26600","35.10579","0.01797"
"70286","421.68600","35.14070","0.01825"
"70356","422.10600","35.17574","0.01830"
"70426","422.52600","35.21071","0.01804"
"70496","422.94600","35.24575","0.01836"
"70566","423.36600","35.28067","0.01804"
"70636","423.78600","35.31570","0.01818"
"70706","424.20600","35.35074","0.01788"
"70776","424.62600","35.38572","0.01829"
"70846","425.04600","35.42075","0.01831"
"70916","425.46600","35.45573","0.01844"
"70986","425.88600","35.49076","0.01838"
"71056","426.30600","35.52574","0.01863"
"71126","426.72600","35.56078","0.01840"
"71196","427.14600","35.59570","0.01911"
"71266","427.56600","35.63074","0.01882"
"71336","427.98600","35.66571","0.01929"
"71406","428.40600","35.70075","0.01847"
"71476","428.82600","35.73573","0.01881"
"71546","429.24600","35.77065","0.01915"
"71616","429.66600","35.80568","0.01905"
"71686","430.08600","35.84077","0.01921"
"71756","430.50600","35.87575","0.01960"
"71826","430.92600","35.91073","0.01904"
"71896","431.34600","35.94571","0.01929"
"71966","431.76600","35.98074","0.01941"
"72036","432.18600","36.01578","0.01987"
"72106","432.60600","36.05075","0.01958"
"72176","433.02600","36.08567","0.01994"
"72246","433.44600","36.12071","0.01950"
"72316","433.86600","36.15575","0.01962"
"72386","434.28600","36.19072","0.01966"
"72456","434.70600","36.22570","0.02001"
"72526","435.12600","36.26068","0.01997"
"72596","435.54600","36.29565","0.01982"
"72666","435.96600","36.33075","0.02053"
"72736","436.38600","36.36573","0.02024"
"72806","436.80600","36.40071","0.02097"
"72876","437.22600","36.43568","0.01977"
"72946","437.64600","36.47072","0.02004"
"73016","438.06600","36.50576","0.02066"
"73086","438.48600","36.54073","0.02027"
"73156","438.90600","36.57565","0.02058"
"73226","439.32600","36.61074","0.02109"
"73296","439.74600","36.64578","0.02103"
"73366","440.16600","36.68070","0.02070"
"73436","440.58600","36.71568","0.02047"
"73506","441.00600","36.75065","0.01979"
"73576","441.42600","36.78575","0.01984"
"73646","441.84600","36.82072","0.01987"
"73716","442.26600","36.85570","0.02052"
"73786","442.68600","36.89068","0.02066"
"73856","443.10600","36.92572","0.02076"
"73926","443.52600","36.96075","0.02034"
"73996","443.94600","36.99579","0.02056"
"74066","444.36600","37.03077","0.02044"
"74136","444.78600","37.06574","0.02098"
"74206","445.20600","37.10078","0.02075"
"74276","445.62600","37.13576","0.02123"
"74346","446.04600","37.17073","0.02109"
"74416","446.46600","37.20565","0.02097"
"74486","446.88600","37.24069","0.02137"
"74556","447.30600","37.27578","0.02166"
"74626","447.72600","37.31076","0.02118"
"74696","448.14600","37.34568","0.02203"
"74766","448.56600","37.38065","0.02130"
"74836","448.98600","37.41575","0.02151"
"74906","449.40600","37.45079","0.02127"
"74976","449.82600","37.48570","0.02090"
"75046","450.24600","37.52068","0.02049"
"75116","450.66600","37.55572","0.02047"
"75186","451.08600","37.59076","0.01994"
"75256","451.50600","37.62573","0.01589"
"75326","451.92600","37.66071","0.01457"
"75396","452.34600","37.69569","0.01421"
"75466","452.76600","37.73072","0.01434"
"75536","453.18600","37.76570","0.01614"
"75606","453.60600","37.80074","0.01553"
"75676","454.02600","37.83571","0.01510"
"75746","454.44600","37.87069","0.01516"
"75816","454.86600","37.90573","0.01532"
"75886","455.28600","37.94076","0.01563"
"75956","455.70600","37.97574","0.01542"
"76026","456.12600","38.01066","0.01575"
"76096","456.54600","38.04575","0.01578"
"76166","456.96600","38.08079","0.01578"
"76236","457.38600","38.11571","0.01669"
"76306","457.80600","38.15068","0.01638"
"76376","458.22600","38.18567","0.01646"
"76446","458.64600","38.22070","0.01618"
"76516","459.06600","38.25574","0.01622"
"76586","459.48600","38.29077","0.01676"
"76656","459.90600","38.32569","0.01681"
"76726","460.32600","38.36073","0.01671"
"76796","460.74600","38.39576","0.01656"
"76866","461.16600","38.43080","0.01667"
"76936","461.58600","38.46572","0.01707"
"77006","462.00600","38.50069","0.01654"
"77076","462.42600","38.53579","0.01711"
"77146","462.84600","38.57071","0.01675"
"77216","463.26600","38.60574","0.01681"
"77286","463.68600","38.64066","0.01714"
"77356","464.10600","38.67570","0.01712"
"77426","464.52600","38.71067","0.01727"
"77496","464.94600","38.74577","0.01773"
"77566","465.36600","38.78062","0.01746"
"77636","465.78600","38.81567","0.01743"
"77706","466.20600","38.85076","0.01735"
"77776","466.62600","38.88574","0.01757"
"77846","467.04600","38.92072","0.01688"
"77916","467.46600","38.95569","0.01713"
"77986","467.88600","38.99073","0.01710"
"78056","468.30600","39.02576","0.01725"
"78126","468.72600","39.06080","0.01770"
"78196","469.14600","39.09566","0.01737"
"78266","469.56600","39.13070","0.01762"
"78336","469.98600","39.16567","0.01729"
"78406","470.40600","39.20077","0.01738"
"78476","470.82600","39.23574","0.01794"
"78546","471.24600","39.27072","0.01768"
"78616","471.66600","39.30569","0.01741"
"78686","472.08600","39.34074","0.01838"
"78756","472.50600","39.37577","0.01757"
"78826","472.92600","39.41075","0.01586"
"78896","473.34600","39.44566","0.01504"
"78966","473.76600","39.48071","0.01432"
"79036","474.18600","39.51580","0.01448"
"79106","474.60600","39.55072","0.01474"
"79176","475.02600","39.58569","0.01486"
"79246","475.44600","39.62067","0.01475"
"79316","475.86600","39.65571","0.01488"
"79386","476.28600","39.69068","0.01540"
"79456","476.70600","39.72572","0.01517"
"79526","477.12600","39.76070","0.01483"
"79596","477.54600","39.79567","0.01528"
"79666","477.96600","39.83071","0.01517"
"79736","478.38600","39.86575","0.01534"
"79806","478.80600","39.90072","0.01523"
"79876","479.22600","39.93576","0.01597"
"79946","479.64600","39.97079","0.01553"
"80016","480.06600","40.00577","0.01522"
"80086","480.48600","40.04074","0.01576"
"80156","480.90600","40.07567","0.01492"
"80226","481.32600","40.11071","0.01458"
"80296","481.74600","40.14574","0.01545"
"80366","482.16600","40.18084","0.01565"
"80436","482.58600","40.21576","0.01482"
"80506","483.00600","40.25068","0.01499"
"80576","483.42600","40.28571","0.01552"
"80646","483.84600","40.32075","0.01541"
"80716","484.26600","40.35572","0.01490"
"80786","484.68600","40.39075","0.01532"
"80856","485.10600","40.42574","0.01541"
"80926","485.52600","40.46077","0.01561"
"80996","485.94600","40.49575","0.01582"
"81066","486.36600","40.53067","0.01561"
"81136","486.78600","40.56564","0.01587"
"81206","487.20600","40.60068","0.01612"
"81276","487.62600","40.63571","0.01607"
"81346","488.04600","40.67081","0.01590"
"81416","488.46600","40.70567","0.01590"
"81486","488.88600","40.74071","0.01634"
"81556","489.30600","40.77575","0.01629"
"81626","489.72600","40.81078","0.01622"
"81696","490.14600","40.84576","0.01607"
"81766","490.56600","40.88067","0.01618"
"81836","490.98600","40.91577","0.01587"
"81906","491.40600","40.95074","0.01647"
"81976","491.82600","40.98572","0.01532"
"82046","492.24600","41.02070","0.01578"
"82116","492.66600","41.05568","0.01565"
"82186","493.08600","41.09072","0.01588"
"82256","493.50600","41.12569","0.01592"
"82326","493.92600","41.16073","0.01566"
"82396","494.34600","41.19564","0.01516"
"82466","494.76600","41.23074","0.01549"
"82536","495.18600","41.26578","0.01587"
"82606","495.60600","41.30075","0.01540"
"82676","496.02600","41.33573","0.01576"
"82746","496.44600","41.37071","0.01592"
"82816","496.86600","41.40575","0.01589"
"82886","497.28600","41.44078","0.01575"
"82956","497.70600","41.47582","0.01578"
"83026","498.12600","41.51062","0.01623"
"83096","498.54600","41.54571","0.01640"
"83166","498.96600","41.58075","0.01513"
"83236","499.38600","41.61578","0.01517"
"83306","499.80600","41.65070","0.01406"
"83376","500.22600","41.68574","0.01400"
"83446","500.64600","41.72078","0.01438"
"83516","501.06600","41.75576","0.01492"
"83586","501.48600","41.79073","0.01431"
"83656","501.90600","41.82570","0.01493"
"83726","502.32600","41.86074","0.01421"
"83796","502.74600","41.89572","0.01498"
"83866","503.16600","41.93076","0.01449"
"83936","503.58600","41.96568","0.01494"
"84006","504.00600","42.00065","0.01488"
"84076","504.42600","42.03569","0.01516"
"84146","504.84600","42.07073","0.01508"
"84216","505.26600","42.10571","0.01527"
"84286","505.68600","42.14068","0.01511"
"84356","506.10600","42.17572","0.01527"
"84426","506.52600","42.21075","0.01468"
"84496","506.94600","42.24573","0.01623"
"84566","507.36600","42.28076","0.01511"
"84636","507.78600","42.31569","0.01580"
"84706","508.20600","42.35072","0.01568"
"84776","508.62600","42.38570","0.01526"
"84846","509.04600","42.42073","0.01508"
"84916","509.46600","42.45571","0.01552"
"84986","509.88600","42.49068","0.01547"
"85056","510.30600","42.52578","0.01487"
"85126","510.72600","42.56070","0.01494"
"85196","511.14600","42.59574","0.01535"
"85266","511.56600","42.63065","0.01506"
"85336","511.98600","42.66570","0.01555"
"85406","512.40600","42.70073","0.01497"
"85476","512.82600","42.73582","0.01550"
"85546","513.24600","42.77068","0.01547"
"85616","513.66600","42.80572","0.01568"
"85686","514.08600","42.84076","0.01571"
"85756","514.50600","42.87573","0.01589"
"85826","514.92600","42.91077","0.01564"
"85896","515.34600","42.94563","0.01582"
"85966","515.76600","42.98072","0.01554"
"85992","515.92000","42.99352","0.01598"