File: Trajectories_together/170121_1Specimen_RawData_8.csv
"","V1","V2","V3"
"1","End date","1/21/2017",""
"2","Specimen label","19CG_NoLabel2",""
"3","Maximum Load","0.01001","N"
"4","Time","Extension","Load"
"5","(s)","(mm)","(N)"
"6","0.00000","0.00000","-0.00028"
"64","0.34800","0.02894","0.00004"
"122","0.69600","0.05824","-0.00007"
"180","1.04400","0.08723","0.00043"
"238","1.39200","0.11617","0.00012"
"296","1.74000","0.14517","0.00055"
"354","2.08800","0.17423","0.00066"
"412","2.43600","0.20316","0.00080"
"470","2.78400","0.23216","0.00095"
"528","3.13200","0.26116","0.00112"
"586","3.48000","0.29010","0.00084"
"644","3.82800","0.31922","0.00107"
"702","4.17600","0.34815","0.00115"
"760","4.52400","0.37715","0.00105"
"818","4.87200","0.40621","0.00093"
"876","5.22000","0.43509","0.00102"
"934","5.56800","0.46421","0.00101"
"992","5.91600","0.49320","0.00088"
"1050","6.26400","0.52214","0.00099"
"1108","6.61200","0.55120","0.00117"
"1166","6.96000","0.58014","0.00102"
"1224","7.30800","0.60914","0.00109"
"1282","7.65600","0.63819","0.00135"
"1340","8.00400","0.66719","0.00112"
"1398","8.35200","0.69613","0.00099"
"1456","8.70000","0.72519","0.00090"
"1514","9.04800","0.75419","0.00129"
"1572","9.39600","0.78318","0.00099"
"1630","9.74400","0.81224","0.00066"
"1688","10.09200","0.84112","0.00071"
"1746","10.44000","0.87018","0.00049"
"1804","10.78800","0.89923","0.00074"
"1862","11.13600","0.92817","0.00066"
"1920","11.48400","0.95717","0.00063"
"1978","11.83200","0.98617","0.00093"
"2036","12.18000","1.01511","0.00088"
"2094","12.52800","1.04416","0.00066"
"2152","12.87600","1.07322","0.00097"
"2210","13.22400","1.10210","0.00055"
"2268","13.57200","1.13116","0.00074"
"2326","13.92000","1.16022","0.00110"
"2384","14.26800","1.18915","0.00097"
"2442","14.61600","1.21821","0.00127"
"2500","14.96400","1.24715","0.00064"
"2558","15.31200","1.27609","0.00077"
"2616","15.66000","1.30521","0.00118"
"2674","16.00800","1.33414","0.00103"
"2732","16.35600","1.36320","0.00100"
"2790","16.70400","1.39214","0.00088"
"2848","17.05200","1.42120","0.00111"
"2906","17.40000","1.45020","0.00065"
"2964","17.74800","1.47919","0.00112"
"3022","18.09600","1.50813","0.00090"
"3080","18.44400","1.53719","0.00088"
"3138","18.79200","1.56625","0.00108"
"3196","19.14000","1.59513","0.00077"
"3254","19.48800","1.62418","0.00106"
"3312","19.83600","1.65318","0.00108"
"3370","20.18400","1.68212","0.00123"
"3428","20.53200","1.71124","0.00126"
"3486","20.88000","1.74017","0.00163"
"3544","21.22800","1.76911","0.00118"
"3602","21.57600","1.79817","0.00128"
"3660","21.92400","1.82723","0.00137"
"3718","22.27200","1.85617","0.00177"
"3776","22.62000","1.88516","0.00160"
"3834","22.96800","1.91416","0.00127"
"3892","23.31600","1.94316","0.00123"
"3950","23.66400","1.97216","0.00099"
"4008","24.01200","2.00116","0.00130"
"4066","24.36000","2.03021","0.00168"
"4124","24.70800","2.05915","0.00160"
"4182","25.05600","2.08815","0.00156"
"4240","25.40400","2.11721","0.00145"
"4298","25.75200","2.14621","0.00146"
"4356","26.10000","2.17514","0.00125"
"4414","26.44800","2.20420","0.00140"
"4472","26.79600","2.23320","0.00130"
"4530","27.14400","2.26214","0.00165"
"4588","27.49200","2.29119","0.00167"
"4646","27.84000","2.32013","0.00182"
"4704","28.18800","2.34907","0.00152"
"4762","28.53600","2.37819","0.00173"
"4820","28.88400","2.40713","0.00174"
"4878","29.23200","2.43624","0.00179"
"4936","29.58000","2.46524","0.00138"
"4994","29.92800","2.49412","0.00153"
"5052","30.27600","2.52318","0.00167"
"5110","30.62400","2.55218","0.00159"
"5168","30.97200","2.58111","0.00181"
"5226","31.32000","2.61017","0.00146"
"5284","31.66800","2.63917","0.00179"
"5342","32.01600","2.66817","0.00116"
"5400","32.36400","2.69723","0.00155"
"5458","32.71200","2.72616","0.00143"
"5516","33.06000","2.75516","0.00126"
"5574","33.40800","2.78422","0.00131"
"5632","33.75600","2.81316","0.00110"
"5690","34.10400","2.84216","0.00115"
"5748","34.45200","2.87115","0.00171"
"5806","34.80000","2.90015","0.00107"
"5864","35.14800","2.92921","0.00138"
"5922","35.49600","2.95815","0.00109"
"5980","35.84400","2.98714","0.00117"
"6038","36.19200","3.01620","0.00119"
"6096","36.54000","3.04520","0.00140"
"6154","36.88800","3.07414","0.00130"
"6212","37.23600","3.10320","0.00157"
"6270","37.58400","3.13219","0.00114"
"6328","37.93200","3.16113","0.00096"
"6386","38.28000","3.19019","0.00166"
"6444","38.62800","3.21919","0.00122"
"6502","38.97600","3.24813","0.00151"
"6560","39.32400","3.27718","0.00151"
"6618","39.67200","3.30612","0.00162"
"6676","40.02000","3.33518","0.00150"
"6734","40.36800","3.36424","0.00198"
"6792","40.71600","3.39312","0.00129"
"6850","41.06400","3.42211","0.00170"
"6908","41.41200","3.45117","0.00128"
"6966","41.76000","3.48017","0.00164"
"7024","42.10800","3.50917","0.00166"
"7082","42.45600","3.53822","0.00146"
"7140","42.80400","3.56716","0.00142"
"7198","43.15200","3.59622","0.00188"
"7256","43.50000","3.62516","0.00198"
"7314","43.84800","3.65416","0.00192"
"7372","44.19600","3.68321","0.00157"
"7430","44.54400","3.71215","0.00171"
"7488","44.89200","3.74115","0.00189"
"7546","45.24000","3.77015","0.00154"
"7604","45.58800","3.79915","0.00177"
"7662","45.93600","3.82814","0.00179"
"7720","46.28400","3.85714","0.00194"
"7778","46.63200","3.88620","0.00208"
"7836","46.98000","3.91514","0.00196"
"7894","47.32800","3.94426","0.00172"
"7952","47.67600","3.97307","0.00153"
"8010","48.02400","4.00219","0.00211"
"8068","48.37200","4.03119","0.00187"
"8126","48.72000","4.06013","0.00171"
"8184","49.06800","4.08925","0.00219"
"8242","49.41600","4.11812","0.00196"
"8300","49.76400","4.14712","0.00196"
"8358","50.11200","4.17618","0.00188"
"8416","50.46000","4.20518","0.00242"
"8474","50.80800","4.23418","0.00187"
"8532","51.15600","4.26317","0.00212"
"8590","51.50400","4.29217","0.00176"
"8648","51.85200","4.32117","0.00238"
"8706","52.20000","4.35017","0.00225"
"8764","52.54800","4.37916","0.00244"
"8822","52.89600","4.40816","0.00221"
"8880","53.24400","4.43722","0.00236"
"8938","53.59200","4.46610","0.00216"
"8996","53.94000","4.49516","0.00217"
"9054","54.28800","4.52415","0.00199"
"9112","54.63600","4.55315","0.00280"
"9170","54.98400","4.58215","0.00255"
"9228","55.33200","4.61121","0.00228"
"9286","55.68000","4.64015","0.00276"
"9344","56.02800","4.66920","0.00205"
"9402","56.37600","4.69820","0.00214"
"9460","56.72400","4.72714","0.00254"
"9518","57.07200","4.75620","0.00233"
"9576","57.42000","4.78514","0.00285"
"9634","57.76800","4.81419","0.00266"
"9692","58.11600","4.84319","0.00216"
"9750","58.46400","4.87207","0.00240"
"9808","58.81200","4.90125","0.00228"
"9866","59.16000","4.93018","0.00248"
"9924","59.50800","4.95912","0.00240"
"9982","59.85600","4.98824","0.00225"
"10040","60.20400","5.01718","0.00284"
"10098","60.55200","5.04618","0.00263"
"10156","60.90000","5.07517","0.00272"
"10214","61.24800","5.10417","0.00252"
"10272","61.59600","5.13317","0.00248"
"10330","61.94400","5.16217","0.00261"
"10388","62.29200","5.19117","0.00288"
"10446","62.64000","5.22010","0.00270"
"10504","62.98800","5.24922","0.00245"
"10562","63.33600","5.27816","0.00255"
"10620","63.68400","5.30716","0.00284"
"10678","64.03200","5.33616","0.00244"
"10736","64.38000","5.36509","0.00287"
"10794","64.72800","5.39421","0.00253"
"10852","65.07600","5.42321","0.00270"
"10910","65.42400","5.45215","0.00292"
"10968","65.77200","5.48115","0.00264"
"11026","66.12000","5.51020","0.00273"
"11084","66.46800","5.53908","0.00289"
"11142","66.81600","5.56820","0.00261"
"11200","67.16400","5.59720","0.00259"
"11258","67.51200","5.62614","0.00244"
"11316","67.86000","5.65525","0.00300"
"11374","68.20800","5.68413","0.00268"
"11432","68.55600","5.71319","0.00286"
"11490","68.90400","5.74219","0.00258"
"11548","69.25200","5.77112","0.00276"
"11606","69.60000","5.80018","0.00250"
"11664","69.94800","5.82918","0.00318"
"11722","70.29600","5.85818","0.00263"
"11780","70.64400","5.88712","0.00246"
"11838","70.99200","5.91617","0.00243"
"11896","71.34000","5.94511","0.00285"
"11954","71.68800","5.97417","0.00302"
"12012","72.03600","6.00323","0.00278"
"12070","72.38400","6.03211","0.00281"
"12128","72.73200","6.06116","0.00293"
"12186","73.08000","6.09016","0.00298"
"12244","73.42800","6.11916","0.00241"
"12302","73.77600","6.14822","0.00280"
"12360","74.12400","6.17716","0.00316"
"12418","74.47200","6.20621","0.00306"
"12476","74.82000","6.23515","0.00312"
"12534","75.16800","6.26415","0.00322"
"12592","75.51600","6.29321","0.00275"
"12650","75.86400","6.32220","0.00291"
"12708","76.21200","6.35114","0.00315"
"12766","76.56000","6.38020","0.00291"
"12824","76.90800","6.40920","0.00304"
"12882","77.25600","6.43808","0.00283"
"12940","77.60400","6.46725","0.00306"
"12998","77.95200","6.49619","0.00286"
"13056","78.30000","6.52519","0.00310"
"13114","78.64800","6.55419","0.00277"
"13172","78.99600","6.58319","0.00326"
"13230","79.34400","6.61212","0.00321"
"13288","79.69200","6.64118","0.00307"
"13346","80.04000","6.67018","0.00261"
"13404","80.38800","6.69918","0.00298"
"13462","80.73600","6.72818","0.00278"
"13520","81.08400","6.75717","0.00338"
"13578","81.43200","6.78611","0.00307"
"13636","81.78000","6.81523","0.00335"
"13694","82.12800","6.84411","0.00298"
"13752","82.47600","6.87323","0.00299"
"13810","82.82400","6.90222","0.00306"
"13868","83.17200","6.93116","0.00328"
"13926","83.52000","6.96022","0.00295"
"13984","83.86800","6.98916","0.00316"
"14042","84.21600","7.01816","0.00305"
"14100","84.56400","7.04721","0.00302"
"14158","84.91200","7.07615","0.00350"
"14216","85.26000","7.10515","0.00331"
"14274","85.60800","7.13415","0.00329"
"14332","85.95600","7.16314","0.00274"
"14390","86.30400","7.19214","0.00312"
"14448","86.65200","7.22126","0.00336"
"14506","87.00000","7.25014","0.00322"
"14564","87.34800","7.27920","0.00354"
"14622","87.69600","7.30819","0.00293"
"14680","88.04400","7.33713","0.00330"
"14738","88.39200","7.36619","0.00286"
"14796","88.74000","7.39519","0.00309"
"14854","89.08800","7.42413","0.00331"
"14912","89.43600","7.45318","0.00327"
"14970","89.78400","7.48218","0.00366"
"15028","90.13200","7.51112","0.00377"
"15086","90.48000","7.54018","0.00350"
"15144","90.82800","7.56918","0.00307"
"15202","91.17600","7.59811","0.00327"
"15260","91.52400","7.62723","0.00330"
"15318","91.87200","7.65611","0.00339"
"15376","92.22000","7.68511","0.00337"
"15434","92.56800","7.71417","0.00345"
"15492","92.91600","7.74316","0.00332"
"15550","93.26400","7.77222","0.00332"
"15608","93.61200","7.80116","0.00334"
"15666","93.96000","7.83016","0.00331"
"15724","94.30800","7.85915","0.00353"
"15782","94.65600","7.88821","0.00305"
"15840","95.00400","7.91715","0.00312"
"15898","95.35200","7.94621","0.00338"
"15956","95.70000","7.97521","0.00357"
"16014","96.04800","8.00420","0.00344"
"16072","96.39600","8.03320","0.00326"
"16130","96.74400","8.06214","0.00358"
"16188","97.09200","8.09114","0.00334"
"16246","97.44000","8.12020","0.00389"
"16304","97.78800","8.14919","0.00404"
"16362","98.13600","8.17819","0.00360"
"16420","98.48400","8.20713","0.00314"
"16478","98.83200","8.23619","0.00285"
"16536","99.18000","8.26513","0.00306"
"16594","99.52800","8.29418","0.00248"
"16652","99.87600","8.32312","0.00296"
"16710","100.22400","8.35218","0.00299"
"16768","100.57200","8.38124","0.00275"
"16826","100.92000","8.41012","0.00266"
"16884","101.26800","8.43917","0.00283"
"16942","101.61600","8.46823","0.00267"
"17000","101.96400","8.49711","0.00270"
"17058","102.31200","8.52617","0.00257"
"17116","102.66000","8.55516","0.00259"
"17174","103.00800","8.58416","0.00290"
"17232","103.35600","8.61322","0.00264"
"17290","103.70400","8.64216","0.00300"
"17348","104.05200","8.67122","0.00306"
"17406","104.40000","8.70015","0.00310"
"17464","104.74800","8.72915","0.00330"
"17522","105.09600","8.75815","0.00287"
"17580","105.44400","8.78721","0.00248"
"17638","105.79200","8.81615","0.00289"
"17696","106.14000","8.84520","0.00291"
"17754","106.48800","8.87420","0.00297"
"17812","106.83600","8.90308","0.00340"
"17870","107.18400","8.93220","0.00276"
"17928","107.53200","8.96119","0.00315"
"17986","107.88000","8.99013","0.00287"
"18044","108.22800","9.01925","0.00267"
"18102","108.57600","9.04819","0.00293"
"18160","108.92400","9.07719","0.00290"
"18218","109.27200","9.10618","0.00292"
"18276","109.62000","9.13518","0.00295"
"18334","109.96800","9.16412","0.00312"
"18392","110.31600","9.19324","0.00269"
"18450","110.66400","9.22212","0.00312"
"18508","111.01200","9.25117","0.00356"
"18566","111.36000","9.28017","0.00307"
"18624","111.70800","9.30905","0.00318"
"18682","112.05600","9.33823","0.00308"
"18740","112.40400","9.36723","0.00269"
"18798","112.75200","9.39616","0.00312"
"18856","113.10000","9.42522","0.00344"
"18914","113.44800","9.45422","0.00335"
"18972","113.79600","9.48316","0.00323"
"19030","114.14400","9.51216","0.00374"
"19088","114.49200","9.54121","0.00384"
"19146","114.84000","9.57015","0.00351"
"19204","115.18800","9.59915","0.00338"
"19262","115.53600","9.62815","0.00355"
"19320","115.88400","9.65715","0.00392"
"19378","116.23200","9.68620","0.00327"
"19436","116.58000","9.71514","0.00366"
"19494","116.92800","9.74420","0.00355"
"19552","117.27600","9.77326","0.00390"
"19610","117.62400","9.80208","0.00390"
"19668","117.97200","9.83113","0.00368"
"19726","118.32000","9.86013","0.00337"
"19784","118.66800","9.88913","0.00406"
"19842","119.01600","9.91819","0.00357"
"19900","119.36400","9.94718","0.00361"
"19958","119.71200","9.97612","0.00363"
"20016","120.06000","10.00518","0.00343"
"20074","120.40800","10.03418","0.00424"
"20132","120.75600","10.06318","0.00425"
"20190","121.10400","10.09223","0.00372"
"20248","121.45200","10.12117","0.00374"
"20306","121.80000","10.15017","0.00432"
"20364","122.14800","10.17917","0.00413"
"20422","122.49600","10.20811","0.00411"
"20480","122.84400","10.23716","0.00437"
"20538","123.19200","10.26616","0.00396"
"20596","123.54000","10.29516","0.00425"
"20654","123.88800","10.32422","0.00405"
"20712","124.23600","10.35322","0.00380"
"20770","124.58400","10.38215","0.00367"
"20828","124.93200","10.41121","0.00350"
"20886","125.28000","10.44021","0.00412"
"20944","125.62800","10.46915","0.00339"
"21002","125.97600","10.49820","0.00398"
"21060","126.32400","10.52714","0.00391"
"21118","126.67200","10.55620","0.00397"
"21176","127.02000","10.58520","0.00406"
"21234","127.36800","10.61414","0.00381"
"21292","127.71600","10.64319","0.00455"
"21350","128.06400","10.67219","0.00437"
"21408","128.41200","10.70113","0.00430"
"21466","128.76000","10.73019","0.00424"
"21524","129.10800","10.75925","0.00389"
"21582","129.45600","10.78813","0.00392"
"21640","129.80400","10.81718","0.00414"
"21698","130.15200","10.84618","0.00338"
"21756","130.50000","10.87512","0.00443"
"21814","130.84800","10.90424","0.00405"
"21872","131.19600","10.93317","0.00366"
"21930","131.54400","10.96217","0.00370"
"21988","131.89200","10.99117","0.00392"
"22046","132.24000","11.02017","0.00351"
"22104","132.58800","11.04917","0.00394"
"22162","132.93600","11.07816","0.00387"
"22220","133.28400","11.10716","0.00379"
"22278","133.63200","11.13622","0.00391"
"22336","133.98000","11.16522","0.00343"
"22394","134.32800","11.19410","0.00440"
"22452","134.67600","11.22315","0.00358"
"22510","135.02400","11.25221","0.00429"
"22568","135.37200","11.28109","0.00434"
"22626","135.72000","11.31021","0.00373"
"22684","136.06800","11.33914","0.00419"
"22742","136.41600","11.36814","0.00424"
"22800","136.76400","11.39720","0.00449"
"22858","137.11200","11.42614","0.00431"
"22916","137.46000","11.45514","0.00396"
"22974","137.80800","11.48419","0.00441"
"23032","138.15600","11.51319","0.00413"
"23090","138.50400","11.54213","0.00467"
"23148","138.85200","11.57119","0.00436"
"23206","139.20000","11.60019","0.00481"
"23264","139.54800","11.62912","0.00517"
"23322","139.89600","11.65824","0.00506"
"23380","140.24400","11.68712","0.00472"
"23438","140.59200","11.71624","0.00481"
"23496","140.94000","11.74518","0.00537"
"23554","141.28800","11.77411","0.00479"
"23612","141.63600","11.80317","0.00556"
"23670","141.98400","11.83223","0.00504"
"23728","142.33200","11.86111","0.00514"
"23786","142.68000","11.89017","0.00519"
"23844","143.02800","11.91916","0.00550"
"23902","143.37600","11.94810","0.00554"
"23960","143.72400","11.97716","0.00572"
"24018","144.07200","12.00616","0.00554"
"24076","144.42000","12.03515","0.00553"
"24134","144.76800","12.06415","0.00494"
"24192","145.11600","12.09315","0.00522"
"24250","145.46400","12.12221","0.00499"
"24308","145.81200","12.15115","0.00382"
"24366","146.16000","12.18008","0.00367"
"24424","146.50800","12.20920","0.00303"
"24482","146.85600","12.23820","0.00331"
"24540","147.20400","12.26720","0.00324"
"24598","147.55200","12.29620","0.00292"
"24656","147.90000","12.32519","0.00327"
"24714","148.24800","12.35413","0.00334"
"24772","148.59600","12.38319","0.00381"
"24830","148.94400","12.41213","0.00369"
"24888","149.29200","12.44112","0.00352"
"24946","149.64000","12.47018","0.00380"
"25004","149.98800","12.49918","0.00369"
"25062","150.33600","12.52812","0.00370"
"25120","150.68400","12.55718","0.00385"
"25178","151.03200","12.58612","0.00383"
"25236","151.38000","12.61517","0.00389"
"25294","151.72800","12.64417","0.00415"
"25352","152.07600","12.67317","0.00421"
"25410","152.42400","12.70223","0.00401"
"25468","152.77200","12.73117","0.00421"
"25526","153.12000","12.76010","0.00413"
"25584","153.46800","12.78916","0.00431"
"25642","153.81600","12.81822","0.00406"
"25700","154.16400","12.84716","0.00419"
"25758","154.51200","12.87621","0.00411"
"25816","154.86000","12.90515","0.00358"
"25874","155.20800","12.93415","0.00405"
"25932","155.55600","12.96315","0.00403"
"25990","155.90400","12.99209","0.00443"
"26048","156.25200","13.02120","0.00372"
"26106","156.60000","13.05020","0.00424"
"26164","156.94800","13.07914","0.00372"
"26222","157.29600","13.10814","0.00426"
"26280","157.64400","13.13720","0.00421"
"26338","157.99200","13.16613","0.00367"
"26396","158.34000","13.19513","0.00353"
"26454","158.68800","13.22425","0.00326"
"26512","159.03600","13.25313","0.00408"
"26570","159.38400","13.28224","0.00384"
"26628","159.73200","13.31118","0.00374"
"26686","160.08000","13.34012","0.00408"
"26744","160.42800","13.36918","0.00366"
"26802","160.77600","13.39818","0.00419"
"26860","161.12400","13.42718","0.00386"
"26918","161.47200","13.45617","0.00375"
"26976","161.82000","13.48517","0.00366"
"27034","162.16800","13.51417","0.00387"
"27092","162.51600","13.54317","0.00360"
"27150","162.86400","13.57216","0.00358"
"27208","163.21200","13.60116","0.00364"
"27266","163.56000","13.63022","0.00423"
"27324","163.90800","13.65910","0.00364"
"27382","164.25600","13.68816","0.00395"
"27440","164.60400","13.71721","0.00365"
"27498","164.95200","13.74615","0.00400"
"27556","165.30000","13.77521","0.00391"
"27614","165.64800","13.80421","0.00425"
"27672","165.99600","13.83315","0.00393"
"27730","166.34400","13.86220","0.00382"
"27788","166.69200","13.89120","0.00426"
"27846","167.04000","13.92020","0.00398"
"27904","167.38800","13.94920","0.00416"
"27962","167.73600","13.97819","0.00400"
"28020","168.08400","14.00719","0.00410"
"28078","168.43200","14.03619","0.00447"
"28136","168.78000","14.06507","0.00411"
"28194","169.12800","14.09419","0.00439"
"28252","169.47600","14.12319","0.00432"
"28310","169.82400","14.15212","0.00449"
"28368","170.17200","14.18124","0.00472"
"28426","170.52000","14.21018","0.00427"
"28484","170.86800","14.23918","0.00446"
"28542","171.21600","14.26817","0.00450"
"28600","171.56400","14.29717","0.00503"
"28658","171.91200","14.32617","0.00466"
"28716","172.26000","14.35517","0.00485"
"28774","172.60800","14.38417","0.00482"
"28832","172.95600","14.41317","0.00459"
"28890","173.30400","14.44222","0.00491"
"28948","173.65200","14.47116","0.00443"
"29006","174.00000","14.50016","0.00442"
"29064","174.34800","14.52921","0.00447"
"29122","174.69600","14.55809","0.00420"
"29180","175.04400","14.58721","0.00416"
"29238","175.39200","14.61615","0.00470"
"29296","175.74000","14.64515","0.00430"
"29354","176.08800","14.67415","0.00431"
"29412","176.43600","14.70320","0.00474"
"29470","176.78400","14.73208","0.00493"
"29528","177.13200","14.76120","0.00435"
"29586","177.48000","14.79020","0.00497"
"29644","177.82800","14.81920","0.00463"
"29702","178.17600","14.84819","0.00465"
"29760","178.52400","14.87713","0.00472"
"29818","178.87200","14.90613","0.00516"
"29876","179.22000","14.93519","0.00559"
"29934","179.56800","14.96412","0.00553"
"29992","179.91600","14.99324","0.00545"
"30050","180.26400","15.02218","0.00535"
"30108","180.61200","15.05112","0.00521"
"30166","180.96000","15.08018","0.00532"
"30224","181.30800","15.10912","0.00601"
"30282","181.65600","15.13811","0.00517"
"30340","182.00400","15.16717","0.00558"
"30398","182.35200","15.19623","0.00530"
"30456","182.70000","15.22517","0.00620"
"30514","183.04800","15.25422","0.00541"
"30572","183.39600","15.28316","0.00633"
"30630","183.74400","15.31210","0.00632"
"30688","184.09200","15.34116","0.00603"
"30746","184.44000","15.37016","0.00602"
"30804","184.78800","15.39915","0.00654"
"30862","185.13600","15.42821","0.00608"
"30920","185.48400","15.45715","0.00596"
"30978","185.83200","15.48621","0.00518"
"31036","186.18000","15.51521","0.00403"
"31094","186.52800","15.54414","0.00425"
"31152","186.87600","15.57320","0.00479"
"31210","187.22400","15.60220","0.00427"
"31268","187.57200","15.63108","0.00436"
"31326","187.92000","15.66019","0.00330"
"31384","188.26800","15.68919","0.00383"
"31442","188.61600","15.71813","0.00347"
"31500","188.96400","15.74719","0.00416"
"31558","189.31200","15.77619","0.00383"
"31616","189.66000","15.80518","0.00339"
"31674","190.00800","15.83418","0.00397"
"31732","190.35600","15.86318","0.00392"
"31790","190.70400","15.89218","0.00366"
"31848","191.05200","15.92118","0.00407"
"31906","191.40000","15.95017","0.00413"
"31964","191.74800","15.97911","0.00452"
"32022","192.09600","16.00817","0.00440"
"32080","192.44400","16.03717","0.00431"
"32138","192.79200","16.06623","0.00412"
"32196","193.14000","16.09522","0.00452"
"32254","193.48800","16.12410","0.00469"
"32312","193.83600","16.15322","0.00457"
"32370","194.18400","16.18216","0.00405"
"32428","194.53200","16.21109","0.00397"
"32486","194.88000","16.24021","0.00455"
"32544","195.22800","16.26915","0.00457"
"32602","195.57600","16.29815","0.00423"
"32660","195.92400","16.32721","0.00404"
"32718","196.27200","16.35614","0.00405"
"32776","196.62000","16.38514","0.00355"
"32834","196.96800","16.41420","0.00413"
"32892","197.31600","16.44320","0.00435"
"32950","197.66400","16.47220","0.00451"
"33008","198.01200","16.50119","0.00418"
"33066","198.36000","16.53013","0.00439"
"33124","198.70800","16.55919","0.00430"
"33182","199.05600","16.58825","0.00382"
"33240","199.40400","16.61712","0.00405"
"33298","199.75200","16.64618","0.00429"
"33356","200.10000","16.67518","0.00438"
"33414","200.44800","16.70412","0.00469"
"33472","200.79600","16.73318","0.00390"
"33530","201.14400","16.76223","0.00406"
"33588","201.49200","16.79117","0.00422"
"33646","201.84000","16.82017","0.00429"
"33704","202.18800","16.84917","0.00465"
"33762","202.53600","16.87817","0.00427"
"33820","202.88400","16.90722","0.00479"
"33878","203.23200","16.93610","0.00459"
"33936","203.58000","16.96522","0.00462"
"33994","203.92800","16.99422","0.00438"
"34052","204.27600","17.02310","0.00457"
"34110","204.62400","17.05221","0.00498"
"34168","204.97200","17.08115","0.00419"
"34226","205.32000","17.11015","0.00444"
"34284","205.66800","17.13921","0.00392"
"34342","206.01600","17.16821","0.00467"
"34400","206.36400","17.19714","0.00502"
"34458","206.71200","17.22614","0.00482"
"34516","207.06000","17.25520","0.00504"
"34574","207.40800","17.28414","0.00531"
"34632","207.75600","17.31326","0.00510"
"34690","208.10400","17.34219","0.00510"
"34748","208.45200","17.37119","0.00388"
"34806","208.80000","17.40019","0.00446"
"34864","209.14800","17.42913","0.00440"
"34922","209.49600","17.45819","0.00500"
"34980","209.84400","17.48724","0.00461"
"35038","210.19200","17.51612","0.00490"
"35096","210.54000","17.54518","0.00496"
"35154","210.88800","17.57418","0.00515"
"35212","211.23600","17.60312","0.00503"
"35270","211.58400","17.63217","0.00482"
"35328","211.93200","17.66123","0.00504"
"35386","212.28000","17.69017","0.00580"
"35444","212.62800","17.71923","0.00501"
"35502","212.97600","17.74816","0.00501"
"35560","213.32400","17.77716","0.00521"
"35618","213.67200","17.80616","0.00514"
"35676","214.02000","17.83516","0.00571"
"35734","214.36800","17.86416","0.00585"
"35792","214.71600","17.89315","0.00574"
"35850","215.06400","17.92215","0.00603"
"35908","215.41200","17.95115","0.00615"
"35966","215.76000","17.98021","0.00632"
"36024","216.10800","18.00915","0.00628"
"36082","216.45600","18.03820","0.00613"
"36140","216.80400","18.06720","0.00667"
"36198","217.15200","18.09614","0.00711"
"36256","217.50000","18.12514","0.00443"
"36314","217.84800","18.15413","0.00457"
"36372","218.19600","18.18313","0.00440"
"36430","218.54400","18.21219","0.00514"
"36488","218.89200","18.24119","0.00497"
"36546","219.24000","18.27019","0.00513"
"36604","219.58800","18.29913","0.00548"
"36662","219.93600","18.32812","0.00614"
"36720","220.28400","18.35718","0.00617"
"36778","220.63200","18.38618","0.00658"
"36836","220.98000","18.41517","0.00698"
"36894","221.32800","18.44418","0.00657"
"36952","221.67600","18.47323","0.00736"
"37010","222.02400","18.50211","0.00782"
"37068","222.37200","18.53117","0.00800"
"37126","222.72000","18.56017","0.00750"
"37184","223.06800","18.58916","0.00755"
"37242","223.41600","18.61822","0.00775"
"37300","223.76400","18.64716","0.00819"
"37358","224.11200","18.67616","0.00746"
"37416","224.46000","18.70516","0.00497"
"37474","224.80800","18.73415","0.00480"
"37532","225.15600","18.76315","0.00480"
"37590","225.50400","18.79221","0.00447"
"37648","225.85200","18.82121","0.00537"
"37706","226.20000","18.85015","0.00585"
"37764","226.54800","18.87920","0.00577"
"37822","226.89600","18.90814","0.00593"
"37880","227.24400","18.93720","0.00607"
"37938","227.59200","18.96620","0.00691"
"37996","227.94000","18.99508","0.00721"
"38054","228.28800","19.02425","0.00628"
"38112","228.63600","19.05319","0.00630"
"38170","228.98400","19.08219","0.00627"
"38228","229.33200","19.11119","0.00575"
"38286","229.68000","19.14018","0.00511"
"38344","230.02800","19.16912","0.00497"
"38402","230.37600","19.19818","0.00423"
"38460","230.72400","19.22724","0.00386"
"38518","231.07200","19.25618","0.00437"
"38576","231.42000","19.28523","0.00442"
"38634","231.76800","19.31411","0.00471"
"38692","232.11600","19.34317","0.00518"
"38750","232.46400","19.37217","0.00521"
"38808","232.81200","19.40111","0.00528"
"38866","233.16000","19.43022","0.00506"
"38924","233.50800","19.45916","0.00464"
"38982","233.85600","19.48816","0.00508"
"39040","234.20400","19.51716","0.00367"
"39098","234.55200","19.54615","0.00378"
"39156","234.90000","19.57515","0.00338"
"39214","235.24800","19.60415","0.00382"
"39272","235.59600","19.63321","0.00285"
"39330","235.94400","19.66215","0.00384"
"39388","236.29200","19.69120","0.00353"
"39446","236.64000","19.72014","0.00346"
"39504","236.98800","19.74914","0.00372"
"39562","237.33600","19.77820","0.00395"
"39620","237.68400","19.80714","0.00404"
"39678","238.03200","19.83619","0.00380"
"39736","238.38000","19.86519","0.00384"
"39794","238.72800","19.89413","0.00385"
"39852","239.07600","19.92319","0.00389"
"39910","239.42400","19.95218","0.00389"
"39968","239.77200","19.98118","0.00407"
"40026","240.12000","20.01018","0.00328"
"40084","240.46800","20.03918","0.00398"
"40142","240.81600","20.06812","0.00409"
"40200","241.16400","20.09718","0.00372"
"40258","241.51200","20.12617","0.00444"
"40316","241.86000","20.15517","0.00410"
"40374","242.20800","20.18417","0.00369"
"40432","242.55600","20.21317","0.00416"
"40490","242.90400","20.24217","0.00422"
"40548","243.25200","20.27116","0.00447"
"40606","243.60000","20.30016","0.00503"
"40664","243.94800","20.32922","0.00474"
"40722","244.29600","20.35815","0.00500"
"40780","244.64400","20.38715","0.00500"
"40838","244.99200","20.41609","0.00566"
"40896","245.34000","20.44521","0.00569"
"40954","245.68800","20.47415","0.00570"
"41012","246.03600","20.50321","0.00593"
"41070","246.38400","20.53220","0.00643"
"41128","246.73200","20.56114","0.00676"
"41186","247.08000","20.59020","0.00674"
"41244","247.42800","20.61914","0.00734"
"41302","247.77600","20.64814","0.00623"
"41360","248.12400","20.67719","0.00737"
"41418","248.47200","20.70619","0.00731"
"41476","248.82000","20.73519","0.00708"
"41534","249.16800","20.76419","0.00775"
"41592","249.51600","20.79313","0.00780"
"41650","249.86400","20.82218","0.00751"
"41708","250.21200","20.85118","0.00699"
"41766","250.56000","20.88018","0.00710"
"41824","250.90800","20.90918","0.00700"
"41882","251.25600","20.93823","0.00742"
"41940","251.60400","20.96711","0.00421"
"41998","251.95200","20.99617","0.00395"
"42056","252.30000","21.02517","0.00433"
"42114","252.64800","21.05411","0.00420"
"42172","252.99600","21.08323","0.00400"
"42230","253.34400","21.11222","0.00464"
"42288","253.69200","21.14110","0.00484"
"42346","254.04000","21.17022","0.00470"
"42404","254.38800","21.19921","0.00520"
"42462","254.73600","21.22821","0.00491"
"42520","255.08400","21.25721","0.00509"
"42578","255.43200","21.28615","0.00495"
"42636","255.78000","21.31515","0.00552"
"42694","256.12800","21.34420","0.00559"
"42752","256.47600","21.37308","0.00502"
"42810","256.82400","21.40220","0.00507"
"42868","257.17200","21.43120","0.00546"
"42926","257.52000","21.46014","0.00541"
"42984","257.86800","21.48919","0.00558"
"43042","258.21600","21.51819","0.00618"
"43100","258.56400","21.54713","0.00618"
"43158","258.91200","21.57619","0.00625"
"43216","259.26000","21.60519","0.00673"
"43274","259.60800","21.63412","0.00712"
"43332","259.95600","21.66318","0.00722"
"43390","260.30400","21.69218","0.00700"
"43448","260.65200","21.72112","0.00709"
"43506","261.00000","21.75017","0.00765"
"43564","261.34800","21.77918","0.00823"
"43622","261.69600","21.80823","0.00836"
"43680","262.04400","21.83717","0.00867"
"43738","262.39200","21.86611","0.00747"
"43796","262.74000","21.89517","0.00783"
"43854","263.08800","21.92416","0.00717"
"43912","263.43600","21.95316","0.00638"
"43970","263.78400","21.98216","0.00581"
"44028","264.13200","22.01116","0.00606"
"44086","264.48000","22.04016","0.00525"
"44144","264.82800","22.06921","0.00594"
"44202","265.17600","22.09815","0.00624"
"44260","265.52400","22.12709","0.00667"
"44318","265.87200","22.15621","0.00660"
"44376","266.22000","22.18515","0.00766"
"44434","266.56800","22.21414","0.00840"
"44492","266.91600","22.24314","0.00834"
"44550","267.26400","22.27214","0.00870"
"44608","267.61200","22.30120","0.00871"
"44666","267.96000","22.33019","0.00892"
"44724","268.30800","22.35919","0.00883"
"44782","268.65600","22.38813","0.00937"
"44840","269.00400","22.41719","0.00889"
"44898","269.35200","22.44619","0.00760"
"44956","269.70000","22.47518","0.00705"
"45014","270.04800","22.50418","0.00836"
"45072","270.39600","22.53318","0.00754"
"45130","270.74400","22.56218","0.00828"
"45188","271.09200","22.59112","0.00801"
"45246","271.44000","22.62011","0.00909"
"45304","271.78800","22.64923","0.00652"
"45362","272.13600","22.67811","0.00549"
"45420","272.48400","22.70717","0.00560"
"45478","272.83200","22.73617","0.00595"
"45536","273.18000","22.76517","0.00697"
"45594","273.52800","22.79416","0.00637"
"45652","273.87600","22.82316","0.00720"
"45710","274.22400","22.85216","0.00762"
"45768","274.57200","22.88122","0.00701"
"45826","274.92000","22.91021","0.00799"
"45884","275.26800","22.93909","0.00795"
"45942","275.61600","22.96821","0.00831"
"46000","275.96400","22.99721","0.00781"
"46058","276.31200","23.02621","0.00833"
"46116","276.66000","23.05520","0.00855"
"46174","277.00800","23.08414","0.00963"
"46232","277.35600","23.11314","0.00987"
"46290","277.70400","23.14220","0.00882"
"46348","278.05200","23.17114","0.00818"
"46406","278.40000","23.20013","0.00844"
"46464","278.74800","23.22919","0.00245"
"46522","279.09600","23.25819","0.00296"
"46580","279.44400","23.28713","0.00292"
"46638","279.79200","23.31624","0.00331"
"46696","280.14000","23.34506","0.00248"
"46754","280.48800","23.37418","0.00305"
"46812","280.83600","23.40324","0.00311"
"46870","281.18400","23.43218","0.00320"
"46928","281.53200","23.46117","0.00345"
"46986","281.88000","23.49017","0.00276"
"47044","282.22800","23.51911","0.00266"
"47102","282.57600","23.54823","0.00339"
"47160","282.92400","23.57717","0.00320"
"47218","283.27200","23.60616","0.00302"
"47276","283.62000","23.63516","0.00323"
"47334","283.96800","23.66416","0.00356"
"47392","284.31600","23.69316","0.00351"
"47450","284.66400","23.72228","0.00352"
"47508","285.01200","23.75109","0.00337"
"47566","285.36000","23.78015","0.00303"
"47624","285.70800","23.80921","0.00307"
"47682","286.05600","23.83815","0.00339"
"47740","286.40400","23.86720","0.00331"
"47798","286.75200","23.89620","0.00364"
"47856","287.10000","23.92514","0.00366"
"47914","287.44800","23.95420","0.00366"
"47972","287.79600","23.98320","0.00338"
"48030","288.14400","24.01213","0.00338"
"48088","288.49200","24.04119","0.00370"
"48146","288.84000","24.07019","0.00325"
"48204","289.18800","24.09913","0.00384"
"48262","289.53600","24.12819","0.00347"
"48320","289.88400","24.15718","0.00352"
"48378","290.23200","24.18612","0.00395"
"48436","290.58000","24.21518","0.00398"
"48494","290.92800","24.24412","0.00302"
"48552","291.27600","24.27317","0.00313"
"48610","291.62400","24.30217","0.00333"
"48668","291.97200","24.33117","0.00363"
"48726","292.32000","24.36017","0.00402"
"48784","292.66800","24.38917","0.00380"
"48842","293.01600","24.41810","0.00355"
"48900","293.36400","24.44722","0.00353"
"48958","293.71200","24.47622","0.00363"
"49016","294.06000","24.50516","0.00371"
"49074","294.40800","24.53416","0.00415"
"49132","294.75600","24.56316","0.00355"
"49190","295.10400","24.59215","0.00397"
"49248","295.45200","24.62121","0.00386"
"49306","295.80000","24.65015","0.00382"
"49364","296.14800","24.67921","0.00419"
"49422","296.49600","24.70815","0.00394"
"49480","296.84400","24.73714","0.00400"
"49538","297.19200","24.76620","0.00397"
"49596","297.54000","24.79520","0.00381"
"49654","297.88800","24.82413","0.00339"
"49712","298.23600","24.85319","0.00416"
"49770","298.58400","24.88213","0.00463"
"49828","298.93200","24.91113","0.00417"
"49886","299.28000","24.94019","0.00429"
"49944","299.62800","24.96913","0.00380"
"50002","299.97600","24.99812","0.00352"
"50060","300.32400","25.02724","0.00346"
"50118","300.67200","25.05618","0.00335"
"50176","301.02000","25.08517","0.00274"
"50234","301.36800","25.11418","0.00291"
"50292","301.71600","25.14318","0.00319"
"50350","302.06400","25.17217","0.00341"
"50408","302.41200","25.20117","0.00351"
"50466","302.76000","25.23017","0.00371"
"50524","303.10800","25.25916","0.00339"
"50582","303.45600","25.28822","0.00325"
"50640","303.80400","25.31716","0.00366"
"50698","304.15200","25.34622","0.00354"
"50756","304.50000","25.37522","0.00341"
"50814","304.84800","25.40409","0.00334"
"50872","305.19600","25.43315","0.00327"
"50930","305.54400","25.46221","0.00360"
"50988","305.89200","25.49115","0.00355"
"51046","306.24000","25.52021","0.00330"
"51104","306.58800","25.54914","0.00341"
"51162","306.93600","25.57814","0.00379"
"51220","307.28400","25.60720","0.00352"
"51278","307.63200","25.63620","0.00376"
"51336","307.98000","25.66514","0.00315"
"51394","308.32800","25.69419","0.00363"
"51452","308.67600","25.72313","0.00361"
"51510","309.02400","25.75213","0.00332"
"51568","309.37200","25.78119","0.00308"
"51626","309.72000","25.81007","0.00348"
"51684","310.06800","25.83918","0.00359"
"51742","310.41600","25.86824","0.00294"
"51800","310.76400","25.89718","0.00340"
"51858","311.11200","25.92618","0.00308"
"51916","311.46000","25.95518","0.00320"
"51974","311.80800","25.98417","0.00364"
"52032","312.15600","26.01317","0.00348"
"52090","312.50400","26.04223","0.00345"
"52148","312.85200","26.07117","0.00295"
"52206","313.20000","26.10017","0.00328"
"52264","313.54800","26.12910","0.00318"
"52322","313.89600","26.15816","0.00383"
"52380","314.24400","26.18722","0.00384"
"52438","314.59200","26.21615","0.00364"
"52496","314.94000","26.24521","0.00395"
"52554","315.28800","26.27421","0.00410"
"52612","315.63600","26.30315","0.00361"
"52670","315.98400","26.33221","0.00372"
"52728","316.33200","26.36115","0.00390"
"52786","316.68000","26.39014","0.00375"
"52844","317.02800","26.41914","0.00415"
"52902","317.37600","26.44820","0.00391"
"52960","317.72400","26.47720","0.00383"
"53018","318.07200","26.50620","0.00443"
"53076","318.42000","26.53519","0.00432"
"53134","318.76800","26.56413","0.00423"
"53192","319.11600","26.59319","0.00393"
"53250","319.46400","26.62213","0.00402"
"53308","319.81200","26.65118","0.00406"
"53366","320.16000","26.68018","0.00403"
"53424","320.50800","26.70912","0.00408"
"53482","320.85600","26.73818","0.00405"
"53540","321.20400","26.76718","0.00388"
"53598","321.55200","26.79612","0.00359"
"53656","321.90000","26.82523","0.00387"
"53714","322.24800","26.85417","0.00371"
"53772","322.59600","26.88311","0.00390"
"53830","322.94400","26.91223","0.00438"
"53888","323.29200","26.94117","0.00430"
"53946","323.64000","26.97016","0.00268"
"54004","323.98800","26.99922","0.00227"
"54062","324.33600","27.02816","0.00219"
"54120","324.68400","27.05716","0.00197"
"54178","325.03200","27.08621","0.00246"
"54236","325.38000","27.11515","0.00216"
"54294","325.72800","27.14421","0.00237"
"54352","326.07600","27.17315","0.00178"
"54410","326.42400","27.20214","0.00176"
"54468","326.77200","27.23114","0.00192"
"54526","327.12000","27.26020","0.00182"
"54584","327.46800","27.28914","0.00170"
"54642","327.81600","27.31820","0.00193"
"54700","328.16400","27.34720","0.00194"
"54758","328.51200","27.37613","0.00183"
"54816","328.86000","27.40519","0.00233"
"54874","329.20800","27.43413","0.00239"
"54932","329.55600","27.46313","0.00241"
"54990","329.90400","27.49219","0.00221"
"55048","330.25200","27.52112","0.00239"
"55106","330.60000","27.55018","0.00241"
"55164","330.94800","27.57918","0.00270"
"55222","331.29600","27.60812","0.00273"
"55280","331.64400","27.63717","0.00238"
"55338","331.99200","27.66617","0.00205"
"55396","332.34000","27.69511","0.00186"
"55454","332.68800","27.72417","0.00167"
"55512","333.03600","27.75323","0.00220"
"55570","333.38400","27.78210","0.00210"
"55628","333.73200","27.81122","0.00216"
"55686","334.08000","27.84016","0.00237"
"55744","334.42800","27.86910","0.00235"
"55802","334.77600","27.89821","0.00204"
"55860","335.12400","27.92715","0.00218"
"55918","335.47200","27.95615","0.00194"
"55976","335.82000","27.98515","0.00178"
"56034","336.16800","28.01414","0.00174"
"56092","336.51600","28.04320","0.00174"
"56150","336.86400","28.07220","0.00204"
"56208","337.21200","28.10114","0.00223"
"56266","337.56000","28.13014","0.00213"
"56324","337.90800","28.15920","0.00163"
"56382","338.25600","28.18819","0.00198"
"56440","338.60400","28.21719","0.00211"
"56498","338.95200","28.24625","0.00165"
"56556","339.30000","28.27513","0.00222"
"56614","339.64800","28.30419","0.00212"
"56672","339.99600","28.33318","0.00175"
"56730","340.34400","28.36218","0.00184"
"56788","340.69200","28.39118","0.00176"
"56846","341.04000","28.42018","0.00194"
"56904","341.38800","28.44918","0.00187"
"56962","341.73600","28.47818","0.00147"
"57020","342.08400","28.50717","0.00183"
"57078","342.43200","28.53617","0.00176"
"57136","342.78000","28.56517","0.00224"
"57194","343.12800","28.59411","0.00207"
"57252","343.47600","28.62316","0.00152"
"57310","343.82400","28.65222","0.00115"
"57368","344.17200","28.68110","0.00174"
"57426","344.52000","28.71022","0.00129"
"57484","344.86800","28.73922","0.00152"
"57542","345.21600","28.76815","0.00187"
"57600","345.56400","28.79721","0.00164"
"57658","345.91200","28.82621","0.00116"
"57716","346.26000","28.85515","0.00105"
"57774","346.60800","28.88421","0.00151"
"57832","346.95600","28.91320","0.00129"
"57890","347.30400","28.94214","0.00149"
"57948","347.65200","28.97120","0.00105"
"58006","348.00000","29.00019","0.00133"
"58064","348.34800","29.02913","0.00119"
"58122","348.69600","29.05819","0.00136"
"58180","349.04400","29.08707","0.00160"
"58238","349.39200","29.11619","0.00120"
"58296","349.74000","29.14519","0.00127"
"58354","350.08800","29.17413","0.00111"
"58412","350.43600","29.20318","0.00105"
"58470","350.78400","29.23218","0.00164"
"58528","351.13200","29.26112","0.00163"
"58586","351.48000","29.29024","0.00102"
"58644","351.82800","29.31917","0.00119"
"58702","352.17600","29.34817","0.00145"
"58760","352.52400","29.37717","0.00174"
"58818","352.87200","29.40617","0.00128"
"58876","353.22000","29.43517","0.00150"
"58934","353.56800","29.46422","0.00157"
"58992","353.91600","29.49316","0.00093"
"59050","354.26400","29.52216","0.00120"
"59108","354.61200","29.55116","0.00122"
"59166","354.96000","29.58016","0.00104"
"59224","355.30800","29.60915","0.00170"
"59282","355.65600","29.63821","0.00128"
"59340","356.00400","29.66715","0.00133"
"59398","356.35200","29.69621","0.00178"
"59456","356.70000","29.72527","0.00134"
"59514","357.04800","29.75408","0.00153"
"59572","357.39600","29.78320","0.00175"
"59630","357.74400","29.81220","0.00179"
"59688","358.09200","29.84114","0.00152"
"59746","358.44000","29.87025","0.00155"
"59804","358.78800","29.89913","0.00191"
"59862","359.13600","29.92813","0.00149"
"59920","359.48400","29.95719","0.00174"
"59978","359.83200","29.98613","0.00187"
"60036","360.18000","30.01512","0.00203"
"60094","360.52800","30.04412","0.00126"
"60152","360.87600","30.07318","0.00187"
"60210","361.22400","30.10218","0.00174"
"60268","361.57200","30.13117","0.00155"
"60326","361.92000","30.16017","0.00166"
"60384","362.26800","30.18917","0.00146"
"60442","362.61600","30.21817","0.00110"
"60500","362.96400","30.24717","0.00153"
"60558","363.31200","30.27617","0.00097"
"60616","363.66000","30.30522","0.00135"
"60674","364.00800","30.33416","0.00156"
"60732","364.35600","30.36322","0.00160"
"60790","364.70400","30.39216","0.00144"
"60848","365.05200","30.42122","0.00135"
"60906","365.40000","30.45015","0.00178"
"60964","365.74800","30.47915","0.00128"
"61022","366.09600","30.50821","0.00156"
"61080","366.44400","30.53721","0.00169"
"61138","366.79200","30.56614","0.00138"
"61196","367.14000","30.59514","0.00131"
"61254","367.48800","30.62414","0.00145"
"61312","367.83600","30.65308","0.00147"
"61370","368.18400","30.68225","0.00159"
"61428","368.53200","30.71113","0.00189"
"61486","368.88000","30.74019","0.00164"
"61544","369.22800","30.76925","0.00147"
"61602","369.57600","30.79819","0.00150"
"61660","369.92400","30.82712","0.00110"
"61718","370.27200","30.85618","0.00161"
"61776","370.62000","30.88512","0.00124"
"61834","370.96800","30.91418","0.00150"
"61892","371.31600","30.94318","0.00159"
"61950","371.66400","30.97218","0.00129"
"62008","372.01200","31.00117","0.00163"
"62066","372.36000","31.03023","0.00173"
"62124","372.70800","31.05911","0.00163"
"62182","373.05600","31.08823","0.00143"
"62240","373.40400","31.11722","0.00165"
"62298","373.75200","31.14610","0.00155"
"62356","374.10000","31.17516","0.00167"
"62414","374.44800","31.20416","0.00130"
"62472","374.79600","31.23316","0.00189"
"62530","375.14400","31.26227","0.00148"
"62588","375.49200","31.29121","0.00168"
"62646","375.84000","31.32015","0.00189"
"62704","376.18800","31.34921","0.00187"
"62762","376.53600","31.37814","0.00175"
"62820","376.88400","31.40714","0.00174"
"62878","377.23200","31.43620","0.00190"
"62936","377.58000","31.46514","0.00176"
"62994","377.92800","31.49420","0.00177"
"63052","378.27600","31.52313","0.00157"
"63110","378.62400","31.55213","0.00178"
"63168","378.97200","31.58119","0.00184"
"63226","379.32000","31.61019","0.00216"
"63284","379.66800","31.63918","0.00211"
"63342","380.01600","31.66824","0.00167"
"63400","380.36400","31.69718","0.00173"
"63458","380.71200","31.72612","0.00147"
"63516","381.06000","31.75517","0.00177"
"63574","381.40800","31.78417","0.00207"
"63632","381.75600","31.81311","0.00187"
"63690","382.10400","31.84223","0.00204"
"63748","382.45200","31.87117","0.00143"
"63806","382.80000","31.90017","0.00168"
"63864","383.14800","31.92922","0.00178"
"63922","383.49600","31.95810","0.00168"
"63980","383.84400","31.98722","0.00239"
"64038","384.19200","32.01622","0.00179"
"64096","384.54000","32.04515","0.00196"
"64154","384.88800","32.07415","0.00163"
"64212","385.23600","32.10321","0.00236"
"64270","385.58400","32.13215","0.00205"
"64328","385.93200","32.16115","0.00189"
"64386","386.28000","32.19014","0.00210"
"64444","386.62800","32.21915","0.00165"
"64502","386.97600","32.24820","0.00231"
"64560","387.32400","32.27714","0.00183"
"64618","387.67200","32.30620","0.00185"
"64676","388.02000","32.33520","0.00208"
"64734","388.36800","32.36413","0.00162"
"64792","388.71600","32.39319","0.00186"
"64850","389.06400","32.42219","0.00202"
"64908","389.41200","32.45119","0.00186"
"64966","389.76000","32.48013","0.00190"
"65024","390.10800","32.50918","0.00176"
"65082","390.45600","32.53812","0.00180"
"65140","390.80400","32.56718","0.00147"
"65198","391.15200","32.59630","0.00200"
"65256","391.50000","32.62512","0.00196"
"65314","391.84800","32.65423","0.00202"
"65372","392.19600","32.68317","0.00196"
"65430","392.54400","32.71217","0.00198"
"65488","392.89200","32.74123","0.00187"
"65546","393.24000","32.77010","0.00215"
"65604","393.58800","32.79916","0.00219"
"65662","393.93600","32.82822","0.00128"
"65720","394.28400","32.85716","0.00184"
"65778","394.63200","32.88615","0.00154"
"65836","394.98000","32.91515","0.00155"
"65894","395.32800","32.94415","0.00152"
"65952","395.67600","32.97315","0.00183"
"66010","396.02400","33.00221","0.00154"
"66068","396.37200","33.03109","0.00113"
"66126","396.72000","33.06020","0.00165"
"66184","397.06800","33.08926","0.00190"
"66242","397.41600","33.11814","0.00148"
"66300","397.76400","33.14714","0.00188"
"66358","398.11200","33.17614","0.00185"
"66416","398.46000","33.20513","0.00169"
"66474","398.80800","33.23413","0.00182"
"66532","399.15600","33.26319","0.00112"
"66590","399.50400","33.29219","0.00139"
"66648","399.85200","33.32118","0.00124"
"66706","400.20000","33.35018","0.00079"
"66764","400.54800","33.37912","0.00090"
"66822","400.89600","33.40824","0.00151"
"66880","401.24400","33.43712","0.00102"
"66938","401.59200","33.46618","0.00093"
"66996","401.94000","33.49523","0.00132"
"67054","402.28800","33.52411","0.00142"
"67112","402.63600","33.55323","0.00122"
"67170","402.98400","33.58216","0.00147"
"67228","403.33200","33.61110","0.00123"
"67286","403.68000","33.64022","0.00122"
"67344","404.02800","33.66916","0.00094"
"67402","404.37600","33.69816","0.00108"
"67460","404.72400","33.72715","0.00124"
"67518","405.07200","33.75621","0.00096"
"67576","405.42000","33.78515","0.00111"
"67634","405.76800","33.81421","0.00078"
"67692","406.11600","33.84309","0.00107"
"67750","406.46400","33.87215","0.00116"
"67808","406.81200","33.90120","0.00102"
"67866","407.16000","33.93020","0.00111"
"67924","407.50800","33.95920","0.00093"
"67982","407.85600","33.98820","0.00097"
"68040","408.20400","34.01714","0.00079"
"68098","408.55200","34.04613","0.00121"
"68156","408.90000","34.07519","0.00112"
"68214","409.24800","34.10413","0.00110"
"68272","409.59600","34.13319","0.00095"
"68330","409.94400","34.16219","0.00103"
"68388","410.29400","34.19130","0.00089"
"68446","410.64200","34.22036","0.00095"
"68504","410.99000","34.24930","0.00095"
"68562","411.33800","34.27830","0.00110"
"68620","411.68600","34.30729","0.00121"
"68678","412.03400","34.33629","0.00099"
"68736","412.38200","34.36535","0.00113"
"68794","412.73000","34.39429","0.00143"
"68852","413.07800","34.42328","0.00071"
"68910","413.42600","34.45234","0.00094"
"68968","413.77400","34.48134","0.00075"
"69026","414.12200","34.51028","0.00099"
"69084","414.47000","34.53934","0.00109"
"69142","414.81800","34.56839","0.00115"
"69200","415.16600","34.59733","0.00095"
"69258","415.51400","34.62639","0.00078"
"69316","415.86200","34.65533","0.00107"
"69374","416.21000","34.68427","0.00116"
"69432","416.55800","34.71338","0.00152"
"69490","416.90600","34.74232","0.00158"
"69548","417.25400","34.77132","0.00088"
"69606","417.60200","34.80032","0.00150"
"69664","417.95000","34.82932","0.00099"
"69722","418.29800","34.85831","0.00064"
"69780","418.64600","34.88737","0.00125"
"69838","418.99400","34.91631","0.00096"
"69896","419.34200","34.94531","0.00089"
"69954","419.69000","34.97437","0.00096"
"70012","420.03800","35.00330","0.00076"
"70070","420.38600","35.03236","0.00084"
"70128","420.73400","35.06136","0.00122"
"70186","421.08200","35.09030","0.00136"
"70244","421.43000","35.11935","0.00091"
"70302","421.77800","35.14835","0.00086"
"70360","422.12600","35.17735","0.00129"
"70418","422.47400","35.20635","0.00078"
"70476","422.82200","35.23534","0.00113"
"70534","423.17000","35.26434","0.00127"
"70592","423.51800","35.29334","0.00116"
"70650","423.86600","35.32234","0.00061"
"70708","424.21400","35.35128","0.00075"
"70766","424.56200","35.38034","0.00170"
"70824","424.91000","35.40928","0.00047"
"70882","425.25800","35.43833","0.00157"
"70940","425.60600","35.46739","0.00116"
"70998","425.95400","35.49627","0.00106"
"71056","426.30200","35.52539","0.00053"
"71114","426.65000","35.55438","0.00090"
"71172","426.99800","35.58332","0.00094"
"71230","427.34600","35.61238","0.00116"
"71288","427.69400","35.64132","0.00080"
"71346","428.04200","35.67031","0.00122"
"71404","428.39000","35.69938","0.00099"
"71462","428.73800","35.72831","0.00087"
"71520","429.08600","35.75731","0.00111"
"71578","429.43400","35.78637","0.00120"
"71636","429.78200","35.81531","0.00096"
"71694","430.13000","35.84430","0.00076"
"71752","430.47800","35.87336","0.00053"
"71810","430.82600","35.90230","0.00113"
"71868","431.17400","35.93135","0.00080"
"71894","431.33000","35.94427","0.00044"