File: Trajectories_together/170121_1Specimen_RawData_9.csv
"","V1","V2","V3"
"1","End date","1/21/2017",""
"2","Specimen label","4DG_25",""
"3","Maximum Load","0.99007","N"
"4","Time","Extension","Load"
"5","(s)","(mm)","(N)"
"6","0.00000","0.00000","-0.00002"
"70","0.38400","0.03211","0.00232"
"134","0.76800","0.06415","0.00285"
"198","1.15200","0.09614","0.00352"
"262","1.53600","0.12813","0.00409"
"326","1.92000","0.16012","0.00472"
"390","2.30400","0.19216","0.00529"
"454","2.68800","0.22409","0.00583"
"518","3.07200","0.25608","0.00614"
"582","3.45600","0.28813","0.00636"
"646","3.84000","0.32011","0.00653"
"710","4.22400","0.35216","0.00664"
"774","4.60800","0.38409","0.00687"
"838","4.99200","0.41614","0.00703"
"902","5.37600","0.44812","0.00735"
"966","5.76000","0.48011","0.00775"
"1030","6.14400","0.51210","0.00783"
"1094","6.52800","0.54414","0.00801"
"1158","6.91200","0.57607","0.00780"
"1222","7.29600","0.60806","0.00869"
"1286","7.68000","0.64011","0.00850"
"1350","8.06400","0.67215","0.00855"
"1414","8.44800","0.70408","0.00943"
"1478","8.83200","0.73607","0.00863"
"1542","9.21600","0.76818","0.00927"
"1606","9.60000","0.80010","0.00880"
"1670","9.98400","0.83203","0.00914"
"1734","10.36800","0.86414","0.01003"
"1798","10.75200","0.89607","0.00966"
"1862","11.13600","0.92805","0.00936"
"1926","11.52000","0.96010","0.00936"
"1990","11.90400","0.99209","0.00954"
"2054","12.28800","1.02413","0.00989"
"2118","12.67200","1.05606","0.01036"
"2182","13.05600","1.08811","0.01052"
"2246","13.44000","1.12016","0.01023"
"2310","13.82400","1.15208","0.01010"
"2374","14.20800","1.18407","0.01021"
"2438","14.59200","1.21612","0.01099"
"2502","14.97600","1.24811","0.01050"
"2566","15.36000","1.28003","0.01051"
"2630","15.74400","1.31208","0.01045"
"2694","16.12800","1.34413","0.01096"
"2758","16.51200","1.37606","0.01128"
"2822","16.89600","1.40810","0.01149"
"2886","17.28000","1.44015","0.01117"
"2950","17.66400","1.47214","0.01155"
"3014","18.04800","1.50407","0.01129"
"3078","18.43200","1.53611","0.01145"
"3142","18.81600","1.56816","0.01150"
"3206","19.20000","1.60009","0.01122"
"3270","19.58400","1.63207","0.01044"
"3334","19.96800","1.66412","0.01130"
"3398","20.35200","1.69611","0.01120"
"3462","20.73600","1.72804","0.01103"
"3526","21.12000","1.76014","0.01117"
"3590","21.50400","1.79213","0.01156"
"3654","21.88800","1.82406","0.01101"
"3718","22.27200","1.85617","0.01189"
"3782","22.65600","1.88815","0.01140"
"3846","23.04000","1.92008","0.01186"
"3910","23.42400","1.95207","0.01138"
"3974","23.80800","1.98412","0.01232"
"4038","24.19200","2.01616","0.01199"
"4102","24.57600","2.04809","0.01192"
"4166","24.96000","2.08014","0.01185"
"4230","25.34400","2.11213","0.01157"
"4294","25.72800","2.14411","0.01212"
"4358","26.11200","2.17610","0.01193"
"4422","26.49600","2.20815","0.01197"
"4486","26.88000","2.24019","0.01187"
"4550","27.26400","2.27206","0.01163"
"4614","27.64800","2.30411","0.01171"
"4678","28.03200","2.33610","0.01195"
"4742","28.41600","2.36814","0.01100"
"4806","28.80000","2.40007","0.01057"
"4870","29.18400","2.43212","0.01107"
"4934","29.56800","2.46417","0.01082"
"4998","29.95200","2.49603","0.01079"
"5062","30.33600","2.52808","0.01070"
"5126","30.72000","2.56013","0.01135"
"5190","31.10400","2.59212","0.01004"
"5254","31.48800","2.62410","0.01048"
"5318","31.87200","2.65615","0.01064"
"5382","32.25600","2.68808","0.01011"
"5446","32.64000","2.72007","0.01070"
"5510","33.02400","2.75217","0.01118"
"5574","33.40800","2.78410","0.01087"
"5638","33.79200","2.81609","0.01093"
"5702","34.17600","2.84813","0.01105"
"5766","34.56000","2.88012","0.01121"
"5830","34.94400","2.91217","0.01152"
"5894","35.32800","2.94410","0.01118"
"5958","35.71200","2.97614","0.01163"
"6022","36.09600","3.00807","0.01131"
"6086","36.48000","3.04012","0.01149"
"6150","36.86400","3.07205","0.01117"
"6214","37.24800","3.10409","0.01132"
"6278","37.63200","3.13620","0.01106"
"6342","38.01600","3.16801","0.01069"
"6406","38.40000","3.20012","0.01094"
"6470","38.78400","3.23210","0.01051"
"6534","39.16800","3.26409","0.01110"
"6598","39.55200","3.29614","0.01137"
"6662","39.93600","3.32818","0.01115"
"6726","40.32000","3.36011","0.01154"
"6790","40.70400","3.39210","0.01154"
"6854","41.08800","3.42415","0.01171"
"6918","41.47200","3.45613","0.01188"
"6982","41.85600","3.48806","0.01174"
"7046","42.24000","3.52005","0.01216"
"7110","42.62400","3.55210","0.01185"
"7174","43.00800","3.58414","0.01173"
"7238","43.39200","3.61607","0.01301"
"7302","43.77600","3.64812","0.01277"
"7366","44.16000","3.68005","0.01314"
"7430","44.54400","3.71209","0.01302"
"7494","44.92800","3.74408","0.01279"
"7558","45.31200","3.77613","0.01300"
"7622","45.69600","3.80817","0.01330"
"7686","46.08000","3.84010","0.01299"
"7750","46.46400","3.87203","0.01435"
"7814","46.84800","3.90414","0.01374"
"7878","47.23200","3.93612","0.01436"
"7942","47.61600","3.96811","0.01448"
"8006","48.00000","4.00010","0.01484"
"8070","48.38400","4.03209","0.01490"
"8134","48.76800","4.06407","0.01456"
"8198","49.15200","4.09612","0.01487"
"8262","49.53600","4.12817","0.01543"
"8326","49.92000","4.16004","0.01259"
"8390","50.30400","4.19208","0.01287"
"8454","50.68800","4.22419","0.01380"
"8518","51.07200","4.25612","0.01312"
"8582","51.45600","4.28805","0.01315"
"8646","51.84000","4.32015","0.01342"
"8710","52.22400","4.35214","0.01397"
"8774","52.60800","4.38413","0.01403"
"8838","52.99200","4.41611","0.01401"
"8902","53.37600","4.44810","0.01436"
"8966","53.76000","4.48009","0.01482"
"9030","54.14400","4.51208","0.01485"
"9094","54.52800","4.54412","0.01473"
"9158","54.91200","4.57611","0.01493"
"9222","55.29600","4.60810","0.01540"
"9286","55.68000","4.64009","0.01660"
"9350","56.06400","4.67213","0.01611"
"9414","56.44800","4.70412","0.01688"
"9478","56.83200","4.73605","0.01698"
"9542","57.21600","4.76804","0.01760"
"9606","57.60000","4.80014","0.01824"
"9670","57.98400","4.83213","0.01657"
"9734","58.36800","4.86406","0.01815"
"9798","58.75200","4.89616","0.01889"
"9862","59.13600","4.92815","0.01831"
"9926","59.52000","4.96002","0.01915"
"9990","59.90400","4.99213","0.01777"
"10054","60.28800","5.02411","0.01847"
"10118","60.67200","5.05610","0.01938"
"10182","61.05600","5.08809","0.01893"
"10246","61.44000","5.12014","0.01975"
"10310","61.82400","5.15206","0.02013"
"10374","62.20800","5.18405","0.02066"
"10438","62.59200","5.21616","0.02117"
"10502","62.97600","5.24815","0.02131"
"10566","63.36000","5.28007","0.02223"
"10630","63.74400","5.31206","0.02233"
"10694","64.12800","5.34411","0.02124"
"10758","64.51200","5.37616","0.02224"
"10822","64.89600","5.40808","0.02265"
"10886","65.28000","5.44013","0.02236"
"10950","65.66400","5.47212","0.02212"
"11014","66.04800","5.50410","0.02285"
"11078","66.43200","5.53603","0.02321"
"11142","66.81600","5.56814","0.02362"
"11206","67.20000","5.60013","0.02336"
"11270","67.58400","5.63205","0.02425"
"11334","67.96800","5.66416","0.02522"
"11398","68.35200","5.69615","0.02562"
"11462","68.73600","5.72808","0.02529"
"11526","69.12000","5.76012","0.02596"
"11590","69.50400","5.79211","0.02704"
"11654","69.88800","5.82416","0.02728"
"11718","70.27200","5.85603","0.02677"
"11782","70.65600","5.88807","0.02890"
"11846","71.04000","5.92018","0.02878"
"11910","71.42400","5.95211","0.02832"
"11974","71.80800","5.98410","0.02917"
"12038","72.19200","6.01614","0.02928"
"12102","72.57600","6.04813","0.02972"
"12166","72.96000","6.08006","0.03059"
"12230","73.34400","6.11210","0.03147"
"12294","73.72800","6.14409","0.03112"
"12358","74.11200","6.17614","0.03190"
"12422","74.49600","6.20807","0.03202"
"12486","74.88000","6.24011","0.03264"
"12550","75.26400","6.27210","0.03318"
"12614","75.64800","6.30409","0.03408"
"12678","76.03200","6.33614","0.03332"
"12742","76.41600","6.36812","0.03375"
"12806","76.80000","6.40005","0.03410"
"12870","77.18400","6.43210","0.03448"
"12934","77.56800","6.46415","0.03470"
"12998","77.95200","6.49613","0.03496"
"13062","78.33600","6.52806","0.03525"
"13126","78.72000","6.56005","0.03537"
"13190","79.10400","6.59215","0.03570"
"13254","79.48800","6.62408","0.03642"
"13318","79.87200","6.65607","0.03562"
"13382","80.25600","6.68818","0.03680"
"13446","80.64000","6.72010","0.03607"
"13510","81.02400","6.75209","0.03571"
"13574","81.40800","6.78414","0.03703"
"13638","81.79200","6.81613","0.03723"
"13702","82.17600","6.84805","0.03737"
"13766","82.56000","6.88016","0.03696"
"13830","82.94400","6.91215","0.03749"
"13894","83.32800","6.94408","0.03809"
"13958","83.71200","6.97606","0.03834"
"14022","84.09600","7.00817","0.03910"
"14086","84.48000","7.04016","0.03964"
"14150","84.86400","7.07209","0.03931"
"14214","85.24800","7.10413","0.03987"
"14278","85.63200","7.13612","0.03996"
"14342","86.01600","7.16817","0.04037"
"14406","86.40000","7.20015","0.04043"
"14470","86.78400","7.23208","0.04121"
"14534","87.16800","7.26413","0.04102"
"14598","87.55200","7.29612","0.04233"
"14662","87.93600","7.32804","0.04242"
"14726","88.32000","7.36015","0.04360"
"14790","88.70400","7.39214","0.04286"
"14854","89.08800","7.42407","0.04351"
"14918","89.47200","7.45611","0.04201"
"14982","89.85600","7.48816","0.04223"
"15046","90.24000","7.52003","0.04252"
"15110","90.62400","7.55214","0.04333"
"15174","91.00800","7.58418","0.04346"
"15238","91.39200","7.61605","0.04389"
"15302","91.77600","7.64804","0.04407"
"15366","92.16000","7.68015","0.04423"
"15430","92.54400","7.71213","0.04461"
"15494","92.92800","7.74406","0.04565"
"15558","93.31200","7.77611","0.04492"
"15622","93.69600","7.80809","0.04670"
"15686","94.08000","7.84008","0.04651"
"15750","94.46400","7.87213","0.04687"
"15814","94.84800","7.90412","0.04771"
"15878","95.23200","7.93610","0.04793"
"15942","95.61600","7.96809","0.04808"
"16006","96.00000","8.00008","0.04823"
"16070","96.38400","8.03219","0.04908"
"16134","96.76800","8.06411","0.04937"
"16198","97.15200","8.09610","0.04953"
"16262","97.53600","8.12815","0.05019"
"16326","97.92000","8.16013","0.05043"
"16390","98.30400","8.19206","0.05036"
"16454","98.68800","8.22411","0.05159"
"16518","99.07200","8.25616","0.05166"
"16582","99.45600","8.28814","0.05162"
"16646","99.84000","8.32013","0.05226"
"16710","100.22400","8.35212","0.05317"
"16774","100.60800","8.38417","0.05334"
"16838","100.99200","8.41603","0.05370"
"16902","101.37600","8.44814","0.05466"
"16966","101.76000","8.48013","0.05463"
"17030","102.14400","8.51206","0.05544"
"17094","102.52800","8.54404","0.05498"
"17158","102.91200","8.57615","0.05436"
"17222","103.29600","8.60814","0.05464"
"17286","103.68000","8.64013","0.05307"
"17350","104.06400","8.67211","0.05387"
"17414","104.44800","8.70410","0.05507"
"17478","104.83200","8.73609","0.05488"
"17542","105.21600","8.76807","0.05538"
"17606","105.60000","8.80012","0.05642"
"17670","105.98400","8.83217","0.05663"
"17734","106.36800","8.86410","0.05642"
"17798","106.75200","8.89608","0.05735"
"17862","107.13600","8.92813","0.05793"
"17926","107.52000","8.96012","0.05729"
"17990","107.90400","8.99211","0.05701"
"18054","108.28800","9.02409","0.05303"
"18118","108.67200","9.05614","0.05183"
"18182","109.05600","9.08807","0.05071"
"18246","109.44000","9.12012","0.05090"
"18310","109.82400","9.15216","0.05050"
"18374","110.20800","9.18409","0.05190"
"18438","110.59200","9.21608","0.05269"
"18502","110.97600","9.24813","0.05265"
"18566","111.36000","9.28017","0.05163"
"18630","111.74400","9.31210","0.05144"
"18694","112.12800","9.34415","0.05215"
"18758","112.51200","9.37613","0.05236"
"18822","112.89600","9.40812","0.03738"
"18886","113.28000","9.44005","0.03800"
"18950","113.66400","9.47216","0.03885"
"19014","114.04800","9.50408","0.03918"
"19078","114.43200","9.53613","0.03934"
"19142","114.81600","9.56812","0.03945"
"19206","115.20000","9.60011","0.03934"
"19270","115.58400","9.63209","0.04037"
"19334","115.96800","9.66414","0.04091"
"19398","116.35200","9.69613","0.04142"
"19462","116.73600","9.72818","0.04160"
"19526","117.12000","9.76004","0.04191"
"19590","117.50400","9.79203","0.04290"
"19654","117.88800","9.82408","0.04287"
"19718","118.27200","9.85612","0.04387"
"19782","118.65600","9.88805","0.04292"
"19846","119.04000","9.92016","0.04448"
"19910","119.42400","9.95215","0.04439"
"19974","119.80800","9.98402","0.04494"
"20038","120.19200","10.01612","0.04544"
"20102","120.57600","10.04811","0.04598"
"20166","120.96000","10.08010","0.04627"
"20230","121.34400","10.11214","0.04663"
"20294","121.72800","10.14413","0.04686"
"20358","122.11200","10.17612","0.04770"
"20422","122.49600","10.20805","0.04845"
"20486","122.88000","10.24015","0.04906"
"20550","123.26400","10.27208","0.04951"
"20614","123.64800","10.30413","0.04951"
"20678","124.03200","10.33612","0.04988"
"20742","124.41600","10.36816","0.05088"
"20806","124.80000","10.40015","0.05117"
"20870","125.18400","10.43208","0.05175"
"20934","125.56800","10.46413","0.05190"
"20998","125.95200","10.49611","0.05292"
"21062","126.33600","10.52804","0.05325"
"21126","126.72000","10.56009","0.05381"
"21190","127.10400","10.59213","0.05401"
"21254","127.48800","10.62412","0.05447"
"21318","127.87200","10.65611","0.05552"
"21382","128.25600","10.68810","0.05539"
"21446","128.64000","10.72014","0.05613"
"21510","129.02400","10.75213","0.05590"
"21574","129.40800","10.78412","0.05668"
"21638","129.79200","10.81617","0.05734"
"21702","130.17600","10.84815","0.05778"
"21766","130.56000","10.88002","0.05851"
"21830","130.94400","10.91207","0.05832"
"21894","131.32800","10.94412","0.05916"
"21958","131.71200","10.97610","0.05918"
"22022","132.09600","11.00809","0.05958"
"22086","132.48000","11.04008","0.06057"
"22150","132.86400","11.07213","0.06094"
"22214","133.24800","11.10399","0.06099"
"22278","133.63200","11.13616","0.06163"
"22342","134.01600","11.16815","0.06192"
"22406","134.40000","11.20008","0.06227"
"22470","134.78400","11.23206","0.06242"
"22534","135.16800","11.26417","0.06299"
"22598","135.55200","11.29610","0.06354"
"22662","135.93600","11.32808","0.06371"
"22726","136.32000","11.36007","0.06434"
"22790","136.70400","11.39206","0.06420"
"22854","137.08800","11.42411","0.06420"
"22918","137.47200","11.45609","0.06468"
"22982","137.85600","11.48814","0.06534"
"23046","138.24000","11.52013","0.06550"
"23110","138.62400","11.55206","0.06596"
"23174","139.00800","11.58404","0.06583"
"23238","139.39200","11.61615","0.06567"
"23302","139.77600","11.64808","0.06674"
"23366","140.16000","11.68007","0.06664"
"23430","140.54400","11.71217","0.06715"
"23494","140.92800","11.74416","0.06701"
"23558","141.31200","11.77603","0.06744"
"23622","141.69600","11.80814","0.06783"
"23686","142.08000","11.84012","0.06800"
"23750","142.46400","11.87205","0.06786"
"23814","142.84800","11.90410","0.06831"
"23878","143.23200","11.93614","0.06857"
"23942","143.61600","11.96807","0.06879"
"24006","144.00000","12.00006","0.06900"
"24070","144.38400","12.03217","0.06922"
"24134","144.76800","12.06409","0.06936"
"24198","145.15200","12.09608","0.06970"
"24262","145.53600","12.12807","0.06987"
"24326","145.92000","12.16012","0.06971"
"24390","146.30400","12.19210","0.07042"
"24454","146.68800","12.22415","0.07074"
"24518","147.07200","12.25614","0.07062"
"24582","147.45600","12.28812","0.07105"
"24646","147.84000","12.32011","0.07172"
"24710","148.22400","12.35210","0.07146"
"24774","148.60800","12.38415","0.07215"
"24838","148.99200","12.41613","0.07253"
"24902","149.37600","12.44806","0.07292"
"24966","149.76000","12.48011","0.07322"
"25030","150.14400","12.51216","0.07225"
"25094","150.52800","12.54408","0.07230"
"25158","150.91200","12.57607","0.07299"
"25222","151.29600","12.60818","0.07351"
"25286","151.68000","12.64011","0.07373"
"25350","152.06400","12.67203","0.07473"
"25414","152.44800","12.70414","0.07520"
"25478","152.83200","12.73613","0.07588"
"25542","153.21600","12.76812","0.07641"
"25606","153.60000","12.80010","0.07674"
"25670","153.98400","12.83215","0.07769"
"25734","154.36800","12.86414","0.07818"
"25798","154.75200","12.89606","0.03942"
"25862","155.13600","12.92817","0.03973"
"25926","155.52000","12.96010","0.04111"
"25990","155.90400","12.99203","0.04059"
"26054","156.28800","13.02407","0.04088"
"26118","156.67200","13.05612","0.04178"
"26182","157.05600","13.08811","0.04287"
"26246","157.44000","13.12004","0.04383"
"26310","157.82400","13.15208","0.04423"
"26374","158.20800","13.18413","0.04419"
"26438","158.59200","13.21612","0.04533"
"26502","158.97600","13.24804","0.04552"
"26566","159.36000","13.28015","0.04552"
"26630","159.74400","13.31214","0.04648"
"26694","160.12800","13.34413","0.04651"
"26758","160.51200","13.37611","0.04673"
"26822","160.89600","13.40810","0.04783"
"26886","161.28000","13.44009","0.04784"
"26950","161.66400","13.47208","0.04785"
"27014","162.04800","13.50418","0.04872"
"27078","162.43200","13.53611","0.04941"
"27142","162.81600","13.56804","0.04907"
"27206","163.20000","13.60021","0.05012"
"27270","163.58400","13.63213","0.05019"
"27334","163.96800","13.66406","0.05066"
"27398","164.35200","13.69611","0.05153"
"27462","164.73600","13.72810","0.05146"
"27526","165.12000","13.76008","0.05110"
"27590","165.50400","13.79207","0.05175"
"27654","165.88800","13.82412","0.05301"
"27718","166.27200","13.85611","0.05355"
"27782","166.65600","13.88809","0.05363"
"27846","167.04000","13.92008","0.05416"
"27910","167.42400","13.95213","0.05415"
"27974","167.80800","13.98411","0.05509"
"28038","168.19200","14.01604","0.05509"
"28102","168.57600","14.04809","0.05437"
"28166","168.96000","14.08014","0.05480"
"28230","169.34400","14.11212","0.05591"
"28294","169.72800","14.14411","0.05620"
"28358","170.11200","14.17610","0.05655"
"28422","170.49600","14.20815","0.05689"
"28486","170.88000","14.24007","0.05746"
"28550","171.26400","14.27212","0.05789"
"28614","171.64800","14.30417","0.05789"
"28678","172.03200","14.33609","0.05822"
"28742","172.41600","14.36814","0.05810"
"28806","172.80000","14.40019","0.05927"
"28870","173.18400","14.43212","0.05997"
"28934","173.56800","14.46404","0.05970"
"28998","173.95200","14.49609","0.06058"
"29062","174.33600","14.52808","0.06053"
"29126","174.72000","14.56007","0.06018"
"29190","175.10400","14.59217","0.06122"
"29254","175.48800","14.62416","0.06103"
"29318","175.87200","14.65609","0.06112"
"29382","176.25600","14.68808","0.06164"
"29446","176.64000","14.72006","0.06188"
"29510","177.02400","14.75211","0.06249"
"29574","177.40800","14.78410","0.06121"
"29638","177.79200","14.81609","0.06126"
"29702","178.17600","14.84813","0.06154"
"29766","178.56000","14.88012","0.06206"
"29830","178.94400","14.91211","0.06258"
"29894","179.32800","14.94410","0.06275"
"29958","179.71200","14.97614","0.06240"
"30022","180.09600","15.00807","0.06223"
"30086","180.48000","15.04012","0.06240"
"30150","180.86400","15.07217","0.06325"
"30214","181.24800","15.10409","0.06365"
"30278","181.63200","15.13608","0.06342"
"30342","182.01600","15.16813","0.06352"
"30406","182.40000","15.20017","0.06353"
"30470","182.78400","15.23204","0.06423"
"30534","183.16800","15.26409","0.06178"
"30598","183.55200","15.29614","0.06259"
"30662","183.93600","15.32812","0.06361"
"30726","184.32000","15.36005","0.06401"
"30790","184.70400","15.39216","0.06375"
"30854","185.08800","15.42415","0.06461"
"30918","185.47200","15.45607","0.06462"
"30982","185.85600","15.48812","0.06477"
"31046","186.24000","15.52017","0.06460"
"31110","186.62400","15.55210","0.06462"
"31174","187.00800","15.58408","0.06497"
"31238","187.39200","15.61613","0.06592"
"31302","187.77600","15.64812","0.06585"
"31366","188.16000","15.68010","0.06615"
"31430","188.54400","15.71209","0.06687"
"31494","188.92800","15.74414","0.06698"
"31558","189.31200","15.77607","0.06707"
"31622","189.69600","15.80805","0.06728"
"31686","190.08000","15.84010","0.06736"
"31750","190.46400","15.87221","0.06747"
"31814","190.84800","15.90407","0.06815"
"31878","191.23200","15.93606","0.06835"
"31942","191.61600","15.96817","0.06852"
"32006","192.00000","16.00016","0.06899"
"32070","192.38400","16.03209","0.06932"
"32134","192.76800","16.06413","0.06934"
"32198","193.15200","16.09612","0.06931"
"32262","193.53600","16.12805","0.06969"
"32326","193.92000","16.16009","0.06999"
"32390","194.30400","16.19214","0.07053"
"32454","194.68800","16.22407","0.07060"
"32518","195.07200","16.25606","0.07071"
"32582","195.45600","16.28816","0.07098"
"32646","195.84000","16.32015","0.07128"
"32710","196.22400","16.35208","0.07186"
"32774","196.60800","16.38412","0.07209"
"32838","196.99200","16.41605","0.07247"
"32902","197.37600","16.44816","0.07279"
"32966","197.76000","16.48015","0.07333"
"33030","198.14400","16.51208","0.07374"
"33094","198.52800","16.54412","0.07420"
"33158","198.91200","16.57611","0.07538"
"33222","199.29600","16.60810","0.07643"
"33286","199.68000","16.64008","0.07763"
"33350","200.06400","16.67213","0.07864"
"33414","200.44800","16.70406","0.07925"
"33478","200.83200","16.73617","0.08041"
"33542","201.21600","16.76821","0.08202"
"33606","201.60000","16.80002","0.08240"
"33670","201.98400","16.83213","0.08421"
"33734","202.36800","16.86411","0.08516"
"33798","202.75200","16.89610","0.08596"
"33862","203.13600","16.92809","0.08612"
"33926","203.52000","16.96014","0.08658"
"33990","203.90400","16.99213","0.08718"
"34054","204.28800","17.02411","0.08840"
"34118","204.67200","17.05610","0.09005"
"34182","205.05600","17.08815","0.09128"
"34246","205.44000","17.12008","0.09134"
"34310","205.82400","17.15206","0.09242"
"34374","206.20800","17.18411","0.09384"
"34438","206.59200","17.21610","0.09499"
"34502","206.97600","17.24809","0.09627"
"34566","207.36000","17.28013","0.09807"
"34630","207.74400","17.31206","0.09920"
"34694","208.12800","17.34411","0.10047"
"34758","208.51200","17.37609","0.10123"
"34822","208.89600","17.40814","0.10173"
"34886","209.28000","17.44019","0.10267"
"34950","209.66400","17.47206","0.10223"
"35014","210.04800","17.50404","0.10259"
"35078","210.43200","17.53615","0.10353"
"35142","210.81600","17.56814","0.10497"
"35206","211.20000","17.60007","0.10540"
"35270","211.58400","17.63211","0.10715"
"35334","211.96800","17.66416","0.10796"
"35398","212.35200","17.69603","0.10798"
"35462","212.73600","17.72813","0.10862"
"35526","213.12000","17.76018","0.11042"
"35590","213.50400","17.79211","0.11084"
"35654","213.88800","17.82410","0.11158"
"35718","214.27200","17.85614","0.11334"
"35782","214.65600","17.88813","0.11521"
"35846","215.04000","17.92006","0.11447"
"35910","215.42400","17.95211","0.11620"
"35974","215.80800","17.98415","0.11696"
"36038","216.19200","18.01608","0.11802"
"36102","216.57600","18.04813","0.11913"
"36166","216.96000","18.08012","0.11960"
"36230","217.34400","18.11210","0.12027"
"36294","217.72800","18.14403","0.12076"
"36358","218.11200","18.17614","0.12111"
"36422","218.49600","18.20813","0.12108"
"36486","218.88000","18.24011","0.12104"
"36550","219.26400","18.27210","0.12111"
"36614","219.64800","18.30409","0.12111"
"36678","220.03200","18.33613","0.12144"
"36742","220.41600","18.36806","0.12193"
"36806","220.80000","18.40011","0.12249"
"36870","221.18400","18.43210","0.12314"
"36934","221.56800","18.46408","0.12359"
"36998","221.95200","18.49607","0.12500"
"37062","222.33600","18.52812","0.12661"
"37126","222.72000","18.56011","0.12861"
"37190","223.10400","18.59203","0.13065"
"37254","223.48800","18.62414","0.13247"
"37318","223.87200","18.65619","0.13080"
"37382","224.25600","18.68812","0.13218"
"37446","224.64000","18.72010","0.13296"
"37510","225.02400","18.75215","0.13407"
"37574","225.40800","18.78414","0.13534"
"37638","225.79200","18.81612","0.13762"
"37702","226.17600","18.84817","0.13996"
"37766","226.56000","18.88010","0.14186"
"37830","226.94400","18.91215","0.14481"
"37894","227.32800","18.94414","0.14678"
"37958","227.71200","18.97612","0.14806"
"38022","228.09600","19.00817","0.14981"
"38086","228.48000","19.04010","0.15203"
"38150","228.86400","19.07214","0.15289"
"38214","229.24800","19.10413","0.15400"
"38278","229.63200","19.13612","0.15521"
"38342","230.01600","19.16811","0.15651"
"38406","230.40000","19.20009","0.15756"
"38470","230.78400","19.23214","0.15848"
"38534","231.16800","19.26407","0.16000"
"38598","231.55200","19.29612","0.16087"
"38662","231.93600","19.32816","0.16098"
"38726","232.32000","19.36009","0.16201"
"38790","232.70400","19.39208","0.16389"
"38854","233.08800","19.42413","0.16574"
"38918","233.47200","19.45611","0.16746"
"38982","233.85600","19.48804","0.16825"
"39046","234.24000","19.52009","0.16912"
"39110","234.62400","19.55213","0.17047"
"39174","235.00800","19.58412","0.17185"
"39238","235.39200","19.61611","0.17279"
"39302","235.77600","19.64816","0.17428"
"39366","236.16000","19.68014","0.17593"
"39430","236.54400","19.71207","0.17726"
"39494","236.92800","19.74412","0.17909"
"39558","237.31200","19.77617","0.18191"
"39622","237.69600","19.80809","0.18372"
"39686","238.08000","19.84008","0.18676"
"39750","238.46400","19.87213","0.19030"
"39814","238.84800","19.90417","0.19231"
"39878","239.23200","19.93610","0.19302"
"39942","239.61600","19.96809","0.19247"
"40006","240.00000","20.00008","0.19678"
"40070","240.38400","20.03213","0.20104"
"40134","240.76800","20.06405","0.20127"
"40198","241.15200","20.09610","0.18814"
"40262","241.53600","20.12815","0.16845"
"40326","241.92000","20.16007","0.16259"
"40390","242.30400","20.19212","0.15793"
"40454","242.68800","20.22417","0.15974"
"40518","243.07200","20.25610","0.16101"
"40582","243.45600","20.28802","0.16275"
"40646","243.84000","20.32019","0.16481"
"40710","244.22400","20.35212","0.16612"
"40774","244.60800","20.38404","0.16809"
"40838","244.99200","20.41615","0.16936"
"40902","245.37600","20.44814","0.17095"
"40966","245.76000","20.48007","0.16987"
"41030","246.14400","20.51212","0.17185"
"41094","246.52800","20.54410","0.17253"
"41158","246.91200","20.57609","0.17401"
"41222","247.29600","20.60807","0.17588"
"41286","247.68000","20.64012","0.17838"
"41350","248.06400","20.67205","0.17885"
"41414","248.44800","20.70410","0.18037"
"41478","248.83200","20.73609","0.17583"
"41542","249.21600","20.76813","0.17850"
"41606","249.60000","20.80012","0.18266"
"41670","249.98400","20.83205","0.18609"
"41734","250.36800","20.86410","0.18954"
"41798","250.75200","20.89614","0.19288"
"41862","251.13600","20.92807","0.19875"
"41926","251.52000","20.96006","0.20398"
"41990","251.90400","20.99211","0.20869"
"42054","252.28800","21.02415","0.21481"
"42118","252.67200","21.05608","0.21979"
"42182","253.05600","21.08807","0.22255"
"42246","253.44000","21.12011","0.22335"
"42310","253.82400","21.15204","0.22453"
"42374","254.20800","21.18409","0.22619"
"42438","254.59200","21.21614","0.22738"
"42502","254.97600","21.24806","0.22898"
"42566","255.36000","21.28005","0.23241"
"42630","255.74400","21.31216","0.23613"
"42694","256.12800","21.34409","0.24054"
"42758","256.51200","21.37607","0.24507"
"42822","256.89600","21.40812","0.24839"
"42886","257.28000","21.44011","0.25183"
"42950","257.66400","21.47216","0.25614"
"43014","258.04800","21.50408","0.25993"
"43078","258.43200","21.53613","0.26345"
"43142","258.81600","21.56812","0.26596"
"43206","259.20000","21.60011","0.26799"
"43270","259.58400","21.63209","0.26912"
"43334","259.96800","21.66408","0.27016"
"43398","260.35200","21.69613","0.27086"
"43462","260.73600","21.72806","0.27167"
"43526","261.12000","21.76010","0.27232"
"43590","261.50400","21.79215","0.27351"
"43654","261.88800","21.82408","0.27466"
"43718","262.27200","21.85606","0.27587"
"43782","262.65600","21.88811","0.27723"
"43846","263.04000","21.92016","0.27899"
"43910","263.42400","21.95209","0.28052"
"43974","263.80800","21.98413","0.28508"
"44038","264.19200","22.01618","0.28890"
"44102","264.57600","22.04805","0.29349"
"44166","264.96000","22.08010","0.29768"
"44230","265.34400","22.11214","0.30125"
"44294","265.72800","22.14413","0.30629"
"44358","266.11200","22.17606","0.30895"
"44422","266.49600","22.20811","0.31267"
"44486","266.88000","22.24009","0.29685"
"44550","267.26400","22.27208","0.29941"
"44614","267.64800","22.30412","0.29958"
"44678","268.03200","22.33611","0.30388"
"44742","268.41600","22.36810","0.30846"
"44806","268.80000","22.40009","0.31289"
"44870","269.18400","22.43213","0.31419"
"44934","269.56800","22.46418","0.31687"
"44998","269.95200","22.49611","0.31867"
"45062","270.33600","22.52810","0.32033"
"45126","270.72000","22.56009","0.32231"
"45190","271.10400","22.59213","0.32561"
"45254","271.48800","22.62406","0.33237"
"45318","271.87200","22.65611","0.34059"
"45382","272.25600","22.68821","0.34967"
"45446","272.64000","22.72002","0.35760"
"45510","273.02400","22.75213","0.36376"
"45574","273.40800","22.78412","0.36805"
"45638","273.79200","22.81610","0.37115"
"45702","274.17600","22.84809","0.37426"
"45766","274.56000","22.88014","0.37670"
"45830","274.94400","22.91213","0.37868"
"45894","275.32800","22.94406","0.37977"
"45958","275.71200","22.97610","0.38088"
"46022","276.09600","23.00815","0.38262"
"46086","276.48000","23.04008","0.38409"
"46150","276.86400","23.07206","0.38617"
"46214","277.24800","23.10411","0.38797"
"46278","277.63200","23.13610","0.38136"
"46342","278.01600","23.16809","0.27322"
"46406","278.40000","23.20013","0.27305"
"46470","278.78400","23.23212","0.27784"
"46534","279.16800","23.26411","0.27859"
"46598","279.55200","23.29609","0.28946"
"46662","279.93600","23.32814","0.29720"
"46726","280.32000","23.36013","0.29981"
"46790","280.70400","23.39211","0.30904"
"46854","281.08800","23.42404","0.31254"
"46918","281.47200","23.45609","0.31858"
"46982","281.85600","23.48814","0.32274"
"47046","282.24000","23.52012","0.32318"
"47110","282.62400","23.55217","0.32898"
"47174","283.00800","23.58416","0.34195"
"47238","283.39200","23.61603","0.35189"
"47302","283.77600","23.64814","0.36051"
"47366","284.16000","23.68012","0.36565"
"47430","284.54400","23.71211","0.37021"
"47494","284.92800","23.74410","0.37419"
"47558","285.31200","23.77614","0.37604"
"47622","285.69600","23.80813","0.37680"
"47686","286.08000","23.84006","0.37851"
"47750","286.46400","23.87205","0.38026"
"47814","286.84800","23.90409","0.38061"
"47878","287.23200","23.93608","0.38213"
"47942","287.61600","23.96807","0.38505"
"48006","288.00000","24.00018","0.38564"
"48070","288.38400","24.03216","0.38679"
"48134","288.76800","24.06409","0.39057"
"48198","289.15200","24.09614","0.39322"
"48262","289.53600","24.12813","0.39486"
"48326","289.92000","24.16005","0.40103"
"48390","290.30400","24.19210","0.40589"
"48454","290.68800","24.22415","0.41161"
"48518","291.07200","24.25614","0.41956"
"48582","291.45600","24.28806","0.42313"
"48646","291.84000","24.32011","0.42427"
"48710","292.22400","24.35210","0.42784"
"48774","292.60800","24.38408","0.42953"
"48838","292.99200","24.41607","0.43085"
"48902","293.37600","24.44812","0.43597"
"48966","293.76000","24.48017","0.44131"
"49030","294.14400","24.51204","0.44508"
"49094","294.52800","24.54408","0.45186"
"49158","294.91200","24.57613","0.45551"
"49222","295.29600","24.60811","0.45825"
"49286","295.68000","24.64010","0.46284"
"49350","296.06400","24.67215","0.46390"
"49414","296.44800","24.70408","0.46624"
"49478","296.83200","24.73607","0.46768"
"49542","297.21600","24.76811","0.46901"
"49606","297.60000","24.80016","0.47147"
"49670","297.98400","24.83215","0.47397"
"49734","298.36800","24.86408","0.47970"
"49798","298.75200","24.89612","0.48311"
"49862","299.13600","24.92811","0.48669"
"49926","299.52000","24.96010","0.49194"
"49990","299.90400","24.99209","0.49094"
"50054","300.28800","25.02407","0.49613"
"50118","300.67200","25.05612","0.50289"
"50182","301.05600","25.08811","0.50761"
"50246","301.44000","25.12015","0.49117"
"50310","301.82400","25.15214","0.49754"
"50374","302.20800","25.18407","0.50603"
"50438","302.59200","25.21606","0.51161"
"50502","302.97600","25.24810","0.51479"
"50566","303.36000","25.28009","0.51946"
"50630","303.74400","25.31208","0.52272"
"50694","304.12800","25.34413","0.52729"
"50758","304.51200","25.37617","0.52805"
"50822","304.89600","25.40798","0.53014"
"50886","305.28000","25.44015","0.53155"
"50950","305.66400","25.47214","0.53533"
"51014","306.04800","25.50406","0.54052"
"51078","306.43200","25.53611","0.55009"
"51142","306.81600","25.56810","0.55818"
"51206","307.20000","25.60008","0.56228"
"51270","307.58400","25.63207","0.56803"
"51334","307.96800","25.66418","0.57290"
"51398","308.35200","25.69611","0.57725"
"51462","308.73600","25.72809","0.58086"
"51526","309.12000","25.76008","0.58381"
"51590","309.50400","25.79213","0.58522"
"51654","309.88800","25.82411","0.58780"
"51718","310.27200","25.85610","0.58893"
"51782","310.65600","25.88809","0.58926"
"51846","311.04000","25.92014","0.59080"
"51910","311.42400","25.95213","0.59234"
"51974","311.80800","25.98411","0.59478"
"52038","312.19200","26.01610","0.59772"
"52102","312.57600","26.04815","0.60355"
"52166","312.96000","26.08001","0.60950"
"52230","313.34400","26.11206","0.62003"
"52294","313.72800","26.14417","0.62687"
"52358","314.11200","26.17610","0.63222"
"52422","314.49600","26.20814","0.63593"
"52486","314.88000","26.24013","0.64118"
"52550","315.26400","26.27206","0.64880"
"52614","315.64800","26.30405","0.65778"
"52678","316.03200","26.33615","0.66462"
"52742","316.41600","26.36814","0.43390"
"52806","316.80000","26.40007","0.36982"
"52870","317.18400","26.43206","0.36371"
"52934","317.56800","26.46410","0.37681"
"52998","317.95200","26.49609","0.37798"
"53062","318.33600","26.52814","0.37977"
"53126","318.72000","26.56013","0.38070"
"53190","319.10400","26.59211","0.38648"
"53254","319.48800","26.62410","0.38867"
"53318","319.87200","26.65609","0.39297"
"53382","320.25600","26.68814","0.40151"
"53446","320.64000","26.72012","0.40037"
"53510","321.02400","26.75211","0.40137"
"53574","321.40800","26.78410","0.41532"
"53638","321.79200","26.81608","0.42518"
"53702","322.17600","26.84807","0.42652"
"53766","322.56000","26.88012","0.43226"
"53830","322.94400","26.91211","0.44218"
"53894","323.32800","26.94415","0.44497"
"53958","323.71200","26.97608","0.45492"
"54022","324.09600","27.00813","0.46072"
"54086","324.48000","27.04012","0.46308"
"54150","324.86400","27.07204","0.46721"
"54214","325.24800","27.10409","0.46755"
"54278","325.63200","27.13614","0.47077"
"54342","326.01600","27.16813","0.47639"
"54406","326.40000","27.20005","0.47840"
"54470","326.78400","27.23216","0.48656"
"54534","327.16800","27.26415","0.48554"
"54598","327.55200","27.29608","0.49242"
"54662","327.93600","27.32812","0.50080"
"54726","328.32000","27.36011","0.50612"
"54790","328.70400","27.39210","0.51534"
"54854","329.08800","27.42414","0.51799"
"54918","329.47200","27.45613","0.52521"
"54982","329.85600","27.48812","0.52741"
"55046","330.24000","27.52011","0.53005"
"55110","330.62400","27.55209","0.53418"
"55174","331.00800","27.58414","0.53924"
"55238","331.39200","27.61613","0.55027"
"55302","331.77600","27.64805","0.55489"
"55366","332.16000","27.68010","0.56518"
"55430","332.54400","27.71209","0.56885"
"55494","332.92800","27.74414","0.57497"
"55558","333.31200","27.77606","0.57746"
"55622","333.69600","27.80811","0.57975"
"55686","334.08000","27.84010","0.58273"
"55750","334.46400","27.87203","0.58811"
"55814","334.84800","27.90407","0.58971"
"55878","335.23200","27.93612","0.59202"
"55942","335.61600","27.96805","0.59308"
"56006","336.00000","28.00010","0.59652"
"56070","336.38400","28.03214","0.59720"
"56134","336.76800","28.06413","0.60195"
"56198","337.15200","28.09606","0.60793"
"56262","337.53600","28.12811","0.61850"
"56326","337.92000","28.16009","0.62670"
"56390","338.30400","28.19208","0.63141"
"56454","338.68800","28.22413","0.63457"
"56518","339.07200","28.25611","0.63958"
"56582","339.45600","28.28810","0.64943"
"56646","339.84000","28.32015","0.65668"
"56710","340.22400","28.35214","0.65852"
"56774","340.60800","28.38412","0.66117"
"56838","340.99200","28.41611","0.66465"
"56902","341.37600","28.44810","0.63416"
"56966","341.76000","28.48015","0.62255"
"57030","342.14400","28.51213","0.62914"
"57094","342.52800","28.54406","0.63171"
"57158","342.91200","28.57611","0.63685"
"57222","343.29600","28.60810","0.64210"
"57286","343.68000","28.64008","0.65072"
"57350","344.06400","28.67213","0.65426"
"57414","344.44800","28.70412","0.64630"
"57478","344.83200","28.73616","0.65608"
"57542","345.21600","28.76809","0.66349"
"57606","345.60000","28.80008","0.67048"
"57670","345.98400","28.83213","0.67551"
"57734","346.36800","28.86411","0.67798"
"57798","346.75200","28.89610","0.67928"
"57862","347.13600","28.92815","0.68022"
"57926","347.52000","28.96008","0.68197"
"57990","347.90400","28.99206","0.68484"
"58054","348.28800","29.02417","0.68843"
"58118","348.67200","29.05616","0.69039"
"58182","349.05600","29.08803","0.69535"
"58246","349.44000","29.12013","0.70426"
"58310","349.82400","29.15212","0.71167"
"58374","350.20800","29.18405","0.71856"
"58438","350.59200","29.21604","0.72292"
"58502","350.97600","29.24814","0.72986"
"58566","351.36000","29.28013","0.73305"
"58630","351.74400","29.31212","0.73889"
"58694","352.12800","29.34410","0.74023"
"58758","352.51200","29.37609","0.74140"
"58822","352.89600","29.40814","0.74515"
"58886","353.28000","29.44007","0.74843"
"58950","353.66400","29.47211","0.75738"
"59014","354.04800","29.50416","0.76557"
"59078","354.43200","29.53609","0.76737"
"59142","354.81600","29.56808","0.77590"
"59206","355.20000","29.60012","0.78055"
"59270","355.58400","29.63211","0.78537"
"59334","355.96800","29.66404","0.79019"
"59398","356.35200","29.69609","0.77758"
"59462","356.73600","29.72813","0.78464"
"59526","357.12000","29.76000","0.78967"
"59590","357.50400","29.79211","0.79293"
"59654","357.88800","29.82415","0.79455"
"59718","358.27200","29.85608","0.79886"
"59782","358.65600","29.88807","0.80440"
"59846","359.04000","29.92018","0.81185"
"59910","359.42400","29.95211","0.81888"
"59974","359.80800","29.98409","0.82372"
"60038","360.19200","30.01614","0.82831"
"60102","360.57600","30.04807","0.83112"
"60166","360.96000","30.08012","0.83379"
"60230","361.34400","30.11210","0.84116"
"60294","361.72800","30.14415","0.85343"
"60358","362.11200","30.17620","0.86534"
"60422","362.49600","30.20807","0.87426"
"60486","362.88000","30.24005","0.88349"
"60550","363.26400","30.27210","0.88880"
"60614","363.64800","30.30415","0.89050"
"60678","364.03200","30.33607","0.79970"
"60742","364.41600","30.36812","0.80359"
"60806","364.80000","30.40017","0.81045"
"60870","365.18400","30.43204","0.82099"
"60934","365.56800","30.46408","0.83050"
"60998","365.95200","30.49613","0.83574"
"61062","366.33600","30.52806","0.84483"
"61126","366.72000","30.56010","0.84382"
"61190","367.10400","30.59215","0.85677"
"61254","367.48800","30.62408","0.82397"
"61318","367.87200","30.65606","0.83003"
"61382","368.25600","30.68811","0.83011"
"61446","368.64000","30.72010","0.83358"
"61510","369.02400","30.75209","0.83952"
"61574","369.40800","30.78408","0.85271"
"61638","369.79200","30.81612","0.86710"
"61702","370.17600","30.84817","0.87876"
"61766","370.56000","30.88010","0.88747"
"61830","370.94400","30.91209","0.89175"
"61894","371.32800","30.94413","0.89336"
"61958","371.71200","30.97606","0.89507"
"62022","372.09600","31.00811","0.89825"
"62086","372.48000","31.04015","0.90168"
"62150","372.86400","31.07208","0.90572"
"62214","373.24800","31.10407","0.91228"
"62278","373.63200","31.13606","0.91976"
"62342","374.01600","31.16811","0.92740"
"62406","374.40000","31.20015","0.93533"
"62470","374.78400","31.23202","0.94225"
"62534","375.16800","31.26413","0.94661"
"62598","375.55200","31.29605","0.95129"
"62662","375.93600","31.32804","0.95846"
"62726","376.32000","31.36009","0.96579"
"62790","376.70400","31.39219","0.90566"
"62854","377.08800","31.42412","0.91047"
"62918","377.47200","31.45611","0.91697"
"62982","377.85600","31.48816","0.92476"
"63046","378.24000","31.52014","0.93363"
"63110","378.62400","31.55207","0.94076"
"63174","379.00800","31.58406","0.94516"
"63238","379.39200","31.61617","0.94994"
"63302","379.77600","31.64810","0.95933"
"63366","380.16000","31.68014","0.96690"
"63430","380.54400","31.71213","0.97298"
"63494","380.92800","31.74412","0.97774"
"63558","381.31200","31.77604","0.98142"
"63622","381.69600","31.80815","0.98414"
"63686","382.08000","31.84008","0.98642"
"63750","382.46400","31.87212","0.98712"
"63814","382.84800","31.90411","0.98911"
"63878","383.23200","31.93622","0.92550"
"63942","383.61600","31.96815","0.93007"
"64006","384.00000","32.00008","0.93534"
"64070","384.38400","32.03212","0.94108"
"64134","384.76800","32.06411","0.94491"
"64198","385.15200","32.09610","0.76860"
"64262","385.53600","32.12809","0.76368"
"64326","385.92000","32.16013","0.75565"
"64390","386.30400","32.19218","0.75864"
"64454","386.68800","32.22405","0.76236"
"64518","387.07200","32.25615","0.76120"
"64582","387.45600","32.28814","0.72672"
"64646","387.84000","32.32007","0.73328"
"64710","388.22400","32.35212","0.69645"
"64774","388.60800","32.38410","0.69848"
"64838","388.99200","32.41609","0.42761"
"64902","389.37600","32.44808","0.42094"
"64966","389.76000","32.48018","0.40815"
"65030","390.14400","32.51211","0.40372"
"65094","390.52800","32.54410","0.40118"
"65158","390.91200","32.57609","0.39807"
"65222","391.29600","32.60813","0.40084"
"65286","391.68000","32.64012","0.39976"
"65350","392.06400","32.67205","0.39957"
"65414","392.44800","32.70410","0.40549"
"65478","392.83200","32.73615","0.40677"
"65542","393.21600","32.76813","0.40848"
"65606","393.60000","32.80006","0.41715"
"65670","393.98400","32.83210","0.41971"
"65734","394.36800","32.86409","0.42376"
"65798","394.75200","32.89608","0.42721"
"65862","395.13600","32.92813","0.42953"
"65926","395.52000","32.96012","0.43112"
"65990","395.90400","32.99210","0.43744"
"66054","396.28800","33.02409","0.44405"
"66118","396.67200","33.05614","0.44792"
"66182","397.05600","33.08813","0.45247"
"66246","397.44000","33.12005","0.45519"
"66310","397.82400","33.15210","0.45906"
"66374","398.20800","33.18409","0.46357"
"66438","398.59200","33.21608","0.46367"
"66502","398.97600","33.24806","0.46587"
"66566","399.36000","33.28011","0.46758"
"66630","399.74400","33.31210","0.46657"
"66694","400.12800","33.34402","0.46894"
"66758","400.51200","33.37619","0.47261"
"66822","400.89600","33.40812","0.47566"
"66886","401.28000","33.44004","0.48167"
"66950","401.66400","33.47210","0.48371"
"67014","402.04800","33.50414","0.48885"
"67078","402.43200","33.53613","0.49366"
"67142","402.81600","33.56812","0.49807"
"67206","403.20000","33.60010","0.50500"
"67270","403.58400","33.63215","0.50597"
"67334","403.96800","33.66408","0.51085"
"67398","404.35200","33.69607","0.51496"
"67462","404.73600","33.72811","0.51831"
"67526","405.12000","33.76016","0.52330"
"67590","405.50400","33.79209","0.52616"
"67654","405.88800","33.82407","0.52832"
"67718","406.27200","33.85612","0.52961"
"67782","406.65600","33.88811","0.53211"
"67846","407.04000","33.92004","0.53708"
"67910","407.42400","33.95214","0.54357"
"67974","407.80800","33.98413","0.55142"
"68038","408.19200","34.01606","0.55712"
"68102","408.57600","34.04816","0.56243"
"68166","408.96000","34.08015","0.56599"
"68230","409.34400","34.11202","0.57040"
"68294","409.72800","34.14413","0.57341"
"68358","410.11200","34.17617","0.57731"
"68422","410.49600","34.20810","0.57918"
"68486","410.88000","34.24009","0.58141"
"68550","411.26400","34.27214","0.58277"
"68614","411.64800","34.30412","0.58608"
"68678","412.03200","34.33611","0.58820"
"68742","412.41600","34.36816","0.59037"
"68806","412.80000","34.40015","0.59161"
"68870","413.18400","34.43214","0.59325"
"68934","413.56800","34.46412","0.59567"
"68998","413.95200","34.49611","0.59857"
"69062","414.33600","34.52816","0.60241"
"69126","414.72000","34.56009","0.60654"
"69190","415.10400","34.59213","0.60812"
"69254","415.48800","34.62418","0.61752"
"69318","415.87200","34.65617","0.62447"
"69382","416.25600","34.68803","0.62892"
"69446","416.64000","34.72008","0.63077"
"69510","417.02400","34.75219","0.63436"
"69574","417.40800","34.78406","0.57156"
"69638","417.79200","34.81610","0.58077"
"69702","418.17600","34.84815","0.58078"
"69766","418.56000","34.88008","0.58228"
"69830","418.94400","34.91206","0.58324"
"69894","419.32800","34.94411","0.58541"
"69958","419.71200","34.97610","0.58590"
"70022","420.09600","35.00809","0.58756"
"70086","420.48000","35.04013","0.58891"
"70150","420.86400","35.07212","0.59004"
"70214","421.24800","35.10411","0.59026"
"70278","421.63200","35.13610","0.59127"
"70342","422.01600","35.16809","0.59214"
"70406","422.40000","35.20013","0.59309"
"70470","422.78400","35.23212","0.59407"
"70534","423.16800","35.26410","0.59525"
"70598","423.55200","35.29615","0.59629"
"70662","423.93600","35.32808","0.59798"
"70726","424.32000","35.36007","0.59938"
"70790","424.70400","35.39212","0.49023"
"70854","425.08800","35.42416","0.48478"
"70918","425.47200","35.45609","0.49565"
"70982","425.85600","35.48808","0.49537"
"71046","426.24000","35.52013","0.49454"
"71110","426.62400","35.55211","0.50599"
"71174","427.00800","35.58404","0.51092"
"71238","427.39200","35.61615","0.51036"
"71302","427.77600","35.64813","0.51303"
"71366","428.16000","35.68006","0.51928"
"71430","428.54400","35.71211","0.52095"
"71494","428.92800","35.74416","0.52278"
"71558","429.31200","35.77608","0.52607"
"71622","429.69600","35.80801","0.52770"
"71686","430.08000","35.84018","0.52850"
"71750","430.46400","35.87217","0.52895"
"71814","430.84800","35.90409","0.53012"
"71878","431.23200","35.93614","0.53119"
"71942","431.61600","35.96807","0.53372"
"72006","432.00000","36.00011","0.53514"
"72070","432.38400","36.03210","0.54046"
"72134","432.76800","36.06415","0.54606"
"72198","433.15200","36.09614","0.55169"
"72262","433.53600","36.12812","0.55620"
"72326","433.92000","36.16011","0.55988"
"72390","434.30400","36.19210","0.56430"
"72454","434.68800","36.22409","0.56840"
"72518","435.07200","36.25607","0.57254"
"72582","435.45600","36.28812","0.57542"
"72646","435.84000","36.32011","0.05201"
"72710","436.22400","36.35204","0.10231"
"72774","436.60800","36.38408","0.00467"
"72838","436.99200","36.41613","0.06359"
"72902","437.37600","36.44812","0.00805"
"72966","437.76000","36.48005","0.01939"
"73030","438.14400","36.51209","0.01136"
"73094","438.52800","36.54414","0.03256"
"73158","438.91200","36.57601","0.03065"
"73222","439.29600","36.60812","0.01449"
"73286","439.68000","36.64010","0.03884"
"73350","440.06400","36.67209","0.01703"
"73414","440.44800","36.70408","0.01859"
"73478","440.83200","36.73612","0.03248"
"73542","441.21600","36.76811","0.02147"
"73606","441.60000","36.80004","0.02111"
"73670","441.98400","36.83215","0.03232"
"73734","442.36800","36.86407","0.02575"
"73798","442.75200","36.89612","0.02355"
"73862","443.13600","36.92811","0.03191"
"73926","443.52000","36.96016","0.02887"
"73990","443.90400","36.99215","0.02580"
"74054","444.28800","37.02413","0.03174"
"74118","444.67200","37.05606","0.03217"
"74182","445.05600","37.08810","0.02832"
"74246","445.44000","37.12015","0.03214"
"74310","445.82400","37.15208","0.03398"
"74374","446.20800","37.18419","0.03155"
"74438","446.59200","37.21618","0.03263"
"74502","446.97600","37.24804","0.03585"
"74566","447.36000","37.28009","0.03421"
"74630","447.74400","37.31208","0.03461"
"74694","448.12800","37.34406","0.03624"
"74758","448.51200","37.37611","0.03614"
"74822","448.89600","37.40816","0.03629"
"74886","449.28000","37.44009","0.03799"
"74950","449.66400","37.47201","0.03818"
"75014","450.04800","37.50412","0.03812"
"75078","450.43200","37.53611","0.03885"
"75142","450.81600","37.56810","0.03966"
"75206","451.20000","37.60002","0.03971"
"75270","451.58400","37.63213","0.04021"
"75334","451.96800","37.66412","0.04197"
"75398","452.35200","37.69604","0.04203"
"75462","452.73600","37.72809","0.04203"
"75526","453.12000","37.76008","0.04362"
"75590","453.50400","37.79213","0.04386"
"75654","453.88800","37.82411","0.04418"
"75718","454.27200","37.85610","0.04537"
"75782","454.65600","37.88815","0.04615"
"75846","455.04000","37.92008","0.04680"
"75910","455.42400","37.95213","0.04747"
"75974","455.80800","37.98411","0.04860"
"76038","456.19200","38.01616","0.04901"
"76102","456.57600","38.04815","0.04988"
"76166","456.96000","38.08014","0.05148"
"76230","457.34400","38.11218","0.05180"
"76294","457.72800","38.14405","0.05322"
"76358","458.11200","38.17604","0.05315"
"76422","458.49600","38.20814","0.05432"
"76486","458.88000","38.24013","0.05526"
"76550","459.26400","38.27212","0.05602"
"76614","459.64800","38.30410","0.05758"
"76678","460.03200","38.33609","0.05803"
"76742","460.41600","38.36808","0.05865"
"76806","460.80000","38.40013","0.05838"
"76870","461.18400","38.43211","0.05888"
"76934","461.56800","38.46410","0.05885"
"76998","461.95200","38.49609","0.05930"
"77062","462.33600","38.52814","0.06006"
"77126","462.72000","38.56012","0.06072"
"77190","463.10400","38.59205","0.06062"
"77254","463.48800","38.62416","0.06180"
"77318","463.87200","38.65609","0.06276"
"77382","464.25600","38.68808","0.06330"
"77446","464.64000","38.72012","0.06369"
"77510","465.02400","38.75211","0.06424"
"77574","465.40800","38.78415","0.06473"
"77638","465.79200","38.81608","0.06562"
"77702","466.17600","38.84807","0.06570"
"77766","466.56000","38.88012","0.06604"
"77830","466.94400","38.91211","0.06693"
"77894","467.32800","38.94409","0.06682"
"77958","467.71200","38.97614","0.06740"
"78022","468.09600","39.00813","0.06756"
"78086","468.48000","39.04005","0.06822"
"78150","468.86400","39.07215","0.06860"
"78214","469.24800","39.10421","0.06892"
"78278","469.63200","39.13607","0.06939"
"78342","470.01600","39.16806","0.06999"
"78406","470.40000","39.20011","0.06997"
"78449","470.65800","39.22152","0.07063"