File: Trajectories_together/170108_2Specimen_RawData_4.csv
"","V1","V2","V3"
"1","End date","1/8/2017",""
"2","Specimen label","13DG_7",""
"3","Maximum Load","0.06960","N"
"4","Time","Extension","Load"
"5","(s)","(mm)","(N)"
"6","0.00000","0.00000","-0.00019"
"72","0.39600","0.03324","-0.00013"
"138","0.79200","0.06631","0.00014"
"204","1.18800","0.09925","0.00043"
"270","1.58400","0.13225","0.00009"
"336","1.98000","0.16526","0.00021"
"402","2.37600","0.19820","0.00094"
"468","2.77200","0.23121","0.00127"
"534","3.16800","0.26421","0.00139"
"600","3.56400","0.29721","0.00103"
"666","3.96000","0.33016","0.00123"
"732","4.35600","0.36322","0.00103"
"798","4.75200","0.39623","0.00121"
"864","5.14800","0.42923","0.00113"
"930","5.54400","0.46217","0.00123"
"996","5.94000","0.49524","0.00197"
"1062","6.33600","0.52824","0.00141"
"1128","6.73200","0.56118","0.00168"
"1194","7.12800","0.59413","0.00186"
"1260","7.52400","0.62725","0.00211"
"1326","7.92000","0.66026","0.00216"
"1392","8.31600","0.69320","0.00176"
"1458","8.71200","0.72614","0.00228"
"1524","9.10800","0.75927","0.00225"
"1590","9.50400","0.79227","0.00247"
"1656","9.90000","0.82516","0.00217"
"1722","10.29600","0.85822","0.00246"
"1788","10.69200","0.89122","0.00276"
"1854","11.08800","0.92429","0.00241"
"1920","11.48400","0.95717","0.00225"
"1986","11.88000","0.99017","0.00239"
"2052","12.27600","1.02324","0.00255"
"2118","12.67200","1.05630","0.00261"
"2184","13.06800","1.08913","0.00276"
"2250","13.46400","1.12225","0.00247"
"2316","13.86000","1.15525","0.00260"
"2382","14.25600","1.18826","0.00286"
"2448","14.65200","1.22120","0.00240"
"2514","15.04800","1.25420","0.00242"
"2580","15.44400","1.28721","0.00253"
"2646","15.84000","1.32021","0.00262"
"2712","16.23600","1.35316","0.00208"
"2778","16.63200","1.38622","0.00269"
"2844","17.02800","1.41922","0.00278"
"2910","17.42400","1.45217","0.00269"
"2976","17.82000","1.48517","0.00244"
"3042","18.21600","1.51818","0.00289"
"3108","18.61200","1.55124","0.00269"
"3174","19.00800","1.58424","0.00304"
"3240","19.40400","1.61725","0.00267"
"3306","19.80000","1.65025","0.00268"
"3372","20.19600","1.68325","0.00313"
"3438","20.59200","1.71620","0.00300"
"3504","20.98800","1.74926","0.00285"
"3570","21.38400","1.78227","0.00323"
"3636","21.78000","1.81521","0.00291"
"3702","22.17600","1.84821","0.00314"
"3768","22.57200","1.88128","0.00298"
"3834","22.96800","1.91422","0.00302"
"3900","23.36400","1.94717","0.00308"
"3966","23.76000","1.98017","0.00302"
"4032","24.15600","2.01329","0.00295"
"4098","24.55200","2.04624","0.00342"
"4164","24.94800","2.07918","0.00321"
"4230","25.34400","2.11219","0.00307"
"4296","25.74000","2.14525","0.00256"
"4362","26.13600","2.17825","0.00248"
"4428","26.53200","2.21114","0.00205"
"4494","26.92800","2.24420","0.00278"
"4560","27.32400","2.27726","0.00211"
"4626","27.72000","2.31021","0.00256"
"4692","28.11600","2.34315","0.00249"
"4758","28.51200","2.37622","0.00283"
"4824","28.90800","2.40922","0.00184"
"4890","29.30400","2.44222","0.00216"
"4956","29.70000","2.47523","0.00250"
"5022","30.09600","2.50823","0.00223"
"5088","30.49200","2.54123","0.00206"
"5154","30.88800","2.57424","0.00232"
"5220","31.28400","2.60718","0.00180"
"5286","31.68000","2.64025","0.00168"
"5352","32.07600","2.67325","0.00208"
"5418","32.47200","2.70625","0.00225"
"5484","32.86800","2.73920","0.00176"
"5550","33.26400","2.77226","0.00254"
"5616","33.66000","2.80521","0.00259"
"5682","34.05600","2.83821","0.00212"
"5748","34.45200","2.87121","0.00245"
"5814","34.84800","2.90422","0.00264"
"5880","35.24400","2.93722","0.00257"
"5946","35.64000","2.97022","0.00274"
"6012","36.03600","3.00323","0.00300"
"6078","36.43200","3.03617","0.00317"
"6144","36.82800","3.06924","0.00287"
"6210","37.22400","3.10224","0.00293"
"6276","37.62000","3.13524","0.00293"
"6342","38.01600","3.16819","0.00288"
"6408","38.41200","3.20119","0.00286"
"6474","38.80800","3.23419","0.00288"
"6540","39.20400","3.26732","0.00281"
"6606","39.60000","3.30026","0.00303"
"6672","39.99600","3.33315","0.00330"
"6738","40.39200","3.36621","0.00311"
"6804","40.78800","3.39921","0.00326"
"6870","41.18400","3.43222","0.00356"
"6936","41.58000","3.46516","0.00294"
"7002","41.97600","3.49823","0.00337"
"7068","42.37200","3.53129","0.00339"
"7134","42.76800","3.56423","0.00299"
"7200","43.16400","3.59712","0.00355"
"7266","43.56000","3.63024","0.00365"
"7332","43.95600","3.66325","0.00330"
"7398","44.35200","3.69619","0.00325"
"7464","44.74800","3.72925","0.00330"
"7530","45.14400","3.76220","0.00356"
"7596","45.54000","3.79532","0.00353"
"7662","45.93600","3.82820","0.00348"
"7728","46.33200","3.86115","0.00395"
"7794","46.72800","3.89421","0.00307"
"7860","47.12400","3.92728","0.00389"
"7926","47.52000","3.96022","0.00370"
"7992","47.91600","3.99316","0.00422"
"8058","48.31200","4.02623","0.00417"
"8124","48.70800","4.05923","0.00407"
"8190","49.10400","4.09223","0.00396"
"8256","49.50000","4.12518","0.00374"
"8322","49.89600","4.15824","0.00373"
"8388","50.29200","4.19125","0.00367"
"8454","50.68800","4.22419","0.00411"
"8520","51.08400","4.25725","0.00408"
"8586","51.48000","4.29020","0.00366"
"8652","51.87600","4.32326","0.00455"
"8718","52.27200","4.35627","0.00454"
"8784","52.66800","4.38921","0.00441"
"8850","53.06400","4.42221","0.00474"
"8916","53.46000","4.45522","0.00459"
"8982","53.85600","4.48816","0.00448"
"9048","54.25200","4.52122","0.00472"
"9114","54.64800","4.55423","0.00445"
"9180","55.04400","4.58723","0.00431"
"9246","55.44000","4.62024","0.00501"
"9312","55.83600","4.65318","0.00446"
"9378","56.23200","4.68624","0.00448"
"9444","56.62800","4.71919","0.00449"
"9510","57.02400","4.75225","0.00458"
"9576","57.42000","4.78526","0.00500"
"9642","57.81600","4.81826","0.00470"
"9708","58.21200","4.85120","0.00493"
"9774","58.60800","4.88433","0.00422"
"9840","59.00400","4.91727","0.00449"
"9906","59.40000","4.95015","0.00451"
"9972","59.79600","4.98322","0.00520"
"10038","60.19200","5.01628","0.00482"
"10104","60.58800","5.04929","0.00433"
"10170","60.98400","5.08217","0.00465"
"10236","61.38000","5.11523","0.00489"
"10302","61.77600","5.14824","0.00476"
"10368","62.17200","5.18130","0.00482"
"10434","62.56800","5.21413","0.00482"
"10500","62.96400","5.24719","0.00487"
"10566","63.36000","5.28025","0.00480"
"10632","63.75600","5.31326","0.00493"
"10698","64.15200","5.34614","0.00469"
"10764","64.54800","5.37920","0.00517"
"10830","64.94400","5.41227","0.00491"
"10896","65.34000","5.44521","0.00417"
"10962","65.73600","5.47822","0.00448"
"11028","66.13200","5.51122","0.00431"
"11094","66.52800","5.54422","0.00477"
"11160","66.92400","5.57723","0.00502"
"11226","67.32000","5.61017","0.00434"
"11292","67.71600","5.64324","0.00479"
"11358","68.11200","5.67624","0.00432"
"11424","68.50800","5.70924","0.00468"
"11490","68.90400","5.74219","0.00434"
"11556","69.30000","5.77525","0.00452"
"11622","69.69600","5.80825","0.00497"
"11688","70.09200","5.84126","0.00441"
"11754","70.48800","5.87426","0.00415"
"11820","70.88400","5.90721","0.00441"
"11886","71.28000","5.94027","0.00440"
"11952","71.67600","5.97321","0.00419"
"12018","72.07200","6.00628","0.00433"
"12084","72.46800","6.03922","0.00478"
"12150","72.86400","6.07223","0.00433"
"12216","73.26000","6.10517","0.00467"
"12282","73.65600","6.13829","0.00506"
"12348","74.05200","6.17124","0.00492"
"12414","74.44800","6.20418","0.00480"
"12480","74.84400","6.23724","0.00495"
"12546","75.24000","6.27025","0.00503"
"12612","75.63600","6.30325","0.00507"
"12678","76.03200","6.33614","0.00560"
"12744","76.42800","6.36920","0.00533"
"12810","76.82400","6.40226","0.00502"
"12876","77.22000","6.43521","0.00544"
"12942","77.61600","6.46815","0.00526"
"13008","78.01200","6.50121","0.00524"
"13074","78.40800","6.53422","0.00528"
"13140","78.80400","6.56722","0.00548"
"13206","79.20000","6.60017","0.00528"
"13272","79.59600","6.63317","0.00541"
"13338","79.99200","6.66629","0.00519"
"13404","80.38800","6.69924","0.00535"
"13470","80.78400","6.73218","0.00586"
"13536","81.18000","6.76525","0.00594"
"13602","81.57600","6.79825","0.00638"
"13668","81.97200","6.83119","0.00613"
"13734","82.36800","6.86420","0.00607"
"13800","82.76400","6.89726","0.00646"
"13866","83.16000","6.93026","0.00662"
"13932","83.55600","6.96321","0.00586"
"13998","83.95200","6.99621","0.00602"
"14064","84.34800","7.02928","0.00678"
"14130","84.74400","7.06222","0.00630"
"14196","85.14000","7.09516","0.00674"
"14262","85.53600","7.12823","0.00705"
"14328","85.93200","7.16117","0.00644"
"14394","86.32800","7.19424","0.00665"
"14460","86.72400","7.22718","0.00643"
"14526","87.12000","7.26024","0.00690"
"14592","87.51600","7.29325","0.00616"
"14658","87.91200","7.32619","0.00688"
"14724","88.30800","7.35919","0.00676"
"14790","88.70400","7.39226","0.00731"
"14856","89.10000","7.42520","0.00742"
"14922","89.49600","7.45821","0.00709"
"14988","89.89200","7.49121","0.00766"
"15054","90.28800","7.52427","0.00689"
"15120","90.68400","7.55728","0.00621"
"15186","91.08000","7.59016","0.00672"
"15252","91.47600","7.62323","0.00658"
"15318","91.87200","7.65629","0.00555"
"15384","92.26800","7.68917","0.00603"
"15450","92.66400","7.72218","0.00657"
"15516","93.06000","7.75524","0.00585"
"15582","93.45600","7.78824","0.00544"
"15648","93.85200","7.82125","0.00560"
"15714","94.24800","7.85419","0.00621"
"15780","94.64400","7.88726","0.00618"
"15846","95.04000","7.92032","0.00620"
"15912","95.43600","7.95320","0.00623"
"15978","95.83200","7.98621","0.00613"
"16044","96.22800","8.01927","0.00584"
"16110","96.62400","8.05233","0.00567"
"16176","97.02000","8.08516","0.00606"
"16242","97.41600","8.11822","0.00629"
"16308","97.81200","8.15123","0.00629"
"16374","98.20800","8.18429","0.00611"
"16440","98.60400","8.21717","0.00594"
"16506","99.00000","8.25018","0.00627"
"16572","99.39600","8.28318","0.00667"
"16638","99.79200","8.31625","0.00646"
"16704","100.18800","8.34919","0.00632"
"16770","100.58400","8.38219","0.00651"
"16836","100.98000","8.41526","0.00662"
"16902","101.37600","8.44820","0.00643"
"16968","101.77200","8.48120","0.00705"
"17034","102.16800","8.51421","0.00676"
"17100","102.56400","8.54721","0.00696"
"17166","102.96000","8.58022","0.00740"
"17232","103.35600","8.61322","0.00709"
"17298","103.75200","8.64622","0.00711"
"17364","104.14800","8.67917","0.00681"
"17430","104.54400","8.71217","0.00701"
"17496","104.94000","8.74524","0.00672"
"17562","105.33600","8.77824","0.00726"
"17628","105.73200","8.81118","0.00734"
"17694","106.12800","8.84419","0.00784"
"17760","106.52400","8.87725","0.00691"
"17826","106.92000","8.91025","0.00719"
"17892","107.31600","8.94320","0.00746"
"17958","107.71200","8.97620","0.00673"
"18024","108.10800","9.00927","0.00747"
"18090","108.50400","9.04227","0.00755"
"18156","108.90000","9.07515","0.00739"
"18222","109.29600","9.10822","0.00797"
"18288","109.69200","9.14128","0.00749"
"18354","110.08800","9.17423","0.00814"
"18420","110.48400","9.20717","0.00754"
"18486","110.88000","9.24017","0.00802"
"18552","111.27600","9.27330","0.00821"
"18618","111.67200","9.30624","0.00804"
"18684","112.06800","9.33912","0.00804"
"18750","112.46400","9.37225","0.00858"
"18816","112.86000","9.40525","0.00890"
"18882","113.25600","9.43820","0.00886"
"18948","113.65200","9.47120","0.00914"
"19014","114.04800","9.50420","0.00879"
"19080","114.44400","9.53727","0.00871"
"19146","114.84000","9.57021","0.00874"
"19212","115.23600","9.60316","0.00926"
"19278","115.63200","9.63622","0.00916"
"19344","116.02800","9.66928","0.00973"
"19410","116.42400","9.70223","0.00882"
"19476","116.82000","9.73517","0.00925"
"19542","117.21600","9.76823","0.00981"
"19608","117.61200","9.80130","0.00933"
"19674","118.00800","9.83418","0.01070"
"19740","118.40400","9.86719","0.00991"
"19806","118.80000","9.90025","0.00986"
"19872","119.19600","9.93325","0.00977"
"19938","119.59200","9.96620","0.01025"
"20004","119.98800","9.99926","0.01021"
"20070","120.38400","10.03221","0.01027"
"20136","120.78000","10.06527","0.01094"
"20202","121.17600","10.09821","0.01113"
"20268","121.57200","10.13122","0.01003"
"20334","121.96800","10.16416","0.01065"
"20400","122.36400","10.19722","0.01030"
"20466","122.76000","10.23017","0.00954"
"20532","123.15600","10.26323","0.01074"
"20598","123.55200","10.29624","0.01135"
"20664","123.94800","10.32918","0.01099"
"20730","124.34400","10.36218","0.01125"
"20796","124.74000","10.39525","0.01105"
"20862","125.13600","10.42825","0.01159"
"20928","125.53200","10.46114","0.01180"
"20994","125.92800","10.49426","0.01132"
"21060","126.32400","10.52726","0.01196"
"21126","126.72000","10.56021","0.01173"
"21192","127.11600","10.59315","0.01216"
"21258","127.51200","10.62621","0.01189"
"21324","127.90800","10.65922","0.01199"
"21390","128.30400","10.69216","0.01257"
"21456","128.70000","10.72517","0.01257"
"21522","129.09600","10.75823","0.01238"
"21588","129.49200","10.79123","0.01233"
"21654","129.88800","10.82418","0.01389"
"21720","130.28400","10.85718","0.01347"
"21786","130.68000","10.89024","0.01331"
"21852","131.07600","10.92325","0.01306"
"21918","131.47200","10.95619","0.01365"
"21984","131.86800","10.98920","0.01410"
"22050","132.26400","11.02226","0.01449"
"22116","132.66000","11.05526","0.01403"
"22182","133.05600","11.08821","0.01437"
"22248","133.45200","11.12121","0.01414"
"22314","133.84800","11.15427","0.01432"
"22380","134.24400","11.18722","0.01391"
"22446","134.64000","11.22022","0.01385"
"22512","135.03600","11.25323","0.01481"
"22578","135.43200","11.28623","0.01440"
"22644","135.82800","11.31917","0.01480"
"22710","136.22400","11.35218","0.01552"
"22776","136.62000","11.38524","0.01539"
"22842","137.01600","11.41825","0.01562"
"22908","137.41200","11.45119","0.01559"
"22974","137.80800","11.48419","0.01550"
"23040","138.20400","11.51726","0.01547"
"23106","138.60000","11.55026","0.01638"
"23172","138.99600","11.58321","0.01640"
"23238","139.39200","11.61627","0.01639"
"23304","139.78800","11.64921","0.01617"
"23370","140.18400","11.68222","0.01641"
"23436","140.58000","11.71516","0.01734"
"23502","140.97600","11.74816","0.01775"
"23568","141.37200","11.78123","0.01710"
"23634","141.76800","11.81429","0.01737"
"23700","142.16400","11.84712","0.01734"
"23766","142.56000","11.88024","0.01766"
"23832","142.95600","11.91324","0.01774"
"23898","143.35200","11.94619","0.01795"
"23964","143.74800","11.97919","0.01775"
"24030","144.14400","12.01225","0.01801"
"24096","144.54000","12.04526","0.01770"
"24162","144.93600","12.07820","0.01781"
"24228","145.33200","12.11121","0.01855"
"24294","145.72800","12.14427","0.01815"
"24360","146.12400","12.17727","0.01911"
"24426","146.52000","12.21016","0.01916"
"24492","146.91600","12.24322","0.01892"
"24558","147.31200","12.27623","0.01901"
"24624","147.70800","12.30929","0.01826"
"24690","148.10400","12.34217","0.01909"
"24756","148.50000","12.37518","0.01929"
"24822","148.89600","12.40818","0.01908"
"24888","149.29200","12.44125","0.01935"
"24954","149.68800","12.47419","0.01998"
"25020","150.08400","12.50719","0.02031"
"25086","150.48000","12.54026","0.01918"
"25152","150.87600","12.57320","0.01935"
"25218","151.27200","12.60620","0.01963"
"25284","151.66800","12.63921","0.02023"
"25350","152.06400","12.67227","0.02038"
"25416","152.46000","12.70522","0.02055"
"25482","152.85600","12.73822","0.01983"
"25548","153.25200","12.77128","0.01991"
"25614","153.64800","12.80423","0.02037"
"25680","154.04400","12.83717","0.02066"
"25746","154.44000","12.87024","0.02051"
"25812","154.83600","12.90324","0.02027"
"25878","155.23200","12.93624","0.02034"
"25944","155.62800","12.96919","0.02049"
"26010","156.02400","13.00225","0.02013"
"26076","156.42000","13.03525","0.02075"
"26142","156.81600","13.06820","0.02098"
"26208","157.21200","13.10114","0.02095"
"26274","157.60800","13.13426","0.02099"
"26340","158.00400","13.16721","0.01969"
"26406","158.40000","13.20021","0.02048"
"26472","158.79600","13.23322","0.02053"
"26538","159.19200","13.26628","0.02093"
"26604","159.58800","13.29923","0.02114"
"26670","159.98400","13.33217","0.02109"
"26736","160.38000","13.36523","0.02146"
"26802","160.77600","13.39824","0.02093"
"26868","161.17200","13.43124","0.02052"
"26934","161.56800","13.46412","0.02032"
"27000","161.96400","13.49719","0.02074"
"27066","162.36000","13.53019","0.02105"
"27132","162.75600","13.56320","0.02086"
"27198","163.15200","13.59614","0.02080"
"27264","163.54800","13.62920","0.02125"
"27330","163.94400","13.66227","0.02150"
"27396","164.34000","13.69521","0.02121"
"27462","164.73600","13.72816","0.02150"
"27528","165.13200","13.76122","0.02131"
"27594","165.52800","13.79428","0.02175"
"27660","165.92400","13.82723","0.02169"
"27726","166.32000","13.86017","0.02230"
"27792","166.71600","13.89323","0.02190"
"27858","167.11200","13.92624","0.02180"
"27924","167.50800","13.95918","0.02232"
"27990","167.90400","13.99219","0.02267"
"28056","168.30000","14.02525","0.02248"
"28122","168.69600","14.05825","0.02221"
"28188","169.09200","14.09120","0.02217"
"28254","169.48800","14.12420","0.02243"
"28320","169.88400","14.15727","0.02257"
"28386","170.28000","14.19021","0.02269"
"28452","170.67600","14.22315","0.02256"
"28518","171.07200","14.25628","0.02323"
"28584","171.46800","14.28922","0.02324"
"28650","171.86400","14.32216","0.02331"
"28716","172.26000","14.35517","0.02292"
"28782","172.65600","14.38823","0.02296"
"28848","173.05200","14.42124","0.02311"
"28914","173.44800","14.45424","0.02276"
"28980","173.84400","14.48724","0.02254"
"29046","174.24000","14.52025","0.02267"
"29112","174.63600","14.55319","0.02306"
"29178","175.03200","14.58619","0.02298"
"29244","175.42800","14.61920","0.02300"
"29310","175.82400","14.65226","0.02320"
"29376","176.22000","14.68521","0.02350"
"29442","176.61600","14.71815","0.02333"
"29508","177.01200","14.75121","0.02356"
"29574","177.40800","14.78428","0.02404"
"29640","177.80400","14.81722","0.02351"
"29706","178.20000","14.85023","0.02383"
"29772","178.59600","14.88323","0.02368"
"29838","178.99200","14.91623","0.02361"
"29904","179.38800","14.94918","0.02390"
"29970","179.78400","14.98218","0.02428"
"30036","180.18000","15.01524","0.02383"
"30102","180.57600","15.04825","0.02408"
"30168","180.97200","15.08119","0.02443"
"30234","181.36800","15.11420","0.02429"
"30300","181.76400","15.14720","0.02422"
"30366","182.16000","15.18020","0.02448"
"30432","182.55600","15.21321","0.02452"
"30498","182.95200","15.24621","0.02462"
"30564","183.34800","15.27928","0.02413"
"30630","183.74400","15.31222","0.02472"
"30696","184.14000","15.34522","0.02461"
"30762","184.53600","15.37823","0.02470"
"30828","184.93200","15.41123","0.02431"
"30894","185.32800","15.44423","0.02482"
"30960","185.72400","15.47718","0.02462"
"31026","186.12000","15.51024","0.02477"
"31092","186.51600","15.54325","0.02525"
"31158","186.91200","15.57619","0.02522"
"31224","187.30800","15.60919","0.02497"
"31290","187.70400","15.64226","0.02527"
"31356","188.10000","15.67526","0.02505"
"31422","188.49600","15.70820","0.02515"
"31488","188.89200","15.74121","0.02534"
"31554","189.28800","15.77427","0.02551"
"31620","189.68400","15.80722","0.02537"
"31686","190.08000","15.84016","0.02543"
"31752","190.47600","15.87322","0.02538"
"31818","190.87200","15.90623","0.02559"
"31884","191.26800","15.93923","0.02550"
"31950","191.66400","15.97217","0.02556"
"32016","192.06000","16.00524","0.02480"
"32082","192.45600","16.03824","0.02460"
"32148","192.85200","16.07125","0.02482"
"32214","193.24800","16.10419","0.02522"
"32280","193.64400","16.13725","0.02514"
"32346","194.04000","16.17026","0.02538"
"32412","194.43600","16.20314","0.02551"
"32478","194.83200","16.23621","0.02532"
"32544","195.22800","16.26927","0.02572"
"32610","195.62400","16.30227","0.02565"
"32676","196.02000","16.33516","0.02560"
"32742","196.41600","16.36816","0.02621"
"32808","196.81200","16.40123","0.02602"
"32874","197.20800","16.43423","0.02603"
"32940","197.60400","16.46717","0.02571"
"33006","198.00000","16.50024","0.02581"
"33072","198.39600","16.53318","0.02592"
"33138","198.79200","16.56624","0.02573"
"33204","199.18800","16.59925","0.02591"
"33270","199.58400","16.63225","0.02583"
"33336","199.98000","16.66526","0.02616"
"33402","200.37600","16.69826","0.02617"
"33468","200.77200","16.73120","0.02605"
"33534","201.16800","16.76421","0.02624"
"33600","201.56400","16.79727","0.02593"
"33666","201.96000","16.83022","0.02636"
"33732","202.35600","16.86322","0.02682"
"33798","202.75200","16.89622","0.02641"
"33864","203.14800","16.92929","0.02673"
"33930","203.54400","16.96217","0.02659"
"33996","203.94000","16.99523","0.02667"
"34062","204.33600","17.02824","0.02704"
"34128","204.73200","17.06124","0.02683"
"34194","205.12800","17.09425","0.02680"
"34260","205.52400","17.12731","0.02670"
"34326","205.92000","17.16025","0.02656"
"34392","206.31600","17.19320","0.02672"
"34458","206.71200","17.22620","0.02667"
"34524","207.10800","17.25920","0.02692"
"34590","207.50400","17.29221","0.02695"
"34656","207.90000","17.32515","0.02696"
"34722","208.29600","17.35816","0.02756"
"34788","208.69200","17.39128","0.02740"
"34854","209.08800","17.42422","0.02740"
"34920","209.48400","17.45717","0.02751"
"34986","209.88000","17.49023","0.02787"
"35052","210.27600","17.52330","0.02778"
"35118","210.67200","17.55630","0.02781"
"35184","211.06800","17.58912","0.02833"
"35250","211.46400","17.62225","0.02753"
"35316","211.86000","17.65525","0.02757"
"35382","212.25600","17.68826","0.02799"
"35448","212.65200","17.72114","0.02792"
"35514","213.04800","17.75420","0.02822"
"35580","213.44400","17.78721","0.02868"
"35646","213.84000","17.82021","0.02789"
"35712","214.23600","17.85315","0.02835"
"35778","214.63200","17.88622","0.02848"
"35844","215.02800","17.91922","0.02837"
"35910","215.42400","17.95217","0.02850"
"35976","215.82000","17.98523","0.02831"
"36042","216.21600","18.01823","0.02812"
"36108","216.61200","18.05130","0.02779"
"36174","217.00800","18.08424","0.02839"
"36240","217.40400","18.11719","0.02855"
"36306","217.80000","18.15025","0.02824"
"36372","218.19600","18.18325","0.02828"
"36438","218.59200","18.21614","0.02720"
"36504","218.98800","18.24920","0.02757"
"36570","219.38400","18.28221","0.02800"
"36636","219.78000","18.31521","0.02854"
"36702","220.17600","18.34821","0.02818"
"36768","220.57200","18.38128","0.02871"
"36834","220.96800","18.41422","0.02861"
"36900","221.36400","18.44722","0.02866"
"36966","221.76000","18.48017","0.02914"
"37032","222.15600","18.51329","0.02891"
"37098","222.55200","18.54623","0.02918"
"37164","222.94800","18.57924","0.02938"
"37230","223.34400","18.61224","0.02942"
"37296","223.74000","18.64525","0.03005"
"37362","224.13600","18.67825","0.02998"
"37428","224.53200","18.71119","0.03014"
"37494","224.92800","18.74426","0.03045"
"37560","225.32400","18.77726","0.03053"
"37626","225.72000","18.81021","0.03096"
"37692","226.11600","18.84315","0.03122"
"37758","226.51200","18.87621","0.03171"
"37824","226.90800","18.90922","0.03116"
"37890","227.30400","18.94222","0.03146"
"37956","227.70000","18.97516","0.03209"
"38022","228.09600","19.00823","0.03186"
"38088","228.49200","19.04129","0.03222"
"38154","228.88800","19.07418","0.03230"
"38220","229.28400","19.10718","0.03255"
"38286","229.68000","19.14024","0.03339"
"38352","230.07600","19.17325","0.03300"
"38418","230.47200","19.20619","0.03398"
"38484","230.86800","19.23920","0.03343"
"38550","231.26400","19.27226","0.03440"
"38616","231.66000","19.30526","0.03423"
"38682","232.05600","19.33815","0.03377"
"38748","232.45200","19.37121","0.03330"
"38814","232.84800","19.40421","0.03345"
"38880","233.24400","19.43716","0.03432"
"38946","233.64000","19.47022","0.03485"
"39012","234.03600","19.50323","0.03570"
"39078","234.43200","19.53629","0.03484"
"39144","234.82800","19.56917","0.03522"
"39210","235.22400","19.60218","0.03618"
"39276","235.62000","19.63530","0.03611"
"39342","236.01600","19.66825","0.03697"
"39408","236.41200","19.70125","0.03746"
"39474","236.80800","19.73419","0.03709"
"39540","237.20400","19.76726","0.03572"
"39606","237.60000","19.80026","0.03612"
"39672","237.99600","19.83315","0.03691"
"39738","238.39200","19.86621","0.03613"
"39804","238.78800","19.89921","0.03667"
"39870","239.18400","19.93216","0.03713"
"39936","239.58000","19.96516","0.03741"
"40002","239.97600","19.99822","0.03784"
"40068","240.37200","20.03123","0.03799"
"40134","240.76800","20.06423","0.03781"
"40200","241.16400","20.09718","0.03797"
"40266","241.56000","20.13030","0.03845"
"40332","241.95600","20.16330","0.03689"
"40398","242.35200","20.19619","0.03775"
"40464","242.74800","20.22919","0.03875"
"40530","243.14400","20.26225","0.03937"
"40596","243.54000","20.29526","0.04029"
"40662","243.93600","20.32820","0.04025"
"40728","244.33200","20.36121","0.04112"
"40794","244.72800","20.39421","0.04139"
"40860","245.12400","20.42727","0.04179"
"40926","245.52000","20.46010","0.04260"
"40992","245.91600","20.49322","0.04169"
"41058","246.31200","20.52622","0.04194"
"41124","246.70800","20.55929","0.04222"
"41190","247.10400","20.59217","0.04269"
"41256","247.50000","20.62524","0.04373"
"41322","247.89600","20.65824","0.04427"
"41388","248.29200","20.69124","0.04452"
"41454","248.68800","20.72419","0.04559"
"41520","249.08400","20.75725","0.04498"
"41586","249.48000","20.79020","0.04523"
"41652","249.87600","20.82320","0.04622"
"41718","250.27200","20.85620","0.04506"
"41784","250.66800","20.88921","0.04629"
"41850","251.06400","20.92221","0.04544"
"41916","251.46000","20.95522","0.04661"
"41982","251.85600","20.98816","0.04695"
"42048","252.25200","21.02122","0.04697"
"42114","252.64800","21.05423","0.04727"
"42180","253.04400","21.08717","0.04800"
"42246","253.44000","21.12024","0.04826"
"42312","253.83600","21.15318","0.04881"
"42378","254.23200","21.18624","0.04850"
"42444","254.62800","21.21919","0.04885"
"42510","255.02400","21.25225","0.04887"
"42576","255.42000","21.28526","0.04970"
"42642","255.81600","21.31814","0.04963"
"42708","256.21200","21.35120","0.05039"
"42774","256.60800","21.38427","0.05067"
"42840","257.00400","21.41721","0.05082"
"42906","257.40000","21.45015","0.05060"
"42972","257.79600","21.48322","0.05145"
"43038","258.19200","21.51622","0.05092"
"43104","258.58800","21.54922","0.05110"
"43170","258.98400","21.58223","0.05169"
"43236","259.38000","21.61523","0.03781"
"43302","259.77600","21.64829","0.03721"
"43368","260.17200","21.68124","0.03097"
"43434","260.56800","21.71418","0.03073"
"43500","260.96400","21.74718","0.02918"
"43566","261.36000","21.78031","0.03012"
"43632","261.75600","21.81325","0.03031"
"43698","262.15200","21.84614","0.03033"
"43764","262.54800","21.87920","0.03158"
"43830","262.94400","21.91227","0.03173"
"43896","263.34000","21.94521","0.03156"
"43962","263.73600","21.97815","0.02923"
"44028","264.13200","22.01128","0.02920"
"44094","264.52800","22.04428","0.02949"
"44160","264.92400","22.07722","0.02877"
"44226","265.32000","22.11017","0.02897"
"44292","265.71600","22.14323","0.02818"
"44358","266.11200","22.17624","0.02848"
"44424","266.50800","22.20918","0.02902"
"44490","266.90400","22.24224","0.02909"
"44556","267.30000","22.27525","0.02892"
"44622","267.69600","22.30825","0.02984"
"44688","268.09200","22.34120","0.02976"
"44754","268.48800","22.37420","0.02959"
"44820","268.88400","22.40720","0.02978"
"44886","269.28000","22.44021","0.02989"
"44952","269.67600","22.47327","0.03011"
"45018","270.07200","22.50621","0.03035"
"45084","270.46800","22.53922","0.03020"
"45150","270.86400","22.57222","0.03057"
"45216","271.26000","22.60517","0.03110"
"45282","271.65600","22.63823","0.03147"
"45348","272.05200","22.67123","0.03143"
"45414","272.44800","22.70418","0.03187"
"45480","272.84400","22.73724","0.03167"
"45546","273.24000","22.77024","0.03174"
"45612","273.63600","22.80319","0.03190"
"45678","274.03200","22.83619","0.03216"
"45744","274.42800","22.86926","0.03273"
"45810","274.82400","22.90226","0.03334"
"45876","275.22000","22.93521","0.03269"
"45942","275.61600","22.96821","0.03244"
"46008","276.01200","23.00121","0.03213"
"46074","276.40800","23.03422","0.03171"
"46140","276.80400","23.06716","0.03177"
"46206","277.20000","23.10023","0.03308"
"46272","277.59600","23.13317","0.03379"
"46338","277.99200","23.16629","0.03281"
"46404","278.38800","23.19917","0.03410"
"46470","278.78400","23.23218","0.03225"
"46536","279.18000","23.26524","0.03320"
"46602","279.57600","23.29831","0.03197"
"46668","279.97200","23.33113","0.03385"
"46734","280.36800","23.36419","0.03341"
"46800","280.76400","23.39726","0.03277"
"46866","281.16000","23.43026","0.03318"
"46932","281.55600","23.46314","0.03386"
"46998","281.95200","23.49621","0.03415"
"47064","282.34800","23.52921","0.03447"
"47130","282.74400","23.56228","0.03407"
"47196","283.14000","23.59516","0.03468"
"47262","283.53600","23.62829","0.03424"
"47328","283.93200","23.66123","0.03455"
"47394","284.32800","23.69423","0.03515"
"47460","284.72400","23.72724","0.03577"
"47526","285.12000","23.76018","0.03586"
"47592","285.51600","23.79324","0.03769"
"47658","285.91200","23.82619","0.03722"
"47724","286.30800","23.85919","0.03824"
"47790","286.70400","23.89226","0.03932"
"47856","287.10000","23.92526","0.03990"
"47922","287.49600","23.95814","0.04120"
"47988","287.89200","23.99121","0.04091"
"48054","288.28800","24.02421","0.04215"
"48120","288.68400","24.05722","0.04322"
"48186","289.08000","24.09016","0.04357"
"48252","289.47600","24.12328","0.04295"
"48318","289.87200","24.15629","0.04269"
"48384","290.26800","24.18917","0.04058"
"48450","290.66400","24.22211","0.04201"
"48516","291.06000","24.25524","0.04327"
"48582","291.45600","24.28824","0.04476"
"48648","291.85200","24.32119","0.04368"
"48714","292.24800","24.35413","0.04456"
"48780","292.64400","24.38725","0.04497"
"48846","293.04000","24.42026","0.04509"
"48912","293.43600","24.45314","0.04528"
"48978","293.83200","24.48620","0.04672"
"49044","294.22800","24.51927","0.04691"
"49110","294.62400","24.55227","0.04717"
"49176","295.02000","24.58516","0.04803"
"49242","295.41600","24.61816","0.04799"
"49308","295.81200","24.65122","0.04872"
"49374","296.20800","24.68429","0.04972"
"49440","296.60400","24.71717","0.04845"
"49506","297.00000","24.75018","0.04970"
"49572","297.39600","24.78324","0.05012"
"49638","297.79200","24.81624","0.05016"
"49704","298.18800","24.84919","0.05081"
"49770","298.58400","24.88225","0.05114"
"49836","298.98000","24.91525","0.05197"
"49902","299.37600","24.94820","0.05248"
"49968","299.77200","24.98120","0.05290"
"50034","300.16800","25.01427","0.05189"
"50100","300.56400","25.04721","0.05292"
"50166","300.96000","25.08015","0.05347"
"50232","301.35600","25.11322","0.05071"
"50298","301.75200","25.14622","0.02466"
"50364","302.14800","25.17923","0.02532"
"50430","302.54400","25.21217","0.02556"
"50496","302.94000","25.24523","0.02597"
"50562","303.33600","25.27824","0.02598"
"50628","303.73200","25.31118","0.02644"
"50694","304.12800","25.34418","0.02696"
"50760","304.52400","25.37725","0.02717"
"50826","304.92000","25.41019","0.02703"
"50892","305.31600","25.44320","0.02815"
"50958","305.71200","25.47614","0.02768"
"51024","306.10800","25.50926","0.02758"
"51090","306.50400","25.54227","0.02794"
"51156","306.90000","25.57515","0.02798"
"51222","307.29600","25.60822","0.02830"
"51288","307.69200","25.64128","0.02789"
"51354","308.08800","25.67416","0.02828"
"51420","308.48400","25.70717","0.02823"
"51486","308.88000","25.74023","0.02850"
"51552","309.27600","25.77329","0.02882"
"51618","309.67200","25.80618","0.02911"
"51684","310.06800","25.83912","0.02634"
"51750","310.46400","25.87225","0.02011"
"51816","310.86000","25.90525","0.02160"
"51882","311.25600","25.93819","0.02308"
"51948","311.65200","25.97120","0.02329"
"52014","312.04800","26.00420","0.02273"
"52080","312.44400","26.03726","0.02386"
"52146","312.84000","26.07021","0.02446"
"52212","313.23600","26.10315","0.02441"
"52278","313.63200","26.13628","0.02400"
"52344","314.02800","26.16928","0.02497"
"52410","314.42400","26.20216","0.02521"
"52476","314.82000","26.23517","0.02526"
"52542","315.21600","26.26823","0.02527"
"52608","315.61200","26.30124","0.02582"
"52674","316.00800","26.33424","0.02626"
"52740","316.40400","26.36719","0.02643"
"52806","316.80000","26.40019","0.02620"
"52872","317.19600","26.43319","0.02679"
"52938","317.59200","26.46619","0.02701"
"53004","317.98800","26.49926","0.02735"
"53070","318.38400","26.53221","0.02745"
"53136","318.78000","26.56521","0.02824"
"53202","319.17600","26.59821","0.02820"
"53268","319.57200","26.63122","0.02888"
"53334","319.96800","26.66428","0.02857"
"53400","320.36400","26.69722","0.02926"
"53466","320.76000","26.73023","0.02969"
"53532","321.15600","26.76323","0.02983"
"53598","321.55200","26.79623","0.03078"
"53664","321.94800","26.82918","0.03054"
"53730","322.34400","26.86224","0.03080"
"53796","322.74000","26.89524","0.03190"
"53862","323.13600","26.92825","0.03177"
"53928","323.53200","26.96125","0.03248"
"53994","323.92800","26.99426","0.03249"
"54060","324.32400","27.02726","0.03326"
"54126","324.72000","27.06020","0.03459"
"54192","325.11600","27.09321","0.03448"
"54258","325.51200","27.12627","0.03461"
"54324","325.90800","27.15928","0.03541"
"54390","326.30400","27.19216","0.03555"
"54456","326.70000","27.22516","0.03653"
"54522","327.09600","27.25823","0.03635"
"54588","327.49200","27.29123","0.03596"
"54654","327.88800","27.32417","0.03639"
"54720","328.28400","27.35718","0.03754"
"54786","328.68000","27.39024","0.03741"
"54852","329.07600","27.42325","0.03790"
"54918","329.47200","27.45613","0.03828"
"54984","329.86800","27.48920","0.03819"
"55050","330.26400","27.52220","0.03869"
"55116","330.66000","27.55526","0.03857"
"55182","331.05600","27.58815","0.03788"
"55248","331.45200","27.62127","0.03463"
"55314","331.84800","27.65421","0.03616"
"55380","332.24400","27.68728","0.03703"
"55446","332.64000","27.72022","0.03731"
"55512","333.03600","27.75323","0.03808"
"55578","333.43200","27.78623","0.03809"
"55644","333.82800","27.81923","0.03759"
"55710","334.22400","27.85218","0.03800"
"55776","334.62000","27.88524","0.03910"
"55842","335.01600","27.91825","0.03886"
"55908","335.41200","27.95119","0.03906"
"55974","335.80800","27.98419","0.03908"
"56040","336.20400","28.01726","0.03944"
"56106","336.60000","28.05020","0.04006"
"56172","336.99600","28.08320","0.04057"
"56238","337.39200","28.11621","0.04109"
"56304","337.78800","28.14921","0.03965"
"56370","338.18400","28.18221","0.04071"
"56436","338.58000","28.21522","0.04128"
"56502","338.97600","28.24822","0.04104"
"56568","339.37200","28.28123","0.04122"
"56634","339.76800","28.31423","0.04232"
"56700","340.16400","28.34711","0.04166"
"56766","340.56000","28.38024","0.04259"
"56832","340.95600","28.41324","0.04265"
"56898","341.35200","28.44619","0.04282"
"56964","341.74800","28.47919","0.04255"
"57030","342.14400","28.51225","0.04302"
"57096","342.54000","28.54526","0.04338"
"57162","342.93600","28.57820","0.04402"
"57228","343.33200","28.61121","0.04403"
"57294","343.72800","28.64427","0.04434"
"57360","344.12400","28.67721","0.04421"
"57426","344.52000","28.71016","0.04361"
"57492","344.91600","28.74322","0.04473"
"57558","345.31200","28.77622","0.04465"
"57624","345.70800","28.80923","0.04381"
"57690","346.10400","28.84217","0.04352"
"57756","346.50000","28.87518","0.04338"
"57822","346.89600","28.90824","0.04379"
"57888","347.29200","28.94124","0.04375"
"57954","347.68800","28.97413","0.04421"
"58020","348.08400","29.00725","0.04518"
"58086","348.48000","29.04026","0.04498"
"58152","348.87600","29.07320","0.04477"
"58218","349.27200","29.10614","0.04535"
"58284","349.66800","29.13921","0.04505"
"58350","350.06400","29.17227","0.04116"
"58416","350.46000","29.20521","0.04152"
"58482","350.85600","29.23822","0.04170"
"58548","351.25200","29.27122","0.04190"
"58614","351.64800","29.30429","0.04210"
"58680","352.04400","29.33717","0.04217"
"58746","352.44000","29.37024","0.04287"
"58812","352.83600","29.40318","0.04339"
"58878","353.23200","29.43618","0.04391"
"58944","353.62800","29.46924","0.04356"
"59010","354.02400","29.50225","0.04526"
"59076","354.42000","29.53519","0.04594"
"59142","354.81600","29.56814","0.04585"
"59208","355.21200","29.60120","0.04608"
"59274","355.60800","29.63420","0.04675"
"59340","356.00400","29.66721","0.04710"
"59406","356.40000","29.70021","0.04735"
"59472","356.79600","29.73322","0.04839"
"59538","357.19200","29.76622","0.04869"
"59604","357.58800","29.79922","0.04953"
"59670","357.98400","29.83217","0.04972"
"59736","358.38000","29.86517","0.04971"
"59802","358.77600","29.89829","0.05020"
"59868","359.17200","29.93124","0.04953"
"59934","359.56800","29.96418","0.05029"
"60000","359.96400","29.99725","0.05066"
"60066","360.36000","30.03025","0.05113"
"60132","360.75600","30.06319","0.05135"
"60198","361.15200","30.09620","0.05108"
"60264","361.54800","30.12920","0.05160"
"60330","361.94400","30.16232","0.05174"
"60396","362.34000","30.19521","0.01777"
"60462","362.73600","30.22815","0.02004"
"60528","363.13200","30.26122","0.01987"
"60594","363.52800","30.29428","0.02040"
"60660","363.92400","30.32716","0.02204"
"60726","364.32000","30.36017","0.02228"
"60792","364.71600","30.39323","0.02211"
"60858","365.11200","30.42624","0.02349"
"60924","365.50800","30.45918","0.02452"
"60990","365.90400","30.49212","0.02410"
"61056","366.30000","30.52525","0.02401"
"61122","366.69600","30.55819","0.02548"
"61188","367.09200","30.59120","0.02556"
"61254","367.48800","30.62420","0.02521"
"61320","367.88400","30.65720","0.02561"
"61386","368.28000","30.69021","0.02634"
"61452","368.67600","30.72315","0.02636"
"61518","369.07200","30.75622","0.02685"
"61584","369.46800","30.78922","0.02726"
"61650","369.86400","30.82222","0.02715"
"61716","370.26000","30.85523","0.02800"
"61782","370.65600","30.88823","0.02859"
"61848","371.05200","30.92123","0.02908"
"61914","371.44800","30.95418","0.02936"
"61980","371.84400","30.98724","0.03012"
"62046","372.24000","31.02019","0.03106"
"62112","372.63600","31.05325","0.03168"
"62178","373.03200","31.08619","0.03212"
"62244","373.42800","31.11926","0.03451"
"62310","373.82400","31.15226","0.03407"
"62376","374.22000","31.18521","0.03571"
"62442","374.61600","31.21815","0.03658"
"62508","375.01200","31.25127","0.03706"
"62574","375.40800","31.28421","0.03877"
"62640","375.80400","31.31722","0.03948"
"62706","376.20000","31.35022","0.03962"
"62772","376.59600","31.38323","0.04112"
"62838","376.99200","31.41623","0.04167"
"62904","377.38800","31.44917","0.04310"
"62970","377.78400","31.48218","0.04429"
"63036","378.18000","31.51530","0.04527"
"63102","378.57600","31.54831","0.04555"
"63168","378.97200","31.58113","0.04584"
"63234","379.36800","31.61425","0.04630"
"63300","379.76400","31.64726","0.04706"
"63366","380.16000","31.68020","0.04748"
"63432","380.55600","31.71315","0.04817"
"63498","380.95200","31.74621","0.04854"
"63564","381.34800","31.77921","0.04935"
"63630","381.74400","31.81222","0.04917"
"63696","382.14000","31.84516","0.04953"
"63762","382.53600","31.87823","0.04894"
"63828","382.93200","31.91129","0.04878"
"63894","383.32800","31.94423","0.04997"
"63960","383.72400","31.97718","0.04973"
"64026","384.12000","32.01030","0.05005"
"64092","384.51600","32.04330","0.05078"
"64158","384.91200","32.07625","0.05023"
"64224","385.30800","32.10919","0.05061"
"64290","385.70400","32.14225","0.05058"
"64356","386.10000","32.17526","0.05098"
"64422","386.49600","32.20820","0.05106"
"64488","386.89200","32.24126","0.05079"
"64554","387.28800","32.27421","0.05134"
"64620","387.68400","32.30722","0.05081"
"64686","388.08000","32.34022","0.05160"
"64752","388.47600","32.37322","0.05201"
"64818","388.87200","32.40623","0.05275"
"64884","389.26800","32.43923","0.05360"
"64950","389.66400","32.47218","0.05433"
"65016","390.06000","32.50524","0.05504"
"65082","390.45600","32.53824","0.05573"
"65148","390.85200","32.57119","0.04035"
"65214","391.24800","32.60419","0.04246"
"65280","391.64400","32.63725","0.04379"
"65346","392.04000","32.67026","0.04612"
"65412","392.43600","32.70314","0.04749"
"65478","392.83200","32.73621","0.04820"
"65544","393.22800","32.76927","0.01686"
"65610","393.62400","32.80221","0.01869"
"65676","394.02000","32.83516","0.01791"
"65742","394.41600","32.86822","0.02117"
"65808","394.81200","32.90128","0.02038"
"65874","395.20800","32.93423","0.02099"
"65940","395.60400","32.96717","0.02134"
"66006","396.00000","33.00029","0.02015"
"66072","396.39600","33.03329","0.02067"
"66138","396.79200","33.06624","0.02159"
"66204","397.18800","33.09925","0.02148"
"66270","397.58400","33.13225","0.02143"
"66336","397.98000","33.16531","0.02175"
"66402","398.37600","33.19820","0.02159"
"66468","398.77200","33.23114","0.02190"
"66534","399.16800","33.26426","0.02241"
"66600","399.56400","33.29727","0.02274"
"66666","399.96000","33.33015","0.02217"
"66732","400.35600","33.36322","0.02241"
"66798","400.75200","33.39622","0.02270"
"66864","401.14800","33.42923","0.02298"
"66930","401.54400","33.46217","0.02289"
"66996","401.94000","33.49523","0.02278"
"67062","402.33600","33.52818","0.02278"
"67128","402.73200","33.56118","0.02303"
"67194","403.12800","33.59418","0.02323"
"67260","403.52400","33.62725","0.02369"
"67326","403.92000","33.66025","0.02376"
"67392","404.31600","33.69320","0.02368"
"67458","404.71200","33.72620","0.02392"
"67524","405.10800","33.75926","0.02376"
"67590","405.50400","33.79221","0.02412"
"67656","405.90000","33.82515","0.02435"
"67722","406.29600","33.85822","0.02427"
"67788","406.69200","33.89122","0.02442"
"67854","407.08800","33.92416","0.02461"
"67920","407.48400","33.95716","0.02489"
"67986","407.88000","33.99023","0.02474"
"68052","408.27600","34.02323","0.02482"
"68118","408.67200","34.05624","0.02438"
"68184","409.06800","34.08924","0.02464"
"68250","409.46400","34.12224","0.02464"
"68316","409.86000","34.15531","0.02504"
"68382","410.25600","34.18819","0.02509"
"68448","410.65200","34.22113","0.02533"
"68514","411.04800","34.25420","0.02515"
"68580","411.44400","34.28720","0.02506"
"68646","411.84000","34.32015","0.02497"
"68712","412.23600","34.35321","0.02537"
"68778","412.63200","34.38622","0.02547"
"68844","413.02800","34.41922","0.02576"
"68910","413.42400","34.45216","0.02601"
"68976","413.82000","34.48523","0.02589"
"69042","414.21600","34.51823","0.02584"
"69108","414.61200","34.55123","0.02588"
"69174","415.00800","34.58418","0.02603"
"69240","415.40400","34.61718","0.02582"
"69306","415.80000","34.65025","0.02630"
"69372","416.19600","34.68325","0.02621"
"69438","416.59200","34.71613","0.02632"
"69504","416.98800","34.74920","0.02653"
"69570","417.38400","34.78220","0.02644"
"69636","417.78000","34.81521","0.02688"
"69702","418.17600","34.84821","0.02702"
"69768","418.57200","34.88121","0.02716"
"69834","418.96800","34.91428","0.02722"
"69900","419.36400","34.94722","0.02778"
"69966","419.76000","34.98022","0.02839"
"70032","420.15600","35.01329","0.02793"
"70098","420.55200","35.04623","0.02803"
"70164","420.94800","35.07918","0.02832"
"70230","421.34400","35.11224","0.02862"
"70296","421.74000","35.14519","0.02871"
"70362","422.13600","35.17825","0.02940"
"70428","422.53200","35.21119","0.02954"
"70494","422.92800","35.24426","0.02968"
"70560","423.32400","35.27720","0.03032"
"70626","423.72000","35.31020","0.03056"
"70692","424.11600","35.34321","0.03072"
"70758","424.51200","35.37621","0.03095"
"70824","424.90800","35.40921","0.03177"
"70890","425.30400","35.44216","0.03279"
"70956","425.70000","35.47522","0.03237"
"71022","426.09600","35.50823","0.03323"
"71088","426.49200","35.54123","0.03272"
"71154","426.88800","35.57412","0.03332"
"71220","427.28400","35.60724","0.03466"
"71286","427.68000","35.64024","0.03554"
"71352","428.07600","35.67319","0.03633"
"71418","428.47200","35.70619","0.03650"
"71484","428.86800","35.73919","0.03732"
"71550","429.26400","35.77225","0.03967"
"71616","429.66000","35.80520","0.03964"
"71682","430.05600","35.83815","0.04008"
"71748","430.45200","35.87121","0.04041"
"71814","430.84800","35.90427","0.04191"
"71880","431.24400","35.93722","0.04215"
"71946","431.64000","35.97022","0.04366"
"72012","432.03600","36.00322","0.04285"
"72078","432.43200","36.03629","0.04243"
"72144","432.82800","36.06923","0.04303"
"72210","433.22400","36.10218","0.04373"
"72276","433.62000","36.13530","0.04425"
"72342","434.01600","36.16824","0.04524"
"72408","434.41200","36.20119","0.04618"
"72474","434.80800","36.23419","0.04710"
"72540","435.20400","36.26725","0.04767"
"72606","435.60000","36.30026","0.04902"
"72672","435.99600","36.33315","0.04925"
"72738","436.39200","36.36621","0.05001"
"72804","436.78800","36.39921","0.05115"
"72870","437.18400","36.43227","0.05173"
"72936","437.58000","36.46516","0.05263"
"73002","437.97600","36.49828","0.05362"
"73068","438.37200","36.53122","0.05368"
"73134","438.76800","36.56423","0.05230"
"73200","439.16400","36.59717","0.05318"
"73266","439.56000","36.63023","0.05455"
"73332","439.95600","36.66324","0.05525"
"73398","440.35200","36.69619","0.05648"
"73464","440.74800","36.72919","0.05738"
"73530","441.14400","36.76219","0.05860"
"73596","441.54000","36.79525","0.06017"
"73662","441.93600","36.82820","0.06049"
"73728","442.33200","36.86120","0.06168"
"73794","442.72800","36.89427","0.05787"
"73860","443.12400","36.92721","0.05869"
"73926","443.52000","36.96016","0.05466"
"73992","443.91600","36.99322","0.05627"
"74058","444.31200","37.02628","0.05827"
"74124","444.70800","37.05923","0.05913"
"74190","445.10400","37.09223","0.06057"
"74256","445.50000","37.12523","0.06183"
"74322","445.89600","37.15824","0.06301"
"74388","446.29200","37.19124","0.06435"
"74454","446.68800","37.22419","0.06534"
"74520","447.08400","37.25725","0.06649"
"74586","447.48000","37.29019","0.06632"
"74652","447.87600","37.32320","0.06726"
"74718","448.27200","37.35620","0.06715"
"74784","448.66800","37.38920","0.06846"
"74850","449.06400","37.42221","0.06882"
"74916","449.46000","37.45521","0.05561"
"74982","449.85600","37.48816","0.05505"
"75048","450.25200","37.52122","0.05481"
"75114","450.64800","37.55422","0.05543"
"75180","451.04400","37.58723","0.05468"
"75246","451.44000","37.62023","0.05486"
"75312","451.83600","37.65318","0.05413"
"75378","452.23200","37.68618","0.05410"
"75444","452.62800","37.71918","0.05123"
"75510","453.02400","37.75225","0.05231"
"75576","453.42000","37.78525","0.05296"
"75642","453.81600","37.81819","0.05306"
"75708","454.21200","37.85120","0.05376"
"75774","454.60800","37.88426","0.05500"
"75840","455.00400","37.91721","0.05602"
"75906","455.40000","37.95021","0.05738"
"75972","455.79600","37.98321","0.05868"
"76038","456.19200","38.01622","0.05991"
"76104","456.58800","38.04922","0.05781"
"76170","456.98400","38.08217","0.05911"
"76236","457.38000","38.11523","0.06039"
"76302","457.77600","38.14823","0.06222"
"76368","458.17200","38.18118","0.06347"
"76434","458.56800","38.21418","0.06379"
"76500","458.96400","38.24725","0.06568"
"76566","459.36000","38.28025","0.06652"
"76632","459.75600","38.31325","0.06662"
"76698","460.15200","38.34620","0.06738"
"76764","460.54800","38.37926","0.06832"
"76830","460.94400","38.41227","0.06906"
"76896","461.34000","38.44515","0.06130"
"76962","461.73600","38.47821","0.05833"
"77028","462.13200","38.51122","0.00989"
"77094","462.52800","38.54428","0.00957"
"77160","462.92400","38.57716","0.01315"
"77226","463.32000","38.61017","0.00890"
"77292","463.71600","38.64323","0.01388"
"77358","464.11200","38.67624","0.01187"
"77424","464.50800","38.70918","0.00878"
"77490","464.90400","38.74218","0.01193"
"77556","465.30000","38.77525","0.01350"
"77622","465.69600","38.80825","0.01030"
"77688","466.09200","38.84119","0.01219"
"77754","466.48800","38.87420","0.01363"
"77820","466.88400","38.90720","0.01151"
"77886","467.28000","38.94027","0.01311"
"77952","467.67600","38.97321","0.01456"
"78018","468.07200","39.00621","0.01392"
"78084","468.46800","39.03928","0.01369"
"78150","468.86400","39.07222","0.01495"
"78216","469.26000","39.10516","0.01515"
"78282","469.65600","39.13829","0.01429"
"78348","470.05200","39.17123","0.01558"
"78414","470.44800","39.20412","0.01647"
"78480","470.84400","39.23724","0.01577"
"78546","471.24000","39.27024","0.01550"
"78612","471.63600","39.30319","0.01653"
"78678","472.03200","39.33619","0.01671"
"78744","472.42800","39.36926","0.01659"
"78810","472.82400","39.40219","0.01655"
"78876","473.22000","39.43520","0.01789"
"78942","473.61600","39.46815","0.01708"
"79008","474.01200","39.50121","0.01702"
"79074","474.40800","39.53428","0.01788"
"79140","474.80400","39.56716","0.01791"
"79206","475.20000","39.60022","0.01765"
"79272","475.59600","39.63322","0.01830"
"79338","475.99200","39.66623","0.01827"
"79404","476.38800","39.69917","0.01820"
"79470","476.78400","39.73218","0.01837"
"79536","477.18000","39.76524","0.01892"
"79602","477.57600","39.79824","0.01942"
"79668","477.97200","39.83112","0.01865"
"79734","478.36800","39.86425","0.01918"
"79800","478.76400","39.89725","0.01938"
"79866","479.16000","39.93026","0.01978"
"79932","479.55600","39.96320","0.02013"
"79998","479.95200","39.99621","0.02001"
"80064","480.34800","40.02921","0.02066"
"80130","480.74400","40.06221","0.02068"
"80196","481.14000","40.09516","0.02075"
"80262","481.53600","40.12828","0.02100"
"80328","481.93200","40.16122","0.02175"
"80394","482.32800","40.19423","0.02143"
"80460","482.72400","40.22723","0.02144"
"80526","483.12000","40.26018","0.02190"
"80592","483.51600","40.29324","0.02182"
"80625","483.71400","40.30975","0.02200"