File: Trajectories_together/170121_1Specimen_RawData_10.csv
"","V1","V2","V3"
"1","End date","1/21/2017",""
"2","Specimen label","4DG_32",""
"3","Maximum Load","0.96321","N"
"4","Time","Extension","Load"
"5","(s)","(mm)","(N)"
"6","0.00000","0.00000","-0.00108"
"79","0.43800","0.03683","0.00859"
"152","0.87600","0.07324","0.01253"
"225","1.31400","0.10971","0.01457"
"298","1.75200","0.14619","0.01563"
"371","2.19000","0.18272","0.01658"
"444","2.62800","0.21925","0.01680"
"517","3.06600","0.25572","0.01697"
"590","3.50400","0.29225","0.01734"
"663","3.94200","0.32866","0.01753"
"736","4.38000","0.36513","0.01756"
"809","4.81800","0.40173","0.01743"
"882","5.25600","0.43820","0.01771"
"955","5.69400","0.47473","0.01732"
"1028","6.13200","0.51120","0.01691"
"1101","6.57000","0.54773","0.01702"
"1174","7.00800","0.58420","0.01753"
"1247","7.44600","0.62073","0.01657"
"1320","7.88400","0.65727","0.01607"
"1393","8.32200","0.69368","0.01588"
"1466","8.76000","0.73015","0.01617"
"1539","9.19800","0.76668","0.01651"
"1612","9.63600","0.80327","0.01655"
"1685","10.07400","0.83968","0.01664"
"1758","10.51200","0.87616","0.01639"
"1831","10.95000","0.91263","0.01674"
"1904","11.38800","0.94922","0.01680"
"1977","11.82600","0.98569","0.01692"
"2050","12.26400","1.02222","0.01672"
"2123","12.70200","1.05869","0.01722"
"2196","13.14000","1.09516","0.01695"
"2269","13.57800","1.13164","0.01702"
"2342","14.01600","1.16823","0.01686"
"2415","14.45400","1.20476","0.01732"
"2488","14.89200","1.24123","0.01676"
"2561","15.33000","1.27770","0.01764"
"2634","15.76800","1.31417","0.01704"
"2707","16.20600","1.35077","0.01746"
"2780","16.64400","1.38724","0.01735"
"2853","17.08200","1.42371","0.01720"
"2926","17.52000","1.46018","0.01777"
"2999","17.95800","1.49665","0.01750"
"3072","18.39600","1.53312","0.01785"
"3145","18.83400","1.56971","0.01813"
"3218","19.27200","1.60619","0.01807"
"3291","19.71000","1.64272","0.01796"
"3364","20.14800","1.67919","0.01790"
"3437","20.58600","1.71566","0.01813"
"3510","21.02400","1.75219","0.01825"
"3583","21.46200","1.78866","0.01793"
"3656","21.90000","1.82520","0.01804"
"3729","22.33800","1.86173","0.01832"
"3802","22.77600","1.89814","0.01797"
"3875","23.21400","1.93473","0.01797"
"3948","23.65200","1.97126","0.01829"
"4021","24.09000","2.00773","0.01855"
"4094","24.52800","2.04420","0.01860"
"4167","24.96600","2.08068","0.01861"
"4240","25.40400","2.11721","0.01899"
"4313","25.84200","2.15374","0.01912"
"4386","26.28000","2.19021","0.01867"
"4459","26.71800","2.22674","0.01909"
"4532","27.15600","2.26315","0.01866"
"4605","27.59400","2.29968","0.01845"
"4678","28.03200","2.33622","0.01876"
"4751","28.47000","2.37275","0.01897"
"4824","28.90800","2.40922","0.01911"
"4897","29.34600","2.44569","0.01952"
"4970","29.78400","2.48216","0.01873"
"5043","30.22200","2.51869","0.01898"
"5116","30.66000","2.55523","0.01902"
"5189","31.09800","2.59176","0.01961"
"5262","31.53600","2.62823","0.01938"
"5335","31.97400","2.66464","0.01936"
"5408","32.41200","2.70111","0.01950"
"5481","32.85000","2.73776","0.01934"
"5554","33.28800","2.77429","0.01955"
"5627","33.72600","2.81077","0.01928"
"5700","34.16400","2.84718","0.01926"
"5773","34.60200","2.88359","0.01945"
"5846","35.04000","2.92018","0.01960"
"5919","35.47800","2.95677","0.01932"
"5992","35.91600","2.99318","0.01979"
"6065","36.35400","3.02971","0.02046"
"6138","36.79200","3.06613","0.01982"
"6211","37.23000","3.10272","0.02005"
"6284","37.66800","3.13925","0.01964"
"6357","38.10600","3.17572","0.02017"
"6430","38.54400","3.21219","0.02003"
"6503","38.98200","3.24872","0.02020"
"6576","39.42000","3.28514","0.01999"
"6649","39.85800","3.32173","0.02003"
"6722","40.29600","3.35820","0.02047"
"6795","40.73400","3.39473","0.01989"
"6868","41.17200","3.43120","0.02001"
"6941","41.61000","3.46767","0.02059"
"7014","42.04800","3.50420","0.02056"
"7087","42.48600","3.54074","0.02060"
"7160","42.92400","3.57721","0.02012"
"7233","43.36200","3.61368","0.02008"
"7306","43.80000","3.65021","0.02042"
"7379","44.23800","3.68668","0.02035"
"7452","44.67600","3.72321","0.02086"
"7525","45.11400","3.75969","0.02083"
"7598","45.55200","3.79622","0.02011"
"7671","45.99000","3.83269","0.02075"
"7744","46.42800","3.86916","0.02023"
"7817","46.86600","3.90569","0.02029"
"7890","47.30400","3.94222","0.02074"
"7963","47.74200","3.97869","0.02090"
"8036","48.18000","4.01523","0.02030"
"8109","48.61800","4.05170","0.02039"
"8182","49.05600","4.08817","0.02068"
"8255","49.49400","4.12470","0.02044"
"8328","49.93200","4.16123","0.02077"
"8401","50.37000","4.19776","0.02075"
"8474","50.80800","4.23423","0.02104"
"8547","51.24600","4.27065","0.02049"
"8620","51.68400","4.30724","0.02059"
"8693","52.12200","4.34371","0.02110"
"8766","52.56000","4.38024","0.02113"
"8839","52.99800","4.41671","0.02114"
"8912","53.43600","4.45312","0.02103"
"8985","53.87400","4.48972","0.02115"
"9058","54.31200","4.52625","0.02112"
"9131","54.75000","4.56272","0.02092"
"9204","55.18800","4.59919","0.02105"
"9277","55.62600","4.63566","0.02080"
"9350","56.06400","4.67219","0.02044"
"9423","56.50200","4.70872","0.02115"
"9496","56.94000","4.74526","0.02053"
"9569","57.37800","4.78173","0.02101"
"9642","57.81600","4.81820","0.02062"
"9715","58.25400","4.85467","0.02103"
"9788","58.69200","4.89126","0.02101"
"9861","59.13000","4.92773","0.02082"
"9934","59.56800","4.96421","0.02056"
"10007","60.00600","5.00068","0.02098"
"10080","60.44400","5.03715","0.02059"
"10153","60.88200","5.07374","0.02059"
"10226","61.32000","5.11021","0.02093"
"10299","61.75800","5.14668","0.02127"
"10372","62.19600","5.18315","0.02098"
"10445","62.63400","5.21963","0.02090"
"10518","63.07200","5.25616","0.02133"
"10591","63.51000","5.29269","0.02117"
"10664","63.94800","5.32922","0.02063"
"10737","64.38600","5.36569","0.02069"
"10810","64.82400","5.40222","0.02110"
"10883","65.26200","5.43870","0.02097"
"10956","65.70000","5.47523","0.02125"
"11029","66.13800","5.51170","0.02071"
"11102","66.57600","5.54823","0.02139"
"11175","67.01400","5.58476","0.02090"
"11248","67.45200","5.62111","0.02113"
"11321","67.89000","5.65770","0.02156"
"11394","68.32800","5.69418","0.02143"
"11467","68.76600","5.73071","0.02101"
"11540","69.20400","5.76724","0.02172"
"11613","69.64200","5.80365","0.02141"
"11686","70.08000","5.84018","0.02143"
"11759","70.51800","5.87665","0.02148"
"11832","70.95600","5.91319","0.02153"
"11905","71.39400","5.94972","0.02142"
"11978","71.83200","5.98619","0.02178"
"12051","72.27000","6.02266","0.02210"
"12124","72.70800","6.05919","0.02239"
"12197","73.14600","6.09572","0.02185"
"12270","73.58400","6.13219","0.02183"
"12343","74.02200","6.16873","0.02261"
"12416","74.46000","6.20520","0.02250"
"12489","74.89800","6.24161","0.02216"
"12562","75.33600","6.27820","0.02173"
"12635","75.77400","6.31473","0.02175"
"12708","76.21200","6.35120","0.02220"
"12781","76.65000","6.38767","0.02196"
"12854","77.08800","6.42415","0.02233"
"12927","77.52600","6.46074","0.02254"
"13000","77.96400","6.49721","0.02214"
"13073","78.40200","6.53368","0.02286"
"13146","78.84000","6.57015","0.02277"
"13219","79.27800","6.60662","0.02246"
"13292","79.71600","6.64321","0.02302"
"13365","80.15400","6.67969","0.02302"
"13438","80.59200","6.71622","0.02344"
"13511","81.03000","6.75269","0.02292"
"13584","81.46800","6.78916","0.02321"
"13657","81.90600","6.82569","0.02322"
"13730","82.34400","6.86222","0.02347"
"13803","82.78200","6.89876","0.02337"
"13876","83.22000","6.93529","0.02328"
"13949","83.65800","6.97170","0.02388"
"14022","84.09600","7.00817","0.02269"
"14095","84.53400","7.04470","0.02287"
"14168","84.97200","7.08123","0.02318"
"14241","85.41000","7.11770","0.02402"
"14314","85.84800","7.15418","0.02346"
"14387","86.28600","7.19065","0.02312"
"14460","86.72400","7.22712","0.02336"
"14533","87.16200","7.26371","0.02299"
"14606","87.60000","7.30018","0.02314"
"14679","88.03800","7.33671","0.02334"
"14752","88.47600","7.37313","0.02299"
"14825","88.91400","7.40972","0.02248"
"14898","89.35200","7.44625","0.02258"
"14971","89.79000","7.48272","0.02280"
"15044","90.22800","7.51925","0.02310"
"15117","90.66600","7.55572","0.02276"
"15190","91.10400","7.59220","0.02285"
"15263","91.54200","7.62873","0.02301"
"15336","91.98000","7.66520","0.02309"
"15409","92.41800","7.70173","0.02298"
"15482","92.85600","7.73820","0.02319"
"15555","93.29400","7.77461","0.02324"
"15628","93.73200","7.81114","0.02356"
"15701","94.17000","7.84768","0.02295"
"15774","94.60800","7.88421","0.02341"
"15847","95.04600","7.92074","0.02445"
"15920","95.48400","7.95721","0.02358"
"15993","95.92200","7.99362","0.02358"
"16066","96.36000","8.03021","0.02319"
"16139","96.79800","8.06674","0.02334"
"16212","97.23600","8.10322","0.02338"
"16285","97.67400","8.13969","0.02379"
"16358","98.11200","8.17616","0.02366"
"16431","98.55000","8.21269","0.02424"
"16504","98.98800","8.24922","0.02341"
"16577","99.42600","8.28575","0.02320"
"16650","99.86400","8.32228","0.02434"
"16723","100.30200","8.35870","0.02404"
"16796","100.74000","8.39511","0.02449"
"16869","101.17800","8.43170","0.02461"
"16942","101.61600","8.46823","0.02469"
"17015","102.05400","8.50476","0.02412"
"17088","102.49200","8.54117","0.02397"
"17161","102.93000","8.57765","0.02467"
"17234","103.36800","8.61418","0.02460"
"17307","103.80600","8.65071","0.02459"
"17380","104.24400","8.68724","0.02493"
"17453","104.68200","8.72371","0.02449"
"17526","105.12000","8.76018","0.02488"
"17599","105.55800","8.79671","0.02517"
"17672","105.99600","8.83319","0.02510"
"17745","106.43400","8.86972","0.02444"
"17818","106.87200","8.90625","0.02463"
"17891","107.31000","8.94272","0.02328"
"17964","107.74800","8.97919","0.02462"
"18037","108.18600","9.01572","0.02436"
"18110","108.62400","9.05226","0.02430"
"18183","109.06200","9.08873","0.02401"
"18256","109.50000","9.12520","0.02513"
"18329","109.93800","9.16167","0.02498"
"18402","110.37600","9.19820","0.02501"
"18475","110.81400","9.23473","0.02499"
"18548","111.25200","9.27120","0.02558"
"18621","111.69000","9.30768","0.02585"
"18694","112.12800","9.34415","0.02596"
"18767","112.56600","9.38068","0.02617"
"18840","113.00400","9.41721","0.02624"
"18913","113.44200","9.45368","0.02603"
"18986","113.88000","9.49021","0.02645"
"19059","114.31800","9.52668","0.02695"
"19132","114.75600","9.56322","0.02659"
"19205","115.19400","9.59975","0.02681"
"19278","115.63200","9.63622","0.02588"
"19351","116.07000","9.67275","0.02592"
"19424","116.50800","9.70922","0.02691"
"19497","116.94600","9.74563","0.02689"
"19570","117.38400","9.78217","0.02653"
"19643","117.82200","9.81870","0.02753"
"19716","118.26000","9.85523","0.02755"
"19789","118.69800","9.89170","0.02772"
"19862","119.13600","9.92811","0.02714"
"19935","119.57400","9.96464","0.02783"
"20008","120.01200","10.00117","0.02714"
"20081","120.45000","10.03771","0.02769"
"20154","120.88800","10.07424","0.02671"
"20227","121.32600","10.11071","0.02712"
"20300","121.76400","10.14718","0.02777"
"20373","122.20200","10.18371","0.02785"
"20446","122.64000","10.22024","0.02732"
"20519","123.07800","10.25677","0.02746"
"20592","123.51600","10.29319","0.02841"
"20665","123.95400","10.32966","0.02876"
"20738","124.39200","10.36619","0.02856"
"20811","124.83000","10.40272","0.02932"
"20884","125.26800","10.43919","0.02886"
"20957","125.70600","10.47572","0.03026"
"21030","126.14400","10.51220","0.03060"
"21103","126.58200","10.54867","0.03000"
"21176","127.02000","10.58520","0.03085"
"21249","127.45800","10.62173","0.03057"
"21322","127.89600","10.65820","0.03105"
"21395","128.33400","10.69473","0.03152"
"21468","128.77200","10.73114","0.03180"
"21541","129.21000","10.76768","0.03047"
"21614","129.64800","10.80421","0.03211"
"21687","130.08600","10.84068","0.03179"
"21760","130.52400","10.87721","0.03102"
"21833","130.96200","10.91368","0.03205"
"21906","131.40000","10.95015","0.03244"
"21979","131.83800","10.98675","0.03316"
"22052","132.27600","11.02322","0.03291"
"22125","132.71400","11.05975","0.03321"
"22198","133.15200","11.09622","0.03355"
"22271","133.59000","11.13269","0.03302"
"22344","134.02800","11.16922","0.03332"
"22417","134.46600","11.20575","0.03325"
"22490","134.90400","11.24223","0.03292"
"22563","135.34200","11.27870","0.03436"
"22636","135.78000","11.31517","0.03308"
"22709","136.21800","11.35164","0.03340"
"22782","136.65600","11.38817","0.03360"
"22855","137.09400","11.42470","0.03400"
"22928","137.53200","11.46118","0.03545"
"23001","137.97000","11.49765","0.03470"
"23074","138.40800","11.53418","0.03373"
"23147","138.84600","11.57071","0.03395"
"23220","139.28400","11.60724","0.03469"
"23293","139.72200","11.64377","0.03476"
"23366","140.16000","11.68018","0.03446"
"23439","140.59800","11.71666","0.03507"
"23512","141.03600","11.75325","0.03465"
"23585","141.47400","11.78972","0.03564"
"23658","141.91200","11.82619","0.03578"
"23731","142.35000","11.86272","0.03613"
"23804","142.78800","11.89913","0.03591"
"23877","143.22600","11.93566","0.03685"
"23950","143.66400","11.97220","0.03606"
"24023","144.10200","12.00873","0.03620"
"24096","144.54000","12.04526","0.03652"
"24169","144.97800","12.08161","0.03569"
"24242","145.41600","12.11820","0.03617"
"24315","145.85400","12.15467","0.03681"
"24388","146.29200","12.19121","0.03708"
"24461","146.73000","12.22768","0.03624"
"24534","147.16800","12.26421","0.03617"
"24607","147.60600","12.30062","0.03604"
"24680","148.04400","12.33721","0.03768"
"24753","148.48200","12.37374","0.03849"
"24826","148.92000","12.41027","0.03794"
"24899","149.35800","12.44669","0.03811"
"24972","149.79600","12.48316","0.03895"
"25045","150.23400","12.51969","0.03943"
"25118","150.67200","12.55622","0.04043"
"25191","151.11000","12.59269","0.04011"
"25264","151.54800","12.62922","0.04123"
"25337","151.98600","12.66569","0.04203"
"25410","152.42400","12.70217","0.04134"
"25483","152.86200","12.73870","0.04126"
"25556","153.30000","12.77523","0.04202"
"25629","153.73800","12.81176","0.04252"
"25702","154.17600","12.84817","0.04251"
"25775","154.61400","12.88464","0.04380"
"25848","155.05200","12.92118","0.04440"
"25921","155.49000","12.95771","0.04448"
"25994","155.92800","12.99424","0.04496"
"26067","156.36600","13.03071","0.04478"
"26140","156.80400","13.06718","0.04613"
"26213","157.24200","13.10365","0.04653"
"26286","157.68000","13.14018","0.04731"
"26359","158.11800","13.17678","0.04742"
"26432","158.55600","13.21331","0.04764"
"26505","158.99400","13.24972","0.04846"
"26578","159.43200","13.28619","0.04895"
"26651","159.87000","13.32266","0.04971"
"26724","160.30800","13.35919","0.04971"
"26797","160.74600","13.39573","0.04956"
"26870","161.18400","13.43220","0.05065"
"26943","161.62200","13.46867","0.05139"
"27016","162.06000","13.50520","0.05176"
"27089","162.49800","13.54173","0.05210"
"27162","162.93600","13.57820","0.05300"
"27235","163.37400","13.61467","0.05286"
"27308","163.81200","13.65121","0.05382"
"27381","164.25000","13.68768","0.05387"
"27454","164.68800","13.72427","0.05440"
"27527","165.12600","13.76068","0.05576"
"27600","165.56400","13.79727","0.05684"
"27673","166.00200","13.83374","0.05646"
"27746","166.44000","13.87016","0.05690"
"27819","166.87800","13.90675","0.05806"
"27892","167.31600","13.94322","0.05779"
"27965","167.75400","13.97969","0.05921"
"28038","168.19200","14.01616","0.06056"
"28111","168.63000","14.05269","0.06045"
"28184","169.06800","14.08916","0.06188"
"28257","169.50600","14.12570","0.06201"
"28330","169.94400","14.16223","0.06117"
"28403","170.38200","14.19870","0.06275"
"28476","170.82000","14.23517","0.06378"
"28549","171.25800","14.27164","0.06499"
"28622","171.69600","14.30817","0.06575"
"28695","172.13400","14.34477","0.06670"
"28768","172.57200","14.38118","0.06795"
"28841","173.01000","14.41771","0.06851"
"28914","173.44800","14.45418","0.06941"
"28987","173.88600","14.49071","0.06912"
"29060","174.32400","14.52718","0.07021"
"29133","174.76200","14.56378","0.07078"
"29206","175.20000","14.60025","0.07140"
"29279","175.63800","14.63672","0.07191"
"29352","176.07600","14.67319","0.07198"
"29425","176.51400","14.70966","0.07341"
"29498","176.95200","14.74619","0.07074"
"29571","177.39000","14.78272","0.07275"
"29644","177.82800","14.81920","0.07404"
"29717","178.26600","14.85567","0.07386"
"29790","178.70400","14.89220","0.07566"
"29863","179.14200","14.92873","0.07611"
"29936","179.58000","14.96520","0.07677"
"30009","180.01800","15.00173","0.07727"
"30082","180.45600","15.03815","0.07761"
"30155","180.89400","15.07468","0.07872"
"30228","181.33200","15.11127","0.07908"
"30301","181.77000","15.14774","0.07916"
"30374","182.20800","15.18421","0.08020"
"30447","182.64600","15.22074","0.07991"
"30520","183.08400","15.25721","0.08050"
"30593","183.52200","15.29368","0.08065"
"30666","183.96000","15.33022","0.08122"
"30739","184.39800","15.36675","0.08207"
"30812","184.83600","15.40322","0.08277"
"30885","185.27400","15.43969","0.08326"
"30958","185.71200","15.47622","0.08312"
"31031","186.15000","15.51275","0.08399"
"31104","186.58800","15.54923","0.08507"
"31177","187.02600","15.58570","0.08635"
"31250","187.46400","15.62211","0.08657"
"31323","187.90200","15.65864","0.08851"
"31396","188.34000","15.69523","0.08988"
"31469","188.77800","15.73176","0.09170"
"31542","189.21600","15.76817","0.09424"
"31615","189.65400","15.80464","0.09513"
"31688","190.09200","15.84118","0.09773"
"31761","190.53000","15.87771","0.09889"
"31834","190.96800","15.91424","0.10012"
"31907","191.40600","15.95077","0.10069"
"31980","191.84400","15.98718","0.10222"
"32053","192.28200","16.02371","0.10379"
"32126","192.72000","16.06019","0.10629"
"32199","193.15800","16.09672","0.10769"
"32272","193.59600","16.13325","0.10944"
"32345","194.03400","16.16966","0.11070"
"32418","194.47200","16.20613","0.11255"
"32491","194.91000","16.24266","0.11444"
"32564","195.34800","16.27919","0.11666"
"32637","195.78600","16.31567","0.11952"
"32710","196.22400","16.35220","0.12149"
"32783","196.66200","16.38867","0.12286"
"32856","197.10000","16.42520","0.12577"
"32929","197.53800","16.46167","0.12890"
"33002","197.97600","16.49826","0.12950"
"33075","198.41400","16.53473","0.13120"
"33148","198.85200","16.57121","0.12826"
"33221","199.29000","16.60768","0.12936"
"33294","199.72800","16.64415","0.13048"
"33367","200.16600","16.68074","0.13205"
"33440","200.60400","16.71721","0.13276"
"33513","201.04200","16.75374","0.13189"
"33586","201.48000","16.79022","0.13224"
"33659","201.91800","16.82669","0.13305"
"33732","202.35600","16.86316","0.13388"
"33805","202.79400","16.89975","0.13353"
"33878","203.23200","16.93622","0.13452"
"33951","203.67000","16.97269","0.13575"
"34024","204.10800","17.00911","0.13899"
"34097","204.54600","17.04570","0.14094"
"34170","204.98400","17.08223","0.14462"
"34243","205.42200","17.11876","0.14911"
"34316","205.86000","17.15523","0.15239"
"34389","206.29800","17.19164","0.15534"
"34462","206.73600","17.22817","0.15815"
"34535","207.17400","17.26476","0.16084"
"34608","207.61200","17.30124","0.16314"
"34681","208.05000","17.33777","0.16523"
"34754","208.48800","17.37418","0.16740"
"34827","208.92600","17.41065","0.16882"
"34900","209.36400","17.44724","0.16993"
"34973","209.80200","17.48372","0.17167"
"35046","210.24000","17.52025","0.17273"
"35119","210.67800","17.55672","0.17449"
"35192","211.11600","17.59313","0.17601"
"35265","211.55400","17.62960","0.17736"
"35338","211.99200","17.66625","0.17936"
"35411","212.43000","17.70272","0.18137"
"35484","212.86800","17.73926","0.18256"
"35557","213.30600","17.77567","0.18512"
"35630","213.74400","17.81214","0.18715"
"35703","214.18200","17.84867","0.19081"
"35776","214.62000","17.88526","0.19379"
"35849","215.05800","17.92173","0.19913"
"35922","215.49600","17.95820","0.20509"
"35995","215.93400","17.99468","0.21187"
"36068","216.37200","18.03121","0.21953"
"36141","216.81000","18.06774","0.22583"
"36214","217.24800","18.10427","0.23033"
"36287","217.68600","18.14074","0.23445"
"36360","218.12400","18.17715","0.23561"
"36433","218.56200","18.21369","0.23679"
"36506","219.00000","18.25016","0.24027"
"36579","219.43800","18.28669","0.24274"
"36652","219.87600","18.32322","0.23642"
"36725","220.31400","18.35969","0.23441"
"36798","220.75200","18.39616","0.23496"
"36871","221.19000","18.43263","0.23459"
"36944","221.62800","18.46922","0.23184"
"37017","222.06600","18.50570","0.23102"
"37090","222.50400","18.54223","0.22860"
"37163","222.94200","18.57864","0.23334"
"37236","223.38000","18.61523","0.23548"
"37309","223.81800","18.65176","0.23700"
"37382","224.25600","18.68824","0.23897"
"37455","224.69400","18.72471","0.23972"
"37528","225.13200","18.76124","0.24020"
"37601","225.57000","18.79765","0.24201"
"37674","226.00800","18.83418","0.24571"
"37747","226.44600","18.87071","0.25082"
"37820","226.88400","18.90724","0.25567"
"37893","227.32200","18.94366","0.26037"
"37966","227.76000","18.98013","0.26522"
"38039","228.19800","19.01666","0.26930"
"38112","228.63600","19.05319","0.27297"
"38185","229.07400","19.08972","0.27659"
"38258","229.51200","19.12619","0.27936"
"38331","229.95000","19.16261","0.28060"
"38404","230.38800","19.19920","0.28222"
"38477","230.82600","19.23573","0.28326"
"38550","231.26400","19.27226","0.28453"
"38623","231.70200","19.30867","0.28606"
"38696","232.14000","19.34520","0.28766"
"38769","232.57800","19.38167","0.28961"
"38842","233.01600","19.41821","0.29254"
"38915","233.45400","19.45474","0.29634"
"38988","233.89200","19.49127","0.28831"
"39061","234.33000","19.52768","0.28786"
"39134","234.76800","19.56415","0.28698"
"39207","235.20600","19.60074","0.28947"
"39280","235.64400","19.63721","0.29281"
"39353","236.08200","19.67369","0.29673"
"39426","236.52000","19.71022","0.30080"
"39499","236.95800","19.74669","0.30685"
"39572","237.39600","19.78322","0.31286"
"39645","237.83400","19.81969","0.31774"
"39718","238.27200","19.85616","0.32286"
"39791","238.71000","19.89270","0.32711"
"39864","239.14800","19.92917","0.33055"
"39937","239.58600","19.96570","0.33286"
"40010","240.02400","20.00223","0.33481"
"40083","240.46200","20.03876","0.33953"
"40156","240.90000","20.07523","0.34505"
"40229","241.33800","20.11170","0.35423"
"40302","241.77600","20.14818","0.36066"
"40375","242.21400","20.18471","0.36496"
"40448","242.65200","20.22124","0.37149"
"40521","243.09000","20.25771","0.37801"
"40594","243.52800","20.29418","0.38250"
"40667","243.96600","20.33065","0.38604"
"40740","244.40400","20.36719","0.38905"
"40813","244.84200","20.40366","0.39064"
"40886","245.28000","20.44025","0.39205"
"40959","245.71800","20.47672","0.39345"
"41032","246.15600","20.51319","0.39525"
"41105","246.59400","20.54966","0.39750"
"41178","247.03200","20.58619","0.39933"
"41251","247.47000","20.62272","0.40176"
"41324","247.90800","20.65926","0.40514"
"41397","248.34600","20.69573","0.40836"
"41470","248.78400","20.73220","0.41293"
"41543","249.22200","20.76867","0.41746"
"41616","249.66000","20.80520","0.42296"
"41689","250.09800","20.84173","0.39606"
"41762","250.53600","20.87820","0.39599"
"41835","250.97400","20.91467","0.39894"
"41908","251.41200","20.95115","0.40269"
"41981","251.85000","20.98774","0.40854"
"42054","252.28800","21.02421","0.41278"
"42127","252.72600","21.06075","0.42179"
"42200","253.16400","21.09715","0.42895"
"42273","253.60200","21.13363","0.43444"
"42346","254.04000","21.17016","0.43837"
"42419","254.47800","21.20669","0.44071"
"42492","254.91600","21.24322","0.44355"
"42565","255.35400","21.27975","0.44845"
"42638","255.79200","21.31617","0.45340"
"42711","256.23000","21.35270","0.45876"
"42784","256.66800","21.38923","0.46396"
"42857","257.10600","21.42576","0.46845"
"42930","257.54400","21.46223","0.47223"
"43003","257.98200","21.49870","0.46619"
"43076","258.42000","21.53517","0.46747"
"43149","258.85800","21.57176","0.47060"
"43222","259.29600","21.60824","0.47474"
"43295","259.73400","21.64471","0.47720"
"43368","260.17200","21.68118","0.47947"
"43441","260.61000","21.71765","0.48157"
"43514","261.04800","21.75418","0.48442"
"43587","261.48600","21.79071","0.48755"
"43660","261.92400","21.82724","0.49033"
"43733","262.36200","21.86366","0.49383"
"43806","262.80000","21.90013","0.49799"
"43879","263.23800","21.93666","0.50236"
"43952","263.67600","21.97319","0.50856"
"44025","264.11400","22.00972","0.51468"
"44098","264.55200","22.04620","0.52024"
"44171","264.99000","22.08273","0.52554"
"44244","265.42800","22.11914","0.52994"
"44317","265.86600","22.15573","0.53495"
"44390","266.30400","22.19226","0.53824"
"44463","266.74200","22.22873","0.54092"
"44536","267.18000","22.26514","0.54196"
"44609","267.61800","22.30168","0.54382"
"44682","268.05600","22.33815","0.54983"
"44755","268.49400","22.37474","0.55619"
"44828","268.93200","22.41121","0.56350"
"44901","269.37000","22.44774","0.57006"
"44974","269.80800","22.48421","0.57613"
"45047","270.24600","22.52069","0.58149"
"45120","270.68400","22.55716","0.58570"
"45193","271.12200","22.59375","0.58914"
"45266","271.56000","22.63022","0.59171"
"45339","271.99800","22.66669","0.59504"
"45412","272.43600","22.70310","0.59726"
"45485","272.87400","22.73969","0.59936"
"45558","273.31200","22.77622","0.59826"
"45631","273.75000","22.81276","0.60073"
"45704","274.18800","22.84923","0.60291"
"45777","274.62600","22.88570","0.60486"
"45850","275.06400","22.92211","0.60710"
"45923","275.50200","22.95876","0.61042"
"45996","275.94000","22.99523","0.61473"
"46069","276.37800","23.03170","0.62179"
"46142","276.81600","23.06818","0.62934"
"46215","277.25400","23.10465","0.63734"
"46288","277.69200","23.14118","0.64250"
"46361","278.13000","23.17771","0.64599"
"46434","278.56800","23.21418","0.65040"
"46507","279.00600","23.25071","0.65483"
"46580","279.44400","23.28713","0.66205"
"46653","279.88200","23.32366","0.66979"
"46726","280.32000","23.36019","0.67498"
"46799","280.75800","23.39672","0.67970"
"46872","281.19600","23.43325","0.68415"
"46945","281.63400","23.46966","0.68759"
"47018","282.07200","23.50620","0.69015"
"47091","282.51000","23.54273","0.69157"
"47164","282.94800","23.57920","0.69280"
"47237","283.38600","23.61579","0.69503"
"47310","283.82400","23.65220","0.69717"
"47383","284.26200","23.68867","0.69955"
"47456","284.70000","23.72520","0.70241"
"47529","285.13800","23.76174","0.70650"
"47602","285.57600","23.79815","0.70914"
"47675","286.01400","23.83468","0.71499"
"47748","286.45200","23.87121","0.72193"
"47821","286.89000","23.90774","0.72746"
"47894","287.32800","23.94421","0.73454"
"47967","287.76600","23.98068","0.74155"
"48040","288.20400","24.01722","0.74771"
"48113","288.64200","24.05375","0.75112"
"48186","289.08000","24.09016","0.75209"
"48259","289.51800","24.12669","0.75445"
"48332","289.95600","24.16316","0.75917"
"48405","290.39400","24.19975","0.76761"
"48478","290.83200","24.23623","0.77438"
"48551","291.27000","24.27270","0.78144"
"48624","291.70800","24.30923","0.78787"
"48697","292.14600","24.34570","0.79385"
"48770","292.58400","24.38223","0.79822"
"48843","293.02200","24.41870","0.80132"
"48916","293.46000","24.45517","0.80436"
"48989","293.89800","24.49171","0.80628"
"49062","294.33600","24.52830","0.80844"
"49135","294.77400","24.56471","0.81168"
"49208","295.21200","24.60124","0.81551"
"49281","295.65000","24.63765","0.82061"
"49354","296.08800","24.67418","0.82570"
"49427","296.52600","24.71066","0.82681"
"49500","296.96400","24.74725","0.83245"
"49573","297.40200","24.78372","0.83914"
"49646","297.84000","24.82025","0.84288"
"49719","298.27800","24.85660","0.84613"
"49792","298.71600","24.89319","0.85233"
"49865","299.15400","24.92978","0.86025"
"49938","299.59200","24.96626","0.86897"
"50011","300.03000","25.00273","0.87787"
"50084","300.46800","25.03920","0.88507"
"50157","300.90600","25.07567","0.89215"
"50230","301.34400","25.11226","0.89825"
"50303","301.78200","25.14874","0.90218"
"50376","302.22000","25.18526","0.90382"
"50449","302.65800","25.22168","0.90485"
"50522","303.09600","25.25815","0.90622"
"50595","303.53400","25.29474","0.90809"
"50668","303.97200","25.33121","0.91083"
"50741","304.41000","25.36768","0.91435"
"50814","304.84800","25.40421","0.81783"
"50887","305.28600","25.44063","0.81542"
"50960","305.72400","25.47716","0.81819"
"51033","306.16200","25.51375","0.82076"
"51106","306.60000","25.55022","0.82486"
"51179","307.03800","25.58675","0.82727"
"51252","307.47600","25.62316","0.83216"
"51325","307.91400","25.65969","0.83740"
"51398","308.35200","25.69629","0.84121"
"51471","308.79000","25.73276","0.84431"
"51544","309.22800","25.76923","0.84603"
"51617","309.66600","25.80570","0.84965"
"51690","310.10400","25.84211","0.85339"
"51763","310.54200","25.87871","0.85398"
"51836","310.98000","25.91518","0.85926"
"51909","311.41800","25.95171","0.86409"
"51982","311.85600","25.98824","0.87168"
"52055","312.29400","26.02465","0.87954"
"52128","312.73200","26.06118","0.88831"
"52201","313.17000","26.09771","0.89476"
"52274","313.60800","26.13419","0.90001"
"52347","314.04600","26.17072","0.90347"
"52420","314.48400","26.20719","0.90451"
"52493","314.92200","26.24366","0.90514"
"52566","315.36000","26.28019","0.90584"
"52639","315.79800","26.31672","0.90678"
"52712","316.23600","26.35325","0.90822"
"52785","316.67400","26.38979","0.90990"
"52858","317.11200","26.42614","0.91157"
"52931","317.55000","26.46273","0.90739"
"53004","317.98800","26.49920","0.90725"
"53077","318.42600","26.53567","0.90829"
"53150","318.86400","26.57220","0.91024"
"53223","319.30200","26.60868","0.91274"
"53296","319.74000","26.64515","0.91524"
"53369","320.17800","26.68174","0.91902"
"53442","320.61600","26.71821","0.92321"
"53515","321.05400","26.75468","0.92859"
"53588","321.49200","26.79115","0.93340"
"53661","321.93000","26.82768","0.93886"
"53734","322.36800","26.86421","0.94452"
"53807","322.80600","26.90075","0.94996"
"53880","323.24400","26.93722","0.95417"
"53953","323.68200","26.97375","0.95659"
"54026","324.12000","27.01016","0.95935"
"54099","324.55800","27.04675","0.92056"
"54172","324.99600","27.08328","0.88247"
"54245","325.43400","27.11975","0.88436"
"54318","325.87200","27.15623","0.88819"
"54391","326.31000","27.19264","0.89451"
"54464","326.74800","27.22917","0.89805"
"54537","327.18600","27.26570","0.90077"
"54610","327.62400","27.30223","0.90175"
"54683","328.06200","27.33870","0.90341"
"54756","328.50000","27.37518","0.90426"
"54829","328.93800","27.41165","0.90488"
"54902","329.37600","27.44818","0.90559"
"54975","329.81400","27.48471","0.76502"
"55048","330.25200","27.52124","0.73083"
"55121","330.69000","27.55771","0.72522"
"55194","331.12800","27.59418","0.72261"
"55267","331.56600","27.63066","0.72202"
"55340","332.00400","27.66725","0.72240"
"55413","332.44200","27.70372","0.72321"
"55486","332.88000","27.74025","0.71276"
"55559","333.31800","27.77672","0.71050"
"55632","333.75600","27.81313","0.71054"
"55705","334.19400","27.84973","0.71200"
"55778","334.63200","27.88626","0.71309"
"55851","335.07000","27.92273","0.71261"
"55924","335.50800","27.95920","0.53826"
"55997","335.94600","27.99567","0.53863"
"56070","336.38400","28.03214","0.53751"
"56143","336.82200","28.06874","0.53876"
"56216","337.26000","28.10514","0.53636"
"56289","337.69800","28.14168","0.02273"
"56362","338.13600","28.17815","0.01948"
"56435","338.57400","28.21468","0.02034"
"56508","339.01200","28.25115","0.01964"
"56581","339.45000","28.28774","0.01935"
"56654","339.88800","28.32422","0.01748"
"56727","340.32600","28.36069","0.01954"
"56800","340.76400","28.39716","0.02194"
"56873","341.20200","28.43375","0.02125"
"56946","341.64000","28.47022","0.02171"
"57019","342.07800","28.50675","0.01913"
"57092","342.51600","28.54323","0.01878"
"57165","342.95400","28.57964","0.01948"
"57238","343.39200","28.61617","0.01975"
"57311","343.83000","28.65270","0.02130"
"57384","344.26800","28.68917","0.02091"
"57457","344.70600","28.72570","0.02052"
"57530","345.14400","28.76217","0.02064"
"57603","345.58200","28.79865","0.02039"
"57676","346.02000","28.83518","0.01985"
"57749","346.45800","28.87171","0.02037"
"57822","346.89600","28.90824","0.02118"
"57895","347.33400","28.94471","0.02145"
"57968","347.77200","28.98118","0.02184"
"58041","348.21000","29.01771","0.02142"
"58114","348.64800","29.05425","0.02184"
"58187","349.08600","29.09072","0.02133"
"58260","349.52400","29.12725","0.02145"
"58333","349.96200","29.16372","0.02175"
"58406","350.40000","29.20019","0.02221"
"58479","350.83800","29.23672","0.02191"
"58552","351.27600","29.27326","0.02208"
"58625","351.71400","29.30973","0.02297"
"58698","352.15200","29.34620","0.02251"
"58771","352.59000","29.38267","0.02320"
"58844","353.02800","29.41920","0.02346"
"58917","353.46600","29.45573","0.02354"
"58990","353.90400","29.49215","0.02355"
"59063","354.34200","29.52868","0.02375"
"59136","354.78000","29.56515","0.02436"
"59209","355.21800","29.60174","0.02452"
"59282","355.65600","29.63815","0.02450"
"59355","356.09400","29.67474","0.02465"
"59428","356.53200","29.71121","0.02487"
"59501","356.97000","29.74768","0.02612"
"59574","357.40800","29.78422","0.02549"
"59647","357.84600","29.82075","0.02619"
"59720","358.28400","29.85722","0.02631"
"59793","358.72200","29.89375","0.02664"
"59866","359.16000","29.93022","0.02737"
"59939","359.59800","29.96669","0.02745"
"60012","360.03600","30.00323","0.02722"
"60085","360.47400","30.03975","0.02837"
"60158","360.91200","30.07623","0.02878"
"60231","361.35000","30.11270","0.02933"
"60304","361.78800","30.14917","0.02925"
"60377","362.22600","30.18564","0.02910"
"60450","362.66400","30.22223","0.03063"
"60523","363.10200","30.25871","0.03030"
"60596","363.54000","30.29524","0.03089"
"60669","363.97800","30.33171","0.03186"
"60742","364.41600","30.36818","0.03238"
"60815","364.85400","30.40471","0.03232"
"60888","365.29200","30.44124","0.03269"
"60961","365.73000","30.47777","0.03334"
"61034","366.16800","30.51419","0.03435"
"61107","366.60600","30.55066","0.03525"
"61180","367.04400","30.58719","0.03619"
"61253","367.48200","30.62366","0.03588"
"61326","367.92000","30.66019","0.03707"
"61399","368.35800","30.69673","0.03761"
"61472","368.79600","30.73314","0.03734"
"61545","369.23400","30.76967","0.03865"
"61618","369.67200","30.80620","0.03857"
"61691","370.11000","30.84273","0.03905"
"61764","370.54800","30.87920","0.03893"
"61837","370.98600","30.91567","0.03952"
"61910","371.42400","30.95221","0.04005"
"61983","371.86200","30.98868","0.04098"
"62056","372.30000","31.02527","0.04105"
"62129","372.73800","31.06174","0.04174"
"62202","373.17600","31.09821","0.04185"
"62275","373.61400","31.13468","0.04260"
"62348","374.05200","31.17115","0.04352"
"62421","374.49000","31.20769","0.04330"
"62494","374.92800","31.24422","0.04338"
"62567","375.36600","31.28075","0.04387"
"62640","375.80400","31.31716","0.04430"
"62713","376.24200","31.35363","0.04455"
"62786","376.68000","31.39022","0.04478"
"62859","377.11800","31.42669","0.04503"
"62932","377.55600","31.46322","0.04482"
"63005","377.99400","31.49969","0.04467"
"63078","378.43200","31.53617","0.04592"
"63151","378.87000","31.57270","0.04573"
"63224","379.30800","31.60923","0.04615"
"63297","379.74600","31.64570","0.04652"
"63370","380.18400","31.68217","0.04718"
"63443","380.62200","31.71865","0.04735"
"63516","381.06000","31.75517","0.04834"
"63589","381.49800","31.79171","0.04873"
"63662","381.93600","31.82824","0.04860"
"63735","382.37400","31.86471","0.04943"
"63808","382.81200","31.90118","0.04994"
"63881","383.25000","31.93765","0.05053"
"63954","383.68800","31.97419","0.05074"
"64027","384.12600","32.01078","0.05165"
"64100","384.56400","32.04725","0.05234"
"64173","385.00200","32.08372","0.05225"
"64246","385.44000","32.12013","0.05309"
"64319","385.87800","32.15667","0.05366"
"64392","386.31600","32.19326","0.05433"
"64465","386.75400","32.22966","0.05458"
"64538","387.19200","32.26626","0.05545"
"64611","387.63000","32.30267","0.05643"
"64684","388.06800","32.33914","0.05774"
"64757","388.50600","32.37573","0.05837"
"64830","388.94400","32.41220","0.05820"
"64903","389.38200","32.44880","0.05769"
"64976","389.82000","32.48515","0.05768"
"65049","390.25800","32.52168","0.05838"
"65122","390.69600","32.55827","0.05898"
"65195","391.13400","32.59468","0.05882"
"65268","391.57200","32.63128","0.05856"
"65341","392.01000","32.66769","0.05882"
"65414","392.44800","32.70415","0.05896"
"65487","392.88600","32.74075","0.05951"
"65560","393.32400","32.77722","0.05947"
"65633","393.76200","32.81375","0.06037"
"65706","394.20000","32.85022","0.06179"
"65779","394.63800","32.88663","0.06243"
"65852","395.07600","32.92323","0.06276"
"65925","395.51400","32.95970","0.06299"
"65998","395.95200","32.99623","0.06208"
"66071","396.39000","33.03270","0.06003"
"66144","396.82800","33.06917","0.06080"
"66217","397.26600","33.10571","0.06086"
"66290","397.70400","33.14217","0.06256"
"66363","398.14200","33.17871","0.06321"
"66436","398.58000","33.21524","0.06443"
"66509","399.01800","33.25177","0.06382"
"66582","399.45600","33.28818","0.06501"
"66655","399.89400","33.32465","0.06500"
"66728","400.33200","33.36119","0.06583"
"66801","400.77000","33.39766","0.06592"
"66874","401.20800","33.43425","0.05922"
"66947","401.64600","33.47072","0.06026"
"67020","402.08400","33.50719","0.06117"
"67093","402.52200","33.54372","0.06212"
"67166","402.96000","33.58019","0.06213"
"67239","403.39800","33.61673","0.06320"
"67312","403.83600","33.65319","0.06358"
"67385","404.27400","33.68967","0.06505"
"67458","404.71200","33.72620","0.06493"
"67531","405.15000","33.76273","0.06538"
"67604","405.58800","33.79920","0.06609"
"67677","406.02600","33.83567","0.06687"
"67750","406.46400","33.87215","0.06663"
"67823","406.90200","33.90874","0.06764"
"67896","407.34000","33.94521","0.06855"
"67969","407.77800","33.98168","0.06867"
"68042","408.21600","34.01821","0.06949"
"68115","408.65400","34.05474","0.06904"
"68188","409.09200","34.09122","0.06949"
"68261","409.53000","34.12775","0.07035"
"68334","409.96800","34.16422","0.07156"
"68407","410.40600","34.20075","0.07172"
"68480","410.84400","34.23722","0.07209"
"68553","411.28200","34.27363","0.07244"
"68626","411.72000","34.31022","0.07309"
"68699","412.15800","34.34669","0.07295"
"68772","412.59600","34.38322","0.07414"
"68845","413.03400","34.41970","0.07457"
"68918","413.47200","34.45611","0.07420"
"68991","413.91000","34.49270","0.07485"
"69064","414.34800","34.52917","0.07418"
"69137","414.78600","34.56570","0.07451"
"69210","415.22400","34.60224","0.07483"
"69283","415.66200","34.63865","0.07518"
"69356","416.10000","34.67518","0.07605"
"69429","416.53800","34.71177","0.07629"
"69502","416.97600","34.74824","0.07642"
"69575","417.41400","34.78477","0.07691"
"69648","417.85200","34.82119","0.07609"
"69721","418.29000","34.85766","0.07663"
"69794","418.72800","34.89419","0.07722"
"69867","419.16600","34.93072","0.07625"
"69940","419.60400","34.96719","0.07719"
"70013","420.04200","35.00372","0.07780"
"70086","420.48000","35.04013","0.07822"
"70159","420.91800","35.07673","0.07820"
"70232","421.35600","35.11320","0.07863"
"70305","421.79400","35.14973","0.07901"
"70378","422.23200","35.18620","0.07921"
"70451","422.67000","35.22267","0.07941"
"70524","423.10800","35.25914","0.07912"
"70597","423.54600","35.29567","0.07963"
"70670","423.98400","35.33227","0.07980"
"70743","424.42200","35.36874","0.08066"
"70816","424.86000","35.40521","0.08014"
"70889","425.29800","35.44168","0.08041"
"70962","425.73600","35.47815","0.08072"
"71035","426.17400","35.51468","0.08065"
"71108","426.61200","35.55122","0.08116"
"71181","427.05000","35.58769","0.08130"
"71254","427.48800","35.62422","0.08152"
"71327","427.92600","35.66063","0.08175"
"71400","428.36400","35.69716","0.08058"
"71473","428.80200","35.73375","0.08086"
"71546","429.24000","35.77022","0.08051"
"71619","429.67800","35.80670","0.08119"
"71692","430.11600","35.84311","0.08179"
"71765","430.55400","35.87964","0.08175"
"71838","430.99200","35.91623","0.08112"
"71911","431.43000","35.95270","0.08162"
"71984","431.86800","35.98923","0.08228"
"72057","432.30600","36.02564","0.08255"
"72130","432.74400","36.06218","0.08248"
"72203","433.18200","36.09871","0.08265"
"72276","433.62000","36.13524","0.08315"
"72349","434.05800","36.17177","0.08331"
"72422","434.49600","36.20818","0.08289"
"72495","434.93400","36.24465","0.08309"
"72568","435.37200","36.28119","0.08296"
"72641","435.81000","36.31772","0.08333"
"72714","436.24800","36.35425","0.08326"
"72787","436.68600","36.39072","0.08343"
"72860","437.12400","36.42713","0.08375"
"72933","437.56200","36.46366","0.08396"
"73006","438.00000","36.50019","0.08446"
"73079","438.43800","36.53667","0.08484"
"73152","438.87600","36.57314","0.08435"
"73225","439.31400","36.60967","0.08422"
"73298","439.75200","36.64620","0.07830"
"73371","440.19000","36.68273","0.07906"
"73444","440.62800","36.71920","0.07891"
"73517","441.06600","36.75574","0.07849"
"73590","441.50400","36.79221","0.07888"
"73663","441.94200","36.82874","0.07940"
"73736","442.38000","36.86521","0.07903"
"73809","442.81800","36.90168","0.07952"
"73882","443.25600","36.93821","0.07914"
"73955","443.69400","36.97468","0.07907"
"74028","444.13200","37.01116","0.07950"
"74101","444.57000","37.04769","0.08005"
"74174","445.00800","37.08422","0.08032"
"74247","445.44600","37.12069","0.08032"
"74320","445.88400","37.15722","0.08039"
"74393","446.32200","37.19363","0.08093"
"74466","446.76000","37.23016","0.08105"
"74539","447.19800","37.26664","0.08141"
"74612","447.63600","37.30323","0.08213"
"74685","448.07400","37.33970","0.08220"
"74758","448.51200","37.37617","0.08214"
"74831","448.95000","37.41264","0.08238"
"74904","449.38800","37.44917","0.08227"
"74977","449.82600","37.48577","0.08188"
"75050","450.26400","37.52224","0.08236"
"75123","450.70200","37.55871","0.08275"
"75196","451.14000","37.59518","0.08284"
"75269","451.57800","37.63165","0.08270"
"75342","452.01600","37.66824","0.08240"
"75415","452.45400","37.70471","0.08302"
"75488","452.89200","37.74119","0.08286"
"75561","453.33000","37.77772","0.08258"
"75634","453.76800","37.81413","0.08277"
"75707","454.20600","37.85072","0.08271"
"75780","454.64400","37.88725","0.08245"
"75853","455.08200","37.92373","0.08292"
"75926","455.52000","37.96019","0.08333"
"75999","455.95800","37.99661","0.08341"
"76072","456.39600","38.03320","0.08310"
"76145","456.83400","38.06973","0.08323"
"76218","457.27200","38.10620","0.08352"
"76291","457.71000","38.14273","0.08392"
"76364","458.14800","38.17920","0.08378"
"76437","458.58600","38.21568","0.08418"
"76510","459.02400","38.25221","0.08351"
"76583","459.46200","38.28874","0.08291"
"76656","459.90000","38.32527","0.08330"
"76729","460.33800","38.36168","0.08307"
"76802","460.77600","38.39816","0.08345"
"76875","461.21400","38.43468","0.08389"
"76948","461.65200","38.47122","0.08442"
"77021","462.09000","38.50769","0.08505"
"77094","462.52800","38.54422","0.08490"
"77167","462.96600","38.58063","0.08526"
"77240","463.40400","38.61716","0.08540"
"77313","463.84200","38.65369","0.08580"
"77386","464.28000","38.69022","0.08583"
"77459","464.71800","38.72670","0.08623"
"77532","465.15600","38.76317","0.08713"
"77605","465.59400","38.79970","0.08761"
"77678","466.03200","38.83624","0.08845"
"77751","466.47000","38.87276","0.08871"
"77824","466.90800","38.90923","0.08885"
"77897","467.34600","38.94571","0.08978"
"77970","467.78400","38.98224","0.09031"
"78043","468.22200","39.01871","0.08985"
"78116","468.66000","39.05518","0.08921"
"78189","469.09800","39.09171","0.08472"
"78262","469.53600","39.12818","0.08436"
"78335","469.97400","39.16471","0.08469"
"78408","470.41200","39.20112","0.08517"
"78481","470.85000","39.23772","0.08591"
"78554","471.28800","39.27419","0.08633"
"78627","471.72600","39.31072","0.08682"
"78700","472.16400","39.34713","0.08721"
"78773","472.60200","39.38366","0.08771"
"78846","473.04000","39.42020","0.08783"
"78919","473.47800","39.45673","0.08904"
"78992","473.91600","39.49326","0.08887"
"79065","474.35400","39.52973","0.08950"
"79138","474.79200","39.56614","0.08997"
"79211","475.23000","39.60267","0.08915"
"79284","475.66800","39.63926","0.09067"
"79357","476.10600","39.67574","0.09182"
"79430","476.54400","39.71221","0.09223"
"79503","476.98200","39.74868","0.09303"
"79576","477.42000","39.78521","0.09318"
"79649","477.85800","39.82168","0.09518"
"79722","478.29600","39.85822","0.08913"
"79795","478.73400","39.89474","0.08879"
"79868","479.17200","39.93122","0.08806"
"79941","479.61000","39.96763","0.08836"
"80014","480.04800","40.00422","0.08871"
"80087","480.48600","40.04074","0.08919"
"80160","480.92400","40.07722","0.08894"
"80233","481.36200","40.11369","0.08920"
"80306","481.80000","40.15017","0.08926"
"80379","482.23800","40.18670","0.09053"
"80452","482.67600","40.22323","0.09125"
"80525","483.11400","40.25976","0.09239"
"80598","483.55200","40.29623","0.09250"
"80671","483.99000","40.33264","0.09311"
"80744","484.42800","40.36917","0.09415"
"80817","484.86600","40.40570","0.09416"
"80890","485.30400","40.44224","0.09470"
"80963","485.74200","40.47877","0.09642"
"81036","486.18000","40.51524","0.09785"
"81109","486.61800","40.55165","0.09832"
"81182","487.05600","40.58818","0.09930"
"81255","487.49400","40.62471","0.10032"
"81328","487.93200","40.66125","0.10128"
"81401","488.37000","40.69772","0.10292"
"81474","488.80800","40.73413","0.10328"
"81547","489.24600","40.77066","0.10360"
"81620","489.68400","40.80719","0.10468"
"81693","490.12200","40.84373","0.10538"
"81766","490.56000","40.88026","0.10626"
"81839","490.99800","40.91667","0.10683"
"81912","491.43600","40.95320","0.10694"
"81985","491.87400","40.98967","0.10774"
"82058","492.31200","41.02620","0.10867"
"82131","492.75000","41.06274","0.10857"
"82204","493.18800","41.09921","0.10784"
"82277","493.62600","41.13568","0.10908"
"82350","494.06400","41.17215","0.10925"
"82423","494.50200","41.20868","0.10979"
"82496","494.94000","41.24521","0.10996"
"82569","495.37800","41.28175","0.11044"
"82642","495.81600","41.31821","0.11142"
"82715","496.25400","41.35463","0.11267"
"82788","496.69200","41.39116","0.11314"
"82861","497.13000","41.42775","0.11342"
"82934","497.56800","41.46422","0.11270"
"83007","498.00600","41.50069","0.11256"
"83080","498.44400","41.53717","0.11247"
"83153","498.88200","41.57364","0.10779"
"83226","499.32000","41.61023","0.10769"
"83299","499.75800","41.64676","0.10455"
"83372","500.19600","41.68323","0.10338"
"83445","500.63400","41.71970","0.10188"
"83518","501.07200","41.75618","0.10146"
"83591","501.51000","41.79271","0.10208"
"83664","501.94800","41.82924","0.10238"
"83737","502.38600","41.86571","0.10370"
"83810","502.82400","41.90218","0.10449"
"83883","503.26200","41.93871","0.10448"
"83956","503.70000","41.97512","0.10528"
"84029","504.13800","42.01178","0.10556"
"84102","504.57600","42.04824","0.10646"
"84175","505.01400","42.08472","0.10701"
"84248","505.45200","42.12113","0.10736"
"84321","505.89000","42.15766","0.10627"
"84394","506.32800","42.19419","0.10787"
"84467","506.76600","42.23072","0.10783"
"84540","507.20400","42.26720","0.10569"
"84613","507.64200","42.30367","0.10618"
"84686","508.08000","42.34020","0.10728"
"84759","508.51800","42.37673","0.10766"
"84832","508.95600","42.41320","0.10873"
"84905","509.39400","42.44973","0.10862"
"84978","509.83200","42.48614","0.10958"
"85051","510.27000","42.52267","0.11047"
"85124","510.70800","42.55921","0.11096"
"85197","511.14600","42.59574","0.11241"
"85270","511.58400","42.63227","0.11304"
"85343","512.02200","42.66868","0.11275"
"85416","512.46000","42.70521","0.11152"
"85489","512.89800","42.74163","0.11175"
"85562","513.33600","42.77822","0.11145"
"85635","513.77400","42.81469","0.11053"
"85708","514.21200","42.85122","0.10741"
"85781","514.65000","42.88769","0.10720"
"85854","515.08800","42.92416","0.10697"
"85927","515.52600","42.96069","0.10918"
"86000","515.96400","42.99728","0.11040"
"86073","516.40200","43.03370","0.11165"
"86146","516.84000","43.07017","0.11284"
"86219","517.27800","43.10670","0.11326"
"86292","517.71600","43.14317","0.11372"
"86365","518.15400","43.17976","0.11446"
"86438","518.59200","43.21624","0.11539"
"86511","519.03000","43.25271","0.11589"
"86584","519.46800","43.28912","0.11729"
"86657","519.90600","43.32565","0.11530"
"86730","520.34400","43.36218","0.11528"
"86803","520.78200","43.39871","0.11384"
"86876","521.22000","43.43518","0.11403"
"86949","521.65800","43.47166","0.11491"
"87022","522.09600","43.50813","0.11535"
"87095","522.53400","43.54466","0.11546"
"87168","522.97200","43.58125","0.11467"
"87241","523.41000","43.61772","0.11482"
"87314","523.84800","43.65419","0.11469"
"87387","524.28600","43.69066","0.11352"
"87460","524.72400","43.72720","0.11319"
"87533","525.16200","43.76378","0.11420"
"87606","525.60000","43.80020","0.11423"
"87679","526.03800","43.83673","0.11489"
"87752","526.47600","43.87320","0.11600"
"87825","526.91400","43.90967","0.11645"
"87898","527.35200","43.94621","0.11739"
"87971","527.79000","43.98268","0.11810"
"88044","528.22800","44.01921","0.11916"
"88117","528.66600","44.05568","0.12088"
"88190","529.10400","44.09215","0.12012"
"88263","529.54200","44.12868","0.12086"
"88336","529.98000","44.16521","0.12129"
"88409","530.41800","44.20169","0.11992"
"88482","530.85600","44.23822","0.12177"
"88555","531.29400","44.27463","0.12340"
"88628","531.73200","44.31122","0.12333"
"88701","532.17000","44.34769","0.12419"
"88774","532.60800","44.38428","0.12588"
"88847","533.04600","44.42069","0.12648"
"88920","533.48400","44.45717","0.12806"
"88993","533.92200","44.49370","0.12904"
"89066","534.36000","44.53022","0.12517"
"89139","534.79800","44.56676","0.12607"
"89212","535.23600","44.60323","0.12814"
"89285","535.67400","44.63970","0.12984"
"89358","536.11200","44.67617","0.13074"
"89431","536.55000","44.71271","0.13115"
"89504","536.98800","44.74923","0.12940"
"89577","537.42600","44.78571","0.12957"
"89650","537.86400","44.82218","0.13018"
"89723","538.30200","44.85865","0.13030"
"89796","538.74000","44.89512","0.13133"
"89869","539.17800","44.93172","0.13206"
"89896","539.33600","44.94481","0.13196"