File: Trajectories_together/170122_2Specimen_RawData_5.csv
"","V1","V2","V3"
"1","End date","1/22/2017",""
"2","Specimen label","12CG_94",""
"3","Maximum Load","0.94534","N"
"4","Time","Extension","Load"
"5","(s)","(mm)","(N)"
"6","0.00000","0.00000","0.00067"
"76","0.42000","0.03516","0.00332"
"146","0.84000","0.07013","0.00664"
"216","1.26000","0.10517","0.00894"
"286","1.68000","0.14009","0.01146"
"356","2.10000","0.17506","0.01429"
"426","2.52000","0.21010","0.01774"
"496","2.94000","0.24514","0.01901"
"566","3.36000","0.28011","0.02138"
"636","3.78000","0.31515","0.02456"
"706","4.20000","0.35013","0.02571"
"776","4.62000","0.38510","0.02626"
"846","5.04000","0.42008","0.02757"
"916","5.46000","0.45518","0.02921"
"986","5.88000","0.49009","0.03029"
"1056","6.30000","0.52513","0.02942"
"1126","6.72000","0.56011","0.03009"
"1196","7.14000","0.59509","0.03086"
"1266","7.56000","0.63012","0.03196"
"1336","7.98000","0.66510","0.03197"
"1406","8.40000","0.70014","0.03281"
"1476","8.82000","0.73517","0.03299"
"1546","9.24000","0.77021","0.03354"
"1616","9.66000","0.80513","0.03451"
"1686","10.08000","0.84010","0.03430"
"1756","10.50000","0.87520","0.03495"
"1826","10.92000","0.91018","0.03541"
"1896","11.34000","0.94509","0.03526"
"1966","11.76000","0.98013","0.03558"
"2036","12.18000","1.01517","0.03609"
"2106","12.60000","1.05014","0.03660"
"2176","13.02000","1.08518","0.03668"
"2246","13.44000","1.12010","0.03730"
"2316","13.86000","1.15507","0.03733"
"2386","14.28000","1.19011","0.03765"
"2456","14.70000","1.22515","0.03768"
"2526","15.12000","1.26012","0.03820"
"2596","15.54000","1.29504","0.03831"
"2666","15.96000","1.33014","0.03866"
"2736","16.38000","1.36511","0.03848"
"2806","16.80000","1.40015","0.03910"
"2876","17.22000","1.43513","0.04005"
"2946","17.64000","1.47011","0.03980"
"3016","18.06000","1.50514","0.03962"
"3086","18.48000","1.54018","0.04017"
"3156","18.90000","1.57510","0.04119"
"3226","19.32000","1.61007","0.04103"
"3296","19.74000","1.64511","0.04111"
"3366","20.16000","1.68021","0.04162"
"3436","20.58000","1.71512","0.04157"
"3506","21.00000","1.75010","0.04194"
"3576","21.42000","1.78514","0.04176"
"3646","21.84000","1.82011","0.04222"
"3716","22.26000","1.85515","0.04269"
"3786","22.68000","1.89019","0.04293"
"3856","23.10000","1.92510","0.04327"
"3926","23.52000","1.96014","0.04296"
"3996","23.94000","1.99512","0.04347"
"4066","24.36000","2.03009","0.04435"
"4136","24.78000","2.06519","0.04416"
"4206","25.20000","2.10005","0.04451"
"4276","25.62000","2.13514","0.04506"
"4346","26.04000","2.17012","0.04569"
"4416","26.46000","2.20516","0.04439"
"4486","26.88000","2.24013","0.04486"
"4556","27.30000","2.27511","0.04533"
"4626","27.72000","2.31015","0.04597"
"4696","28.14000","2.34518","0.04583"
"4766","28.56000","2.38016","0.04612"
"4836","28.98000","2.41508","0.04653"
"4906","29.40000","2.45012","0.04788"
"4976","29.82000","2.48515","0.04791"
"5046","30.24000","2.52013","0.04706"
"5116","30.66000","2.55511","0.04725"
"5186","31.08000","2.59014","0.04786"
"5256","31.50000","2.62512","0.04849"
"5326","31.92000","2.66016","0.04801"
"5396","32.34000","2.69513","0.04719"
"5466","32.76000","2.73011","0.04800"
"5536","33.18000","2.76509","0.04869"
"5606","33.60000","2.80018","0.04818"
"5676","34.02000","2.83522","0.04905"
"5746","34.44000","2.87014","0.04963"
"5816","34.86000","2.90511","0.04922"
"5886","35.28000","2.94009","0.04971"
"5956","35.70000","2.97513","0.04997"
"6026","36.12000","3.01010","0.04962"
"6096","36.54000","3.04508","0.05099"
"6166","36.96000","3.08012","0.05074"
"6236","37.38000","3.11515","0.05115"
"6306","37.80000","3.15013","0.05165"
"6376","38.22000","3.18511","0.05190"
"6446","38.64000","3.22014","0.05184"
"6516","39.06000","3.25512","0.05224"
"6586","39.48000","3.29016","0.05221"
"6656","39.90000","3.32520","0.05292"
"6726","40.32000","3.36011","0.05304"
"6796","40.74000","3.39509","0.05319"
"6866","41.16000","3.43013","0.05351"
"6936","41.58000","3.46510","0.05439"
"7006","42.00000","3.50014","0.05338"
"7076","42.42000","3.53506","0.05436"
"7146","42.84000","3.57009","0.05449"
"7216","43.26000","3.60519","0.05456"
"7286","43.68000","3.64017","0.05484"
"7356","44.10000","3.67514","0.05531"
"7426","44.52000","3.71012","0.05583"
"7496","44.94000","3.74516","0.05572"
"7566","45.36000","3.78019","0.05582"
"7636","45.78000","3.81517","0.05614"
"7706","46.20000","3.85009","0.05619"
"7776","46.62000","3.88512","0.05644"
"7846","47.04000","3.92010","0.05568"
"7916","47.46000","3.95514","0.05639"
"7986","47.88000","3.99011","0.05619"
"8056","48.30000","4.02509","0.05668"
"8126","48.72000","4.06013","0.05680"
"8196","49.14000","4.09510","0.05603"
"8266","49.56000","4.13014","0.05642"
"8336","49.98000","4.16506","0.05667"
"8406","50.40000","4.20015","0.05748"
"8476","50.82000","4.23519","0.05692"
"8546","51.24000","4.27017","0.05830"
"8616","51.66000","4.30515","0.05753"
"8686","52.08000","4.34012","0.05796"
"8756","52.50000","4.37510","0.05794"
"8826","52.92000","4.41014","0.05784"
"8896","53.34000","4.44511","0.05686"
"8966","53.76000","4.48009","0.05738"
"9036","54.18000","4.51513","0.05805"
"9106","54.60000","4.55016","0.05790"
"9176","55.02000","4.58514","0.05777"
"9246","55.44000","4.62012","0.05787"
"9316","55.86000","4.65509","0.05860"
"9386","56.28000","4.69013","0.05872"
"9456","56.70000","4.72517","0.05887"
"9526","57.12000","4.76020","0.05946"
"9596","57.54000","4.79512","0.05975"
"9666","57.96000","4.83010","0.05980"
"9736","58.38000","4.86513","0.05995"
"9806","58.80000","4.90011","0.06047"
"9876","59.22000","4.93515","0.06038"
"9946","59.64000","4.97006","0.06095"
"10016","60.06000","5.00516","0.06129"
"10086","60.48000","5.04014","0.06126"
"10156","60.90000","5.07517","0.06142"
"10226","61.32000","5.11009","0.06154"
"10296","61.74000","5.14507","0.06178"
"10366","62.16000","5.18017","0.06148"
"10436","62.58000","5.21520","0.06192"
"10506","63.00000","5.25012","0.06212"
"10576","63.42000","5.28510","0.06222"
"10646","63.84000","5.32013","0.06250"
"10716","64.26000","5.35517","0.06279"
"10786","64.68000","5.39015","0.06241"
"10856","65.10000","5.42512","0.06267"
"10926","65.52000","5.46016","0.06259"
"10996","65.94000","5.49514","0.06252"
"11066","66.36000","5.53011","0.06244"
"11136","66.78000","5.56509","0.06218"
"11206","67.20000","5.60007","0.06163"
"11276","67.62000","5.63510","0.06242"
"11346","68.04000","5.67014","0.06232"
"11416","68.46000","5.70518","0.06268"
"11486","68.88000","5.74015","0.06285"
"11556","69.30000","5.77507","0.06292"
"11626","69.72000","5.81017","0.06303"
"11696","70.14000","5.84514","0.06339"
"11766","70.56000","5.88006","0.06352"
"11836","70.98000","5.91504","0.06354"
"11906","71.40000","5.95008","0.06344"
"11976","71.82000","5.98517","0.06384"
"12046","72.24000","6.02015","0.06384"
"12116","72.66000","6.05513","0.06404"
"12186","73.08000","6.09010","0.06407"
"12256","73.50000","6.12514","0.06423"
"12326","73.92000","6.16017","0.06464"
"12396","74.34000","6.19521","0.06495"
"12466","74.76000","6.23013","0.06489"
"12536","75.18000","6.26511","0.06482"
"12606","75.60000","6.30014","0.06516"
"12676","76.02000","6.33512","0.06516"
"12746","76.44000","6.37016","0.06582"
"12816","76.86000","6.40507","0.06554"
"12886","77.28000","6.44017","0.06601"
"12956","77.70000","6.47515","0.06605"
"13026","78.12000","6.51018","0.06630"
"13096","78.54000","6.54510","0.06641"
"13166","78.96000","6.58008","0.06646"
"13236","79.38000","6.61517","0.06672"
"13306","79.80000","6.65021","0.06730"
"13376","80.22000","6.68519","0.06759"
"13446","80.64000","6.72010","0.06746"
"13516","81.06000","6.75514","0.06787"
"13586","81.48000","6.79012","0.06810"
"13656","81.90000","6.82516","0.06853"
"13726","82.32000","6.86013","0.06815"
"13796","82.74000","6.89511","0.06870"
"13866","83.16000","6.93009","0.06943"
"13936","83.58000","6.96512","0.06879"
"14006","84.00000","7.00010","0.06930"
"14076","84.42000","7.03508","0.07013"
"14146","84.84000","7.07011","0.07033"
"14216","85.26000","7.10515","0.07045"
"14286","85.68000","7.14019","0.07132"
"14356","86.10000","7.17516","0.07128"
"14426","86.52000","7.21008","0.07182"
"14496","86.94000","7.24512","0.07221"
"14566","87.36000","7.28015","0.07287"
"14636","87.78000","7.31513","0.07313"
"14706","88.20000","7.35011","0.07332"
"14776","88.62000","7.38514","0.07413"
"14846","89.04000","7.42018","0.07496"
"14916","89.46000","7.45510","0.07490"
"14986","89.88000","7.49013","0.07502"
"15056","90.30000","7.52511","0.07559"
"15126","90.72000","7.56015","0.07614"
"15196","91.14000","7.59518","0.07683"
"15266","91.56000","7.63016","0.07715"
"15336","91.98000","7.66508","0.07775"
"15406","92.40000","7.70006","0.07746"
"15476","92.82000","7.73515","0.07921"
"15546","93.24000","7.77013","0.07939"
"15616","93.66000","7.80517","0.08068"
"15686","94.08000","7.84008","0.08124"
"15756","94.50000","7.87512","0.08123"
"15826","94.92000","7.91015","0.08276"
"15896","95.34000","7.94519","0.08331"
"15966","95.76000","7.98011","0.08410"
"16036","96.18000","8.01509","0.08375"
"16106","96.60000","8.05018","0.08463"
"16176","97.02000","8.08516","0.08501"
"16246","97.44000","8.12014","0.08616"
"16316","97.86000","8.15511","0.08672"
"16386","98.28000","8.19015","0.08760"
"16456","98.70000","8.22513","0.08821"
"16526","99.12000","8.26016","0.08683"
"16596","99.54000","8.29508","0.08690"
"16666","99.96000","8.33012","0.08618"
"16736","100.38000","8.36509","0.08687"
"16806","100.80000","8.40013","0.08767"
"16876","101.22000","8.43511","0.08831"
"16946","101.64000","8.47008","0.08817"
"17016","102.06000","8.50512","0.08922"
"17086","102.48000","8.54016","0.09028"
"17156","102.90000","8.57519","0.09115"
"17226","103.32000","8.61017","0.09131"
"17296","103.74000","8.64509","0.09254"
"17366","104.16000","8.68013","0.09281"
"17436","104.58000","8.71510","0.09353"
"17506","105.00000","8.75014","0.09410"
"17576","105.42000","8.78512","0.09478"
"17646","105.84000","8.82009","0.09538"
"17716","106.26000","8.85513","0.09601"
"17786","106.68000","8.89011","0.09636"
"17856","107.10000","8.92508","0.09658"
"17926","107.52000","8.96012","0.09735"
"17996","107.94000","8.99516","0.09805"
"18066","108.36000","9.03019","0.09894"
"18136","108.78000","9.06517","0.09817"
"18206","109.20000","9.10009","0.09975"
"18276","109.62000","9.13512","0.10044"
"18346","110.04000","9.17010","0.10102"
"18416","110.46000","9.20514","0.10123"
"18486","110.88000","9.24017","0.10233"
"18556","111.30000","9.27503","0.10317"
"18626","111.72000","9.31013","0.10226"
"18696","112.14000","9.34510","0.10283"
"18766","112.56000","9.38014","0.10163"
"18836","112.98000","9.41506","0.09642"
"18906","113.40000","9.45010","0.09509"
"18976","113.82000","9.48519","0.09547"
"19046","114.24000","9.52017","0.09568"
"19116","114.66000","9.55515","0.09596"
"19186","115.08000","9.59012","0.09655"
"19256","115.50000","9.62510","0.09666"
"19326","115.92000","9.66014","0.09730"
"19396","116.34000","9.69511","0.09744"
"19466","116.76000","9.73009","0.09839"
"19536","117.18000","9.76513","0.09894"
"19606","117.60000","9.80010","0.09965"
"19676","118.02000","9.83514","0.09958"
"19746","118.44000","9.87012","0.09970"
"19816","118.86000","9.90509","0.09975"
"19886","119.28000","9.94013","0.10022"
"19956","119.70000","9.97517","0.10109"
"20026","120.12000","10.01020","0.10191"
"20096","120.54000","10.04512","0.10280"
"20166","120.96000","10.08010","0.10391"
"20236","121.38000","10.11507","0.10484"
"20306","121.80000","10.15011","0.10623"
"20376","122.22000","10.18509","0.10715"
"20446","122.64000","10.22006","0.10831"
"20516","123.06000","10.25510","0.10963"
"20586","123.48000","10.29014","0.11021"
"20656","123.90000","10.32511","0.11100"
"20726","124.32000","10.36015","0.11177"
"20796","124.74000","10.39513","0.11235"
"20866","125.16000","10.43016","0.11372"
"20936","125.58000","10.46520","0.11397"
"21006","126.00000","10.50012","0.11438"
"21076","126.42000","10.53509","0.11492"
"21146","126.84000","10.57013","0.11497"
"21216","127.26000","10.60517","0.11492"
"21286","127.68000","10.64009","0.11549"
"21356","128.10000","10.67518","0.11550"
"21426","128.52000","10.71004","0.11605"
"21496","128.94000","10.74514","0.11633"
"21566","129.36000","10.78017","0.11624"
"21636","129.78000","10.81521","0.11680"
"21706","130.20000","10.85013","0.11678"
"21776","130.62000","10.88510","0.11707"
"21846","131.04000","10.92020","0.11716"
"21916","131.46000","10.95518","0.11727"
"21986","131.88000","10.99015","0.11761"
"22056","132.30000","11.02507","0.11774"
"22126","132.72000","11.06011","0.11829"
"22196","133.14000","11.09514","0.11886"
"22266","133.56000","11.13018","0.11917"
"22336","133.98000","11.16516","0.11977"
"22406","134.40000","11.20013","0.12125"
"22476","134.82000","11.23511","0.12184"
"22546","135.24000","11.27009","0.12317"
"22616","135.66000","11.30512","0.12436"
"22686","136.08000","11.34010","0.12578"
"22756","136.50000","11.37514","0.12685"
"22826","136.92000","11.41017","0.12875"
"22896","137.34000","11.44515","0.13059"
"22966","137.76000","11.48013","0.13223"
"23036","138.18000","11.51511","0.13354"
"23106","138.60000","11.55014","0.13453"
"23176","139.02000","11.58512","0.13598"
"23246","139.44000","11.62010","0.13728"
"23316","139.86000","11.65507","0.13886"
"23386","140.28000","11.69011","0.13980"
"23456","140.70000","11.72515","0.14125"
"23526","141.12000","11.76012","0.14250"
"23596","141.54000","11.79510","0.14355"
"23666","141.96000","11.83014","0.14456"
"23736","142.38000","11.86517","0.14566"
"23806","142.80000","11.90021","0.14670"
"23876","143.22000","11.93513","0.14746"
"23946","143.64000","11.97016","0.14859"
"24016","144.06000","12.00514","0.14898"
"24086","144.48000","12.04018","0.14978"
"24156","144.90000","12.07515","0.15066"
"24226","145.32000","12.11013","0.15113"
"24296","145.74000","12.14505","0.15178"
"24366","146.16000","12.18008","0.15166"
"24436","146.58000","12.21518","0.15224"
"24506","147.00000","12.25016","0.15287"
"24576","147.42000","12.28513","0.15338"
"24646","147.84000","12.32005","0.15464"
"24716","148.26000","12.35515","0.15530"
"24786","148.68000","12.39019","0.15494"
"24856","149.10000","12.42510","0.15607"
"24926","149.52000","12.46008","0.15712"
"24996","149.94000","12.49512","0.15821"
"25066","150.36000","12.53015","0.15886"
"25136","150.78000","12.56513","0.15973"
"25206","151.20000","12.60011","0.16043"
"25276","151.62000","12.63508","0.16170"
"25346","152.04000","12.67012","0.16217"
"25416","152.46000","12.70516","0.16274"
"25486","152.88000","12.74013","0.16384"
"25556","153.30000","12.77511","0.16436"
"25626","153.72000","12.81015","0.16491"
"25696","154.14000","12.84512","0.16575"
"25766","154.56000","12.88016","0.16674"
"25836","154.98000","12.91514","0.16736"
"25906","155.40000","12.95012","0.16714"
"25976","155.82000","12.98515","0.16843"
"26046","156.24000","13.02013","0.16958"
"26116","156.66000","13.05510","0.17050"
"26186","157.08000","13.09008","0.17211"
"26256","157.50000","13.12512","0.17351"
"26326","157.92000","13.16016","0.17499"
"26396","158.34000","13.19513","0.17626"
"26466","158.76000","13.23011","0.17871"
"26536","159.18000","13.26508","0.18100"
"26606","159.60000","13.30012","0.18300"
"26676","160.02000","13.33516","0.18543"
"26746","160.44000","13.37020","0.18815"
"26816","160.86000","13.40511","0.19131"
"26886","161.28000","13.44015","0.19509"
"26956","161.70000","13.47513","0.19822"
"27026","162.12000","13.51010","0.20113"
"27096","162.54000","13.54520","0.20492"
"27166","162.96000","13.58006","0.20818"
"27236","163.38000","13.61509","0.21129"
"27306","163.80000","13.65013","0.21294"
"27376","164.22000","13.68517","0.21488"
"27446","164.64000","13.72008","0.21617"
"27516","165.06000","13.75506","0.21692"
"27586","165.48000","13.79016","0.21870"
"27656","165.90000","13.82513","0.21909"
"27726","166.32000","13.86011","0.22029"
"27796","166.74000","13.89509","0.22070"
"27866","167.16000","13.93013","0.22164"
"27936","167.58000","13.96516","0.22248"
"28006","168.00000","14.00014","0.22410"
"28076","168.42000","14.03512","0.22605"
"28146","168.84000","14.07015","0.22795"
"28216","169.26000","14.10507","0.22989"
"28286","169.68000","14.14016","0.23270"
"28356","170.10000","14.17514","0.23435"
"28426","170.52000","14.21012","0.23690"
"28496","170.94000","14.24510","0.23850"
"28566","171.36000","14.28013","0.24137"
"28636","171.78000","14.31517","0.24333"
"28706","172.20000","14.35015","0.24550"
"28776","172.62000","14.38512","0.24841"
"28846","173.04000","14.42016","0.25010"
"28916","173.46000","14.45514","0.25202"
"28986","173.88000","14.49011","0.25428"
"29056","174.30000","14.52509","0.25596"
"29126","174.72000","14.56007","0.25806"
"29196","175.14000","14.59516","0.25921"
"29266","175.56000","14.63008","0.26053"
"29336","175.98000","14.66512","0.26211"
"29406","176.40000","14.70009","0.26285"
"29476","176.82000","14.73513","0.26386"
"29546","177.24000","14.77011","0.26439"
"29616","177.66000","14.80514","0.26500"
"29686","178.08000","14.84012","0.26586"
"29756","178.50000","14.87510","0.26610"
"29826","178.92000","14.91013","0.26640"
"29896","179.34000","14.94511","0.26718"
"29966","179.76000","14.98009","0.26756"
"30036","180.18000","15.01507","0.26824"
"30106","180.60000","15.05010","0.26901"
"30176","181.02000","15.08520","0.27005"
"30246","181.44000","15.12018","0.27055"
"30316","181.86000","15.15509","0.27148"
"30386","182.28000","15.19013","0.27277"
"30456","182.70000","15.22517","0.27403"
"30526","183.12000","15.26014","0.27497"
"30596","183.54000","15.29512","0.27726"
"30666","183.96000","15.33010","0.27898"
"30736","184.38000","15.36513","0.28126"
"30806","184.80000","15.40011","0.27993"
"30876","185.22000","15.43515","0.28331"
"30946","185.64000","15.47012","0.28549"
"31016","186.06000","15.50510","0.28875"
"31086","186.48000","15.54008","0.29107"
"31156","186.90000","15.57517","0.29386"
"31226","187.32000","15.61015","0.29662"
"31296","187.74000","15.64507","0.29952"
"31366","188.16000","15.68016","0.30193"
"31436","188.58000","15.71520","0.30562"
"31506","189.00000","15.75018","0.30828"
"31576","189.42000","15.78509","0.31044"
"31646","189.84000","15.82007","0.31216"
"31716","190.26000","15.85511","0.31359"
"31786","190.68000","15.89020","0.31490"
"31856","191.10000","15.92512","0.31584"
"31926","191.52000","15.96004","0.31750"
"31996","191.94000","15.99514","0.31940"
"32066","192.36000","16.03011","0.32174"
"32136","192.78000","16.06509","0.32589"
"32206","193.20000","16.10013","0.33016"
"32276","193.62000","16.13510","0.33387"
"32346","194.04000","16.17014","0.34020"
"32416","194.46000","16.20518","0.34074"
"32486","194.88000","16.24015","0.34098"
"32556","195.30000","16.27513","0.34656"
"32626","195.72000","16.31010","0.34998"
"32696","196.14000","16.34514","0.35397"
"32766","196.56000","16.38012","0.35825"
"32836","196.98000","16.41516","0.35943"
"32906","197.40000","16.45001","0.36180"
"32976","197.82000","16.48511","0.36491"
"33046","198.24000","16.52015","0.35975"
"33116","198.66000","16.55518","0.36257"
"33186","199.08000","16.59010","0.36614"
"33256","199.50000","16.62514","0.36054"
"33326","199.92000","16.66017","0.36340"
"33396","200.34000","16.69515","0.36600"
"33466","200.76000","16.73013","0.36336"
"33536","201.18000","16.76510","0.36652"
"33606","201.60000","16.80008","0.36866"
"33676","202.02000","16.83512","0.37023"
"33746","202.44000","16.87009","0.37169"
"33816","202.86000","16.90507","0.37278"
"33886","203.28000","16.94011","0.37384"
"33956","203.70000","16.97515","0.37424"
"34026","204.12000","17.01012","0.37491"
"34096","204.54000","17.04510","0.37569"
"34166","204.96000","17.08008","0.37651"
"34236","205.38000","17.11517","0.37717"
"34306","205.80000","17.15015","0.37802"
"34376","206.22000","17.18518","0.37901"
"34446","206.64000","17.22016","0.37922"
"34516","207.06000","17.25508","0.38124"
"34586","207.48000","17.29012","0.38254"
"34656","207.90000","17.32509","0.38418"
"34726","208.32000","17.36013","0.38585"
"34796","208.74000","17.39505","0.38839"
"34866","209.16000","17.43008","0.39074"
"34936","209.58000","17.46512","0.37865"
"35006","210.00000","17.50010","0.37566"
"35076","210.42000","17.53513","0.37680"
"35146","210.84000","17.57005","0.37818"
"35216","211.26000","17.60515","0.38006"
"35286","211.68000","17.64013","0.38123"
"35356","212.10000","17.67522","0.38347"
"35426","212.52000","17.71014","0.38620"
"35496","212.94000","17.74512","0.38835"
"35566","213.36000","17.78015","0.38749"
"35636","213.78000","17.81513","0.39055"
"35706","214.20000","17.85016","0.39415"
"35776","214.62000","17.88508","0.39818"
"35846","215.04000","17.92012","0.40290"
"35916","215.46000","17.95516","0.40752"
"35986","215.88000","17.99019","0.41186"
"36056","216.30000","18.02517","0.41640"
"36126","216.72000","18.06009","0.41904"
"36196","217.14000","18.09518","0.42107"
"36266","217.56000","18.13016","0.42270"
"36336","217.98000","18.16514","0.42448"
"36406","218.40000","18.20011","0.42539"
"36476","218.82000","18.23515","0.42666"
"36546","219.24000","18.27013","0.42587"
"36616","219.66000","18.30516","0.37498"
"36686","220.08000","18.34008","0.37340"
"36756","220.50000","18.37512","0.37266"
"36826","220.92000","18.41009","0.37429"
"36896","221.34000","18.44513","0.37618"
"36966","221.76000","18.48011","0.37732"
"37036","222.18000","18.51508","0.37987"
"37106","222.60000","18.55012","0.38344"
"37176","223.02000","18.58516","0.38603"
"37246","223.44000","18.62020","0.39004"
"37316","223.86000","18.65511","0.39583"
"37386","224.28000","18.69009","0.40085"
"37456","224.70000","18.72512","0.40359"
"37526","225.12000","18.76016","0.41030"
"37596","225.54000","18.79508","0.41584"
"37666","225.96000","18.83006","0.42016"
"37736","226.38000","18.86509","0.42197"
"37806","226.80000","18.90019","0.40321"
"37876","227.22000","18.93511","0.40850"
"37946","227.64000","18.97008","0.41431"
"38016","228.06000","19.00506","0.41864"
"38086","228.48000","19.04016","0.42109"
"38156","228.90000","19.07519","0.42341"
"38226","229.32000","19.11017","0.42458"
"38296","229.74000","19.14515","0.42748"
"38366","230.16000","19.18012","0.43058"
"38436","230.58000","19.21516","0.43472"
"38506","231.00000","19.25014","0.43829"
"38576","231.42000","19.28511","0.44227"
"38646","231.84000","19.32003","0.44639"
"38716","232.26000","19.35513","0.44910"
"38786","232.68000","19.39010","0.45257"
"38856","233.10000","19.42520","0.45527"
"38926","233.52000","19.46012","0.45790"
"38996","233.94000","19.49509","0.45969"
"39066","234.36000","19.53013","0.46149"
"39136","234.78000","19.56511","0.46213"
"39206","235.20000","19.60015","0.46331"
"39276","235.62000","19.63506","0.46477"
"39346","236.04000","19.67016","0.46710"
"39416","236.46000","19.70514","0.42338"
"39486","236.88000","19.74017","0.41226"
"39556","237.30000","19.77509","0.41801"
"39626","237.72000","19.81007","0.42153"
"39696","238.14000","19.84510","0.42385"
"39766","238.56000","19.88014","0.42728"
"39836","238.98000","19.91512","0.43100"
"39906","239.40000","19.95009","0.43732"
"39976","239.82000","19.98513","0.44167"
"40046","240.24000","20.02017","0.44690"
"40116","240.66000","20.05520","0.45062"
"40186","241.08000","20.09012","0.45254"
"40256","241.50000","20.12510","0.45662"
"40326","241.92000","20.16014","0.45853"
"40396","242.34000","20.19517","0.46096"
"40466","242.76000","20.23015","0.46221"
"40536","243.18000","20.26506","0.46338"
"40606","243.60000","20.30010","0.46511"
"40676","244.02000","20.33514","0.46766"
"40746","244.44000","20.37011","0.46998"
"40816","244.86000","20.40509","0.47164"
"40886","245.28000","20.44007","0.47533"
"40956","245.70000","20.47517","0.47759"
"41026","246.12000","20.51014","0.48034"
"41096","246.54000","20.54518","0.48432"
"41166","246.96000","20.58015","0.48737"
"41236","247.38000","20.61507","0.49068"
"41306","247.80000","20.65017","0.49179"
"41376","248.22000","20.68514","0.49660"
"41446","248.64000","20.72012","0.50036"
"41516","249.06000","20.75504","0.50447"
"41586","249.48000","20.79007","0.50757"
"41656","249.90000","20.82517","0.51119"
"41726","250.32000","20.86015","0.51420"
"41796","250.74000","20.89513","0.51778"
"41866","251.16000","20.93010","0.51988"
"41936","251.58000","20.96514","0.52247"
"42006","252.00000","21.00018","0.52359"
"42076","252.42000","21.03515","0.52410"
"42146","252.84000","21.07013","0.52542"
"42216","253.26000","21.10511","0.52665"
"42286","253.68000","21.14014","0.52897"
"42356","254.10000","21.17512","0.53233"
"42426","254.52000","21.21010","0.53805"
"42496","254.94000","21.24513","0.54405"
"42566","255.36000","21.28011","0.54871"
"42636","255.78000","21.31515","0.55319"
"42706","256.20000","21.35012","0.53595"
"42776","256.62000","21.38510","0.54227"
"42846","257.04000","21.42014","0.54794"
"42916","257.46000","21.45512","0.55360"
"42986","257.88000","21.49015","0.55784"
"43056","258.30000","21.52513","0.56175"
"43126","258.72000","21.56011","0.56584"
"43196","259.14000","21.59514","0.56938"
"43266","259.56000","21.63018","0.57218"
"43336","259.98000","21.66510","0.57390"
"43406","260.40000","21.70007","0.57697"
"43476","260.82000","21.73511","0.57887"
"43546","261.24000","21.77015","0.58082"
"43616","261.66000","21.80512","0.58328"
"43686","262.08000","21.84010","0.58456"
"43756","262.50000","21.87508","0.58613"
"43826","262.92000","21.91011","0.58674"
"43896","263.34000","21.94515","0.58815"
"43966","263.76000","21.98018","0.58960"
"44036","264.18000","22.01510","0.59155"
"44106","264.60000","22.05008","0.59381"
"44176","265.02000","22.08518","0.59678"
"44246","265.44000","22.12010","0.60147"
"44316","265.86000","22.15513","0.60795"
"44386","266.28000","22.19005","0.61283"
"44456","266.70000","22.22515","0.61813"
"44526","267.12000","22.26018","0.62254"
"44596","267.54000","22.29516","0.62458"
"44666","267.96000","22.33008","0.62516"
"44736","268.38000","22.36511","0.31812"
"44806","268.80000","22.40015","0.32568"
"44876","269.22000","22.43519","0.34282"
"44946","269.64000","22.47016","0.34867"
"45016","270.06000","22.50514","0.34467"
"45086","270.48000","22.54012","0.35530"
"45156","270.90000","22.57509","0.36185"
"45226","271.32000","22.61013","0.37065"
"45296","271.74000","22.64511","0.37279"
"45366","272.16000","22.68008","0.37319"
"45436","272.58000","22.71506","0.37455"
"45506","273.00000","22.75010","0.37542"
"45576","273.42000","22.78514","0.37595"
"45646","273.84000","22.82005","0.37801"
"45716","274.26000","22.85509","0.37960"
"45786","274.68000","22.89012","0.38126"
"45856","275.10000","22.92516","0.38155"
"45926","275.52000","22.96020","0.36047"
"45996","275.94000","22.99511","0.36334"
"46066","276.36000","23.03015","0.36818"
"46136","276.78000","23.06513","0.37025"
"46206","277.20000","23.10011","0.37226"
"46276","277.62000","23.13502","0.37411"
"46346","278.04000","23.17012","0.37492"
"46416","278.46000","23.20515","0.37587"
"46486","278.88000","23.24013","0.37770"
"46556","279.30000","23.27511","0.37886"
"46626","279.72000","23.31008","0.38088"
"46696","280.14000","23.34518","0.38308"
"46766","280.56000","23.38022","0.38543"
"46836","280.98000","23.41520","0.38905"
"46906","281.40000","23.45011","0.39261"
"46976","281.82000","23.48515","0.39667"
"47046","282.24000","23.52019","0.40416"
"47116","282.66000","23.55510","0.40982"
"47186","283.08000","23.59014","0.41607"
"47256","283.50000","23.62506","0.41922"
"47326","283.92000","23.66015","0.42187"
"47396","284.34000","23.69513","0.42454"
"47466","284.76000","23.73017","0.42630"
"47536","285.18000","23.76508","0.43090"
"47606","285.60000","23.80012","0.43565"
"47676","286.02000","23.83516","0.44051"
"47746","286.44000","23.87013","0.44592"
"47816","286.86000","23.90517","0.44911"
"47886","287.28000","23.94009","0.45368"
"47956","287.70000","23.97512","0.45645"
"48026","288.12000","24.01016","0.45965"
"48096","288.54000","24.04514","0.46123"
"48166","288.96000","24.08012","0.46301"
"48236","289.38000","24.11509","0.46485"
"48306","289.80000","24.15013","0.46720"
"48376","290.22000","24.18516","0.47077"
"48446","290.64000","24.22014","0.47428"
"48516","291.06000","24.25506","0.47870"
"48586","291.48000","24.29009","0.48280"
"48656","291.90000","24.32513","0.48814"
"48726","292.32000","24.36017","0.49334"
"48796","292.74000","24.39515","0.50007"
"48866","293.16000","24.43012","0.50498"
"48936","293.58000","24.46516","0.50991"
"49006","294.00000","24.50014","0.51421"
"49076","294.42000","24.53511","0.51915"
"49146","294.84000","24.57009","0.52255"
"49216","295.26000","24.60513","0.52347"
"49286","295.68000","24.64017","0.52544"
"49356","296.10000","24.67508","0.52735"
"49426","296.52000","24.71006","0.53257"
"49496","296.94000","24.74509","0.53976"
"49566","297.36000","24.78019","0.53046"
"49636","297.78000","24.81517","0.53711"
"49706","298.20000","24.85020","0.54482"
"49776","298.62000","24.88512","0.55130"
"49846","299.04000","24.92010","0.55755"
"49916","299.46000","24.95513","0.56297"
"49986","299.88000","24.99011","0.56818"
"50056","300.30000","25.02515","0.57135"
"50126","300.72000","25.06006","0.57430"
"50196","301.14000","25.09510","0.57818"
"50266","301.56000","25.13014","0.58062"
"50336","301.98000","25.16517","0.58338"
"50406","302.40000","25.20015","0.58548"
"50476","302.82000","25.23513","0.58704"
"50546","303.24000","25.27016","0.58902"
"50616","303.66000","25.30520","0.59145"
"50686","304.08000","25.34018","0.59500"
"50756","304.50000","25.37510","0.58590"
"50826","304.92000","25.41013","0.58779"
"50896","305.34000","25.44517","0.58965"
"50966","305.76000","25.48015","0.59177"
"51036","306.18000","25.51506","0.59594"
"51106","306.60000","25.55016","0.59968"
"51176","307.02000","25.58513","0.60581"
"51246","307.44000","25.62011","0.61363"
"51316","307.86000","25.65515","0.62102"
"51386","308.28000","25.69013","0.62563"
"51456","308.70000","25.72510","0.62936"
"51526","309.12000","25.76014","0.63236"
"51596","309.54000","25.79518","0.63762"
"51666","309.96000","25.83015","0.64387"
"51736","310.38000","25.86507","0.65063"
"51806","310.80000","25.90011","0.65764"
"51876","311.22000","25.93514","0.66232"
"51946","311.64000","25.97006","0.66674"
"52016","312.06000","26.00510","0.67020"
"52086","312.48000","26.04013","0.67279"
"52156","312.90000","26.07511","0.67428"
"52226","313.32000","26.11009","0.67507"
"52296","313.74000","26.14513","0.67607"
"52366","314.16000","26.18010","0.67763"
"52436","314.58000","26.21514","0.67945"
"52506","315.00000","26.25018","0.68180"
"52576","315.42000","26.28521","0.68417"
"52646","315.84000","26.32013","0.68753"
"52716","316.26000","26.35511","0.69172"
"52786","316.68000","26.39014","0.69754"
"52856","317.10000","26.42512","0.70261"
"52926","317.52000","26.46010","0.70765"
"52996","317.94000","26.49501","0.71325"
"53066","318.36000","26.53011","0.71922"
"53136","318.78000","26.56515","0.72608"
"53206","319.20000","26.60013","0.73120"
"53276","319.62000","26.63510","0.73368"
"53346","320.04000","26.67008","0.73499"
"53416","320.46000","26.70517","0.73606"
"53486","320.88000","26.74015","0.73835"
"53556","321.30000","26.77513","0.74244"
"53626","321.72000","26.81010","0.74941"
"53696","322.14000","26.84514","0.75587"
"53766","322.56000","26.88012","0.76091"
"53836","322.98000","26.91516","0.76639"
"53906","323.40000","26.95013","0.77207"
"53976","323.82000","26.98511","0.77626"
"54046","324.24000","27.02009","0.77995"
"54116","324.66000","27.05512","0.78291"
"54186","325.08000","27.09010","0.78568"
"54256","325.50000","27.12508","0.78752"
"54326","325.92000","27.16011","0.78967"
"54396","326.34000","27.19515","0.79143"
"54466","326.76000","27.23019","0.79426"
"54536","327.18000","27.26517","0.79883"
"54606","327.60000","27.30008","0.80317"
"54676","328.02000","27.33518","0.80757"
"54746","328.44000","27.37016","0.81274"
"54816","328.86000","27.40513","0.81813"
"54886","329.28000","27.44005","0.82307"
"54956","329.70000","27.47508","0.82576"
"55026","330.12000","27.51012","0.82885"
"55096","330.54000","27.54510","0.83182"
"55166","330.96000","27.58014","0.83798"
"55236","331.38000","27.61511","0.84647"
"55306","331.80000","27.65015","0.85393"
"55376","332.22000","27.68513","0.86061"
"55446","332.64000","27.72016","0.86801"
"55516","333.06000","27.75514","0.87396"
"55586","333.48000","27.79012","0.88001"
"55656","333.90000","27.82515","0.88421"
"55726","334.32000","27.86013","0.88681"
"55796","334.74000","27.89511","0.88790"
"55866","335.16000","27.93008","0.88846"
"55936","335.58000","27.96512","0.88940"
"56006","336.00000","28.00016","0.89152"
"56076","336.42000","28.03519","0.89378"
"56146","336.84000","28.07011","0.89634"
"56216","337.26000","28.10509","0.89934"
"56286","337.68000","28.14018","0.90286"
"56356","338.10000","28.17516","0.90735"
"56426","338.52000","28.21014","0.91165"
"56496","338.94000","28.24511","0.91641"
"56566","339.36000","28.28009","0.92101"
"56636","339.78000","28.31513","0.92700"
"56706","340.20000","28.35016","0.93351"
"56776","340.62000","28.38514","0.93680"
"56846","341.04000","28.42012","0.93893"
"56916","341.46000","28.45509","0.94097"
"56986","341.88000","28.49013","0.94342"
"57056","342.30000","28.52511","0.94471"
"57126","342.72000","28.56009","0.93843"
"57196","343.14000","28.59512","0.26773"
"57266","343.56000","28.63016","0.26518"
"57336","343.98000","28.66520","0.26733"
"57406","344.40000","28.70011","0.26679"
"57476","344.82000","28.73509","0.26817"
"57546","345.24000","28.77013","0.26968"
"57616","345.66000","28.80516","0.26790"
"57686","346.08000","28.84014","0.26852"
"57756","346.50000","28.87512","0.26851"
"57826","346.92000","28.91010","0.27299"
"57896","347.34000","28.94519","0.27324"
"57966","347.76000","28.98011","0.27258"
"58036","348.18000","29.01514","0.27375"
"58106","348.60000","29.05012","0.27626"
"58176","349.02000","29.08516","0.28410"
"58246","349.44000","29.12013","0.28069"
"58316","349.86000","29.15517","0.28507"
"58386","350.28000","29.19015","0.27247"
"58456","350.70000","29.22507","0.27506"
"58526","351.12000","29.26016","0.27208"
"58596","351.54000","29.29514","0.27250"
"58666","351.96000","29.33018","0.27396"
"58736","352.38000","29.36509","0.28050"
"58806","352.80000","29.40013","0.28377"
"58876","353.22000","29.43517","0.28216"
"58946","353.64000","29.47014","0.28498"
"59016","354.06000","29.50512","0.29129"
"59086","354.48000","29.54010","0.29777"
"59156","354.90000","29.57519","0.29354"
"59226","355.32000","29.61017","0.29478"
"59296","355.74000","29.64509","0.30069"
"59366","356.16000","29.68006","0.30632"
"59436","356.58000","29.71516","0.30435"
"59506","357.00000","29.75014","0.30704"
"59576","357.42000","29.78511","0.31203"
"59646","357.84000","29.82009","0.30550"
"59716","358.26000","29.85507","0.30155"
"59786","358.68000","29.89010","0.30230"
"59856","359.10000","29.92514","0.31003"
"59926","359.52000","29.96018","0.31285"
"59996","359.94000","29.99509","0.31232"
"60066","360.36000","30.03007","0.31418"
"60136","360.78000","30.06517","0.31619"
"60206","361.20000","30.10021","0.31709"
"60276","361.62000","30.13518","0.31816"
"60346","362.04000","30.17010","0.32317"
"60416","362.46000","30.20514","0.33384"
"60486","362.88000","30.24017","0.32034"
"60556","363.30000","30.27515","0.31436"
"60626","363.72000","30.31013","0.31666"
"60696","364.14000","30.34510","0.31822"
"60766","364.56000","30.38014","0.31795"
"60836","364.98000","30.41511","0.32283"
"60906","365.40000","30.45009","0.32872"
"60976","365.82000","30.48513","0.33096"
"61046","366.24000","30.52011","0.33624"
"61116","366.66000","30.55520","0.34660"
"61186","367.08000","30.59018","0.34860"
"61256","367.50000","30.62510","0.35123"
"61326","367.92000","30.66013","0.35815"
"61396","368.34000","30.69517","0.36269"
"61466","368.76000","30.73009","0.36404"
"61536","369.18000","30.76518","0.36798"
"61606","369.60000","30.80004","0.37097"
"61676","370.02000","30.83514","0.37147"
"61746","370.44000","30.87017","0.37339"
"61816","370.86000","30.90515","0.37451"
"61886","371.28000","30.94007","0.37463"
"61956","371.70000","30.97510","0.37555"
"62026","372.12000","31.01014","0.37705"
"62096","372.54000","31.04518","0.37726"
"62166","372.96000","31.08015","0.37907"
"62236","373.38000","31.11507","0.38100"
"62306","373.80000","31.15011","0.38166"
"62376","374.22000","31.18515","0.38359"
"62446","374.64000","31.22012","0.38567"
"62516","375.06000","31.25510","0.38706"
"62586","375.48000","31.29013","0.39033"
"62656","375.90000","31.32511","0.39056"
"62726","376.32000","31.36015","0.39267"
"62796","376.74000","31.39513","0.39781"
"62866","377.16000","31.43010","0.39925"
"62936","377.58000","31.46514","0.40584"
"63006","378.00000","31.50018","0.41011"
"63076","378.42000","31.53521","0.41491"
"63146","378.84000","31.57013","0.41922"
"63216","379.26000","31.60511","0.42115"
"63286","379.68000","31.64014","0.42312"
"63356","380.10000","31.67512","0.42507"
"63426","380.52000","31.71010","0.42741"
"63496","380.94000","31.74507","0.43105"
"63566","381.36000","31.78011","0.43484"
"63636","381.78000","31.81515","0.44015"
"63706","382.20000","31.85012","0.44308"
"63776","382.62000","31.88516","0.44685"
"63846","383.04000","31.92014","0.45130"
"63916","383.46000","31.95517","0.45386"
"63986","383.88000","31.99015","0.45679"
"64056","384.30000","32.02512","0.45822"
"64126","384.72000","32.06010","0.46003"
"64196","385.14000","32.09514","0.46119"
"64266","385.56000","32.13018","0.46270"
"64336","385.98000","32.16510","0.46399"
"64406","386.40000","32.20013","0.46584"
"64476","386.82000","32.23505","0.46746"
"64546","387.24000","32.27015","0.47041"
"64616","387.66000","32.30518","0.47405"
"64686","388.08000","32.34016","0.47725"
"64756","388.50000","32.37513","0.48012"
"64826","388.92000","32.41011","0.48340"
"64896","389.34000","32.44515","0.48753"
"64966","389.76000","32.48018","0.49107"
"65036","390.18000","32.51516","0.49711"
"65106","390.60000","32.55014","0.50124"
"65176","391.02000","32.58511","0.50586"
"65246","391.44000","32.62015","0.50778"
"65316","391.86000","32.65513","0.51268"
"65386","392.28000","32.69011","0.51553"
"65456","392.70000","32.72514","0.52005"
"65526","393.12000","32.76012","0.52193"
"65596","393.54000","32.79516","0.52369"
"65666","393.96000","32.83014","0.52482"
"65736","394.38000","32.86505","0.52632"
"65806","394.80000","32.90009","0.52858"
"65876","395.22000","32.93518","0.53243"
"65946","395.64000","32.97016","0.53837"
"66016","396.06000","33.00514","0.54455"
"66086","396.48000","33.04005","0.55076"
"66156","396.90000","33.07515","0.55427"
"66226","397.32000","33.11013","0.55954"
"66296","397.74000","33.14510","0.56412"
"66366","398.16000","33.18008","0.56795"
"66436","398.58000","33.21506","0.57163"
"66506","399.00000","33.25015","0.57489"
"66576","399.42000","33.28513","0.57690"
"66646","399.84000","33.32011","0.57890"
"66716","400.26000","33.35509","0.58113"
"66786","400.68000","33.39013","0.53841"
"66856","401.10000","33.42516","0.48988"
"66926","401.52000","33.46014","0.48851"
"66996","401.94000","33.49517","0.49567"
"67066","402.36000","33.53009","0.49878"
"67136","402.78000","33.56519","0.50620"
"67206","403.20000","33.60016","0.50946"
"67276","403.62000","33.63514","0.51408"
"67346","404.04000","33.67006","0.51821"
"67416","404.46000","33.70509","0.52195"
"67486","404.88000","33.74013","0.52352"
"67556","405.30000","33.77517","0.52473"
"67626","405.72000","33.81008","0.52641"
"67696","406.14000","33.84506","0.53125"
"67766","406.56000","33.88015","0.53652"
"67836","406.98000","33.91513","0.54325"
"67906","407.40000","33.95011","0.55121"
"67976","407.82000","33.98509","0.55724"
"68046","408.24000","34.02013","0.56397"
"68116","408.66000","34.05516","0.56799"
"68186","409.08000","34.09014","0.57239"
"68256","409.50000","34.12511","0.57534"
"68326","409.92000","34.16009","0.57784"
"68396","410.34000","34.19513","0.58044"
"68466","410.76000","34.23011","0.58239"
"68536","411.18000","34.26514","0.58516"
"68606","411.60000","34.30006","0.58637"
"68676","412.02000","34.33509","0.58806"
"68746","412.44000","34.37013","0.59020"
"68816","412.86000","34.40517","0.59307"
"68886","413.28000","34.44014","0.59687"
"68956","413.70000","34.47512","0.60180"
"69026","414.12000","34.51016","0.60915"
"69096","414.54000","34.54514","0.61820"
"69166","414.96000","34.58011","0.62425"
"69236","415.38000","34.61509","0.62774"
"69306","415.80000","34.65013","0.63046"
"69376","416.22000","34.68517","0.63471"
"69446","416.64000","34.72014","0.63845"
"69516","417.06000","34.75512","0.64266"
"69586","417.48000","34.79010","0.65212"
"69656","417.90000","34.82513","0.65757"
"69726","418.32000","34.86017","0.66231"
"69796","418.74000","34.89520","0.66665"
"69866","419.16000","34.93012","0.66952"
"69936","419.58000","34.96510","0.67217"
"70006","420.00000","35.00013","0.67394"
"70076","420.42000","35.03511","0.67503"
"70146","420.84000","35.07015","0.67603"
"70216","421.26000","35.10506","0.67725"
"70286","421.68000","35.14010","0.67944"
"70356","422.10000","35.17514","0.68150"
"70426","422.52000","35.21017","0.68343"
"70496","422.94000","35.24509","0.68665"
"70566","423.36000","35.28007","0.69043"
"70636","423.78000","35.31517","0.69557"
"70706","424.20000","35.35014","0.70069"
"70776","424.62000","35.38512","0.70617"
"70846","425.04000","35.42016","0.71119"
"70916","425.46000","35.45514","0.71733"
"70986","425.88000","35.49017","0.72299"
"71056","426.30000","35.52515","0.72923"
"71126","426.72000","35.56006","0.73271"
"71196","427.14000","35.59510","0.73455"
"71266","427.56000","35.63008","0.73550"
"71336","427.98000","35.66512","0.73769"
"71406","428.40000","35.70015","0.46266"
"71476","428.82000","35.73513","0.46429"
"71546","429.24000","35.77010","0.46467"
"71616","429.66000","35.80508","0.47361"
"71686","430.08000","35.84018","0.47087"
"71756","430.50000","35.87516","0.47777"
"71826","430.92000","35.91013","0.47891"
"71896","431.34000","35.94517","0.48369"
"71966","431.76000","35.98014","0.49176"
"72036","432.18000","36.01512","0.49576"
"72106","432.60000","36.05010","0.50727"
"72176","433.02000","36.08508","0.50886"
"72246","433.44000","36.12017","0.51940"
"72316","433.86000","36.15509","0.52045"
"72386","434.28000","36.19019","0.52484"
"72456","434.70000","36.22504","0.52535"
"72526","435.12000","36.26008","0.53744"
"72596","435.54000","36.29512","0.53919"
"72666","435.96000","36.33021","0.55549"
"72736","436.38000","36.36513","0.55613"
"72806","436.80000","36.40010","0.56517"
"72876","437.22000","36.43514","0.56485"
"72946","437.64000","36.47012","0.57052"
"73016","438.06000","36.50515","0.30699"
"73086","438.48000","36.54007","0.33124"
"73156","438.90000","36.57511","0.32059"
"73226","439.32000","36.61015","0.33716"
"73296","439.74000","36.64518","0.36385"
"73366","440.16000","36.68010","0.35547"
"73436","440.58000","36.71508","0.36508"
"73506","441.00000","36.75011","0.37405"
"73576","441.42000","36.78515","0.37418"
"73646","441.84000","36.82013","0.37503"
"73716","442.26000","36.85511","0.37850"
"73786","442.68000","36.89014","0.38041"
"73856","443.10000","36.92512","0.38190"
"73926","443.52000","36.96016","0.38451"
"73996","443.94000","36.99513","0.39170"
"74066","444.36000","37.03011","0.39948"
"74136","444.78000","37.06509","0.40535"
"74206","445.20000","37.10012","0.41137"
"74276","445.62000","37.13510","0.41845"
"74346","446.04000","37.17007","0.42227"
"74416","446.46000","37.20512","0.42513"
"74486","446.88000","37.24015","0.43009"
"74556","447.30000","37.27519","0.43700"
"74626","447.72000","37.31010","0.44239"
"74696","448.14000","37.34508","0.44841"
"74766","448.56000","37.38012","0.45409"
"74836","448.98000","37.41521","0.45871"
"74906","449.40000","37.45013","0.46172"
"74976","449.82000","37.48505","0.46346"
"75046","450.24000","37.52008","0.46533"
"75116","450.66000","37.55512","0.46378"
"75186","451.08000","37.59010","0.46498"
"75256","451.50000","37.62513","0.46799"
"75326","451.92000","37.66005","0.47148"
"75396","452.34000","37.69515","0.47422"
"75466","452.76000","37.73013","0.47847"
"75536","453.18000","37.76516","0.48346"
"75606","453.60000","37.80014","0.48936"
"75676","454.02000","37.83512","0.49670"
"75746","454.44000","37.87016","0.50384"
"75816","454.86000","37.90513","0.50857"
"75886","455.28000","37.94017","0.51330"
"75956","455.70000","37.97503","0.51921"
"76026","456.12000","38.01012","0.52228"
"76096","456.54000","38.04516","0.52402"
"76166","456.96000","38.08019","0.52581"
"76236","457.38000","38.11511","0.52982"
"76306","457.80000","38.15009","0.53718"
"76376","458.22000","38.18512","0.54564"
"76446","458.64000","38.22016","0.55345"
"76516","459.06000","38.25513","0.54402"
"76586","459.48000","38.29011","0.55173"
"76656","459.90000","38.32515","0.56002"
"76726","460.32000","38.36013","0.56441"
"76796","460.74000","38.39510","0.56726"
"76866","461.16000","38.43014","0.57145"
"76936","461.58000","38.46512","0.57414"
"77006","462.00000","38.50010","0.57788"
"77076","462.42000","38.53513","0.58022"
"77146","462.84000","38.57011","0.58392"
"77216","463.26000","38.60509","0.58527"
"77286","463.68000","38.64012","0.58733"
"77356","464.10000","38.67516","0.58934"
"77426","464.52000","38.71014","0.59252"
"77496","464.94000","38.74517","0.59608"
"77566","465.36000","38.78009","0.60344"
"77636","465.78000","38.81512","0.61170"
"77706","466.20000","38.85010","0.61944"
"77776","466.62000","38.88514","0.62449"
"77846","467.04000","38.92012","0.62887"
"77916","467.46000","38.95509","0.63243"
"77986","467.88000","38.99013","0.63729"
"78056","468.30000","39.02510","0.57427"
"78126","468.72000","39.06014","0.57122"
"78196","469.14000","39.09506","0.57246"
"78266","469.56000","39.13015","0.57574"
"78336","469.98000","39.16513","0.57912"
"78406","470.40000","39.20017","0.58189"
"78476","470.82000","39.23509","0.58512"
"78546","471.24000","39.27013","0.58684"
"78616","471.66000","39.30516","0.58902"
"78686","472.08000","39.34014","0.59148"
"78756","472.50000","39.37511","0.59439"
"78826","472.92000","39.41003","0.59767"
"78896","473.34000","39.44507","0.60329"
"78966","473.76000","39.48016","0.61219"
"79036","474.18000","39.51514","0.62102"
"79106","474.60000","39.55012","0.62684"
"79176","475.02000","39.58509","0.63043"
"79246","475.44000","39.62019","0.63564"
"79316","475.86000","39.65516","0.64205"
"79386","476.28000","39.69014","0.60384"
"79456","476.70000","39.72512","0.52218"
"79526","477.12000","39.76016","0.37103"
"79596","477.54000","39.79514","0.36864"
"79666","477.96000","39.83012","0.37629"
"79736","478.38000","39.86509","0.38485"
"79806","478.80000","39.90006","0.38189"
"79876","479.22000","39.93510","0.38879"
"79946","479.64000","39.97014","0.40620"
"80016","480.06000","40.00512","0.41571"
"80086","480.48000","40.04010","0.42091"
"80156","480.90000","40.07513","0.42411"
"80226","481.32000","40.11011","0.42817"
"80296","481.74000","40.14515","0.43517"
"80366","482.16000","40.18018","0.43903"
"80436","482.58000","40.21510","0.44433"
"80506","483.00000","40.25013","0.45076"
"80576","483.42000","40.28517","0.45497"
"80646","483.84000","40.32009","0.45893"
"80716","484.26000","40.35506","0.46170"
"80786","484.68000","40.39010","0.46352"
"80856","485.10000","40.42520","0.46771"
"80926","485.52000","40.46018","0.47294"
"80996","485.94000","40.49509","0.48004"
"81066","486.36000","40.53007","0.48636"
"81136","486.78000","40.56517","0.49608"
"81206","487.20000","40.60014","0.50498"
"81276","487.62000","40.63518","0.51090"
"81346","488.04000","40.67015","0.51770"
"81416","488.46000","40.70513","0.52217"
"81486","488.88000","40.74017","0.52447"
"81556","489.30000","40.77515","0.52680"
"81626","489.72000","40.81012","0.53459"
"81696","490.14000","40.84504","0.54489"
"81766","490.56000","40.88007","0.54709"
"81836","490.98000","40.91511","0.43468"
"81906","491.40000","40.95015","0.44067"
"81976","491.82000","40.98507","0.44925"
"82046","492.24000","41.02004","0.45548"
"82116","492.66000","41.05514","0.45965"
"82186","493.08000","41.09012","0.46163"
"82256","493.50000","41.12510","0.31655"
"82326","493.92000","41.16007","0.31528"
"82396","494.34000","41.19511","0.33106"
"82466","494.76000","41.23014","0.32879"
"82536","495.18000","41.26512","0.33866"
"82606","495.60000","41.30010","0.35190"
"82676","496.02000","41.33508","0.35549"
"82746","496.44000","41.37011","0.36115"
"82816","496.86000","41.40515","0.36626"
"82886","497.28000","41.44012","0.36831"
"82956","497.70000","41.47504","0.37206"
"83026","498.12000","41.51007","0.37384"
"83096","498.54000","41.54511","0.37483"
"83166","498.96000","41.58015","0.37658"
"83236","499.38000","41.61513","0.37850"
"83306","499.80000","41.65010","0.38065"
"83376","500.22000","41.68515","0.38450"
"83446","500.64000","41.72018","0.38889"
"83516","501.06000","41.75510","0.39527"
"83586","501.48000","41.79008","0.40314"
"83656","501.90000","41.82511","0.41120"
"83726","502.32000","41.86015","0.41758"
"83796","502.74000","41.89512","0.42149"
"83866","503.16000","41.93010","0.42377"
"83936","503.58000","41.96508","0.42733"
"84006","504.00000","42.00018","0.43455"
"84076","504.42000","42.03515","0.44181"
"84146","504.84000","42.07019","0.44729"
"84216","505.26000","42.10516","0.45225"
"84286","505.68000","42.14008","0.45627"
"84356","506.10000","42.17517","0.46039"
"84426","506.52000","42.21009","0.46213"
"84496","506.94000","42.24513","0.46466"
"84566","507.36000","42.28005","0.46679"
"84636","507.78000","42.31509","0.47063"
"84706","508.20000","42.35012","0.47589"
"84776","508.62000","42.38516","0.48022"
"84846","509.04000","42.42007","0.48585"
"84916","509.46000","42.45505","0.49218"
"84986","509.88000","42.49015","0.49893"
"85056","510.30000","42.52519","0.50345"
"85126","510.72000","42.56016","0.50835"
"85196","511.14000","42.59514","0.51560"
"85266","511.56000","42.63012","0.52041"
"85336","511.98000","42.66515","0.52342"
"85406","512.40000","42.70013","0.52569"
"85476","512.82000","42.73511","0.53078"
"85546","513.24000","42.77008","0.53812"
"85616","513.66000","42.80511","0.54814"
"85686","514.08000","42.84015","0.55530"
"85756","514.50000","42.87513","0.55978"
"85826","514.92000","42.91011","0.56150"
"85895","515.33000","42.94425","0.56620"