File: Trajectories_together/170121_1Specimen_RawData_6.csv
"","V1","V2","V3"
"1","End date","1/21/2017",""
"2","Specimen label","19CG_45",""
"3","Maximum Load","0.25120","N"
"4","Time","Extension","Load"
"5","(s)","(mm)","(N)"
"6","0.00000","0.00006","0.00049"
"67","0.36600","0.03061","0.00244"
"128","0.73200","0.06128","0.00467"
"189","1.09800","0.09166","0.00699"
"250","1.46400","0.12221","0.00889"
"311","1.83000","0.15270","0.01060"
"372","2.19600","0.18314","0.01237"
"433","2.56200","0.21375","0.01440"
"494","2.92800","0.24418","0.01565"
"555","3.29400","0.27467","0.01670"
"616","3.66000","0.30517","0.01791"
"677","4.02600","0.33566","0.01820"
"738","4.39200","0.36615","0.01948"
"799","4.75800","0.39664","0.02004"
"860","5.12400","0.42720","0.02078"
"921","5.49000","0.45763","0.02160"
"982","5.85600","0.48812","0.02155"
"1043","6.22200","0.51873","0.02226"
"1104","6.58800","0.54917","0.02228"
"1165","6.95400","0.57966","0.02299"
"1226","7.32000","0.61021","0.02289"
"1287","7.68600","0.64064","0.02353"
"1348","8.05200","0.67114","0.02445"
"1409","8.41800","0.70169","0.02479"
"1470","8.78400","0.73218","0.02427"
"1531","9.15000","0.76262","0.02421"
"1592","9.51600","0.79317","0.02475"
"1653","9.88200","0.82372","0.02572"
"1714","10.24800","0.85409","0.02543"
"1775","10.61400","0.88471","0.02537"
"1836","10.98000","0.91520","0.02560"
"1897","11.34600","0.94563","0.02567"
"1958","11.71200","0.97618","0.02607"
"2019","12.07800","1.00668","0.02594"
"2080","12.44400","1.03717","0.02611"
"2141","12.81000","1.06760","0.02638"
"2202","13.17600","1.09815","0.02672"
"2263","13.54200","1.12871","0.02690"
"2324","13.90800","1.15920","0.02642"
"2385","14.27400","1.18969","0.02687"
"2446","14.64000","1.22012","0.02662"
"2507","15.00600","1.25068","0.02720"
"2568","15.37200","1.28117","0.02701"
"2629","15.73800","1.31166","0.02691"
"2690","16.10400","1.34222","0.02732"
"2751","16.47000","1.37271","0.02727"
"2812","16.83600","1.40320","0.02711"
"2873","17.20200","1.43363","0.02711"
"2934","17.56800","1.46419","0.02705"
"2995","17.93400","1.49468","0.02720"
"3056","18.30000","1.52511","0.02719"
"3117","18.66600","1.55566","0.02729"
"3178","19.03200","1.58622","0.02749"
"3239","19.39800","1.61659","0.02737"
"3300","19.76400","1.64720","0.02740"
"3361","20.13000","1.67769","0.02770"
"3422","20.49600","1.70819","0.02716"
"3483","20.86200","1.73868","0.02774"
"3544","21.22800","1.76917","0.02783"
"3605","21.59400","1.79967","0.02762"
"3666","21.96000","1.83016","0.02760"
"3727","22.32600","1.86065","0.02791"
"3788","22.69200","1.89120","0.02775"
"3849","23.05800","1.92170","0.02805"
"3910","23.42400","1.95219","0.02778"
"3971","23.79000","1.98262","0.02801"
"4032","24.15600","2.01311","0.02835"
"4093","24.52200","2.04367","0.02775"
"4154","24.88800","2.07422","0.02828"
"4215","25.25400","2.10465","0.02801"
"4276","25.62000","2.13514","0.02815"
"4337","25.98600","2.16570","0.02770"
"4398","26.35200","2.19613","0.02837"
"4459","26.71800","2.22668","0.02833"
"4520","27.08400","2.25723","0.02826"
"4581","27.45000","2.28761","0.02801"
"4642","27.81600","2.31822","0.02798"
"4703","28.18200","2.34865","0.02870"
"4764","28.54800","2.37914","0.02801"
"4825","28.91400","2.40970","0.02780"
"4886","29.28000","2.44025","0.02796"
"4947","29.64600","2.47062","0.02813"
"5008","30.01200","2.50118","0.02763"
"5069","30.37800","2.53173","0.02832"
"5130","30.74400","2.56216","0.02806"
"5191","31.11000","2.59271","0.02813"
"5252","31.47600","2.62315","0.02824"
"5313","31.84200","2.65370","0.02822"
"5374","32.20800","2.68419","0.02841"
"5435","32.57400","2.71468","0.02850"
"5496","32.94000","2.74518","0.02791"
"5557","33.30600","2.77561","0.02834"
"5618","33.67200","2.80622","0.02845"
"5679","34.03800","2.83665","0.02831"
"5740","34.40400","2.86715","0.02823"
"5801","34.77000","2.89770","0.02834"
"5862","35.13600","2.92819","0.02827"
"5923","35.50200","2.95863","0.02818"
"5984","35.86800","2.98924","0.02840"
"6045","36.23400","3.01967","0.02797"
"6106","36.60000","3.05010","0.02844"
"6167","36.96600","3.08072","0.02837"
"6228","37.33200","3.11121","0.02868"
"6289","37.69800","3.14164","0.02801"
"6350","38.06400","3.17219","0.02869"
"6411","38.43000","3.20269","0.02863"
"6472","38.79600","3.23306","0.02790"
"6533","39.16200","3.26373","0.02824"
"6594","39.52800","3.29416","0.02876"
"6655","39.89400","3.32466","0.02828"
"6716","40.26000","3.35515","0.02834"
"6777","40.62600","3.38570","0.02843"
"6838","40.99200","3.41619","0.02834"
"6899","41.35800","3.44669","0.02825"
"6960","41.72400","3.47724","0.02835"
"7021","42.09000","3.50767","0.02879"
"7082","42.45600","3.53817","0.02861"
"7143","42.82200","3.56866","0.02898"
"7204","43.18800","3.59915","0.02861"
"7265","43.55400","3.62964","0.02877"
"7326","43.92000","3.66020","0.02863"
"7387","44.28600","3.69069","0.02853"
"7448","44.65200","3.72112","0.02851"
"7509","45.01800","3.75173","0.02868"
"7570","45.38400","3.78223","0.02876"
"7631","45.75000","3.81260","0.02830"
"7692","46.11600","3.84321","0.02864"
"7753","46.48200","3.87376","0.02848"
"7814","46.84800","3.90408","0.02859"
"7875","47.21400","3.93469","0.02819"
"7936","47.58000","3.96518","0.02855"
"7997","47.94600","3.99567","0.02875"
"8058","48.31200","4.02623","0.02888"
"8119","48.67800","4.05666","0.02893"
"8180","49.04400","4.08715","0.02834"
"8241","49.41000","4.11770","0.02883"
"8302","49.77600","4.14820","0.02838"
"8363","50.14200","4.17869","0.02833"
"8424","50.50800","4.20918","0.02858"
"8485","50.87400","4.23968","0.02856"
"8546","51.24000","4.27011","0.02868"
"8607","51.60600","4.30066","0.02884"
"8668","51.97200","4.33121","0.02909"
"8729","52.33800","4.36171","0.02889"
"8790","52.70400","4.39214","0.02885"
"8851","53.07000","4.42275","0.02873"
"8912","53.43600","4.45318","0.02896"
"8973","53.80200","4.48362","0.02911"
"9034","54.16800","4.51417","0.02887"
"9095","54.53400","4.54472","0.02887"
"9156","54.90000","4.57515","0.02872"
"9217","55.26600","4.60571","0.02895"
"9278","55.63200","4.63620","0.02849"
"9339","55.99800","4.66657","0.02826"
"9400","56.36400","4.69725","0.02867"
"9461","56.73000","4.72768","0.02871"
"9522","57.09600","4.75817","0.02878"
"9583","57.46200","4.78872","0.02821"
"9644","57.82800","4.81922","0.02824"
"9705","58.19400","4.84965","0.02882"
"9766","58.56000","4.88014","0.02880"
"9827","58.92600","4.91069","0.02917"
"9888","59.29200","4.94119","0.02877"
"9949","59.65800","4.97168","0.02913"
"10010","60.02400","5.00217","0.02827"
"10071","60.39000","5.03266","0.02833"
"10132","60.75600","5.06310","0.02889"
"10193","61.12200","5.09371","0.02906"
"10254","61.48800","5.12420","0.02902"
"10315","61.85400","5.15464","0.02855"
"10376","62.22000","5.18525","0.02899"
"10437","62.58600","5.21568","0.02889"
"10498","62.95200","5.24611","0.02873"
"10559","63.31800","5.27667","0.02926"
"10620","63.68400","5.30722","0.02854"
"10681","64.05000","5.33759","0.02878"
"10742","64.41600","5.36820","0.02882"
"10803","64.78200","5.39870","0.02887"
"10864","65.14800","5.42913","0.02884"
"10925","65.51400","5.45968","0.02865"
"10986","65.88000","5.49017","0.02860"
"11047","66.24600","5.52061","0.02861"
"11108","66.61200","5.55122","0.02883"
"11169","66.97800","5.58171","0.02872"
"11230","67.34400","5.61214","0.02860"
"11291","67.71000","5.64270","0.02883"
"11352","68.07600","5.67313","0.02883"
"11413","68.44200","5.70368","0.02902"
"11474","68.80800","5.73412","0.02850"
"11535","69.17400","5.76467","0.02901"
"11596","69.54000","5.79516","0.02881"
"11657","69.90600","5.82565","0.02874"
"11718","70.27200","5.85621","0.02885"
"11779","70.63800","5.88670","0.02901"
"11840","71.00400","5.91719","0.02907"
"11901","71.37000","5.94768","0.02930"
"11962","71.73600","5.97824","0.02900"
"12023","72.10200","6.00861","0.02893"
"12084","72.46800","6.03922","0.02925"
"12145","72.83400","6.06965","0.02868"
"12206","73.20000","6.10009","0.02932"
"12267","73.56600","6.13070","0.02939"
"12328","73.93200","6.16119","0.02880"
"12389","74.29800","6.19162","0.02886"
"12450","74.66400","6.22218","0.02907"
"12511","75.03000","6.25273","0.02914"
"12572","75.39600","6.28310","0.02853"
"12633","75.76200","6.31371","0.02934"
"12694","76.12800","6.34421","0.02909"
"12755","76.49400","6.37464","0.02900"
"12816","76.86000","6.40513","0.02936"
"12877","77.22600","6.43569","0.02889"
"12938","77.59200","6.46618","0.02893"
"12999","77.95800","6.49667","0.02921"
"13060","78.32400","6.52722","0.02889"
"13121","78.69000","6.55766","0.02876"
"13182","79.05600","6.58815","0.02924"
"13243","79.42200","6.61870","0.02909"
"13304","79.78800","6.64919","0.02897"
"13365","80.15400","6.67969","0.02924"
"13426","80.52000","6.71018","0.02917"
"13487","80.88600","6.74067","0.02917"
"13548","81.25200","6.77111","0.02908"
"13609","81.61800","6.80172","0.02932"
"13670","81.98400","6.83221","0.02905"
"13731","82.35000","6.86264","0.02898"
"13792","82.71600","6.89320","0.02902"
"13853","83.08200","6.92369","0.02888"
"13914","83.44800","6.95412","0.02938"
"13975","83.81400","6.98467","0.02873"
"14036","84.18000","7.01523","0.02887"
"14097","84.54600","7.04560","0.02944"
"14158","84.91200","7.07621","0.02898"
"14219","85.27800","7.10670","0.02904"
"14280","85.64400","7.13720","0.02885"
"14341","86.01000","7.16763","0.02914"
"14402","86.37600","7.19818","0.02872"
"14463","86.74200","7.22867","0.02901"
"14524","87.10800","7.25917","0.02883"
"14585","87.47400","7.28966","0.02902"
"14646","87.84000","7.32021","0.02867"
"14707","88.20600","7.35065","0.02864"
"14768","88.57200","7.38120","0.02857"
"14829","88.93800","7.41169","0.02894"
"14890","89.30400","7.44218","0.02926"
"14951","89.67000","7.47268","0.02935"
"15012","90.03600","7.50317","0.02895"
"15073","90.40200","7.53360","0.02906"
"15134","90.76800","7.56421","0.02885"
"15195","91.13400","7.59471","0.02899"
"15256","91.50000","7.62514","0.02865"
"15317","91.86600","7.65569","0.02902"
"15378","92.23200","7.68624","0.02889"
"15439","92.59800","7.71662","0.02902"
"15500","92.96400","7.74723","0.02902"
"15561","93.33000","7.77772","0.02904"
"15622","93.69600","7.80816","0.02911"
"15683","94.06200","7.83865","0.02926"
"15744","94.42800","7.86914","0.02883"
"15805","94.79400","7.89969","0.02873"
"15866","95.16000","7.93018","0.02930"
"15927","95.52600","7.96068","0.02901"
"15988","95.89200","7.99117","0.02884"
"16049","96.25800","8.02166","0.02945"
"16110","96.62400","8.05216","0.02957"
"16171","96.99000","8.08271","0.02888"
"16232","97.35600","8.11320","0.02879"
"16293","97.72200","8.14369","0.02911"
"16354","98.08800","8.17419","0.02931"
"16415","98.45400","8.20462","0.02913"
"16476","98.82000","8.23517","0.02942"
"16537","99.18600","8.26572","0.02888"
"16598","99.55200","8.29616","0.02935"
"16659","99.91800","8.32671","0.02907"
"16720","100.28400","8.35720","0.02871"
"16781","100.65000","8.38763","0.02932"
"16842","101.01600","8.41819","0.02887"
"16903","101.38200","8.44868","0.02947"
"16964","101.74800","8.47917","0.02907"
"17025","102.11400","8.50966","0.02966"
"17086","102.48000","8.54016","0.02909"
"17147","102.84600","8.57065","0.02920"
"17208","103.21200","8.60114","0.02928"
"17269","103.57800","8.63175","0.02964"
"17330","103.94400","8.66213","0.02947"
"17391","104.31000","8.69268","0.02961"
"17452","104.67600","8.72317","0.02925"
"17513","105.04200","8.75367","0.02946"
"17574","105.40800","8.78416","0.02932"
"17635","105.77400","8.81477","0.02943"
"17696","106.14000","8.84520","0.02950"
"17757","106.50600","8.87570","0.02940"
"17818","106.87200","8.90619","0.02944"
"17879","107.23800","8.93668","0.02950"
"17940","107.60400","8.96717","0.02923"
"18001","107.97000","8.99773","0.02963"
"18062","108.33600","9.02816","0.02979"
"18123","108.70200","9.05865","0.02904"
"18184","109.06800","9.08920","0.02999"
"18245","109.43400","9.11970","0.02954"
"18306","109.80000","9.15013","0.02899"
"18367","110.16600","9.18068","0.02948"
"18428","110.53200","9.21124","0.02947"
"18489","110.89800","9.24167","0.02956"
"18550","111.26400","9.27216","0.02945"
"18611","111.63000","9.30265","0.02969"
"18672","111.99600","9.33315","0.02943"
"18733","112.36200","9.36370","0.02985"
"18794","112.72800","9.39413","0.02935"
"18855","113.09400","9.42462","0.02940"
"18916","113.46000","9.45518","0.02964"
"18977","113.82600","9.48573","0.02977"
"19038","114.19200","9.51616","0.02981"
"19099","114.55800","9.54665","0.02996"
"19160","114.92400","9.57721","0.02958"
"19221","115.29000","9.60764","0.02952"
"19282","115.65600","9.63813","0.02973"
"19343","116.02200","9.66875","0.02919"
"19404","116.38800","9.69918","0.03023"
"19465","116.75400","9.72967","0.02975"
"19526","117.12000","9.76022","0.02931"
"19587","117.48600","9.79072","0.03000"
"19648","117.85200","9.82115","0.02932"
"19709","118.21800","9.85170","0.02981"
"19770","118.58400","9.88219","0.02920"
"19831","118.95000","9.91269","0.02983"
"19892","119.31600","9.94318","0.02995"
"19953","119.68200","9.97373","0.03015"
"20014","120.04800","10.00410","0.02973"
"20075","120.41400","10.03466","0.02933"
"20136","120.78000","10.06521","0.02959"
"20197","121.14600","10.09564","0.02976"
"20258","121.51200","10.12619","0.02990"
"20319","121.87800","10.15669","0.02985"
"20380","122.24400","10.18718","0.02941"
"20441","122.61000","10.21761","0.02948"
"20502","122.97600","10.24817","0.02991"
"20563","123.34200","10.27866","0.02971"
"20624","123.70800","10.30921","0.02950"
"20685","124.07400","10.33970","0.02955"
"20746","124.44000","10.37014","0.02934"
"20807","124.80600","10.40069","0.02984"
"20868","125.17200","10.43118","0.02976"
"20929","125.53800","10.46167","0.02989"
"20990","125.90400","10.49217","0.02959"
"21051","126.27000","10.52272","0.02985"
"21112","126.63600","10.55321","0.02952"
"21173","127.00200","10.58364","0.02965"
"21234","127.36800","10.61414","0.02956"
"21295","127.73400","10.64463","0.03000"
"21356","128.10000","10.67512","0.02995"
"21417","128.46600","10.70561","0.02990"
"21478","128.83200","10.73623","0.02942"
"21539","129.19800","10.76666","0.02951"
"21600","129.56400","10.79721","0.03010"
"21661","129.93000","10.82765","0.02972"
"21722","130.29600","10.85820","0.02990"
"21783","130.66200","10.88863","0.03059"
"21844","131.02800","10.91918","0.03043"
"21905","131.39400","10.94968","0.02987"
"21966","131.76000","10.98017","0.02993"
"22027","132.12600","11.01072","0.03011"
"22088","132.49200","11.04109","0.02991"
"22149","132.85800","11.07171","0.02991"
"22210","133.22400","11.10220","0.02996"
"22271","133.59000","11.13263","0.02988"
"22332","133.95600","11.16313","0.03004"
"22393","134.32200","11.19368","0.02978"
"22454","134.68800","11.22417","0.02998"
"22515","135.05400","11.25460","0.02968"
"22576","135.42000","11.28515","0.02983"
"22637","135.78600","11.31565","0.02954"
"22698","136.15200","11.34620","0.02984"
"22759","136.51800","11.37669","0.02976"
"22820","136.88400","11.40724","0.02974"
"22881","137.25000","11.43762","0.03034"
"22942","137.61600","11.46817","0.02982"
"23003","137.98200","11.49866","0.03008"
"23064","138.34800","11.52915","0.03009"
"23125","138.71400","11.55971","0.03025"
"23186","139.08000","11.59020","0.03017"
"23247","139.44600","11.62069","0.03020"
"23308","139.81200","11.65113","0.03007"
"23369","140.17800","11.68168","0.03026"
"23430","140.54400","11.71205","0.03000"
"23491","140.91000","11.74266","0.03031"
"23552","141.27600","11.77316","0.03029"
"23613","141.64200","11.80365","0.03000"
"23674","142.00800","11.83414","0.03026"
"23735","142.37400","11.86469","0.03069"
"23796","142.74000","11.89519","0.03036"
"23857","143.10600","11.92568","0.03004"
"23918","143.47200","11.95623","0.03087"
"23979","143.83800","11.98667","0.03051"
"24040","144.20400","12.01716","0.03030"
"24101","144.57000","12.04765","0.02989"
"24162","144.93600","12.07820","0.03025"
"24223","145.30200","12.10864","0.03019"
"24284","145.66800","12.13913","0.03075"
"24345","146.03400","12.16968","0.03103"
"24406","146.40000","12.20017","0.03019"
"24467","146.76600","12.23067","0.03071"
"24528","147.13200","12.26116","0.03018"
"24589","147.49800","12.29165","0.03074"
"24650","147.86400","12.32214","0.03054"
"24711","148.23000","12.35270","0.03088"
"24772","148.59600","12.38313","0.03104"
"24833","148.96200","12.41368","0.03047"
"24894","149.32800","12.44423","0.03093"
"24955","149.69400","12.47467","0.03051"
"25016","150.06000","12.50516","0.03057"
"25077","150.42600","12.53571","0.03061"
"25138","150.79200","12.56615","0.03051"
"25199","151.15800","12.59664","0.03083"
"25260","151.52400","12.62725","0.03074"
"25321","151.89000","12.65768","0.03048"
"25382","152.25600","12.68818","0.03084"
"25443","152.62200","12.71867","0.03081"
"25504","152.98800","12.74910","0.03041"
"25565","153.35400","12.77965","0.03055"
"25626","153.72000","12.81015","0.03074"
"25687","154.08600","12.84070","0.03064"
"25748","154.45200","12.87119","0.03037"
"25809","154.81800","12.90168","0.03115"
"25870","155.18400","12.93218","0.03076"
"25931","155.55000","12.96267","0.03044"
"25992","155.91600","12.99316","0.03102"
"26053","156.28200","13.02372","0.03075"
"26114","156.64800","13.05415","0.03120"
"26175","157.01400","13.08470","0.03096"
"26236","157.38000","13.11519","0.03091"
"26297","157.74600","13.14563","0.03113"
"26358","158.11200","13.17618","0.03086"
"26419","158.47800","13.20667","0.03077"
"26480","158.84400","13.23716","0.03137"
"26541","159.21000","13.26766","0.03117"
"26602","159.57600","13.29815","0.03118"
"26663","159.94200","13.32864","0.03120"
"26724","160.30800","13.35913","0.03135"
"26785","160.67400","13.38969","0.03097"
"26846","161.04000","13.42018","0.03127"
"26907","161.40600","13.45067","0.03125"
"26968","161.77200","13.48116","0.03152"
"27029","162.13800","13.51166","0.03114"
"27090","162.50400","13.54215","0.03112"
"27151","162.87000","13.57264","0.03131"
"27212","163.23600","13.60320","0.03116"
"27273","163.60200","13.63369","0.03113"
"27334","163.96800","13.66424","0.03129"
"27395","164.33400","13.69467","0.03138"
"27456","164.70000","13.72517","0.03170"
"27517","165.06600","13.75566","0.03176"
"27578","165.43200","13.78621","0.03170"
"27639","165.79800","13.81664","0.03158"
"27700","166.16400","13.84720","0.03158"
"27761","166.53000","13.87769","0.03177"
"27822","166.89600","13.90818","0.03152"
"27883","167.26200","13.93867","0.03178"
"27944","167.62800","13.96917","0.03194"
"28005","167.99400","13.99966","0.03222"
"28066","168.36000","14.03015","0.03190"
"28127","168.72600","14.06070","0.03156"
"28188","169.09200","14.09120","0.03188"
"28249","169.45800","14.12169","0.03182"
"28310","169.82400","14.15218","0.03183"
"28371","170.19000","14.18267","0.03172"
"28432","170.55600","14.21317","0.03199"
"28493","170.92200","14.24372","0.03221"
"28554","171.28800","14.27415","0.03210"
"28615","171.65400","14.30465","0.03231"
"28676","172.02000","14.33520","0.03215"
"28737","172.38600","14.36569","0.03232"
"28798","172.75200","14.39618","0.03196"
"28859","173.11800","14.42668","0.03231"
"28920","173.48400","14.45723","0.03241"
"28981","173.85000","14.48754","0.03246"
"29042","174.21600","14.51821","0.03233"
"29103","174.58200","14.54871","0.03254"
"29164","174.94800","14.57914","0.03238"
"29225","175.31400","14.60969","0.03285"
"29286","175.68000","14.64019","0.03259"
"29347","176.04600","14.67068","0.03276"
"29408","176.41200","14.70111","0.03222"
"29469","176.77800","14.73172","0.03310"
"29530","177.14400","14.76216","0.03249"
"29591","177.51000","14.79271","0.03209"
"29652","177.87600","14.82320","0.03192"
"29713","178.24200","14.85363","0.03210"
"29774","178.60800","14.88419","0.03182"
"29835","178.97400","14.91468","0.03253"
"29896","179.34000","14.94517","0.03181"
"29957","179.70600","14.97566","0.03213"
"30018","180.07200","15.00622","0.03230"
"30079","180.43800","15.03665","0.03250"
"30140","180.80400","15.06714","0.03276"
"30201","181.17000","15.09769","0.03279"
"30262","181.53600","15.12819","0.03294"
"30323","181.90200","15.15862","0.03226"
"30384","182.26800","15.18917","0.03234"
"30445","182.63400","15.21972","0.03195"
"30506","183.00000","15.25016","0.03229"
"30567","183.36600","15.28071","0.03243"
"30628","183.73200","15.31120","0.03238"
"30689","184.09800","15.34164","0.03224"
"30750","184.46400","15.37219","0.03186"
"30811","184.83000","15.40268","0.03121"
"30872","185.19600","15.43317","0.03028"
"30933","185.56200","15.46367","0.03053"
"30994","185.92800","15.49416","0.03089"
"31055","186.29400","15.52465","0.03080"
"31116","186.66000","15.55515","0.03117"
"31177","187.02600","15.58570","0.03114"
"31238","187.39200","15.61619","0.03123"
"31299","187.75800","15.64668","0.03108"
"31360","188.12400","15.67723","0.03124"
"31421","188.49000","15.70767","0.03154"
"31482","188.85600","15.73816","0.03139"
"31543","189.22200","15.76871","0.03113"
"31604","189.58800","15.79914","0.03140"
"31665","189.95400","15.82964","0.03171"
"31726","190.32000","15.86025","0.03155"
"31787","190.68600","15.89074","0.03139"
"31848","191.05200","15.92112","0.03193"
"31909","191.41800","15.95173","0.03152"
"31970","191.78400","15.98216","0.03132"
"32031","192.15000","16.01259","0.03151"
"32092","192.51600","16.04315","0.03141"
"32153","192.88200","16.07370","0.03166"
"32214","193.24800","16.10419","0.03155"
"32275","193.61400","16.13468","0.03146"
"32336","193.98000","16.16518","0.03246"
"32397","194.34600","16.19567","0.03177"
"32458","194.71200","16.22616","0.03176"
"32519","195.07800","16.25665","0.03229"
"32580","195.44400","16.28715","0.03167"
"32641","195.81000","16.31764","0.03205"
"32702","196.17600","16.34819","0.03240"
"32763","196.54200","16.37868","0.03197"
"32824","196.90800","16.40918","0.03212"
"32885","197.27400","16.43973","0.03163"
"32946","197.64000","16.47016","0.03188"
"33007","198.00600","16.50066","0.03228"
"33068","198.37200","16.53121","0.03223"
"33129","198.73800","16.56170","0.03203"
"33190","199.10400","16.59213","0.03242"
"33251","199.47000","16.62268","0.03253"
"33312","199.83600","16.65318","0.03231"
"33373","200.20200","16.68361","0.03210"
"33434","200.56800","16.71422","0.03244"
"33495","200.93400","16.74472","0.03245"
"33556","201.30000","16.77515","0.03288"
"33617","201.66600","16.80564","0.03294"
"33678","202.03200","16.83619","0.03340"
"33739","202.39800","16.86663","0.03259"
"33800","202.76400","16.89718","0.03252"
"33861","203.13000","16.92767","0.03279"
"33922","203.49600","16.95816","0.03267"
"33983","203.86200","16.98866","0.03315"
"34044","204.22800","17.01915","0.03282"
"34105","204.59400","17.04970","0.03261"
"34166","204.96000","17.08014","0.03259"
"34227","205.32600","17.11075","0.03277"
"34288","205.69200","17.14118","0.03342"
"34349","206.05800","17.17161","0.03326"
"34410","206.42400","17.20217","0.03297"
"34471","206.79000","17.23266","0.03346"
"34532","207.15600","17.26309","0.03298"
"34593","207.52200","17.29376","0.03328"
"34654","207.88800","17.32425","0.03314"
"34715","208.25400","17.35463","0.03286"
"34776","208.62000","17.38524","0.03405"
"34837","208.98600","17.41567","0.03353"
"34898","209.35200","17.44611","0.03343"
"34959","209.71800","17.47666","0.03332"
"35020","210.08400","17.50721","0.03323"
"35081","210.45000","17.53758","0.03357"
"35142","210.81600","17.56820","0.03361"
"35203","211.18200","17.59869","0.03406"
"35264","211.54800","17.62912","0.03388"
"35325","211.91400","17.65968","0.03446"
"35386","212.28000","17.69017","0.03406"
"35447","212.64600","17.72066","0.03479"
"35508","213.01200","17.75115","0.03373"
"35569","213.37800","17.78171","0.03411"
"35630","213.74400","17.81220","0.03365"
"35691","214.11000","17.84263","0.03356"
"35752","214.47600","17.87318","0.03440"
"35813","214.84200","17.90368","0.03426"
"35874","215.20800","17.93417","0.03415"
"35935","215.57400","17.96466","0.03520"
"35996","215.94000","17.99521","0.03444"
"36057","216.30600","18.02565","0.03473"
"36118","216.67200","18.05620","0.03414"
"36179","217.03800","18.08669","0.03403"
"36240","217.40400","18.11713","0.03472"
"36301","217.77000","18.14774","0.03391"
"36362","218.13600","18.17823","0.03403"
"36423","218.50200","18.20866","0.03443"
"36484","218.86800","18.23922","0.03418"
"36545","219.23400","18.26971","0.03419"
"36606","219.60000","18.30008","0.03465"
"36667","219.96600","18.33069","0.03438"
"36728","220.33200","18.36119","0.03490"
"36789","220.69800","18.39168","0.03436"
"36850","221.06400","18.42217","0.03442"
"36911","221.43000","18.45267","0.03483"
"36972","221.79600","18.48316","0.03472"
"37033","222.16200","18.51365","0.03469"
"37094","222.52800","18.54420","0.03485"
"37155","222.89400","18.57469","0.03549"
"37216","223.26000","18.60519","0.03492"
"37277","223.62600","18.63568","0.03511"
"37338","223.99200","18.66617","0.03506"
"37399","224.35800","18.69661","0.03527"
"37460","224.72400","18.72716","0.03554"
"37521","225.09000","18.75771","0.03478"
"37582","225.45600","18.78808","0.03518"
"37643","225.82200","18.81875","0.03611"
"37704","226.18800","18.84925","0.03557"
"37765","226.55400","18.87962","0.03528"
"37826","226.92000","18.91017","0.03547"
"37887","227.28600","18.94073","0.03625"
"37948","227.65200","18.97110","0.03559"
"38009","228.01800","19.00171","0.03620"
"38070","228.38400","19.03220","0.03579"
"38131","228.75000","19.06264","0.03599"
"38192","229.11600","19.09319","0.03700"
"38253","229.48200","19.12362","0.03682"
"38314","229.84800","19.15417","0.03601"
"38375","230.21400","19.18467","0.03709"
"38436","230.58000","19.21516","0.03706"
"38497","230.94600","19.24565","0.03694"
"38558","231.31200","19.27615","0.03762"
"38619","231.67800","19.30670","0.03761"
"38680","232.04400","19.33713","0.03805"
"38741","232.41000","19.36762","0.03814"
"38802","232.77600","19.39817","0.03772"
"38863","233.14200","19.42873","0.03834"
"38924","233.50800","19.45910","0.03844"
"38985","233.87400","19.48971","0.03902"
"39046","234.24000","19.52021","0.03823"
"39107","234.60600","19.55064","0.03916"
"39168","234.97200","19.58119","0.03872"
"39229","235.33800","19.61168","0.03929"
"39290","235.70400","19.64212","0.03989"
"39351","236.07000","19.67267","0.03776"
"39412","236.43600","19.70322","0.03642"
"39473","236.80200","19.73359","0.03836"
"39534","237.16800","19.76421","0.03786"
"39595","237.53400","19.79464","0.03732"
"39656","237.90000","19.82513","0.03754"
"39717","238.26600","19.85569","0.03833"
"39778","238.63200","19.88624","0.03777"
"39839","238.99800","19.91661","0.03826"
"39900","239.36400","19.94716","0.03778"
"39961","239.73000","19.97772","0.03905"
"40022","240.09600","20.00815","0.03854"
"40083","240.46200","20.03864","0.03870"
"40144","240.82800","20.06919","0.03901"
"40205","241.19400","20.09968","0.03866"
"40266","241.56000","20.13012","0.03883"
"40327","241.92600","20.16067","0.03911"
"40388","242.29200","20.19116","0.03946"
"40449","242.65800","20.22166","0.03944"
"40510","243.02400","20.25215","0.03883"
"40571","243.39000","20.28270","0.03926"
"40632","243.75600","20.31314","0.03994"
"40693","244.12200","20.34369","0.04026"
"40754","244.48800","20.37418","0.04055"
"40815","244.85400","20.40461","0.04059"
"40876","245.22000","20.43522","0.04128"
"40937","245.58600","20.46566","0.04149"
"40998","245.95200","20.49615","0.04059"
"41059","246.31800","20.52670","0.04131"
"41120","246.68400","20.55720","0.04165"
"41181","247.05000","20.58763","0.04234"
"41242","247.41600","20.61818","0.04194"
"41303","247.78200","20.64874","0.04209"
"41364","248.14800","20.67916","0.04322"
"41425","248.51400","20.70966","0.04325"
"41486","248.88000","20.74015","0.04337"
"41547","249.24600","20.77070","0.04296"
"41608","249.61200","20.80114","0.04309"
"41669","249.97800","20.83169","0.04388"
"41730","250.34400","20.86218","0.04401"
"41791","250.71000","20.89268","0.04358"
"41852","251.07600","20.92317","0.04228"
"41913","251.44200","20.95372","0.03921"
"41974","251.80800","20.98415","0.03890"
"42035","252.17400","21.01471","0.03795"
"42096","252.54000","21.04520","0.03811"
"42157","252.90600","21.07563","0.03748"
"42218","253.27200","21.10618","0.03774"
"42279","253.63800","21.13667","0.03869"
"42340","254.00400","21.16717","0.03820"
"42401","254.37000","21.19772","0.03930"
"42462","254.73600","21.22821","0.03849"
"42523","255.10200","21.25865","0.03943"
"42584","255.46800","21.28914","0.03928"
"42645","255.83400","21.31969","0.03948"
"42706","256.20000","21.35012","0.03971"
"42767","256.56600","21.38068","0.04028"
"42828","256.93200","21.41117","0.04019"
"42889","257.29800","21.44166","0.03933"
"42950","257.66400","21.47216","0.04118"
"43011","258.03000","21.50265","0.04064"
"43072","258.39600","21.53320","0.04101"
"43133","258.76200","21.56369","0.04132"
"43194","259.12800","21.59418","0.04179"
"43255","259.49400","21.62468","0.04165"
"43316","259.86000","21.65517","0.04156"
"43377","260.22600","21.68566","0.04162"
"43438","260.59200","21.71622","0.04075"
"43499","260.95800","21.74665","0.04201"
"43560","261.32400","21.77720","0.03976"
"43621","261.69000","21.80769","0.04003"
"43682","262.05600","21.83813","0.04072"
"43743","262.42200","21.86874","0.03967"
"43804","262.78800","21.89917","0.03921"
"43865","263.15400","21.92966","0.04048"
"43926","263.52000","21.96016","0.03974"
"43987","263.88600","21.99071","0.04038"
"44048","264.25200","22.02108","0.04120"
"44109","264.61800","22.05169","0.04077"
"44170","264.98400","22.08219","0.04156"
"44231","265.35000","22.11262","0.04159"
"44292","265.71600","22.14323","0.04122"
"44353","266.08200","22.17367","0.04166"
"44414","266.44800","22.20416","0.04075"
"44475","266.81400","22.23465","0.04207"
"44536","267.18000","22.26526","0.04137"
"44597","267.54600","22.29570","0.03963"
"44658","267.91200","22.32613","0.04016"
"44719","268.27800","22.35668","0.03994"
"44780","268.64400","22.38717","0.04005"
"44841","269.01000","22.41767","0.04104"
"44902","269.37600","22.44816","0.04087"
"44963","269.74200","22.47871","0.04052"
"45024","270.10800","22.50914","0.04051"
"45085","270.47400","22.53970","0.03995"
"45146","270.84000","22.57013","0.04145"
"45207","271.20600","22.60062","0.03943"
"45268","271.57200","22.63118","0.03994"
"45329","271.93800","22.66173","0.04002"
"45390","272.30400","22.69216","0.03929"
"45451","272.67000","22.72271","0.03635"
"45512","273.03600","22.75321","0.03780"
"45573","273.40200","22.78364","0.03863"
"45634","273.76800","22.81419","0.03779"
"45695","274.13400","22.84468","0.03780"
"45756","274.50000","22.87518","0.03885"
"45817","274.86600","22.90561","0.03934"
"45878","275.23200","22.93616","0.03940"
"45939","275.59800","22.96666","0.03948"
"46000","275.96400","22.99709","0.03983"
"46061","276.33000","23.02770","0.03998"
"46122","276.69600","23.05819","0.03996"
"46183","277.06200","23.08862","0.04078"
"46244","277.42800","23.11918","0.04070"
"46305","277.79400","23.14973","0.03982"
"46366","278.16000","23.18016","0.04034"
"46427","278.52600","23.21072","0.04084"
"46488","278.89200","23.24115","0.04101"
"46549","279.25800","23.27164","0.04078"
"46610","279.62400","23.30219","0.04083"
"46671","279.99000","23.33269","0.04138"
"46732","280.35600","23.36318","0.04094"
"46793","280.72200","23.39373","0.04166"
"46854","281.08800","23.42416","0.04191"
"46915","281.45400","23.45454","0.04204"
"46976","281.82000","23.48521","0.03347"
"47037","282.18600","23.51570","0.03326"
"47098","282.55200","23.54607","0.03549"
"47159","282.91800","23.57669","0.03486"
"47220","283.28400","23.60724","0.03415"
"47281","283.65000","23.63767","0.03379"
"47342","284.01600","23.66811","0.03563"
"47403","284.38200","23.69872","0.03456"
"47464","284.74800","23.72915","0.03388"
"47525","285.11400","23.75970","0.03514"
"47586","285.48000","23.79013","0.03492"
"47647","285.84600","23.82063","0.03583"
"47708","286.21200","23.85112","0.03494"
"47769","286.57800","23.88173","0.03477"
"47830","286.94400","23.91216","0.03584"
"47891","287.31000","23.94266","0.03527"
"47952","287.67600","23.97321","0.03575"
"48013","288.04200","24.00364","0.03583"
"48074","288.40800","24.03407","0.03583"
"48135","288.77400","24.06469","0.03666"
"48196","289.14000","24.09518","0.03620"
"48257","289.50600","24.12561","0.03646"
"48318","289.87200","24.15623","0.03698"
"48379","290.23800","24.18672","0.03658"
"48440","290.60400","24.21709","0.03696"
"48501","290.97000","24.24771","0.03702"
"48562","291.33600","24.27820","0.03709"
"48623","291.70200","24.30869","0.03800"
"48684","292.06800","24.33912","0.03783"
"48745","292.43400","24.36968","0.03769"
"48806","292.80000","24.40017","0.03705"
"48867","293.16600","24.43066","0.03760"
"48928","293.53200","24.46121","0.03767"
"48989","293.89800","24.49165","0.03758"
"49050","294.26400","24.52214","0.03570"
"49111","294.63000","24.55269","0.03428"
"49172","294.99600","24.58318","0.03459"
"49233","295.36200","24.61368","0.03480"
"49294","295.72800","24.64423","0.03576"
"49355","296.09400","24.67466","0.03526"
"49416","296.46000","24.70509","0.03589"
"49477","296.82600","24.73571","0.03568"
"49538","297.19200","24.76620","0.03517"
"49599","297.55800","24.79663","0.03587"
"49660","297.92400","24.82719","0.03646"
"49721","298.29000","24.85774","0.03652"
"49782","298.65600","24.88811","0.03697"
"49843","299.02200","24.91872","0.03744"
"49904","299.38800","24.94922","0.03706"
"49965","299.75400","24.97965","0.03746"
"50026","300.12000","25.01014","0.03749"
"50087","300.48600","25.04069","0.03741"
"50148","300.85200","25.07113","0.03762"
"50209","301.21800","25.10168","0.03809"
"50270","301.58400","25.13223","0.03735"
"50331","301.95000","25.16266","0.03797"
"50392","302.31600","25.19322","0.03806"
"50453","302.68200","25.22365","0.03775"
"50514","303.04800","25.25420","0.03842"
"50575","303.41400","25.28464","0.03845"
"50636","303.78000","25.31519","0.03832"
"50697","304.14600","25.34568","0.03821"
"50758","304.51200","25.37617","0.03870"
"50819","304.87800","25.40667","0.03874"
"50880","305.24400","25.43716","0.03892"
"50941","305.61000","25.46765","0.03957"
"51002","305.97600","25.49820","0.03908"
"51063","306.34200","25.52870","0.03879"
"51124","306.70800","25.55907","0.03926"
"51185","307.07400","25.58968","0.03982"
"51246","307.44000","25.62017","0.04004"
"51307","307.80600","25.65067","0.04030"
"51368","308.17200","25.68116","0.04019"
"51429","308.53800","25.71171","0.04047"
"51490","308.90400","25.74220","0.04107"
"51551","309.27000","25.77264","0.04095"
"51612","309.63600","25.80325","0.04066"
"51673","310.00200","25.83362","0.04042"
"51734","310.36800","25.86418","0.04060"
"51795","310.73400","25.89467","0.04049"
"51856","311.10000","25.92516","0.04086"
"51917","311.46600","25.95565","0.04113"
"51978","311.83200","25.98621","0.04140"
"52039","312.19800","26.01670","0.04114"
"52100","312.56400","26.04713","0.04177"
"52161","312.93000","26.07774","0.04223"
"52222","313.29600","26.10818","0.04176"
"52283","313.66200","26.13867","0.04310"
"52344","314.02800","26.16916","0.04238"
"52405","314.39400","26.19971","0.04170"
"52466","314.76000","26.23014","0.04325"
"52527","315.12600","26.26070","0.04292"
"52588","315.49200","26.29119","0.04328"
"52649","315.85800","26.32162","0.04399"
"52710","316.22400","26.35218","0.04352"
"52771","316.59000","26.38267","0.04298"
"52832","316.95600","26.41316","0.04491"
"52893","317.32200","26.44366","0.04402"
"52954","317.68800","26.47427","0.04476"
"53015","318.05400","26.50464","0.04524"
"53076","318.42000","26.53513","0.04495"
"53137","318.78600","26.56569","0.04491"
"53198","319.15200","26.59612","0.04453"
"53259","319.51800","26.62667","0.04372"
"53320","319.88400","26.65716","0.04448"
"53381","320.25000","26.68772","0.04443"
"53442","320.61600","26.71815","0.04540"
"53503","320.98200","26.74870","0.04528"
"53564","321.34800","26.77913","0.04623"
"53625","321.71400","26.80968","0.04646"
"53686","322.08000","26.84018","0.04590"
"53747","322.44600","26.87067","0.04674"
"53808","322.81200","26.90116","0.04684"
"53869","323.17800","26.93172","0.04772"
"53930","323.54400","26.96215","0.04640"
"53991","323.91000","26.99264","0.04796"
"54052","324.27600","27.02320","0.04744"
"54113","324.64200","27.05369","0.04905"
"54174","325.00800","27.08418","0.04838"
"54235","325.37400","27.11467","0.04895"
"54296","325.74000","27.14523","0.04908"
"54357","326.10600","27.17560","0.04952"
"54418","326.47200","27.20615","0.04908"
"54479","326.83800","27.23670","0.04936"
"54540","327.20400","27.26714","0.05035"
"54601","327.57000","27.29775","0.05031"
"54662","327.93600","27.32818","0.05052"
"54723","328.30200","27.35867","0.05117"
"54784","328.66800","27.38911","0.05122"
"54845","329.03400","27.41972","0.05127"
"54906","329.40000","27.45015","0.05184"
"54967","329.76600","27.48064","0.05232"
"55028","330.13200","27.51120","0.05252"
"55089","330.49800","27.54163","0.05287"
"55150","330.86400","27.57218","0.05337"
"55211","331.23000","27.60273","0.05416"
"55272","331.59600","27.63323","0.05501"
"55333","331.96200","27.66366","0.05437"
"55394","332.32800","27.69415","0.05540"
"55455","332.69400","27.72471","0.05531"
"55516","333.06000","27.75514","0.05537"
"55577","333.42600","27.78569","0.05592"
"55638","333.79200","27.81618","0.05637"
"55699","334.15800","27.84668","0.05637"
"55760","334.52400","27.87717","0.05608"
"55821","334.89000","27.90772","0.05735"
"55882","335.25600","27.93809","0.05725"
"55943","335.62200","27.96871","0.05747"
"56004","335.98800","27.99920","0.05820"
"56065","336.35400","28.02963","0.05839"
"56126","336.72000","28.06019","0.05895"
"56187","337.08600","28.09068","0.05973"
"56248","337.45200","28.12117","0.05931"
"56309","337.81800","28.15166","0.06031"
"56370","338.18400","28.18221","0.06040"
"56431","338.55000","28.21259","0.06037"
"56492","338.91600","28.24320","0.06127"
"56553","339.28200","28.27369","0.06095"
"56614","339.64800","28.30419","0.06076"
"56675","340.01400","28.33468","0.06184"
"56736","340.38000","28.36523","0.06210"
"56797","340.74600","28.39566","0.06242"
"56858","341.11200","28.42616","0.06327"
"56919","341.47800","28.45671","0.06326"
"56980","341.84400","28.48714","0.06412"
"57041","342.21000","28.51769","0.06394"
"57102","342.57600","28.54819","0.06467"
"57163","342.94200","28.57868","0.06498"
"57224","343.30800","28.60917","0.06521"
"57285","343.67400","28.63967","0.06536"
"57346","344.04000","28.67016","0.06600"
"57407","344.40600","28.70071","0.06690"
"57468","344.77200","28.73120","0.06824"
"57529","345.13800","28.76170","0.06758"
"57590","345.50400","28.79213","0.06810"
"57651","345.87000","28.82268","0.06853"
"57712","346.23600","28.85323","0.06888"
"57773","346.60200","28.88361","0.07011"
"57834","346.96800","28.91422","0.06970"
"57895","347.33400","28.94471","0.06756"
"57956","347.70000","28.97514","0.06965"
"58017","348.06600","29.00570","0.07015"
"58078","348.43200","29.03619","0.06996"
"58139","348.79800","29.06668","0.07090"
"58200","349.16400","29.09717","0.07079"
"58261","349.53000","29.12773","0.07168"
"58322","349.89600","29.15810","0.07195"
"58383","350.26200","29.18865","0.07273"
"58444","350.62800","29.21915","0.07337"
"58505","350.99400","29.24970","0.07420"
"58566","351.36000","29.28013","0.07471"
"58627","351.72600","29.31068","0.07483"
"58688","352.09200","29.34118","0.07591"
"58749","352.45800","29.37161","0.07671"
"58810","352.82400","29.40216","0.07706"
"58871","353.19000","29.43271","0.07775"
"58932","353.55600","29.46315","0.07828"
"58993","353.92200","29.49370","0.07904"
"59054","354.28800","29.52419","0.07973"
"59115","354.65400","29.55457","0.08075"
"59176","355.02000","29.58518","0.08066"
"59237","355.38600","29.61573","0.08151"
"59298","355.75200","29.64610","0.08190"
"59359","356.11800","29.67672","0.08283"
"59420","356.48400","29.70715","0.08286"
"59481","356.85000","29.73770","0.08407"
"59542","357.21600","29.76819","0.08426"
"59603","357.58200","29.79869","0.08509"
"59664","357.94800","29.82912","0.08580"
"59725","358.31400","29.85967","0.08546"
"59786","358.68000","29.89022","0.08595"
"59847","359.04600","29.92072","0.08629"
"59908","359.41200","29.95115","0.08694"
"59969","359.77800","29.98164","0.08736"
"60030","360.14400","30.01219","0.08744"
"60091","360.51000","30.04263","0.08816"
"60152","360.87600","30.07318","0.08880"
"60213","361.24200","30.10367","0.08853"
"60274","361.60800","30.13416","0.08930"
"60335","361.97400","30.16472","0.08958"
"60396","362.34000","30.19521","0.09007"
"60457","362.70600","30.22564","0.09002"
"60518","363.07200","30.25614","0.09107"
"60579","363.43800","30.28675","0.09108"
"60640","363.80400","30.31712","0.09164"
"60701","364.17000","30.34767","0.09191"
"60762","364.53600","30.37822","0.09197"
"60823","364.90200","30.40866","0.09240"
"60884","365.26800","30.43915","0.09279"
"60945","365.63400","30.46964","0.09335"
"61006","366.00000","30.50014","0.09320"
"61067","366.36600","30.53069","0.09362"
"61128","366.73200","30.56124","0.09382"
"61189","367.09800","30.59167","0.06275"
"61250","367.46400","30.62217","0.03953"
"61311","367.83000","30.65266","0.06082"
"61372","368.19600","30.68315","0.05010"
"61433","368.56200","30.71364","0.05180"
"61494","368.92800","30.74420","0.05709"
"61555","369.29400","30.77469","0.05269"
"61616","369.66000","30.80518","0.05026"
"61677","370.02600","30.83568","0.05785"
"61738","370.39200","30.86617","0.05562"
"61799","370.75800","30.89666","0.05310"
"61860","371.12400","30.92715","0.05854"
"61921","371.49000","30.95777","0.05581"
"61982","371.85600","30.98814","0.05634"
"62043","372.22200","31.01869","0.05943"
"62104","372.58800","31.04918","0.05854"
"62165","372.95400","31.07962","0.05865"
"62226","373.32000","31.11017","0.05969"
"62287","373.68600","31.14066","0.05916"
"62348","374.05200","31.17115","0.06080"
"62409","374.41800","31.20164","0.06062"
"62470","374.78400","31.23220","0.06063"
"62531","375.15000","31.26263","0.06339"
"62592","375.51600","31.29318","0.06339"
"62653","375.88200","31.32368","0.06189"
"62714","376.24800","31.35417","0.06393"
"62775","376.61400","31.38466","0.06522"
"62836","376.98000","31.41515","0.06446"
"62897","377.34600","31.44564","0.06593"
"62958","377.71200","31.47614","0.06712"
"63019","378.07800","31.50669","0.06689"
"63080","378.44400","31.53718","0.06813"
"63141","378.81000","31.56768","0.06931"
"63202","379.17600","31.59817","0.06929"
"63263","379.54200","31.62872","0.07051"
"63324","379.90800","31.65916","0.07112"
"63385","380.27400","31.68971","0.07126"
"63446","380.64000","31.72020","0.07262"
"63507","381.00600","31.75057","0.07301"
"63568","381.37200","31.78119","0.07366"
"63629","381.73800","31.81174","0.07450"
"63690","382.10400","31.84217","0.07550"
"63751","382.47000","31.87266","0.07606"
"63812","382.83600","31.90322","0.07692"
"63873","383.20200","31.93359","0.07720"
"63934","383.56800","31.96414","0.07772"
"63995","383.93400","31.99469","0.07835"
"64056","384.30000","32.02519","0.07886"
"64117","384.66600","32.05568","0.07923"
"64178","385.03200","32.08617","0.08033"
"64239","385.39800","32.11666","0.08048"
"64300","385.76400","32.14716","0.08196"
"64361","386.13000","32.17771","0.08198"
"64422","386.49600","32.20814","0.08243"
"64483","386.86200","32.23864","0.08310"
"64544","387.22800","32.26919","0.08311"
"64605","387.59400","32.29968","0.08401"
"64666","387.96000","32.33012","0.08418"
"64727","388.32600","32.36073","0.08416"
"64788","388.69200","32.39122","0.08504"
"64849","389.05800","32.42159","0.08452"
"64910","389.42400","32.45220","0.08273"
"64971","389.79000","32.48270","0.08268"
"65032","390.15600","32.51313","0.08233"
"65093","390.52200","32.54368","0.08227"
"65154","390.88800","32.57423","0.08338"
"65215","391.25400","32.60461","0.08407"
"65276","391.62000","32.63516","0.08405"
"65337","391.98600","32.66571","0.08565"
"65398","392.35200","32.69615","0.08564"
"65459","392.71800","32.72670","0.08632"
"65520","393.08400","32.75713","0.08702"
"65581","393.45000","32.78762","0.08777"
"65642","393.81600","32.81818","0.08831"
"65703","394.18200","32.84867","0.08912"
"65764","394.54800","32.87916","0.08962"
"65825","394.91400","32.90965","0.08831"
"65886","395.28000","32.94020","0.08761"
"65947","395.64600","32.97064","0.08538"
"66008","396.01200","33.00113","0.08678"
"66069","396.37800","33.03168","0.08598"
"66130","396.74400","33.06218","0.08747"
"66191","397.11000","33.09267","0.08790"
"66252","397.47600","33.12322","0.08842"
"66313","397.84200","33.15371","0.08908"
"66374","398.20800","33.18415","0.08939"
"66435","398.57400","33.21470","0.08951"
"66496","398.94000","33.24519","0.09003"
"66557","399.30600","33.27568","0.09084"
"66618","399.67200","33.30618","0.09113"
"66679","400.03800","33.33673","0.09150"
"66740","400.40400","33.36710","0.09167"
"66801","400.77000","33.39766","0.09223"
"66862","401.13600","33.42815","0.09247"
"66923","401.50200","33.45864","0.09295"
"66984","401.86800","33.48919","0.09366"
"67045","402.23400","33.51968","0.09362"
"67106","402.60000","33.55018","0.09414"
"67167","402.96600","33.58067","0.09514"
"67228","403.33200","33.61116","0.09518"
"67289","403.69800","33.64165","0.09533"
"67350","404.06400","33.67215","0.09666"
"67411","404.43000","33.70270","0.09403"
"67472","404.79600","33.73319","0.09103"
"67533","405.16200","33.76363","0.08941"
"67594","405.52800","33.79424","0.08901"
"67655","405.89400","33.82473","0.09118"
"67716","406.26000","33.85511","0.09169"
"67777","406.62600","33.88572","0.09179"
"67838","406.99200","33.91615","0.09254"
"67899","407.35800","33.94664","0.09262"
"67960","407.72400","33.97720","0.09338"
"68021","408.09000","34.00769","0.09375"
"68082","408.45600","34.03812","0.09448"
"68143","408.82200","34.06867","0.09515"
"68204","409.18800","34.09917","0.09574"
"68265","409.55400","34.12960","0.09678"
"68326","409.92000","34.16021","0.09749"
"68387","410.28600","34.19064","0.09718"
"68448","410.65200","34.22120","0.09984"
"68509","411.01800","34.25169","0.10037"
"68570","411.38400","34.28218","0.10043"
"68631","411.75000","34.31261","0.10234"
"68692","412.11600","34.34317","0.10301"
"68753","412.48200","34.37372","0.10410"
"68814","412.84800","34.40415","0.10687"
"68875","413.21400","34.43465","0.10722"
"68936","413.58000","34.46514","0.10810"
"68997","413.94600","34.49569","0.11028"
"69058","414.31200","34.52612","0.10992"
"69119","414.67800","34.55667","0.11197"
"69180","415.04400","34.58717","0.11440"
"69241","415.41000","34.61766","0.11492"
"69302","415.77600","34.64821","0.11741"
"69363","416.14200","34.67876","0.11906"
"69424","416.50800","34.70908","0.12001"
"69485","416.87400","34.73969","0.12183"
"69546","417.24000","34.77018","0.12348"
"69607","417.60600","34.80062","0.12436"
"69668","417.97200","34.83117","0.12549"
"69729","418.33800","34.86166","0.12747"
"69790","418.70400","34.89215","0.12850"
"69851","419.07000","34.92265","0.13023"
"69912","419.43600","34.95320","0.13235"
"69973","419.80200","34.98363","0.13323"
"70034","420.16800","35.01419","0.13600"
"70095","420.53400","35.04468","0.13769"
"70156","420.90000","35.07511","0.13917"
"70217","421.26600","35.10561","0.14022"
"70278","421.63200","35.13622","0.14156"
"70339","421.99800","35.16665","0.14224"
"70400","422.36400","35.19714","0.14306"
"70461","422.73000","35.22770","0.14347"
"70522","423.09600","35.25819","0.14395"
"70583","423.46200","35.28862","0.14438"
"70644","423.82800","35.31917","0.14446"
"70705","424.19400","35.34972","0.14534"
"70766","424.56000","35.38016","0.14588"
"70827","424.92600","35.41071","0.14748"
"70888","425.29200","35.44120","0.14840"
"70949","425.65800","35.47164","0.15022"
"71010","426.02400","35.50225","0.15227"
"71071","426.39000","35.53268","0.15451"
"71132","426.75600","35.56311","0.15764"
"71193","427.12200","35.59367","0.15932"
"71254","427.48800","35.62416","0.16118"
"71315","427.85400","35.65465","0.16393"
"71376","428.22000","35.68514","0.16638"
"71437","428.58600","35.71569","0.16808"
"71498","428.95200","35.74613","0.16966"
"71559","429.31800","35.77668","0.17147"
"71620","429.68400","35.80717","0.17329"
"71681","430.05000","35.83767","0.17494"
"71742","430.41600","35.86816","0.17611"
"71803","430.78200","35.89871","0.17725"
"71864","431.14800","35.92920","0.17836"
"71925","431.51400","35.95964","0.17920"
"71986","431.88000","35.99019","0.18059"
"72047","432.24600","36.02068","0.18157"
"72108","432.61200","36.05118","0.18200"
"72169","432.97800","36.08173","0.18330"
"72230","433.34400","36.11222","0.18402"
"72291","433.71000","36.14265","0.18585"
"72352","434.07600","36.17321","0.18728"
"72413","434.44200","36.20370","0.18838"
"72474","434.80800","36.23407","0.18948"
"72535","435.17400","36.26474","0.19057"
"72596","435.54000","36.29517","0.19152"
"72657","435.90600","36.32567","0.19284"
"72718","436.27200","36.35616","0.19391"
"72779","436.63800","36.38671","0.19505"
"72840","437.00400","36.41714","0.19623"
"72901","437.37000","36.44764","0.19756"
"72962","437.73600","36.47819","0.19925"
"73023","438.10200","36.50868","0.20125"
"73084","438.46800","36.53918","0.20292"
"73145","438.83400","36.56967","0.20549"
"73206","439.20000","36.60016","0.20762"
"73267","439.56600","36.63060","0.21038"
"73328","439.93200","36.66121","0.21418"
"73389","440.29800","36.69164","0.21683"
"73450","440.66400","36.72213","0.22020"
"73511","441.03000","36.75275","0.22424"
"73572","441.39600","36.78318","0.22939"
"73633","441.76200","36.81361","0.23334"
"73694","442.12800","36.84422","0.23623"
"73755","442.49400","36.87471","0.23875"
"73816","442.86000","36.90509","0.23960"
"73877","443.22600","36.93576","0.24184"
"73938","443.59200","36.96619","0.24290"
"73999","443.95800","36.99662","0.24416"
"74060","444.32400","37.02718","0.24509"
"74121","444.69000","37.05767","0.24576"
"74182","445.05600","37.08810","0.24668"
"74243","445.42200","37.11872","0.24756"
"74304","445.78800","37.14921","0.24845"
"74365","446.15400","37.17964","0.24898"
"74426","446.52000","37.21020","0.24968"
"74487","446.88600","37.24069","0.25066"
"74548","447.25200","37.27118","0.04709"
"74609","447.61800","37.30162","0.03266"
"74670","447.98400","37.33223","0.02898"
"74731","448.35000","37.36266","0.02940"
"74792","448.71600","37.39315","0.02894"
"74853","449.08200","37.42370","0.02870"
"74914","449.44800","37.45420","0.02915"
"74975","449.81400","37.48463","0.02875"
"75036","450.18000","37.51524","0.02862"
"75097","450.54600","37.54573","0.02777"
"75158","450.91200","37.57617","0.02929"
"75219","451.27800","37.60672","0.02892"
"75280","451.64400","37.63715","0.02886"
"75341","452.01000","37.66765","0.02851"
"75402","452.37600","37.69820","0.02908"
"75463","452.74200","37.72869","0.02862"
"75524","453.10800","37.75912","0.02834"
"75526","453.11600","37.75984","0.02851"