File: Trajectories_together/170108_0Specimen_RawData_3.csv
"","V1","V2","V3"
"1","End date","1/8/2017",""
"2","Specimen label","20CG_63",""
"3","Maximum Load","0.05759","N"
"4","Time","Extension","Load"
"5","(s)","(mm)","(N)"
"6","0.00000","0.00000","0.00030"
"64","0.34800","0.02900","0.00075"
"122","0.69600","0.05818","0.00110"
"180","1.04400","0.08723","0.00128"
"238","1.39200","0.11617","0.00132"
"296","1.74000","0.14517","0.00186"
"354","2.08800","0.17417","0.00226"
"412","2.43600","0.20311","0.00253"
"470","2.78400","0.23222","0.00227"
"528","3.13200","0.26116","0.00250"
"586","3.48000","0.29016","0.00330"
"644","3.82800","0.31922","0.00288"
"702","4.17600","0.34821","0.00261"
"760","4.52400","0.37715","0.00309"
"818","4.87200","0.40621","0.00416"
"876","5.22000","0.43521","0.00364"
"934","5.56800","0.46415","0.00367"
"992","5.91600","0.49320","0.00357"
"1050","6.26400","0.52214","0.00354"
"1108","6.61200","0.55114","0.00400"
"1166","6.96000","0.58026","0.00358"
"1224","7.30800","0.60914","0.00409"
"1282","7.65600","0.63819","0.00444"
"1340","8.00400","0.66719","0.00456"
"1398","8.35200","0.69613","0.00493"
"1456","8.70000","0.72519","0.00453"
"1514","9.04800","0.75419","0.00478"
"1572","9.39600","0.78312","0.00415"
"1630","9.74400","0.81218","0.00361"
"1688","10.09200","0.84124","0.00382"
"1746","10.44000","0.87012","0.00502"
"1804","10.78800","0.89923","0.00513"
"1862","11.13600","0.92823","0.00490"
"1920","11.48400","0.95717","0.00398"
"1978","11.83200","0.98623","0.00508"
"2036","12.18000","1.01523","0.00527"
"2094","12.52800","1.04416","0.00450"
"2152","12.87600","1.07316","0.00563"
"2210","13.22400","1.10216","0.00528"
"2268","13.57200","1.13116","0.00510"
"2326","13.92000","1.16016","0.00522"
"2384","14.26800","1.18915","0.00596"
"2442","14.61600","1.21815","0.00566"
"2500","14.96400","1.24727","0.00614"
"2558","15.31200","1.27615","0.00648"
"2616","15.66000","1.30521","0.00635"
"2674","16.00800","1.33420","0.00637"
"2732","16.35600","1.36314","0.00656"
"2790","16.70400","1.39220","0.00651"
"2848","17.05200","1.42120","0.00714"
"2906","17.40000","1.45020","0.00689"
"2964","17.74800","1.47925","0.00756"
"3022","18.09600","1.50813","0.00712"
"3080","18.44400","1.53719","0.00624"
"3138","18.79200","1.56619","0.00658"
"3196","19.14000","1.59518","0.00625"
"3254","19.48800","1.62418","0.00708"
"3312","19.83600","1.65324","0.00692"
"3370","20.18400","1.68212","0.00690"
"3428","20.53200","1.71118","0.00714"
"3486","20.88000","1.74017","0.00699"
"3544","21.22800","1.76911","0.00771"
"3602","21.57600","1.79817","0.00713"
"3660","21.92400","1.82717","0.00797"
"3718","22.27200","1.85617","0.00807"
"3776","22.62000","1.88516","0.00839"
"3834","22.96800","1.91422","0.00849"
"3892","23.31600","1.94316","0.00867"
"3950","23.66400","1.97222","0.00884"
"4008","24.01200","2.00122","0.00917"
"4066","24.36000","2.03015","0.00860"
"4124","24.70800","2.05921","0.00929"
"4182","25.05600","2.08815","0.00971"
"4240","25.40400","2.11715","0.00954"
"4298","25.75200","2.14621","0.00938"
"4356","26.10000","2.17508","0.00982"
"4414","26.44800","2.20420","0.00949"
"4472","26.79600","2.23320","0.00979"
"4530","27.14400","2.26214","0.01017"
"4588","27.49200","2.29119","0.00928"
"4646","27.84000","2.32013","0.00944"
"4704","28.18800","2.34913","0.01003"
"4762","28.53600","2.37819","0.01043"
"4820","28.88400","2.40719","0.01059"
"4878","29.23200","2.43618","0.01080"
"4936","29.58000","2.46518","0.01077"
"4994","29.92800","2.49418","0.01133"
"5052","30.27600","2.52318","0.01135"
"5110","30.62400","2.55224","0.01155"
"5168","30.97200","2.58111","0.01123"
"5226","31.32000","2.61023","0.01158"
"5284","31.66800","2.63917","0.01175"
"5342","32.01600","2.66811","0.01229"
"5400","32.36400","2.69723","0.01242"
"5458","32.71200","2.72616","0.01212"
"5516","33.06000","2.75510","0.01255"
"5574","33.40800","2.78422","0.01338"
"5632","33.75600","2.81328","0.01309"
"5690","34.10400","2.84210","0.01320"
"5748","34.45200","2.87121","0.01344"
"5806","34.80000","2.90021","0.01391"
"5864","35.14800","2.92915","0.01328"
"5922","35.49600","2.95821","0.01407"
"5980","35.84400","2.98714","0.01367"
"6038","36.19200","3.01614","0.01403"
"6096","36.54000","3.04520","0.01437"
"6154","36.88800","3.07414","0.01532"
"6212","37.23600","3.10320","0.01477"
"6270","37.58400","3.13219","0.01548"
"6328","37.93200","3.16113","0.01525"
"6386","38.28000","3.19019","0.01561"
"6444","38.62800","3.21925","0.01534"
"6502","38.97600","3.24819","0.01609"
"6560","39.32400","3.27718","0.01641"
"6618","39.67200","3.30618","0.01651"
"6676","40.02000","3.33518","0.01675"
"6734","40.36800","3.36418","0.01702"
"6792","40.71600","3.39318","0.01705"
"6850","41.06400","3.42217","0.01714"
"6908","41.41200","3.45117","0.01779"
"6966","41.76000","3.48017","0.01816"
"7024","42.10800","3.50917","0.01831"
"7082","42.45600","3.53817","0.01819"
"7140","42.80400","3.56716","0.01856"
"7198","43.15200","3.59622","0.01879"
"7256","43.50000","3.62522","0.01914"
"7314","43.84800","3.65410","0.01866"
"7372","44.19600","3.68321","0.01955"
"7430","44.54400","3.71221","0.02002"
"7488","44.89200","3.74115","0.02031"
"7546","45.24000","3.77027","0.02071"
"7604","45.58800","3.79921","0.02073"
"7662","45.93600","3.82814","0.02130"
"7720","46.28400","3.85720","0.02175"
"7778","46.63200","3.88614","0.02166"
"7836","46.98000","3.91514","0.02174"
"7894","47.32800","3.94414","0.02232"
"7952","47.67600","3.97319","0.02255"
"8010","48.02400","4.00219","0.02313"
"8068","48.37200","4.03125","0.02341"
"8126","48.72000","4.06019","0.02296"
"8184","49.06800","4.08913","0.02329"
"8242","49.41600","4.11824","0.02395"
"8300","49.76400","4.14718","0.02340"
"8358","50.11200","4.17618","0.02389"
"8416","50.46000","4.20518","0.02454"
"8474","50.80800","4.23412","0.00441"
"8532","51.15600","4.26317","0.00966"
"8590","51.50400","4.29217","0.00991"
"8648","51.85200","4.32111","0.01022"
"8706","52.20000","4.35023","0.01027"
"8764","52.54800","4.37916","0.01047"
"8822","52.89600","4.40816","0.01094"
"8880","53.24400","4.43716","0.01066"
"8938","53.59200","4.46616","0.01160"
"8996","53.94000","4.49516","0.01260"
"9054","54.28800","4.52421","0.01336"
"9112","54.63600","4.55309","0.01287"
"9170","54.98400","4.58221","0.01385"
"9228","55.33200","4.61115","0.01417"
"9286","55.68000","4.64009","0.01417"
"9344","56.02800","4.66920","0.01428"
"9402","56.37600","4.69820","0.01519"
"9460","56.72400","4.72720","0.01559"
"9518","57.07200","4.75620","0.01584"
"9576","57.42000","4.78520","0.01579"
"9634","57.76800","4.81413","0.01675"
"9692","58.11600","4.84319","0.01709"
"9750","58.46400","4.87213","0.01685"
"9808","58.81200","4.90107","0.01720"
"9866","59.16000","4.93024","0.01762"
"9924","59.50800","4.95918","0.01753"
"9982","59.85600","4.98818","0.01815"
"10040","60.20400","5.01718","0.01836"
"10098","60.55200","5.04612","0.01824"
"10156","60.90000","5.07517","0.01858"
"10214","61.24800","5.10423","0.01930"
"10272","61.59600","5.13317","0.01928"
"10330","61.94400","5.16217","0.01987"
"10388","62.29200","5.19123","0.01946"
"10446","62.64000","5.22016","0.01979"
"10504","62.98800","5.24922","0.02038"
"10562","63.33600","5.27816","0.02071"
"10620","63.68400","5.30710","0.02087"
"10678","64.03200","5.33622","0.02066"
"10736","64.38000","5.36515","0.02078"
"10794","64.72800","5.39421","0.02095"
"10852","65.07600","5.42321","0.02125"
"10910","65.42400","5.45215","0.02154"
"10968","65.77200","5.48121","0.02196"
"11026","66.12000","5.51014","0.02223"
"11084","66.46800","5.53914","0.02219"
"11142","66.81600","5.56820","0.02232"
"11200","67.16400","5.59720","0.02275"
"11258","67.51200","5.62614","0.02325"
"11316","67.86000","5.65519","0.02327"
"11374","68.20800","5.68425","0.02324"
"11432","68.55600","5.71313","0.02381"
"11490","68.90400","5.74225","0.02443"
"11548","69.25200","5.77118","0.02354"
"11606","69.60000","5.80018","0.02427"
"11664","69.94800","5.82924","0.02468"
"11722","70.29600","5.85818","0.02485"
"11780","70.64400","5.88718","0.02500"
"11838","70.99200","5.91617","0.02548"
"11896","71.34000","5.94517","0.02592"
"11954","71.68800","5.97417","0.02540"
"12012","72.03600","6.00317","0.02576"
"12070","72.38400","6.03217","0.02636"
"12128","72.73200","6.06116","0.02633"
"12186","73.08000","6.09022","0.02692"
"12244","73.42800","6.11916","0.02752"
"12302","73.77600","6.14816","0.02742"
"12360","74.12400","6.17716","0.02775"
"12418","74.47200","6.20615","0.02780"
"12476","74.82000","6.23521","0.02821"
"12534","75.16800","6.26415","0.02853"
"12592","75.51600","6.29321","0.02850"
"12650","75.86400","6.32220","0.02933"
"12708","76.21200","6.35120","0.02945"
"12766","76.56000","6.38020","0.03017"
"12824","76.90800","6.40920","0.03036"
"12882","77.25600","6.43820","0.03081"
"12940","77.60400","6.46713","0.03024"
"12998","77.95200","6.49625","0.03019"
"13056","78.30000","6.52513","0.03087"
"13114","78.64800","6.55419","0.03125"
"13172","78.99600","6.58325","0.03200"
"13230","79.34400","6.61212","0.03140"
"13288","79.69200","6.64124","0.03179"
"13346","80.04000","6.67018","0.03215"
"13404","80.38800","6.69918","0.03226"
"13462","80.73600","6.72818","0.03242"
"13520","81.08400","6.75717","0.03180"
"13578","81.43200","6.78617","0.03307"
"13636","81.78000","6.81517","0.03234"
"13694","82.12800","6.84417","0.03320"
"13752","82.47600","6.87317","0.03212"
"13810","82.82400","6.90216","0.03258"
"13868","83.17200","6.93116","0.03322"
"13926","83.52000","6.96016","0.03326"
"13984","83.86800","6.98922","0.03283"
"14042","84.21600","7.01816","0.03348"
"14100","84.56400","7.04721","0.03484"
"14158","84.91200","7.07621","0.03514"
"14216","85.26000","7.10515","0.03472"
"14274","85.60800","7.13415","0.03525"
"14332","85.95600","7.16320","0.03588"
"14390","86.30400","7.19214","0.03591"
"14448","86.65200","7.22120","0.03625"
"14506","87.00000","7.25020","0.03671"
"14564","87.34800","7.27914","0.03688"
"14622","87.69600","7.30819","0.03757"
"14680","88.04400","7.33713","0.03627"
"14738","88.39200","7.36619","0.03582"
"14796","88.74000","7.39519","0.03660"
"14854","89.08800","7.42413","0.03717"
"14912","89.43600","7.45318","0.03856"
"14970","89.78400","7.48218","0.03867"
"15028","90.13200","7.51112","0.03907"
"15086","90.48000","7.54018","0.03875"
"15144","90.82800","7.56918","0.03386"
"15202","91.17600","7.59817","0.03462"
"15260","91.52400","7.62723","0.03547"
"15318","91.87200","7.65623","0.03618"
"15376","92.22000","7.68517","0.03760"
"15434","92.56800","7.71417","0.03762"
"15492","92.91600","7.74316","0.03834"
"15550","93.26400","7.77210","0.03815"
"15608","93.61200","7.80116","0.03884"
"15666","93.96000","7.83022","0.03967"
"15724","94.30800","7.85915","0.04055"
"15782","94.65600","7.88815","0.04118"
"15840","95.00400","7.91715","0.04182"
"15898","95.35200","7.94621","0.04174"
"15956","95.70000","7.97521","0.04214"
"16014","96.04800","8.00420","0.04268"
"16072","96.39600","8.03314","0.04315"
"16130","96.74400","8.06220","0.04379"
"16188","97.09200","8.09114","0.04442"
"16246","97.44000","8.12020","0.04400"
"16304","97.78800","8.14919","0.04445"
"16362","98.13600","8.17813","0.04543"
"16420","98.48400","8.20725","0.04523"
"16478","98.83200","8.23619","0.04605"
"16536","99.18000","8.26519","0.04591"
"16594","99.52800","8.29418","0.04709"
"16652","99.87600","8.32312","0.04766"
"16710","100.22400","8.35218","0.04831"
"16768","100.57200","8.38118","0.04940"
"16826","100.92000","8.41018","0.04936"
"16884","101.26800","8.43917","0.05031"
"16942","101.61600","8.46817","0.05063"
"17000","101.96400","8.49711","0.05073"
"17058","102.31200","8.52617","0.05158"
"17116","102.66000","8.55522","0.05260"
"17174","103.00800","8.58410","0.05287"
"17232","103.35600","8.61322","0.05379"
"17290","103.70400","8.64222","0.05442"
"17348","104.05200","8.67116","0.05467"
"17406","104.40000","8.70021","0.05562"
"17464","104.74800","8.72915","0.05498"
"17522","105.09600","8.75815","0.05535"
"17580","105.44400","8.78727","0.05650"
"17638","105.79200","8.81621","0.05628"
"17696","106.14000","8.84514","0.05684"
"17754","106.48800","8.87420","0.05627"
"17812","106.83600","8.90320","0.05707"
"17870","107.18400","8.93220","0.04565"
"17928","107.53200","8.96126","0.00599"
"17986","107.88000","8.99013","0.00745"
"18044","108.22800","9.01919","0.00858"
"18102","108.57600","9.04819","0.00843"
"18160","108.92400","9.07719","0.00911"
"18218","109.27200","9.10618","0.00843"
"18276","109.62000","9.13512","0.00966"
"18334","109.96800","9.16418","0.01009"
"18392","110.31600","9.19318","0.00935"
"18450","110.66400","9.22224","0.01054"
"18508","111.01200","9.25117","0.01069"
"18566","111.36000","9.28017","0.01013"
"18624","111.70800","9.30917","0.01107"
"18682","112.05600","9.33817","0.01133"
"18740","112.40400","9.36723","0.01094"
"18798","112.75200","9.39610","0.01170"
"18856","113.10000","9.42516","0.01193"
"18914","113.44800","9.45422","0.01211"
"18972","113.79600","9.48310","0.01287"
"19030","114.14400","9.51222","0.01228"
"19088","114.49200","9.54115","0.01210"
"19146","114.84000","9.57015","0.01292"
"19204","115.18800","9.59921","0.01223"
"19262","115.53600","9.62821","0.01265"
"19320","115.88400","9.65709","0.01359"
"19378","116.23200","9.68614","0.01337"
"19436","116.58000","9.71520","0.01307"
"19494","116.92800","9.74420","0.01361"
"19552","117.27600","9.77320","0.01334"
"19610","117.62400","9.80213","0.01395"
"19668","117.97200","9.83113","0.01423"
"19726","118.32000","9.86019","0.01358"
"19784","118.66800","9.88913","0.01416"
"19842","119.01600","9.91819","0.01410"
"19900","119.36400","9.94718","0.01385"
"19958","119.71200","9.97618","0.01357"
"20016","120.06000","10.00518","0.01429"
"20074","120.40800","10.03418","0.01396"
"20132","120.75600","10.06312","0.01374"
"20190","121.10400","10.09217","0.01430"
"20248","121.45200","10.12123","0.01412"
"20306","121.80000","10.15017","0.01473"
"20364","122.14800","10.17917","0.01455"
"20422","122.49600","10.20817","0.01403"
"20480","122.84400","10.23716","0.01473"
"20538","123.19200","10.26622","0.01476"
"20596","123.54000","10.29510","0.01488"
"20654","123.88800","10.32416","0.01487"
"20712","124.23600","10.35316","0.01497"
"20770","124.58400","10.38215","0.01530"
"20828","124.93200","10.41121","0.01523"
"20886","125.28000","10.44021","0.01440"
"20944","125.62800","10.46915","0.01493"
"21002","125.97600","10.49820","0.01513"
"21060","126.32400","10.52720","0.01582"
"21118","126.67200","10.55614","0.01524"
"21176","127.02000","10.58520","0.01557"
"21234","127.36800","10.61414","0.01578"
"21292","127.71600","10.64314","0.01534"
"21350","128.06400","10.67225","0.01480"
"21408","128.41200","10.70119","0.01483"
"21466","128.75999","10.73019","0.01512"
"21524","129.10800","10.75919","0.01504"
"21582","129.45599","10.78818","0.01521"
"21640","129.80400","10.81718","0.01541"
"21698","130.15199","10.84624","0.01535"
"21756","130.50000","10.87518","0.01528"
"21814","130.84801","10.90412","0.01558"
"21872","131.19600","10.93317","0.01621"
"21930","131.54401","10.96211","0.01616"
"21988","131.89200","10.99123","0.01586"
"22046","132.24001","11.02017","0.01591"
"22104","132.58800","11.04917","0.01577"
"22162","132.93600","11.07822","0.01541"
"22220","133.28400","11.10716","0.01577"
"22278","133.63200","11.13616","0.01611"
"22336","133.98000","11.16522","0.01632"
"22394","134.32800","11.19415","0.01624"
"22452","134.67599","11.22321","0.01652"
"22510","135.02400","11.25215","0.01644"
"22568","135.37199","11.28115","0.01581"
"22626","135.72000","11.31015","0.01566"
"22684","136.06799","11.33921","0.01653"
"22742","136.41600","11.36814","0.01618"
"22800","136.76401","11.39720","0.01651"
"22858","137.11200","11.42620","0.01653"
"22916","137.46001","11.45514","0.01711"
"22974","137.80800","11.48419","0.01694"
"23032","138.15601","11.51319","0.01731"
"23090","138.50400","11.54213","0.01738"
"23148","138.85201","11.57119","0.01732"
"23206","139.20000","11.60019","0.01672"
"23264","139.54800","11.62912","0.01732"
"23322","139.89600","11.65818","0.01722"
"23380","140.24400","11.68718","0.01764"
"23438","140.59200","11.71618","0.01757"
"23496","140.94000","11.74523","0.01758"
"23554","141.28799","11.77417","0.01737"
"23612","141.63600","11.80317","0.01706"
"23670","141.98399","11.83223","0.01752"
"23728","142.33200","11.86111","0.01779"
"23786","142.67999","11.89017","0.01746"
"23844","143.02800","11.91922","0.01774"
"23902","143.37601","11.94816","0.01806"
"23960","143.72400","11.97716","0.01780"
"24018","144.07201","12.00616","0.01822"
"24076","144.42000","12.03515","0.01830"
"24134","144.76801","12.06421","0.01835"
"24192","145.11600","12.09321","0.01934"
"24250","145.46400","12.12215","0.01877"
"24308","145.81200","12.15121","0.01860"
"24366","146.16000","12.18020","0.01883"
"24424","146.50800","12.20914","0.01883"
"24482","146.85600","12.23820","0.01905"
"24540","147.20399","12.26714","0.01845"
"24598","147.55200","12.29620","0.01903"
"24656","147.89999","12.32519","0.01898"
"24714","148.24800","12.35413","0.01964"
"24772","148.59599","12.38319","0.01938"
"24830","148.94400","12.41219","0.01977"
"24888","149.29201","12.44118","0.01966"
"24946","149.64000","12.47024","0.01891"
"25004","149.98801","12.49924","0.02041"
"25062","150.33600","12.52812","0.01964"
"25120","150.68401","12.55718","0.01984"
"25178","151.03200","12.58617","0.01989"
"25236","151.38000","12.61511","0.02016"
"25294","151.72800","12.64423","0.01870"
"25352","152.07600","12.67317","0.01937"
"25410","152.42400","12.70217","0.01926"
"25468","152.77200","12.73117","0.01970"
"25526","153.12000","12.76016","0.01972"
"25584","153.46800","12.78922","0.01952"
"25642","153.81599","12.81816","0.01970"
"25700","154.16400","12.84716","0.01947"
"25758","154.51199","12.87615","0.01976"
"25816","154.86000","12.90521","0.01988"
"25874","155.20799","12.93415","0.02011"
"25932","155.55600","12.96321","0.02012"
"25990","155.90401","12.99221","0.02030"
"26048","156.25200","13.02114","0.01985"
"26106","156.60001","13.05020","0.02018"
"26164","156.94800","13.07914","0.01941"
"26222","157.29601","13.10814","0.02006"
"26280","157.64400","13.13720","0.02015"
"26338","157.99200","13.16619","0.02022"
"26396","158.34000","13.19519","0.02009"
"26454","158.68800","13.22419","0.02042"
"26512","159.03600","13.25319","0.02010"
"26570","159.38400","13.28219","0.02048"
"26628","159.73199","13.31118","0.02040"
"26686","160.08000","13.34018","0.02014"
"26744","160.42799","13.36918","0.02066"
"26802","160.77600","13.39818","0.02038"
"26860","161.12399","13.42712","0.02112"
"26918","161.47200","13.45623","0.02135"
"26976","161.82001","13.48517","0.02121"
"27034","162.16800","13.51411","0.02083"
"27092","162.51601","13.54323","0.02147"
"27150","162.86400","13.57216","0.02155"
"27208","163.21201","13.60116","0.02176"
"27266","163.56000","13.63022","0.02122"
"27324","163.90800","13.65922","0.02132"
"27382","164.25600","13.68816","0.02177"
"27440","164.60400","13.71721","0.02098"
"27498","164.95200","13.74615","0.02172"
"27556","165.30000","13.77515","0.02171"
"27614","165.64799","13.80421","0.02173"
"27672","165.99600","13.83315","0.02205"
"27730","166.34399","13.86220","0.02194"
"27788","166.69200","13.89120","0.02188"
"27846","167.03999","13.92008","0.02213"
"27904","167.38800","13.94920","0.02258"
"27962","167.73599","13.97819","0.02270"
"28020","168.08400","14.00719","0.02322"
"28078","168.43201","14.03619","0.02305"
"28136","168.78000","14.06519","0.02281"
"28194","169.12801","14.09419","0.02169"
"28252","169.47600","14.12319","0.02217"
"28310","169.82401","14.15218","0.02181"
"28368","170.17200","14.18112","0.02282"
"28426","170.52000","14.21018","0.02274"
"28484","170.86800","14.23912","0.02284"
"28542","171.21600","14.26817","0.02323"
"28600","171.56400","14.29723","0.02325"
"28658","171.91200","14.32611","0.02364"
"28716","172.25999","14.35523","0.02346"
"28774","172.60800","14.38423","0.02393"
"28832","172.95599","14.41317","0.02309"
"28890","173.30400","14.44216","0.02366"
"28948","173.65199","14.47116","0.02377"
"29006","174.00000","14.50016","0.02378"
"29064","174.34801","14.52921","0.02464"
"29122","174.69600","14.55821","0.02397"
"29180","175.04401","14.58715","0.02386"
"29238","175.39200","14.61621","0.02394"
"29296","175.74001","14.64515","0.02450"
"29354","176.08800","14.67421","0.02425"
"29412","176.43600","14.70320","0.02415"
"29470","176.78400","14.73208","0.02473"
"29528","177.13200","14.76120","0.02497"
"29586","177.48000","14.79026","0.02528"
"29644","177.82800","14.81920","0.02538"
"29702","178.17599","14.84819","0.02547"
"29760","178.52400","14.87719","0.02581"
"29818","178.87199","14.90613","0.02609"
"29876","179.22000","14.93519","0.02608"
"29934","179.56799","14.96418","0.02537"
"29992","179.91600","14.99312","0.02566"
"30050","180.26401","15.02224","0.02560"
"30108","180.61200","15.05118","0.02568"
"30166","180.96001","15.08012","0.02603"
"30224","181.30800","15.10917","0.02610"
"30282","181.65601","15.13817","0.02617"
"30340","182.00400","15.16717","0.02617"
"30398","182.35201","15.19617","0.02623"
"30456","182.70000","15.22517","0.02639"
"30514","183.04800","15.25416","0.02596"
"30572","183.39600","15.28322","0.02614"
"30630","183.74400","15.31216","0.02560"
"30688","184.09200","15.34122","0.02705"
"30746","184.44000","15.37022","0.02690"
"30804","184.78799","15.39909","0.02730"
"30862","185.13600","15.42821","0.02741"
"30920","185.48399","15.45721","0.02801"
"30978","185.83200","15.48615","0.02833"
"31036","186.17999","15.51527","0.02846"
"31094","186.52800","15.54420","0.02660"
"31152","186.87601","15.57314","0.02745"
"31210","187.22400","15.60220","0.02770"
"31268","187.57201","15.63120","0.02737"
"31326","187.92000","15.66013","0.02781"
"31384","188.26801","15.68913","0.02771"
"31442","188.61600","15.71819","0.02807"
"31500","188.96400","15.74713","0.02872"
"31558","189.31200","15.77625","0.02873"
"31616","189.66000","15.80512","0.02928"
"31674","190.00800","15.83418","0.02938"
"31732","190.35600","15.86318","0.02887"
"31790","190.70399","15.89218","0.02922"
"31848","191.05200","15.92124","0.02970"
"31906","191.39999","15.95011","0.02966"
"31964","191.74800","15.97917","0.02370"
"32022","192.09599","16.00823","0.00993"
"32080","192.44400","16.03717","0.00624"
"32138","192.79201","16.06616","0.00738"
"32196","193.14000","16.09516","0.00661"
"32254","193.48801","16.12416","0.00924"
"32312","193.83600","16.15316","0.00707"
"32370","194.18401","16.18222","0.00894"
"32428","194.53200","16.21115","0.00800"
"32486","194.88000","16.24021","0.00915"
"32544","195.22800","16.26927","0.00902"
"32602","195.57600","16.29809","0.00952"
"32660","195.92400","16.32721","0.01074"
"32718","196.27200","16.35620","0.00942"
"32776","196.62000","16.38520","0.01104"
"32834","196.96800","16.41420","0.01000"
"32892","197.31599","16.44320","0.01040"
"32950","197.66400","16.47214","0.01111"
"33008","198.01199","16.50119","0.01130"
"33066","198.36000","16.53019","0.01224"
"33124","198.70799","16.55919","0.01108"
"33182","199.05600","16.58825","0.01202"
"33240","199.40401","16.61712","0.01206"
"33298","199.75200","16.64618","0.01230"
"33356","200.10001","16.67518","0.01350"
"33414","200.44800","16.70412","0.01267"
"33472","200.79601","16.73324","0.01282"
"33530","201.14400","16.76217","0.01285"
"33588","201.49200","16.79117","0.01328"
"33646","201.84000","16.82023","0.01349"
"33704","202.18800","16.84917","0.01345"
"33762","202.53600","16.87817","0.01394"
"33820","202.88400","16.90717","0.01432"
"33878","203.23199","16.93616","0.01436"
"33936","203.58000","16.96516","0.01457"
"33994","203.92799","16.99416","0.01454"
"34052","204.27600","17.02316","0.01483"
"34110","204.62399","17.05215","0.01530"
"34168","204.97200","17.08121","0.01583"
"34226","205.32001","17.11015","0.01542"
"34284","205.66800","17.13921","0.01577"
"34342","206.01601","17.16821","0.01641"
"34400","206.36400","17.19714","0.01590"
"34458","206.71201","17.22620","0.01578"
"34516","207.06000","17.25520","0.01613"
"34574","207.40800","17.28414","0.01599"
"34632","207.75600","17.31320","0.01600"
"34690","208.10400","17.34219","0.01677"
"34748","208.45200","17.37107","0.01704"
"34806","208.80000","17.40025","0.01695"
"34864","209.14799","17.42919","0.01655"
"34922","209.49600","17.45819","0.01738"
"34980","209.84399","17.48718","0.01731"
"35038","210.19200","17.51618","0.01755"
"35096","210.53999","17.54518","0.01746"
"35154","210.88800","17.57418","0.01788"
"35212","211.23599","17.60317","0.01817"
"35270","211.58400","17.63217","0.01768"
"35328","211.93201","17.66111","0.01825"
"35386","212.28000","17.69017","0.01847"
"35444","212.62801","17.71917","0.01869"
"35502","212.97600","17.74822","0.01888"
"35560","213.32401","17.77716","0.01926"
"35618","213.67200","17.80616","0.01885"
"35676","214.02000","17.83522","0.01974"
"35734","214.36800","17.86410","0.01956"
"35792","214.71600","17.89321","0.01972"
"35850","215.06400","17.92215","0.02002"
"35908","215.41200","17.95115","0.02034"
"35966","215.75999","17.98021","0.02111"
"36024","216.10800","18.00915","0.02052"
"36082","216.45599","18.03820","0.02068"
"36140","216.80400","18.06720","0.02102"
"36198","217.15199","18.09620","0.02122"
"36256","217.50000","18.12520","0.02149"
"36314","217.84801","18.15419","0.02147"
"36372","218.19600","18.18313","0.02193"
"36430","218.54401","18.21219","0.02049"
"36488","218.89200","18.24119","0.02094"
"36546","219.24001","18.27013","0.02109"
"36604","219.58800","18.29918","0.02106"
"36662","219.93600","18.32818","0.02120"
"36720","220.28400","18.35718","0.02190"
"36778","220.63200","18.38618","0.02144"
"36836","220.98000","18.41517","0.02169"
"36894","221.32800","18.44418","0.02218"
"36952","221.67599","18.47323","0.02198"
"37010","222.02400","18.50223","0.02224"
"37068","222.37199","18.53111","0.02285"
"37126","222.72000","18.56017","0.02266"
"37184","223.06799","18.58916","0.02226"
"37242","223.41600","18.61816","0.02296"
"37300","223.76401","18.64722","0.02333"
"37358","224.11200","18.67610","0.02338"
"37416","224.46001","18.70522","0.02265"
"37474","224.80800","18.73421","0.02285"
"37532","225.15601","18.76315","0.02336"
"37590","225.50400","18.79221","0.02373"
"37648","225.85201","18.82115","0.02363"
"37706","226.20000","18.85015","0.02352"
"37764","226.54800","18.87926","0.02391"
"37822","226.89600","18.90820","0.02312"
"37880","227.24400","18.93720","0.02348"
"37938","227.59200","18.96620","0.02349"
"37996","227.94000","18.99513","0.02381"
"38054","228.28799","19.02419","0.02379"
"38112","228.63600","19.05325","0.02418"
"38170","228.98399","19.08213","0.02182"
"38228","229.33200","19.11119","0.02150"
"38286","229.67999","19.14024","0.02180"
"38344","230.02800","19.16912","0.02265"
"38402","230.37601","19.19818","0.02252"
"38460","230.72400","19.22724","0.02247"
"38518","231.07201","19.25612","0.02238"
"38576","231.42000","19.28523","0.02201"
"38634","231.76801","19.31423","0.02223"
"38692","232.11600","19.34311","0.02270"
"38750","232.46400","19.37217","0.02246"
"38808","232.81200","19.40123","0.02257"
"38866","233.16000","19.43016","0.02240"
"38924","233.50800","19.45922","0.02241"
"38982","233.85600","19.48822","0.02309"
"39040","234.20399","19.51716","0.02305"
"39098","234.55200","19.54622","0.02313"
"39156","234.89999","19.57521","0.02208"
"39214","235.24800","19.60421","0.02228"
"39272","235.59599","19.63315","0.02370"
"39330","235.94400","19.66215","0.02308"
"39388","236.29201","19.69114","0.02347"
"39446","236.64000","19.72026","0.02361"
"39504","236.98801","19.74914","0.02378"
"39562","237.33600","19.77814","0.02369"
"39620","237.68401","19.80720","0.02318"
"39678","238.03200","19.83619","0.02224"
"39736","238.38000","19.86519","0.02205"
"39794","238.72800","19.89413","0.02265"
"39852","239.07600","19.92313","0.02266"
"39910","239.42400","19.95218","0.02227"
"39968","239.77200","19.98118","0.02275"
"40026","240.12000","20.01024","0.02284"
"40084","240.46800","20.03918","0.02296"
"40142","240.81599","20.06818","0.02308"
"40200","241.16400","20.09718","0.02325"
"40258","241.51199","20.12623","0.02336"
"40316","241.86000","20.15511","0.02356"
"40374","242.20799","20.18417","0.02415"
"40432","242.55600","20.21317","0.02363"
"40490","242.90401","20.24211","0.02391"
"40548","243.25200","20.27122","0.02448"
"40606","243.60001","20.30016","0.02417"
"40664","243.94800","20.32916","0.02415"
"40722","244.29601","20.35822","0.02408"
"40780","244.64400","20.38715","0.02407"
"40838","244.99200","20.41615","0.02391"
"40896","245.34000","20.44515","0.02442"
"40954","245.68800","20.47415","0.02414"
"41012","246.03600","20.50321","0.02417"
"41070","246.38400","20.53220","0.02387"
"41128","246.73199","20.56114","0.02407"
"41186","247.08000","20.59014","0.02397"
"41244","247.42799","20.61920","0.02389"
"41302","247.77600","20.64820","0.02465"
"41360","248.12399","20.67719","0.02441"
"41418","248.47200","20.70619","0.02487"
"41476","248.82001","20.73513","0.02527"
"41534","249.16800","20.76419","0.02503"
"41592","249.51601","20.79318","0.02410"
"41650","249.86400","20.82218","0.02430"
"41708","250.21201","20.85118","0.02459"
"41766","250.56000","20.88018","0.02552"
"41824","250.90800","20.90918","0.02524"
"41882","251.25600","20.93823","0.02583"
"41940","251.60400","20.96717","0.02544"
"41998","251.95200","20.99617","0.02578"
"42056","252.30000","21.02523","0.02589"
"42114","252.64799","21.05417","0.02574"
"42172","252.99600","21.08316","0.02549"
"42230","253.34399","21.11216","0.02563"
"42288","253.69200","21.14110","0.02595"
"42346","254.03999","21.17022","0.02558"
"42404","254.38800","21.19916","0.02344"
"42462","254.73599","21.22816","0.02405"
"42520","255.08400","21.25727","0.02368"
"42578","255.43201","21.28615","0.02436"
"42636","255.78000","21.31515","0.02455"
"42694","256.12799","21.34414","0.02487"
"42752","256.47601","21.37320","0.02490"
"42810","256.82401","21.40214","0.02504"
"42868","257.17200","21.43120","0.02522"
"42926","257.51999","21.46020","0.02524"
"42984","257.86801","21.48913","0.02539"
"43042","258.21600","21.51819","0.02643"
"43100","258.56400","21.54713","0.02574"
"43158","258.91199","21.57619","0.02622"
"43216","259.26001","21.60525","0.02602"
"43274","259.60800","21.63412","0.02549"
"43332","259.95599","21.66318","0.02626"
"43390","260.30399","21.69218","0.02576"
"43448","260.65201","21.72112","0.02700"
"43506","261.00000","21.75017","0.02670"
"43564","261.34799","21.77918","0.02719"
"43622","261.69601","21.80817","0.02693"
"43680","262.04401","21.83717","0.02747"
"43738","262.39200","21.86617","0.02746"
"43796","262.73999","21.89517","0.02756"
"43854","263.08801","21.92416","0.02790"
"43912","263.43600","21.95316","0.02812"
"43970","263.78400","21.98222","0.02756"
"44028","264.13199","22.01122","0.02825"
"44086","264.48001","22.04016","0.02899"
"44144","264.82800","22.06915","0.02859"
"44202","265.17599","22.09815","0.02917"
"44260","265.52399","22.12715","0.02910"
"44318","265.87201","22.15615","0.02879"
"44376","266.22000","22.18521","0.02876"
"44434","266.56799","22.21414","0.02833"
"44492","266.91599","22.24320","0.02850"
"44550","267.26401","22.27220","0.02890"
"44608","267.61200","22.30114","0.02930"
"44666","267.95999","22.33019","0.02948"
"44724","268.30801","22.35913","0.02937"
"44782","268.65601","22.38813","0.02916"
"44840","269.00400","22.41719","0.03009"
"44898","269.35199","22.44613","0.03005"
"44956","269.70001","22.47518","0.02997"
"45014","270.04800","22.50418","0.02456"
"45072","270.39600","22.53318","0.02477"
"45130","270.74399","22.56224","0.02510"
"45188","271.09201","22.59124","0.02558"
"45246","271.44000","22.62017","0.02574"
"45304","271.78799","22.64917","0.02683"
"45362","272.13599","22.67817","0.02652"
"45420","272.48401","22.70717","0.02719"
"45478","272.83200","22.73623","0.02744"
"45536","273.17999","22.76517","0.02784"
"45594","273.52802","22.79416","0.02792"
"45652","273.87601","22.82316","0.02866"
"45710","274.22400","22.85216","0.02837"
"45768","274.57199","22.88115","0.02890"
"45826","274.92001","22.91015","0.02877"
"45884","275.26801","22.93915","0.02959"
"45942","275.61600","22.96815","0.03005"
"46000","275.96399","22.99721","0.02985"
"46058","276.31201","23.02615","0.02967"
"46116","276.66000","23.05514","0.02915"
"46174","277.00800","23.08420","0.02965"
"46232","277.35599","23.11314","0.02994"
"46290","277.70401","23.14226","0.02953"
"46348","278.05200","23.17120","0.02990"
"46406","278.39999","23.20013","0.03009"
"46464","278.74799","23.22925","0.03005"
"46522","279.09601","23.25819","0.03003"
"46580","279.44400","23.28713","0.03027"
"46638","279.79199","23.31618","0.02968"
"46696","280.14001","23.34518","0.02966"
"46754","280.48801","23.37412","0.02844"
"46812","280.83600","23.40324","0.02925"
"46870","281.18399","23.43218","0.02917"
"46928","281.53201","23.46111","0.02858"
"46986","281.88000","23.49023","0.02857"
"47044","282.22800","23.51911","0.02854"
"47102","282.57599","23.54823","0.02869"
"47160","282.92401","23.57722","0.02953"
"47218","283.27200","23.60610","0.02965"
"47276","283.62000","23.63516","0.02907"
"47334","283.96799","23.66422","0.02933"
"47392","284.31601","23.69322","0.02892"
"47450","284.66400","23.72221","0.02916"
"47508","285.01199","23.75121","0.02881"
"47566","285.35999","23.78015","0.02926"
"47624","285.70801","23.80921","0.02919"
"47682","286.05600","23.83815","0.02990"
"47740","286.40399","23.86714","0.02974"
"47798","286.75201","23.89626","0.03015"
"47856","287.10001","23.92514","0.03007"
"47914","287.44800","23.95420","0.03026"
"47972","287.79599","23.98320","0.03011"
"48030","288.14401","24.01208","0.03032"
"48088","288.49200","24.04125","0.03007"
"48146","288.84000","24.07019","0.02951"
"48204","289.18799","24.09919","0.03067"
"48262","289.53601","24.12819","0.03113"
"48320","289.88400","24.15718","0.03133"
"48378","290.23199","24.18612","0.03104"
"48436","290.57999","24.21518","0.03112"
"48494","290.92801","24.24418","0.03174"
"48552","291.27600","24.27317","0.03258"
"48610","291.62399","24.30217","0.03170"
"48668","291.97198","24.33117","0.03175"
"48726","292.32001","24.36017","0.03234"
"48784","292.66800","24.38917","0.03167"
"48842","293.01599","24.41810","0.03164"
"48900","293.36401","24.44722","0.03187"
"48958","293.71201","24.47622","0.03261"
"49016","294.06000","24.50516","0.03233"
"49074","294.40799","24.53416","0.03230"
"49132","294.75601","24.56316","0.03334"
"49190","295.10400","24.59215","0.03283"
"49248","295.45200","24.62121","0.03338"
"49306","295.79999","24.65015","0.03380"
"49364","296.14801","24.67909","0.03311"
"49422","296.49600","24.70820","0.03334"
"49480","296.84399","24.73714","0.03341"
"49538","297.19199","24.76620","0.03407"
"49596","297.54001","24.79520","0.03397"
"49654","297.88800","24.82413","0.03369"
"49712","298.23599","24.85319","0.03377"
"49770","298.58401","24.88219","0.03335"
"49828","298.93201","24.91119","0.03357"
"49886","299.28000","24.94013","0.03264"
"49944","299.62799","24.96919","0.03314"
"50002","299.97601","24.99812","0.03275"
"50060","300.32401","25.02718","0.03348"
"50118","300.67200","25.05624","0.03354"
"50176","301.01999","25.08512","0.03406"
"50234","301.36801","25.11423","0.03429"
"50292","301.71600","25.14323","0.03434"
"50350","302.06400","25.17211","0.03434"
"50408","302.41199","25.20117","0.03424"
"50466","302.76001","25.23017","0.03471"
"50524","303.10800","25.25911","0.03472"
"50582","303.45599","25.28822","0.03526"
"50640","303.80399","25.31722","0.03498"
"50698","304.15201","25.34616","0.03194"
"50756","304.50000","25.37516","0.03353"
"50814","304.84799","25.40415","0.03302"
"50872","305.19601","25.43315","0.03331"
"50930","305.54401","25.46227","0.03344"
"50988","305.89200","25.49115","0.03315"
"51046","306.23999","25.52021","0.03293"
"51104","306.58801","25.54921","0.03339"
"51162","306.93600","25.57820","0.03387"
"51220","307.28400","25.60720","0.03395"
"51278","307.63199","25.63614","0.03451"
"51336","307.98001","25.66519","0.03477"
"51394","308.32800","25.69425","0.03485"
"51452","308.67599","25.72319","0.03507"
"51510","309.02399","25.75219","0.03507"
"51568","309.37201","25.78113","0.03535"
"51626","309.72000","25.81025","0.03579"
"51684","310.06799","25.83918","0.03541"
"51742","310.41599","25.86824","0.03517"
"51800","310.76401","25.89712","0.03550"
"51858","311.11200","25.92618","0.03595"
"51916","311.45999","25.95523","0.03682"
"51974","311.80801","25.98411","0.03656"
"52032","312.15601","26.01323","0.03689"
"52090","312.50400","26.04223","0.03582"
"52148","312.85199","26.07117","0.03186"
"52206","313.20001","26.10022","0.03191"
"52264","313.54800","26.12916","0.03269"
"52322","313.89600","26.15816","0.03345"
"52380","314.24399","26.18722","0.03347"
"52438","314.59201","26.21615","0.03347"
"52496","314.94000","26.24521","0.03346"
"52554","315.28799","26.27421","0.03058"
"52612","315.63599","26.30315","0.02906"
"52670","315.98401","26.33215","0.02860"
"52728","316.33200","26.36121","0.02959"
"52786","316.67999","26.39014","0.03039"
"52844","317.02802","26.41920","0.03111"
"52902","317.37601","26.44814","0.03182"
"52960","317.72400","26.47714","0.03166"
"53018","318.07199","26.50614","0.03171"
"53076","318.42001","26.53519","0.03252"
"53134","318.76801","26.56413","0.03279"
"53192","319.11600","26.59319","0.03263"
"53250","319.46399","26.62219","0.03376"
"53308","319.81201","26.65118","0.03364"
"53366","320.16000","26.68018","0.03411"
"53424","320.50800","26.70918","0.03462"
"53482","320.85599","26.73812","0.03492"
"53540","321.20401","26.76723","0.03546"
"53598","321.55200","26.79617","0.03546"
"53656","321.89999","26.82523","0.03564"
"53714","322.24799","26.85411","0.03617"
"53772","322.59601","26.88311","0.03625"
"53830","322.94400","26.91223","0.03669"
"53888","323.29199","26.94117","0.03796"
"53946","323.64001","26.97010","0.03778"
"54004","323.98801","26.99922","0.03834"
"54062","324.33600","27.02822","0.03927"
"54120","324.68399","27.05716","0.03903"
"54178","325.03201","27.08621","0.03981"
"54236","325.38000","27.11521","0.04022"
"54294","325.72800","27.14409","0.04099"
"54352","326.07599","27.17321","0.04079"
"54410","326.42401","27.20214","0.04078"
"54468","326.77200","27.23114","0.04222"
"54526","327.12000","27.26020","0.04243"
"54584","327.46799","27.28914","0.04245"
"54642","327.81601","27.31820","0.04132"
"54700","328.16400","27.34720","0.03848"
"54758","328.51199","27.37619","0.03870"
"54816","328.85999","27.40519","0.03916"
"54874","329.20801","27.43419","0.03971"
"54932","329.55600","27.46313","0.03986"
"54990","329.90399","27.49219","0.04100"
"55048","330.25201","27.52118","0.04110"
"55106","330.60001","27.55012","0.04127"
"55164","330.94800","27.57918","0.04143"
"55222","331.29599","27.60818","0.04139"
"55280","331.64401","27.63717","0.04149"
"55338","331.99200","27.66617","0.04210"
"55396","332.34000","27.69517","0.04085"
"55454","332.68799","27.72417","0.04100"
"55512","333.03601","27.75317","0.04046"
"55570","333.38400","27.78222","0.04074"
"55628","333.73199","27.81116","0.04136"
"55686","334.07999","27.84022","0.04098"
"55744","334.42801","27.86910","0.03513"
"55802","334.77600","27.89821","0.03579"
"55860","335.12399","27.92721","0.03747"
"55918","335.47198","27.95615","0.03777"
"55976","335.82001","27.98521","0.03596"
"56034","336.16800","28.01421","0.03749"
"56092","336.51599","28.04315","0.03858"
"56150","336.86401","28.07220","0.03908"
"56208","337.21201","28.10114","0.03989"
"56266","337.56000","28.13014","0.03968"
"56324","337.90799","28.15920","0.03948"
"56382","338.25601","28.18819","0.03991"
"56440","338.60400","28.21713","0.03956"
"56498","338.95200","28.24619","0.04020"
"56556","339.29999","28.27513","0.04008"
"56614","339.64801","28.30413","0.04047"
"56672","339.99600","28.33324","0.03997"
"56730","340.34399","28.36212","0.03925"
"56788","340.69199","28.39118","0.04011"
"56846","341.04001","28.42018","0.04068"
"56904","341.38800","28.44911","0.04097"
"56962","341.73599","28.47818","0.04101"
"57020","342.08401","28.50717","0.04240"
"57078","342.43201","28.53617","0.04228"
"57136","342.78000","28.56517","0.04230"
"57194","343.12799","28.59422","0.04209"
"57252","343.47601","28.62316","0.04211"
"57310","343.82401","28.65216","0.04310"
"57368","344.17200","28.68116","0.04391"
"57426","344.51999","28.71022","0.04465"
"57484","344.86801","28.73922","0.04503"
"57542","345.21600","28.76809","0.04578"
"57600","345.56400","28.79721","0.04582"
"57658","345.91199","28.82621","0.04665"
"57716","346.26001","28.85509","0.04729"
"57774","346.60800","28.88421","0.04809"
"57832","346.95599","28.91320","0.04781"
"57890","347.30399","28.94220","0.04661"
"57948","347.65201","28.97120","0.04504"
"58006","348.00000","29.00014","0.04502"
"58064","348.34799","29.02913","0.04495"
"58122","348.69601","29.05819","0.04421"
"58180","349.04401","29.08719","0.04027"
"58238","349.39200","29.11613","0.04108"
"58296","349.73999","29.14525","0.04258"
"58354","350.08801","29.17413","0.04302"
"58412","350.43600","29.20312","0.03884"
"58470","350.78400","29.23218","0.03550"
"58528","351.13199","29.26118","0.03485"
"58586","351.48001","29.29018","0.03642"
"58644","351.82800","29.31923","0.03637"
"58702","352.17599","29.34811","0.03666"
"58760","352.52399","29.37717","0.03790"
"58818","352.87201","29.40623","0.03865"
"58876","353.22000","29.43517","0.03898"
"58934","353.56799","29.46416","0.03919"
"58992","353.91599","29.49322","0.04066"
"59050","354.26401","29.52216","0.04079"
"59108","354.61200","29.55122","0.04129"
"59166","354.95999","29.58016","0.04200"
"59224","355.30801","29.60915","0.04211"
"59282","355.65601","29.63815","0.04205"
"59340","356.00400","29.66715","0.04110"
"59398","356.35199","29.69621","0.03947"
"59456","356.70001","29.72514","0.03995"
"59514","357.04800","29.75414","0.03986"
"59572","357.39600","29.78320","0.04065"
"59630","357.74399","29.81220","0.04103"
"59688","358.09201","29.84120","0.04217"
"59746","358.44000","29.87020","0.04272"
"59804","358.78799","29.89925","0.04317"
"59862","359.13599","29.92813","0.04341"
"59920","359.48401","29.95719","0.04392"
"59978","359.83200","29.98618","0.04383"
"60036","360.17999","30.01512","0.04535"
"60094","360.52802","30.04424","0.04607"
"60152","360.87601","30.07318","0.04645"
"60210","361.22400","30.10218","0.04554"
"60268","361.57199","30.13117","0.04645"
"60326","361.92001","30.16017","0.04757"
"60384","362.26801","30.18917","0.04841"
"60442","362.61600","30.21817","0.04857"
"60500","362.96399","30.24717","0.04070"
"60558","363.31201","30.27617","0.04045"
"60616","363.66000","30.30522","0.03628"
"60674","364.00800","30.33416","0.03763"
"60732","364.35599","30.36322","0.03747"
"60790","364.70401","30.39221","0.03798"
"60848","365.05200","30.42115","0.03816"
"60906","365.39999","30.45015","0.03917"
"60964","365.74799","30.47921","0.04050"
"61022","366.09601","30.50815","0.04172"
"61080","366.44400","30.53721","0.04320"
"61138","366.79199","30.56614","0.04336"
"61196","367.14001","30.59520","0.03972"
"61254","367.48801","30.62420","0.04025"
"61312","367.83600","30.65314","0.04117"
"61370","368.18399","30.68208","0.04230"
"61428","368.53201","30.71119","0.04263"
"61486","368.88000","30.74019","0.04306"
"61544","369.22800","30.76919","0.03082"
"61602","369.57599","30.79825","0.02706"
"61660","369.92401","30.82712","0.02800"
"61718","370.27200","30.85625","0.02946"
"61776","370.62000","30.88518","0.03017"
"61834","370.96799","30.91412","0.03168"
"61892","371.31601","30.94318","0.03035"
"61950","371.66400","30.97218","0.02554"
"62008","372.01199","31.00111","0.02630"
"62066","372.35999","31.03023","0.02702"
"62124","372.70801","31.05917","0.02706"
"62182","373.05600","31.08817","0.02670"
"62240","373.40399","31.11722","0.02650"
"62298","373.75201","31.14616","0.02660"
"62356","374.10001","31.17516","0.02712"
"62414","374.44800","31.20422","0.02733"
"62472","374.79599","31.23310","0.02880"
"62530","375.14401","31.26221","0.02700"
"62588","375.49200","31.29121","0.02690"
"62646","375.84000","31.32015","0.02774"
"62704","376.18799","31.34914","0.02780"
"62762","376.53601","31.37820","0.02767"
"62820","376.88400","31.40714","0.02859"
"62878","377.23199","31.43620","0.02733"
"62936","377.57999","31.46526","0.02764"
"62994","377.92801","31.49414","0.02816"
"63052","378.27600","31.52319","0.02763"
"63110","378.62399","31.55219","0.02812"
"63168","378.97198","31.58119","0.02876"
"63226","379.32001","31.61019","0.02913"
"63284","379.66800","31.63913","0.02896"
"63342","380.01599","31.66824","0.02867"
"63400","380.36401","31.69718","0.02903"
"63458","380.71201","31.72612","0.02933"
"63516","381.06000","31.75517","0.02906"
"63574","381.40799","31.78417","0.02896"
"63632","381.75601","31.81318","0.02732"
"63690","382.10400","31.84217","0.02749"
"63748","382.45200","31.87123","0.02757"
"63806","382.79999","31.90011","0.02678"
"63864","383.14801","31.92916","0.02736"
"63922","383.49600","31.95816","0.02829"
"63980","383.84399","31.98716","0.02810"
"64038","384.19199","32.01622","0.02830"
"64096","384.54001","32.04515","0.02880"
"64154","384.88800","32.07415","0.02912"
"64212","385.23599","32.10315","0.02954"
"64270","385.58401","32.13215","0.02889"
"64328","385.93201","32.16121","0.02871"
"64386","386.28000","32.19014","0.02926"
"64444","386.62799","32.21920","0.02884"
"64502","386.97601","32.24814","0.02782"
"64560","387.32401","32.27720","0.02894"
"64618","387.67200","32.30608","0.02963"
"64676","388.01999","32.33520","0.02956"
"64734","388.36801","32.36419","0.02994"
"64792","388.71600","32.39319","0.03006"
"64850","389.06400","32.42225","0.03052"
"64908","389.41199","32.45113","0.03030"
"64966","389.76001","32.48013","0.03004"
"65024","390.10800","32.50918","0.02998"
"65082","390.45599","32.53812","0.03046"
"65140","390.80399","32.56718","0.02988"
"65198","391.15201","32.59618","0.03037"
"65256","391.50000","32.62518","0.03065"
"65314","391.84799","32.65417","0.03090"
"65372","392.19601","32.68317","0.03152"
"65430","392.54401","32.71217","0.03133"
"65488","392.89200","32.74117","0.03218"
"65546","393.23999","32.77023","0.03145"
"65604","393.58801","32.79916","0.03202"
"65662","393.93600","32.82822","0.03213"
"65720","394.28400","32.85722","0.03141"
"65778","394.63199","32.88615","0.03097"
"65836","394.98001","32.91515","0.03109"
"65894","395.32800","32.94415","0.03134"
"65952","395.67599","32.97309","0.03234"
"66010","396.02399","33.00221","0.03135"
"66068","396.37201","33.03121","0.03166"
"66126","396.72000","33.06015","0.03155"
"66184","397.06799","33.08920","0.03082"
"66242","397.41599","33.11814","0.03125"
"66300","397.76401","33.14708","0.03150"
"66358","398.11200","33.17625","0.03119"
"66416","398.45999","33.20507","0.03132"
"66474","398.80801","33.23425","0.03229"
"66532","399.15601","33.26325","0.03253"
"66590","399.50400","33.29213","0.03293"
"66648","399.85199","33.32118","0.03314"
"66706","400.20001","33.35018","0.03352"
"66764","400.54800","33.37918","0.03308"
"66822","400.89600","33.40818","0.03270"
"66880","401.24399","33.43718","0.03263"
"66938","401.59201","33.46618","0.03256"
"66996","401.94000","33.49517","0.03338"
"67054","402.28799","33.52417","0.03275"
"67112","402.63599","33.55311","0.03263"
"67170","402.98401","33.58223","0.03187"
"67228","403.33200","33.61116","0.03172"
"67286","403.67999","33.64022","0.03145"
"67344","404.02802","33.66922","0.03077"
"67402","404.37601","33.69810","0.03106"
"67460","404.72400","33.72721","0.03157"
"67518","405.07199","33.75621","0.03058"
"67576","405.42001","33.78515","0.03078"
"67634","405.76801","33.81421","0.03038"
"67692","406.11600","33.84315","0.03045"
"67750","406.46399","33.87215","0.03125"
"67808","406.81201","33.90120","0.03136"
"67866","407.16000","33.93014","0.03178"
"67924","407.50800","33.95914","0.03130"
"67982","407.85599","33.98820","0.03147"
"68040","408.20401","34.01714","0.03104"
"68098","408.55200","34.04619","0.03128"
"68156","408.89999","34.07519","0.03067"
"68214","409.24799","34.10413","0.03144"
"68272","409.59601","34.13319","0.03065"
"68330","409.94400","34.16219","0.03089"
"68388","410.29199","34.19118","0.03058"
"68446","410.64001","34.22012","0.03065"
"68504","410.98801","34.24918","0.03068"
"68562","411.33600","34.27812","0.03143"
"68620","411.68399","34.30724","0.03149"
"68678","412.03201","34.33623","0.03072"
"68736","412.38000","34.36511","0.03108"
"68794","412.72800","34.39417","0.03150"
"68852","413.07599","34.42316","0.03178"
"68910","413.42401","34.45216","0.03105"
"68968","413.77200","34.48122","0.03115"
"69026","414.12000","34.51016","0.03143"
"69084","414.46799","34.53922","0.03059"
"69142","414.81601","34.56816","0.02946"
"69200","415.16400","34.59716","0.02966"
"69258","415.51199","34.62621","0.03001"
"69316","415.85999","34.65521","0.02912"
"69374","416.20801","34.68415","0.02845"
"69432","416.55600","34.71320","0.02863"
"69490","416.90399","34.74220","0.02945"
"69548","417.25201","34.77114","0.02977"
"69606","417.60001","34.80020","0.03049"
"69664","417.94800","34.82925","0.03162"
"69722","418.29599","34.85814","0.03033"
"69780","418.64401","34.88719","0.03014"
"69838","418.99200","34.91613","0.03049"
"69896","419.34000","34.94513","0.03102"
"69954","419.68799","34.97419","0.03104"
"70012","420.03601","35.00319","0.03129"
"70070","420.38400","35.03218","0.03152"
"70128","420.73199","35.06118","0.03028"
"70186","421.07999","35.09018","0.03130"
"70244","421.42801","35.11917","0.03088"
"70302","421.77600","35.14823","0.03154"
"70360","422.12399","35.17711","0.03204"
"70418","422.47198","35.20623","0.03138"
"70476","422.82001","35.23523","0.03153"
"70534","423.16800","35.26416","0.02566"
"70592","423.51599","35.29322","0.02629"
"70650","423.86401","35.32216","0.02511"
"70708","424.21201","35.35116","0.02487"
"70724","424.30600","35.35899","0.02542"