File: Trajectories_together/170121_3Specimen_RawData_3.csv
"","V1","V2","V3"
"1","End date","1/21/2017",""
"2","Specimen label","13CT_5",""
"3","Maximum Load","0.06552","N"
"4","Time","Extension","Load"
"5","(s)","(mm)","(N)"
"6","0.00000","0.00000","-0.00001"
"44","0.22800","0.01728","0.00133"
"82","0.45600","0.03838","0.00323"
"120","0.68400","0.05722","0.00266"
"158","0.91200","0.07629","0.00370"
"196","1.14000","0.09518","0.00418"
"234","1.36800","0.11426","0.00424"
"272","1.59600","0.13321","0.00439"
"310","1.82400","0.15222","0.00454"
"348","2.05200","0.17124","0.00420"
"386","2.28000","0.19019","0.00427"
"424","2.50800","0.20920","0.00469"
"462","2.73600","0.22816","0.00442"
"500","2.96400","0.24729","0.00470"
"538","3.19200","0.26624","0.00476"
"576","3.42000","0.28520","0.00505"
"614","3.64800","0.30427","0.00414"
"652","3.87600","0.32316","0.00465"
"690","4.10400","0.34224","0.00478"
"728","4.33200","0.36119","0.00455"
"766","4.56000","0.38020","0.00458"
"804","4.78800","0.39921","0.00453"
"842","5.01600","0.41817","0.00533"
"880","5.24400","0.43724","0.00537"
"918","5.47200","0.45619","0.00506"
"956","5.70000","0.47527","0.00541"
"994","5.92800","0.49422","0.00485"
"1032","6.15600","0.51323","0.00498"
"1070","6.38400","0.53225","0.00476"
"1108","6.61200","0.55120","0.00445"
"1146","6.84000","0.57021","0.00401"
"1184","7.06800","0.58923","0.00455"
"1222","7.29600","0.60818","0.00426"
"1260","7.52400","0.62719","0.00474"
"1298","7.75200","0.64621","0.00438"
"1336","7.98000","0.66522","0.00459"
"1374","8.20800","0.68423","0.00441"
"1412","8.43600","0.70324","0.00458"
"1450","8.66400","0.72220","0.00460"
"1488","8.89200","0.74121","0.00477"
"1526","9.12000","0.76022","0.00468"
"1564","9.34800","0.77924","0.00424"
"1602","9.57600","0.79825","0.00457"
"1640","9.80400","0.81720","0.00407"
"1678","10.03200","0.83628","0.00441"
"1716","10.26000","0.85517","0.00487"
"1754","10.48800","0.87424","0.00388"
"1792","10.71600","0.89320","0.00495"
"1830","10.94400","0.91227","0.00468"
"1868","11.17200","0.93128","0.00498"
"1906","11.40000","0.95018","0.00432"
"1944","11.62800","0.96925","0.00537"
"1982","11.85600","0.98820","0.00440"
"2020","12.08400","1.00727","0.00488"
"2058","12.31200","1.02623","0.00470"
"2096","12.54000","1.04524","0.00438"
"2134","12.76800","1.06425","0.00460"
"2172","12.99600","1.08321","0.00439"
"2210","13.22400","1.10228","0.00503"
"2248","13.45200","1.12123","0.00422"
"2286","13.68000","1.14019","0.00459"
"2324","13.90800","1.15926","0.00506"
"2362","14.13600","1.17821","0.00466"
"2400","14.36400","1.19723","0.00432"
"2438","14.59200","1.21618","0.00375"
"2476","14.82000","1.23525","0.00467"
"2514","15.04800","1.25420","0.00415"
"2552","15.27600","1.27322","0.00448"
"2590","15.50400","1.29217","0.00453"
"2628","15.73200","1.31118","0.00493"
"2666","15.96000","1.33026","0.00519"
"2704","16.18800","1.34915","0.00436"
"2742","16.41600","1.36828","0.00393"
"2780","16.64400","1.38724","0.00470"
"2818","16.87200","1.40625","0.00384"
"2856","17.10000","1.42520","0.00377"
"2894","17.32800","1.44416","0.00466"
"2932","17.55600","1.46323","0.00486"
"2970","17.78400","1.48218","0.00505"
"3008","18.01200","1.50126","0.00380"
"3046","18.24000","1.52027","0.00404"
"3084","18.46800","1.53922","0.00449"
"3122","18.69600","1.55823","0.00416"
"3160","18.92400","1.57713","0.00464"
"3198","19.15200","1.59620","0.00430"
"3236","19.38000","1.61521","0.00468"
"3274","19.60800","1.63429","0.00481"
"3312","19.83600","1.65330","0.00434"
"3350","20.06400","1.67219","0.00456"
"3388","20.29200","1.69127","0.00436"
"3426","20.52000","1.71022","0.00436"
"3464","20.74800","1.72923","0.00457"
"3502","20.97600","1.74825","0.00459"
"3540","21.20400","1.76720","0.00529"
"3578","21.43200","1.78627","0.00443"
"3616","21.66000","1.80517","0.00481"
"3654","21.88800","1.82424","0.00480"
"3692","22.11600","1.84319","0.00434"
"3730","22.34400","1.86220","0.00450"
"3768","22.57200","1.88128","0.00566"
"3806","22.80000","1.90017","0.00463"
"3844","23.02800","1.91924","0.00513"
"3882","23.25600","1.93814","0.00474"
"3920","23.48400","1.95721","0.00427"
"3958","23.71200","1.97622","0.00469"
"3996","23.94000","1.99524","0.00420"
"4034","24.16800","2.01425","0.00502"
"4072","24.39600","2.03320","0.00430"
"4110","24.62400","2.05222","0.00439"
"4148","24.85200","2.07123","0.00500"
"4186","25.08000","2.09018","0.00479"
"4224","25.30800","2.10920","0.00479"
"4262","25.53600","2.12821","0.00524"
"4300","25.76400","2.14716","0.00523"
"4338","25.99200","2.16623","0.00470"
"4376","26.22000","2.18525","0.00469"
"4414","26.44800","2.20414","0.00454"
"4452","26.67600","2.22321","0.00477"
"4490","26.90400","2.24217","0.00436"
"4528","27.13200","2.26124","0.00540"
"4566","27.36000","2.28025","0.00477"
"4604","27.58800","2.29921","0.00453"
"4642","27.81600","2.31822","0.00484"
"4680","28.04400","2.33717","0.00471"
"4718","28.27200","2.35625","0.00505"
"4756","28.50000","2.37520","0.00458"
"4794","28.72800","2.39421","0.00463"
"4832","28.95600","2.41323","0.00479"
"4870","29.18400","2.43224","0.00536"
"4908","29.41200","2.45119","0.00464"
"4946","29.64000","2.47014","0.00457"
"4984","29.86800","2.48922","0.00505"
"5022","30.09600","2.50817","0.00467"
"5060","30.32400","2.52724","0.00420"
"5098","30.55200","2.54626","0.00442"
"5136","30.78000","2.56515","0.00513"
"5174","31.00800","2.58422","0.00487"
"5212","31.23600","2.60324","0.00521"
"5250","31.46400","2.62225","0.00511"
"5288","31.69200","2.64120","0.00518"
"5326","31.92000","2.66022","0.00454"
"5364","32.14800","2.67923","0.00487"
"5402","32.37600","2.69818","0.00443"
"5440","32.60400","2.71725","0.00483"
"5478","32.83200","2.73621","0.00433"
"5516","33.06000","2.75522","0.00447"
"5554","33.28800","2.77417","0.00496"
"5592","33.51600","2.79319","0.00458"
"5630","33.74400","2.81220","0.00449"
"5668","33.97200","2.83121","0.00509"
"5706","34.20000","2.85029","0.00470"
"5744","34.42800","2.86918","0.00449"
"5782","34.65600","2.88819","0.00515"
"5820","34.88400","2.90721","0.00507"
"5858","35.11200","2.92622","0.00554"
"5896","35.34000","2.94529","0.00497"
"5934","35.56800","2.96413","0.00467"
"5972","35.79600","2.98332","0.00546"
"6010","36.02400","3.00221","0.00542"
"6048","36.25200","3.02122","0.00548"
"6086","36.48000","3.04024","0.00516"
"6124","36.70800","3.05913","0.00529"
"6162","36.93600","3.07832","0.00504"
"6200","37.16400","3.09716","0.00498"
"6238","37.39200","3.11623","0.00499"
"6276","37.62000","3.13524","0.00469"
"6314","37.84800","3.15420","0.00517"
"6352","38.07600","3.17327","0.00523"
"6390","38.30400","3.19216","0.00476"
"6428","38.53200","3.21124","0.00505"
"6466","38.76000","3.23019","0.00468"
"6504","38.98800","3.24920","0.00418"
"6542","39.21600","3.26828","0.00459"
"6580","39.44400","3.28717","0.00505"
"6618","39.67200","3.30624","0.00467"
"6656","39.90000","3.32520","0.00454"
"6694","40.12800","3.34421","0.00479"
"6732","40.35600","3.36322","0.00495"
"6770","40.58400","3.38223","0.00494"
"6808","40.81200","3.40125","0.00518"
"6846","41.04000","3.42020","0.00473"
"6884","41.26800","3.43927","0.00533"
"6922","41.49600","3.45823","0.00455"
"6960","41.72400","3.47724","0.00495"
"6998","41.95200","3.49625","0.00502"
"7036","42.18000","3.51521","0.00520"
"7074","42.40800","3.53422","0.00497"
"7112","42.63600","3.55317","0.00494"
"7150","42.86400","3.57219","0.00483"
"7188","43.09200","3.59120","0.00448"
"7226","43.32000","3.61021","0.00511"
"7264","43.54800","3.62922","0.00514"
"7302","43.77600","3.64824","0.00508"
"7340","44.00400","3.66725","0.00486"
"7378","44.23200","3.68620","0.00494"
"7416","44.46000","3.70522","0.00480"
"7454","44.68800","3.72423","0.00474"
"7492","44.91600","3.74324","0.00467"
"7530","45.14400","3.76226","0.00499"
"7568","45.37200","3.78121","0.00539"
"7606","45.60000","3.80028","0.00478"
"7644","45.82800","3.81918","0.00536"
"7682","46.05600","3.83825","0.00513"
"7720","46.28400","3.85720","0.00515"
"7758","46.51200","3.87622","0.00497"
"7796","46.74000","3.89523","0.00532"
"7834","46.96800","3.91424","0.00496"
"7872","47.19600","3.93325","0.00496"
"7910","47.42400","3.95215","0.00473"
"7948","47.65200","3.97122","0.00558"
"7986","47.88000","3.99023","0.00526"
"8024","48.10800","4.00925","0.00506"
"8062","48.33600","4.02826","0.00460"
"8100","48.56400","4.04721","0.00551"
"8138","48.79200","4.06623","0.00499"
"8176","49.02000","4.08512","0.00517"
"8214","49.24800","4.10431","0.00495"
"8252","49.47600","4.12321","0.00567"
"8290","49.70400","4.14222","0.00509"
"8328","49.93200","4.16123","0.00546"
"8366","50.16000","4.18018","0.00503"
"8404","50.38800","4.19920","0.00506"
"8442","50.61600","4.21821","0.00524"
"8480","50.84400","4.23728","0.00455"
"8518","51.07200","4.25618","0.00556"
"8556","51.30000","4.27519","0.00529"
"8594","51.52800","4.29420","0.00527"
"8632","51.75600","4.31322","0.00487"
"8670","51.98400","4.33223","0.00520"
"8708","52.21200","4.35118","0.00475"
"8746","52.44000","4.37026","0.00543"
"8784","52.66800","4.38921","0.00494"
"8822","52.89600","4.40816","0.00448"
"8860","53.12400","4.42724","0.00535"
"8898","53.35200","4.44613","0.00512"
"8936","53.58000","4.46526","0.00528"
"8974","53.80800","4.48421","0.00490"
"9012","54.03600","4.50329","0.00518"
"9050","54.26400","4.52224","0.00510"
"9088","54.49200","4.54113","0.00505"
"9126","54.72000","4.56027","0.00519"
"9164","54.94800","4.57922","0.00555"
"9202","55.17600","4.59823","0.00538"
"9240","55.40400","4.61719","0.00507"
"9278","55.63200","4.63620","0.00590"
"9316","55.86000","4.65527","0.00518"
"9354","56.08800","4.67417","0.00543"
"9392","56.31600","4.69324","0.00546"
"9430","56.54400","4.71219","0.00560"
"9468","56.77200","4.73127","0.00575"
"9506","57.00000","4.75028","0.00504"
"9544","57.22800","4.76923","0.00512"
"9582","57.45600","4.78824","0.00534"
"9620","57.68400","4.80714","0.00535"
"9658","57.91200","4.82621","0.00500"
"9696","58.14000","4.84522","0.00565"
"9734","58.36800","4.86424","0.00548"
"9772","58.59600","4.88325","0.00563"
"9810","58.82400","4.90220","0.00572"
"9848","59.05200","4.92128","0.00533"
"9886","59.28000","4.94017","0.00509"
"9924","59.50800","4.95924","0.00476"
"9962","59.73600","4.97820","0.00544"
"10000","59.96400","4.99721","0.00512"
"10038","60.19200","5.01622","0.00565"
"10076","60.42000","5.03517","0.00535"
"10114","60.64800","5.05419","0.00538"
"10152","60.87600","5.07320","0.00568"
"10190","61.10400","5.09221","0.00571"
"10228","61.33200","5.11123","0.00551"
"10266","61.56000","5.13024","0.00605"
"10304","61.78800","5.14925","0.00587"
"10342","62.01600","5.16821","0.00595"
"10380","62.24400","5.18722","0.00561"
"10418","62.47200","5.20617","0.00590"
"10456","62.70000","5.22525","0.00542"
"10494","62.92800","5.24420","0.00504"
"10532","63.15600","5.26321","0.00564"
"10570","63.38400","5.28223","0.00593"
"10608","63.61200","5.30124","0.00540"
"10646","63.84000","5.32025","0.00556"
"10684","64.06800","5.33921","0.00523"
"10722","64.29600","5.35822","0.00543"
"10760","64.52400","5.37723","0.00543"
"10798","64.75200","5.39624","0.00554"
"10836","64.98000","5.41526","0.00529"
"10874","65.20800","5.43421","0.00589"
"10912","65.43600","5.45322","0.00575"
"10950","65.66400","5.47224","0.00527"
"10988","65.89200","5.49125","0.00591"
"11026","66.12000","5.51020","0.00568"
"11064","66.34800","5.52922","0.00607"
"11102","66.57600","5.54823","0.00558"
"11140","66.80400","5.56718","0.00529"
"11178","67.03200","5.58620","0.00588"
"11216","67.26000","5.60521","0.00559"
"11254","67.48800","5.62422","0.00532"
"11292","67.71600","5.64318","0.00604"
"11330","67.94400","5.66219","0.00589"
"11368","68.17200","5.68120","0.00641"
"11406","68.40000","5.70015","0.00603"
"11444","68.62800","5.71929","0.00570"
"11482","68.85600","5.73818","0.00593"
"11520","69.08400","5.75725","0.00582"
"11558","69.31200","5.77627","0.00606"
"11596","69.54000","5.79522","0.00595"
"11634","69.76800","5.81429","0.00641"
"11672","69.99600","5.83319","0.00622"
"11710","70.22400","5.85226","0.00566"
"11748","70.45200","5.87121","0.00561"
"11786","70.68000","5.89023","0.00620"
"11824","70.90800","5.90924","0.00530"
"11862","71.13600","5.92813","0.00601"
"11900","71.36400","5.94726","0.00624"
"11938","71.59200","5.96622","0.00633"
"11976","71.82000","5.98529","0.00607"
"12014","72.04800","6.00424","0.00642"
"12052","72.27600","6.02320","0.00581"
"12090","72.50400","6.04227","0.00624"
"12128","72.73200","6.06110","0.00603"
"12166","72.96000","6.08024","0.00640"
"12204","73.18800","6.09919","0.00585"
"12242","73.41600","6.11826","0.00566"
"12280","73.64400","6.13728","0.00592"
"12318","73.87200","6.15617","0.00586"
"12356","74.10000","6.17530","0.00593"
"12394","74.32800","6.19420","0.00650"
"12432","74.55600","6.21321","0.00610"
"12470","74.78400","6.23222","0.00633"
"12508","75.01200","6.25124","0.00593"
"12546","75.24000","6.27025","0.00606"
"12584","75.46800","6.28920","0.00631"
"12622","75.69600","6.30821","0.00632"
"12660","75.92400","6.32723","0.00630"
"12698","76.15200","6.34624","0.00634"
"12736","76.38000","6.36525","0.00615"
"12774","76.60800","6.38421","0.00527"
"12812","76.83600","6.40322","0.00642"
"12850","77.06400","6.42217","0.00626"
"12888","77.29200","6.44125","0.00632"
"12926","77.52000","6.46020","0.00665"
"12964","77.74800","6.47921","0.00621"
"13002","77.97600","6.49817","0.00632"
"13040","78.20400","6.51724","0.00629"
"13078","78.43200","6.53625","0.00635"
"13116","78.66000","6.55514","0.00612"
"13154","78.88800","6.57422","0.00614"
"13192","79.11600","6.59323","0.00601"
"13230","79.34400","6.61224","0.00614"
"13268","79.57200","6.63126","0.00594"
"13306","79.80000","6.65021","0.00654"
"13344","80.02800","6.66928","0.00619"
"13382","80.25600","6.68818","0.00643"
"13420","80.48400","6.70725","0.00616"
"13458","80.71200","6.72620","0.00667"
"13496","80.94000","6.74522","0.00616"
"13534","81.16800","6.76423","0.00636"
"13572","81.39600","6.78324","0.00636"
"13610","81.62400","6.80220","0.00647"
"13648","81.85200","6.82121","0.00604"
"13686","82.08000","6.84022","0.00613"
"13724","82.30800","6.85923","0.00666"
"13762","82.53600","6.87825","0.00624"
"13800","82.76400","6.89726","0.00664"
"13838","82.99200","6.91627","0.00671"
"13876","83.22000","6.93523","0.00669"
"13914","83.44800","6.95418","0.00697"
"13952","83.67600","6.97325","0.00679"
"13990","83.90400","6.99227","0.00698"
"14028","84.13200","7.01122","0.00697"
"14066","84.36000","7.03023","0.00662"
"14104","84.58800","7.04919","0.00658"
"14142","84.81600","7.06826","0.00631"
"14180","85.04400","7.08721","0.00669"
"14218","85.27200","7.10629","0.00667"
"14256","85.50000","7.12518","0.00670"
"14294","85.72800","7.14419","0.00631"
"14332","85.95600","7.16320","0.00686"
"14370","86.18400","7.18216","0.00679"
"14408","86.41200","7.20123","0.00691"
"14446","86.64000","7.22018","0.00706"
"14484","86.86800","7.23926","0.00661"
"14522","87.09600","7.25821","0.00713"
"14560","87.32400","7.27722","0.00669"
"14598","87.55200","7.29624","0.00700"
"14636","87.78000","7.31519","0.00735"
"14674","88.00800","7.33426","0.00688"
"14712","88.23600","7.35316","0.00693"
"14750","88.46400","7.37223","0.00703"
"14788","88.69200","7.39124","0.00698"
"14826","88.92000","7.41014","0.00649"
"14864","89.14800","7.42933","0.00708"
"14902","89.37600","7.44816","0.00713"
"14940","89.60400","7.46724","0.00719"
"14978","89.83200","7.48619","0.00647"
"15016","90.06000","7.50520","0.00696"
"15054","90.28800","7.52427","0.00665"
"15092","90.51600","7.54317","0.00738"
"15130","90.74400","7.56230","0.00711"
"15168","90.97200","7.58119","0.00677"
"15206","91.20000","7.60027","0.00697"
"15244","91.42800","7.61922","0.00719"
"15282","91.65600","7.63823","0.00722"
"15320","91.88400","7.65725","0.00717"
"15358","92.11200","7.67620","0.00723"
"15396","92.34000","7.69521","0.00679"
"15434","92.56800","7.71422","0.00734"
"15472","92.79600","7.73324","0.00731"
"15510","93.02400","7.75225","0.00676"
"15548","93.25200","7.77114","0.00722"
"15586","93.48000","7.79028","0.00734"
"15624","93.70800","7.80917","0.00728"
"15662","93.93600","7.82818","0.00703"
"15700","94.16400","7.84720","0.00745"
"15738","94.39200","7.86621","0.00678"
"15776","94.62000","7.88528","0.00698"
"15814","94.84800","7.90418","0.00734"
"15852","95.07600","7.92325","0.00685"
"15890","95.30400","7.94214","0.00705"
"15928","95.53200","7.96128","0.00766"
"15966","95.76000","7.98023","0.00691"
"16004","95.98800","7.99924","0.00776"
"16042","96.21600","8.01825","0.00784"
"16080","96.44400","8.03715","0.00724"
"16118","96.67200","8.05622","0.00738"
"16156","96.90000","8.07523","0.00753"
"16194","97.12800","8.09425","0.00712"
"16232","97.35600","8.11326","0.00740"
"16270","97.58400","8.13221","0.00746"
"16308","97.81200","8.15123","0.00756"
"16346","98.04000","8.17018","0.00759"
"16384","98.26800","8.18919","0.00783"
"16422","98.49600","8.20815","0.00773"
"16460","98.72400","8.22722","0.00736"
"16498","98.95200","8.24623","0.00752"
"16536","99.18000","8.26519","0.00761"
"16574","99.40800","8.28432","0.00743"
"16612","99.63600","8.30321","0.00754"
"16650","99.86400","8.32222","0.00805"
"16688","100.09200","8.34118","0.00733"
"16726","100.32000","8.36025","0.00776"
"16764","100.54800","8.37926","0.00749"
"16802","100.77600","8.39822","0.00782"
"16840","101.00400","8.41717","0.00756"
"16878","101.23200","8.43618","0.00729"
"16916","101.46000","8.45526","0.00787"
"16954","101.68800","8.47421","0.00813"
"16992","101.91600","8.49328","0.00773"
"17030","102.14400","8.51224","0.00750"
"17068","102.37200","8.53125","0.00740"
"17106","102.60000","8.55026","0.00792"
"17144","102.82800","8.56922","0.00770"
"17182","103.05600","8.58823","0.00764"
"17220","103.28400","8.60718","0.00817"
"17258","103.51200","8.62625","0.00780"
"17296","103.74000","8.64521","0.00826"
"17334","103.96800","8.66416","0.00809"
"17372","104.19600","8.68323","0.00796"
"17410","104.42400","8.70219","0.00808"
"17448","104.65200","8.72132","0.00775"
"17486","104.88000","8.74021","0.00779"
"17524","105.10800","8.75923","0.00807"
"17562","105.33600","8.77824","0.00785"
"17600","105.56400","8.79713","0.00779"
"17638","105.79200","8.81627","0.00808"
"17676","106.02000","8.83516","0.00786"
"17714","106.24800","8.85429","0.00799"
"17752","106.47600","8.87324","0.00778"
"17790","106.70400","8.89214","0.00798"
"17828","106.93200","8.91127","0.00803"
"17866","107.16000","8.93016","0.00777"
"17904","107.38800","8.94924","0.00788"
"17942","107.61600","8.96819","0.00805"
"17980","107.84400","8.98726","0.00852"
"18018","108.07200","9.00628","0.00796"
"18056","108.30000","9.02523","0.00831"
"18094","108.52800","9.04424","0.00828"
"18132","108.75600","9.06320","0.00812"
"18170","108.98400","9.08227","0.00812"
"18208","109.21200","9.10116","0.00755"
"18246","109.44000","9.12024","0.00780"
"18284","109.66800","9.13925","0.00835"
"18322","109.89600","9.15814","0.00820"
"18360","110.12400","9.17727","0.00799"
"18398","110.35200","9.19623","0.00843"
"18436","110.58000","9.21530","0.00781"
"18474","110.80800","9.23425","0.00800"
"18512","111.03600","9.25321","0.00798"
"18550","111.26400","9.27222","0.00771"
"18588","111.49200","9.29111","0.00797"
"18626","111.72000","9.31025","0.00785"
"18664","111.94800","9.32920","0.00761"
"18702","112.17600","9.34821","0.00720"
"18740","112.40400","9.36729","0.00733"
"18778","112.63200","9.38624","0.00762"
"18816","112.86000","9.40525","0.00729"
"18854","113.08800","9.42421","0.00722"
"18892","113.31600","9.44322","0.00747"
"18930","113.54400","9.46223","0.00784"
"18968","113.77200","9.48125","0.00757"
"19006","114.00000","9.50026","0.00786"
"19044","114.22800","9.51921","0.00794"
"19082","114.45600","9.53822","0.00708"
"19120","114.68400","9.55718","0.00756"
"19158","114.91200","9.57625","0.00740"
"19196","115.14000","9.59520","0.00763"
"19234","115.36800","9.61422","0.00797"
"19272","115.59600","9.63323","0.00788"
"19310","115.82400","9.65218","0.00803"
"19348","116.05200","9.67126","0.00817"
"19386","116.28000","9.69021","0.00777"
"19424","116.50800","9.70922","0.00795"
"19462","116.73600","9.72824","0.00809"
"19500","116.96400","9.74725","0.00753"
"19538","117.19200","9.76626","0.00778"
"19576","117.42000","9.78521","0.00823"
"19614","117.64800","9.80417","0.00812"
"19652","117.87600","9.82324","0.00778"
"19690","118.10400","9.84225","0.00795"
"19728","118.33200","9.86127","0.00751"
"19766","118.56000","9.88022","0.00816"
"19804","118.78800","9.89923","0.00788"
"19842","119.01600","9.91825","0.00802"
"19880","119.24400","9.93720","0.00817"
"19918","119.47200","9.95615","0.00806"
"19956","119.70000","9.97522","0.00766"
"19994","119.92800","9.99418","0.00765"
"20032","120.15600","10.01319","0.00763"
"20070","120.38400","10.03221","0.00752"
"20108","120.61200","10.05122","0.00763"
"20146","120.84000","10.07029","0.00801"
"20184","121.06800","10.08913","0.00792"
"20222","121.29600","10.10826","0.00789"
"20260","121.52400","10.12721","0.00786"
"20298","121.75200","10.14622","0.00748"
"20336","121.98000","10.16524","0.00779"
"20374","122.20800","10.18413","0.00750"
"20412","122.43600","10.20326","0.00799"
"20450","122.66400","10.22222","0.00774"
"20488","122.89200","10.24123","0.00787"
"20526","123.12000","10.26024","0.00819"
"20564","123.34800","10.27920","0.00795"
"20602","123.57600","10.29827","0.00777"
"20640","123.80400","10.31722","0.00744"
"20678","124.03200","10.33624","0.00782"
"20716","124.26000","10.35519","0.00811"
"20754","124.48800","10.37420","0.00769"
"20792","124.71600","10.39328","0.00759"
"20830","124.94400","10.41217","0.00820"
"20868","125.17200","10.43130","0.00792"
"20906","125.40000","10.45019","0.00808"
"20944","125.62800","10.46921","0.00821"
"20982","125.85600","10.48822","0.00770"
"21020","126.08400","10.50723","0.00775"
"21058","126.31200","10.52625","0.00802"
"21096","126.54000","10.54514","0.00795"
"21134","126.76800","10.56427","0.00782"
"21172","126.99600","10.58322","0.00836"
"21210","127.22400","10.60224","0.00847"
"21248","127.45200","10.62119","0.00790"
"21286","127.68000","10.64020","0.00792"
"21324","127.90800","10.65922","0.00888"
"21362","128.13600","10.67823","0.00837"
"21400","128.36400","10.69724","0.00853"
"21438","128.59200","10.71626","0.00834"
"21476","128.82000","10.73521","0.00824"
"21514","129.04800","10.75428","0.00811"
"21552","129.27600","10.77318","0.00854"
"21590","129.50400","10.79225","0.00842"
"21628","129.73200","10.81120","0.00844"
"21666","129.96000","10.83028","0.00801"
"21704","130.18800","10.84929","0.00822"
"21742","130.41600","10.86824","0.00863"
"21780","130.64400","10.88725","0.00837"
"21818","130.87200","10.90615","0.00827"
"21856","131.10000","10.92528","0.00814"
"21894","131.32800","10.94423","0.00841"
"21932","131.55600","10.96325","0.00862"
"21970","131.78400","10.98220","0.00864"
"22008","132.01200","11.00121","0.00866"
"22046","132.24000","11.02023","0.00852"
"22084","132.46800","11.03918","0.00873"
"22122","132.69600","11.05819","0.00837"
"22160","132.92400","11.07721","0.00853"
"22198","133.15200","11.09616","0.00800"
"22236","133.38000","11.11523","0.00867"
"22274","133.60800","11.13419","0.00865"
"22312","133.83600","11.15326","0.00861"
"22350","134.06400","11.17221","0.00854"
"22388","134.29200","11.19123","0.00907"
"22426","134.52000","11.21024","0.00872"
"22464","134.74800","11.22919","0.00867"
"22502","134.97600","11.24826","0.00892"
"22540","135.20400","11.26722","0.00889"
"22578","135.43200","11.28623","0.00889"
"22616","135.66000","11.30519","0.00915"
"22654","135.88800","11.32426","0.00887"
"22692","136.11600","11.34321","0.00900"
"22730","136.34400","11.36222","0.00875"
"22768","136.57200","11.38124","0.00915"
"22806","136.80000","11.40019","0.00888"
"22844","137.02800","11.41920","0.00882"
"22882","137.25600","11.43822","0.00919"
"22920","137.48400","11.45723","0.00884"
"22958","137.71200","11.47618","0.00873"
"22996","137.94000","11.49525","0.00887"
"23034","138.16800","11.51421","0.00896"
"23072","138.39600","11.53322","0.00884"
"23110","138.62400","11.55223","0.00886"
"23148","138.85200","11.57125","0.00911"
"23186","139.08000","11.59026","0.00928"
"23224","139.30800","11.60927","0.00873"
"23262","139.53600","11.62823","0.00975"
"23300","139.76400","11.64724","0.00883"
"23338","139.99200","11.66613","0.00935"
"23376","140.22000","11.68527","0.00965"
"23414","140.44800","11.70422","0.00881"
"23452","140.67600","11.72323","0.00925"
"23490","140.90400","11.74225","0.00956"
"23528","141.13200","11.76120","0.00915"
"23566","141.36000","11.78027","0.00899"
"23604","141.58800","11.79917","0.00920"
"23642","141.81600","11.81830","0.00891"
"23680","142.04400","11.83719","0.00942"
"23718","142.27200","11.85620","0.00963"
"23756","142.50000","11.87522","0.00943"
"23794","142.72800","11.89417","0.00954"
"23832","142.95600","11.91324","0.00963"
"23870","143.18400","11.93220","0.00934"
"23908","143.41200","11.95127","0.00941"
"23946","143.64000","11.97022","0.00918"
"23984","143.86800","11.98918","0.00935"
"24022","144.09600","12.00825","0.00901"
"24060","144.32400","12.02720","0.00931"
"24098","144.55200","12.04622","0.00968"
"24136","144.78000","12.06523","0.00934"
"24174","145.00800","12.08424","0.00949"
"24212","145.23600","12.10326","0.00901"
"24250","145.46400","12.12221","0.00930"
"24288","145.69200","12.14128","0.00988"
"24326","145.92000","12.16012","0.00974"
"24364","146.14800","12.17925","0.00952"
"24402","146.37600","12.19820","0.00921"
"24440","146.60400","12.21721","0.00948"
"24478","146.83200","12.23629","0.00934"
"24516","147.06000","12.25524","0.00960"
"24554","147.28800","12.27425","0.00972"
"24592","147.51600","12.29315","0.00961"
"24630","147.74400","12.31222","0.01005"
"24668","147.97200","12.33117","0.00918"
"24706","148.20000","12.35025","0.00996"
"24744","148.42800","12.36926","0.00956"
"24782","148.65600","12.38821","0.00976"
"24820","148.88400","12.40722","0.00995"
"24858","149.11200","12.42618","0.01003"
"24896","149.34000","12.44525","0.00993"
"24934","149.56800","12.46426","0.01027"
"24972","149.79600","12.48316","0.01022"
"25010","150.02400","12.50223","0.00948"
"25048","150.25200","12.52118","0.00960"
"25086","150.48000","12.54026","0.00937"
"25124","150.70800","12.55921","0.00997"
"25162","150.93600","12.57822","0.00912"
"25200","151.16400","12.59724","0.00919"
"25238","151.39200","12.61619","0.00895"
"25276","151.62000","12.63526","0.00888"
"25314","151.84800","12.65416","0.00948"
"25352","152.07600","12.67317","0.00964"
"25390","152.30400","12.69218","0.00910"
"25428","152.53200","12.71125","0.00961"
"25466","152.76000","12.73021","0.00964"
"25504","152.98800","12.74922","0.00937"
"25542","153.21600","12.76824","0.00966"
"25580","153.44400","12.78725","0.00879"
"25618","153.67200","12.80620","0.00894"
"25656","153.90000","12.82521","0.00945"
"25694","154.12800","12.84429","0.00911"
"25732","154.35600","12.86324","0.00923"
"25770","154.58400","12.88219","0.00932"
"25808","154.81200","12.90127","0.00965"
"25846","155.04000","12.92022","0.00946"
"25884","155.26800","12.93923","0.00984"
"25922","155.49600","12.95819","0.00897"
"25960","155.72400","12.97726","0.00826"
"25998","155.95200","12.99627","0.00818"
"26036","156.18000","13.01517","0.00907"
"26074","156.40800","13.03424","0.00845"
"26112","156.63600","13.05319","0.00914"
"26150","156.86400","13.07226","0.00882"
"26188","157.09200","13.09122","0.00867"
"26226","157.32000","13.11023","0.00936"
"26264","157.54800","13.12924","0.00894"
"26302","157.77600","13.14814","0.00851"
"26340","158.00400","13.16727","0.00886"
"26378","158.23200","13.18616","0.00856"
"26416","158.46000","13.20524","0.00865"
"26454","158.68800","13.22419","0.00907"
"26492","158.91600","13.24320","0.00938"
"26530","159.14400","13.26228","0.00885"
"26568","159.37200","13.28117","0.00894"
"26606","159.60000","13.30024","0.00882"
"26644","159.82800","13.31925","0.00910"
"26682","160.05600","13.33821","0.00941"
"26720","160.28400","13.35722","0.00914"
"26758","160.51200","13.37617","0.00941"
"26796","160.74000","13.39525","0.00897"
"26834","160.96800","13.41414","0.00930"
"26872","161.19600","13.43327","0.00924"
"26910","161.42400","13.45223","0.00999"
"26948","161.65200","13.47124","0.00972"
"26986","161.88000","13.49025","0.01007"
"27024","162.10800","13.50921","0.00995"
"27062","162.33600","13.52828","0.01063"
"27100","162.56400","13.54717","0.01050"
"27138","162.79200","13.56631","0.01058"
"27176","163.02000","13.58520","0.01050"
"27214","163.24800","13.60421","0.01051"
"27252","163.47600","13.62322","0.01067"
"27290","163.70400","13.64224","0.01111"
"27328","163.93200","13.66119","0.01113"
"27366","164.16000","13.68015","0.01159"
"27404","164.38800","13.69922","0.01145"
"27442","164.61600","13.71829","0.01159"
"27480","164.84400","13.73724","0.01132"
"27518","165.07200","13.75620","0.01159"
"27556","165.30000","13.77515","0.01188"
"27594","165.52800","13.79422","0.01199"
"27632","165.75600","13.81318","0.01230"
"27670","165.98400","13.83225","0.01226"
"27708","166.21200","13.85126","0.01246"
"27746","166.44000","13.87016","0.01297"
"27784","166.66800","13.88929","0.01289"
"27822","166.89600","13.90824","0.01339"
"27860","167.12400","13.92725","0.01320"
"27898","167.35200","13.94621","0.01328"
"27936","167.58000","13.96522","0.01393"
"27974","167.80800","13.98423","0.01430"
"28012","168.03600","14.00319","0.01444"
"28050","168.26400","14.02226","0.01474"
"28088","168.49200","14.04121","0.01501"
"28126","168.72000","14.06023","0.01531"
"28164","168.94800","14.07924","0.01620"
"28202","169.17600","14.09825","0.01617"
"28240","169.40400","14.11727","0.01697"
"28278","169.63200","14.13622","0.01604"
"28316","169.86000","14.15517","0.01685"
"28354","170.08800","14.17418","0.01654"
"28392","170.31600","14.19320","0.01809"
"28430","170.54400","14.21221","0.01779"
"28468","170.77200","14.23123","0.01869"
"28506","171.00000","14.25024","0.01843"
"28544","171.22800","14.26919","0.02000"
"28582","171.45600","14.28820","0.01982"
"28620","171.68400","14.30722","0.02014"
"28658","171.91200","14.32623","0.02124"
"28696","172.14000","14.34518","0.02146"
"28734","172.36800","14.36426","0.02250"
"28772","172.59600","14.38327","0.02364"
"28810","172.82400","14.40216","0.02309"
"28848","173.05200","14.42124","0.02534"
"28886","173.28000","14.44019","0.02526"
"28924","173.50800","14.45926","0.02642"
"28962","173.73600","14.47815","0.02765"
"29000","173.96400","14.49723","0.02833"
"29038","174.19200","14.51624","0.02975"
"29076","174.42000","14.53519","0.03199"
"29114","174.64800","14.55427","0.03197"
"29152","174.87600","14.57316","0.03270"
"29190","175.10400","14.59223","0.03387"
"29228","175.33200","14.61119","0.03554"
"29266","175.56000","14.63020","0.02932"
"29304","175.78800","14.64927","0.01638"
"29342","176.01600","14.66817","0.01856"
"29380","176.24400","14.68724","0.01353"
"29418","176.47200","14.70619","0.01516"
"29456","176.70000","14.72521","0.01601"
"29494","176.92800","14.74422","0.01600"
"29532","177.15600","14.76317","0.01712"
"29570","177.38400","14.78225","0.01721"
"29608","177.61200","14.80120","0.01835"
"29646","177.84000","14.82027","0.01899"
"29684","178.06800","14.83922","0.02090"
"29722","178.29600","14.85824","0.02010"
"29760","178.52400","14.87725","0.02173"
"29798","178.75200","14.89614","0.02376"
"29836","178.98000","14.91522","0.02361"
"29874","179.20800","14.93423","0.02397"
"29912","179.43600","14.95324","0.02636"
"29950","179.66400","14.97226","0.02397"
"29988","179.89200","14.99121","0.02546"
"30026","180.12000","15.01022","0.02851"
"30064","180.34800","15.02918","0.02831"
"30102","180.57600","15.04825","0.02917"
"30140","180.80400","15.06720","0.03249"
"30178","181.03200","15.08622","0.03161"
"30216","181.26000","15.10523","0.03273"
"30254","181.48800","15.12418","0.03512"
"30292","181.71600","15.14325","0.03459"
"30330","181.94400","15.16221","0.03601"
"30368","182.17200","15.18128","0.03747"
"30406","182.40000","15.20023","0.03893"
"30444","182.62800","15.21925","0.03953"
"30482","182.85600","15.23826","0.04080"
"30520","183.08400","15.25715","0.04098"
"30558","183.31200","15.27617","0.04289"
"30596","183.54000","15.29518","0.04407"
"30634","183.76800","15.31425","0.04513"
"30672","183.99600","15.33327","0.04650"
"30710","184.22400","15.35222","0.04726"
"30748","184.45200","15.37123","0.04801"
"30786","184.68000","15.39018","0.05014"
"30824","184.90800","15.40920","0.05072"
"30862","185.13600","15.42821","0.05163"
"30900","185.36400","15.44722","0.05358"
"30938","185.59200","15.46624","0.05395"
"30976","185.82000","15.48519","0.05500"
"31014","186.04800","15.50426","0.05607"
"31052","186.27600","15.52316","0.05671"
"31090","186.50400","15.54223","0.05765"
"31128","186.73200","15.56124","0.05633"
"31166","186.96000","15.58026","0.01066"
"31204","187.18800","15.59927","0.00659"
"31242","187.41600","15.61822","0.00637"
"31280","187.64400","15.63723","0.00629"
"31318","187.87200","15.65619","0.00487"
"31356","188.10000","15.67520","0.00630"
"31394","188.32800","15.69421","0.00726"
"31432","188.55600","15.71323","0.00672"
"31470","188.78400","15.73224","0.00653"
"31508","189.01200","15.75125","0.00663"
"31546","189.24000","15.77021","0.00729"
"31584","189.46800","15.78922","0.00712"
"31622","189.69600","15.80823","0.00719"
"31660","189.92400","15.82725","0.00638"
"31698","190.15200","15.84626","0.00728"
"31736","190.38000","15.86521","0.00770"
"31774","190.60800","15.88422","0.00656"
"31812","190.83600","15.90324","0.00672"
"31850","191.06400","15.92219","0.00720"
"31888","191.29200","15.94126","0.00710"
"31926","191.52000","15.96022","0.00741"
"31964","191.74800","15.97923","0.00730"
"32002","191.97600","15.99824","0.00769"
"32040","192.20400","16.01714","0.00722"
"32078","192.43200","16.03627","0.00652"
"32116","192.66000","16.05522","0.00743"
"32154","192.88800","16.07424","0.00777"
"32192","193.11600","16.09319","0.00699"
"32230","193.34400","16.11220","0.00781"
"32268","193.57200","16.13128","0.00746"
"32306","193.80000","16.15017","0.00768"
"32344","194.02800","16.16924","0.00747"
"32382","194.25600","16.18819","0.00789"
"32420","194.48400","16.20727","0.00824"
"32458","194.71200","16.22622","0.00792"
"32496","194.94000","16.24524","0.00853"
"32534","195.16800","16.26425","0.00884"
"32572","195.39600","16.28314","0.00841"
"32610","195.62400","16.30227","0.00836"
"32648","195.85200","16.32123","0.00889"
"32686","196.08000","16.34018","0.00905"
"32724","196.30800","16.35919","0.00871"
"32762","196.53600","16.37815","0.00890"
"32800","196.76400","16.39728","0.00872"
"32838","196.99200","16.41623","0.00960"
"32876","197.22000","16.43530","0.00918"
"32914","197.44800","16.45420","0.00971"
"32952","197.67600","16.47321","0.00988"
"32990","197.90400","16.49228","0.01021"
"33028","198.13200","16.51118","0.01057"
"33066","198.36000","16.53025","0.01027"
"33104","198.58800","16.54914","0.01109"
"33142","198.81600","16.56822","0.01016"
"33180","199.04400","16.58723","0.00892"
"33218","199.27200","16.60624","0.00907"
"33256","199.50000","16.62526","0.00882"
"33294","199.72800","16.64421","0.00889"
"33332","199.95600","16.66322","0.00916"
"33370","200.18400","16.68224","0.00819"
"33408","200.41200","16.70125","0.00916"
"33446","200.64000","16.72026","0.00863"
"33484","200.86800","16.73916","0.00923"
"33522","201.09600","16.75823","0.00926"
"33560","201.32400","16.77712","0.00949"
"33598","201.55200","16.79626","0.00945"
"33636","201.78000","16.81521","0.00953"
"33674","202.00800","16.83422","0.00899"
"33712","202.23600","16.85329","0.00864"
"33750","202.46400","16.87219","0.00860"
"33788","202.69200","16.89120","0.00852"
"33826","202.92000","16.91021","0.00915"
"33864","203.14800","16.92923","0.00921"
"33902","203.37600","16.94824","0.00945"
"33940","203.60400","16.96719","0.00950"
"33978","203.83200","16.98627","0.00943"
"34016","204.06000","17.00516","0.00914"
"34054","204.28800","17.02423","0.00997"
"34092","204.51600","17.04325","0.00970"
"34130","204.74400","17.06226","0.00996"
"34168","204.97200","17.08121","0.00994"
"34206","205.20000","17.10022","0.00983"
"34244","205.42800","17.11924","0.01029"
"34282","205.65600","17.13819","0.01050"
"34320","205.88400","17.15720","0.01112"
"34358","206.11200","17.17622","0.01089"
"34396","206.34000","17.19523","0.01090"
"34434","206.56800","17.21418","0.01143"
"34472","206.79600","17.23320","0.01081"
"34510","207.02400","17.25221","0.01171"
"34548","207.25200","17.27116","0.01169"
"34586","207.48000","17.29024","0.01198"
"34624","207.70800","17.30919","0.01229"
"34662","207.93600","17.32826","0.01245"
"34700","208.16400","17.34722","0.01278"
"34738","208.39200","17.36623","0.01252"
"34776","208.62000","17.38524","0.01313"
"34814","208.84800","17.40420","0.01351"
"34852","209.07600","17.42327","0.01313"
"34890","209.30400","17.44222","0.01409"
"34928","209.53200","17.46124","0.01380"
"34966","209.76000","17.48019","0.01436"
"35004","209.98800","17.49926","0.01450"
"35042","210.21600","17.51821","0.01451"
"35080","210.44400","17.53717","0.01499"
"35118","210.67200","17.55624","0.01500"
"35156","210.90000","17.57519","0.01569"
"35194","211.12800","17.59421","0.01638"
"35232","211.35600","17.61328","0.01710"
"35270","211.58400","17.63217","0.01719"
"35308","211.81200","17.65125","0.01809"
"35346","212.04000","17.67020","0.01841"
"35384","212.26800","17.68927","0.01876"
"35422","212.49600","17.70823","0.01938"
"35460","212.72400","17.72724","0.02005"
"35498","212.95200","17.74625","0.02063"
"35536","213.18000","17.76514","0.02128"
"35574","213.40800","17.78428","0.02217"
"35612","213.63600","17.80317","0.02309"
"35650","213.86400","17.82224","0.02361"
"35688","214.09200","17.84120","0.02465"
"35726","214.32000","17.86021","0.02573"
"35764","214.54800","17.87922","0.02638"
"35802","214.77600","17.89818","0.02778"
"35840","215.00400","17.91725","0.02797"
"35878","215.23200","17.93620","0.02955"
"35916","215.46000","17.95522","0.03063"
"35954","215.68800","17.97423","0.03250"
"35992","215.91600","17.99318","0.03274"
"36030","216.14400","18.01225","0.03336"
"36068","216.37200","18.03115","0.03077"
"36106","216.60000","18.05022","0.00758"
"36144","216.82800","18.06917","0.00686"
"36182","217.05600","18.08825","0.00681"
"36220","217.28400","18.10726","0.00809"
"36258","217.51200","18.12615","0.00694"
"36296","217.74000","18.14528","0.00698"
"36334","217.96800","18.16418","0.00752"
"36372","218.19600","18.18325","0.00720"
"36410","218.42400","18.20226","0.00683"
"36448","218.65200","18.22116","0.00717"
"36486","218.88000","18.24029","0.00817"
"36524","219.10800","18.25918","0.00754"
"36562","219.33600","18.27826","0.00830"
"36600","219.56400","18.29721","0.00740"
"36638","219.79200","18.31623","0.00771"
"36676","220.02000","18.33524","0.00827"
"36714","220.24800","18.35419","0.00797"
"36752","220.47600","18.37326","0.00878"
"36790","220.70400","18.39222","0.00879"
"36828","220.93200","18.41123","0.00892"
"36866","221.16000","18.43018","0.00925"
"36904","221.38800","18.44926","0.00894"
"36942","221.61600","18.46827","0.00949"
"36980","221.84400","18.48716","0.00991"
"37018","222.07200","18.50624","0.00935"
"37056","222.30000","18.52525","0.01017"
"37094","222.52800","18.54426","0.01033"
"37132","222.75600","18.56327","0.01030"
"37170","222.98400","18.58223","0.00969"
"37208","223.21200","18.60124","0.01002"
"37246","223.44000","18.62020","0.01102"
"37284","223.66800","18.63921","0.01102"
"37322","223.89600","18.65822","0.01130"
"37360","224.12400","18.67723","0.01119"
"37398","224.35200","18.69619","0.01150"
"37436","224.58000","18.71520","0.01193"
"37474","224.80800","18.73427","0.01171"
"37512","225.03600","18.75323","0.01222"
"37550","225.26400","18.77224","0.01246"
"37588","225.49200","18.79119","0.01281"
"37626","225.72000","18.81021","0.01309"
"37664","225.94800","18.82922","0.01293"
"37702","226.17600","18.84823","0.01269"
"37740","226.40400","18.86719","0.01347"
"37778","226.63200","18.88614","0.01377"
"37816","226.86000","18.90527","0.01419"
"37854","227.08800","18.92422","0.01435"
"37892","227.31600","18.94324","0.01488"
"37930","227.54400","18.96219","0.01545"
"37968","227.77200","18.98120","0.01592"
"38006","228.00000","19.00028","0.01544"
"38044","228.22800","19.01917","0.01622"
"38082","228.45600","19.03824","0.01629"
"38120","228.68400","19.05720","0.01646"
"38158","228.91200","19.07621","0.01650"
"38196","229.14000","19.09522","0.01710"
"38234","229.36800","19.11423","0.01472"
"38272","229.59600","19.13319","0.01532"
"38310","229.82400","19.15220","0.01689"
"38348","230.05200","19.17128","0.01637"
"38386","230.28000","19.19023","0.01735"
"38424","230.50800","19.20924","0.01776"
"38462","230.73600","19.22819","0.01804"
"38500","230.96400","19.24721","0.01967"
"38538","231.19200","19.26622","0.01922"
"38576","231.42000","19.28517","0.02028"
"38614","231.64800","19.30425","0.01960"
"38652","231.87600","19.32320","0.02239"
"38690","232.10400","19.34221","0.02271"
"38728","232.33200","19.36123","0.02434"
"38766","232.56000","19.38024","0.02560"
"38804","232.78800","19.39925","0.02565"
"38842","233.01600","19.41815","0.02760"
"38880","233.24400","19.43728","0.02910"
"38918","233.47200","19.45623","0.02983"
"38956","233.70000","19.47518","0.03100"
"38994","233.92800","19.49420","0.03141"
"39032","234.15600","19.51315","0.03187"
"39070","234.38400","19.53228","0.03288"
"39108","234.61200","19.55118","0.03430"
"39146","234.84000","19.57025","0.03513"
"39184","235.06800","19.58926","0.03683"
"39222","235.29600","19.60816","0.01449"
"39260","235.52400","19.62723","0.01533"
"39298","235.75200","19.64618","0.01604"
"39336","235.98000","19.66526","0.01815"
"39374","236.20800","19.68421","0.01916"
"39412","236.43600","19.70322","0.01967"
"39450","236.66400","19.72229","0.01990"
"39488","236.89200","19.74113","0.02316"
"39526","237.12000","19.76026","0.02251"
"39564","237.34800","19.77921","0.02308"
"39602","237.57600","19.79823","0.02381"
"39640","237.80400","19.81730","0.02684"
"39678","238.03200","19.83619","0.02594"
"39716","238.26000","19.85527","0.02661"
"39754","238.48800","19.87416","0.03025"
"39792","238.71600","19.89323","0.02874"
"39830","238.94400","19.91225","0.03014"
"39868","239.17200","19.93120","0.03112"
"39906","239.40000","19.95021","0.03224"
"39944","239.62800","19.96917","0.03252"
"39982","239.85600","19.98824","0.03322"
"40020","240.08400","20.00719","0.03677"
"40058","240.31200","20.02626","0.03498"
"40096","240.54000","20.04522","0.03632"
"40134","240.76800","20.06423","0.03908"
"40172","240.99600","20.08324","0.03759"
"40210","241.22400","20.10220","0.03874"
"40248","241.45200","20.12127","0.04022"
"40286","241.68000","20.14016","0.03958"
"40324","241.90800","20.15924","0.03994"
"40362","242.13600","20.17819","0.01061"
"40400","242.36400","20.19720","0.00788"
"40438","242.59200","20.21622","0.00963"
"40476","242.82000","20.23523","0.00551"
"40514","243.04800","20.25424","0.00582"
"40552","243.27600","20.27320","0.00747"
"40590","243.50400","20.29227","0.00857"
"40628","243.73200","20.31122","0.00633"
"40666","243.96000","20.33023","0.00620"
"40704","244.18800","20.34925","0.00791"
"40742","244.41600","20.36820","0.00782"
"40780","244.64400","20.38721","0.00585"
"40818","244.87200","20.40617","0.00625"
"40856","245.10000","20.42524","0.00802"
"40894","245.32800","20.44425","0.00669"
"40932","245.55600","20.46321","0.00625"
"40970","245.78400","20.48222","0.00697"
"41008","246.01200","20.50123","0.00740"
"41046","246.24000","20.52024","0.00690"
"41084","246.46800","20.53920","0.00673"
"41122","246.69600","20.55821","0.00824"
"41160","246.92400","20.57723","0.00700"
"41198","247.15200","20.59624","0.00657"
"41236","247.38000","20.61525","0.00790"
"41274","247.60800","20.63421","0.00712"
"41312","247.83600","20.65322","0.00753"
"41350","248.06400","20.67223","0.00826"
"41388","248.29200","20.69124","0.00824"
"41426","248.52000","20.71020","0.00745"
"41464","248.74800","20.72921","0.00778"
"41502","248.97600","20.74822","0.00860"
"41540","249.20400","20.76724","0.00789"
"41578","249.43200","20.78625","0.00783"
"41616","249.66000","20.80514","0.00849"
"41654","249.88800","20.82422","0.00739"
"41692","250.11600","20.84323","0.00906"
"41730","250.34400","20.86224","0.00784"
"41768","250.57200","20.88132","0.00839"
"41806","250.80000","20.90015","0.00865"
"41844","251.02800","20.91928","0.00794"
"41882","251.25600","20.93823","0.00927"
"41920","251.48400","20.95719","0.00803"
"41958","251.71200","20.97626","0.00843"
"41996","251.94000","20.99516","0.00904"
"42034","252.16800","21.01429","0.00910"
"42072","252.39600","21.03318","0.00951"
"42110","252.62400","21.05225","0.00880"
"42148","252.85200","21.07121","0.00954"
"42186","253.08000","21.09022","0.00880"
"42224","253.30800","21.10923","0.00971"
"42262","253.53600","21.12813","0.00978"
"42300","253.76400","21.14726","0.00838"
"42338","253.99200","21.16615","0.01054"
"42376","254.22000","21.18522","0.00873"
"42414","254.44800","21.20424","0.01170"
"42452","254.67600","21.22319","0.00860"
"42490","254.90400","21.24226","0.01013"
"42528","255.13200","21.26116","0.01131"
"42566","255.36000","21.28017","0.00763"
"42604","255.58800","21.29924","0.01240"
"42642","255.81600","21.31820","0.00866"
"42680","256.04400","21.33727","0.01113"
"42718","256.27200","21.35616","0.00995"
"42756","256.50000","21.37523","0.01132"
"42794","256.72800","21.39419","0.01066"
"42832","256.95600","21.41326","0.01090"
"42870","257.18400","21.43222","0.01108"
"42908","257.41200","21.45123","0.01027"
"42946","257.64000","21.47024","0.01306"
"42984","257.86800","21.48919","0.01026"
"43022","258.09600","21.50821","0.01302"
"43060","258.32400","21.52722","0.01017"
"43098","258.55200","21.54623","0.01323"
"43136","258.78000","21.56525","0.01073"
"43174","259.00800","21.58426","0.01329"
"43212","259.23600","21.60321","0.01160"
"43250","259.46400","21.62217","0.01419"
"43288","259.69200","21.64124","0.01201"
"43326","259.92000","21.66019","0.01387"
"43364","260.14800","21.67921","0.01273"
"43402","260.37600","21.69822","0.01466"
"43440","260.60400","21.71717","0.01332"
"43478","260.83200","21.73625","0.01406"
"43516","261.06000","21.75520","0.01453"
"43554","261.28800","21.77421","0.01464"
"43592","261.51600","21.79323","0.01525"
"43630","261.74400","21.81218","0.01470"
"43668","261.97200","21.83119","0.01517"
"43706","262.20000","21.85020","0.01601"
"43744","262.42800","21.86922","0.01582"
"43782","262.65600","21.88817","0.01588"
"43820","262.88400","21.90724","0.01611"
"43858","263.11200","21.92620","0.01698"
"43896","263.34000","21.94527","0.01663"
"43934","263.56800","21.96422","0.01766"
"43972","263.79600","21.98324","0.01771"
"44010","264.02400","22.00225","0.01928"
"44048","264.25200","22.02120","0.01825"
"44086","264.48000","22.04022","0.02024"
"44124","264.70800","22.05923","0.01941"
"44162","264.93600","22.07824","0.02089"
"44200","265.16400","22.09719","0.02066"
"44238","265.39200","22.11621","0.02207"
"44276","265.62000","22.13528","0.02222"
"44314","265.84800","22.15423","0.02359"
"44352","266.07600","22.17325","0.02301"
"44390","266.30400","22.19220","0.02435"
"44428","266.53200","22.21127","0.02548"
"44466","266.76000","22.23022","0.02548"
"44504","266.98800","22.24918","0.02631"
"44542","267.21600","22.26826","0.02771"
"44580","267.44400","22.28720","0.02909"
"44618","267.67200","22.30628","0.02908"
"44656","267.90000","22.32523","0.03020"
"44694","268.12800","22.34419","0.03076"
"44732","268.35600","22.36320","0.03227"
"44770","268.58400","22.38215","0.03367"
"44808","268.81200","22.40129","0.03375"
"44846","269.04000","22.42024","0.03570"
"44884","269.26800","22.43925","0.03607"
"44922","269.49600","22.45820","0.03682"
"44960","269.72400","22.47716","0.03852"
"44998","269.95200","22.49629","0.03884"
"45036","270.18000","22.51518","0.04008"
"45074","270.40800","22.53425","0.04163"
"45112","270.63600","22.55321","0.04238"
"45150","270.86400","22.57222","0.04281"
"45188","271.09200","22.59130","0.04481"
"45226","271.32000","22.61019","0.04549"
"45264","271.54800","22.62926","0.04659"
"45302","271.77600","22.64822","0.04704"
"45340","272.00400","22.66723","0.04920"
"45378","272.23200","22.68624","0.04949"
"45416","272.46000","22.70526","0.05113"
"45454","272.68800","22.72427","0.05237"
"45492","272.91600","22.74316","0.05288"
"45530","273.14400","22.76223","0.05439"
"45568","273.37200","22.78125","0.05556"
"45606","273.60000","22.80026","0.05651"
"45644","273.82800","22.81927","0.05826"
"45682","274.05600","22.83823","0.05970"
"45720","274.28400","22.85730","0.05898"
"45758","274.51200","22.87619","0.06061"
"45796","274.74000","22.89521","0.06191"
"45834","274.96800","22.91422","0.06281"
"45872","275.19600","22.93323","0.06379"
"45910","275.42400","22.95224","0.06460"
"45948","275.65200","22.97120","0.06540"
"45986","275.88000","22.99027","0.04657"
"46024","276.10800","23.00916","0.00673"
"46062","276.33600","23.02830","0.00439"
"46100","276.56400","23.04725","0.00377"
"46138","276.79200","23.06626","0.00487"
"46176","277.02000","23.08522","0.00566"
"46214","277.24800","23.10417","0.00574"
"46252","277.47600","23.12324","0.00656"
"46290","277.70400","23.14220","0.00607"
"46328","277.93200","23.16127","0.00545"
"46366","278.16000","23.18028","0.00596"
"46404","278.38800","23.19924","0.00571"
"46433","278.56000","23.21358","0.00605"