File: Trajectories_together/170121_3Specimen_RawData_2.csv
"","V1","V2","V3"
"1","End date","1/21/2017",""
"2","Specimen label","13CT_6",""
"3","Maximum Load","0.10381","N"
"4","Time","Extension","Load"
"5","(s)","(mm)","(N)"
"6","0.00000","0.00000","0.00027"
"35","0.17400","0.01124","0.00174"
"64","0.34800","0.02906","0.00499"
"93","0.52200","0.04377","0.00753"
"122","0.69600","0.05824","0.00733"
"151","0.87000","0.07276","0.00941"
"180","1.04400","0.08723","0.00979"
"209","1.21800","0.10176","0.01065"
"238","1.39200","0.11623","0.01109"
"267","1.56600","0.13064","0.01103"
"296","1.74000","0.14523","0.01169"
"325","1.91400","0.15970","0.01194"
"354","2.08800","0.17417","0.01259"
"383","2.26200","0.18876","0.01294"
"412","2.43600","0.20322","0.01254"
"441","2.61000","0.21769","0.01318"
"470","2.78400","0.23216","0.01317"
"499","2.95800","0.24675","0.01279"
"528","3.13200","0.26122","0.01273"
"557","3.30600","0.27569","0.01300"
"586","3.48000","0.29022","0.01323"
"615","3.65400","0.30469","0.01294"
"644","3.82800","0.31922","0.01308"
"673","4.00200","0.33375","0.01289"
"702","4.17600","0.34821","0.01321"
"731","4.35000","0.36262","0.01292"
"760","4.52400","0.37721","0.01250"
"789","4.69800","0.39174","0.01306"
"818","4.87200","0.40615","0.01324"
"847","5.04600","0.42074","0.01343"
"876","5.22000","0.43521","0.01293"
"905","5.39400","0.44962","0.01385"
"934","5.56800","0.46421","0.01268"
"963","5.74200","0.47868","0.01221"
"992","5.91600","0.49314","0.01269"
"1021","6.09000","0.50773","0.01272"
"1050","6.26400","0.52226","0.01291"
"1079","6.43800","0.53667","0.01299"
"1108","6.61200","0.55120","0.01276"
"1137","6.78600","0.56567","0.01248"
"1166","6.96000","0.58014","0.01352"
"1195","7.13400","0.59473","0.01278"
"1224","7.30800","0.60926","0.01312"
"1253","7.48200","0.62366","0.01305"
"1282","7.65600","0.63819","0.01286"
"1311","7.83000","0.65272","0.01341"
"1340","8.00400","0.66719","0.01340"
"1369","8.17800","0.68172","0.01339"
"1398","8.35200","0.69619","0.01354"
"1427","8.52600","0.71066","0.01387"
"1456","8.70000","0.72519","0.01327"
"1485","8.87400","0.73972","0.01334"
"1514","9.04800","0.75419","0.01362"
"1543","9.22200","0.76865","0.01281"
"1572","9.39600","0.78318","0.01375"
"1601","9.57000","0.79771","0.01296"
"1630","9.74400","0.81224","0.01351"
"1659","9.91800","0.82671","0.01371"
"1688","10.09200","0.84118","0.01304"
"1717","10.26600","0.85565","0.01296"
"1746","10.44000","0.87018","0.01324"
"1775","10.61400","0.88471","0.01310"
"1804","10.78800","0.89917","0.01327"
"1833","10.96200","0.91370","0.01381"
"1862","11.13600","0.92823","0.01410"
"1891","11.31000","0.94264","0.01421"
"1920","11.48400","0.95723","0.01401"
"1949","11.65800","0.97170","0.01430"
"1978","11.83200","0.98617","0.01420"
"2007","12.00600","1.00076","0.01442"
"2036","12.18000","1.01523","0.01431"
"2065","12.35400","1.02964","0.01483"
"2094","12.52800","1.04416","0.01431"
"2123","12.70200","1.05875","0.01457"
"2152","12.87600","1.07316","0.01489"
"2181","13.05000","1.08769","0.01535"
"2210","13.22400","1.10222","0.01483"
"2239","13.39800","1.11663","0.01480"
"2268","13.57200","1.13122","0.01520"
"2297","13.74600","1.14575","0.01491"
"2326","13.92000","1.16022","0.01538"
"2355","14.09400","1.17469","0.01475"
"2384","14.26800","1.18921","0.01501"
"2413","14.44200","1.20368","0.01464"
"2442","14.61600","1.21815","0.01516"
"2471","14.79000","1.23268","0.01512"
"2500","14.96400","1.24721","0.01502"
"2529","15.13800","1.26168","0.01498"
"2558","15.31200","1.27627","0.01480"
"2587","15.48600","1.29074","0.01353"
"2616","15.66000","1.30515","0.01462"
"2645","15.83400","1.31967","0.01465"
"2674","16.00800","1.33420","0.01372"
"2703","16.18200","1.34867","0.01426"
"2732","16.35600","1.36320","0.01447"
"2761","16.53000","1.37767","0.01428"
"2790","16.70400","1.39214","0.01401"
"2819","16.87800","1.40673","0.01394"
"2848","17.05200","1.42120","0.01412"
"2877","17.22600","1.43567","0.01446"
"2906","17.40000","1.45020","0.01471"
"2935","17.57400","1.46472","0.01455"
"2964","17.74800","1.47913","0.01439"
"2993","17.92200","1.49372","0.01436"
"3022","18.09600","1.50819","0.01451"
"3051","18.27000","1.52266","0.01481"
"3080","18.44400","1.53719","0.01455"
"3109","18.61800","1.55172","0.01468"
"3138","18.79200","1.56613","0.01432"
"3167","18.96600","1.58072","0.01441"
"3196","19.14000","1.59524","0.01488"
"3225","19.31400","1.60965","0.01446"
"3254","19.48800","1.62424","0.01453"
"3283","19.66200","1.63871","0.01512"
"3312","19.83600","1.65318","0.01524"
"3341","20.01000","1.66765","0.01474"
"3370","20.18400","1.68230","0.01446"
"3399","20.35800","1.69671","0.01517"
"3428","20.53200","1.71118","0.01482"
"3457","20.70600","1.72571","0.01494"
"3486","20.88000","1.74017","0.01482"
"3515","21.05400","1.75470","0.01487"
"3544","21.22800","1.76923","0.01471"
"3573","21.40200","1.78364","0.01497"
"3602","21.57600","1.79811","0.01479"
"3631","21.75000","1.81270","0.01487"
"3660","21.92400","1.82723","0.01538"
"3689","22.09800","1.84170","0.01510"
"3718","22.27200","1.85623","0.01525"
"3747","22.44600","1.87069","0.01494"
"3776","22.62000","1.88516","0.01458"
"3805","22.79400","1.89975","0.01522"
"3834","22.96800","1.91422","0.01532"
"3863","23.14200","1.92863","0.01523"
"3892","23.31600","1.94322","0.01585"
"3921","23.49000","1.95775","0.01523"
"3950","23.66400","1.97216","0.01544"
"3979","23.83800","1.98669","0.01507"
"4008","24.01200","2.00122","0.01550"
"4037","24.18600","2.01568","0.01535"
"4066","24.36000","2.03021","0.01566"
"4095","24.53400","2.04474","0.01526"
"4124","24.70800","2.05921","0.01537"
"4153","24.88200","2.07368","0.01542"
"4182","25.05600","2.08821","0.01598"
"4211","25.23000","2.10268","0.01583"
"4240","25.40400","2.11715","0.01607"
"4269","25.57800","2.13174","0.01573"
"4298","25.75200","2.14615","0.01581"
"4327","25.92600","2.16067","0.01589"
"4356","26.10000","2.17514","0.01677"
"4385","26.27400","2.18961","0.01582"
"4414","26.44800","2.20420","0.01661"
"4443","26.62200","2.21873","0.01637"
"4472","26.79600","2.23326","0.01625"
"4501","26.97000","2.24773","0.01604"
"4530","27.14400","2.26220","0.01653"
"4559","27.31800","2.27667","0.01627"
"4588","27.49200","2.29119","0.01644"
"4617","27.66600","2.30572","0.01685"
"4646","27.84000","2.32025","0.01662"
"4675","28.01400","2.33460","0.01642"
"4704","28.18800","2.34925","0.01680"
"4733","28.36200","2.36372","0.01651"
"4762","28.53600","2.37819","0.01668"
"4791","28.71000","2.39272","0.01675"
"4820","28.88400","2.40719","0.01703"
"4849","29.05800","2.42166","0.01737"
"4878","29.23200","2.43624","0.01713"
"4907","29.40600","2.45071","0.01710"
"4936","29.58000","2.46518","0.01748"
"4965","29.75400","2.47971","0.01737"
"4994","29.92800","2.49424","0.01749"
"5023","30.10200","2.50865","0.01723"
"5052","30.27600","2.52318","0.01748"
"5081","30.45000","2.53771","0.01719"
"5110","30.62400","2.55218","0.01760"
"5139","30.79800","2.56670","0.01772"
"5168","30.97200","2.58123","0.01758"
"5197","31.14600","2.59564","0.01766"
"5226","31.32000","2.61017","0.01805"
"5255","31.49400","2.62470","0.01765"
"5284","31.66800","2.63923","0.01787"
"5313","31.84200","2.65370","0.01812"
"5342","32.01600","2.66817","0.01858"
"5371","32.19000","2.68270","0.01843"
"5400","32.36400","2.69717","0.01843"
"5429","32.53800","2.71175","0.01775"
"5458","32.71200","2.72616","0.01883"
"5487","32.88600","2.74063","0.01848"
"5516","33.06000","2.75516","0.01898"
"5545","33.23400","2.76969","0.01942"
"5574","33.40800","2.78416","0.01955"
"5603","33.58200","2.79869","0.01888"
"5632","33.75600","2.81322","0.01927"
"5661","33.93000","2.82763","0.01919"
"5690","34.10400","2.84222","0.01935"
"5719","34.27800","2.85668","0.02018"
"5748","34.45200","2.87115","0.02024"
"5777","34.62600","2.88568","0.01989"
"5806","34.80000","2.90021","0.01996"
"5835","34.97400","2.91468","0.02077"
"5864","35.14800","2.92921","0.02063"
"5893","35.32200","2.94374","0.02146"
"5922","35.49600","2.95815","0.02087"
"5951","35.67000","2.97274","0.02133"
"5980","35.84400","2.98726","0.02139"
"6009","36.01800","3.00167","0.02197"
"6038","36.19200","3.01620","0.02223"
"6067","36.36600","3.03067","0.02207"
"6096","36.54000","3.04520","0.02261"
"6125","36.71400","3.05967","0.02304"
"6154","36.88800","3.07426","0.02319"
"6183","37.06200","3.08867","0.02287"
"6212","37.23600","3.10320","0.02392"
"6241","37.41000","3.11773","0.02360"
"6270","37.58400","3.13219","0.02380"
"6299","37.75800","3.14672","0.02463"
"6328","37.93200","3.16119","0.02570"
"6357","38.10600","3.17572","0.02553"
"6386","38.28000","3.19019","0.02580"
"6415","38.45400","3.20472","0.02525"
"6444","38.62800","3.21919","0.02655"
"6473","38.80200","3.23366","0.02634"
"6502","38.97600","3.24819","0.02741"
"6531","39.15000","3.26271","0.02821"
"6560","39.32400","3.27718","0.02894"
"6589","39.49800","3.29171","0.02933"
"6618","39.67200","3.30618","0.02921"
"6647","39.84600","3.32071","0.03068"
"6676","40.02000","3.33524","0.03100"
"6705","40.19400","3.34971","0.03160"
"6734","40.36800","3.36412","0.03338"
"6763","40.54200","3.37877","0.03346"
"6792","40.71600","3.39330","0.03422"
"6821","40.89000","3.40764","0.03486"
"6850","41.06400","3.42223","0.03550"
"6879","41.23800","3.43670","0.03653"
"6908","41.41200","3.45117","0.03663"
"6937","41.58600","3.46564","0.03784"
"6966","41.76000","3.48017","0.03868"
"6995","41.93400","3.49464","0.03910"
"7024","42.10800","3.50917","0.04045"
"7053","42.28200","3.52370","0.04092"
"7082","42.45600","3.53817","0.04192"
"7111","42.63000","3.55269","0.04231"
"7140","42.80400","3.56722","0.04359"
"7169","42.97800","3.58169","0.04376"
"7198","43.15200","3.59616","0.04364"
"7227","43.32600","3.61069","0.04445"
"7256","43.50000","3.62516","0.04480"
"7285","43.67400","3.63969","0.04611"
"7314","43.84800","3.65422","0.04642"
"7343","44.02200","3.66875","0.04726"
"7372","44.19600","3.68315","0.04834"
"7401","44.37000","3.69768","0.04881"
"7430","44.54400","3.71221","0.05031"
"7459","44.71800","3.72668","0.05048"
"7488","44.89200","3.74121","0.05104"
"7517","45.06600","3.75568","0.05168"
"7546","45.24000","3.77015","0.05293"
"7575","45.41400","3.78474","0.05283"
"7604","45.58800","3.79927","0.05368"
"7633","45.76200","3.81362","0.05331"
"7662","45.93600","3.82826","0.05411"
"7691","46.11000","3.84267","0.05451"
"7720","46.28400","3.85714","0.05509"
"7749","46.45800","3.87167","0.05456"
"7778","46.63200","3.88620","0.04771"
"7807","46.80600","3.90067","0.01674"
"7836","46.98000","3.91514","0.01749"
"7865","47.15400","3.92973","0.01711"
"7894","47.32800","3.94420","0.01756"
"7923","47.50200","3.95866","0.01811"
"7952","47.67600","3.97319","0.01778"
"7981","47.85000","3.98766","0.01818"
"8010","48.02400","4.00219","0.01826"
"8039","48.19800","4.01678","0.01844"
"8068","48.37200","4.03113","0.01820"
"8097","48.54600","4.04566","0.01824"
"8126","48.72000","4.06019","0.01790"
"8155","48.89400","4.07472","0.01887"
"8184","49.06800","4.08919","0.01805"
"8213","49.24200","4.10371","0.01835"
"8242","49.41600","4.11818","0.01874"
"8271","49.59000","4.13271","0.01827"
"8300","49.76400","4.14724","0.01801"
"8329","49.93800","4.16171","0.01888"
"8358","50.11200","4.17618","0.01813"
"8387","50.28600","4.19071","0.01728"
"8416","50.46000","4.20524","0.01785"
"8445","50.63400","4.21971","0.01806"
"8474","50.80800","4.23423","0.01775"
"8503","50.98200","4.24864","0.01828"
"8532","51.15600","4.26317","0.01803"
"8561","51.33000","4.27776","0.01822"
"8590","51.50400","4.29217","0.01812"
"8619","51.67800","4.30664","0.01804"
"8648","51.85200","4.32117","0.01808"
"8677","52.02600","4.33570","0.01824"
"8706","52.20000","4.35017","0.01817"
"8735","52.37400","4.36470","0.01858"
"8764","52.54800","4.37922","0.01847"
"8793","52.72200","4.39363","0.01788"
"8822","52.89600","4.40828","0.01804"
"8851","53.07000","4.42269","0.01836"
"8880","53.24400","4.43716","0.01818"
"8909","53.41800","4.45169","0.01864"
"8938","53.59200","4.46622","0.01859"
"8967","53.76600","4.48069","0.01844"
"8996","53.94000","4.49522","0.01838"
"9025","54.11400","4.50975","0.01839"
"9054","54.28800","4.52421","0.01866"
"9083","54.46200","4.53868","0.01871"
"9112","54.63600","4.55321","0.01926"
"9141","54.81000","4.56768","0.01865"
"9170","54.98400","4.58215","0.01862"
"9199","55.15800","4.59674","0.01869"
"9228","55.33200","4.61121","0.01868"
"9257","55.50600","4.62568","0.01867"
"9286","55.68000","4.64021","0.01896"
"9315","55.85400","4.65468","0.01881"
"9344","56.02800","4.66920","0.01910"
"9373","56.20200","4.68373","0.01919"
"9402","56.37600","4.69820","0.01903"
"9431","56.55000","4.71267","0.01974"
"9460","56.72400","4.72720","0.01963"
"9489","56.89800","4.74173","0.01986"
"9518","57.07200","4.75620","0.01910"
"9547","57.24600","4.77073","0.01941"
"9576","57.42000","4.78520","0.01924"
"9605","57.59400","4.79960","0.01954"
"9634","57.76800","4.81419","0.01979"
"9663","57.94200","4.82866","0.01944"
"9692","58.11600","4.84313","0.01972"
"9721","58.29000","4.85772","0.01966"
"9750","58.46400","4.87219","0.01978"
"9779","58.63800","4.88672","0.02022"
"9808","58.81200","4.90125","0.02010"
"9837","58.98600","4.91572","0.02054"
"9866","59.16000","4.93018","0.01950"
"9895","59.33400","4.94471","0.01988"
"9924","59.50800","4.95924","0.02040"
"9953","59.68200","4.97365","0.02046"
"9982","59.85600","4.98818","0.02003"
"10011","60.03000","5.00271","0.02045"
"10040","60.20400","5.01718","0.02014"
"10069","60.37800","5.03171","0.02055"
"10098","60.55200","5.04624","0.02050"
"10127","60.72600","5.06065","0.02028"
"10156","60.90000","5.07523","0.02097"
"10185","61.07400","5.08970","0.02071"
"10214","61.24800","5.10423","0.02034"
"10243","61.42200","5.11870","0.02052"
"10272","61.59600","5.13323","0.02005"
"10301","61.77000","5.14770","0.02055"
"10330","61.94400","5.16217","0.02013"
"10359","62.11800","5.17670","0.02054"
"10388","62.29200","5.19123","0.02065"
"10417","62.46600","5.20564","0.02067"
"10446","62.64000","5.22022","0.02068"
"10475","62.81400","5.23475","0.02061"
"10504","62.98800","5.24916","0.02079"
"10533","63.16200","5.26375","0.02053"
"10562","63.33600","5.27822","0.02147"
"10591","63.51000","5.29269","0.02113"
"10620","63.68400","5.30722","0.02077"
"10649","63.85800","5.32169","0.02070"
"10678","64.03200","5.33610","0.02114"
"10707","64.20600","5.35069","0.02115"
"10736","64.38000","5.36527","0.02119"
"10765","64.55400","5.37962","0.02120"
"10794","64.72800","5.39421","0.02118"
"10823","64.90200","5.40868","0.02149"
"10852","65.07600","5.42321","0.02176"
"10881","65.25000","5.43774","0.02170"
"10910","65.42400","5.45227","0.02178"
"10939","65.59800","5.46674","0.02157"
"10968","65.77200","5.48121","0.02207"
"10997","65.94600","5.49573","0.02212"
"11026","66.12000","5.51020","0.02189"
"11055","66.29400","5.52473","0.02233"
"11084","66.46800","5.53920","0.02249"
"11113","66.64200","5.55367","0.02267"
"11142","66.81600","5.56820","0.02291"
"11171","66.99000","5.58273","0.02285"
"11200","67.16400","5.59720","0.02314"
"11229","67.33800","5.61167","0.02314"
"11258","67.51200","5.62619","0.02325"
"11287","67.68600","5.64072","0.02315"
"11316","67.86000","5.65519","0.02378"
"11345","68.03400","5.66972","0.02386"
"11374","68.20800","5.68413","0.02466"
"11403","68.38200","5.69866","0.02416"
"11432","68.55600","5.71325","0.02462"
"11461","68.73000","5.72766","0.02465"
"11490","68.90400","5.74219","0.02487"
"11519","69.07800","5.75672","0.02491"
"11548","69.25200","5.77118","0.02492"
"11577","69.42600","5.78565","0.02553"
"11606","69.60000","5.80024","0.02568"
"11635","69.77400","5.81477","0.02472"
"11664","69.94800","5.82918","0.02502"
"11693","70.12200","5.84377","0.02577"
"11722","70.29600","5.85824","0.02634"
"11751","70.47000","5.87259","0.02653"
"11780","70.64400","5.88718","0.02611"
"11809","70.81800","5.90170","0.02645"
"11838","70.99200","5.91617","0.02726"
"11867","71.16600","5.93070","0.02748"
"11896","71.34000","5.94523","0.02787"
"11925","71.51400","5.95970","0.02815"
"11954","71.68800","5.97423","0.02950"
"11983","71.86200","5.98876","0.02959"
"12012","72.03600","6.00317","0.03014"
"12041","72.21000","6.01770","0.03032"
"12070","72.38400","6.03223","0.03036"
"12099","72.55800","6.04670","0.03069"
"12128","72.73200","6.06116","0.03058"
"12157","72.90600","6.07569","0.03193"
"12186","73.08000","6.09016","0.03152"
"12215","73.25400","6.10475","0.03291"
"12244","73.42800","6.11922","0.03339"
"12273","73.60200","6.13375","0.03332"
"12302","73.77600","6.14822","0.03232"
"12331","73.95000","6.16269","0.03329"
"12360","74.12400","6.17722","0.03311"
"12389","74.29800","6.19168","0.03447"
"12418","74.47200","6.20621","0.03515"
"12447","74.64600","6.22074","0.03639"
"12476","74.82000","6.23509","0.03508"
"12505","74.99400","6.24974","0.03579"
"12534","75.16800","6.26421","0.03647"
"12563","75.34200","6.27862","0.03730"
"12592","75.51600","6.29321","0.03758"
"12621","75.69000","6.30768","0.03869"
"12650","75.86400","6.32220","0.03926"
"12679","76.03800","6.33673","0.03973"
"12708","76.21200","6.35120","0.03685"
"12737","76.38600","6.36567","0.03151"
"12766","76.56000","6.38020","0.03249"
"12795","76.73400","6.39473","0.03360"
"12824","76.90800","6.40914","0.03318"
"12853","77.08200","6.42367","0.03400"
"12882","77.25600","6.43820","0.03355"
"12911","77.43000","6.45267","0.03329"
"12940","77.60400","6.46719","0.03383"
"12969","77.77800","6.48172","0.03454"
"12998","77.95200","6.49619","0.03538"
"13027","78.12600","6.51072","0.03367"
"13056","78.30000","6.52519","0.03462"
"13085","78.47400","6.53972","0.03348"
"13114","78.64800","6.55419","0.03188"
"13143","78.82200","6.56872","0.03173"
"13172","78.99600","6.58319","0.03272"
"13201","79.17000","6.59766","0.03353"
"13230","79.34400","6.61218","0.03393"
"13259","79.51800","6.62665","0.03400"
"13288","79.69200","6.64112","0.03447"
"13317","79.86600","6.65577","0.03500"
"13346","80.04000","6.67024","0.03553"
"13375","80.21400","6.68465","0.03629"
"13404","80.38800","6.69924","0.03557"
"13433","80.56200","6.71371","0.03631"
"13462","80.73600","6.72818","0.03707"
"13491","80.91000","6.74276","0.03631"
"13520","81.08400","6.75723","0.03667"
"13549","81.25800","6.77164","0.03807"
"13578","81.43200","6.78617","0.03742"
"13607","81.60600","6.80076","0.03819"
"13636","81.78000","6.81517","0.03874"
"13665","81.95400","6.82970","0.03872"
"13694","82.12800","6.84423","0.03766"
"13723","82.30200","6.85870","0.02859"
"13752","82.47600","6.87317","0.02821"
"13781","82.65000","6.88775","0.02822"
"13810","82.82400","6.90222","0.02796"
"13839","82.99800","6.91675","0.02722"
"13868","83.17200","6.93122","0.02744"
"13897","83.34600","6.94569","0.02777"
"13926","83.52000","6.96016","0.02945"
"13955","83.69400","6.97469","0.02888"
"13984","83.86800","6.98922","0.02503"
"14013","84.04200","7.00375","0.02450"
"14042","84.21600","7.01827","0.02425"
"14071","84.39000","7.03268","0.02404"
"14100","84.56400","7.04715","0.02530"
"14129","84.73800","7.06168","0.02497"
"14158","84.91200","7.07621","0.02525"
"14187","85.08600","7.09068","0.02513"
"14216","85.26000","7.10515","0.02552"
"14245","85.43400","7.11968","0.02596"
"14274","85.60800","7.13415","0.02589"
"14303","85.78200","7.14874","0.02606"
"14332","85.95600","7.16320","0.02615"
"14361","86.13000","7.17767","0.02654"
"14390","86.30400","7.19220","0.02604"
"14419","86.47800","7.20673","0.02560"
"14448","86.65200","7.22114","0.02640"
"14477","86.82600","7.23573","0.02540"
"14506","87.00000","7.25020","0.02581"
"14535","87.17400","7.26467","0.02567"
"14564","87.34800","7.27926","0.02563"
"14593","87.52200","7.29373","0.02551"
"14622","87.69600","7.30814","0.02609"
"14651","87.87000","7.32272","0.02458"
"14680","88.04400","7.33725","0.02433"
"14709","88.21800","7.35166","0.02355"
"14738","88.39200","7.36625","0.02299"
"14767","88.56600","7.38072","0.02325"
"14796","88.74000","7.39519","0.02337"
"14825","88.91400","7.40972","0.02338"
"14854","89.08800","7.42425","0.02290"
"14883","89.26200","7.43871","0.02321"
"14912","89.43600","7.45312","0.02332"
"14941","89.61000","7.46771","0.02396"
"14970","89.78400","7.48212","0.02419"
"14999","89.95800","7.49665","0.02421"
"15028","90.13200","7.51118","0.02383"
"15057","90.30600","7.52571","0.02403"
"15086","90.48000","7.54018","0.02444"
"15115","90.65400","7.55471","0.02482"
"15144","90.82800","7.56918","0.02411"
"15173","91.00200","7.58370","0.02473"
"15202","91.17600","7.59817","0.02425"
"15231","91.35000","7.61276","0.02488"
"15260","91.52400","7.62723","0.02561"
"15289","91.69800","7.64170","0.02559"
"15318","91.87200","7.65623","0.02567"
"15347","92.04600","7.67064","0.02551"
"15376","92.22000","7.68529","0.02624"
"15405","92.39400","7.69976","0.02675"
"15434","92.56800","7.71417","0.02701"
"15463","92.74200","7.72869","0.02695"
"15492","92.91600","7.74322","0.02682"
"15521","93.09000","7.75769","0.02696"
"15550","93.26400","7.77222","0.02748"
"15579","93.43800","7.78669","0.02754"
"15608","93.61200","7.80116","0.02731"
"15637","93.78600","7.81575","0.02771"
"15666","93.96000","7.83022","0.02794"
"15695","94.13400","7.84463","0.02829"
"15724","94.30800","7.85927","0.02839"
"15753","94.48200","7.87374","0.02847"
"15782","94.65600","7.88821","0.02837"
"15811","94.83000","7.90268","0.02763"
"15840","95.00400","7.91721","0.02852"
"15869","95.17800","7.93168","0.02759"
"15898","95.35200","7.94621","0.02779"
"15927","95.52600","7.96074","0.02777"
"15956","95.70000","7.97515","0.02792"
"15985","95.87400","7.98974","0.02784"
"16014","96.04800","8.00420","0.02842"
"16043","96.22200","8.01867","0.02873"
"16072","96.39600","8.03320","0.02905"
"16101","96.57000","8.04773","0.02866"
"16130","96.74400","8.06220","0.02860"
"16159","96.91800","8.07667","0.02906"
"16188","97.09200","8.09126","0.02952"
"16217","97.26600","8.10573","0.02900"
"16246","97.44000","8.12008","0.02930"
"16275","97.61400","8.13472","0.02995"
"16304","97.78800","8.14925","0.02938"
"16333","97.96200","8.16366","0.03000"
"16362","98.13600","8.17819","0.02954"
"16391","98.31000","8.19272","0.03053"
"16420","98.48400","8.20713","0.03120"
"16449","98.65800","8.22172","0.03111"
"16478","98.83200","8.23625","0.03162"
"16507","99.00600","8.25066","0.03240"
"16536","99.18000","8.26524","0.03275"
"16565","99.35400","8.27971","0.03238"
"16594","99.52800","8.29418","0.03329"
"16623","99.70200","8.30871","0.03276"
"16652","99.87600","8.32324","0.03318"
"16681","100.05000","8.33771","0.03350"
"16710","100.22400","8.35218","0.03474"
"16739","100.39800","8.36677","0.03463"
"16768","100.57200","8.38118","0.03571"
"16797","100.74600","8.39571","0.03549"
"16826","100.92000","8.41018","0.03561"
"16855","101.09400","8.42470","0.03623"
"16884","101.26800","8.43923","0.03648"
"16913","101.44200","8.45370","0.03664"
"16942","101.61600","8.46823","0.03771"
"16971","101.79000","8.48270","0.03794"
"17000","101.96400","8.49723","0.03839"
"17029","102.13800","8.51170","0.03868"
"17058","102.31200","8.52617","0.03925"
"17087","102.48600","8.54070","0.03967"
"17116","102.66000","8.55516","0.04014"
"17145","102.83400","8.56969","0.04110"
"17174","103.00800","8.58422","0.04065"
"17203","103.18200","8.59869","0.04199"
"17232","103.35600","8.61316","0.04207"
"17261","103.53000","8.62769","0.04288"
"17290","103.70400","8.64222","0.04252"
"17319","103.87800","8.65669","0.04255"
"17348","104.05200","8.67122","0.04343"
"17377","104.22600","8.68569","0.04394"
"17406","104.40000","8.70015","0.04460"
"17435","104.57400","8.71474","0.04480"
"17464","104.74800","8.72921","0.04549"
"17493","104.92200","8.74362","0.04409"
"17522","105.09600","8.75821","0.04447"
"17551","105.27000","8.77274","0.04496"
"17580","105.44400","8.78715","0.04562"
"17609","105.61800","8.80174","0.04544"
"17638","105.79200","8.81621","0.04696"
"17667","105.96600","8.83068","0.04650"
"17696","106.14000","8.84526","0.04754"
"17725","106.31400","8.85973","0.04799"
"17754","106.48800","8.87420","0.04837"
"17783","106.66200","8.88861","0.04849"
"17812","106.83600","8.90320","0.04922"
"17841","107.01000","8.91767","0.04916"
"17870","107.18400","8.93220","0.04947"
"17899","107.35800","8.94679","0.04996"
"17928","107.53200","8.96119","0.05088"
"17957","107.70600","8.97566","0.05108"
"17986","107.88000","8.99025","0.05150"
"18015","108.05400","9.00472","0.05187"
"18044","108.22800","9.01913","0.05187"
"18073","108.40200","9.03372","0.05167"
"18102","108.57600","9.04825","0.05220"
"18131","108.75000","9.06272","0.05313"
"18160","108.92400","9.07719","0.05322"
"18189","109.09800","9.09166","0.05329"
"18218","109.27200","9.10613","0.05412"
"18247","109.44600","9.12077","0.05370"
"18276","109.62000","9.13524","0.05523"
"18305","109.79400","9.14971","0.05508"
"18334","109.96800","9.16424","0.05577"
"18363","110.14200","9.17871","0.05555"
"18392","110.31600","9.19318","0.05530"
"18421","110.49000","9.20765","0.05566"
"18450","110.66400","9.22218","0.05579"
"18479","110.83800","9.23665","0.05630"
"18508","111.01200","9.25117","0.05699"
"18537","111.18600","9.26564","0.05752"
"18566","111.36000","9.28017","0.05743"
"18595","111.53400","9.29470","0.05773"
"18624","111.70800","9.30917","0.05908"
"18653","111.88200","9.32370","0.05932"
"18682","112.05600","9.33823","0.05969"
"18711","112.23000","9.35270","0.06031"
"18740","112.40400","9.36711","0.06044"
"18769","112.57800","9.38175","0.06120"
"18798","112.75200","9.39628","0.06199"
"18827","112.92600","9.41069","0.06176"
"18856","113.10000","9.42522","0.06282"
"18885","113.27400","9.43969","0.06290"
"18914","113.44800","9.45416","0.06378"
"18943","113.62200","9.46869","0.06468"
"18972","113.79600","9.48322","0.06472"
"19001","113.97000","9.49769","0.06526"
"19030","114.14400","9.51216","0.06599"
"19059","114.31800","9.52680","0.06626"
"19088","114.49200","9.54121","0.06647"
"19117","114.66600","9.55568","0.06675"
"19146","114.84000","9.57021","0.06785"
"19175","115.01400","9.58468","0.06818"
"19204","115.18800","9.59921","0.06844"
"19233","115.36200","9.61374","0.06860"
"19262","115.53600","9.62821","0.06941"
"19291","115.71000","9.64262","0.06966"
"19320","115.88400","9.65720","0.07052"
"19349","116.05800","9.67173","0.07092"
"19378","116.23200","9.68614","0.07103"
"19407","116.40600","9.70067","0.07177"
"19436","116.58000","9.71520","0.07199"
"19465","116.75400","9.72973","0.07256"
"19494","116.92800","9.74420","0.07304"
"19523","117.10200","9.75879","0.07332"
"19552","117.27600","9.77314","0.07363"
"19581","117.45000","9.78773","0.07388"
"19610","117.62400","9.80225","0.07435"
"19639","117.79800","9.81666","0.07453"
"19668","117.97200","9.83119","0.07532"
"19697","118.14600","9.84566","0.07514"
"19726","118.32000","9.86019","0.07543"
"19755","118.49400","9.87466","0.07585"
"19784","118.66800","9.88925","0.07662"
"19813","118.84200","9.90372","0.07659"
"19842","119.01600","9.91819","0.07680"
"19871","119.19000","9.93271","0.07746"
"19900","119.36400","9.94718","0.07742"
"19929","119.53800","9.96171","0.07825"
"19958","119.71200","9.97618","0.07797"
"19987","119.88600","9.99071","0.07815"
"20016","120.06000","10.00518","0.07832"
"20045","120.23400","10.01971","0.07861"
"20074","120.40800","10.03412","0.07897"
"20103","120.58200","10.04865","0.07879"
"20132","120.75600","10.06324","0.07918"
"20161","120.93000","10.07777","0.07979"
"20190","121.10400","10.09217","0.07986"
"20219","121.27800","10.10670","0.07997"
"20248","121.45200","10.12123","0.08014"
"20277","121.62600","10.13564","0.08064"
"20306","121.80000","10.15029","0.08090"
"20335","121.97400","10.16470","0.08103"
"20364","122.14800","10.17917","0.08139"
"20393","122.32200","10.19370","0.08163"
"20422","122.49600","10.20823","0.08163"
"20451","122.67000","10.22269","0.08157"
"20480","122.84400","10.23722","0.08176"
"20509","123.01800","10.25175","0.08211"
"20538","123.19200","10.26616","0.08254"
"20567","123.36600","10.28069","0.08277"
"20596","123.54000","10.29522","0.08280"
"20625","123.71400","10.30963","0.08342"
"20654","123.88800","10.32416","0.08387"
"20683","124.06200","10.33875","0.08375"
"20712","124.23600","10.35316","0.08448"
"20741","124.41000","10.36762","0.08445"
"20770","124.58400","10.38221","0.08506"
"20799","124.75800","10.39662","0.08511"
"20828","124.93200","10.41121","0.08555"
"20857","125.10600","10.42574","0.08608"
"20886","125.28000","10.44021","0.08625"
"20915","125.45400","10.45468","0.08658"
"20944","125.62800","10.46921","0.08662"
"20973","125.80200","10.48374","0.08774"
"21002","125.97600","10.49820","0.08785"
"21031","126.15000","10.51267","0.08863"
"21060","126.32400","10.52720","0.08910"
"21089","126.49800","10.54167","0.09017"
"21118","126.67200","10.55620","0.08990"
"21147","126.84600","10.57073","0.09065"
"21176","127.02000","10.58520","0.09114"
"21205","127.19400","10.59973","0.09143"
"21234","127.36800","10.61426","0.09221"
"21263","127.54200","10.62872","0.09288"
"21292","127.71600","10.64319","0.09345"
"21321","127.89000","10.65772","0.09368"
"21350","128.06400","10.67219","0.09360"
"21379","128.23800","10.68672","0.09461"
"21408","128.41200","10.70119","0.09435"
"21437","128.58600","10.71566","0.03822"
"21466","128.76000","10.73019","0.02824"
"21495","128.93400","10.74472","0.02924"
"21524","129.10800","10.75919","0.02722"
"21553","129.28200","10.77372","0.02895"
"21582","129.45600","10.78818","0.03358"
"21611","129.63000","10.80265","0.03060"
"21640","129.80400","10.81724","0.03244"
"21669","129.97800","10.83171","0.03750"
"21698","130.15200","10.84618","0.03211"
"21727","130.32600","10.86071","0.03289"
"21756","130.50000","10.87524","0.03851"
"21785","130.67400","10.88971","0.03506"
"21814","130.84800","10.90418","0.03708"
"21843","131.02200","10.91870","0.04191"
"21872","131.19600","10.93317","0.03710"
"21901","131.37000","10.94764","0.03938"
"21930","131.54400","10.96223","0.04331"
"21959","131.71800","10.97670","0.03954"
"21988","131.89200","10.99117","0.04229"
"22017","132.06600","11.00570","0.04512"
"22046","132.24000","11.02023","0.04161"
"22075","132.41400","11.03470","0.04390"
"22104","132.58800","11.04923","0.04639"
"22133","132.76200","11.06369","0.04318"
"22162","132.93600","11.07816","0.04596"
"22191","133.11000","11.09275","0.04768"
"22220","133.28400","11.10722","0.04591"
"22249","133.45800","11.12169","0.04819"
"22278","133.63200","11.13622","0.04886"
"22307","133.80600","11.15069","0.04645"
"22336","133.98000","11.16516","0.04949"
"22365","134.15400","11.17969","0.04996"
"22394","134.32800","11.19421","0.04923"
"22423","134.50200","11.20868","0.05193"
"22452","134.67600","11.22321","0.05084"
"22481","134.85000","11.23774","0.05138"
"22510","135.02400","11.25221","0.05390"
"22539","135.19800","11.26674","0.05254"
"22568","135.37200","11.28121","0.05349"
"22597","135.54600","11.29568","0.05517"
"22626","135.72000","11.31021","0.05344"
"22655","135.89400","11.32473","0.05546"
"22684","136.06800","11.33921","0.05701"
"22713","136.24200","11.35367","0.05671"
"22742","136.41600","11.36820","0.05766"
"22771","136.59000","11.38267","0.05852"
"22800","136.76400","11.39714","0.05812"
"22829","136.93800","11.41167","0.06032"
"22858","137.11200","11.42620","0.05979"
"22887","137.28600","11.44073","0.06025"
"22916","137.46000","11.45520","0.06269"
"22945","137.63400","11.46967","0.06186"
"22974","137.80800","11.48419","0.06273"
"23003","137.98200","11.49872","0.06308"
"23032","138.15600","11.51325","0.06094"
"23061","138.33000","11.52772","0.04815"
"23090","138.50400","11.54219","0.04266"
"23119","138.67800","11.55672","0.04139"
"23148","138.85200","11.57119","0.04246"
"23177","139.02600","11.58578","0.04174"
"23206","139.20000","11.60019","0.04195"
"23235","139.37400","11.61466","0.04358"
"23264","139.54800","11.62924","0.04384"
"23293","139.72200","11.64371","0.04327"
"23322","139.89600","11.65812","0.04302"
"23351","140.07000","11.67271","0.04231"
"23380","140.24400","11.68724","0.04177"
"23409","140.41800","11.70165","0.04529"
"23438","140.59200","11.71624","0.04248"
"23467","140.76600","11.73071","0.04336"
"23496","140.94000","11.74518","0.04399"
"23525","141.11400","11.75964","0.04315"
"23554","141.28800","11.77423","0.04331"
"23583","141.46200","11.78870","0.04444"
"23612","141.63600","11.80317","0.04345"
"23641","141.81000","11.81776","0.04435"
"23670","141.98400","11.83217","0.04545"
"23699","142.15800","11.84670","0.04515"
"23728","142.33200","11.86123","0.04575"
"23757","142.50600","11.87570","0.04658"
"23786","142.68000","11.89017","0.04595"
"23815","142.85400","11.90469","0.04722"
"23844","143.02800","11.91922","0.04715"
"23873","143.20200","11.93369","0.04675"
"23902","143.37600","11.94822","0.04745"
"23931","143.55000","11.96269","0.04716"
"23960","143.72400","11.97716","0.04776"
"23989","143.89800","11.99169","0.04752"
"24018","144.07200","12.00622","0.04817"
"24047","144.24600","12.02063","0.04727"
"24076","144.42000","12.03522","0.04796"
"24105","144.59400","12.04974","0.04836"
"24134","144.76800","12.06421","0.04969"
"24163","144.94200","12.07874","0.04973"
"24192","145.11600","12.09321","0.04939"
"24221","145.29000","12.10768","0.05000"
"24250","145.46400","12.12227","0.05036"
"24279","145.63800","12.13668","0.05077"
"24308","145.81200","12.15115","0.05046"
"24337","145.98600","12.16568","0.05076"
"24366","146.16000","12.18020","0.05086"
"24395","146.33400","12.19467","0.05215"
"24424","146.50800","12.20920","0.05106"
"24453","146.68200","12.22373","0.05146"
"24482","146.85600","12.23814","0.05142"
"24511","147.03000","12.25273","0.04424"
"24540","147.20400","12.26720","0.04506"
"24569","147.37800","12.28167","0.04462"
"24598","147.55200","12.29626","0.02283"
"24627","147.72600","12.31072","0.02507"
"24656","147.90000","12.32519","0.02711"
"24685","148.07400","12.33972","0.02292"
"24714","148.24800","12.35419","0.02587"
"24743","148.42200","12.36866","0.02535"
"24772","148.59600","12.38319","0.02459"
"24801","148.77000","12.39772","0.02441"
"24830","148.94400","12.41219","0.02478"
"24859","149.11800","12.42660","0.02359"
"24888","149.29200","12.44118","0.02623"
"24917","149.46600","12.45571","0.02640"
"24946","149.64000","12.47018","0.02464"
"24975","149.81400","12.48471","0.02532"
"25004","149.98800","12.49918","0.02889"
"25033","150.16200","12.51365","0.02651"
"25062","150.33600","12.52824","0.02600"
"25091","150.51000","12.54271","0.02822"
"25120","150.68400","12.55712","0.02842"
"25149","150.85800","12.57171","0.02808"
"25178","151.03200","12.58623","0.02909"
"25207","151.20600","12.60064","0.02894"
"25236","151.38000","12.61523","0.02938"
"25265","151.55400","12.62976","0.03228"
"25294","151.72800","12.64417","0.03067"
"25323","151.90200","12.65870","0.02978"
"25352","152.07600","12.67329","0.03419"
"25381","152.25000","12.68764","0.03288"
"25410","152.42400","12.70217","0.03272"
"25439","152.59800","12.71670","0.03436"
"25468","152.77200","12.73123","0.03627"
"25497","152.94600","12.74575","0.03437"
"25526","153.12000","12.76022","0.03549"
"25555","153.29400","12.77469","0.03705"
"25584","153.46800","12.78916","0.03683"
"25613","153.64200","12.80375","0.03807"
"25642","153.81600","12.81822","0.03986"
"25671","153.99000","12.83263","0.04079"
"25700","154.16400","12.84716","0.04035"
"25729","154.33800","12.86169","0.04223"
"25758","154.51200","12.87621","0.04260"
"25787","154.68600","12.89068","0.04281"
"25816","154.86000","12.90515","0.04395"
"25845","155.03400","12.91968","0.04520"
"25874","155.20800","12.93421","0.04526"
"25903","155.38200","12.94868","0.04615"
"25932","155.55600","12.96321","0.04750"
"25961","155.73000","12.97768","0.04787"
"25990","155.90400","12.99221","0.04916"
"26019","156.07800","13.00667","0.04939"
"26048","156.25200","13.02126","0.05041"
"26077","156.42600","13.03567","0.05022"
"26106","156.60000","13.05008","0.05105"
"26135","156.77400","13.06473","0.05218"
"26164","156.94800","13.07926","0.05295"
"26193","157.12200","13.09361","0.05321"
"26222","157.29600","13.10820","0.05470"
"26251","157.47000","13.12273","0.05499"
"26280","157.64400","13.13714","0.05551"
"26309","157.81800","13.15172","0.05631"
"26338","157.99200","13.16625","0.05772"
"26367","158.16600","13.18066","0.05807"
"26396","158.34000","13.19519","0.05867"
"26425","158.51400","13.20972","0.06093"
"26454","158.68800","13.22419","0.06086"
"26483","158.86200","13.23872","0.06218"
"26512","159.03600","13.25325","0.06407"
"26541","159.21000","13.26766","0.06466"
"26570","159.38400","13.28219","0.06464"
"26599","159.55800","13.29671","0.06613"
"26628","159.73200","13.31118","0.06638"
"26657","159.90600","13.32565","0.06646"
"26686","160.08000","13.34024","0.06830"
"26715","160.25400","13.35471","0.06887"
"26744","160.42800","13.36918","0.06916"
"26773","160.60200","13.38371","0.07097"
"26802","160.77600","13.39818","0.07099"
"26831","160.95000","13.41271","0.07168"
"26860","161.12400","13.42724","0.07338"
"26889","161.29800","13.44170","0.07288"
"26918","161.47200","13.45617","0.07347"
"26947","161.64600","13.47070","0.07440"
"26976","161.82000","13.48523","0.07475"
"27005","161.99400","13.49964","0.07531"
"27034","162.16800","13.51423","0.07587"
"27063","162.34200","13.52870","0.07612"
"27092","162.51600","13.54317","0.07675"
"27121","162.69000","13.55770","0.07770"
"27150","162.86400","13.57216","0.07788"
"27179","163.03800","13.58669","0.07810"
"27208","163.21200","13.60122","0.07879"
"27237","163.38600","13.61575","0.07902"
"27266","163.56000","13.63022","0.07943"
"27295","163.73400","13.64469","0.07974"
"27324","163.90800","13.65922","0.07992"
"27353","164.08200","13.67369","0.08014"
"27382","164.25600","13.68822","0.08064"
"27411","164.43000","13.70274","0.08088"
"27440","164.60400","13.71715","0.08123"
"27469","164.77800","13.73168","0.08130"
"27498","164.95200","13.74621","0.08192"
"27527","165.12600","13.76068","0.08222"
"27556","165.30000","13.77515","0.08262"
"27585","165.47400","13.78974","0.08295"
"27614","165.64800","13.80415","0.08325"
"27643","165.82200","13.81874","0.08357"
"27672","165.99600","13.83321","0.08426"
"27701","166.17000","13.84768","0.08435"
"27730","166.34400","13.86214","0.08498"
"27759","166.51800","13.87673","0.08517"
"27788","166.69200","13.89120","0.08554"
"27817","166.86600","13.90567","0.08635"
"27846","167.04000","13.92020","0.08683"
"27875","167.21400","13.93467","0.08724"
"27904","167.38800","13.94920","0.08821"
"27933","167.56200","13.96373","0.08814"
"27962","167.73600","13.97826","0.08749"
"27991","167.91000","13.99266","0.08781"
"28020","168.08400","14.00719","0.08731"
"28049","168.25800","14.02172","0.08746"
"28078","168.43200","14.03619","0.08861"
"28107","168.60600","14.05072","0.08869"
"28136","168.78000","14.06525","0.08932"
"28165","168.95400","14.07966","0.08972"
"28194","169.12800","14.09425","0.08999"
"28223","169.30200","14.10878","0.09049"
"28252","169.47600","14.12313","0.09148"
"28281","169.65000","14.13765","0.09143"
"28310","169.82400","14.15218","0.09249"
"28339","169.99800","14.16671","0.09337"
"28368","170.17200","14.18118","0.09307"
"28397","170.34600","14.19571","0.09502"
"28426","170.52000","14.21018","0.09454"
"28455","170.69400","14.22471","0.09475"
"28484","170.86800","14.23924","0.09497"
"28513","171.04200","14.25371","0.09603"
"28542","171.21600","14.26817","0.09668"
"28571","171.39000","14.28270","0.09762"
"28600","171.56400","14.29717","0.09826"
"28629","171.73800","14.31170","0.09892"
"28658","171.91200","14.32623","0.09942"
"28687","172.08600","14.34070","0.10009"
"28716","172.26000","14.35517","0.10055"
"28745","172.43400","14.36970","0.10135"
"28774","172.60800","14.38417","0.10154"
"28803","172.78200","14.39863","0.10218"
"28832","172.95600","14.41317","0.10237"
"28861","173.13000","14.42775","0.10354"
"28890","173.30400","14.44222","0.10357"
"28919","173.47800","14.45675","0.02284"
"28948","173.65200","14.47116","0.01617"
"28977","173.82600","14.48563","0.01491"
"29006","174.00000","14.50022","0.01388"
"29035","174.17400","14.51475","0.01273"
"29064","174.34800","14.52916","0.01808"
"29093","174.52200","14.54374","0.01520"
"29122","174.69600","14.55815","0.01403"
"29151","174.87000","14.57262","0.01639"
"29180","175.04400","14.58721","0.01735"
"29209","175.21800","14.60174","0.01365"
"29238","175.39200","14.61621","0.01637"
"29267","175.56600","14.63068","0.01713"
"29296","175.74000","14.64527","0.01508"
"29325","175.91400","14.65968","0.01410"
"29354","176.08800","14.67421","0.01806"
"29383","176.26200","14.68874","0.01539"
"29412","176.43600","14.70314","0.01440"
"29441","176.61000","14.71773","0.01689"
"29470","176.78400","14.73220","0.01613"
"29499","176.95800","14.74667","0.01606"
"29528","177.13200","14.76114","0.01572"
"29557","177.30600","14.77573","0.01563"
"29586","177.48000","14.79020","0.01545"
"29615","177.65400","14.80467","0.01539"
"29644","177.82800","14.81913","0.01666"
"29673","178.00200","14.83372","0.01536"
"29702","178.17600","14.84819","0.01510"
"29731","178.35000","14.86272","0.01681"
"29760","178.52400","14.87719","0.01501"
"29789","178.69800","14.89166","0.01575"
"29818","178.87200","14.90625","0.01625"
"29847","179.04600","14.92072","0.01557"
"29876","179.22000","14.93519","0.01631"
"29905","179.39400","14.94966","0.01587"
"29934","179.56800","14.96418","0.01533"
"29963","179.74200","14.97865","0.01530"
"29992","179.91600","14.99324","0.01636"
"30021","180.09000","15.00771","0.01657"
"30050","180.26400","15.02212","0.01607"
"30079","180.43800","15.03671","0.01685"
"30108","180.61200","15.05124","0.01610"
"30137","180.78600","15.06571","0.01593"
"30166","180.96000","15.08018","0.01622"
"30195","181.13400","15.09470","0.01644"
"30224","181.30800","15.10917","0.01623"
"30253","181.48200","15.12370","0.01600"
"30282","181.65600","15.13823","0.01633"
"30311","181.83000","15.15264","0.01645"
"30340","182.00400","15.16723","0.01626"
"30369","182.17800","15.18170","0.01651"
"30398","182.35200","15.19617","0.01623"
"30427","182.52600","15.21070","0.01637"
"30456","182.70000","15.22523","0.01639"
"30485","182.87400","15.23970","0.01631"
"30514","183.04800","15.25422","0.01678"
"30543","183.22200","15.26869","0.01636"
"30572","183.39600","15.28322","0.01652"
"30601","183.57000","15.29769","0.01655"
"30630","183.74400","15.31222","0.01625"
"30659","183.91800","15.32675","0.01676"
"30688","184.09200","15.34116","0.01721"
"30717","184.26600","15.35569","0.01690"
"30746","184.44000","15.37016","0.01693"
"30775","184.61400","15.38462","0.01650"
"30804","184.78800","15.39921","0.01671"
"30833","184.96200","15.41374","0.01697"
"30862","185.13600","15.42809","0.01714"
"30891","185.31000","15.44268","0.01738"
"30920","185.48400","15.45721","0.01684"
"30949","185.65800","15.47168","0.01683"
"30978","185.83200","15.48621","0.01666"
"31007","186.00600","15.50074","0.01712"
"31036","186.18000","15.51515","0.01691"
"31065","186.35400","15.52979","0.01728"
"31094","186.52800","15.54426","0.01716"
"31123","186.70200","15.55867","0.01681"
"31152","186.87600","15.57320","0.01699"
"31181","187.05000","15.58767","0.01726"
"31210","187.22400","15.60220","0.01735"
"31239","187.39800","15.61667","0.01694"
"31268","187.57200","15.63120","0.01724"
"31297","187.74600","15.64566","0.01726"
"31326","187.92000","15.66019","0.01722"
"31355","188.09400","15.67472","0.01749"
"31384","188.26800","15.68919","0.01720"
"31413","188.44200","15.70366","0.01728"
"31442","188.61600","15.71819","0.01770"
"31471","188.79000","15.73272","0.01725"
"31500","188.96400","15.74719","0.01715"
"31529","189.13800","15.76172","0.01741"
"31558","189.31200","15.77619","0.01709"
"31587","189.48600","15.79071","0.01719"
"31616","189.66000","15.80524","0.01764"
"31645","189.83400","15.81965","0.01772"
"31674","190.00800","15.83418","0.01741"
"31703","190.18200","15.84865","0.01795"
"31732","190.35600","15.86324","0.01717"
"31761","190.53000","15.87771","0.01763"
"31790","190.70400","15.89218","0.01714"
"31819","190.87800","15.90671","0.01767"
"31848","191.05200","15.92118","0.01760"
"31877","191.22600","15.93570","0.01779"
"31906","191.40000","15.95023","0.01767"
"31935","191.57400","15.96464","0.01794"
"31964","191.74800","15.97923","0.01760"
"31993","191.92200","15.99370","0.01743"
"32022","192.09600","16.00817","0.01809"
"32051","192.27000","16.02276","0.01767"
"32080","192.44400","16.03723","0.01786"
"32109","192.61800","16.05169","0.01798"
"32138","192.79200","16.06623","0.01784"
"32167","192.96600","16.08075","0.01754"
"32196","193.14000","16.09516","0.01761"
"32225","193.31400","16.10969","0.01748"
"32254","193.48800","16.12422","0.01772"
"32283","193.66200","16.13869","0.01780"
"32312","193.83600","16.15322","0.01781"
"32341","194.01000","16.16775","0.01770"
"32370","194.18400","16.18216","0.01757"
"32399","194.35800","16.19669","0.01800"
"32428","194.53200","16.21121","0.01756"
"32457","194.70600","16.22568","0.01803"
"32486","194.88000","16.24015","0.01776"
"32515","195.05400","16.25462","0.01817"
"32544","195.22800","16.26915","0.01740"
"32573","195.40200","16.28368","0.01781"
"32602","195.57600","16.29821","0.01825"
"32631","195.75000","16.31268","0.01813"
"32660","195.92400","16.32715","0.01756"
"32689","196.09800","16.34173","0.01785"
"32718","196.27200","16.35620","0.01826"
"32747","196.44600","16.37067","0.01830"
"32776","196.62000","16.38526","0.01762"
"32805","196.79400","16.39973","0.01821"
"32834","196.96800","16.41420","0.01800"
"32863","197.14200","16.42879","0.01853"
"32892","197.31600","16.44320","0.01748"
"32921","197.49000","16.45767","0.01779"
"32950","197.66400","16.47220","0.01810"
"32979","197.83800","16.48672","0.01814"
"33008","198.01200","16.50119","0.01844"
"33037","198.18600","16.51566","0.01800"
"33066","198.36000","16.53019","0.01822"
"33095","198.53400","16.54466","0.01846"
"33124","198.70800","16.55919","0.01876"
"33153","198.88200","16.57372","0.01787"
"33182","199.05600","16.58819","0.01794"
"33211","199.23000","16.60271","0.01833"
"33240","199.40400","16.61724","0.01871"
"33269","199.57800","16.63171","0.01836"
"33298","199.75200","16.64618","0.01806"
"33327","199.92600","16.66071","0.01821"
"33356","200.10000","16.67518","0.01859"
"33385","200.27400","16.68965","0.01881"
"33414","200.44800","16.70424","0.01849"
"33443","200.62200","16.71865","0.01876"
"33472","200.79600","16.73318","0.01846"
"33501","200.97000","16.74776","0.01864"
"33530","201.14400","16.76223","0.01823"
"33559","201.31800","16.77670","0.01851"
"33588","201.49200","16.79123","0.01880"
"33617","201.66600","16.80564","0.01884"
"33646","201.84000","16.82017","0.01866"
"33675","202.01400","16.83476","0.01879"
"33704","202.18800","16.84923","0.01866"
"33733","202.36200","16.86370","0.01857"
"33762","202.53600","16.87823","0.01888"
"33791","202.71000","16.89270","0.01867"
"33820","202.88400","16.90717","0.01851"
"33849","203.05800","16.92169","0.01898"
"33878","203.23200","16.93622","0.01873"
"33907","203.40600","16.95069","0.01883"
"33936","203.58000","16.96522","0.01888"
"33965","203.75400","16.97969","0.01866"
"33994","203.92800","16.99416","0.01895"
"34023","204.10200","17.00875","0.01878"
"34052","204.27600","17.02321","0.01854"
"34081","204.45000","17.03768","0.01870"
"34110","204.62400","17.05215","0.01958"
"34139","204.79800","17.06668","0.01906"
"34168","204.97200","17.08115","0.01885"
"34197","205.14600","17.09574","0.01922"
"34226","205.32000","17.11021","0.01928"
"34255","205.49400","17.12468","0.01868"
"34284","205.66800","17.13921","0.01895"
"34313","205.84200","17.15368","0.01965"
"34342","206.01600","17.16821","0.01948"
"34371","206.19000","17.18267","0.01917"
"34400","206.36400","17.19720","0.01910"
"34429","206.53800","17.21167","0.01949"
"34458","206.71200","17.22620","0.01930"
"34487","206.88600","17.24073","0.01935"
"34516","207.06000","17.25520","0.01926"
"34545","207.23400","17.26967","0.01956"
"34574","207.40800","17.28420","0.01979"
"34603","207.58200","17.29873","0.01979"
"34632","207.75600","17.31320","0.01991"
"34661","207.93000","17.32772","0.02001"
"34690","208.10400","17.34213","0.01979"
"34719","208.27800","17.35660","0.01980"
"34748","208.45200","17.37125","0.01936"
"34777","208.62600","17.38572","0.02013"
"34806","208.80000","17.40013","0.01971"
"34835","208.97400","17.41472","0.01983"
"34864","209.14800","17.42925","0.01978"
"34893","209.32200","17.44366","0.01990"
"34922","209.49600","17.45824","0.01590"
"34951","209.67000","17.47271","0.01442"
"34980","209.84400","17.48712","0.01487"
"35009","210.01800","17.50171","0.01420"
"35038","210.19200","17.51624","0.01422"
"35067","210.36600","17.53065","0.01425"
"35096","210.54000","17.54518","0.01401"
"35125","210.71400","17.55971","0.01369"
"35154","210.88800","17.57418","0.01398"
"35183","211.06200","17.58871","0.01401"
"35212","211.23600","17.60323","0.01434"
"35241","211.41000","17.61770","0.01441"
"35270","211.58400","17.63223","0.01351"
"35299","211.75800","17.64676","0.01394"
"35328","211.93200","17.66123","0.01425"
"35357","212.10600","17.67570","0.01384"
"35386","212.28000","17.69023","0.01369"
"35415","212.45400","17.70470","0.01390"
"35444","212.62800","17.71923","0.01484"
"35473","212.80200","17.73363","0.01414"
"35502","212.97600","17.74816","0.01435"
"35531","213.15000","17.76263","0.01323"
"35560","213.32400","17.77722","0.01396"
"35589","213.49800","17.79175","0.01373"
"35618","213.67200","17.80616","0.01381"
"35647","213.84600","17.82069","0.01382"
"35676","214.02000","17.83522","0.01420"
"35705","214.19400","17.84969","0.01396"
"35734","214.36800","17.86422","0.01437"
"35763","214.54200","17.87868","0.01388"
"35792","214.71600","17.89315","0.01410"
"35821","214.89000","17.90774","0.01453"
"35850","215.06400","17.92221","0.01343"
"35861","215.12600","17.92735","0.01419"