File: Trajectories_together/170122_1Specimen_RawData_3.csv
"","V1","V2","V3"
"1","End date","1/22/2017",""
"2","Specimen label","3BT_19",""
"3","Maximum Load","0.13672","N"
"4","Time","Extension","Load"
"5","(s)","(mm)","(N)"
"6","0.00000","0.00000","0.00028"
"53","0.28200","0.02278","0.00002"
"100","0.56400","0.04723","-0.00034"
"147","0.84600","0.07073","-0.00056"
"194","1.12800","0.09423","-0.00057"
"241","1.41000","0.11773","-0.00050"
"288","1.69200","0.14116","-0.00059"
"335","1.97400","0.16472","-0.00050"
"382","2.25600","0.18816","-0.00028"
"429","2.53800","0.21171","-0.00037"
"476","2.82000","0.23521","-0.00046"
"523","3.10200","0.25871","0.00009"
"570","3.38400","0.28215","-0.00013"
"617","3.66600","0.30570","0.00016"
"664","3.94800","0.32920","-0.00007"
"711","4.23000","0.35270","0.00031"
"758","4.51200","0.37626","0.00011"
"805","4.79400","0.39969","-0.00012"
"852","5.07600","0.42319","0.00004"
"899","5.35800","0.44669","-0.00013"
"946","5.64000","0.47018","0.00060"
"993","5.92200","0.49368","-0.00001"
"1040","6.20400","0.51724","0.00000"
"1087","6.48600","0.54074","0.00003"
"1134","6.76800","0.56423","-0.00002"
"1181","7.05000","0.58767","0.00004"
"1228","7.33200","0.61123","0.00013"
"1275","7.61400","0.63467","0.00010"
"1322","7.89600","0.65822","0.00001"
"1369","8.17800","0.68166","0.00072"
"1416","8.46000","0.70522","-0.00009"
"1463","8.74200","0.72871","0.00030"
"1510","9.02400","0.75227","0.00081"
"1557","9.30600","0.77571","0.00035"
"1604","9.58800","0.79921","0.00027"
"1651","9.87000","0.82270","0.00029"
"1698","10.15200","0.84620","0.00028"
"1745","10.43400","0.86970","0.00033"
"1792","10.71600","0.89320","0.00022"
"1839","10.99800","0.91675","0.00065"
"1886","11.28000","0.94019","0.00057"
"1933","11.56200","0.96375","0.00073"
"1980","11.84400","0.98718","0.00028"
"2027","12.12600","1.01074","0.00023"
"2074","12.40800","1.03412","0.00039"
"2121","12.69000","1.05768","0.00058"
"2168","12.97200","1.08111","0.00041"
"2215","13.25400","1.10473","0.00102"
"2262","13.53600","1.12817","0.00110"
"2309","13.81800","1.15173","0.00045"
"2356","14.10000","1.17522","0.00050"
"2403","14.38200","1.19872","0.00134"
"2450","14.66400","1.22222","0.00133"
"2497","14.94600","1.24571","0.00095"
"2544","15.22800","1.26915","0.00074"
"2591","15.51000","1.29271","0.00080"
"2638","15.79200","1.31621","0.00104"
"2685","16.07400","1.33976","0.00104"
"2732","16.35600","1.36326","0.00125"
"2779","16.63800","1.38670","0.00091"
"2826","16.92000","1.41026","0.00079"
"2873","17.20200","1.43369","0.00194"
"2920","17.48400","1.45719","0.00141"
"2967","17.76600","1.48063","0.00126"
"3014","18.04800","1.50419","0.00149"
"3061","18.33000","1.52768","0.00128"
"3108","18.61200","1.55118","0.00113"
"3155","18.89400","1.57462","0.00117"
"3202","19.17600","1.59823","0.00171"
"3249","19.45800","1.62167","0.00167"
"3296","19.74000","1.64523","0.00160"
"3343","20.02200","1.66861","0.00171"
"3390","20.30400","1.69222","0.00141"
"3437","20.58600","1.71566","0.00203"
"3484","20.86800","1.73922","0.00145"
"3531","21.15000","1.76266","0.00172"
"3578","21.43200","1.78621","0.00236"
"3625","21.71400","1.80971","0.00194"
"3672","21.99600","1.83321","0.00232"
"3719","22.27800","1.85670","0.00199"
"3766","22.56000","1.88020","0.00191"
"3813","22.84200","1.90370","0.00260"
"3860","23.12400","1.92720","0.00226"
"3907","23.40600","1.95069","0.00236"
"3954","23.68800","1.97419","0.00218"
"4001","23.97000","1.99775","0.00254"
"4048","24.25200","2.02119","0.00255"
"4095","24.53400","2.04474","0.00249"
"4142","24.81600","2.06818","0.00261"
"4189","25.09800","2.09174","0.00289"
"4236","25.38000","2.11517","0.00242"
"4283","25.66200","2.13873","0.00244"
"4330","25.94400","2.16217","0.00311"
"4377","26.22600","2.18573","0.00250"
"4424","26.50800","2.20922","0.00256"
"4471","26.79000","2.23272","0.00266"
"4518","27.07200","2.25622","0.00328"
"4565","27.35400","2.27972","0.00283"
"4612","27.63600","2.30321","0.00307"
"4659","27.91800","2.32671","0.00233"
"4706","28.20000","2.35027","0.00388"
"4753","28.48200","2.37370","0.00359"
"4800","28.76400","2.39726","0.00288"
"4847","29.04600","2.42070","0.00292"
"4894","29.32800","2.44420","0.00341"
"4941","29.61000","2.46763","0.00344"
"4988","29.89200","2.49119","0.00331"
"5035","30.17400","2.51469","0.00352"
"5082","30.45600","2.53825","0.00402"
"5129","30.73800","2.56168","0.00402"
"5176","31.02000","2.58524","0.00386"
"5223","31.30200","2.60868","0.00400"
"5270","31.58400","2.63223","0.00382"
"5317","31.86600","2.65573","0.00410"
"5364","32.14800","2.67923","0.00392"
"5411","32.43000","2.70273","0.00426"
"5458","32.71200","2.72622","0.00363"
"5505","32.99400","2.74972","0.00429"
"5552","33.27600","2.77322","0.00430"
"5599","33.55800","2.79677","0.00420"
"5646","33.84000","2.82015","0.00437"
"5693","34.12200","2.84371","0.00400"
"5740","34.40400","2.86721","0.00438"
"5787","34.68600","2.89070","0.00483"
"5834","34.96800","2.91414","0.00427"
"5881","35.25000","2.93770","0.00465"
"5928","35.53200","2.96114","0.00472"
"5975","35.81400","2.98469","0.00474"
"6022","36.09600","3.00819","0.00477"
"6069","36.37800","3.03175","0.00454"
"6116","36.66000","3.05519","0.00507"
"6163","36.94200","3.07874","0.00379"
"6210","37.22400","3.10212","0.00371"
"6257","37.50600","3.12574","0.00410"
"6304","37.78800","3.14917","0.00390"
"6351","38.07000","3.17273","0.00336"
"6398","38.35200","3.19617","0.00450"
"6445","38.63400","3.21973","0.00424"
"6492","38.91600","3.24322","0.00416"
"6539","39.19800","3.26672","0.00450"
"6586","39.48000","3.29022","0.00452"
"6633","39.76200","3.31372","0.00470"
"6680","40.04400","3.33721","0.00446"
"6727","40.32600","3.36065","0.00445"
"6774","40.60800","3.38427","0.00491"
"6821","40.89000","3.40770","0.00455"
"6868","41.17200","3.43126","0.00511"
"6915","41.45400","3.45470","0.00461"
"6962","41.73600","3.47820","0.00519"
"7009","42.01800","3.50169","0.00508"
"7056","42.30000","3.52525","0.00528"
"7103","42.58200","3.54869","0.00510"
"7150","42.86400","3.57219","0.00482"
"7197","43.14600","3.59568","0.00503"
"7244","43.42800","3.61924","0.00407"
"7291","43.71000","3.64274","0.00393"
"7338","43.99200","3.66623","0.00413"
"7385","44.27400","3.68973","0.00482"
"7432","44.55600","3.71323","0.00410"
"7479","44.83800","3.73673","0.00465"
"7526","45.12000","3.76016","0.00415"
"7573","45.40200","3.78372","0.00447"
"7620","45.68400","3.80722","0.00445"
"7667","45.96600","3.83078","0.00475"
"7714","46.24800","3.85415","0.00514"
"7761","46.53000","3.87771","0.00486"
"7808","46.81200","3.90115","0.00520"
"7855","47.09400","3.92476","0.00467"
"7902","47.37600","3.94820","0.00458"
"7949","47.65800","3.97170","0.00436"
"7996","47.94000","3.99514","0.00551"
"8043","48.22200","4.01875","0.00537"
"8090","48.50400","4.04225","0.00521"
"8137","48.78600","4.06575","0.00561"
"8184","49.06800","4.08919","0.00601"
"8231","49.35000","4.11274","0.00612"
"8278","49.63200","4.13624","0.00602"
"8325","49.91400","4.15968","0.00611"
"8372","50.19600","4.18317","0.00551"
"8419","50.47800","4.20667","0.00587"
"8466","50.76000","4.23023","0.00612"
"8513","51.04200","4.25367","0.00615"
"8560","51.32400","4.27722","0.00639"
"8607","51.60600","4.30066","0.00675"
"8654","51.88800","4.32422","0.00660"
"8701","52.17000","4.34766","0.00668"
"8748","52.45200","4.37121","0.00682"
"8795","52.73400","4.39465","0.00738"
"8842","53.01600","4.41821","0.00733"
"8889","53.29800","4.44165","0.00692"
"8936","53.58000","4.46520","0.00768"
"8983","53.86200","4.48864","0.00798"
"9030","54.14400","4.51226","0.00795"
"9077","54.42600","4.53563","0.00849"
"9124","54.70800","4.55925","0.00796"
"9171","54.99000","4.58269","0.00826"
"9218","55.27200","4.60625","0.00803"
"9265","55.55400","4.62968","0.00818"
"9312","55.83600","4.65324","0.00848"
"9359","56.11800","4.67668","0.00905"
"9406","56.40000","4.70023","0.00893"
"9453","56.68200","4.72373","0.00883"
"9500","56.96400","4.74723","0.00886"
"9547","57.24600","4.77073","0.00898"
"9594","57.52800","4.79422","0.00937"
"9641","57.81000","4.81778","0.00890"
"9688","58.09200","4.84122","0.00888"
"9735","58.37400","4.86472","0.00956"
"9782","58.65600","4.88815","0.00973"
"9829","58.93800","4.91171","0.00934"
"9876","59.22000","4.93521","0.01021"
"9923","59.50200","4.95870","0.00968"
"9970","59.78400","4.98220","0.00984"
"10017","60.06600","5.00570","0.01078"
"10064","60.34800","5.02914","0.01079"
"10111","60.63000","5.05269","0.01074"
"10158","60.91200","5.07613","0.01089"
"10205","61.19400","5.09969","0.01089"
"10252","61.47600","5.12319","0.01132"
"10299","61.75800","5.14668","0.01076"
"10346","62.04000","5.17018","0.01178"
"10393","62.32200","5.19374","0.01155"
"10440","62.60400","5.21718","0.01174"
"10487","62.88600","5.24067","0.01285"
"10534","63.16800","5.26429","0.01199"
"10581","63.45000","5.28773","0.01133"
"10628","63.73200","5.31128","0.01170"
"10675","64.01400","5.33472","0.01226"
"10722","64.29600","5.35828","0.01256"
"10769","64.57800","5.38166","0.01186"
"10816","64.86000","5.40521","0.01235"
"10863","65.14200","5.42871","0.01267"
"10910","65.42400","5.45227","0.01325"
"10957","65.70600","5.47570","0.01296"
"11004","65.98800","5.49920","0.01327"
"11051","66.27000","5.52264","0.01344"
"11098","66.55200","5.54620","0.01401"
"11145","66.83400","5.56969","0.01469"
"11192","67.11600","5.59319","0.01416"
"11239","67.39800","5.61669","0.01463"
"11286","67.68000","5.64019","0.01463"
"11333","67.96200","5.66368","0.01454"
"11380","68.24400","5.68718","0.01530"
"11427","68.52600","5.71074","0.01524"
"11474","68.80800","5.73417","0.01612"
"11521","69.09000","5.75773","0.01602"
"11568","69.37200","5.78117","0.01632"
"11615","69.65400","5.80473","0.01616"
"11662","69.93600","5.82822","0.01628"
"11709","70.21800","5.85172","0.01698"
"11756","70.50000","5.87516","0.01641"
"11803","70.78200","5.89872","0.01722"
"11850","71.06400","5.92215","0.01695"
"11897","71.34600","5.94571","0.01717"
"11944","71.62800","5.96915","0.01792"
"11991","71.91000","5.99276","0.01816"
"12038","72.19200","6.01620","0.01795"
"12085","72.47400","6.03976","0.01842"
"12132","72.75600","6.06320","0.01873"
"12179","73.03800","6.08675","0.01907"
"12226","73.32000","6.11019","0.01842"
"12273","73.60200","6.13375","0.01907"
"12320","73.88400","6.15725","0.01964"
"12367","74.16600","6.18074","0.01938"
"12414","74.44800","6.20424","0.01994"
"12461","74.73000","6.22774","0.01957"
"12508","75.01200","6.25124","0.02000"
"12555","75.29400","6.27467","0.02016"
"12602","75.57600","6.29823","0.02050"
"12649","75.85800","6.32167","0.02080"
"12696","76.14000","6.34516","0.02062"
"12743","76.42200","6.36872","0.02107"
"12790","76.70400","6.39222","0.02125"
"12837","76.98600","6.41566","0.02139"
"12884","77.26800","6.43921","0.02133"
"12931","77.55000","6.46265","0.02187"
"12978","77.83200","6.48621","0.02178"
"13025","78.11400","6.50964","0.02245"
"13072","78.39600","6.53320","0.02219"
"13119","78.67800","6.55670","0.02194"
"13166","78.96000","6.58020","0.02330"
"13213","79.24200","6.60375","0.02280"
"13260","79.52400","6.62725","0.02358"
"13307","79.80600","6.65075","0.02341"
"13354","80.08800","6.67425","0.02370"
"13401","80.37000","6.69768","0.02366"
"13448","80.65200","6.72124","0.02423"
"13495","80.93400","6.74474","0.02469"
"13542","81.21600","6.76818","0.02430"
"13589","81.49800","6.79173","0.02496"
"13636","81.78000","6.81523","0.02456"
"13683","82.06200","6.83879","0.02563"
"13730","82.34400","6.86216","0.02522"
"13777","82.62600","6.88572","0.02549"
"13824","82.90800","6.90916","0.02579"
"13871","83.19000","6.93272","0.02599"
"13918","83.47200","6.95609","0.02596"
"13965","83.75400","6.97971","0.02610"
"14012","84.03600","7.00315","0.02639"
"14059","84.31800","7.02671","0.02698"
"14106","84.60000","7.05020","0.02666"
"14153","84.88200","7.07370","0.02717"
"14200","85.16400","7.09720","0.02726"
"14247","85.44600","7.12069","0.02735"
"14294","85.72800","7.14419","0.02776"
"14341","86.01000","7.16763","0.02787"
"14388","86.29200","7.19119","0.02802"
"14435","86.57400","7.21474","0.02814"
"14482","86.85600","7.23824","0.02785"
"14529","87.13800","7.26168","0.02798"
"14576","87.42000","7.28524","0.02819"
"14623","87.70200","7.30867","0.02829"
"14670","87.98400","7.33223","0.02845"
"14717","88.26600","7.35567","0.02841"
"14764","88.54800","7.37922","0.02877"
"14811","88.83000","7.40266","0.02907"
"14858","89.11200","7.42628","0.02914"
"14905","89.39400","7.44972","0.02890"
"14952","89.67600","7.47321","0.02946"
"14999","89.95800","7.49671","0.02966"
"15046","90.24000","7.52027","0.03013"
"15093","90.52200","7.54371","0.02983"
"15140","90.80400","7.56726","0.02959"
"15187","91.08600","7.59070","0.03023"
"15234","91.36800","7.61426","0.03034"
"15281","91.65000","7.63769","0.03043"
"15328","91.93200","7.66125","0.03041"
"15375","92.21400","7.68469","0.03015"
"15422","92.49600","7.70819","0.03036"
"15469","92.77800","7.73174","0.03085"
"15516","93.06000","7.75524","0.03097"
"15563","93.34200","7.77874","0.03080"
"15610","93.62400","7.80224","0.03097"
"15657","93.90600","7.82573","0.00806"
"15704","94.18800","7.84917","0.00896"
"15751","94.47000","7.87273","0.00830"
"15798","94.75200","7.89616","0.00902"
"15845","95.03400","7.91972","0.00905"
"15892","95.31600","7.94316","0.00883"
"15939","95.59800","7.96672","0.00976"
"15986","95.88000","7.99021","0.00994"
"16033","96.16200","8.01371","0.01065"
"16080","96.44400","8.03721","0.01064"
"16127","96.72600","8.06076","0.01074"
"16174","97.00800","8.08420","0.01103"
"16221","97.29000","8.10776","0.01070"
"16268","97.57200","8.13126","0.01073"
"16315","97.85400","8.15469","0.01221"
"16362","98.13600","8.17825","0.01223"
"16409","98.41800","8.20169","0.01270"
"16456","98.70000","8.22519","0.01247"
"16503","98.98200","8.24868","0.01228"
"16550","99.26400","8.27224","0.01265"
"16597","99.54600","8.29568","0.01197"
"16644","99.82800","8.31917","0.01247"
"16691","100.11000","8.34267","0.01065"
"16738","100.39200","8.36623","0.01171"
"16785","100.67400","8.38967","0.01236"
"16832","100.95600","8.41322","0.01200"
"16879","101.23800","8.43666","0.01178"
"16926","101.52000","8.46022","0.01328"
"16973","101.80200","8.48366","0.01298"
"17020","102.08400","8.50721","0.01303"
"17067","102.36600","8.53071","0.01311"
"17114","102.64800","8.55415","0.01392"
"17161","102.93000","8.57765","0.01406"
"17208","103.21200","8.60114","0.01409"
"17255","103.49400","8.62470","0.01445"
"17302","103.77600","8.64820","0.01423"
"17349","104.05800","8.67175","0.01483"
"17396","104.34000","8.69519","0.01582"
"17443","104.62200","8.71875","0.01426"
"17490","104.90400","8.74219","0.01455"
"17537","105.18600","8.76574","0.01522"
"17584","105.46800","8.78924","0.01563"
"17631","105.75000","8.81280","0.01578"
"17678","106.03200","8.83617","0.01532"
"17725","106.31400","8.85973","0.01537"
"17772","106.59600","8.88317","0.01536"
"17819","106.87800","8.90667","0.01520"
"17866","107.16000","8.93011","0.01533"
"17913","107.44200","8.95378","0.01625"
"17960","107.72400","8.97716","0.01649"
"18007","108.00600","9.00072","0.01702"
"18054","108.28800","9.02421","0.01680"
"18101","108.57000","9.04777","0.01686"
"18148","108.85200","9.07121","0.01751"
"18195","109.13400","9.09471","0.01726"
"18242","109.41600","9.11820","0.01742"
"18289","109.69800","9.14170","0.01709"
"18336","109.98000","9.16526","0.01756"
"18383","110.26200","9.18869","0.01814"
"18430","110.54400","9.21219","0.01893"
"18477","110.82600","9.23569","0.01945"
"18524","111.10800","9.25919","0.02020"
"18571","111.39000","9.28268","0.01972"
"18618","111.67200","9.30618","0.02052"
"18665","111.95400","9.32968","0.02113"
"18712","112.23600","9.35318","0.02110"
"18759","112.51800","9.37667","0.02187"
"18806","112.80000","9.40023","0.02132"
"18853","113.08200","9.42373","0.02130"
"18900","113.36400","9.44722","0.02218"
"18947","113.64600","9.47072","0.02224"
"18994","113.92800","9.49428","0.02308"
"19041","114.21000","9.51772","0.02340"
"19088","114.49200","9.54127","0.02367"
"19135","114.77400","9.56477","0.02429"
"19182","115.05600","9.58821","0.02528"
"19229","115.33800","9.61165","0.02522"
"19276","115.62000","9.63514","0.02564"
"19323","115.90200","9.65870","0.02638"
"19370","116.18400","9.68220","0.02699"
"19417","116.46600","9.70576","0.02624"
"19464","116.74800","9.72919","0.02700"
"19511","117.03000","9.75269","0.02728"
"19558","117.31200","9.77613","0.02796"
"19605","117.59400","9.79968","0.02824"
"19652","117.87600","9.82318","0.02822"
"19699","118.15800","9.84668","0.02863"
"19746","118.44000","9.87018","0.02805"
"19793","118.72200","9.89373","0.02926"
"19840","119.00400","9.91717","0.02951"
"19887","119.28600","9.94073","0.02947"
"19934","119.56800","9.96422","0.02979"
"19981","119.85000","9.98772","0.02990"
"20028","120.13200","10.01122","0.03022"
"20075","120.41400","10.03472","0.03079"
"20122","120.69600","10.05821","0.03089"
"20169","120.97800","10.08177","0.03084"
"20216","121.26000","10.10527","0.03133"
"20263","121.54200","10.12871","0.03164"
"20310","121.82400","10.15226","0.03163"
"20357","122.10600","10.17570","0.03193"
"20404","122.38800","10.19926","0.03218"
"20451","122.67000","10.22269","0.03275"
"20498","122.95200","10.24625","0.03281"
"20545","123.23400","10.26969","0.03320"
"20592","123.51600","10.29325","0.03343"
"20639","123.79800","10.31668","0.03331"
"20686","124.08000","10.34024","0.03340"
"20733","124.36200","10.36362","0.03266"
"20780","124.64400","10.38724","0.03325"
"20827","124.92600","10.41067","0.03315"
"20874","125.20800","10.43423","0.03361"
"20921","125.49000","10.45767","0.03416"
"20968","125.77200","10.48123","0.03440"
"21015","126.05400","10.50466","0.03505"
"21062","126.33600","10.52822","0.03520"
"21109","126.61800","10.55172","0.03643"
"21156","126.90000","10.57521","0.03655"
"21203","127.18200","10.59871","0.03749"
"21250","127.46400","10.62221","0.03771"
"21297","127.74600","10.64577","0.03829"
"21344","128.02800","10.66920","0.03874"
"21391","128.31000","10.69276","0.03755"
"21438","128.59200","10.71620","0.03303"
"21485","128.87400","10.73975","0.03217"
"21532","129.15600","10.76319","0.03158"
"21579","129.43800","10.78675","0.03139"
"21626","129.72000","10.81019","0.03096"
"21673","130.00200","10.83374","0.03156"
"21720","130.28400","10.85718","0.03162"
"21767","130.56600","10.88074","0.03162"
"21814","130.84800","10.90418","0.03150"
"21861","131.13000","10.92773","0.02944"
"21908","131.41200","10.95117","0.03012"
"21955","131.69400","10.97473","0.03034"
"22002","131.97600","10.99817","0.03075"
"22049","132.25800","11.02166","0.03029"
"22096","132.54000","11.04516","0.03091"
"22143","132.82200","11.06866","0.03105"
"22190","133.10400","11.09221","0.03154"
"22237","133.38600","11.11571","0.03182"
"22284","133.66800","11.13921","0.03172"
"22331","133.95000","11.16271","0.03156"
"22378","134.23200","11.18620","0.03191"
"22425","134.51400","11.20970","0.03147"
"22472","134.79600","11.23320","0.03140"
"22519","135.07800","11.25664","0.03068"
"22566","135.36000","11.28025","0.03035"
"22613","135.64200","11.30369","0.03053"
"22660","135.92400","11.32725","0.03066"
"22707","136.20600","11.35074","0.03081"
"22754","136.48800","11.37424","0.03132"
"22801","136.77000","11.39768","0.03137"
"22848","137.05200","11.42118","0.03162"
"22895","137.33400","11.44467","0.03182"
"22942","137.61600","11.46823","0.03217"
"22989","137.89800","11.49173","0.03201"
"23036","138.18000","11.51523","0.03237"
"23083","138.46200","11.53872","0.03156"
"23130","138.74400","11.56222","0.03124"
"23177","139.02600","11.58572","0.03084"
"23224","139.30800","11.60915","0.03077"
"23271","139.59000","11.63271","0.03099"
"23318","139.87200","11.65621","0.03151"
"23365","140.15400","11.67971","0.03159"
"23412","140.43600","11.70314","0.03171"
"23459","140.71800","11.72670","0.03114"
"23506","141.00000","11.75020","0.03097"
"23553","141.28200","11.77369","0.03020"
"23600","141.56400","11.79713","0.02968"
"23647","141.84600","11.82069","0.02969"
"23694","142.12800","11.84413","0.02492"
"23741","142.41000","11.86774","0.02624"
"23788","142.69200","11.89118","0.02744"
"23835","142.97400","11.91474","0.02790"
"23882","143.25600","11.93824","0.02864"
"23929","143.53800","11.96173","0.02902"
"23976","143.82000","11.98523","0.02946"
"24023","144.10200","12.00873","0.02996"
"24070","144.38400","12.03217","0.03040"
"24117","144.66600","12.05572","0.03070"
"24164","144.94800","12.07922","0.03109"
"24211","145.23000","12.10272","0.03100"
"24258","145.51200","12.12627","0.03151"
"24305","145.79400","12.14971","0.03187"
"24352","146.07600","12.17327","0.03211"
"24399","146.35800","12.19671","0.03299"
"24446","146.64000","12.22026","0.03376"
"24493","146.92200","12.24370","0.03459"
"24540","147.20400","12.26720","0.03531"
"24587","147.48600","12.29064","0.03593"
"24634","147.76800","12.31419","0.03728"
"24681","148.05000","12.33763","0.03814"
"24728","148.33200","12.36125","0.03943"
"24775","148.61400","12.38468","0.04125"
"24822","148.89600","12.40824","0.04326"
"24869","149.17800","12.43168","0.04351"
"24916","149.46000","12.45518","0.04430"
"24963","149.74200","12.47867","0.04421"
"25010","150.02400","12.50217","0.03454"
"25057","150.30600","12.52567","0.03380"
"25104","150.58800","12.54917","0.03389"
"25151","150.87000","12.57272","0.03368"
"25198","151.15200","12.59616","0.03408"
"25245","151.43400","12.61972","0.03489"
"25292","151.71600","12.64316","0.03545"
"25339","151.99800","12.66671","0.03654"
"25386","152.28000","12.69015","0.03689"
"25433","152.56200","12.71371","0.03237"
"25480","152.84400","12.73714","0.03058"
"25527","153.12600","12.76076","0.03064"
"25574","153.40800","12.78420","0.03165"
"25621","153.69000","12.80775","0.03238"
"25668","153.97200","12.83119","0.03227"
"25715","154.25400","12.85475","0.03213"
"25762","154.53600","12.87825","0.03301"
"25809","154.81800","12.90174","0.03352"
"25856","155.10000","12.92524","0.03361"
"25903","155.38200","12.94874","0.03483"
"25950","155.66400","12.97224","0.03542"
"25997","155.94600","12.99573","0.03482"
"26044","156.22800","13.01923","0.03578"
"26091","156.51000","13.04273","0.03707"
"26138","156.79200","13.06623","0.03646"
"26185","157.07400","13.08966","0.03488"
"26232","157.35600","13.11322","0.03510"
"26279","157.63800","13.13672","0.03693"
"26326","157.92000","13.16021","0.03853"
"26373","158.20200","13.18371","0.03924"
"26420","158.48400","13.20721","0.04181"
"26467","158.76600","13.23065","0.04325"
"26514","159.04800","13.25420","0.04576"
"26561","159.33000","13.27770","0.04735"
"26608","159.61200","13.30126","0.05010"
"26655","159.89400","13.32464","0.05237"
"26702","160.17600","13.34825","0.05425"
"26749","160.45800","13.37169","0.05642"
"26796","160.74000","13.39525","0.05799"
"26843","161.02200","13.41875","0.05977"
"26890","161.30400","13.44224","0.06150"
"26937","161.58600","13.46568","0.06344"
"26984","161.86800","13.48924","0.06481"
"27031","162.15000","13.51273","0.06634"
"27078","162.43200","13.53623","0.06819"
"27125","162.71400","13.55973","0.07074"
"27172","162.99600","13.58323","0.07300"
"27219","163.27800","13.60678","0.07424"
"27266","163.56000","13.63022","0.07670"
"27313","163.84200","13.65372","0.07830"
"27360","164.12400","13.67722","0.07936"
"27407","164.40600","13.70071","0.08074"
"27454","164.68800","13.72415","0.08145"
"27501","164.97000","13.74765","0.08209"
"27548","165.25200","13.77114","0.08267"
"27595","165.53400","13.79476","0.08293"
"27642","165.81600","13.81814","0.08356"
"27689","166.09800","13.84175","0.08398"
"27736","166.38000","13.86513","0.08380"
"27783","166.66200","13.88869","0.08460"
"27830","166.94400","13.91213","0.08502"
"27877","167.22600","13.93569","0.02355"
"27924","167.50800","13.95918","0.00232"
"27971","167.79000","13.98274","0.00803"
"28018","168.07200","14.00618","0.00075"
"28065","168.35400","14.02967","0.00462"
"28112","168.63600","14.05323","0.00346"
"28159","168.91800","14.07673","0.00160"
"28206","169.20000","14.10023","0.00985"
"28253","169.48200","14.12366","0.00147"
"28300","169.76400","14.14728","0.00295"
"28347","170.04600","14.17072","0.00885"
"28394","170.32800","14.19427","0.00382"
"28441","170.61000","14.21765","0.00262"
"28488","170.89200","14.24127","0.00650"
"28535","171.17400","14.26471","0.00145"
"28582","171.45600","14.28826","0.00823"
"28629","171.73800","14.31170","0.00315"
"28676","172.02000","14.33520","0.00473"
"28723","172.30200","14.35870","0.00658"
"28770","172.58400","14.38225","0.00362"
"28817","172.86600","14.40569","0.00748"
"28864","173.14800","14.42925","0.00440"
"28911","173.43000","14.45274","0.00626"
"28958","173.71200","14.47624","0.00582"
"29005","173.99400","14.49974","0.00626"
"29052","174.27600","14.52318","0.00675"
"29099","174.55800","14.54673","0.00609"
"29146","174.84000","14.57017","0.00672"
"29193","175.12200","14.59373","0.00692"
"29240","175.40400","14.61717","0.00661"
"29287","175.68600","14.64072","0.00885"
"29334","175.96800","14.66416","0.00667"
"29381","176.25000","14.68772","0.00939"
"29428","176.53200","14.71115","0.00752"
"29475","176.81400","14.73471","0.01011"
"29522","177.09600","14.75815","0.00794"
"29569","177.37800","14.78171","0.01076"
"29616","177.66000","14.80520","0.00963"
"29663","177.94200","14.82876","0.01072"
"29710","178.22400","14.85220","0.01058"
"29757","178.50600","14.87576","0.01108"
"29804","178.78800","14.89925","0.01105"
"29851","179.07000","14.92275","0.01095"
"29898","179.35200","14.94619","0.01327"
"29945","179.63400","14.96969","0.01190"
"29992","179.91600","14.99324","0.01393"
"30039","180.19800","15.01668","0.01232"
"30086","180.48000","15.04024","0.01467"
"30133","180.76200","15.06367","0.01351"
"30180","181.04400","15.08723","0.01536"
"30227","181.32600","15.11067","0.01470"
"30274","181.60800","15.13423","0.01580"
"30321","181.89000","15.15766","0.01584"
"30368","182.17200","15.18122","0.01678"
"30415","182.45400","15.20466","0.01655"
"30462","182.73600","15.22821","0.01699"
"30509","183.01800","15.25165","0.01773"
"30556","183.30000","15.27521","0.01839"
"30603","183.58200","15.29865","0.01875"
"30650","183.86400","15.32226","0.01880"
"30697","184.14600","15.34570","0.01952"
"30744","184.42800","15.36926","0.01978"
"30791","184.71000","15.39270","0.02085"
"30838","184.99200","15.41625","0.02093"
"30885","185.27400","15.43969","0.02171"
"30932","185.55600","15.46325","0.02148"
"30979","185.83800","15.48674","0.02207"
"31026","186.12000","15.51024","0.02202"
"31073","186.40200","15.53374","0.02290"
"31120","186.68400","15.55724","0.02385"
"31167","186.96600","15.58079","0.02321"
"31214","187.24800","15.60417","0.02438"
"31261","187.53000","15.62773","0.02402"
"31308","187.81200","15.65117","0.02523"
"31355","188.09400","15.67466","0.02507"
"31402","188.37600","15.69816","0.02570"
"31449","188.65800","15.72166","0.02583"
"31496","188.94000","15.74516","0.02693"
"31543","189.22200","15.76871","0.02685"
"31590","189.50400","15.79215","0.02641"
"31637","189.78600","15.81571","0.02696"
"31684","190.06800","15.83920","0.02659"
"31731","190.35000","15.86270","0.02763"
"31778","190.63200","15.88620","0.02775"
"31825","190.91400","15.90970","0.02860"
"31872","191.19600","15.93319","0.02842"
"31919","191.47800","15.95669","0.02891"
"31966","191.76000","15.98025","0.02920"
"32013","192.04200","16.00374","0.02953"
"32060","192.32400","16.02724","0.02997"
"32107","192.60600","16.05068","0.03036"
"32154","192.88800","16.07424","0.03061"
"32201","193.17000","16.09767","0.03047"
"32248","193.45200","16.12123","0.03099"
"32295","193.73400","16.14467","0.03112"
"32342","194.01600","16.16823","0.03152"
"32389","194.29800","16.19172","0.03185"
"32436","194.58000","16.21528","0.03202"
"32483","194.86200","16.23872","0.03239"
"32530","195.14400","16.26227","0.03239"
"32577","195.42600","16.28571","0.03330"
"32624","195.70800","16.30921","0.03310"
"32671","195.99000","16.33271","0.03358"
"32718","196.27200","16.35620","0.03389"
"32765","196.55400","16.37970","0.03469"
"32812","196.83600","16.40320","0.03547"
"32859","197.11800","16.42669","0.03565"
"32906","197.40000","16.45013","0.03651"
"32953","197.68200","16.47375","0.03650"
"33000","197.96400","16.49719","0.03749"
"33047","198.24600","16.52074","0.03816"
"33094","198.52800","16.54418","0.03837"
"33141","198.81000","16.56774","0.03914"
"33188","199.09200","16.59118","0.03953"
"33235","199.37400","16.61467","0.04140"
"33282","199.65600","16.63817","0.04168"
"33329","199.93800","16.66173","0.04278"
"33376","200.22000","16.68517","0.04373"
"33423","200.50200","16.70872","0.04453"
"33470","200.78400","16.73210","0.04596"
"33517","201.06600","16.75572","0.00437"
"33564","201.34800","16.77915","0.00574"
"33611","201.63000","16.80271","-0.00057"
"33658","201.91200","16.82621","0.00543"
"33705","202.19400","16.84977","0.00077"
"33752","202.47600","16.87320","0.00661"
"33799","202.75800","16.89676","0.00032"
"33846","203.04000","16.92020","0.00590"
"33893","203.32200","16.94370","0.00138"
"33940","203.60400","16.96725","0.00516"
"33987","203.88600","16.99069","0.00232"
"34034","204.16800","17.01425","0.00479"
"34081","204.45000","17.03775","0.00242"
"34128","204.73200","17.06124","0.00451"
"34175","205.01400","17.08468","0.00455"
"34222","205.29600","17.10818","0.00349"
"34269","205.57800","17.13167","0.00416"
"34316","205.86000","17.15523","0.00373"
"34363","206.14200","17.17861","0.00446"
"34410","206.42400","17.20217","0.00492"
"34457","206.70600","17.22566","0.00376"
"34504","206.98800","17.24922","0.00536"
"34551","207.27000","17.27266","0.00336"
"34598","207.55200","17.29622","0.00517"
"34645","207.83400","17.31971","0.00370"
"34692","208.11600","17.34321","0.00509"
"34739","208.39800","17.36671","0.00397"
"34786","208.68000","17.39026","0.00386"
"34833","208.96200","17.41370","0.00590"
"34880","209.24400","17.43720","0.00391"
"34927","209.52600","17.46070","0.00549"
"34974","209.80800","17.48425","0.00362"
"35021","210.09000","17.50775","0.00621"
"35068","210.37200","17.53119","0.00391"
"35115","210.65400","17.55474","0.00545"
"35162","210.93600","17.57818","0.00466"
"35209","211.21800","17.60174","0.00529"
"35256","211.50000","17.62518","0.00402"
"35303","211.78200","17.64874","0.00623"
"35350","212.06400","17.67217","0.00500"
"35397","212.34600","17.69573","0.00588"
"35444","212.62800","17.71917","0.00419"
"35491","212.91000","17.74272","0.00708"
"35538","213.19200","17.76616","0.00464"
"35585","213.47400","17.78972","0.00635"
"35632","213.75600","17.81316","0.00514"
"35679","214.03800","17.83671","0.00656"
"35726","214.32000","17.86021","0.00479"
"35773","214.60200","17.88371","0.00669"
"35820","214.88400","17.90720","0.00580"
"35867","215.16600","17.93064","0.00638"
"35914","215.44800","17.95420","0.00541"
"35961","215.73000","17.97764","0.00697"
"36008","216.01200","18.00125","0.00594"
"36055","216.29400","18.02469","0.00628"
"36102","216.57600","18.04825","0.00638"
"36149","216.85800","18.07169","0.00714"
"36196","217.14000","18.09524","0.00645"
"36243","217.42200","18.11868","0.00692"
"36290","217.70400","18.14224","0.00692"
"36337","217.98600","18.16567","0.00652"
"36384","218.26800","18.18923","0.00756"
"36431","218.55000","18.21267","0.00678"
"36478","218.83200","18.23623","0.00778"
"36525","219.11400","18.25972","0.00711"
"36572","219.39600","18.28328","0.00839"
"36619","219.67800","18.30672","0.00728"
"36666","219.96000","18.33027","0.00826"
"36713","220.24200","18.35371","0.00739"
"36760","220.52400","18.37721","0.00795"
"36807","220.80600","18.40071","0.00694"
"36854","221.08800","18.42420","0.00887"
"36901","221.37000","18.44770","0.00773"
"36948","221.65200","18.47114","0.00859"
"36995","221.93400","18.49476","0.00759"
"37042","222.21600","18.51825","0.00905"
"37089","222.49800","18.54175","0.00825"
"37136","222.78000","18.56519","0.00902"
"37183","223.06200","18.58875","0.00841"
"37230","223.34400","18.61218","0.00869"
"37277","223.62600","18.63568","0.00808"
"37324","223.90800","18.65918","0.00818"
"37371","224.19000","18.68274","0.00731"
"37418","224.47200","18.70617","0.00792"
"37465","224.75400","18.72973","0.00748"
"37512","225.03600","18.75323","0.00789"
"37559","225.31800","18.77672","0.00803"
"37606","225.60000","18.80022","0.00777"
"37653","225.88200","18.82378","0.00862"
"37700","226.16400","18.84722","0.00842"
"37747","226.44600","18.87071","0.00882"
"37794","226.72800","18.89421","0.00870"
"37841","227.01000","18.91777","0.01015"
"37888","227.29200","18.94127","0.00912"
"37935","227.57400","18.96470","0.00980"
"37982","227.85600","18.98826","0.00892"
"38029","228.13800","19.01170","0.01026"
"38076","228.42000","19.03519","0.00844"
"38123","228.70200","19.05869","0.01015"
"38170","228.98400","19.08219","0.00943"
"38217","229.26600","19.10569","0.01051"
"38264","229.54800","19.12918","0.00979"
"38311","229.83000","19.15262","0.01025"
"38358","230.11200","19.17624","0.00938"
"38405","230.39400","19.19967","0.01071"
"38452","230.67600","19.22323","0.01057"
"38499","230.95800","19.24667","0.01075"
"38546","231.24000","19.27023","0.01077"
"38593","231.52200","19.29372","0.01055"
"38640","231.80400","19.31716","0.01158"
"38687","232.08600","19.34066","0.01081"
"38734","232.36800","19.36416","0.01125"
"38781","232.65000","19.38771","0.01053"
"38828","232.93200","19.41121","0.01152"
"38875","233.21400","19.43477","0.01180"
"38922","233.49600","19.45820","0.01211"
"38969","233.77800","19.48176","0.01155"
"39016","234.06000","19.50520","0.01268"
"39063","234.34200","19.52876","0.01197"
"39110","234.62400","19.55219","0.01274"
"39157","234.90600","19.57575","0.01197"
"39204","235.18800","19.59919","0.01328"
"39251","235.47000","19.62280","0.01240"
"39298","235.75200","19.64618","0.01338"
"39345","236.03400","19.66974","0.01317"
"39392","236.31600","19.69318","0.01092"
"39439","236.59800","19.71673","0.01154"
"39486","236.88000","19.74017","0.01252"
"39533","237.16200","19.76373","0.01267"
"39580","237.44400","19.78717","0.01215"
"39627","237.72600","19.81072","0.01271"
"39674","238.00800","19.83422","0.01295"
"39721","238.29000","19.85772","0.01279"
"39768","238.57200","19.88121","0.01336"
"39815","238.85400","19.90471","0.01313"
"39862","239.13600","19.92821","0.01327"
"39909","239.41800","19.95165","0.01332"
"39956","239.70000","19.97520","0.01363"
"40003","239.98200","19.99870","0.01426"
"40050","240.26400","20.02226","0.01337"
"40097","240.54600","20.04564","0.01473"
"40144","240.82800","20.06919","0.01450"
"40191","241.11000","20.09269","0.01493"
"40238","241.39200","20.11619","0.01219"
"40285","241.67400","20.13963","0.01273"
"40332","241.95600","20.16324","0.01236"
"40379","242.23800","20.18674","0.01354"
"40426","242.52000","20.21024","0.01303"
"40473","242.80200","20.23374","0.01351"
"40520","243.08400","20.25729","0.01466"
"40567","243.36600","20.28073","0.01439"
"40614","243.64800","20.30423","0.01443"
"40661","243.93000","20.32778","0.01488"
"40708","244.21200","20.35122","0.01496"
"40755","244.49400","20.37472","0.01537"
"40802","244.77600","20.39816","0.01587"
"40849","245.05800","20.42171","0.01550"
"40896","245.34000","20.44521","0.01708"
"40943","245.62200","20.46871","0.01673"
"40990","245.90400","20.49220","0.01714"
"41037","246.18600","20.51570","0.01669"
"41084","246.46800","20.53914","0.01777"
"41131","246.75000","20.56270","0.01756"
"41178","247.03200","20.58619","0.01872"
"41225","247.31400","20.60963","0.01788"
"41272","247.59600","20.63313","0.01925"
"41319","247.87800","20.65669","0.01956"
"41366","248.16000","20.68018","0.01938"
"41413","248.44200","20.70374","0.02010"
"41460","248.72400","20.72718","0.02003"
"41507","249.00600","20.75073","0.02059"
"41554","249.28800","20.77423","0.02065"
"41601","249.57000","20.79773","0.02106"
"41648","249.85200","20.82117","0.02135"
"41695","250.13400","20.84472","0.02183"
"41742","250.41600","20.86828","0.02175"
"41789","250.69800","20.89172","0.02303"
"41836","250.98000","20.91527","0.02285"
"41883","251.26200","20.93871","0.02269"
"41930","251.54400","20.96227","0.02286"
"41977","251.82600","20.98571","0.02324"
"42024","252.10800","21.00926","0.02347"
"42071","252.39000","21.03270","0.02412"
"42118","252.67200","21.05626","0.02437"
"42165","252.95400","21.07970","0.02381"
"42212","253.23600","21.10325","0.02381"
"42259","253.51800","21.12663","0.02426"
"42306","253.80000","21.15025","0.02506"
"42353","254.08200","21.17363","0.02553"
"42400","254.36400","21.19718","0.02542"
"42447","254.64600","21.22068","0.02607"
"42494","254.92800","21.24418","0.02615"
"42541","255.21000","21.26768","0.02619"
"42588","255.49200","21.29117","0.02691"
"42635","255.77400","21.31467","0.02739"
"42682","256.05600","21.33822","0.02743"
"42729","256.33800","21.36172","0.02768"
"42776","256.62000","21.38522","0.02815"
"42823","256.90200","21.40872","0.02844"
"42870","257.18400","21.43222","0.02900"
"42917","257.46600","21.45577","0.02897"
"42964","257.74800","21.47921","0.02965"
"43011","258.03000","21.50271","0.02974"
"43058","258.31200","21.52614","0.03003"
"43105","258.59400","21.54970","0.03053"
"43152","258.87600","21.57314","0.03032"
"43199","259.15800","21.59676","0.03051"
"43246","259.44000","21.62020","0.03083"
"43293","259.72200","21.64375","0.03100"
"43340","260.00400","21.66719","0.03129"
"43387","260.28600","21.69075","0.03171"
"43434","260.56800","21.71418","0.03194"
"43481","260.85000","21.73774","0.03185"
"43528","261.13200","21.76118","0.03236"
"43575","261.41400","21.78468","0.03230"
"43622","261.69600","21.80817","0.03299"
"43669","261.97800","21.83173","0.03345"
"43716","262.26000","21.85517","0.03352"
"43763","262.54200","21.87867","0.03371"
"43810","262.82400","21.90222","0.03352"
"43857","263.10600","21.92572","0.03420"
"43904","263.38800","21.94922","0.03481"
"43951","263.67000","21.97265","0.03492"
"43998","263.95200","21.99621","0.03569"
"44045","264.23400","22.01965","0.03599"
"44092","264.51600","22.04321","0.03650"
"44139","264.79800","22.06664","0.03675"
"44186","265.08000","22.09020","0.03742"
"44233","265.36200","22.11370","0.03785"
"44280","265.64400","22.13725","0.03830"
"44327","265.92600","22.16069","0.03883"
"44374","266.20800","22.18419","0.03932"
"44421","266.49000","22.20769","0.03991"
"44468","266.77200","22.23124","0.04112"
"44515","267.05400","22.25474","0.04180"
"44562","267.33600","22.27824","0.04298"
"44609","267.61800","22.30173","0.04315"
"44656","267.90000","22.32523","0.04444"
"44703","268.18200","22.34879","0.04529"
"44750","268.46400","22.37217","0.04637"
"44797","268.74600","22.39572","0.04643"
"44844","269.02800","22.41916","0.04820"
"44891","269.31000","22.44272","0.04923"
"44938","269.59200","22.46616","0.04959"
"44985","269.87400","22.48971","0.05054"
"45032","270.15600","22.51321","0.05182"
"45079","270.43800","22.53671","0.05325"
"45126","270.72000","22.56015","0.05401"
"45173","271.00200","22.58370","0.05537"
"45220","271.28400","22.60714","0.05600"
"45267","271.56600","22.63076","0.05660"
"45314","271.84800","22.65419","0.05747"
"45361","272.13000","22.67775","0.05833"
"45408","272.41200","22.70119","0.05954"
"45455","272.69400","22.72468","0.06016"
"45502","272.97600","22.74818","0.06117"
"45549","273.25800","22.77174","0.06238"
"45596","273.54000","22.79524","0.06278"
"45643","273.82200","22.81874","0.06392"
"45690","274.10400","22.84223","0.06468"
"45737","274.38600","22.86573","0.06530"
"45784","274.66800","22.88929","0.06653"
"45831","274.95000","22.91273","0.06770"
"45878","275.23200","22.93622","0.06857"
"45925","275.51400","22.95972","0.06956"
"45972","275.79600","22.98322","0.07092"
"46019","276.07800","23.00672","0.07148"
"46066","276.36000","23.03021","0.07307"
"46113","276.64200","23.05365","0.07373"
"46160","276.92400","23.07721","0.07527"
"46207","277.20600","23.10065","0.07618"
"46254","277.48800","23.12420","0.07705"
"46301","277.77000","23.14764","0.07862"
"46348","278.05200","23.17120","0.07907"
"46395","278.33400","23.19469","0.08016"
"46442","278.61600","23.21819","0.08061"
"46489","278.89800","23.24169","0.08084"
"46536","279.18000","23.26518","0.08109"
"46583","279.46200","23.28868","0.08192"
"46630","279.74400","23.31218","0.08185"
"46677","280.02600","23.33568","0.08230"
"46724","280.30800","23.35917","0.08251"
"46771","280.59000","23.38267","0.08294"
"46818","280.87200","23.40617","0.08329"
"46865","281.15400","23.42967","0.08333"
"46912","281.43600","23.45316","0.08365"
"46959","281.71800","23.47666","0.08383"
"47006","282.00000","23.50016","0.08406"
"47053","282.28200","23.52371","0.08412"
"47100","282.56400","23.54721","0.08474"
"47147","282.84600","23.57077","0.08509"
"47194","283.12800","23.59420","0.08509"
"47241","283.41000","23.61776","0.08603"
"47288","283.69200","23.64126","0.08711"
"47335","283.97400","23.66476","0.08719"
"47382","284.25600","23.68819","0.08836"
"47429","284.53800","23.71175","0.08853"
"47476","284.82000","23.73525","0.08936"
"47523","285.10200","23.75875","0.08967"
"47570","285.38400","23.78224","0.09081"
"47617","285.66600","23.80568","0.09215"
"47664","285.94800","23.82924","0.09251"
"47711","286.23000","23.85268","0.09335"
"47758","286.51200","23.87623","0.09478"
"47805","286.79400","23.89967","0.09580"
"47852","287.07600","23.92323","0.09672"
"47899","287.35800","23.94672","0.09759"
"47946","287.64000","23.97022","0.09895"
"47993","287.92200","23.99360","0.10086"
"48040","288.20400","24.01722","0.10128"
"48087","288.48600","24.04066","0.10239"
"48134","288.76800","24.06421","0.10358"
"48181","289.05000","24.08765","0.10535"
"48228","289.33200","24.11126","0.10511"
"48275","289.61400","24.13470","0.10670"
"48322","289.89600","24.15820","0.10745"
"48369","290.17800","24.18170","0.10874"
"48416","290.46000","24.20519","0.10969"
"48463","290.74200","24.22869","0.11062"
"48510","291.02400","24.25225","0.11100"
"48557","291.30600","24.27575","0.11178"
"48604","291.58800","24.29925","0.11211"
"48651","291.87000","24.32274","0.11352"
"48698","292.15200","24.34624","0.11395"
"48745","292.43400","24.36974","0.11473"
"48792","292.71600","24.39317","0.11540"
"48839","292.99800","24.41673","0.11602"
"48886","293.28000","24.44017","0.11615"
"48933","293.56200","24.46372","0.11701"
"48980","293.84400","24.48716","0.11796"
"49027","294.12600","24.51072","0.11843"
"49074","294.40800","24.53416","0.11851"
"49121","294.69000","24.55771","0.11911"
"49168","294.97200","24.58115","0.11922"
"49215","295.25400","24.60471","0.12020"
"49262","295.53600","24.62815","0.12024"
"49309","295.81800","24.65170","0.12088"
"49356","296.10000","24.67514","0.12115"
"49403","296.38200","24.69870","0.12161"
"49450","296.66400","24.72214","0.12191"
"49497","296.94600","24.74569","0.12215"
"49544","297.22800","24.76919","0.12275"
"49591","297.51000","24.79269","0.12323"
"49638","297.79200","24.81624","0.12401"
"49685","298.07400","24.83974","0.12497"
"49732","298.35600","24.86318","0.12524"
"49779","298.63800","24.88667","0.12602"
"49826","298.92000","24.91023","0.12652"
"49873","299.20200","24.93373","0.12712"
"49920","299.48400","24.95729","0.12780"
"49967","299.76600","24.98073","0.12812"
"50014","300.04800","25.00428","0.12880"
"50061","300.33000","25.02772","0.12921"
"50108","300.61200","25.05122","0.12914"
"50155","300.89400","25.07465","0.12948"
"50202","301.17600","25.09821","0.13008"
"50249","301.45800","25.12171","0.13074"
"50296","301.74000","25.14526","0.13103"
"50343","302.02200","25.16870","0.13125"
"50390","302.30400","25.19226","0.13174"
"50437","302.58600","25.21576","0.13221"
"50484","302.86800","25.23919","0.13233"
"50531","303.15000","25.26269","0.13297"
"50578","303.43200","25.28619","0.13314"
"50625","303.71400","25.30975","0.13324"
"50672","303.99600","25.33319","0.13380"
"50719","304.27800","25.35674","0.13433"
"50766","304.56000","25.38018","0.13437"
"50813","304.84200","25.40373","0.13487"
"50860","305.12400","25.42711","0.13524"
"50907","305.40600","25.45073","0.13591"
"50954","305.68800","25.47417","0.05252"
"51001","305.97000","25.49772","-0.01456"
"51048","306.25200","25.52116","-0.00180"
"51095","306.53400","25.54478","-0.00454"
"51142","306.81600","25.56821","0.00049"
"51189","307.09800","25.59177","-0.00153"
"51236","307.38000","25.61521","-0.00174"
"51283","307.66200","25.63877","-0.00100"
"51330","307.94400","25.66227","0.00004"
"51377","308.22600","25.68576","0.00106"
"51424","308.50800","25.70920","-0.00044"
"51471","308.79000","25.73276","-0.00171"
"51518","309.07200","25.75626","-0.00128"
"51565","309.35400","25.77969","-0.00117"
"51612","309.63600","25.80319","-0.00109"
"51659","309.91800","25.82668","-0.00156"
"51706","310.20000","25.85025","-0.00268"
"51753","310.48200","25.87362","-0.00162"
"51800","310.76400","25.89718","-0.00134"
"51847","311.04600","25.92062","-0.00142"
"51894","311.32800","25.94417","-0.00155"
"51941","311.61000","25.96761","-0.00140"
"51988","311.89200","25.99123","-0.00104"
"52035","312.17400","26.01461","-0.00149"
"52082","312.45600","26.03822","-0.00116"
"52129","312.73800","26.06166","-0.00171"
"52176","313.02000","26.08522","-0.00136"
"52223","313.30200","26.10872","-0.00044"
"52270","313.58400","26.13221","-0.00143"
"52317","313.86600","26.15571","-0.00211"
"52364","314.14800","26.17921","-0.00189"
"52411","314.43000","26.20271","-0.00147"
"52458","314.71200","26.22626","-0.00074"
"52505","314.99400","26.24976","-0.00128"
"52552","315.27600","26.27320","-0.00161"
"52599","315.55800","26.29675","-0.00183"
"52646","315.84000","26.32019","-0.00109"
"52693","316.12200","26.34381","-0.00124"
"52740","316.40400","26.36719","-0.00183"
"52787","316.68600","26.39074","-0.00220"
"52834","316.96800","26.41418","-0.00228"
"52881","317.25000","26.43773","-0.00169"
"52928","317.53200","26.46117","-0.00150"
"52975","317.81400","26.48473","-0.00169"
"53022","318.09600","26.50817","-0.00199"
"53069","318.37800","26.53167","-0.00125"
"53116","318.66000","26.55516","-0.00112"
"53163","318.94200","26.57872","-0.00184"
"53210","319.22400","26.60216","-0.00221"
"53257","319.50600","26.62571","-0.00223"
"53304","319.78800","26.64921","-0.00095"
"53351","320.07000","26.67265","-0.00135"
"53398","320.35200","26.69621","-0.00158"
"53445","320.63400","26.71970","-0.00179"
"53492","320.91600","26.74320","-0.00138"
"53539","321.19800","26.76670","-0.00137"
"53586","321.48000","26.79031","-0.00149"
"53633","321.76200","26.81369","-0.00133"
"53680","322.04400","26.83725","-0.00206"
"53727","322.32600","26.86069","-0.00180"
"53774","322.60800","26.88424","-0.00102"
"53821","322.89000","26.90762","-0.00156"
"53868","323.17200","26.93118","-0.00115"
"53915","323.45400","26.95468","-0.00211"
"53962","323.73600","26.97823","-0.00096"
"54009","324.01800","27.00167","-0.00115"
"54056","324.30000","27.02523","-0.00138"
"54103","324.58200","27.04873","-0.00177"
"54150","324.86400","27.07222","-0.00177"
"54197","325.14600","27.09572","-0.00165"
"54244","325.42800","27.11922","-0.00181"
"54291","325.71000","27.14272","-0.00131"
"54338","325.99200","27.16621","-0.00157"
"54385","326.27400","27.18971","-0.00164"
"54432","326.55600","27.21314","-0.00156"
"54479","326.83800","27.23676","-0.00126"
"54526","327.12000","27.26020","-0.00207"
"54573","327.40200","27.28376","-0.00141"
"54620","327.68400","27.30713","-0.00090"
"54667","327.96600","27.33069","-0.00154"
"54714","328.24800","27.35419","-0.00169"
"54761","328.53000","27.37769","-0.00159"
"54808","328.81200","27.40112","-0.00124"
"54855","329.09400","27.42474","-0.00132"
"54902","329.37600","27.44818","-0.00136"
"54949","329.65800","27.47174","-0.00164"
"54996","329.94000","27.49511","-0.00172"
"55043","330.22200","27.51873","-0.00121"
"55090","330.50400","27.54217","-0.00174"
"55137","330.78600","27.56573","-0.00198"
"55184","331.06800","27.58916","-0.00225"
"55231","331.35000","27.61272","-0.00010"
"55278","331.63200","27.63622","-0.00099"
"55325","331.91400","27.65977","-0.00240"
"55372","332.19600","27.68321","-0.00212"
"55419","332.47800","27.70677","-0.00160"
"55466","332.76000","27.73027","-0.00107"
"55513","333.04200","27.75370","-0.00155"
"55560","333.32400","27.77726","-0.00153"
"55607","333.60600","27.80070","-0.00104"
"55654","333.88800","27.82426","-0.00155"
"55701","334.17000","27.84769","-0.00220"
"55748","334.45200","27.87119","-0.00172"
"55795","334.73400","27.89469","-0.00138"
"55842","335.01600","27.91818","-0.00173"
"55889","335.29800","27.94162","-0.00133"
"55936","335.58000","27.96518","-0.00143"
"55983","335.86200","27.98868","-0.00162"
"56030","336.14400","28.01224","-0.00207"
"56077","336.42600","28.03567","-0.00130"
"56124","336.70800","28.05923","-0.00141"
"56171","336.99000","28.08273","-0.00181"
"56218","337.27200","28.10616","-0.00225"
"56265","337.55400","28.12972","-0.00058"
"56312","337.83600","28.15322","-0.00122"
"56359","338.11800","28.17672","-0.00171"
"56406","338.40000","28.20021","-0.00131"
"56453","338.68200","28.22371","-0.00107"
"56500","338.96400","28.24721","-0.00194"
"56547","339.24600","28.27076","-0.00148"
"56594","339.52800","28.29420","-0.00229"
"56641","339.81000","28.31776","-0.00145"
"56688","340.09200","28.34120","-0.00146"
"56735","340.37400","28.36475","-0.00100"
"56782","340.65600","28.38819","-0.00132"
"56829","340.93800","28.41175","-0.00115"
"56876","341.22000","28.43519","-0.00139"
"56923","341.50200","28.45868","-0.00101"
"56970","341.78400","28.48218","-0.00183"
"57017","342.06600","28.50574","-0.00165"
"57064","342.34800","28.52917","-0.00214"
"57111","342.63000","28.55273","-0.00184"
"57158","342.91200","28.57617","-0.00182"
"57205","343.19400","28.59967","-0.00190"
"57252","343.47600","28.62322","-0.00240"
"57299","343.75800","28.64666","-0.00181"
"57346","344.04000","28.67016","-0.00133"
"57393","344.32200","28.69366","-0.00137"
"57440","344.60400","28.71721","-0.00198"
"57487","344.88600","28.74065","-0.00184"
"57534","345.16800","28.76427","-0.00193"
"57581","345.45000","28.78765","-0.00103"
"57628","345.73200","28.81120","-0.00228"
"57675","346.01400","28.83464","-0.00182"
"57722","346.29600","28.85820","-0.00254"
"57769","346.57800","28.88163","-0.00157"
"57816","346.86000","28.90525","-0.00165"
"57863","347.14200","28.92869","-0.00193"
"57910","347.42400","28.95225","-0.00159"
"57957","347.70600","28.97568","-0.00126"
"58004","347.98800","28.99924","-0.00134"
"58051","348.27000","29.02274","-0.00150"
"58098","348.55200","29.04629","-0.00225"
"58145","348.83400","29.06973","-0.00216"
"58192","349.11600","29.09323","-0.00169"
"58239","349.39800","29.11673","-0.00133"
"58267","349.56600","29.13072","-0.00201"