File: Trajectories_together/170108_2Specimen_RawData_8.csv
"","V1","V2","V3"
"1","End date","1/8/2017",""
"2","Specimen label","9BT_74_2",""
"3","Maximum Load","0.16759","N"
"4","Time","Extension","Load"
"5","(s)","(mm)","(N)"
"6","0.00000","17.88723","0.05831"
"16","0.06000","17.88849","0.05818"
"26","0.12000","17.89220","0.05878"
"36","0.18000","17.89812","0.05957"
"46","0.24000","17.90493","0.06067"
"56","0.30000","17.91145","0.06141"
"66","0.36000","17.91719","0.06192"
"76","0.42000","17.92245","0.06295"
"86","0.48000","17.92747","0.06335"
"96","0.54000","17.93244","0.06423"
"106","0.60000","17.93740","0.06443"
"116","0.66000","17.94236","0.06494"
"126","0.72000","17.94738","0.06603"
"136","0.78000","17.95240","0.06636"
"146","0.84000","17.95749","0.06665"
"156","0.90000","17.96239","0.06735"
"166","0.96000","17.96741","0.06747"
"176","1.02000","17.97237","0.06803"
"186","1.08000","17.97734","0.06847"
"196","1.14000","17.98236","0.06950"
"206","1.20000","17.98732","0.06974"
"216","1.26000","17.99240","0.06983"
"226","1.32000","17.99737","0.07074"
"236","1.38000","18.00239","0.07091"
"246","1.44000","18.00741","0.07123"
"256","1.50000","18.01237","0.07175"
"266","1.56000","18.01740","0.07210"
"276","1.62000","18.02230","0.07247"
"286","1.68000","18.02732","0.07264"
"296","1.74000","18.03240","0.07296"
"306","1.80000","18.03736","0.07274"
"316","1.86000","18.04245","0.07471"
"326","1.92000","18.04741","0.07344"
"336","1.98000","18.05243","0.07389"
"346","2.04000","18.05739","0.07456"
"356","2.10000","18.06236","0.07445"
"366","2.16000","18.06738","0.07489"
"376","2.22000","18.07228","0.07485"
"386","2.28000","18.07737","0.07499"
"396","2.34000","18.08233","0.07517"
"406","2.40000","18.08741","0.07492"
"416","2.46000","18.09243","0.07479"
"426","2.52000","18.09734","0.07482"
"436","2.58000","18.10236","0.07536"
"446","2.64000","18.10738","0.07488"
"456","2.70000","18.11234","0.07414"
"466","2.76000","18.11731","0.07405"
"476","2.82000","18.12227","0.07428"
"486","2.88000","18.12735","0.07454"
"496","2.94000","18.13237","0.07362"
"506","3.00000","18.13739","0.07354"
"516","3.06000","18.14235","0.07379"
"526","3.12000","18.14738","0.07407"
"536","3.18000","18.15240","0.07449"
"546","3.24000","18.15730","0.07425"
"556","3.30000","18.16233","0.07373"
"566","3.36000","18.16729","0.07349"
"576","3.42000","18.17237","0.07352"
"586","3.48000","18.17739","0.07377"
"596","3.54000","18.18242","0.07332"
"606","3.60000","18.18744","0.07301"
"616","3.66000","18.19234","0.07283"
"626","3.72000","18.19736","0.07300"
"636","3.78000","18.20233","0.07332"
"646","3.84000","18.20735","0.07375"
"656","3.90000","18.21231","0.07350"
"666","3.96000","18.21733","0.07384"
"676","4.02000","18.22241","0.07362"
"686","4.08000","18.22738","0.07333"
"696","4.14000","18.23240","0.07412"
"706","4.20000","18.23742","0.07448"
"716","4.26000","18.24232","0.07469"
"726","4.32000","18.24735","0.07453"
"736","4.38000","18.25231","0.07462"
"746","4.44000","18.25733","0.07476"
"756","4.50000","18.26235","0.07469"
"766","4.56000","18.26732","0.07504"
"776","4.62000","18.27234","0.07502"
"786","4.68000","18.27736","0.07519"
"796","4.74000","18.28238","0.07524"
"806","4.80000","18.28735","0.07541"
"816","4.86000","18.29231","0.07574"
"826","4.92000","18.29727","0.07581"
"836","4.98000","18.30229","0.07572"
"846","5.04000","18.30732","0.07579"
"856","5.10000","18.31234","0.07591"
"866","5.16000","18.31736","0.07642"
"876","5.22000","18.32232","0.07662"
"886","5.28000","18.32741","0.07654"
"896","5.34000","18.33237","0.07652"
"906","5.40000","18.33727","0.07649"
"916","5.46000","18.34235","0.07662"
"926","5.52000","18.34726","0.07694"
"936","5.58000","18.35240","0.07723"
"946","5.64000","18.35736","0.07704"
"956","5.70000","18.36238","0.07733"
"966","5.76000","18.36740","0.07729"
"976","5.82000","18.37237","0.07744"
"986","5.88000","18.37739","0.07757"
"996","5.94000","18.38229","0.07740"
"1006","6.00000","18.38737","0.07781"
"1016","6.06000","18.39234","0.07790"
"1026","6.12000","18.39730","0.07818"
"1036","6.18000","18.40238","0.07776"
"1046","6.24000","18.40734","0.07781"
"1056","6.30000","18.41237","0.07771"
"1066","6.36000","18.41739","0.07795"
"1076","6.42000","18.42235","0.07843"
"1086","6.48000","18.42731","0.07833"
"1096","6.54000","18.43228","0.07851"
"1106","6.60000","18.43730","0.07865"
"1116","6.66000","18.44232","0.07875"
"1126","6.72000","18.44734","0.07909"
"1136","6.78000","18.45230","0.07924"
"1146","6.84000","18.45733","0.07916"
"1156","6.90000","18.46235","0.07898"
"1166","6.96000","18.46737","0.07949"
"1176","7.02000","18.47233","0.07945"
"1186","7.08000","18.47730","0.07976"
"1196","7.14000","18.48226","0.07988"
"1206","7.20000","18.48734","0.07960"
"1216","7.26000","18.49236","0.07990"
"1226","7.32000","18.49739","0.08060"
"1236","7.38000","18.50235","0.08079"
"1246","7.44000","18.50737","0.08118"
"1256","7.50000","18.51233","0.08105"
"1266","7.56000","18.51736","0.08136"
"1276","7.62000","18.52232","0.08138"
"1286","7.68000","18.52728","0.08249"
"1296","7.74000","18.53230","0.08234"
"1306","7.80000","18.53739","0.08253"
"1316","7.86000","18.54235","0.08285"
"1326","7.92000","18.54737","0.08285"
"1336","7.98000","18.55233","0.08386"
"1346","8.04000","18.55729","0.08423"
"1356","8.10000","18.56238","0.08406"
"1366","8.16000","18.56728","0.08429"
"1376","8.22000","18.57230","0.08474"
"1386","8.28000","18.57733","0.08527"
"1396","8.34000","18.58235","0.08548"
"1406","8.40000","18.58737","0.08572"
"1416","8.46000","18.59239","0.08615"
"1426","8.52000","18.59741","0.08721"
"1436","8.58000","18.60238","0.08794"
"1446","8.64000","18.60734","0.08875"
"1456","8.70000","18.61230","0.08889"
"1466","8.76000","18.61738","0.08932"
"1476","8.82000","18.62235","0.08980"
"1486","8.88000","18.62743","0.09002"
"1496","8.94000","18.63233","0.09049"
"1506","9.00000","18.63735","0.09086"
"1516","9.06000","18.64238","0.09065"
"1526","9.12000","18.64734","0.09105"
"1536","9.18000","18.65236","0.09149"
"1546","9.24000","18.65732","0.09178"
"1556","9.30000","18.66235","0.09171"
"1566","9.36000","18.66731","0.09254"
"1576","9.42000","18.67233","0.09291"
"1586","9.48000","18.67735","0.09367"
"1596","9.54000","18.68237","0.09549"
"1606","9.60000","18.68740","0.09524"
"1616","9.66000","18.69230","0.09579"
"1626","9.72000","18.69732","0.09638"
"1636","9.78000","18.70234","0.09607"
"1646","9.84000","18.70731","0.09675"
"1656","9.90000","18.71233","0.09823"
"1666","9.96000","18.71735","0.09826"
"1676","10.02000","18.72237","0.09864"
"1686","10.08000","18.72734","0.09899"
"1696","10.14000","18.73236","0.10064"
"1706","10.20000","18.73738","0.10090"
"1716","10.26000","18.74228","0.10208"
"1726","10.32000","18.74737","0.10190"
"1736","10.38000","18.75233","0.10321"
"1746","10.44000","18.75735","0.10366"
"1756","10.50000","18.76237","0.10389"
"1766","10.56000","18.76734","0.10457"
"1776","10.62000","18.77236","0.10460"
"1786","10.68000","18.77738","0.10556"
"1796","10.74000","18.78240","0.10721"
"1806","10.80000","18.78731","0.10781"
"1816","10.86000","18.79227","0.10695"
"1826","10.92000","18.79735","0.10742"
"1836","10.98000","18.80237","0.10949"
"1846","11.04000","18.80740","0.10939"
"1856","11.10000","18.81236","0.10948"
"1866","11.16000","18.81738","0.11080"
"1876","11.22000","18.82234","0.11078"
"1886","11.28000","18.82731","0.11174"
"1896","11.34000","18.83233","0.11210"
"1906","11.40000","18.83729","0.11208"
"1916","11.46000","18.84231","0.11247"
"1926","11.52000","18.84734","0.11450"
"1936","11.58000","18.85236","0.11427"
"1946","11.64000","18.85738","0.11548"
"1956","11.70000","18.86240","0.11667"
"1966","11.76000","18.86736","0.11718"
"1976","11.82000","18.87233","0.11820"
"1986","11.88000","18.87735","0.11823"
"1996","11.94000","18.88231","0.11893"
"2006","12.00000","18.88733","0.11938"
"2016","12.06000","18.89236","0.12001"
"2026","12.12000","18.89738","0.12046"
"2036","12.18000","18.90240","0.12188"
"2046","12.24000","18.90736","0.12294"
"2056","12.30000","18.91233","0.12333"
"2066","12.36000","18.91735","0.12483"
"2076","12.42000","18.92231","0.12502"
"2086","12.48000","18.92733","0.12551"
"2096","12.54000","18.93230","0.12685"
"2106","12.60000","18.93738","0.12699"
"2116","12.66000","18.94240","0.12815"
"2126","12.72000","18.94736","0.12940"
"2136","12.78000","18.95238","0.12902"
"2146","12.84000","18.95729","0.12973"
"2156","12.90000","18.96237","0.13060"
"2166","12.96000","18.96727","0.13093"
"2176","13.02000","18.97229","0.13157"
"2186","13.08000","18.97732","0.13237"
"2196","13.14000","18.98234","0.13283"
"2206","13.20000","18.98736","0.13325"
"2216","13.26000","18.99232","0.13237"
"2226","13.32000","18.99741","0.12984"
"2236","13.38000","19.00237","0.13019"
"2246","13.44000","19.00733","0.13014"
"2256","13.50000","19.01235","0.13193"
"2266","13.56000","19.01732","0.13279"
"2276","13.62000","19.02234","0.13292"
"2286","13.68000","19.02730","0.13299"
"2296","13.74000","19.03232","0.13379"
"2306","13.80000","19.03735","0.13454"
"2316","13.86000","19.04237","0.13454"
"2326","13.92000","19.04739","0.13481"
"2336","13.98000","19.05229","0.13501"
"2346","14.04000","19.05732","0.13182"
"2356","14.10000","19.06228","0.12729"
"2366","14.16000","19.06730","0.12586"
"2376","14.22000","19.07238","0.12746"
"2386","14.28000","19.07734","0.12727"
"2396","14.34000","19.08237","0.12761"
"2406","14.40000","19.08739","0.12797"
"2416","14.46000","19.09235","0.12828"
"2426","14.52000","19.09737","0.12912"
"2436","14.58000","19.10228","0.13055"
"2446","14.64000","19.10736","0.13091"
"2456","14.70000","19.11232","0.13222"
"2466","14.76000","19.11734","0.13274"
"2476","14.82000","19.12237","0.13223"
"2486","14.88000","19.12739","0.13214"
"2496","14.94000","19.13241","0.13264"
"2506","15.00000","19.13737","0.13312"
"2516","15.06000","19.14240","0.13368"
"2526","15.12000","19.14730","0.13312"
"2536","15.18000","19.15232","0.13327"
"2546","15.24000","19.15734","0.13140"
"2556","15.30000","19.16237","0.12935"
"2566","15.36000","19.16739","0.10370"
"2576","15.42000","19.17235","0.10524"
"2586","15.48000","19.17737","0.10600"
"2596","15.54000","19.18240","0.10597"
"2606","15.60000","19.18736","0.10445"
"2616","15.66000","19.19232","0.10332"
"2626","15.72000","19.19734","0.10400"
"2636","15.78000","19.20230","0.10366"
"2646","15.84000","19.20739","0.10554"
"2656","15.90000","19.21235","0.10736"
"2666","15.96000","19.21731","0.10839"
"2676","16.02000","19.22234","0.10932"
"2686","16.08000","19.22736","0.10790"
"2696","16.14000","19.23238","0.10802"
"2706","16.20000","19.23734","0.10774"
"2716","16.26000","19.24231","0.10981"
"2726","16.32000","19.24733","0.11253"
"2736","16.38000","19.25235","0.11353"
"2746","16.44000","19.25737","0.11399"
"2756","16.50000","19.26239","0.11256"
"2766","16.56000","19.26736","0.11146"
"2776","16.62000","19.27238","0.11220"
"2786","16.68000","19.27734","0.11366"
"2796","16.74000","19.28236","0.11583"
"2806","16.80000","19.28739","0.11877"
"2816","16.86000","19.29235","0.11847"
"2826","16.92000","19.29737","0.11750"
"2836","16.98000","19.30239","0.11657"
"2846","17.04000","19.30742","0.11746"
"2856","17.10000","19.31238","0.11766"
"2866","17.16000","19.31734","0.11981"
"2876","17.22000","19.32236","0.12319"
"2886","17.28000","19.32733","0.12222"
"2896","17.34000","19.33235","0.12105"
"2906","17.40000","19.33731","0.12028"
"2916","17.46000","19.34233","0.12035"
"2926","17.52000","19.34741","0.12274"
"2936","17.58000","19.35232","0.12456"
"2946","17.64000","19.35740","0.12572"
"2956","17.70000","19.36230","0.12629"
"2966","17.76000","19.36732","0.12503"
"2976","17.82000","19.37229","0.12442"
"2986","17.88000","19.37725","0.12483"
"2996","17.94000","19.38239","0.12664"
"3006","18.00000","19.38736","0.12838"
"3016","18.06000","19.39238","0.12930"
"3026","18.12000","19.39734","0.13021"
"3036","18.18000","19.40236","0.12959"
"3046","18.24000","19.40738","0.12775"
"3056","18.30000","19.41229","0.12847"
"3066","18.36000","19.41737","0.12970"
"3076","18.42000","19.42233","0.13194"
"3086","18.48000","19.42735","0.13197"
"3096","18.54000","19.43232","0.12144"
"3106","18.60000","19.43728","0.11934"
"3116","18.66000","19.44230","0.11733"
"3126","18.72000","19.44732","0.11775"
"3136","18.78000","19.45241","0.11447"
"3146","18.84000","19.45731","0.10735"
"3156","18.90000","19.46227","0.10366"
"3166","18.96000","19.46729","0.10400"
"3176","19.02000","19.47232","0.10638"
"3186","19.08000","19.47740","0.11003"
"3196","19.14000","19.48236","0.10847"
"3206","19.20000","19.48738","0.10620"
"3216","19.26000","19.49240","0.10688"
"3226","19.32000","19.49737","0.11032"
"3236","19.38000","19.50233","0.11353"
"3246","19.44000","19.50735","0.11288"
"3256","19.50000","19.51231","0.10869"
"3266","19.56000","19.51734","0.10668"
"3276","19.62000","19.52236","0.10976"
"3286","19.68000","19.52738","0.11423"
"3296","19.74000","19.53234","0.11687"
"3306","19.80000","19.53737","0.11502"
"3316","19.86000","19.54239","0.11223"
"3326","19.92000","19.54735","0.11449"
"3336","19.98000","19.55231","0.11762"
"3346","20.04000","19.55728","0.11857"
"3356","20.10000","19.56236","0.11663"
"3366","20.16000","19.56738","0.11686"
"3376","20.22000","19.57240","0.09384"
"3386","20.28000","19.57737","0.05381"
"3396","20.34000","19.58239","0.05385"
"3406","20.40000","19.58741","0.05971"
"3416","20.46000","19.59231","0.06125"
"3426","20.52000","19.59733","0.05722"
"3436","20.58000","19.60224","0.05724"
"3446","20.64000","19.60738","0.05957"
"3456","20.70000","19.61240","0.06155"
"3466","20.76000","19.61736","0.06071"
"3476","20.82000","19.62239","0.06051"
"3486","20.88000","19.62735","0.06136"
"3496","20.94000","19.63237","0.06490"
"3506","21.00000","19.63733","0.06624"
"3516","21.06000","19.64236","0.06314"
"3526","21.12000","19.64726","0.05808"
"3536","21.18000","19.65234","0.05523"
"3546","21.24000","19.65736","0.05693"
"3556","21.30000","19.66238","0.06238"
"3566","21.36000","19.66741","0.06698"
"3576","21.42000","19.67237","0.06590"
"3586","21.48000","19.67733","0.06205"
"3596","21.54000","19.68236","0.06028"
"3606","21.60000","19.68732","0.06183"
"3616","21.66000","19.69234","0.06567"
"3626","21.72000","19.69730","0.06656"
"3636","21.78000","19.70232","0.06584"
"3646","21.84000","19.70741","0.06594"
"3656","21.90000","19.71237","0.06766"
"3666","21.96000","19.71739","0.06937"
"3676","22.02000","19.72229","0.06877"
"3686","22.08000","19.72732","0.06506"
"3696","22.14000","19.73228","0.06286"
"3706","22.20000","19.73730","0.06379"
"3716","22.26000","19.74232","0.06844"
"3726","22.32000","19.74735","0.07121"
"3736","22.38000","19.75243","0.07078"
"3746","22.44000","19.75733","0.06780"
"3756","22.50000","19.76241","0.06478"
"3766","22.56000","19.76731","0.06574"
"3776","22.62000","19.77234","0.06862"
"3786","22.68000","19.77736","0.07075"
"3796","22.74000","19.78226","0.07021"
"3806","22.80000","19.78735","0.06997"
"3816","22.86000","19.79231","0.07041"
"3826","22.92000","19.79733","0.07140"
"3836","22.98000","19.80235","0.07140"
"3846","23.04000","19.80738","0.07006"
"3856","23.10000","19.81240","0.06846"
"3866","23.16000","19.81736","0.06965"
"3876","23.22000","19.82232","0.07214"
"3886","23.28000","19.82728","0.07387"
"3896","23.34000","19.83231","0.07365"
"3906","23.40000","19.83733","0.07153"
"3916","23.46000","19.84235","0.06967"
"3926","23.52000","19.84737","0.07038"
"3936","23.58000","19.85240","0.07212"
"3946","23.64000","19.85736","0.07408"
"3956","23.70000","19.86232","0.07408"
"3966","23.76000","19.86728","0.07340"
"3976","23.82000","19.87231","0.07326"
"3986","23.88000","19.87733","0.07367"
"3996","23.94000","19.88235","0.07409"
"4006","24.00000","19.88732","0.07373"
"4016","24.06000","19.89233","0.07340"
"4026","24.12000","19.89736","0.07409"
"4036","24.18000","19.90232","0.07496"
"4046","24.24000","19.90734","0.07590"
"4056","24.30000","19.91231","0.07561"
"4066","24.36000","19.91733","0.07435"
"4076","24.42000","19.92235","0.07344"
"4086","24.48000","19.92737","0.07436"
"4096","24.54000","19.93239","0.07546"
"4106","24.60000","19.93736","0.07614"
"4116","24.66000","19.94238","0.07616"
"4126","24.72000","19.94734","0.07578"
"4136","24.78000","19.95237","0.07546"
"4146","24.84000","19.95733","0.07587"
"4156","24.90000","19.96235","0.07599"
"4166","24.96000","19.96737","0.07590"
"4176","25.02000","19.97239","0.07628"
"4186","25.08000","19.97742","0.07649"
"4196","25.14000","19.98238","0.07707"
"4206","25.20000","19.98734","0.07725"
"4216","25.26000","19.99242","0.07693"
"4226","25.32000","19.99739","0.07621"
"4236","25.38000","20.00235","0.07614"
"4246","25.44000","20.00737","0.07661"
"4256","25.50000","20.01233","0.07742"
"4266","25.56000","20.01735","0.07778"
"4276","25.62000","20.02232","0.07748"
"4286","25.68000","20.02740","0.07729"
"4296","25.74000","20.03236","0.07700"
"4306","25.80000","20.03739","0.07734"
"4316","25.86000","20.04229","0.07774"
"4326","25.92000","20.04731","0.07787"
"4336","25.98000","20.05233","0.07785"
"4346","26.04000","20.05736","0.07810"
"4356","26.10000","20.06238","0.07841"
"4366","26.16000","20.06734","0.07830"
"4376","26.22000","20.07236","0.07803"
"4386","26.28000","20.07738","0.07784"
"4396","26.34000","20.08229","0.07823"
"4406","26.40000","20.08737","0.07905"
"4416","26.46000","20.09233","0.07945"
"4426","26.52000","20.09735","0.07947"
"4436","26.58000","20.10232","0.07898"
"4446","26.64000","20.10734","0.07862"
"4456","26.70000","20.11236","0.07896"
"4466","26.76000","20.11732","0.07925"
"4476","26.82000","20.12234","0.08006"
"4486","26.88000","20.12731","0.08047"
"4496","26.94000","20.13233","0.08038"
"4506","27.00000","20.13735","0.08041"
"4516","27.06000","20.14232","0.08049"
"4526","27.12000","20.14734","0.08050"
"4536","27.18000","20.15236","0.08036"
"4546","27.24000","20.15738","0.08046"
"4556","27.30000","20.16241","0.08156"
"4566","27.36000","20.16737","0.08271"
"4576","27.42000","20.17239","0.08339"
"4586","27.48000","20.17735","0.08238"
"4596","27.54000","20.18232","0.08177"
"4606","27.60000","20.18734","0.08157"
"4616","27.66000","20.19236","0.08254"
"4626","27.72000","20.19738","0.08406"
"4636","27.78000","20.20234","0.08460"
"4646","27.84000","20.20737","0.08495"
"4656","27.90000","20.21239","0.08401"
"4666","27.96000","20.21741","0.08449"
"4676","28.02000","20.22231","0.08449"
"4686","28.08000","20.22728","0.08502"
"4696","28.14000","20.23236","0.08561"
"4706","28.20000","20.23738","0.08598"
"4716","28.26000","20.24246","0.08790"
"4726","28.32000","20.24736","0.08845"
"4736","28.38000","20.25233","0.08806"
"4746","28.44000","20.25729","0.08656"
"4756","28.50000","20.26231","0.08703"
"4766","28.56000","20.26734","0.08886"
"4776","28.62000","20.27230","0.09023"
"4786","28.68000","20.27732","0.09125"
"4796","28.74000","20.28234","0.09055"
"4806","28.80000","20.28736","0.09031"
"4816","28.86000","20.29233","0.09049"
"4826","28.92000","20.29735","0.09134"
"4836","28.98000","20.30237","0.09209"
"4846","29.04000","20.30734","0.09226"
"4856","29.10000","20.31236","0.09327"
"4866","29.16000","20.31726","0.09459"
"4876","29.22000","20.32228","0.09503"
"4886","29.28000","20.32737","0.09469"
"4896","29.34000","20.33239","0.09410"
"4906","29.40000","20.33741","0.09439"
"4916","29.46000","20.34237","0.09630"
"4926","29.52000","20.34739","0.09770"
"4936","29.58000","20.35236","0.09899"
"4946","29.64000","20.35732","0.09839"
"4956","29.70000","20.36228","0.09791"
"4966","29.76000","20.36730","0.09801"
"4976","29.82000","20.37239","0.09921"
"4986","29.88000","20.37741","0.09999"
"4996","29.94000","20.38237","0.10152"
"5006","30.00000","20.38739","0.10148"
"5016","30.06000","20.39235","0.10227"
"5026","30.12000","20.39738","0.10320"
"5036","30.18000","20.40234","0.10261"
"5046","30.24000","20.40730","0.10272"
"5056","30.30000","20.41226","0.10289"
"5066","30.36000","20.41729","0.10412"
"5076","30.42000","20.42243","0.10627"
"5086","30.48000","20.42739","0.10626"
"5096","30.54000","20.43242","0.10671"
"5106","30.60000","20.43732","0.10626"
"5116","30.66000","20.44234","0.10621"
"5126","30.72000","20.44730","0.10768"
"5136","30.78000","20.45226","0.10898"
"5146","30.84000","20.45735","0.10961"
"5156","30.90000","20.46231","0.11005"
"5166","30.96000","20.46733","0.11017"
"5176","31.02000","20.47235","0.11103"
"5186","31.08000","20.47738","0.11110"
"5196","31.14000","20.48240","0.11171"
"5206","31.20000","20.48730","0.11283"
"5216","31.26000","20.49232","0.11338"
"5226","31.32000","20.49728","0.11597"
"5236","31.38000","20.50231","0.11606"
"5246","31.44000","20.50733","0.11523"
"5256","31.50000","20.51235","0.11514"
"5266","31.56000","20.51738","0.11706"
"5276","31.62000","20.52234","0.11844"
"5286","31.68000","20.52736","0.11980"
"5296","31.74000","20.53232","0.11985"
"5306","31.80000","20.53728","0.12037"
"5316","31.86000","20.54231","0.12058"
"5326","31.92000","20.54727","0.12094"
"5336","31.98000","20.55235","0.12219"
"5346","32.04000","20.55737","0.12295"
"5356","32.10000","20.56234","0.12445"
"5366","32.16000","20.56736","0.12539"
"5376","32.22000","20.57232","0.12528"
"5386","32.28000","20.57740","0.12632"
"5396","32.34000","20.58237","0.12602"
"5406","32.40000","20.58727","0.12605"
"5416","32.46000","20.59229","0.12767"
"5426","32.52000","20.59731","0.12831"
"5436","32.58000","20.60240","0.12892"
"5446","32.64000","20.60736","0.12968"
"5456","32.70000","20.61238","0.12986"
"5466","32.76000","20.61740","0.12945"
"5476","32.82000","20.62230","0.12973"
"5486","32.88000","20.62733","0.13120"
"5496","32.94000","20.63223","0.13223"
"5506","33.00000","20.63731","0.13298"
"5516","33.06000","20.64234","0.13333"
"5526","33.12000","20.64736","0.13380"
"5536","33.18000","20.65238","0.13374"
"5546","33.24000","20.65734","0.13338"
"5556","33.30000","20.66236","0.13399"
"5566","33.36000","20.66733","0.13433"
"5576","33.42000","20.67235","0.13488"
"5586","33.48000","20.67725","0.13519"
"5596","33.54000","20.68234","0.13584"
"5606","33.60000","20.68736","0.13538"
"5616","33.66000","20.69238","0.13607"
"5626","33.72000","20.69740","0.13666"
"5636","33.78000","20.70237","0.13677"
"5646","33.84000","20.70739","0.13702"
"5656","33.90000","20.71235","0.13737"
"5666","33.96000","20.71731","0.13711"
"5676","34.02000","20.72234","0.13723"
"5686","34.08000","20.72729","0.13743"
"5696","34.14000","20.73238","0.13797"
"5706","34.20000","20.73740","0.13790"
"5716","34.26000","20.74236","0.13826"
"5726","34.32000","20.74739","0.13855"
"5736","34.38000","20.75235","0.13822"
"5746","34.44000","20.75737","0.13861"
"5756","34.50000","20.76233","0.13872"
"5766","34.56000","20.76736","0.13887"
"5776","34.62000","20.77232","0.13920"
"5786","34.68000","20.77740","0.13941"
"5796","34.74000","20.78242","0.13964"
"5806","34.80000","20.78733","0.13922"
"5816","34.86000","20.79235","0.13970"
"5826","34.92000","20.79731","0.14042"
"5836","34.98000","20.80233","0.14087"
"5846","35.04000","20.80736","0.14054"
"5856","35.10000","20.81232","0.14107"
"5866","35.16000","20.81734","0.14152"
"5876","35.22000","20.82236","0.14212"
"5886","35.28000","20.82738","0.14177"
"5896","35.34000","20.83241","0.14230"
"5906","35.40000","20.83737","0.14301"
"5916","35.46000","20.84233","0.14373"
"5926","35.52000","20.84729","0.14406"
"5936","35.58000","20.85232","0.14450"
"5946","35.64000","20.85728","0.14452"
"5956","35.70000","20.86236","0.14484"
"5966","35.76000","20.86738","0.14548"
"5976","35.82000","20.87235","0.14595"
"5986","35.88000","20.87743","0.14624"
"5996","35.94000","20.88239","0.14663"
"6006","36.00000","20.88741","0.14694"
"6016","36.06000","20.89231","0.14745"
"6026","36.12000","20.89728","0.14845"
"6036","36.18000","20.90230","0.14895"
"6046","36.24000","20.90738","0.14921"
"6056","36.30000","20.91235","0.14987"
"6066","36.36000","20.91737","0.15105"
"6076","36.42000","20.92233","0.15113"
"6086","36.48000","20.92735","0.15187"
"6096","36.54000","20.93238","0.15225"
"6106","36.60000","20.93734","0.15237"
"6116","36.66000","20.94230","0.15413"
"6126","36.72000","20.94726","0.15387"
"6136","36.78000","20.95234","0.15424"
"6146","36.84000","20.95737","0.15467"
"6156","36.90000","20.96239","0.15533"
"6166","36.96000","20.96735","0.15565"
"6176","37.02000","20.97237","0.15618"
"6186","37.08000","20.97733","0.15735"
"6196","37.14000","20.98236","0.15755"
"6206","37.20000","20.98732","0.15788"
"6216","37.26000","20.99228","0.15868"
"6226","37.32000","20.99737","0.15872"
"6236","37.38000","21.00233","0.15869"
"6246","37.44000","21.00741","0.15999"
"6256","37.50000","21.01237","0.16050"
"6266","37.56000","21.01740","0.16128"
"6276","37.62000","21.02236","0.16097"
"6286","37.68000","21.02732","0.16137"
"6296","37.74000","21.03234","0.16204"
"6306","37.80000","21.03725","0.16227"
"6316","37.86000","21.04239","0.16284"
"6326","37.92000","21.04741","0.16359"
"6336","37.98000","21.05237","0.16395"
"6346","38.04000","21.05739","0.16503"
"6356","38.10000","21.06236","0.16474"
"6366","38.16000","21.06738","0.16526"
"6376","38.22000","21.07228","0.16600"
"6386","38.28000","21.07730","0.16703"
"6396","38.34000","21.08227","0.16680"
"6406","38.40000","21.08729","0.16725"
"6416","38.46000","21.09237","0.16743"
"6426","38.52000","21.09739","0.16757"
"6436","38.58000","21.10242","0.07645"
"6446","38.64000","21.10738","0.01253"
"6456","38.70000","21.11234","0.02207"
"6466","38.76000","21.11730","0.04344"
"6476","38.82000","21.12233","0.04118"
"6486","38.88000","21.12735","0.02152"
"6496","38.94000","21.13231","0.02294"
"6506","39.00000","21.13733","0.01197"
"6516","39.06000","21.14236","0.01486"
"6526","39.12000","21.14738","0.03217"
"6536","39.18000","21.15240","0.03467"
"6546","39.24000","21.15730","0.03954"
"6556","39.30000","21.16232","0.03992"
"6566","39.36000","21.16729","0.02519"
"6576","39.42000","21.17231","0.01618"
"6586","39.48000","21.17733","0.01636"
"6596","39.54000","21.18230","0.02368"
"6606","39.60000","21.18738","0.02735"
"6616","39.66000","21.19234","0.03157"
"6626","39.72000","21.19736","0.03118"
"6636","39.78000","21.20232","0.02974"
"6646","39.84000","21.20735","0.03558"
"6656","39.90000","21.21231","0.03357"
"6666","39.96000","21.21727","0.02767"
"6676","40.02000","21.22235","0.02914"
"6686","40.08000","21.22744","0.02709"
"6696","40.14000","21.23240","0.03001"
"6706","40.20000","21.23736","0.03069"
"6716","40.26000","21.24238","0.02863"
"6726","40.32000","21.24735","0.02231"
"6736","40.38000","21.25237","0.02064"
"6746","40.44000","21.25733","0.02802"
"6756","40.50000","21.26235","0.02886"
"6766","40.56000","21.26738","0.03619"
"6776","40.62000","21.27240","0.03651"
"6786","40.68000","21.27736","0.02931"
"6796","40.74000","21.28238","0.02780"
"6806","40.80000","21.28741","0.02439"
"6816","40.86000","21.29237","0.02359"
"6826","40.92000","21.29739","0.02462"
"6836","40.98000","21.30235","0.02785"
"6846","41.04000","21.30732","0.02853"
"6856","41.10000","21.31234","0.03038"
"6866","41.16000","21.31736","0.03349"
"6876","41.22000","21.32232","0.03210"
"6886","41.28000","21.32734","0.03251"
"6896","41.34000","21.33243","0.03039"
"6906","41.40000","21.33733","0.02667"
"6916","41.46000","21.34235","0.02767"
"6926","41.52000","21.34725","0.03014"
"6936","41.58000","21.35228","0.03049"
"6946","41.64000","21.35730","0.02828"
"6956","41.70000","21.36232","0.02612"
"6966","41.76000","21.36740","0.02677"
"6976","41.82000","21.37236","0.03045"
"6986","41.88000","21.37739","0.03330"
"6996","41.94000","21.38235","0.03361"
"7006","42.00000","21.38731","0.03140"
"7016","42.06000","21.39233","0.02941"
"7026","42.12000","21.39730","0.02790"
"7036","42.18000","21.40238","0.02809"
"7046","42.24000","21.40734","0.02790"
"7056","42.30000","21.41243","0.02785"
"7066","42.36000","21.41733","0.02869"
"7076","42.42000","21.42235","0.03056"
"7086","42.48000","21.42737","0.03364"
"7096","42.54000","21.43234","0.03585"
"7106","42.60000","21.43736","0.03482"
"7116","42.66000","21.44232","0.03086"
"7126","42.72000","21.44734","0.02912"
"7136","42.78000","21.45237","0.02873"
"7146","42.84000","21.45733","0.02945"
"7156","42.90000","21.46241","0.03051"
"7166","42.96000","21.46737","0.03035"
"7176","43.02000","21.47233","0.02915"
"7186","43.08000","21.47730","0.02973"
"7196","43.14000","21.48226","0.03195"
"7206","43.20000","21.48734","0.03327"
"7216","43.26000","21.49230","0.03425"
"7226","43.32000","21.49739","0.03171"
"7236","43.38000","21.50235","0.03030"
"7246","43.44000","21.50737","0.02997"
"7256","43.50000","21.51233","0.03010"
"7266","43.56000","21.51730","0.02980"
"7276","43.62000","21.52232","0.02938"
"7286","43.68000","21.52728","0.02985"
"7296","43.74000","21.53230","0.03155"
"7306","43.80000","21.53733","0.03536"
"7316","43.86000","21.54235","0.03719"
"7326","43.92000","21.54737","0.03543"
"7336","43.98000","21.55239","0.03254"
"7346","44.04000","21.55735","0.03052"
"7356","44.10000","21.56232","0.02987"
"7366","44.16000","21.56734","0.03033"
"7376","44.22000","21.57230","0.03097"
"7386","44.28000","21.57732","0.03092"
"7396","44.34000","21.58229","0.03173"
"7406","44.40000","21.58737","0.03304"
"7416","44.46000","21.59233","0.03528"
"7426","44.52000","21.59742","0.03680"
"7436","44.58000","21.60238","0.03367"
"7446","44.64000","21.60734","0.03172"
"7456","44.70000","21.61230","0.03127"
"7466","44.76000","21.61727","0.03146"
"7476","44.82000","21.62235","0.03208"
"7486","44.88000","21.62737","0.03161"
"7496","44.94000","21.63239","0.03139"
"7506","45.00000","21.63735","0.03266"
"7516","45.06000","21.64244","0.03560"
"7526","45.12000","21.64740","0.03888"
"7536","45.18000","21.65236","0.03872"
"7546","45.24000","21.65732","0.03568"
"7556","45.30000","21.66228","0.03310"
"7566","45.36000","21.66731","0.03208"
"7576","45.42000","21.67233","0.03189"
"7586","45.48000","21.67741","0.03179"
"7596","45.54000","21.68237","0.03223"
"7606","45.60000","21.68734","0.03379"
"7616","45.66000","21.69230","0.03689"
"7626","45.72000","21.69732","0.04029"
"7636","45.78000","21.70229","0.03979"
"7646","45.84000","21.70725","0.03624"
"7656","45.90000","21.71233","0.03342"
"7666","45.96000","21.71735","0.03263"
"7676","46.02000","21.72237","0.03272"
"7686","46.08000","21.72734","0.03375"
"7696","46.14000","21.73236","0.03459"
"7706","46.20000","21.73738","0.03520"
"7716","46.26000","21.74234","0.03797"
"7726","46.32000","21.74737","0.03995"
"7736","46.38000","21.75227","0.04149"
"7746","46.44000","21.75729","0.04009"
"7756","46.50000","21.76237","0.03826"
"7766","46.56000","21.76740","0.03601"
"7776","46.62000","21.77242","0.03531"
"7786","46.68000","21.77738","0.03451"
"7796","46.74000","21.78234","0.03454"
"7806","46.80000","21.78736","0.03533"
"7816","46.86000","21.79233","0.03837"
"7826","46.92000","21.79735","0.04307"
"7836","46.98000","21.80231","0.04498"
"7846","47.04000","21.80733","0.04400"
"7856","47.10000","21.81242","0.03957"
"7866","47.16000","21.81738","0.03615"
"7876","47.22000","21.82240","0.03528"
"7886","47.28000","21.82737","0.03544"
"7896","47.34000","21.83239","0.03712"
"7906","47.40000","21.83735","0.03983"
"7916","47.46000","21.84237","0.04331"
"7926","47.52000","21.84734","0.04627"
"7936","47.58000","21.85229","0.04737"
"7946","47.64000","21.85738","0.04488"
"7956","47.70000","21.86234","0.04159"
"7966","47.76000","21.86736","0.04010"
"7976","47.82000","21.87239","0.03965"
"7986","47.88000","21.87735","0.04037"
"7996","47.94000","21.88231","0.04092"
"8006","48.00000","21.88727","0.04064"
"8016","48.06000","21.89235","0.04427"
"8026","48.12000","21.89738","0.04719"
"8036","48.18000","21.90234","0.04915"
"8046","48.24000","21.90736","0.04757"
"8056","48.30000","21.91238","0.04473"
"8066","48.36000","21.91741","0.04249"
"8076","48.42000","21.92237","0.04213"
"8086","48.48000","21.92733","0.04098"
"8096","48.54000","21.93236","0.04152"
"8106","48.60000","21.93738","0.04405"
"8116","48.66000","21.94240","0.04779"
"8126","48.72000","21.94736","0.05104"
"8136","48.78000","21.95244","0.05173"
"8146","48.84000","21.95741","0.04895"
"8156","48.90000","21.96237","0.04634"
"8166","48.96000","21.96733","0.04496"
"8176","49.02000","21.97230","0.04352"
"8186","49.08000","21.97732","0.04414"
"8196","49.14000","21.98228","0.04654"
"8206","49.20000","21.98736","0.04921"
"8216","49.26000","21.99232","0.05163"
"8226","49.32000","21.99735","0.05185"
"8236","49.38000","22.00237","0.05224"
"8246","49.44000","22.00739","0.05023"
"8256","49.50000","22.01235","0.04835"
"8266","49.56000","22.01731","0.04785"
"8276","49.62000","22.02228","0.04658"
"8286","49.68000","22.02730","0.04744"
"8296","49.74000","22.03238","0.04861"
"8306","49.80000","22.03735","0.05082"
"8316","49.86000","22.04237","0.05298"
"8326","49.92000","22.04739","0.05434"
"8336","49.98000","22.05235","0.05396"
"8346","50.04000","22.05732","0.05275"
"8356","50.10000","22.06228","0.05058"
"8366","50.16000","22.06724","0.04965"
"8376","50.22000","22.07238","0.04934"
"8386","50.28000","22.07735","0.04988"
"8396","50.34000","22.08243","0.05266"
"8406","50.40000","22.08739","0.05444"
"8416","50.46000","22.09235","0.05586"
"8426","50.52000","22.09738","0.05631"
"8436","50.58000","22.10233","0.05434"
"8446","50.64000","22.10736","0.05335"
"8456","50.70000","22.11232","0.05118"
"8466","50.76000","22.11734","0.05079"
"8476","50.82000","22.12230","0.05209"
"8486","50.88000","22.12733","0.05349"
"8496","50.94000","22.13235","0.05540"
"8506","51.00000","22.13731","0.05657"
"8516","51.06000","22.14240","0.05755"
"8526","51.12000","22.14730","0.05646"
"8536","51.18000","22.15232","0.05549"
"8546","51.24000","22.15728","0.05445"
"8556","51.30000","22.16225","0.05381"
"8566","51.36000","22.16739","0.05436"
"8576","51.42000","22.17241","0.05486"
"8586","51.48000","22.17737","0.05613"
"8596","51.54000","22.18234","0.05772"
"8606","51.60000","22.18736","0.05872"
"8616","51.66000","22.19238","0.05886"
"8626","51.72000","22.19734","0.05788"
"8636","51.78000","22.20237","0.05639"
"8646","51.84000","22.20733","0.05606"
"8656","51.90000","22.21241","0.05549"
"8666","51.96000","22.21743","0.05600"
"8676","52.02000","22.22239","0.05762"
"8686","52.08000","22.22736","0.05907"
"8696","52.14000","22.23238","0.06092"
"8706","52.20000","22.23734","0.06079"
"8716","52.26000","22.24230","0.05987"
"8726","52.32000","22.24733","0.05870"
"8736","52.38000","22.25229","0.05780"
"8746","52.44000","22.25731","0.05752"
"8756","52.50000","22.26239","0.05830"
"8766","52.56000","22.26736","0.05891"
"8776","52.62000","22.27238","0.06066"
"8786","52.68000","22.27734","0.06186"
"8796","52.74000","22.28230","0.06202"
"8806","52.80000","22.28732","0.06197"
"8816","52.86000","22.29229","0.06089"
"8826","52.92000","22.29737","0.05967"
"8836","52.98000","22.30239","0.05986"
"8846","53.04000","22.30742","0.06021"
"8856","53.10000","22.31238","0.06061"
"8866","53.16000","22.31740","0.06143"
"8876","53.22000","22.32242","0.06288"
"8886","53.28000","22.32732","0.06378"
"8896","53.34000","22.33229","0.06392"
"8906","53.40000","22.33731","0.06234"
"8916","53.46000","22.34233","0.06188"
"8926","53.52000","22.34735","0.06122"
"8936","53.58000","22.35238","0.06144"
"8946","53.64000","22.35740","0.06216"
"8956","53.70000","22.36236","0.06301"
"8966","53.76000","22.36738","0.06516"
"8976","53.82000","22.37234","0.06563"
"8986","53.88000","22.37731","0.06524"
"8996","53.94000","22.38233","0.06470"
"9006","54.00000","22.38735","0.06350"
"9016","54.06000","22.39238","0.06290"
"9026","54.12000","22.39740","0.06321"
"9036","54.18000","22.40230","0.06376"
"9046","54.24000","22.40738","0.06549"
"9056","54.30000","22.41229","0.06650"
"9066","54.36000","22.41731","0.06701"
"9076","54.42000","22.42227","0.06676"
"9086","54.48000","22.42729","0.06618"
"9096","54.54000","22.43232","0.06546"
"9106","54.60000","22.43734","0.06539"
"9116","54.66000","22.44242","0.06540"
"9126","54.72000","22.44738","0.06595"
"9136","54.78000","22.45240","0.06690"
"9146","54.84000","22.45737","0.06786"
"9156","54.90000","22.46233","0.06817"
"9166","54.96000","22.46735","0.06850"
"9176","55.02000","22.47231","0.06788"
"9186","55.08000","22.47740","0.06709"
"9196","55.14000","22.48236","0.06664"
"9206","55.20000","22.48738","0.06651"
"9216","55.26000","22.49240","0.06727"
"9226","55.32000","22.49737","0.06827"
"9236","55.38000","22.50239","0.06921"
"9246","55.44000","22.50735","0.06980"
"9256","55.50000","22.51231","0.06972"
"9266","55.56000","22.51728","0.06936"
"9276","55.62000","22.52230","0.06856"
"9286","55.68000","22.52738","0.06820"
"9296","55.74000","22.53240","0.06850"
"9306","55.80000","22.53736","0.06895"
"9316","55.86000","22.54239","0.07014"
"9326","55.92000","22.54735","0.07106"
"9336","55.98000","22.55231","0.07103"
"9346","56.04000","22.55728","0.07098"
"9356","56.10000","22.56230","0.07019"
"9366","56.16000","22.56732","0.07015"
"9376","56.22000","22.57234","0.06974"
"9386","56.28000","22.57737","0.07037"
"9396","56.34000","22.58233","0.07090"
"9406","56.40000","22.58735","0.07125"
"9416","56.46000","22.59231","0.07177"
"9426","56.52000","22.59733","0.07181"
"9436","56.58000","22.60230","0.07144"
"9446","56.64000","22.60732","0.07174"
"9456","56.70000","22.61228","0.07131"
"9466","56.76000","22.61730","0.07038"
"9476","56.82000","22.62239","0.07072"
"9486","56.88000","22.62735","0.07202"
"9496","56.94000","22.63237","0.07268"
"9506","57.00000","22.63733","0.07290"
"9516","57.06000","22.64230","0.07302"
"9526","57.12000","22.64726","0.07303"
"9536","57.18000","22.65228","0.07270"
"9546","57.24000","22.65736","0.07262"
"9556","57.30000","22.66239","0.07246"
"9566","57.36000","22.66735","0.07276"
"9576","57.42000","22.67237","0.07312"
"9586","57.48000","22.67739","0.07375"
"9596","57.54000","22.68235","0.07367"
"9606","57.60000","22.68732","0.07366"
"9616","57.66000","22.69228","0.07336"
"9626","57.72000","22.69730","0.07321"
"9636","57.78000","22.70233","0.07319"
"9646","57.84000","22.70735","0.07328"
"9656","57.90000","22.71231","0.07324"
"9666","57.96000","22.71739","0.07399"
"9676","58.02000","22.72235","0.07440"
"9686","58.08000","22.72732","0.07458"
"9696","58.14000","22.73234","0.07502"
"9706","58.20000","22.73730","0.07443"
"9716","58.26000","22.74232","0.07419"
"9726","58.32000","22.74735","0.07431"
"9736","58.38000","22.75237","0.07436"
"9746","58.44000","22.75733","0.07465"
"9756","58.50000","22.76235","0.07502"
"9766","58.56000","22.76737","0.07501"
"9776","58.62000","22.77234","0.07546"
"9786","58.68000","22.77736","0.07536"
"9796","58.74000","22.78226","0.07533"
"9806","58.80000","22.78729","0.07450"
"9816","58.86000","22.79237","0.07471"
"9826","58.92000","22.79739","0.07468"
"9836","58.98000","22.80241","0.07507"
"9846","59.04000","22.80732","0.07552"
"9856","59.10000","22.81240","0.07529"
"9866","59.16000","22.81736","0.07558"
"9876","59.22000","22.82238","0.07539"
"9886","59.28000","22.82735","0.07538"
"9896","59.34000","22.83231","0.07534"
"9906","59.40000","22.83739","0.07513"
"9916","59.46000","22.84241","0.07533"
"9926","59.52000","22.84737","0.07560"
"9936","59.58000","22.85239","0.07618"
"9946","59.64000","22.85736","0.07591"
"9956","59.70000","22.86238","0.07600"
"9966","59.76000","22.86734","0.07608"
"9976","59.82000","22.87231","0.07583"
"9986","59.88000","22.87733","0.07609"
"9996","59.94000","22.88235","0.07570"
"10006","60.00000","22.88737","0.07593"
"10016","60.06000","22.89240","0.07632"
"10026","60.12000","22.89742","0.07650"
"10036","60.18000","22.90238","0.07660"
"10046","60.24000","22.90740","0.07656"
"10056","60.30000","22.91236","0.07638"
"10066","60.36000","22.91733","0.07634"
"10076","60.42000","22.92235","0.07655"
"10086","60.48000","22.92731","0.07625"
"10096","60.54000","22.93240","0.07660"
"10106","60.60000","22.93736","0.07670"
"10116","60.66000","22.94232","0.07687"
"10126","60.72000","22.94734","0.07702"
"10136","60.78000","22.95230","0.07686"
"10146","60.84000","22.95733","0.07679"
"10156","60.90000","22.96229","0.07701"
"10166","60.96000","22.96731","0.07680"
"10176","61.02000","22.97234","0.07715"
"10186","61.08000","22.97736","0.07735"
"10196","61.14000","22.98232","0.07726"
"10206","61.20000","22.98734","0.07745"
"10216","61.26000","22.99236","0.07748"
"10226","61.32000","22.99733","0.07743"
"10236","61.38000","23.00235","0.07737"
"10246","61.44000","23.00737","0.07726"
"10256","61.50000","23.01233","0.07753"
"10266","61.56000","23.01736","0.07760"
"10276","61.62000","23.02238","0.07773"
"10286","61.68000","23.02740","0.07781"
"10296","61.74000","23.03236","0.07804"
"10306","61.80000","23.03739","0.07795"
"10316","61.86000","23.04235","0.07784"
"10326","61.92000","23.04731","0.07765"
"10336","61.98000","23.05227","0.07767"
"10346","62.04000","23.05729","0.07814"
"10356","62.10000","23.06238","0.07796"
"10366","62.16000","23.06740","0.07842"
"10376","62.22000","23.07236","0.07820"
"10386","62.28000","23.07738","0.07834"
"10396","62.34000","23.08235","0.07858"
"10406","62.40000","23.08737","0.07835"
"10416","62.46000","23.09233","0.07846"
"10426","62.52000","23.09730","0.07833"
"10436","62.58000","23.10232","0.07853"
"10446","62.64000","23.10734","0.07867"
"10456","62.70000","23.11242","0.07908"
"10466","62.76000","23.11732","0.07893"
"10476","62.82000","23.12235","0.07904"
"10486","62.88000","23.12737","0.07886"
"10496","62.94000","23.13227","0.07898"
"10506","63.00000","23.13729","0.07874"
"10516","63.06000","23.14226","0.07942"
"10526","63.12000","23.14734","0.07910"
"10536","63.18000","23.15236","0.07950"
"10546","63.24000","23.15738","0.07983"
"10556","63.30000","23.16235","0.07963"
"10566","63.36000","23.16737","0.07939"
"10576","63.42000","23.17239","0.07967"
"10586","63.48000","23.17735","0.07928"
"10596","63.54000","23.18232","0.07957"
"10606","63.60000","23.18728","0.07997"
"10616","63.66000","23.19230","0.07971"
"10626","63.72000","23.19732","0.08019"
"10636","63.78000","23.20240","0.08036"
"10646","63.84000","23.20737","0.07981"
"10656","63.90000","23.21239","0.08025"
"10666","63.96000","23.21735","0.08030"
"10676","64.02000","23.22238","0.08059"
"10686","64.08000","23.22733","0.08083"
"10696","64.14000","23.23230","0.08076"
"10706","64.20000","23.23726","0.08108"
"10716","64.26000","23.24240","0.08127"
"10726","64.32000","23.24737","0.08117"
"10736","64.38000","23.25239","0.08119"
"10746","64.44000","23.25741","0.08090"
"10756","64.50000","23.26237","0.08140"
"10766","64.56000","23.26740","0.08160"
"10776","64.62000","23.27236","0.08171"
"10786","64.68000","23.27732","0.08209"
"10796","64.74000","23.28228","0.08166"
"10806","64.80000","23.28730","0.08234"
"10816","64.86000","23.29233","0.08231"
"10826","64.92000","23.29735","0.08206"
"10836","64.98000","23.30237","0.08214"
"10846","65.04000","23.30734","0.08227"
"10856","65.10000","23.31230","0.08286"
"10866","65.16000","23.31732","0.08367"
"10876","65.22000","23.32228","0.08371"
"10886","65.28000","23.32730","0.08355"
"10896","65.34000","23.33233","0.08377"
"10906","65.40000","23.33735","0.08390"
"10916","65.46000","23.34237","0.08430"
"10926","65.52000","23.34739","0.08440"
"10936","65.58000","23.35242","0.08433"
"10946","65.64000","23.35732","0.08537"
"10956","65.70000","23.36234","0.08558"
"10966","65.76000","23.36730","0.08539"
"10976","65.82000","23.37233","0.08522"
"10986","65.88000","23.37735","0.08540"
"10996","65.94000","23.38237","0.08558"
"11006","66.00000","23.38739","0.08569"
"11016","66.06000","23.39236","0.08643"
"11026","66.12000","23.39738","0.08648"
"11036","66.18000","23.40234","0.08695"
"11046","66.24000","23.40730","0.08759"
"11056","66.30000","23.41232","0.08695"
"11066","66.36000","23.41729","0.08767"
"11076","66.42000","23.42237","0.08770"
"11086","66.48000","23.42733","0.08738"
"11096","66.54000","23.43236","0.08820"
"11106","66.60000","23.43744","0.08851"
"11116","66.66000","23.44234","0.08907"
"11126","66.72000","23.44736","0.08942"
"11136","66.78000","23.45226","0.08963"
"11146","66.84000","23.45729","0.08924"
"11156","66.90000","23.46231","0.08898"
"11166","66.96000","23.46733","0.08978"
"11176","67.02000","23.47235","0.09009"
"11186","67.08000","23.47732","0.09081"
"11196","67.14000","23.48240","0.09110"
"11206","67.20000","23.48736","0.09160"
"11216","67.26000","23.49238","0.09138"
"11226","67.32000","23.49729","0.09116"
"11236","67.38000","23.50225","0.09135"
"11246","67.44000","23.50733","0.09106"
"11256","67.50000","23.51235","0.09156"
"11266","67.56000","23.51744","0.09200"
"11276","67.62000","23.52234","0.09284"
"11286","67.68000","23.52736","0.09247"
"11296","67.74000","23.53238","0.09278"
"11306","67.80000","23.53735","0.09270"
"11316","67.86000","23.54237","0.09334"
"11326","67.92000","23.54733","0.09299"
"11336","67.98000","23.55235","0.09346"
"11346","68.04000","23.55738","0.09377"
"11356","68.10000","23.56240","0.09392"
"11366","68.16000","23.56742","0.09415"
"11376","68.22000","23.57232","0.09348"
"11386","68.28000","23.57734","0.09260"
"11396","68.34000","23.58237","0.09363"
"11406","68.40000","23.58733","0.09285"
"11416","68.46000","23.59229","0.08673"
"11426","68.52000","23.59731","0.08783"
"11436","68.58000","23.60234","0.08755"
"11446","68.64000","23.60736","0.08739"
"11456","68.70000","23.61238","0.08728"
"11466","68.76000","23.61740","0.08786"
"11476","68.82000","23.62231","0.06726"
"11486","68.88000","23.62733","0.04240"
"11496","68.94000","23.63235","0.03129"
"11506","69.00000","23.63731","0.05280"
"11516","69.06000","23.64234","0.04563"
"11526","69.12000","23.64736","0.03612"
"11536","69.18000","23.65238","0.03127"
"11546","69.24000","23.65734","0.01118"
"11556","69.30000","23.66236","0.00240"
"11566","69.36000","23.66733","0.00862"
"11576","69.42000","23.67235","0.00354"
"11586","69.48000","23.67731","0.00824"
"11596","69.54000","23.68228","0.00411"
"11606","69.60000","23.68736","0.00722"
"11616","69.66000","23.69232","0.00385"
"11626","69.72000","23.69740","0.00529"
"11636","69.78000","23.70236","0.00406"
"11646","69.84000","23.70733","0.00533"
"11656","69.90000","23.71235","0.00384"
"11666","69.96000","23.71731","0.00367"
"11676","70.02000","23.72233","0.00369"
"11686","70.08000","23.72730","0.00447"
"11696","70.14000","23.73238","0.00472"
"11706","70.20000","23.73734","0.00471"
"11716","70.26000","23.74236","0.00515"
"11726","70.32000","23.74739","0.00449"
"11736","70.38000","23.75235","0.00577"
"11746","70.44000","23.75737","0.00421"
"11756","70.50000","23.76233","0.00396"
"11766","70.56000","23.76730","0.00412"
"11776","70.62000","23.77232","0.00373"
"11786","70.68000","23.77734","0.00313"
"11796","70.74000","23.78242","0.00411"
"11806","70.80000","23.78733","0.00391"
"11816","70.86000","23.79241","0.00329"
"11826","70.92000","23.79737","0.00395"
"11836","70.98000","23.80239","0.00423"
"11846","71.04000","23.80735","0.00393"
"11856","71.10000","23.81232","0.00400"
"11866","71.16000","23.81734","0.00406"
"11876","71.22000","23.82236","0.00398"
"11886","71.28000","23.82738","0.00489"
"11896","71.34000","23.83241","0.00552"
"11906","71.40000","23.83737","0.00550"
"11916","71.46000","23.84239","0.00501"
"11926","71.52000","23.84730","0.00569"
"11936","71.58000","23.85238","0.00407"
"11946","71.64000","23.85734","0.00333"
"11956","71.70000","23.86224","0.00354"
"11966","71.76000","23.86739","0.00396"
"11976","71.82000","23.87235","0.00337"
"11986","71.88000","23.87743","0.00409"
"11996","71.94000","23.88233","0.00397"
"12006","72.00000","23.88735","0.00407"
"12016","72.06000","23.89237","0.00397"
"12026","72.12000","23.89734","0.00429"
"12036","72.18000","23.90230","0.00409"
"12046","72.24000","23.90726","0.00409"
"12056","72.30000","23.91234","0.00463"
"12066","72.36000","23.91737","0.00429"
"12076","72.42000","23.92239","0.00489"
"12086","72.48000","23.92735","0.00551"
"12096","72.54000","23.93237","0.00509"
"12106","72.60000","23.93734","0.00472"
"12116","72.66000","23.94236","0.00482"
"12126","72.72000","23.94732","0.00437"
"12136","72.78000","23.95229","0.00403"
"12146","72.84000","23.95737","0.00364"
"12156","72.90000","23.96239","0.00325"
"12160","72.92000","23.96406","0.00312"