File: Trajectories_together/170107_1Specimen_RawData_8.csv
"","V1","V2","V3"
"1","End date","1/7/2017",""
"2","Specimen label","17CT_36",""
"3","Maximum Load","0.72786","N"
"4","Time","Extension","Load"
"5","(s)","(mm)","(N)"
"6","0.00000","0.00000","-0.00430"
"55","0.29400","0.02386","-0.00418"
"104","0.58800","0.04933","-0.00260"
"153","0.88200","0.07372","-0.00246"
"202","1.17600","0.09823","-0.00193"
"251","1.47000","0.12269","-0.00112"
"300","1.76400","0.14720","-0.00084"
"349","2.05800","0.17172","0.00038"
"398","2.35200","0.19617","0.00034"
"447","2.64600","0.22074","0.00119"
"496","2.94000","0.24514","0.00086"
"545","3.23400","0.26971","0.00143"
"594","3.52800","0.29416","0.00093"
"643","3.82200","0.31874","0.00222"
"692","4.11600","0.34319","0.00185"
"741","4.41000","0.36771","0.00243"
"790","4.70400","0.39216","0.00306"
"839","4.99800","0.41661","0.00337"
"888","5.29200","0.44119","0.00289"
"937","5.58600","0.46564","0.00357"
"986","5.88000","0.49021","0.00325"
"1035","6.17400","0.51467","0.00357"
"1084","6.46800","0.53924","0.00381"
"1133","6.76200","0.56364","0.00406"
"1182","7.05600","0.58821","0.00357"
"1231","7.35000","0.61266","0.00456"
"1280","7.64400","0.63724","0.00420"
"1329","7.93800","0.66169","0.00465"
"1378","8.23200","0.68620","0.00503"
"1427","8.52600","0.71072","0.00541"
"1476","8.82000","0.73517","0.00521"
"1525","9.11400","0.75975","0.00589"
"1574","9.40800","0.78414","0.00541"
"1623","9.70200","0.80877","0.00594"
"1672","9.99600","0.83317","0.00623"
"1721","10.29000","0.85774","0.00643"
"1770","10.58400","0.88219","0.00661"
"1819","10.87800","0.90677","0.00680"
"1868","11.17200","0.93122","0.00679"
"1917","11.46600","0.95568","0.00695"
"1966","11.76000","0.98025","0.00719"
"2015","12.05400","1.00470","0.00773"
"2064","12.34800","1.02922","0.00795"
"2113","12.64200","1.05367","0.00800"
"2162","12.93600","1.07818","0.00805"
"2211","13.23000","1.10264","0.00799"
"2260","13.52400","1.12721","0.00807"
"2309","13.81800","1.15173","0.00805"
"2358","14.11200","1.17624","0.00839"
"2407","14.40600","1.20075","0.00855"
"2456","14.70000","1.22521","0.00927"
"2505","14.99400","1.24978","0.00946"
"2554","15.28800","1.27417","0.00956"
"2603","15.58200","1.29875","0.00958"
"2652","15.87600","1.32320","0.00972"
"2701","16.17000","1.34778","0.01004"
"2750","16.46400","1.37217","0.00981"
"2799","16.75800","1.39674","0.01014"
"2848","17.05200","1.42120","0.01083"
"2897","17.34600","1.44565","0.01045"
"2946","17.64000","1.47016","0.01119"
"2995","17.93400","1.49468","0.01121"
"3044","18.22800","1.51919","0.01164"
"3093","18.52200","1.54365","0.01171"
"3142","18.81600","1.56822","0.01170"
"3191","19.11000","1.59267","0.01209"
"3240","19.40400","1.61725","0.01225"
"3289","19.69800","1.64164","0.01266"
"3338","19.99200","1.66621","0.01301"
"3387","20.28600","1.69067","0.01269"
"3436","20.58000","1.71524","0.01317"
"3485","20.87400","1.73976","0.01389"
"3534","21.16800","1.76427","0.01439"
"3583","21.46200","1.78878","0.01442"
"3632","21.75600","1.81318","0.01498"
"3681","22.05000","1.83769","0.01529"
"3730","22.34400","1.86215","0.01540"
"3779","22.63800","1.88672","0.01608"
"3828","22.93200","1.91117","0.01613"
"3877","23.22600","1.93569","0.01638"
"3926","23.52000","1.96020","0.01629"
"3975","23.81400","1.98471","0.01720"
"4024","24.10800","2.00923","0.01718"
"4073","24.40200","2.03368","0.01752"
"4122","24.69600","2.05819","0.01777"
"4171","24.99000","2.08265","0.01822"
"4220","25.28400","2.10722","0.01835"
"4269","25.57800","2.13162","0.01893"
"4318","25.87200","2.15625","0.01956"
"4367","26.16600","2.18070","0.01946"
"4416","26.46000","2.20528","0.02034"
"4465","26.75400","2.22973","0.02061"
"4514","27.04800","2.25424","0.02041"
"4563","27.34200","2.27870","0.02177"
"4612","27.63600","2.30321","0.02207"
"4661","27.93000","2.32773","0.02214"
"4710","28.22400","2.35212","0.02304"
"4759","28.51800","2.37669","0.02340"
"4808","28.81200","2.40115","0.02444"
"4857","29.10600","2.42572","0.02591"
"4906","29.40000","2.45017","0.02563"
"4955","29.69400","2.47469","0.02448"
"5004","29.98800","2.49920","0.02630"
"5053","30.28200","2.52366","0.02639"
"5102","30.57600","2.54817","0.02674"
"5151","30.87000","2.57262","0.02830"
"5200","31.16400","2.59720","0.02815"
"5249","31.45800","2.62165","0.02823"
"5298","31.75200","2.64622","0.02936"
"5347","32.04600","2.67068","0.03001"
"5396","32.34000","2.69525","0.03062"
"5445","32.63400","2.71971","0.03137"
"5494","32.92800","2.74428","0.03166"
"5543","33.22200","2.76873","0.03221"
"5592","33.51600","2.79325","0.03289"
"5641","33.81000","2.81776","0.03382"
"5690","34.10400","2.84222","0.03453"
"5739","34.39800","2.86673","0.03494"
"5788","34.69200","2.89112","0.03622"
"5837","34.98600","2.91570","0.03588"
"5886","35.28000","2.94015","0.03775"
"5935","35.57400","2.96472","0.03915"
"5984","35.86800","2.98918","0.03920"
"6033","36.16200","3.01369","0.04066"
"6082","36.45600","3.03820","0.04141"
"6131","36.75000","3.06272","0.04222"
"6180","37.04400","3.08723","0.04306"
"6229","37.33800","3.11169","0.04398"
"6278","37.63200","3.13620","0.04517"
"6327","37.92600","3.16065","0.04609"
"6376","38.22000","3.18523","0.04658"
"6425","38.51400","3.20968","0.04843"
"6474","38.80800","3.23419","0.04896"
"6523","39.10200","3.25871","0.04982"
"6572","39.39600","3.28322","0.05076"
"6621","39.69000","3.30774","0.05196"
"6670","39.98400","3.33225","0.05277"
"6719","40.27800","3.35670","0.05394"
"6768","40.57200","3.38116","0.05431"
"6817","40.86600","3.40573","0.05440"
"6866","41.16000","3.43013","0.05547"
"6915","41.45400","3.45470","0.05634"
"6964","41.74800","3.47909","0.05691"
"7013","42.04200","3.50373","0.05709"
"7062","42.33600","3.52812","0.05812"
"7111","42.63000","3.55269","0.05874"
"7160","42.92400","3.57721","0.05917"
"7209","43.21800","3.60166","0.05991"
"7258","43.51200","3.62624","0.06028"
"7307","43.80600","3.65069","0.06069"
"7356","44.10000","3.67526","0.06027"
"7405","44.39400","3.69966","0.05856"
"7454","44.68800","3.72423","0.05897"
"7503","44.98200","3.74868","0.05947"
"7552","45.27600","3.77326","0.05935"
"7601","45.57000","3.79771","0.05981"
"7650","45.86400","3.82223","0.06019"
"7699","46.15800","3.84674","0.06079"
"7748","46.45200","3.87125","0.06118"
"7797","46.74600","3.89577","0.06175"
"7846","47.04000","3.92022","0.06198"
"7895","47.33400","3.94473","0.06254"
"7944","47.62800","3.96913","0.06287"
"7993","47.92200","3.99370","0.06326"
"8042","48.21600","4.01816","0.06350"
"8091","48.51000","4.04273","0.06423"
"8140","48.80400","4.06718","0.06517"
"8189","49.09800","4.09170","0.06549"
"8238","49.39200","4.11621","0.06561"
"8287","49.68600","4.14066","0.06631"
"8336","49.98000","4.16524","0.06713"
"8385","50.27400","4.18969","0.06780"
"8434","50.56800","4.21421","0.06867"
"8483","50.86200","4.23866","0.06947"
"8532","51.15600","4.26329","0.07037"
"8581","51.45000","4.28769","0.07162"
"8630","51.74400","4.31220","0.07244"
"8679","52.03800","4.33671","0.07369"
"8728","52.33200","4.36123","0.07474"
"8777","52.62600","4.38574","0.07491"
"8826","52.92000","4.41020","0.07670"
"8875","53.21400","4.43471","0.07708"
"8924","53.50800","4.45916","0.07853"
"8973","53.80200","4.48368","0.07991"
"9022","54.09600","4.50813","0.08170"
"9071","54.39000","4.53276","0.08243"
"9120","54.68400","4.55716","0.08297"
"9169","54.97800","4.58173","0.08619"
"9218","55.27200","4.60619","0.08787"
"9267","55.56600","4.63070","0.08938"
"9316","55.86000","4.65521","0.09082"
"9365","56.15400","4.67967","0.09260"
"9414","56.44800","4.70424","0.09338"
"9463","56.74200","4.72869","0.09565"
"9512","57.03600","4.75327","0.09839"
"9561","57.33000","4.77772","0.10006"
"9610","57.62400","4.80230","0.10245"
"9659","57.91800","4.82669","0.10484"
"9708","58.21200","4.85120","0.10700"
"9757","58.50600","4.87566","0.10937"
"9806","58.80000","4.90023","0.11134"
"9855","59.09400","4.92474","0.11328"
"9904","59.38800","4.94914","0.11446"
"9953","59.68200","4.97377","0.11636"
"10002","59.97600","4.99823","0.11812"
"10051","60.27000","5.02274","0.11985"
"10100","60.56400","5.04713","0.12153"
"10149","60.85800","5.07171","0.12311"
"10198","61.15200","5.09616","0.12422"
"10247","61.44600","5.12073","0.12569"
"10296","61.74000","5.14519","0.12518"
"10345","62.03400","5.16976","0.12535"
"10394","62.32800","5.19422","0.12710"
"10443","62.62200","5.21867","0.12726"
"10492","62.91600","5.24330","0.12951"
"10541","63.21000","5.26770","0.13069"
"10590","63.50400","5.29221","0.13179"
"10639","63.79800","5.31666","0.13371"
"10688","64.09200","5.34118","0.13472"
"10737","64.38600","5.36569","0.13488"
"10786","64.68000","5.39021","0.13531"
"10835","64.97400","5.41472","0.13687"
"10884","65.26800","5.43917","0.13777"
"10933","65.56200","5.46375","0.13946"
"10982","65.85600","5.48814","0.14060"
"11031","66.15000","5.51271","0.14293"
"11080","66.44400","5.53711","0.14425"
"11129","66.73800","5.56168","0.14654"
"11178","67.03200","5.58614","0.14894"
"11227","67.32600","5.61077","0.15041"
"11276","67.62000","5.63516","0.15268"
"11325","67.91400","5.65974","0.15429"
"11374","68.20800","5.68419","0.15625"
"11423","68.50200","5.70876","0.15792"
"11472","68.79600","5.73322","0.15954"
"11521","69.09000","5.75767","0.16145"
"11570","69.38400","5.78225","0.16317"
"11619","69.67800","5.80664","0.16533"
"11668","69.97200","5.83127","0.16696"
"11717","70.26600","5.85567","0.16769"
"11766","70.56000","5.88024","0.16938"
"11815","70.85400","5.90469","0.17004"
"11864","71.14800","5.92921","0.17114"
"11913","71.44200","5.95372","0.17203"
"11962","71.73600","5.97824","0.17296"
"12011","72.03000","6.00275","0.17391"
"12060","72.32400","6.02720","0.17514"
"12109","72.61800","6.05172","0.17607"
"12158","72.91200","6.07617","0.17713"
"12207","73.20600","6.10068","0.17891"
"12256","73.50000","6.12514","0.18042"
"12305","73.79400","6.14977","0.18254"
"12354","74.08800","6.17423","0.18398"
"12403","74.38200","6.19874","0.18625"
"12452","74.67600","6.22325","0.18880"
"12501","74.97000","6.24771","0.18992"
"12550","75.26400","6.27228","0.19191"
"12599","75.55800","6.29667","0.19435"
"12648","75.85200","6.32125","0.19588"
"12697","76.14600","6.34564","0.19770"
"12746","76.44000","6.37022","0.20068"
"12795","76.73400","6.39467","0.20358"
"12844","77.02800","6.41924","0.20620"
"12893","77.32200","6.44364","0.20834"
"12942","77.61600","6.46821","0.21024"
"12991","77.91000","6.49272","0.21268"
"13040","78.20400","6.51718","0.21444"
"13089","78.49800","6.54169","0.21683"
"13138","78.79200","6.56615","0.21932"
"13187","79.08600","6.59072","0.22175"
"13236","79.38000","6.61517","0.22451"
"13285","79.67400","6.63969","0.22736"
"13334","79.96800","6.66414","0.22918"
"13383","80.26200","6.68871","0.23307"
"13432","80.55600","6.71317","0.23518"
"13481","80.85000","6.73774","0.21419"
"13530","81.14400","6.76220","0.21821"
"13579","81.43800","6.78671","0.22203"
"13628","81.73200","6.81122","0.22504"
"13677","82.02600","6.83568","0.22936"
"13726","82.32000","6.86025","0.23259"
"13775","82.61400","6.88470","0.23657"
"13824","82.90800","6.90928","0.23998"
"13873","83.20200","6.93367","0.24567"
"13922","83.49600","6.95825","0.25066"
"13971","83.79000","6.98270","0.25708"
"14020","84.08400","7.00721","0.26009"
"14069","84.37800","7.03173","0.26358"
"14118","84.67200","7.05618","0.26676"
"14167","84.96600","7.08075","0.26934"
"14216","85.26000","7.10515","0.27170"
"14265","85.55400","7.12972","0.27373"
"14314","85.84800","7.15412","0.27504"
"14363","86.14200","7.17875","0.27732"
"14412","86.43600","7.20320","0.27866"
"14461","86.73000","7.22778","0.27975"
"14510","87.02400","7.25223","0.28083"
"14559","87.31800","7.27674","0.28144"
"14608","87.61200","7.30120","0.28247"
"14657","87.90600","7.32571","0.28339"
"14706","88.20000","7.35023","0.28492"
"14755","88.49400","7.37468","0.28609"
"14804","88.78800","7.39919","0.28795"
"14853","89.08200","7.42365","0.28964"
"14902","89.37600","7.44822","0.29205"
"14951","89.67000","7.47268","0.29501"
"15000","89.96400","7.49725","0.29660"
"15049","90.25800","7.52170","0.30031"
"15098","90.55200","7.54616","0.30395"
"15147","90.84600","7.57073","0.30836"
"15196","91.14000","7.59518","0.31244"
"15245","91.43400","7.61970","0.31635"
"15294","91.72800","7.64415","0.31944"
"15343","92.02200","7.66873","0.32286"
"15392","92.31600","7.69312","0.32680"
"15441","92.61000","7.71775","0.33012"
"15490","92.90400","7.74227","0.33169"
"15539","93.19800","7.76672","0.33290"
"15588","93.49200","7.79123","0.33600"
"15637","93.78600","7.81575","0.33926"
"15686","94.08000","7.84026","0.34159"
"15735","94.37400","7.86466","0.34381"
"15784","94.66800","7.88923","0.34647"
"15833","94.96200","7.91368","0.34945"
"15882","95.25600","7.93820","0.35369"
"15931","95.55000","7.96265","0.35628"
"15980","95.84400","7.98728","0.35834"
"16029","96.13800","8.01168","0.36114"
"16078","96.43200","8.03625","0.36302"
"16127","96.72600","8.06065","0.36533"
"16176","97.02000","8.08516","0.36861"
"16225","97.31400","8.10973","0.37072"
"16274","97.60800","8.13419","0.36282"
"16323","97.90200","8.15876","0.36291"
"16372","98.19600","8.18321","0.36543"
"16421","98.49000","8.20773","0.36871"
"16470","98.78400","8.23218","0.37063"
"16519","99.07800","8.25669","0.37317"
"16568","99.37200","8.28121","0.37550"
"16617","99.66600","8.30566","0.37624"
"16666","99.96000","8.33018","0.37369"
"16715","100.25400","8.35469","0.37663"
"16764","100.54800","8.37926","0.37886"
"16813","100.84200","8.40372","0.38232"
"16862","101.13600","8.42823","0.38650"
"16911","101.43000","8.45263","0.39088"
"16960","101.72400","8.47720","0.39414"
"17009","102.01800","8.50159","0.39836"
"17058","102.31200","8.52623","0.34567"
"17107","102.60600","8.55068","0.27664"
"17156","102.90000","8.57519","0.27946"
"17205","103.19400","8.59971","0.28227"
"17254","103.48800","8.62422","0.28325"
"17303","103.78200","8.64874","0.28326"
"17352","104.07600","8.67319","0.28362"
"17401","104.37000","8.69770","0.28669"
"17450","104.66400","8.72222","0.29137"
"17499","104.95800","8.74673","0.29380"
"17548","105.25200","8.77118","0.29654"
"17597","105.54600","8.79576","0.30613"
"17646","105.84000","8.82021","0.31416"
"17695","106.13400","8.84473","0.28977"
"17744","106.42800","8.86912","0.28774"
"17793","106.72200","8.89363","0.28974"
"17842","107.01600","8.91821","0.19145"
"17891","107.31000","8.94266","0.19550"
"17940","107.60400","8.96723","0.19169"
"17989","107.89800","8.99169","0.19837"
"18038","108.19200","9.01626","0.20582"
"18087","108.48600","9.04066","0.20864"
"18136","108.78000","9.06523","0.21819"
"18185","109.07400","9.08968","0.21979"
"18234","109.36800","9.11420","0.22762"
"18283","109.66200","9.13871","0.23174"
"18332","109.95600","9.16316","0.23325"
"18381","110.25000","9.18774","0.23995"
"18430","110.54400","9.21219","0.24218"
"18479","110.83800","9.23676","0.25254"
"18528","111.13200","9.26116","0.25499"
"18577","111.42600","9.28573","0.26160"
"18626","111.72000","9.31019","0.26665"
"18675","112.01400","9.33476","0.26930"
"18724","112.30800","9.35915","0.27308"
"18773","112.60200","9.38373","0.27485"
"18822","112.89600","9.40818","0.27870"
"18871","113.19000","9.43270","0.28004"
"18920","113.48400","9.45721","0.28190"
"18969","113.77800","9.48166","0.28320"
"19018","114.07200","9.50618","0.28408"
"19067","114.36600","9.53057","0.28554"
"19116","114.66000","9.55520","0.17242"
"19165","114.95400","9.57966","0.17390"
"19214","115.24800","9.60423","0.17212"
"19263","115.54200","9.62869","0.17458"
"19312","115.83600","9.65326","0.17815"
"19361","116.13000","9.67771","0.17869"
"19410","116.42400","9.70217","0.18147"
"19459","116.71800","9.72674","0.18349"
"19508","117.01200","9.75119","0.18866"
"19557","117.30600","9.77571","0.19163"
"19606","117.60000","9.80016","0.19193"
"19655","117.89400","9.82474","0.19428"
"19704","118.18800","9.84919","0.19581"
"19753","118.48200","9.87376","0.20153"
"19802","118.77600","9.89822","0.20666"
"19851","119.07000","9.92273","0.20897"
"19900","119.36400","9.94724","0.21168"
"19949","119.65800","9.97170","0.21399"
"19998","119.95200","9.99621","0.21812"
"20047","120.24600","10.02067","0.22447"
"20096","120.54000","10.04524","0.22819"
"20145","120.83400","10.06963","0.23208"
"20194","121.12800","10.09427","0.23508"
"20243","121.42200","10.11866","0.23924"
"20292","121.71600","10.14323","0.24551"
"20341","122.01000","10.16769","0.25385"
"20390","122.30400","10.19220","0.26168"
"20439","122.59800","10.21677","0.26672"
"20488","122.89200","10.24123","0.26974"
"20537","123.18600","10.26574","0.27195"
"20586","123.48000","10.29020","0.27518"
"20635","123.77400","10.31477","0.27705"
"20684","124.06800","10.33916","0.27943"
"20733","124.36200","10.36374","0.28116"
"20782","124.65600","10.38819","0.28272"
"20831","124.95000","10.41271","0.28494"
"20880","125.24400","10.43722","0.28717"
"20929","125.53800","10.46167","0.28941"
"20978","125.83200","10.48619","0.29270"
"21027","126.12600","10.51064","0.29714"
"21076","126.42000","10.53522","0.30273"
"21125","126.71400","10.55961","0.30807"
"21174","127.00800","10.58418","0.31294"
"21223","127.30200","10.60857","0.31814"
"21272","127.59600","10.63321","0.32351"
"21321","127.89000","10.65766","0.32754"
"21370","128.18400","10.68224","0.33179"
"21419","128.47800","10.70669","0.33626"
"21468","128.77200","10.73127","0.33940"
"21517","129.06600","10.75578","0.34244"
"21566","129.36000","10.78023","0.34570"
"21615","129.65400","10.80469","0.34988"
"21664","129.94800","10.82914","0.35471"
"21713","130.24200","10.85371","0.35761"
"21762","130.53600","10.87817","0.36092"
"21811","130.83000","10.90274","0.36441"
"21860","131.12400","10.92719","0.36786"
"21909","131.41800","10.95171","0.37085"
"21958","131.71200","10.97622","0.37349"
"22007","132.00600","11.00074","0.37599"
"22056","132.30000","11.02525","0.37889"
"22105","132.59400","11.04970","0.35970"
"22154","132.88800","11.07422","0.35893"
"22203","133.18200","11.09867","0.35987"
"22252","133.47600","11.12319","0.36256"
"22301","133.77000","11.14770","0.36499"
"22350","134.06400","11.17227","0.36837"
"22399","134.35800","11.19672","0.37117"
"22448","134.65200","11.22124","0.37403"
"22497","134.94600","11.24575","0.37632"
"22546","135.24000","11.27027","0.38006"
"22595","135.53400","11.29478","0.38371"
"22644","135.82800","11.31917","0.38744"
"22693","136.12200","11.34369","0.39157"
"22742","136.41600","11.36814","0.39597"
"22791","136.71000","11.39272","0.40019"
"22840","137.00400","11.41711","0.40351"
"22889","137.29800","11.44174","0.40746"
"22938","137.59200","11.46620","0.41236"
"22987","137.88600","11.49071","0.41548"
"23036","138.18000","11.51517","0.41834"
"23085","138.47400","11.53968","0.42138"
"23134","138.76800","11.56419","0.42383"
"23183","139.06200","11.58865","0.41624"
"23232","139.35600","11.61322","0.41389"
"23281","139.65000","11.63761","0.41581"
"23330","139.94400","11.66219","0.41855"
"23379","140.23800","11.68664","0.42235"
"23428","140.53200","11.71122","0.42472"
"23477","140.82600","11.73573","0.42872"
"23526","141.12000","11.76024","0.43164"
"23575","141.41400","11.78476","0.43566"
"23624","141.70800","11.80921","0.43928"
"23673","142.00200","11.83378","0.44363"
"23722","142.29600","11.85818","0.44883"
"23771","142.59000","11.88269","0.45498"
"23820","142.88400","11.90721","0.45879"
"23869","143.17800","11.93172","0.46329"
"23918","143.47200","11.95623","0.46487"
"23967","143.76600","11.98075","0.40455"
"24016","144.06000","12.00526","0.40804"
"24065","144.35400","12.02971","0.41324"
"24114","144.64800","12.05423","0.41831"
"24163","144.94200","12.07868","0.42263"
"24212","145.23600","12.10326","0.42683"
"24261","145.53000","12.12759","0.43025"
"24310","145.82400","12.15222","0.43482"
"24359","146.11800","12.17674","0.44012"
"24408","146.41200","12.20131","0.44563"
"24457","146.70600","12.22570","0.45220"
"24506","147.00000","12.25028","0.46000"
"24555","147.29400","12.27467","0.46664"
"24604","147.58800","12.29919","0.47156"
"24653","147.88200","12.32370","0.47595"
"24702","148.17600","12.34821","0.48014"
"24751","148.47000","12.37273","0.48260"
"24800","148.76400","12.39718","0.48518"
"24849","149.05800","12.42169","0.48710"
"24898","149.35200","12.44615","0.48934"
"24947","149.64600","12.47072","0.49192"
"24996","149.94000","12.49512","0.49422"
"25045","150.23400","12.51969","0.49672"
"25094","150.52800","12.54420","0.50027"
"25143","150.82200","12.56866","0.50390"
"25192","151.11600","12.59317","0.50781"
"25241","151.41000","12.61768","0.51332"
"25290","151.70400","12.64220","0.51798"
"25339","151.99800","12.66665","0.52277"
"25388","152.29200","12.69123","0.52600"
"25437","152.58600","12.71562","0.52949"
"25486","152.88000","12.74019","0.50997"
"25535","153.17400","12.76465","0.51264"
"25584","153.46800","12.78922","0.51719"
"25633","153.76200","12.81373","0.52244"
"25682","154.05600","12.83825","0.52608"
"25731","154.35000","12.86276","0.53041"
"25780","154.64400","12.88716","0.53432"
"25829","154.93800","12.91173","0.53645"
"25878","155.23200","12.93612","0.53989"
"25927","155.52600","12.96070","0.54263"
"25976","155.82000","12.98515","0.54584"
"26025","156.11400","13.00972","0.55062"
"26074","156.40800","13.03418","0.55622"
"26123","156.70200","13.05875","0.56101"
"26172","156.99600","13.08321","0.56450"
"26221","157.29000","13.10772","0.56865"
"26270","157.58400","13.13223","0.57178"
"26319","157.87800","13.15669","0.57419"
"26368","158.17200","13.18120","0.57651"
"26417","158.46600","13.20571","0.57816"
"26466","158.76000","13.23023","0.58017"
"26515","159.05400","13.25468","0.58200"
"26564","159.34800","13.27925","0.58317"
"26613","159.64200","13.30371","0.58461"
"26662","159.93600","13.32822","0.58650"
"26711","160.23000","13.35268","0.58878"
"26760","160.52400","13.37719","0.59208"
"26809","160.81800","13.40176","0.59506"
"26858","161.11200","13.42622","0.59874"
"26907","161.40600","13.45073","0.60296"
"26956","161.70000","13.47513","0.60729"
"27005","161.99400","13.49970","0.61357"
"27054","162.28800","13.52415","0.61809"
"27103","162.58200","13.54867","0.62278"
"27152","162.87600","13.57318","0.62600"
"27201","163.17000","13.59770","0.62862"
"27250","163.46400","13.62215","0.63113"
"27299","163.75800","13.64666","0.63312"
"27348","164.05200","13.67124","0.63543"
"27397","164.34600","13.69569","0.63638"
"27446","164.64000","13.72020","0.63828"
"27495","164.93400","13.74472","0.64051"
"27544","165.22800","13.76929","0.63613"
"27593","165.52200","13.79368","0.62893"
"27642","165.81600","13.81820","0.63193"
"27691","166.11000","13.84271","0.63322"
"27740","166.40400","13.86723","0.60367"
"27789","166.69800","13.89168","0.58516"
"27838","166.99200","13.91619","0.58634"
"27887","167.28600","13.94071","0.58736"
"27936","167.58000","13.96516","0.58957"
"27985","167.87400","13.98974","0.59201"
"28034","168.16800","14.01413","0.59513"
"28083","168.46200","14.03876","0.59909"
"28132","168.75600","14.06322","0.60311"
"28181","169.05000","14.08767","0.60933"
"28230","169.34400","14.11218","0.61377"
"28279","169.63800","14.13670","0.61963"
"28328","169.93200","14.16127","0.62342"
"28377","170.22600","14.18566","0.62781"
"28426","170.52000","14.21024","0.63103"
"28475","170.81400","14.23469","0.63439"
"28524","171.10800","14.25927","0.63768"
"28573","171.40200","14.28366","0.64132"
"28622","171.69600","14.30823","0.64375"
"28671","171.99000","14.33269","0.64756"
"28720","172.28400","14.35720","0.65067"
"28769","172.57800","14.38171","0.65568"
"28818","172.87200","14.40623","0.65936"
"28867","173.16600","14.43074","0.66430"
"28916","173.46000","14.45520","0.66902"
"28965","173.75400","14.47971","0.67259"
"29014","174.04800","14.50422","0.67683"
"29063","174.34200","14.52868","0.68007"
"29112","174.63600","14.55313","0.68206"
"29161","174.93000","14.57770","0.68478"
"29210","175.22400","14.60210","0.68684"
"29259","175.51800","14.62673","0.68867"
"29308","175.81200","14.65119","0.68991"
"29357","176.10600","14.67570","0.69196"
"29406","176.40000","14.70021","0.69380"
"29455","176.69400","14.72473","0.69665"
"29504","176.98800","14.74924","0.69890"
"29553","177.28200","14.77370","0.70166"
"29602","177.57600","14.79821","0.70465"
"29651","177.87000","14.82266","0.70757"
"29700","178.16400","14.84718","0.71256"
"29749","178.45800","14.87169","0.71620"
"29798","178.75200","14.89626","0.72101"
"29847","179.04600","14.92072","0.72528"
"29896","179.34000","14.94523","0.65733"
"29945","179.63400","14.96974","0.62224"
"29994","179.92800","14.99426","0.62356"
"30043","180.22200","15.01871","0.62660"
"30092","180.51600","15.04317","0.62728"
"30141","180.81000","15.06768","0.63069"
"30190","181.10400","15.09213","0.63303"
"30239","181.39800","15.11671","0.63480"
"30288","181.69200","15.14116","0.56057"
"30337","181.98600","15.16574","0.55908"
"30386","182.28000","15.19025","0.56153"
"30435","182.57400","15.21476","0.56255"
"30484","182.86800","15.23922","0.56502"
"30533","183.16200","15.26373","0.56849"
"30582","183.45600","15.28824","0.56935"
"30631","183.75000","15.31270","0.57171"
"30680","184.04400","15.33721","0.57418"
"30729","184.33800","15.36172","0.57595"
"30778","184.63200","15.38624","0.57894"
"30827","184.92600","15.41069","0.58027"
"30876","185.22000","15.43521","0.58225"
"30925","185.51400","15.45972","0.58437"
"30974","185.80800","15.48417","0.58612"
"31023","186.10200","15.50869","0.58766"
"31072","186.39600","15.53314","0.58920"
"31121","186.69000","15.55766","0.59025"
"31170","186.98400","15.58211","0.59045"
"31219","187.27800","15.60668","0.59129"
"31268","187.57200","15.63114","0.59377"
"31317","187.86600","15.65571","0.59752"
"31366","188.16000","15.68016","0.60124"
"31415","188.45400","15.70474","0.60490"
"31464","188.74800","15.72919","0.60750"
"31513","189.04200","15.75371","0.61046"
"31562","189.33600","15.77822","0.61518"
"31611","189.63000","15.80267","0.61933"
"31660","189.92400","15.82725","0.62322"
"31709","190.21800","15.85170","0.62667"
"31758","190.51200","15.87621","0.62966"
"31807","190.80600","15.90067","0.63176"
"31856","191.10000","15.92524","0.63396"
"31905","191.39400","15.94969","0.63636"
"31954","191.68800","15.97421","0.63851"
"32003","191.98200","15.99872","0.64029"
"32052","192.27600","16.02318","0.64200"
"32101","192.57000","16.04775","0.64351"
"32150","192.86400","16.07220","0.64541"
"32199","193.15800","16.09672","0.64883"
"32248","193.45200","16.12117","0.65032"
"32297","193.74600","16.14569","0.65340"
"32346","194.04000","16.17014","0.65471"
"32395","194.33400","16.19471","0.65737"
"32444","194.62800","16.21923","0.65967"
"32493","194.92200","16.24380","0.66233"
"32542","195.21600","16.26825","0.66536"
"32591","195.51000","16.29271","0.66706"
"32640","195.80400","16.31728","0.66039"
"32689","196.09800","16.34167","0.66246"
"32738","196.39200","16.36619","0.66427"
"32787","196.68600","16.39064","0.66750"
"32836","196.98000","16.41522","0.61617"
"32885","197.27400","16.43967","0.61858"
"32934","197.56800","16.46418","0.61844"
"32983","197.86200","16.48870","0.62137"
"33032","198.15600","16.51321","0.62373"
"33081","198.45000","16.53766","0.62531"
"33130","198.74400","16.56212","0.62775"
"33179","199.03800","16.58669","0.62952"
"33228","199.33200","16.61115","0.63151"
"33277","199.62600","16.63572","0.63407"
"33326","199.92000","16.66017","0.63595"
"33375","200.21400","16.68475","0.63840"
"33424","200.50800","16.70920","0.64001"
"33473","200.80200","16.73372","0.64214"
"33522","201.09600","16.75823","0.64461"
"33571","201.39000","16.78274","0.64684"
"33620","201.68400","16.80720","0.64926"
"33669","201.97800","16.83165","0.65166"
"33718","202.27200","16.85622","0.65413"
"33767","202.56600","16.88068","0.65678"
"33816","202.86000","16.90519","0.65946"
"33865","203.15400","16.92965","0.66339"
"33914","203.44800","16.95422","0.66608"
"33963","203.74200","16.97861","0.66951"
"34012","204.03600","17.00325","0.67257"
"34061","204.33000","17.02770","0.67515"
"34110","204.62400","17.05221","0.67697"
"34159","204.91800","17.07673","0.67902"
"34208","205.21200","17.10118","0.68138"
"34257","205.50600","17.12576","0.68282"
"34306","205.80000","17.15021","0.68375"
"34355","206.09400","17.17472","0.68549"
"34404","206.38800","17.19918","0.68649"
"34453","206.68200","17.22375","0.68739"
"34502","206.97600","17.24820","0.68859"
"34551","207.27000","17.27278","0.68989"
"34600","207.56400","17.29723","0.69127"
"34649","207.85800","17.32174","0.69257"
"34698","208.15200","17.34620","0.69374"
"34747","208.44600","17.37071","0.69582"
"34796","208.74000","17.39523","0.69770"
"34845","209.03400","17.41968","0.69873"
"34894","209.32800","17.44413","0.69925"
"34943","209.62200","17.46865","0.61984"
"34992","209.91600","17.49322","0.57308"
"35041","210.21000","17.51768","0.57206"
"35090","210.50400","17.54219","0.57330"
"35139","210.79800","17.56670","0.57424"
"35188","211.09200","17.59116","0.57423"
"35237","211.38600","17.61567","0.57542"
"35286","211.68000","17.64013","0.57622"
"35335","211.97400","17.66470","0.57691"
"35384","212.26800","17.68915","0.57815"
"35433","212.56200","17.71373","0.57952"
"35482","212.85600","17.73818","0.58017"
"35531","213.15000","17.76275","0.58169"
"35580","213.44400","17.78715","0.58294"
"35629","213.73800","17.81172","0.58405"
"35678","214.03200","17.83623","0.58504"
"35727","214.32600","17.86075","0.58633"
"35776","214.62000","17.88526","0.58729"
"35825","214.91400","17.90965","0.58926"
"35874","215.20800","17.93429","0.59039"
"35923","215.50200","17.95868","0.59222"
"35972","215.79600","17.98320","0.59425"
"36021","216.09000","18.00765","0.59573"
"36070","216.38400","18.03222","0.59954"
"36119","216.67800","18.05668","0.60176"
"36168","216.97200","18.08119","0.60539"
"36217","217.26600","18.10571","0.31790"
"36266","217.56000","18.13016","0.30659"
"36315","217.85400","18.15473","0.31037"
"36364","218.14800","18.17925","0.31636"
"36413","218.44200","18.20376","0.31737"
"36462","218.73600","18.22821","0.31515"
"36511","219.03000","18.25273","0.31364"
"36560","219.32400","18.27718","0.31391"
"36609","219.61800","18.30169","0.31790"
"36658","219.91200","18.32615","0.31937"
"36707","220.20600","18.35072","0.32085"
"36756","220.50000","18.37524","0.32448"
"36805","220.79400","18.39969","0.33129"
"36854","221.08800","18.42426","0.33557"
"36903","221.38200","18.44866","0.33897"
"36952","221.67600","18.47323","0.33932"
"37001","221.97000","18.49763","0.33953"
"37050","222.26400","18.52220","0.34077"
"37099","222.55800","18.54659","0.34202"
"37148","222.85200","18.57117","0.34376"
"37197","223.14600","18.59562","0.34624"
"37246","223.44000","18.62020","0.34887"
"37295","223.73400","18.64465","0.35173"
"37344","224.02800","18.66916","0.35446"
"37393","224.32200","18.69368","0.35779"
"37442","224.61600","18.71819","0.36054"
"37491","224.91000","18.74270","0.36408"
"37540","225.20400","18.76716","0.36628"
"37589","225.49800","18.79173","0.36798"
"37638","225.79200","18.81618","0.36920"
"37687","226.08600","18.84076","0.37096"
"37736","226.38000","18.86521","0.37204"
"37785","226.67400","18.88972","0.37342"
"37834","226.96800","18.91424","0.37526"
"37883","227.26200","18.93869","0.37658"
"37932","227.55600","18.96321","0.37741"
"37981","227.85000","18.98766","0.37956"
"38030","228.14400","19.01224","0.38143"
"38079","228.43800","19.03663","0.38401"
"38128","228.73200","19.06120","0.38684"
"38177","229.02600","19.08566","0.38885"
"38226","229.32000","19.11023","0.39211"
"38275","229.61400","19.13468","0.39436"
"38324","229.90800","19.15920","0.39650"
"38373","230.20200","19.18377","0.39960"
"38422","230.49600","19.20816","0.40147"
"38471","230.79000","19.23274","0.40437"
"38520","231.08400","19.25719","0.40648"
"38569","231.37800","19.28176","0.41006"
"38618","231.67200","19.30616","0.41438"
"38667","231.96600","19.33073","0.41723"
"38716","232.26000","19.35519","0.41901"
"38765","232.55400","19.37970","0.42080"
"38814","232.84800","19.40421","0.42329"
"38863","233.14200","19.42873","0.42559"
"38912","233.43600","19.45324","0.42746"
"38961","233.73000","19.47764","0.42919"
"39010","234.02400","19.50221","0.43061"
"39059","234.31800","19.52666","0.43268"
"39108","234.61200","19.55118","0.43492"
"39157","234.90600","19.57557","0.43713"
"39206","235.20000","19.60015","0.43949"
"39255","235.49400","19.62466","0.44145"
"39304","235.78800","19.64917","0.44465"
"39353","236.08200","19.67369","0.44694"
"39402","236.37600","19.69820","0.45059"
"39451","236.67000","19.72271","0.45359"
"39500","236.96400","19.74717","0.45733"
"39549","237.25800","19.77174","0.46113"
"39598","237.55200","19.79619","0.46438"
"39647","237.84600","19.82071","0.46773"
"39696","238.14000","19.84522","0.47013"
"39745","238.43400","19.86973","0.47393"
"39794","238.72800","19.89419","0.47662"
"39843","239.02200","19.91870","0.47908"
"39892","239.31600","19.94316","0.48080"
"39941","239.61000","19.96767","0.48299"
"39990","239.90400","19.99224","0.48445"
"40039","240.19800","20.01664","0.48596"
"40088","240.49200","20.04127","0.48750"
"40137","240.78600","20.06567","0.48893"
"40186","241.08000","20.09018","0.49026"
"40235","241.37400","20.11457","0.49175"
"40284","241.66800","20.13927","0.49292"
"40333","241.96200","20.16366","0.49487"
"40382","242.25600","20.18823","0.49581"
"40431","242.55000","20.21269","0.49781"
"40480","242.84400","20.23720","0.50020"
"40529","243.13800","20.26178","0.50188"
"40578","243.43200","20.28617","0.50381"
"40627","243.72600","20.31075","0.50685"
"40676","244.02000","20.33520","0.50974"
"40725","244.31400","20.35971","0.51210"
"40774","244.60800","20.38416","0.51494"
"40823","244.90200","20.40868","0.51884"
"40872","245.19600","20.43313","0.51951"
"40921","245.49000","20.45771","0.52165"
"40970","245.78400","20.48222","0.47900"
"41019","246.07800","20.50673","0.48056"
"41068","246.37200","20.53125","0.48106"
"41117","246.66600","20.55564","0.48143"
"41166","246.96000","20.58022","0.48224"
"41215","247.25400","20.60467","0.48359"
"41264","247.54800","20.62918","0.48451"
"41313","247.84200","20.65364","0.48519"
"41362","248.13600","20.67821","0.48620"
"41411","248.43000","20.70272","0.48788"
"41460","248.72400","20.72724","0.48927"
"41509","249.01800","20.75175","0.42515"
"41558","249.31200","20.77621","0.41966"
"41607","249.60600","20.80072","0.41782"
"41656","249.90000","20.82511","0.41810"
"41705","250.19400","20.84969","0.42023"
"41754","250.48800","20.87420","0.42112"
"41803","250.78200","20.89878","0.42289"
"41852","251.07600","20.92317","0.42495"
"41901","251.37000","20.94774","0.42628"
"41950","251.66400","20.97219","0.42843"
"41999","251.95800","20.99671","0.43049"
"42048","252.25200","21.02122","0.43344"
"42097","252.54600","21.04568","0.43558"
"42146","252.84000","21.07019","0.43766"
"42195","253.13400","21.09464","0.44038"
"42244","253.42800","21.11916","0.44285"
"42293","253.72200","21.14367","0.44630"
"42342","254.01600","21.16825","0.44979"
"42391","254.31000","21.19264","0.45396"
"42440","254.60400","21.21721","0.45814"
"42489","254.89800","21.24173","0.46150"
"42538","255.19200","21.26624","0.46541"
"42587","255.48600","21.29075","0.46859"
"42636","255.78000","21.31521","0.47140"
"42685","256.07400","21.33978","0.47387"
"42734","256.36800","21.36418","0.47654"
"42783","256.66200","21.38869","0.47826"
"42832","256.95600","21.41314","0.47969"
"42881","257.25000","21.43772","0.48051"
"42930","257.54400","21.46217","0.48200"
"42979","257.83800","21.48674","0.48288"
"43028","258.13200","21.51114","0.48419"
"43077","258.42600","21.53565","0.48548"
"43126","258.72000","21.56017","0.48672"
"43175","259.01400","21.58468","0.48807"
"43224","259.30800","21.60919","0.48740"
"43273","259.60200","21.63365","0.06320"
"43322","259.89600","21.65816","0.06116"
"43371","260.19000","21.68262","0.06688"
"43420","260.48400","21.70719","0.06377"
"43469","260.77800","21.73164","0.06336"
"43518","261.07200","21.75621","0.06827"
"43567","261.36600","21.78073","0.06528"
"43616","261.66000","21.80524","0.07123"
"43665","261.95400","21.82976","0.06738"
"43714","262.24800","21.85427","0.06761"
"43763","262.54200","21.87873","0.07353"
"43812","262.83600","21.90318","0.07021"
"43861","263.13000","21.92769","0.07483"
"43910","263.42400","21.95215","0.07305"
"43959","263.71800","21.97672","0.07641"
"44008","264.01200","22.00117","0.07904"
"44057","264.30600","22.02569","0.07818"
"44106","264.60000","22.05020","0.08358"
"44155","264.89400","22.07471","0.08223"
"44204","265.18800","22.09923","0.08517"
"44253","265.48200","22.12368","0.09044"
"44302","265.77600","22.14819","0.09020"
"44351","266.07000","22.17271","0.09537"
"44400","266.36400","22.19722","0.09705"
"44449","266.65800","22.22168","0.09781"
"44498","266.95200","22.24619","0.10604"
"44547","267.24600","22.27071","0.10476"
"44596","267.54000","22.29528","0.10689"
"44645","267.83400","22.31973","0.11115"
"44694","268.12800","22.34425","0.11160"
"44743","268.42200","22.36870","0.11470"
"44792","268.71600","22.39321","0.11883"
"44841","269.01000","22.41773","0.11903"
"44890","269.30400","22.44218","0.12052"
"44939","269.59800","22.46675","0.12437"
"44988","269.89200","22.49115","0.12400"
"45037","270.18600","22.51572","0.12719"
"45086","270.48000","22.54018","0.12874"
"45135","270.77400","22.56469","0.12997"
"45184","271.06800","22.58914","0.13276"
"45233","271.36200","22.61366","0.13427"
"45282","271.65600","22.63823","0.13496"
"45331","271.95000","22.66268","0.13738"
"45380","272.24400","22.68720","0.13937"
"45429","272.53800","22.71165","0.13967"
"45478","272.83200","22.73623","0.14182"
"45527","273.12600","22.76062","0.14585"
"45576","273.42000","22.78525","0.14574"
"45625","273.71400","22.80971","0.14842"
"45674","274.00800","22.83428","0.15087"
"45723","274.30200","22.85868","0.15175"
"45772","274.59600","22.88319","0.15347"
"45821","274.89000","22.90776","0.15622"
"45870","275.18400","22.93216","0.15657"
"45919","275.47800","22.95667","0.15750"
"45968","275.77200","22.98112","0.16039"
"46017","276.06600","23.00570","0.16179"
"46066","276.36000","23.03015","0.16245"
"46115","276.65400","23.05478","0.16478"
"46164","276.94800","23.07918","0.16639"
"46213","277.24200","23.10375","0.08039"
"46262","277.53600","23.12821","0.09890"
"46311","277.83000","23.15266","0.07749"
"46360","278.12400","23.17723","0.10192"
"46409","278.41800","23.20169","0.08689"
"46458","278.71200","23.22620","0.09088"
"46507","279.00600","23.25066","0.10194"
"46556","279.30000","23.27523","0.09161"
"46605","279.59400","23.29974","0.11461"
"46654","279.88800","23.32420","0.09629"
"46703","280.18200","23.34871","0.10913"
"46752","280.47600","23.37316","0.11243"
"46801","280.77000","23.39768","0.10618"
"46850","281.06400","23.42219","0.12081"
"46899","281.35800","23.44670","0.11232"
"46948","281.65200","23.47122","0.11913"
"46997","281.94600","23.49573","0.12087"
"47046","282.24000","23.52019","0.11721"
"47095","282.53400","23.54476","0.12887"
"47144","282.82800","23.56909","0.12284"
"47193","283.12200","23.59373","0.12560"
"47242","283.41600","23.61818","0.13323"
"47291","283.71000","23.64269","0.12733"
"47340","284.00400","23.66721","0.13263"
"47389","284.29800","23.69172","0.13570"
"47438","284.59200","23.71618","0.13308"
"47487","284.88600","23.74069","0.13880"
"47536","285.18000","23.76526","0.13760"
"47585","285.47400","23.78966","0.14001"
"47634","285.76800","23.81423","0.14510"
"47683","286.06200","23.83863","0.14132"
"47732","286.35600","23.86320","0.14501"
"47781","286.65000","23.88771","0.15070"
"47830","286.94400","23.91228","0.14797"
"47879","287.23800","23.93674","0.15039"
"47928","287.53200","23.96119","0.15493"
"47977","287.82600","23.98571","0.15454"
"48026","288.12000","24.01016","0.15595"
"48075","288.41400","24.03468","0.15902"
"48124","288.70800","24.05913","0.15817"
"48173","289.00200","24.08370","0.16124"
"48222","289.29600","24.10822","0.16407"
"48271","289.59000","24.13273","0.16296"
"48320","289.88400","24.15718","0.16527"
"48369","290.17800","24.18170","0.16767"
"48418","290.47200","24.20621","0.16717"
"48467","290.76600","24.23072","0.16833"
"48516","291.06000","24.25524","0.16974"
"48565","291.35400","24.27969","0.17017"
"48614","291.64800","24.30427","0.17072"
"48663","291.94200","24.32866","0.17190"
"48712","292.23600","24.35323","0.17233"
"48761","292.53000","24.37769","0.17269"
"48810","292.82400","24.40220","0.17359"
"48859","293.11800","24.42665","0.17419"
"48908","293.41200","24.45123","0.17392"
"48957","293.70600","24.47574","0.17519"
"49006","294.00000","24.50019","0.17566"
"49055","294.29400","24.52471","0.17631"
"49104","294.58800","24.54916","0.17662"
"49153","294.88200","24.57368","0.17778"
"49202","295.17600","24.59813","0.17751"
"49251","295.47000","24.62271","0.17878"
"49300","295.76400","24.64716","0.17935"
"49349","296.05800","24.67167","0.18016"
"49398","296.35200","24.69619","0.17982"
"49447","296.64600","24.72070","0.18149"
"49496","296.94000","24.74521","0.18208"
"49545","297.23400","24.76967","0.18242"
"49594","297.52800","24.79424","0.18335"
"49643","297.82200","24.81870","0.18421"
"49692","298.11600","24.84321","0.18466"
"49741","298.41000","24.86766","0.18532"
"49790","298.70400","24.89224","0.18602"
"49839","298.99800","24.91669","0.18648"
"49888","299.29200","24.94120","0.18660"
"49937","299.58600","24.96572","0.18717"
"49986","299.88000","24.99023","0.18841"
"50035","300.17400","25.01475","0.18846"
"50084","300.46800","25.03920","0.18912"
"50133","300.76200","25.06371","0.18934"
"50182","301.05600","25.08817","0.18984"
"50231","301.35000","25.11274","0.19033"
"50280","301.64400","25.13713","0.19089"
"50329","301.93800","25.16177","0.19224"
"50378","302.23200","25.18616","0.19196"
"50427","302.52600","25.21074","0.19218"
"50476","302.82000","25.23519","0.19273"
"50525","303.11400","25.25970","0.19292"
"50574","303.40800","25.28422","0.19354"
"50623","303.70200","25.30867","0.19480"
"50672","303.99600","25.33324","0.19471"
"50721","304.29000","25.35770","0.19541"
"50770","304.58400","25.38221","0.19601"
"50819","304.87800","25.40667","0.19682"
"50868","305.17200","25.43124","0.19523"
"50917","305.46600","25.45569","0.19452"
"50966","305.76000","25.48021","0.19444"
"51015","306.05400","25.50466","0.19563"
"51064","306.34800","25.52917","0.19498"
"51113","306.64200","25.55375","0.19574"
"51162","306.93600","25.57814","0.19682"
"51211","307.23000","25.60272","0.19785"
"51260","307.52400","25.62717","0.19711"
"51309","307.81800","25.65168","0.19723"
"51358","308.11200","25.67614","0.19398"
"51407","308.40600","25.70077","0.19344"
"51456","308.70000","25.72516","0.19312"
"51505","308.99400","25.74968","0.19371"
"51554","309.28800","25.77419","0.19382"
"51603","309.58200","25.79876","0.19385"
"51652","309.87600","25.82328","0.19432"
"51701","310.17000","25.84767","0.19436"
"51750","310.46400","25.87225","0.19478"
"51799","310.75800","25.89670","0.19445"
"51848","311.05200","25.92121","0.19466"
"51897","311.34600","25.94567","0.19485"
"51946","311.64000","25.97018","0.19562"
"51995","311.93400","25.99464","0.19589"
"52044","312.22800","26.01921","0.19661"
"52093","312.52200","26.04372","0.19665"
"52142","312.81600","26.06824","0.19666"
"52191","313.11000","26.09275","0.19633"
"52240","313.40400","26.11721","0.19670"
"52289","313.69800","26.14166","0.19778"
"52338","313.99200","26.16617","0.19817"
"52387","314.28600","26.19075","0.19807"
"52436","314.58000","26.21514","0.19894"
"52485","314.87400","26.23971","0.19883"
"52534","315.16800","26.26423","0.19883"
"52583","315.46200","26.28874","0.19817"
"52632","315.75600","26.31325","0.19933"
"52681","316.05000","26.33771","0.19901"
"52730","316.34400","26.36228","0.19954"
"52779","316.63800","26.38668","0.19985"
"52828","316.93200","26.41119","0.19973"
"52877","317.22600","26.43564","0.20078"
"52926","317.52000","26.46028","0.20139"
"52975","317.81400","26.48467","0.20173"
"53024","318.10800","26.50924","0.20097"
"53073","318.40200","26.53370","0.20133"
"53122","318.69600","26.55821","0.20110"
"53171","318.99000","26.58267","0.20150"
"53220","319.28400","26.60718","0.20191"
"53269","319.57800","26.63169","0.20264"
"53318","319.87200","26.65615","0.20326"
"53367","320.16600","26.68072","0.20309"
"53416","320.46000","26.70517","0.20346"
"53465","320.75400","26.72969","0.20422"
"53514","321.04800","26.75420","0.20432"
"53563","321.34200","26.77872","0.20432"
"53612","321.63600","26.80317","0.20442"
"53661","321.93000","26.82768","0.20568"
"53710","322.22400","26.85220","0.20555"
"53759","322.51800","26.87671","0.20623"
"53808","322.81200","26.90129","0.20689"
"53857","323.10600","26.92568","0.20758"
"53906","323.40000","26.95019","0.20726"
"53955","323.69400","26.97464","0.20790"
"54004","323.98800","26.99922","0.20797"
"54053","324.28200","27.02361","0.20854"
"54102","324.57600","27.04825","0.20850"
"54151","324.87000","27.07270","0.20869"
"54200","325.16400","27.09716","0.20959"
"54249","325.45800","27.12173","0.21033"
"54298","325.75200","27.14624","0.21036"
"54347","326.04600","27.17070","0.21094"
"54396","326.34000","27.19515","0.21071"
"54445","326.63400","27.21972","0.21120"
"54494","326.92800","27.24418","0.21137"
"54543","327.22200","27.26875","0.21167"
"54592","327.51600","27.29321","0.21228"
"54641","327.81000","27.31778","0.21207"
"54690","328.10400","27.34223","0.21264"
"54739","328.39800","27.36669","0.21283"
"54788","328.69200","27.39120","0.21335"
"54837","328.98600","27.41566","0.21365"
"54886","329.28000","27.44017","0.21369"
"54935","329.57400","27.46468","0.21450"
"54984","329.86800","27.48920","0.21462"
"55033","330.16200","27.51371","0.21453"
"55082","330.45600","27.53822","0.21508"
"55131","330.75000","27.56268","0.21552"
"55180","331.04400","27.58725","0.21570"
"55229","331.33800","27.61170","0.21637"
"55278","331.63200","27.63616","0.21646"
"55327","331.92600","27.66067","0.21720"
"55376","332.22000","27.68518","0.21769"
"55425","332.51400","27.70970","0.21737"
"55474","332.80800","27.73415","0.21813"
"55523","333.10200","27.75872","0.21853"
"55572","333.39600","27.78318","0.21840"
"55621","333.69000","27.80769","0.21931"
"55670","333.98400","27.83221","0.21943"
"55719","334.27800","27.85678","0.21993"
"55768","334.57200","27.88124","0.21940"
"55817","334.86600","27.90569","0.22024"
"55866","335.16000","27.93026","0.22057"
"55915","335.45400","27.95465","0.22064"
"55964","335.74800","27.97923","0.22132"
"56013","336.04200","28.00362","0.22098"
"56062","336.33600","28.02820","0.22139"
"56111","336.63000","28.05265","0.22190"
"56160","336.92400","28.07722","0.22223"
"56209","337.21800","28.10168","0.22228"
"56258","337.51200","28.12625","0.22222"
"56307","337.80600","28.15071","0.22297"
"56356","338.10000","28.17522","0.22317"
"56405","338.39400","28.19973","0.22412"
"56454","338.68800","28.22419","0.22373"
"56503","338.98200","28.24870","0.22449"
"56552","339.27600","28.27316","0.22433"
"56601","339.57000","28.29773","0.22508"
"56650","339.86400","28.32218","0.22543"
"56699","340.15800","28.34676","0.22616"
"56748","340.45200","28.37121","0.22716"
"56797","340.74600","28.39573","0.22655"
"56846","341.04000","28.42018","0.22685"
"56895","341.33400","28.44469","0.22660"
"56944","341.62800","28.46926","0.22661"
"56993","341.92200","28.49366","0.22775"
"57042","342.21600","28.51817","0.22804"
"57091","342.51000","28.54263","0.22748"
"57140","342.80400","28.56726","0.22676"
"57189","343.09800","28.59166","0.22757"
"57238","343.39200","28.61623","0.22817"
"57287","343.68600","28.64068","0.22752"
"57336","343.98000","28.66520","0.22767"
"57385","344.27400","28.68965","0.22876"
"57434","344.56800","28.71416","0.22881"
"57483","344.86200","28.73874","0.22924"
"57532","345.15600","28.76319","0.22931"
"57581","345.45000","28.78777","0.22988"
"57630","345.74400","28.81222","0.23023"
"57679","346.03800","28.83673","0.22976"
"57728","346.33200","28.86119","0.23042"
"57777","346.62600","28.88576","0.23093"
"57826","346.92000","28.91021","0.23007"
"57875","347.21400","28.93473","0.23056"
"57924","347.50800","28.95918","0.23071"
"57973","347.80200","28.98369","0.23087"
"58022","348.09600","29.00827","0.23160"
"58071","348.39000","29.03272","0.23174"
"58120","348.68400","29.05724","0.23210"
"58169","348.97800","29.08169","0.23245"
"58218","349.27200","29.10620","0.23306"
"58267","349.56600","29.13066","0.23314"
"58316","349.86000","29.15517","0.23344"
"58365","350.15400","29.17974","0.23426"
"58414","350.44800","29.20420","0.23429"
"58463","350.74200","29.22871","0.23440"
"58512","351.03600","29.25317","0.23408"
"58561","351.33000","29.27774","0.23496"
"58610","351.62400","29.30219","0.23507"
"58659","351.91800","29.32677","0.23477"
"58708","352.21200","29.35116","0.23517"
"58757","352.50600","29.37580","0.23515"
"58806","352.80000","29.40019","0.23622"
"58855","353.09400","29.42470","0.23569"
"58904","353.38800","29.44916","0.23635"
"58953","353.68200","29.47373","0.23711"
"59002","353.97600","29.49824","0.23664"
"59051","354.27000","29.52270","0.23742"
"59100","354.56400","29.54727","0.23771"
"59149","354.85800","29.57166","0.23774"
"59198","355.15200","29.59618","0.23801"
"59247","355.44600","29.62057","0.23759"
"59296","355.74000","29.64521","0.23780"
"59345","356.03400","29.66966","0.23832"
"59394","356.32800","29.69417","0.23813"
"59443","356.62200","29.71869","0.23764"
"59492","356.91600","29.74320","0.00529"
"59541","357.21000","29.76777","0.01115"
"59590","357.50400","29.79223","0.00342"
"59639","357.79800","29.81674","-0.00276"
"59688","358.09200","29.84114","-0.00404"
"59737","358.38600","29.86571","-0.00278"
"59786","358.68000","29.89017","-0.00364"
"59835","358.97400","29.91474","-0.00466"
"59884","359.26800","29.93919","-0.00500"
"59933","359.56200","29.96365","0.00003"
"59982","359.85600","29.98816","-0.00280"
"60031","360.15000","30.01267","-0.00345"
"60080","360.44400","30.03725","-0.00261"
"60129","360.73800","30.06170","-0.00096"
"60178","361.03200","30.08621","-0.00441"
"60227","361.32600","30.11067","-0.00418"
"60276","361.62000","30.13524","-0.00052"
"60325","361.91400","30.15963","-0.00271"
"60374","362.20800","30.18421","-0.00437"
"60423","362.50200","30.20866","-0.00299"
"60460","362.72400","30.22720","-0.00119"