File: Trajectories_together/170107_1Specimen_RawData_4.csv
"","V1","V2","V3"
"1","End date","1/7/2017",""
"2","Specimen label","18DT_44",""
"3","Maximum Load","0.20391","N"
"4","Time","Extension","Load"
"5","(s)","(mm)","(N)"
"6","0.00000","0.00000","0.00027"
"73","0.40200","0.03378","0.00028"
"140","0.80400","0.06720","0.00117"
"207","1.20600","0.10075","0.00133"
"274","1.60800","0.13423","0.00089"
"341","2.01000","0.16771","0.00139"
"408","2.41200","0.20119","0.00107"
"475","2.81400","0.23473","0.00128"
"542","3.21600","0.26822","0.00140"
"609","3.61800","0.30170","0.00205"
"676","4.02000","0.33518","0.00153"
"743","4.42200","0.36878","0.00163"
"810","4.82400","0.40220","0.00208"
"877","5.22600","0.43575","0.00234"
"944","5.62800","0.46917","0.00185"
"1011","6.03000","0.50277","0.00195"
"1078","6.43200","0.53625","0.00244"
"1145","6.83400","0.56973","0.00242"
"1212","7.23600","0.60322","0.00234"
"1279","7.63800","0.63670","0.00222"
"1346","8.04000","0.67018","0.00282"
"1413","8.44200","0.70372","0.00231"
"1480","8.84400","0.73715","0.00291"
"1547","9.24600","0.77075","0.00275"
"1614","9.64800","0.80423","0.00260"
"1681","10.05000","0.83771","0.00281"
"1748","10.45200","0.87125","0.00302"
"1815","10.85400","0.90474","0.00296"
"1882","11.25600","0.93822","0.00301"
"1949","11.65800","0.97170","0.00265"
"2016","12.06000","1.00518","0.00276"
"2083","12.46200","1.03872","0.00306"
"2150","12.86400","1.07221","0.00298"
"2217","13.26600","1.10575","0.00316"
"2284","13.66800","1.13917","0.00316"
"2351","14.07000","1.17271","0.00287"
"2418","14.47200","1.20625","0.00327"
"2485","14.87400","1.23974","0.00293"
"2552","15.27600","1.27316","0.00318"
"2619","15.67800","1.30670","0.00342"
"2686","16.08000","1.34024","0.00337"
"2753","16.48200","1.37372","0.00326"
"2820","16.88400","1.40721","0.00381"
"2887","17.28600","1.44075","0.00372"
"2954","17.68800","1.47423","0.00403"
"3021","18.09000","1.50771","0.00321"
"3088","18.49200","1.54125","0.00387"
"3155","18.89400","1.57474","0.00410"
"3222","19.29600","1.60822","0.00352"
"3289","19.69800","1.64164","0.00370"
"3356","20.10000","1.67518","0.00365"
"3423","20.50200","1.70872","0.00401"
"3490","20.90400","1.74221","0.00399"
"3557","21.30600","1.77569","0.00376"
"3624","21.70800","1.80917","0.00398"
"3691","22.11000","1.84271","0.00343"
"3758","22.51200","1.87632","0.00397"
"3825","22.91400","1.90974","0.00407"
"3892","23.31600","1.94316","0.00404"
"3959","23.71800","1.97676","0.00452"
"4026","24.12000","2.01030","0.00426"
"4093","24.52200","2.04373","0.00409"
"4160","24.92400","2.07721","0.00437"
"4227","25.32600","2.11075","0.00431"
"4294","25.72800","2.14423","0.00396"
"4361","26.13000","2.17771","0.00511"
"4428","26.53200","2.21120","0.00400"
"4495","26.93400","2.24480","0.00446"
"4562","27.33600","2.27822","0.00436"
"4629","27.73800","2.31170","0.00451"
"4696","28.14000","2.34524","0.00475"
"4763","28.54200","2.37873","0.00463"
"4830","28.94400","2.41227","0.00481"
"4897","29.34600","2.44563","0.00489"
"4964","29.74800","2.47917","0.00492"
"5031","30.15000","2.51272","0.00501"
"5098","30.55200","2.54626","0.00467"
"5165","30.95400","2.57968","0.00503"
"5232","31.35600","2.61316","0.00476"
"5299","31.75800","2.64670","0.00501"
"5366","32.16000","2.68025","0.00412"
"5433","32.56200","2.71367","0.00470"
"5500","32.96400","2.74727","0.00477"
"5567","33.36600","2.78075","0.00467"
"5634","33.76800","2.81423","0.00538"
"5701","34.17000","2.84766","0.00481"
"5768","34.57200","2.88126","0.00491"
"5835","34.97400","2.91480","0.00511"
"5902","35.37600","2.94822","0.00478"
"5969","35.77800","2.98164","0.00486"
"6036","36.18000","3.01519","0.00523"
"6103","36.58200","3.04879","0.00534"
"6170","36.98400","3.08221","0.00478"
"6237","37.38600","3.11569","0.00492"
"6304","37.78800","3.14923","0.00541"
"6371","38.19000","3.18272","0.00510"
"6438","38.59200","3.21620","0.00506"
"6505","38.99400","3.24968","0.00525"
"6572","39.39600","3.28322","0.00541"
"6639","39.79800","3.31670","0.00495"
"6706","40.20000","3.35025","0.00539"
"6773","40.60200","3.38367","0.00514"
"6840","41.00400","3.41721","0.00563"
"6907","41.40600","3.45075","0.00541"
"6974","41.80800","3.48418","0.00536"
"7041","42.21000","3.51772","0.00586"
"7108","42.61200","3.55126","0.00535"
"7175","43.01400","3.58480","0.00529"
"7242","43.41600","3.61816","0.00568"
"7309","43.81800","3.65165","0.00569"
"7376","44.22000","3.68525","0.00525"
"7443","44.62200","3.71873","0.00553"
"7510","45.02400","3.75221","0.00534"
"7577","45.42600","3.78569","0.00491"
"7644","45.82800","3.81924","0.00587"
"7711","46.23000","3.85272","0.00574"
"7778","46.63200","3.88620","0.00546"
"7845","47.03400","3.91968","0.00563"
"7912","47.43600","3.95322","0.00572"
"7979","47.83800","3.98671","0.00556"
"8046","48.24000","4.02019","0.00610"
"8113","48.64200","4.05367","0.00603"
"8180","49.04400","4.08721","0.00519"
"8247","49.44600","4.12075","0.00564"
"8314","49.84800","4.15418","0.00573"
"8381","50.25000","4.18772","0.00597"
"8448","50.65200","4.22126","0.00571"
"8515","51.05400","4.25480","0.00574"
"8582","51.45600","4.28823","0.00595"
"8649","51.85800","4.32165","0.00563"
"8716","52.26000","4.35525","0.00606"
"8783","52.66200","4.38873","0.00618"
"8850","53.06400","4.42221","0.00602"
"8917","53.46600","4.45576","0.00594"
"8984","53.86800","4.48918","0.00620"
"9051","54.27000","4.52278","0.00657"
"9118","54.67200","4.55620","0.00608"
"9185","55.07400","4.58968","0.00590"
"9252","55.47600","4.62323","0.00601"
"9319","55.87800","4.65671","0.00606"
"9386","56.28000","4.69019","0.00650"
"9453","56.68200","4.72373","0.00591"
"9520","57.08400","4.75727","0.00662"
"9587","57.48600","4.79076","0.00575"
"9654","57.88800","4.82418","0.00650"
"9721","58.29000","4.85772","0.00687"
"9788","58.69200","4.89126","0.00622"
"9855","59.09400","4.92474","0.00619"
"9922","59.49600","4.95817","0.00651"
"9989","59.89800","4.99171","0.00630"
"10056","60.30000","5.02525","0.00634"
"10123","60.70200","5.05873","0.00702"
"10190","61.10400","5.09221","0.00733"
"10257","61.50600","5.12570","0.00717"
"10324","61.90800","5.15924","0.00696"
"10391","62.31000","5.19272","0.00665"
"10458","62.71200","5.22614","0.00700"
"10525","63.11400","5.25974","0.00672"
"10592","63.51600","5.29323","0.00667"
"10659","63.91800","5.32671","0.00710"
"10726","64.32000","5.36019","0.00671"
"10793","64.72200","5.39373","0.00625"
"10860","65.12400","5.42728","0.00705"
"10927","65.52600","5.46076","0.00704"
"10994","65.92800","5.49412","0.00710"
"11061","66.33000","5.52772","0.00739"
"11128","66.73200","5.56126","0.00735"
"11195","67.13400","5.59475","0.00721"
"11262","67.53600","5.62817","0.00714"
"11329","67.93800","5.66171","0.00719"
"11396","68.34000","5.69525","0.00655"
"11463","68.74200","5.72873","0.00706"
"11530","69.14400","5.76222","0.00687"
"11597","69.54600","5.79576","0.00702"
"11664","69.94800","5.82924","0.00732"
"11731","70.35000","5.86272","0.00693"
"11798","70.75200","5.89620","0.00645"
"11865","71.15400","5.92975","0.00636"
"11932","71.55600","5.96329","0.00687"
"11999","71.95800","5.99671","0.00653"
"12066","72.36000","6.03013","0.00683"
"12133","72.76200","6.06373","0.00690"
"12200","73.16400","6.09722","0.00689"
"12267","73.56600","6.13076","0.00718"
"12334","73.96800","6.16418","0.00706"
"12401","74.37000","6.19772","0.00720"
"12468","74.77200","6.23120","0.00721"
"12535","75.17400","6.26475","0.00695"
"12602","75.57600","6.29823","0.00710"
"12669","75.97800","6.33171","0.00720"
"12736","76.38000","6.36519","0.00708"
"12803","76.78200","6.39868","0.00693"
"12870","77.18400","6.43216","0.00753"
"12937","77.58600","6.46576","0.00748"
"13004","77.98800","6.49924","0.00724"
"13071","78.39000","6.53272","0.00713"
"13138","78.79200","6.56621","0.00761"
"13205","79.19400","6.59975","0.00779"
"13272","79.59600","6.63329","0.00737"
"13339","79.99800","6.66671","0.00719"
"13406","80.40000","6.70019","0.00775"
"13473","80.80200","6.73374","0.00673"
"13540","81.20400","6.76728","0.00706"
"13607","81.60600","6.80076","0.00714"
"13674","82.00800","6.83418","0.00650"
"13741","82.41000","6.86772","0.00723"
"13808","82.81200","6.90127","0.00713"
"13875","83.21400","6.93475","0.00681"
"13942","83.61600","6.96823","0.00664"
"14009","84.01800","7.00171","0.00743"
"14076","84.42000","7.03525","0.00726"
"14143","84.82200","7.06868","0.00727"
"14210","85.22400","7.10216","0.00768"
"14277","85.62600","7.13582","0.00705"
"14344","86.02800","7.16924","0.00743"
"14411","86.43000","7.20267","0.00736"
"14478","86.83200","7.23627","0.00745"
"14545","87.23400","7.26975","0.00732"
"14612","87.63600","7.30329","0.00720"
"14679","88.03800","7.33671","0.00765"
"14746","88.44000","7.37020","0.00765"
"14813","88.84200","7.40374","0.00726"
"14880","89.24400","7.43728","0.00807"
"14947","89.64600","7.47070","0.00779"
"15014","90.04800","7.50418","0.00750"
"15081","90.45000","7.53779","0.00801"
"15148","90.85200","7.57127","0.00739"
"15215","91.25400","7.60469","0.00716"
"15282","91.65600","7.63823","0.00763"
"15349","92.05800","7.67177","0.00730"
"15416","92.46000","7.70526","0.00726"
"15483","92.86200","7.73868","0.00737"
"15550","93.26400","7.77222","0.00779"
"15617","93.66600","7.80576","0.00791"
"15684","94.06800","7.83924","0.00819"
"15751","94.47000","7.87267","0.00768"
"15818","94.87200","7.90621","0.00802"
"15885","95.27400","7.93975","0.00790"
"15952","95.67600","7.97323","0.00762"
"16019","96.07800","8.00666","0.00816"
"16086","96.48000","8.04026","0.00798"
"16153","96.88200","8.07368","0.00753"
"16220","97.28400","8.10722","0.00774"
"16287","97.68600","8.14070","0.00787"
"16354","98.08800","8.17419","0.00777"
"16421","98.49000","8.20773","0.00762"
"16488","98.89200","8.24121","0.00777"
"16555","99.29400","8.27469","0.00763"
"16622","99.69600","8.30823","0.00777"
"16689","100.09800","8.34172","0.00805"
"16756","100.50000","8.37526","0.00777"
"16823","100.90200","8.40868","0.00813"
"16890","101.30400","8.44222","0.00790"
"16957","101.70600","8.47576","0.00791"
"17024","102.10800","8.50919","0.00791"
"17091","102.51000","8.54267","0.00779"
"17158","102.91200","8.57621","0.00798"
"17225","103.31400","8.60975","0.00791"
"17292","103.71600","8.64323","0.00799"
"17359","104.11800","8.67672","0.00808"
"17426","104.52000","8.71020","0.00889"
"17493","104.92200","8.74368","0.00872"
"17560","105.32400","8.77722","0.00846"
"17627","105.72600","8.81065","0.00878"
"17694","106.12800","8.84419","0.00832"
"17761","106.53000","8.87767","0.00857"
"17828","106.93200","8.91121","0.00775"
"17895","107.33400","8.94469","0.00861"
"17962","107.73600","8.97830","0.00827"
"18029","108.13800","9.01172","0.00793"
"18096","108.54000","9.04520","0.00833"
"18163","108.94200","9.07868","0.00872"
"18230","109.34400","9.11222","0.00846"
"18297","109.74600","9.14577","0.00844"
"18364","110.14800","9.17925","0.00865"
"18431","110.55000","9.21267","0.00873"
"18498","110.95200","9.24621","0.00782"
"18565","111.35400","9.27975","0.00848"
"18632","111.75600","9.31324","0.00799"
"18699","112.15800","9.34672","0.00824"
"18766","112.56000","9.38020","0.00858"
"18833","112.96200","9.41368","0.00817"
"18900","113.36400","9.44722","0.00818"
"18967","113.76600","9.48071","0.00837"
"19034","114.16800","9.51425","0.00904"
"19101","114.57000","9.54767","0.00900"
"19168","114.97200","9.58115","0.00824"
"19235","115.37400","9.61469","0.00829"
"19302","115.77600","9.64830","0.00898"
"19369","116.17800","9.68172","0.00881"
"19436","116.58000","9.71520","0.00919"
"19503","116.98200","9.74874","0.00902"
"19570","117.38400","9.78223","0.00952"
"19637","117.78600","9.81577","0.00941"
"19704","118.18800","9.84925","0.00892"
"19771","118.59000","9.88273","0.00935"
"19838","118.99200","9.91627","0.00942"
"19905","119.39400","9.94976","0.00823"
"19972","119.79600","9.98324","0.00790"
"20039","120.19800","10.01672","0.00784"
"20106","120.60000","10.05026","0.00823"
"20173","121.00200","10.08374","0.00798"
"20240","121.40400","10.11717","0.00829"
"20307","121.80600","10.15071","0.00782"
"20374","122.20800","10.18425","0.00843"
"20441","122.61000","10.21773","0.00814"
"20508","123.01200","10.25115","0.00781"
"20575","123.41400","10.28470","0.00830"
"20642","123.81600","10.31824","0.00827"
"20709","124.21800","10.35178","0.00848"
"20776","124.62000","10.38520","0.00895"
"20843","125.02200","10.41874","0.00829"
"20910","125.42400","10.45229","0.00902"
"20977","125.82600","10.48583","0.00858"
"21044","126.22800","10.51919","0.00826"
"21111","126.63000","10.55273","0.00891"
"21178","127.03200","10.58628","0.00993"
"21245","127.43400","10.61976","0.00923"
"21312","127.83600","10.65318","0.00959"
"21379","128.23800","10.68672","0.00984"
"21446","128.64000","10.72026","0.00960"
"21513","129.04200","10.75375","0.00996"
"21580","129.44400","10.78717","0.01041"
"21647","129.84600","10.82071","0.01033"
"21714","130.24800","10.85425","0.01078"
"21781","130.65000","10.88773","0.01079"
"21848","131.05200","10.92115","0.01079"
"21915","131.45400","10.95470","0.01114"
"21982","131.85600","10.98830","0.01146"
"22049","132.25800","11.02178","0.01045"
"22116","132.66000","11.05514","0.01072"
"22183","133.06200","11.08869","0.01100"
"22250","133.46400","11.12223","0.00949"
"22317","133.86600","11.15577","0.01000"
"22384","134.26800","11.18913","0.01050"
"22451","134.67000","11.22274","0.01103"
"22518","135.07200","11.25622","0.01159"
"22585","135.47400","11.28976","0.01082"
"22652","135.87600","11.32318","0.01105"
"22719","136.27800","11.35672","0.01155"
"22786","136.68000","11.39021","0.01125"
"22853","137.08200","11.42369","0.01231"
"22920","137.48400","11.45717","0.01202"
"22987","137.88600","11.49077","0.01121"
"23054","138.28800","11.52419","0.01126"
"23121","138.69000","11.55768","0.01279"
"23188","139.09200","11.59116","0.01314"
"23255","139.49400","11.62476","0.01259"
"23322","139.89600","11.65824","0.01264"
"23389","140.29800","11.69172","0.01361"
"23456","140.70000","11.72521","0.01366"
"23523","141.10200","11.75869","0.01357"
"23590","141.50400","11.79223","0.01352"
"23657","141.90600","11.82571","0.01369"
"23724","142.30800","11.85919","0.01393"
"23791","142.71000","11.89274","0.01414"
"23858","143.11200","11.92622","0.01385"
"23925","143.51400","11.95970","0.01306"
"23992","143.91600","11.99318","0.01380"
"24059","144.31800","12.02672","0.01359"
"24126","144.72000","12.06027","0.01377"
"24193","145.12200","12.09375","0.01344"
"24260","145.52400","12.12717","0.01213"
"24327","145.92600","12.16077","0.01225"
"24394","146.32800","12.19425","0.01183"
"24461","146.73000","12.22774","0.00911"
"24528","147.13200","12.26122","0.00761"
"24595","147.53400","12.29476","0.00852"
"24662","147.93600","12.32830","0.00896"
"24729","148.33800","12.36167","0.00780"
"24796","148.74000","12.39515","0.00728"
"24863","149.14200","12.42869","0.00816"
"24930","149.54400","12.46223","0.00858"
"24997","149.94600","12.49571","0.00731"
"25064","150.34800","12.52925","0.00761"
"25131","150.75000","12.56274","0.00738"
"25198","151.15200","12.59622","0.00728"
"25265","151.55400","12.62970","0.00740"
"25332","151.95600","12.66318","0.00770"
"25399","152.35800","12.69679","0.00820"
"25466","152.76000","12.73027","0.00861"
"25533","153.16200","12.76369","0.00745"
"25600","153.56400","12.79723","0.00814"
"25667","153.96600","12.83077","0.00836"
"25734","154.36800","12.86426","0.00821"
"25801","154.77000","12.89774","0.00813"
"25868","155.17200","12.93122","0.00842"
"25935","155.57400","12.96476","0.00858"
"26002","155.97600","12.99824","0.00822"
"26069","156.37800","13.03173","0.00817"
"26136","156.78000","13.06521","0.00875"
"26203","157.18200","13.09869","0.00782"
"26270","157.58400","13.13223","0.00924"
"26337","157.98600","13.16572","0.00885"
"26404","158.38800","13.19920","0.00867"
"26471","158.79000","13.23274","0.00880"
"26538","159.19200","13.26622","0.00885"
"26605","159.59400","13.29964","0.00888"
"26672","159.99600","13.33325","0.00907"
"26739","160.39800","13.36679","0.00876"
"26806","160.80000","13.40027","0.00945"
"26873","161.20200","13.43369","0.00908"
"26940","161.60400","13.46717","0.00942"
"27007","162.00600","13.50072","0.00959"
"27074","162.40800","13.53420","0.00991"
"27141","162.81000","13.56768","0.00970"
"27208","163.21200","13.60122","0.00949"
"27275","163.61400","13.63476","0.00910"
"27342","164.01600","13.66825","0.00973"
"27409","164.41800","13.70173","0.01028"
"27476","164.82000","13.73521","0.01002"
"27543","165.22200","13.76875","0.00978"
"27610","165.62400","13.80223","0.00952"
"27677","166.02600","13.83572","0.00886"
"27744","166.42800","13.86920","0.00962"
"27811","166.83000","13.90274","0.00944"
"27878","167.23200","13.93622","0.00963"
"27945","167.63400","13.96970","0.00976"
"28012","168.03600","14.00325","0.00993"
"28079","168.43800","14.03673","0.00973"
"28146","168.84000","14.07027","0.00986"
"28213","169.24200","14.10363","0.01028"
"28280","169.64400","14.13723","0.00952"
"28347","170.04600","14.17072","0.00986"
"28414","170.44800","14.20426","0.01035"
"28481","170.85000","14.23768","0.01026"
"28548","171.25200","14.27116","0.00988"
"28615","171.65400","14.30471","0.01047"
"28682","172.05600","14.33825","0.01068"
"28749","172.45800","14.37167","0.01038"
"28816","172.86000","14.40521","0.01087"
"28883","173.26200","14.43869","0.01088"
"28950","173.66400","14.47224","0.01059"
"29017","174.06600","14.50566","0.01060"
"29084","174.46800","14.53920","0.01089"
"29151","174.87000","14.57274","0.01059"
"29218","175.27200","14.60623","0.01114"
"29285","175.67400","14.63971","0.01092"
"29352","176.07600","14.67319","0.01106"
"29419","176.47800","14.70673","0.01094"
"29486","176.88000","14.74027","0.01149"
"29553","177.28200","14.77363","0.01129"
"29620","177.68400","14.80724","0.01149"
"29687","178.08600","14.84072","0.01168"
"29754","178.48800","14.87426","0.01127"
"29821","178.89000","14.90768","0.01194"
"29888","179.29200","14.94123","0.01192"
"29955","179.69400","14.97471","0.01228"
"30022","180.09600","15.00819","0.01229"
"30089","180.49800","15.04167","0.01243"
"30156","180.90000","15.07527","0.01220"
"30223","181.30200","15.10870","0.01253"
"30290","181.70400","15.14224","0.01342"
"30357","182.10600","15.17572","0.01290"
"30424","182.50800","15.20926","0.01309"
"30491","182.91000","15.24280","0.01323"
"30558","183.31200","15.27623","0.01385"
"30625","183.71400","15.30971","0.01358"
"30692","184.11600","15.34319","0.01353"
"30759","184.51800","15.37673","0.01288"
"30826","184.92000","15.41021","0.01379"
"30893","185.32200","15.44364","0.01389"
"30960","185.72400","15.47730","0.01349"
"31027","186.12600","15.51078","0.01393"
"31094","186.52800","15.54426","0.01404"
"31161","186.93000","15.57768","0.01393"
"31228","187.33200","15.61123","0.01419"
"31295","187.73400","15.64477","0.01487"
"31362","188.13600","15.67825","0.01534"
"31429","188.53800","15.71167","0.01488"
"31496","188.94000","15.74527","0.01482"
"31563","189.34200","15.77876","0.01560"
"31630","189.74400","15.81224","0.01507"
"31697","190.14600","15.84566","0.01497"
"31764","190.54800","15.87926","0.01527"
"31831","190.95000","15.91275","0.01593"
"31898","191.35200","15.94617","0.01497"
"31965","191.75400","15.97971","0.01573"
"32032","192.15600","16.01325","0.01643"
"32099","192.55800","16.04679","0.01615"
"32166","192.96000","16.08022","0.01664"
"32233","193.36200","16.11370","0.01650"
"32300","193.76400","16.14724","0.01655"
"32367","194.16600","16.18078","0.01699"
"32434","194.56800","16.21420","0.01669"
"32501","194.97000","16.24769","0.01718"
"32568","195.37200","16.28123","0.01688"
"32635","195.77400","16.31471","0.01713"
"32702","196.17600","16.34819","0.01817"
"32769","196.57800","16.38173","0.01812"
"32836","196.98000","16.41528","0.01765"
"32903","197.38200","16.44870","0.01841"
"32970","197.78400","16.48212","0.01864"
"33037","198.18600","16.51572","0.01844"
"33104","198.58800","16.54926","0.01868"
"33171","198.99000","16.58275","0.01930"
"33238","199.39200","16.61617","0.01922"
"33305","199.79400","16.64971","0.01919"
"33372","200.19600","16.68319","0.01955"
"33439","200.59800","16.71674","0.01999"
"33506","201.00000","16.75022","0.01992"
"33573","201.40200","16.78370","0.02035"
"33640","201.80400","16.81724","0.02058"
"33707","202.20600","16.85072","0.02055"
"33774","202.60800","16.88415","0.02122"
"33841","203.01000","16.91775","0.02088"
"33908","203.41200","16.95123","0.02115"
"33975","203.81400","16.98471","0.02151"
"34042","204.21600","17.01813","0.02162"
"34109","204.61800","17.05174","0.02172"
"34176","205.02000","17.08528","0.02229"
"34243","205.42200","17.11870","0.02231"
"34310","205.82400","17.15218","0.02227"
"34377","206.22600","17.18572","0.02292"
"34444","206.62800","17.21921","0.02332"
"34511","207.03000","17.25275","0.02340"
"34578","207.43200","17.28617","0.02334"
"34645","207.83400","17.31971","0.02353"
"34712","208.23600","17.35319","0.02382"
"34779","208.63800","17.38668","0.02450"
"34846","209.04000","17.42022","0.02422"
"34913","209.44200","17.45376","0.02437"
"34980","209.84400","17.48718","0.02500"
"35047","210.24600","17.52072","0.02579"
"35114","210.64800","17.55421","0.02535"
"35181","211.05000","17.58781","0.02559"
"35248","211.45200","17.62123","0.02597"
"35315","211.85400","17.65477","0.02642"
"35382","212.25600","17.68819","0.02706"
"35449","212.65800","17.72180","0.02757"
"35516","213.06000","17.75522","0.02778"
"35583","213.46200","17.78870","0.02747"
"35650","213.86400","17.82224","0.02807"
"35717","214.26600","17.85573","0.02799"
"35784","214.66800","17.88921","0.02885"
"35851","215.07000","17.92275","0.02897"
"35918","215.47200","17.95617","0.02973"
"35985","215.87400","17.98971","0.03052"
"36052","216.27600","18.02320","0.03078"
"36119","216.67800","18.05668","0.03096"
"36186","217.08000","18.09022","0.03085"
"36253","217.48200","18.12376","0.03122"
"36320","217.88400","18.15730","0.03117"
"36387","218.28600","18.19067","0.03096"
"36454","218.68800","18.22421","0.03083"
"36521","219.09000","18.25769","0.03065"
"36588","219.49200","18.29123","0.03077"
"36655","219.89400","18.32471","0.03123"
"36722","220.29600","18.35820","0.03161"
"36789","220.69800","18.39174","0.03058"
"36856","221.10000","18.42528","0.00726"
"36923","221.50200","18.45870","0.00983"
"36990","221.90400","18.49224","0.00749"
"37057","222.30600","18.52573","0.00787"
"37124","222.70800","18.55927","0.00843"
"37191","223.11000","18.59269","0.00800"
"37258","223.51200","18.62617","0.00869"
"37325","223.91400","18.65978","0.00800"
"37392","224.31600","18.69326","0.00869"
"37459","224.71800","18.72668","0.00863"
"37526","225.12000","18.76022","0.00899"
"37593","225.52200","18.79376","0.00939"
"37660","225.92400","18.82725","0.00945"
"37727","226.32600","18.86067","0.01007"
"37794","226.72800","18.89421","0.00994"
"37861","227.13000","18.92769","0.01046"
"37928","227.53200","18.96123","0.01140"
"37995","227.93400","18.99466","0.01174"
"38062","228.33600","19.02820","0.01180"
"38129","228.73800","19.06180","0.00888"
"38196","229.14000","19.09534","0.00877"
"38263","229.54200","19.12870","0.00937"
"38330","229.94400","19.16219","0.00912"
"38397","230.34600","19.19573","0.00958"
"38464","230.74800","19.22927","0.00940"
"38531","231.15000","19.26269","0.00868"
"38598","231.55200","19.29623","0.00929"
"38665","231.95400","19.32972","0.00881"
"38732","232.35600","19.36326","0.00903"
"38799","232.75800","19.39668","0.00912"
"38866","233.16000","19.43022","0.00980"
"38933","233.56200","19.46376","0.00927"
"39000","233.96400","19.49725","0.00965"
"39067","234.36600","19.53061","0.00932"
"39134","234.76800","19.56421","0.00949"
"39201","235.17000","19.59775","0.00934"
"39268","235.57200","19.63124","0.00993"
"39335","235.97400","19.66466","0.00913"
"39402","236.37600","19.69814","0.00950"
"39469","236.77800","19.73174","0.00968"
"39536","237.18000","19.76528","0.01051"
"39603","237.58200","19.79864","0.00936"
"39670","237.98400","19.83219","0.00985"
"39737","238.38600","19.86573","0.00952"
"39804","238.78800","19.89921","0.00969"
"39871","239.19000","19.93270","0.01065"
"39938","239.59200","19.96624","0.00947"
"40005","239.99400","19.99972","0.01019"
"40072","240.39600","20.03320","0.00990"
"40139","240.79800","20.06662","0.01008"
"40206","241.20000","20.10023","0.01124"
"40273","241.60200","20.13377","0.01045"
"40340","242.00400","20.16725","0.01098"
"40407","242.40600","20.20067","0.01049"
"40474","242.80800","20.23421","0.01079"
"40541","243.21000","20.26776","0.01053"
"40608","243.61200","20.30124","0.01065"
"40675","244.01400","20.33466","0.01091"
"40742","244.41600","20.36820","0.01070"
"40809","244.81800","20.40168","0.01076"
"40876","245.22000","20.43522","0.01075"
"40943","245.62200","20.46865","0.01128"
"41010","246.02400","20.50225","0.01055"
"41077","246.42600","20.53573","0.01139"
"41144","246.82800","20.56921","0.01168"
"41211","247.23000","20.60270","0.01138"
"41278","247.63200","20.63624","0.01150"
"41345","248.03400","20.66972","0.01154"
"41412","248.43600","20.70320","0.01218"
"41479","248.83800","20.73663","0.01214"
"41546","249.24000","20.77028","0.01191"
"41613","249.64200","20.80377","0.01157"
"41680","250.04400","20.83719","0.01156"
"41747","250.44600","20.87067","0.01185"
"41814","250.84800","20.90421","0.01233"
"41881","251.25000","20.93770","0.01222"
"41948","251.65200","20.97124","0.01212"
"42015","252.05400","21.00472","0.01234"
"42082","252.45600","21.03826","0.01188"
"42149","252.85800","21.07174","0.01282"
"42216","253.26000","21.10523","0.01223"
"42283","253.66200","21.13871","0.01203"
"42350","254.06400","21.17225","0.01272"
"42417","254.46600","21.20573","0.01291"
"42484","254.86800","21.23921","0.01268"
"42551","255.27000","21.27270","0.01262"
"42618","255.67200","21.30624","0.01240"
"42685","256.07400","21.33978","0.01283"
"42752","256.47600","21.37314","0.01282"
"42819","256.87800","21.40668","0.01302"
"42886","257.28000","21.44029","0.01359"
"42953","257.68200","21.47377","0.01337"
"43020","258.08400","21.50719","0.01347"
"43087","258.48600","21.54067","0.01332"
"43154","258.88800","21.57428","0.01316"
"43221","259.29000","21.60776","0.01297"
"43288","259.69200","21.64118","0.01354"
"43355","260.09400","21.67472","0.01347"
"43422","260.49600","21.70821","0.01338"
"43489","260.89800","21.74175","0.01315"
"43556","261.30000","21.77523","0.01328"
"43623","261.70200","21.80871","0.01368"
"43690","262.10400","21.84225","0.01336"
"43757","262.50600","21.87574","0.01344"
"43824","262.90800","21.90922","0.01368"
"43891","263.31000","21.94270","0.01310"
"43958","263.71200","21.97624","0.01389"
"44025","264.11400","22.00972","0.01397"
"44092","264.51600","22.04315","0.01387"
"44159","264.91800","22.07669","0.01328"
"44226","265.32000","22.11029","0.01391"
"44293","265.72200","22.14377","0.01344"
"44360","266.12400","22.17713","0.01412"
"44427","266.52600","22.21068","0.01343"
"44494","266.92800","22.24428","0.01328"
"44561","267.33000","22.27776","0.01406"
"44628","267.73200","22.31118","0.01398"
"44695","268.13400","22.34472","0.01479"
"44762","268.53600","22.37821","0.01381"
"44829","268.93800","22.41175","0.01413"
"44896","269.34000","22.44523","0.01401"
"44963","269.74200","22.47871","0.01436"
"45030","270.14400","22.51225","0.01355"
"45097","270.54600","22.54574","0.01429"
"45164","270.94800","22.57922","0.01414"
"45231","271.35000","22.61270","0.01439"
"45298","271.75200","22.64630","0.01409"
"45365","272.15400","22.67978","0.01415"
"45432","272.55600","22.71315","0.01448"
"45499","272.95800","22.74675","0.01441"
"45566","273.36000","22.78029","0.01394"
"45633","273.76200","22.81377","0.01379"
"45700","274.16400","22.84725","0.01442"
"45767","274.56600","22.88074","0.01402"
"45834","274.96800","22.91428","0.01425"
"45901","275.37000","22.94776","0.01447"
"45968","275.77200","22.98118","0.01376"
"46035","276.17400","23.01472","0.01388"
"46102","276.57600","23.04820","0.01381"
"46169","276.97800","23.08169","0.01436"
"46236","277.38000","23.11517","0.01471"
"46303","277.78200","23.14877","0.01443"
"46370","278.18400","23.18226","0.01487"
"46437","278.58600","23.21574","0.01526"
"46504","278.98800","23.24916","0.01427"
"46571","279.39000","23.28270","0.01479"
"46638","279.79200","23.31624","0.01461"
"46705","280.19400","23.34973","0.01424"
"46772","280.59600","23.38321","0.01417"
"46839","280.99800","23.41669","0.01373"
"46906","281.40000","23.45023","0.01461"
"46973","281.80200","23.48372","0.01465"
"47040","282.20400","23.51720","0.01453"
"47107","282.60600","23.55068","0.01442"
"47174","283.00800","23.58422","0.01525"
"47241","283.41000","23.61770","0.01411"
"47308","283.81200","23.65112","0.01486"
"47375","284.21400","23.68472","0.01512"
"47442","284.61600","23.71821","0.01477"
"47509","285.01800","23.75169","0.01470"
"47576","285.42000","23.78511","0.01461"
"47643","285.82200","23.81878","0.01494"
"47710","286.22400","23.85225","0.01513"
"47777","286.62600","23.88568","0.01524"
"47844","287.02800","23.91916","0.01430"
"47911","287.43000","23.95270","0.01537"
"47978","287.83200","23.98625","0.01552"
"48045","288.23400","24.01973","0.01463"
"48112","288.63600","24.05315","0.01505"
"48179","289.03800","24.08669","0.01541"
"48246","289.44000","24.12023","0.01553"
"48313","289.84200","24.15372","0.01554"
"48380","290.24400","24.18720","0.01449"
"48447","290.64600","24.22074","0.01462"
"48514","291.04800","24.25428","0.01517"
"48581","291.45000","24.28770","0.01471"
"48648","291.85200","24.32119","0.01529"
"48715","292.25400","24.35479","0.01492"
"48782","292.65600","24.38821","0.01481"
"48849","293.05800","24.42169","0.01524"
"48916","293.46000","24.45517","0.01561"
"48983","293.86200","24.48872","0.01516"
"49050","294.26400","24.52226","0.01517"
"49117","294.66600","24.55568","0.01496"
"49184","295.06800","24.58922","0.01545"
"49251","295.47000","24.62276","0.01526"
"49318","295.87200","24.65625","0.01548"
"49385","296.27400","24.68973","0.01513"
"49452","296.67600","24.72315","0.01440"
"49519","297.07800","24.75675","0.01497"
"49586","297.48000","24.79024","0.01461"
"49653","297.88200","24.82372","0.01515"
"49720","298.28400","24.85720","0.01508"
"49787","298.68600","24.89074","0.01507"
"49854","299.08800","24.92428","0.01542"
"49921","299.49000","24.95770","0.01534"
"49988","299.89200","24.99125","0.01515"
"50055","300.29400","25.02479","0.01570"
"50122","300.69600","25.05821","0.01604"
"50189","301.09800","25.09163","0.01590"
"50256","301.50000","25.12518","0.01555"
"50323","301.90200","25.15872","0.01519"
"50390","302.30400","25.19226","0.01556"
"50457","302.70600","25.22562","0.01617"
"50524","303.10800","25.25922","0.01565"
"50591","303.51000","25.29276","0.01582"
"50658","303.91200","25.32625","0.01596"
"50725","304.31400","25.35973","0.01593"
"50792","304.71600","25.39315","0.01612"
"50859","305.11800","25.42675","0.01587"
"50926","305.52000","25.46024","0.01587"
"50993","305.92200","25.49372","0.01605"
"51060","306.32400","25.52726","0.01604"
"51127","306.72600","25.56068","0.01557"
"51194","307.12800","25.59422","0.01578"
"51261","307.53000","25.62765","0.01577"
"51328","307.93200","25.66125","0.01636"
"51395","308.33400","25.69473","0.01626"
"51462","308.73600","25.72821","0.01605"
"51529","309.13800","25.76163","0.01620"
"51596","309.54000","25.79524","0.01608"
"51663","309.94200","25.82872","0.01653"
"51730","310.34400","25.86226","0.01605"
"51797","310.74600","25.89569","0.01603"
"51864","311.14800","25.92929","0.01689"
"51931","311.55000","25.96277","0.01602"
"51998","311.95200","25.99625","0.01622"
"52065","312.35400","26.02973","0.01570"
"52132","312.75600","26.06321","0.01619"
"52199","313.15800","26.09670","0.01647"
"52266","313.56000","26.13018","0.01691"
"52333","313.96200","26.16372","0.01713"
"52400","314.36400","26.19726","0.01736"
"52467","314.76600","26.23075","0.01720"
"52534","315.16800","26.26423","0.01695"
"52601","315.57000","26.29765","0.01707"
"52668","315.97200","26.33131","0.01702"
"52735","316.37400","26.36479","0.01751"
"52802","316.77600","26.39822","0.01722"
"52869","317.17800","26.43170","0.01734"
"52936","317.58000","26.46518","0.01754"
"53003","317.98200","26.49872","0.01664"
"53070","318.38400","26.53226","0.01664"
"53137","318.78600","26.56569","0.01666"
"53204","319.18800","26.59929","0.01665"
"53271","319.59000","26.63271","0.01644"
"53338","319.99200","26.66619","0.01614"
"53405","320.39400","26.69973","0.01700"
"53472","320.79600","26.73322","0.01735"
"53539","321.19800","26.76670","0.01679"
"53606","321.60000","26.80018","0.01709"
"53673","322.00200","26.83366","0.01690"
"53740","322.40400","26.86726","0.01737"
"53807","322.80600","26.90075","0.01746"
"53874","323.20800","26.93417","0.01725"
"53941","323.61000","26.96771","0.01707"
"54008","324.01200","27.00126","0.01746"
"54075","324.41400","27.03480","0.01788"
"54142","324.81600","27.06822","0.01796"
"54209","325.21800","27.10170","0.01761"
"54276","325.62000","27.13524","0.01769"
"54343","326.02200","27.16879","0.01761"
"54410","326.42400","27.20220","0.01688"
"54477","326.82600","27.23569","0.01595"
"54544","327.22800","27.26923","0.01667"
"54611","327.63000","27.30271","0.01682"
"54678","328.03200","27.33619","0.01591"
"54745","328.43400","27.36974","0.01572"
"54812","328.83600","27.40322","0.01632"
"54879","329.23800","27.43676","0.01597"
"54946","329.64000","27.47018","0.01609"
"55013","330.04200","27.50367","0.01620"
"55080","330.44400","27.53721","0.01613"
"55147","330.84600","27.57075","0.01604"
"55214","331.24800","27.60423","0.01632"
"55281","331.65000","27.63771","0.01645"
"55348","332.05200","27.67125","0.01646"
"55415","332.45400","27.70480","0.01587"
"55482","332.85600","27.73816","0.01665"
"55549","333.25800","27.77170","0.01647"
"55616","333.66000","27.80524","0.01656"
"55683","334.06200","27.83879","0.01678"
"55750","334.46400","27.87221","0.01644"
"55817","334.86600","27.90569","0.01661"
"55884","335.26800","27.93929","0.01657"
"55951","335.67000","27.97277","0.01661"
"56018","336.07200","28.00614","0.01698"
"56085","336.47400","28.03974","0.01663"
"56152","336.87600","28.07322","0.01741"
"56219","337.27800","28.10670","0.01688"
"56286","337.68000","28.14018","0.01763"
"56353","338.08200","28.17373","0.01714"
"56420","338.48400","28.20727","0.01712"
"56487","338.88600","28.24075","0.01707"
"56554","339.28800","28.27417","0.01704"
"56621","339.69000","28.30765","0.01748"
"56688","340.09200","28.34120","0.01763"
"56755","340.49400","28.37474","0.01718"
"56822","340.89600","28.40816","0.01779"
"56889","341.29800","28.44170","0.01787"
"56956","341.70000","28.47524","0.01755"
"57023","342.10200","28.50879","0.01759"
"57090","342.50400","28.54221","0.01747"
"57157","342.90600","28.57575","0.01815"
"57224","343.30800","28.60923","0.01802"
"57291","343.71000","28.64271","0.01817"
"57358","344.11200","28.67614","0.01817"
"57425","344.51400","28.70974","0.01820"
"57492","344.91600","28.74322","0.01846"
"57559","345.31800","28.77670","0.01844"
"57626","345.72000","28.81018","0.01799"
"57693","346.12200","28.84373","0.01771"
"57760","346.52400","28.87727","0.01834"
"57827","346.92600","28.91069","0.01848"
"57894","347.32800","28.94417","0.01872"
"57961","347.73000","28.97766","0.01861"
"58028","348.13200","29.01126","0.01875"
"58095","348.53400","29.04468","0.01892"
"58162","348.93600","29.07816","0.01917"
"58229","349.33800","29.11176","0.01926"
"58296","349.74000","29.14519","0.01912"
"58363","350.14200","29.17873","0.01945"
"58430","350.54400","29.21215","0.01930"
"58497","350.94600","29.24575","0.01953"
"58564","351.34800","29.27924","0.01936"
"58631","351.75000","29.31272","0.02006"
"58698","352.15200","29.34620","0.01988"
"58765","352.55400","29.37974","0.01998"
"58832","352.95600","29.41322","0.01988"
"58899","353.35800","29.44665","0.02007"
"58966","353.76000","29.48019","0.02058"
"59033","354.16200","29.51379","0.02007"
"59100","354.56400","29.54727","0.02031"
"59167","354.96600","29.58075","0.02050"
"59234","355.36800","29.61423","0.02080"
"59301","355.77000","29.64771","0.02091"
"59368","356.17200","29.68126","0.02084"
"59435","356.57400","29.71474","0.02084"
"59502","356.97600","29.74822","0.02129"
"59569","357.37800","29.78170","0.02087"
"59636","357.78000","29.81519","0.02085"
"59703","358.18200","29.84867","0.02107"
"59770","358.58400","29.88215","0.02103"
"59837","358.98600","29.91575","0.02128"
"59904","359.38800","29.94930","0.02133"
"59971","359.79000","29.98266","0.02123"
"60038","360.19200","30.01620","0.02162"
"60105","360.59400","30.04974","0.02160"
"60172","360.99600","30.08328","0.02218"
"60239","361.39800","30.11665","0.02192"
"60306","361.80000","30.15019","0.02199"
"60373","362.20200","30.18379","0.02244"
"60440","362.60400","30.21721","0.02228"
"60507","363.00600","30.25075","0.02265"
"60574","363.40800","30.28424","0.02249"
"60641","363.81000","30.31772","0.02282"
"60708","364.21200","30.35126","0.02314"
"60775","364.61400","30.38474","0.02283"
"60842","365.01600","30.41822","0.02312"
"60909","365.41800","30.45177","0.02337"
"60976","365.82000","30.48519","0.02336"
"61043","366.22200","30.51867","0.02335"
"61110","366.62400","30.55221","0.02403"
"61177","367.02600","30.58575","0.02426"
"61244","367.42800","30.61924","0.02393"
"61311","367.83000","30.65266","0.02428"
"61378","368.23200","30.68620","0.02427"
"61445","368.63400","30.71974","0.02407"
"61512","369.03600","30.75329","0.02504"
"61579","369.43800","30.78671","0.02489"
"61646","369.84000","30.82019","0.02495"
"61713","370.24200","30.85379","0.02517"
"61780","370.64400","30.88721","0.02608"
"61847","371.04600","30.92076","0.02537"
"61914","371.44800","30.95424","0.02534"
"61981","371.85000","30.98772","0.02618"
"62048","372.25200","31.02126","0.02595"
"62115","372.65400","31.05474","0.02643"
"62182","373.05600","31.08823","0.02672"
"62249","373.45800","31.12171","0.02667"
"62316","373.86000","31.15519","0.02727"
"62383","374.26200","31.18867","0.02729"
"62450","374.66400","31.22222","0.02741"
"62517","375.06600","31.25576","0.02749"
"62584","375.46800","31.28924","0.02724"
"62651","375.87000","31.32266","0.02821"
"62718","376.27200","31.35626","0.02751"
"62785","376.67400","31.38974","0.02745"
"62852","377.07600","31.42329","0.02787"
"62919","377.47800","31.45671","0.02753"
"62986","377.88000","31.49019","0.02793"
"63053","378.28200","31.52373","0.02836"
"63120","378.68400","31.55721","0.02820"
"63187","379.08600","31.59064","0.02858"
"63254","379.48800","31.62424","0.02863"
"63321","379.89000","31.65772","0.02906"
"63388","380.29200","31.69120","0.02945"
"63455","380.69400","31.72468","0.02986"
"63522","381.09600","31.75823","0.03011"
"63589","381.49800","31.79171","0.03021"
"63656","381.90000","31.82519","0.03081"
"63723","382.30200","31.85867","0.03059"
"63790","382.70400","31.89221","0.03090"
"63857","383.10600","31.92576","0.03088"
"63924","383.50800","31.95924","0.03165"
"63991","383.91000","31.99266","0.03197"
"64058","384.31200","32.02620","0.03168"
"64125","384.71400","32.05975","0.03239"
"64192","385.11600","32.09323","0.03238"
"64259","385.51800","32.12671","0.03314"
"64326","385.92000","32.16019","0.03322"
"64393","386.32200","32.19373","0.03322"
"64460","386.72400","32.22715","0.03373"
"64527","387.12600","32.26070","0.03376"
"64594","387.52800","32.29424","0.03496"
"64661","387.93000","32.32772","0.03436"
"64728","388.33200","32.36120","0.03515"
"64795","388.73400","32.39468","0.03591"
"64862","389.13600","32.42823","0.03615"
"64929","389.53800","32.46177","0.03655"
"64996","389.94000","32.49519","0.03683"
"65063","390.34200","32.52874","0.03697"
"65130","390.74400","32.56221","0.03730"
"65197","391.14600","32.59576","0.03801"
"65264","391.54800","32.62924","0.03812"
"65331","391.95000","32.66261","0.03863"
"65398","392.35200","32.69627","0.03906"
"65465","392.75400","32.72974","0.03903"
"65532","393.15600","32.76323","0.03956"
"65599","393.55800","32.79671","0.04070"
"65666","393.96000","32.83019","0.04069"
"65733","394.36200","32.86374","0.04114"
"65800","394.76400","32.89722","0.04119"
"65867","395.16600","32.93070","0.04190"
"65934","395.56800","32.96430","0.04189"
"66001","395.97000","32.99772","0.04245"
"66068","396.37200","33.03121","0.04293"
"66135","396.77400","33.06475","0.04356"
"66202","397.17600","33.09829","0.04409"
"66269","397.57800","33.13177","0.04482"
"66336","397.98000","33.16520","0.04503"
"66403","398.38200","33.19874","0.04551"
"66470","398.78400","33.23228","0.04596"
"66537","399.18600","33.26576","0.04653"
"66604","399.58800","33.29918","0.04746"
"66671","399.99000","33.33266","0.04806"
"66738","400.39200","33.36627","0.04851"
"66805","400.79400","33.39975","0.04952"
"66872","401.19600","33.43317","0.04944"
"66939","401.59800","33.46671","0.05032"
"67006","402.00000","33.50026","0.05177"
"67073","402.40200","33.53374","0.05224"
"67140","402.80400","33.56716","0.05215"
"67207","403.20600","33.60076","0.05371"
"67274","403.60800","33.63424","0.05377"
"67341","404.01000","33.66772","0.05496"
"67408","404.41200","33.70115","0.05584"
"67475","404.81400","33.73469","0.05634"
"67542","405.21600","33.76829","0.05666"
"67609","405.61800","33.80177","0.05717"
"67676","406.02000","33.83514","0.05852"
"67743","406.42200","33.86868","0.05976"
"67810","406.82400","33.90222","0.05967"
"67877","407.22600","33.93576","0.06058"
"67944","407.62800","33.96918","0.06152"
"68011","408.03000","34.00272","0.06230"
"68078","408.43200","34.03621","0.06265"
"68145","408.83400","34.06975","0.06340"
"68212","409.23600","34.10317","0.06424"
"68279","409.63800","34.13671","0.06498"
"68346","410.04000","34.17020","0.06535"
"68413","410.44200","34.20368","0.06625"
"68480","410.84400","34.23716","0.06712"
"68547","411.24600","34.27070","0.06761"
"68614","411.64800","34.30424","0.06766"
"68681","412.05000","34.33767","0.06849"
"68748","412.45200","34.37115","0.06883"
"68815","412.85400","34.40475","0.06942"
"68882","413.25600","34.43823","0.06980"
"68949","413.65800","34.47171","0.07053"
"69016","414.06000","34.50520","0.07068"
"69083","414.46200","34.53868","0.07109"
"69150","414.86400","34.57216","0.07162"
"69217","415.26600","34.60571","0.07203"
"69284","415.66800","34.63918","0.07236"
"69351","416.07000","34.67273","0.07280"
"69418","416.47200","34.70621","0.07283"
"69485","416.87400","34.73975","0.07363"
"69552","417.27600","34.77317","0.07418"
"69619","417.67800","34.80678","0.07448"
"69686","418.08000","34.84026","0.07483"
"69753","418.48200","34.87368","0.07519"
"69820","418.88400","34.90716","0.07568"
"69887","419.28600","34.94077","0.07583"
"69954","419.68800","34.97425","0.07626"
"70021","420.09000","35.00772","0.07633"
"70088","420.49200","35.04121","0.07686"
"70155","420.89400","35.07475","0.07755"
"70222","421.29600","35.10823","0.07775"
"70289","421.69800","35.14172","0.07822"
"70356","422.10000","35.17520","0.07870"
"70423","422.50200","35.20874","0.07937"
"70490","422.90400","35.24222","0.07963"
"70557","423.30600","35.27570","0.08037"
"70624","423.70800","35.30925","0.08088"
"70691","424.11000","35.34273","0.08171"
"70758","424.51200","35.37621","0.08230"
"70825","424.91400","35.40975","0.08259"
"70892","425.31600","35.44318","0.08371"
"70959","425.71800","35.47678","0.08401"
"71026","426.12000","35.51026","0.08467"
"71093","426.52200","35.54368","0.08624"
"71160","426.92400","35.57716","0.08703"
"71227","427.32600","35.61071","0.08799"
"71294","427.72800","35.64431","0.08865"
"71361","428.13000","35.67767","0.08965"
"71428","428.53200","35.71121","0.09090"
"71495","428.93400","35.74475","0.09169"
"71562","429.33600","35.77829","0.09279"
"71629","429.73800","35.81172","0.09339"
"71696","430.14000","35.84514","0.09511"
"71763","430.54200","35.87874","0.09621"
"71830","430.94400","35.91222","0.09695"
"71897","431.34600","35.94571","0.09875"
"71964","431.74800","35.97919","0.10054"
"72031","432.15000","36.01273","0.10142"
"72098","432.55200","36.04622","0.10322"
"72165","432.95400","36.07969","0.10533"
"72232","433.35600","36.11324","0.10745"
"72299","433.75800","36.14678","0.10811"
"72366","434.16000","36.18026","0.10999"
"72433","434.56200","36.21368","0.11257"
"72500","434.96400","36.24717","0.11397"
"72567","435.36600","36.28071","0.11577"
"72634","435.76800","36.31425","0.11708"
"72701","436.17000","36.34767","0.11901"
"72768","436.57200","36.38121","0.12042"
"72835","436.97400","36.41470","0.12189"
"72902","437.37600","36.44824","0.12264"
"72969","437.77800","36.48172","0.12405"
"73036","438.18000","36.51520","0.12551"
"73103","438.58200","36.54874","0.12746"
"73170","438.98400","36.58229","0.12829"
"73237","439.38600","36.61571","0.12914"
"73304","439.78800","36.64925","0.13115"
"73371","440.19000","36.68273","0.13239"
"73438","440.59200","36.71622","0.13387"
"73505","440.99400","36.74963","0.13503"
"73572","441.39600","36.78324","0.13597"
"73639","441.79800","36.81678","0.13784"
"73706","442.20000","36.85026","0.13859"
"73773","442.60200","36.88363","0.13983"
"73840","443.00400","36.91711","0.14103"
"73907","443.40600","36.95077","0.14223"
"73974","443.80800","36.98425","0.14312"
"74041","444.21000","37.01767","0.14492"
"74108","444.61200","37.05116","0.14599"
"74175","445.01400","37.08470","0.14635"
"74242","445.41600","37.11824","0.14724"
"74309","445.81800","37.15166","0.14857"
"74376","446.22000","37.18526","0.14976"
"74443","446.62200","37.21875","0.15059"
"74510","447.02400","37.25217","0.15212"
"74577","447.42600","37.28565","0.15312"
"74644","447.82800","37.31925","0.15447"
"74711","448.23000","37.35273","0.15584"
"74778","448.63200","37.38622","0.15708"
"74845","449.03400","37.41970","0.15932"
"74912","449.43600","37.45324","0.16010"
"74979","449.83800","37.48672","0.16135"
"75046","450.24000","37.52020","0.16252"
"75113","450.64200","37.55369","0.16325"
"75180","451.04400","37.58717","0.16513"
"75247","451.44600","37.62071","0.16666"
"75314","451.84800","37.65425","0.16817"
"75381","452.25000","37.68773","0.16848"
"75448","452.65200","37.72122","0.17038"
"75515","453.05400","37.75476","0.17132"
"75582","453.45600","37.78818","0.17227"
"75649","453.85800","37.82172","0.17346"
"75716","454.26000","37.85526","0.17467"
"75783","454.66200","37.88875","0.17560"
"75850","455.06400","37.92217","0.17661"
"75917","455.46600","37.95565","0.17801"
"75984","455.86800","37.98925","0.17903"
"76051","456.27000","38.02279","0.17966"
"76118","456.67200","38.05622","0.18062"
"76185","457.07400","38.08970","0.18021"
"76252","457.47600","38.12324","0.18130"
"76319","457.87800","38.15673","0.18265"
"76386","458.28000","38.19020","0.18392"
"76453","458.68200","38.22375","0.18490"
"76520","459.08400","38.25723","0.18481"
"76587","459.48600","38.29071","0.18539"
"76654","459.88800","38.32426","0.18566"
"76721","460.29000","38.35773","0.18650"
"76788","460.69200","38.39128","0.18729"
"76855","461.09400","38.42476","0.18809"
"76922","461.49600","38.45824","0.18866"
"76989","461.89800","38.49173","0.18941"
"77056","462.30000","38.52526","0.19032"
"77123","462.70200","38.55875","0.19092"
"77190","463.10400","38.59211","0.19219"
"77257","463.50600","38.62571","0.19356"
"77324","463.90800","38.65926","0.19445"
"77391","464.31000","38.69273","0.19561"
"77458","464.71200","38.72616","0.19632"
"77525","465.11400","38.75970","0.19742"
"77592","465.51600","38.79324","0.19865"
"77659","465.91800","38.82679","0.20023"
"77726","466.32000","38.86021","0.20166"
"77793","466.72200","38.89369","0.20207"
"77860","467.12400","38.92723","0.20257"
"77927","467.52600","38.96071","0.20278"
"77994","467.92800","38.99420","0.20296"
"78061","468.33000","39.02768","0.01843"
"78128","468.73200","39.06122","0.00570"
"78195","469.13400","39.09476","0.00861"
"78262","469.53600","39.12818","0.00966"
"78329","469.93800","39.16173","0.00774"
"78396","470.34000","39.19527","0.00650"
"78463","470.74200","39.22874","0.00620"
"78530","471.14400","39.26211","0.00759"
"78597","471.54600","39.29571","0.00766"
"78664","471.94800","39.32920","0.00685"
"78731","472.35000","39.36274","0.00758"
"78798","472.75200","39.39616","0.00724"
"78865","473.15400","39.42970","0.00709"
"78932","473.55600","39.46325","0.00713"
"78999","473.95800","39.49672","0.00670"
"79066","474.36000","39.53015","0.00711"
"79133","474.76200","39.56369","0.00716"
"79200","475.16400","39.59717","0.00705"
"79267","475.56600","39.63071","0.00719"
"79334","475.96800","39.66419","0.00671"
"79401","476.37000","39.69774","0.00715"
"79468","476.77200","39.73122","0.00712"
"79535","477.17400","39.76470","0.00641"
"79602","477.57600","39.79818","0.00749"
"79669","477.97800","39.83173","0.00769"
"79736","478.38000","39.86521","0.00705"
"79803","478.78200","39.89875","0.00713"
"79870","479.18400","39.93211","0.00767"
"79937","479.58600","39.96571","0.00708"
"80004","479.98800","39.99926","0.00639"
"80071","480.39000","40.03274","0.00706"
"80138","480.79200","40.06616","0.00765"
"80205","481.19400","40.09964","0.00641"
"80272","481.59600","40.13324","0.00751"
"80339","481.99800","40.16679","0.00716"
"80406","482.40000","40.20021","0.00733"
"80473","482.80200","40.23375","0.00703"
"80540","483.20400","40.26717","0.00686"
"80607","483.60600","40.30072","0.00639"
"80674","484.00800","40.33420","0.00754"
"80741","484.41000","40.36780","0.00709"
"80808","484.81200","40.40122","0.00708"
"80875","485.21400","40.43476","0.00756"
"80942","485.61600","40.46819","0.00739"
"81009","486.01800","40.50167","0.00725"
"81076","486.42000","40.53527","0.00705"
"81143","486.82200","40.56875","0.00741"
"81210","487.22400","40.60211","0.00737"
"81277","487.62600","40.63571","0.00724"
"81344","488.02800","40.66920","0.00724"
"81411","488.43000","40.70274","0.00749"
"81478","488.83200","40.73616","0.00706"
"81545","489.23400","40.76971","0.00732"
"81612","489.63600","40.80325","0.00769"
"81679","490.03800","40.83673","0.00768"
"81746","490.44000","40.87021","0.00757"
"81807","490.80200","40.90041","0.00805"