File: Trajectories_together/170122_2Specimen_RawData_3.csv
"","V1","V2","V3"
"1","End date","1/22/2017",""
"2","Specimen label","3CT_21",""
"3","Maximum Load","0.29249","N"
"4","Time","Extension","Load"
"5","(s)","(mm)","(N)"
"6","0.00000","0.00000","0.00063"
"51","0.27000","0.02123","0.00051"
"96","0.54000","0.04520","0.00022"
"141","0.81000","0.06774","0.00070"
"186","1.08000","0.09010","0.00045"
"231","1.35000","0.11264","0.00089"
"276","1.62000","0.13512","0.00097"
"321","1.89000","0.15766","0.00136"
"366","2.16000","0.18015","0.00136"
"411","2.43000","0.20269","0.00090"
"456","2.70000","0.22511","0.00091"
"501","2.97000","0.24765","0.00110"
"546","3.24000","0.27007","0.00113"
"591","3.51000","0.29261","0.00164"
"636","3.78000","0.31509","0.00091"
"681","4.05000","0.33763","0.00108"
"726","4.32000","0.36011","0.00127"
"771","4.59000","0.38265","0.00131"
"816","4.86000","0.40513","0.00088"
"861","5.13000","0.42761","0.00080"
"906","5.40000","0.45010","0.00108"
"951","5.67000","0.47264","0.00159"
"996","5.94000","0.49506","0.00084"
"1041","6.21000","0.51766","0.00120"
"1086","6.48000","0.54002","0.00071"
"1131","6.75000","0.56262","0.00107"
"1176","7.02000","0.58510","0.00118"
"1221","7.29000","0.60770","0.00140"
"1266","7.56000","0.63012","0.00100"
"1311","7.83000","0.65266","0.00123"
"1356","8.10000","0.67508","0.00120"
"1401","8.37000","0.69762","0.00094"
"1446","8.64000","0.72005","0.00140"
"1491","8.91000","0.74265","0.00139"
"1536","9.18000","0.76507","0.00095"
"1581","9.45000","0.78767","0.00107"
"1626","9.72000","0.81009","0.00114"
"1671","9.99000","0.83263","0.00131"
"1716","10.26000","0.85511","0.00112"
"1761","10.53000","0.87765","0.00169"
"1806","10.80000","0.90007","0.00111"
"1851","11.07000","0.92261","0.00111"
"1896","11.34000","0.94509","0.00083"
"1941","11.61000","0.96763","0.00110"
"1986","11.88000","0.99011","0.00174"
"2031","12.15000","1.01260","0.00166"
"2076","12.42000","1.03514","0.00126"
"2121","12.69000","1.05768","0.00094"
"2166","12.96000","1.08016","0.00069"
"2211","13.23000","1.10270","0.00106"
"2256","13.50000","1.12512","0.00156"
"2301","13.77000","1.14766","0.00118"
"2346","14.04000","1.17014","0.00116"
"2391","14.31000","1.19268","0.00146"
"2436","14.58000","1.21510","0.00154"
"2481","14.85000","1.23764","0.00117"
"2526","15.12000","1.26006","0.00118"
"2571","15.39000","1.28266","0.00149"
"2616","15.66000","1.30509","0.00159"
"2661","15.93000","1.32763","0.00076"
"2706","16.20000","1.35011","0.00139"
"2751","16.47000","1.37265","0.00191"
"2796","16.74000","1.39513","0.00174"
"2841","17.01000","1.41761","0.00180"
"2886","17.28000","1.44015","0.00179"
"2931","17.55000","1.46263","0.00120"
"2976","17.82000","1.48511","0.00140"
"3021","18.09000","1.50765","0.00108"
"3066","18.36000","1.53007","0.00107"
"3111","18.63000","1.55267","0.00151"
"3156","18.90000","1.57516","0.00129"
"3201","19.17000","1.59758","0.00134"
"3246","19.44000","1.62006","0.00096"
"3291","19.71000","1.64260","0.00107"
"3336","19.98000","1.66514","0.00113"
"3381","20.25000","1.68756","0.00151"
"3426","20.52000","1.71010","0.00127"
"3471","20.79000","1.73258","0.00195"
"3516","21.06000","1.75512","0.00109"
"3561","21.33000","1.77760","0.00157"
"3606","21.60000","1.80014","0.00122"
"3651","21.87000","1.82262","0.00147"
"3696","22.14000","1.84510","0.00150"
"3741","22.41000","1.86759","0.00183"
"3786","22.68000","1.89013","0.00111"
"3831","22.95000","1.91267","0.00112"
"3876","23.22000","1.93515","0.00122"
"3921","23.49000","1.95769","0.00129"
"3966","23.76000","1.98011","0.00157"
"4011","24.03000","2.00259","0.00106"
"4056","24.30000","2.02507","0.00144"
"4101","24.57000","2.04761","0.00089"
"4146","24.84000","2.07009","0.00114"
"4191","25.11000","2.09263","0.00128"
"4236","25.38000","2.11511","0.00164"
"4281","25.65000","2.13766","0.00103"
"4326","25.92000","2.16014","0.00116"
"4371","26.19000","2.18262","0.00161"
"4416","26.46000","2.20516","0.00098"
"4461","26.73000","2.22764","0.00098"
"4506","27.00000","2.25012","0.00175"
"4551","27.27000","2.27260","0.00143"
"4596","27.54000","2.29508","0.00094"
"4641","27.81000","2.31768","0.00237"
"4686","28.08000","2.34016","0.00110"
"4731","28.35000","2.36264","0.00115"
"4776","28.62000","2.38512","0.00122"
"4821","28.89000","2.40760","0.00132"
"4866","29.16000","2.43009","0.00126"
"4911","29.43000","2.45257","0.00161"
"4956","29.70000","2.47511","0.00120"
"5001","29.97000","2.49765","0.00105"
"5046","30.24000","2.52013","0.00132"
"5091","30.51000","2.54267","0.00117"
"5136","30.78000","2.56515","0.00169"
"5181","31.05000","2.58757","0.00123"
"5226","31.32000","2.61011","0.00110"
"5271","31.59000","2.63259","0.00091"
"5316","31.86000","2.65513","0.00110"
"5361","32.13000","2.67767","0.00122"
"5406","32.40000","2.70016","0.00110"
"5451","32.67000","2.72264","0.00149"
"5496","32.94000","2.74512","0.00152"
"5541","33.21000","2.76760","0.00161"
"5586","33.48000","2.79008","0.00152"
"5631","33.75000","2.81262","0.00163"
"5676","34.02000","2.83510","0.00113"
"5721","34.29000","2.85764","0.00202"
"5766","34.56000","2.88012","0.00203"
"5811","34.83000","2.90266","0.00099"
"5856","35.10000","2.92514","0.00144"
"5901","35.37000","2.94762","0.00153"
"5946","35.64000","2.97016","0.00103"
"5991","35.91000","2.99265","0.00149"
"6036","36.18000","3.01513","0.00107"
"6081","36.45000","3.03767","0.00196"
"6126","36.72000","3.06015","0.00149"
"6171","36.99000","3.08263","0.00169"
"6216","37.26000","3.10517","0.00150"
"6261","37.53000","3.12759","0.00158"
"6306","37.80000","3.15013","0.00126"
"6351","38.07000","3.17255","0.00120"
"6396","38.34000","3.19515","0.00136"
"6441","38.61000","3.21763","0.00194"
"6486","38.88000","3.24017","0.00161"
"6531","39.15000","3.26265","0.00274"
"6576","39.42000","3.28520","0.00135"
"6621","39.69000","3.30762","0.00109"
"6666","39.96000","3.33016","0.00121"
"6711","40.23000","3.35264","0.00181"
"6756","40.50000","3.37518","0.00183"
"6801","40.77000","3.39760","0.00170"
"6846","41.04000","3.42020","0.00175"
"6891","41.31000","3.44262","0.00064"
"6936","41.58000","3.46510","0.00154"
"6981","41.85000","3.48758","0.00158"
"7026","42.12000","3.51012","0.00189"
"7071","42.39000","3.53260","0.00108"
"7116","42.66000","3.55515","0.00132"
"7161","42.93000","3.57763","0.00177"
"7206","43.20000","3.60017","0.00175"
"7251","43.47000","3.62259","0.00223"
"7296","43.74000","3.64519","0.00111"
"7341","44.01000","3.66767","0.00154"
"7386","44.28000","3.69015","0.00114"
"7431","44.55000","3.71263","0.00189"
"7476","44.82000","3.73511","0.00167"
"7521","45.09000","3.75759","0.00183"
"7566","45.36000","3.78013","0.00165"
"7611","45.63000","3.80261","0.00187"
"7656","45.90000","3.82515","0.00178"
"7701","46.17000","3.84758","0.00166"
"7746","46.44000","3.87018","0.00133"
"7791","46.71000","3.89260","0.00169"
"7836","46.98000","3.91514","0.00170"
"7881","47.25000","3.93756","0.00195"
"7926","47.52000","3.96010","0.00162"
"7971","47.79000","3.98258","0.00160"
"8016","48.06000","4.00518","0.00114"
"8061","48.33000","4.02760","0.00207"
"8106","48.60000","4.05020","0.00170"
"8151","48.87000","4.07262","0.00202"
"8196","49.14000","4.09516","0.00199"
"8241","49.41000","4.11765","0.00233"
"8286","49.68000","4.14019","0.00093"
"8331","49.95000","4.16261","0.00142"
"8376","50.22000","4.18521","0.00234"
"8421","50.49000","4.20763","0.00208"
"8466","50.76000","4.23017","0.00164"
"8511","51.03000","4.25259","0.00174"
"8556","51.30000","4.27513","0.00245"
"8601","51.57000","4.29761","0.00179"
"8646","51.84000","4.32015","0.00145"
"8691","52.11000","4.34263","0.00274"
"8736","52.38000","4.36511","0.00153"
"8781","52.65000","4.38760","0.00193"
"8826","52.92000","4.41020","0.00176"
"8871","53.19000","4.43262","0.00210"
"8916","53.46000","4.45510","0.00165"
"8961","53.73000","4.47764","0.00167"
"9006","54.00000","4.50012","0.00243"
"9051","54.27000","4.52260","0.00163"
"9096","54.54000","4.54514","0.00132"
"9141","54.81000","4.56762","0.00125"
"9186","55.08000","4.59016","0.00170"
"9231","55.35000","4.61258","0.00213"
"9276","55.62000","4.63518","0.00159"
"9321","55.89000","4.65760","0.00193"
"9366","56.16000","4.68015","0.00157"
"9411","56.43000","4.70257","0.00199"
"9456","56.70000","4.72517","0.00198"
"9501","56.97000","4.74759","0.00132"
"9546","57.24000","4.77013","0.00208"
"9591","57.51000","4.79255","0.00172"
"9636","57.78000","4.81521","0.00260"
"9681","58.05000","4.83763","0.00139"
"9726","58.32000","4.86017","0.00198"
"9771","58.59000","4.88259","0.00157"
"9816","58.86000","4.90513","0.00138"
"9861","59.13000","4.92755","0.00233"
"9906","59.40000","4.95015","0.00195"
"9951","59.67000","4.97258","0.00191"
"9996","59.94000","4.99518","0.00246"
"10041","60.21000","5.01766","0.00189"
"10086","60.48000","5.04014","0.00208"
"10131","60.75000","5.06262","0.00201"
"10176","61.02000","5.08510","0.00228"
"10221","61.29000","5.10758","0.00219"
"10266","61.56000","5.13018","0.00182"
"10311","61.83000","5.15260","0.00220"
"10356","62.10000","5.17514","0.00210"
"10401","62.37000","5.19762","0.00130"
"10446","62.64000","5.22016","0.00163"
"10491","62.91000","5.24259","0.00180"
"10536","63.18000","5.26513","0.00191"
"10581","63.45000","5.28761","0.00216"
"10626","63.72000","5.31015","0.00148"
"10671","63.99000","5.33263","0.00140"
"10716","64.26000","5.35517","0.00207"
"10761","64.53000","5.37759","0.00132"
"10806","64.80000","5.40013","0.00194"
"10851","65.07000","5.42261","0.00160"
"10896","65.34000","5.44515","0.00189"
"10941","65.61000","5.46751","0.00183"
"10986","65.88000","5.49011","0.00172"
"11031","66.15000","5.51260","0.00182"
"11076","66.42000","5.53520","0.00188"
"11121","66.69000","5.55762","0.00225"
"11166","66.96000","5.58016","0.00159"
"11211","67.23000","5.60258","0.00204"
"11256","67.50000","5.62512","0.00124"
"11301","67.77000","5.64754","0.00246"
"11346","68.04000","5.67014","0.00179"
"11391","68.31000","5.69262","0.00231"
"11436","68.58000","5.71516","0.00230"
"11481","68.85000","5.73764","0.00178"
"11526","69.12000","5.76018","0.00233"
"11571","69.39000","5.78260","0.00217"
"11616","69.66000","5.80515","0.00214"
"11661","69.93000","5.82757","0.00216"
"11706","70.20000","5.85017","0.00171"
"11751","70.47000","5.87259","0.00197"
"11796","70.74000","5.89513","0.00189"
"11841","71.01000","5.91761","0.00196"
"11886","71.28000","5.94015","0.00193"
"11931","71.55000","5.96257","0.00263"
"11976","71.82000","5.98511","0.00208"
"12021","72.09000","6.00753","0.00203"
"12066","72.36000","6.03013","0.00147"
"12111","72.63000","6.05255","0.00177"
"12156","72.90000","6.07515","0.00244"
"12201","73.17000","6.09764","0.00175"
"12246","73.44000","6.12018","0.00197"
"12291","73.71000","6.14260","0.00215"
"12336","73.98000","6.16514","0.00152"
"12381","74.25000","6.18756","0.00193"
"12426","74.52000","6.21016","0.00215"
"12471","74.79000","6.23258","0.00194"
"12516","75.06000","6.25512","0.00156"
"12561","75.33000","6.27754","0.00218"
"12606","75.60000","6.30020","0.00188"
"12651","75.87000","6.32262","0.00227"
"12696","76.14000","6.34516","0.00229"
"12741","76.41000","6.36759","0.00234"
"12786","76.68000","6.39019","0.00235"
"12831","76.95000","6.41255","0.00196"
"12876","77.22000","6.43515","0.00180"
"12921","77.49000","6.45763","0.00221"
"12966","77.76000","6.48017","0.00260"
"13011","78.03000","6.50259","0.00201"
"13056","78.30000","6.52513","0.00235"
"13101","78.57000","6.54761","0.00207"
"13146","78.84000","6.57009","0.00195"
"13191","79.11000","6.59257","0.00261"
"13236","79.38000","6.61511","0.00179"
"13281","79.65000","6.63759","0.00252"
"13326","79.92000","6.66019","0.00189"
"13371","80.19000","6.68262","0.00159"
"13416","80.46000","6.70516","0.00146"
"13461","80.73000","6.72758","0.00185"
"13506","81.00000","6.75012","0.00234"
"13551","81.27000","6.77260","0.00238"
"13596","81.54000","6.79520","0.00219"
"13641","81.81000","6.81762","0.00207"
"13686","82.08000","6.84016","0.00223"
"13731","82.35000","6.86264","0.00141"
"13776","82.62000","6.88518","0.00209"
"13821","82.89000","6.90760","0.00170"
"13866","83.16000","6.93015","0.00196"
"13911","83.43000","6.95257","0.00235"
"13956","83.70000","6.97511","0.00240"
"14001","83.97000","6.99753","0.00253"
"14046","84.24000","7.02013","0.00246"
"14091","84.51000","7.04261","0.00205"
"14136","84.78000","7.06521","0.00219"
"14181","85.05000","7.08763","0.00269"
"14226","85.32000","7.11017","0.00211"
"14271","85.59000","7.13259","0.00215"
"14316","85.86000","7.15519","0.00239"
"14361","86.13000","7.17761","0.00227"
"14406","86.40000","7.20015","0.00200"
"14451","86.67000","7.22264","0.00245"
"14496","86.94000","7.24518","0.00157"
"14541","87.21000","7.26760","0.00185"
"14586","87.48000","7.29014","0.00228"
"14631","87.75000","7.31256","0.00206"
"14676","88.02000","7.33510","0.00197"
"14721","88.29000","7.35758","0.00197"
"14766","88.56000","7.38018","0.00258"
"14811","88.83000","7.40260","0.00208"
"14856","89.10000","7.42514","0.00253"
"14901","89.37000","7.44762","0.00226"
"14946","89.64000","7.47016","0.00197"
"14991","89.91000","7.49259","0.00208"
"15036","90.18000","7.51513","0.00187"
"15081","90.45000","7.53761","0.00215"
"15126","90.72000","7.56015","0.00216"
"15171","90.99000","7.58263","0.00209"
"15216","91.26000","7.60511","0.00224"
"15261","91.53000","7.62765","0.00243"
"15306","91.80000","7.65019","0.00209"
"15351","92.07000","7.67261","0.00263"
"15396","92.34000","7.69515","0.00247"
"15441","92.61000","7.71757","0.00222"
"15486","92.88000","7.74017","0.00219"
"15531","93.15000","7.76259","0.00185"
"15576","93.42000","7.78514","0.00330"
"15621","93.69000","7.80762","0.00264"
"15666","93.96000","7.83022","0.00287"
"15711","94.23000","7.85264","0.00260"
"15756","94.50000","7.87518","0.00290"
"15801","94.77000","7.89760","0.00199"
"15846","95.04000","7.92014","0.00285"
"15891","95.31000","7.94256","0.00226"
"15936","95.58000","7.96510","0.00221"
"15981","95.85000","7.98764","0.00264"
"16026","96.12000","8.01018","0.00206"
"16071","96.39000","8.03266","0.00271"
"16116","96.66000","8.05515","0.00249"
"16161","96.93000","8.07763","0.00220"
"16206","97.20000","8.10017","0.00265"
"16251","97.47000","8.12259","0.00226"
"16296","97.74000","8.14513","0.00231"
"16341","98.01000","8.16755","0.00267"
"16386","98.28000","8.19009","0.00247"
"16431","98.55000","8.21263","0.00227"
"16476","98.82000","8.23517","0.00236"
"16521","99.09000","8.25765","0.00183"
"16566","99.36000","8.28013","0.00212"
"16611","99.63000","8.30261","0.00233"
"16656","99.90000","8.32515","0.00257"
"16701","100.17000","8.34764","0.00235"
"16746","100.44000","8.37018","0.00247"
"16791","100.71000","8.39266","0.00248"
"16836","100.98000","8.41514","0.00197"
"16881","101.25000","8.43762","0.00212"
"16926","101.52000","8.46010","0.00247"
"16971","101.79000","8.48258","0.00225"
"17016","102.06000","8.50512","0.00256"
"17061","102.33000","8.52766","0.00267"
"17106","102.60000","8.55014","0.00210"
"17151","102.87000","8.57262","0.00235"
"17196","103.14000","8.59516","0.00225"
"17241","103.41000","8.61765","0.00209"
"17286","103.68000","8.64013","0.00235"
"17331","103.95000","8.66261","0.00227"
"17376","104.22000","8.68509","0.00264"
"17421","104.49000","8.70763","0.00221"
"17466","104.76000","8.73017","0.00266"
"17511","105.03000","8.75265","0.00271"
"17556","105.30000","8.77519","0.00248"
"17601","105.57000","8.79767","0.00268"
"17646","105.84000","8.82015","0.00250"
"17691","106.11000","8.84263","0.00212"
"17736","106.38000","8.86511","0.00288"
"17781","106.65000","8.88765","0.00313"
"17826","106.92000","8.91014","0.00250"
"17871","107.19000","8.93262","0.00250"
"17916","107.46000","8.95510","0.00261"
"17961","107.73000","8.97770","0.00206"
"18006","108.00000","9.00018","0.00266"
"18051","108.27000","9.02266","0.00228"
"18096","108.54000","9.04508","0.00211"
"18141","108.81000","9.06762","0.00282"
"18186","109.08000","9.09016","0.00215"
"18231","109.35000","9.11264","0.00202"
"18276","109.62000","9.13518","0.00239"
"18321","109.89000","9.15766","0.00194"
"18366","110.16000","9.18014","0.00287"
"18411","110.43000","9.20257","0.00219"
"18456","110.70000","9.22511","0.00184"
"18501","110.97000","9.24759","0.00243"
"18546","111.24000","9.27013","0.00239"
"18591","111.51000","9.29267","0.00267"
"18636","111.78000","9.31515","0.00230"
"18681","112.05000","9.33763","0.00221"
"18726","112.32000","9.36017","0.00271"
"18771","112.59000","9.38259","0.00193"
"18816","112.86000","9.40513","0.00193"
"18861","113.13000","9.42761","0.00270"
"18906","113.40000","9.45010","0.00230"
"18951","113.67000","9.47264","0.00237"
"18996","113.94000","9.49518","0.00197"
"19041","114.21000","9.51766","0.00197"
"19086","114.48000","9.54014","0.00224"
"19131","114.75000","9.56268","0.00245"
"19176","115.02000","9.58516","0.00277"
"19221","115.29000","9.60764","0.00212"
"19266","115.56000","9.63006","0.00222"
"19311","115.83000","9.65266","0.00286"
"19356","116.10000","9.67508","0.00219"
"19401","116.37000","9.69768","0.00263"
"19446","116.64000","9.72016","0.00193"
"19491","116.91000","9.74270","0.00254"
"19536","117.18000","9.76513","0.00276"
"19581","117.45000","9.78767","0.00243"
"19626","117.72000","9.81015","0.00226"
"19671","117.99000","9.83263","0.00198"
"19716","118.26000","9.85511","0.00237"
"19761","118.53000","9.87771","0.00237"
"19806","118.80000","9.90013","0.00193"
"19851","119.07000","9.92267","0.00285"
"19896","119.34000","9.94509","0.00241"
"19941","119.61000","9.96757","0.00240"
"19986","119.88000","9.99005","0.00255"
"20031","120.15000","10.01265","0.00252"
"20076","120.42000","10.03508","0.00289"
"20121","120.69000","10.05762","0.00257"
"20166","120.96000","10.08010","0.00244"
"20211","121.23000","10.10264","0.00271"
"20256","121.50000","10.12512","0.00258"
"20301","121.77000","10.14766","0.00317"
"20346","122.04000","10.17014","0.00234"
"20391","122.31000","10.19262","0.00236"
"20436","122.58000","10.21510","0.00282"
"20481","122.85000","10.23764","0.00281"
"20526","123.12000","10.26012","0.00214"
"20571","123.39000","10.28266","0.00245"
"20616","123.66000","10.30509","0.00218"
"20661","123.93000","10.32769","0.00262"
"20706","124.20000","10.35011","0.00305"
"20751","124.47000","10.37265","0.00240"
"20796","124.74000","10.39513","0.00260"
"20841","125.01000","10.41767","0.00299"
"20886","125.28000","10.44015","0.00282"
"20931","125.55000","10.46269","0.00337"
"20976","125.82000","10.48511","0.00257"
"21021","126.09000","10.50765","0.00259"
"21066","126.36000","10.53007","0.00279"
"21111","126.63000","10.55267","0.00250"
"21156","126.90000","10.57515","0.00292"
"21201","127.17000","10.59764","0.00234"
"21246","127.44000","10.62012","0.00226"
"21291","127.71000","10.64266","0.00293"
"21336","127.98000","10.66508","0.00263"
"21381","128.25000","10.68768","0.00285"
"21426","128.52000","10.71016","0.00286"
"21471","128.79000","10.73264","0.00325"
"21516","129.06000","10.75512","0.00276"
"21561","129.33000","10.77766","0.00293"
"21606","129.60000","10.80008","0.00290"
"21651","129.87000","10.82262","0.00305"
"21696","130.14000","10.84516","0.00289"
"21741","130.41000","10.86770","0.00290"
"21786","130.68000","10.89012","0.00252"
"21831","130.95000","10.91267","0.00292"
"21876","131.22000","10.93515","0.00296"
"21921","131.49000","10.95763","0.00306"
"21966","131.76000","10.98011","0.00301"
"22011","132.03000","11.00265","0.00293"
"22056","132.30000","11.02507","0.00320"
"22101","132.57000","11.04767","0.00253"
"22146","132.84000","11.07015","0.00316"
"22191","133.11000","11.09263","0.00336"
"22236","133.38000","11.11505","0.00304"
"22281","133.65000","11.13759","0.00333"
"22326","133.92000","11.16008","0.00258"
"22371","134.19000","11.18262","0.00306"
"22416","134.46000","11.20504","0.00266"
"22461","134.73000","11.22764","0.00273"
"22506","135.00000","11.25012","0.00308"
"22551","135.27000","11.27266","0.00297"
"22596","135.54000","11.29508","0.00280"
"22641","135.81000","11.31762","0.00314"
"22686","136.08000","11.34010","0.00320"
"22731","136.35000","11.36264","0.00292"
"22776","136.62000","11.38506","0.00300"
"22821","136.89000","11.40760","0.00295"
"22866","137.16000","11.43008","0.00258"
"22911","137.43000","11.45268","0.00335"
"22956","137.70000","11.47511","0.00331"
"23001","137.97000","11.49765","0.00311"
"23046","138.24000","11.52007","0.00326"
"23091","138.51000","11.54261","0.00334"
"23136","138.78000","11.56509","0.00333"
"23181","139.05000","11.58763","0.00291"
"23226","139.32000","11.61011","0.00380"
"23271","139.59000","11.63271","0.00341"
"23316","139.86000","11.65513","0.00371"
"23361","140.13000","11.67761","0.00333"
"23406","140.40000","11.70009","0.00349"
"23451","140.67000","11.72264","0.00298"
"23496","140.94000","11.74512","0.00310"
"23541","141.21000","11.76766","0.00374"
"23586","141.48000","11.79014","0.00356"
"23631","141.75000","11.81268","0.00370"
"23676","142.02000","11.83510","0.00323"
"23721","142.29000","11.85764","0.00324"
"23766","142.56000","11.88006","0.00369"
"23811","142.83000","11.90266","0.00306"
"23856","143.10000","11.92508","0.00351"
"23901","143.37000","11.94762","0.00341"
"23946","143.64000","11.97004","0.00366"
"23991","143.91000","11.99264","0.00372"
"24036","144.18000","12.01512","0.00348"
"24081","144.45000","12.03773","0.00318"
"24126","144.72000","12.06009","0.00400"
"24171","144.99000","12.08263","0.00318"
"24216","145.26000","12.10505","0.00339"
"24261","145.53000","12.12765","0.00388"
"24306","145.80000","12.15007","0.00342"
"24351","146.07000","12.17261","0.00367"
"24396","146.34000","12.19509","0.00333"
"24441","146.61000","12.21763","0.00377"
"24486","146.88000","12.24011","0.00365"
"24531","147.15000","12.26259","0.00371"
"24576","147.42000","12.28502","0.00348"
"24621","147.69000","12.30762","0.00364"
"24666","147.96000","12.33010","0.00342"
"24711","148.23000","12.35264","0.00335"
"24756","148.50000","12.37512","0.00395"
"24801","148.77000","12.39766","0.00382"
"24846","149.04000","12.42008","0.00324"
"24891","149.31000","12.44262","0.00406"
"24936","149.58000","12.46504","0.00369"
"24981","149.85000","12.48764","0.00391"
"25026","150.12000","12.51012","0.00357"
"25071","150.39000","12.53266","0.00398"
"25116","150.66000","12.55509","0.00428"
"25161","150.93000","12.57768","0.00373"
"25206","151.20000","12.60011","0.00440"
"25251","151.47000","12.62265","0.00437"
"25296","151.74000","12.64507","0.00399"
"25341","152.01000","12.66761","0.00391"
"25386","152.28000","12.69003","0.00362"
"25431","152.55000","12.71269","0.00356"
"25476","152.82000","12.73505","0.00408"
"25521","153.09000","12.75765","0.00409"
"25566","153.36000","12.78013","0.00381"
"25611","153.63000","12.80267","0.00398"
"25656","153.90000","12.82509","0.00380"
"25701","154.17000","12.84763","0.00390"
"25746","154.44000","12.87012","0.00417"
"25791","154.71000","12.89266","0.00395"
"25836","154.98000","12.91508","0.00366"
"25881","155.25000","12.93768","0.00392"
"25926","155.52000","12.96010","0.00417"
"25971","155.79000","12.98264","0.00374"
"26016","156.06000","13.00506","0.00411"
"26061","156.33000","13.02760","0.00412"
"26106","156.60000","13.05008","0.00412"
"26151","156.87000","13.07262","0.00439"
"26196","157.14000","13.09504","0.00380"
"26241","157.41000","13.11765","0.00404"
"26286","157.68000","13.14007","0.00411"
"26331","157.95000","13.16261","0.00394"
"26376","158.22000","13.18515","0.00394"
"26421","158.49000","13.20763","0.00410"
"26466","158.76000","13.23005","0.00344"
"26511","159.03000","13.25265","0.00373"
"26556","159.30000","13.27513","0.00352"
"26601","159.57000","13.29767","0.00427"
"26646","159.84000","13.32015","0.00376"
"26691","160.11000","13.34263","0.00391"
"26736","160.38000","13.36511","0.00406"
"26781","160.65000","13.38765","0.00355"
"26826","160.92000","13.41008","0.00408"
"26871","161.19000","13.43268","0.00409"
"26916","161.46000","13.45504","0.00383"
"26961","161.73000","13.47764","0.00417"
"27006","162.00000","13.50012","0.00392"
"27051","162.27000","13.52266","0.00342"
"27096","162.54000","13.54514","0.00374"
"27141","162.81000","13.56768","0.00443"
"27186","163.08000","13.59010","0.00438"
"27231","163.35000","13.61264","0.00435"
"27276","163.62000","13.63512","0.00393"
"27321","163.89000","13.65766","0.00341"
"27366","164.16000","13.68015","0.00390"
"27411","164.43000","13.70268","0.00393"
"27456","164.70000","13.72517","0.00386"
"27501","164.97000","13.74765","0.00387"
"27546","165.24000","13.77013","0.00433"
"27591","165.51000","13.79261","0.00459"
"27636","165.78000","13.81509","0.00409"
"27681","166.05000","13.83763","0.00415"
"27726","166.32000","13.86011","0.00439"
"27771","166.59000","13.88265","0.00398"
"27816","166.86000","13.90513","0.00469"
"27861","167.13000","13.92761","0.00468"
"27906","167.40000","13.95009","0.00390"
"27951","167.67000","13.97263","0.00387"
"27996","167.94000","13.99512","0.00458"
"28041","168.21000","14.01766","0.00432"
"28086","168.48000","14.04008","0.00404"
"28131","168.75000","14.06268","0.00441"
"28176","169.02000","14.08516","0.00438"
"28221","169.29000","14.10770","0.00432"
"28266","169.56000","14.13012","0.00438"
"28311","169.83000","14.15266","0.00454"
"28356","170.10000","14.17508","0.00467"
"28401","170.37000","14.19762","0.00415"
"28446","170.64000","14.22010","0.00420"
"28491","170.91000","14.24264","0.00489"
"28536","171.18000","14.26507","0.00480"
"28581","171.45000","14.28767","0.00434"
"28626","171.72000","14.31015","0.00439"
"28671","171.99000","14.33263","0.00444"
"28716","172.26000","14.35505","0.00459"
"28761","172.53000","14.37759","0.00441"
"28806","172.80000","14.40013","0.00453"
"28851","173.07000","14.42261","0.00453"
"28896","173.34000","14.44509","0.00462"
"28941","173.61000","14.46769","0.00482"
"28986","173.88000","14.49017","0.00451"
"29031","174.15000","14.51265","0.00439"
"29076","174.42000","14.53513","0.00475"
"29121","174.69000","14.55762","0.00474"
"29166","174.96000","14.58016","0.00459"
"29211","175.23000","14.60264","0.00430"
"29256","175.50000","14.62518","0.00461"
"29301","175.77000","14.64760","0.00482"
"29346","176.04000","14.67014","0.00540"
"29391","176.31000","14.69268","0.00475"
"29436","176.58000","14.71516","0.00506"
"29481","176.85000","14.73764","0.00458"
"29526","177.12000","14.76018","0.00433"
"29571","177.39000","14.78260","0.00514"
"29616","177.66000","14.80514","0.00514"
"29661","177.93000","14.82768","0.00514"
"29706","178.20000","14.85017","0.00492"
"29751","178.47000","14.87265","0.00481"
"29796","178.74000","14.89513","0.00448"
"29841","179.01000","14.91761","0.00480"
"29886","179.28000","14.94009","0.00515"
"29931","179.55000","14.96257","0.00544"
"29976","179.82000","14.98511","0.00506"
"30021","180.09000","15.00765","0.00528"
"30066","180.36000","15.03019","0.00520"
"30111","180.63000","15.05267","0.00548"
"30156","180.90000","15.07515","0.00552"
"30201","181.17000","15.09763","0.00536"
"30246","181.44000","15.12012","0.00525"
"30291","181.71000","15.14260","0.00569"
"30336","181.98000","15.16514","0.00564"
"30381","182.25000","15.18762","0.00524"
"30426","182.52000","15.21010","0.00592"
"30471","182.79000","15.23264","0.00549"
"30516","183.06000","15.25512","0.00543"
"30561","183.33000","15.27766","0.00594"
"30606","183.60000","15.30014","0.00569"
"30651","183.87000","15.32256","0.00557"
"30696","184.14000","15.34510","0.00550"
"30741","184.41000","15.36759","0.00570"
"30786","184.68000","15.39013","0.00601"
"30831","184.95000","15.41261","0.00572"
"30876","185.22000","15.43521","0.00543"
"30921","185.49000","15.45769","0.00597"
"30966","185.76000","15.48011","0.00562"
"31011","186.03000","15.50265","0.00552"
"31056","186.30000","15.52513","0.00579"
"31101","186.57000","15.54761","0.00541"
"31146","186.84000","15.57015","0.00585"
"31191","187.11000","15.59263","0.00593"
"31236","187.38000","15.61517","0.00532"
"31281","187.65000","15.63765","0.00606"
"31326","187.92000","15.66013","0.00575"
"31371","188.19000","15.68262","0.00648"
"31416","188.46000","15.70510","0.00560"
"31461","188.73000","15.72758","0.00607"
"31506","189.00000","15.75018","0.00620"
"31551","189.27000","15.77266","0.00603"
"31596","189.54000","15.79514","0.00625"
"31641","189.81000","15.81768","0.00648"
"31686","190.08000","15.84010","0.00585"
"31731","190.35000","15.86264","0.00614"
"31776","190.62000","15.88512","0.00641"
"31821","190.89000","15.90760","0.00626"
"31866","191.16000","15.93014","0.00581"
"31911","191.43000","15.95262","0.00558"
"31956","191.70000","15.97516","0.00658"
"32001","191.97000","15.99765","0.00642"
"32046","192.24000","16.02019","0.00637"
"32091","192.51000","16.04261","0.00648"
"32136","192.78000","16.06515","0.00625"
"32181","193.05000","16.08757","0.00651"
"32226","193.32000","16.11011","0.00669"
"32271","193.59000","16.13259","0.00637"
"32316","193.86000","16.15513","0.00660"
"32361","194.13000","16.17761","0.00695"
"32406","194.40000","16.20021","0.00665"
"32451","194.67000","16.22263","0.00659"
"32496","194.94000","16.24517","0.00722"
"32541","195.21000","16.26760","0.00697"
"32586","195.48000","16.29014","0.00720"
"32631","195.75000","16.31262","0.00691"
"32676","196.02000","16.33516","0.00712"
"32721","196.29000","16.35764","0.00772"
"32766","196.56000","16.38018","0.00747"
"32811","196.83000","16.40260","0.00686"
"32856","197.10000","16.42514","0.00719"
"32901","197.37000","16.44762","0.00765"
"32946","197.64000","16.47010","0.00699"
"32991","197.91000","16.49258","0.00772"
"33036","198.18000","16.51513","0.00722"
"33081","198.45000","16.53761","0.00720"
"33126","198.72000","16.56015","0.00746"
"33171","198.99000","16.58263","0.00751"
"33216","199.26000","16.60517","0.00824"
"33261","199.53000","16.62765","0.00726"
"33306","199.80000","16.65013","0.00774"
"33351","200.07000","16.67261","0.00781"
"33396","200.34000","16.69515","0.00804"
"33441","200.61000","16.71763","0.00829"
"33486","200.88000","16.74017","0.00824"
"33531","201.15000","16.76265","0.00821"
"33576","201.42000","16.78519","0.00845"
"33621","201.69000","16.80761","0.00798"
"33666","201.96000","16.83010","0.00861"
"33711","202.23000","16.85258","0.00867"
"33756","202.50000","16.87518","0.00824"
"33801","202.77000","16.89760","0.00832"
"33846","203.04000","16.92020","0.00892"
"33891","203.31000","16.94262","0.00848"
"33936","203.58000","16.96516","0.00858"
"33981","203.85000","16.98758","0.00887"
"34026","204.12000","17.01012","0.00867"
"34071","204.39000","17.03260","0.00884"
"34116","204.66000","17.05514","0.00915"
"34161","204.93000","17.07756","0.00950"
"34206","205.20000","17.10016","0.00906"
"34251","205.47000","17.12259","0.00905"
"34296","205.74000","17.14513","0.00938"
"34341","206.01000","17.16761","0.00942"
"34386","206.28000","17.19015","0.00941"
"34431","206.55000","17.21263","0.00995"
"34476","206.82000","17.23517","0.00913"
"34521","207.09000","17.25765","0.00984"
"34566","207.36000","17.28013","0.00983"
"34611","207.63000","17.30261","0.01026"
"34656","207.90000","17.32515","0.00977"
"34701","208.17000","17.34763","0.00960"
"34746","208.44000","17.37017","0.01026"
"34791","208.71000","17.39260","0.01012"
"34836","208.98000","17.41514","0.01001"
"34881","209.25000","17.43762","0.01033"
"34926","209.52000","17.46016","0.01071"
"34971","209.79000","17.48258","0.01068"
"35016","210.06000","17.50518","0.01103"
"35061","210.33000","17.52766","0.01121"
"35106","210.60000","17.55014","0.01136"
"35151","210.87000","17.57256","0.01078"
"35196","211.14000","17.59516","0.01142"
"35241","211.41000","17.61758","0.01150"
"35286","211.68000","17.64013","0.01135"
"35331","211.95000","17.66255","0.01167"
"35376","212.22000","17.68514","0.01126"
"35421","212.49000","17.70763","0.01198"
"35466","212.76000","17.73017","0.01212"
"35511","213.03000","17.75265","0.01179"
"35556","213.30000","17.77519","0.01290"
"35601","213.57000","17.79761","0.01229"
"35646","213.84000","17.82015","0.01262"
"35691","214.11000","17.84257","0.01288"
"35736","214.38000","17.86511","0.01244"
"35781","214.65000","17.88753","0.01254"
"35826","214.92000","17.91013","0.01337"
"35871","215.19000","17.93261","0.01353"
"35916","215.46000","17.95516","0.01350"
"35961","215.73000","17.97752","0.01366"
"36006","216.00000","18.00012","0.01340"
"36051","216.27000","18.02260","0.01387"
"36096","216.54000","18.04514","0.01405"
"36141","216.81000","18.06762","0.01423"
"36186","217.08000","18.09016","0.01530"
"36231","217.35000","18.11264","0.01429"
"36276","217.62000","18.13512","0.01466"
"36321","217.89000","18.15760","0.01527"
"36366","218.16000","18.18014","0.01538"
"36411","218.43000","18.20263","0.01498"
"36456","218.70000","18.22516","0.01534"
"36501","218.97000","18.24764","0.01519"
"36546","219.24000","18.27013","0.01577"
"36591","219.51000","18.29261","0.01579"
"36636","219.78000","18.31515","0.01616"
"36681","220.05000","18.33757","0.01640"
"36726","220.32000","18.36011","0.01715"
"36771","220.59000","18.38259","0.01739"
"36816","220.86000","18.40513","0.01695"
"36861","221.13000","18.42755","0.01753"
"36906","221.40000","18.45015","0.01755"
"36951","221.67000","18.47263","0.01725"
"36996","221.94000","18.49517","0.01773"
"37041","222.21000","18.51760","0.01792"
"37086","222.48000","18.54014","0.01865"
"37131","222.75000","18.56262","0.01890"
"37176","223.02000","18.58516","0.01938"
"37221","223.29000","18.60752","0.01907"
"37266","223.56000","18.63018","0.01926"
"37311","223.83000","18.65260","0.01990"
"37356","224.10000","18.67514","0.01899"
"37401","224.37000","18.69756","0.02003"
"37446","224.64000","18.72010","0.02019"
"37491","224.91000","18.74252","0.02043"
"37536","225.18000","18.76512","0.02042"
"37581","225.45000","18.78755","0.02069"
"37626","225.72000","18.81015","0.02042"
"37671","225.99000","18.83263","0.02107"
"37716","226.26000","18.85517","0.02138"
"37761","226.53000","18.87765","0.02099"
"37806","226.80000","18.90013","0.02155"
"37851","227.07000","18.92255","0.02201"
"37896","227.34000","18.94515","0.02301"
"37941","227.61000","18.96757","0.02345"
"37986","227.88000","18.99017","0.02269"
"38031","228.15000","19.01259","0.02361"
"38076","228.42000","19.03514","0.02357"
"38121","228.69000","19.05762","0.02367"
"38166","228.96000","19.08015","0.02417"
"38211","229.23000","19.10252","0.02415"
"38256","229.50000","19.12512","0.02474"
"38301","229.77000","19.14754","0.02532"
"38346","230.04000","19.17014","0.02552"
"38391","230.31000","19.19256","0.02537"
"38436","230.58000","19.21516","0.02620"
"38481","230.85000","19.23764","0.02657"
"38526","231.12000","19.26018","0.02623"
"38571","231.39000","19.28260","0.02672"
"38616","231.66000","19.30514","0.02702"
"38661","231.93000","19.32756","0.02750"
"38706","232.20000","19.35011","0.02767"
"38751","232.47000","19.37259","0.02810"
"38796","232.74000","19.39513","0.02796"
"38841","233.01000","19.41761","0.02860"
"38886","233.28000","19.44015","0.02867"
"38931","233.55000","19.46257","0.02908"
"38976","233.82000","19.48517","0.02944"
"39021","234.09000","19.50753","0.03004"
"39066","234.36000","19.53007","0.03019"
"39111","234.63000","19.55261","0.03043"
"39156","234.90000","19.57515","0.03049"
"39201","235.17000","19.59764","0.03085"
"39246","235.44000","19.62012","0.03118"
"39291","235.71000","19.64260","0.03205"
"39336","235.98000","19.66514","0.03195"
"39381","236.25000","19.68756","0.03199"
"39426","236.52000","19.71010","0.03213"
"39471","236.79000","19.73264","0.03256"
"39516","237.06000","19.75518","0.03217"
"39561","237.33000","19.77760","0.03268"
"39606","237.60000","19.80014","0.03297"
"39651","237.87000","19.82262","0.03335"
"39696","238.14000","19.84516","0.03380"
"39741","238.41000","19.86758","0.03358"
"39786","238.68000","19.89018","0.03394"
"39831","238.95000","19.91261","0.03436"
"39876","239.22000","19.93515","0.03473"
"39921","239.49000","19.95763","0.03500"
"39966","239.76000","19.98017","0.03478"
"40011","240.03000","20.00265","0.03497"
"40056","240.30000","20.02519","0.03540"
"40101","240.57000","20.04761","0.03554"
"40146","240.84000","20.07015","0.03576"
"40191","241.11000","20.09257","0.03608"
"40236","241.38000","20.11517","0.03637"
"40281","241.65000","20.13765","0.03641"
"40326","241.92000","20.16014","0.03711"
"40371","242.19000","20.18262","0.03697"
"40416","242.46000","20.20515","0.03704"
"40461","242.73000","20.22757","0.03773"
"40506","243.00000","20.25012","0.03814"
"40551","243.27000","20.27260","0.03852"
"40596","243.54000","20.29514","0.03892"
"40641","243.81000","20.31762","0.03932"
"40686","244.08000","20.34010","0.03992"
"40731","244.35000","20.36264","0.04027"
"40776","244.62000","20.38512","0.04108"
"40821","244.89000","20.40760","0.04178"
"40866","245.16000","20.43014","0.04231"
"40911","245.43000","20.45262","0.04258"
"40956","245.70000","20.47517","0.04392"
"41001","245.97000","20.49765","0.04511"
"41046","246.24000","20.52013","0.04591"
"41091","246.51000","20.54261","0.04702"
"41136","246.78000","20.56515","0.04718"
"41181","247.05000","20.58757","0.04850"
"41226","247.32000","20.61011","0.04887"
"41271","247.59000","20.63259","0.05051"
"41316","247.86000","20.65513","0.05093"
"41361","248.13000","20.67761","0.05267"
"41406","248.40000","20.70015","0.05376"
"41451","248.67000","20.72257","0.05458"
"41496","248.94000","20.74517","0.05608"
"41541","249.21000","20.76765","0.05705"
"41586","249.48000","20.79014","0.05834"
"41631","249.75000","20.81262","0.05921"
"41676","250.02000","20.83516","0.06008"
"41721","250.29000","20.85758","0.06100"
"41766","250.56000","20.88012","0.06192"
"41811","250.83000","20.90260","0.06350"
"41856","251.10000","20.92508","0.06452"
"41901","251.37000","20.94762","0.06525"
"41946","251.64000","20.97016","0.06593"
"41991","251.91000","20.99264","0.06699"
"42036","252.18000","21.01513","0.06782"
"42081","252.45000","21.03761","0.06931"
"42126","252.72000","21.06015","0.07089"
"42171","252.99000","21.08263","0.07142"
"42216","253.26000","21.10517","0.07290"
"42261","253.53000","21.12765","0.07466"
"42306","253.80000","21.15019","0.07604"
"42351","254.07000","21.17267","0.07817"
"42396","254.34000","21.19515","0.07911"
"42441","254.61000","21.21763","0.08069"
"42486","254.88000","21.24011","0.08151"
"42531","255.15000","21.26265","0.08273"
"42576","255.42000","21.28513","0.08429"
"42621","255.69000","21.30767","0.08480"
"42666","255.96000","21.33016","0.08543"
"42711","256.23000","21.35264","0.08591"
"42756","256.50000","21.37512","0.08611"
"42801","256.77000","21.39760","0.08677"
"42846","257.04000","21.42008","0.08696"
"42891","257.31000","21.44262","0.08720"
"42936","257.58000","21.46510","0.08736"
"42981","257.85000","21.48758","0.08787"
"43026","258.12000","21.51018","0.08842"
"43071","258.39000","21.53260","0.08936"
"43116","258.66000","21.55515","0.09056"
"43161","258.93000","21.57763","0.09192"
"43206","259.20000","21.60011","0.09394"
"43251","259.47000","21.62265","0.09564"
"43296","259.74000","21.64513","0.09863"
"43341","260.01000","21.66761","0.10105"
"43386","260.28000","21.69015","0.10253"
"43431","260.55000","21.71263","0.10537"
"43476","260.82000","21.73517","0.10705"
"43521","261.09000","21.75765","0.10956"
"43566","261.36000","21.78007","0.11186"
"43611","261.63000","21.80261","0.11292"
"43656","261.90000","21.82509","0.11559"
"43701","262.17000","21.84763","0.11700"
"43746","262.44000","21.87018","0.11863"
"43791","262.71000","21.89266","0.11973"
"43836","262.98000","21.91514","0.12114"
"43881","263.25000","21.93768","0.12252"
"43926","263.52000","21.96010","0.12386"
"43971","263.79000","21.98264","0.12494"
"44016","264.06000","22.00512","0.12599"
"44061","264.33000","22.02766","0.12802"
"44106","264.60000","22.05020","0.12899"
"44151","264.87000","22.07268","0.13018"
"44196","265.14000","22.09516","0.13233"
"44241","265.41000","22.11764","0.13324"
"44286","265.68000","22.14013","0.13432"
"44331","265.95000","22.16261","0.13547"
"44376","266.22000","22.18508","0.13668"
"44421","266.49000","22.20763","0.13774"
"44466","266.76000","22.23011","0.13870"
"44511","267.03000","22.25265","0.14066"
"44556","267.30000","22.27519","0.14332"
"44601","267.57000","22.29761","0.14526"
"44646","267.84000","22.32009","0.14834"
"44691","268.11000","22.34263","0.15254"
"44736","268.38000","22.36511","0.15607"
"44781","268.65000","22.38759","0.16090"
"44826","268.92000","22.41013","0.16539"
"44871","269.19000","22.43268","0.17202"
"44916","269.46000","22.45516","0.17686"
"44961","269.73000","22.47770","0.18195"
"45006","270.00000","22.50012","0.18539"
"45051","270.27000","22.52260","0.18807"
"45096","270.54000","22.54508","0.18962"
"45141","270.81000","22.56762","0.19101"
"45186","271.08000","22.59010","0.19191"
"45231","271.35000","22.61264","0.19331"
"45276","271.62000","22.63512","0.19561"
"45321","271.89000","22.65766","0.19784"
"45366","272.16000","22.68008","0.19815"
"45411","272.43000","22.70263","0.19208"
"45456","272.70000","22.72505","0.19313"
"45501","272.97000","22.74764","0.19379"
"45546","273.24000","22.77013","0.19550"
"45591","273.51000","22.79267","0.19852"
"45636","273.78000","22.81509","0.19841"
"45681","274.05000","22.83763","0.20189"
"45726","274.32000","22.86011","0.20693"
"45771","274.59000","22.88265","0.20949"
"45816","274.86000","22.90507","0.21276"
"45861","275.13000","22.92767","0.21655"
"45906","275.40000","22.95015","0.21950"
"45951","275.67000","22.97269","0.22313"
"45996","275.94000","22.99511","0.22643"
"46041","276.21000","23.01766","0.22861"
"46086","276.48000","23.04014","0.23123"
"46131","276.75000","23.06268","0.23269"
"46176","277.02000","23.08516","0.23404"
"46221","277.29000","23.10764","0.23501"
"46266","277.56000","23.13012","0.23584"
"46311","277.83000","23.15266","0.23655"
"46356","278.10000","23.17514","0.23740"
"46401","278.37000","23.19768","0.23829"
"46446","278.64000","23.22010","0.23914"
"46491","278.91000","23.24264","0.23987"
"46536","279.18000","23.26506","0.24087"
"46581","279.45000","23.28766","0.24239"
"46626","279.72000","23.31008","0.24426"
"46671","279.99000","23.33263","0.24618"
"46716","280.26000","23.35505","0.24921"
"46761","280.53000","23.37765","0.25317"
"46806","280.80000","23.40013","0.25694"
"46851","281.07000","23.42267","0.25997"
"46896","281.34000","23.44515","0.26340"
"46941","281.61000","23.46769","0.26621"
"46986","281.88000","23.49011","0.26889"
"47031","282.15000","23.51265","0.27221"
"47076","282.42000","23.53513","0.27649"
"47121","282.69000","23.55767","0.27923"
"47166","282.96000","23.58010","0.28147"
"47211","283.23000","23.60264","0.28384"
"47256","283.50000","23.62512","0.28489"
"47301","283.77000","23.64766","0.28619"
"47346","284.04000","23.67008","0.28792"
"47391","284.31000","23.69262","0.29016"
"47436","284.58000","23.71510","0.25357"
"47481","284.85000","23.73764","0.19949"
"47526","285.12000","23.76006","0.19721"
"47571","285.39000","23.78272","0.19747"
"47616","285.66000","23.80514","0.19901"
"47661","285.93000","23.82768","0.20160"
"47706","286.20000","23.85011","0.20502"
"47751","286.47000","23.87258","0.20812"
"47796","286.74000","23.89513","0.21066"
"47841","287.01000","23.91767","0.21335"
"47886","287.28000","23.94009","0.21689"
"47931","287.55000","23.96263","0.21928"
"47976","287.82000","23.98511","0.22245"
"48021","288.09000","24.00765","0.22460"
"48066","288.36000","24.03007","0.22721"
"48111","288.63000","24.05261","0.22978"
"48156","288.90000","24.07509","0.23136"
"48201","289.17000","24.09764","0.23250"
"48246","289.44000","24.12005","0.23342"
"48291","289.71000","24.14266","0.23468"
"48336","289.98000","24.16514","0.23540"
"48381","290.25000","24.18768","0.23626"
"48426","290.52000","24.21010","0.23668"
"48471","290.79000","24.23264","0.23751"
"48516","291.06000","24.25506","0.23815"
"48561","291.33000","24.27760","0.23892"
"48606","291.60000","24.30008","0.23969"
"48651","291.87000","24.32262","0.24043"
"48696","292.14000","24.34504","0.24138"
"48741","292.41000","24.36764","0.24284"
"48786","292.68000","24.39012","0.24455"
"48831","292.95000","24.41261","0.24620"
"48876","293.22000","24.43508","0.13542"
"48921","293.49000","24.45757","0.12899"
"48966","293.76000","24.48005","0.13095"
"49011","294.03000","24.50259","0.13118"
"49056","294.30000","24.52507","0.13145"
"49101","294.57000","24.54767","0.13344"
"49146","294.84000","24.57009","0.13228"
"49191","295.11000","24.59263","0.13923"
"49236","295.38000","24.61511","0.13357"
"49281","295.65000","24.63759","0.13877"
"49326","295.92000","24.66007","0.13778"
"49371","296.19000","24.68262","0.13664"
"49416","296.46000","24.70509","0.14230"
"49461","296.73000","24.72764","0.14072"
"49506","297.00000","24.75006","0.14961"
"49551","297.27000","24.77266","0.14297"
"49596","297.54000","24.79508","0.15225"
"49641","297.81000","24.81762","0.15430"
"49686","298.08000","24.84004","0.14940"
"49731","298.35000","24.86264","0.16786"
"49776","298.62000","24.88506","0.16247"
"49821","298.89000","24.90766","0.16784"
"49866","299.16000","24.93008","0.17093"
"49911","299.43000","24.95268","0.17051"
"49956","299.70000","24.97504","0.18515"
"50001","299.97000","24.99765","0.17753"
"50046","300.24000","25.02007","0.18511"
"50091","300.51000","25.04267","0.18908"
"50136","300.78000","25.06509","0.18736"
"50181","301.05000","25.08769","0.05942"
"50226","301.32000","25.11011","0.06387"
"50271","301.59000","25.13271","0.06463"
"50316","301.86000","25.15507","0.05869"
"50361","302.13000","25.17761","0.06807"
"50406","302.40000","25.20003","0.05694"
"50451","302.67000","25.22264","0.06906"
"50496","302.94000","25.24505","0.06133"
"50541","303.21000","25.26765","0.07811"
"50586","303.48000","25.29008","0.06890"
"50631","303.75000","25.31268","0.08577"
"50676","304.02000","25.33510","0.07655"
"50721","304.29000","25.35764","0.08645"
"50766","304.56000","25.38006","0.07825"
"50811","304.83000","25.40260","0.08461"
"50856","305.10000","25.42508","0.08005"
"50901","305.37000","25.44762","0.08324"
"50946","305.64000","25.47010","0.08435"
"50991","305.91000","25.49264","0.08431"
"51036","306.18000","25.51512","0.08707"
"51081","306.45000","25.53767","0.08602"
"51126","306.72000","25.56003","0.08903"
"51171","306.99000","25.58263","0.08759"
"51216","307.26000","25.60505","0.08902"
"51261","307.53000","25.62765","0.09184"
"51306","307.80000","25.65007","0.08816"
"51351","308.07000","25.67267","0.10139"
"51396","308.34000","25.69515","0.08897"
"51441","308.61000","25.71769","0.10739"
"51486","308.88000","25.74011","0.09230"
"51531","309.15000","25.76265","0.10654"
"51576","309.42000","25.78507","0.09920"
"51621","309.69000","25.80762","0.10529"
"51666","309.96000","25.83009","0.10616"
"51711","310.23000","25.85264","0.10899"
"51756","310.50000","25.87512","0.10863"
"51801","310.77000","25.89766","0.11571"
"51846","311.04000","25.92008","0.10834"
"51891","311.31000","25.94262","0.11971"
"51936","311.58000","25.96510","0.11193"
"51981","311.85000","25.98764","0.12002"
"52026","312.12000","26.01012","0.11840"
"52071","312.39000","26.03266","0.12077"
"52116","312.66000","26.05514","0.12078"
"52161","312.93000","26.07763","0.12352"
"52206","313.20000","26.10010","0.12075"
"52251","313.47000","26.12265","0.12625"
"52296","313.74000","26.14513","0.12242"
"52341","314.01000","26.16767","0.12656"
"52386","314.28000","26.19009","0.12550"
"52431","314.55000","26.21263","0.12704"
"52476","314.82000","26.23511","0.12702"
"52521","315.09000","26.25765","0.12922"
"52566","315.36000","26.28007","0.12886"
"52611","315.63000","26.30267","0.13110"
"52656","315.90000","26.32509","0.13257"
"52701","316.17000","26.34757","0.13182"
"52746","316.44000","26.37005","0.13512"
"52791","316.71000","26.39266","0.13378"
"52836","316.98000","26.41514","0.13639"
"52881","317.25000","26.43762","0.13590"
"52926","317.52000","26.46016","0.13925"
"52971","317.79000","26.48270","0.13751"
"53016","318.06000","26.50512","0.14097"
"53061","318.33000","26.52766","0.14021"
"53106","318.60000","26.55008","0.14101"
"53151","318.87000","26.57262","0.14544"
"53196","319.14000","26.59510","0.14494"
"53241","319.41000","26.61765","0.15135"
"53286","319.68000","26.64013","0.14969"
"53331","319.95000","26.66266","0.15996"
"53376","320.22000","26.68515","0.15371"
"53421","320.49000","26.70763","0.16146"
"53466","320.76000","26.73010","0.16428"
"53511","321.03000","26.75265","0.16469"
"53556","321.30000","26.77507","0.17485"
"53601","321.57000","26.79761","0.17296"
"53646","321.84000","26.82009","0.18280"
"53691","322.11000","26.84263","0.17866"
"53736","322.38000","26.86517","0.18227"
"53781","322.65000","26.88765","0.18332"
"53826","322.92000","26.91013","0.18465"
"53871","323.19000","26.93268","0.18877"
"53916","323.46000","26.95516","0.18711"
"53961","323.73000","26.97764","0.19026"
"54006","324.00000","27.00012","0.18975"
"54051","324.27000","27.02266","0.19061"
"54096","324.54000","27.04514","0.19221"
"54141","324.81000","27.06762","0.19161"
"54186","325.08000","27.09010","0.00392"
"54231","325.35000","27.11258","0.02556"
"54276","325.62000","27.13506","0.00802"
"54321","325.89000","27.15760","0.00955"
"54366","326.16000","27.18015","0.00762"
"54411","326.43000","27.20268","0.00905"
"54456","326.70000","27.22510","0.00852"
"54501","326.97000","27.24765","0.01287"
"54546","327.24000","27.27013","0.00650"
"54591","327.51000","27.29261","0.01187"
"54636","327.78000","27.31509","0.00790"
"54681","328.05000","27.33763","0.01020"
"54726","328.32000","27.36011","0.00896"
"54771","328.59000","27.38265","0.01093"
"54816","328.86000","27.40513","0.00961"
"54861","329.13000","27.42767","0.01054"
"54906","329.40000","27.45009","0.01063"
"54951","329.67000","27.47257","0.01000"
"54996","329.94000","27.49511","0.01138"
"55041","330.21000","27.51760","0.01023"
"55086","330.48000","27.54008","0.01189"
"55131","330.75000","27.56262","0.01099"
"55176","331.02000","27.58510","0.01170"
"55221","331.29000","27.60764","0.01173"
"55253","331.48200","27.62360","0.01377"