File: Trajectories_together/170122_1Specimen_RawData_6.csv
"","V1","V2","V3"
"1","End date","1/22/2017",""
"2","Specimen label","18BG_48",""
"3","Maximum Load","0.13923","N"
"4","Time","Extension","Load"
"5","(s)","(mm)","(N)"
"6","0.00000","0.00000","0.00028"
"38","0.19200","0.01309","0.00007"
"70","0.38400","0.03217","0.00048"
"102","0.57600","0.04819","0.00032"
"134","0.76800","0.06421","0.00044"
"166","0.96000","0.08030","0.00080"
"198","1.15200","0.09614","0.00083"
"230","1.34400","0.11222","0.00079"
"262","1.53600","0.12825","0.00054"
"294","1.72800","0.14415","0.00053"
"326","1.92000","0.16018","0.00104"
"358","2.11200","0.17620","0.00024"
"390","2.30400","0.19216","0.00023"
"422","2.49600","0.20825","0.00088"
"454","2.68800","0.22421","0.00036"
"486","2.88000","0.24017","0.00080"
"518","3.07200","0.25620","0.00084"
"550","3.26400","0.27222","0.00112"
"582","3.45600","0.28819","0.00118"
"614","3.64800","0.30421","0.00154"
"646","3.84000","0.32017","0.00098"
"678","4.03200","0.33620","0.00182"
"710","4.22400","0.35222","0.00118"
"742","4.41600","0.36818","0.00111"
"774","4.60800","0.38421","0.00113"
"806","4.80000","0.40023","0.00093"
"838","4.99200","0.41614","0.00108"
"870","5.18400","0.43222","0.00175"
"902","5.37600","0.44824","0.00125"
"934","5.56800","0.46421","0.00165"
"966","5.76000","0.48023","0.00135"
"998","5.95200","0.49619","0.00116"
"1030","6.14400","0.51216","0.00129"
"1062","6.33600","0.52818","0.00177"
"1094","6.52800","0.54420","0.00097"
"1126","6.72000","0.56023","0.00171"
"1158","6.91200","0.57625","0.00127"
"1190","7.10400","0.59216","0.00165"
"1222","7.29600","0.60824","0.00114"
"1254","7.48800","0.62420","0.00149"
"1286","7.68000","0.64017","0.00161"
"1318","7.87200","0.65625","0.00175"
"1350","8.06400","0.67215","0.00106"
"1382","8.25600","0.68824","0.00148"
"1414","8.44800","0.70420","0.00103"
"1446","8.64000","0.72016","0.00127"
"1478","8.83200","0.73619","0.00162"
"1510","9.02400","0.75221","0.00115"
"1542","9.21600","0.76818","0.00107"
"1574","9.40800","0.78420","0.00091"
"1606","9.60000","0.80028","0.00133"
"1638","9.79200","0.81613","0.00033"
"1670","9.98400","0.83221","0.00118"
"1702","10.17600","0.84823","0.00104"
"1734","10.36800","0.86414","0.00090"
"1766","10.56000","0.88022","0.00067"
"1798","10.75200","0.89619","0.00134"
"1830","10.94400","0.91221","0.00115"
"1862","11.13600","0.92823","0.00094"
"1894","11.32800","0.94420","0.00086"
"1926","11.52000","0.96022","0.00186"
"1958","11.71200","0.97624","0.00172"
"1990","11.90400","0.99215","0.00162"
"2022","12.09600","1.00823","0.00145"
"2054","12.28800","1.02425","0.00059"
"2086","12.48000","1.04010","0.00175"
"2118","12.67200","1.05624","0.00143"
"2150","12.86400","1.07221","0.00152"
"2182","13.05600","1.08817","0.00091"
"2214","13.24800","1.10419","0.00069"
"2246","13.44000","1.12022","0.00144"
"2278","13.63200","1.13612","0.00137"
"2310","13.82400","1.15220","0.00179"
"2342","14.01600","1.16823","0.00132"
"2374","14.20800","1.18419","0.00158"
"2406","14.40000","1.20022","0.00131"
"2438","14.59200","1.21618","0.00090"
"2470","14.78400","1.23220","0.00150"
"2502","14.97600","1.24823","0.00199"
"2534","15.16800","1.26413","0.00103"
"2566","15.36000","1.28021","0.00142"
"2598","15.55200","1.29624","0.00162"
"2630","15.74400","1.31214","0.00104"
"2662","15.93600","1.32822","0.00228"
"2694","16.12800","1.34425","0.00097"
"2726","16.32000","1.36021","0.00165"
"2758","16.51200","1.37618","0.00168"
"2790","16.70400","1.39220","0.00167"
"2822","16.89600","1.40816","0.00127"
"2854","17.08800","1.42425","0.00164"
"2886","17.28000","1.44015","0.00185"
"2918","17.47200","1.45617","0.00184"
"2950","17.66400","1.47220","0.00166"
"2982","17.85600","1.48816","0.00170"
"3014","18.04800","1.50419","0.00154"
"3046","18.24000","1.52021","0.00187"
"3078","18.43200","1.53617","0.00191"
"3110","18.62400","1.55226","0.00167"
"3142","18.81600","1.56822","0.00214"
"3174","19.00800","1.58412","0.00243"
"3206","19.20000","1.60021","0.00173"
"3238","19.39200","1.61617","0.00137"
"3270","19.58400","1.63219","0.00214"
"3302","19.77600","1.64822","0.00214"
"3334","19.96800","1.66418","0.00144"
"3366","20.16000","1.68027","0.00207"
"3398","20.35200","1.69623","0.00163"
"3430","20.54400","1.71219","0.00249"
"3462","20.73600","1.72828","0.00238"
"3494","20.92800","1.74418","0.00179"
"3526","21.12000","1.76020","0.00223"
"3558","21.31200","1.77623","0.00172"
"3590","21.50400","1.79213","0.00218"
"3622","21.69600","1.80816","0.00248"
"3654","21.88800","1.82430","0.00197"
"3686","22.08000","1.84020","0.00241"
"3718","22.27200","1.85623","0.00240"
"3750","22.46400","1.87219","0.00246"
"3782","22.65600","1.88821","0.00221"
"3814","22.84800","1.90424","0.00183"
"3846","23.04000","1.92026","0.00229"
"3878","23.23200","1.93616","0.00235"
"3910","23.42400","1.95219","0.00248"
"3942","23.61600","1.96821","0.00202"
"3974","23.80800","1.98412","0.00290"
"4006","24.00000","2.00020","0.00257"
"4038","24.19200","2.01622","0.00213"
"4070","24.38400","2.03213","0.00212"
"4102","24.57600","2.04821","0.00263"
"4134","24.76800","2.06423","0.00209"
"4166","24.96000","2.08014","0.00221"
"4198","25.15200","2.09622","0.00243"
"4230","25.34400","2.11219","0.00264"
"4262","25.53600","2.12815","0.00282"
"4294","25.72800","2.14423","0.00293"
"4326","25.92000","2.16020","0.00239"
"4358","26.11200","2.17622","0.00302"
"4390","26.30400","2.19218","0.00299"
"4422","26.49600","2.20815","0.00236"
"4454","26.68800","2.22423","0.00225"
"4486","26.88000","2.24025","0.00252"
"4518","27.07200","2.25622","0.00252"
"4550","27.26400","2.27218","0.00252"
"4582","27.45600","2.28815","0.00247"
"4614","27.64800","2.30423","0.00239"
"4646","27.84000","2.32019","0.00215"
"4678","28.03200","2.33622","0.00278"
"4710","28.22400","2.35224","0.00279"
"4742","28.41600","2.36820","0.00228"
"4774","28.60800","2.38423","0.00261"
"4806","28.80000","2.40019","0.00258"
"4838","28.99200","2.41621","0.00232"
"4870","29.18400","2.43218","0.00281"
"4902","29.37600","2.44826","0.00276"
"4934","29.56800","2.46417","0.00273"
"4966","29.76000","2.48013","0.00297"
"4998","29.95200","2.49621","0.00278"
"5030","30.14400","2.51218","0.00236"
"5062","30.33600","2.52820","0.00238"
"5094","30.52800","2.54416","0.00282"
"5126","30.72000","2.56013","0.00265"
"5158","30.91200","2.57621","0.00325"
"5190","31.10400","2.59224","0.00241"
"5222","31.29600","2.60814","0.00223"
"5254","31.48800","2.62428","0.00242"
"5286","31.68000","2.64019","0.00313"
"5318","31.87200","2.65609","0.00264"
"5350","32.06400","2.67223","0.00271"
"5382","32.25600","2.68826","0.00283"
"5414","32.44800","2.70410","0.00279"
"5446","32.64000","2.72024","0.00323"
"5478","32.83200","2.73621","0.00355"
"5510","33.02400","2.75217","0.00295"
"5542","33.21600","2.76826","0.00299"
"5574","33.40800","2.78416","0.00281"
"5606","33.60000","2.80018","0.00261"
"5638","33.79200","2.81627","0.00293"
"5670","33.98400","2.83217","0.00283"
"5702","34.17600","2.84819","0.00263"
"5734","34.36800","2.86422","0.00276"
"5766","34.56000","2.88018","0.00288"
"5798","34.75200","2.89620","0.00256"
"5830","34.94400","2.91229","0.00314"
"5862","35.13600","2.92819","0.00209"
"5894","35.32800","2.94416","0.00250"
"5926","35.52000","2.96024","0.00336"
"5958","35.71200","2.97620","0.00321"
"5990","35.90400","2.99217","0.00263"
"6022","36.09600","3.00819","0.00253"
"6054","36.28800","3.02421","0.00280"
"6086","36.48000","3.04018","0.00305"
"6118","36.67200","3.05620","0.00293"
"6150","36.86400","3.07217","0.00285"
"6182","37.05600","3.08819","0.00323"
"6214","37.24800","3.10421","0.00268"
"6246","37.44000","3.12024","0.00259"
"6278","37.63200","3.13620","0.00288"
"6310","37.82400","3.15216","0.00323"
"6342","38.01600","3.16819","0.00296"
"6374","38.20800","3.18421","0.00321"
"6406","38.40000","3.20017","0.00280"
"6438","38.59200","3.21620","0.00364"
"6470","38.78400","3.23216","0.00354"
"6502","38.97600","3.24819","0.00315"
"6534","39.16800","3.26421","0.00323"
"6566","39.36000","3.28017","0.00298"
"6598","39.55200","3.29620","0.00318"
"6630","39.74400","3.31222","0.00335"
"6662","39.93600","3.32812","0.00318"
"6694","40.12800","3.34427","0.00365"
"6726","40.32000","3.36017","0.00353"
"6758","40.51200","3.37614","0.00301"
"6790","40.70400","3.39228","0.00345"
"6822","40.89600","3.40818","0.00306"
"6854","41.08800","3.42421","0.00335"
"6886","41.28000","3.44023","0.00351"
"6918","41.47200","3.45613","0.00313"
"6950","41.66400","3.47222","0.00330"
"6982","41.85600","3.48824","0.00380"
"7014","42.04800","3.50420","0.00349"
"7046","42.24000","3.52023","0.00313"
"7078","42.43200","3.53625","0.00362"
"7110","42.62400","3.55216","0.00336"
"7142","42.81600","3.56818","0.00395"
"7174","43.00800","3.58420","0.00350"
"7206","43.20000","3.60017","0.00316"
"7238","43.39200","3.61619","0.00359"
"7270","43.58400","3.63221","0.00376"
"7302","43.77600","3.64818","0.00358"
"7334","43.96800","3.66426","0.00342"
"7366","44.16000","3.68022","0.00373"
"7398","44.35200","3.69619","0.00339"
"7430","44.54400","3.71221","0.00383"
"7462","44.73600","3.72812","0.00361"
"7494","44.92800","3.74420","0.00395"
"7526","45.12000","3.76022","0.00359"
"7558","45.31200","3.77613","0.00315"
"7590","45.50400","3.79221","0.00357"
"7622","45.69600","3.80817","0.00399"
"7654","45.88800","3.82414","0.00369"
"7686","46.08000","3.84022","0.00352"
"7718","46.27200","3.85625","0.00329"
"7750","46.46400","3.87215","0.00325"
"7782","46.65600","3.88817","0.00334"
"7814","46.84800","3.90420","0.00336"
"7846","47.04000","3.92022","0.00365"
"7878","47.23200","3.93618","0.00319"
"7910","47.42400","3.95221","0.00353"
"7942","47.61600","3.96817","0.00371"
"7974","47.80800","3.98420","0.00343"
"8006","48.00000","4.00016","0.00306"
"8038","48.19200","4.01624","0.00376"
"8070","48.38400","4.03221","0.00377"
"8102","48.57600","4.04823","0.00345"
"8134","48.76800","4.06419","0.00378"
"8166","48.96000","4.08016","0.00317"
"8198","49.15200","4.09618","0.00339"
"8230","49.34400","4.11214","0.00386"
"8262","49.53600","4.12817","0.00361"
"8294","49.72800","4.14419","0.00383"
"8326","49.92000","4.16022","0.00378"
"8358","50.11200","4.17618","0.00384"
"8390","50.30400","4.19226","0.00387"
"8422","50.49600","4.20823","0.00366"
"8454","50.68800","4.22419","0.00386"
"8486","50.88000","4.24015","0.00381"
"8518","51.07200","4.25618","0.00424"
"8550","51.26400","4.27214","0.00395"
"8582","51.45600","4.28823","0.00385"
"8614","51.64800","4.30419","0.00380"
"8646","51.84000","4.32015","0.00386"
"8678","52.03200","4.33624","0.00378"
"8710","52.22400","4.35220","0.00351"
"8742","52.41600","4.36816","0.00422"
"8774","52.60800","4.38425","0.00294"
"8806","52.80000","4.40015","0.00410"
"8838","52.99200","4.41617","0.00364"
"8870","53.18400","4.43226","0.00325"
"8902","53.37600","4.44816","0.00423"
"8934","53.56800","4.46425","0.00373"
"8966","53.76000","4.48027","0.00419"
"8998","53.95200","4.49617","0.00381"
"9030","54.14400","4.51226","0.00352"
"9062","54.33600","4.52822","0.00354"
"9094","54.52800","4.54418","0.00352"
"9126","54.72000","4.56021","0.00397"
"9158","54.91200","4.57617","0.00382"
"9190","55.10400","4.59219","0.00362"
"9222","55.29600","4.60822","0.00440"
"9254","55.48800","4.62418","0.00365"
"9286","55.68000","4.64021","0.00428"
"9318","55.87200","4.65617","0.00370"
"9350","56.06400","4.67219","0.00359"
"9382","56.25600","4.68822","0.00366"
"9414","56.44800","4.70424","0.00429"
"9446","56.64000","4.72020","0.00412"
"9478","56.83200","4.73623","0.00397"
"9510","57.02400","4.75219","0.00386"
"9542","57.21600","4.76822","0.00376"
"9574","57.40800","4.78418","0.00404"
"9606","57.60000","4.80020","0.00407"
"9638","57.79200","4.81623","0.00409"
"9670","57.98400","4.83219","0.00371"
"9702","58.17600","4.84815","0.00393"
"9734","58.36800","4.86424","0.00394"
"9766","58.56000","4.88026","0.00333"
"9798","58.75200","4.89611","0.00398"
"9830","58.94400","4.91225","0.00397"
"9862","59.13600","4.92821","0.00372"
"9894","59.32800","4.94418","0.00399"
"9926","59.52000","4.96026","0.00430"
"9958","59.71200","4.97616","0.00398"
"9990","59.90400","4.99219","0.00418"
"10022","60.09600","5.00821","0.00398"
"10054","60.28800","5.02417","0.00392"
"10086","60.48000","5.04026","0.00396"
"10118","60.67200","5.05622","0.00389"
"10150","60.86400","5.07213","0.00418"
"10182","61.05600","5.08821","0.00404"
"10214","61.24800","5.10423","0.00454"
"10246","61.44000","5.12014","0.00418"
"10278","61.63200","5.13622","0.00336"
"10310","61.82400","5.15224","0.00388"
"10342","62.01600","5.16809","0.00414"
"10374","62.20800","5.18423","0.00405"
"10406","62.40000","5.20019","0.00467"
"10438","62.59200","5.21616","0.00399"
"10470","62.78400","5.23218","0.00419"
"10502","62.97600","5.24821","0.00366"
"10534","63.16800","5.26417","0.00448"
"10566","63.36000","5.28025","0.00428"
"10598","63.55200","5.29622","0.00385"
"10630","63.74400","5.31218","0.00380"
"10662","63.93600","5.32820","0.00396"
"10694","64.12800","5.34417","0.00412"
"10726","64.32000","5.36019","0.00417"
"10758","64.51200","5.37621","0.00403"
"10790","64.70400","5.39212","0.00368"
"10822","64.89600","5.40820","0.00372"
"10854","65.08800","5.42423","0.00414"
"10886","65.28000","5.44019","0.00429"
"10918","65.47200","5.45621","0.00415"
"10950","65.66400","5.47224","0.00320"
"10982","65.85600","5.48820","0.00345"
"11014","66.04800","5.50422","0.00350"
"11046","66.24000","5.52013","0.00353"
"11078","66.43200","5.53621","0.00316"
"11110","66.62400","5.55224","0.00373"
"11142","66.81600","5.56814","0.00364"
"11174","67.00800","5.58422","0.00416"
"11206","67.20000","5.60019","0.00390"
"11238","67.39200","5.61615","0.00352"
"11270","67.58400","5.63223","0.00341"
"11302","67.77600","5.64820","0.00405"
"11334","67.96800","5.66422","0.00372"
"11366","68.16000","5.68019","0.00342"
"11398","68.35200","5.69615","0.00385"
"11430","68.54400","5.71223","0.00336"
"11462","68.73600","5.72820","0.00382"
"11494","68.92800","5.74416","0.00368"
"11526","69.12000","5.76024","0.00393"
"11558","69.31200","5.77621","0.00359"
"11590","69.50400","5.79217","0.00436"
"11622","69.69600","5.80825","0.00414"
"11654","69.88800","5.82422","0.00387"
"11686","70.08000","5.84012","0.00372"
"11718","70.27200","5.85621","0.00430"
"11750","70.46400","5.87223","0.00363"
"11782","70.65600","5.88813","0.00347"
"11814","70.84800","5.90422","0.00400"
"11846","71.04000","5.92018","0.00346"
"11878","71.23200","5.93620","0.00392"
"11910","71.42400","5.95217","0.00387"
"11942","71.61600","5.96825","0.00360"
"11974","71.80800","5.98422","0.00373"
"12006","72.00000","6.00024","0.00392"
"12038","72.19200","6.01620","0.00435"
"12070","72.38400","6.03223","0.00360"
"12102","72.57600","6.04819","0.00398"
"12134","72.76800","6.06415","0.00420"
"12166","72.96000","6.08024","0.00399"
"12198","73.15200","6.09614","0.00437"
"12230","73.34400","6.11216","0.00373"
"12262","73.53600","6.12825","0.00400"
"12294","73.72800","6.14415","0.00373"
"12326","73.92000","6.16024","0.00391"
"12358","74.11200","6.17620","0.00407"
"12390","74.30400","6.19216","0.00407"
"12422","74.49600","6.20825","0.00420"
"12454","74.68800","6.22421","0.00427"
"12486","74.88000","6.24011","0.00459"
"12518","75.07200","6.25620","0.00420"
"12550","75.26400","6.27222","0.00426"
"12582","75.45600","6.28819","0.00416"
"12614","75.64800","6.30421","0.00368"
"12646","75.84000","6.32023","0.00425"
"12678","76.03200","6.33614","0.00376"
"12710","76.22400","6.35216","0.00384"
"12742","76.41600","6.36824","0.00427"
"12774","76.60800","6.38421","0.00440"
"12806","76.80000","6.40023","0.00465"
"12838","76.99200","6.41619","0.00460"
"12870","77.18400","6.43216","0.00456"
"12902","77.37600","6.44818","0.00448"
"12934","77.56800","6.46421","0.00421"
"12966","77.76000","6.48017","0.00439"
"12998","77.95200","6.49625","0.00391"
"13030","78.14400","6.51222","0.00456"
"13062","78.33600","6.52824","0.00465"
"13094","78.52800","6.54420","0.00385"
"13126","78.72000","6.56023","0.00380"
"13158","78.91200","6.57619","0.00419"
"13190","79.10400","6.59222","0.00450"
"13222","79.29600","6.60818","0.00428"
"13254","79.48800","6.62420","0.00443"
"13286","79.68000","6.64023","0.00449"
"13318","79.87200","6.65619","0.00472"
"13350","80.06400","6.67221","0.00456"
"13382","80.25600","6.68818","0.00430"
"13414","80.44800","6.70426","0.00403"
"13446","80.64000","6.72022","0.00454"
"13478","80.83200","6.73613","0.00374"
"13510","81.02400","6.75227","0.00447"
"13542","81.21600","6.76818","0.00491"
"13574","81.40800","6.78414","0.00495"
"13606","81.60000","6.80022","0.00433"
"13638","81.79200","6.81619","0.00482"
"13670","81.98400","6.83215","0.00486"
"13702","82.17600","6.84817","0.00411"
"13734","82.36800","6.86414","0.00411"
"13766","82.56000","6.88022","0.00441"
"13798","82.75200","6.89624","0.00474"
"13830","82.94400","6.91215","0.00461"
"13862","83.13600","6.92823","0.00429"
"13894","83.32800","6.94420","0.00428"
"13926","83.52000","6.96016","0.00511"
"13958","83.71200","6.97618","0.00475"
"13990","83.90400","6.99221","0.00445"
"14022","84.09600","7.00811","0.00462"
"14054","84.28800","7.02425","0.00474"
"14086","84.48000","7.04022","0.00429"
"14118","84.67200","7.05618","0.00389"
"14150","84.86400","7.07221","0.00503"
"14182","85.05600","7.08823","0.00486"
"14214","85.24800","7.10419","0.00467"
"14246","85.44000","7.12022","0.00442"
"14278","85.63200","7.13618","0.00482"
"14310","85.82400","7.15214","0.00411"
"14342","86.01600","7.16823","0.00461"
"14374","86.20800","7.18413","0.00411"
"14406","86.40000","7.20021","0.00478"
"14438","86.59200","7.21624","0.00446"
"14470","86.78400","7.23220","0.00407"
"14502","86.97600","7.24823","0.00496"
"14534","87.16800","7.26419","0.00495"
"14566","87.36000","7.28021","0.00457"
"14598","87.55200","7.29624","0.00465"
"14630","87.74400","7.31220","0.00462"
"14662","87.93600","7.32816","0.00488"
"14694","88.12800","7.34419","0.00480"
"14726","88.32000","7.36021","0.00471"
"14758","88.51200","7.37624","0.00469"
"14790","88.70400","7.39220","0.00494"
"14822","88.89600","7.40822","0.00502"
"14854","89.08800","7.42419","0.00520"
"14886","89.28000","7.44015","0.00455"
"14918","89.47200","7.45617","0.00463"
"14950","89.66400","7.47220","0.00525"
"14982","89.85600","7.48816","0.00484"
"15014","90.04800","7.50418","0.00458"
"15046","90.24000","7.52015","0.00455"
"15078","90.43200","7.53617","0.00515"
"15110","90.62400","7.55220","0.00472"
"15142","90.81600","7.56822","0.00489"
"15174","91.00800","7.58418","0.00474"
"15206","91.20000","7.60021","0.00521"
"15238","91.39200","7.61623","0.00471"
"15270","91.58400","7.63219","0.00510"
"15302","91.77600","7.64828","0.00529"
"15334","91.96800","7.66418","0.00468"
"15366","92.16000","7.68009","0.00546"
"15398","92.35200","7.69623","0.00497"
"15430","92.54400","7.71219","0.00476"
"15462","92.73600","7.72816","0.00494"
"15494","92.92800","7.74424","0.00482"
"15526","93.12000","7.76020","0.00493"
"15558","93.31200","7.77623","0.00505"
"15590","93.50400","7.79225","0.00512"
"15622","93.69600","7.80816","0.00475"
"15654","93.88800","7.82412","0.00505"
"15686","94.08000","7.84026","0.00550"
"15718","94.27200","7.85616","0.00521"
"15750","94.46400","7.87219","0.00482"
"15782","94.65600","7.88821","0.00484"
"15814","94.84800","7.90418","0.00556"
"15846","95.04000","7.92020","0.00530"
"15878","95.23200","7.93622","0.00478"
"15910","95.42400","7.95219","0.00536"
"15942","95.61600","7.96821","0.00458"
"15974","95.80800","7.98423","0.00565"
"16006","96.00000","8.00020","0.00529"
"16038","96.19200","8.01622","0.00508"
"16070","96.38400","8.03219","0.00549"
"16102","96.57600","8.04815","0.00541"
"16134","96.76800","8.06423","0.00538"
"16166","96.96000","8.08020","0.00510"
"16198","97.15200","8.09622","0.00508"
"16230","97.34400","8.11218","0.00529"
"16262","97.53600","8.12821","0.00486"
"16294","97.72800","8.14423","0.00559"
"16326","97.92000","8.16025","0.00517"
"16358","98.11200","8.17622","0.00535"
"16390","98.30400","8.19218","0.00508"
"16422","98.49600","8.20815","0.00542"
"16454","98.68800","8.22417","0.00541"
"16486","98.88000","8.24025","0.00530"
"16518","99.07200","8.25616","0.00431"
"16550","99.26400","8.27218","0.00570"
"16582","99.45600","8.28820","0.00522"
"16614","99.64800","8.30417","0.00496"
"16646","99.84000","8.32019","0.00506"
"16678","100.03200","8.33622","0.00466"
"16710","100.22400","8.35212","0.00490"
"16742","100.41600","8.36826","0.00497"
"16774","100.60800","8.38417","0.00496"
"16806","100.80000","8.40019","0.00508"
"16838","100.99200","8.41621","0.00518"
"16870","101.18400","8.43218","0.00475"
"16902","101.37600","8.44820","0.00470"
"16934","101.56800","8.46416","0.00495"
"16966","101.76000","8.48013","0.00510"
"16998","101.95200","8.49621","0.00496"
"17030","102.14400","8.51224","0.00476"
"17062","102.33600","8.52820","0.00448"
"17094","102.52800","8.54416","0.00531"
"17126","102.72000","8.56019","0.00486"
"17158","102.91200","8.57615","0.00473"
"17190","103.10400","8.59223","0.00523"
"17222","103.29600","8.60820","0.00486"
"17254","103.48800","8.62416","0.00516"
"17286","103.68000","8.64025","0.00505"
"17318","103.87200","8.65621","0.00499"
"17350","104.06400","8.67217","0.00506"
"17382","104.25600","8.68826","0.00484"
"17414","104.44800","8.70422","0.00469"
"17446","104.64000","8.72018","0.00491"
"17478","104.83200","8.73627","0.00502"
"17510","105.02400","8.75211","0.00520"
"17542","105.21600","8.76819","0.00445"
"17574","105.40800","8.78422","0.00482"
"17606","105.60000","8.80012","0.00482"
"17638","105.79200","8.81621","0.00489"
"17670","105.98400","8.83223","0.00514"
"17702","106.17600","8.84819","0.00483"
"17734","106.36800","8.86428","0.00532"
"17766","106.56000","8.88018","0.00467"
"17798","106.75200","8.89614","0.00540"
"17830","106.94400","8.91217","0.00475"
"17862","107.13600","8.92819","0.00551"
"17894","107.32800","8.94416","0.00501"
"17926","107.52000","8.96024","0.00548"
"17958","107.71200","8.97620","0.00455"
"17990","107.90400","8.99223","0.00487"
"18022","108.09600","9.00825","0.00514"
"18054","108.28800","9.02415","0.00483"
"18086","108.48000","9.04024","0.00485"
"18118","108.67200","9.05620","0.00503"
"18150","108.86400","9.07222","0.00445"
"18182","109.05600","9.08819","0.00460"
"18214","109.24800","9.10421","0.00435"
"18246","109.44000","9.12024","0.00494"
"18278","109.63200","9.13620","0.00476"
"18310","109.82400","9.15216","0.00506"
"18342","110.01600","9.16819","0.00485"
"18374","110.20800","9.18421","0.00523"
"18406","110.40000","9.20017","0.00547"
"18438","110.59200","9.21626","0.00494"
"18470","110.78400","9.23222","0.00463"
"18502","110.97600","9.24813","0.00518"
"18534","111.16800","9.26427","0.00483"
"18566","111.36000","9.28017","0.00578"
"18598","111.55200","9.29620","0.00506"
"18630","111.74400","9.31222","0.00458"
"18662","111.93600","9.32818","0.00508"
"18694","112.12800","9.34421","0.00515"
"18726","112.32000","9.36023","0.00516"
"18758","112.51200","9.37619","0.00568"
"18790","112.70400","9.39222","0.00510"
"18822","112.89600","9.40824","0.00550"
"18854","113.08800","9.42415","0.00494"
"18886","113.28000","9.44023","0.00553"
"18918","113.47200","9.45625","0.00523"
"18950","113.66400","9.47210","0.00466"
"18982","113.85600","9.48824","0.00552"
"19014","114.04800","9.50426","0.00525"
"19046","114.24000","9.52017","0.00579"
"19078","114.43200","9.53625","0.00532"
"19110","114.62400","9.55222","0.00550"
"19142","114.81600","9.56818","0.00553"
"19174","115.00800","9.58420","0.00554"
"19206","115.20000","9.60017","0.00502"
"19238","115.39200","9.61625","0.00593"
"19270","115.58400","9.63215","0.00545"
"19302","115.77600","9.64818","0.00526"
"19334","115.96800","9.66420","0.00572"
"19366","116.16000","9.68022","0.00565"
"19398","116.35200","9.69619","0.00542"
"19430","116.54400","9.71221","0.00599"
"19462","116.73600","9.72824","0.00619"
"19494","116.92800","9.74420","0.00539"
"19526","117.12000","9.76016","0.00640"
"19558","117.31200","9.77625","0.00657"
"19590","117.50400","9.79221","0.00684"
"19622","117.69600","9.80817","0.00649"
"19654","117.88800","9.82420","0.00646"
"19686","118.08000","9.84016","0.00621"
"19718","118.27200","9.85624","0.00610"
"19750","118.46400","9.87221","0.00650"
"19782","118.65600","9.88823","0.00688"
"19814","118.84800","9.90420","0.00638"
"19846","119.04000","9.92016","0.00679"
"19878","119.23200","9.93624","0.00611"
"19910","119.42400","9.95221","0.00700"
"19942","119.61600","9.96817","0.00624"
"19974","119.80800","9.98419","0.00712"
"20006","120.00000","10.00016","0.00636"
"20038","120.19200","10.01624","0.00717"
"20070","120.38400","10.03221","0.00742"
"20102","120.57600","10.04817","0.00749"
"20134","120.76800","10.06419","0.00718"
"20166","120.96000","10.08022","0.00766"
"20198","121.15200","10.09618","0.00731"
"20230","121.34400","10.11220","0.00794"
"20262","121.53600","10.12823","0.00751"
"20294","121.72800","10.14413","0.00735"
"20326","121.92000","10.16022","0.00708"
"20358","122.11200","10.17624","0.00684"
"20390","122.30400","10.19208","0.00731"
"20422","122.49600","10.20828","0.00749"
"20454","122.68800","10.22419","0.00764"
"20486","122.88000","10.24015","0.00719"
"20518","123.07200","10.25624","0.00741"
"20550","123.26400","10.27220","0.00743"
"20582","123.45600","10.28822","0.00773"
"20614","123.64800","10.30419","0.00811"
"20646","123.84000","10.32015","0.00750"
"20678","124.03200","10.33624","0.00669"
"20710","124.22400","10.35220","0.00704"
"20742","124.41600","10.36816","0.00725"
"20774","124.60800","10.38419","0.00765"
"20806","124.80000","10.40021","0.00732"
"20838","124.99200","10.41611","0.00726"
"20870","125.18400","10.43220","0.00715"
"20902","125.37600","10.44822","0.00793"
"20934","125.56800","10.46418","0.00760"
"20966","125.76000","10.48021","0.00759"
"20998","125.95200","10.49623","0.00763"
"21030","126.14400","10.51220","0.00775"
"21062","126.33600","10.52822","0.00731"
"21094","126.52800","10.54418","0.00843"
"21126","126.72000","10.56021","0.00776"
"21158","126.91200","10.57623","0.00801"
"21190","127.10400","10.59219","0.00832"
"21222","127.29600","10.60822","0.00801"
"21254","127.48800","10.62418","0.00770"
"21286","127.68000","10.64015","0.00845"
"21318","127.87200","10.65623","0.00791"
"21350","128.06400","10.67225","0.00840"
"21382","128.25600","10.68816","0.00779"
"21414","128.44800","10.70418","0.00816"
"21446","128.64000","10.72020","0.00838"
"21478","128.83200","10.73611","0.00839"
"21510","129.02400","10.75225","0.00825"
"21542","129.21600","10.76821","0.00847"
"21574","129.40800","10.78424","0.00874"
"21606","129.60000","10.80020","0.00852"
"21638","129.79200","10.81623","0.00852"
"21670","129.98400","10.83219","0.00892"
"21702","130.17600","10.84821","0.00892"
"21734","130.36800","10.86418","0.00852"
"21766","130.56000","10.88014","0.00847"
"21798","130.75200","10.89616","0.00918"
"21830","130.94400","10.91213","0.00925"
"21862","131.13600","10.92821","0.00893"
"21894","131.32800","10.94423","0.00941"
"21926","131.52000","10.96020","0.00908"
"21958","131.71200","10.97622","0.00937"
"21990","131.90400","10.99219","0.01001"
"22022","132.09600","11.00821","0.01025"
"22054","132.28800","11.02423","0.00975"
"22086","132.48000","11.04020","0.00952"
"22118","132.67200","11.05622","0.00903"
"22150","132.86400","11.07218","0.00922"
"22182","133.05600","11.08815","0.00912"
"22214","133.24800","11.10423","0.00892"
"22246","133.44000","11.12020","0.00911"
"22278","133.63200","11.13616","0.00910"
"22310","133.82400","11.15224","0.00956"
"22342","134.01600","11.16821","0.00907"
"22374","134.20800","11.18423","0.00898"
"22406","134.40000","11.20025","0.00967"
"22438","134.59200","11.21622","0.00992"
"22470","134.78400","11.23218","0.00948"
"22502","134.97600","11.24821","0.01001"
"22534","135.16800","11.26417","0.00966"
"22566","135.36000","11.28019","0.00940"
"22598","135.55200","11.29628","0.00988"
"22630","135.74400","11.31212","0.01012"
"22662","135.93600","11.32820","0.00973"
"22694","136.12800","11.34423","0.01042"
"22726","136.32000","11.36013","0.00995"
"22758","136.51200","11.37621","0.01015"
"22790","136.70400","11.39218","0.01047"
"22822","136.89600","11.40814","0.01103"
"22854","137.08800","11.42423","0.01063"
"22886","137.28000","11.44013","0.01134"
"22918","137.47200","11.45615","0.01153"
"22950","137.66400","11.47224","0.01134"
"22982","137.85600","11.48820","0.01054"
"23014","138.04800","11.50416","0.01171"
"23046","138.24000","11.52019","0.01155"
"23078","138.43200","11.53615","0.01121"
"23110","138.62400","11.55223","0.01177"
"23142","138.81600","11.56820","0.01211"
"23174","139.00800","11.58416","0.01228"
"23206","139.20000","11.60019","0.01186"
"23238","139.39200","11.61621","0.01231"
"23270","139.58400","11.63223","0.01276"
"23302","139.77600","11.64820","0.01307"
"23334","139.96800","11.66422","0.01314"
"23366","140.16000","11.68018","0.01362"
"23398","140.35200","11.69621","0.01399"
"23430","140.54400","11.71217","0.01375"
"23462","140.73600","11.72826","0.01334"
"23494","140.92800","11.74422","0.01332"
"23526","141.12000","11.76018","0.01439"
"23558","141.31200","11.77621","0.01377"
"23590","141.50400","11.79217","0.01434"
"23622","141.69600","11.80819","0.01373"
"23654","141.88800","11.82422","0.01350"
"23686","142.08000","11.84012","0.01401"
"23718","142.27200","11.85620","0.01449"
"23750","142.46400","11.87223","0.01466"
"23782","142.65600","11.88819","0.01491"
"23814","142.84800","11.90422","0.01481"
"23846","143.04000","11.92024","0.01540"
"23878","143.23200","11.93614","0.01502"
"23910","143.42400","11.95229","0.01487"
"23942","143.61600","11.96819","0.01557"
"23974","143.80800","11.98415","0.01548"
"24006","144.00000","12.00024","0.01437"
"24038","144.19200","12.01620","0.01534"
"24070","144.38400","12.03217","0.01490"
"24102","144.57600","12.04825","0.01538"
"24134","144.76800","12.06421","0.01563"
"24166","144.96000","12.08018","0.01523"
"24198","145.15200","12.09626","0.01566"
"24230","145.34400","12.11216","0.01615"
"24262","145.53600","12.12813","0.01581"
"24294","145.72800","12.14427","0.01679"
"24326","145.92000","12.16018","0.01730"
"24358","146.11200","12.17620","0.01713"
"24390","146.30400","12.19222","0.01716"
"24422","146.49600","12.20813","0.01733"
"24454","146.68800","12.22421","0.01769"
"24486","146.88000","12.24023","0.01762"
"24518","147.07200","12.25620","0.01809"
"24550","147.26400","12.27216","0.01875"
"24582","147.45600","12.28824","0.01845"
"24614","147.64800","12.30421","0.01844"
"24646","147.84000","12.32023","0.01880"
"24678","148.03200","12.33614","0.01939"
"24710","148.22400","12.35222","0.01895"
"24742","148.41600","12.36818","0.01918"
"24774","148.60800","12.38421","0.02022"
"24806","148.80000","12.40017","0.01951"
"24838","148.99200","12.41619","0.02048"
"24870","149.18400","12.43216","0.02045"
"24902","149.37600","12.44824","0.02041"
"24934","149.56800","12.46420","0.02047"
"24966","149.76000","12.48023","0.02047"
"24998","149.95200","12.49619","0.02073"
"25030","150.14400","12.51216","0.01874"
"25062","150.33600","12.52818","0.01426"
"25094","150.52800","12.54420","0.01332"
"25126","150.72000","12.56017","0.01419"
"25158","150.91200","12.57625","0.01416"
"25190","151.10400","12.59221","0.01424"
"25222","151.29600","12.60818","0.01480"
"25254","151.48800","12.62420","0.01485"
"25286","151.68000","12.64023","0.01511"
"25318","151.87200","12.65613","0.01480"
"25350","152.06400","12.67221","0.01527"
"25382","152.25600","12.68818","0.01532"
"25414","152.44800","12.70414","0.01529"
"25446","152.64000","12.72028","0.01606"
"25478","152.83200","12.73619","0.01537"
"25510","153.02400","12.75221","0.01582"
"25542","153.21600","12.76824","0.01490"
"25574","153.40800","12.78414","0.01582"
"25606","153.60000","12.80022","0.01595"
"25638","153.79200","12.81625","0.01560"
"25670","153.98400","12.83215","0.01598"
"25702","154.17600","12.84823","0.01534"
"25734","154.36800","12.86420","0.01564"
"25766","154.56000","12.88010","0.01616"
"25798","154.75200","12.89624","0.01600"
"25830","154.94400","12.91221","0.01650"
"25862","155.13600","12.92811","0.01721"
"25894","155.32800","12.94425","0.01667"
"25926","155.52000","12.96022","0.01632"
"25958","155.71200","12.97618","0.01725"
"25990","155.90400","12.99221","0.01777"
"26022","156.09600","13.00823","0.01858"
"26054","156.28800","13.02413","0.01829"
"26086","156.48000","13.04022","0.01890"
"26118","156.67200","13.05612","0.01954"
"26150","156.86400","13.07220","0.01822"
"26182","157.05600","13.08823","0.01896"
"26214","157.24800","13.10419","0.01865"
"26246","157.44000","13.12022","0.01948"
"26278","157.63200","13.13624","0.01964"
"26310","157.82400","13.15220","0.02026"
"26342","158.01600","13.16817","0.02072"
"26374","158.20800","13.18419","0.02032"
"26406","158.40000","13.20015","0.02124"
"26438","158.59200","13.21618","0.02120"
"26470","158.78400","13.23220","0.02157"
"26502","158.97600","13.24817","0.02095"
"26534","159.16800","13.26425","0.02135"
"26566","159.36000","13.28015","0.02170"
"26598","159.55200","13.29624","0.02189"
"26630","159.74400","13.31220","0.02264"
"26662","159.93600","13.32816","0.02249"
"26694","160.12800","13.34425","0.02356"
"26726","160.32000","13.36021","0.02307"
"26758","160.51200","13.37617","0.02303"
"26790","160.70400","13.39220","0.02342"
"26822","160.89600","13.40816","0.02443"
"26854","161.08800","13.42419","0.02423"
"26886","161.28000","13.44021","0.02433"
"26918","161.47200","13.45617","0.02496"
"26950","161.66400","13.47226","0.02507"
"26982","161.85600","13.48822","0.02600"
"27014","162.04800","13.50412","0.02567"
"27046","162.24000","13.52021","0.02589"
"27078","162.43200","13.53623","0.02648"
"27110","162.62400","13.55220","0.02662"
"27142","162.81600","13.56822","0.02684"
"27174","163.00800","13.58424","0.02740"
"27206","163.20000","13.60015","0.02713"
"27238","163.39200","13.61623","0.02723"
"27270","163.58400","13.63219","0.02805"
"27302","163.77600","13.64816","0.02802"
"27334","163.96800","13.66424","0.02821"
"27366","164.16000","13.68015","0.02834"
"27398","164.35200","13.69617","0.02816"
"27430","164.54400","13.71225","0.02871"
"27462","164.73600","13.72816","0.02859"
"27494","164.92800","13.74424","0.02919"
"27526","165.12000","13.76026","0.02904"
"27558","165.31200","13.77617","0.02909"
"27590","165.50400","13.79225","0.02984"
"27622","165.69600","13.80821","0.03015"
"27654","165.88800","13.82418","0.03043"
"27686","166.08000","13.84020","0.03043"
"27718","166.27200","13.85623","0.03087"
"27750","166.46400","13.87213","0.03093"
"27782","166.65600","13.88821","0.03131"
"27814","166.84800","13.90418","0.03156"
"27846","167.04000","13.92020","0.03128"
"27878","167.23200","13.93622","0.03137"
"27910","167.42400","13.95219","0.03138"
"27942","167.61600","13.96821","0.03153"
"27974","167.80800","13.98423","0.03175"
"28006","168.00000","14.00020","0.03213"
"28038","168.19200","14.01622","0.03160"
"28070","168.38400","14.03225","0.03198"
"28102","168.57600","14.04821","0.03227"
"28134","168.76800","14.06423","0.03189"
"28166","168.96000","14.08026","0.03264"
"28198","169.15200","14.09622","0.03276"
"28230","169.34400","14.11218","0.03312"
"28262","169.53600","14.12821","0.03339"
"28294","169.72800","14.14417","0.03320"
"28326","169.92000","14.16020","0.03362"
"28358","170.11200","14.17622","0.03340"
"28390","170.30400","14.19218","0.03329"
"28422","170.49600","14.20821","0.03401"
"28454","170.68800","14.22417","0.03413"
"28486","170.88000","14.24025","0.03407"
"28518","171.07200","14.25616","0.03488"
"28550","171.26400","14.27218","0.03444"
"28582","171.45600","14.28826","0.03480"
"28614","171.64800","14.30417","0.03503"
"28646","171.84000","14.32019","0.03492"
"28678","172.03200","14.33622","0.03525"
"28710","172.22400","14.35218","0.03532"
"28742","172.41600","14.36820","0.03540"
"28774","172.60800","14.38423","0.03553"
"28806","172.80000","14.40019","0.03587"
"28838","172.99200","14.41621","0.03636"
"28870","173.18400","14.43224","0.03651"
"28902","173.37600","14.44814","0.03676"
"28934","173.56800","14.46422","0.03685"
"28966","173.76000","14.48025","0.03753"
"28998","173.95200","14.49609","0.03770"
"29030","174.14400","14.51230","0.03846"
"29062","174.33600","14.52820","0.03865"
"29094","174.52800","14.54416","0.03905"
"29126","174.72000","14.56019","0.03953"
"29158","174.91200","14.57621","0.04022"
"29190","175.10400","14.59217","0.04090"
"29222","175.29600","14.60820","0.04123"
"29254","175.48800","14.62416","0.04214"
"29286","175.68000","14.64019","0.04264"
"29318","175.87200","14.65621","0.04401"
"29350","176.06400","14.67217","0.04450"
"29382","176.25600","14.68820","0.04475"
"29414","176.44800","14.70422","0.04574"
"29446","176.64000","14.72018","0.04610"
"29478","176.83200","14.73621","0.04657"
"29510","177.02400","14.75223","0.04761"
"29542","177.21600","14.76814","0.04847"
"29574","177.40800","14.78422","0.04996"
"29606","177.60000","14.80024","0.05107"
"29638","177.79200","14.81614","0.05132"
"29670","177.98400","14.83223","0.05319"
"29702","178.17600","14.84819","0.05347"
"29734","178.36800","14.86422","0.05490"
"29766","178.56000","14.88024","0.05615"
"29798","178.75200","14.89620","0.05689"
"29830","178.94400","14.91229","0.05757"
"29862","179.13600","14.92825","0.05732"
"29894","179.32800","14.94410","0.04692"
"29926","179.52000","14.96024","0.04486"
"29958","179.71200","14.97620","0.04276"
"29990","179.90400","14.99217","0.04018"
"30022","180.09600","15.00825","0.04035"
"30054","180.28800","15.02415","0.04064"
"30086","180.48000","15.04018","0.04187"
"30118","180.67200","15.05620","0.04279"
"30150","180.86400","15.07217","0.04304"
"30182","181.05600","15.08819","0.04427"
"30214","181.24800","15.10421","0.04392"
"30246","181.44000","15.12018","0.04454"
"30278","181.63200","15.13620","0.04574"
"30310","181.82400","15.15216","0.04561"
"30342","182.01600","15.16819","0.04685"
"30374","182.20800","15.18421","0.04729"
"30406","182.40000","15.20017","0.04680"
"30438","182.59200","15.21620","0.04856"
"30470","182.78400","15.23222","0.04896"
"30502","182.97600","15.24819","0.04943"
"30534","183.16800","15.26421","0.05079"
"30566","183.36000","15.28023","0.05077"
"30598","183.55200","15.29614","0.05183"
"30630","183.74400","15.31222","0.05226"
"30662","183.93600","15.32824","0.05280"
"30694","184.12800","15.34421","0.05417"
"30726","184.32000","15.36023","0.05427"
"30758","184.51200","15.37619","0.05294"
"30790","184.70400","15.39210","0.05452"
"30822","184.89600","15.40824","0.05224"
"30854","185.08800","15.42415","0.05279"
"30886","185.28000","15.44017","0.05262"
"30918","185.47200","15.45625","0.05226"
"30950","185.66400","15.47216","0.05342"
"30982","185.85600","15.48818","0.05394"
"31014","186.04800","15.50420","0.05512"
"31046","186.24000","15.52011","0.05523"
"31078","186.43200","15.53625","0.05609"
"31110","186.62400","15.55222","0.05667"
"31142","186.81600","15.56818","0.05783"
"31174","187.00800","15.58420","0.05847"
"31206","187.20000","15.60029","0.05938"
"31238","187.39200","15.61607","0.05811"
"31270","187.58400","15.63221","0.05861"
"31302","187.77600","15.64818","0.05842"
"31334","187.96800","15.66414","0.05973"
"31366","188.16000","15.68022","0.05989"
"31398","188.35200","15.69619","0.06037"
"31430","188.54400","15.71215","0.06115"
"31462","188.73600","15.72823","0.06135"
"31494","188.92800","15.74420","0.06243"
"31526","189.12000","15.76016","0.06264"
"31558","189.31200","15.77625","0.06297"
"31590","189.50400","15.79215","0.06342"
"31622","189.69600","15.80817","0.06402"
"31654","189.88800","15.82420","0.06458"
"31686","190.08000","15.84016","0.06499"
"31718","190.27200","15.85618","0.06521"
"31750","190.46400","15.87221","0.06612"
"31782","190.65600","15.88823","0.06650"
"31814","190.84800","15.90420","0.06694"
"31846","191.04000","15.92016","0.06713"
"31878","191.23200","15.93618","0.06775"
"31910","191.42400","15.95221","0.06799"
"31942","191.61600","15.96817","0.06825"
"31974","191.80800","15.98413","0.06873"
"32006","192.00000","16.00022","0.06914"
"32038","192.19200","16.01612","0.07022"
"32070","192.38400","16.03220","0.07081"
"32102","192.57600","16.04817","0.07055"
"32134","192.76800","16.06419","0.07118"
"32166","192.96000","16.08027","0.07186"
"32198","193.15200","16.09618","0.07231"
"32230","193.34400","16.11220","0.07329"
"32262","193.53600","16.12823","0.07365"
"32294","193.72800","16.14413","0.07502"
"32326","193.92000","16.16021","0.07565"
"32358","194.11200","16.17624","0.07636"
"32390","194.30400","16.19214","0.07673"
"32422","194.49600","16.20822","0.07694"
"32454","194.68800","16.22419","0.07721"
"32486","194.88000","16.24015","0.07915"
"32518","195.07200","16.25624","0.07959"
"32550","195.26400","16.27220","0.08051"
"32582","195.45600","16.28816","0.08060"
"32614","195.64800","16.30425","0.08107"
"32646","195.84000","16.32021","0.08175"
"32678","196.03200","16.33617","0.08171"
"32710","196.22400","16.35226","0.08289"
"32742","196.41600","16.36822","0.08340"
"32774","196.60800","16.38412","0.08390"
"32806","196.80000","16.40027","0.08438"
"32838","196.99200","16.41617","0.08444"
"32870","197.18400","16.43214","0.08455"
"32902","197.37600","16.44822","0.08490"
"32934","197.56800","16.46412","0.08509"
"32966","197.76000","16.48015","0.08507"
"32998","197.95200","16.49623","0.08535"
"33030","198.14400","16.51213","0.08587"
"33062","198.33600","16.52822","0.08585"
"33094","198.52800","16.54424","0.08603"
"33126","198.72000","16.56015","0.08611"
"33158","198.91200","16.57617","0.08616"
"33190","199.10400","16.59219","0.08629"
"33222","199.29600","16.60816","0.08648"
"33254","199.48800","16.62418","0.08646"
"33286","199.68000","16.64014","0.08682"
"33318","199.87200","16.65623","0.08702"
"33350","200.06400","16.67219","0.08697"
"33382","200.25600","16.68822","0.08708"
"33414","200.44800","16.70418","0.08707"
"33446","200.64000","16.72020","0.08742"
"33478","200.83200","16.73623","0.08781"
"33510","201.02400","16.75225","0.08787"
"33542","201.21600","16.76821","0.08820"
"33574","201.40800","16.78424","0.08828"
"33606","201.60000","16.80020","0.08893"
"33638","201.79200","16.81617","0.08997"
"33670","201.98400","16.83219","0.09018"
"33702","202.17600","16.84821","0.08952"
"33734","202.36800","16.86411","0.09103"
"33766","202.56000","16.88020","0.09068"
"33798","202.75200","16.89622","0.09200"
"33830","202.94400","16.91213","0.09287"
"33862","203.13600","16.92821","0.09306"
"33894","203.32800","16.94423","0.09497"
"33926","203.52000","16.96014","0.09510"
"33958","203.71200","16.97628","0.09691"
"33990","203.90400","16.99219","0.09680"
"34022","204.09600","17.00815","0.09745"
"34054","204.28800","17.02423","0.09813"
"34086","204.48000","17.04020","0.09993"
"34118","204.67200","17.05616","0.10015"
"34150","204.86400","17.07224","0.10178"
"34182","205.05600","17.08815","0.10260"
"34214","205.24800","17.10423","0.10344"
"34246","205.44000","17.12025","0.10471"
"34278","205.63200","17.13616","0.10438"
"34310","205.82400","17.15224","0.10569"
"34342","206.01600","17.16826","0.10636"
"34374","206.20800","17.18411","0.10713"
"34406","206.40000","17.20025","0.10835"
"34438","206.59200","17.21628","0.10915"
"34470","206.78400","17.23212","0.10982"
"34502","206.97600","17.24820","0.11044"
"34534","207.16800","17.26417","0.11090"
"34566","207.36000","17.28019","0.11115"
"34598","207.55200","17.29622","0.11250"
"34630","207.74400","17.31218","0.11277"
"34662","207.93600","17.32820","0.11346"
"34694","208.12800","17.34422","0.11430"
"34726","208.32000","17.36013","0.11474"
"34758","208.51200","17.37627","0.11499"
"34790","208.70400","17.39224","0.11549"
"34822","208.89600","17.40820","0.11624"
"34854","209.08800","17.42422","0.11655"
"34886","209.28000","17.44025","0.11718"
"34918","209.47200","17.45615","0.11752"
"34950","209.66400","17.47218","0.11796"
"34982","209.85600","17.48820","0.11838"
"35014","210.04800","17.50422","0.11857"
"35046","210.24000","17.52019","0.11937"
"35078","210.43200","17.53621","0.11963"
"35110","210.62400","17.55218","0.11990"
"35142","210.81600","17.56820","0.12011"
"35174","211.00800","17.58416","0.12056"
"35206","211.20000","17.60018","0.12094"
"35238","211.39200","17.61621","0.12123"
"35270","211.58400","17.63217","0.12112"
"35302","211.77600","17.64826","0.12134"
"35334","211.96800","17.66422","0.12184"
"35366","212.16000","17.68018","0.12191"
"35398","212.35200","17.69621","0.12264"
"35430","212.54400","17.71217","0.12297"
"35462","212.73600","17.72820","0.12333"
"35494","212.92800","17.74422","0.12401"
"35526","213.12000","17.76018","0.12438"
"35558","213.31200","17.77621","0.12453"
"35590","213.50400","17.79223","0.12433"
"35622","213.69600","17.80813","0.12478"
"35654","213.88800","17.82428","0.12543"
"35686","214.08000","17.84018","0.12600"
"35718","214.27200","17.85614","0.12654"
"35750","214.46400","17.87229","0.12699"
"35782","214.65600","17.88819","0.12683"
"35814","214.84800","17.90416","0.12779"
"35846","215.04000","17.92024","0.12814"
"35878","215.23200","17.93620","0.12739"
"35910","215.42400","17.95217","0.12828"
"35942","215.61600","17.96825","0.12873"
"35974","215.80800","17.98415","0.12954"
"36006","216.00000","18.00018","0.12945"
"36038","216.19200","18.01620","0.13038"
"36070","216.38400","18.03222","0.13051"
"36102","216.57600","18.04819","0.13087"
"36134","216.76800","18.06421","0.13110"
"36166","216.96000","18.08018","0.13166"
"36198","217.15200","18.09620","0.13217"
"36230","217.34400","18.11228","0.13228"
"36262","217.53600","18.12813","0.13294"
"36294","217.72800","18.14421","0.13314"
"36326","217.92000","18.16023","0.13358"
"36358","218.11200","18.17614","0.13378"
"36390","218.30400","18.19222","0.13405"
"36422","218.49600","18.20819","0.13453"
"36454","218.68800","18.22421","0.13470"
"36486","218.88000","18.24023","0.13507"
"36518","219.07200","18.25620","0.13541"
"36550","219.26400","18.27222","0.13565"
"36582","219.45600","18.28824","0.13574"
"36614","219.64800","18.30421","0.13619"
"36646","219.84000","18.32023","0.13646"
"36678","220.03200","18.33625","0.13669"
"36710","220.22400","18.35216","0.13721"
"36742","220.41600","18.36824","0.13756"
"36774","220.60800","18.38420","0.13751"
"36806","220.80000","18.40023","0.13753"
"36838","220.99200","18.41619","0.13828"
"36870","221.18400","18.43222","0.13874"
"36902","221.37600","18.44818","0.13915"
"36934","221.56800","18.46420","0.13860"
"36966","221.76000","18.48017","0.13872"
"36998","221.95200","18.49625","0.13733"
"37030","222.14400","18.51221","0.13727"
"37062","222.33600","18.52818","0.13659"
"37094","222.52800","18.54426","0.13633"
"37126","222.72000","18.56017","0.13561"
"37158","222.91200","18.57619","0.13561"
"37190","223.10400","18.59221","0.13552"
"37222","223.29600","18.60818","0.01064"
"37254","223.48800","18.62420","0.00442"
"37286","223.68000","18.64016","0.00861"
"37318","223.87200","18.65619","0.00236"
"37350","224.06400","18.67215","0.00379"
"37382","224.25600","18.68818","0.00522"
"37414","224.44800","18.70414","0.00691"
"37446","224.64000","18.72016","0.00868"
"37478","224.83200","18.73625","0.00452"
"37510","225.02400","18.75215","0.00441"
"37542","225.21600","18.76823","0.00656"
"37574","225.40800","18.78420","0.00623"
"37606","225.60000","18.80016","0.00522"
"37638","225.79200","18.81624","0.00620"
"37670","225.98400","18.83221","0.00606"
"37702","226.17600","18.84811","0.00592"
"37734","226.36800","18.86426","0.00489"
"37766","226.56000","18.88016","0.00649"
"37798","226.75200","18.89618","0.00770"
"37830","226.94400","18.91221","0.00701"
"37862","227.13600","18.92817","0.00502"
"37894","227.32800","18.94419","0.00513"
"37926","227.52000","18.96022","0.00615"
"37958","227.71200","18.97618","0.00854"
"37990","227.90400","18.99220","0.00716"
"38022","228.09600","19.00823","0.00626"
"38054","228.28800","19.02419","0.00579"
"38086","228.48000","19.04016","0.00734"
"38118","228.67200","19.05624","0.00813"
"38150","228.86400","19.07214","0.00751"
"38182","229.05600","19.08823","0.00644"
"38214","229.24800","19.10419","0.00694"
"38246","229.44000","19.12021","0.00717"
"38278","229.63200","19.13618","0.00802"
"38310","229.82400","19.15220","0.00841"
"38342","230.01600","19.16817","0.00755"
"38374","230.20800","19.18419","0.00756"
"38406","230.40000","19.20015","0.00724"
"38438","230.59200","19.21624","0.00865"
"38470","230.78400","19.23220","0.00882"
"38502","230.97600","19.24816","0.00818"
"38534","231.16800","19.26425","0.00745"
"38566","231.36000","19.28021","0.00788"
"38598","231.55200","19.29618","0.00953"
"38630","231.74400","19.31226","0.00940"
"38662","231.93600","19.32816","0.00820"
"38694","232.12800","19.34419","0.00782"
"38726","232.32000","19.36021","0.00925"
"38758","232.51200","19.37617","0.01012"
"38790","232.70400","19.39220","0.00938"
"38822","232.89600","19.40822","0.00904"
"38854","233.08800","19.42418","0.00888"
"38886","233.28000","19.44021","0.00919"
"38918","233.47200","19.45623","0.01070"
"38950","233.66400","19.47214","0.01046"
"38982","233.85600","19.48822","0.00885"
"39014","234.04800","19.50418","0.00889"
"39046","234.24000","19.52015","0.00976"
"39078","234.43200","19.53623","0.01106"
"39110","234.62400","19.55219","0.01022"
"39142","234.81600","19.56816","0.00937"
"39174","235.00800","19.58418","0.01013"
"39206","235.20000","19.60020","0.01048"
"39238","235.39200","19.61623","0.01080"
"39270","235.58400","19.63225","0.01081"
"39302","235.77600","19.64822","0.01018"
"39334","235.96800","19.66424","0.00999"
"39366","236.16000","19.68020","0.01148"
"39398","236.35200","19.69611","0.00436"
"39430","236.54400","19.71225","0.00581"
"39462","236.73600","19.72815","0.00485"
"39494","236.92800","19.74418","0.00504"
"39526","237.12000","19.76020","0.00484"
"39558","237.31200","19.77623","0.00468"
"39590","237.50400","19.79219","0.00429"
"39622","237.69600","19.80821","0.00435"
"39654","237.88800","19.82418","0.00492"
"39686","238.08000","19.84020","0.00455"
"39718","238.27200","19.85622","0.00494"
"39750","238.46400","19.87213","0.00443"
"39782","238.65600","19.88821","0.00466"
"39814","238.84800","19.90424","0.00378"
"39846","239.04000","19.92014","0.00400"
"39878","239.23200","19.93622","0.00425"
"39910","239.42400","19.95225","0.00368"
"39942","239.61600","19.96815","0.00412"
"39974","239.80800","19.98423","0.00392"
"40006","240.00000","20.00026","0.00401"
"40038","240.19200","20.01616","0.00375"
"40070","240.38400","20.03218","0.00335"
"40102","240.57600","20.04815","0.00373"
"40134","240.76800","20.06417","0.00352"
"40166","240.96000","20.08019","0.00387"
"40187","241.08200","20.09036","0.00395"