File: Trajectories_together/170107_2Specimen_RawData_2.csv
"","V1","V2","V3"
"1","End date","1/7/2017",""
"2","Specimen label","17DG_39",""
"3","Maximum Load","0.72575","N"
"4","Time","Extension","Load"
"5","(s)","(mm)","(N)"
"6","0.00000","30.39048","0.00941"
"81","0.45000","30.42821","0.00956"
"156","0.90000","30.46570","0.00920"
"231","1.35000","30.50324","0.00971"
"306","1.80000","30.54062","0.00945"
"381","2.25000","30.57816","0.00933"
"456","2.70000","30.61559","0.00973"
"531","3.15000","30.65314","0.00982"
"606","3.60000","30.69063","0.01007"
"681","4.05000","30.72817","0.01027"
"756","4.50000","30.76566","0.00995"
"831","4.95000","30.80315","0.00934"
"906","5.40000","30.84058","0.00994"
"981","5.85000","30.87807","0.00971"
"1056","6.30000","30.91555","0.00999"
"1131","6.75000","30.95316","0.00990"
"1206","7.20000","30.99065","0.01030"
"1281","7.65000","31.02814","0.01062"
"1356","8.10000","31.06562","0.01005"
"1431","8.55000","31.10312","0.01015"
"1506","9.00000","31.14060","0.01084"
"1581","9.45000","31.17815","0.01053"
"1656","9.90000","31.21558","0.01057"
"1731","10.35000","31.25313","0.01035"
"1806","10.80000","31.29061","0.01065"
"1881","11.25000","31.32810","0.01060"
"1956","11.70000","31.36565","0.00997"
"2031","12.15000","31.40319","0.01080"
"2106","12.60000","31.44062","0.01120"
"2181","13.05000","31.47811","0.01060"
"2256","13.50000","31.51560","0.01057"
"2331","13.95000","31.55309","0.01065"
"2406","14.40000","31.59064","0.01060"
"2481","14.85000","31.62812","0.01076"
"2556","15.30000","31.66561","0.01074"
"2631","15.75000","31.70316","0.01057"
"2706","16.20000","31.74059","0.01123"
"2781","16.65000","31.77814","0.01047"
"2856","17.10000","31.81563","0.01142"
"2931","17.55000","31.85317","0.01117"
"3006","18.00000","31.89066","0.01106"
"3081","18.45000","31.92809","0.01112"
"3156","18.90000","31.96564","0.01099"
"3231","19.35000","32.00306","0.01126"
"3306","19.80000","32.04061","0.01115"
"3381","20.25000","32.07810","0.01148"
"3456","20.70000","32.11565","0.01151"
"3531","21.15000","32.15320","0.01126"
"3606","21.60000","32.19062","0.01133"
"3681","22.05000","32.22817","0.01187"
"3756","22.50000","32.26560","0.01172"
"3831","22.95000","32.30315","0.01168"
"3906","23.40000","32.34058","0.01152"
"3981","23.85000","32.37812","0.01112"
"4056","24.30000","32.41562","0.01157"
"4131","24.75000","32.45310","0.01181"
"4206","25.20000","32.49065","0.01237"
"4281","25.65000","32.52814","0.01128"
"4356","26.10000","32.56568","0.01172"
"4431","26.55000","32.60317","0.01220"
"4506","27.00000","32.64060","0.01197"
"4581","27.45000","32.67809","0.01188"
"4656","27.90000","32.71558","0.01223"
"4731","28.35000","32.75312","0.01228"
"4806","28.80000","32.79061","0.01212"
"4881","29.25000","32.82816","0.01290"
"4956","29.70000","32.86559","0.01245"
"5031","30.15000","32.90308","0.01257"
"5106","30.60000","32.94056","0.01217"
"5181","31.05000","32.97817","0.01214"
"5256","31.50000","33.01560","0.01264"
"5331","31.95000","33.05315","0.01277"
"5406","32.40000","33.09064","0.01301"
"5481","32.85000","33.12806","0.01293"
"5556","33.30000","33.16555","0.01242"
"5631","33.75000","33.20310","0.01239"
"5706","34.20000","33.24065","0.01271"
"5781","34.65000","33.27820","0.01335"
"5856","35.10000","33.31562","0.01343"
"5931","35.55000","33.35311","0.01307"
"6006","36.00000","33.39060","0.01282"
"6081","36.45000","33.42809","0.01285"
"6156","36.90000","33.46563","0.01319"
"6231","37.35000","33.50318","0.01317"
"6306","37.80000","33.54067","0.01313"
"6381","38.25000","33.57810","0.01317"
"6456","38.70000","33.61559","0.01327"
"6531","39.15000","33.65314","0.01328"
"6606","39.60000","33.69069","0.01331"
"6681","40.05000","33.72811","0.01310"
"6756","40.50000","33.76566","0.01322"
"6831","40.95000","33.80309","0.01344"
"6906","41.40000","33.84064","0.01347"
"6981","41.85000","33.87812","0.01333"
"7056","42.30000","33.91567","0.01364"
"7131","42.75000","33.95310","0.01337"
"7206","43.20000","33.99065","0.01377"
"7281","43.65000","34.02808","0.01302"
"7356","44.10000","34.06562","0.01381"
"7431","44.55000","34.10317","0.01346"
"7506","45.00000","34.14066","0.01380"
"7581","45.45000","34.17815","0.01367"
"7656","45.90000","34.21558","0.01378"
"7731","46.35000","34.25306","0.01413"
"7806","46.80000","34.29061","0.01404"
"7881","47.25000","34.32810","0.01445"
"7956","47.70000","34.36565","0.01401"
"8031","48.15000","34.40314","0.01467"
"8106","48.60000","34.44069","0.01370"
"8181","49.05000","34.47811","0.01444"
"8256","49.50000","34.51554","0.01463"
"8331","49.95000","34.55309","0.01437"
"8406","50.40000","34.59064","0.01431"
"8481","50.85000","34.62812","0.01386"
"8556","51.30000","34.66561","0.01442"
"8631","51.75000","34.70310","0.01405"
"8706","52.20000","34.74059","0.01499"
"8781","52.65000","34.77814","0.01510"
"8856","53.10000","34.81562","0.01523"
"8931","53.55000","34.85311","0.01479"
"9006","54.00000","34.89066","0.01482"
"9081","54.45000","34.92815","0.01514"
"9156","54.90000","34.96558","0.01428"
"9231","55.35000","35.00312","0.01696"
"9306","55.80000","35.04062","0.01343"
"9381","56.25000","35.07816","0.01490"
"9456","56.70000","35.11559","0.01621"
"9531","57.15000","35.15319","0.01574"
"9606","57.60000","35.19062","0.01442"
"9681","58.05000","35.22811","0.01381"
"9756","58.50000","35.26566","0.01517"
"9831","58.95000","35.30315","0.01263"
"9906","59.40000","35.34064","0.01635"
"9981","59.85000","35.37812","0.01513"
"10056","60.30000","35.41555","0.01554"
"10131","60.75000","35.45310","0.01683"
"10206","61.20000","35.49071","0.00631"
"10281","61.65000","35.52819","0.00672"
"10356","62.10000","35.56562","0.00622"
"10431","62.55000","35.60317","0.00679"
"10506","63.00000","35.64060","0.00667"
"10581","63.45000","35.67809","0.00639"
"10656","63.90000","35.71558","0.00647"
"10731","64.35000","35.75312","0.00587"
"10806","64.80000","35.79067","0.00642"
"10881","65.25000","35.82810","0.00582"
"10956","65.70000","35.86559","0.00627"
"11031","66.15000","35.90302","0.00635"
"11106","66.60000","35.94057","0.00690"
"11181","67.05000","35.97817","0.00618"
"11256","67.50000","36.01566","0.00616"
"11331","67.95000","36.05315","0.00582"
"11406","68.40000","36.09058","0.00628"
"11481","68.85000","36.12806","0.00592"
"11556","69.30000","36.16555","0.00613"
"11631","69.75000","36.20316","0.00619"
"11706","70.20000","36.24065","0.00605"
"11781","70.65000","36.27819","0.00595"
"11856","71.10000","36.31562","0.00601"
"11931","71.55000","36.35311","0.00635"
"12006","72.00000","36.39066","0.00578"
"12081","72.45000","36.42815","0.00646"
"12156","72.90000","36.46564","0.00616"
"12231","73.35000","36.50312","0.00654"
"12306","73.80000","36.54067","0.00600"
"12381","74.25000","36.57810","0.00607"
"12456","74.70000","36.61565","0.00620"
"12531","75.15000","36.65313","0.00660"
"12606","75.60000","36.69062","0.00616"
"12681","76.05000","36.72817","0.00663"
"12756","76.50000","36.76560","0.00670"
"12831","76.95000","36.80309","0.00647"
"12906","77.40000","36.84058","0.00687"
"12981","77.85000","36.87819","0.00595"
"13056","78.30000","36.91567","0.00634"
"13131","78.75000","36.95316","0.00643"
"13206","79.20000","36.99059","0.00685"
"13281","79.65000","37.02802","0.00639"
"13356","80.10000","37.06562","0.00621"
"13431","80.55000","37.10317","0.00681"
"13506","81.00000","37.14066","0.00649"
"13581","81.45000","37.17821","0.00676"
"13656","81.90000","37.21558","0.00629"
"13731","82.35000","37.25306","0.00669"
"13806","82.80000","37.29055","0.00685"
"13881","83.25000","37.32816","0.00662"
"13956","83.70000","37.36565","0.00630"
"14031","84.15000","37.40319","0.00663"
"14106","84.60000","37.44062","0.00691"
"14181","85.05000","37.47811","0.00664"
"14256","85.50000","37.51560","0.00656"
"14331","85.95000","37.55309","0.00642"
"14406","86.40000","37.59064","0.00653"
"14481","86.85000","37.62812","0.00649"
"14556","87.30000","37.66561","0.00665"
"14631","87.75000","37.70316","0.00624"
"14706","88.20000","37.74059","0.00694"
"14781","88.65000","37.77814","0.00684"
"14856","89.10000","37.81562","0.00671"
"14931","89.55000","37.85311","0.00667"
"15006","90.00000","37.89060","0.00712"
"15081","90.45000","37.92815","0.00730"
"15156","90.90000","37.96558","0.00651"
"15231","91.35000","38.00312","0.00638"
"15306","91.80000","38.04061","0.00695"
"15381","92.25000","38.07816","0.00720"
"15456","92.70000","38.11565","0.00620"
"15531","93.15000","38.15308","0.00693"
"15606","93.60000","38.19057","0.00640"
"15681","94.05000","38.22817","0.00640"
"15756","94.50000","38.26566","0.00638"
"15831","94.95000","38.30315","0.00700"
"15906","95.40000","38.34064","0.00648"
"15981","95.85000","38.37812","0.00633"
"16056","96.30000","38.41561","0.00661"
"16131","96.75000","38.45316","0.00690"
"16206","97.20000","38.49065","0.00614"
"16281","97.65000","38.52820","0.00664"
"16356","98.10000","38.56562","0.00633"
"16431","98.55000","38.60311","0.00676"
"16506","99.00000","38.64060","0.00600"
"16581","99.45000","38.67803","0.00637"
"16656","99.90000","38.71563","0.00610"
"16731","100.35000","38.75319","0.00636"
"16806","100.80000","38.79067","0.00612"
"16881","101.25000","38.82816","0.00653"
"16956","101.70000","38.86553","0.00674"
"17031","102.15000","38.90314","0.00670"
"17106","102.60000","38.94062","0.00666"
"17181","103.05000","38.97817","0.00604"
"17256","103.50000","39.01566","0.00649"
"17331","103.95000","39.05309","0.00672"
"17406","104.40000","39.09057","0.00679"
"17481","104.85000","39.12807","0.00636"
"17556","105.30000","39.16561","0.00674"
"17631","105.75000","39.20309","0.00626"
"17706","106.20000","39.24065","0.00648"
"17781","106.65000","39.27813","0.00693"
"17856","107.10000","39.31562","0.00673"
"17931","107.55000","39.35305","0.00687"
"18006","108.00000","39.39060","0.00654"
"18081","108.45000","39.42815","0.00690"
"18156","108.90000","39.46564","0.00691"
"18231","109.35000","39.50312","0.00672"
"18306","109.80000","39.54055","0.00688"
"18381","110.25000","39.57810","0.00667"
"18456","110.70000","39.61571","0.00667"
"18531","111.15000","39.65314","0.00683"
"18606","111.60000","39.69068","0.00650"
"18681","112.05000","39.72811","0.00699"
"18756","112.50000","39.76554","0.00661"
"18831","112.95000","39.80309","0.00680"
"18906","113.40000","39.84063","0.00676"
"18981","113.85000","39.87812","0.00707"
"19056","114.30000","39.91567","0.00679"
"19131","114.75000","39.95310","0.00707"
"19206","115.20000","39.99059","0.00687"
"19281","115.65000","40.02814","0.00699"
"19356","116.10000","40.06556","0.00760"
"19431","116.55000","40.10317","0.00757"
"19506","117.00000","40.14066","0.00728"
"19581","117.45000","40.17815","0.00741"
"19656","117.90000","40.21557","0.00717"
"19731","118.35000","40.25307","0.00727"
"19806","118.80000","40.29061","0.00742"
"19881","119.25000","40.32816","0.00731"
"19956","119.70000","40.36565","0.00758"
"20031","120.15000","40.40313","0.00704"
"20106","120.60000","40.44062","0.00809"
"20181","121.05000","40.47812","0.00745"
"20256","121.50000","40.51560","0.00724"
"20331","121.95000","40.55315","0.00796"
"20406","122.40000","40.59058","0.00805"
"20481","122.85000","40.62812","0.00789"
"20556","123.30000","40.66561","0.00786"
"20631","123.75000","40.70316","0.00770"
"20706","124.20000","40.74065","0.00779"
"20781","124.65000","40.77814","0.00804"
"20856","125.10000","40.81562","0.00790"
"20931","125.55000","40.85311","0.00852"
"21006","126.00000","40.89060","0.00816"
"21081","126.45000","40.92809","0.00863"
"21156","126.90000","40.96564","0.00890"
"21231","127.35000","41.00318","0.00876"
"21306","127.80000","41.04067","0.00894"
"21381","128.25000","41.07816","0.00958"
"21456","128.70000","41.11565","0.00967"
"21531","129.14999","41.15308","0.00959"
"21606","129.60001","41.19056","0.01016"
"21681","130.05000","41.22817","0.00952"
"21756","130.50000","41.26566","0.01001"
"21831","130.95000","41.30315","0.00999"
"21906","131.39999","41.34063","0.01048"
"21981","131.85001","41.37807","0.01119"
"22056","132.30000","41.41561","0.01087"
"22131","132.75000","41.45310","0.01137"
"22206","133.20000","41.49059","0.01120"
"22281","133.64999","41.52814","0.01227"
"22356","134.10001","41.56568","0.01176"
"22431","134.55000","41.60305","0.01217"
"22506","135.00000","41.64060","0.01235"
"22581","135.45000","41.67809","0.01256"
"22656","135.89999","41.71569","0.01335"
"22731","136.35001","41.75319","0.01430"
"22806","136.80000","41.79067","0.01371"
"22881","137.25000","41.82810","0.01433"
"22956","137.70000","41.86559","0.01403"
"23031","138.14999","41.90314","0.01529"
"23106","138.60001","41.94068","0.01503"
"23181","139.05000","41.97812","0.01543"
"23256","139.50000","42.01560","0.01538"
"23331","139.95000","42.05309","0.01599"
"23406","140.39999","42.09057","0.01657"
"23481","140.85001","42.12812","0.01649"
"23556","141.30000","42.16567","0.01684"
"23631","141.75000","42.20316","0.01695"
"23706","142.20000","42.24059","0.01753"
"23781","142.64999","42.27808","0.01791"
"23856","143.10001","42.31556","0.01816"
"23931","143.55000","42.35311","0.01806"
"24006","144.00000","42.39066","0.01900"
"24081","144.45000","42.42815","0.01918"
"24156","144.89999","42.46563","0.01935"
"24231","145.35001","42.50307","0.01989"
"24306","145.80000","42.54062","0.02014"
"24381","146.25000","42.57810","0.02056"
"24456","146.70000","42.61570","0.02099"
"24531","147.14999","42.65319","0.02115"
"24606","147.60001","42.69062","0.02175"
"24681","148.05000","42.72811","0.02192"
"24756","148.50000","42.76554","0.02211"
"24831","148.95000","42.80315","0.02249"
"24906","149.39999","42.84064","0.02289"
"24981","149.85001","42.87819","0.02353"
"25056","150.30000","42.91567","0.02371"
"25131","150.75000","42.95316","0.02392"
"25206","151.20000","42.99059","0.02498"
"25281","151.64999","43.02813","0.02513"
"25356","152.10001","43.06563","0.02520"
"25431","152.55000","43.10312","0.02588"
"25506","153.00000","43.14066","0.02571"
"25581","153.45000","43.17815","0.02637"
"25656","153.89999","43.21557","0.02687"
"25731","154.35001","43.25312","0.02712"
"25806","154.80000","43.29061","0.02731"
"25881","155.25000","43.32816","0.02798"
"25956","155.70000","43.36565","0.02838"
"26031","156.14999","43.40308","0.02900"
"26106","156.60001","43.44062","0.02929"
"26181","157.05000","43.47805","0.02980"
"26256","157.50000","43.51560","0.03072"
"26331","157.95000","43.55315","0.03063"
"26406","158.39999","43.59063","0.03137"
"26481","158.85001","43.62812","0.03197"
"26556","159.30000","43.66562","0.03245"
"26631","159.75000","43.70310","0.03281"
"26706","160.20000","43.74065","0.03329"
"26781","160.64999","43.77814","0.03430"
"26856","161.10001","43.81568","0.03462"
"26931","161.55000","43.85311","0.03567"
"27006","162.00000","43.89054","0.03642"
"27081","162.45000","43.92809","0.03668"
"27156","162.89999","43.96558","0.03745"
"27231","163.35001","44.00319","0.03744"
"27306","163.80000","44.04067","0.03861"
"27381","164.25000","44.07816","0.03918"
"27456","164.70000","44.11559","0.04025"
"27531","165.14999","44.15313","0.04076"
"27606","165.60001","44.19062","0.04085"
"27681","166.05000","44.22812","0.04187"
"27756","166.50000","44.26572","0.04220"
"27831","166.95000","44.30315","0.04279"
"27906","167.39999","44.34057","0.04366"
"27981","167.85001","44.37812","0.04422"
"28056","168.30000","44.41561","0.04495"
"28131","168.75000","44.45316","0.04571"
"28206","169.20000","44.49064","0.04579"
"28281","169.64999","44.52819","0.04651"
"28356","170.10001","44.56562","0.04652"
"28431","170.55000","44.60311","0.04834"
"28506","171.00000","44.64060","0.04903"
"28581","171.45000","44.67815","0.04902"
"28656","171.89999","44.71563","0.05115"
"28731","172.35001","44.75312","0.05126"
"28806","172.80000","44.79061","0.04901"
"28881","173.25000","44.82810","0.05229"
"28956","173.70000","44.86565","0.05067"
"29031","174.14999","44.90314","0.05096"
"29106","174.60001","44.94062","0.05638"
"29181","175.05000","44.97811","0.04505"
"29256","175.50000","45.01559","0.04326"
"29331","175.95000","45.05314","0.04560"
"29406","176.39999","45.09058","0.04606"
"29481","176.85001","45.12812","0.04558"
"29556","177.30000","45.16561","0.04742"
"29631","177.75000","45.20316","0.04901"
"29706","178.20000","45.24059","0.04846"
"29781","178.64999","45.27808","0.05171"
"29856","179.10001","45.31556","0.05280"
"29931","179.55000","45.35311","0.05363"
"30006","180.00000","45.39066","0.05561"
"30081","180.45000","45.42820","0.05763"
"30156","180.89999","45.46557","0.05847"
"30231","181.35001","45.50306","0.05955"
"30306","181.80000","45.54061","0.06158"
"30381","182.25000","45.57816","0.06304"
"30456","182.70000","45.61564","0.06373"
"30531","183.14999","45.65319","0.06491"
"30606","183.60001","45.69062","0.06613"
"30681","184.05000","45.72805","0.06687"
"30756","184.50000","45.76560","0.06731"
"30831","184.95000","45.80309","0.06869"
"30906","185.39999","45.84063","0.06971"
"30981","185.85001","45.87812","0.07022"
"31056","186.30000","45.91567","0.07066"
"31131","186.75000","45.95310","0.06804"
"31206","187.20000","45.99059","0.06829"
"31281","187.64999","46.02820","0.06916"
"31356","188.10001","46.06562","0.06998"
"31431","188.55000","46.10317","0.07129"
"31506","189.00000","46.14059","0.07135"
"31581","189.45000","46.17809","0.07203"
"31656","189.89999","46.21563","0.07285"
"31731","190.35001","46.25319","0.07378"
"31806","190.80000","46.29067","0.07432"
"31881","191.25000","46.32810","0.07496"
"31956","191.70000","46.36565","0.07543"
"32031","192.14999","46.40308","0.07657"
"32106","192.60001","46.44062","0.07741"
"32181","193.05000","46.47811","0.07808"
"32256","193.50000","46.51566","0.07871"
"32331","193.95000","46.55315","0.08001"
"32406","194.39999","46.59064","0.08101"
"32481","194.85001","46.62807","0.08190"
"32556","195.30000","46.66555","0.08373"
"32631","195.75000","46.70310","0.08498"
"32706","196.20000","46.74064","0.08641"
"32781","196.64999","46.77813","0.08768"
"32856","197.10001","46.81563","0.08972"
"32931","197.55000","46.85311","0.09262"
"33006","198.00000","46.89060","0.09387"
"33081","198.45000","46.92809","0.09574"
"33156","198.89999","46.96563","0.09859"
"33231","199.35001","47.00312","0.10075"
"33306","199.80000","47.04067","0.10380"
"33381","200.25000","47.07809","0.10228"
"33456","200.70000","47.11559","0.10458"
"33531","201.14999","47.15314","0.11164"
"33606","201.60001","47.19062","0.11669"
"33681","202.05000","47.22811","0.11780"
"33756","202.50000","47.26566","0.11846"
"33831","202.95000","47.30314","0.12089"
"33906","203.39999","47.34063","0.12496"
"33981","203.85001","47.37812","0.12836"
"34056","204.30000","47.41561","0.13005"
"34131","204.75000","47.45316","0.13281"
"34206","205.20000","47.49065","0.13569"
"34281","205.64999","47.52813","0.13896"
"34356","206.10001","47.56562","0.14233"
"34431","206.55000","47.60311","0.14545"
"34506","207.00000","47.64066","0.14752"
"34581","207.45000","47.67815","0.14913"
"34656","207.89999","47.71564","0.15265"
"34731","208.35001","47.75319","0.15682"
"34806","208.80000","47.79049","0.16004"
"34881","209.25000","47.82816","0.16292"
"34956","209.70000","47.86564","0.16605"
"35031","210.14999","47.90314","0.16819"
"35106","210.60001","47.94068","0.17022"
"35181","211.05000","47.97811","0.17310"
"35256","211.50000","48.01554","0.17656"
"35331","211.95000","48.05302","0.17976"
"35406","212.39999","48.09063","0.18178"
"35481","212.85001","48.12818","0.18392"
"35556","213.30000","48.16567","0.18575"
"35631","213.75000","48.20316","0.18789"
"35706","214.20000","48.24059","0.19020"
"35781","214.64999","48.27808","0.19327"
"35856","215.10001","48.31556","0.19641"
"35931","215.55000","48.35317","0.19906"
"36006","216.00000","48.39066","0.20228"
"36081","216.45000","48.42809","0.20598"
"36156","216.89999","48.46564","0.21045"
"36231","217.35001","48.50306","0.21494"
"36306","217.80000","48.54067","0.21989"
"36381","218.25000","48.57810","0.22416"
"36456","218.70000","48.61565","0.22698"
"36531","219.14999","48.65313","0.23196"
"36606","219.60001","48.69062","0.23615"
"36681","220.05000","48.72811","0.24109"
"36756","220.50000","48.76559","0.24655"
"36831","220.95000","48.80315","0.25213"
"36906","221.39999","48.84064","0.25929"
"36981","221.85001","48.87812","0.26653"
"37056","222.30000","48.91555","0.27301"
"37131","222.75000","48.95310","0.27831"
"37206","223.20000","48.99065","0.28232"
"37281","223.64999","49.02814","0.28584"
"37356","224.10001","49.06568","0.28931"
"37431","224.55000","49.10311","0.29219"
"37506","225.00000","49.14060","0.29444"
"37581","225.45000","49.17809","0.29616"
"37656","225.89999","49.21563","0.29886"
"37731","226.35001","49.25318","0.30230"
"37806","226.80000","49.29061","0.30656"
"37881","227.25000","49.32809","0.31305"
"37956","227.70000","49.36559","0.31948"
"38031","228.14999","49.40307","0.32475"
"38106","228.60001","49.44056","0.33025"
"38181","229.05000","49.47817","0.33661"
"38256","229.50000","49.51566","0.34246"
"38331","229.95000","49.55315","0.34929"
"38406","230.39999","49.59064","0.35390"
"38481","230.85001","49.62806","0.35884"
"38556","231.30000","49.66561","0.36433"
"38631","231.75000","49.70310","0.36971"
"38706","232.20000","49.74065","0.37443"
"38781","232.64999","49.77813","0.37867"
"38856","233.10001","49.81562","0.38339"
"38931","233.55000","49.85311","0.38713"
"39006","234.00000","49.89060","0.39054"
"39081","234.45000","49.92815","0.39485"
"39156","234.89999","49.96563","0.40090"
"39231","235.35001","50.00312","0.40723"
"39306","235.80000","50.04062","0.41312"
"39381","236.25000","50.07816","0.41931"
"39456","236.70000","50.11559","0.42578"
"39531","237.14999","50.15314","0.43090"
"39606","237.60001","50.19062","0.43641"
"39681","238.05000","50.22811","0.44135"
"39756","238.50000","50.26566","0.44913"
"39831","238.95000","50.30303","0.45545"
"39906","239.39999","50.34057","0.46159"
"39981","239.85001","50.37818","0.47030"
"40056","240.30000","50.41567","0.47804"
"40131","240.75000","50.45316","0.48553"
"40206","241.20000","50.49059","0.49137"
"40281","241.64999","50.52807","0.49483"
"40356","242.10001","50.56556","0.49791"
"40431","242.55000","50.60312","0.27641"
"40506","243.00000","50.64066","0.27982"
"40581","243.45000","50.67821","0.28032"
"40656","243.89999","50.71564","0.28583"
"40731","244.35001","50.75312","0.28912"
"40806","244.80000","50.79067","0.28928"
"40881","245.25000","50.82810","0.29170"
"40956","245.70000","50.86565","0.29421"
"41031","246.14999","50.90313","0.29485"
"41106","246.60001","50.94068","0.29611"
"41181","247.05000","50.97811","0.29837"
"41256","247.50000","51.01548","0.30014"
"41331","247.95000","51.05309","0.30198"
"41406","248.39999","51.09064","0.30651"
"41481","248.85001","51.12818","0.31149"
"41556","249.30000","51.16562","0.31635"
"41631","249.75000","51.20310","0.32278"
"41706","250.20000","51.24059","0.32671"
"41781","250.64999","51.27814","0.32994"
"41856","251.10001","51.31562","0.33556"
"41931","251.55000","51.35311","0.33982"
"42006","252.00000","51.39066","0.34458"
"42081","252.45000","51.42808","0.34984"
"42156","252.89999","51.46563","0.35270"
"42231","253.35001","51.50312","0.35638"
"42306","253.80000","51.54061","0.35996"
"42381","254.25000","51.57816","0.36457"
"42456","254.70000","51.61559","0.36872"
"42531","255.14999","51.65313","0.37146"
"42606","255.60001","51.69056","0.37436"
"42681","256.04999","51.72812","0.37772"
"42756","256.50000","51.76566","0.38152"
"42831","256.95001","51.80321","0.38425"
"42906","257.39999","51.84069","0.38680"
"42981","257.85001","51.87812","0.38906"
"43056","258.29999","51.91555","0.39176"
"43131","258.75000","51.95310","0.39618"
"43206","259.20001","51.99064","0.40023"
"43281","259.64999","52.02819","0.40435"
"43356","260.10001","52.06562","0.40908"
"43431","260.54999","52.10311","0.41214"
"43506","261.00000","52.14054","0.41712"
"43581","261.45001","52.17815","0.38076"
"43656","261.89999","52.21564","0.38000"
"43731","262.35001","52.25312","0.38454"
"43806","262.79999","52.29067","0.38473"
"43881","263.25000","52.32816","0.38961"
"43956","263.70001","52.36559","0.39140"
"44031","264.14999","52.40308","0.39711"
"44106","264.60001","52.44056","0.39988"
"44181","265.04999","52.47817","0.40469"
"44256","265.50000","52.51566","0.40907"
"44331","265.95001","52.55315","0.41520"
"44406","266.39999","52.59063","0.42061"
"44481","266.85001","52.62807","0.42420"
"44556","267.29999","52.66562","0.42881"
"44631","267.75000","52.70316","0.43227"
"44706","268.20001","52.74059","0.43770"
"44781","268.64999","52.77813","0.44195"
"44856","269.10001","52.81562","0.44484"
"44931","269.54999","52.85311","0.45015"
"45006","270.00000","52.89066","0.45540"
"45081","270.45001","52.92821","0.46126"
"45156","270.89999","52.96564","0.46548"
"45231","271.35001","53.00312","0.47326"
"45306","271.79999","53.04055","0.47998"
"45381","272.25000","53.07810","0.48461"
"45456","272.70001","53.11564","0.48858"
"45531","273.14999","53.15313","0.49356"
"45606","273.60001","53.19063","0.49627"
"45681","274.04999","53.22817","0.49866"
"45756","274.50000","53.26560","0.50208"
"45831","274.95001","53.30309","0.50580"
"45906","275.39999","53.34064","0.50892"
"45981","275.85001","53.37818","0.51307"
"46056","276.29999","53.41567","0.51835"
"46131","276.75000","53.45316","0.52388"
"46206","277.20001","53.49065","0.52887"
"46281","277.64999","53.52808","0.53557"
"46356","278.10001","53.56562","0.54063"
"46431","278.54999","53.60311","0.54599"
"46506","279.00000","53.64066","0.55303"
"46581","279.45001","53.67815","0.55747"
"46656","279.89999","53.71563","0.56291"
"46731","280.35001","53.75313","0.56907"
"46806","280.79999","53.79062","0.57449"
"46881","281.25000","53.82816","0.57877"
"46956","281.70001","53.86559","0.58348"
"47031","282.14999","53.90319","0.58677"
"47106","282.60001","53.94062","0.59018"
"47181","283.04999","53.97811","0.59335"
"47256","283.50000","54.01559","0.59626"
"47331","283.95001","54.05309","0.59912"
"47406","284.39999","54.09069","0.60173"
"47481","284.85001","54.12812","0.60627"
"47556","285.29999","54.16561","0.61015"
"47631","285.75000","54.20310","0.61532"
"47706","286.20001","54.24052","0.62328"
"47781","286.64999","54.27813","0.62912"
"47856","287.10001","54.31562","0.63536"
"47931","287.54999","54.35317","0.63979"
"48006","288.00000","54.39060","0.64475"
"48081","288.45001","54.42809","0.65044"
"48156","288.89999","54.46564","0.65502"
"48231","289.35001","54.50318","0.66089"
"48306","289.79999","54.54067","0.66496"
"48381","290.25000","54.57816","0.67159"
"48456","290.70001","54.61565","0.67622"
"48531","291.14999","54.65302","0.68268"
"48606","291.60001","54.69056","0.68752"
"48681","292.04999","54.72811","0.69160"
"48756","292.50000","54.76566","0.69567"
"48831","292.95001","54.80315","0.69846"
"48906","293.39999","54.84063","0.70089"
"48981","293.85001","54.87806","0.70301"
"49056","294.29999","54.91562","0.70556"
"49131","294.75000","54.95310","0.70916"
"49206","295.20001","54.99065","0.71283"
"49281","295.64999","55.02820","0.71594"
"49356","296.10001","55.06568","0.72128"
"49431","296.54999","55.10311","0.64739"
"49506","297.00000","55.14059","0.60022"
"49581","297.45001","55.17814","0.59854"
"49656","297.89999","55.21564","0.59739"
"49731","298.35001","55.25312","0.60304"
"49806","298.79999","55.29067","0.60092"
"49881","299.25000","55.32810","0.20639"
"49956","299.70001","55.36559","0.21594"
"50031","300.14999","55.40313","0.22339"
"50106","300.60001","55.44062","0.20906"
"50181","301.04999","55.47818","0.20392"
"50256","301.50000","55.51560","0.20863"
"50331","301.95001","55.55309","0.21637"
"50406","302.39999","55.59064","0.22033"
"50481","302.85001","55.62812","0.21737"
"50556","303.29999","55.66561","0.21468"
"50631","303.75000","55.70316","0.22012"
"50706","304.20001","55.74059","0.22916"
"50781","304.64999","55.77807","0.23139"
"50856","305.10001","55.81556","0.22717"
"50931","305.54999","55.85311","0.22235"
"51006","306.00000","55.89066","0.22222"
"51081","306.45001","55.92815","0.22372"
"51156","306.89999","55.96569","0.22475"
"51231","307.35001","56.00312","0.22513"
"51306","307.79999","56.04055","0.22580"
"51381","308.25000","56.07810","0.22634"
"51456","308.70001","56.11565","0.22528"
"51531","309.14999","56.15313","0.22811"
"51606","309.60001","56.19062","0.23348"
"51681","310.04999","56.22805","0.23825"
"51756","310.50000","56.26559","0.24032"
"51831","310.95001","56.30309","0.23909"
"51906","311.39999","56.34058","0.23626"
"51981","311.85001","56.37813","0.23503"
"52056","312.29999","56.41567","0.23604"
"52131","312.75000","56.45316","0.23695"
"52206","313.20001","56.49059","0.23881"
"52281","313.64999","56.52808","0.24270"
"52356","314.10001","56.56556","0.24448"
"52431","314.54999","56.60311","0.24488"
"52506","315.00000","56.64060","0.24562"
"52581","315.45001","56.67821","0.24696"
"52656","315.89999","56.71564","0.24664"
"52731","316.35001","56.75307","0.24681"
"52806","316.79999","56.79067","0.24853"
"52881","317.25000","56.82810","0.25141"
"52956","317.70001","56.86564","0.25543"
"53031","318.14999","56.90307","0.25886"
"53106","318.60001","56.94056","0.26342"
"53181","319.04999","56.97811","0.26673"
"53256","319.50000","57.01566","0.27021"
"53331","319.95001","57.05321","0.27244"
"53406","320.39999","57.09058","0.27231"
"53481","320.85001","57.12812","0.27294"
"53556","321.29999","57.16555","0.27289"
"53631","321.75000","57.20310","0.27170"
"53706","322.20001","57.24059","0.27120"
"53781","322.64999","57.27813","0.27136"
"53856","323.10001","57.31568","0.27247"
"53931","323.54999","57.35311","0.27356"
"54006","324.00000","57.39060","0.27473"
"54081","324.45001","57.42803","0.27592"
"54156","324.89999","57.46558","0.27672"
"54231","325.35001","57.50319","0.27713"
"54306","325.79999","57.54061","0.27807"
"54381","326.25000","57.57816","0.27829"
"54456","326.70001","57.61559","0.27948"
"54531","327.14999","57.65308","0.28034"
"54606","327.60001","57.69056","0.28117"
"54681","328.04999","57.72817","0.28168"
"54756","328.50000","57.76566","0.28302"
"54831","328.95001","57.80315","0.28367"
"54906","329.39999","57.84064","0.28414"
"54981","329.85001","57.87807","0.28535"
"55056","330.29999","57.91561","0.28657"
"55131","330.75000","57.95310","0.28663"
"55206","331.20001","57.99064","0.28795"
"55281","331.64999","58.02814","0.28870"
"55356","332.10001","58.06569","0.28974"
"55431","332.54999","58.10311","0.29035"
"55506","333.00000","58.14060","0.29125"
"55581","333.45001","58.17815","0.29160"
"55656","333.89999","58.21563","0.29211"
"55731","334.35001","58.25319","0.29240"
"55806","334.79999","58.29061","0.29314"
"55881","335.25000","58.32810","0.29356"
"55956","335.70001","58.36559","0.29342"
"56031","336.14999","58.40320","0.29399"
"56106","336.60001","58.44062","0.29459"
"56181","337.04999","58.47812","0.29458"
"56256","337.50000","58.51560","0.29514"
"56331","337.95001","58.55303","0.29498"
"56406","338.39999","58.59064","0.29533"
"56481","338.85001","58.62812","0.29546"
"56556","339.29999","58.66567","0.29571"
"56631","339.75000","58.70316","0.29568"
"56706","340.20001","58.74059","0.29594"
"56781","340.64999","58.77808","0.29617"
"56856","341.10001","58.81556","0.29642"
"56931","341.54999","58.85311","0.29712"
"57006","342.00000","58.89066","0.29740"
"57081","342.45001","58.92821","0.29783"
"57156","342.89999","58.96564","0.29776"
"57231","343.35001","59.00312","0.29817"
"57306","343.79999","59.04055","0.29858"
"57381","344.25000","59.07804","0.29904"
"57456","344.70001","59.11565","0.29956"
"57531","345.14999","59.15314","0.30035"
"57606","345.60001","59.19062","0.30065"
"57681","346.04999","59.22811","0.30170"
"57756","346.50000","59.26554","0.30167"
"57831","346.95001","59.30315","0.30245"
"57906","347.39999","59.34063","0.30283"
"57981","347.85001","59.37812","0.30346"
"58056","348.29999","59.41567","0.30386"
"58131","348.75000","59.45316","0.30473"
"58206","349.20001","59.49059","0.30525"
"58281","349.64999","59.52813","0.30586"
"58356","350.10001","59.56562","0.30632"
"58431","350.54999","59.60317","0.30678"
"58506","351.00000","59.64066","0.30775"
"58581","351.45001","59.67809","0.30780"
"58656","351.89999","59.71564","0.30868"
"58731","352.35001","59.75312","0.30914"
"58806","352.79999","59.79067","0.30954"
"58881","353.25000","59.82816","0.31032"
"58956","353.70001","59.86565","0.31147"
"59031","354.14999","59.90308","0.31271"
"59106","354.60001","59.94056","0.31367"
"59181","355.04999","59.97811","0.31438"
"59256","355.50000","60.01566","0.01286"
"59331","355.95001","60.05315","0.01417"
"59406","356.39999","60.09063","0.00950"
"59481","356.85001","60.12812","0.00992"
"59556","357.29999","60.16555","0.01105"
"59631","357.75000","60.20304","0.01240"
"59706","358.20001","60.24065","0.01172"
"59781","358.64999","60.27814","0.01110"
"59856","359.10001","60.31569","0.01080"
"59931","359.54999","60.35311","0.01232"
"60006","360.00000","60.39054","0.01277"
"60081","360.45001","60.42809","0.01314"
"60156","360.89999","60.46563","0.01235"
"60231","361.35001","60.50319","0.01180"
"60306","361.79999","60.54067","0.01281"
"60381","362.25000","60.57810","0.01442"
"60456","362.70001","60.61559","0.01384"
"60531","363.14999","60.65307","0.01295"
"60606","363.60001","60.69062","0.01333"
"60681","364.04999","60.72812","0.01470"
"60756","364.50000","60.76566","0.01446"
"60831","364.95001","60.80315","0.01397"
"60906","365.39999","60.84064","0.01350"
"60981","365.85001","60.87806","0.01538"
"61056","366.29999","60.91561","0.01600"
"61131","366.75000","60.95316","0.01566"
"61206","367.20001","60.99065","0.01473"
"61281","367.64999","61.02813","0.01504"
"61356","368.10001","61.06556","0.01660"
"61431","368.54999","61.10311","0.01657"
"61506","369.00000","61.14066","0.01643"
"61581","369.45001","61.17815","0.01577"
"61656","369.89999","61.21563","0.01608"
"61731","370.35001","61.25312","0.01742"
"61806","370.79999","61.29055","0.01656"
"61881","371.25000","61.32810","0.01727"
"61956","371.70001","61.36565","0.01740"
"62031","372.14999","61.40319","0.01779"
"62106","372.60001","61.44069","0.01775"
"62181","373.04999","61.47811","0.01832"
"62256","373.50000","61.51560","0.01830"
"62331","373.95001","61.55315","0.01803"
"62406","374.39999","61.59063","0.01778"
"62481","374.85001","61.62812","0.01822"
"62556","375.29999","61.66561","0.01912"
"62631","375.75000","61.70316","0.01845"
"62706","376.20001","61.74059","0.01956"
"62781","376.64999","61.77807","0.01894"
"62856","377.10001","61.81556","0.01914"
"62931","377.54999","61.85312","0.01868"
"63006","378.00000","61.89066","0.01905"
"63081","378.45001","61.92815","0.01955"
"63156","378.89999","61.96564","0.01986"
"63231","379.35001","62.00312","0.02009"
"63306","379.79999","62.04061","0.01981"
"63381","380.25000","62.07816","0.02015"
"63456","380.70001","62.11559","0.02047"
"63531","381.14999","62.15313","0.02110"
"63606","381.60001","62.19062","0.02085"
"63681","382.04999","62.22811","0.02073"
"63756","382.50000","62.26560","0.02101"
"63831","382.95001","62.30315","0.02154"
"63906","383.39999","62.34063","0.02112"
"63981","383.85001","62.37812","0.02161"
"64056","384.29999","62.41562","0.02186"
"64131","384.75000","62.45310","0.02185"
"64206","385.20001","62.49065","0.02210"
"64281","385.64999","62.52819","0.02198"
"64356","386.10001","62.56568","0.02276"
"64431","386.54999","62.60317","0.02282"
"64506","387.00000","62.64065","0.02280"
"64581","387.45001","62.67809","0.02288"
"64656","387.89999","62.71558","0.02365"
"64731","388.35001","62.75318","0.02371"
"64806","388.79999","62.79067","0.02393"
"64881","389.25000","62.82809","0.02422"
"64956","389.70001","62.86565","0.02394"
"65031","390.14999","62.90307","0.02463"
"65106","390.60001","62.94062","0.02544"
"65181","391.04999","62.97810","0.02510"
"65256","391.50000","63.01566","0.02568"
"65331","391.95001","63.05315","0.02574"
"65406","392.39999","63.09063","0.02554"
"65481","392.85001","63.12806","0.02656"
"65556","393.29999","63.16560","0.02651"
"65631","393.75000","63.20309","0.02670"
"65706","394.20001","63.24064","0.02702"
"65781","394.64999","63.27813","0.02767"
"65856","395.10001","63.31568","0.02828"
"65931","395.54999","63.35311","0.02841"
"66006","396.00000","63.39054","0.02873"
"66081","396.45001","63.42808","0.02905"
"66156","396.89999","63.46563","0.02927"
"66231","397.35001","63.50312","0.02998"
"66306","397.79999","63.54067","0.03070"
"66381","398.25000","63.57810","0.03058"
"66456","398.70001","63.61558","0.03152"
"66531","399.14999","63.65313","0.03212"
"66606","399.60001","63.69068","0.03170"
"66681","400.04999","63.72811","0.03292"
"66756","400.50000","63.76565","0.03302"
"66831","400.95001","63.80309","0.03379"
"66906","401.39999","63.84057","0.03401"
"66981","401.85001","63.87812","0.03492"
"67056","402.29999","63.91567","0.03495"
"67131","402.75000","63.95316","0.03579"
"67206","403.20001","63.99065","0.03611"
"67281","403.64999","64.02807","0.03680"
"67356","404.10001","64.06562","0.03692"
"67431","404.54999","64.10310","0.03733"
"67506","405.00000","64.14072","0.03770"
"67581","405.45001","64.17821","0.03939"
"67656","405.89999","64.21563","0.03969"
"67731","406.35001","64.25312","0.03974"
"67806","406.79999","64.29054","0.04081"
"67881","407.25000","64.32809","0.04082"
"67956","407.70001","64.36564","0.04185"
"68031","408.14999","64.40313","0.04270"
"68106","408.60001","64.44068","0.04273"
"68181","409.04999","64.47810","0.04367"
"68256","409.50000","64.51559","0.04416"
"68331","409.95001","64.55314","0.04506"
"68406","410.39999","64.59063","0.04573"
"68481","410.85001","64.62812","0.04653"
"68556","411.29999","64.66566","0.04698"
"68631","411.75000","64.70315","0.04797"
"68706","412.20001","64.74059","0.04826"
"68781","412.64999","64.77814","0.04901"
"68856","413.10001","64.81556","0.05055"
"68931","413.54999","64.85317","0.05162"
"69006","414.00000","64.89059","0.05227"
"69081","414.45001","64.92809","0.05331"
"69156","414.89999","64.96563","0.05459"
"69231","415.35001","65.00306","0.05547"
"69306","415.79999","65.04061","0.05586"
"69381","416.25000","65.07816","0.05742"
"69456","416.70001","65.11565","0.05831"
"69531","417.14999","65.15313","0.05959"
"69606","417.60001","65.19062","0.06030"
"69681","418.04999","65.22810","0.06111"
"69756","418.50000","65.26566","0.06202"
"69831","418.95001","65.30315","0.06275"
"69906","419.39999","65.34063","0.06380"
"69981","419.85001","65.37812","0.06473"
"70056","420.29999","65.41554","0.06506"
"70131","420.75000","65.45309","0.06617"
"70206","421.20001","65.49064","0.06694"
"70281","421.64999","65.52819","0.06766"
"70356","422.10001","65.56567","0.06829"
"70431","422.54999","65.60316","0.06925"
"70506","423.00000","65.64066","0.06939"
"70581","423.45001","65.67814","0.06989"
"70656","423.89999","65.71558","0.07078"
"70731","424.35001","65.75312","0.07116"
"70806","424.79999","65.79066","0.07173"
"70881","425.25000","65.82816","0.07222"
"70956","425.70001","65.86559","0.07266"
"71031","426.14999","65.90308","0.07346"
"71106","426.60001","65.94062","0.07377"
"71181","427.04999","65.97811","0.07422"
"71256","427.50000","66.01559","0.07440"
"71331","427.95001","66.05321","0.07512"
"71406","428.39999","66.09063","0.07574"
"71481","428.85001","66.12812","0.07589"
"71556","429.29999","66.16560","0.07682"
"71631","429.75000","66.20316","0.07731"
"71706","430.20001","66.24065","0.07806"
"71781","430.64999","66.27807","0.07864"
"71856","431.10001","66.31562","0.07903"
"71931","431.54999","66.35310","0.07957"
"72006","432.00000","66.39059","0.08047"
"72081","432.45001","66.42814","0.08129"
"72156","432.89999","66.46563","0.08224"
"72231","433.35001","66.50312","0.08232"
"72306","433.79999","66.54055","0.08397"
"72381","434.25000","66.57809","0.08499"
"72456","434.70001","66.61559","0.08567"
"72531","435.14999","66.65313","0.08705"
"72606","435.60001","66.69061","0.08686"
"72681","436.04999","66.72816","0.08849"
"72756","436.50000","66.76560","0.08984"
"72831","436.95001","66.80302","0.09105"
"72906","437.39999","66.84058","0.09136"
"72981","437.85001","66.87817","0.09299"
"73056","438.29999","66.91567","0.09390"
"73131","438.75000","66.95316","0.09524"
"73206","439.20001","66.99059","0.09698"
"73281","439.64999","67.02807","0.09860"
"73356","440.10001","67.06562","0.09912"
"73431","440.54999","67.10311","0.10115"
"73506","441.00000","67.14066","0.10263"
"73581","441.45001","67.17821","0.10481"
"73656","441.89999","67.21563","0.10569"
"73731","442.35001","67.25312","0.10753"
"73806","442.79999","67.29060","0.10763"
"73881","443.25000","67.32809","0.10927"
"73956","443.70001","67.36559","0.11082"
"74031","444.14999","67.40313","0.11258"
"74106","444.60001","67.44068","0.11424"
"74181","445.04999","67.47810","0.11559"
"74256","445.50000","67.51559","0.11638"
"74331","445.95001","67.55314","0.11843"
"74406","446.39999","67.59063","0.11889"
"74481","446.85001","67.62812","0.12055"
"74556","447.29999","67.66560","0.12088"
"74631","447.75000","67.70309","0.12266"
"74706","448.20001","67.74064","0.12333"
"74781","448.64999","67.77813","0.12463"
"74856","449.10001","67.81567","0.12579"
"74931","449.54999","67.85305","0.12732"
"75006","450.00000","67.89066","0.12825"
"75081","450.45001","67.92809","0.12957"
"75156","450.89999","67.96564","0.13083"
"75231","451.35001","68.00312","0.13247"
"75306","451.79999","68.04061","0.13273"
"75381","452.25000","68.07809","0.13438"
"75456","452.70001","68.11559","0.13599"
"75531","453.14999","68.15307","0.13764"
"75606","453.60001","68.19056","0.13865"
"75681","454.04999","68.22811","0.14033"
"75756","454.50000","68.26566","0.14090"
"75831","454.95001","68.30315","0.14271"
"75906","455.39999","68.34063","0.14369"
"75981","455.85001","68.37812","0.14504"
"76056","456.29999","68.41554","0.14597"
"76131","456.75000","68.45309","0.14629"
"76206","457.20001","68.49065","0.14771"
"76281","457.64999","68.52813","0.14873"
"76356","458.10001","68.56568","0.15006"
"76431","458.54999","68.60310","0.15143"
"76506","459.00000","68.64059","0.15230"
"76581","459.45001","68.67814","0.15353"
"76656","459.89999","68.71563","0.15288"
"76731","460.35001","68.75311","0.15378"
"76806","460.79999","68.79066","0.15468"
"76881","461.25000","68.82816","0.15678"
"76956","461.70001","68.86564","0.15856"
"77031","462.14999","68.90313","0.15975"
"77106","462.60001","68.94062","0.16074"
"77181","463.04999","68.97816","0.16236"
"77256","463.50000","69.01566","0.16367"
"77331","463.95001","69.05309","0.16550"
"77406","464.39999","69.09058","0.16671"
"77481","464.85001","69.12806","0.16792"
"77556","465.29999","69.16567","0.16866"
"77631","465.75000","69.20316","0.17035"
"77706","466.20001","69.24065","0.17215"
"77781","466.64999","69.27813","0.17349"
"77856","467.10001","69.31556","0.17476"
"77931","467.54999","69.35317","0.17573"
"78006","468.00000","69.39066","0.17702"
"78081","468.45001","69.42815","0.17885"
"78156","468.89999","69.46569","0.17968"
"78231","469.35001","69.50306","0.18090"
"78306","469.79999","69.54060","0.18185"
"78381","470.25000","69.57809","0.18259"
"78456","470.70001","69.61564","0.18368"
"78531","471.14999","69.65313","0.18443"
"78606","471.60001","69.69068","0.18507"
"78681","472.04999","69.72810","0.18605"
"78756","472.50000","69.76559","0.18688"
"78831","472.95001","69.80308","0.18847"
"78906","473.39999","69.84058","0.18988"
"78981","473.85001","69.87817","0.19151"
"79056","474.29999","69.91561","0.19305"
"79131","474.75000","69.95316","0.19471"
"79206","475.20001","69.99064","0.19627"
"79281","475.64999","70.02808","0.19854"
"79356","476.10001","70.06567","0.19992"
"79431","476.54999","70.10316","0.20185"
"79506","477.00000","70.14066","0.20317"
"79581","477.45001","70.17815","0.20538"
"79656","477.89999","70.21564","0.20679"
"79731","478.35001","70.25306","0.20957"
"79806","478.79999","70.29061","0.21153"
"79881","479.25000","70.32816","0.21429"
"79956","479.70001","70.36565","0.21714"
"80031","480.14999","70.40313","0.21990"
"80106","480.60001","70.44062","0.22199"
"80181","481.04999","70.47810","0.22375"
"80256","481.50000","70.51566","0.22620"
"80331","481.95001","70.55315","0.22908"
"80406","482.39999","70.59063","0.23154"
"80481","482.85001","70.62812","0.23425"
"80556","483.29999","70.66560","0.23647"
"80631","483.75000","70.70309","0.23951"
"80706","484.20001","70.74058","0.24178"
"80781","484.64999","70.77819","0.24527"
"80856","485.10001","70.81562","0.24927"
"80931","485.54999","70.85310","0.25208"
"81006","486.00000","70.89059","0.25656"
"81081","486.45001","70.92809","0.26125"
"81156","486.89999","70.96558","0.26547"
"81231","487.35001","71.00317","0.26953"
"81306","487.79999","71.04061","0.27322"
"81381","488.25000","71.07816","0.27676"
"81456","488.70001","71.11559","0.27866"
"81531","489.14999","71.15302","0.28131"
"81606","489.60001","71.19062","0.28290"
"81681","490.04999","71.22811","0.28548"
"81756","490.50000","71.26566","0.28591"
"81831","490.95001","71.30315","0.24573"
"81906","491.39999","71.34057","0.24870"
"81981","491.85001","71.37806","0.25267"
"82056","492.29999","71.41555","0.25702"
"82131","492.75000","71.45309","0.25975"
"82206","493.20001","71.49065","0.26125"
"82281","493.64999","71.52813","0.26399"
"82356","494.10001","71.56568","0.26640"
"82431","494.54999","71.60310","0.26980"
"82506","495.00000","71.64053","0.27201"
"82581","495.45001","71.67809","0.27475"
"82656","495.89999","71.71563","0.27738"
"82731","496.35001","71.75312","0.27954"
"82806","496.79999","71.79060","0.28152"
"82881","497.25000","71.82809","0.28407"
"82956","497.70001","71.86558","0.28566"
"83031","498.14999","71.90319","0.28717"
"83106","498.60001","71.94068","0.28845"
"83181","499.04999","71.97816","0.28919"
"83256","499.50000","72.01566","0.29008"
"83331","499.95001","72.05309","0.29094"
"83406","500.39999","72.09058","0.29203"
"83481","500.85001","72.12812","0.29258"
"83556","501.29999","72.16566","0.29328"
"83631","501.75000","72.20316","0.29458"
"83706","502.20001","72.24065","0.29516"
"83781","502.64999","72.27814","0.29620"
"83856","503.10001","72.31562","0.29732"
"83931","503.54999","72.35305","0.29911"
"84006","504.00000","72.39066","0.30017"
"84081","504.45001","72.42815","0.30225"
"84156","504.89999","72.46569","0.30426"
"84231","505.35001","72.50312","0.30677"
"84306","505.79999","72.54048","0.30884"
"84381","506.25000","72.57809","0.31065"
"84456","506.70001","72.61565","0.31383"
"84531","507.14999","72.65319","0.31608"
"84606","507.60001","72.69068","0.31864"
"84681","508.04999","72.72810","0.32156"
"84756","508.50000","72.76559","0.32327"
"84831","508.95001","72.80308","0.32594"
"84906","509.39999","72.84063","0.32836"
"84981","509.85001","72.87812","0.33110"
"85056","510.29999","72.91560","0.33375"
"85131","510.75000","72.95309","0.33678"
"85206","511.20001","72.99064","0.33895"
"85281","511.64999","73.02808","0.33996"
"85356","512.09998","73.06561","0.34234"
"85431","512.54999","73.10316","0.34464"
"85506","513.00000","73.14066","0.34690"
"85581","513.45001","73.17814","0.34963"
"85656","513.90002","73.21558","0.35197"
"85731","514.34998","73.25312","0.35348"
"85806","514.79999","73.29066","0.35456"
"85881","515.25000","73.32816","0.35596"
"85956","515.70001","73.36570","0.35746"
"86031","516.15002","73.40314","0.35835"
"86106","516.59998","73.44056","0.36089"
"86181","517.04999","73.47811","0.36332"
"86256","517.50000","73.51566","0.36573"
"86331","517.95001","73.55321","0.36636"
"86406","518.40002","73.59063","0.36829"
"86481","518.84998","73.62812","0.36935"
"86556","519.29999","73.66554","0.36997"
"86631","519.75000","73.70309","0.37205"
"86706","520.20001","73.74059","0.37379"
"86781","520.65002","73.77813","0.37520"
"86856","521.09998","73.81562","0.37623"
"86931","521.54999","73.85310","0.37675"
"87006","522.00000","73.89059","0.37796"
"87081","522.45001","73.92808","0.37913"
"87156","522.90002","73.96557","0.38043"
"87231","523.34998","74.00318","0.38278"
"87306","523.79999","74.04060","0.38388"
"87381","524.25000","74.07816","0.38451"
"87456","524.70001","74.11564","0.38568"
"87531","525.15002","74.15308","0.38694"
"87606","525.59998","74.19061","0.38746"
"87681","526.04999","74.22811","0.38859"
"87756","526.50000","74.26560","0.39005"
"87831","526.95001","74.30309","0.39097"
"87906","527.40002","74.34058","0.39164"
"87981","527.84998","74.37812","0.39293"
"88056","528.29999","74.41561","0.39454"
"88131","528.75000","74.45316","0.39567"
"88206","529.20001","74.49059","0.39818"
"88281","529.65002","74.52813","0.39926"
"88356","530.09998","74.56562","0.40119"
"88431","530.54999","74.60311","0.40301"
"88506","531.00000","74.64059","0.40513"
"88581","531.45001","74.67815","0.40690"
"88656","531.90002","74.71563","0.40874"
"88731","532.34998","74.75318","0.40992"
"88806","532.79999","74.79060","0.41198"
"88881","533.25000","74.82809","0.41390"
"88956","533.70001","74.86559","0.41612"
"89031","534.15002","74.90319","0.41775"
"89106","534.59998","74.94068","0.41905"
"89181","535.04999","74.97810","0.42163"
"89256","535.50000","75.01559","0.42380"
"89331","535.95001","75.05302","0.42595"
"89406","536.40002","75.09063","0.42730"
"89481","536.84998","75.12812","0.42946"
"89556","537.29999","75.16566","0.32898"
"89631","537.75000","75.20316","0.31946"
"89706","538.20001","75.24064","0.31794"
"89781","538.65002","75.27813","0.31744"
"89856","539.09998","75.31562","0.31852"
"89931","539.54999","75.35311","0.31876"
"90006","540.00000","75.39059","0.31918"
"90081","540.45001","75.42815","0.32006"
"90156","540.90002","75.46564","0.32081"
"90231","541.34998","75.50306","0.32205"
"90306","541.79999","75.54055","0.32212"
"90381","542.25000","75.57809","0.32268"
"90456","542.70001","75.61571","0.32281"
"90531","543.15002","75.65313","0.32358"
"90606","543.59998","75.69062","0.32491"
"90681","544.04999","75.72805","0.32559"
"90756","544.50000","75.76553","0.32721"
"90831","544.95001","75.80315","0.32909"
"90906","545.40002","75.84063","0.33083"
"90981","545.84998","75.87812","0.33246"
"91056","546.29999","75.91560","0.33423"
"91131","546.75000","75.95309","0.33557"
"91206","547.20001","75.99065","0.01871"
"91281","547.65002","76.02813","0.00662"
"91356","548.09998","76.06562","0.00985"
"91431","548.54999","76.10316","0.00671"
"91506","549.00000","76.14059","0.00784"
"91581","549.45001","76.17808","0.00763"
"91643","549.81799","76.20882","0.00692"