File: Trajectories_together/170122_2Specimen_RawData_2.csv
"","V1","V2","V3"
"1","End date","1/22/2017",""
"2","Specimen label","3CT_17_run2",""
"3","Maximum Load","0.29793","N"
"4","Time","Extension","Load"
"5","(s)","(mm)","(N)"
"6","0.00000","10.69796","0.03585"
"26","0.12000","10.70322","0.03665"
"46","0.24000","10.71602","0.03712"
"66","0.36000","10.72792","0.03705"
"86","0.48000","10.73826","0.03698"
"106","0.60000","10.74813","0.03702"
"126","0.72000","10.75811","0.03762"
"146","0.84000","10.76804","0.03857"
"166","0.96000","10.77814","0.03835"
"186","1.08000","10.78818","0.03802"
"206","1.20000","10.79811","0.03803"
"226","1.32000","10.80803","0.03842"
"246","1.44000","10.81802","0.03919"
"266","1.56000","10.82812","0.03911"
"286","1.68000","10.83811","0.03897"
"306","1.80000","10.84803","0.03879"
"326","1.92000","10.85802","0.03917"
"346","2.04000","10.86806","0.04004"
"366","2.16000","10.87811","0.04012"
"386","2.28000","10.88809","0.03931"
"406","2.40000","10.89802","0.03954"
"426","2.52000","10.90806","0.04008"
"446","2.64000","10.91811","0.04121"
"466","2.76000","10.92815","0.04086"
"486","2.88000","10.93808","0.04025"
"506","3.00000","10.94806","0.04023"
"526","3.12000","10.95811","0.04105"
"546","3.24000","10.96815","0.04173"
"566","3.36000","10.97814","0.04159"
"586","3.48000","10.98806","0.04102"
"606","3.60000","10.99804","0.04141"
"626","3.72000","11.00809","0.04208"
"646","3.84000","11.01813","0.04308"
"666","3.96000","11.02806","0.04240"
"686","4.08000","11.03811","0.04217"
"706","4.20000","11.04809","0.04254"
"726","4.32000","11.05807","0.04393"
"746","4.44000","11.06812","0.04430"
"766","4.56000","11.07804","0.04354"
"786","4.68000","11.08809","0.04346"
"806","4.80000","11.09813","0.04423"
"826","4.92000","11.10812","0.04518"
"846","5.04000","11.11810","0.04513"
"866","5.16000","11.12803","0.04505"
"886","5.28000","11.13813","0.04507"
"906","5.40000","11.14812","0.04671"
"926","5.52000","11.15804","0.04735"
"946","5.64000","11.16809","0.04711"
"966","5.76000","11.17807","0.04703"
"986","5.88000","11.18812","0.04691"
"1006","6.00000","11.19810","0.04849"
"1026","6.12000","11.20809","0.04968"
"1046","6.24000","11.21807","0.04897"
"1066","6.36000","11.22812","0.04890"
"1086","6.48000","11.23804","0.05026"
"1106","6.60000","11.24803","0.05133"
"1126","6.72000","11.25807","0.05169"
"1146","6.84000","11.26805","0.05081"
"1166","6.96000","11.27810","0.05103"
"1186","7.08000","11.28808","0.05257"
"1206","7.20000","11.29807","0.05367"
"1226","7.32000","11.30805","0.05345"
"1246","7.44000","11.31810","0.05371"
"1266","7.56000","11.32808","0.05464"
"1286","7.68000","11.33813","0.05559"
"1306","7.80000","11.34805","0.05620"
"1326","7.92000","11.35810","0.05597"
"1346","8.04000","11.36808","0.05619"
"1366","8.16000","11.37813","0.05734"
"1386","8.28000","11.38811","0.05879"
"1406","8.40000","11.39810","0.05841"
"1426","8.52000","11.40814","0.05857"
"1446","8.64000","11.41813","0.05891"
"1466","8.76000","11.42805","0.06072"
"1486","8.88000","11.43804","0.06106"
"1506","9.00000","11.44808","0.06122"
"1526","9.12000","11.45813","0.06129"
"1546","9.24000","11.46811","0.06233"
"1566","9.36000","11.47810","0.06287"
"1586","9.48000","11.48808","0.06354"
"1606","9.60000","11.49813","0.06294"
"1626","9.72000","11.50811","0.06434"
"1646","9.84000","11.51810","0.06525"
"1666","9.96000","11.52808","0.06577"
"1686","10.08000","11.53812","0.06567"
"1706","10.20000","11.54811","0.06596"
"1726","10.32000","11.55809","0.06738"
"1746","10.44000","11.56808","0.06771"
"1766","10.56000","11.57812","0.06791"
"1786","10.68000","11.58811","0.06827"
"1806","10.80000","11.59809","0.06895"
"1826","10.92000","11.60808","0.06964"
"1846","11.04000","11.61806","0.06994"
"1866","11.16000","11.62805","0.07034"
"1886","11.28000","11.63809","0.07048"
"1906","11.40000","11.64820","0.07150"
"1926","11.52000","11.65806","0.07206"
"1946","11.64000","11.66805","0.07209"
"1966","11.76000","11.67809","0.07188"
"1986","11.88000","11.68814","0.07287"
"2006","12.00000","11.69812","0.07357"
"2026","12.12000","11.70811","0.07411"
"2046","12.24000","11.71809","0.07430"
"2066","12.36000","11.72808","0.07518"
"2086","12.48000","11.73812","0.07611"
"2106","12.60000","11.74805","0.07682"
"2126","12.72000","11.75809","0.07668"
"2146","12.84000","11.76808","0.07783"
"2166","12.96000","11.77806","0.07760"
"2186","13.08000","11.78804","0.07918"
"2206","13.20000","11.79803","0.07954"
"2226","13.32000","11.80807","0.07973"
"2246","13.44000","11.81812","0.08025"
"2266","13.56000","11.82810","0.08123"
"2286","13.68000","11.83809","0.08145"
"2306","13.80000","11.84807","0.08263"
"2326","13.92000","11.85812","0.08302"
"2346","14.04000","11.86810","0.08452"
"2366","14.16000","11.87809","0.08498"
"2386","14.28000","11.88813","0.08541"
"2406","14.40000","11.89812","0.08510"
"2426","14.52000","11.90810","0.08635"
"2446","14.64000","11.91809","0.08628"
"2466","14.76000","11.92807","0.08647"
"2486","14.88000","11.93806","0.08710"
"2506","15.00000","11.94816","0.08772"
"2526","15.12000","11.95809","0.08800"
"2546","15.24000","11.96807","0.08840"
"2566","15.36000","11.97800","0.08850"
"2586","15.48000","11.98810","0.08884"
"2606","15.60000","11.99808","0.08942"
"2626","15.72000","12.00813","0.08931"
"2646","15.84000","12.01806","0.08959"
"2666","15.96000","12.02804","0.08999"
"2686","16.08000","12.03808","0.08996"
"2706","16.20000","12.04813","0.09035"
"2726","16.32000","12.05811","0.09061"
"2746","16.44000","12.06810","0.09039"
"2766","16.56000","12.07814","0.09084"
"2786","16.68000","12.08813","0.09076"
"2806","16.80000","12.09811","0.09084"
"2826","16.92000","12.10810","0.09110"
"2846","17.04000","12.11808","0.09115"
"2866","17.16000","12.12813","0.09130"
"2886","17.28000","12.13811","0.09154"
"2906","17.40000","12.14804","0.09164"
"2926","17.52000","12.15802","0.09190"
"2946","17.64000","12.16813","0.09182"
"2966","17.76000","12.17805","0.09183"
"2986","17.88000","12.18816","0.09240"
"3006","18.00000","12.19808","0.09261"
"3026","18.12000","12.20807","0.09258"
"3046","18.24000","12.21811","0.09290"
"3066","18.36000","12.22815","0.09313"
"3086","18.48000","12.23808","0.09373"
"3106","18.60000","12.24800","0.09411"
"3126","18.72000","12.25811","0.09475"
"3146","18.84000","12.26809","0.09507"
"3166","18.96000","12.27808","0.09598"
"3186","19.08000","12.28806","0.09626"
"3206","19.20000","12.29805","0.09665"
"3226","19.32000","12.30815","0.09723"
"3246","19.44000","12.31814","0.09818"
"3266","19.56000","12.32806","0.09888"
"3286","19.68000","12.33805","0.10052"
"3306","19.80000","12.34809","0.10092"
"3326","19.92000","12.35808","0.10086"
"3346","20.04000","12.36812","0.10232"
"3366","20.16000","12.37811","0.10333"
"3386","20.28000","12.38809","0.10371"
"3406","20.40000","12.39814","0.10421"
"3426","20.52000","12.40812","0.10505"
"3446","20.64000","12.41811","0.10609"
"3466","20.76000","12.42809","0.10675"
"3486","20.88000","12.43808","0.10772"
"3506","21.00000","12.44812","0.10854"
"3526","21.12000","12.45811","0.10882"
"3546","21.24000","12.46803","0.10923"
"3566","21.36000","12.47808","0.11024"
"3586","21.48000","12.48812","0.11117"
"3606","21.60000","12.49816","0.11216"
"3626","21.72000","12.50809","0.11265"
"3646","21.84000","12.51801","0.11316"
"3666","21.96000","12.52812","0.11376"
"3686","22.08000","12.53810","0.11483"
"3706","22.20000","12.54815","0.11453"
"3726","22.32000","12.55807","0.11612"
"3746","22.44000","12.56812","0.11640"
"3766","22.56000","12.57810","0.11690"
"3786","22.68000","12.58809","0.11756"
"3806","22.80000","12.59813","0.11820"
"3826","22.92000","12.60806","0.11854"
"3846","23.04000","12.61810","0.11940"
"3866","23.16000","12.62815","0.11976"
"3886","23.28000","12.63813","0.12043"
"3906","23.40000","12.64806","0.12073"
"3926","23.52000","12.65804","0.12135"
"3946","23.64000","12.66809","0.12173"
"3966","23.76000","12.67813","0.12224"
"3986","23.88000","12.68812","0.12262"
"4006","24.00000","12.69804","0.12296"
"4026","24.12000","12.70809","0.12343"
"4046","24.24000","12.71807","0.12405"
"4066","24.36000","12.72806","0.12411"
"4086","24.48000","12.73810","0.12467"
"4106","24.60000","12.74809","0.12493"
"4126","24.72000","12.75813","0.12527"
"4146","24.84000","12.76812","0.12558"
"4166","24.96000","12.77810","0.12570"
"4186","25.08000","12.78808","0.12605"
"4206","25.20000","12.79813","0.12651"
"4226","25.32000","12.80811","0.12683"
"4246","25.44000","12.81810","0.12701"
"4266","25.56000","12.82802","0.12764"
"4286","25.68000","12.83807","0.12789"
"4306","25.80000","12.84811","0.12799"
"4326","25.92000","12.85810","0.12872"
"4346","26.04000","12.86808","0.12904"
"4366","26.16000","12.87807","0.12932"
"4386","26.28000","12.88811","0.12956"
"4406","26.40000","12.89816","0.13014"
"4426","26.52000","12.90814","0.13003"
"4446","26.64000","12.91807","0.13104"
"4466","26.76000","12.92811","0.13110"
"4486","26.88000","12.93816","0.13172"
"4506","27.00000","12.94814","0.13177"
"4526","27.12000","12.95807","0.13274"
"4546","27.24000","12.96799","0.13244"
"4566","27.36000","12.97816","0.13302"
"4586","27.48000","12.98814","0.13356"
"4606","27.60000","12.99812","0.13387"
"4626","27.72000","13.00805","0.13437"
"4646","27.84000","13.01803","0.13482"
"4666","27.96000","13.02808","0.13521"
"4686","28.08000","13.03813","0.13579"
"4706","28.20000","13.04811","0.13592"
"4726","28.32000","13.05809","0.13610"
"4746","28.44000","13.06808","0.13669"
"4766","28.56000","13.07812","0.13715"
"4786","28.68000","13.08811","0.13762"
"4806","28.80000","13.09803","0.13767"
"4826","28.92000","13.10808","0.13813"
"4846","29.04000","13.11812","0.13869"
"4866","29.16000","13.12811","0.13872"
"4886","29.28000","13.13809","0.13896"
"4906","29.40000","13.14808","0.13941"
"4926","29.52000","13.15812","0.13957"
"4946","29.64000","13.16817","0.13982"
"4966","29.76000","13.17809","0.14029"
"4986","29.88000","13.18802","0.14039"
"5006","30.00000","13.19806","0.14071"
"5026","30.12000","13.20811","0.14109"
"5046","30.24000","13.21809","0.14156"
"5066","30.36000","13.22802","0.14196"
"5086","30.48000","13.23806","0.14227"
"5106","30.60000","13.24811","0.14272"
"5126","30.72000","13.25815","0.14328"
"5146","30.84000","13.26807","0.14376"
"5166","30.96000","13.27806","0.14391"
"5186","31.08000","13.28811","0.14433"
"5206","31.20000","13.29815","0.14488"
"5226","31.32000","13.30813","0.14525"
"5246","31.44000","13.31806","0.14607"
"5266","31.56000","13.32804","0.14675"
"5286","31.68000","13.33815","0.14727"
"5306","31.80000","13.34813","0.14763"
"5326","31.92000","13.35812","0.14893"
"5346","32.04000","13.36804","0.14976"
"5366","32.16000","13.37809","0.14995"
"5386","32.28000","13.38807","0.15135"
"5406","32.40000","13.39812","0.15237"
"5426","32.52000","13.40810","0.15259"
"5446","32.64000","13.41809","0.15344"
"5466","32.76000","13.42813","0.15393"
"5486","32.88000","13.43812","0.15459"
"5506","33.00000","13.44804","0.15611"
"5526","33.12000","13.45809","0.15701"
"5546","33.24000","13.46813","0.15799"
"5566","33.36000","13.47818","0.15987"
"5586","33.48000","13.48816","0.16114"
"5606","33.60000","13.49809","0.16168"
"5626","33.72000","13.50813","0.16327"
"5646","33.84000","13.51812","0.16414"
"5666","33.96000","13.52810","0.16547"
"5686","34.08000","13.53808","0.16693"
"5706","34.20000","13.54801","0.16962"
"5726","34.32000","13.55811","0.17046"
"5746","34.44000","13.56810","0.17183"
"5766","34.56000","13.57808","0.17261"
"5786","34.68000","13.58807","0.17565"
"5806","34.80000","13.59811","0.17577"
"5826","34.92000","13.60816","0.17702"
"5846","35.04000","13.61814","0.17816"
"5866","35.16000","13.62807","0.17905"
"5886","35.28000","13.63799","0.18031"
"5906","35.40000","13.64816","0.18246"
"5926","35.52000","13.65814","0.18352"
"5946","35.64000","13.66813","0.18384"
"5966","35.76000","13.67805","0.18606"
"5986","35.88000","13.68804","0.18728"
"6006","36.00000","13.69814","0.18743"
"6026","36.12000","13.70813","0.18807"
"6046","36.24000","13.71805","0.18966"
"6066","36.36000","13.72804","0.18925"
"6086","36.48000","13.73808","0.19034"
"6106","36.60000","13.74812","0.19029"
"6126","36.72000","13.75811","0.19104"
"6146","36.84000","13.76803","0.19195"
"6166","36.96000","13.77808","0.19177"
"6186","37.08000","13.78812","0.19269"
"6206","37.20000","13.79811","0.19293"
"6226","37.32000","13.80803","0.19337"
"6246","37.44000","13.81802","0.19359"
"6266","37.56000","13.82812","0.19387"
"6286","37.68000","13.83811","0.19406"
"6306","37.80000","13.84809","0.19436"
"6326","37.92000","13.85808","0.19468"
"6346","38.04000","13.86806","0.19495"
"6366","38.16000","13.87811","0.19551"
"6386","38.28000","13.88815","0.19555"
"6406","38.40000","13.89808","0.19598"
"6426","38.52000","13.90806","0.19585"
"6446","38.64000","13.91811","0.19648"
"6466","38.76000","13.92809","0.19699"
"6486","38.88000","13.93808","0.19682"
"6506","39.00000","13.94800","0.19771"
"6526","39.12000","13.95811","0.19781"
"6546","39.24000","13.96815","0.19793"
"6566","39.36000","13.97814","0.19873"
"6586","39.48000","13.98812","0.19982"
"6606","39.60000","13.99804","0.20010"
"6626","39.72000","14.00809","0.20065"
"6646","39.84000","14.01808","0.20144"
"6666","39.96000","14.02818","0.20127"
"6686","40.08000","14.03811","0.20181"
"6706","40.20000","14.04809","0.20310"
"6726","40.32000","14.05813","0.20394"
"6746","40.44000","14.06812","0.20422"
"6766","40.56000","14.07810","0.20383"
"6786","40.68000","14.08809","0.20445"
"6806","40.80000","14.09813","0.20634"
"6826","40.92000","14.10806","0.20709"
"6846","41.04000","14.11804","0.20754"
"6866","41.16000","14.12803","0.20837"
"6886","41.28000","14.13807","0.20937"
"6906","41.40000","14.14812","0.21056"
"6926","41.52000","14.15810","0.21118"
"6946","41.64000","14.16809","0.21182"
"6966","41.76000","14.17807","0.21277"
"6986","41.88000","14.18812","0.21284"
"7006","42.00000","14.19810","0.21413"
"7026","42.12000","14.20809","0.21485"
"7046","42.24000","14.21807","0.21503"
"7066","42.36000","14.22812","0.21591"
"7086","42.48000","14.23810","0.21565"
"7106","42.60000","14.24815","0.21656"
"7126","42.72000","14.25807","0.21721"
"7146","42.84000","14.26811","0.21758"
"7166","42.96000","14.27816","0.21818"
"7186","43.08000","14.28808","0.21875"
"7206","43.20000","14.29807","0.21963"
"7226","43.32000","14.30799","0.21984"
"7246","43.44000","14.31810","0.21933"
"7266","43.56000","14.32814","0.22061"
"7286","43.68000","14.33813","0.22137"
"7306","43.80000","14.34805","0.22152"
"7326","43.92000","14.35804","0.22159"
"7346","44.04000","14.36814","0.22198"
"7366","44.16000","14.37813","0.22333"
"7386","44.28000","14.38811","0.22334"
"7406","44.40000","14.39810","0.22400"
"7426","44.52000","14.40808","0.22446"
"7446","44.64000","14.41813","0.22487"
"7466","44.76000","14.42811","0.22576"
"7486","44.88000","14.43810","0.22637"
"7506","45.00000","14.44808","0.22691"
"7526","45.12000","14.45813","0.22697"
"7546","45.24000","14.46817","0.22766"
"7566","45.36000","14.47810","0.22830"
"7586","45.48000","14.48808","0.22851"
"7606","45.60000","14.49813","0.22907"
"7626","45.72000","14.50811","0.22946"
"7646","45.84000","14.51816","0.22980"
"7666","45.96000","14.52808","0.23027"
"7686","46.08000","14.53806","0.23134"
"7706","46.20000","14.54805","0.23106"
"7726","46.32000","14.55815","0.23209"
"7746","46.44000","14.56808","0.23229"
"7766","46.56000","14.57806","0.23208"
"7786","46.68000","14.58811","0.23272"
"7806","46.80000","14.59809","0.23335"
"7826","46.92000","14.60814","0.23340"
"7846","47.04000","14.61806","0.23398"
"7866","47.16000","14.62811","0.23435"
"7886","47.28000","14.63809","0.23400"
"7906","47.40000","14.64814","0.23495"
"7926","47.52000","14.65812","0.23530"
"7946","47.64000","14.66805","0.23546"
"7966","47.76000","14.67809","0.23607"
"7986","47.88000","14.68814","0.23633"
"8006","48.00000","14.69812","0.23647"
"8026","48.12000","14.70805","0.23683"
"8046","48.24000","14.71803","0.23695"
"8066","48.36000","14.72808","0.23743"
"8086","48.48000","14.73812","0.23732"
"8106","48.60000","14.74805","0.23767"
"8126","48.72000","14.75809","0.23783"
"8146","48.84000","14.76807","0.23823"
"8166","48.96000","14.77806","0.23826"
"8186","49.08000","14.78810","0.23857"
"8206","49.20000","14.79809","0.23870"
"8226","49.32000","14.80807","0.23866"
"8246","49.44000","14.81812","0.23875"
"8266","49.56000","14.82810","0.23907"
"8286","49.68000","14.83809","0.23924"
"8306","49.80000","14.84807","0.23938"
"8326","49.92000","14.85812","0.23950"
"8346","50.04000","14.86810","0.23942"
"8366","50.16000","14.87815","0.23970"
"8386","50.28000","14.88807","0.23992"
"8406","50.40000","14.89806","0.23992"
"8426","50.52000","14.90810","0.23987"
"8446","50.64000","14.91809","0.24016"
"8466","50.76000","14.92807","0.24016"
"8486","50.88000","14.93806","0.24038"
"8506","51.00000","14.94810","0.24050"
"8526","51.12000","14.95815","0.24056"
"8546","51.24000","14.96807","0.24081"
"8566","51.36000","14.97806","0.24075"
"8586","51.48000","14.98810","0.24107"
"8606","51.60000","14.99814","0.24099"
"8626","51.72000","15.00813","0.24111"
"8646","51.84000","15.01805","0.24123"
"8666","51.96000","15.02804","0.24139"
"8686","52.08000","15.03808","0.24122"
"8706","52.20000","15.04813","0.24135"
"8726","52.32000","15.05811","0.24131"
"8746","52.44000","15.06810","0.24177"
"8766","52.56000","15.07808","0.24171"
"8786","52.68000","15.08807","0.24200"
"8806","52.80000","15.09811","0.24208"
"8826","52.92000","15.10810","0.24230"
"8846","53.04000","15.11802","0.24227"
"8866","53.16000","15.12813","0.24241"
"8886","53.28000","15.13811","0.24250"
"8906","53.40000","15.14810","0.24284"
"8926","53.52000","15.15808","0.24281"
"8946","53.64000","15.16807","0.24311"
"8966","53.76000","15.17811","0.24289"
"8986","53.88000","15.18816","0.24325"
"9006","54.00000","15.19808","0.24335"
"9026","54.12000","15.20807","0.24328"
"9046","54.24000","15.21805","0.24353"
"9066","54.36000","15.22816","0.24382"
"9086","54.48000","15.23814","0.24423"
"9106","54.60000","15.24806","0.24414"
"9126","54.72000","15.25811","0.24433"
"9146","54.84000","15.26809","0.24447"
"9166","54.96000","15.27814","0.24472"
"9186","55.08000","15.28806","0.24497"
"9206","55.20000","15.29805","0.24498"
"9226","55.32000","15.30809","0.24513"
"9246","55.44000","15.31814","0.24547"
"9266","55.56000","15.32806","0.24553"
"9286","55.68000","15.33805","0.24615"
"9306","55.80000","15.34809","0.24622"
"9326","55.92000","15.35808","0.24640"
"9346","56.04000","15.36812","0.24675"
"9366","56.16000","15.37811","0.24722"
"9386","56.28000","15.38803","0.24755"
"9406","56.40000","15.39808","0.24767"
"9426","56.52000","15.40806","0.24852"
"9446","56.64000","15.41811","0.24885"
"9466","56.76000","15.42809","0.24892"
"9486","56.88000","15.43808","0.24967"
"9506","57.00000","15.44812","0.25022"
"9526","57.12000","15.45811","0.25033"
"9546","57.24000","15.46809","0.25118"
"9566","57.36000","15.47808","0.25152"
"9586","57.48000","15.48812","0.25207"
"9606","57.60000","15.49817","0.25265"
"9626","57.72000","15.50809","0.25323"
"9646","57.84000","15.51807","0.25322"
"9666","57.96000","15.52806","0.25403"
"9686","58.08000","15.53810","0.25528"
"9706","58.20000","15.54809","0.25601"
"9726","58.32000","15.55807","0.25689"
"9746","58.44000","15.56806","0.25772"
"9766","58.56000","15.57810","0.25869"
"9786","58.68000","15.58815","0.25937"
"9806","58.80000","15.59807","0.25956"
"9826","58.92000","15.60812","0.26000"
"9846","59.04000","15.61810","0.26144"
"9866","59.16000","15.62809","0.26242"
"9886","59.28000","15.63813","0.26323"
"9906","59.40000","15.64806","0.26417"
"9926","59.52000","15.65804","0.26480"
"9946","59.64000","15.66815","0.26582"
"9966","59.76000","15.67813","0.26650"
"9986","59.88000","15.68812","0.26822"
"10006","60.00000","15.69804","0.26814"
"10026","60.12000","15.70809","0.26951"
"10046","60.24000","15.71807","0.26988"
"10066","60.36000","15.72811","0.27055"
"10086","60.48000","15.73810","0.27132"
"10106","60.60000","15.74808","0.27197"
"10126","60.72000","15.75813","0.27308"
"10146","60.84000","15.76811","0.27375"
"10166","60.96000","15.77810","0.27503"
"10186","61.08000","15.78808","0.27541"
"10206","61.20000","15.79807","0.27683"
"10226","61.32000","15.80811","0.27766"
"10246","61.44000","15.81810","0.27909"
"10266","61.56000","15.82808","0.27961"
"10286","61.68000","15.83801","0.28026"
"10306","61.80000","15.84811","0.28138"
"10326","61.92000","15.85816","0.28213"
"10346","62.04000","15.86814","0.28347"
"10366","62.16000","15.87807","0.28405"
"10386","62.28000","15.88811","0.28400"
"10406","62.40000","15.89816","0.28470"
"10426","62.52000","15.90814","0.28598"
"10446","62.64000","15.91807","0.28573"
"10466","62.76000","15.92805","0.28669"
"10486","62.88000","15.93810","0.28647"
"10506","63.00000","15.94814","0.28746"
"10526","63.12000","15.95813","0.28720"
"10546","63.24000","15.96805","0.28768"
"10566","63.36000","15.97809","0.28835"
"10586","63.48000","15.98814","0.28880"
"10606","63.60000","15.99813","0.28895"
"10626","63.72000","16.00805","0.28955"
"10646","63.84000","16.01803","0.28965"
"10666","63.96000","16.02808","0.29031"
"10686","64.08000","16.03812","0.29056"
"10706","64.20000","16.04811","0.29097"
"10726","64.32000","16.05803","0.29110"
"10746","64.44000","16.06808","0.29211"
"10766","64.56000","16.07806","0.29225"
"10786","64.68000","16.08811","0.29313"
"10806","64.80000","16.09809","0.29335"
"10826","64.92000","16.10808","0.29384"
"10846","65.04000","16.11812","0.29487"
"10866","65.16000","16.12811","0.29525"
"10886","65.28000","16.13809","0.29609"
"10906","65.40000","16.14808","0.29630"
"10926","65.52000","16.15812","0.29725"
"10946","65.64000","16.16817","0.29698"
"10966","65.76000","16.17809","0.29511"
"10986","65.88000","16.18808","0.29385"
"11006","66.00000","16.19806","0.01608"
"11026","66.12000","16.20811","0.02156"
"11046","66.24000","16.21815","0.02061"
"11066","66.36000","16.22808","0.02085"
"11086","66.48000","16.23806","0.01074"
"11106","66.60000","16.24811","0.01532"
"11126","66.72000","16.25809","0.02864"
"11146","66.84000","16.26814","0.02521"
"11166","66.96000","16.27806","0.01588"
"11186","67.08000","16.28810","0.01669"
"11206","67.20000","16.29815","0.02799"
"11226","67.32000","16.30807","0.02729"
"11246","67.44000","16.31806","0.01781"
"11266","67.56000","16.32804","0.01727"
"11286","67.68000","16.33809","0.02717"
"11306","67.80000","16.34813","0.02877"
"11326","67.92000","16.35812","0.01957"
"11346","68.04000","16.36804","0.01759"
"11366","68.16000","16.37809","0.02584"
"11386","68.28000","16.38813","0.03109"
"11406","68.40000","16.39812","0.02150"
"11426","68.52000","16.40810","0.01755"
"11446","68.64000","16.41803","0.02513"
"11466","68.76000","16.42813","0.03154"
"11486","68.88000","16.43812","0.02456"
"11506","69.00000","16.44804","0.01849"
"11526","69.12000","16.45808","0.02402"
"11546","69.24000","16.46813","0.03067"
"11566","69.36000","16.47818","0.02719"
"11586","69.48000","16.48810","0.02022"
"11606","69.60000","16.49809","0.02456"
"11626","69.72000","16.50801","0.03101"
"11646","69.84000","16.51811","0.02867"
"11666","69.96000","16.52810","0.02142"
"11686","70.08000","16.53814","0.02314"
"11706","70.20000","16.54807","0.03087"
"11726","70.32000","16.55811","0.02975"
"11746","70.44000","16.56816","0.02270"
"11766","70.56000","16.57814","0.02326"
"11786","70.68000","16.58807","0.03024"
"11806","70.80000","16.59811","0.03059"
"11826","70.92000","16.60804","0.02374"
"11846","71.04000","16.61814","0.02379"
"11866","71.16000","16.62807","0.03023"
"11886","71.28000","16.63811","0.03197"
"11906","71.40000","16.64810","0.02659"
"11926","71.52000","16.65814","0.02396"
"11946","71.64000","16.66813","0.03072"
"11966","71.76000","16.67805","0.03259"
"11986","71.88000","16.68804","0.02798"
"12006","72.00000","16.69814","0.02515"
"12026","72.12000","16.70812","0.03103"
"12046","72.24000","16.71817","0.03306"
"12066","72.36000","16.72803","0.02857"
"12086","72.48000","16.73808","0.02686"
"12106","72.60000","16.74813","0.03188"
"12126","72.72000","16.75811","0.03416"
"12146","72.84000","16.76815","0.02987"
"12166","72.96000","16.77808","0.02750"
"12186","73.08000","16.78812","0.03218"
"12206","73.20000","16.79811","0.03453"
"12226","73.32000","16.80809","0.03093"
"12246","73.44000","16.81808","0.02831"
"12266","73.56000","16.82806","0.03189"
"12286","73.68000","16.83811","0.03526"
"12306","73.80000","16.84809","0.03167"
"12326","73.92000","16.85808","0.02988"
"12346","74.04000","16.86806","0.03381"
"12366","74.16000","16.87811","0.03516"
"12386","74.28000","16.88809","0.03325"
"12406","74.40000","16.89808","0.03092"
"12426","74.52000","16.90806","0.03461"
"12446","74.64000","16.91805","0.03591"
"12466","74.76000","16.92809","0.03305"
"12486","74.88000","16.93808","0.03194"
"12506","75.00000","16.94812","0.03452"
"12526","75.12000","16.95811","0.03630"
"12546","75.24000","16.96815","0.03454"
"12566","75.36000","16.97814","0.03321"
"12586","75.48000","16.98806","0.03577"
"12606","75.60000","16.99810","0.03634"
"12626","75.72000","17.00809","0.03456"
"12646","75.84000","17.01819","0.03429"
"12666","75.96000","17.02818","0.03619"
"12686","76.08000","17.03810","0.03763"
"12706","76.20000","17.04809","0.03574"
"12726","76.32000","17.05813","0.03522"
"12746","76.44000","17.06812","0.03695"
"12766","76.56000","17.07810","0.03745"
"12786","76.68000","17.08809","0.03623"
"12806","76.80000","17.09813","0.03613"
"12826","76.92000","17.10812","0.03734"
"12846","77.04000","17.11810","0.03756"
"12866","77.16000","17.12809","0.03509"
"12886","77.28000","17.13807","0.03531"
"12906","77.40000","17.14812","0.03657"
"12926","77.52000","17.15810","0.03695"
"12946","77.64000","17.16809","0.03607"
"12966","77.76000","17.17807","0.03596"
"12986","77.88000","17.18806","0.03734"
"13006","78.00000","17.19810","0.03717"
"13026","78.12000","17.20814","0.03623"
"13046","78.24000","17.21807","0.03635"
"13066","78.36000","17.22806","0.03764"
"13086","78.48000","17.23810","0.03778"
"13106","78.60000","17.24809","0.03651"
"13126","78.72000","17.25813","0.03708"
"13146","78.84000","17.26805","0.03874"
"13166","78.96000","17.27810","0.03817"
"13186","79.08000","17.28808","0.03721"
"13206","79.20000","17.29813","0.03781"
"13226","79.32000","17.30805","0.03894"
"13246","79.44000","17.31810","0.03840"
"13266","79.56000","17.32808","0.03801"
"13286","79.68000","17.33807","0.03835"
"13306","79.80000","17.34805","0.03922"
"13326","79.92000","17.35804","0.03888"
"13346","80.04000","17.36808","0.03856"
"13366","80.16000","17.37813","0.03870"
"13386","80.28000","17.38817","0.03947"
"13406","80.40000","17.39804","0.03815"
"13426","80.52000","17.40802","0.03700"
"13446","80.64000","17.41813","0.03785"
"13466","80.76000","17.42811","0.03664"
"13486","80.88000","17.43810","0.03606"
"13506","81.00000","17.44808","0.03546"
"13526","81.12000","17.45812","0.03656"
"13546","81.24000","17.46805","0.03645"
"13566","81.36000","17.47810","0.03611"
"13586","81.48000","17.48808","0.03603"
"13606","81.60000","17.49806","0.03647"
"13626","81.72000","17.50811","0.03692"
"13646","81.84000","17.51809","0.03566"
"13666","81.96000","17.52808","0.03568"
"13686","82.08000","17.53800","0.03686"
"13706","82.20000","17.54811","0.03758"
"13726","82.32000","17.55815","0.03714"
"13746","82.44000","17.56814","0.03747"
"13766","82.56000","17.57812","0.03797"
"13786","82.68000","17.58805","0.03847"
"13806","82.80000","17.59809","0.03757"
"13826","82.92000","17.60808","0.03770"
"13846","83.04000","17.61812","0.03841"
"13866","83.16000","17.62811","0.03830"
"13886","83.28000","17.63815","0.03796"
"13906","83.40000","17.64814","0.03873"
"13926","83.52000","17.65812","0.03891"
"13946","83.64000","17.66811","0.03937"
"13966","83.76000","17.67809","0.03885"
"13986","83.88000","17.68819","0.03946"
"14006","84.00000","17.69812","0.03953"
"14026","84.12000","17.70804","0.03951"
"14046","84.24000","17.71803","0.03899"
"14066","84.36000","17.72808","0.03986"
"14086","84.48000","17.73812","0.04006"
"14106","84.60000","17.74810","0.04016"
"14126","84.72000","17.75809","0.03990"
"14146","84.84000","17.76807","0.04009"
"14166","84.96000","17.77812","0.04007"
"14186","85.08000","17.78810","0.03971"
"14206","85.20000","17.79803","0.04009"
"14226","85.32000","17.80801","0.04085"
"14246","85.44000","17.81812","0.04041"
"14266","85.56000","17.82810","0.03972"
"14286","85.68000","17.83815","0.04019"
"14306","85.80000","17.84807","0.04101"
"14326","85.92000","17.85812","0.04107"
"14346","86.04000","17.86816","0.04053"
"14366","86.16000","17.87815","0.04100"
"14386","86.28000","17.88807","0.04153"
"14406","86.40000","17.89806","0.04160"
"14426","86.52000","17.90810","0.04121"
"14446","86.64000","17.91809","0.04190"
"14466","86.76000","17.92813","0.04172"
"14486","86.88000","17.93806","0.04157"
"14506","87.00000","17.94804","0.04203"
"14526","87.12000","17.95809","0.04278"
"14546","87.24000","17.96813","0.04284"
"14566","87.36000","17.97812","0.04256"
"14586","87.48000","17.98804","0.04352"
"14606","87.60000","17.99814","0.04407"
"14626","87.72000","18.00813","0.04364"
"14646","87.84000","18.01805","0.04409"
"14666","87.96000","18.02810","0.04439"
"14686","88.08000","18.03808","0.04545"
"14706","88.20000","18.04813","0.04531"
"14726","88.32000","18.05817","0.04438"
"14746","88.44000","18.06810","0.04346"
"14766","88.56000","18.07802","0.04353"
"14786","88.68000","18.08807","0.04258"
"14806","88.80000","18.09811","0.04202"
"14826","88.92000","18.10810","0.04233"
"14846","89.04000","18.11808","0.04207"
"14866","89.16000","18.12807","0.04119"
"14886","89.28000","18.13811","0.04123"
"14906","89.40000","18.14810","0.04131"
"14926","89.52000","18.15808","0.04149"
"14946","89.64000","18.16807","0.04171"
"14966","89.76000","18.17811","0.04149"
"14986","89.88000","18.18816","0.04209"
"15006","90.00000","18.19808","0.04209"
"15026","90.12000","18.20807","0.04219"
"15046","90.24000","18.21811","0.04264"
"15066","90.36000","18.22809","0.04281"
"15086","90.48000","18.23814","0.04377"
"15106","90.60000","18.24812","0.04421"
"15126","90.72000","18.25805","0.04498"
"15146","90.84000","18.26809","0.04548"
"15166","90.96000","18.27814","0.04613"
"15186","91.08000","18.28812","0.04663"
"15206","91.20000","18.29805","0.04725"
"15226","91.32000","18.30809","0.04745"
"15246","91.44000","18.31808","0.04799"
"15266","91.56000","18.32806","0.04840"
"15286","91.68000","18.33805","0.04885"
"15306","91.80000","18.34803","0.04955"
"15326","91.92000","18.35814","0.05041"
"15346","92.04000","18.36812","0.05072"
"15366","92.16000","18.37811","0.05147"
"15386","92.28000","18.38809","0.05252"
"15406","92.40000","18.39808","0.05259"
"15426","92.52000","18.40812","0.05310"
"15446","92.64000","18.41811","0.05412"
"15466","92.76000","18.42809","0.05453"
"15486","92.88000","18.43807","0.05469"
"15506","93.00000","18.44806","0.05540"
"15526","93.12000","18.45811","0.05584"
"15546","93.24000","18.46809","0.05731"
"15566","93.36000","18.47802","0.05722"
"15586","93.48000","18.48812","0.05885"
"15606","93.60000","18.49810","0.05920"
"15626","93.72000","18.50809","0.06002"
"15646","93.84000","18.51801","0.06035"
"15666","93.96000","18.52806","0.06077"
"15686","94.08000","18.53816","0.06179"
"15706","94.20000","18.54815","0.06247"
"15726","94.32000","18.55813","0.06240"
"15746","94.44000","18.56806","0.06294"
"15766","94.56000","18.57810","0.06437"
"15786","94.68000","18.58809","0.06541"
"15806","94.80000","18.59807","0.06641"
"15826","94.92000","18.60806","0.06721"
"15846","95.04000","18.61804","0.06786"
"15866","95.16000","18.62809","0.06831"
"15886","95.28000","18.63813","0.06912"
"15906","95.40000","18.64806","0.06994"
"15926","95.52000","18.65804","0.07018"
"15946","95.64000","18.66814","0.07093"
"15966","95.76000","18.67819","0.07178"
"15986","95.88000","18.68812","0.07238"
"16006","96.00000","18.69804","0.07144"
"16026","96.12000","18.70809","0.07265"
"16046","96.24000","18.71813","0.07369"
"16066","96.36000","18.72817","0.07467"
"16086","96.48000","18.73810","0.07436"
"16106","96.60000","18.74802","0.07465"
"16126","96.72000","18.75807","0.07562"
"16146","96.84000","18.76811","0.07732"
"16166","96.96000","18.77810","0.07811"
"16186","97.08000","18.78808","0.07881"
"16206","97.20000","18.79807","0.08127"
"16226","97.32000","18.80805","0.08247"
"16246","97.44000","18.81810","0.08390"
"16266","97.56000","18.82808","0.08436"
"16286","97.68000","18.83801","0.08551"
"16306","97.80000","18.84811","0.08557"
"16326","97.92000","18.85816","0.08610"
"16346","98.04000","18.86814","0.08719"
"16366","98.16000","18.87807","0.08818"
"16386","98.28000","18.88805","0.08851"
"16406","98.40000","18.89810","0.08947"
"16426","98.52000","18.90814","0.08938"
"16446","98.64000","18.91813","0.08974"
"16466","98.76000","18.92811","0.08996"
"16486","98.88000","18.93810","0.09031"
"16506","99.00000","18.94814","0.08607"
"16526","99.12000","18.95813","0.08613"
"16546","99.24000","18.96811","0.08777"
"16566","99.36000","18.97809","0.08997"
"16586","99.48000","18.98814","0.08991"
"16606","99.60000","18.99806","0.08936"
"16626","99.72000","19.00811","0.09060"
"16646","99.84000","19.01803","0.09085"
"16666","99.96000","19.02814","0.09070"
"16686","100.08000","19.03812","0.09109"
"16706","100.20000","19.04811","0.09163"
"16726","100.32000","19.05803","0.09180"
"16746","100.44000","19.06808","0.09181"
"16766","100.56000","19.07812","0.09241"
"16786","100.68000","19.08817","0.09336"
"16806","100.80000","19.09815","0.09358"
"16826","100.92000","19.10808","0.09369"
"16846","101.04000","19.11812","0.09319"
"16866","101.16000","19.12811","0.09404"
"16886","101.28000","19.13809","0.09457"
"16906","101.40000","19.14808","0.09639"
"16926","101.52000","19.15812","0.09663"
"16946","101.64000","19.16817","0.09800"
"16966","101.76000","19.17809","0.09755"
"16986","101.88000","19.18808","0.09737"
"17006","102.00000","19.19812","0.09932"
"17026","102.12000","19.20811","0.10088"
"17046","102.24000","19.21809","0.10201"
"17066","102.36000","19.22813","0.09951"
"17086","102.48000","19.23806","0.09961"
"17106","102.60000","19.24810","0.10313"
"17126","102.72000","19.25815","0.10969"
"17146","102.84000","19.26814","0.09933"
"17166","102.96000","19.27812","0.09598"
"17186","103.08000","19.28810","0.10826"
"17206","103.20000","19.29815","0.11230"
"17226","103.32000","19.30807","0.10372"
"17246","103.44000","19.31812","0.10573"
"17266","103.56000","19.32804","0.11511"
"17286","103.68000","19.33809","0.11470"
"17306","103.80000","19.34813","0.10906"
"17326","103.92000","19.35812","0.11352"
"17346","104.04000","19.36810","0.11994"
"17366","104.16000","19.37803","0.11732"
"17386","104.28000","19.38813","0.11554"
"17406","104.40000","19.39812","0.12089"
"17426","104.52000","19.40816","0.12264"
"17446","104.64000","19.41809","0.11920"
"17466","104.76000","19.42807","0.12071"
"17486","104.88000","19.43818","0.12436"
"17506","105.00000","19.44816","0.12356"
"17526","105.12000","19.45815","0.12197"
"17546","105.24000","19.46807","0.12471"
"17566","105.36000","19.47805","0.12610"
"17586","105.48000","19.48810","0.12557"
"17606","105.60000","19.49808","0.12579"
"17626","105.72000","19.50801","0.12805"
"17646","105.84000","19.51811","0.12798"
"17666","105.96000","19.52810","0.12623"
"17686","106.08000","19.53814","0.12490"
"17706","106.20000","19.54807","0.06216"
"17726","106.32000","19.55805","0.07972"
"17746","106.44000","19.56810","0.06578"
"17766","106.56000","19.57808","0.05442"
"17786","106.68000","19.58813","0.06045"
"17806","106.80000","19.59805","0.07249"
"17826","106.92000","19.60804","0.07106"
"17846","107.04000","19.61808","0.05876"
"17866","107.16000","19.62813","0.05989"
"17886","107.28000","19.63805","0.06852"
"17906","107.40000","19.64810","0.07661"
"17926","107.52000","19.65814","0.06494"
"17946","107.64000","19.66806","0.06527"
"17966","107.76000","19.67811","0.06746"
"17986","107.88000","19.68810","0.07974"
"18006","108.00000","19.69808","0.07004"
"18026","108.12000","19.70812","0.06625"
"18046","108.24000","19.71811","0.06763"
"18066","108.36000","19.72803","0.07914"
"18086","108.48000","19.73802","0.07517"
"18106","108.60000","19.74806","0.07054"
"18126","108.72000","19.75811","0.07064"
"18146","108.84000","19.76815","0.07945"
"18166","108.96000","19.77808","0.08227"
"18186","109.08000","19.78806","0.07325"
"18206","109.20000","19.79811","0.07170"
"18226","109.32000","19.80815","0.07946"
"18246","109.44000","19.81808","0.08544"
"18266","109.56000","19.82812","0.07673"
"18286","109.68000","19.83811","0.07418"
"18306","109.80000","19.84809","0.08113"
"18326","109.92000","19.85808","0.08751"
"18346","110.04000","19.86806","0.08099"
"18366","110.16000","19.87805","0.07664"
"18386","110.28000","19.88809","0.08203"
"18406","110.40000","19.89808","0.08903"
"18426","110.52000","19.90806","0.08417"
"18446","110.64000","19.91805","0.07889"
"18466","110.76000","19.92803","0.08431"
"18486","110.88000","19.93807","0.09017"
"18506","111.00000","19.94812","0.08625"
"18526","111.12000","19.95811","0.08171"
"18546","111.24000","19.96809","0.08685"
"18566","111.36000","19.97807","0.09056"
"18586","111.48000","19.98812","0.08822"
"18606","111.60000","19.99804","0.08553"
"18626","111.72000","20.00809","0.08887"
"18646","111.84000","20.01814","0.09135"
"18666","111.96000","20.02812","0.08943"
"18686","112.08000","20.03810","0.08757"
"18706","112.20000","20.04803","0.08994"
"18726","112.32000","20.05807","0.09131"
"18746","112.44000","20.06812","0.09039"
"18766","112.56000","20.07816","0.08794"
"18786","112.68000","20.08803","0.08998"
"18806","112.80000","20.09801","0.09144"
"18826","112.92000","20.10811","0.09049"
"18846","113.04000","20.11810","0.08976"
"18866","113.16000","20.12815","0.09059"
"18886","113.28000","20.13807","0.09191"
"18906","113.40000","20.14812","0.09100"
"18926","113.52000","20.15810","0.09059"
"18946","113.64000","20.16815","0.09114"
"18966","113.76000","20.17813","0.09266"
"18986","113.88000","20.18806","0.09153"
"19006","114.00000","20.19810","0.09104"
"19026","114.12000","20.20815","0.09188"
"19046","114.24000","20.21807","0.09404"
"19066","114.36000","20.22805","0.09176"
"19086","114.48000","20.23810","0.09164"
"19106","114.60000","20.24814","0.09300"
"19126","114.72000","20.25813","0.09553"
"19146","114.84000","20.26811","0.09266"
"19166","114.96000","20.27804","0.09222"
"19186","115.08000","20.28814","0.09497"
"19206","115.20000","20.29813","0.09671"
"19226","115.32000","20.30811","0.09407"
"19246","115.44000","20.31804","0.09352"
"19266","115.56000","20.32808","0.09677"
"19286","115.68000","20.33807","0.09846"
"19306","115.80000","20.34811","0.09537"
"19326","115.92000","20.35810","0.09559"
"19346","116.04000","20.36808","0.10027"
"19366","116.16000","20.37812","0.10069"
"19386","116.28000","20.38811","0.09682"
"19406","116.40000","20.39810","0.09785"
"19426","116.52000","20.40802","0.10274"
"19446","116.64000","20.41807","0.10186"
"19466","116.76000","20.42811","0.09942"
"19486","116.88000","20.43810","0.10177"
"19506","117.00000","20.44808","0.10571"
"19526","117.12000","20.45807","0.10434"
"19546","117.24000","20.46805","0.10286"
"19566","117.36000","20.47809","0.10522"
"19586","117.48000","20.48808","0.10886"
"19606","117.60000","20.49807","0.10664"
"19626","117.72000","20.50811","0.10531"
"19646","117.84000","20.51815","0.10889"
"19666","117.96000","20.52808","0.11055"
"19686","118.08000","20.53812","0.10922"
"19706","118.20000","20.54811","0.10869"
"19726","118.32000","20.55815","0.11157"
"19746","118.44000","20.56814","0.11251"
"19766","118.56000","20.57812","0.11138"
"19786","118.68000","20.58805","0.11108"
"19806","118.80000","20.59809","0.11335"
"19826","118.92000","20.60814","0.11401"
"19846","119.04000","20.61812","0.11266"
"19866","119.16000","20.62811","0.11394"
"19886","119.28000","20.63809","0.11608"
"19906","119.40000","20.64814","0.11618"
"19926","119.52000","20.65812","0.11557"
"19946","119.64000","20.66811","0.11693"
"19966","119.76000","20.67803","0.11812"
"19986","119.88000","20.68814","0.11836"
"20006","120.00000","20.69812","0.11734"
"20026","120.12000","20.70811","0.11912"
"20046","120.24000","20.71803","0.12009"
"20066","120.36000","20.72807","0.11927"
"20086","120.48000","20.73812","0.11954"
"20106","120.60000","20.74817","0.12105"
"20126","120.72000","20.75809","0.12132"
"20146","120.84000","20.76801","0.12093"
"20166","120.96000","20.77812","0.12143"
"20186","121.08000","20.78810","0.12232"
"20206","121.20000","20.79815","0.12250"
"20226","121.32000","20.80807","0.12232"
"20246","121.44000","20.81812","0.12330"
"20266","121.56000","20.82816","0.12414"
"20286","121.68000","20.83815","0.12399"
"20306","121.80000","20.84813","0.12409"
"20326","121.92000","20.85806","0.12449"
"20346","122.04000","20.86810","0.12535"
"20366","122.16000","20.87815","0.12518"
"20386","122.28000","20.88807","0.12525"
"20406","122.40000","20.89806","0.12575"
"20426","122.52000","20.90804","0.12620"
"20446","122.64000","20.91815","0.12667"
"20466","122.76000","20.92813","0.12652"
"20486","122.88000","20.93812","0.12728"
"20506","123.00000","20.94804","0.12779"
"20526","123.12000","20.95808","0.12720"
"20546","123.24000","20.96813","0.12783"
"20566","123.36000","20.97812","0.12796"
"20586","123.48000","20.98810","0.12806"
"20606","123.60000","20.99809","0.12830"
"20626","123.72000","21.00813","0.12898"
"20646","123.84000","21.01811","0.12971"
"20666","123.96000","21.02810","0.12915"
"20686","124.08000","21.03808","0.12961"
"20706","124.20000","21.04813","0.12996"
"20726","124.32000","21.05817","0.13051"
"20746","124.44000","21.06810","0.13033"
"20766","124.56000","21.07808","0.13061"
"20786","124.68000","21.08807","0.13112"
"20806","124.80000","21.09811","0.13149"
"20826","124.92000","21.10816","0.13157"
"20846","125.04000","21.11808","0.13186"
"20866","125.16000","21.12807","0.13206"
"20886","125.28000","21.13811","0.13216"
"20906","125.40000","21.14810","0.13261"
"20926","125.52000","21.15808","0.13303"
"20946","125.64000","21.16807","0.13375"
"20966","125.76000","21.17805","0.13381"
"20986","125.88000","21.18809","0.13419"
"21006","126.00000","21.19808","0.13463"
"21026","126.12000","21.20806","0.13451"
"21046","126.24000","21.21805","0.13501"
"21066","126.36000","21.22809","0.13570"
"21086","126.48000","21.23814","0.13624"
"21106","126.60000","21.24813","0.13663"
"21126","126.72000","21.25805","0.13673"
"21146","126.84000","21.26809","0.13704"
"21166","126.96000","21.27814","0.13711"
"21186","127.08000","21.28806","0.13746"
"21206","127.20000","21.29811","0.13800"
"21226","127.32000","21.30803","0.13811"
"21246","127.44000","21.31808","0.13841"
"21266","127.56000","21.32812","0.13899"
"21286","127.68000","21.33805","0.13861"
"21306","127.80000","21.34809","0.13896"
"21326","127.92000","21.35808","0.13904"
"21346","128.04000","21.36812","0.13953"
"21366","128.16000","21.37811","0.13965"
"21386","128.28000","21.38803","0.14000"
"21406","128.40000","21.39808","0.14024"
"21426","128.52000","21.40812","0.14050"
"21446","128.64000","21.41817","0.14081"
"21466","128.76000","21.42815","0.14109"
"21486","128.88000","21.43801","0.14126"
"21506","129.00000","21.44812","0.14115"
"21526","129.12000","21.45810","0.14173"
"21546","129.24000","21.46809","0.14160"
"21566","129.36000","21.47808","0.14221"
"21586","129.48000","21.48806","0.14284"
"21606","129.60000","21.49810","0.14280"
"21626","129.72000","21.50809","0.14332"
"21646","129.84000","21.51807","0.14363"
"21666","129.96000","21.52806","0.14389"
"21686","130.08000","21.53810","0.14458"
"21706","130.20000","21.54815","0.14490"
"21726","130.32000","21.55807","0.14546"
"21746","130.44000","21.56806","0.14555"
"21766","130.56000","21.57804","0.14568"
"21786","130.68000","21.58815","-0.00342"
"21806","130.80000","21.59813","0.00345"
"21826","130.92000","21.60812","0.00611"
"21846","131.04000","21.61804","0.00219"
"21866","131.16000","21.62815","0.00190"
"21886","131.28000","21.63813","0.00562"
"21906","131.40000","21.64812","0.00720"
"21926","131.52000","21.65810","0.00686"
"21946","131.64000","21.66809","0.00669"
"21966","131.76000","21.67813","0.00598"
"21986","131.88000","21.68811","0.00624"
"22006","132.00000","21.69810","0.00603"
"22026","132.12000","21.70802","0.00637"
"22046","132.24000","21.71813","0.00747"
"22066","132.36000","21.72817","0.00746"
"22086","132.48000","21.73810","0.00703"
"22106","132.60000","21.74809","0.00710"
"22126","132.72000","21.75807","0.00727"
"22146","132.84000","21.76811","0.00691"
"22166","132.96000","21.77816","0.00704"
"22186","133.08000","21.78814","0.00656"
"22206","133.20000","21.79807","0.00587"
"22226","133.32000","21.80811","0.00641"
"22246","133.44000","21.81810","0.00696"
"22266","133.56000","21.82814","0.00727"
"22286","133.68000","21.83807","0.00741"
"22306","133.80000","21.84811","0.00725"
"22326","133.92000","21.85816","0.00753"
"22346","134.04000","21.86808","0.00692"
"22366","134.16000","21.87813","0.00705"
"22386","134.28000","21.88805","0.00716"
"22406","134.40000","21.89810","0.00668"
"22426","134.52000","21.90814","0.00693"
"22446","134.64000","21.91806","0.00634"
"22466","134.76000","21.92811","0.00674"
"22486","134.88000","21.93810","0.00736"
"22506","135.00000","21.94814","0.00665"
"22526","135.12000","21.95813","0.00695"
"22546","135.24000","21.96811","0.00644"
"22566","135.36000","21.97810","0.00713"
"22586","135.48000","21.98808","0.00760"
"22606","135.60000","21.99806","0.00712"
"22626","135.72000","22.00805","0.00668"
"22646","135.84000","22.01809","0.00678"
"22666","135.96000","22.02808","0.00651"
"22686","136.08000","22.03806","0.00656"
"22706","136.20000","22.04811","0.00666"
"22726","136.32000","22.05803","0.00775"
"22746","136.44000","22.06802","0.00717"
"22766","136.56000","22.07812","0.00728"
"22786","136.68000","22.08817","0.00727"
"22806","136.80000","22.09815","0.00713"
"22826","136.92000","22.10808","0.00644"
"22846","137.04000","22.11806","0.00633"
"22866","137.16000","22.12811","0.00590"
"22886","137.28000","22.13809","0.00636"
"22906","137.40000","22.14814","0.00680"
"22926","137.52000","22.15806","0.00678"
"22946","137.64000","22.16811","0.00715"
"22966","137.76000","22.17809","0.00689"
"22986","137.88000","22.18807","0.00738"
"23006","138.00000","22.19806","0.00665"
"23026","138.12000","22.20811","0.00703"
"23046","138.24000","22.21815","0.00710"
"23066","138.36000","22.22813","0.00665"
"23086","138.48000","22.23812","0.00617"
"23106","138.60000","22.24810","0.00661"
"23126","138.72000","22.25809","0.00673"
"23146","138.84000","22.26807","0.00679"
"23166","138.96000","22.27812","0.00719"
"23186","139.08000","22.28811","0.00712"
"23206","139.20000","22.29803","0.00719"
"23226","139.32000","22.30813","0.00691"
"23246","139.44000","22.31812","0.00687"
"23266","139.56000","22.32810","0.00670"
"23286","139.68000","22.33809","0.00706"
"23306","139.80000","22.34807","0.00632"
"23326","139.92000","22.35812","0.00616"
"23346","140.04000","22.36810","0.00650"
"23366","140.16000","22.37803","0.00720"
"23386","140.28000","22.38807","0.00700"
"23406","140.40000","22.39811","0.00704"
"23426","140.52000","22.40810","0.00710"
"23446","140.64000","22.41803","0.00748"
"23466","140.76000","22.42801","0.00709"
"23486","140.88000","22.43811","0.00716"
"23506","141.00000","22.44816","0.00596"
"23526","141.12000","22.45815","0.00605"
"23546","141.24000","22.46807","0.00597"
"23566","141.36000","22.47806","0.00726"
"23586","141.48000","22.48810","0.00699"
"23606","141.60000","22.49814","0.00735"
"23626","141.72000","22.50807","0.00739"
"23646","141.84000","22.51811","0.00709"
"23666","141.96000","22.52810","0.00685"
"23686","142.08000","22.53808","0.00690"
"23706","142.20000","22.54807","0.00670"
"23726","142.32000","22.55805","0.00667"
"23746","142.44000","22.56804","0.00687"
"23766","142.56000","22.57808","0.00670"
"23786","142.68000","22.58807","0.00685"
"23806","142.80000","22.59805","0.00749"
"23826","142.92000","22.60804","0.00721"
"23846","143.04000","22.61808","0.00696"
"23866","143.16000","22.62807","0.00713"
"23886","143.28000","22.63811","0.00676"
"23906","143.40000","22.64810","0.00696"
"23917","143.46600","22.65359","0.00693"