File: Trajectories_together/170122_2Specimen_RawData_7.csv
"","V1","V2","V3"
"1","End date","1/22/2017",""
"2","Specimen label","12CG_95",""
"3","Maximum Load","0.02496","N"
"4","Time","Extension","Load"
"5","(s)","(mm)","(N)"
"6","0.00000","0.00000","-0.00090"
"37","0.18600","0.01250","0.00040"
"68","0.37200","0.03115","0.00161"
"99","0.55800","0.04676","0.00181"
"130","0.74400","0.06230","0.00162"
"161","0.93000","0.07779","0.00225"
"192","1.11600","0.09321","0.00256"
"223","1.30200","0.10876","0.00312"
"254","1.48800","0.12430","0.00354"
"285","1.67400","0.13967","0.00313"
"316","1.86000","0.15521","0.00374"
"347","2.04600","0.17076","0.00403"
"378","2.23200","0.18618","0.00355"
"409","2.41800","0.20179","0.00418"
"440","2.60400","0.21728","0.00397"
"471","2.79000","0.23270","0.00423"
"502","2.97600","0.24825","0.00442"
"533","3.16200","0.26373","0.00512"
"564","3.34800","0.27922","0.00425"
"595","3.53400","0.29476","0.00491"
"626","3.72000","0.31025","0.00503"
"657","3.90600","0.32573","0.00505"
"688","4.09200","0.34122","0.00495"
"719","4.27800","0.35670","0.00511"
"750","4.46400","0.37225","0.00546"
"781","4.65000","0.38774","0.00536"
"812","4.83600","0.40316","0.00555"
"843","5.02200","0.41871","0.00540"
"874","5.20800","0.43425","0.00560"
"905","5.39400","0.44968","0.00570"
"936","5.58000","0.46522","0.00597"
"967","5.76600","0.48077","0.00566"
"998","5.95200","0.49619","0.00585"
"1029","6.13800","0.51174","0.00597"
"1060","6.32400","0.52728","0.00598"
"1091","6.51000","0.54271","0.00579"
"1122","6.69600","0.55825","0.00643"
"1153","6.88200","0.57368","0.00624"
"1184","7.06800","0.58917","0.00626"
"1215","7.25400","0.60477","0.00607"
"1246","7.44000","0.62020","0.00624"
"1277","7.62600","0.63568","0.00661"
"1308","7.81200","0.65123","0.00633"
"1339","7.99800","0.66671","0.00646"
"1370","8.18400","0.68214","0.00670"
"1401","8.37000","0.69774","0.00673"
"1432","8.55600","0.71323","0.00662"
"1463","8.74200","0.72866","0.00623"
"1494","8.92800","0.74426","0.00636"
"1525","9.11400","0.75969","0.00701"
"1556","9.30000","0.77517","0.00682"
"1587","9.48600","0.79072","0.00673"
"1618","9.67200","0.80620","0.00640"
"1649","9.85800","0.82169","0.00676"
"1680","10.04400","0.83729","0.00693"
"1711","10.23000","0.85272","0.00692"
"1742","10.41600","0.86820","0.00723"
"1773","10.60200","0.88369","0.00695"
"1804","10.78800","0.89923","0.00679"
"1835","10.97400","0.91472","0.00708"
"1866","11.16000","0.93027","0.00729"
"1897","11.34600","0.94569","0.00673"
"1928","11.53200","0.96124","0.00706"
"1959","11.71800","0.97678","0.00740"
"1990","11.90400","0.99221","0.00729"
"2021","12.09000","1.00781","0.00747"
"2052","12.27600","1.02324","0.00675"
"2083","12.46200","1.03866","0.00800"
"2114","12.64800","1.05421","0.00719"
"2145","12.83400","1.06969","0.00749"
"2176","13.02000","1.08512","0.00757"
"2207","13.20600","1.10073","0.00736"
"2238","13.39200","1.11627","0.00739"
"2269","13.57800","1.13170","0.00773"
"2300","13.76400","1.14718","0.00739"
"2331","13.95000","1.16279","0.00787"
"2362","14.13600","1.17821","0.00773"
"2393","14.32200","1.19370","0.00753"
"2424","14.50800","1.20918","0.00774"
"2455","14.69400","1.22473","0.00764"
"2486","14.88000","1.24027","0.00820"
"2517","15.06600","1.25570","0.00824"
"2548","15.25200","1.27119","0.00758"
"2579","15.43800","1.28673","0.00793"
"2610","15.62400","1.30216","0.00827"
"2641","15.81000","1.31776","0.00812"
"2672","15.99600","1.33325","0.00781"
"2703","16.18200","1.34867","0.00809"
"2734","16.36800","1.36422","0.00866"
"2765","16.55400","1.37976","0.00795"
"2796","16.74000","1.39519","0.00856"
"2827","16.92600","1.41067","0.00810"
"2858","17.11200","1.42628","0.00819"
"2889","17.29800","1.44165","0.00824"
"2920","17.48400","1.45725","0.00807"
"2951","17.67000","1.47274","0.00866"
"2982","17.85600","1.48822","0.00873"
"3013","18.04200","1.50371","0.00822"
"3044","18.22800","1.51919","0.00863"
"3075","18.41400","1.53474","0.00831"
"3106","18.60000","1.55022","0.00829"
"3137","18.78600","1.56571","0.00845"
"3168","18.97200","1.58119","0.00870"
"3199","19.15800","1.59674","0.00824"
"3230","19.34400","1.61222","0.00876"
"3261","19.53000","1.62771","0.00882"
"3292","19.71600","1.64326","0.00870"
"3323","19.90200","1.65868","0.00877"
"3354","20.08800","1.67417","0.00878"
"3385","20.27400","1.68977","0.00915"
"3416","20.46000","1.70520","0.00934"
"3447","20.64600","1.72068","0.00869"
"3478","20.83200","1.73623","0.00834"
"3509","21.01800","1.75171","0.00932"
"3540","21.20400","1.76720","0.00889"
"3571","21.39000","1.78274","0.00908"
"3602","21.57600","1.79823","0.00935"
"3633","21.76200","1.81372","0.00911"
"3664","21.94800","1.82920","0.00890"
"3695","22.13400","1.84469","0.00923"
"3726","22.32000","1.86023","0.00946"
"3757","22.50600","1.87572","0.00963"
"3788","22.69200","1.89120","0.00940"
"3819","22.87800","1.90681","0.00940"
"3850","23.06400","1.92223","0.00953"
"3881","23.25000","1.93766","0.00931"
"3912","23.43600","1.95326","0.00942"
"3943","23.62200","1.96869","0.00942"
"3974","23.80800","1.98412","0.00928"
"4005","23.99400","1.99978","0.00986"
"4036","24.18000","2.01521","0.00914"
"4067","24.36600","2.03069","0.00867"
"4098","24.55200","2.04624","0.01008"
"4129","24.73800","2.06172","0.00962"
"4160","24.92400","2.07721","0.00901"
"4191","25.11000","2.09275","0.00972"
"4222","25.29600","2.10818","0.00945"
"4253","25.48200","2.12372","0.00995"
"4284","25.66800","2.13921","0.00979"
"4315","25.85400","2.15470","0.00954"
"4346","26.04000","2.17018","0.00951"
"4377","26.22600","2.18573","0.01037"
"4408","26.41200","2.20121","0.00977"
"4439","26.59800","2.21670","0.00978"
"4470","26.78400","2.23224","0.00984"
"4501","26.97000","2.24767","0.01005"
"4532","27.15600","2.26321","0.00957"
"4563","27.34200","2.27876","0.01018"
"4594","27.52800","2.29412","0.01041"
"4625","27.71400","2.30979","0.01016"
"4656","27.90000","2.32527","0.01053"
"4687","28.08600","2.34070","0.00969"
"4718","28.27200","2.35625","0.01010"
"4749","28.45800","2.37179","0.01044"
"4780","28.64400","2.38722","0.00962"
"4811","28.83000","2.40270","0.01022"
"4842","29.01600","2.41825","0.01025"
"4873","29.20200","2.43373","0.01034"
"4904","29.38800","2.44922","0.00978"
"4935","29.57400","2.46470","0.01024"
"4966","29.76000","2.48025","0.01018"
"4997","29.94600","2.49567","0.01060"
"5028","30.13200","2.51122","0.01061"
"5059","30.31800","2.52671","0.01073"
"5090","30.50400","2.54225","0.01084"
"5121","30.69000","2.55768","0.01041"
"5152","30.87600","2.57322","0.01043"
"5183","31.06200","2.58877","0.01108"
"5214","31.24800","2.60419","0.01091"
"5245","31.43400","2.61974","0.01067"
"5276","31.62000","2.63522","0.01075"
"5307","31.80600","2.65065","0.01073"
"5338","31.99200","2.66625","0.01080"
"5369","32.17800","2.68174","0.01101"
"5400","32.36400","2.69717","0.01094"
"5431","32.55000","2.71277","0.01086"
"5462","32.73600","2.72826","0.01036"
"5493","32.92200","2.74362","0.01085"
"5524","33.10800","2.75923","0.01142"
"5555","33.29400","2.77471","0.01102"
"5586","33.48000","2.79020","0.01115"
"5617","33.66600","2.80574","0.01126"
"5648","33.85200","2.82123","0.01116"
"5679","34.03800","2.83671","0.01129"
"5710","34.22400","2.85220","0.01180"
"5741","34.41000","2.86769","0.01091"
"5772","34.59600","2.88323","0.01174"
"5803","34.78200","2.89872","0.01194"
"5834","34.96800","2.91414","0.01136"
"5865","35.15400","2.92969","0.01141"
"5896","35.34000","2.94523","0.01142"
"5927","35.52600","2.96072","0.01169"
"5958","35.71200","2.97620","0.01121"
"5989","35.89800","2.99175","0.01187"
"6020","36.08400","3.00717","0.01163"
"6051","36.27000","3.02272","0.01166"
"6082","36.45600","3.03820","0.01179"
"6113","36.64200","3.05369","0.01171"
"6144","36.82800","3.06924","0.01175"
"6175","37.01400","3.08472","0.01206"
"6206","37.20000","3.10021","0.01189"
"6237","37.38600","3.11575","0.01201"
"6268","37.57200","3.13118","0.01198"
"6299","37.75800","3.14672","0.01214"
"6330","37.94400","3.16227","0.01195"
"6361","38.13000","3.17769","0.01239"
"6392","38.31600","3.19318","0.01211"
"6423","38.50200","3.20872","0.01231"
"6454","38.68800","3.22415","0.01219"
"6485","38.87400","3.23970","0.01216"
"6516","39.06000","3.25530","0.01218"
"6547","39.24600","3.27073","0.01201"
"6578","39.43200","3.28621","0.01181"
"6609","39.61800","3.30170","0.01232"
"6640","39.80400","3.31718","0.01206"
"6671","39.99000","3.33273","0.01229"
"6702","40.17600","3.34821","0.01262"
"6733","40.36200","3.36370","0.01229"
"6764","40.54800","3.37918","0.01245"
"6795","40.73400","3.39473","0.01219"
"6826","40.92000","3.41016","0.01252"
"6857","41.10600","3.42576","0.01261"
"6888","41.29200","3.44119","0.01213"
"6919","41.47800","3.45667","0.01224"
"6950","41.66400","3.47228","0.01233"
"6981","41.85000","3.48770","0.01255"
"7012","42.03600","3.50319","0.01236"
"7043","42.22200","3.51873","0.01301"
"7074","42.40800","3.53422","0.01301"
"7105","42.59400","3.54964","0.01272"
"7136","42.78000","3.56525","0.01229"
"7167","42.96600","3.58074","0.01256"
"7198","43.15200","3.59616","0.01316"
"7229","43.33800","3.61171","0.01275"
"7260","43.52400","3.62719","0.01277"
"7291","43.71000","3.64268","0.01311"
"7322","43.89600","3.65816","0.01302"
"7353","44.08200","3.67377","0.01282"
"7384","44.26800","3.68919","0.01315"
"7415","44.45400","3.70468","0.01328"
"7446","44.64000","3.72022","0.01315"
"7477","44.82600","3.73571","0.01283"
"7508","45.01200","3.75126","0.01290"
"7539","45.19800","3.76674","0.01342"
"7570","45.38400","3.78223","0.01281"
"7601","45.57000","3.79771","0.01298"
"7632","45.75600","3.81314","0.01298"
"7663","45.94200","3.82874","0.01305"
"7694","46.12800","3.84429","0.01343"
"7725","46.31400","3.85971","0.01362"
"7756","46.50000","3.87526","0.01308"
"7787","46.68600","3.89068","0.01335"
"7818","46.87200","3.90617","0.01318"
"7849","47.05800","3.92172","0.01348"
"7880","47.24400","3.93720","0.01324"
"7911","47.43000","3.95269","0.01341"
"7942","47.61600","3.96823","0.01348"
"7973","47.80200","3.98372","0.01325"
"8004","47.98800","3.99914","0.01414"
"8035","48.17400","4.01469","0.01333"
"8066","48.36000","4.03023","0.01359"
"8097","48.54600","4.04572","0.01373"
"8128","48.73200","4.06126","0.01370"
"8159","48.91800","4.07669","0.01368"
"8190","49.10400","4.09223","0.01336"
"8221","49.29000","4.10772","0.01375"
"8252","49.47600","4.12321","0.01397"
"8283","49.66200","4.13869","0.01359"
"8314","49.84800","4.15430","0.01373"
"8345","50.03400","4.16966","0.01391"
"8376","50.22000","4.18521","0.01372"
"8407","50.40600","4.20075","0.01425"
"8438","50.59200","4.21618","0.01389"
"8469","50.77800","4.23166","0.01384"
"8500","50.96400","4.24727","0.01334"
"8531","51.15000","4.26269","0.01392"
"8562","51.33600","4.27824","0.01410"
"8593","51.52200","4.29373","0.01402"
"8624","51.70800","4.30915","0.01332"
"8655","51.89400","4.32470","0.01431"
"8686","52.08000","4.34018","0.01414"
"8717","52.26600","4.35573","0.01398"
"8748","52.45200","4.37121","0.01377"
"8779","52.63800","4.38676","0.01473"
"8810","52.82400","4.40218","0.01398"
"8841","53.01000","4.41773","0.01420"
"8872","53.19600","4.43321","0.01387"
"8903","53.38200","4.44864","0.01419"
"8934","53.56800","4.46430","0.01409"
"8965","53.75400","4.47973","0.01424"
"8996","53.94000","4.49516","0.01429"
"9027","54.12600","4.51076","0.01402"
"9058","54.31200","4.52619","0.01482"
"9089","54.49800","4.54167","0.01403"
"9120","54.68400","4.55722","0.01480"
"9151","54.87000","4.57270","0.01392"
"9182","55.05600","4.58819","0.01438"
"9213","55.24200","4.60373","0.01476"
"9244","55.42800","4.61922","0.01466"
"9275","55.61400","4.63465","0.01433"
"9306","55.80000","4.65019","0.01447"
"9337","55.98600","4.66568","0.01432"
"9368","56.17200","4.68122","0.01388"
"9399","56.35800","4.69671","0.01430"
"9430","56.54400","4.71219","0.01444"
"9461","56.73000","4.72774","0.01544"
"9492","56.91600","4.74322","0.01509"
"9523","57.10200","4.75865","0.01465"
"9554","57.28800","4.77425","0.01462"
"9585","57.47400","4.78968","0.01431"
"9616","57.66000","4.80517","0.01401"
"9647","57.84600","4.82077","0.01489"
"9678","58.03200","4.83626","0.01462"
"9709","58.21800","4.85168","0.01442"
"9740","58.40400","4.86723","0.01491"
"9771","58.59000","4.88271","0.01401"
"9802","58.77600","4.89814","0.01499"
"9833","58.96200","4.91374","0.01489"
"9864","59.14800","4.92923","0.01427"
"9895","59.33400","4.94471","0.01457"
"9926","59.52000","4.96020","0.01504"
"9957","59.70600","4.97575","0.01432"
"9988","59.89200","4.99117","0.01480"
"10019","60.07800","5.00672","0.01462"
"10050","60.26400","5.02220","0.01430"
"10081","60.45000","5.03769","0.01421"
"10112","60.63600","5.05323","0.01437"
"10143","60.82200","5.06872","0.01456"
"10174","61.00800","5.08420","0.01415"
"10205","61.19400","5.09975","0.01480"
"10236","61.38000","5.11517","0.01480"
"10267","61.56600","5.13072","0.01431"
"10298","61.75200","5.14626","0.01417"
"10329","61.93800","5.16163","0.01457"
"10360","62.12400","5.17724","0.01424"
"10391","62.31000","5.19278","0.01432"
"10422","62.49600","5.20815","0.01383"
"10453","62.68200","5.22375","0.01400"
"10484","62.86800","5.23924","0.01391"
"10515","63.05400","5.25466","0.01357"
"10546","63.24000","5.27027","0.01373"
"10577","63.42600","5.28569","0.01334"
"10608","63.61200","5.30124","0.01310"
"10639","63.79800","5.31672","0.01352"
"10670","63.98400","5.33215","0.01321"
"10701","64.17000","5.34770","0.01367"
"10732","64.35600","5.36324","0.01356"
"10763","64.54200","5.37867","0.01357"
"10794","64.72800","5.39421","0.01358"
"10825","64.91400","5.40976","0.01359"
"10856","65.10000","5.42518","0.01368"
"10887","65.28600","5.44073","0.01353"
"10918","65.47200","5.45627","0.01341"
"10949","65.65800","5.47170","0.01338"
"10980","65.84400","5.48718","0.01338"
"11011","66.03000","5.50279","0.01340"
"11042","66.21600","5.51816","0.01367"
"11073","66.40200","5.53370","0.01329"
"11104","66.58800","5.54925","0.01381"
"11135","66.77400","5.56467","0.01337"
"11166","66.96000","5.58028","0.01390"
"11197","67.14600","5.59570","0.01397"
"11228","67.33200","5.61119","0.01365"
"11259","67.51800","5.62673","0.01356"
"11290","67.70400","5.64222","0.01395"
"11321","67.89000","5.65770","0.01310"
"11352","68.07600","5.67325","0.01336"
"11383","68.26200","5.68874","0.01346"
"11414","68.44800","5.70416","0.01380"
"11445","68.63400","5.71971","0.01356"
"11476","68.82000","5.73519","0.01377"
"11507","69.00600","5.75062","0.01339"
"11538","69.19200","5.76628","0.01279"
"11569","69.37800","5.78171","0.01353"
"11600","69.56400","5.79719","0.01350"
"11631","69.75000","5.81280","0.01300"
"11662","69.93600","5.82822","0.01299"
"11693","70.12200","5.84371","0.01292"
"11724","70.30800","5.85920","0.01390"
"11755","70.49400","5.87474","0.01335"
"11786","70.68000","5.89023","0.01282"
"11817","70.86600","5.90571","0.01319"
"11848","71.05200","5.92126","0.01332"
"11879","71.23800","5.93668","0.01329"
"11910","71.42400","5.95223","0.01360"
"11941","71.61000","5.96771","0.01320"
"11972","71.79600","5.98326","0.01336"
"12003","71.98200","5.99880","0.01395"
"12034","72.16800","6.01417","0.01356"
"12065","72.35400","6.02972","0.01348"
"12096","72.54000","6.04520","0.01348"
"12127","72.72600","6.06063","0.01434"
"12158","72.91200","6.07629","0.01414"
"12189","73.09800","6.09172","0.01342"
"12220","73.28400","6.10714","0.01327"
"12251","73.47000","6.12275","0.01377"
"12282","73.65600","6.13829","0.01416"
"12313","73.84200","6.15366","0.01350"
"12344","74.02800","6.16920","0.01408"
"12375","74.21400","6.18475","0.01352"
"12406","74.40000","6.20023","0.01381"
"12437","74.58600","6.21572","0.01382"
"12468","74.77200","6.23120","0.01366"
"12499","74.95800","6.24675","0.01372"
"12530","75.14400","6.26224","0.01399"
"12561","75.33000","6.27766","0.01396"
"12592","75.51600","6.29321","0.01421"
"12623","75.70200","6.30875","0.01396"
"12654","75.88800","6.32424","0.01428"
"12685","76.07400","6.33972","0.01447"
"12716","76.26000","6.35521","0.01389"
"12747","76.44600","6.37069","0.01408"
"12778","76.63200","6.38618","0.01428"
"12809","76.81800","6.40173","0.01400"
"12840","77.00400","6.41715","0.01397"
"12871","77.19000","6.43270","0.01441"
"12902","77.37600","6.44830","0.01409"
"12933","77.56200","6.46361","0.01426"
"12964","77.74800","6.47921","0.01348"
"12995","77.93400","6.49476","0.01445"
"13026","78.12000","6.51024","0.01397"
"13057","78.30600","6.52573","0.01396"
"13088","78.49200","6.54121","0.01361"
"13119","78.67800","6.55670","0.01372"
"13150","78.86400","6.57219","0.01428"
"13181","79.05000","6.58767","0.01352"
"13212","79.23600","6.60322","0.01409"
"13243","79.42200","6.61870","0.01420"
"13274","79.60800","6.63419","0.01420"
"13305","79.79400","6.64967","0.01423"
"13336","79.98000","6.66522","0.01404"
"13367","80.16600","6.68070","0.01461"
"13398","80.35200","6.69625","0.01380"
"13429","80.53800","6.71179","0.01372"
"13460","80.72400","6.72716","0.01357"
"13491","80.91000","6.74271","0.01380"
"13522","81.09600","6.75825","0.01392"
"13553","81.28200","6.77368","0.01336"
"13584","81.46800","6.78916","0.01371"
"13615","81.65400","6.80471","0.01374"
"13646","81.84000","6.82019","0.01336"
"13677","82.02600","6.83574","0.01451"
"13708","82.21200","6.85128","0.01450"
"13739","82.39800","6.86671","0.01441"
"13770","82.58400","6.88225","0.01407"
"13801","82.77000","6.89774","0.01465"
"13832","82.95600","6.91317","0.01425"
"13863","83.14200","6.92877","0.01455"
"13894","83.32800","6.94426","0.01430"
"13925","83.51400","6.95968","0.01406"
"13956","83.70000","6.97523","0.01451"
"13987","83.88600","6.99071","0.01443"
"14018","84.07200","7.00614","0.01436"
"14049","84.25800","7.02180","0.01428"
"14080","84.44400","7.03723","0.01463"
"14111","84.63000","7.05265","0.01409"
"14142","84.81600","7.06820","0.01453"
"14173","85.00200","7.08368","0.01451"
"14204","85.18800","7.09917","0.01396"
"14235","85.37400","7.11472","0.01452"
"14266","85.56000","7.13020","0.01475"
"14297","85.74600","7.14569","0.01461"
"14328","85.93200","7.16123","0.01421"
"14359","86.11800","7.17672","0.01482"
"14390","86.30400","7.19226","0.01497"
"14421","86.49000","7.20775","0.01434"
"14452","86.67600","7.22317","0.01451"
"14483","86.86200","7.23872","0.01471"
"14514","87.04800","7.25426","0.01442"
"14545","87.23400","7.26969","0.01454"
"14576","87.42000","7.28524","0.01459"
"14607","87.60600","7.30078","0.01470"
"14638","87.79200","7.31615","0.01510"
"14669","87.97800","7.33175","0.01478"
"14700","88.16400","7.34724","0.01518"
"14731","88.35000","7.36266","0.01465"
"14762","88.53600","7.37827","0.01535"
"14793","88.72200","7.39375","0.01487"
"14824","88.90800","7.40918","0.01511"
"14855","89.09400","7.42472","0.01528"
"14886","89.28000","7.44027","0.01497"
"14917","89.46600","7.45570","0.01478"
"14948","89.65200","7.47124","0.01556"
"14979","89.83800","7.48667","0.01501"
"15010","90.02400","7.50221","0.01474"
"15041","90.21000","7.51770","0.01551"
"15072","90.39600","7.53318","0.01525"
"15103","90.58200","7.54873","0.01458"
"15134","90.76800","7.56421","0.01531"
"15165","90.95400","7.57964","0.01539"
"15196","91.14000","7.59524","0.01544"
"15227","91.32600","7.61073","0.01534"
"15258","91.51200","7.62621","0.01548"
"15289","91.69800","7.64170","0.01524"
"15320","91.88400","7.65725","0.01551"
"15351","92.07000","7.67261","0.01510"
"15382","92.25600","7.68822","0.01500"
"15413","92.44200","7.70376","0.01563"
"15444","92.62800","7.71919","0.01493"
"15475","92.81400","7.73473","0.01513"
"15506","93.00000","7.75022","0.01540"
"15537","93.18600","7.76564","0.01500"
"15568","93.37200","7.78125","0.01543"
"15599","93.55800","7.79667","0.01541"
"15630","93.74400","7.81222","0.01525"
"15661","93.93000","7.82771","0.01548"
"15692","94.11600","7.84319","0.01552"
"15723","94.30200","7.85874","0.01541"
"15754","94.48800","7.87422","0.01523"
"15785","94.67400","7.88971","0.01537"
"15816","94.86000","7.90525","0.01490"
"15847","95.04600","7.92074","0.01549"
"15878","95.23200","7.93622","0.01557"
"15909","95.41800","7.95171","0.01539"
"15940","95.60400","7.96725","0.01561"
"15971","95.79000","7.98268","0.01566"
"16002","95.97600","7.99823","0.01583"
"16033","96.16200","8.01377","0.01494"
"16064","96.34800","8.02914","0.01591"
"16095","96.53400","8.04474","0.01561"
"16126","96.72000","8.06023","0.01591"
"16157","96.90600","8.07571","0.01579"
"16188","97.09200","8.09126","0.01541"
"16219","97.27800","8.10674","0.01613"
"16250","97.46400","8.12223","0.01562"
"16281","97.65000","8.13777","0.01606"
"16312","97.83600","8.15320","0.01565"
"16343","98.02200","8.16868","0.01579"
"16374","98.20800","8.18429","0.01605"
"16405","98.39400","8.19966","0.01541"
"16436","98.58000","8.21514","0.01613"
"16467","98.76600","8.23075","0.01597"
"16498","98.95200","8.24617","0.01616"
"16529","99.13800","8.26166","0.01603"
"16560","99.32400","8.27720","0.01602"
"16591","99.51000","8.29269","0.01553"
"16622","99.69600","8.30817","0.01602"
"16653","99.88200","8.32372","0.01608"
"16684","100.06800","8.33920","0.01597"
"16715","100.25400","8.35475","0.01653"
"16746","100.44000","8.37024","0.01647"
"16777","100.62600","8.38572","0.01622"
"16808","100.81200","8.40121","0.01616"
"16839","100.99800","8.41675","0.01568"
"16870","101.18400","8.43224","0.01574"
"16901","101.37000","8.44772","0.01659"
"16932","101.55600","8.46327","0.01607"
"16963","101.74200","8.47869","0.01624"
"16994","101.92800","8.49424","0.01597"
"17025","102.11400","8.50972","0.01651"
"17056","102.30000","8.52515","0.01658"
"17087","102.48600","8.54076","0.01586"
"17118","102.67200","8.55618","0.01624"
"17149","102.85800","8.57167","0.01645"
"17180","103.04400","8.58721","0.01652"
"17211","103.23000","8.60276","0.01631"
"17242","103.41600","8.61812","0.01620"
"17273","103.60200","8.63373","0.01635"
"17304","103.78800","8.64921","0.01656"
"17335","103.97400","8.66470","0.01625"
"17366","104.16000","8.68024","0.01584"
"17397","104.34600","8.69573","0.01674"
"17428","104.53200","8.71122","0.01687"
"17459","104.71800","8.72676","0.01645"
"17490","104.90400","8.74225","0.01666"
"17521","105.09000","8.75773","0.01698"
"17552","105.27600","8.77322","0.01686"
"17583","105.46200","8.78870","0.01633"
"17614","105.64800","8.80425","0.01655"
"17645","105.83400","8.81973","0.01649"
"17676","106.02000","8.83522","0.01656"
"17707","106.20600","8.85076","0.01563"
"17738","106.39200","8.86625","0.01452"
"17769","106.57800","8.88167","0.01464"
"17800","106.76400","8.89722","0.01518"
"17831","106.95000","8.91277","0.01560"
"17862","107.13600","8.92819","0.01517"
"17893","107.32200","8.94368","0.01575"
"17924","107.50800","8.95922","0.01571"
"17955","107.69400","8.97471","0.01491"
"17986","107.88000","8.99025","0.01567"
"18017","108.06600","9.00574","0.01569"
"18048","108.25200","9.02116","0.01494"
"18079","108.43800","9.03677","0.01580"
"18110","108.62400","9.05219","0.01577"
"18141","108.81000","9.06768","0.01630"
"18172","108.99600","9.08323","0.01670"
"18203","109.18200","9.09865","0.01558"
"18234","109.36800","9.11420","0.01593"
"18265","109.55400","9.12974","0.01583"
"18296","109.74000","9.14523","0.01599"
"18327","109.92600","9.16071","0.01633"
"18358","110.11200","9.17626","0.01577"
"18389","110.29800","9.19174","0.01613"
"18420","110.48400","9.20723","0.01589"
"18451","110.67000","9.22277","0.01613"
"18482","110.85600","9.23820","0.01648"
"18513","111.04200","9.25369","0.01620"
"18544","111.22800","9.26929","0.01596"
"18575","111.41400","9.28466","0.01644"
"18606","111.60000","9.30020","0.01625"
"18637","111.78600","9.31575","0.01697"
"18668","111.97200","9.33117","0.01628"
"18699","112.15800","9.34672","0.01673"
"18730","112.34400","9.36226","0.01587"
"18761","112.53000","9.37769","0.01646"
"18792","112.71600","9.39324","0.01607"
"18823","112.90200","9.40872","0.01611"
"18854","113.08800","9.42415","0.01591"
"18885","113.27400","9.43975","0.01626"
"18916","113.46000","9.45524","0.01644"
"18947","113.64600","9.47066","0.01649"
"18978","113.83200","9.48633","0.01624"
"19009","114.01800","9.50175","0.01633"
"19040","114.20400","9.51712","0.01672"
"19071","114.39000","9.53278","0.01586"
"19102","114.57600","9.54821","0.01690"
"19133","114.76200","9.56369","0.01647"
"19164","114.94800","9.57924","0.01638"
"19195","115.13400","9.59473","0.01669"
"19226","115.32000","9.61021","0.01630"
"19257","115.50600","9.62570","0.01684"
"19288","115.69200","9.64118","0.01623"
"19319","115.87800","9.65673","0.01661"
"19350","116.06400","9.67227","0.01627"
"19381","116.25000","9.68770","0.01632"
"19412","116.43600","9.70324","0.01638"
"19443","116.62200","9.71873","0.01627"
"19474","116.80800","9.73415","0.01647"
"19505","116.99400","9.74976","0.01629"
"19536","117.18000","9.76525","0.01601"
"19567","117.36600","9.78067","0.01645"
"19598","117.55200","9.79628","0.01649"
"19629","117.73800","9.81170","0.01717"
"19660","117.92400","9.82713","0.01715"
"19691","118.11000","9.84273","0.01690"
"19722","118.29600","9.85828","0.01694"
"19753","118.48200","9.87364","0.01706"
"19784","118.66800","9.88925","0.01711"
"19815","118.85400","9.90479","0.01682"
"19846","119.04000","9.92010","0.01633"
"19877","119.22600","9.93576","0.01667"
"19908","119.41200","9.95125","0.01700"
"19939","119.59800","9.96667","0.01645"
"19970","119.78400","9.98228","0.01685"
"20001","119.97000","9.99771","0.01689"
"20032","120.15600","10.01319","0.01703"
"20063","120.34200","10.02874","0.01691"
"20094","120.52800","10.04416","0.01706"
"20125","120.71400","10.05971","0.01681"
"20156","120.90000","10.07525","0.01646"
"20187","121.08600","10.09068","0.01691"
"20218","121.27200","10.10623","0.01675"
"20249","121.45800","10.12177","0.01688"
"20280","121.64400","10.13720","0.01709"
"20311","121.83000","10.15268","0.01603"
"20342","122.01600","10.16829","0.01601"
"20373","122.20200","10.18365","0.01647"
"20404","122.38800","10.19920","0.01566"
"20435","122.57400","10.21474","0.01607"
"20466","122.76000","10.23017","0.01682"
"20497","122.94600","10.24571","0.01694"
"20528","123.13200","10.26126","0.01661"
"20559","123.31800","10.27668","0.01688"
"20590","123.50400","10.29229","0.01668"
"20621","123.69000","10.30772","0.01639"
"20652","123.87600","10.32320","0.01734"
"20683","124.06200","10.33875","0.01635"
"20714","124.24800","10.35417","0.01623"
"20745","124.43400","10.36972","0.01715"
"20776","124.62000","10.38526","0.01686"
"20807","124.80600","10.40069","0.01659"
"20838","124.99200","10.41623","0.01652"
"20869","125.17800","10.43172","0.01661"
"20900","125.36400","10.44720","0.01699"
"20931","125.55000","10.46275","0.01638"
"20962","125.73600","10.47824","0.01605"
"20993","125.92200","10.49372","0.01643"
"21024","126.10800","10.50921","0.01586"
"21055","126.29400","10.52475","0.01605"
"21086","126.48000","10.54018","0.01625"
"21117","126.66600","10.55572","0.01603"
"21148","126.85200","10.57121","0.01682"
"21179","127.03800","10.58663","0.01646"
"21210","127.22400","10.60224","0.01659"
"21241","127.41000","10.61772","0.01598"
"21272","127.59600","10.63321","0.01612"
"21303","127.78200","10.64876","0.01616"
"21334","127.96800","10.66418","0.01661"
"21365","128.15400","10.67967","0.01586"
"21396","128.34000","10.69527","0.01602"
"21427","128.52600","10.71070","0.01599"
"21458","128.71200","10.72618","0.01660"
"21489","128.89800","10.74173","0.01590"
"21520","129.08400","10.75721","0.01515"
"21551","129.27000","10.77264","0.01524"
"21582","129.45600","10.78824","0.01508"
"21613","129.64200","10.80373","0.01563"
"21644","129.82800","10.81916","0.01531"
"21675","130.01400","10.83470","0.01558"
"21706","130.20000","10.85025","0.01522"
"21737","130.38600","10.86567","0.01532"
"21768","130.57200","10.88122","0.01527"
"21799","130.75800","10.89676","0.01562"
"21830","130.94400","10.91225","0.01537"
"21861","131.13000","10.92773","0.01572"
"21892","131.31600","10.94322","0.01562"
"21923","131.50200","10.95870","0.01547"
"21954","131.68800","10.97419","0.01565"
"21985","131.87400","10.98973","0.01569"
"22016","132.06000","11.00522","0.01537"
"22047","132.24600","11.02071","0.01633"
"22078","132.43200","11.03619","0.01554"
"22109","132.61800","11.05174","0.01623"
"22140","132.80400","11.06716","0.01591"
"22171","132.99000","11.08265","0.01636"
"22202","133.17600","11.09825","0.01605"
"22233","133.36200","11.11368","0.01582"
"22264","133.54800","11.12916","0.01541"
"22295","133.73400","11.14471","0.01470"
"22326","133.92000","11.16025","0.01539"
"22357","134.10600","11.17568","0.01580"
"22388","134.29200","11.19123","0.01551"
"22419","134.47800","11.20677","0.01573"
"22450","134.66400","11.22220","0.01669"
"22481","134.85000","11.23768","0.01550"
"22512","135.03600","11.25323","0.01535"
"22543","135.22200","11.26871","0.01591"
"22574","135.40800","11.28420","0.01575"
"22605","135.59400","11.29968","0.01588"
"22636","135.78000","11.31523","0.01578"
"22667","135.96600","11.33077","0.01581"
"22698","136.15200","11.34620","0.01580"
"22729","136.33800","11.36174","0.01602"
"22760","136.52400","11.37723","0.01580"
"22791","136.71000","11.39272","0.01620"
"22822","136.89600","11.40820","0.01586"
"22853","137.08200","11.42375","0.01614"
"22884","137.26800","11.43917","0.01612"
"22915","137.45400","11.45472","0.01610"
"22946","137.64000","11.47026","0.01643"
"22977","137.82600","11.48569","0.01582"
"23008","138.01200","11.50123","0.01616"
"23039","138.19800","11.51678","0.01590"
"23070","138.38400","11.53221","0.01625"
"23101","138.57000","11.54769","0.01599"
"23132","138.75600","11.56324","0.01596"
"23163","138.94200","11.57866","0.01626"
"23194","139.12800","11.59415","0.01594"
"23225","139.31400","11.60969","0.01648"
"23256","139.50000","11.62524","0.01665"
"23287","139.68600","11.64072","0.01632"
"23318","139.87200","11.65621","0.01592"
"23349","140.05800","11.67169","0.01581"
"23380","140.24400","11.68724","0.01629"
"23411","140.43000","11.70273","0.01649"
"23442","140.61600","11.71827","0.01616"
"23473","140.80200","11.73370","0.01673"
"23504","140.98800","11.74918","0.01602"
"23535","141.17400","11.76473","0.01663"
"23566","141.36000","11.78021","0.01681"
"23597","141.54600","11.79570","0.01613"
"23628","141.73200","11.81118","0.01657"
"23659","141.91800","11.82673","0.01641"
"23690","142.10400","11.84221","0.01642"
"23721","142.29000","11.85776","0.01637"
"23752","142.47600","11.87325","0.01627"
"23783","142.66200","11.88873","0.01682"
"23814","142.84800","11.90428","0.01692"
"23845","143.03400","11.91976","0.01688"
"23876","143.22000","11.93519","0.01653"
"23907","143.40600","11.95079","0.01614"
"23938","143.59200","11.96622","0.01720"
"23969","143.77800","11.98164","0.01689"
"24000","143.96400","11.99725","0.01669"
"24031","144.15000","12.01273","0.01693"
"24062","144.33600","12.02816","0.01658"
"24093","144.52200","12.04377","0.01728"
"24124","144.70800","12.05925","0.01699"
"24155","144.89400","12.07468","0.01683"
"24186","145.08000","12.09022","0.01691"
"24217","145.26600","12.10577","0.01676"
"24248","145.45200","12.12113","0.01685"
"24279","145.63800","12.13674","0.01662"
"24310","145.82400","12.15222","0.01676"
"24341","146.01000","12.16765","0.01702"
"24372","146.19600","12.18325","0.01709"
"24403","146.38200","12.19868","0.01657"
"24434","146.56800","12.21422","0.01674"
"24465","146.75400","12.22977","0.01692"
"24496","146.94000","12.24520","0.01725"
"24527","147.12600","12.26074","0.01719"
"24558","147.31200","12.27629","0.01712"
"24589","147.49800","12.29165","0.01777"
"24620","147.68400","12.30720","0.01685"
"24651","147.87000","12.32274","0.01727"
"24682","148.05600","12.33817","0.01726"
"24713","148.24200","12.35371","0.01739"
"24744","148.42800","12.36920","0.01735"
"24775","148.61400","12.38468","0.01710"
"24806","148.80000","12.40023","0.01746"
"24837","148.98600","12.41577","0.01703"
"24868","149.17200","12.43120","0.01696"
"24899","149.35800","12.44669","0.01709"
"24930","149.54400","12.46223","0.01706"
"24961","149.73000","12.47772","0.01760"
"24992","149.91600","12.49320","0.01794"
"25023","150.10200","12.50869","0.01686"
"25054","150.28800","12.52423","0.01738"
"25085","150.47400","12.53972","0.01784"
"25116","150.66000","12.55520","0.01731"
"25147","150.84600","12.57075","0.01735"
"25178","151.03200","12.58623","0.01713"
"25209","151.21800","12.60166","0.01743"
"25240","151.40400","12.61726","0.01713"
"25271","151.59000","12.63275","0.01830"
"25302","151.77600","12.64818","0.01721"
"25333","151.96200","12.66372","0.01767"
"25364","152.14800","12.67921","0.01797"
"25395","152.33400","12.69463","0.01767"
"25426","152.52000","12.71024","0.01778"
"25457","152.70600","12.72578","0.01774"
"25488","152.89200","12.74115","0.01737"
"25519","153.07800","12.75675","0.01754"
"25550","153.26400","12.77224","0.01811"
"25581","153.45000","12.78767","0.01812"
"25612","153.63600","12.80327","0.01822"
"25643","153.82200","12.81870","0.01754"
"25674","154.00800","12.83418","0.01745"
"25705","154.19400","12.84973","0.01748"
"25736","154.38000","12.86515","0.01783"
"25767","154.56600","12.88070","0.01745"
"25798","154.75200","12.89624","0.01780"
"25829","154.93800","12.91167","0.01801"
"25860","155.12400","12.92715","0.01829"
"25891","155.31000","12.94276","0.01818"
"25922","155.49600","12.95819","0.01762"
"25953","155.68200","12.97373","0.01723"
"25984","155.86800","12.98922","0.01746"
"26015","156.05400","13.00470","0.01729"
"26046","156.24000","13.02025","0.01737"
"26077","156.42600","13.03573","0.01765"
"26108","156.61200","13.05122","0.01774"
"26139","156.79800","13.06670","0.01781"
"26170","156.98400","13.08225","0.01777"
"26201","157.17000","13.09767","0.01720"
"26232","157.35600","13.11322","0.01817"
"26263","157.54200","13.12871","0.01749"
"26294","157.72800","13.14419","0.01760"
"26325","157.91400","13.15974","0.01845"
"26356","158.10000","13.17522","0.01827"
"26387","158.28600","13.19071","0.01776"
"26418","158.47200","13.20625","0.01797"
"26449","158.65800","13.22168","0.01785"
"26480","158.84400","13.23716","0.01821"
"26511","159.03000","13.25277","0.01837"
"26542","159.21600","13.26819","0.01830"
"26573","159.40200","13.28368","0.01790"
"26604","159.58800","13.29923","0.01795"
"26635","159.77400","13.31471","0.01791"
"26666","159.96000","13.33020","0.01836"
"26697","160.14600","13.34574","0.01850"
"26728","160.33200","13.36123","0.01838"
"26759","160.51800","13.37671","0.01862"
"26790","160.70400","13.39220","0.01847"
"26821","160.89000","13.40768","0.01875"
"26852","161.07600","13.42317","0.01888"
"26883","161.26200","13.43877","0.01813"
"26914","161.44800","13.45420","0.01862"
"26945","161.63400","13.46975","0.01881"
"26976","161.82000","13.48523","0.01891"
"27007","162.00600","13.50072","0.01848"
"27038","162.19200","13.51626","0.01874"
"27069","162.37800","13.53175","0.01898"
"27100","162.56400","13.54711","0.01833"
"27131","162.75000","13.56278","0.01898"
"27162","162.93600","13.57820","0.01907"
"27193","163.12200","13.59363","0.01882"
"27224","163.30800","13.60923","0.01863"
"27255","163.49400","13.62472","0.01888"
"27286","163.68000","13.64015","0.01936"
"27317","163.86600","13.65575","0.01895"
"27348","164.05200","13.67124","0.01852"
"27379","164.23800","13.68666","0.01865"
"27410","164.42400","13.70221","0.01855"
"27441","164.61000","13.71775","0.01847"
"27472","164.79600","13.73318","0.01911"
"27503","164.98200","13.74872","0.01889"
"27534","165.16800","13.76415","0.01861"
"27565","165.35400","13.77969","0.01940"
"27596","165.54000","13.79524","0.01900"
"27627","165.72600","13.81067","0.01894"
"27658","165.91200","13.82621","0.01920"
"27689","166.09800","13.84170","0.01913"
"27720","166.28400","13.85718","0.01913"
"27751","166.47000","13.87273","0.01905"
"27782","166.65600","13.88827","0.01880"
"27813","166.84200","13.90370","0.01867"
"27844","167.02800","13.91924","0.01913"
"27875","167.21400","13.93473","0.01888"
"27906","167.40000","13.95021","0.01911"
"27937","167.58600","13.96576","0.01888"
"27968","167.77200","13.98124","0.01958"
"27999","167.95800","13.99673","0.01877"
"28030","168.14400","14.01221","0.01936"
"28061","168.33000","14.02776","0.01899"
"28092","168.51600","14.04319","0.01907"
"28123","168.70200","14.05873","0.01955"
"28154","168.88800","14.07422","0.01933"
"28185","169.07400","14.08964","0.01888"
"28216","169.26000","14.10525","0.01943"
"28247","169.44600","14.12073","0.01953"
"28278","169.63200","14.13622","0.01946"
"28309","169.81800","14.15176","0.01878"
"28340","170.00400","14.16719","0.01940"
"28371","170.19000","14.18267","0.01954"
"28402","170.37600","14.19822","0.01909"
"28433","170.56200","14.21371","0.01943"
"28464","170.74800","14.22913","0.01973"
"28495","170.93400","14.24480","0.01924"
"28526","171.12000","14.26016","0.01963"
"28557","171.30600","14.27565","0.01947"
"28588","171.49200","14.29125","0.01933"
"28619","171.67800","14.30668","0.01904"
"28650","171.86400","14.32222","0.01952"
"28681","172.05000","14.33777","0.01958"
"28712","172.23600","14.35320","0.01969"
"28743","172.42200","14.36880","0.01960"
"28774","172.60800","14.38423","0.01954"
"28805","172.79400","14.39971","0.01951"
"28836","172.98000","14.41526","0.01899"
"28867","173.16600","14.43074","0.01902"
"28898","173.35200","14.44617","0.01965"
"28929","173.53800","14.46171","0.01943"
"28960","173.72400","14.47720","0.01968"
"28991","173.91000","14.49262","0.02000"
"29022","174.09600","14.50829","0.01928"
"29053","174.28200","14.52372","0.01946"
"29084","174.46800","14.53914","0.01987"
"29115","174.65400","14.55475","0.01956"
"29146","174.84000","14.57023","0.01952"
"29177","175.02600","14.58566","0.01946"
"29208","175.21200","14.60120","0.01959"
"29239","175.39800","14.61675","0.01979"
"29270","175.58400","14.63217","0.01971"
"29301","175.77000","14.64772","0.01979"
"29332","175.95600","14.66320","0.01934"
"29363","176.14200","14.67869","0.01978"
"29394","176.32800","14.69423","0.02032"
"29425","176.51400","14.70966","0.02006"
"29456","176.70000","14.72521","0.02009"
"29487","176.88600","14.74075","0.02009"
"29518","177.07200","14.75618","0.01954"
"29549","177.25800","14.77172","0.01977"
"29580","177.44400","14.78727","0.01995"
"29611","177.63000","14.80263","0.02041"
"29642","177.81600","14.81830","0.01949"
"29673","178.00200","14.83372","0.01939"
"29704","178.18800","14.84915","0.02028"
"29735","178.37400","14.86475","0.02013"
"29766","178.56000","14.88030","0.02036"
"29797","178.74600","14.89561","0.02026"
"29828","178.93200","14.91127","0.02017"
"29859","179.11800","14.92676","0.02035"
"29890","179.30400","14.94218","0.01989"
"29921","179.49000","14.95773","0.02023"
"29952","179.67600","14.97327","0.02050"
"29983","179.86200","14.98870","0.02002"
"30014","180.04800","15.00424","0.01994"
"30045","180.23400","15.01973","0.02053"
"30076","180.42000","15.03521","0.02088"
"30107","180.60600","15.05076","0.02047"
"30138","180.79200","15.06619","0.02053"
"30169","180.97800","15.08173","0.01996"
"30200","181.16400","15.09722","0.02003"
"30231","181.35000","15.11270","0.01956"
"30262","181.53600","15.12825","0.01978"
"30293","181.72200","15.14373","0.02010"
"30324","181.90800","15.15922","0.02033"
"30355","182.09400","15.17470","0.02050"
"30386","182.28000","15.19025","0.01991"
"30417","182.46600","15.20568","0.02081"
"30448","182.65200","15.22122","0.02024"
"30479","182.83800","15.23676","0.01959"
"30510","183.02400","15.25219","0.02055"
"30541","183.21000","15.26774","0.01988"
"30572","183.39600","15.28322","0.02047"
"30603","183.58200","15.29871","0.02067"
"30634","183.76800","15.31425","0.02089"
"30665","183.95400","15.32974","0.02070"
"30696","184.14000","15.34516","0.02060"
"30727","184.32600","15.36071","0.02029"
"30758","184.51200","15.37619","0.01993"
"30789","184.69800","15.39174","0.02087"
"30820","184.88400","15.40722","0.01995"
"30851","185.07000","15.42265","0.02066"
"30882","185.25600","15.43820","0.02046"
"30913","185.44200","15.45374","0.01965"
"30944","185.62800","15.46923","0.02068"
"30975","185.81400","15.48471","0.02033"
"31006","186.00000","15.50026","0.02032"
"31037","186.18600","15.51568","0.02036"
"31068","186.37200","15.53117","0.01957"
"31099","186.55800","15.54677","0.02026"
"31130","186.74400","15.56220","0.01999"
"31161","186.93000","15.57768","0.02028"
"31192","187.11600","15.59323","0.02063"
"31223","187.30200","15.60872","0.02015"
"31254","187.48800","15.62420","0.02051"
"31285","187.67400","15.63975","0.02021"
"31316","187.86000","15.65517","0.01982"
"31347","188.04600","15.67078","0.02028"
"31378","188.23200","15.68620","0.02058"
"31409","188.41800","15.70163","0.02061"
"31440","188.60400","15.71729","0.02028"
"31471","188.79000","15.73272","0.02066"
"31502","188.97600","15.74814","0.02047"
"31533","189.16200","15.76375","0.02095"
"31564","189.34800","15.77923","0.02083"
"31595","189.53400","15.79466","0.02075"
"31626","189.72000","15.81021","0.02145"
"31657","189.90600","15.82569","0.02080"
"31688","190.09200","15.84124","0.02071"
"31719","190.27800","15.85672","0.02088"
"31750","190.46400","15.87227","0.02042"
"31781","190.65000","15.88769","0.02072"
"31812","190.83600","15.90318","0.02052"
"31843","191.02200","15.91872","0.02099"
"31874","191.20800","15.93421","0.01946"
"31905","191.39400","15.94969","0.01946"
"31936","191.58000","15.96524","0.02019"
"31967","191.76600","15.98067","0.01976"
"31998","191.95200","15.99621","0.01981"
"32029","192.13800","16.01170","0.01972"
"32060","192.32400","16.02718","0.01998"
"32091","192.51000","16.04273","0.01947"
"32122","192.69600","16.05821","0.01976"
"32153","192.88200","16.07376","0.01963"
"32184","193.06800","16.08924","0.02035"
"32215","193.25400","16.10467","0.01975"
"32246","193.44000","16.12021","0.02010"
"32277","193.62600","16.13576","0.01998"
"32308","193.81200","16.15125","0.01988"
"32339","193.99800","16.16673","0.01965"
"32370","194.18400","16.18228","0.01989"
"32401","194.37000","16.19770","0.02024"
"32432","194.55600","16.21319","0.01973"
"32463","194.74200","16.22873","0.02008"
"32494","194.92800","16.24422","0.02010"
"32525","195.11400","16.25970","0.02056"
"32556","195.30000","16.27519","0.02044"
"32587","195.48600","16.29073","0.01991"
"32618","195.67200","16.30622","0.02029"
"32649","195.85800","16.32170","0.01981"
"32680","196.04400","16.33719","0.02045"
"32711","196.23000","16.35268","0.01972"
"32742","196.41600","16.36816","0.01996"
"32773","196.60200","16.38377","0.02030"
"32804","196.78800","16.39925","0.01982"
"32835","196.97400","16.41468","0.02055"
"32866","197.16000","16.43022","0.02017"
"32897","197.34600","16.44577","0.02024"
"32928","197.53200","16.46119","0.02021"
"32959","197.71800","16.47668","0.02038"
"32990","197.90400","16.49223","0.02045"
"33021","198.09000","16.50771","0.02024"
"33052","198.27600","16.52320","0.02047"
"33083","198.46200","16.53874","0.02127"
"33114","198.64800","16.55417","0.02018"
"33145","198.83400","16.56971","0.02094"
"33176","199.02000","16.58520","0.02018"
"33207","199.20600","16.60068","0.02145"
"33238","199.39200","16.61617","0.02025"
"33269","199.57800","16.63171","0.02088"
"33300","199.76400","16.64720","0.02089"
"33331","199.95000","16.66274","0.02070"
"33362","200.13600","16.67823","0.02104"
"33393","200.32200","16.69371","0.02094"
"33424","200.50800","16.70926","0.02079"
"33455","200.69400","16.72475","0.02081"
"33486","200.88000","16.74023","0.02063"
"33517","201.06600","16.75572","0.02090"
"33548","201.25200","16.77120","0.02101"
"33579","201.43800","16.78675","0.02108"
"33610","201.62400","16.80223","0.02194"
"33641","201.81000","16.81772","0.02112"
"33672","201.99600","16.83320","0.02087"
"33703","202.18200","16.84875","0.02108"
"33734","202.36800","16.86423","0.02051"
"33765","202.55400","16.87972","0.02104"
"33796","202.74000","16.89521","0.02119"
"33827","202.92600","16.91069","0.02100"
"33858","203.11200","16.92624","0.02121"
"33889","203.29800","16.94172","0.02094"
"33920","203.48400","16.95715","0.02171"
"33951","203.67000","16.97281","0.02148"
"33982","203.85600","16.98818","0.02138"
"34013","204.04200","17.00360","0.02130"
"34044","204.22800","17.01927","0.02152"
"34075","204.41400","17.03476","0.02211"
"34106","204.60000","17.05012","0.02214"
"34137","204.78600","17.06573","0.02204"
"34168","204.97200","17.08121","0.02153"
"34199","205.15800","17.09670","0.02153"
"34230","205.34400","17.11224","0.02132"
"34261","205.53000","17.12773","0.02150"
"34292","205.71600","17.14315","0.02225"
"34323","205.90200","17.15870","0.02118"
"34354","206.08800","17.17424","0.02115"
"34385","206.27400","17.18967","0.02069"
"34416","206.46000","17.20522","0.02104"
"34447","206.64600","17.22070","0.02149"
"34478","206.83200","17.23625","0.02175"
"34509","207.01800","17.25173","0.02114"
"34540","207.20400","17.26716","0.02107"
"34571","207.39000","17.28276","0.02095"
"34602","207.57600","17.29825","0.02100"
"34633","207.76200","17.31367","0.02101"
"34664","207.94800","17.32922","0.02156"
"34695","208.13400","17.34476","0.02149"
"34726","208.32000","17.36013","0.02180"
"34757","208.50600","17.37568","0.02209"
"34788","208.69200","17.39122","0.02072"
"34819","208.87800","17.40665","0.02174"
"34850","209.06400","17.42219","0.02093"
"34881","209.25000","17.43768","0.02137"
"34912","209.43600","17.45316","0.02091"
"34943","209.62200","17.46871","0.02156"
"34974","209.80800","17.48425","0.02071"
"35005","209.99400","17.49968","0.02211"
"35036","210.18000","17.51522","0.02153"
"35067","210.36600","17.53071","0.02135"
"35098","210.55200","17.54620","0.02125"
"35129","210.73800","17.56174","0.02115"
"35160","210.92400","17.57722","0.02153"
"35191","211.11000","17.59277","0.02091"
"35222","211.29600","17.60826","0.02140"
"35253","211.48200","17.62368","0.02171"
"35284","211.66800","17.63923","0.02054"
"35315","211.85400","17.65471","0.02144"
"35346","212.04000","17.67020","0.02156"
"35377","212.22600","17.68574","0.02151"
"35408","212.41200","17.70123","0.02193"
"35439","212.59800","17.71671","0.02160"
"35470","212.78400","17.73226","0.02106"
"35501","212.97000","17.74775","0.02258"
"35532","213.15600","17.76317","0.02115"
"35563","213.34200","17.77878","0.02181"
"35594","213.52800","17.79420","0.02216"
"35625","213.71400","17.80969","0.02207"
"35656","213.90000","17.82523","0.02205"
"35687","214.08600","17.84072","0.02200"
"35718","214.27200","17.85620","0.02254"
"35749","214.45800","17.87175","0.02184"
"35780","214.64400","17.88717","0.02175"
"35811","214.83000","17.90272","0.02195"
"35842","215.01600","17.91826","0.02173"
"35873","215.20200","17.93369","0.02203"
"35904","215.38800","17.94918","0.02242"
"35935","215.57400","17.96478","0.02198"
"35966","215.76000","17.98021","0.02213"
"35997","215.94600","17.99569","0.02256"
"36028","216.13200","18.01124","0.02224"
"36059","216.31800","18.02672","0.02236"
"36090","216.50400","18.04221","0.02247"
"36121","216.69000","18.05770","0.02251"
"36152","216.87600","18.07318","0.02201"
"36183","217.06200","18.08872","0.02192"
"36214","217.24800","18.10421","0.02270"
"36245","217.43400","18.11970","0.02266"
"36276","217.62000","18.13524","0.02260"
"36307","217.80600","18.15073","0.02213"
"36338","217.99200","18.16621","0.02241"
"36369","218.17800","18.18176","0.02308"
"36400","218.36400","18.19724","0.02283"
"36431","218.55000","18.21267","0.02261"
"36462","218.73600","18.22827","0.02254"
"36493","218.92200","18.24370","0.02275"
"36524","219.10800","18.25918","0.02300"
"36555","219.29400","18.27479","0.02282"
"36586","219.48000","18.29016","0.02287"
"36617","219.66600","18.30564","0.02237"
"36648","219.85200","18.32125","0.02300"
"36679","220.03800","18.33667","0.02339"
"36710","220.22400","18.35222","0.02298"
"36741","220.41000","18.36770","0.02266"
"36772","220.59600","18.38319","0.02272"
"36803","220.78200","18.39873","0.02334"
"36834","220.96800","18.41422","0.02354"
"36865","221.15400","18.42971","0.02304"
"36896","221.34000","18.44525","0.02303"
"36927","221.52600","18.46074","0.02260"
"36958","221.71200","18.47622","0.02331"
"36989","221.89800","18.49171","0.02316"
"37020","222.08400","18.50725","0.02344"
"37051","222.27000","18.52262","0.02300"
"37082","222.45600","18.53828","0.02338"
"37113","222.64200","18.55377","0.02339"
"37144","222.82800","18.56919","0.02327"
"37175","223.01400","18.58474","0.02347"
"37206","223.20000","18.60023","0.02422"
"37237","223.38600","18.61565","0.02322"
"37268","223.57200","18.63126","0.02347"
"37299","223.75800","18.64680","0.02304"
"37330","223.94400","18.66217","0.02328"
"37361","224.13000","18.67771","0.02373"
"37392","224.31600","18.69320","0.02396"
"37423","224.50200","18.70868","0.02374"
"37454","224.68800","18.72417","0.02386"
"37485","224.87400","18.73971","0.02402"
"37516","225.06000","18.75520","0.02391"
"37547","225.24600","18.77069","0.02376"
"37578","225.43200","18.78623","0.02387"
"37609","225.61800","18.80172","0.02327"
"37640","225.80400","18.81720","0.02377"
"37671","225.99000","18.83275","0.02381"
"37702","226.17600","18.84817","0.02417"
"37733","226.36200","18.86372","0.02376"
"37764","226.54800","18.87914","0.02429"
"37795","226.73400","18.89475","0.02404"
"37826","226.92000","18.91023","0.02381"
"37857","227.10600","18.92572","0.02412"
"37888","227.29200","18.94120","0.02460"
"37919","227.47800","18.95675","0.02383"
"37950","227.66400","18.97218","0.02389"
"37981","227.85000","18.98766","0.02417"
"38012","228.03600","19.00321","0.02383"
"38043","228.22200","19.01869","0.02446"
"38074","228.40800","19.03424","0.02439"
"38105","228.59400","19.04972","0.02433"
"38136","228.78000","19.06521","0.02444"
"38167","228.96600","19.08075","0.02403"
"38198","229.15200","19.09624","0.02406"
"38229","229.33800","19.11167","0.02398"
"38260","229.52400","19.12727","0.02446"
"38291","229.71000","19.14269","0.02427"
"38322","229.89600","19.15818","0.02395"
"38353","230.08200","19.17373","0.02343"
"38384","230.26800","19.18921","0.02423"
"38415","230.45400","19.20470","0.02356"
"38446","230.64000","19.22024","0.02348"
"38477","230.82600","19.23567","0.02423"
"38508","231.01200","19.25115","0.02416"
"38512","231.03400","19.25307","0.02367"