File: Trajectories_together/170108_1Specimen_RawData_10.csv
"","V1","V2","V3"
"1","End date","1/8/2017",""
"2","Specimen label","19AG_UNK",""
"3","Maximum Load","0.01075","N"
"4","Time","Extension","Load"
"5","(s)","(mm)","(N)"
"6","0.00000","0.00000","0.00756"
"27","0.12600","0.00538","0.00790"
"48","0.25200","0.01901","0.00773"
"69","0.37800","0.03151","0.00752"
"90","0.50400","0.04221","0.00741"
"111","0.63000","0.05273","0.00780"
"132","0.75600","0.06320","0.00798"
"153","0.88200","0.07366","0.00766"
"174","1.00800","0.08418","0.00779"
"195","1.13400","0.09471","0.00792"
"216","1.26000","0.10523","0.00787"
"237","1.38600","0.11569","0.00779"
"258","1.51200","0.12610","0.00768"
"279","1.63800","0.13662","0.00758"
"300","1.76400","0.14720","0.00806"
"321","1.89000","0.15766","0.00790"
"342","2.01600","0.16819","0.00791"
"363","2.14200","0.17871","0.00748"
"384","2.26800","0.18923","0.00762"
"405","2.39400","0.19970","0.00785"
"426","2.52000","0.21010","0.00810"
"447","2.64600","0.22062","0.00785"
"468","2.77200","0.23115","0.00788"
"489","2.89800","0.24167","0.00780"
"510","3.02400","0.25213","0.00805"
"531","3.15000","0.26266","0.00808"
"552","3.27600","0.27318","0.00770"
"573","3.40200","0.28370","0.00787"
"594","3.52800","0.29416","0.00804"
"615","3.65400","0.30457","0.00816"
"636","3.78000","0.31515","0.00785"
"657","3.90600","0.32567","0.00799"
"678","4.03200","0.33620","0.00829"
"699","4.15800","0.34666","0.00791"
"720","4.28400","0.35712","0.00762"
"741","4.41000","0.36771","0.00783"
"762","4.53600","0.37817","0.00793"
"783","4.66200","0.38863","0.00769"
"804","4.78800","0.39910","0.00779"
"825","4.91400","0.40962","0.00820"
"846","5.04000","0.42014","0.00780"
"867","5.16600","0.43066","0.00757"
"888","5.29200","0.44113","0.00796"
"909","5.41800","0.45165","0.00779"
"930","5.54400","0.46217","0.00754"
"951","5.67000","0.47264","0.00767"
"972","5.79600","0.48310","0.00779"
"993","5.92200","0.49356","0.00799"
"1014","6.04800","0.50415","0.00775"
"1035","6.17400","0.51473","0.00797"
"1056","6.30000","0.52519","0.00813"
"1077","6.42600","0.53565","0.00776"
"1098","6.55200","0.54612","0.00811"
"1119","6.67800","0.55664","0.00768"
"1140","6.80400","0.56710","0.00794"
"1161","6.93000","0.57757","0.00762"
"1182","7.05600","0.58809","0.00797"
"1203","7.18200","0.59867","0.00782"
"1224","7.30800","0.60920","0.00798"
"1245","7.43400","0.61966","0.00778"
"1266","7.56000","0.63012","0.00762"
"1287","7.68600","0.64064","0.00797"
"1308","7.81200","0.65117","0.00822"
"1329","7.93800","0.66163","0.00807"
"1350","8.06400","0.67209","0.00779"
"1371","8.19000","0.68268","0.00778"
"1392","8.31600","0.69314","0.00764"
"1413","8.44200","0.70366","0.00805"
"1434","8.56800","0.71413","0.00790"
"1455","8.69400","0.72465","0.00783"
"1476","8.82000","0.73511","0.00781"
"1497","8.94600","0.74564","0.00800"
"1518","9.07200","0.75610","0.00827"
"1539","9.19800","0.76662","0.00786"
"1560","9.32400","0.77720","0.00823"
"1581","9.45000","0.78767","0.00816"
"1602","9.57600","0.79813","0.00805"
"1623","9.70200","0.80859","0.00819"
"1644","9.82800","0.81918","0.00800"
"1665","9.95400","0.82964","0.00794"
"1686","10.08000","0.84016","0.00821"
"1707","10.20600","0.85063","0.00795"
"1728","10.33200","0.86115","0.00820"
"1749","10.45800","0.87173","0.00796"
"1770","10.58400","0.88213","0.00776"
"1791","10.71000","0.89260","0.00766"
"1812","10.83600","0.90312","0.00801"
"1833","10.96200","0.91364","0.00821"
"1854","11.08800","0.92411","0.00832"
"1875","11.21400","0.93457","0.00815"
"1896","11.34000","0.94509","0.00816"
"1917","11.46600","0.95568","0.00798"
"1938","11.59200","0.96614","0.00819"
"1959","11.71800","0.97660","0.00816"
"1980","11.84400","0.98713","0.00787"
"2001","11.97000","0.99771","0.00808"
"2022","12.09600","1.00817","0.00801"
"2043","12.22200","1.01863","0.00809"
"2064","12.34800","1.02910","0.00831"
"2085","12.47400","1.03968","0.00821"
"2106","12.60000","1.05020","0.00792"
"2127","12.72600","1.06067","0.00870"
"2148","12.85200","1.07107","0.00803"
"2169","12.97800","1.08159","0.00806"
"2190","13.10400","1.09212","0.00807"
"2211","13.23000","1.10264","0.00793"
"2232","13.35600","1.11310","0.00818"
"2253","13.48200","1.12362","0.00779"
"2274","13.60800","1.13421","0.00784"
"2295","13.73400","1.14467","0.00844"
"2316","13.86000","1.15513","0.00840"
"2337","13.98600","1.16560","0.00808"
"2358","14.11200","1.17618","0.00807"
"2379","14.23800","1.18670","0.00776"
"2400","14.36400","1.19711","0.00782"
"2421","14.49000","1.20763","0.00805"
"2442","14.61600","1.21815","0.00806"
"2463","14.74200","1.22867","0.00818"
"2484","14.86800","1.23914","0.00802"
"2505","14.99400","1.24960","0.00781"
"2526","15.12000","1.26018","0.00819"
"2547","15.24600","1.27065","0.00804"
"2568","15.37200","1.28117","0.00819"
"2589","15.49800","1.29163","0.00807"
"2610","15.62400","1.30216","0.00820"
"2631","15.75000","1.31268","0.00783"
"2652","15.87600","1.32314","0.00796"
"2673","16.00200","1.33361","0.00804"
"2694","16.12800","1.34413","0.00758"
"2715","16.25400","1.35465","0.00807"
"2736","16.38000","1.36517","0.00799"
"2757","16.50600","1.37564","0.00790"
"2778","16.63200","1.38616","0.00799"
"2799","16.75800","1.39668","0.00827"
"2820","16.88400","1.40715","0.00836"
"2841","17.01000","1.41767","0.00802"
"2862","17.13600","1.42813","0.00791"
"2883","17.26200","1.43866","0.00809"
"2904","17.38800","1.44912","0.00839"
"2925","17.51400","1.45964","0.00790"
"2946","17.64000","1.47016","0.00852"
"2967","17.76600","1.48063","0.00856"
"2988","17.89200","1.49121","0.00875"
"3009","18.01800","1.50161","0.00835"
"3030","18.14400","1.51214","0.00753"
"3051","18.27000","1.52260","0.00797"
"3072","18.39600","1.53312","0.00754"
"3093","18.52200","1.54365","0.00844"
"3114","18.64800","1.55417","0.00758"
"3135","18.77400","1.56463","0.00830"
"3156","18.90000","1.57510","0.00870"
"3177","19.02600","1.58562","0.00850"
"3198","19.15200","1.59614","0.00895"
"3219","19.27800","1.60666","0.00826"
"3240","19.40400","1.61713","0.00834"
"3261","19.53000","1.62765","0.00901"
"3282","19.65600","1.63811","0.00833"
"3303","19.78200","1.64864","0.00840"
"3324","19.90800","1.65910","0.00885"
"3345","20.03400","1.66962","0.00759"
"3366","20.16000","1.68015","0.00813"
"3387","20.28600","1.69061","0.00870"
"3408","20.41200","1.70113","0.00900"
"3429","20.53800","1.71165","0.00754"
"3450","20.66400","1.72218","0.00864"
"3471","20.79000","1.73270","0.00870"
"3492","20.91600","1.74310","0.00910"
"3513","21.04200","1.75363","0.00871"
"3534","21.16800","1.76415","0.00784"
"3555","21.29400","1.77467","0.00830"
"3576","21.42000","1.78514","0.00825"
"3597","21.54600","1.79566","0.00872"
"3618","21.67200","1.80624","0.00884"
"3639","21.79800","1.81665","0.00865"
"3660","21.92400","1.82711","0.00847"
"3681","22.05000","1.83757","0.00891"
"3702","22.17600","1.84815","0.00867"
"3723","22.30200","1.85862","0.00853"
"3744","22.42800","1.86914","0.00847"
"3765","22.55400","1.87960","0.00900"
"3786","22.68000","1.89013","0.00865"
"3807","22.80600","1.90071","0.00850"
"3828","22.93200","1.91117","0.00858"
"3849","23.05800","1.92158","0.00831"
"3870","23.18400","1.93210","0.00850"
"3891","23.31000","1.94268","0.00896"
"3912","23.43600","1.95314","0.00889"
"3933","23.56200","1.96361","0.00845"
"3954","23.68800","1.97413","0.00847"
"3975","23.81400","1.98465","0.00923"
"3996","23.94000","1.99518","0.00899"
"4017","24.06600","2.00558","0.00811"
"4038","24.19200","2.01604","0.00866"
"4059","24.31800","2.02663","0.00892"
"4080","24.44400","2.03715","0.00887"
"4101","24.57000","2.04761","0.00877"
"4122","24.69600","2.05808","0.00917"
"4143","24.82200","2.06860","0.00821"
"4164","24.94800","2.07918","0.00864"
"4185","25.07400","2.08964","0.00855"
"4206","25.20000","2.10011","0.00889"
"4227","25.32600","2.11063","0.00882"
"4248","25.45200","2.12109","0.00881"
"4269","25.57800","2.13168","0.00859"
"4290","25.70400","2.14208","0.00874"
"4311","25.83000","2.15266","0.00883"
"4332","25.95600","2.16319","0.00846"
"4353","26.08200","2.17365","0.00874"
"4374","26.20800","2.18411","0.00734"
"4395","26.33400","2.19457","0.00780"
"4416","26.46000","2.20516","0.00830"
"4437","26.58600","2.21562","0.00853"
"4458","26.71200","2.22614","0.00807"
"4479","26.83800","2.23661","0.00782"
"4500","26.96400","2.24713","0.00815"
"4521","27.09000","2.25765","0.00809"
"4542","27.21600","2.26812","0.00814"
"4563","27.34200","2.27864","0.00822"
"4584","27.46800","2.28916","0.00834"
"4605","27.59400","2.29968","0.00842"
"4626","27.72000","2.31015","0.00845"
"4647","27.84600","2.32067","0.00842"
"4668","27.97200","2.33119","0.00823"
"4689","28.09800","2.34172","0.00811"
"4710","28.22400","2.35218","0.00822"
"4731","28.35000","2.36264","0.00829"
"4752","28.47600","2.37305","0.00847"
"4773","28.60200","2.38369","0.00841"
"4794","28.72800","2.39415","0.00839"
"4815","28.85400","2.40462","0.00835"
"4836","28.98000","2.41514","0.00822"
"4857","29.10600","2.42566","0.00820"
"4878","29.23200","2.43618","0.00810"
"4899","29.35800","2.44671","0.00830"
"4920","29.48400","2.45711","0.00803"
"4941","29.61000","2.46763","0.00845"
"4962","29.73600","2.47816","0.00859"
"4983","29.86200","2.48862","0.00835"
"5004","29.98800","2.49920","0.00853"
"5025","30.11400","2.50961","0.00849"
"5046","30.24000","2.52019","0.00865"
"5067","30.36600","2.53065","0.00826"
"5088","30.49200","2.54112","0.00840"
"5109","30.61800","2.55152","0.00814"
"5130","30.74400","2.56216","0.00831"
"5151","30.87000","2.57268","0.00844"
"5172","30.99600","2.58315","0.00817"
"5193","31.12200","2.59361","0.00835"
"5214","31.24800","2.60413","0.00827"
"5235","31.37400","2.61466","0.00852"
"5256","31.50000","2.62512","0.00845"
"5277","31.62600","2.63564","0.00845"
"5298","31.75200","2.64605","0.00836"
"5319","31.87800","2.65669","0.00833"
"5340","32.00400","2.66721","0.00833"
"5361","32.13000","2.67767","0.00826"
"5382","32.25600","2.68808","0.00817"
"5403","32.38200","2.69860","0.00819"
"5424","32.50800","2.70918","0.00821"
"5445","32.63400","2.71965","0.00819"
"5466","32.76000","2.73011","0.00852"
"5487","32.88600","2.74063","0.00854"
"5508","33.01200","2.75116","0.00811"
"5529","33.13800","2.76168","0.00867"
"5550","33.26400","2.77214","0.00823"
"5571","33.39000","2.78260","0.00822"
"5592","33.51600","2.79313","0.00843"
"5613","33.64200","2.80365","0.00817"
"5634","33.76800","2.81411","0.00850"
"5655","33.89400","2.82458","0.00856"
"5676","34.02000","2.83516","0.00879"
"5697","34.14600","2.84568","0.00826"
"5718","34.27200","2.85615","0.00851"
"5739","34.39800","2.86661","0.00842"
"5760","34.52400","2.87713","0.00840"
"5781","34.65000","2.88760","0.00845"
"5802","34.77600","2.89812","0.00851"
"5823","34.90200","2.90858","0.00856"
"5844","35.02800","2.91910","0.00841"
"5865","35.15400","2.92969","0.00845"
"5886","35.28000","2.94015","0.00867"
"5907","35.40600","2.95067","0.00812"
"5928","35.53200","2.96108","0.00863"
"5949","35.65800","2.97166","0.00857"
"5970","35.78400","2.98212","0.00857"
"5991","35.91000","2.99265","0.00818"
"6012","36.03600","3.00311","0.00805"
"6033","36.16200","3.01363","0.00862"
"6054","36.28800","3.02421","0.00839"
"6075","36.41400","3.03462","0.00854"
"6096","36.54000","3.04508","0.00877"
"6117","36.66600","3.05566","0.00863"
"6138","36.79200","3.06613","0.00845"
"6159","36.91800","3.07659","0.00878"
"6180","37.04400","3.08711","0.00847"
"6201","37.17000","3.09764","0.00845"
"6222","37.29600","3.10822","0.00842"
"6243","37.42200","3.11868","0.00856"
"6264","37.54800","3.12909","0.00848"
"6285","37.67400","3.13961","0.00849"
"6306","37.80000","3.15013","0.00857"
"6327","37.92600","3.16065","0.00862"
"6348","38.05200","3.17112","0.00856"
"6369","38.17800","3.18158","0.00846"
"6390","38.30400","3.19216","0.00845"
"6411","38.43000","3.20263","0.00842"
"6432","38.55600","3.21315","0.00868"
"6453","38.68200","3.22355","0.00871"
"6474","38.80800","3.23419","0.00808"
"6495","38.93400","3.24466","0.00784"
"6516","39.06000","3.25512","0.00799"
"6537","39.18600","3.26564","0.00856"
"6558","39.31200","3.27617","0.00878"
"6579","39.43800","3.28675","0.00786"
"6600","39.56400","3.29715","0.00751"
"6621","39.69000","3.30762","0.00745"
"6642","39.81600","3.31808","0.00802"
"6663","39.94200","3.32872","0.00909"
"6684","40.06800","3.33919","0.00916"
"6705","40.19400","3.34965","0.00916"
"6726","40.32000","3.36005","0.00818"
"6747","40.44600","3.37063","0.00756"
"6768","40.57200","3.38116","0.00789"
"6789","40.69800","3.39162","0.00911"
"6810","40.82400","3.40214","0.00887"
"6831","40.95000","3.41261","0.00841"
"6852","41.07600","3.42319","0.00825"
"6873","41.20200","3.43365","0.00863"
"6894","41.32800","3.44412","0.00836"
"6915","41.45400","3.45464","0.00872"
"6936","41.58000","3.46516","0.00891"
"6957","41.70600","3.47569","0.00907"
"6978","41.83200","3.48609","0.00854"
"6999","41.95800","3.49655","0.00886"
"7020","42.08400","3.50719","0.00855"
"7041","42.21000","3.51766","0.00904"
"7062","42.33600","3.52818","0.00890"
"7083","42.46200","3.53864","0.00947"
"7104","42.58800","3.54917","0.00910"
"7125","42.71400","3.55963","0.00895"
"7146","42.84000","3.57015","0.00919"
"7167","42.96600","3.58062","0.00864"
"7188","43.09200","3.59108","0.00925"
"7209","43.21800","3.60160","0.00977"
"7230","43.34400","3.61218","0.00933"
"7251","43.47000","3.62259","0.00956"
"7272","43.59600","3.63311","0.00912"
"7293","43.72200","3.64369","0.00804"
"7314","43.84800","3.65416","0.00886"
"7335","43.97400","3.66462","0.00766"
"7356","44.10000","3.67514","0.00827"
"7377","44.22600","3.68567","0.00840"
"7398","44.35200","3.69613","0.00904"
"7419","44.47800","3.70665","0.00855"
"7440","44.60400","3.71712","0.00831"
"7461","44.73000","3.72764","0.00794"
"7482","44.85600","3.73816","0.00839"
"7503","44.98200","3.74862","0.00877"
"7524","45.10800","3.75915","0.00864"
"7545","45.23400","3.76967","0.00853"
"7566","45.36000","3.78019","0.00854"
"7587","45.48600","3.79066","0.00895"
"7608","45.61200","3.80112","0.00895"
"7629","45.73800","3.81164","0.00875"
"7650","45.86400","3.82217","0.00823"
"7671","45.99000","3.83263","0.00841"
"7692","46.11600","3.84309","0.00840"
"7713","46.24200","3.85361","0.00838"
"7734","46.36800","3.86414","0.00882"
"7755","46.49400","3.87466","0.00876"
"7776","46.62000","3.88518","0.00885"
"7797","46.74600","3.89565","0.00878"
"7818","46.87200","3.90617","0.00868"
"7839","46.99800","3.91663","0.00841"
"7860","47.12400","3.92716","0.00824"
"7881","47.25000","3.93762","0.00839"
"7902","47.37600","3.94814","0.00884"
"7923","47.50200","3.95866","0.00882"
"7944","47.62800","3.96919","0.00834"
"7965","47.75400","3.97959","0.00854"
"7986","47.88000","3.99005","0.00846"
"8007","48.00600","4.00070","0.00888"
"8028","48.13200","4.01116","0.00844"
"8049","48.25800","4.02168","0.00843"
"8070","48.38400","4.03209","0.00845"
"8091","48.51000","4.04267","0.00833"
"8112","48.63600","4.05319","0.00820"
"8133","48.76200","4.06366","0.00847"
"8154","48.88800","4.07412","0.00892"
"8175","49.01400","4.08458","0.00882"
"8196","49.14000","4.09516","0.00885"
"8217","49.26600","4.10569","0.00883"
"8238","49.39200","4.11609","0.00871"
"8259","49.51800","4.12661","0.00843"
"8280","49.64400","4.13720","0.00826"
"8301","49.77000","4.14766","0.00847"
"8322","49.89600","4.15812","0.00840"
"8343","50.02200","4.16859","0.00824"
"8364","50.14800","4.17911","0.00889"
"8385","50.27400","4.18963","0.00886"
"8406","50.40000","4.20015","0.00900"
"8427","50.52600","4.21062","0.00871"
"8448","50.65200","4.22120","0.00872"
"8469","50.77800","4.23172","0.00899"
"8490","50.90400","4.24219","0.00854"
"8511","51.03000","4.25265","0.00895"
"8532","51.15600","4.26311","0.00907"
"8553","51.28200","4.27364","0.00917"
"8574","51.40800","4.28416","0.00878"
"8595","51.53400","4.29462","0.00887"
"8616","51.66000","4.30509","0.00867"
"8637","51.78600","4.31567","0.00871"
"8658","51.91200","4.32619","0.00906"
"8679","52.03800","4.33665","0.00895"
"8700","52.16400","4.34706","0.00845"
"8721","52.29000","4.35764","0.00887"
"8742","52.41600","4.36816","0.00888"
"8763","52.54200","4.37863","0.00887"
"8784","52.66800","4.38915","0.00849"
"8805","52.79400","4.39967","0.00895"
"8826","52.92000","4.41020","0.00930"
"8847","53.04600","4.42066","0.00836"
"8868","53.17200","4.43118","0.00850"
"8889","53.29800","4.44165","0.00870"
"8910","53.42400","4.45217","0.00876"
"8931","53.55000","4.46269","0.00846"
"8952","53.67600","4.47315","0.00879"
"8973","53.80200","4.48362","0.00858"
"8994","53.92800","4.49420","0.00887"
"9015","54.05400","4.50460","0.00850"
"9036","54.18000","4.51513","0.00881"
"9057","54.30600","4.52559","0.00886"
"9078","54.43200","4.53611","0.00902"
"9099","54.55800","4.54664","0.00899"
"9120","54.68400","4.55710","0.00850"
"9141","54.81000","4.56768","0.00897"
"9162","54.93600","4.57820","0.00935"
"9183","55.06200","4.58867","0.00895"
"9204","55.18800","4.59913","0.00850"
"9225","55.31400","4.60959","0.00917"
"9246","55.44000","4.62012","0.00915"
"9267","55.56600","4.63070","0.00924"
"9288","55.69200","4.64116","0.00891"
"9309","55.81800","4.65163","0.00886"
"9330","55.94400","4.66209","0.00867"
"9351","56.07000","4.67267","0.00905"
"9372","56.19600","4.68313","0.00923"
"9393","56.32200","4.69360","0.00911"
"9414","56.44800","4.70406","0.00887"
"9435","56.57400","4.71464","0.00885"
"9456","56.70000","4.72517","0.00869"
"9477","56.82600","4.73569","0.00938"
"9498","56.95200","4.74609","0.00986"
"9519","57.07800","4.75662","0.00907"
"9540","57.20400","4.76720","0.00889"
"9561","57.33000","4.77766","0.00970"
"9582","57.45600","4.78813","0.00903"
"9603","57.58200","4.79859","0.00987"
"9624","57.70800","4.80917","0.01025"
"9645","57.83400","4.81969","0.00920"
"9666","57.96000","4.83016","0.00870"
"9687","58.08600","4.84068","0.00905"
"9708","58.21200","4.85114","0.00913"
"9729","58.33800","4.86167","0.00946"
"9750","58.46400","4.87213","0.00881"
"9771","58.59000","4.88259","0.00967"
"9792","58.71600","4.89312","0.00895"
"9813","58.84200","4.90364","0.00867"
"9834","58.96800","4.91422","0.00860"
"9855","59.09400","4.92462","0.00896"
"9876","59.22000","4.93515","0.00915"
"9897","59.34600","4.94567","0.00916"
"9918","59.47200","4.95619","0.00865"
"9939","59.59800","4.96666","0.00886"
"9960","59.72400","4.97712","0.00875"
"9981","59.85000","4.98764","0.00897"
"10002","59.97600","4.99817","0.00843"
"10023","60.10200","5.00869","0.00855"
"10044","60.22800","5.01909","0.00859"
"10065","60.35400","5.02968","0.00878"
"10086","60.48000","5.04014","0.00896"
"10107","60.60600","5.05060","0.00903"
"10128","60.73200","5.06106","0.00899"
"10149","60.85800","5.07165","0.00830"
"10170","60.98400","5.08217","0.00860"
"10191","61.11000","5.09263","0.00875"
"10212","61.23600","5.10316","0.00844"
"10233","61.36200","5.11362","0.00893"
"10254","61.48800","5.12414","0.00890"
"10275","61.61400","5.13467","0.00922"
"10296","61.74000","5.14513","0.00907"
"10317","61.86600","5.15559","0.00879"
"10338","61.99200","5.16617","0.00891"
"10359","62.11800","5.17670","0.00882"
"10380","62.24400","5.18716","0.00829"
"10401","62.37000","5.19762","0.00840"
"10422","62.49600","5.20815","0.00887"
"10443","62.62200","5.21861","0.00877"
"10464","62.74800","5.22907","0.00880"
"10485","62.87400","5.23960","0.00882"
"10506","63.00000","5.25012","0.00898"
"10527","63.12600","5.26070","0.00875"
"10548","63.25200","5.27116","0.00864"
"10569","63.37800","5.28163","0.00900"
"10590","63.50400","5.29215","0.00841"
"10611","63.63000","5.30267","0.00880"
"10632","63.75600","5.31320","0.00870"
"10653","63.88200","5.32360","0.00870"
"10674","64.00800","5.33412","0.00889"
"10695","64.13400","5.34471","0.00884"
"10716","64.26000","5.35517","0.00865"
"10737","64.38600","5.36569","0.00905"
"10758","64.51200","5.37609","0.00862"
"10779","64.63800","5.38668","0.00861"
"10800","64.76400","5.39720","0.00853"
"10821","64.89000","5.40766","0.00851"
"10842","65.01600","5.41813","0.00882"
"10863","65.14200","5.42859","0.00855"
"10884","65.26800","5.43917","0.00907"
"10905","65.39400","5.44970","0.00890"
"10926","65.52000","5.46016","0.00875"
"10947","65.64600","5.47056","0.00855"
"10968","65.77200","5.48115","0.00884"
"10989","65.89800","5.49167","0.00887"
"11010","66.02400","5.50213","0.00892"
"11031","66.15000","5.51260","0.00893"
"11052","66.27600","5.52318","0.00881"
"11073","66.40200","5.53370","0.00901"
"11094","66.52800","5.54416","0.00884"
"11115","66.65400","5.55457","0.00848"
"11136","66.78000","5.56509","0.00896"
"11157","66.90600","5.57567","0.00876"
"11178","67.03200","5.58614","0.00853"
"11199","67.15800","5.59660","0.00872"
"11220","67.28400","5.60712","0.00866"
"11241","67.41000","5.61765","0.00915"
"11262","67.53600","5.62817","0.00923"
"11283","67.66200","5.63857","0.00895"
"11304","67.78800","5.64903","0.00844"
"11325","67.91400","5.65968","0.00911"
"11346","68.04000","5.67014","0.00858"
"11367","68.16600","5.68066","0.00877"
"11388","68.29200","5.69113","0.00878"
"11409","68.41800","5.70165","0.00919"
"11430","68.54400","5.71217","0.00894"
"11451","68.67000","5.72264","0.00881"
"11472","68.79600","5.73310","0.00924"
"11493","68.92200","5.74362","0.00917"
"11514","69.04800","5.75414","0.00897"
"11535","69.17400","5.76467","0.00888"
"11556","69.30000","5.77513","0.00883"
"11577","69.42600","5.78565","0.00877"
"11598","69.55200","5.79618","0.00911"
"11619","69.67800","5.80664","0.00897"
"11640","69.80400","5.81710","0.00897"
"11661","69.93000","5.82757","0.00904"
"11682","70.05600","5.83815","0.00891"
"11703","70.18200","5.84867","0.00899"
"11724","70.30800","5.85920","0.00912"
"11745","70.43400","5.86966","0.00890"
"11766","70.56000","5.88012","0.00851"
"11787","70.68600","5.89064","0.00863"
"11808","70.81200","5.90111","0.00929"
"11829","70.93800","5.91163","0.00935"
"11850","71.06400","5.92209","0.00921"
"11871","71.19000","5.93268","0.00933"
"11892","71.31600","5.94320","0.00940"
"11913","71.44200","5.95366","0.00902"
"11934","71.56800","5.96413","0.00921"
"11955","71.69400","5.97465","0.00876"
"11976","71.82000","5.98517","0.00861"
"11997","71.94600","5.99564","0.00881"
"12018","72.07200","6.00616","0.00892"
"12039","72.19800","6.01668","0.00904"
"12060","72.32400","6.02714","0.00907"
"12081","72.45000","6.03767","0.00900"
"12102","72.57600","6.04807","0.00902"
"12123","72.70200","6.05865","0.00905"
"12144","72.82800","6.06918","0.00870"
"12165","72.95400","6.07970","0.00885"
"12186","73.08000","6.09010","0.00942"
"12207","73.20600","6.10063","0.00895"
"12228","73.33200","6.11121","0.00933"
"12249","73.45800","6.12167","0.00923"
"12270","73.58400","6.13213","0.00901"
"12291","73.71000","6.14260","0.00889"
"12312","73.83600","6.15318","0.00869"
"12333","73.96200","6.16370","0.00906"
"12354","74.08800","6.17411","0.00850"
"12375","74.21400","6.18457","0.00930"
"12396","74.34000","6.19521","0.00926"
"12417","74.46600","6.20574","0.00891"
"12438","74.59200","6.21620","0.00884"
"12459","74.71800","6.22660","0.00900"
"12480","74.84400","6.23712","0.00888"
"12501","74.97000","6.24771","0.00932"
"12522","75.09600","6.25817","0.00900"
"12543","75.22200","6.26863","0.00888"
"12564","75.34800","6.27910","0.00915"
"12585","75.47400","6.28968","0.00891"
"12606","75.60000","6.30020","0.00879"
"12627","75.72600","6.31061","0.00912"
"12648","75.85200","6.32107","0.00908"
"12669","75.97800","6.33165","0.00902"
"12690","76.10400","6.34217","0.00915"
"12711","76.23000","6.35264","0.00930"
"12732","76.35600","6.36310","0.00901"
"12753","76.48200","6.37362","0.00920"
"12774","76.60800","6.38415","0.00891"
"12795","76.73400","6.39467","0.00896"
"12816","76.86000","6.40507","0.00877"
"12837","76.98600","6.41560","0.00873"
"12858","77.11200","6.42618","0.00896"
"12879","77.23800","6.43670","0.00947"
"12900","77.36400","6.44711","0.00929"
"12921","77.49000","6.45763","0.00916"
"12942","77.61600","6.46821","0.00920"
"12963","77.74200","6.47867","0.00865"
"12984","77.86800","6.48914","0.00874"
"13005","77.99400","6.49954","0.00888"
"13026","78.12000","6.51012","0.00896"
"13047","78.24600","6.52065","0.00869"
"13068","78.37200","6.53117","0.00874"
"13089","78.49800","6.54163","0.00916"
"13110","78.62400","6.55216","0.00911"
"13131","78.75000","6.56268","0.00891"
"13152","78.87600","6.57314","0.00878"
"13173","79.00200","6.58360","0.00885"
"13194","79.12800","6.59413","0.00830"
"13215","79.25400","6.60465","0.00881"
"13236","79.38000","6.61517","0.00887"
"13257","79.50600","6.62564","0.00906"
"13278","79.63200","6.63616","0.00932"
"13299","79.75800","6.64668","0.00951"
"13320","79.88400","6.65715","0.00884"
"13341","80.01000","6.66761","0.00894"
"13362","80.13600","6.67807","0.00909"
"13383","80.26200","6.68866","0.00881"
"13404","80.38800","6.69918","0.00906"
"13425","80.51400","6.70964","0.00874"
"13446","80.64000","6.72016","0.00907"
"13467","80.76600","6.73069","0.00882"
"13488","80.89200","6.74115","0.00932"
"13509","81.01800","6.75161","0.00935"
"13530","81.14400","6.76208","0.00946"
"13551","81.27000","6.77260","0.00880"
"13572","81.39600","6.78318","0.00897"
"13593","81.52200","6.79365","0.00928"
"13614","81.64800","6.80411","0.00866"
"13635","81.77400","6.81457","0.00884"
"13656","81.90000","6.82521","0.00910"
"13677","82.02600","6.83568","0.00883"
"13698","82.15200","6.84614","0.00897"
"13719","82.27800","6.85660","0.00907"
"13740","82.40400","6.86713","0.00930"
"13761","82.53000","6.87765","0.00889"
"13782","82.65600","6.88817","0.00883"
"13803","82.78200","6.89858","0.00882"
"13824","82.90800","6.90916","0.00878"
"13845","83.03400","6.91968","0.00895"
"13866","83.16000","6.93015","0.00895"
"13887","83.28600","6.94061","0.00898"
"13908","83.41200","6.95107","0.00922"
"13929","83.53800","6.96171","0.00890"
"13950","83.66400","6.97218","0.00871"
"13971","83.79000","6.98264","0.00888"
"13992","83.91600","6.99310","0.00902"
"14013","84.04200","7.00363","0.00882"
"14034","84.16800","7.01421","0.00883"
"14055","84.29400","7.02461","0.00897"
"14076","84.42000","7.03514","0.00897"
"14097","84.54600","7.04560","0.00877"
"14118","84.67200","7.05618","0.00896"
"14139","84.79800","7.06670","0.00873"
"14160","84.92400","7.07711","0.00904"
"14181","85.05000","7.08763","0.00857"
"14202","85.17600","7.09815","0.00862"
"14223","85.30200","7.10868","0.00884"
"14244","85.42800","7.11914","0.00841"
"14265","85.55400","7.12960","0.00861"
"14286","85.68000","7.14019","0.00887"
"14307","85.80600","7.15065","0.00889"
"14328","85.93200","7.16117","0.00872"
"14349","86.05800","7.17158","0.00837"
"14370","86.18400","7.18210","0.00857"
"14391","86.31000","7.19256","0.00852"
"14412","86.43600","7.20308","0.00834"
"14433","86.56200","7.21355","0.00873"
"14454","86.68800","7.22413","0.00865"
"14475","86.81400","7.23471","0.00887"
"14496","86.94000","7.24518","0.00881"
"14517","87.06600","7.25564","0.00816"
"14538","87.19200","7.26610","0.00863"
"14559","87.31800","7.27663","0.00897"
"14580","87.44400","7.28715","0.00839"
"14601","87.57000","7.29761","0.00890"
"14622","87.69600","7.30814","0.00902"
"14643","87.82200","7.31866","0.00842"
"14664","87.94800","7.32912","0.00895"
"14685","88.07400","7.33964","0.00862"
"14706","88.20000","7.35011","0.00866"
"14727","88.32600","7.36063","0.00865"
"14748","88.45200","7.37115","0.00872"
"14769","88.57800","7.38162","0.00863"
"14790","88.70400","7.39208","0.00887"
"14811","88.83000","7.40260","0.00900"
"14832","88.95600","7.41324","0.00898"
"14853","89.08200","7.42365","0.00894"
"14874","89.20800","7.43411","0.00874"
"14895","89.33400","7.44457","0.00902"
"14916","89.46000","7.45516","0.00890"
"14937","89.58600","7.46568","0.00866"
"14958","89.71200","7.47608","0.00889"
"14979","89.83800","7.48661","0.00878"
"15000","89.96400","7.49719","0.00879"
"15021","90.09000","7.50771","0.00918"
"15042","90.21600","7.51818","0.00887"
"15063","90.34200","7.52858","0.00876"
"15084","90.46800","7.53916","0.00900"
"15105","90.59400","7.54962","0.00862"
"15126","90.72000","7.56015","0.00889"
"15147","90.84600","7.57055","0.00911"
"15168","90.97200","7.58119","0.00872"
"15189","91.09800","7.59172","0.00876"
"15210","91.22400","7.60218","0.00896"
"15231","91.35000","7.61264","0.00862"
"15252","91.47600","7.62311","0.00885"
"15273","91.60200","7.63369","0.00910"
"15294","91.72800","7.64415","0.00868"
"15315","91.85400","7.65461","0.00879"
"15336","91.98000","7.66508","0.00881"
"15357","92.10600","7.67566","0.00917"
"15378","92.23200","7.68618","0.00900"
"15399","92.35800","7.69659","0.00862"
"15420","92.48400","7.70711","0.00852"
"15441","92.61000","7.71757","0.00911"
"15462","92.73600","7.72810","0.00884"
"15483","92.86200","7.73862","0.00893"
"15504","92.98800","7.74908","0.00892"
"15525","93.11400","7.75967","0.00899"
"15546","93.24000","7.77019","0.00924"
"15567","93.36600","7.78071","0.00895"
"15588","93.49200","7.79111","0.00868"
"15609","93.61800","7.80158","0.00893"
"15630","93.74400","7.81222","0.00902"
"15651","93.87000","7.82262","0.00916"
"15672","93.99600","7.83315","0.00880"
"15693","94.12200","7.84361","0.00901"
"15714","94.24800","7.85419","0.00886"
"15735","94.37400","7.86466","0.00893"
"15756","94.50000","7.87512","0.00931"
"15777","94.62600","7.88558","0.00932"
"15798","94.75200","7.89610","0.00890"
"15819","94.87800","7.90663","0.00874"
"15840","95.00400","7.91721","0.00894"
"15861","95.13000","7.92767","0.00896"
"15882","95.25600","7.93814","0.00901"
"15903","95.38200","7.94866","0.00855"
"15924","95.50800","7.95918","0.00919"
"15945","95.63400","7.96965","0.00919"
"15966","95.76000","7.98011","0.00920"
"15987","95.88600","7.99063","0.00943"
"16008","96.01200","8.00115","0.00905"
"16029","96.13800","8.01168","0.00894"
"16050","96.26400","8.02214","0.00905"
"16071","96.39000","8.03266","0.00936"
"16092","96.51600","8.04313","0.00948"
"16113","96.64200","8.05365","0.00923"
"16134","96.76800","8.06411","0.00842"
"16155","96.89400","8.07464","0.00911"
"16176","97.02000","8.08516","0.00869"
"16197","97.14600","8.09562","0.00856"
"16218","97.27200","8.10609","0.00891"
"16239","97.39800","8.11661","0.00904"
"16260","97.52400","8.12713","0.00887"
"16281","97.65000","8.13765","0.00918"
"16302","97.77600","8.14812","0.00872"
"16323","97.90200","8.15864","0.00902"
"16344","98.02800","8.16916","0.00884"
"16365","98.15400","8.17969","0.00847"
"16386","98.28000","8.19015","0.00905"
"16407","98.40600","8.20061","0.00876"
"16428","98.53200","8.21119","0.00887"
"16449","98.65800","8.22166","0.00913"
"16470","98.78400","8.23212","0.00928"
"16491","98.91000","8.24259","0.00885"
"16512","99.03600","8.25311","0.00895"
"16533","99.16200","8.26369","0.00877"
"16554","99.28800","8.27415","0.00911"
"16575","99.41400","8.28462","0.00914"
"16596","99.54000","8.29508","0.00934"
"16617","99.66600","8.30566","0.00874"
"16638","99.79200","8.31619","0.00890"
"16659","99.91800","8.32665","0.00968"
"16680","100.04400","8.33711","0.00913"
"16701","100.17000","8.34764","0.00885"
"16722","100.29600","8.35822","0.00896"
"16743","100.42200","8.36868","0.00876"
"16764","100.54800","8.37908","0.00873"
"16785","100.67400","8.38961","0.00871"
"16806","100.80000","8.40019","0.00911"
"16827","100.92600","8.41065","0.00921"
"16848","101.05200","8.42118","0.00840"
"16869","101.17800","8.43164","0.00883"
"16890","101.30400","8.44216","0.00909"
"16911","101.43000","8.45269","0.00875"
"16932","101.55600","8.46315","0.00901"
"16953","101.68200","8.47361","0.00910"
"16974","101.80800","8.48413","0.00904"
"16995","101.93400","8.49466","0.00868"
"17016","102.06000","8.50512","0.00895"
"17037","102.18600","8.51558","0.00875"
"17058","102.31200","8.52617","0.00867"
"17079","102.43800","8.53669","0.00856"
"17100","102.56400","8.54715","0.00898"
"17121","102.69000","8.55762","0.00884"
"17142","102.81600","8.56808","0.00865"
"17163","102.94200","8.57866","0.00878"
"17184","103.06800","8.58918","0.00907"
"17205","103.19400","8.59959","0.00865"
"17226","103.32000","8.61011","0.00899"
"17247","103.44600","8.62063","0.00889"
"17268","103.57200","8.63116","0.00901"
"17289","103.69800","8.64162","0.00877"
"17310","103.82400","8.65202","0.00892"
"17331","103.95000","8.66267","0.00906"
"17352","104.07600","8.67313","0.00895"
"17373","104.20200","8.68365","0.00884"
"17394","104.32800","8.69411","0.00891"
"17415","104.45400","8.70464","0.00881"
"17436","104.58000","8.71516","0.00912"
"17457","104.70600","8.72568","0.00878"
"17478","104.83200","8.73615","0.00896"
"17499","104.95800","8.74661","0.00908"
"17520","105.08400","8.75719","0.00915"
"17541","105.21000","8.76766","0.00908"
"17562","105.33600","8.77812","0.00895"
"17583","105.46200","8.78864","0.00900"
"17604","105.58800","8.79917","0.00914"
"17625","105.71400","8.80963","0.00871"
"17646","105.84000","8.82009","0.00877"
"17667","105.96600","8.83056","0.00899"
"17688","106.09200","8.84114","0.00897"
"17709","106.21800","8.85166","0.00894"
"17730","106.34400","8.86212","0.00904"
"17751","106.47000","8.87259","0.00892"
"17772","106.59600","8.88317","0.00886"
"17793","106.72200","8.89363","0.00918"
"17814","106.84800","8.90416","0.00911"
"17835","106.97400","8.91456","0.00875"
"17856","107.10000","8.92508","0.00880"
"17877","107.22600","8.93567","0.00952"
"17898","107.35200","8.94613","0.00932"
"17919","107.47800","8.95665","0.00883"
"17940","107.60400","8.96711","0.00924"
"17961","107.73000","8.97770","0.00949"
"17982","107.85600","8.98816","0.00917"
"18003","107.98200","8.99856","0.00909"
"18024","108.10800","9.00909","0.00904"
"18045","108.23400","9.01967","0.00889"
"18066","108.36000","9.03019","0.00932"
"18087","108.48600","9.04066","0.00914"
"18108","108.61200","9.05112","0.00913"
"18129","108.73800","9.06158","0.00895"
"18150","108.86400","9.07216","0.00912"
"18171","108.99000","9.08269","0.00918"
"18192","109.11600","9.09309","0.00911"
"18213","109.24200","9.10355","0.00945"
"18234","109.36800","9.11420","0.00963"
"18255","109.49400","9.12466","0.00903"
"18276","109.62000","9.13518","0.00924"
"18297","109.74600","9.14559","0.00911"
"18318","109.87200","9.15611","0.00908"
"18339","109.99800","9.16663","0.00878"
"18360","110.12400","9.17710","0.00912"
"18381","110.25000","9.18756","0.00975"
"18402","110.37600","9.19808","0.00909"
"18423","110.50200","9.20866","0.00895"
"18444","110.62800","9.21919","0.00910"
"18465","110.75400","9.22959","0.00897"
"18486","110.88000","9.24011","0.00878"
"18507","111.00600","9.25064","0.00929"
"18528","111.13200","9.26116","0.00900"
"18549","111.25800","9.27156","0.00934"
"18570","111.38400","9.28215","0.00902"
"18591","111.51000","9.29267","0.00903"
"18612","111.63600","9.30319","0.00932"
"18633","111.76200","9.31365","0.00887"
"18654","111.88800","9.32412","0.00900"
"18675","112.01400","9.33464","0.00936"
"18696","112.14000","9.34516","0.00926"
"18717","112.26600","9.35569","0.00891"
"18738","112.39200","9.36615","0.00916"
"18759","112.51800","9.37661","0.00900"
"18780","112.64400","9.38714","0.00905"
"18801","112.77000","9.39766","0.00914"
"18822","112.89600","9.40812","0.00900"
"18843","113.02200","9.41859","0.00915"
"18864","113.14800","9.42917","0.00908"
"18885","113.27400","9.43963","0.00904"
"18906","113.40000","9.45010","0.00914"
"18927","113.52600","9.46062","0.00921"
"18948","113.65200","9.47114","0.00888"
"18969","113.77800","9.48166","0.00935"
"18990","113.90400","9.49213","0.00928"
"19011","114.03000","9.50259","0.00943"
"19032","114.15600","9.51311","0.00935"
"19053","114.28200","9.52364","0.00924"
"19074","114.40800","9.53410","0.00921"
"19095","114.53400","9.54462","0.00921"
"19116","114.66000","9.55515","0.00931"
"19137","114.78600","9.56573","0.00917"
"19158","114.91200","9.57619","0.00905"
"19179","115.03800","9.58659","0.00926"
"19200","115.16400","9.59712","0.00932"
"19221","115.29000","9.60764","0.00925"
"19242","115.41600","9.61816","0.00907"
"19263","115.54200","9.62863","0.00902"
"19284","115.66800","9.63909","0.00904"
"19305","115.79400","9.64967","0.00951"
"19326","115.92000","9.66019","0.00950"
"19347","116.04600","9.67066","0.00917"
"19368","116.17200","9.68112","0.00892"
"19389","116.29800","9.69164","0.00899"
"19410","116.42400","9.70217","0.00918"
"19431","116.55000","9.71263","0.00917"
"19452","116.67600","9.72309","0.00889"
"19473","116.80200","9.73362","0.00937"
"19494","116.92800","9.74420","0.00931"
"19515","117.05400","9.75472","0.00941"
"19536","117.18000","9.76513","0.00939"
"19557","117.30600","9.77553","0.00894"
"19578","117.43200","9.78617","0.00918"
"19599","117.55800","9.79669","0.00951"
"19620","117.68400","9.80716","0.00896"
"19641","117.81000","9.81756","0.00941"
"19662","117.93600","9.82820","0.00920"
"19683","118.06200","9.83867","0.00916"
"19704","118.18800","9.84913","0.00906"
"19725","118.31400","9.85959","0.00914"
"19746","118.44000","9.87006","0.00932"
"19767","118.56600","9.88064","0.00929"
"19788","118.69200","9.89116","0.00905"
"19809","118.81800","9.90157","0.00906"
"19830","118.94400","9.91215","0.00938"
"19851","119.07000","9.92273","0.00916"
"19872","119.19600","9.93319","0.00903"
"19893","119.32200","9.94360","0.00925"
"19914","119.44800","9.95406","0.00959"
"19935","119.57400","9.96464","0.00942"
"19956","119.70000","9.97517","0.00922"
"19977","119.82600","9.98563","0.00921"
"19998","119.95200","9.99609","0.00935"
"20019","120.07800","10.00661","0.00900"
"20040","120.20400","10.01714","0.00909"
"20061","120.33000","10.02766","0.00922"
"20082","120.45600","10.03812","0.00909"
"20103","120.58200","10.04865","0.00930"
"20124","120.70800","10.05911","0.00921"
"20145","120.83400","10.06969","0.00933"
"20166","120.96000","10.08016","0.00931"
"20187","121.08600","10.09062","0.00914"
"20208","121.21200","10.10120","0.00890"
"20229","121.33800","10.11167","0.00902"
"20250","121.46400","10.12213","0.00909"
"20271","121.59000","10.13259","0.00907"
"20292","121.71600","10.14311","0.00935"
"20313","121.84200","10.15370","0.00916"
"20334","121.96800","10.16416","0.00916"
"20355","122.09400","10.17462","0.00916"
"20376","122.22000","10.18515","0.00926"
"20397","122.34600","10.19561","0.00915"
"20418","122.47200","10.20613","0.00909"
"20439","122.59800","10.21660","0.00864"
"20460","122.72400","10.22712","0.00951"
"20481","122.85000","10.23764","0.00882"
"20502","122.97600","10.24817","0.00903"
"20523","123.10200","10.25863","0.00882"
"20544","123.22800","10.26909","0.00904"
"20565","123.35400","10.27967","0.00873"
"20586","123.48000","10.29014","0.00871"
"20607","123.60600","10.30060","0.00864"
"20628","123.73200","10.31112","0.00853"
"20649","123.85800","10.32165","0.00893"
"20670","123.98400","10.33217","0.00897"
"20691","124.11000","10.34269","0.00894"
"20712","124.23600","10.35310","0.00854"
"20733","124.36200","10.36362","0.00895"
"20754","124.48800","10.37414","0.00887"
"20775","124.61400","10.38466","0.00894"
"20796","124.74000","10.39507","0.00903"
"20817","124.86600","10.40565","0.00862"
"20838","124.99200","10.41623","0.00875"
"20859","125.11800","10.42664","0.00883"
"20880","125.24400","10.43710","0.00883"
"20901","125.37000","10.44756","0.00862"
"20922","125.49600","10.45821","0.00864"
"20943","125.62200","10.46873","0.00897"
"20964","125.74800","10.47913","0.00856"
"20985","125.87400","10.48959","0.00901"
"21006","126.00000","10.50018","0.00883"
"21027","126.12600","10.51070","0.00883"
"21048","126.25200","10.52116","0.00898"
"21069","126.37800","10.53163","0.00909"
"21090","126.50400","10.54215","0.00901"
"21111","126.63000","10.55267","0.00904"
"21132","126.75600","10.56314","0.00912"
"21153","126.88200","10.57360","0.00909"
"21174","127.00800","10.58412","0.00883"
"21195","127.13400","10.59471","0.00916"
"21216","127.26000","10.60517","0.00914"
"21237","127.38600","10.61563","0.00910"
"21258","127.51200","10.62609","0.00940"
"21279","127.63800","10.63662","0.00906"
"21300","127.76400","10.64720","0.00874"
"21321","127.89000","10.65766","0.00908"
"21342","128.01600","10.66807","0.00932"
"21363","128.14200","10.67865","0.00876"
"21384","128.26800","10.68917","0.00900"
"21405","128.39400","10.69970","0.00899"
"21426","128.52000","10.71010","0.00921"
"21447","128.64600","10.72062","0.00917"
"21468","128.77200","10.73114","0.00893"
"21489","128.89800","10.74167","0.00907"
"21510","129.02400","10.75213","0.00929"
"21531","129.15000","10.76259","0.00941"
"21552","129.27600","10.77312","0.00931"
"21573","129.40200","10.78364","0.00941"
"21594","129.52800","10.79410","0.00886"
"21615","129.65400","10.80457","0.00921"
"21636","129.78000","10.81515","0.00929"
"21657","129.90600","10.82567","0.00912"
"21678","130.03200","10.83613","0.00941"
"21699","130.15800","10.84666","0.00938"
"21720","130.28400","10.85718","0.00880"
"21741","130.41000","10.86770","0.00918"
"21762","130.53600","10.87817","0.00909"
"21783","130.66200","10.88863","0.00900"
"21804","130.78800","10.89909","0.00931"
"21825","130.91400","10.90968","0.00906"
"21846","131.04000","10.92014","0.00911"
"21867","131.16600","10.93060","0.00918"
"21888","131.29200","10.94113","0.00918"
"21909","131.41800","10.95171","0.00941"
"21930","131.54400","10.96217","0.00942"
"21951","131.67000","10.97263","0.00941"
"21972","131.79600","10.98310","0.00956"
"21993","131.92200","10.99368","0.00927"
"22014","132.04800","11.00420","0.00924"
"22035","132.17400","11.01461","0.00918"
"22056","132.30000","11.02513","0.00957"
"22077","132.42600","11.03565","0.00929"
"22098","132.55200","11.04618","0.00915"
"22119","132.67800","11.05664","0.00953"
"22140","132.80400","11.06704","0.00939"
"22161","132.93000","11.07763","0.00913"
"22182","133.05600","11.08821","0.00953"
"22203","133.18200","11.09867","0.00920"
"22224","133.30800","11.10913","0.00927"
"22245","133.43400","11.11960","0.00933"
"22266","133.56000","11.13018","0.00925"
"22287","133.68600","11.14064","0.00945"
"22308","133.81200","11.15117","0.00934"
"22329","133.93800","11.16157","0.00962"
"22350","134.06400","11.17215","0.00953"
"22371","134.19000","11.18268","0.00982"
"22392","134.31600","11.19314","0.00930"
"22413","134.44200","11.20360","0.00911"
"22434","134.56800","11.21418","0.00946"
"22455","134.69400","11.22471","0.00967"
"22476","134.82000","11.23511","0.00943"
"22497","134.94600","11.24563","0.00965"
"22518","135.07200","11.25610","0.00941"
"22539","135.19800","11.26668","0.00946"
"22560","135.32400","11.27714","0.00909"
"22581","135.45000","11.28767","0.00920"
"22602","135.57600","11.29813","0.00931"
"22623","135.70200","11.30859","0.00974"
"22644","135.82800","11.31917","0.00934"
"22665","135.95400","11.32958","0.00907"
"22686","136.08000","11.34010","0.00915"
"22707","136.20600","11.35062","0.00969"
"22728","136.33200","11.36115","0.00934"
"22749","136.45800","11.37173","0.00950"
"22770","136.58400","11.38213","0.00989"
"22791","136.71000","11.39266","0.00983"
"22812","136.83600","11.40318","0.00959"
"22833","136.96200","11.41370","0.00981"
"22854","137.08800","11.42417","0.00952"
"22875","137.21400","11.43463","0.00967"
"22896","137.34000","11.44515","0.00938"
"22917","137.46600","11.45567","0.00933"
"22938","137.59200","11.46614","0.00969"
"22959","137.71800","11.47660","0.00937"
"22980","137.84400","11.48712","0.00947"
"23001","137.97000","11.49765","0.00976"
"23022","138.09600","11.50817","0.01009"
"23043","138.22200","11.51857","0.00918"
"23064","138.34800","11.52910","0.00928"
"23085","138.47400","11.53968","0.00932"
"23106","138.60000","11.55020","0.00970"
"23127","138.72600","11.56067","0.00957"
"23148","138.85200","11.57113","0.00953"
"23169","138.97800","11.58165","0.00974"
"23190","139.10400","11.59211","0.00980"
"23211","139.23000","11.60264","0.00958"
"23232","139.35600","11.61310","0.00944"
"23253","139.48200","11.62362","0.01002"
"23274","139.60800","11.63421","0.00988"
"23295","139.73400","11.64461","0.00996"
"23316","139.86000","11.65507","0.00973"
"23337","139.98600","11.66560","0.00950"
"23358","140.11200","11.67612","0.00970"
"23379","140.23800","11.68658","0.00966"
"23400","140.36400","11.69711","0.00963"
"23421","140.49000","11.70763","0.00952"
"23442","140.61600","11.71815","0.00955"
"23463","140.74200","11.72861","0.00901"
"23484","140.86800","11.73908","0.00992"
"23505","140.99400","11.74960","0.00963"
"23526","141.12000","11.76018","0.00994"
"23547","141.24600","11.77071","0.00958"
"23568","141.37200","11.78111","0.00970"
"23589","141.49800","11.79157","0.00962"
"23610","141.62400","11.80216","0.00989"
"23631","141.75000","11.81268","0.00962"
"23652","141.87600","11.82314","0.00975"
"23673","142.00200","11.83360","0.00988"
"23694","142.12800","11.84413","0.01007"
"23715","142.25400","11.85465","0.00983"
"23736","142.38000","11.86511","0.00985"
"23757","142.50600","11.87558","0.00983"
"23778","142.63200","11.88616","0.00937"
"23799","142.75800","11.89674","0.00967"
"23820","142.88400","11.90721","0.00983"
"23841","143.01000","11.91761","0.00947"
"23862","143.13600","11.92807","0.00967"
"23883","143.26200","11.93865","0.00936"
"23904","143.38800","11.94918","0.00978"
"23925","143.51400","11.95964","0.00985"
"23946","143.64000","11.97010","0.00955"
"23967","143.76600","11.98069","0.00959"
"23988","143.89200","11.99121","0.00991"
"24009","144.01800","12.00161","0.01003"
"24030","144.14400","12.01214","0.00965"
"24051","144.27000","12.02266","0.00989"
"24072","144.39600","12.03318","0.00973"
"24093","144.52200","12.04370","0.00949"
"24114","144.64800","12.05411","0.00946"
"24135","144.77400","12.06463","0.00986"
"24156","144.90000","12.07515","0.00993"
"24177","145.02600","12.08568","0.00962"
"24198","145.15200","12.09614","0.00977"
"24219","145.27800","12.10660","0.00956"
"24240","145.40400","12.11713","0.00952"
"24261","145.53000","12.12765","0.00976"
"24282","145.65600","12.13811","0.01011"
"24303","145.78200","12.14864","0.00990"
"24324","145.90800","12.15916","0.00977"
"24345","146.03400","12.16968","0.01022"
"24366","146.16000","12.18014","0.00968"
"24387","146.28600","12.19061","0.01002"
"24408","146.41200","12.20113","0.01013"
"24429","146.53800","12.21159","0.01000"
"24450","146.66400","12.22212","0.00993"
"24471","146.79000","12.23264","0.00990"
"24492","146.91600","12.24316","0.00996"
"24513","147.04200","12.25375","0.01011"
"24534","147.16800","12.26415","0.00996"
"24555","147.29400","12.27461","0.00991"
"24576","147.42000","12.28508","0.00990"
"24597","147.54600","12.29560","0.00988"
"24618","147.67200","12.30618","0.01001"
"24639","147.79800","12.31664","0.01006"
"24660","147.92400","12.32717","0.01002"
"24681","148.05000","12.33763","0.00998"
"24702","148.17600","12.34815","0.01010"
"24723","148.30200","12.35868","0.01027"
"24744","148.42800","12.36914","0.00979"
"24765","148.55400","12.37966","0.01020"
"24786","148.68000","12.39019","0.00990"
"24807","148.80600","12.40065","0.00986"
"24828","148.93200","12.41111","0.01032"
"24849","149.05800","12.42163","0.00961"
"24870","149.18400","12.43216","0.01031"
"24891","149.31000","12.44268","0.01008"
"24912","149.43600","12.45308","0.01019"
"24933","149.56200","12.46361","0.01008"
"24954","149.68800","12.47419","0.01001"
"24975","149.81400","12.48465","0.00976"
"24996","149.94000","12.49518","0.01006"
"25017","150.06600","12.50558","0.01021"
"25038","150.19200","12.51616","0.01008"
"25059","150.31800","12.52668","0.00996"
"25080","150.44400","12.53715","0.00986"
"25101","150.57000","12.54761","0.00969"
"25122","150.69600","12.55813","0.00996"
"25143","150.82200","12.56872","0.00964"
"25164","150.94800","12.57918","0.00957"
"25185","151.07400","12.58964","0.00995"
"25206","151.20000","12.60011","0.00994"
"25227","151.32600","12.61063","0.01033"
"25248","151.45200","12.62115","0.01031"
"25269","151.57800","12.63162","0.00996"
"25290","151.70400","12.64208","0.01006"
"25311","151.83000","12.65266","0.01007"
"25332","151.95600","12.66318","0.00985"
"25353","152.08200","12.67365","0.01006"
"25374","152.20800","12.68411","0.01035"
"25395","152.33400","12.69463","0.01008"
"25416","152.46000","12.70516","0.00989"
"25437","152.58600","12.71562","0.01035"
"25458","152.71200","12.72614","0.01019"
"25479","152.83800","12.73661","0.01023"
"25500","152.96400","12.74719","0.00980"
"25521","153.09000","12.75771","0.01001"
"25542","153.21600","12.76812","0.00980"
"25563","153.34200","12.77858","0.01010"
"25584","153.46800","12.78910","0.01012"
"25605","153.59400","12.79968","0.01036"
"25626","153.72000","12.81015","0.01014"
"25647","153.84600","12.82055","0.01026"
"25668","153.97200","12.83113","0.01016"
"25689","154.09800","12.84165","0.01019"
"25710","154.22400","12.85218","0.01042"
"25731","154.35000","12.86264","0.01012"
"25752","154.47600","12.87311","0.00999"
"25773","154.60200","12.88363","0.01003"
"25794","154.72800","12.89415","0.01063"
"25815","154.85400","12.90461","0.01030"
"25836","154.98000","12.91514","0.01023"
"25857","155.10600","12.92566","0.01002"
"25878","155.23200","12.93618","0.01008"
"25899","155.35800","12.94665","0.01049"
"25906","155.39800","12.94993","0.01002"