File: Trajectories_together/170121_3Specimen_RawData_1.csv
"","V1","V2","V3"
"1","End date","1/21/2017",""
"2","Specimen label","4DG_31",""
"3","Maximum Load","1.04612","N"
"4","Time","Extension","Load"
"5","(s)","(mm)","(N)"
"6","0.00000","0.00000","-0.00001"
"75","0.41400","0.03486","0.00151"
"144","0.82800","0.06924","0.00294"
"213","1.24200","0.10368","0.00366"
"282","1.65600","0.13823","0.00423"
"351","2.07000","0.17279","0.00411"
"420","2.48400","0.20723","0.00572"
"489","2.89800","0.24167","0.00578"
"558","3.31200","0.27617","0.00635"
"627","3.72600","0.31073","0.00639"
"696","4.14000","0.34522","0.00685"
"765","4.55400","0.37972","0.00715"
"834","4.96800","0.41416","0.00749"
"903","5.38200","0.44872","0.00779"
"972","5.79600","0.48322","0.00894"
"1041","6.21000","0.51772","0.00934"
"1110","6.62400","0.55210","0.00963"
"1179","7.03800","0.58671","0.01023"
"1248","7.45200","0.62127","0.01086"
"1317","7.86600","0.65577","0.01092"
"1386","8.28000","0.69015","0.01198"
"1455","8.69400","0.72471","0.01279"
"1524","9.10800","0.75927","0.01311"
"1593","9.52200","0.79377","0.01339"
"1662","9.93600","0.82814","0.01367"
"1731","10.35000","0.86264","0.01473"
"1800","10.76400","0.89720","0.01560"
"1869","11.17800","0.93176","0.01640"
"1938","11.59200","0.96620","0.01681"
"2007","12.00600","1.00070","0.01704"
"2076","12.42000","1.03526","0.01784"
"2145","12.83400","1.06969","0.01796"
"2214","13.24800","1.10425","0.01907"
"2283","13.66200","1.13869","0.01952"
"2352","14.07600","1.17313","0.02050"
"2421","14.49000","1.20769","0.02044"
"2490","14.90400","1.24219","0.02174"
"2559","15.31800","1.27669","0.02242"
"2628","15.73200","1.31112","0.02410"
"2697","16.14600","1.34574","0.02369"
"2766","16.56000","1.38024","0.02345"
"2835","16.97400","1.41474","0.02383"
"2904","17.38800","1.44918","0.02404"
"2973","17.80200","1.48368","0.02479"
"3042","18.21600","1.51824","0.02617"
"3111","18.63000","1.55273","0.02389"
"3180","19.04400","1.58723","0.02535"
"3249","19.45800","1.62167","0.02538"
"3318","19.87200","1.65623","0.02631"
"3387","20.28600","1.69079","0.02679"
"3456","20.70000","1.72523","0.02691"
"3525","21.11400","1.75967","0.02818"
"3594","21.52800","1.79416","0.02828"
"3663","21.94200","1.82872","0.02884"
"3732","22.35600","1.86322","0.02996"
"3801","22.77000","1.89766","0.03020"
"3870","23.18400","1.93216","0.03084"
"3939","23.59800","1.96672","0.03053"
"4008","24.01200","2.00128","0.03205"
"4077","24.42600","2.03571","0.02217"
"4146","24.84000","2.07015","0.02397"
"4215","25.25400","2.10471","0.02530"
"4284","25.66800","2.13921","0.03136"
"4353","26.08200","2.17371","0.03608"
"4422","26.49600","2.20821","0.03224"
"4491","26.91000","2.24271","0.03178"
"4560","27.32400","2.27726","0.02814"
"4629","27.73800","2.31176","0.02871"
"4698","28.15200","2.34614","0.03029"
"4767","28.56600","2.38070","0.03455"
"4836","28.98000","2.41526","0.03252"
"4905","29.39400","2.44976","0.02923"
"4974","29.80800","2.48420","0.03004"
"5043","30.22200","2.51869","0.03081"
"5112","30.63600","2.55319","0.03186"
"5181","31.05000","2.58769","0.03200"
"5250","31.46400","2.62225","0.03274"
"5319","31.87800","2.65663","0.03343"
"5388","32.29200","2.69119","0.03328"
"5457","32.70600","2.72575","0.03376"
"5526","33.12000","2.76018","0.03472"
"5595","33.53400","2.79468","0.03481"
"5664","33.94800","2.82924","0.03593"
"5733","34.36200","2.86374","0.03667"
"5802","34.77600","2.89824","0.03728"
"5871","35.19000","2.93268","0.03811"
"5940","35.60400","2.96718","0.03857"
"6009","36.01800","3.00173","0.03840"
"6078","36.43200","3.03623","0.03868"
"6147","36.84600","3.07067","0.03956"
"6216","37.26000","3.10517","0.04093"
"6285","37.67400","3.13973","0.04170"
"6354","38.08800","3.17429","0.04141"
"6423","38.50200","3.20872","0.04176"
"6492","38.91600","3.24310","0.04270"
"6561","39.33000","3.27766","0.04244"
"6630","39.74400","3.31228","0.04337"
"6699","40.15800","3.34672","0.04369"
"6768","40.57200","3.38122","0.04434"
"6837","40.98600","3.41566","0.04469"
"6906","41.40000","3.45027","0.04514"
"6975","41.81400","3.48477","0.04508"
"7044","42.22800","3.51927","0.04584"
"7113","42.64200","3.55365","0.04607"
"7182","43.05600","3.58815","0.04683"
"7251","43.47000","3.62271","0.04732"
"7320","43.88400","3.65721","0.04767"
"7389","44.29800","3.69170","0.04823"
"7458","44.71200","3.72620","0.04861"
"7527","45.12600","3.76076","0.04961"
"7596","45.54000","3.79526","0.04985"
"7665","45.95400","3.82964","0.05044"
"7734","46.36800","3.86414","0.05115"
"7803","46.78200","3.89870","0.05208"
"7872","47.19600","3.93319","0.05174"
"7941","47.61000","3.96775","0.05212"
"8010","48.02400","4.00219","0.05303"
"8079","48.43800","4.03675","0.05327"
"8148","48.85200","4.07125","0.05393"
"8217","49.26600","4.10575","0.05397"
"8286","49.68000","4.14013","0.05465"
"8355","50.09400","4.17468","0.05510"
"8424","50.50800","4.20924","0.05589"
"8493","50.92200","4.24374","0.05628"
"8562","51.33600","4.27812","0.05644"
"8631","51.75000","4.31262","0.05658"
"8700","52.16400","4.34730","0.05577"
"8769","52.57800","4.38174","0.05675"
"8838","52.99200","4.41623","0.05700"
"8907","53.40600","4.45067","0.05660"
"8976","53.82000","4.48517","0.05696"
"9045","54.23400","4.51967","0.05674"
"9114","54.64800","4.55423","0.05809"
"9183","55.06200","4.58867","0.05767"
"9252","55.47600","4.62317","0.05802"
"9321","55.89000","4.65772","0.05912"
"9390","56.30400","4.69228","0.05919"
"9459","56.71800","4.72672","0.05931"
"9528","57.13200","4.76116","0.05986"
"9597","57.54600","4.79572","0.06004"
"9666","57.96000","4.83016","0.05901"
"9735","58.37400","4.86472","0.05921"
"9804","58.78800","4.89915","0.05972"
"9873","59.20200","4.93371","0.06003"
"9942","59.61600","4.96827","0.06007"
"10011","60.03000","5.00271","0.06078"
"10080","60.44400","5.03715","0.06056"
"10149","60.85800","5.07171","0.06102"
"10218","61.27200","5.10620","0.06134"
"10287","61.68600","5.14070","0.06168"
"10356","62.10000","5.17514","0.06231"
"10425","62.51400","5.20970","0.06247"
"10494","62.92800","5.24426","0.05945"
"10563","63.34200","5.27876","0.06006"
"10632","63.75600","5.31320","0.05956"
"10701","64.17000","5.34764","0.05994"
"10770","64.58400","5.38213","0.05899"
"10839","64.99800","5.41675","0.05850"
"10908","65.41200","5.45119","0.05842"
"10977","65.82600","5.48569","0.05876"
"11046","66.24000","5.52019","0.05918"
"11115","66.65400","5.55469","0.05938"
"11184","67.06800","5.58930","0.05880"
"11253","67.48200","5.62368","0.05842"
"11322","67.89600","5.65818","0.05826"
"11391","68.31000","5.69274","0.05912"
"11460","68.72400","5.72724","0.05977"
"11529","69.13800","5.76168","0.05982"
"11598","69.55200","5.79618","0.06009"
"11667","69.96600","5.83074","0.06048"
"11736","70.38000","5.86523","0.06105"
"11805","70.79400","5.89973","0.06164"
"11874","71.20800","5.93417","0.06155"
"11943","71.62200","5.96873","0.06252"
"12012","72.03600","6.00323","0.06263"
"12081","72.45000","6.03779","0.06310"
"12150","72.86400","6.07223","0.06286"
"12219","73.27800","6.10666","0.06351"
"12288","73.69200","6.14122","0.06380"
"12357","74.10600","6.17572","0.06424"
"12426","74.52000","6.21022","0.06488"
"12495","74.93400","6.24466","0.06518"
"12564","75.34800","6.27916","0.06553"
"12633","75.76200","6.31377","0.06608"
"12702","76.17600","6.34821","0.06654"
"12771","76.59000","6.38265","0.06675"
"12840","77.00400","6.41721","0.06734"
"12909","77.41800","6.45171","0.06756"
"12978","77.83200","6.48621","0.06832"
"13047","78.24600","6.52071","0.06901"
"13116","78.66000","6.55514","0.06970"
"13185","79.07400","6.58970","0.07008"
"13254","79.48800","6.62420","0.07036"
"13323","79.90200","6.65870","0.07101"
"13392","80.31600","6.69314","0.07183"
"13461","80.73000","6.72776","0.07256"
"13530","81.14400","6.76226","0.07365"
"13599","81.55800","6.79669","0.07470"
"13668","81.97200","6.83119","0.07558"
"13737","82.38600","6.86569","0.07654"
"13806","82.80000","6.90019","0.07750"
"13875","83.21400","6.93475","0.07839"
"13944","83.62800","6.96919","0.07982"
"14013","84.04200","7.00363","0.08047"
"14082","84.45600","7.03824","0.08141"
"14151","84.87000","7.07280","0.08261"
"14220","85.28400","7.10724","0.08334"
"14289","85.69800","7.14168","0.08455"
"14358","86.11200","7.17618","0.08479"
"14427","86.52600","7.21068","0.08579"
"14496","86.94000","7.24518","0.08492"
"14565","87.35400","7.27962","0.08587"
"14634","87.76800","7.31417","0.08704"
"14703","88.18200","7.34879","0.08802"
"14772","88.59600","7.38329","0.08906"
"14841","89.01000","7.41773","0.09067"
"14910","89.42400","7.45217","0.09137"
"14979","89.83800","7.48673","0.09277"
"15048","90.25200","7.52116","0.09374"
"15117","90.66600","7.55572","0.09474"
"15186","91.08000","7.59022","0.09528"
"15255","91.49400","7.62472","0.09614"
"15324","91.90800","7.65922","0.09746"
"15393","92.32200","7.69378","0.09814"
"15462","92.73600","7.72816","0.09995"
"15531","93.15000","7.76271","0.10098"
"15600","93.56400","7.79721","0.10180"
"15669","93.97800","7.83171","0.10345"
"15738","94.39200","7.86615","0.10465"
"15807","94.80600","7.90071","0.10567"
"15876","95.22000","7.93527","0.10733"
"15945","95.63400","7.96977","0.10808"
"16014","96.04800","8.00420","0.10988"
"16083","96.46200","8.03864","0.11094"
"16152","96.87600","8.07320","0.11087"
"16221","97.29000","8.10776","0.11170"
"16290","97.70400","8.14220","0.11282"
"16359","98.11800","8.17664","0.11366"
"16428","98.53200","8.21119","0.11405"
"16497","98.94600","8.24569","0.11471"
"16566","99.36000","8.28025","0.11538"
"16635","99.77400","8.31475","0.11559"
"16704","100.18800","8.34913","0.11610"
"16773","100.60200","8.38375","0.11654"
"16842","101.01600","8.41825","0.11675"
"16911","101.43000","8.45269","0.11737"
"16980","101.84400","8.48712","0.11746"
"17049","102.25800","8.52174","0.11771"
"17118","102.67200","8.55624","0.11777"
"17187","103.08600","8.59074","0.11825"
"17256","103.50000","8.62518","0.11871"
"17325","103.91400","8.65968","0.11980"
"17394","104.32800","8.69423","0.12118"
"17463","104.74200","8.72873","0.12187"
"17532","105.15600","8.76317","0.12361"
"17601","105.57000","8.79761","0.12523"
"17670","105.98400","8.83223","0.12644"
"17739","106.39800","8.86679","0.12825"
"17808","106.81200","8.90123","0.12965"
"17877","107.22600","8.93567","0.13217"
"17946","107.64000","8.97016","0.13420"
"18015","108.05400","9.00472","0.13561"
"18084","108.46800","9.03922","0.13770"
"18153","108.88200","9.07372","0.13893"
"18222","109.29600","9.10816","0.14090"
"18291","109.71000","9.14272","0.14236"
"18360","110.12400","9.17727","0.14334"
"18429","110.53800","9.21171","0.14441"
"18498","110.95200","9.24615","0.14595"
"18567","111.36600","9.28071","0.14755"
"18636","111.78000","9.31521","0.14847"
"18705","112.19400","9.34971","0.14959"
"18774","112.60800","9.38415","0.15035"
"18843","113.02200","9.41870","0.15104"
"18912","113.43600","9.45326","0.15242"
"18981","113.85000","9.48770","0.15278"
"19050","114.26400","9.52220","0.15355"
"19119","114.67800","9.55670","0.15439"
"19188","115.09200","9.59120","0.15557"
"19257","115.50600","9.62570","0.15657"
"19326","115.92000","9.66019","0.15698"
"19395","116.33400","9.69469","0.15827"
"19464","116.74800","9.72919","0.15907"
"19533","117.16200","9.76375","0.15977"
"19602","117.57600","9.79825","0.16064"
"19671","117.99000","9.83263","0.16162"
"19740","118.40400","9.86719","0.16250"
"19809","118.81800","9.90174","0.16353"
"19878","119.23200","9.93624","0.16451"
"19947","119.64600","9.97062","0.16482"
"20016","120.06000","10.00518","0.16545"
"20085","120.47400","10.03974","0.16654"
"20154","120.88800","10.07424","0.16754"
"20223","121.30200","10.10868","0.16835"
"20292","121.71600","10.14318","0.16990"
"20361","122.13000","10.17767","0.17136"
"20430","122.54400","10.21217","0.17305"
"20499","122.95800","10.24673","0.17519"
"20568","123.37200","10.28117","0.17632"
"20637","123.78600","10.31573","0.17836"
"20706","124.20000","10.35029","0.17985"
"20775","124.61400","10.38472","0.18216"
"20844","125.02800","10.41922","0.18508"
"20913","125.44200","10.45366","0.18851"
"20982","125.85600","10.48822","0.19188"
"21051","126.27000","10.52266","0.19357"
"21120","126.68400","10.55716","0.19775"
"21189","127.09800","10.59166","0.20148"
"21258","127.51200","10.62621","0.20438"
"21327","127.92600","10.66071","0.20724"
"21396","128.34000","10.69527","0.21005"
"21465","128.75400","10.72971","0.21282"
"21534","129.16800","10.76421","0.21560"
"21603","129.58200","10.79871","0.21694"
"21672","129.99600","10.83321","0.21361"
"21741","130.41000","10.86765","0.21554"
"21810","130.82400","10.90214","0.21724"
"21879","131.23800","10.93676","0.21895"
"21948","131.65200","10.97126","0.22036"
"22017","132.06600","11.00570","0.22151"
"22086","132.48000","11.04020","0.22266"
"22155","132.89400","11.07470","0.22417"
"22224","133.30800","11.10919","0.22515"
"22293","133.72200","11.14369","0.22764"
"22362","134.13600","11.17819","0.22996"
"22431","134.55000","11.21275","0.23266"
"22500","134.96400","11.24725","0.23494"
"22569","135.37800","11.28181","0.23843"
"22638","135.79200","11.31618","0.24113"
"22707","136.20600","11.35069","0.24324"
"22776","136.62000","11.38524","0.24672"
"22845","137.03400","11.41974","0.24965"
"22914","137.44800","11.45418","0.25196"
"22983","137.86200","11.48868","0.25216"
"23052","138.27600","11.52324","0.25356"
"23121","138.69000","11.55774","0.25658"
"23190","139.10400","11.59223","0.25824"
"23259","139.51800","11.62667","0.25953"
"23328","139.93200","11.66117","0.26161"
"23397","140.34600","11.69573","0.26289"
"23466","140.76000","11.73023","0.26402"
"23535","141.17400","11.76467","0.26486"
"23604","141.58800","11.79922","0.26561"
"23673","142.00200","11.83372","0.26631"
"23742","142.41600","11.86828","0.26697"
"23811","142.83000","11.90272","0.26745"
"23880","143.24400","11.93716","0.26820"
"23949","143.65800","11.97172","0.26879"
"24018","144.07200","12.00622","0.26965"
"24087","144.48600","12.04072","0.27084"
"24156","144.90000","12.07515","0.27181"
"24225","145.31400","12.10971","0.27268"
"24294","145.72800","12.14421","0.27460"
"24363","146.14200","12.17871","0.27649"
"24432","146.55600","12.21321","0.27844"
"24501","146.97000","12.24771","0.28153"
"24570","147.38400","12.28221","0.28476"
"24639","147.79800","12.31670","0.28784"
"24708","148.21200","12.35120","0.29087"
"24777","148.62600","12.38564","0.29335"
"24846","149.04000","12.42026","0.29513"
"24915","149.45400","12.45470","0.29704"
"24984","149.86800","12.48920","0.30011"
"25053","150.28200","12.52369","0.30231"
"25122","150.69600","12.55819","0.30495"
"25191","151.11000","12.59269","0.30779"
"25260","151.52400","12.62719","0.30978"
"25329","151.93800","12.66175","0.31229"
"25398","152.35200","12.69619","0.31358"
"25467","152.76600","12.73069","0.31534"
"25536","153.18000","12.76525","0.19228"
"25605","153.59400","12.79968","0.21549"
"25674","154.00800","12.83412","0.20902"
"25743","154.42200","12.86868","0.21503"
"25812","154.83600","12.90324","0.21504"
"25881","155.25000","12.93768","0.22144"
"25950","155.66400","12.97218","0.22519"
"26019","156.07800","13.00673","0.23430"
"26088","156.49200","13.04123","0.23206"
"26157","156.90600","13.07573","0.23669"
"26226","157.32000","13.11017","0.24480"
"26295","157.73400","13.14473","0.25421"
"26364","158.14800","13.17917","0.25719"
"26433","158.56200","13.21373","0.25783"
"26502","158.97600","13.24817","0.26152"
"26571","159.39000","13.28266","0.26521"
"26640","159.80400","13.31722","0.26634"
"26709","160.21800","13.35172","0.26645"
"26778","160.63200","13.38628","0.26748"
"26847","161.04600","13.42066","0.27009"
"26916","161.46000","13.45516","0.27089"
"26985","161.87400","13.48971","0.27144"
"27054","162.28800","13.52421","0.27482"
"27123","162.70200","13.55865","0.28026"
"27192","163.11600","13.59315","0.28051"
"27261","163.53000","13.62777","0.28461"
"27330","163.94400","13.66221","0.29314"
"27399","164.35800","13.69671","0.29602"
"27468","164.77200","13.73120","0.29686"
"27537","165.18600","13.76576","0.30414"
"27606","165.60000","13.80020","0.30852"
"27675","166.01400","13.83470","0.30719"
"27744","166.42800","13.86914","0.31310"
"27813","166.84200","13.90370","0.31558"
"27882","167.25600","13.93826","0.31568"
"27951","167.67000","13.97275","0.32036"
"28020","168.08400","14.00719","0.32612"
"28089","168.49800","14.04169","0.32650"
"28158","168.91200","14.07619","0.33542"
"28227","169.32600","14.11075","0.34150"
"28296","169.74000","14.14519","0.34358"
"28365","170.15400","14.17963","0.35447"
"28434","170.56800","14.21424","0.35747"
"28503","170.98200","14.24874","0.35887"
"28572","171.39600","14.28324","0.36603"
"28641","171.81000","14.31768","0.36707"
"28710","172.22400","14.35218","0.37102"
"28779","172.63800","14.38674","0.37363"
"28848","173.05200","14.42124","0.37443"
"28917","173.46600","14.45567","0.37660"
"28986","173.88000","14.49017","0.37723"
"29055","174.29400","14.52473","0.37882"
"29124","174.70800","14.55923","0.38055"
"29193","175.12200","14.59373","0.38152"
"29262","175.53600","14.62817","0.38491"
"29331","175.95000","14.66272","0.38610"
"29400","176.36400","14.69722","0.38947"
"29469","176.77800","14.73178","0.39477"
"29538","177.19200","14.76622","0.39807"
"29607","177.60600","14.80072","0.40612"
"29676","178.02000","14.83528","0.40915"
"29745","178.43400","14.86978","0.41593"
"29814","178.84800","14.90422","0.41665"
"29883","179.26200","14.93865","0.42197"
"29952","179.67600","14.97321","0.42329"
"30021","180.09000","15.00771","0.42638"
"30090","180.50400","15.04221","0.42888"
"30159","180.91800","15.07671","0.43332"
"30228","181.33200","15.11121","0.43860"
"30297","181.74600","15.14571","0.44278"
"30366","182.16000","15.18020","0.44805"
"30435","182.57400","15.21470","0.45032"
"30504","182.98800","15.24920","0.45596"
"30573","183.40200","15.28370","0.45807"
"30642","183.81600","15.31820","0.46097"
"30711","184.23000","15.35270","0.46286"
"30780","184.64400","15.38720","0.46502"
"30849","185.05800","15.42169","0.46764"
"30918","185.47200","15.45625","0.47177"
"30987","185.88600","15.49069","0.47544"
"31056","186.30000","15.52513","0.47912"
"31125","186.71400","15.55969","0.48343"
"31194","187.12800","15.59419","0.48771"
"31263","187.54200","15.62874","0.49339"
"31332","187.95600","15.66312","0.49966"
"31401","188.37000","15.69774","0.50468"
"31470","188.78400","15.73224","0.50984"
"31539","189.19800","15.76680","0.51500"
"31608","189.61200","15.80124","0.51886"
"31677","190.02600","15.83568","0.52281"
"31746","190.44000","15.87023","0.52479"
"31815","190.85400","15.90467","0.52724"
"31884","191.26800","15.93917","0.53298"
"31953","191.68200","15.97361","0.53900"
"32022","192.09600","16.00823","0.54699"
"32091","192.51000","16.04273","0.55323"
"32160","192.92400","16.07723","0.55942"
"32229","193.33800","16.11166","0.56528"
"32298","193.75200","16.14622","0.56976"
"32367","194.16600","16.18072","0.57380"
"32436","194.58000","16.21522","0.57728"
"32505","194.99400","16.24972","0.57919"
"32574","195.40800","16.28416","0.58303"
"32643","195.82200","16.31872","0.58533"
"32712","196.23600","16.35321","0.58562"
"32781","196.65000","16.38771","0.58741"
"32850","197.06400","16.42215","0.58694"
"32919","197.47800","16.45671","0.58945"
"32988","197.89200","16.49121","0.59325"
"33057","198.30600","16.52565","0.59775"
"33126","198.72000","16.56015","0.60510"
"33195","199.13400","16.59470","0.55363"
"33264","199.54800","16.62926","0.56607"
"33333","199.96200","16.66370","0.57103"
"33402","200.37600","16.69820","0.56606"
"33471","200.79000","16.73276","0.57204"
"33540","201.20400","16.76720","0.57615"
"33609","201.61800","16.80176","0.57501"
"33678","202.03200","16.83619","0.57977"
"33747","202.44600","16.87063","0.58438"
"33816","202.86000","16.90519","0.58789"
"33885","203.27400","16.93975","0.59029"
"33954","203.68800","16.97425","0.59608"
"34023","204.10200","17.00869","0.60004"
"34092","204.51600","17.04319","0.60606"
"34161","204.93000","17.07768","0.60924"
"34230","205.34400","17.11224","0.61758"
"34299","205.75800","17.14662","0.62463"
"34368","206.17200","17.18118","0.59604"
"34437","206.58600","17.21574","0.60101"
"34506","207.00000","17.25024","0.60786"
"34575","207.41400","17.28474","0.61767"
"34644","207.82800","17.31917","0.62302"
"34713","208.24200","17.35373","0.62839"
"34782","208.65600","17.38823","0.63458"
"34851","209.07000","17.42273","0.64004"
"34920","209.48400","17.45711","0.64883"
"34989","209.89800","17.49173","0.65902"
"35058","210.31200","17.52623","0.66551"
"35127","210.72600","17.56072","0.67031"
"35196","211.14000","17.59522","0.67325"
"35265","211.55400","17.62966","0.67561"
"35334","211.96800","17.66422","0.67748"
"35403","212.38200","17.69872","0.68030"
"35472","212.79600","17.73322","0.68347"
"35541","213.21000","17.76765","0.68775"
"35610","213.62400","17.80221","0.69127"
"35679","214.03800","17.83671","0.69720"
"35748","214.45200","17.87121","0.70443"
"35817","214.86600","17.90571","0.71156"
"35886","215.28000","17.94015","0.71941"
"35955","215.69400","17.97471","0.72831"
"36024","216.10800","18.00920","0.73303"
"36093","216.52200","18.04370","0.73507"
"36162","216.93600","18.07820","0.73751"
"36231","217.35000","18.11270","0.74195"
"36300","217.76400","18.14720","0.74963"
"36369","218.17800","18.18170","0.75827"
"36438","218.59200","18.21620","0.76645"
"36507","219.00600","18.25069","0.77341"
"36576","219.42000","18.28519","0.77937"
"36645","219.83400","18.31969","0.78359"
"36714","220.24800","18.35419","0.78723"
"36783","220.66200","18.38875","0.79022"
"36852","221.07600","18.42325","0.79454"
"36921","221.49000","18.45781","0.79998"
"36990","221.90400","18.49218","0.80443"
"37059","222.31800","18.52668","0.80907"
"37128","222.73200","18.56124","0.81560"
"37197","223.14600","18.59574","0.82176"
"37266","223.56000","18.63018","0.82700"
"37335","223.97400","18.66468","0.83161"
"37404","224.38800","18.69924","0.83875"
"37473","224.80200","18.73373","0.85059"
"37542","225.21600","18.76823","0.86294"
"37611","225.63000","18.80267","0.87333"
"37680","226.04400","18.83717","0.88112"
"37749","226.45800","18.87173","0.88575"
"37818","226.87200","18.90623","0.88788"
"37887","227.28600","18.94067","0.88959"
"37956","227.70000","18.97516","0.89153"
"38025","228.11400","19.00966","0.89544"
"38094","228.52800","19.04422","0.89774"
"38163","228.94200","19.07872","0.90234"
"38232","229.35600","19.11316","0.90987"
"38301","229.77000","19.14772","0.91664"
"38370","230.18400","19.18222","0.92594"
"38439","230.59800","19.21671","0.93397"
"38508","231.01200","19.25115","0.93892"
"38577","231.42600","19.28571","0.94356"
"38646","231.84000","19.32021","0.95079"
"38715","232.25400","19.35471","0.95949"
"38784","232.66800","19.38921","0.96753"
"38853","233.08200","19.42371","0.97375"
"38922","233.49600","19.45826","0.97846"
"38991","233.91000","19.49270","0.98436"
"39060","234.32400","19.52714","0.98952"
"39129","234.73800","19.56164","0.99555"
"39198","235.15200","19.59620","1.00327"
"39267","235.56600","19.63070","1.01161"
"39336","235.98000","19.66520","1.02113"
"39405","236.39400","19.69969","1.03112"
"39474","236.80800","19.73419","1.03953"
"39543","237.22200","19.76875","1.04474"
"39612","237.63600","19.80319","1.04609"
"39681","238.05000","19.83769","0.96188"
"39750","238.46400","19.87213","0.97281"
"39819","238.87800","19.90669","0.94164"
"39888","239.29200","19.94124","0.94061"
"39957","239.70600","19.97574","0.78529"
"40026","240.12000","20.01018","0.66332"
"40095","240.53400","20.04468","0.65905"
"40164","240.94800","20.07924","0.65932"
"40233","241.36200","20.11374","0.45907"
"40302","241.77600","20.14818","0.45396"
"40371","242.19000","20.18267","0.40523"
"40440","242.60400","20.21723","0.39324"
"40509","243.01800","20.25173","0.39273"
"40578","243.43200","20.28623","0.39491"
"40647","243.84600","20.32073","0.39514"
"40716","244.26000","20.35523","0.39876"
"40785","244.67400","20.38967","0.40391"
"40854","245.08800","20.42422","0.40709"
"40923","245.50200","20.45866","0.41152"
"40992","245.91600","20.49316","0.41371"
"41061","246.33000","20.52772","0.41800"
"41130","246.74400","20.56222","0.42112"
"41199","247.15800","20.59666","0.42337"
"41268","247.57200","20.63116","0.42628"
"41337","247.98600","20.66571","0.43177"
"41406","248.40000","20.70021","0.43799"
"41475","248.81400","20.73465","0.44281"
"41544","249.22800","20.76921","0.44878"
"41613","249.64200","20.80371","0.45219"
"41682","250.05600","20.83821","0.45764"
"41751","250.47000","20.87271","0.46020"
"41820","250.88400","20.90720","0.46269"
"41889","251.29800","20.94170","0.46444"
"41958","251.71200","20.97620","0.46746"
"42027","252.12600","21.01070","0.46959"
"42096","252.54000","21.04514","0.47430"
"42165","252.95400","21.07976","0.47720"
"42234","253.36800","21.11426","0.48274"
"42303","253.78200","21.14875","0.48426"
"42372","254.19600","21.18319","0.48905"
"42441","254.61000","21.21769","0.49173"
"42510","255.02400","21.25225","0.49759"
"42579","255.43800","21.28669","0.50141"
"42648","255.85200","21.32119","0.50441"
"42717","256.26600","21.35563","0.49457"
"42786","256.68000","21.39024","0.50083"
"42855","257.09400","21.42474","0.50587"
"42924","257.50800","21.45924","0.51048"
"42993","257.92200","21.49368","0.51482"
"43062","258.33600","21.52812","0.51921"
"43131","258.75000","21.56274","0.52259"
"43200","259.16400","21.59723","0.52403"
"43269","259.57800","21.63167","0.52629"
"43338","259.99200","21.66611","0.52835"
"43407","260.40600","21.70067","0.53205"
"43476","260.82000","21.73523","0.53842"
"43545","261.23400","21.76973","0.54455"
"43614","261.64800","21.80416","0.55197"
"43683","262.06200","21.83872","0.55808"
"43752","262.47600","21.87322","0.56481"
"43821","262.89000","21.90772","0.56889"
"43890","263.30400","21.94216","0.57205"
"43959","263.71800","21.97666","0.57592"
"44028","264.13200","22.01122","0.44113"
"44097","264.54600","22.04578","0.44243"
"44166","264.96000","22.08022","0.43807"
"44235","265.37400","22.11471","0.44634"
"44304","265.78800","22.14921","0.44430"
"44373","266.20200","22.18371","0.45234"
"44442","266.61600","22.21815","0.45084"
"44511","267.03000","22.25265","0.45699"
"44580","267.44400","22.28720","0.45600"
"44649","267.85800","22.32170","0.46077"
"44718","268.27200","22.35620","0.46071"
"44787","268.68600","22.39070","0.46356"
"44856","269.10000","22.42520","0.46450"
"44925","269.51400","22.45976","0.46821"
"44994","269.92800","22.49420","0.46967"
"45063","270.34200","22.52869","0.47493"
"45132","270.75600","22.56319","0.47559"
"45201","271.17000","22.59763","0.48197"
"45270","271.58400","22.63225","0.48268"
"45339","271.99800","22.66675","0.49138"
"45408","272.41200","22.70119","0.49438"
"45477","272.82600","22.73575","0.50192"
"45546","273.24000","22.77019","0.50326"
"45615","273.65400","22.80474","0.51168"
"45684","274.06800","22.83918","0.51302"
"45753","274.48200","22.87368","0.51858"
"45822","274.89600","22.90824","0.51898"
"45891","275.31000","22.94274","0.52226"
"45960","275.72400","22.97724","0.46415"
"46029","276.13800","23.01168","0.40015"
"46098","276.55200","23.04623","0.39523"
"46167","276.96600","23.08067","0.39654"
"46236","277.38000","23.11523","0.39917"
"46305","277.79400","23.14961","0.40203"
"46374","278.20800","23.18417","0.39873"
"46443","278.62200","23.21867","0.39571"
"46512","279.03600","23.25323","0.35840"
"46581","279.45000","23.28772","0.36481"
"46650","279.86400","23.32216","0.37115"
"46719","280.27800","23.35672","0.37337"
"46788","280.69200","23.39122","0.37466"
"46857","281.10600","23.42572","0.37579"
"46926","281.52000","23.46016","0.37837"
"46995","281.93400","23.49472","0.37882"
"47064","282.34800","23.52927","0.38137"
"47133","282.76200","23.56371","0.38378"
"47202","283.17600","23.59815","0.38461"
"47271","283.59000","23.63271","0.38910"
"47340","284.00400","23.66721","0.39156"
"47409","284.41800","23.70171","0.39684"
"47478","284.83200","23.73621","0.40292"
"47547","285.24600","23.77070","0.40660"
"47616","285.66000","23.80526","0.41668"
"47685","286.07400","23.83970","0.41924"
"47754","286.48800","23.87420","0.42309"
"47823","286.90200","23.90870","0.27073"
"47892","287.31600","23.94320","0.26909"
"47961","287.73000","23.97770","0.26946"
"48030","288.14400","24.01220","0.26924"
"48099","288.55800","24.04663","0.27040"
"48168","288.97200","24.08119","0.27209"
"48237","289.38600","24.11569","0.27425"
"48306","289.80000","24.15025","0.27482"
"48375","290.21400","24.18469","0.27757"
"48444","290.62800","24.21918","0.28204"
"48513","291.04200","24.25374","0.28453"
"48582","291.45600","24.28824","0.28656"
"48651","291.87000","24.32268","0.28931"
"48720","292.28400","24.35712","0.29412"
"48789","292.69800","24.39174","0.29563"
"48858","293.11200","24.42624","0.29904"
"48927","293.52600","24.46074","0.30396"
"48996","293.94000","24.49517","0.30707"
"49065","294.35400","24.52967","0.30816"
"49134","294.76800","24.56417","0.31165"
"49203","295.18200","24.59873","0.31373"
"49272","295.59600","24.63317","0.31408"
"49341","296.01000","24.66767","0.31566"
"49410","296.42400","24.70222","0.31848"
"49479","296.83800","24.73672","0.32078"
"49548","297.25200","24.77122","0.32326"
"49617","297.66600","24.80572","0.32852"
"49686","298.08000","24.84022","0.33131"
"49755","298.49400","24.87472","0.33410"
"49824","298.90800","24.90922","0.34089"
"49893","299.32200","24.94359","0.34632"
"49962","299.73600","24.97821","0.34811"
"50031","300.15000","25.01271","0.33995"
"50100","300.56400","25.04727","0.32172"
"50169","300.97800","25.08165","0.32414"
"50238","301.39200","25.11615","0.06171"
"50307","301.80600","25.15077","0.06311"
"50376","302.22000","25.18521","0.06746"
"50445","302.63400","25.21964","0.06617"
"50514","303.04800","25.25414","0.06740"
"50583","303.46200","25.28870","0.07366"
"50652","303.87600","25.32320","0.07920"
"50721","304.29000","25.35770","0.07856"
"50790","304.70400","25.39219","0.07726"
"50859","305.11800","25.42675","0.07805"
"50928","305.53200","25.46125","0.08242"
"50997","305.94600","25.49575","0.08674"
"51066","306.36000","25.53019","0.08769"
"51135","306.77400","25.56463","0.08766"
"51204","307.18800","25.59925","0.09005"
"51273","307.60200","25.63375","0.09367"
"51342","308.01600","25.66825","0.09711"
"51411","308.43000","25.70268","0.09861"
"51480","308.84400","25.73724","0.10081"
"51549","309.25800","25.77174","0.10173"
"51618","309.67200","25.80618","0.10163"
"51687","310.08600","25.84068","0.10189"
"51756","310.50000","25.87518","0.07918"
"51825","310.91400","25.90973","0.07947"
"51894","311.32800","25.94423","0.07999"
"51963","311.74200","25.97867","0.08181"
"52032","312.15600","26.01323","0.08154"
"52101","312.57000","26.04773","0.08226"
"52170","312.98400","26.08223","0.08582"
"52239","313.39800","26.11667","0.08811"
"52308","313.81200","26.15122","0.09096"
"52377","314.22600","26.18566","0.09342"
"52446","314.64000","26.22022","0.09554"
"52515","315.05400","26.25472","0.09726"
"52584","315.46800","26.28916","0.09929"
"52653","315.88200","26.32378","0.10173"
"52722","316.29600","26.35822","0.10396"
"52791","316.71000","26.39271","0.10562"
"52860","317.12400","26.42715","0.10765"
"52929","317.53800","26.46171","0.10953"
"52998","317.95200","26.49621","0.11075"
"53067","318.36600","26.53077","0.11279"
"53136","318.78000","26.56521","0.11397"
"53205","319.19400","26.59971","0.11519"
"53274","319.60800","26.63420","0.11560"
"53343","320.02200","26.66870","0.11607"
"53412","320.43600","26.70320","0.11641"
"53481","320.85000","26.73764","0.11685"
"53550","321.26400","26.77226","0.11709"
"53619","321.67800","26.80670","0.11512"
"53688","322.09200","26.84120","0.11560"
"53757","322.50600","26.87569","0.11466"
"53826","322.92000","26.91019","0.11474"
"53895","323.33400","26.94475","0.11521"
"53964","323.74800","26.97919","0.11487"
"54033","324.16200","27.01369","0.11563"
"54102","324.57600","27.04813","0.11626"
"54171","324.99000","27.08269","0.11664"
"54240","325.40400","27.11719","0.11686"
"54309","325.81800","27.15174","0.11741"
"54378","326.23200","27.18612","0.11790"
"54447","326.64600","27.22068","0.11833"
"54516","327.06000","27.25524","0.12001"
"54585","327.47400","27.28968","0.12099"
"54654","327.88800","27.32412","0.12115"
"54723","328.30200","27.35867","0.12303"
"54792","328.71600","27.39329","0.12479"
"54861","329.13000","27.42767","0.12604"
"54930","329.54400","27.46223","0.12605"
"54999","329.95800","27.49673","0.12240"
"55068","330.37200","27.53117","0.12201"
"55137","330.78600","27.56573","0.12225"
"55206","331.20000","27.60023","0.11993"
"55275","331.61400","27.63466","0.12108"
"55344","332.02800","27.66916","0.12284"
"55413","332.44200","27.70372","0.12481"
"55482","332.85600","27.73822","0.12482"
"55551","333.27000","27.77272","0.12595"
"55620","333.68400","27.80721","0.12507"
"55689","334.09800","27.84171","0.12639"
"55758","334.51200","27.87621","0.12633"
"55827","334.92600","27.91065","0.12127"
"55896","335.34000","27.94515","0.12110"
"55965","335.75400","27.97971","0.12096"
"56034","336.16800","28.01421","0.12008"
"56103","336.58200","28.04871","0.12000"
"56172","336.99600","28.08315","0.11781"
"56241","337.41000","28.11776","0.11808"
"56310","337.82400","28.15220","0.11788"
"56379","338.23800","28.18670","0.11708"
"56448","338.65200","28.22120","0.11698"
"56517","339.06600","28.25570","0.11730"
"56586","339.48000","28.29025","0.11711"
"56655","339.89400","28.32475","0.11728"
"56724","340.30800","28.35925","0.11825"
"56793","340.72200","28.39375","0.11854"
"56862","341.13600","28.42825","0.11889"
"56931","341.55000","28.46275","0.11954"
"57000","341.96400","28.49725","0.12105"
"57069","342.37800","28.53163","0.11793"
"57138","342.79200","28.56618","0.11772"
"57207","343.20600","28.60074","0.11736"
"57276","343.62000","28.63524","0.11803"
"57345","344.03400","28.66974","0.11827"
"57414","344.44800","28.70418","0.11924"
"57483","344.86200","28.73874","0.12073"
"57552","345.27600","28.77317","0.11878"
"57621","345.69000","28.80767","0.11929"
"57690","346.10400","28.84217","0.12036"
"57759","346.51800","28.87673","0.12241"
"57828","346.93200","28.91123","0.12337"
"57897","347.34600","28.94567","0.12071"
"57966","347.76000","28.98017","0.12260"
"58035","348.17400","29.01472","0.12376"
"58104","348.58800","29.04922","0.12575"
"58173","349.00200","29.08372","0.12745"
"58242","349.41600","29.11822","0.12684"
"58311","349.83000","29.15272","0.12895"
"58380","350.24400","29.18728","0.13029"
"58449","350.65800","29.22172","0.13293"
"58518","351.07200","29.25616","0.13488"
"58587","351.48600","29.29065","0.13463"
"58656","351.90000","29.32527","0.13699"
"58725","352.31400","29.35971","0.13859"
"58794","352.72800","29.39415","0.13764"
"58863","353.14200","29.42859","0.13888"
"58932","353.55600","29.46321","0.14097"
"59001","353.97000","29.49771","0.14206"
"59070","354.38400","29.53220","0.14431"
"59139","354.79800","29.56664","0.14321"
"59208","355.21200","29.60114","0.14424"
"59277","355.62600","29.63570","0.14554"
"59346","356.04000","29.67020","0.14693"
"59415","356.45400","29.70470","0.14785"
"59484","356.86800","29.73919","0.15014"
"59553","357.28200","29.77369","0.15107"
"59622","357.69600","29.80819","0.15181"
"59691","358.11000","29.84269","0.15292"
"59760","358.52400","29.87713","0.15304"
"59829","358.93800","29.91175","0.15422"
"59898","359.35200","29.94625","0.15542"
"59967","359.76600","29.98075","0.15654"
"60036","360.18000","30.01512","0.15730"
"60105","360.59400","30.04962","0.15872"
"60174","361.00800","30.08424","0.15981"
"60243","361.42200","30.11874","0.16108"
"60312","361.83600","30.15318","0.16243"
"60381","362.25000","30.18768","0.16320"
"60450","362.66400","30.22217","0.16445"
"60519","363.07800","30.25667","0.16546"
"60588","363.49200","30.29117","0.16586"
"60657","363.90600","30.32567","0.16700"
"60726","364.32000","30.36023","0.16763"
"60795","364.73400","30.39473","0.16863"
"60864","365.14800","30.42923","0.16959"
"60933","365.56200","30.46366","0.16980"
"61002","365.97600","30.49816","0.17024"
"61071","366.39000","30.53272","0.17093"
"61140","366.80400","30.56722","0.17266"
"61209","367.21800","30.60172","0.17379"
"61278","367.63200","30.63616","0.17623"
"61347","368.04600","30.67066","0.17736"
"61416","368.46000","30.70521","0.17937"
"61485","368.87400","30.73971","0.18143"
"61554","369.28800","30.77421","0.18271"
"61623","369.70200","30.80871","0.18510"
"61692","370.11600","30.84321","0.18990"
"61761","370.53000","30.87771","0.19443"
"61830","370.94400","30.91221","0.19648"
"61899","371.35800","30.94665","0.20143"
"61968","371.77200","30.98126","0.18804"
"62037","372.18600","31.01570","0.18993"
"62106","372.60000","31.05020","0.19051"
"62175","373.01400","31.08470","0.19288"
"62244","373.42800","31.11920","0.19135"
"62313","373.84200","31.15370","0.18443"
"62382","374.25600","31.18820","0.17520"
"62451","374.67000","31.22269","0.17185"
"62520","375.08400","31.25713","0.17034"
"62589","375.49800","31.29169","0.17076"
"62658","375.91200","31.32625","0.17191"
"62727","376.32600","31.36074","0.17104"
"62796","376.74000","31.39519","0.17262"
"62865","377.15400","31.42974","0.17236"
"62934","377.56800","31.46424","0.17204"
"63003","377.98200","31.49868","0.17327"
"63072","378.39600","31.53318","0.17320"
"63141","378.81000","31.56768","0.17035"
"63210","379.22400","31.60223","0.17107"
"63279","379.63800","31.63667","0.17173"
"63348","380.05200","31.67117","0.17207"
"63417","380.46600","31.70573","0.17398"
"63486","380.88000","31.74023","0.17590"
"63555","381.29400","31.77473","0.17802"
"63624","381.70800","31.80917","0.18092"
"63693","382.12200","31.84373","0.18383"
"63762","382.53600","31.87823","0.18639"
"63831","382.95000","31.91272","0.18947"
"63900","383.36400","31.94722","0.19306"
"63969","383.77800","31.98166","0.19301"
"64038","384.19200","32.01622","0.19110"
"64107","384.60600","32.05078","0.19237"
"64176","385.02000","32.08521","0.19308"
"64245","385.43400","32.11959","0.19633"
"64314","385.84800","32.15421","0.19540"
"64383","386.26200","32.18871","0.19766"
"64452","386.67600","32.22321","0.19412"
"64521","387.09000","32.25771","0.19421"
"64590","387.50400","32.29214","0.19424"
"64659","387.91800","32.32677","0.19701"
"64728","388.33200","32.36120","0.19908"
"64797","388.74600","32.39564","0.20180"
"64866","389.16000","32.43014","0.20542"
"64935","389.57400","32.46470","0.20736"
"65004","389.98800","32.49920","0.20756"
"65073","390.40200","32.53370","0.20771"
"65142","390.81600","32.56820","0.20922"
"65211","391.23000","32.60270","0.21258"
"65280","391.64400","32.63720","0.21453"
"65349","392.05800","32.67175","0.21622"
"65418","392.47200","32.70619","0.21826"
"65487","392.88600","32.74063","0.21965"
"65556","393.30000","32.77525","0.21908"
"65625","393.71400","32.80975","0.22021"
"65694","394.12800","32.84424","0.22126"
"65763","394.54200","32.87868","0.22223"
"65832","394.95600","32.91324","0.22415"
"65901","395.37000","32.94774","0.22678"
"65970","395.78400","32.98218","0.22635"
"66039","396.19800","33.01662","0.22711"
"66108","396.61200","33.05117","0.23072"
"66177","397.02600","33.08574","0.23281"
"66246","397.44000","33.12024","0.23685"
"66315","397.85400","33.15467","0.23849"
"66384","398.26800","33.18917","0.24012"
"66453","398.68200","33.22372","0.24279"
"66522","399.09600","33.25822","0.24509"
"66591","399.51000","33.29267","0.24776"
"66660","399.92400","33.32716","0.25100"
"66729","400.33800","33.36166","0.25371"
"66798","400.75200","33.39622","0.25629"
"66867","401.16600","33.43072","0.25841"
"66936","401.58000","33.46522","0.25923"
"67005","401.99400","33.49978","0.26005"
"67074","402.40800","33.53421","0.26226"
"67143","402.82200","33.56871","0.26304"
"67212","403.23600","33.60315","0.26436"
"67281","403.65000","33.63765","0.26449"
"67350","404.06400","33.67227","0.26540"
"67419","404.47800","33.70671","0.26608"
"67488","404.89200","33.74121","0.26675"
"67557","405.30600","33.77571","0.26727"
"67626","405.72000","33.81026","0.26778"
"67695","406.13400","33.84470","0.26846"
"67764","406.54800","33.87920","0.26924"
"67833","406.96200","33.91358","0.26958"
"67902","407.37600","33.94820","0.26965"
"67971","407.79000","33.98270","0.27039"
"68040","408.20400","34.01719","0.27141"
"68109","408.61800","34.05169","0.27181"
"68178","409.03200","34.08619","0.27381"
"68247","409.44600","34.12069","0.27344"
"68316","409.86000","34.15519","0.27128"
"68385","410.27400","34.18969","0.27145"
"68454","410.68800","34.22419","0.27229"
"68523","411.10200","34.25869","0.27447"
"68592","411.51600","34.29318","0.27613"
"68661","411.93000","34.32768","0.27726"
"68730","412.34400","34.36218","0.27955"
"68799","412.75800","34.39674","0.28138"
"68868","413.17200","34.43130","0.27730"
"68937","413.58600","34.46574","0.27637"
"69006","414.00000","34.50018","0.27742"
"69075","414.41400","34.53468","0.27828"
"69144","414.82800","34.56923","0.27923"
"69213","415.24200","34.60367","0.27985"
"69282","415.65600","34.63817","0.27872"
"69351","416.07000","34.67266","0.27683"
"69420","416.48400","34.70723","0.27753"
"69489","416.89800","34.74173","0.27593"
"69558","417.31200","34.77622","0.27501"
"69627","417.72600","34.81066","0.27148"
"69696","418.14000","34.84516","0.27137"
"69765","418.55400","34.87972","0.27177"
"69834","418.96800","34.91422","0.27303"
"69903","419.38200","34.94872","0.27439"
"69972","419.79600","34.98322","0.27587"
"70041","420.21000","35.01777","0.27675"
"70110","420.62400","35.05227","0.27845"
"70179","421.03800","35.08665","0.28208"
"70248","421.45200","35.12115","0.28431"
"70317","421.86600","35.15570","0.28465"
"70386","422.28000","35.19020","0.28517"
"70455","422.69400","35.22470","0.28645"
"70524","423.10800","35.25920","0.28892"
"70593","423.52200","35.29370","0.29175"
"70662","423.93600","35.32826","0.29337"
"70731","424.35000","35.36276","0.29535"
"70800","424.76400","35.39714","0.29725"
"70869","425.17800","35.43169","0.29939"
"70938","425.59200","35.46619","0.30101"
"71007","426.00600","35.50069","0.30189"
"71076","426.42000","35.53519","0.30536"
"71145","426.83400","35.56969","0.30828"
"71214","427.24800","35.60425","0.31131"
"71283","427.66200","35.63869","0.31302"
"71352","428.07600","35.67324","0.31369"
"71421","428.49000","35.70762","0.31526"
"71490","428.90400","35.74218","0.31646"
"71559","429.31800","35.77668","0.31763"
"71628","429.73200","35.81124","0.32014"
"71697","430.14600","35.84568","0.32150"
"71766","430.56000","35.88018","0.32553"
"71835","430.97400","35.91473","0.32970"
"71904","431.38800","35.94923","0.33353"
"71973","431.80200","35.98367","0.33909"
"72042","432.21600","36.01811","0.34554"
"72111","432.63000","36.05273","0.35154"
"72180","433.04400","36.08717","0.35639"
"72249","433.45800","36.12173","0.35960"
"72318","433.87200","36.15617","0.36241"
"72387","434.28600","36.19072","0.36528"
"72456","434.70000","36.22522","0.36703"
"72525","435.11400","36.25972","0.36855"
"72594","435.52800","36.29422","0.37063"
"72663","435.94200","36.32866","0.37203"
"72732","436.35600","36.36322","0.37362"
"72801","436.77000","36.39771","0.37445"
"72870","437.18400","36.43221","0.37516"
"72939","437.59800","36.46666","0.35253"
"73008","438.01200","36.50127","0.35579"
"73077","438.42600","36.53577","0.35921"
"73146","438.84000","36.57021","0.35908"
"73215","439.25400","36.60464","0.36034"
"73284","439.66800","36.63914","0.36257"
"73353","440.08200","36.67376","0.36302"
"73422","440.49600","36.70820","0.36449"
"73491","440.91000","36.74270","0.36859"
"73560","441.32400","36.77720","0.37123"
"73629","441.73800","36.81170","0.37304"
"73698","442.15200","36.84620","0.37494"
"73767","442.56600","36.88070","0.37520"
"73836","442.98000","36.91525","0.37543"
"73905","443.39400","36.94970","0.37596"
"73974","443.80800","36.98419","0.37707"
"74043","444.22200","37.01869","0.37837"
"74112","444.63600","37.05319","0.37995"
"74181","445.05000","37.08775","0.37919"
"74250","445.46400","37.12225","0.38053"
"74319","445.87800","37.15674","0.38190"
"74388","446.29200","37.19118","0.38327"
"74457","446.70600","37.22568","0.38633"
"74526","447.12000","37.26018","0.38902"
"74595","447.53400","37.29468","0.39201"
"74664","447.94800","37.32918","0.39610"
"74733","448.36200","37.36367","0.39964"
"74802","448.77600","37.39824","0.40504"
"74871","449.19000","37.43273","0.40694"
"74940","449.60400","37.46723","0.41170"
"75009","450.01800","37.50161","0.41534"
"75078","450.43200","37.53622","0.41861"
"75147","450.84600","37.57072","0.40371"
"75216","451.26000","37.60522","0.40716"
"75285","451.67400","37.63966","0.40910"
"75354","452.08800","37.67416","0.40823"
"75423","452.50200","37.70872","0.41151"
"75492","452.91600","37.74322","0.41384"
"75561","453.33000","37.77772","0.41471"
"75630","453.74400","37.81210","0.41462"
"75699","454.15800","37.84671","0.41644"
"75768","454.57200","37.88121","0.41907"
"75837","454.98600","37.91571","0.41833"
"75906","455.40000","37.95015","0.42000"
"75975","455.81400","37.98471","0.42154"
"76044","456.22800","38.01926","0.41978"
"76113","456.64200","38.05376","0.42166"
"76182","457.05600","38.08815","0.42367"
"76251","457.47000","38.12264","0.42510"
"76320","457.88400","38.15720","0.42838"
"76389","458.29800","38.19164","0.43331"
"76458","458.71200","38.22620","0.43839"
"76527","459.12600","38.26070","0.44183"
"76596","459.54000","38.29519","0.44499"
"76665","459.95400","38.32969","0.44978"
"76734","460.36800","38.36419","0.45323"
"76803","460.78200","38.39863","0.45630"
"76872","461.19600","38.43313","0.45765"
"76941","461.61000","38.46775","0.46009"
"77010","462.02400","38.50225","0.46074"
"77079","462.43800","38.53669","0.46184"
"77148","462.85200","38.57119","0.46299"
"77217","463.26600","38.60574","0.46446"
"77286","463.68000","38.64024","0.46736"
"77355","464.09400","38.67468","0.46981"
"77424","464.50800","38.70912","0.47299"
"77493","464.92200","38.74368","0.47544"
"77562","465.33600","38.77823","0.47101"
"77631","465.75000","38.81273","0.47196"
"77700","466.16400","38.84723","0.47461"
"77769","466.57800","38.88173","0.47823"
"77838","466.99200","38.91623","0.47956"
"77907","467.40600","38.95073","0.45928"
"77976","467.82000","38.98517","0.45841"
"78045","468.23400","39.01966","0.45962"
"78114","468.64800","39.05423","0.45836"
"78183","469.06200","39.08872","0.46096"
"78252","469.47600","39.12322","0.46205"
"78321","469.89000","39.15772","0.46313"
"78390","470.30400","39.19228","0.46457"
"78459","470.71800","39.22672","0.46395"
"78528","471.13200","39.26121","0.46149"
"78597","471.54600","39.29565","0.46167"
"78666","471.96000","39.33015","0.46423"
"78735","472.37400","39.36471","0.46715"
"78804","472.78800","39.39921","0.46806"
"78873","473.20200","39.43365","0.47123"
"78942","473.61600","39.46815","0.47398"
"79011","474.03000","39.50276","0.47756"
"79080","474.44400","39.53727","0.47964"
"79149","474.85800","39.57170","0.48083"
"79218","475.27200","39.60614","0.48391"
"79287","475.68600","39.64070","0.48604"
"79356","476.10000","39.67520","0.48691"
"79425","476.51400","39.70970","0.49047"
"79494","476.92800","39.74419","0.49472"
"79563","477.34200","39.77869","0.50117"
"79632","477.75600","39.81326","0.50437"
"79701","478.17000","39.84775","0.50639"
"79770","478.58400","39.88219","0.51022"
"79839","478.99800","39.91669","0.51040"
"79908","479.41200","39.95119","0.51351"
"79977","479.82600","39.98569","0.51688"
"80046","480.24000","40.02018","0.51966"
"80115","480.65400","40.05468","0.52139"
"80184","481.06800","40.08924","0.52231"
"80253","481.48200","40.12374","0.52336"
"80322","481.89600","40.15824","0.52387"
"80391","482.31000","40.19262","0.52491"
"80460","482.72400","40.22723","0.52644"
"80529","483.13800","40.26173","0.52698"
"80598","483.55200","40.29617","0.52125"
"80667","483.96600","40.33067","0.52263"
"80736","484.38000","40.36517","0.52364"
"80805","484.79400","40.39973","0.52533"
"80874","485.20800","40.43428","0.52812"
"80943","485.62200","40.46867","0.53292"
"81012","486.03600","40.50316","0.53744"
"81081","486.45000","40.53766","0.54187"
"81150","486.86400","40.57228","0.54636"
"81219","487.27800","40.60672","0.55011"
"81288","487.69200","40.64116","0.55428"
"81357","488.10600","40.67566","0.55942"
"81426","488.52000","40.71021","0.33885"
"81495","488.93400","40.74477","0.33616"
"81564","489.34800","40.77921","0.35625"
"81633","489.76200","40.81365","0.36350"
"81702","490.17600","40.84815","0.35908"
"81771","490.59000","40.88271","0.36814"
"81840","491.00400","40.91714","0.37357"
"81909","491.41800","40.95171","0.37197"
"81978","491.83200","40.98620","0.37458"
"82047","492.24600","41.02070","0.37698"
"82116","492.66000","41.05520","0.37676"
"82185","493.07400","41.08964","0.37881"
"82254","493.48800","41.12420","0.38401"
"82323","493.90200","41.15870","0.38239"
"82392","494.31600","41.19325","0.38649"
"82461","494.73000","41.22770","0.39215"
"82530","495.14400","41.26219","0.39166"
"82599","495.55800","41.29669","0.40131"
"82668","495.97200","41.33119","0.40615"
"82737","496.38600","41.36568","0.40713"
"82806","496.80000","41.40012","0.41826"
"82875","497.21400","41.43468","0.41923"
"82944","497.62800","41.46918","0.42197"
"83013","498.04200","41.50374","0.42485"
"83082","498.45600","41.53812","0.42541"
"83151","498.87000","41.57268","0.43136"
"83220","499.28400","41.60724","0.43474"
"83289","499.69800","41.64174","0.43786"
"83358","500.11200","41.67617","0.44335"
"83427","500.52600","41.71067","0.44355"
"83496","500.94000","41.74523","0.44882"
"83565","501.35400","41.77973","0.44450"
"83634","501.76800","41.81423","0.44754"
"83703","502.18200","41.84872","0.44995"
"83772","502.59600","41.88322","0.45153"
"83841","503.01000","41.91772","0.45520"
"83910","503.42400","41.95222","0.45546"
"83979","503.83800","41.98666","0.45818"
"84048","504.25200","42.02116","0.45975"
"84117","504.66600","42.05572","0.46085"
"84186","505.08000","42.09027","0.46234"
"84255","505.49400","42.12471","0.46368"
"84324","505.90800","42.15915","0.46468"
"84393","506.32200","42.19378","0.46595"
"84462","506.73600","42.22827","0.46840"
"84531","507.15000","42.26271","0.46920"
"84600","507.56400","42.29715","0.46903"
"84669","507.97800","42.33165","0.47018"
"84738","508.39200","42.36626","0.47249"
"84807","508.80600","42.40070","0.47389"
"84876","509.22000","42.43514","0.47522"
"84945","509.63400","42.46970","0.47333"
"85014","510.04800","42.50426","0.47177"
"85024","510.10400","42.50886","0.47154"