File: Trajectories_together/170225_1Specimen_RawData_5.csv
"","V1","V2","V3"
"1","End date","2/25/2017",""
"2","Specimen label","2AT_15",""
"3","Maximum Load","0.21246","N"
"4","Time","Extension","Load"
"5","(s)","(mm)","(N)"
"6","0.00000","0.00000","-0.00007"
"74","0.40800","0.03426","-0.00005"
"142","0.81600","0.06822","0.00024"
"210","1.22400","0.10224","0.00034"
"278","1.63200","0.13620","0.00069"
"346","2.04000","0.17016","0.00064"
"414","2.44800","0.20418","0.00085"
"482","2.85600","0.23826","0.00076"
"550","3.26400","0.27222","0.00104"
"618","3.67200","0.30624","0.00072"
"686","4.08000","0.34020","0.00093"
"754","4.48800","0.37422","0.00077"
"822","4.89600","0.40824","0.00092"
"890","5.30400","0.44226","0.00092"
"958","5.71200","0.47616","0.00091"
"1026","6.12000","0.51018","0.00073"
"1094","6.52800","0.54420","0.00079"
"1162","6.93600","0.57822","0.00090"
"1230","7.34400","0.61219","0.00082"
"1298","7.75200","0.64621","0.00094"
"1366","8.16000","0.68029","0.00072"
"1434","8.56800","0.71425","0.00135"
"1502","8.97600","0.74815","0.00149"
"1570","9.38400","0.78217","0.00112"
"1638","9.79200","0.81625","0.00060"
"1706","10.20000","0.85027","0.00081"
"1774","10.60800","0.88429","0.00110"
"1842","11.01600","0.91819","0.00084"
"1910","11.42400","0.95227","0.00026"
"1978","11.83200","0.98623","0.00112"
"2046","12.24000","1.02019","0.00081"
"2114","12.64800","1.05415","0.00082"
"2182","13.05600","1.08829","0.00046"
"2250","13.46400","1.12231","0.00107"
"2318","13.87200","1.15621","0.00122"
"2386","14.28000","1.19017","0.00061"
"2454","14.68800","1.22419","0.00047"
"2522","15.09600","1.25827","0.00119"
"2590","15.50400","1.29223","0.00080"
"2658","15.91200","1.32619","0.00083"
"2726","16.32000","1.36021","0.00098"
"2794","16.72800","1.39423","0.00088"
"2862","17.13600","1.42819","0.00076"
"2930","17.54400","1.46215","0.00110"
"2998","17.95200","1.49623","0.00084"
"3066","18.36000","1.53025","0.00077"
"3134","18.76800","1.56427","0.00066"
"3202","19.17600","1.59817","0.00120"
"3270","19.58400","1.63213","0.00114"
"3338","19.99200","1.66621","0.00120"
"3406","20.40000","1.70024","0.00126"
"3474","20.80800","1.73420","0.00113"
"3542","21.21600","1.76822","0.00074"
"3610","21.62400","1.80230","0.00119"
"3678","22.03200","1.83626","0.00104"
"3746","22.44000","1.87016","0.00111"
"3814","22.84800","1.90424","0.00091"
"3882","23.25600","1.93826","0.00171"
"3950","23.66400","1.97228","0.00113"
"4018","24.07200","2.00624","0.00076"
"4086","24.48000","2.04020","0.00169"
"4154","24.88800","2.07422","0.00127"
"4222","25.29600","2.10818","0.00108"
"4290","25.70400","2.14220","0.00122"
"4358","26.11200","2.17622","0.00141"
"4426","26.52000","2.21024","0.00123"
"4494","26.92800","2.24426","0.00175"
"4562","27.33600","2.27816","0.00167"
"4630","27.74400","2.31218","0.00141"
"4698","28.15200","2.34620","0.00155"
"4766","28.56000","2.38022","0.00156"
"4834","28.96800","2.41424","0.00134"
"4902","29.37600","2.44820","0.00177"
"4970","29.78400","2.48222","0.00181"
"5038","30.19200","2.51624","0.00175"
"5106","30.60000","2.55026","0.00137"
"5174","31.00800","2.58416","0.00159"
"5242","31.41600","2.61824","0.00110"
"5310","31.82400","2.65220","0.00191"
"5378","32.23200","2.68622","0.00168"
"5446","32.64000","2.72018","0.00144"
"5514","33.04800","2.75420","0.00207"
"5582","33.45600","2.78823","0.00174"
"5650","33.86400","2.82225","0.00178"
"5718","34.27200","2.85621","0.00187"
"5786","34.68000","2.89023","0.00177"
"5854","35.08800","2.92419","0.00157"
"5922","35.49600","2.95821","0.00225"
"5990","35.90400","2.99217","0.00221"
"6058","36.31200","3.02619","0.00209"
"6126","36.72000","3.06027","0.00214"
"6194","37.12800","3.09423","0.00185"
"6262","37.53600","3.12819","0.00221"
"6330","37.94400","3.16221","0.00223"
"6398","38.35200","3.19617","0.00277"
"6466","38.76000","3.23019","0.00261"
"6534","39.16800","3.26427","0.00259"
"6602","39.57600","3.29817","0.00255"
"6670","39.98400","3.33219","0.00240"
"6738","40.39200","3.36627","0.00244"
"6806","40.80000","3.40023","0.00264"
"6874","41.20800","3.43419","0.00308"
"6942","41.61600","3.46827","0.00338"
"7010","42.02400","3.50229","0.00301"
"7078","42.43200","3.53625","0.00284"
"7146","42.84000","3.57015","0.00326"
"7214","43.24800","3.60423","0.00339"
"7282","43.65600","3.63825","0.00346"
"7350","44.06400","3.67221","0.00263"
"7418","44.47200","3.70623","0.00303"
"7486","44.88000","3.74019","0.00342"
"7554","45.28800","3.77421","0.00339"
"7622","45.69600","3.80823","0.00333"
"7690","46.10400","3.84220","0.00332"
"7758","46.51200","3.87622","0.00324"
"7826","46.92000","3.91024","0.00357"
"7894","47.32800","3.94426","0.00375"
"7962","47.73600","3.97816","0.00352"
"8030","48.14400","4.01218","0.00392"
"8098","48.55200","4.04620","0.00465"
"8166","48.96000","4.08022","0.00428"
"8234","49.36800","4.11418","0.00438"
"8302","49.77600","4.14820","0.00426"
"8370","50.18400","4.18228","0.00428"
"8438","50.59200","4.21618","0.00436"
"8506","51.00000","4.25020","0.00477"
"8574","51.40800","4.28422","0.00526"
"8642","51.81600","4.31824","0.00498"
"8710","52.22400","4.35226","0.00504"
"8778","52.63200","4.38622","0.00546"
"8846","53.04000","4.42018","0.00571"
"8914","53.44800","4.45420","0.00522"
"8982","53.85600","4.48822","0.00601"
"9050","54.26400","4.52224","0.00547"
"9118","54.67200","4.55620","0.00608"
"9186","55.08000","4.59022","0.00621"
"9254","55.48800","4.62418","0.00594"
"9322","55.89600","4.65826","0.00627"
"9390","56.30400","4.69210","0.00584"
"9458","56.71200","4.72624","0.00663"
"9526","57.12000","4.76026","0.00691"
"9594","57.52800","4.79428","0.00670"
"9662","57.93600","4.82824","0.00735"
"9730","58.34400","4.86220","0.00760"
"9798","58.75200","4.89622","0.00752"
"9866","59.16000","4.93024","0.00721"
"9934","59.56800","4.96421","0.00781"
"10002","59.97600","4.99823","0.00807"
"10070","60.38400","5.03225","0.00796"
"10138","60.79200","5.06621","0.00919"
"10206","61.20000","5.10023","0.00902"
"10274","61.60800","5.13419","0.00888"
"10342","62.01600","5.16821","0.00918"
"10410","62.42400","5.20229","0.00929"
"10478","62.83200","5.23625","0.00947"
"10546","63.24000","5.27015","0.00996"
"10614","63.64800","5.30423","0.01046"
"10682","64.05600","5.33819","0.01065"
"10750","64.46400","5.37221","0.01020"
"10818","64.87200","5.40617","0.01104"
"10886","65.28000","5.44025","0.01123"
"10954","65.68800","5.47427","0.01169"
"11022","66.09600","5.50817","0.01176"
"11090","66.50400","5.54213","0.01220"
"11158","66.91200","5.57621","0.01254"
"11226","67.32000","5.61023","0.01223"
"11294","67.72800","5.64425","0.01274"
"11362","68.13600","5.67815","0.01292"
"11430","68.54400","5.71217","0.01326"
"11498","68.95200","5.74625","0.01385"
"11566","69.36000","5.78021","0.01417"
"11634","69.76800","5.81417","0.01491"
"11702","70.17600","5.84819","0.01437"
"11770","70.58400","5.88221","0.01537"
"11838","70.99200","5.91623","0.01518"
"11906","71.40000","5.95019","0.01556"
"11974","71.80800","5.98416","0.01571"
"12042","72.21600","6.01829","0.01657"
"12110","72.62400","6.05226","0.01702"
"12178","73.03200","6.08622","0.01696"
"12246","73.44000","6.12018","0.01716"
"12314","73.84800","6.15426","0.01773"
"12382","74.25600","6.18822","0.01857"
"12450","74.66400","6.22218","0.01854"
"12518","75.07200","6.25614","0.01869"
"12586","75.48000","6.29028","0.01962"
"12654","75.88800","6.32424","0.01984"
"12722","76.29600","6.35826","0.02002"
"12790","76.70400","6.39222","0.02070"
"12858","77.11200","6.42624","0.02065"
"12926","77.52000","6.46026","0.02160"
"12994","77.92800","6.49422","0.02156"
"13062","78.33600","6.52818","0.02234"
"13130","78.74400","6.56226","0.02286"
"13198","79.15200","6.59622","0.02423"
"13266","79.56000","6.63024","0.02466"
"13334","79.96800","6.66420","0.02536"
"13402","80.37600","6.69816","0.02519"
"13470","80.78400","6.73230","0.02574"
"13538","81.19200","6.76626","0.02663"
"13606","81.60000","6.80016","0.02743"
"13674","82.00800","6.83418","0.02876"
"13742","82.41600","6.86826","0.02884"
"13810","82.82400","6.90222","0.03008"
"13878","83.23200","6.93618","0.03041"
"13946","83.64000","6.97020","0.03079"
"14014","84.04800","7.00422","0.03318"
"14082","84.45600","7.03824","0.03313"
"14150","84.86400","7.07221","0.03423"
"14218","85.27200","7.10623","0.03448"
"14286","85.68000","7.14025","0.03586"
"14354","86.08800","7.17427","0.03688"
"14422","86.49600","7.20817","0.03835"
"14490","86.90400","7.24219","0.03842"
"14558","87.31200","7.27621","0.03992"
"14626","87.72000","7.31023","0.04090"
"14694","88.12800","7.34419","0.04096"
"14762","88.53600","7.37821","0.04257"
"14830","88.94400","7.41223","0.04351"
"14898","89.35200","7.44625","0.04425"
"14966","89.76000","7.48021","0.04583"
"15034","90.16800","7.51417","0.04591"
"15102","90.57600","7.54819","0.04662"
"15170","90.98400","7.58227","0.04738"
"15238","91.39200","7.61623","0.04815"
"15306","91.80000","7.65019","0.04869"
"15374","92.20800","7.68421","0.04944"
"15442","92.61600","7.71823","0.04978"
"15510","93.02400","7.75219","0.05036"
"15578","93.43200","7.78621","0.05098"
"15646","93.84000","7.82023","0.05162"
"15714","94.24800","7.85425","0.05242"
"15782","94.65600","7.88827","0.05253"
"15850","95.06400","7.92217","0.05250"
"15918","95.47200","7.95625","0.05272"
"15986","95.88000","7.99021","0.05315"
"16054","96.28800","8.02429","0.05345"
"16122","96.69600","8.05825","0.05363"
"16190","97.10400","8.09221","0.05381"
"16258","97.51200","8.12624","0.05439"
"16326","97.92000","8.16025","0.05446"
"16394","98.32800","8.19422","0.05476"
"16462","98.73600","8.22818","0.05513"
"16530","99.14400","8.26226","0.05546"
"16598","99.55200","8.29622","0.05554"
"16666","99.96000","8.33024","0.05599"
"16734","100.36800","8.36420","0.05632"
"16802","100.77600","8.39822","0.05650"
"16870","101.18400","8.43224","0.05649"
"16938","101.59200","8.46620","0.05692"
"17006","102.00000","8.50022","0.05725"
"17074","102.40800","8.53424","0.05770"
"17142","102.81600","8.56820","0.05789"
"17210","103.22400","8.60228","0.05827"
"17278","103.63200","8.63618","0.05849"
"17346","104.04000","8.67020","0.05900"
"17414","104.44800","8.70428","0.05919"
"17482","104.85600","8.73824","0.05967"
"17550","105.26400","8.77214","0.05984"
"17618","105.67200","8.80616","0.06036"
"17686","106.08000","8.84024","0.06043"
"17754","106.48800","8.87426","0.06086"
"17822","106.89600","8.90816","0.06101"
"17890","107.30400","8.94224","0.06199"
"17958","107.71200","8.97626","0.06262"
"18026","108.12000","9.01028","0.06299"
"18094","108.52800","9.04418","0.06381"
"18162","108.93600","9.07820","0.06473"
"18230","109.34400","9.11228","0.06517"
"18298","109.75200","9.14624","0.06650"
"18366","110.16000","9.18021","0.06653"
"18434","110.56800","9.21416","0.06763"
"18502","110.97600","9.24824","0.06903"
"18570","111.38400","9.28221","0.06946"
"18638","111.79200","9.31617","0.07067"
"18706","112.20000","9.35019","0.07152"
"18774","112.60800","9.38421","0.07275"
"18842","113.01600","9.41823","0.07348"
"18910","113.42400","9.45219","0.07436"
"18978","113.83200","9.48621","0.07534"
"19046","114.24000","9.52017","0.07566"
"19114","114.64800","9.55425","0.07637"
"19182","115.05600","9.58827","0.07738"
"19250","115.46400","9.62217","0.07809"
"19318","115.87200","9.65619","0.07935"
"19386","116.28000","9.69027","0.07985"
"19454","116.68800","9.72423","0.08103"
"19522","117.09600","9.75819","0.08191"
"19590","117.50400","9.79221","0.08158"
"19658","117.91200","9.82623","0.08217"
"19726","118.32000","9.86019","0.08271"
"19794","118.72800","9.89415","0.08363"
"19862","119.13600","9.92823","0.08367"
"19930","119.54400","9.96225","0.08393"
"19998","119.95200","9.99621","0.08481"
"20066","120.36000","10.03017","0.08490"
"20134","120.76800","10.06425","0.08514"
"20202","121.17600","10.09821","0.08525"
"20270","121.58400","10.13223","0.08577"
"20338","121.99200","10.16619","0.08553"
"20406","122.40000","10.20015","0.08602"
"20474","122.80800","10.23423","0.08652"
"20542","123.21600","10.26825","0.08714"
"20610","123.62400","10.30227","0.08723"
"20678","124.03200","10.33618","0.08856"
"20746","124.44000","10.37020","0.09006"
"20814","124.84800","10.40421","0.09071"
"20882","125.25600","10.43824","0.09059"
"20950","125.66400","10.47220","0.09286"
"21018","126.07200","10.50622","0.09335"
"21086","126.48000","10.54024","0.09425"
"21154","126.88800","10.57420","0.09484"
"21222","127.29600","10.60816","0.09527"
"21290","127.70400","10.64224","0.09582"
"21358","128.11200","10.67626","0.09670"
"21426","128.52000","10.71022","0.09726"
"21494","128.92800","10.74418","0.09797"
"21562","129.33600","10.77820","0.09895"
"21630","129.74400","10.81222","0.09966"
"21698","130.15200","10.84624","0.09956"
"21766","130.56000","10.88026","0.10094"
"21834","130.96800","10.91422","0.10054"
"21902","131.37600","10.94824","0.10120"
"21970","131.78400","10.98220","0.10163"
"22038","132.19200","11.01616","0.10198"
"22106","132.60000","11.05018","0.10237"
"22174","133.00800","11.08426","0.10266"
"22242","133.41600","11.11822","0.10290"
"22310","133.82400","11.15218","0.10321"
"22378","134.23200","11.18614","0.10367"
"22446","134.64000","11.22022","0.10385"
"22514","135.04800","11.25430","0.10426"
"22582","135.45600","11.28820","0.10458"
"22650","135.86400","11.32222","0.10474"
"22718","136.27200","11.35625","0.10511"
"22786","136.68000","11.39021","0.10531"
"22854","137.08800","11.42423","0.10554"
"22922","137.49600","11.45813","0.10617"
"22990","137.90400","11.49227","0.10659"
"23058","138.31200","11.52629","0.10742"
"23126","138.72000","11.56025","0.10859"
"23194","139.12800","11.59421","0.10934"
"23262","139.53600","11.62817","0.11069"
"23330","139.94400","11.66219","0.11225"
"23398","140.35200","11.69621","0.11283"
"23466","140.76000","11.73017","0.11408"
"23534","141.16800","11.76425","0.11503"
"23602","141.57600","11.79821","0.11501"
"23670","141.98400","11.83223","0.11562"
"23738","142.39200","11.86613","0.11355"
"23806","142.80000","11.90027","0.11371"
"23874","143.20800","11.93423","0.11438"
"23942","143.61600","11.96825","0.11417"
"24010","144.02400","12.00221","0.09822"
"24078","144.43200","12.03623","0.07941"
"24146","144.84000","12.07025","0.07642"
"24214","145.24800","12.10421","0.07666"
"24282","145.65600","12.13823","0.07531"
"24350","146.06400","12.17219","0.07414"
"24418","146.47200","12.20627","0.07435"
"24486","146.88000","12.24023","0.07341"
"24554","147.28800","12.27419","0.07142"
"24622","147.69600","12.30821","0.07184"
"24690","148.10400","12.34223","0.07228"
"24758","148.51200","12.37625","0.07316"
"24826","148.92000","12.41021","0.07301"
"24894","149.32800","12.44417","0.07142"
"24962","149.73600","12.47820","0.07201"
"25030","150.14400","12.51222","0.07319"
"25098","150.55200","12.54624","0.07469"
"25166","150.96000","12.58020","0.07653"
"25234","151.36800","12.61427","0.07689"
"25302","151.77600","12.64824","0.07712"
"25370","152.18400","12.68220","0.07767"
"25438","152.59200","12.71616","0.07914"
"25506","153.00000","12.75018","0.07876"
"25574","153.40800","12.78426","0.07896"
"25642","153.81600","12.81828","0.08099"
"25710","154.22400","12.85218","0.08258"
"25778","154.63200","12.88620","0.08400"
"25846","155.04000","12.92022","0.08603"
"25914","155.44800","12.95424","0.08798"
"25982","155.85600","12.98820","0.09022"
"26050","156.26400","13.02222","0.09301"
"26118","156.67200","13.05624","0.09550"
"26186","157.08000","13.09026","0.09871"
"26254","157.48800","13.12416","0.09975"
"26322","157.89600","13.15818","0.10121"
"26390","158.30400","13.19220","0.10233"
"26458","158.71200","13.22628","0.10300"
"26526","159.12000","13.26024","0.10361"
"26594","159.52800","13.29420","0.10366"
"26662","159.93600","13.32822","0.10341"
"26730","160.34400","13.36224","0.10276"
"26798","160.75200","13.39620","0.10267"
"26866","161.16000","13.43017","0.10312"
"26934","161.56800","13.46424","0.10343"
"27002","161.97600","13.49826","0.10392"
"27070","162.38400","13.53222","0.10403"
"27138","162.79200","13.56618","0.10405"
"27206","163.20000","13.60021","0.10478"
"27274","163.60800","13.63423","0.10511"
"27342","164.01600","13.66819","0.10527"
"27410","164.42400","13.70221","0.10583"
"27478","164.83200","13.73623","0.10635"
"27546","165.24000","13.77025","0.10680"
"27614","165.64800","13.80421","0.10724"
"27682","166.05600","13.83817","0.10774"
"27750","166.46400","13.87225","0.10926"
"27818","166.87200","13.90633","0.10942"
"27886","167.28000","13.94029","0.11036"
"27954","167.68800","13.97413","0.11235"
"28022","168.09600","14.00821","0.11239"
"28090","168.50400","14.04229","0.11700"
"28158","168.91200","14.07625","0.11657"
"28226","169.32000","14.11021","0.05840"
"28294","169.72800","14.14417","0.05036"
"28362","170.13600","14.17831","0.04899"
"28430","170.54400","14.21221","0.05487"
"28498","170.95200","14.24617","0.05924"
"28566","171.36000","14.28019","0.05545"
"28634","171.76800","14.31427","0.05668"
"28702","172.17600","14.34829","0.05916"
"28770","172.58400","14.38219","0.05735"
"28838","172.99200","14.41621","0.06041"
"28906","173.40000","14.45023","0.06033"
"28974","173.80800","14.48425","0.06005"
"29042","174.21600","14.51821","0.06451"
"29110","174.62400","14.55223","0.06084"
"29178","175.03200","14.58625","0.06358"
"29246","175.44000","14.62021","0.06666"
"29314","175.84800","14.65423","0.06282"
"29382","176.25600","14.68820","0.06957"
"29450","176.66400","14.72222","0.06744"
"29518","177.07200","14.75624","0.07241"
"29586","177.48000","14.79026","0.07172"
"29654","177.88800","14.82416","0.06913"
"29722","178.29600","14.85818","0.07469"
"29790","178.70400","14.89226","0.06932"
"29858","179.11200","14.92628","0.07439"
"29926","179.52000","14.96018","0.07257"
"29994","179.92800","14.99426","0.07760"
"30062","180.33600","15.02822","0.07461"
"30130","180.74400","15.06224","0.07428"
"30198","181.15200","15.09620","0.07659"
"30266","181.56000","15.13022","0.07128"
"30334","181.96800","15.16424","0.07328"
"30402","182.37600","15.19826","0.07121"
"30470","182.78400","15.23228","0.07570"
"30538","183.19200","15.26618","0.07362"
"30606","183.60000","15.30020","0.07492"
"30674","184.00800","15.33422","0.07818"
"30742","184.41600","15.36824","0.07575"
"30810","184.82400","15.40214","0.06304"
"30878","185.23200","15.43628","0.06072"
"30946","185.64000","15.47030","0.06317"
"31014","186.04800","15.50420","0.06299"
"31082","186.45600","15.53822","0.06273"
"31150","186.86400","15.57224","0.06554"
"31218","187.27200","15.60626","0.06405"
"31286","187.68000","15.64022","0.06546"
"31354","188.08800","15.67418","0.06908"
"31422","188.49600","15.70820","0.06750"
"31490","188.90400","15.74223","0.06950"
"31558","189.31200","15.77625","0.06842"
"31626","189.72000","15.81021","0.07021"
"31694","190.12800","15.84423","0.07138"
"31762","190.53600","15.87825","0.07187"
"31830","190.94400","15.91221","0.07713"
"31898","191.35200","15.94611","0.07583"
"31966","191.76000","15.98019","0.07826"
"32034","192.16800","16.01427","0.08032"
"32102","192.57600","16.04829","0.08215"
"32170","192.98400","16.08219","0.08328"
"32238","193.39200","16.11621","0.08331"
"32306","193.80000","16.15029","0.08578"
"32374","194.20800","16.18425","0.08718"
"32442","194.61600","16.21815","0.08954"
"32510","195.02400","16.25223","0.09079"
"32578","195.43200","16.28625","0.09562"
"32646","195.84000","16.32021","0.09648"
"32714","196.24800","16.35417","0.09768"
"32782","196.65600","16.38819","0.09894"
"32850","197.06400","16.42227","0.10175"
"32918","197.47200","16.45623","0.10245"
"32986","197.88000","16.49019","0.10250"
"33054","198.28800","16.52421","0.10349"
"33122","198.69600","16.55823","0.10421"
"33190","199.10400","16.59219","0.10467"
"33258","199.51200","16.62621","0.10471"
"33326","199.92000","16.66023","0.10535"
"33394","200.32800","16.69419","0.10558"
"33462","200.73600","16.72828","0.10724"
"33530","201.14400","16.76223","0.10838"
"33598","201.55200","16.79613","0.10859"
"33666","201.96000","16.83022","0.10895"
"33734","202.36800","16.86418","0.11092"
"33802","202.77600","16.89826","0.11472"
"33870","203.18400","16.93216","0.11577"
"33938","203.59200","16.96624","0.11702"
"34006","204.00000","17.00020","0.11940"
"34074","204.40800","17.03422","0.12111"
"34142","204.81600","17.06818","0.12596"
"34210","205.22400","17.10226","0.12770"
"34278","205.63200","17.13622","0.12821"
"34346","206.04000","17.17024","0.12946"
"34414","206.44800","17.20420","0.13156"
"34482","206.85600","17.23822","0.13369"
"34550","207.26400","17.27218","0.13540"
"34618","207.67200","17.30620","0.13618"
"34686","208.08000","17.34016","0.13598"
"34754","208.48800","17.37424","0.13757"
"34822","208.89600","17.40820","0.13850"
"34890","209.30400","17.44222","0.13964"
"34958","209.71200","17.47618","0.13994"
"35026","210.12000","17.51020","0.14011"
"35094","210.52800","17.54422","0.14076"
"35162","210.93600","17.57824","0.14181"
"35230","211.34400","17.61226","0.14305"
"35298","211.75200","17.64616","0.14447"
"35366","212.16000","17.68018","0.14432"
"35434","212.56800","17.71426","0.14385"
"35502","212.97600","17.74822","0.14315"
"35570","213.38400","17.78218","0.14393"
"35638","213.79200","17.81627","0.14417"
"35706","214.20000","17.85022","0.14563"
"35774","214.60800","17.88424","0.14646"
"35842","215.01600","17.91815","0.14715"
"35910","215.42400","17.95223","0.14746"
"35978","215.83200","17.98625","0.14797"
"36046","216.24000","18.02027","0.14784"
"36114","216.64800","18.05417","0.14834"
"36182","217.05600","18.08819","0.14865"
"36250","217.46400","18.12221","0.14917"
"36318","217.87200","18.15623","0.14959"
"36386","218.28000","18.19019","0.14991"
"36454","218.68800","18.22421","0.15006"
"36522","219.09600","18.25823","0.15039"
"36590","219.50400","18.29225","0.15068"
"36658","219.91200","18.32621","0.15111"
"36726","220.32000","18.36023","0.15218"
"36794","220.72800","18.39425","0.15284"
"36862","221.13600","18.42827","0.15389"
"36930","221.54400","18.46223","0.15454"
"36998","221.95200","18.49619","0.15559"
"37066","222.36000","18.53027","0.15655"
"37134","222.76800","18.56423","0.15812"
"37202","223.17600","18.59819","0.15952"
"37270","223.58400","18.63215","0.16159"
"37338","223.99200","18.66629","0.16382"
"37406","224.40000","18.70025","0.16622"
"37474","224.80800","18.73421","0.16771"
"37542","225.21600","18.76823","0.17058"
"37610","225.62400","18.80219","0.17265"
"37678","226.03200","18.83621","0.17373"
"37746","226.44000","18.87017","0.17615"
"37814","226.84800","18.90413","0.17870"
"37882","227.25600","18.93827","0.18268"
"37950","227.66400","18.97223","0.18587"
"38018","228.07200","19.00626","0.18896"
"38086","228.48000","19.04022","0.19274"
"38154","228.88800","19.07424","0.19613"
"38222","229.29600","19.10826","0.19770"
"38290","229.70400","19.14222","0.19830"
"38358","230.11200","19.17618","0.19978"
"38426","230.52000","19.21020","0.20245"
"38494","230.92800","19.24428","0.20470"
"38562","231.33600","19.27824","0.20327"
"38630","231.74400","19.31220","0.15719"
"38698","232.15200","19.34628","0.15448"
"38766","232.56000","19.38024","0.15558"
"38834","232.96800","19.41420","0.15718"
"38902","233.37600","19.44822","0.15933"
"38970","233.78400","19.48224","0.16040"
"39038","234.19200","19.51620","0.16302"
"39106","234.60000","19.55028","0.16344"
"39174","235.00800","19.58424","0.16568"
"39242","235.41600","19.61820","0.16767"
"39310","235.82400","19.65222","0.17083"
"39378","236.23200","19.68624","0.17156"
"39446","236.64000","19.72026","0.17323"
"39514","237.04800","19.75416","0.17439"
"39582","237.45600","19.78824","0.17543"
"39650","237.86400","19.82226","0.17674"
"39718","238.27200","19.85616","0.17815"
"39786","238.68000","19.89018","0.17318"
"39854","239.08800","19.92420","0.16338"
"39922","239.49600","19.95822","0.16162"
"39990","239.90400","19.99224","0.16280"
"40058","240.31200","20.02620","0.16508"
"40126","240.72000","20.06022","0.16503"
"40194","241.12800","20.09431","0.15864"
"40262","241.53600","20.12827","0.15939"
"40330","241.94400","20.16217","0.16145"
"40398","242.35200","20.19624","0.16382"
"40466","242.76000","20.23026","0.16759"
"40534","243.16800","20.26423","0.16681"
"40602","243.57600","20.29819","0.15552"
"40670","243.98400","20.33221","0.15566"
"40738","244.39200","20.36617","0.15685"
"40806","244.80000","20.40025","0.15733"
"40874","245.20800","20.43421","0.15893"
"40942","245.61600","20.46817","0.16134"
"41010","246.02400","20.50219","0.16435"
"41078","246.43200","20.53627","0.16672"
"41146","246.84000","20.57017","0.16981"
"41214","247.24800","20.60413","0.17418"
"41282","247.65600","20.63827","0.17751"
"41350","248.06400","20.67229","0.18272"
"41418","248.47200","20.70625","0.18865"
"41486","248.88000","20.74021","0.19222"
"41554","249.28800","20.77429","0.19579"
"41622","249.69600","20.80825","0.19948"
"41690","250.10400","20.84227","0.20212"
"41758","250.51200","20.87623","0.20382"
"41826","250.92000","20.91019","0.20546"
"41894","251.32800","20.94421","0.20653"
"41962","251.73600","20.97817","0.20692"
"42030","252.14400","21.01219","0.20398"
"42098","252.55200","21.04622","0.20119"
"42166","252.96000","21.08023","0.19986"
"42234","253.36800","21.11426","0.16857"
"42302","253.77600","21.14810","0.17276"
"42370","254.18400","21.18224","0.17514"
"42438","254.59200","21.21626","0.17931"
"42506","255.00000","21.25028","0.18495"
"42574","255.40800","21.28424","0.19071"
"42642","255.81600","21.31820","0.19647"
"42710","256.22400","21.35228","0.20244"
"42778","256.63200","21.38624","0.20631"
"42846","257.04000","21.42026","0.20841"
"42914","257.44800","21.45416","0.20957"
"42982","257.85600","21.48824","0.21074"
"43050","258.26400","21.52226","0.21123"
"43118","258.67200","21.55622","0.21211"
"43186","259.08000","21.59018","0.20523"
"43254","259.48800","21.62420","0.20631"
"43322","259.89600","21.65822","0.18820"
"43390","260.30400","21.69218","0.19377"
"43458","260.71200","21.72620","0.19796"
"43526","261.12000","21.76028","0.19890"
"43594","261.52800","21.79424","0.19195"
"43662","261.93600","21.82826","0.16015"
"43730","262.34400","21.86222","0.15719"
"43798","262.75200","21.89624","0.15223"
"43866","263.16000","21.93026","0.15119"
"43934","263.56800","21.96422","0.15135"
"44002","263.97600","21.99818","0.14404"
"44070","264.38400","22.03221","0.14211"
"44138","264.79200","22.06623","0.14227"
"44206","265.20000","22.10025","0.14260"
"44274","265.60800","22.13420","0.14287"
"44342","266.01600","22.16822","0.14330"
"44410","266.42400","22.20219","0.14484"
"44478","266.83200","22.23620","0.14539"
"44546","267.24000","22.27017","0.14664"
"44614","267.64800","22.30419","0.14719"
"44682","268.05600","22.33827","0.14778"
"44750","268.46400","22.37229","0.14851"
"44818","268.87200","22.40619","0.14902"
"44886","269.28000","22.44021","0.14952"
"44954","269.68800","22.47423","0.14933"
"45022","270.09600","22.50831","0.14973"
"45090","270.50400","22.54221","0.15014"
"45158","270.91200","22.57617","0.15006"
"45226","271.32000","22.61025","0.15024"
"45294","271.72800","22.64427","0.14999"
"45362","272.13600","22.67817","0.14970"
"45430","272.54400","22.71219","0.15012"
"45498","272.95200","22.74621","0.15055"
"45566","273.36000","22.78023","0.15062"
"45634","273.76800","22.81419","0.15086"
"45702","274.17600","22.84821","0.15100"
"45770","274.58400","22.88223","0.15133"
"45838","274.99200","22.91619","0.15114"
"45906","275.40000","22.95021","0.15057"
"45974","275.80800","22.98423","0.15078"
"46042","276.21600","23.01825","0.15054"
"46110","276.62400","23.05227","0.14831"
"46178","277.03200","23.08624","0.14895"
"46246","277.44000","23.12020","0.14928"
"46314","277.84800","23.15421","0.14977"
"46382","278.25600","23.18823","0.15017"
"46450","278.66400","23.22232","0.15067"
"46518","279.07200","23.25622","0.15109"
"46586","279.48000","23.29018","0.15160"
"46654","279.88800","23.32420","0.15250"
"46722","280.29600","23.35828","0.15098"
"46790","280.70400","23.39211","0.15057"
"46858","281.11200","23.42626","0.14815"
"46926","281.52000","23.46022","0.14760"
"46994","281.92800","23.49424","0.14792"
"47062","282.33600","23.52820","0.14811"
"47130","282.74400","23.56222","0.14843"
"47198","283.15200","23.59630","0.14550"
"47266","283.56000","23.63026","0.14253"
"47334","283.96800","23.66422","0.07835"
"47402","284.37600","23.69824","0.07445"
"47470","284.78400","23.73226","0.07769"
"47538","285.19200","23.76628","0.08027"
"47606","285.60000","23.80018","0.08003"
"47674","286.00800","23.83420","0.08165"
"47742","286.41600","23.86822","0.08424"
"47810","286.82400","23.90224","0.08698"
"47878","287.23200","23.93620","0.08831"
"47946","287.64000","23.97016","0.08861"
"48014","288.04800","24.00418","0.08992"
"48082","288.45600","24.03826","0.09315"
"48150","288.86400","24.07222","0.09723"
"48218","289.27200","24.10618","0.09891"
"48286","289.68000","24.14020","0.10017"
"48354","290.08800","24.17422","0.10005"
"48422","290.49600","24.20819","0.10128"
"48490","290.90400","24.24214","0.10236"
"48558","291.31200","24.27622","0.10266"
"48626","291.72000","24.31030","0.10387"
"48694","292.12800","24.34426","0.10425"
"48762","292.53600","24.37817","0.10500"
"48830","292.94400","24.41219","0.10562"
"48898","293.35200","24.44621","0.10586"
"48966","293.76000","24.48022","0.10740"
"49034","294.16800","24.51419","0.10913"
"49102","294.57600","24.54821","0.11005"
"49170","294.98400","24.58223","0.11134"
"49238","295.39200","24.61619","0.11264"
"49306","295.80000","24.65021","0.11561"
"49374","296.20800","24.68417","0.11755"
"49442","296.61600","24.71825","0.11864"
"49510","297.02400","24.75227","0.12159"
"49578","297.43200","24.78623","0.12281"
"49646","297.84000","24.82019","0.12410"
"49714","298.24800","24.85421","0.12653"
"49782","298.65600","24.88823","0.12833"
"49850","299.06400","24.92219","0.12962"
"49918","299.47200","24.95621","0.13099"
"49986","299.88000","24.99029","0.13295"
"50054","300.28800","25.02425","0.13386"
"50122","300.69600","25.05821","0.13517"
"50190","301.10400","25.09217","0.13623"
"50258","301.51200","25.12619","0.13724"
"50326","301.92000","25.16027","0.13764"
"50394","302.32800","25.19423","0.13892"
"50462","302.73600","25.22820","0.13997"
"50530","303.14400","25.26215","0.14013"
"50598","303.55200","25.29623","0.14079"
"50666","303.96000","25.33025","0.14187"
"50734","304.36800","25.36422","0.14221"
"50802","304.77600","25.39824","0.14371"
"50870","305.18400","25.43226","0.14394"
"50938","305.59200","25.46622","0.14427"
"51006","306.00000","25.50018","0.14529"
"51074","306.40800","25.53420","0.14574"
"51142","306.81600","25.56828","0.14627"
"51210","307.22400","25.60224","0.14697"
"51278","307.63200","25.63620","0.14759"
"51346","308.04000","25.67016","0.14797"
"51414","308.44800","25.70424","0.14841"
"51482","308.85600","25.73820","0.14867"
"51550","309.26400","25.77222","0.14905"
"51618","309.67200","25.80618","0.14904"
"51686","310.08000","25.84020","0.14964"
"51754","310.48800","25.87428","0.14996"
"51822","310.89600","25.90818","0.14987"
"51890","311.30400","25.94214","0.15021"
"51958","311.71200","25.97622","0.15051"
"52026","312.12000","26.01024","0.15080"
"52094","312.52800","26.04420","0.15119"
"52162","312.93600","26.07816","0.15182"
"52230","313.34400","26.11224","0.15243"
"52298","313.75200","26.14626","0.15283"
"52366","314.16000","26.18028","0.15379"
"52434","314.56800","26.21418","0.15461"
"52502","314.97600","26.24826","0.15563"
"52570","315.38400","26.28228","0.15698"
"52638","315.79200","26.31618","0.15859"
"52706","316.20000","26.35014","0.15880"
"52774","316.60800","26.38416","0.16039"
"52842","317.01600","26.41825","0.16272"
"52910","317.42400","26.45226","0.16426"
"52978","317.83200","26.48623","0.16652"
"53046","318.24000","26.52025","0.16896"
"53114","318.64800","26.55420","0.17095"
"53182","319.05600","26.58823","0.17307"
"53250","319.46400","26.62219","0.17428"
"53318","319.87200","26.65621","0.17595"
"53386","320.28000","26.69029","0.17800"
"53454","320.68800","26.72425","0.17917"
"53522","321.09600","26.75821","0.18195"
"53590","321.50400","26.79223","0.18307"
"53658","321.91200","26.82625","0.18438"
"53726","322.32000","26.86021","0.18781"
"53794","322.72800","26.89423","0.18996"
"53862","323.13600","26.92819","0.19138"
"53930","323.54400","26.96227","0.19299"
"53998","323.95200","26.99623","0.19546"
"54066","324.36000","27.03019","0.19662"
"54134","324.76800","27.06415","0.19950"
"54202","325.17600","27.09823","0.20083"
"54270","325.58400","27.13225","0.20171"
"54338","325.99200","27.16627","0.20320"
"54406","326.40000","27.20017","0.20417"
"54474","326.80800","27.23419","0.20540"
"54542","327.21600","27.26827","0.20628"
"54610","327.62400","27.30223","0.20723"
"54678","328.03200","27.33619","0.20807"
"54746","328.44000","27.37027","0.20826"
"54814","328.84800","27.40423","0.20778"
"54882","329.25600","27.43820","0.20815"
"54950","329.66400","27.47215","0.20880"
"55018","330.07200","27.50617","0.20958"
"55086","330.48000","27.54020","0.20950"
"55154","330.88800","27.57427","0.21005"
"55222","331.29600","27.60818","0.14587"
"55290","331.70400","27.64220","0.01752"
"55358","332.11200","27.67622","0.00566"
"55426","332.52000","27.71024","0.00928"
"55494","332.92800","27.74420","0.00838"
"55562","333.33600","27.77816","0.00725"
"55630","333.74400","27.81224","0.01005"
"55698","334.15200","27.84626","0.00668"
"55766","334.56000","27.88022","0.01380"
"55834","334.96800","27.91424","0.00757"
"55902","335.37600","27.94826","0.01404"
"55970","335.78400","27.98228","0.00812"
"56038","336.19200","28.01624","0.01155"
"56106","336.60000","28.05020","0.00893"
"56174","337.00800","28.08422","0.01159"
"56242","337.41600","28.11824","0.01017"
"56310","337.82400","28.15220","0.01133"
"56378","338.23200","28.18616","0.01097"
"56446","338.64000","28.22018","0.01126"
"56514","339.04800","28.25426","0.01217"
"56582","339.45600","28.28828","0.01204"
"56650","339.86400","28.32212","0.01223"
"56718","340.27200","28.35620","0.01193"
"56786","340.68000","28.39029","0.01337"
"56854","341.08800","28.42424","0.01255"
"56922","341.49600","28.45820","0.01385"
"56990","341.90400","28.49217","0.01329"
"57058","342.31200","28.52624","0.01329"
"57126","342.72000","28.56026","0.01280"
"57194","343.12800","28.59416","0.01328"
"57262","343.53600","28.62819","0.01387"
"57330","343.94400","28.66226","0.01427"
"57398","344.35200","28.69629","0.01408"
"57466","344.76000","28.73019","0.01512"
"57534","345.16800","28.76421","0.01420"
"57602","345.57600","28.79823","0.01466"
"57670","345.98400","28.83231","0.01420"
"57738","346.39200","28.86621","0.01525"
"57806","346.80000","28.90023","0.01452"
"57874","347.20800","28.93425","0.01458"
"57942","347.61600","28.96821","0.01465"
"58010","348.02400","29.00223","0.01522"
"58078","348.43200","29.03619","0.01525"
"58146","348.84000","29.07027","0.01467"
"58214","349.24800","29.10423","0.01425"
"58282","349.65600","29.13819","0.01366"
"58350","350.06400","29.17221","0.01341"
"58418","350.47200","29.20623","0.01312"
"58486","350.88000","29.24025","0.01364"
"58554","351.28800","29.27421","0.01367"
"58622","351.69600","29.30823","0.01427"
"58690","352.10400","29.34225","0.01375"
"58758","352.51200","29.37621","0.01441"
"58826","352.92000","29.41023","0.01435"
"58894","353.32800","29.44419","0.01471"
"58962","353.73600","29.47821","0.01400"
"59030","354.14400","29.51223","0.01380"
"59098","354.55200","29.54626","0.01267"
"59166","354.96000","29.58021","0.01389"
"59234","355.36800","29.61418","0.01341"
"59302","355.77600","29.64820","0.01358"
"59370","356.18400","29.68222","0.01252"
"59438","356.59200","29.71623","0.01353"
"59506","357.00000","29.75020","0.01348"
"59574","357.40800","29.78422","0.01374"
"59642","357.81600","29.81824","0.01415"
"59710","358.22400","29.85214","0.01424"
"59778","358.63200","29.88622","0.01339"
"59846","359.04000","29.92024","0.01313"
"59914","359.44800","29.95426","0.01397"
"59982","359.85600","29.98822","0.01385"
"60050","360.26400","30.02224","0.01416"
"60118","360.67200","30.05620","0.01404"
"60186","361.08000","30.09016","0.01415"
"60254","361.48800","30.12424","0.01452"
"60322","361.89600","30.15820","0.01420"
"60390","362.30400","30.19222","0.01449"
"60458","362.71200","30.22624","0.01434"
"60526","363.12000","30.26020","0.01467"
"60594","363.52800","30.29410","0.01441"
"60662","363.93600","30.32818","0.01506"
"60730","364.34400","30.36226","0.01500"
"60798","364.75200","30.39628","0.01471"
"60866","365.16000","30.43018","0.01471"
"60934","365.56800","30.46420","0.01518"
"61002","365.97600","30.49822","0.01495"
"61070","366.38400","30.53224","0.01535"
"61138","366.79200","30.56614","0.01530"
"61206","367.20000","30.60022","0.01568"
"61274","367.60800","30.63424","0.01507"
"61342","368.01600","30.66821","0.01562"
"61410","368.42400","30.70217","0.01539"
"61478","368.83200","30.73619","0.01487"
"61546","369.24000","30.77026","0.01559"
"61614","369.64800","30.80422","0.01510"
"61682","370.05600","30.83819","0.01530"
"61750","370.46400","30.87221","0.01490"
"61818","370.87200","30.90623","0.01517"
"61886","371.28000","30.94025","0.01469"
"61954","371.68800","30.97421","0.01530"
"62022","372.09600","31.00823","0.01582"
"62090","372.50400","31.04225","0.01641"
"62158","372.91200","31.07627","0.01637"
"62226","373.32000","31.11023","0.01619"
"62294","373.72800","31.14419","0.01626"
"62362","374.13600","31.17821","0.01628"
"62430","374.54400","31.21223","0.01670"
"62498","374.95200","31.24625","0.01646"
"62566","375.36000","31.28015","0.01658"
"62634","375.76800","31.31423","0.01662"
"62702","376.17600","31.34819","0.01615"
"62770","376.58400","31.38221","0.01659"
"62838","376.99200","31.41617","0.01686"
"62906","377.40000","31.45025","0.01697"
"62974","377.80800","31.48427","0.01695"
"63042","378.21600","31.51823","0.01770"
"63110","378.62400","31.55213","0.01754"
"63178","379.03200","31.58621","0.01767"
"63246","379.44000","31.62017","0.01731"
"63314","379.84800","31.65419","0.01724"
"63382","380.25600","31.68821","0.01727"
"63450","380.66400","31.72223","0.01800"
"63518","381.07200","31.75625","0.01709"
"63586","381.48000","31.79021","0.01673"
"63654","381.88800","31.82423","0.01738"
"63722","382.29600","31.85819","0.01781"
"63790","382.70400","31.89221","0.01719"
"63858","383.11200","31.92629","0.01750"
"63926","383.52000","31.96020","0.01822"
"63994","383.92800","31.99416","0.01770"
"64062","384.33600","32.02824","0.01871"
"64130","384.74400","32.06219","0.01875"
"64198","385.15200","32.09622","0.01831"
"64266","385.56000","32.13018","0.01856"
"64334","385.96800","32.16426","0.01829"
"64402","386.37600","32.19822","0.01705"
"64470","386.78400","32.23218","0.01737"
"64538","387.19200","32.26614","0.01678"
"64606","387.60000","32.30022","0.01613"
"64674","388.00800","32.33424","0.01608"
"64742","388.41600","32.36826","0.01604"
"64810","388.82400","32.40216","0.01596"
"64878","389.23200","32.43612","0.01583"
"64946","389.64000","32.47026","0.01563"
"65014","390.04800","32.50422","0.01544"
"65082","390.45600","32.53818","0.01518"
"65150","390.86400","32.57226","0.01539"
"65218","391.27200","32.60622","0.01570"
"65286","391.68000","32.64024","0.01527"
"65354","392.08800","32.67414","0.01526"
"65422","392.49600","32.70816","0.01562"
"65490","392.90400","32.74224","0.01573"
"65558","393.31200","32.77626","0.01637"
"65626","393.72000","32.81022","0.01582"
"65694","394.12800","32.84418","0.01651"
"65762","394.53600","32.87820","0.01651"
"65830","394.94400","32.91222","0.01618"
"65898","395.35200","32.94619","0.01594"
"65966","395.76000","32.98020","0.01607"
"66034","396.16800","33.01429","0.01582"
"66102","396.57600","33.04824","0.01606"
"66170","396.98400","33.08221","0.01593"
"66238","397.39200","33.11617","0.01632"
"66306","397.80000","33.15018","0.01683"
"66374","398.20800","33.18427","0.01625"
"66442","398.61600","33.21823","0.01608"
"66510","399.02400","33.25219","0.01642"
"66578","399.43200","33.28621","0.01633"
"66646","399.84000","33.32017","0.01623"
"66714","400.24800","33.35425","0.01679"
"66782","400.65600","33.38815","0.01767"
"66850","401.06400","33.42229","0.01714"
"66918","401.47200","33.45625","0.01710"
"66986","401.88000","33.49021","0.01717"
"67054","402.28800","33.52417","0.01721"
"67122","402.69600","33.55825","0.01782"
"67190","403.10400","33.59227","0.01775"
"67258","403.51200","33.62623","0.01827"
"67326","403.92000","33.66019","0.01880"
"67394","404.32800","33.69421","0.01837"
"67462","404.73600","33.72823","0.01858"
"67530","405.14400","33.76219","0.01884"
"67598","405.55200","33.79615","0.01756"
"67666","405.96000","33.83023","0.01753"
"67734","406.36800","33.86425","0.01705"
"67802","406.77600","33.89821","0.01690"
"67870","407.18400","33.93224","0.01715"
"67938","407.59200","33.96619","0.01669"
"68006","408.00000","34.00021","0.01677"
"68074","408.40800","34.03423","0.01655"
"68142","408.81600","34.06826","0.01693"
"68210","409.22400","34.10221","0.01623"
"68278","409.63200","34.13623","0.01691"
"68346","410.04000","34.17025","0.01762"
"68414","410.44800","34.20422","0.01757"
"68482","410.85600","34.23818","0.01770"
"68550","411.26400","34.27226","0.01769"
"68618","411.67200","34.30622","0.01788"
"68686","412.08000","34.34018","0.01744"
"68754","412.48800","34.37420","0.01750"
"68822","412.89600","34.40816","0.01784"
"68890","413.30400","34.44224","0.01789"
"68958","413.71200","34.47626","0.01727"
"69026","414.12000","34.51022","0.01793"
"69094","414.52800","34.54424","0.01847"
"69162","414.93600","34.57820","0.01712"
"69230","415.34400","34.61222","0.01645"
"69298","415.75200","34.64618","0.01570"
"69366","416.16000","34.68020","0.01699"
"69434","416.56800","34.71422","0.01573"
"69502","416.97600","34.74824","0.01650"
"69570","417.38400","34.78220","0.01655"
"69638","417.79200","34.81616","0.01678"
"69706","418.20000","34.85024","0.01684"
"69774","418.60800","34.88426","0.01735"
"69842","419.01600","34.91822","0.01683"
"69910","419.42400","34.95218","0.01669"
"69978","419.83200","34.98621","0.01674"
"70046","420.24000","35.02023","0.01696"
"70114","420.64800","35.05413","0.01720"
"70182","421.05600","35.08820","0.01711"
"70250","421.46400","35.12222","0.01722"
"70318","421.87200","35.15625","0.01708"
"70386","422.28000","35.19020","0.01791"
"70454","422.68800","35.22422","0.01713"
"70522","423.09600","35.25819","0.01814"
"70590","423.50400","35.29221","0.01792"
"70658","423.91200","35.32623","0.01876"
"70726","424.32000","35.36025","0.01875"
"70794","424.72800","35.39427","0.01916"
"70862","425.13600","35.42823","0.01941"
"70930","425.54400","35.46225","0.01860"
"70998","425.95200","35.49609","0.01824"
"71066","426.36000","35.53023","0.01866"
"71134","426.76800","35.56425","0.01912"
"71202","427.17600","35.59827","0.01911"
"71270","427.58400","35.63217","0.01994"
"71338","427.99200","35.66619","0.01949"
"71406","428.40000","35.70021","0.01947"
"71474","428.80800","35.73423","0.01925"
"71542","429.21600","35.76819","0.01879"
"71610","429.62400","35.80221","0.01904"
"71678","430.03200","35.83623","0.01877"
"71746","430.44000","35.87025","0.01911"
"71814","430.84800","35.90416","0.01976"
"71882","431.25600","35.93823","0.01995"
"71950","431.66400","35.97225","0.02059"
"72018","432.07200","36.00633","0.02008"
"72086","432.48000","36.04023","0.01982"
"72154","432.88800","36.07420","0.01949"
"72222","433.29600","36.10827","0.01923"
"72290","433.70400","36.14217","0.01897"
"72358","434.11200","36.17619","0.01854"
"72426","434.52000","36.21022","0.01857"
"72494","434.92800","36.24424","0.01903"
"72562","435.33600","36.27826","0.01961"
"72630","435.74400","36.31221","0.01963"
"72698","436.15200","36.34618","0.01951"
"72766","436.56000","36.38020","0.01989"
"72834","436.96800","36.41422","0.02045"
"72902","437.37600","36.44824","0.02045"
"72970","437.78400","36.48220","0.02062"
"73038","438.19200","36.51628","0.02090"
"73106","438.60000","36.55018","0.02052"
"73174","439.00800","36.58426","0.02089"
"73242","439.41600","36.61822","0.02084"
"73310","439.82400","36.65224","0.02154"
"73378","440.23200","36.68626","0.02163"
"73446","440.64000","36.72022","0.02169"
"73514","441.04800","36.75412","0.02141"
"73582","441.45600","36.78820","0.02178"
"73650","441.86400","36.82228","0.02025"
"73718","442.27200","36.85630","0.01929"
"73786","442.68000","36.89020","0.01911"
"73854","443.08800","36.92416","0.01917"
"73922","443.49600","36.95824","0.01904"
"73990","443.90400","36.99226","0.01924"
"74058","444.31200","37.02617","0.01891"
"74126","444.72000","37.06018","0.01848"
"74194","445.12800","37.09420","0.01963"
"74262","445.53600","37.12828","0.01963"
"74330","445.94400","37.16224","0.02034"
"74398","446.35200","37.19614","0.01975"
"74466","446.76000","37.23022","0.01971"
"74534","447.16800","37.26425","0.01962"
"74602","447.57600","37.29821","0.01994"
"74670","447.98400","37.33223","0.01974"
"74738","448.39200","37.36618","0.01914"
"74806","448.80000","37.40020","0.01861"
"74874","449.20800","37.43423","0.01816"
"74942","449.61600","37.46813","0.01850"
"75010","450.02400","37.50221","0.01810"
"75078","450.43200","37.53622","0.01895"
"75146","450.84000","37.57025","0.01904"
"75214","451.24800","37.60415","0.01970"
"75282","451.65600","37.63817","0.02036"
"75350","452.06400","37.67225","0.01890"
"75418","452.47200","37.70627","0.01944"
"75486","452.88000","37.74017","0.01906"
"75554","453.28800","37.77425","0.01975"
"75622","453.69600","37.80827","0.01976"
"75690","454.10400","37.84223","0.01926"
"75758","454.51200","37.87619","0.01932"
"75826","454.92000","37.91021","0.01912"
"75894","455.32800","37.94429","0.01973"
"75962","455.73600","37.97825","0.02004"
"76030","456.14400","38.01215","0.01838"
"76098","456.55200","38.04623","0.01689"
"76166","456.96000","38.08019","0.01892"
"76234","457.36800","38.11427","0.01784"
"76302","457.77600","38.14817","0.01958"
"76370","458.18400","38.18219","0.01893"
"76438","458.59200","38.21621","0.01959"
"76506","459.00000","38.25023","0.01712"
"76574","459.40800","38.28419","0.01562"
"76642","459.81600","38.31822","0.01695"
"76710","460.22400","38.35224","0.01539"
"76778","460.63200","38.38626","0.01442"
"76846","461.04000","38.42022","0.01605"
"76914","461.44800","38.45417","0.01567"
"76982","461.85600","38.48820","0.01492"
"77050","462.26400","38.52222","0.01551"
"77118","462.67200","38.55624","0.01550"
"77186","463.08000","38.59019","0.01575"
"77254","463.48800","38.62422","0.01522"
"77322","463.89600","38.65824","0.01566"
"77390","464.30400","38.69220","0.01601"
"77458","464.71200","38.72610","0.01636"
"77526","465.12000","38.76018","0.01638"
"77594","465.52800","38.79420","0.01596"
"77662","465.93600","38.82822","0.01649"
"77730","466.34400","38.86218","0.01720"
"77798","466.75200","38.89620","0.01698"
"77866","467.16000","38.93028","0.01726"
"77934","467.56800","38.96424","0.01710"
"78002","467.97600","38.99820","0.01680"
"78070","468.38400","39.03216","0.01621"
"78138","468.79200","39.06618","0.01652"
"78206","469.20000","39.10026","0.01615"
"78274","469.60800","39.13422","0.01537"
"78342","470.01600","39.16818","0.01584"
"78410","470.42400","39.20226","0.01577"
"78478","470.83200","39.23623","0.01565"
"78546","471.24000","39.27018","0.01522"
"78614","471.64800","39.30420","0.01587"
"78682","472.05600","39.33822","0.01618"
"78750","472.46400","39.37218","0.01623"
"78818","472.87200","39.40620","0.01663"
"78886","473.28000","39.44017","0.01662"
"78954","473.68800","39.47424","0.01633"
"79022","474.09600","39.50826","0.01558"
"79090","474.50400","39.54223","0.01539"
"79158","474.91200","39.57618","0.01511"
"79226","475.32000","39.61021","0.01555"
"79294","475.72800","39.64423","0.01540"
"79362","476.13600","39.67825","0.01599"
"79430","476.54400","39.71221","0.01616"
"79498","476.95200","39.74622","0.01674"
"79566","477.36000","39.78019","0.01722"
"79634","477.76800","39.81421","0.01651"
"79702","478.17600","39.84817","0.01635"
"79770","478.58400","39.88219","0.01588"
"79838","478.99200","39.91621","0.01671"
"79906","479.40000","39.95023","0.01628"
"79974","479.80800","39.98419","0.01543"
"80042","480.21600","40.01815","0.01492"
"80110","480.62400","40.05229","0.01449"
"80178","481.03200","40.08625","0.01531"
"80246","481.44000","40.12020","0.01477"
"80314","481.84800","40.15417","0.01509"
"80382","482.25600","40.18825","0.01499"
"80450","482.66400","40.22227","0.01603"
"80518","483.07200","40.25623","0.01615"
"80586","483.48000","40.29019","0.01691"
"80654","483.88800","40.32421","0.01668"
"80722","484.29600","40.35823","0.01630"
"80790","484.70400","40.39219","0.01610"
"80858","485.11200","40.42615","0.01580"
"80926","485.52000","40.46023","0.01657"
"80994","485.92800","40.49420","0.01675"
"81062","486.33600","40.52827","0.01685"
"81130","486.74400","40.56218","0.01694"
"81198","487.15200","40.59626","0.01342"
"81266","487.56000","40.63027","0.01360"
"81334","487.96800","40.66423","0.01361"
"81402","488.37600","40.69813","0.01473"
"81470","488.78400","40.73222","0.01395"
"81538","489.19200","40.76624","0.01582"
"81606","489.60000","40.80026","0.01420"
"81674","490.00800","40.83421","0.01627"
"81742","490.41600","40.86824","0.01461"
"81810","490.82400","40.90220","0.01552"
"81878","491.23200","40.93622","0.01522"
"81946","491.64000","40.97018","0.01600"
"82014","492.04800","41.00420","0.01446"
"82082","492.45600","41.03822","0.01519"
"82150","492.86400","41.07224","0.01428"
"82218","493.27200","41.10620","0.01563"
"82286","493.68000","41.14016","0.01516"
"82354","494.08800","41.17424","0.01648"
"82422","494.49600","41.20826","0.01571"
"82490","494.90400","41.24222","0.01561"
"82558","495.31200","41.27618","0.01425"
"82626","495.72000","41.31026","0.01281"
"82694","496.12800","41.34428","0.01298"
"82762","496.53600","41.37818","0.01316"
"82830","496.94400","41.41220","0.01328"
"82898","497.35200","41.44622","0.01394"
"82966","497.76000","41.48024","0.01391"
"83034","498.16800","41.51421","0.01404"
"83084","498.46800","41.53926","0.01351"