File: Trajectories_together/170226_3Specimen_RawData_5.csv
"","V1","V2","V3"
"1","End date","2/26/2017",""
"2","Specimen label","4CT_23_pl",""
"3","Maximum Load","0.00139","N"
"4","Time","Extension","Load"
"5","(s)","(mm)","(N)"
"6","0.00000","0.00000","0.00061"
"11","0.03000","0.00036","0.00059"
"16","0.06000","0.00143","0.00066"
"21","0.09000","0.00317","0.00049"
"26","0.12000","0.00580","0.00044"
"31","0.15000","0.00879","0.00042"
"36","0.18000","0.01202","0.00033"
"41","0.21000","0.01531","0.00086"
"46","0.24000","0.01847","0.00100"
"51","0.27000","0.02158","0.00076"
"56","0.30000","0.02445","0.00048"
"61","0.33000","0.02726","0.00049"
"66","0.36000","0.02995","0.00055"
"71","0.39000","0.03265","0.00075"
"76","0.42000","0.03522","0.00047"
"81","0.45000","0.03773","0.00026"
"86","0.48000","0.04024","0.00025"
"91","0.51000","0.04275","0.00057"
"96","0.54000","0.04526","0.00008"
"101","0.57000","0.04771","-0.00008"
"106","0.60000","0.05016","0.00008"
"111","0.63000","0.05267","0.00014"
"116","0.66000","0.05519","0.00032"
"121","0.69000","0.05770","0.00045"
"126","0.72000","0.06015","0.00053"
"131","0.75000","0.06266","0.00023"
"136","0.78000","0.06517","0.00002"
"141","0.81000","0.06768","-0.00004"
"146","0.84000","0.07019","0.00016"
"151","0.87000","0.07264","0.00065"
"156","0.90000","0.07516","0.00050"
"161","0.93000","0.07767","0.00056"
"166","0.96000","0.08024","0.00030"
"171","0.99000","0.08269","0.00060"
"176","1.02000","0.08520","0.00047"
"181","1.05000","0.08771","0.00022"
"186","1.08000","0.09022","0.00004"
"191","1.11000","0.09279","0.00104"
"196","1.14000","0.09518","0.00115"
"201","1.17000","0.09770","0.00011"
"206","1.20000","0.10021","0.00069"
"211","1.23000","0.10272","0.00033"
"216","1.26000","0.10517","0.00021"
"221","1.29000","0.10762","0.00052"
"226","1.32000","0.11007","0.00047"
"231","1.35000","0.11264","0.00032"
"236","1.38000","0.11515","0.00060"
"241","1.41000","0.11761","0.00063"
"246","1.44000","0.12012","0.00030"
"251","1.47000","0.12257","0.00062"
"256","1.50000","0.12514","0.00035"
"261","1.53000","0.12765","0.00036"
"266","1.56000","0.13016","0.00072"
"271","1.59000","0.13261","0.00009"
"276","1.62000","0.13512","0.00038"
"281","1.65000","0.13764","0.00063"
"286","1.68000","0.14021","0.00047"
"291","1.71000","0.14266","0.00068"
"296","1.74000","0.14517","0.00027"
"301","1.77000","0.14768","0.00060"
"306","1.80000","0.15019","0.00068"
"311","1.83000","0.15270","0.00053"
"316","1.86000","0.15515","0.00034"
"321","1.89000","0.15761","0.00084"
"326","1.92000","0.16012","0.00074"
"331","1.95000","0.16263","-0.00002"
"336","1.98000","0.16514","-0.00009"
"341","2.01000","0.16765","0.00041"
"346","2.04000","0.17016","0.00047"
"351","2.07000","0.17267","0.00093"
"356","2.10000","0.17518","0.00100"
"361","2.13000","0.17769","0.00001"
"366","2.16000","0.18021","0.00018"
"371","2.19000","0.18266","0.00049"
"376","2.22000","0.18517","0.00022"
"381","2.25000","0.18768","0.00043"
"386","2.28000","0.19013","0.00026"
"391","2.31000","0.19264","0.00078"
"396","2.34000","0.19515","0.00025"
"401","2.37000","0.19766","0.00003"
"406","2.40000","0.20018","0.00042"
"411","2.43000","0.20263","0.00096"
"416","2.46000","0.20508","0.00101"
"421","2.49000","0.20759","0.00016"
"426","2.52000","0.21010","0.00034"
"431","2.55000","0.21261","0.00025"
"436","2.58000","0.21506","0.00080"
"441","2.61000","0.21763","0.00078"
"446","2.64000","0.22015","0.00051"
"451","2.67000","0.22272","0.00056"
"456","2.70000","0.22517","0.00046"
"461","2.73000","0.22768","0.00038"
"466","2.76000","0.23013","0.00016"
"471","2.79000","0.23264","0.00018"
"476","2.82000","0.23515","0.00002"
"481","2.85000","0.23766","0.00046"
"486","2.88000","0.24017","0.00013"
"491","2.91000","0.24263","0.00044"
"496","2.94000","0.24514","0.00037"
"501","2.97000","0.24759","0.00055"
"506","3.00000","0.25010","0.00054"
"511","3.03000","0.25261","0.00041"
"516","3.06000","0.25512","0.00034"
"521","3.09000","0.25763","0.00064"
"526","3.12000","0.26008","0.00007"
"531","3.15000","0.26266","0.00028"
"536","3.18000","0.26517","0.00032"
"541","3.21000","0.26768","0.00059"
"546","3.24000","0.27019","0.00068"
"551","3.27000","0.27270","0.00037"
"556","3.30000","0.27515","0.00029"
"561","3.33000","0.27772","0.00040"
"566","3.36000","0.28017","0.00036"
"571","3.39000","0.28268","0.00029"
"576","3.42000","0.28514","0.00044"
"581","3.45000","0.28765","0.00052"
"586","3.48000","0.29016","0.00061"
"591","3.51000","0.29261","0.00022"
"596","3.54000","0.29512","0.00028"
"601","3.57000","0.29757","0.00041"
"606","3.60000","0.30008","0.00042"
"611","3.63000","0.30259","0.00048"
"616","3.66000","0.30511","0.00028"
"621","3.69000","0.30768","0.00046"
"626","3.72000","0.31019","0.00040"
"631","3.75000","0.31270","0.00020"
"636","3.78000","0.31521","0.00058"
"641","3.81000","0.31766","0.00117"
"646","3.84000","0.32017","0.00045"
"651","3.87000","0.32262","0.00035"
"656","3.90000","0.32514","0.00090"
"661","3.93000","0.32765","0.00081"
"666","3.96000","0.33022","0.00072"
"671","3.99000","0.33267","0.00066"
"676","4.02000","0.33512","0.00038"
"681","4.05000","0.33763","0.00046"
"686","4.08000","0.34014","0.00064"
"691","4.11000","0.34265","0.00005"
"696","4.14000","0.34511","0.00044"
"701","4.17000","0.34756","0.00058"
"706","4.20000","0.35007","0.00039"
"711","4.23000","0.35264","0.00024"
"716","4.26000","0.35521","0.00035"
"721","4.29000","0.35772","0.00032"
"726","4.32000","0.36017","0.00022"
"731","4.35000","0.36262","-0.00013"
"736","4.38000","0.36519","0.00029"
"741","4.41000","0.36771","0.00036"
"746","4.44000","0.37022","0.00027"
"751","4.47000","0.37267","0.00068"
"756","4.50000","0.37512","0.00030"
"761","4.53000","0.37763","0.00009"
"766","4.56000","0.38014","0.00039"
"771","4.59000","0.38259","0.00040"
"776","4.62000","0.38510","-0.00016"
"781","4.65000","0.38762","-0.00053"
"786","4.68000","0.39013","0.00032"
"791","4.71000","0.39264","0.00027"
"796","4.74000","0.39509","0.00006"
"801","4.77000","0.39760","0.00020"
"806","4.80000","0.40011","0.00047"
"811","4.83000","0.40268","0.00035"
"816","4.86000","0.40519","-0.00007"
"821","4.89000","0.40765","0.00040"
"826","4.92000","0.41010","0.00079"
"831","4.95000","0.41261","0.00035"
"836","4.98000","0.41512","0.00024"
"841","5.01000","0.41763","0.00064"
"846","5.04000","0.42014","0.00025"
"851","5.07000","0.42259","0.00070"
"856","5.10000","0.42510","0.00121"
"861","5.13000","0.42761","0.00062"
"866","5.16000","0.43007","0.00038"
"871","5.19000","0.43258","0.00016"
"876","5.22000","0.43509","0.00062"
"881","5.25000","0.43760","0.00045"
"886","5.28000","0.44017","0.00033"
"891","5.31000","0.44262","0.00020"
"896","5.34000","0.44513","0.00011"
"901","5.37000","0.44764","0.00004"
"906","5.40000","0.45022","0.00071"
"911","5.43000","0.45267","0.00088"
"916","5.46000","0.45512","0.00070"
"921","5.49000","0.45763","0.00041"
"926","5.52000","0.46014","0.00030"
"931","5.55000","0.46271","0.00029"
"936","5.58000","0.46516","0.00012"
"941","5.61000","0.46761","-0.00012"
"946","5.64000","0.47013","0.00055"
"951","5.67000","0.47264","0.00064"
"956","5.70000","0.47515","0.00037"
"961","5.73000","0.47760","0.00058"
"966","5.76000","0.48005","0.00056"
"971","5.79000","0.48256","0.00049"
"976","5.82000","0.48513","0.00048"
"981","5.85000","0.48770","0.00003"
"986","5.88000","0.49015","-0.00014"
"991","5.91000","0.49267","0.00055"
"996","5.94000","0.49518","0.00083"
"1001","5.97000","0.49769","0.00039"
"1006","6.00000","0.50020","0.00083"
"1011","6.03000","0.50265","0.00024"
"1016","6.06000","0.50516","0.00013"
"1021","6.09000","0.50761","0.00034"
"1026","6.12000","0.51018","0.00022"
"1031","6.15000","0.51270","0.00026"
"1036","6.18000","0.51515","0.00025"
"1041","6.21000","0.51760","0.00029"
"1046","6.24000","0.52011","0.00024"
"1051","6.27000","0.52262","0.00072"
"1056","6.30000","0.52513","0.00033"
"1061","6.33000","0.52758","0.00070"
"1066","6.36000","0.53009","0.00080"
"1071","6.39000","0.53266","0.00087"
"1076","6.42000","0.53518","0.00056"
"1081","6.45000","0.53769","0.00002"
"1086","6.48000","0.54014","-0.00036"
"1091","6.51000","0.54265","-0.00016"
"1096","6.54000","0.54516","0.00026"
"1101","6.57000","0.54767","0.00089"
"1106","6.60000","0.55018","0.00063"
"1111","6.63000","0.55263","0.00062"
"1116","6.66000","0.55515","0.00113"
"1121","6.69000","0.55766","0.00101"
"1126","6.72000","0.56017","0.00061"
"1131","6.75000","0.56268","0.00062"
"1136","6.78000","0.56513","0.00065"
"1141","6.81000","0.56758","0.00072"
"1146","6.84000","0.57009","-0.00008"
"1151","6.87000","0.57260","0.00002"
"1156","6.90000","0.57512","0.00051"
"1161","6.93000","0.57763","0.00042"
"1166","6.96000","0.58014","0.00062"
"1171","6.99000","0.58265","0.00036"
"1176","7.02000","0.58516","0.00035"
"1181","7.05000","0.58761","0.00022"
"1186","7.08000","0.59012","0.00029"
"1191","7.11000","0.59263","0.00074"
"1196","7.14000","0.59515","0.00078"
"1201","7.17000","0.59766","0.00030"
"1206","7.20000","0.60023","0.00046"
"1211","7.23000","0.60262","0.00054"
"1216","7.26000","0.60513","0.00096"
"1221","7.29000","0.60758","0.00034"
"1226","7.32000","0.61009","0.00051"
"1231","7.35000","0.61254","0.00075"
"1236","7.38000","0.61505","0.00090"
"1241","7.41000","0.61763","0.00032"
"1246","7.44000","0.62014","0.00030"
"1251","7.47000","0.62265","0.00030"
"1256","7.50000","0.62516","0.00072"
"1261","7.53000","0.62767","0.00081"
"1266","7.56000","0.63024","0.00046"
"1271","7.59000","0.63269","0.00017"
"1276","7.62000","0.63514","0.00057"
"1281","7.65000","0.63766","0.00016"
"1286","7.68000","0.64017","0.00011"
"1291","7.71000","0.64268","0.00053"
"1296","7.74000","0.64513","0.00052"
"1301","7.77000","0.64764","0.00062"
"1306","7.80000","0.65015","0.00035"
"1311","7.83000","0.65266","0.00045"
"1316","7.86000","0.65517","0.00000"
"1321","7.89000","0.65763","0.00080"
"1326","7.92000","0.66008","0.00059"
"1331","7.95000","0.66259","0.00001"
"1336","7.98000","0.66516","0.00007"
"1341","8.01000","0.66767","0.00031"
"1346","8.04000","0.67018","0.00017"
"1351","8.07000","0.67269","0.00029"
"1356","8.10000","0.67514","0.00057"
"1361","8.13000","0.67771","0.00046"
"1366","8.16000","0.68017","0.00008"
"1371","8.19000","0.68262","0.00024"
"1376","8.22000","0.68513","0.00078"
"1381","8.25000","0.68764","0.00075"
"1386","8.28000","0.69015","0.00044"
"1391","8.31000","0.69266","0.00003"
"1396","8.34000","0.69517","0.00031"
"1401","8.37000","0.69762","0.00088"
"1406","8.40000","0.70014","0.00093"
"1411","8.43000","0.70265","0.00022"
"1416","8.46000","0.70510","0.00043"
"1421","8.49000","0.70761","0.00033"
"1426","8.52000","0.71012","0.00056"
"1431","8.55000","0.71263","0.00026"
"1436","8.58000","0.71514","0.00038"
"1441","8.61000","0.71765","0.00059"
"1446","8.64000","0.72016","0.00085"
"1451","8.67000","0.72262","0.00027"
"1456","8.70000","0.72513","0.00059"
"1461","8.73000","0.72764","0.00031"
"1466","8.76000","0.73015","0.00057"
"1471","8.79000","0.73266","0.00057"
"1476","8.82000","0.73517","0.00110"
"1481","8.85000","0.73768","0.00047"
"1486","8.88000","0.74013","0.00019"
"1491","8.91000","0.74265","0.00039"
"1496","8.94000","0.74510","0.00059"
"1501","8.97000","0.74761","-0.00006"
"1506","9.00000","0.75012","-0.00044"
"1511","9.03000","0.75263","-0.00020"
"1516","9.06000","0.75508","0.00030"
"1521","9.09000","0.75765","0.00055"
"1526","9.12000","0.76016","0.00066"
"1531","9.15000","0.76274","0.00023"
"1536","9.18000","0.76519","0.00013"
"1541","9.21000","0.76764","0.00038"
"1546","9.24000","0.77015","0.00013"
"1551","9.27000","0.77266","0.00029"
"1556","9.30000","0.77517","0.00020"
"1561","9.33000","0.77762","0.00066"
"1566","9.36000","0.78013","0.00058"
"1571","9.39000","0.78264","0.00032"
"1576","9.42000","0.78516","0.00005"
"1581","9.45000","0.78767","0.00014"
"1586","9.48000","0.79012","0.00046"
"1591","9.51000","0.79257","0.00051"
"1596","9.54000","0.79508","0.00027"
"1601","9.57000","0.79765","-0.00011"
"1606","9.60000","0.80016","0.00012"
"1611","9.63000","0.80261","0.00011"
"1616","9.66000","0.80513","0.00070"
"1621","9.69000","0.80770","0.00035"
"1626","9.72000","0.81021","0.00001"
"1631","9.75000","0.81266","0.00032"
"1636","9.78000","0.81517","0.00055"
"1641","9.81000","0.81762","0.00041"
"1646","9.84000","0.82019","0.00087"
"1651","9.87000","0.82264","0.00029"
"1656","9.90000","0.82510","-0.00001"
"1661","9.93000","0.82761","0.00043"
"1666","9.96000","0.83012","-0.00004"
"1671","9.99000","0.83263","0.00054"
"1676","10.02000","0.83514","0.00107"
"1681","10.05000","0.83765","0.00045"
"1686","10.08000","0.84010","0.00071"
"1691","10.11000","0.84261","0.00081"
"1696","10.14000","0.84518","0.00057"
"1701","10.17000","0.84764","0.00047"
"1706","10.20000","0.85015","0.00097"
"1711","10.23000","0.85266","0.00040"
"1716","10.26000","0.85517","0.00045"
"1721","10.29000","0.85774","0.00044"
"1726","10.32000","0.86019","0.00028"
"1731","10.35000","0.86264","0.00072"
"1736","10.38000","0.86515","0.00075"
"1741","10.41000","0.86767","0.00059"
"1746","10.44000","0.87018","0.00009"
"1751","10.47000","0.87263","-0.00004"
"1756","10.50000","0.87508","-0.00030"
"1761","10.53000","0.87759","0.00030"
"1766","10.56000","0.88010","0.00087"
"1771","10.59000","0.88261","0.00086"
"1776","10.62000","0.88512","0.00073"
"1781","10.65000","0.88764","0.00017"
"1786","10.68000","0.89015","0.00058"
"1791","10.71000","0.89266","0.00025"
"1796","10.74000","0.89517","0.00033"
"1801","10.77000","0.89768","0.00068"
"1806","10.80000","0.90019","0.00075"
"1811","10.83000","0.90264","0.00069"
"1816","10.86000","0.90515","0.00027"
"1821","10.89000","0.90766","0.00071"
"1826","10.92000","0.91018","0.00056"
"1831","10.95000","0.91269","0.00040"
"1836","10.98000","0.91520","0.00057"
"1841","11.01000","0.91765","0.00063"
"1846","11.04000","0.92016","0.00043"
"1851","11.07000","0.92267","0.00052"
"1856","11.10000","0.92512","0.00059"
"1861","11.13000","0.92757","0.00047"
"1866","11.16000","0.93015","0.00056"
"1871","11.19000","0.93266","0.00078"
"1876","11.22000","0.93517","0.00056"
"1881","11.25000","0.93768","0.00021"
"1886","11.28000","0.94019","0.00093"
"1891","11.31000","0.94270","0.00030"
"1896","11.34000","0.94521","-0.00010"
"1901","11.37000","0.94766","-0.00010"
"1906","11.40000","0.95018","0.00024"
"1911","11.43000","0.95269","0.00046"
"1916","11.46000","0.95514","0.00039"
"1921","11.49000","0.95765","0.00071"
"1926","11.52000","0.96016","0.00021"
"1931","11.55000","0.96261","0.00046"
"1936","11.58000","0.96512","0.00038"
"1941","11.61000","0.96763","0.00031"
"1946","11.64000","0.97009","0.00074"
"1951","11.67000","0.97260","0.00042"
"1956","11.70000","0.97511","0.00053"
"1961","11.73000","0.97768","0.00034"
"1966","11.76000","0.98013","0.00037"
"1971","11.79000","0.98264","0.00040"
"1976","11.82000","0.98515","0.00025"
"1981","11.85000","0.98772","0.00015"
"1986","11.88000","0.99017","0.00044"
"1991","11.91000","0.99263","0.00014"
"1996","11.94000","0.99514","0.00021"
"2001","11.97000","0.99765","0.00052"
"2006","12.00000","1.00022","0.00063"
"2011","12.03000","1.00267","0.00064"
"2016","12.06000","1.00518","0.00025"
"2021","12.09000","1.00763","0.00067"
"2026","12.12000","1.01014","0.00049"
"2031","12.15000","1.01266","0.00030"
"2036","12.18000","1.01511","0.00036"
"2041","12.21000","1.01762","0.00020"
"2046","12.24000","1.02007","0.00058"
"2051","12.27000","1.02264","0.00079"
"2056","12.30000","1.02515","0.00047"
"2061","12.33000","1.02766","0.00026"
"2066","12.36000","1.03017","0.00024"
"2071","12.39000","1.03268","0.00046"
"2076","12.42000","1.03520","-0.00008"
"2081","12.45000","1.03771","0.00014"
"2086","12.48000","1.04022","0.00014"
"2091","12.51000","1.04273","0.00001"
"2096","12.54000","1.04518","0.00029"
"2101","12.57000","1.04769","0.00017"
"2106","12.60000","1.05014","0.00086"
"2111","12.63000","1.05265","0.00034"
"2116","12.66000","1.05511","0.00023"
"2121","12.69000","1.05762","0.00044"
"2126","12.72000","1.06007","0.00071"
"2131","12.75000","1.06258","0.00073"
"2136","12.78000","1.06509","0.00048"
"2141","12.81000","1.06760","0.00049"
"2146","12.84000","1.07011","0.00038"
"2151","12.87000","1.07262","-0.00002"
"2156","12.90000","1.07520","0.00053"
"2161","12.93000","1.07765","0.00025"
"2166","12.96000","1.08010","0.00024"
"2171","12.99000","1.08261","0.00037"
"2176","13.02000","1.08512","0.00038"
"2181","13.05000","1.08763","0.00059"
"2186","13.08000","1.09008","0.00073"
"2191","13.11000","1.09259","0.00058"
"2196","13.14000","1.09511","0.00045"
"2201","13.17000","1.09762","0.00012"
"2206","13.20000","1.10013","0.00069"
"2211","13.23000","1.10258","0.00074"
"2216","13.26000","1.10509","0.00072"
"2221","13.29000","1.10760","0.00056"
"2226","13.32000","1.11011","0.00054"
"2231","13.35000","1.11262","0.00050"
"2236","13.38000","1.11507","0.00023"
"2241","13.41000","1.11759","0.00024"
"2246","13.44000","1.12016","0.00011"
"2251","13.47000","1.12267","0.00037"
"2256","13.50000","1.12518","0.00026"
"2261","13.53000","1.12763","0.00011"
"2266","13.56000","1.13020","0.00019"
"2271","13.59000","1.13271","0.00012"
"2276","13.62000","1.13516","0.00043"
"2281","13.65000","1.13762","0.00062"
"2286","13.68000","1.14013","0.00060"
"2291","13.71000","1.14264","0.00065"
"2296","13.74000","1.14515","0.00074"
"2301","13.77000","1.14760","0.00033"
"2306","13.80000","1.15011","0.00070"
"2311","13.83000","1.15256","0.00020"
"2316","13.86000","1.15513","0.00059"
"2321","13.89000","1.15764","0.00020"
"2326","13.92000","1.16010","0.00064"
"2331","13.95000","1.16261","0.00030"
"2336","13.98000","1.16518","0.00027"
"2341","14.01000","1.16769","0.00060"
"2346","14.04000","1.17020","0.00071"
"2351","14.07000","1.17265","0.00047"
"2356","14.10000","1.17516","0.00022"
"2361","14.13000","1.17767","0.00034"
"2366","14.16000","1.18019","0.00059"
"2371","14.19000","1.18270","0.00037"
"2376","14.22000","1.18515","0.00037"
"2381","14.25000","1.18760","0.00026"
"2386","14.28000","1.19011","0.00021"
"2391","14.31000","1.19262","0.00078"
"2396","14.34000","1.19507","0.00006"
"2401","14.37000","1.19758","0.00024"
"2406","14.40000","1.20010","0.00055"
"2411","14.43000","1.20267","0.00068"
"2416","14.46000","1.20512","0.00047"
"2421","14.49000","1.20763","0.00022"
"2426","14.52000","1.21014","0.00061"
"2431","14.55000","1.21265","0.00093"
"2436","14.58000","1.21516","0.00039"
"2441","14.61000","1.21767","0.00035"
"2446","14.64000","1.22018","0.00041"
"2451","14.67000","1.22270","0.00117"
"2456","14.70000","1.22515","0.00035"
"2461","14.73000","1.22766","0.00058"
"2466","14.76000","1.23017","0.00004"
"2471","14.79000","1.23262","0.00045"
"2476","14.82000","1.23513","0.00048"
"2481","14.85000","1.23764","0.00026"
"2486","14.88000","1.24009","0.00046"
"2491","14.91000","1.24261","0.00046"
"2496","14.94000","1.24512","0.00024"
"2501","14.97000","1.24763","0.00065"
"2506","15.00000","1.25014","0.00069"
"2511","15.03000","1.25265","0.00036"
"2516","15.06000","1.25516","0.00028"
"2521","15.09000","1.25767","0.00001"
"2526","15.12000","1.26012","0.00075"
"2531","15.15000","1.26264","0.00058"
"2536","15.18000","1.26515","0.00008"
"2541","15.21000","1.26766","-0.00002"
"2546","15.24000","1.27017","0.00056"
"2551","15.27000","1.27262","0.00014"
"2556","15.30000","1.27513","0.00019"
"2561","15.33000","1.27764","0.00079"
"2566","15.36000","1.28009","0.00027"
"2571","15.39000","1.28261","0.00035"
"2576","15.42000","1.28512","0.00016"
"2581","15.45000","1.28763","0.00023"
"2586","15.48000","1.29014","0.00044"
"2591","15.51000","1.29259","0.00081"
"2596","15.54000","1.29510","0.00078"
"2601","15.57000","1.29767","0.00059"
"2606","15.60000","1.30018","0.00016"
"2611","15.63000","1.30263","-0.00008"
"2616","15.66000","1.30515","0.00027"
"2621","15.69000","1.30766","0.00045"
"2626","15.72000","1.31017","0.00081"
"2631","15.75000","1.31268","0.00066"
"2636","15.78000","1.31513","0.00069"
"2641","15.81000","1.31764","0.00055"
"2646","15.84000","1.32015","-0.00032"
"2651","15.87000","1.32266","0.00018"
"2656","15.90000","1.32512","0.00039"
"2661","15.93000","1.32757","0.00026"
"2666","15.96000","1.33008","0.00013"
"2671","15.99000","1.33253","0.00041"
"2676","16.02000","1.33510","0.00093"
"2681","16.05000","1.33761","0.00076"
"2686","16.08000","1.34018","-0.00031"
"2691","16.11000","1.34269","0.00020"
"2696","16.14000","1.34520","-0.00003"
"2701","16.17000","1.34772","-0.00010"
"2706","16.20000","1.35017","0.00017"
"2711","16.23000","1.35268","0.00006"
"2716","16.26000","1.35519","0.00026"
"2721","16.29000","1.35770","0.00114"
"2726","16.32000","1.36015","-0.00026"
"2731","16.35000","1.36266","-0.00016"
"2736","16.38000","1.36517","0.00036"
"2741","16.41000","1.36769","0.00036"
"2746","16.44000","1.37014","0.00063"
"2751","16.47000","1.37265","0.00022"
"2756","16.50000","1.37510","0.00022"
"2761","16.53000","1.37761","0.00047"
"2766","16.56000","1.38012","0.00017"
"2771","16.59000","1.38263","0.00001"
"2776","16.62000","1.38514","-0.00004"
"2781","16.65000","1.38766","0.00013"
"2786","16.68000","1.39017","0.00030"
"2791","16.71000","1.39268","0.00029"
"2796","16.74000","1.39519","0.00010"
"2801","16.77000","1.39770","-0.00012"
"2806","16.80000","1.40015","0.00033"
"2811","16.83000","1.40266","0.00017"
"2816","16.86000","1.40511","0.00036"
"2821","16.89000","1.40768","0.00020"
"2826","16.92000","1.41014","0.00032"
"2831","16.95000","1.41265","-0.00011"
"2836","16.98000","1.41510","-0.00002"
"2841","17.01000","1.41767","-0.00011"
"2846","17.04000","1.42012","0.00018"
"2851","17.07000","1.42257","0.00061"
"2856","17.10000","1.42508","0.00043"
"2861","17.13000","1.42759","0.00032"
"2866","17.16000","1.43017","0.00068"
"2871","17.19000","1.43268","0.00101"
"2876","17.22000","1.43519","0.00084"
"2881","17.25000","1.43764","0.00059"
"2886","17.28000","1.44015","-0.00018"
"2891","17.31000","1.44266","0.00007"
"2896","17.34000","1.44517","0.00012"
"2901","17.37000","1.44768","0.00034"
"2906","17.40000","1.45014","0.00071"
"2911","17.43000","1.45265","0.00013"
"2916","17.46000","1.45522","0.00004"
"2921","17.49000","1.45767","0.00026"
"2926","17.52000","1.46012","0.00086"
"2931","17.55000","1.46263","0.00031"
"2936","17.58000","1.46508","0.00033"
"2941","17.61000","1.46765","0.00027"
"2946","17.64000","1.47016","0.00062"
"2951","17.67000","1.47262","0.00043"
"2956","17.70000","1.47513","0.00016"
"2961","17.73000","1.47770","0.00022"
"2966","17.76000","1.48021","0.00025"
"2971","17.79000","1.48266","0.00043"
"2976","17.82000","1.48511","0.00069"
"2981","17.85000","1.48762","0.00086"
"2986","17.88000","1.49013","0.00059"
"2991","17.91000","1.49265","0.00045"
"2996","17.94000","1.49510","0.00051"
"3001","17.97000","1.49761","0.00005"
"3006","18.00000","1.50012","0.00046"
"3011","18.03000","1.50269","0.00056"
"3016","18.06000","1.50514","0.00009"
"3021","18.09000","1.50759","0.00019"
"3026","18.12000","1.51010","0.00045"
"3031","18.15000","1.51262","0.00021"
"3036","18.18000","1.51513","0.00021"
"3041","18.21000","1.51764","0.00052"
"3046","18.24000","1.52015","0.00062"
"3051","18.27000","1.52266","0.00062"
"3056","18.30000","1.52517","0.00089"
"3061","18.33000","1.52768","0.00090"
"3066","18.36000","1.53013","0.00096"
"3071","18.39000","1.53264","0.00049"
"3076","18.42000","1.53516","-0.00002"
"3081","18.45000","1.53767","0.00039"
"3086","18.48000","1.54018","0.00069"
"3091","18.51000","1.54263","0.00052"
"3096","18.54000","1.54514","0.00052"
"3101","18.57000","1.54765","0.00013"
"3106","18.60000","1.55010","0.00014"
"3111","18.63000","1.55261","-0.00013"
"3116","18.66000","1.55513","0.00022"
"3121","18.69000","1.55764","0.00061"
"3126","18.72000","1.56015","0.00026"
"3131","18.75000","1.56266","0.00008"
"3136","18.78000","1.56517","0.00033"
"3141","18.81000","1.56768","-0.00001"
"3146","18.84000","1.57013","0.00026"
"3151","18.87000","1.57264","0.00022"
"3156","18.90000","1.57516","0.00057"
"3161","18.93000","1.57767","0.00043"
"3166","18.96000","1.58018","-0.00030"
"3171","18.99000","1.58269","0.00039"
"3176","19.02000","1.58520","0.00036"
"3181","19.05000","1.58771","0.00043"
"3186","19.08000","1.59016","0.00020"
"3191","19.11000","1.59261","0.00022"
"3196","19.14000","1.59513","0.00032"
"3201","19.17000","1.59764","0.00052"
"3206","19.20000","1.60015","0.00044"
"3211","19.23000","1.60260","0.00052"
"3216","19.26000","1.60511","0.00039"
"3221","19.29000","1.60762","0.00060"
"3226","19.32000","1.61019","0.00099"
"3231","19.35000","1.61264","0.00025"
"3236","19.38000","1.61515","0.00039"
"3241","19.41000","1.61761","0.00044"
"3246","19.44000","1.62012","0.00029"
"3251","19.47000","1.62269","0.00063"
"3256","19.50000","1.62514","0.00099"
"3261","19.53000","1.62765","0.00023"
"3266","19.56000","1.63010","-0.00004"
"3271","19.59000","1.63267","0.00061"
"3276","19.62000","1.63518","0.00068"
"3281","19.65000","1.63764","0.00074"
"3286","19.68000","1.64009","0.00040"
"3291","19.71000","1.64260","0.00070"
"3296","19.74000","1.64505","0.00058"
"3301","19.77000","1.64762","0.00055"
"3306","19.80000","1.65013","0.00020"
"3311","19.83000","1.65264","0.00052"
"3316","19.86000","1.65515","0.00063"
"3321","19.89000","1.65766","0.00050"
"3326","19.92000","1.66018","0.00026"
"3331","19.95000","1.66269","-0.00004"
"3336","19.98000","1.66514","0.00041"
"3341","20.01000","1.66765","0.00030"
"3346","20.04000","1.67016","0.00024"
"3351","20.07000","1.67267","0.00052"
"3356","20.10000","1.67518","0.00074"
"3361","20.13000","1.67763","0.00049"
"3366","20.16000","1.68015","0.00029"
"3371","20.19000","1.68266","0.00040"
"3376","20.22000","1.68517","0.00072"
"3381","20.25000","1.68768","0.00037"
"3386","20.28000","1.69007","0.00070"
"3391","20.31000","1.69264","0.00024"
"3396","20.34000","1.69515","0.00005"
"3401","20.37000","1.69766","0.00021"
"3406","20.40000","1.70018","0.00039"
"3411","20.43000","1.70263","0.00021"
"3416","20.46000","1.70520","0.00028"
"3421","20.49000","1.70771","0.00043"
"3426","20.52000","1.71016","0.00096"
"3431","20.55000","1.71267","0.00045"
"3436","20.58000","1.71518","0.00064"
"3441","20.61000","1.71769","0.00114"
"3446","20.64000","1.72020","0.00049"
"3451","20.67000","1.72266","0.00024"
"3456","20.70000","1.72511","0.00006"
"3461","20.73000","1.72762","-0.00015"
"3466","20.76000","1.73013","0.00039"
"3471","20.79000","1.73264","0.00089"
"3476","20.82000","1.73509","0.00075"
"3481","20.85000","1.73754","0.00027"
"3486","20.88000","1.74011","0.00047"
"3491","20.91000","1.74269","0.00069"
"3496","20.94000","1.74514","0.00047"
"3501","20.97000","1.74765","0.00045"
"3506","21.00000","1.75016","0.00085"
"3511","21.03000","1.75267","0.00040"
"3516","21.06000","1.75518","0.00026"
"3521","21.09000","1.75769","0.00045"
"3526","21.12000","1.76014","0.00056"
"3531","21.15000","1.76266","0.00067"
"3536","21.18000","1.76523","0.00001"
"3541","21.21000","1.76768","0.00029"
"3546","21.24000","1.77013","0.00007"
"3551","21.27000","1.77258","-0.00017"
"3556","21.30000","1.77509","0.00023"
"3561","21.33000","1.77760","0.00034"
"3566","21.36000","1.78011","0.00017"
"3571","21.39000","1.78257","0.00011"
"3576","21.42000","1.78508","0.00020"
"3581","21.45000","1.78765","0.00018"
"3586","21.48000","1.79022","0.00010"
"3591","21.51000","1.79267","0.00040"
"3596","21.54000","1.79518","0.00081"
"3601","21.57000","1.79763","0.00045"
"3606","21.60000","1.80020","-0.00006"
"3611","21.63000","1.80271","0.00013"
"3616","21.66000","1.80517","0.00008"
"3621","21.69000","1.80768","0.00038"
"3626","21.72000","1.81013","0.00041"
"3631","21.75000","1.81270","-0.00005"
"3636","21.78000","1.81521","0.00036"
"3641","21.81000","1.81760","0.00034"
"3646","21.84000","1.82011","0.00055"
"3651","21.87000","1.82262","-0.00011"
"3656","21.90000","1.82514","-0.00007"
"3661","21.93000","1.82765","0.00039"
"3666","21.96000","1.83016","0.00045"
"3671","21.99000","1.83261","0.00074"
"3676","22.02000","1.83518","0.00077"
"3681","22.05000","1.83769","0.00049"
"3686","22.08000","1.84020","0.00009"
"3691","22.11000","1.84265","0.00026"
"3696","22.14000","1.84516","0.00031"
"3701","22.17000","1.84768","0.00048"
"3706","22.20000","1.85019","0.00066"
"3711","22.23000","1.85270","0.00015"
"3716","22.26000","1.85515","-0.00020"
"3721","22.29000","1.85760","0.00008"
"3726","22.32000","1.86017","0.00034"
"3731","22.35000","1.86262","0.00036"
"3736","22.38000","1.86513","0.00036"
"3741","22.41000","1.86759","0.00133"
"3746","22.44000","1.87010","0.00060"
"3751","22.47000","1.87261","0.00043"
"3756","22.50000","1.87512","0.00065"
"3761","22.53000","1.87757","0.00039"
"3766","22.56000","1.88008","0.00018"
"3771","22.59000","1.88259","0.00050"
"3776","22.62000","1.88516","0.00047"
"3781","22.65000","1.88768","0.00076"
"3786","22.68000","1.89019","-0.00015"
"3791","22.71000","1.89270","0.00009"
"3796","22.74000","1.89521","0.00070"
"3801","22.77000","1.89772","0.00027"
"3806","22.80000","1.90017","0.00003"
"3811","22.83000","1.90262","0.00028"
"3816","22.86000","1.90507","0.00008"
"3821","22.89000","1.90759","-0.00029"
"3826","22.92000","1.91016","-0.00010"
"3831","22.95000","1.91255","0.00040"
"3836","22.98000","1.91506","-0.00008"
"3841","23.01000","1.91757","0.00008"
"3846","23.04000","1.92014","0.00064"
"3851","23.07000","1.92265","0.00039"
"3856","23.10000","1.92516","0.00000"
"3861","23.13000","1.92767","-0.00001"
"3866","23.16000","1.93019","0.00036"
"3871","23.19000","1.93270","0.00036"
"3876","23.22000","1.93521","0.00056"
"3881","23.25000","1.93766","0.00057"
"3886","23.28000","1.94017","0.00079"
"3891","23.31000","1.94268","0.00021"
"3896","23.34000","1.94519","0.00067"
"3901","23.37000","1.94764","0.00011"
"3906","23.40000","1.95016","0.00055"
"3911","23.43000","1.95261","0.00071"
"3916","23.46000","1.95512","0.00010"
"3921","23.49000","1.95763","0.00046"
"3926","23.52000","1.96008","0.00026"
"3931","23.55000","1.96259","0.00043"
"3936","23.58000","1.96510","0.00050"
"3941","23.61000","1.96761","0.00067"
"3946","23.64000","1.97012","0.00043"
"3951","23.67000","1.97264","0.00027"
"3956","23.70000","1.97515","0.00054"
"3961","23.73000","1.97766","0.00067"
"3966","23.76000","1.98017","0.00038"
"3971","23.79000","1.98268","-0.00011"
"3976","23.82000","1.98519","0.00016"
"3981","23.85000","1.98770","-0.00002"
"3986","23.88000","1.99015","0.00051"
"3991","23.91000","1.99261","0.00057"
"3996","23.94000","1.99512","0.00036"
"4001","23.97000","1.99763","0.00048"
"4006","24.00000","2.00014","0.00022"
"4011","24.03000","2.00259","0.00023"
"4016","24.06000","2.00510","0.00029"
"4021","24.09000","2.00761","0.00062"
"4026","24.12000","2.01012","-0.00012"
"4031","24.15000","2.01264","-0.00011"
"4036","24.18000","2.01515","-0.00001"
"4041","24.21000","2.01766","0.00034"
"4046","24.24000","2.02017","0.00055"
"4051","24.27000","2.02268","0.00052"
"4056","24.30000","2.02513","0.00045"
"4061","24.33000","2.02770","0.00079"
"4066","24.36000","2.03015","0.00027"
"4071","24.39000","2.03266","0.00032"
"4076","24.42000","2.03518","0.00066"
"4081","24.45000","2.03763","0.00079"
"4086","24.48000","2.04014","0.00066"
"4091","24.51000","2.04265","0.00046"
"4096","24.54000","2.04510","0.00015"
"4101","24.57000","2.04761","-0.00024"
"4106","24.60000","2.05006","0.00074"
"4111","24.63000","2.05263","0.00079"
"4116","24.66000","2.05515","0.00090"
"4121","24.69000","2.05766","0.00097"
"4126","24.72000","2.06017","0.00065"
"4131","24.75000","2.06268","0.00042"
"4136","24.78000","2.06519","0.00050"
"4141","24.81000","2.06764","0.00013"
"4146","24.84000","2.07009","0.00014"
"4151","24.87000","2.07260","0.00009"
"4156","24.90000","2.07518","0.00025"
"4161","24.93000","2.07769","0.00018"
"4166","24.96000","2.08020","-0.00003"
"4171","24.99000","2.08265","0.00024"
"4176","25.02000","2.08516","0.00047"
"4181","25.05000","2.08767","0.00016"
"4186","25.08000","2.09012","-0.00032"
"4191","25.11000","2.09257","0.00033"
"4196","25.14000","2.09509","0.00044"
"4201","25.17000","2.09760","0.00027"
"4206","25.20000","2.10017","0.00042"
"4211","25.23000","2.10268","0.00067"
"4216","25.26000","2.10519","0.00038"
"4221","25.29000","2.10764","0.00011"
"4226","25.32000","2.11015","0.00065"
"4231","25.35000","2.11266","0.00027"
"4236","25.38000","2.11517","0.00028"
"4241","25.41000","2.11763","0.00021"
"4246","25.44000","2.12014","0.00048"
"4251","25.47000","2.12265","0.00050"
"4256","25.50000","2.12522","0.00003"
"4261","25.53000","2.12767","-0.00004"
"4266","25.56000","2.13012","0.00001"
"4271","25.59000","2.13263","0.00042"
"4276","25.62000","2.13514","0.00033"
"4281","25.65000","2.13766","0.00004"
"4286","25.68000","2.14011","0.00049"
"4291","25.71000","2.14256","0.00025"
"4296","25.74000","2.14507","0.00068"
"4301","25.77000","2.14764","-0.00006"
"4306","25.80000","2.15015","0.00004"
"4311","25.83000","2.15266","0.00058"
"4316","25.86000","2.15511","0.00045"
"4321","25.89000","2.15762","-0.00010"
"4326","25.92000","2.16020","0.00018"
"4331","25.95000","2.16265","-0.00047"
"4336","25.98000","2.16516","0.00037"
"4341","26.01000","2.16761","0.00060"
"4346","26.04000","2.17012","0.00006"
"4351","26.07000","2.17263","-0.00007"
"4356","26.10000","2.17514","0.00019"
"4361","26.13000","2.17759","0.00033"
"4366","26.16000","2.18011","0.00032"
"4371","26.19000","2.18256","0.00010"
"4376","26.22000","2.18513","-0.00051"
"4381","26.25000","2.18764","0.00016"
"4386","26.28000","2.19015","0.00020"
"4391","26.31000","2.19266","-0.00008"
"4396","26.34000","2.19517","-0.00047"
"4401","26.37000","2.19774","0.00012"
"4406","26.40000","2.20020","0.00102"
"4411","26.43000","2.20265","0.00028"
"4416","26.46000","2.20516","0.00061"
"4421","26.49000","2.20767","0.00029"
"4426","26.52000","2.21018","0.00015"
"4431","26.55000","2.21263","0.00024"
"4436","26.58000","2.21514","-0.00018"
"4441","26.61000","2.21759","0.00012"
"4446","26.64000","2.22010","0.00056"
"4451","26.67000","2.22262","0.00032"
"4456","26.70000","2.22507","0.00044"
"4461","26.73000","2.22758","0.00018"
"4466","26.76000","2.23009","0.00050"
"4471","26.79000","2.23266","0.00018"
"4476","26.82000","2.23517","0.00037"
"4481","26.85000","2.23762","0.00018"
"4486","26.88000","2.24013","0.00009"
"4491","26.91000","2.24265","0.00084"
"4496","26.94000","2.24522","0.00069"
"4501","26.97000","2.24767","0.00072"
"4506","27.00000","2.25012","0.00065"
"4511","27.03000","2.25263","0.00013"
"4516","27.06000","2.25514","0.00013"
"4521","27.09000","2.25765","0.00061"
"4526","27.12000","2.26010","0.00066"
"4531","27.15000","2.26262","0.00039"
"4536","27.18000","2.26507","0.00045"
"4541","27.21000","2.26764","0.00054"
"4546","27.24000","2.27015","0.00033"
"4551","27.27000","2.27260","0.00029"
"4556","27.30000","2.27511","0.00072"
"4561","27.33000","2.27762","-0.00002"
"4566","27.36000","2.28013","-0.00029"
"4571","27.39000","2.28264","0.00009"
"4576","27.42000","2.28516","0.00075"
"4581","27.45000","2.28767","0.00044"
"4586","27.48000","2.29018","0.00037"
"4591","27.51000","2.29269","0.00075"
"4596","27.54000","2.29514","0.00037"
"4601","27.57000","2.29765","0.00012"
"4606","27.60000","2.30016","0.00022"
"4611","27.63000","2.30267","0.00072"
"4616","27.66000","2.30519","-0.00011"
"4621","27.69000","2.30764","-0.00020"
"4626","27.72000","2.31015","0.00044"
"4631","27.75000","2.31266","0.00024"
"4636","27.78000","2.31511","0.00046"
"4641","27.81000","2.31756","0.00016"
"4646","27.84000","2.32013","0.00008"
"4651","27.87000","2.32264","0.00019"
"4656","27.90000","2.32516","0.00022"
"4661","27.93000","2.32767","0.00039"
"4666","27.96000","2.33018","0.00033"
"4671","27.99000","2.33269","-0.00022"
"4676","28.02000","2.33520","-0.00040"
"4681","28.05000","2.33765","-0.00032"
"4686","28.08000","2.34016","-0.00004"
"4691","28.11000","2.34267","0.00045"
"4696","28.14000","2.34518","0.00058"
"4701","28.17000","2.34764","-0.00008"
"4706","28.20000","2.35015","-0.00002"
"4711","28.23000","2.35266","0.00027"
"4716","28.26000","2.35511","-0.00011"
"4721","28.29000","2.35762","-0.00004"
"4726","28.32000","2.36007","0.00017"
"4731","28.35000","2.36258","0.00041"
"4736","28.38000","2.36509","0.00055"
"4741","28.41000","2.36761","0.00048"
"4746","28.44000","2.37012","-0.00007"
"4751","28.47000","2.37269","-0.00007"
"4756","28.50000","2.37520","-0.00005"
"4761","28.53000","2.37771","0.00052"
"4766","28.56000","2.38016","0.00070"
"4771","28.59000","2.38261","0.00026"
"4776","28.62000","2.38512","-0.00010"
"4781","28.65000","2.38770","0.00024"
"4786","28.68000","2.39015","0.00047"
"4791","28.71000","2.39266","0.00035"
"4796","28.74000","2.39511","0.00016"
"4801","28.77000","2.39762","0.00032"
"4806","28.80000","2.40013","0.00011"
"4811","28.83000","2.40258","0.00018"
"4816","28.86000","2.40509","0.00015"
"4821","28.89000","2.40755","0.00060"
"4826","28.92000","2.41012","0.00029"
"4831","28.95000","2.41269","0.00029"
"4836","28.98000","2.41514","0.00052"
"4841","29.01000","2.41765","0.00027"
"4846","29.04000","2.42016","0.00021"
"4851","29.07000","2.42267","0.00034"
"4856","29.10000","2.42518","0.00032"
"4861","29.13000","2.42769","0.00030"
"4866","29.16000","2.43015","-0.00027"
"4871","29.19000","2.43266","0.00056"
"4876","29.22000","2.43523","0.00057"
"4881","29.25000","2.43768","-0.00007"
"4886","29.28000","2.44019","-0.00006"
"4891","29.31000","2.44264","0.00035"
"4896","29.34000","2.44515","-0.00023"
"4901","29.37000","2.44766","-0.00025"
"4906","29.40000","2.45012","0.00031"
"4911","29.43000","2.45257","0.00040"
"4916","29.46000","2.45508","0.00037"
"4921","29.49000","2.45765","0.00041"
"4926","29.52000","2.46022","0.00027"
"4931","29.55000","2.46267","0.00028"
"4936","29.58000","2.46518","0.00001"
"4941","29.61000","2.46769","0.00010"
"4946","29.64000","2.47020","-0.00007"
"4951","29.67000","2.47272","0.00022"
"4956","29.70000","2.47517","0.00032"
"4961","29.73000","2.47768","0.00033"
"4966","29.76000","2.48019","0.00026"
"4971","29.79000","2.48270","0.00034"
"4976","29.82000","2.48521","0.00040"
"4981","29.85000","2.48766","0.00025"
"4986","29.88000","2.49011","0.00024"
"4991","29.91000","2.49263","0.00007"
"4996","29.94000","2.49514","0.00018"
"5001","29.97000","2.49759","0.00015"
"5006","30.00000","2.50004","-0.00001"
"5011","30.03000","2.50261","0.00045"
"5016","30.06000","2.50518","0.00063"
"5021","30.09000","2.50769","0.00035"
"5026","30.12000","2.51020","0.00034"
"5031","30.15000","2.51266","0.00070"
"5036","30.18000","2.51517","0.00056"
"5041","30.21000","2.51768","0.00023"
"5046","30.24000","2.52019","0.00029"
"5051","30.27000","2.52264","0.00067"
"5056","30.30000","2.52515","0.00026"
"5061","30.33000","2.52760","0.00045"
"5066","30.36000","2.53017","0.00056"
"5071","30.39000","2.53268","0.00026"
"5076","30.42000","2.53514","0.00023"
"5081","30.45000","2.53759","0.00055"
"5086","30.48000","2.54010","0.00054"
"5091","30.51000","2.54261","0.00039"
"5096","30.54000","2.54512","0.00042"
"5101","30.57000","2.54757","0.00048"
"5106","30.60000","2.55008","0.00053"
"5111","30.63000","2.55259","0.00013"
"5116","30.66000","2.55517","0.00023"
"5121","30.69000","2.55768","-0.00021"
"5126","30.72000","2.56013","-0.00019"
"5131","30.75000","2.56264","0.00066"
"5136","30.78000","2.56515","0.00030"
"5141","30.81000","2.56766","0.00045"
"5146","30.84000","2.57017","0.00047"
"5151","30.87000","2.57262","0.00043"
"5156","30.90000","2.57508","0.00071"
"5161","30.93000","2.57765","0.00018"
"5166","30.96000","2.58010","0.00082"
"5171","30.99000","2.58255","0.00041"
"5176","31.02000","2.58506","-0.00019"
"5181","31.05000","2.58757","0.00059"
"5186","31.08000","2.59014","0.00034"
"5191","31.11000","2.59265","0.00025"
"5196","31.14000","2.59510","0.00061"
"5201","31.17000","2.59762","0.00042"
"5206","31.20000","2.60013","0.00058"
"5211","31.23000","2.60264","0.00002"
"5216","31.26000","2.60515","0.00001"
"5221","31.29000","2.60766","0.00025"
"5226","31.32000","2.61023","-0.00003"
"5231","31.35000","2.61268","-0.00035"
"5236","31.38000","2.61519","0.00014"
"5241","31.41000","2.61771","0.00033"
"5246","31.44000","2.62016","0.00024"
"5251","31.47000","2.62267","-0.00025"
"5256","31.50000","2.62518","0.00027"
"5261","31.53000","2.62763","-0.00002"
"5266","31.56000","2.63014","0.00029"
"5271","31.59000","2.63265","0.00052"
"5276","31.62000","2.63510","0.00032"
"5281","31.65000","2.63762","0.00054"
"5286","31.68000","2.64013","0.00003"
"5291","31.71000","2.64264","0.00043"
"5296","31.74000","2.64515","0.00041"
"5301","31.77000","2.64766","0.00044"
"5306","31.80000","2.65017","0.00030"
"5311","31.83000","2.65268","-0.00024"
"5316","31.86000","2.65519","-0.00060"
"5321","31.89000","2.65770","0.00001"
"5326","31.92000","2.66022","0.00085"
"5331","31.95000","2.66267","0.00004"
"5336","31.98000","2.66512","0.00005"
"5341","32.01000","2.66763","0.00021"
"5346","32.04000","2.67008","-0.00016"
"5351","32.07000","2.67259","-0.00009"
"5356","32.10000","2.67510","0.00016"
"5361","32.13000","2.67755","0.00050"
"5366","32.16000","2.68007","0.00097"
"5371","32.19000","2.68258","0.00065"
"5376","32.22000","2.68509","0.00062"
"5381","32.25000","2.68766","-0.00029"
"5386","32.28000","2.69017","-0.00029"
"5391","32.31000","2.69262","-0.00028"
"5396","32.34000","2.69513","-0.00017"
"5401","32.37000","2.69764","0.00022"
"5406","32.40000","2.70021","0.00024"
"5411","32.43000","2.70267","0.00040"
"5416","32.46000","2.70512","-0.00002"
"5421","32.49000","2.70763","0.00032"
"5426","32.52000","2.71014","0.00072"
"5431","32.55000","2.71265","-0.00043"
"5436","32.58000","2.71510","-0.00005"
"5441","32.61000","2.71755","0.00037"
"5446","32.64000","2.72007","0.00038"
"5451","32.67000","2.72264","0.00001"
"5456","32.70000","2.72515","0.00030"
"5461","32.73000","2.72766","0.00062"
"5466","32.76000","2.73017","0.00043"
"5471","32.79000","2.73268","0.00042"
"5476","32.82000","2.73519","0.00049"
"5481","32.85000","2.73770","0.00015"
"5486","32.88000","2.74015","0.00002"
"5491","32.91000","2.74261","0.00015"
"5496","32.94000","2.74518","0.00043"
"5501","32.97000","2.74769","0.00051"
"5506","33.00000","2.75020","0.00075"
"5511","33.03000","2.75265","0.00019"
"5516","33.06000","2.75516","0.00005"
"5521","33.09000","2.75767","0.00024"
"5526","33.12000","2.76012","-0.00007"
"5531","33.15000","2.76264","-0.00024"
"5536","33.18000","2.76509","0.00016"
"5541","33.21000","2.76760","-0.00029"
"5546","33.24000","2.77017","-0.00027"
"5551","33.27000","2.77262","0.00015"
"5556","33.30000","2.77513","0.00011"
"5561","33.33000","2.77764","-0.00011"
"5566","33.36000","2.78015","0.00017"
"5571","33.39000","2.78272","0.00002"
"5576","33.42000","2.78518","0.00013"
"5581","33.45000","2.78763","0.00031"
"5586","33.48000","2.79008","-0.00024"
"5591","33.51000","2.79265","0.00015"
"5596","33.54000","2.79516","0.00037"
"5601","33.57000","2.79767","0.00043"
"5606","33.60000","2.80012","0.00047"
"5611","33.63000","2.80257","0.00058"
"5616","33.66000","2.80515","0.00034"
"5621","33.69000","2.80766","0.00046"
"5626","33.72000","2.81011","-0.00015"
"5631","33.75000","2.81256","-0.00047"
"5636","33.78000","2.81507","0.00017"
"5641","33.81000","2.81764","-0.00015"
"5646","33.84000","2.82015","0.00019"
"5651","33.87000","2.82260","-0.00012"
"5656","33.90000","2.82518","0.00024"
"5661","33.93000","2.82769","0.00061"
"5666","33.96000","2.83020","0.00022"
"5671","33.99000","2.83265","-0.00010"
"5676","34.02000","2.83516","-0.00013"
"5681","34.05000","2.83761","0.00020"
"5686","34.08000","2.84012","0.00040"
"5691","34.11000","2.84269","0.00008"
"5696","34.14000","2.84514","0.00025"
"5701","34.17000","2.84760","-0.00002"
"5706","34.20000","2.85011","-0.00022"
"5711","34.23000","2.85262","0.00005"
"5716","34.26000","2.85513","0.00044"
"5721","34.29000","2.85758","0.00044"
"5726","34.32000","2.86009","0.00003"
"5731","34.35000","2.86260","-0.00009"
"5736","34.38000","2.86517","0.00016"
"5741","34.41000","2.86769","0.00058"
"5746","34.44000","2.87014","-0.00023"
"5751","34.47000","2.87265","0.00042"
"5756","34.50000","2.87510","0.00056"
"5761","34.53000","2.87767","0.00016"
"5766","34.56000","2.88018","-0.00026"
"5771","34.59000","2.88269","0.00008"
"5776","34.62000","2.88514","-0.00020"
"5781","34.65000","2.88766","0.00022"
"5786","34.68000","2.89017","0.00017"
"5791","34.71000","2.89268","0.00013"
"5796","34.74000","2.89513","0.00003"
"5801","34.77000","2.89764","-0.00035"
"5806","34.80000","2.90015","0.00011"
"5811","34.83000","2.90266","0.00037"
"5816","34.86000","2.90517","-0.00021"
"5821","34.89000","2.90762","0.00025"
"5826","34.92000","2.91014","0.00030"
"5831","34.95000","2.91271","-0.00006"
"5836","34.98000","2.91522","-0.00015"
"5841","35.01000","2.91767","0.00019"
"5846","35.04000","2.92012","0.00021"
"5851","35.07000","2.92263","-0.00023"
"5856","35.10000","2.92520","0.00035"
"5861","35.13000","2.92765","-0.00011"
"5866","35.16000","2.93017","0.00031"
"5871","35.19000","2.93262","0.00015"
"5876","35.22000","2.93513","0.00033"
"5881","35.25000","2.93764","0.00048"
"5886","35.28000","2.94015","0.00050"
"5891","35.31000","2.94266","0.00041"
"5896","35.34000","2.94511","0.00050"
"5901","35.37000","2.94762","0.00053"
"5906","35.40000","2.95014","0.00023"
"5911","35.43000","2.95265","0.00036"
"5916","35.46000","2.95516","0.00045"
"5921","35.49000","2.95767","0.00038"
"5926","35.52000","2.96018","0.00035"
"5931","35.55000","2.96263","0.00007"
"5936","35.58000","2.96514","-0.00032"
"5941","35.61000","2.96765","-0.00026"