File: Trajectories_together/170212_1Specimen_RawData_9.csv
"","V1","V2","V3"
"1","End date","2/12/2017",""
"2","Specimen label","9DG_77",""
"3","Maximum Load","0.07952","N"
"4","Time","Extension","Load"
"5","(s)","(mm)","(N)"
"6","0.00000","0.00000","-0.00007"
"78","0.43200","0.03623","0.00029"
"150","0.86400","0.07217","0.00057"
"222","1.29600","0.10810","0.00027"
"294","1.72800","0.14415","0.00071"
"366","2.16000","0.18015","0.00096"
"438","2.59200","0.21614","0.00112"
"510","3.02400","0.25207","0.00044"
"582","3.45600","0.28813","0.00113"
"654","3.88800","0.32418","0.00082"
"726","4.32000","0.36017","0.00080"
"798","4.75200","0.39617","0.00131"
"870","5.18400","0.43210","0.00119"
"942","5.61600","0.46815","0.00106"
"1014","6.04800","0.50415","0.00122"
"1086","6.48000","0.54020","0.00175"
"1158","6.91200","0.57613","0.00136"
"1230","7.34400","0.61213","0.00191"
"1302","7.77600","0.64812","0.00129"
"1374","8.20800","0.68411","0.00129"
"1446","8.64000","0.72016","0.00203"
"1518","9.07200","0.75616","0.00193"
"1590","9.50400","0.79209","0.00203"
"1662","9.93600","0.82814","0.00174"
"1734","10.36800","0.86420","0.00161"
"1806","10.80000","0.90013","0.00171"
"1878","11.23200","0.93618","0.00165"
"1950","11.66400","0.97212","0.00165"
"2022","12.09600","1.00817","0.00198"
"2094","12.52800","1.04416","0.00233"
"2166","12.96000","1.08016","0.00226"
"2238","13.39200","1.11615","0.00241"
"2310","13.82400","1.15214","0.00233"
"2382","14.25600","1.18808","0.00249"
"2454","14.68800","1.22419","0.00263"
"2526","15.12000","1.26018","0.00262"
"2598","15.55200","1.29618","0.00308"
"2670","15.98400","1.33217","0.00286"
"2742","16.41600","1.36816","0.00244"
"2814","16.84800","1.40416","0.00339"
"2886","17.28000","1.44015","0.00247"
"2958","17.71200","1.47614","0.00278"
"3030","18.14400","1.51208","0.00256"
"3102","18.57600","1.54813","0.00305"
"3174","19.00800","1.58412","0.00258"
"3246","19.44000","1.62018","0.00317"
"3318","19.87200","1.65617","0.00269"
"3390","20.30400","1.69216","0.00251"
"3462","20.73600","1.72810","0.00314"
"3534","21.16800","1.76415","0.00296"
"3606","21.60000","1.80020","0.00291"
"3678","22.03200","1.83620","0.00338"
"3750","22.46400","1.87213","0.00325"
"3822","22.89600","1.90812","0.00304"
"3894","23.32800","1.94418","0.00334"
"3966","23.76000","1.98017","0.00390"
"4038","24.19200","2.01610","0.00363"
"4110","24.62400","2.05216","0.00346"
"4182","25.05600","2.08815","0.00336"
"4254","25.48800","2.12414","0.00391"
"4326","25.92000","2.16014","0.00366"
"4398","26.35200","2.19619","0.00357"
"4470","26.78400","2.23212","0.00350"
"4542","27.21600","2.26812","0.00312"
"4614","27.64800","2.30411","0.00348"
"4686","28.08000","2.34016","0.00318"
"4758","28.51200","2.37616","0.00430"
"4830","28.94400","2.41215","0.00340"
"4902","29.37600","2.44814","0.00374"
"4974","29.80800","2.48420","0.00419"
"5046","30.24000","2.52019","0.00448"
"5118","30.67200","2.55624","0.00491"
"5190","31.10400","2.59212","0.00464"
"5262","31.53600","2.62811","0.00409"
"5334","31.96800","2.66410","0.00512"
"5406","32.40000","2.70016","0.00497"
"5478","32.83200","2.73615","0.00500"
"5550","33.26400","2.77214","0.00546"
"5622","33.69600","2.80808","0.00563"
"5694","34.12800","2.84419","0.00526"
"5766","34.56000","2.88018","0.00612"
"5838","34.99200","2.91612","0.00643"
"5910","35.42400","2.95211","0.00561"
"5982","35.85600","2.98810","0.00578"
"6054","36.28800","3.02410","0.00640"
"6126","36.72000","3.06015","0.00666"
"6198","37.15200","3.09614","0.00680"
"6270","37.58400","3.13219","0.00676"
"6342","38.01600","3.16807","0.00663"
"6414","38.44800","3.20412","0.00697"
"6486","38.88000","3.24017","0.00693"
"6558","39.31200","3.27617","0.00684"
"6630","39.74400","3.31210","0.00676"
"6702","40.17600","3.34809","0.00646"
"6774","40.60800","3.38409","0.00650"
"6846","41.04000","3.42014","0.00676"
"6918","41.47200","3.45613","0.00729"
"6990","41.90400","3.49219","0.00680"
"7062","42.33600","3.52806","0.00696"
"7134","42.76800","3.56411","0.00745"
"7206","43.20000","3.60017","0.00754"
"7278","43.63200","3.63616","0.00732"
"7350","44.06400","3.67215","0.00785"
"7422","44.49600","3.70803","0.00757"
"7494","44.92800","3.74408","0.00724"
"7566","45.36000","3.78013","0.00770"
"7638","45.79200","3.81613","0.00830"
"7710","46.22400","3.85218","0.00787"
"7782","46.65600","3.88805","0.00804"
"7854","47.08800","3.92411","0.00842"
"7926","47.52000","3.96016","0.00853"
"7998","47.95200","3.99615","0.00838"
"8070","48.38400","4.03215","0.00781"
"8142","48.81600","4.06808","0.00844"
"8214","49.24800","4.10413","0.00835"
"8286","49.68000","4.14019","0.00903"
"8358","50.11200","4.17618","0.00930"
"8430","50.54400","4.21217","0.00886"
"8502","50.97600","4.24811","0.00925"
"8574","51.40800","4.28410","0.00876"
"8646","51.84000","4.32015","0.00984"
"8718","52.27200","4.35615","0.00962"
"8790","52.70400","4.39220","0.00983"
"8862","53.13600","4.42813","0.00995"
"8934","53.56800","4.46413","0.01062"
"9006","54.00000","4.50018","0.01018"
"9078","54.43200","4.53611","0.00978"
"9150","54.86400","4.57217","0.01047"
"9222","55.29600","4.60816","0.00975"
"9294","55.72800","4.64409","0.01029"
"9366","56.16000","4.68021","0.01098"
"9438","56.59200","4.71620","0.01049"
"9510","57.02400","4.75219","0.01076"
"9582","57.45600","4.78813","0.01006"
"9654","57.88800","4.82412","0.00997"
"9726","58.32000","4.86017","0.00951"
"9798","58.75200","4.89616","0.01003"
"9870","59.18400","4.93216","0.01048"
"9942","59.61600","4.96815","0.01098"
"10014","60.04800","5.00414","0.01093"
"10086","60.48000","5.04014","0.01094"
"10158","60.91200","5.07619","0.01081"
"10230","61.34400","5.11224","0.01192"
"10302","61.77600","5.14812","0.01202"
"10374","62.20800","5.18411","0.01194"
"10446","62.64000","5.22010","0.01258"
"10518","63.07200","5.25622","0.01204"
"10590","63.50400","5.29221","0.01269"
"10662","63.93600","5.32814","0.01287"
"10734","64.36800","5.36414","0.01319"
"10806","64.80000","5.40013","0.01349"
"10878","65.23200","5.43618","0.01248"
"10950","65.66400","5.47212","0.01282"
"11022","66.09600","5.50811","0.01362"
"11094","66.52800","5.54410","0.01391"
"11166","66.96000","5.58010","0.01433"
"11238","67.39200","5.61621","0.01395"
"11310","67.82400","5.65214","0.01485"
"11382","68.25600","5.68814","0.01505"
"11454","68.68800","5.72413","0.01500"
"11526","69.12000","5.76012","0.01539"
"11598","69.55200","5.79618","0.00309"
"11670","69.98400","5.83217","0.00255"
"11742","70.41600","5.86810","0.00289"
"11814","70.84800","5.90410","0.00260"
"11886","71.28000","5.94015","0.00302"
"11958","71.71200","5.97614","0.00237"
"12030","72.14400","6.01214","0.00283"
"12102","72.57600","6.04813","0.00381"
"12174","73.00800","6.08406","0.00379"
"12246","73.44000","6.12012","0.00381"
"12318","73.87200","6.15617","0.00414"
"12390","74.30400","6.19216","0.00420"
"12462","74.73600","6.22810","0.00395"
"12534","75.16800","6.26409","0.00339"
"12606","75.60000","6.30014","0.00431"
"12678","76.03200","6.33620","0.00398"
"12750","76.46400","6.37213","0.00493"
"12822","76.89600","6.40812","0.00462"
"12894","77.32800","6.44406","0.00515"
"12966","77.76000","6.48017","0.00460"
"13038","78.19200","6.51610","0.00557"
"13110","78.62400","6.55210","0.00501"
"13182","79.05600","6.58815","0.00543"
"13254","79.48800","6.62408","0.00538"
"13326","79.92000","6.66008","0.00587"
"13398","80.35200","6.69613","0.00609"
"13470","80.78400","6.73212","0.00461"
"13542","81.21600","6.76818","0.00501"
"13614","81.64800","6.80411","0.00509"
"13686","82.08000","6.84010","0.00525"
"13758","82.51200","6.87615","0.00581"
"13830","82.94400","6.91215","0.00557"
"13902","83.37600","6.94814","0.00648"
"13974","83.80800","6.98408","0.00630"
"14046","84.24000","7.02013","0.00677"
"14118","84.67200","7.05612","0.00747"
"14190","85.10400","7.09211","0.00771"
"14262","85.53600","7.12817","0.00759"
"14334","85.96800","7.16410","0.00687"
"14406","86.40000","7.20015","0.00775"
"14478","86.83200","7.23609","0.00808"
"14550","87.26400","7.27214","0.00756"
"14622","87.69600","7.30814","0.00758"
"14694","88.12800","7.34413","0.00830"
"14766","88.56000","7.38012","0.00835"
"14838","88.99200","7.41617","0.00846"
"14910","89.42400","7.45217","0.00836"
"14982","89.85600","7.48816","0.00878"
"15054","90.28800","7.52415","0.00929"
"15126","90.72000","7.56009","0.00926"
"15198","91.15200","7.59614","0.00983"
"15270","91.58400","7.63219","0.01049"
"15342","92.01600","7.66819","0.01021"
"15414","92.44800","7.70418","0.01051"
"15486","92.88000","7.74011","0.01070"
"15558","93.31200","7.77617","0.00997"
"15630","93.74400","7.81216","0.01043"
"15702","94.17600","7.84815","0.01093"
"15774","94.60800","7.88409","0.01031"
"15846","95.04000","7.92008","0.01007"
"15918","95.47200","7.95619","0.01063"
"15990","95.90400","7.99219","0.01087"
"16062","96.33600","8.02824","0.01018"
"16134","96.76800","8.06417","0.00740"
"16206","97.20000","8.10017","0.00612"
"16278","97.63200","8.13616","0.00571"
"16350","98.06400","8.17215","0.00670"
"16422","98.49600","8.20815","0.00681"
"16494","98.92800","8.24420","0.00780"
"16566","99.36000","8.28013","0.00841"
"16638","99.79200","8.31613","0.00879"
"16710","100.22400","8.35212","0.00961"
"16782","100.65600","8.38817","0.01023"
"16854","101.08800","8.42417","0.01075"
"16926","101.52000","8.46016","0.01046"
"16998","101.95200","8.49615","0.01117"
"17070","102.38400","8.53221","0.01147"
"17142","102.81600","8.56814","0.01200"
"17214","103.24800","8.60419","0.01224"
"17286","103.68000","8.64013","0.01308"
"17358","104.11200","8.67618","0.01391"
"17430","104.54400","8.71211","0.01457"
"17502","104.97600","8.74817","0.01479"
"17574","105.40800","8.78416","0.01560"
"17646","105.84000","8.82009","0.01564"
"17718","106.27200","8.85608","0.01618"
"17790","106.70400","8.89214","0.01720"
"17862","107.13600","8.92813","0.01766"
"17934","107.56800","8.96418","0.01756"
"18006","108.00000","9.00006","0.01887"
"18078","108.43200","9.03611","0.02005"
"18150","108.86400","9.07211","0.02076"
"18222","109.29600","9.10816","0.02168"
"18294","109.72800","9.14409","0.02167"
"18366","110.16000","9.18009","0.02102"
"18438","110.59200","9.21608","0.02215"
"18510","111.02400","9.25219","0.02208"
"18582","111.45600","9.28813","0.02298"
"18654","111.88800","9.32418","0.02377"
"18726","112.32000","9.36011","0.02482"
"18798","112.75200","9.39610","0.02582"
"18870","113.18400","9.43210","0.02651"
"18942","113.61600","9.46815","0.02713"
"19014","114.04800","9.50414","0.02798"
"19086","114.48000","9.54008","0.02793"
"19158","114.91200","9.57613","0.02923"
"19230","115.34400","9.61212","0.02975"
"19302","115.77600","9.64818","0.03064"
"19374","116.20800","9.68411","0.03126"
"19446","116.64000","9.72010","0.03172"
"19518","117.07200","9.75610","0.02667"
"19590","117.50400","9.79215","0.02402"
"19662","117.93600","9.82814","0.02203"
"19734","118.36800","9.86414","0.01840"
"19806","118.80000","9.90013","0.00954"
"19878","119.23200","9.93618","0.01051"
"19950","119.66400","9.97212","0.01023"
"20022","120.09600","10.00811","0.01030"
"20094","120.52800","10.04416","0.01074"
"20166","120.96000","10.08010","0.01125"
"20238","121.39200","10.11609","0.01162"
"20310","121.82400","10.15208","0.01186"
"20382","122.25600","10.18814","0.01237"
"20454","122.68800","10.22419","0.01306"
"20526","123.12000","10.26012","0.01383"
"20598","123.55200","10.29612","0.01419"
"20670","123.98400","10.33211","0.01413"
"20742","124.41600","10.36810","0.01486"
"20814","124.84800","10.40416","0.01468"
"20886","125.28000","10.44015","0.01551"
"20958","125.71200","10.47614","0.01581"
"21030","126.14400","10.51208","0.01568"
"21102","126.57600","10.54819","0.01670"
"21174","127.00800","10.58418","0.01657"
"21246","127.44000","10.62012","0.01663"
"21318","127.87200","10.65611","0.01627"
"21390","128.30400","10.69210","0.01784"
"21462","128.73600","10.72816","0.01797"
"21534","129.16800","10.76421","0.01870"
"21606","129.60000","10.80014","0.01862"
"21678","130.03200","10.83613","0.01902"
"21750","130.46400","10.87213","0.01907"
"21822","130.89600","10.90812","0.01927"
"21894","131.32800","10.94418","0.01929"
"21966","131.76000","10.98017","0.01900"
"22038","132.19200","11.01610","0.01868"
"22110","132.62400","11.05215","0.01938"
"22182","133.05600","11.08821","0.01988"
"22254","133.48800","11.12420","0.01889"
"22326","133.92000","11.16019","0.01840"
"22398","134.35200","11.19613","0.01923"
"22470","134.78400","11.23212","0.00832"
"22542","135.21600","11.26818","0.00414"
"22614","135.64800","11.30417","0.00532"
"22686","136.08000","11.34016","0.00403"
"22758","136.51200","11.37609","0.00623"
"22830","136.94400","11.41215","0.00699"
"22902","137.37600","11.44814","0.00593"
"22974","137.80800","11.48419","0.00620"
"23046","138.24000","11.52019","0.00610"
"23118","138.67200","11.55612","0.00600"
"23190","139.10400","11.59211","0.00614"
"23262","139.53600","11.62817","0.00680"
"23334","139.96800","11.66416","0.00606"
"23406","140.40000","11.70021","0.00662"
"23478","140.83200","11.73615","0.00668"
"23550","141.26400","11.77208","0.00699"
"23622","141.69600","11.80819","0.00742"
"23694","142.12800","11.84413","0.00707"
"23766","142.56000","11.88018","0.00697"
"23838","142.99200","11.91611","0.00787"
"23910","143.42400","11.95205","0.00785"
"23982","143.85600","11.98816","0.00756"
"24054","144.28800","12.02415","0.00693"
"24126","144.72000","12.06021","0.00728"
"24198","145.15200","12.09614","0.00778"
"24270","145.58400","12.13213","0.00798"
"24342","146.01600","12.16819","0.00773"
"24414","146.44800","12.20412","0.00779"
"24486","146.88000","12.24017","0.00839"
"24558","147.31200","12.27611","0.00864"
"24630","147.74400","12.31210","0.00841"
"24702","148.17600","12.34809","0.00934"
"24774","148.60800","12.38415","0.00923"
"24846","149.04000","12.42020","0.00972"
"24918","149.47200","12.45613","0.00978"
"24990","149.90400","12.49207","0.00943"
"25062","150.33600","12.52818","0.00928"
"25134","150.76800","12.56423","0.00904"
"25206","151.20000","12.60023","0.00941"
"25278","151.63200","12.63610","0.01067"
"25350","152.06400","12.67209","0.01090"
"25422","152.49600","12.70815","0.01089"
"25494","152.92800","12.74414","0.01113"
"25566","153.36000","12.78013","0.01166"
"25638","153.79200","12.81613","0.01080"
"25710","154.22400","12.85206","0.01119"
"25782","154.65600","12.88811","0.00826"
"25854","155.08800","12.92416","0.00899"
"25926","155.52000","12.96022","0.00934"
"25998","155.95200","12.99615","0.00975"
"26070","156.38400","13.03209","0.00964"
"26142","156.81600","13.06808","0.01005"
"26214","157.24800","13.10413","0.01000"
"26286","157.68000","13.14018","0.01031"
"26358","158.11200","13.17612","0.01129"
"26430","158.54400","13.21211","0.01156"
"26502","158.97600","13.24817","0.01164"
"26574","159.40800","13.28416","0.01235"
"26646","159.84000","13.32021","0.01055"
"26718","160.27200","13.35609","0.01081"
"26790","160.70400","13.39208","0.00823"
"26862","161.13600","13.42807","0.00931"
"26934","161.56800","13.46419","0.00974"
"27006","162.00000","13.50012","0.00991"
"27078","162.43200","13.53611","0.00993"
"27150","162.86400","13.57210","0.01027"
"27222","163.29600","13.60816","0.01037"
"27294","163.72800","13.64415","0.01054"
"27366","164.16000","13.68015","0.00991"
"27438","164.59200","13.71614","0.01049"
"27510","165.02400","13.75207","0.01009"
"27582","165.45600","13.78812","0.01121"
"27654","165.88800","13.82418","0.01142"
"27726","166.32000","13.86017","0.01155"
"27798","166.75200","13.89616","0.01144"
"27870","167.18400","13.93204","0.01181"
"27942","167.61600","13.96809","0.01213"
"28014","168.04800","14.00414","0.01265"
"28086","168.48000","14.04020","0.01273"
"28158","168.91200","14.07613","0.01351"
"28230","169.34400","14.11206","0.01334"
"28302","169.77600","14.14812","0.01323"
"28374","170.20800","14.18417","0.01376"
"28446","170.64000","14.22016","0.01446"
"28518","171.07200","14.25616","0.01414"
"28590","171.50400","14.29209","0.01396"
"28662","171.93600","14.32814","0.01381"
"28734","172.36800","14.36414","0.01457"
"28806","172.80000","14.40019","0.01493"
"28878","173.23200","14.43618","0.01562"
"28950","173.66400","14.47212","0.01563"
"29022","174.09600","14.50811","0.01595"
"29094","174.52800","14.54410","0.01612"
"29166","174.96000","14.58016","0.01570"
"29238","175.39200","14.61621","0.01630"
"29310","175.82400","14.65214","0.01631"
"29382","176.25600","14.68814","0.01681"
"29454","176.68800","14.72419","0.01763"
"29526","177.12000","14.76018","0.01854"
"29598","177.55200","14.79618","0.01824"
"29670","177.98400","14.83217","0.01680"
"29742","178.41600","14.86810","0.01849"
"29814","178.84800","14.90416","0.01799"
"29886","179.28000","14.94021","0.01813"
"29958","179.71200","14.97614","0.01915"
"30030","180.14400","15.01208","0.01967"
"30102","180.57600","15.04813","0.01996"
"30174","181.00800","15.08418","0.01870"
"30246","181.44000","15.12018","0.01973"
"30318","181.87200","15.15623","0.01997"
"30390","182.30400","15.19210","0.02029"
"30462","182.73600","15.22816","0.02143"
"30534","183.16800","15.26415","0.02123"
"30606","183.60000","15.30014","0.02213"
"30678","184.03200","15.33620","0.02275"
"30750","184.46400","15.37219","0.02292"
"30822","184.89600","15.40806","0.01824"
"30894","185.32800","15.44417","0.01827"
"30966","185.76000","15.48023","0.01431"
"31038","186.19200","15.51616","0.01283"
"31110","186.62400","15.55216","0.01351"
"31182","187.05600","15.58809","0.01398"
"31254","187.48800","15.62414","0.01462"
"31326","187.92000","15.66019","0.01524"
"31398","188.35200","15.69613","0.01592"
"31470","188.78400","15.73212","0.01600"
"31542","189.21600","15.76811","0.01713"
"31614","189.64800","15.80411","0.01695"
"31686","190.08000","15.84016","0.01744"
"31758","190.51200","15.87621","0.01815"
"31830","190.94400","15.91209","0.01842"
"31902","191.37600","15.94808","0.01853"
"31974","191.80800","15.98407","0.01984"
"32046","192.24000","16.02019","0.01961"
"32118","192.67200","16.05618","0.02023"
"32190","193.10400","16.09217","0.01932"
"32262","193.53600","16.12805","0.01997"
"32334","193.96800","16.16410","0.02091"
"32406","194.40000","16.20015","0.02200"
"32478","194.83200","16.23621","0.02287"
"32550","195.26400","16.27220","0.02306"
"32622","195.69600","16.30813","0.02353"
"32694","196.12800","16.34413","0.02477"
"32766","196.56000","16.38018","0.02620"
"32838","196.99200","16.41611","0.02593"
"32910","197.42400","16.45217","0.02671"
"32982","197.85600","16.48810","0.02679"
"33054","198.28800","16.52409","0.02751"
"33126","198.72000","16.56015","0.02749"
"33198","199.15200","16.59614","0.02765"
"33270","199.58400","16.63213","0.02803"
"33342","200.01600","16.66807","0.02900"
"33414","200.44800","16.70412","0.02928"
"33486","200.88000","16.74017","0.03019"
"33558","201.31200","16.77611","0.03066"
"33630","201.74400","16.81216","0.03128"
"33702","202.17600","16.84809","0.03165"
"33774","202.60800","16.88408","0.03299"
"33846","203.04000","16.92014","0.03312"
"33918","203.47200","16.95619","0.03219"
"33990","203.90400","16.99213","0.03278"
"34062","204.33600","17.02812","0.03238"
"34134","204.76800","17.06411","0.03050"
"34206","205.20000","17.10016","0.03179"
"34278","205.63200","17.13610","0.03299"
"34350","206.06400","17.17215","0.03319"
"34422","206.49600","17.20808","0.03336"
"34494","206.92800","17.24414","0.03351"
"34566","207.36000","17.28013","0.03449"
"34638","207.79200","17.31613","0.03544"
"34710","208.22400","17.35218","0.03552"
"34782","208.65600","17.38811","0.03646"
"34854","209.08800","17.42405","0.03663"
"34926","209.52000","17.46016","0.03695"
"34998","209.95200","17.49615","0.03740"
"35070","210.38400","17.53214","0.03825"
"35142","210.81600","17.56808","0.03873"
"35214","211.24800","17.60413","0.03911"
"35286","211.68000","17.64018","0.03972"
"35358","212.11200","17.67618","0.04041"
"35430","212.54400","17.71211","0.04071"
"35502","212.97600","17.74816","0.04155"
"35574","213.40800","17.78410","0.04157"
"35646","213.84000","17.82015","0.04219"
"35718","214.27200","17.85614","0.04230"
"35790","214.70400","17.89220","0.04347"
"35862","215.13600","17.92813","0.04436"
"35934","215.56800","17.96412","0.04491"
"36006","216.00000","18.00012","0.04618"
"36078","216.43200","18.03617","0.04707"
"36150","216.86400","18.07216","0.04788"
"36222","217.29600","18.10816","0.04893"
"36294","217.72800","18.14409","0.04989"
"36366","218.16000","18.18014","0.05115"
"36438","218.59200","18.21614","0.05202"
"36510","219.02400","18.25219","0.05325"
"36582","219.45600","18.28818","0.05453"
"36654","219.88800","18.32406","0.05592"
"36726","220.32000","18.36017","0.05710"
"36798","220.75200","18.39616","0.05815"
"36870","221.18400","18.43216","0.05848"
"36942","221.61600","18.46821","0.05965"
"37014","222.04800","18.50414","0.06031"
"37086","222.48000","18.54020","0.06167"
"37158","222.91200","18.57619","0.06331"
"37230","223.34400","18.61212","0.06439"
"37302","223.77600","18.64812","0.06492"
"37374","224.20800","18.68411","0.06623"
"37446","224.64000","18.72016","0.06819"
"37518","225.07200","18.75616","0.06857"
"37590","225.50400","18.79215","0.07010"
"37662","225.93600","18.82814","0.07145"
"37734","226.36800","18.86414","0.07205"
"37806","226.80000","18.90013","0.07382"
"37878","227.23200","18.93618","0.07420"
"37950","227.66400","18.97218","0.07518"
"38022","228.09600","19.00817","0.07430"
"38094","228.52800","19.04410","0.07574"
"38166","228.96000","19.08015","0.07769"
"38238","229.39200","19.11615","0.07843"
"38310","229.82400","19.15214","-0.00607"
"38382","230.25600","19.18814","-0.00400"
"38454","230.68800","19.22413","-0.00262"
"38526","231.12000","19.26012","-0.00208"
"38598","231.55200","19.29618","-0.00156"
"38670","231.98400","19.33217","-0.00178"
"38742","232.41600","19.36816","-0.00060"
"38814","232.84800","19.40415","-0.00033"
"38886","233.28000","19.44015","-0.00125"
"38958","233.71200","19.47608","-0.00137"
"39030","234.14400","19.51214","-0.00136"
"39102","234.57600","19.54813","-0.00149"
"39174","235.00800","19.58412","-0.00170"
"39246","235.44000","19.62012","-0.00071"
"39318","235.87200","19.65611","-0.00139"
"39390","236.30400","19.69216","-0.00140"
"39462","236.73600","19.72821","-0.00087"
"39534","237.16800","19.76409","-0.00137"
"39606","237.60000","19.80014","-0.00134"
"39678","238.03200","19.83614","-0.00098"
"39750","238.46400","19.87213","-0.00095"
"39822","238.89600","19.90818","-0.00096"
"39894","239.32800","19.94417","-0.00082"
"39966","239.76000","19.98011","-0.00138"
"40038","240.19200","20.01616","-0.00097"
"40110","240.62400","20.05215","-0.00109"
"40182","241.05600","20.08815","-0.00073"
"40254","241.48800","20.12408","-0.00119"
"40326","241.92000","20.16014","-0.00113"
"40398","242.35200","20.19607","-0.00174"
"40470","242.78400","20.23218","-0.00112"
"40542","243.21600","20.26817","-0.00109"
"40614","243.64800","20.30411","-0.00165"
"40686","244.08000","20.34010","-0.00087"
"40758","244.51200","20.37609","-0.00064"
"40830","244.94400","20.41221","-0.00176"
"40902","245.37600","20.44814","-0.00115"
"40974","245.80800","20.48413","-0.00093"
"41046","246.24000","20.52007","-0.00056"
"41118","246.67200","20.55612","-0.00090"
"41190","247.10400","20.59217","-0.00062"
"41262","247.53600","20.62817","-0.00128"
"41334","247.96800","20.66416","-0.00081"
"41406","248.40000","20.70015","-0.00056"
"41478","248.83200","20.73609","-0.00127"
"41550","249.26400","20.77214","-0.00127"
"41622","249.69600","20.80813","-0.00110"
"41694","250.12800","20.84413","-0.00085"
"41766","250.56000","20.88012","-0.00090"
"41838","250.99200","20.91611","-0.00049"
"41910","251.42400","20.95217","-0.00091"
"41982","251.85600","20.98816","-0.00046"
"42054","252.28800","21.02415","-0.00078"
"42126","252.72000","21.06009","-0.00098"
"42198","253.15200","21.09614","-0.00115"
"42270","253.58400","21.13219","-0.00078"
"42342","254.01600","21.16818","-0.00133"
"42414","254.44800","21.20418","-0.00102"
"42486","254.88000","21.24011","-0.00134"
"42558","255.31200","21.27610","-0.00115"
"42630","255.74400","21.31216","-0.00107"
"42702","256.17600","21.34815","-0.00081"
"42774","256.60800","21.38415","-0.00089"
"42846","257.04000","21.42008","-0.00164"
"42918","257.47200","21.45613","-0.00084"
"42990","257.90400","21.49219","-0.00096"
"43062","258.33600","21.52818","-0.00185"
"43134","258.76800","21.56417","-0.00097"
"43206","259.20000","21.60016","-0.00135"
"43278","259.63200","21.63610","-0.00143"
"43350","260.06400","21.67209","-0.00097"
"43422","260.49600","21.70814","-0.00077"
"43494","260.92800","21.74420","-0.00049"
"43566","261.36000","21.78013","-0.00047"
"43638","261.79200","21.81612","-0.00051"
"43710","262.22400","21.85218","-0.00093"
"43782","262.65600","21.88817","-0.00114"
"43854","263.08800","21.92422","-0.00173"
"43926","263.52000","21.96010","-0.00085"
"43998","263.95200","21.99609","-0.00062"
"44070","264.38400","22.03221","-0.00353"
"44142","264.81600","22.06814","-0.00131"
"44214","265.24800","22.10419","-0.00054"
"44286","265.68000","22.14013","-0.00091"
"44358","266.11200","22.17612","-0.00146"
"44430","266.54400","22.21211","-0.00067"
"44502","266.97600","22.24816","-0.00072"
"44574","267.40800","22.28416","-0.00160"
"44646","267.84000","22.32015","-0.00044"
"44718","268.27200","22.35608","-0.00086"
"44790","268.70400","22.39214","-0.00074"
"44862","269.13600","22.42813","-0.00118"
"44934","269.56800","22.46418","-0.00073"
"45006","270.00000","22.50012","-0.00250"
"45078","270.43200","22.53605","-0.00076"
"45150","270.86400","22.57216","-0.00094"
"45222","271.29600","22.60816","-0.00118"
"45294","271.72800","22.64421","-0.00031"
"45366","272.16000","22.68014","-0.00098"
"45438","272.59200","22.71608","-0.00121"
"45510","273.02400","22.75213","-0.00084"
"45582","273.45600","22.78812","-0.00107"
"45654","273.88800","22.82412","-0.00104"
"45726","274.32000","22.86011","-0.00091"
"45798","274.75200","22.89610","-0.00087"
"45870","275.18400","22.93216","-0.00047"
"45942","275.61600","22.96815","-0.00098"
"46014","276.04800","23.00420","-0.00127"
"46086","276.48000","23.04014","-0.00104"
"46158","276.91200","23.07613","-0.00105"
"46230","277.34400","23.11212","-0.00082"
"46302","277.77600","23.14812","-0.00132"
"46374","278.20800","23.18417","-0.00102"
"46446","278.64000","23.22016","-0.00065"
"46518","279.07200","23.25604","-0.00098"
"46590","279.50400","23.29215","-0.00048"
"46662","279.93600","23.32814","-0.00074"
"46734","280.36800","23.36419","-0.00113"
"46806","280.80000","23.40019","-0.00081"
"46878","281.23200","23.43606","-0.00021"
"46950","281.66400","23.47206","-0.00111"
"47022","282.09600","23.50817","-0.00048"
"47094","282.52800","23.54410","-0.00073"
"47166","282.96000","23.58016","-0.00056"
"47238","283.39200","23.61603","-0.00103"
"47310","283.82400","23.65214","-0.00007"
"47382","284.25600","23.68813","-0.00052"
"47454","284.68800","23.72419","-0.00094"
"47526","285.12000","23.76012","-0.00079"
"47598","285.55200","23.79605","-0.00108"
"47670","285.98400","23.83205","-0.00086"
"47742","286.41600","23.86816","-0.00070"
"47814","286.84800","23.90409","-0.00066"
"47886","287.28000","23.94015","-0.00071"
"47958","287.71200","23.97608","-0.00069"
"48030","288.14400","24.01213","-0.00022"
"48102","288.57600","24.04813","-0.00135"
"48174","289.00800","24.08418","-0.00076"
"48246","289.44000","24.12012","-0.00099"
"48318","289.87200","24.15605","-0.00081"
"48390","290.30400","24.19210","-0.00044"
"48462","290.73600","24.22815","-0.00048"
"48534","291.16800","24.26415","-0.00078"
"48606","291.60000","24.30014","-0.00011"
"48678","292.03200","24.33607","-0.00012"
"48750","292.46400","24.37213","0.00010"
"48822","292.89600","24.40812","-0.00040"
"48894","293.32800","24.44417","-0.00038"
"48966","293.76000","24.48017","-0.00084"
"49038","294.19200","24.51610","-0.00050"
"49110","294.62400","24.55209","-0.00024"
"49182","295.05600","24.58815","-0.00078"
"49254","295.48800","24.62414","-0.00027"
"49326","295.92000","24.66019","-0.00019"
"49398","296.35200","24.69613","-0.00077"
"49470","296.78400","24.73212","-0.00071"
"49542","297.21600","24.76817","-0.00035"
"49614","297.64800","24.80416","-0.00053"
"49686","298.08000","24.84016","-0.00072"
"49758","298.51200","24.87615","-0.00084"
"49830","298.94400","24.91215","0.00020"
"49902","299.37600","24.94820","-0.00084"
"49974","299.80800","24.98419","-0.00063"
"50046","300.24000","25.02019","-0.00052"
"50118","300.67200","25.05612","-0.00041"
"50190","301.10400","25.09211","-0.00118"
"50262","301.53600","25.12817","-0.00110"
"50334","301.96800","25.16416","-0.00074"
"50406","302.40000","25.20021","-0.00060"
"50478","302.83200","25.23615","-0.00048"
"50550","303.26400","25.27214","-0.00072"
"50622","303.69600","25.30813","-0.00025"
"50694","304.12800","25.34418","-0.00091"
"50766","304.56000","25.38024","-0.00067"
"50838","304.99200","25.41611","-0.00084"
"50910","305.42400","25.45210","-0.00114"
"50982","305.85600","25.48822","-0.00105"
"51054","306.28800","25.52415","-0.00090"
"51126","306.72000","25.56020","-0.00075"
"51198","307.15200","25.59614","-0.00072"
"51270","307.58400","25.63207","-0.00077"
"51342","308.01600","25.66813","-0.00030"
"51414","308.44800","25.70418","-0.00119"
"51486","308.88000","25.74017","-0.00078"
"51558","309.31200","25.77610","-0.00116"
"51630","309.74400","25.81210","-0.00114"
"51702","310.17600","25.84815","-0.00090"
"51774","310.60800","25.88415","-0.00062"
"51846","311.04000","25.92020","-0.00047"
"51918","311.47200","25.95607","-0.00089"
"51990","311.90400","25.99212","-0.00095"
"52062","312.33600","26.02812","-0.00129"
"52134","312.76800","26.06417","-0.00135"
"52206","313.20000","26.10017","0.00023"
"52278","313.63200","26.13616","-0.00057"
"52350","314.06400","26.17209","-0.00057"
"52422","314.49600","26.20814","-0.00024"
"52494","314.92800","26.24414","-0.00094"
"52566","315.36000","26.28013","-0.00019"
"52638","315.79200","26.31612","-0.00082"
"52710","316.22400","26.35206","-0.00053"
"52782","316.65600","26.38817","-0.00052"
"52854","317.08800","26.42416","-0.00097"
"52926","317.52000","26.46010","-0.00114"
"52998","317.95200","26.49609","-0.00143"
"53070","318.38400","26.53209","-0.00100"
"53142","318.81600","26.56814","-0.00136"
"53214","319.24800","26.60419","-0.00030"
"53286","319.68000","26.64013","-0.00052"
"53358","320.11200","26.67612","-0.00053"
"53430","320.54400","26.71211","-0.00037"
"53502","320.97600","26.74804","-0.00095"
"53574","321.40800","26.78416","-0.00042"
"53646","321.84000","26.82015","-0.00042"
"53718","322.27200","26.85614","-0.00018"
"53790","322.70400","26.89202","-0.00082"
"53862","323.13600","26.92813","-0.00024"
"53934","323.56800","26.96412","-0.00055"
"54006","324.00000","27.00018","-0.00091"
"54078","324.43200","27.03617","-0.00066"
"54150","324.86400","27.07216","-0.00052"
"54222","325.29600","27.10810","-0.00124"
"54294","325.72800","27.14415","-0.00072"
"54366","326.16000","27.18015","-0.00066"
"54438","326.59200","27.21620","-0.00081"
"54510","327.02400","27.25213","-0.00099"
"54582","327.45600","27.28806","-0.00047"
"54654","327.88800","27.32417","-0.00043"
"54726","328.32000","27.36017","-0.00066"
"54798","328.75200","27.39610","-0.00089"
"54870","329.18400","27.43210","-0.00073"
"54942","329.61600","27.46815","-0.00125"
"55014","330.04800","27.50414","-0.00004"
"55086","330.48000","27.54014","-0.00050"
"55158","330.91200","27.57613","-0.00160"
"55230","331.34400","27.61212","-0.00077"
"55302","331.77600","27.64812","-0.00099"
"55374","332.20800","27.68411","-0.00146"
"55446","332.64000","27.72016","-0.00086"
"55518","333.07200","27.75616","-0.00117"
"55590","333.50400","27.79209","-0.00064"
"55662","333.93600","27.82814","-0.00035"
"55734","334.36800","27.86414","-0.00039"
"55806","334.80000","27.90019","-0.00090"
"55878","335.23200","27.93618","-0.00109"
"55950","335.66400","27.97211","-0.00063"
"56022","336.09600","28.00811","-0.00081"
"56094","336.52800","28.04416","-0.00034"
"56166","336.96000","28.08010","-0.00063"
"56238","337.39200","28.11615","-0.00025"
"56310","337.82400","28.15214","-0.00034"
"56382","338.25600","28.18808","-0.00085"
"56454","338.68800","28.22419","-0.00063"
"56526","339.12000","28.26018","-0.00085"
"56598","339.55200","28.29617","-0.00090"
"56670","339.98400","28.33211","-0.00095"
"56742","340.41600","28.36804","-0.00089"
"56814","340.84800","28.40421","-0.00088"
"56886","341.28000","28.44021","-0.00138"
"56958","341.71200","28.47614","-0.00068"
"57030","342.14400","28.51213","-0.00085"
"57102","342.57600","28.54813","-0.00122"
"57174","343.00800","28.58418","-0.00052"
"57246","343.44000","28.62017","-0.00106"
"57318","343.87200","28.65623","-0.00122"
"57390","344.30400","28.69216","-0.00061"
"57462","344.73600","28.72810","-0.00064"
"57534","345.16800","28.76415","-0.00131"
"57606","345.60000","28.80014","-0.00112"
"57678","346.03200","28.83619","-0.00068"
"57750","346.46400","28.87213","-0.00128"
"57822","346.89600","28.90812","-0.00049"
"57894","347.32800","28.94411","-0.00064"
"57966","347.76000","28.98017","-0.00063"
"58038","348.19200","29.01616","-0.00175"
"58110","348.62400","29.05215","-0.00167"
"58182","349.05600","29.08809","-0.00173"
"58254","349.48800","29.12414","-0.00133"
"58326","349.92000","29.16019","-0.00095"
"58398","350.35200","29.19619","-0.00071"
"58470","350.78400","29.23218","-0.00088"
"58542","351.21600","29.26811","-0.00077"
"58614","351.64800","29.30417","-0.00049"
"58686","352.08000","29.34016","-0.00047"
"58758","352.51200","29.37615","-0.00090"
"58830","352.94400","29.41215","-0.00102"
"58902","353.37600","29.44808","-0.00075"
"58974","353.80800","29.48413","-0.00040"
"59046","354.24000","29.52013","-0.00137"
"59118","354.67200","29.55612","-0.00051"
"59190","355.10400","29.59211","-0.00148"
"59262","355.53600","29.62811","-0.00057"
"59334","355.96800","29.66410","-0.00105"
"59406","356.40000","29.70015","-0.00084"
"59478","356.83200","29.73615","-0.00089"
"59550","357.26400","29.77220","-0.00035"
"59622","357.69600","29.80807","-0.00039"
"59694","358.12800","29.84412","-0.00022"
"59766","358.56000","29.88012","-0.00118"
"59838","358.99200","29.91611","-0.00044"
"59910","359.42400","29.95217","-0.00088"
"59982","359.85600","29.98810","-0.00078"
"60054","360.28800","30.02421","-0.00103"
"60126","360.72000","30.06021","-0.00056"
"60198","361.15200","30.09614","-0.00035"
"60270","361.58400","30.13213","-0.00022"
"60342","362.01600","30.16813","-0.00107"
"60414","362.44800","30.20412","-0.00139"
"60486","362.88000","30.24011","-0.00126"
"60558","363.31200","30.27617","-0.00038"
"60630","363.74400","30.31216","-0.00055"
"60702","364.17600","30.34815","-0.00057"
"60774","364.60800","30.38408","-0.00046"
"60846","365.04000","30.42014","-0.00054"
"60918","365.47200","30.45613","-0.00093"
"60990","365.90400","30.49218","-0.00065"
"61062","366.33600","30.52812","0.00025"
"61134","366.76800","30.56411","-0.00076"
"61206","367.20000","30.60011","-0.00097"
"61278","367.63200","30.63616","-0.00045"
"61350","368.06400","30.67215","-0.00083"
"61422","368.49600","30.70815","-0.00078"
"61494","368.92800","30.74408","-0.00104"
"61566","369.36000","30.78013","-0.00145"
"61638","369.79200","30.81618","-0.00075"
"61710","370.22400","30.85218","-0.00118"
"61782","370.65600","30.88811","-0.00045"
"61854","371.08800","30.92410","-0.00047"
"61926","371.52000","30.96010","-0.00068"
"61998","371.95200","30.99615","-0.00097"
"62070","372.38400","31.03214","-0.00086"
"62142","372.81600","31.06814","-0.00147"
"62214","373.24800","31.10413","-0.00119"
"62286","373.68000","31.14012","-0.00089"
"62358","374.11200","31.17618","-0.00088"
"62430","374.54400","31.21217","-0.00094"
"62502","374.97600","31.24810","-0.00049"
"62574","375.40800","31.28409","-0.00123"
"62646","375.84000","31.32015","-0.00111"
"62718","376.27200","31.35620","-0.00142"
"62790","376.70400","31.39219","-0.00102"
"62862","377.13600","31.42813","-0.00072"
"62934","377.56800","31.46412","-0.00055"
"63006","378.00000","31.50012","-0.00129"
"63078","378.43200","31.53617","-0.00127"
"63150","378.86400","31.57216","-0.00069"
"63222","379.29600","31.60821","-0.00148"
"63294","379.72800","31.64415","-0.00083"
"63366","380.16000","31.68008","-0.00111"
"63438","380.59200","31.71619","-0.00148"
"63510","381.02400","31.75213","-0.00023"
"63582","381.45600","31.78818","-0.00091"
"63654","381.88800","31.82412","-0.00061"
"63726","382.32000","31.86011","-0.00169"
"63798","382.75200","31.89622","-0.00060"
"63870","383.18400","31.93215","-0.00072"
"63942","383.61600","31.96821","-0.00166"
"64014","384.04800","32.00408","-0.00106"
"64086","384.48000","32.04007","-0.00068"
"64158","384.91200","32.07619","-0.00186"
"64230","385.34400","32.11212","-0.00089"
"64302","385.77600","32.14817","-0.00066"
"64374","386.20800","32.18410","-0.00060"
"64446","386.64000","32.22010","-0.00079"
"64518","387.07200","32.25621","-0.00091"
"64590","387.50400","32.29214","-0.00038"
"64662","387.93600","32.32814","-0.00102"
"64734","388.36800","32.36413","-0.00035"
"64806","388.80000","32.40013","-0.00094"
"64878","389.23200","32.43612","-0.00089"
"64950","389.66400","32.47218","-0.00044"
"65022","390.09600","32.50816","-0.00190"
"65094","390.52800","32.54416","-0.00044"
"65166","390.96000","32.58009","-0.00130"
"65238","391.39200","32.61615","-0.00091"
"65310","391.82400","32.65214","-0.00039"
"65382","392.25600","32.68819","-0.00074"
"65454","392.68800","32.72407","-0.00091"
"65526","393.12000","32.76012","-0.00004"
"65598","393.55200","32.79617","0.00013"
"65670","393.98400","32.83216","-0.00126"
"65742","394.41600","32.86816","0.00009"
"65814","394.84800","32.90409","-0.00108"
"65886","395.28000","32.94009","-0.00040"
"65958","395.71200","32.97614","-0.00081"
"66030","396.14400","33.01213","-0.00124"
"66102","396.57600","33.04819","-0.00071"
"66174","397.00800","33.08412","-0.00184"
"66246","397.44000","33.12011","-0.00140"
"66318","397.87200","33.15611","-0.00110"
"66390","398.30400","33.19216","-0.00068"
"66462","398.73600","33.22815","-0.00034"
"66534","399.16800","33.26414","-0.00085"
"66606","399.60000","33.30002","-0.00065"
"66678","400.03200","33.33613","-0.00075"
"66750","400.46400","33.37218","-0.00052"
"66822","400.89600","33.40818","-0.00103"
"66894","401.32800","33.44411","-0.00118"
"66966","401.76000","33.48005","-0.00097"
"67038","402.19200","33.51616","-0.00119"
"67110","402.62400","33.55215","-0.00117"
"67182","403.05600","33.58815","-0.00031"
"67254","403.48800","33.62414","-0.00088"
"67326","403.92000","33.66007","-0.00007"
"67398","404.35200","33.69613","-0.00106"
"67470","404.78400","33.73212","-0.00093"
"67542","405.21600","33.76811","-0.00051"
"67614","405.64800","33.80410","-0.00085"
"67686","406.08000","33.84010","-0.00051"
"67758","406.51200","33.87609","-0.00075"
"67830","406.94400","33.91214","0.00021"
"67902","407.37600","33.94814","-0.00049"
"67974","407.80800","33.98413","-0.00085"
"68046","408.24000","34.02007","-0.00050"
"68118","408.67200","34.05611","-0.00005"
"68190","409.10400","34.09217","-0.00096"
"68262","409.53600","34.12816","-0.00068"
"68334","409.96800","34.16416","-0.00040"
"68406","410.40000","34.20009","-0.00040"
"68478","410.83200","34.23608","-0.00063"
"68550","411.26400","34.27214","-0.00080"
"68622","411.69600","34.30813","-0.00045"
"68694","412.12800","34.34412","-0.00038"
"68766","412.56000","34.38005","-0.00084"
"68838","412.99200","34.41611","-0.00124"
"68910","413.42400","34.45216","-0.00009"
"68982","413.85600","34.48816","-0.00047"
"69054","414.28800","34.52415","-0.00084"
"69126","414.72000","34.56009","-0.00079"
"69198","415.15200","34.59608","-0.00055"
"69270","415.58400","34.63219","-0.00050"
"69342","416.01600","34.66813","0.00012"
"69414","416.44800","34.70417","-0.00068"
"69486","416.88000","34.74005","0.00015"
"69558","417.31200","34.77616","-0.00021"
"69630","417.74400","34.81216","-0.00018"
"69702","418.17600","34.84815","-0.00058"
"69774","418.60800","34.88420","-0.00017"
"69846","419.04000","34.92014","0.00009"
"69918","419.47200","34.95613","-0.00026"
"69990","419.90400","34.99218","-0.00039"
"70062","420.33600","35.02818","-0.00033"
"70134","420.76800","35.06417","0.00031"
"70206","421.20000","35.10010","0.00009"
"70278","421.63200","35.13615","0.00074"
"70350","422.06400","35.17215","0.00003"
"70422","422.49600","35.20815","-0.00080"
"70494","422.92800","35.24414","-0.00017"
"70566","423.36000","35.28013","-0.00040"
"70638","423.79200","35.31612","-0.00059"
"70710","424.22400","35.35217","0.00020"
"70782","424.65600","35.38817","-0.00014"
"70854","425.08800","35.42416","-0.00006"
"70926","425.52000","35.46016","-0.00031"
"70998","425.95200","35.49615","-0.00039"
"71070","426.38400","35.53220","0.00009"
"71142","426.81600","35.56820","0.00041"
"71214","427.24800","35.60425","-0.00024"
"71286","427.68000","35.64018","0.00024"
"71358","428.11200","35.67617","-0.00015"
"71430","428.54400","35.71217","-0.00038"
"71502","428.97600","35.74816","0.00086"
"71574","429.40800","35.78416","0.00019"
"71646","429.84000","35.82015","0.00012"
"71718","430.27200","35.85608","-0.00111"
"71790","430.70400","35.89214","-0.00057"
"71862","431.13600","35.92819","-0.00012"
"71934","431.56800","35.96418","-0.00109"
"72006","432.00000","36.00017","-0.00141"
"72078","432.43200","36.03617","-0.00055"
"72150","432.86400","36.07216","-0.00069"
"72222","433.29600","36.10822","-0.00098"
"72294","433.72800","36.14421","-0.00068"
"72366","434.16000","36.18008","-0.00117"
"72438","434.59200","36.21608","-0.00105"
"72510","435.02400","36.25212","-0.00091"
"72582","435.45600","36.28812","-0.00130"
"72654","435.88800","36.32417","-0.00041"
"72726","436.32000","36.36011","-0.00114"
"72798","436.75200","36.39610","-0.00066"
"72870","437.18400","36.43216","-0.00054"
"72942","437.61600","36.46815","-0.00090"
"73014","438.04800","36.50414","-0.00103"
"73086","438.48000","36.54013","-0.00059"
"73158","438.91200","36.57613","-0.00136"
"73230","439.34400","36.61212","-0.00072"
"73302","439.77600","36.64817","-0.00098"
"73374","440.20800","36.68417","-0.00144"
"73446","440.64000","36.72016","-0.00119"
"73518","441.07200","36.75610","-0.00156"
"73590","441.50400","36.79209","-0.00031"
"73662","441.93600","36.82820","-0.00101"
"73734","442.36800","36.86413","-0.00043"
"73806","442.80000","36.90012","-0.00085"
"73878","443.23200","36.93606","-0.00083"
"73950","443.66400","36.97211","-0.00061"
"74022","444.09600","37.00817","-0.00054"
"74094","444.52800","37.04416","-0.00038"
"74166","444.96000","37.08009","-0.00078"
"74238","445.39200","37.11609","-0.00097"
"74310","445.82400","37.15214","-0.00090"
"74382","446.25600","37.18819","-0.00089"
"74454","446.68800","37.22412","-0.00113"
"74526","447.12000","37.26012","-0.00085"
"74598","447.55200","37.29605","-0.00042"
"74670","447.98400","37.33211","-0.00104"
"74742","448.41600","37.36816","-0.00093"
"74814","448.84800","37.40409","-0.00057"
"74886","449.28000","37.44015","-0.00076"
"74958","449.71200","37.47614","-0.00151"
"75030","450.14400","37.51207","-0.00065"
"75102","450.57600","37.54813","-0.00108"
"75174","451.00800","37.58412","-0.00081"
"75246","451.44000","37.62017","-0.00077"
"75318","451.87200","37.65605","-0.00101"
"75390","452.30400","37.69210","-0.00025"
"75462","452.73600","37.72809","-0.00060"
"75534","453.16800","37.76415","-0.00047"
"75606","453.60000","37.80014","-0.00046"
"75678","454.03200","37.83613","-0.00068"
"75750","454.46400","37.87212","-0.00038"
"75822","454.89600","37.90818","0.00010"
"75894","455.32800","37.94411","-0.00008"
"75966","455.76000","37.98022","-0.00036"
"76038","456.19200","38.01610","-0.00038"
"76110","456.62400","38.05215","-0.00026"
"76182","457.05600","38.08815","-0.00096"
"76254","457.48800","38.12414","-0.00010"
"76326","457.92000","38.16013","-0.00016"
"76398","458.35200","38.19613","0.00040"
"76470","458.78400","38.23212","0.00017"
"76542","459.21600","38.26817","-0.00013"
"76614","459.64800","38.30416","-0.00015"
"76686","460.08000","38.34022","-0.00004"
"76758","460.51200","38.37615","-0.00049"
"76830","460.94400","38.41208","0.00039"
"76902","461.37600","38.44814","0.00058"
"76974","461.80800","38.48419","0.00023"
"77046","462.24000","38.52018","0.00005"
"77118","462.67200","38.55612","-0.00012"
"77190","463.10400","38.59211","0.00093"
"77262","463.53600","38.62817","0.00054"
"77334","463.96800","38.66422","-0.00013"
"77406","464.40000","38.70021","0.00006"
"77478","464.83200","38.73614","-0.00014"
"77550","465.26400","38.77214","-0.00048"
"77622","465.69600","38.80819","0.00021"
"77694","466.12800","38.84418","0.00037"
"77766","466.56000","38.88018","0.00062"
"77838","466.99200","38.91611","0.00060"
"77910","467.42400","38.95211","0.00014"
"77982","467.85600","38.98816","0.00020"
"78054","468.28800","39.02415","0.00052"
"78126","468.72000","39.06020","0.00023"
"78198","469.15200","39.09613","0.00026"
"78270","469.58400","39.13207","0.00105"
"78342","470.01600","39.16818","0.00068"
"78414","470.44800","39.20418","0.00070"
"78486","470.88000","39.24011","0.00043"
"78558","471.31200","39.27610","0.00080"
"78630","471.74400","39.31210","0.00085"
"78702","472.17600","39.34808","0.00029"
"78774","472.60800","39.38414","0.00114"
"78846","473.04000","39.42013","0.00102"
"78918","473.47200","39.45613","0.00061"
"78990","473.90400","39.49212","0.00086"
"79062","474.33600","39.52812","0.00069"
"79134","474.76800","39.56417","0.00116"
"79206","475.20000","39.60016","0.00156"
"79278","475.63200","39.63616","0.00170"
"79350","476.06400","39.67209","0.00197"
"79422","476.49600","39.70808","0.00156"
"79494","476.92800","39.74414","0.00213"
"79566","477.36000","39.78012","0.00127"
"79638","477.79200","39.81618","0.00134"
"79710","478.22400","39.85212","0.00167"
"79782","478.65600","39.88811","0.00257"
"79854","479.08800","39.92410","0.00179"
"79926","479.52000","39.96015","0.00185"
"79998","479.95200","39.99615","0.00245"
"80070","480.38400","40.03214","0.00271"
"80142","480.81600","40.06813","0.00213"
"80214","481.24800","40.10419","0.00233"
"80286","481.68000","40.14018","0.00287"
"80358","482.11200","40.17617","0.00258"
"80430","482.54400","40.21211","0.00283"
"80502","482.97600","40.24816","0.00261"
"80574","483.40800","40.28409","0.00312"
"80646","483.84000","40.32014","0.00402"
"80718","484.27200","40.35614","0.00348"
"80790","484.70400","40.39214","0.00387"
"80862","485.13600","40.42812","0.00393"
"80934","485.56800","40.46412","0.00420"
"81006","486.00000","40.50017","0.00414"
"81078","486.43200","40.53617","0.00402"
"81150","486.86400","40.57204","0.00451"
"81222","487.29600","40.60809","0.00452"
"81294","487.72800","40.64415","0.00438"
"81366","488.16000","40.68014","0.00527"
"81438","488.59200","40.71613","0.00517"
"81510","489.02400","40.75213","0.00462"
"81582","489.45600","40.78812","0.00454"
"81654","489.88800","40.82417","0.00213"
"81726","490.32000","40.86017","-0.00058"
"81798","490.75200","40.89622","-0.00108"
"81870","491.18400","40.93209","-0.00095"
"81942","491.61600","40.96808","-0.00139"
"82014","492.04800","41.00408","-0.00105"
"82086","492.48000","41.04013","-0.00170"
"82158","492.91200","41.07613","-0.00147"
"82230","493.34400","41.11212","-0.00117"
"82302","493.77600","41.14811","-0.00107"
"82374","494.20800","41.18411","-0.00136"
"82446","494.64000","41.22016","-0.00157"
"82518","495.07200","41.25615","-0.00160"
"82590","495.50400","41.29214","-0.00163"
"82662","495.93600","41.32814","-0.00163"
"82734","496.36800","41.36413","-0.00137"
"82806","496.80000","41.40019","-0.00179"
"82878","497.23200","41.43618","-0.00137"
"82950","497.66400","41.47211","-0.00149"
"83022","498.09600","41.50811","-0.00138"
"83094","498.52800","41.54410","-0.00129"
"83166","498.96000","41.58015","-0.00183"
"83238","499.39200","41.61615","-0.00127"
"83310","499.82400","41.65214","-0.00084"
"83382","500.25600","41.68813","-0.00169"
"83454","500.68800","41.72412","-0.00181"
"83526","501.12000","41.76018","-0.00118"
"83598","501.55200","41.79617","-0.00087"
"83670","501.98400","41.83216","-0.00122"
"83742","502.41600","41.86810","-0.00103"
"83814","502.84800","41.90409","-0.00090"
"83886","503.28000","41.94020","-0.00148"
"83958","503.71200","41.97620","-0.00150"
"84030","504.14400","42.01219","-0.00138"
"84102","504.57600","42.04813","-0.00160"
"84174","505.00800","42.08412","-0.00140"
"84246","505.44000","42.12017","-0.00199"
"84318","505.87200","42.15623","-0.00104"
"84390","506.30400","42.19210","-0.00183"
"84462","506.73600","42.22815","-0.00088"
"84534","507.16800","42.26414","-0.00124"
"84606","507.60000","42.30019","-0.00136"
"84678","508.03200","42.33619","-0.00067"
"84750","508.46400","42.37218","-0.00108"
"84822","508.89600","42.40812","-0.00119"
"84894","509.32800","42.44411","-0.00163"
"84966","509.76000","42.48016","-0.00120"
"85038","510.19200","42.51616","-0.00119"
"85110","510.62400","42.55215","-0.00140"
"85182","511.05600","42.58815","-0.00072"
"85254","511.48800","42.62414","-0.00082"
"85326","511.92000","42.66019","-0.00122"
"85398","512.35200","42.69613","-0.00044"
"85470","512.78400","42.73217","-0.00121"
"85542","513.21600","42.76811","-0.00124"
"85614","513.64800","42.80404","-0.00094"
"85686","514.08000","42.84015","-0.00077"
"85758","514.51200","42.87615","-0.00076"
"85830","514.94400","42.91214","0.00018"
"85902","515.37600","42.94814","-0.00093"
"85974","515.80800","42.98413","-0.00071"
"86046","516.24000","43.02018","-0.00024"
"86118","516.67200","43.05618","-0.00057"
"86190","517.10400","43.09217","-0.00044"
"86262","517.53600","43.12816","-0.00043"
"86334","517.96800","43.16410","-0.00099"
"86406","518.40000","43.20009","-0.00073"
"86478","518.83200","43.23615","-0.00033"
"86550","519.26400","43.27214","-0.00062"
"86622","519.69600","43.30813","-0.00086"
"86694","520.12800","43.34407","-0.00085"
"86766","520.56000","43.38018","-0.00098"
"86838","520.99200","43.41617","-0.00068"
"86900","521.36200","43.44702","-0.00066"