File: Trajectories_together/170212_1Specimen_RawData_3.csv
"","V1","V2","V3"
"1","End date","2/12/2017",""
"2","Specimen label","10BG_67",""
"3","Maximum Load","0.04377","N"
"4","Time","Extension","Load"
"5","(s)","(mm)","(N)"
"6","0.00000","0.00000","-0.00037"
"49","0.25800","0.02027","0.00268"
"92","0.51600","0.04329","0.00557"
"135","0.77400","0.06469","0.00702"
"178","1.03200","0.08622","0.00907"
"221","1.29000","0.10768","0.01019"
"264","1.54800","0.12921","0.01173"
"307","1.80600","0.15067","0.01247"
"350","2.06400","0.17219","0.01380"
"393","2.32200","0.19366","0.01437"
"436","2.58000","0.21518","0.01478"
"479","2.83800","0.23671","0.01512"
"522","3.09600","0.25823","0.01598"
"565","3.35400","0.27964","0.01741"
"608","3.61200","0.30122","0.01758"
"651","3.87000","0.32268","0.01784"
"694","4.12800","0.34421","0.01861"
"737","4.38600","0.36573","0.01923"
"780","4.64400","0.38726","0.01883"
"823","4.90200","0.40872","0.02036"
"866","5.16000","0.43019","0.02007"
"909","5.41800","0.45165","0.02027"
"952","5.67600","0.47323","0.02115"
"995","5.93400","0.49476","0.02098"
"1038","6.19200","0.51616","0.02194"
"1081","6.45000","0.53775","0.02188"
"1124","6.70800","0.55915","0.02205"
"1167","6.96600","0.58074","0.02259"
"1210","7.22400","0.60220","0.02214"
"1253","7.48200","0.62372","0.02324"
"1296","7.74000","0.64513","0.02322"
"1339","7.99800","0.66665","0.02348"
"1382","8.25600","0.68812","0.02339"
"1425","8.51400","0.70976","0.02342"
"1468","8.77200","0.73117","0.02367"
"1511","9.03000","0.75269","0.02340"
"1554","9.28800","0.77415","0.02326"
"1597","9.54600","0.79574","0.02332"
"1640","9.80400","0.81714","0.02371"
"1683","10.06200","0.83873","0.02364"
"1726","10.32000","0.86019","0.02390"
"1769","10.57800","0.88178","0.02486"
"1812","10.83600","0.90318","0.02373"
"1855","11.09400","0.92470","0.02390"
"1898","11.35200","0.94623","0.02536"
"1941","11.61000","0.96769","0.02468"
"1984","11.86800","0.98916","0.02458"
"2027","12.12600","1.01068","0.02470"
"2070","12.38400","1.03221","0.02501"
"2113","12.64200","1.05373","0.02478"
"2156","12.90000","1.07520","0.02457"
"2199","13.15800","1.09666","0.02441"
"2242","13.41600","1.11818","0.02473"
"2285","13.67400","1.13971","0.02439"
"2328","13.93200","1.16117","0.02529"
"2371","14.19000","1.18264","0.02557"
"2414","14.44800","1.20422","0.02507"
"2457","14.70600","1.22563","0.02485"
"2500","14.96400","1.24721","0.02515"
"2543","15.22200","1.26867","0.02528"
"2586","15.48000","1.29020","0.02546"
"2629","15.73800","1.31166","0.02514"
"2672","15.99600","1.33325","0.02543"
"2715","16.25400","1.35465","0.02536"
"2758","16.51200","1.37618","0.02577"
"2801","16.77000","1.39770","0.02570"
"2844","17.02800","1.41928","0.02547"
"2887","17.28600","1.44075","0.02588"
"2930","17.54400","1.46221","0.02578"
"2973","17.80200","1.48368","0.02591"
"3016","18.06000","1.50520","0.02621"
"3059","18.31800","1.52679","0.02648"
"3102","18.57600","1.54819","0.02560"
"3145","18.83400","1.56971","0.02596"
"3188","19.09200","1.59112","0.02603"
"3231","19.35000","1.61270","0.02550"
"3274","19.60800","1.63417","0.02550"
"3317","19.86600","1.65569","0.02604"
"3360","20.12400","1.67722","0.02601"
"3403","20.38200","1.69868","0.02665"
"3446","20.64000","1.72014","0.02646"
"3489","20.89800","1.74167","0.02653"
"3532","21.15600","1.76319","0.02637"
"3575","21.41400","1.78478","0.02568"
"3618","21.67200","1.80618","0.02584"
"3661","21.93000","1.82771","0.02613"
"3704","22.18800","1.84923","0.02614"
"3747","22.44600","1.87075","0.02701"
"3790","22.70400","1.89216","0.02611"
"3833","22.96200","1.91368","0.02712"
"3876","23.22000","1.93521","0.02620"
"3919","23.47800","1.95673","0.02688"
"3962","23.73600","1.97820","0.02632"
"4005","23.99400","1.99972","0.02669"
"4048","24.25200","2.02119","0.02670"
"4091","24.51000","2.04265","0.02679"
"4134","24.76800","2.06423","0.02602"
"4177","25.02600","2.08570","0.02643"
"4220","25.28400","2.10728","0.02672"
"4263","25.54200","2.12869","0.02617"
"4306","25.80000","2.15021","0.02661"
"4349","26.05800","2.17162","0.02670"
"4392","26.31600","2.19320","0.02674"
"4435","26.57400","2.21466","0.02608"
"4478","26.83200","2.23619","0.02684"
"4521","27.09000","2.25765","0.02690"
"4564","27.34800","2.27924","0.02676"
"4607","27.60600","2.30070","0.02697"
"4650","27.86400","2.32223","0.02637"
"4693","28.12200","2.34369","0.02706"
"4736","28.38000","2.36521","0.02697"
"4779","28.63800","2.38668","0.02630"
"4822","28.89600","2.40826","0.02709"
"4865","29.15400","2.42967","0.02630"
"4908","29.41200","2.45119","0.02619"
"4951","29.67000","2.47266","0.02723"
"4994","29.92800","2.49424","0.02706"
"5037","30.18600","2.51576","0.02739"
"5080","30.44400","2.53723","0.02670"
"5123","30.70200","2.55869","0.02707"
"5166","30.96000","2.58022","0.02663"
"5209","31.21800","2.60174","0.02707"
"5252","31.47600","2.62321","0.02757"
"5295","31.73400","2.64473","0.02708"
"5338","31.99200","2.66613","0.02739"
"5381","32.25000","2.68772","0.02689"
"5424","32.50800","2.70912","0.02698"
"5467","32.76600","2.73077","0.02677"
"5510","33.02400","2.75217","0.02682"
"5553","33.28200","2.77370","0.02656"
"5596","33.54000","2.79516","0.02699"
"5639","33.79800","2.81668","0.02751"
"5682","34.05600","2.83815","0.02691"
"5725","34.31400","2.85973","0.02695"
"5768","34.57200","2.88120","0.02738"
"5811","34.83000","2.90272","0.02694"
"5854","35.08800","2.92419","0.02733"
"5897","35.34600","2.94571","0.02705"
"5940","35.60400","2.96718","0.02718"
"5983","35.86200","2.98870","0.02715"
"6026","36.12000","3.01022","0.02711"
"6069","36.37800","3.03175","0.02702"
"6112","36.63600","3.05321","0.02677"
"6155","36.89400","3.07468","0.02727"
"6198","37.15200","3.09614","0.02687"
"6241","37.41000","3.11767","0.02748"
"6284","37.66800","3.13919","0.02681"
"6327","37.92600","3.16071","0.02702"
"6370","38.18400","3.18218","0.02673"
"6413","38.44200","3.20364","0.02720"
"6456","38.70000","3.22523","0.02672"
"6499","38.95800","3.24663","0.02751"
"6542","39.21600","3.26822","0.02660"
"6585","39.47400","3.28968","0.02700"
"6628","39.73200","3.31120","0.02743"
"6671","39.99000","3.33261","0.02733"
"6714","40.24800","3.35425","0.02709"
"6757","40.50600","3.37566","0.02684"
"6800","40.76400","3.39724","0.02703"
"6843","41.02200","3.41871","0.02647"
"6886","41.28000","3.44023","0.02649"
"6929","41.53800","3.46169","0.02704"
"6972","41.79600","3.48322","0.02747"
"7015","42.05400","3.50468","0.02684"
"7058","42.31200","3.52621","0.02683"
"7101","42.57000","3.54773","0.02642"
"7144","42.82800","3.56920","0.02719"
"7187","43.08600","3.59072","0.02682"
"7230","43.34400","3.61218","0.02707"
"7273","43.60200","3.63371","0.02696"
"7316","43.86000","3.65517","0.02715"
"7359","44.11800","3.67676","0.02664"
"7402","44.37600","3.69816","0.02669"
"7445","44.63400","3.71969","0.02678"
"7488","44.89200","3.74115","0.02657"
"7531","45.15000","3.76273","0.02715"
"7574","45.40800","3.78420","0.02713"
"7617","45.66600","3.80572","0.02699"
"7660","45.92400","3.82719","0.02686"
"7703","46.18200","3.84871","0.02714"
"7746","46.44000","3.87018","0.02666"
"7789","46.69800","3.89170","0.02610"
"7832","46.95600","3.91317","0.02698"
"7875","47.21400","3.93469","0.02686"
"7918","47.47200","3.95615","0.02671"
"7961","47.73000","3.97774","0.02656"
"8004","47.98800","3.99920","0.02626"
"8047","48.24600","4.02079","0.02703"
"8090","48.50400","4.04213","0.02621"
"8133","48.76200","4.06372","0.02735"
"8176","49.02000","4.08524","0.02684"
"8219","49.27800","4.10670","0.02687"
"8262","49.53600","4.12823","0.02644"
"8305","49.79400","4.14963","0.02711"
"8348","50.05200","4.17122","0.02725"
"8391","50.31000","4.19268","0.02710"
"8434","50.56800","4.21421","0.02681"
"8477","50.82600","4.23567","0.02704"
"8520","51.08400","4.25725","0.02741"
"8563","51.34200","4.27860","0.02720"
"8606","51.60000","4.30024","0.02684"
"8649","51.85800","4.32171","0.02742"
"8692","52.11600","4.34323","0.02686"
"8735","52.37400","4.36470","0.02681"
"8778","52.63200","4.38616","0.02706"
"8821","52.89000","4.40768","0.02714"
"8864","53.14800","4.42921","0.02701"
"8907","53.40600","4.45067","0.02711"
"8950","53.66400","4.47220","0.02651"
"8993","53.92200","4.49372","0.02725"
"9036","54.18000","4.51519","0.02704"
"9079","54.43800","4.53671","0.02704"
"9122","54.69600","4.55817","0.02699"
"9165","54.95400","4.57964","0.02729"
"9208","55.21200","4.60116","0.02704"
"9251","55.47000","4.62269","0.02651"
"9294","55.72800","4.64421","0.02726"
"9337","55.98600","4.66568","0.02724"
"9380","56.24400","4.68720","0.02719"
"9423","56.50200","4.70866","0.02730"
"9466","56.76000","4.73019","0.02720"
"9509","57.01800","4.75171","0.02697"
"9552","57.27600","4.77318","0.02719"
"9595","57.53400","4.79470","0.02744"
"9638","57.79200","4.81611","0.02738"
"9681","58.05000","4.83769","0.02712"
"9724","58.30800","4.85916","0.02780"
"9767","58.56600","4.88074","0.02786"
"9810","58.82400","4.90214","0.02658"
"9853","59.08200","4.92367","0.02697"
"9896","59.34000","4.94513","0.02688"
"9939","59.59800","4.96672","0.02786"
"9982","59.85600","4.98818","0.02786"
"10025","60.11400","5.00971","0.02756"
"10068","60.37200","5.03117","0.02692"
"10111","60.63000","5.05275","0.02734"
"10154","60.88800","5.07428","0.02717"
"10197","61.14600","5.09568","0.02738"
"10240","61.40400","5.11721","0.02669"
"10283","61.66200","5.13873","0.02775"
"10326","61.92000","5.16020","0.02691"
"10369","62.17800","5.18166","0.02705"
"10412","62.43600","5.20318","0.02714"
"10455","62.69400","5.22465","0.02756"
"10498","62.95200","5.24623","0.02756"
"10541","63.21000","5.26770","0.02785"
"10584","63.46800","5.28922","0.02744"
"10627","63.72600","5.31063","0.02787"
"10670","63.98400","5.33221","0.02748"
"10713","64.24200","5.35367","0.02712"
"10756","64.50000","5.37520","0.02806"
"10799","64.75800","5.39666","0.02751"
"10842","65.01600","5.41819","0.02754"
"10885","65.27400","5.43965","0.02755"
"10928","65.53200","5.46118","0.02732"
"10971","65.79000","5.48270","0.02720"
"11014","66.04800","5.50422","0.02747"
"11057","66.30600","5.52569","0.02743"
"11100","66.56400","5.54721","0.02961"
"11143","66.82200","5.56868","0.02851"
"11186","67.08000","5.59020","0.02808"
"11229","67.33800","5.61167","0.02696"
"11272","67.59600","5.63319","0.02707"
"11315","67.85400","5.65472","0.02705"
"11358","68.11200","5.67618","0.02743"
"11401","68.37000","5.69776","0.02691"
"11444","68.62800","5.71923","0.02778"
"11487","68.88600","5.74069","0.02727"
"11530","69.14400","5.76216","0.02698"
"11573","69.40200","5.78374","0.02697"
"11616","69.66000","5.80520","0.02739"
"11659","69.91800","5.82673","0.02723"
"11702","70.17600","5.84813","0.02718"
"11745","70.43400","5.86972","0.02746"
"11788","70.69200","5.89118","0.02716"
"11831","70.95000","5.91271","0.02748"
"11874","71.20800","5.93417","0.02747"
"11917","71.46600","5.95570","0.02717"
"11960","71.72400","5.97722","0.02717"
"12003","71.98200","5.99868","0.02740"
"12046","72.24000","6.02021","0.02756"
"12089","72.49800","6.04173","0.02713"
"12132","72.75600","6.06314","0.02700"
"12175","73.01400","6.08472","0.02737"
"12218","73.27200","6.10619","0.02731"
"12261","73.53000","6.12777","0.02752"
"12304","73.78800","6.14923","0.02770"
"12347","74.04600","6.17070","0.02764"
"12390","74.30400","6.19216","0.02764"
"12433","74.56200","6.21369","0.02742"
"12476","74.82000","6.23521","0.02712"
"12519","75.07800","6.25668","0.02707"
"12562","75.33600","6.27820","0.02809"
"12605","75.59400","6.29960","0.02795"
"12648","75.85200","6.32119","0.02777"
"12691","76.11000","6.34271","0.02763"
"12734","76.36800","6.36424","0.02797"
"12777","76.62600","6.38564","0.02695"
"12820","76.88400","6.40723","0.02667"
"12863","77.14200","6.42863","0.02768"
"12906","77.40000","6.45021","0.02788"
"12949","77.65800","6.47168","0.02777"
"12992","77.91600","6.49320","0.02748"
"13035","78.17400","6.51467","0.02775"
"13078","78.43200","6.53619","0.02815"
"13121","78.69000","6.55766","0.02766"
"13164","78.94800","6.57924","0.02777"
"13207","79.20600","6.60070","0.02747"
"13250","79.46400","6.62223","0.02816"
"13293","79.72200","6.64369","0.02776"
"13336","79.98000","6.66516","0.02767"
"13379","80.23800","6.68668","0.02797"
"13422","80.49600","6.70821","0.02723"
"13465","80.75400","6.72967","0.02783"
"13508","81.01200","6.75126","0.02815"
"13551","81.27000","6.77278","0.02779"
"13594","81.52800","6.79418","0.02737"
"13637","81.78600","6.81571","0.02771"
"13680","82.04400","6.83711","0.02808"
"13723","82.30200","6.85876","0.02765"
"13766","82.56000","6.88016","0.02798"
"13809","82.81800","6.90169","0.02789"
"13852","83.07600","6.92315","0.02813"
"13895","83.33400","6.94467","0.02766"
"13938","83.59200","6.96614","0.02798"
"13981","83.85000","6.98772","0.02740"
"14024","84.10800","7.00919","0.02821"
"14067","84.36600","7.03071","0.02812"
"14110","84.62400","7.05218","0.02746"
"14153","84.88200","7.07370","0.02800"
"14196","85.14000","7.09516","0.02774"
"14239","85.39800","7.11675","0.02803"
"14282","85.65600","7.13815","0.02822"
"14325","85.91400","7.15968","0.02782"
"14368","86.17200","7.18120","0.02802"
"14411","86.43000","7.20273","0.02798"
"14454","86.68800","7.22419","0.02840"
"14497","86.94600","7.24571","0.02835"
"14540","87.20400","7.26718","0.02828"
"14583","87.46200","7.28870","0.02741"
"14626","87.72000","7.31023","0.02766"
"14669","87.97800","7.33169","0.02803"
"14712","88.23600","7.35322","0.02827"
"14755","88.49400","7.37468","0.02801"
"14798","88.75200","7.39626","0.02801"
"14841","89.01000","7.41773","0.02805"
"14884","89.26800","7.43919","0.02817"
"14927","89.52600","7.46060","0.02852"
"14970","89.78400","7.48218","0.02780"
"15013","90.04200","7.50371","0.02771"
"15056","90.30000","7.52523","0.02784"
"15099","90.55800","7.54663","0.02864"
"15142","90.81600","7.56822","0.02759"
"15185","91.07400","7.58962","0.02863"
"15228","91.33200","7.61127","0.02830"
"15271","91.59000","7.63261","0.02765"
"15314","91.84800","7.65426","0.02799"
"15357","92.10600","7.67572","0.02809"
"15400","92.36400","7.69725","0.02794"
"15443","92.62200","7.71871","0.02862"
"15486","92.88000","7.74023","0.02838"
"15529","93.13800","7.76170","0.02804"
"15572","93.39600","7.78316","0.02771"
"15615","93.65400","7.80469","0.02815"
"15658","93.91200","7.82621","0.02808"
"15701","94.17000","7.84773","0.02775"
"15744","94.42800","7.86914","0.02909"
"15787","94.68600","7.89072","0.02762"
"15830","94.94400","7.91213","0.02832"
"15873","95.20200","7.93371","0.02820"
"15916","95.46000","7.95518","0.02857"
"15959","95.71800","7.97670","0.02829"
"16002","95.97600","7.99817","0.02812"
"16045","96.23400","8.01969","0.02800"
"16088","96.49200","8.04115","0.02817"
"16131","96.75000","8.06274","0.02813"
"16174","97.00800","8.08420","0.02804"
"16217","97.26600","8.10573","0.02841"
"16260","97.52400","8.12719","0.02806"
"16303","97.78200","8.14872","0.02778"
"16346","98.04000","8.17018","0.02825"
"16389","98.29800","8.19170","0.02837"
"16432","98.55600","8.21317","0.02814"
"16475","98.81400","8.23469","0.02756"
"16518","99.07200","8.25622","0.02862"
"16561","99.33000","8.27774","0.02813"
"16604","99.58800","8.29921","0.02833"
"16647","99.84600","8.32073","0.02884"
"16690","100.10400","8.34219","0.02818"
"16733","100.36200","8.36372","0.02882"
"16776","100.62000","8.38524","0.02801"
"16819","100.87800","8.40665","0.02895"
"16862","101.13600","8.42817","0.02832"
"16905","101.39400","8.44964","0.02880"
"16948","101.65200","8.47128","0.02837"
"16991","101.91000","8.49269","0.02852"
"17034","102.16800","8.51421","0.02837"
"17077","102.42600","8.53561","0.02860"
"17120","102.68400","8.55720","0.02826"
"17163","102.94200","8.57866","0.02832"
"17206","103.20000","8.60019","0.02832"
"17249","103.45800","8.62171","0.02842"
"17292","103.71600","8.64323","0.02848"
"17335","103.97400","8.66470","0.02782"
"17378","104.23200","8.68622","0.02808"
"17421","104.49000","8.70769","0.02870"
"17464","104.74800","8.72921","0.02773"
"17507","105.00600","8.75068","0.02849"
"17550","105.26400","8.77220","0.02823"
"17593","105.52200","8.79373","0.02831"
"17636","105.78000","8.81519","0.02818"
"17679","106.03800","8.83665","0.02814"
"17722","106.29600","8.85818","0.02785"
"17765","106.55400","8.87964","0.02841"
"17808","106.81200","8.90117","0.02825"
"17851","107.07000","8.92269","0.02759"
"17894","107.32800","8.94416","0.02827"
"17937","107.58600","8.96574","0.02806"
"17980","107.84400","8.98714","0.02844"
"18023","108.10200","9.00873","0.02836"
"18066","108.36000","9.03013","0.02820"
"18109","108.61800","9.05172","0.02797"
"18152","108.87600","9.07312","0.02808"
"18195","109.13400","9.09471","0.02802"
"18238","109.39200","9.11617","0.02839"
"18281","109.65000","9.13775","0.02861"
"18324","109.90800","9.15916","0.02852"
"18367","110.16600","9.18068","0.02894"
"18410","110.42400","9.20221","0.02849"
"18453","110.68200","9.22367","0.02835"
"18496","110.94000","9.24514","0.02859"
"18539","111.19800","9.26672","0.02834"
"18582","111.45600","9.28818","0.02811"
"18625","111.71400","9.30965","0.02889"
"18668","111.97200","9.33123","0.02764"
"18711","112.23000","9.35270","0.02816"
"18754","112.48800","9.37422","0.02795"
"18797","112.74600","9.39569","0.02801"
"18840","113.00400","9.41721","0.02830"
"18883","113.26200","9.43873","0.02863"
"18926","113.52000","9.46020","0.02821"
"18969","113.77800","9.48166","0.02789"
"19012","114.03600","9.50325","0.02815"
"19055","114.29400","9.52465","0.02841"
"19098","114.55200","9.54624","0.02775"
"19141","114.81000","9.56764","0.02798"
"19184","115.06800","9.58922","0.02814"
"19227","115.32600","9.61069","0.02800"
"19270","115.58400","9.63221","0.02829"
"19313","115.84200","9.65368","0.02910"
"19356","116.10000","9.67520","0.02767"
"19399","116.35800","9.69673","0.02784"
"19442","116.61600","9.71825","0.02747"
"19485","116.87400","9.73971","0.02760"
"19528","117.13200","9.76124","0.02821"
"19571","117.39000","9.78264","0.02786"
"19614","117.64800","9.80417","0.02821"
"19657","117.90600","9.82569","0.02761"
"19700","118.16400","9.84722","0.02788"
"19743","118.42200","9.86868","0.02823"
"19786","118.68000","9.89020","0.02810"
"19829","118.93800","9.91167","0.02747"
"19872","119.19600","9.93319","0.02834"
"19915","119.45400","9.95472","0.02843"
"19958","119.71200","9.97618","0.02780"
"20001","119.97000","9.99771","0.02787"
"20044","120.22800","10.01911","0.02799"
"20087","120.48600","10.04070","0.02835"
"20130","120.74400","10.06216","0.02752"
"20173","121.00200","10.08374","0.02761"
"20216","121.26000","10.10515","0.02784"
"20259","121.51800","10.12667","0.02799"
"20302","121.77600","10.14814","0.02792"
"20345","122.03400","10.16972","0.02752"
"20388","122.29200","10.19118","0.02774"
"20431","122.55000","10.21271","0.02772"
"20474","122.80800","10.23423","0.02851"
"20517","123.06600","10.25570","0.02827"
"20560","123.32400","10.27722","0.02839"
"20603","123.58200","10.29875","0.02790"
"20646","123.84000","10.32015","0.02795"
"20689","124.09800","10.34174","0.02822"
"20732","124.35600","10.36320","0.02797"
"20775","124.61400","10.38466","0.02814"
"20818","124.87200","10.40625","0.02810"
"20861","125.13000","10.42771","0.02789"
"20904","125.38800","10.44924","0.02855"
"20947","125.64600","10.47064","0.02842"
"20990","125.90400","10.49223","0.02785"
"21033","126.16200","10.51369","0.02821"
"21076","126.42000","10.53522","0.02765"
"21119","126.67800","10.55668","0.02843"
"21162","126.93600","10.57820","0.02813"
"21205","127.19400","10.59961","0.02818"
"21248","127.45200","10.62125","0.02771"
"21291","127.71000","10.64266","0.02815"
"21334","127.96800","10.66424","0.02768"
"21377","128.22600","10.68565","0.02807"
"21420","128.48400","10.70723","0.02831"
"21463","128.74200","10.72869","0.02788"
"21506","129.00000","10.75022","0.02827"
"21549","129.25800","10.77168","0.02791"
"21592","129.51600","10.79321","0.02882"
"21635","129.77400","10.81467","0.02809"
"21678","130.03200","10.83626","0.02813"
"21721","130.29000","10.85766","0.02849"
"21764","130.54800","10.87918","0.02779"
"21807","130.80600","10.90071","0.02846"
"21850","131.06400","10.92223","0.02774"
"21893","131.32200","10.94370","0.02806"
"21936","131.58000","10.96522","0.02819"
"21979","131.83800","10.98675","0.02759"
"22022","132.09600","11.00821","0.02827"
"22065","132.35400","11.02967","0.02819"
"22108","132.61200","11.05114","0.02828"
"22151","132.87000","11.07266","0.02824"
"22194","133.12800","11.09413","0.02810"
"22237","133.38600","11.11571","0.02907"
"22280","133.64400","11.13718","0.02755"
"22323","133.90200","11.15870","0.02843"
"22366","134.16000","11.18010","0.02868"
"22409","134.41800","11.20175","0.02828"
"22452","134.67600","11.22315","0.02861"
"22495","134.93400","11.24474","0.02878"
"22538","135.19200","11.26614","0.02838"
"22581","135.45000","11.28773","0.02853"
"22624","135.70800","11.30919","0.02782"
"22667","135.96600","11.33071","0.02843"
"22710","136.22400","11.35218","0.02892"
"22753","136.48200","11.37370","0.02859"
"22796","136.74000","11.39517","0.02950"
"22839","136.99800","11.41669","0.02860"
"22882","137.25600","11.43822","0.02836"
"22925","137.51400","11.45974","0.02825"
"22968","137.77200","11.48127","0.02871"
"23011","138.03000","11.50267","0.02889"
"23054","138.28800","11.52425","0.02855"
"23097","138.54600","11.54566","0.02909"
"23140","138.80400","11.56724","0.02922"
"23183","139.06200","11.58865","0.02873"
"23226","139.32000","11.61023","0.02841"
"23269","139.57800","11.63164","0.02890"
"23312","139.83600","11.65316","0.02898"
"23355","140.09400","11.67468","0.02907"
"23398","140.35200","11.69621","0.02949"
"23441","140.61000","11.71767","0.02834"
"23484","140.86800","11.73920","0.02924"
"23527","141.12600","11.76066","0.02864"
"23570","141.38400","11.78225","0.02894"
"23613","141.64200","11.80371","0.02923"
"23656","141.90000","11.82517","0.02944"
"23699","142.15800","11.84664","0.02911"
"23742","142.41600","11.86822","0.02884"
"23785","142.67400","11.88969","0.02902"
"23828","142.93200","11.91121","0.02894"
"23871","143.19000","11.93267","0.02934"
"23914","143.44800","11.95420","0.02885"
"23957","143.70600","11.97572","0.02874"
"24000","143.96400","11.99725","0.02901"
"24043","144.22200","12.01871","0.02904"
"24086","144.48000","12.04012","0.02880"
"24129","144.73800","12.06176","0.02870"
"24172","144.99600","12.08317","0.02910"
"24215","145.25400","12.10469","0.02878"
"24258","145.51200","12.12615","0.02868"
"24301","145.77000","12.14768","0.02933"
"24344","146.02800","12.16914","0.02970"
"24387","146.28600","12.19073","0.02915"
"24430","146.54400","12.21219","0.02955"
"24473","146.80200","12.23372","0.02923"
"24516","147.06000","12.25524","0.02942"
"24559","147.31800","12.27670","0.02947"
"24602","147.57600","12.29817","0.02917"
"24645","147.83400","12.31975","0.02920"
"24688","148.09200","12.34122","0.02992"
"24731","148.35000","12.36274","0.02954"
"24774","148.60800","12.38421","0.02958"
"24817","148.86600","12.40567","0.02942"
"24860","149.12400","12.42719","0.02954"
"24903","149.38200","12.44872","0.02969"
"24946","149.64000","12.47018","0.02939"
"24989","149.89800","12.49165","0.02963"
"25032","150.15600","12.51317","0.02908"
"25075","150.41400","12.53470","0.02934"
"25118","150.67200","12.55622","0.02912"
"25161","150.93000","12.57768","0.02969"
"25204","151.18800","12.59927","0.02943"
"25247","151.44600","12.62067","0.02910"
"25290","151.70400","12.64220","0.02920"
"25333","151.96200","12.66360","0.02953"
"25376","152.22000","12.68519","0.02934"
"25419","152.47800","12.70665","0.02950"
"25462","152.73600","12.72824","0.02942"
"25505","152.99400","12.74964","0.02931"
"25548","153.25200","12.77116","0.03010"
"25591","153.51000","12.79263","0.02951"
"25634","153.76800","12.81421","0.02937"
"25677","154.02600","12.83568","0.02960"
"25720","154.28400","12.85720","0.03044"
"25763","154.54200","12.87866","0.02968"
"25806","154.80000","12.90019","0.02991"
"25849","155.05800","12.92171","0.02947"
"25892","155.31600","12.94318","0.02980"
"25935","155.57400","12.96470","0.02938"
"25978","155.83200","12.98623","0.02972"
"26021","156.09000","13.00769","0.03013"
"26064","156.34800","13.02916","0.02972"
"26107","156.60600","13.05068","0.02970"
"26150","156.86400","13.07220","0.03021"
"26193","157.12200","13.09373","0.03034"
"26236","157.38000","13.11513","0.02979"
"26279","157.63800","13.13672","0.03041"
"26322","157.89600","13.15824","0.03011"
"26365","158.15400","13.17971","0.02954"
"26408","158.41200","13.20111","0.02991"
"26451","158.67000","13.22269","0.02946"
"26494","158.92800","13.24416","0.02932"
"26537","159.18600","13.26574","0.02919"
"26580","159.44400","13.28721","0.02965"
"26623","159.70200","13.30867","0.02973"
"26666","159.96000","13.33020","0.02993"
"26709","160.21800","13.35172","0.02994"
"26752","160.47600","13.37319","0.02921"
"26795","160.73400","13.39471","0.02965"
"26838","160.99200","13.41617","0.02975"
"26881","161.25000","13.43770","0.02954"
"26924","161.50800","13.45916","0.02972"
"26967","161.76600","13.48075","0.02998"
"27010","162.02400","13.50221","0.03015"
"27053","162.28200","13.52367","0.03015"
"27096","162.54000","13.54520","0.02951"
"27139","162.79800","13.56666","0.03045"
"27182","163.05600","13.58825","0.03023"
"27225","163.31400","13.60965","0.03064"
"27268","163.57200","13.63118","0.02967"
"27311","163.83000","13.65270","0.03034"
"27354","164.08800","13.67423","0.03091"
"27397","164.34600","13.69569","0.03059"
"27440","164.60400","13.71721","0.03012"
"27483","164.86200","13.73862","0.03130"
"27526","165.12000","13.76014","0.03072"
"27569","165.37800","13.78167","0.03100"
"27612","165.63600","13.80325","0.03005"
"27655","165.89400","13.82472","0.03077"
"27698","166.15200","13.84618","0.03025"
"27741","166.41000","13.86770","0.03074"
"27784","166.66800","13.88923","0.03078"
"27827","166.92600","13.91069","0.03113"
"27870","167.18400","13.93222","0.03062"
"27913","167.44200","13.95362","0.03040"
"27956","167.70000","13.97520","0.03118"
"27999","167.95800","13.99667","0.03111"
"28042","168.21600","14.01819","0.03063"
"28085","168.47400","14.03966","0.03063"
"28128","168.73200","14.06118","0.03140"
"28171","168.99000","14.08271","0.03068"
"28214","169.24800","14.10423","0.03087"
"28257","169.50600","14.12576","0.03096"
"28300","169.76400","14.14716","0.03149"
"28343","170.02200","14.16868","0.03100"
"28386","170.28000","14.19009","0.03112"
"28429","170.53800","14.21173","0.03121"
"28472","170.79600","14.23314","0.03123"
"28515","171.05400","14.25472","0.03113"
"28558","171.31200","14.27613","0.03216"
"28601","171.57000","14.29771","0.03144"
"28644","171.82800","14.31911","0.03166"
"28687","172.08600","14.34070","0.03104"
"28730","172.34400","14.36216","0.03147"
"28773","172.60200","14.38369","0.03165"
"28816","172.86000","14.40515","0.03185"
"28859","173.11800","14.42674","0.03114"
"28902","173.37600","14.44820","0.03157"
"28945","173.63400","14.46972","0.03128"
"28988","173.89200","14.49119","0.03207"
"29031","174.15000","14.51271","0.03117"
"29074","174.40800","14.53424","0.03160"
"29117","174.66600","14.55576","0.03156"
"29160","174.92400","14.57723","0.03201"
"29203","175.18200","14.59869","0.03192"
"29246","175.44000","14.62021","0.03190"
"29289","175.69800","14.64168","0.03162"
"29332","175.95600","14.66320","0.03156"
"29375","176.21400","14.68467","0.03163"
"29418","176.47200","14.70619","0.03235"
"29461","176.73000","14.72766","0.03207"
"29504","176.98800","14.74924","0.03126"
"29547","177.24600","14.77065","0.03185"
"29590","177.50400","14.79217","0.03201"
"29633","177.76200","14.81363","0.03250"
"29676","178.02000","14.83522","0.03182"
"29719","178.27800","14.85668","0.03197"
"29762","178.53600","14.87827","0.03221"
"29805","178.79400","14.89967","0.03197"
"29848","179.05200","14.92120","0.03238"
"29891","179.31000","14.94266","0.03161"
"29934","179.56800","14.96418","0.03193"
"29977","179.82600","14.98565","0.03248"
"30020","180.08400","15.00717","0.03218"
"30063","180.34200","15.02864","0.03222"
"30106","180.60000","15.05022","0.03210"
"30149","180.85800","15.07169","0.03208"
"30192","181.11600","15.09321","0.03191"
"30235","181.37400","15.11468","0.03190"
"30278","181.63200","15.13614","0.03208"
"30321","181.89000","15.15772","0.03195"
"30364","182.14800","15.17919","0.03217"
"30407","182.40600","15.20071","0.03253"
"30450","182.66400","15.22212","0.03236"
"30493","182.92200","15.24370","0.03217"
"30536","183.18000","15.26517","0.03240"
"30579","183.43800","15.28669","0.03233"
"30622","183.69600","15.30815","0.03196"
"30665","183.95400","15.32968","0.03207"
"30708","184.21200","15.35114","0.03234"
"30751","184.47000","15.37273","0.03229"
"30794","184.72800","15.39419","0.03251"
"30837","184.98600","15.41572","0.03282"
"30880","185.24400","15.43712","0.03268"
"30923","185.50200","15.45870","0.03260"
"30966","185.76000","15.48017","0.03284"
"31009","186.01800","15.50175","0.03270"
"31052","186.27600","15.52316","0.03233"
"31095","186.53400","15.54468","0.03284"
"31138","186.79200","15.56614","0.03310"
"31181","187.05000","15.58773","0.03281"
"31224","187.30800","15.60919","0.03296"
"31267","187.56600","15.63072","0.03266"
"31310","187.82400","15.65218","0.03298"
"31353","188.08200","15.67371","0.03313"
"31396","188.34000","15.69517","0.03289"
"31439","188.59800","15.71669","0.03340"
"31482","188.85600","15.73822","0.03367"
"31525","189.11400","15.75962","0.03382"
"31568","189.37200","15.78121","0.03257"
"31611","189.63000","15.80267","0.03314"
"31654","189.88800","15.82426","0.03293"
"31697","190.14600","15.84566","0.03337"
"31740","190.40400","15.86718","0.03351"
"31783","190.66200","15.88865","0.03325"
"31826","190.92000","15.91023","0.03336"
"31869","191.17800","15.93170","0.03348"
"31912","191.43600","15.95322","0.03359"
"31955","191.69400","15.97469","0.03308"
"31998","191.95200","15.99621","0.03355"
"32041","192.21000","16.01768","0.03385"
"32084","192.46800","16.03926","0.03363"
"32127","192.72600","16.06066","0.03372"
"32170","192.98400","16.08219","0.03365"
"32213","193.24200","16.10365","0.03375"
"32256","193.50000","16.12518","0.03404"
"32299","193.75800","16.14670","0.03417"
"32342","194.01600","16.16823","0.03356"
"32385","194.27400","16.18969","0.03321"
"32428","194.53200","16.21121","0.03426"
"32471","194.79000","16.23268","0.03389"
"32514","195.04800","16.25420","0.03414"
"32557","195.30600","16.27573","0.03395"
"32600","195.56400","16.29713","0.03439"
"32643","195.82200","16.31878","0.03390"
"32686","196.08000","16.34018","0.03421"
"32729","196.33800","16.36170","0.03434"
"32772","196.59600","16.38317","0.03449"
"32815","196.85400","16.40469","0.03401"
"32858","197.11200","16.42616","0.03375"
"32901","197.37000","16.44774","0.03456"
"32944","197.62800","16.46921","0.03390"
"32987","197.88600","16.49067","0.03466"
"33030","198.14400","16.51213","0.03478"
"33073","198.40200","16.53372","0.03488"
"33116","198.66000","16.55518","0.03461"
"33159","198.91800","16.57671","0.03424"
"33202","199.17600","16.59817","0.03454"
"33245","199.43400","16.61970","0.03488"
"33288","199.69200","16.64116","0.03445"
"33331","199.95000","16.66269","0.03496"
"33374","200.20800","16.68421","0.03542"
"33417","200.46600","16.70567","0.03486"
"33460","200.72400","16.72726","0.03542"
"33503","200.98200","16.74872","0.03534"
"33546","201.24000","16.77019","0.03498"
"33589","201.49800","16.79171","0.03511"
"33632","201.75600","16.81318","0.03459"
"33675","202.01400","16.83464","0.03515"
"33718","202.27200","16.85622","0.03474"
"33761","202.53000","16.87769","0.03489"
"33804","202.78800","16.89921","0.03470"
"33847","203.04600","16.92062","0.03518"
"33890","203.30400","16.94214","0.03494"
"33933","203.56200","16.96367","0.03551"
"33976","203.82000","16.98525","0.03437"
"34019","204.07800","17.00665","0.03492"
"34062","204.33600","17.02824","0.03508"
"34105","204.59400","17.04964","0.03487"
"34148","204.85200","17.07129","0.03513"
"34191","205.11000","17.09275","0.03527"
"34234","205.36800","17.11422","0.03541"
"34277","205.62600","17.13568","0.03552"
"34320","205.88400","17.15714","0.03563"
"34363","206.14200","17.17873","0.03577"
"34406","206.40000","17.20019","0.03570"
"34449","206.65800","17.22172","0.03626"
"34492","206.91600","17.24318","0.03589"
"34535","207.17400","17.26471","0.03593"
"34578","207.43200","17.28617","0.03597"
"34621","207.69000","17.30770","0.03604"
"34664","207.94800","17.32916","0.03573"
"34707","208.20600","17.35068","0.03578"
"34750","208.46400","17.37215","0.03615"
"34793","208.72200","17.39373","0.03694"
"34836","208.98000","17.41520","0.03664"
"34879","209.23800","17.43672","0.03622"
"34922","209.49600","17.45812","0.03597"
"34965","209.75400","17.47971","0.03660"
"35008","210.01200","17.50117","0.03649"
"35051","210.27000","17.52276","0.03620"
"35094","210.52800","17.54416","0.03687"
"35137","210.78600","17.56569","0.03677"
"35180","211.04400","17.58715","0.03708"
"35223","211.30200","17.60874","0.03682"
"35266","211.56000","17.63020","0.03767"
"35309","211.81800","17.65172","0.03700"
"35352","212.07600","17.67325","0.03716"
"35395","212.33400","17.69471","0.03720"
"35438","212.59200","17.71624","0.03775"
"35481","212.85000","17.73776","0.03720"
"35524","213.10800","17.75922","0.03720"
"35567","213.36600","17.78069","0.03758"
"35610","213.62400","17.80221","0.03734"
"35653","213.88200","17.82368","0.03737"
"35696","214.14000","17.84520","0.03783"
"35739","214.39800","17.86667","0.03726"
"35782","214.65600","17.88819","0.03802"
"35825","214.91400","17.90965","0.03841"
"35868","215.17200","17.93124","0.03784"
"35911","215.43000","17.95271","0.03818"
"35954","215.68800","17.97423","0.03804"
"35997","215.94600","17.99563","0.03756"
"36040","216.20400","18.01722","0.03831"
"36083","216.46200","18.03868","0.03749"
"36126","216.72000","18.06021","0.03791"
"36169","216.97800","18.08167","0.03830"
"36212","217.23600","18.10319","0.03878"
"36255","217.49400","18.12472","0.03836"
"36298","217.75200","18.14618","0.03857"
"36341","218.01000","18.16771","0.03899"
"36384","218.26800","18.18923","0.03883"
"36427","218.52600","18.21064","0.03878"
"36470","218.78400","18.23222","0.03845"
"36513","219.04200","18.25368","0.03859"
"36556","219.30000","18.27515","0.03802"
"36599","219.55800","18.29667","0.03926"
"36642","219.81600","18.31820","0.03793"
"36685","220.07400","18.33978","0.03821"
"36728","220.33200","18.36119","0.03854"
"36771","220.59000","18.38271","0.03914"
"36814","220.84800","18.40412","0.03893"
"36857","221.10600","18.42570","0.03859"
"36900","221.36400","18.44716","0.03939"
"36943","221.62200","18.46869","0.03882"
"36986","221.88000","18.49015","0.03912"
"37029","222.13800","18.51174","0.03882"
"37072","222.39600","18.53314","0.03918"
"37115","222.65400","18.55473","0.03870"
"37158","222.91200","18.57619","0.03908"
"37201","223.17000","18.59772","0.03900"
"37244","223.42800","18.61918","0.03882"
"37287","223.68600","18.64070","0.03955"
"37330","223.94400","18.66217","0.03941"
"37373","224.20200","18.68375","0.03930"
"37416","224.46000","18.70522","0.03950"
"37459","224.71800","18.72668","0.03970"
"37502","224.97600","18.74820","0.03932"
"37545","225.23400","18.76967","0.04002"
"37588","225.49200","18.79119","0.03982"
"37631","225.75000","18.81272","0.03956"
"37674","226.00800","18.83418","0.03980"
"37717","226.26600","18.85565","0.04024"
"37760","226.52400","18.87723","0.03965"
"37803","226.78200","18.89869","0.04036"
"37846","227.04000","18.92022","0.03994"
"37889","227.29800","18.94168","0.04045"
"37932","227.55600","18.96321","0.04002"
"37975","227.81400","18.98467","0.04112"
"38018","228.07200","19.00626","0.04005"
"38061","228.33000","19.02766","0.04026"
"38104","228.58800","19.04918","0.04031"
"38147","228.84600","19.07065","0.04037"
"38190","229.10400","19.09223","0.04021"
"38233","229.36200","19.11370","0.03998"
"38276","229.62000","19.13522","0.04014"
"38319","229.87800","19.15669","0.03998"
"38362","230.13600","19.17821","0.04007"
"38405","230.39400","19.19967","0.04002"
"38448","230.65200","19.22126","0.04057"
"38491","230.91000","19.24266","0.04007"
"38534","231.16800","19.26419","0.04051"
"38577","231.42600","19.28565","0.04059"
"38620","231.68400","19.30718","0.04012"
"38663","231.94200","19.32870","0.04085"
"38706","232.20000","19.35017","0.04098"
"38749","232.45800","19.37175","0.04061"
"38792","232.71600","19.39321","0.04068"
"38835","232.97400","19.41474","0.04074"
"38878","233.23200","19.43614","0.04070"
"38921","233.49000","19.45773","0.04106"
"38964","233.74800","19.47913","0.04106"
"39007","234.00600","19.50072","0.04101"
"39050","234.26400","19.52218","0.04084"
"39093","234.52200","19.54370","0.04096"
"39136","234.78000","19.56517","0.04099"
"39179","235.03800","19.58669","0.04074"
"39222","235.29600","19.60822","0.04048"
"39265","235.55400","19.62974","0.04111"
"39308","235.81200","19.65121","0.04165"
"39351","236.07000","19.67273","0.04156"
"39394","236.32800","19.69419","0.04167"
"39437","236.58600","19.71572","0.04179"
"39480","236.84400","19.73718","0.04177"
"39523","237.10200","19.75871","0.04165"
"39566","237.36000","19.78023","0.04177"
"39609","237.61800","19.80169","0.04186"
"39652","237.87600","19.82316","0.04180"
"39695","238.13400","19.84468","0.04223"
"39738","238.39200","19.86627","0.04227"
"39781","238.65000","19.88767","0.04151"
"39824","238.90800","19.90920","0.04201"
"39867","239.16600","19.93066","0.04179"
"39910","239.42400","19.95225","0.04188"
"39953","239.68200","19.97371","0.04270"
"39996","239.94000","19.99524","0.04212"
"40039","240.19800","20.01664","0.04293"
"40082","240.45600","20.03828","0.04211"
"40125","240.71400","20.05969","0.04246"
"40168","240.97200","20.08121","0.04234"
"40211","241.23000","20.10267","0.04284"
"40254","241.48800","20.12414","0.04236"
"40297","241.74600","20.14566","0.04237"
"40340","242.00400","20.16719","0.04223"
"40383","242.26200","20.18871","0.04231"
"40426","242.52000","20.21024","0.04223"
"40469","242.77800","20.23170","0.04165"
"40512","243.03600","20.25317","0.04185"
"40555","243.29400","20.27469","0.04237"
"40598","243.55200","20.29621","0.04155"
"40641","243.81000","20.31768","0.04233"
"40684","244.06800","20.33920","0.04213"
"40727","244.32600","20.36073","0.04228"
"40770","244.58400","20.38219","0.04184"
"40813","244.84200","20.40372","0.04252"
"40856","245.10000","20.42518","0.04234"
"40899","245.35800","20.44676","0.04254"
"40942","245.61600","20.46823","0.04237"
"40985","245.87400","20.48969","0.04198"
"41028","246.13200","20.51116","0.04196"
"41071","246.39000","20.53268","0.04146"
"41114","246.64800","20.55415","0.04148"
"41157","246.90600","20.57573","0.04158"
"41200","247.16400","20.59719","0.04153"
"41243","247.42200","20.61872","0.04147"
"41286","247.68000","20.64012","0.04192"
"41329","247.93800","20.66177","0.04192"
"41372","248.19600","20.68317","0.04165"
"41415","248.45400","20.70476","0.04243"
"41458","248.71200","20.72622","0.04216"
"41501","248.97000","20.74769","0.04219"
"41544","249.22800","20.76915","0.04237"
"41587","249.48600","20.79073","0.04230"
"41630","249.74400","20.81220","0.04201"
"41673","250.00200","20.83372","0.04174"
"41716","250.26000","20.85518","0.04206"
"41759","250.51800","20.87665","0.04166"
"41802","250.77600","20.89824","0.04149"
"41845","251.03400","20.91970","0.04170"
"41888","251.29200","20.94122","0.04228"
"41931","251.55000","20.96269","0.04236"
"41974","251.80800","20.98421","0.04155"
"42017","252.06600","21.00567","0.04200"
"42060","252.32400","21.02726","0.04213"
"42103","252.58200","21.04866","0.04198"
"42146","252.84000","21.07019","0.04225"
"42189","253.09800","21.09166","0.04206"
"42232","253.35600","21.11324","0.04225"
"42275","253.61400","21.13470","0.04157"
"42318","253.87200","21.15617","0.04209"
"42361","254.13000","21.17763","0.04205"
"42404","254.38800","21.19921","0.04143"
"42447","254.64600","21.22068","0.04153"
"42490","254.90400","21.24226","0.04117"
"42533","255.16200","21.26367","0.04104"
"42576","255.42000","21.28526","0.04202"
"42619","255.67800","21.30672","0.04161"
"42662","255.93600","21.32824","0.03971"
"42705","256.19400","21.34971","0.03961"
"42748","256.45200","21.37123","0.03974"
"42791","256.71000","21.39270","0.03970"
"42834","256.96800","21.41416","0.04021"
"42877","257.22600","21.43568","0.03948"
"42920","257.48400","21.45715","0.03943"
"42963","257.74200","21.47873","0.03941"
"43006","258.00000","21.50014","0.04002"
"43049","258.25800","21.52172","0.04042"
"43092","258.51600","21.54313","0.04043"
"43135","258.77400","21.56477","0.04031"
"43178","259.03200","21.58617","0.03971"
"43221","259.29000","21.60764","0.04084"
"43264","259.54800","21.62916","0.04055"
"43307","259.80600","21.65075","0.04068"
"43350","260.06400","21.67221","0.04016"
"43393","260.32200","21.69374","0.04083"
"43436","260.58000","21.71514","0.04067"
"43479","260.83800","21.73672","0.04073"
"43522","261.09600","21.75819","0.04140"
"43565","261.35400","21.77971","0.04068"
"43608","261.61200","21.80118","0.04057"
"43651","261.87000","21.82270","0.04125"
"43694","262.12800","21.84416","0.04135"
"43737","262.38600","21.86569","0.04107"
"43780","262.64400","21.88721","0.04096"
"43823","262.90200","21.90874","0.04176"
"43866","263.16000","21.93020","0.04100"
"43909","263.41800","21.95173","0.04090"
"43952","263.67600","21.97319","0.04176"
"43995","263.93400","21.99471","0.04099"
"44038","264.19200","22.01624","0.04152"
"44081","264.45000","22.03765","0.04142"
"44124","264.70800","22.05923","0.04127"
"44167","264.96600","22.08063","0.04159"
"44210","265.22400","22.10222","0.04101"
"44253","265.48200","22.12362","0.04107"
"44296","265.74000","22.14520","0.04165"
"44339","265.99800","22.16667","0.04138"
"44382","266.25600","22.18819","0.04194"
"44425","266.51400","22.20966","0.04115"
"44468","266.77200","22.23124","0.04148"
"44511","267.03000","22.25265","0.04175"
"44554","267.28800","22.27423","0.04184"
"44597","267.54600","22.29570","0.04165"
"44640","267.80400","22.31728","0.04243"
"44683","268.06200","22.33868","0.04218"
"44726","268.32000","22.36021","0.04206"
"44769","268.57800","22.38167","0.04194"
"44812","268.83600","22.40320","0.04197"
"44855","269.09400","22.42472","0.04189"
"44898","269.35200","22.44619","0.04195"
"44941","269.61000","22.46771","0.04257"
"44984","269.86800","22.48918","0.04222"
"45027","270.12600","22.51070","0.04215"
"45070","270.38400","22.53222","0.04249"
"45113","270.64200","22.55375","0.04181"
"45156","270.90000","22.57515","0.04215"
"45199","271.15800","22.59674","0.04182"
"45242","271.41600","22.61820","0.04216"
"45285","271.67400","22.63972","0.04219"
"45328","271.93200","22.66113","0.04238"
"45371","272.19000","22.68271","0.04224"
"45414","272.44800","22.70418","0.04233"
"45457","272.70600","22.72570","0.04166"
"45500","272.96400","22.74717","0.04269"
"45543","273.22200","22.76869","0.04232"
"45586","273.48000","22.79015","0.04213"
"45629","273.73800","22.81174","0.04234"
"45672","273.99600","22.83315","0.04274"
"45715","274.25400","22.85473","0.04228"
"45758","274.51200","22.87619","0.04211"
"45801","274.77000","22.89766","0.04217"
"45844","275.02800","22.91918","0.04187"
"45887","275.28600","22.94071","0.04171"
"45930","275.54400","22.96223","0.04088"
"45973","275.80200","22.98369","0.04160"
"46016","276.06000","23.00522","0.04149"
"46059","276.31800","23.02668","0.04198"
"46102","276.57600","23.04820","0.04169"
"46145","276.83400","23.06967","0.04203"
"46188","277.09200","23.09120","0.04201"
"46231","277.35000","23.11260","0.04236"
"46274","277.60800","23.13419","0.04220"
"46317","277.86600","23.15571","0.04239"
"46360","278.12400","23.17723","0.04217"
"46403","278.38200","23.19870","0.04201"
"46446","278.64000","23.22016","0.04238"
"46489","278.89800","23.24169","0.04224"
"46532","279.15600","23.26327","0.04243"
"46575","279.41400","23.28468","0.04312"
"46618","279.67200","23.30620","0.04226"
"46661","279.93000","23.32760","0.04293"
"46704","280.18800","23.34925","0.04270"
"46747","280.44600","23.37071","0.04221"
"46790","280.70400","23.39224","0.04242"
"46833","280.96200","23.41364","0.04215"
"46876","281.22000","23.43523","0.04243"
"46919","281.47800","23.45675","0.04236"
"46962","281.73600","23.47821","0.04228"
"47005","281.99400","23.49968","0.04258"
"47048","282.25200","23.52114","0.04242"
"47091","282.51000","23.54273","0.04263"
"47134","282.76800","23.56419","0.04227"
"47177","283.02600","23.58572","0.04287"
"47220","283.28400","23.60718","0.04344"
"47263","283.54200","23.62870","0.04261"
"47306","283.80000","23.65017","0.04228"
"47349","284.05800","23.67169","0.04237"
"47392","284.31600","23.69316","0.04187"
"47435","284.57400","23.71468","0.04206"
"47478","284.83200","23.73615","0.04167"
"47521","285.09000","23.75767","0.04189"
"47564","285.34800","23.77913","0.04178"
"47607","285.60600","23.80072","0.04202"
"47650","285.86400","23.82218","0.04227"
"47693","286.12200","23.84371","0.04184"
"47736","286.38000","23.86517","0.04265"
"47779","286.63800","23.88676","0.04285"
"47822","286.89600","23.90822","0.04264"
"47865","287.15400","23.92974","0.04299"
"47908","287.41200","23.95115","0.04246"
"47951","287.67000","23.97267","0.04284"
"47994","287.92800","23.99414","0.04261"
"48037","288.18600","24.01572","0.04310"
"48080","288.44400","24.03718","0.04238"
"48123","288.70200","24.05865","0.04263"
"48166","288.96000","24.08024","0.04227"
"48209","289.21800","24.10170","0.04320"
"48252","289.47600","24.12322","0.04250"
"48295","289.73400","24.14463","0.04254"
"48338","289.99200","24.16621","0.04297"
"48381","290.25000","24.18762","0.04306"
"48424","290.50800","24.20926","0.04361"
"48467","290.76600","24.23067","0.04326"
"48510","291.02400","24.25225","0.04313"
"48553","291.28200","24.27365","0.04321"
"48596","291.54000","24.29524","0.04330"
"48639","291.79800","24.31664","0.04325"
"48682","292.05600","24.33822","0.04252"
"48725","292.31400","24.35963","0.04240"
"48768","292.57200","24.38121","0.04317"
"48811","292.83000","24.40268","0.04323"
"48854","293.08800","24.42420","0.04257"
"48897","293.34600","24.44573","0.04350"
"48940","293.60400","24.46719","0.04311"
"48983","293.86200","24.48866","0.04314"
"49026","294.12000","24.51018","0.04233"
"49069","294.37800","24.53176","0.04286"
"49112","294.63600","24.55323","0.04291"
"49155","294.89400","24.57470","0.04190"
"49198","295.15200","24.59616","0.04110"
"49241","295.41000","24.61774","0.04063"
"49284","295.66800","24.63921","0.04049"
"49327","295.92600","24.66067","0.04144"
"49370","296.18400","24.68213","0.04122"
"49413","296.44200","24.70366","0.04065"
"49456","296.70000","24.72518","0.04042"
"49499","296.95800","24.74671","0.04017"
"49542","297.21600","24.76811","0.04034"
"49585","297.47400","24.78970","0.04120"
"49628","297.73200","24.81122","0.04077"
"49671","297.99000","24.83269","0.04098"
"49714","298.24800","24.85415","0.04064"
"49757","298.50600","24.87579","0.04059"
"49800","298.76400","24.89714","0.04115"
"49843","299.02200","24.91872","0.04143"
"49886","299.28000","24.94019","0.04098"
"49929","299.53800","24.96171","0.04086"
"49972","299.79600","24.98323","0.04085"
"50015","300.05400","25.00464","0.04123"
"50058","300.31200","25.02617","0.04132"
"50101","300.57000","25.04769","0.04108"
"50144","300.82800","25.06921","0.04075"
"50187","301.08600","25.09068","0.04117"
"50230","301.34400","25.11220","0.04103"
"50273","301.60200","25.13367","0.04146"
"50316","301.86000","25.15525","0.04135"
"50359","302.11800","25.17671","0.04129"
"50402","302.37600","25.19824","0.04103"
"50445","302.63400","25.21964","0.04120"
"50488","302.89200","25.24117","0.04097"
"50531","303.15000","25.26269","0.04107"
"50574","303.40800","25.28422","0.04095"
"50617","303.66600","25.30568","0.04070"
"50660","303.92400","25.32721","0.04093"
"50703","304.18200","25.34867","0.04102"
"50746","304.44000","25.37025","0.04129"
"50789","304.69800","25.39166","0.04181"
"50832","304.95600","25.41318","0.04109"
"50875","305.21400","25.43465","0.04094"
"50918","305.47200","25.45617","0.04180"
"50961","305.73000","25.47770","0.04117"
"51004","305.98800","25.49928","0.04155"
"51047","306.24600","25.52074","0.04101"
"51090","306.50400","25.54221","0.04157"
"51133","306.76200","25.56367","0.04106"
"51176","307.02000","25.58520","0.04146"
"51219","307.27800","25.60672","0.04177"
"51262","307.53600","25.62819","0.04140"
"51305","307.79400","25.64971","0.04199"
"51348","308.05200","25.67112","0.04183"
"51391","308.31000","25.69270","0.04140"
"51434","308.56800","25.71416","0.04118"
"51477","308.82600","25.73575","0.04075"
"51520","309.08400","25.75715","0.04174"
"51563","309.34200","25.77874","0.04118"
"51606","309.60000","25.80014","0.04115"
"51649","309.85800","25.82172","0.04170"
"51692","310.11600","25.84319","0.04128"
"51735","310.37400","25.86465","0.04165"
"51778","310.63200","25.88624","0.04184"
"51821","310.89000","25.90770","0.04092"
"51864","311.14800","25.92917","0.04195"
"51907","311.40600","25.95075","0.04186"
"51950","311.66400","25.97216","0.04104"
"51993","311.92200","25.99368","0.04194"
"52036","312.18000","26.01520","0.04116"
"52079","312.43800","26.03673","0.04119"
"52122","312.69600","26.05819","0.04189"
"52165","312.95400","26.07966","0.04193"
"52208","313.21200","26.10118","0.04157"
"52251","313.47000","26.12265","0.04159"
"52294","313.72800","26.14417","0.04149"
"52337","313.98600","26.16569","0.04186"
"52380","314.24400","26.18722","0.04176"
"52423","314.50200","26.20868","0.04164"
"52450","314.66400","26.22219","0.04139"