File: Trajectories_together/170226_2Specimen_RawData_2.csv
"","V1","V2","V3"
"1","End date","2/26/2017",""
"2","Specimen label","7BT_54",""
"3","Maximum Load","0.12958","N"
"4","Time","Extension","Load"
"5","(s)","(mm)","(N)"
"6","0.00000","0.00000","-0.00057"
"30","0.14400","0.00795","-0.00005"
"54","0.28800","0.02332","-0.00030"
"78","0.43200","0.03623","-0.00056"
"102","0.57600","0.04825","-0.00059"
"126","0.72000","0.06021","0.00043"
"150","0.86400","0.07223","0.00044"
"174","1.00800","0.08412","-0.00048"
"198","1.15200","0.09626","0.00012"
"222","1.29600","0.10822","-0.00016"
"246","1.44000","0.12018","-0.00032"
"270","1.58400","0.13213","0.00010"
"294","1.72800","0.14421","0.00012"
"318","1.87200","0.15617","0.00017"
"342","2.01600","0.16819","-0.00013"
"366","2.16000","0.18015","0.00009"
"390","2.30400","0.19222","-0.00032"
"414","2.44800","0.20418","-0.00008"
"438","2.59200","0.21614","0.00031"
"462","2.73600","0.22816","-0.00017"
"486","2.88000","0.24017","0.00031"
"510","3.02400","0.25213","0.00007"
"534","3.16800","0.26409","0.00050"
"558","3.31200","0.27617","0.00019"
"582","3.45600","0.28819","-0.00002"
"606","3.60000","0.30014","0.00032"
"630","3.74400","0.31216","0.00047"
"654","3.88800","0.32418","0.00065"
"678","4.03200","0.33620","-0.00005"
"702","4.17600","0.34815","0.00045"
"726","4.32000","0.36017","0.00087"
"750","4.46400","0.37219","0.00032"
"774","4.60800","0.38421","0.00061"
"798","4.75200","0.39611","0.00030"
"822","4.89600","0.40818","0.00066"
"846","5.04000","0.42020","0.00025"
"870","5.18400","0.43216","0.00114"
"894","5.32800","0.44418","0.00163"
"918","5.47200","0.45619","0.00051"
"942","5.61600","0.46821","0.00066"
"966","5.76000","0.48017","0.00005"
"990","5.90400","0.49213","0.00114"
"1014","6.04800","0.50421","0.00040"
"1038","6.19200","0.51616","0.00113"
"1062","6.33600","0.52812","0.00080"
"1086","6.48000","0.54020","0.00086"
"1110","6.62400","0.55222","0.00043"
"1134","6.76800","0.56417","0.00058"
"1158","6.91200","0.57613","0.00153"
"1182","7.05600","0.58821","0.00075"
"1206","7.20000","0.60023","0.00112"
"1230","7.34400","0.61219","0.00084"
"1254","7.48800","0.62414","0.00083"
"1278","7.63200","0.63622","0.00075"
"1302","7.77600","0.64824","0.00090"
"1326","7.92000","0.66014","0.00149"
"1350","8.06400","0.67215","0.00085"
"1374","8.20800","0.68417","0.00116"
"1398","8.35200","0.69619","0.00071"
"1422","8.49600","0.70815","0.00145"
"1446","8.64000","0.72016","0.00079"
"1470","8.78400","0.73218","0.00160"
"1494","8.92800","0.74420","0.00097"
"1518","9.07200","0.75616","0.00143"
"1542","9.21600","0.76824","0.00193"
"1566","9.36000","0.78025","0.00096"
"1590","9.50400","0.79221","0.00141"
"1614","9.64800","0.80411","0.00230"
"1638","9.79200","0.81619","0.00208"
"1662","9.93600","0.82820","0.00177"
"1686","10.08000","0.84016","0.00151"
"1710","10.22400","0.85218","0.00058"
"1734","10.36800","0.86426","0.00006"
"1758","10.51200","0.87622","0.00086"
"1782","10.65600","0.88817","0.00151"
"1806","10.80000","0.90019","0.00140"
"1830","10.94400","0.91221","0.00121"
"1854","11.08800","0.92417","-0.00017"
"1878","11.23200","0.93618","0.00014"
"1902","11.37600","0.94820","0.00041"
"1926","11.52000","0.96022","0.00158"
"1950","11.66400","0.97218","0.00106"
"1974","11.80800","0.98420","0.00107"
"1998","11.95200","0.99621","0.00028"
"2022","12.09600","1.00817","0.00038"
"2046","12.24000","1.02013","0.00143"
"2070","12.38400","1.03221","0.00197"
"2094","12.52800","1.04422","0.00058"
"2118","12.67200","1.05624","0.00049"
"2142","12.81600","1.06820","0.00043"
"2166","12.96000","1.08022","0.00150"
"2190","13.10400","1.09218","0.00204"
"2214","13.24800","1.10419","0.00112"
"2238","13.39200","1.11615","0.00150"
"2262","13.53600","1.12823","0.00111"
"2286","13.68000","1.14019","0.00112"
"2310","13.82400","1.15220","0.00107"
"2334","13.96800","1.16416","0.00142"
"2358","14.11200","1.17624","0.00143"
"2382","14.25600","1.18820","0.00119"
"2406","14.40000","1.20016","0.00131"
"2430","14.54400","1.21217","0.00149"
"2454","14.68800","1.22425","0.00239"
"2478","14.83200","1.23621","0.00164"
"2502","14.97600","1.24811","0.00135"
"2526","15.12000","1.26024","0.00105"
"2550","15.26400","1.27220","0.00164"
"2574","15.40800","1.28416","0.00187"
"2598","15.55200","1.29618","0.00202"
"2622","15.69600","1.30820","0.00170"
"2646","15.84000","1.32021","0.00091"
"2670","15.98400","1.33211","0.00261"
"2694","16.12800","1.34413","0.00164"
"2718","16.27200","1.35621","0.00181"
"2742","16.41600","1.36822","0.00175"
"2766","16.56000","1.38012","0.00200"
"2790","16.70400","1.39220","0.00209"
"2814","16.84800","1.40422","0.00216"
"2838","16.99200","1.41617","0.00216"
"2862","17.13600","1.42813","0.00231"
"2886","17.28000","1.44015","0.00169"
"2910","17.42400","1.45223","0.00241"
"2934","17.56800","1.46413","0.00251"
"2958","17.71200","1.47614","0.00218"
"2982","17.85600","1.48822","0.00232"
"3006","18.00000","1.50024","0.00262"
"3030","18.14400","1.51214","0.00242"
"3054","18.28800","1.52415","0.00284"
"3078","18.43200","1.53617","0.00249"
"3102","18.57600","1.54825","0.00255"
"3126","18.72000","1.56015","0.00248"
"3150","18.86400","1.57217","0.00222"
"3174","19.00800","1.58418","0.00257"
"3198","19.15200","1.59620","0.00219"
"3222","19.29600","1.60816","0.00278"
"3246","19.44000","1.62018","0.00293"
"3270","19.58400","1.63219","0.00273"
"3294","19.72800","1.64415","0.00257"
"3318","19.87200","1.65617","0.00319"
"3342","20.01600","1.66819","0.00327"
"3366","20.16000","1.68015","0.00309"
"3390","20.30400","1.69216","0.00310"
"3414","20.44800","1.70418","0.00362"
"3438","20.59200","1.71614","0.00282"
"3462","20.73600","1.72816","0.00280"
"3486","20.88000","1.74011","0.00329"
"3510","21.02400","1.75213","0.00209"
"3534","21.16800","1.76415","0.00237"
"3558","21.31200","1.77617","0.00257"
"3582","21.45600","1.78813","0.00331"
"3606","21.60000","1.80020","0.00274"
"3630","21.74400","1.81216","0.00244"
"3654","21.88800","1.82418","0.00268"
"3678","22.03200","1.83614","0.00326"
"3702","22.17600","1.84821","0.00270"
"3726","22.32000","1.86017","0.00268"
"3750","22.46400","1.87213","0.00363"
"3774","22.60800","1.88421","0.00317"
"3798","22.75200","1.89617","0.00320"
"3822","22.89600","1.90818","0.00348"
"3846","23.04000","1.92008","0.00273"
"3870","23.18400","1.93222","0.00303"
"3894","23.32800","1.94418","0.00262"
"3918","23.47200","1.95619","0.00303"
"3942","23.61600","1.96809","0.00303"
"3966","23.76000","1.98023","0.00339"
"3990","23.90400","1.99219","0.00311"
"4014","24.04800","2.00415","0.00380"
"4038","24.19200","2.01616","0.00348"
"4062","24.33600","2.02818","0.00354"
"4086","24.48000","2.04020","0.00394"
"4110","24.62400","2.05210","0.00379"
"4134","24.76800","2.06417","0.00375"
"4158","24.91200","2.07619","0.00374"
"4182","25.05600","2.08821","0.00361"
"4206","25.20000","2.10017","0.00409"
"4230","25.34400","2.11219","0.00403"
"4254","25.48800","2.12420","0.00395"
"4278","25.63200","2.13616","0.00408"
"4302","25.77600","2.14812","0.00391"
"4326","25.92000","2.16020","0.00416"
"4350","26.06400","2.17221","0.00413"
"4374","26.20800","2.18411","0.00408"
"4398","26.35200","2.19613","0.00394"
"4422","26.49600","2.20815","0.00431"
"4446","26.64000","2.22022","0.00420"
"4470","26.78400","2.23218","0.00468"
"4494","26.92800","2.24414","0.00424"
"4518","27.07200","2.25616","0.00480"
"4542","27.21600","2.26818","0.00493"
"4566","27.36000","2.28013","0.00497"
"4590","27.50400","2.29215","0.00529"
"4614","27.64800","2.30417","0.00507"
"4638","27.79200","2.31613","0.00480"
"4662","27.93600","2.32814","0.00519"
"4686","28.08000","2.34016","0.00527"
"4710","28.22400","2.35218","0.00531"
"4734","28.36800","2.36414","0.00523"
"4758","28.51200","2.37616","0.00533"
"4782","28.65600","2.38817","0.00587"
"4806","28.80000","2.40019","0.00592"
"4830","28.94400","2.41209","0.00604"
"4854","29.08800","2.42417","0.00589"
"4878","29.23200","2.43618","0.00588"
"4902","29.37600","2.44814","0.00605"
"4926","29.52000","2.46016","0.00638"
"4950","29.66400","2.47218","0.00622"
"4974","29.80800","2.48420","0.00609"
"4998","29.95200","2.49615","0.00618"
"5022","30.09600","2.50811","0.00632"
"5046","30.24000","2.52019","0.00694"
"5070","30.38400","2.53221","0.00711"
"5094","30.52800","2.54416","0.00616"
"5118","30.67200","2.55618","0.00691"
"5142","30.81600","2.56820","0.00686"
"5166","30.96000","2.58016","0.00770"
"5190","31.10400","2.59212","0.00750"
"5214","31.24800","2.60419","0.00690"
"5238","31.39200","2.61615","0.00687"
"5262","31.53600","2.62817","0.00693"
"5286","31.68000","2.64007","0.00712"
"5310","31.82400","2.65220","0.00730"
"5334","31.96800","2.66416","0.00701"
"5358","32.11200","2.67618","0.00747"
"5382","32.25600","2.68808","0.00842"
"5406","32.40000","2.70021","0.00848"
"5430","32.54400","2.71217","0.00772"
"5454","32.68800","2.72419","0.00816"
"5478","32.83200","2.73621","0.00801"
"5502","32.97600","2.74823","0.00874"
"5526","33.12000","2.76018","0.00880"
"5550","33.26400","2.77214","0.00811"
"5574","33.40800","2.78416","0.00895"
"5598","33.55200","2.79618","0.00922"
"5622","33.69600","2.80814","0.00840"
"5646","33.84000","2.82009","0.00895"
"5670","33.98400","2.83217","0.00970"
"5694","34.12800","2.84419","0.00885"
"5718","34.27200","2.85615","0.00952"
"5742","34.41600","2.86810","0.00927"
"5766","34.56000","2.88012","0.00949"
"5790","34.70400","2.89214","0.00938"
"5814","34.84800","2.90416","0.01085"
"5838","34.99200","2.91612","0.00990"
"5862","35.13600","2.92813","0.00995"
"5886","35.28000","2.94015","0.00996"
"5910","35.42400","2.95211","0.01050"
"5934","35.56800","2.96419","0.00988"
"5958","35.71200","2.97614","0.01030"
"5982","35.85600","2.98816","0.01050"
"6006","36.00000","3.00012","0.01094"
"6030","36.14400","3.01220","0.01130"
"6054","36.28800","3.02421","0.01069"
"6078","36.43200","3.03617","0.01144"
"6102","36.57600","3.04813","0.01138"
"6126","36.72000","3.06015","0.01174"
"6150","36.86400","3.07217","0.01192"
"6174","37.00800","3.08412","0.01189"
"6198","37.15200","3.09614","0.01243"
"6222","37.29600","3.10816","0.01181"
"6246","37.44000","3.12012","0.01231"
"6270","37.58400","3.13207","0.01223"
"6294","37.72800","3.14415","0.01124"
"6318","37.87200","3.15617","0.01148"
"6342","38.01600","3.16813","0.01175"
"6366","38.16000","3.18015","0.01222"
"6390","38.30400","3.19216","0.01172"
"6414","38.44800","3.20418","0.01231"
"6438","38.59200","3.21614","0.01303"
"6462","38.73600","3.22816","0.01162"
"6486","38.88000","3.24017","0.01281"
"6510","39.02400","3.25219","0.01287"
"6534","39.16800","3.26409","0.01271"
"6558","39.31200","3.27617","0.01286"
"6582","39.45600","3.28813","0.01300"
"6606","39.60000","3.30014","0.01318"
"6630","39.74400","3.31210","0.01279"
"6654","39.88800","3.32418","0.01330"
"6678","40.03200","3.33620","0.01336"
"6702","40.17600","3.34815","0.01384"
"6726","40.32000","3.36017","0.01386"
"6750","40.46400","3.37219","0.01381"
"6774","40.60800","3.38421","0.01399"
"6798","40.75200","3.39617","0.01460"
"6822","40.89600","3.40812","0.01547"
"6846","41.04000","3.42020","0.01555"
"6870","41.18400","3.43216","0.01505"
"6894","41.32800","3.44412","0.01570"
"6918","41.47200","3.45613","0.01495"
"6942","41.61600","3.46815","0.01537"
"6966","41.76000","3.48017","0.01598"
"6990","41.90400","3.49213","0.01639"
"7014","42.04800","3.50415","0.01591"
"7038","42.19200","3.51616","0.01636"
"7062","42.33600","3.52818","0.01639"
"7086","42.48000","3.54014","0.01662"
"7110","42.62400","3.55222","0.01729"
"7134","42.76800","3.56423","0.01739"
"7158","42.91200","3.57613","0.01755"
"7182","43.05600","3.58815","0.01756"
"7206","43.20000","3.60017","0.01786"
"7230","43.34400","3.61218","0.01846"
"7254","43.48800","3.62414","0.01795"
"7278","43.63200","3.63616","0.01853"
"7302","43.77600","3.64818","0.01878"
"7326","43.92000","3.66020","0.01890"
"7350","44.06400","3.67215","0.01870"
"7374","44.20800","3.68423","0.01934"
"7398","44.35200","3.69619","0.01929"
"7422","44.49600","3.70815","0.01929"
"7446","44.64000","3.72016","0.01984"
"7470","44.78400","3.73224","0.02044"
"7494","44.92800","3.74414","0.02052"
"7518","45.07200","3.75616","0.02056"
"7542","45.21600","3.76818","0.02137"
"7566","45.36000","3.78019","0.02100"
"7590","45.50400","3.79221","0.02082"
"7614","45.64800","3.80417","0.02117"
"7638","45.79200","3.81625","0.02170"
"7662","45.93600","3.82820","0.02172"
"7686","46.08000","3.84016","0.02182"
"7710","46.22400","3.85212","0.02184"
"7734","46.36800","3.86420","0.02224"
"7758","46.51200","3.87616","0.02236"
"7782","46.65600","3.88811","0.02344"
"7806","46.80000","3.90019","0.02303"
"7830","46.94400","3.91221","0.02358"
"7854","47.08800","3.92417","0.02357"
"7878","47.23200","3.93612","0.02356"
"7902","47.37600","3.94820","0.02401"
"7926","47.52000","3.96022","0.02404"
"7950","47.66400","3.97218","0.02429"
"7974","47.80800","3.98414","0.02459"
"7998","47.95200","3.99627","0.02475"
"8022","48.09600","4.00823","0.02464"
"8046","48.24000","4.02019","0.02565"
"8070","48.38400","4.03215","0.02521"
"8094","48.52800","4.04422","0.02581"
"8118","48.67200","4.05618","0.02526"
"8142","48.81600","4.06814","0.02557"
"8166","48.96000","4.08022","0.02616"
"8190","49.10400","4.09223","0.02619"
"8214","49.24800","4.10419","0.02653"
"8238","49.39200","4.11609","0.02695"
"8262","49.53600","4.12817","0.02634"
"8286","49.68000","4.14019","0.02727"
"8310","49.82400","4.15214","0.02696"
"8334","49.96800","4.16416","0.02763"
"8358","50.11200","4.17618","0.02762"
"8382","50.25600","4.18820","0.02749"
"8406","50.40000","4.20015","0.02796"
"8430","50.54400","4.21217","0.02801"
"8454","50.68800","4.22425","0.02783"
"8478","50.83200","4.23627","0.02877"
"8502","50.97600","4.24817","0.02896"
"8526","51.12000","4.26018","0.02885"
"8550","51.26400","4.27220","0.02961"
"8574","51.40800","4.28422","0.02986"
"8598","51.55200","4.29618","0.03011"
"8622","51.69600","4.30819","0.03036"
"8646","51.84000","4.32021","0.03083"
"8670","51.98400","4.33217","0.03087"
"8694","52.12800","4.34419","0.03092"
"8718","52.27200","4.35621","0.03130"
"8742","52.41600","4.36822","0.03164"
"8766","52.56000","4.38018","0.03192"
"8790","52.70400","4.39220","0.03183"
"8814","52.84800","4.40428","0.02910"
"8838","52.99200","4.41623","0.02703"
"8862","53.13600","4.42819","0.02683"
"8886","53.28000","4.44015","0.02686"
"8910","53.42400","4.45217","0.02641"
"8934","53.56800","4.46413","0.02462"
"8958","53.71200","4.47608","0.02723"
"8982","53.85600","4.48816","0.02788"
"9006","54.00000","4.50018","0.02852"
"9030","54.14400","4.51220","0.02825"
"9054","54.28800","4.52415","0.02915"
"9078","54.43200","4.53623","0.02939"
"9102","54.57600","4.54819","0.02934"
"9126","54.72000","4.56015","0.02887"
"9150","54.86400","4.57217","0.02949"
"9174","55.00800","4.58418","0.03002"
"9198","55.15200","4.59620","0.02959"
"9222","55.29600","4.60816","0.03011"
"9246","55.44000","4.62018","0.03057"
"9270","55.58400","4.63219","0.03000"
"9294","55.72800","4.64421","0.03063"
"9318","55.87200","4.65617","0.03182"
"9342","56.01600","4.66825","0.03205"
"9366","56.16000","4.68021","0.03184"
"9390","56.30400","4.69216","0.03210"
"9414","56.44800","4.70418","0.03287"
"9438","56.59200","4.71626","0.03232"
"9462","56.73600","4.72822","0.03267"
"9486","56.88000","4.74017","0.03287"
"9510","57.02400","4.75219","0.03325"
"9534","57.16800","4.76421","0.03391"
"9558","57.31200","4.77617","0.03410"
"9582","57.45600","4.78813","0.03400"
"9606","57.60000","4.80020","0.03472"
"9630","57.74400","4.81222","0.03495"
"9654","57.88800","4.82418","0.03442"
"9678","58.03200","4.83614","0.03474"
"9702","58.17600","4.84827","0.03563"
"9726","58.32000","4.86023","0.03575"
"9750","58.46400","4.87219","0.03567"
"9774","58.60800","4.88421","0.03645"
"9798","58.75200","4.89622","0.03604"
"9822","58.89600","4.90818","0.03635"
"9846","59.04000","4.92014","0.03635"
"9870","59.18400","4.93216","0.03688"
"9894","59.32800","4.94418","0.03652"
"9918","59.47200","4.95619","0.03667"
"9942","59.61600","4.96809","0.03721"
"9966","59.76000","4.98023","0.03718"
"9990","59.90400","4.99225","0.03786"
"10014","60.04800","5.00414","0.03805"
"10038","60.19200","5.01616","0.03825"
"10062","60.33600","5.02818","0.03868"
"10086","60.48000","5.04020","0.03857"
"10110","60.62400","5.05210","0.03849"
"10134","60.76800","5.06417","0.03878"
"10158","60.91200","5.07619","0.03921"
"10182","61.05600","5.08821","0.03872"
"10206","61.20000","5.10017","0.03933"
"10230","61.34400","5.11212","0.03997"
"10254","61.48800","5.12414","0.04020"
"10278","61.63200","5.13616","0.03988"
"10302","61.77600","5.14812","0.04064"
"10326","61.92000","5.16020","0.04075"
"10350","62.06400","5.17215","0.04031"
"10374","62.20800","5.18417","0.04072"
"10398","62.35200","5.19613","0.04106"
"10422","62.49600","5.20815","0.04099"
"10446","62.64000","5.22016","0.04143"
"10470","62.78400","5.23212","0.04167"
"10494","62.92800","5.24414","0.04175"
"10518","63.07200","5.25622","0.04186"
"10542","63.21600","5.26818","0.04239"
"10566","63.36000","5.28013","0.04242"
"10590","63.50400","5.29221","0.04289"
"10614","63.64800","5.30417","0.04293"
"10638","63.79200","5.31619","0.04290"
"10662","63.93600","5.32814","0.04336"
"10686","64.08000","5.34022","0.04324"
"10710","64.22400","5.35218","0.04374"
"10734","64.36800","5.36414","0.04387"
"10758","64.51200","5.37609","0.04422"
"10782","64.65600","5.38823","0.04432"
"10806","64.80000","5.40025","0.04453"
"10830","64.94400","5.41221","0.04478"
"10854","65.08800","5.42417","0.04482"
"10878","65.23200","5.43624","0.04515"
"10902","65.37600","5.44820","0.04507"
"10926","65.52000","5.46010","0.04532"
"10950","65.66400","5.47218","0.04603"
"10974","65.80800","5.48414","0.04596"
"10998","65.95200","5.49615","0.04599"
"11022","66.09600","5.50811","0.04626"
"11046","66.24000","5.52019","0.04642"
"11070","66.38400","5.53221","0.04694"
"11094","66.52800","5.54416","0.04749"
"11118","66.67200","5.55612","0.04714"
"11142","66.81600","5.56820","0.04776"
"11166","66.96000","5.58016","0.04746"
"11190","67.10400","5.59212","0.04788"
"11214","67.24800","5.60413","0.04836"
"11238","67.39200","5.61615","0.04819"
"11262","67.53600","5.62817","0.04896"
"11286","67.68000","5.64007","0.04908"
"11310","67.82400","5.65214","0.04921"
"11334","67.96800","5.66416","0.04973"
"11358","68.11200","5.67612","0.05025"
"11382","68.25600","5.68814","0.05027"
"11406","68.40000","5.70015","0.05120"
"11430","68.54400","5.71223","0.05162"
"11454","68.68800","5.72419","0.05138"
"11478","68.83200","5.73615","0.05190"
"11502","68.97600","5.74823","0.05262"
"11526","69.12000","5.76024","0.05276"
"11550","69.26400","5.77214","0.05293"
"11574","69.40800","5.78416","0.05315"
"11598","69.55200","5.79618","0.05339"
"11622","69.69600","5.80819","0.05385"
"11646","69.84000","5.82009","0.05406"
"11670","69.98400","5.83217","0.05421"
"11694","70.12800","5.84419","0.05428"
"11718","70.27200","5.85615","0.05409"
"11742","70.41600","5.86810","0.05442"
"11766","70.56000","5.88018","0.05074"
"11790","70.70400","5.89214","0.05060"
"11814","70.84800","5.90416","0.05045"
"11838","70.99200","5.91611","0.05083"
"11862","71.13600","5.92813","0.05117"
"11886","71.28000","5.94021","0.05157"
"11910","71.42400","5.95211","0.05178"
"11934","71.56800","5.96419","0.05194"
"11958","71.71200","5.97614","0.05205"
"11982","71.85600","5.98816","0.05221"
"12006","72.00000","6.00012","0.05254"
"12030","72.14400","6.01214","0.05278"
"12054","72.28800","6.02415","0.05260"
"12078","72.43200","6.03611","0.05157"
"12102","72.57600","6.04813","0.05181"
"12126","72.72000","6.06015","0.05285"
"12150","72.86400","6.07217","0.05230"
"12174","73.00800","6.08412","0.05345"
"12198","73.15200","6.09614","0.05279"
"12222","73.29600","6.10816","0.05401"
"12246","73.44000","6.12018","0.05384"
"12270","73.58400","6.13207","0.05445"
"12294","73.72800","6.14421","0.05447"
"12318","73.87200","6.15617","0.05397"
"12342","74.01600","6.16813","0.05405"
"12366","74.16000","6.18009","0.05491"
"12390","74.30400","6.19216","0.05447"
"12414","74.44800","6.20418","0.05560"
"12438","74.59200","6.21620","0.05523"
"12462","74.73600","6.22816","0.05537"
"12486","74.88000","6.24023","0.05579"
"12510","75.02400","6.25219","0.05614"
"12534","75.16800","6.26415","0.05600"
"12558","75.31200","6.27611","0.05658"
"12582","75.45600","6.28819","0.05697"
"12606","75.60000","6.30014","0.05743"
"12630","75.74400","6.31216","0.05711"
"12654","75.88800","6.32412","0.05788"
"12678","76.03200","6.33620","0.05824"
"12702","76.17600","6.34815","0.05865"
"12726","76.32000","6.36011","0.05891"
"12750","76.46400","6.37213","0.05920"
"12774","76.60800","6.38421","0.05955"
"12798","76.75200","6.39616","0.05958"
"12822","76.89600","6.40812","0.06047"
"12846","77.04000","6.42014","0.06081"
"12870","77.18400","6.43216","0.06127"
"12894","77.32800","6.44412","0.06118"
"12918","77.47200","6.45613","0.06210"
"12942","77.61600","6.46815","0.06237"
"12966","77.76000","6.48017","0.06235"
"12990","77.90400","6.49213","0.06305"
"13014","78.04800","6.50415","0.06274"
"13038","78.19200","6.51616","0.06316"
"13062","78.33600","6.52818","0.06385"
"13086","78.48000","6.54008","0.06440"
"13110","78.62400","6.55216","0.06500"
"13134","78.76800","6.56417","0.06519"
"13158","78.91200","6.57613","0.06556"
"13182","79.05600","6.58809","0.06619"
"13206","79.20000","6.60017","0.06609"
"13230","79.34400","6.61218","0.06692"
"13254","79.48800","6.62414","0.06747"
"13278","79.63200","6.63616","0.06837"
"13302","79.77600","6.64818","0.06867"
"13326","79.92000","6.66014","0.06876"
"13350","80.06400","6.67209","0.06921"
"13374","80.20800","6.68417","0.06959"
"13398","80.35200","6.69619","0.07038"
"13422","80.49600","6.70815","0.07083"
"13446","80.64000","6.72010","0.07083"
"13470","80.78400","6.73218","0.07101"
"13494","80.92800","6.74420","0.07174"
"13518","81.07200","6.75616","0.07256"
"13542","81.21600","6.76818","0.07284"
"13566","81.36000","6.78019","0.07292"
"13590","81.50400","6.79221","0.07348"
"13614","81.64800","6.80411","0.07421"
"13638","81.79200","6.81619","0.07438"
"13662","81.93600","6.82820","0.07483"
"13686","82.08000","6.84016","0.07498"
"13710","82.22400","6.85212","0.07593"
"13734","82.36800","6.86420","0.07672"
"13758","82.51200","6.87615","0.07688"
"13782","82.65600","6.88811","0.07750"
"13806","82.80000","6.90007","0.07770"
"13830","82.94400","6.91221","0.07854"
"13854","83.08800","6.92417","0.07882"
"13878","83.23200","6.93612","0.07922"
"13902","83.37600","6.94814","0.08007"
"13926","83.52000","6.96022","0.07936"
"13950","83.66400","6.97218","0.08005"
"13974","83.80800","6.98413","0.08048"
"13998","83.95200","6.99615","0.08070"
"14022","84.09600","7.00823","0.08083"
"14046","84.24000","7.02019","0.08096"
"14070","84.38400","7.03215","0.08148"
"14094","84.52800","7.04416","0.08135"
"14118","84.67200","7.05618","0.08153"
"14142","84.81600","7.06814","0.08202"
"14166","84.96000","7.08010","0.08272"
"14190","85.10400","7.09218","0.08275"
"14214","85.24800","7.10419","0.08336"
"14238","85.39200","7.11615","0.08387"
"14262","85.53600","7.12817","0.08385"
"14286","85.68000","7.14019","0.08409"
"14310","85.82400","7.15220","0.08428"
"14334","85.96800","7.16416","0.08501"
"14358","86.11200","7.17618","0.08500"
"14382","86.25600","7.18814","0.08508"
"14406","86.40000","7.20021","0.08645"
"14430","86.54400","7.21217","0.08602"
"14454","86.68800","7.22419","0.08638"
"14478","86.83200","7.23621","0.08709"
"14502","86.97600","7.24817","0.08738"
"14526","87.12000","7.26018","0.08704"
"14550","87.26400","7.27220","0.08779"
"14574","87.40800","7.28422","0.08794"
"14598","87.55200","7.29618","0.08799"
"14622","87.69600","7.30819","0.08837"
"14646","87.84000","7.32021","0.08825"
"14670","87.98400","7.33217","0.08888"
"14694","88.12800","7.34413","0.08933"
"14718","88.27200","7.35615","0.08932"
"14742","88.41600","7.36816","0.08951"
"14766","88.56000","7.38018","0.09010"
"14790","88.70400","7.39214","0.09025"
"14814","88.84800","7.40422","0.09055"
"14838","88.99200","7.41617","0.09078"
"14862","89.13600","7.42819","0.09101"
"14886","89.28000","7.44015","0.09162"
"14910","89.42400","7.45223","0.09160"
"14934","89.56800","7.46413","0.09174"
"14958","89.71200","7.47614","0.09212"
"14982","89.85600","7.48816","0.09268"
"15006","90.00000","7.50018","0.09257"
"15030","90.14400","7.51220","0.09273"
"15054","90.28800","7.52409","0.09363"
"15078","90.43200","7.53623","0.09325"
"15102","90.57600","7.54825","0.09402"
"15126","90.72000","7.56021","0.09524"
"15150","90.86400","7.57216","0.09471"
"15174","91.00800","7.58424","0.09534"
"15198","91.15200","7.59620","0.09617"
"15222","91.29600","7.60816","0.09630"
"15246","91.44000","7.62018","0.09680"
"15270","91.58400","7.63225","0.09738"
"15294","91.72800","7.64421","0.09736"
"15318","91.87200","7.65617","0.09845"
"15342","92.01600","7.66819","0.09891"
"15366","92.16000","7.68026","0.09858"
"15390","92.30400","7.69222","0.09915"
"15414","92.44800","7.70418","0.09934"
"15438","92.59200","7.71620","0.10002"
"15462","92.73600","7.72822","0.10069"
"15486","92.88000","7.74017","0.10091"
"15510","93.02400","7.75213","0.10150"
"15534","93.16800","7.76415","0.10181"
"15558","93.31200","7.77623","0.10228"
"15582","93.45600","7.78813","0.10306"
"15606","93.60000","7.80014","0.10333"
"15630","93.74400","7.81216","0.10387"
"15654","93.88800","7.82418","0.10350"
"15678","94.03200","7.83614","0.10449"
"15702","94.17600","7.84815","0.10513"
"15726","94.32000","7.86023","0.10539"
"15750","94.46400","7.87225","0.10624"
"15774","94.60800","7.88421","0.10662"
"15798","94.75200","7.89622","0.10701"
"15822","94.89600","7.90824","0.10750"
"15846","95.04000","7.92020","0.10707"
"15870","95.18400","7.93216","0.10790"
"15894","95.32800","7.94418","0.10838"
"15918","95.47200","7.95619","0.10858"
"15942","95.61600","7.96815","0.10929"
"15966","95.76000","7.98023","0.10999"
"15990","95.90400","7.99225","0.11010"
"16014","96.04800","8.00426","0.11020"
"16038","96.19200","8.01616","0.11049"
"16062","96.33600","8.02812","0.11079"
"16086","96.48000","8.04020","0.11172"
"16110","96.62400","8.05221","0.11160"
"16134","96.76800","8.06417","0.11235"
"16158","96.91200","8.07625","0.11247"
"16182","97.05600","8.08821","0.11321"
"16206","97.20000","8.10017","0.11432"
"16230","97.34400","8.11218","0.11403"
"16254","97.48800","8.12420","0.11499"
"16278","97.63200","8.13616","0.11487"
"16302","97.77600","8.14812","0.11480"
"16326","97.92000","8.16013","0.11493"
"16350","98.06400","8.17215","0.11550"
"16374","98.20800","8.18417","0.11561"
"16398","98.35200","8.19613","0.11632"
"16422","98.49600","8.20821","0.11642"
"16446","98.64000","8.22016","0.11679"
"16470","98.78400","8.23218","0.11719"
"16494","98.92800","8.24414","0.11723"
"16518","99.07200","8.25622","0.11732"
"16542","99.21600","8.26823","0.11757"
"16566","99.36000","8.28019","0.11789"
"16590","99.50400","8.29215","0.11886"
"16614","99.64800","8.30423","0.11867"
"16638","99.79200","8.31619","0.11929"
"16662","99.93600","8.32814","0.11945"
"16686","100.08000","8.34016","0.12036"
"16710","100.22400","8.35224","0.12073"
"16734","100.36800","8.36420","0.12080"
"16758","100.51200","8.37615","0.12157"
"16782","100.65600","8.38817","0.12178"
"16806","100.80000","8.40019","0.12266"
"16830","100.94400","8.41215","0.12311"
"16854","101.08800","8.42411","0.12354"
"16878","101.23200","8.43624","0.12401"
"16902","101.37600","8.44820","0.12457"
"16926","101.52000","8.46016","0.12473"
"16950","101.66400","8.47218","0.12557"
"16974","101.80800","8.48425","0.12545"
"16998","101.95200","8.49621","0.12597"
"17022","102.09600","8.50811","0.12643"
"17046","102.24000","8.52013","0.12714"
"17070","102.38400","8.53215","0.12697"
"17094","102.52800","8.54416","0.12740"
"17118","102.67200","8.55612","0.12736"
"17142","102.81600","8.56814","0.12768"
"17166","102.96000","8.58016","0.12790"
"17190","103.10400","8.59217","0.12851"
"17214","103.24800","8.60413","0.12853"
"17238","103.39200","8.61615","0.12873"
"17262","103.53600","8.62823","0.12880"
"17286","103.68000","8.64013","0.12910"
"17310","103.82400","8.65214","0.12921"
"17334","103.96800","8.66416","-0.00115"
"17358","104.11200","8.67618","0.00433"
"17382","104.25600","8.68814","-0.00210"
"17406","104.40000","8.70015","0.00169"
"17430","104.54400","8.71217","0.00328"
"17454","104.68800","8.72419","0.00669"
"17478","104.83200","8.73609","-0.00217"
"17502","104.97600","8.74817","0.00017"
"17526","105.12000","8.76018","0.00110"
"17550","105.26400","8.77214","0.00211"
"17574","105.40800","8.78416","0.00285"
"17598","105.55200","8.79618","-0.00124"
"17622","105.69600","8.80813","0.00376"
"17646","105.84000","8.82015","0.00669"
"17670","105.98400","8.83211","0.00346"
"17694","106.12800","8.84419","-0.00106"
"17718","106.27200","8.85614","0.00114"
"17742","106.41600","8.86816","0.00973"
"17766","106.56000","8.88018","0.00424"
"17790","106.70400","8.89214","-0.00051"
"17814","106.84800","8.90416","0.00091"
"17838","106.99200","8.91617","0.00872"
"17862","107.13600","8.92819","0.00366"
"17886","107.28000","8.94021","-0.00086"
"17910","107.42400","8.95217","0.00329"
"17934","107.56800","8.96412","0.00678"
"17958","107.71200","8.97620","0.00380"
"17982","107.85600","8.98816","0.00102"
"18006","108.00000","9.00018","0.00426"
"18030","108.14400","9.01214","0.00606"
"18054","108.28800","9.02415","0.00266"
"18078","108.43200","9.03617","0.00165"
"18102","108.57600","9.04807","0.00427"
"18126","108.72000","9.06021","0.00541"
"18150","108.86400","9.07216","0.00267"
"18174","109.00800","9.08418","0.00110"
"18198","109.15200","9.09614","0.00424"
"18222","109.29600","9.10822","0.00534"
"18246","109.44000","9.12018","0.00309"
"18270","109.58400","9.13213","0.00165"
"18294","109.72800","9.14409","0.00402"
"18318","109.87200","9.15623","0.00572"
"18342","110.01600","9.16819","0.00307"
"18366","110.16000","9.18014","0.00107"
"18390","110.30400","9.19210","0.00373"
"18414","110.44800","9.20418","0.00615"
"18438","110.59200","9.21614","0.00279"
"18462","110.73600","9.22816","0.00159"
"18486","110.88000","9.24017","0.00469"
"18510","111.02400","9.25219","0.00566"
"18534","111.16800","9.26415","0.00217"
"18558","111.31200","9.27611","0.00302"
"18582","111.45600","9.28813","0.00582"
"18606","111.60000","9.30020","0.00529"
"18630","111.74400","9.31216","0.00243"
"18654","111.88800","9.32412","0.00327"
"18678","112.03200","9.33619","0.00523"
"18702","112.17600","9.34821","0.00425"
"18726","112.32000","9.36011","0.00326"
"18750","112.46400","9.37213","0.00455"
"18774","112.60800","9.38415","0.00531"
"18798","112.75200","9.39616","0.00418"
"18822","112.89600","9.40812","0.00279"
"18846","113.04000","9.42020","0.00408"
"18870","113.18400","9.43216","0.00580"
"18894","113.32800","9.44412","0.00443"
"18918","113.47200","9.45607","0.00383"
"18942","113.61600","9.46815","0.00447"
"18966","113.76000","9.48017","0.00567"
"18990","113.90400","9.49213","0.00455"
"19014","114.04800","9.50414","0.00332"
"19038","114.19200","9.51616","0.00545"
"19062","114.33600","9.52818","0.00639"
"19086","114.48000","9.54020","0.00413"
"19110","114.62400","9.55222","0.00377"
"19134","114.76800","9.56417","0.00564"
"19158","114.91200","9.57613","0.00568"
"19182","115.05600","9.58809","0.00432"
"19206","115.20000","9.60017","0.00450"
"19230","115.34400","9.61218","0.00631"
"19254","115.48800","9.62414","0.00455"
"19278","115.63200","9.63610","0.00414"
"19302","115.77600","9.64818","0.00501"
"19326","115.92000","9.66019","0.00605"
"19350","116.06400","9.67215","0.00545"
"19374","116.20800","9.68417","0.00501"
"19398","116.35200","9.69613","0.00542"
"19422","116.49600","9.70815","0.00688"
"19446","116.64000","9.72010","0.00487"
"19470","116.78400","9.73218","0.00444"
"19494","116.92800","9.74414","0.00578"
"19518","117.07200","9.75616","0.00672"
"19542","117.21600","9.76805","0.00507"
"19566","117.36000","9.78019","0.00503"
"19590","117.50400","9.79221","0.00641"
"19614","117.64800","9.80411","0.00625"
"19638","117.79200","9.81613","0.00593"
"19662","117.93600","9.82820","0.00582"
"19686","118.08000","9.84022","0.00678"
"19710","118.22400","9.85212","0.00635"
"19734","118.36800","9.86414","0.00475"
"19758","118.51200","9.87621","0.00636"
"19782","118.65600","9.88817","0.00718"
"19806","118.80000","9.90013","0.00620"
"19830","118.94400","9.91215","0.00517"
"19854","119.08800","9.92416","0.00666"
"19878","119.23200","9.93612","0.00692"
"19902","119.37600","9.94808","0.00509"
"19926","119.52000","9.96016","0.00553"
"19950","119.66400","9.97218","0.00696"
"19974","119.80800","9.98413","0.00662"
"19998","119.95200","9.99609","0.00596"
"20022","120.09600","10.00817","0.00549"
"20046","120.24000","10.02019","0.00677"
"20070","120.38400","10.03215","0.00676"
"20094","120.52800","10.04416","0.00591"
"20118","120.67200","10.05618","0.00634"
"20142","120.81600","10.06820","0.00782"
"20166","120.96000","10.08010","0.00672"
"20190","121.10400","10.09217","0.00610"
"20214","121.24800","10.10413","0.00666"
"20238","121.39200","10.11615","0.00741"
"20262","121.53600","10.12805","0.00696"
"20286","121.68000","10.14019","0.00640"
"20310","121.82400","10.15214","0.00720"
"20334","121.96800","10.16410","0.00671"
"20358","122.11200","10.17612","0.00637"
"20382","122.25600","10.18814","0.00607"
"20406","122.40000","10.20015","0.00760"
"20430","122.54400","10.21217","0.00809"
"20454","122.68800","10.22419","0.00690"
"20478","122.83200","10.23621","0.00740"
"20502","122.97600","10.24817","0.00788"
"20526","123.12000","10.26012","0.00741"
"20550","123.26400","10.27214","0.00747"
"20574","123.40800","10.28416","0.00747"
"20598","123.55200","10.29612","0.00819"
"20622","123.69600","10.30807","0.00772"
"20646","123.84000","10.32015","0.00764"
"20670","123.98400","10.33217","0.00817"
"20694","124.12800","10.34413","0.00865"
"20718","124.27200","10.35620","0.00796"
"20742","124.41600","10.36822","0.00807"
"20766","124.56000","10.38018","0.00885"
"20790","124.70400","10.39214","0.00831"
"20814","124.84800","10.40421","0.00821"
"20838","124.99200","10.41617","0.00811"
"20862","125.13600","10.42819","0.00867"
"20886","125.28000","10.44009","0.00865"
"20910","125.42400","10.45217","0.00824"
"20934","125.56800","10.46418","0.00883"
"20958","125.71200","10.47614","0.00900"
"20982","125.85600","10.48810","0.00843"
"21006","126.00000","10.50018","0.00816"
"21030","126.14400","10.51220","0.00914"
"21054","126.28800","10.52409","0.00960"
"21078","126.43200","10.53617","0.00918"
"21102","126.57600","10.54819","0.00833"
"21126","126.72000","10.56021","0.00979"
"21150","126.86400","10.57217","0.00886"
"21174","127.00800","10.58418","0.00887"
"21198","127.15200","10.59620","0.00875"
"21222","127.29600","10.60822","0.00905"
"21246","127.44000","10.62018","0.00906"
"21270","127.58400","10.63219","0.00896"
"21294","127.72800","10.64415","0.00992"
"21318","127.87200","10.65617","0.01009"
"21342","128.01600","10.66819","0.01052"
"21366","128.16000","10.68020","0.00947"
"21390","128.30400","10.69222","0.00933"
"21414","128.44800","10.70418","0.00999"
"21438","128.59200","10.71620","0.01053"
"21462","128.73600","10.72822","0.00998"
"21486","128.88000","10.74023","0.01042"
"21510","129.02400","10.75219","0.01061"
"21534","129.16800","10.76421","0.01037"
"21558","129.31200","10.77617","0.00974"
"21582","129.45600","10.78818","0.01100"
"21606","129.60000","10.80014","0.01109"
"21630","129.74400","10.81216","0.01037"
"21654","129.88800","10.82418","0.01056"
"21678","130.03200","10.83613","0.01110"
"21702","130.17600","10.84815","0.01070"
"21726","130.32000","10.86023","0.01065"
"21750","130.46400","10.87219","0.01041"
"21774","130.60800","10.88421","0.01115"
"21798","130.75200","10.89622","0.01114"
"21822","130.89600","10.90824","0.01048"
"21846","131.04000","10.92014","0.01183"
"21870","131.18400","10.93216","0.01139"
"21894","131.32800","10.94418","0.01125"
"21918","131.47200","10.95619","0.01182"
"21942","131.61600","10.96821","0.01167"
"21966","131.76000","10.98017","0.01214"
"21990","131.90400","10.99219","0.01119"
"22014","132.04800","11.00420","0.01191"
"22038","132.19200","11.01616","0.01180"
"22062","132.33600","11.02818","0.01174"
"22086","132.48000","11.04026","0.01166"
"22110","132.62400","11.05222","0.01218"
"22134","132.76800","11.06417","0.01193"
"22158","132.91200","11.07619","0.01247"
"22182","133.05600","11.08821","0.01236"
"22206","133.20000","11.10023","0.01218"
"22230","133.34400","11.11212","0.01256"
"22254","133.48800","11.12420","0.01231"
"22278","133.63200","11.13616","0.01278"
"22302","133.77600","11.14818","0.01234"
"22326","133.92000","11.16014","0.01300"
"22350","134.06400","11.17221","0.01345"
"22374","134.20800","11.18417","0.01296"
"22398","134.35200","11.19613","0.01311"
"22422","134.49600","11.20821","0.01339"
"22446","134.64000","11.22022","0.01290"
"22470","134.78400","11.23224","0.01360"
"22494","134.92800","11.24414","0.01383"
"22518","135.07200","11.25616","0.01318"
"22542","135.21600","11.26824","0.01364"
"22566","135.36000","11.28019","0.01447"
"22590","135.50400","11.29215","0.01423"
"22614","135.64800","11.30423","0.01420"
"22638","135.79200","11.31618","0.01387"
"22662","135.93600","11.32820","0.01454"
"22686","136.08000","11.34016","0.01390"
"22710","136.22400","11.35218","0.01429"
"22734","136.36800","11.36420","0.01484"
"22758","136.51200","11.37615","0.01478"
"22782","136.65600","11.38817","0.01443"
"22806","136.80000","11.40019","0.01537"
"22830","136.94400","11.41221","0.01550"
"22854","137.08800","11.42417","0.01500"
"22878","137.23200","11.43618","0.01504"
"22902","137.37600","11.44820","0.01556"
"22926","137.52000","11.46022","0.01553"
"22950","137.66400","11.47218","0.01587"
"22974","137.80800","11.48419","0.01534"
"22998","137.95200","11.49621","0.01626"
"23022","138.09600","11.50817","0.01602"
"23046","138.24000","11.52019","0.01582"
"23070","138.38400","11.53221","0.01642"
"23094","138.52800","11.54416","0.01665"
"23118","138.67200","11.55612","0.01682"
"23142","138.81600","11.56814","0.01637"
"23166","138.96000","11.58022","0.01664"
"23190","139.10400","11.59217","0.01718"
"23214","139.24800","11.60413","0.01653"
"23238","139.39200","11.61615","0.01664"
"23262","139.53600","11.62817","0.01724"
"23286","139.68000","11.64019","0.01779"
"23310","139.82400","11.65214","0.01736"
"23334","139.96800","11.66422","0.01753"
"23358","140.11200","11.67618","0.01857"
"23382","140.25600","11.68820","0.01832"
"23406","140.40000","11.70021","0.01855"
"23430","140.54400","11.71223","0.01858"
"23454","140.68800","11.72413","0.01905"
"23478","140.83200","11.73615","0.01881"
"23502","140.97600","11.74810","0.01844"
"23526","141.12000","11.76018","0.01904"
"23550","141.26400","11.77214","0.01946"
"23574","141.40800","11.78410","0.01972"
"23598","141.55200","11.79618","0.01900"
"23622","141.69600","11.80814","0.01931"
"23646","141.84000","11.82015","0.01981"
"23670","141.98400","11.83211","0.01958"
"23694","142.12800","11.84425","0.01988"
"23718","142.27200","11.85620","0.02029"
"23742","142.41600","11.86816","0.02096"
"23766","142.56000","11.88018","0.02121"
"23790","142.70400","11.89220","0.02061"
"23814","142.84800","11.90416","0.02095"
"23838","142.99200","11.91617","0.02116"
"23862","143.13600","11.92819","0.02138"
"23886","143.28000","11.94021","0.02146"
"23910","143.42400","11.95223","0.02196"
"23934","143.56800","11.96412","0.02188"
"23958","143.71200","11.97620","0.02165"
"23982","143.85600","11.98816","0.02152"
"24006","144.00000","12.00012","0.02237"
"24030","144.14400","12.01208","0.02273"
"24054","144.28800","12.02421","0.02246"
"24078","144.43200","12.03617","0.02229"
"24102","144.57600","12.04813","0.02314"
"24126","144.72000","12.06015","0.02338"
"24150","144.86400","12.07222","0.02346"
"24174","145.00800","12.08418","0.02356"
"24198","145.15200","12.09614","0.02409"
"24222","145.29600","12.10816","0.02443"
"24246","145.44000","12.12018","0.02378"
"24270","145.58400","12.13219","0.02488"
"24294","145.72800","12.14409","0.02501"
"24318","145.87200","12.15617","0.02490"
"24342","146.01600","12.16819","0.02540"
"24366","146.16000","12.18014","0.02533"
"24390","146.30400","12.19216","0.02557"
"24414","146.44800","12.20424","0.02609"
"24438","146.59200","12.21620","0.02638"
"24462","146.73600","12.22815","0.02703"
"24486","146.88000","12.24017","0.02644"
"24510","147.02400","12.25219","0.02711"
"24534","147.16800","12.26415","0.02733"
"24558","147.31200","12.27611","0.02817"
"24582","147.45600","12.28812","0.02814"
"24606","147.60000","12.30014","0.02865"
"24630","147.74400","12.31216","0.02873"
"24654","147.88800","12.32412","0.02848"
"24678","148.03200","12.33619","0.02908"
"24702","148.17600","12.34821","0.02882"
"24726","148.32000","12.36017","0.02921"
"24750","148.46400","12.37213","0.02969"
"24774","148.60800","12.38415","0.02992"
"24798","148.75200","12.39616","0.03025"
"24822","148.89600","12.40812","0.03049"
"24846","149.04000","12.42008","0.03077"
"24870","149.18400","12.43216","0.03106"
"24894","149.32800","12.44417","0.03132"
"24918","149.47200","12.45607","0.03168"
"24942","149.61600","12.46815","0.03152"
"24966","149.76000","12.48017","0.03239"
"24990","149.90400","12.49213","0.03289"
"25014","150.04800","12.50414","0.03275"
"25038","150.19200","12.51622","0.03307"
"25062","150.33600","12.52818","0.03335"
"25086","150.48000","12.54020","0.03433"
"25110","150.62400","12.55216","0.03394"
"25134","150.76800","12.56423","0.03449"
"25158","150.91200","12.57625","0.03446"
"25182","151.05600","12.58815","0.03506"
"25206","151.20000","12.60017","0.03566"
"25230","151.34400","12.61218","0.03552"
"25254","151.48800","12.62414","0.03615"
"25278","151.63200","12.63610","0.03586"
"25302","151.77600","12.64818","0.03661"
"25326","151.92000","12.66019","0.03709"
"25350","152.06400","12.67215","0.03734"
"25374","152.20800","12.68411","0.03753"
"25398","152.35200","12.69619","0.03762"
"25422","152.49600","12.70821","0.03828"
"25446","152.64000","12.72016","0.03850"
"25470","152.78400","12.73212","0.03878"
"25494","152.92800","12.74420","0.03865"
"25518","153.07200","12.75616","0.03939"
"25542","153.21600","12.76817","0.03960"
"25566","153.36000","12.78013","0.04027"
"25590","153.50400","12.79215","0.04053"
"25614","153.64800","12.80417","0.04025"
"25638","153.79200","12.81613","0.04107"
"25662","153.93600","12.82814","0.04162"
"25686","154.08000","12.84022","0.04090"
"25710","154.22400","12.85218","0.04152"
"25734","154.36800","12.86414","0.04191"
"25758","154.51200","12.87621","0.04236"
"25782","154.65600","12.88823","0.04248"
"25806","154.80000","12.90019","0.04285"
"25830","154.94400","12.91215","0.04309"
"25854","155.08800","12.92416","0.04292"
"25878","155.23200","12.93618","0.04349"
"25902","155.37600","12.94808","0.04396"
"25926","155.52000","12.96016","0.04430"
"25950","155.66400","12.97212","0.04456"
"25974","155.80800","12.98419","0.04475"
"25998","155.95200","12.99609","0.04513"
"26022","156.09600","13.00817","0.04553"
"26046","156.24000","13.02013","0.04606"
"26070","156.38400","13.03215","0.04658"
"26094","156.52800","13.04410","0.04665"
"26118","156.67200","13.05618","0.04681"
"26142","156.81600","13.06814","0.04771"
"26166","156.96000","13.08016","0.04758"
"26190","157.10400","13.09211","0.04801"
"26214","157.24800","13.10413","0.04902"
"26238","157.39200","13.11615","0.04905"
"26262","157.53600","13.12811","0.04977"
"26286","157.68000","13.14018","0.04981"
"26310","157.82400","13.15214","0.05110"
"26334","157.96800","13.16416","0.05112"
"26358","158.11200","13.17612","0.05139"
"26382","158.25600","13.18820","0.05175"
"26406","158.40000","13.20021","0.05253"
"26430","158.54400","13.21211","0.05296"
"26454","158.68800","13.22419","0.05364"
"26478","158.83200","13.23621","0.05417"
"26502","158.97600","13.24817","0.05504"
"26526","159.12000","13.26012","0.05601"
"26550","159.26400","13.27214","0.05580"
"26574","159.40800","13.28416","0.05657"
"26598","159.55200","13.29618","0.05704"
"26622","159.69600","13.30813","0.05790"
"26646","159.84000","13.32021","0.05822"
"26670","159.98400","13.33217","0.05877"
"26694","160.12800","13.34413","0.05954"
"26718","160.27200","13.35609","0.05987"
"26742","160.41600","13.36822","0.06050"
"26766","160.56000","13.38018","0.06116"
"26790","160.70400","13.39220","0.06099"
"26814","160.84800","13.40410","0.06211"
"26838","160.99200","13.41623","0.06261"
"26862","161.13600","13.42819","0.06307"
"26886","161.28000","13.44015","0.06382"
"26910","161.42400","13.45217","0.06372"
"26934","161.56800","13.46419","0.06497"
"26958","161.71200","13.47620","0.06573"
"26982","161.85600","13.48810","0.06615"
"27006","162.00000","13.50018","0.06711"
"27030","162.14400","13.51220","0.06818"
"27054","162.28800","13.52415","0.06885"
"27078","162.43200","13.53611","0.06939"
"27102","162.57600","13.54813","0.07002"
"27126","162.72000","13.56021","0.07121"
"27150","162.86400","13.57210","0.07239"
"27174","163.00800","13.58412","0.07218"
"27198","163.15200","13.59620","0.07293"
"27222","163.29600","13.60822","0.07384"
"27246","163.44000","13.62012","0.07455"
"27270","163.58400","13.63219","0.07551"
"27294","163.72800","13.64415","0.07604"
"27318","163.87200","13.65617","0.07673"
"27342","164.01600","13.66813","0.07718"
"27366","164.16000","13.68015","0.07802"
"27390","164.30400","13.69216","0.07869"
"27414","164.44800","13.70412","0.07921"
"27438","164.59200","13.71608","0.07961"
"27462","164.73600","13.72816","0.08002"
"27486","164.88000","13.74017","0.08069"
"27510","165.02400","13.75213","0.08097"
"27534","165.16800","13.76415","0.08132"
"27558","165.31200","13.77617","0.08181"
"27582","165.45600","13.78818","0.08251"
"27606","165.60000","13.80014","0.08308"
"27630","165.74400","13.81216","0.08354"
"27654","165.88800","13.82424","0.08332"
"27678","166.03200","13.83619","0.08440"
"27702","166.17600","13.84815","0.08486"
"27726","166.32000","13.86017","0.08495"
"27750","166.46400","13.87219","0.08588"
"27774","166.60800","13.88415","0.08653"
"27798","166.75200","13.89616","0.08673"
"27822","166.89600","13.90818","0.08728"
"27846","167.04000","13.92020","0.08770"
"27870","167.18400","13.93216","0.08837"
"27894","167.32800","13.94417","0.08849"
"27918","167.47200","13.95619","0.08883"
"27942","167.61600","13.96821","0.08964"
"27966","167.76000","13.98011","0.08967"
"27990","167.90400","13.99219","0.08988"
"28014","168.04800","14.00420","0.09085"
"28038","168.19200","14.01622","0.09104"
"28062","168.33600","14.02812","0.09133"
"28086","168.48000","14.04020","0.09181"
"28110","168.62400","14.05221","0.09252"
"28134","168.76800","14.06417","0.09271"
"28158","168.91200","14.07613","0.09285"
"28182","169.05600","14.08821","0.09403"
"28206","169.20000","14.10023","0.09415"
"28230","169.34400","14.11212","0.09508"
"28254","169.48800","14.12414","0.09528"
"28278","169.63200","14.13622","0.09604"
"28302","169.77600","14.14818","0.09630"
"28326","169.92000","14.16014","0.09718"
"28350","170.06400","14.17215","0.09768"
"28374","170.20800","14.18423","0.09850"
"28398","170.35200","14.19619","0.09857"
"28422","170.49600","14.20815","0.09945"
"28446","170.64000","14.22016","0.10060"
"28470","170.78400","14.23218","0.10018"
"28494","170.92800","14.24414","0.10181"
"28518","171.07200","14.25616","0.10201"
"28542","171.21600","14.26823","0.10278"
"28566","171.36000","14.28019","0.10317"
"28590","171.50400","14.29215","0.10385"
"28614","171.64800","14.30417","0.10424"
"28638","171.79200","14.31625","0.10449"
"28662","171.93600","14.32820","0.10551"
"28686","172.08000","14.34016","0.10644"
"28710","172.22400","14.35218","0.10693"
"28734","172.36800","14.36420","0.10779"
"28758","172.51200","14.37621","0.10782"
"28782","172.65600","14.38817","0.10904"
"28806","172.80000","14.40019","0.10945"
"28830","172.94400","14.41221","0.11046"
"28854","173.08800","14.42417","0.11090"
"28878","173.23200","14.43618","0.11232"
"28902","173.37600","14.44820","0.11242"
"28926","173.52000","14.46022","0.11375"
"28950","173.66400","14.47218","0.11364"
"28974","173.80800","14.48419","0.11505"
"28998","173.95200","14.49621","0.11521"
"29022","174.09600","14.50823","0.11588"
"29046","174.24000","14.52019","0.11696"
"29070","174.38400","14.53220","0.11846"
"29094","174.52800","14.54422","0.11912"
"29118","174.67200","14.55618","0.12008"
"29142","174.81600","14.56814","0.12091"
"29166","174.96000","14.58016","0.12105"
"29190","175.10400","14.59211","0.12212"
"29214","175.24800","14.60413","0.12299"
"29238","175.39200","14.61615","0.12273"
"29262","175.53600","14.62823","0.12427"
"29286","175.68000","14.64019","0.12421"
"29310","175.82400","14.65220","0.12461"
"29334","175.96800","14.66416","0.12478"
"29358","176.11200","14.67624","-0.00953"
"29382","176.25600","14.68820","0.00665"
"29406","176.40000","14.70015","-0.00555"
"29430","176.54400","14.71223","0.00491"
"29454","176.68800","14.72425","-0.00076"
"29478","176.83200","14.73621","0.00069"
"29502","176.97600","14.74816","-0.00185"
"29526","177.12000","14.76024","0.00008"
"29550","177.26400","14.77214","-0.00110"
"29574","177.40800","14.78410","0.00042"
"29598","177.55200","14.79618","-0.00192"
"29622","177.69600","14.80819","-0.00050"
"29646","177.84000","14.82021","-0.00162"
"29670","177.98400","14.83217","-0.00173"
"29694","178.12800","14.84419","-0.00171"
"29718","178.27200","14.85626","-0.00224"
"29742","178.41600","14.86822","-0.00160"
"29766","178.56000","14.88012","-0.00188"
"29790","178.70400","14.89220","-0.00139"
"29814","178.84800","14.90416","-0.00180"
"29838","178.99200","14.91611","-0.00166"
"29862","179.13600","14.92813","-0.00230"
"29886","179.28000","14.94021","-0.00246"
"29910","179.42400","14.95223","-0.00195"
"29934","179.56800","14.96412","-0.00161"
"29958","179.71200","14.97620","-0.00172"
"29982","179.85600","14.98822","-0.00150"
"30006","180.00000","15.00024","-0.00140"
"30018","180.07200","15.00616","-0.00145"