File: Trajectories_together/170212_3Specimen_RawData_10.csv
"","V1","V2","V3"
"1","End date","2/12/2017",""
"2","Specimen label","12DT_92",""
"3","Maximum Load","0.01519","N"
"4","Time","Extension","Load"
"5","(s)","(mm)","(N)"
"6","0.00000","0.00000","0.00001"
"44","0.22800","0.01716","0.00093"
"82","0.45600","0.03821","0.00036"
"120","0.68400","0.05722","0.00046"
"158","0.91200","0.07623","0.00076"
"196","1.14000","0.09518","0.00056"
"234","1.36800","0.11420","0.00098"
"272","1.59600","0.13309","0.00148"
"310","1.82400","0.15216","0.00064"
"348","2.05200","0.17118","0.00117"
"386","2.28000","0.19019","0.00177"
"424","2.50800","0.20920","0.00099"
"462","2.73600","0.22816","0.00094"
"500","2.96400","0.24717","0.00162"
"538","3.19200","0.26606","0.00124"
"576","3.42000","0.28520","0.00110"
"614","3.64800","0.30415","0.00106"
"652","3.87600","0.32316","0.00125"
"690","4.10400","0.34218","0.00144"
"728","4.33200","0.36119","0.00137"
"766","4.56000","0.38014","0.00114"
"804","4.78800","0.39915","0.00169"
"842","5.01600","0.41823","0.00202"
"880","5.24400","0.43718","0.00122"
"918","5.47200","0.45619","0.00139"
"956","5.70000","0.47521","0.00100"
"994","5.92800","0.49410","0.00144"
"1032","6.15600","0.51323","0.00083"
"1070","6.38400","0.53213","0.00139"
"1108","6.61200","0.55120","0.00161"
"1146","6.84000","0.57015","0.00144"
"1184","7.06800","0.58917","0.00154"
"1222","7.29600","0.60818","0.00174"
"1260","7.52400","0.62713","0.00133"
"1298","7.75200","0.64621","0.00168"
"1336","7.98000","0.66516","0.00172"
"1374","8.20800","0.68417","0.00150"
"1412","8.43600","0.70318","0.00155"
"1450","8.66400","0.72214","0.00265"
"1488","8.89200","0.74121","0.00206"
"1526","9.12000","0.76016","0.00182"
"1564","9.34800","0.77918","0.00201"
"1602","9.57600","0.79813","0.00204"
"1640","9.80400","0.81720","0.00192"
"1678","10.03200","0.83622","0.00212"
"1716","10.26000","0.85517","0.00173"
"1754","10.48800","0.87418","0.00184"
"1792","10.71600","0.89320","0.00175"
"1830","10.94400","0.91221","0.00181"
"1868","11.17200","0.93116","0.00207"
"1906","11.40000","0.95024","0.00226"
"1944","11.62800","0.96913","0.00218"
"1982","11.85600","0.98820","0.00162"
"2020","12.08400","1.00721","0.00142"
"2058","12.31200","1.02617","0.00255"
"2096","12.54000","1.04524","0.00264"
"2134","12.76800","1.06419","0.00228"
"2172","12.99600","1.08321","0.00231"
"2210","13.22400","1.10216","0.00205"
"2248","13.45200","1.12117","0.00222"
"2286","13.68000","1.14019","0.00194"
"2324","13.90800","1.15920","0.00249"
"2362","14.13600","1.17821","0.00208"
"2400","14.36400","1.19717","0.00237"
"2438","14.59200","1.21618","0.00205"
"2476","14.82000","1.23519","0.00230"
"2514","15.04800","1.25415","0.00218"
"2552","15.27600","1.27322","0.00232"
"2590","15.50400","1.29211","0.00227"
"2628","15.73200","1.31124","0.00268"
"2666","15.96000","1.33014","0.00221"
"2704","16.18800","1.34915","0.00252"
"2742","16.41600","1.36822","0.00237"
"2780","16.64400","1.38706","0.00241"
"2818","16.87200","1.40625","0.00234"
"2856","17.10000","1.42514","0.00242"
"2894","17.32800","1.44416","0.00245"
"2932","17.55600","1.46317","0.00228"
"2970","17.78400","1.48218","0.00253"
"3008","18.01200","1.50120","0.00288"
"3046","18.24000","1.52015","0.00230"
"3084","18.46800","1.53922","0.00281"
"3122","18.69600","1.55817","0.00264"
"3160","18.92400","1.57725","0.00234"
"3198","19.15200","1.59620","0.00204"
"3236","19.38000","1.61515","0.00280"
"3274","19.60800","1.63423","0.00227"
"3312","19.83600","1.65312","0.00244"
"3350","20.06400","1.67219","0.00250"
"3388","20.29200","1.69115","0.00263"
"3426","20.52000","1.71022","0.00233"
"3464","20.74800","1.72923","0.00233"
"3502","20.97600","1.74813","0.00280"
"3540","21.20400","1.76720","0.00212"
"3578","21.43200","1.78615","0.00233"
"3616","21.66000","1.80523","0.00244"
"3654","21.88800","1.82418","0.00228"
"3692","22.11600","1.84313","0.00283"
"3730","22.34400","1.86220","0.00277"
"3768","22.57200","1.88110","0.00255"
"3806","22.80000","1.90017","0.00231"
"3844","23.02800","1.91912","0.00250"
"3882","23.25600","1.93820","0.00260"
"3920","23.48400","1.95721","0.00269"
"3958","23.71200","1.97616","0.00267"
"3996","23.94000","1.99518","0.00287"
"4034","24.16800","2.01413","0.00292"
"4072","24.39600","2.03314","0.00249"
"4110","24.62400","2.05216","0.00261"
"4148","24.85200","2.07117","0.00338"
"4186","25.08000","2.09024","0.00266"
"4224","25.30800","2.10920","0.00252"
"4262","25.53600","2.12821","0.00306"
"4300","25.76400","2.14716","0.00325"
"4338","25.99200","2.16617","0.00324"
"4376","26.22000","2.18519","0.00327"
"4414","26.44800","2.20420","0.00305"
"4452","26.67600","2.22321","0.00326"
"4490","26.90400","2.24217","0.00332"
"4528","27.13200","2.26118","0.00413"
"4566","27.36000","2.28019","0.00261"
"4604","27.58800","2.29921","0.00310"
"4642","27.81600","2.31822","0.00331"
"4680","28.04400","2.33717","0.00274"
"4718","28.27200","2.35619","0.00265"
"4756","28.50000","2.37520","0.00307"
"4794","28.72800","2.39415","0.00272"
"4832","28.95600","2.41311","0.00301"
"4870","29.18400","2.43218","0.00297"
"4908","29.41200","2.45113","0.00314"
"4946","29.64000","2.47020","0.00313"
"4984","29.86800","2.48916","0.00286"
"5022","30.09600","2.50811","0.00333"
"5060","30.32400","2.52718","0.00376"
"5098","30.55200","2.54614","0.00280"
"5136","30.78000","2.56521","0.00284"
"5174","31.00800","2.58416","0.00331"
"5212","31.23600","2.60318","0.00395"
"5250","31.46400","2.62219","0.00346"
"5288","31.69200","2.64114","0.00295"
"5326","31.92000","2.66022","0.00285"
"5364","32.14800","2.67917","0.00340"
"5402","32.37600","2.69824","0.00375"
"5440","32.60400","2.71720","0.00286"
"5478","32.83200","2.73615","0.00382"
"5516","33.06000","2.75522","0.00355"
"5554","33.28800","2.77417","0.00364"
"5592","33.51600","2.79325","0.00304"
"5630","33.74400","2.81214","0.00312"
"5668","33.97200","2.83121","0.00342"
"5706","34.20000","2.85023","0.00314"
"5744","34.42800","2.86918","0.00339"
"5782","34.65600","2.88819","0.00339"
"5820","34.88400","2.90721","0.00323"
"5858","35.11200","2.92622","0.00310"
"5896","35.34000","2.94511","0.00290"
"5934","35.56800","2.96419","0.00335"
"5972","35.79600","2.98320","0.00289"
"6010","36.02400","3.00215","0.00337"
"6048","36.25200","3.02122","0.00380"
"6086","36.48000","3.04018","0.00410"
"6124","36.70800","3.05919","0.00324"
"6162","36.93600","3.07814","0.00378"
"6200","37.16400","3.09716","0.00413"
"6238","37.39200","3.11617","0.00348"
"6276","37.62000","3.13512","0.00283"
"6314","37.84800","3.15420","0.00325"
"6352","38.07600","3.17315","0.00358"
"6390","38.30400","3.19216","0.00352"
"6428","38.53200","3.21118","0.00338"
"6466","38.76000","3.23019","0.00315"
"6504","38.98800","3.24914","0.00392"
"6542","39.21600","3.26810","0.00297"
"6580","39.44400","3.28723","0.00391"
"6618","39.67200","3.30618","0.00354"
"6656","39.90000","3.32520","0.00399"
"6694","40.12800","3.34427","0.00313"
"6732","40.35600","3.36310","0.00351"
"6770","40.58400","3.38217","0.00339"
"6808","40.81200","3.40113","0.00344"
"6846","41.04000","3.42020","0.00348"
"6884","41.26800","3.43921","0.00386"
"6922","41.49600","3.45817","0.00389"
"6960","41.72400","3.47718","0.00344"
"6998","41.95200","3.49613","0.00341"
"7036","42.18000","3.51521","0.00386"
"7074","42.40800","3.53416","0.00291"
"7112","42.63600","3.55323","0.00361"
"7150","42.86400","3.57219","0.00363"
"7188","43.09200","3.59114","0.00357"
"7226","43.32000","3.61021","0.00304"
"7264","43.54800","3.62916","0.00335"
"7302","43.77600","3.64812","0.00355"
"7340","44.00400","3.66719","0.00354"
"7378","44.23200","3.68614","0.00361"
"7416","44.46000","3.70522","0.00389"
"7454","44.68800","3.72417","0.00347"
"7492","44.91600","3.74318","0.00379"
"7530","45.14400","3.76214","0.00405"
"7568","45.37200","3.78115","0.00376"
"7606","45.60000","3.80016","0.00383"
"7644","45.82800","3.81918","0.00314"
"7682","46.05600","3.83819","0.00422"
"7720","46.28400","3.85714","0.00341"
"7758","46.51200","3.87616","0.00349"
"7796","46.74000","3.89517","0.00370"
"7834","46.96800","3.91418","0.00357"
"7872","47.19600","3.93314","0.00389"
"7910","47.42400","3.95221","0.00358"
"7948","47.65200","3.97122","0.00364"
"7986","47.88000","3.99017","0.00379"
"8024","48.10800","4.00919","0.00372"
"8062","48.33600","4.02814","0.00405"
"8100","48.56400","4.04721","0.00401"
"8138","48.79200","4.06617","0.00379"
"8176","49.02000","4.08524","0.00327"
"8214","49.24800","4.10419","0.00401"
"8252","49.47600","4.12315","0.00375"
"8290","49.70400","4.14216","0.00355"
"8328","49.93200","4.16117","0.00381"
"8366","50.16000","4.18018","0.00380"
"8404","50.38800","4.19920","0.00350"
"8442","50.61600","4.21815","0.00293"
"8480","50.84400","4.23722","0.00368"
"8518","51.07200","4.25618","0.00338"
"8556","51.30000","4.27525","0.00411"
"8594","51.52800","4.29414","0.00352"
"8632","51.75600","4.31316","0.00396"
"8670","51.98400","4.33217","0.00415"
"8708","52.21200","4.35118","0.00394"
"8746","52.44000","4.37020","0.00370"
"8784","52.66800","4.38909","0.00329"
"8822","52.89600","4.40822","0.00420"
"8860","53.12400","4.42718","0.00353"
"8898","53.35200","4.44613","0.00385"
"8936","53.58000","4.46520","0.00354"
"8974","53.80800","4.48416","0.00357"
"9012","54.03600","4.50317","0.00383"
"9050","54.26400","4.52218","0.00400"
"9088","54.49200","4.54125","0.00318"
"9126","54.72000","4.56015","0.00353"
"9164","54.94800","4.57916","0.00370"
"9202","55.17600","4.59823","0.00377"
"9240","55.40400","4.61713","0.00328"
"9278","55.63200","4.63620","0.00348"
"9316","55.86000","4.65509","0.00382"
"9354","56.08800","4.67423","0.00384"
"9392","56.31600","4.69324","0.00378"
"9430","56.54400","4.71219","0.00409"
"9468","56.77200","4.73121","0.00367"
"9506","57.00000","4.75010","0.00391"
"9544","57.22800","4.76923","0.00401"
"9582","57.45600","4.78819","0.00343"
"9620","57.68400","4.80720","0.00324"
"9658","57.91200","4.82615","0.00345"
"9696","58.14000","4.84510","0.00387"
"9734","58.36800","4.86424","0.00364"
"9772","58.59600","4.88313","0.00392"
"9810","58.82400","4.90220","0.00401"
"9848","59.05200","4.92116","0.00425"
"9886","59.28000","4.94011","0.00364"
"9924","59.50800","4.95924","0.00352"
"9962","59.73600","4.97814","0.00402"
"10000","59.96400","4.99721","0.00401"
"10038","60.19200","5.01616","0.00366"
"10076","60.42000","5.03517","0.00358"
"10114","60.64800","5.05419","0.00355"
"10152","60.87600","5.07314","0.00393"
"10190","61.10400","5.09221","0.00334"
"10228","61.33200","5.11111","0.00402"
"10266","61.56000","5.13018","0.00400"
"10304","61.78800","5.14919","0.00343"
"10342","62.01600","5.16821","0.00396"
"10380","62.24400","5.18722","0.00394"
"10418","62.47200","5.20617","0.00331"
"10456","62.70000","5.22519","0.00385"
"10494","62.92800","5.24414","0.00356"
"10532","63.15600","5.26315","0.00393"
"10570","63.38400","5.28217","0.00355"
"10608","63.61200","5.30118","0.00399"
"10646","63.84000","5.32019","0.00366"
"10684","64.06800","5.33915","0.00415"
"10722","64.29600","5.35822","0.00376"
"10760","64.52400","5.37711","0.00323"
"10798","64.75200","5.39618","0.00352"
"10836","64.98000","5.41514","0.00390"
"10874","65.20800","5.43421","0.00385"
"10912","65.43600","5.45322","0.00342"
"10950","65.66400","5.47218","0.00430"
"10988","65.89200","5.49119","0.00358"
"11026","66.12000","5.51014","0.00452"
"11064","66.34800","5.52922","0.00369"
"11102","66.57600","5.54817","0.00383"
"11140","66.80400","5.56724","0.00410"
"11178","67.03200","5.58620","0.00373"
"11216","67.26000","5.60515","0.00364"
"11254","67.48800","5.62422","0.00327"
"11292","67.71600","5.64312","0.00349"
"11330","67.94400","5.66219","0.00430"
"11368","68.17200","5.68114","0.00356"
"11406","68.40000","5.70015","0.00373"
"11444","68.62800","5.71917","0.00380"
"11482","68.85600","5.73812","0.00321"
"11520","69.08400","5.75719","0.00366"
"11558","69.31200","5.77615","0.00352"
"11596","69.54000","5.79522","0.00363"
"11634","69.76800","5.81417","0.00360"
"11672","69.99600","5.83319","0.00396"
"11710","70.22400","5.85220","0.00319"
"11748","70.45200","5.87115","0.00391"
"11786","70.68000","5.89023","0.00353"
"11824","70.90800","5.90918","0.00377"
"11862","71.13600","5.92819","0.00382"
"11900","71.36400","5.94720","0.00386"
"11938","71.59200","5.96616","0.00417"
"11976","71.82000","5.98517","0.00379"
"12014","72.04800","6.00407","0.00416"
"12052","72.27600","6.02326","0.00367"
"12090","72.50400","6.04215","0.00331"
"12128","72.73200","6.06122","0.00355"
"12166","72.96000","6.08018","0.00352"
"12204","73.18800","6.09919","0.00368"
"12242","73.41600","6.11820","0.00356"
"12280","73.64400","6.13710","0.00394"
"12318","73.87200","6.15623","0.00389"
"12356","74.10000","6.17512","0.00362"
"12394","74.32800","6.19420","0.00385"
"12432","74.55600","6.21321","0.00367"
"12470","74.78400","6.23216","0.00326"
"12508","75.01200","6.25117","0.00364"
"12546","75.24000","6.27013","0.00331"
"12584","75.46800","6.28920","0.00335"
"12622","75.69600","6.30821","0.00357"
"12660","75.92400","6.32717","0.00409"
"12698","76.15200","6.34624","0.00390"
"12736","76.38000","6.36513","0.00356"
"12774","76.60800","6.38415","0.00346"
"12812","76.83600","6.40316","0.00375"
"12850","77.06400","6.42217","0.00360"
"12888","77.29200","6.44119","0.00415"
"12926","77.52000","6.46014","0.00361"
"12964","77.74800","6.47921","0.00362"
"13002","77.97600","6.49811","0.00355"
"13040","78.20400","6.51718","0.00270"
"13078","78.43200","6.53613","0.00313"
"13116","78.66000","6.55520","0.00301"
"13154","78.88800","6.57416","0.00221"
"13192","79.11600","6.59311","0.00256"
"13230","79.34400","6.61218","0.00276"
"13268","79.57200","6.63120","0.00349"
"13306","79.80000","6.65015","0.00281"
"13344","80.02800","6.66922","0.00263"
"13382","80.25600","6.68818","0.00274"
"13420","80.48400","6.70719","0.00293"
"13458","80.71200","6.72614","0.00267"
"13496","80.94000","6.74522","0.00303"
"13534","81.16800","6.76417","0.00265"
"13572","81.39600","6.78318","0.00263"
"13610","81.62400","6.80214","0.00217"
"13648","81.85200","6.82121","0.00250"
"13686","82.08000","6.84022","0.00216"
"13724","82.30800","6.85912","0.00252"
"13762","82.53600","6.87819","0.00246"
"13800","82.76400","6.89714","0.00311"
"13838","82.99200","6.91621","0.00280"
"13876","83.22000","6.93517","0.00279"
"13914","83.44800","6.95418","0.00260"
"13952","83.67600","6.97313","0.00242"
"13990","83.90400","6.99215","0.00296"
"14028","84.13200","7.01122","0.00272"
"14066","84.36000","7.03017","0.00262"
"14104","84.58800","7.04919","0.00284"
"14142","84.81600","7.06814","0.00226"
"14180","85.04400","7.08721","0.00256"
"14218","85.27200","7.10617","0.00234"
"14256","85.50000","7.12512","0.00256"
"14294","85.72800","7.14419","0.00267"
"14332","85.95600","7.16320","0.00284"
"14370","86.18400","7.18216","0.00187"
"14408","86.41200","7.20123","0.00258"
"14446","86.64000","7.22018","0.00274"
"14484","86.86800","7.23914","0.00285"
"14522","87.09600","7.25809","0.00289"
"14560","87.32400","7.27722","0.00261"
"14598","87.55200","7.29618","0.00251"
"14636","87.78000","7.31519","0.00233"
"14674","88.00800","7.33414","0.00249"
"14712","88.23600","7.35310","0.00251"
"14750","88.46400","7.37217","0.00332"
"14788","88.69200","7.39118","0.00281"
"14826","88.92000","7.41025","0.00300"
"14864","89.14800","7.42915","0.00150"
"14902","89.37600","7.44816","0.00276"
"14940","89.60400","7.46717","0.00263"
"14978","89.83200","7.48613","0.00302"
"15016","90.06000","7.50514","0.00270"
"15054","90.28800","7.52415","0.00273"
"15092","90.51600","7.54323","0.00313"
"15130","90.74400","7.56218","0.00289"
"15168","90.97200","7.58113","0.00298"
"15206","91.20000","7.60015","0.00282"
"15244","91.42800","7.61910","0.00256"
"15282","91.65600","7.63823","0.00274"
"15320","91.88400","7.65713","0.00284"
"15358","92.11200","7.67620","0.00287"
"15396","92.34000","7.69521","0.00241"
"15434","92.56800","7.71411","0.00287"
"15472","92.79600","7.73324","0.00325"
"15510","93.02400","7.75213","0.00272"
"15548","93.25200","7.77120","0.00251"
"15586","93.48000","7.79016","0.00307"
"15624","93.70800","7.80923","0.00300"
"15662","93.93600","7.82818","0.00276"
"15700","94.16400","7.84714","0.00265"
"15738","94.39200","7.86621","0.00279"
"15776","94.62000","7.88516","0.00307"
"15814","94.84800","7.90418","0.00327"
"15852","95.07600","7.92319","0.00284"
"15890","95.30400","7.94220","0.00284"
"15928","95.53200","7.96122","0.00300"
"15966","95.76000","7.98011","0.00316"
"16004","95.98800","7.99918","0.00273"
"16042","96.21600","8.01814","0.00344"
"16080","96.44400","8.03715","0.00209"
"16118","96.67200","8.05622","0.00257"
"16156","96.90000","8.07517","0.00285"
"16194","97.12800","8.09419","0.00261"
"16232","97.35600","8.11314","0.00250"
"16270","97.58400","8.13221","0.00320"
"16308","97.81200","8.15117","0.00262"
"16346","98.04000","8.17018","0.00286"
"16384","98.26800","8.18919","0.00253"
"16422","98.49600","8.20815","0.00271"
"16460","98.72400","8.22722","0.00342"
"16498","98.95200","8.24617","0.00277"
"16536","99.18000","8.26519","0.00310"
"16574","99.40800","8.28420","0.00275"
"16612","99.63600","8.30315","0.00301"
"16650","99.86400","8.32216","0.00323"
"16688","100.09200","8.34118","0.00255"
"16726","100.32000","8.36019","0.00328"
"16764","100.54800","8.37914","0.00311"
"16802","100.77600","8.39816","0.00290"
"16840","101.00400","8.41717","0.00309"
"16878","101.23200","8.43618","0.00350"
"16916","101.46000","8.45520","0.00342"
"16954","101.68800","8.47415","0.00246"
"16992","101.91600","8.49322","0.00305"
"17030","102.14400","8.51218","0.00326"
"17068","102.37200","8.53119","0.00313"
"17106","102.60000","8.55014","0.00327"
"17144","102.82800","8.56916","0.00358"
"17182","103.05600","8.58823","0.00344"
"17220","103.28400","8.60718","0.00355"
"17258","103.51200","8.62619","0.00384"
"17296","103.74000","8.64515","0.00278"
"17334","103.96800","8.66422","0.00323"
"17372","104.19600","8.68317","0.00300"
"17410","104.42400","8.70219","0.00319"
"17448","104.65200","8.72114","0.00382"
"17486","104.88000","8.74009","0.00257"
"17524","105.10800","8.75917","0.00281"
"17562","105.33600","8.77818","0.00348"
"17600","105.56400","8.79719","0.00352"
"17638","105.79200","8.81615","0.00259"
"17676","106.02000","8.83516","0.00348"
"17714","106.24800","8.85417","0.00322"
"17752","106.47600","8.87313","0.00331"
"17790","106.70400","8.89220","0.00342"
"17828","106.93200","8.91115","0.00383"
"17866","107.16000","8.93016","0.00368"
"17904","107.38800","8.94918","0.00330"
"17942","107.61600","8.96813","0.00330"
"17980","107.84400","8.98720","0.00340"
"18018","108.07200","9.00616","0.00372"
"18056","108.30000","9.02523","0.00298"
"18094","108.52800","9.04412","0.00320"
"18132","108.75600","9.06320","0.00306"
"18170","108.98400","9.08221","0.00285"
"18208","109.21200","9.10110","0.00378"
"18246","109.44000","9.12018","0.00339"
"18284","109.66800","9.13913","0.00343"
"18322","109.89600","9.15820","0.00389"
"18360","110.12400","9.17715","0.00352"
"18398","110.35200","9.19611","0.00315"
"18436","110.58000","9.21518","0.00359"
"18474","110.80800","9.23413","0.00338"
"18512","111.03600","9.25321","0.00390"
"18550","111.26400","9.27210","0.00383"
"18588","111.49200","9.29117","0.00314"
"18626","111.72000","9.31025","0.00344"
"18664","111.94800","9.32914","0.00380"
"18702","112.17600","9.34821","0.00390"
"18740","112.40400","9.36711","0.00384"
"18778","112.63200","9.38618","0.00407"
"18816","112.86000","9.40519","0.00362"
"18854","113.08800","9.42421","0.00394"
"18892","113.31600","9.44322","0.00404"
"18930","113.54400","9.46211","0.00384"
"18968","113.77200","9.48118","0.00384"
"19006","114.00000","9.50014","0.00414"
"19044","114.22800","9.51921","0.00382"
"19082","114.45600","9.53816","0.00398"
"19120","114.68400","9.55718","0.00319"
"19158","114.91200","9.57619","0.00425"
"19196","115.14000","9.59514","0.00331"
"19234","115.36800","9.61416","0.00391"
"19272","115.59600","9.63317","0.00424"
"19310","115.82400","9.65218","0.00321"
"19348","116.05200","9.67120","0.00397"
"19386","116.28000","9.69015","0.00374"
"19424","116.50800","9.70922","0.00402"
"19462","116.73600","9.72812","0.00346"
"19500","116.96400","9.74719","0.00426"
"19538","117.19200","9.76614","0.00421"
"19576","117.42000","9.78521","0.00373"
"19614","117.64800","9.80423","0.00388"
"19652","117.87600","9.82318","0.00401"
"19690","118.10400","9.84219","0.00434"
"19728","118.33200","9.86109","0.00403"
"19766","118.56000","9.88022","0.00434"
"19804","118.78800","9.89917","0.00443"
"19842","119.01600","9.91813","0.00426"
"19880","119.24400","9.93714","0.00441"
"19918","119.47200","9.95615","0.00419"
"19956","119.70000","9.97517","0.00389"
"19994","119.92800","9.99412","0.00421"
"20032","120.15600","10.01319","0.00393"
"20070","120.38400","10.03215","0.00401"
"20108","120.61200","10.05116","0.00469"
"20146","120.84000","10.07023","0.00446"
"20184","121.06800","10.08918","0.00478"
"20222","121.29600","10.10814","0.00501"
"20260","121.52400","10.12715","0.00418"
"20298","121.75200","10.14622","0.00432"
"20336","121.98000","10.16518","0.00405"
"20374","122.20800","10.18419","0.00498"
"20412","122.43600","10.20320","0.00452"
"20450","122.66400","10.22216","0.00454"
"20488","122.89200","10.24117","0.00507"
"20526","123.12000","10.26012","0.00396"
"20564","123.34800","10.27925","0.00441"
"20602","123.57600","10.29815","0.00441"
"20640","123.80400","10.31716","0.00399"
"20678","124.03200","10.33618","0.00371"
"20716","124.26000","10.35513","0.00448"
"20754","124.48800","10.37420","0.00414"
"20792","124.71600","10.39316","0.00422"
"20830","124.94400","10.41223","0.00484"
"20868","125.17200","10.43118","0.00403"
"20906","125.40000","10.45013","0.00441"
"20944","125.62800","10.46921","0.00447"
"20982","125.85600","10.48816","0.00352"
"21020","126.08400","10.50717","0.00427"
"21058","126.31200","10.52619","0.00464"
"21096","126.54000","10.54520","0.00457"
"21134","126.76800","10.56421","0.00414"
"21172","126.99600","10.58311","0.00431"
"21210","127.22400","10.60224","0.00395"
"21248","127.45200","10.62113","0.00435"
"21286","127.68000","10.64027","0.00432"
"21324","127.90800","10.65916","0.00474"
"21362","128.13600","10.67817","0.00461"
"21400","128.36400","10.69724","0.00396"
"21438","128.59200","10.71608","0.00425"
"21476","128.82000","10.73521","0.00487"
"21514","129.04800","10.75416","0.00486"
"21552","129.27600","10.77324","0.00401"
"21590","129.50400","10.79219","0.00497"
"21628","129.73200","10.81120","0.00496"
"21666","129.96000","10.83022","0.00469"
"21704","130.18800","10.84905","0.00500"
"21742","130.41600","10.86818","0.00517"
"21780","130.64400","10.88720","0.00431"
"21818","130.87200","10.90621","0.00486"
"21856","131.10000","10.92516","0.00516"
"21894","131.32800","10.94412","0.00590"
"21932","131.55600","10.96319","0.00483"
"21970","131.78400","10.98214","0.00508"
"22008","132.01200","11.00121","0.00519"
"22046","132.24000","11.02017","0.00554"
"22084","132.46800","11.03918","0.00525"
"22122","132.69600","11.05819","0.00513"
"22160","132.92400","11.07715","0.00543"
"22198","133.15200","11.09616","0.00507"
"22236","133.38000","11.11511","0.00608"
"22274","133.60800","11.13425","0.00602"
"22312","133.83600","11.15320","0.00503"
"22350","134.06400","11.17221","0.00531"
"22388","134.29200","11.19116","0.00526"
"22426","134.52000","11.21012","0.00550"
"22464","134.74800","11.22913","0.00582"
"22502","134.97600","11.24815","0.00563"
"22540","135.20400","11.26722","0.00532"
"22578","135.43200","11.28617","0.00576"
"22616","135.66000","11.30519","0.00545"
"22654","135.88800","11.32420","0.00593"
"22692","136.11600","11.34321","0.00566"
"22730","136.34400","11.36216","0.00522"
"22768","136.57200","11.38118","0.00565"
"22806","136.80000","11.40019","0.00549"
"22844","137.02800","11.41920","0.00584"
"22882","137.25600","11.43816","0.00577"
"22920","137.48400","11.45723","0.00616"
"22958","137.71200","11.47612","0.00581"
"22996","137.94000","11.49514","0.00581"
"23034","138.16800","11.51415","0.00592"
"23072","138.39600","11.53322","0.00591"
"23110","138.62400","11.55218","0.00587"
"23148","138.85200","11.57113","0.00548"
"23186","139.08000","11.59020","0.00576"
"23224","139.30800","11.60915","0.00584"
"23262","139.53600","11.62817","0.00618"
"23300","139.76400","11.64712","0.00613"
"23338","139.99200","11.66625","0.00590"
"23376","140.22000","11.68515","0.00589"
"23414","140.44800","11.70422","0.00575"
"23452","140.67600","11.72317","0.00592"
"23490","140.90400","11.74213","0.00643"
"23528","141.13200","11.76120","0.00627"
"23566","141.36000","11.78015","0.00662"
"23604","141.58800","11.79917","0.00688"
"23642","141.81600","11.81818","0.00612"
"23680","142.04400","11.83713","0.00682"
"23718","142.27200","11.85620","0.00664"
"23756","142.50000","11.87516","0.00642"
"23794","142.72800","11.89423","0.00584"
"23832","142.95600","11.91312","0.00621"
"23870","143.18400","11.93214","0.00668"
"23908","143.41200","11.95121","0.00654"
"23946","143.64000","11.97010","0.00660"
"23984","143.86800","11.98924","0.00624"
"24022","144.09600","12.00813","0.00688"
"24060","144.32400","12.02726","0.00621"
"24098","144.55200","12.04616","0.00669"
"24136","144.78000","12.06517","0.00667"
"24174","145.00800","12.08424","0.00655"
"24212","145.23600","12.10314","0.00704"
"24250","145.46400","12.12221","0.00658"
"24288","145.69200","12.14110","0.00603"
"24326","145.92000","12.16018","0.00693"
"24364","146.14800","12.17925","0.00651"
"24402","146.37600","12.19814","0.00662"
"24440","146.60400","12.21721","0.00673"
"24478","146.83200","12.23617","0.00691"
"24516","147.06000","12.25518","0.00683"
"24554","147.28800","12.27413","0.00684"
"24592","147.51600","12.29315","0.00659"
"24630","147.74400","12.31222","0.00626"
"24668","147.97200","12.33111","0.00667"
"24706","148.20000","12.35018","0.00666"
"24744","148.42800","12.36920","0.00687"
"24782","148.65600","12.38815","0.00665"
"24820","148.88400","12.40716","0.00673"
"24858","149.11200","12.42618","0.00641"
"24896","149.34000","12.44519","0.00691"
"24934","149.56800","12.46409","0.00664"
"24972","149.79600","12.48316","0.00648"
"25010","150.02400","12.50217","0.00706"
"25048","150.25200","12.52118","0.00635"
"25086","150.48000","12.54020","0.00621"
"25124","150.70800","12.55915","0.00670"
"25162","150.93600","12.57816","0.00647"
"25200","151.16400","12.59712","0.00690"
"25238","151.39200","12.61619","0.00684"
"25276","151.62000","12.63514","0.00644"
"25314","151.84800","12.65421","0.00713"
"25352","152.07600","12.67317","0.00674"
"25390","152.30400","12.69212","0.00666"
"25428","152.53200","12.71119","0.00654"
"25466","152.76000","12.73015","0.00654"
"25504","152.98800","12.74922","0.00651"
"25542","153.21600","12.76817","0.00674"
"25580","153.44400","12.78713","0.00627"
"25618","153.67200","12.80620","0.00746"
"25656","153.90000","12.82515","0.00721"
"25694","154.12800","12.84423","0.00695"
"25732","154.35600","12.86312","0.00742"
"25770","154.58400","12.88219","0.00703"
"25808","154.81200","12.90121","0.00701"
"25846","155.04000","12.92016","0.00712"
"25884","155.26800","12.93917","0.00632"
"25922","155.49600","12.95819","0.00692"
"25960","155.72400","12.97714","0.00729"
"25998","155.95200","12.99615","0.00698"
"26036","156.18000","13.01522","0.00675"
"26074","156.40800","13.03418","0.00690"
"26112","156.63600","13.05319","0.00698"
"26150","156.86400","13.07215","0.00690"
"26188","157.09200","13.09116","0.00671"
"26226","157.32000","13.11017","0.00701"
"26264","157.54800","13.12918","0.00712"
"26302","157.77600","13.14820","0.00727"
"26340","158.00400","13.16721","0.00750"
"26378","158.23200","13.18616","0.00748"
"26416","158.46000","13.20518","0.00749"
"26454","158.68800","13.22419","0.00704"
"26492","158.91600","13.24320","0.00731"
"26530","159.14400","13.26216","0.00761"
"26568","159.37200","13.28123","0.00716"
"26606","159.60000","13.30018","0.00753"
"26644","159.82800","13.31913","0.00731"
"26682","160.05600","13.33815","0.00727"
"26720","160.28400","13.35710","0.00699"
"26758","160.51200","13.37623","0.00757"
"26796","160.74000","13.39519","0.00757"
"26834","160.96800","13.41426","0.00716"
"26872","161.19600","13.43321","0.00762"
"26910","161.42400","13.45211","0.00758"
"26948","161.65200","13.47124","0.00749"
"26986","161.88000","13.49019","0.00727"
"27024","162.10800","13.50921","0.00770"
"27062","162.33600","13.52816","0.00764"
"27100","162.56400","13.54717","0.00753"
"27138","162.79200","13.56625","0.00779"
"27176","163.02000","13.58508","0.00724"
"27214","163.24800","13.60421","0.00787"
"27252","163.47600","13.62311","0.00754"
"27290","163.70400","13.64218","0.00759"
"27328","163.93200","13.66119","0.00794"
"27366","164.16000","13.68015","0.00817"
"27404","164.38800","13.69922","0.00830"
"27442","164.61600","13.71811","0.00772"
"27480","164.84400","13.73718","0.00740"
"27518","165.07200","13.75614","0.00735"
"27556","165.30000","13.77521","0.00758"
"27594","165.52800","13.79422","0.00786"
"27632","165.75600","13.81318","0.00729"
"27670","165.98400","13.83219","0.00812"
"27708","166.21200","13.85114","0.00821"
"27746","166.44000","13.87022","0.00812"
"27784","166.66800","13.88917","0.00794"
"27822","166.89600","13.90818","0.00823"
"27860","167.12400","13.92719","0.00790"
"27898","167.35200","13.94615","0.00795"
"27936","167.58000","13.96522","0.00717"
"27974","167.80800","13.98411","0.00754"
"28012","168.03600","14.00319","0.00685"
"28050","168.26400","14.02220","0.00749"
"28088","168.49200","14.04115","0.00726"
"28126","168.72000","14.06023","0.00699"
"28164","168.94800","14.07912","0.00691"
"28202","169.17600","14.09819","0.00687"
"28240","169.40400","14.11715","0.00715"
"28278","169.63200","14.13622","0.00677"
"28316","169.86000","14.15517","0.00745"
"28354","170.08800","14.17418","0.00749"
"28392","170.31600","14.19320","0.00671"
"28430","170.54400","14.21215","0.00741"
"28468","170.77200","14.23116","0.00667"
"28506","171.00000","14.25012","0.00713"
"28544","171.22800","14.26919","0.00648"
"28582","171.45600","14.28820","0.00737"
"28620","171.68400","14.30716","0.00704"
"28658","171.91200","14.32623","0.00680"
"28696","172.14000","14.34518","0.00665"
"28734","172.36800","14.36414","0.00704"
"28772","172.59600","14.38321","0.00704"
"28810","172.82400","14.40216","0.00647"
"28848","173.05200","14.42118","0.00728"
"28886","173.28000","14.44019","0.00743"
"28924","173.50800","14.45920","0.00693"
"28962","173.73600","14.47815","0.00658"
"29000","173.96400","14.49717","0.00621"
"29038","174.19200","14.51618","0.00625"
"29076","174.42000","14.53519","0.00645"
"29114","174.64800","14.55415","0.00617"
"29152","174.87600","14.57316","0.00568"
"29190","175.10400","14.59217","0.00607"
"29228","175.33200","14.61119","0.00625"
"29266","175.56000","14.63020","0.00647"
"29304","175.78800","14.64915","0.00593"
"29342","176.01600","14.66817","0.00623"
"29380","176.24400","14.68718","0.00586"
"29418","176.47200","14.70619","0.00609"
"29456","176.70000","14.72521","0.00658"
"29494","176.92800","14.74410","0.00617"
"29532","177.15600","14.76323","0.00647"
"29570","177.38400","14.78218","0.00665"
"29608","177.61200","14.80114","0.00666"
"29646","177.84000","14.82021","0.00638"
"29684","178.06800","14.83911","0.00634"
"29722","178.29600","14.85824","0.00685"
"29760","178.52400","14.87713","0.00626"
"29798","178.75200","14.89620","0.00651"
"29836","178.98000","14.91516","0.00669"
"29874","179.20800","14.93417","0.00639"
"29912","179.43600","14.95318","0.00654"
"29950","179.66400","14.97214","0.00669"
"29988","179.89200","14.99121","0.00658"
"30026","180.12000","15.01010","0.00642"
"30064","180.34800","15.02918","0.00650"
"30102","180.57600","15.04819","0.00673"
"30140","180.80400","15.06714","0.00686"
"30178","181.03200","15.08622","0.00602"
"30216","181.26000","15.10511","0.00654"
"30254","181.48800","15.12418","0.00683"
"30292","181.71600","15.14319","0.00721"
"30330","181.94400","15.16221","0.00648"
"30368","182.17200","15.18122","0.00677"
"30406","182.40000","15.20012","0.00660"
"30444","182.62800","15.21919","0.00662"
"30482","182.85600","15.23820","0.00656"
"30520","183.08400","15.25721","0.00655"
"30558","183.31200","15.27617","0.00647"
"30596","183.54000","15.29518","0.00674"
"30634","183.76800","15.31419","0.00652"
"30672","183.99600","15.33309","0.00656"
"30710","184.22400","15.35216","0.00719"
"30748","184.45200","15.37111","0.00671"
"30786","184.68000","15.39018","0.00661"
"30824","184.90800","15.40926","0.00695"
"30862","185.13600","15.42815","0.00725"
"30900","185.36400","15.44716","0.00673"
"30938","185.59200","15.46612","0.00654"
"30976","185.82000","15.48519","0.00651"
"31014","186.04800","15.50420","0.00665"
"31052","186.27600","15.52322","0.00660"
"31090","186.50400","15.54217","0.00567"
"31128","186.73200","15.56112","0.00683"
"31166","186.96000","15.58020","0.00643"
"31204","187.18800","15.59915","0.00631"
"31242","187.41600","15.61822","0.00640"
"31280","187.64400","15.63723","0.00633"
"31318","187.87200","15.65613","0.00655"
"31356","188.10000","15.67520","0.00658"
"31394","188.32800","15.69415","0.00607"
"31432","188.55600","15.71317","0.00710"
"31470","188.78400","15.73212","0.00668"
"31508","189.01200","15.75119","0.00629"
"31546","189.24000","15.77021","0.00655"
"31584","189.46800","15.78916","0.00687"
"31622","189.69600","15.80823","0.00644"
"31660","189.92400","15.82719","0.00710"
"31698","190.15200","15.84614","0.00700"
"31736","190.38000","15.86509","0.00657"
"31774","190.60800","15.88422","0.00605"
"31812","190.83600","15.90318","0.00668"
"31850","191.06400","15.92219","0.00666"
"31888","191.29200","15.94120","0.00674"
"31926","191.52000","15.96016","0.00653"
"31964","191.74800","15.97917","0.00635"
"32002","191.97600","15.99818","0.00661"
"32040","192.20400","16.01720","0.00686"
"32078","192.43200","16.03615","0.00645"
"32116","192.66000","16.05522","0.00648"
"32154","192.88800","16.07418","0.00688"
"32192","193.11600","16.09319","0.00606"
"32230","193.34400","16.11220","0.00695"
"32268","193.57200","16.13116","0.00570"
"32306","193.80000","16.15023","0.00650"
"32344","194.02800","16.16918","0.00668"
"32382","194.25600","16.18814","0.00633"
"32420","194.48400","16.20721","0.00634"
"32458","194.71200","16.22610","0.00619"
"32496","194.94000","16.24524","0.00644"
"32534","195.16800","16.26413","0.00675"
"32572","195.39600","16.28320","0.00661"
"32610","195.62400","16.30221","0.00662"
"32648","195.85200","16.32111","0.00616"
"32686","196.08000","16.34024","0.00681"
"32724","196.30800","16.35919","0.00663"
"32762","196.53600","16.37827","0.00652"
"32800","196.76400","16.39716","0.00602"
"32838","196.99200","16.41617","0.00647"
"32876","197.22000","16.43519","0.00641"
"32914","197.44800","16.45414","0.00648"
"32952","197.67600","16.47321","0.00672"
"32990","197.90400","16.49217","0.00609"
"33028","198.13200","16.51118","0.00650"
"33066","198.36000","16.53019","0.00647"
"33104","198.58800","16.54914","0.00583"
"33142","198.81600","16.56822","0.00600"
"33180","199.04400","16.58711","0.00673"
"33218","199.27200","16.60624","0.00613"
"33256","199.50000","16.62520","0.00613"
"33294","199.72800","16.64421","0.00595"
"33332","199.95600","16.66316","0.00639"
"33370","200.18400","16.68212","0.00643"
"33408","200.41200","16.70125","0.00602"
"33446","200.64000","16.72014","0.00633"
"33484","200.86800","16.73922","0.00639"
"33522","201.09600","16.75817","0.00630"
"33560","201.32400","16.77718","0.00636"
"33598","201.55200","16.79620","0.00636"
"33636","201.78000","16.81515","0.00611"
"33674","202.00800","16.83416","0.00645"
"33712","202.23600","16.85312","0.00605"
"33750","202.46400","16.87225","0.00604"
"33788","202.69200","16.89120","0.00545"
"33826","202.92000","16.91021","0.00576"
"33864","203.14800","16.92917","0.00609"
"33902","203.37600","16.94812","0.00597"
"33940","203.60400","16.96719","0.00609"
"33978","203.83200","16.98615","0.00619"
"34016","204.06000","17.00522","0.00589"
"34054","204.28800","17.02423","0.00568"
"34092","204.51600","17.04313","0.00642"
"34130","204.74400","17.06220","0.00631"
"34168","204.97200","17.08115","0.00614"
"34206","205.20000","17.10016","0.00640"
"34244","205.42800","17.11918","0.00598"
"34282","205.65600","17.13813","0.00631"
"34320","205.88400","17.15720","0.00616"
"34358","206.11200","17.17616","0.00622"
"34396","206.34000","17.19517","0.00633"
"34434","206.56800","17.21418","0.00643"
"34472","206.79600","17.23314","0.00647"
"34510","207.02400","17.25215","0.00611"
"34548","207.25200","17.27116","0.00606"
"34586","207.48000","17.29024","0.00590"
"34624","207.70800","17.30913","0.00653"
"34662","207.93600","17.32820","0.00631"
"34700","208.16400","17.34715","0.00677"
"34738","208.39200","17.36617","0.00601"
"34776","208.62000","17.38518","0.00630"
"34814","208.84800","17.40420","0.00576"
"34852","209.07600","17.42315","0.00620"
"34890","209.30400","17.44216","0.00653"
"34928","209.53200","17.46118","0.00616"
"34966","209.76000","17.48013","0.00630"
"35004","209.98800","17.49920","0.00555"
"35042","210.21600","17.51809","0.00593"
"35080","210.44400","17.53723","0.00572"
"35118","210.67200","17.55618","0.00595"
"35156","210.90000","17.57513","0.00584"
"35194","211.12800","17.59414","0.00553"
"35232","211.35600","17.61316","0.00590"
"35270","211.58400","17.63223","0.00604"
"35308","211.81200","17.65119","0.00566"
"35346","212.04000","17.67020","0.00601"
"35384","212.26800","17.68921","0.00570"
"35422","212.49600","17.70811","0.00562"
"35460","212.72400","17.72724","0.00587"
"35498","212.95200","17.74613","0.00597"
"35536","213.18000","17.76520","0.00594"
"35574","213.40800","17.78416","0.00574"
"35612","213.63600","17.80317","0.00597"
"35650","213.86400","17.82218","0.00602"
"35688","214.09200","17.84114","0.00527"
"35726","214.32000","17.86021","0.00544"
"35764","214.54800","17.87910","0.00586"
"35802","214.77600","17.89824","0.00584"
"35840","215.00400","17.91719","0.00584"
"35878","215.23200","17.93614","0.00571"
"35916","215.46000","17.95516","0.00621"
"35954","215.68800","17.97417","0.00599"
"35992","215.91600","17.99318","0.00604"
"36030","216.14400","18.01213","0.00564"
"36068","216.37200","18.03115","0.00531"
"36106","216.60000","18.05022","0.00556"
"36144","216.82800","18.06911","0.00581"
"36182","217.05600","18.08819","0.00564"
"36220","217.28400","18.10714","0.00551"
"36258","217.51200","18.12615","0.00586"
"36296","217.74000","18.14517","0.00565"
"36334","217.96800","18.16412","0.00606"
"36372","218.19600","18.18319","0.00555"
"36410","218.42400","18.20215","0.00560"
"36448","218.65200","18.22122","0.00601"
"36486","218.88000","18.24011","0.00590"
"36524","219.10800","18.25918","0.00558"
"36562","219.33600","18.27814","0.00606"
"36600","219.56400","18.29715","0.00617"
"36638","219.79200","18.31623","0.00578"
"36676","220.02000","18.33512","0.00638"
"36714","220.24800","18.35425","0.00654"
"36752","220.47600","18.37314","0.00632"
"36790","220.70400","18.39216","0.00626"
"36828","220.93200","18.41123","0.00614"
"36866","221.16000","18.43012","0.00606"
"36904","221.38800","18.44926","0.00592"
"36942","221.61600","18.46815","0.00502"
"36980","221.84400","18.48722","0.00556"
"37018","222.07200","18.50624","0.00522"
"37056","222.30000","18.52519","0.00572"
"37094","222.52800","18.54420","0.00535"
"37132","222.75600","18.56310","0.00565"
"37170","222.98400","18.58223","0.00552"
"37208","223.21200","18.60112","0.00571"
"37246","223.44000","18.62013","0.00574"
"37284","223.66800","18.63921","0.00531"
"37322","223.89600","18.65810","0.00496"
"37360","224.12400","18.67717","0.00581"
"37398","224.35200","18.69613","0.00546"
"37436","224.58000","18.71514","0.00562"
"37474","224.80800","18.73415","0.00597"
"37512","225.03600","18.75323","0.00582"
"37550","225.26400","18.77224","0.00556"
"37588","225.49200","18.79113","0.00592"
"37626","225.72000","18.81015","0.00590"
"37664","225.94800","18.82916","0.00591"
"37702","226.17600","18.84817","0.00559"
"37740","226.40400","18.86713","0.00616"
"37778","226.63200","18.88620","0.00572"
"37816","226.86000","18.90515","0.00590"
"37854","227.08800","18.92416","0.00633"
"37892","227.31600","18.94318","0.00620"
"37930","227.54400","18.96213","0.00566"
"37968","227.77200","18.98120","0.00567"
"38006","228.00000","19.00022","0.00566"
"38044","228.22800","19.01923","0.00581"
"38082","228.45600","19.03818","0.00592"
"38120","228.68400","19.05714","0.00575"
"38158","228.91200","19.07615","0.00503"
"38196","229.14000","19.09516","0.00600"
"38234","229.36800","19.11423","0.00621"
"38272","229.59600","19.13313","0.00614"
"38310","229.82400","19.15220","0.00631"
"38348","230.05200","19.17122","0.00581"
"38386","230.28000","19.19011","0.00628"
"38424","230.50800","19.20918","0.00550"
"38462","230.73600","19.22813","0.00588"
"38500","230.96400","19.24721","0.00564"
"38538","231.19200","19.26616","0.00607"
"38576","231.42000","19.28517","0.00607"
"38614","231.64800","19.30419","0.00618"
"38652","231.87600","19.32314","0.00573"
"38690","232.10400","19.34221","0.00607"
"38728","232.33200","19.36117","0.00573"
"38766","232.56000","19.38024","0.00610"
"38804","232.78800","19.39919","0.00588"
"38842","233.01600","19.41821","0.00629"
"38880","233.24400","19.43716","0.00596"
"38918","233.47200","19.45611","0.00607"
"38956","233.70000","19.47524","0.00601"
"38994","233.92800","19.49414","0.00606"
"39032","234.15600","19.51321","0.00624"
"39070","234.38400","19.53216","0.00645"
"39108","234.61200","19.55118","0.00585"
"39146","234.84000","19.57019","0.00630"
"39184","235.06800","19.58914","0.00671"
"39222","235.29600","19.60822","0.00685"
"39260","235.52400","19.62711","0.00595"
"39298","235.75200","19.64618","0.00649"
"39336","235.98000","19.66514","0.00630"
"39374","236.20800","19.68415","0.00644"
"39412","236.43600","19.70316","0.00621"
"39450","236.66400","19.72211","0.00653"
"39488","236.89200","19.74125","0.00642"
"39526","237.12000","19.76020","0.00608"
"39564","237.34800","19.77915","0.00663"
"39602","237.57600","19.79823","0.00609"
"39640","237.80400","19.81712","0.00655"
"39678","238.03200","19.83619","0.00603"
"39716","238.26000","19.85515","0.00652"
"39754","238.48800","19.87422","0.00634"
"39792","238.71600","19.89317","0.00610"
"39830","238.94400","19.91207","0.00627"
"39868","239.17200","19.93120","0.00595"
"39906","239.40000","19.95015","0.00658"
"39944","239.62800","19.96917","0.00695"
"39982","239.85600","19.98812","0.00668"
"40020","240.08400","20.00719","0.00647"
"40058","240.31200","20.02620","0.00637"
"40096","240.54000","20.04510","0.00688"
"40134","240.76800","20.06423","0.00670"
"40172","240.99600","20.08319","0.00710"
"40210","241.22400","20.10220","0.00610"
"40248","241.45200","20.12121","0.00654"
"40286","241.68000","20.14016","0.00696"
"40324","241.90800","20.15918","0.00610"
"40362","242.13600","20.17813","0.00643"
"40400","242.36400","20.19720","0.00631"
"40438","242.59200","20.21622","0.00671"
"40476","242.82000","20.23517","0.00702"
"40514","243.04800","20.25418","0.00734"
"40552","243.27600","20.27313","0.00687"
"40590","243.50400","20.29221","0.00693"
"40628","243.73200","20.31116","0.00635"
"40666","243.96000","20.33023","0.00647"
"40704","244.18800","20.34913","0.00652"
"40742","244.41600","20.36820","0.00671"
"40780","244.64400","20.38715","0.00696"
"40818","244.87200","20.40617","0.00633"
"40856","245.10000","20.42518","0.00677"
"40894","245.32800","20.44413","0.00717"
"40932","245.55600","20.46315","0.00649"
"40970","245.78400","20.48216","0.00701"
"41008","246.01200","20.50123","0.00668"
"41046","246.24000","20.52013","0.00668"
"41084","246.46800","20.53920","0.00602"
"41122","246.69600","20.55821","0.00658"
"41160","246.92400","20.57711","0.00665"
"41198","247.15200","20.59618","0.00721"
"41236","247.38000","20.61519","0.00658"
"41274","247.60800","20.63421","0.00675"
"41312","247.83600","20.65316","0.00669"
"41350","248.06400","20.67217","0.00667"
"41388","248.29200","20.69118","0.00662"
"41426","248.52000","20.71014","0.00732"
"41464","248.74800","20.72921","0.00643"
"41502","248.97600","20.74817","0.00709"
"41540","249.20400","20.76724","0.00736"
"41578","249.43200","20.78619","0.00755"
"41616","249.66000","20.80514","0.00687"
"41654","249.88800","20.82422","0.00662"
"41692","250.11600","20.84317","0.00703"
"41730","250.34400","20.86224","0.00750"
"41768","250.57200","20.88114","0.00770"
"41806","250.80000","20.90015","0.00704"
"41844","251.02800","20.91922","0.00706"
"41882","251.25600","20.93812","0.00707"
"41920","251.48400","20.95719","0.00644"
"41958","251.71200","20.97620","0.00737"
"41996","251.94000","20.99516","0.00705"
"42034","252.16800","21.01417","0.00647"
"42072","252.39600","21.03312","0.00678"
"42110","252.62400","21.05219","0.00727"
"42148","252.85200","21.07115","0.00745"
"42186","253.08000","21.09022","0.00705"
"42224","253.30800","21.10911","0.00677"
"42262","253.53600","21.12819","0.00696"
"42300","253.76400","21.14720","0.00717"
"42338","253.99200","21.16615","0.00720"
"42376","254.22000","21.18517","0.00739"
"42414","254.44800","21.20412","0.00672"
"42452","254.67600","21.22319","0.00688"
"42490","254.90400","21.24215","0.00707"
"42528","255.13200","21.26116","0.00732"
"42566","255.36000","21.28023","0.00708"
"42604","255.58800","21.29913","0.00688"
"42642","255.81600","21.31820","0.00630"
"42680","256.04400","21.33715","0.00729"
"42718","256.27200","21.35622","0.00670"
"42756","256.50000","21.37518","0.00671"
"42794","256.72800","21.39413","0.00680"
"42832","256.95600","21.41320","0.00670"
"42870","257.18400","21.43210","0.00691"
"42908","257.41200","21.45117","0.00725"
"42946","257.64000","21.47012","0.00784"
"42984","257.86800","21.48919","0.00698"
"43022","258.09600","21.50821","0.00690"
"43060","258.32400","21.52716","0.00764"
"43098","258.55200","21.54623","0.00648"
"43136","258.78000","21.56513","0.00716"
"43174","259.00800","21.58414","0.00737"
"43212","259.23600","21.60315","0.00693"
"43250","259.46400","21.62217","0.00737"
"43288","259.69200","21.64124","0.00688"
"43326","259.92000","21.66013","0.00705"
"43364","260.14800","21.67914","0.00712"
"43402","260.37600","21.69816","0.00687"
"43440","260.60400","21.71723","0.00724"
"43478","260.83200","21.73619","0.00740"
"43516","261.06000","21.75520","0.00688"
"43554","261.28800","21.77415","0.00758"
"43592","261.51600","21.79317","0.00747"
"43630","261.74400","21.81218","0.00709"
"43668","261.97200","21.83119","0.00709"
"43706","262.20000","21.85014","0.00524"
"43744","262.42800","21.86910","0.00788"
"43782","262.65600","21.88823","0.00321"
"43820","262.88400","21.90724","0.00709"
"43858","263.11200","21.92614","0.00409"
"43896","263.34000","21.94521","0.00663"
"43934","263.56800","21.96416","0.00489"
"43972","263.79600","21.98324","0.00538"
"44010","264.02400","22.00219","0.00524"
"44048","264.25200","22.02120","0.00691"
"44086","264.48000","22.04022","0.00462"
"44124","264.70800","22.05911","0.00669"
"44162","264.93600","22.07818","0.00508"
"44200","265.16400","22.09714","0.00581"
"44238","265.39200","22.11621","0.01189"
"44276","265.62000","22.13516","0.00487"
"44314","265.84800","22.15417","0.00605"
"44352","266.07600","22.17319","0.00770"
"44390","266.30400","22.19214","0.00433"
"44428","266.53200","22.21121","0.00666"
"44466","266.76000","22.23017","0.00655"
"44504","266.98800","22.24912","0.00243"
"44542","267.21600","22.26819","0.00334"
"44580","267.44400","22.28720","0.00300"
"44618","267.67200","22.30622","0.00264"
"44656","267.90000","22.32511","0.00236"
"44694","268.12800","22.34425","0.00263"
"44732","268.35600","22.36320","0.00447"
"44770","268.58400","22.38215","0.00428"
"44808","268.81200","22.40117","0.00392"
"44846","269.04000","22.42012","0.00448"
"44884","269.26800","22.43925","0.00248"
"44922","269.49600","22.45815","0.00236"
"44960","269.72400","22.47722","0.00191"
"44998","269.95200","22.49611","0.00173"
"45036","270.18000","22.51512","0.00177"
"45074","270.40800","22.53414","0.00205"
"45112","270.63600","22.55315","0.00245"
"45150","270.86400","22.57216","0.00346"
"45188","271.09200","22.59112","0.00382"
"45226","271.32000","22.61025","0.00336"
"45264","271.54800","22.62914","0.00456"
"45302","271.77600","22.64816","0.00462"
"45340","272.00400","22.66717","0.00245"
"45378","272.23200","22.68612","0.00385"
"45416","272.46000","22.70520","0.00251"
"45454","272.68800","22.72415","0.00310"
"45492","272.91600","22.74316","0.00409"
"45530","273.14400","22.76223","0.00380"
"45568","273.37200","22.78113","0.00390"
"45606","273.60000","22.80020","0.00406"
"45644","273.82800","22.81909","0.00422"
"45682","274.05600","22.83823","0.00355"
"45720","274.28400","22.85712","0.00305"
"45758","274.51200","22.87613","0.00438"
"45796","274.74000","22.89521","0.00373"
"45834","274.96800","22.91410","0.00329"
"45872","275.19600","22.93323","0.00441"
"45910","275.42400","22.95213","0.00457"
"45948","275.65200","22.97120","0.00370"
"45986","275.88000","22.99021","0.00419"
"46024","276.10800","23.00923","0.00362"
"46062","276.33600","23.02824","0.00414"
"46100","276.56400","23.04713","0.00378"
"46138","276.79200","23.06614","0.00384"
"46176","277.02000","23.08516","0.00436"
"46214","277.24800","23.10417","0.00415"
"46252","277.47600","23.12318","0.00443"
"46290","277.70400","23.14214","0.00444"
"46328","277.93200","23.16121","0.00458"
"46366","278.16000","23.18016","0.00332"
"46404","278.38800","23.19917","0.00411"
"46442","278.61600","23.21813","0.00399"
"46480","278.84400","23.23720","0.00410"
"46518","279.07200","23.25622","0.00450"
"46556","279.30000","23.27517","0.00486"
"46594","279.52800","23.29418","0.00440"
"46632","279.75600","23.31307","0.00398"
"46670","279.98400","23.33227","0.00403"
"46708","280.21200","23.35116","0.00384"
"46746","280.44000","23.37023","0.00437"
"46784","280.66800","23.38919","0.00417"
"46822","280.89600","23.40820","0.00382"
"46860","281.12400","23.42715","0.00457"
"46893","281.31800","23.44336","0.00430"