File: Trajectories_together/170212_3Specimen_RawData_2.csv
"","V1","V2","V3"
"1","End date","2/12/2017",""
"2","Specimen label","13BG_6",""
"3","Maximum Load","0.00360","N"
"4","Time","Extension","Load"
"5","(s)","(mm)","(N)"
"6","0.00000","0.00000","-0.00006"
"20","0.08400","0.00263","0.00028"
"34","0.16800","0.01046","0.00047"
"48","0.25200","0.01967","0.00035"
"62","0.33600","0.02786","-0.00021"
"76","0.42000","0.03534","-0.00017"
"90","0.50400","0.04233","0.00024"
"104","0.58800","0.04933","0.00024"
"118","0.67200","0.05626","0.00026"
"132","0.75600","0.06326","0.00004"
"146","0.84000","0.07025","0.00052"
"160","0.92400","0.07719","-0.00045"
"174","1.00800","0.08424","0.00049"
"188","1.09200","0.09130","0.00016"
"202","1.17600","0.09823","-0.00023"
"216","1.26000","0.10523","0.00007"
"230","1.34400","0.11222","0.00015"
"244","1.42800","0.11922","0.00030"
"258","1.51200","0.12622","0.00044"
"272","1.59600","0.13321","0.00049"
"286","1.68000","0.14027","0.00004"
"300","1.76400","0.14726","0.00009"
"314","1.84800","0.15426","0.00045"
"328","1.93200","0.16119","-0.00007"
"342","2.01600","0.16819","0.00001"
"356","2.10000","0.17524","0.00021"
"370","2.18400","0.18224","-0.00016"
"384","2.26800","0.18929","0.00022"
"398","2.35200","0.19623","0.00000"
"412","2.43600","0.20322","0.00044"
"426","2.52000","0.21016","0.00027"
"440","2.60400","0.21722","0.00071"
"454","2.68800","0.22427","-0.00048"
"468","2.77200","0.23121","0.00048"
"482","2.85600","0.23826","0.00058"
"496","2.94000","0.24520","0.00054"
"510","3.02400","0.25219","0.00019"
"524","3.10800","0.25919","-0.00018"
"538","3.19200","0.26618","0.00055"
"552","3.27600","0.27324","0.00007"
"566","3.36000","0.28023","0.00007"
"580","3.44400","0.28723","0.00016"
"594","3.52800","0.29422","0.00031"
"608","3.61200","0.30116","0.00035"
"622","3.69600","0.30822","-0.00014"
"636","3.78000","0.31527","0.00050"
"650","3.86400","0.32227","-0.00049"
"664","3.94800","0.32926","0.00010"
"678","4.03200","0.33620","0.00038"
"692","4.11600","0.34319","0.00021"
"706","4.20000","0.35019","0.00052"
"720","4.28400","0.35718","0.00055"
"734","4.36800","0.36424","0.00060"
"748","4.45200","0.37123","0.00059"
"762","4.53600","0.37823","0.00002"
"776","4.62000","0.38522","-0.00006"
"790","4.70400","0.39216","0.00000"
"804","4.78800","0.39921","0.00041"
"818","4.87200","0.40621","0.00045"
"832","4.95600","0.41321","0.00002"
"846","5.04000","0.42026","0.00000"
"860","5.12400","0.42720","-0.00034"
"874","5.20800","0.43419","0.00069"
"888","5.29200","0.44125","0.00041"
"902","5.37600","0.44824","0.00020"
"916","5.46000","0.45518","0.00055"
"930","5.54400","0.46229","0.00000"
"944","5.62800","0.46923","0.00033"
"958","5.71200","0.47616","0.00035"
"972","5.79600","0.48316","-0.00011"
"986","5.88000","0.49021","0.00032"
"1000","5.96400","0.49727","0.00003"
"1014","6.04800","0.50426","0.00050"
"1028","6.13200","0.51126","0.00068"
"1042","6.21600","0.51826","-0.00003"
"1056","6.30000","0.52519","0.00064"
"1070","6.38400","0.53219","0.00020"
"1084","6.46800","0.53924","0.00005"
"1098","6.55200","0.54630","0.00034"
"1112","6.63600","0.55323","0.00031"
"1126","6.72000","0.56023","0.00058"
"1140","6.80400","0.56722","0.00102"
"1154","6.88800","0.57416","-0.00007"
"1168","6.97200","0.58127","0.00000"
"1182","7.05600","0.58827","0.00001"
"1196","7.14000","0.59526","0.00092"
"1210","7.22400","0.60220","0.00019"
"1224","7.30800","0.60920","0.00051"
"1238","7.39200","0.61619","0.00036"
"1252","7.47600","0.62319","0.00099"
"1266","7.56000","0.63030","0.00042"
"1280","7.64400","0.63718","0.00023"
"1294","7.72800","0.64423","0.00046"
"1308","7.81200","0.65117","0.00025"
"1322","7.89600","0.65816","0.00080"
"1336","7.98000","0.66522","0.00010"
"1350","8.06400","0.67221","0.00021"
"1364","8.14800","0.67927","0.00034"
"1378","8.23200","0.68626","0.00008"
"1392","8.31600","0.69320","0.00007"
"1406","8.40000","0.70020","0.00078"
"1420","8.48400","0.70719","0.00019"
"1434","8.56800","0.71425","0.00051"
"1448","8.65200","0.72124","0.00080"
"1462","8.73600","0.72824","0.00000"
"1476","8.82000","0.73529","0.00061"
"1490","8.90400","0.74223","0.00023"
"1504","8.98800","0.74922","0.00162"
"1518","9.07200","0.75622","0.00055"
"1532","9.15600","0.76327","0.00045"
"1546","9.24000","0.77021","0.00053"
"1560","9.32400","0.77726","0.00048"
"1574","9.40800","0.78426","0.00065"
"1588","9.49200","0.79119","0.00051"
"1602","9.57600","0.79819","0.00060"
"1616","9.66000","0.80525","0.00103"
"1630","9.74400","0.81230","0.00010"
"1644","9.82800","0.81924","0.00006"
"1658","9.91200","0.82623","0.00041"
"1672","9.99600","0.83323","0.00002"
"1686","10.08000","0.84022","0.00037"
"1700","10.16400","0.84722","0.00068"
"1714","10.24800","0.85427","0.00037"
"1728","10.33200","0.86127","0.00037"
"1742","10.41600","0.86826","0.00076"
"1756","10.50000","0.87520","0.00046"
"1770","10.58400","0.88225","0.00013"
"1784","10.66800","0.88919","0.00053"
"1798","10.75200","0.89625","0.00097"
"1812","10.83600","0.90330","0.00092"
"1826","10.92000","0.91024","0.00038"
"1840","11.00400","0.91729","0.00019"
"1854","11.08800","0.92417","0.00045"
"1868","11.17200","0.93116","0.00062"
"1882","11.25600","0.93822","0.00064"
"1896","11.34000","0.94527","0.00121"
"1910","11.42400","0.95233","0.00039"
"1924","11.50800","0.95920","0.00077"
"1938","11.59200","0.96626","0.00070"
"1952","11.67600","0.97313","0.00069"
"1966","11.76000","0.98025","0.00030"
"1980","11.84400","0.98724","0.00043"
"1994","11.92800","0.99424","0.00058"
"2008","12.01200","1.00130","0.00006"
"2022","12.09600","1.00823","0.00062"
"2036","12.18000","1.01517","0.00037"
"2050","12.26400","1.02216","0.00083"
"2064","12.34800","1.02916","0.00074"
"2078","12.43200","1.03621","0.00021"
"2092","12.51600","1.04327","0.00054"
"2106","12.60000","1.05026","0.00032"
"2120","12.68400","1.05720","0.00069"
"2134","12.76800","1.06413","0.00022"
"2148","12.85200","1.07125","0.00061"
"2162","12.93600","1.07818","0.00068"
"2176","13.02000","1.08530","0.00026"
"2190","13.10400","1.09224","0.00062"
"2204","13.18800","1.09923","0.00062"
"2218","13.27200","1.10623","0.00038"
"2232","13.35600","1.11316","0.00037"
"2246","13.44000","1.12022","0.00066"
"2260","13.52400","1.12721","0.00046"
"2274","13.60800","1.13427","0.00083"
"2288","13.69200","1.14120","0.00085"
"2302","13.77600","1.14820","0.00047"
"2316","13.86000","1.15519","0.00046"
"2330","13.94400","1.16225","0.00074"
"2344","14.02800","1.16924","0.00062"
"2358","14.11200","1.17624","0.00036"
"2372","14.19600","1.18329","0.00054"
"2386","14.28000","1.19023","0.00066"
"2400","14.36400","1.19717","0.00042"
"2414","14.44800","1.20422","0.00032"
"2428","14.53200","1.21122","0.00069"
"2442","14.61600","1.21827","0.00032"
"2456","14.70000","1.22521","0.00114"
"2470","14.78400","1.23226","0.00018"
"2484","14.86800","1.23926","0.00051"
"2498","14.95200","1.24613","0.00030"
"2512","15.03600","1.25325","0.00074"
"2526","15.12000","1.26024","0.00031"
"2540","15.20400","1.26724","0.00049"
"2554","15.28800","1.27423","0.00002"
"2568","15.37200","1.28123","0.00030"
"2582","15.45600","1.28823","0.00055"
"2596","15.54000","1.29516","0.00054"
"2610","15.62400","1.30222","0.00066"
"2624","15.70800","1.30921","0.00026"
"2638","15.79200","1.31627","0.00059"
"2652","15.87600","1.32326","0.00044"
"2666","15.96000","1.33020","0.00040"
"2680","16.04400","1.33719","0.00113"
"2694","16.12800","1.34425","0.00061"
"2708","16.21200","1.35124","0.00054"
"2722","16.29600","1.35824","0.00059"
"2736","16.38000","1.36517","0.00092"
"2750","16.46400","1.37223","0.00046"
"2764","16.54800","1.37917","0.00135"
"2778","16.63200","1.38622","0.00011"
"2792","16.71600","1.39322","0.00090"
"2806","16.80000","1.40021","0.00075"
"2820","16.88400","1.40727","0.00031"
"2834","16.96800","1.41420","0.00089"
"2848","17.05200","1.42120","0.00074"
"2862","17.13600","1.42819","0.00083"
"2876","17.22000","1.43525","0.00029"
"2890","17.30400","1.44224","0.00091"
"2904","17.38800","1.44924","0.00086"
"2918","17.47200","1.45623","0.00047"
"2932","17.55600","1.46323","0.00069"
"2946","17.64000","1.47016","0.00078"
"2960","17.72400","1.47722","0.00011"
"2974","17.80800","1.48428","0.00066"
"2988","17.89200","1.49121","0.00075"
"3002","17.97600","1.49821","0.00100"
"3016","18.06000","1.50520","0.00077"
"3030","18.14400","1.51220","0.00065"
"3044","18.22800","1.51919","0.00022"
"3058","18.31200","1.52631","0.00075"
"3072","18.39600","1.53318","0.00045"
"3086","18.48000","1.54024","0.00089"
"3100","18.56400","1.54717","-0.00005"
"3114","18.64800","1.55417","0.00059"
"3128","18.73200","1.56122","0.00070"
"3142","18.81600","1.56822","0.00041"
"3156","18.90000","1.57527","0.00027"
"3170","18.98400","1.58221","0.00065"
"3184","19.06800","1.58927","0.00078"
"3198","19.15200","1.59620","0.00028"
"3212","19.23600","1.60314","0.00100"
"3226","19.32000","1.61025","0.00076"
"3240","19.40400","1.61725","0.00068"
"3254","19.48800","1.62424","0.00069"
"3268","19.57200","1.63124","0.00093"
"3282","19.65600","1.63823","0.00066"
"3296","19.74000","1.64523","0.00043"
"3310","19.82400","1.65216","0.00092"
"3324","19.90800","1.65928","0.00071"
"3338","19.99200","1.66627","0.00063"
"3352","20.07600","1.67327","0.00077"
"3366","20.16000","1.68021","0.00061"
"3380","20.24400","1.68720","0.00034"
"3394","20.32800","1.69420","0.00073"
"3408","20.41200","1.70119","0.00077"
"3422","20.49600","1.70831","0.00094"
"3436","20.58000","1.71524","0.00051"
"3450","20.66400","1.72224","0.00018"
"3464","20.74800","1.72917","0.00000"
"3478","20.83200","1.73617","0.00038"
"3492","20.91600","1.74322","0.00027"
"3506","21.00000","1.75022","0.00089"
"3520","21.08400","1.75721","0.00086"
"3534","21.16800","1.76427","0.00087"
"3548","21.25200","1.77126","0.00113"
"3562","21.33600","1.77820","0.00073"
"3576","21.42000","1.78520","0.00058"
"3590","21.50400","1.79225","0.00083"
"3604","21.58800","1.79925","0.00028"
"3618","21.67200","1.80624","0.00053"
"3632","21.75600","1.81324","0.00043"
"3646","21.84000","1.82023","0.00063"
"3660","21.92400","1.82723","0.00003"
"3674","22.00800","1.83422","0.00045"
"3688","22.09200","1.84128","0.00097"
"3702","22.17600","1.84827","-0.00014"
"3716","22.26000","1.85527","0.00074"
"3730","22.34400","1.86226","0.00042"
"3744","22.42800","1.86914","0.00038"
"3758","22.51200","1.87626","0.00055"
"3772","22.59600","1.88325","0.00057"
"3786","22.68000","1.89025","0.00085"
"3800","22.76400","1.89724","0.00068"
"3814","22.84800","1.90424","0.00006"
"3828","22.93200","1.91123","0.00019"
"3842","23.01600","1.91817","0.00045"
"3856","23.10000","1.92522","0.00037"
"3870","23.18400","1.93228","0.00124"
"3884","23.26800","1.93921","0.00056"
"3898","23.35200","1.94627","0.00076"
"3912","23.43600","1.95320","0.00036"
"3926","23.52000","1.96020","0.00045"
"3940","23.60400","1.96720","0.00113"
"3954","23.68800","1.97425","0.00089"
"3968","23.77200","1.98131","0.00059"
"3982","23.85600","1.98824","0.00019"
"3996","23.94000","1.99524","0.00045"
"4010","24.02400","2.00223","0.00003"
"4024","24.10800","2.00917","0.00045"
"4038","24.19200","2.01622","0.00027"
"4052","24.27600","2.02322","0.00074"
"4066","24.36000","2.03027","0.00054"
"4080","24.44400","2.03721","0.00070"
"4094","24.52800","2.04420","0.00022"
"4108","24.61200","2.05120","0.00064"
"4122","24.69600","2.05825","0.00059"
"4136","24.78000","2.06531","0.00069"
"4150","24.86400","2.07225","0.00062"
"4164","24.94800","2.07924","0.00066"
"4178","25.03200","2.08618","0.00038"
"4192","25.11600","2.09317","0.00075"
"4206","25.20000","2.10023","0.00063"
"4220","25.28400","2.10728","0.00043"
"4234","25.36800","2.11422","0.00069"
"4248","25.45200","2.12121","0.00041"
"4262","25.53600","2.12821","0.00046"
"4276","25.62000","2.13520","0.00071"
"4290","25.70400","2.14220","0.00076"
"4304","25.78800","2.14919","0.00064"
"4318","25.87200","2.15619","0.00070"
"4332","25.95600","2.16325","0.00003"
"4346","26.04000","2.17024","0.00074"
"4360","26.12400","2.17718","0.00088"
"4374","26.20800","2.18417","0.00011"
"4388","26.29200","2.19117","0.00067"
"4402","26.37600","2.19828","0.00081"
"4416","26.46000","2.20522","0.00079"
"4430","26.54400","2.21227","0.00055"
"4444","26.62800","2.21927","0.00117"
"4458","26.71200","2.22620","0.00048"
"4472","26.79600","2.23320","0.00110"
"4486","26.88000","2.24025","0.00059"
"4500","26.96400","2.24725","0.00068"
"4514","27.04800","2.25424","0.00062"
"4528","27.13200","2.26118","0.00078"
"4542","27.21600","2.26824","0.00062"
"4556","27.30000","2.27517","0.00082"
"4570","27.38400","2.28223","0.00001"
"4584","27.46800","2.28928","0.00077"
"4598","27.55200","2.29622","0.00118"
"4612","27.63600","2.30327","0.00065"
"4626","27.72000","2.31021","0.00056"
"4640","27.80400","2.31720","0.00036"
"4654","27.88800","2.32414","0.00036"
"4668","27.97200","2.33125","0.00058"
"4682","28.05600","2.33831","0.00047"
"4696","28.14000","2.34524","0.00049"
"4710","28.22400","2.35230","0.00073"
"4724","28.30800","2.35918","0.00077"
"4738","28.39200","2.36611","0.00086"
"4752","28.47600","2.37323","0.00116"
"4766","28.56000","2.38028","0.00076"
"4780","28.64400","2.38728","0.00075"
"4794","28.72800","2.39427","0.00092"
"4808","28.81200","2.40121","0.00078"
"4822","28.89600","2.40820","0.00077"
"4836","28.98000","2.41520","0.00089"
"4850","29.06400","2.42225","0.00075"
"4864","29.14800","2.42931","0.00097"
"4878","29.23200","2.43624","0.00072"
"4892","29.31600","2.44324","0.00080"
"4906","29.40000","2.45023","0.00089"
"4920","29.48400","2.45717","0.00064"
"4934","29.56800","2.46423","0.00024"
"4948","29.65200","2.47128","0.00083"
"4962","29.73600","2.47822","0.00096"
"4976","29.82000","2.48527","0.00071"
"4990","29.90400","2.49221","0.00040"
"5004","29.98800","2.49914","0.00067"
"5018","30.07200","2.50626","0.00034"
"5032","30.15600","2.51325","0.00050"
"5046","30.24000","2.52025","0.00126"
"5060","30.32400","2.52724","0.00105"
"5074","30.40800","2.53424","0.00037"
"5088","30.49200","2.54117","0.00082"
"5102","30.57600","2.54823","0.00089"
"5116","30.66000","2.55523","0.00058"
"5130","30.74400","2.56222","0.00065"
"5144","30.82800","2.56922","0.00052"
"5158","30.91200","2.57621","0.00062"
"5172","30.99600","2.58321","0.00085"
"5186","31.08000","2.59020","0.00076"
"5200","31.16400","2.59720","0.00069"
"5214","31.24800","2.60425","0.00079"
"5228","31.33200","2.61119","0.00073"
"5242","31.41600","2.61824","0.00063"
"5256","31.50000","2.62524","0.00095"
"5270","31.58400","2.63217","0.00066"
"5284","31.66800","2.63923","0.00080"
"5298","31.75200","2.64622","0.00032"
"5312","31.83600","2.65322","0.00044"
"5326","31.92000","2.66022","0.00070"
"5340","32.00400","2.66721","0.00119"
"5354","32.08800","2.67421","0.00092"
"5368","32.17200","2.68114","0.00098"
"5382","32.25600","2.68826","0.00081"
"5396","32.34000","2.69525","0.00067"
"5410","32.42400","2.70225","0.00045"
"5424","32.50800","2.70924","0.00038"
"5438","32.59200","2.71624","0.00047"
"5452","32.67600","2.72323","0.00081"
"5466","32.76000","2.73023","0.00042"
"5480","32.84400","2.73728","0.00085"
"5494","32.92800","2.74428","0.00098"
"5508","33.01200","2.75128","0.00056"
"5522","33.09600","2.75821","0.00077"
"5536","33.18000","2.76527","0.00111"
"5550","33.26400","2.77220","0.00073"
"5564","33.34800","2.77920","0.00038"
"5578","33.43200","2.78625","0.00017"
"5592","33.51600","2.79325","0.00060"
"5606","33.60000","2.80018","0.00050"
"5620","33.68400","2.80724","0.00094"
"5634","33.76800","2.81417","0.00070"
"5648","33.85200","2.82117","0.00041"
"5662","33.93600","2.82822","0.00126"
"5676","34.02000","2.83522","0.00024"
"5690","34.10400","2.84222","0.00035"
"5704","34.18800","2.84921","0.00106"
"5718","34.27200","2.85621","-0.00002"
"5732","34.35600","2.86320","0.00064"
"5746","34.44000","2.87026","0.00101"
"5760","34.52400","2.87725","0.00110"
"5774","34.60800","2.88425","0.00060"
"5788","34.69200","2.89124","0.00134"
"5802","34.77600","2.89818","0.00116"
"5816","34.86000","2.90517","0.00074"
"5830","34.94400","2.91223","0.00041"
"5844","35.02800","2.91922","0.00035"
"5858","35.11200","2.92622","0.00003"
"5872","35.19600","2.93321","0.00056"
"5886","35.28000","2.94021","0.00094"
"5900","35.36400","2.94715","0.00053"
"5914","35.44800","2.95420","0.00040"
"5928","35.53200","2.96132","0.00060"
"5942","35.61600","2.96819","0.00084"
"5956","35.70000","2.97525","0.00096"
"5970","35.78400","2.98218","0.00106"
"5984","35.86800","2.98918","0.00087"
"5998","35.95200","2.99623","0.00026"
"6012","36.03600","3.00323","0.00071"
"6026","36.12000","3.01028","0.00103"
"6040","36.20400","3.01722","0.00057"
"6054","36.28800","3.02427","0.00066"
"6068","36.37200","3.03121","0.00118"
"6082","36.45600","3.03815","0.00084"
"6096","36.54000","3.04526","0.00099"
"6110","36.62400","3.05226","0.00070"
"6124","36.70800","3.05925","0.00061"
"6138","36.79200","3.06625","0.00049"
"6152","36.87600","3.07324","0.00036"
"6166","36.96000","3.08018","0.00071"
"6180","37.04400","3.08717","0.00087"
"6194","37.12800","3.09423","0.00050"
"6208","37.21200","3.10122","0.00030"
"6222","37.29600","3.10822","0.00087"
"6236","37.38000","3.11521","0.00045"
"6250","37.46400","3.12221","0.00108"
"6264","37.54800","3.12920","0.00052"
"6278","37.63200","3.13620","0.00081"
"6292","37.71600","3.14326","0.00064"
"6306","37.80000","3.15019","0.00136"
"6320","37.88400","3.15725","0.00060"
"6334","37.96800","3.16424","0.00075"
"6348","38.05200","3.17118","0.00039"
"6362","38.13600","3.17823","0.00052"
"6376","38.22000","3.18523","0.00046"
"6390","38.30400","3.19222","0.00082"
"6404","38.38800","3.19922","0.00020"
"6418","38.47200","3.20621","0.00067"
"6432","38.55600","3.21321","0.00069"
"6446","38.64000","3.22014","0.00031"
"6460","38.72400","3.22726","0.00037"
"6474","38.80800","3.23426","0.00104"
"6488","38.89200","3.24125","0.00083"
"6502","38.97600","3.24825","0.00042"
"6516","39.06000","3.25518","0.00028"
"6530","39.14400","3.26218","0.00025"
"6544","39.22800","3.26917","0.00102"
"6558","39.31200","3.27623","0.00107"
"6572","39.39600","3.28328","0.00076"
"6586","39.48000","3.29028","0.00100"
"6600","39.56400","3.29727","0.00106"
"6614","39.64800","3.30421","0.00068"
"6628","39.73200","3.31120","0.00068"
"6642","39.81600","3.31820","0.00099"
"6656","39.90000","3.32520","0.00079"
"6670","39.98400","3.33225","0.00038"
"6684","40.06800","3.33919","0.00079"
"6698","40.15200","3.34618","0.00038"
"6712","40.23600","3.35312","0.00013"
"6726","40.32000","3.36023","0.00044"
"6740","40.40400","3.36729","0.00112"
"6754","40.48800","3.37428","0.00081"
"6768","40.57200","3.38122","0.00077"
"6782","40.65600","3.38821","0.00054"
"6796","40.74000","3.39521","0.00086"
"6810","40.82400","3.40220","0.00122"
"6824","40.90800","3.40926","0.00072"
"6838","40.99200","3.41625","0.00101"
"6852","41.07600","3.42319","0.00068"
"6866","41.16000","3.43024","0.00108"
"6880","41.24400","3.43724","0.00033"
"6894","41.32800","3.44418","0.00082"
"6908","41.41200","3.45123","0.00136"
"6922","41.49600","3.45823","0.00039"
"6936","41.58000","3.46528","0.00139"
"6950","41.66400","3.47222","0.00092"
"6964","41.74800","3.47921","0.00044"
"6978","41.83200","3.48621","0.00069"
"6992","41.91600","3.49320","0.00046"
"7006","42.00000","3.50026","0.00084"
"7020","42.08400","3.50725","0.00049"
"7034","42.16800","3.51425","0.00088"
"7048","42.25200","3.52119","0.00036"
"7062","42.33600","3.52818","0.00133"
"7076","42.42000","3.53518","0.00051"
"7090","42.50400","3.54223","0.00067"
"7104","42.58800","3.54929","0.00105"
"7118","42.67200","3.55622","0.00043"
"7132","42.75600","3.56322","0.00052"
"7146","42.84000","3.57021","0.00102"
"7160","42.92400","3.57721","0.00090"
"7174","43.00800","3.58426","0.00084"
"7188","43.09200","3.59126","0.00051"
"7202","43.17600","3.59825","0.00081"
"7216","43.26000","3.60525","0.00051"
"7230","43.34400","3.61218","0.00077"
"7244","43.42800","3.61918","0.00100"
"7258","43.51200","3.62618","0.00086"
"7272","43.59600","3.63329","0.00107"
"7286","43.68000","3.64023","0.00120"
"7300","43.76400","3.64728","0.00110"
"7314","43.84800","3.65428","0.00066"
"7328","43.93200","3.66115","0.00099"
"7342","44.01600","3.66821","0.00071"
"7356","44.10000","3.67526","0.00078"
"7370","44.18400","3.68226","0.00114"
"7384","44.26800","3.68925","0.00042"
"7398","44.35200","3.69625","0.00015"
"7412","44.43600","3.70324","0.00126"
"7426","44.52000","3.71018","0.00099"
"7440","44.60400","3.71723","0.00053"
"7454","44.68800","3.72423","0.00069"
"7468","44.77200","3.73123","0.00111"
"7482","44.85600","3.73828","0.00041"
"7496","44.94000","3.74522","0.00034"
"7510","45.02400","3.75221","0.00033"
"7524","45.10800","3.75921","0.00044"
"7538","45.19200","3.76626","0.00094"
"7552","45.27600","3.77326","0.00084"
"7566","45.36000","3.78025","0.00081"
"7580","45.44400","3.78725","0.00064"
"7594","45.52800","3.79418","0.00068"
"7608","45.61200","3.80118","0.00071"
"7622","45.69600","3.80817","0.00058"
"7636","45.78000","3.81529","0.00058"
"7650","45.86400","3.82223","0.00079"
"7664","45.94800","3.82928","0.00084"
"7678","46.03200","3.83622","0.00058"
"7692","46.11600","3.84321","0.00066"
"7706","46.20000","3.85021","0.00100"
"7720","46.28400","3.85720","0.00115"
"7734","46.36800","3.86426","0.00101"
"7748","46.45200","3.87125","0.00080"
"7762","46.53600","3.87819","0.00083"
"7776","46.62000","3.88518","0.00038"
"7790","46.70400","3.89218","0.00096"
"7804","46.78800","3.89923","0.00127"
"7818","46.87200","3.90629","0.00091"
"7832","46.95600","3.91322","0.00058"
"7846","47.04000","3.92028","0.00061"
"7860","47.12400","3.92722","0.00114"
"7874","47.20800","3.93421","0.00070"
"7888","47.29200","3.94127","0.00048"
"7902","47.37600","3.94820","0.00103"
"7916","47.46000","3.95526","0.00085"
"7930","47.54400","3.96225","0.00091"
"7944","47.62800","3.96919","0.00064"
"7958","47.71200","3.97618","0.00128"
"7972","47.79600","3.98318","0.00074"
"7986","47.88000","3.99023","0.00097"
"8000","47.96400","3.99717","0.00098"
"8014","48.04800","4.00422","0.00100"
"8028","48.13200","4.01128","0.00102"
"8042","48.21600","4.01822","0.00066"
"8056","48.30000","4.02521","0.00100"
"8070","48.38400","4.03227","0.00053"
"8084","48.46800","4.03926","0.00093"
"8098","48.55200","4.04626","0.00105"
"8112","48.63600","4.05325","0.00099"
"8126","48.72000","4.06025","0.00047"
"8140","48.80400","4.06718","0.00128"
"8154","48.88800","4.07424","0.00068"
"8168","48.97200","4.08123","0.00082"
"8182","49.05600","4.08829","0.00086"
"8196","49.14000","4.09522","0.00105"
"8210","49.22400","4.10222","0.00114"
"8224","49.30800","4.10921","0.00095"
"8238","49.39200","4.11615","0.00058"
"8252","49.47600","4.12321","0.00124"
"8266","49.56000","4.13026","0.00070"
"8280","49.64400","4.13726","0.00098"
"8294","49.72800","4.14425","0.00079"
"8308","49.81200","4.15125","0.00107"
"8322","49.89600","4.15818","0.00060"
"8336","49.98000","4.16524","0.00088"
"8350","50.06400","4.17223","0.00077"
"8364","50.14800","4.17923","0.00183"
"8378","50.23200","4.18628","0.00094"
"8392","50.31600","4.19328","0.00106"
"8406","50.40000","4.20021","0.00103"
"8420","50.48400","4.20721","0.00096"
"8434","50.56800","4.21427","0.00069"
"8448","50.65200","4.22126","0.00091"
"8462","50.73600","4.22826","0.00118"
"8476","50.82000","4.23519","0.00085"
"8490","50.90400","4.24219","0.00122"
"8504","50.98800","4.24912","0.00094"
"8518","51.07200","4.25624","0.00081"
"8532","51.15600","4.26323","0.00095"
"8546","51.24000","4.27023","0.00114"
"8560","51.32400","4.27722","0.00108"
"8574","51.40800","4.28416","0.00137"
"8588","51.49200","4.29121","0.00033"
"8602","51.57600","4.29821","0.00082"
"8616","51.66000","4.30526","0.00094"
"8630","51.74400","4.31226","0.00074"
"8644","51.82800","4.31926","0.00068"
"8658","51.91200","4.32631","0.00076"
"8672","51.99600","4.33319","0.00094"
"8686","52.08000","4.34018","0.00126"
"8700","52.16400","4.34724","0.00072"
"8714","52.24800","4.35423","0.00136"
"8728","52.33200","4.36123","0.00100"
"8742","52.41600","4.36822","0.00117"
"8756","52.50000","4.37522","0.00095"
"8770","52.58400","4.38215","0.00070"
"8784","52.66800","4.38921","0.00084"
"8798","52.75200","4.39632","0.00096"
"8812","52.83600","4.40320","0.00129"
"8826","52.92000","4.41026","0.00107"
"8840","53.00400","4.41719","0.00164"
"8854","53.08800","4.42419","0.00048"
"8868","53.17200","4.43118","0.00060"
"8882","53.25600","4.43824","0.00113"
"8896","53.34000","4.44523","0.00124"
"8910","53.42400","4.45223","0.00170"
"8924","53.50800","4.45922","0.00087"
"8938","53.59200","4.46622","0.00067"
"8952","53.67600","4.47321","0.00105"
"8966","53.76000","4.48021","0.00162"
"8980","53.84400","4.48726","0.00080"
"8994","53.92800","4.49426","0.00127"
"9008","54.01200","4.50125","0.00162"
"9022","54.09600","4.50819","0.00108"
"9036","54.18000","4.51519","0.00099"
"9050","54.26400","4.52212","0.00097"
"9064","54.34800","4.52930","0.00139"
"9078","54.43200","4.53623","0.00161"
"9092","54.51600","4.54323","0.00089"
"9106","54.60000","4.55022","0.00100"
"9120","54.68400","4.55722","0.00074"
"9134","54.76800","4.56421","0.00115"
"9148","54.85200","4.57121","0.00089"
"9162","54.93600","4.57826","0.00075"
"9176","55.02000","4.58526","0.00170"
"9190","55.10400","4.59225","0.00118"
"9204","55.18800","4.59919","0.00099"
"9218","55.27200","4.60619","0.00138"
"9232","55.35600","4.61318","0.00115"
"9246","55.44000","4.62018","0.00125"
"9260","55.52400","4.62723","0.00118"
"9274","55.60800","4.63429","0.00111"
"9288","55.69200","4.64122","0.00102"
"9302","55.77600","4.64822","0.00095"
"9316","55.86000","4.65515","0.00103"
"9330","55.94400","4.66227","0.00099"
"9344","56.02800","4.66920","0.00083"
"9358","56.11200","4.67626","0.00097"
"9372","56.19600","4.68325","0.00104"
"9386","56.28000","4.69013","0.00133"
"9400","56.36400","4.69719","0.00160"
"9414","56.44800","4.70418","0.00103"
"9428","56.53200","4.71124","0.00107"
"9442","56.61600","4.71829","0.00114"
"9456","56.70000","4.72523","0.00123"
"9470","56.78400","4.73222","0.00133"
"9484","56.86800","4.73916","0.00122"
"9498","56.95200","4.74621","0.00127"
"9512","57.03600","4.75327","0.00094"
"9526","57.12000","4.76026","0.00170"
"9540","57.20400","4.76726","0.00034"
"9554","57.28800","4.77425","0.00177"
"9568","57.37200","4.78119","0.00128"
"9582","57.45600","4.78819","0.00122"
"9596","57.54000","4.79518","0.00138"
"9610","57.62400","4.80224","0.00126"
"9624","57.70800","4.80923","0.00141"
"9638","57.79200","4.81623","0.00066"
"9652","57.87600","4.82322","0.00122"
"9666","57.96000","4.83022","0.00137"
"9680","58.04400","4.83721","0.00091"
"9694","58.12800","4.84427","0.00116"
"9708","58.21200","4.85132","0.00104"
"9722","58.29600","4.85826","0.00187"
"9736","58.38000","4.86525","0.00073"
"9750","58.46400","4.87219","0.00068"
"9764","58.54800","4.87918","0.00159"
"9778","58.63200","4.88624","0.00139"
"9792","58.71600","4.89323","0.00079"
"9806","58.80000","4.90023","0.00217"
"9820","58.88400","4.90723","0.00126"
"9834","58.96800","4.91422","0.00098"
"9848","59.05200","4.92122","0.00188"
"9862","59.13600","4.92821","0.00152"
"9876","59.22000","4.93527","0.00073"
"9890","59.30400","4.94220","0.00094"
"9904","59.38800","4.94926","0.00133"
"9918","59.47200","4.95619","0.00187"
"9932","59.55600","4.96319","0.00089"
"9946","59.64000","4.97024","0.00110"
"9960","59.72400","4.97724","0.00097"
"9974","59.80800","4.98429","0.00111"
"9988","59.89200","4.99123","0.00151"
"10002","59.97600","4.99823","0.00129"
"10016","60.06000","5.00522","0.00132"
"10030","60.14400","5.01222","0.00085"
"10044","60.22800","5.01921","0.00120"
"10058","60.31200","5.02621","0.00067"
"10072","60.39600","5.03320","0.00159"
"10086","60.48000","5.04026","0.00069"
"10100","60.56400","5.04719","0.00106"
"10114","60.64800","5.05419","0.00141"
"10128","60.73200","5.06118","0.00130"
"10142","60.81600","5.06824","0.00081"
"10156","60.90000","5.07523","0.00126"
"10170","60.98400","5.08229","0.00140"
"10184","61.06800","5.08923","0.00106"
"10198","61.15200","5.09628","0.00106"
"10212","61.23600","5.10322","0.00065"
"10226","61.32000","5.11027","0.00112"
"10240","61.40400","5.11727","0.00173"
"10254","61.48800","5.12420","0.00118"
"10268","61.57200","5.13126","0.00150"
"10282","61.65600","5.13819","0.00072"
"10296","61.74000","5.14513","0.00108"
"10310","61.82400","5.15218","0.00167"
"10324","61.90800","5.15924","0.00104"
"10338","61.99200","5.16623","0.00127"
"10352","62.07600","5.17329","0.00089"
"10366","62.16000","5.18023","0.00083"
"10380","62.24400","5.18722","0.00044"
"10394","62.32800","5.19416","0.00145"
"10408","62.41200","5.20127","0.00113"
"10422","62.49600","5.20827","0.00164"
"10436","62.58000","5.21526","0.00099"
"10450","62.66400","5.22226","0.00096"
"10464","62.74800","5.22919","0.00154"
"10478","62.83200","5.23613","0.00108"
"10492","62.91600","5.24324","0.00115"
"10506","63.00000","5.25024","0.00136"
"10520","63.08400","5.25729","0.00064"
"10534","63.16800","5.26423","0.00071"
"10548","63.25200","5.27122","0.00102"
"10562","63.33600","5.27816","0.00185"
"10576","63.42000","5.28522","0.00132"
"10590","63.50400","5.29221","0.00141"
"10604","63.58800","5.29921","0.00132"
"10618","63.67200","5.30626","0.00121"
"10632","63.75600","5.31320","0.00117"
"10646","63.84000","5.32013","0.00145"
"10660","63.92400","5.32719","0.00092"
"10674","64.00800","5.33424","0.00094"
"10688","64.09200","5.34130","0.00130"
"10702","64.17600","5.34823","0.00144"
"10716","64.26000","5.35523","0.00140"
"10730","64.34400","5.36216","0.00108"
"10744","64.42800","5.36922","0.00148"
"10758","64.51200","5.37621","0.00139"
"10772","64.59600","5.38321","0.00161"
"10786","64.68000","5.39026","0.00122"
"10800","64.76400","5.39726","0.00132"
"10814","64.84800","5.40426","0.00154"
"10828","64.93200","5.41119","0.00123"
"10842","65.01600","5.41819","0.00120"
"10856","65.10000","5.42524","0.00068"
"10870","65.18400","5.43224","0.00110"
"10884","65.26800","5.43923","0.00103"
"10898","65.35200","5.44623","0.00144"
"10912","65.43600","5.45322","0.00134"
"10926","65.52000","5.46016","0.00105"
"10940","65.60400","5.46727","0.00122"
"10954","65.68800","5.47427","0.00158"
"10968","65.77200","5.48121","0.00162"
"10982","65.85600","5.48826","0.00168"
"10996","65.94000","5.49526","0.00111"
"11010","66.02400","5.50219","0.00199"
"11024","66.10800","5.50925","0.00153"
"11038","66.19200","5.51624","0.00189"
"11052","66.27600","5.52324","0.00151"
"11066","66.36000","5.53023","0.00166"
"11080","66.44400","5.53723","0.00191"
"11094","66.52800","5.54422","0.00152"
"11108","66.61200","5.55122","0.00165"
"11122","66.69600","5.55821","0.00142"
"11136","66.78000","5.56521","0.00113"
"11150","66.86400","5.57221","0.00086"
"11164","66.94800","5.57920","0.00173"
"11178","67.03200","5.58620","0.00109"
"11192","67.11600","5.59319","0.00143"
"11206","67.20000","5.60019","0.00182"
"11220","67.28400","5.60724","0.00168"
"11234","67.36800","5.61424","0.00130"
"11248","67.45200","5.62123","0.00139"
"11262","67.53600","5.62829","0.00197"
"11276","67.62000","5.63522","0.00141"
"11290","67.70400","5.64228","0.00179"
"11304","67.78800","5.64927","0.00164"
"11318","67.87200","5.65627","0.00147"
"11332","67.95600","5.66326","0.00124"
"11346","68.04000","5.67020","0.00101"
"11360","68.12400","5.67720","0.00136"
"11374","68.20800","5.68413","0.00176"
"11388","68.29200","5.69125","0.00114"
"11402","68.37600","5.69824","0.00106"
"11416","68.46000","5.70524","0.00143"
"11430","68.54400","5.71223","0.00118"
"11444","68.62800","5.71917","0.00104"
"11458","68.71200","5.72622","0.00111"
"11472","68.79600","5.73322","0.00136"
"11486","68.88000","5.74021","0.00183"
"11500","68.96400","5.74721","0.00139"
"11514","69.04800","5.75426","0.00062"
"11528","69.13200","5.76126","0.00105"
"11542","69.21600","5.76814","0.00128"
"11556","69.30000","5.77519","0.00097"
"11570","69.38400","5.78225","0.00137"
"11584","69.46800","5.78930","0.00153"
"11598","69.55200","5.79630","0.00121"
"11612","69.63600","5.80323","0.00092"
"11626","69.72000","5.81017","0.00105"
"11640","69.80400","5.81716","0.00130"
"11654","69.88800","5.82422","0.00155"
"11668","69.97200","5.83133","0.00199"
"11682","70.05600","5.83821","0.00149"
"11696","70.14000","5.84520","0.00146"
"11710","70.22400","5.85220","0.00132"
"11724","70.30800","5.85913","0.00121"
"11738","70.39200","5.86619","0.00133"
"11752","70.47600","5.87325","0.00130"
"11766","70.56000","5.88024","0.00160"
"11780","70.64400","5.88724","0.00174"
"11794","70.72800","5.89423","0.00174"
"11808","70.81200","5.90123","0.00149"
"11822","70.89600","5.90816","0.00159"
"11836","70.98000","5.91528","0.00115"
"11850","71.06400","5.92227","0.00153"
"11864","71.14800","5.92921","0.00193"
"11878","71.23200","5.93626","0.00146"
"11892","71.31600","5.94326","0.00100"
"11906","71.40000","5.95019","0.00177"
"11920","71.48400","5.95713","0.00119"
"11934","71.56800","5.96431","0.00193"
"11948","71.65200","5.97124","0.00172"
"11962","71.73600","5.97824","0.00156"
"11976","71.82000","5.98523","0.00131"
"11990","71.90400","5.99223","0.00148"
"12004","71.98800","5.99922","0.00175"
"12018","72.07200","6.00616","0.00190"
"12032","72.15600","6.01333","0.00188"
"12046","72.24000","6.02027","0.00176"
"12060","72.32400","6.02720","0.00107"
"12074","72.40800","6.03420","0.00127"
"12088","72.49200","6.04113","0.00165"
"12102","72.57600","6.04825","0.00170"
"12116","72.66000","6.05525","0.00125"
"12130","72.74400","6.06224","0.00142"
"12144","72.82800","6.06924","0.00112"
"12158","72.91200","6.07623","0.00148"
"12172","72.99600","6.08317","0.00171"
"12186","73.08000","6.09016","0.00121"
"12200","73.16400","6.09722","0.00137"
"12214","73.24800","6.10421","0.00144"
"12228","73.33200","6.11127","0.00141"
"12242","73.41600","6.11826","0.00105"
"12256","73.50000","6.12520","0.00140"
"12270","73.58400","6.13219","0.00114"
"12284","73.66800","6.13919","0.00157"
"12298","73.75200","6.14624","0.00120"
"12312","73.83600","6.15324","0.00151"
"12326","73.92000","6.16024","0.00184"
"12340","74.00400","6.16729","0.00142"
"12354","74.08800","6.17423","0.00158"
"12368","74.17200","6.18122","0.00129"
"12382","74.25600","6.18822","0.00100"
"12396","74.34000","6.19521","0.00100"
"12410","74.42400","6.20227","0.00195"
"12424","74.50800","6.20920","0.00113"
"12438","74.59200","6.21614","0.00107"
"12452","74.67600","6.22313","0.00175"
"12466","74.76000","6.23025","0.00110"
"12480","74.84400","6.23724","0.00107"
"12494","74.92800","6.24424","0.00166"
"12508","75.01200","6.25124","0.00202"
"12522","75.09600","6.25817","0.00119"
"12536","75.18000","6.26517","0.00156"
"12550","75.26400","6.27222","0.00149"
"12564","75.34800","6.27922","0.00160"
"12578","75.43200","6.28627","0.00134"
"12592","75.51600","6.29321","0.00132"
"12606","75.60000","6.30026","0.00166"
"12620","75.68400","6.30720","0.00129"
"12634","75.76800","6.31419","0.00114"
"12648","75.85200","6.32125","0.00104"
"12662","75.93600","6.32824","0.00148"
"12676","76.02000","6.33524","0.00134"
"12690","76.10400","6.34217","0.00183"
"12704","76.18800","6.34923","0.00117"
"12718","76.27200","6.35623","0.00135"
"12732","76.35600","6.36316","0.00135"
"12746","76.44000","6.37028","0.00158"
"12760","76.52400","6.37721","0.00158"
"12774","76.60800","6.38421","0.00103"
"12788","76.69200","6.39120","0.00126"
"12802","76.77600","6.39820","0.00132"
"12816","76.86000","6.40519","0.00163"
"12830","76.94400","6.41225","0.00141"
"12844","77.02800","6.41924","0.00153"
"12858","77.11200","6.42624","0.00160"
"12872","77.19600","6.43317","0.00143"
"12886","77.28000","6.44023","0.00161"
"12900","77.36400","6.44717","0.00191"
"12914","77.44800","6.45422","0.00144"
"12928","77.53200","6.46122","0.00184"
"12942","77.61600","6.46827","0.00109"
"12956","77.70000","6.47527","0.00148"
"12970","77.78400","6.48220","0.00194"
"12984","77.86800","6.48920","0.00126"
"12998","77.95200","6.49625","0.00187"
"13012","78.03600","6.50325","0.00167"
"13026","78.12000","6.51024","0.00193"
"13040","78.20400","6.51724","0.00124"
"13054","78.28800","6.52423","0.00100"
"13068","78.37200","6.53123","0.00123"
"13082","78.45600","6.53816","0.00117"
"13096","78.54000","6.54528","0.00115"
"13110","78.62400","6.55228","0.00204"
"13124","78.70800","6.55921","0.00172"
"13138","78.79200","6.56627","0.00139"
"13152","78.87600","6.57320","0.00129"
"13166","78.96000","6.58020","0.00104"
"13180","79.04400","6.58725","0.00110"
"13194","79.12800","6.59425","0.00126"
"13208","79.21200","6.60124","0.00191"
"13222","79.29600","6.60824","0.00157"
"13236","79.38000","6.61517","0.00205"
"13250","79.46400","6.62217","0.00132"
"13264","79.54800","6.62916","0.00167"
"13278","79.63200","6.63628","0.00138"
"13292","79.71600","6.64328","0.00171"
"13306","79.80000","6.65021","0.00135"
"13320","79.88400","6.65727","0.00173"
"13334","79.96800","6.66420","0.00178"
"13348","80.05200","6.67120","0.00238"
"13362","80.13600","6.67819","0.00148"
"13376","80.22000","6.68525","0.00176"
"13390","80.30400","6.69230","0.00175"
"13404","80.38800","6.69924","0.00165"
"13418","80.47200","6.70623","0.00203"
"13432","80.55600","6.71317","0.00148"
"13446","80.64000","6.72016","0.00133"
"13460","80.72400","6.72722","0.00186"
"13474","80.80800","6.73421","0.00207"
"13488","80.89200","6.74127","0.00173"
"13502","80.97600","6.74821","0.00153"
"13516","81.06000","6.75520","0.00178"
"13530","81.14400","6.76220","0.00141"
"13544","81.22800","6.76919","0.00198"
"13558","81.31200","6.77631","0.00139"
"13572","81.39600","6.78324","0.00192"
"13586","81.48000","6.79024","0.00122"
"13600","81.56400","6.79717","0.00158"
"13614","81.64800","6.80417","0.00197"
"13628","81.73200","6.81122","0.00177"
"13642","81.81600","6.81828","0.00225"
"13656","81.90000","6.82521","0.00212"
"13670","81.98400","6.83221","0.00208"
"13684","82.06800","6.83921","0.00169"
"13698","82.15200","6.84620","0.00147"
"13712","82.23600","6.85320","0.00121"
"13726","82.32000","6.86025","0.00157"
"13740","82.40400","6.86725","0.00203"
"13754","82.48800","6.87424","0.00190"
"13768","82.57200","6.88124","0.00226"
"13782","82.65600","6.88823","0.00129"
"13796","82.74000","6.89523","0.00200"
"13810","82.82400","6.90222","0.00144"
"13824","82.90800","6.90928","0.00161"
"13838","82.99200","6.91621","0.00193"
"13852","83.07600","6.92327","0.00171"
"13866","83.16000","6.93020","0.00125"
"13880","83.24400","6.93714","0.00161"
"13894","83.32800","6.94426","0.00211"
"13908","83.41200","6.95125","0.00147"
"13922","83.49600","6.95825","0.00151"
"13936","83.58000","6.96524","0.00225"
"13950","83.66400","6.97224","0.00212"
"13964","83.74800","6.97923","0.00212"
"13978","83.83200","6.98617","0.00173"
"13992","83.91600","6.99328","0.00230"
"14006","84.00000","7.00022","0.00144"
"14020","84.08400","7.00721","0.00167"
"14034","84.16800","7.01421","0.00195"
"14048","84.25200","7.02120","0.00202"
"14062","84.33600","7.02820","0.00144"
"14076","84.42000","7.03514","0.00204"
"14090","84.50400","7.04219","0.00203"
"14104","84.58800","7.04925","0.00225"
"14118","84.67200","7.05624","0.00226"
"14132","84.75600","7.06324","0.00159"
"14146","84.84000","7.07017","0.00190"
"14160","84.92400","7.07723","0.00210"
"14174","85.00800","7.08422","0.00232"
"14188","85.09200","7.09128","0.00172"
"14202","85.17600","7.09821","0.00215"
"14216","85.26000","7.10515","0.00150"
"14230","85.34400","7.11220","0.00191"
"14244","85.42800","7.11920","0.00156"
"14258","85.51200","7.12620","0.00174"
"14272","85.59600","7.13325","0.00183"
"14286","85.68000","7.14025","0.00227"
"14300","85.76400","7.14718","0.00170"
"14314","85.84800","7.15418","0.00243"
"14328","85.93200","7.16117","0.00212"
"14342","86.01600","7.16823","0.00185"
"14356","86.10000","7.17522","0.00209"
"14370","86.18400","7.18222","0.00185"
"14384","86.26800","7.18927","0.00182"
"14398","86.35200","7.19621","0.00186"
"14412","86.43600","7.20314","0.00230"
"14426","86.52000","7.21020","0.00166"
"14440","86.60400","7.21725","0.00189"
"14454","86.68800","7.22425","0.00178"
"14468","86.77200","7.23125","0.00207"
"14482","86.85600","7.23824","0.00179"
"14496","86.94000","7.24524","0.00210"
"14510","87.02400","7.25217","0.00221"
"14524","87.10800","7.25923","0.00191"
"14538","87.19200","7.26628","0.00202"
"14552","87.27600","7.27322","0.00213"
"14566","87.36000","7.28021","0.00230"
"14580","87.44400","7.28721","0.00166"
"14594","87.52800","7.29420","0.00205"
"14608","87.61200","7.30120","0.00229"
"14622","87.69600","7.30825","0.00212"
"14636","87.78000","7.31525","0.00204"
"14650","87.86400","7.32218","0.00139"
"14664","87.94800","7.32924","0.00238"
"14678","88.03200","7.33618","0.00172"
"14692","88.11600","7.34317","0.00197"
"14706","88.20000","7.35023","0.00251"
"14720","88.28400","7.35728","0.00190"
"14734","88.36800","7.36428","0.00190"
"14748","88.45200","7.37121","0.00225"
"14762","88.53600","7.37821","0.00205"
"14776","88.62000","7.38520","0.00230"
"14790","88.70400","7.39214","0.00226"
"14804","88.78800","7.39925","0.00150"
"14818","88.87200","7.40619","0.00218"
"14832","88.95600","7.41324","0.00212"
"14846","89.04000","7.42024","0.00290"
"14860","89.12400","7.42718","0.00263"
"14874","89.20800","7.43423","0.00227"
"14888","89.29200","7.44123","0.00265"
"14902","89.37600","7.44828","0.00175"
"14916","89.46000","7.45528","0.00227"
"14930","89.54400","7.46227","0.00209"
"14944","89.62800","7.46921","0.00223"
"14958","89.71200","7.47620","0.00186"
"14972","89.79600","7.48320","0.00209"
"14986","89.88000","7.49019","0.00259"
"15000","89.96400","7.49725","0.00211"
"15014","90.04800","7.50424","0.00212"
"15028","90.13200","7.51124","0.00214"
"15042","90.21600","7.51818","0.00187"
"15056","90.30000","7.52523","0.00200"
"15070","90.38400","7.53217","0.00229"
"15084","90.46800","7.53922","0.00233"
"15098","90.55200","7.54622","0.00215"
"15112","90.63600","7.55327","0.00202"
"15126","90.72000","7.56015","0.00193"
"15140","90.80400","7.56720","0.00241"
"15154","90.88800","7.57420","0.00236"
"15168","90.97200","7.58119","0.00248"
"15182","91.05600","7.58825","0.00230"
"15196","91.14000","7.59524","0.00242"
"15210","91.22400","7.60224","0.00193"
"15224","91.30800","7.60918","0.00230"
"15238","91.39200","7.61623","0.00270"
"15252","91.47600","7.62323","0.00225"
"15266","91.56000","7.63022","0.00175"
"15280","91.64400","7.63728","0.00222"
"15294","91.72800","7.64421","0.00206"
"15308","91.81200","7.65121","0.00236"
"15322","91.89600","7.65814","0.00225"
"15336","91.98000","7.66526","0.00273"
"15350","92.06400","7.67231","0.00240"
"15364","92.14800","7.67919","0.00210"
"15378","92.23200","7.68624","0.00238"
"15392","92.31600","7.69318","0.00226"
"15406","92.40000","7.70018","0.00284"
"15420","92.48400","7.70717","0.00185"
"15434","92.56800","7.71417","0.00266"
"15448","92.65200","7.72128","0.00236"
"15462","92.73600","7.72822","0.00239"
"15476","92.82000","7.73521","0.00244"
"15490","92.90400","7.74221","0.00249"
"15504","92.98800","7.74914","0.00272"
"15518","93.07200","7.75626","0.00236"
"15532","93.15600","7.76325","0.00235"
"15546","93.24000","7.77025","0.00286"
"15560","93.32400","7.77724","0.00240"
"15574","93.40800","7.78424","0.00215"
"15588","93.49200","7.79117","0.00279"
"15602","93.57600","7.79823","0.00230"
"15616","93.66000","7.80528","0.00235"
"15630","93.74400","7.81222","0.00281"
"15644","93.82800","7.81921","0.00240"
"15658","93.91200","7.82621","0.00233"
"15672","93.99600","7.83321","0.00243"
"15686","94.08000","7.84020","0.00216"
"15700","94.16400","7.84720","0.00221"
"15714","94.24800","7.85425","0.00254"
"15728","94.33200","7.86125","0.00277"
"15742","94.41600","7.86818","0.00256"
"15756","94.50000","7.87524","0.00233"
"15770","94.58400","7.88217","0.00297"
"15784","94.66800","7.88923","0.00253"
"15798","94.75200","7.89622","0.00238"
"15812","94.83600","7.90322","0.00198"
"15826","94.92000","7.91027","0.00201"
"15840","95.00400","7.91721","0.00295"
"15854","95.08800","7.92421","0.00224"
"15868","95.17200","7.93120","0.00245"
"15882","95.25600","7.93826","0.00268"
"15896","95.34000","7.94525","0.00240"
"15910","95.42400","7.95225","0.00319"
"15924","95.50800","7.95924","0.00204"
"15938","95.59200","7.96618","0.00247"
"15952","95.67600","7.97323","0.00251"
"15966","95.76000","7.98023","0.00308"
"15980","95.84400","7.98728","0.00283"
"15994","95.92800","7.99422","0.00213"
"16008","96.01200","8.00121","0.00292"
"16022","96.09600","8.00821","0.00265"
"16036","96.18000","8.01515","0.00319"
"16050","96.26400","8.02226","0.00277"
"16064","96.34800","8.02926","0.00226"
"16078","96.43200","8.03625","0.00281"
"16092","96.51600","8.04331","0.00317"
"16106","96.60000","8.05018","0.00290"
"16120","96.68400","8.05724","0.00254"
"16134","96.76800","8.06417","0.00304"
"16148","96.85200","8.07123","0.00273"
"16162","96.93600","8.07828","0.00235"
"16176","97.02000","8.08528","0.00272"
"16190","97.10400","8.09221","0.00268"
"16204","97.18800","8.09921","0.00311"
"16218","97.27200","8.10614","0.00293"
"16232","97.35600","8.11320","0.00248"
"16246","97.44000","8.12032","0.00289"
"16260","97.52400","8.12725","0.00270"
"16274","97.60800","8.13425","0.00281"
"16288","97.69200","8.14124","0.00271"
"16302","97.77600","8.14818","0.00277"
"16316","97.86000","8.15523","0.00204"
"16330","97.94400","8.16223","0.00233"
"16344","98.02800","8.16928","0.00294"
"16358","98.11200","8.17628","0.00302"
"16372","98.19600","8.18321","0.00297"
"16386","98.28000","8.19021","0.00271"
"16400","98.36400","8.19720","0.00240"
"16414","98.44800","8.20414","0.00275"
"16428","98.53200","8.21126","0.00296"
"16442","98.61600","8.21825","0.00248"
"16456","98.70000","8.22525","0.00265"
"16470","98.78400","8.23218","0.00310"
"16484","98.86800","8.23918","0.00306"
"16498","98.95200","8.24623","0.00266"
"16512","99.03600","8.25323","0.00287"
"16526","99.12000","8.26022","0.00287"
"16540","99.20400","8.26722","0.00303"
"16554","99.28800","8.27421","0.00252"
"16568","99.37200","8.28121","0.00266"
"16582","99.45600","8.28820","0.00283"
"16596","99.54000","8.29526","0.00286"
"16610","99.62400","8.30219","0.00272"
"16624","99.70800","8.30925","0.00291"
"16638","99.79200","8.31619","0.00267"
"16652","99.87600","8.32318","0.00265"
"16666","99.96000","8.33024","0.00281"
"16680","100.04400","8.33723","0.00281"
"16694","100.12800","8.34423","0.00340"
"16708","100.21200","8.35122","0.00279"
"16722","100.29600","8.35828","0.00283"
"16736","100.38000","8.36521","0.00294"
"16750","100.46400","8.37215","0.00231"
"16764","100.54800","8.37926","0.00351"
"16778","100.63200","8.38620","0.00259"
"16792","100.71600","8.39319","0.00256"
"16806","100.80000","8.40019","0.00208"
"16820","100.88400","8.40725","0.00137"
"16834","100.96800","8.41424","0.00053"
"16848","101.05200","8.42118","-0.00055"
"16862","101.13600","8.42823","0.00057"
"16876","101.22000","8.43523","-0.00013"
"16890","101.30400","8.44222","0.00082"
"16904","101.38800","8.44922","0.00097"
"16918","101.47200","8.45621","0.00017"
"16932","101.55600","8.46321","-0.00018"
"16946","101.64000","8.47020","0.00038"
"16960","101.72400","8.47720","-0.00034"
"16974","101.80800","8.48425","-0.00087"
"16988","101.89200","8.49125","-0.00039"
"17002","101.97600","8.49825","-0.00015"
"17016","102.06000","8.50518","-0.00063"
"17030","102.14400","8.51224","0.00061"
"17044","102.22800","8.51923","0.00029"
"17058","102.31200","8.52629","0.00048"
"17072","102.39600","8.53322","0.00010"
"17086","102.48000","8.54016","0.00083"
"17100","102.56400","8.54721","-0.00050"
"17114","102.64800","8.55415","0.00041"
"17128","102.73200","8.56120","0.00033"
"17142","102.81600","8.56826","0.00001"
"17156","102.90000","8.57525","0.00077"
"17170","102.98400","8.58219","-0.00026"
"17184","103.06800","8.58918","0.00024"
"17198","103.15200","8.59618","-0.00013"
"17212","103.23600","8.60318","0.00044"
"17226","103.32000","8.61023","0.00026"
"17240","103.40400","8.61723","0.00044"
"17254","103.48800","8.62422","-0.00012"
"17268","103.57200","8.63122","0.00053"
"17282","103.65600","8.63815","0.00056"
"17296","103.74000","8.64515","0.00083"
"17310","103.82400","8.65226","0.00076"
"17324","103.90800","8.65926","0.00061"
"17338","103.99200","8.66625","0.00062"
"17352","104.07600","8.67325","0.00103"
"17366","104.16000","8.68024","0.00017"
"17380","104.24400","8.68718","0.00082"
"17394","104.32800","8.69423","0.00040"
"17408","104.41200","8.70129","0.00089"
"17422","104.49600","8.70823","0.00046"
"17436","104.58000","8.71528","0.00097"
"17450","104.66400","8.72222","0.00047"
"17464","104.74800","8.72915","0.00076"
"17478","104.83200","8.73621","0.00076"
"17491","104.90800","8.74260","0.00057"