File: Trajectories_together/170212_3Specimen_RawData_9.csv
"","V1","V2","V3"
"1","End date","2/12/2017",""
"2","Specimen label","4AT_30",""
"3","Maximum Load","0.08356","N"
"4","Time","Extension","Load"
"5","(s)","(mm)","(N)"
"6","0.00000","0.00000","-0.00003"
"75","0.41400","0.03480","0.00009"
"144","0.82800","0.06924","0.00045"
"213","1.24200","0.10373","0.00006"
"282","1.65600","0.13817","0.00061"
"351","2.07000","0.17267","0.00029"
"420","2.48400","0.20723","0.00111"
"489","2.89800","0.24167","0.00101"
"558","3.31200","0.27623","0.00124"
"627","3.72600","0.31073","0.00059"
"696","4.14000","0.34522","0.00094"
"765","4.55400","0.37966","0.00120"
"834","4.96800","0.41416","0.00098"
"903","5.38200","0.44872","0.00105"
"972","5.79600","0.48322","0.00135"
"1041","6.21000","0.51766","0.00086"
"1110","6.62400","0.55216","0.00169"
"1179","7.03800","0.58671","0.00144"
"1248","7.45200","0.62121","0.00166"
"1317","7.86600","0.65571","0.00150"
"1386","8.28000","0.69015","0.00147"
"1455","8.69400","0.72471","0.00137"
"1524","9.10800","0.75921","0.00127"
"1593","9.52200","0.79371","0.00172"
"1662","9.93600","0.82820","0.00191"
"1731","10.35000","0.86270","0.00210"
"1800","10.76400","0.89726","0.00215"
"1869","11.17800","0.93170","0.00175"
"1938","11.59200","0.96614","0.00169"
"2007","12.00600","1.00070","0.00258"
"2076","12.42000","1.03520","0.00237"
"2145","12.83400","1.06969","0.00204"
"2214","13.24800","1.10425","0.00213"
"2283","13.66200","1.13863","0.00253"
"2352","14.07600","1.17319","0.00220"
"2421","14.49000","1.20775","0.00208"
"2490","14.90400","1.24219","0.00182"
"2559","15.31800","1.27663","0.00268"
"2628","15.73200","1.31118","0.00252"
"2697","16.14600","1.34574","0.00170"
"2766","16.56000","1.38024","0.00216"
"2835","16.97400","1.41468","0.00239"
"2904","17.38800","1.44918","0.00256"
"2973","17.80200","1.48368","0.00200"
"3042","18.21600","1.51818","0.00287"
"3111","18.63000","1.55273","0.00287"
"3180","19.04400","1.58711","0.00279"
"3249","19.45800","1.62167","0.00186"
"3318","19.87200","1.65623","0.00343"
"3387","20.28600","1.69073","0.00269"
"3456","20.70000","1.72517","0.00302"
"3525","21.11400","1.75967","0.00227"
"3594","21.52800","1.79422","0.00283"
"3663","21.94200","1.82872","0.00294"
"3732","22.35600","1.86316","0.00228"
"3801","22.77000","1.89766","0.00270"
"3870","23.18400","1.93216","0.00279"
"3939","23.59800","1.96672","0.00251"
"4008","24.01200","2.00122","0.00267"
"4077","24.42600","2.03571","0.00262"
"4146","24.84000","2.07021","0.00252"
"4215","25.25400","2.10471","0.00259"
"4284","25.66800","2.13921","0.00249"
"4353","26.08200","2.17365","0.00293"
"4422","26.49600","2.20815","0.00262"
"4491","26.91000","2.24271","0.00243"
"4560","27.32400","2.27726","0.00247"
"4629","27.73800","2.31170","0.00328"
"4698","28.15200","2.34620","0.00301"
"4767","28.56600","2.38076","0.00256"
"4836","28.98000","2.41520","0.00320"
"4905","29.39400","2.44976","0.00236"
"4974","29.80800","2.48414","0.00263"
"5043","30.22200","2.51863","0.00351"
"5112","30.63600","2.55319","0.00272"
"5181","31.05000","2.58775","0.00300"
"5250","31.46400","2.62219","0.00345"
"5319","31.87800","2.65669","0.00214"
"5388","32.29200","2.69125","0.00303"
"5457","32.70600","2.72569","0.00279"
"5526","33.12000","2.76018","0.00276"
"5595","33.53400","2.79474","0.00326"
"5664","33.94800","2.82918","0.00298"
"5733","34.36200","2.86374","0.00337"
"5802","34.77600","2.89824","0.00307"
"5871","35.19000","2.93268","0.00263"
"5940","35.60400","2.96724","0.00293"
"6009","36.01800","3.00173","0.00288"
"6078","36.43200","3.03623","0.00289"
"6147","36.84600","3.07067","0.00283"
"6216","37.26000","3.10517","0.00352"
"6285","37.67400","3.13973","0.00319"
"6354","38.08800","3.17423","0.00289"
"6423","38.50200","3.20866","0.00322"
"6492","38.91600","3.24322","0.00321"
"6561","39.33000","3.27772","0.00293"
"6630","39.74400","3.31222","0.00339"
"6699","40.15800","3.34666","0.00285"
"6768","40.57200","3.38116","0.00327"
"6837","40.98600","3.41572","0.00327"
"6906","41.40000","3.45021","0.00415"
"6975","41.81400","3.48471","0.00302"
"7044","42.22800","3.51921","0.00297"
"7113","42.64200","3.55371","0.00340"
"7182","43.05600","3.58821","0.00319"
"7251","43.47000","3.62271","0.00322"
"7320","43.88400","3.65715","0.00315"
"7389","44.29800","3.69170","0.00287"
"7458","44.71200","3.72620","0.00302"
"7527","45.12600","3.76070","0.00339"
"7596","45.54000","3.79520","0.00301"
"7665","45.95400","3.82970","0.00295"
"7734","46.36800","3.86426","0.00343"
"7803","46.78200","3.89870","0.00319"
"7872","47.19600","3.93319","0.00321"
"7941","47.61000","3.96763","0.00286"
"8010","48.02400","4.00213","0.00271"
"8079","48.43800","4.03675","0.00370"
"8148","48.85200","4.07125","0.00290"
"8217","49.26600","4.10569","0.00262"
"8286","49.68000","4.14013","0.00272"
"8355","50.09400","4.17474","0.00342"
"8424","50.50800","4.20924","0.00341"
"8493","50.92200","4.24368","0.00274"
"8562","51.33600","4.27806","0.00341"
"8631","51.75000","4.31268","0.00341"
"8700","52.16400","4.34724","0.00338"
"8769","52.57800","4.38174","0.00341"
"8838","52.99200","4.41617","0.00415"
"8907","53.40600","4.45067","0.00359"
"8976","53.82000","4.48517","0.00367"
"9045","54.23400","4.51973","0.00330"
"9114","54.64800","4.55417","0.00308"
"9183","55.06200","4.58867","0.00268"
"9252","55.47600","4.62317","0.00325"
"9321","55.89000","4.65766","0.00307"
"9390","56.30400","4.69222","0.00347"
"9459","56.71800","4.72660","0.00356"
"9528","57.13200","4.76122","0.00366"
"9597","57.54600","4.79572","0.00375"
"9666","57.96000","4.83022","0.00344"
"9735","58.37400","4.86466","0.00316"
"9804","58.78800","4.89915","0.00338"
"9873","59.20200","4.93371","0.00379"
"9942","59.61600","4.96821","0.00360"
"10011","60.03000","5.00271","0.00355"
"10080","60.44400","5.03721","0.00324"
"10149","60.85800","5.07171","0.00382"
"10218","61.27200","5.10620","0.00370"
"10287","61.68600","5.14070","0.00324"
"10356","62.10000","5.17514","0.00330"
"10425","62.51400","5.20964","0.00364"
"10494","62.92800","5.24420","0.00379"
"10563","63.34200","5.27876","0.00367"
"10632","63.75600","5.31320","0.00384"
"10701","64.17000","5.34770","0.00425"
"10770","64.58400","5.38225","0.00379"
"10839","64.99800","5.41675","0.00353"
"10908","65.41200","5.45119","0.00355"
"10977","65.82600","5.48569","0.00377"
"11046","66.24000","5.52019","0.00350"
"11115","66.65400","5.55469","0.00394"
"11184","67.06800","5.58924","0.00356"
"11253","67.48200","5.62368","0.00357"
"11322","67.89600","5.65824","0.00369"
"11391","68.31000","5.69268","0.00394"
"11460","68.72400","5.72724","0.00372"
"11529","69.13800","5.76168","0.00351"
"11598","69.55200","5.79624","0.00382"
"11667","69.96600","5.83068","0.00394"
"11736","70.38000","5.86523","0.00429"
"11805","70.79400","5.89967","0.00417"
"11874","71.20800","5.93423","0.00392"
"11943","71.62200","5.96873","0.00464"
"12012","72.03600","6.00323","0.00394"
"12081","72.45000","6.03773","0.00451"
"12150","72.86400","6.07217","0.00416"
"12219","73.27800","6.10672","0.00437"
"12288","73.69200","6.14122","0.00454"
"12357","74.10600","6.17572","0.00449"
"12426","74.52000","6.21016","0.00403"
"12495","74.93400","6.24466","0.00457"
"12564","75.34800","6.27928","0.00462"
"12633","75.76200","6.31377","0.00470"
"12702","76.17600","6.34821","0.00464"
"12771","76.59000","6.38271","0.00481"
"12840","77.00400","6.41727","0.00484"
"12909","77.41800","6.45171","0.00480"
"12978","77.83200","6.48621","0.00475"
"13047","78.24600","6.52065","0.00492"
"13116","78.66000","6.55520","0.00458"
"13185","79.07400","6.58970","0.00469"
"13254","79.48800","6.62426","0.00536"
"13323","79.90200","6.65864","0.00473"
"13392","80.31600","6.69314","0.00502"
"13461","80.73000","6.72776","0.00442"
"13530","81.14400","6.76220","0.00486"
"13599","81.55800","6.79669","0.00555"
"13668","81.97200","6.83119","0.00537"
"13737","82.38600","6.86575","0.00530"
"13806","82.80000","6.90025","0.00566"
"13875","83.21400","6.93469","0.00497"
"13944","83.62800","6.96913","0.00489"
"14013","84.04200","7.00369","0.00540"
"14082","84.45600","7.03824","0.00524"
"14151","84.87000","7.07268","0.00586"
"14220","85.28400","7.10718","0.00539"
"14289","85.69800","7.14168","0.00536"
"14358","86.11200","7.17618","0.00564"
"14427","86.52600","7.21074","0.00569"
"14496","86.94000","7.24518","0.00581"
"14565","87.35400","7.27967","0.00581"
"14634","87.76800","7.31417","0.00518"
"14703","88.18200","7.34873","0.00552"
"14772","88.59600","7.38317","0.00570"
"14841","89.01000","7.41767","0.00602"
"14910","89.42400","7.45223","0.00558"
"14979","89.83800","7.48673","0.00585"
"15048","90.25200","7.52122","0.00578"
"15117","90.66600","7.55566","0.00553"
"15186","91.08000","7.59016","0.00544"
"15255","91.49400","7.62472","0.00599"
"15324","91.90800","7.65922","0.00546"
"15393","92.32200","7.69366","0.00614"
"15462","92.73600","7.72822","0.00592"
"15531","93.15000","7.76277","0.00593"
"15600","93.56400","7.79721","0.00521"
"15669","93.97800","7.83171","0.00609"
"15738","94.39200","7.86609","0.00678"
"15807","94.80600","7.90065","0.00642"
"15876","95.22000","7.93521","0.00609"
"15945","95.63400","7.96971","0.00608"
"16014","96.04800","8.00414","0.00653"
"16083","96.46200","8.03870","0.00599"
"16152","96.87600","8.07320","0.00638"
"16221","97.29000","8.10770","0.00632"
"16290","97.70400","8.14220","0.00613"
"16359","98.11800","8.17670","0.00650"
"16428","98.53200","8.21119","0.00643"
"16497","98.94600","8.24569","0.00638"
"16566","99.36000","8.28025","0.00705"
"16635","99.77400","8.31463","0.00697"
"16704","100.18800","8.34925","0.00674"
"16773","100.60200","8.38375","0.00674"
"16842","101.01600","8.41819","0.00655"
"16911","101.43000","8.45269","0.00736"
"16980","101.84400","8.48718","0.00705"
"17049","102.25800","8.52174","0.00577"
"17118","102.67200","8.55618","0.00562"
"17187","103.08600","8.59068","0.00556"
"17256","103.50000","8.62518","0.00578"
"17325","103.91400","8.65974","0.00608"
"17394","104.32800","8.69423","0.00686"
"17463","104.74200","8.72867","0.00630"
"17532","105.15600","8.76311","0.00650"
"17601","105.57000","8.79767","0.00649"
"17670","105.98400","8.83217","0.00605"
"17739","106.39800","8.86673","0.00635"
"17808","106.81200","8.90117","0.00607"
"17877","107.22600","8.93567","0.00682"
"17946","107.64000","8.97028","0.00689"
"18015","108.05400","9.00478","0.00629"
"18084","108.46800","9.03916","0.00547"
"18153","108.88200","9.07372","0.00569"
"18222","109.29600","9.10822","0.00604"
"18291","109.71000","9.14272","0.00599"
"18360","110.12400","9.17727","0.00617"
"18429","110.53800","9.21165","0.00593"
"18498","110.95200","9.24627","0.00673"
"18567","111.36600","9.28077","0.00704"
"18636","111.78000","9.31521","0.00641"
"18705","112.19400","9.34965","0.00589"
"18774","112.60800","9.38421","0.00603"
"18843","113.02200","9.41870","0.00608"
"18912","113.43600","9.45320","0.00673"
"18981","113.85000","9.48764","0.00601"
"19050","114.26400","9.52214","0.00645"
"19119","114.67800","9.55676","0.00650"
"19188","115.09200","9.59126","0.00633"
"19257","115.50600","9.62570","0.00626"
"19326","115.92000","9.66014","0.00661"
"19395","116.33400","9.69469","0.00646"
"19464","116.74800","9.72925","0.00639"
"19533","117.16200","9.76375","0.00655"
"19602","117.57600","9.79819","0.00697"
"19671","117.99000","9.83269","0.00661"
"19740","118.40400","9.86719","0.00709"
"19809","118.81800","9.90174","0.00678"
"19878","119.23200","9.93618","0.00680"
"19947","119.64600","9.97068","0.00717"
"20016","120.06000","10.00518","0.00723"
"20085","120.47400","10.03974","0.00678"
"20154","120.88800","10.07424","0.00681"
"20223","121.30200","10.10868","0.00668"
"20292","121.71600","10.14323","0.00677"
"20361","122.13000","10.17767","0.00724"
"20430","122.54400","10.21223","0.00713"
"20499","122.95800","10.24667","0.00700"
"20568","123.37200","10.28111","0.00674"
"20637","123.78600","10.31573","0.00749"
"20706","124.20000","10.35017","0.00719"
"20775","124.61400","10.38466","0.00703"
"20844","125.02800","10.41916","0.00722"
"20913","125.44200","10.45372","0.00787"
"20982","125.85600","10.48822","0.00689"
"21051","126.27000","10.52266","0.00738"
"21120","126.68400","10.55716","0.00802"
"21189","127.09800","10.59166","0.00734"
"21258","127.51200","10.62621","0.00812"
"21327","127.92600","10.66071","0.00727"
"21396","128.34000","10.69521","0.00792"
"21465","128.75400","10.72971","0.00673"
"21534","129.16800","10.76427","0.00784"
"21603","129.58200","10.79871","0.00816"
"21672","129.99600","10.83321","0.00796"
"21741","130.41000","10.86765","0.00816"
"21810","130.82400","10.90214","0.00810"
"21879","131.23800","10.93670","0.00845"
"21948","131.65200","10.97120","0.00836"
"22017","132.06600","11.00570","0.00793"
"22086","132.48000","11.04026","0.00778"
"22155","132.89400","11.07476","0.00826"
"22224","133.30800","11.10925","0.00802"
"22293","133.72200","11.14363","0.00775"
"22362","134.13600","11.17819","0.00842"
"22431","134.55000","11.21269","0.00813"
"22500","134.96400","11.24719","0.00788"
"22569","135.37800","11.28163","0.00831"
"22638","135.79200","11.31613","0.00788"
"22707","136.20600","11.35074","0.00795"
"22776","136.62000","11.38524","0.00795"
"22845","137.03400","11.41968","0.00754"
"22914","137.44800","11.45412","0.00704"
"22983","137.86200","11.48868","0.00730"
"23052","138.27600","11.52318","0.00706"
"23121","138.69000","11.55768","0.00742"
"23190","139.10400","11.59217","0.00738"
"23259","139.51800","11.62673","0.00758"
"23328","139.93200","11.66123","0.00777"
"23397","140.34600","11.69573","0.00779"
"23466","140.76000","11.73023","0.00809"
"23535","141.17400","11.76467","0.00801"
"23604","141.58800","11.79922","0.00791"
"23673","142.00200","11.83372","0.00848"
"23742","142.41600","11.86822","0.00866"
"23811","142.83000","11.90266","0.00851"
"23880","143.24400","11.93722","0.00866"
"23949","143.65800","11.97172","0.00899"
"24018","144.07200","12.00622","0.00933"
"24087","144.48600","12.04066","0.00871"
"24156","144.90000","12.07521","0.00792"
"24225","145.31400","12.10971","0.00806"
"24294","145.72800","12.14421","0.00797"
"24363","146.14200","12.17871","0.00854"
"24432","146.55600","12.21315","0.00870"
"24501","146.97000","12.24771","0.00855"
"24570","147.38400","12.28226","0.00877"
"24639","147.79800","12.31670","0.00848"
"24708","148.21200","12.35108","0.00775"
"24777","148.62600","12.38564","0.00905"
"24846","149.04000","12.42020","0.00858"
"24915","149.45400","12.45476","0.00763"
"24984","149.86800","12.48920","0.00796"
"25053","150.28200","12.52363","0.00803"
"25122","150.69600","12.55825","0.00786"
"25191","151.11000","12.59275","0.00793"
"25260","151.52400","12.62719","0.00900"
"25329","151.93800","12.66163","0.00838"
"25398","152.35200","12.69619","0.00873"
"25467","152.76600","12.73069","0.00838"
"25536","153.18000","12.76525","0.00905"
"25605","153.59400","12.79968","0.00914"
"25674","154.00800","12.83424","0.00928"
"25743","154.42200","12.86874","0.00894"
"25812","154.83600","12.90324","0.00931"
"25881","155.25000","12.93768","0.00965"
"25950","155.66400","12.97218","0.00925"
"26019","156.07800","13.00667","0.00968"
"26088","156.49200","13.04123","0.01018"
"26157","156.90600","13.07567","0.00946"
"26226","157.32000","13.11017","0.01037"
"26295","157.73400","13.14473","0.01022"
"26364","158.14800","13.17917","0.00957"
"26433","158.56200","13.21373","0.01088"
"26502","158.97600","13.24817","0.01076"
"26571","159.39000","13.28266","0.01078"
"26640","159.80400","13.31722","0.01078"
"26709","160.21800","13.35172","0.01144"
"26778","160.63200","13.38616","0.01149"
"26847","161.04600","13.42066","0.01143"
"26916","161.46000","13.45522","0.01203"
"26985","161.87400","13.48971","0.01184"
"27054","162.28800","13.52421","0.01219"
"27123","162.70200","13.55865","0.01142"
"27192","163.11600","13.59315","0.01189"
"27261","163.53000","13.62771","0.01200"
"27330","163.94400","13.66221","0.01204"
"27399","164.35800","13.69671","0.01067"
"27468","164.77200","13.73120","0.01101"
"27537","165.18600","13.76570","0.01196"
"27606","165.60000","13.80026","0.01149"
"27675","166.01400","13.83470","0.01141"
"27744","166.42800","13.86914","0.01218"
"27813","166.84200","13.90370","0.01246"
"27882","167.25600","13.93820","0.01319"
"27951","167.67000","13.97269","0.01333"
"28020","168.08400","14.00713","0.01319"
"28089","168.49800","14.04175","0.01272"
"28158","168.91200","14.07625","0.01303"
"28227","169.32600","14.11069","0.01394"
"28296","169.74000","14.14513","0.01360"
"28365","170.15400","14.17969","0.01384"
"28434","170.56800","14.21418","0.01389"
"28503","170.98200","14.24868","0.01403"
"28572","171.39600","14.28318","0.01157"
"28641","171.81000","14.31768","0.01217"
"28710","172.22400","14.35224","0.01182"
"28779","172.63800","14.38674","0.01166"
"28848","173.05200","14.42118","0.01162"
"28917","173.46600","14.45567","0.01188"
"28986","173.88000","14.49017","0.01262"
"29055","174.29400","14.52467","0.01332"
"29124","174.70800","14.55923","0.01312"
"29193","175.12200","14.59373","0.01330"
"29262","175.53600","14.62823","0.01354"
"29331","175.95000","14.66272","0.01416"
"29400","176.36400","14.69728","0.01456"
"29469","176.77800","14.73166","0.01477"
"29538","177.19200","14.76616","0.01481"
"29607","177.60600","14.80066","0.01494"
"29676","178.02000","14.83522","0.01531"
"29745","178.43400","14.86966","0.01556"
"29814","178.84800","14.90416","0.01589"
"29883","179.26200","14.93871","0.01586"
"29952","179.67600","14.97327","0.01597"
"30021","180.09000","15.00771","0.01558"
"30090","180.50400","15.04215","0.01655"
"30159","180.91800","15.07671","0.01725"
"30228","181.33200","15.11121","0.01727"
"30297","181.74600","15.14571","0.01760"
"30366","182.16000","15.18020","0.01778"
"30435","182.57400","15.21464","0.01833"
"30504","182.98800","15.24920","0.01890"
"30573","183.40200","15.28370","0.01842"
"30642","183.81600","15.31826","0.01888"
"30711","184.23000","15.35264","0.01952"
"30780","184.64400","15.38720","0.01952"
"30849","185.05800","15.42169","0.02027"
"30918","185.47200","15.45625","0.02062"
"30987","185.88600","15.49057","0.02079"
"31056","186.30000","15.52519","0.02080"
"31125","186.71400","15.55975","0.02177"
"31194","187.12800","15.59419","0.02238"
"31263","187.54200","15.62868","0.02279"
"31332","187.95600","15.66318","0.02327"
"31401","188.37000","15.69768","0.02388"
"31470","188.78400","15.73218","0.02396"
"31539","189.19800","15.76674","0.02411"
"31608","189.61200","15.80118","0.02493"
"31677","190.02600","15.83574","0.02496"
"31746","190.44000","15.87023","0.02511"
"31815","190.85400","15.90473","0.02312"
"31884","191.26800","15.93917","0.02318"
"31953","191.68200","15.97367","0.02366"
"32022","192.09600","16.00823","0.02356"
"32091","192.51000","16.04273","0.02420"
"32160","192.92400","16.07723","0.02417"
"32229","193.33800","16.11172","0.02457"
"32298","193.75200","16.14628","0.02303"
"32367","194.16600","16.18072","0.02384"
"32436","194.58000","16.21522","0.02422"
"32505","194.99400","16.24966","0.02457"
"32574","195.40800","16.28416","0.02504"
"32643","195.82200","16.31872","0.02479"
"32712","196.23600","16.35321","0.02534"
"32781","196.65000","16.38765","0.02535"
"32850","197.06400","16.42221","0.02494"
"32919","197.47800","16.45677","0.02553"
"32988","197.89200","16.49121","0.02577"
"33057","198.30600","16.52571","0.02605"
"33126","198.72000","16.56015","0.02609"
"33195","199.13400","16.59470","0.02713"
"33264","199.54800","16.62920","0.02743"
"33333","199.96200","16.66364","0.02804"
"33402","200.37600","16.69814","0.02833"
"33471","200.79000","16.73270","0.02851"
"33540","201.20400","16.76720","0.02886"
"33609","201.61800","16.80176","0.02456"
"33678","202.03200","16.83613","0.02442"
"33747","202.44600","16.87069","0.02588"
"33816","202.86000","16.90519","0.02603"
"33885","203.27400","16.93975","0.02679"
"33954","203.68800","16.97419","0.02715"
"34023","204.10200","17.00863","0.02694"
"34092","204.51600","17.04325","0.02734"
"34161","204.93000","17.07774","0.02830"
"34230","205.34400","17.11224","0.02849"
"34299","205.75800","17.14668","0.02850"
"34368","206.17200","17.18118","0.02892"
"34437","206.58600","17.21574","0.02916"
"34506","207.00000","17.25024","0.02994"
"34575","207.41400","17.28468","0.02994"
"34644","207.82800","17.31923","0.03030"
"34713","208.24200","17.35373","0.03112"
"34782","208.65600","17.38823","0.03025"
"34851","209.07000","17.42267","0.03151"
"34920","209.48400","17.45711","0.03132"
"34989","209.89800","17.49173","0.03234"
"35058","210.31200","17.52623","0.03296"
"35127","210.72600","17.56072","0.03365"
"35196","211.14000","17.59516","0.03423"
"35265","211.55400","17.62972","0.03474"
"35334","211.96800","17.66422","0.03558"
"35403","212.38200","17.69872","0.03628"
"35472","212.79600","17.73316","0.03721"
"35541","213.21000","17.76765","0.03740"
"35610","213.62400","17.80221","0.03458"
"35679","214.03800","17.83671","0.02162"
"35748","214.45200","17.87115","0.02209"
"35817","214.86600","17.90565","0.02317"
"35886","215.28000","17.94021","0.02389"
"35955","215.69400","17.97477","0.02357"
"36024","216.10800","18.00920","0.02408"
"36093","216.52200","18.04364","0.02458"
"36162","216.93600","18.07814","0.02522"
"36231","217.35000","18.11270","0.02588"
"36300","217.76400","18.14720","0.02604"
"36369","218.17800","18.18170","0.02693"
"36438","218.59200","18.21620","0.02534"
"36507","219.00600","18.25069","0.02264"
"36576","219.42000","18.28525","0.02342"
"36645","219.83400","18.31969","0.02415"
"36714","220.24800","18.35413","0.02436"
"36783","220.66200","18.38869","0.02462"
"36852","221.07600","18.42319","0.02567"
"36921","221.49000","18.45769","0.02635"
"36990","221.90400","18.49212","0.02512"
"37059","222.31800","18.52674","0.02592"
"37128","222.73200","18.56124","0.02645"
"37197","223.14600","18.59568","0.02647"
"37266","223.56000","18.63018","0.02645"
"37335","223.97400","18.66468","0.02627"
"37404","224.38800","18.69918","0.02732"
"37473","224.80200","18.73368","0.02783"
"37542","225.21600","18.76818","0.02817"
"37611","225.63000","18.80261","0.02859"
"37680","226.04400","18.83723","0.02847"
"37749","226.45800","18.87173","0.02867"
"37818","226.87200","18.90623","0.02940"
"37887","227.28600","18.94067","0.02950"
"37956","227.70000","18.97516","0.02987"
"38025","228.11400","19.00972","0.02982"
"38094","228.52800","19.04422","0.03037"
"38163","228.94200","19.07860","0.03040"
"38232","229.35600","19.11322","0.03079"
"38301","229.77000","19.14778","0.03123"
"38370","230.18400","19.18222","0.03157"
"38439","230.59800","19.21671","0.03166"
"38508","231.01200","19.25121","0.03171"
"38577","231.42600","19.28571","0.03202"
"38646","231.84000","19.32015","0.03200"
"38715","232.25400","19.35465","0.03142"
"38784","232.66800","19.38921","0.03221"
"38853","233.08200","19.42371","0.03256"
"38922","233.49600","19.45826","0.03278"
"38991","233.91000","19.49276","0.03330"
"39060","234.32400","19.52720","0.03332"
"39129","234.73800","19.56164","0.03349"
"39198","235.15200","19.59620","0.03357"
"39267","235.56600","19.63070","0.03368"
"39336","235.98000","19.66520","0.03440"
"39405","236.39400","19.69963","0.03497"
"39474","236.80800","19.73425","0.03448"
"39543","237.22200","19.76875","0.03508"
"39612","237.63600","19.80325","0.03505"
"39681","238.05000","19.83769","0.03510"
"39750","238.46400","19.87219","0.03602"
"39819","238.87800","19.90674","0.03646"
"39888","239.29200","19.94124","0.03657"
"39957","239.70600","19.97568","0.03677"
"40026","240.12000","20.01018","0.03755"
"40095","240.53400","20.04474","0.03764"
"40164","240.94800","20.07924","0.03786"
"40233","241.36200","20.11368","0.03841"
"40302","241.77600","20.14824","0.03833"
"40371","242.19000","20.18267","0.03701"
"40440","242.60400","20.21723","0.03710"
"40509","243.01800","20.25167","0.03750"
"40578","243.43200","20.28617","0.03837"
"40647","243.84600","20.32073","0.03851"
"40716","244.26000","20.35523","0.03874"
"40785","244.67400","20.38973","0.03756"
"40854","245.08800","20.42417","0.03863"
"40923","245.50200","20.45866","0.03957"
"40992","245.91600","20.49322","0.04001"
"41061","246.33000","20.52772","0.04144"
"41130","246.74400","20.56216","0.04149"
"41199","247.15800","20.59666","0.04140"
"41268","247.57200","20.63122","0.04172"
"41337","247.98600","20.66577","0.04176"
"41406","248.40000","20.70021","0.04260"
"41475","248.81400","20.73465","0.04348"
"41544","249.22800","20.76915","0.04408"
"41613","249.64200","20.80371","0.04482"
"41682","250.05600","20.83821","0.04437"
"41751","250.47000","20.87271","0.04314"
"41820","250.88400","20.90720","0.04343"
"41889","251.29800","20.94170","0.04344"
"41958","251.71200","20.97626","0.04385"
"42027","252.12600","21.01070","0.04435"
"42096","252.54000","21.04514","0.04552"
"42165","252.95400","21.07970","0.04565"
"42234","253.36800","21.11420","0.04679"
"42303","253.78200","21.14869","0.04889"
"42372","254.19600","21.18313","0.04989"
"42441","254.61000","21.21769","0.05038"
"42510","255.02400","21.25225","0.05169"
"42579","255.43800","21.28669","0.05259"
"42648","255.85200","21.32119","0.05319"
"42717","256.26600","21.35568","0.05436"
"42786","256.68000","21.39018","0.05523"
"42855","257.09400","21.42468","0.05503"
"42924","257.50800","21.45918","0.05545"
"42993","257.92200","21.49362","0.05617"
"43062","258.33600","21.52824","0.05857"
"43131","258.75000","21.56274","0.05880"
"43200","259.16400","21.59718","0.06042"
"43269","259.57800","21.63167","0.06181"
"43338","259.99200","21.66617","0.06294"
"43407","260.40600","21.70067","0.06434"
"43476","260.82000","21.73523","0.06584"
"43545","261.23400","21.76967","0.05241"
"43614","261.64800","21.80416","0.05442"
"43683","262.06200","21.83872","0.05552"
"43752","262.47600","21.87322","0.05735"
"43821","262.89000","21.90766","0.05858"
"43890","263.30400","21.94216","0.06039"
"43959","263.71800","21.97666","0.06046"
"44028","264.13200","22.01122","0.06201"
"44097","264.54600","22.04565","0.06386"
"44166","264.96000","22.08015","0.06521"
"44235","265.37400","22.11471","0.06612"
"44304","265.78800","22.14927","0.06690"
"44373","266.20200","22.18371","0.06868"
"44442","266.61600","22.21815","0.06944"
"44511","267.03000","22.25271","0.06978"
"44580","267.44400","22.28715","0.07110"
"44649","267.85800","22.32170","0.07139"
"44718","268.27200","22.35614","0.07170"
"44787","268.68600","22.39064","0.07228"
"44856","269.10000","22.42526","0.07311"
"44925","269.51400","22.45970","0.07402"
"44994","269.92800","22.49426","0.07482"
"45063","270.34200","22.52864","0.07523"
"45132","270.75600","22.56319","0.07582"
"45201","271.17000","22.59769","0.07696"
"45270","271.58400","22.63225","0.07744"
"45339","271.99800","22.66669","0.07772"
"45408","272.41200","22.70119","0.07875"
"45477","272.82600","22.73575","0.07921"
"45546","273.24000","22.77024","0.07978"
"45615","273.65400","22.80468","0.07724"
"45684","274.06800","22.83918","0.07781"
"45753","274.48200","22.87374","0.07904"
"45822","274.89600","22.90818","0.07992"
"45891","275.31000","22.94268","0.08044"
"45960","275.72400","22.97718","0.08125"
"46029","276.13800","23.01173","0.08135"
"46098","276.55200","23.04630","0.08165"
"46167","276.96600","23.08079","0.08170"
"46236","277.38000","23.11517","0.08192"
"46305","277.79400","23.14967","0.08266"
"46374","278.20800","23.18423","0.08353"
"46443","278.62200","23.21873","0.08257"
"46512","279.03600","23.25323","-0.00035"
"46581","279.45000","23.28766","-0.00153"
"46650","279.86400","23.32222","-0.00061"
"46719","280.27800","23.35672","0.00112"
"46788","280.69200","23.39122","0.00036"
"46857","281.10600","23.42566","-0.00008"
"46926","281.52000","23.46016","0.00044"
"46995","281.93400","23.49472","0.00027"
"47064","282.34800","23.52921","0.00021"
"47133","282.76200","23.56365","0.00030"
"47202","283.17600","23.59821","0.00023"
"47271","283.59000","23.63271","0.00039"
"47340","284.00400","23.66721","0.00035"
"47409","284.41800","23.70171","-0.00025"
"47478","284.83200","23.73621","0.00014"
"47547","285.24600","23.77070","-0.00018"
"47616","285.66000","23.80520","0.00057"
"47685","286.07400","23.83970","0.00035"
"47754","286.48800","23.87420","0.00033"
"47823","286.90200","23.90870","-0.00014"
"47892","287.31600","23.94320","0.00022"
"47961","287.73000","23.97776","0.00067"
"48030","288.14400","24.01213","0.00035"
"48099","288.55800","24.04663","0.00022"
"48168","288.97200","24.08119","0.00046"
"48237","289.38600","24.11569","0.00014"
"48306","289.80000","24.15019","0.00073"
"48375","290.21400","24.18463","0.00001"
"48444","290.62800","24.21925","0.00089"
"48513","291.04200","24.25374","0.00037"
"48582","291.45600","24.28818","0.00060"
"48651","291.87000","24.32268","0.00123"
"48720","292.28400","24.35718","0.00051"
"48789","292.69800","24.39174","0.00068"
"48858","293.11200","24.42624","0.00064"
"48927","293.52600","24.46067","0.00014"
"48996","293.94000","24.49517","0.00007"
"49065","294.35400","24.52967","0.00073"
"49134","294.76800","24.56423","-0.00007"
"49203","295.18200","24.59867","0.00013"
"49272","295.59600","24.63317","0.00100"
"49341","296.01000","24.66773","0.00019"
"49410","296.42400","24.70222","0.00013"
"49479","296.83800","24.73672","0.00052"
"49548","297.25200","24.77116","0.00011"
"49617","297.66600","24.80572","-0.00017"
"49686","298.08000","24.84022","0.00028"
"49755","298.49400","24.87472","0.00031"
"49824","298.90800","24.90915","0.00069"
"49893","299.32200","24.94365","0.00051"
"49962","299.73600","24.97821","0.00046"
"50031","300.15000","25.01271","0.00062"
"50100","300.56400","25.04721","0.00034"
"50169","300.97800","25.08165","-0.00022"
"50238","301.39200","25.11621","0.00053"
"50307","301.80600","25.15071","0.00059"
"50376","302.22000","25.18526","0.00027"
"50445","302.63400","25.21970","0.00017"
"50514","303.04800","25.25414","0.00016"
"50583","303.46200","25.28870","0.00090"
"50652","303.87600","25.32320","0.00026"
"50721","304.29000","25.35770","-0.00030"
"50790","304.70400","25.39219","0.00035"
"50859","305.11800","25.42669","-0.00008"
"50928","305.53200","25.46125","0.00030"
"50997","305.94600","25.49569","0.00002"
"51066","306.36000","25.53013","-0.00010"
"51135","306.77400","25.56469","0.00027"
"51204","307.18800","25.59919","0.00078"
"51273","307.60200","25.63369","0.00025"
"51342","308.01600","25.66813","0.00000"
"51411","308.43000","25.70268","0.00059"
"51480","308.84400","25.73724","0.00023"
"51549","309.25800","25.77174","0.00016"
"51618","309.67200","25.80624","0.00075"
"51687","310.08600","25.84068","0.00017"
"51756","310.50000","25.87523","0.00006"
"51825","310.91400","25.90973","0.00008"
"51894","311.32800","25.94417","-0.00040"
"51963","311.74200","25.97867","0.00011"
"52032","312.15600","26.01323","0.00073"
"52101","312.57000","26.04773","0.00005"
"52170","312.98400","26.08223","0.00078"
"52239","313.39800","26.11673","0.00012"
"52308","313.81200","26.15117","0.00071"
"52377","314.22600","26.18572","-0.00007"
"52446","314.64000","26.22028","0.00033"
"52515","315.05400","26.25460","0.00117"
"52584","315.46800","26.28922","0.00050"
"52653","315.88200","26.32372","-0.00001"
"52722","316.29600","26.35822","0.00025"
"52791","316.71000","26.39271","0.00060"
"52860","317.12400","26.42721","0.00064"
"52929","317.53800","26.46171","0.00021"
"52998","317.95200","26.49615","0.00063"
"53067","318.36600","26.53077","-0.00027"
"53136","318.78000","26.56521","0.00063"
"53205","319.19400","26.59971","0.00004"
"53274","319.60800","26.63426","0.00045"
"53343","320.02200","26.66870","0.00053"
"53412","320.43600","26.70320","-0.00020"
"53481","320.85000","26.73764","0.00003"
"53550","321.26400","26.77220","0.00033"
"53619","321.67800","26.80670","0.00048"
"53688","322.09200","26.84126","-0.00007"
"53757","322.50600","26.87563","0.00052"
"53826","322.92000","26.91025","-0.00012"
"53895","323.33400","26.94469","0.00013"
"53964","323.74800","26.97919","0.00077"
"54033","324.16200","27.01369","0.00004"
"54102","324.57600","27.04819","-0.00015"
"54171","324.99000","27.08275","0.00069"
"54240","325.40400","27.11719","0.00016"
"54309","325.81800","27.15168","0.00035"
"54378","326.23200","27.18618","0.00094"
"54447","326.64600","27.22074","0.00009"
"54516","327.06000","27.25524","-0.00008"
"54585","327.47400","27.28968","0.00071"
"54654","327.88800","27.32417","0.00005"
"54723","328.30200","27.35867","0.00077"
"54792","328.71600","27.39317","0.00148"
"54861","329.13000","27.42767","0.00040"
"54930","329.54400","27.46217","0.00018"
"54999","329.95800","27.49667","0.00118"
"55068","330.37200","27.53117","0.00051"
"55137","330.78600","27.56573","-0.00072"
"55206","331.20000","27.60016","0.00098"
"55275","331.61400","27.63466","0.00014"
"55344","332.02800","27.66916","0.00023"
"55413","332.44200","27.70372","0.00074"
"55482","332.85600","27.73816","0.00057"
"55551","333.27000","27.77260","-0.00004"
"55620","333.68400","27.80721","0.00234"
"55689","334.09800","27.84177","0.00017"
"55758","334.51200","27.87621","-0.00008"
"55827","334.92600","27.91065","0.00181"
"55896","335.34000","27.94521","0.00074"
"55965","335.75400","27.97971","0.00045"
"56034","336.16800","28.01421","0.00201"
"56103","336.58200","28.04871","-0.00011"
"56172","336.99600","28.08315","0.00059"
"56241","337.41000","28.11770","0.00158"
"56310","337.82400","28.15226","0.00056"
"56379","338.23800","28.18670","0.00136"
"56448","338.65200","28.22120","0.00139"
"56517","339.06600","28.25570","0.00037"
"56586","339.48000","28.29020","0.00093"
"56655","339.89400","28.32470","0.00078"
"56724","340.30800","28.35913","0.00024"
"56793","340.72200","28.39369","0.00200"
"56862","341.13600","28.42825","0.00082"
"56931","341.55000","28.46275","0.00033"
"57000","341.96400","28.49725","0.00231"
"57069","342.37800","28.53168","0.00064"
"57138","342.79200","28.56624","0.00036"
"57207","343.20600","28.60068","0.00222"
"57276","343.62000","28.63518","0.00017"
"57345","344.03400","28.66968","0.00169"
"57414","344.44800","28.70424","0.00115"
"57483","344.86200","28.73874","0.00031"
"57552","345.27600","28.77323","0.00281"
"57621","345.69000","28.80767","0.00089"
"57690","346.10400","28.84217","0.00125"
"57759","346.51800","28.87673","0.00205"
"57828","346.93200","28.91117","0.00084"
"57897","347.34600","28.94567","0.00247"
"57966","347.76000","28.98022","0.00110"
"58035","348.17400","29.01472","0.00103"
"58104","348.58800","29.04922","0.00197"
"58173","349.00200","29.08372","0.00132"
"58242","349.41600","29.11816","0.00265"
"58311","349.83000","29.15272","0.00183"
"58380","350.24400","29.18722","0.00211"
"58449","350.65800","29.22166","0.00230"
"58518","351.07200","29.25609","0.00200"
"58587","351.48600","29.29065","0.00316"
"58656","351.90000","29.32521","0.00200"
"58725","352.31400","29.35971","0.00280"
"58794","352.72800","29.39421","0.00181"
"58863","353.14200","29.42871","0.00231"
"58932","353.55600","29.46321","0.00296"
"59001","353.97000","29.49771","0.00242"
"59070","354.38400","29.53214","0.00290"
"59139","354.79800","29.56664","0.00231"
"59208","355.21200","29.60120","0.00293"
"59277","355.62600","29.63570","0.00276"
"59346","356.04000","29.67020","0.00154"
"59415","356.45400","29.70464","0.00224"
"59484","356.86800","29.73919","0.00210"
"59553","357.28200","29.77369","0.00260"
"59622","357.69600","29.80819","0.00271"
"59691","358.11000","29.84263","0.00254"
"59760","358.52400","29.87719","0.00319"
"59829","358.93800","29.91169","0.00268"
"59898","359.35200","29.94625","0.00289"
"59967","359.76600","29.98069","0.00257"
"60036","360.18000","30.01518","0.00308"
"60105","360.59400","30.04968","0.00253"
"60174","361.00800","30.08418","0.00292"
"60243","361.42200","30.11868","0.00253"
"60312","361.83600","30.15318","0.00322"
"60381","362.25000","30.18768","0.00324"
"60450","362.66400","30.22223","0.00357"
"60519","363.07800","30.25673","0.00334"
"60588","363.49200","30.29117","0.00310"
"60657","363.90600","30.32567","0.00329"
"60726","364.32000","30.36017","0.00303"
"60795","364.73400","30.39467","0.00352"
"60864","365.14800","30.42923","0.00342"
"60933","365.56200","30.46366","0.00355"
"61002","365.97600","30.49822","0.00334"
"61071","366.39000","30.53272","0.00377"
"61140","366.80400","30.56728","0.00365"
"61209","367.21800","30.60166","0.00368"
"61278","367.63200","30.63622","0.00354"
"61347","368.04600","30.67072","0.00309"
"61416","368.46000","30.70521","0.00286"
"61485","368.87400","30.73971","0.00345"
"61554","369.28800","30.77421","0.00348"
"61623","369.70200","30.80871","0.00319"
"61692","370.11600","30.84321","0.00266"
"61761","370.53000","30.87771","0.00349"
"61830","370.94400","30.91221","0.00260"
"61899","371.35800","30.94670","0.00305"
"61968","371.77200","30.98120","0.00331"
"62037","372.18600","31.01570","0.00310"
"62106","372.60000","31.05014","0.00321"
"62175","373.01400","31.08470","0.00315"
"62244","373.42800","31.11920","0.00329"
"62313","373.84200","31.15376","0.00298"
"62382","374.25600","31.18825","0.00291"
"62451","374.67000","31.22263","0.00320"
"62520","375.08400","31.25719","0.00367"
"62589","375.49800","31.29175","0.00332"
"62658","375.91200","31.32619","0.00359"
"62727","376.32600","31.36063","0.00341"
"62796","376.74000","31.39524","0.00350"
"62865","377.15400","31.42974","0.00341"
"62934","377.56800","31.46424","0.00329"
"63003","377.98200","31.49868","0.00386"
"63072","378.39600","31.53324","0.00349"
"63141","378.81000","31.56774","0.00356"
"63210","379.22400","31.60223","0.00271"
"63279","379.63800","31.63661","0.00321"
"63348","380.05200","31.67117","0.00375"
"63417","380.46600","31.70567","0.00324"
"63486","380.88000","31.74023","0.00343"
"63555","381.29400","31.77473","0.00285"
"63624","381.70800","31.80917","0.00310"
"63693","382.12200","31.84373","0.00362"
"63762","382.53600","31.87823","0.00353"
"63831","382.95000","31.91272","0.00378"
"63900","383.36400","31.94710","0.00340"
"63969","383.77800","31.98172","0.00389"
"64038","384.19200","32.01622","0.00329"
"64107","384.60600","32.05072","0.00371"
"64176","385.02000","32.08521","0.00318"
"64245","385.43400","32.11971","0.00413"
"64314","385.84800","32.15421","0.00344"
"64383","386.26200","32.18871","0.00400"
"64452","386.67600","32.22321","0.00309"
"64521","387.09000","32.25765","0.00345"
"64590","387.50400","32.29221","0.00390"
"64659","387.91800","32.32671","0.00364"
"64728","388.33200","32.36120","0.00411"
"64797","388.74600","32.39570","0.00365"
"64866","389.16000","32.43020","0.00321"
"64935","389.57400","32.46470","0.00382"
"65004","389.98800","32.49920","0.00421"
"65073","390.40200","32.53370","0.00394"
"65142","390.81600","32.56813","0.00390"
"65211","391.23000","32.60270","0.00390"
"65280","391.64400","32.63720","0.00378"
"65349","392.05800","32.67169","0.00346"
"65418","392.47200","32.70613","0.00329"
"65487","392.88600","32.74068","0.00384"
"65556","393.30000","32.77525","0.00360"
"65625","393.71400","32.80968","0.00363"
"65694","394.12800","32.84412","0.00367"
"65763","394.54200","32.87868","0.00286"
"65832","394.95600","32.91324","0.00323"
"65901","395.37000","32.94774","0.00268"
"65970","395.78400","32.98218","0.00306"
"66039","396.19800","33.01668","0.00343"
"66108","396.61200","33.05117","0.00308"
"66177","397.02600","33.08574","0.00334"
"66246","397.44000","33.12011","0.00327"
"66315","397.85400","33.15461","0.00276"
"66384","398.26800","33.18917","0.00335"
"66453","398.68200","33.22367","0.00321"
"66522","399.09600","33.25822","0.00329"
"66591","399.51000","33.29267","0.00260"
"66660","399.92400","33.32722","0.00293"
"66729","400.33800","33.36172","0.00320"
"66798","400.75200","33.39622","0.00295"
"66867","401.16600","33.43066","0.00228"
"66936","401.58000","33.46522","0.00293"
"67005","401.99400","33.49972","0.00282"
"67074","402.40800","33.53421","0.00315"
"67143","402.82200","33.56871","0.00289"
"67212","403.23600","33.60315","0.00246"
"67281","403.65000","33.63771","0.00270"
"67350","404.06400","33.67221","0.00298"
"67419","404.47800","33.70671","0.00280"
"67488","404.89200","33.74115","0.00356"
"67557","405.30600","33.77571","0.00315"
"67626","405.72000","33.81026","0.00371"
"67695","406.13400","33.84476","0.00346"
"67764","406.54800","33.87926","0.00325"
"67833","406.96200","33.91370","0.00298"
"67902","407.37600","33.94820","0.00283"
"67971","407.79000","33.98270","0.00372"
"68040","408.20400","34.01719","0.00335"
"68109","408.61800","34.05164","0.00302"
"68178","409.03200","34.08619","0.00310"
"68247","409.44600","34.12069","0.00293"
"68316","409.86000","34.15525","0.00298"
"68385","410.27400","34.18969","0.00319"
"68454","410.68800","34.22419","0.00236"
"68523","411.10200","34.25875","0.00300"
"68592","411.51600","34.29324","0.00226"
"68661","411.93000","34.32762","0.00250"
"68730","412.34400","34.36224","0.00251"
"68799","412.75800","34.39674","0.00318"
"68868","413.17200","34.43124","0.00312"
"68937","413.58600","34.46574","0.00271"
"69006","414.00000","34.50023","0.00185"
"69075","414.41400","34.53473","0.00239"
"69144","414.82800","34.56923","0.00248"
"69213","415.24200","34.60373","0.00257"
"69282","415.65600","34.63817","0.00278"
"69351","416.07000","34.67266","0.00224"
"69420","416.48400","34.70723","0.00261"
"69489","416.89800","34.74173","0.00261"
"69558","417.31200","34.77622","0.00285"
"69627","417.72600","34.81066","0.00267"
"69696","418.14000","34.84522","0.00300"
"69765","418.55400","34.87972","0.00254"
"69834","418.96800","34.91416","0.00302"
"69903","419.38200","34.94865","0.00312"
"69972","419.79600","34.98322","0.00303"
"70041","420.21000","35.01772","0.00201"
"70110","420.62400","35.05221","0.00269"
"70179","421.03800","35.08671","0.00250"
"70248","421.45200","35.12121","0.00222"
"70317","421.86600","35.15570","0.00195"
"70386","422.28000","35.19020","0.00234"
"70455","422.69400","35.22464","0.00232"
"70524","423.10800","35.25920","0.00215"
"70593","423.52200","35.29364","0.00222"
"70662","423.93600","35.32820","0.00196"
"70731","424.35000","35.36264","0.00138"
"70800","424.76400","35.39714","0.00171"
"70869","425.17800","35.43169","0.00200"
"70938","425.59200","35.46619","0.00273"
"71007","426.00600","35.50069","0.00218"
"71076","426.42000","35.53513","0.00261"
"71145","426.83400","35.56969","0.00225"
"71214","427.24800","35.60425","0.00252"
"71283","427.66200","35.63874","0.00219"
"71352","428.07600","35.67319","0.00225"
"71421","428.49000","35.70768","0.00205"
"71490","428.90400","35.74224","0.00234"
"71559","429.31800","35.77668","0.00180"
"71628","429.73200","35.81118","0.00239"
"71697","430.14600","35.84562","0.00190"
"71766","430.56000","35.88024","0.00249"
"71835","430.97400","35.91467","0.00250"
"71904","431.38800","35.94923","0.00236"
"71973","431.80200","35.98367","0.00281"
"72042","432.21600","36.01817","0.00235"
"72111","432.63000","36.05273","0.00281"
"72180","433.04400","36.08723","0.00242"
"72249","433.45800","36.12167","0.00294"
"72318","433.87200","36.15617","0.00239"
"72387","434.28600","36.19066","0.00249"
"72456","434.70000","36.22522","0.00283"
"72525","435.11400","36.25972","0.00287"
"72594","435.52800","36.29416","0.00291"
"72663","435.94200","36.32866","0.00293"
"72732","436.35600","36.36322","0.00133"
"72801","436.77000","36.39766","0.00098"
"72870","437.18400","36.43216","0.00100"
"72939","437.59800","36.46671","0.00051"
"73008","438.01200","36.50121","0.00116"
"73077","438.42600","36.53571","0.00053"
"73146","438.84000","36.57027","0.00108"
"73215","439.25400","36.60471","0.00131"
"73284","439.66800","36.63921","0.00086"
"73353","440.08200","36.67370","0.00114"
"73422","440.49600","36.70814","0.00108"
"73491","440.91000","36.74264","0.00093"
"73560","441.32400","36.77720","0.00124"
"73629","441.73800","36.81170","0.00098"
"73698","442.15200","36.84626","0.00074"
"73767","442.56600","36.88070","0.00063"
"73836","442.98000","36.91520","0.00098"
"73905","443.39400","36.94975","0.00090"
"73974","443.80800","36.98425","0.00135"
"74043","444.22200","37.01863","0.00131"
"74112","444.63600","37.05319","0.00178"
"74181","445.05000","37.08775","0.00119"
"74250","445.46400","37.12225","0.00075"
"74319","445.87800","37.15668","0.00088"
"74388","446.29200","37.19118","0.00077"
"74457","446.70600","37.22574","0.00099"
"74526","447.12000","37.26018","0.00116"
"74595","447.53400","37.29474","0.00137"
"74664","447.94800","37.32918","0.00085"
"74733","448.36200","37.36367","0.00083"
"74802","448.77600","37.39824","0.00102"
"74871","449.19000","37.43273","0.00095"
"74940","449.60400","37.46723","0.00129"
"75009","450.01800","37.50173","0.00100"
"75078","450.43200","37.53622","0.00128"
"75147","450.84600","37.57072","0.00095"
"75216","451.26000","37.60522","0.00121"
"75285","451.67400","37.63960","0.00082"
"75354","452.08800","37.67422","0.00135"
"75423","452.50200","37.70872","0.00146"
"75492","452.91600","37.74322","0.00145"
"75561","453.33000","37.77772","0.00154"
"75630","453.74400","37.81215","0.00132"
"75699","454.15800","37.84671","0.00089"
"75768","454.57200","37.88121","0.00145"
"75837","454.98600","37.91565","0.00164"
"75906","455.40000","37.95015","0.00108"
"75975","455.81400","37.98471","0.00180"
"76044","456.22800","38.01921","0.00175"
"76113","456.64200","38.05371","0.00164"
"76182","457.05600","38.08815","0.00102"
"76251","457.47000","38.12276","0.00070"
"76320","457.88400","38.15720","0.00046"
"76389","458.29800","38.19170","0.00091"
"76458","458.71200","38.22614","0.00117"
"76527","459.12600","38.26064","0.00064"
"76596","459.54000","38.29519","0.00092"
"76665","459.95400","38.32969","0.00023"
"76734","460.36800","38.36419","0.00036"
"76803","460.78200","38.39863","0.00019"
"76872","461.19600","38.43319","0.00100"
"76941","461.61000","38.46769","0.00051"
"77010","462.02400","38.50219","0.00061"
"77079","462.43800","38.53663","0.00048"
"77148","462.85200","38.57119","0.00127"
"77217","463.26600","38.60568","0.00103"
"77286","463.68000","38.64024","0.00113"
"77355","464.09400","38.67468","0.00095"
"77424","464.50800","38.70918","0.00023"
"77493","464.92200","38.74374","0.00038"
"77562","465.33600","38.77823","0.00036"
"77631","465.75000","38.81268","0.00089"
"77700","466.16400","38.84718","0.00059"
"77769","466.57800","38.88167","0.00096"
"77838","466.99200","38.91623","0.00129"
"77907","467.40600","38.95073","0.00056"
"77976","467.82000","38.98517","0.00068"
"78045","468.23400","39.01973","0.00095"
"78114","468.64800","39.05423","0.00038"
"78183","469.06200","39.08872","0.00042"
"78252","469.47600","39.12310","0.00063"
"78321","469.89000","39.15766","0.00065"
"78390","470.30400","39.19222","0.00005"
"78459","470.71800","39.22672","0.00065"
"78528","471.13200","39.26121","0.00060"
"78597","471.54600","39.29571","0.00036"
"78666","471.96000","39.33022","0.00001"
"78735","472.37400","39.36471","0.00030"
"78804","472.78800","39.39921","0.00103"
"78873","473.20200","39.43365","0.00033"
"78942","473.61600","39.46826","0.00073"
"79011","474.03000","39.50270","0.00076"
"79080","474.44400","39.53727","0.00034"
"79149","474.85800","39.57170","0.00001"
"79218","475.27200","39.60620","0.00028"
"79287","475.68600","39.64070","0.00010"
"79356","476.10000","39.67520","0.00077"
"79425","476.51400","39.70970","0.00032"
"79494","476.92800","39.74419","0.00037"
"79563","477.34200","39.77869","0.00038"
"79632","477.75600","39.81319","0.00061"
"79701","478.17000","39.84775","0.00055"
"79770","478.58400","39.88213","0.00040"
"79839","478.99800","39.91675","0.00068"
"79908","479.41200","39.95119","0.00075"
"79977","479.82600","39.98563","0.00043"
"80046","480.24000","40.02012","0.00051"
"80115","480.65400","40.05468","0.00076"
"80184","481.06800","40.08924","0.00051"
"80253","481.48200","40.12368","0.00055"
"80322","481.89600","40.15824","0.00017"
"80391","482.31000","40.19268","0.00033"
"80460","482.72400","40.22723","0.00007"
"80529","483.13800","40.26173","-0.00018"
"80598","483.55200","40.29617","0.00024"
"80667","483.96600","40.33061","0.00045"
"80736","484.38000","40.36517","0.00019"
"80805","484.79400","40.39973","0.00071"
"80874","485.20800","40.43423","0.00106"
"80943","485.62200","40.46867","0.00031"
"81012","486.03600","40.50316","0.00023"
"81081","486.45000","40.53772","0.00026"
"81150","486.86400","40.57222","-0.00009"
"81219","487.27800","40.60666","0.00022"
"81288","487.69200","40.64116","0.00030"
"81357","488.10600","40.67572","0.00067"
"81426","488.52000","40.71021","0.00005"
"81495","488.93400","40.74466","0.00037"
"81564","489.34800","40.77921","0.00031"
"81633","489.76200","40.81371","0.00066"
"81702","490.17600","40.84821","0.00032"
"81771","490.59000","40.88271","0.00040"
"81840","491.00400","40.91714","0.00063"
"81909","491.41800","40.95165","0.00010"
"81978","491.83200","40.98620","0.00079"
"82047","492.24600","41.02076","0.00044"
"82116","492.66000","41.05520","0.00014"
"82185","493.07400","41.08969","0.00051"
"82254","493.48800","41.12426","0.00085"
"82323","493.90200","41.15870","0.00035"
"82392","494.31600","41.19325","0.00040"
"82461","494.73000","41.22763","0.00049"
"82530","495.14400","41.26219","-0.00008"
"82599","495.55800","41.29675","0.00045"
"82668","495.97200","41.33125","0.00027"
"82737","496.38600","41.36563","0.00024"
"82806","496.80000","41.40012","0.00044"
"82875","497.21400","41.43475","0.00066"
"82944","497.62800","41.46924","0.00032"
"83013","498.04200","41.50368","-0.00010"
"83082","498.45600","41.53818","0.00063"
"83151","498.87000","41.57273","-0.00032"
"83220","499.28400","41.60724","0.00011"
"83289","499.69800","41.64167","0.00009"
"83358","500.11200","41.67617","0.00041"
"83427","500.52600","41.71074","0.00011"
"83496","500.94000","41.74523","0.00088"
"83565","501.35400","41.77973","-0.00020"
"83634","501.76800","41.81417","0.00068"
"83703","502.18200","41.84867","0.00016"
"83772","502.59600","41.88316","0.00009"
"83841","503.01000","41.91772","0.00026"
"83910","503.42400","41.95222","-0.00010"
"83979","503.83800","41.98666","0.00003"
"84048","504.25200","42.02122","0.00026"
"84117","504.66600","42.05572","0.00066"
"84186","505.08000","42.09016","0.00056"
"84255","505.49400","42.12460","0.00017"
"84324","505.90800","42.15921","0.00000"
"84393","506.32200","42.19371","0.00090"
"84462","506.73600","42.22821","0.00049"
"84531","507.15000","42.26271","-0.00032"
"84600","507.56400","42.29721","0.00050"
"84641","507.81000","42.31772","0.00008"