File: Trajectories_together/170226_1Specimen_RawData_8.csv
"","V1","V2","V3"
"1","End date","2/26/2017",""
"2","Specimen label","6AT_44",""
"3","Maximum Load","0.06217","N"
"4","Time","Extension","Load"
"5","(s)","(mm)","(N)"
"6","0.00000","0.00000","0.00004"
"61","0.33000","0.02738","0.00088"
"116","0.66000","0.05513","0.00051"
"171","0.99000","0.08269","0.00134"
"226","1.32000","0.11013","0.00138"
"281","1.65000","0.13770","0.00207"
"336","1.98000","0.16520","0.00184"
"391","2.31000","0.19258","0.00246"
"446","2.64000","0.22020","0.00199"
"501","2.97000","0.24765","0.00250"
"556","3.30000","0.27515","0.00278"
"611","3.63000","0.30265","0.00333"
"666","3.96000","0.33016","0.00294"
"721","4.29000","0.35772","0.00286"
"776","4.62000","0.38516","0.00287"
"831","4.95000","0.41267","0.00272"
"886","5.28000","0.44017","0.00372"
"941","5.61000","0.46761","0.00414"
"996","5.94000","0.49518","0.00422"
"1051","6.27000","0.52274","0.00460"
"1106","6.60000","0.55012","0.00413"
"1161","6.93000","0.57769","0.00498"
"1216","7.26000","0.60513","0.00423"
"1271","7.59000","0.63269","0.00513"
"1326","7.92000","0.66020","0.00500"
"1381","8.25000","0.68764","0.00524"
"1436","8.58000","0.71514","0.00513"
"1491","8.91000","0.74271","0.00586"
"1546","9.24000","0.77015","0.00508"
"1601","9.57000","0.79771","0.00472"
"1656","9.90000","0.82510","0.00556"
"1711","10.23000","0.85272","0.00569"
"1766","10.56000","0.88016","0.00576"
"1821","10.89000","0.90766","0.00575"
"1876","11.22000","0.93523","0.00634"
"1931","11.55000","0.96267","0.00574"
"1986","11.88000","0.99017","0.00614"
"2041","12.21000","1.01768","0.00671"
"2096","12.54000","1.04512","0.00692"
"2151","12.87000","1.07268","0.00683"
"2206","13.20000","1.10019","0.00651"
"2261","13.53000","1.12763","0.00768"
"2316","13.86000","1.15519","0.00684"
"2371","14.19000","1.18264","0.00686"
"2426","14.52000","1.21020","0.00706"
"2481","14.85000","1.23770","0.00761"
"2536","15.18000","1.26515","0.00739"
"2591","15.51000","1.29271","0.00730"
"2646","15.84000","1.32015","0.00762"
"2701","16.17000","1.34772","0.00793"
"2756","16.50000","1.37522","0.00811"
"2811","16.83000","1.40260","0.00837"
"2866","17.16000","1.43023","0.00833"
"2921","17.49000","1.45767","0.00795"
"2976","17.82000","1.48511","0.00846"
"3031","18.15000","1.51274","0.00909"
"3086","18.48000","1.54012","0.00821"
"3141","18.81000","1.56768","0.00901"
"3196","19.14000","1.59518","0.00900"
"3251","19.47000","1.62263","0.00964"
"3306","19.80000","1.65019","0.00927"
"3361","20.13000","1.67757","0.01015"
"3416","20.46000","1.70526","0.00945"
"3471","20.79000","1.73270","0.00900"
"3526","21.12000","1.76014","0.00838"
"3581","21.45000","1.78771","0.00894"
"3636","21.78000","1.81521","0.00882"
"3691","22.11000","1.84265","0.00856"
"3746","22.44000","1.87022","0.00875"
"3801","22.77000","1.89766","0.00904"
"3856","23.10000","1.92516","0.00938"
"3911","23.43000","1.95273","0.00908"
"3966","23.76000","1.98017","0.00935"
"4021","24.09000","2.00767","0.00969"
"4076","24.42000","2.03512","0.00974"
"4131","24.75000","2.06268","0.00931"
"4186","25.08000","2.09018","0.00969"
"4241","25.41000","2.11763","0.01035"
"4296","25.74000","2.14519","0.00932"
"4351","26.07000","2.17269","0.00959"
"4406","26.40000","2.20020","0.00982"
"4461","26.73000","2.22770","0.00989"
"4516","27.06000","2.25514","0.01001"
"4571","27.39000","2.28270","0.01009"
"4626","27.72000","2.31021","0.00977"
"4681","28.05000","2.33765","0.00972"
"4736","28.38000","2.36515","0.00985"
"4791","28.71000","2.39260","0.01014"
"4846","29.04000","2.42016","0.01053"
"4901","29.37000","2.44766","0.00995"
"4956","29.70000","2.47511","0.00998"
"5011","30.03000","2.50267","0.00959"
"5066","30.36000","2.53017","0.00961"
"5121","30.69000","2.55768","0.00981"
"5176","31.02000","2.58518","0.01024"
"5231","31.35000","2.61262","0.00929"
"5286","31.68000","2.64019","0.01029"
"5341","32.01000","2.66769","0.00977"
"5396","32.34000","2.69513","0.01011"
"5451","32.67000","2.72270","0.01013"
"5506","33.00000","2.75014","0.01036"
"5561","33.33000","2.77764","0.01028"
"5616","33.66000","2.80521","0.01020"
"5671","33.99000","2.83265","0.01018"
"5726","34.32000","2.86015","0.01023"
"5781","34.65000","2.88766","0.01045"
"5836","34.98000","2.91522","0.01063"
"5891","35.31000","2.94272","0.01114"
"5946","35.64000","2.97010","0.01109"
"6001","35.97000","2.99773","0.01073"
"6056","36.30000","3.02517","0.01061"
"6111","36.63000","3.05267","0.00975"
"6166","36.96000","3.08018","0.01024"
"6221","37.29000","3.10762","0.01027"
"6276","37.62000","3.13518","0.01022"
"6331","37.95000","3.16269","0.01048"
"6386","38.28000","3.19013","0.01086"
"6441","38.61000","3.21769","0.01075"
"6496","38.94000","3.24514","0.01084"
"6551","39.27000","3.27270","0.01145"
"6606","39.60000","3.30020","0.01097"
"6661","39.93000","3.32765","0.01108"
"6716","40.26000","3.35521","0.01098"
"6771","40.59000","3.38265","0.01086"
"6826","40.92000","3.41016","0.01072"
"6881","41.25000","3.43772","0.01162"
"6936","41.58000","3.46516","0.01125"
"6991","41.91000","3.49273","0.01118"
"7046","42.24000","3.52023","0.01047"
"7101","42.57000","3.54767","0.01094"
"7156","42.90000","3.57523","0.01109"
"7211","43.23000","3.60262","0.01143"
"7266","43.56000","3.63024","0.01128"
"7321","43.89000","3.65768","0.01121"
"7376","44.22000","3.68513","0.00962"
"7431","44.55000","3.71269","0.01044"
"7486","44.88000","3.74013","0.01098"
"7541","45.21000","3.76764","0.01106"
"7596","45.54000","3.79520","0.01024"
"7651","45.87000","3.82270","0.01102"
"7706","46.20000","3.85021","0.01109"
"7761","46.53000","3.87765","0.01164"
"7816","46.86000","3.90521","0.01138"
"7871","47.19000","3.93272","0.01204"
"7926","47.52000","3.96010","0.01194"
"7981","47.85000","3.98766","0.01258"
"8036","48.18000","4.01517","0.01187"
"8091","48.51000","4.04261","0.01219"
"8146","48.84000","4.07017","0.01234"
"8201","49.17000","4.09774","0.01270"
"8256","49.50000","4.12512","0.01295"
"8311","49.83000","4.15268","0.01225"
"8366","50.16000","4.18018","0.01208"
"8421","50.49000","4.20769","0.01243"
"8476","50.82000","4.23513","0.01258"
"8531","51.15000","4.26269","0.01086"
"8586","51.48000","4.29026","0.01103"
"8641","51.81000","4.31764","0.01210"
"8696","52.14000","4.34520","0.01207"
"8751","52.47000","4.37271","0.01231"
"8806","52.80000","4.40015","0.01328"
"8861","53.13000","4.42771","0.01292"
"8916","53.46000","4.45516","0.01328"
"8971","53.79000","4.48266","0.01329"
"9026","54.12000","4.51016","0.01444"
"9081","54.45000","4.53767","0.01404"
"9136","54.78000","4.56517","0.01385"
"9191","55.11000","4.59261","0.01427"
"9246","55.44000","4.62018","0.01415"
"9301","55.77000","4.64768","0.01398"
"9356","56.10000","4.67512","0.01350"
"9411","56.43000","4.70269","0.01440"
"9466","56.76000","4.73019","0.01429"
"9521","57.09000","4.75763","0.01415"
"9576","57.42000","4.78520","0.01449"
"9631","57.75000","4.81264","0.01460"
"9686","58.08000","4.84020","0.01457"
"9741","58.41000","4.86765","0.01487"
"9796","58.74000","4.89515","0.01445"
"9851","59.07000","4.92271","0.01430"
"9906","59.40000","4.95015","0.01431"
"9961","59.73000","4.97772","0.01436"
"10016","60.06000","5.00522","0.01385"
"10071","60.39000","5.03260","0.01421"
"10126","60.72000","5.06017","0.01487"
"10181","61.05000","5.08767","0.01444"
"10236","61.38000","5.11523","0.01386"
"10291","61.71000","5.14268","0.01365"
"10346","62.04000","5.17012","0.01505"
"10401","62.37000","5.19774","0.01546"
"10456","62.70000","5.22513","0.01574"
"10511","63.03000","5.25263","0.01567"
"10566","63.36000","5.28019","0.01570"
"10621","63.69000","5.30764","0.01635"
"10676","64.02000","5.33520","0.01653"
"10731","64.35000","5.36270","0.01632"
"10786","64.68000","5.39015","0.01723"
"10841","65.01000","5.41765","0.01746"
"10896","65.34000","5.44515","0.01652"
"10951","65.67000","5.47271","0.01766"
"11006","66.00000","5.50016","0.01780"
"11061","66.33000","5.52766","0.01798"
"11116","66.66000","5.55516","0.01824"
"11171","66.99000","5.58267","0.01856"
"11226","67.32000","5.61017","0.01894"
"11281","67.65000","5.63767","0.01895"
"11336","67.98000","5.66512","0.01967"
"11391","68.31000","5.69268","0.01862"
"11446","68.64000","5.72018","0.01909"
"11501","68.97000","5.74763","0.01922"
"11556","69.30000","5.77513","0.01973"
"11611","69.63000","5.80257","0.01966"
"11666","69.96000","5.83020","0.01867"
"11721","70.29000","5.85770","0.01981"
"11776","70.62000","5.88514","0.01994"
"11831","70.95000","5.91271","0.02038"
"11886","71.28000","5.94015","0.02032"
"11941","71.61000","5.96765","0.02094"
"11996","71.94000","5.99522","0.02096"
"12051","72.27000","6.02266","0.02187"
"12106","72.60000","6.05022","0.02265"
"12161","72.93000","6.07767","0.02193"
"12216","73.26000","6.10517","0.02276"
"12271","73.59000","6.13267","0.02263"
"12326","73.92000","6.16012","0.02264"
"12381","74.25000","6.18768","0.02274"
"12436","74.58000","6.21524","0.02291"
"12491","74.91000","6.24268","0.02286"
"12546","75.24000","6.27019","0.02374"
"12601","75.57000","6.29769","0.02334"
"12656","75.90000","6.32514","0.02224"
"12711","76.23000","6.35270","0.02338"
"12766","76.56000","6.38014","0.02334"
"12821","76.89000","6.40770","0.02327"
"12876","77.22000","6.43515","0.02382"
"12931","77.55000","6.46265","0.02389"
"12986","77.88000","6.49021","0.02452"
"13041","78.21000","6.51760","0.02472"
"13096","78.54000","6.54522","0.02363"
"13151","78.87000","6.57272","0.02369"
"13206","79.20000","6.60017","0.02427"
"13261","79.53000","6.62767","0.02432"
"13316","79.86000","6.65517","0.02392"
"13371","80.19000","6.68268","0.02409"
"13426","80.52000","6.71018","0.02496"
"13481","80.85000","6.73768","0.02644"
"13536","81.18000","6.76525","0.02740"
"13591","81.51000","6.79263","0.02700"
"13646","81.84000","6.82013","0.02765"
"13701","82.17000","6.84770","0.02754"
"13756","82.50000","6.87514","0.02764"
"13811","82.83000","6.90270","0.02611"
"13866","83.16000","6.93020","0.02536"
"13921","83.49000","6.95765","0.02553"
"13976","83.82000","6.98515","0.02567"
"14031","84.15000","7.01265","0.02614"
"14086","84.48000","7.04022","0.02651"
"14141","84.81000","7.06772","0.02662"
"14196","85.14000","7.09516","0.02763"
"14251","85.47000","7.12273","0.02669"
"14306","85.80000","7.15017","0.02781"
"14361","86.13000","7.17761","0.02798"
"14416","86.46000","7.20524","0.02685"
"14471","86.79000","7.23262","0.02736"
"14526","87.12000","7.26018","0.02788"
"14581","87.45000","7.28769","0.02764"
"14636","87.78000","7.31519","0.02572"
"14691","88.11000","7.34269","0.02121"
"14746","88.44000","7.37008","0.01446"
"14801","88.77000","7.39770","0.01481"
"14856","89.10000","7.42514","0.01435"
"14911","89.43000","7.45265","0.01498"
"14966","89.76000","7.48027","0.01365"
"15021","90.09000","7.50765","0.01201"
"15076","90.42000","7.53516","0.01209"
"15131","90.75000","7.56272","0.01222"
"15186","91.08000","7.59016","0.01314"
"15241","91.41000","7.61766","0.01452"
"15296","91.74000","7.64517","0.01433"
"15351","92.07000","7.67267","0.01426"
"15406","92.40000","7.70018","0.01423"
"15461","92.73000","7.72762","0.01420"
"15516","93.06000","7.75518","0.01179"
"15571","93.39000","7.78268","0.01138"
"15626","93.72000","7.81013","0.01232"
"15681","94.05000","7.83769","0.01184"
"15736","94.38000","7.86519","0.01237"
"15791","94.71000","7.89264","0.01313"
"15846","95.04000","7.92020","0.01324"
"15901","95.37000","7.94764","0.01243"
"15956","95.70000","7.97521","0.01233"
"16011","96.03000","8.00265","0.01164"
"16066","96.36000","8.03021","0.01111"
"16121","96.69000","8.05772","0.01099"
"16176","97.02000","8.08510","0.01056"
"16231","97.35000","8.11272","0.01093"
"16286","97.68000","8.14023","0.01066"
"16341","98.01000","8.16767","0.01047"
"16396","98.34000","8.19517","0.01047"
"16451","98.67000","8.22268","0.01041"
"16506","99.00000","8.25018","0.00987"
"16561","99.33000","8.27768","0.01050"
"16616","99.66000","8.30513","0.01101"
"16671","99.99000","8.33269","0.01106"
"16726","100.32000","8.36013","0.01154"
"16781","100.65000","8.38769","0.01178"
"16836","100.98000","8.41526","0.01152"
"16891","101.31000","8.44264","0.01171"
"16946","101.64000","8.47020","0.01214"
"17001","101.97000","8.49771","0.01257"
"17056","102.30000","8.52515","0.01263"
"17111","102.63000","8.55265","0.01282"
"17166","102.96000","8.58016","0.01381"
"17221","103.29000","8.60766","0.01347"
"17276","103.62000","8.63522","0.01324"
"17331","103.95000","8.66261","0.01291"
"17386","104.28000","8.69017","0.01336"
"17441","104.61000","8.71761","0.01335"
"17496","104.94000","8.74518","0.01399"
"17551","105.27000","8.77268","0.01414"
"17606","105.60000","8.80012","0.01385"
"17661","105.93000","8.82769","0.01398"
"17716","106.26000","8.85519","0.01405"
"17771","106.59000","8.88269","0.01385"
"17826","106.92000","8.91020","0.01500"
"17881","107.25000","8.93764","0.01456"
"17936","107.58000","8.96520","0.01325"
"17991","107.91000","8.99270","0.01337"
"18046","108.24000","9.02021","0.01361"
"18101","108.57000","9.04771","0.01332"
"18156","108.90000","9.07515","0.01421"
"18211","109.23000","9.10266","0.01429"
"18266","109.56200","9.13040","0.01477"
"18321","109.89200","9.15778","0.01486"
"18376","110.22200","9.18535","0.01450"
"18431","110.55200","9.21285","0.01412"
"18486","110.88200","9.24029","0.01462"
"18541","111.21200","9.26792","0.01480"
"18596","111.54200","9.29530","0.01568"
"18651","111.87200","9.32286","0.01341"
"18706","112.20200","9.35037","0.01297"
"18761","112.53200","9.37781","0.01408"
"18816","112.86200","9.40537","0.01356"
"18871","113.19200","9.43281","0.01379"
"18926","113.52200","9.46032","0.01416"
"18981","113.85200","9.48782","0.01525"
"19036","114.18200","9.51532","0.01451"
"19091","114.51200","9.54283","0.01558"
"19146","114.84200","9.57033","0.01477"
"19201","115.17200","9.59789","0.01536"
"19256","115.50200","9.62540","0.01623"
"19311","115.83200","9.65278","0.01589"
"19366","116.16200","9.68040","0.01637"
"19421","116.49200","9.70779","0.01626"
"19476","116.82200","9.73535","0.01656"
"19531","117.15200","9.76285","0.01664"
"19586","117.48200","9.79030","0.01703"
"19641","117.81200","9.81780","0.01739"
"19696","118.14200","9.84536","0.01832"
"19751","118.47200","9.87287","0.01902"
"19806","118.80200","9.90031","0.01817"
"19861","119.13200","9.92781","0.01877"
"19916","119.46200","9.95537","0.01913"
"19971","119.79200","9.98288","0.01934"
"20026","120.12200","10.01026","0.01911"
"20081","120.45200","10.03788","0.01671"
"20136","120.78200","10.06533","0.01698"
"20191","121.11200","10.09283","0.01815"
"20246","121.44200","10.12033","0.01782"
"20301","121.77200","10.14778","0.01838"
"20356","122.10200","10.17534","0.01896"
"20411","122.43200","10.20284","0.01925"
"20466","122.76200","10.23035","0.01953"
"20521","123.09200","10.25791","0.02035"
"20576","123.42200","10.28523","0.01994"
"20631","123.75200","10.31286","0.01992"
"20686","124.08200","10.34030","0.02056"
"20741","124.41200","10.36786","0.02098"
"20796","124.74200","10.39537","0.02139"
"20851","125.07200","10.42287","0.02130"
"20906","125.40200","10.45037","0.02164"
"20961","125.73200","10.47788","0.02160"
"21016","126.06200","10.50538","0.02084"
"21071","126.39200","10.53288","0.02134"
"21126","126.72200","10.56033","0.01928"
"21181","127.05200","10.58783","0.01962"
"21236","127.38200","10.61539","0.01846"
"21291","127.71200","10.64284","0.01913"
"21346","128.04200","10.67040","0.01969"
"21401","128.37200","10.69790","0.01968"
"21456","128.70200","10.72534","0.02127"
"21511","129.03200","10.75285","0.02111"
"21566","129.36200","10.78035","0.02144"
"21621","129.69200","10.80785","0.02196"
"21676","130.02200","10.83536","0.02179"
"21731","130.35200","10.86280","0.02217"
"21786","130.68200","10.89036","0.02279"
"21841","131.01200","10.91781","0.02366"
"21896","131.34200","10.94531","0.02389"
"21951","131.67200","10.97287","0.02399"
"22006","132.00200","11.00032","0.02372"
"22061","132.33200","11.02788","0.02346"
"22116","132.66200","11.05532","0.02382"
"22171","132.99200","11.08283","0.02365"
"22226","133.32200","11.11033","0.02375"
"22281","133.65200","11.13777","0.02355"
"22336","133.98200","11.16540","0.02421"
"22391","134.31200","11.19284","0.02503"
"22446","134.64200","11.22028","0.02574"
"22501","134.97200","11.24785","0.02547"
"22556","135.30200","11.27535","0.02628"
"22611","135.63200","11.30279","0.02674"
"22666","135.96200","11.33035","0.02691"
"22721","136.29200","11.35786","0.02666"
"22776","136.62200","11.38536","0.01604"
"22831","136.95200","11.41287","0.01410"
"22886","137.28200","11.44031","0.01530"
"22941","137.61200","11.46781","0.01581"
"22996","137.94200","11.49525","0.01708"
"23051","138.27200","11.52294","0.01801"
"23106","138.60200","11.55038","0.01880"
"23161","138.93200","11.57782","0.02005"
"23216","139.26200","11.60539","0.02015"
"23271","139.59200","11.63277","0.02053"
"23326","139.92200","11.66033","0.02041"
"23381","140.25200","11.68784","0.02195"
"23436","140.58200","11.71528","0.02242"
"23491","140.91200","11.74290","0.02285"
"23546","141.24200","11.77035","0.01799"
"23601","141.57200","11.79791","0.02018"
"23656","141.90200","11.82535","0.02038"
"23711","142.23200","11.85274","0.02105"
"23766","142.56200","11.88036","0.02193"
"23821","142.89200","11.90786","0.02179"
"23876","143.22200","11.93531","0.02273"
"23931","143.55200","11.96287","0.02202"
"23986","143.88200","11.99031","0.02217"
"24041","144.21200","12.01782","0.02238"
"24096","144.54200","12.04538","0.02307"
"24151","144.87200","12.07282","0.02303"
"24206","145.20200","12.10039","0.02324"
"24261","145.53200","12.12783","0.02265"
"24316","145.86200","12.15539","0.02377"
"24371","146.19200","12.18289","0.02306"
"24426","146.52200","12.21022","0.02408"
"24481","146.85200","12.23790","0.02394"
"24536","147.18200","12.26534","0.02300"
"24591","147.51200","12.29285","0.02223"
"24646","147.84200","12.32035","0.02332"
"24701","148.17200","12.34785","0.02320"
"24756","148.50200","12.37536","0.02326"
"24811","148.83200","12.40280","0.02324"
"24866","149.16200","12.43030","0.02327"
"24921","149.49200","12.45787","0.02365"
"24976","149.82200","12.48531","0.02359"
"25031","150.15200","12.51287","0.02253"
"25086","150.48200","12.54038","0.02318"
"25141","150.81200","12.56776","0.02326"
"25196","151.14200","12.59538","0.02393"
"25251","151.47200","12.62283","0.00289"
"25306","151.80200","12.65039","0.00401"
"25361","152.13200","12.67789","0.00524"
"25416","152.46200","12.70528","0.00403"
"25471","152.79200","12.73284","0.00472"
"25526","153.12200","12.76034","0.00440"
"25581","153.45200","12.78779","0.00443"
"25636","153.78200","12.81541","0.00465"
"25691","154.11200","12.84285","0.00454"
"25746","154.44200","12.87036","0.00536"
"25801","154.77200","12.89792","0.00449"
"25856","155.10200","12.92524","0.00552"
"25911","155.43200","12.95286","0.00535"
"25966","155.76200","12.98037","0.00560"
"26021","156.09200","13.00787","0.00642"
"26076","156.42200","13.03537","0.00595"
"26131","156.75200","13.06282","0.00617"
"26186","157.08200","13.09038","0.00636"
"26241","157.41200","13.11782","0.00533"
"26296","157.74200","13.14533","0.00560"
"26351","158.07200","13.17289","0.00670"
"26406","158.40200","13.20033","0.00633"
"26461","158.73200","13.22784","0.00679"
"26516","159.06200","13.25534","0.00695"
"26571","159.39200","13.28278","0.00721"
"26626","159.72200","13.31035","0.00687"
"26681","160.05200","13.33779","0.00839"
"26736","160.38200","13.36529","0.00821"
"26791","160.71200","13.39286","0.00817"
"26846","161.04200","13.42030","0.00821"
"26901","161.37200","13.44786","0.00864"
"26956","161.70200","13.47537","0.00887"
"27011","162.03200","13.50281","0.00904"
"27066","162.36200","13.53037","0.00977"
"27121","162.69200","13.55781","0.00955"
"27176","163.02200","13.58538","0.00993"
"27231","163.35200","13.61288","0.01024"
"27286","163.68200","13.64032","0.01075"
"27341","164.01200","13.66789","0.01073"
"27396","164.34200","13.69527","0.01038"
"27451","164.67200","13.72283","0.01102"
"27506","165.00200","13.75040","0.01160"
"27561","165.33200","13.77778","0.01183"
"27616","165.66200","13.80534","0.01245"
"27671","165.99200","13.83279","0.01270"
"27726","166.32200","13.86029","0.01333"
"27781","166.65200","13.88785","0.01370"
"27836","166.98200","13.91536","0.01427"
"27891","167.31200","13.94292","0.01428"
"27946","167.64200","13.97030","0.01443"
"28001","167.97200","13.99781","0.01465"
"28056","168.30200","14.02531","0.01420"
"28111","168.63200","14.05281","0.01408"
"28166","168.96200","14.08038","0.01481"
"28221","169.29200","14.10788","0.01556"
"28276","169.62200","14.13532","0.01582"
"28331","169.95200","14.16283","0.01636"
"28386","170.28200","14.19039","0.01665"
"28441","170.61200","14.21777","0.01715"
"28496","170.94200","14.24533","0.01636"
"28551","171.27200","14.27278","0.01874"
"28606","171.60200","14.30040","0.01833"
"28661","171.93200","14.32784","0.01810"
"28716","172.26200","14.35535","0.01815"
"28771","172.59200","14.38285","0.01871"
"28826","172.92200","14.41023","0.01884"
"28881","173.25200","14.43786","0.01818"
"28936","173.58200","14.46536","0.01910"
"28991","173.91200","14.49286","0.01926"
"29046","174.24200","14.52037","0.01994"
"29101","174.57200","14.54787","0.01889"
"29156","174.90200","14.57531","0.01932"
"29211","175.23200","14.60282","0.01993"
"29266","175.56200","14.63032","0.02039"
"29321","175.89200","14.65788","0.02097"
"29376","176.22200","14.68533","0.02105"
"29431","176.55200","14.71289","0.02103"
"29486","176.88200","14.74039","0.02129"
"29541","177.21200","14.76778","0.02212"
"29596","177.54200","14.79534","0.02032"
"29651","177.87200","14.82284","0.01979"
"29706","178.20200","14.85028","0.02055"
"29761","178.53200","14.87779","0.01982"
"29816","178.86200","14.90529","0.01976"
"29871","179.19200","14.93285","0.01891"
"29926","179.52200","14.96036","0.01874"
"29981","179.85200","14.98780","0.01961"
"30036","180.18200","15.01536","0.01974"
"30091","180.51200","15.04287","0.01986"
"30146","180.84200","15.07031","0.01791"
"30201","181.17200","15.09787","0.01799"
"30256","181.50200","15.12526","0.01823"
"30311","181.83200","15.15288","0.01752"
"30366","182.16200","15.18038","0.01751"
"30421","182.49200","15.20783","0.01725"
"30476","182.82200","15.23533","0.01749"
"30531","183.15200","15.26277","0.01787"
"30586","183.48200","15.29034","0.01537"
"30641","183.81200","15.31784","0.01601"
"30696","184.14200","15.34534","0.01640"
"30751","184.47200","15.37290","0.01690"
"30806","184.80200","15.40029","0.01657"
"30861","185.13200","15.42785","0.01564"
"30916","185.46200","15.45535","0.01518"
"30971","185.79200","15.48280","0.01493"
"31026","186.12200","15.51030","0.01406"
"31081","186.45200","15.53780","0.01337"
"31136","186.78200","15.56537","0.01304"
"31191","187.11200","15.59287","0.01221"
"31246","187.44200","15.62031","0.01335"
"31301","187.77200","15.64788","0.01113"
"31356","188.10200","15.67532","0.01136"
"31411","188.43200","15.70276","0.01120"
"31466","188.76200","15.73033","0.01142"
"31521","189.09200","15.75783","0.01181"
"31576","189.42200","15.78533","0.01187"
"31631","189.75200","15.81290","0.01163"
"31686","190.08200","15.84028","0.01068"
"31741","190.41200","15.86784","0.01141"
"31796","190.74200","15.89529","0.01137"
"31851","191.07200","15.92285","0.01080"
"31906","191.40200","15.95035","0.00985"
"31961","191.73200","15.97780","0.01025"
"32016","192.06200","16.00536","0.01041"
"32071","192.39200","16.03286","0.01037"
"32126","192.72200","16.06037","0.00993"
"32181","193.05200","16.08781","0.01028"
"32236","193.38200","16.11537","0.00985"
"32291","193.71200","16.14288","0.00965"
"32346","194.04200","16.17038","0.01011"
"32401","194.37200","16.19788","0.01058"
"32456","194.70200","16.22532","0.01060"
"32511","195.03200","16.25283","0.01087"
"32566","195.36200","16.28033","0.01046"
"32621","195.69200","16.30795","0.01084"
"32676","196.02200","16.33528","0.01091"
"32731","196.35200","16.36284","0.01072"
"32786","196.68200","16.39028","0.01119"
"32841","197.01200","16.41785","0.01179"
"32896","197.34200","16.44535","0.01100"
"32951","197.67200","16.47279","0.01065"
"33006","198.00200","16.50030","0.01113"
"33061","198.33200","16.52780","0.01057"
"33116","198.66200","16.55530","0.01130"
"33171","198.99200","16.58293","0.01035"
"33226","199.32200","16.61031","0.01023"
"33281","199.65200","16.63781","0.01058"
"33336","199.98200","16.66537","0.01056"
"33391","200.31200","16.69282","0.01179"
"33446","200.64200","16.72038","0.01183"
"33501","200.97200","16.74783","0.01193"
"33556","201.30200","16.77533","0.01115"
"33611","201.63200","16.80283","0.01115"
"33666","201.96200","16.83027","0.01107"
"33721","202.29200","16.85790","0.01120"
"33776","202.62200","16.88534","0.01083"
"33831","202.95200","16.91284","0.01158"
"33886","203.28200","16.94035","0.01152"
"33941","203.61200","16.96779","0.01087"
"33996","203.94200","16.99535","0.01167"
"34051","204.27200","17.02286","0.01190"
"34106","204.60200","17.05030","0.01284"
"34161","204.93200","17.07786","0.01155"
"34216","205.26200","17.10537","0.01256"
"34271","205.59200","17.13287","0.01290"
"34326","205.92200","17.16037","0.01263"
"34381","206.25200","17.18782","0.01230"
"34436","206.58200","17.21538","0.01211"
"34491","206.91200","17.24282","0.01054"
"34546","207.24200","17.27027","0.01050"
"34601","207.57200","17.29789","0.01079"
"34656","207.90200","17.32527","0.01059"
"34711","208.23200","17.35284","0.01068"
"34766","208.56200","17.38034","0.01066"
"34821","208.89200","17.40784","0.01075"
"34876","209.22200","17.43535","0.01120"
"34931","209.55200","17.46285","0.01088"
"34986","209.88200","17.49035","0.01082"
"35041","210.21200","17.51785","0.01180"
"35096","210.54200","17.54530","0.01148"
"35151","210.87200","17.57286","0.01234"
"35206","211.20200","17.60036","0.01210"
"35261","211.53200","17.62781","0.01151"
"35316","211.86200","17.65537","0.01166"
"35371","212.19200","17.68282","0.01209"
"35426","212.52200","17.71038","0.01236"
"35481","212.85200","17.73782","0.01219"
"35536","213.18200","17.76532","0.01308"
"35591","213.51200","17.79283","0.01317"
"35646","213.84200","17.82027","0.01406"
"35701","214.17200","17.84783","0.01307"
"35756","214.50200","17.87539","0.01368"
"35811","214.83200","17.90284","0.01383"
"35866","215.16200","17.93034","0.01445"
"35921","215.49200","17.95785","0.01449"
"35976","215.82200","17.98535","0.01386"
"36031","216.15200","18.01285","0.01520"
"36086","216.48200","18.04030","0.01497"
"36141","216.81200","18.06786","0.01573"
"36196","217.14200","18.09530","0.01460"
"36251","217.47200","18.12280","0.01420"
"36306","217.80200","18.15037","0.01431"
"36361","218.13200","18.17781","0.01445"
"36416","218.46200","18.20537","0.01483"
"36471","218.79200","18.23288","0.01490"
"36526","219.12200","18.26026","0.01529"
"36581","219.45200","18.28782","0.01532"
"36636","219.78200","18.31533","0.01604"
"36691","220.11200","18.34283","0.01616"
"36746","220.44200","18.37033","0.01611"
"36801","220.77200","18.39784","0.01645"
"36856","221.10200","18.42540","0.01698"
"36911","221.43200","18.45284","0.01598"
"36966","221.76200","18.48035","0.01613"
"37021","222.09200","18.50785","0.01703"
"37076","222.42200","18.53529","0.01708"
"37131","222.75200","18.56286","0.01650"
"37186","223.08200","18.59042","0.01571"
"37241","223.41200","18.61780","0.01577"
"37296","223.74200","18.64531","0.01600"
"37351","224.07200","18.67281","0.01489"
"37406","224.40200","18.70037","0.01263"
"37461","224.73200","18.72788","0.01275"
"37516","225.06200","18.75532","0.01245"
"37571","225.39200","18.78282","0.01267"
"37626","225.72200","18.81032","0.01237"
"37681","226.05200","18.83783","0.01293"
"37736","226.38200","18.86539","0.01327"
"37791","226.71200","18.89277","0.01288"
"37846","227.04200","18.92034","0.01286"
"37901","227.37200","18.94784","0.01293"
"37956","227.70200","18.97534","0.01269"
"38011","228.03200","19.00285","0.01309"
"38066","228.36200","19.03029","0.01267"
"38121","228.69200","19.05785","0.01280"
"38176","229.02200","19.08536","0.01368"
"38231","229.35200","19.11280","0.01280"
"38286","229.68200","19.14036","0.01276"
"38341","230.01200","19.16781","0.01265"
"38396","230.34200","19.19531","0.01227"
"38451","230.67200","19.22293","0.01278"
"38506","231.00200","19.25032","0.01275"
"38561","231.33200","19.27788","0.01173"
"38616","231.66200","19.30538","0.01238"
"38671","231.99200","19.33289","0.01243"
"38726","232.32200","19.36033","0.01133"
"38781","232.65200","19.38777","0.01125"
"38836","232.98200","19.41540","0.01140"
"38891","233.31200","19.44284","0.01139"
"38946","233.64200","19.47028","0.01183"
"39001","233.97200","19.49791","0.01106"
"39056","234.30200","19.52535","0.01004"
"39111","234.63200","19.55285","0.01040"
"39166","234.96200","19.58035","0.01007"
"39221","235.29200","19.60780","0.01014"
"39276","235.62200","19.63536","0.00951"
"39331","235.95200","19.66281","0.00996"
"39386","236.28200","19.69037","0.00966"
"39441","236.61200","19.71781","0.00972"
"39496","236.94200","19.74525","0.00968"
"39551","237.27200","19.77288","0.01011"
"39606","237.60200","19.80032","0.01027"
"39661","237.93200","19.82788","0.00999"
"39716","238.26200","19.85539","0.01055"
"39771","238.59200","19.88283","0.01008"
"39826","238.92200","19.91033","0.01043"
"39881","239.25200","19.93784","0.00939"
"39936","239.58200","19.96534","0.01019"
"39991","239.91200","19.99284","0.01000"
"40046","240.24200","20.02035","0.01042"
"40101","240.57200","20.04785","0.01051"
"40156","240.90200","20.07541","0.01050"
"40211","241.23200","20.10274","0.00987"
"40266","241.56200","20.13036","0.00982"
"40321","241.89200","20.15786","0.01018"
"40376","242.22200","20.18530","0.01009"
"40431","242.55200","20.21287","0.01001"
"40486","242.88200","20.24037","0.01041"
"40541","243.21200","20.26781","0.01030"
"40596","243.54200","20.29532","0.01087"
"40651","243.87200","20.32282","0.01104"
"40706","244.20200","20.35032","0.01075"
"40761","244.53200","20.37783","0.01073"
"40816","244.86200","20.40539","0.01004"
"40871","245.19200","20.43283","0.01028"
"40926","245.52200","20.46028","0.01061"
"40981","245.85200","20.48784","0.01051"
"41036","246.18200","20.51534","0.01113"
"41091","246.51200","20.54279","0.01063"
"41146","246.84200","20.57035","0.01075"
"41201","247.17200","20.59785","0.01096"
"41256","247.50200","20.62530","0.01128"
"41311","247.83200","20.65286","0.01116"
"41366","248.16200","20.68030","0.01149"
"41421","248.49200","20.70787","0.01123"
"41476","248.82200","20.73531","0.01098"
"41531","249.15200","20.76287","0.01192"
"41586","249.48200","20.79038","0.01145"
"41641","249.81200","20.81782","0.01071"
"41696","250.14200","20.84538","0.01159"
"41751","250.47200","20.87288","0.01116"
"41806","250.80200","20.90033","0.01079"
"41861","251.13200","20.92789","0.01167"
"41916","251.46200","20.95528","0.01143"
"41971","251.79200","20.98290","0.01213"
"42026","252.12200","21.01028","0.01191"
"42081","252.45200","21.03778","0.01223"
"42136","252.78200","21.06541","0.01176"
"42191","253.11200","21.09279","0.01154"
"42246","253.44200","21.12041","0.01131"
"42301","253.77200","21.14786","0.01191"
"42356","254.10200","21.17530","0.01117"
"42411","254.43200","21.20280","0.01119"
"42466","254.76200","21.23031","0.01040"
"42521","255.09200","21.25787","0.01107"
"42576","255.42200","21.28537","0.01093"
"42631","255.75200","21.31282","0.01128"
"42686","256.08200","21.34038","0.01157"
"42741","256.41200","21.36782","0.01175"
"42796","256.74200","21.39527","0.01162"
"42851","257.07200","21.42283","0.01232"
"42906","257.40200","21.45027","0.01265"
"42961","257.73200","21.47789","0.01206"
"43016","258.06200","21.50540","0.01192"
"43071","258.39200","21.53284","0.01248"
"43126","258.72200","21.56034","0.01169"
"43181","259.05200","21.58779","0.01178"
"43236","259.38200","21.61541","0.01145"
"43291","259.71200","21.64285","0.01195"
"43346","260.04200","21.67030","0.01200"
"43401","260.37200","21.69786","0.01253"
"43456","260.70200","21.72536","0.01253"
"43511","261.03200","21.75287","0.01356"
"43566","261.36200","21.78037","0.01314"
"43621","261.69200","21.80781","0.01282"
"43676","262.02200","21.83538","0.01318"
"43731","262.35200","21.86282","0.01290"
"43786","262.68200","21.89032","0.01231"
"43841","263.01200","21.91783","0.01212"
"43896","263.34200","21.94527","0.01202"
"43951","263.67200","21.97289","0.01234"
"44006","264.00200","22.00034","0.01288"
"44061","264.33200","22.02778","0.01232"
"44116","264.66200","22.05534","0.01326"
"44171","264.99200","22.08279","0.01321"
"44226","265.32200","22.11029","0.01369"
"44281","265.65200","22.13785","0.01372"
"44336","265.98200","22.16529","0.01335"
"44391","266.31200","22.19286","0.01309"
"44446","266.64200","22.22036","0.01362"
"44501","266.97200","22.24781","0.01372"
"44556","267.30200","22.27537","0.01381"
"44611","267.63200","22.30275","0.01424"
"44666","267.96200","22.33038","0.01403"
"44721","268.29200","22.35788","0.01497"
"44776","268.62200","22.38532","0.01467"
"44831","268.95200","22.41289","0.01384"
"44886","269.28200","22.44033","0.01463"
"44941","269.61200","22.46783","0.01460"
"44996","269.94200","22.49533","0.01458"
"45051","270.27200","22.52284","0.01458"
"45106","270.60200","22.55040","0.01475"
"45161","270.93200","22.57778","0.01544"
"45216","271.26200","22.60534","0.01489"
"45271","271.59200","22.63291","0.01569"
"45326","271.92200","22.66029","0.01504"
"45381","272.25200","22.68786","0.01530"
"45436","272.58200","22.71536","0.01529"
"45491","272.91200","22.74286","0.01558"
"45546","273.24200","22.77036","0.01557"
"45601","273.57200","22.79787","0.01624"
"45656","273.90200","22.82531","0.01710"
"45711","274.23200","22.85287","0.01675"
"45766","274.56200","22.88032","0.01713"
"45821","274.89200","22.90782","0.01773"
"45876","275.22200","22.93533","0.01790"
"45931","275.55200","22.96283","0.01827"
"45986","275.88200","22.99039","0.01849"
"46041","276.21200","23.01777","0.01877"
"46096","276.54200","23.04540","0.01785"
"46151","276.87200","23.07284","0.01772"
"46206","277.20200","23.10034","0.01660"
"46261","277.53200","23.12785","0.01727"
"46316","277.86200","23.15529","0.01737"
"46371","278.19200","23.18285","0.01790"
"46426","278.52200","23.21042","0.01791"
"46481","278.85200","23.23780","0.01817"
"46536","279.18200","23.26542","0.01910"
"46591","279.51200","23.29281","0.01901"
"46646","279.84200","23.32031","0.01925"
"46701","280.17200","23.34787","0.01967"
"46756","280.50200","23.37532","0.02015"
"46811","280.83200","23.40282","0.02107"
"46866","281.16200","23.43032","0.02070"
"46921","281.49200","23.45783","0.02120"
"46976","281.82200","23.48539","0.02195"
"47031","282.15200","23.51277","0.02109"
"47086","282.48200","23.54033","0.02277"
"47141","282.81200","23.56784","0.02290"
"47196","283.14200","23.59528","0.02323"
"47251","283.47200","23.62290","0.02339"
"47306","283.80200","23.65029","0.02273"
"47361","284.13200","23.67785","0.02399"
"47416","284.46200","23.70535","0.02402"
"47471","284.79200","23.73280","0.02383"
"47526","285.12200","23.76042","0.02362"
"47581","285.45200","23.78780","0.02408"
"47636","285.78200","23.81531","0.02404"
"47691","286.11200","23.84287","0.02378"
"47746","286.44200","23.87025","0.02354"
"47801","286.77200","23.89788","0.02201"
"47856","287.10200","23.92532","0.02072"
"47911","287.43200","23.95282","0.02118"
"47966","287.76200","23.98033","0.02115"
"48021","288.09200","24.00783","0.02116"
"48076","288.42200","24.03533","0.02175"
"48131","288.75200","24.06283","0.02253"
"48186","289.08200","24.09034","0.02237"
"48241","289.41200","24.11784","0.02269"
"48296","289.74200","24.14535","0.02302"
"48351","290.07200","24.17285","0.02298"
"48406","290.40200","24.20041","0.02400"
"48461","290.73200","24.22774","0.02353"
"48516","291.06200","24.25536","0.02415"
"48571","291.39200","24.28286","0.02462"
"48626","291.72200","24.31030","0.02501"
"48681","292.05200","24.33781","0.02533"
"48736","292.38200","24.36531","0.02575"
"48791","292.71200","24.39281","0.02612"
"48846","293.04200","24.42032","0.02546"
"48901","293.37200","24.44782","0.02593"
"48956","293.70200","24.47538","0.02605"
"49011","294.03200","24.50277","0.02626"
"49066","294.36200","24.53033","0.02638"
"49121","294.69200","24.55789","0.02701"
"49176","295.02200","24.58534","0.02718"
"49231","295.35200","24.61284","0.02729"
"49286","295.68200","24.64034","0.02742"
"49341","296.01200","24.66785","0.02711"
"49396","296.34200","24.69535","0.02788"
"49451","296.67200","24.72285","0.02842"
"49506","297.00200","24.75035","0.02891"
"49561","297.33200","24.77786","0.02924"
"49616","297.66200","24.80530","0.02947"
"49671","297.99200","24.83286","0.03008"
"49726","298.32200","24.86031","0.03040"
"49781","298.65200","24.88781","0.03100"
"49836","298.98200","24.91537","0.03142"
"49891","299.31200","24.94282","0.03113"
"49946","299.64200","24.97032","0.03068"
"50001","299.97200","24.99783","0.03124"
"50056","300.30200","25.02533","0.03166"
"50111","300.63200","25.05283","0.03094"
"50166","300.96200","25.08027","0.03053"
"50221","301.29200","25.10784","0.03188"
"50276","301.62200","25.13534","0.03175"
"50331","301.95200","25.16278","0.03240"
"50386","302.28200","25.19040","0.03219"
"50441","302.61200","25.21779","0.03228"
"50496","302.94200","25.24535","0.03313"
"50551","303.27200","25.27286","0.03329"
"50606","303.60200","25.30024","0.01465"
"50661","303.93200","25.32786","0.01474"
"50716","304.26200","25.35530","0.01498"
"50771","304.59200","25.38287","0.01454"
"50826","304.92200","25.41037","0.01556"
"50881","305.25200","25.43782","0.01702"
"50936","305.58200","25.46538","0.01638"
"50991","305.91200","25.49282","0.01615"
"51046","306.24200","25.52032","0.01704"
"51101","306.57200","25.54783","0.01704"
"51156","306.90200","25.57533","0.01657"
"51211","307.23200","25.60284","0.01786"
"51266","307.56200","25.63040","0.01777"
"51321","307.89200","25.65784","0.01737"
"51376","308.22200","25.68535","0.01760"
"51431","308.55200","25.71279","0.01776"
"51486","308.88200","25.74041","0.01758"
"51541","309.21200","25.76785","0.01859"
"51596","309.54200","25.79524","0.01949"
"51651","309.87200","25.82286","0.01935"
"51706","310.20200","25.85030","0.01995"
"51761","310.53200","25.87787","0.01958"
"51816","310.86200","25.90537","0.01967"
"51871","311.19200","25.93282","0.02105"
"51926","311.52200","25.96037","0.02165"
"51981","311.85200","25.98776","0.02034"
"52036","312.18200","26.01532","0.02124"
"52091","312.51200","26.04282","0.02218"
"52146","312.84200","26.07033","0.02151"
"52201","313.17200","26.09789","0.02211"
"52256","313.50200","26.12539","0.02063"
"52311","313.83200","26.15284","0.02110"
"52366","314.16200","26.18034","0.02088"
"52421","314.49200","26.20779","0.02120"
"52476","314.82200","26.23535","0.02115"
"52531","315.15200","26.26285","0.02091"
"52586","315.48200","26.29035","0.02216"
"52641","315.81200","26.31786","0.02180"
"52696","316.14200","26.34530","0.02212"
"52751","316.47200","26.37280","0.02236"
"52806","316.80200","26.40037","0.02184"
"52861","317.13200","26.42781","0.02168"
"52916","317.46200","26.45537","0.02209"
"52971","317.79200","26.48288","0.02238"
"53026","318.12200","26.51032","0.02204"
"53081","318.45200","26.53788","0.02221"
"53136","318.78200","26.56533","0.02040"
"53191","319.11200","26.59283","0.01609"
"53246","319.44200","26.62039","0.01618"
"53301","319.77200","26.64784","0.01689"
"53356","320.10200","26.67540","0.01809"
"53411","320.43200","26.70278","0.01770"
"53466","320.76200","26.73029","0.01841"
"53521","321.09200","26.75785","0.01889"
"53576","321.42200","26.78529","0.01963"
"53631","321.75200","26.81285","0.01915"
"53686","322.08200","26.84036","0.02030"
"53741","322.41200","26.86786","0.01984"
"53796","322.74200","26.89531","0.02056"
"53851","323.07200","26.92281","0.01950"
"53906","323.40200","26.95037","0.01946"
"53961","323.73200","26.97787","0.01950"
"54016","324.06200","27.00532","0.01962"
"54071","324.39200","27.03294","0.02005"
"54126","324.72200","27.06032","0.02063"
"54181","325.05200","27.08777","0.02108"
"54236","325.38200","27.11539","0.02016"
"54291","325.71200","27.14284","0.02006"
"54346","326.04200","27.17039","0.02007"
"54401","326.37200","27.19784","0.01998"
"54456","326.70200","27.22534","0.02003"
"54511","327.03200","27.25285","0.02000"
"54566","327.36200","27.28029","0.02035"
"54621","327.69200","27.30791","0.01995"
"54676","328.02200","27.33536","0.01960"
"54731","328.35200","27.36280","0.02072"
"54786","328.68200","27.39036","0.01985"
"54841","329.01200","27.41780","0.01872"
"54896","329.34200","27.44531","0.01892"
"54951","329.67200","27.47287","0.01919"
"55006","330.00200","27.50032","0.01704"
"55061","330.33200","27.52788","0.01739"
"55116","330.66200","27.55532","0.01752"
"55171","330.99200","27.58282","0.01730"
"55226","331.32200","27.61033","0.01715"
"55281","331.65200","27.63771","0.01755"
"55336","331.98200","27.66539","0.01768"
"55391","332.31200","27.69278","0.01782"
"55446","332.64200","27.72028","0.01791"
"55501","332.97200","27.74784","0.01719"
"55556","333.30200","27.77535","0.01801"
"55611","333.63200","27.80285","0.01796"
"55666","333.96200","27.83029","0.01794"
"55721","334.29200","27.85786","0.01845"
"55776","334.62200","27.88536","0.01857"
"55831","334.95200","27.91286","0.01877"
"55886","335.28200","27.94037","0.01882"
"55941","335.61200","27.96787","0.01946"
"55996","335.94200","27.99525","0.01893"
"56051","336.27200","28.02288","0.01920"
"56106","336.60200","28.05038","0.01873"
"56161","336.93200","28.07782","0.01835"
"56216","337.26200","28.10539","0.01857"
"56271","337.59200","28.13283","0.01873"
"56326","337.92200","28.16033","0.01952"
"56381","338.25200","28.18784","0.01901"
"56436","338.58200","28.21528","0.01928"
"56491","338.91200","28.24284","0.01985"
"56546","339.24200","28.27028","0.01938"
"56601","339.57200","28.29785","0.01981"
"56656","339.90200","28.32535","0.01962"
"56711","340.23200","28.35279","0.01934"
"56766","340.56200","28.38036","0.01975"
"56821","340.89200","28.40786","0.01947"
"56876","341.22200","28.43536","0.01948"
"56931","341.55200","28.46281","0.01968"
"56986","341.88200","28.49031","0.01951"
"57041","342.21200","28.51781","0.01968"
"57096","342.54200","28.54538","0.02069"
"57151","342.87200","28.57282","0.02111"
"57206","343.20200","28.60032","0.01993"
"57261","343.53200","28.62783","0.02043"
"57316","343.86200","28.65533","0.02086"
"57371","344.19200","28.68289","0.02042"
"57426","344.52200","28.71028","0.02045"
"57481","344.85200","28.73784","0.02095"
"57536","345.18200","28.76534","0.02136"
"57591","345.51200","28.79284","0.02115"
"57646","345.84200","28.82035","0.02105"
"57701","346.17200","28.84779","0.02144"
"57756","346.50200","28.87536","0.02127"
"57811","346.83200","28.90280","0.02115"
"57866","347.16200","28.93030","0.02167"
"57921","347.49200","28.95793","0.02145"
"57976","347.82200","28.98531","0.02220"
"58031","348.15200","29.01281","0.02209"
"58086","348.48200","29.04037","0.02187"
"58141","348.81200","29.06782","0.02261"
"58196","349.14200","29.09532","0.02263"
"58251","349.47200","29.12283","0.02252"
"58306","349.80200","29.15033","0.02332"
"58361","350.13200","29.17783","0.02226"
"58416","350.46200","29.20527","0.02242"
"58471","350.79200","29.23284","0.02349"
"58526","351.12200","29.26034","0.02396"
"58581","351.45200","29.28778","0.02355"
"58636","351.78200","29.31541","0.02374"
"58691","352.11200","29.34279","0.02336"
"58746","352.44200","29.37035","0.02333"
"58801","352.77200","29.39792","0.02370"
"58856","353.10200","29.42530","0.02425"
"58911","353.43200","29.45286","0.02425"
"58966","353.76200","29.48031","0.02429"
"59021","354.09200","29.50787","0.02408"
"59076","354.42200","29.53543","0.02393"
"59131","354.75200","29.56281","0.02423"
"59186","355.08200","29.59038","0.02501"
"59241","355.41200","29.61782","0.02495"
"59296","355.74200","29.64532","0.02541"
"59351","356.07200","29.67289","0.02581"
"59406","356.40200","29.70033","0.02641"
"59461","356.73200","29.72789","0.02620"
"59516","357.06200","29.75528","0.02598"
"59571","357.39200","29.78278","0.02632"
"59626","357.72200","29.81034","0.02623"
"59681","358.05200","29.83785","0.02563"
"59736","358.38200","29.86535","0.02654"
"59791","358.71200","29.89291","0.02636"
"59846","359.04200","29.92030","0.02653"
"59901","359.37200","29.94786","0.02698"
"59956","359.70200","29.97530","0.02677"
"60011","360.03200","30.00281","0.02678"
"60066","360.36200","30.03037","0.02746"
"60121","360.69200","30.05781","0.02716"
"60176","361.02200","30.08532","0.02730"
"60231","361.35200","30.11282","0.02704"
"60286","361.68200","30.14032","0.02858"
"60341","362.01200","30.16783","0.02769"
"60396","362.34200","30.19533","0.02838"
"60451","362.67200","30.22289","0.02814"
"60506","363.00200","30.25040","0.02838"
"60561","363.33200","30.27784","0.02865"
"60616","363.66200","30.30534","0.02929"
"60671","363.99200","30.33284","0.02863"
"60726","364.32200","30.36035","0.02923"
"60781","364.65200","30.38785","0.02946"
"60836","364.98200","30.41536","0.02962"
"60891","365.31200","30.44286","0.02972"
"60946","365.64200","30.47030","0.03086"
"61001","365.97200","30.49786","0.03113"
"61056","366.30200","30.52537","0.03009"
"61111","366.63200","30.55275","0.03075"
"61166","366.96200","30.58031","0.03103"
"61221","367.29200","30.60782","0.03093"
"61276","367.62200","30.63532","0.03150"
"61331","367.95200","30.66282","0.03149"
"61386","368.28200","30.69033","0.03203"
"61441","368.61200","30.71783","0.03148"
"61496","368.94200","30.74533","0.03182"
"61551","369.27200","30.77278","0.03238"
"61606","369.60200","30.80034","0.03287"
"61661","369.93200","30.82784","0.03281"
"61716","370.26200","30.85529","0.03272"
"61771","370.59200","30.88291","0.03278"
"61826","370.92200","30.91035","0.03306"
"61881","371.25200","30.93786","0.03356"
"61936","371.58200","30.96536","0.03339"
"61991","371.91200","30.99280","0.03382"
"62046","372.24200","31.02031","0.03411"
"62101","372.57200","31.04781","0.03400"
"62156","372.90200","31.07537","0.03423"
"62211","373.23200","31.10287","0.03478"
"62266","373.56200","31.13032","0.03491"
"62321","373.89200","31.15788","0.03504"
"62376","374.22200","31.18533","0.03549"
"62431","374.55200","31.21283","0.03553"
"62486","374.88200","31.24039","0.03566"
"62541","375.21200","31.26783","0.03632"
"62596","375.54200","31.29534","0.03589"
"62651","375.87200","31.32284","0.03705"
"62706","376.20200","31.35034","0.03766"
"62761","376.53200","31.37784","0.03711"
"62816","376.86200","31.40529","0.03793"
"62871","377.19200","31.43285","0.03789"
"62926","377.52200","31.46030","0.03786"
"62981","377.85200","31.48780","0.03845"
"63036","378.18200","31.51536","0.03832"
"63091","378.51200","31.54286","0.03816"
"63146","378.84200","31.57031","0.03875"
"63201","379.17200","31.59787","0.03923"
"63256","379.50200","31.62531","0.03946"
"63311","379.83200","31.65288","0.03992"
"63366","380.16200","31.68032","0.03968"
"63421","380.49200","31.70788","0.04005"
"63476","380.82200","31.73533","0.04033"
"63531","381.15200","31.76277","0.04031"
"63586","381.48200","31.79039","0.04107"
"63641","381.81200","31.81789","0.04124"
"63696","382.14200","31.84534","0.04102"
"63751","382.47200","31.87284","0.04181"
"63806","382.80200","31.90029","0.04171"
"63861","383.13200","31.92785","0.04199"
"63916","383.46200","31.95535","0.04216"
"63971","383.79200","31.98285","0.04273"
"64026","384.12200","32.01036","0.04269"
"64081","384.45200","32.03780","0.04300"
"64136","384.78200","32.06536","0.04302"
"64191","385.11200","32.09287","0.04287"
"64246","385.44200","32.12025","0.04286"
"64301","385.77200","32.14787","0.04336"
"64356","386.10200","32.17532","0.04401"
"64411","386.43200","32.20282","0.04411"
"64466","386.76200","32.23038","0.04428"
"64521","387.09200","32.25783","0.04482"
"64576","387.42200","32.28533","0.04466"
"64631","387.75200","32.31283","0.04483"
"64686","388.08200","32.34034","0.04493"
"64741","388.41200","32.36784","0.04568"
"64796","388.74200","32.39528","0.04568"
"64851","389.07200","32.42285","0.04591"
"64906","389.40200","32.45041","0.04622"
"64961","389.73200","32.47779","0.04642"
"65016","390.06200","32.50536","0.04659"
"65071","390.39200","32.53280","0.04654"
"65126","390.72200","32.56036","0.04733"
"65181","391.05200","32.58787","0.04734"
"65236","391.38200","32.61531","0.04752"
"65291","391.71200","32.64287","0.04780"
"65346","392.04200","32.67031","0.04819"
"65401","392.37200","32.69782","0.04851"
"65456","392.70200","32.72538","0.04842"
"65511","393.03200","32.75277","0.04876"
"65566","393.36200","32.78033","0.04906"
"65621","393.69200","32.80789","0.04976"
"65676","394.02200","32.83533","0.05006"
"65731","394.35200","32.86290","0.05047"
"65786","394.68200","32.89034","0.05041"
"65841","395.01200","32.91785","0.05140"
"65896","395.34200","32.94535","0.05139"
"65951","395.67200","32.97279","0.05243"
"66006","396.00200","33.00035","0.05254"
"66061","396.33200","33.02786","0.05333"
"66116","396.66200","33.05530","0.05360"
"66171","396.99200","33.08292","0.05471"
"66226","397.32200","33.11024","0.05466"
"66281","397.65200","33.13781","0.05561"
"66336","397.98200","33.16531","0.05635"
"66391","398.31200","33.19282","0.05706"
"66446","398.64200","33.22038","0.05794"
"66501","398.97200","33.24782","0.05856"
"66556","399.30200","33.27538","0.05899"
"66611","399.63200","33.30283","0.06042"
"66666","399.96200","33.33027","0.06099"
"66721","400.29200","33.35789","0.02733"
"66776","400.62200","33.38534","0.00315"
"66831","400.95200","33.41278","-0.00278"
"66886","401.28200","33.44040","0.00065"
"66941","401.61200","33.46779","-0.00152"
"66996","401.94200","33.49535","-0.00085"
"67051","402.27200","33.52285","-0.00222"
"67106","402.60200","33.55036","0.00104"
"67161","402.93200","33.57786","-0.00036"
"67216","403.26200","33.60530","0.00129"
"67271","403.59200","33.63287","-0.00221"
"67326","403.92200","33.66037","-0.00041"
"67381","404.25200","33.68782","-0.00031"
"67436","404.58200","33.71538","0.00067"
"67491","404.91200","33.74288","-0.00216"
"67546","405.24200","33.77032","-0.00121"
"67601","405.57200","33.79789","-0.00188"
"67656","405.90200","33.82527","0.00049"
"67711","406.23200","33.85289","-0.00168"
"67766","406.56200","33.88034","-0.00029"
"67821","406.89200","33.90784","-0.00186"
"67876","407.22200","33.93534","0.00005"
"67931","407.55200","33.96279","-0.00084"
"67986","407.88200","33.99035","-0.00010"
"68041","408.21200","34.01785","-0.00134"
"68096","408.54200","34.04530","-0.00067"
"68142","408.81800","34.06832","-0.00206"