File: Trajectories_together/170226_1Specimen_RawData_3.csv
"","V1","V2","V3"
"1","End date","2/26/2017",""
"2","Specimen label","1AT_7",""
"3","Maximum Load","0.00847","N"
"4","Time","Extension","Load"
"5","(s)","(mm)","(N)"
"6","0.00000","0.00000","0.00081"
"36","0.18000","0.01172","0.00122"
"66","0.36000","0.03007","0.00116"
"96","0.54000","0.04526","0.00080"
"126","0.72000","0.06015","0.00071"
"156","0.90000","0.07522","0.00108"
"186","1.08000","0.09022","0.00117"
"216","1.26000","0.10511","0.00148"
"246","1.44000","0.12018","0.00139"
"276","1.62000","0.13524","0.00142"
"306","1.80000","0.15013","0.00128"
"336","1.98000","0.16520","0.00124"
"366","2.16000","0.18021","0.00134"
"396","2.34000","0.19515","0.00115"
"426","2.52000","0.21022","0.00113"
"456","2.70000","0.22517","0.00179"
"486","2.88000","0.24011","0.00140"
"516","3.06000","0.25518","0.00120"
"546","3.24000","0.27025","0.00168"
"576","3.42000","0.28514","0.00128"
"606","3.60000","0.30014","0.00151"
"636","3.78000","0.31521","0.00148"
"666","3.96000","0.33016","0.00151"
"696","4.14000","0.34522","0.00129"
"726","4.32000","0.36017","0.00148"
"756","4.50000","0.37518","0.00177"
"786","4.68000","0.39019","0.00209"
"816","4.86000","0.40519","0.00201"
"846","5.04000","0.42014","0.00139"
"876","5.22000","0.43521","0.00224"
"906","5.40000","0.45016","0.00131"
"936","5.58000","0.46510","0.00186"
"966","5.76000","0.48017","0.00176"
"996","5.94000","0.49518","0.00200"
"1026","6.12000","0.51018","0.00171"
"1056","6.30000","0.52513","0.00177"
"1086","6.48000","0.54014","0.00175"
"1116","6.66000","0.55509","0.00224"
"1146","6.84000","0.57021","0.00177"
"1176","7.02000","0.58522","0.00201"
"1206","7.20000","0.60017","0.00178"
"1236","7.38000","0.61523","0.00220"
"1266","7.56000","0.63018","0.00182"
"1296","7.74000","0.64507","0.00199"
"1326","7.92000","0.66020","0.00171"
"1356","8.10000","0.67520","0.00199"
"1386","8.28000","0.69009","0.00167"
"1416","8.46000","0.70516","0.00224"
"1446","8.64000","0.72016","0.00151"
"1476","8.82000","0.73511","0.00214"
"1506","9.00000","0.75024","0.00186"
"1536","9.18000","0.76513","0.00193"
"1566","9.36000","0.78013","0.00227"
"1596","9.54000","0.79520","0.00150"
"1626","9.72000","0.81021","0.00212"
"1656","9.90000","0.82510","0.00207"
"1686","10.08000","0.84022","0.00168"
"1716","10.26000","0.85523","0.00237"
"1746","10.44000","0.87012","0.00187"
"1776","10.62000","0.88518","0.00255"
"1806","10.80000","0.90019","0.00246"
"1836","10.98000","0.91514","0.00182"
"1866","11.16000","0.93021","0.00191"
"1896","11.34000","0.94521","0.00243"
"1926","11.52000","0.96016","0.00197"
"1956","11.70000","0.97517","0.00236"
"1986","11.88000","0.99017","0.00237"
"2016","12.06000","1.00506","0.00239"
"2046","12.24000","1.02025","0.00247"
"2076","12.42000","1.03520","0.00257"
"2106","12.60000","1.05014","0.00231"
"2136","12.78000","1.06515","0.00216"
"2166","12.96000","1.08016","0.00274"
"2196","13.14000","1.09516","0.00229"
"2226","13.32000","1.11023","0.00230"
"2256","13.50000","1.12512","0.00277"
"2286","13.68000","1.14013","0.00297"
"2316","13.86000","1.15519","0.00230"
"2346","14.04000","1.17014","0.00285"
"2376","14.22000","1.18509","0.00236"
"2406","14.40000","1.20022","0.00253"
"2436","14.58000","1.21516","0.00263"
"2466","14.76000","1.23017","0.00252"
"2496","14.94000","1.24518","0.00183"
"2526","15.12000","1.26024","0.00264"
"2556","15.30000","1.27513","0.00178"
"2586","15.48000","1.29020","0.00339"
"2616","15.66000","1.30515","0.00247"
"2646","15.84000","1.32015","0.00306"
"2676","16.02000","1.33522","0.00249"
"2706","16.20000","1.35017","0.00269"
"2736","16.38000","1.36511","0.00255"
"2766","16.56000","1.38024","0.00232"
"2796","16.74000","1.39519","0.00238"
"2826","16.92000","1.41008","0.00263"
"2856","17.10000","1.42520","0.00243"
"2886","17.28000","1.44021","0.00198"
"2916","17.46000","1.45516","0.00216"
"2946","17.64000","1.47016","0.00261"
"2976","17.82000","1.48517","0.00283"
"3006","18.00000","1.50018","0.00222"
"3036","18.18000","1.51519","0.00225"
"3066","18.36000","1.53013","0.00284"
"3096","18.54000","1.54514","0.00273"
"3126","18.72000","1.56021","0.00269"
"3156","18.90000","1.57516","0.00279"
"3186","19.08000","1.59010","0.00303"
"3216","19.26000","1.60517","0.00260"
"3246","19.44000","1.62018","0.00295"
"3276","19.62000","1.63512","0.00243"
"3306","19.80000","1.65019","0.00176"
"3336","19.98000","1.66520","0.00271"
"3366","20.16000","1.68015","0.00258"
"3396","20.34000","1.69521","0.00249"
"3426","20.52000","1.71016","0.00298"
"3456","20.70000","1.72517","0.00347"
"3486","20.88000","1.74017","0.00330"
"3516","21.06000","1.75518","0.00300"
"3546","21.24000","1.77007","0.00318"
"3576","21.42000","1.78520","0.00269"
"3606","21.60000","1.80020","0.00255"
"3636","21.78000","1.81515","0.00322"
"3666","21.96000","1.83016","0.00301"
"3696","22.14000","1.84522","0.00292"
"3726","22.32000","1.86017","0.00313"
"3756","22.50000","1.87518","0.00351"
"3786","22.68000","1.89019","0.00319"
"3816","22.86000","1.90519","0.00263"
"3846","23.04000","1.92020","0.00304"
"3876","23.22000","1.93515","0.00324"
"3906","23.40000","1.95016","0.00327"
"3936","23.58000","1.96522","0.00240"
"3966","23.76000","1.98017","0.00333"
"3996","23.94000","1.99518","0.00283"
"4026","24.12000","2.01018","0.00311"
"4056","24.30000","2.02519","0.00324"
"4086","24.48000","2.04014","0.00303"
"4116","24.66000","2.05515","0.00287"
"4146","24.84000","2.07015","0.00299"
"4176","25.02000","2.08522","0.00323"
"4206","25.20000","2.10017","0.00307"
"4236","25.38000","2.11517","0.00339"
"4266","25.56000","2.13012","0.00294"
"4296","25.74000","2.14525","0.00312"
"4326","25.92000","2.16020","0.00304"
"4356","26.10000","2.17508","0.00343"
"4386","26.28000","2.19021","0.00302"
"4416","26.46000","2.20522","0.00289"
"4446","26.64000","2.22016","0.00273"
"4476","26.82000","2.23517","0.00286"
"4506","27.00000","2.25012","0.00317"
"4536","27.18000","2.26519","0.00363"
"4566","27.36000","2.28019","0.00270"
"4596","27.54000","2.29520","0.00345"
"4626","27.72000","2.31015","0.00284"
"4656","27.90000","2.32521","0.00311"
"4686","28.08000","2.34016","0.00305"
"4716","28.26000","2.35517","0.00346"
"4746","28.44000","2.37018","0.00306"
"4776","28.62000","2.38518","0.00338"
"4806","28.80000","2.40013","0.00329"
"4836","28.98000","2.41514","0.00307"
"4866","29.16000","2.43015","0.00258"
"4896","29.34000","2.44515","0.00338"
"4926","29.52000","2.46016","0.00303"
"4956","29.70000","2.47517","0.00313"
"4986","29.88000","2.49017","0.00328"
"5016","30.06000","2.50518","0.00338"
"5046","30.24000","2.52013","0.00321"
"5076","30.42000","2.53514","0.00273"
"5106","30.60000","2.55020","0.00306"
"5136","30.78000","2.56515","0.00278"
"5166","30.96000","2.58016","0.00284"
"5196","31.14000","2.59516","0.00282"
"5226","31.32000","2.61011","0.00265"
"5256","31.50000","2.62518","0.00323"
"5286","31.68000","2.64019","0.00264"
"5316","31.86000","2.65513","0.00303"
"5346","32.04000","2.67014","0.00266"
"5376","32.22000","2.68521","0.00340"
"5406","32.40000","2.70010","0.00241"
"5436","32.58000","2.71516","0.00256"
"5466","32.76000","2.73023","0.00277"
"5496","32.94000","2.74518","0.00254"
"5526","33.12000","2.76018","0.00279"
"5556","33.30000","2.77513","0.00311"
"5586","33.48000","2.79014","0.00318"
"5616","33.66000","2.80521","0.00349"
"5646","33.84000","2.82015","0.00249"
"5676","34.02000","2.83516","0.00196"
"5706","34.20000","2.85017","0.00213"
"5736","34.38000","2.86517","0.00189"
"5766","34.56000","2.88018","0.00270"
"5796","34.74000","2.89513","0.00188"
"5826","34.92000","2.91026","0.00229"
"5856","35.10000","2.92514","0.00258"
"5886","35.28000","2.94015","0.00300"
"5916","35.46000","2.95522","0.00255"
"5946","35.64000","2.97016","0.00231"
"5976","35.82000","2.98517","0.00261"
"6006","36.00000","3.00018","0.00260"
"6036","36.18000","3.01513","0.00270"
"6066","36.36000","3.03019","0.00301"
"6096","36.54000","3.04520","0.00262"
"6126","36.72000","3.06015","0.00233"
"6156","36.90000","3.07516","0.00243"
"6186","37.08000","3.09016","0.00275"
"6216","37.26000","3.10517","0.00283"
"6246","37.44000","3.12012","0.00250"
"6276","37.62000","3.13512","0.00263"
"6306","37.80000","3.15019","0.00236"
"6336","37.98000","3.16514","0.00209"
"6366","38.16000","3.18015","0.00224"
"6396","38.34000","3.19515","0.00219"
"6426","38.52000","3.21016","0.00191"
"6456","38.70000","3.22523","0.00213"
"6486","38.88000","3.24017","0.00226"
"6516","39.06000","3.25518","0.00170"
"6546","39.24000","3.27019","0.00245"
"6576","39.42000","3.28520","0.00247"
"6606","39.60000","3.30014","0.00218"
"6636","39.78000","3.31521","0.00287"
"6666","39.96000","3.33016","0.00263"
"6696","40.14000","3.34516","0.00251"
"6726","40.32000","3.36017","0.00208"
"6756","40.50000","3.37518","0.00229"
"6786","40.68000","3.39019","0.00240"
"6816","40.86000","3.40519","0.00175"
"6846","41.04000","3.42014","0.00244"
"6876","41.22000","3.43521","0.00260"
"6906","41.40000","3.45021","0.00188"
"6936","41.58000","3.46516","0.00278"
"6966","41.76000","3.48017","0.00260"
"6996","41.94000","3.49518","0.00290"
"7026","42.12000","3.51012","0.00205"
"7056","42.30000","3.52519","0.00249"
"7086","42.48000","3.54020","0.00241"
"7116","42.66000","3.55515","0.00245"
"7146","42.84000","3.57021","0.00245"
"7176","43.02000","3.58522","0.00264"
"7206","43.20000","3.60017","0.00265"
"7236","43.38000","3.61517","0.00265"
"7266","43.56000","3.63024","0.00244"
"7296","43.74000","3.64513","0.00299"
"7326","43.92000","3.66014","0.00251"
"7356","44.10000","3.67520","0.00251"
"7386","44.28000","3.69015","0.00297"
"7416","44.46000","3.70522","0.00218"
"7446","44.64000","3.72016","0.00245"
"7476","44.82000","3.73511","0.00254"
"7506","45.00000","3.75024","0.00254"
"7536","45.18000","3.76519","0.00292"
"7566","45.36000","3.78013","0.00319"
"7596","45.54000","3.79520","0.00307"
"7626","45.72000","3.81021","0.00273"
"7656","45.90000","3.82515","0.00324"
"7686","46.08000","3.84016","0.00281"
"7716","46.26000","3.85523","0.00282"
"7746","46.44000","3.87012","0.00295"
"7776","46.62000","3.88518","0.00270"
"7806","46.80000","3.90019","0.00296"
"7836","46.98000","3.91520","0.00295"
"7866","47.16000","3.93021","0.00299"
"7896","47.34000","3.94515","0.00291"
"7926","47.52000","3.96016","0.00301"
"7956","47.70000","3.97517","0.00237"
"7986","47.88000","3.99017","0.00228"
"8016","48.06000","4.00518","0.00294"
"8046","48.24000","4.02019","0.00304"
"8076","48.42000","4.03520","0.00235"
"8106","48.60000","4.05014","0.00315"
"8136","48.78000","4.06521","0.00289"
"8166","48.96000","4.08016","0.00270"
"8196","49.14000","4.09516","0.00291"
"8226","49.32000","4.11011","0.00240"
"8256","49.50000","4.12518","0.00259"
"8286","49.68000","4.14013","0.00262"
"8316","49.86000","4.15519","0.00226"
"8346","50.04000","4.17020","0.00284"
"8376","50.22000","4.18509","0.00292"
"8406","50.40000","4.20021","0.00207"
"8436","50.58000","4.21516","0.00231"
"8466","50.76000","4.23011","0.00257"
"8496","50.94000","4.24518","0.00318"
"8526","51.12000","4.26018","0.00304"
"8556","51.30000","4.27513","0.00319"
"8586","51.48000","4.29020","0.00244"
"8616","51.66000","4.30521","0.00280"
"8646","51.84000","4.32009","0.00229"
"8676","52.02000","4.33522","0.00279"
"8706","52.20000","4.35023","0.00295"
"8736","52.38000","4.36517","0.00297"
"8766","52.56000","4.38018","0.00306"
"8796","52.74000","4.39525","0.00332"
"8826","52.92000","4.41014","0.00265"
"8856","53.10000","4.42514","0.00312"
"8886","53.28000","4.44027","0.00268"
"8916","53.46000","4.45516","0.00326"
"8946","53.64000","4.47016","0.00366"
"8976","53.82000","4.48517","0.00251"
"9006","54.00000","4.50018","0.00324"
"9036","54.18000","4.51519","0.00320"
"9066","54.36000","4.53019","0.00274"
"9096","54.54000","4.54514","0.00277"
"9126","54.72000","4.56021","0.00333"
"9156","54.90000","4.57521","0.00225"
"9186","55.08000","4.59010","0.00245"
"9216","55.26000","4.60517","0.00269"
"9246","55.44000","4.62024","0.00293"
"9276","55.62000","4.63512","0.00250"
"9306","55.80000","4.65019","0.00252"
"9336","55.98000","4.66520","0.00244"
"9366","56.16000","4.68009","0.00272"
"9396","56.34000","4.69515","0.00304"
"9426","56.52000","4.71022","0.00307"
"9456","56.70000","4.72517","0.00353"
"9486","56.88000","4.74023","0.00267"
"9516","57.06000","4.75518","0.00273"
"9546","57.24000","4.77013","0.00258"
"9576","57.42000","4.78514","0.00312"
"9606","57.60000","4.80020","0.00324"
"9636","57.78000","4.81515","0.00268"
"9666","57.96000","4.83016","0.00278"
"9696","58.14000","4.84516","0.00306"
"9726","58.32000","4.86017","0.00278"
"9756","58.50000","4.87524","0.00271"
"9786","58.68000","4.89019","0.00260"
"9816","58.86000","4.90513","0.00246"
"9846","59.04000","4.92026","0.00302"
"9876","59.22000","4.93515","0.00322"
"9906","59.40000","4.95010","0.00358"
"9936","59.58000","4.96516","0.00310"
"9966","59.76000","4.98017","0.00279"
"9996","59.94000","4.99518","0.00270"
"10026","60.12000","5.01018","0.00256"
"10056","60.30000","5.02519","0.00238"
"10086","60.48000","5.04014","0.00269"
"10116","60.66000","5.05526","0.00299"
"10146","60.84000","5.07015","0.00223"
"10176","61.02000","5.08516","0.00297"
"10206","61.20000","5.10023","0.00270"
"10236","61.38000","5.11517","0.00313"
"10266","61.56000","5.13012","0.00234"
"10296","61.74000","5.14519","0.00284"
"10326","61.92000","5.16026","0.00302"
"10356","62.10000","5.17508","0.00351"
"10386","62.28000","5.19021","0.00347"
"10416","62.46000","5.20522","0.00302"
"10446","62.64000","5.22016","0.00288"
"10476","62.82000","5.23517","0.00252"
"10506","63.00000","5.25018","0.00286"
"10536","63.18000","5.26519","0.00266"
"10566","63.36000","5.28019","0.00301"
"10596","63.54000","5.29520","0.00283"
"10626","63.72000","5.31015","0.00244"
"10656","63.90000","5.32515","0.00311"
"10686","64.08000","5.34016","0.00305"
"10716","64.26000","5.35511","0.00269"
"10746","64.44000","5.37018","0.00283"
"10776","64.62000","5.38518","0.00271"
"10806","64.80000","5.40013","0.00227"
"10836","64.98000","5.41514","0.00283"
"10866","65.16000","5.43015","0.00268"
"10896","65.34000","5.44515","0.00305"
"10926","65.52000","5.46022","0.00248"
"10956","65.70000","5.47511","0.00260"
"10986","65.88000","5.49011","0.00245"
"11016","66.06000","5.50524","0.00293"
"11046","66.24000","5.52019","0.00242"
"11076","66.42000","5.53514","0.00289"
"11106","66.60000","5.55014","0.00266"
"11136","66.78000","5.56521","0.00279"
"11166","66.96000","5.58010","0.00245"
"11196","67.14000","5.59516","0.00217"
"11226","67.32000","5.61017","0.00280"
"11256","67.50000","5.62518","0.00328"
"11286","67.68000","5.64025","0.00268"
"11316","67.86000","5.65519","0.00282"
"11346","68.04000","5.67014","0.00306"
"11376","68.22000","5.68521","0.00287"
"11406","68.40000","5.70021","0.00246"
"11436","68.58000","5.71510","0.00281"
"11466","68.76000","5.73023","0.00305"
"11496","68.94000","5.74524","0.00252"
"11526","69.12000","5.76012","0.00280"
"11556","69.30000","5.77519","0.00286"
"11586","69.48000","5.79014","0.00269"
"11616","69.66000","5.80515","0.00236"
"11646","69.84000","5.82015","0.00370"
"11676","70.02000","5.83510","0.00320"
"11706","70.20000","5.85011","0.00318"
"11736","70.38000","5.86523","0.00318"
"11766","70.56000","5.88018","0.00256"
"11796","70.74000","5.89513","0.00263"
"11826","70.92000","5.91020","0.00310"
"11856","71.10000","5.92520","0.00273"
"11886","71.28000","5.94015","0.00302"
"11916","71.46000","5.95522","0.00295"
"11946","71.64000","5.97022","0.00250"
"11976","71.82000","5.98511","0.00284"
"12006","72.00000","6.00018","0.00306"
"12036","72.18000","6.01519","0.00300"
"12066","72.36000","6.03013","0.00320"
"12096","72.54000","6.04520","0.00274"
"12126","72.72000","6.06021","0.00326"
"12156","72.90000","6.07515","0.00258"
"12186","73.08000","6.09016","0.00287"
"12216","73.26000","6.10517","0.00294"
"12246","73.44000","6.12012","0.00259"
"12276","73.62000","6.13512","0.00332"
"12306","73.80000","6.15019","0.00308"
"12336","73.98000","6.16520","0.00305"
"12366","74.16000","6.18014","0.00305"
"12396","74.34000","6.19515","0.00314"
"12426","74.52000","6.21016","0.00264"
"12456","74.70000","6.22523","0.00332"
"12486","74.88000","6.24011","0.00290"
"12516","75.06000","6.25512","0.00306"
"12546","75.24000","6.27019","0.00284"
"12576","75.42000","6.28520","0.00343"
"12606","75.60000","6.30014","0.00306"
"12636","75.78000","6.31515","0.00290"
"12666","75.96000","6.33022","0.00323"
"12696","76.14000","6.34516","0.00274"
"12726","76.32000","6.36017","0.00316"
"12756","76.50000","6.37518","0.00250"
"12786","76.68000","6.39013","0.00335"
"12816","76.86000","6.40513","0.00351"
"12846","77.04000","6.42020","0.00320"
"12876","77.22000","6.43515","0.00340"
"12906","77.40000","6.45021","0.00326"
"12936","77.58000","6.46516","0.00353"
"12966","77.76000","6.48011","0.00364"
"12996","77.94000","6.49518","0.00367"
"13026","78.12000","6.51024","0.00354"
"13056","78.30000","6.52513","0.00300"
"13086","78.48000","6.54020","0.00334"
"13116","78.66000","6.55514","0.00303"
"13146","78.84000","6.57021","0.00314"
"13176","79.02000","6.58516","0.00318"
"13206","79.20000","6.60017","0.00364"
"13236","79.38000","6.61517","0.00391"
"13266","79.56000","6.63024","0.00372"
"13296","79.74000","6.64513","0.00350"
"13326","79.92000","6.66014","0.00321"
"13356","80.10000","6.67520","0.00314"
"13386","80.28000","6.69021","0.00368"
"13416","80.46000","6.70516","0.00355"
"13446","80.64000","6.72016","0.00322"
"13476","80.82000","6.73517","0.00302"
"13506","81.00000","6.75012","0.00343"
"13536","81.18000","6.76519","0.00316"
"13566","81.36000","6.78013","0.00323"
"13596","81.54000","6.79520","0.00343"
"13626","81.72000","6.81021","0.00329"
"13656","81.90000","6.82516","0.00365"
"13686","82.08000","6.84016","0.00320"
"13716","82.26000","6.85523","0.00255"
"13746","82.44000","6.87018","0.00367"
"13776","82.62000","6.88512","0.00305"
"13806","82.80000","6.90013","0.00296"
"13836","82.98000","6.91514","0.00346"
"13866","83.16000","6.93015","0.00394"
"13896","83.34000","6.94515","0.00359"
"13926","83.52000","6.96010","0.00404"
"13956","83.70000","6.97517","0.00407"
"13986","83.88000","6.99023","0.00350"
"14016","84.06000","7.00512","0.00377"
"14046","84.24000","7.02019","0.00433"
"14076","84.42000","7.03519","0.00372"
"14106","84.60000","7.05014","0.00440"
"14136","84.78000","7.06515","0.00430"
"14166","84.96000","7.08022","0.00427"
"14196","85.14000","7.09516","0.00372"
"14226","85.32000","7.11017","0.00446"
"14256","85.50000","7.12518","0.00319"
"14286","85.68000","7.14013","0.00393"
"14316","85.86000","7.15519","0.00367"
"14346","86.04000","7.17020","0.00336"
"14376","86.22000","7.18515","0.00393"
"14406","86.40000","7.20015","0.00424"
"14436","86.58000","7.21528","0.00456"
"14466","86.76000","7.23017","0.00332"
"14496","86.94000","7.24512","0.00412"
"14526","87.12000","7.26018","0.00409"
"14556","87.30000","7.27519","0.00391"
"14586","87.48000","7.29014","0.00398"
"14616","87.66000","7.30515","0.00415"
"14646","87.84000","7.32015","0.00354"
"14676","88.02000","7.33522","0.00406"
"14706","88.20000","7.35017","0.00377"
"14736","88.38000","7.36517","0.00452"
"14766","88.56000","7.38018","0.00358"
"14796","88.74000","7.39519","0.00375"
"14826","88.92000","7.41020","0.00394"
"14856","89.10000","7.42514","0.00350"
"14886","89.28000","7.44021","0.00394"
"14916","89.46000","7.45516","0.00422"
"14946","89.64000","7.47016","0.00377"
"14976","89.82000","7.48517","0.00374"
"15006","90.00000","7.50018","0.00423"
"15036","90.18000","7.51519","0.00359"
"15066","90.36000","7.53013","0.00379"
"15096","90.54000","7.54514","0.00406"
"15126","90.72000","7.56015","0.00386"
"15156","90.90000","7.57521","0.00385"
"15186","91.08000","7.59016","0.00368"
"15216","91.26000","7.60511","0.00381"
"15246","91.44000","7.62018","0.00405"
"15276","91.62000","7.63518","0.00399"
"15306","91.80000","7.65013","0.00427"
"15336","91.98000","7.66520","0.00418"
"15366","92.16000","7.68015","0.00478"
"15396","92.34000","7.69515","0.00367"
"15426","92.52000","7.71022","0.00394"
"15456","92.70000","7.72511","0.00418"
"15486","92.88000","7.74017","0.00408"
"15516","93.06000","7.75524","0.00399"
"15546","93.24000","7.77013","0.00414"
"15576","93.42000","7.78520","0.00358"
"15606","93.60000","7.80020","0.00411"
"15636","93.78000","7.81515","0.00369"
"15666","93.96000","7.83016","0.00355"
"15696","94.14000","7.84516","0.00393"
"15726","94.32000","7.86017","0.00414"
"15756","94.50000","7.87518","0.00389"
"15786","94.68000","7.89024","0.00391"
"15816","94.86000","7.90513","0.00401"
"15846","95.04000","7.92020","0.00428"
"15876","95.22000","7.93521","0.00427"
"15906","95.40000","7.95015","0.00401"
"15936","95.58000","7.96516","0.00430"
"15966","95.76000","7.98017","0.00404"
"15996","95.94000","7.99512","0.00360"
"16026","96.12000","8.01018","0.00380"
"16056","96.30000","8.02519","0.00366"
"16086","96.48000","8.04014","0.00413"
"16116","96.66000","8.05515","0.00426"
"16146","96.84000","8.07021","0.00408"
"16176","97.02000","8.08516","0.00463"
"16206","97.20000","8.10023","0.00420"
"16236","97.38000","8.11523","0.00464"
"16266","97.56000","8.13018","0.00482"
"16296","97.74000","8.14519","0.00371"
"16326","97.92000","8.16025","0.00365"
"16356","98.10000","8.17514","0.00429"
"16386","98.28000","8.19021","0.00467"
"16416","98.46000","8.20516","0.00455"
"16446","98.64000","8.22016","0.00411"
"16476","98.82000","8.23511","0.00450"
"16506","99.00000","8.25018","0.00345"
"16536","99.18000","8.26513","0.00399"
"16566","99.36000","8.28019","0.00479"
"16596","99.54000","8.29520","0.00368"
"16626","99.72000","8.31015","0.00357"
"16656","99.90000","8.32515","0.00381"
"16686","100.08000","8.34016","0.00359"
"16716","100.26000","8.35517","0.00391"
"16746","100.44000","8.37018","0.00403"
"16776","100.62000","8.38518","0.00429"
"16806","100.80000","8.40019","0.00457"
"16836","100.98000","8.41520","0.00424"
"16866","101.16000","8.43020","0.00434"
"16896","101.34000","8.44515","0.00402"
"16926","101.52000","8.46022","0.00407"
"16956","101.70000","8.47523","0.00380"
"16986","101.88000","8.49011","0.00465"
"17016","102.06000","8.50518","0.00405"
"17046","102.24000","8.52019","0.00409"
"17076","102.42000","8.53514","0.00467"
"17106","102.60000","8.55020","0.00454"
"17136","102.78000","8.56521","0.00419"
"17166","102.96000","8.58016","0.00473"
"17196","103.14000","8.59516","0.00437"
"17226","103.32000","8.61017","0.00379"
"17256","103.50000","8.62512","0.00421"
"17286","103.68000","8.64019","0.00414"
"17316","103.86000","8.65519","0.00430"
"17346","104.04000","8.67014","0.00435"
"17376","104.22000","8.68521","0.00456"
"17406","104.40000","8.70021","0.00471"
"17436","104.58000","8.71510","0.00433"
"17466","104.76000","8.73017","0.00504"
"17496","104.94000","8.74524","0.00436"
"17526","105.12000","8.76012","0.00486"
"17556","105.30000","8.77519","0.00518"
"17586","105.48000","8.79020","0.00412"
"17616","105.66000","8.80514","0.00503"
"17646","105.84000","8.82021","0.00473"
"17676","106.02000","8.83522","0.00474"
"17706","106.20000","8.85011","0.00547"
"17736","106.38000","8.86517","0.00439"
"17766","106.56000","8.88024","0.00478"
"17796","106.74000","8.89507","0.00463"
"17826","106.92000","8.91020","0.00499"
"17856","107.10000","8.92520","0.00500"
"17886","107.28000","8.94009","0.00479"
"17916","107.46000","8.95516","0.00488"
"17946","107.64000","8.97016","0.00449"
"17976","107.82000","8.98517","0.00444"
"18006","108.00000","9.00018","0.00466"
"18036","108.18000","9.01519","0.00483"
"18066","108.36000","9.03013","0.00497"
"18096","108.54000","9.04520","0.00441"
"18126","108.72000","9.06015","0.00516"
"18156","108.90000","9.07509","0.00503"
"18186","109.08000","9.09022","0.00448"
"18216","109.26000","9.10523","0.00500"
"18246","109.44000","9.12018","0.00466"
"18276","109.62000","9.13518","0.00433"
"18306","109.80000","9.15025","0.00551"
"18336","109.98000","9.16514","0.00515"
"18366","110.16000","9.18021","0.00534"
"18396","110.34000","9.19515","0.00500"
"18426","110.52000","9.21016","0.00440"
"18456","110.70000","9.22523","0.00485"
"18486","110.88000","9.24017","0.00338"
"18516","111.06000","9.25506","0.00383"
"18546","111.24000","9.27019","0.00385"
"18576","111.42000","9.28519","0.00387"
"18606","111.60000","9.30014","0.00379"
"18636","111.78000","9.31527","0.00412"
"18666","111.96000","9.33022","0.00443"
"18696","112.14000","9.34510","0.00424"
"18726","112.32000","9.36023","0.00425"
"18756","112.50000","9.37518","0.00465"
"18786","112.68000","9.39013","0.00420"
"18816","112.86000","9.40519","0.00435"
"18846","113.04000","9.42020","0.00443"
"18876","113.22000","9.43515","0.00398"
"18906","113.40000","9.45015","0.00442"
"18936","113.58000","9.46516","0.00479"
"18966","113.76000","9.48011","0.00354"
"18996","113.94000","9.49518","0.00264"
"19026","114.12000","9.51024","0.00336"
"19056","114.30000","9.52513","0.00306"
"19086","114.48000","9.54020","0.00335"
"19116","114.66000","9.55515","0.00348"
"19146","114.84000","9.57015","0.00352"
"19176","115.02000","9.58522","0.00395"
"19206","115.20000","9.60017","0.00346"
"19236","115.38000","9.61511","0.00361"
"19266","115.56000","9.63024","0.00335"
"19296","115.74000","9.64519","0.00294"
"19326","115.92000","9.66008","0.00316"
"19356","116.10000","9.67520","0.00340"
"19386","116.28000","9.69021","0.00340"
"19416","116.46000","9.70516","0.00381"
"19446","116.64000","9.72016","0.00341"
"19476","116.82000","9.73517","0.00373"
"19506","117.00000","9.75012","0.00410"
"19536","117.18000","9.76525","0.00362"
"19566","117.36000","9.78013","0.00350"
"19596","117.54000","9.79508","0.00336"
"19626","117.72000","9.81027","0.00339"
"19656","117.90000","9.82515","0.00402"
"19686","118.08000","9.84010","0.00403"
"19716","118.26000","9.85517","0.00424"
"19746","118.44000","9.87024","0.00415"
"19776","118.62000","9.88512","0.00393"
"19806","118.80000","9.90019","0.00385"
"19836","118.98000","9.91520","0.00450"
"19866","119.16000","9.93014","0.00413"
"19896","119.34000","9.94521","0.00484"
"19926","119.52000","9.96010","0.00388"
"19956","119.70000","9.97511","0.00410"
"19986","119.88000","9.99023","0.00366"
"20016","120.06000","10.00524","0.00397"
"20046","120.24000","10.02013","0.00414"
"20076","120.42000","10.03520","0.00370"
"20106","120.60000","10.05020","0.00449"
"20136","120.78000","10.06515","0.00363"
"20166","120.96000","10.08022","0.00436"
"20196","121.14000","10.09516","0.00442"
"20226","121.32000","10.11011","0.00395"
"20256","121.50000","10.12518","0.00434"
"20286","121.68000","10.14012","0.00409"
"20316","121.86000","10.15513","0.00414"
"20346","122.04000","10.17020","0.00414"
"20376","122.22000","10.18515","0.00384"
"20406","122.40000","10.20009","0.00413"
"20436","122.58000","10.21522","0.00423"
"20466","122.76000","10.23023","0.00406"
"20496","122.94000","10.24512","0.00399"
"20526","123.12000","10.26018","0.00425"
"20556","123.30000","10.27519","0.00457"
"20586","123.48000","10.29014","0.00427"
"20616","123.66000","10.30515","0.00466"
"20646","123.84000","10.32015","0.00390"
"20676","124.02000","10.33516","0.00442"
"20706","124.20000","10.35017","0.00415"
"20736","124.38000","10.36517","0.00412"
"20766","124.56000","10.38012","0.00461"
"20796","124.74000","10.39513","0.00430"
"20826","124.92000","10.41019","0.00416"
"20856","125.10000","10.42514","0.00451"
"20886","125.28000","10.44015","0.00431"
"20916","125.46000","10.45522","0.00414"
"20946","125.64000","10.47016","0.00461"
"20976","125.82000","10.48517","0.00498"
"21006","126.00000","10.50012","0.00419"
"21036","126.18000","10.51519","0.00416"
"21066","126.36000","10.53019","0.00465"
"21096","126.54000","10.54508","0.00442"
"21126","126.72000","10.56015","0.00473"
"21156","126.90000","10.57521","0.00487"
"21186","127.08000","10.59016","0.00440"
"21216","127.26000","10.60517","0.00422"
"21246","127.44000","10.62018","0.00377"
"21276","127.62000","10.63524","0.00416"
"21306","127.80000","10.65013","0.00479"
"21336","127.98000","10.66520","0.00434"
"21366","128.16000","10.68014","0.00430"
"21396","128.34000","10.69515","0.00463"
"21426","128.52000","10.71016","0.00405"
"21456","128.70000","10.72517","0.00395"
"21486","128.88000","10.74011","0.00453"
"21516","129.06000","10.75524","0.00413"
"21546","129.24000","10.77019","0.00418"
"21576","129.42000","10.78508","0.00435"
"21606","129.60000","10.80020","0.00497"
"21636","129.78000","10.81515","0.00449"
"21666","129.96000","10.83016","0.00444"
"21696","130.14000","10.84516","0.00476"
"21726","130.32000","10.86017","0.00422"
"21756","130.50000","10.87518","0.00444"
"21786","130.68000","10.89019","0.00450"
"21816","130.86000","10.90513","0.00501"
"21846","131.04000","10.92014","0.00489"
"21876","131.22000","10.93521","0.00455"
"21906","131.40000","10.95015","0.00450"
"21936","131.58000","10.96516","0.00461"
"21966","131.76000","10.98017","0.00461"
"21996","131.94000","10.99524","0.00493"
"22026","132.12000","11.01018","0.00430"
"22056","132.30000","11.02513","0.00483"
"22086","132.48000","11.04020","0.00518"
"22116","132.66000","11.05520","0.00489"
"22146","132.84000","11.07021","0.00461"
"22176","133.02000","11.08516","0.00504"
"22206","133.20000","11.10017","0.00520"
"22236","133.38000","11.11517","0.00445"
"22266","133.56000","11.13018","0.00445"
"22296","133.74000","11.14513","0.00510"
"22326","133.92000","11.16019","0.00502"
"22356","134.10000","11.17514","0.00472"
"22386","134.28000","11.19015","0.00488"
"22416","134.46000","11.20516","0.00508"
"22446","134.64000","11.22016","0.00492"
"22476","134.82000","11.23517","0.00453"
"22506","135.00000","11.25018","0.00490"
"22536","135.18000","11.26513","0.00490"
"22566","135.36000","11.28019","0.00466"
"22596","135.54000","11.29520","0.00527"
"22626","135.72000","11.31009","0.00522"
"22656","135.90000","11.32515","0.00525"
"22686","136.08000","11.34022","0.00487"
"22716","136.26000","11.35517","0.00501"
"22746","136.44000","11.37017","0.00503"
"22776","136.62000","11.38518","0.00452"
"22806","136.80000","11.40019","0.00510"
"22836","136.98000","11.41520","0.00527"
"22866","137.16000","11.43014","0.00536"
"22896","137.34000","11.44515","0.00565"
"22926","137.52000","11.46016","0.00526"
"22956","137.70000","11.47523","0.00477"
"22986","137.88000","11.49017","0.00533"
"23016","138.06000","11.50512","0.00569"
"23046","138.24000","11.52019","0.00532"
"23076","138.42000","11.53519","0.00542"
"23106","138.60000","11.55014","0.00471"
"23136","138.78000","11.56515","0.00485"
"23166","138.96000","11.58016","0.00515"
"23196","139.14000","11.59516","0.00494"
"23226","139.32000","11.61017","0.00526"
"23256","139.50000","11.62518","0.00505"
"23286","139.68000","11.64019","0.00475"
"23316","139.86000","11.65519","0.00512"
"23346","140.04000","11.67014","0.00575"
"23376","140.22000","11.68515","0.00487"
"23406","140.40000","11.70021","0.00508"
"23436","140.58000","11.71510","0.00523"
"23466","140.76000","11.73017","0.00548"
"23496","140.94000","11.74518","0.00518"
"23526","141.12000","11.76012","0.00558"
"23556","141.30000","11.77519","0.00519"
"23586","141.48000","11.79020","0.00578"
"23616","141.66000","11.80515","0.00575"
"23646","141.84000","11.82015","0.00523"
"23676","142.02000","11.83516","0.00602"
"23706","142.20000","11.85011","0.00534"
"23736","142.38000","11.86517","0.00479"
"23766","142.56000","11.88024","0.00561"
"23796","142.74000","11.89519","0.00542"
"23826","142.92000","11.91014","0.00531"
"23856","143.10000","11.92514","0.00578"
"23886","143.28000","11.94021","0.00596"
"23916","143.46000","11.95516","0.00589"
"23946","143.64000","11.97016","0.00574"
"23976","143.82000","11.98511","0.00578"
"24006","144.00000","12.00018","0.00618"
"24036","144.18000","12.01518","0.00566"
"24066","144.36000","12.03013","0.00593"
"24096","144.54000","12.04520","0.00593"
"24126","144.72000","12.06021","0.00649"
"24156","144.90000","12.07515","0.00616"
"24186","145.08000","12.09022","0.00608"
"24216","145.26000","12.10523","0.00655"
"24246","145.44000","12.12018","0.00624"
"24276","145.62000","12.13518","0.00592"
"24306","145.80000","12.15019","0.00562"
"24336","145.98000","12.16520","0.00572"
"24366","146.16000","12.18020","0.00578"
"24396","146.34000","12.19521","0.00552"
"24426","146.52000","12.21010","0.00489"
"24456","146.70000","12.22523","0.00783"
"24486","146.88000","12.24017","0.00497"
"24516","147.06000","12.25512","0.00498"
"24546","147.24000","12.27019","0.00473"
"24576","147.42000","12.28520","0.00488"
"24606","147.60000","12.30014","0.00596"
"24636","147.78000","12.31515","0.00596"
"24666","147.96000","12.33022","0.00611"
"24696","148.14000","12.34516","0.00546"
"24726","148.32000","12.36017","0.00616"
"24756","148.50000","12.37518","0.00624"
"24786","148.68000","12.39019","0.00592"
"24816","148.86000","12.40519","0.00663"
"24846","149.04000","12.42020","0.00640"
"24876","149.22000","12.43515","0.00585"
"24906","149.40000","12.45021","0.00611"
"24936","149.58000","12.46522","0.00643"
"24966","149.76000","12.48011","0.00682"
"24996","149.94000","12.49518","0.00676"
"25026","150.12000","12.51018","0.00643"
"25056","150.30000","12.52519","0.00636"
"25086","150.48000","12.54020","0.00600"
"25116","150.66000","12.55520","0.00669"
"25146","150.84000","12.57021","0.00652"
"25176","151.02000","12.58522","0.00644"
"25206","151.20000","12.60017","0.00595"
"25236","151.38000","12.61517","0.00692"
"25266","151.56000","12.63018","0.00631"
"25296","151.74000","12.64519","0.00661"
"25326","151.92000","12.66013","0.00689"
"25356","152.10000","12.67514","0.00677"
"25386","152.28000","12.69021","0.00675"
"25416","152.46000","12.70516","0.00655"
"25446","152.64000","12.72022","0.00680"
"25476","152.82000","12.73523","0.00697"
"25506","153.00000","12.75012","0.00639"
"25536","153.18000","12.76519","0.00751"
"25566","153.36000","12.78019","0.00705"
"25596","153.54000","12.79514","0.00655"
"25626","153.72000","12.81021","0.00650"
"25656","153.90000","12.82521","0.00632"
"25686","154.08000","12.84010","0.00570"
"25716","154.26000","12.85517","0.00697"
"25746","154.44000","12.87024","0.00603"
"25776","154.62000","12.88512","0.00656"
"25806","154.80000","12.90019","0.00732"
"25836","154.98000","12.91520","0.00662"
"25866","155.16000","12.93014","0.00687"
"25896","155.34000","12.94521","0.00748"
"25926","155.52000","12.96022","0.00726"
"25956","155.70000","12.97511","0.00546"
"25986","155.88000","12.99017","0.00473"
"26016","156.06000","13.00518","0.00511"
"26046","156.24000","13.02007","0.00529"
"26076","156.42000","13.03520","0.00521"
"26106","156.60000","13.05020","0.00475"
"26136","156.78000","13.06515","0.00461"
"26166","156.96000","13.08016","0.00519"
"26196","157.14000","13.09522","0.00549"
"26226","157.32000","13.11017","0.00534"
"26256","157.50000","13.12518","0.00598"
"26286","157.68000","13.14018","0.00559"
"26316","157.86000","13.15507","0.00623"
"26346","158.04000","13.17020","0.00567"
"26376","158.22000","13.18521","0.00543"
"26406","158.40000","13.20010","0.00556"
"26436","158.58000","13.21522","0.00572"
"26466","158.76000","13.23023","0.00548"
"26496","158.94000","13.24518","0.00615"
"26526","159.12000","13.26018","0.00575"
"26556","159.30000","13.27513","0.00635"
"26586","159.48000","13.29014","0.00558"
"26616","159.66000","13.30514","0.00591"
"26646","159.84000","13.32015","0.00598"
"26676","160.02000","13.33510","0.00590"
"26706","160.20000","13.35023","0.00633"
"26736","160.38000","13.36517","0.00586"
"26766","160.56000","13.38012","0.00597"
"26796","160.74000","13.39519","0.00659"
"26826","160.92000","13.41019","0.00639"
"26856","161.10000","13.42514","0.00613"
"26886","161.28000","13.44015","0.00626"
"26916","161.46000","13.45516","0.00251"
"26946","161.64000","13.47016","0.00186"
"26976","161.82000","13.48517","0.00337"
"27006","162.00000","13.50018","0.00216"
"27036","162.18000","13.51513","0.00168"
"27066","162.36000","13.53025","0.00299"
"27096","162.54000","13.54514","0.00408"
"27126","162.72000","13.56009","0.00227"
"27156","162.90000","13.57521","0.00282"
"27186","163.08000","13.59022","0.00342"
"27216","163.26000","13.60511","0.00306"
"27246","163.44000","13.62024","0.00354"
"27276","163.62000","13.63518","0.00217"
"27306","163.80000","13.65013","0.00282"
"27336","163.98000","13.66526","0.00297"
"27366","164.16000","13.68020","0.00297"
"27396","164.34000","13.69515","0.00289"
"27426","164.52000","13.71022","0.00402"
"27456","164.70000","13.72517","0.00307"
"27486","164.88000","13.74011","0.00271"
"27516","165.06000","13.75518","0.00258"
"27546","165.24000","13.77025","0.00414"
"27576","165.42000","13.78507","0.00423"
"27606","165.60000","13.80020","0.00276"
"27636","165.78000","13.81521","0.00308"
"27666","165.96000","13.83016","0.00324"
"27696","166.14000","13.84522","0.00289"
"27726","166.32000","13.86017","0.00351"
"27756","166.50000","13.87518","0.00443"
"27786","166.68000","13.89018","0.00298"
"27816","166.86000","13.90519","0.00274"
"27846","167.04000","13.92008","0.00337"
"27876","167.22000","13.93521","0.00462"
"27906","167.40000","13.95015","0.00323"
"27936","167.58000","13.96510","0.00323"
"27966","167.76000","13.98017","0.00388"
"27996","167.94000","13.99518","0.00418"
"28026","168.12000","14.01012","0.00362"
"28056","168.30000","14.02525","0.00345"
"28086","168.48000","14.04020","0.00353"
"28116","168.66000","14.05514","0.00387"
"28146","168.84000","14.07021","0.00413"
"28176","169.02000","14.08510","0.00435"
"28206","169.20000","14.10011","0.00357"
"28236","169.38000","14.11523","0.00412"
"28266","169.56000","14.13012","0.00455"
"28296","169.74000","14.14513","0.00422"
"28326","169.92000","14.16020","0.00374"
"28356","170.10000","14.17520","0.00386"
"28386","170.28000","14.19015","0.00432"
"28416","170.46000","14.20522","0.00418"
"28446","170.64000","14.22022","0.00479"
"28476","170.82000","14.23517","0.00476"
"28506","171.00000","14.25018","0.00461"
"28536","171.18000","14.26512","0.00406"
"28566","171.36000","14.28013","0.00463"
"28596","171.54000","14.29526","0.00452"
"28626","171.72000","14.31015","0.00457"
"28656","171.90000","14.32509","0.00461"
"28686","172.08000","14.34022","0.00293"
"28716","172.26000","14.35517","0.00383"
"28746","172.44000","14.37012","0.00368"
"28776","172.62000","14.38518","0.00350"
"28806","172.80000","14.40019","0.00438"
"28836","172.98000","14.41514","0.00332"
"28866","173.16000","14.43020","0.00341"
"28896","173.34000","14.44515","0.00327"
"28926","173.52000","14.46016","0.00375"
"28956","173.70000","14.47523","0.00304"
"28986","173.88000","14.49017","0.00345"
"29016","174.06000","14.50512","0.00398"
"29046","174.24000","14.52019","0.00419"
"29076","174.42000","14.53519","0.00355"
"29106","174.60000","14.55014","0.00353"
"29136","174.78000","14.56515","0.00433"
"29166","174.96000","14.58022","0.00413"
"29196","175.14000","14.59516","0.00397"
"29226","175.32000","14.61017","0.00420"
"29256","175.50000","14.62518","0.00372"
"29286","175.68000","14.64019","0.00412"
"29316","175.86000","14.65519","0.00399"
"29346","176.04000","14.67020","0.00450"
"29376","176.22000","14.68515","0.00437"
"29406","176.40000","14.70021","0.00453"
"29436","176.58000","14.71522","0.00378"
"29466","176.76000","14.73017","0.00362"
"29496","176.94000","14.74518","0.00294"
"29526","177.12000","14.76024","0.00297"
"29556","177.30000","14.77513","0.00316"
"29586","177.48000","14.79020","0.00333"
"29616","177.66000","14.80514","0.00342"
"29646","177.84000","14.82015","0.00370"
"29676","178.02000","14.83522","0.00314"
"29706","178.20000","14.85011","0.00351"
"29736","178.38000","14.86517","0.00359"
"29766","178.56000","14.88024","0.00378"
"29796","178.74000","14.89513","0.00368"
"29826","178.92000","14.91013","0.00295"
"29856","179.10000","14.92520","0.00429"
"29886","179.28000","14.94021","0.00371"
"29916","179.46000","14.95516","0.00386"
"29946","179.64000","14.97016","0.00351"
"29976","179.82000","14.98511","0.00322"
"30006","180.00000","15.00018","0.00410"
"30036","180.18000","15.01518","0.00341"
"30066","180.36000","15.03013","0.00409"
"30096","180.54000","15.04514","0.00370"
"30126","180.72000","15.06027","0.00382"
"30156","180.90000","15.07515","0.00416"
"30186","181.08000","15.09010","0.00391"
"30216","181.26000","15.10517","0.00401"
"30246","181.44000","15.12018","0.00414"
"30276","181.62000","15.13518","0.00375"
"30306","181.80000","15.15019","0.00393"
"30336","181.98000","15.16514","0.00379"
"30366","182.16000","15.18014","0.00392"
"30396","182.34000","15.19515","0.00355"
"30426","182.52000","15.21010","0.00409"
"30456","182.70000","15.22517","0.00410"
"30486","182.88000","15.24023","0.00415"
"30516","183.06000","15.25518","0.00440"
"30546","183.24000","15.27013","0.00377"
"30576","183.42000","15.28519","0.00357"
"30606","183.60000","15.30014","0.00367"
"30636","183.78000","15.31515","0.00422"
"30666","183.96000","15.33016","0.00400"
"30696","184.14000","15.34516","0.00415"
"30726","184.32000","15.36023","0.00380"
"30756","184.50000","15.37518","0.00385"
"30786","184.68000","15.39018","0.00343"
"30816","184.86000","15.40513","0.00443"
"30846","185.04000","15.42020","0.00376"
"30876","185.22000","15.43515","0.00375"
"30906","185.40000","15.45015","0.00391"
"30936","185.58000","15.46516","0.00434"
"30966","185.76000","15.48017","0.00407"
"30996","185.94000","15.49518","0.00404"
"31026","186.12000","15.51012","0.00385"
"31056","186.30000","15.52519","0.00367"
"31086","186.48000","15.54020","0.00374"
"31116","186.66000","15.55520","0.00383"
"31146","186.84000","15.57015","0.00367"
"31176","187.02000","15.58522","0.00349"
"31206","187.20000","15.60017","0.00390"
"31236","187.38000","15.61511","0.00406"
"31266","187.56000","15.63018","0.00327"
"31296","187.74000","15.64519","0.00356"
"31326","187.92000","15.66019","0.00348"
"31356","188.10000","15.67520","0.00368"
"31386","188.28000","15.69015","0.00364"
"31416","188.46000","15.70516","0.00397"
"31446","188.64000","15.72016","0.00360"
"31476","188.82000","15.73523","0.00345"
"31506","189.00000","15.75018","0.00396"
"31536","189.18000","15.76513","0.00360"
"31566","189.36000","15.78019","0.00416"
"31596","189.54000","15.79514","0.00386"
"31626","189.72000","15.81015","0.00379"
"31656","189.90000","15.82521","0.00404"
"31686","190.08000","15.84016","0.00386"
"31716","190.26000","15.85511","0.00387"
"31746","190.44000","15.87017","0.00420"
"31776","190.62000","15.88512","0.00402"
"31806","190.80000","15.90013","0.00356"
"31836","190.98000","15.91520","0.00410"
"31866","191.16000","15.93014","0.00356"
"31896","191.34000","15.94521","0.00365"
"31926","191.52000","15.96022","0.00421"
"31956","191.70000","15.97510","0.00415"
"31986","191.88000","15.99017","0.00390"
"32016","192.06000","16.00524","0.00391"
"32046","192.24000","16.02013","0.00389"
"32076","192.42000","16.03513","0.00423"
"32106","192.60000","16.05014","0.00402"
"32136","192.78000","16.06515","0.00463"
"32166","192.96000","16.08016","0.00389"
"32196","193.14000","16.09516","0.00446"
"32226","193.32000","16.11017","0.00407"
"32256","193.50000","16.12518","0.00405"
"32286","193.68000","16.14018","0.00460"
"32316","193.86000","16.15513","0.00386"
"32346","194.04000","16.17020","0.00427"
"32376","194.22000","16.18521","0.00369"
"32406","194.40000","16.20015","0.00407"
"32436","194.58000","16.21510","0.00427"
"32466","194.76000","16.23017","0.00441"
"32496","194.94000","16.24517","0.00407"
"32526","195.12000","16.26018","0.00399"
"32556","195.30000","16.27513","0.00442"
"32586","195.48000","16.29014","0.00490"
"32616","195.66000","16.30520","0.00424"
"32646","195.84000","16.32015","0.00432"
"32676","196.02000","16.33510","0.00346"
"32706","196.20000","16.35023","0.00383"
"32736","196.38000","16.36523","0.00360"
"32766","196.56000","16.38018","0.00362"
"32796","196.74000","16.39519","0.00414"
"32826","196.92000","16.41019","0.00358"
"32856","197.10000","16.42514","0.00356"
"32886","197.28000","16.44021","0.00428"
"32916","197.46000","16.45521","0.00406"
"32946","197.64000","16.47016","0.00348"
"32976","197.82000","16.48523","0.00399"
"33006","198.00000","16.50018","0.00368"
"33036","198.18000","16.51513","0.00380"
"33066","198.36000","16.53019","0.00413"
"33096","198.54000","16.54520","0.00287"
"33126","198.72000","16.56015","0.00396"
"33156","198.90000","16.57515","0.00402"
"33186","199.08000","16.59022","0.00375"
"33216","199.26000","16.60511","0.00389"
"33246","199.44000","16.62017","0.00389"
"33276","199.62000","16.63518","0.00390"
"33306","199.80000","16.65019","0.00381"
"33336","199.98000","16.66514","0.00419"
"33366","200.16000","16.68020","0.00389"
"33396","200.34000","16.69515","0.00384"
"33426","200.52000","16.71016","0.00364"
"33456","200.70000","16.72517","0.00348"
"33486","200.88000","16.74011","0.00363"
"33516","201.06000","16.75518","0.00393"
"33546","201.24000","16.77019","0.00402"
"33576","201.42000","16.78513","0.00404"
"33606","201.60000","16.80020","0.00408"
"33636","201.78000","16.81521","0.00424"
"33666","201.96000","16.83016","0.00343"
"33696","202.14000","16.84516","0.00401"
"33726","202.32000","16.86023","0.00348"
"33756","202.50000","16.87518","0.00379"
"33786","202.68000","16.89018","0.00394"
"33816","202.86000","16.90525","0.00382"
"33846","203.04000","16.92008","0.00408"
"33876","203.22000","16.93521","0.00393"
"33906","203.40000","16.95021","0.00381"
"33936","203.58000","16.96510","0.00372"
"33966","203.76000","16.98017","0.00438"
"33996","203.94000","16.99517","0.00450"
"34026","204.12000","17.01018","0.00391"
"34056","204.30000","17.02513","0.00375"
"34086","204.48000","17.04020","0.00390"
"34116","204.66000","17.05514","0.00355"
"34146","204.84000","17.07021","0.00373"
"34176","205.02000","17.08522","0.00393"
"34206","205.20000","17.10011","0.00412"
"34236","205.38000","17.11523","0.00449"
"34266","205.56000","17.13018","0.00410"
"34296","205.74000","17.14513","0.00431"
"34326","205.92000","17.16019","0.00420"
"34356","206.10000","17.17520","0.00360"
"34386","206.28000","17.19015","0.00360"
"34416","206.46000","17.20522","0.00406"
"34446","206.64000","17.22022","0.00397"
"34476","206.82000","17.23517","0.00385"
"34506","207.00000","17.25024","0.00379"
"34536","207.18000","17.26518","0.00447"
"34566","207.36000","17.28013","0.00391"
"34596","207.54000","17.29520","0.00393"
"34626","207.72000","17.31021","0.00396"
"34656","207.90000","17.32509","0.00366"
"34686","208.08000","17.34016","0.00382"
"34716","208.26000","17.35523","0.00436"
"34746","208.44000","17.37011","0.00404"
"34776","208.62000","17.38518","0.00425"
"34806","208.80000","17.40019","0.00448"
"34836","208.98000","17.41520","0.00425"
"34866","209.16000","17.43020","0.00473"
"34896","209.34000","17.44521","0.00391"
"34926","209.52000","17.46010","0.00461"
"34956","209.70000","17.47517","0.00414"
"34986","209.88000","17.49023","0.00399"
"35016","210.06000","17.50512","0.00451"
"35046","210.24000","17.52019","0.00430"
"35076","210.42000","17.53519","0.00474"
"35106","210.60000","17.55014","0.00382"
"35136","210.78000","17.56515","0.00412"
"35166","210.96000","17.58015","0.00420"
"35196","211.14000","17.59516","0.00395"
"35226","211.32000","17.61023","0.00498"
"35256","211.50000","17.62518","0.00397"
"35286","211.68000","17.64013","0.00412"
"35316","211.86000","17.65525","0.00491"
"35346","212.04000","17.67020","0.00468"
"35376","212.22000","17.68514","0.00473"
"35406","212.40000","17.70021","0.00432"
"35436","212.58000","17.71516","0.00384"
"35466","212.76000","17.73017","0.00482"
"35496","212.94000","17.74517","0.00482"
"35526","213.12000","17.76018","0.00411"
"35556","213.30000","17.77513","0.00456"
"35586","213.48000","17.79020","0.00450"
"35616","213.66000","17.80520","0.00445"
"35646","213.84000","17.82009","0.00444"
"35676","214.02000","17.83522","0.00516"
"35706","214.20000","17.85016","0.00495"
"35736","214.38000","17.86511","0.00418"
"35766","214.56000","17.88024","0.00459"
"35796","214.74000","17.89519","0.00477"
"35826","214.92000","17.91007","0.00419"
"35856","215.10000","17.92520","0.00492"
"35886","215.28000","17.94021","0.00428"
"35916","215.46000","17.95516","0.00467"
"35946","215.64000","17.97022","0.00431"
"35976","215.82000","17.98517","0.00459"
"36006","216.00000","18.00012","0.00459"
"36036","216.18000","18.01518","0.00469"
"36066","216.36000","18.03019","0.00486"
"36096","216.54000","18.04514","0.00460"
"36126","216.72000","18.06021","0.00459"
"36156","216.90000","18.07521","0.00460"
"36186","217.08000","18.09010","0.00445"
"36216","217.26000","18.10517","0.00441"
"36246","217.44000","18.12024","0.00494"
"36276","217.62000","18.13512","0.00445"
"36306","217.80000","18.15019","0.00466"
"36336","217.98000","18.16520","0.00486"
"36366","218.16000","18.18014","0.00516"
"36396","218.34000","18.19515","0.00464"
"36426","218.52000","18.21016","0.00490"
"36456","218.70000","18.22511","0.00513"
"36486","218.88000","18.24023","0.00469"
"36516","219.06000","18.25518","0.00470"
"36546","219.24000","18.27013","0.00502"
"36576","219.42000","18.28519","0.00481"
"36606","219.60000","18.30020","0.00475"
"36636","219.78000","18.31515","0.00563"
"36666","219.96000","18.33015","0.00483"
"36696","220.14000","18.34516","0.00497"
"36726","220.32000","18.36017","0.00375"
"36756","220.50000","18.37524","0.00212"
"36786","220.68000","18.39013","0.00119"
"36816","220.86000","18.40507","0.00217"
"36846","221.04000","18.42026","0.00230"
"36876","221.22000","18.43515","0.00204"
"36906","221.40000","18.45015","0.00177"
"36936","221.58000","18.46516","0.00128"
"36966","221.76000","18.48017","0.00178"
"36996","221.94000","18.49512","0.00176"
"37026","222.12000","18.51018","0.00157"
"37056","222.30000","18.52519","0.00164"
"37086","222.48000","18.54014","0.00217"
"37116","222.66000","18.55520","0.00195"
"37146","222.84000","18.57015","0.00126"
"37176","223.02000","18.58510","0.00173"
"37206","223.20000","18.60023","0.00208"
"37236","223.38000","18.61517","0.00158"
"37266","223.56000","18.63006","0.00164"
"37296","223.74000","18.64525","0.00147"
"37326","223.92000","18.66019","0.00212"
"37356","224.10000","18.67514","0.00182"
"37386","224.28000","18.69021","0.00145"
"37416","224.46000","18.70522","0.00204"
"37446","224.64000","18.72022","0.00174"
"37476","224.82000","18.73523","0.00186"
"37506","225.00000","18.75018","0.00158"
"37536","225.18000","18.76512","0.00125"
"37566","225.36000","18.78019","0.00159"
"37596","225.54000","18.79520","0.00147"
"37626","225.72000","18.81015","0.00162"
"37656","225.90000","18.82521","0.00204"
"37669","225.97600","18.83155","0.00192"