File: Trajectories_together/170225_2Specimen_RawData_1.csv
"","V1","V2","V3"
"1","End date","2/25/2017",""
"2","Specimen label","1BG_5.2",""
"3","Maximum Load","0.02768","N"
"4","Time","Extension","Load"
"5","(s)","(mm)","(N)"
"6","0.00000","0.00000","-0.00047"
"32","0.15600","0.00873","0.00026"
"58","0.31200","0.02541","0.00053"
"84","0.46800","0.03928","0.00076"
"110","0.62400","0.05214","0.00055"
"136","0.78000","0.06511","0.00084"
"162","0.93600","0.07814","0.00049"
"188","1.09200","0.09118","0.00052"
"214","1.24800","0.10415","0.00040"
"240","1.40400","0.11719","0.00090"
"266","1.56000","0.13022","0.00023"
"292","1.71600","0.14314","0.00050"
"318","1.87200","0.15611","0.00000"
"344","2.02800","0.16914","0.00091"
"370","2.18400","0.18212","0.00095"
"396","2.34000","0.19509","0.00036"
"422","2.49600","0.20813","0.00083"
"448","2.65200","0.22116","0.00043"
"474","2.80800","0.23414","0.00084"
"500","2.96400","0.24717","0.00068"
"526","3.12000","0.26020","0.00077"
"552","3.27600","0.27318","0.00121"
"578","3.43200","0.28609","0.00085"
"604","3.58800","0.29919","0.00099"
"630","3.74400","0.31216","0.00122"
"656","3.90000","0.32514","0.00051"
"682","4.05600","0.33817","0.00056"
"708","4.21200","0.35114","0.00115"
"734","4.36800","0.36412","0.00088"
"760","4.52400","0.37709","0.00105"
"786","4.68000","0.39019","0.00083"
"812","4.83600","0.40316","0.00079"
"838","4.99200","0.41614","0.00096"
"864","5.14800","0.42917","0.00037"
"890","5.30400","0.44220","0.00049"
"916","5.46000","0.45512","0.00123"
"942","5.61600","0.46815","0.00028"
"968","5.77200","0.48113","0.00156"
"994","5.92800","0.49416","0.00080"
"1020","6.08400","0.50708","0.00118"
"1046","6.24000","0.52011","0.00161"
"1072","6.39600","0.53314","0.00162"
"1098","6.55200","0.54612","0.00095"
"1124","6.70800","0.55915","0.00126"
"1150","6.86400","0.57219","0.00097"
"1176","7.02000","0.58516","0.00146"
"1202","7.17600","0.59807","0.00100"
"1228","7.33200","0.61117","0.00057"
"1254","7.48800","0.62414","0.00171"
"1280","7.64400","0.63712","0.00081"
"1306","7.80000","0.65015","0.00112"
"1332","7.95600","0.66313","0.00126"
"1358","8.11200","0.67610","0.00089"
"1384","8.26800","0.68907","0.00127"
"1410","8.42400","0.70217","0.00104"
"1436","8.58000","0.71514","0.00142"
"1462","8.73600","0.72812","0.00164"
"1488","8.89200","0.74115","0.00130"
"1514","9.04800","0.75419","0.00072"
"1540","9.20400","0.76716","0.00116"
"1566","9.36000","0.78007","0.00129"
"1592","9.51600","0.79317","0.00107"
"1618","9.67200","0.80614","0.00075"
"1644","9.82800","0.81906","0.00136"
"1670","9.98400","0.83209","0.00116"
"1696","10.14000","0.84513","0.00070"
"1722","10.29600","0.85810","0.00126"
"1748","10.45200","0.87113","0.00122"
"1774","10.60800","0.88417","0.00168"
"1800","10.76400","0.89720","0.00092"
"1826","10.92000","0.91012","0.00181"
"1852","11.07600","0.92321","0.00154"
"1878","11.23200","0.93618","0.00125"
"1904","11.38800","0.94916","0.00072"
"1930","11.54400","0.96213","0.00070"
"1956","11.70000","0.97517","0.00176"
"1982","11.85600","0.98814","0.00098"
"2008","12.01200","1.00112","0.00152"
"2034","12.16800","1.01415","0.00165"
"2060","12.32400","1.02718","0.00117"
"2086","12.48000","1.04010","0.00124"
"2112","12.63600","1.05313","0.00157"
"2138","12.79200","1.06617","0.00163"
"2164","12.94800","1.07914","0.00112"
"2190","13.10400","1.09206","0.00201"
"2216","13.26000","1.10515","0.00104"
"2242","13.41600","1.11812","0.00125"
"2268","13.57200","1.13116","0.00161"
"2294","13.72800","1.14413","0.00141"
"2320","13.88400","1.15717","0.00101"
"2346","14.04000","1.17014","0.00180"
"2372","14.19600","1.18312","0.00170"
"2398","14.35200","1.19621","0.00126"
"2424","14.50800","1.20912","0.00155"
"2450","14.66400","1.22210","0.00180"
"2476","14.82000","1.23513","0.00088"
"2502","14.97600","1.24817","0.00144"
"2528","15.13200","1.26114","0.00123"
"2554","15.28800","1.27411","0.00124"
"2580","15.44400","1.28715","0.00152"
"2606","15.60000","1.30012","0.00154"
"2632","15.75600","1.31310","0.00125"
"2658","15.91200","1.32619","0.00192"
"2684","16.06800","1.33923","0.00149"
"2710","16.22400","1.35214","0.00145"
"2736","16.38000","1.36511","0.00126"
"2762","16.53600","1.37815","0.00142"
"2788","16.69200","1.39106","0.00134"
"2814","16.84800","1.40404","0.00165"
"2840","17.00400","1.41713","0.00197"
"2866","17.16000","1.43011","0.00138"
"2892","17.31600","1.44308","0.00136"
"2918","17.47200","1.45617","0.00133"
"2944","17.62800","1.46921","0.00201"
"2970","17.78400","1.48218","0.00121"
"2996","17.94000","1.49510","0.00138"
"3022","18.09600","1.50819","0.00219"
"3048","18.25200","1.52117","0.00147"
"3074","18.40800","1.53414","0.00156"
"3100","18.56400","1.54717","0.00149"
"3126","18.72000","1.56015","0.00182"
"3152","18.87600","1.57312","0.00157"
"3178","19.03200","1.58610","0.00192"
"3204","19.18800","1.59913","0.00158"
"3230","19.34400","1.61216","0.00203"
"3256","19.50000","1.62508","0.00197"
"3282","19.65600","1.63811","0.00172"
"3308","19.81200","1.65115","0.00176"
"3334","19.96800","1.66412","0.00125"
"3360","20.12400","1.67710","0.00174"
"3386","20.28000","1.69013","0.00135"
"3412","20.43600","1.70316","0.00205"
"3438","20.59200","1.71608","0.00112"
"3464","20.74800","1.72917","0.00180"
"3490","20.90400","1.74215","0.00153"
"3516","21.06000","1.75512","0.00186"
"3542","21.21600","1.76816","0.00184"
"3568","21.37200","1.78119","0.00184"
"3594","21.52800","1.79416","0.00176"
"3620","21.68400","1.80714","0.00175"
"3646","21.84000","1.82011","0.00211"
"3672","21.99600","1.83315","0.00141"
"3698","22.15200","1.84606","0.00105"
"3724","22.30800","1.85910","0.00090"
"3750","22.46400","1.87213","0.00181"
"3776","22.62000","1.88510","0.00126"
"3802","22.77600","1.89808","0.00220"
"3828","22.93200","1.91117","0.00128"
"3854","23.08800","1.92409","0.00181"
"3880","23.24400","1.93712","0.00141"
"3906","23.40000","1.95010","0.00203"
"3932","23.55600","1.96313","0.00175"
"3958","23.71200","1.97610","0.00176"
"3984","23.86800","1.98908","0.00155"
"4010","24.02400","2.00211","0.00193"
"4036","24.18000","2.01515","0.00211"
"4062","24.33600","2.02812","0.00126"
"4088","24.49200","2.04115","0.00166"
"4114","24.64800","2.05419","0.00214"
"4140","24.80400","2.06716","0.00203"
"4166","24.96000","2.08014","0.00207"
"4192","25.11600","2.09323","0.00178"
"4218","25.27200","2.10615","0.00183"
"4244","25.42800","2.11912","0.00190"
"4270","25.58400","2.13209","0.00199"
"4296","25.74000","2.14513","0.00252"
"4322","25.89600","2.15810","0.00218"
"4348","26.05200","2.17114","0.00182"
"4374","26.20800","2.18417","0.00204"
"4400","26.36400","2.19715","0.00211"
"4426","26.52000","2.21006","0.00213"
"4452","26.67600","2.22315","0.00238"
"4478","26.83200","2.23613","0.00210"
"4504","26.98800","2.24916","0.00193"
"4530","27.14400","2.26214","0.00243"
"4556","27.30000","2.27517","0.00184"
"4582","27.45600","2.28815","0.00231"
"4608","27.61200","2.30106","0.00185"
"4634","27.76800","2.31409","0.00185"
"4660","27.92400","2.32719","0.00225"
"4686","28.08000","2.34010","0.00171"
"4712","28.23600","2.35314","0.00239"
"4738","28.39200","2.36617","0.00244"
"4764","28.54800","2.37914","0.00187"
"4790","28.70400","2.39212","0.00206"
"4816","28.86000","2.40515","0.00175"
"4842","29.01600","2.41819","0.00217"
"4868","29.17200","2.43110","0.00228"
"4894","29.32800","2.44414","0.00208"
"4920","29.48400","2.45711","0.00155"
"4946","29.64000","2.47014","0.00243"
"4972","29.79600","2.48306","0.00201"
"4998","29.95200","2.49615","0.00275"
"5024","30.10800","2.50919","0.00266"
"5050","30.26400","2.52216","0.00142"
"5076","30.42000","2.53514","0.00238"
"5102","30.57600","2.54811","0.00238"
"5128","30.73200","2.56114","0.00214"
"5154","30.88800","2.57412","0.00230"
"5180","31.04400","2.58715","0.00260"
"5206","31.20000","2.60013","0.00256"
"5232","31.35600","2.61310","0.00246"
"5258","31.51200","2.62614","0.00255"
"5284","31.66800","2.63911","0.00226"
"5310","31.82400","2.65208","0.00253"
"5336","31.98000","2.66518","0.00231"
"5362","32.13600","2.67815","0.00269"
"5388","32.29200","2.69113","0.00219"
"5414","32.44800","2.70410","0.00205"
"5440","32.60400","2.71714","0.00164"
"5466","32.76000","2.73011","0.00188"
"5492","32.91600","2.74308","0.00188"
"5518","33.07200","2.75612","0.00237"
"5544","33.22800","2.76915","0.00238"
"5570","33.38400","2.78219","0.00262"
"5596","33.54000","2.79510","0.00278"
"5622","33.69600","2.80819","0.00269"
"5648","33.85200","2.82117","0.00217"
"5674","34.00800","2.83414","0.00231"
"5700","34.16400","2.84712","0.00172"
"5726","34.32000","2.86015","0.00234"
"5752","34.47600","2.87319","0.00228"
"5778","34.63200","2.88610","0.00250"
"5804","34.78800","2.89919","0.00209"
"5830","34.94400","2.91217","0.00265"
"5856","35.10000","2.92508","0.00263"
"5882","35.25600","2.93818","0.00231"
"5908","35.41200","2.95121","0.00285"
"5934","35.56800","2.96419","0.00195"
"5960","35.72400","2.97710","0.00210"
"5986","35.88000","2.99013","0.00296"
"6012","36.03600","3.00317","0.00282"
"6038","36.19200","3.01614","0.00299"
"6064","36.34800","3.02918","0.00299"
"6090","36.50400","3.04215","0.00318"
"6116","36.66000","3.05513","0.00319"
"6142","36.81600","3.06810","0.00258"
"6168","36.97200","3.08113","0.00231"
"6194","37.12800","3.09423","0.00306"
"6220","37.28400","3.10714","0.00231"
"6246","37.44000","3.12018","0.00301"
"6272","37.59600","3.13321","0.00332"
"6298","37.75200","3.14613","0.00328"
"6324","37.90800","3.15910","0.00223"
"6350","38.06400","3.17213","0.00219"
"6376","38.22000","3.18511","0.00242"
"6402","38.37600","3.19808","0.00292"
"6428","38.53200","3.21118","0.00337"
"6454","38.68800","3.22415","0.00344"
"6480","38.84400","3.23712","0.00274"
"6506","39.00000","3.25016","0.00295"
"6532","39.15600","3.26319","0.00295"
"6558","39.31200","3.27617","0.00328"
"6584","39.46800","3.28914","0.00295"
"6610","39.62400","3.30218","0.00318"
"6636","39.78000","3.31521","0.00316"
"6662","39.93600","3.32818","0.00270"
"6688","40.09200","3.34116","0.00323"
"6714","40.24800","3.35413","0.00234"
"6740","40.40400","3.36711","0.00358"
"6766","40.56000","3.38008","0.00328"
"6792","40.71600","3.39318","0.00334"
"6818","40.87200","3.40615","0.00345"
"6844","41.02800","3.41912","0.00287"
"6870","41.18400","3.43216","0.00323"
"6896","41.34000","3.44513","0.00263"
"6922","41.49600","3.45817","0.00324"
"6948","41.65200","3.47108","0.00344"
"6974","41.80800","3.48412","0.00289"
"7000","41.96400","3.49715","0.00319"
"7026","42.12000","3.51006","0.00316"
"7052","42.27600","3.52316","0.00332"
"7078","42.43200","3.53613","0.00328"
"7104","42.58800","3.54911","0.00347"
"7130","42.74400","3.56214","0.00364"
"7156","42.90000","3.57518","0.00360"
"7182","43.05600","3.58821","0.00371"
"7208","43.21200","3.60106","0.00392"
"7234","43.36800","3.61416","0.00314"
"7260","43.52400","3.62719","0.00361"
"7286","43.68000","3.64017","0.00344"
"7312","43.83600","3.65314","0.00353"
"7338","43.99200","3.66617","0.00364"
"7364","44.14800","3.67915","0.00382"
"7390","44.30400","3.69212","0.00404"
"7416","44.46000","3.70522","0.00348"
"7442","44.61600","3.71819","0.00413"
"7468","44.77200","3.73117","0.00385"
"7494","44.92800","3.74414","0.00355"
"7520","45.08400","3.75711","0.00415"
"7546","45.24000","3.77015","0.00327"
"7572","45.39600","3.78306","0.00390"
"7598","45.55200","3.79616","0.00321"
"7624","45.70800","3.80913","0.00371"
"7650","45.86400","3.82211","0.00358"
"7676","46.02000","3.83514","0.00346"
"7702","46.17600","3.84817","0.00369"
"7728","46.33200","3.86121","0.00394"
"7754","46.48800","3.87412","0.00352"
"7780","46.64400","3.88716","0.00389"
"7806","46.80000","3.90013","0.00442"
"7832","46.95600","3.91311","0.00340"
"7858","47.11200","3.92614","0.00384"
"7884","47.26800","3.93917","0.00416"
"7910","47.42400","3.95215","0.00459"
"7936","47.58000","3.96512","0.00442"
"7962","47.73600","3.97816","0.00485"
"7988","47.89200","3.99113","0.00477"
"8014","48.04800","4.00411","0.00391"
"8040","48.20400","4.01714","0.00388"
"8066","48.36000","4.03017","0.00412"
"8092","48.51600","4.04315","0.00478"
"8118","48.67200","4.05612","0.00405"
"8144","48.82800","4.06916","0.00409"
"8170","48.98400","4.08213","0.00430"
"8196","49.14000","4.09510","0.00438"
"8222","49.29600","4.10814","0.00425"
"8248","49.45200","4.12117","0.00377"
"8274","49.60800","4.13415","0.00422"
"8300","49.76400","4.14718","0.00460"
"8326","49.92000","4.16022","0.00452"
"8352","50.07600","4.17319","0.00411"
"8378","50.23200","4.18610","0.00482"
"8404","50.38800","4.19920","0.00492"
"8430","50.54400","4.21211","0.00525"
"8456","50.70000","4.22509","0.00442"
"8482","50.85600","4.23812","0.00472"
"8508","51.01200","4.25116","0.00427"
"8534","51.16800","4.26413","0.00378"
"8560","51.32400","4.27704","0.00442"
"8586","51.48000","4.29020","0.00404"
"8612","51.63600","4.30317","0.00422"
"8638","51.79200","4.31609","0.00439"
"8664","51.94800","4.32918","0.00482"
"8690","52.10400","4.34215","0.00449"
"8716","52.26000","4.35513","0.00489"
"8742","52.41600","4.36810","0.00466"
"8768","52.57200","4.38114","0.00500"
"8794","52.72800","4.39417","0.00439"
"8820","52.88400","4.40709","0.00376"
"8846","53.04000","4.42012","0.00467"
"8872","53.19600","4.43315","0.00408"
"8898","53.35200","4.44613","0.00450"
"8924","53.50800","4.45916","0.00490"
"8950","53.66400","4.47214","0.00458"
"8976","53.82000","4.48517","0.00434"
"9002","53.97600","4.49803","0.00487"
"9028","54.13200","4.51118","0.00517"
"9054","54.28800","4.52415","0.00497"
"9080","54.44400","4.53713","0.00522"
"9106","54.60000","4.55010","0.00460"
"9132","54.75600","4.56314","0.00474"
"9158","54.91200","4.57617","0.00484"
"9184","55.06800","4.58909","0.00532"
"9210","55.22400","4.60218","0.00444"
"9236","55.38000","4.61515","0.00545"
"9262","55.53600","4.62807","0.00518"
"9288","55.69200","4.64116","0.00528"
"9314","55.84800","4.65414","0.00508"
"9340","56.00400","4.66711","0.00578"
"9366","56.16000","4.68009","0.00482"
"9392","56.31600","4.69318","0.00486"
"9418","56.47200","4.70615","0.00504"
"9444","56.62800","4.71919","0.00543"
"9470","56.78400","4.73216","0.00542"
"9496","56.94000","4.74520","0.00492"
"9522","57.09600","4.75817","0.00468"
"9548","57.25200","4.77114","0.00505"
"9574","57.40800","4.78418","0.00542"
"9600","57.56400","4.79709","0.00509"
"9626","57.72000","4.81013","0.00572"
"9652","57.87600","4.82310","0.00492"
"9678","58.03200","4.83614","0.00475"
"9704","58.18800","4.84911","0.00580"
"9730","58.34400","4.86208","0.00513"
"9756","58.50000","4.87518","0.00547"
"9782","58.65600","4.88815","0.00550"
"9808","58.81200","4.90107","0.00546"
"9834","58.96800","4.91416","0.00584"
"9860","59.12400","4.92720","0.00505"
"9886","59.28000","4.94011","0.00547"
"9912","59.43600","4.95314","0.00594"
"9938","59.59200","4.96612","0.00561"
"9964","59.74800","4.97909","0.00582"
"9990","59.90400","4.99207","0.00572"
"10016","60.06000","5.00516","0.00592"
"10042","60.21600","5.01819","0.00621"
"10068","60.37200","5.03111","0.00588"
"10094","60.52800","5.04414","0.00576"
"10120","60.68400","5.05718","0.00570"
"10146","60.84000","5.07015","0.00576"
"10172","60.99600","5.08307","0.00614"
"10198","61.15200","5.09622","0.00585"
"10224","61.30800","5.10914","0.00588"
"10250","61.46400","5.12211","0.00579"
"10276","61.62000","5.13514","0.00562"
"10302","61.77600","5.14818","0.00597"
"10328","61.93200","5.16109","0.00588"
"10354","62.08800","5.17407","0.00584"
"10380","62.24400","5.18716","0.00570"
"10406","62.40000","5.20019","0.00575"
"10432","62.55600","5.21311","0.00584"
"10458","62.71200","5.22614","0.00609"
"10484","62.86800","5.23912","0.00566"
"10510","63.02400","5.25215","0.00628"
"10536","63.18000","5.26513","0.00552"
"10562","63.33600","5.27816","0.00622"
"10588","63.49200","5.29119","0.00630"
"10614","63.64800","5.30411","0.00612"
"10640","63.80400","5.31714","0.00562"
"10666","63.96000","5.33018","0.00615"
"10692","64.11600","5.34315","0.00616"
"10718","64.27200","5.35613","0.00572"
"10744","64.42800","5.36916","0.00637"
"10770","64.58400","5.38213","0.00559"
"10796","64.74000","5.39511","0.00668"
"10822","64.89600","5.40814","0.00601"
"10848","65.05200","5.42112","0.00628"
"10874","65.20800","5.43409","0.00630"
"10900","65.36400","5.44707","0.00548"
"10926","65.52000","5.46016","0.00585"
"10952","65.67600","5.47313","0.00585"
"10978","65.83200","5.48611","0.00573"
"11004","65.98800","5.49920","0.00626"
"11030","66.14400","5.51212","0.00591"
"11056","66.30000","5.52515","0.00544"
"11082","66.45600","5.53807","0.00587"
"11108","66.61200","5.55116","0.00589"
"11134","66.76800","5.56413","0.00614"
"11160","66.92400","5.57711","0.00642"
"11186","67.08000","5.59014","0.00599"
"11212","67.23600","5.60318","0.00552"
"11238","67.39200","5.61609","0.00619"
"11264","67.54800","5.62918","0.00557"
"11290","67.70400","5.64216","0.00569"
"11316","67.86000","5.65519","0.00643"
"11342","68.01600","5.66811","0.00610"
"11368","68.17200","5.68120","0.00601"
"11394","68.32800","5.69418","0.00639"
"11420","68.48400","5.70715","0.00602"
"11446","68.64000","5.72018","0.00636"
"11472","68.79600","5.73316","0.00640"
"11498","68.95200","5.74613","0.00616"
"11524","69.10800","5.75911","0.00639"
"11550","69.26400","5.77220","0.00579"
"11576","69.42000","5.78518","0.00649"
"11602","69.57600","5.79815","0.00618"
"11628","69.73200","5.81118","0.00603"
"11654","69.88800","5.82416","0.00643"
"11680","70.04400","5.83713","0.00606"
"11706","70.20000","5.85017","0.00644"
"11732","70.35600","5.86314","0.00601"
"11758","70.51200","5.87611","0.00648"
"11784","70.66800","5.88909","0.00628"
"11810","70.82400","5.90206","0.00574"
"11836","70.98000","5.91516","0.00609"
"11862","71.13600","5.92807","0.00588"
"11888","71.29200","5.94117","0.00599"
"11914","71.44800","5.95420","0.00641"
"11940","71.60400","5.96717","0.00632"
"11966","71.76000","5.98015","0.00706"
"11992","71.91600","5.99312","0.00646"
"12018","72.07200","6.00616","0.00620"
"12044","72.22800","6.01913","0.00610"
"12070","72.38400","6.03217","0.00649"
"12096","72.54000","6.04514","0.00680"
"12122","72.69600","6.05811","0.00635"
"12148","72.85200","6.07109","0.00507"
"12174","73.00800","6.08418","0.00558"
"12200","73.16400","6.09722","0.00597"
"12226","73.32000","6.11013","0.00607"
"12252","73.47600","6.12317","0.00596"
"12278","73.63200","6.13614","0.00586"
"12304","73.78800","6.14911","0.00562"
"12330","73.94400","6.16209","0.00589"
"12356","74.10000","6.17512","0.00562"
"12382","74.25600","6.18816","0.00588"
"12408","74.41200","6.20113","0.00576"
"12434","74.56800","6.21417","0.00560"
"12460","74.72400","6.22714","0.00536"
"12486","74.88000","6.24011","0.00531"
"12512","75.03600","6.25315","0.00506"
"12538","75.19200","6.26618","0.00474"
"12564","75.34800","6.27916","0.00518"
"12590","75.50400","6.29213","0.00524"
"12616","75.66000","6.30517","0.00449"
"12642","75.81600","6.31820","0.00449"
"12668","75.97200","6.33117","0.00480"
"12694","76.12800","6.34415","0.00488"
"12720","76.28400","6.35718","0.00526"
"12746","76.44000","6.37016","0.00465"
"12772","76.59600","6.38313","0.00529"
"12798","76.75200","6.39622","0.00488"
"12824","76.90800","6.40920","0.00485"
"12850","77.06400","6.42211","0.00524"
"12876","77.22000","6.43515","0.00499"
"12902","77.37600","6.44812","0.00495"
"12928","77.53200","6.46116","0.00445"
"12954","77.68800","6.47407","0.00462"
"12980","77.84400","6.48716","0.00457"
"13006","78.00000","6.50014","0.00506"
"13032","78.15600","6.51311","0.00492"
"13058","78.31200","6.52615","0.00495"
"13084","78.46800","6.53918","0.00442"
"13110","78.62400","6.55216","0.00485"
"13136","78.78000","6.56513","0.00479"
"13162","78.93600","6.57816","0.00541"
"13188","79.09200","6.59114","0.00580"
"13214","79.24800","6.60405","0.00500"
"13240","79.40400","6.61715","0.00541"
"13266","79.56000","6.63018","0.00515"
"13292","79.71600","6.64316","0.00529"
"13318","79.87200","6.65613","0.00570"
"13344","80.02800","6.66916","0.00547"
"13370","80.18400","6.68220","0.00580"
"13396","80.34000","6.69517","0.00497"
"13422","80.49600","6.70815","0.00549"
"13448","80.65200","6.72124","0.00531"
"13474","80.80800","6.73410","0.00530"
"13500","80.96400","6.74713","0.00509"
"13526","81.12000","6.76010","0.00524"
"13552","81.27600","6.77314","0.00552"
"13578","81.43200","6.78605","0.00529"
"13604","81.58800","6.79915","0.00581"
"13630","81.74400","6.81212","0.00537"
"13656","81.90000","6.82516","0.00563"
"13682","82.05600","6.83813","0.00542"
"13708","82.21200","6.85116","0.00544"
"13734","82.36800","6.86414","0.00559"
"13760","82.52400","6.87711","0.00556"
"13786","82.68000","6.89015","0.00545"
"13812","82.83600","6.90318","0.00537"
"13838","82.99200","6.91609","0.00530"
"13864","83.14800","6.92913","0.00454"
"13890","83.30400","6.94216","0.00400"
"13916","83.46000","6.95508","0.00488"
"13942","83.61600","6.96811","0.00469"
"13968","83.77200","6.98115","0.00476"
"13994","83.92800","6.99412","0.00455"
"14020","84.08400","7.00709","0.00501"
"14046","84.24000","7.02013","0.00414"
"14072","84.39600","7.03316","0.00487"
"14098","84.55200","7.04608","0.00477"
"14124","84.70800","7.05911","0.00463"
"14150","84.86400","7.07214","0.00488"
"14176","85.02000","7.08518","0.00528"
"14202","85.17600","7.09809","0.00510"
"14228","85.33200","7.11119","0.00479"
"14254","85.48800","7.12410","0.00512"
"14280","85.64400","7.13714","0.00512"
"14306","85.80000","7.15017","0.00488"
"14332","85.95600","7.16314","0.00535"
"14358","86.11200","7.17618","0.00527"
"14384","86.26800","7.18903","0.00500"
"14410","86.42400","7.20219","0.00461"
"14436","86.58000","7.21516","0.00487"
"14462","86.73600","7.22808","0.00482"
"14488","86.89200","7.24111","0.00540"
"14514","87.04800","7.25415","0.00514"
"14540","87.20400","7.26718","0.00527"
"14566","87.36000","7.28009","0.00505"
"14592","87.51600","7.29313","0.00540"
"14618","87.67200","7.30616","0.00489"
"14644","87.82800","7.31914","0.00618"
"14670","87.98400","7.33211","0.00544"
"14696","88.14000","7.34514","0.00572"
"14722","88.29600","7.35812","0.00564"
"14748","88.45200","7.37109","0.00554"
"14774","88.60800","7.38419","0.00527"
"14800","88.76400","7.39716","0.00555"
"14826","88.92000","7.41014","0.00565"
"14852","89.07600","7.42311","0.00559"
"14878","89.23200","7.43614","0.00552"
"14904","89.38800","7.44918","0.00520"
"14930","89.54400","7.46215","0.00495"
"14956","89.70000","7.47513","0.00517"
"14982","89.85600","7.48816","0.00578"
"15008","90.01200","7.50108","0.00620"
"15034","90.16800","7.51411","0.00554"
"15060","90.32400","7.52714","0.00550"
"15086","90.48000","7.54012","0.00558"
"15112","90.63600","7.55309","0.00562"
"15138","90.79200","7.56619","0.00564"
"15164","90.94800","7.57916","0.00563"
"15190","91.10400","7.59213","0.00583"
"15216","91.26000","7.60517","0.00539"
"15242","91.41600","7.61814","0.00599"
"15268","91.57200","7.63112","0.00572"
"15294","91.72800","7.64415","0.00562"
"15320","91.88400","7.65719","0.00524"
"15346","92.04000","7.67010","0.00580"
"15372","92.19600","7.68307","0.00568"
"15398","92.35200","7.69611","0.00587"
"15424","92.50800","7.70914","0.00592"
"15450","92.66400","7.72212","0.00619"
"15476","92.82000","7.73515","0.00563"
"15502","92.97600","7.74813","0.00587"
"15528","93.13200","7.76116","0.00591"
"15554","93.28800","7.77413","0.00663"
"15580","93.44400","7.78717","0.00552"
"15606","93.60000","7.80014","0.00588"
"15632","93.75600","7.81306","0.00642"
"15658","93.91200","7.82615","0.00588"
"15684","94.06800","7.83912","0.00607"
"15710","94.22400","7.85216","0.00661"
"15736","94.38000","7.86513","0.00630"
"15762","94.53600","7.87823","0.00667"
"15788","94.69200","7.89120","0.00590"
"15814","94.84800","7.90412","0.00624"
"15840","95.00400","7.91715","0.00633"
"15866","95.16000","7.93018","0.00599"
"15892","95.31600","7.94316","0.00666"
"15918","95.47200","7.95607","0.00621"
"15944","95.62800","7.96917","0.00638"
"15970","95.78400","7.98214","0.00646"
"15996","95.94000","7.99512","0.00663"
"16022","96.09600","8.00815","0.00662"
"16048","96.25200","8.02118","0.00615"
"16074","96.40800","8.03410","0.00595"
"16100","96.56400","8.04713","0.00602"
"16126","96.72000","8.06017","0.00666"
"16152","96.87600","8.07314","0.00629"
"16178","97.03200","8.08606","0.00661"
"16204","97.18800","8.09921","0.00649"
"16230","97.34400","8.11218","0.00643"
"16256","97.50000","8.12510","0.00636"
"16282","97.65600","8.13813","0.00647"
"16308","97.81200","8.15117","0.00669"
"16334","97.96800","8.16414","0.00708"
"16360","98.12400","8.17712","0.00695"
"16386","98.28000","8.19021","0.00631"
"16412","98.43600","8.20318","0.00617"
"16438","98.59200","8.21610","0.00595"
"16464","98.74800","8.22913","0.00677"
"16490","98.90400","8.24217","0.00636"
"16516","99.06000","8.25514","0.00619"
"16542","99.21600","8.26812","0.00650"
"16568","99.37200","8.28115","0.00667"
"16594","99.52800","8.29406","0.00635"
"16620","99.68400","8.30710","0.00694"
"16646","99.84000","8.32013","0.00702"
"16672","99.99600","8.33323","0.00718"
"16698","100.15200","8.34614","0.00667"
"16724","100.30800","8.35911","0.00669"
"16750","100.46400","8.37215","0.00694"
"16776","100.62000","8.38512","0.00693"
"16802","100.77600","8.39816","0.00685"
"16828","100.93200","8.41113","0.00653"
"16854","101.08800","8.42417","0.00693"
"16880","101.24400","8.43708","0.00638"
"16906","101.40000","8.45011","0.00672"
"16932","101.55600","8.46315","0.00700"
"16958","101.71200","8.47618","0.00678"
"16984","101.86800","8.48916","0.00705"
"17010","102.02400","8.50219","0.00682"
"17036","102.18000","8.51522","0.00772"
"17062","102.33600","8.52808","0.00762"
"17088","102.49200","8.54111","0.00689"
"17114","102.64800","8.55415","0.00706"
"17140","102.80400","8.56712","0.00702"
"17166","102.96000","8.58004","0.00692"
"17192","103.11600","8.59313","0.00757"
"17218","103.27200","8.60616","0.00717"
"17244","103.42800","8.61914","0.00702"
"17270","103.58400","8.63217","0.00722"
"17296","103.74000","8.64521","0.00716"
"17322","103.89600","8.65812","0.00706"
"17348","104.05200","8.67110","0.00768"
"17374","104.20800","8.68419","0.00713"
"17400","104.36400","8.69717","0.00653"
"17426","104.52000","8.71014","0.00607"
"17452","104.67600","8.72317","0.00634"
"17478","104.83200","8.73615","0.00593"
"17504","104.98800","8.74912","0.00659"
"17530","105.14400","8.76210","0.00683"
"17556","105.30000","8.77519","0.00674"
"17582","105.45600","8.78822","0.00635"
"17608","105.61200","8.80114","0.00662"
"17634","105.76800","8.81411","0.00656"
"17660","105.92400","8.82715","0.00651"
"17686","106.08000","8.84012","0.00673"
"17712","106.23600","8.85310","0.00660"
"17738","106.39200","8.86613","0.00690"
"17764","106.54800","8.87916","0.00645"
"17790","106.70400","8.89208","0.00693"
"17816","106.86000","8.90511","0.00717"
"17842","107.01600","8.91815","0.00633"
"17868","107.17200","8.93112","0.00640"
"17894","107.32800","8.94416","0.00745"
"17920","107.48400","8.95719","0.00632"
"17946","107.64000","8.97016","0.00710"
"17972","107.79600","8.98308","0.00748"
"17998","107.95200","8.99617","0.00750"
"18024","108.10800","9.00915","0.00787"
"18050","108.26400","9.02218","0.00731"
"18076","108.42000","9.03516","0.00602"
"18102","108.57600","9.04813","0.00715"
"18128","108.73200","9.06116","0.00693"
"18154","108.88800","9.07414","0.01021"
"18180","109.04400","9.08717","0.00842"
"18206","109.20000","9.10015","0.00286"
"18232","109.35600","9.11312","0.00421"
"18258","109.51200","9.12609","0.00474"
"18284","109.66800","9.13913","0.00609"
"18310","109.82400","9.15204","0.00460"
"18336","109.98000","9.16508","0.00411"
"18362","110.13600","9.17817","0.00432"
"18388","110.29200","9.19121","0.00375"
"18414","110.44800","9.20412","0.00441"
"18440","110.60400","9.21721","0.00484"
"18466","110.76000","9.23019","0.00515"
"18492","110.91600","9.24316","0.00466"
"18518","111.07200","9.25614","0.00340"
"18544","111.22800","9.26917","0.00473"
"18570","111.38400","9.28209","0.00446"
"18596","111.54000","9.29512","0.00479"
"18622","111.69600","9.30815","0.00595"
"18648","111.85200","9.32119","0.00430"
"18674","112.00800","9.33416","0.00350"
"18700","112.16400","9.34708","0.00347"
"18726","112.32000","9.36017","0.00534"
"18752","112.47600","9.37315","0.00480"
"18778","112.63200","9.38606","0.00534"
"18804","112.78800","9.39921","0.00522"
"18830","112.94400","9.41219","0.00491"
"18856","113.10000","9.42510","0.00400"
"18882","113.25600","9.43814","0.00462"
"18908","113.41200","9.45117","0.00531"
"18934","113.56800","9.46408","0.00449"
"18960","113.72400","9.47706","0.00501"
"18986","113.88000","9.49009","0.00663"
"19012","114.03600","9.50319","0.02590"
"19038","114.19200","9.51610","0.00572"
"19064","114.34800","9.52914","0.00472"
"19090","114.50400","9.54217","0.01610"
"19116","114.66000","9.55515","0.00643"
"19142","114.81600","9.56812","0.01442"
"19168","114.97200","9.58115","0.01101"
"19194","115.12800","9.59419","0.00294"
"19220","115.28400","9.60710","0.00192"
"19246","115.44000","9.62014","0.00310"
"19272","115.59600","9.63311","0.00336"
"19298","115.75200","9.64614","0.00764"
"19324","115.90800","9.65912","0.00167"
"19350","116.06400","9.67215","0.00089"
"19376","116.22000","9.68513","0.00348"
"19402","116.37600","9.69810","0.00281"
"19428","116.53200","9.71113","0.00303"
"19454","116.68800","9.72417","0.00566"
"19480","116.84400","9.73714","0.00435"
"19506","117.00000","9.75006","0.00209"
"19532","117.15600","9.76315","0.00242"
"19558","117.31200","9.77613","0.00267"
"19584","117.46800","9.78910","0.00298"
"19610","117.62400","9.80213","0.00472"
"19636","117.78000","9.81517","0.00547"
"19662","117.93600","9.82814","0.00366"
"19688","118.09200","9.84118","0.00286"
"19714","118.24800","9.85415","0.00272"
"19740","118.40400","9.86713","0.00259"
"19766","118.56000","9.88010","0.00463"
"19792","118.71600","9.89313","0.00531"
"19818","118.87200","9.90611","0.00540"
"19844","119.02800","9.91908","0.00344"
"19870","119.18400","9.93218","0.00265"
"19896","119.34000","9.94515","0.00266"
"19922","119.49600","9.95819","0.00371"
"19948","119.65200","9.97110","0.00439"
"19974","119.80800","9.98419","0.00462"
"20000","119.96400","9.99711","0.00457"
"20026","120.12000","10.01008","0.00407"
"20052","120.27600","10.02318","0.00380"
"20078","120.43200","10.03615","0.00403"
"20104","120.58800","10.04912","0.00475"
"20130","120.74400","10.06204","0.00497"
"20156","120.90000","10.07519","0.00494"
"20182","121.05600","10.08817","0.00499"
"20208","121.21200","10.10114","0.00348"
"20234","121.36800","10.11418","0.00407"
"20260","121.52400","10.12721","0.00402"
"20286","121.68000","10.14012","0.00571"
"20312","121.83600","10.15310","0.00648"
"20338","121.99200","10.16613","0.00385"
"20364","122.14800","10.17917","0.00413"
"20390","122.30400","10.19208","0.00585"
"20416","122.46000","10.20512","0.00614"
"20442","122.61600","10.21815","0.00513"
"20468","122.77200","10.23112","0.00963"
"20494","122.92800","10.24416","0.00661"
"20520","123.08400","10.25719","0.00721"
"20546","123.24000","10.27023","0.00504"
"20572","123.39600","10.28314","0.00419"
"20598","123.55200","10.29612","0.00472"
"20624","123.70800","10.30921","0.00477"
"20650","123.86400","10.32212","0.00474"
"20676","124.02000","10.33516","0.00432"
"20702","124.17600","10.34807","0.00442"
"20728","124.33200","10.36111","0.00485"
"20754","124.48800","10.37402","0.00503"
"20780","124.64400","10.38718","0.00537"
"20806","124.80000","10.40015","0.00514"
"20832","124.95600","10.41312","0.00558"
"20858","125.11200","10.42610","0.00532"
"20884","125.26800","10.43913","0.00598"
"20910","125.42400","10.45211","0.00540"
"20936","125.58000","10.46508","0.00601"
"20962","125.73600","10.47812","0.00553"
"20988","125.89200","10.49115","0.00542"
"21014","126.04800","10.50412","0.00586"
"21040","126.20400","10.51716","0.00624"
"21066","126.36000","10.53013","0.00592"
"21092","126.51600","10.54311","0.00616"
"21118","126.67200","10.55614","0.00639"
"21144","126.82800","10.56918","0.00624"
"21170","126.98400","10.58215","0.00602"
"21196","127.14000","10.59512","0.00635"
"21222","127.29600","10.60816","0.00635"
"21248","127.45200","10.62119","0.00640"
"21274","127.60800","10.63417","0.00735"
"21300","127.76400","10.64708","0.00677"
"21326","127.92000","10.66011","0.00670"
"21352","128.07600","10.67315","0.00697"
"21378","128.23200","10.68606","0.00734"
"21404","128.38800","10.69922","0.00636"
"21430","128.54400","10.71213","0.00668"
"21456","128.70000","10.72511","0.00712"
"21482","128.85600","10.73814","0.00736"
"21508","129.01200","10.75117","0.00513"
"21534","129.16800","10.76415","0.00576"
"21560","129.32400","10.77706","0.00685"
"21586","129.48000","10.79016","0.00668"
"21612","129.63600","10.80313","0.00735"
"21638","129.79200","10.81611","0.00654"
"21664","129.94800","10.82914","0.00610"
"21690","130.10400","10.84217","0.00634"
"21716","130.26000","10.85515","0.00671"
"21742","130.41600","10.86812","0.00663"
"21768","130.57200","10.88122","0.00746"
"21794","130.72800","10.89419","0.00678"
"21820","130.88400","10.90711","0.00687"
"21846","131.04000","10.92008","0.00649"
"21872","131.19600","10.93317","0.00754"
"21898","131.35200","10.94615","0.00707"
"21924","131.50800","10.95906","0.00690"
"21950","131.66400","10.97216","0.00757"
"21976","131.82000","10.98513","0.00673"
"22002","131.97600","10.99811","0.00726"
"22028","132.13200","11.01114","0.00742"
"22054","132.28800","11.02417","0.00781"
"22080","132.44400","11.03715","0.00770"
"22106","132.60000","11.05012","0.00797"
"22132","132.75600","11.06316","0.00790"
"22158","132.91200","11.07619","0.00781"
"22184","133.06800","11.08911","0.00748"
"22210","133.22400","11.10214","0.00765"
"22236","133.38000","11.11517","0.00803"
"22262","133.53600","11.12815","0.00803"
"22288","133.69200","11.14112","0.00807"
"22314","133.84800","11.15422","0.00745"
"22340","134.00400","11.16719","0.00850"
"22366","134.16000","11.18016","0.00824"
"22392","134.31600","11.19320","0.00820"
"22418","134.47200","11.20617","0.00815"
"22444","134.62800","11.21915","0.00895"
"22470","134.78400","11.23212","0.00885"
"22496","134.94000","11.24516","0.00847"
"22522","135.09600","11.25807","0.00824"
"22548","135.25200","11.27110","0.00890"
"22574","135.40800","11.28414","0.00828"
"22600","135.56400","11.29717","0.00849"
"22626","135.72000","11.31015","0.00965"
"22652","135.87600","11.32312","0.00931"
"22678","136.03200","11.33622","0.00870"
"22704","136.18800","11.34913","0.00820"
"22730","136.34400","11.36210","0.00865"
"22756","136.50000","11.37514","0.00885"
"22782","136.65600","11.38817","0.00852"
"22808","136.81200","11.40109","0.00871"
"22834","136.96800","11.41418","0.00857"
"22860","137.12400","11.42716","0.00885"
"22886","137.28000","11.44013","0.00923"
"22912","137.43600","11.45310","0.00901"
"22938","137.59200","11.46620","0.00900"
"22964","137.74800","11.47917","0.00923"
"22990","137.90400","11.49209","0.00958"
"23016","138.06000","11.50518","0.00965"
"23042","138.21600","11.51816","0.00973"
"23068","138.37200","11.53113","0.00895"
"23094","138.52800","11.54404","0.00956"
"23120","138.68400","11.55714","0.00964"
"23146","138.84000","11.57011","0.00986"
"23172","138.99600","11.58309","0.00999"
"23198","139.15200","11.59612","0.00968"
"23224","139.30800","11.60921","0.00975"
"23250","139.46400","11.62213","0.00985"
"23276","139.62000","11.63510","0.01008"
"23302","139.77600","11.64814","0.00989"
"23328","139.93200","11.66117","0.00976"
"23354","140.08800","11.67409","0.00979"
"23380","140.24400","11.68718","0.01044"
"23406","140.40000","11.70015","0.00997"
"23432","140.55600","11.71313","0.01073"
"23458","140.71200","11.72616","0.00637"
"23484","140.86800","11.73914","0.00680"
"23510","141.02400","11.75217","0.00793"
"23536","141.18000","11.76515","0.00774"
"23562","141.33600","11.77818","0.00764"
"23588","141.49200","11.79121","0.00676"
"23614","141.64800","11.80407","0.00828"
"23640","141.80400","11.81710","0.00825"
"23666","141.96000","11.83014","0.00907"
"23692","142.11600","11.84311","0.00884"
"23718","142.27200","11.85609","0.00878"
"23744","142.42800","11.86918","0.00927"
"23770","142.58400","11.88209","0.00959"
"23796","142.74000","11.89513","0.00889"
"23822","142.89600","11.90810","0.00946"
"23848","143.05200","11.92114","0.00915"
"23874","143.20800","11.93411","0.01096"
"23900","143.36400","11.94709","0.00884"
"23926","143.52000","11.96018","0.01055"
"23952","143.67600","11.97309","0.00592"
"23978","143.83200","11.98607","0.00709"
"24004","143.98800","11.99916","0.00748"
"24030","144.14400","12.01219","0.00853"
"24056","144.30000","12.02511","0.00808"
"24082","144.45600","12.03814","0.00736"
"24108","144.61200","12.05118","0.00830"
"24134","144.76800","12.06415","0.00886"
"24160","144.92400","12.07713","0.00924"
"24186","145.08000","12.09016","0.01051"
"24212","145.23600","12.10319","0.00941"
"24238","145.39200","12.11611","0.00887"
"24264","145.54800","12.12914","0.00834"
"24290","145.70400","12.14212","0.01191"
"24316","145.86000","12.15509","0.00775"
"24342","146.01600","12.16807","0.00947"
"24368","146.17200","12.18122","0.01067"
"24394","146.32800","12.19420","0.00739"
"24420","146.48400","12.20717","0.00571"
"24446","146.64000","12.22014","0.00668"
"24472","146.79600","12.23318","0.00210"
"24498","146.95200","12.24615","0.00290"
"24524","147.10800","12.25907","0.00327"
"24550","147.26400","12.27216","0.00213"
"24576","147.42000","12.28513","0.00276"
"24602","147.57600","12.29811","0.00307"
"24628","147.73200","12.31114","0.00295"
"24654","147.88800","12.32412","0.00216"
"24680","148.04400","12.33709","0.00280"
"24706","148.20000","12.35013","0.00232"
"24732","148.35600","12.36316","0.00229"
"24758","148.51200","12.37613","0.00127"
"24784","148.66800","12.38911","0.00195"
"24810","148.82400","12.40214","0.00261"
"24836","148.98000","12.41518","0.00190"
"24862","149.13600","12.42809","0.00186"
"24888","149.29200","12.44106","0.00155"
"24914","149.44800","12.45416","0.00261"
"24940","149.60400","12.46713","0.00204"
"24966","149.76000","12.48005","0.00218"
"24992","149.91600","12.49314","0.00266"
"25018","150.07200","12.50618","0.00272"
"25044","150.22800","12.51915","0.00232"
"25070","150.38400","12.53213","0.00199"
"25096","150.54000","12.54516","0.00227"
"25122","150.69600","12.55813","0.00265"
"25148","150.85200","12.57111","0.00250"
"25174","151.00800","12.58414","0.00270"
"25200","151.16400","12.59712","0.00235"
"25226","151.32000","12.61009","0.00242"
"25252","151.47600","12.62313","0.00192"
"25278","151.63200","12.63616","0.00248"
"25304","151.78800","12.64919","0.00257"
"25330","151.94400","12.66211","0.00267"
"25356","152.10000","12.67520","0.00324"
"25382","152.25600","12.68812","0.00292"
"25408","152.41200","12.70109","0.00284"
"25434","152.56800","12.71413","0.00191"
"25460","152.72400","12.72710","0.00208"
"25486","152.88000","12.74007","0.00267"
"25512","153.03600","12.75311","0.00221"
"25538","153.19200","12.76614","0.00221"
"25564","153.34800","12.77918","0.00253"
"25590","153.50400","12.79209","0.00214"
"25616","153.66000","12.80512","0.00206"
"25642","153.81600","12.81816","0.00226"
"25668","153.97200","12.83113","0.00268"
"25694","154.12800","12.84417","0.00239"
"25720","154.28400","12.85714","0.00235"
"25746","154.44000","12.87012","0.00208"
"25772","154.59600","12.88309","0.00164"
"25798","154.75200","12.89612","0.00187"
"25824","154.90800","12.90916","0.00240"
"25850","155.06400","12.92213","0.00271"
"25876","155.22000","12.93511","0.00359"
"25902","155.37600","12.94820","0.00213"
"25928","155.53200","12.96117","0.00272"
"25954","155.68800","12.97409","0.00298"
"25980","155.84400","12.98718","0.00177"
"26006","156.00000","13.00016","0.00170"
"26032","156.15600","13.01313","0.00133"
"26058","156.31200","13.02617","0.00105"
"26084","156.46800","13.03914","0.00166"
"26110","156.62400","13.05211","0.00108"
"26136","156.78000","13.06509","0.00204"
"26162","156.93600","13.07812","0.00173"
"26188","157.09200","13.09122","0.00142"
"26214","157.24800","13.10407","0.00104"
"26240","157.40400","13.11717","0.00171"
"26266","157.56000","13.13014","0.00162"
"26292","157.71600","13.14311","0.00256"
"26318","157.87200","13.15609","0.00255"
"26344","158.02800","13.16912","0.00183"
"26370","158.18400","13.18216","0.00135"
"26396","158.34000","13.19507","0.00206"
"26422","158.49600","13.20817","0.00168"
"26448","158.65200","13.22114","0.00175"
"26474","158.80800","13.23411","0.00193"
"26500","158.96400","13.24715","0.00195"
"26526","159.12000","13.26018","0.00242"
"26552","159.27600","13.27322","0.00252"
"26578","159.43200","13.28613","0.00249"
"26604","159.58800","13.29917","0.00240"
"26630","159.74400","13.31214","0.00317"
"26656","159.90000","13.32517","0.00308"
"26682","160.05600","13.33815","0.00203"
"26708","160.21200","13.35112","0.00141"
"26734","160.36800","13.36416","0.00227"
"26760","160.52400","13.37707","0.00237"
"26786","160.68000","13.39016","0.00140"
"26812","160.83600","13.40314","0.00087"
"26838","160.99200","13.41611","0.00146"
"26864","161.14800","13.42915","0.00120"
"26890","161.30400","13.44212","0.00194"
"26916","161.46000","13.45516","0.00149"
"26942","161.61600","13.46813","0.00129"
"26968","161.77200","13.48116","0.00140"
"26994","161.92800","13.49414","0.00167"
"27020","162.08400","13.50705","0.00149"
"27046","162.24000","13.52015","0.00186"
"27072","162.39600","13.53318","0.00324"
"27098","162.55200","13.54616","0.00270"
"27124","162.70800","13.55913","0.00258"
"27150","162.86400","13.57222","0.00317"
"27176","163.02000","13.58514","0.00344"
"27202","163.17600","13.59805","0.00366"
"27228","163.33200","13.61115","0.00165"
"27254","163.48800","13.62412","0.00363"
"27280","163.64400","13.63716","0.00225"
"27306","163.80000","13.65013","0.00152"
"27332","163.95600","13.66316","0.00190"
"27358","164.11200","13.67614","0.00175"
"27384","164.26800","13.68911","0.00263"
"27410","164.42400","13.70221","0.00266"
"27436","164.58000","13.71518","0.00314"
"27462","164.73600","13.72816","0.00208"
"27488","164.89200","13.74113","0.00330"
"27514","165.04800","13.75416","0.00435"
"27540","165.20400","13.76714","0.00247"
"27566","165.36000","13.78011","0.00174"
"27592","165.51600","13.79315","0.00160"
"27618","165.67200","13.80618","0.00081"
"27644","165.82800","13.81909","0.00015"
"27670","165.98400","13.83213","-0.00007"
"27696","166.14000","13.84516","-0.00019"
"27722","166.29600","13.85820","0.00091"
"27748","166.45200","13.87111","0.00093"
"27774","166.60800","13.88415","0.00042"
"27800","166.76400","13.89718","0.00119"
"27826","166.92000","13.91009","0.00193"
"27852","167.07600","13.92313","0.00082"
"27878","167.23200","13.93610","0.00165"
"27904","167.38800","13.94914","0.00193"
"27930","167.54400","13.96205","0.00085"
"27956","167.70000","13.97515","-0.00013"
"27982","167.85600","13.98818","0.00089"
"28008","168.01200","14.00115","0.00101"
"28034","168.16800","14.01413","0.00026"
"28060","168.32400","14.02716","0.00095"
"28086","168.48000","14.04014","0.00092"
"28112","168.63600","14.05311","0.00061"
"28138","168.79200","14.06615","0.00016"
"28164","168.94800","14.07918","0.00039"
"28190","169.10400","14.09215","0.00028"
"28216","169.26000","14.10513","0.00090"
"28242","169.41600","14.11816","0.00049"
"28268","169.57200","14.13114","0.00081"
"28294","169.72800","14.14411","0.00064"
"28320","169.88400","14.15721","0.00042"
"28346","170.04000","14.17012","0.00105"
"28372","170.19600","14.18309","0.00118"
"28398","170.35200","14.19613","0.00105"
"28424","170.50800","14.20916","0.00060"
"28450","170.66400","14.22208","0.00085"
"28476","170.82000","14.23511","0.00082"
"28502","170.97600","14.24809","0.00075"
"28528","171.13200","14.26112","0.00086"
"28554","171.28800","14.27409","0.00015"
"28580","171.44400","14.28719","0.00123"
"28606","171.60000","14.30016","0.00174"
"28632","171.75600","14.31314","0.00105"
"28658","171.91200","14.32617","0.00116"
"28684","172.06800","14.33915","0.00130"
"28710","172.22400","14.35218","0.00065"
"28736","172.38000","14.36503","0.00089"
"28762","172.53600","14.37819","0.00036"
"28788","172.69200","14.39116","0.00100"
"28814","172.84800","14.40414","0.00059"
"28840","173.00400","14.41711","0.00107"
"28866","173.16000","14.43015","0.00079"
"28892","173.31600","14.44318","0.00122"
"28918","173.47200","14.45615","0.00079"
"28944","173.62800","14.46919","0.00076"
"28970","173.78400","14.48216","0.00098"
"28996","173.94000","14.49514","0.00093"
"29022","174.09600","14.50811","0.00094"
"29048","174.25200","14.52114","0.00103"
"29074","174.40800","14.53412","0.00167"
"29100","174.56400","14.54709","0.00080"
"29126","174.72000","14.56013","0.00165"
"29152","174.87600","14.57316","0.00213"
"29178","175.03200","14.58614","0.00269"
"29204","175.18800","14.59917","0.00250"
"29230","175.34400","14.61214","0.00085"
"29256","175.50000","14.62518","0.00040"
"29282","175.65600","14.63809","0.00011"
"29308","175.81200","14.65113","0.00024"
"29334","175.96800","14.66416","0.00063"
"29360","176.12400","14.67708","0.00013"
"29386","176.28000","14.69011","0.00111"
"29412","176.43600","14.70314","0.00120"
"29438","176.59200","14.71612","0.00014"
"29464","176.74800","14.72915","-0.00004"
"29490","176.90400","14.74213","-0.00016"
"29516","177.06000","14.75516","-0.00019"
"29542","177.21600","14.76814","-0.00062"
"29568","177.37200","14.78123","0.00112"
"29594","177.52800","14.79414","0.00040"
"29620","177.68400","14.80712","-0.00008"
"29646","177.84000","14.82009","0.00008"
"29672","177.99600","14.83313","0.00009"
"29698","178.15200","14.84610","-0.00046"
"29724","178.30800","14.85907","0.00032"
"29750","178.46400","14.87217","0.00039"
"29776","178.62000","14.88520","0.00002"
"29802","178.77600","14.89812","0.00037"
"29828","178.93200","14.91115","-0.00097"
"29854","179.08800","14.92418","-0.00010"
"29880","179.24400","14.93716","0.00024"
"29906","179.40000","14.95007","-0.00008"
"29932","179.55600","14.96317","-0.00075"
"29958","179.71200","14.97614","0.00015"
"29984","179.86800","14.98912","-0.00046"
"30010","180.02400","15.00215","0.00016"
"30036","180.18000","15.01513","0.00037"
"30062","180.33600","15.02810","-0.00026"
"30088","180.49200","15.04113","0.00024"
"30114","180.64800","15.05417","-0.00018"
"30140","180.80400","15.06714","0.00016"
"30166","180.96000","15.08006","0.00097"
"30192","181.11600","15.09315","0.00101"
"30218","181.27200","15.10613","0.00062"
"30244","181.42800","15.11910","0.00015"
"30270","181.58400","15.13207","0.00068"
"30296","181.74000","15.14517","0.00056"
"30322","181.89600","15.15814","0.00063"
"30348","182.05200","15.17111","0.00053"
"30374","182.20800","15.18415","0.00036"
"30400","182.36400","15.19713","-0.00021"
"30426","182.52000","15.21010","-0.00031"
"30452","182.67600","15.22313","-0.00002"
"30478","182.83200","15.23617","0.00035"
"30504","182.98800","15.24914","0.00074"
"30530","183.14400","15.26206","0.00088"
"30556","183.30000","15.27515","0.00081"
"30582","183.45600","15.28813","0.00196"
"30608","183.61200","15.30110","0.00138"
"30634","183.76800","15.31413","0.00048"
"30660","183.92400","15.32717","0.00036"
"30686","184.08000","15.34014","0.00020"
"30712","184.23600","15.35312","0.00076"
"30738","184.39200","15.36615","0.00055"
"30764","184.54800","15.37918","0.00057"
"30790","184.70400","15.39210","0.00065"
"30816","184.86000","15.40519","0.00079"
"30842","185.01600","15.41817","0.00016"
"30868","185.17200","15.43114","0.00035"
"30894","185.32800","15.44406","0.00006"
"30920","185.48400","15.45715","0.00057"
"30946","185.64000","15.47012","0.00117"
"30972","185.79600","15.48316","0.00025"
"30998","185.95200","15.49613","0.00036"
"31024","186.10800","15.50917","0.00017"
"31050","186.26400","15.52214","0.00058"
"31076","186.42000","15.53511","0.00075"
"31102","186.57600","15.54815","0.00047"
"31128","186.73200","15.56106","0.00037"
"31154","186.88800","15.57410","0.00197"
"31180","187.04400","15.58713","0.00219"
"31206","187.20000","15.60017","0.00109"
"31232","187.35600","15.61308","0.00036"
"31258","187.51200","15.62617","0.00116"
"31284","187.66800","15.63921","0.00068"
"31310","187.82400","15.65218","0.00020"
"31336","187.98000","15.66510","0.00061"
"31362","188.13600","15.67813","0.00021"
"31388","188.29200","15.69122","0.00052"
"31414","188.44800","15.70414","0.00053"
"31440","188.60400","15.71717","0.00041"
"31466","188.76000","15.73015","0.00039"
"31492","188.91600","15.74312","0.00033"
"31518","189.07200","15.75610","0.00054"
"31544","189.22800","15.76919","0.00044"
"31570","189.38400","15.78216","0.00076"
"31596","189.54000","15.79514","0.00033"
"31622","189.69600","15.80817","0.00039"
"31648","189.85200","15.82121","0.00092"
"31674","190.00800","15.83412","0.00079"
"31700","190.16400","15.84710","0.00053"
"31726","190.32000","15.86019","0.00024"
"31752","190.47600","15.87316","0.00066"
"31778","190.63200","15.88608","0.00066"
"31804","190.78800","15.89911","0.00073"
"31830","190.94400","15.91221","-0.00017"
"31856","191.10000","15.92512","0.00093"
"31882","191.25600","15.93816","0.00056"
"31908","191.41200","15.95119","0.00013"
"31934","191.56800","15.96416","-0.00004"
"31960","191.72400","15.97714","0.00060"
"31986","191.88000","15.99011","0.00082"
"32012","192.03600","16.00321","0.00041"
"32038","192.19200","16.01612","0.00028"
"32064","192.34800","16.02916","-0.00009"
"32090","192.50400","16.04213","0.00067"
"32116","192.66000","16.05516","0.00009"
"32142","192.81600","16.06808","0.00071"
"32168","192.97200","16.08117","0.00109"
"32194","193.12800","16.09421","0.00104"
"32220","193.28400","16.10712","0.00138"
"32246","193.44000","16.12016","0.00037"
"32272","193.59600","16.13313","0.00021"
"32298","193.75200","16.14616","0.00068"
"32324","193.90800","16.15908","0.00056"
"32350","194.06400","16.17217","0.00007"
"32376","194.22000","16.18515","0.00105"
"32402","194.37600","16.19812","0.00110"
"32428","194.53200","16.21115","0.00084"
"32454","194.68800","16.22419","0.00021"
"32480","194.84400","16.23716","0.00092"
"32499","194.95400","16.24625","-0.00035"