File: Trajectories_together/170212_3Specimen_RawData_4.csv
"","V1","V2","V3"
"1","End date","2/12/2017",""
"2","Specimen label","13BG_3",""
"3","Maximum Load","0.01368","N"
"4","Time","Extension","Load"
"5","(s)","(mm)","(N)"
"6","0.00000","0.00000","-0.00001"
"60","0.32400","0.02685","0.00042"
"114","0.64800","0.05423","0.00027"
"168","0.97200","0.08125","0.00009"
"222","1.29600","0.10822","0.00020"
"276","1.62000","0.13524","0.00076"
"330","1.94400","0.16227","0.00055"
"384","2.26800","0.18917","0.00000"
"438","2.59200","0.21620","0.00089"
"492","2.91600","0.24316","0.00052"
"546","3.24000","0.27025","0.00052"
"600","3.56400","0.29721","0.00058"
"654","3.88800","0.32418","0.00053"
"708","4.21200","0.35126","0.00014"
"762","4.53600","0.37817","0.00006"
"816","4.86000","0.40525","0.00090"
"870","5.18400","0.43222","0.00010"
"924","5.50800","0.45918","0.00001"
"978","5.83200","0.48627","0.00080"
"1032","6.15600","0.51317","0.00095"
"1086","6.48000","0.54026","0.00114"
"1140","6.80400","0.56722","0.00069"
"1194","7.12800","0.59419","0.00109"
"1248","7.45200","0.62121","0.00050"
"1302","7.77600","0.64812","0.00117"
"1356","8.10000","0.67520","0.00106"
"1410","8.42400","0.70223","0.00065"
"1464","8.74800","0.72919","0.00125"
"1518","9.07200","0.75622","0.00059"
"1572","9.39600","0.78318","0.00128"
"1626","9.72000","0.81021","0.00104"
"1680","10.04400","0.83723","0.00095"
"1734","10.36800","0.86414","0.00156"
"1788","10.69200","0.89128","0.00047"
"1842","11.01600","0.91819","0.00097"
"1896","11.34000","0.94515","0.00140"
"1950","11.66400","0.97224","0.00079"
"2004","11.98800","0.99920","0.00137"
"2058","12.31200","1.02623","0.00061"
"2112","12.63600","1.05313","0.00114"
"2166","12.96000","1.08022","0.00149"
"2220","13.28400","1.10730","0.00050"
"2274","13.60800","1.13415","0.00088"
"2328","13.93200","1.16123","0.00134"
"2382","14.25600","1.18820","0.00067"
"2436","14.58000","1.21528","0.00075"
"2490","14.90400","1.24219","0.00121"
"2544","15.22800","1.26915","0.00125"
"2598","15.55200","1.29624","0.00084"
"2652","15.87600","1.32320","0.00139"
"2706","16.20000","1.35023","0.00093"
"2760","16.52400","1.37725","0.00106"
"2814","16.84800","1.40422","0.00138"
"2868","17.17200","1.43124","0.00081"
"2922","17.49600","1.45821","0.00134"
"2976","17.82000","1.48517","0.00116"
"3030","18.14400","1.51226","0.00144"
"3084","18.46800","1.53922","0.00115"
"3138","18.79200","1.56619","0.00149"
"3192","19.11600","1.59321","0.00116"
"3246","19.44000","1.62024","0.00190"
"3300","19.76400","1.64726","0.00128"
"3354","20.08800","1.67417","0.00139"
"3408","20.41200","1.70125","0.00145"
"3462","20.73600","1.72828","0.00142"
"3516","21.06000","1.75524","0.00147"
"3570","21.38400","1.78227","0.00179"
"3624","21.70800","1.80917","0.00114"
"3678","22.03200","1.83626","0.00143"
"3732","22.35600","1.86322","0.00150"
"3786","22.68000","1.89019","0.00188"
"3840","23.00400","1.91727","0.00167"
"3894","23.32800","1.94424","0.00155"
"3948","23.65200","1.97126","0.00187"
"4002","23.97600","1.99823","0.00176"
"4056","24.30000","2.02525","0.00191"
"4110","24.62400","2.05228","0.00156"
"4164","24.94800","2.07918","0.00159"
"4218","25.27200","2.10627","0.00144"
"4272","25.59600","2.13317","0.00165"
"4326","25.92000","2.16026","0.00226"
"4380","26.24400","2.18722","0.00206"
"4434","26.56800","2.21413","0.00142"
"4488","26.89200","2.24121","0.00102"
"4542","27.21600","2.26824","0.00162"
"4596","27.54000","2.29520","0.00219"
"4650","27.86400","2.32223","0.00174"
"4704","28.18800","2.34919","0.00206"
"4758","28.51200","2.37622","0.00158"
"4812","28.83600","2.40324","0.00178"
"4866","29.16000","2.43021","0.00190"
"4920","29.48400","2.45729","0.00236"
"4974","29.80800","2.48414","0.00186"
"5028","30.13200","2.51122","0.00175"
"5082","30.45600","2.53819","0.00200"
"5136","30.78000","2.56521","0.00210"
"5190","31.10400","2.59224","0.00125"
"5244","31.42800","2.61920","0.00144"
"5298","31.75200","2.64622","0.00247"
"5352","32.07600","2.67325","0.00198"
"5406","32.40000","2.70021","0.00241"
"5460","32.72400","2.72724","0.00216"
"5514","33.04800","2.75414","0.00190"
"5568","33.37200","2.78123","0.00155"
"5622","33.69600","2.80825","0.00200"
"5676","34.02000","2.83516","0.00238"
"5730","34.34400","2.86224","0.00214"
"5784","34.66800","2.88921","0.00178"
"5838","34.99200","2.91623","0.00259"
"5892","35.31600","2.94320","0.00233"
"5946","35.64000","2.97022","0.00233"
"6000","35.96400","2.99731","0.00230"
"6054","36.28800","3.02421","0.00252"
"6108","36.61200","3.05124","0.00267"
"6162","36.93600","3.07826","0.00211"
"6216","37.26000","3.10517","0.00211"
"6270","37.58400","3.13225","0.00203"
"6324","37.90800","3.15916","0.00243"
"6378","38.23200","3.18624","0.00269"
"6432","38.55600","3.21327","0.00212"
"6486","38.88000","3.24017","0.00222"
"6540","39.20400","3.26720","0.00232"
"6594","39.52800","3.29422","0.00215"
"6648","39.85200","3.32125","0.00269"
"6702","40.17600","3.34827","0.00246"
"6756","40.50000","3.37518","0.00302"
"6810","40.82400","3.40220","0.00266"
"6864","41.14800","3.42923","0.00246"
"6918","41.47200","3.45619","0.00274"
"6972","41.79600","3.48322","0.00198"
"7026","42.12000","3.51024","0.00261"
"7080","42.44400","3.53721","0.00275"
"7134","42.76800","3.56417","0.00255"
"7188","43.09200","3.59120","0.00256"
"7242","43.41600","3.61828","0.00281"
"7296","43.74000","3.64519","0.00252"
"7350","44.06400","3.67227","0.00304"
"7404","44.38800","3.69918","0.00283"
"7458","44.71200","3.72620","0.00249"
"7512","45.03600","3.75323","0.00230"
"7566","45.36000","3.78013","0.00217"
"7620","45.68400","3.80722","0.00300"
"7674","46.00800","3.83424","0.00218"
"7728","46.33200","3.86127","0.00234"
"7782","46.65600","3.88823","0.00218"
"7836","46.98000","3.91520","0.00264"
"7890","47.30400","3.94228","0.00287"
"7944","47.62800","3.96925","0.00241"
"7998","47.95200","3.99621","0.00281"
"8052","48.27600","4.02324","0.00324"
"8106","48.60000","4.05020","0.00278"
"8160","48.92400","4.07723","0.00277"
"8214","49.24800","4.10419","0.00292"
"8268","49.57200","4.13122","0.00266"
"8322","49.89600","4.15824","0.00313"
"8376","50.22000","4.18515","0.00264"
"8430","50.54400","4.21217","0.00319"
"8484","50.86800","4.23920","0.00232"
"8538","51.19200","4.26622","0.00247"
"8592","51.51600","4.29325","0.00335"
"8646","51.84000","4.32021","0.00335"
"8700","52.16400","4.34724","0.00294"
"8754","52.48800","4.37420","0.00304"
"8808","52.81200","4.40117","0.00357"
"8862","53.13600","4.42825","0.00350"
"8916","53.46000","4.45522","0.00328"
"8970","53.78400","4.48230","0.00301"
"9024","54.10800","4.50921","0.00295"
"9078","54.43200","4.53617","0.00342"
"9132","54.75600","4.56332","0.00307"
"9186","55.08000","4.59016","0.00321"
"9240","55.40400","4.61725","0.00374"
"9294","55.72800","4.64421","0.00307"
"9348","56.05200","4.67124","0.00357"
"9402","56.37600","4.69826","0.00329"
"9456","56.70000","4.72517","0.00384"
"9510","57.02400","4.75225","0.00333"
"9564","57.34800","4.77922","0.00334"
"9618","57.67200","4.80618","0.00320"
"9672","57.99600","4.83321","0.00337"
"9726","58.32000","4.86017","0.00350"
"9780","58.64400","4.88726","0.00318"
"9834","58.96800","4.91422","0.00360"
"9888","59.29200","4.94119","0.00307"
"9942","59.61600","4.96827","0.00332"
"9996","59.94000","4.99518","0.00336"
"10050","60.26400","5.02226","0.00411"
"10104","60.58800","5.04923","0.00364"
"10158","60.91200","5.07619","0.00323"
"10212","61.23600","5.10322","0.00370"
"10266","61.56000","5.13024","0.00392"
"10320","61.88400","5.15721","0.00354"
"10374","62.20800","5.18423","0.00315"
"10428","62.53200","5.21126","0.00308"
"10482","62.85600","5.23822","0.00369"
"10536","63.18000","5.26519","0.00310"
"10590","63.50400","5.29227","0.00284"
"10644","63.82800","5.31924","0.00295"
"10698","64.15200","5.34620","0.00293"
"10752","64.47600","5.37329","0.00369"
"10806","64.80000","5.40019","0.00304"
"10860","65.12400","5.42722","0.00390"
"10914","65.44800","5.45424","0.00313"
"10968","65.77200","5.48121","0.00270"
"11022","66.09600","5.50823","0.00322"
"11076","66.42000","5.53520","0.00305"
"11130","66.74400","5.56222","0.00375"
"11184","67.06800","5.58924","0.00277"
"11238","67.39200","5.61627","0.00311"
"11292","67.71600","5.64324","0.00319"
"11346","68.04000","5.67014","0.00327"
"11400","68.36400","5.69723","0.00339"
"11454","68.68800","5.72425","0.00296"
"11508","69.01200","5.75122","0.00321"
"11562","69.33600","5.77824","0.00285"
"11616","69.66000","5.80520","0.00338"
"11670","69.98400","5.83223","0.00304"
"11724","70.30800","5.85925","0.00320"
"11778","70.63200","5.88616","0.00373"
"11832","70.95600","5.91324","0.00258"
"11886","71.28000","5.94021","0.00286"
"11940","71.60400","5.96717","0.00306"
"11994","71.92800","5.99426","0.00313"
"12048","72.25200","6.02122","0.00363"
"12102","72.57600","6.04825","0.00291"
"12156","72.90000","6.07521","0.00304"
"12210","73.22400","6.10224","0.00269"
"12264","73.54800","6.12926","0.00328"
"12318","73.87200","6.15623","0.00292"
"12372","74.19600","6.18319","0.00297"
"12426","74.52000","6.21022","0.00321"
"12480","74.84400","6.23730","0.00300"
"12534","75.16800","6.26421","0.00309"
"12588","75.49200","6.29123","0.00336"
"12642","75.81600","6.31820","0.00288"
"12696","76.14000","6.34522","0.00287"
"12750","76.46400","6.37225","0.00326"
"12804","76.78800","6.39927","0.00259"
"12858","77.11200","6.42618","0.00334"
"12912","77.43600","6.45326","0.00252"
"12966","77.76000","6.48017","0.00310"
"13020","78.08400","6.50719","0.00282"
"13074","78.40800","6.53422","0.00278"
"13128","78.73200","6.56124","0.00317"
"13182","79.05600","6.58827","0.00257"
"13236","79.38000","6.61523","0.00273"
"13290","79.70400","6.64226","0.00292"
"13344","80.02800","6.66928","0.00324"
"13398","80.35200","6.69619","0.00224"
"13452","80.67600","6.72327","0.00354"
"13506","81.00000","6.75024","0.00286"
"13560","81.32400","6.77726","0.00319"
"13614","81.64800","6.80429","0.00324"
"13668","81.97200","6.83119","0.00287"
"13722","82.29600","6.85828","0.00274"
"13776","82.62000","6.88524","0.00284"
"13830","82.94400","6.91221","0.00288"
"13884","83.26800","6.93923","0.00260"
"13938","83.59200","6.96620","0.00329"
"13992","83.91600","6.99322","0.00300"
"14046","84.24000","7.02025","0.00220"
"14100","84.56400","7.04721","0.00254"
"14154","84.88800","7.07430","0.00317"
"14208","85.21200","7.10120","0.00248"
"14262","85.53600","7.12823","0.00314"
"14316","85.86000","7.15519","0.00267"
"14370","86.18400","7.18222","0.00317"
"14424","86.50800","7.20924","0.00252"
"14478","86.83200","7.23615","0.00268"
"14532","87.15600","7.26323","0.00342"
"14586","87.48000","7.29026","0.00307"
"14640","87.80400","7.31716","0.00231"
"14694","88.12800","7.34425","0.00241"
"14748","88.45200","7.37115","0.00337"
"14802","88.77600","7.39824","0.00321"
"14856","89.10000","7.42520","0.00227"
"14910","89.42400","7.45223","0.00308"
"14964","89.74800","7.47925","0.00310"
"15018","90.07200","7.50616","0.00289"
"15072","90.39600","7.53324","0.00291"
"15126","90.72000","7.56021","0.00272"
"15180","91.04400","7.58723","0.00264"
"15234","91.36800","7.61426","0.00338"
"15288","91.69200","7.64116","0.00251"
"15342","92.01600","7.66825","0.00271"
"15396","92.34000","7.69521","0.00312"
"15450","92.66400","7.72224","0.00246"
"15504","92.98800","7.74920","0.00265"
"15558","93.31200","7.77617","0.00266"
"15612","93.63600","7.80325","0.00292"
"15666","93.96000","7.83022","0.00286"
"15720","94.28400","7.85718","0.00261"
"15774","94.60800","7.88421","0.00259"
"15828","94.93200","7.91123","0.00255"
"15882","95.25600","7.93820","0.00163"
"15936","95.58000","7.96522","0.00246"
"15990","95.90400","7.99219","0.00291"
"16044","96.22800","8.01921","0.00250"
"16098","96.55200","8.04618","0.00229"
"16152","96.87600","8.07320","0.00281"
"16206","97.20000","8.10023","0.00251"
"16260","97.52400","8.12725","0.00258"
"16314","97.84800","8.15428","0.00248"
"16368","98.17200","8.18118","0.00280"
"16422","98.49600","8.20827","0.00189"
"16476","98.82000","8.23529","0.00258"
"16530","99.14400","8.26220","0.00322"
"16584","99.46800","8.28922","0.00248"
"16638","99.79200","8.31619","0.00161"
"16692","100.11600","8.34327","0.00136"
"16746","100.44000","8.37024","0.00174"
"16800","100.76400","8.39720","0.00123"
"16854","101.08800","8.42422","0.00166"
"16908","101.41200","8.45119","0.00138"
"16962","101.73600","8.47822","0.00134"
"17016","102.06000","8.50524","0.00140"
"17070","102.38400","8.53221","0.00098"
"17124","102.70800","8.55923","0.00138"
"17178","103.03200","8.58619","0.00120"
"17232","103.35600","8.61322","0.00156"
"17286","103.68000","8.64025","0.00075"
"17340","104.00400","8.66721","0.00134"
"17394","104.32800","8.69418","0.00164"
"17448","104.65200","8.72120","0.00125"
"17502","104.97600","8.74828","0.00177"
"17556","105.30000","8.77525","0.00138"
"17610","105.62400","8.80221","0.00132"
"17664","105.94800","8.82924","0.00148"
"17718","106.27200","8.85627","0.00088"
"17772","106.59600","8.88323","0.00117"
"17826","106.92000","8.91025","0.00162"
"17880","107.24400","8.93722","0.00099"
"17934","107.56800","8.96424","0.00157"
"17988","107.89200","8.99121","0.00110"
"18042","108.21600","9.01817","0.00144"
"18096","108.54000","9.04526","0.00097"
"18150","108.86400","9.07216","0.00102"
"18204","109.18800","9.09925","0.00156"
"18258","109.51200","9.12621","0.00117"
"18312","109.83600","9.15324","0.00170"
"18366","110.16000","9.18026","0.00152"
"18420","110.48400","9.20717","0.00071"
"18474","110.80800","9.23419","0.00117"
"18528","111.13200","9.26122","0.00159"
"18582","111.45600","9.28824","0.00184"
"18636","111.78000","9.31521","0.00153"
"18690","112.10400","9.34217","0.00170"
"18744","112.42800","9.36926","0.00114"
"18798","112.75200","9.39622","0.00163"
"18852","113.07600","9.42319","0.00159"
"18906","113.40000","9.45021","0.00177"
"18960","113.72400","9.47718","0.00123"
"19014","114.04800","9.50426","0.00158"
"19068","114.37200","9.53123","0.00113"
"19122","114.69600","9.55819","0.00120"
"19176","115.02000","9.58528","0.00097"
"19230","115.34400","9.61218","0.00115"
"19284","115.66800","9.63921","0.00178"
"19338","115.99200","9.66623","0.00175"
"19392","116.31600","9.69320","0.00171"
"19446","116.64000","9.72028","0.00160"
"19500","116.96400","9.74719","0.00175"
"19554","117.28800","9.77427","0.00174"
"19608","117.61200","9.80124","0.00174"
"19662","117.93600","9.82820","0.00190"
"19716","118.26000","9.85517","0.00123"
"19770","118.58400","9.88219","0.00108"
"19824","118.90800","9.90928","0.00162"
"19878","119.23200","9.93618","0.00096"
"19932","119.55600","9.96315","0.00202"
"19986","119.88000","9.99029","0.00198"
"20040","120.20400","10.01720","0.00117"
"20094","120.52800","10.04422","0.00180"
"20148","120.85200","10.07119","0.00092"
"20202","121.17600","10.09821","0.00106"
"20256","121.50000","10.12524","0.00141"
"20310","121.82400","10.15220","0.00155"
"20364","122.14800","10.17923","0.00211"
"20418","122.47200","10.20625","0.00197"
"20472","122.79600","10.23322","0.00114"
"20526","123.12000","10.26018","0.00121"
"20580","123.44400","10.28715","0.00074"
"20634","123.76800","10.31429","0.00173"
"20688","124.09200","10.34126","0.00142"
"20742","124.41600","10.36822","0.00157"
"20796","124.74000","10.39525","0.00142"
"20850","125.06400","10.42221","0.00163"
"20904","125.38800","10.44924","0.00128"
"20958","125.71200","10.47620","0.00153"
"21012","126.03600","10.50317","0.00148"
"21066","126.36000","10.53025","0.00154"
"21120","126.68400","10.55722","0.00145"
"21174","127.00800","10.58424","0.00183"
"21228","127.33200","10.61121","0.00141"
"21282","127.65600","10.63823","0.00194"
"21336","127.98000","10.66526","0.00096"
"21390","128.30400","10.69222","0.00188"
"21444","128.62800","10.71919","0.00108"
"21498","128.95200","10.74627","0.00182"
"21552","129.27600","10.77318","0.00114"
"21606","129.60000","10.80026","0.00158"
"21660","129.92400","10.82717","0.00184"
"21714","130.24800","10.85419","0.00123"
"21768","130.57200","10.88122","0.00205"
"21822","130.89600","10.90812","0.00158"
"21876","131.22000","10.93527","0.00163"
"21930","131.54400","10.96223","0.00185"
"21984","131.86800","10.98920","0.00185"
"22038","132.19200","11.01622","0.00141"
"22092","132.51600","11.04325","0.00137"
"22146","132.84000","11.07027","0.00126"
"22200","133.16400","11.09724","0.00163"
"22254","133.48800","11.12420","0.00139"
"22308","133.81200","11.15123","0.00125"
"22362","134.13600","11.17819","0.00153"
"22416","134.46000","11.20522","0.00120"
"22470","134.78400","11.23218","0.00130"
"22524","135.10800","11.25927","0.00129"
"22578","135.43200","11.28623","0.00221"
"22632","135.75600","11.31314","0.00181"
"22686","136.08000","11.34022","0.00189"
"22740","136.40400","11.36725","0.00140"
"22794","136.72800","11.39421","0.00197"
"22848","137.05200","11.42124","0.00229"
"22902","137.37600","11.44820","0.00154"
"22956","137.70000","11.47523","0.00092"
"23010","138.02400","11.50219","0.00122"
"23064","138.34800","11.52915","0.00125"
"23118","138.67200","11.55624","0.00144"
"23172","138.99600","11.58321","0.00135"
"23226","139.32000","11.61023","0.00171"
"23280","139.64400","11.63720","0.00169"
"23334","139.96800","11.66422","0.00186"
"23388","140.29200","11.69131","0.00130"
"23442","140.61600","11.71821","0.00158"
"23496","140.94000","11.74530","0.00213"
"23550","141.26400","11.77220","0.00191"
"23604","141.58800","11.79922","0.00134"
"23658","141.91200","11.82631","0.00151"
"23712","142.23600","11.85316","0.00162"
"23766","142.56000","11.88024","0.00169"
"23820","142.88400","11.90721","0.00153"
"23874","143.20800","11.93417","0.00184"
"23928","143.53200","11.96119","0.00204"
"23982","143.85600","11.98822","0.00207"
"24036","144.18000","12.01530","0.00164"
"24090","144.50400","12.04221","0.00142"
"24144","144.82800","12.06917","0.00149"
"24198","145.15200","12.09626","0.00185"
"24252","145.47600","12.12317","0.00125"
"24306","145.80000","12.15025","0.00173"
"24360","146.12400","12.17721","0.00165"
"24414","146.44800","12.20424","0.00194"
"24468","146.77200","12.23126","0.00109"
"24522","147.09600","12.25817","0.00159"
"24576","147.42000","12.28525","0.00131"
"24630","147.74400","12.31222","0.00159"
"24684","148.06800","12.33924","0.00124"
"24738","148.39200","12.36621","0.00166"
"24792","148.71600","12.39318","0.00175"
"24846","149.04000","12.42026","0.00203"
"24900","149.36400","12.44722","0.00155"
"24954","149.68800","12.47419","0.00128"
"25008","150.01200","12.50127","0.00205"
"25062","150.33600","12.52818","0.00150"
"25116","150.66000","12.55526","0.00133"
"25170","150.98400","12.58217","0.00166"
"25224","151.30800","12.60919","0.00158"
"25278","151.63200","12.63628","0.00109"
"25332","151.95600","12.66318","0.00239"
"25386","152.28000","12.69027","0.00129"
"25440","152.60400","12.71723","0.00102"
"25494","152.92800","12.74420","0.00167"
"25548","153.25200","12.77122","0.00188"
"25602","153.57600","12.79819","0.00157"
"25656","153.90000","12.82527","0.00155"
"25710","154.22400","12.85224","0.00191"
"25764","154.54800","12.87920","0.00160"
"25818","154.87200","12.90617","0.00157"
"25872","155.19600","12.93319","0.00159"
"25926","155.52000","12.96022","0.00222"
"25980","155.84400","12.98724","0.00127"
"26034","156.16800","13.01421","0.00130"
"26088","156.49200","13.04123","0.00130"
"26142","156.81600","13.06820","0.00205"
"26196","157.14000","13.09522","0.00186"
"26250","157.46400","13.12225","0.00141"
"26304","157.78800","13.14921","0.00206"
"26358","158.11200","13.17624","0.00110"
"26412","158.43600","13.20320","0.00089"
"26466","158.76000","13.23023","0.00164"
"26520","159.08400","13.25725","0.00132"
"26574","159.40800","13.28422","0.00108"
"26628","159.73200","13.31124","0.00181"
"26682","160.05600","13.33815","0.00129"
"26736","160.38000","13.36523","0.00183"
"26790","160.70400","13.39226","0.00168"
"26844","161.02800","13.41916","0.00117"
"26898","161.35200","13.44625","0.00200"
"26952","161.67600","13.47321","0.00156"
"27006","162.00000","13.50024","0.00139"
"27060","162.32400","13.52726","0.00117"
"27114","162.64800","13.55423","0.00134"
"27168","162.97200","13.58125","0.00153"
"27222","163.29600","13.60816","0.00084"
"27276","163.62000","13.63518","0.00166"
"27330","163.94400","13.66227","0.00156"
"27384","164.26800","13.68917","0.00117"
"27438","164.59200","13.71626","0.00153"
"27492","164.91600","13.74322","0.00126"
"27546","165.24000","13.77031","0.00117"
"27600","165.56400","13.79727","0.00115"
"27654","165.88800","13.82424","0.00157"
"27708","166.21200","13.85126","0.00076"
"27762","166.53600","13.87823","0.00218"
"27816","166.86000","13.90525","0.00123"
"27870","167.18400","13.93222","0.00150"
"27924","167.50800","13.95918","0.00109"
"27978","167.83200","13.98627","0.00085"
"28032","168.15600","14.01317","0.00144"
"28086","168.48000","14.04020","0.00164"
"28140","168.80400","14.06722","0.00142"
"28194","169.12800","14.09419","0.00105"
"28248","169.45200","14.12127","0.00172"
"28302","169.77600","14.14824","0.00107"
"28356","170.10000","14.17526","0.00117"
"28410","170.42400","14.20223","0.00142"
"28464","170.74800","14.22913","0.00142"
"28518","171.07200","14.25628","0.00066"
"28572","171.39600","14.28324","0.00128"
"28626","171.72000","14.31027","0.00072"
"28680","172.04400","14.33723","0.00152"
"28734","172.36800","14.36420","0.00132"
"28788","172.69200","14.39122","0.00165"
"28842","173.01600","14.41819","0.00181"
"28896","173.34000","14.44521","0.00098"
"28950","173.66400","14.47224","0.00155"
"29004","173.98800","14.49914","0.00198"
"29058","174.31200","14.52629","0.00144"
"29112","174.63600","14.55325","0.00115"
"29166","174.96000","14.58016","0.00142"
"29220","175.28400","14.60730","0.00111"
"29274","175.60800","14.63421","0.00128"
"29328","175.93200","14.66123","0.00120"
"29382","176.25600","14.68820","0.00100"
"29436","176.58000","14.71528","0.00141"
"29490","176.90400","14.74224","0.00136"
"29544","177.22800","14.76921","0.00162"
"29598","177.55200","14.79624","0.00089"
"29652","177.87600","14.82320","0.00150"
"29706","178.20000","14.85023","0.00168"
"29760","178.52400","14.87719","0.00141"
"29814","178.84800","14.90416","0.00109"
"29868","179.17200","14.93124","0.00172"
"29922","179.49600","14.95820","0.00198"
"29976","179.82000","14.98517","0.00165"
"30030","180.14400","15.01225","0.00204"
"30084","180.46800","15.03922","0.00107"
"30138","180.79200","15.06625","0.00158"
"30192","181.11600","15.09321","0.00095"
"30246","181.44000","15.12018","0.00124"
"30300","181.76400","15.14726","0.00159"
"30354","182.08800","15.17417","0.00165"
"30408","182.41200","15.20125","0.00184"
"30462","182.73600","15.22821","0.00149"
"30516","183.06000","15.25524","0.00157"
"30570","183.38400","15.28220","0.00171"
"30624","183.70800","15.30917","0.00187"
"30678","184.03200","15.33626","0.00152"
"30732","184.35600","15.36322","0.00229"
"30786","184.68000","15.39018","0.00188"
"30840","185.00400","15.41727","0.00146"
"30894","185.32800","15.44417","0.00187"
"30948","185.65200","15.47126","0.00203"
"31002","185.97600","15.49817","0.00211"
"31056","186.30000","15.52519","0.00160"
"31110","186.62400","15.55222","0.00166"
"31164","186.94800","15.57924","0.00154"
"31218","187.27200","15.60626","0.00200"
"31272","187.59600","15.63323","0.00153"
"31326","187.92000","15.66019","0.00132"
"31380","188.24400","15.68722","0.00190"
"31434","188.56800","15.71418","0.00173"
"31488","188.89200","15.74121","0.00193"
"31542","189.21600","15.76823","0.00119"
"31596","189.54000","15.79520","0.00229"
"31650","189.86400","15.82216","0.00159"
"31704","190.18800","15.84919","0.00162"
"31758","190.51200","15.87621","0.00166"
"31812","190.83600","15.90324","0.00148"
"31866","191.16000","15.93014","0.00126"
"31920","191.48400","15.95723","0.00140"
"31974","191.80800","15.98425","0.00214"
"32028","192.13200","16.01122","0.00146"
"32082","192.45600","16.03824","0.00197"
"32136","192.78000","16.06521","0.00131"
"32190","193.10400","16.09223","0.00083"
"32244","193.42800","16.11914","0.00109"
"32298","193.75200","16.14622","0.00157"
"32352","194.07600","16.17319","0.00163"
"32406","194.40000","16.20021","0.00231"
"32460","194.72400","16.22724","0.00133"
"32514","195.04800","16.25414","0.00101"
"32568","195.37200","16.28129","0.00090"
"32622","195.69600","16.30825","0.00133"
"32676","196.02000","16.33516","0.00162"
"32730","196.34400","16.36224","0.00158"
"32784","196.66800","16.38921","0.00164"
"32838","196.99200","16.41623","0.00154"
"32892","197.31600","16.44326","0.00173"
"32946","197.64000","16.47022","0.00218"
"33000","197.96400","16.49725","0.00268"
"33054","198.28800","16.52421","0.00151"
"33108","198.61200","16.55124","0.00118"
"33162","198.93600","16.57826","0.00151"
"33216","199.26000","16.60523","0.00176"
"33270","199.58400","16.63225","0.00238"
"33324","199.90800","16.65922","0.00161"
"33378","200.23200","16.68624","0.00184"
"33432","200.55600","16.71333","0.00187"
"33486","200.88000","16.74017","0.00121"
"33540","201.20400","16.76726","0.00149"
"33594","201.52800","16.79422","0.00142"
"33648","201.85200","16.82125","0.00147"
"33702","202.17600","16.84827","0.00175"
"33756","202.50000","16.87518","0.00173"
"33810","202.82400","16.90226","0.00163"
"33864","203.14800","16.92923","0.00156"
"33918","203.47200","16.95619","0.00193"
"33972","203.79600","16.98322","0.00172"
"34026","204.12000","17.01018","0.00204"
"34080","204.44400","17.03727","0.00174"
"34134","204.76800","17.06417","0.00201"
"34188","205.09200","17.09120","0.00179"
"34242","205.41600","17.11822","0.00197"
"34296","205.74000","17.14519","0.00194"
"34350","206.06400","17.17227","0.00165"
"34404","206.38800","17.19918","0.00171"
"34458","206.71200","17.22626","0.00149"
"34512","207.03600","17.25328","0.00188"
"34566","207.36000","17.28019","0.00187"
"34620","207.68400","17.30728","0.00130"
"34674","208.00800","17.33424","0.00212"
"34728","208.33200","17.36121","0.00117"
"34782","208.65600","17.38823","0.00160"
"34836","208.98000","17.41514","0.00163"
"34890","209.30400","17.44222","0.00180"
"34944","209.62800","17.46925","0.00228"
"34998","209.95200","17.49621","0.00120"
"35052","210.27600","17.52324","0.00172"
"35106","210.60000","17.55020","0.00196"
"35160","210.92400","17.57729","0.00214"
"35214","211.24800","17.60419","0.00122"
"35268","211.57200","17.63122","0.00229"
"35322","211.89600","17.65824","0.00188"
"35376","212.22000","17.68514","0.00128"
"35430","212.54400","17.71223","0.00193"
"35484","212.86800","17.73926","0.00176"
"35538","213.19200","17.76622","0.00187"
"35592","213.51600","17.79325","0.00176"
"35646","213.84000","17.82015","0.00171"
"35700","214.16400","17.84724","0.00139"
"35754","214.48800","17.87426","0.00198"
"35808","214.81200","17.90122","0.00219"
"35862","215.13600","17.92825","0.00216"
"35916","215.46000","17.95522","0.00172"
"35970","215.78400","17.98224","0.00188"
"36024","216.10800","18.00920","0.00147"
"36078","216.43200","18.03617","0.00180"
"36132","216.75600","18.06326","0.00170"
"36186","217.08000","18.09022","0.00155"
"36240","217.40400","18.11731","0.00168"
"36294","217.72800","18.14427","0.00185"
"36348","218.05200","18.17123","0.00222"
"36402","218.37600","18.19820","0.00142"
"36456","218.70000","18.22516","0.00204"
"36510","219.02400","18.25225","0.00188"
"36564","219.34800","18.27927","0.00223"
"36618","219.67200","18.30618","0.00203"
"36672","219.99600","18.33320","0.00171"
"36726","220.32000","18.36017","0.00183"
"36780","220.64400","18.38725","0.00173"
"36834","220.96800","18.41422","0.00176"
"36888","221.29200","18.44118","0.00224"
"36942","221.61600","18.46821","0.00170"
"36996","221.94000","18.49523","0.00191"
"37050","222.26400","18.52226","0.00159"
"37104","222.58800","18.54928","0.00175"
"37158","222.91200","18.57619","0.00201"
"37212","223.23600","18.60328","0.00141"
"37266","223.56000","18.63018","0.00160"
"37320","223.88400","18.65720","0.00228"
"37374","224.20800","18.68429","0.00193"
"37428","224.53200","18.71119","0.00216"
"37482","224.85600","18.73822","0.00160"
"37536","225.18000","18.76518","0.00219"
"37590","225.50400","18.79227","0.00168"
"37644","225.82800","18.81929","0.00192"
"37698","226.15200","18.84620","0.00191"
"37752","226.47600","18.87322","0.00161"
"37806","226.80000","18.90019","0.00177"
"37860","227.12400","18.92727","0.00201"
"37914","227.44800","18.95424","0.00229"
"37968","227.77200","18.98120","0.00140"
"38022","228.09600","19.00829","0.00203"
"38076","228.42000","19.03519","0.00177"
"38130","228.74400","19.06222","0.00167"
"38184","229.06800","19.08918","0.00188"
"38238","229.39200","19.11621","0.00183"
"38292","229.71600","19.14323","0.00207"
"38346","230.04000","19.17020","0.00225"
"38400","230.36400","19.19722","0.00242"
"38454","230.68800","19.22425","0.00239"
"38508","231.01200","19.25115","0.00230"
"38562","231.33600","19.27818","0.00214"
"38616","231.66000","19.30520","0.00140"
"38670","231.98400","19.33223","0.00234"
"38724","232.30800","19.35925","0.00235"
"38778","232.63200","19.38622","0.00244"
"38832","232.95600","19.41324","0.00225"
"38886","233.28000","19.44021","0.00218"
"38940","233.60400","19.46723","0.00252"
"38994","233.92800","19.49420","0.00179"
"39048","234.25200","19.52116","0.00234"
"39102","234.57600","19.54825","0.00199"
"39156","234.90000","19.57521","0.00191"
"39210","235.22400","19.60218","0.00190"
"39264","235.54800","19.62926","0.00220"
"39318","235.87200","19.65617","0.00216"
"39372","236.19600","19.68325","0.00189"
"39426","236.52000","19.71022","0.00230"
"39480","236.84400","19.73724","0.00169"
"39534","237.16800","19.76427","0.00234"
"39588","237.49200","19.79117","0.00151"
"39642","237.81600","19.81826","0.00197"
"39696","238.14000","19.84516","0.00204"
"39750","238.46400","19.87219","0.00200"
"39804","238.78800","19.89921","0.00197"
"39858","239.11200","19.92618","0.00210"
"39912","239.43600","19.95326","0.00218"
"39966","239.76000","19.98017","0.00220"
"40020","240.08400","20.00719","0.00166"
"40074","240.40800","20.03428","0.00267"
"40128","240.73200","20.06124","0.00224"
"40182","241.05600","20.08827","0.00165"
"40236","241.38000","20.11523","0.00170"
"40290","241.70400","20.14220","0.00194"
"40344","242.02800","20.16922","0.00168"
"40398","242.35200","20.19619","0.00212"
"40452","242.67600","20.22321","0.00163"
"40506","243.00000","20.25023","0.00205"
"40560","243.32400","20.27720","0.00202"
"40614","243.64800","20.30423","0.00222"
"40668","243.97200","20.33113","0.00199"
"40722","244.29600","20.35828","0.00147"
"40776","244.62000","20.38524","0.00209"
"40830","244.94400","20.41221","0.00276"
"40884","245.26800","20.43923","0.00238"
"40938","245.59200","20.46620","0.00272"
"40992","245.91600","20.49322","0.00247"
"41046","246.24000","20.52024","0.00263"
"41100","246.56400","20.54721","0.00334"
"41154","246.88800","20.57430","0.00271"
"41208","247.21200","20.60120","0.00216"
"41262","247.53600","20.62823","0.00270"
"41316","247.86000","20.65519","0.00242"
"41370","248.18400","20.68222","0.00210"
"41424","248.50800","20.70924","0.00262"
"41478","248.83200","20.73615","0.00208"
"41532","249.15600","20.76323","0.00200"
"41586","249.48000","20.79020","0.00191"
"41640","249.80400","20.81722","0.00204"
"41694","250.12800","20.84425","0.00229"
"41748","250.45200","20.87121","0.00211"
"41802","250.77600","20.89824","0.00237"
"41856","251.10000","20.92526","0.00180"
"41910","251.42400","20.95217","0.00267"
"41964","251.74800","20.97925","0.00264"
"42018","252.07200","21.00622","0.00170"
"42072","252.39600","21.03324","0.00255"
"42126","252.72000","21.06020","0.00271"
"42180","253.04400","21.08717","0.00230"
"42234","253.36800","21.11426","0.00273"
"42288","253.69200","21.14116","0.00276"
"42342","254.01600","21.16818","0.00247"
"42396","254.34000","21.19527","0.00252"
"42450","254.66400","21.22218","0.00235"
"42504","254.98800","21.24926","0.00266"
"42558","255.31200","21.27617","0.00236"
"42612","255.63600","21.30325","0.00267"
"42666","255.96000","21.33027","0.00209"
"42720","256.28400","21.35724","0.00266"
"42774","256.60800","21.38420","0.00256"
"42828","256.93200","21.41123","0.00196"
"42882","257.25600","21.43826","0.00266"
"42936","257.58000","21.46528","0.00306"
"42990","257.90400","21.49224","0.00298"
"43044","258.22800","21.51927","0.00298"
"43098","258.55200","21.54618","0.00257"
"43152","258.87600","21.57320","0.00256"
"43206","259.20000","21.60022","0.00264"
"43260","259.52400","21.62725","0.00240"
"43314","259.84800","21.65421","0.00276"
"43368","260.17200","21.68124","0.00210"
"43422","260.49600","21.70827","0.00278"
"43476","260.82000","21.73535","0.00285"
"43530","261.14400","21.76213","0.00283"
"43584","261.46800","21.78922","0.00293"
"43638","261.79200","21.81618","0.00285"
"43692","262.11600","21.84321","0.00261"
"43746","262.44000","21.87029","0.00287"
"43800","262.76400","21.89720","0.00265"
"43854","263.08800","21.92422","0.00289"
"43908","263.41200","21.95119","0.00241"
"43962","263.73600","21.97821","0.00276"
"44016","264.06000","22.00524","0.00289"
"44070","264.38400","22.03221","0.00268"
"44124","264.70800","22.05929","0.00257"
"44178","265.03200","22.08619","0.00272"
"44232","265.35600","22.11322","0.00322"
"44286","265.68000","22.14030","0.00274"
"44340","266.00400","22.16721","0.00299"
"44394","266.32800","22.19423","0.00250"
"44448","266.65200","22.22120","0.00337"
"44502","266.97600","22.24822","0.00276"
"44556","267.30000","22.27525","0.00370"
"44610","267.62400","22.30215","0.00363"
"44664","267.94800","22.32924","0.00356"
"44718","268.27200","22.35620","0.00360"
"44772","268.59600","22.38323","0.00317"
"44826","268.92000","22.41025","0.00328"
"44880","269.24400","22.43716","0.00369"
"44934","269.56800","22.46424","0.00349"
"44988","269.89200","22.49121","0.00351"
"45042","270.21600","22.51823","0.00375"
"45096","270.54000","22.54526","0.00343"
"45150","270.86400","22.57216","0.00348"
"45204","271.18800","22.59925","0.00361"
"45258","271.51200","22.62621","0.00391"
"45312","271.83600","22.65324","0.00344"
"45366","272.16000","22.68026","0.00355"
"45420","272.48400","22.70717","0.00374"
"45474","272.80800","22.73425","0.00328"
"45528","273.13200","22.76122","0.00334"
"45582","273.45600","22.78824","0.00340"
"45636","273.78000","22.81521","0.00339"
"45690","274.10400","22.84217","0.00360"
"45744","274.42800","22.86920","0.00376"
"45798","274.75200","22.89622","0.00370"
"45852","275.07600","22.92319","0.00314"
"45906","275.40000","22.95021","0.00368"
"45960","275.72400","22.97718","0.00405"
"46014","276.04800","23.00420","0.00382"
"46068","276.37200","23.03123","0.00428"
"46122","276.69600","23.05819","0.00386"
"46176","277.02000","23.08528","0.00367"
"46230","277.34400","23.11218","0.00424"
"46284","277.66800","23.13927","0.00427"
"46338","277.99200","23.16623","0.00461"
"46392","278.31600","23.19320","0.00386"
"46446","278.64000","23.22022","0.00432"
"46500","278.96400","23.24713","0.00447"
"46554","279.28800","23.27421","0.00447"
"46608","279.61200","23.30124","0.00390"
"46662","279.93600","23.32820","0.00457"
"46716","280.26000","23.35522","0.00426"
"46770","280.58400","23.38219","0.00432"
"46824","280.90800","23.40928","0.00442"
"46878","281.23200","23.43618","0.00442"
"46932","281.55600","23.46321","0.00471"
"46986","281.88000","23.49023","0.00488"
"47040","282.20400","23.51720","0.00492"
"47094","282.52800","23.54422","0.00469"
"47148","282.85200","23.57125","0.00481"
"47202","283.17600","23.59821","0.00418"
"47256","283.50000","23.62523","0.00502"
"47310","283.82400","23.65220","0.00513"
"47364","284.14800","23.67923","0.00533"
"47418","284.47200","23.70631","0.00476"
"47472","284.79600","23.73322","0.00495"
"47526","285.12000","23.76024","0.00485"
"47580","285.44400","23.78721","0.00526"
"47634","285.76800","23.81423","0.00542"
"47688","286.09200","23.84126","0.00526"
"47742","286.41600","23.86816","0.00569"
"47796","286.74000","23.89519","0.00566"
"47850","287.06400","23.92221","0.00567"
"47904","287.38800","23.94924","0.00592"
"47958","287.71200","23.97626","0.00542"
"48012","288.03600","24.00323","0.00572"
"48066","288.36000","24.03025","0.00585"
"48120","288.68400","24.05716","0.00537"
"48174","289.00800","24.08418","0.00593"
"48228","289.33200","24.11121","0.00647"
"48282","289.65600","24.13823","0.00616"
"48336","289.98000","24.16525","0.00605"
"48390","290.30400","24.19216","0.00631"
"48444","290.62800","24.21925","0.00607"
"48498","290.95200","24.24627","0.00657"
"48552","291.27600","24.27317","0.00605"
"48606","291.60000","24.30026","0.00662"
"48660","291.92400","24.32723","0.00660"
"48714","292.24800","24.35425","0.00611"
"48768","292.57200","24.38128","0.00676"
"48822","292.89600","24.40818","0.00662"
"48876","293.22000","24.43520","0.00709"
"48930","293.54400","24.46217","0.00663"
"48984","293.86800","24.48914","0.00706"
"49038","294.19200","24.51622","0.00639"
"49092","294.51600","24.54318","0.00718"
"49146","294.84000","24.57021","0.00713"
"49200","295.16400","24.59723","0.00678"
"49254","295.48800","24.62420","0.00748"
"49308","295.81200","24.65129","0.00720"
"49362","296.13600","24.67819","0.00743"
"49416","296.46000","24.70521","0.00733"
"49470","296.78400","24.73218","0.00766"
"49524","297.10800","24.75926","0.00738"
"49578","297.43200","24.78623","0.00752"
"49632","297.75600","24.81314","0.00720"
"49686","298.08000","24.84022","0.00822"
"49740","298.40400","24.86724","0.00806"
"49794","298.72800","24.89421","0.00831"
"49848","299.05200","24.92123","0.00800"
"49902","299.37600","24.94820","0.00814"
"49956","299.70000","24.97522","0.00818"
"50010","300.02400","25.00219","0.00873"
"50064","300.34800","25.02921","0.00856"
"50118","300.67200","25.05630","0.00845"
"50172","300.99600","25.08320","0.00827"
"50226","301.32000","25.11029","0.00858"
"50280","301.64400","25.13720","0.00862"
"50334","301.96800","25.16416","0.00921"
"50388","302.29200","25.19124","0.00923"
"50442","302.61600","25.21821","0.00864"
"50496","302.94000","25.24523","0.00918"
"50550","303.26400","25.27226","0.00928"
"50604","303.58800","25.29922","0.00911"
"50658","303.91200","25.32625","0.00976"
"50712","304.23600","25.35315","0.00969"
"50766","304.56000","25.38024","0.00969"
"50820","304.88400","25.40726","0.00998"
"50874","305.20800","25.43417","0.00956"
"50928","305.53200","25.46119","0.01001"
"50982","305.85600","25.48822","0.00993"
"51036","306.18000","25.51524","0.01014"
"51090","306.50400","25.54227","0.00998"
"51144","306.82800","25.56917","0.00996"
"51198","307.15200","25.59626","0.00967"
"51252","307.47600","25.62322","0.00970"
"51306","307.80000","25.65025","0.01061"
"51360","308.12400","25.67721","0.01075"
"51414","308.44800","25.70424","0.01012"
"51468","308.77200","25.73126","0.01051"
"51522","309.09600","25.75817","0.01113"
"51576","309.42000","25.78519","0.01088"
"51630","309.74400","25.81228","0.01138"
"51684","310.06800","25.83924","0.01088"
"51738","310.39200","25.86627","0.01142"
"51792","310.71600","25.89317","0.01115"
"51846","311.04000","25.92026","0.01143"
"51900","311.36400","25.94728","0.01146"
"51954","311.68800","25.97419","0.01144"
"52008","312.01200","26.00127","0.01210"
"52062","312.33600","26.02818","0.01186"
"52116","312.66000","26.05520","0.01198"
"52170","312.98400","26.08223","0.01238"
"52224","313.30800","26.10919","0.01312"
"52278","313.63200","26.13628","0.01214"
"52332","313.95600","26.16312","0.01217"
"52386","314.28000","26.19021","0.01224"
"52440","314.60400","26.21723","0.01244"
"52494","314.92800","26.24420","0.01314"
"52548","315.25200","26.27122","0.01350"
"52602","315.57600","26.29819","0.01282"
"52656","315.90000","26.32527","0.01346"
"52710","316.22400","26.35224","0.01308"
"52764","316.54800","26.37920","0.00201"
"52818","316.87200","26.40617","0.00255"
"52872","317.19600","26.43325","0.00147"
"52926","317.52000","26.46028","0.00091"
"52980","317.84400","26.48724","0.00119"
"53034","318.16800","26.51421","0.00230"
"53088","318.49200","26.54129","0.00108"
"53142","318.81600","26.56820","0.00091"
"53196","319.14000","26.59516","0.00130"
"53250","319.46400","26.62225","0.00172"
"53304","319.78800","26.64921","0.00138"
"53358","320.11200","26.67624","0.00147"
"53412","320.43600","26.70320","0.00169"
"53466","320.76000","26.73023","0.00085"
"53520","321.08400","26.75731","0.00122"
"53574","321.40800","26.78416","0.00160"
"53628","321.73200","26.81124","0.00138"
"53682","322.05600","26.83821","0.00115"
"53736","322.38000","26.86523","0.00220"
"53790","322.70400","26.89226","0.00133"
"53844","323.02800","26.91922","0.00085"
"53898","323.35200","26.94625","0.00144"
"53952","323.67600","26.97321","0.00195"
"54006","324.00000","27.00023","0.00145"
"54060","324.32400","27.02726","0.00143"
"54114","324.64800","27.05422","0.00147"
"54168","324.97200","27.08131","0.00122"
"54222","325.29600","27.10822","0.00164"
"54276","325.62000","27.13518","0.00142"
"54330","325.94400","27.16227","0.00149"
"54384","326.26800","27.18923","0.00207"
"54438","326.59200","27.21620","0.00167"
"54492","326.91600","27.24322","0.00134"
"54546","327.24000","27.27019","0.00183"
"54600","327.56400","27.29727","0.00129"
"54654","327.88800","27.32417","0.00082"
"54708","328.21200","27.35120","0.00176"
"54762","328.53600","27.37822","0.00136"
"54816","328.86000","27.40525","0.00181"
"54870","329.18400","27.43222","0.00174"
"54924","329.50800","27.45912","0.00173"
"54978","329.83200","27.48621","0.00147"
"55032","330.15600","27.51323","0.00132"
"55086","330.48000","27.54020","0.00163"
"55140","330.80400","27.56728","0.00168"
"55194","331.12800","27.59418","0.00135"
"55248","331.45200","27.62127","0.00131"
"55302","331.77600","27.64817","0.00166"
"55356","332.10000","27.67520","0.00200"
"55410","332.42400","27.70228","0.00133"
"55464","332.74800","27.72913","0.00160"
"55518","333.07200","27.75622","0.00184"
"55572","333.39600","27.78324","0.00137"
"55626","333.72000","27.81026","0.00170"
"55680","334.04400","27.83723","0.00191"
"55734","334.36800","27.86414","0.00233"
"55788","334.69200","27.89122","0.00147"
"55842","335.01600","27.91818","0.00177"
"55896","335.34000","27.94521","0.00136"
"55950","335.66400","27.97224","0.00199"
"56004","335.98800","27.99926","0.00140"
"56058","336.31200","28.02622","0.00185"
"56112","336.63600","28.05325","0.00217"
"56166","336.96000","28.08021","0.00209"
"56220","337.28400","28.10730","0.00121"
"56274","337.60800","28.13420","0.00210"
"56328","337.93200","28.16123","0.00166"
"56382","338.25600","28.18819","0.00135"
"56436","338.58000","28.21516","0.00165"
"56490","338.90400","28.24224","0.00213"
"56544","339.22800","28.26921","0.00184"
"56598","339.55200","28.29623","0.00103"
"56652","339.87600","28.32326","0.00178"
"56706","340.20000","28.35022","0.00190"
"56760","340.52400","28.37725","0.00157"
"56814","340.84800","28.40416","0.00204"
"56868","341.17200","28.43124","0.00180"
"56922","341.49600","28.45827","0.00179"
"56976","341.82000","28.48517","0.00133"
"57030","342.14400","28.51220","0.00221"
"57084","342.46800","28.53922","0.00187"
"57138","342.79200","28.56624","0.00178"
"57192","343.11600","28.59321","0.00141"
"57246","343.44000","28.62023","0.00228"
"57300","343.76400","28.64726","0.00188"
"57354","344.08800","28.67422","0.00195"
"57408","344.41200","28.70119","0.00210"
"57462","344.73600","28.72821","0.00205"
"57516","345.06000","28.75518","0.00219"
"57570","345.38400","28.78220","0.00196"
"57624","345.70800","28.80917","0.00169"
"57678","346.03200","28.83625","0.00234"
"57732","346.35600","28.86322","0.00168"
"57786","346.68000","28.89018","0.00187"
"57840","347.00400","28.91721","0.00222"
"57894","347.32800","28.94423","0.00187"
"57948","347.65200","28.97126","0.00172"
"58002","347.97600","28.99828","0.00202"
"58056","348.30000","29.02519","0.00172"
"58110","348.62400","29.05227","0.00114"
"58164","348.94800","29.07924","0.00207"
"58218","349.27200","29.10620","0.00150"
"58272","349.59600","29.13323","0.00190"
"58326","349.92000","29.16019","0.00216"
"58380","350.24400","29.18722","0.00185"
"58434","350.56800","29.21424","0.00177"
"58488","350.89200","29.24121","0.00180"
"58542","351.21600","29.26823","0.00165"
"58596","351.54000","29.29514","0.00253"
"58650","351.86400","29.32222","0.00172"
"58704","352.18800","29.34919","0.00147"
"58758","352.51200","29.37627","0.00166"
"58812","352.83600","29.40330","0.00135"
"58866","353.16000","29.43020","0.00179"
"58920","353.48400","29.45723","0.00194"
"58974","353.80800","29.48425","0.00177"
"59028","354.13200","29.51122","0.00259"
"59082","354.45600","29.53824","0.00223"
"59136","354.78000","29.56521","0.00246"
"59190","355.10400","29.59229","0.00232"
"59244","355.42800","29.61926","0.00226"
"59298","355.75200","29.64616","0.00152"
"59352","356.07600","29.67325","0.00195"
"59406","356.40000","29.70021","0.00224"
"59460","356.72400","29.72724","0.00218"
"59514","357.04800","29.75420","0.00202"
"59568","357.37200","29.78123","0.00186"
"59622","357.69600","29.80825","0.00176"
"59676","358.02000","29.83516","0.00245"
"59730","358.34400","29.86224","0.00218"
"59784","358.66800","29.88927","0.00205"
"59838","358.99200","29.91623","0.00216"
"59892","359.31600","29.94326","0.00220"
"59946","359.64000","29.97016","0.00206"
"60000","359.96400","29.99725","0.00273"
"60054","360.28800","30.02421","0.00183"
"60108","360.61200","30.05124","0.00192"
"60162","360.93600","30.07826","0.00225"
"60216","361.26000","30.10523","0.00266"
"60270","361.58400","30.13225","0.00179"
"60324","361.90800","30.15922","0.00128"
"60378","362.23200","30.18618","0.00214"
"60432","362.55600","30.21327","0.00166"
"60486","362.88000","30.24023","0.00148"
"60540","363.20400","30.26726","0.00159"
"60594","363.52800","30.29422","0.00106"
"60648","363.85200","30.32118","0.00169"
"60702","364.17600","30.34821","0.00150"
"60756","364.50000","30.37512","0.00116"
"60810","364.82400","30.40226","0.00164"
"60864","365.14800","30.42923","0.00121"
"60918","365.47200","30.45619","0.00131"
"60972","365.79600","30.48328","0.00158"
"61026","366.12000","30.51018","0.00139"
"61080","366.44400","30.53727","0.00148"
"61134","366.76800","30.56417","0.00138"
"61188","367.09200","30.59120","0.00168"
"61242","367.41600","30.61822","0.00156"
"61296","367.74000","30.64519","0.00167"
"61350","368.06400","30.67227","0.00130"
"61404","368.38800","30.69923","0.00161"
"61458","368.71200","30.72620","0.00134"
"61512","369.03600","30.75323","0.00127"
"61566","369.36000","30.78013","0.00106"
"61620","369.68400","30.80722","0.00162"
"61674","370.00800","30.83424","0.00146"
"61728","370.33200","30.86121","0.00194"
"61782","370.65600","30.88823","0.00161"
"61836","370.98000","30.91520","0.00096"
"61890","371.30400","30.94222","0.00157"
"61944","371.62800","30.96924","0.00190"
"61998","371.95200","30.99621","0.00153"
"62052","372.27600","31.02323","0.00164"
"62106","372.60000","31.05020","0.00168"
"62160","372.92400","31.07723","0.00149"
"62214","373.24800","31.10425","0.00156"
"62268","373.57200","31.13122","0.00231"
"62322","373.89600","31.15830","0.00171"
"62376","374.22000","31.18515","0.00185"
"62430","374.54400","31.21223","0.00180"
"62484","374.86800","31.23919","0.00164"
"62538","375.19200","31.26622","0.00142"
"62592","375.51600","31.29324","0.00209"
"62646","375.84000","31.32021","0.00156"
"62700","376.16400","31.34729","0.00139"
"62754","376.48800","31.37420","0.00169"
"62808","376.81200","31.40122","0.00151"
"62862","377.13600","31.42819","0.00144"
"62916","377.46000","31.45521","0.00213"
"62970","377.78400","31.48224","0.00161"
"63024","378.10800","31.50926","0.00106"
"63078","378.43200","31.53623","0.00152"
"63132","378.75600","31.56325","0.00181"
"63186","379.08000","31.59022","0.00185"
"63240","379.40400","31.61718","0.00131"
"63294","379.72800","31.64421","0.00156"
"63348","380.05200","31.67123","0.00156"
"63402","380.37600","31.69826","0.00175"
"63456","380.70000","31.72522","0.00136"
"63510","381.02400","31.75225","0.00135"
"63564","381.34800","31.77927","0.00143"
"63618","381.67200","31.80618","0.00155"
"63672","381.99600","31.83326","0.00154"
"63726","382.32000","31.86017","0.00097"
"63780","382.64400","31.88725","0.00210"
"63834","382.96800","31.91427","0.00168"
"63888","383.29200","31.94118","0.00177"
"63942","383.61600","31.96827","0.00122"
"63996","383.94000","31.99523","0.00145"
"64050","384.26400","32.02225","0.00146"
"64104","384.58800","32.04928","0.00135"
"64158","384.91200","32.07619","0.00178"
"64212","385.23600","32.10327","0.00175"
"64266","385.56000","32.13018","0.00174"
"64320","385.88400","32.15720","0.00167"
"64374","386.20800","32.18423","0.00177"
"64428","386.53200","32.21119","0.00186"
"64482","386.85600","32.23822","0.00138"
"64536","387.18000","32.26518","0.00170"
"64590","387.50400","32.29221","0.00202"
"64644","387.82800","32.31929","0.00225"
"64698","388.15200","32.34620","0.00219"
"64752","388.47600","32.37322","0.00186"
"64806","388.80000","32.40025","0.00145"
"64860","389.12400","32.42721","0.00177"
"64914","389.44800","32.45424","0.00134"
"64968","389.77200","32.48114","0.00166"
"65022","390.09600","32.50823","0.00155"
"65076","390.42000","32.53519","0.00131"
"65130","390.74400","32.56221","0.00192"
"65184","391.06800","32.58924","0.00159"
"65238","391.39200","32.61615","0.00227"
"65292","391.71600","32.64323","0.00161"
"65346","392.04000","32.67026","0.00231"
"65400","392.36400","32.69722","0.00190"
"65454","392.68800","32.72425","0.00161"
"65508","393.01200","32.75121","0.00178"
"65562","393.33600","32.77824","0.00149"
"65616","393.66000","32.80520","0.00196"
"65670","393.98400","32.83223","0.00181"
"65724","394.30800","32.85919","0.00156"
"65778","394.63200","32.88610","0.00187"
"65832","394.95600","32.91324","0.00184"
"65886","395.28000","32.94020","0.00205"
"65940","395.60400","32.96723","0.00168"
"65966","395.75800","32.98003","0.00199"