File: Trajectories_together/170212_2Specimen_RawData_6.csv
"","V1","V2","V3"
"1","End date","2/12/2017",""
"2","Specimen label","9CG_76",""
"3","Maximum Load","0.71948","N"
"4","Time","Extension","Load"
"5","(s)","(mm)","(N)"
"6","0.00000","14.42925","0.01766"
"62","0.33600","14.45717","0.01853"
"118","0.67200","14.48545","0.01873"
"174","1.00800","14.51349","0.01984"
"230","1.34400","14.54141","0.02054"
"286","1.68000","14.56951","0.02040"
"342","2.01600","14.59744","0.02109"
"398","2.35200","14.62548","0.02118"
"454","2.68800","14.65346","0.02104"
"510","3.02400","14.68138","0.02226"
"566","3.36000","14.70948","0.02145"
"622","3.69600","14.73746","0.02177"
"678","4.03200","14.76538","0.02185"
"734","4.36800","14.79349","0.02215"
"790","4.70400","14.82135","0.02182"
"846","5.04000","14.84939","0.02257"
"902","5.37600","14.87749","0.02327"
"958","5.71200","14.90541","0.02301"
"1014","6.04800","14.93345","0.02296"
"1070","6.38400","14.96143","0.02346"
"1126","6.72000","14.98948","0.02349"
"1182","7.05600","15.01746","0.02391"
"1238","7.39200","15.04544","0.02383"
"1294","7.72800","15.07342","0.02389"
"1350","8.06400","15.10146","0.02443"
"1406","8.40000","15.12944","0.02389"
"1462","8.73600","15.15742","0.02455"
"1518","9.07200","15.18541","0.02435"
"1574","9.40800","15.21345","0.02459"
"1630","9.74400","15.24143","0.02436"
"1686","10.08000","15.26941","0.02449"
"1742","10.41600","15.29739","0.02473"
"1798","10.75200","15.32549","0.02539"
"1854","11.08800","15.35342","0.02505"
"1910","11.42400","15.38152","0.02494"
"1966","11.76000","15.40944","0.02592"
"2022","12.09600","15.43742","0.02557"
"2078","12.43200","15.46546","0.02611"
"2134","12.76800","15.49338","0.02655"
"2190","13.10400","15.52148","0.02611"
"2246","13.44000","15.54946","0.02649"
"2302","13.77600","15.57745","0.02629"
"2358","14.11200","15.60549","0.02653"
"2414","14.44800","15.63341","0.02702"
"2470","14.78400","15.66139","0.02668"
"2526","15.12000","15.68949","0.02683"
"2582","15.45600","15.71741","0.02692"
"2638","15.79200","15.74545","0.02678"
"2694","16.12800","15.77350","0.02745"
"2750","16.46400","15.80142","0.02714"
"2806","16.80000","15.82946","0.02796"
"2862","17.13600","15.85744","0.02735"
"2918","17.47200","15.88542","0.02745"
"2974","17.80800","15.91340","0.02769"
"3030","18.14400","15.94138","0.02805"
"3086","18.48000","15.96943","0.02718"
"3142","18.81600","15.99741","0.02763"
"3198","19.15200","16.02545","0.02796"
"3254","19.48800","16.05349","0.02766"
"3310","19.82400","16.08147","0.02792"
"3366","20.16000","16.10945","0.02780"
"3422","20.49600","16.13743","0.02808"
"3478","20.83200","16.16536","0.02792"
"3534","21.16800","16.19352","0.02831"
"3590","21.50400","16.22144","0.02897"
"3646","21.84000","16.24936","0.02855"
"3702","22.17600","16.27746","0.02899"
"3758","22.51200","16.30544","0.02856"
"3814","22.84800","16.33342","0.02900"
"3870","23.18400","16.36147","0.02905"
"3926","23.52000","16.38939","0.02889"
"3982","23.85600","16.41749","0.02939"
"4038","24.19200","16.44547","0.02896"
"4094","24.52800","16.47339","0.02961"
"4150","24.86400","16.50143","0.02983"
"4206","25.20000","16.52947","0.02941"
"4262","25.53600","16.55746","0.02972"
"4318","25.87200","16.58544","0.02920"
"4374","26.20800","16.61342","0.02918"
"4430","26.54400","16.64146","0.02970"
"4486","26.88000","16.66950","0.02975"
"4542","27.21600","16.69742","0.02975"
"4598","27.55200","16.72546","0.02988"
"4654","27.88800","16.75339","0.03031"
"4710","28.22400","16.78143","0.03102"
"4766","28.56000","16.80947","0.03069"
"4822","28.89600","16.83745","0.03081"
"4878","29.23200","16.86543","0.03081"
"4934","29.56800","16.89347","0.03039"
"4990","29.90400","16.92145","0.03046"
"5046","30.24000","16.94944","0.03076"
"5102","30.57600","16.97742","0.03040"
"5158","30.91200","17.00552","0.03124"
"5214","31.24800","17.03350","0.03126"
"5270","31.58400","17.06136","0.03076"
"5326","31.92000","17.08946","0.03119"
"5382","32.25600","17.11744","0.03131"
"5438","32.59200","17.14543","0.03155"
"5494","32.92800","17.17353","0.03087"
"5550","33.26400","17.20145","0.03137"
"5606","33.60000","17.22943","0.03157"
"5662","33.93600","17.25753","0.03171"
"5718","34.27200","17.28539","0.03137"
"5774","34.60800","17.31343","0.03142"
"5830","34.94400","17.34142","0.03142"
"5886","35.28000","17.36946","0.03139"
"5942","35.61600","17.39744","0.03131"
"5998","35.95200","17.42548","0.03117"
"6054","36.28800","17.45340","0.03098"
"6110","36.62400","17.48144","0.03155"
"6166","36.96000","17.50942","0.03145"
"6222","37.29600","17.53747","0.03175"
"6278","37.63200","17.56551","0.03218"
"6334","37.96800","17.59343","0.03169"
"6390","38.30400","17.62147","0.03198"
"6446","38.64000","17.64939","0.03217"
"6502","38.97600","17.67743","0.03289"
"6558","39.31200","17.70547","0.03222"
"6614","39.64800","17.73340","0.03256"
"6670","39.98400","17.76144","0.03203"
"6726","40.32000","17.78942","0.03333"
"6782","40.65600","17.81740","0.03288"
"6838","40.99200","17.84544","0.03268"
"6894","41.32800","17.87342","0.03366"
"6950","41.66400","17.90146","0.03285"
"7006","42.00000","17.92945","0.03319"
"7062","42.33600","17.95737","0.03337"
"7118","42.67200","17.98547","0.03369"
"7174","43.00800","18.01345","0.03333"
"7230","43.34400","18.04143","0.03372"
"7286","43.68000","18.06947","0.03393"
"7342","44.01600","18.09739","0.03349"
"7398","44.35200","18.12538","0.03339"
"7454","44.68800","18.15348","0.03378"
"7510","45.02400","18.18140","0.03396"
"7566","45.36000","18.20950","0.03397"
"7622","45.69600","18.23748","0.03441"
"7678","46.03200","18.26540","0.03474"
"7734","46.36800","18.29344","0.03465"
"7790","46.70400","18.32143","0.03446"
"7846","47.04000","18.34947","0.03471"
"7902","47.37600","18.37751","0.03459"
"7958","47.71200","18.40543","0.03497"
"8014","48.04800","18.43347","0.03529"
"8070","48.38400","18.46145","0.03513"
"8126","48.72000","18.48944","0.03542"
"8182","49.05600","18.51742","0.03526"
"8238","49.39200","18.54540","0.03530"
"8294","49.72800","18.57350","0.03560"
"8350","50.06400","18.60148","0.03569"
"8406","50.40000","18.62940","0.03581"
"8462","50.73600","18.65750","0.03616"
"8518","51.07200","18.68548","0.03601"
"8574","51.40800","18.71347","0.03624"
"8630","51.74400","18.74145","0.03627"
"8686","52.08000","18.76943","0.03650"
"8742","52.41600","18.79747","0.03641"
"8798","52.75200","18.82551","0.03659"
"8854","53.08800","18.85337","0.03631"
"8910","53.42400","18.88148","0.03654"
"8966","53.76000","18.90946","0.03626"
"9022","54.09600","18.93738","0.03656"
"9078","54.43200","18.96548","0.03666"
"9134","54.76800","18.99346","0.03723"
"9190","55.10400","19.02144","0.03710"
"9246","55.44000","19.04948","0.03725"
"9302","55.77600","19.07741","0.03722"
"9358","56.11200","19.10545","0.03733"
"9414","56.44800","19.13349","0.03742"
"9470","56.78400","19.16141","0.03766"
"9526","57.12000","19.18945","0.03765"
"9582","57.45600","19.21743","0.03756"
"9638","57.79200","19.24547","0.03798"
"9694","58.12800","19.27345","0.03796"
"9750","58.46400","19.30138","0.03788"
"9806","58.80000","19.32948","0.03822"
"9862","59.13600","19.35746","0.03839"
"9918","59.47200","19.38544","0.03784"
"9974","59.80800","19.41342","0.03811"
"10030","60.14400","19.44140","0.03830"
"10086","60.48000","19.46945","0.03814"
"10142","60.81600","19.49749","0.03859"
"10198","61.15200","19.52541","0.03889"
"10254","61.48800","19.55345","0.03860"
"10310","61.82400","19.58143","0.03849"
"10366","62.16000","19.60941","0.03859"
"10422","62.49600","19.63745","0.03901"
"10478","62.83200","19.66544","0.03898"
"10534","63.16800","19.69341","0.03946"
"10590","63.50400","19.72146","0.03924"
"10646","63.84000","19.74944","0.03926"
"10702","64.17600","19.77748","0.03952"
"10758","64.51200","19.80546","0.03965"
"10814","64.84800","19.83338","0.03973"
"10870","65.18400","19.86149","0.03947"
"10926","65.52000","19.88947","0.03964"
"10982","65.85600","19.91745","0.03938"
"11038","66.19200","19.94543","0.03971"
"11094","66.52800","19.97341","0.03999"
"11150","66.86400","20.00145","0.03994"
"11206","67.20000","20.02943","0.03997"
"11262","67.53600","20.05741","0.03979"
"11318","67.87200","20.08546","0.04024"
"11374","68.20800","20.11344","0.04029"
"11430","68.54400","20.14148","0.04021"
"11486","68.88000","20.16946","0.04018"
"11542","69.21600","20.19744","0.04028"
"11598","69.55200","20.22548","0.04031"
"11654","69.88800","20.25340","0.04048"
"11710","70.22400","20.28145","0.04070"
"11766","70.56000","20.30943","0.04091"
"11822","70.89600","20.33741","0.04071"
"11878","71.23200","20.36545","0.04072"
"11934","71.56800","20.39349","0.04090"
"11990","71.90400","20.42141","0.04102"
"12046","72.24000","20.44946","0.04103"
"12102","72.57600","20.47744","0.04115"
"12158","72.91200","20.50542","0.04159"
"12214","73.24800","20.53346","0.04157"
"12270","73.58400","20.56132","0.04116"
"12326","73.92000","20.58942","0.04166"
"12382","74.25600","20.61753","0.04145"
"12438","74.59200","20.64538","0.04167"
"12494","74.92800","20.67349","0.04193"
"12550","75.26400","20.70141","0.04206"
"12606","75.60000","20.72945","0.04200"
"12662","75.93600","20.75743","0.04227"
"12718","76.27200","20.78547","0.04227"
"12774","76.60800","20.81345","0.04192"
"12830","76.94400","20.84144","0.04194"
"12886","77.28000","20.86942","0.04182"
"12942","77.61600","20.89746","0.04064"
"12998","77.95200","20.92544","0.04103"
"13054","78.28800","20.95348","0.04121"
"13110","78.62400","20.98146","0.04125"
"13166","78.96000","21.00938","0.04111"
"13222","79.29600","21.03742","0.03875"
"13278","79.63200","21.06541","0.03885"
"13334","79.96800","21.09339","0.03866"
"13390","80.30400","21.12149","0.03859"
"13446","80.64000","21.14947","0.03921"
"13502","80.97600","21.17739","0.03924"
"13558","81.31200","21.20543","0.03955"
"13614","81.64800","21.23336","0.03954"
"13670","81.98400","21.26152","0.03991"
"13726","82.32000","21.28950","0.03964"
"13782","82.65600","21.31742","0.03979"
"13838","82.99200","21.34546","0.04023"
"13894","83.32800","21.37344","0.04003"
"13950","83.66400","21.40142","0.04028"
"14006","84.00000","21.42946","0.04008"
"14062","84.33600","21.45745","0.04010"
"14118","84.67200","21.48543","0.04019"
"14174","85.00800","21.51347","0.04039"
"14230","85.34400","21.54139","0.04038"
"14286","85.68000","21.56943","0.04034"
"14342","86.01600","21.59748","0.04039"
"14398","86.35200","21.62546","0.04047"
"14454","86.68800","21.65350","0.04083"
"14510","87.02400","21.68142","0.04088"
"14566","87.36000","21.70946","0.04076"
"14622","87.69600","21.73744","0.04107"
"14678","88.03200","21.76542","0.04065"
"14734","88.36800","21.79352","0.04099"
"14790","88.70400","21.82145","0.04125"
"14846","89.04000","21.84949","0.04093"
"14902","89.37600","21.87741","0.04139"
"14958","89.71200","21.90539","0.04132"
"15014","90.04800","21.93349","0.04109"
"15070","90.38400","21.96147","0.04154"
"15126","90.72000","21.98946","0.04154"
"15182","91.05600","22.01749","0.04100"
"15238","91.39200","22.04542","0.04154"
"15294","91.72800","22.07340","0.04155"
"15350","92.06400","22.10144","0.04172"
"15406","92.40000","22.12936","0.04156"
"15462","92.73600","22.15746","0.04166"
"15518","93.07200","22.18550","0.04172"
"15574","93.40800","22.21342","0.04155"
"15630","93.74400","22.24147","0.04177"
"15686","94.08000","22.26945","0.04215"
"15742","94.41600","22.29743","0.04198"
"15798","94.75200","22.32547","0.04222"
"15854","95.08800","22.35345","0.04257"
"15910","95.42400","22.38143","0.04196"
"15966","95.76000","22.40948","0.04177"
"16022","96.09600","22.43740","0.04193"
"16078","96.43200","22.46544","0.04192"
"16134","96.76800","22.49348","0.04177"
"16190","97.10400","22.52140","0.04158"
"16246","97.44000","22.54944","0.04196"
"16302","97.77600","22.57742","0.04231"
"16358","98.11200","22.60541","0.04208"
"16414","98.44800","22.63345","0.04244"
"16470","98.78400","22.66143","0.04216"
"16526","99.12000","22.68953","0.04203"
"16582","99.45600","22.71739","0.04171"
"16638","99.79200","22.74543","0.04201"
"16694","100.12800","22.77347","0.04231"
"16750","100.46400","22.80140","0.04203"
"16806","100.80000","22.82949","0.04203"
"16862","101.13600","22.85748","0.04252"
"16918","101.47200","22.88540","0.04265"
"16974","101.80800","22.91350","0.04235"
"17030","102.14400","22.94142","0.04272"
"17086","102.48000","22.96941","0.04287"
"17142","102.81600","22.99750","0.04291"
"17198","103.15200","23.02537","0.04224"
"17254","103.48800","23.05347","0.04280"
"17310","103.82400","23.08145","0.04250"
"17366","104.16000","23.10943","0.04271"
"17422","104.49600","23.13741","0.04276"
"17478","104.83200","23.16539","0.04255"
"17534","105.16800","23.19338","0.04234"
"17590","105.50400","23.22148","0.04234"
"17646","105.84000","23.24946","0.04243"
"17702","106.17600","23.27744","0.04237"
"17758","106.51200","23.30548","0.04279"
"17814","106.84800","23.33346","0.04275"
"17870","107.18400","23.36150","0.04310"
"17926","107.52000","23.38943","0.04360"
"17982","107.85600","23.41747","0.04335"
"18038","108.19200","23.44545","0.04356"
"18094","108.52800","23.47337","0.04373"
"18150","108.86400","23.50147","0.04330"
"18206","109.20000","23.52939","0.04340"
"18262","109.53600","23.55743","0.04369"
"18318","109.87200","23.58547","0.04396"
"18374","110.20800","23.61340","0.04428"
"18430","110.54400","23.64150","0.04445"
"18486","110.88000","23.66942","0.04440"
"18542","111.21600","23.69740","0.04407"
"18598","111.55200","23.72544","0.04390"
"18654","111.88800","23.75348","0.04395"
"18710","112.22400","23.78147","0.04433"
"18766","112.56000","23.80951","0.04338"
"18822","112.89600","23.83743","0.04331"
"18878","113.23200","23.86541","0.04364"
"18934","113.56800","23.89351","0.04365"
"18990","113.90400","23.92143","0.04382"
"19046","114.24000","23.94947","0.04389"
"19102","114.57600","23.97746","0.04423"
"19158","114.91200","24.00544","0.04432"
"19214","115.24800","24.03348","0.04461"
"19270","115.58400","24.06146","0.04512"
"19326","115.92000","24.08944","0.04487"
"19382","116.25600","24.11748","0.04472"
"19438","116.59200","24.14535","0.04546"
"19494","116.92800","24.17345","0.04533"
"19550","117.26400","24.20143","0.04541"
"19606","117.60000","24.22935","0.04577"
"19662","117.93600","24.25745","0.04506"
"19718","118.27200","24.28543","0.04576"
"19774","118.60800","24.31347","0.04583"
"19830","118.94400","24.34146","0.04615"
"19886","119.28000","24.36938","0.04654"
"19942","119.61600","24.39748","0.04681"
"19998","119.95200","24.42546","0.04701"
"20054","120.28800","24.45344","0.04734"
"20110","120.62400","24.48148","0.04792"
"20166","120.96000","24.50940","0.04833"
"20222","121.29600","24.53745","0.04815"
"20278","121.63200","24.56549","0.04833"
"20334","121.96800","24.59335","0.04849"
"20390","122.30400","24.62145","0.04902"
"20446","122.64000","24.64943","0.04959"
"20502","122.97600","24.67741","0.04987"
"20558","123.31200","24.70545","0.05055"
"20614","123.64800","24.73343","0.05015"
"20670","123.98400","24.76142","0.05070"
"20726","124.32000","24.78946","0.05047"
"20782","124.65600","24.81738","0.05069"
"20838","124.99200","24.84548","0.05168"
"20894","125.32800","24.87352","0.05200"
"20950","125.66400","24.90138","0.05246"
"21006","126.00000","24.92943","0.05346"
"21062","126.33600","24.95747","0.05286"
"21118","126.67200","24.98545","0.05333"
"21174","127.00800","25.01343","0.05359"
"21230","127.34400","25.04141","0.05389"
"21286","127.68000","25.06945","0.05466"
"21342","128.01600","25.09743","0.05493"
"21398","128.35200","25.12542","0.05634"
"21454","128.68800","25.15346","0.05518"
"21510","129.02400","25.18138","0.05607"
"21566","129.36000","25.20948","0.05615"
"21622","129.69600","25.23746","0.05630"
"21678","130.03200","25.26538","0.05664"
"21734","130.36800","25.29342","0.05645"
"21790","130.70400","25.32141","0.05711"
"21846","131.04000","25.34939","0.05763"
"21902","131.37600","25.37749","0.05779"
"21958","131.71200","25.40547","0.05701"
"22014","132.04800","25.43345","0.05795"
"22070","132.38400","25.46149","0.05825"
"22126","132.72000","25.48941","0.05697"
"22182","133.05600","25.51751","0.05704"
"22238","133.39200","25.54550","0.05578"
"22294","133.72800","25.57342","0.05664"
"22350","134.06400","25.60152","0.05825"
"22406","134.40000","25.62944","0.05916"
"22462","134.73600","25.65742","0.06010"
"22518","135.07200","25.68546","0.06075"
"22574","135.40800","25.71344","0.06115"
"22630","135.74400","25.74149","0.06191"
"22686","136.08000","25.76941","0.06255"
"22742","136.41600","25.79745","0.06344"
"22798","136.75200","25.82537","0.06384"
"22854","137.08800","25.85341","0.06394"
"22910","137.42400","25.88145","0.06431"
"22966","137.76000","25.90950","0.06364"
"23022","138.09600","25.93748","0.06356"
"23078","138.43200","25.96552","0.06407"
"23134","138.76800","25.99338","0.06448"
"23190","139.10400","26.02142","0.06473"
"23246","139.44000","26.04946","0.06604"
"23302","139.77600","26.07744","0.06553"
"23358","140.11200","26.10543","0.06567"
"23414","140.44800","26.13347","0.06631"
"23470","140.78400","26.16139","0.06637"
"23526","141.12000","26.18943","0.06593"
"23582","141.45600","26.21747","0.06664"
"23638","141.79200","26.24540","0.06626"
"23694","142.12800","26.27349","0.06769"
"23750","142.46400","26.30142","0.06787"
"23806","142.80000","26.32940","0.06898"
"23862","143.13600","26.35744","0.06846"
"23918","143.47200","26.38542","0.06918"
"23974","143.80800","26.41346","0.07020"
"24030","144.14400","26.44144","0.06973"
"24086","144.48000","26.46943","0.07102"
"24142","144.81600","26.49740","0.07123"
"24198","145.15200","26.52545","0.07191"
"24254","145.48800","26.55343","0.07278"
"24310","145.82400","26.58153","0.07255"
"24366","146.16000","26.60945","0.07253"
"24422","146.49600","26.63744","0.07361"
"24478","146.83200","26.66541","0.07403"
"24534","147.16800","26.69346","0.07429"
"24590","147.50400","26.72150","0.07389"
"24646","147.84000","26.74942","0.07473"
"24702","148.17600","26.77746","0.07483"
"24758","148.51200","26.80544","0.07628"
"24814","148.84800","26.83342","0.07649"
"24870","149.18400","26.86147","0.07645"
"24926","149.52000","26.88944","0.07728"
"24982","149.85600","26.91743","0.07681"
"25038","150.19200","26.94547","0.07831"
"25094","150.52800","26.97339","0.07804"
"25150","150.86400","27.00149","0.07838"
"25206","151.20000","27.02947","0.07990"
"25262","151.53600","27.05740","0.08013"
"25318","151.87200","27.08550","0.08001"
"25374","152.20800","27.11342","0.08063"
"25430","152.54400","27.14140","0.08079"
"25486","152.88000","27.16944","0.08138"
"25542","153.21600","27.19742","0.08157"
"25598","153.55200","27.22546","0.08284"
"25654","153.88800","27.25351","0.08243"
"25710","154.22400","27.28137","0.08246"
"25766","154.56000","27.30941","0.08258"
"25822","154.89600","27.33745","0.08342"
"25878","155.23200","27.36549","0.08485"
"25934","155.56800","27.39347","0.08489"
"25990","155.90400","27.42145","0.08522"
"26046","156.24000","27.44938","0.08597"
"26102","156.57600","27.47748","0.08593"
"26158","156.91200","27.50540","0.08539"
"26214","157.24800","27.53344","0.08601"
"26270","157.58400","27.56148","0.08662"
"26326","157.92000","27.58946","0.08700"
"26382","158.25600","27.61744","0.08756"
"26438","158.59200","27.64536","0.08832"
"26494","158.92800","27.67347","0.08871"
"26550","159.26400","27.70151","0.08932"
"26606","159.60000","27.72937","0.08962"
"26662","159.93600","27.75747","0.08964"
"26718","160.27200","27.78545","0.08986"
"26774","160.60800","27.81337","0.09005"
"26830","160.94400","27.84148","0.09008"
"26886","161.28000","27.86940","0.09065"
"26942","161.61600","27.89750","0.09074"
"26998","161.95200","27.92548","0.09096"
"27054","162.28800","27.95340","0.09106"
"27110","162.62400","27.98144","0.09135"
"27166","162.96000","28.00942","0.09141"
"27222","163.29600","28.03747","0.09168"
"27278","163.63200","28.06551","0.09186"
"27334","163.96800","28.09343","0.09198"
"27390","164.30400","28.12147","0.09194"
"27446","164.64000","28.14945","0.09204"
"27502","164.97600","28.17737","0.09263"
"27558","165.31200","28.20541","0.09334"
"27614","165.64800","28.23345","0.09331"
"27670","165.98400","28.26144","0.09381"
"27726","166.32000","28.28942","0.09398"
"27782","166.65600","28.31740","0.09509"
"27838","166.99200","28.34538","0.09445"
"27894","167.32800","28.37348","0.09295"
"27950","167.66400","28.40146","0.09378"
"28006","168.00000","28.42945","0.09349"
"28062","168.33600","28.45743","0.09399"
"28118","168.67200","28.48547","0.09461"
"28174","169.00800","28.51345","0.09482"
"28230","169.34400","28.54137","0.09634"
"28286","169.68000","28.56953","0.09755"
"28342","170.01600","28.59745","0.09934"
"28398","170.35200","28.62544","0.10091"
"28454","170.68800","28.65348","0.10298"
"28510","171.02400","28.68140","0.10514"
"28566","171.36000","28.70944","0.10673"
"28622","171.69600","28.73748","0.10944"
"28678","172.03200","28.76546","0.11020"
"28734","172.36800","28.79344","0.11211"
"28790","172.70400","28.82149","0.11290"
"28846","173.04000","28.84947","0.11400"
"28902","173.37600","28.87745","0.11455"
"28958","173.71200","28.90543","0.11551"
"29014","174.04800","28.93341","0.11628"
"29070","174.38400","28.96145","0.11745"
"29126","174.72000","28.98943","0.11870"
"29182","175.05600","29.01741","0.11928"
"29238","175.39200","29.04546","0.11936"
"29294","175.72800","29.07338","0.11912"
"29350","176.06400","29.10148","0.11953"
"29406","176.40000","29.12946","0.12114"
"29462","176.73600","29.15744","0.12258"
"29518","177.07200","29.18549","0.12231"
"29574","177.40800","29.21341","0.12233"
"29630","177.74400","29.24145","0.12367"
"29686","178.08000","29.26943","0.12468"
"29742","178.41600","29.29741","0.12549"
"29798","178.75200","29.32545","0.12609"
"29854","179.08800","29.35337","0.12640"
"29910","179.42400","29.38147","0.12696"
"29966","179.76000","29.40945","0.12767"
"30022","180.09600","29.43738","0.12864"
"30078","180.43200","29.46548","0.12944"
"30134","180.76800","29.49346","0.13038"
"30190","181.10400","29.52144","0.13085"
"30246","181.44000","29.54948","0.13146"
"30302","181.77600","29.57741","0.13189"
"30358","182.11200","29.60538","0.13269"
"30414","182.44800","29.63349","0.13367"
"30470","182.78400","29.66141","0.13389"
"30526","183.12000","29.68945","0.13462"
"30582","183.45600","29.71743","0.13509"
"30638","183.79200","29.74541","0.13579"
"30694","184.12800","29.77345","0.13632"
"30750","184.46400","29.80149","0.13665"
"30806","184.80000","29.82948","0.13708"
"30862","185.13600","29.85746","0.13790"
"30918","185.47200","29.88538","0.13833"
"30974","185.80800","29.91348","0.13852"
"31030","186.14400","29.94140","0.13923"
"31086","186.48000","29.96945","0.13952"
"31142","186.81600","29.99743","0.14031"
"31198","187.15200","30.02547","0.14127"
"31254","187.48800","30.05345","0.14212"
"31310","187.82400","30.08149","0.14246"
"31366","188.16000","30.10941","0.14293"
"31422","188.49600","30.13745","0.14399"
"31478","188.83200","30.16549","0.14466"
"31534","189.16800","30.19348","0.14668"
"31590","189.50400","30.22146","0.14728"
"31646","189.84000","30.24938","0.14788"
"31702","190.17600","30.27742","0.14857"
"31758","190.51200","30.30552","0.15018"
"31814","190.84800","30.33338","0.15200"
"31870","191.18400","30.36142","0.15253"
"31926","191.52000","30.38941","0.15462"
"31982","191.85600","30.41739","0.15774"
"32038","192.19200","30.44549","0.16125"
"32094","192.52800","30.47347","0.16377"
"32150","192.86400","30.50139","0.16584"
"32206","193.20000","30.52949","0.17044"
"32262","193.53600","30.55742","0.17226"
"32318","193.87200","30.58545","0.17345"
"32374","194.20800","30.61350","0.17121"
"32430","194.54400","30.64142","0.17117"
"32486","194.88000","30.66946","0.17236"
"32542","195.21600","30.69744","0.17496"
"32598","195.55200","30.72542","0.17888"
"32654","195.88800","30.75346","0.18393"
"32710","196.22400","30.78145","0.18850"
"32766","196.56000","30.80949","0.19069"
"32822","196.89600","30.83747","0.19263"
"32878","197.23200","30.86539","0.19432"
"32934","197.56800","30.89343","0.19524"
"32990","197.90400","30.92135","0.19603"
"33046","198.24000","30.94946","0.19681"
"33102","198.57600","30.97750","0.19727"
"33158","198.91200","31.00542","0.19861"
"33214","199.24800","31.03346","0.20009"
"33270","199.58400","31.06144","0.20248"
"33326","199.92000","31.08942","0.20319"
"33382","200.25600","31.11746","0.20586"
"33438","200.59200","31.14545","0.20817"
"33494","200.92800","31.17343","0.21087"
"33550","201.26400","31.20147","0.21403"
"33606","201.60000","31.22939","0.21635"
"33662","201.93600","31.25749","0.21872"
"33718","202.27200","31.28547","0.22145"
"33774","202.60800","31.31339","0.22283"
"33830","202.94400","31.34149","0.22566"
"33886","203.28000","31.36941","0.22751"
"33942","203.61600","31.39739","0.23022"
"33998","203.95200","31.42544","0.23239"
"34054","204.28800","31.45342","0.23407"
"34110","204.62400","31.48146","0.23504"
"34166","204.96000","31.50944","0.23615"
"34222","205.29600","31.53742","0.23779"
"34278","205.63200","31.56540","0.23860"
"34334","205.96800","31.59344","0.23960"
"34390","206.30400","31.62149","0.24054"
"34446","206.64000","31.64947","0.24164"
"34502","206.97600","31.67745","0.24236"
"34558","207.31200","31.70543","0.24325"
"34614","207.64800","31.73341","0.24410"
"34670","207.98400","31.76140","0.24502"
"34726","208.32000","31.78944","0.24575"
"34782","208.65600","31.81742","0.24681"
"34838","208.99200","31.84552","0.24782"
"34894","209.32800","31.87344","0.24919"
"34950","209.66400","31.90142","0.25140"
"35006","210.00000","31.92946","0.25354"
"35062","210.33600","31.95744","0.25577"
"35118","210.67200","31.98543","0.25861"
"35174","211.00800","32.01347","0.26164"
"35230","211.34400","32.04139","0.26384"
"35286","211.68000","32.06943","0.26682"
"35342","212.01600","32.09741","0.26886"
"35398","212.35200","32.12545","0.27134"
"35454","212.68800","32.15350","0.27394"
"35510","213.02400","32.18148","0.27565"
"35566","213.36000","32.20940","0.27881"
"35622","213.69600","32.23744","0.28111"
"35678","214.03200","32.26542","0.28378"
"35734","214.36800","32.29346","0.28569"
"35790","214.70400","32.32144","0.28713"
"35846","215.04000","32.34943","0.28851"
"35902","215.37600","32.37747","0.28976"
"35958","215.71200","32.40545","0.29104"
"36014","216.04800","32.43343","0.29181"
"36070","216.38400","32.46147","0.29347"
"36126","216.72000","32.48945","0.29600"
"36182","217.05600","32.51743","0.29945"
"36238","217.39200","32.54548","0.29229"
"36294","217.72800","32.57340","0.29179"
"36350","218.06400","32.60144","0.29359"
"36406","218.40000","32.62942","0.29568"
"36462","218.73600","32.65746","0.29872"
"36518","219.07200","32.68550","0.30233"
"36574","219.40800","32.71336","0.30594"
"36630","219.74400","32.74147","0.31137"
"36686","220.08000","32.76944","0.31610"
"36742","220.41600","32.79743","0.32118"
"36798","220.75200","32.82547","0.32493"
"36854","221.08800","32.85345","0.33052"
"36910","221.42400","32.88143","0.33499"
"36966","221.76000","32.90947","0.34017"
"37022","222.09600","32.93740","0.34321"
"37078","222.43200","32.96544","0.34602"
"37134","222.76800","32.99348","0.34783"
"37190","223.10400","33.02140","0.34885"
"37246","223.44000","33.04944","0.34955"
"37302","223.77600","33.07742","0.35021"
"37358","224.11200","33.10546","0.35097"
"37414","224.44800","33.13345","0.35168"
"37470","224.78400","33.16143","0.35240"
"37526","225.12000","33.18941","0.35412"
"37582","225.45600","33.21745","0.35540"
"37638","225.79200","33.24543","0.35779"
"37694","226.12800","33.27347","0.35978"
"37750","226.46400","33.30145","0.36257"
"37806","226.80000","33.32943","0.36413"
"37862","227.13600","33.35741","0.36671"
"37918","227.47200","33.38540","0.37031"
"37974","227.80800","33.41350","0.37399"
"38030","228.14400","33.44148","0.37757"
"38086","228.48000","33.46940","0.38138"
"38142","228.81600","33.49744","0.38651"
"38198","229.15200","33.52542","0.39008"
"38254","229.48800","33.55341","0.37206"
"38310","229.82400","33.58145","0.37904"
"38366","230.16000","33.60937","0.38696"
"38422","230.49600","33.63747","0.39340"
"38478","230.83200","33.66545","0.39705"
"38534","231.16800","33.69343","0.39875"
"38590","231.50400","33.72148","0.39947"
"38646","231.84000","33.74946","0.40022"
"38702","232.17600","33.77744","0.39983"
"38758","232.51200","33.80548","0.40217"
"38814","232.84800","33.83340","0.40585"
"38870","233.18400","33.86144","0.40860"
"38926","233.52000","33.88948","0.41254"
"38982","233.85600","33.91740","0.41635"
"39038","234.19200","33.94545","0.42047"
"39094","234.52800","33.97349","0.42417"
"39150","234.86400","34.00141","0.42703"
"39206","235.20000","34.02939","0.42994"
"39262","235.53600","34.05743","0.43275"
"39318","235.87200","34.08541","0.43491"
"39374","236.20800","34.11346","0.43618"
"39430","236.54400","34.14144","0.43792"
"39486","236.88000","34.16948","0.44033"
"39542","237.21600","34.19740","0.44174"
"39598","237.55200","34.22550","0.44430"
"39654","237.88800","34.25342","0.44738"
"39710","238.22400","34.28140","0.45019"
"39766","238.56000","34.30951","0.45284"
"39822","238.89600","34.33749","0.45555"
"39878","239.23200","34.36541","0.45815"
"39934","239.56800","34.39351","0.45971"
"39990","239.90400","34.42143","0.46399"
"40046","240.24000","34.44947","0.46729"
"40102","240.57600","34.47746","0.47237"
"40158","240.91200","34.50537","0.47435"
"40214","241.24800","34.53342","0.47983"
"40270","241.58400","34.56146","0.48311"
"40326","241.92000","34.58938","0.48707"
"40382","242.25600","34.61742","0.48971"
"40438","242.59200","34.64547","0.49359"
"40494","242.92800","34.67339","0.49643"
"40550","243.26400","34.70148","0.49766"
"40606","243.60000","34.72940","0.49855"
"40662","243.93600","34.75745","0.49942"
"40718","244.27200","34.78549","0.50174"
"40774","244.60800","34.81341","0.50491"
"40830","244.94400","34.84145","0.50966"
"40886","245.28000","34.86943","0.51508"
"40942","245.61600","34.89748","0.52146"
"40998","245.95200","34.92546","0.52763"
"41054","246.28800","34.95344","0.53243"
"41110","246.62400","34.98148","0.53661"
"41166","246.96000","35.00946","0.54050"
"41222","247.29600","35.03744","0.54393"
"41278","247.63200","35.06548","0.54708"
"41334","247.96800","35.09341","0.54886"
"41390","248.30400","35.12145","0.55138"
"41446","248.64000","35.14943","0.55497"
"41502","248.97600","35.17735","0.55696"
"41558","249.31200","35.20551","0.55916"
"41614","249.64800","35.23349","0.56046"
"41670","249.98400","35.26141","0.56143"
"41726","250.32000","35.28952","0.56247"
"41782","250.65600","35.31744","0.56387"
"41838","250.99200","35.34542","0.56518"
"41894","251.32800","35.37352","0.56733"
"41950","251.66400","35.40144","0.56987"
"42006","252.00000","35.42942","0.57355"
"42062","252.33600","35.45747","0.57755"
"42118","252.67200","35.48539","0.58410"
"42174","253.00800","35.51343","0.58990"
"42230","253.34400","35.54141","0.59524"
"42286","253.68000","35.56945","0.59952"
"42342","254.01600","35.59749","0.60284"
"42398","254.35200","35.62535","0.60579"
"42454","254.68800","35.65345","0.60881"
"42510","255.02400","35.68138","0.61314"
"42566","255.36000","35.70942","0.61844"
"42622","255.69600","35.73746","0.62391"
"42678","256.03200","35.76544","0.62959"
"42734","256.36800","35.79348","0.63553"
"42790","256.70400","35.82140","0.63987"
"42846","257.04000","35.84938","0.64380"
"42902","257.37600","35.87748","0.64534"
"42958","257.71200","35.90547","0.64684"
"43014","258.04800","35.93345","0.64827"
"43070","258.38400","35.96149","0.64967"
"43126","258.72000","35.98941","0.65032"
"43182","259.05600","36.01746","0.65110"
"43238","259.39200","36.04549","0.65199"
"43294","259.72800","36.07342","0.65292"
"43350","260.06400","36.10146","0.65453"
"43406","260.40000","36.12944","0.65610"
"43462","260.73600","36.15742","0.65729"
"43518","261.07200","36.18540","0.66014"
"43574","261.40800","36.21344","0.66254"
"43630","261.74400","36.24143","0.66648"
"43686","262.08000","36.26953","0.66890"
"43742","262.41600","36.29739","0.66899"
"43798","262.75200","36.32543","0.67119"
"43854","263.08800","36.35353","0.67472"
"43910","263.42400","36.38139","0.67801"
"43966","263.76000","36.40944","0.68120"
"44022","264.09600","36.43742","0.67909"
"44078","264.43200","36.46546","0.67910"
"44134","264.76800","36.49344","0.67687"
"44190","265.10400","36.52136","0.68153"
"44246","265.44000","36.54946","0.68373"
"44302","265.77600","36.57744","0.69062"
"44358","266.11200","36.60543","0.69912"
"44414","266.44800","36.63346","0.70534"
"44470","266.78400","36.66138","0.70912"
"44526","267.12000","36.68949","0.71014"
"44582","267.45600","36.71747","0.71112"
"44638","267.79200","36.74539","0.71288"
"44694","268.12800","36.77343","0.71655"
"44750","268.46400","36.80141","-0.01555"
"44806","268.80000","36.82940","0.02515"
"44862","269.13600","36.85744","0.00933"
"44918","269.47200","36.88548","0.02240"
"44974","269.80800","36.91346","0.01366"
"45030","270.14400","36.94150","0.01565"
"45086","270.48000","36.96936","0.00945"
"45142","270.81600","36.99746","0.02024"
"45198","271.15200","37.02544","0.01188"
"45254","271.48800","37.05343","0.01875"
"45310","271.82400","37.08147","0.01419"
"45366","272.16000","37.10945","0.01567"
"45422","272.49600","37.13743","0.01587"
"45478","272.83200","37.16547","0.01301"
"45534","273.16800","37.19339","0.01851"
"45590","273.50400","37.22144","0.01546"
"45646","273.84000","37.24948","0.01421"
"45702","274.17600","37.27740","0.01784"
"45758","274.51200","37.30538","0.01538"
"45814","274.84800","37.33342","0.01508"
"45870","275.18400","37.36146","0.01822"
"45926","275.52000","37.38945","0.01570"
"45982","275.85600","37.41743","0.01550"
"46038","276.19200","37.44547","0.01832"
"46094","276.52800","37.47345","0.01718"
"46150","276.86400","37.50143","0.01631"
"46206","277.20000","37.52947","0.01810"
"46262","277.53600","37.55739","0.01668"
"46318","277.87200","37.58549","0.01648"
"46374","278.20800","37.61348","0.01831"
"46430","278.54400","37.64140","0.01803"
"46486","278.88000","37.66944","0.01761"
"46542","279.21600","37.69742","0.01867"
"46598","279.55200","37.72540","0.01776"
"46654","279.88800","37.75350","0.01784"
"46710","280.22400","37.78136","0.01866"
"46766","280.56000","37.80941","0.01778"
"46822","280.89600","37.83744","0.01782"
"46878","281.23200","37.86537","0.01901"
"46934","281.56800","37.89347","0.01917"
"46990","281.90400","37.92139","0.01925"
"47046","282.24000","37.94943","0.01942"
"47102","282.57600","37.97747","0.01881"
"47158","282.91200","38.00546","0.01973"
"47214","283.24800","38.03344","0.01918"
"47270","283.58400","38.06148","0.01946"
"47326","283.92000","38.08940","0.02002"
"47382","284.25600","38.11744","0.01982"
"47438","284.59200","38.14548","0.02017"
"47494","284.92800","38.17346","0.02093"
"47550","285.26400","38.20145","0.01991"
"47606","285.60000","38.22943","0.02108"
"47662","285.93600","38.25747","0.02226"
"47718","286.27200","38.28545","0.02172"
"47774","286.60800","38.31337","0.02305"
"47830","286.94400","38.34142","0.02268"
"47886","287.28000","38.36945","0.02312"
"47942","287.61600","38.39743","0.02311"
"47998","287.95200","38.42548","0.02282"
"48054","288.28800","38.45340","0.02383"
"48110","288.62400","38.48144","0.02358"
"48166","288.96000","38.50948","0.02407"
"48222","289.29600","38.53741","0.02412"
"48278","289.63200","38.56551","0.02405"
"48334","289.96800","38.59343","0.02420"
"48390","290.30400","38.62141","0.02477"
"48446","290.64000","38.64951","0.02437"
"48502","290.97600","38.67743","0.02478"
"48558","291.31200","38.70547","0.02453"
"48614","291.64800","38.73351","0.02563"
"48670","291.98400","38.76138","0.02590"
"48726","292.32000","38.78942","0.02581"
"48782","292.65600","38.81746","0.02554"
"48838","292.99200","38.84544","0.02557"
"48894","293.32800","38.87342","0.02673"
"48950","293.66400","38.90141","0.02689"
"49006","294.00000","38.92944","0.02723"
"49062","294.33600","38.95749","0.02650"
"49118","294.67200","38.98547","0.02760"
"49174","295.00800","39.01345","0.02789"
"49230","295.34400","39.04143","0.02783"
"49286","295.68000","39.06941","0.02865"
"49342","296.01600","39.09745","0.02842"
"49398","296.35200","39.12537","0.02904"
"49454","296.68800","39.15348","0.02918"
"49510","297.02400","39.18151","0.02881"
"49566","297.36000","39.20937","0.02985"
"49622","297.69600","39.23748","0.03034"
"49678","298.03200","39.26540","0.03059"
"49734","298.36800","39.29344","0.03035"
"49790","298.70400","39.32142","0.03109"
"49846","299.04000","39.34935","0.03077"
"49902","299.37600","39.37751","0.03184"
"49958","299.71200","39.40549","0.03223"
"50014","300.04800","39.43341","0.03213"
"50070","300.38400","39.46145","0.03264"
"50126","300.72000","39.48943","0.03291"
"50182","301.05600","39.51741","0.03325"
"50238","301.39200","39.54539","0.03302"
"50294","301.72800","39.57338","0.03426"
"50350","302.06400","39.60142","0.03451"
"50406","302.40000","39.62952","0.03493"
"50462","302.73600","39.65744","0.03529"
"50518","303.07200","39.68542","0.03510"
"50574","303.40800","39.71346","0.03531"
"50630","303.74400","39.74144","0.03579"
"50686","304.08000","39.76942","0.03649"
"50742","304.41600","39.79741","0.03615"
"50798","304.75200","39.82545","0.03682"
"50854","305.08800","39.85349","0.03651"
"50910","305.42400","39.88141","0.03685"
"50966","305.76000","39.90945","0.03709"
"51022","306.09600","39.93738","0.03703"
"51078","306.43200","39.96542","0.03732"
"51134","306.76800","39.99345","0.03787"
"51190","307.10400","40.02137","0.03792"
"51246","307.44000","40.04948","0.03805"
"51302","307.77600","40.07746","0.03820"
"51358","308.11200","40.10544","0.03822"
"51414","308.44800","40.13348","0.03830"
"51470","308.78400","40.16141","0.03876"
"51526","309.12000","40.18945","0.03903"
"51582","309.45600","40.21749","0.03912"
"51638","309.79200","40.24535","0.03915"
"51694","310.12800","40.27345","0.03964"
"51750","310.46400","40.30143","0.03994"
"51806","310.80000","40.32941","0.03989"
"51862","311.13600","40.35740","0.04007"
"51918","311.47200","40.38544","0.04015"
"51974","311.80800","40.41336","0.04036"
"52030","312.14400","40.44146","0.04075"
"52086","312.48000","40.46938","0.04087"
"52142","312.81600","40.49749","0.04112"
"52198","313.15200","40.52546","0.04107"
"52254","313.48800","40.55344","0.04127"
"52310","313.82400","40.58143","0.04160"
"52366","314.16000","40.60941","0.04188"
"52422","314.49600","40.63745","0.04192"
"52478","314.83200","40.66543","0.04211"
"52534","315.16800","40.69347","0.04228"
"52590","315.50400","40.72145","0.04287"
"52646","315.84000","40.74944","0.04269"
"52702","316.17600","40.77742","0.04275"
"52758","316.51200","40.80545","0.04320"
"52814","316.84800","40.83344","0.04352"
"52870","317.18400","40.86142","0.04375"
"52926","317.52000","40.88940","0.04392"
"52982","317.85600","40.91732","0.04432"
"53038","318.19200","40.94543","0.04495"
"53094","318.52800","40.97346","0.04518"
"53150","318.86400","41.00139","0.04503"
"53206","319.20000","41.02949","0.04587"
"53262","319.53600","41.05741","0.04631"
"53318","319.87200","41.08539","0.04692"
"53374","320.20800","41.11349","0.04753"
"53430","320.54400","41.14142","0.04788"
"53486","320.88000","41.16945","0.04853"
"53542","321.21600","41.19750","0.04899"
"53598","321.55200","41.22542","0.04982"
"53654","321.88800","41.25346","0.05049"
"53710","322.22400","41.28138","0.05086"
"53766","322.56000","41.30943","0.05156"
"53822","322.89600","41.33746","0.05210"
"53878","323.23200","41.36539","0.05205"
"53934","323.56800","41.39343","0.05303"
"53990","323.90400","41.42147","0.05403"
"54046","324.24000","41.44939","0.05488"
"54102","324.57600","41.47749","0.05501"
"54158","324.91200","41.50542","0.05623"
"54214","325.24800","41.53345","0.05665"
"54270","325.58400","41.56144","0.05549"
"54326","325.92000","41.58942","0.05613"
"54382","326.25600","41.61746","0.05691"
"54438","326.59200","41.64545","0.05758"
"54494","326.92800","41.67348","0.05860"
"54550","327.26400","41.70146","0.05874"
"54606","327.60000","41.72944","0.05898"
"54662","327.93600","41.75749","0.05991"
"54718","328.27200","41.78547","0.06047"
"54774","328.60800","41.81339","0.06153"
"54830","328.94400","41.84149","0.06179"
"54886","329.28000","41.86947","0.06297"
"54942","329.61600","41.89745","0.06279"
"54998","329.95200","41.92544","0.06357"
"55054","330.28800","41.95342","0.06360"
"55110","330.62400","41.98140","0.06374"
"55166","330.96000","42.00950","0.06471"
"55222","331.29600","42.03736","0.06551"
"55278","331.63200","42.06540","0.06602"
"55334","331.96800","42.09351","0.06650"
"55390","332.30400","42.12143","0.06656"
"55446","332.64000","42.14946","0.06747"
"55502","332.97600","42.17744","0.04331"
"55558","333.31200","42.20543","0.04368"
"55614","333.64800","42.23347","0.04351"
"55670","333.98400","42.26145","0.04462"
"55726","334.32000","42.28944","0.04660"
"55782","334.65600","42.31747","0.04749"
"55838","334.99200","42.34540","0.04758"
"55894","335.32800","42.37344","0.04861"
"55950","335.66400","42.40142","0.05139"
"56006","336.00000","42.42946","0.05163"
"56062","336.33600","42.45745","0.05287"
"56118","336.67200","42.48537","0.05417"
"56174","337.00800","42.51346","0.05612"
"56230","337.34400","42.54151","0.05703"
"56286","337.68000","42.56943","0.05730"
"56342","338.01600","42.59747","0.05744"
"56398","338.35200","42.62539","0.05947"
"56454","338.68800","42.65349","0.06006"
"56510","339.02400","42.68154","0.06075"
"56566","339.36000","42.70934","0.06150"
"56622","339.69600","42.73750","0.06240"
"56678","340.03200","42.76548","0.06366"
"56734","340.36800","42.79340","0.06414"
"56790","340.70400","42.82150","0.06468"
"56846","341.04000","42.84937","0.06547"
"56902","341.37600","42.87746","0.06620"
"56958","341.71200","42.90545","0.06132"
"57014","342.04800","42.93337","0.06211"
"57070","342.38400","42.96147","0.06285"
"57126","342.72000","42.98945","0.06360"
"57182","343.05600","43.01744","0.06479"
"57238","343.39200","43.04542","0.06509"
"57294","343.72800","43.07345","0.06605"
"57350","344.06400","43.10144","0.06571"
"57406","344.40000","43.12942","0.06618"
"57462","344.73600","43.15740","0.06654"
"57518","345.07200","43.18544","0.06691"
"57574","345.40800","43.21342","0.06759"
"57630","345.74400","43.24146","0.06814"
"57686","346.08000","43.26945","0.06829"
"57742","346.41600","43.29737","0.06905"
"57798","346.75200","43.32547","0.06954"
"57854","347.08800","43.35345","0.07045"
"57910","347.42400","43.38137","0.07033"
"57966","347.76000","43.40947","0.07097"
"58022","348.09600","43.43745","0.07131"
"58078","348.43200","43.46538","0.07173"
"58134","348.76800","43.49348","0.07160"
"58190","349.10400","43.52140","0.07217"
"58246","349.44000","43.54944","0.07255"
"58302","349.77600","43.57748","0.07276"
"58358","350.11200","43.60540","0.07166"
"58414","350.44800","43.63345","0.07205"
"58470","350.78400","43.66149","0.07278"
"58526","351.12000","43.68941","0.07334"
"58582","351.45600","43.71745","0.07438"
"58638","351.79200","43.74543","0.07441"
"58694","352.12800","43.77347","0.07528"
"58750","352.46400","43.80145","0.07571"
"58806","352.80000","43.82944","0.07678"
"58862","353.13600","43.85742","0.07764"
"58918","353.47200","43.88546","0.07783"
"58974","353.80800","43.91344","0.07517"
"59030","354.14400","43.94148","0.07668"
"59086","354.48000","43.96940","0.07792"
"59142","354.81600","43.99744","0.07832"
"59198","355.15200","44.02549","0.07930"
"59254","355.48800","44.05341","0.08014"
"59310","355.82400","44.08151","0.08076"
"59366","356.16000","44.10943","0.08143"
"59422","356.49600","44.13741","0.08193"
"59478","356.83200","44.16545","0.08287"
"59534","357.16800","44.19337","0.08345"
"59590","357.50400","44.22147","0.08424"
"59646","357.84000","44.24952","0.08449"
"59702","358.17600","44.27744","0.08539"
"59758","358.51200","44.30548","0.08564"
"59814","358.84800","44.33340","0.08570"
"59870","359.18400","44.36138","0.08662"
"59926","359.52000","44.38948","0.08702"
"59982","359.85600","44.41740","0.08775"
"60038","360.19200","44.44545","0.08790"
"60094","360.52800","44.47343","0.08846"
"60150","360.86400","44.50135","0.08878"
"60206","361.20000","44.52945","0.08919"
"60262","361.53600","44.55743","0.08967"
"60318","361.87200","44.58541","0.08996"
"60374","362.20800","44.61345","0.09007"
"60430","362.54400","44.64144","0.09034"
"60486","362.88000","44.66942","0.09045"
"60542","363.21600","44.69746","0.09078"
"60598","363.55200","44.72544","0.09120"
"60654","363.88800","44.75343","0.09129"
"60710","364.22400","44.78146","0.09076"
"60766","364.56000","44.80944","0.09070"
"60822","364.89600","44.83743","0.09106"
"60878","365.23200","44.86541","0.09120"
"60934","365.56800","44.89345","0.09158"
"60990","365.90400","44.92149","0.09192"
"61046","366.24000","44.94941","0.09240"
"61102","366.57600","44.97746","0.09156"
"61158","366.91200","45.00538","0.08978"
"61214","367.24800","45.03342","0.09062"
"61270","367.58400","45.06145","0.09085"
"61326","367.92000","45.08938","0.09149"
"61382","368.25600","45.11748","0.09139"
"61438","368.59200","45.14546","0.09188"
"61494","368.92800","45.17344","0.09219"
"61550","369.26400","45.20148","0.09289"
"61606","369.60000","45.22940","0.09324"
"61662","369.93600","45.25745","0.09394"
"61718","370.27200","45.28549","0.09435"
"61774","370.60800","45.31347","0.09547"
"61830","370.94400","45.34145","0.09518"
"61886","371.28000","45.36950","0.09590"
"61942","371.61600","45.39742","0.09712"
"61998","371.95200","45.42545","0.09799"
"62054","372.28800","45.45344","0.09876"
"62110","372.62400","45.48142","0.09955"
"62166","372.96000","45.50946","0.10071"
"62222","373.29600","45.53738","0.10236"
"62278","373.63200","45.56548","0.10288"
"62334","373.96800","45.59346","0.10411"
"62390","374.30400","45.62145","0.10555"
"62446","374.64000","45.64949","0.10657"
"62502","374.97600","45.67741","0.10863"
"62558","375.31200","45.70545","0.10865"
"62614","375.64800","45.73343","0.10925"
"62670","375.98400","45.76135","0.11101"
"62726","376.32000","45.78946","0.11163"
"62782","376.65600","45.81744","0.11276"
"62838","376.99200","45.84542","0.11348"
"62894","377.32800","45.87346","0.11427"
"62950","377.66400","45.90144","0.11507"
"63006","378.00000","45.92942","0.11653"
"63062","378.33600","45.95752","0.11761"
"63118","378.67200","45.98545","0.11773"
"63174","379.00800","46.01348","0.11910"
"63230","379.34400","46.04147","0.12035"
"63286","379.68000","46.06939","0.12074"
"63342","380.01600","46.09749","0.12117"
"63398","380.35200","46.12547","0.12159"
"63454","380.68800","46.15340","0.12229"
"63510","381.02400","46.18144","0.12305"
"63566","381.36000","46.20942","0.12369"
"63622","381.69600","46.23746","0.12424"
"63678","382.03200","46.26556","0.12517"
"63734","382.36800","46.29336","0.12582"
"63790","382.70400","46.32146","0.12617"
"63846","383.04000","46.34945","0.12683"
"63902","383.37600","46.37743","0.12780"
"63958","383.71200","46.40546","0.12779"
"64014","384.04800","46.43339","0.12831"
"64070","384.38400","46.46143","0.12864"
"64126","384.72000","46.48941","0.12941"
"64182","385.05600","46.51740","0.12966"
"64238","385.39200","46.54543","0.12991"
"64294","385.72800","46.57341","0.13046"
"64350","386.06400","46.60146","0.13099"
"64406","386.40000","46.62944","0.13183"
"64462","386.73600","46.65736","0.13223"
"64518","387.07200","46.68546","0.13261"
"64574","387.40800","46.71344","0.13322"
"64630","387.74400","46.74142","0.13334"
"64686","388.08000","46.76946","0.13403"
"64742","388.41600","46.79745","0.13431"
"64798","388.75200","46.82543","0.13490"
"64854","389.08800","46.85347","0.13510"
"64910","389.42400","46.88139","0.13572"
"64966","389.76000","46.90949","0.13557"
"65022","390.09600","46.93747","0.13600"
"65078","390.43200","46.96546","0.13636"
"65134","390.76800","46.99344","0.13685"
"65190","391.10400","47.02147","0.13684"
"65246","391.44000","47.04946","0.13769"
"65302","391.77600","47.07750","0.13789"
"65358","392.11200","47.10537","0.13826"
"65414","392.44800","47.13340","0.13833"
"65470","392.78400","47.16145","0.13860"
"65526","393.12000","47.18937","0.13881"
"65582","393.45600","47.21746","0.13925"
"65638","393.79200","47.24545","0.13972"
"65694","394.12800","47.27343","0.13981"
"65750","394.46400","47.30147","0.13991"
"65806","394.80000","47.32940","0.13984"
"65862","395.13600","47.35749","0.14030"
"65918","395.47200","47.38542","0.14080"
"65974","395.80800","47.41346","0.14138"
"66030","396.14400","47.44144","0.14136"
"66086","396.48000","47.46936","0.14206"
"66142","396.81600","47.49747","0.14234"
"66198","397.15200","47.52550","0.14285"
"66254","397.48800","47.55337","0.14293"
"66310","397.82400","47.58146","0.14299"
"66366","398.16000","47.60945","0.14289"
"66422","398.49600","47.63743","0.14340"
"66478","398.83200","47.66547","0.14369"
"66534","399.16800","47.69345","0.14425"
"66590","399.50400","47.72144","0.14504"
"66646","399.84000","47.74947","0.14443"
"66702","400.17600","47.77740","0.14566"
"66758","400.51200","47.80544","0.14630"
"66814","400.84800","47.83348","0.14667"
"66870","401.18400","47.86140","0.14710"
"66926","401.52000","47.88945","0.14752"
"66982","401.85600","47.91742","0.14821"
"67038","402.19200","47.94540","0.14947"
"67094","402.52800","47.97345","0.14960"
"67150","402.86400","48.00143","0.15073"
"67206","403.20000","48.02947","0.15032"
"67262","403.53600","48.05745","0.15075"
"67318","403.87200","48.08543","0.15102"
"67374","404.20800","48.11341","0.15062"
"67430","404.54400","48.14140","0.15066"
"67486","404.88000","48.16944","0.15276"
"67542","405.21600","48.19748","0.15487"
"67598","405.55200","48.22540","0.15484"
"67654","405.88800","48.25344","0.15616"
"67710","406.22400","48.28142","0.15599"
"67766","406.56000","48.30941","0.15715"
"67822","406.89600","48.33745","0.15932"
"67878","407.23200","48.36543","0.16159"
"67934","407.56800","48.39347","0.16290"
"67990","407.90400","48.42151","0.16401"
"68046","408.24000","48.44938","0.16641"
"68102","408.57600","48.47747","0.16821"
"68158","408.91200","48.50546","0.01606"
"68214","409.24800","48.53337","0.01374"
"68270","409.58400","48.56148","0.01421"
"68326","409.92000","48.58940","0.01952"
"68382","410.25600","48.61738","0.00991"
"68438","410.59200","48.64548","0.01080"
"68494","410.92800","48.67340","0.01672"
"68550","411.26400","48.70150","0.01067"
"68606","411.60000","48.72942","0.01064"
"68662","411.93600","48.75740","0.01278"
"68718","412.27200","48.78539","0.00990"
"68758","412.50800","48.80506","0.01063"