File: Trajectories_together/170212_2Specimen_RawData_3.csv
"","V1","V2","V3"
"1","End date","2/12/2017",""
"2","Specimen label","9CG_75_run2",""
"3","Maximum Load","0.46556","N"
"4","Time","Extension","Load"
"5","(s)","(mm)","(N)"
"6","0.00000","9.99394","0.02982"
"50","0.26400","10.01493","0.03022"
"94","0.52800","10.03818","0.03051"
"138","0.79200","10.06025","0.02966"
"182","1.05600","10.08213","0.02987"
"226","1.32000","10.10419","0.03063"
"270","1.58400","10.12607","0.03080"
"314","1.84800","10.14820","0.03037"
"358","2.11200","10.17014","0.03042"
"402","2.37600","10.19220","0.03071"
"446","2.64000","10.21415","0.03067"
"490","2.90400","10.23615","0.03086"
"534","3.16800","10.25809","0.03107"
"578","3.43200","10.28015","0.03093"
"622","3.69600","10.30216","0.03099"
"666","3.96000","10.32416","0.03096"
"710","4.22400","10.34616","0.03148"
"754","4.48800","10.36816","0.03152"
"798","4.75200","10.39011","0.03072"
"842","5.01600","10.41217","0.03089"
"886","5.28000","10.43417","0.03151"
"930","5.54400","10.45617","0.03129"
"974","5.80800","10.47818","0.03122"
"1018","6.07200","10.50012","0.03147"
"1062","6.33600","10.52212","0.03133"
"1106","6.60000","10.54412","0.03113"
"1150","6.86400","10.56613","0.03089"
"1194","7.12800","10.58813","0.03092"
"1238","7.39200","10.61019","0.03125"
"1282","7.65600","10.63207","0.03120"
"1326","7.92000","10.65414","0.03087"
"1370","8.18400","10.67614","0.03199"
"1414","8.44800","10.69820","0.03175"
"1458","8.71200","10.72014","0.03171"
"1502","8.97600","10.74215","0.03216"
"1546","9.24000","10.76409","0.03188"
"1590","9.50400","10.78609","0.03247"
"1634","9.76800","10.80809","0.03165"
"1678","10.03200","10.83016","0.03152"
"1722","10.29600","10.85216","0.03232"
"1766","10.56000","10.87416","0.03237"
"1810","10.82400","10.89610","0.03233"
"1854","11.08800","10.91811","0.03192"
"1898","11.35200","10.94005","0.03256"
"1942","11.61600","10.96217","0.03291"
"1986","11.88000","10.98411","0.03257"
"2030","12.14400","11.00612","0.03272"
"2074","12.40800","11.02806","0.03267"
"2118","12.67200","11.05018","0.03244"
"2162","12.93600","11.07213","0.03302"
"2206","13.20000","11.09413","0.03286"
"2250","13.46400","11.11607","0.03287"
"2294","13.72800","11.13819","0.03291"
"2338","13.99200","11.16014","0.03263"
"2382","14.25600","11.18220","0.03322"
"2426","14.52000","11.20414","0.03291"
"2470","14.78400","11.22620","0.03364"
"2514","15.04800","11.24815","0.03348"
"2558","15.31200","11.27021","0.03280"
"2602","15.57600","11.29209","0.03345"
"2646","15.84000","11.31415","0.03383"
"2690","16.10400","11.33615","0.03340"
"2734","16.36800","11.35816","0.03403"
"2778","16.63200","11.38016","0.03433"
"2822","16.89600","11.40216","0.03381"
"2866","17.16000","11.42417","0.03424"
"2910","17.42400","11.44617","0.03430"
"2954","17.68800","11.46811","0.03342"
"2998","17.95200","11.49011","0.03395"
"3042","18.21600","11.51212","0.03369"
"3086","18.48000","11.53412","0.03435"
"3130","18.74400","11.55618","0.03482"
"3174","19.00800","11.57818","0.03531"
"3218","19.27200","11.60013","0.03510"
"3262","19.53600","11.62213","0.03510"
"3306","19.80000","11.64419","0.03562"
"3350","20.06400","11.66613","0.03550"
"3394","20.32800","11.68814","0.03521"
"3438","20.59200","11.71014","0.03571"
"3482","20.85600","11.73214","0.03498"
"3526","21.12000","11.75408","0.03530"
"3570","21.38400","11.77615","0.03518"
"3614","21.64800","11.79815","0.03568"
"3658","21.91200","11.82015","0.03600"
"3702","22.17600","11.84215","0.03574"
"3746","22.44000","11.86416","0.03575"
"3790","22.70400","11.88604","0.03639"
"3834","22.96800","11.90810","0.03593"
"3878","23.23200","11.93005","0.03621"
"3922","23.49600","11.95217","0.03532"
"3966","23.76000","11.97411","0.03627"
"4010","24.02400","11.99617","0.03587"
"4054","24.28800","12.01811","0.03640"
"4098","24.55200","12.04018","0.03665"
"4142","24.81600","12.06206","0.03659"
"4186","25.08000","12.08418","0.03612"
"4230","25.34400","12.10612","0.03614"
"4274","25.60800","12.12813","0.03830"
"4318","25.87200","12.15007","0.03777"
"4362","26.13600","12.17213","0.03864"
"4406","26.40000","12.19408","0.03721"
"4450","26.66400","12.21614","0.03728"
"4494","26.92800","12.23814","0.03733"
"4538","27.19200","12.26014","0.03746"
"4582","27.45600","12.28215","0.03621"
"4626","27.72000","12.30421","0.03699"
"4670","27.98400","12.32615","0.03683"
"4714","28.24800","12.34815","0.03860"
"4758","28.51200","12.37016","0.03971"
"4802","28.77600","12.39222","0.03756"
"4846","29.04000","12.41410","0.03889"
"4890","29.30400","12.43616","0.03804"
"4934","29.56800","12.45811","0.03852"
"4978","29.83200","12.48017","0.03835"
"5022","30.09600","12.50217","0.03907"
"5066","30.36000","12.52417","0.03915"
"5110","30.62400","12.54612","0.03906"
"5154","30.88800","12.56818","0.03905"
"5198","31.15200","12.59006","0.03903"
"5242","31.41600","12.61212","0.03951"
"5286","31.68000","12.63413","0.03879"
"5330","31.94400","12.65619","0.03950"
"5374","32.20800","12.67813","0.03877"
"5418","32.47200","12.70007","0.03943"
"5462","32.73600","12.72208","0.03940"
"5506","33.00000","12.74414","0.03953"
"5550","33.26400","12.76614","0.03932"
"5594","33.52800","12.78814","0.03917"
"5638","33.79200","12.81015","0.03958"
"5682","34.05600","12.83215","0.03966"
"5726","34.32000","12.85415","0.03995"
"5770","34.58400","12.87609","0.04017"
"5814","34.84800","12.89816","0.03981"
"5858","35.11200","12.92016","0.03999"
"5902","35.37600","12.94216","0.04021"
"5946","35.64000","12.96410","0.04009"
"5990","35.90400","12.98611","0.04044"
"6034","36.16800","13.00811","0.04029"
"6078","36.43200","13.03011","0.04016"
"6122","36.69600","13.05211","0.04004"
"6166","36.96000","13.07412","0.04080"
"6210","37.22400","13.09612","0.04104"
"6254","37.48800","13.11812","0.04120"
"6298","37.75200","13.14012","0.04104"
"6342","38.01600","13.16213","0.04110"
"6386","38.28000","13.18413","0.04100"
"6430","38.54400","13.20619","0.04142"
"6474","38.80800","13.22808","0.04152"
"6518","39.07200","13.25014","0.04184"
"6562","39.33600","13.27208","0.04185"
"6606","39.60000","13.29414","0.04161"
"6650","39.86400","13.31609","0.04120"
"6694","40.12800","13.33821","0.04168"
"6738","40.39200","13.36009","0.04178"
"6782","40.65600","13.38215","0.04218"
"6826","40.92000","13.40415","0.04210"
"6870","41.18400","13.42616","0.04232"
"6914","41.44800","13.44810","0.04254"
"6958","41.71200","13.47016","0.04237"
"7002","41.97600","13.49217","0.04290"
"7046","42.24000","13.51417","0.04250"
"7090","42.50400","13.53611","0.04280"
"7134","42.76800","13.55811","0.04319"
"7178","43.03200","13.58012","0.04335"
"7222","43.29600","13.60212","0.04373"
"7266","43.56000","13.62412","0.04305"
"7310","43.82400","13.64618","0.04345"
"7354","44.08800","13.66813","0.04406"
"7398","44.35200","13.69019","0.04375"
"7442","44.61600","13.71213","0.04444"
"7486","44.88000","13.73413","0.04461"
"7530","45.14400","13.75620","0.04411"
"7574","45.40800","13.77820","0.04444"
"7618","45.67200","13.80008","0.04451"
"7662","45.93600","13.82208","0.04446"
"7706","46.20000","13.84409","0.04488"
"7750","46.46400","13.86615","0.04510"
"7794","46.72800","13.88821","0.04497"
"7838","46.99200","13.91022","0.04472"
"7882","47.25600","13.93216","0.04520"
"7926","47.52000","13.95416","0.04479"
"7970","47.78400","13.97610","0.04543"
"8014","48.04800","13.99817","0.04504"
"8058","48.31200","14.02017","0.04519"
"8102","48.57600","14.04211","0.04557"
"8146","48.84000","14.06411","0.04560"
"8190","49.10400","14.08611","0.04613"
"8234","49.36800","14.10812","0.04668"
"8278","49.63200","14.13012","0.04597"
"8322","49.89600","14.15218","0.04640"
"8366","50.16000","14.17412","0.04702"
"8410","50.42400","14.19619","0.04637"
"8454","50.68800","14.21807","0.04705"
"8498","50.95200","14.24019","0.04719"
"8542","51.21600","14.26214","0.04732"
"8586","51.48000","14.28420","0.04786"
"8630","51.74400","14.30614","0.04816"
"8674","52.00800","14.32814","0.04818"
"8718","52.27200","14.35009","0.04799"
"8762","52.53600","14.37215","0.04834"
"8806","52.80000","14.39409","0.04827"
"8850","53.06400","14.41615","0.04917"
"8894","53.32800","14.43816","0.04917"
"8938","53.59200","14.46022","0.04860"
"8982","53.85600","14.48210","0.05038"
"9026","54.12000","14.50410","0.04997"
"9070","54.38400","14.52611","0.05084"
"9114","54.64800","14.54817","0.05036"
"9158","54.91200","14.57017","0.05059"
"9202","55.17600","14.59217","0.05059"
"9246","55.44000","14.61412","0.05057"
"9290","55.70400","14.63612","0.05196"
"9334","55.96800","14.65812","0.05085"
"9378","56.23200","14.68018","0.05182"
"9422","56.49600","14.70213","0.05233"
"9466","56.76000","14.72419","0.05243"
"9510","57.02400","14.74613","0.05198"
"9554","57.28800","14.76814","0.05199"
"9598","57.55200","14.79014","0.05293"
"9642","57.81600","14.81220","0.05324"
"9686","58.08000","14.83414","0.05285"
"9730","58.34400","14.85620","0.05356"
"9774","58.60800","14.87809","0.05358"
"9818","58.87200","14.90015","0.05363"
"9862","59.13600","14.92209","0.05354"
"9906","59.40000","14.94416","0.05451"
"9950","59.66400","14.96616","0.05455"
"9994","59.92800","14.98816","0.05496"
"10038","60.19200","15.01016","0.05435"
"10082","60.45600","15.03217","0.05407"
"10126","60.72000","15.05417","0.05464"
"10170","60.98400","15.07617","0.05514"
"10214","61.24800","15.09817","0.05568"
"10258","61.51200","15.12012","0.05555"
"10302","61.77600","15.14212","0.05564"
"10346","62.04000","15.16412","0.05625"
"10390","62.30400","15.18612","0.05649"
"10434","62.56800","15.20813","0.05712"
"10478","62.83200","15.23013","0.05705"
"10522","63.09600","15.25213","0.05672"
"10566","63.36000","15.27419","0.05773"
"10610","63.62400","15.29614","0.05768"
"10654","63.88800","15.31814","0.05779"
"10698","64.15200","15.34014","0.05813"
"10742","64.41600","15.36220","0.05856"
"10786","64.68000","15.38415","0.05842"
"10830","64.94400","15.40615","0.05822"
"10874","65.20800","15.42809","0.05883"
"10918","65.47200","15.45015","0.05920"
"10962","65.73600","15.47210","0.05913"
"11006","66.00000","15.49416","0.05970"
"11050","66.26400","15.51604","0.05952"
"11094","66.52800","15.53816","0.05961"
"11138","66.79200","15.56011","0.05963"
"11182","67.05600","15.58217","0.06075"
"11226","67.32000","15.60405","0.06043"
"11270","67.58400","15.62617","0.06034"
"11314","67.84800","15.64812","0.06103"
"11358","68.11200","15.67018","0.06139"
"11402","68.37600","15.69212","0.06122"
"11446","68.64000","15.71412","0.06200"
"11490","68.90400","15.73613","0.06122"
"11534","69.16800","15.75813","0.06219"
"11578","69.43200","15.78007","0.06176"
"11622","69.69600","15.80213","0.06196"
"11666","69.96000","15.82414","0.06271"
"11710","70.22400","15.84614","0.06270"
"11754","70.48800","15.86808","0.06287"
"11798","70.75200","15.89014","0.06307"
"11842","71.01600","15.91215","0.06295"
"11886","71.28000","15.93421","0.06318"
"11930","71.54400","15.95609","0.06351"
"11974","71.80800","15.97815","0.06348"
"12018","72.07200","16.00010","0.06382"
"12062","72.33600","16.02216","0.06399"
"12106","72.60000","16.04410","0.06419"
"12150","72.86400","16.06616","0.06407"
"12194","73.12800","16.08817","0.06501"
"12238","73.39200","16.11017","0.06452"
"12282","73.65600","16.13211","0.06493"
"12326","73.92000","16.15411","0.06467"
"12370","74.18400","16.17612","0.06523"
"12414","74.44800","16.19818","0.06530"
"12458","74.71200","16.22018","0.06508"
"12502","74.97600","16.24219","0.06584"
"12546","75.24000","16.26413","0.06588"
"12590","75.50400","16.28613","0.06578"
"12634","75.76800","16.30813","0.06611"
"12678","76.03200","16.33014","0.06650"
"12722","76.29600","16.35214","0.06636"
"12766","76.56000","16.37414","0.06656"
"12810","76.82400","16.39614","0.06639"
"12854","77.08800","16.41815","0.06662"
"12898","77.35200","16.44021","0.06685"
"12942","77.61600","16.46215","0.06713"
"12986","77.88000","16.48421","0.06716"
"13030","78.14400","16.50616","0.06740"
"13074","78.40800","16.52816","0.06763"
"13118","78.67200","16.55010","0.06772"
"13162","78.93600","16.57210","0.06823"
"13206","79.20000","16.59411","0.06797"
"13250","79.46400","16.61617","0.06789"
"13294","79.72800","16.63811","0.06806"
"13338","79.99200","16.66011","0.06830"
"13382","80.25600","16.68206","0.06844"
"13426","80.52000","16.70418","0.06872"
"13470","80.78400","16.72612","0.06900"
"13514","81.04800","16.74813","0.06928"
"13558","81.31200","16.77007","0.06983"
"13602","81.57600","16.79219","0.06967"
"13646","81.84000","16.81407","0.06983"
"13690","82.10400","16.83613","0.07004"
"13734","82.36800","16.85808","0.07014"
"13778","82.63200","16.88014","0.07050"
"13822","82.89600","16.90214","0.07054"
"13866","83.16000","16.92420","0.07075"
"13910","83.42400","16.94609","0.07083"
"13954","83.68800","16.96815","0.07116"
"13998","83.95200","16.99015","0.07134"
"14042","84.21600","17.01216","0.07152"
"14086","84.48000","17.03410","0.07188"
"14130","84.74400","17.05616","0.07130"
"14174","85.00800","17.07810","0.07185"
"14218","85.27200","17.10016","0.07196"
"14262","85.53600","17.12211","0.07220"
"14306","85.80000","17.14411","0.07244"
"14350","86.06400","17.16611","0.07223"
"14394","86.32800","17.18818","0.07301"
"14438","86.59200","17.21012","0.07315"
"14482","86.85600","17.23218","0.07367"
"14526","87.12000","17.25412","0.07399"
"14570","87.38400","17.27612","0.07432"
"14614","87.64800","17.29813","0.07474"
"14658","87.91200","17.32019","0.07506"
"14702","88.17600","17.34213","0.07560"
"14746","88.44000","17.36414","0.07594"
"14790","88.70400","17.38614","0.07596"
"14834","88.96800","17.40814","0.07681"
"14878","89.23200","17.43008","0.07687"
"14922","89.49600","17.45215","0.07740"
"14966","89.76000","17.47421","0.07793"
"15010","90.02400","17.49615","0.07852"
"15054","90.28800","17.51815","0.07838"
"15098","90.55200","17.54016","0.07920"
"15142","90.81600","17.56216","0.07989"
"15186","91.08000","17.58416","0.08037"
"15230","91.34400","17.60622","0.08127"
"15274","91.60800","17.62811","0.08139"
"15318","91.87200","17.65017","0.08253"
"15362","92.13600","17.67205","0.08235"
"15406","92.40000","17.69417","0.08351"
"15450","92.66400","17.71612","0.08398"
"15494","92.92800","17.73818","0.08402"
"15538","93.19200","17.76012","0.08462"
"15582","93.45600","17.78218","0.08493"
"15626","93.72000","17.80407","0.08547"
"15670","93.98400","17.82619","0.08622"
"15714","94.24800","17.84813","0.08662"
"15758","94.51200","17.87020","0.08756"
"15802","94.77600","17.89214","0.08740"
"15846","95.04000","17.91414","0.08706"
"15890","95.30400","17.93608","0.08769"
"15934","95.56800","17.95815","0.08847"
"15978","95.83200","17.98009","0.08909"
"16022","96.09600","18.00215","0.08989"
"16066","96.36000","18.02409","0.09101"
"16110","96.62400","18.04616","0.09139"
"16154","96.88800","18.06810","0.09225"
"16198","97.15200","18.09016","0.09237"
"16242","97.41600","18.11210","0.09317"
"16286","97.68000","18.13416","0.09414"
"16330","97.94400","18.15611","0.09463"
"16374","98.20800","18.17811","0.09500"
"16418","98.47200","18.20011","0.09568"
"16462","98.73600","18.22218","0.09684"
"16506","99.00000","18.24412","0.09713"
"16550","99.26400","18.26618","0.09832"
"16594","99.52800","18.28812","0.09885"
"16638","99.79200","18.31019","0.09966"
"16682","100.05600","18.33213","0.09969"
"16726","100.32000","18.35419","0.10031"
"16770","100.58400","18.37613","0.10070"
"16814","100.84800","18.39820","0.10139"
"16858","101.11200","18.42020","0.10238"
"16902","101.37600","18.44214","0.10363"
"16946","101.64000","18.46408","0.10386"
"16990","101.90400","18.48615","0.10472"
"17034","102.16800","18.50809","0.10545"
"17078","102.43200","18.53009","0.10605"
"17122","102.69600","18.55221","0.10645"
"17166","102.96000","18.57416","0.10628"
"17210","103.22400","18.59610","0.10673"
"17254","103.48800","18.61816","0.10702"
"17298","103.75200","18.64016","0.10783"
"17342","104.01600","18.66217","0.10857"
"17386","104.28000","18.68417","0.10906"
"17430","104.54400","18.70617","0.10873"
"17474","104.80800","18.72817","0.10909"
"17518","105.07200","18.75012","0.11006"
"17562","105.33600","18.77218","0.11070"
"17606","105.60000","18.79412","0.11146"
"17650","105.86400","18.81612","0.11233"
"17694","106.12800","18.83819","0.11240"
"17738","106.39200","18.86013","0.11324"
"17782","106.65600","18.88207","0.11355"
"17826","106.92000","18.90413","0.11447"
"17870","107.18400","18.92608","0.11536"
"17914","107.44800","18.94820","0.11507"
"17958","107.71200","18.97008","0.11559"
"18002","107.97600","18.99215","0.11547"
"18046","108.24000","19.01409","0.11635"
"18090","108.50400","19.03615","0.11656"
"18134","108.76800","19.05803","0.11706"
"18178","109.03200","19.08015","0.11720"
"18222","109.29600","19.10204","0.11753"
"18266","109.56000","19.12416","0.11778"
"18310","109.82400","19.14610","0.11811"
"18354","110.08800","19.16817","0.11867"
"18398","110.35200","19.19011","0.11869"
"18442","110.61600","19.21217","0.11932"
"18486","110.88000","19.23411","0.11927"
"18530","111.14400","19.25618","0.11948"
"18574","111.40800","19.27812","0.11974"
"18618","111.67200","19.30012","0.12044"
"18662","111.93600","19.32212","0.12082"
"18706","112.20000","19.34413","0.12143"
"18750","112.46400","19.36607","0.12221"
"18794","112.72800","19.38813","0.12254"
"18838","112.99200","19.41007","0.12310"
"18882","113.25600","19.43214","0.12407"
"18926","113.52000","19.45414","0.12412"
"18970","113.78400","19.47620","0.12463"
"19014","114.04800","19.49814","0.12571"
"19058","114.31200","19.52021","0.12670"
"19102","114.57600","19.54209","0.12589"
"19146","114.84000","19.56415","0.12647"
"19190","115.10400","19.58609","0.12749"
"19234","115.36800","19.60816","0.12880"
"19278","115.63200","19.63016","0.12907"
"19322","115.89600","19.65216","0.13068"
"19366","116.16000","19.67416","0.13127"
"19410","116.42400","19.69617","0.13209"
"19454","116.68800","19.71811","0.13371"
"19498","116.95200","19.74017","0.13497"
"19542","117.21600","19.76217","0.13292"
"19586","117.48000","19.78418","0.13395"
"19630","117.74400","19.80618","0.13564"
"19674","118.00800","19.82812","0.13618"
"19718","118.27200","19.85013","0.13787"
"19762","118.53600","19.87213","0.13873"
"19806","118.80000","19.89419","0.14014"
"19850","119.06400","19.91613","0.14120"
"19894","119.32800","19.93819","0.14187"
"19938","119.59200","19.96013","0.14290"
"19982","119.85600","19.98214","0.14322"
"20026","120.12000","20.00408","0.14395"
"20070","120.38400","20.02620","0.14438"
"20114","120.64800","20.04809","0.14554"
"20158","120.91200","20.07015","0.14593"
"20202","121.17600","20.09209","0.14695"
"20246","121.44000","20.11415","0.14789"
"20290","121.70400","20.13604","0.14835"
"20334","121.96800","20.15816","0.14877"
"20378","122.23200","20.18011","0.14946"
"20422","122.49600","20.20217","0.15037"
"20466","122.76000","20.22411","0.15104"
"20510","123.02400","20.24611","0.15245"
"20554","123.28800","20.26805","0.15314"
"20598","123.55200","20.29011","0.15350"
"20642","123.81600","20.31212","0.15395"
"20686","124.08000","20.33418","0.15483"
"20730","124.34400","20.35606","0.15531"
"20774","124.60800","20.37819","0.15587"
"20818","124.87200","20.40013","0.15655"
"20862","125.13600","20.42213","0.15644"
"20906","125.40000","20.44407","0.15747"
"20950","125.66400","20.46620","0.15700"
"20994","125.92800","20.48814","0.15747"
"21038","126.19200","20.51020","0.15819"
"21082","126.45600","20.53209","0.15874"
"21126","126.72000","20.55415","0.15880"
"21170","126.98400","20.57615","0.15980"
"21214","127.24800","20.59815","0.16032"
"21258","127.51200","20.62009","0.16087"
"21302","127.77600","20.64222","0.16129"
"21346","128.04000","20.66410","0.16168"
"21390","128.30400","20.68616","0.16222"
"21434","128.56800","20.70811","0.16164"
"21478","128.83200","20.73017","0.16223"
"21522","129.09600","20.75211","0.16272"
"21566","129.36000","20.77417","0.16279"
"21610","129.62400","20.79611","0.16344"
"21654","129.88800","20.81818","0.16362"
"21698","130.15200","20.84018","0.16425"
"21742","130.41600","20.86212","0.16419"
"21786","130.68000","20.88418","0.16460"
"21830","130.94400","20.90619","0.16521"
"21874","131.20800","20.92813","0.16553"
"21918","131.47200","20.95013","0.16623"
"21962","131.73600","20.97208","0.16638"
"22006","132.00000","20.99408","0.16714"
"22050","132.26400","21.01614","0.16749"
"22094","132.52800","21.03814","0.16783"
"22138","132.79200","21.06015","0.16882"
"22182","133.05600","21.08215","0.16911"
"22226","133.32000","21.10415","0.16948"
"22270","133.58400","21.12615","0.17091"
"22314","133.84800","21.14816","0.17124"
"22358","134.11200","21.17010","0.17192"
"22402","134.37600","21.19216","0.17308"
"22446","134.64000","21.21410","0.17294"
"22490","134.90400","21.23617","0.17469"
"22534","135.16800","21.25811","0.17519"
"22578","135.43200","21.28017","0.17647"
"22622","135.69600","21.30211","0.17717"
"22666","135.96000","21.32418","0.17883"
"22710","136.22400","21.34606","0.17938"
"22754","136.48800","21.36818","0.18140"
"22798","136.75200","21.39007","0.18253"
"22842","137.01600","21.41219","0.18408"
"22886","137.28000","21.43413","0.18654"
"22930","137.54400","21.45619","0.18855"
"22974","137.80800","21.47814","0.18941"
"23018","138.07200","21.50014","0.19187"
"23062","138.33600","21.52208","0.19268"
"23106","138.60000","21.54408","0.19533"
"23150","138.86400","21.56614","0.19762"
"23194","139.12800","21.58821","0.19973"
"23238","139.39200","21.61015","0.20229"
"23282","139.65600","21.63215","0.20384"
"23326","139.92000","21.65416","0.20625"
"23370","140.18400","21.67616","0.20847"
"23414","140.44800","21.69810","0.21057"
"23458","140.71200","21.72016","0.21254"
"23502","140.97600","21.74211","0.21416"
"23546","141.24000","21.76417","0.21552"
"23590","141.50400","21.78611","0.21753"
"23634","141.76800","21.80817","0.21875"
"23678","142.03200","21.83012","0.22028"
"23722","142.29600","21.85218","0.22056"
"23766","142.56000","21.87412","0.22148"
"23810","142.82400","21.89612","0.22198"
"23854","143.08800","21.91813","0.22285"
"23898","143.35200","21.94019","0.22323"
"23942","143.61600","21.96213","0.22393"
"23986","143.88000","21.98419","0.22451"
"24030","144.14400","22.00620","0.22507"
"24074","144.40800","22.02814","0.22572"
"24118","144.67200","22.05008","0.22648"
"24162","144.93600","22.07214","0.22756"
"24206","145.20000","22.09414","0.22809"
"24250","145.46400","22.11609","0.22923"
"24294","145.72800","22.13815","0.23093"
"24338","145.99200","22.16009","0.23256"
"24382","146.25600","22.18216","0.23331"
"24426","146.52000","22.20410","0.23437"
"24470","146.78400","22.22616","0.23606"
"24514","147.04800","22.24816","0.23757"
"24558","147.31200","22.27017","0.23807"
"24602","147.57600","22.29211","0.23986"
"24646","147.84000","22.31411","0.24162"
"24690","148.10400","22.33611","0.24320"
"24734","148.36800","22.35818","0.24438"
"24778","148.63200","22.38018","0.24674"
"24822","148.89600","22.40212","0.24923"
"24866","149.16000","22.42412","0.25039"
"24910","149.42400","22.44613","0.25115"
"24954","149.68800","22.46813","0.25288"
"24998","149.95200","22.49013","0.25421"
"25042","150.21600","22.51208","0.25278"
"25086","150.48000","22.53420","0.25435"
"25130","150.74400","22.55608","0.25553"
"25174","151.00800","22.57814","0.25666"
"25218","151.27200","22.60003","0.25808"
"25262","151.53600","22.62215","0.25962"
"25306","151.80000","22.64409","0.26072"
"25350","152.06400","22.66615","0.26181"
"25394","152.32800","22.68816","0.26295"
"25438","152.59200","22.71016","0.26381"
"25482","152.85600","22.73210","0.26459"
"25526","153.12000","22.75416","0.26497"
"25570","153.38400","22.77611","0.26521"
"25614","153.64800","22.79817","0.26309"
"25658","153.91200","22.82011","0.26295"
"25702","154.17600","22.84217","0.26359"
"25746","154.44000","22.86412","0.26469"
"25790","154.70400","22.88612","0.26543"
"25834","154.96800","22.90818","0.26642"
"25878","155.23200","22.93019","0.26740"
"25922","155.49600","22.95213","0.26798"
"25966","155.76000","22.97419","0.26860"
"26010","156.02400","22.99607","0.26924"
"26054","156.28800","23.01813","0.26990"
"26098","156.55200","23.04014","0.27058"
"26142","156.81600","23.06220","0.27125"
"26186","157.08000","23.08414","0.27035"
"26230","157.34400","23.10614","0.27083"
"26274","157.60800","23.12808","0.27091"
"26318","157.87200","23.15009","0.27148"
"26362","158.13600","23.17209","0.27224"
"26406","158.40000","23.19415","0.27240"
"26450","158.66400","23.21616","0.27344"
"26494","158.92800","23.23816","0.27415"
"26538","159.19200","23.26016","0.27484"
"26582","159.45600","23.28216","0.27562"
"26626","159.72000","23.30410","0.27688"
"26670","159.98400","23.32617","0.27813"
"26714","160.24800","23.34817","0.27979"
"26758","160.51200","23.37017","0.28086"
"26802","160.77600","23.39218","0.28242"
"26846","161.04000","23.41412","0.28489"
"26890","161.30400","23.43612","0.28645"
"26934","161.56800","23.45812","0.28856"
"26978","161.83200","23.48013","0.29061"
"27022","162.09600","23.50213","0.29266"
"27066","162.36000","23.52413","0.29552"
"27110","162.62400","23.54607","0.29725"
"27154","162.88800","23.56814","0.29897"
"27198","163.15200","23.59008","0.30077"
"27242","163.41600","23.61214","0.30137"
"27286","163.68000","23.63415","0.30182"
"27330","163.94400","23.65621","0.30340"
"27374","164.20800","23.67809","0.30590"
"27418","164.47200","23.70015","0.30631"
"27462","164.73600","23.72215","0.30760"
"27506","165.00000","23.74416","0.30629"
"27550","165.26400","23.76616","0.30810"
"27594","165.52800","23.78822","0.30970"
"27638","165.79200","23.81010","0.31202"
"27682","166.05600","23.83211","0.31364"
"27726","166.32000","23.85411","0.31504"
"27770","166.58400","23.87617","0.31676"
"27814","166.84800","23.89812","0.31879"
"27858","167.11200","23.92018","0.32036"
"27902","167.37600","23.94206","0.32154"
"27946","167.64000","23.96412","0.32365"
"27990","167.90400","23.98606","0.32563"
"28034","168.16800","24.00813","0.32855"
"28078","168.43200","24.03007","0.33049"
"28122","168.69600","24.05219","0.33264"
"28166","168.96000","24.07414","0.33692"
"28210","169.22400","24.09620","0.34030"
"28254","169.48800","24.11808","0.34222"
"28298","169.75200","24.14020","0.34495"
"28342","170.01600","24.16209","0.34824"
"28386","170.28000","24.18415","0.35087"
"28430","170.54400","24.20609","0.35398"
"28474","170.80800","24.22815","0.35671"
"28518","171.07200","24.25010","0.35943"
"28562","171.33600","24.27216","0.36287"
"28606","171.60000","24.29410","0.36477"
"28650","171.86400","24.31616","0.36621"
"28694","172.12800","24.33817","0.36772"
"28738","172.39200","24.36017","0.36902"
"28782","172.65600","24.38211","0.37091"
"28826","172.92000","24.40417","0.37256"
"28870","173.18400","24.42618","0.37411"
"28914","173.44800","24.44812","0.37542"
"28958","173.71200","24.47012","0.37622"
"29002","173.97600","24.49213","0.37685"
"29046","174.24000","24.51419","0.37727"
"29090","174.50400","24.53613","0.37786"
"29134","174.76800","24.55813","0.37815"
"29178","175.03200","24.58014","0.37901"
"29222","175.29600","24.60213","0.37933"
"29266","175.56000","24.62414","0.37981"
"29310","175.82400","24.64614","0.38044"
"29354","176.08800","24.66815","0.38132"
"29398","176.35200","24.69015","0.38204"
"29442","176.61600","24.71215","0.38235"
"29486","176.88000","24.73415","0.38378"
"29530","177.14400","24.75610","0.38520"
"29574","177.40800","24.77816","0.38651"
"29618","177.67200","24.80010","0.38698"
"29662","177.93600","24.82222","0.38931"
"29706","178.20000","24.84411","0.39105"
"29750","178.46400","24.86617","0.39223"
"29794","178.72800","24.88811","0.39366"
"29838","178.99200","24.91017","0.39585"
"29882","179.25600","24.93205","0.39804"
"29926","179.52000","24.95412","0.39975"
"29970","179.78400","24.97606","0.40215"
"30014","180.04800","24.99818","0.40373"
"30058","180.31200","25.02013","0.40680"
"30102","180.57600","25.04213","0.40884"
"30146","180.84000","25.06407","0.41177"
"30190","181.10400","25.08613","0.41433"
"30234","181.36800","25.10807","0.41645"
"30278","181.63200","25.13014","0.41972"
"30322","181.89600","25.15208","0.42180"
"30366","182.16000","25.17420","0.42370"
"30410","182.42400","25.19615","0.42487"
"30454","182.68800","25.21815","0.42602"
"30498","182.95200","25.24015","0.42753"
"30542","183.21600","25.26221","0.42826"
"30586","183.48000","25.28410","0.42905"
"30630","183.74400","25.30616","0.43075"
"30674","184.00800","25.32810","0.43205"
"30718","184.27200","25.35011","0.43367"
"30762","184.53600","25.37211","0.43639"
"30806","184.80000","25.39417","0.43855"
"30850","185.06400","25.41611","0.44002"
"30894","185.32800","25.43817","0.44184"
"30938","185.59200","25.46012","0.44361"
"30982","185.85600","25.48218","0.44570"
"31026","186.12000","25.50412","0.44734"
"31070","186.38400","25.52618","0.44919"
"31114","186.64800","25.54819","0.45049"
"31158","186.91200","25.57019","0.45166"
"31202","187.17600","25.59213","0.45284"
"31246","187.44000","25.61407","0.45446"
"31290","187.70400","25.63614","0.45559"
"31334","187.96800","25.65814","0.45647"
"31378","188.23200","25.68020","0.45765"
"31422","188.49600","25.70215","0.45889"
"31466","188.76000","25.72415","0.45969"
"31510","189.02400","25.74615","0.46115"
"31554","189.28800","25.76815","0.46210"
"31598","189.55200","25.79010","0.46293"
"31642","189.81600","25.81216","0.46368"
"31686","190.08000","25.83416","0.46482"
"31730","190.34400","25.85616","0.44464"
"31774","190.60800","25.87817","0.37735"
"31818","190.87200","25.90017","0.37789"
"31862","191.13600","25.92211","0.37647"
"31906","191.40000","25.94417","0.37557"
"31950","191.66400","25.96612","0.37659"
"31994","191.92800","25.98818","0.37799"
"32038","192.19200","26.01006","0.37762"
"32082","192.45600","26.03212","0.37714"
"32126","192.72000","26.05412","0.37744"
"32170","192.98400","26.07613","0.37832"
"32214","193.24800","26.09813","0.37905"
"32258","193.51200","26.12019","0.37893"
"32302","193.77600","26.14208","0.37908"
"32346","194.04000","26.16414","0.37976"
"32390","194.30400","26.18608","0.38083"
"32434","194.56800","26.20814","0.38136"
"32478","194.83200","26.23009","0.38109"
"32522","195.09600","26.25221","0.38216"
"32566","195.36000","26.27415","0.38356"
"32610","195.62400","26.29615","0.38519"
"32654","195.88800","26.31810","0.38520"
"32698","196.15200","26.34016","0.38567"
"32742","196.41600","26.36210","0.38672"
"32786","196.68000","26.38416","0.38847"
"32830","196.94400","26.40611","0.38941"
"32874","197.20800","26.42817","0.38974"
"32918","197.47200","26.45011","0.39005"
"32962","197.73600","26.47212","0.39138"
"33006","198.00000","26.49412","0.39251"
"33050","198.26400","26.51618","0.39320"
"33094","198.52800","26.53812","0.39275"
"33138","198.79200","26.56013","0.29533"
"33182","199.05600","26.58213","0.29430"
"33226","199.32000","26.60413","0.30158"
"33270","199.58400","26.62613","0.29940"
"33314","199.84800","26.64819","0.29971"
"33358","200.11200","26.67020","0.30267"
"33402","200.37600","26.69214","0.30388"
"33446","200.64000","26.71408","0.30436"
"33490","200.90400","26.73615","0.30639"
"33534","201.16800","26.75809","0.30978"
"33578","201.43200","26.78015","0.30929"
"33622","201.69600","26.80221","0.31010"
"33666","201.96000","26.82416","0.31270"
"33710","202.22400","26.84616","0.31306"
"33754","202.48800","26.86816","0.31341"
"33798","202.75200","26.89016","0.31512"
"33842","203.01600","26.91217","0.31744"
"33886","203.28000","26.93417","0.31737"
"33930","203.54400","26.95617","0.31760"
"33974","203.80800","26.97812","0.31986"
"34018","204.07200","27.00006","0.32173"
"34062","204.33600","27.02212","0.32192"
"34106","204.60000","27.04412","0.32390"
"34150","204.86400","27.06618","0.32447"
"34194","205.12800","27.08813","0.32640"
"34238","205.39200","27.11013","0.32666"
"34282","205.65600","27.13207","0.32809"
"34326","205.92000","27.15419","0.33030"
"34370","206.18400","27.17614","0.33216"
"34414","206.44800","27.19820","0.33462"
"34458","206.71200","27.22008","0.33675"
"34502","206.97600","27.24214","0.34035"
"34546","207.24000","27.26403","0.34155"
"34590","207.50400","27.28615","0.34379"
"34634","207.76800","27.30809","0.34628"
"34678","208.03200","27.33015","0.34781"
"34722","208.29600","27.35216","0.35139"
"34766","208.56000","27.37416","0.35228"
"34810","208.82400","27.39610","0.35465"
"34854","209.08800","27.41811","0.35460"
"34898","209.35200","27.44011","0.35497"
"34942","209.61600","27.46217","0.35503"
"34986","209.88000","27.48411","0.35628"
"35030","210.14400","27.50617","0.35844"
"35074","210.40800","27.52806","0.35919"
"35118","210.67200","27.55012","0.35985"
"35162","210.93600","27.57212","0.36116"
"35206","211.20000","27.59418","0.36156"
"35250","211.46400","27.61613","0.36287"
"35294","211.72800","27.63819","0.36360"
"35338","211.99200","27.66007","0.36468"
"35382","212.25600","27.68219","0.36676"
"35426","212.52000","27.70408","0.36743"
"35470","212.78400","27.72620","0.36858"
"35514","213.04800","27.74814","0.36943"
"35558","213.31200","27.77015","0.36944"
"35602","213.57600","27.79215","0.37059"
"35646","213.84000","27.81415","0.37070"
"35690","214.10400","27.83615","0.37021"
"35734","214.36800","27.85816","0.37035"
"35778","214.63200","27.88016","0.37030"
"35822","214.89600","27.90216","0.37066"
"35866","215.16000","27.92416","0.37029"
"35910","215.42400","27.94617","0.36979"
"35954","215.68800","27.96811","0.36945"
"35998","215.95200","27.99017","0.37047"
"36042","216.21600","28.01217","0.37063"
"36086","216.48000","28.03411","0.37032"
"36130","216.74400","28.05612","0.37060"
"36174","217.00800","28.07806","0.37100"
"36218","217.27200","28.10013","0.37129"
"36262","217.53600","28.12213","0.37163"
"36306","217.80000","28.14413","0.37165"
"36350","218.06400","28.16613","0.37203"
"36394","218.32800","28.18819","0.37237"
"36438","218.59200","28.21014","0.37262"
"36482","218.85600","28.23220","0.37250"
"36526","219.12000","28.25414","0.37316"
"36570","219.38400","28.27615","0.37223"
"36614","219.64800","28.29815","0.37298"
"36658","219.91200","28.32015","0.37315"
"36702","220.17600","28.34209","0.37338"
"36746","220.44000","28.36415","0.37377"
"36790","220.70400","28.38610","0.37376"
"36834","220.96800","28.40822","0.37372"
"36878","221.23200","28.43004","0.37425"
"36922","221.49600","28.45217","0.37440"
"36966","221.76000","28.47405","0.37462"
"37010","222.02400","28.49611","0.37451"
"37054","222.28800","28.51805","0.37559"
"37098","222.55200","28.54017","0.37581"
"37142","222.81600","28.56206","0.37628"
"37186","223.08000","28.58412","0.37672"
"37230","223.34400","28.60606","0.37715"
"37274","223.60800","28.62813","0.37694"
"37318","223.87200","28.65013","0.37726"
"37362","224.13600","28.67207","0.37770"
"37406","224.40000","28.69407","0.37789"
"37450","224.66400","28.71620","0.37811"
"37494","224.92800","28.73814","0.37851"
"37538","225.19200","28.76020","0.37875"
"37582","225.45600","28.78214","0.37882"
"37626","225.72000","28.80420","0.37886"
"37670","225.98400","28.82615","0.37917"
"37714","226.24800","28.84821","0.37951"
"37758","226.51200","28.87009","0.37947"
"37802","226.77600","28.89216","0.37957"
"37846","227.04000","28.91410","0.38003"
"37890","227.30400","28.93616","0.38012"
"37934","227.56800","28.95811","0.38042"
"37978","227.83200","28.98017","0.38058"
"38022","228.09600","29.00217","0.38103"
"38066","228.36000","29.02417","0.38117"
"38110","228.62400","29.04612","0.38138"
"38154","228.88800","29.06818","0.38224"
"38198","229.15200","29.09018","0.38260"
"38242","229.41600","29.11218","0.38286"
"38286","229.68000","29.13413","0.38350"
"38330","229.94400","29.15619","0.38428"
"38374","230.20800","29.17813","0.38512"
"38418","230.47200","29.20013","0.38684"
"38462","230.73600","29.22214","0.38769"
"38506","231.00000","29.24408","0.38937"
"38550","231.26400","29.26620","0.39107"
"38594","231.52800","29.28814","0.39285"
"38638","231.79200","29.31015","0.39494"
"38682","232.05600","29.33209","0.39725"
"38726","232.32000","29.35415","0.39975"
"38770","232.58400","29.37609","0.40152"
"38814","232.84800","29.39816","0.40373"
"38858","233.11200","29.42010","0.40485"
"38902","233.37600","29.44216","0.40744"
"38946","233.64000","29.46410","0.40832"
"38990","233.90400","29.48610","0.41067"
"39034","234.16800","29.50811","0.41090"
"39078","234.43200","29.53017","0.41221"
"39122","234.69600","29.55211","0.41355"
"39166","234.96000","29.57412","0.41535"
"39210","235.22400","29.59606","0.41596"
"39254","235.48800","29.61812","0.41713"
"39298","235.75200","29.64012","0.41757"
"39342","236.01600","29.66219","0.41849"
"39386","236.28000","29.68413","0.41935"
"39430","236.54400","29.70613","0.42000"
"39474","236.80800","29.72808","0.42006"
"39518","237.07200","29.75014","0.42081"
"39562","237.33600","29.77208","0.42045"
"39606","237.60000","29.79414","0.42152"
"39650","237.86400","29.81614","0.42222"
"39694","238.12800","29.83821","0.42207"
"39738","238.39200","29.86015","0.42231"
"39782","238.65600","29.88221","0.42246"
"39826","238.92000","29.90409","0.42322"
"39870","239.18400","29.92616","0.42385"
"39914","239.44800","29.94816","0.42502"
"39958","239.71200","29.97016","0.42529"
"40002","239.97600","29.99211","0.42611"
"40046","240.24000","30.01417","0.42695"
"40090","240.50400","30.03611","0.42779"
"40134","240.76800","30.05817","0.42886"
"40178","241.03200","30.08017","0.42900"
"40222","241.29600","30.10218","0.42984"
"40266","241.56000","30.12412","0.43111"
"40310","241.82400","30.14612","0.43112"
"40354","242.08800","30.16813","0.43191"
"40398","242.35200","30.19013","0.43293"
"40442","242.61600","30.21213","0.43285"
"40486","242.88000","30.23413","0.43427"
"40530","243.14400","30.25620","0.43553"
"40574","243.40800","30.27814","0.43606"
"40618","243.67200","30.30008","0.43768"
"40662","243.93600","30.32214","0.43810"
"40706","244.20000","30.34409","0.43890"
"40750","244.46400","30.36615","0.43995"
"40794","244.72800","30.38821","0.44118"
"40838","244.99200","30.41015","0.44195"
"40882","245.25600","30.43216","0.44341"
"40926","245.52000","30.45410","0.44400"
"40970","245.78400","30.47610","0.44502"
"41014","246.04800","30.49810","0.44583"
"41058","246.31200","30.52017","0.44660"
"41102","246.57600","30.54211","0.44728"
"41146","246.84000","30.56411","0.44828"
"41190","247.10400","30.58605","0.44862"
"41234","247.36800","30.60818","0.44964"
"41278","247.63200","30.63012","0.45020"
"41322","247.89600","30.65212","0.45109"
"41366","248.16000","30.67406","0.45154"
"41410","248.42400","30.69613","0.45140"
"41454","248.68800","30.71807","0.45123"
"41498","248.95200","30.74013","0.45046"
"41542","249.21600","30.76213","0.05256"
"41586","249.48000","30.78420","0.06188"
"41630","249.74400","30.80608","0.06275"
"41674","250.00800","30.82814","0.06215"
"41718","250.27200","30.85009","0.05347"
"41762","250.53600","30.87221","0.06041"
"41806","250.80000","30.89415","0.06027"
"41850","251.06400","30.91615","0.06682"
"41894","251.32800","30.93815","0.05170"
"41938","251.59200","30.96016","0.05448"
"41982","251.85600","30.98216","0.06913"
"42026","252.12000","31.00416","0.05257"
"42070","252.38400","31.02611","0.05819"
"42114","252.64800","31.04823","0.06821"
"42158","252.91200","31.07011","0.05694"
"42202","253.17600","31.09211","0.05656"
"42246","253.44000","31.11406","0.06636"
"42290","253.70400","31.13618","0.05829"
"42334","253.96800","31.15812","0.06502"
"42378","254.23200","31.18018","0.06140"
"42422","254.49600","31.20213","0.05899"
"42466","254.76000","31.22419","0.06683"
"42510","255.02400","31.24613","0.06124"
"42554","255.28800","31.26819","0.06165"
"42598","255.55200","31.29013","0.06761"
"42642","255.81600","31.31220","0.06077"
"42686","256.08000","31.33414","0.06409"
"42730","256.34400","31.35614","0.06564"
"42774","256.60800","31.37808","0.06305"
"42818","256.87200","31.40015","0.06797"
"42862","257.13600","31.42215","0.06402"
"42906","257.40000","31.44415","0.06435"
"42950","257.66400","31.46615","0.06774"
"42994","257.92800","31.48810","0.06499"
"43038","258.19200","31.51016","0.06801"
"43082","258.45600","31.53210","0.06617"
"43126","258.72000","31.55410","0.06568"
"43170","258.98400","31.57617","0.06869"
"43214","259.24800","31.59817","0.06631"
"43258","259.51200","31.62011","0.06849"
"43302","259.77600","31.64218","0.06769"
"43346","260.04000","31.66412","0.06727"
"43390","260.30400","31.68612","0.06945"
"43434","260.56800","31.70812","0.06779"
"43478","260.83200","31.73013","0.06985"
"43522","261.09600","31.75213","0.06886"
"43566","261.36000","31.77419","0.06888"
"43610","261.62400","31.79613","0.07061"
"43654","261.88800","31.81820","0.06902"
"43698","262.15200","31.84008","0.07082"
"43742","262.41600","31.86220","0.06995"
"43786","262.68000","31.88414","0.07047"
"43830","262.94400","31.90615","0.07164"
"43874","263.20800","31.92803","0.07031"
"43918","263.47200","31.95015","0.07234"
"43962","263.73600","31.97209","0.07101"
"44006","264.00000","31.99422","0.07251"
"44050","264.26400","32.01610","0.07270"
"44094","264.52800","32.03816","0.07220"
"44138","264.79200","32.06004","0.07367"
"44182","265.05600","32.08211","0.07254"
"44226","265.32000","32.10411","0.07422"
"44270","265.58400","32.12617","0.07360"
"44314","265.84800","32.14812","0.07428"
"44358","266.11200","32.17018","0.07490"
"44402","266.37600","32.19212","0.07442"
"44446","266.64000","32.21412","0.07601"
"44490","266.90400","32.23613","0.07524"
"44534","267.16800","32.25813","0.07656"
"44578","267.43200","32.28013","0.07623"
"44622","267.69600","32.30219","0.07719"
"44666","267.96000","32.32413","0.07757"
"44710","268.22400","32.34614","0.07768"
"44754","268.48800","32.36814","0.07970"
"44798","268.75200","32.39020","0.07860"
"44842","269.01600","32.41214","0.07947"
"44886","269.28000","32.43415","0.07876"
"44930","269.54400","32.45609","0.08065"
"44974","269.80800","32.47815","0.08080"
"45018","270.07200","32.50010","0.08090"
"45062","270.33600","32.52216","0.08215"
"45106","270.60000","32.54416","0.08219"
"45150","270.86400","32.56616","0.08304"
"45194","271.12800","32.58817","0.08288"
"45238","271.39200","32.61017","0.08377"
"45282","271.65600","32.63211","0.08367"
"45326","271.92000","32.65411","0.08513"
"45370","272.18400","32.67617","0.08541"
"45414","272.44800","32.69818","0.08559"
"45458","272.71200","32.72018","0.08606"
"45502","272.97600","32.74212","0.08651"
"45546","273.24000","32.76413","0.08738"
"45590","273.50400","32.78607","0.08788"
"45634","273.76800","32.80813","0.08820"
"45678","274.03200","32.83014","0.08904"
"45722","274.29600","32.85220","0.08959"
"45766","274.56000","32.87414","0.08960"
"45810","274.82400","32.89620","0.09035"
"45854","275.08800","32.91808","0.09112"
"45898","275.35200","32.94020","0.09169"
"45942","275.61600","32.96215","0.09225"
"45986","275.88000","32.98415","0.09270"
"46030","276.14400","33.00610","0.09313"
"46074","276.40800","33.02816","0.09403"
"46118","276.67200","33.05010","0.09405"
"46162","276.93600","33.07216","0.09478"
"46206","277.20000","33.09410","0.09530"
"46250","277.46400","33.11617","0.09547"
"46294","277.72800","33.13811","0.09597"
"46338","277.99200","33.16011","0.09649"
"46382","278.25600","33.18211","0.09705"
"46426","278.52000","33.20417","0.09817"
"46470","278.78400","33.22612","0.09795"
"46514","279.04800","33.24818","0.09864"
"46558","279.31200","33.27012","0.09942"
"46602","279.57600","33.29213","0.09986"
"46646","279.84000","33.31413","0.10027"
"46690","280.10400","33.33613","0.10113"
"46734","280.36800","33.35807","0.10171"
"46778","280.63200","33.38020","0.10203"
"46822","280.89600","33.40214","0.10283"
"46866","281.16000","33.42420","0.10336"
"46910","281.42400","33.44608","0.10360"
"46954","281.68800","33.46815","0.10419"
"46998","281.95200","33.49015","0.10453"
"47042","282.21600","33.51215","0.10450"
"47086","282.48000","33.53410","0.10569"
"47130","282.74400","33.55616","0.10571"
"47174","283.00800","33.57810","0.10639"
"47218","283.27200","33.60016","0.10654"
"47262","283.53600","33.62210","0.10668"
"47306","283.80000","33.64411","0.10683"
"47350","284.06400","33.66617","0.10797"
"47394","284.32800","33.68811","0.10810"
"47438","284.59200","33.71011","0.10834"
"47482","284.85600","33.73212","0.10862"
"47526","285.12000","33.75412","0.10838"
"47570","285.38400","33.77612","0.10894"
"47614","285.64800","33.79813","0.10988"
"47658","285.91200","33.82013","0.11002"
"47702","286.17600","33.84213","0.11110"
"47746","286.44000","33.86413","0.11233"
"47790","286.70400","33.88614","0.11177"
"47834","286.96800","33.90808","0.11281"
"47878","287.23200","33.93014","0.11321"
"47922","287.49600","33.95214","0.11352"
"47966","287.76000","33.97414","0.11398"
"48010","288.02400","33.99615","0.11386"
"48054","288.28800","34.01815","0.11457"
"48098","288.55200","34.04009","0.11492"
"48142","288.81600","34.06215","0.11542"
"48186","289.08000","34.08416","0.11545"
"48230","289.34400","34.10616","0.11593"
"48274","289.60800","34.12811","0.11624"
"48318","289.87200","34.15017","0.11618"
"48362","290.13600","34.17211","0.11589"
"48406","290.40000","34.19417","0.11646"
"48450","290.66400","34.21611","0.11666"
"48494","290.92800","34.23818","0.11697"
"48538","291.19200","34.26006","0.11744"
"48582","291.45600","34.28218","0.11715"
"48626","291.72000","34.30412","0.11769"
"48670","291.98400","34.32613","0.11781"
"48714","292.24800","34.34813","0.11791"
"48758","292.51200","34.37019","0.11825"
"48802","292.77600","34.39207","0.11827"
"48846","293.04000","34.41408","0.11868"
"48890","293.30400","34.43608","0.11883"
"48934","293.56800","34.45814","0.11915"
"48978","293.83200","34.48014","0.11941"
"49022","294.09600","34.50215","0.11951"
"49066","294.36000","34.52415","0.11995"
"49110","294.62400","34.54615","0.12029"
"49154","294.88800","34.56809","0.12115"
"49198","295.15200","34.59016","0.12083"
"49242","295.41600","34.61210","0.12085"
"49286","295.68000","34.63422","0.12098"
"49330","295.94400","34.65617","0.12143"
"49374","296.20800","34.67817","0.12155"
"49418","296.47200","34.70005","0.12248"
"49462","296.73600","34.72217","0.12209"
"49506","297.00000","34.74412","0.12249"
"49550","297.26400","34.76624","0.12329"
"49594","297.52800","34.78812","0.12429"
"49638","297.79200","34.81012","0.12378"
"49682","298.05600","34.83213","0.12475"
"49726","298.32000","34.85419","0.12531"
"49770","298.58400","34.87613","0.12561"
"49814","298.84800","34.89813","0.12648"
"49858","299.11200","34.92014","0.12684"
"49902","299.37600","34.94214","0.12762"
"49946","299.64000","34.96414","0.12804"
"49990","299.90400","34.98615","0.12757"
"50034","300.16800","35.00815","0.12833"
"50078","300.43200","35.03015","0.12866"
"50122","300.69600","35.05221","0.13034"
"50166","300.96000","35.07415","0.13192"
"50210","301.22400","35.09616","0.13200"
"50254","301.48800","35.11816","0.13281"
"50298","301.75200","35.14016","0.13325"
"50342","302.01600","35.16217","0.13390"
"50386","302.28000","35.18417","0.13625"
"50430","302.54400","35.20611","0.13563"
"50474","302.80800","35.22817","0.13707"
"50518","303.07200","35.25011","0.13755"
"50562","303.33600","35.27218","0.13870"
"50606","303.60000","35.29418","0.13904"
"50650","303.86400","35.31618","0.13976"
"50694","304.12800","35.33813","0.14025"
"50738","304.39200","35.36013","0.14180"
"50782","304.65600","35.38207","0.14166"
"50826","304.92000","35.40413","0.14281"
"50870","305.18400","35.42607","0.14315"
"50914","305.44800","35.44820","0.14364"
"50958","305.71200","35.47008","0.14378"
"51002","305.97600","35.49215","0.14485"
"51046","306.24000","35.51409","0.14427"
"51090","306.50400","35.53615","0.14445"
"51134","306.76800","35.55809","0.14482"
"51178","307.03200","35.58015","0.14536"
"51222","307.29600","35.60210","0.14635"
"51266","307.56000","35.62416","0.14660"
"51310","307.82400","35.64610","0.14769"
"51354","308.08800","35.66811","0.14833"
"51398","308.35200","35.69011","0.14832"
"51442","308.61600","35.71217","0.14885"
"51486","308.88000","35.73411","0.14945"
"51530","309.14400","35.75618","0.15034"
"51574","309.40800","35.77806","0.15112"
"51618","309.67200","35.80012","0.15127"
"51662","309.93600","35.82212","0.15213"
"51706","310.20000","35.84418","0.15212"
"51750","310.46400","35.86613","0.15304"
"51794","310.72800","35.88813","0.15366"
"51838","310.99200","35.91013","0.15396"
"51882","311.25600","35.93219","0.15410"
"51926","311.52000","35.95414","0.15508"
"51970","311.78400","35.97614","0.15572"
"52014","312.04800","35.99814","0.15557"
"52058","312.31200","36.02015","0.15624"
"52102","312.57600","36.04209","0.15679"
"52146","312.84000","36.06415","0.15734"
"52190","313.10400","36.08609","0.15779"
"52234","313.36800","36.10815","0.15811"
"52278","313.63200","36.13021","0.15848"
"52322","313.89600","36.15216","0.15866"
"52366","314.16000","36.17410","0.15875"
"52410","314.42400","36.19616","0.15884"
"52454","314.68800","36.21817","0.15964"
"52498","314.95200","36.24017","0.15971"
"52542","315.21600","36.26217","0.15980"
"52586","315.48000","36.28418","0.16028"
"52630","315.74400","36.30618","0.16020"
"52674","316.00800","36.32812","0.16109"
"52718","316.27200","36.35012","0.16111"
"52762","316.53600","36.37212","0.16144"
"52806","316.80000","36.39419","0.16143"
"52850","317.06400","36.41613","0.16184"
"52894","317.32800","36.43819","0.16225"
"52938","317.59200","36.46008","0.16280"
"52982","317.85600","36.48214","0.16282"
"53026","318.12000","36.50408","0.16320"
"53070","318.38400","36.52620","0.16367"
"53114","318.64800","36.54808","0.16372"
"53158","318.91200","36.57015","0.16436"
"53202","319.17600","36.59203","0.16437"
"53246","319.44000","36.61415","0.16518"
"53290","319.70400","36.63610","0.16554"
"53334","319.96800","36.65816","0.16591"
"53378","320.23200","36.68010","0.16610"
"53422","320.49600","36.70216","0.16633"
"53466","320.76000","36.72411","0.16705"
"53510","321.02400","36.74611","0.16736"
"53554","321.28800","36.76811","0.16776"
"53585","321.47000","36.78330","0.16789"