File: Trajectories_together/170225_2Specimen_RawData_9.csv
"","V1","V2","V3"
"1","End date","2/25/2017",""
"2","Specimen label","1DG_3",""
"3","Maximum Load","0.02647","N"
"4","Time","Extension","Load"
"5","(s)","(mm)","(N)"
"6","0.00000","0.00000","0.00012"
"38","0.19200","0.01339","0.00096"
"70","0.38400","0.03217","-0.00036"
"102","0.57600","0.04819","0.00039"
"134","0.76800","0.06421","0.00105"
"166","0.96000","0.08018","0.00027"
"198","1.15200","0.09614","0.00195"
"230","1.34400","0.11222","0.00136"
"262","1.53600","0.12819","0.00115"
"294","1.72800","0.14409","0.00159"
"326","1.92000","0.16024","0.00166"
"358","2.11200","0.17614","0.00235"
"390","2.30400","0.19210","0.00235"
"422","2.49600","0.20819","0.00166"
"454","2.68800","0.22415","0.00270"
"486","2.88000","0.24011","0.00199"
"518","3.07200","0.25614","0.00217"
"550","3.26400","0.27216","0.00320"
"582","3.45600","0.28813","0.00230"
"614","3.64800","0.30421","0.00263"
"646","3.84000","0.32017","0.00358"
"678","4.03200","0.33620","0.00270"
"710","4.22400","0.35216","0.00318"
"742","4.41600","0.36812","0.00258"
"774","4.60800","0.38421","0.00318"
"806","4.80000","0.40017","0.00353"
"838","4.99200","0.41614","0.00350"
"870","5.18400","0.43216","0.00365"
"902","5.37600","0.44818","0.00339"
"934","5.56800","0.46415","0.00331"
"966","5.76000","0.48017","0.00376"
"998","5.95200","0.49613","0.00384"
"1030","6.14400","0.51222","0.00419"
"1062","6.33600","0.52818","0.00421"
"1094","6.52800","0.54414","0.00407"
"1126","6.72000","0.56023","0.00476"
"1158","6.91200","0.57619","0.00444"
"1190","7.10400","0.59216","0.00441"
"1222","7.29600","0.60818","0.00452"
"1254","7.48800","0.62414","0.00493"
"1286","7.68000","0.64017","0.00442"
"1318","7.87200","0.65619","0.00543"
"1350","8.06400","0.67215","0.00481"
"1382","8.25600","0.68818","0.00459"
"1414","8.44800","0.70426","0.00486"
"1446","8.64000","0.72016","0.00494"
"1478","8.83200","0.73619","0.00600"
"1510","9.02400","0.75221","0.00564"
"1542","9.21600","0.76818","0.00490"
"1574","9.40800","0.78420","0.00555"
"1606","9.60000","0.80022","0.00547"
"1638","9.79200","0.81619","0.00524"
"1670","9.98400","0.83221","0.00633"
"1702","10.17600","0.84817","0.00546"
"1734","10.36800","0.86414","0.00619"
"1766","10.56000","0.88022","0.00575"
"1798","10.75200","0.89619","0.00572"
"1830","10.94400","0.91215","0.00641"
"1862","11.13600","0.92817","0.00627"
"1894","11.32800","0.94414","0.00581"
"1926","11.52000","0.96016","0.00584"
"1958","11.71200","0.97618","0.00663"
"1990","11.90400","0.99215","0.00659"
"2022","12.09600","1.00823","0.00624"
"2054","12.28800","1.02419","0.00716"
"2086","12.48000","1.04016","0.00745"
"2118","12.67200","1.05618","0.00667"
"2150","12.86400","1.07215","0.00697"
"2182","13.05600","1.08817","0.00717"
"2214","13.24800","1.10425","0.00720"
"2246","13.44000","1.12016","0.00739"
"2278","13.63200","1.13618","0.00790"
"2310","13.82400","1.15220","0.00732"
"2342","14.01600","1.16817","0.00797"
"2374","14.20800","1.18419","0.00742"
"2406","14.40000","1.20022","0.00808"
"2438","14.59200","1.21612","0.00800"
"2470","14.78400","1.23220","0.00787"
"2502","14.97600","1.24823","0.00789"
"2534","15.16800","1.26413","0.00852"
"2566","15.36000","1.28021","0.00841"
"2598","15.55200","1.29624","0.00823"
"2630","15.74400","1.31214","0.00872"
"2662","15.93600","1.32816","0.00854"
"2694","16.12800","1.34419","0.00852"
"2726","16.32000","1.36015","0.00843"
"2758","16.51200","1.37624","0.00851"
"2790","16.70400","1.39220","0.00876"
"2822","16.89600","1.40816","0.00912"
"2854","17.08800","1.42419","0.00924"
"2886","17.28000","1.44015","0.00929"
"2918","17.47200","1.45617","0.00922"
"2950","17.66400","1.47220","0.01004"
"2982","17.85600","1.48816","0.01007"
"3014","18.04800","1.50419","0.00922"
"3046","18.24000","1.52021","0.00969"
"3078","18.43200","1.53617","0.00908"
"3110","18.62400","1.55214","0.01005"
"3142","18.81600","1.56816","0.00941"
"3174","19.00800","1.58418","0.01000"
"3206","19.20000","1.60015","0.01014"
"3238","19.39200","1.61617","0.00980"
"3270","19.58400","1.63213","0.00992"
"3302","19.77600","1.64822","0.01040"
"3334","19.96800","1.66418","0.01046"
"3366","20.16000","1.68015","0.01074"
"3398","20.35200","1.69623","0.01055"
"3430","20.54400","1.71213","0.01065"
"3462","20.73600","1.72822","0.01114"
"3494","20.92800","1.74412","0.01062"
"3526","21.12000","1.76014","0.01019"
"3558","21.31200","1.77623","0.01140"
"3590","21.50400","1.79213","0.01080"
"3622","21.69600","1.80816","0.01131"
"3654","21.88800","1.82418","0.01125"
"3686","22.08000","1.84014","0.01154"
"3718","22.27200","1.85623","0.01164"
"3750","22.46400","1.87219","0.01136"
"3782","22.65600","1.88815","0.01088"
"3814","22.84800","1.90424","0.01135"
"3846","23.04000","1.92020","0.01164"
"3878","23.23200","1.93610","0.01183"
"3910","23.42400","1.95219","0.01149"
"3942","23.61600","1.96821","0.01143"
"3974","23.80800","1.98418","0.01147"
"4006","24.00000","2.00020","0.01165"
"4038","24.19200","2.01616","0.01211"
"4070","24.38400","2.03213","0.01211"
"4102","24.57600","2.04827","0.01205"
"4134","24.76800","2.06417","0.01190"
"4166","24.96000","2.08014","0.01250"
"4198","25.15200","2.09622","0.01243"
"4230","25.34400","2.11213","0.01229"
"4262","25.53600","2.12815","0.01210"
"4294","25.72800","2.14423","0.01218"
"4326","25.92000","2.16014","0.01265"
"4358","26.11200","2.17616","0.01221"
"4390","26.30400","2.19218","0.01272"
"4422","26.49600","2.20815","0.01216"
"4454","26.68800","2.22417","0.01269"
"4486","26.88000","2.24019","0.01212"
"4518","27.07200","2.25616","0.01265"
"4550","27.26400","2.27218","0.01263"
"4582","27.45600","2.28821","0.01313"
"4614","27.64800","2.30417","0.01312"
"4646","27.84000","2.32019","0.01291"
"4678","28.03200","2.33622","0.01329"
"4710","28.22400","2.35224","0.01266"
"4742","28.41600","2.36814","0.01287"
"4774","28.60800","2.38417","0.01312"
"4806","28.80000","2.40019","0.01340"
"4838","28.99200","2.41615","0.01303"
"4870","29.18400","2.43218","0.01276"
"4902","29.37600","2.44820","0.01353"
"4934","29.56800","2.46417","0.01383"
"4966","29.76000","2.48019","0.01348"
"4998","29.95200","2.49621","0.01413"
"5030","30.14400","2.51212","0.01355"
"5062","30.33600","2.52820","0.01355"
"5094","30.52800","2.54416","0.01318"
"5126","30.72000","2.56013","0.01332"
"5158","30.91200","2.57621","0.01376"
"5190","31.10400","2.59224","0.01362"
"5222","31.29600","2.60814","0.01312"
"5254","31.48800","2.62422","0.01333"
"5286","31.68000","2.64019","0.01331"
"5318","31.87200","2.65609","0.01360"
"5350","32.06400","2.67223","0.01323"
"5382","32.25600","2.68820","0.01348"
"5414","32.44800","2.70416","0.01374"
"5446","32.64000","2.72024","0.01358"
"5478","32.83200","2.73615","0.01349"
"5510","33.02400","2.75217","0.01394"
"5542","33.21600","2.76826","0.01419"
"5574","33.40800","2.78416","0.01382"
"5606","33.60000","2.80012","0.01402"
"5638","33.79200","2.81621","0.01422"
"5670","33.98400","2.83211","0.01464"
"5702","34.17600","2.84825","0.01403"
"5734","34.36800","2.86422","0.01450"
"5766","34.56000","2.88012","0.01408"
"5798","34.75200","2.89620","0.01447"
"5830","34.94400","2.91217","0.01433"
"5862","35.13600","2.92813","0.01418"
"5894","35.32800","2.94422","0.01374"
"5926","35.52000","2.96018","0.01454"
"5958","35.71200","2.97620","0.01423"
"5990","35.90400","2.99223","0.01478"
"6022","36.09600","3.00819","0.01450"
"6054","36.28800","3.02415","0.01454"
"6086","36.48000","3.04018","0.01539"
"6118","36.67200","3.05614","0.01489"
"6150","36.86400","3.07217","0.01535"
"6182","37.05600","3.08819","0.01547"
"6214","37.24800","3.10415","0.01578"
"6246","37.44000","3.12012","0.01512"
"6278","37.63200","3.13620","0.01553"
"6310","37.82400","3.15222","0.01521"
"6342","38.01600","3.16819","0.01519"
"6374","38.20800","3.18415","0.01560"
"6406","38.40000","3.20017","0.01597"
"6438","38.59200","3.21620","0.01552"
"6470","38.78400","3.23222","0.01555"
"6502","38.97600","3.24819","0.01546"
"6534","39.16800","3.26421","0.01605"
"6566","39.36000","3.28011","0.01624"
"6598","39.55200","3.29626","0.01608"
"6630","39.74400","3.31216","0.01555"
"6662","39.93600","3.32818","0.01630"
"6694","40.12800","3.34421","0.01559"
"6726","40.32000","3.36017","0.01602"
"6758","40.51200","3.37620","0.01577"
"6790","40.70400","3.39222","0.01643"
"6822","40.89600","3.40818","0.01647"
"6854","41.08800","3.42421","0.01632"
"6886","41.28000","3.44017","0.01596"
"6918","41.47200","3.45613","0.01660"
"6950","41.66400","3.47222","0.01670"
"6982","41.85600","3.48818","0.01637"
"7014","42.04800","3.50415","0.01684"
"7046","42.24000","3.52023","0.01718"
"7078","42.43200","3.53619","0.01681"
"7110","42.62400","3.55210","0.01694"
"7142","42.81600","3.56824","0.01758"
"7174","43.00800","3.58420","0.01682"
"7206","43.20000","3.60017","0.01720"
"7238","43.39200","3.61619","0.01737"
"7270","43.58400","3.63215","0.01718"
"7302","43.77600","3.64812","0.01744"
"7334","43.96800","3.66420","0.01716"
"7366","44.16000","3.68017","0.01755"
"7398","44.35200","3.69613","0.01750"
"7430","44.54400","3.71221","0.01761"
"7462","44.73600","3.72812","0.01740"
"7494","44.92800","3.74420","0.01777"
"7526","45.12000","3.76016","0.01717"
"7558","45.31200","3.77613","0.01770"
"7590","45.50400","3.79221","0.01809"
"7622","45.69600","3.80823","0.01808"
"7654","45.88800","3.82414","0.01891"
"7686","46.08000","3.84016","0.01826"
"7718","46.27200","3.85619","0.01819"
"7750","46.46400","3.87215","0.01829"
"7782","46.65600","3.88817","0.01858"
"7814","46.84800","3.90414","0.01828"
"7846","47.04000","3.92016","0.01824"
"7878","47.23200","3.93618","0.01857"
"7910","47.42400","3.95215","0.01880"
"7942","47.61600","3.96817","0.01895"
"7974","47.80800","3.98420","0.01884"
"8006","48.00000","4.00010","0.01889"
"8038","48.19200","4.01624","0.01859"
"8070","48.38400","4.03221","0.01872"
"8102","48.57600","4.04817","0.01918"
"8134","48.76800","4.06419","0.01884"
"8166","48.96000","4.08016","0.01895"
"8198","49.15200","4.09618","0.01942"
"8230","49.34400","4.11220","0.01948"
"8262","49.53600","4.12811","0.01923"
"8294","49.72800","4.14419","0.02020"
"8326","49.92000","4.16016","0.01981"
"8358","50.11200","4.17618","0.01963"
"8390","50.30400","4.19226","0.01997"
"8422","50.49600","4.20817","0.02031"
"8454","50.68800","4.22413","0.01971"
"8486","50.88000","4.24021","0.01989"
"8518","51.07200","4.25618","0.02020"
"8550","51.26400","4.27214","0.01954"
"8582","51.45600","4.28823","0.02029"
"8614","51.64800","4.30413","0.02081"
"8646","51.84000","4.32015","0.02053"
"8678","52.03200","4.33618","0.02004"
"8710","52.22400","4.35220","0.02030"
"8742","52.41600","4.36816","0.02028"
"8774","52.60800","4.38419","0.01991"
"8806","52.80000","4.40015","0.02040"
"8838","52.99200","4.41617","0.01963"
"8870","53.18400","4.43220","0.02018"
"8902","53.37600","4.44810","0.02050"
"8934","53.56800","4.46425","0.02033"
"8966","53.76000","4.48021","0.02040"
"8998","53.95200","4.49611","0.02091"
"9030","54.14400","4.51220","0.02017"
"9062","54.33600","4.52816","0.02133"
"9094","54.52800","4.54412","0.02047"
"9126","54.72000","4.56021","0.02090"
"9158","54.91200","4.57617","0.02113"
"9190","55.10400","4.59213","0.02083"
"9222","55.29600","4.60822","0.02082"
"9254","55.48800","4.62412","0.02087"
"9286","55.68000","4.64021","0.02090"
"9318","55.87200","4.65617","0.02033"
"9350","56.06400","4.67219","0.02031"
"9382","56.25600","4.68822","0.02075"
"9414","56.44800","4.70418","0.02061"
"9446","56.64000","4.72014","0.02054"
"9478","56.83200","4.73617","0.02105"
"9510","57.02400","4.75219","0.02063"
"9542","57.21600","4.76816","0.02087"
"9574","57.40800","4.78418","0.02132"
"9606","57.60000","4.80014","0.02099"
"9638","57.79200","4.81617","0.02142"
"9670","57.98400","4.83219","0.02142"
"9702","58.17600","4.84821","0.02108"
"9734","58.36800","4.86418","0.02027"
"9766","58.56000","4.88020","0.02062"
"9798","58.75200","4.89616","0.02138"
"9830","58.94400","4.91219","0.02119"
"9862","59.13600","4.92815","0.02131"
"9894","59.32800","4.94418","0.02138"
"9926","59.52000","4.96020","0.02173"
"9958","59.71200","4.97616","0.02170"
"9990","59.90400","4.99213","0.02194"
"10022","60.09600","5.00821","0.02207"
"10054","60.28800","5.02411","0.02221"
"10086","60.48000","5.04014","0.02236"
"10118","60.67200","5.05622","0.02214"
"10150","60.86400","5.07219","0.02262"
"10182","61.05600","5.08821","0.02276"
"10214","61.24800","5.10423","0.02213"
"10246","61.44000","5.12014","0.02331"
"10278","61.63200","5.13622","0.02264"
"10310","61.82400","5.15218","0.02214"
"10342","62.01600","5.16809","0.02284"
"10374","62.20800","5.18423","0.02288"
"10406","62.40000","5.20019","0.02304"
"10438","62.59200","5.21616","0.02323"
"10470","62.78400","5.23224","0.02337"
"10502","62.97600","5.24815","0.02248"
"10534","63.16800","5.26417","0.02303"
"10566","63.36000","5.28019","0.02338"
"10598","63.55200","5.29622","0.02340"
"10630","63.74400","5.31218","0.02325"
"10662","63.93600","5.32820","0.02406"
"10694","64.12800","5.34417","0.02384"
"10726","64.32000","5.36019","0.02373"
"10758","64.51200","5.37616","0.02371"
"10790","64.70400","5.39212","0.02359"
"10822","64.89600","5.40820","0.02419"
"10854","65.08800","5.42417","0.02422"
"10886","65.28000","5.44013","0.02362"
"10918","65.47200","5.45621","0.02428"
"10950","65.66400","5.47218","0.02389"
"10982","65.85600","5.48820","0.02420"
"11014","66.04800","5.50422","0.02359"
"11046","66.24000","5.52019","0.02403"
"11078","66.43200","5.53615","0.02405"
"11110","66.62400","5.55224","0.02361"
"11142","66.81600","5.56814","0.02349"
"11174","67.00800","5.58416","0.02423"
"11206","67.20000","5.60019","0.02398"
"11238","67.39200","5.61609","0.02416"
"11270","67.58400","5.63223","0.02376"
"11302","67.77600","5.64820","0.02395"
"11334","67.96800","5.66416","0.02413"
"11366","68.16000","5.68019","0.02457"
"11398","68.35200","5.69615","0.02379"
"11430","68.54400","5.71211","0.02457"
"11462","68.73600","5.72820","0.02434"
"11494","68.92800","5.74416","0.02452"
"11526","69.12000","5.76018","0.02465"
"11558","69.31200","5.77621","0.02454"
"11590","69.50400","5.79217","0.02454"
"11622","69.69600","5.80819","0.02415"
"11654","69.88800","5.82416","0.02408"
"11686","70.08000","5.84018","0.02443"
"11718","70.27200","5.85615","0.02461"
"11750","70.46400","5.87217","0.02455"
"11782","70.65600","5.88819","0.02497"
"11814","70.84800","5.90416","0.02448"
"11846","71.04000","5.92018","0.02465"
"11878","71.23200","5.93620","0.02428"
"11910","71.42400","5.95217","0.02492"
"11942","71.61600","5.96819","0.02425"
"11974","71.80800","5.98416","0.02431"
"12006","72.00000","6.00018","0.02483"
"12038","72.19200","6.01614","0.02476"
"12070","72.38400","6.03223","0.02470"
"12102","72.57600","6.04813","0.02471"
"12134","72.76800","6.06409","0.02435"
"12166","72.96000","6.08018","0.02491"
"12198","73.15200","6.09620","0.02438"
"12230","73.34400","6.11216","0.02475"
"12262","73.53600","6.12819","0.02344"
"12294","73.72800","6.14415","0.02336"
"12326","73.92000","6.16017","0.00112"
"12358","74.11200","6.17626","0.00314"
"12390","74.30400","6.19216","0.00606"
"12422","74.49600","6.20819","0.00192"
"12454","74.68800","6.22421","0.00132"
"12486","74.88000","6.24011","0.00147"
"12518","75.07200","6.25620","0.00160"
"12550","75.26400","6.27222","0.00078"
"12582","75.45600","6.28812","0.00346"
"12614","75.64800","6.30421","0.00247"
"12646","75.84000","6.32023","0.00290"
"12678","76.03200","6.33614","0.00246"
"12710","76.22400","6.35222","0.00175"
"12742","76.41600","6.36818","0.00213"
"12774","76.60800","6.38415","0.00350"
"12806","76.80000","6.40023","0.00251"
"12838","76.99200","6.41613","0.00412"
"12870","77.18400","6.43216","0.00276"
"12902","77.37600","6.44824","0.00315"
"12934","77.56800","6.46415","0.00422"
"12966","77.76000","6.48017","0.00355"
"12998","77.95200","6.49619","0.00350"
"13030","78.14400","6.51216","0.00362"
"13062","78.33600","6.52818","0.00315"
"13094","78.52800","6.54420","0.00434"
"13126","78.72000","6.56017","0.00404"
"13158","78.91200","6.57613","0.00331"
"13190","79.10400","6.59222","0.00429"
"13222","79.29600","6.60818","0.00368"
"13254","79.48800","6.62420","0.00476"
"13286","79.68000","6.64017","0.00497"
"13318","79.87200","6.65619","0.00390"
"13350","80.06400","6.67215","0.00463"
"13382","80.25600","6.68818","0.00481"
"13414","80.44800","6.70420","0.00428"
"13446","80.64000","6.72022","0.00475"
"13478","80.83200","6.73613","0.00463"
"13510","81.02400","6.75221","0.00548"
"13542","81.21600","6.76818","0.00488"
"13574","81.40800","6.78420","0.00399"
"13606","81.60000","6.80016","0.00562"
"13638","81.79200","6.81613","0.00472"
"13670","81.98400","6.83221","0.00500"
"13702","82.17600","6.84817","0.00486"
"13734","82.36800","6.86414","0.00546"
"13766","82.56000","6.88022","0.00501"
"13798","82.75200","6.89618","0.00504"
"13830","82.94400","6.91209","0.00528"
"13862","83.13600","6.92823","0.00514"
"13894","83.32800","6.94414","0.00543"
"13926","83.52000","6.96004","0.00585"
"13958","83.71200","6.97624","0.00533"
"13990","83.90400","6.99221","0.00535"
"14022","84.09600","7.00811","0.00563"
"14054","84.28800","7.02419","0.00580"
"14086","84.48000","7.04022","0.00582"
"14118","84.67200","7.05618","0.00616"
"14150","84.86400","7.07221","0.00623"
"14182","85.05600","7.08817","0.00588"
"14214","85.24800","7.10413","0.00657"
"14246","85.44000","7.12022","0.00632"
"14278","85.63200","7.13612","0.00621"
"14310","85.82400","7.15214","0.00589"
"14342","86.01600","7.16823","0.00606"
"14374","86.20800","7.18413","0.00605"
"14406","86.40000","7.20021","0.00639"
"14438","86.59200","7.21624","0.00626"
"14470","86.78400","7.23214","0.00665"
"14502","86.97600","7.24817","0.00611"
"14534","87.16800","7.26425","0.00624"
"14566","87.36000","7.28015","0.00665"
"14598","87.55200","7.29618","0.00693"
"14630","87.74400","7.31214","0.00680"
"14662","87.93600","7.32816","0.00720"
"14694","88.12800","7.34419","0.00724"
"14726","88.32000","7.36015","0.00720"
"14758","88.51200","7.37624","0.00715"
"14790","88.70400","7.39220","0.00712"
"14822","88.89600","7.40816","0.00736"
"14854","89.08800","7.42419","0.00673"
"14886","89.28000","7.44015","0.00756"
"14918","89.47200","7.45617","0.00729"
"14950","89.66400","7.47220","0.00760"
"14982","89.85600","7.48816","0.00799"
"15014","90.04800","7.50418","0.00767"
"15046","90.24000","7.52015","0.00738"
"15078","90.43200","7.53617","0.00803"
"15110","90.62400","7.55220","0.00809"
"15142","90.81600","7.56822","0.00757"
"15174","91.00800","7.58418","0.00793"
"15206","91.20000","7.60021","0.00765"
"15238","91.39200","7.61617","0.00797"
"15270","91.58400","7.63213","0.00837"
"15302","91.77600","7.64822","0.00814"
"15334","91.96800","7.66418","0.00841"
"15366","92.16000","7.68015","0.00845"
"15398","92.35200","7.69617","0.00866"
"15430","92.54400","7.71213","0.00821"
"15462","92.73600","7.72816","0.00764"
"15494","92.92800","7.74418","0.00827"
"15526","93.12000","7.76014","0.00841"
"15558","93.31200","7.77623","0.00822"
"15590","93.50400","7.79225","0.00855"
"15622","93.69600","7.80816","0.00844"
"15654","93.88800","7.82418","0.00855"
"15686","94.08000","7.84014","0.00931"
"15718","94.27200","7.85605","0.00876"
"15750","94.46400","7.87225","0.00874"
"15782","94.65600","7.88821","0.00901"
"15814","94.84800","7.90412","0.00865"
"15846","95.04000","7.92026","0.00860"
"15878","95.23200","7.93622","0.00888"
"15910","95.42400","7.95213","0.00930"
"15942","95.61600","7.96821","0.00901"
"15974","95.80800","7.98417","0.00903"
"16006","96.00000","8.00020","0.00908"
"16038","96.19200","8.01622","0.00939"
"16070","96.38400","8.03213","0.00937"
"16102","96.57600","8.04821","0.00941"
"16134","96.76800","8.06423","0.00919"
"16166","96.96000","8.08014","0.00940"
"16198","97.15200","8.09622","0.00964"
"16230","97.34400","8.11218","0.00933"
"16262","97.53600","8.12815","0.00997"
"16294","97.72800","8.14417","0.01002"
"16326","97.92000","8.16020","0.00991"
"16358","98.11200","8.17616","0.00975"
"16390","98.30400","8.19218","0.00960"
"16422","98.49600","8.20815","0.00975"
"16454","98.68800","8.22417","0.01000"
"16486","98.88000","8.24019","0.00923"
"16518","99.07200","8.25622","0.00967"
"16550","99.26400","8.27218","0.00987"
"16582","99.45600","8.28820","0.00951"
"16614","99.64800","8.30417","0.00987"
"16646","99.84000","8.32025","0.00987"
"16678","100.03200","8.33622","0.01054"
"16710","100.22400","8.35218","0.01073"
"16742","100.41600","8.36820","0.01050"
"16774","100.60800","8.38417","0.01060"
"16806","100.80000","8.40019","0.01044"
"16838","100.99200","8.41621","0.01073"
"16870","101.18400","8.43218","0.01064"
"16902","101.37600","8.44820","0.01005"
"16934","101.56800","8.46428","0.01010"
"16966","101.76000","8.48013","0.01005"
"16998","101.95200","8.49621","0.01006"
"17030","102.14400","8.51218","0.01024"
"17062","102.33600","8.52814","0.01115"
"17094","102.52800","8.54422","0.01062"
"17126","102.72000","8.56019","0.01077"
"17158","102.91200","8.57615","0.01099"
"17190","103.10400","8.59217","0.01142"
"17222","103.29600","8.60814","0.01136"
"17254","103.48800","8.62416","0.01123"
"17286","103.68000","8.64019","0.01153"
"17318","103.87200","8.65621","0.01061"
"17350","104.06400","8.67217","0.01165"
"17382","104.25600","8.68826","0.01115"
"17414","104.44800","8.70416","0.01132"
"17446","104.64000","8.72024","0.01219"
"17478","104.83200","8.73621","0.01113"
"17510","105.02400","8.75211","0.01147"
"17542","105.21600","8.76819","0.01214"
"17574","105.40800","8.78416","0.01231"
"17606","105.60000","8.80012","0.01214"
"17638","105.79200","8.81621","0.01212"
"17670","105.98400","8.83217","0.01250"
"17702","106.17600","8.84813","0.01167"
"17734","106.36800","8.86422","0.01221"
"17766","106.56000","8.88018","0.01139"
"17798","106.75200","8.89614","0.01213"
"17830","106.94400","8.91217","0.01126"
"17862","107.13600","8.92813","0.01191"
"17894","107.32800","8.94416","0.01192"
"17926","107.52000","8.96018","0.01149"
"17958","107.71200","8.97614","0.01204"
"17990","107.90400","8.99217","0.01203"
"18022","108.09600","9.00825","0.01208"
"18054","108.28800","9.02415","0.01164"
"18086","108.48000","9.04018","0.01214"
"18118","108.67200","9.05620","0.01188"
"18150","108.86400","9.07216","0.01272"
"18182","109.05600","9.08825","0.01230"
"18214","109.24800","9.10421","0.01150"
"18246","109.44000","9.12018","0.01167"
"18278","109.63200","9.13620","0.01191"
"18310","109.82400","9.15216","0.01158"
"18342","110.01600","9.16819","0.01241"
"18374","110.20800","9.18421","0.01249"
"18406","110.40000","9.20017","0.01200"
"18438","110.59200","9.21620","0.01231"
"18470","110.78400","9.23216","0.01246"
"18502","110.97600","9.24819","0.01303"
"18534","111.16800","9.26421","0.01276"
"18566","111.36000","9.28017","0.01291"
"18598","111.55200","9.29620","0.01260"
"18630","111.74400","9.31222","0.01249"
"18662","111.93600","9.32812","0.01268"
"18694","112.12800","9.34421","0.01308"
"18726","112.32000","9.36023","0.01356"
"18758","112.51200","9.37619","0.01378"
"18790","112.70400","9.39222","0.01390"
"18822","112.89600","9.40824","0.01308"
"18854","113.08800","9.42415","0.01344"
"18886","113.28000","9.44017","0.01391"
"18918","113.47200","9.45619","0.01413"
"18950","113.66400","9.47210","0.01389"
"18982","113.85600","9.48824","0.01401"
"19014","114.04800","9.50420","0.01421"
"19046","114.24000","9.52011","0.01401"
"19078","114.43200","9.53625","0.01408"
"19110","114.62400","9.55216","0.01367"
"19142","114.81600","9.56818","0.01397"
"19174","115.00800","9.58426","0.01386"
"19206","115.20000","9.60017","0.01354"
"19238","115.39200","9.61619","0.01400"
"19270","115.58400","9.63221","0.01356"
"19302","115.77600","9.64812","0.01388"
"19334","115.96800","9.66420","0.01373"
"19366","116.16000","9.68017","0.01403"
"19398","116.35200","9.69619","0.01414"
"19430","116.54400","9.71221","0.01422"
"19462","116.73600","9.72818","0.01374"
"19494","116.92800","9.74420","0.01353"
"19526","117.12000","9.76022","0.01419"
"19558","117.31200","9.77619","0.01357"
"19590","117.50400","9.79215","0.01411"
"19622","117.69600","9.80817","0.01427"
"19654","117.88800","9.82414","0.01343"
"19686","118.08000","9.84022","0.01472"
"19718","118.27200","9.85624","0.01445"
"19750","118.46400","9.87215","0.01388"
"19782","118.65600","9.88823","0.01412"
"19814","118.84800","9.90426","0.01502"
"19846","119.04000","9.92010","0.01419"
"19878","119.23200","9.93624","0.01467"
"19910","119.42400","9.95221","0.01461"
"19942","119.61600","9.96817","0.01399"
"19974","119.80800","9.98419","0.01451"
"20006","120.00000","10.00016","0.01448"
"20038","120.19200","10.01618","0.01526"
"20070","120.38400","10.03226","0.01481"
"20102","120.57600","10.04817","0.01485"
"20134","120.76800","10.06413","0.01428"
"20166","120.96000","10.08022","0.01516"
"20198","121.15200","10.09612","0.01426"
"20230","121.34400","10.11220","0.01398"
"20262","121.53600","10.12817","0.01483"
"20294","121.72800","10.14413","0.01481"
"20326","121.92000","10.16022","0.01534"
"20358","122.11200","10.17618","0.01478"
"20390","122.30400","10.19220","0.01498"
"20422","122.49600","10.20823","0.01470"
"20454","122.68800","10.22413","0.01475"
"20486","122.88000","10.24015","0.01478"
"20518","123.07200","10.25618","0.01476"
"20550","123.26400","10.27214","0.01508"
"20582","123.45600","10.28822","0.01499"
"20614","123.64800","10.30425","0.01517"
"20646","123.84000","10.32015","0.01478"
"20678","124.03200","10.33618","0.01534"
"20710","124.22400","10.35220","0.01490"
"20742","124.41600","10.36810","0.01503"
"20774","124.60800","10.38419","0.01502"
"20806","124.80000","10.40021","0.01501"
"20838","124.99200","10.41617","0.01483"
"20870","125.18400","10.43220","0.01472"
"20902","125.37600","10.44816","0.01461"
"20934","125.56800","10.46418","0.01503"
"20966","125.76000","10.48021","0.01432"
"20998","125.95200","10.49611","0.01456"
"21030","126.14400","10.51220","0.01531"
"21062","126.33600","10.52822","0.01455"
"21094","126.52800","10.54406","0.01498"
"21126","126.72000","10.56021","0.01490"
"21158","126.91200","10.57623","0.01442"
"21190","127.10400","10.59208","0.01501"
"21222","127.29600","10.60822","0.01527"
"21254","127.48800","10.62424","0.01520"
"21286","127.68000","10.64009","0.01535"
"21318","127.87200","10.65623","0.01552"
"21350","128.06400","10.67219","0.01533"
"21382","128.25600","10.68816","0.01569"
"21414","128.44800","10.70424","0.01570"
"21446","128.64000","10.72014","0.01576"
"21478","128.83200","10.73617","0.01530"
"21510","129.02400","10.75219","0.01632"
"21542","129.21600","10.76810","0.01575"
"21574","129.40800","10.78424","0.01614"
"21606","129.60000","10.80020","0.01564"
"21638","129.79200","10.81617","0.01543"
"21670","129.98400","10.83219","0.01593"
"21702","130.17600","10.84821","0.01643"
"21734","130.36800","10.86418","0.01547"
"21766","130.56000","10.88014","0.01561"
"21798","130.75200","10.89616","0.01617"
"21830","130.94400","10.91219","0.01634"
"21862","131.13600","10.92815","0.01604"
"21894","131.32800","10.94418","0.01613"
"21926","131.52000","10.96020","0.01583"
"21958","131.71200","10.97616","0.01588"
"21990","131.90400","10.99219","0.01570"
"22022","132.09600","11.00821","0.01680"
"22054","132.28800","11.02423","0.01653"
"22086","132.48000","11.04014","0.01614"
"22118","132.67200","11.05622","0.01613"
"22150","132.86400","11.07213","0.01654"
"22182","133.05600","11.08815","0.01635"
"22214","133.24800","11.10423","0.01623"
"22246","133.44000","11.12014","0.01650"
"22278","133.63200","11.13616","0.01617"
"22310","133.82400","11.15218","0.01622"
"22342","134.01600","11.16815","0.01633"
"22374","134.20800","11.18423","0.01648"
"22406","134.40000","11.20019","0.01673"
"22438","134.59200","11.21616","0.01658"
"22470","134.78400","11.23224","0.01611"
"22502","134.97600","11.24821","0.01724"
"22534","135.16800","11.26411","0.01640"
"22566","135.36000","11.28025","0.01630"
"22598","135.55200","11.29622","0.01650"
"22630","135.74400","11.31212","0.01633"
"22662","135.93600","11.32820","0.01694"
"22694","136.12800","11.34417","0.01645"
"22726","136.32000","11.36013","0.01671"
"22758","136.51200","11.37621","0.01641"
"22790","136.70400","11.39218","0.01658"
"22822","136.89600","11.40814","0.01614"
"22854","137.08800","11.42417","0.01725"
"22886","137.28000","11.44013","0.01637"
"22918","137.47200","11.45615","0.01707"
"22950","137.66400","11.47218","0.01680"
"22982","137.85600","11.48814","0.01661"
"23014","138.04800","11.50422","0.01645"
"23046","138.24000","11.52025","0.01631"
"23078","138.43200","11.53615","0.01708"
"23110","138.62400","11.55218","0.01702"
"23142","138.81600","11.56826","0.01688"
"23174","139.00800","11.58410","0.01689"
"23206","139.20000","11.60019","0.01687"
"23238","139.39200","11.61615","0.01708"
"23270","139.58400","11.63217","0.01686"
"23302","139.77600","11.64820","0.01685"
"23334","139.96800","11.66416","0.01730"
"23366","140.16000","11.68018","0.01719"
"23398","140.35200","11.69615","0.01683"
"23430","140.54400","11.71217","0.01737"
"23462","140.73600","11.72820","0.01687"
"23494","140.92800","11.74416","0.01695"
"23526","141.12000","11.76012","0.01736"
"23558","141.31200","11.77621","0.01773"
"23590","141.50400","11.79211","0.01701"
"23622","141.69600","11.80814","0.01748"
"23654","141.88800","11.82416","0.01734"
"23686","142.08000","11.84012","0.01777"
"23718","142.27200","11.85620","0.01780"
"23750","142.46400","11.87217","0.01748"
"23782","142.65600","11.88813","0.01769"
"23814","142.84800","11.90422","0.01798"
"23846","143.04000","11.92024","0.01803"
"23878","143.23200","11.93608","0.01750"
"23910","143.42400","11.95229","0.01764"
"23942","143.61600","11.96813","0.01829"
"23974","143.80800","11.98409","0.01761"
"24006","144.00000","12.00024","0.01788"
"24038","144.19200","12.01614","0.01757"
"24070","144.38400","12.03217","0.01784"
"24102","144.57600","12.04825","0.01733"
"24134","144.76800","12.06415","0.01824"
"24166","144.96000","12.08018","0.01783"
"24198","145.15200","12.09620","0.01757"
"24230","145.34400","12.11222","0.01784"
"24262","145.53600","12.12819","0.01827"
"24294","145.72800","12.14421","0.01765"
"24326","145.92000","12.16012","0.01806"
"24358","146.11200","12.17620","0.01756"
"24390","146.30400","12.19222","0.01822"
"24422","146.49600","12.20813","0.01765"
"24454","146.68800","12.22421","0.01758"
"24486","146.88000","12.24017","0.01752"
"24518","147.07200","12.25614","0.01824"
"24550","147.26400","12.27222","0.01816"
"24582","147.45600","12.28819","0.01820"
"24614","147.64800","12.30421","0.01838"
"24646","147.84000","12.32023","0.01835"
"24678","148.03200","12.33614","0.01809"
"24710","148.22400","12.35216","0.01824"
"24742","148.41600","12.36824","0.01886"
"24774","148.60800","12.38415","0.01816"
"24806","148.80000","12.40023","0.01808"
"24838","148.99200","12.41619","0.01792"
"24870","149.18400","12.43216","0.01862"
"24902","149.37600","12.44824","0.01804"
"24934","149.56800","12.46420","0.01843"
"24966","149.76000","12.48017","0.01787"
"24998","149.95200","12.49613","0.01804"
"25030","150.14400","12.51222","0.01801"
"25062","150.33600","12.52818","0.01793"
"25094","150.52800","12.54420","0.01820"
"25126","150.72000","12.56017","0.01816"
"25158","150.91200","12.57619","0.01809"
"25190","151.10400","12.59221","0.01810"
"25222","151.29600","12.60818","0.01789"
"25254","151.48800","12.62420","0.01860"
"25286","151.68000","12.64017","0.01819"
"25318","151.87200","12.65619","0.01876"
"25350","152.06400","12.67221","0.01786"
"25382","152.25600","12.68818","0.01828"
"25414","152.44800","12.70420","0.01864"
"25446","152.64000","12.72022","0.01862"
"25478","152.83200","12.73619","0.01821"
"25510","153.02400","12.75215","0.01830"
"25542","153.21600","12.76824","0.01809"
"25574","153.40800","12.78414","0.01859"
"25606","153.60000","12.80022","0.01871"
"25638","153.79200","12.81619","0.01866"
"25670","153.98400","12.83215","0.01902"
"25702","154.17600","12.84823","0.01626"
"25734","154.36800","12.86420","0.01407"
"25766","154.56000","12.88010","0.01465"
"25798","154.75200","12.89624","0.01690"
"25830","154.94400","12.91215","0.01540"
"25862","155.13600","12.92817","0.01562"
"25894","155.32800","12.94425","0.01804"
"25926","155.52000","12.96016","0.01552"
"25958","155.71200","12.97618","0.01764"
"25990","155.90400","12.99227","0.01776"
"26022","156.09600","13.00817","0.01681"
"26054","156.28800","13.02413","0.01834"
"26086","156.48000","13.04022","0.01690"
"26118","156.67200","13.05612","0.01766"
"26150","156.86400","13.07220","0.01903"
"26182","157.05600","13.08817","0.01790"
"26214","157.24800","13.10413","0.01853"
"26246","157.44000","13.12022","0.01901"
"26278","157.63200","13.13624","0.01789"
"26310","157.82400","13.15214","0.01904"
"26342","158.01600","13.16823","0.01898"
"26374","158.20800","13.18419","0.01822"
"26406","158.40000","13.20015","0.01945"
"26438","158.59200","13.21618","0.01931"
"26470","158.78400","13.23214","0.01915"
"26502","158.97600","13.24817","0.01896"
"26534","159.16800","13.26419","0.01956"
"26566","159.36000","13.28015","0.01988"
"26598","159.55200","13.29618","0.01953"
"26630","159.74400","13.31220","0.01961"
"26662","159.93600","13.32816","0.02005"
"26694","160.12800","13.34419","0.02000"
"26726","160.32000","13.36021","0.01944"
"26758","160.51200","13.37617","0.02005"
"26790","160.70400","13.39220","0.01977"
"26822","160.89600","13.40816","0.01963"
"26854","161.08800","13.42419","0.01989"
"26886","161.28000","13.44021","0.01916"
"26918","161.47200","13.45617","0.01986"
"26950","161.66400","13.47220","0.01955"
"26982","161.85600","13.48822","0.02004"
"27014","162.04800","13.50412","0.02008"
"27046","162.24000","13.52021","0.01961"
"27078","162.43200","13.53617","0.01980"
"27110","162.62400","13.55220","0.01993"
"27142","162.81600","13.56822","0.02056"
"27174","163.00800","13.58418","0.01995"
"27206","163.20000","13.60021","0.01988"
"27238","163.39200","13.61617","0.02013"
"27270","163.58400","13.63213","0.01977"
"27302","163.77600","13.64822","0.02034"
"27334","163.96800","13.66418","0.02042"
"27366","164.16000","13.68015","0.02023"
"27398","164.35200","13.69617","0.02009"
"27430","164.54400","13.71219","0.02085"
"27462","164.73600","13.72816","0.02018"
"27494","164.92800","13.74424","0.02099"
"27526","165.12000","13.76020","0.02073"
"27558","165.31200","13.77611","0.02052"
"27590","165.50400","13.79225","0.02046"
"27622","165.69600","13.80815","0.02069"
"27654","165.88800","13.82412","0.02037"
"27686","166.08000","13.84020","0.02074"
"27718","166.27200","13.85623","0.02074"
"27750","166.46400","13.87219","0.02091"
"27782","166.65600","13.88821","0.02128"
"27814","166.84800","13.90411","0.02089"
"27846","167.04000","13.92014","0.02040"
"27878","167.23200","13.93622","0.02098"
"27910","167.42400","13.95213","0.02053"
"27942","167.61600","13.96821","0.02072"
"27974","167.80800","13.98423","0.02110"
"28006","168.00000","14.00020","0.02060"
"28038","168.19200","14.01616","0.02017"
"28070","168.38400","14.03219","0.02034"
"28102","168.57600","14.04815","0.02013"
"28134","168.76800","14.06417","0.02092"
"28166","168.96000","14.08020","0.02086"
"28198","169.15200","14.09616","0.02075"
"28230","169.34400","14.11218","0.02085"
"28262","169.53600","14.12815","0.02088"
"28294","169.72800","14.14423","0.02047"
"28326","169.92000","14.16020","0.02084"
"28358","170.11200","14.17616","0.02106"
"28390","170.30400","14.19224","0.02104"
"28422","170.49600","14.20821","0.02100"
"28454","170.68800","14.22411","0.02102"
"28486","170.88000","14.24025","0.02050"
"28518","171.07200","14.25616","0.02106"
"28550","171.26400","14.27218","0.02050"
"28582","171.45600","14.28820","0.01976"
"28614","171.64800","14.30417","0.02079"
"28646","171.84000","14.32019","0.01972"
"28678","172.03200","14.33622","0.02094"
"28710","172.22400","14.35212","0.02032"
"28742","172.41600","14.36814","0.01984"
"28774","172.60800","14.38423","0.02026"
"28806","172.80000","14.40019","0.02042"
"28838","172.99200","14.41621","0.02000"
"28870","173.18400","14.43218","0.02072"
"28902","173.37600","14.44814","0.01997"
"28934","173.56800","14.46422","0.02073"
"28966","173.76000","14.48019","0.02051"
"28998","173.95200","14.49615","0.02116"
"29030","174.14400","14.51218","0.02035"
"29062","174.33600","14.52814","0.02092"
"29094","174.52800","14.54422","0.02123"
"29126","174.72000","14.56019","0.02060"
"29158","174.91200","14.57615","0.02118"
"29190","175.10400","14.59217","0.02078"
"29222","175.29600","14.60820","0.02115"
"29254","175.48800","14.62416","0.02151"
"29286","175.68000","14.64025","0.02120"
"29318","175.87200","14.65621","0.02157"
"29350","176.06400","14.67217","0.02178"
"29382","176.25600","14.68820","0.02150"
"29414","176.44800","14.70416","0.02168"
"29446","176.64000","14.72012","0.02113"
"29478","176.83200","14.73621","0.02108"
"29510","177.02400","14.75217","0.02126"
"29542","177.21600","14.76820","0.02141"
"29574","177.40800","14.78416","0.02102"
"29606","177.60000","14.80018","0.02175"
"29638","177.79200","14.81621","0.02127"
"29670","177.98400","14.83223","0.02183"
"29702","178.17600","14.84813","0.02166"
"29734","178.36800","14.86422","0.02148"
"29766","178.56000","14.88024","0.02155"
"29798","178.75200","14.89608","0.02188"
"29830","178.94400","14.91223","0.02154"
"29862","179.13600","14.92819","0.02214"
"29894","179.32800","14.94410","0.02122"
"29926","179.52000","14.96018","0.02222"
"29958","179.71200","14.97614","0.02231"
"29990","179.90400","14.99211","0.02245"
"30022","180.09600","15.00819","0.02225"
"30054","180.28800","15.02415","0.02216"
"30086","180.48000","15.04018","0.02168"
"30118","180.67200","15.05620","0.02186"
"30150","180.86400","15.07217","0.02180"
"30182","181.05600","15.08825","0.02231"
"30214","181.24800","15.10421","0.02133"
"30246","181.44000","15.12012","0.02133"
"30278","181.63200","15.13626","0.02227"
"30310","181.82400","15.15216","0.02220"
"30342","182.01600","15.16819","0.02219"
"30374","182.20800","15.18415","0.02170"
"30406","182.40000","15.20017","0.02199"
"30438","182.59200","15.21620","0.02201"
"30470","182.78400","15.23216","0.02233"
"30502","182.97600","15.24819","0.02155"
"30534","183.16800","15.26421","0.02208"
"30566","183.36000","15.28017","0.02173"
"30598","183.55200","15.29620","0.02195"
"30630","183.74400","15.31222","0.02274"
"30662","183.93600","15.32818","0.02303"
"30694","184.12800","15.34415","0.02167"
"30726","184.32000","15.36029","0.01698"
"30758","184.51200","15.37613","0.00770"
"30790","184.70400","15.39210","0.00914"
"30822","184.89600","15.40818","0.00677"
"30854","185.08800","15.42415","0.00437"
"30886","185.28000","15.44017","0.00890"
"30918","185.47200","15.45619","0.00983"
"30950","185.66400","15.47216","0.00717"
"30982","185.85600","15.48824","0.00911"
"31014","186.04800","15.50426","0.00771"
"31046","186.24000","15.52011","0.00318"
"31078","186.43200","15.53625","0.00528"
"31110","186.62400","15.55216","0.00300"
"31142","186.81600","15.56806","0.00221"
"31174","187.00800","15.58426","0.00269"
"31206","187.20000","15.60023","-0.00015"
"31238","187.39200","15.61607","0.00294"
"31270","187.58400","15.63227","0.00200"
"31302","187.77600","15.64818","0.00245"
"31334","187.96800","15.66414","0.00530"
"31366","188.16000","15.68022","0.00413"
"31398","188.35200","15.69619","0.00512"
"31430","188.54400","15.71215","0.00320"
"31462","188.73600","15.72823","0.00437"
"31494","188.92800","15.74414","0.00635"
"31526","189.12000","15.76022","0.00555"
"31558","189.31200","15.77619","0.00399"
"31590","189.50400","15.79215","0.00356"
"31622","189.69600","15.80817","0.00658"
"31654","189.88800","15.82420","0.00472"
"31686","190.08000","15.84016","0.00545"
"31718","190.27200","15.85612","0.00609"
"31750","190.46400","15.87221","0.00272"
"31782","190.65600","15.88817","0.00597"
"31814","190.84800","15.90420","0.00231"
"31846","191.04000","15.92022","0.00580"
"31878","191.23200","15.93618","0.00441"
"31910","191.42400","15.95221","0.00489"
"31942","191.61600","15.96817","0.00415"
"31974","191.80800","15.98419","0.00339"
"32006","192.00000","16.00016","0.00563"
"32038","192.19200","16.01612","0.00411"
"32070","192.38400","16.03220","0.00451"
"32102","192.57600","16.04817","0.00511"
"32134","192.76800","16.06413","0.00467"
"32166","192.96000","16.08022","0.00547"
"32198","193.15200","16.09618","0.00484"
"32230","193.34400","16.11220","0.00571"
"32262","193.53600","16.12823","0.00544"
"32294","193.72800","16.14413","0.00518"
"32326","193.92000","16.16021","0.00462"
"32358","194.11200","16.17618","0.00511"
"32390","194.30400","16.19214","0.00560"
"32422","194.49600","16.20816","0.00516"
"32454","194.68800","16.22419","0.00623"
"32486","194.88000","16.24009","0.00539"
"32518","195.07200","16.25624","0.00523"
"32550","195.26400","16.27214","0.00520"
"32582","195.45600","16.28810","0.00563"
"32614","195.64800","16.30425","0.00568"
"32646","195.84000","16.32015","0.00593"
"32678","196.03200","16.33617","0.00580"
"32710","196.22400","16.35220","0.00627"
"32742","196.41600","16.36816","0.00563"
"32774","196.60800","16.38418","0.00578"
"32806","196.80000","16.40021","0.00584"
"32838","196.99200","16.41617","0.00637"
"32870","197.18400","16.43220","0.00609"
"32902","197.37600","16.44822","0.00611"
"32934","197.56800","16.46412","0.00613"
"32966","197.76000","16.48015","0.00568"
"32998","197.95200","16.49623","0.00664"
"33030","198.14400","16.51213","0.00607"
"33062","198.33600","16.52822","0.00685"
"33094","198.52800","16.54418","0.00567"
"33126","198.72000","16.56015","0.00647"
"33158","198.91200","16.57617","0.00649"
"33190","199.10400","16.59213","0.00671"
"33222","199.29600","16.60816","0.00621"
"33254","199.48800","16.62418","0.00683"
"33286","199.68000","16.64014","0.00641"
"33318","199.87200","16.65617","0.00667"
"33350","200.06400","16.67219","0.00676"
"33382","200.25600","16.68810","0.00652"
"33414","200.44800","16.70424","0.00623"
"33446","200.64000","16.72020","0.00649"
"33478","200.83200","16.73617","0.00650"
"33510","201.02400","16.75219","0.00685"
"33542","201.21600","16.76821","0.00678"
"33574","201.40800","16.78418","0.00670"
"33606","201.60000","16.80014","0.00715"
"33638","201.79200","16.81617","0.00632"
"33670","201.98400","16.83219","0.00661"
"33702","202.17600","16.84821","0.00650"
"33734","202.36800","16.86411","0.00723"
"33766","202.56000","16.88014","0.00731"
"33798","202.75200","16.89616","0.00683"
"33830","202.94400","16.91213","0.00685"
"33862","203.13600","16.92827","0.00779"
"33894","203.32800","16.94417","0.00716"
"33926","203.52000","16.96020","0.00728"
"33958","203.71200","16.97622","0.00689"
"33990","203.90400","16.99213","0.00708"
"34022","204.09600","17.00815","0.00702"
"34054","204.28800","17.02417","0.00732"
"34086","204.48000","17.04020","0.00764"
"34118","204.67200","17.05616","0.00747"
"34150","204.86400","17.07218","0.00806"
"34182","205.05600","17.08815","0.00793"
"34214","205.24800","17.10423","0.00784"
"34246","205.44000","17.12019","0.00760"
"34278","205.63200","17.13616","0.00750"
"34310","205.82400","17.15218","0.00750"
"34342","206.01600","17.16821","0.00863"
"34374","206.20800","17.18411","0.00808"
"34406","206.40000","17.20019","0.00804"
"34438","206.59200","17.21616","0.00802"
"34470","206.78400","17.23212","0.00847"
"34502","206.97600","17.24820","0.00771"
"34534","207.16800","17.26417","0.00834"
"34566","207.36000","17.28013","0.00803"
"34598","207.55200","17.29622","0.00807"
"34630","207.74400","17.31212","0.00817"
"34662","207.93600","17.32820","0.00878"
"34694","208.12800","17.34422","0.00854"
"34726","208.32000","17.36013","0.00817"
"34758","208.51200","17.37621","0.00809"
"34790","208.70400","17.39224","0.00829"
"34822","208.89600","17.40814","0.00824"
"34854","209.08800","17.42422","0.00823"
"34886","209.28000","17.44025","0.00719"
"34918","209.47200","17.45615","0.00745"
"34950","209.66400","17.47218","0.00755"
"34982","209.85600","17.48820","0.00805"
"35014","210.04800","17.50422","0.00670"
"35046","210.24000","17.52019","0.00746"
"35078","210.43200","17.53615","0.00775"
"35110","210.62400","17.55218","0.00769"
"35142","210.81600","17.56814","0.00839"
"35174","211.00800","17.58416","0.00705"
"35206","211.20000","17.60018","0.00838"
"35238","211.39200","17.61621","0.00805"
"35270","211.58400","17.63217","0.00764"
"35302","211.77600","17.64820","0.00687"
"35334","211.96800","17.66416","0.00289"
"35366","212.16000","17.68018","0.00071"
"35398","212.35200","17.69621","0.00552"
"35430","212.54400","17.71217","-0.00011"
"35462","212.73600","17.72820","0.00224"
"35494","212.92800","17.74416","0.00406"
"35526","213.12000","17.76018","0.00383"
"35558","213.31200","17.77621","0.00672"
"35590","213.50400","17.79223","0.00546"
"35622","213.69600","17.80813","0.00571"
"35654","213.88800","17.82421","0.00587"
"35686","214.08000","17.84024","0.00620"
"35718","214.27200","17.85614","0.00634"
"35750","214.46400","17.87223","0.00615"
"35782","214.65600","17.88813","0.00642"
"35814","214.84800","17.90416","0.00649"
"35846","215.04000","17.92018","0.00101"
"35878","215.23200","17.93614","0.00299"
"35910","215.42400","17.95217","0.00352"
"35942","215.61600","17.96819","0.00515"
"35974","215.80800","17.98415","0.00656"
"36006","216.00000","18.00018","0.00596"
"36038","216.19200","18.01620","0.00601"
"36070","216.38400","18.03217","0.00609"
"36102","216.57600","18.04825","0.00632"
"36134","216.76800","18.06421","0.00638"
"36166","216.96000","18.08012","0.00678"
"36198","217.15200","18.09620","0.00674"
"36230","217.34400","18.11216","0.00712"
"36262","217.53600","18.12819","0.00671"
"36294","217.72800","18.14415","0.00726"
"36326","217.92000","18.16017","0.00796"
"36358","218.11200","18.17614","0.00739"
"36390","218.30400","18.19222","0.00704"
"36422","218.49600","18.20819","0.00709"
"36454","218.68800","18.22415","0.00798"
"36486","218.88000","18.24023","0.00769"
"36518","219.07200","18.25614","0.00714"
"36550","219.26400","18.27216","0.00746"
"36582","219.45600","18.28818","0.00754"
"36614","219.64800","18.30415","0.00716"
"36646","219.84000","18.32017","0.00763"
"36678","220.03200","18.33619","0.00745"
"36710","220.22400","18.35216","0.00766"
"36742","220.41600","18.36818","0.00755"
"36774","220.60800","18.38420","0.00798"
"36806","220.80000","18.40017","0.00805"
"36838","220.99200","18.41619","0.00846"
"36870","221.18400","18.43216","0.00826"
"36902","221.37600","18.44818","0.00824"
"36934","221.56800","18.46420","0.00884"
"36966","221.76000","18.48017","0.00838"
"36998","221.95200","18.49619","0.00829"
"37030","222.14400","18.51215","0.00861"
"37062","222.33600","18.52812","0.00856"
"37094","222.52800","18.54420","0.00833"
"37126","222.72000","18.56017","0.00828"
"37158","222.91200","18.57619","0.00891"
"37190","223.10400","18.59215","0.00882"
"37222","223.29600","18.60812","0.00942"
"37254","223.48800","18.62414","0.00823"
"37286","223.68000","18.64016","0.00849"
"37318","223.87200","18.65613","0.00850"
"37350","224.06400","18.67221","0.00908"
"37382","224.25600","18.68818","0.00961"
"37414","224.44800","18.70414","0.00930"
"37446","224.64000","18.72022","0.00904"
"37478","224.83200","18.73619","0.00970"
"37510","225.02400","18.75209","0.00959"
"37542","225.21600","18.76818","0.00989"
"37574","225.40800","18.78426","0.00890"
"37606","225.60000","18.80010","0.00917"
"37638","225.79200","18.81624","0.00955"
"37670","225.98400","18.83215","0.00884"
"37702","226.17600","18.84811","0.00939"
"37734","226.36800","18.86419","0.00988"
"37766","226.56000","18.88022","0.00973"
"37798","226.75200","18.89624","0.00993"
"37830","226.94400","18.91221","0.00981"
"37862","227.13600","18.92817","0.00975"
"37894","227.32800","18.94419","0.00984"
"37926","227.52000","18.96022","0.00981"
"37958","227.71200","18.97612","0.00975"
"37990","227.90400","18.99220","0.00969"
"38022","228.09600","19.00811","0.01021"
"38054","228.28800","19.02413","0.01010"
"38086","228.48000","19.04022","0.00978"
"38118","228.67200","19.05612","0.01012"
"38150","228.86400","19.07220","0.00999"
"38182","229.05600","19.08823","0.01048"
"38214","229.24800","19.10413","0.01011"
"38246","229.44000","19.12021","0.01053"
"38278","229.63200","19.13624","0.01097"
"38310","229.82400","19.15214","0.01092"
"38342","230.01600","19.16823","0.01080"
"38374","230.20800","19.18425","0.01122"
"38406","230.40000","19.20015","0.01079"
"38438","230.59200","19.21624","0.01086"
"38470","230.78400","19.23220","0.01114"
"38502","230.97600","19.24810","0.01091"
"38534","231.16800","19.26419","0.01129"
"38566","231.36000","19.28021","0.01098"
"38598","231.55200","19.29618","0.01104"
"38630","231.74400","19.31220","0.01081"
"38662","231.93600","19.32816","0.01142"
"38694","232.12800","19.34419","0.01102"
"38726","232.32000","19.36021","0.01181"
"38758","232.51200","19.37617","0.01150"
"38790","232.70400","19.39220","0.01171"
"38822","232.89600","19.40822","0.01166"
"38854","233.08800","19.42413","0.01188"
"38886","233.28000","19.44021","0.01175"
"38918","233.47200","19.45617","0.01168"
"38950","233.66400","19.47219","0.01147"
"38982","233.85600","19.48816","0.01249"
"39014","234.04800","19.50418","0.01206"
"39046","234.24000","19.52015","0.01166"
"39078","234.43200","19.53617","0.01173"
"39110","234.62400","19.55219","0.01208"
"39142","234.81600","19.56816","0.01193"
"39174","235.00800","19.58418","0.01191"
"39206","235.20000","19.60015","0.01233"
"39238","235.39200","19.61623","0.01251"
"39270","235.58400","19.63219","0.01278"
"39302","235.77600","19.64810","0.01237"
"39334","235.96800","19.66424","0.01298"
"39366","236.16000","19.68014","0.01267"
"39398","236.35200","19.69611","0.01272"
"39430","236.54400","19.71225","0.01239"
"39462","236.73600","19.72815","0.01269"
"39467","236.76200","19.73031","0.01219"