File: Trajectories_together/170212_3Specimen_RawData_8.csv
"","V1","V2","V3"
"1","End date","2/12/2017",""
"2","Specimen label","17DG_34",""
"3","Maximum Load","0.10603","N"
"4","Time","Extension","Load"
"5","(s)","(mm)","(N)"
"6","0.00000","0.00000","0.00060"
"74","0.40800","0.03432","0.00233"
"142","0.81600","0.06822","0.00351"
"210","1.22400","0.10224","0.00553"
"278","1.63200","0.13614","0.00567"
"346","2.04000","0.17022","0.00652"
"414","2.44800","0.20424","0.00783"
"482","2.85600","0.23826","0.00805"
"550","3.26400","0.27216","0.00905"
"618","3.67200","0.30618","0.01025"
"686","4.08000","0.34020","0.01062"
"754","4.48800","0.37422","0.01062"
"822","4.89600","0.40818","0.01177"
"890","5.30400","0.44220","0.01286"
"958","5.71200","0.47622","0.01324"
"1026","6.12000","0.51024","0.01367"
"1094","6.52800","0.54414","0.01448"
"1162","6.93600","0.57822","0.01554"
"1230","7.34400","0.61224","0.01558"
"1298","7.75200","0.64627","0.01587"
"1366","8.16000","0.68023","0.01676"
"1434","8.56800","0.71425","0.01719"
"1502","8.97600","0.74827","0.01784"
"1570","9.38400","0.78223","0.01773"
"1638","9.79200","0.81619","0.01850"
"1706","10.20000","0.85021","0.01877"
"1774","10.60800","0.88423","0.01941"
"1842","11.01600","0.91831","0.01981"
"1910","11.42400","0.95221","0.02046"
"1978","11.83200","0.98617","0.02061"
"2046","12.24000","1.02025","0.02064"
"2114","12.64800","1.05421","0.02049"
"2182","13.05600","1.08823","0.02146"
"2250","13.46400","1.12219","0.02144"
"2318","13.87200","1.15621","0.02168"
"2386","14.28000","1.19023","0.02137"
"2454","14.68800","1.22425","0.02221"
"2522","15.09600","1.25815","0.02267"
"2590","15.50400","1.29229","0.02258"
"2658","15.91200","1.32625","0.02294"
"2726","16.32000","1.36021","0.02317"
"2794","16.72800","1.39417","0.02363"
"2862","17.13600","1.42819","0.02300"
"2930","17.54400","1.46227","0.02427"
"2998","17.95200","1.49623","0.02379"
"3066","18.36000","1.53019","0.02443"
"3134","18.76800","1.56421","0.02513"
"3202","19.17600","1.59823","0.02447"
"3270","19.58400","1.63225","0.02455"
"3338","19.99200","1.66621","0.02426"
"3406","20.40000","1.70018","0.02482"
"3474","20.80800","1.73420","0.02503"
"3542","21.21600","1.76828","0.02551"
"3610","21.62400","1.80218","0.02539"
"3678","22.03200","1.83614","0.02515"
"3746","22.44000","1.87022","0.02558"
"3814","22.84800","1.90424","0.02608"
"3882","23.25600","1.93826","0.02598"
"3950","23.66400","1.97222","0.02611"
"4018","24.07200","2.00624","0.02595"
"4086","24.48000","2.04026","0.02680"
"4154","24.88800","2.07416","0.02646"
"4222","25.29600","2.10812","0.02630"
"4290","25.70400","2.14226","0.02714"
"4358","26.11200","2.17628","0.02722"
"4426","26.52000","2.21024","0.02694"
"4494","26.92800","2.24420","0.02749"
"4562","27.33600","2.27816","0.02795"
"4630","27.74400","2.31224","0.02780"
"4698","28.15200","2.34620","0.02812"
"4766","28.56000","2.38016","0.02789"
"4834","28.96800","2.41424","0.02788"
"4902","29.37600","2.44826","0.02831"
"4970","29.78400","2.48222","0.02781"
"5038","30.19200","2.51618","0.02902"
"5106","30.60000","2.55014","0.02882"
"5174","31.00800","2.58428","0.02837"
"5242","31.41600","2.61830","0.02857"
"5310","31.82400","2.65214","0.02895"
"5378","32.23200","2.68622","0.02927"
"5446","32.64000","2.72024","0.02938"
"5514","33.04800","2.75426","0.02935"
"5582","33.45600","2.78817","0.02996"
"5650","33.86400","2.82219","0.02992"
"5718","34.27200","2.85627","0.02941"
"5786","34.68000","2.89023","0.02967"
"5854","35.08800","2.92413","0.02997"
"5922","35.49600","2.95821","0.02938"
"5990","35.90400","2.99223","0.03067"
"6058","36.31200","3.02625","0.03016"
"6126","36.72000","3.06021","0.02987"
"6194","37.12800","3.09423","0.03036"
"6262","37.53600","3.12825","0.03047"
"6330","37.94400","3.16221","0.03033"
"6398","38.35200","3.19617","0.03089"
"6466","38.76000","3.23019","0.03077"
"6534","39.16800","3.26427","0.03052"
"6602","39.57600","3.29823","0.03150"
"6670","39.98400","3.33225","0.03138"
"6738","40.39200","3.36615","0.03153"
"6806","40.80000","3.40023","0.03154"
"6874","41.20800","3.43425","0.03176"
"6942","41.61600","3.46827","0.03145"
"7010","42.02400","3.50223","0.03165"
"7078","42.43200","3.53619","0.03183"
"7146","42.84000","3.57027","0.03161"
"7214","43.24800","3.60423","0.03206"
"7282","43.65600","3.63819","0.03244"
"7350","44.06400","3.67221","0.03223"
"7418","44.47200","3.70623","0.03282"
"7486","44.88000","3.74025","0.03285"
"7554","45.28800","3.77421","0.03249"
"7622","45.69600","3.80817","0.03263"
"7690","46.10400","3.84226","0.03266"
"7758","46.51200","3.87628","0.03301"
"7826","46.92000","3.91024","0.03345"
"7894","47.32800","3.94420","0.03331"
"7962","47.73600","3.97822","0.03398"
"8030","48.14400","4.01224","0.03320"
"8098","48.55200","4.04626","0.03365"
"8166","48.96000","4.08016","0.03345"
"8234","49.36800","4.11430","0.03352"
"8302","49.77600","4.14832","0.03391"
"8370","50.18400","4.18222","0.03419"
"8438","50.59200","4.21618","0.03384"
"8506","51.00000","4.25020","0.03467"
"8574","51.40800","4.28422","0.03450"
"8642","51.81600","4.31818","0.03459"
"8710","52.22400","4.35220","0.03459"
"8778","52.63200","4.38622","0.03484"
"8846","53.04000","4.42024","0.03513"
"8914","53.44800","4.45426","0.03482"
"8982","53.85600","4.48822","0.03494"
"9050","54.26400","4.52224","0.03489"
"9118","54.67200","4.55626","0.03543"
"9186","55.08000","4.59028","0.03534"
"9254","55.48800","4.62412","0.03494"
"9322","55.89600","4.65814","0.03496"
"9390","56.30400","4.69228","0.03542"
"9458","56.71200","4.72624","0.03560"
"9526","57.12000","4.76020","0.03479"
"9594","57.52800","4.79422","0.03487"
"9662","57.93600","4.82824","0.03518"
"9730","58.34400","4.86226","0.03458"
"9798","58.75200","4.89611","0.03488"
"9866","59.16000","4.93018","0.03489"
"9934","59.56800","4.96426","0.03585"
"10002","59.97600","4.99823","0.03562"
"10070","60.38400","5.03219","0.03515"
"10138","60.79200","5.06621","0.03514"
"10206","61.20000","5.10023","0.03505"
"10274","61.60800","5.13425","0.03564"
"10342","62.01600","5.16821","0.03571"
"10410","62.42400","5.20223","0.03548"
"10478","62.83200","5.23625","0.03620"
"10546","63.24000","5.27021","0.03585"
"10614","63.64800","5.30417","0.03548"
"10682","64.05600","5.33819","0.03588"
"10750","64.46400","5.37215","0.03658"
"10818","64.87200","5.40623","0.03674"
"10886","65.28000","5.44025","0.03658"
"10954","65.68800","5.47415","0.03604"
"11022","66.09600","5.50817","0.03642"
"11090","66.50400","5.54225","0.03651"
"11158","66.91200","5.57627","0.03622"
"11226","67.32000","5.61017","0.03672"
"11294","67.72800","5.64425","0.03640"
"11362","68.13600","5.67827","0.03647"
"11430","68.54400","5.71223","0.03662"
"11498","68.95200","5.74613","0.03641"
"11566","69.36000","5.78021","0.03653"
"11634","69.76800","5.81423","0.03696"
"11702","70.17600","5.84825","0.03652"
"11770","70.58400","5.88221","0.03734"
"11838","70.99200","5.91623","0.03736"
"11906","71.40000","5.95019","0.03638"
"11974","71.80800","5.98422","0.03682"
"12042","72.21600","6.01817","0.03669"
"12110","72.62400","6.05220","0.03723"
"12178","73.03200","6.08622","0.03718"
"12246","73.44000","6.12018","0.03742"
"12314","73.84800","6.15420","0.03721"
"12382","74.25600","6.18816","0.03785"
"12450","74.66400","6.22218","0.03761"
"12518","75.07200","6.25620","0.03809"
"12586","75.48000","6.29028","0.03837"
"12654","75.88800","6.32418","0.03808"
"12722","76.29600","6.35820","0.03755"
"12790","76.70400","6.39222","0.03753"
"12858","77.11200","6.42624","0.03840"
"12926","77.52000","6.46020","0.03828"
"12994","77.92800","6.49422","0.03937"
"13062","78.33600","6.52824","0.03827"
"13130","78.74400","6.56226","0.03867"
"13198","79.15200","6.59610","0.03870"
"13266","79.56000","6.63018","0.03889"
"13334","79.96800","6.66420","0.03886"
"13402","80.37600","6.69828","0.03930"
"13470","80.78400","6.73218","0.03857"
"13538","81.19200","6.76620","0.03913"
"13606","81.60000","6.80022","0.03960"
"13674","82.00800","6.83418","0.03984"
"13742","82.41600","6.86820","0.03960"
"13810","82.82400","6.90222","0.03876"
"13878","83.23200","6.93624","0.03970"
"13946","83.64000","6.97026","0.03920"
"14014","84.04800","7.00422","0.03938"
"14082","84.45600","7.03818","0.03967"
"14150","84.86400","7.07227","0.03984"
"14218","85.27200","7.10629","0.03982"
"14286","85.68000","7.14019","0.03994"
"14354","86.08800","7.17415","0.03965"
"14422","86.49600","7.20823","0.03955"
"14490","86.90400","7.24225","0.04017"
"14558","87.31200","7.27621","0.03946"
"14626","87.72000","7.31017","0.04035"
"14694","88.12800","7.34425","0.04012"
"14762","88.53600","7.37821","0.04078"
"14830","88.94400","7.41223","0.04020"
"14898","89.35200","7.44613","0.04020"
"14966","89.76000","7.48015","0.04051"
"15034","90.16800","7.51423","0.04055"
"15102","90.57600","7.54819","0.04052"
"15170","90.98400","7.58215","0.04059"
"15238","91.39200","7.61629","0.04034"
"15306","91.80000","7.65025","0.04053"
"15374","92.20800","7.68421","0.03998"
"15442","92.61600","7.71817","0.04072"
"15510","93.02400","7.75219","0.04006"
"15578","93.43200","7.78627","0.04008"
"15646","93.84000","7.82023","0.03958"
"15714","94.24800","7.85413","0.03998"
"15782","94.65600","7.88815","0.03972"
"15850","95.06400","7.92223","0.03949"
"15918","95.47200","7.95625","0.03959"
"15986","95.88000","7.99021","0.03998"
"16054","96.28800","8.02423","0.04017"
"16122","96.69600","8.05825","0.04024"
"16190","97.10400","8.09221","0.04033"
"16258","97.51200","8.12624","0.04045"
"16326","97.92000","8.16025","0.04027"
"16394","98.32800","8.19422","0.04038"
"16462","98.73600","8.22830","0.04068"
"16530","99.14400","8.26226","0.04075"
"16598","99.55200","8.29616","0.04052"
"16666","99.96000","8.33024","0.04065"
"16734","100.36800","8.36420","0.04073"
"16802","100.77600","8.39822","0.04162"
"16870","101.18400","8.43218","0.04154"
"16938","101.59200","8.46626","0.04133"
"17006","102.00000","8.50022","0.04139"
"17074","102.40800","8.53418","0.04116"
"17142","102.81600","8.56814","0.04117"
"17210","103.22400","8.60222","0.04137"
"17278","103.63200","8.63624","0.04061"
"17346","104.04000","8.67026","0.04192"
"17414","104.44800","8.70416","0.04195"
"17482","104.85600","8.73818","0.04183"
"17550","105.26400","8.77226","0.04183"
"17618","105.67200","8.80628","0.04206"
"17686","106.08000","8.84018","0.04230"
"17754","106.48800","8.87420","0.04253"
"17822","106.89600","8.90822","0.04198"
"17890","107.30400","8.94224","0.04198"
"17958","107.71200","8.97620","0.04218"
"18026","108.12000","9.01016","0.04220"
"18094","108.52800","9.04418","0.04210"
"18162","108.93600","9.07826","0.04192"
"18230","109.34400","9.11222","0.04175"
"18298","109.75200","9.14618","0.04249"
"18366","110.16000","9.18021","0.04266"
"18434","110.56800","9.21422","0.04295"
"18502","110.97600","9.24819","0.04269"
"18570","111.38400","9.28215","0.04268"
"18638","111.79200","9.31629","0.04247"
"18706","112.20000","9.35031","0.04280"
"18774","112.60800","9.38421","0.04286"
"18842","113.01600","9.41817","0.04318"
"18910","113.42400","9.45231","0.04287"
"18978","113.83200","9.48627","0.04325"
"19046","114.24000","9.52023","0.04342"
"19114","114.64800","9.55419","0.04332"
"19182","115.05600","9.58821","0.04377"
"19250","115.46400","9.62217","0.04289"
"19318","115.87200","9.65619","0.04320"
"19386","116.28000","9.69021","0.04371"
"19454","116.68800","9.72417","0.04377"
"19522","117.09600","9.75825","0.04310"
"19590","117.50400","9.79227","0.04371"
"19658","117.91200","9.82617","0.04357"
"19726","118.32000","9.86019","0.04414"
"19794","118.72800","9.89427","0.04376"
"19862","119.13600","9.92829","0.04410"
"19930","119.54400","9.96225","0.04442"
"19998","119.95200","9.99621","0.04445"
"20066","120.36000","10.03029","0.04415"
"20134","120.76800","10.06425","0.04443"
"20202","121.17600","10.09821","0.04446"
"20270","121.58400","10.13217","0.04447"
"20338","121.99200","10.16625","0.04470"
"20406","122.40000","10.20027","0.04458"
"20474","122.80800","10.23423","0.04486"
"20542","123.21600","10.26819","0.04464"
"20610","123.62400","10.30221","0.04466"
"20678","124.03200","10.33618","0.04440"
"20746","124.44000","10.37020","0.04443"
"20814","124.84800","10.40416","0.04472"
"20882","125.25600","10.43824","0.04446"
"20950","125.66400","10.47220","0.04493"
"21018","126.07200","10.50622","0.04465"
"21086","126.48000","10.54018","0.04421"
"21154","126.88800","10.57426","0.04417"
"21222","127.29600","10.60828","0.04377"
"21290","127.70400","10.64224","0.04397"
"21358","128.11200","10.67620","0.04425"
"21426","128.52000","10.71022","0.04446"
"21494","128.92800","10.74424","0.04418"
"21562","129.33600","10.77820","0.04432"
"21630","129.74400","10.81222","0.04474"
"21698","130.15200","10.84618","0.04444"
"21766","130.56000","10.88020","0.04472"
"21834","130.96800","10.91422","0.04490"
"21902","131.37600","10.94812","0.04473"
"21970","131.78400","10.98220","0.04516"
"22038","132.19200","11.01622","0.04493"
"22106","132.60000","11.05030","0.04486"
"22174","133.00800","11.08420","0.04481"
"22242","133.41600","11.11822","0.04465"
"22310","133.82400","11.15224","0.04476"
"22378","134.23200","11.18626","0.04523"
"22446","134.64000","11.22022","0.04510"
"22514","135.04800","11.25418","0.04520"
"22582","135.45600","11.28826","0.04536"
"22650","135.86400","11.32228","0.04525"
"22718","136.27200","11.35625","0.04568"
"22786","136.68000","11.39021","0.04555"
"22854","137.08800","11.42423","0.04564"
"22922","137.49600","11.45825","0.04623"
"22990","137.90400","11.49215","0.04638"
"23058","138.31200","11.52623","0.04633"
"23126","138.72000","11.56025","0.04641"
"23194","139.12800","11.59421","0.04669"
"23262","139.53600","11.62823","0.04676"
"23330","139.94400","11.66219","0.04641"
"23398","140.35200","11.69621","0.04674"
"23466","140.76000","11.73029","0.04680"
"23534","141.16800","11.76425","0.04678"
"23602","141.57600","11.79815","0.04727"
"23670","141.98400","11.83217","0.04736"
"23738","142.39200","11.86625","0.04717"
"23806","142.80000","11.90021","0.04741"
"23874","143.20800","11.93417","0.04695"
"23942","143.61600","11.96819","0.04715"
"24010","144.02400","12.00227","0.04714"
"24078","144.43200","12.03629","0.04763"
"24146","144.84000","12.07013","0.04776"
"24214","145.24800","12.10421","0.04747"
"24282","145.65600","12.13823","0.04801"
"24350","146.06400","12.17225","0.04816"
"24418","146.47200","12.20621","0.04830"
"24486","146.88000","12.24017","0.04800"
"24554","147.28800","12.27425","0.04818"
"24622","147.69600","12.30827","0.04851"
"24690","148.10400","12.34217","0.04842"
"24758","148.51200","12.37619","0.04886"
"24826","148.92000","12.41027","0.04874"
"24894","149.32800","12.44429","0.04860"
"24962","149.73600","12.47820","0.04906"
"25030","150.14400","12.51222","0.04928"
"25098","150.55200","12.54618","0.04934"
"25166","150.96000","12.58020","0.04923"
"25234","151.36800","12.61427","0.04886"
"25302","151.77600","12.64818","0.04882"
"25370","152.18400","12.68220","0.04918"
"25438","152.59200","12.71622","0.04919"
"25506","153.00000","12.75024","0.04942"
"25574","153.40800","12.78414","0.04963"
"25642","153.81600","12.81822","0.04956"
"25710","154.22400","12.85224","0.04980"
"25778","154.63200","12.88620","0.04957"
"25846","155.04000","12.92016","0.05012"
"25914","155.44800","12.95424","0.05039"
"25982","155.85600","12.98826","0.05003"
"26050","156.26400","13.02222","0.05012"
"26118","156.67200","13.05618","0.05018"
"26186","157.08000","13.09020","0.05057"
"26254","157.48800","13.12416","0.05069"
"26322","157.89600","13.15824","0.05085"
"26390","158.30400","13.19220","0.05068"
"26458","158.71200","13.22616","0.05138"
"26526","159.12000","13.26024","0.05118"
"26594","159.52800","13.29420","0.05166"
"26662","159.93600","13.32822","0.05175"
"26730","160.34400","13.36212","0.05169"
"26798","160.75200","13.39620","0.05176"
"26866","161.16000","13.43022","0.05215"
"26934","161.56800","13.46424","0.05202"
"27002","161.97600","13.49821","0.05176"
"27070","162.38400","13.53222","0.05132"
"27138","162.79200","13.56625","0.05156"
"27206","163.20000","13.60021","0.05198"
"27274","163.60800","13.63417","0.05212"
"27342","164.01600","13.66825","0.05207"
"27410","164.42400","13.70227","0.05237"
"27478","164.83200","13.73617","0.05272"
"27546","165.24000","13.77013","0.05284"
"27614","165.64800","13.80421","0.05295"
"27682","166.05600","13.83823","0.05341"
"27750","166.46400","13.87219","0.05342"
"27818","166.87200","13.90621","0.05338"
"27886","167.28000","13.94017","0.05410"
"27954","167.68800","13.97419","0.05433"
"28022","168.09600","14.00821","0.05434"
"28090","168.50400","14.04217","0.05468"
"28158","168.91200","14.07619","0.05496"
"28226","169.32000","14.11027","0.05524"
"28294","169.72800","14.14423","0.05481"
"28362","170.13600","14.17813","0.05576"
"28430","170.54400","14.21215","0.05526"
"28498","170.95200","14.24623","0.05553"
"28566","171.36000","14.28019","0.05528"
"28634","171.76800","14.31421","0.05485"
"28702","172.17600","14.34823","0.05395"
"28770","172.58400","14.38225","0.05491"
"28838","172.99200","14.41621","0.05566"
"28906","173.40000","14.45017","0.05539"
"28974","173.80800","14.48413","0.05562"
"29042","174.21600","14.51821","0.05584"
"29110","174.62400","14.55223","0.05548"
"29178","175.03200","14.58625","0.05594"
"29246","175.44000","14.62021","0.05624"
"29314","175.84800","14.65418","0.05666"
"29382","176.25600","14.68820","0.05692"
"29450","176.66400","14.72222","0.05731"
"29518","177.07200","14.75618","0.05759"
"29586","177.48000","14.79020","0.05809"
"29654","177.88800","14.82422","0.05815"
"29722","178.29600","14.85824","0.05837"
"29790","178.70400","14.89214","0.05863"
"29858","179.11200","14.92622","0.05927"
"29926","179.52000","14.96024","0.05936"
"29994","179.92800","14.99426","0.05995"
"30062","180.33600","15.02816","0.06006"
"30130","180.74400","15.06218","0.06072"
"30198","181.15200","15.09626","0.06042"
"30266","181.56000","15.13022","0.06073"
"30334","181.96800","15.16418","0.06092"
"30402","182.37600","15.19826","0.06087"
"30470","182.78400","15.23228","0.06162"
"30538","183.19200","15.26624","0.06110"
"30606","183.60000","15.30020","0.05670"
"30674","184.00800","15.33416","0.05740"
"30742","184.41600","15.36818","0.05768"
"30810","184.82400","15.40232","0.05812"
"30878","185.23200","15.43622","0.05811"
"30946","185.64000","15.47018","0.05869"
"31014","186.04800","15.50420","0.05909"
"31082","186.45600","15.53816","0.05916"
"31150","186.86400","15.57224","0.05974"
"31218","187.27200","15.60620","0.06002"
"31286","187.68000","15.64028","0.05950"
"31354","188.08800","15.67424","0.05986"
"31422","188.49600","15.70815","0.06010"
"31490","188.90400","15.74217","0.06093"
"31558","189.31200","15.77625","0.06103"
"31626","189.72000","15.81021","0.06169"
"31694","190.12800","15.84423","0.06115"
"31762","190.53600","15.87819","0.06150"
"31830","190.94400","15.91221","0.06191"
"31898","191.35200","15.94623","0.06190"
"31966","191.76000","15.98019","0.06264"
"32034","192.16800","16.01421","0.06289"
"32102","192.57600","16.04823","0.06289"
"32170","192.98400","16.08225","0.06349"
"32238","193.39200","16.11621","0.06382"
"32306","193.80000","16.15017","0.06445"
"32374","194.20800","16.18419","0.06420"
"32442","194.61600","16.21827","0.06467"
"32510","195.02400","16.25223","0.06512"
"32578","195.43200","16.28625","0.06555"
"32646","195.84000","16.32015","0.06578"
"32714","196.24800","16.35423","0.06634"
"32782","196.65600","16.38825","0.06705"
"32850","197.06400","16.42215","0.06717"
"32918","197.47200","16.45617","0.06758"
"32986","197.88000","16.49025","0.06777"
"33054","198.28800","16.52427","0.06770"
"33122","198.69600","16.55823","0.06865"
"33190","199.10400","16.59219","0.06902"
"33258","199.51200","16.62621","0.06880"
"33326","199.92000","16.66023","0.06959"
"33394","200.32800","16.69425","0.07041"
"33462","200.73600","16.72821","0.07041"
"33530","201.14400","16.76217","0.07067"
"33598","201.55200","16.79620","0.07104"
"33666","201.96000","16.83022","0.07202"
"33734","202.36800","16.86418","0.07175"
"33802","202.77600","16.89820","0.07241"
"33870","203.18400","16.93228","0.07252"
"33938","203.59200","16.96630","0.07312"
"34006","204.00000","17.00014","0.07399"
"34074","204.40800","17.03416","0.07359"
"34142","204.81600","17.06824","0.07435"
"34210","205.22400","17.10226","0.07498"
"34278","205.63200","17.13622","0.07554"
"34346","206.04000","17.17018","0.07590"
"34414","206.44800","17.20420","0.07594"
"34482","206.85600","17.23822","0.07618"
"34550","207.26400","17.27218","0.07718"
"34618","207.67200","17.30620","0.07709"
"34686","208.08000","17.34022","0.07764"
"34754","208.48800","17.37430","0.07809"
"34822","208.89600","17.40820","0.07845"
"34890","209.30400","17.44216","0.07922"
"34958","209.71200","17.47624","0.07993"
"35026","210.12000","17.51020","0.07951"
"35094","210.52800","17.54416","0.08036"
"35162","210.93600","17.57824","0.08140"
"35230","211.34400","17.61226","0.08169"
"35298","211.75200","17.64622","0.08165"
"35366","212.16000","17.68018","0.08220"
"35434","212.56800","17.71420","0.08298"
"35502","212.97600","17.74822","0.08282"
"35570","213.38400","17.78225","0.08322"
"35638","213.79200","17.81620","0.08406"
"35706","214.20000","17.85016","0.08412"
"35774","214.60800","17.88419","0.08473"
"35842","215.01600","17.91826","0.08486"
"35910","215.42400","17.95223","0.08564"
"35978","215.83200","17.98619","0.08604"
"36046","216.24000","18.02027","0.08655"
"36114","216.64800","18.05423","0.08697"
"36182","217.05600","18.08825","0.08748"
"36250","217.46400","18.12215","0.08840"
"36318","217.87200","18.15623","0.08816"
"36386","218.28000","18.19025","0.08887"
"36454","218.68800","18.22427","0.08897"
"36522","219.09600","18.25823","0.08937"
"36590","219.50400","18.29219","0.08939"
"36658","219.91200","18.32621","0.09035"
"36726","220.32000","18.36023","0.09064"
"36794","220.72800","18.39419","0.09120"
"36862","221.13600","18.42821","0.09142"
"36930","221.54400","18.46229","0.09180"
"36998","221.95200","18.49625","0.09239"
"37066","222.36000","18.53021","0.09262"
"37134","222.76800","18.56423","0.09306"
"37202","223.17600","18.59825","0.09342"
"37270","223.58400","18.63221","0.09340"
"37338","223.99200","18.66623","0.09378"
"37406","224.40000","18.70019","0.09361"
"37474","224.80800","18.73421","0.09401"
"37542","225.21600","18.76818","0.09489"
"37610","225.62400","18.80225","0.09483"
"37678","226.03200","18.83615","0.09537"
"37746","226.44000","18.87024","0.09564"
"37814","226.84800","18.90425","0.09600"
"37882","227.25600","18.93822","0.09616"
"37950","227.66400","18.97218","0.09675"
"38018","228.07200","19.00620","0.09698"
"38086","228.48000","19.04022","0.09737"
"38154","228.88800","19.07424","0.09755"
"38222","229.29600","19.10820","0.09752"
"38290","229.70400","19.14216","0.09779"
"38358","230.11200","19.17624","0.09829"
"38426","230.52000","19.21026","0.09864"
"38494","230.92800","19.24416","0.09907"
"38562","231.33600","19.27824","0.09881"
"38630","231.74400","19.31226","0.09916"
"38698","232.15200","19.34622","0.09921"
"38766","232.56000","19.38018","0.10025"
"38834","232.96800","19.41420","0.09995"
"38902","233.37600","19.44822","0.10050"
"38970","233.78400","19.48224","0.10044"
"39038","234.19200","19.51620","0.10143"
"39106","234.60000","19.55022","0.10122"
"39174","235.00800","19.58424","0.10220"
"39242","235.41600","19.61826","0.10207"
"39310","235.82400","19.65222","0.10294"
"39378","236.23200","19.68618","0.10312"
"39446","236.64000","19.72020","0.10326"
"39514","237.04800","19.75428","0.10458"
"39582","237.45600","19.78824","0.10519"
"39650","237.86400","19.82214","0.10480"
"39718","238.27200","19.85622","0.03069"
"39786","238.68000","19.89024","0.03069"
"39854","239.08800","19.92420","0.02857"
"39922","239.49600","19.95816","0.02823"
"39990","239.90400","19.99224","0.02768"
"40058","240.31200","20.02620","0.02729"
"40126","240.72000","20.06017","0.02807"
"40194","241.12800","20.09412","0.03079"
"40262","241.53600","20.12821","0.02977"
"40330","241.94400","20.16222","0.02952"
"40398","242.35200","20.19619","0.02975"
"40466","242.76000","20.23015","0.02859"
"40534","243.16800","20.26423","0.02923"
"40602","243.57600","20.29819","0.03040"
"40670","243.98400","20.33227","0.03020"
"40738","244.39200","20.36617","0.03011"
"40806","244.80000","20.40019","0.02945"
"40874","245.20800","20.43421","0.02899"
"40942","245.61600","20.46823","0.02894"
"41010","246.02400","20.50225","0.03061"
"41078","246.43200","20.53621","0.03092"
"41146","246.84000","20.57023","0.03050"
"41214","247.24800","20.60431","0.02980"
"41282","247.65600","20.63821","0.02988"
"41350","248.06400","20.67217","0.02955"
"41418","248.47200","20.70619","0.02971"
"41486","248.88000","20.74021","0.03011"
"41554","249.28800","20.77423","0.03017"
"41622","249.69600","20.80819","0.02981"
"41690","250.10400","20.84221","0.03013"
"41758","250.51200","20.87623","0.03083"
"41826","250.92000","20.91019","0.03077"
"41894","251.32800","20.94415","0.03089"
"41962","251.73600","20.97824","0.03054"
"42030","252.14400","21.01225","0.02971"
"42098","252.55200","21.04627","0.02939"
"42166","252.96000","21.08017","0.02926"
"42234","253.36800","21.11414","0.02963"
"42302","253.77600","21.14821","0.03050"
"42370","254.18400","21.18224","0.02996"
"42438","254.59200","21.21620","0.03007"
"42506","255.00000","21.25021","0.02969"
"42574","255.40800","21.28424","0.03006"
"42642","255.81600","21.31825","0.03074"
"42710","256.22400","21.35216","0.03059"
"42778","256.63200","21.38618","0.03097"
"42846","257.04000","21.42020","0.03072"
"42914","257.44800","21.45428","0.03135"
"42982","257.85600","21.48818","0.03126"
"43050","258.26400","21.52220","0.03174"
"43118","258.67200","21.55622","0.03167"
"43186","259.08000","21.59024","0.03144"
"43254","259.48800","21.62420","0.03117"
"43322","259.89600","21.65816","0.03108"
"43390","260.30400","21.69230","0.03083"
"43458","260.71200","21.72626","0.03074"
"43526","261.12000","21.76022","0.03093"
"43594","261.52800","21.79418","0.03103"
"43662","261.93600","21.82814","0.03072"
"43730","262.34400","21.86222","0.03160"
"43798","262.75200","21.89618","0.03109"
"43866","263.16000","21.93014","0.03120"
"43934","263.56800","21.96422","0.03125"
"44002","263.97600","21.99818","0.03116"
"44070","264.38400","22.03226","0.03165"
"44138","264.79200","22.06616","0.03133"
"44206","265.20000","22.10025","0.03145"
"44274","265.60800","22.13426","0.03048"
"44342","266.01600","22.16822","0.03117"
"44410","266.42400","22.20213","0.03068"
"44478","266.83200","22.23620","0.03134"
"44546","267.24000","22.27023","0.03074"
"44614","267.64800","22.30425","0.02929"
"44682","268.05600","22.33821","0.02931"
"44750","268.46400","22.37223","0.02947"
"44818","268.87200","22.40619","0.02990"
"44886","269.28000","22.44027","0.03032"
"44954","269.68800","22.47423","0.03040"
"45022","270.09600","22.50819","0.03053"
"45090","270.50400","22.54221","0.02961"
"45158","270.91200","22.57623","0.02603"
"45226","271.32000","22.61019","0.02829"
"45294","271.72800","22.64415","0.02746"
"45362","272.13600","22.67823","0.02707"
"45430","272.54400","22.71219","0.02738"
"45498","272.95200","22.74621","0.02720"
"45566","273.36000","22.78017","0.02691"
"45634","273.76800","22.81425","0.02691"
"45702","274.17600","22.84827","0.02754"
"45770","274.58400","22.88223","0.02732"
"45838","274.99200","22.91619","0.02677"
"45906","275.40000","22.95021","0.02739"
"45974","275.80800","22.98423","0.02784"
"46042","276.21600","23.01825","0.02775"
"46110","276.62400","23.05221","0.02797"
"46178","277.03200","23.08618","0.02794"
"46246","277.44000","23.12020","0.02728"
"46314","277.84800","23.15421","0.02741"
"46382","278.25600","23.18817","0.02811"
"46450","278.66400","23.22219","0.02803"
"46518","279.07200","23.25622","0.02755"
"46586","279.48000","23.29024","0.02837"
"46654","279.88800","23.32420","0.02829"
"46722","280.29600","23.35822","0.02819"
"46790","280.70400","23.39218","0.02771"
"46858","281.11200","23.42626","0.02784"
"46926","281.52000","23.46022","0.02799"
"46994","281.92800","23.49418","0.02812"
"47062","282.33600","23.52826","0.02778"
"47130","282.74400","23.56228","0.02816"
"47198","283.15200","23.59618","0.02805"
"47266","283.56000","23.63020","0.02786"
"47334","283.96800","23.66422","0.02843"
"47402","284.37600","23.69824","0.02799"
"47470","284.78400","23.73220","0.02828"
"47538","285.19200","23.76616","0.02799"
"47606","285.60000","23.80024","0.02854"
"47674","286.00800","23.83426","0.02868"
"47742","286.41600","23.86822","0.02842"
"47810","286.82400","23.90218","0.02848"
"47878","287.23200","23.93620","0.02899"
"47946","287.64000","23.97022","0.02879"
"48014","288.04800","24.00424","0.02873"
"48082","288.45600","24.03820","0.02889"
"48150","288.86400","24.07222","0.02902"
"48218","289.27200","24.10630","0.02882"
"48286","289.68000","24.14026","0.02889"
"48354","290.08800","24.17410","0.02917"
"48422","290.49600","24.20819","0.02941"
"48490","290.90400","24.24226","0.02861"
"48558","291.31200","24.27622","0.02886"
"48626","291.72000","24.31018","0.02928"
"48694","292.12800","24.34420","0.02911"
"48762","292.53600","24.37828","0.02861"
"48830","292.94400","24.41219","0.02867"
"48898","293.35200","24.44621","0.02765"
"48966","293.76000","24.48017","0.02702"
"49034","294.16800","24.51424","0.02788"
"49102","294.57600","24.54827","0.02773"
"49170","294.98400","24.58217","0.02775"
"49238","295.39200","24.61619","0.02753"
"49306","295.80000","24.65021","0.02697"
"49374","296.20800","24.68423","0.02751"
"49442","296.61600","24.71819","0.02751"
"49510","297.02400","24.75221","0.02751"
"49578","297.43200","24.78623","0.02828"
"49646","297.84000","24.82019","0.02785"
"49714","298.24800","24.85421","0.02755"
"49782","298.65600","24.88817","0.02692"
"49850","299.06400","24.92225","0.02730"
"49918","299.47200","24.95621","0.02733"
"49986","299.88000","24.99023","0.02760"
"50054","300.28800","25.02413","0.02727"
"50122","300.69600","25.05821","0.02708"
"50190","301.10400","25.09223","0.02782"
"50258","301.51200","25.12626","0.02765"
"50326","301.92000","25.16021","0.02742"
"50394","302.32800","25.19423","0.02824"
"50462","302.73600","25.22820","0.02790"
"50530","303.14400","25.26221","0.02832"
"50598","303.55200","25.29617","0.02818"
"50666","303.96000","25.33019","0.02784"
"50734","304.36800","25.36422","0.02819"
"50802","304.77600","25.39824","0.02834"
"50870","305.18400","25.43220","0.02908"
"50938","305.59200","25.46616","0.02921"
"51006","306.00000","25.50024","0.02922"
"51074","306.40800","25.53426","0.02885"
"51142","306.81600","25.56821","0.02882"
"51210","307.22400","25.60218","0.02918"
"51278","307.63200","25.63626","0.02891"
"51346","308.04000","25.67028","0.02939"
"51414","308.44800","25.70418","0.02894"
"51482","308.85600","25.73820","0.02919"
"51550","309.26400","25.77222","0.02921"
"51618","309.67200","25.80624","0.02949"
"51686","310.08000","25.84026","0.02974"
"51754","310.48800","25.87422","0.02964"
"51822","310.89600","25.90824","0.02943"
"51890","311.30400","25.94220","0.03043"
"51958","311.71200","25.97622","0.02977"
"52026","312.12000","26.01018","0.02997"
"52094","312.52800","26.04426","0.03019"
"52162","312.93600","26.07822","0.03030"
"52230","313.34400","26.11224","0.03017"
"52298","313.75200","26.14614","0.03054"
"52366","314.16000","26.18016","0.03106"
"52434","314.56800","26.21424","0.03031"
"52502","314.97600","26.24826","0.03096"
"52570","315.38400","26.28222","0.03084"
"52638","315.79200","26.31618","0.03084"
"52706","316.20000","26.35026","0.03127"
"52774","316.60800","26.38428","0.03144"
"52842","317.01600","26.41812","0.03149"
"52910","317.42400","26.45221","0.03077"
"52978","317.83200","26.48628","0.03088"
"53046","318.24000","26.52025","0.03125"
"53114","318.64800","26.55415","0.03139"
"53182","319.05600","26.58817","0.03165"
"53250","319.46400","26.62225","0.03151"
"53318","319.87200","26.65627","0.03122"
"53386","320.28000","26.69023","0.03210"
"53454","320.68800","26.72425","0.03187"
"53522","321.09600","26.75821","0.03185"
"53590","321.50400","26.79223","0.03201"
"53658","321.91200","26.82619","0.03169"
"53726","322.32000","26.86015","0.03167"
"53794","322.72800","26.89423","0.03247"
"53862","323.13600","26.92831","0.03089"
"53930","323.54400","26.96227","0.03110"
"53998","323.95200","26.99617","0.03068"
"54066","324.36000","27.03025","0.03073"
"54134","324.76800","27.06421","0.03107"
"54202","325.17600","27.09823","0.03124"
"54270","325.58400","27.13219","0.03159"
"54338","325.99200","27.16621","0.03095"
"54406","326.40000","27.20023","0.03164"
"54474","326.80800","27.23419","0.03179"
"54542","327.21600","27.26815","0.03133"
"54610","327.62400","27.30223","0.03147"
"54678","328.03200","27.33625","0.03150"
"54746","328.44000","27.37027","0.03166"
"54814","328.84800","27.40417","0.03204"
"54882","329.25600","27.43820","0.03208"
"54950","329.66400","27.47221","0.03219"
"55018","330.07200","27.50624","0.03254"
"55086","330.48000","27.54020","0.03248"
"55154","330.88800","27.57422","0.03216"
"55222","331.29600","27.60824","0.03300"
"55290","331.70400","27.64226","0.03275"
"55358","332.11200","27.67622","0.03267"
"55426","332.52000","27.71018","0.03267"
"55494","332.92800","27.74420","0.03321"
"55562","333.33600","27.77828","0.03304"
"55630","333.74400","27.81224","0.03234"
"55698","334.15200","27.84620","0.03358"
"55766","334.56000","27.88022","0.03341"
"55834","334.96800","27.91424","0.03405"
"55902","335.37600","27.94820","0.03357"
"55970","335.78400","27.98216","0.03412"
"56038","336.19200","28.01624","0.03371"
"56106","336.60000","28.05020","0.03375"
"56174","337.00800","28.08422","0.03404"
"56242","337.41600","28.11812","0.03426"
"56310","337.82400","28.15220","0.03511"
"56378","338.23200","28.18622","0.03420"
"56446","338.64000","28.22024","0.03510"
"56514","339.04800","28.25420","0.03445"
"56582","339.45600","28.28816","0.03457"
"56650","339.86400","28.32218","0.03336"
"56718","340.27200","28.35626","0.03234"
"56786","340.68000","28.39022","0.03304"
"56854","341.08800","28.42424","0.03337"
"56922","341.49600","28.45827","0.03381"
"56990","341.90400","28.49222","0.03379"
"57058","342.31200","28.52619","0.03338"
"57126","342.72000","28.56021","0.03360"
"57194","343.12800","28.59422","0.03376"
"57262","343.53600","28.62824","0.03438"
"57330","343.94400","28.66221","0.03461"
"57398","344.35200","28.69617","0.03449"
"57466","344.76000","28.73025","0.03463"
"57534","345.16800","28.76421","0.03477"
"57602","345.57600","28.79817","0.03489"
"57670","345.98400","28.83219","0.03487"
"57738","346.39200","28.86627","0.03490"
"57806","346.80000","28.90023","0.03533"
"57874","347.20800","28.93425","0.03464"
"57942","347.61600","28.96821","0.03490"
"58010","348.02400","29.00217","0.03511"
"58078","348.43200","29.03625","0.03524"
"58146","348.84000","29.07021","0.03550"
"58214","349.24800","29.10417","0.03490"
"58282","349.65600","29.13825","0.03565"
"58350","350.06400","29.17221","0.03542"
"58418","350.47200","29.20623","0.03570"
"58486","350.88000","29.24019","0.03623"
"58554","351.28800","29.27421","0.03568"
"58622","351.69600","29.30829","0.03570"
"58690","352.10400","29.34225","0.03654"
"58758","352.51200","29.37615","0.03608"
"58826","352.92000","29.41023","0.03661"
"58894","353.32800","29.44426","0.03671"
"58962","353.73600","29.47821","0.03671"
"59030","354.14400","29.51223","0.03622"
"59098","354.55200","29.54619","0.03633"
"59166","354.96000","29.58021","0.03585"
"59234","355.36800","29.61423","0.03520"
"59302","355.77600","29.64820","0.03580"
"59370","356.18400","29.68222","0.03567"
"59438","356.59200","29.71623","0.03434"
"59506","357.00000","29.75026","0.03519"
"59574","357.40800","29.78422","0.03486"
"59642","357.81600","29.81818","0.03485"
"59710","358.22400","29.85226","0.03533"
"59778","358.63200","29.88628","0.03552"
"59846","359.04000","29.92024","0.03565"
"59914","359.44800","29.95420","0.03510"
"59982","359.85600","29.98822","0.03537"
"60050","360.26400","30.02224","0.03561"
"60118","360.67200","30.05620","0.03505"
"60186","361.08000","30.09016","0.03533"
"60254","361.48800","30.12424","0.03464"
"60322","361.89600","30.15826","0.03472"
"60390","362.30400","30.19222","0.03486"
"60458","362.71200","30.22618","0.03526"
"60526","363.12000","30.26020","0.03457"
"60594","363.52800","30.29422","0.03465"
"60662","363.93600","30.32824","0.03521"
"60730","364.34400","30.36220","0.03516"
"60798","364.75200","30.39628","0.03562"
"60866","365.16000","30.43024","0.03640"
"60934","365.56800","30.46420","0.03610"
"61002","365.97600","30.49816","0.03594"
"61070","366.38400","30.53218","0.03585"
"61138","366.79200","30.56620","0.03575"
"61206","367.20000","30.60028","0.03599"
"61274","367.60800","30.63418","0.03540"
"61342","368.01600","30.66821","0.03531"
"61410","368.42400","30.70222","0.03582"
"61478","368.83200","30.73625","0.03570"
"61546","369.24000","30.77021","0.03622"
"61614","369.64800","30.80416","0.03621"
"61682","370.05600","30.83825","0.03608"
"61750","370.46400","30.87226","0.03587"
"61818","370.87200","30.90617","0.03615"
"61886","371.28000","30.94025","0.03652"
"61954","371.68800","30.97427","0.03668"
"62022","372.09600","31.00823","0.03634"
"62090","372.50400","31.04225","0.03615"
"62158","372.91200","31.07621","0.03673"
"62226","373.32000","31.11023","0.03650"
"62294","373.72800","31.14419","0.03625"
"62362","374.13600","31.17821","0.03619"
"62430","374.54400","31.21223","0.03675"
"62498","374.95200","31.24619","0.03706"
"62566","375.36000","31.28027","0.03713"
"62634","375.76800","31.31423","0.03682"
"62702","376.17600","31.34813","0.03682"
"62770","376.58400","31.38221","0.03697"
"62838","376.99200","31.41629","0.03703"
"62906","377.40000","31.45025","0.03725"
"62974","377.80800","31.48421","0.03725"
"63042","378.21600","31.51817","0.03771"
"63110","378.62400","31.55225","0.03741"
"63178","379.03200","31.58621","0.03686"
"63246","379.44000","31.62017","0.03771"
"63314","379.84800","31.65419","0.03743"
"63382","380.25600","31.68827","0.03741"
"63450","380.66400","31.72223","0.03678"
"63518","381.07200","31.75619","0.03707"
"63586","381.48000","31.79015","0.03684"
"63654","381.88800","31.82423","0.03726"
"63722","382.29600","31.85825","0.03643"
"63790","382.70400","31.89221","0.03671"
"63858","383.11200","31.92617","0.03704"
"63926","383.52000","31.96026","0.03718"
"63994","383.92800","31.99422","0.03679"
"64062","384.33600","32.02824","0.03688"
"64130","384.74400","32.06219","0.03533"
"64198","385.15200","32.09628","0.03545"
"64266","385.56000","32.13030","0.03516"
"64334","385.96800","32.16420","0.03500"
"64402","386.37600","32.19816","0.03590"
"64470","386.78400","32.23218","0.03530"
"64538","387.19200","32.26626","0.03471"
"64606","387.60000","32.30022","0.03547"
"64674","388.00800","32.33418","0.03576"
"64742","388.41600","32.36820","0.03637"
"64810","388.82400","32.40222","0.03607"
"64878","389.23200","32.43624","0.03622"
"64946","389.64000","32.47014","0.03600"
"65014","390.04800","32.50422","0.03639"
"65082","390.45600","32.53824","0.03637"
"65150","390.86400","32.57226","0.03620"
"65218","391.27200","32.60616","0.03648"
"65286","391.68000","32.64018","0.03678"
"65354","392.08800","32.67426","0.03632"
"65422","392.49600","32.70828","0.03707"
"65490","392.90400","32.74218","0.03691"
"65558","393.31200","32.77620","0.03713"
"65626","393.72000","32.81028","0.03690"
"65694","394.12800","32.84424","0.03692"
"65762","394.53600","32.87815","0.03706"
"65830","394.94400","32.91222","0.03705"
"65898","395.35200","32.94624","0.03754"
"65966","395.76000","32.98026","0.03789"
"66034","396.16800","33.01417","0.03734"
"66102","396.57600","33.04819","0.03804"
"66170","396.98400","33.08221","0.03811"
"66238","397.39200","33.11617","0.03834"
"66306","397.80000","33.15018","0.03876"
"66374","398.20800","33.18421","0.03905"
"66442","398.61600","33.21823","0.03925"
"66510","399.02400","33.25219","0.03946"
"66578","399.43200","33.28621","0.04038"
"66646","399.84000","33.32017","0.03991"
"66714","400.24800","33.35419","0.03975"
"66782","400.65600","33.38821","0.03679"
"66850","401.06400","33.42229","0.03743"
"66918","401.47200","33.45619","0.03650"
"66986","401.88000","33.49021","0.03646"
"67054","402.28800","33.52423","0.03634"
"67122","402.69600","33.55825","0.03668"
"67190","403.10400","33.59215","0.03663"
"67258","403.51200","33.62623","0.03698"
"67326","403.92000","33.66025","0.03753"
"67394","404.32800","33.69427","0.03754"
"67462","404.73600","33.72817","0.03753"
"67530","405.14400","33.76219","0.03782"
"67598","405.55200","33.79622","0.03802"
"67666","405.96000","33.83023","0.03821"
"67734","406.36800","33.86419","0.03807"
"67802","406.77600","33.89821","0.03868"
"67870","407.18400","33.93224","0.03885"
"67938","407.59200","33.96631","0.03911"
"68006","408.00000","34.00021","0.03960"
"68074","408.40800","34.03417","0.03943"
"68142","408.81600","34.06819","0.03951"
"68210","409.22400","34.10221","0.03912"
"68278","409.63200","34.13623","0.03978"
"68346","410.04000","34.17020","0.03994"
"68414","410.44800","34.20422","0.03995"
"68482","410.85600","34.23824","0.04031"
"68550","411.26400","34.27226","0.04066"
"68618","411.67200","34.30616","0.04085"
"68686","412.08000","34.34024","0.04103"
"68754","412.48800","34.37420","0.04098"
"68822","412.89600","34.40822","0.04132"
"68890","413.30400","34.44218","0.04174"
"68958","413.71200","34.47626","0.04166"
"69026","414.12000","34.51028","0.04199"
"69094","414.52800","34.54424","0.04258"
"69162","414.93600","34.57814","0.04191"
"69230","415.34400","34.61222","0.04307"
"69298","415.75200","34.64618","0.04344"
"69366","416.16000","34.68020","0.04298"
"69434","416.56800","34.71416","0.04356"
"69502","416.97600","34.74818","0.04406"
"69570","417.38400","34.78220","0.04431"
"69638","417.79200","34.81622","0.04457"
"69706","418.20000","34.85019","0.04494"
"69774","418.60800","34.88420","0.04494"
"69842","419.01600","34.91822","0.04499"
"69910","419.42400","34.95224","0.04498"
"69978","419.83200","34.98621","0.04532"
"70046","420.24000","35.02016","0.04542"
"70114","420.64800","35.05424","0.04568"
"70182","421.05600","35.08820","0.04562"
"70250","421.46400","35.12222","0.04592"
"70318","421.87200","35.15619","0.04632"
"70386","422.28000","35.19027","0.04647"
"70454","422.68800","35.22422","0.04650"
"70522","423.09600","35.25819","0.04641"
"70590","423.50400","35.29215","0.04610"
"70658","423.91200","35.32623","0.04672"
"70726","424.32000","35.36025","0.04696"
"70794","424.72800","35.39421","0.04714"
"70862","425.13600","35.42817","0.04744"
"70930","425.54400","35.46213","0.04748"
"70998","425.95200","35.49621","0.04773"
"71066","426.36000","35.53023","0.04823"
"71134","426.76800","35.56419","0.04856"
"71202","427.17600","35.59827","0.04883"
"71270","427.58400","35.63223","0.04909"
"71338","427.99200","35.66619","0.04960"
"71406","428.40000","35.70021","0.04988"
"71474","428.80800","35.73417","0.05042"
"71542","429.21600","35.76825","0.05075"
"71610","429.62400","35.80227","0.05077"
"71678","430.03200","35.83623","0.05183"
"71746","430.44000","35.87019","0.05209"
"71814","430.84800","35.90427","0.05288"
"71882","431.25600","35.93818","0.05378"
"71950","431.66400","35.97219","0.05416"
"72018","432.07200","36.00615","0.05478"
"72086","432.48000","36.04023","0.05571"
"72154","432.88800","36.07425","0.05658"
"72222","433.29600","36.10822","0.05683"
"72290","433.70400","36.14217","0.04053"
"72358","434.11200","36.17619","0.04125"
"72426","434.52000","36.21022","0.04015"
"72494","434.92800","36.24424","0.04240"
"72562","435.33600","36.27819","0.04133"
"72630","435.74400","36.31221","0.03926"
"72698","436.15200","36.34624","0.03983"
"72766","436.56000","36.38026","0.04071"
"72834","436.96800","36.41416","0.04266"
"72902","437.37600","36.44824","0.04274"
"72970","437.78400","36.48225","0.04206"
"73038","438.19200","36.51622","0.04065"
"73106","438.60000","36.55012","0.04148"
"73174","439.00800","36.58414","0.04097"
"73242","439.41600","36.61822","0.04385"
"73310","439.82400","36.65224","0.04169"
"73378","440.23200","36.68620","0.04371"
"73446","440.64000","36.72022","0.04152"
"73514","441.04800","36.75424","0.04306"
"73582","441.45600","36.78820","0.04181"
"73650","441.86400","36.82216","0.04422"
"73718","442.27200","36.85618","0.04279"
"73786","442.68000","36.89026","0.04456"
"73854","443.08800","36.92428","0.04263"
"73922","443.49600","36.95818","0.04435"
"73990","443.90400","36.99220","0.04469"
"74058","444.31200","37.02622","0.04519"
"74126","444.72000","37.06024","0.04615"
"74194","445.12800","37.09420","0.04415"
"74262","445.53600","37.12822","0.04522"
"74330","445.94400","37.16224","0.04513"
"74398","446.35200","37.19621","0.04678"
"74466","446.76000","37.23016","0.04702"
"74534","447.16800","37.26419","0.04564"
"74602","447.57600","37.29821","0.04648"
"74670","447.98400","37.33223","0.04640"
"74738","448.39200","37.36618","0.04768"
"74806","448.80000","37.40020","0.04768"
"74874","449.20800","37.43423","0.04760"
"74942","449.61600","37.46825","0.04784"
"75010","450.02400","37.50221","0.04763"
"75078","450.43200","37.53622","0.04805"
"75146","450.84000","37.57025","0.04763"
"75214","451.24800","37.60421","0.04804"
"75282","451.65600","37.63823","0.04822"
"75350","452.06400","37.67219","0.04820"
"75418","452.47200","37.70615","0.04887"
"75486","452.88000","37.74023","0.04897"
"75554","453.28800","37.77425","0.04936"
"75622","453.69600","37.80815","0.04955"
"75690","454.10400","37.84217","0.04894"
"75758","454.51200","37.87619","0.04987"
"75826","454.92000","37.91027","0.05050"
"75894","455.32800","37.94423","0.05104"
"75962","455.73600","37.97819","0.05166"
"76030","456.14400","38.01227","0.05180"
"76098","456.55200","38.04623","0.05218"
"76166","456.96000","38.08025","0.05267"
"76234","457.36800","38.11421","0.05275"
"76302","457.77600","38.14830","0.05387"
"76370","458.18400","38.18232","0.05472"
"76438","458.59200","38.21621","0.05558"
"76506","459.00000","38.25023","0.05628"
"76574","459.40800","38.28419","0.05674"
"76642","459.81600","38.31822","0.05610"
"76710","460.22400","38.35218","0.05774"
"76778","460.63200","38.38614","0.05852"
"76846","461.04000","38.42022","0.05982"
"76914","461.44800","38.45417","0.06045"
"76982","461.85600","38.48820","0.06011"
"77050","462.26400","38.52216","0.05957"
"77118","462.67200","38.55624","0.06069"
"77186","463.08000","38.59026","0.06069"
"77254","463.48800","38.62428","0.06294"
"77322","463.89600","38.65824","0.06467"
"77390","464.30400","38.69220","0.06473"
"77458","464.71200","38.72628","0.06605"
"77526","465.12000","38.76018","0.06783"
"77594","465.52800","38.79420","0.06859"
"77662","465.93600","38.82822","0.06969"
"77730","466.34400","38.86224","0.05068"
"77798","466.75200","38.89632","0.05179"
"77866","467.16000","38.93016","0.05249"
"77934","467.56800","38.96418","0.05200"
"78002","467.97600","38.99820","0.05321"
"78070","468.38400","39.03228","0.05312"
"78138","468.79200","39.06618","0.05309"
"78206","469.20000","39.10020","0.05497"
"78274","469.60800","39.13422","0.05592"
"78342","470.01600","39.16824","0.05761"
"78410","470.42400","39.20220","0.05620"
"78478","470.83200","39.23623","0.05687"
"78546","471.24000","39.27024","0.05574"
"78614","471.64800","39.30426","0.05770"
"78682","472.05600","39.33822","0.05906"
"78750","472.46400","39.37218","0.06032"
"78818","472.87200","39.40620","0.06086"
"78886","473.28000","39.44023","0.05997"
"78954","473.68800","39.47419","0.06073"
"79022","474.09600","39.50820","0.06194"
"79090","474.50400","39.54223","0.06324"
"79158","474.91200","39.57618","0.06484"
"79226","475.32000","39.61021","0.06569"
"79294","475.72800","39.64411","0.06632"
"79362","476.13600","39.67825","0.06614"
"79430","476.54400","39.71227","0.05981"
"79498","476.95200","39.74622","0.06053"
"79566","477.36000","39.78012","0.06060"
"79634","477.76800","39.81421","0.06142"
"79702","478.17600","39.84823","0.06154"
"79770","478.58400","39.88225","0.06334"
"79838","478.99200","39.91621","0.06384"
"79906","479.40000","39.95023","0.06515"
"79974","479.80800","39.98425","0.06648"
"80042","480.21600","40.01827","0.06716"
"80110","480.62400","40.05217","0.06798"
"80178","481.03200","40.08619","0.06925"
"80246","481.44000","40.12020","0.07056"
"80314","481.84800","40.15423","0.07144"
"80382","482.25600","40.18819","0.07244"
"80450","482.66400","40.22221","0.07347"
"80518","483.07200","40.25623","0.07438"
"80586","483.48000","40.29019","0.07547"
"80654","483.88800","40.32421","0.07651"
"80722","484.29600","40.35823","0.07804"
"80790","484.70400","40.39225","0.07910"
"80858","485.11200","40.42621","0.07974"
"80926","485.52000","40.46023","0.08104"
"80994","485.92800","40.49413","0.08296"
"81062","486.33600","40.52816","0.08424"
"81130","486.74400","40.56223","0.08546"
"81198","487.15200","40.59626","0.08661"
"81266","487.56000","40.63016","0.08771"
"81334","487.96800","40.66417","0.08947"
"81402","488.37600","40.69820","0.09039"
"81470","488.78400","40.73228","0.09140"
"81538","489.19200","40.76618","0.09266"
"81606","489.60000","40.80020","0.09384"
"81674","490.00800","40.83428","0.09473"
"81742","490.41600","40.86824","0.09518"
"81810","490.82400","40.90214","0.09641"
"81878","491.23200","40.93616","0.09722"
"81946","491.64000","40.97018","0.09771"
"82014","492.04800","41.00426","0.09880"
"82082","492.45600","41.03822","0.09947"
"82150","492.86400","41.07218","0.10044"
"82218","493.27200","41.10620","0.10122"
"82286","493.68000","41.14022","0.10283"
"82354","494.08800","41.17418","0.10335"
"82422","494.49600","41.20820","0.10455"
"82490","494.90400","41.24222","0.10540"
"82558","495.31200","41.27630","0.04963"
"82626","495.72000","41.31020","0.04846"
"82694","496.12800","41.34416","0.02153"
"82762","496.53600","41.37825","0.01955"
"82830","496.94400","41.41220","0.02170"
"82898","497.35200","41.44622","0.02045"
"82966","497.76000","41.48018","0.01965"
"83034","498.16800","41.51421","0.02159"
"83102","498.57600","41.54822","0.02098"
"83170","498.98400","41.58218","0.02052"
"83238","499.39200","41.61615","0.02059"
"83306","499.80000","41.65029","0.02102"
"83374","500.20800","41.68425","0.02091"
"83442","500.61600","41.71821","0.02038"
"83510","501.02400","41.75216","0.02089"
"83578","501.43200","41.78619","0.02047"
"83646","501.84000","41.82021","0.02040"
"83714","502.24800","41.85423","0.02140"
"83782","502.65600","41.88819","0.02048"
"83850","503.06400","41.92220","0.01987"
"83918","503.47200","41.95623","0.02072"
"83986","503.88000","41.99019","0.02054"
"84054","504.28800","42.02421","0.02040"
"84114","504.64800","42.05423","0.02091"