File: Trajectories_together/170225_1Specimen_RawData_1.csv
"","V1","V2","V3"
"1","End date","2/25/2017",""
"2","Specimen label","2AT_11",""
"3","Maximum Load","0.12005","N"
"4","Time","Extension","Load"
"5","(s)","(mm)","(N)"
"6","0.00000","0.00000","-0.00002"
"60","0.32400","0.02679","-0.00012"
"114","0.64800","0.05417","0.00041"
"168","0.97200","0.08113","0.00041"
"222","1.29600","0.10816","0.00066"
"276","1.62000","0.13512","0.00103"
"330","1.94400","0.16215","0.00131"
"384","2.26800","0.18911","0.00152"
"438","2.59200","0.21614","0.00164"
"492","2.91600","0.24316","0.00209"
"546","3.24000","0.27007","0.00161"
"600","3.56400","0.29709","0.00184"
"654","3.88800","0.32406","0.00199"
"708","4.21200","0.35114","0.00171"
"762","4.53600","0.37817","0.00154"
"816","4.86000","0.40513","0.00225"
"870","5.18400","0.43210","0.00180"
"924","5.50800","0.45912","0.00285"
"978","5.83200","0.48615","0.00263"
"1032","6.15600","0.51311","0.00225"
"1086","6.48000","0.54008","0.00314"
"1140","6.80400","0.56716","0.00306"
"1194","7.12800","0.59407","0.00368"
"1248","7.45200","0.62109","0.00277"
"1302","7.77600","0.64812","0.00281"
"1356","8.10000","0.67514","0.00366"
"1410","8.42400","0.70211","0.00348"
"1464","8.74800","0.72907","0.00391"
"1518","9.07200","0.75610","0.00384"
"1572","9.39600","0.78318","0.00365"
"1626","9.72000","0.81009","0.00408"
"1680","10.04400","0.83711","0.00419"
"1734","10.36800","0.86408","0.00433"
"1788","10.69200","0.89110","0.00398"
"1842","11.01600","0.91813","0.00428"
"1896","11.34000","0.94509","0.00452"
"1950","11.66400","0.97212","0.00459"
"2004","11.98800","0.99914","0.00434"
"2058","12.31200","1.02617","0.00463"
"2112","12.63600","1.05313","0.00480"
"2166","12.96000","1.08004","0.00481"
"2220","13.28400","1.10718","0.00493"
"2274","13.60800","1.13409","0.00538"
"2328","13.93200","1.16111","0.00488"
"2382","14.25600","1.18814","0.00533"
"2436","14.58000","1.21510","0.00555"
"2490","14.90400","1.24213","0.00576"
"2544","15.22800","1.26909","0.00581"
"2598","15.55200","1.29612","0.00588"
"2652","15.87600","1.32314","0.00559"
"2706","16.20000","1.35005","0.00618"
"2760","16.52400","1.37713","0.00608"
"2814","16.84800","1.40416","0.00599"
"2868","17.17200","1.43112","0.00606"
"2922","17.49600","1.45815","0.00636"
"2976","17.82000","1.48505","0.00613"
"3030","18.14400","1.51208","0.00601"
"3084","18.46800","1.53910","0.00669"
"3138","18.79200","1.56607","0.00662"
"3192","19.11600","1.59315","0.00672"
"3246","19.44000","1.62012","0.00617"
"3300","19.76400","1.64714","0.00664"
"3354","20.08800","1.67417","0.00649"
"3408","20.41200","1.70107","0.00710"
"3462","20.73600","1.72816","0.00704"
"3516","21.06000","1.75500","0.00722"
"3570","21.38400","1.78215","0.00710"
"3624","21.70800","1.80911","0.00709"
"3678","22.03200","1.83614","0.00717"
"3732","22.35600","1.86316","0.00688"
"3786","22.68000","1.89007","0.00783"
"3840","23.00400","1.91715","0.00787"
"3894","23.32800","1.94412","0.00803"
"3948","23.65200","1.97108","0.00759"
"4002","23.97600","1.99811","0.00791"
"4056","24.30000","2.02507","0.00853"
"4110","24.62400","2.05216","0.00836"
"4164","24.94800","2.07912","0.00844"
"4218","25.27200","2.10609","0.00780"
"4272","25.59600","2.13311","0.00831"
"4326","25.92000","2.16008","0.00856"
"4380","26.24400","2.18710","0.00903"
"4434","26.56800","2.21413","0.00867"
"4488","26.89200","2.24115","0.00865"
"4542","27.21600","2.26812","0.00868"
"4596","27.54000","2.29508","0.00872"
"4650","27.86400","2.32211","0.00898"
"4704","28.18800","2.34913","0.00890"
"4758","28.51200","2.37610","0.00890"
"4812","28.83600","2.40306","0.00888"
"4866","29.16000","2.43003","0.00955"
"4920","29.48400","2.45717","0.00966"
"4974","29.80800","2.48414","0.00973"
"5028","30.13200","2.51110","0.01005"
"5082","30.45600","2.53813","0.01017"
"5136","30.78000","2.56509","0.01043"
"5190","31.10400","2.59212","0.01026"
"5244","31.42800","2.61908","0.01028"
"5298","31.75200","2.64611","0.01004"
"5352","32.07600","2.67319","0.01121"
"5406","32.40000","2.70010","0.01014"
"5460","32.72400","2.72712","0.01032"
"5514","33.04800","2.75409","0.01059"
"5568","33.37200","2.78105","0.01089"
"5622","33.69600","2.80814","0.01097"
"5676","34.02000","2.83504","0.01131"
"5730","34.34400","2.86212","0.00974"
"5784","34.66800","2.88909","0.01004"
"5838","34.99200","2.91612","0.01010"
"5892","35.31600","2.94314","0.01079"
"5946","35.64000","2.97010","0.01025"
"6000","35.96400","2.99713","0.01084"
"6054","36.28800","3.02410","0.01095"
"6108","36.61200","3.05106","0.01120"
"6162","36.93600","3.07814","0.01177"
"6216","37.26000","3.10511","0.01117"
"6270","37.58400","3.13207","0.01129"
"6324","37.90800","3.15916","0.01168"
"6378","38.23200","3.18606","0.01128"
"6432","38.55600","3.21315","0.01215"
"6486","38.88000","3.24005","0.01188"
"6540","39.20400","3.26714","0.01177"
"6594","39.52800","3.29416","0.01186"
"6648","39.85200","3.32107","0.01249"
"6702","40.17600","3.34815","0.01225"
"6756","40.50000","3.37512","0.01265"
"6810","40.82400","3.40214","0.01243"
"6864","41.14800","3.42911","0.01227"
"6918","41.47200","3.45607","0.01242"
"6972","41.79600","3.48316","0.01274"
"7026","42.12000","3.51012","0.01327"
"7080","42.44400","3.53715","0.01257"
"7134","42.76800","3.56411","0.01295"
"7188","43.09200","3.59114","0.01373"
"7242","43.41600","3.61816","0.01356"
"7296","43.74000","3.64507","0.01447"
"7350","44.06400","3.67203","0.01411"
"7404","44.38800","3.69918","0.01407"
"7458","44.71200","3.72608","0.01373"
"7512","45.03600","3.75317","0.01396"
"7566","45.36000","3.78007","0.01376"
"7620","45.68400","3.80716","0.01391"
"7674","46.00800","3.83418","0.01450"
"7728","46.33200","3.86109","0.01408"
"7782","46.65600","3.88811","0.01416"
"7836","46.98000","3.91508","0.01433"
"7890","47.30400","3.94210","0.01491"
"7944","47.62800","3.96913","0.01583"
"7998","47.95200","3.99603","0.01514"
"8052","48.27600","4.02312","0.01510"
"8106","48.60000","4.05008","0.01553"
"8160","48.92400","4.07711","0.01554"
"8214","49.24800","4.10413","0.01553"
"8268","49.57200","4.13110","0.01611"
"8322","49.89600","4.15818","0.01669"
"8376","50.22000","4.18515","0.01641"
"8430","50.54400","4.21217","0.01679"
"8484","50.86800","4.23914","0.01673"
"8538","51.19200","4.26604","0.01693"
"8592","51.51600","4.29307","0.01776"
"8646","51.84000","4.32009","0.01776"
"8700","52.16400","4.34712","0.01801"
"8754","52.48800","4.37414","0.01782"
"8808","52.81200","4.40105","0.01794"
"8862","53.13600","4.42813","0.01806"
"8916","53.46000","4.45510","0.01822"
"8970","53.78400","4.48212","0.01940"
"9024","54.10800","4.50915","0.01938"
"9078","54.43200","4.53605","0.01936"
"9132","54.75600","4.56314","0.01952"
"9186","55.08000","4.59016","0.02066"
"9240","55.40400","4.61707","0.01842"
"9294","55.72800","4.64421","0.01898"
"9348","56.05200","4.67106","0.01960"
"9402","56.37600","4.69808","0.01977"
"9456","56.70000","4.72505","0.01988"
"9510","57.02400","4.75207","0.01990"
"9564","57.34800","4.77916","0.02052"
"9618","57.67200","4.80612","0.02127"
"9672","57.99600","4.83315","0.02128"
"9726","58.32000","4.86011","0.02166"
"9780","58.64400","4.88708","0.02156"
"9834","58.96800","4.91410","0.02180"
"9888","59.29200","4.94107","0.02297"
"9942","59.61600","4.96815","0.02142"
"9996","59.94000","4.99512","0.02276"
"10050","60.26400","5.02208","0.02274"
"10104","60.58800","5.04917","0.02325"
"10158","60.91200","5.07613","0.02299"
"10212","61.23600","5.10316","0.02349"
"10266","61.56000","5.13012","0.02376"
"10320","61.88400","5.15709","0.02458"
"10374","62.20800","5.18411","0.02473"
"10428","62.53200","5.21108","0.02429"
"10482","62.85600","5.23810","0.02434"
"10536","63.18000","5.26519","0.02566"
"10590","63.50400","5.29209","0.02496"
"10644","63.82800","5.31912","0.02566"
"10698","64.15200","5.34602","0.02613"
"10752","64.47600","5.37317","0.02647"
"10806","64.80000","5.40019","0.02623"
"10860","65.12400","5.42710","0.02730"
"10914","65.44800","5.45418","0.02725"
"10968","65.77200","5.48109","0.02752"
"11022","66.09600","5.50811","0.02734"
"11076","66.42000","5.53514","0.02801"
"11130","66.74400","5.56210","0.02872"
"11184","67.06800","5.58913","0.02943"
"11238","67.39200","5.61609","0.02941"
"11292","67.71600","5.64312","0.02920"
"11346","68.04000","5.67014","0.02862"
"11400","68.36400","5.69711","0.02938"
"11454","68.68800","5.72413","0.02873"
"11508","69.01200","5.75110","0.02896"
"11562","69.33600","5.77806","0.03034"
"11616","69.66000","5.80515","0.02969"
"11670","69.98400","5.83211","0.02982"
"11724","70.30800","5.85913","0.03103"
"11778","70.63200","5.88610","0.03027"
"11832","70.95600","5.91313","0.03086"
"11886","71.28000","5.94015","0.03168"
"11940","71.60400","5.96711","0.03173"
"11994","71.92800","5.99414","0.03177"
"12048","72.25200","6.02111","0.03292"
"12102","72.57600","6.04807","0.03198"
"12156","72.90000","6.07515","0.03296"
"12210","73.22400","6.10212","0.03222"
"12264","73.54800","6.12914","0.03329"
"12318","73.87200","6.15605","0.03335"
"12372","74.19600","6.18313","0.03346"
"12426","74.52000","6.21010","0.03364"
"12480","74.84400","6.23706","0.03391"
"12534","75.16800","6.26415","0.03410"
"12588","75.49200","6.29106","0.03263"
"12642","75.81600","6.31820","0.03350"
"12696","76.14000","6.34516","0.03417"
"12750","76.46400","6.37201","0.03402"
"12804","76.78800","6.39915","0.03486"
"12858","77.11200","6.42606","0.03523"
"12912","77.43600","6.45308","0.03553"
"12966","77.76000","6.48011","0.03482"
"13020","78.08400","6.50707","0.03501"
"13074","78.40800","6.53410","0.03538"
"13128","78.73200","6.56112","0.03581"
"13182","79.05600","6.58809","0.03607"
"13236","79.38000","6.61511","0.03644"
"13290","79.70400","6.64208","0.03713"
"13344","80.02800","6.66916","0.03655"
"13398","80.35200","6.69613","0.03676"
"13452","80.67600","6.72309","0.03667"
"13506","81.00000","6.75018","0.03710"
"13560","81.32400","6.77708","0.03646"
"13614","81.64800","6.80411","0.03680"
"13668","81.97200","6.83107","0.03471"
"13722","82.29600","6.85810","0.03477"
"13776","82.62000","6.88512","0.03525"
"13830","82.94400","6.91203","0.03532"
"13884","83.26800","6.93917","0.03561"
"13938","83.59200","6.96614","0.03639"
"13992","83.91600","6.99310","0.03625"
"14046","84.24000","7.02013","0.03691"
"14100","84.56400","7.04709","0.03713"
"14154","84.88800","7.07412","0.03663"
"14208","85.21200","7.10114","0.03764"
"14262","85.53600","7.12811","0.03757"
"14316","85.86000","7.15519","0.03739"
"14370","86.18400","7.18210","0.03800"
"14424","86.50800","7.20912","0.03801"
"14478","86.83200","7.23609","0.03840"
"14532","87.15600","7.26311","0.03822"
"14586","87.48000","7.29014","0.03882"
"14640","87.80400","7.31704","0.03844"
"14694","88.12800","7.34413","0.03851"
"14748","88.45200","7.37115","0.03894"
"14802","88.77600","7.39812","0.03897"
"14856","89.10000","7.42508","0.03897"
"14910","89.42400","7.45205","0.03865"
"14964","89.74800","7.47913","0.03952"
"15018","90.07200","7.50610","0.03957"
"15072","90.39600","7.53312","0.03974"
"15126","90.72000","7.56015","0.03979"
"15180","91.04400","7.58711","0.04015"
"15234","91.36800","7.61414","0.04021"
"15288","91.69200","7.64104","0.03946"
"15342","92.01600","7.66807","0.04008"
"15396","92.34000","7.69515","0.04036"
"15450","92.66400","7.72206","0.04025"
"15504","92.98800","7.74908","0.04047"
"15558","93.31200","7.77611","0.04075"
"15612","93.63600","7.80307","0.04085"
"15666","93.96000","7.83010","0.04119"
"15720","94.28400","7.85706","0.04112"
"15774","94.60800","7.88415","0.04131"
"15828","94.93200","7.91111","0.04117"
"15882","95.25600","7.93808","0.04166"
"15936","95.58000","7.96510","0.04181"
"15990","95.90400","7.99213","0.04154"
"16044","96.22800","8.01915","0.04127"
"16098","96.55200","8.04612","0.04167"
"16152","96.87600","8.07308","0.04175"
"16206","97.20000","8.10017","0.04190"
"16260","97.52400","8.12707","0.04170"
"16314","97.84800","8.15416","0.04198"
"16368","98.17200","8.18118","0.04192"
"16422","98.49600","8.20809","0.04196"
"16476","98.82000","8.23511","0.04183"
"16530","99.14400","8.26208","0.04210"
"16584","99.46800","8.28904","0.04214"
"16638","99.79200","8.31613","0.04234"
"16692","100.11600","8.34303","0.04252"
"16746","100.44000","8.37012","0.04236"
"16800","100.76400","8.39708","0.04268"
"16854","101.08800","8.42417","0.04246"
"16908","101.41200","8.45113","0.04300"
"16962","101.73600","8.47810","0.04255"
"17016","102.06000","8.50518","0.04287"
"17070","102.38400","8.53209","0.04295"
"17124","102.70800","8.55911","0.04320"
"17178","103.03200","8.58608","0.04306"
"17232","103.35600","8.61304","0.04337"
"17286","103.68000","8.64019","0.04342"
"17340","104.00400","8.66709","0.04342"
"17394","104.32800","8.69406","0.04377"
"17448","104.65200","8.72114","0.04377"
"17502","104.97600","8.74811","0.04401"
"17556","105.30000","8.77513","0.04408"
"17610","105.62400","8.80210","0.04397"
"17664","105.94800","8.82912","0.04432"
"17718","106.27200","8.85620","0.04450"
"17772","106.59600","8.88305","0.04405"
"17826","106.92000","8.91014","0.04398"
"17880","107.24400","8.93716","0.04462"
"17934","107.56800","8.96412","0.04461"
"17988","107.89200","8.99115","0.04464"
"18042","108.21600","9.01805","0.04476"
"18096","108.54000","9.04520","0.04482"
"18150","108.86400","9.07211","0.04493"
"18204","109.18800","9.09907","0.04552"
"18258","109.51200","9.12609","0.04532"
"18312","109.83600","9.15312","0.04537"
"18366","110.16000","9.18014","0.04552"
"18420","110.48400","9.20705","0.04594"
"18474","110.80800","9.23407","0.04572"
"18528","111.13200","9.26110","0.04601"
"18582","111.45600","9.28806","0.04630"
"18636","111.78000","9.31509","0.04612"
"18690","112.10400","9.34211","0.04654"
"18744","112.42800","9.36914","0.04668"
"18798","112.75200","9.39616","0.04674"
"18852","113.07600","9.42307","0.04670"
"18906","113.40000","9.45010","0.04670"
"18960","113.72400","9.47712","0.04719"
"19014","114.04800","9.50408","0.04696"
"19068","114.37200","9.53111","0.04722"
"19122","114.69600","9.55807","0.04690"
"19176","115.02000","9.58516","0.04732"
"19230","115.34400","9.61212","0.04761"
"19284","115.66800","9.63903","0.04768"
"19338","115.99200","9.66617","0.04776"
"19392","116.31600","9.69308","0.04817"
"19446","116.64000","9.72010","0.04813"
"19500","116.96400","9.74707","0.04824"
"19554","117.28800","9.77409","0.04862"
"19608","117.61200","9.80112","0.04878"
"19662","117.93600","9.82808","0.04922"
"19716","118.26000","9.85511","0.04905"
"19770","118.58400","9.88207","0.04977"
"19824","118.90800","9.90910","0.04973"
"19878","119.23200","9.93606","0.05023"
"19932","119.55600","9.96309","0.05013"
"19986","119.88000","9.99017","0.05032"
"20040","120.20400","10.01714","0.05027"
"20094","120.52800","10.04410","0.05076"
"20148","120.85200","10.07113","0.05091"
"20202","121.17600","10.09809","0.05142"
"20256","121.50000","10.12506","0.05149"
"20310","121.82400","10.15214","0.05170"
"20364","122.14800","10.17911","0.05217"
"20418","122.47200","10.20613","0.05255"
"20472","122.79600","10.23310","0.05172"
"20526","123.12000","10.26012","0.05172"
"20580","123.44400","10.28715","0.05209"
"20634","123.76800","10.31405","0.05215"
"20688","124.09200","10.34114","0.05265"
"20742","124.41600","10.36804","0.05351"
"20796","124.74000","10.39513","0.05375"
"20850","125.06400","10.42215","0.05382"
"20904","125.38800","10.44906","0.05507"
"20958","125.71200","10.47614","0.05496"
"21012","126.03600","10.50311","0.05607"
"21066","126.36000","10.53013","0.05625"
"21120","126.68400","10.55710","0.05668"
"21174","127.00800","10.58406","0.05708"
"21228","127.33200","10.61121","0.05762"
"21282","127.65600","10.63811","0.05845"
"21336","127.98000","10.66508","0.05921"
"21390","128.30400","10.69216","0.05966"
"21444","128.62800","10.71913","0.06090"
"21498","128.95200","10.74615","0.06032"
"21552","129.27600","10.77306","0.06086"
"21606","129.60000","10.80008","0.06150"
"21660","129.92400","10.82717","0.06187"
"21714","130.24800","10.85407","0.06231"
"21768","130.57200","10.88110","0.06307"
"21822","130.89600","10.90806","0.06067"
"21876","131.22000","10.93515","0.06095"
"21930","131.54400","10.96211","0.06154"
"21984","131.86800","10.98908","0.06235"
"22038","132.19200","11.01616","0.06252"
"22092","132.51600","11.04313","0.06290"
"22146","132.84000","11.07015","0.06414"
"22200","133.16400","11.09712","0.06419"
"22254","133.48800","11.12402","0.06526"
"22308","133.81200","11.15111","0.06545"
"22362","134.13600","11.17813","0.06573"
"22416","134.46000","11.20510","0.06630"
"22470","134.78400","11.23212","0.06679"
"22524","135.10800","11.25903","0.06752"
"22578","135.43200","11.28617","0.06785"
"22632","135.75600","11.31308","0.06747"
"22686","136.08000","11.34010","0.06778"
"22740","136.40400","11.36713","0.06893"
"22794","136.72800","11.39403","0.06909"
"22848","137.05200","11.42112","0.06947"
"22902","137.37600","11.44814","0.07046"
"22956","137.70000","11.47511","0.07066"
"23010","138.02400","11.50213","0.07081"
"23064","138.34800","11.52910","0.07150"
"23118","138.67200","11.55612","0.07231"
"23172","138.99600","11.58309","0.07268"
"23226","139.32000","11.61011","0.07344"
"23280","139.64400","11.63714","0.07189"
"23334","139.96800","11.66404","0.07250"
"23388","140.29200","11.69113","0.07316"
"23442","140.61600","11.71809","0.07358"
"23496","140.94000","11.74512","0.07428"
"23550","141.26400","11.77214","0.07490"
"23604","141.58800","11.79905","0.07541"
"23658","141.91200","11.82613","0.07631"
"23712","142.23600","11.85310","0.07698"
"23766","142.56000","11.88012","0.07694"
"23820","142.88400","11.90715","0.07797"
"23874","143.20800","11.93405","0.07954"
"23928","143.53200","11.96119","0.08054"
"23982","143.85600","11.98810","0.08046"
"24036","144.18000","12.01512","0.08182"
"24090","144.50400","12.04209","0.08148"
"24144","144.82800","12.06912","0.07947"
"24198","145.15200","12.09614","0.07983"
"24252","145.47600","12.12311","0.08060"
"24306","145.80000","12.15007","0.08169"
"24360","146.12400","12.17715","0.08189"
"24414","146.44800","12.20406","0.08321"
"24468","146.77200","12.23120","0.08384"
"24522","147.09600","12.25811","0.08455"
"24576","147.42000","12.28508","0.08393"
"24630","147.74400","12.31216","0.08386"
"24684","148.06800","12.33906","0.08165"
"24738","148.39200","12.36615","0.08234"
"24792","148.71600","12.39311","0.08039"
"24846","149.04000","12.42008","0.08059"
"24900","149.36400","12.44710","0.07380"
"24954","149.68800","12.47401","0.07428"
"25008","150.01200","12.50121","0.07149"
"25062","150.33600","12.52812","0.07148"
"25116","150.66000","12.55509","0.06958"
"25170","150.98400","12.58211","0.06741"
"25224","151.30800","12.60913","0.06714"
"25278","151.63200","12.63610","0.05579"
"25332","151.95600","12.66306","0.05418"
"25386","152.28000","12.69009","0.05523"
"25440","152.60400","12.71717","0.05580"
"25494","152.92800","12.74408","0.05642"
"25548","153.25200","12.77110","0.05706"
"25602","153.57600","12.79813","0.05844"
"25656","153.90000","12.82509","0.05962"
"25710","154.22400","12.85212","0.05927"
"25764","154.54800","12.87908","0.06064"
"25818","154.87200","12.90611","0.06199"
"25872","155.19600","12.93313","0.06266"
"25926","155.52000","12.96010","0.06320"
"25980","155.84400","12.98712","0.06297"
"26034","156.16800","13.01415","0.06135"
"26088","156.49200","13.04111","0.06331"
"26142","156.81600","13.06808","0.06416"
"26196","157.14000","13.09504","0.06495"
"26250","157.46400","13.12213","0.06575"
"26304","157.78800","13.14909","0.06630"
"26358","158.11200","13.17612","0.06651"
"26412","158.43600","13.20314","0.06756"
"26466","158.76000","13.23005","0.06774"
"26520","159.08400","13.25713","0.06853"
"26574","159.40800","13.28404","0.06932"
"26628","159.73200","13.31112","0.06923"
"26682","160.05600","13.33815","0.06716"
"26736","160.38000","13.36505","0.06765"
"26790","160.70400","13.39214","0.06781"
"26844","161.02800","13.41910","0.06834"
"26898","161.35200","13.44619","0.06895"
"26952","161.67600","13.47315","0.06910"
"27006","162.00000","13.50012","0.06941"
"27060","162.32400","13.52714","0.07030"
"27114","162.64800","13.55411","0.07091"
"27168","162.97200","13.58113","0.07170"
"27222","163.29600","13.60810","0.07175"
"27276","163.62000","13.63512","0.07230"
"27330","163.94400","13.66215","0.07323"
"27384","164.26800","13.68911","0.07354"
"27438","164.59200","13.71608","0.07444"
"27492","164.91600","13.74316","0.07452"
"27546","165.24000","13.77013","0.07534"
"27600","165.56400","13.79715","0.07682"
"27654","165.88800","13.82412","0.07756"
"27708","166.21200","13.85114","0.07756"
"27762","166.53600","13.87817","0.07867"
"27816","166.86000","13.90507","0.07894"
"27870","167.18400","13.93216","0.08049"
"27924","167.50800","13.95912","0.08142"
"27978","167.83200","13.98609","0.08273"
"28032","168.15600","14.01311","0.08358"
"28086","168.48000","14.04008","0.08434"
"28140","168.80400","14.06716","0.08611"
"28194","169.12800","14.09413","0.08637"
"28248","169.45200","14.12109","0.08707"
"28302","169.77600","14.14812","0.08778"
"28356","170.10000","14.17508","0.08831"
"28410","170.42400","14.20217","0.08775"
"28464","170.74800","14.22913","0.08799"
"28518","171.07200","14.25610","0.08855"
"28572","171.39600","14.28312","0.08740"
"28626","171.72000","14.31009","0.08778"
"28680","172.04400","14.33711","0.08835"
"28734","172.36800","14.36414","0.08932"
"28788","172.69200","14.39116","0.08936"
"28842","173.01600","14.41813","0.08983"
"28896","173.34000","14.44503","0.08474"
"28950","173.66400","14.47212","0.08414"
"29004","173.98800","14.49914","0.07363"
"29058","174.31200","14.52611","0.05581"
"29112","174.63600","14.55307","0.05217"
"29166","174.96000","14.58004","0.04757"
"29220","175.28400","14.60712","0.04769"
"29274","175.60800","14.63415","0.04722"
"29328","175.93200","14.66111","0.04861"
"29382","176.25600","14.68820","0.04921"
"29436","176.58000","14.71504","0.04823"
"29490","176.90400","14.74213","0.04966"
"29544","177.22800","14.76909","0.05046"
"29598","177.55200","14.79612","0.04956"
"29652","177.87600","14.82314","0.05053"
"29706","178.20000","14.85005","0.05225"
"29760","178.52400","14.87713","0.05037"
"29814","178.84800","14.90410","0.04860"
"29868","179.17200","14.93106","0.04919"
"29922","179.49600","14.95809","0.04840"
"29976","179.82000","14.98505","0.04848"
"30030","180.14400","15.01220","0.04789"
"30084","180.46800","15.03916","0.04723"
"30138","180.79200","15.06607","0.02476"
"30192","181.11600","15.09315","0.02352"
"30246","181.44000","15.12012","0.02056"
"30300","181.76400","15.14708","0.02628"
"30354","182.08800","15.17410","0.02810"
"30408","182.41200","15.20107","0.02567"
"30462","182.73600","15.22810","0.02691"
"30516","183.06000","15.25512","0.02833"
"30570","183.38400","15.28215","0.03054"
"30624","183.70800","15.30917","0.03070"
"30678","184.03200","15.33607","0.03004"
"30732","184.35600","15.36310","0.03189"
"30786","184.68000","15.39006","0.03239"
"30840","185.00400","15.41715","0.03360"
"30894","185.32800","15.44417","0.03381"
"30948","185.65200","15.47108","0.03466"
"31002","185.97600","15.49811","0.03457"
"31056","186.30000","15.52513","0.03562"
"31110","186.62400","15.55216","0.03620"
"31164","186.94800","15.57912","0.03643"
"31218","187.27200","15.60608","0.02187"
"31272","187.59600","15.63317","0.02136"
"31326","187.92000","15.66013","0.02268"
"31380","188.24400","15.68716","0.02251"
"31434","188.56800","15.71412","0.02335"
"31488","188.89200","15.74115","0.02549"
"31542","189.21600","15.76811","0.02403"
"31596","189.54000","15.79508","0.02277"
"31650","189.86400","15.82210","0.02663"
"31704","190.18800","15.84913","0.02634"
"31758","190.51200","15.87603","0.02344"
"31812","190.83600","15.90318","0.02328"
"31866","191.16000","15.93008","0.02275"
"31920","191.48400","15.95717","0.02455"
"31974","191.80800","15.98407","0.02389"
"32028","192.13200","16.01104","0.02518"
"32082","192.45600","16.03812","0.02466"
"32136","192.78000","16.06515","0.02511"
"32190","193.10400","16.09217","0.02632"
"32244","193.42800","16.11914","0.02633"
"32298","193.75200","16.14604","0.02679"
"32352","194.07600","16.17319","0.02777"
"32406","194.40000","16.20003","0.02794"
"32460","194.72400","16.22712","0.02891"
"32514","195.04800","16.25414","0.02868"
"32568","195.37200","16.28105","0.02996"
"32622","195.69600","16.30819","0.03004"
"32676","196.02000","16.33510","0.02979"
"32730","196.34400","16.36218","0.03109"
"32784","196.66800","16.38915","0.03159"
"32838","196.99200","16.41605","0.03283"
"32892","197.31600","16.44308","0.03314"
"32946","197.64000","16.47010","0.03276"
"33000","197.96400","16.49713","0.03377"
"33054","198.28800","16.52415","0.03419"
"33108","198.61200","16.55112","0.03469"
"33162","198.93600","16.57814","0.03487"
"33216","199.26000","16.60505","0.03558"
"33270","199.58400","16.63207","0.03567"
"33324","199.90800","16.65910","0.03661"
"33378","200.23200","16.68606","0.03626"
"33432","200.55600","16.71309","0.03764"
"33486","200.88000","16.74011","0.03779"
"33540","201.20400","16.76714","0.03811"
"33594","201.52800","16.79422","0.03880"
"33648","201.85200","16.82101","0.03871"
"33702","202.17600","16.84809","0.03915"
"33756","202.50000","16.87512","0.03927"
"33810","202.82400","16.90214","0.03918"
"33864","203.14800","16.92917","0.03990"
"33918","203.47200","16.95601","0.04002"
"33972","203.79600","16.98316","0.04009"
"34026","204.12000","17.01012","0.04063"
"34080","204.44400","17.03715","0.04060"
"34134","204.76800","17.06405","0.04100"
"34188","205.09200","17.09108","0.04145"
"34242","205.41600","17.11816","0.04131"
"34296","205.74000","17.14513","0.04212"
"34350","206.06400","17.17215","0.04210"
"34404","206.38800","17.19912","0.04230"
"34458","206.71200","17.22608","0.04229"
"34512","207.03600","17.25311","0.04259"
"34566","207.36000","17.28013","0.04293"
"34620","207.68400","17.30710","0.04322"
"34674","208.00800","17.33412","0.04384"
"34728","208.33200","17.36109","0.04383"
"34782","208.65600","17.38811","0.04403"
"34836","208.98000","17.41520","0.04435"
"34890","209.30400","17.44210","0.04421"
"34944","209.62800","17.46907","0.04475"
"34998","209.95200","17.49603","0.04476"
"35052","210.27600","17.52317","0.04508"
"35106","210.60000","17.55014","0.04525"
"35160","210.92400","17.57705","0.04532"
"35214","211.24800","17.60413","0.04567"
"35268","211.57200","17.63110","0.04588"
"35322","211.89600","17.65812","0.04628"
"35376","212.22000","17.68509","0.04643"
"35430","212.54400","17.71205","0.04646"
"35484","212.86800","17.73914","0.04678"
"35538","213.19200","17.76604","0.04733"
"35592","213.51600","17.79313","0.04724"
"35646","213.84000","17.82009","0.04697"
"35700","214.16400","17.84711","0.04758"
"35754","214.48800","17.87414","0.04795"
"35808","214.81200","17.90105","0.04811"
"35862","215.13600","17.92813","0.04855"
"35916","215.46000","17.95510","0.04904"
"35970","215.78400","17.98212","0.04971"
"36024","216.10800","18.00908","0.04963"
"36078","216.43200","18.03611","0.05053"
"36132","216.75600","18.06314","0.05068"
"36186","217.08000","18.09016","0.05152"
"36240","217.40400","18.11707","0.05273"
"36294","217.72800","18.14415","0.05317"
"36348","218.05200","18.17111","0.05318"
"36402","218.37600","18.19808","0.05353"
"36456","218.70000","18.22511","0.05421"
"36510","219.02400","18.25207","0.05487"
"36564","219.34800","18.27910","0.05536"
"36618","219.67200","18.30600","0.05522"
"36672","219.99600","18.33308","0.05390"
"36726","220.32000","18.36011","0.05458"
"36780","220.64400","18.38708","0.03692"
"36834","220.96800","18.41416","0.03713"
"36888","221.29200","18.44106","0.03820"
"36942","221.61600","18.46815","0.03800"
"36996","221.94000","18.49512","0.03840"
"37050","222.26400","18.52208","0.03548"
"37104","222.58800","18.54910","0.03645"
"37158","222.91200","18.57607","0.03793"
"37212","223.23600","18.60316","0.03818"
"37266","223.56000","18.63012","0.03746"
"37320","223.88400","18.65714","0.03876"
"37374","224.20800","18.68417","0.03860"
"37428","224.53200","18.71113","0.03972"
"37482","224.85600","18.73810","0.03941"
"37536","225.18000","18.76512","0.03964"
"37590","225.50400","18.79209","0.04005"
"37644","225.82800","18.81905","0.04058"
"37698","226.15200","18.84614","0.04073"
"37752","226.47600","18.87317","0.04136"
"37806","226.80000","18.90019","0.04146"
"37860","227.12400","18.92709","0.04189"
"37914","227.44800","18.95412","0.04261"
"37968","227.77200","18.98114","0.04292"
"38022","228.09600","19.00811","0.04325"
"38076","228.42000","19.03514","0.04376"
"38130","228.74400","19.06210","0.04411"
"38184","229.06800","19.08918","0.04416"
"38238","229.39200","19.11609","0.04492"
"38292","229.71600","19.14305","0.04476"
"38346","230.04000","19.17008","0.04550"
"38400","230.36400","19.19711","0.04591"
"38454","230.68800","19.22413","0.04598"
"38508","231.01200","19.25109","0.04684"
"38562","231.33600","19.27812","0.04725"
"38616","231.66000","19.30520","0.04729"
"38670","231.98400","19.33205","0.04794"
"38724","232.30800","19.35913","0.04834"
"38778","232.63200","19.38610","0.04832"
"38832","232.95600","19.41312","0.04917"
"38886","233.28000","19.44009","0.04935"
"38940","233.60400","19.46700","0.05015"
"38994","233.92800","19.49414","0.05053"
"39048","234.25200","19.52110","0.05058"
"39102","234.57600","19.54813","0.02489"
"39156","234.90000","19.57515","0.01837"
"39210","235.22400","19.60206","0.02429"
"39264","235.54800","19.62908","0.02086"
"39318","235.87200","19.65611","0.02882"
"39372","236.19600","19.68313","0.02254"
"39426","236.52000","19.71016","0.02534"
"39480","236.84400","19.73706","0.02510"
"39534","237.16800","19.76415","0.02906"
"39588","237.49200","19.79111","0.02653"
"39642","237.81600","19.81814","0.02698"
"39696","238.14000","19.84510","0.02866"
"39750","238.46400","19.87201","0.02903"
"39804","238.78800","19.89915","0.03174"
"39858","239.11200","19.92612","0.03018"
"39912","239.43600","19.95314","0.03285"
"39966","239.76000","19.98011","0.03166"
"40020","240.08400","20.00701","0.03398"
"40074","240.40800","20.03416","0.03332"
"40128","240.73200","20.06112","0.03360"
"40182","241.05600","20.08809","0.03541"
"40236","241.38000","20.11511","0.03565"
"40290","241.70400","20.14214","0.03670"
"40344","242.02800","20.16910","0.03575"
"40398","242.35200","20.19613","0.03732"
"40452","242.67600","20.22309","0.03806"
"40506","243.00000","20.25018","0.03789"
"40560","243.32400","20.27708","0.03857"
"40614","243.64800","20.30416","0.03817"
"40668","243.97200","20.33113","0.03914"
"40722","244.29600","20.35810","0.03900"
"40776","244.62000","20.38512","0.03952"
"40830","244.94400","20.41203","0.04019"
"40884","245.26800","20.43911","0.04026"
"40938","245.59200","20.46614","0.04085"
"40992","245.91600","20.49304","0.04073"
"41046","246.24000","20.52007","0.04121"
"41100","246.56400","20.54709","0.04169"
"41154","246.88800","20.57417","0.04149"
"41208","247.21200","20.60120","0.04222"
"41262","247.53600","20.62811","0.04248"
"41316","247.86000","20.65513","0.04222"
"41370","248.18400","20.68210","0.04276"
"41424","248.50800","20.70912","0.04279"
"41478","248.83200","20.73615","0.04279"
"41532","249.15600","20.76317","0.01063"
"41586","249.48000","20.79014","0.01848"
"41640","249.80400","20.81704","0.01603"
"41694","250.12800","20.84413","0.01253"
"41748","250.45200","20.87115","0.01695"
"41802","250.77600","20.89812","0.01580"
"41856","251.10000","20.92514","0.01344"
"41910","251.42400","20.95211","0.01825"
"41964","251.74800","20.97913","0.01724"
"42018","252.07200","21.00616","0.01480"
"42072","252.39600","21.03306","0.01675"
"42126","252.72000","21.06009","0.01734"
"42180","253.04400","21.08711","0.01504"
"42234","253.36800","21.11414","0.01694"
"42288","253.69200","21.14116","0.01856"
"42342","254.01600","21.16807","0.01824"
"42396","254.34000","21.19515","0.01678"
"42450","254.66400","21.22211","0.01934"
"42504","254.98800","21.24914","0.01837"
"42558","255.31200","21.27610","0.01870"
"42612","255.63600","21.30307","0.01944"
"42666","255.96000","21.33016","0.01916"
"42720","256.28400","21.35706","0.01923"
"42774","256.60800","21.38415","0.01928"
"42828","256.93200","21.41111","0.02056"
"42882","257.25600","21.43801","0.02008"
"42936","257.58000","21.46510","0.02072"
"42990","257.90400","21.49212","0.02115"
"43044","258.22800","21.51915","0.02098"
"43098","258.55200","21.54611","0.02079"
"43152","258.87600","21.57308","0.02172"
"43206","259.20000","21.60011","0.02200"
"43260","259.52400","21.62707","0.02225"
"43314","259.84800","21.65403","0.02213"
"43368","260.17200","21.68112","0.02233"
"43422","260.49600","21.70809","0.02286"
"43476","260.82000","21.73511","0.02305"
"43530","261.14400","21.76213","0.02391"
"43584","261.46800","21.78904","0.02416"
"43638","261.79200","21.81618","0.02361"
"43692","262.11600","21.84309","0.02389"
"43746","262.44000","21.87018","0.02403"
"43800","262.76400","21.89708","0.02482"
"43854","263.08800","21.92410","0.02463"
"43908","263.41200","21.95113","0.02503"
"43962","263.73600","21.97803","0.02529"
"44016","264.06000","22.00512","0.02512"
"44070","264.38400","22.03208","0.02596"
"44124","264.70800","22.05911","0.02615"
"44178","265.03200","22.08607","0.02595"
"44232","265.35600","22.11310","0.02672"
"44286","265.68000","22.14013","0.02757"
"44340","266.00400","22.16709","0.02750"
"44394","266.32800","22.19411","0.02777"
"44448","266.65200","22.22114","0.02746"
"44502","266.97600","22.24810","0.02772"
"44556","267.30000","22.27513","0.02776"
"44610","267.62400","22.30210","0.02938"
"44664","267.94800","22.32906","0.02882"
"44718","268.27200","22.35614","0.02994"
"44772","268.59600","22.38305","0.03083"
"44826","268.92000","22.41007","0.02980"
"44880","269.24400","22.43716","0.03076"
"44934","269.56800","22.46412","0.03117"
"44988","269.89200","22.49109","0.03131"
"45042","270.21600","22.51805","0.03254"
"45096","270.54000","22.54514","0.03273"
"45150","270.86400","22.57210","0.03348"
"45204","271.18800","22.59907","0.03388"
"45258","271.51200","22.62615","0.03402"
"45312","271.83600","22.65312","0.03420"
"45366","272.16000","22.68014","0.03506"
"45420","272.48400","22.70711","0.03550"
"45474","272.80800","22.73407","0.03569"
"45528","273.13200","22.76116","0.03597"
"45582","273.45600","22.78806","0.03580"
"45636","273.78000","22.81509","0.03639"
"45690","274.10400","22.84211","0.03670"
"45744","274.42800","22.86914","0.03682"
"45798","274.75200","22.89610","0.03675"
"45852","275.07600","22.92307","0.03758"
"45906","275.40000","22.95009","0.03750"
"45960","275.72400","22.97712","0.03805"
"46014","276.04800","23.00414","0.03841"
"46068","276.37200","23.03111","0.03881"
"46122","276.69600","23.05807","0.03878"
"46176","277.02000","23.08510","0.03899"
"46230","277.34400","23.11212","0.03980"
"46284","277.66800","23.13909","0.04015"
"46338","277.99200","23.16611","0.04029"
"46392","278.31600","23.19308","0.04049"
"46446","278.64000","23.22010","0.04002"
"46500","278.96400","23.24713","0.04028"
"46554","279.28800","23.27409","0.04071"
"46608","279.61200","23.30112","0.04072"
"46662","279.93600","23.32808","0.04091"
"46716","280.26000","23.35511","0.04085"
"46770","280.58400","23.38219","0.04146"
"46824","280.90800","23.40910","0.04162"
"46878","281.23200","23.43612","0.04180"
"46932","281.55600","23.46309","0.04181"
"46986","281.88000","23.49017","0.04196"
"47040","282.20400","23.51714","0.04253"
"47094","282.52800","23.54410","0.04257"
"47148","282.85200","23.57113","0.04273"
"47202","283.17600","23.59809","0.04321"
"47256","283.50000","23.62512","0.04343"
"47310","283.82400","23.65214","0.04380"
"47364","284.14800","23.67905","0.04412"
"47418","284.47200","23.70613","0.04427"
"47472","284.79600","23.73310","0.04468"
"47526","285.12000","23.76006","0.04480"
"47580","285.44400","23.78714","0.04510"
"47634","285.76800","23.81411","0.04548"
"47688","286.09200","23.84120","0.04554"
"47742","286.41600","23.86810","0.04580"
"47796","286.74000","23.89513","0.04626"
"47850","287.06400","23.92215","0.04649"
"47904","287.38800","23.94905","0.04686"
"47958","287.71200","23.97614","0.04725"
"48012","288.03600","24.00311","0.04713"
"48066","288.36000","24.03013","0.04815"
"48120","288.68400","24.05716","0.04888"
"48174","289.00800","24.08406","0.04932"
"48228","289.33200","24.11108","0.04978"
"48282","289.65600","24.13811","0.05069"
"48336","289.98000","24.16508","0.05114"
"48390","290.30400","24.19216","0.05262"
"48444","290.62800","24.21913","0.05342"
"48498","290.95200","24.24615","0.05435"
"48552","291.27600","24.27312","0.05526"
"48606","291.60000","24.30014","0.05627"
"48660","291.92400","24.32717","0.05744"
"48714","292.24800","24.35407","0.05792"
"48768","292.57200","24.38109","0.05921"
"48822","292.89600","24.40812","0.05903"
"48876","293.22000","24.43515","0.06027"
"48930","293.54400","24.46217","0.06171"
"48984","293.86800","24.48907","0.06286"
"49038","294.19200","24.51610","0.06418"
"49092","294.51600","24.54313","0.06441"
"49146","294.84000","24.57003","0.06547"
"49200","295.16400","24.59711","0.06717"
"49254","295.48800","24.62402","0.06791"
"49308","295.81200","24.65117","0.06951"
"49362","296.13600","24.67813","0.07049"
"49416","296.46000","24.70509","0.07166"
"49470","296.78400","24.73218","0.07333"
"49524","297.10800","24.75902","0.07468"
"49578","297.43200","24.78617","0.07498"
"49632","297.75600","24.81308","0.07574"
"49686","298.08000","24.84010","0.07674"
"49740","298.40400","24.86712","0.07868"
"49794","298.72800","24.89409","0.07979"
"49848","299.05200","24.92111","0.08050"
"49902","299.37600","24.94808","0.08224"
"49956","299.70000","24.97511","0.08382"
"50010","300.02400","25.00207","0.08445"
"50064","300.34800","25.02903","0.08625"
"50118","300.67200","25.05612","0.08689"
"50172","300.99600","25.08309","0.08704"
"50226","301.32000","25.11005","0.08819"
"50280","301.64400","25.13713","0.08849"
"50334","301.96800","25.16410","0.08923"
"50388","302.29200","25.19106","0.08964"
"50442","302.61600","25.21809","0.09012"
"50496","302.94000","25.24505","0.09081"
"50550","303.26400","25.27214","0.09181"
"50604","303.58800","25.29911","0.09228"
"50658","303.91200","25.32613","0.09272"
"50712","304.23600","25.35315","0.09370"
"50766","304.56000","25.38012","0.09453"
"50820","304.88400","25.40714","0.09499"
"50874","305.20800","25.43405","0.09633"
"50928","305.53200","25.46113","0.09810"
"50982","305.85600","25.48816","0.09975"
"51036","306.18000","25.51506","0.10272"
"51090","306.50400","25.54215","0.10368"
"51144","306.82800","25.56905","0.10624"
"51198","307.15200","25.59614","0.10729"
"51252","307.47600","25.62310","0.10857"
"51306","307.80000","25.65007","0.11021"
"51360","308.12400","25.67709","0.11190"
"51414","308.44800","25.70412","0.11344"
"51468","308.77200","25.73108","0.11502"
"51522","309.09600","25.75811","0.11631"
"51576","309.42000","25.78513","0.11621"
"51630","309.74400","25.81210","0.11843"
"51684","310.06800","25.83906","0.11917"
"51738","310.39200","25.86609","0.11968"
"51792","310.71600","25.89317","0.01828"
"51846","311.04000","25.92008","0.00833"
"51900","311.36400","25.94710","0.01531"
"51954","311.68800","25.97407","0.01291"
"52008","312.01200","26.00115","0.00209"
"52062","312.33600","26.02818","0.00998"
"52116","312.66000","26.05514","0.01660"
"52170","312.98400","26.08211","0.00386"
"52224","313.30800","26.10913","0.01029"
"52278","313.63200","26.13610","0.01461"
"52332","313.95600","26.16312","0.00579"
"52386","314.28000","26.19009","0.00853"
"52440","314.60400","26.21711","0.01214"
"52494","314.92800","26.24408","0.00962"
"52548","315.25200","26.27104","0.00676"
"52602","315.57600","26.29813","0.01180"
"52656","315.90000","26.32509","0.01487"
"52710","316.22400","26.35212","0.00760"
"52764","316.54800","26.37908","0.01041"
"52818","316.87200","26.40611","0.01364"
"52872","317.19600","26.43313","0.01030"
"52926","317.52000","26.46010","0.00948"
"52980","317.84400","26.48712","0.01241"
"53034","318.16800","26.51409","0.01406"
"53088","318.49200","26.54111","0.00962"
"53142","318.81600","26.56814","0.01190"
"53196","319.14000","26.59510","0.01440"
"53250","319.46400","26.62213","0.01228"
"53304","319.78800","26.64909","0.01112"
"53358","320.11200","26.67606","0.01267"
"53412","320.43600","26.70308","0.01496"
"53466","320.76000","26.73010","0.01195"
"53520","321.08400","26.75719","0.01287"
"53574","321.40800","26.78410","0.01444"
"53628","321.73200","26.81112","0.01441"
"53682","322.05600","26.83815","0.01201"
"53736","322.38000","26.86505","0.01364"
"53790","322.70400","26.89208","0.01514"
"53844","323.02800","26.91910","0.01410"
"53898","323.35200","26.94613","0.01317"
"53952","323.67600","26.97315","0.01485"
"54006","324.00000","27.00006","0.01599"
"54060","324.32400","27.02714","0.01445"
"54114","324.64800","27.05411","0.01487"
"54168","324.97200","27.08107","0.01574"
"54222","325.29600","27.10810","0.01590"
"54276","325.62000","27.13506","0.01400"
"54330","325.94400","27.16215","0.01556"
"54384","326.26800","27.18911","0.01634"
"54438","326.59200","27.21608","0.01592"
"54492","326.91600","27.24316","0.01579"
"54546","327.24000","27.27007","0.01631"
"54600","327.56400","27.29715","0.01662"
"54654","327.88800","27.32405","0.01648"
"54708","328.21200","27.35108","0.01645"
"54762","328.53600","27.37816","0.01711"
"54816","328.86000","27.40507","0.01694"
"54870","329.18400","27.43216","0.01607"
"54924","329.50800","27.45912","0.01593"
"54978","329.83200","27.48609","0.01650"
"55032","330.15600","27.51311","0.01690"
"55086","330.48000","27.54002","0.01715"
"55140","330.80400","27.56716","0.01694"
"55194","331.12800","27.59413","0.01718"
"55248","331.45200","27.62115","0.01781"
"55302","331.77600","27.64812","0.01755"
"55356","332.10000","27.67514","0.01791"
"55410","332.42400","27.70211","0.01875"
"55464","332.74800","27.72913","0.01854"
"55518","333.07200","27.75610","0.01837"
"55572","333.39600","27.78312","0.01857"
"55626","333.72000","27.81008","0.01922"
"55680","334.04400","27.83711","0.01866"
"55734","334.36800","27.86407","0.01815"
"55788","334.69200","27.89110","0.01892"
"55842","335.01600","27.91813","0.01863"
"55896","335.34000","27.94509","0.01857"
"55950","335.66400","27.97211","0.01828"
"56004","335.98800","27.99914","0.01873"
"56058","336.31200","28.02610","0.01867"
"56112","336.63600","28.05313","0.01850"
"56166","336.96000","28.08010","0.01912"
"56220","337.28400","28.10712","0.01926"
"56274","337.60800","28.13408","0.02030"
"56328","337.93200","28.16105","0.01978"
"56382","338.25600","28.18814","0.02000"
"56436","338.58000","28.21510","0.02057"
"56490","338.90400","28.24207","0.02006"
"56544","339.22800","28.26915","0.02021"
"56598","339.55200","28.29611","0.02109"
"56652","339.87600","28.32320","0.02137"
"56706","340.20000","28.35010","0.01995"
"56760","340.52400","28.37707","0.02012"
"56814","340.84800","28.40409","0.02111"
"56868","341.17200","28.43106","0.02120"
"56922","341.49600","28.45808","0.02107"
"56976","341.82000","28.48505","0.02111"
"57030","342.14400","28.51213","0.02089"
"57084","342.46800","28.53910","0.02139"
"57138","342.79200","28.56607","0.02144"
"57192","343.11600","28.59309","0.02147"
"57246","343.44000","28.62011","0.02201"
"57300","343.76400","28.64714","0.02161"
"57354","344.08800","28.67417","0.02163"
"57408","344.41200","28.70113","0.02214"
"57462","344.73600","28.72815","0.02235"
"57516","345.06000","28.75512","0.02181"
"57570","345.38400","28.78209","0.02179"
"57624","345.70800","28.80911","0.02224"
"57678","346.03200","28.83607","0.02316"
"57732","346.35600","28.86310","0.02406"
"57786","346.68000","28.89006","0.02484"
"57840","347.00400","28.91715","0.02458"
"57894","347.32800","28.94417","0.02517"
"57948","347.65200","28.97108","0.02484"
"58002","347.97600","28.99816","0.02527"
"58056","348.30000","29.02507","0.02565"
"58110","348.62400","29.05209","0.02591"
"58164","348.94800","29.07918","0.02628"
"58218","349.27200","29.10608","0.02731"
"58272","349.59600","29.13317","0.02775"
"58326","349.92000","29.16007","0.02757"
"58380","350.24400","29.18710","0.02765"
"58434","350.56800","29.21412","0.02843"
"58488","350.89200","29.24109","0.02887"
"58542","351.21600","29.26817","0.02959"
"58596","351.54000","29.29508","0.03023"
"58650","351.86400","29.32211","0.03125"
"58704","352.18800","29.34913","0.03059"
"58758","352.51200","29.37609","0.03072"
"58812","352.83600","29.40312","0.03090"
"58866","353.16000","29.43008","0.03019"
"58920","353.48400","29.45711","0.03053"
"58974","353.80800","29.48413","0.02103"
"59028","354.13200","29.51104","0.02210"
"59082","354.45600","29.53812","0.02213"
"59136","354.78000","29.56515","0.02540"
"59190","355.10400","29.59211","0.02222"
"59244","355.42800","29.61914","0.02244"
"59298","355.75200","29.64604","0.02384"
"59352","356.07600","29.67313","0.02407"
"59406","356.40000","29.70009","0.02377"
"59460","356.72400","29.72712","0.02333"
"59514","357.04800","29.75420","0.02406"
"59568","357.37200","29.78111","0.02381"
"59622","357.69600","29.80813","0.02573"
"59676","358.02000","29.83504","0.02475"
"59730","358.34400","29.86206","0.02508"
"59784","358.66800","29.88915","0.02517"
"59838","358.99200","29.91611","0.02628"
"59892","359.31600","29.94314","0.02558"
"59946","359.64000","29.97010","0.02533"
"60000","359.96400","29.99713","0.02626"
"60054","360.28800","30.02409","0.02702"
"60108","360.61200","30.05106","0.02787"
"60162","360.93600","30.07814","0.02730"
"60216","361.26000","30.10511","0.02784"
"60270","361.58400","30.13213","0.02788"
"60324","361.90800","30.15910","0.02922"
"60378","362.23200","30.18612","0.02888"
"60432","362.55600","30.21315","0.02901"
"60486","362.88000","30.24011","0.02939"
"60540","363.20400","30.26708","0.02917"
"60594","363.52800","30.29410","0.02929"
"60648","363.85200","30.32107","0.02675"
"60702","364.17600","30.34815","0.02533"
"60756","364.50000","30.37518","0.02533"
"60810","364.82400","30.40214","0.02548"
"60864","365.14800","30.42911","0.02633"
"60918","365.47200","30.45607","0.02686"
"60972","365.79600","30.48316","0.02798"
"61026","366.12000","30.51012","0.02760"
"61080","366.44400","30.53709","0.02752"
"61134","366.76800","30.56411","0.02857"
"61188","367.09200","30.59108","0.02970"
"61242","367.41600","30.61816","0.03012"
"61296","367.74000","30.64512","0.03105"
"61350","368.06400","30.67209","0.03131"
"61404","368.38800","30.69912","0.03166"
"61458","368.71200","30.72608","0.03310"
"61512","369.03600","30.75317","0.03260"
"61566","369.36000","30.78013","0.03378"
"61620","369.68400","30.80710","0.03463"
"61674","370.00800","30.83418","0.03485"
"61728","370.33200","30.86109","0.02913"
"61782","370.65600","30.88811","0.03071"
"61836","370.98000","30.91514","0.02965"
"61890","371.30400","30.94210","0.02867"
"61944","371.62800","30.96912","0.02866"
"61998","371.95200","30.99609","0.02937"
"62052","372.27600","31.02317","0.02983"
"62106","372.60000","31.05014","0.02897"
"62160","372.92400","31.07711","0.02827"
"62214","373.24800","31.10413","0.02737"
"62268","373.57200","31.13110","0.02722"
"62322","373.89600","31.15812","0.02771"
"62376","374.22000","31.18515","0.02707"
"62430","374.54400","31.21211","0.02750"
"62484","374.86800","31.23919","0.02747"
"62538","375.19200","31.26610","0.02809"
"62592","375.51600","31.29312","0.02862"
"62646","375.84000","31.32009","0.02848"
"62700","376.16400","31.34711","0.02864"
"62754","376.48800","31.37414","0.02949"
"62808","376.81200","31.40110","0.02954"
"62862","377.13600","31.42813","0.03022"
"62916","377.46000","31.45515","0.02922"
"62970","377.78400","31.48206","0.03008"
"63024","378.10800","31.50914","0.03066"
"63078","378.43200","31.53611","0.03041"
"63132","378.75600","31.56313","0.03090"
"63186","379.08000","31.59010","0.03103"
"63240","379.40400","31.61706","0.03189"
"63294","379.72800","31.64415","0.03152"
"63348","380.05200","31.67111","0.03160"
"63402","380.37600","31.69808","0.03196"
"63456","380.70000","31.72510","0.03165"
"63510","381.02400","31.75207","0.03207"
"63564","381.34800","31.77921","0.03221"
"63618","381.67200","31.80612","0.03260"
"63672","381.99600","31.83308","0.03307"
"63726","382.32000","31.86017","0.03286"
"63780","382.64400","31.88707","0.03372"
"63834","382.96800","31.91416","0.03343"
"63888","383.29200","31.94106","0.03361"
"63942","383.61600","31.96815","0.03470"
"63996","383.94000","31.99511","0.03348"
"64050","384.26400","32.02208","0.03436"
"64104","384.58800","32.04916","0.03478"
"64158","384.91200","32.07613","0.03472"
"64212","385.23600","32.10309","0.03587"
"64266","385.56000","32.13012","0.03585"
"64320","385.88400","32.15702","0.03588"
"64374","386.20800","32.18417","0.03571"
"64428","386.53200","32.21107","0.03664"
"64482","386.85600","32.23809","0.03662"
"64536","387.18000","32.26518","0.03669"
"64590","387.50400","32.29209","0.03694"
"64644","387.82800","32.31911","0.03777"
"64698","388.15200","32.34614","0.03708"
"64752","388.47600","32.37310","0.03739"
"64806","388.80000","32.40013","0.03760"
"64860","389.12400","32.42709","0.03808"
"64914","389.44800","32.45418","0.03797"
"64968","389.77200","32.48114","0.03814"
"65022","390.09600","32.50811","0.03863"
"65076","390.42000","32.53513","0.03853"
"65130","390.74400","32.56203","0.03882"
"65184","391.06800","32.58918","0.03889"
"65238","391.39200","32.61609","0.03890"
"65292","391.71600","32.64311","0.03914"
"65346","392.04000","32.67014","0.03932"
"65400","392.36400","32.69710","0.03958"
"65454","392.68800","32.72413","0.03962"
"65508","393.01200","32.75103","0.04019"
"65562","393.33600","32.77806","0.03999"
"65616","393.66000","32.80514","0.04025"
"65670","393.98400","32.83205","0.04046"
"65724","394.30800","32.85913","0.04107"
"65778","394.63200","32.88610","0.04070"
"65832","394.95600","32.91312","0.04131"
"65886","395.28000","32.94015","0.04134"
"65940","395.60400","32.96705","0.04167"
"65994","395.92800","32.99414","0.04190"
"66048","396.25200","33.02110","0.04179"
"66102","396.57600","33.04807","0.04191"
"66156","396.90000","33.07509","0.04225"
"66210","397.22400","33.10205","0.04248"
"66264","397.54800","33.12914","0.04267"
"66318","397.87200","33.15611","0.04273"
"66372","398.19600","33.18307","0.04280"
"66426","398.52000","33.21016","0.04316"
"66480","398.84400","33.23712","0.04349"
"66534","399.16800","33.26408","0.04376"
"66588","399.49200","33.29117","0.04389"
"66642","399.81600","33.31808","0.04378"
"66687","400.08200","33.34032","0.04437"