File: Trajectories_together/170225_1Specimen_RawData_3.csv
"","V1","V2","V3"
"1","End date","2/25/2017",""
"2","Specimen label","2AT_13",""
"3","Maximum Load","0.10934","N"
"4","Time","Extension","Load"
"5","(s)","(mm)","(N)"
"6","0.00000","0.00000","-0.00030"
"69","0.37800","0.03169","0.00039"
"132","0.75600","0.06320","0.00051"
"195","1.13400","0.09477","0.00092"
"258","1.51200","0.12622","0.00135"
"321","1.89000","0.15766","0.00206"
"384","2.26800","0.18923","0.00166"
"447","2.64600","0.22074","0.00154"
"510","3.02400","0.25213","0.00198"
"573","3.40200","0.28370","0.00203"
"636","3.78000","0.31521","0.00223"
"699","4.15800","0.34672","0.00233"
"762","4.53600","0.37823","0.00335"
"825","4.91400","0.40974","0.00219"
"888","5.29200","0.44125","0.00301"
"951","5.67000","0.47264","0.00263"
"1014","6.04800","0.50421","0.00334"
"1077","6.42600","0.53577","0.00314"
"1140","6.80400","0.56716","0.00345"
"1203","7.18200","0.59873","0.00329"
"1266","7.56000","0.63024","0.00361"
"1329","7.93800","0.66169","0.00396"
"1392","8.31600","0.69314","0.00396"
"1455","8.69400","0.72477","0.00426"
"1518","9.07200","0.75628","0.00489"
"1581","9.45000","0.78773","0.00424"
"1644","9.82800","0.81924","0.00453"
"1707","10.20600","0.85069","0.00513"
"1770","10.58400","0.88213","0.00460"
"1833","10.96200","0.91370","0.00520"
"1896","11.34000","0.94521","0.00518"
"1959","11.71800","0.97666","0.00576"
"2022","12.09600","1.00823","0.00595"
"2085","12.47400","1.03974","0.00535"
"2148","12.85200","1.07119","0.00532"
"2211","13.23000","1.10270","0.00616"
"2274","13.60800","1.13427","0.00535"
"2337","13.98600","1.16572","0.00588"
"2400","14.36400","1.19723","0.00626"
"2463","14.74200","1.22873","0.00646"
"2526","15.12000","1.26024","0.00558"
"2589","15.49800","1.29169","0.00647"
"2652","15.87600","1.32314","0.00652"
"2715","16.25400","1.35477","0.00712"
"2778","16.63200","1.38622","0.00676"
"2841","17.01000","1.41767","0.00761"
"2904","17.38800","1.44924","0.00641"
"2967","17.76600","1.48069","0.00753"
"3030","18.14400","1.51220","0.00690"
"3093","18.52200","1.54365","0.00645"
"3156","18.90000","1.57522","0.00705"
"3219","19.27800","1.60672","0.00730"
"3282","19.65600","1.63823","0.00656"
"3345","20.03400","1.66968","0.00757"
"3408","20.41200","1.70125","0.00762"
"3471","20.79000","1.73270","0.00724"
"3534","21.16800","1.76415","0.00672"
"3597","21.54600","1.79572","0.00787"
"3660","21.92400","1.82723","0.00741"
"3723","22.30200","1.85868","0.00776"
"3786","22.68000","1.89025","0.00786"
"3849","23.05800","1.92176","0.00786"
"3912","23.43600","1.95320","0.00766"
"3975","23.81400","1.98471","0.00825"
"4038","24.19200","2.01622","0.00775"
"4101","24.57000","2.04767","0.00762"
"4164","24.94800","2.07924","0.00791"
"4227","25.32600","2.11075","0.00809"
"4290","25.70400","2.14214","0.00775"
"4353","26.08200","2.17371","0.00804"
"4416","26.46000","2.20522","0.00801"
"4479","26.83800","2.23667","0.00845"
"4542","27.21600","2.26818","0.00709"
"4605","27.59400","2.29974","0.00770"
"4668","27.97200","2.33125","0.00748"
"4731","28.35000","2.36264","0.00765"
"4794","28.72800","2.39421","0.00731"
"4857","29.10600","2.42572","0.00754"
"4920","29.48400","2.45717","0.00805"
"4983","29.86200","2.48868","0.00763"
"5046","30.24000","2.52025","0.00743"
"5109","30.61800","2.55176","0.00763"
"5172","30.99600","2.58315","0.00771"
"5235","31.37400","2.61472","0.00762"
"5298","31.75200","2.64622","0.00710"
"5361","32.13000","2.67773","0.00724"
"5424","32.50800","2.70918","0.00737"
"5487","32.88600","2.74069","0.00776"
"5550","33.26400","2.77226","0.00805"
"5613","33.64200","2.80365","0.00753"
"5676","34.02000","2.83522","0.00759"
"5739","34.39800","2.86673","0.00810"
"5802","34.77600","2.89818","0.00733"
"5865","35.15400","2.92975","0.00752"
"5928","35.53200","2.96126","0.00700"
"5991","35.91000","2.99271","0.00712"
"6054","36.28800","3.02421","0.00683"
"6117","36.66600","3.05572","0.00720"
"6180","37.04400","3.08717","0.00726"
"6243","37.42200","3.11868","0.00692"
"6306","37.80000","3.15025","0.00780"
"6369","38.17800","3.18176","0.00723"
"6432","38.55600","3.21321","0.00707"
"6495","38.93400","3.24472","0.00695"
"6558","39.31200","3.27623","0.00712"
"6621","39.69000","3.30768","0.00685"
"6684","40.06800","3.33919","0.00678"
"6747","40.44600","3.37075","0.00686"
"6810","40.82400","3.40226","0.00711"
"6873","41.20200","3.43365","0.00674"
"6936","41.58000","3.46522","0.00669"
"6999","41.95800","3.49673","0.00726"
"7062","42.33600","3.52818","0.00685"
"7125","42.71400","3.55969","0.00694"
"7188","43.09200","3.59120","0.00738"
"7251","43.47000","3.62271","0.00741"
"7314","43.84800","3.65416","0.00707"
"7377","44.22600","3.68573","0.00717"
"7440","44.60400","3.71723","0.00718"
"7503","44.98200","3.74862","0.00724"
"7566","45.36000","3.78019","0.00681"
"7629","45.73800","3.81176","0.00771"
"7692","46.11600","3.84321","0.00752"
"7755","46.49400","3.87466","0.00712"
"7818","46.87200","3.90623","0.00728"
"7881","47.25000","3.93768","0.00630"
"7944","47.62800","3.96919","0.00734"
"8007","48.00600","4.00076","0.00654"
"8070","48.38400","4.03227","0.00710"
"8133","48.76200","4.06372","0.00640"
"8196","49.14000","4.09516","0.00658"
"8259","49.51800","4.12673","0.00620"
"8322","49.89600","4.15818","0.00624"
"8385","50.27400","4.18975","0.00601"
"8448","50.65200","4.22126","0.00640"
"8511","51.03000","4.25271","0.00638"
"8574","51.40800","4.28416","0.00631"
"8637","51.78600","4.31573","0.00638"
"8700","52.16400","4.34724","0.00615"
"8763","52.54200","4.37869","0.00702"
"8826","52.92000","4.41026","0.00664"
"8889","53.29800","4.44170","0.00682"
"8952","53.67600","4.47321","0.00667"
"9015","54.05400","4.50466","0.00642"
"9078","54.43200","4.53617","0.00700"
"9141","54.81000","4.56774","0.00684"
"9204","55.18800","4.59919","0.00704"
"9267","55.56600","4.63070","0.00670"
"9330","55.94400","4.66227","0.00688"
"9393","56.32200","4.69366","0.00726"
"9456","56.70000","4.72517","0.00748"
"9519","57.07800","4.75674","0.00714"
"9582","57.45600","4.78824","0.00695"
"9645","57.83400","4.81969","0.00718"
"9708","58.21200","4.85126","0.00724"
"9771","58.59000","4.88277","0.00705"
"9834","58.96800","4.91416","0.00681"
"9897","59.34600","4.94567","0.00701"
"9960","59.72400","4.97724","0.00661"
"10023","60.10200","5.00869","0.00747"
"10086","60.48000","5.04020","0.00705"
"10149","60.85800","5.07177","0.00699"
"10212","61.23600","5.10328","0.00702"
"10275","61.61400","5.13467","0.00715"
"10338","61.99200","5.16617","0.00712"
"10401","62.37000","5.19774","0.00725"
"10464","62.74800","5.22913","0.00733"
"10527","63.12600","5.26070","0.00730"
"10590","63.50400","5.29221","0.00640"
"10653","63.88200","5.32372","0.00653"
"10716","64.26000","5.35523","0.00667"
"10779","64.63800","5.38674","0.00689"
"10842","65.01600","5.41825","0.00753"
"10905","65.39400","5.44970","0.00712"
"10968","65.77200","5.48127","0.00695"
"11031","66.15000","5.51277","0.00720"
"11094","66.52800","5.54416","0.00736"
"11157","66.90600","5.57573","0.00742"
"11220","67.28400","5.60718","0.00793"
"11283","67.66200","5.63869","0.00757"
"11346","68.04000","5.67020","0.00770"
"11409","68.41800","5.70177","0.00796"
"11472","68.79600","5.73316","0.00742"
"11535","69.17400","5.76467","0.00765"
"11598","69.55200","5.79624","0.00782"
"11661","69.93000","5.82769","0.00761"
"11724","70.30800","5.85925","0.00771"
"11787","70.68600","5.89070","0.00766"
"11850","71.06400","5.92221","0.00762"
"11913","71.44200","5.95372","0.00781"
"11976","71.82000","5.98517","0.00775"
"12039","72.19800","6.01674","0.00794"
"12102","72.57600","6.04819","0.00850"
"12165","72.95400","6.07964","0.00761"
"12228","73.33200","6.11127","0.00835"
"12291","73.71000","6.14272","0.00837"
"12354","74.08800","6.17417","0.00825"
"12417","74.46600","6.20574","0.00847"
"12480","74.84400","6.23718","0.00860"
"12543","75.22200","6.26869","0.00864"
"12606","75.60000","6.30020","0.00885"
"12669","75.97800","6.33177","0.00915"
"12732","76.35600","6.36322","0.00887"
"12795","76.73400","6.39467","0.00871"
"12858","77.11200","6.42618","0.00847"
"12921","77.49000","6.45775","0.00861"
"12984","77.86800","6.48920","0.00845"
"13047","78.24600","6.52071","0.00883"
"13110","78.62400","6.55228","0.00931"
"13173","79.00200","6.58372","0.00907"
"13236","79.38000","6.61517","0.00901"
"13299","79.75800","6.64674","0.00800"
"13362","80.13600","6.67819","0.00797"
"13425","80.51400","6.70970","0.00789"
"13488","80.89200","6.74121","0.00850"
"13551","81.27000","6.77272","0.00818"
"13614","81.64800","6.80423","0.00832"
"13677","82.02600","6.83568","0.00783"
"13740","82.40400","6.86725","0.00829"
"13803","82.78200","6.89876","0.00884"
"13866","83.16000","6.93015","0.00913"
"13929","83.53800","6.96171","0.00915"
"13992","83.91600","6.99328","0.00911"
"14055","84.29400","7.02467","0.00906"
"14118","84.67200","7.05624","0.00930"
"14181","85.05000","7.08775","0.00931"
"14244","85.42800","7.11914","0.00929"
"14307","85.80600","7.15071","0.00935"
"14370","86.18400","7.18222","0.00943"
"14433","86.56200","7.21373","0.00925"
"14496","86.94000","7.24518","0.00952"
"14559","87.31800","7.27668","0.00989"
"14622","87.69600","7.30819","0.01020"
"14685","88.07400","7.33964","0.01046"
"14748","88.45200","7.37121","0.01020"
"14811","88.83000","7.40272","0.01068"
"14874","89.20800","7.43423","0.01029"
"14937","89.58600","7.46568","0.01021"
"15000","89.96400","7.49719","0.01087"
"15063","90.34200","7.52870","0.01077"
"15126","90.72000","7.56015","0.01125"
"15189","91.09800","7.59178","0.01156"
"15252","91.47600","7.62323","0.01119"
"15315","91.85400","7.65468","0.01094"
"15378","92.23200","7.68618","0.01099"
"15441","92.61000","7.71769","0.01077"
"15504","92.98800","7.74920","0.01196"
"15567","93.36600","7.78071","0.01157"
"15630","93.74400","7.81222","0.01185"
"15693","94.12200","7.84373","0.01194"
"15756","94.50000","7.87518","0.01311"
"15819","94.87800","7.90669","0.01304"
"15882","95.25600","7.93820","0.01368"
"15945","95.63400","7.96971","0.01381"
"16008","96.01200","8.00121","0.01404"
"16071","96.39000","8.03272","0.01393"
"16134","96.76800","8.06423","0.01522"
"16197","97.14600","8.09568","0.01567"
"16260","97.52400","8.12719","0.01636"
"16323","97.90200","8.15870","0.01699"
"16386","98.28000","8.19021","0.01763"
"16449","98.65800","8.22166","0.01819"
"16512","99.03600","8.25323","0.01951"
"16575","99.41400","8.28468","0.01973"
"16638","99.79200","8.31619","0.02035"
"16701","100.17000","8.34775","0.01918"
"16764","100.54800","8.37926","0.02065"
"16827","100.92600","8.41065","0.02145"
"16890","101.30400","8.44228","0.02243"
"16953","101.68200","8.47373","0.02459"
"17016","102.06000","8.50518","0.02477"
"17079","102.43800","8.53675","0.02587"
"17142","102.81600","8.56826","0.02715"
"17205","103.19400","8.59971","0.02821"
"17268","103.57200","8.63116","0.02940"
"17331","103.95000","8.66273","0.03054"
"17394","104.32800","8.69423","0.03173"
"17457","104.70600","8.72568","0.03275"
"17520","105.08400","8.75719","0.03469"
"17583","105.46200","8.78876","0.03601"
"17646","105.84000","8.82021","0.03695"
"17709","106.21800","8.85166","0.03904"
"17772","106.59600","8.88329","0.03891"
"17835","106.97400","8.91474","0.04023"
"17898","107.35200","8.94619","0.04059"
"17961","107.73000","8.97776","0.03875"
"18024","108.10800","9.00921","0.03982"
"18087","108.48600","9.04066","0.04114"
"18150","108.86400","9.07222","0.04234"
"18213","109.24200","9.10373","0.04264"
"18276","109.62000","9.13524","0.04321"
"18339","109.99800","9.16669","0.04422"
"18402","110.37600","9.19826","0.04488"
"18465","110.75400","9.22971","0.04564"
"18528","111.13200","9.26116","0.04596"
"18591","111.51000","9.29273","0.04639"
"18654","111.88800","9.32424","0.04690"
"18717","112.26600","9.35569","0.04737"
"18780","112.64400","9.38720","0.04788"
"18843","113.02200","9.41870","0.04827"
"18906","113.40000","9.45021","0.04898"
"18969","113.77800","9.48172","0.04528"
"19032","114.15600","9.51323","0.04635"
"19095","114.53400","9.54474","0.04749"
"19158","114.91200","9.57619","0.04797"
"19221","115.29000","9.60770","0.04885"
"19284","115.66800","9.63927","0.04935"
"19347","116.04600","9.67072","0.05004"
"19410","116.42400","9.70223","0.05023"
"19473","116.80200","9.73374","0.05080"
"19536","117.18000","9.76525","0.05155"
"19599","117.55800","9.79669","0.05230"
"19662","117.93600","9.82820","0.05283"
"19725","118.31400","9.85971","0.04888"
"19788","118.69200","9.89116","0.05030"
"19851","119.07000","9.92273","0.05046"
"19914","119.44800","9.95424","0.05211"
"19977","119.82600","9.98569","0.05278"
"20040","120.20400","10.01720","0.05281"
"20103","120.58200","10.04871","0.05469"
"20166","120.96000","10.08022","0.05519"
"20229","121.33800","10.11167","0.05566"
"20292","121.71600","10.14323","0.05735"
"20355","122.09400","10.17480","0.05977"
"20418","122.47200","10.20613","0.05948"
"20481","122.85000","10.23770","0.06022"
"20544","123.22800","10.26927","0.06290"
"20607","123.60600","10.30072","0.06405"
"20670","123.98400","10.33217","0.06506"
"20733","124.36200","10.36374","0.06649"
"20796","124.74000","10.39525","0.06882"
"20859","125.11800","10.42676","0.06903"
"20922","125.49600","10.45826","0.07030"
"20985","125.87400","10.48972","0.07191"
"21048","126.25200","10.52116","0.07337"
"21111","126.63000","10.55267","0.07408"
"21174","127.00800","10.58424","0.07552"
"21237","127.38600","10.61575","0.07667"
"21300","127.76400","10.64720","0.07786"
"21363","128.14200","10.67871","0.07810"
"21426","128.52000","10.71016","0.07921"
"21489","128.89800","10.74167","0.08117"
"21552","129.27600","10.77324","0.08277"
"21615","129.65400","10.80475","0.08344"
"21678","130.03200","10.83619","0.08557"
"21741","130.41000","10.86776","0.08718"
"21804","130.78800","10.89921","0.08821"
"21867","131.16600","10.93066","0.08955"
"21930","131.54400","10.96217","0.09087"
"21993","131.92200","10.99374","0.09232"
"22056","132.30000","11.02525","0.09325"
"22119","132.67800","11.05664","0.09388"
"22182","133.05600","11.08821","0.09450"
"22245","133.43400","11.11978","0.09490"
"22308","133.81200","11.15117","0.09547"
"22371","134.19000","11.18268","0.09620"
"22434","134.56800","11.21424","0.09645"
"22497","134.94600","11.24569","0.09720"
"22560","135.32400","11.27714","0.09799"
"22623","135.70200","11.30871","0.09905"
"22686","136.08000","11.34022","0.09944"
"22749","136.45800","11.37167","0.10088"
"22812","136.83600","11.40324","0.10204"
"22875","137.21400","11.43475","0.10330"
"22938","137.59200","11.46620","0.10582"
"23001","137.97000","11.49765","0.10697"
"23064","138.34800","11.52922","0.10801"
"23127","138.72600","11.56073","0.10824"
"23190","139.10400","11.59223","0.10906"
"23253","139.48200","11.62374","0.10784"
"23316","139.86000","11.65525","0.00696"
"23379","140.23800","11.68664","0.00083"
"23442","140.61600","11.71821","0.00261"
"23505","140.99400","11.74972","-0.00005"
"23568","141.37200","11.78117","0.00187"
"23631","141.75000","11.81268","0.00128"
"23694","142.12800","11.84419","0.00137"
"23757","142.50600","11.87570","0.00237"
"23820","142.88400","11.90721","0.00160"
"23883","143.26200","11.93877","0.00159"
"23946","143.64000","11.97028","0.00180"
"24009","144.01800","12.00167","0.00221"
"24072","144.39600","12.03324","0.00190"
"24135","144.77400","12.06475","0.00203"
"24198","145.15200","12.09620","0.00242"
"24261","145.53000","12.12765","0.00234"
"24324","145.90800","12.15928","0.00291"
"24387","146.28600","12.19067","0.00160"
"24450","146.66400","12.22218","0.00141"
"24513","147.04200","12.25375","0.00263"
"24576","147.42000","12.28525","0.00169"
"24639","147.79800","12.31670","0.00236"
"24702","148.17600","12.34821","0.00187"
"24765","148.55400","12.37972","0.00228"
"24828","148.93200","12.41117","0.00175"
"24891","149.31000","12.44268","0.00226"
"24954","149.68800","12.47419","0.00203"
"25017","150.06600","12.50576","0.00248"
"25080","150.44400","12.53715","0.00167"
"25143","150.82200","12.56872","0.00234"
"25206","151.20000","12.60023","0.00248"
"25269","151.57800","12.63167","0.00281"
"25332","151.95600","12.66318","0.00264"
"25395","152.33400","12.69475","0.00182"
"25458","152.71200","12.72626","0.00259"
"25521","153.09000","12.75771","0.00226"
"25584","153.46800","12.78922","0.00215"
"25647","153.84600","12.82079","0.00234"
"25710","154.22400","12.85218","0.00205"
"25773","154.60200","12.88369","0.00196"
"25836","154.98000","12.91526","0.00320"
"25899","155.35800","12.94671","0.00269"
"25962","155.73600","12.97816","0.00203"
"26025","156.11400","13.00972","0.00250"
"26088","156.49200","13.04123","0.00294"
"26151","156.87000","13.07262","0.00244"
"26214","157.24800","13.10425","0.00315"
"26277","157.62600","13.13576","0.00213"
"26340","158.00400","13.16721","0.00264"
"26403","158.38200","13.19872","0.00263"
"26466","158.76000","13.23017","0.00259"
"26529","159.13800","13.26174","0.00253"
"26592","159.51600","13.29319","0.00258"
"26655","159.89400","13.32476","0.00280"
"26718","160.27200","13.35627","0.00311"
"26781","160.65000","13.38771","0.00310"
"26844","161.02800","13.41922","0.00243"
"26907","161.40600","13.45079","0.00260"
"26970","161.78400","13.48212","0.00282"
"27033","162.16200","13.51375","0.00292"
"27096","162.54000","13.54526","0.00330"
"27159","162.91800","13.57671","0.00296"
"27222","163.29600","13.60816","0.00258"
"27285","163.67400","13.63979","0.00321"
"27348","164.05200","13.67124","0.00266"
"27411","164.43000","13.70268","0.00361"
"27474","164.80800","13.73419","0.00271"
"27537","165.18600","13.76570","0.00331"
"27600","165.56400","13.79721","0.00275"
"27663","165.94200","13.82866","0.00251"
"27726","166.32000","13.86023","0.00402"
"27789","166.69800","13.89174","0.00283"
"27852","167.07600","13.92319","0.00343"
"27915","167.45400","13.95470","0.00274"
"27978","167.83200","13.98621","0.00368"
"28041","168.21000","14.01772","0.00319"
"28104","168.58800","14.04928","0.00288"
"28167","168.96600","14.08068","0.00317"
"28230","169.34400","14.11218","0.00348"
"28293","169.72200","14.14369","0.00353"
"28356","170.10000","14.17520","0.00301"
"28419","170.47800","14.20671","0.00363"
"28482","170.85600","14.23822","0.00409"
"28545","171.23400","14.26973","0.00257"
"28608","171.61200","14.30124","0.00318"
"28671","171.99000","14.33263","0.00417"
"28734","172.36800","14.36420","0.00342"
"28797","172.74600","14.39577","0.00364"
"28860","173.12400","14.42721","0.00360"
"28923","173.50200","14.45872","0.00383"
"28986","173.88000","14.49023","0.00407"
"29049","174.25800","14.52168","0.00322"
"29112","174.63600","14.55319","0.00376"
"29175","175.01400","14.58470","0.00409"
"29238","175.39200","14.61627","0.00342"
"29301","175.77000","14.64766","0.00372"
"29364","176.14800","14.67917","0.00446"
"29427","176.52600","14.71068","0.00369"
"29490","176.90400","14.74224","0.00365"
"29553","177.28200","14.77363","0.00352"
"29616","177.66000","14.80520","0.00367"
"29679","178.03800","14.83677","0.00360"
"29742","178.41600","14.86810","0.00378"
"29805","178.79400","14.89973","0.00399"
"29868","179.17200","14.93124","0.00425"
"29931","179.55000","14.96263","0.00448"
"29994","179.92800","14.99426","0.00429"
"30057","180.30600","15.02571","0.00408"
"30120","180.68400","15.05722","0.00397"
"30183","181.06200","15.08867","0.00353"
"30246","181.44000","15.12024","0.00234"
"30309","181.81800","15.15174","0.00300"
"30372","182.19600","15.18319","0.00273"
"30435","182.57400","15.21470","0.00308"
"30498","182.95200","15.24627","0.00262"
"30561","183.33000","15.27772","0.00282"
"30624","183.70800","15.30923","0.00247"
"30687","184.08600","15.34080","0.00273"
"30750","184.46400","15.37225","0.00287"
"30813","184.84200","15.40364","0.00268"
"30876","185.22000","15.43527","0.00277"
"30939","185.59800","15.46672","0.00338"
"31002","185.97600","15.49822","0.00297"
"31065","186.35400","15.52973","0.00349"
"31128","186.73200","15.56118","0.00310"
"31191","187.11000","15.59269","0.00309"
"31254","187.48800","15.62420","0.00289"
"31317","187.86600","15.65577","0.00324"
"31380","188.24400","15.68722","0.00347"
"31443","188.62200","15.71867","0.00288"
"31506","189.00000","15.75024","0.00329"
"31569","189.37800","15.78174","0.00369"
"31632","189.75600","15.81313","0.00288"
"31695","190.13400","15.84470","0.00265"
"31758","190.51200","15.87621","0.00328"
"31821","190.89000","15.90772","0.00327"
"31884","191.26800","15.93917","0.00321"
"31947","191.64600","15.97068","0.00315"
"32010","192.02400","16.00219","0.00341"
"32073","192.40200","16.03370","0.00302"
"32136","192.78000","16.06521","0.00284"
"32199","193.15800","16.09672","0.00354"
"32262","193.53600","16.12823","0.00287"
"32325","193.91400","16.15968","0.00365"
"32388","194.29200","16.19124","0.00279"
"32451","194.67000","16.22269","0.00304"
"32514","195.04800","16.25420","0.00294"
"32577","195.42600","16.28571","0.00311"
"32640","195.80400","16.31722","0.00345"
"32703","196.18200","16.34867","0.00358"
"32766","196.56000","16.38024","0.00318"
"32829","196.93800","16.41175","0.00283"
"32892","197.31600","16.44320","0.00283"
"32955","197.69400","16.47471","0.00291"
"33018","198.07200","16.50622","0.00313"
"33081","198.45000","16.53772","0.00349"
"33144","198.82800","16.56918","0.00278"
"33207","199.20600","16.60074","0.00333"
"33270","199.58400","16.63225","0.00293"
"33333","199.96200","16.66364","0.00278"
"33396","200.34000","16.69527","0.00301"
"33459","200.71800","16.72678","0.00288"
"33522","201.09600","16.75817","0.00313"
"33585","201.47400","16.78974","0.00286"
"33648","201.85200","16.82119","0.00320"
"33711","202.23000","16.85275","0.00254"
"33774","202.60800","16.88421","0.00311"
"33837","202.98600","16.91571","0.00328"
"33900","203.36400","16.94728","0.00306"
"33963","203.74200","16.97867","0.00274"
"34026","204.12000","17.01024","0.00312"
"34089","204.49800","17.04169","0.00320"
"34152","204.87600","17.07320","0.00309"
"34215","205.25400","17.10471","0.00301"
"34278","205.63200","17.13622","0.00318"
"34341","206.01000","17.16773","0.00307"
"34404","206.38800","17.19912","0.00281"
"34467","206.76600","17.23075","0.00375"
"34530","207.14400","17.26219","0.00318"
"34593","207.52200","17.29364","0.00338"
"34656","207.90000","17.32521","0.00332"
"34719","208.27800","17.35672","0.00339"
"34782","208.65600","17.38823","0.00276"
"34845","209.03400","17.41968","0.00304"
"34908","209.41200","17.45125","0.00349"
"34971","209.79000","17.48270","0.00316"
"35034","210.16800","17.51415","0.00323"
"35097","210.54600","17.54566","0.00313"
"35160","210.92400","17.57729","0.00322"
"35223","211.30200","17.60874","0.00319"
"35286","211.68000","17.64024","0.00322"
"35349","212.05800","17.67175","0.00348"
"35412","212.43600","17.70320","0.00354"
"35475","212.81400","17.73465","0.00261"
"35538","213.19200","17.76628","0.00318"
"35601","213.57000","17.79773","0.00318"
"35664","213.94800","17.82918","0.00376"
"35727","214.32600","17.86075","0.00361"
"35790","214.70400","17.89220","0.00331"
"35853","215.08200","17.92371","0.00290"
"35916","215.46000","17.95516","0.00274"
"35979","215.83800","17.98672","0.00322"
"36042","216.21600","18.01823","0.00361"
"36105","216.59400","18.04968","0.00336"
"36168","216.97200","18.08125","0.00301"
"36231","217.35000","18.11276","0.00302"
"36294","217.72800","18.14415","0.00358"
"36357","218.10600","18.17578","0.00314"
"36420","218.48400","18.20723","0.00323"
"36483","218.86200","18.23868","0.00377"
"36546","219.24000","18.27019","0.00313"
"36609","219.61800","18.30176","0.00398"
"36672","219.99600","18.33320","0.00378"
"36735","220.37400","18.36465","0.00365"
"36798","220.75200","18.39622","0.00333"
"36861","221.13000","18.42773","0.00351"
"36924","221.50800","18.45918","0.00331"
"36987","221.88600","18.49069","0.00385"
"37050","222.26400","18.52226","0.00304"
"37113","222.64200","18.55365","0.00362"
"37176","223.02000","18.58516","0.00347"
"37239","223.39800","18.61673","0.00385"
"37302","223.77600","18.64818","0.00403"
"37365","224.15400","18.67969","0.00405"
"37428","224.53200","18.71125","0.00382"
"37491","224.91000","18.74276","0.00402"
"37554","225.28800","18.77415","0.00404"
"37617","225.66600","18.80572","0.00365"
"37680","226.04400","18.83723","0.00374"
"37743","226.42200","18.86874","0.00372"
"37806","226.80000","18.90019","0.00344"
"37869","227.17800","18.93176","0.00368"
"37932","227.55600","18.96327","0.00391"
"37995","227.93400","18.99466","0.00370"
"38058","228.31200","19.02623","0.00358"
"38121","228.69000","19.05773","0.00351"
"38184","229.06800","19.08924","0.00390"
"38247","229.44600","19.12069","0.00346"
"38310","229.82400","19.15220","0.00382"
"38373","230.20200","19.18371","0.00402"
"38436","230.58000","19.21522","0.00362"
"38499","230.95800","19.24673","0.00392"
"38562","231.33600","19.27824","0.00391"
"38625","231.71400","19.30975","0.00346"
"38688","232.09200","19.34126","0.00358"
"38751","232.47000","19.37271","0.00375"
"38814","232.84800","19.40421","0.00406"
"38877","233.22600","19.43567","0.00385"
"38940","233.60400","19.46729","0.00394"
"39003","233.98200","19.49874","0.00394"
"39066","234.36000","19.53013","0.00450"
"39129","234.73800","19.56176","0.00446"
"39192","235.11600","19.59327","0.00380"
"39255","235.49400","19.62466","0.00377"
"39318","235.87200","19.65623","0.00469"
"39381","236.25000","19.68773","0.00382"
"39444","236.62800","19.71918","0.00399"
"39507","237.00600","19.75070","0.00346"
"39570","237.38400","19.78226","0.00401"
"39633","237.76200","19.81371","0.00416"
"39696","238.14000","19.84516","0.00344"
"39759","238.51800","19.87667","0.00382"
"39822","238.89600","19.90830","0.00340"
"39885","239.27400","19.93969","0.00347"
"39948","239.65200","19.97120","0.00284"
"40011","240.03000","20.00271","0.00180"
"40074","240.40800","20.03422","0.00182"
"40137","240.78600","20.06567","0.00226"
"40200","241.16400","20.09723","0.00144"
"40263","241.54200","20.12874","0.00220"
"40326","241.92000","20.16019","0.00164"
"40389","242.29800","20.19170","0.00150"
"40452","242.67600","20.22315","0.00216"
"40515","243.05400","20.25472","0.00253"
"40578","243.43200","20.28623","0.00207"
"40641","243.81000","20.31768","0.00225"
"40704","244.18800","20.34919","0.00168"
"40767","244.56600","20.38070","0.00206"
"40830","244.94400","20.41221","0.00220"
"40893","245.32200","20.44372","0.00286"
"40956","245.70000","20.47517","0.00214"
"41019","246.07800","20.50667","0.00147"
"41082","246.45600","20.53824","0.00272"
"41145","246.83400","20.56969","0.00226"
"41208","247.21200","20.60120","0.00250"
"41271","247.59000","20.63277","0.00221"
"41334","247.96800","20.66422","0.00246"
"41397","248.34600","20.69567","0.00225"
"41460","248.72400","20.72718","0.00247"
"41523","249.10200","20.75869","0.00220"
"41586","249.48000","20.79014","0.00206"
"41649","249.85800","20.82170","0.00223"
"41712","250.23600","20.85327","0.00232"
"41775","250.61400","20.88466","0.00253"
"41838","250.99200","20.91617","0.00249"
"41901","251.37000","20.94774","0.00216"
"41964","251.74800","20.97925","0.00241"
"42027","252.12600","21.01070","0.00229"
"42090","252.50400","21.04221","0.00345"
"42153","252.88200","21.07372","0.00281"
"42216","253.26000","21.10517","0.00300"
"42279","253.63800","21.13667","0.00279"
"42342","254.01600","21.16818","0.00276"
"42405","254.39400","21.19975","0.00269"
"42468","254.77200","21.23120","0.00257"
"42531","255.15000","21.26277","0.00257"
"42594","255.52800","21.29422","0.00243"
"42657","255.90600","21.32561","0.00232"
"42720","256.28400","21.35724","0.00251"
"42783","256.66200","21.38875","0.00298"
"42846","257.04000","21.42020","0.00202"
"42909","257.41800","21.45177","0.00253"
"42972","257.79600","21.48328","0.00275"
"43035","258.17400","21.51467","0.00247"
"43098","258.55200","21.54618","0.00243"
"43161","258.93000","21.57774","0.00229"
"43224","259.30800","21.60925","0.00245"
"43287","259.68600","21.64070","0.00299"
"43350","260.06400","21.67221","0.00194"
"43413","260.44200","21.70372","0.00302"
"43476","260.82000","21.73517","0.00333"
"43539","261.19800","21.76668","0.00285"
"43602","261.57600","21.79825","0.00315"
"43665","261.95400","21.82970","0.00288"
"43728","262.33200","21.86121","0.00284"
"43791","262.71000","21.89277","0.00367"
"43854","263.08800","21.92422","0.00286"
"43917","263.46600","21.95567","0.00307"
"43980","263.84400","21.98724","0.00304"
"44043","264.22200","22.01869","0.00307"
"44106","264.60000","22.05020","0.00335"
"44169","264.97800","22.08171","0.00298"
"44232","265.35600","22.11322","0.00346"
"44295","265.73400","22.14473","0.00301"
"44358","266.11200","22.17618","0.00325"
"44421","266.49000","22.20769","0.00387"
"44484","266.86800","22.23925","0.00299"
"44547","267.24600","22.27064","0.00383"
"44610","267.62400","22.30221","0.00325"
"44673","268.00200","22.33372","0.00305"
"44736","268.38000","22.36523","0.00357"
"44799","268.75800","22.39668","0.00310"
"44862","269.13600","22.42825","0.00362"
"44925","269.51400","22.45970","0.00308"
"44988","269.89200","22.49121","0.00331"
"45051","270.27000","22.52272","0.00352"
"45114","270.64800","22.55429","0.00372"
"45177","271.02600","22.58567","0.00334"
"45240","271.40400","22.61712","0.00415"
"45303","271.78200","22.64875","0.00371"
"45366","272.16000","22.68026","0.00359"
"45429","272.53800","22.71171","0.00363"
"45492","272.91600","22.74322","0.00357"
"45555","273.29400","22.77473","0.00403"
"45618","273.67200","22.80618","0.00405"
"45681","274.05000","22.83769","0.00366"
"45744","274.42800","22.86920","0.00378"
"45807","274.80600","22.90071","0.00391"
"45870","275.18400","22.93222","0.00368"
"45933","275.56200","22.96372","0.00406"
"45996","275.94000","22.99517","0.00397"
"46059","276.31800","23.02668","0.00397"
"46122","276.69600","23.05825","0.00371"
"46185","277.07400","23.08976","0.00414"
"46248","277.45200","23.12115","0.00400"
"46311","277.83000","23.15272","0.00389"
"46374","278.20800","23.18423","0.00449"
"46437","278.58600","23.21568","0.00466"
"46500","278.96400","23.24719","0.00441"
"46563","279.34200","23.27870","0.00455"
"46626","279.72000","23.31014","0.00463"
"46689","280.09800","23.34166","0.00397"
"46752","280.47600","23.37322","0.00447"
"46815","280.85400","23.40473","0.00478"
"46878","281.23200","23.43618","0.00460"
"46941","281.61000","23.46769","0.00494"
"47004","281.98800","23.49920","0.00442"
"47067","282.36600","23.53071","0.00454"
"47130","282.74400","23.56216","0.00449"
"47193","283.12200","23.59379","0.00494"
"47256","283.50000","23.62523","0.00489"
"47319","283.87800","23.65668","0.00438"
"47382","284.25600","23.68826","0.00465"
"47445","284.63400","23.71970","0.00401"
"47508","285.01200","23.75115","0.00510"
"47571","285.39000","23.78272","0.00524"
"47634","285.76800","23.81417","0.00409"
"47697","286.14600","23.84568","0.00454"
"47760","286.52400","23.87725","0.00490"
"47823","286.90200","23.90870","0.00459"
"47886","287.28000","23.94020","0.00498"
"47949","287.65800","23.97172","0.00414"
"48012","288.03600","24.00316","0.00501"
"48075","288.41400","24.03473","0.00489"
"48138","288.79200","24.06618","0.00458"
"48201","289.17000","24.09769","0.00459"
"48264","289.54800","24.12920","0.00430"
"48327","289.92600","24.16077","0.00482"
"48390","290.30400","24.19216","0.00498"
"48453","290.68200","24.22373","0.00458"
"48516","291.06000","24.25524","0.00454"
"48579","291.43800","24.28663","0.00442"
"48642","291.81600","24.31826","0.00447"
"48705","292.19400","24.34971","0.00460"
"48768","292.57200","24.38121","0.00391"
"48831","292.95000","24.41272","0.00442"
"48894","293.32800","24.44423","0.00493"
"48957","293.70600","24.47574","0.00429"
"49020","294.08400","24.50713","0.00383"
"49083","294.46200","24.53876","0.00440"
"49146","294.84000","24.57027","0.00407"
"49209","295.21800","24.60166","0.00429"
"49272","295.59600","24.63323","0.00422"
"49335","295.97400","24.66468","0.00363"
"49398","296.35200","24.69625","0.00378"
"49461","296.73000","24.72770","0.00418"
"49524","297.10800","24.75920","0.00363"
"49587","297.48600","24.79071","0.00436"
"49650","297.86400","24.82216","0.00362"
"49713","298.24200","24.85373","0.00494"
"49776","298.62000","24.88524","0.00392"
"49839","298.99800","24.91669","0.00446"
"49902","299.37600","24.94820","0.00362"
"49965","299.75400","24.97971","0.00407"
"50028","300.13200","25.01116","0.00378"
"50091","300.51000","25.04273","0.00412"
"50154","300.88800","25.07424","0.00402"
"50217","301.26600","25.10575","0.00421"
"50280","301.64400","25.13713","0.00435"
"50343","302.02200","25.16876","0.00441"
"50406","302.40000","25.20021","0.00399"
"50469","302.77800","25.23172","0.00389"
"50532","303.15600","25.26317","0.00368"
"50595","303.53400","25.29468","0.00435"
"50658","303.91200","25.32625","0.00449"
"50721","304.29000","25.35770","0.00413"
"50784","304.66800","25.38921","0.00431"
"50847","305.04600","25.42071","0.00422"
"50910","305.42400","25.45217","0.00383"
"50973","305.80200","25.48368","0.00363"
"51036","306.18000","25.51518","0.00296"
"51099","306.55800","25.54669","0.00340"
"51162","306.93600","25.57820","0.00345"
"51225","307.31400","25.60971","0.00319"
"51288","307.69200","25.64122","0.00367"
"51351","308.07000","25.67267","0.00310"
"51414","308.44800","25.70424","0.00399"
"51477","308.82600","25.73575","0.00359"
"51540","309.20400","25.76720","0.00424"
"51603","309.58200","25.79865","0.00381"
"51666","309.96000","25.83021","0.00385"
"51729","310.33800","25.86172","0.00286"
"51792","310.71600","25.89317","0.00368"
"51855","311.09400","25.92474","0.00328"
"51918","311.47200","25.95619","0.00345"
"51981","311.85000","25.98764","0.00341"
"52044","312.22800","26.01921","0.00344"
"52107","312.60600","26.05072","0.00329"
"52170","312.98400","26.08217","0.00363"
"52233","313.36200","26.11374","0.00391"
"52296","313.74000","26.14524","0.00356"
"52359","314.11800","26.17669","0.00346"
"52422","314.49600","26.20820","0.00399"
"52485","314.87400","26.23971","0.00359"
"52548","315.25200","26.27128","0.00334"
"52611","315.63000","26.30267","0.00364"
"52674","316.00800","26.33418","0.00391"
"52737","316.38600","26.36581","0.00304"
"52800","316.76400","26.39720","0.00383"
"52863","317.14200","26.42871","0.00370"
"52926","317.52000","26.46021","0.00348"
"52989","317.89800","26.49173","0.00355"
"53052","318.27600","26.52317","0.00417"
"53115","318.65400","26.55480","0.00351"
"53178","319.03200","26.58619","0.00299"
"53241","319.41000","26.61770","0.00326"
"53304","319.78800","26.64921","0.00283"
"53367","320.16600","26.68072","0.00268"
"53430","320.54400","26.71223","0.00326"
"53493","320.92200","26.74374","0.00342"
"53556","321.30000","26.77525","0.00256"
"53619","321.67800","26.80670","0.00344"
"53682","322.05600","26.83821","0.00312"
"53745","322.43400","26.86972","0.00305"
"53808","322.81200","26.90116","0.00317"
"53871","323.19000","26.93268","0.00392"
"53934","323.56800","26.96424","0.00311"
"53997","323.94600","26.99569","0.00275"
"54060","324.32400","27.02720","0.00339"
"54123","324.70200","27.05871","0.00313"
"54186","325.08000","27.09022","0.00345"
"54249","325.45800","27.12167","0.00327"
"54312","325.83600","27.15318","0.00296"
"54375","326.21400","27.18469","0.00313"
"54438","326.59200","27.21626","0.00368"
"54501","326.97000","27.24765","0.00380"
"54564","327.34800","27.27921","0.00358"
"54627","327.72600","27.31078","0.00315"
"54690","328.10400","27.34223","0.00300"
"54753","328.48200","27.37368","0.00353"
"54816","328.86000","27.40525","0.00329"
"54879","329.23800","27.43676","0.00308"
"54942","329.61600","27.46815","0.00322"
"55005","329.99400","27.49972","0.00328"
"55068","330.37200","27.53123","0.00352"
"55131","330.75000","27.56268","0.00389"
"55194","331.12800","27.59418","0.00346"
"55257","331.50600","27.62569","0.00330"
"55320","331.88400","27.65721","0.00387"
"55383","332.26200","27.68865","0.00349"
"55446","332.64000","27.72028","0.00370"
"55509","333.01800","27.75173","0.00386"
"55572","333.39600","27.78318","0.00326"
"55635","333.77400","27.81475","0.00369"
"55698","334.15200","27.84626","0.00390"
"55761","334.53000","27.87765","0.00352"
"55824","334.90800","27.90922","0.00364"
"55887","335.28600","27.94072","0.00449"
"55950","335.66400","27.97224","0.00367"
"56013","336.04200","28.00374","0.00302"
"56076","336.42000","28.03525","0.00382"
"56139","336.79800","28.06676","0.00335"
"56202","337.17600","28.09815","0.00381"
"56265","337.55400","28.12972","0.00348"
"56328","337.93200","28.16123","0.00422"
"56391","338.31000","28.19268","0.00384"
"56454","338.68800","28.22425","0.00382"
"56517","339.06600","28.25576","0.00379"
"56580","339.44400","28.28721","0.00432"
"56643","339.82200","28.31866","0.00358"
"56706","340.20000","28.35022","0.00428"
"56769","340.57800","28.38173","0.00419"
"56832","340.95600","28.41318","0.00377"
"56895","341.33400","28.44475","0.00412"
"56958","341.71200","28.47620","0.00417"
"57021","342.09000","28.50771","0.00405"
"57084","342.46800","28.53922","0.00383"
"57147","342.84600","28.57073","0.00429"
"57210","343.22400","28.60224","0.00404"
"57273","343.60200","28.63369","0.00429"
"57336","343.98000","28.66520","0.00431"
"57399","344.35800","28.69677","0.00381"
"57462","344.73600","28.72815","0.00392"
"57525","345.11400","28.75972","0.00408"
"57588","345.49200","28.79123","0.00463"
"57651","345.87000","28.82268","0.00367"
"57714","346.24800","28.85413","0.00456"
"57777","346.62600","28.88576","0.00431"
"57840","347.00400","28.91721","0.00408"
"57903","347.38200","28.94872","0.00458"
"57966","347.76000","28.98022","0.00353"
"58029","348.13800","29.01173","0.00449"
"58092","348.51600","29.04318","0.00418"
"58155","348.89400","29.07470","0.00514"
"58218","349.27200","29.10626","0.00404"
"58281","349.65000","29.13771","0.00434"
"58344","350.02800","29.16922","0.00454"
"58407","350.40600","29.20073","0.00464"
"58470","350.78400","29.23224","0.00441"
"58533","351.16200","29.26363","0.00441"
"58596","351.54000","29.29526","0.00463"
"58659","351.91800","29.32671","0.00486"
"58722","352.29600","29.35816","0.00459"
"58785","352.67400","29.38966","0.00496"
"58848","353.05200","29.42123","0.00456"
"58911","353.43000","29.45274","0.00466"
"58974","353.80800","29.48419","0.00484"
"59037","354.18600","29.51576","0.00521"
"59100","354.56400","29.54727","0.00483"
"59163","354.94200","29.57860","0.00508"
"59226","355.32000","29.61023","0.00472"
"59289","355.69800","29.64174","0.00521"
"59352","356.07600","29.67313","0.00495"
"59415","356.45400","29.70470","0.00496"
"59478","356.83200","29.73626","0.00530"
"59541","357.21000","29.76771","0.00531"
"59604","357.58800","29.79917","0.00544"
"59667","357.96600","29.83073","0.00540"
"59730","358.34400","29.86224","0.00509"
"59793","358.72200","29.89369","0.00505"
"59856","359.10000","29.92514","0.00487"
"59919","359.47800","29.95671","0.00483"
"59982","359.85600","29.98822","0.00515"
"60045","360.23400","30.01967","0.00477"
"60108","360.61200","30.05124","0.00513"
"60171","360.99000","30.08269","0.00517"
"60234","361.36800","30.11419","0.00540"
"60297","361.74600","30.14576","0.00445"
"60360","362.12400","30.17727","0.00573"
"60423","362.50200","30.20866","0.00530"
"60486","362.88000","30.24023","0.00582"
"60549","363.25800","30.27168","0.00503"
"60612","363.63600","30.30319","0.00569"
"60675","364.01400","30.33470","0.00549"
"60738","364.39200","30.36621","0.00486"
"60801","364.77000","30.39778","0.00529"
"60864","365.14800","30.42923","0.00450"
"60927","365.52600","30.46067","0.00579"
"60990","365.90400","30.49224","0.00520"
"61053","366.28200","30.52369","0.00548"
"61116","366.66000","30.55520","0.00596"
"61179","367.03800","30.58671","0.00584"
"61242","367.41600","30.61822","0.00528"
"61305","367.79400","30.64973","0.00566"
"61368","368.17200","30.68130","0.00573"
"61431","368.55000","30.71269","0.00566"
"61494","368.92800","30.74414","0.00574"
"61557","369.30600","30.77571","0.00533"
"61620","369.68400","30.80728","0.00588"
"61683","370.06200","30.83873","0.00581"
"61746","370.44000","30.87017","0.00552"
"61809","370.81800","30.90174","0.00580"
"61872","371.19600","30.93319","0.00597"
"61935","371.57400","30.96470","0.00619"
"61998","371.95200","30.99627","0.00585"
"62061","372.33000","31.02778","0.00570"
"62124","372.70800","31.05917","0.00561"
"62187","373.08600","31.09074","0.00596"
"62250","373.46400","31.12218","0.00576"
"62313","373.84200","31.15364","0.00607"
"62376","374.22000","31.18515","0.00612"
"62439","374.59800","31.21671","0.00648"
"62502","374.97600","31.24822","0.00575"
"62565","375.35400","31.27967","0.00628"
"62628","375.73200","31.31118","0.00631"
"62691","376.11000","31.34275","0.00660"
"62754","376.48800","31.37420","0.00611"
"62817","376.86600","31.40577","0.00563"
"62880","377.24400","31.43721","0.00647"
"62943","377.62200","31.46873","0.00562"
"63006","378.00000","31.50023","0.00584"
"63069","378.37800","31.53174","0.00654"
"63132","378.75600","31.56319","0.00553"
"63195","379.13400","31.59470","0.00684"
"63258","379.51200","31.62627","0.00655"
"63321","379.89000","31.65766","0.00666"
"63384","380.26800","31.68923","0.00667"
"63447","380.64600","31.72074","0.00651"
"63510","381.02400","31.75219","0.00700"
"63573","381.40200","31.78370","0.00609"
"63636","381.78000","31.81515","0.00667"
"63699","382.15800","31.84677","0.00595"
"63762","382.53600","31.87823","0.00666"
"63825","382.91400","31.90961","0.00635"
"63888","383.29200","31.94118","0.00653"
"63951","383.67000","31.97275","0.00677"
"64014","384.04800","32.00414","0.00665"
"64077","384.42600","32.03571","0.00667"
"64140","384.80400","32.06722","0.00628"
"64203","385.18200","32.09873","0.00718"
"64266","385.56000","32.13018","0.00627"
"64329","385.93800","32.16175","0.00662"
"64392","386.31600","32.19326","0.00656"
"64455","386.69400","32.22470","0.00722"
"64518","387.07200","32.25615","0.00736"
"64581","387.45000","32.28772","0.00645"
"64644","387.82800","32.31923","0.00659"
"64707","388.20600","32.35068","0.00696"
"64770","388.58400","32.38225","0.00675"
"64833","388.96200","32.41370","0.00694"
"64896","389.34000","32.44515","0.00730"
"64959","389.71800","32.47672","0.00657"
"65022","390.09600","32.50823","0.00720"
"65085","390.47400","32.53968","0.00731"
"65148","390.85200","32.57124","0.00723"
"65211","391.23000","32.60270","0.00732"
"65274","391.60800","32.63420","0.00731"
"65337","391.98600","32.66571","0.00749"
"65400","392.36400","32.69728","0.00731"
"65463","392.74200","32.72873","0.00781"
"65526","393.12000","32.76012","0.00755"
"65589","393.49800","32.79169","0.00710"
"65652","393.87600","32.82326","0.00730"
"65715","394.25400","32.85464","0.00790"
"65778","394.63200","32.88622","0.00769"
"65841","395.01000","32.91772","0.00731"
"65904","395.38800","32.94923","0.00785"
"65967","395.76600","32.98068","0.00780"
"66030","396.14400","33.01225","0.00764"
"66093","396.52200","33.04370","0.00793"
"66156","396.90000","33.07521","0.00769"
"66219","397.27800","33.10672","0.00747"
"66282","397.65600","33.13823","0.00777"
"66345","398.03400","33.16968","0.00815"
"66408","398.41200","33.20119","0.00758"
"66471","398.79000","33.23270","0.00808"
"66534","399.16800","33.26421","0.00823"
"66597","399.54600","33.29565","0.00770"
"66660","399.92400","33.32722","0.00809"
"66723","400.30200","33.35873","0.00826"
"66786","400.68000","33.39018","0.00846"
"66849","401.05800","33.42175","0.00812"
"66912","401.43600","33.45320","0.00763"
"66975","401.81400","33.48471","0.00831"
"67038","402.19200","33.51622","0.00766"
"67101","402.57000","33.54773","0.00839"
"67164","402.94800","33.57924","0.00854"
"67227","403.32600","33.61069","0.00876"
"67290","403.70400","33.64220","0.00893"
"67353","404.08200","33.67370","0.00874"
"67416","404.46000","33.70515","0.00863"
"67479","404.83800","33.73672","0.00903"
"67542","405.21600","33.76823","0.00886"
"67605","405.59400","33.79968","0.00881"
"67668","405.97200","33.83119","0.00889"
"67731","406.35000","33.86276","0.00903"
"67794","406.72800","33.89427","0.00866"
"67857","407.10600","33.92566","0.00906"
"67920","407.48400","33.95723","0.00896"
"67983","407.86200","33.98874","0.00895"
"68046","408.24000","34.02024","0.00886"
"68109","408.61800","34.05164","0.00922"
"68172","408.99600","34.08320","0.00912"
"68235","409.37400","34.11477","0.00916"
"68298","409.75200","34.14616","0.00905"
"68361","410.13000","34.17773","0.00913"
"68424","410.50800","34.20924","0.00923"
"68487","410.88600","34.24069","0.00928"
"68550","411.26400","34.27226","0.00931"
"68613","411.64200","34.30376","0.00950"
"68676","412.02000","34.33516","0.00925"
"68739","412.39800","34.36672","0.00989"
"68802","412.77600","34.39823","0.00939"
"68865","413.15400","34.42968","0.00983"
"68928","413.53200","34.46119","0.00954"
"68991","413.91000","34.49276","0.00947"
"69054","414.28800","34.52421","0.00995"
"69117","414.66600","34.55566","0.00927"
"69180","415.04400","34.58723","0.00992"
"69243","415.42200","34.61874","0.01050"
"69306","415.80000","34.65019","0.00980"
"69369","416.17800","34.68170","0.01012"
"69432","416.55600","34.71326","0.01055"
"69495","416.93400","34.74466","0.01053"
"69558","417.31200","34.77616","0.01064"
"69621","417.69000","34.80773","0.01045"
"69684","418.06800","34.83924","0.01073"
"69747","418.44600","34.87069","0.01012"
"69810","418.82400","34.90220","0.01048"
"69873","419.20200","34.93371","0.01070"
"69936","419.58000","34.96522","0.01065"
"69999","419.95800","34.99667","0.01052"
"70062","420.33600","35.02823","0.01078"
"70125","420.71400","35.05975","0.01033"
"70188","421.09200","35.09119","0.01053"
"70251","421.47000","35.12270","0.01089"
"70314","421.84800","35.15421","0.01113"
"70377","422.22600","35.18566","0.01049"
"70440","422.60400","35.21723","0.01078"
"70503","422.98200","35.24874","0.01130"
"70566","423.36000","35.28019","0.01083"
"70629","423.73800","35.31170","0.01121"
"70692","424.11600","35.34321","0.01090"
"70755","424.49400","35.37472","0.01095"
"70818","424.87200","35.40622","0.01116"
"70881","425.25000","35.43773","0.01125"
"70944","425.62800","35.46925","0.01199"
"71007","426.00600","35.50069","0.01198"
"71070","426.38400","35.53214","0.01174"
"71133","426.76200","35.56371","0.01154"
"71196","427.14000","35.59522","0.01105"
"71259","427.51800","35.62661","0.01160"
"71322","427.89600","35.65824","0.01211"
"71385","428.27400","35.68975","0.01208"
"71448","428.65200","35.72114","0.01186"
"71511","429.03000","35.75277","0.01255"
"71574","429.40800","35.78421","0.01175"
"71637","429.78600","35.81566","0.01217"
"71700","430.16400","35.84717","0.01246"
"71763","430.54200","35.87874","0.01245"
"71826","430.92000","35.91019","0.01226"
"71889","431.29800","35.94164","0.01235"
"71952","431.67600","35.97327","0.01210"
"72015","432.05400","36.00472","0.01266"
"72078","432.43200","36.03611","0.01272"
"72141","432.81000","36.06773","0.01254"
"72204","433.18800","36.09925","0.01273"
"72267","433.56600","36.13070","0.01277"
"72330","433.94400","36.16220","0.01321"
"72393","434.32200","36.19371","0.01328"
"72456","434.70000","36.22516","0.01298"
"72519","435.07800","36.25667","0.01316"
"72582","435.45600","36.28824","0.01316"
"72645","435.83400","36.31975","0.01351"
"72708","436.21200","36.35120","0.01374"
"72771","436.59000","36.38271","0.01373"
"72834","436.96800","36.41422","0.01335"
"72897","437.34600","36.44572","0.01416"
"72960","437.72400","36.47723","0.01376"
"73023","438.10200","36.50874","0.01434"
"73086","438.48000","36.54020","0.01397"
"73149","438.85800","36.57164","0.01434"
"73212","439.23600","36.60327","0.01436"
"73275","439.61400","36.63472","0.01427"
"73338","439.99200","36.66617","0.01493"
"73401","440.37000","36.69774","0.01407"
"73464","440.74800","36.72919","0.01481"
"73527","441.12600","36.76070","0.01474"
"73590","441.50400","36.79221","0.01499"
"73653","441.88200","36.82372","0.01477"
"73716","442.26000","36.85522","0.01426"
"73779","442.63800","36.88667","0.01508"
"73842","443.01600","36.91818","0.01452"
"73905","443.39400","36.94975","0.01537"
"73968","443.77200","36.98120","0.01528"
"74031","444.15000","37.01265","0.01511"
"74094","444.52800","37.04428","0.01539"
"74157","444.90600","37.07573","0.01614"
"74220","445.28400","37.10712","0.01589"
"74283","445.66200","37.13874","0.01592"
"74346","446.04000","37.17026","0.01628"
"74409","446.41800","37.20164","0.01628"
"74472","446.79600","37.23322","0.01617"
"74535","447.17400","37.26472","0.01657"
"74598","447.55200","37.29623","0.01624"
"74661","447.93000","37.32768","0.01626"
"74724","448.30800","37.35925","0.01605"
"74787","448.68600","37.39076","0.01708"
"74850","449.06400","37.42215","0.01645"
"74913","449.44200","37.45372","0.01722"
"74976","449.82000","37.48523","0.01673"
"75039","450.19800","37.51662","0.01776"
"75102","450.57600","37.54818","0.01763"
"75165","450.95400","37.57976","0.01760"
"75228","451.33200","37.61121","0.01772"
"75291","451.71000","37.64272","0.01732"
"75354","452.08800","37.67422","0.01834"
"75417","452.46600","37.70573","0.01837"
"75480","452.84400","37.73718","0.01840"
"75543","453.22200","37.76869","0.01789"
"75606","453.60000","37.80026","0.01854"
"75669","453.97800","37.83171","0.01916"
"75732","454.35600","37.86328","0.01912"
"75795","454.73400","37.89473","0.01873"
"75858","455.11200","37.92617","0.01923"
"75921","455.49000","37.95768","0.01921"
"75984","455.86800","37.98925","0.02023"
"76047","456.24600","38.02070","0.01969"
"76110","456.62400","38.05215","0.01973"
"76173","457.00200","38.08372","0.01982"
"76236","457.38000","38.11517","0.01989"
"76299","457.75800","38.14668","0.02050"
"76362","458.13600","38.17819","0.02066"
"76425","458.51400","38.20969","0.02044"
"76488","458.89200","38.24121","0.02067"
"76551","459.27000","38.27272","0.02012"
"76614","459.64800","38.30423","0.02050"
"76677","460.02600","38.33573","0.02154"
"76740","460.40400","38.36712","0.02153"
"76803","460.78200","38.39869","0.02097"
"76866","461.16000","38.43026","0.02176"
"76929","461.53800","38.46171","0.02170"
"76992","461.91600","38.49322","0.02164"
"77055","462.29400","38.52473","0.02218"
"77118","462.67200","38.55624","0.02324"
"77181","463.05000","38.58768","0.02307"
"77244","463.42800","38.61926","0.02310"
"77307","463.80600","38.65076","0.02329"
"77370","464.18400","38.68222","0.02387"
"77433","464.56200","38.71367","0.02383"
"77496","464.94000","38.74523","0.02428"
"77559","465.31800","38.77674","0.02419"
"77622","465.69600","38.80813","0.02369"
"77685","466.07400","38.83976","0.02320"
"77748","466.45200","38.87121","0.02464"
"77808","466.80800","38.90086","0.02445"