File: Trajectories_together/170212_1Specimen_RawData_5.csv
"","V1","V2","V3"
"1","End date","2/12/2017",""
"2","Specimen label","9AG_80",""
"3","Maximum Load","0.51878","N"
"4","Time","Extension","Load"
"5","(s)","(mm)","(N)"
"6","0.00000","0.00000","-0.00025"
"38","0.19200","0.01315","0.00025"
"70","0.38400","0.03223","0.00130"
"102","0.57600","0.04825","0.00114"
"134","0.76800","0.06421","0.00094"
"166","0.96000","0.08024","0.00175"
"198","1.15200","0.09620","0.00235"
"230","1.34400","0.11222","0.00257"
"262","1.53600","0.12819","0.00278"
"294","1.72800","0.14415","0.00318"
"326","1.92000","0.16024","0.00297"
"358","2.11200","0.17620","0.00319"
"390","2.30400","0.19216","0.00363"
"422","2.49600","0.20825","0.00445"
"454","2.68800","0.22421","0.00370"
"486","2.88000","0.24017","0.00401"
"518","3.07200","0.25620","0.00448"
"550","3.26400","0.27222","0.00469"
"582","3.45600","0.28819","0.00479"
"614","3.64800","0.30421","0.00519"
"646","3.84000","0.32017","0.00538"
"678","4.03200","0.33614","0.00524"
"710","4.22400","0.35222","0.00492"
"742","4.41600","0.36818","0.00563"
"774","4.60800","0.38421","0.00638"
"806","4.80000","0.40023","0.00628"
"838","4.99200","0.41619","0.00614"
"870","5.18400","0.43216","0.00650"
"902","5.37600","0.44824","0.00609"
"934","5.56800","0.46415","0.00672"
"966","5.76000","0.48017","0.00674"
"998","5.95200","0.49619","0.00754"
"1030","6.14400","0.51210","0.00767"
"1062","6.33600","0.52824","0.00709"
"1094","6.52800","0.54420","0.00771"
"1126","6.72000","0.56017","0.00799"
"1158","6.91200","0.57619","0.00776"
"1190","7.10400","0.59216","0.00838"
"1222","7.29600","0.60818","0.00863"
"1254","7.48800","0.62420","0.00859"
"1286","7.68000","0.64023","0.00860"
"1318","7.87200","0.65619","0.00879"
"1350","8.06400","0.67221","0.00897"
"1382","8.25600","0.68818","0.00825"
"1414","8.44800","0.70420","0.00876"
"1446","8.64000","0.72022","0.00905"
"1478","8.83200","0.73613","0.00894"
"1510","9.02400","0.75215","0.00871"
"1542","9.21600","0.76824","0.00962"
"1574","9.40800","0.78414","0.00877"
"1606","9.60000","0.80016","0.00970"
"1638","9.79200","0.81619","0.00914"
"1670","9.98400","0.83221","0.00913"
"1702","10.17600","0.84817","0.00980"
"1734","10.36800","0.86420","0.00983"
"1766","10.56000","0.88022","0.01057"
"1798","10.75200","0.89619","0.01070"
"1830","10.94400","0.91215","0.01077"
"1862","11.13600","0.92823","0.01071"
"1894","11.32800","0.94420","0.01080"
"1926","11.52000","0.96022","0.01093"
"1958","11.71200","0.97618","0.01100"
"1990","11.90400","0.99215","0.01119"
"2022","12.09600","1.00817","0.01138"
"2054","12.28800","1.02419","0.01153"
"2086","12.48000","1.04016","0.01130"
"2118","12.67200","1.05624","0.01104"
"2150","12.86400","1.07221","0.01184"
"2182","13.05600","1.08817","0.01176"
"2214","13.24800","1.10419","0.01162"
"2246","13.44000","1.12022","0.01262"
"2278","13.63200","1.13618","0.01174"
"2310","13.82400","1.15226","0.01202"
"2342","14.01600","1.16823","0.01206"
"2374","14.20800","1.18413","0.01221"
"2406","14.40000","1.20027","0.01239"
"2438","14.59200","1.21618","0.01246"
"2470","14.78400","1.23214","0.01245"
"2502","14.97600","1.24817","0.01302"
"2534","15.16800","1.26419","0.01295"
"2566","15.36000","1.28015","0.01286"
"2598","15.55200","1.29624","0.01314"
"2630","15.74400","1.31220","0.01284"
"2662","15.93600","1.32822","0.01417"
"2694","16.12800","1.34419","0.01333"
"2726","16.32000","1.36015","0.01433"
"2758","16.51200","1.37618","0.01362"
"2790","16.70400","1.39220","0.01357"
"2822","16.89600","1.40816","0.01398"
"2854","17.08800","1.42419","0.01379"
"2886","17.28000","1.44021","0.01357"
"2918","17.47200","1.45617","0.01411"
"2950","17.66400","1.47220","0.01376"
"2982","17.85600","1.48822","0.01385"
"3014","18.04800","1.50419","0.01414"
"3046","18.24000","1.52021","0.01407"
"3078","18.43200","1.53617","0.01427"
"3110","18.62400","1.55220","0.01453"
"3142","18.81600","1.56816","0.01421"
"3174","19.00800","1.58412","0.01495"
"3206","19.20000","1.60021","0.01426"
"3238","19.39200","1.61623","0.01469"
"3270","19.58400","1.63213","0.01453"
"3302","19.77600","1.64822","0.01469"
"3334","19.96800","1.66418","0.01502"
"3366","20.16000","1.68015","0.01459"
"3398","20.35200","1.69623","0.01468"
"3430","20.54400","1.71213","0.01486"
"3462","20.73600","1.72816","0.01522"
"3494","20.92800","1.74418","0.01547"
"3526","21.12000","1.76020","0.01575"
"3558","21.31200","1.77617","0.01615"
"3590","21.50400","1.79219","0.01522"
"3622","21.69600","1.80816","0.01566"
"3654","21.88800","1.82418","0.01604"
"3686","22.08000","1.84026","0.01634"
"3718","22.27200","1.85617","0.01592"
"3750","22.46400","1.87219","0.01590"
"3782","22.65600","1.88821","0.01579"
"3814","22.84800","1.90418","0.01654"
"3846","23.04000","1.92020","0.01629"
"3878","23.23200","1.93616","0.01663"
"3910","23.42400","1.95219","0.01728"
"3942","23.61600","1.96821","0.01607"
"3974","23.80800","1.98418","0.01666"
"4006","24.00000","2.00020","0.01717"
"4038","24.19200","2.01622","0.01689"
"4070","24.38400","2.03219","0.01663"
"4102","24.57600","2.04827","0.01712"
"4134","24.76800","2.06417","0.01721"
"4166","24.96000","2.08014","0.01692"
"4198","25.15200","2.09622","0.01744"
"4230","25.34400","2.11219","0.01671"
"4262","25.53600","2.12815","0.01759"
"4294","25.72800","2.14423","0.01700"
"4326","25.92000","2.16020","0.01742"
"4358","26.11200","2.17616","0.01709"
"4390","26.30400","2.19218","0.01641"
"4422","26.49600","2.20815","0.01642"
"4454","26.68800","2.22417","0.01667"
"4486","26.88000","2.24019","0.01656"
"4518","27.07200","2.25616","0.01625"
"4550","27.26400","2.27218","0.01687"
"4582","27.45600","2.28821","0.01662"
"4614","27.64800","2.30423","0.01691"
"4646","27.84000","2.32019","0.01683"
"4678","28.03200","2.33622","0.01701"
"4710","28.22400","2.35212","0.01689"
"4742","28.41600","2.36820","0.01719"
"4774","28.60800","2.38423","0.01666"
"4806","28.80000","2.40019","0.01735"
"4838","28.99200","2.41621","0.01689"
"4870","29.18400","2.43218","0.01731"
"4902","29.37600","2.44814","0.01769"
"4934","29.56800","2.46423","0.01741"
"4966","29.76000","2.48013","0.01704"
"4998","29.95200","2.49621","0.01805"
"5030","30.14400","2.51224","0.01763"
"5062","30.33600","2.52820","0.01776"
"5094","30.52800","2.54416","0.01773"
"5126","30.72000","2.56019","0.01805"
"5158","30.91200","2.57621","0.01814"
"5190","31.10400","2.59218","0.01806"
"5222","31.29600","2.60820","0.01798"
"5254","31.48800","2.62410","0.01707"
"5286","31.68000","2.64019","0.01726"
"5318","31.87200","2.65621","0.01656"
"5350","32.06400","2.67223","0.01679"
"5382","32.25600","2.68820","0.01769"
"5414","32.44800","2.70416","0.01840"
"5446","32.64000","2.72018","0.01758"
"5478","32.83200","2.73621","0.01813"
"5510","33.02400","2.75217","0.01782"
"5542","33.21600","2.76826","0.01787"
"5574","33.40800","2.78416","0.01784"
"5606","33.60000","2.80018","0.01812"
"5638","33.79200","2.81621","0.01861"
"5670","33.98400","2.83217","0.01915"
"5702","34.17600","2.84819","0.01837"
"5734","34.36800","2.86422","0.01776"
"5766","34.56000","2.88012","0.01852"
"5798","34.75200","2.89620","0.01830"
"5830","34.94400","2.91223","0.01839"
"5862","35.13600","2.92819","0.01858"
"5894","35.32800","2.94422","0.01866"
"5926","35.52000","2.96018","0.01837"
"5958","35.71200","2.97614","0.01836"
"5990","35.90400","2.99223","0.01861"
"6022","36.09600","3.00819","0.01850"
"6054","36.28800","3.02410","0.01854"
"6086","36.48000","3.04024","0.01887"
"6118","36.67200","3.05620","0.01888"
"6150","36.86400","3.07217","0.01904"
"6182","37.05600","3.08825","0.01922"
"6214","37.24800","3.10415","0.01885"
"6246","37.44000","3.12018","0.01929"
"6278","37.63200","3.13626","0.02009"
"6310","37.82400","3.15210","0.01921"
"6342","38.01600","3.16819","0.01957"
"6374","38.20800","3.18427","0.01942"
"6406","38.40000","3.20017","0.02032"
"6438","38.59200","3.21620","0.02015"
"6470","38.78400","3.23222","0.01954"
"6502","38.97600","3.24813","0.01950"
"6534","39.16800","3.26421","0.02031"
"6566","39.36000","3.28017","0.02009"
"6598","39.55200","3.29620","0.02001"
"6630","39.74400","3.31216","0.02016"
"6662","39.93600","3.32818","0.02077"
"6694","40.12800","3.34421","0.02068"
"6726","40.32000","3.36023","0.02030"
"6758","40.51200","3.37620","0.02084"
"6790","40.70400","3.39222","0.02001"
"6822","40.89600","3.40818","0.02061"
"6854","41.08800","3.42421","0.02026"
"6886","41.28000","3.44023","0.01944"
"6918","41.47200","3.45619","0.02057"
"6950","41.66400","3.47222","0.02063"
"6982","41.85600","3.48818","0.02081"
"7014","42.04800","3.50420","0.02149"
"7046","42.24000","3.52023","0.02116"
"7078","42.43200","3.53619","0.02041"
"7110","42.62400","3.55216","0.02166"
"7142","42.81600","3.56818","0.02148"
"7174","43.00800","3.58420","0.02171"
"7206","43.20000","3.60011","0.02142"
"7238","43.39200","3.61619","0.02143"
"7270","43.58400","3.63221","0.02142"
"7302","43.77600","3.64812","0.02231"
"7334","43.96800","3.66426","0.02197"
"7366","44.16000","3.68017","0.02199"
"7398","44.35200","3.69613","0.02229"
"7430","44.54400","3.71221","0.02113"
"7462","44.73600","3.72824","0.02191"
"7494","44.92800","3.74420","0.02199"
"7526","45.12000","3.76022","0.02181"
"7558","45.31200","3.77619","0.02232"
"7590","45.50400","3.79221","0.02264"
"7622","45.69600","3.80823","0.02195"
"7654","45.88800","3.82420","0.02234"
"7686","46.08000","3.84016","0.02210"
"7718","46.27200","3.85625","0.02291"
"7750","46.46400","3.87215","0.02312"
"7782","46.65600","3.88823","0.02177"
"7814","46.84800","3.90420","0.02266"
"7846","47.04000","3.92016","0.02299"
"7878","47.23200","3.93618","0.02243"
"7910","47.42400","3.95221","0.02246"
"7942","47.61600","3.96817","0.02275"
"7974","47.80800","3.98425","0.02266"
"8006","48.00000","4.00022","0.02298"
"8038","48.19200","4.01618","0.02352"
"8070","48.38400","4.03221","0.02282"
"8102","48.57600","4.04817","0.02302"
"8134","48.76800","4.06419","0.02355"
"8166","48.96000","4.08022","0.02332"
"8198","49.15200","4.09612","0.02358"
"8230","49.34400","4.11220","0.02337"
"8262","49.53600","4.12823","0.02333"
"8294","49.72800","4.14413","0.02332"
"8326","49.92000","4.16016","0.02378"
"8358","50.11200","4.17624","0.02419"
"8390","50.30400","4.19220","0.02361"
"8422","50.49600","4.20817","0.02446"
"8454","50.68800","4.22419","0.02419"
"8486","50.88000","4.24015","0.02393"
"8518","51.07200","4.25624","0.02370"
"8550","51.26400","4.27220","0.02428"
"8582","51.45600","4.28823","0.02483"
"8614","51.64800","4.30419","0.02447"
"8646","51.84000","4.32015","0.02470"
"8678","52.03200","4.33624","0.02458"
"8710","52.22400","4.35220","0.02499"
"8742","52.41600","4.36810","0.02427"
"8774","52.60800","4.38425","0.02519"
"8806","52.80000","4.40021","0.02479"
"8838","52.99200","4.41617","0.02482"
"8870","53.18400","4.43220","0.02531"
"8902","53.37600","4.44816","0.02513"
"8934","53.56800","4.46425","0.02501"
"8966","53.76000","4.48021","0.02475"
"8998","53.95200","4.49617","0.02480"
"9030","54.14400","4.51226","0.02477"
"9062","54.33600","4.52822","0.02553"
"9094","54.52800","4.54418","0.02564"
"9126","54.72000","4.56021","0.02447"
"9158","54.91200","4.57617","0.02504"
"9190","55.10400","4.59213","0.02551"
"9222","55.29600","4.60822","0.02489"
"9254","55.48800","4.62418","0.02486"
"9286","55.68000","4.64015","0.02591"
"9318","55.87200","4.65617","0.02570"
"9350","56.06400","4.67219","0.02535"
"9382","56.25600","4.68822","0.02660"
"9414","56.44800","4.70424","0.02553"
"9446","56.64000","4.72020","0.02578"
"9478","56.83200","4.73617","0.02596"
"9510","57.02400","4.75225","0.02598"
"9542","57.21600","4.76810","0.02606"
"9574","57.40800","4.78418","0.02638"
"9606","57.60000","4.80020","0.02580"
"9638","57.79200","4.81617","0.02566"
"9670","57.98400","4.83225","0.02594"
"9702","58.17600","4.84821","0.02574"
"9734","58.36800","4.86412","0.02565"
"9766","58.56000","4.88020","0.02579"
"9798","58.75200","4.89622","0.02576"
"9830","58.94400","4.91219","0.02528"
"9862","59.13600","4.92821","0.02650"
"9894","59.32800","4.94418","0.02602"
"9926","59.52000","4.96020","0.02610"
"9958","59.71200","4.97622","0.02579"
"9990","59.90400","4.99213","0.02638"
"10022","60.09600","5.00821","0.02715"
"10054","60.28800","5.02417","0.02670"
"10086","60.48000","5.04014","0.02674"
"10118","60.67200","5.05622","0.02655"
"10150","60.86400","5.07219","0.02646"
"10182","61.05600","5.08821","0.02682"
"10214","61.24800","5.10417","0.02703"
"10246","61.44000","5.12020","0.02654"
"10278","61.63200","5.13622","0.02730"
"10310","61.82400","5.15218","0.02676"
"10342","62.01600","5.16815","0.02750"
"10374","62.20800","5.18423","0.02729"
"10406","62.40000","5.20019","0.02720"
"10438","62.59200","5.21616","0.02669"
"10470","62.78400","5.23224","0.02735"
"10502","62.97600","5.24821","0.02728"
"10534","63.16800","5.26417","0.02704"
"10566","63.36000","5.28019","0.02705"
"10598","63.55200","5.29622","0.02690"
"10630","63.74400","5.31212","0.02765"
"10662","63.93600","5.32820","0.02824"
"10694","64.12800","5.34417","0.02759"
"10726","64.32000","5.36019","0.02742"
"10758","64.51200","5.37621","0.02799"
"10790","64.70400","5.39212","0.02734"
"10822","64.89600","5.40820","0.02765"
"10854","65.08800","5.42423","0.02783"
"10886","65.28000","5.44013","0.02815"
"10918","65.47200","5.45621","0.02857"
"10950","65.66400","5.47218","0.02805"
"10982","65.85600","5.48808","0.02852"
"11014","66.04800","5.50428","0.02857"
"11046","66.24000","5.52019","0.02825"
"11078","66.43200","5.53615","0.02843"
"11110","66.62400","5.55224","0.02868"
"11142","66.81600","5.56814","0.02863"
"11174","67.00800","5.58416","0.02847"
"11206","67.20000","5.60025","0.02871"
"11238","67.39200","5.61621","0.02884"
"11270","67.58400","5.63223","0.02834"
"11302","67.77600","5.64820","0.02879"
"11334","67.96800","5.66416","0.02840"
"11366","68.16000","5.68019","0.02904"
"11398","68.35200","5.69621","0.02932"
"11430","68.54400","5.71211","0.02886"
"11462","68.73600","5.72820","0.03006"
"11494","68.92800","5.74422","0.02971"
"11526","69.12000","5.76018","0.02946"
"11558","69.31200","5.77621","0.02948"
"11590","69.50400","5.79217","0.02927"
"11622","69.69600","5.80819","0.02946"
"11654","69.88800","5.82416","0.02981"
"11686","70.08000","5.84018","0.02994"
"11718","70.27200","5.85621","0.02990"
"11750","70.46400","5.87223","0.02982"
"11782","70.65600","5.88819","0.02991"
"11814","70.84800","5.90422","0.02990"
"11846","71.04000","5.92018","0.03011"
"11878","71.23200","5.93614","0.02984"
"11910","71.42400","5.95229","0.02979"
"11942","71.61600","5.96813","0.02973"
"11974","71.80800","5.98416","0.02950"
"12006","72.00000","6.00018","0.03023"
"12038","72.19200","6.01620","0.02977"
"12070","72.38400","6.03217","0.02974"
"12102","72.57600","6.04819","0.03010"
"12134","72.76800","6.06415","0.03039"
"12166","72.96000","6.08018","0.03008"
"12198","73.15200","6.09620","0.03048"
"12230","73.34400","6.11216","0.03014"
"12262","73.53600","6.12819","0.03097"
"12294","73.72800","6.14421","0.03003"
"12326","73.92000","6.16017","0.02973"
"12358","74.11200","6.17620","0.03046"
"12390","74.30400","6.19216","0.03007"
"12422","74.49600","6.20819","0.03094"
"12454","74.68800","6.22421","0.03023"
"12486","74.88000","6.24017","0.02989"
"12518","75.07200","6.25620","0.03086"
"12550","75.26400","6.27216","0.03084"
"12582","75.45600","6.28819","0.03127"
"12614","75.64800","6.30415","0.03096"
"12646","75.84000","6.32017","0.03090"
"12678","76.03200","6.33614","0.03118"
"12710","76.22400","6.35222","0.03100"
"12742","76.41600","6.36818","0.03165"
"12774","76.60800","6.38415","0.03091"
"12806","76.80000","6.40017","0.03193"
"12838","76.99200","6.41619","0.03169"
"12870","77.18400","6.43216","0.03182"
"12902","77.37600","6.44818","0.03151"
"12934","77.56800","6.46421","0.03170"
"12966","77.76000","6.48017","0.03204"
"12998","77.95200","6.49625","0.03194"
"13030","78.14400","6.51222","0.03201"
"13062","78.33600","6.52818","0.03242"
"13094","78.52800","6.54420","0.03287"
"13126","78.72000","6.56011","0.03232"
"13158","78.91200","6.57619","0.03257"
"13190","79.10400","6.59222","0.03263"
"13222","79.29600","6.60812","0.03262"
"13254","79.48800","6.62426","0.03309"
"13286","79.68000","6.64023","0.03327"
"13318","79.87200","6.65607","0.03334"
"13350","80.06400","6.67221","0.03331"
"13382","80.25600","6.68824","0.03280"
"13414","80.44800","6.70414","0.03295"
"13446","80.64000","6.72022","0.03386"
"13478","80.83200","6.73613","0.03393"
"13510","81.02400","6.75221","0.03397"
"13542","81.21600","6.76824","0.03331"
"13574","81.40800","6.78420","0.03352"
"13606","81.60000","6.80016","0.03368"
"13638","81.79200","6.81619","0.03421"
"13670","81.98400","6.83221","0.03421"
"13702","82.17600","6.84823","0.03368"
"13734","82.36800","6.86420","0.03414"
"13766","82.56000","6.88016","0.03442"
"13798","82.75200","6.89618","0.03471"
"13830","82.94400","6.91215","0.03459"
"13862","83.13600","6.92817","0.03467"
"13894","83.32800","6.94420","0.03499"
"13926","83.52000","6.96016","0.03496"
"13958","83.71200","6.97618","0.03572"
"13990","83.90400","6.99221","0.03500"
"14022","84.09600","7.00817","0.03510"
"14054","84.28800","7.02419","0.03533"
"14086","84.48000","7.04028","0.03497"
"14118","84.67200","7.05612","0.03575"
"14150","84.86400","7.07221","0.03605"
"14182","85.05600","7.08817","0.03554"
"14214","85.24800","7.10413","0.03593"
"14246","85.44000","7.12022","0.03574"
"14278","85.63200","7.13612","0.03628"
"14310","85.82400","7.15214","0.03544"
"14342","86.01600","7.16823","0.03545"
"14374","86.20800","7.18413","0.03618"
"14406","86.40000","7.20021","0.03644"
"14438","86.59200","7.21624","0.03671"
"14470","86.78400","7.23214","0.03701"
"14502","86.97600","7.24823","0.03673"
"14534","87.16800","7.26419","0.03704"
"14566","87.36000","7.28009","0.03702"
"14598","87.55200","7.29624","0.03680"
"14630","87.74400","7.31226","0.03648"
"14662","87.93600","7.32810","0.03648"
"14694","88.12800","7.34425","0.03699"
"14726","88.32000","7.36021","0.03727"
"14758","88.51200","7.37617","0.03759"
"14790","88.70400","7.39220","0.03749"
"14822","88.89600","7.40822","0.03741"
"14854","89.08800","7.42419","0.03779"
"14886","89.28000","7.44021","0.03802"
"14918","89.47200","7.45617","0.03809"
"14950","89.66400","7.47214","0.03838"
"14982","89.85600","7.48822","0.03803"
"15014","90.04800","7.50412","0.03872"
"15046","90.24000","7.52021","0.03919"
"15078","90.43200","7.53629","0.03903"
"15110","90.62400","7.55220","0.03955"
"15142","90.81600","7.56816","0.03957"
"15174","91.00800","7.58418","0.03999"
"15206","91.20000","7.60015","0.04037"
"15238","91.39200","7.61617","0.04061"
"15270","91.58400","7.63219","0.04095"
"15302","91.77600","7.64816","0.04075"
"15334","91.96800","7.66424","0.04048"
"15366","92.16000","7.68015","0.04129"
"15398","92.35200","7.69623","0.04100"
"15430","92.54400","7.71219","0.04145"
"15462","92.73600","7.72816","0.04174"
"15494","92.92800","7.74424","0.04237"
"15526","93.12000","7.76020","0.04291"
"15558","93.31200","7.77617","0.04255"
"15590","93.50400","7.79219","0.04269"
"15622","93.69600","7.80816","0.04350"
"15654","93.88800","7.82424","0.04356"
"15686","94.08000","7.84020","0.04359"
"15718","94.27200","7.85616","0.04425"
"15750","94.46400","7.87225","0.04425"
"15782","94.65600","7.88821","0.04450"
"15814","94.84800","7.90412","0.04419"
"15846","95.04000","7.92020","0.04475"
"15878","95.23200","7.93616","0.04486"
"15910","95.42400","7.95213","0.04522"
"15942","95.61600","7.96827","0.04524"
"15974","95.80800","7.98417","0.04615"
"16006","96.00000","8.00014","0.04580"
"16038","96.19200","8.01622","0.04598"
"16070","96.38400","8.03219","0.04562"
"16102","96.57600","8.04815","0.04576"
"16134","96.76800","8.06423","0.04599"
"16166","96.96000","8.08020","0.04586"
"16198","97.15200","8.09616","0.04669"
"16230","97.34400","8.11224","0.04684"
"16262","97.53600","8.12821","0.04693"
"16294","97.72800","8.14417","0.04718"
"16326","97.92000","8.16020","0.04727"
"16358","98.11200","8.17616","0.04841"
"16390","98.30400","8.19218","0.04792"
"16422","98.49600","8.20821","0.04801"
"16454","98.68800","8.22411","0.04871"
"16486","98.88000","8.24025","0.04899"
"16518","99.07200","8.25622","0.04900"
"16550","99.26400","8.27218","0.04822"
"16582","99.45600","8.28820","0.04864"
"16614","99.64800","8.30417","0.04898"
"16646","99.84000","8.32019","0.04943"
"16678","100.03200","8.33622","0.04904"
"16710","100.22400","8.35212","0.04963"
"16742","100.41600","8.36820","0.04981"
"16774","100.60800","8.38423","0.04960"
"16806","100.80000","8.40019","0.05043"
"16838","100.99200","8.41621","0.05019"
"16870","101.18400","8.43218","0.05081"
"16902","101.37600","8.44814","0.05046"
"16934","101.56800","8.46422","0.05112"
"16966","101.76000","8.48019","0.05158"
"16998","101.95200","8.49615","0.05176"
"17030","102.14400","8.51218","0.05239"
"17062","102.33600","8.52814","0.05221"
"17094","102.52800","8.54416","0.05236"
"17126","102.72000","8.56019","0.05295"
"17158","102.91200","8.57621","0.05285"
"17190","103.10400","8.59217","0.05324"
"17222","103.29600","8.60820","0.05299"
"17254","103.48800","8.62416","0.05358"
"17286","103.68000","8.64025","0.05351"
"17318","103.87200","8.65627","0.05403"
"17350","104.06400","8.67211","0.05360"
"17382","104.25600","8.68826","0.05431"
"17414","104.44800","8.70416","0.05408"
"17446","104.64000","8.72018","0.05442"
"17478","104.83200","8.73621","0.05452"
"17510","105.02400","8.75223","0.05497"
"17542","105.21600","8.76819","0.05550"
"17574","105.40800","8.78422","0.05536"
"17606","105.60000","8.80018","0.05529"
"17638","105.79200","8.81621","0.05546"
"17670","105.98400","8.83223","0.05557"
"17702","106.17600","8.84813","0.05559"
"17734","106.36800","8.86422","0.05545"
"17766","106.56000","8.88018","0.05610"
"17798","106.75200","8.89608","0.05591"
"17830","106.94400","8.91223","0.05614"
"17862","107.13600","8.92819","0.05616"
"17894","107.32800","8.94416","0.05662"
"17926","107.52000","8.96024","0.05679"
"17958","107.71200","8.97620","0.05665"
"17990","107.90400","8.99223","0.05694"
"18022","108.09600","9.00819","0.05758"
"18054","108.28800","9.02415","0.05730"
"18086","108.48000","9.04024","0.05775"
"18118","108.67200","9.05626","0.05782"
"18150","108.86400","9.07211","0.05794"
"18182","109.05600","9.08819","0.05797"
"18214","109.24800","9.10421","0.05829"
"18246","109.44000","9.12018","0.05843"
"18278","109.63200","9.13620","0.05863"
"18310","109.82400","9.15222","0.05871"
"18342","110.01600","9.16813","0.05841"
"18374","110.20800","9.18421","0.05873"
"18406","110.40000","9.20023","0.05895"
"18438","110.59200","9.21620","0.05892"
"18470","110.78400","9.23216","0.05876"
"18502","110.97600","9.24819","0.05892"
"18534","111.16800","9.26415","0.05900"
"18566","111.36000","9.28017","0.05932"
"18598","111.55200","9.29614","0.05928"
"18630","111.74400","9.31222","0.05953"
"18662","111.93600","9.32824","0.05998"
"18694","112.12800","9.34415","0.05967"
"18726","112.32000","9.36023","0.06005"
"18758","112.51200","9.37619","0.06000"
"18790","112.70400","9.39222","0.06037"
"18822","112.89600","9.40824","0.05989"
"18854","113.08800","9.42421","0.06057"
"18886","113.28000","9.44017","0.06091"
"18918","113.47200","9.45625","0.06100"
"18950","113.66400","9.47216","0.06090"
"18982","113.85600","9.48818","0.06103"
"19014","114.04800","9.50420","0.06119"
"19046","114.24000","9.52017","0.06135"
"19078","114.43200","9.53625","0.06153"
"19110","114.62400","9.55222","0.06154"
"19142","114.81600","9.56818","0.06161"
"19174","115.00800","9.58420","0.06186"
"19206","115.20000","9.60017","0.06224"
"19238","115.39200","9.61613","0.06224"
"19270","115.58400","9.63221","0.06257"
"19302","115.77600","9.64818","0.06253"
"19334","115.96800","9.66420","0.06242"
"19366","116.16000","9.68022","0.06285"
"19398","116.35200","9.69619","0.06296"
"19430","116.54400","9.71221","0.06283"
"19462","116.73600","9.72824","0.06340"
"19494","116.92800","9.74420","0.06365"
"19526","117.12000","9.76022","0.06395"
"19558","117.31200","9.77619","0.06404"
"19590","117.50400","9.79209","0.06427"
"19622","117.69600","9.80823","0.06463"
"19654","117.88800","9.82426","0.06480"
"19686","118.08000","9.84010","0.06527"
"19718","118.27200","9.85624","0.06557"
"19750","118.46400","9.87221","0.06563"
"19782","118.65600","9.88817","0.06558"
"19814","118.84800","9.90420","0.06627"
"19846","119.04000","9.92016","0.06655"
"19878","119.23200","9.93618","0.06711"
"19910","119.42400","9.95221","0.06742"
"19942","119.61600","9.96811","0.06781"
"19974","119.80800","9.98419","0.06861"
"20006","120.00000","10.00022","0.06833"
"20038","120.19200","10.01618","0.06908"
"20070","120.38400","10.03221","0.06926"
"20102","120.57600","10.04823","0.06982"
"20134","120.76800","10.06419","0.07028"
"20166","120.96000","10.08022","0.07053"
"20198","121.15200","10.09618","0.07146"
"20230","121.34400","10.11220","0.07134"
"20262","121.53600","10.12823","0.07164"
"20294","121.72800","10.14419","0.07260"
"20326","121.92000","10.16015","0.07330"
"20358","122.11200","10.17618","0.07339"
"20390","122.30400","10.19220","0.07457"
"20422","122.49600","10.20823","0.07462"
"20454","122.68800","10.22425","0.07513"
"20486","122.88000","10.24015","0.07595"
"20518","123.07200","10.25624","0.07653"
"20550","123.26400","10.27220","0.07612"
"20582","123.45600","10.28816","0.07455"
"20614","123.64800","10.30419","0.07428"
"20646","123.84000","10.32015","0.07418"
"20678","124.03200","10.33624","0.07364"
"20710","124.22400","10.35220","0.07412"
"20742","124.41600","10.36822","0.07046"
"20774","124.60800","10.38419","0.07108"
"20806","124.80000","10.40027","0.07189"
"20838","124.99200","10.41617","0.07291"
"20870","125.18400","10.43220","0.07388"
"20902","125.37600","10.44822","0.07460"
"20934","125.56800","10.46413","0.07541"
"20966","125.76000","10.48027","0.07587"
"20998","125.95200","10.49623","0.07643"
"21030","126.14400","10.51214","0.07747"
"21062","126.33600","10.52822","0.07798"
"21094","126.52800","10.54418","0.07793"
"21126","126.72000","10.56015","0.07845"
"21158","126.91200","10.57623","0.07894"
"21190","127.10400","10.59219","0.07975"
"21222","127.29600","10.60822","0.08026"
"21254","127.48800","10.62424","0.08057"
"21286","127.68000","10.64015","0.08206"
"21318","127.87200","10.65623","0.08213"
"21350","128.06400","10.67219","0.08324"
"21382","128.25600","10.68816","0.08375"
"21414","128.44800","10.70418","0.08504"
"21446","128.64000","10.72020","0.08590"
"21478","128.83200","10.73617","0.08612"
"21510","129.02400","10.75219","0.08683"
"21542","129.21600","10.76821","0.08746"
"21574","129.40800","10.78418","0.08775"
"21606","129.60000","10.80020","0.08857"
"21638","129.79200","10.81617","0.08936"
"21670","129.98400","10.83219","0.08931"
"21702","130.17600","10.84821","0.09004"
"21734","130.36800","10.86418","0.08789"
"21766","130.56000","10.88020","0.08859"
"21798","130.75200","10.89622","0.08883"
"21830","130.94400","10.91213","0.08944"
"21862","131.13600","10.92827","0.08985"
"21894","131.32800","10.94423","0.09145"
"21926","131.52000","10.96008","0.09103"
"21958","131.71200","10.97622","0.09234"
"21990","131.90400","10.99219","0.09255"
"22022","132.09600","11.00815","0.09384"
"22054","132.28800","11.02423","0.09381"
"22086","132.48000","11.04014","0.09462"
"22118","132.67200","11.05616","0.09444"
"22150","132.86400","11.07224","0.09582"
"22182","133.05600","11.08815","0.09583"
"22214","133.24800","11.10423","0.09668"
"22246","133.44000","11.12020","0.09729"
"22278","133.63200","11.13616","0.09839"
"22310","133.82400","11.15218","0.09863"
"22342","134.01600","11.16821","0.09947"
"22374","134.20800","11.18417","0.09945"
"22406","134.40000","11.20019","0.10040"
"22438","134.59200","11.21616","0.10093"
"22470","134.78400","11.23218","0.10129"
"22502","134.97600","11.24821","0.10270"
"22534","135.16800","11.26417","0.10224"
"22566","135.36000","11.28019","0.10335"
"22598","135.55200","11.29622","0.10376"
"22630","135.74400","11.31218","0.10400"
"22662","135.93600","11.32820","0.10459"
"22694","136.12800","11.34423","0.10292"
"22726","136.32000","11.36019","0.10193"
"22758","136.51200","11.37621","0.10302"
"22790","136.70400","11.39218","0.10297"
"22822","136.89600","11.40814","0.10356"
"22854","137.08800","11.42428","0.10404"
"22886","137.28000","11.44019","0.10466"
"22918","137.47200","11.45615","0.10495"
"22950","137.66400","11.47224","0.10531"
"22982","137.85600","11.48820","0.10563"
"23014","138.04800","11.50422","0.10579"
"23046","138.24000","11.52019","0.10640"
"23078","138.43200","11.53615","0.10619"
"23110","138.62400","11.55223","0.10637"
"23142","138.81600","11.56820","0.10698"
"23174","139.00800","11.58410","0.10778"
"23206","139.20000","11.60019","0.10779"
"23238","139.39200","11.61627","0.10820"
"23270","139.58400","11.63211","0.10836"
"23302","139.77600","11.64826","0.10872"
"23334","139.96800","11.66416","0.10867"
"23366","140.16000","11.68013","0.10906"
"23398","140.35200","11.69621","0.10947"
"23430","140.54400","11.71217","0.10863"
"23462","140.73600","11.72814","0.10924"
"23494","140.92800","11.74422","0.10904"
"23526","141.12000","11.76012","0.10910"
"23558","141.31200","11.77621","0.10931"
"23590","141.50400","11.79223","0.10986"
"23622","141.69600","11.80814","0.11011"
"23654","141.88800","11.82422","0.11055"
"23686","142.08000","11.84024","0.11059"
"23718","142.27200","11.85614","0.11125"
"23750","142.46400","11.87217","0.11160"
"23782","142.65600","11.88825","0.11194"
"23814","142.84800","11.90422","0.11183"
"23846","143.04000","11.92018","0.11210"
"23878","143.23200","11.93620","0.11297"
"23910","143.42400","11.95223","0.11287"
"23942","143.61600","11.96819","0.11378"
"23974","143.80800","11.98421","0.11415"
"24006","144.00000","12.00018","0.11459"
"24038","144.19200","12.01614","0.11520"
"24070","144.38400","12.03217","0.11588"
"24102","144.57600","12.04819","0.11577"
"24134","144.76800","12.06421","0.11605"
"24166","144.96000","12.08018","0.11715"
"24198","145.15200","12.09620","0.11789"
"24230","145.34400","12.11216","0.11882"
"24262","145.53600","12.12819","0.11983"
"24294","145.72800","12.14421","0.12088"
"24326","145.92000","12.16018","0.12148"
"24358","146.11200","12.17620","0.12329"
"24390","146.30400","12.19222","0.12388"
"24422","146.49600","12.20807","0.12470"
"24454","146.68800","12.22421","0.12491"
"24486","146.88000","12.24023","0.12287"
"24518","147.07200","12.25614","0.12237"
"24550","147.26400","12.27228","0.12369"
"24582","147.45600","12.28819","0.12438"
"24614","147.64800","12.30409","0.12553"
"24646","147.84000","12.32023","0.12630"
"24678","148.03200","12.33619","0.12682"
"24710","148.22400","12.35216","0.12780"
"24742","148.41600","12.36824","0.12903"
"24774","148.60800","12.38421","0.12992"
"24806","148.80000","12.40017","0.13115"
"24838","148.99200","12.41619","0.13202"
"24870","149.18400","12.43216","0.13254"
"24902","149.37600","12.44818","0.13279"
"24934","149.56800","12.46420","0.13379"
"24966","149.76000","12.48017","0.13439"
"24998","149.95200","12.49619","0.13554"
"25030","150.14400","12.51228","0.13579"
"25062","150.33600","12.52818","0.13684"
"25094","150.52800","12.54420","0.13755"
"25126","150.72000","12.56023","0.13854"
"25158","150.91200","12.57619","0.13817"
"25190","151.10400","12.59215","0.13961"
"25222","151.29600","12.60818","0.13955"
"25254","151.48800","12.62420","0.14016"
"25286","151.68000","12.64017","0.14077"
"25318","151.87200","12.65619","0.13944"
"25350","152.06400","12.67221","0.13979"
"25382","152.25600","12.68818","0.14062"
"25414","152.44800","12.70420","0.14126"
"25446","152.64000","12.72022","0.14173"
"25478","152.83200","12.73619","0.14170"
"25510","153.02400","12.75215","0.14242"
"25542","153.21600","12.76824","0.14292"
"25574","153.40800","12.78420","0.14333"
"25606","153.60000","12.80022","0.14408"
"25638","153.79200","12.81619","0.14448"
"25670","153.98400","12.83215","0.14462"
"25702","154.17600","12.84817","0.14469"
"25734","154.36800","12.86420","0.14518"
"25766","154.56000","12.88016","0.14627"
"25798","154.75200","12.89624","0.14645"
"25830","154.94400","12.91221","0.14611"
"25862","155.13600","12.92817","0.14512"
"25894","155.32800","12.94425","0.14512"
"25926","155.52000","12.96022","0.14526"
"25958","155.71200","12.97612","0.14572"
"25990","155.90400","12.99227","0.14681"
"26022","156.09600","13.00817","0.14714"
"26054","156.28800","13.02413","0.14715"
"26086","156.48000","13.04022","0.14785"
"26118","156.67200","13.05618","0.14820"
"26150","156.86400","13.07215","0.14872"
"26182","157.05600","13.08817","0.14902"
"26214","157.24800","13.10419","0.14929"
"26246","157.44000","13.12022","0.15007"
"26278","157.63200","13.13624","0.15013"
"26310","157.82400","13.15214","0.15072"
"26342","158.01600","13.16823","0.15082"
"26374","158.20800","13.18419","0.15134"
"26406","158.40000","13.20015","0.15063"
"26438","158.59200","13.21624","0.15064"
"26470","158.78400","13.23220","0.15088"
"26502","158.97600","13.24811","0.15150"
"26534","159.16800","13.26419","0.15170"
"26566","159.36000","13.28015","0.15212"
"26598","159.55200","13.29618","0.15248"
"26630","159.74400","13.31226","0.15302"
"26662","159.93600","13.32816","0.15342"
"26694","160.12800","13.34419","0.15372"
"26726","160.32000","13.36021","0.15425"
"26758","160.51200","13.37611","0.15453"
"26790","160.70400","13.39220","0.15479"
"26822","160.89600","13.40822","0.15532"
"26854","161.08800","13.42413","0.15573"
"26886","161.28000","13.44021","0.15641"
"26918","161.47200","13.45623","0.15676"
"26950","161.66400","13.47220","0.15710"
"26982","161.85600","13.48816","0.15744"
"27014","162.04800","13.50418","0.15757"
"27046","162.24000","13.52015","0.15820"
"27078","162.43200","13.53617","0.15866"
"27110","162.62400","13.55220","0.15926"
"27142","162.81600","13.56822","0.15931"
"27174","163.00800","13.58418","0.16006"
"27206","163.20000","13.60021","0.16082"
"27238","163.39200","13.61623","0.16117"
"27270","163.58400","13.63219","0.16157"
"27302","163.77600","13.64816","0.16279"
"27334","163.96800","13.66424","0.15982"
"27366","164.16000","13.68020","0.16029"
"27398","164.35200","13.69617","0.16067"
"27430","164.54400","13.71225","0.16141"
"27462","164.73600","13.72822","0.16186"
"27494","164.92800","13.74418","0.16265"
"27526","165.12000","13.76020","0.16336"
"27558","165.31200","13.77617","0.16438"
"27590","165.50400","13.79225","0.16454"
"27622","165.69600","13.80821","0.16588"
"27654","165.88800","13.82418","0.16609"
"27686","166.08000","13.84020","0.16718"
"27718","166.27200","13.85623","0.16834"
"27750","166.46400","13.87213","0.16939"
"27782","166.65600","13.88821","0.17036"
"27814","166.84800","13.90418","0.17132"
"27846","167.04000","13.92014","0.17228"
"27878","167.23200","13.93622","0.17350"
"27910","167.42400","13.95219","0.17525"
"27942","167.61600","13.96815","0.17647"
"27974","167.80800","13.98423","0.17805"
"28006","168.00000","14.00020","0.17866"
"28038","168.19200","14.01616","0.18028"
"28070","168.38400","14.03219","0.18138"
"28102","168.57600","14.04815","0.18250"
"28134","168.76800","14.06417","0.18301"
"28166","168.96000","14.08026","0.18559"
"28198","169.15200","14.09616","0.18682"
"28230","169.34400","14.11224","0.18809"
"28262","169.53600","14.12821","0.19049"
"28294","169.72800","14.14417","0.19146"
"28326","169.92000","14.16020","0.19273"
"28358","170.11200","14.17622","0.19500"
"28390","170.30400","14.19218","0.19667"
"28422","170.49600","14.20821","0.19830"
"28454","170.68800","14.22417","0.20015"
"28486","170.88000","14.24013","0.20009"
"28518","171.07200","14.25622","0.20283"
"28550","171.26400","14.27218","0.20419"
"28582","171.45600","14.28820","0.20547"
"28614","171.64800","14.30423","0.20642"
"28646","171.84000","14.32019","0.20819"
"28678","172.03200","14.33616","0.20913"
"28710","172.22400","14.35218","0.21016"
"28742","172.41600","14.36814","0.21051"
"28774","172.60800","14.38423","0.21151"
"28806","172.80000","14.40019","0.21179"
"28838","172.99200","14.41621","0.21256"
"28870","173.18400","14.43212","0.21339"
"28902","173.37600","14.44820","0.21393"
"28934","173.56800","14.46416","0.21443"
"28966","173.76000","14.48025","0.21500"
"28998","173.95200","14.49621","0.21543"
"29030","174.14400","14.51224","0.21597"
"29062","174.33600","14.52820","0.21675"
"29094","174.52800","14.54416","0.21696"
"29126","174.72000","14.56025","0.21752"
"29158","174.91200","14.57615","0.21866"
"29190","175.10400","14.59217","0.21903"
"29222","175.29600","14.60820","0.21967"
"29254","175.48800","14.62416","0.22067"
"29286","175.68000","14.64019","0.22128"
"29318","175.87200","14.65621","0.22211"
"29350","176.06400","14.67217","0.22336"
"29382","176.25600","14.68820","0.22428"
"29414","176.44800","14.70422","0.22489"
"29446","176.64000","14.72018","0.22618"
"29478","176.83200","14.73621","0.22720"
"29510","177.02400","14.75223","0.22808"
"29542","177.21600","14.76814","0.22853"
"29574","177.40800","14.78422","0.23008"
"29606","177.60000","14.80024","0.23138"
"29638","177.79200","14.81609","0.23323"
"29670","177.98400","14.83223","0.23482"
"29702","178.17600","14.84819","0.23533"
"29734","178.36800","14.86416","0.23678"
"29766","178.56000","14.88024","0.23789"
"29798","178.75200","14.89614","0.23859"
"29830","178.94400","14.91217","0.24010"
"29862","179.13600","14.92825","0.24083"
"29894","179.32800","14.94422","0.24183"
"29926","179.52000","14.96024","0.24316"
"29958","179.71200","14.97620","0.24451"
"29990","179.90400","14.99217","0.24552"
"30022","180.09600","15.00819","0.24675"
"30054","180.28800","15.02421","0.24786"
"30086","180.48000","15.04018","0.24878"
"30118","180.67200","15.05620","0.25005"
"30150","180.86400","15.07222","0.25056"
"30182","181.05600","15.08819","0.25180"
"30214","181.24800","15.10415","0.25262"
"30246","181.44000","15.12018","0.25341"
"30278","181.63200","15.13620","0.25441"
"30310","181.82400","15.15222","0.25493"
"30342","182.01600","15.16819","0.25573"
"30374","182.20800","15.18421","0.25641"
"30406","182.40000","15.20017","0.25714"
"30438","182.59200","15.21614","0.25723"
"30470","182.78400","15.23222","0.25806"
"30502","182.97600","15.24819","0.25844"
"30534","183.16800","15.26415","0.25876"
"30566","183.36000","15.28023","0.25889"
"30598","183.55200","15.29614","0.25932"
"30630","183.74400","15.31216","0.25969"
"30662","183.93600","15.32818","0.24593"
"30694","184.12800","15.34415","0.24607"
"30726","184.32000","15.36017","0.24729"
"30758","184.51200","15.37619","0.24940"
"30790","184.70400","15.39216","0.24973"
"30822","184.89600","15.40818","0.25043"
"30854","185.08800","15.42421","0.25169"
"30886","185.28000","15.44017","0.25324"
"30918","185.47200","15.45619","0.25434"
"30950","185.66400","15.47222","0.25476"
"30982","185.85600","15.48818","0.25589"
"31014","186.04800","15.50414","0.25678"
"31046","186.24000","15.52017","0.25690"
"31078","186.43200","15.53619","0.25740"
"31110","186.62400","15.55222","0.25797"
"31142","186.81600","15.56818","0.25834"
"31174","187.00800","15.58420","0.25875"
"31206","187.20000","15.60017","0.25926"
"31238","187.39200","15.61619","0.25964"
"31270","187.58400","15.63221","0.26002"
"31302","187.77600","15.64824","0.26069"
"31334","187.96800","15.66420","0.26105"
"31366","188.16000","15.68028","0.26155"
"31398","188.35200","15.69613","0.26143"
"31430","188.54400","15.71215","0.26147"
"31462","188.73600","15.72823","0.26161"
"31494","188.92800","15.74414","0.26216"
"31526","189.12000","15.76016","0.26256"
"31558","189.31200","15.77619","0.26270"
"31590","189.50400","15.79215","0.26346"
"31622","189.69600","15.80817","0.26403"
"31654","189.88800","15.82426","0.26452"
"31686","190.08000","15.84016","0.26498"
"31718","190.27200","15.85618","0.26536"
"31750","190.46400","15.87221","0.26608"
"31782","190.65600","15.88817","0.26651"
"31814","190.84800","15.90420","0.26712"
"31846","191.04000","15.92022","0.26832"
"31878","191.23200","15.93612","0.26944"
"31910","191.42400","15.95221","0.27050"
"31942","191.61600","15.96823","0.27099"
"31974","191.80800","15.98413","0.27173"
"32006","192.00000","16.00022","0.27343"
"32038","192.19200","16.01624","0.27432"
"32070","192.38400","16.03220","0.27584"
"32102","192.57600","16.04823","0.27736"
"32134","192.76800","16.06413","0.27827"
"32166","192.96000","16.08022","0.27954"
"32198","193.15200","16.09618","0.28105"
"32230","193.34400","16.11214","0.28188"
"32262","193.53600","16.12817","0.28336"
"32294","193.72800","16.14419","0.28516"
"32326","193.92000","16.16015","0.28557"
"32358","194.11200","16.17618","0.28732"
"32390","194.30400","16.19220","0.28905"
"32422","194.49600","16.20816","0.29069"
"32454","194.68800","16.22419","0.29193"
"32486","194.88000","16.24021","0.29282"
"32518","195.07200","16.25624","0.29531"
"32550","195.26400","16.27220","0.29598"
"32582","195.45600","16.28816","0.29797"
"32614","195.64800","16.30413","0.29959"
"32646","195.84000","16.32021","0.30032"
"32678","196.03200","16.33617","0.30132"
"32710","196.22400","16.35226","0.30299"
"32742","196.41600","16.36822","0.30456"
"32774","196.60800","16.38418","0.30604"
"32806","196.80000","16.40021","0.30625"
"32838","196.99200","16.41617","0.30801"
"32870","197.18400","16.43214","0.30870"
"32902","197.37600","16.44816","0.30956"
"32934","197.56800","16.46412","0.31056"
"32966","197.76000","16.48021","0.31207"
"32998","197.95200","16.49623","0.31319"
"33030","198.14400","16.51220","0.31375"
"33062","198.33600","16.52822","0.31500"
"33094","198.52800","16.54424","0.31669"
"33126","198.72000","16.56015","0.31822"
"33158","198.91200","16.57623","0.32037"
"33190","199.10400","16.59219","0.32270"
"33222","199.29600","16.60810","0.32435"
"33254","199.48800","16.62424","0.32671"
"33286","199.68000","16.64021","0.32865"
"33318","199.87200","16.65611","0.33143"
"33350","200.06400","16.67225","0.33397"
"33382","200.25600","16.68815","0.33575"
"33414","200.44800","16.70412","0.33727"
"33446","200.64000","16.72020","0.33991"
"33478","200.83200","16.73617","0.34209"
"33510","201.02400","16.75219","0.34539"
"33542","201.21600","16.76821","0.34762"
"33574","201.40800","16.78418","0.34963"
"33606","201.60000","16.80014","0.35176"
"33638","201.79200","16.81623","0.35351"
"33670","201.98400","16.83213","0.35596"
"33702","202.17600","16.84821","0.35738"
"33734","202.36800","16.86423","0.35874"
"33766","202.56000","16.88020","0.36041"
"33798","202.75200","16.89616","0.36211"
"33830","202.94400","16.91225","0.36324"
"33862","203.13600","16.92821","0.36404"
"33894","203.32800","16.94417","0.36526"
"33926","203.52000","16.96020","0.36582"
"33958","203.71200","16.97616","0.36724"
"33990","203.90400","16.99219","0.36771"
"34022","204.09600","17.00821","0.36804"
"34054","204.28800","17.02417","0.36839"
"34086","204.48000","17.04020","0.36896"
"34118","204.67200","17.05616","0.36927"
"34150","204.86400","17.07218","0.36966"
"34182","205.05600","17.08821","0.36972"
"34214","205.24800","17.10417","0.37000"
"34246","205.44000","17.12019","0.37050"
"34278","205.63200","17.13616","0.37068"
"34310","205.82400","17.15218","0.37094"
"34342","206.01600","17.16821","0.37118"
"34374","206.20800","17.18417","0.37173"
"34406","206.40000","17.20019","0.37228"
"34438","206.59200","17.21622","0.37318"
"34470","206.78400","17.23212","0.37363"
"34502","206.97600","17.24826","0.37389"
"34534","207.16800","17.26423","0.37482"
"34566","207.36000","17.28013","0.37522"
"34598","207.55200","17.29627","0.37594"
"34630","207.74400","17.31218","0.37549"
"34662","207.93600","17.32814","0.37648"
"34694","208.12800","17.34422","0.37718"
"34726","208.32000","17.36019","0.37857"
"34758","208.51200","17.37615","0.37927"
"34790","208.70400","17.39218","0.38033"
"34822","208.89600","17.40820","0.38098"
"34854","209.08800","17.42422","0.38191"
"34886","209.28000","17.44025","0.38366"
"34918","209.47200","17.45621","0.38534"
"34950","209.66400","17.47218","0.38684"
"34982","209.85600","17.48820","0.38807"
"35014","210.04800","17.50416","0.38939"
"35046","210.24000","17.52019","0.39097"
"35078","210.43200","17.53615","0.39277"
"35110","210.62400","17.55211","0.39475"
"35142","210.81600","17.56820","0.39628"
"35174","211.00800","17.58422","0.39923"
"35206","211.20000","17.60012","0.40029"
"35238","211.39200","17.61621","0.40202"
"35270","211.58400","17.63217","0.40397"
"35302","211.77600","17.64820","0.40668"
"35334","211.96800","17.66422","0.40822"
"35366","212.16000","17.68018","0.40929"
"35398","212.35200","17.69621","0.41125"
"35430","212.54400","17.71223","0.41306"
"35462","212.73600","17.72820","0.41444"
"35494","212.92800","17.74422","0.41528"
"35526","213.12000","17.76018","0.41663"
"35558","213.31200","17.77614","0.41740"
"35590","213.50400","17.79217","0.41805"
"35622","213.69600","17.80819","0.41934"
"35654","213.88800","17.82416","0.41990"
"35686","214.08000","17.84018","0.42079"
"35718","214.27200","17.85620","0.42214"
"35750","214.46400","17.87223","0.42392"
"35782","214.65600","17.88819","0.42467"
"35814","214.84800","17.90421","0.42642"
"35846","215.04000","17.92018","0.42795"
"35878","215.23200","17.93620","0.42896"
"35910","215.42400","17.95217","0.43112"
"35942","215.61600","17.96825","0.43257"
"35974","215.80800","17.98421","0.43434"
"36006","216.00000","18.00018","0.43578"
"36038","216.19200","18.01626","0.43785"
"36070","216.38400","18.03210","0.43896"
"36102","216.57600","18.04819","0.44084"
"36134","216.76800","18.06421","0.44192"
"36166","216.96000","18.08018","0.44344"
"36198","217.15200","18.09620","0.44413"
"36230","217.34400","18.11222","0.44556"
"36262","217.53600","18.12819","0.44669"
"36294","217.72800","18.14421","0.44773"
"36326","217.92000","18.16023","0.44830"
"36358","218.11200","18.17614","0.44924"
"36390","218.30400","18.19222","0.45044"
"36422","218.49600","18.20819","0.45159"
"36454","218.68800","18.22415","0.45221"
"36486","218.88000","18.24023","0.45351"
"36518","219.07200","18.25620","0.45400"
"36550","219.26400","18.27216","0.45486"
"36582","219.45600","18.28824","0.45559"
"36614","219.64800","18.30415","0.45620"
"36646","219.84000","18.32017","0.45674"
"36678","220.03200","18.33625","0.45756"
"36710","220.22400","18.35216","0.45851"
"36742","220.41600","18.36824","0.45963"
"36774","220.60800","18.38420","0.46055"
"36806","220.80000","18.40017","0.46200"
"36838","220.99200","18.41619","0.46280"
"36870","221.18400","18.43216","0.46426"
"36902","221.37600","18.44818","0.46519"
"36934","221.56800","18.46420","0.46659"
"36966","221.76000","18.48017","0.46779"
"36998","221.95200","18.49613","0.46920"
"37030","222.14400","18.51221","0.47086"
"37062","222.33600","18.52824","0.47168"
"37094","222.52800","18.54420","0.47339"
"37126","222.72000","18.56017","0.47431"
"37158","222.91200","18.57619","0.47595"
"37190","223.10400","18.59215","0.47712"
"37222","223.29600","18.60824","0.47917"
"37254","223.48800","18.62420","0.48084"
"37286","223.68000","18.64016","0.48208"
"37318","223.87200","18.65619","0.48391"
"37350","224.06400","18.67215","0.48565"
"37382","224.25600","18.68818","0.48731"
"37414","224.44800","18.70420","0.48946"
"37446","224.64000","18.72016","0.49083"
"37478","224.83200","18.73619","0.49300"
"37510","225.02400","18.75215","0.49492"
"37542","225.21600","18.76818","0.49665"
"37574","225.40800","18.78426","0.49875"
"37606","225.60000","18.80016","0.50027"
"37638","225.79200","18.81618","0.50176"
"37670","225.98400","18.83221","0.50336"
"37702","226.17600","18.84817","0.50585"
"37734","226.36800","18.86426","0.50668"
"37766","226.56000","18.88022","0.50889"
"37798","226.75200","18.89618","0.51039"
"37830","226.94400","18.91227","0.51212"
"37862","227.13600","18.92817","0.51348"
"37894","227.32800","18.94419","0.51456"
"37926","227.52000","18.96016","0.51579"
"37958","227.71200","18.97612","0.51678"
"37990","227.90400","18.99220","0.51748"
"38022","228.09600","19.00823","0.51838"
"38054","228.28800","19.02413","0.51853"
"38086","228.48000","19.04022","0.51747"
"38118","228.67200","19.05624","0.51690"
"38150","228.86400","19.07214","0.51764"
"38182","229.05600","19.08817","0.51471"
"38214","229.24800","19.10419","0.51377"
"38246","229.44000","19.12010","0.51461"
"38278","229.63200","19.13624","0.51517"
"38310","229.82400","19.15220","0.51258"
"38342","230.01600","19.16811","0.51274"
"38374","230.20800","19.18425","0.49729"
"38406","230.40000","19.20021","0.49896"
"38438","230.59200","19.21618","0.49979"
"38470","230.78400","19.23226","0.48781"
"38502","230.97600","19.24816","0.47261"
"38534","231.16800","19.26419","0.47374"
"38566","231.36000","19.28021","0.47543"
"38598","231.55200","19.29618","0.47791"
"38630","231.74400","19.31220","0.48017"
"38662","231.93600","19.32822","0.47532"
"38694","232.12800","19.34413","0.47837"
"38726","232.32000","19.36021","0.48132"
"38758","232.51200","19.37617","0.48433"
"38790","232.70400","19.39220","0.48675"
"38822","232.89600","19.40822","0.48883"
"38854","233.08800","19.42418","0.23002"
"38886","233.28000","19.44021","0.07338"
"38918","233.47200","19.45623","0.07856"
"38950","233.66400","19.47219","0.07688"
"38982","233.85600","19.48822","0.08013"
"39014","234.04800","19.50424","0.09475"
"39046","234.24000","19.52015","0.08081"
"39078","234.43200","19.53623","0.08024"
"39110","234.62400","19.55219","0.08734"
"39142","234.81600","19.56816","0.08053"
"39174","235.00800","19.58424","0.09728"
"39206","235.20000","19.60020","0.08252"
"39238","235.39200","19.61623","0.08587"
"39270","235.58400","19.63219","0.08866"
"39302","235.77600","19.64816","0.08543"
"39334","235.96800","19.66418","0.09936"
"39366","236.16000","19.68020","0.08734"
"39398","236.35200","19.69617","0.09251"
"39430","236.54400","19.71219","0.09050"
"39462","236.73600","19.72827","0.09016"
"39494","236.92800","19.74418","0.10023"
"39526","237.12000","19.76020","0.09336"
"39558","237.31200","19.77623","0.09720"
"39590","237.50400","19.79219","0.09439"
"39622","237.69600","19.80821","0.08987"
"39654","237.88800","19.82418","0.09902"
"39686","238.08000","19.84014","0.09345"
"39718","238.27200","19.85622","0.10033"
"39750","238.46400","19.87225","0.09591"
"39782","238.65600","19.88821","0.09639"
"39814","238.84800","19.90424","0.10225"
"39846","239.04000","19.92014","0.09891"
"39878","239.23200","19.93622","0.10631"
"39910","239.42400","19.95218","0.10130"
"39942","239.61600","19.96815","0.10404"
"39974","239.80800","19.98423","0.10467"
"40006","240.00000","20.00020","0.10432"
"40038","240.19200","20.01610","0.10873"
"40070","240.38400","20.03224","0.10646"
"40102","240.57600","20.04815","0.10903"
"40134","240.76800","20.06417","0.10771"
"40166","240.96000","20.08019","0.10859"
"40198","241.15200","20.09616","0.10958"
"40207","241.20600","20.10064","0.10940"