File: Trajectories_together/170212_1Specimen_RawData_8.csv
"","V1","V2","V3"
"1","End date","2/12/2017",""
"2","Specimen label","9AG_76",""
"3","Maximum Load","0.27510","N"
"4","Time","Extension","Load"
"5","(s)","(mm)","(N)"
"6","0.00000","0.00000","-0.00004"
"49","0.25800","0.01997","0.00110"
"92","0.51600","0.04317","0.00187"
"135","0.77400","0.06469","0.00117"
"178","1.03200","0.08610","0.00298"
"221","1.29000","0.10768","0.00415"
"264","1.54800","0.12915","0.00393"
"307","1.80600","0.15067","0.00398"
"350","2.06400","0.17207","0.00537"
"393","2.32200","0.19366","0.00633"
"436","2.58000","0.21512","0.00696"
"479","2.83800","0.23665","0.00755"
"522","3.09600","0.25811","0.00861"
"565","3.35400","0.27964","0.00906"
"608","3.61200","0.30116","0.01042"
"651","3.87000","0.32256","0.01077"
"694","4.12800","0.34415","0.01155"
"737","4.38600","0.36555","0.01251"
"780","4.64400","0.38714","0.01287"
"823","4.90200","0.40860","0.01415"
"866","5.16000","0.43013","0.01492"
"909","5.41800","0.45159","0.01654"
"952","5.67600","0.47311","0.01812"
"995","5.93400","0.49452","0.01922"
"1038","6.19200","0.51610","0.02107"
"1081","6.45000","0.53763","0.02236"
"1124","6.70800","0.55915","0.02544"
"1167","6.96600","0.58062","0.02778"
"1210","7.22400","0.60214","0.03058"
"1253","7.48200","0.62354","0.03443"
"1296","7.74000","0.64519","0.03715"
"1339","7.99800","0.66659","0.04123"
"1382","8.25600","0.68812","0.04414"
"1425","8.51400","0.70958","0.04776"
"1468","8.77200","0.73111","0.05163"
"1511","9.03000","0.75263","0.05452"
"1554","9.28800","0.77415","0.05795"
"1597","9.54600","0.79562","0.06100"
"1640","9.80400","0.81708","0.06352"
"1683","10.06200","0.83861","0.06632"
"1726","10.32000","0.86013","0.06836"
"1769","10.57800","0.88166","0.06999"
"1812","10.83600","0.90306","0.07122"
"1855","11.09400","0.92465","0.07223"
"1898","11.35200","0.94599","0.07307"
"1941","11.61000","0.96763","0.07410"
"1984","11.86800","0.98904","0.07533"
"2027","12.12600","1.01062","0.07720"
"2070","12.38400","1.03209","0.07936"
"2113","12.64200","1.05361","0.08181"
"2156","12.90000","1.07508","0.08541"
"2199","13.15800","1.09666","0.08972"
"2242","13.41600","1.11806","0.09344"
"2285","13.67400","1.13959","0.09698"
"2328","13.93200","1.16105","0.09978"
"2371","14.19000","1.18264","0.10316"
"2414","14.44800","1.20410","0.10492"
"2457","14.70600","1.22563","0.10642"
"2500","14.96400","1.24709","0.10696"
"2543","15.22200","1.26861","0.10848"
"2586","15.48000","1.29014","0.10947"
"2629","15.73800","1.31160","0.11011"
"2672","15.99600","1.33313","0.11105"
"2715","16.25400","1.35465","0.11162"
"2758","16.51200","1.37612","0.11243"
"2801","16.77000","1.39764","0.11336"
"2844","17.02800","1.41910","0.11342"
"2887","17.28600","1.44057","0.11480"
"2930","17.54400","1.46215","0.11442"
"2973","17.80200","1.48356","0.11498"
"3016","18.06000","1.50514","0.11568"
"3059","18.31800","1.52655","0.11611"
"3102","18.57600","1.54807","0.11622"
"3145","18.83400","1.56954","0.11670"
"3188","19.09200","1.59112","0.11737"
"3231","19.35000","1.61258","0.11792"
"3274","19.60800","1.63417","0.11848"
"3317","19.86600","1.65563","0.11836"
"3360","20.12400","1.67716","0.11927"
"3403","20.38200","1.69856","0.11944"
"3446","20.64000","1.72014","0.11954"
"3489","20.89800","1.74161","0.12068"
"3532","21.15600","1.76307","0.12073"
"3575","21.41400","1.78460","0.12169"
"3618","21.67200","1.80612","0.12161"
"3661","21.93000","1.82771","0.12210"
"3704","22.18800","1.84905","0.12213"
"3747","22.44600","1.87058","0.12251"
"3790","22.70400","1.89210","0.12297"
"3833","22.96200","1.91362","0.12268"
"3876","23.22000","1.93509","0.12315"
"3919","23.47800","1.95661","0.12342"
"3962","23.73600","1.97808","0.12335"
"4005","23.99400","1.99966","0.12424"
"4048","24.25200","2.02107","0.12471"
"4091","24.51000","2.04265","0.12491"
"4134","24.76800","2.06411","0.12471"
"4177","25.02600","2.08558","0.12496"
"4220","25.28400","2.10710","0.12542"
"4263","25.54200","2.12863","0.12600"
"4306","25.80000","2.15009","0.12597"
"4349","26.05800","2.17168","0.12539"
"4392","26.31600","2.19308","0.12561"
"4435","26.57400","2.21466","0.12540"
"4478","26.83200","2.23613","0.12583"
"4521","27.09000","2.25765","0.12644"
"4564","27.34800","2.27912","0.12654"
"4607","27.60600","2.30064","0.12607"
"4650","27.86400","2.32211","0.12716"
"4693","28.12200","2.34363","0.12689"
"4736","28.38000","2.36515","0.12709"
"4779","28.63800","2.38662","0.12749"
"4822","28.89600","2.40814","0.12711"
"4865","29.15400","2.42961","0.12806"
"4908","29.41200","2.45113","0.12755"
"4951","29.67000","2.47266","0.12817"
"4994","29.92800","2.49412","0.12848"
"5037","30.18600","2.51553","0.12831"
"5080","30.44400","2.53711","0.12824"
"5123","30.70200","2.55857","0.12884"
"5166","30.96000","2.58016","0.12853"
"5209","31.21800","2.60162","0.12854"
"5252","31.47600","2.62309","0.12867"
"5295","31.73400","2.64461","0.12871"
"5338","31.99200","2.66613","0.12929"
"5381","32.25000","2.68766","0.12889"
"5424","32.50800","2.70912","0.12885"
"5467","32.76600","2.73065","0.13012"
"5510","33.02400","2.75217","0.12962"
"5553","33.28200","2.77364","0.12943"
"5596","33.54000","2.79516","0.12995"
"5639","33.79800","2.81657","0.12976"
"5682","34.05600","2.83809","0.13022"
"5725","34.31400","2.85955","0.12974"
"5768","34.57200","2.88114","0.13041"
"5811","34.83000","2.90266","0.13071"
"5854","35.08800","2.92413","0.12983"
"5897","35.34600","2.94565","0.13048"
"5940","35.60400","2.96712","0.13002"
"5983","35.86200","2.98864","0.12937"
"6026","36.12000","3.01010","0.13011"
"6069","36.37800","3.03163","0.13073"
"6112","36.63600","3.05303","0.13044"
"6155","36.89400","3.07468","0.13069"
"6198","37.15200","3.09608","0.13084"
"6241","37.41000","3.11761","0.13004"
"6284","37.66800","3.13907","0.13044"
"6327","37.92600","3.16059","0.13071"
"6370","38.18400","3.18206","0.13087"
"6413","38.44200","3.20364","0.13058"
"6456","38.70000","3.22511","0.13100"
"6499","38.95800","3.24663","0.13041"
"6542","39.21600","3.26810","0.13087"
"6585","39.47400","3.28962","0.13065"
"6628","39.73200","3.31108","0.13119"
"6671","39.99000","3.33267","0.13075"
"6714","40.24800","3.35407","0.13126"
"6757","40.50600","3.37566","0.13108"
"6800","40.76400","3.39712","0.13058"
"6843","41.02200","3.41859","0.13120"
"6886","41.28000","3.44011","0.13124"
"6929","41.53800","3.46157","0.13159"
"6972","41.79600","3.48310","0.13130"
"7015","42.05400","3.50462","0.13108"
"7058","42.31200","3.52615","0.13156"
"7101","42.57000","3.54755","0.13151"
"7144","42.82800","3.56914","0.13104"
"7187","43.08600","3.59060","0.13155"
"7230","43.34400","3.61213","0.13143"
"7273","43.60200","3.63365","0.13171"
"7316","43.86000","3.65511","0.13184"
"7359","44.11800","3.67658","0.13117"
"7402","44.37600","3.69816","0.13120"
"7445","44.63400","3.71963","0.13109"
"7488","44.89200","3.74115","0.13165"
"7531","45.15000","3.76262","0.13171"
"7574","45.40800","3.78414","0.13133"
"7617","45.66600","3.80554","0.13190"
"7660","45.92400","3.82713","0.13174"
"7703","46.18200","3.84865","0.13132"
"7746","46.44000","3.87012","0.13172"
"7789","46.69800","3.89158","0.13165"
"7832","46.95600","3.91311","0.13137"
"7875","47.21400","3.93463","0.13146"
"7918","47.47200","3.95615","0.13210"
"7961","47.73000","3.97768","0.13135"
"8004","47.98800","3.99908","0.13092"
"8047","48.24600","4.02067","0.13172"
"8090","48.50400","4.04213","0.13128"
"8133","48.76200","4.06366","0.13160"
"8176","49.02000","4.08506","0.13144"
"8219","49.27800","4.10658","0.13162"
"8262","49.53600","4.12805","0.13157"
"8305","49.79400","4.14963","0.13140"
"8348","50.05200","4.17110","0.13183"
"8391","50.31000","4.19262","0.13166"
"8434","50.56800","4.21409","0.13194"
"8477","50.82600","4.23561","0.13060"
"8520","51.08400","4.25707","0.13191"
"8563","51.34200","4.27866","0.13192"
"8606","51.60000","4.30006","0.13151"
"8649","51.85800","4.32165","0.13190"
"8692","52.11600","4.34311","0.13198"
"8735","52.37400","4.36464","0.13262"
"8778","52.63200","4.38610","0.13158"
"8821","52.89000","4.40762","0.13195"
"8864","53.14800","4.42909","0.13231"
"8907","53.40600","4.45061","0.13221"
"8950","53.66400","4.47214","0.13168"
"8993","53.92200","4.49366","0.13241"
"9036","54.18000","4.51513","0.13229"
"9079","54.43800","4.53659","0.13250"
"9122","54.69600","4.55812","0.13234"
"9165","54.95400","4.57964","0.13219"
"9208","55.21200","4.60116","0.13204"
"9251","55.47000","4.62257","0.13245"
"9294","55.72800","4.64415","0.13219"
"9337","55.98600","4.66562","0.13338"
"9380","56.24400","4.68714","0.13277"
"9423","56.50200","4.70860","0.13281"
"9466","56.76000","4.73013","0.13267"
"9509","57.01800","4.75153","0.13246"
"9552","57.27600","4.77312","0.13302"
"9595","57.53400","4.79458","0.13277"
"9638","57.79200","4.81617","0.13257"
"9681","58.05000","4.83763","0.13302"
"9724","58.30800","4.85916","0.13303"
"9767","58.56600","4.88062","0.13342"
"9810","58.82400","4.90214","0.13314"
"9853","59.08200","4.92367","0.13212"
"9896","59.34000","4.94513","0.13284"
"9939","59.59800","4.96660","0.13304"
"9982","59.85600","4.98812","0.13314"
"10025","60.11400","5.00958","0.13320"
"10068","60.37200","5.03111","0.13370"
"10111","60.63000","5.05263","0.13318"
"10154","60.88800","5.07410","0.13327"
"10197","61.14600","5.09562","0.13312"
"10240","61.40400","5.11709","0.13348"
"10283","61.66200","5.13861","0.13367"
"10326","61.92000","5.16002","0.13339"
"10369","62.17800","5.18160","0.13336"
"10412","62.43600","5.20306","0.13348"
"10455","62.69400","5.22465","0.13336"
"10498","62.95200","5.24611","0.13400"
"10541","63.21000","5.26764","0.13344"
"10584","63.46800","5.28910","0.13421"
"10627","63.72600","5.31069","0.13329"
"10670","63.98400","5.33209","0.13375"
"10713","64.24200","5.35361","0.13347"
"10756","64.50000","5.37508","0.13381"
"10799","64.75800","5.39666","0.13404"
"10842","65.01600","5.41813","0.13368"
"10885","65.27400","5.43965","0.13369"
"10928","65.53200","5.46112","0.13358"
"10971","65.79000","5.48264","0.13398"
"11014","66.04800","5.50410","0.13335"
"11057","66.30600","5.52557","0.13394"
"11100","66.56400","5.54709","0.13464"
"11143","66.82200","5.56862","0.13352"
"11186","67.08000","5.59014","0.13369"
"11229","67.33800","5.61161","0.13428"
"11272","67.59600","5.63313","0.13465"
"11315","67.85400","5.65460","0.13436"
"11358","68.11200","5.67612","0.13486"
"11401","68.37000","5.69752","0.13413"
"11444","68.62800","5.71911","0.13434"
"11487","68.88600","5.74057","0.13476"
"11530","69.14400","5.76210","0.13469"
"11573","69.40200","5.78356","0.13513"
"11616","69.66000","5.80509","0.13493"
"11659","69.91800","5.82661","0.13453"
"11702","70.17600","5.84813","0.13481"
"11745","70.43400","5.86960","0.13483"
"11788","70.69200","5.89112","0.13441"
"11831","70.95000","5.91259","0.13546"
"11874","71.20800","5.93417","0.13481"
"11917","71.46600","5.95558","0.13537"
"11960","71.72400","5.97716","0.13508"
"12003","71.98200","5.99862","0.13521"
"12046","72.24000","6.02009","0.13507"
"12089","72.49800","6.04161","0.13522"
"12132","72.75600","6.06308","0.13512"
"12175","73.01400","6.08466","0.13490"
"12218","73.27200","6.10607","0.13474"
"12261","73.53000","6.12759","0.13482"
"12304","73.78800","6.14906","0.13473"
"12347","74.04600","6.17064","0.13509"
"12390","74.30400","6.19210","0.13521"
"12433","74.56200","6.21363","0.13522"
"12476","74.82000","6.23503","0.13556"
"12519","75.07800","6.25668","0.13546"
"12562","75.33600","6.27808","0.13521"
"12605","75.59400","6.29966","0.13479"
"12648","75.85200","6.32113","0.13521"
"12691","76.11000","6.34259","0.13546"
"12734","76.36800","6.36406","0.13483"
"12777","76.62600","6.38564","0.13476"
"12820","76.88400","6.40711","0.13495"
"12863","77.14200","6.42863","0.13461"
"12906","77.40000","6.45010","0.13507"
"12949","77.65800","6.47162","0.13468"
"12992","77.91600","6.49314","0.13490"
"13035","78.17400","6.51467","0.13496"
"13078","78.43200","6.53607","0.13511"
"13121","78.69000","6.55760","0.13464"
"13164","78.94800","6.57912","0.13520"
"13207","79.20600","6.60059","0.13481"
"13250","79.46400","6.62211","0.13513"
"13293","79.72200","6.64357","0.13531"
"13336","79.98000","6.66516","0.13498"
"13379","80.23800","6.68656","0.13473"
"13422","80.49600","6.70815","0.13533"
"13465","80.75400","6.72961","0.13524"
"13508","81.01200","6.75113","0.13392"
"13551","81.27000","6.77254","0.13401"
"13594","81.52800","6.79412","0.13403"
"13637","81.78600","6.81559","0.13387"
"13680","82.04400","6.83717","0.13354"
"13723","82.30200","6.85858","0.13423"
"13766","82.56000","6.88010","0.13426"
"13809","82.81800","6.90157","0.13397"
"13852","83.07600","6.92309","0.13399"
"13895","83.33400","6.94461","0.13431"
"13938","83.59200","6.96614","0.13355"
"13981","83.85000","6.98760","0.13412"
"14024","84.10800","7.00913","0.13378"
"14067","84.36600","7.03059","0.13395"
"14110","84.62400","7.05212","0.13449"
"14153","84.88200","7.07364","0.13437"
"14196","85.14000","7.09510","0.13367"
"14239","85.39800","7.11657","0.13449"
"14282","85.65600","7.13809","0.13441"
"14325","85.91400","7.15962","0.13336"
"14368","86.17200","7.18108","0.13439"
"14411","86.43000","7.20261","0.13357"
"14454","86.68800","7.22407","0.13419"
"14497","86.94600","7.24565","0.13386"
"14540","87.20400","7.26712","0.13427"
"14583","87.46200","7.28858","0.13354"
"14626","87.72000","7.31011","0.13398"
"14669","87.97800","7.33163","0.13454"
"14712","88.23600","7.35310","0.13395"
"14755","88.49400","7.37462","0.13363"
"14798","88.75200","7.39608","0.13385"
"14841","89.01000","7.41767","0.13397"
"14884","89.26800","7.43907","0.13366"
"14927","89.52600","7.46066","0.13408"
"14970","89.78400","7.48212","0.13436"
"15013","90.04200","7.50359","0.13413"
"15056","90.30000","7.52511","0.13349"
"15099","90.55800","7.54663","0.13445"
"15142","90.81600","7.56810","0.13371"
"15185","91.07400","7.58962","0.13386"
"15228","91.33200","7.61109","0.13407"
"15271","91.59000","7.63261","0.13417"
"15314","91.84800","7.65414","0.13403"
"15357","92.10600","7.67554","0.13340"
"15400","92.36400","7.69712","0.13381"
"15443","92.62200","7.71859","0.13417"
"15486","92.88000","7.74011","0.13392"
"15529","93.13800","7.76158","0.13411"
"15572","93.39600","7.78316","0.13370"
"15615","93.65400","7.80457","0.13435"
"15658","93.91200","7.82609","0.13423"
"15701","94.17000","7.84756","0.13397"
"15744","94.42800","7.86914","0.13398"
"15787","94.68600","7.89060","0.13389"
"15830","94.94400","7.91213","0.13421"
"15873","95.20200","7.93353","0.13420"
"15916","95.46000","7.95518","0.13450"
"15959","95.71800","7.97658","0.13395"
"16002","95.97600","7.99817","0.13448"
"16045","96.23400","8.01963","0.13426"
"16088","96.49200","8.04115","0.13401"
"16131","96.75000","8.06262","0.13372"
"16174","97.00800","8.08414","0.13404"
"16217","97.26600","8.10567","0.13379"
"16260","97.52400","8.12713","0.13436"
"16303","97.78200","8.14860","0.13428"
"16346","98.04000","8.17006","0.13481"
"16389","98.29800","8.19164","0.13450"
"16432","98.55600","8.21311","0.13372"
"16475","98.81400","8.23469","0.13327"
"16518","99.07200","8.25604","0.13426"
"16561","99.33000","8.27762","0.13400"
"16604","99.58800","8.29909","0.13427"
"16647","99.84600","8.32067","0.13365"
"16690","100.10400","8.34207","0.13434"
"16733","100.36200","8.36360","0.13356"
"16776","100.62000","8.38512","0.13439"
"16819","100.87800","8.40665","0.13405"
"16862","101.13600","8.42811","0.13304"
"16905","101.39400","8.44964","0.13309"
"16948","101.65200","8.47110","0.13362"
"16991","101.91000","8.49262","0.13410"
"17034","102.16800","8.51415","0.13279"
"17077","102.42600","8.53567","0.13242"
"17120","102.68400","8.55708","0.13344"
"17163","102.94200","8.57860","0.13329"
"17206","103.20000","8.60007","0.13310"
"17249","103.45800","8.62159","0.13309"
"17292","103.71600","8.64317","0.13413"
"17335","103.97400","8.66464","0.13394"
"17378","104.23200","8.68610","0.13294"
"17421","104.49000","8.70763","0.13319"
"17464","104.74800","8.72909","0.13345"
"17507","105.00600","8.75056","0.13396"
"17550","105.26400","8.77214","0.13393"
"17593","105.52200","8.79361","0.13386"
"17636","105.78000","8.81513","0.13459"
"17679","106.03800","8.83653","0.13336"
"17722","106.29600","8.85818","0.13411"
"17765","106.55400","8.87958","0.13445"
"17808","106.81200","8.90111","0.13422"
"17851","107.07000","8.92257","0.13371"
"17894","107.32800","8.94410","0.13363"
"17937","107.58600","8.96562","0.13381"
"17980","107.84400","8.98714","0.13408"
"18023","108.10200","9.00861","0.13393"
"18066","108.36000","9.03013","0.13394"
"18109","108.61800","9.05160","0.13382"
"18152","108.87600","9.07312","0.13365"
"18195","109.13400","9.09459","0.13397"
"18238","109.39200","9.11611","0.13410"
"18281","109.65000","9.13757","0.13402"
"18324","109.90800","9.15910","0.13442"
"18367","110.16600","9.18062","0.13389"
"18410","110.42400","9.20209","0.13341"
"18453","110.68200","9.22361","0.13368"
"18496","110.94000","9.24508","0.13455"
"18539","111.19800","9.26660","0.13426"
"18582","111.45600","9.28806","0.13459"
"18625","111.71400","9.30959","0.13407"
"18668","111.97200","9.33105","0.13425"
"18711","112.23000","9.35264","0.13419"
"18754","112.48800","9.37410","0.13423"
"18797","112.74600","9.39557","0.13395"
"18840","113.00400","9.41709","0.13405"
"18883","113.26200","9.43861","0.13412"
"18926","113.52000","9.46008","0.13428"
"18969","113.77800","9.48166","0.13439"
"19012","114.03600","9.50307","0.13411"
"19055","114.29400","9.52465","0.13414"
"19098","114.55200","9.54606","0.13401"
"19141","114.81000","9.56764","0.13449"
"19184","115.06800","9.58910","0.13448"
"19227","115.32600","9.61063","0.13414"
"19270","115.58400","9.63209","0.13499"
"19313","115.84200","9.65362","0.13467"
"19356","116.10000","9.67514","0.13476"
"19399","116.35800","9.69667","0.13423"
"19442","116.61600","9.71813","0.13452"
"19485","116.87400","9.73960","0.13494"
"19528","117.13200","9.76118","0.13371"
"19571","117.39000","9.78258","0.13491"
"19614","117.64800","9.80417","0.13433"
"19657","117.90600","9.82557","0.13456"
"19700","118.16400","9.84710","0.13474"
"19743","118.42200","9.86856","0.13416"
"19786","118.68000","9.89009","0.13452"
"19829","118.93800","9.91161","0.13445"
"19872","119.19600","9.93313","0.13449"
"19915","119.45400","9.95460","0.13466"
"19958","119.71200","9.97612","0.13499"
"20001","119.97000","9.99759","0.13547"
"20044","120.22800","10.01917","0.13459"
"20087","120.48600","10.04058","0.13483"
"20130","120.74400","10.06210","0.13516"
"20173","121.00200","10.08356","0.13437"
"20216","121.26000","10.10515","0.13518"
"20259","121.51800","10.12661","0.13484"
"20302","121.77600","10.14820","0.13544"
"20345","122.03400","10.16954","0.13463"
"20388","122.29200","10.19113","0.13459"
"20431","122.55000","10.21265","0.13475"
"20474","122.80800","10.23411","0.13504"
"20517","123.06600","10.25564","0.13507"
"20560","123.32400","10.27704","0.13501"
"20603","123.58200","10.29863","0.13490"
"20646","123.84000","10.32009","0.13460"
"20689","124.09800","10.34162","0.13505"
"20732","124.35600","10.36302","0.13467"
"20775","124.61400","10.38466","0.13446"
"20818","124.87200","10.40607","0.13518"
"20861","125.13000","10.42759","0.13523"
"20904","125.38800","10.44912","0.13480"
"20947","125.64600","10.47058","0.13526"
"20990","125.90400","10.49205","0.13529"
"21033","126.16200","10.51363","0.13478"
"21076","126.42000","10.53504","0.13535"
"21119","126.67800","10.55668","0.13545"
"21162","126.93600","10.57808","0.13512"
"21205","127.19400","10.59961","0.13540"
"21248","127.45200","10.62107","0.13499"
"21291","127.71000","10.64266","0.13486"
"21334","127.96800","10.66412","0.13542"
"21377","128.22600","10.68559","0.13491"
"21420","128.48400","10.70711","0.13528"
"21463","128.74200","10.72857","0.13530"
"21506","129.00000","10.75016","0.13529"
"21549","129.25800","10.77162","0.13498"
"21592","129.51600","10.79315","0.13505"
"21635","129.77400","10.81455","0.13532"
"21678","130.03200","10.83613","0.13549"
"21721","130.29000","10.85760","0.13558"
"21764","130.54800","10.87912","0.13521"
"21807","130.80600","10.90053","0.13563"
"21850","131.06400","10.92211","0.13564"
"21893","131.32200","10.94358","0.13528"
"21936","131.58000","10.96516","0.13556"
"21979","131.83800","10.98657","0.13512"
"22022","132.09600","11.00815","0.13505"
"22065","132.35400","11.02962","0.13578"
"22108","132.61200","11.05114","0.13587"
"22151","132.87000","11.07260","0.13549"
"22194","133.12800","11.09413","0.13502"
"22237","133.38600","11.11553","0.13627"
"22280","133.64400","11.13711","0.13572"
"22323","133.90200","11.15864","0.13623"
"22366","134.16000","11.18016","0.13557"
"22409","134.41800","11.20163","0.13528"
"22452","134.67600","11.22309","0.13584"
"22495","134.93400","11.24462","0.13561"
"22538","135.19200","11.26608","0.13529"
"22581","135.45000","11.28767","0.13553"
"22624","135.70800","11.30913","0.13470"
"22667","135.96600","11.33060","0.13395"
"22710","136.22400","11.35212","0.13445"
"22753","136.48200","11.37358","0.13456"
"22796","136.74000","11.39511","0.13527"
"22839","136.99800","11.41663","0.13390"
"22882","137.25600","11.43804","0.13464"
"22925","137.51400","11.45962","0.13456"
"22968","137.77200","11.48108","0.13464"
"23011","138.03000","11.50261","0.13520"
"23054","138.28800","11.52407","0.13414"
"23097","138.54600","11.54560","0.13524"
"23140","138.80400","11.56712","0.13520"
"23183","139.06200","11.58865","0.13485"
"23226","139.32000","11.61011","0.13452"
"23269","139.57800","11.63164","0.13480"
"23312","139.83600","11.65310","0.13516"
"23355","140.09400","11.67468","0.13481"
"23398","140.35200","11.69615","0.13496"
"23441","140.61000","11.71767","0.13512"
"23484","140.86800","11.73914","0.13475"
"23527","141.12600","11.76060","0.13518"
"23570","141.38400","11.78212","0.13527"
"23613","141.64200","11.80359","0.13485"
"23656","141.90000","11.82517","0.13515"
"23699","142.15800","11.84658","0.13508"
"23742","142.41600","11.86816","0.13521"
"23785","142.67400","11.88957","0.13577"
"23828","142.93200","11.91115","0.13489"
"23871","143.19000","11.93262","0.13538"
"23914","143.44800","11.95414","0.13529"
"23957","143.70600","11.97554","0.13529"
"24000","143.96400","11.99713","0.13566"
"24043","144.22200","12.01859","0.13496"
"24086","144.48000","12.04012","0.13558"
"24129","144.73800","12.06158","0.13580"
"24172","144.99600","12.08311","0.13576"
"24215","145.25400","12.10463","0.13543"
"24258","145.51200","12.12615","0.13591"
"24301","145.77000","12.14762","0.13538"
"24344","146.02800","12.16914","0.13579"
"24387","146.28600","12.19055","0.13563"
"24430","146.54400","12.21213","0.13507"
"24473","146.80200","12.23366","0.13551"
"24516","147.06000","12.25518","0.13590"
"24559","147.31800","12.27664","0.13667"
"24602","147.57600","12.29817","0.13606"
"24645","147.83400","12.31957","0.13578"
"24688","148.09200","12.34116","0.13609"
"24731","148.35000","12.36268","0.13568"
"24774","148.60800","12.38409","0.13642"
"24817","148.86600","12.40567","0.13556"
"24860","149.12400","12.42707","0.13567"
"24903","149.38200","12.44866","0.13596"
"24946","149.64000","12.47012","0.13587"
"24989","149.89800","12.49165","0.13586"
"25032","150.15600","12.51305","0.13604"
"25075","150.41400","12.53464","0.13593"
"25118","150.67200","12.55604","0.13569"
"25161","150.93000","12.57763","0.13527"
"25204","151.18800","12.59909","0.13565"
"25247","151.44600","12.62061","0.13608"
"25290","151.70400","12.64214","0.13608"
"25333","151.96200","12.66366","0.13587"
"25376","152.22000","12.68513","0.13612"
"25419","152.47800","12.70659","0.13665"
"25462","152.73600","12.72806","0.13536"
"25505","152.99400","12.74964","0.13637"
"25548","153.25200","12.77110","0.13646"
"25591","153.51000","12.79263","0.13609"
"25634","153.76800","12.81409","0.13550"
"25677","154.02600","12.83556","0.13596"
"25720","154.28400","12.85708","0.13635"
"25763","154.54200","12.87861","0.13592"
"25806","154.80000","12.90013","0.13546"
"25849","155.05800","12.92159","0.13587"
"25892","155.31600","12.94312","0.13496"
"25935","155.57400","12.96458","0.13578"
"25978","155.83200","12.98611","0.13590"
"26021","156.09000","13.00757","0.13583"
"26064","156.34800","13.02910","0.13553"
"26107","156.60600","13.05056","0.13623"
"26150","156.86400","13.07215","0.13616"
"26193","157.12200","13.09355","0.13620"
"26236","157.38000","13.11513","0.13616"
"26279","157.63800","13.13660","0.13625"
"26322","157.89600","13.15812","0.13636"
"26365","158.15400","13.17959","0.13590"
"26408","158.41200","13.20117","0.13621"
"26451","158.67000","13.22257","0.13603"
"26494","158.92800","13.24410","0.13597"
"26537","159.18600","13.26556","0.13532"
"26580","159.44400","13.28715","0.13533"
"26623","159.70200","13.30867","0.13495"
"26666","159.96000","13.33014","0.13439"
"26709","160.21800","13.35166","0.13524"
"26752","160.47600","13.37313","0.13510"
"26795","160.73400","13.39465","0.13562"
"26838","160.99200","13.41611","0.13561"
"26881","161.25000","13.43764","0.13536"
"26924","161.50800","13.45904","0.13539"
"26967","161.76600","13.48063","0.13602"
"27010","162.02400","13.50203","0.13580"
"27053","162.28200","13.52361","0.13502"
"27096","162.54000","13.54508","0.13523"
"27139","162.79800","13.56660","0.13605"
"27182","163.05600","13.58807","0.13672"
"27225","163.31400","13.60959","0.13601"
"27268","163.57200","13.63112","0.13574"
"27311","163.83000","13.65264","0.13581"
"27354","164.08800","13.67405","0.13666"
"27397","164.34600","13.69563","0.13620"
"27440","164.60400","13.71709","0.13666"
"27483","164.86200","13.73868","0.13657"
"27526","165.12000","13.76008","0.13608"
"27569","165.37800","13.78161","0.13717"
"27612","165.63600","13.80313","0.13672"
"27655","165.89400","13.82465","0.13673"
"27698","166.15200","13.84612","0.13621"
"27741","166.41000","13.86764","0.13697"
"27784","166.66800","13.88911","0.13706"
"27827","166.92600","13.91057","0.13672"
"27870","167.18400","13.93210","0.13672"
"27913","167.44200","13.95362","0.13656"
"27956","167.70000","13.97515","0.13714"
"27999","167.95800","13.99661","0.13686"
"28042","168.21600","14.01819","0.13711"
"28085","168.47400","14.03960","0.13776"
"28128","168.73200","14.06112","0.13699"
"28171","168.99000","14.08259","0.13721"
"28214","169.24800","14.10411","0.13756"
"28257","169.50600","14.12558","0.13783"
"28300","169.76400","14.14710","0.13710"
"28343","170.02200","14.16862","0.13722"
"28386","170.28000","14.19015","0.13758"
"28429","170.53800","14.21155","0.13782"
"28472","170.79600","14.23314","0.13757"
"28515","171.05400","14.25460","0.13753"
"28558","171.31200","14.27619","0.13844"
"28601","171.57000","14.29759","0.13869"
"28644","171.82800","14.31911","0.13792"
"28687","172.08600","14.34058","0.13843"
"28730","172.34400","14.36210","0.13753"
"28773","172.60200","14.38369","0.13772"
"28816","172.86000","14.40515","0.13796"
"28859","173.11800","14.42662","0.13882"
"28902","173.37600","14.44814","0.13830"
"28945","173.63400","14.46960","0.13811"
"28988","173.89200","14.49113","0.13843"
"29031","174.15000","14.51265","0.13819"
"29074","174.40800","14.53406","0.13807"
"29117","174.66600","14.55564","0.13837"
"29160","174.92400","14.57705","0.13877"
"29203","175.18200","14.59869","0.13853"
"29246","175.44000","14.62004","0.13906"
"29289","175.69800","14.64162","0.13885"
"29332","175.95600","14.66308","0.13886"
"29375","176.21400","14.68461","0.13907"
"29418","176.47200","14.70613","0.13908"
"29461","176.73000","14.72760","0.13982"
"29504","176.98800","14.74912","0.13926"
"29547","177.24600","14.77065","0.14029"
"29590","177.50400","14.79211","0.14027"
"29633","177.76200","14.81363","0.14020"
"29676","178.02000","14.83510","0.13954"
"29719","178.27800","14.85662","0.14016"
"29762","178.53600","14.87809","0.14064"
"29805","178.79400","14.89967","0.14078"
"29848","179.05200","14.92114","0.14124"
"29891","179.31000","14.94260","0.14005"
"29934","179.56800","14.96406","0.14108"
"29977","179.82600","14.98559","0.14127"
"30020","180.08400","15.00711","0.14083"
"30063","180.34200","15.02864","0.14142"
"30106","180.60000","15.05010","0.14174"
"30149","180.85800","15.07157","0.14187"
"30192","181.11600","15.09315","0.14206"
"30235","181.37400","15.11456","0.14306"
"30278","181.63200","15.13614","0.14282"
"30321","181.89000","15.15754","0.14332"
"30364","182.14800","15.17913","0.14329"
"30407","182.40600","15.20053","0.14351"
"30450","182.66400","15.22218","0.14444"
"30493","182.92200","15.24358","0.14408"
"30536","183.18000","15.26517","0.14506"
"30579","183.43800","15.28657","0.14496"
"30622","183.69600","15.30815","0.14501"
"30665","183.95400","15.32962","0.14612"
"30708","184.21200","15.35114","0.14647"
"30751","184.47000","15.37255","0.14227"
"30794","184.72800","15.39413","0.14312"
"30837","184.98600","15.41566","0.14319"
"30880","185.24400","15.43706","0.14332"
"30923","185.50200","15.45864","0.14373"
"30966","185.76000","15.48011","0.14402"
"31009","186.01800","15.50163","0.14491"
"31052","186.27600","15.52310","0.14417"
"31095","186.53400","15.54462","0.13517"
"31138","186.79200","15.56609","0.13623"
"31181","187.05000","15.58761","0.13512"
"31224","187.30800","15.60907","0.13595"
"31267","187.56600","15.63060","0.13461"
"31310","187.82400","15.65212","0.13623"
"31353","188.08200","15.67365","0.13480"
"31396","188.34000","15.69511","0.13544"
"31439","188.59800","15.71663","0.13650"
"31482","188.85600","15.73810","0.13639"
"31525","189.11400","15.75962","0.13611"
"31568","189.37200","15.78109","0.13617"
"31611","189.63000","15.80261","0.13646"
"31654","189.88800","15.82408","0.13572"
"31697","190.14600","15.84560","0.13743"
"31740","190.40400","15.86713","0.13702"
"31783","190.66200","15.88865","0.13723"
"31826","190.92000","15.91005","0.13750"
"31869","191.17800","15.93164","0.13894"
"31912","191.43600","15.95316","0.13757"
"31955","191.69400","15.97463","0.13931"
"31998","191.95200","15.99615","0.13802"
"32041","192.21000","16.01756","0.13913"
"32084","192.46800","16.03914","0.13828"
"32127","192.72600","16.06054","0.13928"
"32170","192.98400","16.08213","0.13836"
"32213","193.24200","16.10359","0.13922"
"32256","193.50000","16.12512","0.13876"
"32299","193.75800","16.14652","0.14077"
"32342","194.01600","16.16817","0.14035"
"32385","194.27400","16.18957","0.14091"
"32428","194.53200","16.21115","0.14068"
"32471","194.79000","16.23262","0.14230"
"32514","195.04800","16.25408","0.14177"
"32557","195.30600","16.27561","0.14296"
"32600","195.56400","16.29719","0.14293"
"32643","195.82200","16.31860","0.14342"
"32686","196.08000","16.34012","0.14370"
"32729","196.33800","16.36164","0.14431"
"32772","196.59600","16.38317","0.14395"
"32815","196.85400","16.40463","0.14520"
"32858","197.11200","16.42610","0.14496"
"32901","197.37000","16.44756","0.14576"
"32944","197.62800","16.46909","0.14595"
"32987","197.88600","16.49061","0.14647"
"33030","198.14400","16.51213","0.14698"
"33073","198.40200","16.53366","0.14770"
"33116","198.66000","16.55512","0.14782"
"33159","198.91800","16.57659","0.14702"
"33202","199.17600","16.59811","0.14789"
"33245","199.43400","16.61964","0.14771"
"33288","199.69200","16.64104","0.14924"
"33331","199.95000","16.66263","0.14887"
"33374","200.20800","16.68403","0.15027"
"33417","200.46600","16.70561","0.15011"
"33460","200.72400","16.72708","0.15130"
"33503","200.98200","16.74866","0.15204"
"33546","201.24000","16.77007","0.15256"
"33589","201.49800","16.79159","0.15297"
"33632","201.75600","16.81306","0.15366"
"33675","202.01400","16.83464","0.15427"
"33718","202.27200","16.85610","0.15452"
"33761","202.53000","16.87763","0.15599"
"33804","202.78800","16.89909","0.15613"
"33847","203.04600","16.92068","0.15592"
"33890","203.30400","16.94214","0.15649"
"33933","203.56200","16.96360","0.15495"
"33976","203.82000","16.98507","0.13393"
"34019","204.07800","17.00660","0.13338"
"34062","204.33600","17.02812","0.13305"
"34105","204.59400","17.04958","0.13583"
"34148","204.85200","17.07111","0.13388"
"34191","205.11000","17.09257","0.13632"
"34234","205.36800","17.11410","0.13665"
"34277","205.62600","17.13562","0.13578"
"34320","205.88400","17.15709","0.13621"
"34363","206.14200","17.17855","0.13934"
"34406","206.40000","17.20007","0.13468"
"34449","206.65800","17.22160","0.13823"
"34492","206.91600","17.24312","0.13737"
"34535","207.17400","17.26459","0.13757"
"34578","207.43200","17.28611","0.13571"
"34621","207.69000","17.30758","0.13784"
"34664","207.94800","17.32910","0.13536"
"34707","208.20600","17.35056","0.13897"
"34750","208.46400","17.37221","0.13717"
"34793","208.72200","17.39355","0.13783"
"34836","208.98000","17.41514","0.13906"
"34879","209.23800","17.43660","0.13916"
"34922","209.49600","17.45812","0.13892"
"34965","209.75400","17.47959","0.13943"
"35008","210.01200","17.50111","0.14080"
"35051","210.27000","17.52264","0.13991"
"35094","210.52800","17.54410","0.14175"
"35137","210.78600","17.56569","0.14125"
"35180","211.04400","17.58715","0.14134"
"35223","211.30200","17.60861","0.14296"
"35266","211.56000","17.63008","0.14195"
"35309","211.81800","17.65166","0.14366"
"35352","212.07600","17.67307","0.14297"
"35395","212.33400","17.69465","0.14328"
"35438","212.59200","17.71600","0.14555"
"35481","212.85000","17.73758","0.14483"
"35524","213.10800","17.75904","0.14642"
"35567","213.36600","17.78063","0.14676"
"35610","213.62400","17.80210","0.14660"
"35653","213.88200","17.82362","0.14739"
"35696","214.14000","17.84508","0.14845"
"35739","214.39800","17.86661","0.14799"
"35782","214.65600","17.88807","0.14976"
"35825","214.91400","17.90965","0.15016"
"35868","215.17200","17.93106","0.15014"
"35911","215.43000","17.95264","0.15094"
"35954","215.68800","17.97411","0.15134"
"35997","215.94600","17.99569","0.15199"
"36040","216.20400","18.01716","0.15180"
"36083","216.46200","18.03862","0.15245"
"36126","216.72000","18.06009","0.15381"
"36169","216.97800","18.08161","0.15381"
"36212","217.23600","18.10313","0.15478"
"36255","217.49400","18.12454","0.15539"
"36298","217.75200","18.14612","0.15583"
"36341","218.01000","18.16753","0.15620"
"36384","218.26800","18.18911","0.15748"
"36427","218.52600","18.21064","0.15722"
"36470","218.78400","18.23216","0.15834"
"36513","219.04200","18.25356","0.15879"
"36556","219.30000","18.27509","0.15874"
"36599","219.55800","18.29655","0.16038"
"36642","219.81600","18.31814","0.15997"
"36685","220.07400","18.33960","0.16012"
"36728","220.33200","18.36113","0.16079"
"36771","220.59000","18.38259","0.16137"
"36814","220.84800","18.40412","0.16219"
"36857","221.10600","18.42558","0.16306"
"36900","221.36400","18.44716","0.16302"
"36943","221.62200","18.46863","0.16357"
"36986","221.88000","18.49015","0.16376"
"37029","222.13800","18.51162","0.16463"
"37072","222.39600","18.53308","0.16528"
"37115","222.65400","18.55461","0.16480"
"37158","222.91200","18.57607","0.16576"
"37201","223.17000","18.59759","0.16648"
"37244","223.42800","18.61918","0.16650"
"37287","223.68600","18.64070","0.16736"
"37330","223.94400","18.66211","0.16747"
"37373","224.20200","18.68363","0.16812"
"37416","224.46000","18.70510","0.16874"
"37459","224.71800","18.72662","0.16900"
"37502","224.97600","18.74809","0.16913"
"37545","225.23400","18.76961","0.16955"
"37588","225.49200","18.79101","0.16983"
"37631","225.75000","18.81260","0.17034"
"37674","226.00800","18.83406","0.17065"
"37717","226.26600","18.85571","0.17109"
"37760","226.52400","18.87711","0.17136"
"37803","226.78200","18.89863","0.17204"
"37846","227.04000","18.92010","0.17198"
"37889","227.29800","18.94162","0.17259"
"37932","227.55600","18.96309","0.17273"
"37975","227.81400","18.98461","0.17310"
"38018","228.07200","19.00607","0.17365"
"38061","228.33000","19.02760","0.17390"
"38104","228.58800","19.04913","0.17441"
"38147","228.84600","19.07059","0.17481"
"38190","229.10400","19.09211","0.17486"
"38233","229.36200","19.11364","0.17559"
"38276","229.62000","19.13516","0.17603"
"38319","229.87800","19.15663","0.17673"
"38362","230.13600","19.17815","0.17701"
"38405","230.39400","19.19962","0.17785"
"38448","230.65200","19.22114","0.17865"
"38491","230.91000","19.24260","0.17896"
"38534","231.16800","19.26419","0.17967"
"38577","231.42600","19.28559","0.18025"
"38620","231.68400","19.30712","0.18099"
"38663","231.94200","19.32852","0.18174"
"38706","232.20000","19.35011","0.18252"
"38749","232.45800","19.37163","0.18307"
"38792","232.71600","19.39309","0.18236"
"38835","232.97400","19.41456","0.18303"
"38878","233.23200","19.43614","0.18333"
"38921","233.49000","19.45755","0.18465"
"38964","233.74800","19.47919","0.18498"
"39007","234.00600","19.50060","0.18648"
"39050","234.26400","19.52212","0.18706"
"39093","234.52200","19.54358","0.18771"
"39136","234.78000","19.56517","0.18875"
"39179","235.03800","19.58663","0.18917"
"39222","235.29600","19.60816","0.19079"
"39265","235.55400","19.62962","0.19122"
"39308","235.81200","19.65103","0.19286"
"39351","236.07000","19.67261","0.19337"
"39394","236.32800","19.69413","0.19462"
"39437","236.58600","19.71566","0.19505"
"39480","236.84400","19.73706","0.19626"
"39523","237.10200","19.75865","0.19694"
"39566","237.36000","19.78005","0.19777"
"39609","237.61800","19.80163","0.19908"
"39652","237.87600","19.82304","0.20027"
"39695","238.13400","19.84462","0.20144"
"39738","238.39200","19.86609","0.20189"
"39781","238.65000","19.88761","0.20339"
"39824","238.90800","19.90908","0.20411"
"39867","239.16600","19.93066","0.20440"
"39910","239.42400","19.95207","0.20604"
"39953","239.68200","19.97365","0.20634"
"39996","239.94000","19.99512","0.20804"
"40039","240.19800","20.01664","0.20839"
"40082","240.45600","20.03810","0.20955"
"40125","240.71400","20.05963","0.21033"
"40168","240.97200","20.08103","0.21106"
"40211","241.23000","20.10262","0.21180"
"40254","241.48800","20.12414","0.21230"
"40297","241.74600","20.14561","0.21352"
"40340","242.00400","20.16713","0.21508"
"40383","242.26200","20.18865","0.21509"
"40426","242.52000","20.21012","0.21633"
"40469","242.77800","20.23164","0.21708"
"40512","243.03600","20.25317","0.21769"
"40555","243.29400","20.27457","0.21832"
"40598","243.55200","20.29609","0.21889"
"40641","243.81000","20.31756","0.21954"
"40684","244.06800","20.33920","0.21977"
"40727","244.32600","20.36055","0.22020"
"40770","244.58400","20.38207","0.22098"
"40813","244.84200","20.40354","0.22146"
"40856","245.10000","20.42512","0.22162"
"40899","245.35800","20.44658","0.22199"
"40942","245.61600","20.46811","0.22283"
"40985","245.87400","20.48964","0.22259"
"41028","246.13200","20.51116","0.22348"
"41071","246.39000","20.53262","0.22396"
"41114","246.64800","20.55409","0.22507"
"41157","246.90600","20.57561","0.22557"
"41200","247.16400","20.59713","0.22597"
"41243","247.42200","20.61860","0.22715"
"41286","247.68000","20.64012","0.22768"
"41329","247.93800","20.66165","0.22847"
"41372","248.19600","20.68305","0.22942"
"41415","248.45400","20.70458","0.23054"
"41458","248.71200","20.72604","0.23198"
"41501","248.97000","20.74757","0.23268"
"41544","249.22800","20.76909","0.23370"
"41587","249.48600","20.79062","0.23443"
"41630","249.74400","20.81208","0.23599"
"41673","250.00200","20.83366","0.23761"
"41716","250.26000","20.85507","0.23860"
"41759","250.51800","20.87665","0.23995"
"41802","250.77600","20.89806","0.24086"
"41845","251.03400","20.91958","0.24183"
"41888","251.29200","20.94105","0.24346"
"41931","251.55000","20.96263","0.24460"
"41974","251.80800","20.98415","0.24531"
"42017","252.06600","21.00567","0.24641"
"42060","252.32400","21.02708","0.24773"
"42103","252.58200","21.04866","0.24771"
"42146","252.84000","21.07013","0.24942"
"42189","253.09800","21.09166","0.25009"
"42232","253.35600","21.11312","0.25082"
"42275","253.61400","21.13464","0.25199"
"42318","253.87200","21.15611","0.25266"
"42361","254.13000","21.17757","0.25352"
"42404","254.38800","21.19916","0.25484"
"42447","254.64600","21.22062","0.25556"
"42490","254.90400","21.24215","0.25603"
"42533","255.16200","21.26361","0.25714"
"42576","255.42000","21.28513","0.25756"
"42619","255.67800","21.30666","0.25826"
"42662","255.93600","21.32812","0.25915"
"42705","256.19400","21.34953","0.26001"
"42748","256.45200","21.37111","0.26068"
"42791","256.71000","21.39257","0.26092"
"42834","256.96800","21.41416","0.26167"
"42877","257.22600","21.43556","0.26235"
"42920","257.48400","21.45709","0.26263"
"42963","257.74200","21.47861","0.26305"
"43006","258.00000","21.50014","0.26355"
"43049","258.25800","21.52160","0.26451"
"43092","258.51600","21.54313","0.26470"
"43135","258.77400","21.56465","0.26530"
"43178","259.03200","21.58617","0.26638"
"43221","259.29000","21.60764","0.26634"
"43264","259.54800","21.62916","0.26680"
"43307","259.80600","21.65057","0.26752"
"43350","260.06400","21.67209","0.26831"
"43393","260.32200","21.69361","0.26869"
"43436","260.58000","21.71514","0.26906"
"43479","260.83800","21.73666","0.26925"
"43522","261.09600","21.75807","0.26915"
"43565","261.35400","21.77959","0.12964"
"43608","261.61200","21.80112","0.13931"
"43651","261.87000","21.82264","0.14207"
"43694","262.12800","21.84411","0.14047"
"43737","262.38600","21.86563","0.13792"
"43780","262.64400","21.88703","0.14538"
"43823","262.90200","21.90862","0.13686"
"43866","263.16000","21.93008","0.14509"
"43909","263.41800","21.95167","0.13803"
"43952","263.67600","21.97307","0.14458"
"43995","263.93400","21.99454","0.14039"
"44038","264.19200","22.01606","0.14202"
"44081","264.45000","22.03770","0.14320"
"44124","264.70800","22.05911","0.14116"
"44167","264.96600","22.08063","0.14395"
"44210","265.22400","22.10210","0.14133"
"44253","265.48200","22.12362","0.14520"
"44296","265.74000","22.14515","0.14202"
"44339","265.99800","22.16661","0.14446"
"44382","266.25600","22.18807","0.14411"
"44425","266.51400","22.20966","0.14316"
"44468","266.77200","22.23112","0.14611"
"44511","267.03000","22.25259","0.14300"
"44554","267.28800","22.27411","0.14645"
"44597","267.54600","22.29558","0.14439"
"44640","267.80400","22.31710","0.14478"
"44683","268.06200","22.33862","0.14668"
"44726","268.32000","22.36015","0.14434"
"44769","268.57800","22.38161","0.14788"
"44812","268.83600","22.40314","0.14568"
"44855","269.09400","22.42460","0.14748"
"44898","269.35200","22.44613","0.14864"
"44941","269.61000","22.46759","0.14643"
"44984","269.86800","22.48918","0.14878"
"45027","270.12600","22.51058","0.14825"
"45070","270.38400","22.53217","0.14831"
"45113","270.64200","22.55357","0.15058"
"45156","270.90000","22.57509","0.14857"
"45199","271.15800","22.59656","0.14990"
"45242","271.41600","22.61808","0.15227"
"45285","271.67400","22.63961","0.14936"
"45328","271.93200","22.66113","0.15241"
"45371","272.19000","22.68259","0.15254"
"45414","272.44800","22.70412","0.15169"
"45457","272.70600","22.72558","0.15425"
"45500","272.96400","22.74711","0.15310"
"45543","273.22200","22.76863","0.15375"
"45586","273.48000","22.79010","0.15485"
"45629","273.73800","22.81162","0.15472"
"45672","273.99600","22.83308","0.15446"
"45715","274.25400","22.85467","0.15629"
"45758","274.51200","22.87607","0.15674"
"45801","274.77000","22.89766","0.15573"
"45844","275.02800","22.91912","0.15847"
"45887","275.28600","22.94059","0.15864"
"45930","275.54400","22.96205","0.15822"
"45973","275.80200","22.98363","0.15860"
"46016","276.06000","23.00510","0.15960"
"46059","276.31800","23.02662","0.16026"
"46102","276.57600","23.04803","0.16046"
"46145","276.83400","23.06967","0.16093"
"46188","277.09200","23.09108","0.16227"
"46231","277.35000","23.11266","0.16207"
"46274","277.60800","23.13406","0.16210"
"46317","277.86600","23.15565","0.16362"
"46360","278.12400","23.17711","0.16384"
"46403","278.38200","23.19864","0.16282"
"46446","278.64000","23.22010","0.16464"
"46489","278.89800","23.24157","0.16464"
"46532","279.15600","23.26309","0.16588"
"46575","279.41400","23.28461","0.16598"
"46618","279.67200","23.30614","0.16591"
"46661","279.93000","23.32766","0.16754"
"46704","280.18800","23.34913","0.16675"
"46747","280.44600","23.37059","0.16767"
"46790","280.70400","23.39211","0.16813"
"46833","280.96200","23.41364","0.16782"
"46876","281.22000","23.43517","0.16958"
"46919","281.47800","23.45651","0.16880"
"46962","281.73600","23.47815","0.16938"
"47005","281.99400","23.49956","0.17017"
"47048","282.25200","23.52108","0.16985"
"47091","282.51000","23.54255","0.17174"
"47134","282.76800","23.56413","0.17125"
"47177","283.02600","23.58560","0.17168"
"47220","283.28400","23.60712","0.17272"
"47263","283.54200","23.62859","0.17218"
"47306","283.80000","23.65017","0.17399"
"47349","284.05800","23.67157","0.17291"
"47392","284.31600","23.69310","0.17416"
"47435","284.57400","23.71456","0.17491"
"47478","284.83200","23.73615","0.17481"
"47521","285.09000","23.75767","0.17676"
"47564","285.34800","23.77913","0.17565"
"47607","285.60600","23.80060","0.17816"
"47650","285.86400","23.82212","0.17680"
"47693","286.12200","23.84365","0.17906"
"47736","286.38000","23.86511","0.17915"
"47779","286.63800","23.88664","0.17950"
"47822","286.89600","23.90804","0.18210"
"47865","287.15400","23.92963","0.18039"
"47908","287.41200","23.95109","0.18429"
"47951","287.67000","23.97261","0.18251"
"47994","287.92800","23.99408","0.18592"
"48037","288.18600","24.01560","0.18532"
"48080","288.44400","24.03707","0.18709"
"48123","288.70200","24.05865","0.18888"
"48166","288.96000","24.08012","0.18882"
"48209","289.21800","24.10164","0.19186"
"48252","289.47600","24.12310","0.19137"
"48295","289.73400","24.14463","0.19471"
"48338","289.99200","24.16609","0.19392"
"48381","290.25000","24.18768","0.19604"
"48424","290.50800","24.20908","0.19743"
"48467","290.76600","24.23067","0.19811"
"48510","291.02400","24.25213","0.20021"
"48553","291.28200","24.27365","0.19983"
"48596","291.54000","24.29518","0.20342"
"48639","291.79800","24.31664","0.20265"
"48682","292.05600","24.33805","0.20577"
"48725","292.31400","24.35957","0.20512"
"48768","292.57200","24.38116","0.20770"
"48811","292.83000","24.40262","0.20765"
"48854","293.08800","24.42408","0.21006"
"48897","293.34600","24.44561","0.21065"
"48940","293.60400","24.46713","0.21193"
"48983","293.86200","24.48860","0.21331"
"49026","294.12000","24.51012","0.21392"
"49069","294.37800","24.53152","0.21546"
"49112","294.63600","24.55311","0.21612"
"49155","294.89400","24.57458","0.21806"
"49198","295.15200","24.59616","0.21788"
"49241","295.41000","24.61756","0.21958"
"49284","295.66800","24.63909","0.21901"
"49327","295.92600","24.66055","0.22036"
"49370","296.18400","24.68213","0.22072"
"49413","296.44200","24.70360","0.22164"
"49456","296.70000","24.72512","0.22187"
"49499","296.95800","24.74659","0.22275"
"49542","297.21600","24.76811","0.22308"
"49585","297.47400","24.78958","0.22388"
"49628","297.73200","24.81110","0.22455"
"49671","297.99000","24.83263","0.22561"
"49714","298.24800","24.85409","0.22705"
"49757","298.50600","24.87561","0.22766"
"49800","298.76400","24.89708","0.22870"
"49843","299.02200","24.91860","0.23019"
"49886","299.28000","24.94013","0.23135"
"49929","299.53800","24.96159","0.23225"
"49972","299.79600","24.98306","0.23466"
"50015","300.05400","25.00464","0.23613"
"50058","300.31200","25.02611","0.23743"
"50101","300.57000","25.04757","0.23841"
"50144","300.82800","25.06903","0.23990"
"50187","301.08600","25.09062","0.24139"
"50230","301.34400","25.11208","0.24305"
"50273","301.60200","25.13361","0.24347"
"50316","301.86000","25.15507","0.24568"
"50359","302.11800","25.17659","0.24663"
"50402","302.37600","25.19812","0.24808"
"50445","302.63400","25.21964","0.24899"
"50488","302.89200","25.24111","0.25057"
"50531","303.15000","25.26263","0.25156"
"50574","303.40800","25.28410","0.25213"
"50617","303.66600","25.30562","0.25338"
"50660","303.92400","25.32715","0.25425"
"50703","304.18200","25.34867","0.25493"
"50746","304.44000","25.37013","0.25594"
"50789","304.69800","25.39160","0.25669"
"50832","304.95600","25.41312","0.25760"
"50875","305.21400","25.43459","0.25848"
"50918","305.47200","25.45617","0.25869"
"50961","305.73000","25.47758","0.25979"
"51004","305.98800","25.49910","0.26064"
"51047","306.24600","25.52057","0.26105"
"51090","306.50400","25.54215","0.26167"
"51133","306.76200","25.56361","0.26256"
"51176","307.02000","25.58513","0.26273"
"51219","307.27800","25.60654","0.26376"
"51262","307.53600","25.62807","0.26417"
"51305","307.79400","25.64959","0.26479"
"51348","308.05200","25.67112","0.26497"
"51391","308.31000","25.69258","0.26562"
"51434","308.56800","25.71411","0.26618"
"51477","308.82600","25.73557","0.26689"
"51520","309.08400","25.75715","0.26686"
"51563","309.34200","25.77856","0.26763"
"51606","309.60000","25.80014","0.26841"
"51649","309.85800","25.82154","0.26850"
"51692","310.11600","25.84313","0.26933"
"51735","310.37400","25.86459","0.27039"
"51778","310.63200","25.88612","0.27020"
"51821","310.89000","25.90764","0.27127"
"51864","311.14800","25.92911","0.27189"
"51907","311.40600","25.95063","0.27233"
"51950","311.66400","25.97209","0.27356"
"51993","311.92200","25.99368","0.27448"
"52036","312.18000","26.01508","0.12023"
"52079","312.43800","26.03661","0.13257"
"52122","312.69600","26.05801","0.13589"
"52165","312.95400","26.07966","0.13361"
"52208","313.21200","26.10112","0.13153"
"52251","313.47000","26.12265","0.13102"
"52294","313.72800","26.14405","0.13093"
"52337","313.98600","26.16557","0.13170"
"52380","314.24400","26.18704","0.13110"
"52423","314.50200","26.20862","0.13237"
"52466","314.76000","26.23009","0.13150"
"52509","315.01800","26.25161","0.13156"
"52552","315.27600","26.27308","0.13102"
"52570","315.38000","26.28175","0.13106"