File: Trajectories_together/170226_1Specimen_RawData_5.csv
"","V1","V2","V3"
"1","End date","2/26/2017",""
"2","Specimen label","4BG_28",""
"3","Maximum Load","0.36069","N"
"4","Time","Extension","Load"
"5","(s)","(mm)","(N)"
"6","0.00000","16.07627","0.02036"
"58","0.31200","16.10168","0.02105"
"110","0.62400","16.12841","0.02168"
"162","0.93600","16.15441","0.02303"
"214","1.24800","16.18042","0.02381"
"266","1.56000","16.20637","0.02473"
"318","1.87200","16.23244","0.02542"
"370","2.18400","16.25839","0.02613"
"422","2.49600","16.28440","0.02729"
"474","2.80800","16.31034","0.02745"
"526","3.12000","16.33635","0.02818"
"578","3.43200","16.36242","0.02838"
"630","3.74400","16.38843","0.02939"
"682","4.05600","16.41444","0.03026"
"734","4.36800","16.44039","0.02964"
"786","4.68000","16.46640","0.03058"
"838","4.99200","16.49240","0.03194"
"890","5.30400","16.51835","0.03198"
"942","5.61600","16.54442","0.03241"
"994","5.92800","16.57037","0.03320"
"1046","6.24000","16.59638","0.03409"
"1098","6.55200","16.62233","0.03414"
"1150","6.86400","16.64840","0.03427"
"1202","7.17600","16.67446","0.03439"
"1254","7.48800","16.70035","0.03567"
"1306","7.80000","16.72642","0.03471"
"1358","8.11200","16.75231","0.03638"
"1410","8.42400","16.77838","0.03760"
"1462","8.73600","16.80433","0.03769"
"1514","9.04800","16.83039","0.03592"
"1566","9.36000","16.85640","0.03559"
"1618","9.67200","16.88235","0.03773"
"1670","9.98400","16.90836","0.03784"
"1722","10.29600","16.93431","0.03896"
"1774","10.60800","16.96038","0.03927"
"1826","10.92000","16.98639","0.04021"
"1878","11.23200","17.01239","0.04013"
"1930","11.54400","17.03834","0.04148"
"1982","11.85600","17.06429","0.04089"
"2034","12.16800","17.09036","0.04189"
"2086","12.48000","17.11637","0.04261"
"2138","12.79200","17.14238","0.04259"
"2190","13.10400","17.16838","0.04282"
"2242","13.41600","17.19433","0.04174"
"2294","13.72800","17.22034","0.04241"
"2346","14.04000","17.24635","0.04232"
"2398","14.35200","17.27242","0.04226"
"2450","14.66400","17.29843","0.04246"
"2502","14.97600","17.32438","0.04355"
"2554","15.28800","17.35044","0.04375"
"2606","15.60000","17.37633","0.04421"
"2658","15.91200","17.40240","0.04333"
"2710","16.22400","17.42835","0.04368"
"2762","16.53600","17.45442","0.04418"
"2814","16.84800","17.48037","0.04489"
"2866","17.16000","17.50638","0.04495"
"2918","17.47200","17.53238","0.04535"
"2970","17.78400","17.55833","0.04554"
"3022","18.09600","17.58440","0.04586"
"3074","18.40800","17.61035","0.04594"
"3126","18.72000","17.63642","0.04646"
"3178","19.03200","17.66237","0.04629"
"3230","19.34400","17.68831","0.04716"
"3282","19.65600","17.71438","0.04687"
"3334","19.96800","17.74039","0.04736"
"3386","20.28000","17.76640","0.04774"
"3438","20.59200","17.79241","0.04821"
"3490","20.90400","17.81836","0.04871"
"3542","21.21600","17.84443","0.04860"
"3594","21.52800","17.87037","0.04887"
"3646","21.84000","17.89644","0.04898"
"3698","22.15200","17.92233","0.04922"
"3750","22.46400","17.94834","0.04919"
"3802","22.77600","17.97435","0.04990"
"3854","23.08800","18.00036","0.05021"
"3906","23.40000","18.02642","0.05038"
"3958","23.71200","18.05231","0.05067"
"4010","24.02400","18.07844","0.05048"
"4062","24.33600","18.10439","0.05074"
"4114","24.64800","18.13040","0.05089"
"4166","24.96000","18.15641","0.05121"
"4218","25.27200","18.18236","0.05133"
"4270","25.58400","18.20836","0.05149"
"4322","25.89600","18.23431","0.05168"
"4374","26.20800","18.26038","0.05122"
"4426","26.52000","18.28639","0.05128"
"4478","26.83200","18.31240","0.05188"
"4530","27.14400","18.33847","0.05182"
"4582","27.45600","18.36436","0.05219"
"4634","27.76800","18.39036","0.05249"
"4686","28.08000","18.41631","0.05217"
"4738","28.39200","18.44238","0.05240"
"4790","28.70400","18.46839","0.05236"
"4842","29.01600","18.49440","0.05218"
"4894","29.32800","18.52040","0.05189"
"4946","29.64000","18.54635","0.05258"
"4998","29.95200","18.57236","0.05280"
"5050","30.26400","18.59837","0.05296"
"5102","30.57600","18.62438","0.05329"
"5154","30.88800","18.65045","0.05361"
"5206","31.20000","18.67634","0.05387"
"5258","31.51200","18.70234","0.05412"
"5310","31.82400","18.72835","0.05436"
"5362","32.13600","18.75442","0.05466"
"5414","32.44800","18.78043","0.05506"
"5466","32.76000","18.80638","0.05548"
"5518","33.07200","18.83239","0.05614"
"5570","33.38400","18.85834","0.05634"
"5622","33.69600","18.88440","0.05642"
"5674","34.00800","18.91041","0.05611"
"5726","34.32000","18.93648","0.03518"
"5778","34.63200","18.96243","0.03522"
"5830","34.94400","18.98832","0.03668"
"5882","35.25600","19.01439","0.04080"
"5934","35.56800","19.04033","0.03714"
"5986","35.88000","19.06640","0.03969"
"6038","36.19200","19.09235","0.04059"
"6090","36.50400","19.11836","0.04070"
"6142","36.81600","19.14443","0.04281"
"6194","37.12800","19.17038","0.04211"
"6246","37.44000","19.19639","0.04353"
"6298","37.75200","19.22234","0.04300"
"6350","38.06400","19.24840","0.04388"
"6402","38.37600","19.27435","0.04494"
"6454","38.68800","19.30030","0.04488"
"6506","39.00000","19.32637","0.04550"
"6558","39.31200","19.35238","0.04553"
"6610","39.62400","19.37839","0.04620"
"6662","39.93600","19.40439","0.04666"
"6714","40.24800","19.43034","0.04706"
"6766","40.56000","19.45635","0.04718"
"6818","40.87200","19.48230","0.04701"
"6870","41.18400","19.50837","0.04778"
"6922","41.49600","19.53432","0.04808"
"6974","41.80800","19.56038","0.04797"
"7026","42.12000","19.58639","0.04574"
"7078","42.43200","19.61234","0.04570"
"7130","42.74400","19.63841","0.04601"
"7182","43.05600","19.66436","0.04639"
"7234","43.36800","19.69043","0.04659"
"7286","43.68000","19.71631","0.04716"
"7338","43.99200","19.74238","0.04729"
"7390","44.30400","19.76839","0.04714"
"7442","44.61600","19.79434","0.04742"
"7494","44.92800","19.82041","0.04794"
"7546","45.24000","19.84636","0.04815"
"7598","45.55200","19.87243","0.04836"
"7650","45.86400","19.89837","0.04829"
"7702","46.17600","19.92432","0.04839"
"7754","46.48800","19.95039","0.04850"
"7806","46.80000","19.97640","0.04943"
"7858","47.11200","20.00241","0.04933"
"7910","47.42400","20.02836","0.04965"
"7962","47.73600","20.05437","0.04971"
"8014","48.04800","20.08037","0.04979"
"8066","48.36000","20.10638","0.04994"
"8118","48.67200","20.13245","0.04980"
"8170","48.98400","20.15834","0.05025"
"8222","49.29600","20.18441","0.05041"
"8274","49.60800","20.21036","0.05026"
"8326","49.92000","20.23637","0.05043"
"8378","50.23200","20.26243","0.05086"
"8430","50.54400","20.28832","0.05090"
"8482","50.85600","20.31439","0.05082"
"8534","51.16800","20.34028","0.05139"
"8586","51.48000","20.36641","0.05140"
"8638","51.79200","20.39235","0.05192"
"8690","52.10400","20.41842","0.05205"
"8742","52.41600","20.44443","0.05211"
"8794","52.72800","20.47038","0.05260"
"8846","53.04000","20.49645","0.05249"
"8898","53.35200","20.52234","0.05257"
"8950","53.66400","20.54840","0.05282"
"9002","53.97600","20.57442","0.05323"
"9054","54.28800","20.60036","0.05343"
"9106","54.60000","20.62637","0.05344"
"9158","54.91200","20.65232","0.05393"
"9210","55.22400","20.67839","0.05458"
"9262","55.53600","20.70434","0.05425"
"9314","55.84800","20.73040","0.05510"
"9366","56.16000","20.75642","0.05496"
"9418","56.47200","20.78236","0.05554"
"9470","56.78400","20.80837","0.05528"
"9522","57.09600","20.83432","0.05599"
"9574","57.40800","20.86045","0.05653"
"9626","57.72000","20.88640","0.05657"
"9678","58.03200","20.91240","0.05716"
"9730","58.34400","20.93842","0.05717"
"9782","58.65600","20.96430","0.05726"
"9834","58.96800","20.99037","0.05754"
"9886","59.28000","21.01638","0.05828"
"9938","59.59200","21.04245","0.05818"
"9990","59.90400","21.06840","0.05879"
"10042","60.21600","21.09435","0.05915"
"10094","60.52800","21.12041","0.05870"
"10146","60.84000","21.14636","0.05936"
"10198","61.15200","21.17243","0.05920"
"10250","61.46400","21.19832","0.05969"
"10302","61.77600","21.22439","0.05965"
"10354","62.08800","21.25040","0.06009"
"10406","62.40000","21.27635","0.06075"
"10458","62.71200","21.30241","0.06040"
"10510","63.02400","21.32836","0.06021"
"10562","63.33600","21.35443","0.06109"
"10614","63.64800","21.38038","0.06181"
"10666","63.96000","21.40633","0.06189"
"10718","64.27200","21.43240","0.06245"
"10770","64.58400","21.45835","0.06280"
"10822","64.89600","21.48441","0.06325"
"10874","65.20800","21.51036","0.06352"
"10926","65.52000","21.53637","0.06403"
"10978","65.83200","21.56244","0.06433"
"11030","66.14400","21.58833","0.06530"
"11082","66.45600","21.61440","0.06627"
"11134","66.76800","21.64034","0.06661"
"11186","67.08000","21.66641","0.06688"
"11238","67.39200","21.69236","0.06701"
"11290","67.70400","21.71837","0.06374"
"11342","68.01600","21.74444","0.06424"
"11394","68.32800","21.77038","0.06650"
"11446","68.64000","21.79639","0.06645"
"11498","68.95200","21.82228","0.06579"
"11550","69.26400","21.84835","0.06660"
"11602","69.57600","21.87436","0.06577"
"11654","69.88800","21.90037","0.06724"
"11706","70.20000","21.92638","0.06792"
"11758","70.51200","21.95238","0.06819"
"11810","70.82400","21.97839","0.06911"
"11862","71.13600","22.00434","0.06878"
"11914","71.44800","22.03035","0.06853"
"11966","71.76000","22.05642","0.06967"
"12018","72.07200","22.08243","0.06950"
"12070","72.38400","22.10838","0.06964"
"12122","72.69600","22.13433","0.07087"
"12174","73.00800","22.16039","0.07049"
"12226","73.32000","22.18640","0.07115"
"12278","73.63200","22.21235","0.07225"
"12330","73.94400","22.23842","0.07136"
"12382","74.25600","22.26431","0.07003"
"12434","74.56800","22.29037","0.07148"
"12486","74.88000","22.31632","0.07149"
"12538","75.19200","22.34239","0.07153"
"12590","75.50400","22.36846","0.07303"
"12642","75.81600","22.39435","0.07387"
"12694","76.12800","22.42042","0.07430"
"12746","76.44000","22.44631","0.07579"
"12798","76.75200","22.47237","0.07642"
"12850","77.06400","22.49838","0.07794"
"12902","77.37600","22.52439","0.07771"
"12954","77.68800","22.55040","0.07864"
"13006","78.00000","22.57641","0.07977"
"13058","78.31200","22.60242","0.08119"
"13110","78.62400","22.62831","0.08102"
"13162","78.93600","22.65443","0.08185"
"13214","79.24800","22.68038","0.08273"
"13266","79.56000","22.70633","0.08344"
"13318","79.87200","22.73240","0.08438"
"13370","80.18400","22.75835","0.08323"
"13422","80.49600","22.78442","0.08459"
"13474","80.80800","22.81036","0.08508"
"13526","81.12000","22.83637","0.08596"
"13578","81.43200","22.86238","0.08632"
"13630","81.74400","22.88839","0.08716"
"13682","82.05600","22.91440","0.08745"
"13734","82.36800","22.94035","0.08742"
"13786","82.68000","22.96642","0.08666"
"13838","82.99200","22.99236","0.08327"
"13890","83.30400","23.01837","0.08421"
"13942","83.61600","23.04438","0.08496"
"13994","83.92800","23.07033","0.08642"
"14046","84.24000","23.09640","0.08733"
"14098","84.55200","23.12235","0.08756"
"14150","84.86400","23.14842","0.08928"
"14202","85.17600","23.17436","0.08997"
"14254","85.48800","23.20037","0.09016"
"14306","85.80000","23.22644","0.09099"
"14358","86.11200","23.25233","0.09201"
"14410","86.42400","23.27846","0.09329"
"14462","86.73600","23.30435","0.09389"
"14514","87.04800","23.33035","0.09420"
"14566","87.36000","23.35636","0.09440"
"14618","87.67200","23.38237","0.09532"
"14670","87.98400","23.40844","0.09568"
"14722","88.29600","23.43433","0.09631"
"14774","88.60800","23.46040","0.09667"
"14826","88.92000","23.48641","0.09710"
"14878","89.23200","23.51235","0.09764"
"14930","89.54400","23.53842","0.09783"
"14982","89.85600","23.56437","0.09824"
"15034","90.16800","23.59038","0.09833"
"15086","90.48000","23.61639","0.09883"
"15138","90.79200","23.64240","0.09947"
"15190","91.10400","23.66841","0.10000"
"15242","91.41600","23.69435","0.10126"
"15294","91.72800","23.72042","0.10133"
"15346","92.04000","23.74637","0.10136"
"15398","92.35200","23.77238","0.10141"
"15450","92.66400","23.79839","0.10237"
"15502","92.97600","23.82440","0.10313"
"15554","93.28800","23.85046","0.10404"
"15606","93.60000","23.87635","0.10435"
"15658","93.91200","23.90236","0.10469"
"15710","94.22400","23.92837","0.10630"
"15762","94.53600","23.95438","0.10726"
"15814","94.84800","23.98038","0.10757"
"15866","95.16000","24.00640","0.10900"
"15918","95.47200","24.03240","0.11004"
"15970","95.78400","24.05835","0.11097"
"16022","96.09600","24.08442","0.11227"
"16074","96.40800","24.11037","0.11329"
"16126","96.72000","24.13638","0.11507"
"16178","97.03200","24.16238","0.11547"
"16230","97.34400","24.18833","0.11698"
"16282","97.65600","24.21434","0.11792"
"16334","97.96800","24.24029","0.11877"
"16386","98.28000","24.26642","0.12047"
"16438","98.59200","24.29237","0.12208"
"16490","98.90400","24.31838","0.12218"
"16542","99.21600","24.34445","0.12317"
"16594","99.52800","24.37033","0.12420"
"16646","99.84000","24.39634","0.12449"
"16698","100.15200","24.42235","0.12588"
"16750","100.46400","24.44842","0.12659"
"16802","100.77600","24.47437","0.12798"
"16854","101.08800","24.50038","0.12891"
"16906","101.40000","24.52638","0.12983"
"16958","101.71200","24.55233","0.12958"
"17010","102.02400","24.57840","0.13108"
"17062","102.33600","24.60435","0.13145"
"17114","102.64800","24.63042","0.13265"
"17166","102.96000","24.65636","0.13347"
"17218","103.27200","24.68238","0.13410"
"17270","103.58400","24.70838","0.13414"
"17322","103.89600","24.73433","0.13498"
"17374","104.20800","24.76046","0.13597"
"17426","104.52000","24.78635","0.13621"
"17478","104.83200","24.81236","0.13701"
"17530","105.14400","24.83837","0.13749"
"17582","105.45600","24.86438","0.13800"
"17634","105.76800","24.89038","0.13823"
"17686","106.08000","24.91639","0.13879"
"17738","106.39200","24.94240","0.14020"
"17790","106.70400","24.96841","0.14096"
"17842","107.01600","24.99436","0.14143"
"17894","107.32800","25.02036","0.14243"
"17946","107.64000","25.04638","0.14233"
"17998","107.95200","25.07244","0.14257"
"18050","108.26400","25.09833","0.14315"
"18102","108.57600","25.12434","0.14313"
"18154","108.88800","25.15035","0.14208"
"18206","109.20000","25.17636","0.14119"
"18258","109.51200","25.20236","0.14193"
"18310","109.82400","25.22831","0.14241"
"18362","110.13600","25.25444","0.14297"
"18414","110.44800","25.28039","0.14311"
"18466","110.76000","25.30634","0.14377"
"18518","111.07200","25.33247","0.14428"
"18570","111.38400","25.35841","0.14448"
"18622","111.69600","25.38436","0.14520"
"18674","112.00800","25.41031","0.14560"
"18726","112.32000","25.43638","0.14652"
"18778","112.63200","25.46233","0.14642"
"18830","112.94400","25.48834","0.14699"
"18882","113.25600","25.51440","0.14744"
"18934","113.56800","25.54036","0.14813"
"18986","113.88000","25.56642","0.14893"
"19038","114.19200","25.59237","0.14989"
"19090","114.50400","25.61838","0.15054"
"19142","114.81600","25.64445","0.15163"
"19194","115.12800","25.67034","0.15304"
"19246","115.44000","25.69640","0.15398"
"19298","115.75200","25.72229","0.15470"
"19350","116.06400","25.74836","0.15559"
"19402","116.37600","25.77443","0.15671"
"19454","116.68800","25.80044","0.15799"
"19506","117.00000","25.82645","0.15939"
"19558","117.31200","25.85234","0.16129"
"19610","117.62400","25.87840","0.16229"
"19662","117.93600","25.90435","0.16417"
"19714","118.24800","25.93042","0.16627"
"19766","118.56000","25.95643","0.16815"
"19818","118.87200","25.98238","0.16932"
"19870","119.18400","26.00833","0.17108"
"19922","119.49600","26.03428","0.17308"
"19974","119.80800","26.06040","0.17541"
"20026","120.12000","26.08636","0.17697"
"20078","120.43200","26.11242","0.18057"
"20130","120.74400","26.13843","0.18207"
"20182","121.05600","26.16438","0.18421"
"20234","121.36800","26.19045","0.18535"
"20286","121.68000","26.21634","0.18784"
"20338","121.99200","26.24246","0.19000"
"20390","122.30400","26.26841","0.19187"
"20442","122.61600","26.29436","0.19249"
"20494","122.92800","26.32037","0.19471"
"20546","123.24000","26.34638","0.19604"
"20598","123.55200","26.37239","0.19761"
"20650","123.86400","26.39839","0.19871"
"20702","124.17600","26.42434","0.20007"
"20754","124.48800","26.45041","0.20150"
"20806","124.80000","26.47636","0.20176"
"20858","125.11200","26.50243","0.20232"
"20910","125.42400","26.52838","0.20347"
"20962","125.73600","26.55439","0.20436"
"21014","126.04800","26.58034","0.20485"
"21066","126.36000","26.60634","0.20556"
"21118","126.67200","26.63241","0.20597"
"21170","126.98400","26.65836","0.20744"
"21222","127.29600","26.68443","0.20780"
"21274","127.60800","26.71038","0.20840"
"21326","127.92000","26.73639","0.20967"
"21378","128.23200","26.76239","0.21012"
"21430","128.54400","26.78834","0.21008"
"21482","128.85600","26.81441","0.21102"
"21534","129.16800","26.84036","0.21261"
"21586","129.48000","26.86643","0.21323"
"21638","129.79200","26.89238","0.21515"
"21690","130.10400","26.91838","0.21544"
"21742","130.41600","26.94439","0.21669"
"21794","130.72800","26.97034","0.21851"
"21846","131.04000","26.99641","0.21986"
"21898","131.35200","27.02236","0.22119"
"21950","131.66400","27.04843","0.22250"
"22002","131.97600","27.07438","0.22323"
"22054","132.28800","27.10038","0.22543"
"22106","132.60000","27.12645","0.22617"
"22158","132.91200","27.15234","0.22739"
"22210","133.22400","27.17841","0.22931"
"22262","133.53600","27.20436","0.23088"
"22314","133.84800","27.23037","0.23279"
"22366","134.16000","27.25637","0.23283"
"22418","134.47200","27.28238","0.23454"
"22470","134.78400","27.30839","0.23609"
"22522","135.09600","27.33434","0.23702"
"22574","135.40800","27.36035","0.23846"
"22626","135.72000","27.38636","0.23888"
"22678","136.03200","27.41243","0.24016"
"22730","136.34400","27.43849","0.23949"
"22782","136.65600","27.46438","0.24117"
"22834","136.96800","27.49039","0.24235"
"22886","137.28000","27.51628","0.24316"
"22938","137.59200","27.54241","0.24425"
"22990","137.90400","27.56841","0.24474"
"23042","138.21600","27.59436","0.24558"
"23094","138.52800","27.62037","0.24624"
"23146","138.84000","27.64632","0.24692"
"23198","139.15200","27.67239","0.24759"
"23250","139.46400","27.69834","0.24858"
"23302","139.77600","27.72441","0.24903"
"23354","140.08800","27.75041","0.24982"
"23406","140.40000","27.77636","0.25058"
"23458","140.71200","27.80231","0.25093"
"23510","141.02400","27.82826","0.25178"
"23562","141.33600","27.85439","0.25248"
"23614","141.64800","27.88040","0.25281"
"23666","141.96000","27.90635","0.25329"
"23718","142.27200","27.93242","0.25368"
"23770","142.58400","27.95836","0.25401"
"23822","142.89600","27.98431","0.25435"
"23874","143.20800","28.01032","0.25566"
"23926","143.52000","28.03639","0.25687"
"23978","143.83200","28.06240","0.25793"
"24030","144.14400","28.08834","0.25857"
"24082","144.45600","28.11436","0.25946"
"24134","144.76800","28.14030","0.26022"
"24186","145.08000","28.16643","0.26154"
"24238","145.39200","28.19238","0.26208"
"24290","145.70400","28.21833","0.26233"
"24342","146.01600","28.24440","0.26327"
"24394","146.32800","28.27035","0.26500"
"24446","146.64000","28.29641","0.26700"
"24498","146.95200","28.32236","0.26858"
"24550","147.26400","28.34843","0.26981"
"24602","147.57600","28.37432","0.27224"
"24654","147.88800","28.40038","0.27368"
"24706","148.20000","28.42640","0.27448"
"24758","148.51200","28.45234","0.27580"
"24810","148.82400","28.47847","0.27688"
"24862","149.13600","28.50436","0.27782"
"24914","149.44800","28.53043","0.27927"
"24966","149.76000","28.55644","0.28093"
"25018","150.07200","28.58239","0.28209"
"25070","150.38400","28.60846","0.28359"
"25122","150.69600","28.63434","0.28513"
"25174","151.00800","28.66041","0.28578"
"25226","151.32000","28.68636","0.28683"
"25278","151.63200","28.71231","0.28772"
"25330","151.94400","28.73838","0.18439"
"25382","152.25600","28.76439","0.18838"
"25434","152.56800","28.79039","0.18808"
"25486","152.88000","28.81628","0.19039"
"25538","153.19200","28.84241","0.19155"
"25590","153.50400","28.86842","0.17413"
"25642","153.81600","28.89437","0.18039"
"25694","154.12800","28.92044","0.18457"
"25746","154.44000","28.94633","0.18828"
"25798","154.75200","28.97239","0.19137"
"25850","155.06400","28.99834","0.19506"
"25902","155.37600","29.02435","0.19564"
"25954","155.68800","29.05036","0.19774"
"26006","156.00000","29.07631","0.19720"
"26058","156.31200","29.10244","0.19980"
"26110","156.62400","29.12832","0.20091"
"26162","156.93600","29.15439","0.20170"
"26214","157.24800","29.18040","0.20304"
"26266","157.56000","29.20641","0.20337"
"26318","157.87200","29.23242","0.20462"
"26370","158.18400","29.25837","0.20514"
"26422","158.49600","29.28438","0.20629"
"26474","158.80800","29.31032","0.20754"
"26526","159.12000","29.33639","0.20843"
"26578","159.43200","29.36240","0.20967"
"26630","159.74400","29.38841","0.20893"
"26682","160.05600","29.41442","0.20961"
"26734","160.36800","29.44031","0.21083"
"26786","160.68000","29.46638","0.21189"
"26838","160.99200","29.49238","0.21338"
"26890","161.30400","29.51839","0.21083"
"26942","161.61600","29.54440","0.21183"
"26994","161.92800","29.57035","0.21261"
"27046","162.24000","29.59636","0.21347"
"27098","162.55200","29.62231","0.21568"
"27150","162.86400","29.64843","0.21803"
"27202","163.17600","29.67439","0.21885"
"27254","163.48800","29.70039","0.22014"
"27306","163.80000","29.72646","0.22209"
"27358","164.11200","29.75235","0.22269"
"27410","164.42400","29.77842","0.22431"
"27462","164.73600","29.80436","0.22605"
"27514","165.04800","29.83043","0.22900"
"27566","165.36000","29.85638","0.23055"
"27618","165.67200","29.88233","0.11212"
"27670","165.98400","29.90834","0.11425"
"27722","166.29600","29.93429","0.11126"
"27774","166.60800","29.96036","0.11059"
"27826","166.92000","29.98637","0.11178"
"27878","167.23200","30.01237","0.11463"
"27930","167.54400","30.03838","0.11567"
"27982","167.85600","30.06433","0.11489"
"28034","168.16800","30.09040","0.11147"
"28086","168.48000","30.11641","0.11335"
"28138","168.79200","30.14236","0.11613"
"28190","169.10400","30.16830","0.11867"
"28242","169.41600","30.19431","0.12149"
"28294","169.72800","30.22038","0.12348"
"28346","170.04000","30.24633","0.12464"
"28398","170.35200","30.27240","0.12566"
"28450","170.66400","30.29835","0.12626"
"28502","170.97600","30.32442","0.12727"
"28554","171.28800","30.35036","0.12862"
"28606","171.60000","30.37631","0.13009"
"28658","171.91200","30.40244","0.13126"
"28710","172.22400","30.42839","0.13099"
"28762","172.53600","30.45440","0.13196"
"28814","172.84800","30.48034","0.13397"
"28866","173.16000","30.50636","0.13495"
"28918","173.47200","30.53236","0.13608"
"28970","173.78400","30.55837","0.13687"
"29022","174.09600","30.58444","0.13729"
"29074","174.40800","30.61033","0.13749"
"29126","174.72000","30.63640","0.13896"
"29178","175.03200","30.66234","0.13888"
"29230","175.34400","30.68841","0.10660"
"29282","175.65600","30.71442","0.11107"
"29334","175.96800","30.74037","0.11478"
"29386","176.28000","30.76638","0.11732"
"29438","176.59200","30.79233","0.12014"
"29490","176.90400","30.81840","0.12103"
"29542","177.21600","30.84441","0.12103"
"29594","177.52800","30.87041","0.12024"
"29646","177.84000","30.89636","0.12208"
"29698","178.15200","30.92237","0.05852"
"29750","178.46400","30.94844","0.05730"
"29802","178.77600","30.97439","0.05963"
"29854","179.08800","31.00039","0.05917"
"29906","179.40000","31.02646","0.06244"
"29958","179.71200","31.05235","0.06135"
"30010","180.02400","31.07836","0.06288"
"30062","180.33600","31.10431","0.06598"
"30114","180.64800","31.13038","0.06384"
"30166","180.96000","31.15639","0.06760"
"30218","181.27200","31.18239","0.06930"
"30270","181.58400","31.20840","0.06857"
"30322","181.89600","31.23435","0.07030"
"30374","182.20800","31.26042","0.07139"
"30426","182.52000","31.28643","0.07319"
"30478","182.83200","31.31244","0.07436"
"30530","183.14400","31.33838","0.07393"
"30582","183.45600","31.36433","0.07594"
"30634","183.76800","31.39034","0.07763"
"30686","184.08000","31.41623","0.07751"
"30738","184.39200","31.44242","0.07888"
"30790","184.70400","31.46836","0.07826"
"30842","185.01600","31.49438","0.07884"
"30894","185.32800","31.52038","0.07874"
"30946","185.64000","31.54639","0.07859"
"30998","185.95200","31.57240","0.07934"
"31050","186.26400","31.59835","0.08059"
"31102","186.57600","31.62442","0.08165"
"31154","186.88800","31.65036","0.08211"
"31206","187.20000","31.67637","0.08380"
"31258","187.51200","31.70244","0.08495"
"31310","187.82400","31.72833","0.08619"
"31362","188.13600","31.75440","0.08737"
"31414","188.44800","31.78041","0.08822"
"31466","188.76000","31.80642","0.08988"
"31518","189.07200","31.83236","0.09025"
"31570","189.38400","31.85831","0.09082"
"31622","189.69600","31.88444","0.09249"
"31674","190.00800","31.91039","0.09282"
"31726","190.32000","31.93640","0.09357"
"31778","190.63200","31.96235","0.09359"
"31830","190.94400","31.98836","0.09431"
"31882","191.25600","32.01443","0.09443"
"31934","191.56800","32.04031","0.09497"
"31986","191.88000","32.06644","0.09587"
"32038","192.19200","32.09239","0.09605"
"32090","192.50400","32.11840","0.09619"
"32142","192.81600","32.14441","0.09663"
"32194","193.12800","32.17041","0.09751"
"32246","193.44000","32.19643","0.09769"
"32298","193.75200","32.22237","0.09794"
"32350","194.06400","32.24838","0.09786"
"32402","194.37600","32.27433","0.09858"
"32454","194.68800","32.30034","0.09868"
"32506","195.00000","32.32641","0.09868"
"32558","195.31200","32.35236","0.09853"
"32610","195.62400","32.37836","0.09903"
"32662","195.93600","32.40431","0.09938"
"32714","196.24800","32.43038","0.09960"
"32766","196.56000","32.45639","0.10073"
"32818","196.87200","32.48234","0.10080"
"32870","197.18400","32.50846","0.10073"
"32922","197.49600","32.53436","0.10084"
"32974","197.80800","32.56042","0.10197"
"33026","198.12000","32.58631","0.10257"
"33078","198.43200","32.61238","0.10327"
"33130","198.74400","32.63839","0.10445"
"33182","199.05600","32.66434","0.10443"
"33234","199.36800","32.69041","0.10628"
"33286","199.68000","32.71635","0.10775"
"33338","199.99200","32.74242","0.10776"
"33390","200.30400","32.76837","0.10939"
"33442","200.61600","32.79444","0.11036"
"33494","200.92800","32.82045","0.11176"
"33546","201.24000","32.84634","0.11379"
"33598","201.55200","32.87234","0.11540"
"33650","201.86400","32.89829","0.11663"
"33702","202.17600","32.92436","0.11938"
"33754","202.48800","32.95037","0.12085"
"33806","202.80000","32.97638","0.12207"
"33858","203.11200","33.00239","0.12343"
"33910","203.42400","33.02827","0.12188"
"33962","203.73600","33.05434","0.12307"
"34014","204.04800","33.08035","0.11370"
"34066","204.36000","33.10636","0.11361"
"34118","204.67200","33.13243","0.11535"
"34170","204.98400","33.15832","0.11794"
"34222","205.29600","33.18439","0.11900"
"34274","205.60800","33.21027","0.12118"
"34326","205.92000","33.23640","0.12298"
"34378","206.23200","33.26241","0.12428"
"34430","206.54400","33.28842","0.12690"
"34482","206.85600","33.31443","0.12820"
"34534","207.16800","33.34037","0.12800"
"34586","207.48000","33.36639","0.13008"
"34638","207.79200","33.39233","0.13168"
"34690","208.10400","33.41846","0.13331"
"34742","208.41600","33.44441","0.13432"
"34794","208.72800","33.47036","0.13514"
"34846","209.04000","33.49637","0.13575"
"34898","209.35200","33.52232","0.13639"
"34950","209.66400","33.54839","0.13739"
"35002","209.97600","33.57434","0.13810"
"35054","210.28800","33.60040","0.13863"
"35106","210.60000","33.62641","0.13955"
"35158","210.91200","33.65236","0.14016"
"35210","211.22400","33.67843","0.14076"
"35262","211.53600","33.70437","0.14152"
"35314","211.84800","33.73038","0.14181"
"35366","212.16000","33.75639","0.14209"
"35418","212.47200","33.78234","0.14289"
"35470","212.78400","33.80841","0.14342"
"35522","213.09600","33.83436","0.14385"
"35574","213.40800","33.86043","0.14446"
"35626","213.72000","33.88632","0.14500"
"35678","214.03200","33.91238","0.14555"
"35730","214.34400","33.93839","0.14630"
"35782","214.65600","33.96434","0.14740"
"35834","214.96800","33.99041","0.14794"
"35886","215.28000","34.01636","0.14918"
"35938","215.59200","34.04243","0.15058"
"35990","215.90400","34.06832","0.15241"
"36042","216.21600","34.09432","0.15369"
"36094","216.52800","34.12039","0.15507"
"36146","216.84000","34.14640","0.15709"
"36198","217.15200","34.17241","0.15910"
"36250","217.46400","34.19830","0.16133"
"36302","217.77600","34.22437","0.16399"
"36354","218.08800","34.25037","0.16631"
"36406","218.40000","34.27638","0.15296"
"36458","218.71200","34.30245","0.15411"
"36510","219.02400","34.32840","0.15671"
"36562","219.33600","34.35435","0.15930"
"36614","219.64800","34.38036","0.16206"
"36666","219.96000","34.40636","0.16513"
"36718","220.27200","34.43237","0.16483"
"36770","220.58400","34.45838","0.16788"
"36822","220.89600","34.48439","0.17114"
"36874","221.20800","34.51034","0.17412"
"36926","221.52000","34.53641","0.17756"
"36978","221.83200","34.56242","0.18151"
"37030","222.14400","34.58842","0.18617"
"37082","222.45600","34.61443","0.18949"
"37134","222.76800","34.64032","0.19244"
"37186","223.08000","34.66639","0.19303"
"37238","223.39200","34.69234","0.19515"
"37290","223.70400","34.71841","0.19705"
"37342","224.01600","34.74442","0.19896"
"37394","224.32800","34.77042","0.20018"
"37446","224.64000","34.79637","0.20147"
"37498","224.95200","34.82232","0.20244"
"37550","225.26400","34.84845","0.20381"
"37602","225.57600","34.87434","0.20478"
"37654","225.88800","34.90041","0.20569"
"37706","226.20000","34.92641","0.20754"
"37758","226.51200","34.95230","0.20861"
"37810","226.82400","34.97837","0.21030"
"37862","227.13600","35.00426","0.21192"
"37914","227.44800","35.03039","0.21352"
"37966","227.76000","35.05640","0.21551"
"38018","228.07200","35.08234","0.21768"
"38070","228.38400","35.10841","0.21846"
"38122","228.69600","35.13430","0.21983"
"38174","229.00800","35.16037","0.22123"
"38226","229.32000","35.18638","0.22367"
"38278","229.63200","35.21239","0.22461"
"38330","229.94400","35.23834","0.22738"
"38382","230.25600","35.26434","0.22855"
"38434","230.56800","35.29035","0.23049"
"38486","230.88000","35.31636","0.23235"
"38538","231.19200","35.34243","0.23459"
"38590","231.50400","35.36838","0.23688"
"38642","231.81600","35.39439","0.23855"
"38694","232.12800","35.42039","0.24022"
"38746","232.44000","35.44635","0.24137"
"38798","232.75200","35.47241","0.24294"
"38850","233.06400","35.49836","0.24440"
"38902","233.37600","35.52443","0.24518"
"38954","233.68800","35.55038","0.24630"
"39006","234.00000","35.57632","0.24653"
"39058","234.31200","35.60239","0.24734"
"39110","234.62400","35.62835","0.24800"
"39162","234.93600","35.65441","0.24841"
"39214","235.24800","35.68036","0.24937"
"39266","235.56000","35.70637","0.25008"
"39318","235.87200","35.73238","0.25059"
"39370","236.18400","35.75839","0.25130"
"39422","236.49600","35.78439","0.25218"
"39474","236.80800","35.81040","0.25346"
"39526","237.12000","35.83641","0.25453"
"39578","237.43200","35.86236","0.25582"
"39630","237.74400","35.88831","0.25700"
"39682","238.05600","35.91438","0.25856"
"39734","238.36800","35.94039","0.25956"
"39786","238.68000","35.96639","0.26119"
"39838","238.99200","35.99234","0.26355"
"39890","239.30400","36.01841","0.26540"
"39942","239.61600","36.04442","0.26727"
"39994","239.92800","36.07037","0.26813"
"40046","240.24000","36.09644","0.26868"
"40098","240.55200","36.12233","0.27014"
"40150","240.86400","36.14839","0.27224"
"40202","241.17600","36.17434","0.27366"
"40254","241.48800","36.20035","0.27501"
"40306","241.80000","36.22642","0.27615"
"40358","242.11200","36.25231","0.27746"
"40410","242.42400","36.27843","0.27886"
"40462","242.73600","36.30433","0.28027"
"40514","243.04800","36.33039","0.28252"
"40566","243.36000","36.35634","0.28420"
"40618","243.67200","36.38241","0.28594"
"40670","243.98400","36.40842","0.28728"
"40722","244.29600","36.43437","0.28980"
"40774","244.60800","36.46037","0.29127"
"40826","244.92000","36.48632","0.29328"
"40878","245.23200","36.51239","0.29433"
"40930","245.54400","36.53840","0.29594"
"40982","245.85600","36.56435","0.29733"
"41034","246.16800","36.59035","0.29841"
"41086","246.48000","36.61637","0.29940"
"41138","246.79200","36.64237","0.30017"
"41190","247.10400","36.66838","0.30239"
"41242","247.41600","36.69445","0.30495"
"41294","247.72800","36.72040","0.30755"
"41346","248.04000","36.74635","0.30911"
"41398","248.35200","36.77235","0.31348"
"41450","248.66400","36.79831","0.31502"
"41502","248.97600","36.82444","0.31786"
"41554","249.28800","36.85038","0.32079"
"41606","249.60000","36.87639","0.32359"
"41658","249.91200","36.90240","0.32587"
"41710","250.22400","36.92835","0.32937"
"41762","250.53600","36.95441","0.33219"
"41814","250.84800","36.98037","0.33493"
"41866","251.16000","37.00644","0.33644"
"41918","251.47200","37.03238","0.33870"
"41970","251.78400","37.05833","0.34065"
"42022","252.09600","37.08434","0.34333"
"42074","252.40800","37.11035","0.34553"
"42126","252.72000","37.13642","0.34773"
"42178","253.03200","37.16236","0.35001"
"42230","253.34400","37.18837","0.35202"
"42282","253.65600","37.21438","0.35361"
"42334","253.96800","37.24039","0.35500"
"42386","254.28000","37.26640","0.35571"
"42438","254.59200","37.29240","0.35656"
"42490","254.90400","37.31836","0.35672"
"42542","255.21600","37.34436","0.35690"
"42594","255.52800","37.37031","0.35741"
"42646","255.84000","37.39638","0.35771"
"42698","256.15200","37.42233","0.35756"
"42750","256.46400","37.44840","0.35778"
"42802","256.77600","37.47435","0.35816"
"42854","257.08800","37.50035","0.35833"
"42906","257.40000","37.52642","0.35871"
"42958","257.71200","37.55237","0.35867"
"43010","258.02400","37.57844","0.35930"
"43062","258.33600","37.60433","0.35983"
"43114","258.64800","37.63040","0.36011"
"43166","258.96000","37.65635","0.03215"
"43218","259.27200","37.68235","0.05642"
"43270","259.58400","37.70842","0.05765"
"43322","259.89600","37.73437","0.05422"
"43374","260.20800","37.76044","0.05598"
"43426","260.52000","37.78633","0.05647"
"43478","260.83200","37.81240","0.05181"
"43530","261.14400","37.83834","0.07038"
"43582","261.45600","37.86441","0.05314"
"43634","261.76800","37.89042","0.05879"
"43686","262.08000","37.91637","0.05566"
"43738","262.39200","37.94238","0.06641"
"43790","262.70400","37.96833","0.05482"
"43842","263.01600","37.99440","0.06030"
"43894","263.32800","38.02040","0.05836"
"43946","263.64000","38.04635","0.06430"
"43998","263.95200","38.07236","0.05648"
"44050","264.26400","38.09837","0.05948"
"44102","264.57600","38.12438","0.06511"
"44154","264.88800","38.15039","0.06528"
"44206","265.20000","38.17640","0.07000"
"44258","265.51200","38.20246","0.06705"
"44310","265.82400","38.22829","0.07675"
"44362","266.13600","38.25442","0.07445"
"44414","266.44800","38.28031","0.07687"
"44466","266.76000","38.30644","0.07797"
"44518","267.07200","38.33238","0.08135"
"44570","267.38400","38.35839","0.08741"
"44622","267.69600","38.38440","0.08587"
"44674","268.00800","38.41029","0.08467"
"44726","268.32000","38.43642","0.08651"
"44778","268.63200","38.46237","0.08998"
"44830","268.94400","38.48844","0.09255"
"44882","269.25600","38.51438","0.09237"
"44934","269.56800","38.54033","0.09412"
"44986","269.88000","38.56635","0.09628"
"45038","270.19200","38.59229","0.09698"
"45090","270.50400","38.61842","0.09801"
"45142","270.81600","38.64437","0.09814"
"45194","271.12800","38.67038","0.09932"
"45246","271.44000","38.69645","0.09596"
"45298","271.75200","38.72239","0.09635"
"45350","272.06400","38.74840","0.09674"
"45402","272.37600","38.77441","0.09712"
"45454","272.68800","38.80042","0.09823"
"45506","273.00000","38.82637","0.09990"
"45558","273.31200","38.85231","0.10207"
"45610","273.62400","38.87833","0.10275"
"45662","273.93600","38.90433","0.10395"
"45714","274.24800","38.93040","0.10697"
"45766","274.56000","38.95635","0.10972"
"45818","274.87200","38.98242","0.11124"
"45870","275.18400","39.00843","0.11306"
"45922","275.49600","39.03431","0.11471"
"45974","275.80800","39.06044","0.11679"
"46026","276.12000","39.08639","0.11957"
"46078","276.43200","39.11240","0.12272"
"46130","276.74400","39.13835","0.12466"
"46182","277.05600","39.16435","0.12669"
"46234","277.36800","39.19037","0.12818"
"46286","277.68000","39.21637","0.12933"
"46338","277.99200","39.24244","0.13134"
"46390","278.30400","39.26839","0.13295"
"46442","278.61600","39.29440","0.13503"
"46494","278.92800","39.32040","0.13686"
"46546","279.24000","39.34641","0.13766"
"46598","279.55200","39.37243","0.13884"
"46650","279.86400","39.39837","0.13956"
"46702","280.17600","39.42444","0.14072"
"46754","280.48800","39.45033","0.14143"
"46806","280.80000","39.47634","0.14290"
"46858","281.11200","39.50240","0.14354"
"46910","281.42400","39.52835","0.14454"
"46962","281.73600","39.55436","0.14505"
"47014","282.04800","39.58031","0.14525"
"47066","282.36000","39.60638","0.14660"
"47118","282.67200","39.63239","0.14961"
"47170","282.98400","39.65840","0.14998"
"47222","283.29600","39.68440","0.15253"
"47274","283.60800","39.71029","0.15412"
"47326","283.92000","39.73636","0.15652"
"47378","284.23200","39.76237","0.15604"
"47430","284.54400","39.78838","0.15989"
"47482","284.85600","39.81445","0.16114"
"47534","285.16800","39.84034","0.16321"
"47586","285.48000","39.86640","0.16499"
"47638","285.79200","39.89229","0.16673"
"47690","286.10400","39.91836","0.17075"
"47742","286.41600","39.94437","0.17196"
"47794","286.72800","39.97038","0.17577"
"47846","287.04000","39.99639","0.17578"
"47898","287.35200","40.02234","0.17697"
"47950","287.66400","40.04840","0.18032"
"48002","287.97600","40.07435","0.18766"
"48054","288.28800","40.10036","0.19311"
"48106","288.60000","40.12637","0.19696"
"48158","288.91200","40.15237","0.19909"
"48210","289.22400","40.17839","0.20174"
"48262","289.53600","40.20427","0.20373"
"48314","289.84800","40.23040","0.20443"
"48366","290.16000","40.25642","0.20676"
"48418","290.47200","40.28242","0.20799"
"48470","290.78400","40.30843","0.20995"
"48522","291.09600","40.33432","0.20477"
"48574","291.40800","40.36039","0.20408"
"48626","291.72000","40.38633","0.20551"
"48678","292.03200","40.41240","0.20757"
"48730","292.34400","40.43842","0.21049"
"48782","292.65600","40.46436","0.21338"
"48834","292.96800","40.49043","0.21324"
"48886","293.28000","40.51632","0.18996"
"48938","293.59200","40.54239","0.19390"
"48990","293.90400","40.56840","0.19884"
"49042","294.21600","40.59440","0.20115"
"49094","294.52800","40.62041","0.20351"
"49146","294.84000","40.64636","0.20574"
"49198","295.15200","40.67242","0.20923"
"49250","295.46400","40.69831","0.21147"
"49302","295.77600","40.72445","0.21434"
"49354","296.08800","40.75040","0.21858"
"49406","296.40000","40.77634","0.22184"
"49458","296.71200","40.80241","0.22455"
"49510","297.02400","40.82836","0.22776"
"49562","297.33600","40.85442","0.23103"
"49614","297.64800","40.88037","0.23378"
"49666","297.96000","40.90638","0.23564"
"49718","298.27200","40.93240","0.23868"
"49770","298.58400","40.95834","0.24080"
"49822","298.89600","40.98441","0.24351"
"49874","299.20800","41.01030","0.24439"
"49926","299.52000","41.03637","0.24606"
"49978","299.83200","41.06238","0.24744"
"50030","300.14400","41.08838","0.24898"
"50082","300.45600","41.11440","0.25028"
"50134","300.76800","41.14034","0.25143"
"50186","301.08000","41.16641","0.25262"
"50238","301.39200","41.19229","0.25425"
"50290","301.70400","41.21842","0.25569"
"50342","302.01600","41.24437","0.25720"
"50394","302.32800","41.27032","0.25892"
"50446","302.64000","41.29645","0.26110"
"50498","302.95200","41.32234","0.26373"
"50550","303.26400","41.34841","0.26692"
"50602","303.57600","41.37436","0.26865"
"50654","303.88800","41.40036","0.27143"
"50706","304.20000","41.42638","0.27445"
"50758","304.51200","41.45238","0.27677"
"50810","304.82400","41.47845","0.28001"
"50862","305.13600","41.50434","0.28282"
"50914","305.44800","41.53035","0.28398"
"50966","305.76000","41.55636","0.16504"
"51018","306.07200","41.58236","0.14977"
"51070","306.38400","41.60843","0.14825"
"51122","306.69600","41.63432","0.14928"
"51174","307.00800","41.66039","0.15078"
"51226","307.32000","41.68634","0.15346"
"51278","307.63200","41.71241","0.15358"
"51330","307.94400","41.73842","0.15464"
"51382","308.25600","41.76436","0.15796"
"51434","308.56800","41.79043","0.15877"
"51486","308.88000","41.81631","0.16119"
"51538","309.19200","41.84239","0.16286"
"51590","309.50400","41.86834","0.16591"
"51642","309.81600","41.89441","0.16731"
"51694","310.12800","41.92042","0.16841"
"51746","310.44000","41.94636","0.17152"
"51798","310.75200","41.97237","0.17348"
"51850","311.06400","41.99832","0.17606"
"51902","311.37600","42.02439","0.17911"
"51954","311.68800","42.05033","0.18396"
"52006","312.00000","42.07634","0.18697"
"52058","312.31200","42.10242","0.19045"
"52110","312.62400","42.12836","0.19377"
"52162","312.93600","42.15437","0.19529"
"52214","313.24800","42.18032","0.19562"
"52266","313.56000","42.20644","0.19780"
"52318","313.87200","42.23233","0.19972"
"52370","314.18400","42.25834","0.20085"
"52422","314.49600","42.28441","0.20195"
"52474","314.80800","42.31036","0.20228"
"52526","315.12000","42.33637","0.20336"
"52578","315.43200","42.36238","0.20384"
"52630","315.74400","42.38839","0.20455"
"52682","316.05600","42.41440","0.20525"
"52734","316.36800","42.44034","0.20606"
"52786","316.68000","42.46641","0.20733"
"52838","316.99200","42.49236","0.20905"
"52890","317.30400","42.51843","0.20979"
"52942","317.61600","42.54438","0.21152"
"52994","317.92800","42.57033","0.21131"
"53046","318.24000","42.59639","0.21297"
"53098","318.55200","42.62234","0.21396"
"53150","318.86400","42.64841","0.21480"
"53202","319.17600","42.67436","0.21589"
"53254","319.48800","42.70037","0.21796"
"53306","319.80000","42.72632","0.21960"
"53358","320.11200","42.75233","0.22076"
"53410","320.42400","42.77840","0.22247"
"53462","320.73600","42.80441","0.22429"
"53514","321.04800","42.83041","0.22512"
"53566","321.36000","42.85636","0.22667"
"53618","321.67200","42.88237","0.22803"
"53670","321.98400","42.90838","0.22868"
"53722","322.29600","42.93438","0.22904"
"53774","322.60800","42.96039","0.23102"
"53826","322.92000","42.98634","0.23367"
"53878","323.23200","43.01241","0.23552"
"53930","323.54400","43.03836","0.23780"
"53982","323.85600","43.06430","0.23759"
"54034","324.16800","43.09044","0.23824"
"54086","324.48000","43.11633","0.23899"
"54138","324.79200","43.14240","0.23925"
"54190","325.10400","43.16834","0.24015"
"54242","325.41600","43.19441","0.24052"
"54294","325.72800","43.22042","0.24118"
"54346","326.04000","43.24637","0.24229"
"54398","326.35200","43.27238","0.24270"
"54450","326.66400","43.29832","0.24323"
"54502","326.97600","43.32439","0.24380"
"54554","327.28800","43.35034","0.24414"
"54606","327.60000","43.37635","-0.00181"
"54658","327.91200","43.40236","0.01311"
"54710","328.22400","43.42837","0.01161"
"54762","328.53600","43.45443","0.00968"
"54814","328.84800","43.48032","0.01031"
"54866","329.16000","43.50639","0.01618"
"54918","329.47200","43.53240","0.00883"
"54970","329.78400","43.55841","0.00950"
"55022","330.09600","43.58442","0.01247"
"55074","330.40800","43.61031","0.00947"
"55126","330.72000","43.63638","0.00894"
"55178","331.03200","43.66238","0.00997"
"55230","331.34400","43.68839","0.01344"
"55282","331.65600","43.71434","0.00855"
"55334","331.96800","43.74035","0.01056"
"55386","332.28000","43.76635","0.01145"
"55438","332.59200","43.79224","0.01069"
"55490","332.90400","43.81843","0.00983"
"55542","333.21600","43.84444","0.00993"
"55594","333.52800","43.87039","0.01253"
"55646","333.84000","43.89640","0.00934"
"55698","334.15200","43.92229","0.01104"
"55750","334.46400","43.94835","0.01047"
"55802","334.77600","43.97430","0.01169"
"55854","335.08800","44.00043","0.01010"
"55906","335.40000","44.02638","0.01037"
"55958","335.71200","44.05239","0.01157"
"56010","336.02400","44.07846","0.01039"
"56062","336.33600","44.10435","0.01033"
"56114","336.64800","44.13041","0.01047"
"56166","336.96000","44.15636","0.01241"
"56218","337.27200","44.18238","0.01047"
"56270","337.58400","44.20838","0.00978"
"56322","337.89600","44.23433","0.01152"
"56374","338.20800","44.26040","0.01142"
"56426","338.52000","44.28635","0.01016"
"56478","338.83200","44.31242","0.01079"
"56530","339.14400","44.33836","0.01213"
"56582","339.45600","44.36437","0.01048"
"56634","339.76800","44.39038","0.01046"
"56686","340.08000","44.41633","0.01251"
"56738","340.39200","44.44240","0.01147"
"56790","340.70400","44.46840","0.01041"
"56842","341.01600","44.49435","0.01171"
"56894","341.32800","44.52036","0.01309"
"56946","341.64000","44.54631","0.01132"
"56998","341.95200","44.57243","0.01121"
"57050","342.26400","44.59833","0.01279"
"57102","342.57600","44.62434","0.01137"
"57154","342.88800","44.65034","0.01119"
"57206","343.20000","44.67641","0.01209"
"57258","343.51200","44.70242","0.01269"
"57310","343.82400","44.72837","0.01091"
"57362","344.13600","44.75444","0.01173"
"57414","344.44800","44.78033","0.01315"
"57466","344.76000","44.80640","0.01178"
"57518","345.07200","44.83234","0.01167"
"57570","345.38400","44.85835","0.01236"
"57622","345.69600","44.88442","0.01225"
"57674","346.00800","44.91031","0.01204"
"57726","346.32000","44.93637","0.01238"
"57778","346.63200","44.96233","0.01308"
"57830","346.94400","44.98840","0.01246"
"57882","347.25600","45.01440","0.01271"
"57934","347.56800","45.04036","0.01401"
"57986","347.88000","45.06642","0.01290"
"58038","348.19200","45.09231","0.01220"
"58090","348.50400","45.11844","0.01393"
"58142","348.81600","45.14433","0.01412"
"58194","349.12800","45.17039","0.01311"
"58246","349.44000","45.19646","0.01419"
"58298","349.75200","45.22235","0.01382"
"58350","350.06400","45.24836","0.01354"
"58402","350.37600","45.27431","0.01412"
"58454","350.68800","45.30038","0.01463"
"58506","351.00000","45.32639","0.01394"
"58558","351.31200","45.35239","0.01470"
"58610","351.62400","45.37840","0.01548"
"58662","351.93600","45.40429","0.01422"
"58714","352.24800","45.43036","0.01508"
"58766","352.56000","45.45637","0.01537"
"58818","352.87200","45.48238","0.01514"
"58870","353.18400","45.50845","0.01542"
"58922","353.49600","45.53439","0.01629"
"58974","353.80800","45.56041","0.01532"
"59026","354.12000","45.58629","0.01608"
"59078","354.43200","45.61242","0.01641"
"59130","354.74400","45.63837","0.01571"
"59182","355.05600","45.66438","0.01608"
"59234","355.36800","45.69044","0.01670"
"59286","355.68000","45.71634","0.01652"
"59338","355.99200","45.74234","0.01705"
"59390","356.30400","45.76835","0.01790"
"59442","356.61600","45.79442","0.01801"
"59494","356.92800","45.82037","0.01852"
"59546","357.24000","45.84631","0.01854"
"59598","357.55200","45.87232","0.01875"
"59650","357.86400","45.89827","0.01860"
"59702","358.17600","45.92440","0.01983"
"59754","358.48800","45.95041","0.01909"
"59806","358.80000","45.97636","0.01955"
"59858","359.11200","46.00237","0.02021"
"59910","359.42400","46.02831","0.02014"
"59962","359.73600","46.05439","0.02065"
"60014","360.04800","46.08033","0.02110"
"60066","360.36000","46.10640","0.02111"
"60118","360.67200","46.13235","0.02140"
"60170","360.98400","46.15836","0.02257"
"60222","361.29600","46.18436","0.02249"
"60274","361.60800","46.21031","0.02278"
"60326","361.92000","46.23644","0.02353"
"60378","362.23200","46.26239","0.02267"
"60430","362.54400","46.28840","0.02348"
"60482","362.85600","46.31434","0.02427"
"60534","363.16800","46.34036","0.02452"
"60586","363.48000","46.36642","0.02455"
"60638","363.79200","46.39237","0.02421"
"60690","364.10400","46.41838","0.02508"
"60742","364.41600","46.44439","0.02514"
"60794","364.72800","46.47040","0.02506"
"60846","365.04000","46.49641","0.02611"
"60898","365.35200","46.52242","0.02570"
"60950","365.66400","46.54843","0.02581"
"61002","365.97600","46.57437","0.02623"
"61054","366.28800","46.60038","0.02724"
"61106","366.60000","46.62639","0.02707"
"61158","366.91200","46.65234","0.02718"
"61210","367.22400","46.67841","0.02639"
"61262","367.53600","46.70436","0.02597"
"61314","367.84800","46.73042","0.02679"
"61366","368.16000","46.75637","0.02694"
"61418","368.47200","46.78238","0.02783"
"61470","368.78400","46.80845","0.02671"
"61522","369.09600","46.83434","0.02706"
"61574","369.40800","46.86041","0.02730"
"61626","369.72000","46.88630","0.02775"
"61678","370.03200","46.91236","0.02828"
"61730","370.34400","46.93837","0.02863"
"61782","370.65600","46.96444","0.02844"
"61834","370.96800","46.99045","0.02909"
"61886","371.28000","47.01633","0.02799"
"61938","371.59200","47.04241","0.02827"
"61990","371.90400","47.06836","0.02890"
"62042","372.21600","47.09442","0.02928"
"62094","372.52800","47.12037","0.02902"
"62146","372.84000","47.14638","0.03007"
"62198","373.15200","47.17239","0.02953"
"62250","373.46400","47.19833","0.02992"
"62302","373.77600","47.22441","0.02975"
"62354","374.08800","47.25035","0.03047"
"62406","374.40000","47.27642","0.03071"
"62458","374.71200","47.30237","0.03084"
"62510","375.02400","47.32832","0.03042"
"62562","375.33600","47.35439","0.03009"
"62614","375.64800","47.38027","0.03073"
"62666","375.96000","47.40641","0.03069"
"62718","376.27200","47.43241","0.03134"
"62770","376.58400","47.45842","0.03212"
"62822","376.89600","47.48443","0.03123"
"62874","377.20800","47.51032","0.03114"
"62926","377.52000","47.53638","0.03272"
"62978","377.83200","47.56233","0.03181"
"63030","378.14400","47.58846","0.03248"
"63052","378.27200","47.59904","0.03255"