File: Trajectories_together/170226_1Specimen_RawData_1.csv
"","V1","V2","V3"
"1","End date","2/26/2017",""
"2","Specimen label","1AT_2",""
"3","Maximum Load","0.07470","N"
"4","Time","Extension","Load"
"5","(s)","(mm)","(N)"
"6","0.00000","0.00000","0.00032"
"45","0.23400","0.01782","0.00007"
"84","0.46800","0.03922","-0.00032"
"123","0.70200","0.05877","0.00006"
"162","0.93600","0.07820","0.00055"
"201","1.17000","0.09776","0.00067"
"240","1.40400","0.11719","0.00060"
"279","1.63800","0.13668","0.00041"
"318","1.87200","0.15617","0.00076"
"357","2.10600","0.17560","0.00084"
"396","2.34000","0.19521","0.00011"
"435","2.57400","0.21464","0.00050"
"474","2.80800","0.23420","0.00064"
"513","3.04200","0.25369","0.00081"
"552","3.27600","0.27318","0.00037"
"591","3.51000","0.29273","0.00037"
"630","3.74400","0.31216","0.00087"
"669","3.97800","0.33165","0.00076"
"708","4.21200","0.35114","0.00102"
"747","4.44600","0.37075","0.00055"
"786","4.68000","0.39019","0.00061"
"825","4.91400","0.40968","0.00057"
"864","5.14800","0.42923","0.00063"
"903","5.38200","0.44866","0.00049"
"942","5.61600","0.46821","0.00064"
"981","5.85000","0.48764","0.00114"
"1020","6.08400","0.50719","0.00049"
"1059","6.31800","0.52669","0.00099"
"1098","6.55200","0.54618","0.00054"
"1137","6.78600","0.56567","0.00081"
"1176","7.02000","0.58516","0.00127"
"1215","7.25400","0.60465","0.00084"
"1254","7.48800","0.62414","0.00105"
"1293","7.72200","0.64369","0.00041"
"1332","7.95600","0.66319","0.00054"
"1371","8.19000","0.68274","0.00094"
"1410","8.42400","0.70217","0.00143"
"1449","8.65800","0.72166","0.00123"
"1488","8.89200","0.74121","0.00101"
"1527","9.12600","0.76070","0.00103"
"1566","9.36000","0.78019","0.00074"
"1605","9.59400","0.79969","0.00044"
"1644","9.82800","0.81924","0.00036"
"1683","10.06200","0.83873","0.00092"
"1722","10.29600","0.85816","0.00114"
"1761","10.53000","0.87765","0.00096"
"1800","10.76400","0.89720","0.00107"
"1839","10.99800","0.91669","0.00155"
"1878","11.23200","0.93618","0.00142"
"1917","11.46600","0.95568","0.00071"
"1956","11.70000","0.97517","0.00081"
"1995","11.93400","0.99472","0.00079"
"2034","12.16800","1.01415","0.00184"
"2073","12.40200","1.03364","0.00086"
"2112","12.63600","1.05319","0.00091"
"2151","12.87000","1.07262","0.00070"
"2190","13.10400","1.09218","0.00078"
"2229","13.33800","1.11167","0.00120"
"2268","13.57200","1.13122","0.00108"
"2307","13.80600","1.15071","0.00109"
"2346","14.04000","1.17014","0.00098"
"2385","14.27400","1.18969","0.00122"
"2424","14.50800","1.20912","0.00096"
"2463","14.74200","1.22867","0.00074"
"2502","14.97600","1.24811","0.00082"
"2541","15.21000","1.26772","0.00064"
"2580","15.44400","1.28715","0.00081"
"2619","15.67800","1.30670","0.00095"
"2658","15.91200","1.32619","0.00133"
"2697","16.14600","1.34562","0.00083"
"2736","16.38000","1.36523","0.00091"
"2775","16.61400","1.38467","0.00113"
"2814","16.84800","1.40416","0.00075"
"2853","17.08200","1.42365","0.00100"
"2892","17.31600","1.44320","0.00112"
"2931","17.55000","1.46269","0.00087"
"2970","17.78400","1.48218","0.00112"
"3009","18.01800","1.50167","0.00049"
"3048","18.25200","1.52117","0.00118"
"3087","18.48600","1.54072","0.00140"
"3126","18.72000","1.56021","0.00095"
"3165","18.95400","1.57976","0.00074"
"3204","19.18800","1.59913","0.00086"
"3243","19.42200","1.61868","0.00059"
"3282","19.65600","1.63817","0.00081"
"3321","19.89000","1.65761","0.00107"
"3360","20.12400","1.67716","0.00067"
"3399","20.35800","1.69659","0.00097"
"3438","20.59200","1.71620","0.00093"
"3477","20.82600","1.73569","0.00113"
"3516","21.06000","1.75518","0.00054"
"3555","21.29400","1.77467","0.00066"
"3594","21.52800","1.79416","0.00096"
"3633","21.76200","1.81366","0.00128"
"3672","21.99600","1.83315","0.00131"
"3711","22.23000","1.85270","0.00071"
"3750","22.46400","1.87219","0.00089"
"3789","22.69800","1.89168","0.00128"
"3828","22.93200","1.91117","0.00138"
"3867","23.16600","1.93066","0.00094"
"3906","23.40000","1.95022","0.00089"
"3945","23.63400","1.96959","0.00093"
"3984","23.86800","1.98920","0.00137"
"4023","24.10200","2.00863","0.00082"
"4062","24.33600","2.02818","0.00096"
"4101","24.57000","2.04767","0.00070"
"4140","24.80400","2.06716","0.00134"
"4179","25.03800","2.08671","0.00131"
"4218","25.27200","2.10615","0.00116"
"4257","25.50600","2.12564","0.00148"
"4296","25.74000","2.14507","0.00115"
"4335","25.97400","2.16474","0.00111"
"4374","26.20800","2.18423","0.00134"
"4413","26.44200","2.20366","0.00151"
"4452","26.67600","2.22315","0.00122"
"4491","26.91000","2.24265","0.00133"
"4530","27.14400","2.26226","0.00113"
"4569","27.37800","2.28163","0.00118"
"4608","27.61200","2.30118","0.00135"
"4647","27.84600","2.32067","0.00132"
"4686","28.08000","2.34016","0.00171"
"4725","28.31400","2.35965","0.00141"
"4764","28.54800","2.37920","0.00143"
"4803","28.78200","2.39876","0.00143"
"4842","29.01600","2.41819","0.00141"
"4881","29.25000","2.43768","0.00124"
"4920","29.48400","2.45717","0.00069"
"4959","29.71800","2.47672","0.00133"
"4998","29.95200","2.49615","0.00142"
"5037","30.18600","2.51570","0.00130"
"5076","30.42000","2.53526","0.00132"
"5115","30.65400","2.55463","0.00100"
"5154","30.88800","2.57424","0.00136"
"5193","31.12200","2.59361","0.00091"
"5232","31.35600","2.61322","0.00170"
"5271","31.59000","2.63271","0.00151"
"5310","31.82400","2.65220","0.00130"
"5349","32.05800","2.67170","0.00133"
"5388","32.29200","2.69119","0.00161"
"5427","32.52600","2.71074","0.00126"
"5466","32.76000","2.73011","0.00123"
"5505","32.99400","2.74966","0.00143"
"5544","33.22800","2.76915","0.00142"
"5583","33.46200","2.78864","0.00176"
"5622","33.69600","2.80819","0.00132"
"5661","33.93000","2.82769","0.00112"
"5700","34.16400","2.84724","0.00092"
"5739","34.39800","2.86661","0.00109"
"5778","34.63200","2.88616","0.00136"
"5817","34.86600","2.90571","0.00161"
"5856","35.10000","2.92520","0.00096"
"5895","35.33400","2.94469","0.00136"
"5934","35.56800","2.96419","0.00145"
"5973","35.80200","2.98368","0.00164"
"6012","36.03600","3.00317","0.00159"
"6051","36.27000","3.02266","0.00139"
"6090","36.50400","3.04215","0.00141"
"6129","36.73800","3.06176","0.00082"
"6168","36.97200","3.08113","0.00223"
"6207","37.20600","3.10069","0.00149"
"6246","37.44000","3.12024","0.00187"
"6285","37.67400","3.13967","0.00112"
"6324","37.90800","3.15916","0.00128"
"6363","38.14200","3.17859","0.00117"
"6402","38.37600","3.19820","0.00187"
"6441","38.61000","3.21769","0.00191"
"6480","38.84400","3.23718","0.00141"
"6519","39.07800","3.25668","0.00131"
"6558","39.31200","3.27617","0.00135"
"6597","39.54600","3.29566","0.00140"
"6636","39.78000","3.31509","0.00139"
"6675","40.01400","3.33470","0.00191"
"6714","40.24800","3.35413","0.00139"
"6753","40.48200","3.37374","0.00184"
"6792","40.71600","3.39312","0.00192"
"6831","40.95000","3.41267","0.00118"
"6870","41.18400","3.43222","0.00140"
"6909","41.41800","3.45165","0.00148"
"6948","41.65200","3.47120","0.00177"
"6987","41.88600","3.49069","0.00167"
"7026","42.12000","3.51018","0.00219"
"7065","42.35400","3.52968","0.00176"
"7104","42.58800","3.54923","0.00152"
"7143","42.82200","3.56872","0.00107"
"7182","43.05600","3.58815","0.00121"
"7221","43.29000","3.60764","0.00082"
"7260","43.52400","3.62713","0.00133"
"7299","43.75800","3.64674","0.00131"
"7338","43.99200","3.66617","0.00093"
"7377","44.22600","3.68567","0.00191"
"7416","44.46000","3.70516","0.00185"
"7455","44.69400","3.72471","0.00140"
"7494","44.92800","3.74420","0.00126"
"7533","45.16200","3.76363","0.00123"
"7572","45.39600","3.78318","0.00193"
"7611","45.63000","3.80267","0.00218"
"7650","45.86400","3.82211","0.00188"
"7689","46.09800","3.84166","0.00156"
"7728","46.33200","3.86121","0.00199"
"7767","46.56600","3.88070","0.00155"
"7806","46.80000","3.90019","0.00169"
"7845","47.03400","3.91968","0.00148"
"7884","47.26800","3.93911","0.00229"
"7923","47.50200","3.95872","0.00185"
"7962","47.73600","3.97816","0.00178"
"8001","47.97000","3.99771","0.00150"
"8040","48.20400","4.01720","0.00143"
"8079","48.43800","4.03663","0.00169"
"8118","48.67200","4.05618","0.00201"
"8157","48.90600","4.07567","0.00174"
"8196","49.14000","4.09522","0.00181"
"8235","49.37400","4.11466","0.00186"
"8274","49.60800","4.13421","0.00157"
"8313","49.84200","4.15370","0.00149"
"8352","50.07600","4.17319","0.00181"
"8391","50.31000","4.19268","0.00193"
"8430","50.54400","4.21217","0.00129"
"8469","50.77800","4.23166","0.00208"
"8508","51.01200","4.25116","0.00196"
"8547","51.24600","4.27071","0.00216"
"8586","51.48000","4.29014","0.00201"
"8625","51.71400","4.30969","0.00215"
"8664","51.94800","4.32918","0.00181"
"8703","52.18200","4.34861","0.00192"
"8742","52.41600","4.36822","0.00212"
"8781","52.65000","4.38771","0.00188"
"8820","52.88400","4.40721","0.00195"
"8859","53.11800","4.42670","0.00231"
"8898","53.35200","4.44619","0.00134"
"8937","53.58600","4.46568","0.00210"
"8976","53.82000","4.48517","0.00175"
"9015","54.05400","4.50466","0.00191"
"9054","54.28800","4.52415","0.00180"
"9093","54.52200","4.54371","0.00217"
"9132","54.75600","4.56314","0.00203"
"9171","54.99000","4.58275","0.00194"
"9210","55.22400","4.60218","0.00173"
"9249","55.45800","4.62167","0.00165"
"9288","55.69200","4.64122","0.00227"
"9327","55.92600","4.66059","0.00194"
"9366","56.16000","4.68021","0.00189"
"9405","56.39400","4.69964","0.00221"
"9444","56.62800","4.71925","0.00194"
"9483","56.86200","4.73868","0.00236"
"9522","57.09600","4.75817","0.00213"
"9561","57.33000","4.77766","0.00212"
"9600","57.56400","4.79715","0.00230"
"9639","57.79800","4.81664","0.00203"
"9678","58.03200","4.83614","0.00215"
"9717","58.26600","4.85569","0.00196"
"9756","58.50000","4.87512","0.00172"
"9795","58.73400","4.89467","0.00184"
"9834","58.96800","4.91422","0.00237"
"9873","59.20200","4.93365","0.00216"
"9912","59.43600","4.95320","0.00194"
"9951","59.67000","4.97264","0.00231"
"9990","59.90400","4.99219","0.00211"
"10029","60.13800","5.01168","0.00215"
"10068","60.37200","5.03117","0.00225"
"10107","60.60600","5.05066","0.00200"
"10146","60.84000","5.07015","0.00192"
"10185","61.07400","5.08964","0.00244"
"10224","61.30800","5.10914","0.00202"
"10263","61.54200","5.12869","0.00194"
"10302","61.77600","5.14818","0.00189"
"10341","62.01000","5.16773","0.00216"
"10380","62.24400","5.18716","0.00221"
"10419","62.47800","5.20665","0.00254"
"10458","62.71200","5.22620","0.00248"
"10497","62.94600","5.24564","0.00229"
"10536","63.18000","5.26519","0.00225"
"10575","63.41400","5.28462","0.00258"
"10614","63.64800","5.30417","0.00180"
"10653","63.88200","5.32366","0.00227"
"10692","64.11600","5.34321","0.00287"
"10731","64.35000","5.36264","0.00194"
"10770","64.58400","5.38219","0.00168"
"10809","64.81800","5.40169","0.00180"
"10848","65.05200","5.42112","0.00165"
"10887","65.28600","5.44073","0.00214"
"10926","65.52000","5.46016","0.00209"
"10965","65.75400","5.47971","0.00244"
"11004","65.98800","5.49914","0.00136"
"11043","66.22200","5.51869","0.00209"
"11082","66.45600","5.53824","0.00241"
"11121","66.69000","5.55762","0.00202"
"11160","66.92400","5.57717","0.00220"
"11199","67.15800","5.59666","0.00211"
"11238","67.39200","5.61621","0.00215"
"11277","67.62600","5.63570","0.00220"
"11316","67.86000","5.65519","0.00262"
"11355","68.09400","5.67474","0.00249"
"11394","68.32800","5.69418","0.00223"
"11433","68.56200","5.71367","0.00289"
"11472","68.79600","5.73316","0.00207"
"11511","69.03000","5.75277","0.00282"
"11550","69.26400","5.77220","0.00246"
"11589","69.49800","5.79163","0.00232"
"11628","69.73200","5.81118","0.00261"
"11667","69.96600","5.83068","0.00268"
"11706","70.20000","5.85023","0.00244"
"11745","70.43400","5.86966","0.00282"
"11784","70.66800","5.88915","0.00292"
"11823","70.90200","5.90870","0.00260"
"11862","71.13600","5.92813","0.00271"
"11901","71.37000","5.94762","0.00279"
"11940","71.60400","5.96717","0.00278"
"11979","71.83800","5.98667","0.00275"
"12018","72.07200","6.00616","0.00258"
"12057","72.30600","6.02565","0.00276"
"12096","72.54000","6.04520","0.00301"
"12135","72.77400","6.06475","0.00266"
"12174","73.00800","6.08412","0.00284"
"12213","73.24200","6.10367","0.00274"
"12252","73.47600","6.12323","0.00278"
"12291","73.71000","6.14260","0.00298"
"12330","73.94400","6.16215","0.00269"
"12369","74.17800","6.18164","0.00250"
"12408","74.41200","6.20125","0.00295"
"12447","74.64600","6.22068","0.00271"
"12486","74.88000","6.24017","0.00286"
"12525","75.11400","6.25967","0.00320"
"12564","75.34800","6.27922","0.00296"
"12603","75.58200","6.29871","0.00271"
"12642","75.81600","6.31814","0.00282"
"12681","76.05000","6.33769","0.00301"
"12720","76.28400","6.35712","0.00276"
"12759","76.51800","6.37667","0.00302"
"12798","76.75200","6.39616","0.00324"
"12837","76.98600","6.41566","0.00289"
"12876","77.22000","6.43521","0.00302"
"12915","77.45400","6.45464","0.00335"
"12954","77.68800","6.47419","0.00292"
"12993","77.92200","6.49368","0.00297"
"13032","78.15600","6.51317","0.00323"
"13071","78.39000","6.53266","0.00285"
"13110","78.62400","6.55216","0.00309"
"13149","78.85800","6.57171","0.00365"
"13188","79.09200","6.59114","0.00360"
"13227","79.32600","6.61063","0.00328"
"13266","79.56000","6.63018","0.00364"
"13305","79.79400","6.64973","0.00295"
"13344","80.02800","6.66916","0.00303"
"13383","80.26200","6.68871","0.00280"
"13422","80.49600","6.70827","0.00354"
"13461","80.73000","6.72764","0.00349"
"13500","80.96400","6.74719","0.00328"
"13539","81.19800","6.76662","0.00371"
"13578","81.43200","6.78623","0.00345"
"13617","81.66600","6.80566","0.00331"
"13656","81.90000","6.82516","0.00238"
"13695","82.13400","6.84471","0.00256"
"13734","82.36800","6.86420","0.00249"
"13773","82.60200","6.88369","0.00293"
"13812","82.83600","6.90312","0.00298"
"13851","83.07000","6.92273","0.00282"
"13890","83.30400","6.94216","0.00301"
"13929","83.53800","6.96171","0.00241"
"13968","83.77200","6.98115","0.00242"
"14007","84.00600","7.00064","0.00262"
"14046","84.24000","7.02019","0.00246"
"14085","84.47400","7.03956","0.00292"
"14124","84.70800","7.05917","0.00286"
"14163","84.94200","7.07866","0.00293"
"14202","85.17600","7.09821","0.00322"
"14241","85.41000","7.11770","0.00324"
"14280","85.64400","7.13720","0.00219"
"14319","85.87800","7.15669","0.00256"
"14358","86.11200","7.17618","0.00227"
"14397","86.34600","7.19567","0.00128"
"14436","86.58000","7.21510","0.00183"
"14475","86.81400","7.23465","0.00143"
"14514","87.04800","7.25415","0.00208"
"14553","87.28200","7.27370","0.00166"
"14592","87.51600","7.29319","0.00174"
"14631","87.75000","7.31268","0.00206"
"14670","87.98400","7.33223","0.00204"
"14709","88.21800","7.35160","0.00188"
"14748","88.45200","7.37115","0.00228"
"14787","88.68600","7.39070","0.00212"
"14826","88.92000","7.41020","0.00204"
"14865","89.15400","7.42969","0.00227"
"14904","89.38800","7.44918","0.00212"
"14943","89.62200","7.46867","0.00238"
"14982","89.85600","7.48816","0.00213"
"15021","90.09000","7.50765","0.00236"
"15060","90.32400","7.52714","0.00199"
"15099","90.55800","7.54669","0.00215"
"15138","90.79200","7.56619","0.00233"
"15177","91.02600","7.58568","0.00259"
"15216","91.26000","7.60523","0.00308"
"15255","91.49400","7.62460","0.00276"
"15294","91.72800","7.64421","0.00271"
"15333","91.96200","7.66364","0.00237"
"15372","92.19600","7.68319","0.00247"
"15411","92.43000","7.70269","0.00261"
"15450","92.66400","7.72218","0.00277"
"15489","92.89800","7.74167","0.00236"
"15528","93.13200","7.76116","0.00250"
"15567","93.36600","7.78071","0.00297"
"15606","93.60000","7.80014","0.00246"
"15645","93.83400","7.81969","0.00241"
"15684","94.06800","7.83919","0.00287"
"15723","94.30200","7.85874","0.00270"
"15762","94.53600","7.87817","0.00236"
"15801","94.77000","7.89766","0.00261"
"15840","95.00400","7.91721","0.00285"
"15879","95.23800","7.93658","0.00340"
"15918","95.47200","7.95619","0.00315"
"15957","95.70600","7.97568","0.00337"
"15996","95.94000","7.99524","0.00329"
"16035","96.17400","8.01467","0.00289"
"16074","96.40800","8.03416","0.00275"
"16113","96.64200","8.05365","0.00288"
"16152","96.87600","8.07314","0.00349"
"16191","97.11000","8.09269","0.00287"
"16230","97.34400","8.11212","0.00260"
"16269","97.57800","8.13173","0.00328"
"16308","97.81200","8.15117","0.00320"
"16347","98.04600","8.17072","0.00309"
"16386","98.28000","8.19021","0.00285"
"16425","98.51400","8.20970","0.00336"
"16464","98.74800","8.22919","0.00266"
"16503","98.98200","8.24862","0.00294"
"16542","99.21600","8.26818","0.00310"
"16581","99.45000","8.28767","0.00263"
"16620","99.68400","8.30722","0.00222"
"16659","99.91800","8.32671","0.00300"
"16698","100.15200","8.34620","0.00304"
"16737","100.38600","8.36569","0.00287"
"16776","100.62000","8.38518","0.00267"
"16815","100.85400","8.40467","0.00331"
"16854","101.08800","8.42411","0.00274"
"16893","101.32200","8.44372","0.00283"
"16932","101.55600","8.46315","0.00322"
"16971","101.79000","8.48270","0.00335"
"17010","102.02400","8.50219","0.00345"
"17049","102.25800","8.52168","0.00373"
"17088","102.49200","8.54117","0.00409"
"17127","102.72600","8.56067","0.00323"
"17166","102.96000","8.58016","0.00360"
"17205","103.19400","8.59971","0.00354"
"17244","103.42800","8.61920","0.00367"
"17283","103.66200","8.63869","0.00369"
"17322","103.89600","8.65818","0.00398"
"17361","104.13000","8.67767","0.00428"
"17400","104.36400","8.69717","0.00406"
"17439","104.59800","8.71666","0.00398"
"17478","104.83200","8.73615","0.00438"
"17517","105.06600","8.75576","0.00349"
"17556","105.30000","8.77513","0.00424"
"17595","105.53400","8.79468","0.00425"
"17634","105.76800","8.81417","0.00332"
"17673","106.00200","8.83366","0.00367"
"17712","106.23600","8.85316","0.00433"
"17751","106.47000","8.87265","0.00434"
"17790","106.70400","8.89220","0.00424"
"17829","106.93800","8.91169","0.00425"
"17868","107.17200","8.93124","0.00484"
"17907","107.40600","8.95067","0.00395"
"17946","107.64000","8.97016","0.00484"
"17985","107.87400","8.98966","0.00427"
"18024","108.10800","9.00915","0.00452"
"18063","108.34200","9.02876","0.00462"
"18102","108.57600","9.04813","0.00441"
"18141","108.81000","9.06774","0.00473"
"18180","109.04400","9.08717","0.00459"
"18219","109.27800","9.10666","0.00494"
"18258","109.51200","9.12615","0.00484"
"18297","109.74600","9.14559","0.00489"
"18336","109.98000","9.16520","0.00489"
"18375","110.21400","9.18463","0.00506"
"18414","110.44800","9.20418","0.00455"
"18453","110.68200","9.22367","0.00485"
"18492","110.91600","9.24322","0.00570"
"18531","111.15000","9.26271","0.00524"
"18570","111.38400","9.28215","0.00532"
"18609","111.61800","9.30170","0.00504"
"18648","111.85200","9.32113","0.00566"
"18687","112.08600","9.34074","0.00558"
"18726","112.32000","9.36017","0.00556"
"18765","112.55400","9.37960","0.00572"
"18804","112.78800","9.39921","0.00587"
"18843","113.02200","9.41864","0.00559"
"18882","113.25600","9.43820","0.00595"
"18921","113.49000","9.45763","0.00579"
"18960","113.72400","9.47718","0.00556"
"18999","113.95800","9.49667","0.00611"
"19038","114.19200","9.51616","0.00556"
"19077","114.42600","9.53565","0.00582"
"19116","114.66000","9.55520","0.00635"
"19155","114.89400","9.57470","0.00639"
"19194","115.12800","9.59413","0.00639"
"19233","115.36200","9.61374","0.00601"
"19272","115.59600","9.63317","0.00651"
"19311","115.83000","9.65272","0.00572"
"19350","116.06400","9.67215","0.00547"
"19389","116.29800","9.69164","0.00620"
"19428","116.53200","9.71120","0.00622"
"19467","116.76600","9.73063","0.00615"
"19506","117.00000","9.75018","0.00583"
"19545","117.23400","9.76961","0.00600"
"19584","117.46800","9.78922","0.00578"
"19623","117.70200","9.80865","0.00575"
"19662","117.93600","9.82820","0.00602"
"19701","118.17000","9.84769","0.00612"
"19740","118.40400","9.86719","0.00406"
"19779","118.63800","9.88674","0.00452"
"19818","118.87200","9.90611","0.00425"
"19857","119.10600","9.92572","0.00453"
"19896","119.34000","9.94515","0.00548"
"19935","119.57400","9.96470","0.00505"
"19974","119.80800","9.98419","0.00521"
"20013","120.04200","10.00369","0.00496"
"20052","120.27600","10.02324","0.00477"
"20091","120.51000","10.04255","0.00444"
"20130","120.74400","10.06216","0.00436"
"20169","120.97800","10.08165","0.00395"
"20208","121.21200","10.10120","0.00416"
"20247","121.44600","10.12069","0.00456"
"20286","121.68000","10.14019","0.00386"
"20325","121.91400","10.15968","0.00411"
"20364","122.14800","10.17917","0.00451"
"20403","122.38200","10.19866","0.00450"
"20442","122.61600","10.21815","0.00508"
"20481","122.85000","10.23770","0.00437"
"20520","123.08400","10.25713","0.00450"
"20559","123.31800","10.27668","0.00486"
"20598","123.55200","10.29624","0.00391"
"20637","123.78600","10.31567","0.00487"
"20676","124.02000","10.33522","0.00442"
"20715","124.25400","10.35465","0.00424"
"20754","124.48800","10.37420","0.00477"
"20793","124.72200","10.39363","0.00477"
"20832","124.95600","10.41318","0.00457"
"20871","125.19000","10.43268","0.00512"
"20910","125.42400","10.45217","0.00431"
"20949","125.65800","10.47166","0.00452"
"20988","125.89200","10.49109","0.00457"
"21027","126.12600","10.51076","0.00507"
"21066","126.36000","10.53019","0.00442"
"21105","126.59400","10.54968","0.00471"
"21144","126.82800","10.56918","0.00486"
"21183","127.06200","10.58867","0.00493"
"21222","127.29600","10.60822","0.00494"
"21261","127.53000","10.62759","0.00537"
"21300","127.76400","10.64720","0.00534"
"21339","127.99800","10.66663","0.00521"
"21378","128.23200","10.68618","0.00520"
"21417","128.46600","10.70568","0.00571"
"21456","128.70000","10.72517","0.00536"
"21495","128.93400","10.74466","0.00542"
"21534","129.16800","10.76415","0.00575"
"21573","129.40200","10.78364","0.00574"
"21612","129.63600","10.80313","0.00607"
"21651","129.87000","10.82274","0.00608"
"21690","130.10400","10.84217","0.00612"
"21729","130.33800","10.86173","0.00622"
"21768","130.57200","10.88116","0.00631"
"21807","130.80600","10.90071","0.00630"
"21846","131.04000","10.92020","0.00651"
"21885","131.27400","10.93963","0.00693"
"21924","131.50800","10.95918","0.00697"
"21963","131.74200","10.97867","0.00710"
"22002","131.97600","10.99817","0.00719"
"22041","132.21000","11.01772","0.00696"
"22080","132.44400","11.03721","0.00738"
"22119","132.67800","11.05670","0.00712"
"22158","132.91200","11.07619","0.00760"
"22197","133.14600","11.09568","0.00762"
"22236","133.38000","11.11511","0.00770"
"22275","133.61400","11.13472","0.00804"
"22314","133.84800","11.15416","0.00818"
"22353","134.08200","11.17371","0.00806"
"22392","134.31600","11.19320","0.00846"
"22431","134.55000","11.21269","0.00857"
"22470","134.78400","11.23218","0.00820"
"22509","135.01800","11.25161","0.00825"
"22548","135.25200","11.27116","0.00879"
"22587","135.48600","11.29066","0.00949"
"22626","135.72000","11.31015","0.00866"
"22665","135.95400","11.32964","0.00857"
"22704","136.18800","11.34919","0.00803"
"22743","136.42200","11.36868","0.00894"
"22782","136.65600","11.38817","0.00960"
"22821","136.89000","11.40772","0.00956"
"22860","137.12400","11.42716","0.01019"
"22899","137.35800","11.44670","0.00945"
"22938","137.59200","11.46614","0.01012"
"22977","137.82600","11.48569","0.00954"
"23016","138.06000","11.50518","0.00968"
"23055","138.29400","11.52467","0.00971"
"23094","138.52800","11.54422","0.00965"
"23133","138.76200","11.56365","0.01061"
"23172","138.99600","11.58321","0.00960"
"23211","139.23000","11.60270","0.01083"
"23250","139.46400","11.62219","0.01045"
"23289","139.69800","11.64162","0.01111"
"23328","139.93200","11.66117","0.01107"
"23367","140.16600","11.68066","0.01135"
"23406","140.40000","11.70015","0.01145"
"23445","140.63400","11.71976","0.01132"
"23484","140.86800","11.73914","0.01182"
"23523","141.10200","11.75875","0.01201"
"23562","141.33600","11.77824","0.01219"
"23601","141.57000","11.79767","0.01130"
"23640","141.80400","11.81722","0.01233"
"23679","142.03800","11.83659","0.01236"
"23718","142.27200","11.85614","0.01255"
"23757","142.50600","11.87558","0.01309"
"23796","142.74000","11.89519","0.01260"
"23835","142.97400","11.91468","0.01309"
"23874","143.20800","11.93417","0.01334"
"23913","143.44200","11.95372","0.01369"
"23952","143.67600","11.97315","0.01333"
"23991","143.91000","11.99270","0.01341"
"24030","144.14400","12.01214","0.01410"
"24069","144.37800","12.03175","0.01412"
"24108","144.61200","12.05112","0.01455"
"24147","144.84600","12.07073","0.01453"
"24186","145.08000","12.09022","0.01522"
"24225","145.31400","12.10965","0.01490"
"24264","145.54800","12.12920","0.01545"
"24303","145.78200","12.14864","0.01517"
"24342","146.01600","12.16813","0.01575"
"24381","146.25000","12.18762","0.01656"
"24420","146.48400","12.20717","0.01662"
"24459","146.71800","12.22666","0.01680"
"24498","146.95200","12.24621","0.01659"
"24537","147.18600","12.26564","0.01773"
"24576","147.42000","12.28513","0.01788"
"24615","147.65400","12.30468","0.01820"
"24654","147.88800","12.32412","0.01863"
"24693","148.12200","12.34373","0.01881"
"24732","148.35600","12.36316","0.01917"
"24771","148.59000","12.38265","0.01850"
"24810","148.82400","12.40220","0.01918"
"24849","149.05800","12.42163","0.02031"
"24888","149.29200","12.44118","0.01930"
"24927","149.52600","12.46062","0.01963"
"24966","149.76000","12.48023","0.01961"
"25005","149.99400","12.49966","0.02014"
"25044","150.22800","12.51921","0.02020"
"25083","150.46200","12.53864","0.02022"
"25122","150.69600","12.55819","0.02093"
"25161","150.93000","12.57768","0.02111"
"25200","151.16400","12.59718","0.02081"
"25239","151.39800","12.61673","0.02154"
"25278","151.63200","12.63616","0.02164"
"25317","151.86600","12.65577","0.02292"
"25356","152.10000","12.67520","0.02236"
"25395","152.33400","12.69463","0.02317"
"25434","152.56800","12.71424","0.02425"
"25473","152.80200","12.73362","0.02420"
"25512","153.03600","12.75317","0.02468"
"25551","153.27000","12.77266","0.02437"
"25590","153.50400","12.79215","0.02514"
"25629","153.73800","12.81170","0.02492"
"25668","153.97200","12.83119","0.02521"
"25707","154.20600","12.85068","0.02491"
"25746","154.44000","12.87017","0.02533"
"25785","154.67400","12.88973","0.02511"
"25824","154.90800","12.90910","0.02552"
"25863","155.14200","12.92871","0.02507"
"25902","155.37600","12.94820","0.02169"
"25941","155.61000","12.96769","0.01803"
"25980","155.84400","12.98718","0.01925"
"26019","156.07800","13.00661","0.01978"
"26058","156.31200","13.02617","0.02083"
"26097","156.54600","13.04566","0.02051"
"26136","156.78000","13.06515","0.02150"
"26175","157.01400","13.08464","0.02185"
"26214","157.24800","13.10413","0.02258"
"26253","157.48200","13.12362","0.01938"
"26292","157.71600","13.14323","0.02018"
"26331","157.95000","13.16273","0.02060"
"26370","158.18400","13.18216","0.02092"
"26409","158.41800","13.20171","0.02058"
"26448","158.65200","13.22114","0.02150"
"26487","158.88600","13.24075","0.02155"
"26526","159.12000","13.26018","0.02175"
"26565","159.35400","13.27973","0.02223"
"26604","159.58800","13.29923","0.02313"
"26643","159.82200","13.31866","0.02297"
"26682","160.05600","13.33821","0.02249"
"26721","160.29000","13.35764","0.02278"
"26760","160.52400","13.37719","0.02397"
"26799","160.75800","13.39662","0.02381"
"26838","160.99200","13.41617","0.02569"
"26877","161.22600","13.43566","0.02485"
"26916","161.46000","13.45516","0.02542"
"26955","161.69400","13.47471","0.02615"
"26994","161.92800","13.49408","0.02641"
"27033","162.16200","13.51375","0.02655"
"27072","162.39600","13.53318","0.02741"
"27111","162.63000","13.55267","0.02737"
"27150","162.86400","13.57222","0.02842"
"27189","163.09800","13.59172","0.02877"
"27228","163.33200","13.61121","0.02849"
"27267","163.56600","13.63058","0.02901"
"27306","163.80000","13.65013","0.02836"
"27345","164.03400","13.66968","0.02922"
"27384","164.26800","13.68923","0.02957"
"27423","164.50200","13.70866","0.02990"
"27462","164.73600","13.72822","0.03020"
"27501","164.97000","13.74765","0.03075"
"27540","165.20400","13.76714","0.03142"
"27579","165.43800","13.78663","0.03134"
"27618","165.67200","13.80612","0.03209"
"27657","165.90600","13.82573","0.03213"
"27696","166.14000","13.84510","0.03216"
"27735","166.37400","13.86472","0.03162"
"27774","166.60800","13.88421","0.03177"
"27813","166.84200","13.90364","0.03286"
"27852","167.07600","13.92319","0.03301"
"27891","167.31000","13.94262","0.03312"
"27930","167.54400","13.96217","0.03237"
"27969","167.77800","13.98160","0.03242"
"28008","168.01200","14.00121","0.03309"
"28047","168.24600","14.02071","0.03312"
"28086","168.48000","14.04020","0.03379"
"28125","168.71400","14.05969","0.03367"
"28164","168.94800","14.07912","0.03392"
"28203","169.18200","14.09873","0.00115"
"28242","169.41600","14.11816","0.00312"
"28281","169.65000","14.13777","0.00576"
"28320","169.88400","14.15715","0.00053"
"28359","170.11800","14.17670","0.00231"
"28398","170.35200","14.19619","0.00130"
"28437","170.58600","14.21562","0.00243"
"28476","170.82000","14.23517","0.00318"
"28515","171.05400","14.25466","0.00159"
"28554","171.28800","14.27415","0.00181"
"28593","171.52200","14.29365","0.00257"
"28632","171.75600","14.31320","0.00287"
"28671","171.99000","14.33269","0.00184"
"28710","172.22400","14.35218","0.00282"
"28749","172.45800","14.37167","0.00142"
"28788","172.69200","14.39110","0.00435"
"28827","172.92600","14.41071","0.00188"
"28866","173.16000","14.43015","0.00232"
"28905","173.39400","14.44964","0.00243"
"28944","173.62800","14.46919","0.00344"
"28983","173.86200","14.48862","0.00280"
"29022","174.09600","14.50817","0.00265"
"29061","174.33000","14.52760","0.00259"
"29100","174.56400","14.54721","0.00366"
"29139","174.79800","14.56670","0.00304"
"29178","175.03200","14.58619","0.00260"
"29217","175.26600","14.60569","0.00302"
"29256","175.50000","14.62524","0.00373"
"29295","175.73400","14.64473","0.00433"
"29334","175.96800","14.66416","0.00327"
"29373","176.20200","14.68365","0.00303"
"29412","176.43600","14.70308","0.00459"
"29451","176.67000","14.72276","0.00424"
"29490","176.90400","14.74219","0.00371"
"29529","177.13800","14.76174","0.00368"
"29568","177.37200","14.78123","0.00338"
"29607","177.60600","14.80060","0.00024"
"29646","177.84000","14.82021","-0.00043"
"29685","178.07400","14.83964","-0.00001"
"29724","178.30800","14.85919","-0.00115"
"29763","178.54200","14.87862","-0.00128"
"29802","178.77600","14.89818","0.00053"
"29841","179.01000","14.91767","-0.00007"
"29880","179.24400","14.93722","-0.00059"
"29919","179.47800","14.95671","0.00018"
"29958","179.71200","14.97620","-0.00014"
"29997","179.94600","14.99569","-0.00049"
"30036","180.18000","15.01518","-0.00054"
"30075","180.41400","15.03474","0.00004"
"30114","180.64800","15.05411","0.00015"
"30153","180.88200","15.07366","0.00035"
"30192","181.11600","15.09321","-0.00028"
"30231","181.35000","15.11264","0.00067"
"30270","181.58400","15.13219","0.00035"
"30309","181.81800","15.15168","0.00062"
"30348","182.05200","15.17124","-0.00003"
"30387","182.28600","15.19067","0.00055"
"30426","182.52000","15.21022","0.00004"
"30465","182.75400","15.22965","0.00059"
"30504","182.98800","15.24914","0.00026"
"30543","183.22200","15.26869","0.00000"
"30582","183.45600","15.28813","0.00009"
"30621","183.69000","15.30768","0.00110"
"30660","183.92400","15.32717","0.00098"
"30699","184.15800","15.34672","0.00021"
"30738","184.39200","15.36621","0.00065"
"30777","184.62600","15.38564","0.00049"
"30816","184.86000","15.40519","0.00088"
"30855","185.09400","15.42462","0.00117"
"30894","185.32800","15.44417","-0.00008"
"30933","185.56200","15.46361","0.00114"
"30972","185.79600","15.48322","0.00099"
"31011","186.03000","15.50265","0.00092"
"31050","186.26400","15.52220","0.00125"
"31089","186.49800","15.54169","0.00047"
"31128","186.73200","15.56112","0.00102"
"31167","186.96600","15.58067","0.00128"
"31206","187.20000","15.60011","0.00106"
"31245","187.43400","15.61972","0.00053"
"31284","187.66800","15.63915","0.00111"
"31323","187.90200","15.65870","0.00089"
"31362","188.13600","15.67825","0.00109"
"31401","188.37000","15.69762","0.00078"
"31440","188.60400","15.71717","0.00091"
"31479","188.83800","15.73666","0.00120"
"31518","189.07200","15.75616","0.00136"
"31557","189.30600","15.77565","0.00147"
"31596","189.54000","15.79520","0.00119"
"31635","189.77400","15.81469","0.00111"
"31674","190.00800","15.83418","0.00174"
"31713","190.24200","15.85367","0.00143"
"31752","190.47600","15.87316","0.00114"
"31791","190.71000","15.89272","0.00108"
"31830","190.94400","15.91215","0.00127"
"31869","191.17800","15.93170","0.00162"
"31908","191.41200","15.95113","0.00139"
"31947","191.64600","15.97068","0.00119"
"31986","191.88000","15.99017","0.00124"
"32025","192.11400","16.00966","0.00149"
"32064","192.34800","16.02916","0.00154"
"32103","192.58200","16.04865","0.00191"
"32142","192.81600","16.06814","0.00148"
"32181","193.05000","16.08763","0.00193"
"32220","193.28400","16.10724","0.00139"
"32259","193.51800","16.12661","0.00103"
"32298","193.75200","16.14616","0.00095"
"32337","193.98600","16.16571","0.00128"
"32376","194.22000","16.18509","0.00163"
"32415","194.45400","16.20476","0.00128"
"32454","194.68800","16.22413","0.00112"
"32493","194.92200","16.24374","0.00132"
"32532","195.15600","16.26317","0.00187"
"32571","195.39000","16.28272","0.00125"
"32610","195.62400","16.30221","0.00141"
"32649","195.85800","16.32165","0.00190"
"32688","196.09200","16.34114","0.00174"
"32727","196.32600","16.36063","0.00130"
"32766","196.56000","16.38018","0.00186"
"32805","196.79400","16.39967","0.00126"
"32844","197.02800","16.41916","0.00169"
"32883","197.26200","16.43871","0.00121"
"32922","197.49600","16.45815","0.00136"
"32961","197.73000","16.47770","0.00129"
"33000","197.96400","16.49713","0.00168"
"33039","198.19800","16.51674","0.00160"
"33078","198.43200","16.53617","0.00178"
"33117","198.66600","16.55572","0.00192"
"33156","198.90000","16.57515","0.00232"
"33195","199.13400","16.59464","0.00204"
"33234","199.36800","16.61419","0.00180"
"33273","199.60200","16.63363","0.00186"
"33312","199.83600","16.65318","0.00167"
"33351","200.07000","16.67267","0.00207"
"33390","200.30400","16.69222","0.00129"
"33429","200.53800","16.71165","0.00240"
"33468","200.77200","16.73120","0.00177"
"33507","201.00600","16.75069","0.00200"
"33546","201.24000","16.77013","0.00230"
"33585","201.47400","16.78974","0.00178"
"33624","201.70800","16.80911","0.00212"
"33663","201.94200","16.82872","0.00175"
"33702","202.17600","16.84815","0.00249"
"33741","202.41000","16.86770","0.00215"
"33780","202.64400","16.88720","0.00242"
"33819","202.87800","16.90663","0.00222"
"33858","203.11200","16.92624","0.00211"
"33897","203.34600","16.94561","0.00222"
"33936","203.58000","16.96522","0.00171"
"33975","203.81400","16.98465","0.00191"
"34014","204.04800","17.00420","0.00168"
"34053","204.28200","17.02363","0.00161"
"34092","204.51600","17.04313","0.00193"
"34131","204.75000","17.06274","0.00190"
"34170","204.98400","17.08211","0.00204"
"34209","205.21800","17.10172","0.00175"
"34248","205.45200","17.12115","0.00223"
"34287","205.68600","17.14070","0.00236"
"34326","205.92000","17.16019","0.00190"
"34365","206.15400","17.17962","0.00204"
"34404","206.38800","17.19918","0.00235"
"34443","206.62200","17.21867","0.00229"
"34482","206.85600","17.23816","0.00177"
"34521","207.09000","17.25765","0.00211"
"34560","207.32400","17.27720","0.00132"
"34599","207.55800","17.29669","0.00262"
"34638","207.79200","17.31618","0.00185"
"34677","208.02600","17.33568","0.00207"
"34716","208.26000","17.35517","0.00206"
"34755","208.49400","17.37466","0.00204"
"34794","208.72800","17.39409","0.00235"
"34833","208.96200","17.41370","0.00196"
"34872","209.19600","17.43313","0.00171"
"34911","209.43000","17.45268","0.00156"
"34950","209.66400","17.47223","0.00187"
"34989","209.89800","17.49167","0.00208"
"35028","210.13200","17.51122","0.00212"
"35067","210.36600","17.53065","0.00259"
"35106","210.60000","17.55020","0.00249"
"35145","210.83400","17.56963","0.00203"
"35184","211.06800","17.58918","0.00258"
"35223","211.30200","17.60868","0.00201"
"35262","211.53600","17.62823","0.00224"
"35301","211.77000","17.64766","0.00203"
"35340","212.00400","17.66709","0.00278"
"35379","212.23800","17.68670","0.00212"
"35418","212.47200","17.70613","0.00258"
"35457","212.70600","17.72574","0.00217"
"35496","212.94000","17.74517","0.00247"
"35535","213.17400","17.76467","0.00245"
"35574","213.40800","17.78422","0.00239"
"35613","213.64200","17.80365","0.00214"
"35652","213.87600","17.82320","0.00238"
"35691","214.11000","17.84263","0.00235"
"35730","214.34400","17.86218","0.00280"
"35769","214.57800","17.88161","0.00269"
"35808","214.81200","17.90122","0.00284"
"35847","215.04600","17.92066","0.00214"
"35886","215.28000","17.94021","0.00251"
"35925","215.51400","17.95970","0.00353"
"35964","215.74800","17.97919","0.00229"
"36003","215.98200","17.99868","0.00215"
"36042","216.21600","18.01817","0.00235"
"36081","216.45000","18.03773","0.00268"
"36120","216.68400","18.05722","0.00277"
"36159","216.91800","18.07665","0.00257"
"36198","217.15200","18.09614","0.00295"
"36237","217.38600","18.11563","0.00334"
"36276","217.62000","18.13518","0.00313"
"36315","217.85400","18.15467","0.00308"
"36354","218.08800","18.17416","0.00318"
"36393","218.32200","18.19372","0.00277"
"36432","218.55600","18.21321","0.00327"
"36471","218.79000","18.23270","0.00336"
"36510","219.02400","18.25219","0.00334"
"36549","219.25800","18.27168","0.00351"
"36588","219.49200","18.29111","0.00393"
"36627","219.72600","18.31067","0.00386"
"36666","219.96000","18.33015","0.00324"
"36705","220.19400","18.34971","0.00344"
"36744","220.42800","18.36926","0.00319"
"36783","220.66200","18.38863","0.00365"
"36822","220.89600","18.40818","0.00326"
"36861","221.13000","18.42767","0.00338"
"36900","221.36400","18.44716","0.00353"
"36939","221.59800","18.46666","0.00395"
"36978","221.83200","18.48621","0.00340"
"37017","222.06600","18.50564","0.00352"
"37056","222.30000","18.52519","0.00375"
"37095","222.53400","18.54468","0.00338"
"37134","222.76800","18.56417","0.00419"
"37173","223.00200","18.58372","0.00400"
"37212","223.23600","18.60316","0.00385"
"37251","223.47000","18.62271","0.00414"
"37290","223.70400","18.64214","0.00423"
"37329","223.93800","18.66169","0.00421"
"37368","224.17200","18.68118","0.00436"
"37407","224.40600","18.70061","0.00434"
"37446","224.64000","18.72016","0.00455"
"37485","224.87400","18.73965","0.00461"
"37524","225.10800","18.75915","0.00435"
"37563","225.34200","18.77870","0.00473"
"37602","225.57600","18.79825","0.00486"
"37641","225.81000","18.81768","0.00504"
"37680","226.04400","18.83717","0.00474"
"37719","226.27800","18.85672","0.00519"
"37758","226.51200","18.87615","0.00485"
"37797","226.74600","18.89576","0.00502"
"37836","226.98000","18.91514","0.00491"
"37875","227.21400","18.93475","0.00466"
"37914","227.44800","18.95418","0.00498"
"37953","227.68200","18.97373","0.00597"
"37992","227.91600","18.99322","0.00599"
"38031","228.15000","19.01265","0.00577"
"38070","228.38400","19.03220","0.00637"
"38109","228.61800","19.05164","0.00600"
"38148","228.85200","19.07119","0.00638"
"38187","229.08600","19.09068","0.00644"
"38226","229.32000","19.11023","0.00713"
"38265","229.55400","19.12966","0.00708"
"38304","229.78800","19.14915","0.00716"
"38343","230.02200","19.16870","0.00738"
"38382","230.25600","19.18814","0.00721"
"38421","230.49000","19.20769","0.00765"
"38460","230.72400","19.22718","0.00803"
"38499","230.95800","19.24673","0.00808"
"38538","231.19200","19.26622","0.00839"
"38577","231.42600","19.28565","0.00845"
"38616","231.66000","19.30520","0.00905"
"38655","231.89400","19.32463","0.00850"
"38694","232.12800","19.34413","0.00891"
"38733","232.36200","19.36362","0.00890"
"38772","232.59600","19.38323","0.00896"
"38811","232.83000","19.40266","0.00837"
"38850","233.06400","19.42221","0.00927"
"38889","233.29800","19.44164","0.00938"
"38928","233.53200","19.46113","0.00973"
"38967","233.76600","19.48075","0.01005"
"39006","234.00000","19.50012","0.01044"
"39045","234.23400","19.51973","0.01084"
"39084","234.46800","19.53916","0.01094"
"39123","234.70200","19.55865","0.01200"
"39162","234.93600","19.57814","0.01200"
"39201","235.17000","19.59764","0.01254"
"39240","235.40400","19.61719","0.01205"
"39279","235.63800","19.63662","0.01311"
"39318","235.87200","19.65617","0.01276"
"39357","236.10600","19.67566","0.01285"
"39396","236.34000","19.69527","0.01286"
"39435","236.57400","19.71464","0.01383"
"39474","236.80800","19.73419","0.01373"
"39513","237.04200","19.75368","0.01433"
"39552","237.27600","19.77306","0.01419"
"39591","237.51000","19.79279","0.00494"
"39630","237.74400","19.81216","0.00336"
"39669","237.97800","19.83177","0.00258"
"39708","238.21200","19.85120","0.00301"
"39747","238.44600","19.87069","0.00201"
"39786","238.68000","19.89024","0.00344"
"39825","238.91400","19.90968","0.00328"
"39864","239.14800","19.92922","0.00303"
"39903","239.38200","19.94866","0.00229"
"39942","239.61600","19.96821","0.00327"
"39981","239.85000","19.98764","0.00396"
"40020","240.08400","20.00719","0.00271"
"40059","240.31800","20.02668","0.00266"
"40098","240.55200","20.04618","0.00299"
"40137","240.78600","20.06573","0.00313"
"40176","241.02000","20.08510","0.00347"
"40215","241.25400","20.10471","0.00429"
"40254","241.48800","20.12414","0.00409"
"40293","241.72200","20.14363","0.00389"
"40332","241.95600","20.16318","0.00438"
"40371","242.19000","20.18262","0.00443"
"40410","242.42400","20.20217","0.00480"
"40449","242.65800","20.22160","0.00445"
"40488","242.89200","20.24115","0.00455"
"40527","243.12600","20.26064","0.00508"
"40566","243.36000","20.28019","0.00568"
"40605","243.59400","20.29962","0.00570"
"40644","243.82800","20.31918","0.00613"
"40683","244.06200","20.33873","0.00612"
"40722","244.29600","20.35822","0.00632"
"40761","244.53000","20.37771","0.00505"
"40800","244.76400","20.39714","0.00457"
"40839","244.99800","20.41669","0.00486"
"40878","245.23200","20.43618","0.00496"
"40917","245.46600","20.45567","0.00503"
"40956","245.70000","20.47522","0.00498"
"40995","245.93400","20.49466","0.00466"
"41034","246.16800","20.51421","0.00496"
"41073","246.40200","20.53358","0.00545"
"41112","246.63600","20.55319","0.00621"
"41151","246.87000","20.57268","0.00562"
"41190","247.10400","20.59223","0.00551"
"41229","247.33800","20.61166","0.00601"
"41268","247.57200","20.63116","0.00652"
"41307","247.80600","20.65071","0.00715"
"41346","248.04000","20.67014","0.00693"
"41385","248.27400","20.68969","0.00789"
"41424","248.50800","20.70918","0.00825"
"41463","248.74200","20.72867","0.00891"
"41502","248.97600","20.74822","0.00875"
"41541","249.21000","20.76765","0.00891"
"41580","249.44400","20.78720","0.00933"
"41619","249.67800","20.80664","0.00997"
"41658","249.91200","20.82613","0.01018"
"41697","250.14600","20.84562","0.01081"
"41736","250.38000","20.86517","0.01065"
"41775","250.61400","20.88466","0.01100"
"41814","250.84800","20.90415","0.01099"
"41853","251.08200","20.92371","0.01085"
"41892","251.31600","20.94314","0.01015"
"41931","251.55000","20.96269","0.01015"
"41970","251.78400","20.98212","0.01097"
"42009","252.01800","21.00167","0.00947"
"42048","252.25200","21.02116","0.01015"
"42087","252.48600","21.04065","0.01087"
"42126","252.72000","21.06015","0.01068"
"42165","252.95400","21.07970","0.01074"
"42204","253.18800","21.09919","0.01095"
"42243","253.42200","21.11868","0.01024"
"42282","253.65600","21.13817","0.00795"
"42321","253.89000","21.15760","0.00887"
"42360","254.12400","21.17721","0.01010"
"42399","254.35800","21.19670","0.00999"
"42438","254.59200","21.21620","0.01013"
"42477","254.82600","21.23569","0.01155"
"42516","255.06000","21.25506","0.01248"
"42555","255.29400","21.27473","0.01257"
"42594","255.52800","21.29416","0.01344"
"42633","255.76200","21.31371","0.01441"
"42672","255.99600","21.33315","0.01507"
"42711","256.23000","21.35270","0.01546"
"42750","256.46400","21.37219","0.01622"
"42789","256.69800","21.39168","0.01787"
"42828","256.93200","21.41123","0.01844"
"42867","257.16600","21.43066","0.01906"
"42906","257.40000","21.45015","0.01896"
"42945","257.63400","21.46964","0.02072"
"42984","257.86800","21.48919","0.02112"
"43023","258.10200","21.50869","0.02183"
"43062","258.33600","21.52818","0.02300"
"43101","258.57000","21.54773","0.02308"
"43140","258.80400","21.56710","0.02452"
"43179","259.03800","21.58671","0.02506"
"43218","259.27200","21.60620","0.02645"
"43257","259.50600","21.62569","0.02721"
"43296","259.74000","21.64519","0.02760"
"43335","259.97400","21.66468","0.02795"
"43374","260.20800","21.68417","0.02894"
"43413","260.44200","21.70366","0.02959"
"43452","260.67600","21.72315","0.03032"
"43491","260.91000","21.74264","0.03069"
"43530","261.14400","21.76219","0.03145"
"43569","261.37800","21.78163","0.03181"
"43608","261.61200","21.80124","0.03259"
"43647","261.84600","21.82067","0.03277"
"43686","262.08000","21.84016","0.03348"
"43725","262.31400","21.85971","0.03421"
"43764","262.54800","21.87908","0.03459"
"43803","262.78200","21.89863","0.03496"
"43842","263.01600","21.91813","0.03555"
"43881","263.25000","21.93773","0.03617"
"43920","263.48400","21.95723","0.03633"
"43959","263.71800","21.97666","0.03684"
"43998","263.95200","21.99621","0.03710"
"44037","264.18600","22.01564","0.03726"
"44076","264.42000","22.03519","0.03732"
"44115","264.65400","22.05469","0.03756"
"44154","264.88800","22.07417","0.03799"
"44193","265.12200","22.09367","0.03826"
"44232","265.35600","22.11322","0.03850"
"44271","265.59000","22.13271","0.03792"
"44310","265.82400","22.15214","0.03815"
"44349","266.05800","22.17175","0.03834"
"44388","266.29200","22.19112","0.03906"
"44427","266.52600","22.21068","0.03921"
"44466","266.76000","22.23017","0.03953"
"44505","266.99400","22.24966","0.03965"
"44544","267.22800","22.26921","0.04012"
"44583","267.46200","22.28864","0.04065"
"44622","267.69600","22.30819","0.04127"
"44661","267.93000","22.32762","0.04119"
"44700","268.16400","22.34718","0.04149"
"44739","268.39800","22.36666","0.04211"
"44778","268.63200","22.38622","0.04276"
"44817","268.86600","22.40565","0.04297"
"44856","269.10000","22.42514","0.03733"
"44895","269.33400","22.44475","0.03708"
"44934","269.56800","22.46412","0.03880"
"44973","269.80200","22.48373","0.03824"
"45012","270.03600","22.50310","0.03892"
"45051","270.27000","22.52272","0.03945"
"45090","270.50400","22.54221","0.03920"
"45129","270.73800","22.56170","0.04020"
"45168","270.97200","22.58119","0.04044"
"45207","271.20600","22.60062","0.04063"
"45246","271.44000","22.62024","0.04175"
"45285","271.67400","22.63961","0.04119"
"45324","271.90800","22.65922","0.04200"
"45363","272.14200","22.67865","0.04261"
"45402","272.37600","22.69820","0.04240"
"45441","272.61000","22.71769","0.04370"
"45480","272.84400","22.73718","0.04394"
"45519","273.07800","22.75667","0.04443"
"45558","273.31200","22.77611","0.04555"
"45597","273.54600","22.79566","0.04517"
"45636","273.78000","22.81515","0.04630"
"45675","274.01400","22.83470","0.04638"
"45714","274.24800","22.85419","0.04779"
"45753","274.48200","22.87368","0.04916"
"45792","274.71600","22.89323","0.04843"
"45831","274.95000","22.91266","0.05002"
"45870","275.18400","22.93216","0.05038"
"45909","275.41800","22.95164","0.05177"
"45948","275.65200","22.97120","0.05259"
"45987","275.88600","22.99063","0.05247"
"46026","276.12000","23.01018","0.05414"
"46065","276.35400","23.02967","0.05468"
"46104","276.58800","23.04916","0.05546"
"46143","276.82200","23.06871","0.05715"
"46182","277.05600","23.08815","0.05720"
"46221","277.29000","23.10776","0.05849"
"46260","277.52400","23.12713","0.05894"
"46299","277.75800","23.14668","0.05999"
"46338","277.99200","23.16617","0.06131"
"46377","278.22600","23.18567","0.06092"
"46416","278.46000","23.20515","0.06236"
"46455","278.69400","23.22464","0.06244"
"46494","278.92800","23.24420","0.06397"
"46533","279.16200","23.26363","0.06449"
"46572","279.39600","23.28324","0.06557"
"46611","279.63000","23.30267","0.06659"
"46650","279.86400","23.32222","0.06693"
"46689","280.09800","23.34171","0.06901"
"46728","280.33200","23.36115","0.06946"
"46767","280.56600","23.38070","0.07021"
"46806","280.80000","23.40013","0.06935"
"46845","281.03400","23.41974","0.07049"
"46884","281.26800","23.43917","0.07087"
"46923","281.50200","23.45866","0.07181"
"46962","281.73600","23.47821","0.07280"
"47001","281.97000","23.49771","0.07336"
"47040","282.20400","23.51720","0.07463"
"47079","282.43800","23.53663","-0.00430"
"47118","282.67200","23.55618","0.00670"
"47157","282.90600","23.57561","-0.00225"
"47196","283.14000","23.59516","-0.00339"
"47235","283.37400","23.61471","-0.00052"
"47274","283.60800","23.63415","0.00180"
"47313","283.84200","23.65370","-0.00116"
"47352","284.07600","23.67313","-0.00091"
"47391","284.31000","23.69268","-0.00010"
"47430","284.54400","23.71217","0.00202"
"47469","284.77800","23.73172","-0.00052"
"47508","285.01200","23.75121","-0.00035"
"47547","285.24600","23.77065","0.00143"
"47586","285.48000","23.79013","0.00127"
"47625","285.71400","23.80969","-0.00034"
"47664","285.94800","23.82912","-0.00013"
"47703","286.18200","23.84867","0.00126"
"47717","286.26600","23.85566","0.00064"