File: Trajectories_together/170225_2Specimen_RawData_5.csv
"","V1","V2","V3"
"1","End date","2/25/2017",""
"2","Specimen label","1CT_6",""
"3","Maximum Load","0.03198","N"
"4","Time","Extension","Load"
"5","(s)","(mm)","(N)"
"6","0.00000","0.00000","0.00076"
"75","0.41400","0.03468","0.00024"
"144","0.82800","0.06918","-0.00011"
"213","1.24200","0.10368","0.00074"
"282","1.65600","0.13811","0.00059"
"351","2.07000","0.17261","0.00077"
"420","2.48400","0.20711","0.00091"
"489","2.89800","0.24167","0.00149"
"558","3.31200","0.27623","0.00192"
"627","3.72600","0.31067","0.00207"
"696","4.14000","0.34516","0.00194"
"765","4.55400","0.37966","0.00260"
"834","4.96800","0.41416","0.00150"
"903","5.38200","0.44866","0.00242"
"972","5.79600","0.48310","0.00289"
"1041","6.21000","0.51766","0.00365"
"1110","6.62400","0.55216","0.00354"
"1179","7.03800","0.58665","0.00407"
"1248","7.45200","0.62115","0.00447"
"1317","7.86600","0.65565","0.00447"
"1386","8.28000","0.69021","0.00444"
"1455","8.69400","0.72471","0.00485"
"1524","9.10800","0.75915","0.00552"
"1593","9.52200","0.79365","0.00521"
"1662","9.93600","0.82814","0.00648"
"1731","10.35000","0.86270","0.00487"
"1800","10.76400","0.89720","0.00590"
"1869","11.17800","0.93164","0.00563"
"1938","11.59200","0.96614","0.00615"
"2007","12.00600","1.00070","0.00556"
"2076","12.42000","1.03520","0.00528"
"2145","12.83400","1.06963","0.00630"
"2214","13.24800","1.10413","0.00578"
"2283","13.66200","1.13875","0.00613"
"2352","14.07600","1.17319","0.00583"
"2421","14.49000","1.20763","0.00632"
"2490","14.90400","1.24213","0.00625"
"2559","15.31800","1.27669","0.00624"
"2628","15.73200","1.31118","0.00682"
"2697","16.14600","1.34568","0.00668"
"2766","16.56000","1.38012","0.00609"
"2835","16.97400","1.41474","0.00643"
"2904","17.38800","1.44918","0.00660"
"2973","17.80200","1.48368","0.00650"
"3042","18.21600","1.51812","0.00737"
"3111","18.63000","1.55261","0.00675"
"3180","19.04400","1.58717","0.00698"
"3249","19.45800","1.62167","0.00688"
"3318","19.87200","1.65617","0.00666"
"3387","20.28600","1.69067","0.00730"
"3456","20.70000","1.72523","0.00719"
"3525","21.11400","1.75973","0.00724"
"3594","21.52800","1.79422","0.00720"
"3663","21.94200","1.82866","0.00796"
"3732","22.35600","1.86316","0.00747"
"3801","22.77000","1.89766","0.00732"
"3870","23.18400","1.93216","0.00749"
"3939","23.59800","1.96666","0.00787"
"4008","24.01200","2.00116","0.00745"
"4077","24.42600","2.03571","0.00768"
"4146","24.84000","2.07021","0.00793"
"4215","25.25400","2.10465","0.00740"
"4284","25.66800","2.13915","0.00764"
"4353","26.08200","2.17365","0.00735"
"4422","26.49600","2.20815","0.00756"
"4491","26.91000","2.24265","0.00747"
"4560","27.32400","2.27714","0.00815"
"4629","27.73800","2.31164","0.00735"
"4698","28.15200","2.34620","0.00714"
"4767","28.56600","2.38076","0.00750"
"4836","28.98000","2.41514","0.00760"
"4905","29.39400","2.44964","0.00802"
"4974","29.80800","2.48420","0.00799"
"5043","30.22200","2.51869","0.00791"
"5112","30.63600","2.55307","0.00835"
"5181","31.05000","2.58769","0.00797"
"5250","31.46400","2.62219","0.00823"
"5319","31.87800","2.65669","0.00795"
"5388","32.29200","2.69119","0.00800"
"5457","32.70600","2.72563","0.00786"
"5526","33.12000","2.76012","0.00825"
"5595","33.53400","2.79462","0.00875"
"5664","33.94800","2.82918","0.00821"
"5733","34.36200","2.86362","0.00792"
"5802","34.77600","2.89818","0.00833"
"5871","35.19000","2.93268","0.00834"
"5940","35.60400","2.96718","0.00798"
"6009","36.01800","3.00167","0.00837"
"6078","36.43200","3.03617","0.00788"
"6147","36.84600","3.07073","0.00862"
"6216","37.26000","3.10517","0.00789"
"6285","37.67400","3.13967","0.00850"
"6354","38.08800","3.17405","0.00790"
"6423","38.50200","3.20866","0.00850"
"6492","38.91600","3.24316","0.00827"
"6561","39.33000","3.27766","0.00808"
"6630","39.74400","3.31216","0.00819"
"6699","40.15800","3.34666","0.00845"
"6768","40.57200","3.38122","0.00881"
"6837","40.98600","3.41572","0.00849"
"6906","41.40000","3.45016","0.00822"
"6975","41.81400","3.48465","0.00792"
"7044","42.22800","3.51921","0.00817"
"7113","42.64200","3.55371","0.00854"
"7182","43.05600","3.58815","0.00849"
"7251","43.47000","3.62265","0.00750"
"7320","43.88400","3.65715","0.00815"
"7389","44.29800","3.69170","0.00762"
"7458","44.71200","3.72614","0.00779"
"7527","45.12600","3.76064","0.00749"
"7596","45.54000","3.79514","0.00785"
"7665","45.95400","3.82976","0.00846"
"7734","46.36800","3.86426","0.00799"
"7803","46.78200","3.89870","0.00839"
"7872","47.19600","3.93314","0.00739"
"7941","47.61000","3.96769","0.00785"
"8010","48.02400","4.00219","0.00783"
"8079","48.43800","4.03669","0.00764"
"8148","48.85200","4.07113","0.00776"
"8217","49.26600","4.10569","0.00826"
"8286","49.68000","4.14019","0.00763"
"8355","50.09400","4.17468","0.00801"
"8424","50.50800","4.20918","0.00789"
"8493","50.92200","4.24368","0.00818"
"8562","51.33600","4.27818","0.00812"
"8631","51.75000","4.31268","0.00818"
"8700","52.16400","4.34718","0.00864"
"8769","52.57800","4.38168","0.00800"
"8838","52.99200","4.41611","0.00757"
"8907","53.40600","4.45067","0.00847"
"8976","53.82000","4.48517","0.00822"
"9045","54.23400","4.51967","0.00858"
"9114","54.64800","4.55423","0.00793"
"9183","55.06200","4.58867","0.00831"
"9252","55.47600","4.62317","0.00843"
"9321","55.89000","4.65766","0.00881"
"9390","56.30400","4.69216","0.00832"
"9459","56.71800","4.72672","0.00856"
"9528","57.13200","4.76122","0.00822"
"9597","57.54600","4.79566","0.00884"
"9666","57.96000","4.83010","0.00840"
"9735","58.37400","4.86472","0.00821"
"9804","58.78800","4.89915","0.00789"
"9873","59.20200","4.93365","0.00852"
"9942","59.61600","4.96815","0.00874"
"10011","60.03000","5.00271","0.00866"
"10080","60.44400","5.03721","0.00870"
"10149","60.85800","5.07165","0.00917"
"10218","61.27200","5.10615","0.00911"
"10287","61.68600","5.14064","0.00900"
"10356","62.10000","5.17520","0.00932"
"10425","62.51400","5.20964","0.00877"
"10494","62.92800","5.24408","0.00940"
"10563","63.34200","5.27870","0.00921"
"10632","63.75600","5.31320","0.00923"
"10701","64.17000","5.34770","0.00869"
"10770","64.58400","5.38219","0.00941"
"10839","64.99800","5.41663","0.00943"
"10908","65.41200","5.45113","0.00898"
"10977","65.82600","5.48569","0.00837"
"11046","66.24000","5.52019","0.00883"
"11115","66.65400","5.55463","0.00903"
"11184","67.06800","5.58919","0.00829"
"11253","67.48200","5.62374","0.00893"
"11322","67.89600","5.65824","0.00838"
"11391","68.31000","5.69268","0.00918"
"11460","68.72400","5.72712","0.00883"
"11529","69.13800","5.76162","0.00871"
"11598","69.55200","5.79612","0.00952"
"11667","69.96600","5.83068","0.00931"
"11736","70.38000","5.86511","0.00864"
"11805","70.79400","5.89961","0.00900"
"11874","71.20800","5.93417","0.00883"
"11943","71.62200","5.96867","0.00957"
"12012","72.03600","6.00317","0.00877"
"12081","72.45000","6.03767","0.00912"
"12150","72.86400","6.07223","0.00928"
"12219","73.27800","6.10672","0.00917"
"12288","73.69200","6.14110","0.00949"
"12357","74.10600","6.17566","0.00888"
"12426","74.52000","6.21016","0.00992"
"12495","74.93400","6.24472","0.00932"
"12564","75.34800","6.27916","0.00930"
"12633","75.76200","6.31359","0.00919"
"12702","76.17600","6.34815","0.00975"
"12771","76.59000","6.38265","0.00914"
"12840","77.00400","6.41715","0.00970"
"12909","77.41800","6.45159","0.00978"
"12978","77.83200","6.48615","0.00969"
"13047","78.24600","6.52071","0.00990"
"13116","78.66000","6.55520","0.00923"
"13185","79.07400","6.58964","0.00933"
"13254","79.48800","6.62414","0.00962"
"13323","79.90200","6.65870","0.00929"
"13392","80.31600","6.69320","0.00980"
"13461","80.73000","6.72770","0.00955"
"13530","81.14400","6.76208","0.00935"
"13599","81.55800","6.79669","0.00963"
"13668","81.97200","6.83119","0.01032"
"13737","82.38600","6.86569","0.00955"
"13806","82.80000","6.90013","0.01019"
"13875","83.21400","6.93463","0.00946"
"13944","83.62800","6.96919","0.00965"
"14013","84.04200","7.00369","0.00983"
"14082","84.45600","7.03818","0.00948"
"14151","84.87000","7.07268","0.00992"
"14220","85.28400","7.10718","0.01002"
"14289","85.69800","7.14174","0.00941"
"14358","86.11200","7.17624","0.00912"
"14427","86.52600","7.21062","0.00935"
"14496","86.94000","7.24518","0.00953"
"14565","87.35400","7.27967","0.00996"
"14634","87.76800","7.31417","0.00930"
"14703","88.18200","7.34867","0.00952"
"14772","88.59600","7.38311","0.01015"
"14841","89.01000","7.41773","0.00962"
"14910","89.42400","7.45223","0.00938"
"14979","89.83800","7.48667","0.00935"
"15048","90.25200","7.52116","0.00947"
"15117","90.66600","7.55566","0.01013"
"15186","91.08000","7.59016","0.00939"
"15255","91.49400","7.62466","0.00983"
"15324","91.90800","7.65916","0.00988"
"15393","92.32200","7.69366","0.00974"
"15462","92.73600","7.72816","0.00966"
"15531","93.15000","7.76271","0.01024"
"15600","93.56400","7.79715","0.00949"
"15669","93.97800","7.83165","0.00973"
"15738","94.39200","7.86615","0.00979"
"15807","94.80600","7.90065","0.01005"
"15876","95.22000","7.93509","0.00945"
"15945","95.63400","7.96965","0.01034"
"16014","96.04800","8.00420","0.00964"
"16083","96.46200","8.03870","0.00988"
"16152","96.87600","8.07320","0.01038"
"16221","97.29000","8.10764","0.00985"
"16290","97.70400","8.14220","0.00996"
"16359","98.11800","8.17670","0.00978"
"16428","98.53200","8.21119","0.01008"
"16497","98.94600","8.24557","0.01016"
"16566","99.36000","8.28019","0.01013"
"16635","99.77400","8.31469","0.01003"
"16704","100.18800","8.34919","0.01050"
"16773","100.60200","8.38369","0.01041"
"16842","101.01600","8.41813","0.01028"
"16911","101.43000","8.45269","0.01084"
"16980","101.84400","8.48712","0.01024"
"17049","102.25800","8.52162","0.01036"
"17118","102.67200","8.55612","0.00994"
"17187","103.08600","8.59068","0.01061"
"17256","103.50000","8.62518","0.01012"
"17325","103.91400","8.65968","0.01033"
"17394","104.32800","8.69418","0.01070"
"17463","104.74200","8.72867","0.01059"
"17532","105.15600","8.76317","0.01061"
"17601","105.57000","8.79767","0.01055"
"17670","105.98400","8.83211","0.01146"
"17739","106.39800","8.86667","0.01070"
"17808","106.81200","8.90117","0.01030"
"17877","107.22600","8.93567","0.01073"
"17946","107.64000","8.97016","0.01035"
"18015","108.05400","9.00460","0.01100"
"18084","108.46800","9.03916","0.01099"
"18153","108.88200","9.07372","0.01047"
"18222","109.29600","9.10816","0.01055"
"18291","109.71000","9.14260","0.01055"
"18360","110.12400","9.17715","0.01061"
"18429","110.53800","9.21171","0.01109"
"18498","110.95200","9.24621","0.01096"
"18567","111.36600","9.28065","0.01110"
"18636","111.78000","9.31515","0.01085"
"18705","112.19400","9.34971","0.01128"
"18774","112.60800","9.38415","0.01047"
"18843","113.02200","9.41870","0.01089"
"18912","113.43600","9.45308","0.01097"
"18981","113.85000","9.48764","0.01030"
"19050","114.26400","9.52220","0.01101"
"19119","114.67800","9.55670","0.01098"
"19188","115.09200","9.59114","0.01140"
"19257","115.50600","9.62570","0.01082"
"19326","115.92000","9.66019","0.01104"
"19395","116.33400","9.69469","0.01115"
"19464","116.74800","9.72919","0.01121"
"19533","117.16200","9.76369","0.01121"
"19602","117.57600","9.79819","0.01130"
"19671","117.99000","9.83269","0.01079"
"19740","118.40400","9.86719","0.01145"
"19809","118.81800","9.90168","0.01140"
"19878","119.23200","9.93618","0.01119"
"19947","119.64600","9.97062","0.01113"
"20016","120.06000","10.00518","0.01174"
"20085","120.47400","10.03962","0.01117"
"20154","120.88800","10.07418","0.01146"
"20223","121.30200","10.10868","0.01182"
"20292","121.71600","10.14323","0.01147"
"20361","122.13000","10.17767","0.01154"
"20430","122.54400","10.21217","0.01222"
"20499","122.95800","10.24667","0.01182"
"20568","123.37200","10.28117","0.01148"
"20637","123.78600","10.31567","0.01218"
"20706","124.20000","10.35017","0.01187"
"20775","124.61400","10.38466","0.01144"
"20844","125.02800","10.41916","0.01145"
"20913","125.44200","10.45372","0.01169"
"20982","125.85600","10.48816","0.01200"
"21051","126.27000","10.52266","0.01203"
"21120","126.68400","10.55722","0.01276"
"21189","127.09800","10.59172","0.01198"
"21258","127.51200","10.62609","0.01215"
"21327","127.92600","10.66065","0.01214"
"21396","128.34000","10.69521","0.01212"
"21465","128.75400","10.72971","0.01205"
"21534","129.16800","10.76421","0.01246"
"21603","129.58200","10.79865","0.01193"
"21672","129.99600","10.83321","0.01250"
"21741","130.41000","10.86765","0.01247"
"21810","130.82400","10.90214","0.01284"
"21879","131.23800","10.93664","0.01253"
"21948","131.65200","10.97114","0.01231"
"22017","132.06600","11.00576","0.01248"
"22086","132.48000","11.04026","0.01254"
"22155","132.89400","11.07470","0.01229"
"22224","133.30800","11.10919","0.01239"
"22293","133.72200","11.14369","0.01289"
"22362","134.13600","11.17819","0.01328"
"22431","134.55000","11.21263","0.01280"
"22500","134.96400","11.24707","0.01325"
"22569","135.37800","11.28163","0.01273"
"22638","135.79200","11.31618","0.01291"
"22707","136.20600","11.35069","0.01302"
"22776","136.62000","11.38518","0.01382"
"22845","137.03400","11.41968","0.01350"
"22914","137.44800","11.45418","0.01347"
"22983","137.86200","11.48868","0.01336"
"23052","138.27600","11.52312","0.01404"
"23121","138.69000","11.55768","0.01414"
"23190","139.10400","11.59211","0.01440"
"23259","139.51800","11.62667","0.01389"
"23328","139.93200","11.66117","0.01419"
"23397","140.34600","11.69567","0.01440"
"23466","140.76000","11.73017","0.01419"
"23535","141.17400","11.76473","0.01417"
"23604","141.58800","11.79917","0.01434"
"23673","142.00200","11.83360","0.01457"
"23742","142.41600","11.86810","0.01490"
"23811","142.83000","11.90272","0.01485"
"23880","143.24400","11.93722","0.01503"
"23949","143.65800","11.97166","0.01490"
"24018","144.07200","12.00616","0.01494"
"24087","144.48600","12.04072","0.01489"
"24156","144.90000","12.07521","0.01517"
"24225","145.31400","12.10971","0.01579"
"24294","145.72800","12.14409","0.01525"
"24363","146.14200","12.17865","0.01612"
"24432","146.55600","12.21321","0.01647"
"24501","146.97000","12.24771","0.01595"
"24570","147.38400","12.28221","0.01570"
"24639","147.79800","12.31664","0.01614"
"24708","148.21200","12.35120","0.01646"
"24777","148.62600","12.38570","0.01694"
"24846","149.04000","12.42020","0.01681"
"24915","149.45400","12.45464","0.01685"
"24984","149.86800","12.48920","0.01691"
"25053","150.28200","12.52369","0.01717"
"25122","150.69600","12.55819","0.01727"
"25191","151.11000","12.59263","0.01752"
"25260","151.52400","12.62719","0.01832"
"25329","151.93800","12.66169","0.01780"
"25398","152.35200","12.69619","0.01795"
"25467","152.76600","12.73063","0.01853"
"25536","153.18000","12.76519","0.01871"
"25605","153.59400","12.79968","0.01912"
"25674","154.00800","12.83418","0.01855"
"25743","154.42200","12.86868","0.01921"
"25812","154.83600","12.90318","0.01954"
"25881","155.25000","12.93768","0.01974"
"25950","155.66400","12.97218","0.01980"
"26019","156.07800","13.00667","0.02023"
"26088","156.49200","13.04111","0.02082"
"26157","156.90600","13.07567","0.02045"
"26226","157.32000","13.11023","0.02016"
"26295","157.73400","13.14467","0.01400"
"26364","158.14800","13.17917","0.01075"
"26433","158.56200","13.21367","0.01209"
"26502","158.97600","13.24822","0.01344"
"26571","159.39000","13.28272","0.01567"
"26640","159.80400","13.31710","0.01531"
"26709","160.21800","13.35166","0.01413"
"26778","160.63200","13.38616","0.01303"
"26847","161.04600","13.42066","0.01303"
"26916","161.46000","13.45522","0.01226"
"26985","161.87400","13.48965","0.01372"
"27054","162.28800","13.52421","0.01442"
"27123","162.70200","13.55865","0.01476"
"27192","163.11600","13.59315","0.01510"
"27261","163.53000","13.62759","0.01462"
"27330","163.94400","13.66221","0.01420"
"27399","164.35800","13.69671","0.01420"
"27468","164.77200","13.73120","0.01470"
"27537","165.18600","13.76564","0.01474"
"27606","165.60000","13.80014","0.01526"
"27675","166.01400","13.83470","0.01548"
"27744","166.42800","13.86920","0.01623"
"27813","166.84200","13.90370","0.01599"
"27882","167.25600","13.93808","0.01603"
"27951","167.67000","13.97263","0.01597"
"28020","168.08400","14.00719","0.01605"
"28089","168.49800","14.04169","0.01612"
"28158","168.91200","14.07619","0.01659"
"28227","169.32600","14.11063","0.01716"
"28296","169.74000","14.14519","0.01738"
"28365","170.15400","14.17969","0.01784"
"28434","170.56800","14.21412","0.01760"
"28503","170.98200","14.24868","0.01799"
"28572","171.39600","14.28318","0.01802"
"28641","171.81000","14.31768","0.01788"
"28710","172.22400","14.35218","0.01813"
"28779","172.63800","14.38662","0.01875"
"28848","173.05200","14.42118","0.01835"
"28917","173.46600","14.45567","0.01889"
"28986","173.88000","14.49017","0.01911"
"29055","174.29400","14.52461","0.01940"
"29124","174.70800","14.55911","0.01966"
"29193","175.12200","14.59373","0.02008"
"29262","175.53600","14.62823","0.02008"
"29331","175.95000","14.66267","0.02071"
"29400","176.36400","14.69716","0.02112"
"29469","176.77800","14.73172","0.02138"
"29538","177.19200","14.76616","0.02173"
"29607","177.60600","14.80066","0.02260"
"29676","178.02000","14.83510","0.02297"
"29745","178.43400","14.86966","0.02315"
"29814","178.84800","14.90422","0.02401"
"29883","179.26200","14.93865","0.02436"
"29952","179.67600","14.97315","0.02532"
"30021","180.09000","15.00765","0.02570"
"30090","180.50400","15.04215","0.02633"
"30159","180.91800","15.07671","0.02664"
"30228","181.33200","15.11115","0.02692"
"30297","181.74600","15.14565","0.02773"
"30366","182.16000","15.18014","0.02920"
"30435","182.57400","15.21470","0.02955"
"30504","182.98800","15.24920","0.03022"
"30573","183.40200","15.28364","0.02989"
"30642","183.81600","15.31820","0.03101"
"30711","184.23000","15.35270","0.03084"
"30780","184.64400","15.38720","0.01150"
"30849","185.05800","15.42163","0.00374"
"30918","185.47200","15.45613","0.00763"
"30987","185.88600","15.49069","0.00445"
"31056","186.30000","15.52519","0.00813"
"31125","186.71400","15.55963","0.00434"
"31194","187.12800","15.59413","0.00824"
"31263","187.54200","15.62868","0.00511"
"31332","187.95600","15.66318","0.00664"
"31401","188.37000","15.69768","0.00638"
"31470","188.78400","15.73212","0.00645"
"31539","189.19800","15.76668","0.00670"
"31608","189.61200","15.80118","0.00637"
"31677","190.02600","15.83568","0.00688"
"31746","190.44000","15.87017","0.00731"
"31815","190.85400","15.90467","0.00697"
"31884","191.26800","15.93917","0.00693"
"31953","191.68200","15.97367","0.00737"
"32022","192.09600","16.00817","0.00730"
"32091","192.51000","16.04267","0.00781"
"32160","192.92400","16.07717","0.00758"
"32229","193.33800","16.11166","0.00799"
"32298","193.75200","16.14622","0.00796"
"32367","194.16600","16.18060","0.00783"
"32436","194.58000","16.21522","0.00807"
"32505","194.99400","16.24972","0.00769"
"32574","195.40800","16.28416","0.00811"
"32643","195.82200","16.31860","0.00802"
"32712","196.23600","16.35309","0.00653"
"32781","196.65000","16.38771","0.00603"
"32850","197.06400","16.42215","0.00584"
"32919","197.47800","16.45671","0.00661"
"32988","197.89200","16.49115","0.00565"
"33057","198.30600","16.52571","0.00604"
"33126","198.72000","16.56015","0.00678"
"33195","199.13400","16.59464","0.00639"
"33264","199.54800","16.62908","0.00664"
"33333","199.96200","16.66364","0.00687"
"33402","200.37600","16.69820","0.00625"
"33471","200.79000","16.73270","0.00573"
"33540","201.20400","16.76720","0.00673"
"33609","201.61800","16.80164","0.00620"
"33678","202.03200","16.83619","0.00658"
"33747","202.44600","16.87069","0.00638"
"33816","202.86000","16.90507","0.00695"
"33885","203.27400","16.93963","0.00652"
"33954","203.68800","16.97413","0.00674"
"34023","204.10200","17.00863","0.00687"
"34092","204.51600","17.04319","0.00627"
"34161","204.93000","17.07768","0.00668"
"34230","205.34400","17.11218","0.00679"
"34299","205.75800","17.14668","0.00687"
"34368","206.17200","17.18118","0.00709"
"34437","206.58600","17.21562","0.00661"
"34506","207.00000","17.25012","0.00720"
"34575","207.41400","17.28468","0.00674"
"34644","207.82800","17.31923","0.00697"
"34713","208.24200","17.35361","0.00707"
"34782","208.65600","17.38817","0.00720"
"34851","209.07000","17.42273","0.00687"
"34920","209.48400","17.45717","0.00751"
"34989","209.89800","17.49173","0.00712"
"35058","210.31200","17.52611","0.00694"
"35127","210.72600","17.56060","0.00725"
"35196","211.14000","17.59516","0.00733"
"35265","211.55400","17.62972","0.00778"
"35334","211.96800","17.66416","0.00735"
"35403","212.38200","17.69866","0.00703"
"35472","212.79600","17.73322","0.00720"
"35541","213.21000","17.76771","0.00735"
"35610","213.62400","17.80215","0.00705"
"35679","214.03800","17.83665","0.00771"
"35748","214.45200","17.87115","0.00763"
"35817","214.86600","17.90571","0.00708"
"35886","215.28000","17.94021","0.00775"
"35955","215.69400","17.97465","0.00752"
"36024","216.10800","18.00920","0.00727"
"36093","216.52200","18.04364","0.00730"
"36162","216.93600","18.07814","0.00710"
"36231","217.35000","18.11264","0.00739"
"36300","217.76400","18.14714","0.00790"
"36369","218.17800","18.18170","0.00782"
"36438","218.59200","18.21620","0.00807"
"36507","219.00600","18.25069","0.00748"
"36576","219.42000","18.28519","0.00777"
"36645","219.83400","18.31969","0.00810"
"36714","220.24800","18.35419","0.00769"
"36783","220.66200","18.38869","0.00763"
"36852","221.07600","18.42313","0.00831"
"36921","221.49000","18.45769","0.00762"
"36990","221.90400","18.49218","0.00760"
"37059","222.31800","18.52668","0.00806"
"37128","222.73200","18.56118","0.00795"
"37197","223.14600","18.59568","0.00769"
"37266","223.56000","18.63018","0.00827"
"37335","223.97400","18.66468","0.00685"
"37404","224.38800","18.69912","0.00700"
"37473","224.80200","18.73368","0.00741"
"37542","225.21600","18.76818","0.00708"
"37611","225.63000","18.80267","0.00755"
"37680","226.04400","18.83717","0.00715"
"37749","226.45800","18.87161","0.00764"
"37818","226.87200","18.90617","0.00728"
"37887","227.28600","18.94067","0.00721"
"37956","227.70000","18.97522","0.00737"
"38025","228.11400","19.00960","0.00725"
"38094","228.52800","19.04410","0.00655"
"38163","228.94200","19.07872","0.00689"
"38232","229.35600","19.11322","0.00749"
"38301","229.77000","19.14766","0.00674"
"38370","230.18400","19.18210","0.00751"
"38439","230.59800","19.21671","0.00722"
"38508","231.01200","19.25121","0.00698"
"38577","231.42600","19.28565","0.00699"
"38646","231.84000","19.32003","0.00711"
"38715","232.25400","19.35465","0.00666"
"38784","232.66800","19.38921","0.00708"
"38853","233.08200","19.42371","0.00820"
"38922","233.49600","19.45820","0.00766"
"38991","233.91000","19.49264","0.00805"
"39060","234.32400","19.52714","0.00675"
"39129","234.73800","19.56164","0.00732"
"39198","235.15200","19.59620","0.00748"
"39267","235.56600","19.63064","0.00751"
"39336","235.98000","19.66514","0.00762"
"39405","236.39400","19.69969","0.00758"
"39474","236.80800","19.73419","0.00765"
"39543","237.22200","19.76857","0.00746"
"39612","237.63600","19.80319","0.00757"
"39681","238.05000","19.83769","0.00786"
"39750","238.46400","19.87219","0.00777"
"39819","238.87800","19.90663","0.00776"
"39888","239.29200","19.94113","0.00742"
"39957","239.70600","19.97568","0.00687"
"40026","240.12000","20.01018","0.00712"
"40095","240.53400","20.04468","0.00739"
"40164","240.94800","20.07918","0.00722"
"40233","241.36200","20.11368","0.00742"
"40302","241.77600","20.14818","0.00708"
"40371","242.19000","20.18267","0.00715"
"40440","242.60400","20.21705","0.00766"
"40509","243.01800","20.25161","0.00782"
"40578","243.43200","20.28617","0.00741"
"40647","243.84600","20.32073","0.00745"
"40716","244.26000","20.35517","0.00783"
"40785","244.67400","20.38967","0.00736"
"40854","245.08800","20.42422","0.00804"
"40923","245.50200","20.45872","0.00753"
"40992","245.91600","20.49316","0.00806"
"41061","246.33000","20.52766","0.00781"
"41130","246.74400","20.56216","0.00805"
"41199","247.15800","20.59666","0.00869"
"41268","247.57200","20.63122","0.00772"
"41337","247.98600","20.66566","0.00786"
"41406","248.40000","20.70021","0.00813"
"41475","248.81400","20.73471","0.00821"
"41544","249.22800","20.76921","0.00770"
"41613","249.64200","20.80365","0.00863"
"41682","250.05600","20.83815","0.00794"
"41751","250.47000","20.87264","0.00779"
"41820","250.88400","20.90720","0.00845"
"41889","251.29800","20.94164","0.00836"
"41958","251.71200","20.97620","0.00848"
"42027","252.12600","21.01070","0.00802"
"42096","252.54000","21.04520","0.00804"
"42165","252.95400","21.07970","0.00824"
"42234","253.36800","21.11414","0.00892"
"42303","253.78200","21.14869","0.00896"
"42372","254.19600","21.18319","0.00918"
"42441","254.61000","21.21769","0.00885"
"42510","255.02400","21.25219","0.00874"
"42579","255.43800","21.28663","0.00993"
"42648","255.85200","21.32119","0.00880"
"42717","256.26600","21.35568","0.00890"
"42786","256.68000","21.39013","0.00896"
"42855","257.09400","21.42462","0.00934"
"42924","257.50800","21.45924","0.00919"
"42993","257.92200","21.49368","0.00969"
"43062","258.33600","21.52818","0.01006"
"43131","258.75000","21.56268","0.00969"
"43200","259.16400","21.59723","0.00937"
"43269","259.57800","21.63173","0.00985"
"43338","259.99200","21.66617","0.01020"
"43407","260.40600","21.70061","0.00987"
"43476","260.82000","21.73511","0.00996"
"43545","261.23400","21.76973","0.01026"
"43614","261.64800","21.80416","0.00975"
"43683","262.06200","21.83867","0.01018"
"43752","262.47600","21.87317","0.01054"
"43821","262.89000","21.90766","0.00964"
"43890","263.30400","21.94222","0.00951"
"43959","263.71800","21.97666","0.01022"
"44028","264.13200","22.01110","0.01045"
"44097","264.54600","22.04565","0.01040"
"44166","264.96000","22.08022","0.01075"
"44235","265.37400","22.11465","0.01037"
"44304","265.78800","22.14915","0.01100"
"44373","266.20200","22.18365","0.01055"
"44442","266.61600","22.21815","0.01065"
"44511","267.03000","22.25271","0.01034"
"44580","267.44400","22.28715","0.01035"
"44649","267.85800","22.32164","0.01105"
"44718","268.27200","22.35614","0.01082"
"44787","268.68600","22.39070","0.01008"
"44856","269.10000","22.42514","0.01031"
"44925","269.51400","22.45964","0.01096"
"44994","269.92800","22.49420","0.01060"
"45063","270.34200","22.52869","0.01037"
"45132","270.75600","22.56319","0.01143"
"45201","271.17000","22.59763","0.01098"
"45270","271.58400","22.63213","0.01138"
"45339","271.99800","22.66669","0.01107"
"45408","272.41200","22.70119","0.01060"
"45477","272.82600","22.73563","0.01116"
"45546","273.24000","22.77013","0.01096"
"45615","273.65400","22.80468","0.01124"
"45684","274.06800","22.83918","0.01124"
"45753","274.48200","22.87368","0.01120"
"45822","274.89600","22.90806","0.01173"
"45891","275.31000","22.94268","0.01099"
"45960","275.72400","22.97712","0.01084"
"46029","276.13800","23.01168","0.01076"
"46098","276.55200","23.04612","0.01076"
"46167","276.96600","23.08067","0.01044"
"46236","277.38000","23.11517","0.01101"
"46305","277.79400","23.14967","0.01131"
"46374","278.20800","23.18417","0.01058"
"46443","278.62200","23.21867","0.01108"
"46512","279.03600","23.25317","0.01100"
"46581","279.45000","23.28766","0.01101"
"46650","279.86400","23.32222","0.01095"
"46719","280.27800","23.35660","0.01130"
"46788","280.69200","23.39122","0.01121"
"46857","281.10600","23.42572","0.01125"
"46926","281.52000","23.46016","0.01153"
"46995","281.93400","23.49466","0.01135"
"47064","282.34800","23.52916","0.01172"
"47133","282.76200","23.56365","0.01193"
"47202","283.17600","23.59815","0.01195"
"47271","283.59000","23.63265","0.01161"
"47340","284.00400","23.66715","0.01201"
"47409","284.41800","23.70171","0.01202"
"47478","284.83200","23.73621","0.01186"
"47547","285.24600","23.77070","0.01187"
"47616","285.66000","23.80508","0.01246"
"47685","286.07400","23.83964","0.01245"
"47754","286.48800","23.87420","0.01206"
"47823","286.90200","23.90870","0.01243"
"47892","287.31600","23.94314","0.01305"
"47961","287.73000","23.97764","0.01236"
"48030","288.14400","24.01225","0.01229"
"48099","288.55800","24.04669","0.01263"
"48168","288.97200","24.08113","0.01300"
"48237","289.38600","24.11563","0.01284"
"48306","289.80000","24.15019","0.01304"
"48375","290.21400","24.18469","0.01295"
"48444","290.62800","24.21918","0.01273"
"48513","291.04200","24.25362","0.01320"
"48582","291.45600","24.28818","0.01380"
"48651","291.87000","24.32268","0.01339"
"48720","292.28400","24.35718","0.01329"
"48789","292.69800","24.39162","0.01384"
"48858","293.11200","24.42612","0.01371"
"48927","293.52600","24.46067","0.01386"
"48996","293.94000","24.49517","0.01407"
"49065","294.35400","24.52961","0.01427"
"49134","294.76800","24.56411","0.01409"
"49203","295.18200","24.59867","0.01413"
"49272","295.59600","24.63317","0.01468"
"49341","296.01000","24.66773","0.01465"
"49410","296.42400","24.70210","0.01473"
"49479","296.83800","24.73660","0.01498"
"49548","297.25200","24.77116","0.01455"
"49617","297.66600","24.80572","0.01524"
"49686","298.08000","24.84016","0.01497"
"49755","298.49400","24.87460","0.01518"
"49824","298.90800","24.90915","0.01539"
"49893","299.32200","24.94371","0.01537"
"49962","299.73600","24.97816","0.01533"
"50031","300.15000","25.01259","0.01500"
"50100","300.56400","25.04715","0.01536"
"50169","300.97800","25.08171","0.01624"
"50238","301.39200","25.11615","0.01625"
"50307","301.80600","25.15065","0.01596"
"50376","302.22000","25.18521","0.01655"
"50445","302.63400","25.21964","0.01623"
"50514","303.04800","25.25420","0.01689"
"50583","303.46200","25.28864","0.01632"
"50652","303.87600","25.32308","0.01654"
"50721","304.29000","25.35770","0.01679"
"50790","304.70400","25.39219","0.01700"
"50859","305.11800","25.42663","0.01675"
"50928","305.53200","25.46113","0.01659"
"50997","305.94600","25.49569","0.01691"
"51066","306.36000","25.53019","0.01547"
"51135","306.77400","25.56463","0.01469"
"51204","307.18800","25.59907","0.01471"
"51273","307.60200","25.63363","0.01527"
"51342","308.01600","25.66818","0.01607"
"51411","308.43000","25.70268","0.01564"
"51480","308.84400","25.73718","0.01602"
"51549","309.25800","25.77162","0.01520"
"51618","309.67200","25.80624","0.01607"
"51687","310.08600","25.84074","0.01633"
"51756","310.50000","25.87518","0.01627"
"51825","310.91400","25.90967","0.01636"
"51894","311.32800","25.94411","0.01565"
"51963","311.74200","25.97867","0.01617"
"52032","312.15600","26.01317","0.01633"
"52101","312.57000","26.04767","0.01575"
"52170","312.98400","26.08217","0.01610"
"52239","313.39800","26.11673","0.01567"
"52308","313.81200","26.15122","0.01596"
"52377","314.22600","26.18560","0.01577"
"52446","314.64000","26.22010","0.01427"
"52515","315.05400","26.25466","0.01393"
"52584","315.46800","26.28922","0.01067"
"52653","315.88200","26.32360","0.00887"
"52722","316.29600","26.35810","0.01162"
"52791","316.71000","26.39271","0.01194"
"52860","317.12400","26.42721","0.01066"
"52929","317.53800","26.46171","0.01023"
"52998","317.95200","26.49609","0.01076"
"53067","318.36600","26.53071","0.01005"
"53136","318.78000","26.56515","0.01048"
"53205","319.19400","26.59971","0.01040"
"53274","319.60800","26.63415","0.01034"
"53343","320.02200","26.66864","0.01063"
"53412","320.43600","26.70320","0.01064"
"53481","320.85000","26.73770","0.01037"
"53550","321.26400","26.77220","0.01078"
"53619","321.67800","26.80664","0.01010"
"53688","322.09200","26.84120","0.01025"
"53757","322.50600","26.87569","0.01012"
"53826","322.92000","26.91019","0.01000"
"53895","323.33400","26.94463","0.01071"
"53964","323.74800","26.97919","0.00976"
"54033","324.16200","27.01369","0.01008"
"54102","324.57600","27.04825","0.00995"
"54171","324.99000","27.08263","0.00982"
"54240","325.40400","27.11719","0.01007"
"54309","325.81800","27.15168","0.00950"
"54378","326.23200","27.18612","0.00965"
"54447","326.64600","27.22062","0.00958"
"54516","327.06000","27.25512","0.00974"
"54585","327.47400","27.28968","0.00955"
"54654","327.88800","27.32424","0.00947"
"54723","328.30200","27.35873","0.00944"
"54792","328.71600","27.39311","0.00955"
"54861","329.13000","27.42761","0.00998"
"54930","329.54400","27.46217","0.01008"
"54999","329.95800","27.49673","0.00910"
"55068","330.37200","27.53117","0.00942"
"55137","330.78600","27.56561","0.00996"
"55206","331.20000","27.60023","0.01004"
"55275","331.61400","27.63472","0.00980"
"55344","332.02800","27.66916","0.00944"
"55413","332.44200","27.70360","0.01073"
"55482","332.85600","27.73816","0.01030"
"55551","333.27000","27.77272","0.00970"
"55620","333.68400","27.80716","0.01006"
"55689","334.09800","27.84166","0.00998"
"55758","334.51200","27.87621","0.01051"
"55827","334.92600","27.91071","0.00977"
"55896","335.34000","27.94521","0.01022"
"55965","335.75400","27.97965","0.01033"
"56034","336.16800","28.01414","0.01085"
"56103","336.58200","28.04864","0.01023"
"56172","336.99600","28.08320","0.01063"
"56241","337.41000","28.11764","0.01066"
"56310","337.82400","28.15214","0.01063"
"56379","338.23800","28.18670","0.01085"
"56448","338.65200","28.22114","0.01105"
"56517","339.06600","28.25570","0.01082"
"56586","339.48000","28.29008","0.01108"
"56655","339.89400","28.32463","0.01096"
"56724","340.30800","28.35919","0.01073"
"56793","340.72200","28.39369","0.01075"
"56862","341.13600","28.42813","0.01117"
"56931","341.55000","28.46263","0.01164"
"57000","341.96400","28.49718","0.01173"
"57069","342.37800","28.53168","0.01145"
"57138","342.79200","28.56618","0.01150"
"57207","343.20600","28.60062","0.01092"
"57276","343.62000","28.63512","0.01181"
"57345","344.03400","28.66968","0.01143"
"57414","344.44800","28.70418","0.01123"
"57483","344.86200","28.73862","0.01144"
"57552","345.27600","28.77317","0.01146"
"57621","345.69000","28.80767","0.01199"
"57690","346.10400","28.84223","0.01135"
"57759","346.51800","28.87667","0.01133"
"57828","346.93200","28.91111","0.01144"
"57897","347.34600","28.94567","0.01152"
"57966","347.76000","28.98017","0.01106"
"58035","348.17400","29.01467","0.01093"
"58104","348.58800","29.04916","0.01103"
"58173","349.00200","29.08372","0.01143"
"58242","349.41600","29.11822","0.01095"
"58311","349.83000","29.15266","0.01032"
"58380","350.24400","29.18710","0.01019"
"58449","350.65800","29.22166","0.00983"
"58518","351.07200","29.25621","0.00787"
"58587","351.48600","29.29065","0.00688"
"58656","351.90000","29.32515","0.00758"
"58725","352.31400","29.35959","0.00698"
"58794","352.72800","29.39421","0.00711"
"58863","353.14200","29.42871","0.00765"
"58932","353.55600","29.46315","0.00715"
"59001","353.97000","29.49765","0.00750"
"59070","354.38400","29.53214","0.00725"
"59139","354.79800","29.56664","0.00738"
"59208","355.21200","29.60120","0.00776"
"59277","355.62600","29.63564","0.00766"
"59346","356.04000","29.67020","0.00815"
"59415","356.45400","29.70470","0.00815"
"59484","356.86800","29.73925","0.00783"
"59553","357.28200","29.77363","0.00845"
"59622","357.69600","29.80813","0.00812"
"59691","358.11000","29.84269","0.00836"
"59760","358.52400","29.87719","0.00777"
"59829","358.93800","29.91163","0.00830"
"59898","359.35200","29.94607","0.00851"
"59967","359.76600","29.98069","0.00819"
"60036","360.18000","30.01524","0.00848"
"60105","360.59400","30.04968","0.00831"
"60174","361.00800","30.08412","0.00862"
"60243","361.42200","30.11868","0.00843"
"60312","361.83600","30.15318","0.00863"
"60381","362.25000","30.18768","0.00838"
"60450","362.66400","30.22212","0.00823"
"60519","363.07800","30.25661","0.00907"
"60588","363.49200","30.29117","0.00911"
"60657","363.90600","30.32567","0.00860"
"60726","364.32000","30.36023","0.00837"
"60795","364.73400","30.39461","0.00925"
"60864","365.14800","30.42911","0.00893"
"60933","365.56200","30.46366","0.00977"
"61002","365.97600","30.49822","0.00917"
"61071","366.39000","30.53254","0.00945"
"61140","366.80400","30.56716","0.00944"
"61209","367.21800","30.60166","0.00949"
"61278","367.63200","30.63616","0.00942"
"61347","368.04600","30.67066","0.00978"
"61416","368.46000","30.70516","0.00970"
"61485","368.87400","30.73965","0.00929"
"61554","369.28800","30.77409","0.00956"
"61623","369.70200","30.80865","0.00924"
"61692","370.11600","30.84315","0.01001"
"61761","370.53000","30.87765","0.01014"
"61830","370.94400","30.91221","0.01028"
"61899","371.35800","30.94670","0.00949"
"61968","371.77200","30.98114","0.00970"
"62037","372.18600","31.01564","0.00943"
"62106","372.60000","31.05020","0.00996"
"62175","373.01400","31.08470","0.00991"
"62244","373.42800","31.11920","0.01014"
"62313","373.84200","31.15364","0.01029"
"62382","374.25600","31.18825","0.01014"
"62451","374.67000","31.22269","0.01023"
"62520","375.08400","31.25719","0.01049"
"62589","375.49800","31.29163","0.01064"
"62658","375.91200","31.32613","0.01045"
"62727","376.32600","31.36069","0.01063"
"62796","376.74000","31.39519","0.01085"
"62865","377.15400","31.42962","0.01093"
"62934","377.56800","31.46418","0.01048"
"63003","377.98200","31.49868","0.01084"
"63072","378.39600","31.53318","0.01160"
"63141","378.81000","31.56768","0.01071"
"63210","379.22400","31.60217","0.01061"
"63279","379.63800","31.63667","0.01136"
"63348","380.05200","31.67117","0.01163"
"63417","380.46600","31.70567","0.01073"
"63486","380.88000","31.74017","0.01085"
"63555","381.29400","31.77467","0.01131"
"63624","381.70800","31.80917","0.01153"
"63693","382.12200","31.84373","0.01171"
"63762","382.53600","31.87810","0.01189"
"63831","382.95000","31.91266","0.01119"
"63900","383.36400","31.94716","0.01191"
"63969","383.77800","31.98172","0.01195"
"64038","384.19200","32.01616","0.01233"
"64107","384.60600","32.05060","0.01174"
"64176","385.02000","32.08521","0.01162"
"64245","385.43400","32.11971","0.01211"
"64314","385.84800","32.15416","0.01214"
"64383","386.26200","32.18859","0.01229"
"64452","386.67600","32.22321","0.01305"
"64521","387.09000","32.25771","0.01286"
"64590","387.50400","32.29221","0.01295"
"64659","387.91800","32.32659","0.01263"
"64728","388.33200","32.36114","0.01265"
"64797","388.74600","32.39570","0.01255"
"64866","389.16000","32.43026","0.01280"
"64935","389.57400","32.46470","0.01286"
"65004","389.98800","32.49914","0.01254"
"65073","390.40200","32.53370","0.01302"
"65142","390.81600","32.56820","0.01222"
"65211","391.23000","32.60270","0.01277"
"65280","391.64400","32.63713","0.01311"
"65349","392.05800","32.67169","0.01250"
"65418","392.47200","32.70619","0.01300"
"65487","392.88600","32.74068","0.01361"
"65556","393.30000","32.77513","0.01298"
"65625","393.71400","32.80963","0.01347"
"65694","394.12800","32.84424","0.01390"
"65763","394.54200","32.87868","0.01345"
"65832","394.95600","32.91312","0.01387"
"65901","395.37000","32.94762","0.01346"
"65970","395.78400","32.98218","0.01363"
"66039","396.19800","33.01674","0.01418"
"66108","396.61200","33.05117","0.01415"
"66177","397.02600","33.08561","0.01358"
"66246","397.44000","33.12011","0.01457"
"66315","397.85400","33.15467","0.01437"
"66384","398.26800","33.18917","0.01448"
"66453","398.68200","33.22361","0.01502"
"66522","399.09600","33.25817","0.01478"
"66591","399.51000","33.29267","0.01491"
"66660","399.92400","33.32722","0.01460"
"66729","400.33800","33.36166","0.01496"
"66798","400.75200","33.39610","0.01510"
"66867","401.16600","33.43066","0.01549"
"66936","401.58000","33.46516","0.01540"
"67005","401.99400","33.49966","0.01513"
"67074","402.40800","33.53410","0.01517"
"67143","402.82200","33.56865","0.01549"
"67212","403.23600","33.60321","0.01581"
"67281","403.65000","33.63765","0.01527"
"67350","404.06400","33.67209","0.01553"
"67419","404.47800","33.70665","0.01522"
"67488","404.89200","33.74115","0.01574"
"67557","405.30600","33.77571","0.01521"
"67626","405.72000","33.81008","0.01597"
"67695","406.13400","33.84464","0.01518"
"67764","406.54800","33.87920","0.01501"
"67833","406.96200","33.91370","0.01562"
"67902","407.37600","33.94820","0.01552"
"67971","407.79000","33.98264","0.01555"
"68040","408.20400","34.01714","0.01532"
"68109","408.61800","34.05169","0.01526"
"68178","409.03200","34.08619","0.01522"
"68247","409.44600","34.12057","0.01526"
"68316","409.86000","34.15519","0.01547"
"68385","410.27400","34.18969","0.01537"
"68454","410.68800","34.22419","0.01319"
"68523","411.10200","34.25863","0.01243"
"68592","411.51600","34.29312","0.01301"
"68661","411.93000","34.32768","0.01300"
"68730","412.34400","34.36218","0.01335"
"68799","412.75800","34.39668","0.01318"
"68868","413.17200","34.43112","0.01337"
"68937","413.58600","34.46568","0.01325"
"69006","414.00000","34.50023","0.01319"
"69075","414.41400","34.53473","0.01374"
"69144","414.82800","34.56911","0.01368"
"69213","415.24200","34.60361","0.01303"
"69282","415.65600","34.63817","0.01371"
"69351","416.07000","34.67266","0.01386"
"69420","416.48400","34.70716","0.01377"
"69489","416.89800","34.74166","0.01397"
"69558","417.31200","34.77622","0.01416"
"69627","417.72600","34.81072","0.01418"
"69696","418.14000","34.84522","0.01448"
"69765","418.55400","34.87960","0.01455"
"69834","418.96800","34.91416","0.01410"
"69903","419.38200","34.94872","0.01401"
"69972","419.79600","34.98315","0.01436"
"70041","420.21000","35.01765","0.01374"
"70110","420.62400","35.05215","0.01432"
"70179","421.03800","35.08671","0.01397"
"70248","421.45200","35.12121","0.01417"
"70317","421.86600","35.15565","0.01456"
"70386","422.28000","35.19015","0.01400"
"70455","422.69400","35.22464","0.01432"
"70524","423.10800","35.25920","0.01382"
"70593","423.52200","35.29364","0.01390"
"70662","423.93600","35.32814","0.01398"
"70731","424.35000","35.36264","0.01386"
"70800","424.76400","35.39720","0.01383"
"70869","425.17800","35.43169","0.01357"
"70938","425.59200","35.46613","0.01372"
"71007","426.00600","35.50063","0.01345"
"71076","426.42000","35.53519","0.01390"
"71145","426.83400","35.56969","0.01445"
"71214","427.24800","35.60413","0.01402"
"71283","427.66200","35.63863","0.01410"
"71352","428.07600","35.67319","0.01390"
"71421","428.49000","35.70768","0.01426"
"71490","428.90400","35.74218","0.01467"
"71559","429.31800","35.77662","0.01443"
"71628","429.73200","35.81112","0.01442"
"71697","430.14600","35.84574","0.01479"
"71766","430.56000","35.88018","0.01471"
"71835","430.97400","35.91462","0.01532"
"71904","431.38800","35.94917","0.01467"
"71973","431.80200","35.98367","0.01526"
"72042","432.21600","36.01823","0.01489"
"72111","432.63000","36.05267","0.01523"
"72180","433.04400","36.08711","0.01555"
"72249","433.45800","36.12167","0.01529"
"72318","433.87200","36.15617","0.01549"
"72387","434.28600","36.19066","0.01557"
"72456","434.70000","36.22510","0.01641"
"72525","435.11400","36.25966","0.01570"
"72594","435.52800","36.29416","0.01583"
"72663","435.94200","36.32866","0.01628"
"72732","436.35600","36.36316","0.01624"
"72801","436.77000","36.39766","0.01599"
"72870","437.18400","36.43221","0.01704"
"72939","437.59800","36.46666","0.01712"
"73008","438.01200","36.50115","0.01698"
"73077","438.42600","36.53559","0.01534"
"73146","438.84000","36.57021","0.01509"
"73215","439.25400","36.60471","0.01497"
"73284","439.66800","36.63914","0.01487"
"73353","440.08200","36.67364","0.01512"
"73422","440.49600","36.70814","0.01444"
"73491","440.91000","36.74270","0.01379"
"73560","441.32400","36.77720","0.01452"
"73629","441.73800","36.81164","0.01434"
"73698","442.15200","36.84614","0.01461"
"73767","442.56600","36.88070","0.01489"
"73836","442.98000","36.91520","0.01484"
"73905","443.39400","36.94963","0.01496"
"73974","443.80800","36.98413","0.01458"
"74043","444.22200","37.01869","0.01512"
"74112","444.63600","37.05319","0.01588"
"74181","445.05000","37.08763","0.01540"
"74250","445.46400","37.12213","0.01545"
"74319","445.87800","37.15668","0.01577"
"74388","446.29200","37.19124","0.01564"
"74457","446.70600","37.22568","0.01562"
"74526","447.12000","37.26012","0.01569"
"74595","447.53400","37.29468","0.01618"
"74664","447.94800","37.32918","0.01575"
"74733","448.36200","37.36367","0.01592"
"74802","448.77600","37.39811","0.01631"
"74871","449.19000","37.43261","0.01645"
"74940","449.60400","37.46723","0.01639"
"75009","450.01800","37.50173","0.01675"
"75078","450.43200","37.53622","0.01671"
"75147","450.84600","37.57061","0.01704"
"75216","451.26000","37.60522","0.01711"
"75285","451.67400","37.63966","0.01690"
"75354","452.08800","37.67416","0.01739"
"75423","452.50200","37.70860","0.01715"
"75492","452.91600","37.74316","0.01715"
"75561","453.33000","37.77766","0.01764"
"75630","453.74400","37.81222","0.01755"
"75699","454.15800","37.84665","0.01763"
"75768","454.57200","37.88110","0.01771"
"75837","454.98600","37.91571","0.01751"
"75906","455.40000","37.95015","0.01689"
"75975","455.81400","37.98465","0.01671"
"76044","456.22800","38.01915","0.01683"
"76113","456.64200","38.05365","0.01660"
"76182","457.05600","38.08821","0.01683"
"76251","457.47000","38.12270","0.01734"
"76320","457.88400","38.15714","0.01804"
"76389","458.29800","38.19164","0.01779"
"76458","458.71200","38.22620","0.01796"
"76527","459.12600","38.26070","0.01842"
"76596","459.54000","38.29519","0.01802"
"76665","459.95400","38.32957","0.01848"
"76734","460.36800","38.36419","0.01850"
"76803","460.78200","38.39869","0.01849"
"76872","461.19600","38.43319","0.01901"
"76941","461.61000","38.46763","0.01864"
"77010","462.02400","38.50213","0.01834"
"77079","462.43800","38.53669","0.01823"
"77148","462.85200","38.57119","0.01840"
"77217","463.26600","38.60562","0.01870"
"77286","463.68000","38.64018","0.01912"
"77355","464.09400","38.67468","0.01946"
"77424","464.50800","38.70918","0.01935"
"77493","464.92200","38.74368","0.01911"
"77562","465.33600","38.77818","0.01870"
"77631","465.75000","38.81268","0.01985"
"77700","466.16400","38.84718","0.01952"
"77769","466.57800","38.88167","0.01996"
"77838","466.99200","38.91617","0.01952"
"77907","467.40600","38.95061","0.01983"
"77976","467.82000","38.98517","0.01967"
"78045","468.23400","39.01973","0.01999"
"78114","468.64800","39.05416","0.01984"
"78183","469.06200","39.08860","0.02015"
"78252","469.47600","39.12316","0.01978"
"78321","469.89000","39.15766","0.01643"
"78390","470.30400","39.19216","0.01223"
"78459","470.71800","39.22666","0.00715"
"78528","471.13200","39.26121","0.01101"
"78597","471.54600","39.29565","0.00811"
"78666","471.96000","39.33022","0.00861"
"78735","472.37400","39.36459","0.01029"
"78804","472.78800","39.39915","0.00928"
"78873","473.20200","39.43365","0.00968"
"78942","473.61600","39.46815","0.01066"
"79011","474.03000","39.50265","0.00933"
"79080","474.44400","39.53714","0.01023"
"79149","474.85800","39.57164","0.00948"
"79218","475.27200","39.60620","0.01009"
"79287","475.68600","39.64064","0.01077"
"79356","476.10000","39.67514","0.01052"
"79425","476.51400","39.70970","0.01063"
"79494","476.92800","39.74414","0.01086"
"79563","477.34200","39.77869","0.01079"
"79632","477.75600","39.81307","0.01049"
"79701","478.17000","39.84763","0.01146"
"79770","478.58400","39.88225","0.01092"
"79839","478.99800","39.91669","0.01112"
"79908","479.41200","39.95113","0.01095"
"79977","479.82600","39.98563","0.01118"
"80046","480.24000","40.02018","0.01139"
"80115","480.65400","40.05462","0.01149"
"80184","481.06800","40.08918","0.01095"
"80253","481.48200","40.12362","0.01079"
"80322","481.89600","40.15818","0.01137"
"80391","482.31000","40.19268","0.01106"
"80460","482.72400","40.22717","0.01118"
"80529","483.13800","40.26162","0.01192"
"80598","483.55200","40.29617","0.01124"
"80667","483.96600","40.33067","0.01112"
"80736","484.38000","40.36517","0.01182"
"80805","484.79400","40.39966","0.01168"
"80874","485.20800","40.43417","0.01157"
"80943","485.62200","40.46867","0.01157"
"81012","486.03600","40.50322","0.01153"
"81081","486.45000","40.53766","0.01100"
"81150","486.86400","40.57210","0.01150"
"81219","487.27800","40.60660","0.01174"
"81288","487.69200","40.64116","0.01154"
"81357","488.10600","40.67559","0.01125"
"81426","488.52000","40.71009","0.01100"
"81495","488.93400","40.74466","0.01086"
"81564","489.34800","40.77921","0.01050"
"81633","489.76200","40.81371","0.01116"
"81702","490.17600","40.84821","0.01081"
"81771","490.59000","40.88264","0.01076"
"81840","491.00400","40.91714","0.01051"
"81909","491.41800","40.95171","0.01099"
"81978","491.83200","40.98608","0.01087"
"82047","492.24600","41.02064","0.01044"
"82116","492.66000","41.05514","0.01041"
"82185","493.07400","41.08964","0.01012"
"82254","493.48800","41.12426","0.00954"
"82323","493.90200","41.15863","0.00959"
"82392","494.31600","41.19320","0.00963"
"82461","494.73000","41.22770","0.00934"
"82530","495.14400","41.26225","0.01007"
"82599","495.55800","41.29657","0.01008"
"82668","495.97200","41.33119","0.00945"
"82737","496.38600","41.36568","0.00954"
"82806","496.80000","41.40019","0.00953"
"82875","497.21400","41.43468","0.00978"
"82944","497.62800","41.46912","0.00935"
"83013","498.04200","41.50362","0.00924"
"83082","498.45600","41.53812","0.00915"
"83151","498.87000","41.57268","0.00926"
"83220","499.28400","41.60712","0.00881"
"83289","499.69800","41.64167","0.00928"
"83358","500.11200","41.67617","0.00868"
"83427","500.52600","41.71067","0.00826"
"83496","500.94000","41.74517","0.00897"
"83565","501.35400","41.77961","0.00910"
"83634","501.76800","41.81417","0.00872"
"83703","502.18200","41.84867","0.00917"
"83772","502.59600","41.88316","0.00865"
"83841","503.01000","41.91760","0.00860"
"83910","503.42400","41.95222","0.00884"
"83979","503.83800","41.98666","0.00819"
"84048","504.25200","42.02116","0.00779"
"84117","504.66600","42.05566","0.00829"
"84186","505.08000","42.09010","0.00794"
"84255","505.49400","42.12471","0.00842"
"84324","505.90800","42.15915","0.00775"
"84393","506.32200","42.19365","0.00805"
"84462","506.73600","42.22815","0.00804"
"84531","507.15000","42.26271","0.00795"
"84600","507.56400","42.29721","0.00811"
"84669","507.97800","42.33165","0.00783"
"84738","508.39200","42.36615","0.00817"
"84807","508.80600","42.40070","0.00761"
"84876","509.22000","42.43514","0.00842"
"84945","509.63400","42.46964","0.00856"
"85014","510.04800","42.50414","0.00798"
"85083","510.46200","42.53864","0.00850"
"85100","510.56200","42.54695","0.00811"