File: Trajectories_together/170225_1Specimen_RawData_2.csv
"","V1","V2","V3"
"1","End date","2/25/2017",""
"2","Specimen label","2AT_11",""
"3","Maximum Load","0.09713","N"
"4","Time","Extension","Load"
"5","(s)","(mm)","(N)"
"6","0.00000","33.07342","0.03861"
"11","0.03000","33.07372","0.03843"
"16","0.06000","33.07449","0.03858"
"21","0.09000","33.07611","0.03874"
"26","0.12000","33.07832","0.03875"
"31","0.15000","33.08113","0.03862"
"36","0.18000","33.08436","0.03860"
"41","0.21000","33.08777","0.03885"
"46","0.24000","33.09123","0.03907"
"51","0.27000","33.09446","0.03873"
"56","0.30000","33.09763","0.03888"
"61","0.33000","33.10062","0.03906"
"66","0.36000","33.10349","0.03886"
"71","0.39000","33.10612","0.03902"
"76","0.42000","33.10875","0.03866"
"81","0.45000","33.11132","0.03895"
"86","0.48000","33.11383","0.03866"
"91","0.51000","33.11628","0.03926"
"96","0.54000","33.11874","0.03941"
"101","0.57000","33.12125","0.03923"
"106","0.60000","33.12370","0.03921"
"111","0.63000","33.12621","0.03952"
"116","0.66000","33.12866","0.03973"
"121","0.69000","33.13118","0.03934"
"126","0.72000","33.13369","0.03945"
"131","0.75000","33.13620","0.03966"
"136","0.78000","33.13865","0.03945"
"141","0.81000","33.14116","0.03946"
"146","0.84000","33.14367","0.03947"
"151","0.87000","33.14618","0.03923"
"156","0.90000","33.14869","0.03958"
"161","0.93000","33.15120","0.03957"
"166","0.96000","33.15365","0.03985"
"171","0.99000","33.15616","0.03962"
"176","1.02000","33.15874","0.03982"
"181","1.05000","33.16119","0.03972"
"186","1.08000","33.16370","0.03981"
"191","1.11000","33.16621","0.03999"
"196","1.14000","33.16872","0.03978"
"201","1.17000","33.17123","0.03975"
"206","1.20000","33.17368","0.03998"
"211","1.23000","33.17619","0.04009"
"216","1.26000","33.17865","0.03992"
"221","1.29000","33.18116","0.04037"
"226","1.32000","33.18361","0.04017"
"231","1.35000","33.18612","0.04021"
"236","1.38000","33.18857","0.04065"
"241","1.41000","33.19108","0.04064"
"246","1.44000","33.19359","0.04013"
"251","1.47000","33.19617","0.03995"
"256","1.50000","33.19868","0.04028"
"261","1.53000","33.20119","0.04061"
"266","1.56000","33.20370","0.04064"
"271","1.59000","33.20615","0.04047"
"276","1.62000","33.20866","0.04014"
"281","1.65000","33.21117","0.04038"
"286","1.68000","33.21368","0.04055"
"291","1.71000","33.21613","0.04061"
"296","1.74000","33.21864","0.04035"
"301","1.77000","33.22116","0.04003"
"306","1.80000","33.22372","0.04081"
"311","1.83000","33.22618","0.04052"
"316","1.86000","33.22863","0.04039"
"321","1.89000","33.23108","0.04062"
"326","1.92000","33.23359","0.04054"
"331","1.95000","33.23616","0.04043"
"336","1.98000","33.23862","0.04062"
"341","2.01000","33.24113","0.04083"
"346","2.04000","33.24364","0.04099"
"351","2.07000","33.24621","0.04055"
"356","2.10000","33.24872","0.04087"
"361","2.13000","33.25117","0.04111"
"366","2.16000","33.25362","0.04081"
"371","2.19000","33.25613","0.04095"
"376","2.22000","33.25864","0.04137"
"381","2.25000","33.26116","0.04087"
"386","2.28000","33.26367","0.04065"
"391","2.31000","33.26612","0.04062"
"396","2.34000","33.26863","0.04062"
"401","2.37000","33.27114","0.04082"
"406","2.40000","33.27359","0.04126"
"411","2.43000","33.27610","0.04094"
"416","2.46000","33.27855","0.04098"
"421","2.49000","33.28107","0.04114"
"426","2.52000","33.28363","0.04107"
"431","2.55000","33.28615","0.04105"
"436","2.58000","33.28866","0.04144"
"441","2.61000","33.29117","0.04103"
"446","2.64000","33.29368","0.04107"
"451","2.67000","33.29619","0.04140"
"456","2.70000","33.29865","0.04139"
"461","2.73000","33.30116","0.04140"
"466","2.76000","33.30367","0.04126"
"471","2.79000","33.30618","0.04151"
"476","2.82000","33.30869","0.04154"
"481","2.85000","33.31120","0.04164"
"486","2.88000","33.31371","0.04155"
"491","2.91000","33.31616","0.04170"
"496","2.94000","33.31861","0.04190"
"501","2.97000","33.32113","0.04176"
"506","3.00000","33.32364","0.04165"
"511","3.03000","33.32615","0.04148"
"516","3.06000","33.32860","0.04159"
"521","3.09000","33.33117","0.04148"
"526","3.12000","33.33368","0.04154"
"531","3.15000","33.33619","0.04176"
"536","3.18000","33.33870","0.04182"
"541","3.21000","33.34121","0.04214"
"546","3.24000","33.34367","0.04200"
"551","3.27000","33.34618","0.04189"
"556","3.30000","33.34863","0.04172"
"561","3.33000","33.35114","0.04166"
"566","3.36000","33.35365","0.04187"
"571","3.39000","33.35616","0.04203"
"576","3.42000","33.35867","0.04191"
"581","3.45000","33.36113","0.04177"
"586","3.48000","33.36364","0.04211"
"591","3.51000","33.36609","0.04193"
"596","3.54000","33.36854","0.04204"
"601","3.57000","33.37105","0.04198"
"606","3.60000","33.37356","0.04202"
"611","3.63000","33.37613","0.04221"
"616","3.66000","33.37870","0.04244"
"621","3.69000","33.38121","0.04236"
"626","3.72000","33.38372","0.04240"
"631","3.75000","33.38617","0.04219"
"636","3.78000","33.38869","0.04214"
"641","3.81000","33.39120","0.04227"
"646","3.84000","33.39371","0.04225"
"651","3.87000","33.39616","0.04215"
"656","3.90000","33.39861","0.04214"
"661","3.93000","33.40112","0.04245"
"666","3.96000","33.40369","0.04265"
"671","3.99000","33.40615","0.04259"
"676","4.02000","33.40866","0.04234"
"681","4.05000","33.41111","0.04217"
"686","4.08000","33.41362","0.04243"
"691","4.11000","33.41613","0.04253"
"696","4.14000","33.41864","0.04247"
"701","4.17000","33.42115","0.04244"
"706","4.20000","33.42360","0.04260"
"711","4.23000","33.42618","0.04253"
"716","4.26000","33.42869","0.04272"
"721","4.29000","33.43120","0.04273"
"726","4.32000","33.43365","0.04289"
"731","4.35000","33.43616","0.04272"
"736","4.38000","33.43867","0.04293"
"741","4.41000","33.44118","0.04311"
"746","4.44000","33.44363","0.04306"
"751","4.47000","33.44614","0.04297"
"756","4.50000","33.44860","0.04316"
"761","4.53000","33.45111","0.04312"
"766","4.56000","33.45362","0.04281"
"771","4.59000","33.45607","0.04266"
"776","4.62000","33.45858","0.04290"
"781","4.65000","33.46109","0.04306"
"786","4.68000","33.46360","0.04316"
"791","4.71000","33.46611","0.04299"
"796","4.74000","33.46863","0.04290"
"801","4.77000","33.47114","0.04304"
"806","4.80000","33.47365","0.04303"
"811","4.83000","33.47616","0.04317"
"816","4.86000","33.47861","0.04332"
"821","4.89000","33.48118","0.04308"
"826","4.92000","33.48369","0.04307"
"831","4.95000","33.48620","0.04307"
"836","4.98000","33.48866","0.04318"
"841","5.01000","33.49110","0.04336"
"846","5.04000","33.49362","0.04314"
"851","5.07000","33.49613","0.04336"
"856","5.10000","33.49864","0.04331"
"861","5.13000","33.50115","0.04327"
"866","5.16000","33.50360","0.04328"
"871","5.19000","33.50605","0.04353"
"876","5.22000","33.50863","0.04352"
"881","5.25000","33.51114","0.04356"
"886","5.28000","33.51359","0.04370"
"891","5.31000","33.51610","0.04345"
"896","5.34000","33.51867","0.04343"
"901","5.37000","33.52118","0.04360"
"906","5.40000","33.52369","0.04339"
"911","5.43000","33.52620","0.04334"
"916","5.46000","33.52866","0.04357"
"921","5.49000","33.53117","0.04366"
"926","5.52000","33.53368","0.04385"
"931","5.55000","33.53619","0.04345"
"936","5.58000","33.53864","0.04349"
"941","5.61000","33.54115","0.04374"
"946","5.64000","33.54360","0.04365"
"951","5.67000","33.54611","0.04376"
"956","5.70000","33.54862","0.04385"
"961","5.73000","33.55114","0.04414"
"966","5.76000","33.55359","0.04386"
"971","5.79000","33.55610","0.04361"
"976","5.82000","33.55867","0.04375"
"981","5.85000","33.56112","0.04378"
"986","5.88000","33.56363","0.04404"
"991","5.91000","33.56608","0.04408"
"996","5.94000","33.56865","0.04411"
"1001","5.97000","33.57122","0.04411"
"1006","6.00000","33.57368","0.04407"
"1011","6.03000","33.57619","0.04442"
"1016","6.06000","33.57864","0.04427"
"1021","6.09000","33.58115","0.04445"
"1026","6.12000","33.58366","0.04441"
"1031","6.15000","33.58611","0.04423"
"1036","6.18000","33.58856","0.04412"
"1041","6.21000","33.59107","0.04431"
"1046","6.24000","33.59365","0.04449"
"1051","6.27000","33.59616","0.04416"
"1056","6.30000","33.59861","0.04436"
"1061","6.33000","33.60112","0.04455"
"1066","6.36000","33.60363","0.04434"
"1071","6.39000","33.60620","0.04439"
"1076","6.42000","33.60871","0.04454"
"1081","6.45000","33.61110","0.04458"
"1086","6.48000","33.61361","0.04468"
"1091","6.51000","33.61613","0.04465"
"1096","6.54000","33.61869","0.04452"
"1101","6.57000","33.62115","0.04463"
"1106","6.60000","33.62360","0.04461"
"1111","6.63000","33.62611","0.04471"
"1116","6.66000","33.62862","0.04480"
"1121","6.69000","33.63113","0.04458"
"1126","6.72000","33.63359","0.04485"
"1131","6.75000","33.63610","0.04494"
"1136","6.78000","33.63855","0.04489"
"1141","6.81000","33.64112","0.04482"
"1146","6.84000","33.64363","0.04477"
"1151","6.87000","33.64614","0.04489"
"1156","6.90000","33.64865","0.04498"
"1161","6.93000","33.65116","0.04479"
"1166","6.96000","33.65373","0.04472"
"1171","6.99000","33.65619","0.04489"
"1176","7.02000","33.65864","0.04496"
"1181","7.05000","33.66115","0.04489"
"1186","7.08000","33.66366","0.04480"
"1191","7.11000","33.66617","0.04502"
"1196","7.14000","33.66868","0.04494"
"1201","7.17000","33.67113","0.04494"
"1206","7.20000","33.67365","0.04498"
"1211","7.23000","33.67616","0.04522"
"1216","7.26000","33.67867","0.04527"
"1221","7.29000","33.68112","0.04520"
"1226","7.32000","33.68357","0.04508"
"1231","7.35000","33.68608","0.04513"
"1236","7.38000","33.68865","0.04516"
"1241","7.41000","33.69117","0.04505"
"1246","7.44000","33.69361","0.04525"
"1251","7.47000","33.69613","0.04564"
"1256","7.50000","33.69870","0.04554"
"1261","7.53000","33.70121","0.04551"
"1266","7.56000","33.70366","0.04540"
"1271","7.59000","33.70617","0.04560"
"1276","7.62000","33.70862","0.04557"
"1281","7.65000","33.71113","0.04548"
"1286","7.68000","33.71364","0.04565"
"1291","7.71000","33.71615","0.04553"
"1296","7.74000","33.71861","0.04557"
"1301","7.77000","33.72112","0.04570"
"1306","7.80000","33.72363","0.04561"
"1311","7.83000","33.72608","0.04577"
"1316","7.86000","33.72859","0.04584"
"1321","7.89000","33.73110","0.04587"
"1326","7.92000","33.73361","0.04559"
"1331","7.95000","33.73613","0.04562"
"1336","7.98000","33.73864","0.04569"
"1341","8.01000","33.74115","0.04593"
"1346","8.04000","33.74366","0.04594"
"1351","8.07000","33.74611","0.04586"
"1356","8.10000","33.74868","0.04581"
"1361","8.13000","33.75119","0.04610"
"1366","8.16000","33.75370","0.04600"
"1371","8.19000","33.75615","0.04607"
"1376","8.22000","33.75860","0.04617"
"1381","8.25000","33.76112","0.04606"
"1386","8.28000","33.76363","0.04623"
"1391","8.31000","33.76614","0.04622"
"1396","8.34000","33.76865","0.04618"
"1401","8.37000","33.77110","0.04632"
"1406","8.40000","33.77361","0.04649"
"1411","8.43000","33.77612","0.04630"
"1416","8.46000","33.77869","0.04620"
"1421","8.49000","33.78114","0.04615"
"1426","8.52000","33.78366","0.04611"
"1431","8.55000","33.78617","0.04626"
"1436","8.58000","33.78868","0.04618"
"1441","8.61000","33.79119","0.04597"
"1446","8.64000","33.79364","0.04591"
"1451","8.67000","33.79615","0.04615"
"1456","8.70000","33.79866","0.04622"
"1461","8.73000","33.80117","0.04598"
"1466","8.76000","33.80363","0.04583"
"1471","8.79000","33.80608","0.04625"
"1476","8.82000","33.80865","0.04636"
"1481","8.85000","33.81110","0.04650"
"1486","8.88000","33.81361","0.04646"
"1491","8.91000","33.81606","0.04622"
"1496","8.94000","33.81857","0.04619"
"1501","8.97000","33.82114","0.04660"
"1506","9.00000","33.82359","0.04675"
"1511","9.03000","33.82617","0.04670"
"1516","9.06000","33.82862","0.04668"
"1521","9.09000","33.83113","0.04647"
"1526","9.12000","33.83370","0.04643"
"1531","9.15000","33.83615","0.04667"
"1536","9.18000","33.83860","0.04651"
"1541","9.21000","33.84111","0.04666"
"1546","9.24000","33.84362","0.04645"
"1551","9.27000","33.84620","0.04651"
"1556","9.30000","33.84865","0.04679"
"1561","9.33000","33.85110","0.04721"
"1566","9.36000","33.85361","0.04716"
"1571","9.39000","33.85612","0.04696"
"1576","9.42000","33.85863","0.04678"
"1581","9.45000","33.86108","0.04679"
"1586","9.48000","33.86360","0.04673"
"1591","9.51000","33.86611","0.04710"
"1596","9.54000","33.86868","0.04726"
"1601","9.57000","33.87113","0.04724"
"1606","9.60000","33.87364","0.04730"
"1611","9.63000","33.87615","0.04753"
"1616","9.66000","33.87866","0.04709"
"1621","9.69000","33.88117","0.04718"
"1626","9.72000","33.88368","0.04727"
"1631","9.75000","33.88614","0.04740"
"1636","9.78000","33.88865","0.04730"
"1641","9.81000","33.89116","0.04742"
"1646","9.84000","33.89373","0.04750"
"1651","9.87000","33.89618","0.04732"
"1656","9.90000","33.89863","0.04757"
"1661","9.93000","33.90108","0.04749"
"1666","9.96000","33.90359","0.04769"
"1671","9.99000","33.90611","0.04797"
"1676","10.02000","33.90856","0.04765"
"1681","10.05000","33.91107","0.04727"
"1686","10.08000","33.91364","0.04789"
"1691","10.11000","33.91615","0.04782"
"1696","10.14000","33.91866","0.04821"
"1701","10.17000","33.92117","0.04837"
"1706","10.20000","33.92362","0.04801"
"1711","10.23000","33.92614","0.04787"
"1716","10.26000","33.92871","0.04784"
"1721","10.29000","33.93116","0.04813"
"1726","10.32000","33.93367","0.04798"
"1731","10.35000","33.93618","0.04777"
"1736","10.38000","33.93863","0.04815"
"1741","10.41000","33.94114","0.04817"
"1746","10.44000","33.94359","0.04834"
"1751","10.47000","33.94611","0.04819"
"1756","10.50000","33.94855","0.04820"
"1761","10.53000","33.95107","0.04826"
"1766","10.56000","33.95364","0.04819"
"1771","10.59000","33.95615","0.04847"
"1776","10.62000","33.95866","0.04840"
"1781","10.65000","33.96117","0.04820"
"1786","10.68000","33.96368","0.04815"
"1791","10.71000","33.96619","0.04822"
"1796","10.74000","33.96870","0.04849"
"1801","10.77000","33.97116","0.04857"
"1806","10.80000","33.97367","0.04837"
"1811","10.83000","33.97618","0.04881"
"1816","10.86000","33.97863","0.04883"
"1821","10.89000","33.98114","0.04887"
"1826","10.92000","33.98359","0.04900"
"1831","10.95000","33.98610","0.04908"
"1836","10.98000","33.98861","0.04929"
"1841","11.01000","33.99113","0.04912"
"1846","11.04000","33.99364","0.04905"
"1851","11.07000","33.99609","0.04891"
"1856","11.10000","33.99860","0.04924"
"1861","11.13000","34.00117","0.04898"
"1866","11.16000","34.00368","0.04914"
"1871","11.19000","34.00620","0.04922"
"1876","11.22000","34.00871","0.04944"
"1881","11.25000","34.01122","0.04929"
"1886","11.28000","34.01373","0.04945"
"1891","11.31000","34.01612","0.04924"
"1896","11.34000","34.01863","0.04956"
"1901","11.37000","34.02114","0.04950"
"1906","11.40000","34.02371","0.04949"
"1911","11.43000","34.02623","0.04970"
"1916","11.46000","34.02868","0.04979"
"1921","11.49000","34.03113","0.04976"
"1926","11.52000","34.03364","0.04983"
"1931","11.55000","34.03615","0.04989"
"1936","11.58000","34.03860","0.05007"
"1941","11.61000","34.04105","0.05020"
"1946","11.64000","34.04356","0.05007"
"1951","11.67000","34.04613","0.05001"
"1956","11.70000","34.04870","0.05017"
"1961","11.73000","34.05116","0.04991"
"1966","11.76000","34.05367","0.04998"
"1971","11.79000","34.05618","0.04996"
"1976","11.82000","34.05869","0.04986"
"1981","11.85000","34.06120","0.04992"
"1986","11.88000","34.06365","0.04996"
"1991","11.91000","34.06616","0.04962"
"1996","11.94000","34.06867","0.04965"
"2001","11.97000","34.07119","0.04981"
"2006","12.00000","34.07364","0.05003"
"2011","12.03000","34.07615","0.04978"
"2016","12.06000","34.07866","0.05023"
"2021","12.09000","34.08117","0.05030"
"2026","12.12000","34.08362","0.04997"
"2031","12.15000","34.08607","0.05044"
"2036","12.18000","34.08858","0.05036"
"2041","12.21000","34.09109","0.05031"
"2046","12.24000","34.09361","0.05045"
"2051","12.27000","34.09612","0.05032"
"2056","12.30000","34.09863","0.05051"
"2061","12.33000","34.10120","0.05087"
"2066","12.36000","34.10365","0.05092"
"2071","12.39000","34.10616","0.05083"
"2076","12.42000","34.10867","0.05082"
"2081","12.45000","34.11118","0.05054"
"2086","12.48000","34.11364","0.05060"
"2091","12.51000","34.11615","0.05107"
"2096","12.54000","34.11866","0.05075"
"2101","12.57000","34.12117","0.05054"
"2106","12.60000","34.12362","0.05095"
"2111","12.63000","34.12613","0.05103"
"2116","12.66000","34.12859","0.05068"
"2121","12.69000","34.13110","0.05073"
"2126","12.72000","34.13361","0.05112"
"2131","12.75000","34.13612","0.05122"
"2136","12.78000","34.13857","0.05144"
"2141","12.81000","34.14108","0.05125"
"2146","12.84000","34.14365","0.05190"
"2151","12.87000","34.14622","0.05161"
"2156","12.90000","34.14861","0.05182"
"2161","12.93000","34.15112","0.05166"
"2166","12.96000","34.15363","0.05124"
"2171","12.99000","34.15615","0.05174"
"2176","13.02000","34.15866","0.05157"
"2181","13.05000","34.16111","0.05166"
"2186","13.08000","34.16362","0.05150"
"2191","13.11000","34.16613","0.05148"
"2196","13.14000","34.16864","0.05183"
"2201","13.17000","34.17115","0.05234"
"2206","13.20000","34.17360","0.05213"
"2211","13.23000","34.17611","0.05206"
"2216","13.26000","34.17863","0.05246"
"2221","13.29000","34.18114","0.05212"
"2226","13.32000","34.18365","0.05205"
"2231","13.35000","34.18616","0.05213"
"2236","13.38000","34.18861","0.05208"
"2241","13.41000","34.19112","0.05226"
"2246","13.44000","34.19363","0.05232"
"2251","13.47000","34.19614","0.05238"
"2256","13.50000","34.19866","0.05245"
"2261","13.53000","34.20117","0.05280"
"2266","13.56000","34.20368","0.05270"
"2271","13.59000","34.20619","0.05295"
"2276","13.62000","34.20864","0.05314"
"2281","13.65000","34.21109","0.05342"
"2286","13.68000","34.21360","0.05278"
"2291","13.71000","34.21611","0.05304"
"2296","13.74000","34.21856","0.05323"
"2301","13.77000","34.22108","0.05334"
"2306","13.80000","34.22359","0.05338"
"2311","13.83000","34.22610","0.05346"
"2316","13.86000","34.22867","0.05375"
"2321","13.89000","34.23118","0.05394"
"2326","13.92000","34.23363","0.05425"
"2331","13.95000","34.23615","0.05423"
"2336","13.98000","34.23866","0.05408"
"2341","14.01000","34.24117","0.05406"
"2346","14.04000","34.24368","0.05423"
"2351","14.07000","34.24613","0.05365"
"2356","14.10000","34.24864","0.05352"
"2361","14.13000","34.25121","0.05254"
"2366","14.16000","34.25366","0.05229"
"2371","14.19000","34.25611","0.05238"
"2376","14.22000","34.25863","0.05250"
"2381","14.25000","34.26108","0.05208"
"2386","14.28000","34.26365","0.05193"
"2391","14.31000","34.26616","0.05226"
"2396","14.34000","34.26861","0.05329"
"2401","14.37000","34.27112","0.05360"
"2406","14.40000","34.27363","0.05337"
"2411","14.43000","34.27614","0.05375"
"2416","14.46000","34.27865","0.05440"
"2421","14.49000","34.28111","0.05457"
"2426","14.52000","34.28362","0.05431"
"2431","14.55000","34.28613","0.05371"
"2436","14.58000","34.28864","0.05381"
"2441","14.61000","34.29115","0.05402"
"2446","14.64000","34.29366","0.05407"
"2451","14.67000","34.29612","0.05358"
"2456","14.70000","34.29863","0.05345"
"2461","14.73000","34.30120","0.05434"
"2466","14.76000","34.30365","0.05441"
"2471","14.79000","34.30610","0.05470"
"2476","14.82000","34.30855","0.05510"
"2481","14.85000","34.31112","0.05534"
"2486","14.88000","34.31363","0.05555"
"2491","14.91000","34.31608","0.05593"
"2496","14.94000","34.31859","0.05547"
"2501","14.97000","34.32110","0.05515"
"2506","15.00000","34.32368","0.05557"
"2511","15.03000","34.32613","0.05536"
"2516","15.06000","34.32864","0.05511"
"2521","15.09000","34.33109","0.05507"
"2526","15.12000","34.33360","0.05489"
"2531","15.15000","34.33617","0.05514"
"2536","15.18000","34.33862","0.05519"
"2541","15.21000","34.34113","0.05588"
"2546","15.24000","34.34359","0.05665"
"2551","15.27000","34.34610","0.05655"
"2556","15.30000","34.34861","0.05692"
"2561","15.33000","34.35106","0.05664"
"2566","15.36000","34.35357","0.05635"
"2571","15.39000","34.35608","0.05607"
"2576","15.42000","34.35859","0.05595"
"2581","15.45000","34.36111","0.05629"
"2586","15.48000","34.36362","0.05616"
"2591","15.51000","34.36613","0.05639"
"2596","15.54000","34.36864","0.05683"
"2601","15.57000","34.37115","0.05704"
"2606","15.60000","34.37366","0.05725"
"2611","15.63000","34.37617","0.05768"
"2616","15.66000","34.37868","0.05809"
"2621","15.69000","34.38119","0.05791"
"2626","15.72000","34.38364","0.05761"
"2631","15.75000","34.38615","0.05758"
"2636","15.78000","34.38867","0.05766"
"2641","15.81000","34.39112","0.05774"
"2646","15.84000","34.39363","0.05735"
"2651","15.87000","34.39614","0.05744"
"2656","15.90000","34.39865","0.05715"
"2661","15.93000","34.40117","0.05746"
"2666","15.96000","34.40368","0.05798"
"2671","15.99000","34.40612","0.05832"
"2676","16.02000","34.40864","0.05805"
"2681","16.05000","34.41121","0.05856"
"2686","16.08000","34.41372","0.05855"
"2691","16.11000","34.41617","0.05883"
"2696","16.14000","34.41868","0.05858"
"2701","16.17000","34.42113","0.05921"
"2706","16.20000","34.42365","0.05937"
"2711","16.23000","34.42622","0.05894"
"2716","16.26000","34.42867","0.05934"
"2721","16.29000","34.43118","0.05915"
"2726","16.32000","34.43363","0.05955"
"2731","16.35000","34.43614","0.05970"
"2736","16.38000","34.43865","0.06007"
"2741","16.41000","34.44116","0.06000"
"2746","16.44000","34.44361","0.06058"
"2751","16.47000","34.44613","0.06049"
"2756","16.50000","34.44864","0.06033"
"2761","16.53000","34.45115","0.06017"
"2766","16.56000","34.45366","0.06024"
"2771","16.59000","34.45617","0.06057"
"2776","16.62000","34.45868","0.06054"
"2781","16.65000","34.46119","0.06069"
"2786","16.68000","34.46370","0.06029"
"2791","16.71000","34.46621","0.06070"
"2796","16.74000","34.46867","0.06128"
"2801","16.77000","34.47118","0.06186"
"2806","16.80000","34.47363","0.06172"
"2811","16.83000","34.47614","0.06183"
"2816","16.86000","34.47865","0.06171"
"2821","16.89000","34.48116","0.06196"
"2826","16.92000","34.48367","0.06216"
"2831","16.95000","34.48612","0.06233"
"2836","16.98000","34.48864","0.06258"
"2841","17.01000","34.49121","0.06232"
"2846","17.04000","34.49366","0.06209"
"2851","17.07000","34.49611","0.06190"
"2856","17.10000","34.49862","0.06213"
"2861","17.13000","34.50119","0.06218"
"2866","17.16000","34.50370","0.06264"
"2871","17.19000","34.50621","0.06267"
"2876","17.22000","34.50866","0.06270"
"2881","17.25000","34.51112","0.06273"
"2886","17.28000","34.51369","0.06333"
"2891","17.31000","34.51620","0.06324"
"2896","17.34000","34.51865","0.06305"
"2901","17.37000","34.52110","0.06339"
"2906","17.40000","34.52361","0.06335"
"2911","17.43000","34.52612","0.06282"
"2916","17.46000","34.52864","0.06285"
"2921","17.49000","34.53109","0.06349"
"2926","17.52000","34.53360","0.06331"
"2931","17.55000","34.53611","0.06315"
"2936","17.58000","34.53868","0.06299"
"2941","17.61000","34.54113","0.06308"
"2946","17.64000","34.54364","0.06338"
"2951","17.67000","34.54615","0.06373"
"2956","17.70000","34.54866","0.06340"
"2961","17.73000","34.55123","0.06409"
"2966","17.76000","34.55369","0.06418"
"2971","17.79000","34.55614","0.06398"
"2976","17.82000","34.55865","0.06415"
"2981","17.85000","34.56122","0.06373"
"2986","17.88000","34.56367","0.06399"
"2991","17.91000","34.56612","0.06430"
"2996","17.94000","34.56863","0.06450"
"3001","17.97000","34.57114","0.06422"
"3006","18.00000","34.57365","0.06507"
"3011","18.03000","34.57617","0.06554"
"3016","18.06000","34.57862","0.06549"
"3021","18.09000","34.58113","0.06579"
"3026","18.12000","34.58364","0.06615"
"3031","18.15000","34.58615","0.06643"
"3036","18.18000","34.58867","0.06616"
"3041","18.21000","34.59112","0.06612"
"3046","18.24000","34.59363","0.06608"
"3051","18.27000","34.59614","0.06606"
"3056","18.30000","34.59871","0.06695"
"3061","18.33000","34.60116","0.06626"
"3066","18.36000","34.60367","0.06598"
"3071","18.39000","34.60618","0.06626"
"3076","18.42000","34.60869","0.06702"
"3081","18.45000","34.61115","0.06690"
"3086","18.48000","34.61366","0.06704"
"3091","18.51000","34.61610","0.06758"
"3096","18.54000","34.61861","0.06755"
"3101","18.57000","34.62113","0.06735"
"3106","18.60000","34.62364","0.06792"
"3111","18.63000","34.62609","0.06824"
"3116","18.66000","34.62860","0.06844"
"3121","18.69000","34.63111","0.06794"
"3126","18.72000","34.63369","0.06789"
"3131","18.75000","34.63620","0.06782"
"3136","18.78000","34.63871","0.06823"
"3141","18.81000","34.64116","0.06863"
"3146","18.84000","34.64367","0.06843"
"3151","18.87000","34.64618","0.06861"
"3156","18.90000","34.64863","0.06918"
"3161","18.93000","34.65108","0.06917"
"3166","18.96000","34.65366","0.06904"
"3171","18.99000","34.65617","0.06899"
"3176","19.02000","34.65868","0.06900"
"3181","19.05000","34.66113","0.06871"
"3186","19.08000","34.66364","0.06893"
"3191","19.11000","34.66609","0.06983"
"3196","19.14000","34.66860","0.06945"
"3201","19.17000","34.67111","0.06885"
"3206","19.20000","34.67362","0.06931"
"3211","19.23000","34.67614","0.06969"
"3216","19.26000","34.67865","0.06997"
"3221","19.29000","34.68116","0.07032"
"3226","19.32000","34.68373","0.07005"
"3231","19.35000","34.68618","0.07004"
"3236","19.38000","34.68863","0.06994"
"3241","19.41000","34.69114","0.07016"
"3246","19.44000","34.69365","0.07048"
"3251","19.47000","34.69617","0.07029"
"3256","19.50000","34.69862","0.07082"
"3261","19.53000","34.70113","0.07046"
"3266","19.56000","34.70364","0.07035"
"3271","19.59000","34.70609","0.07088"
"3276","19.62000","34.70860","0.07080"
"3281","19.65000","34.71111","0.07086"
"3286","19.68000","34.71356","0.07055"
"3291","19.71000","34.71607","0.07108"
"3296","19.74000","34.71864","0.07123"
"3301","19.77000","34.72110","0.07104"
"3306","19.80000","34.72367","0.07133"
"3311","19.83000","34.72618","0.07134"
"3316","19.86000","34.72869","0.07117"
"3321","19.89000","34.73120","0.07192"
"3326","19.92000","34.73365","0.07166"
"3331","19.95000","34.73616","0.07216"
"3336","19.98000","34.73867","0.07197"
"3341","20.01000","34.74118","0.07195"
"3346","20.04000","34.74370","0.07248"
"3351","20.07000","34.74615","0.07272"
"3356","20.10000","34.74860","0.07257"
"3361","20.13000","34.75111","0.07320"
"3366","20.16000","34.75362","0.07348"
"3371","20.19000","34.75608","0.07285"
"3376","20.22000","34.75859","0.07271"
"3381","20.25000","34.76110","0.07265"
"3386","20.28000","34.76361","0.07306"
"3391","20.31000","34.76618","0.07337"
"3396","20.34000","34.76869","0.07378"
"3401","20.37000","34.77114","0.07390"
"3406","20.40000","34.77365","0.07382"
"3411","20.43000","34.77616","0.07370"
"3416","20.46000","34.77868","0.07418"
"3421","20.49000","34.78112","0.07432"
"3426","20.52000","34.78363","0.07444"
"3431","20.55000","34.78614","0.07450"
"3436","20.58000","34.78866","0.07437"
"3441","20.61000","34.79117","0.07503"
"3446","20.64000","34.79362","0.07515"
"3451","20.67000","34.79607","0.07486"
"3456","20.70000","34.79858","0.07510"
"3461","20.73000","34.80109","0.07517"
"3466","20.76000","34.80361","0.07565"
"3471","20.79000","34.80606","0.07566"
"3476","20.82000","34.80857","0.07549"
"3481","20.85000","34.81108","0.07555"
"3486","20.88000","34.81365","0.07566"
"3491","20.91000","34.81616","0.07636"
"3496","20.94000","34.81867","0.07649"
"3501","20.97000","34.82119","0.07698"
"3506","21.00000","34.82364","0.07747"
"3511","21.03000","34.82621","0.07651"
"3516","21.06000","34.82866","0.07593"
"3521","21.09000","34.83117","0.07635"
"3526","21.12000","34.83368","0.07725"
"3531","21.15000","34.83613","0.07760"
"3536","21.18000","34.83864","0.07787"
"3541","21.21000","34.84115","0.07790"
"3546","21.24000","34.84361","0.07777"
"3551","21.27000","34.84612","0.07766"
"3556","21.30000","34.84863","0.07795"
"3561","21.33000","34.85114","0.07824"
"3566","21.36000","34.85359","0.07779"
"3571","21.39000","34.85610","0.07811"
"3576","21.42000","34.85862","0.07841"
"3581","21.45000","34.86113","0.07806"
"3586","21.48000","34.86370","0.07840"
"3591","21.51000","34.86615","0.07890"
"3596","21.54000","34.86866","0.07875"
"3601","21.57000","34.87117","0.07920"
"3606","21.60000","34.87368","0.07988"
"3611","21.63000","34.87613","0.08013"
"3616","21.66000","34.87864","0.07907"
"3621","21.69000","34.88109","0.07956"
"3626","21.72000","34.88360","0.08011"
"3631","21.75000","34.88612","0.08010"
"3636","21.78000","34.88857","0.08022"
"3641","21.81000","34.89108","0.07981"
"3646","21.84000","34.89359","0.08006"
"3651","21.87000","34.89610","0.08038"
"3656","21.90000","34.89861","0.08146"
"3661","21.93000","34.90112","0.08196"
"3666","21.96000","34.90358","0.08185"
"3671","21.99000","34.90609","0.08211"
"3676","22.02000","34.90866","0.08143"
"3681","22.05000","34.91117","0.08170"
"3686","22.08000","34.91362","0.08197"
"3691","22.11000","34.91613","0.08206"
"3696","22.14000","34.91864","0.08194"
"3701","22.17000","34.92122","0.08193"
"3706","22.20000","34.92366","0.08244"
"3711","22.23000","34.92612","0.08245"
"3716","22.26000","34.92857","0.08287"
"3721","22.29000","34.93108","0.08259"
"3726","22.32000","34.93365","0.08265"
"3731","22.35000","34.93610","0.08261"
"3736","22.38000","34.93855","0.08293"
"3741","22.41000","34.94106","0.08375"
"3746","22.44000","34.94363","0.08435"
"3751","22.47000","34.94614","0.08423"
"3756","22.50000","34.94865","0.08414"
"3761","22.53000","34.95116","0.08451"
"3766","22.56000","34.95368","0.08439"
"3771","22.59000","34.95619","0.08471"
"3776","22.62000","34.95870","0.08484"
"3781","22.65000","34.96115","0.08506"
"3786","22.68000","34.96367","0.08460"
"3791","22.71000","34.96618","0.08509"
"3796","22.74000","34.96869","0.08532"
"3801","22.77000","34.97120","0.08474"
"3806","22.80000","34.97365","0.08576"
"3811","22.83000","34.97610","0.08549"
"3816","22.86000","34.97861","0.08521"
"3821","22.89000","34.98112","0.08554"
"3826","22.92000","34.98363","0.08554"
"3831","22.95000","34.98608","0.08619"
"3836","22.98000","34.98860","0.08666"
"3841","23.01000","34.99111","0.08596"
"3846","23.04000","34.99362","0.08607"
"3851","23.07000","34.99613","0.08626"
"3856","23.10000","34.99864","0.08668"
"3861","23.13000","35.00109","0.08676"
"3866","23.16000","35.00366","0.08661"
"3871","23.19000","35.00617","0.08698"
"3876","23.22000","35.00868","0.08691"
"3881","23.25000","35.01120","0.08720"
"3886","23.28000","35.01365","0.08745"
"3891","23.31000","35.01616","0.08741"
"3896","23.34000","35.01867","0.08719"
"3901","23.37000","35.02112","0.08762"
"3906","23.40000","35.02369","0.08819"
"3911","23.43000","35.02608","0.08779"
"3916","23.46000","35.02859","0.08739"
"3921","23.49000","35.03111","0.08825"
"3926","23.52000","35.03362","0.08827"
"3931","23.55000","35.03619","0.08847"
"3936","23.58000","35.03864","0.08886"
"3941","23.61000","35.04115","0.08904"
"3946","23.64000","35.04366","0.08875"
"3951","23.67000","35.04617","0.08854"
"3956","23.70000","35.04862","0.08894"
"3961","23.73000","35.05113","0.08909"
"3966","23.76000","35.05365","0.08915"
"3971","23.79000","35.05616","0.08896"
"3976","23.82000","35.05873","0.08895"
"3981","23.85000","35.06118","0.08929"
"3986","23.88000","35.06363","0.08932"
"3991","23.91000","35.06614","0.08949"
"3996","23.94000","35.06859","0.08963"
"4001","23.97000","35.07111","0.08972"
"4006","24.00000","35.07355","0.08980"
"4011","24.03000","35.07607","0.08936"
"4016","24.06000","35.07864","0.08938"
"4021","24.09000","35.08115","0.09006"
"4026","24.12000","35.08366","0.09038"
"4031","24.15000","35.08617","0.09001"
"4036","24.18000","35.08868","0.09011"
"4041","24.21000","35.09119","0.09018"
"4046","24.24000","35.09370","0.09027"
"4051","24.27000","35.09622","0.09028"
"4056","24.30000","35.09867","0.09031"
"4061","24.33000","35.10118","0.09080"
"4066","24.36000","35.10369","0.09063"
"4071","24.39000","35.10614","0.09028"
"4076","24.42000","35.10865","0.09050"
"4081","24.45000","35.11116","0.09070"
"4086","24.48000","35.11367","0.09067"
"4091","24.51000","35.11612","0.09084"
"4096","24.54000","35.11858","0.09082"
"4101","24.57000","35.12109","0.09092"
"4106","24.60000","35.12366","0.09085"
"4111","24.63000","35.12617","0.09101"
"4116","24.66000","35.12862","0.09097"
"4121","24.69000","35.13113","0.09097"
"4126","24.72000","35.13364","0.09093"
"4131","24.75000","35.13622","0.09097"
"4136","24.78000","35.13867","0.09129"
"4141","24.81000","35.14112","0.09125"
"4146","24.84000","35.14363","0.09133"
"4151","24.87000","35.14614","0.09133"
"4156","24.90000","35.14865","0.09148"
"4161","24.93000","35.15117","0.09151"
"4166","24.96000","35.15362","0.09151"
"4171","24.99000","35.15613","0.09158"
"4176","25.02000","35.15864","0.09170"
"4181","25.05000","35.16115","0.09175"
"4186","25.08000","35.16360","0.09175"
"4191","25.11000","35.16611","0.09185"
"4196","25.14000","35.16862","0.09171"
"4201","25.17000","35.17113","0.09165"
"4206","25.20000","35.17365","0.09168"
"4211","25.23000","35.17616","0.09187"
"4216","25.26000","35.17867","0.09182"
"4221","25.29000","35.18112","0.09190"
"4226","25.32000","35.18363","0.09193"
"4231","25.35000","35.18620","0.09206"
"4236","25.38000","35.18865","0.09207"
"4241","25.41000","35.19116","0.09216"
"4246","25.44000","35.19361","0.09228"
"4251","25.47000","35.19613","0.09214"
"4256","25.50000","35.19864","0.09234"
"4261","25.53000","35.20115","0.09243"
"4266","25.56000","35.20360","0.09243"
"4271","25.59000","35.20611","0.09247"
"4276","25.62000","35.20862","0.09268"
"4281","25.65000","35.21107","0.09277"
"4286","25.68000","35.21358","0.09279"
"4291","25.71000","35.21609","0.09273"
"4296","25.74000","35.21861","0.09280"
"4301","25.77000","35.22118","0.09289"
"4306","25.80000","35.22369","0.09300"
"4311","25.83000","35.22614","0.09310"
"4316","25.86000","35.22865","0.09306"
"4321","25.89000","35.23116","0.09324"
"4326","25.92000","35.23367","0.09305"
"4331","25.95000","35.23612","0.09332"
"4336","25.98000","35.23857","0.09343"
"4341","26.01000","35.24109","0.09372"
"4346","26.04000","35.24360","0.09367"
"4351","26.07000","35.24611","0.09361"
"4356","26.10000","35.24862","0.09335"
"4361","26.13000","35.25107","0.09370"
"4366","26.16000","35.25359","0.09391"
"4371","26.19000","35.25615","0.09376"
"4376","26.22000","35.25867","0.09400"
"4381","26.25000","35.26112","0.09398"
"4386","26.28000","35.26363","0.09379"
"4391","26.31000","35.26614","0.09384"
"4396","26.34000","35.26871","0.09394"
"4401","26.37000","35.27116","0.09419"
"4406","26.40000","35.27367","0.09412"
"4411","26.43000","35.27618","0.09452"
"4416","26.46000","35.27869","0.09472"
"4421","26.49000","35.28120","0.09421"
"4426","26.52000","35.28365","0.09412"
"4431","26.55000","35.28611","0.09394"
"4436","26.58000","35.28862","0.09414"
"4441","26.61000","35.29113","0.09413"
"4446","26.64000","35.29364","0.09427"
"4451","26.67000","35.29615","0.09450"
"4456","26.70000","35.29860","0.09493"
"4461","26.73000","35.30112","0.09475"
"4466","26.76000","35.30368","0.09479"
"4471","26.79000","35.30614","0.09509"
"4476","26.82000","35.30865","0.09550"
"4481","26.85000","35.31116","0.09502"
"4486","26.88000","35.31367","0.09506"
"4491","26.91000","35.31618","0.09507"
"4496","26.94000","35.31870","0.09502"
"4501","26.97000","35.32115","0.09519"
"4506","27.00000","35.32366","0.09521"
"4511","27.03000","35.32617","0.09579"
"4516","27.06000","35.32868","0.09587"
"4521","27.09000","35.33113","0.09587"
"4526","27.12000","35.33358","0.09589"
"4531","27.15000","35.33609","0.09617"
"4536","27.18000","35.33860","0.09621"
"4541","27.21000","35.34111","0.09643"
"4546","27.24000","35.34362","0.09674"
"4551","27.27000","35.34613","0.09620"
"4556","27.30000","35.34865","0.09631"
"4561","27.33000","35.35116","0.09685"
"4566","27.36000","35.35367","0.09676"
"4571","27.39000","35.35618","0.09713"
"4576","27.42000","35.35869","0.09705"
"4581","27.45000","35.36115","0.09673"
"4586","27.48000","35.36366","0.09635"
"4591","27.51000","35.36617","0.09663"
"4596","27.54000","35.36868","0.09641"
"4601","27.57000","35.37119","0.09583"
"4606","27.60000","35.37364","0.09591"
"4611","27.63000","35.37615","0.09590"
"4616","27.66000","35.37860","0.09508"
"4621","27.69000","35.38111","0.09429"
"4626","27.72000","35.38356","0.09307"
"4631","27.75000","35.38608","0.09215"
"4636","27.78000","35.38859","0.04918"
"4641","27.81000","35.39116","-0.00589"
"4646","27.84000","35.39367","-0.01656"
"4651","27.87000","35.39618","0.00680"
"4656","27.90000","35.39869","-0.01317"
"4661","27.93000","35.40120","-0.00343"
"4666","27.96000","35.40365","0.00239"
"4671","27.99000","35.40617","-0.01156"
"4676","28.02000","35.40868","0.00541"
"4681","28.05000","35.41119","-0.00267"
"4686","28.08000","35.41364","-0.00573"
"4691","28.11000","35.41615","0.00622"
"4696","28.14000","35.41860","-0.00328"
"4701","28.17000","35.42112","0.00027"
"4706","28.20000","35.42363","0.00142"
"4711","28.23000","35.42614","-0.00484"
"4716","28.26000","35.42859","0.00191"
"4721","28.29000","35.43104","0.00021"
"4726","28.32000","35.43361","-0.00081"
"4731","28.35000","35.43612","0.00315"
"4736","28.38000","35.43863","-0.00341"
"4741","28.41000","35.44114","0.00186"
"4746","28.44000","35.44365","-0.00118"
"4751","28.47000","35.44622","-0.00673"
"4756","28.50000","35.44867","-0.00171"
"4761","28.53000","35.45113","-0.00457"
"4766","28.56000","35.45364","-0.00604"
"4771","28.59000","35.45615","-0.00069"
"4776","28.62000","35.45872","-0.00488"
"4781","28.65000","35.46117","-0.00495"
"4786","28.68000","35.46368","-0.00240"
"4791","28.71000","35.46613","-0.00532"
"4796","28.74000","35.46865","-0.00259"
"4801","28.77000","35.47116","-0.00337"
"4806","28.80000","35.47361","-0.00497"
"4811","28.83000","35.47612","-0.00272"
"4816","28.86000","35.47857","-0.00532"
"4821","28.89000","35.48108","-0.00397"
"4826","28.92000","35.48365","-0.00415"
"4831","28.95000","35.48616","-0.00551"
"4836","28.98000","35.48868","-0.00349"
"4841","29.01000","35.49119","-0.00616"
"4846","29.04000","35.49370","-0.00559"
"4851","29.07000","35.49621","-0.00312"
"4856","29.10000","35.49866","-0.00606"
"4861","29.13000","35.50123","-0.00465"
"4866","29.16000","35.50368","-0.00476"
"4871","29.19000","35.50613","-0.00612"
"4876","29.22000","35.50864","-0.00425"
"4881","29.25000","35.51115","-0.00433"
"4886","29.28000","35.51361","-0.00373"
"4891","29.31000","35.51612","-0.00364"
"4896","29.34000","35.51857","-0.00404"
"4901","29.37000","35.52108","-0.00273"
"4906","29.40000","35.52359","-0.00398"
"4911","29.43000","35.52610","-0.00510"
"4916","29.46000","35.52861","-0.00348"
"4921","29.49000","35.53119","-0.00439"
"4926","29.52000","35.53370","-0.00390"
"4931","29.55000","35.53621","-0.00350"
"4936","29.58000","35.53866","-0.00410"
"4941","29.61000","35.54117","-0.00208"
"4946","29.64000","35.54368","-0.00226"
"4951","29.67000","35.54619","-0.00216"
"4956","29.70000","35.54871","-0.00281"
"4961","29.73000","35.55116","-0.00424"
"4966","29.76000","35.55361","-0.00467"
"4971","29.79000","35.55618","-0.00537"
"4976","29.82000","35.55863","-0.00525"
"4981","29.85000","35.56114","-0.00385"
"4986","29.88000","35.56359","-0.00486"
"4991","29.91000","35.56616","-0.00457"
"4996","29.94000","35.56867","-0.00348"
"5001","29.97000","35.57113","-0.00483"
"5006","30.00000","35.57364","-0.00407"
"5011","30.03000","35.57609","-0.00320"
"5016","30.06000","35.57866","-0.00450"
"5021","30.09000","35.58117","-0.00362"
"5026","30.12000","35.58362","-0.00420"
"5031","30.15000","35.58613","-0.00470"
"5036","30.18000","35.58865","-0.00460"
"5041","30.21000","35.59121","-0.00502"
"5046","30.24000","35.59367","-0.00426"
"5051","30.27000","35.59612","-0.00525"
"5056","30.30000","35.59863","-0.00538"
"5061","30.33000","35.60114","-0.00481"
"5066","30.36000","35.60365","-0.00513"
"5071","30.39000","35.60610","-0.00460"
"5076","30.42000","35.60855","-0.00442"
"5081","30.45000","35.61106","-0.00500"
"5086","30.48000","35.61363","-0.00409"
"5091","30.51000","35.61615","-0.00361"
"5096","30.54000","35.61866","-0.00484"
"5101","30.57000","35.62117","-0.00469"
"5106","30.60000","35.62368","-0.00378"
"5111","30.63000","35.62619","-0.00410"
"5116","30.66000","35.62870","-0.00456"
"5121","30.69000","35.63115","-0.00449"
"5126","30.72000","35.63366","-0.00380"
"5131","30.75000","35.63618","-0.00443"
"5136","30.78000","35.63874","-0.00390"
"5141","30.81000","35.64120","-0.00369"
"5146","30.84000","35.64365","-0.00415"
"5151","30.87000","35.64616","-0.00438"
"5156","30.90000","35.64861","-0.00358"
"5161","30.93000","35.65113","-0.00328"
"5166","30.96000","35.65364","-0.00316"
"5171","30.99000","35.65615","-0.00386"
"5176","31.02000","35.65866","-0.00505"
"5181","31.05000","35.66117","-0.00468"
"5186","31.08000","35.66362","-0.00432"
"5191","31.11000","35.66613","-0.00452"
"5196","31.14000","35.66870","-0.00422"
"5201","31.17000","35.67115","-0.00422"
"5206","31.20000","35.67366","-0.00439"
"5211","31.23000","35.67611","-0.00415"
"5216","31.26000","35.67868","-0.00398"
"5221","31.29000","35.68119","-0.00444"
"5226","31.32000","35.68371","-0.00473"
"5231","31.35000","35.68616","-0.00344"
"5236","31.38000","35.68861","-0.00324"
"5241","31.41000","35.69112","-0.00419"
"5246","31.44000","35.69363","-0.00381"
"5251","31.47000","35.69609","-0.00466"
"5256","31.50000","35.69860","-0.00528"
"5261","31.53000","35.70111","-0.00489"
"5266","31.56000","35.70362","-0.00515"
"5271","31.59000","35.70613","-0.00480"
"5276","31.62000","35.70864","-0.00444"
"5281","31.65000","35.71115","-0.00516"
"5286","31.68000","35.71366","-0.00570"
"5291","31.71000","35.71618","-0.00511"
"5296","31.74000","35.71863","-0.00450"
"5301","31.77000","35.72114","-0.00487"
"5306","31.80000","35.72365","-0.00453"
"5311","31.83000","35.72616","-0.00445"
"5316","31.86000","35.72873","-0.00430"
"5321","31.89000","35.73118","-0.00447"
"5326","31.92000","35.73363","-0.00395"
"5331","31.95000","35.73615","-0.00421"
"5336","31.98000","35.73859","-0.00411"
"5341","32.01000","35.74110","-0.00354"
"5346","32.04000","35.74362","-0.00433"
"5351","32.07000","35.74613","-0.00453"
"5356","32.10000","35.74864","-0.00383"
"5361","32.13000","35.75109","-0.00414"
"5366","32.16000","35.75366","-0.00391"
"5371","32.19000","35.75618","-0.00420"
"5376","32.22000","35.75869","-0.00432"
"5381","32.25000","35.76114","-0.00484"
"5386","32.28000","35.76359","-0.00392"
"5391","32.31000","35.76610","-0.00422"
"5396","32.34000","35.76867","-0.00504"
"5401","32.37000","35.77118","-0.00455"
"5406","32.40000","35.77363","-0.00455"
"5411","32.43000","35.77614","-0.00456"
"5416","32.46000","35.77859","-0.00474"
"5421","32.49000","35.78111","-0.00446"
"5426","32.52000","35.78362","-0.00441"
"5431","32.55000","35.78607","-0.00459"
"5436","32.58000","35.78858","-0.00436"
"5441","32.61000","35.79103","-0.00454"
"5446","32.64000","35.79360","-0.00412"
"5451","32.67000","35.79611","-0.00401"
"5456","32.70000","35.79863","-0.00391"
"5461","32.73000","35.80119","-0.00428"
"5466","32.76000","35.80365","-0.00478"
"5471","32.79000","35.80622","-0.00538"
"5476","32.82000","35.80867","-0.00497"
"5481","32.85000","35.81112","-0.00439"
"5486","32.88000","35.81363","-0.00443"
"5491","32.91000","35.81614","-0.00456"
"5496","32.94000","35.81866","-0.00514"
"5501","32.97000","35.82117","-0.00585"
"5506","33.00000","35.82368","-0.00512"
"5511","33.03000","35.82613","-0.00445"
"5516","33.06000","35.82864","-0.00435"
"5521","33.09000","35.83115","-0.00408"
"5526","33.12000","35.83360","-0.00357"
"5531","33.15000","35.83605","-0.00417"
"5536","33.18000","35.83856","-0.00397"
"5541","33.21000","35.84113","-0.00437"
"5546","33.24000","35.84359","-0.00417"
"5551","33.27000","35.84610","-0.00403"
"5556","33.30000","35.84861","-0.00430"
"5561","33.33000","35.85112","-0.00368"
"5566","33.36000","35.85363","-0.00390"
"5571","33.39000","35.85614","-0.00426"
"5576","33.42000","35.85859","-0.00396"
"5581","33.45000","35.86110","-0.00421"
"5586","33.48000","35.86362","-0.00396"
"5591","33.51000","35.86613","-0.00413"
"5596","33.54000","35.86864","-0.00438"
"5601","33.57000","35.87109","-0.00474"
"5606","33.60000","35.87360","-0.00352"
"5611","33.63000","35.87611","-0.00416"
"5616","33.66000","35.87862","-0.00493"
"5621","33.69000","35.88107","-0.00433"
"5626","33.72000","35.88359","-0.00435"
"5631","33.75000","35.88610","-0.00538"
"5636","33.78000","35.88867","-0.00474"
"5641","33.81000","35.89118","-0.00486"
"5646","33.84000","35.89369","-0.00466"
"5651","33.87000","35.89614","-0.00397"
"5656","33.90000","35.89865","-0.00381"
"5661","33.93000","35.90116","-0.00402"
"5666","33.96000","35.90368","-0.00419"
"5671","33.99000","35.90612","-0.00411"
"5676","34.02000","35.90863","-0.00473"
"5681","34.05000","35.91115","-0.00477"
"5686","34.08000","35.91366","-0.00522"
"5691","34.11000","35.91617","-0.00526"
"5696","34.14000","35.91862","-0.00547"
"5701","34.17000","35.92113","-0.00492"
"5706","34.20000","35.92358","-0.00448"
"5711","34.23000","35.92616","-0.00452"
"5716","34.26000","35.92867","-0.00498"
"5721","34.29000","35.93112","-0.00486"
"5726","34.32000","35.93363","-0.00436"
"5731","34.35000","35.93614","-0.00460"
"5736","34.38000","35.93871","-0.00403"
"5741","34.41000","35.94122","-0.00423"
"5746","34.44000","35.94367","-0.00458"
"5751","34.47000","35.94613","-0.00459"
"5756","34.50000","35.94864","-0.00436"
"5761","34.53000","35.95115","-0.00390"
"5766","34.56000","35.95366","-0.00351"
"5771","34.59000","35.95611","-0.00309"
"5776","34.62000","35.95862","-0.00378"
"5781","34.65000","35.96113","-0.00424"
"5786","34.68000","35.96364","-0.00399"
"5791","34.71000","35.96609","-0.00372"
"5796","34.74000","35.96861","-0.00384"
"5801","34.77000","35.97112","-0.00433"
"5806","34.80000","35.97363","-0.00472"
"5811","34.83000","35.97614","-0.00441"
"5816","34.86000","35.97859","-0.00436"
"5821","34.89000","35.98110","-0.00443"
"5826","34.92000","35.98362","-0.00413"
"5831","34.95000","35.98618","-0.00391"
"5836","34.98000","35.98864","-0.00452"
"5841","35.01000","35.99115","-0.00495"
"5846","35.04000","35.99366","-0.00463"
"5851","35.07000","35.99617","-0.00484"
"5856","35.10000","35.99868","-0.00482"
"5861","35.13000","36.00113","-0.00410"
"5866","35.16000","36.00358","-0.00435"
"5871","35.19000","36.00609","-0.00453"
"5876","35.22000","36.00860","-0.00457"
"5881","35.25000","36.01112","-0.00490"
"5886","35.28000","36.01357","-0.00423"
"5891","35.31000","36.01608","-0.00433"
"5896","35.34000","36.01865","-0.00433"
"5901","35.37000","36.02116","-0.00443"
"5906","35.40000","36.02367","-0.00415"
"5911","35.43000","36.02612","-0.00400"
"5916","35.46000","36.02863","-0.00444"
"5921","35.49000","36.03115","-0.00499"
"5926","35.52000","36.03366","-0.00493"
"5931","35.55000","36.03617","-0.00478"
"5936","35.58000","36.03868","-0.00453"
"5941","35.61000","36.04119","-0.00511"
"5946","35.64000","36.04370","-0.00472"
"5951","35.67000","36.04622","-0.00519"
"5956","35.70000","36.04866","-0.00450"
"5961","35.73000","36.05112","-0.00416"
"5966","35.76000","36.05357","-0.00436"
"5971","35.79000","36.05614","-0.00467"
"5976","35.82000","36.05865","-0.00413"
"5981","35.85000","36.06110","-0.00418"
"5986","35.88000","36.06361","-0.00437"
"5991","35.91000","36.06612","-0.00358"
"5996","35.94000","36.06869","-0.00372"
"6001","35.97000","36.07121","-0.00407"
"6006","36.00000","36.07365","-0.00353"
"6011","36.03000","36.07611","-0.00416"
"6016","36.06000","36.07862","-0.00432"
"6021","36.09000","36.08119","-0.00456"
"6026","36.12000","36.08370","-0.00419"
"6031","36.15000","36.08615","-0.00452"
"6036","36.18000","36.08867","-0.00436"
"6041","36.21000","36.09111","-0.00458"
"6046","36.24000","36.09369","-0.00435"
"6051","36.27000","36.09614","-0.00427"
"6056","36.30000","36.09865","-0.00471"
"6061","36.33000","36.10110","-0.00511"
"6066","36.36000","36.10361","-0.00466"
"6071","36.39000","36.10612","-0.00504"
"6076","36.42000","36.10863","-0.00484"
"6081","36.45000","36.11114","-0.00469"
"6086","36.48000","36.11366","-0.00454"
"6091","36.51000","36.11617","-0.00475"
"6096","36.54000","36.11868","-0.00403"
"6101","36.57000","36.12119","-0.00380"
"6106","36.60000","36.12370","-0.00395"
"6111","36.63000","36.12615","-0.00386"
"6116","36.66000","36.12866","-0.00448"
"6121","36.69000","36.13117","-0.00471"
"6126","36.72000","36.13369","-0.00438"
"6131","36.75000","36.13614","-0.00448"
"6136","36.78000","36.13865","-0.00475"
"6141","36.81000","36.14116","-0.00490"
"6146","36.84000","36.14361","-0.00441"
"6151","36.87000","36.14618","-0.00471"
"6156","36.90000","36.14863","-0.00477"
"6161","36.93000","36.15108","-0.00440"
"6166","36.96000","36.15359","-0.00460"
"6171","36.99000","36.15611","-0.00427"
"6176","37.02000","36.15868","-0.00411"
"6181","37.05000","36.16119","-0.00391"
"6186","37.08000","36.16370","-0.00459"
"6191","37.11000","36.16615","-0.00441"
"6196","37.14000","36.16866","-0.00445"
"6201","37.17000","36.17123","-0.00411"
"6206","37.20000","36.17368","-0.00370"
"6211","37.23000","36.17619","-0.00415"
"6216","37.26000","36.17870","-0.00403"
"6221","37.29000","36.18116","-0.00396"
"6226","37.32000","36.18367","-0.00400"
"6231","37.35000","36.18618","-0.00450"
"6236","37.38000","36.18863","-0.00473"
"6241","37.41000","36.19114","-0.00436"
"6246","37.44000","36.19360","-0.00386"
"6251","37.47000","36.19604","-0.00500"
"6256","37.50000","36.19862","-0.00496"
"6261","37.53000","36.20113","-0.00513"
"6266","37.56000","36.20364","-0.00514"