File: Trajectories_together/170225_1Specimen_RawData_10.csv
"","V1","V2","V3"
"1","End date","2/25/2017",""
"2","Specimen label","1BG_5",""
"3","Maximum Load","0.25051","N"
"4","Time","Extension","Load"
"5","(s)","(mm)","(N)"
"6","0.00000","0.00000","-0.00026"
"55","0.29400","0.02398","0.00025"
"104","0.58800","0.04921","0.00017"
"153","0.88200","0.07372","-0.00024"
"202","1.17600","0.09817","0.00046"
"251","1.47000","0.12275","0.00077"
"300","1.76400","0.14720","0.00016"
"349","2.05800","0.17172","0.00043"
"398","2.35200","0.19623","0.00067"
"447","2.64600","0.22062","0.00066"
"496","2.94000","0.24520","0.00123"
"545","3.23400","0.26971","0.00061"
"594","3.52800","0.29422","0.00050"
"643","3.82200","0.31862","0.00078"
"692","4.11600","0.34319","0.00094"
"741","4.41000","0.36765","0.00084"
"790","4.70400","0.39222","0.00101"
"839","4.99800","0.41667","0.00092"
"888","5.29200","0.44125","0.00125"
"937","5.58600","0.46564","0.00118"
"986","5.88000","0.49015","0.00041"
"1035","6.17400","0.51467","0.00118"
"1084","6.46800","0.53912","0.00075"
"1133","6.76200","0.56364","0.00120"
"1182","7.05600","0.58809","0.00101"
"1231","7.35000","0.61272","0.00130"
"1280","7.64400","0.63712","0.00095"
"1329","7.93800","0.66169","0.00108"
"1378","8.23200","0.68614","0.00127"
"1427","8.52600","0.71066","0.00066"
"1476","8.82000","0.73517","0.00106"
"1525","9.11400","0.75963","0.00123"
"1574","9.40800","0.78414","0.00105"
"1623","9.70200","0.80865","0.00152"
"1672","9.99600","0.83317","0.00147"
"1721","10.29000","0.85768","0.00178"
"1770","10.58400","0.88219","0.00137"
"1819","10.87800","0.90665","0.00131"
"1868","11.17200","0.93116","0.00129"
"1917","11.46600","0.95568","0.00120"
"1966","11.76000","0.98019","0.00082"
"2015","12.05400","1.00470","0.00125"
"2064","12.34800","1.02916","0.00154"
"2113","12.64200","1.05373","0.00203"
"2162","12.93600","1.07812","0.00195"
"2211","13.23000","1.10270","0.00101"
"2260","13.52400","1.12715","0.00139"
"2309","13.81800","1.15167","0.00201"
"2358","14.11200","1.17612","0.00217"
"2407","14.40600","1.20069","0.00146"
"2456","14.70000","1.22515","0.00130"
"2505","14.99400","1.24972","0.00195"
"2554","15.28800","1.27417","0.00150"
"2603","15.58200","1.29869","0.00147"
"2652","15.87600","1.32320","0.00177"
"2701","16.17000","1.34766","0.00199"
"2750","16.46400","1.37223","0.00152"
"2799","16.75800","1.39668","0.00214"
"2848","17.05200","1.42120","0.00177"
"2897","17.34600","1.44565","0.00231"
"2946","17.64000","1.47016","0.00189"
"2995","17.93400","1.49468","0.00177"
"3044","18.22800","1.51919","0.00201"
"3093","18.52200","1.54371","0.00194"
"3142","18.81600","1.56816","0.00211"
"3191","19.11000","1.59273","0.00213"
"3240","19.40400","1.61713","0.00200"
"3289","19.69800","1.64164","0.00193"
"3338","19.99200","1.66610","0.00240"
"3387","20.28600","1.69067","0.00209"
"3436","20.58000","1.71512","0.00243"
"3485","20.87400","1.73970","0.00200"
"3534","21.16800","1.76415","0.00234"
"3583","21.46200","1.78866","0.00217"
"3632","21.75600","1.81318","0.00213"
"3681","22.05000","1.83763","0.00282"
"3730","22.34400","1.86220","0.00195"
"3779","22.63800","1.88666","0.00237"
"3828","22.93200","1.91123","0.00286"
"3877","23.22600","1.93569","0.00221"
"3926","23.52000","1.96026","0.00235"
"3975","23.81400","1.98471","0.00283"
"4024","24.10800","2.00923","0.00209"
"4073","24.40200","2.03362","0.00227"
"4122","24.69600","2.05814","0.00272"
"4171","24.99000","2.08265","0.00289"
"4220","25.28400","2.10716","0.00265"
"4269","25.57800","2.13168","0.00274"
"4318","25.87200","2.15613","0.00258"
"4367","26.16600","2.18070","0.00219"
"4416","26.46000","2.20510","0.00227"
"4465","26.75400","2.22973","0.00295"
"4514","27.04800","2.25418","0.00231"
"4563","27.34200","2.27870","0.00259"
"4612","27.63600","2.30321","0.00278"
"4661","27.93000","2.32767","0.00201"
"4710","28.22400","2.35224","0.00254"
"4759","28.51800","2.37669","0.00270"
"4808","28.81200","2.40127","0.00297"
"4857","29.10600","2.42566","0.00291"
"4906","29.40000","2.45023","0.00277"
"4955","29.69400","2.47463","0.00285"
"5004","29.98800","2.49920","0.00274"
"5053","30.28200","2.52366","0.00290"
"5102","30.57600","2.54817","0.00335"
"5151","30.87000","2.57262","0.00284"
"5200","31.16400","2.59714","0.00265"
"5249","31.45800","2.62171","0.00306"
"5298","31.75200","2.64616","0.00277"
"5347","32.04600","2.67062","0.00296"
"5396","32.34000","2.69513","0.00265"
"5445","32.63400","2.71965","0.00281"
"5494","32.92800","2.74410","0.00311"
"5543","33.22200","2.76867","0.00308"
"5592","33.51600","2.79313","0.00336"
"5641","33.81000","2.81770","0.00326"
"5690","34.10400","2.84216","0.00277"
"5739","34.39800","2.86667","0.00352"
"5788","34.69200","2.89118","0.00307"
"5837","34.98600","2.91570","0.00350"
"5886","35.28000","2.94027","0.00320"
"5935","35.57400","2.96466","0.00334"
"5984","35.86800","2.98918","0.00293"
"6033","36.16200","3.01363","0.00321"
"6082","36.45600","3.03815","0.00349"
"6131","36.75000","3.06266","0.00397"
"6180","37.04400","3.08717","0.00371"
"6229","37.33800","3.11169","0.00311"
"6278","37.63200","3.13614","0.00327"
"6327","37.92600","3.16071","0.00326"
"6376","38.22000","3.18517","0.00362"
"6425","38.51400","3.20968","0.00369"
"6474","38.80800","3.23414","0.00342"
"6523","39.10200","3.25865","0.00377"
"6572","39.39600","3.28310","0.00387"
"6621","39.69000","3.30774","0.00371"
"6670","39.98400","3.33219","0.00382"
"6719","40.27800","3.35670","0.00360"
"6768","40.57200","3.38122","0.00373"
"6817","40.86600","3.40573","0.00362"
"6866","41.16000","3.43024","0.00368"
"6915","41.45400","3.45470","0.00415"
"6964","41.74800","3.47921","0.00398"
"7013","42.04200","3.50367","0.00367"
"7062","42.33600","3.52818","0.00372"
"7111","42.63000","3.55263","0.00374"
"7160","42.92400","3.57721","0.00427"
"7209","43.21800","3.60166","0.00371"
"7258","43.51200","3.62618","0.00353"
"7307","43.80600","3.65069","0.00386"
"7356","44.10000","3.67514","0.00451"
"7405","44.39400","3.69966","0.00458"
"7454","44.68800","3.72411","0.00479"
"7503","44.98200","3.74862","0.00423"
"7552","45.27600","3.77308","0.00448"
"7601","45.57000","3.79765","0.00409"
"7650","45.86400","3.82211","0.00406"
"7699","46.15800","3.84668","0.00394"
"7748","46.45200","3.87119","0.00414"
"7797","46.74600","3.89571","0.00451"
"7846","47.04000","3.92016","0.00435"
"7895","47.33400","3.94467","0.00432"
"7944","47.62800","3.96919","0.00428"
"7993","47.92200","3.99364","0.00427"
"8042","48.21600","4.01822","0.00395"
"8091","48.51000","4.04261","0.00407"
"8140","48.80400","4.06718","0.00481"
"8189","49.09800","4.09164","0.00416"
"8238","49.39200","4.11621","0.00458"
"8287","49.68600","4.14066","0.00369"
"8336","49.98000","4.16518","0.00397"
"8385","50.27400","4.18969","0.00443"
"8434","50.56800","4.21415","0.00481"
"8483","50.86200","4.23872","0.00421"
"8532","51.15600","4.26317","0.00430"
"8581","51.45000","4.28769","0.00402"
"8630","51.74400","4.31214","0.00492"
"8679","52.03800","4.33665","0.00440"
"8728","52.33200","4.36117","0.00493"
"8777","52.62600","4.38568","0.00439"
"8826","52.92000","4.41020","0.00380"
"8875","53.21400","4.43471","0.00455"
"8924","53.50800","4.45922","0.00452"
"8973","53.80200","4.48374","0.00445"
"9022","54.09600","4.50825","0.00485"
"9071","54.39000","4.53270","0.00451"
"9120","54.68400","4.55722","0.00463"
"9169","54.97800","4.58167","0.00416"
"9218","55.27200","4.60625","0.00415"
"9267","55.56600","4.63058","0.00423"
"9316","55.86000","4.65515","0.00444"
"9365","56.15400","4.67967","0.00441"
"9414","56.44800","4.70412","0.00536"
"9463","56.74200","4.72863","0.00415"
"9512","57.03600","4.75315","0.00487"
"9561","57.33000","4.77766","0.00462"
"9610","57.62400","4.80212","0.00482"
"9659","57.91800","4.82669","0.00471"
"9708","58.21200","4.85114","0.00504"
"9757","58.50600","4.87572","0.00483"
"9806","58.80000","4.90011","0.00456"
"9855","59.09400","4.92468","0.00470"
"9904","59.38800","4.94920","0.00485"
"9953","59.68200","4.97371","0.00505"
"10002","59.97600","4.99817","0.00491"
"10051","60.27000","5.02268","0.00404"
"10100","60.56400","5.04719","0.00472"
"10149","60.85800","5.07165","0.00437"
"10198","61.15200","5.09616","0.00517"
"10247","61.44600","5.12067","0.00495"
"10296","61.74000","5.14519","0.00482"
"10345","62.03400","5.16964","0.00444"
"10394","62.32800","5.19416","0.00457"
"10443","62.62200","5.21867","0.00482"
"10492","62.91600","5.24324","0.00492"
"10541","63.21000","5.26770","0.00495"
"10590","63.50400","5.29215","0.00512"
"10639","63.79800","5.31672","0.00559"
"10688","64.09200","5.34112","0.00506"
"10737","64.38600","5.36569","0.00524"
"10786","64.68000","5.39015","0.00543"
"10835","64.97400","5.41472","0.00476"
"10884","65.26800","5.43917","0.00504"
"10933","65.56200","5.46375","0.00429"
"10982","65.85600","5.48814","0.00454"
"11031","66.15000","5.51271","0.00435"
"11080","66.44400","5.53717","0.00487"
"11129","66.73800","5.56162","0.00466"
"11178","67.03200","5.58620","0.00457"
"11227","67.32600","5.61065","0.00460"
"11276","67.62000","5.63516","0.00496"
"11325","67.91400","5.65962","0.00481"
"11374","68.20800","5.68413","0.00477"
"11423","68.50200","5.70864","0.00455"
"11472","68.79600","5.73316","0.00500"
"11521","69.09000","5.75767","0.00424"
"11570","69.38400","5.78219","0.00505"
"11619","69.67800","5.80670","0.00479"
"11668","69.97200","5.83115","0.00511"
"11717","70.26600","5.85567","0.00483"
"11766","70.56000","5.88012","0.00490"
"11815","70.85400","5.90469","0.00492"
"11864","71.14800","5.92915","0.00511"
"11913","71.44200","5.95372","0.00535"
"11962","71.73600","5.97818","0.00518"
"12011","72.03000","6.00275","0.00464"
"12060","72.32400","6.02720","0.00466"
"12109","72.61800","6.05172","0.00472"
"12158","72.91200","6.07623","0.00494"
"12207","73.20600","6.10068","0.00509"
"12256","73.50000","6.12520","0.00469"
"12305","73.79400","6.14965","0.00483"
"12354","74.08800","6.17417","0.00510"
"12403","74.38200","6.19862","0.00523"
"12452","74.67600","6.22319","0.00531"
"12501","74.97000","6.24765","0.00489"
"12550","75.26400","6.27216","0.00528"
"12599","75.55800","6.29667","0.00544"
"12648","75.85200","6.32113","0.00482"
"12697","76.14600","6.34570","0.00553"
"12746","76.44000","6.37016","0.00484"
"12795","76.73400","6.39473","0.00548"
"12844","77.02800","6.41918","0.00507"
"12893","77.32200","6.44370","0.00498"
"12942","77.61600","6.46815","0.00523"
"12991","77.91000","6.49266","0.00532"
"13040","78.20400","6.51718","0.00572"
"13089","78.49800","6.54163","0.00531"
"13138","78.79200","6.56621","0.00538"
"13187","79.08600","6.59066","0.00554"
"13236","79.38000","6.61523","0.00596"
"13285","79.67400","6.63969","0.00490"
"13334","79.96800","6.66420","0.00568"
"13383","80.26200","6.68860","0.00527"
"13432","80.55600","6.71317","0.00562"
"13481","80.85000","6.73756","0.00577"
"13530","81.14400","6.76220","0.00574"
"13579","81.43800","6.78665","0.00570"
"13628","81.73200","6.81116","0.00530"
"13677","82.02600","6.83568","0.00531"
"13726","82.32000","6.86013","0.00564"
"13775","82.61400","6.88470","0.00556"
"13824","82.90800","6.90916","0.00612"
"13873","83.20200","6.93367","0.00587"
"13922","83.49600","6.95813","0.00595"
"13971","83.79000","6.98270","0.00587"
"14020","84.08400","7.00715","0.00551"
"14069","84.37800","7.03173","0.00534"
"14118","84.67200","7.05618","0.00605"
"14167","84.96600","7.08070","0.00537"
"14216","85.26000","7.10521","0.00592"
"14265","85.55400","7.12966","0.00612"
"14314","85.84800","7.15418","0.00602"
"14363","86.14200","7.17869","0.00646"
"14412","86.43600","7.20320","0.00609"
"14461","86.73000","7.22766","0.00574"
"14510","87.02400","7.25217","0.00534"
"14559","87.31800","7.27668","0.00576"
"14608","87.61200","7.30114","0.00639"
"14657","87.90600","7.32571","0.00517"
"14706","88.20000","7.35017","0.00558"
"14755","88.49400","7.37474","0.00579"
"14804","88.78800","7.39913","0.00572"
"14853","89.08200","7.42371","0.00554"
"14902","89.37600","7.44816","0.00570"
"14951","89.67000","7.47273","0.00500"
"15000","89.96400","7.49713","0.00542"
"15049","90.25800","7.52170","0.00590"
"15098","90.55200","7.54616","0.00593"
"15147","90.84600","7.57067","0.00554"
"15196","91.14000","7.59518","0.00622"
"15245","91.43400","7.61970","0.00591"
"15294","91.72800","7.64415","0.00591"
"15343","92.02200","7.66861","0.00550"
"15392","92.31600","7.69318","0.00551"
"15441","92.61000","7.71763","0.00565"
"15490","92.90400","7.74215","0.00575"
"15539","93.19800","7.76654","0.00543"
"15588","93.49200","7.79117","0.00616"
"15637","93.78600","7.81563","0.00584"
"15686","94.08000","7.84020","0.00538"
"15735","94.37400","7.86466","0.00594"
"15784","94.66800","7.88923","0.00585"
"15833","94.96200","7.91368","0.00617"
"15882","95.25600","7.93820","0.00581"
"15931","95.55000","7.96271","0.00606"
"15980","95.84400","7.98716","0.00593"
"16029","96.13800","8.01168","0.00616"
"16078","96.43200","8.03613","0.00546"
"16127","96.72600","8.06071","0.00546"
"16176","97.02000","8.08516","0.00592"
"16225","97.31400","8.10967","0.00612"
"16274","97.60800","8.13419","0.00595"
"16323","97.90200","8.15864","0.00620"
"16372","98.19600","8.18315","0.00635"
"16421","98.49000","8.20761","0.00651"
"16470","98.78400","8.23224","0.00578"
"16519","99.07800","8.25664","0.00586"
"16568","99.37200","8.28121","0.00618"
"16617","99.66600","8.30560","0.00604"
"16666","99.96000","8.33018","0.00639"
"16715","100.25400","8.35469","0.00622"
"16764","100.54800","8.37920","0.00642"
"16813","100.84200","8.40372","0.00615"
"16862","101.13600","8.42823","0.00610"
"16911","101.43000","8.45269","0.00600"
"16960","101.72400","8.47714","0.00626"
"17009","102.01800","8.50171","0.00605"
"17058","102.31200","8.52611","0.00564"
"17107","102.60600","8.55068","0.00605"
"17156","102.90000","8.57513","0.00598"
"17205","103.19400","8.59971","0.00642"
"17254","103.48800","8.62416","0.00646"
"17303","103.78200","8.64868","0.00615"
"17352","104.07600","8.67319","0.00638"
"17401","104.37000","8.69764","0.00644"
"17450","104.66400","8.72222","0.00680"
"17499","104.95800","8.74667","0.00633"
"17548","105.25200","8.77118","0.00619"
"17597","105.54600","8.79564","0.00583"
"17646","105.84000","8.82021","0.00592"
"17695","106.13400","8.84461","0.00683"
"17744","106.42800","8.86918","0.00605"
"17793","106.72200","8.89363","0.00629"
"17842","107.01600","8.91821","0.00745"
"17891","107.31000","8.94272","0.00630"
"17940","107.60400","8.96717","0.00644"
"17989","107.89800","8.99169","0.00641"
"18038","108.19200","9.01614","0.00685"
"18087","108.48600","9.04066","0.00648"
"18136","108.78000","9.06511","0.00637"
"18185","109.07400","9.08968","0.00635"
"18234","109.36800","9.11414","0.00628"
"18283","109.66200","9.13871","0.00676"
"18332","109.95600","9.16316","0.00669"
"18381","110.25000","9.18768","0.00637"
"18430","110.54400","9.21219","0.00736"
"18479","110.83800","9.23665","0.00671"
"18528","111.13200","9.26116","0.00709"
"18577","111.42600","9.28567","0.00684"
"18626","111.72000","9.31019","0.00681"
"18675","112.01400","9.33464","0.00663"
"18724","112.30800","9.35921","0.00687"
"18773","112.60200","9.38367","0.00724"
"18822","112.89600","9.40818","0.00703"
"18871","113.19000","9.43270","0.00679"
"18920","113.48400","9.45721","0.00708"
"18969","113.77800","9.48166","0.00673"
"19018","114.07200","9.50612","0.00704"
"19067","114.36600","9.53075","0.00731"
"19116","114.66000","9.55515","0.00728"
"19165","114.95400","9.57966","0.00687"
"19214","115.24800","9.60411","0.00726"
"19263","115.54200","9.62869","0.00809"
"19312","115.83600","9.65314","0.00759"
"19361","116.13000","9.67771","0.00715"
"19410","116.42400","9.70217","0.00712"
"19459","116.71800","9.72662","0.00735"
"19508","117.01200","9.75119","0.00751"
"19557","117.30600","9.77565","0.00782"
"19606","117.60000","9.80016","0.00737"
"19655","117.89400","9.82462","0.00731"
"19704","118.18800","9.84919","0.00693"
"19753","118.48200","9.87364","0.00749"
"19802","118.77600","9.89816","0.00770"
"19851","119.07000","9.92267","0.00706"
"19900","119.36400","9.94718","0.00734"
"19949","119.65800","9.97164","0.00728"
"19998","119.95200","9.99615","0.00706"
"20047","120.24600","10.02072","0.00703"
"20096","120.54000","10.04518","0.00766"
"20145","120.83400","10.06969","0.00772"
"20194","121.12800","10.09415","0.00742"
"20243","121.42200","10.11866","0.00715"
"20292","121.71600","10.14311","0.00832"
"20341","122.01000","10.16769","0.00776"
"20390","122.30400","10.19214","0.00785"
"20439","122.59800","10.21666","0.00734"
"20488","122.89200","10.24117","0.00761"
"20537","123.18600","10.26568","0.00740"
"20586","123.48000","10.29020","0.00724"
"20635","123.77400","10.31465","0.00806"
"20684","124.06800","10.33922","0.00786"
"20733","124.36200","10.36368","0.00731"
"20782","124.65600","10.38819","0.00788"
"20831","124.95000","10.41265","0.00742"
"20880","125.24400","10.43722","0.00815"
"20929","125.53800","10.46167","0.00767"
"20978","125.83200","10.48625","0.00782"
"21027","126.12600","10.51070","0.00788"
"21076","126.42000","10.53522","0.00718"
"21125","126.71400","10.55967","0.00826"
"21174","127.00800","10.58418","0.00822"
"21223","127.30200","10.60870","0.00819"
"21272","127.59600","10.63315","0.00774"
"21321","127.89000","10.65772","0.00834"
"21370","128.18400","10.68212","0.00827"
"21419","128.47800","10.70663","0.00779"
"21468","128.77200","10.73114","0.00783"
"21517","129.06600","10.75566","0.00779"
"21566","129.36000","10.78017","0.00737"
"21615","129.65400","10.80463","0.00745"
"21664","129.94800","10.82920","0.00766"
"21713","130.24200","10.85365","0.00742"
"21762","130.53600","10.87823","0.00738"
"21811","130.83000","10.90262","0.00739"
"21860","131.12400","10.92719","0.00720"
"21909","131.41800","10.95165","0.00751"
"21958","131.71200","10.97616","0.00745"
"22007","132.00600","11.00068","0.00776"
"22056","132.30000","11.02519","0.00828"
"22105","132.59400","11.04970","0.00805"
"22154","132.88800","11.07416","0.00798"
"22203","133.18200","11.09873","0.00840"
"22252","133.47600","11.12313","0.00815"
"22301","133.77000","11.14764","0.00823"
"22350","134.06400","11.17209","0.00803"
"22399","134.35800","11.19667","0.00811"
"22448","134.65200","11.22118","0.00777"
"22497","134.94600","11.24575","0.00795"
"22546","135.24000","11.27015","0.00805"
"22595","135.53400","11.29472","0.00819"
"22644","135.82800","11.31917","0.00760"
"22693","136.12200","11.34363","0.00801"
"22742","136.41600","11.36820","0.00851"
"22791","136.71000","11.39266","0.00830"
"22840","137.00400","11.41723","0.00835"
"22889","137.29800","11.44168","0.00830"
"22938","137.59200","11.46626","0.00785"
"22987","137.88600","11.49071","0.00811"
"23036","138.18000","11.51517","0.00792"
"23085","138.47400","11.53968","0.00850"
"23134","138.76800","11.56413","0.00815"
"23183","139.06200","11.58865","0.00801"
"23232","139.35600","11.61316","0.00818"
"23281","139.65000","11.63767","0.00847"
"23330","139.94400","11.66213","0.00840"
"23379","140.23800","11.68670","0.00816"
"23428","140.53200","11.71116","0.00796"
"23477","140.82600","11.73573","0.00861"
"23526","141.12000","11.76012","0.00765"
"23575","141.41400","11.78470","0.00831"
"23624","141.70800","11.80915","0.00844"
"23673","142.00200","11.83366","0.00793"
"23722","142.29600","11.85818","0.00843"
"23771","142.59000","11.88269","0.00815"
"23820","142.88400","11.90721","0.00815"
"23869","143.17800","11.93166","0.00944"
"23918","143.47200","11.95623","0.00877"
"23967","143.76600","11.98069","0.00899"
"24016","144.06000","12.00520","0.00869"
"24065","144.35400","12.02965","0.00823"
"24114","144.64800","12.05417","0.00852"
"24163","144.94200","12.07868","0.00855"
"24212","145.23600","12.10319","0.00874"
"24261","145.53000","12.12771","0.00825"
"24310","145.82400","12.15216","0.00837"
"24359","146.11800","12.17668","0.00846"
"24408","146.41200","12.20113","0.00867"
"24457","146.70600","12.22564","0.00885"
"24506","147.00000","12.25010","0.00893"
"24555","147.29400","12.27467","0.00785"
"24604","147.58800","12.29912","0.00820"
"24653","147.88200","12.32370","0.00798"
"24702","148.17600","12.34821","0.00791"
"24751","148.47000","12.37273","0.00870"
"24800","148.76400","12.39724","0.00847"
"24849","149.05800","12.42169","0.00780"
"24898","149.35200","12.44627","0.00838"
"24947","149.64600","12.47072","0.00815"
"24996","149.94000","12.49523","0.00795"
"25045","150.23400","12.51963","0.00821"
"25094","150.52800","12.54420","0.00846"
"25143","150.82200","12.56866","0.00828"
"25192","151.11600","12.59317","0.00843"
"25241","151.41000","12.61762","0.00865"
"25290","151.70400","12.64220","0.00857"
"25339","151.99800","12.66671","0.00836"
"25388","152.29200","12.69116","0.00811"
"25437","152.58600","12.71568","0.00821"
"25486","152.88000","12.74007","0.00841"
"25535","153.17400","12.76465","0.00858"
"25584","153.46800","12.78910","0.00890"
"25633","153.76200","12.81367","0.00821"
"25682","154.05600","12.83813","0.00889"
"25731","154.35000","12.86270","0.00890"
"25780","154.64400","12.88722","0.00901"
"25829","154.93800","12.91167","0.00928"
"25878","155.23200","12.93618","0.00933"
"25927","155.52600","12.96064","0.00875"
"25976","155.82000","12.98521","0.00864"
"26025","156.11400","13.00966","0.00951"
"26074","156.40800","13.03418","0.00869"
"26123","156.70200","13.05863","0.00931"
"26172","156.99600","13.08321","0.00951"
"26221","157.29000","13.10766","0.00847"
"26270","157.58400","13.13217","0.00956"
"26319","157.87800","13.15669","0.00857"
"26368","158.17200","13.18120","0.00836"
"26417","158.46600","13.20571","0.00910"
"26466","158.76000","13.23011","0.00897"
"26515","159.05400","13.25468","0.00902"
"26564","159.34800","13.27914","0.00887"
"26613","159.64200","13.30371","0.00908"
"26662","159.93600","13.32810","0.00907"
"26711","160.23000","13.35268","0.00902"
"26760","160.52400","13.37719","0.00920"
"26809","160.81800","13.40170","0.00921"
"26858","161.11200","13.42616","0.00905"
"26907","161.40600","13.45073","0.00862"
"26956","161.70000","13.47519","0.00968"
"27005","161.99400","13.49964","0.00925"
"27054","162.28800","13.52421","0.00937"
"27103","162.58200","13.54861","0.00866"
"27152","162.87600","13.57318","0.00909"
"27201","163.17000","13.59764","0.00874"
"27250","163.46400","13.62215","0.00868"
"27299","163.75800","13.64666","0.00849"
"27348","164.05200","13.67112","0.00841"
"27397","164.34600","13.69563","0.00891"
"27446","164.64000","13.72014","0.00884"
"27495","164.93400","13.74472","0.00895"
"27544","165.22800","13.76917","0.00925"
"27593","165.52200","13.79368","0.00850"
"27642","165.81600","13.81814","0.00905"
"27691","166.11000","13.84265","0.00931"
"27740","166.40400","13.86711","0.00954"
"27789","166.69800","13.89174","0.00905"
"27838","166.99200","13.91619","0.00882"
"27887","167.28600","13.94071","0.00914"
"27936","167.58000","13.96522","0.00862"
"27985","167.87400","13.98967","0.00964"
"28034","168.16800","14.01425","0.00933"
"28083","168.46200","14.03864","0.00824"
"28132","168.75600","14.06322","0.00925"
"28181","169.05000","14.08761","0.00898"
"28230","169.34400","14.11218","0.00856"
"28279","169.63800","14.13664","0.00902"
"28328","169.93200","14.16121","0.00941"
"28377","170.22600","14.18566","0.00883"
"28426","170.52000","14.21018","0.00868"
"28475","170.81400","14.23469","0.00923"
"28524","171.10800","14.25920","0.00931"
"28573","171.40200","14.28366","0.00921"
"28622","171.69600","14.30817","0.00893"
"28671","171.99000","14.33269","0.00954"
"28720","172.28400","14.35714","0.00932"
"28769","172.57800","14.38166","0.00934"
"28818","172.87200","14.40611","0.00965"
"28867","173.16600","14.43068","0.00887"
"28916","173.46000","14.45520","0.00973"
"28965","173.75400","14.47971","0.00990"
"29014","174.04800","14.50422","0.00972"
"29063","174.34200","14.52868","0.00895"
"29112","174.63600","14.55325","0.00950"
"29161","174.93000","14.57759","0.00946"
"29210","175.22400","14.60216","0.00954"
"29259","175.51800","14.62661","0.00889"
"29308","175.81200","14.65125","0.00948"
"29357","176.10600","14.67564","0.00897"
"29406","176.40000","14.70021","0.00935"
"29455","176.69400","14.72473","0.00902"
"29504","176.98800","14.74918","0.00912"
"29553","177.28200","14.77363","0.00899"
"29602","177.57600","14.79815","0.00913"
"29651","177.87000","14.82266","0.00953"
"29700","178.16400","14.84718","0.00974"
"29749","178.45800","14.87169","0.00912"
"29798","178.75200","14.89614","0.00971"
"29847","179.04600","14.92072","0.00919"
"29896","179.34000","14.94517","0.00924"
"29945","179.63400","14.96974","0.00862"
"29994","179.92800","14.99414","0.00906"
"30043","180.22200","15.01865","0.00858"
"30092","180.51600","15.04317","0.00973"
"30141","180.81000","15.06768","0.00868"
"30190","181.10400","15.09219","0.00885"
"30239","181.39800","15.11665","0.00884"
"30288","181.69200","15.14116","0.00929"
"30337","181.98600","15.16562","0.00917"
"30386","182.28000","15.19019","0.00953"
"30435","182.57400","15.21464","0.00933"
"30484","182.86800","15.23922","0.00906"
"30533","183.16200","15.26367","0.00962"
"30582","183.45600","15.28813","0.00952"
"30631","183.75000","15.31270","0.00960"
"30680","184.04400","15.33715","0.00957"
"30729","184.33800","15.36166","0.00940"
"30778","184.63200","15.38612","0.00971"
"30827","184.92600","15.41069","0.00978"
"30876","185.22000","15.43515","0.00966"
"30925","185.51400","15.45972","0.00908"
"30974","185.80800","15.48417","0.00930"
"31023","186.10200","15.50875","0.00969"
"31072","186.39600","15.53320","0.01006"
"31121","186.69000","15.55766","0.00980"
"31170","186.98400","15.58217","0.00982"
"31219","187.27800","15.60662","0.00993"
"31268","187.57200","15.63114","0.01019"
"31317","187.86600","15.65559","0.01060"
"31366","188.16000","15.68016","0.00935"
"31415","188.45400","15.70462","0.01006"
"31464","188.74800","15.72919","0.00956"
"31513","189.04200","15.75365","0.01012"
"31562","189.33600","15.77816","0.01015"
"31611","189.63000","15.80267","0.00982"
"31660","189.92400","15.82713","0.00971"
"31709","190.21800","15.85170","0.01005"
"31758","190.51200","15.87615","0.00997"
"31807","190.80600","15.90067","0.01037"
"31856","191.10000","15.92512","0.01032"
"31905","191.39400","15.94969","0.01093"
"31954","191.68800","15.97415","0.01074"
"32003","191.98200","15.99866","0.01024"
"32052","192.27600","16.02318","0.01024"
"32101","192.57000","16.04769","0.01033"
"32150","192.86400","16.07220","0.01024"
"32199","193.15800","16.09672","0.01058"
"32248","193.45200","16.12123","0.01086"
"32297","193.74600","16.14569","0.00984"
"32346","194.04000","16.17020","0.00974"
"32395","194.33400","16.19459","0.01034"
"32444","194.62800","16.21917","0.01098"
"32493","194.92200","16.24362","0.01103"
"32542","195.21600","16.26819","0.01037"
"32591","195.51000","16.29265","0.01076"
"32640","195.80400","16.31716","0.01079"
"32689","196.09800","16.34167","0.01062"
"32738","196.39200","16.36619","0.01058"
"32787","196.68600","16.39070","0.01114"
"32836","196.98000","16.41516","0.01142"
"32885","197.27400","16.43967","0.01134"
"32934","197.56800","16.46412","0.01025"
"32983","197.86200","16.48870","0.01096"
"33032","198.15600","16.51315","0.01089"
"33081","198.45000","16.53766","0.01121"
"33130","198.74400","16.56218","0.01120"
"33179","199.03800","16.58669","0.01117"
"33228","199.33200","16.61121","0.01127"
"33277","199.62600","16.63572","0.01145"
"33326","199.92000","16.66023","0.01220"
"33375","200.21400","16.68463","0.01167"
"33424","200.50800","16.70914","0.01151"
"33473","200.80200","16.73360","0.01188"
"33522","201.09600","16.75823","0.01153"
"33571","201.39000","16.78262","0.01165"
"33620","201.68400","16.80720","0.01167"
"33669","201.97800","16.83165","0.01183"
"33718","202.27200","16.85616","0.01238"
"33767","202.56600","16.88068","0.01168"
"33816","202.86000","16.90513","0.01189"
"33865","203.15400","16.92970","0.01219"
"33914","203.44800","16.95416","0.01177"
"33963","203.74200","16.97867","0.01223"
"34012","204.03600","17.00319","0.01246"
"34061","204.33000","17.02770","0.01271"
"34110","204.62400","17.05215","0.01276"
"34159","204.91800","17.07667","0.01327"
"34208","205.21200","17.10118","0.01240"
"34257","205.50600","17.12570","0.01293"
"34306","205.80000","17.15015","0.01258"
"34355","206.09400","17.17466","0.01250"
"34404","206.38800","17.19918","0.01296"
"34453","206.68200","17.22369","0.01275"
"34502","206.97600","17.24820","0.01208"
"34551","207.27000","17.27266","0.01207"
"34600","207.56400","17.29717","0.01273"
"34649","207.85800","17.32163","0.01294"
"34698","208.15200","17.34620","0.01229"
"34747","208.44600","17.37071","0.01269"
"34796","208.74000","17.39517","0.01277"
"34845","209.03400","17.41968","0.01299"
"34894","209.32800","17.44419","0.01263"
"34943","209.62200","17.46877","0.01320"
"34992","209.91600","17.49316","0.01332"
"35041","210.21000","17.51773","0.01273"
"35090","210.50400","17.54213","0.01364"
"35139","210.79800","17.56670","0.01299"
"35188","211.09200","17.59116","0.01385"
"35237","211.38600","17.61567","0.01411"
"35286","211.68000","17.64018","0.01338"
"35335","211.97400","17.66464","0.01355"
"35384","212.26800","17.68921","0.01416"
"35433","212.56200","17.71373","0.01477"
"35482","212.85600","17.73818","0.01442"
"35531","213.15000","17.76263","0.01429"
"35580","213.44400","17.78715","0.01516"
"35629","213.73800","17.81160","0.01524"
"35678","214.03200","17.83617","0.01489"
"35727","214.32600","17.86063","0.01461"
"35776","214.62000","17.88520","0.01585"
"35825","214.91400","17.90965","0.01508"
"35874","215.20800","17.93417","0.01531"
"35923","215.50200","17.95874","0.01558"
"35972","215.79600","17.98320","0.01583"
"36021","216.09000","18.00771","0.01596"
"36070","216.38400","18.03210","0.01582"
"36119","216.67800","18.05668","0.01660"
"36168","216.97200","18.08113","0.01570"
"36217","217.26600","18.10571","0.01676"
"36266","217.56000","18.13016","0.01678"
"36315","217.85400","18.15467","0.01704"
"36364","218.14800","18.17919","0.01690"
"36413","218.44200","18.20364","0.01708"
"36462","218.73600","18.22821","0.01735"
"36511","219.03000","18.25261","0.01799"
"36560","219.32400","18.27718","0.01595"
"36609","219.61800","18.30164","0.01477"
"36658","219.91200","18.32621","0.01658"
"36707","220.20600","18.35060","0.01590"
"36756","220.50000","18.37518","0.01587"
"36805","220.79400","18.39969","0.01573"
"36854","221.08800","18.42420","0.01641"
"36903","221.38200","18.44872","0.01638"
"36952","221.67600","18.47323","0.01722"
"37001","221.97000","18.49768","0.01686"
"37050","222.26400","18.52214","0.01754"
"37099","222.55800","18.54671","0.01702"
"37148","222.85200","18.57117","0.01798"
"37197","223.14600","18.59568","0.01845"
"37246","223.44000","18.62008","0.01892"
"37295","223.73400","18.64465","0.01794"
"37344","224.02800","18.66916","0.01878"
"37393","224.32200","18.69368","0.01929"
"37442","224.61600","18.71819","0.01985"
"37491","224.91000","18.74264","0.02023"
"37540","225.20400","18.76716","0.02029"
"37589","225.49800","18.79167","0.02003"
"37638","225.79200","18.81618","0.02072"
"37687","226.08600","18.84058","0.02020"
"37736","226.38000","18.86515","0.02108"
"37785","226.67400","18.88967","0.02099"
"37834","226.96800","18.91424","0.02130"
"37883","227.26200","18.93869","0.02199"
"37932","227.55600","18.96321","0.02272"
"37981","227.85000","18.98772","0.02258"
"38030","228.14400","19.01217","0.02338"
"38079","228.43800","19.03675","0.02357"
"38128","228.73200","19.06114","0.02347"
"38177","229.02600","19.08572","0.02374"
"38226","229.32000","19.11011","0.02426"
"38275","229.61400","19.13474","0.02456"
"38324","229.90800","19.15914","0.02491"
"38373","230.20200","19.18371","0.02530"
"38422","230.49600","19.20816","0.02602"
"38471","230.79000","19.23268","0.02560"
"38520","231.08400","19.25719","0.02596"
"38569","231.37800","19.28165","0.02536"
"38618","231.67200","19.30616","0.02531"
"38667","231.96600","19.33067","0.02482"
"38716","232.26000","19.35519","0.02436"
"38765","232.55400","19.37964","0.02530"
"38814","232.84800","19.40415","0.02529"
"38863","233.14200","19.42867","0.02452"
"38912","233.43600","19.45318","0.02556"
"38961","233.73000","19.47764","0.02553"
"39010","234.02400","19.50221","0.02562"
"39059","234.31800","19.52672","0.02609"
"39108","234.61200","19.55118","0.02065"
"39157","234.90600","19.57575","0.02119"
"39206","235.20000","19.60015","0.02156"
"39255","235.49400","19.62466","0.02147"
"39304","235.78800","19.64911","0.02226"
"39353","236.08200","19.67369","0.02331"
"39402","236.37600","19.69808","0.02366"
"39451","236.67000","19.72265","0.02407"
"39500","236.96400","19.74711","0.02408"
"39549","237.25800","19.77168","0.02596"
"39598","237.55200","19.79619","0.02563"
"39647","237.84600","19.82065","0.02621"
"39696","238.14000","19.84516","0.02682"
"39745","238.43400","19.86968","0.02750"
"39794","238.72800","19.89425","0.02693"
"39843","239.02200","19.91864","0.02701"
"39892","239.31600","19.94321","0.02804"
"39941","239.61000","19.96767","0.02831"
"39990","239.90400","19.99224","0.02939"
"40039","240.19800","20.01670","0.02933"
"40088","240.49200","20.04121","0.03016"
"40137","240.78600","20.06567","0.03100"
"40186","241.08000","20.09018","0.03102"
"40235","241.37400","20.11469","0.03100"
"40284","241.66800","20.13915","0.03155"
"40333","241.96200","20.16366","0.03256"
"40382","242.25600","20.18811","0.03319"
"40431","242.55000","20.21269","0.03450"
"40480","242.84400","20.23714","0.03552"
"40529","243.13800","20.26166","0.03646"
"40578","243.43200","20.28623","0.03686"
"40627","243.72600","20.31062","0.03814"
"40676","244.02000","20.33520","0.03922"
"40725","244.31400","20.35965","0.04050"
"40774","244.60800","20.38423","0.04130"
"40823","244.90200","20.40862","0.04104"
"40872","245.19600","20.43319","0.04085"
"40921","245.49000","20.45765","0.04237"
"40970","245.78400","20.48222","0.04293"
"41019","246.07800","20.50667","0.04390"
"41068","246.37200","20.53119","0.04392"
"41117","246.66600","20.55570","0.04515"
"41166","246.96000","20.58015","0.04567"
"41215","247.25400","20.60467","0.04639"
"41264","247.54800","20.62918","0.04654"
"41313","247.84200","20.65364","0.04673"
"41362","248.13600","20.67815","0.04671"
"41411","248.43000","20.70272","0.04473"
"41460","248.72400","20.72718","0.04597"
"41509","249.01800","20.75169","0.04729"
"41558","249.31200","20.77615","0.04768"
"41607","249.60600","20.80066","0.04802"
"41656","249.90000","20.82517","0.04876"
"41705","250.19400","20.84963","0.04960"
"41754","250.48800","20.87420","0.04930"
"41803","250.78200","20.89871","0.04990"
"41852","251.07600","20.92323","0.05072"
"41901","251.37000","20.94768","0.05060"
"41950","251.66400","20.97219","0.05121"
"41999","251.95800","20.99665","0.05133"
"42048","252.25200","21.02122","0.05194"
"42097","252.54600","21.04568","0.05215"
"42146","252.84000","21.07019","0.05258"
"42195","253.13400","21.09470","0.05286"
"42244","253.42800","21.11916","0.05327"
"42293","253.72200","21.14373","0.04473"
"42342","254.01600","21.16813","0.04103"
"42391","254.31000","21.19270","0.04107"
"42440","254.60400","21.21709","0.04142"
"42489","254.89800","21.24166","0.04289"
"42538","255.19200","21.26612","0.04399"
"42587","255.48600","21.29070","0.04488"
"42636","255.78000","21.31515","0.04477"
"42685","256.07400","21.33966","0.04455"
"42734","256.36800","21.36418","0.04526"
"42783","256.66200","21.38863","0.04558"
"42832","256.95600","21.41320","0.04560"
"42881","257.25000","21.43772","0.04701"
"42930","257.54400","21.46223","0.04691"
"42979","257.83800","21.48668","0.04778"
"43028","258.13200","21.51120","0.04877"
"43077","258.42600","21.53565","0.04959"
"43126","258.72000","21.56017","0.04670"
"43175","259.01400","21.58468","0.04620"
"43224","259.30800","21.60913","0.04551"
"43273","259.60200","21.63365","0.04630"
"43322","259.89600","21.65810","0.04660"
"43371","260.19000","21.68273","0.04649"
"43420","260.48400","21.70713","0.04726"
"43469","260.77800","21.73170","0.04648"
"43518","261.07200","21.75610","0.04392"
"43567","261.36600","21.78067","0.04422"
"43616","261.66000","21.80512","0.04470"
"43665","261.95400","21.82970","0.04462"
"43714","262.24800","21.85415","0.04566"
"43763","262.54200","21.87867","0.04628"
"43812","262.83600","21.90318","0.04686"
"43861","263.13000","21.92769","0.04722"
"43910","263.42400","21.95221","0.04753"
"43959","263.71800","21.97666","0.04478"
"44008","264.01200","22.00123","0.04553"
"44057","264.30600","22.02563","0.04612"
"44106","264.60000","22.05020","0.04694"
"44155","264.89400","22.07466","0.04677"
"44204","265.18800","22.09917","0.04728"
"44253","265.48200","22.12368","0.04836"
"44302","265.77600","22.14819","0.04825"
"44351","266.07000","22.17265","0.04849"
"44400","266.36400","22.19710","0.04895"
"44449","266.65800","22.22168","0.04871"
"44498","266.95200","22.24613","0.04963"
"44547","267.24600","22.27064","0.05017"
"44596","267.54000","22.29510","0.05020"
"44645","267.83400","22.31967","0.05018"
"44694","268.12800","22.34413","0.05078"
"44743","268.42200","22.36870","0.04686"
"44792","268.71600","22.39321","0.04795"
"44841","269.01000","22.41767","0.04890"
"44890","269.30400","22.44224","0.04859"
"44939","269.59800","22.46663","0.04859"
"44988","269.89200","22.49121","0.04965"
"45037","270.18600","22.51566","0.04929"
"45086","270.48000","22.54023","0.04854"
"45135","270.77400","22.56463","0.04926"
"45184","271.06800","22.58920","0.04661"
"45233","271.36200","22.61366","0.04682"
"45282","271.65600","22.63817","0.04713"
"45331","271.95000","22.66262","0.04601"
"45380","272.24400","22.68714","0.04488"
"45429","272.53800","22.71165","0.04349"
"45478","272.83200","22.73617","0.04187"
"45527","273.12600","22.76068","0.03833"
"45576","273.42000","22.78519","0.03755"
"45625","273.71400","22.80965","0.03838"
"45674","274.00800","22.83410","0.03773"
"45723","274.30200","22.85868","0.03687"
"45772","274.59600","22.88319","0.03750"
"45821","274.89000","22.90764","0.03828"
"45870","275.18400","22.93222","0.03911"
"45919","275.47800","22.95673","0.03897"
"45968","275.77200","22.98124","0.03850"
"46017","276.06600","23.00564","0.03929"
"46066","276.36000","23.03021","0.04016"
"46115","276.65400","23.05466","0.04063"
"46164","276.94800","23.07918","0.04114"
"46213","277.24200","23.10363","0.04112"
"46262","277.53600","23.12821","0.04185"
"46311","277.83000","23.15266","0.04203"
"46360","278.12400","23.17718","0.04342"
"46409","278.41800","23.20169","0.04320"
"46458","278.71200","23.22614","0.04348"
"46507","279.00600","23.25071","0.04380"
"46556","279.30000","23.27517","0.04418"
"46605","279.59400","23.29968","0.04473"
"46654","279.88800","23.32414","0.04589"
"46703","280.18200","23.34871","0.04635"
"46752","280.47600","23.37310","0.04671"
"46801","280.77000","23.39774","0.04702"
"46850","281.06400","23.42213","0.04776"
"46899","281.35800","23.44670","0.04809"
"46948","281.65200","23.47122","0.04856"
"46997","281.94600","23.49567","0.04867"
"47046","282.24000","23.52024","0.04903"
"47095","282.53400","23.54464","0.04967"
"47144","282.82800","23.56921","0.05026"
"47193","283.12200","23.59367","0.05050"
"47242","283.41600","23.61818","0.05126"
"47291","283.71000","23.64263","0.05061"
"47340","284.00400","23.66721","0.05168"
"47389","284.29800","23.69166","0.05161"
"47438","284.59200","23.71618","0.05195"
"47487","284.88600","23.74069","0.05166"
"47536","285.18000","23.76508","0.05138"
"47585","285.47400","23.78960","0.05191"
"47634","285.76800","23.81411","0.05228"
"47683","286.06200","23.83868","0.05253"
"47732","286.35600","23.86314","0.05280"
"47781","286.65000","23.88765","0.05197"
"47830","286.94400","23.91211","0.05261"
"47879","287.23800","23.93674","0.05223"
"47928","287.53200","23.96119","0.05241"
"47977","287.82600","23.98571","0.05192"
"48026","288.12000","24.01022","0.05217"
"48075","288.41400","24.03468","0.05270"
"48124","288.70800","24.05919","0.05264"
"48173","289.00200","24.08364","0.05201"
"48222","289.29600","24.10816","0.05229"
"48271","289.59000","24.13261","0.05286"
"48320","289.88400","24.15718","0.05301"
"48369","290.17800","24.18170","0.05273"
"48418","290.47200","24.20621","0.05343"
"48467","290.76600","24.23067","0.05288"
"48516","291.06000","24.25518","0.05302"
"48565","291.35400","24.27963","0.05338"
"48614","291.64800","24.30415","0.05341"
"48663","291.94200","24.32866","0.05390"
"48712","292.23600","24.35317","0.05426"
"48761","292.53000","24.37769","0.05382"
"48810","292.82400","24.40214","0.05416"
"48859","293.11800","24.42665","0.05446"
"48908","293.41200","24.45117","0.05471"
"48957","293.70600","24.47568","0.05535"
"49006","294.00000","24.50019","0.05553"
"49055","294.29400","24.52471","0.05539"
"49104","294.58800","24.54922","0.05548"
"49153","294.88200","24.57368","0.05620"
"49202","295.17600","24.59819","0.05613"
"49251","295.47000","24.62259","0.05643"
"49300","295.76400","24.64722","0.05655"
"49349","296.05800","24.67161","0.05679"
"49398","296.35200","24.69619","0.05687"
"49447","296.64600","24.72064","0.05726"
"49496","296.94000","24.74516","0.05717"
"49545","297.23400","24.76961","0.05776"
"49594","297.52800","24.79418","0.05780"
"49643","297.82200","24.81864","0.05814"
"49692","298.11600","24.84315","0.05827"
"49741","298.41000","24.86772","0.05864"
"49790","298.70400","24.89218","0.05967"
"49839","298.99800","24.91669","0.05963"
"49888","299.29200","24.94114","0.06039"
"49937","299.58600","24.96572","0.06081"
"49986","299.88000","24.99017","0.06196"
"50035","300.17400","25.01468","0.06254"
"50084","300.46800","25.03914","0.06323"
"50133","300.76200","25.06371","0.06405"
"50182","301.05600","25.08817","0.06495"
"50231","301.35000","25.11268","0.06604"
"50280","301.64400","25.13720","0.06729"
"50329","301.93800","25.16165","0.06805"
"50378","302.23200","25.18622","0.06924"
"50427","302.52600","25.21068","0.06955"
"50476","302.82000","25.23519","0.07088"
"50525","303.11400","25.25964","0.07235"
"50574","303.40800","25.28416","0.07350"
"50623","303.70200","25.30867","0.07394"
"50672","303.99600","25.33319","0.07568"
"50721","304.29000","25.35770","0.07657"
"50770","304.58400","25.38215","0.07777"
"50819","304.87800","25.40672","0.07882"
"50868","305.17200","25.43112","0.07990"
"50917","305.46600","25.45569","0.08074"
"50966","305.76000","25.48009","0.08276"
"51015","306.05400","25.50472","0.08362"
"51064","306.34800","25.52917","0.08446"
"51113","306.64200","25.55375","0.08610"
"51162","306.93600","25.57820","0.08629"
"51211","307.23000","25.60266","0.08797"
"51260","307.52400","25.62717","0.08903"
"51309","307.81800","25.65162","0.08998"
"51358","308.11200","25.67614","0.09239"
"51407","308.40600","25.70059","0.09342"
"51456","308.70000","25.72516","0.09583"
"51505","308.99400","25.74962","0.09693"
"51554","309.28800","25.77419","0.09781"
"51603","309.58200","25.79865","0.09884"
"51652","309.87600","25.82316","0.09945"
"51701","310.17000","25.84767","0.10017"
"51750","310.46400","25.87213","0.10105"
"51799","310.75800","25.89670","0.10145"
"51848","311.05200","25.92115","0.10228"
"51897","311.34600","25.94573","0.10290"
"51946","311.64000","25.97018","0.10318"
"51995","311.93400","25.99469","0.10383"
"52044","312.22800","26.01915","0.10407"
"52093","312.52200","26.04372","0.10060"
"52142","312.81600","26.06817","0.10110"
"52191","313.11000","26.09269","0.10266"
"52240","313.40400","26.11721","0.10283"
"52289","313.69800","26.14166","0.10353"
"52338","313.99200","26.16629","0.10414"
"52387","314.28600","26.19063","0.10455"
"52436","314.58000","26.21520","0.10573"
"52485","314.87400","26.23965","0.10675"
"52534","315.16800","26.26417","0.10835"
"52583","315.46200","26.28862","0.10986"
"52632","315.75600","26.31319","0.11105"
"52681","316.05000","26.33765","0.11331"
"52730","316.34400","26.36216","0.11460"
"52779","316.63800","26.38668","0.11652"
"52828","316.93200","26.41119","0.11672"
"52877","317.22600","26.43570","0.11880"
"52926","317.52000","26.46016","0.12056"
"52975","317.81400","26.48473","0.12366"
"53024","318.10800","26.50918","0.12473"
"53073","318.40200","26.53370","0.12707"
"53122","318.69600","26.55815","0.12865"
"53171","318.99000","26.58267","0.12985"
"53220","319.28400","26.60718","0.13179"
"53269","319.57800","26.63169","0.13339"
"53318","319.87200","26.65615","0.13423"
"53367","320.16600","26.68066","0.13588"
"53416","320.46000","26.70523","0.13733"
"53465","320.75400","26.72969","0.13808"
"53514","321.04800","26.75420","0.13996"
"53563","321.34200","26.77860","0.14086"
"53612","321.63600","26.80317","0.14219"
"53661","321.93000","26.82762","0.14247"
"53710","322.22400","26.85220","0.14372"
"53759","322.51800","26.87665","0.14392"
"53808","322.81200","26.90116","0.14485"
"53857","323.10600","26.92562","0.14549"
"53906","323.40000","26.95013","0.14608"
"53955","323.69400","26.97477","0.14656"
"54004","323.98800","26.99922","0.14605"
"54053","324.28200","27.02373","0.14555"
"54102","324.57600","27.04819","0.14575"
"54151","324.87000","27.07270","0.14606"
"54200","325.16400","27.09716","0.14649"
"54249","325.45800","27.12167","0.14718"
"54298","325.75200","27.14612","0.14753"
"54347","326.04600","27.17070","0.14804"
"54396","326.34000","27.19515","0.14843"
"54445","326.63400","27.21966","0.14854"
"54494","326.92800","27.24412","0.14779"
"54543","327.22200","27.26863","0.14767"
"54592","327.51600","27.29314","0.14773"
"54641","327.81000","27.31760","0.14822"
"54690","328.10400","27.34217","0.14771"
"54739","328.39800","27.36669","0.14797"
"54788","328.69200","27.39120","0.14851"
"54837","328.98600","27.41566","0.14881"
"54886","329.28000","27.44017","0.14911"
"54935","329.57400","27.46474","0.14923"
"54984","329.86800","27.48914","0.14947"
"55033","330.16200","27.51371","0.15002"
"55082","330.45600","27.53810","0.15055"
"55131","330.75000","27.56274","0.15119"
"55180","331.04400","27.58713","0.15198"
"55229","331.33800","27.61170","0.15339"
"55278","331.63200","27.63616","0.15469"
"55327","331.92600","27.66067","0.15554"
"55376","332.22000","27.68513","0.15716"
"55425","332.51400","27.70970","0.15851"
"55474","332.80800","27.73415","0.15984"
"55523","333.10200","27.75867","0.16136"
"55572","333.39600","27.78318","0.16337"
"55621","333.69000","27.80763","0.16563"
"55670","333.98400","27.83215","0.16785"
"55719","334.27800","27.85660","0.17045"
"55768","334.57200","27.88117","0.17334"
"55817","334.86600","27.90569","0.17575"
"55866","335.16000","27.93020","0.17740"
"55915","335.45400","27.95472","0.18069"
"55964","335.74800","27.97923","0.18039"
"56013","336.04200","28.00374","0.18359"
"56062","336.33600","28.02814","0.18442"
"56111","336.63000","28.05271","0.18668"
"56160","336.92400","28.07717","0.18908"
"56209","337.21800","28.10168","0.19143"
"56258","337.51200","28.12613","0.19450"
"56307","337.80600","28.15071","0.19696"
"56356","338.10000","28.17516","0.19916"
"56405","338.39400","28.19967","0.20067"
"56454","338.68800","28.22419","0.20319"
"56503","338.98200","28.24864","0.20458"
"56552","339.27600","28.27321","0.20679"
"56601","339.57000","28.29761","0.20741"
"56650","339.86400","28.32218","0.20833"
"56699","340.15800","28.34664","0.20944"
"56748","340.45200","28.37121","0.20945"
"56797","340.74600","28.39561","0.21047"
"56846","341.04000","28.42024","0.21082"
"56895","341.33400","28.44463","0.21154"
"56944","341.62800","28.46921","0.21182"
"56993","341.92200","28.49366","0.21269"
"57042","342.21600","28.51817","0.21355"
"57091","342.51000","28.54269","0.21433"
"57140","342.80400","28.56714","0.21545"
"57189","343.09800","28.59171","0.21691"
"57238","343.39200","28.61617","0.21825"
"57287","343.68600","28.64068","0.21928"
"57336","343.98000","28.66514","0.22173"
"57385","344.27400","28.68971","0.22324"
"57434","344.56800","28.71416","0.22410"
"57483","344.86200","28.73862","0.22503"
"57532","345.15600","28.76319","0.22677"
"57581","345.45000","28.78765","0.22843"
"57630","345.74400","28.81222","0.22949"
"57679","346.03800","28.83661","0.23165"
"57728","346.33200","28.86119","0.23379"
"57777","346.62600","28.88564","0.23572"
"57826","346.92000","28.91015","0.23748"
"57875","347.21400","28.93467","0.23876"
"57924","347.50800","28.95924","0.24139"
"57973","347.80200","28.98369","0.24364"
"58022","348.09600","29.00821","0.24433"
"58071","348.39000","29.03272","0.24555"
"58120","348.68400","29.05717","0.24607"
"58169","348.97800","29.08169","0.24717"
"58218","349.27200","29.10614","0.24722"
"58267","349.56600","29.13066","0.24816"
"58316","349.86000","29.15517","0.24928"
"58365","350.15400","29.17974","0.24915"
"58414","350.44800","29.20414","0.24998"
"58463","350.74200","29.22871","0.25031"
"58512","351.03600","29.25317","0.18806"
"58561","351.33000","29.27762","0.18970"
"58610","351.62400","29.30219","0.18627"
"58659","351.91800","29.32665","0.19600"
"58708","352.21200","29.35116","0.20362"
"58757","352.50600","29.37562","0.20636"
"58806","352.80000","29.40019","0.20909"
"58855","353.09400","29.42464","0.20987"
"58904","353.38800","29.44922","0.20974"
"58953","353.68200","29.47367","0.21174"
"59002","353.97600","29.49818","0.21406"
"59051","354.27000","29.52270","0.21354"
"59100","354.56400","29.54721","0.21477"
"59149","354.85800","29.57166","0.21764"
"59198","355.15200","29.59618","0.21788"
"59247","355.44600","29.62069","0.22084"
"59296","355.74000","29.64515","0.22450"
"59345","356.03400","29.66966","0.22573"
"59394","356.32800","29.69411","0.22571"
"59443","356.62200","29.71875","0.22867"
"59492","356.91600","29.74314","0.22946"
"59541","357.21000","29.76765","0.23031"
"59590","357.50400","29.79217","0.23298"
"59639","357.79800","29.81662","0.23409"
"59688","358.09200","29.84114","0.23507"
"59737","358.38600","29.86559","0.01680"
"59786","358.68000","29.89022","0.02235"
"59835","358.97400","29.91468","0.00715"
"59884","359.26800","29.93919","0.01335"
"59933","359.56200","29.96365","0.01182"
"59982","359.85600","29.98822","0.00897"
"60031","360.15000","30.01273","0.01252"
"60080","360.44400","30.03725","0.01001"
"60129","360.73800","30.06170","0.01918"
"60145","360.83200","30.06953","0.01137"