File: Trajectories_together/170226_2Specimen_RawData_4.csv
"","V1","V2","V3"
"1","End date","2/26/2017",""
"2","Specimen label","7DT_51",""
"3","Maximum Load","0.08631","N"
"4","Time","Extension","Load"
"5","(s)","(mm)","(N)"
"6","0.00000","0.00000","-0.00048"
"66","0.36000","0.03013","0.00073"
"126","0.72000","0.06021","0.00005"
"186","1.08000","0.09022","0.00029"
"246","1.44000","0.12018","0.00063"
"306","1.80000","0.15013","0.00061"
"366","2.16000","0.18021","0.00148"
"426","2.52000","0.21022","0.00133"
"486","2.88000","0.24011","0.00116"
"546","3.24000","0.27025","0.00136"
"606","3.60000","0.30020","0.00195"
"666","3.96000","0.33016","0.00207"
"726","4.32000","0.36017","0.00164"
"786","4.68000","0.39019","0.00172"
"846","5.04000","0.42008","0.00218"
"906","5.40000","0.45022","0.00201"
"966","5.76000","0.48023","0.00218"
"1026","6.12000","0.51012","0.00221"
"1086","6.48000","0.54020","0.00271"
"1146","6.84000","0.57021","0.00221"
"1206","7.20000","0.60011","0.00223"
"1266","7.56000","0.63018","0.00245"
"1326","7.92000","0.66020","0.00282"
"1386","8.28000","0.69021","0.00240"
"1446","8.64000","0.72016","0.00244"
"1506","9.00000","0.75030","0.00325"
"1566","9.36000","0.78013","0.00247"
"1626","9.72000","0.81015","0.00288"
"1686","10.08000","0.84022","0.00223"
"1746","10.44000","0.87018","0.00307"
"1806","10.80000","0.90019","0.00241"
"1866","11.16000","0.93021","0.00311"
"1926","11.52000","0.96010","0.00213"
"1986","11.88000","0.99023","0.00359"
"2046","12.24000","1.02025","0.00242"
"2106","12.60000","1.05014","0.00308"
"2166","12.96000","1.08016","0.00304"
"2226","13.32000","1.11023","0.00335"
"2286","13.68000","1.14013","0.00351"
"2346","14.04000","1.17020","0.00341"
"2406","14.40000","1.20022","0.00259"
"2466","14.76000","1.23017","0.00309"
"2526","15.12000","1.26018","0.00343"
"2586","15.48000","1.29014","0.00339"
"2646","15.84000","1.32015","0.00427"
"2706","16.20000","1.35017","0.00342"
"2766","16.56000","1.38024","0.00355"
"2826","16.92000","1.41014","0.00375"
"2886","17.28000","1.44021","0.00404"
"2946","17.64000","1.47016","0.00376"
"3006","18.00000","1.50018","0.00428"
"3066","18.36000","1.53013","0.00370"
"3126","18.72000","1.56021","0.00398"
"3186","19.08000","1.59016","0.00423"
"3246","19.44000","1.62024","0.00443"
"3306","19.80000","1.65019","0.00459"
"3366","20.16000","1.68021","0.00497"
"3426","20.52000","1.71016","0.00476"
"3486","20.88000","1.74023","0.00493"
"3546","21.24000","1.77013","0.00452"
"3606","21.60000","1.80020","0.00437"
"3666","21.96000","1.83016","0.00472"
"3726","22.32000","1.86017","0.00497"
"3786","22.68000","1.89013","0.00498"
"3846","23.04000","1.92020","0.00548"
"3906","23.40000","1.95016","0.00477"
"3966","23.76000","1.98017","0.00557"
"4026","24.12000","2.01012","0.00541"
"4086","24.48000","2.04020","0.00544"
"4146","24.84000","2.07021","0.00560"
"4206","25.20000","2.10017","0.00582"
"4266","25.56000","2.13018","0.00520"
"4326","25.92000","2.16020","0.00575"
"4386","26.28000","2.19015","0.00583"
"4446","26.64000","2.22022","0.00575"
"4506","27.00000","2.25012","0.00550"
"4566","27.36000","2.28019","0.00622"
"4626","27.72000","2.31015","0.00585"
"4686","28.08000","2.34022","0.00583"
"4746","28.44000","2.37018","0.00606"
"4806","28.80000","2.40019","0.00563"
"4866","29.16000","2.43015","0.00596"
"4926","29.52000","2.46022","0.00622"
"4986","29.88000","2.49017","0.00585"
"5046","30.24000","2.52019","0.00618"
"5106","30.60000","2.55020","0.00622"
"5166","30.96000","2.58016","0.00638"
"5226","31.32000","2.61017","0.00696"
"5286","31.68000","2.64019","0.00646"
"5346","32.04000","2.67014","0.00746"
"5406","32.40000","2.70010","0.00698"
"5466","32.76000","2.73017","0.00646"
"5526","33.12000","2.76018","0.00673"
"5586","33.48000","2.79020","0.00702"
"5646","33.84000","2.82021","0.00730"
"5706","34.20000","2.85017","0.00736"
"5766","34.56000","2.88018","0.00690"
"5826","34.92000","2.91020","0.00659"
"5886","35.28000","2.94021","0.00715"
"5946","35.64000","2.97016","0.00728"
"6006","36.00000","3.00018","0.00837"
"6066","36.36000","3.03025","0.00752"
"6126","36.72000","3.06015","0.00793"
"6186","37.08000","3.09022","0.00742"
"6246","37.44000","3.12018","0.00773"
"6306","37.80000","3.15019","0.00789"
"6366","38.16000","3.18027","0.00829"
"6426","38.52000","3.21016","0.00864"
"6486","38.88000","3.24017","0.00854"
"6546","39.24000","3.27025","0.00845"
"6606","39.60000","3.30014","0.00827"
"6666","39.96000","3.33016","0.00860"
"6726","40.32000","3.36023","0.00848"
"6786","40.68000","3.39019","0.00867"
"6846","41.04000","3.42014","0.00887"
"6906","41.40000","3.45021","0.00942"
"6966","41.76000","3.48017","0.00913"
"7026","42.12000","3.51018","0.00928"
"7086","42.48000","3.54020","0.00916"
"7146","42.84000","3.57021","0.00953"
"7206","43.20000","3.60017","0.01011"
"7266","43.56000","3.63018","0.00959"
"7326","43.92000","3.66020","0.01001"
"7386","44.28000","3.69021","0.00982"
"7446","44.64000","3.72022","0.01050"
"7506","45.00000","3.75024","0.01036"
"7566","45.36000","3.78013","0.01032"
"7626","45.72000","3.81021","0.01030"
"7686","46.08000","3.84022","0.01066"
"7746","46.44000","3.87012","0.01103"
"7806","46.80000","3.90019","0.01127"
"7866","47.16000","3.93027","0.01054"
"7926","47.52000","3.96016","0.01096"
"7986","47.88000","3.99017","0.01052"
"8046","48.24000","4.02019","0.01063"
"8106","48.60000","4.05014","0.01086"
"8166","48.96000","4.08022","0.01133"
"8226","49.32000","4.11023","0.01177"
"8286","49.68000","4.14013","0.01141"
"8346","50.04000","4.17020","0.01217"
"8406","50.40000","4.20021","0.01169"
"8466","50.76000","4.23017","0.01123"
"8526","51.12000","4.26018","0.01173"
"8586","51.48000","4.29020","0.01247"
"8646","51.84000","4.32015","0.01203"
"8706","52.20000","4.35017","0.01228"
"8766","52.56000","4.38018","0.01199"
"8826","52.92000","4.41014","0.01199"
"8886","53.28000","4.44021","0.01258"
"8946","53.64000","4.47022","0.01232"
"9006","54.00000","4.50012","0.01265"
"9066","54.36000","4.53019","0.01263"
"9126","54.72000","4.56021","0.01238"
"9186","55.08000","4.59016","0.01276"
"9246","55.44000","4.62018","0.01281"
"9306","55.80000","4.65025","0.01272"
"9366","56.16000","4.68015","0.01277"
"9426","56.52000","4.71016","0.01368"
"9486","56.88000","4.74023","0.01295"
"9546","57.24000","4.77013","0.01296"
"9606","57.60000","4.80020","0.01236"
"9666","57.96000","4.83022","0.01166"
"9726","58.32000","4.86017","0.01225"
"9786","58.68000","4.89019","0.01267"
"9846","59.04000","4.92026","0.01283"
"9906","59.40000","4.95015","0.01325"
"9966","59.76000","4.98023","0.01276"
"10026","60.12000","5.01018","0.01337"
"10086","60.48000","5.04020","0.01299"
"10146","60.84000","5.07015","0.01362"
"10206","61.20000","5.10023","0.01369"
"10266","61.56000","5.13018","0.01334"
"10326","61.92000","5.16026","0.01399"
"10386","62.28000","5.19021","0.01389"
"10446","62.64000","5.22016","0.01441"
"10506","63.00000","5.25018","0.01462"
"10566","63.36000","5.28025","0.01462"
"10626","63.72000","5.31009","0.01445"
"10686","64.08000","5.34022","0.01494"
"10746","64.44000","5.37018","0.01502"
"10806","64.80000","5.40019","0.01520"
"10866","65.16000","5.43015","0.01458"
"10926","65.52000","5.46022","0.01509"
"10986","65.88000","5.49011","0.01535"
"11046","66.24000","5.52019","0.01472"
"11106","66.60000","5.55020","0.01518"
"11166","66.96000","5.58016","0.01564"
"11226","67.32000","5.61017","0.01521"
"11286","67.68000","5.64019","0.01473"
"11346","68.04000","5.67014","0.01479"
"11406","68.40000","5.70021","0.01432"
"11466","68.76000","5.73017","0.01485"
"11526","69.12000","5.76018","0.01492"
"11586","69.48000","5.79014","0.01522"
"11646","69.84000","5.82021","0.01509"
"11706","70.20000","5.85017","0.01476"
"11766","70.56000","5.88018","0.01527"
"11826","70.92000","5.91020","0.01515"
"11886","71.28000","5.94015","0.01523"
"11946","71.64000","5.97016","0.01499"
"12006","72.00000","6.00018","0.01570"
"12066","72.36000","6.03013","0.01570"
"12126","72.72000","6.06021","0.01616"
"12186","73.08000","6.09022","0.01572"
"12246","73.44000","6.12012","0.01569"
"12306","73.80000","6.15019","0.01555"
"12366","74.16000","6.18020","0.01627"
"12426","74.52000","6.21016","0.01682"
"12486","74.88000","6.24017","0.01720"
"12546","75.24000","6.27019","0.01771"
"12606","75.60000","6.30014","0.01762"
"12666","75.96000","6.33016","0.01773"
"12726","76.32000","6.36017","0.01719"
"12786","76.68000","6.39019","0.01845"
"12846","77.04000","6.42014","0.01767"
"12906","77.40000","6.45021","0.01837"
"12966","77.76000","6.48017","0.01832"
"13026","78.12000","6.51018","0.01798"
"13086","78.48000","6.54020","0.01818"
"13146","78.84000","6.57015","0.01841"
"13206","79.20000","6.60017","0.01907"
"13266","79.56000","6.63024","0.01899"
"13326","79.92000","6.66025","0.01933"
"13386","80.28000","6.69021","0.01890"
"13446","80.64000","6.72022","0.01896"
"13506","81.00000","6.75024","0.01837"
"13566","81.36000","6.78013","0.01906"
"13626","81.72000","6.81027","0.01819"
"13686","82.08000","6.84016","0.01821"
"13746","82.44000","6.87018","0.01814"
"13806","82.80000","6.90019","0.01831"
"13866","83.16000","6.93020","0.01876"
"13926","83.52000","6.96016","0.01916"
"13986","83.88000","6.99017","0.01943"
"14046","84.24000","7.02013","0.02005"
"14106","84.60000","7.05014","0.02015"
"14166","84.96000","7.08016","0.02020"
"14226","85.32000","7.11023","0.01961"
"14286","85.68000","7.14019","0.02045"
"14346","86.04000","7.17020","0.02123"
"14406","86.40000","7.20015","0.02087"
"14466","86.76000","7.23017","0.02146"
"14526","87.12000","7.26024","0.02194"
"14586","87.48000","7.29020","0.02136"
"14646","87.84000","7.32015","0.02184"
"14706","88.20000","7.35017","0.02215"
"14766","88.56000","7.38018","0.02192"
"14826","88.92000","7.41014","0.02193"
"14886","89.28000","7.44021","0.02291"
"14946","89.64000","7.47016","0.02276"
"15006","90.00000","7.50018","0.02319"
"15066","90.36000","7.53019","0.02337"
"15126","90.72000","7.56015","0.02341"
"15186","91.08000","7.59010","0.02410"
"15246","91.44000","7.62018","0.02414"
"15306","91.80000","7.65019","0.02437"
"15366","92.16000","7.68015","0.02498"
"15426","92.52000","7.71022","0.02384"
"15486","92.88000","7.74017","0.02431"
"15546","93.24000","7.77013","0.02317"
"15606","93.60000","7.80020","0.02309"
"15666","93.96000","7.83022","0.02409"
"15726","94.32000","7.86017","0.02320"
"15786","94.68000","7.89019","0.02315"
"15846","95.04000","7.92020","0.02316"
"15906","95.40000","7.95015","0.02379"
"15966","95.76000","7.98017","0.02266"
"16026","96.12000","8.01018","0.02317"
"16086","96.48000","8.04014","0.02250"
"16146","96.84000","8.07021","0.02146"
"16206","97.20000","8.10023","0.01996"
"16266","97.56000","8.13012","0.01936"
"16326","97.92000","8.16020","0.02031"
"16386","98.28000","8.19021","0.02045"
"16446","98.64000","8.22016","0.02076"
"16506","99.00000","8.25024","0.02151"
"16566","99.36000","8.28019","0.02133"
"16626","99.72000","8.31015","0.02130"
"16686","100.08000","8.34028","0.02139"
"16746","100.44000","8.37018","0.02172"
"16806","100.80000","8.40013","0.02190"
"16866","101.16000","8.43020","0.02200"
"16926","101.52000","8.46022","0.02215"
"16986","101.88000","8.49011","0.02253"
"17046","102.24000","8.52025","0.02209"
"17106","102.60000","8.55020","0.02340"
"17166","102.96000","8.58010","0.02364"
"17226","103.32000","8.61023","0.02156"
"17286","103.68000","8.64025","0.02128"
"17346","104.04000","8.67008","0.02079"
"17406","104.40000","8.70021","0.02195"
"17466","104.76000","8.73017","0.02222"
"17526","105.12000","8.76018","0.02224"
"17586","105.48000","8.79020","0.02032"
"17646","105.84000","8.82027","0.02053"
"17706","106.20000","8.85011","0.02040"
"17766","106.56000","8.88018","0.01998"
"17826","106.92000","8.91020","0.01939"
"17886","107.28000","8.94009","0.02054"
"17946","107.64000","8.97016","0.02043"
"18006","108.00000","9.00024","0.02005"
"18066","108.36000","9.03013","0.02068"
"18126","108.72000","9.06021","0.02042"
"18186","109.08000","9.09016","0.02060"
"18246","109.44000","9.12018","0.02086"
"18306","109.80000","9.15019","0.02145"
"18366","110.16000","9.18021","0.02166"
"18426","110.52000","9.21016","0.02246"
"18486","110.88000","9.24017","0.02274"
"18546","111.24000","9.27019","0.02224"
"18606","111.60000","9.30014","0.02150"
"18666","111.96000","9.33016","0.01685"
"18726","112.32000","9.36023","0.01720"
"18786","112.68000","9.39013","0.01782"
"18846","113.04000","9.42020","0.01941"
"18906","113.40000","9.45021","0.01929"
"18966","113.76000","9.48011","0.01898"
"19026","114.12000","9.51018","0.01950"
"19086","114.48000","9.54026","0.01947"
"19146","114.84000","9.57015","0.02023"
"19206","115.20000","9.60017","0.02055"
"19266","115.56000","9.63024","0.02027"
"19326","115.92000","9.66014","0.02036"
"19386","116.28000","9.69021","0.02030"
"19446","116.64000","9.72016","0.02047"
"19506","117.00000","9.75018","0.02087"
"19566","117.36000","9.78013","0.02054"
"19626","117.72000","9.81021","0.02049"
"19686","118.08000","9.84016","0.01999"
"19746","118.44000","9.87024","0.01990"
"19806","118.80000","9.90019","0.02013"
"19866","119.16000","9.93020","0.02102"
"19926","119.52000","9.96016","0.02054"
"19986","119.88000","9.99017","0.02057"
"20046","120.24000","10.02013","0.02066"
"20106","120.60000","10.05020","0.02056"
"20166","120.96000","10.08016","0.02076"
"20226","121.32000","10.11017","0.02072"
"20286","121.68000","10.14012","0.02154"
"20346","122.04000","10.17020","0.02082"
"20406","122.40000","10.20015","0.01992"
"20466","122.76000","10.23023","0.01992"
"20526","123.12000","10.26018","0.01984"
"20586","123.48000","10.29014","0.01989"
"20646","123.84000","10.32021","0.01979"
"20706","124.20000","10.35023","0.01960"
"20766","124.56000","10.38012","0.02042"
"20826","124.92000","10.41019","0.02025"
"20886","125.28000","10.44021","0.02055"
"20946","125.64000","10.47022","0.02075"
"21006","126.00000","10.50018","0.02059"
"21066","126.36000","10.53019","0.02094"
"21126","126.72000","10.56015","0.02146"
"21186","127.08000","10.59022","0.02119"
"21246","127.44000","10.62018","0.02107"
"21306","127.80000","10.65013","0.02093"
"21366","128.16000","10.68014","0.02177"
"21426","128.52000","10.71022","0.02117"
"21486","128.88000","10.74017","0.02098"
"21546","129.24000","10.77019","0.01774"
"21606","129.60000","10.80020","0.01795"
"21666","129.96000","10.83016","0.01814"
"21726","130.32000","10.86017","0.01872"
"21786","130.68000","10.89024","0.01948"
"21846","131.04000","10.92020","0.01923"
"21906","131.40000","10.95015","0.01881"
"21966","131.76000","10.98023","0.01954"
"22026","132.12000","11.01018","0.01934"
"22086","132.48000","11.04014","0.01974"
"22146","132.84000","11.07021","0.01886"
"22206","133.20000","11.10017","0.01810"
"22266","133.56000","11.13018","0.01816"
"22326","133.92000","11.16019","0.01856"
"22386","134.28000","11.19015","0.01912"
"22446","134.64000","11.22016","0.01864"
"22506","135.00000","11.25018","0.01937"
"22566","135.36000","11.28019","0.02012"
"22626","135.72000","11.31021","0.02009"
"22686","136.08000","11.34022","0.02047"
"22746","136.44000","11.37017","0.02033"
"22806","136.80000","11.40019","0.02088"
"22866","137.16000","11.43014","0.02099"
"22926","137.52000","11.46016","0.02164"
"22986","137.88000","11.49017","0.02174"
"23046","138.24000","11.52019","0.02174"
"23106","138.60000","11.55014","0.02153"
"23166","138.96000","11.58016","0.02001"
"23226","139.32000","11.61017","0.01986"
"23286","139.68000","11.64025","0.02051"
"23346","140.04000","11.67014","0.02086"
"23406","140.40000","11.70021","0.02087"
"23466","140.76000","11.73017","0.02105"
"23526","141.12000","11.76018","0.02103"
"23586","141.48000","11.79020","0.02172"
"23646","141.84000","11.82021","0.02181"
"23706","142.20000","11.85017","0.02194"
"23766","142.56000","11.88024","0.02304"
"23826","142.92000","11.91019","0.02225"
"23886","143.28000","11.94015","0.02217"
"23946","143.64000","11.97016","0.02143"
"24006","144.00000","12.00024","0.02051"
"24066","144.36000","12.03019","0.02058"
"24126","144.72000","12.06027","0.02049"
"24186","145.08000","12.09022","0.02051"
"24246","145.44000","12.12018","0.02095"
"24306","145.80000","12.15019","0.02070"
"24366","146.16000","12.18020","0.02151"
"24426","146.52000","12.21016","0.02178"
"24486","146.88000","12.24017","0.02134"
"24546","147.24000","12.27019","0.02134"
"24606","147.60000","12.30020","0.02170"
"24666","147.96000","12.33022","0.02201"
"24726","148.32000","12.36023","0.02194"
"24786","148.68000","12.39012","0.02166"
"24846","149.04000","12.42020","0.02236"
"24906","149.40000","12.45015","0.02267"
"24966","149.76000","12.48017","0.02267"
"25026","150.12000","12.51018","0.02308"
"25086","150.48000","12.54020","0.02322"
"25146","150.84000","12.57015","0.02328"
"25206","151.20000","12.60023","0.02317"
"25266","151.56000","12.63018","0.02284"
"25326","151.92000","12.66013","0.02412"
"25386","152.28000","12.69021","0.02384"
"25446","152.64000","12.72016","0.02403"
"25506","153.00000","12.75012","0.02431"
"25566","153.36000","12.78019","0.02360"
"25626","153.72000","12.81021","0.02333"
"25686","154.08000","12.84010","0.02351"
"25746","154.44000","12.87017","0.02426"
"25806","154.80000","12.90019","0.02409"
"25866","155.16000","12.93014","0.02405"
"25926","155.52000","12.96016","0.02505"
"25986","155.88000","12.99017","0.02545"
"26046","156.24000","13.02019","0.02516"
"26106","156.60000","13.05026","0.02569"
"26166","156.96000","13.08022","0.02639"
"26226","157.32000","13.11017","0.02606"
"26286","157.68000","13.14018","0.02628"
"26346","158.04000","13.17020","0.02638"
"26406","158.40000","13.20015","0.02758"
"26466","158.76000","13.23023","0.02702"
"26526","159.12000","13.26024","0.02793"
"26586","159.48000","13.29014","0.02776"
"26646","159.84000","13.32021","0.02820"
"26706","160.20000","13.35023","0.02846"
"26766","160.56000","13.38012","0.02889"
"26826","160.92000","13.41025","0.02890"
"26886","161.28000","13.44021","0.02870"
"26946","161.64000","13.47016","0.02888"
"27006","162.00000","13.50018","0.02938"
"27066","162.36000","13.53025","0.02872"
"27126","162.72000","13.56009","0.02991"
"27186","163.08000","13.59022","0.02972"
"27246","163.44000","13.62018","0.03037"
"27306","163.80000","13.65013","0.03050"
"27366","164.16000","13.68015","0.03031"
"27426","164.52000","13.71022","0.03125"
"27486","164.88000","13.74011","0.03165"
"27546","165.24000","13.77025","0.03234"
"27606","165.60000","13.80014","0.03247"
"27666","165.96000","13.83016","0.03284"
"27726","166.32000","13.86017","0.03358"
"27786","166.68000","13.89024","0.03360"
"27846","167.04000","13.92014","0.03466"
"27906","167.40000","13.95021","0.03505"
"27966","167.76000","13.98023","0.03521"
"28026","168.12000","14.01012","0.03626"
"28086","168.48000","14.04014","0.03648"
"28146","168.84000","14.07021","0.03645"
"28206","169.20000","14.10011","0.03786"
"28266","169.56000","14.13018","0.03866"
"28326","169.92000","14.16014","0.03894"
"28386","170.28000","14.19015","0.03890"
"28446","170.64000","14.22016","0.03912"
"28506","171.00000","14.25018","0.03998"
"28566","171.36000","14.28013","0.04092"
"28626","171.72000","14.31021","0.04156"
"28686","172.08000","14.34022","0.04136"
"28746","172.44000","14.37018","0.04211"
"28806","172.80000","14.40013","0.04341"
"28866","173.16000","14.43020","0.04357"
"28926","173.52000","14.46016","0.04411"
"28986","173.88000","14.49017","0.04438"
"29046","174.24000","14.52019","0.04526"
"29106","174.60000","14.55014","0.04546"
"29166","174.96000","14.58022","0.04620"
"29226","175.32000","14.61017","0.04662"
"29286","175.68000","14.64019","0.04725"
"29346","176.04000","14.67020","0.04745"
"29406","176.40000","14.70021","0.04811"
"29466","176.76000","14.73017","0.04832"
"29526","177.12000","14.76018","0.04897"
"29586","177.48000","14.79020","0.04932"
"29646","177.84000","14.82021","0.04990"
"29706","178.20000","14.85017","0.05011"
"29766","178.56000","14.88018","0.05073"
"29826","178.92000","14.91020","0.05172"
"29886","179.28000","14.94021","0.05184"
"29946","179.64000","14.97022","0.05244"
"30006","180.00000","15.00018","0.05272"
"30066","180.36000","15.03019","0.05338"
"30126","180.72000","15.06021","0.05429"
"30186","181.08000","15.09016","0.05488"
"30246","181.44000","15.12018","0.05546"
"30306","181.80000","15.15019","0.05666"
"30366","182.16000","15.18020","0.05736"
"30426","182.52000","15.21016","0.05774"
"30486","182.88000","15.24023","0.05917"
"30546","183.24000","15.27019","0.05968"
"30606","183.60000","15.30020","0.06111"
"30666","183.96000","15.33016","0.06209"
"30726","184.32000","15.36017","0.06303"
"30786","184.68000","15.39013","0.06450"
"30846","185.04000","15.42020","0.06544"
"30906","185.40000","15.45015","0.06649"
"30966","185.76000","15.48017","0.06779"
"31026","186.12000","15.51018","0.06908"
"31086","186.48000","15.54014","0.07002"
"31146","186.84000","15.57015","0.07195"
"31206","187.20000","15.60023","0.07352"
"31266","187.56000","15.63018","0.07505"
"31326","187.92000","15.66019","0.07631"
"31386","188.28000","15.69021","0.07771"
"31446","188.64000","15.72016","0.07908"
"31506","189.00000","15.75018","0.08097"
"31566","189.36000","15.78019","0.08226"
"31626","189.72000","15.81021","0.08302"
"31686","190.08000","15.84016","0.08421"
"31746","190.44000","15.87017","0.08531"
"31806","190.80000","15.90013","0.08334"
"31866","191.16000","15.93014","0.07131"
"31926","191.52000","15.96022","0.07102"
"31986","191.88000","15.99023","0.07162"
"32046","192.24000","16.02019","0.06945"
"32106","192.60000","16.05020","0.07031"
"32166","192.96000","16.08022","0.07008"
"32226","193.32000","16.11011","0.07020"
"32286","193.68000","16.14018","0.00470"
"32346","194.04000","16.17020","0.00631"
"32406","194.40000","16.20015","0.00288"
"32466","194.76000","16.23023","0.00345"
"32526","195.12000","16.26018","0.00330"
"32586","195.48000","16.29014","0.00251"
"32646","195.84000","16.32027","0.00309"
"32706","196.20000","16.35016","0.00219"
"32766","196.56000","16.38012","0.00321"
"32826","196.92000","16.41019","0.00293"
"32886","197.28000","16.44021","0.00294"
"32946","197.64000","16.47016","0.00314"
"33006","198.00000","16.50018","0.00248"
"33066","198.36000","16.53019","0.00292"
"33126","198.72000","16.56009","0.00276"
"33186","199.08000","16.59022","0.00262"
"33246","199.44000","16.62017","0.00280"
"33306","199.80000","16.65013","0.00306"
"33366","200.16000","16.68026","0.00355"
"33426","200.52000","16.71028","0.00273"
"33486","200.88000","16.74011","0.00348"
"33546","201.24000","16.77024","0.00296"
"33606","201.60000","16.80020","0.00299"
"33666","201.96000","16.83016","0.00299"
"33726","202.32000","16.86017","0.00311"
"33786","202.68000","16.89025","0.00326"
"33846","203.04000","16.92008","0.00343"
"33906","203.40000","16.95021","0.00329"
"33966","203.76000","16.98017","0.00342"
"34026","204.12000","17.01018","0.00316"
"34086","204.48000","17.04020","0.00395"
"34146","204.84000","17.07021","0.00315"
"34206","205.20000","17.10011","0.00306"
"34266","205.56000","17.13024","0.00355"
"34326","205.92000","17.16019","0.00318"
"34386","206.28000","17.19021","0.00336"
"34446","206.64000","17.22016","0.00323"
"34506","207.00000","17.25024","0.00331"
"34566","207.36000","17.28013","0.00364"
"34626","207.72000","17.31021","0.00301"
"34686","208.08000","17.34016","0.00387"
"34746","208.44000","17.37017","0.00368"
"34806","208.80000","17.40019","0.00369"
"34866","209.16000","17.43020","0.00364"
"34926","209.52000","17.46010","0.00436"
"34986","209.88000","17.49029","0.00359"
"35046","210.24000","17.52025","0.00391"
"35106","210.60000","17.55014","0.00431"
"35166","210.96000","17.58022","0.00374"
"35226","211.32000","17.61023","0.00359"
"35286","211.68000","17.64013","0.00337"
"35346","212.04000","17.67020","0.00349"
"35406","212.40000","17.70021","0.00340"
"35466","212.76000","17.73017","0.00395"
"35526","213.12000","17.76018","0.00390"
"35586","213.48000","17.79020","0.00357"
"35646","213.84000","17.82009","0.00413"
"35706","214.20000","17.85016","0.00388"
"35766","214.56000","17.88018","0.00408"
"35826","214.92000","17.91019","0.00437"
"35886","215.28000","17.94021","0.00471"
"35946","215.64000","17.97022","0.00355"
"36006","216.00000","18.00012","0.00413"
"36066","216.36000","18.03019","0.00384"
"36126","216.72000","18.06021","0.00401"
"36186","217.08000","18.09016","0.00445"
"36246","217.44000","18.12024","0.00447"
"36306","217.80000","18.15019","0.00422"
"36366","218.16000","18.18014","0.00438"
"36426","218.52000","18.21016","0.00412"
"36486","218.88000","18.24023","0.00435"
"36546","219.24000","18.27013","0.00429"
"36606","219.60000","18.30020","0.00391"
"36666","219.96000","18.33022","0.00484"
"36726","220.32000","18.36017","0.00407"
"36786","220.68000","18.39018","0.00446"
"36846","221.04000","18.42026","0.00420"
"36906","221.40000","18.45015","0.00439"
"36966","221.76000","18.48023","0.00442"
"37026","222.12000","18.51018","0.00427"
"37086","222.48000","18.54020","0.00410"
"37146","222.84000","18.57021","0.00391"
"37206","223.20000","18.60023","0.00351"
"37266","223.56000","18.63012","0.00445"
"37326","223.92000","18.66019","0.00396"
"37386","224.28000","18.69021","0.00437"
"37446","224.64000","18.72016","0.00426"
"37506","225.00000","18.75012","0.00419"
"37566","225.36000","18.78025","0.00467"
"37626","225.72000","18.81015","0.00436"
"37686","226.08000","18.84022","0.00448"
"37746","226.44000","18.87017","0.00421"
"37806","226.80000","18.90019","0.00450"
"37866","227.16000","18.93014","0.00429"
"37926","227.52000","18.96028","0.00450"
"37986","227.88000","18.99017","0.00457"
"38046","228.24000","19.02019","0.00452"
"38106","228.60000","19.05020","0.00471"
"38166","228.96000","19.08022","0.00459"
"38226","229.32000","19.11017","0.00468"
"38286","229.68000","19.14024","0.00440"
"38346","230.04000","19.17014","0.00455"
"38406","230.40000","19.20015","0.00438"
"38466","230.76000","19.23017","0.00433"
"38526","231.12000","19.26018","0.00423"
"38586","231.48000","19.29020","0.00440"
"38646","231.84000","19.32021","0.00448"
"38706","232.20000","19.35017","0.00491"
"38766","232.56000","19.38018","0.00461"
"38826","232.92000","19.41019","0.00484"
"38886","233.28000","19.44015","0.00461"
"38946","233.64000","19.47010","0.00458"
"39006","234.00000","19.50018","0.00490"
"39066","234.36000","19.53019","0.00389"
"39126","234.72000","19.56014","0.00447"
"39186","235.08000","19.59022","0.00405"
"39246","235.44000","19.62017","0.00414"
"39306","235.80000","19.65019","0.00455"
"39366","236.16000","19.68020","0.00427"
"39426","236.52000","19.71016","0.00465"
"39486","236.88000","19.74017","0.00397"
"39546","237.24000","19.77019","0.00387"
"39606","237.60000","19.80014","0.00451"
"39666","237.96000","19.83016","0.00410"
"39726","238.32000","19.86023","0.00436"
"39786","238.68000","19.89018","0.00393"
"39846","239.04000","19.92014","0.00400"
"39906","239.40000","19.95021","0.00398"
"39966","239.76000","19.98017","0.00366"
"40026","240.12000","20.01018","0.00397"
"40086","240.48000","20.04020","0.00452"
"40146","240.84000","20.07021","0.00405"
"40206","241.20000","20.10016","0.00279"
"40266","241.56000","20.13024","0.00393"
"40326","241.92000","20.16019","0.00404"
"40386","242.28000","20.19015","0.00364"
"40446","242.64000","20.22016","0.00375"
"40506","243.00000","20.25023","0.00385"
"40566","243.36000","20.28019","0.00385"
"40626","243.72000","20.31021","0.00374"
"40686","244.08000","20.34022","0.00316"
"40746","244.44000","20.37017","0.00366"
"40806","244.80000","20.40019","0.00302"
"40866","245.16000","20.43020","0.00363"
"40926","245.52000","20.46016","0.00371"
"40986","245.88000","20.49023","0.00366"
"41046","246.24000","20.52019","0.00372"
"41106","246.60000","20.55020","0.00374"
"41166","246.96000","20.58022","0.00318"
"41226","247.32000","20.61017","0.00339"
"41286","247.68000","20.64012","0.00379"
"41346","248.04000","20.67026","0.00367"
"41406","248.40000","20.70021","0.00324"
"41466","248.76000","20.73017","0.00413"
"41526","249.12000","20.76018","0.00330"
"41586","249.48000","20.79020","0.00391"
"41646","249.84000","20.82009","0.00396"
"41706","250.20000","20.85022","0.00364"
"41766","250.56000","20.88018","0.00377"
"41826","250.92000","20.91019","0.00324"
"41886","251.28000","20.94021","0.00387"
"41946","251.64000","20.97022","0.00415"
"42006","252.00000","21.00011","0.00343"
"42066","252.36000","21.03019","0.00373"
"42126","252.72000","21.06020","0.00398"
"42186","253.08000","21.09016","0.00333"
"42246","253.44000","21.12024","0.00335"
"42306","253.80000","21.15025","0.00345"
"42366","254.16000","21.18014","0.00439"
"42426","254.52000","21.21022","0.00347"
"42486","254.88000","21.24017","0.00386"
"42546","255.24000","21.27012","0.00417"
"42606","255.60000","21.30020","0.00342"
"42666","255.96000","21.33021","0.00401"
"42726","256.32000","21.36011","0.00408"
"42786","256.68000","21.39018","0.00383"
"42846","257.04000","21.42020","0.00333"
"42906","257.40000","21.45015","0.00401"
"42966","257.76000","21.48023","0.00377"
"43026","258.12000","21.51024","0.00361"
"43086","258.48000","21.54013","0.00380"
"43146","258.84000","21.57021","0.00429"
"43206","259.20000","21.60022","0.00437"
"43266","259.56000","21.63012","0.00390"
"43326","259.92000","21.66025","0.00377"
"43386","260.28000","21.69021","0.00332"
"43446","260.64000","21.72010","0.00383"
"43506","261.00000","21.75017","0.00366"
"43566","261.36000","21.78025","0.00378"
"43626","261.72000","21.81009","0.00374"
"43686","262.08000","21.84022","0.00360"
"43746","262.44000","21.87023","0.00384"
"43806","262.80000","21.90013","0.00425"
"43866","263.16000","21.93020","0.00363"
"43926","263.52000","21.96022","0.00364"
"43986","263.88000","21.99011","0.00401"
"44046","264.24000","22.02025","0.00358"
"44106","264.60000","22.05020","0.00419"
"44166","264.96000","22.08015","0.00338"
"44226","265.32000","22.11017","0.00424"
"44286","265.68000","22.14024","0.00365"
"44346","266.04000","22.17014","0.00380"
"44406","266.40000","22.20021","0.00368"
"44466","266.76000","22.23017","0.00354"
"44526","267.12000","22.26018","0.00390"
"44586","267.48000","22.29014","0.00396"
"44646","267.84000","22.32021","0.00359"
"44706","268.20000","22.35017","0.00354"
"44766","268.56000","22.38018","0.00396"
"44826","268.92000","22.41019","0.00376"
"44886","269.28000","22.44015","0.00327"
"44946","269.64000","22.47016","0.00355"
"45006","270.00000","22.50024","0.00387"
"45066","270.36000","22.53013","0.00393"
"45126","270.72000","22.56021","0.00371"
"45186","271.08000","22.59022","0.00400"
"45246","271.44000","22.62017","0.00401"
"45306","271.80000","22.65019","0.00333"
"45366","272.16000","22.68020","0.00390"
"45426","272.52000","22.71016","0.00409"
"45486","272.88000","22.74023","0.00404"
"45546","273.24000","22.77013","0.00322"
"45606","273.60000","22.80014","0.00344"
"45666","273.96000","22.83015","0.00404"
"45726","274.32000","22.86023","0.00363"
"45786","274.68000","22.89012","0.00345"
"45846","275.04000","22.92014","0.00393"
"45906","275.40000","22.95015","0.00347"
"45966","275.76000","22.98017","0.00344"
"46026","276.12000","23.01018","0.00338"
"46086","276.48000","23.04020","0.00331"
"46146","276.84000","23.07015","0.00318"
"46206","277.20000","23.10023","0.00372"
"46266","277.56000","23.13018","0.00365"
"46326","277.92000","23.16019","0.00321"
"46386","278.28000","23.19015","0.00386"
"46446","278.64000","23.22022","0.00311"
"46506","279.00000","23.25018","0.00304"
"46566","279.36000","23.28019","0.00358"
"46626","279.72000","23.31021","0.00315"
"46686","280.08000","23.34016","0.00284"
"46746","280.44000","23.37017","0.00353"
"46806","280.80000","23.40019","0.00276"
"46866","281.16000","23.43020","0.00362"
"46926","281.52000","23.46016","0.00336"
"46986","281.88000","23.49023","0.00347"
"47046","282.24000","23.52012","0.00313"
"47106","282.60000","23.55014","0.00335"
"47166","282.96000","23.58016","0.00320"
"47226","283.32000","23.61017","0.00374"
"47286","283.68000","23.64018","0.00375"
"47346","284.04000","23.67020","0.00364"
"47406","284.40000","23.70015","0.00360"
"47466","284.76000","23.73017","0.00397"
"47526","285.12000","23.76018","0.00423"
"47586","285.48000","23.79020","0.00345"
"47646","285.84000","23.82009","0.00338"
"47706","286.20000","23.85022","0.00367"
"47766","286.56000","23.88018","0.00328"
"47826","286.92000","23.91019","0.00295"
"47886","287.28000","23.94015","0.00334"
"47946","287.64000","23.97016","0.00393"
"48006","288.00000","24.00018","0.00365"
"48066","288.36000","24.03025","0.00343"
"48126","288.72000","24.06014","0.00329"
"48186","289.08000","24.09016","0.00327"
"48246","289.44000","24.12023","0.00355"
"48306","289.80000","24.15019","0.00283"
"48366","290.16000","24.18014","0.00335"
"48426","290.52000","24.21022","0.00324"
"48486","290.88000","24.24017","0.00353"
"48546","291.24000","24.27018","0.00414"
"48606","291.60000","24.30020","0.00321"
"48666","291.96000","24.33022","0.00342"
"48726","292.32000","24.36017","0.00345"
"48786","292.68000","24.39018","0.00319"
"48846","293.04000","24.42020","0.00339"
"48906","293.40000","24.45015","0.00377"
"48966","293.76000","24.48017","0.00314"
"49026","294.12000","24.51018","0.00366"
"49086","294.48000","24.54014","0.00368"
"49146","294.84000","24.57021","0.00347"
"49206","295.20000","24.60023","0.00342"
"49266","295.56000","24.63018","0.00415"
"49326","295.92000","24.66019","0.00313"
"49386","296.28000","24.69021","0.00409"
"49446","296.64000","24.72016","0.00433"
"49506","297.00000","24.75018","0.00318"
"49566","297.36000","24.78013","0.00345"
"49626","297.72000","24.81014","0.00376"
"49686","298.08000","24.84022","0.00358"
"49746","298.44000","24.87023","0.00337"
"49806","298.80000","24.90019","0.00355"
"49866","299.16000","24.93020","0.00368"
"49926","299.52000","24.96022","0.00342"
"49986","299.88000","24.99011","0.00357"
"50046","300.24000","25.02019","0.00345"
"50106","300.60000","25.05020","0.00378"
"50166","300.96000","25.08015","0.00381"
"50226","301.32000","25.11017","0.00400"
"50286","301.68000","25.14024","0.00380"
"50346","302.04000","25.17014","0.00374"
"50406","302.40000","25.20021","0.00367"
"50466","302.76000","25.23017","0.00390"
"50526","303.12000","25.26018","0.00331"
"50586","303.48000","25.29020","0.00374"
"50646","303.84000","25.32021","0.00350"
"50706","304.20000","25.35016","0.00357"
"50766","304.56000","25.38024","0.00373"
"50826","304.92000","25.41019","0.00387"
"50886","305.28000","25.44015","0.00330"
"50946","305.64000","25.47022","0.00381"
"51006","306.00000","25.50024","0.00411"
"51066","306.36000","25.53013","0.00394"
"51126","306.72000","25.56026","0.00385"
"51186","307.08000","25.59022","0.00383"
"51246","307.44000","25.62017","0.00395"
"51306","307.80000","25.65019","0.00337"
"51366","308.16000","25.68020","0.00393"
"51426","308.52000","25.71010","0.00368"
"51486","308.88000","25.74023","0.00347"
"51546","309.24000","25.77019","0.00351"
"51606","309.60000","25.80020","0.00378"
"51666","309.96000","25.83021","0.00459"
"51726","310.32000","25.86029","0.00374"
"51786","310.68000","25.89013","0.00373"
"51846","311.04000","25.92020","0.00332"
"51906","311.40000","25.95021","0.00360"
"51966","311.76000","25.98011","0.00367"
"52026","312.12000","26.01024","0.00362"
"52086","312.48000","26.04025","0.00317"
"52146","312.84000","26.07009","0.00392"
"52206","313.20000","26.10022","0.00308"
"52266","313.56000","26.13018","0.00376"
"52326","313.92000","26.16013","0.00373"
"52386","314.28000","26.19015","0.00387"
"52446","314.64000","26.22022","0.00395"
"52506","315.00000","26.25012","0.00404"
"52566","315.36000","26.28019","0.00410"
"52626","315.72000","26.31021","0.00333"
"52686","316.08000","26.34016","0.00398"
"52746","316.44000","26.37017","0.00366"
"52806","316.80000","26.40019","0.00372"
"52866","317.16000","26.43008","0.00383"
"52926","317.52000","26.46021","0.00377"
"52986","317.88000","26.49017","0.00364"
"53046","318.24000","26.52013","0.00379"
"53106","318.60000","26.55020","0.00367"
"53166","318.96000","26.58022","0.00315"
"53226","319.32000","26.61011","0.00398"
"53286","319.68000","26.64018","0.00376"
"53346","320.04000","26.67020","0.00368"
"53406","320.40000","26.70015","0.00358"
"53466","320.76000","26.73023","0.00377"
"53526","321.12000","26.76018","0.00358"
"53586","321.48000","26.79014","0.00406"
"53646","321.84000","26.82021","0.00347"
"53706","322.20000","26.85028","0.00363"
"53766","322.56000","26.88012","0.00344"
"53826","322.92000","26.91025","0.00366"
"53886","323.28000","26.94021","0.00362"
"53946","323.64000","26.97016","0.00324"
"54006","324.00000","27.00018","0.00378"
"54066","324.36000","27.03025","0.00421"
"54126","324.72000","27.06015","0.00328"
"54186","325.08000","27.09016","0.00396"
"54246","325.44000","27.12017","0.00391"
"54306","325.80000","27.15019","0.00405"
"54366","326.16000","27.18015","0.00376"
"54426","326.52000","27.21022","0.00371"
"54486","326.88000","27.24017","0.00333"
"54546","327.24000","27.27024","0.00332"
"54606","327.60000","27.30020","0.00354"
"54666","327.96000","27.33022","0.00315"
"54726","328.32000","27.36017","0.00375"
"54786","328.68000","27.39018","0.00329"
"54846","329.04000","27.42020","0.00314"
"54906","329.40000","27.45021","0.00271"
"54966","329.76000","27.48017","0.00334"
"55026","330.12000","27.51018","0.00331"
"55086","330.48000","27.54014","0.00347"
"55146","330.84000","27.57021","0.00289"
"55206","331.20000","27.60016","0.00355"
"55266","331.56000","27.63024","0.00324"
"55326","331.92000","27.66019","0.00350"
"55386","332.28000","27.69021","0.00298"
"55446","332.64000","27.72022","0.00341"
"55506","333.00000","27.75018","0.00292"
"55566","333.36000","27.78013","0.00318"
"55626","333.72000","27.81015","0.00342"
"55686","334.08000","27.84016","0.00351"
"55746","334.44000","27.87017","0.00360"
"55806","334.80000","27.90013","0.00339"
"55866","335.16000","27.93020","0.00381"
"55926","335.52000","27.96016","0.00303"
"55986","335.88000","27.99017","0.00305"
"56046","336.24000","28.02018","0.00374"
"56106","336.60000","28.05020","0.00374"
"56166","336.96000","28.08016","0.00323"
"56226","337.32000","28.11023","0.00282"
"56286","337.68000","28.14018","0.00331"
"56346","338.04000","28.17014","0.00302"
"56406","338.40000","28.20021","0.00347"
"56466","338.76000","28.23017","0.00262"
"56526","339.12000","28.26012","0.00346"
"56586","339.48000","28.29020","0.00318"
"56646","339.84000","28.32021","0.00302"
"56706","340.20000","28.35022","0.00288"
"56766","340.56000","28.38024","0.00366"
"56826","340.92000","28.41019","0.00352"
"56886","341.28000","28.44015","0.00333"
"56946","341.64000","28.47022","0.00315"
"57006","342.00000","28.50018","0.00288"
"57066","342.36000","28.53019","0.00285"
"57126","342.72000","28.56021","0.00292"
"57186","343.08000","28.59016","0.00289"
"57246","343.44000","28.62017","0.00318"
"57306","343.80000","28.65019","0.00340"
"57366","344.16000","28.68020","0.00345"
"57426","344.52000","28.71022","0.00400"
"57486","344.88000","28.74017","0.00294"
"57546","345.24000","28.77018","0.00335"
"57606","345.60000","28.80014","0.00288"
"57666","345.96000","28.83027","0.00324"
"57726","346.32000","28.86023","0.00366"
"57786","346.68000","28.89013","0.00297"
"57846","347.04000","28.92020","0.00304"
"57906","347.40000","28.95021","0.00285"
"57966","347.76000","28.98017","0.00354"
"58026","348.12000","29.01024","0.00295"
"58086","348.48000","29.04020","0.00314"
"58146","348.84000","29.07015","0.00299"
"58206","349.20000","29.10016","0.00294"
"58266","349.56000","29.13018","0.00335"
"58326","349.92000","29.16014","0.00326"
"58386","350.28000","29.19021","0.00382"
"58446","350.64000","29.22022","0.00357"
"58506","351.00000","29.25011","0.00332"
"58566","351.36000","29.28025","0.00281"
"58626","351.72000","29.31020","0.00310"
"58686","352.08000","29.34016","0.00310"
"58746","352.44000","29.37017","0.00319"
"58806","352.80000","29.40019","0.00304"
"58866","353.16000","29.43014","0.00278"
"58926","353.52000","29.46016","0.00270"
"58986","353.88000","29.49017","0.00329"
"59046","354.24000","29.52019","0.00318"
"59106","354.60000","29.55020","0.00275"
"59166","354.96000","29.58021","0.00321"
"59226","355.32000","29.61011","0.00297"
"59286","355.68000","29.64018","0.00375"
"59346","356.04000","29.67020","0.00318"
"59406","356.40000","29.70015","0.00283"
"59466","356.76000","29.73023","0.00318"
"59526","357.12000","29.76024","0.00289"
"59586","357.48000","29.79014","0.00242"
"59646","357.84000","29.82021","0.00296"
"59706","358.20000","29.85023","0.00257"
"59766","358.56000","29.88018","0.00292"
"59826","358.92000","29.91019","0.00328"
"59886","359.28000","29.94021","0.00294"
"59946","359.64000","29.97016","0.00373"
"60006","360.00000","30.00018","0.00281"
"60066","360.36000","30.03025","0.00293"
"60126","360.72000","30.06015","0.00272"
"60186","361.08000","30.09016","0.00275"
"60246","361.44000","30.12024","0.00298"
"60306","361.80000","30.15013","0.00239"
"60366","362.16000","30.18014","0.00324"
"60426","362.52000","30.21022","0.00364"
"60486","362.88000","30.24011","0.00306"
"60546","363.24000","30.27025","0.00319"
"60606","363.60000","30.30020","0.00356"
"60666","363.96000","30.33015","0.00292"
"60726","364.32000","30.36017","0.00331"
"60786","364.68000","30.39024","0.00269"
"60846","365.04000","30.42014","0.00281"
"60906","365.40000","30.45021","0.00338"
"60966","365.76000","30.48023","0.00331"
"61026","366.12000","30.51018","0.00266"
"61086","366.48000","30.54019","0.00306"
"61146","366.84000","30.57021","0.00272"
"61206","367.20000","30.60011","0.00271"
"61266","367.56000","30.63024","0.00314"
"61326","367.92000","30.66019","0.00301"
"61386","368.28000","30.69021","0.00297"
"61446","368.64000","30.72022","0.00304"
"61506","369.00000","30.75018","0.00326"
"61566","369.36000","30.78013","0.00308"
"61626","369.72000","30.81020","0.00307"
"61686","370.08000","30.84016","0.00290"
"61746","370.44000","30.87017","0.00360"
"61806","370.80000","30.90013","0.00341"
"61866","371.16000","30.93026","0.00284"
"61926","371.52000","30.96016","0.00311"
"61986","371.88000","30.99023","0.00298"
"62046","372.24000","31.02019","0.00327"
"62106","372.60000","31.05014","0.00341"
"62166","372.96000","31.08015","0.00318"
"62226","373.32000","31.11023","0.00312"
"62286","373.68000","31.14012","0.00355"
"62346","374.04000","31.17020","0.00272"
"62406","374.40000","31.20021","0.00258"
"62466","374.76000","31.23017","0.00293"
"62526","375.12000","31.26018","0.00299"
"62586","375.48000","31.29019","0.00295"
"62646","375.84000","31.32015","0.00260"
"62706","376.20000","31.35016","0.00294"
"62766","376.56000","31.38018","0.00277"
"62826","376.92000","31.41013","0.00269"
"62886","377.28000","31.44015","0.00286"
"62946","377.64000","31.47016","0.00266"
"63006","378.00000","31.50018","0.00263"
"63066","378.36000","31.53019","0.00276"
"63126","378.72000","31.56021","0.00241"
"63186","379.08000","31.59016","0.00312"
"63246","379.44000","31.62017","0.00312"
"63306","379.80000","31.65018","0.00343"
"63366","380.16000","31.68020","0.00302"
"63426","380.52000","31.71021","0.00274"
"63486","380.88000","31.74023","0.00318"
"63546","381.24000","31.77019","0.00300"
"63606","381.60000","31.80014","0.00227"
"63666","381.96000","31.83015","0.00296"
"63726","382.32000","31.86017","0.00299"
"63786","382.68000","31.89018","0.00283"
"63846","383.04000","31.92025","0.00266"
"63906","383.40000","31.95015","0.00310"
"63966","383.76000","31.98016","0.00237"
"64026","384.12000","32.01018","0.00295"
"64086","384.48000","32.04020","0.00271"
"64146","384.84000","32.07015","0.00297"
"64206","385.20000","32.10022","0.00277"
"64266","385.56000","32.13018","0.00291"
"64326","385.92000","32.16013","0.00331"
"64386","386.28000","32.19021","0.00314"
"64446","386.64000","32.22022","0.00326"
"64506","387.00000","32.25017","0.00297"
"64566","387.36000","32.28025","0.00288"
"64626","387.72000","32.31014","0.00308"
"64686","388.08000","32.34016","0.00366"
"64746","388.44000","32.37017","0.00289"
"64806","388.80000","32.40025","0.00315"
"64866","389.16000","32.43014","0.00290"
"64926","389.52000","32.46016","0.00306"
"64986","389.88000","32.49023","0.00316"
"65046","390.24000","32.52012","0.00360"
"65106","390.60000","32.55020","0.00277"
"65166","390.96000","32.58021","0.00327"
"65226","391.32000","32.61017","0.00283"
"65286","391.68000","32.64024","0.00327"
"65346","392.04000","32.67014","0.00265"
"65406","392.40000","32.70015","0.00317"
"65466","392.76000","32.73017","0.00315"
"65526","393.12000","32.76024","0.00298"
"65586","393.48000","32.79020","0.00334"
"65646","393.84000","32.82021","0.00288"
"65706","394.20000","32.85016","0.00342"
"65766","394.56000","32.88012","0.00333"
"65826","394.92000","32.91019","0.00347"
"65886","395.28000","32.94020","0.00302"
"65946","395.64000","32.97016","0.00301"
"66006","396.00000","33.00023","0.00334"
"66066","396.36000","33.03019","0.00324"
"66126","396.72000","33.06015","0.00382"
"66186","397.08000","33.09022","0.00301"
"66246","397.44000","33.12017","0.00304"
"66306","397.80000","33.15007","0.00348"
"66366","398.16000","33.18026","0.00350"
"66426","398.52000","33.21021","0.00333"
"66486","398.88000","33.24011","0.00349"
"66546","399.24000","33.27018","0.00312"
"66606","399.60000","33.30020","0.00322"
"66666","399.96000","33.33015","0.00298"
"66726","400.32000","33.36023","0.00288"
"66786","400.68000","33.39018","0.00335"
"66846","401.04000","33.42014","0.00356"
"66906","401.40000","33.45021","0.00332"
"66966","401.76000","33.48022","0.00277"
"67026","402.12000","33.51018","0.00296"
"67086","402.48000","33.54025","0.00337"
"67146","402.84000","33.57021","0.00304"
"67206","403.20000","33.60010","0.00333"
"67266","403.56000","33.63024","0.00282"
"67326","403.92000","33.66013","0.00336"
"67386","404.28000","33.69015","0.00310"
"67446","404.64000","33.72022","0.00319"
"67506","405.00000","33.75024","0.00308"
"67566","405.36000","33.78013","0.00294"
"67626","405.72000","33.81020","0.00334"
"67686","406.08000","33.84022","0.00320"
"67746","406.44000","33.87017","0.00290"
"67806","406.80000","33.90018","0.00345"
"67866","407.16000","33.93026","0.00330"
"67926","407.52000","33.96010","0.00318"
"67986","407.88000","33.99023","0.00310"
"68046","408.24000","34.02019","0.00331"
"68106","408.60000","34.05014","0.00368"
"68166","408.96000","34.08021","0.00329"
"68226","409.32000","34.11023","0.00363"
"68286","409.68000","34.14012","0.00339"
"68346","410.04000","34.17025","0.00308"
"68406","410.40000","34.20021","0.00223"
"68466","410.76000","34.23016","0.00323"
"68526","411.12000","34.26018","0.00295"
"68586","411.48000","34.29025","0.00312"
"68646","411.84000","34.32009","0.00343"
"68706","412.20000","34.35022","0.00270"
"68766","412.56000","34.38024","0.00323"
"68826","412.92000","34.41013","0.00359"
"68886","413.28000","34.44020","0.00300"
"68946","413.64000","34.47028","0.00300"
"69006","414.00000","34.50011","0.00314"
"69066","414.36000","34.53019","0.00316"
"69126","414.72000","34.56020","0.00343"
"69186","415.08000","34.59010","0.00306"
"69246","415.44000","34.62017","0.00288"
"69306","415.80000","34.65025","0.00251"
"69366","416.16000","34.68008","0.00279"
"69426","416.52000","34.71021","0.00318"
"69486","416.88000","34.74023","0.00299"
"69546","417.24000","34.77007","0.00285"
"69606","417.60000","34.80020","0.00317"
"69666","417.96000","34.83021","0.00293"
"69726","418.32000","34.86011","0.00315"
"69786","418.68000","34.89018","0.00272"
"69846","419.04000","34.92020","0.00292"
"69906","419.40000","34.95015","0.00316"
"69966","419.76000","34.98017","0.00349"
"70026","420.12000","35.01018","0.00345"
"70086","420.48000","35.04013","0.00326"
"70146","420.84000","35.07021","0.00328"
"70206","421.20000","35.10022","0.00244"
"70266","421.56000","35.13012","0.00320"
"70326","421.92000","35.16019","0.00269"
"70386","422.28000","35.19020","0.00314"
"70446","422.64000","35.22016","0.00305"
"70506","423.00000","35.25018","0.00298"
"70566","423.36000","35.28019","0.00293"
"70626","423.72000","35.31014","0.00255"
"70686","424.08000","35.34022","0.00240"
"70746","424.44000","35.37023","0.00269"
"70806","424.80000","35.40018","0.00251"
"70866","425.16000","35.43020","0.00275"
"70926","425.52000","35.46022","0.00306"
"70986","425.88000","35.49017","0.00277"
"71046","426.24000","35.52018","0.00334"
"71106","426.60000","35.55020","0.00259"
"71166","426.96000","35.58022","0.00285"
"71226","427.32000","35.61017","0.00283"
"71286","427.68000","35.64024","0.00274"
"71346","428.04000","35.67014","0.00312"
"71406","428.40000","35.70021","0.00256"
"71466","428.76000","35.73011","0.00243"
"71526","429.12000","35.76018","0.00281"
"71586","429.48000","35.79020","0.00310"
"71646","429.84000","35.82021","0.00222"
"71706","430.20000","35.85016","0.00309"
"71766","430.56000","35.88024","0.00243"
"71826","430.92000","35.91013","0.00340"
"71886","431.28000","35.94021","0.00302"
"71946","431.64000","35.97010","0.00243"
"72006","432.00000","36.00023","0.00380"
"72066","432.36000","36.03019","0.00250"
"72126","432.72000","36.06020","0.00250"
"72186","433.08000","36.09016","0.00286"
"72246","433.44000","36.12017","0.00282"
"72306","433.80000","36.15019","0.00249"
"72366","434.16000","36.18020","0.00275"
"72426","434.52000","36.21010","0.00292"
"72486","434.88000","36.24017","0.00298"
"72546","435.24000","36.27018","0.00266"
"72606","435.60000","36.30020","0.00274"
"72666","435.96000","36.33015","0.00286"
"72726","436.32000","36.36023","0.00313"
"72786","436.68000","36.39018","0.00258"
"72846","437.04000","36.42020","0.00320"
"72906","437.40000","36.45015","0.00233"
"72966","437.76000","36.48022","0.00268"
"73026","438.12000","36.51018","0.00321"
"73086","438.48000","36.54013","0.00230"
"73146","438.84000","36.57015","0.00272"
"73206","439.20000","36.60016","0.00312"
"73266","439.56000","36.63018","0.00275"
"73326","439.92000","36.66019","0.00251"
"73386","440.28000","36.69015","0.00257"
"73414","440.44800","36.70420","0.00236"