File: Trajectories_together/170212_3Specimen_RawData_1.csv
"","V1","V2","V3"
"1","End date","2/12/2017",""
"2","Specimen label","13BG_8",""
"3","Maximum Load","0.33378","N"
"4","Time","Extension","Load"
"5","(s)","(mm)","(N)"
"6","0.00000","0.00000","0.00053"
"58","0.31200","0.02565","0.00203"
"110","0.62400","0.05220","0.00239"
"162","0.93600","0.07820","0.00253"
"214","1.24800","0.10421","0.00279"
"266","1.56000","0.13016","0.00303"
"318","1.87200","0.15617","0.00351"
"370","2.18400","0.18206","0.00451"
"422","2.49600","0.20819","0.00461"
"474","2.80800","0.23414","0.00447"
"526","3.12000","0.26014","0.00488"
"578","3.43200","0.28621","0.00482"
"630","3.74400","0.31216","0.00516"
"682","4.05600","0.33817","0.00509"
"734","4.36800","0.36412","0.00575"
"786","4.68000","0.39019","0.00591"
"838","4.99200","0.41619","0.00572"
"890","5.30400","0.44214","0.00620"
"942","5.61600","0.46815","0.00570"
"994","5.92800","0.49410","0.00694"
"1046","6.24000","0.52011","0.00674"
"1098","6.55200","0.54618","0.00698"
"1150","6.86400","0.57219","0.00681"
"1202","7.17600","0.59819","0.00691"
"1254","7.48800","0.62414","0.00756"
"1306","7.80000","0.65015","0.00725"
"1358","8.11200","0.67610","0.00702"
"1410","8.42400","0.70223","0.00754"
"1462","8.73600","0.72818","0.00791"
"1514","9.04800","0.75419","0.00755"
"1566","9.36000","0.78019","0.00802"
"1618","9.67200","0.80614","0.00837"
"1670","9.98400","0.83215","0.00831"
"1722","10.29600","0.85816","0.00876"
"1774","10.60800","0.88423","0.00848"
"1826","10.92000","0.91018","0.00831"
"1878","11.23200","0.93618","0.00844"
"1930","11.54400","0.96219","0.00904"
"1982","11.85600","0.98814","0.00889"
"2034","12.16800","1.01415","0.00881"
"2086","12.48000","1.04016","0.00904"
"2138","12.79200","1.06617","0.00906"
"2190","13.10400","1.09224","0.00967"
"2242","13.41600","1.11812","0.00949"
"2294","13.72800","1.14419","0.00994"
"2346","14.04000","1.17020","0.00958"
"2398","14.35200","1.19621","0.00940"
"2450","14.66400","1.22216","0.00971"
"2502","14.97600","1.24817","0.01011"
"2554","15.28800","1.27417","0.00993"
"2606","15.60000","1.30018","0.01020"
"2658","15.91200","1.32619","0.01058"
"2710","16.22400","1.35214","0.01034"
"2762","16.53600","1.37815","0.01018"
"2814","16.84800","1.40422","0.01045"
"2866","17.16000","1.43011","0.01073"
"2918","17.47200","1.45623","0.01056"
"2970","17.78400","1.48218","0.01027"
"3022","18.09600","1.50819","0.01071"
"3074","18.40800","1.53414","0.01061"
"3126","18.72000","1.56015","0.01099"
"3178","19.03200","1.58622","0.01082"
"3230","19.34400","1.61216","0.01103"
"3282","19.65600","1.63823","0.01091"
"3334","19.96800","1.66412","0.01130"
"3386","20.28000","1.69019","0.01098"
"3438","20.59200","1.71614","0.01155"
"3490","20.90400","1.74215","0.01117"
"3542","21.21600","1.76822","0.01076"
"3594","21.52800","1.79416","0.01201"
"3646","21.84000","1.82017","0.01085"
"3698","22.15200","1.84612","0.01081"
"3750","22.46400","1.87219","0.01159"
"3802","22.77600","1.89820","0.01081"
"3854","23.08800","1.92415","0.01119"
"3906","23.40000","1.95016","0.01142"
"3958","23.71200","1.97610","0.01166"
"4010","24.02400","2.00217","0.01127"
"4062","24.33600","2.02818","0.01138"
"4114","24.64800","2.05419","0.01172"
"4166","24.96000","2.08026","0.01148"
"4218","25.27200","2.10615","0.01181"
"4270","25.58400","2.13215","0.01137"
"4322","25.89600","2.15810","0.01173"
"4374","26.20800","2.18423","0.01183"
"4426","26.52000","2.21024","0.01139"
"4478","26.83200","2.23619","0.01148"
"4530","27.14400","2.26220","0.01187"
"4582","27.45600","2.28809","0.01212"
"4634","27.76800","2.31421","0.01156"
"4686","28.08000","2.34016","0.01183"
"4738","28.39200","2.36617","0.01210"
"4790","28.70400","2.39224","0.01181"
"4842","29.01600","2.41813","0.01142"
"4894","29.32800","2.44420","0.01112"
"4946","29.64000","2.47008","0.01162"
"4998","29.95200","2.49621","0.01220"
"5050","30.26400","2.52222","0.01168"
"5102","30.57600","2.54817","0.01182"
"5154","30.88800","2.57412","0.01171"
"5206","31.20000","2.60013","0.01200"
"5258","31.51200","2.62620","0.01190"
"5310","31.82400","2.65208","0.01194"
"5362","32.13600","2.67815","0.01170"
"5414","32.44800","2.70422","0.01185"
"5466","32.76000","2.73017","0.01170"
"5518","33.07200","2.75612","0.01231"
"5570","33.38400","2.78213","0.01193"
"5622","33.69600","2.80819","0.01225"
"5674","34.00800","2.83420","0.01238"
"5726","34.32000","2.86015","0.01221"
"5778","34.63200","2.88616","0.01283"
"5830","34.94400","2.91211","0.01255"
"5882","35.25600","2.93824","0.01243"
"5934","35.56800","2.96413","0.01332"
"5986","35.88000","2.99019","0.01319"
"6038","36.19200","3.01620","0.01399"
"6090","36.50400","3.04215","0.01342"
"6142","36.81600","3.06822","0.01362"
"6194","37.12800","3.09411","0.01372"
"6246","37.44000","3.12024","0.01220"
"6298","37.75200","3.14613","0.01274"
"6350","38.06400","3.17219","0.01301"
"6402","38.37600","3.19814","0.01291"
"6454","38.68800","3.22415","0.01358"
"6506","39.00000","3.25022","0.01350"
"6558","39.31200","3.27617","0.01356"
"6610","39.62400","3.30224","0.01359"
"6662","39.93600","3.32818","0.01348"
"6714","40.24800","3.35413","0.01422"
"6766","40.56000","3.38020","0.01395"
"6818","40.87200","3.40615","0.01407"
"6870","41.18400","3.43216","0.01447"
"6922","41.49600","3.45817","0.01445"
"6974","41.80800","3.48418","0.01447"
"7026","42.12000","3.51018","0.01481"
"7078","42.43200","3.53613","0.01488"
"7130","42.74400","3.56220","0.01435"
"7182","43.05600","3.58815","0.01500"
"7234","43.36800","3.61422","0.01513"
"7286","43.68000","3.64017","0.01541"
"7338","43.99200","3.66617","0.01558"
"7390","44.30400","3.69224","0.01556"
"7442","44.61600","3.71813","0.01596"
"7494","44.92800","3.74414","0.01515"
"7546","45.24000","3.77009","0.01542"
"7598","45.55200","3.79616","0.01648"
"7650","45.86400","3.82217","0.01607"
"7702","46.17600","3.84823","0.01650"
"7754","46.48800","3.87424","0.01665"
"7806","46.80000","3.90013","0.01682"
"7858","47.11200","3.92620","0.01705"
"7910","47.42400","3.95215","0.01694"
"7962","47.73600","3.97822","0.01618"
"8014","48.04800","4.00422","0.01666"
"8066","48.36000","4.03017","0.01631"
"8118","48.67200","4.05618","0.01681"
"8170","48.98400","4.08213","0.01708"
"8222","49.29600","4.10820","0.01718"
"8274","49.60800","4.13421","0.01747"
"8326","49.92000","4.16022","0.01754"
"8378","50.23200","4.18622","0.01743"
"8430","50.54400","4.21217","0.01828"
"8482","50.85600","4.23818","0.01823"
"8534","51.16800","4.26413","0.01812"
"8586","51.48000","4.29020","0.01883"
"8638","51.79200","4.31621","0.01869"
"8690","52.10400","4.34215","0.01888"
"8742","52.41600","4.36822","0.01734"
"8794","52.72800","4.39411","0.01873"
"8846","53.04000","4.42018","0.01844"
"8898","53.35200","4.44619","0.01897"
"8950","53.66400","4.47220","0.01935"
"9002","53.97600","4.49821","0.01889"
"9054","54.28800","4.52415","0.01915"
"9106","54.60000","4.55016","0.01963"
"9158","54.91200","4.57611","0.02003"
"9210","55.22400","4.60224","0.02037"
"9262","55.53600","4.62819","0.01962"
"9314","55.84800","4.65414","0.02018"
"9366","56.16000","4.68021","0.01982"
"9418","56.47200","4.70609","0.02016"
"9470","56.78400","4.73216","0.02050"
"9522","57.09600","4.75817","0.02016"
"9574","57.40800","4.78418","0.02080"
"9626","57.72000","4.81019","0.02052"
"9678","58.03200","4.83614","0.02087"
"9730","58.34400","4.86220","0.02097"
"9782","58.65600","4.88815","0.02117"
"9834","58.96800","4.91422","0.02055"
"9886","59.28000","4.94011","0.02168"
"9938","59.59200","4.96612","0.02145"
"9990","59.90400","4.99219","0.02188"
"10042","60.21600","5.01814","0.02174"
"10094","60.52800","5.04414","0.02225"
"10146","60.84000","5.07015","0.02240"
"10198","61.15200","5.09622","0.02233"
"10250","61.46400","5.12217","0.02281"
"10302","61.77600","5.14818","0.02188"
"10354","62.08800","5.17425","0.02222"
"10406","62.40000","5.20014","0.02253"
"10458","62.71200","5.22620","0.02192"
"10510","63.02400","5.25209","0.02173"
"10562","63.33600","5.27816","0.02172"
"10614","63.64800","5.30417","0.02148"
"10666","63.96000","5.33018","0.02118"
"10718","64.27200","5.35619","0.02126"
"10770","64.58400","5.38213","0.02110"
"10822","64.89600","5.40820","0.02121"
"10874","65.20800","5.43409","0.02098"
"10926","65.52000","5.46016","0.02142"
"10978","65.83200","5.48623","0.02178"
"11030","66.14400","5.51218","0.02161"
"11082","66.45600","5.53818","0.02221"
"11134","66.76800","5.56413","0.02113"
"11186","67.08000","5.59014","0.02167"
"11238","67.39200","5.61621","0.02212"
"11290","67.70400","5.64222","0.02218"
"11342","68.01600","5.66823","0.02232"
"11394","68.32800","5.69412","0.02283"
"11446","68.64000","5.72018","0.02353"
"11498","68.95200","5.74613","0.02358"
"11550","69.26400","5.77220","0.02326"
"11602","69.57600","5.79821","0.02416"
"11654","69.88800","5.82416","0.02426"
"11706","70.20000","5.85017","0.02477"
"11758","70.51200","5.87611","0.02516"
"11810","70.82400","5.90218","0.02478"
"11862","71.13600","5.92819","0.02488"
"11914","71.44800","5.95420","0.02569"
"11966","71.76000","5.98027","0.02585"
"12018","72.07200","6.00616","0.02617"
"12070","72.38400","6.03217","0.02622"
"12122","72.69600","6.05817","0.02636"
"12174","73.00800","6.08424","0.02630"
"12226","73.32000","6.11013","0.02628"
"12278","73.63200","6.13614","0.02747"
"12330","73.94400","6.16221","0.02739"
"12382","74.25600","6.18810","0.02751"
"12434","74.56800","6.21422","0.02795"
"12486","74.88000","6.24017","0.02797"
"12538","75.19200","6.26618","0.02815"
"12590","75.50400","6.29219","0.02815"
"12642","75.81600","6.31820","0.02879"
"12694","76.12800","6.34415","0.02901"
"12746","76.44000","6.37016","0.02958"
"12798","76.75200","6.39616","0.02954"
"12850","77.06400","6.42217","0.02941"
"12902","77.37600","6.44818","0.02824"
"12954","77.68800","6.47419","0.02843"
"13006","78.00000","6.50014","0.02882"
"13058","78.31200","6.52621","0.02816"
"13110","78.62400","6.55216","0.02872"
"13162","78.93600","6.57816","0.02884"
"13214","79.24800","6.60417","0.02945"
"13266","79.56000","6.63018","0.02961"
"13318","79.87200","6.65619","0.02985"
"13370","80.18400","6.68214","0.03039"
"13422","80.49600","6.70821","0.03046"
"13474","80.80800","6.73410","0.03054"
"13526","81.12000","6.76016","0.03152"
"13578","81.43200","6.78617","0.03129"
"13630","81.74400","6.81212","0.03216"
"13682","82.05600","6.83819","0.03192"
"13734","82.36800","6.86414","0.03247"
"13786","82.68000","6.89021","0.03192"
"13838","82.99200","6.91615","0.03265"
"13890","83.30400","6.94216","0.03305"
"13942","83.61600","6.96823","0.03328"
"13994","83.92800","6.99418","0.03344"
"14046","84.24000","7.02019","0.03342"
"14098","84.55200","7.04614","0.03367"
"14150","84.86400","7.07221","0.03387"
"14202","85.17600","7.09821","0.03306"
"14254","85.48800","7.12416","0.03329"
"14306","85.80000","7.15023","0.03353"
"14358","86.11200","7.17612","0.03305"
"14410","86.42400","7.20219","0.03392"
"14462","86.73600","7.22814","0.03378"
"14514","87.04800","7.25420","0.03420"
"14566","87.36000","7.28027","0.03415"
"14618","87.67200","7.30616","0.03459"
"14670","87.98400","7.33217","0.03482"
"14722","88.29600","7.35812","0.03499"
"14774","88.60800","7.38419","0.03528"
"14826","88.92000","7.41020","0.03544"
"14878","89.23200","7.43620","0.03549"
"14930","89.54400","7.46221","0.03575"
"14982","89.85600","7.48816","0.03580"
"15034","90.16800","7.51417","0.03625"
"15086","90.48000","7.54012","0.03616"
"15138","90.79200","7.56625","0.03669"
"15190","91.10400","7.59220","0.03653"
"15242","91.41600","7.61820","0.03661"
"15294","91.72800","7.64415","0.03719"
"15346","92.04000","7.67010","0.03725"
"15398","92.35200","7.69617","0.03729"
"15450","92.66400","7.72212","0.03781"
"15502","92.97600","7.74819","0.03782"
"15554","93.28800","7.77425","0.03811"
"15606","93.60000","7.80014","0.03825"
"15658","93.91200","7.82615","0.03857"
"15710","94.22400","7.85210","0.03866"
"15762","94.53600","7.87817","0.03869"
"15814","94.84800","7.90418","0.03867"
"15866","95.16000","7.93013","0.03885"
"15918","95.47200","7.95619","0.03885"
"15970","95.78400","7.98208","0.03938"
"16022","96.09600","8.00821","0.03940"
"16074","96.40800","8.03416","0.03993"
"16126","96.72000","8.06017","0.03985"
"16178","97.03200","8.08618","0.03998"
"16230","97.34400","8.11212","0.04086"
"16282","97.65600","8.13819","0.04107"
"16334","97.96800","8.16414","0.04143"
"16386","98.28000","8.19021","0.04186"
"16438","98.59200","8.21616","0.04216"
"16490","98.90400","8.24217","0.04278"
"16542","99.21600","8.26823","0.04271"
"16594","99.52800","8.29412","0.04343"
"16646","99.84000","8.32019","0.04401"
"16698","100.15200","8.34614","0.04439"
"16750","100.46400","8.37227","0.04521"
"16802","100.77600","8.39822","0.04595"
"16854","101.08800","8.42417","0.04565"
"16906","101.40000","8.45023","0.04651"
"16958","101.71200","8.47618","0.04779"
"17010","102.02400","8.50219","0.04775"
"17062","102.33600","8.52814","0.04886"
"17114","102.64800","8.55409","0.04983"
"17166","102.96000","8.58016","0.04978"
"17218","103.27200","8.60616","0.05079"
"17270","103.58400","8.63223","0.05189"
"17322","103.89600","8.65812","0.05240"
"17374","104.20800","8.68425","0.05372"
"17426","104.52000","8.71020","0.05414"
"17478","104.83200","8.73615","0.05405"
"17530","105.14400","8.76222","0.05401"
"17582","105.45600","8.78817","0.05598"
"17634","105.76800","8.81423","0.05681"
"17686","106.08000","8.84012","0.05772"
"17738","106.39200","8.86613","0.05832"
"17790","106.70400","8.89214","0.05914"
"17842","107.01600","8.91821","0.06027"
"17894","107.32800","8.94416","0.06063"
"17946","107.64000","8.97010","0.06194"
"17998","107.95200","8.99623","0.06286"
"18050","108.26400","9.02212","0.06364"
"18102","108.57600","9.04819","0.06408"
"18154","108.88800","9.07420","0.06499"
"18206","109.20000","9.10015","0.06581"
"18258","109.51200","9.12615","0.06589"
"18310","109.82400","9.15210","0.06679"
"18362","110.13600","9.17817","0.06764"
"18414","110.44800","9.20418","0.06875"
"18466","110.76000","9.23019","0.06968"
"18518","111.07200","9.25626","0.07087"
"18570","111.38400","9.28209","0.07205"
"18622","111.69600","9.30815","0.07281"
"18674","112.00800","9.33416","0.07373"
"18726","112.32000","9.36023","0.07538"
"18778","112.63200","9.38624","0.07595"
"18830","112.94400","9.41219","0.07721"
"18882","113.25600","9.43820","0.07885"
"18934","113.56800","9.46408","0.07969"
"18986","113.88000","9.49021","0.08053"
"19038","114.19200","9.51622","0.08207"
"19090","114.50400","9.54217","0.08300"
"19142","114.81600","9.56824","0.08402"
"19194","115.12800","9.59413","0.08484"
"19246","115.44000","9.62014","0.08551"
"19298","115.75200","9.64614","0.08569"
"19350","116.06400","9.67221","0.08641"
"19402","116.37600","9.69822","0.08685"
"19454","116.68800","9.72417","0.08717"
"19506","117.00000","9.75018","0.08782"
"19558","117.31200","9.77613","0.08826"
"19610","117.62400","9.80219","0.08846"
"19662","117.93600","9.82820","0.08899"
"19714","118.24800","9.85421","0.08932"
"19766","118.56000","9.88022","0.08996"
"19818","118.87200","9.90617","0.08986"
"19870","119.18400","9.93218","0.09032"
"19922","119.49600","9.95819","0.09082"
"19974","119.80800","9.98419","0.09187"
"20026","120.12000","10.01020","0.09269"
"20078","120.43200","10.03615","0.09400"
"20130","120.74400","10.06216","0.09535"
"20182","121.05600","10.08811","0.09647"
"20234","121.36800","10.11418","0.09774"
"20286","121.68000","10.14019","0.09877"
"20338","121.99200","10.16619","0.10047"
"20390","122.30400","10.19220","0.10167"
"20442","122.61600","10.21809","0.10305"
"20494","122.92800","10.24422","0.10481"
"20546","123.24000","10.27011","0.10657"
"20598","123.55200","10.29618","0.10758"
"20650","123.86400","10.32212","0.10849"
"20702","124.17600","10.34813","0.11009"
"20754","124.48800","10.37420","0.11090"
"20806","124.80000","10.40015","0.11239"
"20858","125.11200","10.42616","0.11356"
"20910","125.42400","10.45217","0.11493"
"20962","125.73600","10.47824","0.11612"
"21014","126.04800","10.50418","0.11732"
"21066","126.36000","10.53019","0.11837"
"21118","126.67200","10.55626","0.11951"
"21170","126.98400","10.58221","0.12040"
"21222","127.29600","10.60816","0.12182"
"21274","127.60800","10.63411","0.12249"
"21326","127.92000","10.66018","0.12350"
"21378","128.23200","10.68618","0.12437"
"21430","128.54400","10.71213","0.12513"
"21482","128.85600","10.73814","0.12600"
"21534","129.16800","10.76415","0.12654"
"21586","129.48000","10.79016","0.12714"
"21638","129.79200","10.81617","0.12805"
"21690","130.10400","10.84217","0.12842"
"21742","130.41600","10.86824","0.12927"
"21794","130.72800","10.89413","0.12988"
"21846","131.04000","10.92014","0.13073"
"21898","131.35200","10.94609","0.13085"
"21950","131.66400","10.97222","0.13190"
"22002","131.97600","10.99817","0.13217"
"22054","132.28800","11.02417","0.13314"
"22106","132.60000","11.05018","0.13376"
"22158","132.91200","11.07613","0.13430"
"22210","133.22400","11.10220","0.13486"
"22262","133.53600","11.12815","0.13517"
"22314","133.84800","11.15422","0.13557"
"22366","134.16000","11.18016","0.13632"
"22418","134.47200","11.20617","0.13698"
"22470","134.78400","11.23218","0.13761"
"22522","135.09600","11.25807","0.13875"
"22574","135.40800","11.28414","0.13904"
"22626","135.72000","11.31015","0.14021"
"22678","136.03200","11.33622","0.14112"
"22730","136.34400","11.36222","0.14230"
"22782","136.65600","11.38817","0.14261"
"22834","136.96800","11.41418","0.14353"
"22886","137.28000","11.44019","0.14500"
"22938","137.59200","11.46620","0.14711"
"22990","137.90400","11.49221","0.14852"
"23042","138.21600","11.51816","0.15074"
"23094","138.52800","11.54416","0.15228"
"23146","138.84000","11.57011","0.15512"
"23198","139.15200","11.59624","0.15678"
"23250","139.46400","11.62219","0.15955"
"23302","139.77600","11.64820","0.16228"
"23354","140.08800","11.67420","0.16565"
"23406","140.40000","11.70015","0.16767"
"23458","140.71200","11.72622","0.17075"
"23510","141.02400","11.75217","0.17366"
"23562","141.33600","11.77818","0.17511"
"23614","141.64800","11.80419","0.17892"
"23666","141.96000","11.83014","0.18129"
"23718","142.27200","11.85620","0.18319"
"23770","142.58400","11.88215","0.18343"
"23822","142.89600","11.90822","0.18586"
"23874","143.20800","11.93417","0.18834"
"23926","143.52000","11.96018","0.18888"
"23978","143.83200","11.98619","0.19064"
"24030","144.14400","12.01214","0.19128"
"24082","144.45600","12.03821","0.19251"
"24134","144.76800","12.06415","0.19325"
"24186","145.08000","12.09016","0.19357"
"24238","145.39200","12.11617","0.19449"
"24290","145.70400","12.14218","0.19551"
"24342","146.01600","12.16819","0.19643"
"24394","146.32800","12.19413","0.19794"
"24446","146.64000","12.22020","0.19955"
"24498","146.95200","12.24615","0.20118"
"24550","147.26400","12.27222","0.20386"
"24602","147.57600","12.29817","0.20524"
"24654","147.88800","12.32412","0.20695"
"24706","148.20000","12.35025","0.20862"
"24758","148.51200","12.37613","0.21094"
"24810","148.82400","12.40220","0.21272"
"24862","149.13600","12.42815","0.21460"
"24914","149.44800","12.45416","0.21607"
"24966","149.76000","12.48017","0.21748"
"25018","150.07200","12.50612","0.21862"
"25070","150.38400","12.53218","0.22123"
"25122","150.69600","12.55813","0.22355"
"25174","151.00800","12.58420","0.22550"
"25226","151.32000","12.61015","0.22729"
"25278","151.63200","12.63616","0.22861"
"25330","151.94400","12.66217","0.23067"
"25382","152.25600","12.68812","0.23171"
"25434","152.56800","12.71418","0.23300"
"25486","152.88000","12.74007","0.23365"
"25538","153.19200","12.76614","0.23455"
"25590","153.50400","12.79221","0.00732"
"25642","153.81600","12.81816","0.01785"
"25694","154.12800","12.84417","0.02089"
"25746","154.44000","12.87012","0.03136"
"25798","154.75200","12.89618","0.01915"
"25850","155.06400","12.92213","0.02816"
"25902","155.37600","12.94826","0.02964"
"25954","155.68800","12.97421","0.02251"
"26006","156.00000","13.00010","0.03284"
"26058","156.31200","13.02617","0.02659"
"26110","156.62400","13.05211","0.02847"
"26162","156.93600","13.07818","0.03351"
"26214","157.24800","13.10413","0.02716"
"26266","157.56000","13.13020","0.03315"
"26318","157.87200","13.15627","0.03181"
"26370","158.18400","13.18210","0.02937"
"26422","158.49600","13.20817","0.03474"
"26474","158.80800","13.23417","0.03218"
"26526","159.12000","13.26024","0.03299"
"26578","159.43200","13.28619","0.03544"
"26630","159.74400","13.31214","0.03272"
"26682","160.05600","13.33815","0.03457"
"26734","160.36800","13.36416","0.03518"
"26786","160.68000","13.39016","0.03239"
"26838","160.99200","13.41611","0.03532"
"26890","161.30400","13.44218","0.03464"
"26942","161.61600","13.46819","0.03433"
"26994","161.92800","13.49414","0.03612"
"27046","162.24000","13.52015","0.03560"
"27098","162.55200","13.54616","0.03544"
"27150","162.86400","13.57216","0.03701"
"27202","163.17600","13.59823","0.03594"
"27254","163.48800","13.62412","0.03686"
"27306","163.80000","13.65019","0.03746"
"27358","164.11200","13.67614","0.03694"
"27410","164.42400","13.70221","0.03792"
"27462","164.73600","13.72816","0.03795"
"27514","165.04800","13.75416","0.03806"
"27566","165.36000","13.78017","0.03862"
"27618","165.67200","13.80612","0.03861"
"27670","165.98400","13.83225","0.03867"
"27722","166.29600","13.85808","0.03964"
"27774","166.60800","13.88415","0.03902"
"27826","166.92000","13.91009","0.03975"
"27878","167.23200","13.93616","0.04027"
"27930","167.54400","13.96217","0.04000"
"27982","167.85600","13.98818","0.04030"
"28034","168.16800","14.01419","0.04095"
"28086","168.48000","14.04014","0.04069"
"28138","168.79200","14.06621","0.04165"
"28190","169.10400","14.09215","0.04203"
"28242","169.41600","14.11816","0.04171"
"28294","169.72800","14.14423","0.04192"
"28346","170.04000","14.17012","0.04248"
"28398","170.35200","14.19619","0.04288"
"28450","170.66400","14.22214","0.04359"
"28502","170.97600","14.24815","0.04343"
"28554","171.28800","14.27421","0.04409"
"28606","171.60000","14.30016","0.04480"
"28658","171.91200","14.32623","0.04481"
"28710","172.22400","14.35212","0.04549"
"28762","172.53600","14.37819","0.04641"
"28814","172.84800","14.40414","0.04656"
"28866","173.16000","14.43020","0.04713"
"28918","173.47200","14.45627","0.04830"
"28970","173.78400","14.48210","0.04819"
"29022","174.09600","14.50817","0.04800"
"29074","174.40800","14.53412","0.05012"
"29126","174.72000","14.56019","0.05089"
"29178","175.03200","14.58619","0.05056"
"29230","175.34400","14.61220","0.05196"
"29282","175.65600","14.63821","0.05266"
"29334","175.96800","14.66410","0.05353"
"29386","176.28000","14.69023","0.05438"
"29438","176.59200","14.71612","0.05616"
"29490","176.90400","14.74219","0.05708"
"29542","177.21600","14.76820","0.05854"
"29594","177.52800","14.79420","0.05854"
"29646","177.84000","14.82015","0.05954"
"29698","178.15200","14.84604","0.06097"
"29750","178.46400","14.87217","0.06189"
"29802","178.77600","14.89818","0.06328"
"29854","179.08800","14.92413","0.06482"
"29906","179.40000","14.95019","0.06559"
"29958","179.71200","14.97614","0.06612"
"30010","180.02400","15.00221","0.06719"
"30062","180.33600","15.02816","0.06881"
"30114","180.64800","15.05417","0.06983"
"30166","180.96000","15.08018","0.07076"
"30218","181.27200","15.10613","0.07185"
"30270","181.58400","15.13219","0.07333"
"30322","181.89600","15.15808","0.07464"
"30374","182.20800","15.18421","0.07623"
"30426","182.52000","15.21022","0.07781"
"30478","182.83200","15.23617","0.07921"
"30530","183.14400","15.26218","0.08000"
"30582","183.45600","15.28813","0.08158"
"30634","183.76800","15.31425","0.08214"
"30686","184.08000","15.34014","0.08430"
"30738","184.39200","15.36621","0.08540"
"30790","184.70400","15.39216","0.08592"
"30842","185.01600","15.41811","0.08683"
"30894","185.32800","15.44417","0.08769"
"30946","185.64000","15.47012","0.08840"
"30998","185.95200","15.49619","0.08899"
"31050","186.26400","15.52214","0.08954"
"31102","186.57600","15.54815","0.09046"
"31154","186.88800","15.57416","0.09101"
"31206","187.20000","15.60017","0.09205"
"31258","187.51200","15.62623","0.09356"
"31310","187.82400","15.65212","0.09505"
"31362","188.13600","15.67819","0.09710"
"31414","188.44800","15.70414","0.09933"
"31466","188.76000","15.73015","0.09507"
"31518","189.07200","15.75622","0.09850"
"31570","189.38400","15.78210","0.09957"
"31622","189.69600","15.80817","0.10120"
"31674","190.00800","15.83418","0.10525"
"31726","190.32000","15.86019","0.10677"
"31778","190.63200","15.88620","0.10881"
"31830","190.94400","15.91215","0.11130"
"31882","191.25600","15.93822","0.11346"
"31934","191.56800","15.96410","0.11447"
"31986","191.88000","15.99023","0.11621"
"32038","192.19200","16.01612","0.11863"
"32090","192.50400","16.04219","0.11975"
"32142","192.81600","16.06820","0.12114"
"32194","193.12800","16.09415","0.12239"
"32246","193.44000","16.12021","0.12410"
"32298","193.75200","16.14616","0.12488"
"32350","194.06400","16.17217","0.12657"
"32402","194.37600","16.19818","0.12759"
"32454","194.68800","16.22419","0.12862"
"32506","195.00000","16.25020","0.12915"
"32558","195.31200","16.27615","0.13025"
"32610","195.62400","16.30215","0.13085"
"32662","195.93600","16.32810","0.13167"
"32714","196.24800","16.35417","0.13254"
"32766","196.56000","16.38018","0.13357"
"32818","196.87200","16.40613","0.13451"
"32870","197.18400","16.43220","0.13524"
"32922","197.49600","16.45815","0.13608"
"32974","197.80800","16.48415","0.13678"
"33026","198.12000","16.51016","0.13757"
"33078","198.43200","16.53623","0.13854"
"33130","198.74400","16.56224","0.13978"
"33182","199.05600","16.58813","0.14128"
"33234","199.36800","16.61414","0.14259"
"33286","199.68000","16.64008","0.14387"
"33338","199.99200","16.66621","0.14616"
"33390","200.30400","16.69222","0.14828"
"33442","200.61600","16.71817","0.15101"
"33494","200.92800","16.74424","0.15411"
"33546","201.24000","16.77013","0.15601"
"33598","201.55200","16.79620","0.15941"
"33650","201.86400","16.82220","0.16312"
"33702","202.17600","16.84821","0.16562"
"33754","202.48800","16.87416","0.16919"
"33806","202.80000","16.90017","0.17588"
"33858","203.11200","16.92618","0.17860"
"33910","203.42400","16.95213","0.18276"
"33962","203.73600","16.97820","0.18598"
"34014","204.04800","17.00420","0.18943"
"34066","204.36000","17.03015","0.19111"
"34118","204.67200","17.05622","0.19248"
"34170","204.98400","17.08211","0.19361"
"34222","205.29600","17.10818","0.19502"
"34274","205.60800","17.13419","0.19662"
"34326","205.92000","17.16019","0.19905"
"34378","206.23200","17.18620","0.20142"
"34430","206.54400","17.21215","0.20450"
"34482","206.85600","17.23816","0.20723"
"34534","207.16800","17.26411","0.21042"
"34586","207.48000","17.29024","0.21357"
"34638","207.79200","17.31613","0.21658"
"34690","208.10400","17.34213","0.21952"
"34742","208.41600","17.36820","0.22271"
"34794","208.72800","17.39415","0.22455"
"34846","209.04000","17.42016","0.22760"
"34898","209.35200","17.44611","0.22992"
"34950","209.66400","17.47218","0.23206"
"35002","209.97600","17.49818","0.23411"
"35054","210.28800","17.52419","0.23561"
"35106","210.60000","17.55020","0.23676"
"35158","210.91200","17.57621","0.23811"
"35210","211.22400","17.60222","0.23917"
"35262","211.53600","17.62811","0.23976"
"35314","211.84800","17.65417","0.24087"
"35366","212.16000","17.68018","0.24201"
"35418","212.47200","17.70619","0.24233"
"35470","212.78400","17.73220","0.24360"
"35522","213.09600","17.75815","0.24517"
"35574","213.40800","17.78416","0.24689"
"35626","213.72000","17.81017","0.24758"
"35678","214.03200","17.83611","0.24868"
"35730","214.34400","17.86218","0.25057"
"35782","214.65600","17.88813","0.25245"
"35834","214.96800","17.91414","0.25581"
"35886","215.28000","17.94009","0.25866"
"35938","215.59200","17.96616","0.26151"
"35990","215.90400","17.99216","0.26445"
"36042","216.21600","18.01817","0.26717"
"36094","216.52800","18.04424","0.26988"
"36146","216.84000","18.07013","0.27296"
"36198","217.15200","18.09614","0.27581"
"36250","217.46400","18.12209","0.27878"
"36302","217.77600","18.14822","0.28123"
"36354","218.08800","18.17416","0.28320"
"36406","218.40000","18.20017","0.28502"
"36458","218.71200","18.22618","0.28633"
"36510","219.02400","18.25213","0.28824"
"36562","219.33600","18.27820","0.28970"
"36614","219.64800","18.30421","0.29161"
"36666","219.96000","18.33022","0.29369"
"36718","220.27200","18.35616","0.29588"
"36770","220.58400","18.38211","0.30074"
"36822","220.89600","18.40818","0.30551"
"36874","221.20800","18.43407","0.31063"
"36926","221.52000","18.46014","0.31620"
"36978","221.83200","18.48615","0.32118"
"37030","222.14400","18.51215","0.32626"
"37082","222.45600","18.53822","0.32978"
"37134","222.76800","18.56417","0.33341"
"37186","223.08000","18.59018","0.17153"
"37238","223.39200","18.61619","0.17730"
"37290","223.70400","18.64214","0.17801"
"37342","224.01600","18.66821","0.18043"
"37394","224.32800","18.69410","0.18699"
"37446","224.64000","18.72016","0.19084"
"37498","224.95200","18.74611","0.19258"
"37550","225.26400","18.77218","0.19364"
"37602","225.57600","18.79813","0.19618"
"37654","225.88800","18.82420","0.19864"
"37706","226.20000","18.85021","0.20081"
"37758","226.51200","18.87615","0.20343"
"37810","226.82400","18.90222","0.20668"
"37862","227.13600","18.92817","0.21157"
"37914","227.44800","18.95418","0.21461"
"37966","227.76000","18.98013","0.21598"
"38018","228.07200","19.00614","0.21854"
"38070","228.38400","19.03220","0.22105"
"38122","228.69600","19.05815","0.22445"
"38174","229.00800","19.08416","0.22701"
"38226","229.32000","19.11017","0.22941"
"38278","229.63200","19.13624","0.23166"
"38330","229.94400","19.16219","0.23387"
"38382","230.25600","19.18820","0.23518"
"38434","230.56800","19.21420","0.23597"
"38486","230.88000","19.24015","0.23743"
"38538","231.19200","19.26616","0.23869"
"38590","231.50400","19.29217","0.23972"
"38642","231.81600","19.31812","0.24102"
"38694","232.12800","19.34419","0.24178"
"38746","232.44000","19.37020","0.24317"
"38798","232.75200","19.39620","0.24460"
"38850","233.06400","19.42215","0.24646"
"38902","233.37600","19.44822","0.24836"
"38954","233.68800","19.47423","0.25110"
"39006","234.00000","19.50018","0.00019"
"39058","234.31200","19.52625","0.01290"
"39110","234.62400","19.55213","0.01384"
"39162","234.93600","19.57820","0.01950"
"39214","235.24800","19.60415","0.00949"
"39266","235.56000","19.63016","0.00911"
"39318","235.87200","19.65617","0.01511"
"39370","236.18400","19.68212","0.01506"
"39422","236.49600","19.70819","0.01895"
"39474","236.80800","19.73413","0.01200"
"39526","237.12000","19.76020","0.01125"
"39578","237.43200","19.78615","0.01417"
"39630","237.74400","19.81216","0.01493"
"39682","238.05600","19.83817","0.01731"
"39734","238.36800","19.86412","0.01443"
"39786","238.68000","19.89018","0.01491"
"39838","238.99200","19.91613","0.01348"
"39890","239.30400","19.94220","0.01392"
"39942","239.61600","19.96821","0.01660"
"39994","239.92800","19.99416","0.01578"
"40046","240.24000","20.02017","0.01661"
"40098","240.55200","20.04612","0.01490"
"40150","240.86400","20.07218","0.01563"
"40202","241.17600","20.09819","0.01517"
"40254","241.48800","20.12420","0.01668"
"40306","241.80000","20.15021","0.01680"
"40358","242.11200","20.17616","0.01719"
"40410","242.42400","20.20217","0.01730"
"40462","242.73600","20.22811","0.01674"
"40514","243.04800","20.25418","0.01740"
"40566","243.36000","20.28019","0.01713"
"40618","243.67200","20.30614","0.01747"
"40670","243.98400","20.33221","0.01807"
"40722","244.29600","20.35810","0.01816"
"40774","244.60800","20.38416","0.01839"
"40826","244.92000","20.41018","0.01803"
"40878","245.23200","20.43618","0.01847"
"40930","245.54400","20.46219","0.01843"
"40982","245.85600","20.48814","0.01804"
"41034","246.16800","20.51421","0.01853"
"41086","246.48000","20.54015","0.01879"
"41138","246.79200","20.56617","0.01884"
"41190","247.10400","20.59217","0.01915"
"41242","247.41600","20.61818","0.01859"
"41294","247.72800","20.64419","0.01949"
"41346","248.04000","20.67014","0.02014"
"41398","248.35200","20.69621","0.02026"
"41450","248.66400","20.72215","0.02007"
"41502","248.97600","20.74817","0.02060"
"41554","249.28800","20.77417","0.02019"
"41606","249.60000","20.80012","0.02051"
"41658","249.91200","20.82619","0.01993"
"41710","250.22400","20.85208","0.02044"
"41762","250.53600","20.87820","0.02026"
"41814","250.84800","20.90415","0.02156"
"41866","251.16000","20.93016","0.02078"
"41918","251.47200","20.95617","0.02180"
"41970","251.78400","20.98212","0.02138"
"42022","252.09600","21.00825","0.02164"
"42074","252.40800","21.03408","0.02165"
"42126","252.72000","21.06020","0.02218"
"42178","253.03200","21.08610","0.02227"
"42230","253.34400","21.11216","0.02200"
"42282","253.65600","21.13817","0.02167"
"42334","253.96800","21.16412","0.02317"
"42386","254.28000","21.19019","0.02310"
"42438","254.59200","21.21614","0.02303"
"42490","254.90400","21.24215","0.02277"
"42542","255.21600","21.26821","0.02319"
"42594","255.52800","21.29416","0.02334"
"42646","255.84000","21.32023","0.02358"
"42698","256.15200","21.34618","0.02347"
"42750","256.46400","21.37219","0.02371"
"42802","256.77600","21.39813","0.02388"
"42854","257.08800","21.42420","0.02366"
"42906","257.40000","21.45021","0.02447"
"42958","257.71200","21.47610","0.02383"
"43010","258.02400","21.50217","0.02480"
"43062","258.33600","21.52818","0.02393"
"43114","258.64800","21.55413","0.02466"
"43166","258.96000","21.58019","0.02457"
"43218","259.27200","21.60620","0.02530"
"43270","259.58400","21.63221","0.02518"
"43322","259.89600","21.65810","0.02554"
"43374","260.20800","21.68417","0.02531"
"43426","260.52000","21.71012","0.02592"
"43478","260.83200","21.73625","0.02557"
"43530","261.14400","21.76225","0.02593"
"43582","261.45600","21.78814","0.02622"
"43634","261.76800","21.81421","0.02581"
"43686","262.08000","21.84010","0.02579"
"43738","262.39200","21.86617","0.02666"
"43790","262.70400","21.89218","0.02676"
"43842","263.01600","21.91818","0.02657"
"43894","263.32800","21.94419","0.02638"
"43946","263.64000","21.97020","0.02634"
"43998","263.95200","21.99615","0.02684"
"44050","264.26400","22.02210","0.02568"
"44102","264.57600","22.04823","0.02621"
"44154","264.88800","22.07417","0.02630"
"44206","265.20000","22.10018","0.02622"
"44258","265.51200","22.12625","0.02616"
"44310","265.82400","22.15214","0.02701"
"44362","266.13600","22.17821","0.02726"
"44414","266.44800","22.20416","0.02742"
"44466","266.76000","22.23017","0.02696"
"44518","267.07200","22.25617","0.02696"
"44570","267.38400","22.28213","0.02668"
"44622","267.69600","22.30819","0.02685"
"44674","268.00800","22.33414","0.02769"
"44726","268.32000","22.36021","0.02797"
"44778","268.63200","22.38616","0.02780"
"44830","268.94400","22.41211","0.02796"
"44882","269.25600","22.43824","0.02791"
"44934","269.56800","22.46412","0.02790"
"44986","269.88000","22.49025","0.02852"
"45038","270.19200","22.51620","0.02840"
"45090","270.50400","22.54221","0.02885"
"45142","270.81600","22.56816","0.02883"
"45194","271.12800","22.59411","0.02874"
"45246","271.44000","22.62024","0.02928"
"45298","271.75200","22.64612","0.02906"
"45350","272.06400","22.67219","0.02856"
"45402","272.37600","22.69808","0.02834"
"45454","272.68800","22.72415","0.02856"
"45506","273.00000","22.75016","0.02842"
"45558","273.31200","22.77617","0.02884"
"45610","273.62400","22.80217","0.02910"
"45662","273.93600","22.82818","0.02935"
"45714","274.24800","22.85419","0.02943"
"45766","274.56000","22.88020","0.02924"
"45818","274.87200","22.90615","0.02957"
"45870","275.18400","22.93222","0.02937"
"45922","275.49600","22.95816","0.02960"
"45974","275.80800","22.98417","0.03015"
"46026","276.12000","23.01018","0.03023"
"46078","276.43200","23.03619","0.03008"
"46130","276.74400","23.06220","0.03091"
"46182","277.05600","23.08815","0.03044"
"46234","277.36800","23.11422","0.03068"
"46286","277.68000","23.14010","0.03071"
"46338","277.99200","23.16623","0.03119"
"46390","278.30400","23.19212","0.03122"
"46442","278.61600","23.21819","0.03184"
"46494","278.92800","23.24414","0.03165"
"46546","279.24000","23.27015","0.03186"
"46598","279.55200","23.29616","0.03221"
"46650","279.86400","23.32210","0.03196"
"46702","280.17600","23.34817","0.03211"
"46754","280.48800","23.37418","0.03237"
"46806","280.80000","23.40019","0.03227"
"46858","281.11200","23.42620","0.03250"
"46910","281.42400","23.45208","0.03253"
"46962","281.73600","23.47815","0.03245"
"47014","282.04800","23.50410","0.03303"
"47066","282.36000","23.53017","0.03287"
"47118","282.67200","23.55618","0.03323"
"47170","282.98400","23.58219","0.03299"
"47222","283.29600","23.60820","0.03291"
"47274","283.60800","23.63408","0.03334"
"47326","283.92000","23.66015","0.03364"
"47378","284.23200","23.68616","0.03338"
"47430","284.54400","23.71223","0.03346"
"47482","284.85600","23.73824","0.03375"
"47534","285.16800","23.76413","0.03391"
"47586","285.48000","23.79013","0.03399"
"47638","285.79200","23.81614","0.03388"
"47690","286.10400","23.84215","0.03429"
"47742","286.41600","23.86816","0.03424"
"47794","286.72800","23.89417","0.03427"
"47846","287.04000","23.92018","0.03431"
"47898","287.35200","23.94613","0.03459"
"47950","287.66400","23.97220","0.03503"
"48002","287.97600","23.99821","0.03485"
"48054","288.28800","24.02421","0.03499"
"48106","288.60000","24.05022","0.03519"
"48158","288.91200","24.07611","0.03552"
"48210","289.22400","24.10218","0.03524"
"48262","289.53600","24.12819","0.03488"
"48314","289.84800","24.15420","0.03518"
"48366","290.16000","24.18014","0.03526"
"48418","290.47200","24.20615","0.03503"
"48470","290.78400","24.23216","0.03583"
"48522","291.09600","24.25817","0.03605"
"48574","291.40800","24.28424","0.03602"
"48626","291.72000","24.31013","0.03633"
"48678","292.03200","24.33613","0.03639"
"48730","292.34400","24.36220","0.03643"
"48782","292.65600","24.38809","0.03678"
"48834","292.96800","24.41422","0.03694"
"48886","293.28000","24.44011","0.03717"
"48938","293.59200","24.46618","0.03716"
"48990","293.90400","24.49218","0.03719"
"49042","294.21600","24.51819","0.03742"
"49094","294.52800","24.54420","0.03726"
"49146","294.84000","24.57015","0.03787"
"49198","295.15200","24.59622","0.03782"
"49250","295.46400","24.62211","0.03789"
"49302","295.77600","24.64818","0.03776"
"49354","296.08800","24.67413","0.03690"
"49406","296.40000","24.70013","0.03720"
"49458","296.71200","24.72620","0.03726"
"49510","297.02400","24.75215","0.03759"
"49562","297.33600","24.77816","0.03767"
"49614","297.64800","24.80416","0.03762"
"49666","297.96000","24.83018","0.03802"
"49718","298.27200","24.85618","0.03818"
"49770","298.58400","24.88219","0.03813"
"49822","298.89600","24.90820","0.03841"
"49874","299.20800","24.93415","0.03874"
"49926","299.52000","24.96022","0.03810"
"49978","299.83200","24.98616","0.03821"
"50030","300.14400","25.01217","0.03845"
"50082","300.45600","25.03824","0.03847"
"50134","300.76800","25.06413","0.03883"
"50186","301.08000","25.09014","0.03936"
"50238","301.39200","25.11615","0.03921"
"50290","301.70400","25.14215","0.03958"
"50342","302.01600","25.16816","0.03967"
"50394","302.32800","25.19417","0.04021"
"50446","302.64000","25.22024","0.04024"
"50498","302.95200","25.24613","0.04036"
"50550","303.26400","25.27220","0.04071"
"50602","303.57600","25.29815","0.04093"
"50654","303.88800","25.32427","0.04080"
"50706","304.20000","25.35022","0.04102"
"50758","304.51200","25.37617","0.04159"
"50810","304.82400","25.40218","0.04166"
"50862","305.13600","25.42807","0.04221"
"50914","305.44800","25.45420","0.04227"
"50966","305.76000","25.48021","0.04257"
"51018","306.07200","25.50615","0.04253"
"51070","306.38400","25.53216","0.04290"
"51122","306.69600","25.55817","0.04304"
"51174","307.00800","25.58418","0.04349"
"51226","307.32000","25.61013","0.04390"
"51278","307.63200","25.63620","0.04446"
"51330","307.94400","25.66215","0.04432"
"51382","308.25600","25.68815","0.04432"
"51434","308.56800","25.71416","0.04401"
"51486","308.88000","25.74017","0.04463"
"51538","309.19200","25.76618","0.04433"
"51590","309.50400","25.79213","0.04520"
"51642","309.81600","25.81808","0.04582"
"51694","310.12800","25.84414","0.04566"
"51746","310.44000","25.87009","0.04682"
"51798","310.75200","25.89616","0.04696"
"51850","311.06400","25.92211","0.04774"
"51902","311.37600","25.94818","0.04811"
"51954","311.68800","25.97419","0.04853"
"52006","312.00000","26.00014","0.04907"
"52058","312.31200","26.02621","0.04927"
"52110","312.62400","26.05215","0.04955"
"52162","312.93600","26.07822","0.04995"
"52214","313.24800","26.10417","0.05073"
"52266","313.56000","26.13018","0.05103"
"52318","313.87200","26.15613","0.05169"
"52370","314.18400","26.18214","0.05231"
"52422","314.49600","26.20814","0.05281"
"52474","314.80800","26.23409","0.05354"
"52526","315.12000","26.26022","0.05361"
"52578","315.43200","26.28617","0.05423"
"52630","315.74400","26.31212","0.05478"
"52682","316.05600","26.33819","0.05508"
"52734","316.36800","26.36420","0.05554"
"52786","316.68000","26.39020","0.05551"
"52838","316.99200","26.41615","0.05591"
"52890","317.30400","26.44222","0.05611"
"52942","317.61600","26.46811","0.05442"
"52994","317.92800","26.49412","0.05481"
"53046","318.24000","26.52019","0.05552"
"53098","318.55200","26.54613","0.05266"
"53150","318.86400","26.57220","0.05265"
"53202","319.17600","26.59815","0.05320"
"53254","319.48800","26.62416","0.05513"
"53306","319.80000","26.65023","0.05570"
"53358","320.11200","26.67612","0.05650"
"53410","320.42400","26.70218","0.05715"
"53462","320.73600","26.72807","0.05720"
"53514","321.04800","26.75420","0.05786"
"53566","321.36000","26.78015","0.05888"
"53618","321.67200","26.80622","0.06017"
"53670","321.98400","26.83217","0.06054"
"53722","322.29600","26.85812","0.06010"
"53774","322.60800","26.88424","0.06047"
"53826","322.92000","26.91019","0.06199"
"53878","323.23200","26.93620","0.06265"
"53930","323.54400","26.96215","0.06358"
"53982","323.85600","26.98816","0.06228"
"54034","324.16800","27.01417","0.06356"
"54086","324.48000","27.04006","0.06526"
"54138","324.79200","27.06618","0.06606"
"54190","325.10400","27.09213","0.06713"
"54242","325.41600","27.11820","0.06830"
"54294","325.72800","27.14421","0.06952"
"54346","326.04000","27.17016","0.07107"
"54398","326.35200","27.19622","0.07198"
"54450","326.66400","27.22211","0.07278"
"54502","326.97600","27.24818","0.07391"
"54554","327.28800","27.27419","0.07489"
"54606","327.60000","27.30020","0.07481"
"54658","327.91200","27.32621","0.07505"
"54710","328.22400","27.35210","0.07495"
"54762","328.53600","27.37816","0.07512"
"54814","328.84800","27.40417","0.07353"
"54866","329.16000","27.43024","0.07443"
"54918","329.47200","27.45619","0.07600"
"54970","329.78400","27.48214","0.07662"
"55022","330.09600","27.50821","0.07819"
"55074","330.40800","27.53410","0.07951"
"55126","330.72000","27.56023","0.08015"
"55178","331.03200","27.58618","0.08162"
"55230","331.34400","27.61218","0.08250"
"55282","331.65600","27.63819","0.08310"
"55334","331.96800","27.66414","0.08431"
"55386","332.28000","27.69021","0.08493"
"55438","332.59200","27.71616","0.08594"
"55490","332.90400","27.74223","0.08657"
"55542","333.21600","27.76818","0.08702"
"55594","333.52800","27.79418","0.08781"
"55646","333.84000","27.82019","0.08841"
"55698","334.15200","27.84614","0.08889"
"55750","334.46400","27.87221","0.08968"
"55802","334.77600","27.89816","0.08966"
"55854","335.08800","27.92410","0.09004"
"55906","335.40000","27.95017","0.09098"
"55958","335.71200","27.97612","0.09041"
"56010","336.02400","28.00219","0.09108"
"56062","336.33600","28.02814","0.09125"
"56114","336.64800","28.05415","0.09245"
"56166","336.96000","28.08016","0.09411"
"56218","337.27200","28.10610","0.09615"
"56270","337.58400","28.13223","0.09666"
"56322","337.89600","28.15818","0.09870"
"56374","338.20800","28.18413","0.09962"
"56426","338.52000","28.21008","0.10121"
"56478","338.83200","28.23615","0.10263"
"56530","339.14400","28.26216","0.10507"
"56582","339.45600","28.28810","0.10605"
"56634","339.76800","28.31417","0.10793"
"56686","340.08000","28.34018","0.10907"
"56738","340.39200","28.36619","0.10944"
"56790","340.70400","28.39208","0.10723"
"56842","341.01600","28.41814","0.10887"
"56894","341.32800","28.44415","0.11087"
"56946","341.64000","28.47016","0.11239"
"56998","341.95200","28.49617","0.11358"
"57050","342.26400","28.52218","0.11437"
"57102","342.57600","28.54813","0.11311"
"57154","342.88800","28.57413","0.11553"
"57206","343.20000","28.60014","0.11495"
"57258","343.51200","28.62621","0.11649"
"57310","343.82400","28.65216","0.11850"
"57362","344.13600","28.67817","0.11955"
"57414","344.44800","28.70412","0.12091"
"57466","344.76000","28.73019","0.12237"
"57518","345.07200","28.75620","0.12292"
"57570","345.38400","28.78214","0.12365"
"57622","345.69600","28.80821","0.12479"
"57674","346.00800","28.83410","0.12496"
"57726","346.32000","28.86017","0.12595"
"57778","346.63200","28.88618","0.12681"
"57830","346.94400","28.91219","0.12766"
"57882","347.25600","28.93819","0.12864"
"57934","347.56800","28.96414","0.13007"
"57986","347.88000","28.99015","0.13108"
"58038","348.19200","29.01610","0.13178"
"58090","348.50400","29.04223","0.13287"
"58142","348.81600","29.06818","0.13349"
"58194","349.12800","29.09418","0.13518"
"58246","349.44000","29.12019","0.13559"
"58298","349.75200","29.14614","0.13665"
"58350","350.06400","29.17215","0.13561"
"58402","350.37600","29.19816","0.13469"
"58454","350.68800","29.22417","0.13582"
"58506","351.00000","29.25018","0.13608"
"58558","351.31200","29.27618","0.13643"
"58610","351.62400","29.30219","0.11193"
"58662","351.93600","29.32814","0.10156"
"58714","352.24800","29.35421","0.10528"
"58766","352.56000","29.38016","0.10166"
"58818","352.87200","29.40611","0.10173"
"58870","353.18400","29.43218","0.10673"
"58922","353.49600","29.45812","0.10722"
"58974","353.80800","29.48419","0.10841"
"59026","354.12000","29.51014","0.11278"
"59078","354.43200","29.53615","0.11465"
"59130","354.74400","29.56216","0.11615"
"59182","355.05600","29.58817","0.11881"
"59234","355.36800","29.61418","0.11977"
"59286","355.68000","29.64012","0.11999"
"59338","355.99200","29.66619","0.12071"
"59390","356.30400","29.69214","0.11996"
"59442","356.61600","29.71815","0.12031"
"59494","356.92800","29.74416","0.12161"
"59546","357.24000","29.77011","0.12276"
"59598","357.55200","29.79623","0.12379"
"59650","357.86400","29.82212","0.12520"
"59702","358.17600","29.84819","0.12585"
"59754","358.48800","29.87414","0.12707"
"59806","358.80000","29.90021","0.12850"
"59858","359.11200","29.92622","0.12917"
"59910","359.42400","29.95223","0.13032"
"59962","359.73600","29.97817","0.13111"
"60014","360.04800","30.00412","0.13153"
"60066","360.36000","30.03019","0.13244"
"60118","360.67200","30.05614","0.13361"
"60170","360.98400","30.08215","0.13462"
"60222","361.29600","30.10822","0.13574"
"60274","361.60800","30.13416","0.13614"
"60326","361.92000","30.16017","0.13711"
"60378","362.23200","30.18618","0.13790"
"60430","362.54400","30.21219","0.13898"
"60482","362.85600","30.23820","0.14008"
"60534","363.16800","30.26415","0.14152"
"60586","363.48000","30.29016","0.14367"
"60638","363.79200","30.31610","0.14483"
"60690","364.10400","30.34223","0.14736"
"60742","364.41600","30.36818","0.14892"
"60794","364.72800","30.39419","0.15059"
"60846","365.04000","30.42020","0.15335"
"60898","365.35200","30.44615","0.06877"
"60950","365.66400","30.47216","0.06659"
"61002","365.97600","30.49816","0.05733"
"61054","366.28800","30.52423","0.05137"
"61106","366.60000","30.55012","0.05519"
"61158","366.91200","30.57613","0.06194"
"61210","367.22400","30.60214","0.06161"
"61262","367.53600","30.62809","0.06337"
"61314","367.84800","30.65421","0.06620"
"61366","368.16000","30.68016","0.06589"
"61418","368.47200","30.70623","0.06548"
"61470","368.78400","30.73218","0.06576"
"61522","369.09600","30.75813","0.06779"
"61574","369.40800","30.78414","0.06880"
"61626","369.72000","30.81009","0.06943"
"61678","370.03200","30.83621","0.07208"
"61730","370.34400","30.86216","0.07354"
"61782","370.65600","30.88817","0.07291"
"61834","370.96800","30.91418","0.01219"
"61886","371.28000","30.94013","0.01317"
"61938","371.59200","30.96620","0.00959"
"61990","371.90400","30.99214","0.00879"
"62042","372.21600","31.01821","0.01475"
"62094","372.52800","31.04416","0.00646"
"62146","372.84000","31.07011","0.01173"
"62198","373.15200","31.09618","0.00634"
"62250","373.46400","31.12213","0.01094"
"62302","373.77600","31.14820","0.00732"
"62354","374.08800","31.17414","0.00815"
"62406","374.40000","31.20015","0.00968"
"62458","374.71200","31.22616","0.00885"
"62510","375.02400","31.25217","0.00867"
"62562","375.33600","31.27817","0.00816"
"62614","375.64800","31.30412","0.01029"
"62666","375.96000","31.33019","0.00737"
"62718","376.27200","31.35614","0.00982"
"62770","376.58400","31.38215","0.00694"
"62822","376.89600","31.40816","0.01032"
"62874","377.20800","31.43417","0.00721"
"62926","377.52000","31.46024","0.00925"
"62978","377.83200","31.48612","0.00824"
"63030","378.14400","31.51213","0.00952"
"63082","378.45600","31.53814","0.00733"
"63134","378.76800","31.56415","0.00960"
"63186","379.08000","31.59016","0.00909"
"63238","379.39200","31.61611","0.00918"
"63290","379.70400","31.64218","0.00824"
"63342","380.01600","31.66812","0.00868"
"63394","380.32800","31.69413","0.00899"
"63446","380.64000","31.72020","0.00901"
"63498","380.95200","31.74615","0.00885"
"63550","381.26000","31.77186","0.00959"