File: Trajectories_together/170212_2Specimen_RawData_2.csv
"","V1","V2","V3"
"1","End date","2/12/2017",""
"2","Specimen label","9CG_75",""
"3","Maximum Load","0.27909","N"
"4","Time","Extension","Load"
"5","(s)","(mm)","(N)"
"6","0.00000","0.00000","0.00201"
"42","0.21600","0.01590","0.00396"
"78","0.43200","0.03623","0.00652"
"114","0.64800","0.05423","0.00727"
"150","0.86400","0.07217","0.00814"
"186","1.08000","0.09016","0.01046"
"222","1.29600","0.10816","0.01191"
"258","1.51200","0.12616","0.01260"
"294","1.72800","0.14415","0.01401"
"330","1.94400","0.16215","0.01570"
"366","2.16000","0.18009","0.01623"
"402","2.37600","0.19820","0.01837"
"438","2.59200","0.21614","0.02013"
"474","2.80800","0.23420","0.02130"
"510","3.02400","0.25219","0.02254"
"546","3.24000","0.27013","0.02333"
"582","3.45600","0.28819","0.02558"
"618","3.67200","0.30612","0.02675"
"654","3.88800","0.32418","0.02830"
"690","4.10400","0.34218","0.02779"
"726","4.32000","0.36011","0.02803"
"762","4.53600","0.37817","0.02983"
"798","4.75200","0.39611","0.03092"
"834","4.96800","0.41422","0.03207"
"870","5.18400","0.43222","0.03326"
"906","5.40000","0.45010","0.03350"
"942","5.61600","0.46821","0.03452"
"978","5.83200","0.48621","0.03559"
"1014","6.04800","0.50415","0.03586"
"1050","6.26400","0.52220","0.03663"
"1086","6.48000","0.54014","0.03718"
"1122","6.69600","0.55820","0.03813"
"1158","6.91200","0.57619","0.03835"
"1194","7.12800","0.59419","0.03834"
"1230","7.34400","0.61219","0.03941"
"1266","7.56000","0.63012","0.03993"
"1302","7.77600","0.64818","0.04078"
"1338","7.99200","0.66612","0.04055"
"1374","8.20800","0.68417","0.04148"
"1410","8.42400","0.70217","0.04116"
"1446","8.64000","0.72011","0.04257"
"1482","8.85600","0.73816","0.04248"
"1518","9.07200","0.75616","0.04321"
"1554","9.28800","0.77415","0.04304"
"1590","9.50400","0.79221","0.04176"
"1626","9.72000","0.81015","0.04211"
"1662","9.93600","0.82820","0.04232"
"1698","10.15200","0.84614","0.04316"
"1734","10.36800","0.86420","0.04357"
"1770","10.58400","0.88219","0.04348"
"1806","10.80000","0.90013","0.04401"
"1842","11.01600","0.91819","0.04392"
"1878","11.23200","0.93612","0.04385"
"1914","11.44800","0.95412","0.04402"
"1950","11.66400","0.97218","0.04444"
"1986","11.88000","0.99005","0.04557"
"2022","12.09600","1.00823","0.04526"
"2058","12.31200","1.02617","0.04613"
"2094","12.52800","1.04422","0.04577"
"2130","12.74400","1.06216","0.04609"
"2166","12.96000","1.08016","0.04595"
"2202","13.17600","1.09815","0.04651"
"2238","13.39200","1.11615","0.04614"
"2274","13.60800","1.13421","0.04688"
"2310","13.82400","1.15220","0.04639"
"2346","14.04000","1.17008","0.04697"
"2382","14.25600","1.18820","0.04684"
"2418","14.47200","1.20619","0.04745"
"2454","14.68800","1.22419","0.04714"
"2490","14.90400","1.24219","0.04757"
"2526","15.12000","1.26018","0.04771"
"2562","15.33600","1.27818","0.04767"
"2598","15.55200","1.29618","0.04832"
"2634","15.76800","1.31417","0.04807"
"2670","15.98400","1.33217","0.04847"
"2706","16.20000","1.35017","0.04871"
"2742","16.41600","1.36816","0.04882"
"2778","16.63200","1.38616","0.04861"
"2814","16.84800","1.40422","0.04896"
"2850","17.06400","1.42215","0.04909"
"2886","17.28000","1.44015","0.04931"
"2922","17.49600","1.45815","0.04921"
"2958","17.71200","1.47614","0.04884"
"2994","17.92800","1.49414","0.04916"
"3030","18.14400","1.51220","0.04850"
"3066","18.36000","1.53013","0.04855"
"3102","18.57600","1.54819","0.04884"
"3138","18.79200","1.56619","0.04900"
"3174","19.00800","1.58418","0.04861"
"3210","19.22400","1.60212","0.04840"
"3246","19.44000","1.62018","0.04891"
"3282","19.65600","1.63817","0.04809"
"3318","19.87200","1.65611","0.04763"
"3354","20.08800","1.67417","0.04829"
"3390","20.30400","1.69216","0.04823"
"3426","20.52000","1.71016","0.04761"
"3462","20.73600","1.72816","0.04818"
"3498","20.95200","1.74609","0.04865"
"3534","21.16800","1.76421","0.04856"
"3570","21.38400","1.78215","0.04892"
"3606","21.60000","1.80020","0.04878"
"3642","21.81600","1.81820","0.04880"
"3678","22.03200","1.83614","0.04872"
"3714","22.24800","1.85419","0.04836"
"3750","22.46400","1.87213","0.04806"
"3786","22.68000","1.89013","0.04860"
"3822","22.89600","1.90818","0.04881"
"3858","23.11200","1.92612","0.04874"
"3894","23.32800","1.94418","0.04890"
"3930","23.54400","1.96211","0.04958"
"3966","23.76000","1.98017","0.04992"
"4002","23.97600","1.99817","0.04884"
"4038","24.19200","2.01610","0.04976"
"4074","24.40800","2.03422","0.05017"
"4110","24.62400","2.05216","0.04985"
"4146","24.84000","2.07015","0.04998"
"4182","25.05600","2.08815","0.04996"
"4218","25.27200","2.10615","0.04988"
"4254","25.48800","2.12414","0.04852"
"4290","25.70400","2.14214","0.04927"
"4326","25.92000","2.16020","0.04903"
"4362","26.13600","2.17819","0.04969"
"4398","26.35200","2.19613","0.04970"
"4434","26.56800","2.21419","0.05001"
"4470","26.78400","2.23218","0.04975"
"4506","27.00000","2.25012","0.05008"
"4542","27.21600","2.26818","0.05104"
"4578","27.43200","2.28611","0.05031"
"4614","27.64800","2.30417","0.05065"
"4650","27.86400","2.32217","0.05034"
"4686","28.08000","2.34016","0.05064"
"4722","28.29600","2.35816","0.05072"
"4758","28.51200","2.37616","0.05014"
"4794","28.72800","2.39421","0.05065"
"4830","28.94400","2.41215","0.04969"
"4866","29.16000","2.43021","0.05121"
"4902","29.37600","2.44820","0.05041"
"4938","29.59200","2.46614","0.05084"
"4974","29.80800","2.48414","0.05114"
"5010","30.02400","2.50213","0.05090"
"5046","30.24000","2.52013","0.05143"
"5082","30.45600","2.53819","0.05143"
"5118","30.67200","2.55612","0.05153"
"5154","30.88800","2.57424","0.05213"
"5190","31.10400","2.59218","0.05203"
"5226","31.32000","2.61017","0.05273"
"5262","31.53600","2.62817","0.05182"
"5298","31.75200","2.64611","0.05186"
"5334","31.96800","2.66416","0.05258"
"5370","32.18400","2.68216","0.05303"
"5406","32.40000","2.70016","0.05306"
"5442","32.61600","2.71827","0.05288"
"5478","32.83200","2.73609","0.05346"
"5514","33.04800","2.75420","0.05305"
"5550","33.26400","2.77208","0.05291"
"5586","33.48000","2.79020","0.05336"
"5622","33.69600","2.80819","0.05385"
"5658","33.91200","2.82613","0.05348"
"5694","34.12800","2.84413","0.05365"
"5730","34.34400","2.86218","0.05350"
"5766","34.56000","2.88018","0.05403"
"5802","34.77600","2.89824","0.05367"
"5838","34.99200","2.91612","0.05347"
"5874","35.20800","2.93417","0.05444"
"5910","35.42400","2.95217","0.05409"
"5946","35.64000","2.97016","0.05318"
"5982","35.85600","2.98822","0.05434"
"6018","36.07200","3.00616","0.05389"
"6054","36.28800","3.02415","0.05399"
"6090","36.50400","3.04215","0.05390"
"6126","36.72000","3.06015","0.05448"
"6162","36.93600","3.07820","0.05440"
"6198","37.15200","3.09608","0.05477"
"6234","37.36800","3.11420","0.05402"
"6270","37.58400","3.13207","0.05420"
"6306","37.80000","3.15019","0.05492"
"6342","38.01600","3.16819","0.05460"
"6378","38.23200","3.18618","0.05498"
"6414","38.44800","3.20412","0.05469"
"6450","38.66400","3.22218","0.05443"
"6486","38.88000","3.24017","0.05495"
"6522","39.09600","3.25817","0.05497"
"6558","39.31200","3.27617","0.05509"
"6594","39.52800","3.29416","0.05567"
"6630","39.74400","3.31210","0.05537"
"6666","39.96000","3.33022","0.05598"
"6702","40.17600","3.34815","0.05582"
"6738","40.39200","3.36621","0.05625"
"6774","40.60800","3.38421","0.05642"
"6810","40.82400","3.40214","0.05615"
"6846","41.04000","3.42014","0.05581"
"6882","41.25600","3.43820","0.05693"
"6918","41.47200","3.45613","0.05610"
"6954","41.68800","3.47419","0.05627"
"6990","41.90400","3.49213","0.05673"
"7026","42.12000","3.51018","0.05646"
"7062","42.33600","3.52818","0.05633"
"7098","42.55200","3.54618","0.05696"
"7134","42.76800","3.56417","0.05688"
"7170","42.98400","3.58211","0.05686"
"7206","43.20000","3.60017","0.05767"
"7242","43.41600","3.61816","0.05687"
"7278","43.63200","3.63616","0.05632"
"7314","43.84800","3.65422","0.05663"
"7350","44.06400","3.67215","0.05768"
"7386","44.28000","3.69015","0.05719"
"7422","44.49600","3.70815","0.05772"
"7458","44.71200","3.72614","0.05801"
"7494","44.92800","3.74414","0.05755"
"7530","45.14400","3.76214","0.05703"
"7566","45.36000","3.78019","0.05795"
"7602","45.57600","3.79819","0.05794"
"7638","45.79200","3.81613","0.05830"
"7674","46.00800","3.83418","0.05846"
"7710","46.22400","3.85212","0.05827"
"7746","46.44000","3.87018","0.05809"
"7782","46.65600","3.88817","0.05802"
"7818","46.87200","3.90617","0.05808"
"7854","47.08800","3.92417","0.05652"
"7890","47.30400","3.94210","0.05742"
"7926","47.52000","3.96022","0.05753"
"7962","47.73600","3.97816","0.05778"
"7998","47.95200","3.99615","0.05804"
"8034","48.16800","4.01421","0.05845"
"8070","48.38400","4.03215","0.05816"
"8106","48.60000","4.05020","0.05842"
"8142","48.81600","4.06814","0.05925"
"8178","49.03200","4.08614","0.05873"
"8214","49.24800","4.10419","0.05940"
"8250","49.46400","4.12213","0.05905"
"8286","49.68000","4.14019","0.05847"
"8322","49.89600","4.15812","0.05823"
"8358","50.11200","4.17612","0.05783"
"8394","50.32800","4.19418","0.05915"
"8430","50.54400","4.21211","0.05854"
"8466","50.76000","4.23017","0.05892"
"8502","50.97600","4.24817","0.05896"
"8538","51.19200","4.26616","0.05784"
"8574","51.40800","4.28422","0.05857"
"8610","51.62400","4.30210","0.05886"
"8646","51.84000","4.32021","0.05935"
"8682","52.05600","4.33815","0.05918"
"8718","52.27200","4.35615","0.05912"
"8754","52.48800","4.37420","0.05939"
"8790","52.70400","4.39214","0.05950"
"8826","52.92000","4.41020","0.05940"
"8862","53.13600","4.42819","0.05976"
"8898","53.35200","4.44613","0.05969"
"8934","53.56800","4.46419","0.05956"
"8970","53.78400","4.48206","0.05995"
"9006","54.00000","4.50024","0.05963"
"9042","54.21600","4.51812","0.06011"
"9078","54.43200","4.53617","0.06028"
"9114","54.64800","4.55417","0.06020"
"9150","54.86400","4.57211","0.06060"
"9186","55.08000","4.59022","0.06025"
"9222","55.29600","4.60822","0.06011"
"9258","55.51200","4.62616","0.06052"
"9294","55.72800","4.64415","0.06017"
"9330","55.94400","4.66209","0.06059"
"9366","56.16000","4.68021","0.06045"
"9402","56.37600","4.69820","0.05990"
"9438","56.59200","4.71620","0.05935"
"9474","56.80800","4.73419","0.06004"
"9510","57.02400","4.75213","0.06000"
"9546","57.24000","4.77019","0.06064"
"9582","57.45600","4.78819","0.06074"
"9618","57.67200","4.80612","0.06034"
"9654","57.88800","4.82418","0.06027"
"9690","58.10400","4.84206","0.06045"
"9726","58.32000","4.86017","0.06071"
"9762","58.53600","4.87811","0.06053"
"9798","58.75200","4.89616","0.06067"
"9834","58.96800","4.91416","0.06084"
"9870","59.18400","4.93216","0.06139"
"9906","59.40000","4.95015","0.06043"
"9942","59.61600","4.96821","0.06051"
"9978","59.83200","4.98615","0.06089"
"10014","60.04800","5.00420","0.06055"
"10050","60.26400","5.02208","0.06092"
"10086","60.48000","5.04020","0.06115"
"10122","60.69600","5.05813","0.06096"
"10158","60.91200","5.07619","0.06111"
"10194","61.12800","5.09413","0.06088"
"10230","61.34400","5.11212","0.06122"
"10266","61.56000","5.13012","0.06084"
"10302","61.77600","5.14818","0.06048"
"10338","61.99200","5.16617","0.06132"
"10374","62.20800","5.18417","0.06121"
"10410","62.42400","5.20211","0.06105"
"10446","62.64000","5.22016","0.06143"
"10482","62.85600","5.23816","0.06165"
"10518","63.07200","5.25616","0.06195"
"10554","63.28800","5.27415","0.06187"
"10590","63.50400","5.29209","0.06165"
"10626","63.72000","5.31015","0.06202"
"10662","63.93600","5.32814","0.06182"
"10698","64.15200","5.34620","0.06185"
"10734","64.36800","5.36420","0.06175"
"10770","64.58400","5.38207","0.06124"
"10806","64.80000","5.40019","0.06175"
"10842","65.01600","5.41813","0.06235"
"10878","65.23200","5.43618","0.06162"
"10914","65.44800","5.45418","0.06205"
"10950","65.66400","5.47212","0.06194"
"10986","65.88000","5.49017","0.06222"
"11022","66.09600","5.50811","0.06211"
"11058","66.31200","5.52611","0.06238"
"11094","66.52800","5.54416","0.06270"
"11130","66.74400","5.56210","0.06213"
"11166","66.96000","5.58016","0.06248"
"11202","67.17600","5.59815","0.06243"
"11238","67.39200","5.61621","0.06270"
"11274","67.60800","5.63415","0.06346"
"11310","67.82400","5.65214","0.06316"
"11346","68.04000","5.67014","0.06312"
"11382","68.25600","5.68820","0.06299"
"11418","68.47200","5.70613","0.06281"
"11454","68.68800","5.72419","0.06317"
"11490","68.90400","5.74213","0.06340"
"11526","69.12000","5.76018","0.06341"
"11562","69.33600","5.77818","0.06361"
"11598","69.55200","5.79618","0.06322"
"11634","69.76800","5.81411","0.06388"
"11670","69.98400","5.83211","0.06395"
"11706","70.20000","5.85017","0.06305"
"11742","70.41600","5.86816","0.06372"
"11778","70.63200","5.88622","0.06394"
"11814","70.84800","5.90410","0.06371"
"11850","71.06400","5.92215","0.06376"
"11886","71.28000","5.94015","0.06385"
"11922","71.49600","5.95815","0.06384"
"11958","71.71200","5.97620","0.06374"
"11994","71.92800","5.99414","0.06419"
"12030","72.14400","6.01214","0.06414"
"12066","72.36000","6.03019","0.06438"
"12102","72.57600","6.04813","0.06414"
"12138","72.79200","6.06625","0.06494"
"12174","73.00800","6.08418","0.06475"
"12210","73.22400","6.10212","0.06495"
"12246","73.44000","6.12012","0.06458"
"12282","73.65600","6.13817","0.06480"
"12318","73.87200","6.15617","0.06525"
"12354","74.08800","6.17423","0.06488"
"12390","74.30400","6.19210","0.06549"
"12426","74.52000","6.21022","0.06517"
"12462","74.73600","6.22816","0.06532"
"12498","74.95200","6.24615","0.06544"
"12534","75.16800","6.26415","0.06553"
"12570","75.38400","6.28215","0.06518"
"12606","75.60000","6.30020","0.06554"
"12642","75.81600","6.31814","0.06503"
"12678","76.03200","6.33614","0.06515"
"12714","76.24800","6.35419","0.06511"
"12750","76.46400","6.37213","0.06537"
"12786","76.68000","6.39019","0.06550"
"12822","76.89600","6.40812","0.06523"
"12858","77.11200","6.42618","0.06504"
"12894","77.32800","6.44412","0.06495"
"12930","77.54400","6.46217","0.06526"
"12966","77.76000","6.48017","0.06526"
"13002","77.97600","6.49817","0.06593"
"13038","78.19200","6.51616","0.06532"
"13074","78.40800","6.53422","0.06597"
"13110","78.62400","6.55210","0.06582"
"13146","78.84000","6.57021","0.06604"
"13182","79.05600","6.58815","0.06604"
"13218","79.27200","6.60621","0.06621"
"13254","79.48800","6.62414","0.06615"
"13290","79.70400","6.64214","0.06631"
"13326","79.92000","6.66019","0.06612"
"13362","80.13600","6.67819","0.06636"
"13398","80.35200","6.69619","0.06655"
"13434","80.56800","6.71419","0.06660"
"13470","80.78400","6.73212","0.06715"
"13506","81.00000","6.75018","0.06625"
"13542","81.21600","6.76812","0.06705"
"13578","81.43200","6.78623","0.06678"
"13614","81.64800","6.80411","0.06683"
"13650","81.86400","6.82217","0.06679"
"13686","82.08000","6.84016","0.06689"
"13722","82.29600","6.85816","0.06702"
"13758","82.51200","6.87622","0.06720"
"13794","82.72800","6.89415","0.06713"
"13830","82.94400","6.91215","0.06729"
"13866","83.16000","6.93020","0.06735"
"13902","83.37600","6.94814","0.06729"
"13938","83.59200","6.96620","0.06746"
"13974","83.80800","6.98413","0.06748"
"14010","84.02400","7.00213","0.06766"
"14046","84.24000","7.02019","0.06743"
"14082","84.45600","7.03807","0.06753"
"14118","84.67200","7.05618","0.06779"
"14154","84.88800","7.07418","0.06810"
"14190","85.10400","7.09218","0.06788"
"14226","85.32000","7.11023","0.06809"
"14262","85.53600","7.12811","0.06803"
"14298","85.75200","7.14616","0.06838"
"14334","85.96800","7.16416","0.06836"
"14370","86.18400","7.18216","0.06838"
"14406","86.40000","7.20009","0.06834"
"14442","86.61600","7.21815","0.06892"
"14478","86.83200","7.23621","0.06872"
"14514","87.04800","7.25415","0.06858"
"14550","87.26400","7.27214","0.06872"
"14586","87.48000","7.29020","0.06916"
"14622","87.69600","7.30814","0.06917"
"14658","87.91200","7.32619","0.06936"
"14694","88.12800","7.34413","0.06954"
"14730","88.34400","7.36218","0.06977"
"14766","88.56000","7.38018","0.06987"
"14802","88.77600","7.39812","0.06953"
"14838","88.99200","7.41617","0.07004"
"14874","89.20800","7.43417","0.07002"
"14910","89.42400","7.45217","0.06984"
"14946","89.64000","7.47016","0.06975"
"14982","89.85600","7.48816","0.06930"
"15018","90.07200","7.50616","0.06990"
"15054","90.28800","7.52415","0.06990"
"15090","90.50400","7.54221","0.06948"
"15126","90.72000","7.56021","0.06985"
"15162","90.93600","7.57814","0.06982"
"15198","91.15200","7.59620","0.06999"
"15234","91.36800","7.61420","0.07016"
"15270","91.58400","7.63219","0.07050"
"15306","91.80000","7.65019","0.07030"
"15342","92.01600","7.66813","0.07072"
"15378","92.23200","7.68618","0.07053"
"15414","92.44800","7.70412","0.07078"
"15450","92.66400","7.72218","0.07108"
"15486","92.88000","7.74017","0.07088"
"15522","93.09600","7.75811","0.07116"
"15558","93.31200","7.77623","0.07115"
"15594","93.52800","7.79410","0.07127"
"15630","93.74400","7.81216","0.07159"
"15666","93.96000","7.83016","0.07136"
"15702","94.17600","7.84815","0.06551"
"15738","94.39200","7.86615","0.06617"
"15774","94.60800","7.88421","0.06650"
"15810","94.82400","7.90220","0.06682"
"15846","95.04000","7.92020","0.06687"
"15882","95.25600","7.93808","0.06697"
"15918","95.47200","7.95619","0.06744"
"15954","95.68800","7.97413","0.06764"
"15990","95.90400","7.99213","0.06779"
"16026","96.12000","8.01018","0.06803"
"16062","96.33600","8.02812","0.06845"
"16098","96.55200","8.04618","0.06855"
"16134","96.76800","8.06417","0.06878"
"16170","96.98400","8.08217","0.06879"
"16206","97.20000","8.10017","0.06873"
"16242","97.41600","8.11810","0.06919"
"16278","97.63200","8.13622","0.06937"
"16314","97.84800","8.15410","0.06937"
"16350","98.06400","8.17221","0.06921"
"16386","98.28000","8.19021","0.06994"
"16422","98.49600","8.20815","0.07000"
"16458","98.71200","8.22620","0.07027"
"16494","98.92800","8.24414","0.07020"
"16530","99.14400","8.26220","0.07048"
"16566","99.36000","8.28025","0.07032"
"16602","99.57600","8.29813","0.07028"
"16638","99.79200","8.31619","0.07081"
"16674","100.00800","8.33418","0.07066"
"16710","100.22400","8.35218","0.07120"
"16746","100.44000","8.37018","0.07102"
"16782","100.65600","8.38811","0.07121"
"16818","100.87200","8.40617","0.07158"
"16854","101.08800","8.42417","0.07163"
"16890","101.30400","8.44210","0.07178"
"16926","101.52000","8.46022","0.07217"
"16962","101.73600","8.47810","0.07192"
"16998","101.95200","8.49621","0.07214"
"17034","102.16800","8.51409","0.07214"
"17070","102.38400","8.53221","0.07254"
"17106","102.60000","8.55014","0.07336"
"17142","102.81600","8.56814","0.07277"
"17178","103.03200","8.58614","0.07259"
"17214","103.24800","8.60413","0.07267"
"17250","103.46400","8.62219","0.07291"
"17286","103.68000","8.64013","0.07324"
"17322","103.89600","8.65812","0.07360"
"17358","104.11200","8.67612","0.07370"
"17394","104.32800","8.69418","0.07421"
"17430","104.54400","8.71223","0.07406"
"17466","104.76000","8.73017","0.07435"
"17502","104.97600","8.74817","0.07408"
"17538","105.19200","8.76616","0.07382"
"17574","105.40800","8.78416","0.07438"
"17610","105.62400","8.80216","0.07450"
"17646","105.84000","8.82015","0.07489"
"17682","106.05600","8.83815","0.07559"
"17718","106.27200","8.85620","0.07540"
"17754","106.48800","8.87414","0.07572"
"17790","106.70400","8.89220","0.07594"
"17826","106.92000","8.91014","0.07608"
"17862","107.13600","8.92813","0.07657"
"17898","107.35200","8.94619","0.07683"
"17934","107.56800","8.96412","0.07666"
"17970","107.78400","8.98218","0.07659"
"18006","108.00000","9.00018","0.07716"
"18042","108.21600","9.01812","0.07710"
"18078","108.43200","9.03617","0.07655"
"18114","108.64800","9.05417","0.07721"
"18150","108.86400","9.07222","0.07718"
"18186","109.08000","9.09016","0.07781"
"18222","109.29600","9.10816","0.07830"
"18258","109.51200","9.12615","0.07829"
"18294","109.72800","9.14409","0.07858"
"18330","109.94400","9.16221","0.07903"
"18366","110.16000","9.18014","0.07883"
"18402","110.37600","9.19814","0.07913"
"18438","110.59200","9.21620","0.07941"
"18474","110.80800","9.23413","0.07904"
"18510","111.02400","9.25219","0.07954"
"18546","111.24000","9.27019","0.07922"
"18582","111.45600","9.28818","0.07969"
"18618","111.67200","9.30618","0.08047"
"18654","111.88800","9.32412","0.07231"
"18690","112.10400","9.34217","0.07015"
"18726","112.32000","9.36017","0.07029"
"18762","112.53600","9.37817","0.07081"
"18798","112.75200","9.39616","0.07116"
"18834","112.96800","9.41416","0.07107"
"18870","113.18400","9.43222","0.07115"
"18906","113.40000","9.45015","0.07190"
"18942","113.61600","9.46815","0.07194"
"18978","113.83200","9.48615","0.07227"
"19014","114.04800","9.50414","0.07225"
"19050","114.26400","9.52220","0.07302"
"19086","114.48000","9.54014","0.07350"
"19122","114.69600","9.55819","0.07349"
"19158","114.91200","9.57613","0.07409"
"19194","115.12800","9.59407","0.07372"
"19230","115.34400","9.61218","0.07440"
"19266","115.56000","9.63018","0.07435"
"19302","115.77600","9.64818","0.07445"
"19338","115.99200","9.66623","0.07504"
"19374","116.20800","9.68411","0.07533"
"19410","116.42400","9.70223","0.07532"
"19446","116.64000","9.72016","0.07470"
"19482","116.85600","9.73816","0.07557"
"19518","117.07200","9.75622","0.07514"
"19554","117.28800","9.77409","0.07570"
"19590","117.50400","9.79221","0.07582"
"19626","117.72000","9.81021","0.07592"
"19662","117.93600","9.82814","0.07618"
"19698","118.15200","9.84620","0.07658"
"19734","118.36800","9.86408","0.07711"
"19770","118.58400","9.88219","0.07636"
"19806","118.80000","9.90013","0.07684"
"19842","119.01600","9.91813","0.07704"
"19878","119.23200","9.93618","0.07746"
"19914","119.44800","9.95412","0.07788"
"19950","119.66400","9.97212","0.07788"
"19986","119.88000","9.99017","0.07755"
"20022","120.09600","10.00817","0.07773"
"20058","120.31200","10.02617","0.07816"
"20094","120.52800","10.04410","0.07770"
"20130","120.74400","10.06222","0.07853"
"20166","120.96000","10.08016","0.07801"
"20202","121.17600","10.09815","0.07789"
"20238","121.39200","10.11615","0.07837"
"20274","121.60800","10.13415","0.07868"
"20310","121.82400","10.15214","0.07973"
"20346","122.04000","10.17020","0.07833"
"20382","122.25600","10.18814","0.07849"
"20418","122.47200","10.20619","0.07895"
"20454","122.68800","10.22407","0.07903"
"20490","122.90400","10.24219","0.07918"
"20526","123.12000","10.26006","0.07938"
"20562","123.33600","10.27818","0.07980"
"20598","123.55200","10.29618","0.07993"
"20634","123.76800","10.31417","0.08089"
"20670","123.98400","10.33217","0.08102"
"20706","124.20000","10.35017","0.08123"
"20742","124.41600","10.36816","0.08205"
"20778","124.63200","10.38616","0.08250"
"20814","124.84800","10.40409","0.08255"
"20850","125.06400","10.42221","0.08299"
"20886","125.28000","10.44015","0.08209"
"20922","125.49600","10.45821","0.08222"
"20958","125.71200","10.47620","0.08230"
"20994","125.92800","10.49414","0.08284"
"21030","126.14400","10.51220","0.08289"
"21066","126.36000","10.53013","0.08318"
"21102","126.57600","10.54813","0.08366"
"21138","126.79200","10.56619","0.08406"
"21174","127.00800","10.58412","0.08400"
"21210","127.22400","10.60218","0.08283"
"21246","127.44000","10.62012","0.08340"
"21282","127.65600","10.63817","0.08358"
"21318","127.87200","10.65617","0.08418"
"21354","128.08800","10.67417","0.08499"
"21390","128.30400","10.69216","0.08571"
"21426","128.52000","10.71016","0.08517"
"21462","128.73600","10.72816","0.08501"
"21498","128.95200","10.74615","0.08530"
"21534","129.16800","10.76409","0.08574"
"21570","129.38400","10.78215","0.08632"
"21606","129.60000","10.80014","0.08737"
"21642","129.81600","10.81820","0.08811"
"21678","130.03200","10.83619","0.08821"
"21714","130.24800","10.85413","0.08869"
"21750","130.46400","10.87219","0.08912"
"21786","130.68000","10.89012","0.09021"
"21822","130.89600","10.90818","0.09084"
"21858","131.11200","10.92612","0.09058"
"21894","131.32800","10.94412","0.09041"
"21930","131.54400","10.96217","0.09127"
"21966","131.76000","10.98017","0.09125"
"22002","131.97600","10.99817","0.09162"
"22038","132.19200","11.01616","0.09231"
"22074","132.40800","11.03416","0.09277"
"22110","132.62400","11.05222","0.09250"
"22146","132.84000","11.07015","0.09309"
"22182","133.05600","11.08821","0.09098"
"22218","133.27200","11.10620","0.09059"
"22254","133.48800","11.12414","0.09041"
"22290","133.70400","11.14214","0.09073"
"22326","133.92000","11.16014","0.09125"
"22362","134.13600","11.17819","0.09138"
"22398","134.35200","11.19619","0.09193"
"22434","134.56800","11.21407","0.09205"
"22470","134.78400","11.23218","0.09219"
"22506","135.00000","11.25012","0.09287"
"22542","135.21600","11.26818","0.09270"
"22578","135.43200","11.28611","0.09380"
"22614","135.64800","11.30417","0.09420"
"22650","135.86400","11.32216","0.09502"
"22686","136.08000","11.34016","0.09494"
"22722","136.29600","11.35816","0.09518"
"22758","136.51200","11.37615","0.09594"
"22794","136.72800","11.39415","0.09645"
"22830","136.94400","11.41221","0.09717"
"22866","137.16000","11.43008","0.09754"
"22902","137.37600","11.44820","0.09880"
"22938","137.59200","11.46614","0.09864"
"22974","137.80800","11.48413","0.09990"
"23010","138.02400","11.50213","0.09988"
"23046","138.24000","11.52019","0.10039"
"23082","138.45600","11.53818","0.09955"
"23118","138.67200","11.55618","0.09890"
"23154","138.88800","11.57412","0.09948"
"23190","139.10400","11.59223","0.09985"
"23226","139.32000","11.61011","0.10037"
"23262","139.53600","11.62823","0.10125"
"23298","139.75200","11.64616","0.10166"
"23334","139.96800","11.66416","0.10207"
"23370","140.18400","11.68222","0.10133"
"23406","140.40000","11.70015","0.10202"
"23442","140.61600","11.71815","0.10157"
"23478","140.83200","11.73621","0.10201"
"23514","141.04800","11.75414","0.10279"
"23550","141.26400","11.77220","0.10340"
"23586","141.48000","11.79014","0.10340"
"23622","141.69600","11.80825","0.10370"
"23658","141.91200","11.82613","0.10409"
"23694","142.12800","11.84419","0.10423"
"23730","142.34400","11.86218","0.10187"
"23766","142.56000","11.88012","0.10268"
"23802","142.77600","11.89824","0.10235"
"23838","142.99200","11.91617","0.10301"
"23874","143.20800","11.93411","0.10291"
"23910","143.42400","11.95217","0.08816"
"23946","143.64000","11.97016","0.08879"
"23982","143.85600","11.98822","0.08944"
"24018","144.07200","12.00616","0.08957"
"24054","144.28800","12.02415","0.09018"
"24090","144.50400","12.04215","0.09126"
"24126","144.72000","12.06009","0.09181"
"24162","144.93600","12.07820","0.09230"
"24198","145.15200","12.09620","0.09274"
"24234","145.36800","12.11414","0.09244"
"24270","145.58400","12.13219","0.09239"
"24306","145.80000","12.15013","0.09242"
"24342","146.01600","12.16819","0.09291"
"24378","146.23200","12.18612","0.09441"
"24414","146.44800","12.20418","0.09369"
"24450","146.66400","12.22218","0.09439"
"24486","146.88000","12.24011","0.09516"
"24522","147.09600","12.25817","0.09511"
"24558","147.31200","12.27617","0.09627"
"24594","147.52800","12.29416","0.09518"
"24630","147.74400","12.31216","0.09582"
"24666","147.96000","12.33010","0.09712"
"24702","148.17600","12.34821","0.09692"
"24738","148.39200","12.36609","0.09731"
"24774","148.60800","12.38415","0.09790"
"24810","148.82400","12.40220","0.09864"
"24846","149.04000","12.42014","0.09919"
"24882","149.25600","12.43820","0.09997"
"24918","149.47200","12.45613","0.10037"
"24954","149.68800","12.47419","0.10110"
"24990","149.90400","12.49219","0.10141"
"25026","150.12000","12.51012","0.10269"
"25062","150.33600","12.52818","0.10374"
"25098","150.55200","12.54618","0.10388"
"25134","150.76800","12.56417","0.10500"
"25170","150.98400","12.58223","0.10558"
"25206","151.20000","12.60011","0.10593"
"25242","151.41600","12.61822","0.10678"
"25278","151.63200","12.63616","0.10778"
"25314","151.84800","12.65416","0.10757"
"25350","152.06400","12.67221","0.10839"
"25386","152.28000","12.69015","0.10890"
"25422","152.49600","12.70821","0.10982"
"25458","152.71200","12.72614","0.10990"
"25494","152.92800","12.74414","0.11050"
"25530","153.14400","12.76220","0.11129"
"25566","153.36000","12.78013","0.11150"
"25602","153.57600","12.79819","0.11214"
"25638","153.79200","12.81613","0.11252"
"25674","154.00800","12.83418","0.11272"
"25710","154.22400","12.85218","0.11334"
"25746","154.44000","12.87012","0.11364"
"25782","154.65600","12.88811","0.11374"
"25818","154.87200","12.90617","0.11404"
"25854","155.08800","12.92416","0.11489"
"25890","155.30400","12.94216","0.11540"
"25926","155.52000","12.96016","0.11561"
"25962","155.73600","12.97816","0.11587"
"25998","155.95200","12.99615","0.11623"
"26034","156.16800","13.01415","0.11669"
"26070","156.38400","13.03215","0.11649"
"26106","156.60000","13.05014","0.11686"
"26142","156.81600","13.06820","0.11727"
"26178","157.03200","13.08613","0.11764"
"26214","157.24800","13.10419","0.11798"
"26250","157.46400","13.12219","0.11802"
"26286","157.68000","13.14012","0.10766"
"26322","157.89600","13.15818","0.10658"
"26358","158.11200","13.17606","0.10755"
"26394","158.32800","13.19418","0.10829"
"26430","158.54400","13.21217","0.10957"
"26466","158.76000","13.23017","0.11002"
"26502","158.97600","13.24811","0.11093"
"26538","159.19200","13.26616","0.11166"
"26574","159.40800","13.28416","0.11233"
"26610","159.62400","13.30222","0.11309"
"26646","159.84000","13.32009","0.11318"
"26682","160.05600","13.33827","0.11342"
"26718","160.27200","13.35609","0.11443"
"26754","160.48800","13.37420","0.11469"
"26790","160.70400","13.39220","0.11521"
"26826","160.92000","13.41013","0.11499"
"26862","161.13600","13.42819","0.11606"
"26898","161.35200","13.44613","0.11662"
"26934","161.56800","13.46419","0.11662"
"26970","161.78400","13.48224","0.11707"
"27006","162.00000","13.50012","0.11751"
"27042","162.21600","13.51818","0.11786"
"27078","162.43200","13.53611","0.11802"
"27114","162.64800","13.55417","0.11847"
"27150","162.86400","13.57216","0.11873"
"27186","163.08000","13.59016","0.11891"
"27222","163.29600","13.60816","0.11923"
"27258","163.51200","13.62609","0.11944"
"27294","163.72800","13.64421","0.11989"
"27330","163.94400","13.66215","0.11981"
"27366","164.16000","13.68008","0.12013"
"27402","164.37600","13.69820","0.12049"
"27438","164.59200","13.71620","0.12103"
"27474","164.80800","13.73419","0.12151"
"27510","165.02400","13.75219","0.12207"
"27546","165.24000","13.77019","0.12187"
"27582","165.45600","13.78812","0.12294"
"27618","165.67200","13.80612","0.12282"
"27654","165.88800","13.82412","0.12266"
"27690","166.10400","13.84217","0.12360"
"27726","166.32000","13.86011","0.12337"
"27762","166.53600","13.87817","0.12355"
"27798","166.75200","13.89610","0.12374"
"27834","166.96800","13.91422","0.12434"
"27870","167.18400","13.93216","0.12480"
"27906","167.40000","13.95015","0.12531"
"27942","167.61600","13.96815","0.12637"
"27978","167.83200","13.98615","0.12701"
"28014","168.04800","14.00420","0.12774"
"28050","168.26400","14.02214","0.12784"
"28086","168.48000","14.04008","0.12895"
"28122","168.69600","14.05819","0.12963"
"28158","168.91200","14.07613","0.12991"
"28194","169.12800","14.09425","0.13129"
"28230","169.34400","14.11218","0.13179"
"28266","169.56000","14.13012","0.13187"
"28302","169.77600","14.14818","0.13288"
"28338","169.99200","14.16611","0.13387"
"28374","170.20800","14.18417","0.13386"
"28410","170.42400","14.20217","0.13457"
"28446","170.64000","14.22010","0.13488"
"28482","170.85600","14.23822","0.13570"
"28518","171.07200","14.25616","0.13647"
"28554","171.28800","14.27415","0.13747"
"28590","171.50400","14.29221","0.13791"
"28626","171.72000","14.31015","0.13763"
"28662","171.93600","14.32814","0.13952"
"28698","172.15200","14.34608","0.14057"
"28734","172.36800","14.36414","0.14117"
"28770","172.58400","14.38219","0.14219"
"28806","172.80000","14.40013","0.14267"
"28842","173.01600","14.41819","0.14296"
"28878","173.23200","14.43618","0.14360"
"28914","173.44800","14.45418","0.12776"
"28950","173.66400","14.47218","0.12783"
"28986","173.88000","14.49011","0.12947"
"29022","174.09600","14.50817","0.13088"
"29058","174.31200","14.52611","0.13098"
"29094","174.52800","14.54422","0.13222"
"29130","174.74400","14.56216","0.13266"
"29166","174.96000","14.58022","0.13195"
"29202","175.17600","14.59821","0.13257"
"29238","175.39200","14.61615","0.13304"
"29274","175.60800","14.63421","0.12057"
"29310","175.82400","14.65214","0.11896"
"29346","176.04000","14.67020","0.11932"
"29382","176.25600","14.68820","0.12041"
"29418","176.47200","14.70613","0.12042"
"29454","176.68800","14.72419","0.12147"
"29490","176.90400","14.74213","0.12269"
"29526","177.12000","14.76018","0.12333"
"29562","177.33600","14.77818","0.12351"
"29598","177.55200","14.79612","0.12455"
"29634","177.76800","14.81423","0.12528"
"29670","177.98400","14.83223","0.12743"
"29706","178.20000","14.85011","0.12818"
"29742","178.41600","14.86822","0.12748"
"29778","178.63200","14.88610","0.12838"
"29814","178.84800","14.90422","0.12799"
"29850","179.06400","14.92209","0.12867"
"29886","179.28000","14.94015","0.12972"
"29922","179.49600","14.95815","0.12973"
"29958","179.71200","14.97614","0.13131"
"29994","179.92800","14.99420","0.13202"
"30030","180.14400","15.01214","0.13230"
"30066","180.36000","15.03019","0.13475"
"30102","180.57600","15.04825","0.13394"
"30138","180.79200","15.06607","0.13425"
"30174","181.00800","15.08424","0.13547"
"30210","181.22400","15.10218","0.13636"
"30246","181.44000","15.12018","0.13749"
"30282","181.65600","15.13817","0.13919"
"30318","181.87200","15.15617","0.14000"
"30354","182.08800","15.17417","0.14084"
"30390","182.30400","15.19216","0.14120"
"30426","182.52000","15.21016","0.14158"
"30462","182.73600","15.22816","0.14102"
"30498","182.95200","15.24609","0.14250"
"30534","183.16800","15.26421","0.14282"
"30570","183.38400","15.28209","0.14366"
"30606","183.60000","15.30014","0.14415"
"30642","183.81600","15.31814","0.14498"
"30678","184.03200","15.33614","0.14638"
"30714","184.24800","15.35413","0.14709"
"30750","184.46400","15.37213","0.14693"
"30786","184.68000","15.39018","0.14775"
"30822","184.89600","15.40812","0.14813"
"30858","185.11200","15.42606","0.14947"
"30894","185.32800","15.44417","0.14935"
"30930","185.54400","15.46217","0.14709"
"30966","185.76000","15.48017","0.14744"
"31002","185.97600","15.49817","0.14827"
"31038","186.19200","15.51610","0.14872"
"31074","186.40800","15.53416","0.14978"
"31110","186.62400","15.55216","0.15056"
"31146","186.84000","15.57009","0.15102"
"31182","187.05600","15.58821","0.15129"
"31218","187.27200","15.60608","0.15210"
"31254","187.48800","15.62420","0.15242"
"31290","187.70400","15.64214","0.15321"
"31326","187.92000","15.66019","0.15432"
"31362","188.13600","15.67819","0.15470"
"31398","188.35200","15.69619","0.15563"
"31434","188.56800","15.71418","0.15533"
"31470","188.78400","15.73218","0.15607"
"31506","189.00000","15.75012","0.15634"
"31542","189.21600","15.76817","0.15688"
"31578","189.43200","15.78611","0.15694"
"31614","189.64800","15.80417","0.15754"
"31650","189.86400","15.82216","0.15778"
"31686","190.08000","15.84016","0.15838"
"31722","190.29600","15.85816","0.15875"
"31758","190.51200","15.87615","0.15922"
"31794","190.72800","15.89415","0.15977"
"31830","190.94400","15.91215","0.16015"
"31866","191.16000","15.93020","0.16072"
"31902","191.37600","15.94814","0.16121"
"31938","191.59200","15.96614","0.16161"
"31974","191.80800","15.98419","0.16165"
"32010","192.02400","16.00213","0.16201"
"32046","192.24000","16.02013","0.16230"
"32082","192.45600","16.03818","0.16214"
"32118","192.67200","16.05612","0.16294"
"32154","192.88800","16.07418","0.16290"
"32190","193.10400","16.09211","0.16310"
"32226","193.32000","16.11017","0.16383"
"32262","193.53600","16.12817","0.16427"
"32298","193.75200","16.14610","0.16463"
"32334","193.96800","16.16416","0.16536"
"32370","194.18400","16.18210","0.16566"
"32406","194.40000","16.20021","0.16586"
"32442","194.61600","16.21821","0.16653"
"32478","194.83200","16.23609","0.16691"
"32514","195.04800","16.25420","0.16699"
"32550","195.26400","16.27214","0.16762"
"32586","195.48000","16.29020","0.16773"
"32622","195.69600","16.30819","0.16811"
"32658","195.91200","16.32619","0.15959"
"32694","196.12800","16.34413","0.11868"
"32730","196.34400","16.36212","0.11883"
"32766","196.56000","16.38024","0.11960"
"32802","196.77600","16.39818","0.12081"
"32838","196.99200","16.41617","0.11993"
"32874","197.20800","16.43417","0.12129"
"32910","197.42400","16.45217","0.12249"
"32946","197.64000","16.47016","0.12212"
"32982","197.85600","16.48816","0.12115"
"33018","198.07200","16.50616","0.12384"
"33054","198.28800","16.52415","0.12476"
"33090","198.50400","16.54221","0.12561"
"33126","198.72000","16.56015","0.12515"
"33162","198.93600","16.57820","0.12700"
"33198","199.15200","16.59608","0.12816"
"33234","199.36800","16.61419","0.12847"
"33270","199.58400","16.63213","0.12821"
"33306","199.80000","16.65025","0.12995"
"33342","200.01600","16.66813","0.12916"
"33378","200.23200","16.68618","0.13018"
"33414","200.44800","16.70418","0.12965"
"33450","200.66400","16.72212","0.13189"
"33486","200.88000","16.74017","0.13271"
"33522","201.09600","16.75817","0.13161"
"33558","201.31200","16.77617","0.13194"
"33594","201.52800","16.79422","0.13372"
"33630","201.74400","16.81210","0.13398"
"33666","201.96000","16.83022","0.13443"
"33702","202.17600","16.84815","0.13372"
"33738","202.39200","16.86615","0.13492"
"33774","202.60800","16.88415","0.13478"
"33810","202.82400","16.90214","0.13507"
"33846","203.04000","16.92020","0.13499"
"33882","203.25600","16.93819","0.13710"
"33918","203.47200","16.95613","0.13641"
"33954","203.68800","16.97419","0.13709"
"33990","203.90400","16.99213","0.13600"
"34026","204.12000","17.01018","0.13754"
"34062","204.33600","17.02818","0.13748"
"34098","204.55200","17.04611","0.13782"
"34134","204.76800","17.06417","0.13815"
"34170","204.98400","17.08211","0.14021"
"34206","205.20000","17.10016","0.14115"
"34242","205.41600","17.11816","0.14136"
"34278","205.63200","17.13610","0.14218"
"34314","205.84800","17.15421","0.14341"
"34350","206.06400","17.17215","0.14363"
"34386","206.28000","17.19015","0.14467"
"34422","206.49600","17.20821","0.14515"
"34458","206.71200","17.22620","0.14656"
"34494","206.92800","17.24414","0.14670"
"34530","207.14400","17.26213","0.14750"
"34566","207.36000","17.28019","0.14804"
"34602","207.57600","17.29813","0.14951"
"34638","207.79200","17.31613","0.15043"
"34674","208.00800","17.33418","0.15101"
"34710","208.22400","17.35212","0.15128"
"34746","208.44000","17.37017","0.15065"
"34782","208.65600","17.38811","0.15197"
"34818","208.87200","17.40611","0.15211"
"34854","209.08800","17.42410","0.15321"
"34890","209.30400","17.44210","0.15283"
"34926","209.52000","17.46016","0.15381"
"34962","209.73600","17.47816","0.15402"
"34998","209.95200","17.49615","0.15464"
"35034","210.16800","17.51421","0.15444"
"35070","210.38400","17.53208","0.15524"
"35106","210.60000","17.55020","0.15562"
"35142","210.81600","17.56814","0.15518"
"35178","211.03200","17.58613","0.14440"
"35214","211.24800","17.60419","0.14537"
"35250","211.46400","17.62213","0.14545"
"35286","211.68000","17.64018","0.14704"
"35322","211.89600","17.65818","0.14765"
"35358","212.11200","17.67618","0.14959"
"35394","212.32800","17.69417","0.14974"
"35430","212.54400","17.71211","0.15098"
"35466","212.76000","17.73023","0.15188"
"35502","212.97600","17.74816","0.15229"
"35538","213.19200","17.76610","0.15289"
"35574","213.40800","17.78422","0.15370"
"35610","213.62400","17.80210","0.15489"
"35646","213.84000","17.82021","0.15535"
"35682","214.05600","17.83815","0.15599"
"35718","214.27200","17.85620","0.15620"
"35754","214.48800","17.87420","0.15674"
"35790","214.70400","17.89214","0.15723"
"35826","214.92000","17.91013","0.15819"
"35862","215.13600","17.92813","0.15852"
"35898","215.35200","17.94619","0.15894"
"35934","215.56800","17.96418","0.15927"
"35970","215.78400","17.98212","0.15985"
"36006","216.00000","18.00018","0.16023"
"36042","216.21600","18.01817","0.16097"
"36078","216.43200","18.03617","0.16106"
"36114","216.64800","18.05417","0.16145"
"36150","216.86400","18.07216","0.16217"
"36186","217.08000","18.09016","0.16244"
"36222","217.29600","18.10816","0.16240"
"36258","217.51200","18.12621","0.16330"
"36294","217.72800","18.14415","0.16359"
"36330","217.94400","18.16215","0.16361"
"36366","218.16000","18.18014","0.16442"
"36402","218.37600","18.19814","0.16416"
"36438","218.59200","18.21620","0.16502"
"36474","218.80800","18.23419","0.16493"
"36510","219.02400","18.25219","0.16520"
"36546","219.24000","18.27019","0.16593"
"36582","219.45600","18.28812","0.16622"
"36618","219.67200","18.30618","0.16650"
"36654","219.88800","18.32418","0.16683"
"36690","220.10400","18.34217","0.16724"
"36726","220.32000","18.36017","0.16740"
"36762","220.53600","18.37817","0.16769"
"36798","220.75200","18.39622","0.16776"
"36834","220.96800","18.41416","0.16848"
"36870","221.18400","18.43216","0.16866"
"36906","221.40000","18.45021","0.16937"
"36942","221.61600","18.46809","0.16950"
"36978","221.83200","18.48615","0.17012"
"37014","222.04800","18.50420","0.17059"
"37050","222.26400","18.52208","0.16984"
"37086","222.48000","18.54020","0.16967"
"37122","222.69600","18.55813","0.17060"
"37158","222.91200","18.57619","0.17122"
"37194","223.12800","18.59419","0.17176"
"37230","223.34400","18.61218","0.17288"
"37266","223.56000","18.63012","0.17360"
"37302","223.77600","18.64812","0.17453"
"37338","223.99200","18.66617","0.17500"
"37374","224.20800","18.68417","0.17392"
"37410","224.42400","18.70211","0.17335"
"37446","224.64000","18.72016","0.17316"
"37482","224.85600","18.73816","0.17010"
"37518","225.07200","18.75616","0.16661"
"37554","225.28800","18.77415","0.16717"
"37590","225.50400","18.79215","0.16785"
"37626","225.72000","18.81015","0.16825"
"37662","225.93600","18.82814","0.16865"
"37698","226.15200","18.84614","0.16938"
"37734","226.36800","18.86414","0.16904"
"37770","226.58400","18.88207","0.16946"
"37806","226.80000","18.90019","0.17010"
"37842","227.01600","18.91813","0.17061"
"37878","227.23200","18.93618","0.17073"
"37914","227.44800","18.95418","0.17143"
"37950","227.66400","18.97218","0.17236"
"37986","227.88000","18.99017","0.17300"
"38022","228.09600","19.00817","0.17373"
"38058","228.31200","19.02623","0.17380"
"38094","228.52800","19.04422","0.17507"
"38130","228.74400","19.06210","0.17646"
"38166","228.96000","19.08015","0.17714"
"38202","229.17600","19.09815","0.17839"
"38238","229.39200","19.11621","0.17888"
"38274","229.60800","19.13415","0.17980"
"38310","229.82400","19.15214","0.18153"
"38346","230.04000","19.17020","0.18306"
"38382","230.25600","19.18814","0.18374"
"38418","230.47200","19.20613","0.18423"
"38454","230.68800","19.22419","0.18513"
"38490","230.90400","19.24212","0.18452"
"38526","231.12000","19.26018","0.18573"
"38562","231.33600","19.27812","0.18382"
"38598","231.55200","19.29618","0.18454"
"38634","231.76800","19.31417","0.18455"
"38670","231.98400","19.33211","0.18565"
"38706","232.20000","19.35017","0.18631"
"38742","232.41600","19.36810","0.18677"
"38778","232.63200","19.38616","0.17322"
"38814","232.84800","19.40415","0.17456"
"38850","233.06400","19.42215","0.17516"
"38886","233.28000","19.44015","0.17547"
"38922","233.49600","19.45815","0.17597"
"38958","233.71200","19.47620","0.17677"
"38994","233.92800","19.49420","0.17846"
"39030","234.14400","19.51214","0.17928"
"39066","234.36000","19.53019","0.18103"
"39102","234.57600","19.54813","0.18162"
"39138","234.79200","19.56625","0.18260"
"39174","235.00800","19.58412","0.18410"
"39210","235.22400","19.60218","0.18675"
"39246","235.44000","19.62017","0.18734"
"39282","235.65600","19.63811","0.18872"
"39318","235.87200","19.65623","0.19048"
"39354","236.08800","19.67422","0.19229"
"39390","236.30400","19.69216","0.19403"
"39426","236.52000","19.71016","0.19568"
"39462","236.73600","19.72815","0.19857"
"39498","236.95200","19.74621","0.20100"
"39534","237.16800","19.76415","0.20267"
"39570","237.38400","19.78220","0.20245"
"39606","237.60000","19.80014","0.20375"
"39642","237.81600","19.81814","0.20514"
"39678","238.03200","19.83619","0.20657"
"39714","238.24800","19.85413","0.20756"
"39750","238.46400","19.87213","0.20897"
"39786","238.68000","19.89018","0.20796"
"39822","238.89600","19.90812","0.20597"
"39858","239.11200","19.92618","0.20785"
"39894","239.32800","19.94411","0.20749"
"39930","239.54400","19.96217","0.20939"
"39966","239.76000","19.98017","0.21072"
"40002","239.97600","19.99816","0.20826"
"40038","240.19200","20.01616","0.21157"
"40074","240.40800","20.03416","0.21127"
"40110","240.62400","20.05215","0.21144"
"40146","240.84000","20.07015","0.21309"
"40182","241.05600","20.08809","0.21346"
"40218","241.27200","20.10620","0.21438"
"40254","241.48800","20.12414","0.21572"
"40290","241.70400","20.14220","0.21536"
"40326","241.92000","20.16019","0.21540"
"40362","242.13600","20.17813","0.21572"
"40398","242.35200","20.19619","0.21206"
"40434","242.56800","20.21418","0.20398"
"40470","242.78400","20.23212","0.20212"
"40506","243.00000","20.25018","0.20428"
"40542","243.21600","20.26811","0.20675"
"40578","243.43200","20.28623","0.20963"
"40614","243.64800","20.30411","0.20530"
"40650","243.86400","20.32216","0.20271"
"40686","244.08000","20.34016","0.20424"
"40722","244.29600","20.35810","0.20611"
"40758","244.51200","20.37621","0.20840"
"40794","244.72800","20.39415","0.20957"
"40830","244.94400","20.41221","0.21110"
"40866","245.16000","20.43014","0.21213"
"40902","245.37600","20.44808","0.21381"
"40938","245.59200","20.46620","0.21503"
"40974","245.80800","20.48413","0.21658"
"41010","246.02400","20.50219","0.21684"
"41046","246.24000","20.52019","0.21800"
"41082","246.45600","20.53812","0.21866"
"41118","246.67200","20.55618","0.21988"
"41154","246.88800","20.57417","0.22008"
"41190","247.10400","20.59211","0.22076"
"41226","247.32000","20.61017","0.22190"
"41262","247.53600","20.62805","0.22202"
"41298","247.75200","20.64616","0.22237"
"41334","247.96800","20.66416","0.22310"
"41370","248.18400","20.68216","0.22362"
"41406","248.40000","20.70015","0.22413"
"41442","248.61600","20.71815","0.22463"
"41478","248.83200","20.73615","0.22496"
"41514","249.04800","20.75414","0.22534"
"41550","249.26400","20.77220","0.22573"
"41586","249.48000","20.79020","0.22615"
"41622","249.69600","20.80807","0.22649"
"41658","249.91200","20.82619","0.22696"
"41694","250.12800","20.84418","0.22822"
"41730","250.34400","20.86212","0.22861"
"41766","250.56000","20.88012","0.22994"
"41802","250.77600","20.89812","0.23069"
"41838","250.99200","20.91617","0.23185"
"41874","251.20800","20.93417","0.23276"
"41910","251.42400","20.95217","0.23399"
"41946","251.64000","20.97010","0.23527"
"41982","251.85600","20.98810","0.23624"
"42018","252.07200","21.00616","0.23779"
"42054","252.28800","21.02409","0.23842"
"42090","252.50400","21.04215","0.23965"
"42126","252.72000","21.06015","0.24124"
"42162","252.93600","21.07814","0.24246"
"42198","253.15200","21.09620","0.24311"
"42234","253.36800","21.11414","0.24453"
"42270","253.58400","21.13219","0.24578"
"42306","253.80000","21.15019","0.24661"
"42342","254.01600","21.16813","0.24817"
"42378","254.23200","21.18618","0.24868"
"42414","254.44800","21.20412","0.24997"
"42450","254.66400","21.22218","0.25210"
"42486","254.88000","21.24023","0.25219"
"42522","255.09600","21.25811","0.25364"
"42558","255.31200","21.27622","0.25251"
"42594","255.52800","21.29416","0.25374"
"42630","255.74400","21.31216","0.25500"
"42666","255.96000","21.33021","0.25618"
"42702","256.17600","21.34815","0.25655"
"42738","256.39200","21.36621","0.25624"
"42774","256.60800","21.38415","0.25740"
"42810","256.82400","21.40220","0.25750"
"42846","257.04000","21.42020","0.25825"
"42882","257.25600","21.43814","0.25923"
"42918","257.47200","21.45619","0.25967"
"42954","257.68800","21.47419","0.26043"
"42990","257.90400","21.49219","0.25986"
"43026","258.12000","21.51018","0.25905"
"43062","258.33600","21.52818","0.26000"
"43098","258.55200","21.54611","0.26069"
"43134","258.76800","21.56417","0.26104"
"43170","258.98400","21.58217","0.26254"
"43206","259.20000","21.60016","0.26297"
"43242","259.41600","21.61810","0.26352"
"43278","259.63200","21.63622","0.26478"
"43314","259.84800","21.65416","0.26553"
"43350","260.06400","21.67221","0.26595"
"43386","260.28000","21.69009","0.26664"
"43422","260.49600","21.70814","0.26715"
"43458","260.71200","21.72614","0.26759"
"43494","260.92800","21.74420","0.26797"
"43530","261.14400","21.76219","0.26829"
"43566","261.36000","21.78019","0.26886"
"43602","261.57600","21.79819","0.26928"
"43638","261.79200","21.81618","0.26964"
"43674","262.00800","21.83412","0.26974"
"43710","262.22400","21.85224","0.27018"
"43746","262.44000","21.87012","0.27046"
"43782","262.65600","21.88817","0.27110"
"43818","262.87200","21.90617","0.27107"
"43854","263.08800","21.92416","0.27155"
"43890","263.30400","21.94222","0.27173"
"43926","263.52000","21.96022","0.27216"
"43962","263.73600","21.97815","0.27241"
"43998","263.95200","21.99621","0.27292"
"44034","264.16800","22.01415","0.27328"
"44070","264.38400","22.03226","0.27342"
"44106","264.60000","22.05014","0.27406"
"44142","264.81600","22.06814","0.27436"
"44178","265.03200","22.08619","0.27496"
"44214","265.24800","22.10413","0.27470"
"44250","265.46400","22.12219","0.27589"
"44286","265.68000","22.14013","0.27617"
"44322","265.89600","22.15812","0.27685"
"44358","266.11200","22.17624","0.27667"
"44394","266.32800","22.19411","0.27665"
"44430","266.54400","22.21217","0.27702"
"44466","266.76000","22.23017","0.27792"
"44502","266.97600","22.24816","0.27855"
"44538","267.19200","22.26616","0.27886"
"44549","267.25800","22.27172","0.27901"