File: Trajectories_together/170212_1Specimen_RawData_1.csv
"","V1","V2","V3"
"1","End date","2/12/2017",""
"2","Specimen label","10BG_Unk1",""
"3","Maximum Load","0.11691","N"
"4","Time","Extension","Load"
"5","(s)","(mm)","(N)"
"6","0.00000","0.00000","0.00067"
"62","0.33600","0.02786","0.00037"
"118","0.67200","0.05620","0.00075"
"174","1.00800","0.08424","0.00109"
"230","1.34400","0.11217","0.00197"
"286","1.68000","0.14027","0.00196"
"342","2.01600","0.16819","0.00170"
"398","2.35200","0.19623","0.00227"
"454","2.68800","0.22421","0.00281"
"510","3.02400","0.25219","0.00321"
"566","3.36000","0.28023","0.00324"
"622","3.69600","0.30822","0.00341"
"678","4.03200","0.33620","0.00333"
"734","4.36800","0.36424","0.00342"
"790","4.70400","0.39216","0.00397"
"846","5.04000","0.42014","0.00431"
"902","5.37600","0.44818","0.00527"
"958","5.71200","0.47616","0.00518"
"1014","6.04800","0.50421","0.00479"
"1070","6.38400","0.53219","0.00544"
"1126","6.72000","0.56017","0.00548"
"1182","7.05600","0.58821","0.00596"
"1238","7.39200","0.61613","0.00540"
"1294","7.72800","0.64423","0.00571"
"1350","8.06400","0.67221","0.00618"
"1406","8.40000","0.70014","0.00622"
"1462","8.73600","0.72818","0.00676"
"1518","9.07200","0.75616","0.00713"
"1574","9.40800","0.78420","0.00715"
"1630","9.74400","0.81224","0.00673"
"1686","10.08000","0.84016","0.00739"
"1742","10.41600","0.86820","0.00765"
"1798","10.75200","0.89619","0.00739"
"1854","11.08800","0.92411","0.00770"
"1910","11.42400","0.95221","0.00769"
"1966","11.76000","0.98019","0.00800"
"2022","12.09600","1.00823","0.00780"
"2078","12.43200","1.03621","0.00847"
"2134","12.76800","1.06413","0.00832"
"2190","13.10400","1.09218","0.00885"
"2246","13.44000","1.12022","0.00874"
"2302","13.77600","1.14814","0.00917"
"2358","14.11200","1.17618","0.00951"
"2414","14.44800","1.20422","0.00945"
"2470","14.78400","1.23220","0.00932"
"2526","15.12000","1.26018","0.00995"
"2582","15.45600","1.28817","0.00991"
"2638","15.79200","1.31621","0.00981"
"2694","16.12800","1.34419","0.01042"
"2750","16.46400","1.37217","0.01024"
"2806","16.80000","1.40021","0.01023"
"2862","17.13600","1.42813","0.01078"
"2918","17.47200","1.45623","0.01054"
"2974","17.80800","1.48422","0.01091"
"3030","18.14400","1.51214","0.01135"
"3086","18.48000","1.54024","0.01164"
"3142","18.81600","1.56816","0.01177"
"3198","19.15200","1.59620","0.01189"
"3254","19.48800","1.62424","0.01177"
"3310","19.82400","1.65222","0.01202"
"3366","20.16000","1.68021","0.01224"
"3422","20.49600","1.70825","0.01231"
"3478","20.83200","1.73611","0.01230"
"3534","21.16800","1.76421","0.01252"
"3590","21.50400","1.79219","0.01280"
"3646","21.84000","1.82017","0.01282"
"3702","22.17600","1.84815","0.01331"
"3758","22.51200","1.87620","0.01407"
"3814","22.84800","1.90418","0.01392"
"3870","23.18400","1.93216","0.01449"
"3926","23.52000","1.96014","0.01487"
"3982","23.85600","1.98824","0.01461"
"4038","24.19200","2.01622","0.01478"
"4094","24.52800","2.04414","0.01515"
"4150","24.86400","2.07219","0.01500"
"4206","25.20000","2.10023","0.01566"
"4262","25.53600","2.12821","0.01565"
"4318","25.87200","2.15619","0.01528"
"4374","26.20800","2.18417","0.01620"
"4430","26.54400","2.21221","0.01618"
"4486","26.88000","2.24019","0.01592"
"4542","27.21600","2.26818","0.01638"
"4598","27.55200","2.29622","0.01672"
"4654","27.88800","2.32414","0.01698"
"4710","28.22400","2.35224","0.01698"
"4766","28.56000","2.38016","0.01775"
"4822","28.89600","2.40814","0.01697"
"4878","29.23200","2.43624","0.01809"
"4934","29.56800","2.46417","0.01786"
"4990","29.90400","2.49215","0.01851"
"5046","30.24000","2.52025","0.01855"
"5102","30.57600","2.54817","0.01878"
"5158","30.91200","2.57615","0.01935"
"5214","31.24800","2.60419","0.01859"
"5270","31.58400","2.63217","0.02020"
"5326","31.92000","2.66022","0.01914"
"5382","32.25600","2.68820","0.01987"
"5438","32.59200","2.71618","0.02012"
"5494","32.92800","2.74416","0.02036"
"5550","33.26400","2.77220","0.02088"
"5606","33.60000","2.80018","0.02160"
"5662","33.93600","2.82822","0.02116"
"5718","34.27200","2.85609","0.02132"
"5774","34.60800","2.88419","0.02175"
"5830","34.94400","2.91223","0.02214"
"5886","35.28000","2.94015","0.02302"
"5942","35.61600","2.96819","0.02228"
"5998","35.95200","2.99617","0.02281"
"6054","36.28800","3.02421","0.02285"
"6110","36.62400","3.05220","0.02338"
"6166","36.96000","3.08018","0.02354"
"6222","37.29600","3.10822","0.02361"
"6278","37.63200","3.13614","0.02413"
"6334","37.96800","3.16418","0.02436"
"6390","38.30400","3.19222","0.02412"
"6446","38.64000","3.22014","0.02449"
"6502","38.97600","3.24819","0.02469"
"6558","39.31200","3.27623","0.02528"
"6614","39.64800","3.30415","0.02592"
"6670","39.98400","3.33219","0.02581"
"6726","40.32000","3.36017","0.02592"
"6782","40.65600","3.38815","0.02585"
"6838","40.99200","3.41619","0.02625"
"6894","41.32800","3.44418","0.02682"
"6950","41.66400","3.47216","0.02742"
"7006","42.00000","3.50026","0.02738"
"7062","42.33600","3.52812","0.02741"
"7118","42.67200","3.55616","0.02795"
"7174","43.00800","3.58420","0.02784"
"7230","43.34400","3.61213","0.02847"
"7286","43.68000","3.64017","0.02865"
"7342","44.01600","3.66815","0.02749"
"7398","44.35200","3.69619","0.02821"
"7454","44.68800","3.72423","0.02856"
"7510","45.02400","3.75215","0.02894"
"7566","45.36000","3.78019","0.02882"
"7622","45.69600","3.80817","0.02947"
"7678","46.03200","3.83616","0.02960"
"7734","46.36800","3.86420","0.03021"
"7790","46.70400","3.89218","0.03052"
"7846","47.04000","3.92022","0.03070"
"7902","47.37600","3.94820","0.03111"
"7958","47.71200","3.97618","0.03089"
"8014","48.04800","4.00416","0.03155"
"8070","48.38400","4.03221","0.03116"
"8126","48.72000","4.06013","0.03185"
"8182","49.05600","4.08823","0.03197"
"8238","49.39200","4.11615","0.03260"
"8294","49.72800","4.14419","0.03302"
"8350","50.06400","4.17223","0.03310"
"8406","50.40000","4.20009","0.03356"
"8462","50.73600","4.22820","0.03380"
"8518","51.07200","4.25624","0.03399"
"8574","51.40800","4.28416","0.03387"
"8630","51.74400","4.31220","0.03427"
"8686","52.08000","4.34018","0.03452"
"8742","52.41600","4.36822","0.03461"
"8798","52.75200","4.39626","0.03504"
"8854","53.08800","4.42413","0.03552"
"8910","53.42400","4.45217","0.03548"
"8966","53.76000","4.48021","0.03619"
"9022","54.09600","4.50813","0.03645"
"9078","54.43200","4.53617","0.03642"
"9134","54.76800","4.56421","0.03623"
"9190","55.10400","4.59219","0.03672"
"9246","55.44000","4.62024","0.03714"
"9302","55.77600","4.64816","0.03737"
"9358","56.11200","4.67620","0.03748"
"9414","56.44800","4.70418","0.03758"
"9470","56.78400","4.73216","0.03667"
"9526","57.12000","4.76014","0.03627"
"9582","57.45600","4.78813","0.03632"
"9638","57.79200","4.81623","0.03646"
"9694","58.12800","4.84421","0.03686"
"9750","58.46400","4.87213","0.03703"
"9806","58.80000","4.90023","0.03701"
"9862","59.13600","4.92821","0.03804"
"9918","59.47200","4.95619","0.03777"
"9974","59.80800","4.98418","0.03796"
"10030","60.14400","5.01210","0.03814"
"10086","60.48000","5.04020","0.03841"
"10142","60.81600","5.06824","0.03863"
"10198","61.15200","5.09616","0.03871"
"10254","61.48800","5.12426","0.03931"
"10310","61.82400","5.15224","0.03927"
"10366","62.16000","5.18017","0.03978"
"10422","62.49600","5.20821","0.03964"
"10478","62.83200","5.23619","0.04017"
"10534","63.16800","5.26423","0.03995"
"10590","63.50400","5.29221","0.04063"
"10646","63.84000","5.32019","0.04049"
"10702","64.17600","5.34817","0.04066"
"10758","64.51200","5.37616","0.04107"
"10814","64.84800","5.40414","0.04122"
"10870","65.18400","5.43218","0.04094"
"10926","65.52000","5.46022","0.04134"
"10982","65.85600","5.48820","0.04137"
"11038","66.19200","5.51618","0.04132"
"11094","66.52800","5.54410","0.04210"
"11150","66.86400","5.57221","0.04223"
"11206","67.20000","5.60019","0.04251"
"11262","67.53600","5.62817","0.04257"
"11318","67.87200","5.65621","0.04270"
"11374","68.20800","5.68413","0.04305"
"11430","68.54400","5.71223","0.04351"
"11486","68.88000","5.74021","0.04332"
"11542","69.21600","5.76820","0.04359"
"11598","69.55200","5.79624","0.04424"
"11654","69.88800","5.82416","0.04419"
"11710","70.22400","5.85214","0.04469"
"11766","70.56000","5.88024","0.04504"
"11822","70.89600","5.90816","0.04493"
"11878","71.23200","5.93620","0.04525"
"11934","71.56800","5.96425","0.04596"
"11990","71.90400","5.99217","0.04664"
"12046","72.24000","6.02021","0.04676"
"12102","72.57600","6.04819","0.04692"
"12158","72.91200","6.07623","0.04740"
"12214","73.24800","6.10421","0.04795"
"12270","73.58400","6.13219","0.04822"
"12326","73.92000","6.16017","0.04884"
"12382","74.25600","6.18822","0.04888"
"12438","74.59200","6.21620","0.04969"
"12494","74.92800","6.24418","0.05045"
"12550","75.26400","6.27222","0.05061"
"12606","75.60000","6.30014","0.05134"
"12662","75.93600","6.32818","0.05242"
"12718","76.27200","6.35611","0.05283"
"12774","76.60800","6.38421","0.05302"
"12830","76.94400","6.41225","0.05424"
"12886","77.28000","6.44017","0.05445"
"12942","77.61600","6.46821","0.05549"
"12998","77.95200","6.49613","0.05567"
"13054","78.28800","6.52417","0.05629"
"13110","78.62400","6.55216","0.05719"
"13166","78.96000","6.58014","0.05792"
"13222","79.29600","6.60824","0.05849"
"13278","79.63200","6.63622","0.05895"
"13334","79.96800","6.66414","0.05959"
"13390","80.30400","6.69218","0.06046"
"13446","80.64000","6.72016","0.06162"
"13502","80.97600","6.74815","0.06078"
"13558","81.31200","6.77625","0.06195"
"13614","81.64800","6.80417","0.06268"
"13670","81.98400","6.83221","0.06333"
"13726","82.32000","6.86019","0.06431"
"13782","82.65600","6.88817","0.06466"
"13838","82.99200","6.91621","0.06565"
"13894","83.32800","6.94420","0.06718"
"13950","83.66400","6.97212","0.06775"
"14006","84.00000","7.00022","0.06822"
"14062","84.33600","7.02814","0.06886"
"14118","84.67200","7.05618","0.06961"
"14174","85.00800","7.08422","0.07031"
"14230","85.34400","7.11214","0.07123"
"14286","85.68000","7.14019","0.07220"
"14342","86.01600","7.16817","0.07276"
"14398","86.35200","7.19621","0.07346"
"14454","86.68800","7.22419","0.07396"
"14510","87.02400","7.25211","0.07547"
"14566","87.36000","7.28021","0.07604"
"14622","87.69600","7.30825","0.07687"
"14678","88.03200","7.33618","0.07754"
"14734","88.36800","7.36422","0.07830"
"14790","88.70400","7.39220","0.07910"
"14846","89.04000","7.42018","0.07994"
"14902","89.37600","7.44822","0.08043"
"14958","89.71200","7.47608","0.07888"
"15014","90.04800","7.50418","0.06882"
"15070","90.38400","7.53217","0.06941"
"15126","90.72000","7.56021","0.07004"
"15182","91.05600","7.58819","0.07088"
"15238","91.39200","7.61617","0.07146"
"15294","91.72800","7.64415","0.07262"
"15350","92.06400","7.67219","0.07376"
"15406","92.40000","7.70018","0.07410"
"15462","92.73600","7.72822","0.07546"
"15518","93.07200","7.75626","0.07589"
"15574","93.40800","7.78412","0.07731"
"15630","93.74400","7.81216","0.07787"
"15686","94.08000","7.84020","0.07951"
"15742","94.41600","7.86812","0.07998"
"15798","94.75200","7.89616","0.08090"
"15854","95.08800","7.92421","0.08210"
"15910","95.42400","7.95219","0.08022"
"15966","95.76000","7.98017","0.07961"
"16022","96.09600","8.00815","0.07979"
"16078","96.43200","8.03619","0.08071"
"16134","96.76800","8.06417","0.08158"
"16190","97.10400","8.09221","0.08098"
"16246","97.44000","8.12020","0.06139"
"16302","97.77600","8.14806","0.06359"
"16358","98.11200","8.17622","0.06413"
"16414","98.44800","8.20414","0.06463"
"16470","98.78400","8.23218","0.06499"
"16526","99.12000","8.26022","0.06603"
"16582","99.45600","8.28820","0.06680"
"16638","99.79200","8.31619","0.06682"
"16694","100.12800","8.34423","0.03398"
"16750","100.46400","8.37215","0.03772"
"16806","100.80000","8.40025","0.03673"
"16862","101.13600","8.42817","0.03761"
"16918","101.47200","8.45621","0.03897"
"16974","101.80800","8.48419","0.03806"
"17030","102.14400","8.51218","0.03811"
"17086","102.48000","8.54016","0.03924"
"17142","102.81600","8.56826","0.03893"
"17198","103.15200","8.59612","0.03941"
"17254","103.48800","8.62422","0.04001"
"17310","103.82400","8.65220","0.04004"
"17366","104.16000","8.68018","0.04016"
"17422","104.49600","8.70823","0.04094"
"17478","104.83200","8.73615","0.04030"
"17534","105.16800","8.76419","0.04052"
"17590","105.50400","8.79217","0.04098"
"17646","105.84000","8.82015","0.04102"
"17702","106.17600","8.84825","0.04112"
"17758","106.51200","8.87617","0.04181"
"17814","106.84800","8.90422","0.04145"
"17870","107.18400","8.93220","0.04142"
"17926","107.52000","8.96018","0.04227"
"17982","107.85600","8.98822","0.04226"
"18038","108.19200","9.01626","0.04226"
"18094","108.52800","9.04412","0.04292"
"18150","108.86400","9.07216","0.04325"
"18206","109.20000","9.10015","0.04288"
"18262","109.53600","9.12813","0.04379"
"18318","109.87200","9.15623","0.04372"
"18374","110.20800","9.18415","0.04345"
"18430","110.54400","9.21213","0.04401"
"18486","110.88000","9.24023","0.04442"
"18542","111.21600","9.26816","0.04408"
"18598","111.55200","9.29620","0.04456"
"18654","111.88800","9.32424","0.04496"
"18710","112.22400","9.35216","0.04471"
"18766","112.56000","9.38020","0.04522"
"18822","112.89600","9.40818","0.04552"
"18878","113.23200","9.43616","0.04587"
"18934","113.56800","9.46420","0.04532"
"18990","113.90400","9.49213","0.04650"
"19046","114.24000","9.52023","0.04696"
"19102","114.57600","9.54821","0.04687"
"19158","114.91200","9.57619","0.04755"
"19214","115.24800","9.60417","0.04839"
"19270","115.58400","9.63215","0.04756"
"19326","115.92000","9.66019","0.04687"
"19382","116.25600","9.68818","0.04057"
"19438","116.59200","9.71616","0.04098"
"19494","116.92800","9.74420","0.04125"
"19550","117.26400","9.77218","0.04159"
"19606","117.60000","9.80016","0.04181"
"19662","117.93600","9.82820","0.04192"
"19718","118.27200","9.85612","0.04239"
"19774","118.60800","9.88422","0.04195"
"19830","118.94400","9.91227","0.04147"
"19886","119.28000","9.94013","0.02642"
"19942","119.61600","9.96823","0.02846"
"19998","119.95200","9.99621","0.02682"
"20054","120.28800","10.02419","0.02989"
"20110","120.62400","10.05223","0.02889"
"20166","120.96000","10.08016","0.02915"
"20222","121.29600","10.10814","0.03128"
"20278","121.63200","10.13618","0.03047"
"20334","121.96800","10.16410","0.03045"
"20390","122.30400","10.19220","0.03212"
"20446","122.64000","10.22018","0.03092"
"20502","122.97600","10.24817","0.03199"
"20558","123.31200","10.27615","0.03302"
"20614","123.64800","10.30413","0.03235"
"20670","123.98400","10.33217","0.03251"
"20726","124.32000","10.36021","0.03354"
"20782","124.65600","10.38813","0.03365"
"20838","124.99200","10.41617","0.03342"
"20894","125.32800","10.44415","0.03323"
"20950","125.66400","10.47220","0.03368"
"21006","126.00000","10.50018","0.03440"
"21062","126.33600","10.52822","0.03476"
"21118","126.67200","10.55620","0.03447"
"21174","127.00800","10.58424","0.03502"
"21230","127.34400","10.61210","0.03487"
"21286","127.68000","10.64020","0.03469"
"21342","128.01600","10.66819","0.03517"
"21398","128.35200","10.69617","0.03473"
"21454","128.68800","10.72421","0.03480"
"21510","129.02400","10.75213","0.03606"
"21566","129.36000","10.78023","0.03525"
"21622","129.69600","10.80827","0.03596"
"21678","130.03200","10.83613","0.03613"
"21734","130.36800","10.86424","0.03602"
"21790","130.70400","10.89222","0.03632"
"21846","131.04000","10.92014","0.03605"
"21902","131.37600","10.94818","0.03632"
"21958","131.71200","10.97616","0.03591"
"22014","132.04800","11.00426","0.03666"
"22070","132.38400","11.03224","0.03674"
"22126","132.72000","11.06017","0.03653"
"22182","133.05600","11.08815","0.03702"
"22238","133.39200","11.11619","0.03710"
"22294","133.72800","11.14417","0.03670"
"22350","134.06400","11.17215","0.03661"
"22406","134.40000","11.20019","0.03709"
"22462","134.73600","11.22818","0.03744"
"22518","135.07200","11.25622","0.03755"
"22574","135.40800","11.28414","0.03762"
"22630","135.74400","11.31224","0.03668"
"22686","136.08000","11.34022","0.03657"
"22742","136.41600","11.36820","0.03692"
"22798","136.75200","11.39618","0.03736"
"22854","137.08800","11.42417","0.03763"
"22910","137.42400","11.45221","0.03807"
"22966","137.76000","11.48025","0.03838"
"23022","138.09600","11.50817","0.03864"
"23078","138.43200","11.53621","0.03812"
"23134","138.76800","11.56413","0.03853"
"23190","139.10400","11.59217","0.03860"
"23246","139.44000","11.62022","0.03878"
"23302","139.77600","11.64820","0.03939"
"23358","140.11200","11.67618","0.03922"
"23414","140.44800","11.70422","0.03918"
"23470","140.78400","11.73214","0.03917"
"23526","141.12000","11.76018","0.03950"
"23582","141.45600","11.78816","0.03946"
"23638","141.79200","11.81615","0.03961"
"23694","142.12800","11.84419","0.03985"
"23750","142.46400","11.87223","0.04000"
"23806","142.80000","11.90015","0.04005"
"23862","143.13600","11.92819","0.04020"
"23918","143.47200","11.95617","0.04040"
"23974","143.80800","11.98421","0.04026"
"24030","144.14400","12.01219","0.04073"
"24086","144.48000","12.04018","0.04052"
"24142","144.81600","12.06822","0.04053"
"24198","145.15200","12.09614","0.04093"
"24254","145.48800","12.12424","0.04099"
"24310","145.82400","12.15216","0.04114"
"24366","146.16000","12.18014","0.04143"
"24422","146.49600","12.20819","0.04153"
"24478","146.83200","12.23617","0.04144"
"24534","147.16800","12.26415","0.04126"
"24590","147.50400","12.29219","0.04121"
"24646","147.84000","12.32011","0.04147"
"24702","148.17600","12.34821","0.04135"
"24758","148.51200","12.37619","0.04196"
"24814","148.84800","12.40418","0.04167"
"24870","149.18400","12.43222","0.04188"
"24926","149.52000","12.46014","0.04227"
"24982","149.85600","12.48818","0.04251"
"25038","150.19200","12.51622","0.04254"
"25094","150.52800","12.54414","0.04292"
"25150","150.86400","12.57212","0.04275"
"25206","151.20000","12.60023","0.04326"
"25262","151.53600","12.62815","0.04324"
"25318","151.87200","12.65619","0.04279"
"25374","152.20800","12.68417","0.04350"
"25430","152.54400","12.71215","0.04371"
"25486","152.88000","12.74019","0.04348"
"25542","153.21600","12.76817","0.04358"
"25598","153.55200","12.79622","0.04400"
"25654","153.88800","12.82420","0.04400"
"25710","154.22400","12.85218","0.04446"
"25766","154.56000","12.88016","0.04426"
"25822","154.89600","12.90820","0.04440"
"25878","155.23200","12.93624","0.04495"
"25934","155.56800","12.96416","0.04521"
"25990","155.90400","12.99215","0.03140"
"26046","156.24000","13.02025","0.01107"
"26102","156.57600","13.04817","0.00927"
"26158","156.91200","13.07615","0.00872"
"26214","157.24800","13.10425","0.01021"
"26270","157.58400","13.13217","0.00983"
"26326","157.92000","13.16021","0.01091"
"26382","158.25600","13.18820","0.01104"
"26438","158.59200","13.21612","0.01109"
"26494","158.92800","13.24422","0.01152"
"26550","159.26400","13.27220","0.01055"
"26606","159.60000","13.30018","0.01220"
"26662","159.93600","13.32822","0.01142"
"26718","160.27200","13.35620","0.01349"
"26774","160.60800","13.38413","0.01160"
"26830","160.94400","13.41217","0.01364"
"26886","161.28000","13.44015","0.01246"
"26942","161.61600","13.46819","0.01359"
"26998","161.95200","13.49623","0.01338"
"27054","162.28800","13.52415","0.01349"
"27110","162.62400","13.55220","0.01453"
"27166","162.96000","13.58024","0.01468"
"27222","163.29600","13.60822","0.01571"
"27278","163.63200","13.63620","0.01528"
"27334","163.96800","13.66418","0.01538"
"27390","164.30400","13.69216","0.01532"
"27446","164.64000","13.72020","0.01609"
"27502","164.97600","13.74819","0.01637"
"27558","165.31200","13.77623","0.01557"
"27614","165.64800","13.80415","0.01651"
"27670","165.98400","13.83225","0.01674"
"27726","166.32000","13.86017","0.01733"
"27782","166.65600","13.88809","0.01723"
"27838","166.99200","13.91619","0.01725"
"27894","167.32800","13.94424","0.01755"
"27950","167.66400","13.97216","0.01746"
"28006","168.00000","14.00020","0.01846"
"28062","168.33600","14.02818","0.01737"
"28118","168.67200","14.05616","0.01498"
"28174","169.00800","14.08426","0.01498"
"28230","169.34400","14.11212","0.01543"
"28286","169.68000","14.14022","0.01575"
"28342","170.01600","14.16827","0.01547"
"28398","170.35200","14.19619","0.01579"
"28454","170.68800","14.22417","0.01584"
"28510","171.02400","14.25221","0.01635"
"28566","171.36000","14.28013","0.01590"
"28622","171.69600","14.30823","0.01655"
"28678","172.03200","14.33609","0.01600"
"28734","172.36800","14.36420","0.01678"
"28790","172.70400","14.39218","0.01718"
"28846","173.04000","14.42010","0.01751"
"28902","173.37600","14.44826","0.01643"
"28958","173.71200","14.47618","0.01658"
"29014","174.04800","14.50422","0.01708"
"29070","174.38400","14.53215","0.01698"
"29126","174.72000","14.56019","0.01816"
"29182","175.05600","14.58823","0.01718"
"29238","175.39200","14.61621","0.01712"
"29294","175.72800","14.64419","0.01722"
"29350","176.06400","14.67217","0.01745"
"29406","176.40000","14.70015","0.01759"
"29462","176.73600","14.72820","0.01809"
"29518","177.07200","14.75618","0.01853"
"29574","177.40800","14.78416","0.01866"
"29630","177.74400","14.81220","0.01925"
"29686","178.08000","14.84018","0.01867"
"29742","178.41600","14.86810","0.01921"
"29798","178.75200","14.89626","0.01839"
"29854","179.08800","14.92418","0.01815"
"29910","179.42400","14.95217","0.01847"
"29966","179.76000","14.98027","0.01834"
"30022","180.09600","15.00813","0.01842"
"30078","180.43200","15.03617","0.01893"
"30134","180.76800","15.06421","0.01862"
"30190","181.10400","15.09219","0.01880"
"30246","181.44000","15.12018","0.01831"
"30302","181.77600","15.14816","0.01852"
"30358","182.11200","15.17620","0.01942"
"30414","182.44800","15.20418","0.01985"
"30470","182.78400","15.23216","0.01909"
"30526","183.12000","15.26020","0.01914"
"30582","183.45600","15.28818","0.02038"
"30638","183.79200","15.31617","0.02001"
"30694","184.12800","15.34421","0.02060"
"30750","184.46400","15.37213","0.02025"
"30806","184.80000","15.40017","0.02065"
"30862","185.13600","15.42821","0.02127"
"30918","185.47200","15.45619","0.02097"
"30974","185.80800","15.48423","0.02100"
"31030","186.14400","15.51216","0.02139"
"31086","186.48000","15.54014","0.02105"
"31142","186.81600","15.56824","0.02153"
"31198","187.15200","15.59616","0.02202"
"31254","187.48800","15.62426","0.02241"
"31310","187.82400","15.65224","0.02270"
"31366","188.16000","15.68010","0.02292"
"31422","188.49600","15.70820","0.02239"
"31478","188.83200","15.73619","0.02318"
"31534","189.16800","15.76411","0.02352"
"31590","189.50400","15.79227","0.02351"
"31646","189.84000","15.82019","0.02330"
"31702","190.17600","15.84817","0.02297"
"31758","190.51200","15.87621","0.02358"
"31814","190.84800","15.90413","0.02434"
"31870","191.18400","15.93224","0.02304"
"31926","191.52000","15.96022","0.01702"
"31982","191.85600","15.98814","0.01531"
"32038","192.19200","16.01618","0.01563"
"32094","192.52800","16.04416","0.01551"
"32150","192.86400","16.07220","0.01591"
"32206","193.20000","16.10019","0.01577"
"32262","193.53600","16.12823","0.01654"
"32318","193.87200","16.15627","0.01658"
"32374","194.20800","16.18413","0.01713"
"32430","194.54400","16.21217","0.01636"
"32486","194.88000","16.24021","0.01679"
"32542","195.21600","16.26814","0.01747"
"32598","195.55200","16.29623","0.01732"
"32654","195.88800","16.32422","0.01720"
"32710","196.22400","16.35214","0.01782"
"32766","196.56000","16.38018","0.01716"
"32822","196.89600","16.40822","0.01771"
"32878","197.23200","16.43614","0.01803"
"32934","197.56800","16.46418","0.01754"
"32990","197.90400","16.49217","0.01835"
"33046","198.24000","16.52021","0.01803"
"33102","198.57600","16.54825","0.01868"
"33158","198.91200","16.57611","0.01837"
"33214","199.24800","16.60427","0.01868"
"33270","199.58400","16.63219","0.01905"
"33326","199.92000","16.66017","0.01911"
"33382","200.25600","16.68822","0.01893"
"33438","200.59200","16.71620","0.01916"
"33494","200.92800","16.74418","0.01918"
"33550","201.26400","16.77228","0.01981"
"33606","201.60000","16.80014","0.01948"
"33662","201.93600","16.82818","0.01971"
"33718","202.27200","16.85616","0.02000"
"33774","202.60800","16.88415","0.01974"
"33830","202.94400","16.91219","0.02026"
"33886","203.28000","16.94017","0.02039"
"33942","203.61600","16.96815","0.02109"
"33998","203.95200","16.99619","0.02041"
"34054","204.28800","17.02411","0.02093"
"34110","204.62400","17.05221","0.02056"
"34166","204.96000","17.08019","0.02041"
"34222","205.29600","17.10818","0.02089"
"34278","205.63200","17.13622","0.02114"
"34334","205.96800","17.16414","0.02119"
"34390","206.30400","17.19224","0.02137"
"34446","206.64000","17.22022","0.02168"
"34502","206.97600","17.24814","0.02025"
"34558","207.31200","17.27625","0.02001"
"34614","207.64800","17.30417","0.02020"
"34670","207.98400","17.33215","0.02042"
"34726","208.32000","17.36019","0.02034"
"34782","208.65600","17.38811","0.01965"
"34838","208.99200","17.41621","0.01895"
"34894","209.32800","17.44419","0.01882"
"34950","209.66400","17.47218","0.01932"
"35006","210.00000","17.50022","0.01923"
"35062","210.33600","17.52820","0.01927"
"35118","210.67200","17.55612","0.01939"
"35174","211.00800","17.58422","0.01952"
"35230","211.34400","17.61220","0.02000"
"35286","211.68000","17.64018","0.02008"
"35342","212.01600","17.66817","0.02018"
"35398","212.35200","17.69615","0.02082"
"35454","212.68800","17.72419","0.02043"
"35510","213.02400","17.75223","0.02047"
"35566","213.36000","17.78021","0.02074"
"35622","213.69600","17.80819","0.02042"
"35678","214.03200","17.83617","0.02098"
"35734","214.36800","17.86422","0.02126"
"35790","214.70400","17.89220","0.02138"
"35846","215.04000","17.92012","0.02171"
"35902","215.37600","17.94822","0.02188"
"35958","215.71200","17.97614","0.02168"
"36014","216.04800","18.00418","0.02249"
"36070","216.38400","18.03217","0.02193"
"36126","216.72000","18.06009","0.02250"
"36182","217.05600","18.08819","0.02237"
"36238","217.39200","18.11623","0.02173"
"36294","217.72800","18.14415","0.02169"
"36350","218.06400","18.17225","0.01998"
"36406","218.40000","18.20017","0.02072"
"36462","218.73600","18.22816","0.02062"
"36518","219.07200","18.25626","0.02013"
"36574","219.40800","18.28418","0.02106"
"36630","219.74400","18.31216","0.02062"
"36686","220.08000","18.34026","0.02168"
"36742","220.41600","18.36818","0.02138"
"36798","220.75200","18.39622","0.02155"
"36854","221.08800","18.42414","0.02163"
"36910","221.42400","18.45213","0.02219"
"36966","221.76000","18.48017","0.02222"
"37022","222.09600","18.50815","0.02208"
"37078","222.43200","18.53619","0.02283"
"37134","222.76800","18.56417","0.02305"
"37190","223.10400","18.59221","0.02305"
"37246","223.44000","18.62020","0.02336"
"37302","223.77600","18.64818","0.02316"
"37358","224.11200","18.67622","0.02401"
"37414","224.44800","18.70420","0.02371"
"37470","224.78400","18.73212","0.02431"
"37526","225.12000","18.76022","0.02375"
"37582","225.45600","18.78820","0.02434"
"37638","225.79200","18.81618","0.02417"
"37694","226.12800","18.84423","0.02490"
"37750","226.46400","18.87221","0.02494"
"37806","226.80000","18.90019","0.02470"
"37862","227.13600","18.92817","0.02558"
"37918","227.47200","18.95609","0.02573"
"37974","227.80800","18.98419","0.02496"
"38030","228.14400","19.01224","0.02605"
"38086","228.48000","19.04022","0.02660"
"38142","228.81600","19.06820","0.02704"
"38198","229.15200","19.09618","0.02728"
"38254","229.48800","19.12410","0.02647"
"38310","229.82400","19.15226","0.02721"
"38366","230.16000","19.18018","0.02745"
"38422","230.49600","19.20823","0.02728"
"38478","230.83200","19.23627","0.02704"
"38534","231.16800","19.26419","0.02736"
"38590","231.50400","19.29217","0.02751"
"38646","231.84000","19.32021","0.02743"
"38702","232.17600","19.34819","0.02810"
"38758","232.51200","19.37623","0.02797"
"38814","232.84800","19.40415","0.02882"
"38870","233.18400","19.43220","0.02905"
"38926","233.52000","19.46018","0.02959"
"38982","233.85600","19.48816","0.02948"
"39038","234.19200","19.51620","0.03017"
"39094","234.52800","19.54418","0.03027"
"39150","234.86400","19.57222","0.03066"
"39206","235.20000","19.60015","0.03041"
"39262","235.53600","19.62813","0.03035"
"39318","235.87200","19.65623","0.03142"
"39374","236.20800","19.68421","0.03155"
"39430","236.54400","19.71219","0.03151"
"39486","236.88000","19.74023","0.03166"
"39542","237.21600","19.76815","0.01683"
"39598","237.55200","19.79613","0.01364"
"39654","237.88800","19.82418","0.01356"
"39710","238.22400","19.85216","0.01264"
"39766","238.56000","19.88020","0.01371"
"39822","238.89600","19.90824","0.01462"
"39878","239.23200","19.93616","0.01507"
"39934","239.56800","19.96420","0.01477"
"39990","239.90400","19.99218","0.01464"
"40046","240.24000","20.02017","0.01457"
"40102","240.57600","20.04821","0.01544"
"40158","240.91200","20.07607","0.01508"
"40214","241.24800","20.10423","0.01667"
"40270","241.58400","20.13215","0.01583"
"40326","241.92000","20.16014","0.01652"
"40382","242.25600","20.18818","0.01633"
"40438","242.59200","20.21622","0.01587"
"40494","242.92800","20.24420","0.01590"
"40550","243.26400","20.27218","0.01656"
"40606","243.60000","20.30016","0.01644"
"40662","243.93600","20.32820","0.01705"
"40718","244.27200","20.35624","0.01688"
"40774","244.60800","20.38423","0.01730"
"40830","244.94400","20.41221","0.01596"
"40886","245.28000","20.44013","0.01600"
"40942","245.61600","20.46817","0.01561"
"40998","245.95200","20.49621","0.01618"
"41054","246.28800","20.52413","0.01635"
"41110","246.62400","20.55223","0.01596"
"41166","246.96000","20.58015","0.01639"
"41222","247.29600","20.60814","0.01663"
"41278","247.63200","20.63624","0.01703"
"41334","247.96800","20.66422","0.01718"
"41390","248.30400","20.69214","0.01692"
"41446","248.64000","20.72024","0.01759"
"41502","248.97600","20.74810","0.01746"
"41558","249.31200","20.77621","0.01626"
"41614","249.64800","20.80419","0.01609"
"41670","249.98400","20.83217","0.01687"
"41726","250.32000","20.86021","0.01692"
"41782","250.65600","20.88819","0.01705"
"41838","250.99200","20.91617","0.01625"
"41894","251.32800","20.94421","0.01703"
"41950","251.66400","20.97219","0.01701"
"42006","252.00000","21.00024","0.01720"
"42062","252.33600","21.02822","0.01723"
"42118","252.67200","21.05614","0.01743"
"42174","253.00800","21.08418","0.01763"
"42230","253.34400","21.11216","0.01752"
"42286","253.68000","21.14014","0.01801"
"42342","254.01600","21.16825","0.01768"
"42398","254.35200","21.19617","0.01789"
"42454","254.68800","21.22421","0.01764"
"42510","255.02400","21.25213","0.01755"
"42566","255.36000","21.28017","0.01784"
"42622","255.69600","21.30821","0.01773"
"42678","256.03200","21.33613","0.01805"
"42734","256.36800","21.36423","0.01797"
"42790","256.70400","21.39222","0.01809"
"42846","257.04000","21.42014","0.01819"
"42902","257.37600","21.44824","0.01766"
"42958","257.71200","21.47622","0.01785"
"43014","258.04800","21.50414","0.01776"
"43070","258.38400","21.53225","0.01860"
"43126","258.72000","21.56017","0.01865"
"43182","259.05600","21.58815","0.01842"
"43238","259.39200","21.61625","0.01849"
"43294","259.72800","21.64411","0.01841"
"43350","260.06400","21.67221","0.01864"
"43406","260.40000","21.70019","0.01854"
"43462","260.73600","21.72817","0.01920"
"43518","261.07200","21.75615","0.01870"
"43574","261.40800","21.78419","0.01971"
"43630","261.74400","21.81218","0.01958"
"43686","262.08000","21.84022","0.01930"
"43742","262.41600","21.86820","0.01983"
"43798","262.75200","21.89624","0.01991"
"43854","263.08800","21.92416","0.01952"
"43910","263.42400","21.95215","0.01984"
"43966","263.76000","21.98018","0.02092"
"44022","264.09600","22.00817","0.02045"
"44078","264.43200","22.03621","0.02018"
"44134","264.76800","22.06425","0.02074"
"44190","265.10400","22.09211","0.02141"
"44246","265.44000","22.12021","0.02091"
"44302","265.77600","22.14819","0.02141"
"44358","266.11200","22.17618","0.02064"
"44414","266.44800","22.20422","0.02125"
"44470","266.78400","22.23214","0.02122"
"44526","267.12000","22.26018","0.02127"
"44582","267.45600","22.28822","0.02097"
"44638","267.79200","22.31608","0.02169"
"44694","268.12800","22.34425","0.02250"
"44750","268.46400","22.37217","0.02137"
"44806","268.80000","22.40015","0.02112"
"44862","269.13600","22.42819","0.02135"
"44918","269.47200","22.45617","0.02185"
"44974","269.80800","22.48421","0.02191"
"45030","270.14400","22.51225","0.02163"
"45086","270.48000","22.54018","0.02192"
"45142","270.81600","22.56816","0.02262"
"45198","271.15200","22.59620","0.02263"
"45254","271.48800","22.62418","0.02298"
"45310","271.82400","22.65216","0.02311"
"45366","272.16000","22.68020","0.02344"
"45422","272.49600","22.70819","0.02287"
"45478","272.83200","22.73617","0.02291"
"45534","273.16800","22.76421","0.02300"
"45590","273.50400","22.79219","0.02410"
"45646","273.84000","22.82017","0.02325"
"45702","274.17600","22.84815","0.02365"
"45758","274.51200","22.87619","0.02332"
"45814","274.84800","22.90411","0.02399"
"45870","275.18400","22.93227","0.02337"
"45926","275.52000","22.96026","0.02433"
"45982","275.85600","22.98812","0.02401"
"46038","276.19200","23.01622","0.02465"
"46094","276.52800","23.04414","0.02425"
"46150","276.86400","23.07212","0.02478"
"46206","277.20000","23.10023","0.02447"
"46262","277.53600","23.12815","0.02520"
"46318","277.87200","23.15619","0.02535"
"46374","278.20800","23.18423","0.02534"
"46430","278.54400","23.21209","0.02587"
"46486","278.88000","23.24019","0.02616"
"46542","279.21600","23.26823","0.02630"
"46598","279.55200","23.29616","0.02316"
"46654","279.88800","23.32420","0.02423"
"46710","280.22400","23.35218","0.02411"
"46766","280.56000","23.38016","0.02387"
"46822","280.89600","23.40820","0.02480"
"46878","281.23200","23.43618","0.02452"
"46934","281.56800","23.46422","0.02441"
"46990","281.90400","23.49220","0.02444"
"47046","282.24000","23.52019","0.02536"
"47102","282.57600","23.54817","0.02495"
"47158","282.91200","23.57615","0.02479"
"47214","283.24800","23.60419","0.02319"
"47270","283.58400","23.63223","0.02381"
"47326","283.92000","23.66015","0.02363"
"47382","284.25600","23.68819","0.02392"
"47438","284.59200","23.71618","0.02427"
"47494","284.92800","23.74416","0.02409"
"47550","285.26400","23.77220","0.02510"
"47606","285.60000","23.80018","0.02537"
"47662","285.93600","23.82822","0.02482"
"47718","286.27200","23.85620","0.02468"
"47774","286.60800","23.88412","0.02552"
"47830","286.94400","23.91223","0.02571"
"47886","287.28000","23.94015","0.02593"
"47942","287.61600","23.96819","0.02577"
"47998","287.95200","23.99623","0.02622"
"48054","288.28800","24.02415","0.02700"
"48110","288.62400","24.05219","0.02627"
"48166","288.96000","24.08024","0.02660"
"48222","289.29600","24.10816","0.02730"
"48278","289.63200","24.13620","0.02671"
"48334","289.96800","24.16418","0.02744"
"48390","290.30400","24.19216","0.02736"
"48446","290.64000","24.22020","0.02775"
"48502","290.97600","24.24818","0.02871"
"48558","291.31200","24.27616","0.02829"
"48614","291.64800","24.30420","0.02834"
"48670","291.98400","24.33219","0.02865"
"48726","292.32000","24.36017","0.02818"
"48782","292.65600","24.38821","0.02859"
"48838","292.99200","24.41619","0.02663"
"48894","293.32800","24.44423","0.02726"
"48950","293.66400","24.47216","0.02745"
"49006","294.00000","24.50026","0.02723"
"49062","294.33600","24.52824","0.02718"
"49118","294.67200","24.55616","0.02820"
"49174","295.00800","24.58420","0.02812"
"49230","295.34400","24.61218","0.02837"
"49286","295.68000","24.64017","0.02890"
"49342","296.01600","24.66820","0.02906"
"49398","296.35200","24.69613","0.02878"
"49454","296.68800","24.72423","0.02933"
"49510","297.02400","24.75221","0.02967"
"49566","297.36000","24.78025","0.02942"
"49622","297.69600","24.80823","0.02998"
"49678","298.03200","24.83615","0.03049"
"49734","298.36800","24.86413","0.03069"
"49790","298.70400","24.89218","0.03068"
"49846","299.04000","24.92016","0.03081"
"49902","299.37600","24.94820","0.03093"
"49958","299.71200","24.97624","0.03169"
"50014","300.04800","25.00410","0.03116"
"50070","300.38400","25.03220","0.03115"
"50126","300.72000","25.06024","0.03189"
"50182","301.05600","25.08823","0.03168"
"50238","301.39200","25.11621","0.03215"
"50294","301.72800","25.14419","0.03178"
"50350","302.06400","25.17217","0.03104"
"50406","302.40000","25.20015","0.03147"
"50462","302.73600","25.22813","0.03243"
"50518","303.07200","25.25617","0.03165"
"50574","303.40800","25.28422","0.03238"
"50630","303.74400","25.31226","0.03186"
"50686","304.08000","25.34012","0.03207"
"50742","304.41600","25.36810","0.03228"
"50798","304.75200","25.39620","0.03276"
"50854","305.08800","25.42424","0.03258"
"50910","305.42400","25.45223","0.03263"
"50966","305.76000","25.48027","0.03308"
"51022","306.09600","25.50819","0.03342"
"51078","306.43200","25.53617","0.03339"
"51134","306.76800","25.56421","0.03373"
"51190","307.10400","25.59213","0.03368"
"51246","307.44000","25.62024","0.03312"
"51302","307.77600","25.64821","0.03373"
"51358","308.11200","25.67614","0.03383"
"51414","308.44800","25.70418","0.03463"
"51470","308.78400","25.73216","0.03466"
"51526","309.12000","25.76014","0.03448"
"51582","309.45600","25.78824","0.03445"
"51638","309.79200","25.81616","0.03503"
"51694","310.12800","25.84421","0.03078"
"51750","310.46400","25.87219","0.03159"
"51806","310.80000","25.90017","0.03114"
"51862","311.13600","25.92821","0.03220"
"51918","311.47200","25.95619","0.03174"
"51974","311.80800","25.98417","0.03279"
"52030","312.14400","26.01215","0.03173"
"52086","312.48000","26.04013","0.03233"
"52142","312.81600","26.06817","0.03266"
"52198","313.15200","26.09622","0.03290"
"52254","313.48800","26.12420","0.03303"
"52310","313.82400","26.15218","0.03376"
"52366","314.16000","26.18016","0.03333"
"52422","314.49600","26.20820","0.03394"
"52478","314.83200","26.23619","0.03390"
"52534","315.16800","26.26411","0.03422"
"52590","315.50400","26.29221","0.03428"
"52646","315.84000","26.32019","0.03460"
"52702","316.17600","26.34817","0.03442"
"52758","316.51200","26.37621","0.03504"
"52814","316.84800","26.40413","0.03507"
"52870","317.18400","26.43212","0.03537"
"52926","317.52000","26.46021","0.03536"
"52982","317.85600","26.48820","0.03550"
"53038","318.19200","26.51618","0.03554"
"53094","318.52800","26.54422","0.03603"
"53150","318.86400","26.57214","0.03546"
"53206","319.20000","26.60018","0.03596"
"53262","319.53600","26.62817","0.03593"
"53318","319.87200","26.65615","0.03569"
"53374","320.20800","26.68419","0.03607"
"53430","320.54400","26.71217","0.03643"
"53486","320.88000","26.74021","0.03643"
"53542","321.21600","26.76819","0.03611"
"53598","321.55200","26.79612","0.03658"
"53654","321.88800","26.82421","0.03608"
"53710","322.22400","26.85220","0.03639"
"53766","322.56000","26.88018","0.03669"
"53822","322.89600","26.90822","0.03692"
"53878","323.23200","26.93614","0.03693"
"53934","323.56800","26.96418","0.03700"
"53990","323.90400","26.99216","0.03687"
"54046","324.24000","27.02015","0.03695"
"54102","324.57600","27.04819","0.03727"
"54158","324.91200","27.07617","0.03727"
"54214","325.24800","27.10421","0.03712"
"54270","325.58400","27.13225","0.03704"
"54326","325.92000","27.16011","0.03650"
"54382","326.25600","27.18821","0.03733"
"54438","326.59200","27.21620","0.03666"
"54494","326.92800","27.24418","0.03699"
"54550","327.26400","27.27222","0.03759"
"54606","327.60000","27.30014","0.03718"
"54662","327.93600","27.32818","0.03738"
"54718","328.27200","27.35622","0.03724"
"54774","328.60800","27.38414","0.03738"
"54830","328.94400","27.41219","0.03704"
"54886","329.28000","27.44017","0.03719"
"54942","329.61600","27.46815","0.03746"
"54998","329.95200","27.49619","0.03700"
"55054","330.28800","27.52417","0.03693"
"55110","330.62400","27.55221","0.03721"
"55166","330.96000","27.58020","0.03745"
"55222","331.29600","27.60818","0.03774"
"55278","331.63200","27.63622","0.03739"
"55334","331.96800","27.66420","0.03756"
"55390","332.30400","27.69218","0.03745"
"55446","332.64000","27.72016","0.03739"
"55502","332.97600","27.74821","0.03753"
"55558","333.31200","27.77625","0.03756"
"55614","333.64800","27.80429","0.03751"
"55670","333.98400","27.83215","0.03768"
"55726","334.32000","27.86019","0.03775"
"55782","334.65600","27.88817","0.03790"
"55838","334.99200","27.91615","0.03765"
"55894","335.32800","27.94425","0.03730"
"55950","335.66400","27.97211","0.03779"
"56006","336.00000","28.00022","0.03752"
"56062","336.33600","28.02826","0.03764"
"56118","336.67200","28.05612","0.03767"
"56174","337.00800","28.08422","0.03763"
"56230","337.34400","28.11220","0.03758"
"56286","337.68000","28.14012","0.03770"
"56342","338.01600","28.16822","0.03769"
"56398","338.35200","28.19621","0.03818"
"56454","338.68800","28.22419","0.03754"
"56510","339.02400","28.25217","0.03765"
"56566","339.36000","28.28015","0.03696"
"56622","339.69600","28.30819","0.03730"
"56678","340.03200","28.33624","0.03709"
"56734","340.36800","28.36421","0.03731"
"56790","340.70400","28.39220","0.03738"
"56846","341.04000","28.42018","0.03712"
"56902","341.37600","28.44810","0.03752"
"56958","341.71200","28.47620","0.03741"
"57014","342.04800","28.50412","0.03737"
"57070","342.38400","28.53216","0.03736"
"57126","342.72000","28.56021","0.03731"
"57182","343.05600","28.58818","0.03763"
"57238","343.39200","28.61623","0.03781"
"57294","343.72800","28.64415","0.03798"
"57350","344.06400","28.67225","0.03815"
"57406","344.40000","28.70023","0.03791"
"57462","344.73600","28.72815","0.03840"
"57518","345.07200","28.75625","0.03820"
"57574","345.40800","28.78418","0.03800"
"57630","345.74400","28.81216","0.03867"
"57686","346.08000","28.84020","0.03859"
"57742","346.41600","28.86824","0.03865"
"57798","346.75200","28.89622","0.03847"
"57854","347.08800","28.92420","0.03896"
"57910","347.42400","28.95206","0.03915"
"57966","347.76000","28.98022","0.03874"
"58022","348.09600","29.00821","0.03921"
"58078","348.43200","29.03619","0.03873"
"58134","348.76800","29.06423","0.03871"
"58190","349.10400","29.09215","0.03866"
"58246","349.44000","29.12013","0.03911"
"58302","349.77600","29.14824","0.03941"
"58358","350.11200","29.17616","0.03910"
"58414","350.44800","29.20420","0.03842"
"58470","350.78400","29.23224","0.03740"
"58526","351.12000","29.26016","0.03785"
"58582","351.45600","29.28820","0.03842"
"58638","351.79200","29.31618","0.03887"
"58694","352.12800","29.34422","0.03893"
"58750","352.46400","29.37221","0.03860"
"58806","352.80000","29.40019","0.03853"
"58862","353.13600","29.42823","0.03876"
"58918","353.47200","29.45621","0.03919"
"58974","353.80800","29.48413","0.03936"
"59030","354.14400","29.51223","0.03953"
"59086","354.48000","29.54021","0.03952"
"59142","354.81600","29.56820","0.03964"
"59198","355.15200","29.59618","0.03979"
"59254","355.48800","29.62416","0.03977"
"59310","355.82400","29.65220","0.04039"
"59366","356.16000","29.68018","0.04041"
"59422","356.49600","29.70817","0.04042"
"59478","356.83200","29.73626","0.04092"
"59534","357.16800","29.76413","0.04084"
"59590","357.50400","29.79217","0.04090"
"59646","357.84000","29.82021","0.04071"
"59702","358.17600","29.84813","0.04109"
"59758","358.51200","29.87617","0.04099"
"59814","358.84800","29.90421","0.04138"
"59870","359.18400","29.93220","0.04122"
"59926","359.52000","29.96024","0.04159"
"59982","359.85600","29.98816","0.04179"
"60038","360.19200","30.01614","0.04151"
"60094","360.52800","30.04418","0.04211"
"60150","360.86400","30.07216","0.04225"
"60206","361.20000","30.10021","0.04262"
"60262","361.53600","30.12819","0.04264"
"60318","361.87200","30.15617","0.04247"
"60374","362.20800","30.18421","0.03843"
"60430","362.54400","30.21213","0.03744"
"60486","362.88000","30.24023","0.03682"
"60542","363.21600","30.26822","0.03764"
"60598","363.55200","30.29613","0.03912"
"60654","363.88800","30.32424","0.03964"
"60710","364.22400","30.35216","0.04025"
"60766","364.56000","30.38020","0.03991"
"60822","364.89600","30.40818","0.03972"
"60878","365.23200","30.43610","0.03946"
"60934","365.56800","30.46420","0.04005"
"60990","365.90400","30.49224","0.04033"
"61046","366.24000","30.52017","0.04090"
"61102","366.57600","30.54821","0.04114"
"61158","366.91200","30.57619","0.04130"
"61214","367.24800","30.60417","0.04130"
"61270","367.58400","30.63221","0.04149"
"61326","367.92000","30.66013","0.04178"
"61382","368.25600","30.68818","0.04175"
"61438","368.59200","30.71628","0.04177"
"61494","368.92800","30.74414","0.04247"
"61550","369.26400","30.77218","0.04231"
"61606","369.60000","30.80016","0.04222"
"61662","369.93600","30.82820","0.04215"
"61718","370.27200","30.85625","0.04256"
"61774","370.60800","30.88416","0.04267"
"61830","370.94400","30.91221","0.04301"
"61886","371.28000","30.94019","0.04294"
"61942","371.61600","30.96823","0.04337"
"61998","371.95200","30.99621","0.04354"
"62054","372.28800","31.02413","0.04397"
"62110","372.62400","31.05217","0.04409"
"62166","372.96000","31.08015","0.04369"
"62222","373.29600","31.10814","0.04400"
"62278","373.63200","31.13624","0.04458"
"62334","373.96800","31.16422","0.04447"
"62390","374.30400","31.19214","0.04500"
"62446","374.64000","31.22024","0.04489"
"62502","374.97600","31.24822","0.04506"
"62558","375.31200","31.27614","0.04491"
"62614","375.64800","31.30418","0.04536"
"62670","375.98400","31.33211","0.04568"
"62726","376.32000","31.36021","0.04557"
"62782","376.65600","31.38825","0.04617"
"62838","376.99200","31.41611","0.04624"
"62894","377.32800","31.44415","0.04670"
"62950","377.66400","31.47219","0.04702"
"63006","378.00000","31.50018","0.04732"
"63062","378.33600","31.52822","0.04744"
"63118","378.67200","31.55614","0.04764"
"63174","379.00800","31.58418","0.04884"
"63230","379.34400","31.61222","0.04922"
"63286","379.68000","31.64020","0.04971"
"63342","380.01600","31.66824","0.05036"
"63398","380.35200","31.69622","0.05064"
"63454","380.68800","31.72415","0.04964"
"63510","381.02400","31.75219","0.04938"
"63566","381.36000","31.78017","0.04987"
"63622","381.69600","31.80821","0.05061"
"63678","382.03200","31.83619","0.05035"
"63734","382.36800","31.86417","0.05097"
"63790","382.70400","31.89215","0.05182"
"63846","383.04000","31.92014","0.05239"
"63902","383.37600","31.94824","0.05379"
"63958","383.71200","31.97622","0.05381"
"64014","384.04800","32.00414","0.05475"
"64070","384.38400","32.03218","0.05573"
"64126","384.72000","32.06017","0.05623"
"64182","385.05600","32.08815","0.05711"
"64238","385.39200","32.11618","0.05720"
"64294","385.72800","32.14417","0.05807"
"64350","386.06400","32.17215","0.05933"
"64406","386.40000","32.20019","0.05981"
"64462","386.73600","32.22817","0.05891"
"64518","387.07200","32.25621","0.06026"
"64574","387.40800","32.28419","0.06099"
"64630","387.74400","32.31218","0.06177"
"64686","388.08000","32.34016","0.06326"
"64742","388.41600","32.36814","0.06423"
"64798","388.75200","32.39612","0.06530"
"64854","389.08800","32.42422","0.06631"
"64910","389.42400","32.45214","0.06683"
"64966","389.76000","32.48024","0.06791"
"65022","390.09600","32.50816","0.06874"
"65078","390.43200","32.53615","0.06979"
"65134","390.76800","32.56425","0.07086"
"65190","391.10400","32.59217","0.07066"
"65246","391.44000","32.62021","0.07224"
"65302","391.77600","32.64819","0.07298"
"65358","392.11200","32.67617","0.07366"
"65414","392.44800","32.70415","0.07478"
"65470","392.78400","32.73220","0.07365"
"65526","393.12000","32.76018","0.07436"
"65582","393.45600","32.78822","0.07557"
"65638","393.79200","32.81620","0.07691"
"65694","394.12800","32.84418","0.07827"
"65750","394.46400","32.87223","0.07920"
"65806","394.80000","32.90009","0.08099"
"65862","395.13600","32.92825","0.08192"
"65918","395.47200","32.95623","0.08181"
"65974","395.80800","32.98415","0.08210"
"66030","396.14400","33.01219","0.08261"
"66086","396.48000","33.04017","0.08416"
"66142","396.81600","33.06815","0.08607"
"66198","397.15200","33.09626","0.08665"
"66254","397.48800","33.12418","0.08748"
"66310","397.82400","33.15216","0.08896"
"66366","398.16000","33.18014","0.08942"
"66422","398.49600","33.20813","0.08947"
"66478","398.83200","33.23616","0.08981"
"66534","399.16800","33.26414","0.08900"
"66590","399.50400","33.29224","0.08927"
"66646","399.84000","33.32023","0.09056"
"66702","400.17600","33.34815","0.09088"
"66758","400.51200","33.37619","0.09138"
"66814","400.84800","33.40417","0.09189"
"66870","401.18400","33.43216","0.09210"
"66926","401.52000","33.46020","0.09260"
"66982","401.85600","33.48818","0.09310"
"67038","402.19200","33.51622","0.09386"
"67094","402.52800","33.54420","0.09473"
"67150","402.86400","33.57212","0.09473"
"67206","403.20000","33.60016","0.09633"
"67262","403.53600","33.62820","0.09737"
"67318","403.87200","33.65619","0.09772"
"67374","404.20800","33.68423","0.09982"
"67430","404.54400","33.71209","0.10069"
"67486","404.88000","33.74019","0.10179"
"67542","405.21600","33.76823","0.10202"
"67598","405.55200","33.79615","0.10364"
"67654","405.88800","33.82425","0.10528"
"67710","406.22400","33.85218","0.10681"
"67766","406.56000","33.88015","0.10804"
"67822","406.89600","33.90820","0.10915"
"67878","407.23200","33.93618","0.11019"
"67934","407.56800","33.96416","0.11007"
"67990","407.90400","33.99226","0.11212"
"68046","408.24000","34.02013","0.11436"
"68102","408.57600","34.04816","0.11518"
"68158","408.91200","34.07621","0.11656"
"68214","409.24800","34.10413","0.00903"
"68270","409.58400","34.13217","0.00521"
"68326","409.92000","34.16021","0.00260"
"68382","410.25600","34.18819","0.00280"
"68438","410.59200","34.21623","0.00540"
"68494","410.92800","34.24416","0.00469"
"68550","411.26400","34.27220","0.00481"
"68606","411.60000","34.30018","0.00413"
"68662","411.93600","34.32816","0.00459"
"68718","412.27200","34.35620","0.00488"
"68774","412.60800","34.38412","0.00439"
"68830","412.94400","34.41222","0.00527"
"68886","413.28000","34.44027","0.00512"
"68942","413.61600","34.46819","0.00452"
"68998","413.95200","34.49623","0.00470"
"69054","414.28800","34.52415","0.00298"
"69110","414.62400","34.55219","0.00478"
"69166","414.96000","34.58017","0.00491"
"69222","415.29600","34.60815","0.00450"
"69240","415.40000","34.61688","0.00427"