File: Trajectories_together/170226_3Specimen_RawData_6.csv
"","V1","V2","V3"
"1","End date","2/26/2017",""
"2","Specimen label","4CT_32_pl",""
"3","Maximum Load","0.14378","N"
"4","Time","Extension","Load"
"5","(s)","(mm)","(N)"
"6","0.00000","0.00000","0.00022"
"13","0.04200","0.00060","0.00043"
"20","0.08400","0.00275","0.00072"
"27","0.12600","0.00628","0.00105"
"34","0.16800","0.01064","0.00082"
"41","0.21000","0.01525","0.00021"
"48","0.25200","0.01973","0.00061"
"55","0.29400","0.02404","-0.00060"
"62","0.33600","0.02792","-0.00004"
"69","0.37800","0.03169","0.00059"
"76","0.42000","0.03528","-0.00004"
"83","0.46200","0.03874","0.00010"
"90","0.50400","0.04221","-0.00003"
"97","0.54600","0.04574","-0.00029"
"104","0.58800","0.04927","0.00071"
"111","0.63000","0.05273","0.00036"
"118","0.67200","0.05632","0.00017"
"125","0.71400","0.05979","0.00035"
"132","0.75600","0.06320","0.00031"
"139","0.79800","0.06673","0.00017"
"146","0.84000","0.07025","0.00013"
"153","0.88200","0.07378","0.00077"
"160","0.92400","0.07719","0.00100"
"167","0.96600","0.08072","0.00048"
"174","1.00800","0.08418","0.00045"
"181","1.05000","0.08765","-0.00028"
"188","1.09200","0.09118","0.00050"
"195","1.13400","0.09471","0.00078"
"202","1.17600","0.09823","0.00062"
"209","1.21800","0.10170","0.00023"
"216","1.26000","0.10523","0.00138"
"223","1.30200","0.10876","0.00093"
"230","1.34400","0.11222","0.00074"
"237","1.38600","0.11569","-0.00032"
"244","1.42800","0.11922","0.00050"
"251","1.47000","0.12269","0.00066"
"258","1.51200","0.12622","0.00050"
"265","1.55400","0.12968","0.00051"
"272","1.59600","0.13315","0.00018"
"279","1.63800","0.13668","0.00108"
"286","1.68000","0.14021","0.00082"
"293","1.72200","0.14373","0.00082"
"300","1.76400","0.14720","0.00039"
"307","1.80600","0.15073","0.00023"
"314","1.84800","0.15420","0.00015"
"321","1.89000","0.15766","0.00032"
"328","1.93200","0.16119","0.00049"
"335","1.97400","0.16466","0.00060"
"342","2.01600","0.16813","0.00029"
"349","2.05800","0.17166","0.00055"
"356","2.10000","0.17512","0.00104"
"363","2.14200","0.17865","0.00106"
"370","2.18400","0.18218","0.00067"
"377","2.22600","0.18571","0.00007"
"384","2.26800","0.18923","0.00050"
"391","2.31000","0.19276","0.00059"
"398","2.35200","0.19623","0.00014"
"405","2.39400","0.19976","0.00056"
"412","2.43600","0.20322","0.00073"
"419","2.47800","0.20669","0.00048"
"426","2.52000","0.21016","0.00082"
"433","2.56200","0.21369","0.00018"
"440","2.60400","0.21722","0.00066"
"447","2.64600","0.22062","0.00061"
"454","2.68800","0.22415","0.00042"
"461","2.73000","0.22774","0.00063"
"468","2.77200","0.23121","0.00048"
"475","2.81400","0.23473","0.00086"
"482","2.85600","0.23826","0.00048"
"489","2.89800","0.24173","0.00090"
"496","2.94000","0.24520","0.00045"
"503","2.98200","0.24872","0.00054"
"510","3.02400","0.25225","0.00055"
"517","3.06600","0.25572","0.00102"
"524","3.10800","0.25919","0.00089"
"531","3.15000","0.26266","0.00087"
"538","3.19200","0.26618","0.00077"
"545","3.23400","0.26965","0.00054"
"552","3.27600","0.27318","0.00130"
"559","3.31800","0.27671","0.00129"
"566","3.36000","0.28023","0.00090"
"573","3.40200","0.28370","0.00077"
"580","3.44400","0.28723","0.00123"
"587","3.48600","0.29070","0.00040"
"594","3.52800","0.29422","0.00138"
"601","3.57000","0.29769","0.00076"
"608","3.61200","0.30122","0.00086"
"615","3.65400","0.30469","0.00058"
"622","3.69600","0.30816","0.00052"
"629","3.73800","0.31168","0.00099"
"636","3.78000","0.31521","0.00105"
"643","3.82200","0.31868","0.00078"
"650","3.86400","0.32227","0.00035"
"657","3.90600","0.32579","0.00070"
"664","3.94800","0.32920","0.00067"
"671","3.99000","0.33273","0.00095"
"678","4.03200","0.33626","0.00055"
"685","4.07400","0.33966","0.00168"
"692","4.11600","0.34313","0.00160"
"699","4.15800","0.34666","0.00105"
"706","4.20000","0.35019","0.00069"
"713","4.24200","0.35366","0.00062"
"720","4.28400","0.35712","0.00064"
"727","4.32600","0.36071","0.00085"
"734","4.36800","0.36418","0.00082"
"741","4.41000","0.36771","0.00099"
"748","4.45200","0.37129","0.00136"
"755","4.49400","0.37476","0.00126"
"762","4.53600","0.37823","0.00103"
"769","4.57800","0.38176","0.00062"
"776","4.62000","0.38522","0.00100"
"783","4.66200","0.38869","0.00081"
"790","4.70400","0.39216","0.00118"
"797","4.74600","0.39569","0.00169"
"804","4.78800","0.39915","0.00128"
"811","4.83000","0.40262","0.00074"
"818","4.87200","0.40621","0.00122"
"825","4.91400","0.40968","0.00048"
"832","4.95600","0.41321","0.00056"
"839","4.99800","0.41673","0.00135"
"846","5.04000","0.42026","0.00121"
"853","5.08200","0.42373","0.00112"
"860","5.12400","0.42720","0.00138"
"867","5.16600","0.43072","0.00148"
"874","5.20800","0.43419","0.00107"
"881","5.25000","0.43766","0.00098"
"888","5.29200","0.44119","0.00121"
"895","5.33400","0.44465","0.00104"
"902","5.37600","0.44812","0.00102"
"909","5.41800","0.45165","0.00187"
"916","5.46000","0.45524","0.00151"
"923","5.50200","0.45877","0.00097"
"930","5.54400","0.46223","0.00115"
"937","5.58600","0.46576","0.00078"
"944","5.62800","0.46923","0.00121"
"951","5.67000","0.47270","0.00098"
"958","5.71200","0.47616","0.00135"
"965","5.75400","0.47969","0.00161"
"972","5.79600","0.48322","0.00117"
"979","5.83800","0.48663","0.00152"
"986","5.88000","0.49015","0.00166"
"993","5.92200","0.49368","0.00152"
"1000","5.96400","0.49721","0.00170"
"1007","6.00600","0.50068","0.00122"
"1014","6.04800","0.50426","0.00138"
"1021","6.09000","0.50773","0.00126"
"1028","6.13200","0.51120","0.00096"
"1035","6.17400","0.51473","0.00106"
"1042","6.21600","0.51826","0.00160"
"1049","6.25800","0.52166","0.00100"
"1056","6.30000","0.52519","0.00144"
"1063","6.34200","0.52866","0.00119"
"1070","6.38400","0.53213","0.00085"
"1077","6.42600","0.53559","0.00186"
"1084","6.46800","0.53918","0.00134"
"1091","6.51000","0.54265","0.00097"
"1098","6.55200","0.54618","0.00142"
"1105","6.59400","0.54970","0.00177"
"1112","6.63600","0.55323","0.00142"
"1119","6.67800","0.55670","0.00174"
"1126","6.72000","0.56023","0.00096"
"1133","6.76200","0.56376","0.00152"
"1140","6.80400","0.56716","0.00131"
"1147","6.84600","0.57069","0.00118"
"1154","6.88800","0.57416","0.00185"
"1161","6.93000","0.57763","0.00212"
"1168","6.97200","0.58115","0.00233"
"1175","7.01400","0.58468","0.00179"
"1182","7.05600","0.58821","0.00193"
"1189","7.09800","0.59174","0.00187"
"1196","7.14000","0.59520","0.00132"
"1203","7.18200","0.59873","0.00118"
"1210","7.22400","0.60220","0.00126"
"1217","7.26600","0.60579","0.00167"
"1224","7.30800","0.60926","0.00203"
"1231","7.35000","0.61272","0.00146"
"1238","7.39200","0.61619","0.00215"
"1245","7.43400","0.61972","0.00172"
"1252","7.47600","0.62319","0.00154"
"1259","7.51800","0.62671","0.00179"
"1266","7.56000","0.63018","0.00177"
"1273","7.60200","0.63371","0.00145"
"1280","7.64400","0.63724","0.00148"
"1287","7.68600","0.64070","0.00210"
"1294","7.72800","0.64423","0.00197"
"1301","7.77000","0.64776","0.00187"
"1308","7.81200","0.65123","0.00150"
"1315","7.85400","0.65470","0.00146"
"1322","7.89600","0.65822","0.00144"
"1329","7.93800","0.66169","0.00152"
"1336","7.98000","0.66516","0.00184"
"1343","8.02200","0.66863","0.00158"
"1350","8.06400","0.67221","0.00200"
"1357","8.10600","0.67568","0.00161"
"1364","8.14800","0.67921","0.00205"
"1371","8.19000","0.68274","0.00212"
"1378","8.23200","0.68620","0.00136"
"1385","8.27400","0.68967","0.00158"
"1392","8.31600","0.69320","0.00213"
"1399","8.35800","0.69673","0.00154"
"1406","8.40000","0.70020","0.00211"
"1413","8.44200","0.70366","0.00282"
"1420","8.48400","0.70719","0.00229"
"1427","8.52600","0.71060","0.00190"
"1434","8.56800","0.71413","0.00222"
"1441","8.61000","0.71771","0.00231"
"1448","8.65200","0.72124","0.00219"
"1455","8.69400","0.72471","0.00164"
"1462","8.73600","0.72824","0.00164"
"1469","8.77800","0.73176","0.00189"
"1476","8.82000","0.73517","0.00224"
"1483","8.86200","0.73870","0.00168"
"1490","8.90400","0.74223","0.00201"
"1497","8.94600","0.74575","0.00182"
"1504","8.98800","0.74922","0.00242"
"1511","9.03000","0.75275","0.00205"
"1518","9.07200","0.75622","0.00229"
"1525","9.11400","0.75969","0.00204"
"1532","9.15600","0.76321","0.00233"
"1539","9.19800","0.76674","0.00234"
"1546","9.24000","0.77021","0.00207"
"1553","9.28200","0.77374","0.00223"
"1560","9.32400","0.77726","0.00243"
"1567","9.36600","0.78073","0.00212"
"1574","9.40800","0.78426","0.00186"
"1581","9.45000","0.78773","0.00133"
"1588","9.49200","0.79125","0.00194"
"1595","9.53400","0.79472","0.00293"
"1602","9.57600","0.79819","0.00195"
"1609","9.61800","0.80166","0.00220"
"1616","9.66000","0.80519","0.00213"
"1623","9.70200","0.80871","0.00187"
"1630","9.74400","0.81224","0.00178"
"1637","9.78600","0.81571","0.00226"
"1644","9.82800","0.81924","0.00219"
"1651","9.87000","0.82270","0.00215"
"1658","9.91200","0.82623","0.00187"
"1665","9.95400","0.82976","0.00251"
"1672","9.99600","0.83323","0.00217"
"1679","10.03800","0.83675","0.00248"
"1686","10.08000","0.84022","0.00278"
"1693","10.12200","0.84369","0.00270"
"1700","10.16400","0.84716","0.00231"
"1707","10.20600","0.85069","0.00234"
"1714","10.24800","0.85415","0.00235"
"1721","10.29000","0.85768","0.00225"
"1728","10.33200","0.86127","0.00214"
"1735","10.37400","0.86480","0.00294"
"1742","10.41600","0.86820","0.00242"
"1749","10.45800","0.87167","0.00236"
"1756","10.50000","0.87520","0.00240"
"1763","10.54200","0.87867","0.00289"
"1770","10.58400","0.88213","0.00282"
"1777","10.62600","0.88566","0.00249"
"1784","10.66800","0.88913","0.00254"
"1791","10.71000","0.89260","0.00218"
"1798","10.75200","0.89619","0.00269"
"1805","10.79400","0.89971","0.00266"
"1812","10.83600","0.90324","0.00275"
"1819","10.87800","0.90671","0.00333"
"1826","10.92000","0.91024","0.00280"
"1833","10.96200","0.91370","0.00243"
"1840","11.00400","0.91723","0.00323"
"1847","11.04600","0.92070","0.00224"
"1854","11.08800","0.92423","0.00311"
"1861","11.13000","0.92769","0.00296"
"1868","11.17200","0.93116","0.00303"
"1875","11.21400","0.93469","0.00246"
"1882","11.25600","0.93816","0.00311"
"1889","11.29800","0.94163","0.00248"
"1896","11.34000","0.94515","0.00252"
"1903","11.38200","0.94868","0.00292"
"1910","11.42400","0.95221","0.00260"
"1917","11.46600","0.95568","0.00326"
"1924","11.50800","0.95920","0.00334"
"1931","11.55000","0.96267","0.00325"
"1938","11.59200","0.96620","0.00377"
"1945","11.63400","0.96973","0.00285"
"1952","11.67600","0.97319","0.00328"
"1959","11.71800","0.97666","0.00290"
"1966","11.76000","0.98013","0.00304"
"1973","11.80200","0.98366","0.00263"
"1980","11.84400","0.98718","0.00289"
"1987","11.88600","0.99071","0.00354"
"1994","11.92800","0.99430","0.00314"
"2001","11.97000","0.99777","0.00287"
"2008","12.01200","1.00124","0.00308"
"2015","12.05400","1.00476","0.00299"
"2022","12.09600","1.00823","0.00247"
"2029","12.13800","1.01170","0.00307"
"2036","12.18000","1.01523","0.00282"
"2043","12.22200","1.01875","0.00296"
"2050","12.26400","1.02216","0.00310"
"2057","12.30600","1.02569","0.00304"
"2064","12.34800","1.02922","0.00296"
"2071","12.39000","1.03268","0.00366"
"2078","12.43200","1.03615","0.00344"
"2085","12.47400","1.03974","0.00304"
"2092","12.51600","1.04327","0.00354"
"2099","12.55800","1.04668","0.00309"
"2106","12.60000","1.05020","0.00333"
"2113","12.64200","1.05373","0.00400"
"2120","12.68400","1.05720","0.00436"
"2127","12.72600","1.06067","0.00442"
"2134","12.76800","1.06419","0.00370"
"2141","12.81000","1.06766","0.00350"
"2148","12.85200","1.07113","0.00317"
"2155","12.89400","1.07466","0.00326"
"2162","12.93600","1.07818","0.00394"
"2169","12.97800","1.08171","0.00382"
"2176","13.02000","1.08518","0.00363"
"2183","13.06200","1.08877","0.00350"
"2190","13.10400","1.09224","0.00335"
"2197","13.14600","1.09570","0.00298"
"2204","13.18800","1.09923","0.00376"
"2211","13.23000","1.10276","0.00315"
"2218","13.27200","1.10623","0.00335"
"2225","13.31400","1.10969","0.00359"
"2232","13.35600","1.11316","0.00349"
"2239","13.39800","1.11663","0.00367"
"2246","13.44000","1.12016","0.00351"
"2253","13.48200","1.12368","0.00355"
"2260","13.52400","1.12721","0.00307"
"2267","13.56600","1.13074","0.00298"
"2274","13.60800","1.13421","0.00331"
"2281","13.65000","1.13774","0.00342"
"2288","13.69200","1.14120","0.00341"
"2295","13.73400","1.14473","0.00391"
"2302","13.77600","1.14826","0.00425"
"2309","13.81800","1.15173","0.00393"
"2316","13.86000","1.15519","0.00355"
"2323","13.90200","1.15866","0.00345"
"2330","13.94400","1.16213","0.00373"
"2337","13.98600","1.16560","0.00371"
"2344","14.02800","1.16918","0.00357"
"2351","14.07000","1.17277","0.00373"
"2358","14.11200","1.17624","0.00401"
"2365","14.15400","1.17971","0.00393"
"2372","14.19600","1.18323","0.00388"
"2379","14.23800","1.18676","0.00352"
"2386","14.28000","1.19023","0.00428"
"2393","14.32200","1.19370","0.00358"
"2400","14.36400","1.19723","0.00345"
"2407","14.40600","1.20069","0.00433"
"2414","14.44800","1.20416","0.00418"
"2421","14.49000","1.20763","0.00395"
"2428","14.53200","1.21116","0.00371"
"2435","14.57400","1.21468","0.00424"
"2442","14.61600","1.21815","0.00390"
"2449","14.65800","1.22168","0.00427"
"2456","14.70000","1.22521","0.00344"
"2463","14.74200","1.22873","0.00395"
"2470","14.78400","1.23220","0.00446"
"2477","14.82600","1.23573","0.00423"
"2484","14.86800","1.23920","0.00413"
"2491","14.91000","1.24267","0.00457"
"2498","14.95200","1.24613","0.00423"
"2505","14.99400","1.24966","0.00424"
"2512","15.03600","1.25313","0.00414"
"2519","15.07800","1.25666","0.00456"
"2526","15.12000","1.26018","0.00358"
"2533","15.16200","1.26371","0.00456"
"2540","15.20400","1.26724","0.00395"
"2547","15.24600","1.27071","0.00404"
"2554","15.28800","1.27423","0.00438"
"2561","15.33000","1.27776","0.00413"
"2568","15.37200","1.28129","0.00464"
"2575","15.41400","1.28470","0.00411"
"2582","15.45600","1.28817","0.00419"
"2589","15.49800","1.29169","0.00395"
"2596","15.54000","1.29522","0.00346"
"2603","15.58200","1.29863","0.00380"
"2610","15.62400","1.30222","0.00423"
"2617","15.66600","1.30574","0.00462"
"2624","15.70800","1.30921","0.00399"
"2631","15.75000","1.31274","0.00491"
"2638","15.79200","1.31627","0.00429"
"2645","15.83400","1.31973","0.00429"
"2652","15.87600","1.32320","0.00442"
"2659","15.91800","1.32673","0.00436"
"2666","15.96000","1.33026","0.00484"
"2673","16.00200","1.33367","0.00446"
"2680","16.04400","1.33719","0.00471"
"2687","16.08600","1.34072","0.00410"
"2694","16.12800","1.34419","0.00496"
"2701","16.17000","1.34766","0.00444"
"2708","16.21200","1.35124","0.00449"
"2715","16.25400","1.35477","0.00511"
"2722","16.29600","1.35824","0.00524"
"2729","16.33800","1.36177","0.00423"
"2736","16.38000","1.36529","0.00458"
"2743","16.42200","1.36870","0.00402"
"2750","16.46400","1.37217","0.00475"
"2757","16.50600","1.37576","0.00466"
"2764","16.54800","1.37917","0.00458"
"2771","16.59000","1.38263","0.00546"
"2778","16.63200","1.38616","0.00477"
"2785","16.67400","1.38969","0.00530"
"2792","16.71600","1.39322","0.00542"
"2799","16.75800","1.39674","0.00481"
"2806","16.80000","1.40027","0.00488"
"2813","16.84200","1.40368","0.00464"
"2820","16.88400","1.40715","0.00522"
"2827","16.92600","1.41073","0.00477"
"2834","16.96800","1.41420","0.00472"
"2841","17.01000","1.41773","0.00521"
"2848","17.05200","1.42120","0.00512"
"2855","17.09400","1.42472","0.00565"
"2862","17.13600","1.42813","0.00484"
"2869","17.17800","1.43160","0.00490"
"2876","17.22000","1.43519","0.00522"
"2883","17.26200","1.43866","0.00466"
"2890","17.30400","1.44224","0.00526"
"2897","17.34600","1.44571","0.00509"
"2904","17.38800","1.44924","0.00472"
"2911","17.43000","1.45271","0.00492"
"2918","17.47200","1.45617","0.00509"
"2925","17.51400","1.45970","0.00528"
"2932","17.55600","1.46323","0.00574"
"2939","17.59800","1.46670","0.00571"
"2946","17.64000","1.47022","0.00508"
"2953","17.68200","1.47369","0.00565"
"2960","17.72400","1.47716","0.00497"
"2967","17.76600","1.48069","0.00480"
"2974","17.80800","1.48422","0.00549"
"2981","17.85000","1.48768","0.00498"
"2988","17.89200","1.49121","0.00591"
"2995","17.93400","1.49474","0.00532"
"3002","17.97600","1.49821","0.00568"
"3009","18.01800","1.50167","0.00543"
"3016","18.06000","1.50520","0.00524"
"3023","18.10200","1.50873","0.00522"
"3030","18.14400","1.51220","0.00502"
"3037","18.18600","1.51566","0.00523"
"3044","18.22800","1.51919","0.00557"
"3051","18.27000","1.52266","0.00553"
"3058","18.31200","1.52619","0.00585"
"3065","18.35400","1.52972","0.00573"
"3072","18.39600","1.53318","0.00560"
"3079","18.43800","1.53671","0.00538"
"3086","18.48000","1.54018","0.00597"
"3093","18.52200","1.54371","0.00632"
"3100","18.56400","1.54723","0.00545"
"3107","18.60600","1.55070","0.00603"
"3114","18.64800","1.55423","0.00523"
"3121","18.69000","1.55770","0.00572"
"3128","18.73200","1.56122","0.00633"
"3135","18.77400","1.56463","0.00549"
"3142","18.81600","1.56816","0.00507"
"3149","18.85800","1.57169","0.00603"
"3156","18.90000","1.57522","0.00641"
"3163","18.94200","1.57874","0.00570"
"3170","18.98400","1.58221","0.00537"
"3177","19.02600","1.58568","0.00623"
"3184","19.06800","1.58921","0.00605"
"3191","19.11000","1.59267","0.00616"
"3198","19.15200","1.59620","0.00630"
"3205","19.19400","1.59967","0.00611"
"3212","19.23600","1.60320","0.00611"
"3219","19.27800","1.60666","0.00599"
"3226","19.32000","1.61007","0.00613"
"3233","19.36200","1.61366","0.00639"
"3240","19.40400","1.61719","0.00578"
"3247","19.44600","1.62071","0.00672"
"3254","19.48800","1.62418","0.00645"
"3261","19.53000","1.62777","0.00597"
"3268","19.57200","1.63118","0.00631"
"3275","19.61400","1.63471","0.00605"
"3282","19.65600","1.63823","0.00613"
"3289","19.69800","1.64170","0.00606"
"3296","19.74000","1.64517","0.00635"
"3303","19.78200","1.64870","0.00655"
"3310","19.82400","1.65222","0.00659"
"3317","19.86600","1.65563","0.00662"
"3324","19.90800","1.65916","0.00638"
"3331","19.95000","1.66275","0.00646"
"3338","19.99200","1.66621","0.00605"
"3345","20.03400","1.66974","0.00658"
"3352","20.07600","1.67327","0.00677"
"3359","20.11800","1.67674","0.00640"
"3366","20.16000","1.68021","0.00724"
"3373","20.20200","1.68373","0.00708"
"3380","20.24400","1.68726","0.00641"
"3387","20.28600","1.69073","0.00657"
"3394","20.32800","1.69420","0.00674"
"3401","20.37000","1.69766","0.00659"
"3408","20.41200","1.70119","0.00680"
"3415","20.45400","1.70466","0.00688"
"3422","20.49600","1.70819","0.00678"
"3429","20.53800","1.71177","0.00662"
"3436","20.58000","1.71524","0.00611"
"3443","20.62200","1.71871","0.00646"
"3450","20.66400","1.72224","0.00715"
"3457","20.70600","1.72571","0.00737"
"3464","20.74800","1.72917","0.00741"
"3471","20.79000","1.73270","0.00751"
"3478","20.83200","1.73617","0.00724"
"3485","20.87400","1.73964","0.00715"
"3492","20.91600","1.74310","0.00745"
"3499","20.95800","1.74669","0.00776"
"3506","21.00000","1.75022","0.00699"
"3513","21.04200","1.75375","0.00742"
"3520","21.08400","1.75727","0.00741"
"3527","21.12600","1.76080","0.00760"
"3534","21.16800","1.76421","0.00831"
"3541","21.21000","1.76768","0.00808"
"3548","21.25200","1.77121","0.00756"
"3555","21.29400","1.77467","0.00792"
"3562","21.33600","1.77814","0.00760"
"3569","21.37800","1.78167","0.00764"
"3576","21.42000","1.78520","0.00784"
"3583","21.46200","1.78860","0.00736"
"3590","21.50400","1.79213","0.00754"
"3597","21.54600","1.79572","0.00759"
"3604","21.58800","1.79925","0.00804"
"3611","21.63000","1.80271","0.00741"
"3618","21.67200","1.80630","0.00830"
"3625","21.71400","1.80971","0.00794"
"3632","21.75600","1.81324","0.00818"
"3639","21.79800","1.81671","0.00768"
"3646","21.84000","1.82029","0.00760"
"3653","21.88200","1.82370","0.00838"
"3660","21.92400","1.82717","0.00777"
"3667","21.96600","1.83070","0.00771"
"3674","22.00800","1.83410","0.00808"
"3681","22.05000","1.83763","0.00855"
"3688","22.09200","1.84122","0.00782"
"3695","22.13400","1.84475","0.00821"
"3702","22.17600","1.84827","0.00847"
"3709","22.21800","1.85174","0.00814"
"3716","22.26000","1.85521","0.00830"
"3723","22.30200","1.85874","0.00825"
"3730","22.34400","1.86226","0.00833"
"3737","22.38600","1.86573","0.00808"
"3744","22.42800","1.86920","0.00821"
"3751","22.47000","1.87273","0.00879"
"3758","22.51200","1.87614","0.00811"
"3765","22.55400","1.87960","0.00815"
"3772","22.59600","1.88319","0.00826"
"3779","22.63800","1.88672","0.00924"
"3786","22.68000","1.89025","0.00930"
"3793","22.72200","1.89377","0.00850"
"3800","22.76400","1.89730","0.00848"
"3807","22.80600","1.90077","0.00827"
"3814","22.84800","1.90424","0.00845"
"3821","22.89000","1.90770","0.00875"
"3828","22.93200","1.91123","0.00880"
"3835","22.97400","1.91470","0.00825"
"3842","23.01600","1.91823","0.00835"
"3849","23.05800","1.92170","0.00935"
"3856","23.10000","1.92516","0.00867"
"3863","23.14200","1.92869","0.00877"
"3870","23.18400","1.93216","0.00857"
"3877","23.22600","1.93569","0.00900"
"3884","23.26800","1.93927","0.00961"
"3891","23.31000","1.94274","0.00878"
"3898","23.35200","1.94621","0.00883"
"3905","23.39400","1.94974","0.00886"
"3912","23.43600","1.95320","0.00903"
"3919","23.47800","1.95667","0.00934"
"3926","23.52000","1.96020","0.00985"
"3933","23.56200","1.96373","0.00951"
"3940","23.60400","1.96714","0.00917"
"3947","23.64600","1.97060","0.00949"
"3954","23.68800","1.97419","0.00973"
"3961","23.73000","1.97766","0.00972"
"3968","23.77200","1.98119","0.00948"
"3975","23.81400","1.98471","0.00952"
"3982","23.85600","1.98824","0.00984"
"3989","23.89800","1.99171","0.00970"
"3996","23.94000","1.99524","0.01020"
"4003","23.98200","1.99876","0.00976"
"4010","24.02400","2.00217","0.01008"
"4017","24.06600","2.00564","0.00924"
"4024","24.10800","2.00917","0.00978"
"4031","24.15000","2.01264","0.00887"
"4038","24.19200","2.01610","0.00975"
"4045","24.23400","2.01969","0.01010"
"4052","24.27600","2.02322","0.00957"
"4059","24.31800","2.02675","0.00973"
"4066","24.36000","2.03021","0.00979"
"4073","24.40200","2.03380","0.00985"
"4080","24.44400","2.03721","0.00937"
"4087","24.48600","2.04074","0.01007"
"4094","24.52800","2.04426","0.01043"
"4101","24.57000","2.04773","0.01047"
"4108","24.61200","2.05120","0.00979"
"4115","24.65400","2.05467","0.01024"
"4122","24.69600","2.05819","0.01041"
"4129","24.73800","2.06166","0.01042"
"4136","24.78000","2.06519","0.01073"
"4143","24.82200","2.06872","0.01022"
"4150","24.86400","2.07225","0.01001"
"4157","24.90600","2.07571","0.01077"
"4164","24.94800","2.07918","0.01082"
"4171","24.99000","2.08277","0.01077"
"4178","25.03200","2.08624","0.00996"
"4185","25.07400","2.08970","0.01021"
"4192","25.11600","2.09323","0.01101"
"4199","25.15800","2.09670","0.01060"
"4206","25.20000","2.10017","0.01011"
"4213","25.24200","2.10363","0.01021"
"4220","25.28400","2.10722","0.01066"
"4227","25.32600","2.11069","0.01024"
"4234","25.36800","2.11422","0.01072"
"4241","25.41000","2.11775","0.01135"
"4248","25.45200","2.12121","0.01070"
"4255","25.49400","2.12468","0.01072"
"4262","25.53600","2.12821","0.01128"
"4269","25.57800","2.13174","0.01119"
"4276","25.62000","2.13520","0.01121"
"4283","25.66200","2.13867","0.01081"
"4290","25.70400","2.14220","0.01107"
"4297","25.74600","2.14567","0.01099"
"4304","25.78800","2.14913","0.01106"
"4311","25.83000","2.15272","0.01097"
"4318","25.87200","2.15619","0.01125"
"4325","25.91400","2.15972","0.01132"
"4332","25.95600","2.16325","0.01195"
"4339","25.99800","2.16671","0.01118"
"4346","26.04000","2.17024","0.01118"
"4353","26.08200","2.17371","0.01188"
"4360","26.12400","2.17718","0.01159"
"4367","26.16600","2.18070","0.01193"
"4374","26.20800","2.18417","0.01172"
"4381","26.25000","2.18770","0.01177"
"4388","26.29200","2.19117","0.01220"
"4395","26.33400","2.19469","0.01222"
"4402","26.37600","2.19816","0.01228"
"4409","26.41800","2.20169","0.01201"
"4416","26.46000","2.20522","0.01204"
"4423","26.50200","2.20874","0.01210"
"4430","26.54400","2.21221","0.01165"
"4437","26.58600","2.21568","0.01228"
"4444","26.62800","2.21921","0.01195"
"4451","26.67000","2.22274","0.01256"
"4458","26.71200","2.22620","0.01211"
"4465","26.75400","2.22973","0.01234"
"4472","26.79600","2.23320","0.01255"
"4479","26.83800","2.23667","0.01212"
"4486","26.88000","2.24013","0.01257"
"4493","26.92200","2.24366","0.01268"
"4500","26.96400","2.24719","0.01318"
"4507","27.00600","2.25072","0.01232"
"4514","27.04800","2.25424","0.01265"
"4521","27.09000","2.25771","0.01338"
"4528","27.13200","2.26124","0.01283"
"4535","27.17400","2.26471","0.01248"
"4542","27.21600","2.26818","0.01280"
"4549","27.25800","2.27170","0.01277"
"4556","27.30000","2.27523","0.01271"
"4563","27.34200","2.27864","0.01278"
"4570","27.38400","2.28217","0.01344"
"4577","27.42600","2.28569","0.01309"
"4584","27.46800","2.28916","0.01284"
"4591","27.51000","2.29269","0.01259"
"4598","27.55200","2.29622","0.01313"
"4605","27.59400","2.29974","0.01332"
"4612","27.63600","2.30315","0.01270"
"4619","27.67800","2.30668","0.01357"
"4626","27.72000","2.31021","0.01316"
"4633","27.76200","2.31368","0.01317"
"4640","27.80400","2.31714","0.01371"
"4647","27.84600","2.32073","0.01337"
"4654","27.88800","2.32420","0.01296"
"4661","27.93000","2.32767","0.01323"
"4668","27.97200","2.33119","0.01325"
"4675","28.01400","2.33466","0.01334"
"4682","28.05600","2.33819","0.01391"
"4689","28.09800","2.34172","0.01362"
"4696","28.14000","2.34530","0.01347"
"4703","28.18200","2.34871","0.01389"
"4710","28.22400","2.35224","0.01380"
"4717","28.26600","2.35577","0.01349"
"4724","28.30800","2.35918","0.01454"
"4731","28.35000","2.36264","0.01421"
"4738","28.39200","2.36623","0.01451"
"4745","28.43400","2.36970","0.01435"
"4752","28.47600","2.37317","0.01418"
"4759","28.51800","2.37669","0.01517"
"4766","28.56000","2.38022","0.01406"
"4773","28.60200","2.38369","0.01456"
"4780","28.64400","2.38722","0.01468"
"4787","28.68600","2.39074","0.01453"
"4794","28.72800","2.39427","0.01453"
"4801","28.77000","2.39774","0.01458"
"4808","28.81200","2.40121","0.01472"
"4815","28.85400","2.40473","0.01483"
"4822","28.89600","2.40820","0.01509"
"4829","28.93800","2.41167","0.01473"
"4836","28.98000","2.41520","0.01489"
"4843","29.02200","2.41867","0.01482"
"4850","29.06400","2.42219","0.01489"
"4857","29.10600","2.42572","0.01506"
"4864","29.14800","2.42925","0.01457"
"4871","29.19000","2.43278","0.01502"
"4878","29.23200","2.43618","0.01470"
"4885","29.27400","2.43971","0.01539"
"4892","29.31600","2.44318","0.01512"
"4899","29.35800","2.44671","0.01548"
"4906","29.40000","2.45023","0.01539"
"4913","29.44200","2.45376","0.01512"
"4920","29.48400","2.45717","0.01547"
"4927","29.52600","2.46064","0.01515"
"4934","29.56800","2.46423","0.01625"
"4941","29.61000","2.46769","0.01635"
"4948","29.65200","2.47122","0.01587"
"4955","29.69400","2.47475","0.01580"
"4962","29.73600","2.47822","0.01622"
"4969","29.77800","2.48168","0.01631"
"4976","29.82000","2.48521","0.01619"
"4983","29.86200","2.48874","0.01653"
"4990","29.90400","2.49221","0.01638"
"4997","29.94600","2.49567","0.01649"
"5004","29.98800","2.49914","0.01655"
"5011","30.03000","2.50267","0.01661"
"5018","30.07200","2.50620","0.01629"
"5025","30.11400","2.50967","0.01674"
"5032","30.15600","2.51319","0.01738"
"5039","30.19800","2.51672","0.01717"
"5046","30.24000","2.52019","0.01760"
"5053","30.28200","2.52372","0.01718"
"5060","30.32400","2.52718","0.01697"
"5067","30.36600","2.53077","0.01724"
"5074","30.40800","2.53424","0.01759"
"5081","30.45000","2.53771","0.01730"
"5088","30.49200","2.54123","0.01727"
"5095","30.53400","2.54470","0.01719"
"5102","30.57600","2.54817","0.01768"
"5109","30.61800","2.55164","0.01766"
"5116","30.66000","2.55517","0.01816"
"5123","30.70200","2.55869","0.01811"
"5130","30.74400","2.56222","0.01755"
"5137","30.78600","2.56575","0.01806"
"5144","30.82800","2.56922","0.01828"
"5151","30.87000","2.57274","0.01832"
"5158","30.91200","2.57621","0.01808"
"5165","30.95400","2.57974","0.01833"
"5172","30.99600","2.58327","0.01867"
"5179","31.03800","2.58673","0.01905"
"5186","31.08000","2.59020","0.01859"
"5193","31.12200","2.59367","0.01894"
"5200","31.16400","2.59720","0.01894"
"5207","31.20600","2.60061","0.01883"
"5214","31.24800","2.60413","0.01894"
"5221","31.29000","2.60772","0.01940"
"5228","31.33200","2.61125","0.01959"
"5235","31.37400","2.61472","0.01992"
"5242","31.41600","2.61824","0.01976"
"5249","31.45800","2.62177","0.01948"
"5256","31.50000","2.62524","0.01893"
"5263","31.54200","2.62871","0.01944"
"5270","31.58400","2.63223","0.01978"
"5277","31.62600","2.63564","0.01978"
"5284","31.66800","2.63917","0.01984"
"5291","31.71000","2.64270","0.01984"
"5298","31.75200","2.64616","0.01966"
"5305","31.79400","2.64963","0.02043"
"5312","31.83600","2.65316","0.02044"
"5319","31.87800","2.65675","0.02066"
"5326","31.92000","2.66022","0.02050"
"5333","31.96200","2.66368","0.02113"
"5340","32.00400","2.66721","0.02104"
"5347","32.04600","2.67074","0.02086"
"5354","32.08800","2.67415","0.02126"
"5361","32.13000","2.67767","0.02130"
"5368","32.17200","2.68120","0.02125"
"5375","32.21400","2.68461","0.02105"
"5382","32.25600","2.68814","0.02124"
"5389","32.29800","2.69172","0.02085"
"5396","32.34000","2.69519","0.02144"
"5403","32.38200","2.69866","0.02209"
"5410","32.42400","2.70225","0.02192"
"5417","32.46600","2.70578","0.02222"
"5424","32.50800","2.70918","0.02175"
"5431","32.55000","2.71271","0.02154"
"5438","32.59200","2.71624","0.02260"
"5445","32.63400","2.71971","0.02253"
"5452","32.67600","2.72317","0.02214"
"5459","32.71800","2.72670","0.02284"
"5466","32.76000","2.73017","0.02304"
"5473","32.80200","2.73364","0.02298"
"5480","32.84400","2.73716","0.02282"
"5487","32.88600","2.74075","0.02285"
"5494","32.92800","2.74422","0.02354"
"5501","32.97000","2.74775","0.02386"
"5508","33.01200","2.75128","0.02362"
"5515","33.05400","2.75474","0.02356"
"5522","33.09600","2.75821","0.02397"
"5529","33.13800","2.76174","0.02417"
"5536","33.18000","2.76527","0.02403"
"5543","33.22200","2.76867","0.02508"
"5550","33.26400","2.77220","0.02399"
"5557","33.30600","2.77567","0.02418"
"5564","33.34800","2.77914","0.02455"
"5571","33.39000","2.78266","0.02473"
"5578","33.43200","2.78619","0.02494"
"5585","33.47400","2.78972","0.02496"
"5592","33.51600","2.79319","0.02535"
"5599","33.55800","2.79666","0.02524"
"5606","33.60000","2.80024","0.02509"
"5613","33.64200","2.80371","0.02555"
"5620","33.68400","2.80718","0.02553"
"5627","33.72600","2.81071","0.02540"
"5634","33.76800","2.81417","0.02614"
"5641","33.81000","2.81770","0.02628"
"5648","33.85200","2.82117","0.02650"
"5655","33.89400","2.82470","0.02644"
"5662","33.93600","2.82816","0.02676"
"5669","33.97800","2.83169","0.02662"
"5676","34.02000","2.83522","0.02704"
"5683","34.06200","2.83869","0.02658"
"5690","34.10400","2.84216","0.02685"
"5697","34.14600","2.84568","0.02763"
"5704","34.18800","2.84921","0.02752"
"5711","34.23000","2.85274","0.02731"
"5718","34.27200","2.85621","0.02769"
"5725","34.31400","2.85967","0.02764"
"5732","34.35600","2.86314","0.02782"
"5739","34.39800","2.86661","0.02843"
"5746","34.44000","2.87020","0.02823"
"5753","34.48200","2.87372","0.02823"
"5760","34.52400","2.87719","0.02868"
"5767","34.56600","2.88072","0.02887"
"5774","34.60800","2.88425","0.02855"
"5781","34.65000","2.88771","0.02926"
"5788","34.69200","2.89124","0.02999"
"5795","34.73400","2.89477","0.02963"
"5802","34.77600","2.89824","0.02978"
"5809","34.81800","2.90171","0.03005"
"5816","34.86000","2.90523","0.03002"
"5823","34.90200","2.90870","0.03053"
"5830","34.94400","2.91211","0.03019"
"5837","34.98600","2.91564","0.03056"
"5844","35.02800","2.91922","0.03054"
"5851","35.07000","2.92275","0.03104"
"5858","35.11200","2.92622","0.03151"
"5865","35.15400","2.92975","0.03206"
"5872","35.19600","2.93321","0.03180"
"5879","35.23800","2.93674","0.03196"
"5886","35.28000","2.94021","0.03150"
"5893","35.32200","2.94374","0.03222"
"5900","35.36400","2.94721","0.03269"
"5907","35.40600","2.95073","0.03277"
"5914","35.44800","2.95420","0.03271"
"5921","35.49000","2.95767","0.03288"
"5928","35.53200","2.96120","0.03313"
"5935","35.57400","2.96472","0.03351"
"5942","35.61600","2.96819","0.03328"
"5949","35.65800","2.97172","0.03425"
"5956","35.70000","2.97519","0.03410"
"5963","35.74200","2.97871","0.03446"
"5970","35.78400","2.98224","0.03524"
"5977","35.82600","2.98571","0.03500"
"5984","35.86800","2.98924","0.03575"
"5991","35.91000","2.99271","0.03554"
"5998","35.95200","2.99617","0.03644"
"6005","35.99400","2.99964","0.03624"
"6012","36.03600","3.00317","0.03634"
"6019","36.07800","3.00670","0.03671"
"6026","36.12000","3.01016","0.03676"
"6033","36.16200","3.01375","0.03696"
"6040","36.20400","3.01728","0.03721"
"6047","36.24600","3.02069","0.03733"
"6054","36.28800","3.02421","0.03833"
"6061","36.33000","3.02774","0.03814"
"6068","36.37200","3.03115","0.03844"
"6075","36.41400","3.03468","0.03906"
"6082","36.45600","3.03820","0.03875"
"6089","36.49800","3.04167","0.03940"
"6096","36.54000","3.04514","0.03984"
"6103","36.58200","3.04867","0.03975"
"6110","36.62400","3.05220","0.04023"
"6117","36.66600","3.05566","0.04088"
"6124","36.70800","3.05925","0.04034"
"6131","36.75000","3.06278","0.04105"
"6138","36.79200","3.06619","0.04133"
"6145","36.83400","3.06971","0.04138"
"6152","36.87600","3.07324","0.04180"
"6159","36.91800","3.07665","0.04194"
"6166","36.96000","3.08012","0.04225"
"6173","37.00200","3.08365","0.04270"
"6180","37.04400","3.08723","0.04270"
"6187","37.08600","3.09070","0.04320"
"6194","37.12800","3.09417","0.04350"
"6201","37.17000","3.09776","0.04366"
"6208","37.21200","3.10122","0.04445"
"6215","37.25400","3.10469","0.04422"
"6222","37.29600","3.10822","0.04425"
"6229","37.33800","3.11175","0.04467"
"6236","37.38000","3.11521","0.04470"
"6243","37.42200","3.11874","0.04538"
"6250","37.46400","3.12227","0.04570"
"6257","37.50600","3.12568","0.04580"
"6264","37.54800","3.12914","0.04589"
"6271","37.59000","3.13267","0.04582"
"6278","37.63200","3.13614","0.04646"
"6285","37.67400","3.13973","0.04699"
"6292","37.71600","3.14320","0.04703"
"6299","37.75800","3.14672","0.04721"
"6306","37.80000","3.15025","0.04728"
"6313","37.84200","3.15372","0.04810"
"6320","37.88400","3.15719","0.04811"
"6327","37.92600","3.16071","0.04824"
"6334","37.96800","3.16424","0.04876"
"6341","38.01000","3.16771","0.04932"
"6348","38.05200","3.17118","0.04984"
"6355","38.09400","3.17470","0.05047"
"6362","38.13600","3.17817","0.05048"
"6369","38.17800","3.18164","0.05117"
"6376","38.22000","3.18523","0.05163"
"6383","38.26200","3.18876","0.05172"
"6390","38.30400","3.19222","0.05191"
"6397","38.34600","3.19575","0.05245"
"6404","38.38800","3.19922","0.05339"
"6411","38.43000","3.20275","0.05350"
"6418","38.47200","3.20621","0.05354"
"6425","38.51400","3.20974","0.05397"
"6432","38.55600","3.21321","0.05469"
"6439","38.59800","3.21668","0.05533"
"6446","38.64000","3.22020","0.05514"
"6453","38.68200","3.22361","0.05562"
"6460","38.72400","3.22714","0.05671"
"6467","38.76600","3.23073","0.05639"
"6474","38.80800","3.23419","0.05708"
"6481","38.85000","3.23772","0.05751"
"6488","38.89200","3.24125","0.05805"
"6495","38.93400","3.24472","0.05873"
"6502","38.97600","3.24819","0.05896"
"6509","39.01800","3.25171","0.05910"
"6516","39.06000","3.25524","0.05948"
"6523","39.10200","3.25871","0.06001"
"6530","39.14400","3.26218","0.06047"
"6537","39.18600","3.26570","0.06079"
"6544","39.22800","3.26917","0.06137"
"6551","39.27000","3.27264","0.06186"
"6558","39.31200","3.27617","0.06210"
"6565","39.35400","3.27970","0.06308"
"6572","39.39600","3.28322","0.06374"
"6579","39.43800","3.28675","0.06398"
"6586","39.48000","3.29028","0.06494"
"6593","39.52200","3.29375","0.06499"
"6600","39.56400","3.29721","0.06592"
"6607","39.60600","3.30074","0.06680"
"6614","39.64800","3.30421","0.06710"
"6621","39.69000","3.30768","0.06783"
"6628","39.73200","3.31114","0.06842"
"6635","39.77400","3.31467","0.06920"
"6642","39.81600","3.31820","0.06986"
"6649","39.85800","3.32167","0.06986"
"6656","39.90000","3.32520","0.07097"
"6663","39.94200","3.32872","0.07168"
"6670","39.98400","3.33219","0.07202"
"6677","40.02600","3.33572","0.07338"
"6684","40.06800","3.33919","0.07378"
"6691","40.11000","3.34271","0.07401"
"6698","40.15200","3.34618","0.07489"
"6705","40.19400","3.34971","0.07519"
"6712","40.23600","3.35318","0.07588"
"6719","40.27800","3.35664","0.07692"
"6726","40.32000","3.36023","0.07673"
"6733","40.36200","3.36370","0.07739"
"6740","40.40400","3.36717","0.07804"
"6747","40.44600","3.37069","0.07858"
"6754","40.48800","3.37428","0.07898"
"6761","40.53000","3.37769","0.07898"
"6768","40.57200","3.38122","0.07936"
"6775","40.61400","3.38481","0.08005"
"6782","40.65600","3.38827","0.08063"
"6789","40.69800","3.39168","0.08065"
"6796","40.74000","3.39521","0.08101"
"6803","40.78200","3.39868","0.08167"
"6810","40.82400","3.40214","0.08194"
"6817","40.86600","3.40561","0.08240"
"6824","40.90800","3.40920","0.08279"
"6831","40.95000","3.41267","0.08335"
"6838","40.99200","3.41619","0.08340"
"6845","41.03400","3.41978","0.08425"
"6852","41.07600","3.42325","0.08419"
"6859","41.11800","3.42672","0.08489"
"6866","41.16000","3.43024","0.08522"
"6873","41.20200","3.43377","0.08609"
"6880","41.24400","3.43718","0.08591"
"6887","41.28600","3.44065","0.08639"
"6894","41.32800","3.44418","0.08692"
"6901","41.37000","3.44770","0.08704"
"6908","41.41200","3.45117","0.08771"
"6915","41.45400","3.45470","0.08779"
"6922","41.49600","3.45823","0.08858"
"6929","41.53800","3.46169","0.08910"
"6936","41.58000","3.46522","0.08958"
"6943","41.62200","3.46875","0.09022"
"6950","41.66400","3.47222","0.09026"
"6957","41.70600","3.47574","0.09038"
"6964","41.74800","3.47921","0.09151"
"6971","41.79000","3.48274","0.09194"
"6978","41.83200","3.48621","0.09235"
"6985","41.87400","3.48968","0.09262"
"6992","41.91600","3.49320","0.09260"
"6999","41.95800","3.49667","0.09357"
"7006","42.00000","3.50020","0.09432"
"7013","42.04200","3.50373","0.09479"
"7020","42.08400","3.50719","0.09507"
"7027","42.12600","3.51072","0.09532"
"7034","42.16800","3.51425","0.09634"
"7041","42.21000","3.51778","0.09639"
"7048","42.25200","3.52124","0.09674"
"7055","42.29400","3.52471","0.09695"
"7062","42.33600","3.52824","0.09786"
"7069","42.37800","3.53171","0.09866"
"7076","42.42000","3.53518","0.09897"
"7083","42.46200","3.53864","0.09923"
"7090","42.50400","3.54217","0.09943"
"7097","42.54600","3.54564","0.10011"
"7104","42.58800","3.54923","0.10034"
"7111","42.63000","3.55269","0.10068"
"7118","42.67200","3.55616","0.10166"
"7125","42.71400","3.55969","0.10202"
"7132","42.75600","3.56322","0.10241"
"7139","42.79800","3.56668","0.10248"
"7146","42.84000","3.57021","0.10292"
"7153","42.88200","3.57368","0.10357"
"7160","42.92400","3.57715","0.10405"
"7167","42.96600","3.58062","0.10443"
"7174","43.00800","3.58408","0.10457"
"7181","43.05000","3.58767","0.10517"
"7188","43.09200","3.59120","0.10566"
"7195","43.13400","3.59473","0.10565"
"7202","43.17600","3.59825","0.10643"
"7209","43.21800","3.60172","0.10684"
"7216","43.26000","3.60525","0.10712"
"7223","43.30200","3.60872","0.10753"
"7230","43.34400","3.61224","0.10842"
"7237","43.38600","3.61571","0.10916"
"7244","43.42800","3.61924","0.10915"
"7251","43.47000","3.62271","0.11079"
"7258","43.51200","3.62618","0.11094"
"7265","43.55400","3.62970","0.11153"
"7272","43.59600","3.63317","0.11182"
"7279","43.63800","3.63670","0.11274"
"7286","43.68000","3.64023","0.11329"
"7293","43.72200","3.64375","0.11411"
"7300","43.76400","3.64722","0.11438"
"7307","43.80600","3.65075","0.11464"
"7314","43.84800","3.65422","0.11545"
"7321","43.89000","3.65768","0.11623"
"7328","43.93200","3.66127","0.11679"
"7335","43.97400","3.66468","0.11689"
"7342","44.01600","3.66815","0.11762"
"7349","44.05800","3.67174","0.11805"
"7356","44.10000","3.67514","0.11921"
"7363","44.14200","3.67867","0.11990"
"7370","44.18400","3.68220","0.11987"
"7377","44.22600","3.68573","0.12055"
"7384","44.26800","3.68925","0.12134"
"7391","44.31000","3.69266","0.12186"
"7398","44.35200","3.69625","0.12195"
"7405","44.39400","3.69972","0.12276"
"7412","44.43600","3.70318","0.12340"
"7419","44.47800","3.70671","0.12425"
"7426","44.52000","3.71024","0.12424"
"7433","44.56200","3.71365","0.12456"
"7440","44.60400","3.71712","0.12470"
"7447","44.64600","3.72070","0.12506"
"7454","44.68800","3.72417","0.12599"
"7461","44.73000","3.72770","0.12555"
"7468","44.77200","3.73123","0.12606"
"7475","44.81400","3.73475","0.12685"
"7482","44.85600","3.73816","0.12691"
"7489","44.89800","3.74169","0.12754"
"7496","44.94000","3.74522","0.12798"
"7503","44.98200","3.74862","0.12818"
"7510","45.02400","3.75215","0.12840"
"7517","45.06600","3.75574","0.12836"
"7524","45.10800","3.75915","0.12897"
"7531","45.15000","3.76262","0.12913"
"7538","45.19200","3.76620","0.12932"
"7545","45.23400","3.76967","0.12938"
"7552","45.27600","3.77320","0.12968"
"7559","45.31800","3.77673","0.13008"
"7566","45.36000","3.78025","0.13033"
"7573","45.40200","3.78372","0.13063"
"7580","45.44400","3.78725","0.13090"
"7587","45.48600","3.79078","0.13094"
"7594","45.52800","3.79418","0.13121"
"7601","45.57000","3.79771","0.13141"
"7608","45.61200","3.80118","0.13157"
"7615","45.65400","3.80471","0.13182"
"7622","45.69600","3.80817","0.13197"
"7629","45.73800","3.81170","0.13227"
"7636","45.78000","3.81523","0.13245"
"7643","45.82200","3.81870","0.13261"
"7650","45.86400","3.82223","0.13274"
"7657","45.90600","3.82575","0.13273"
"7664","45.94800","3.82922","0.13266"
"7671","45.99000","3.83275","0.13321"
"7678","46.03200","3.83622","0.13325"
"7685","46.07400","3.83974","0.13356"
"7692","46.11600","3.84321","0.13387"
"7699","46.15800","3.84668","0.13372"
"7706","46.20000","3.85021","0.13386"
"7713","46.24200","3.85367","0.13409"
"7720","46.28400","3.85714","0.13451"
"7727","46.32600","3.86067","0.13459"
"7734","46.36800","3.86420","0.13466"
"7741","46.41000","3.86773","0.13473"
"7748","46.45200","3.87119","0.13487"
"7755","46.49400","3.87472","0.13523"
"7762","46.53600","3.87825","0.13500"
"7769","46.57800","3.88172","0.13559"
"7776","46.62000","3.88518","0.13606"
"7783","46.66200","3.88871","0.13608"
"7790","46.70400","3.89218","0.13578"
"7797","46.74600","3.89565","0.13609"
"7804","46.78800","3.89917","0.13663"
"7811","46.83000","3.90270","0.13647"
"7818","46.87200","3.90623","0.13660"
"7825","46.91400","3.90976","0.13672"
"7832","46.95600","3.91322","0.13672"
"7839","46.99800","3.91675","0.13704"
"7846","47.04000","3.92022","0.13747"
"7853","47.08200","3.92369","0.13750"
"7860","47.12400","3.92722","0.13808"
"7867","47.16600","3.93068","0.13756"
"7874","47.20800","3.93421","0.13830"
"7881","47.25000","3.93768","0.13803"
"7888","47.29200","3.94115","0.13836"
"7895","47.33400","3.94467","0.13860"
"7902","47.37600","3.94820","0.13881"
"7909","47.41800","3.95173","0.13833"
"7916","47.46000","3.95520","0.13947"
"7923","47.50200","3.95878","0.13938"
"7930","47.54400","3.96219","0.13923"
"7937","47.58600","3.96572","0.13962"
"7944","47.62800","3.96925","0.13954"
"7951","47.67000","3.97278","0.13999"
"7958","47.71200","3.97618","0.14019"
"7965","47.75400","3.97971","0.14027"
"7972","47.79600","3.98324","0.14013"
"7979","47.83800","3.98665","0.14051"
"7986","47.88000","3.99011","0.14049"
"7993","47.92200","3.99370","0.14060"
"8000","47.96400","3.99723","0.14108"
"8007","48.00600","4.00070","0.14111"
"8014","48.04800","4.00422","0.14115"
"8021","48.09000","4.00775","0.14142"
"8028","48.13200","4.01122","0.14153"
"8035","48.17400","4.01469","0.14164"
"8042","48.21600","4.01828","0.14148"
"8049","48.25800","4.02168","0.14166"
"8056","48.30000","4.02515","0.14173"
"8063","48.34200","4.02868","0.14205"
"8070","48.38400","4.03215","0.14222"
"8077","48.42600","4.03567","0.14246"
"8084","48.46800","4.03920","0.14245"
"8091","48.51000","4.04273","0.14268"
"8098","48.55200","4.04626","0.14286"
"8105","48.59400","4.04972","0.14294"
"8112","48.63600","4.05325","0.14297"
"8119","48.67800","4.05672","0.14360"
"8126","48.72000","4.06019","0.14377"
"8133","48.76200","4.06372","0.14334"
"8140","48.80400","4.06724","0.13165"
"8147","48.84600","4.07065","0.12687"
"8154","48.88800","4.07412","0.12801"
"8161","48.93000","4.07765","0.03616"
"8168","48.97200","4.08123","-0.01258"
"8175","49.01400","4.08470","-0.00940"
"8182","49.05600","4.08823","-0.00929"
"8189","49.09800","4.09176","-0.00882"
"8196","49.14000","4.09522","-0.00832"
"8203","49.18200","4.09869","-0.00757"
"8210","49.22400","4.10228","-0.00665"
"8217","49.26600","4.10575","-0.00519"
"8224","49.30800","4.10916","-0.00346"
"8231","49.35000","4.11268","-0.00198"
"8238","49.39200","4.11621","-0.00091"
"8245","49.43400","4.11962","0.00043"
"8252","49.47600","4.12315","0.00027"
"8259","49.51800","4.12667","0.00030"
"8266","49.56000","4.13014","-0.00031"
"8273","49.60200","4.13367","-0.00116"
"8280","49.64400","4.13720","-0.00156"
"8287","49.68600","4.14072","-0.00174"
"8294","49.72800","4.14419","-0.00091"
"8301","49.77000","4.14772","-0.00118"
"8308","49.81200","4.15125","-0.00055"
"8315","49.85400","4.15471","-0.00075"
"8322","49.89600","4.15812","-0.00055"
"8329","49.93800","4.16171","-0.00095"
"8336","49.98000","4.16512","-0.00120"
"8343","50.02200","4.16859","-0.00231"
"8350","50.06400","4.17217","-0.00275"
"8357","50.10600","4.17576","-0.00301"
"8364","50.14800","4.17923","-0.00292"
"8371","50.19000","4.18270","-0.00277"
"8378","50.23200","4.18628","-0.00397"
"8385","50.27400","4.18975","-0.00318"
"8392","50.31600","4.19322","-0.00327"
"8399","50.35800","4.19675","-0.00315"
"8406","50.40000","4.20021","-0.00334"
"8413","50.44200","4.20368","-0.00266"
"8420","50.48400","4.20721","-0.00230"
"8427","50.52600","4.21068","-0.00246"
"8434","50.56800","4.21421","-0.00307"
"8441","50.61000","4.21767","-0.00263"
"8448","50.65200","4.22120","-0.00267"
"8455","50.69400","4.22467","-0.00282"
"8462","50.73600","4.22820","-0.00248"
"8469","50.77800","4.23172","-0.00284"
"8476","50.82000","4.23519","-0.00311"
"8483","50.86200","4.23878","-0.00307"
"8490","50.90400","4.24225","-0.00258"
"8497","50.94600","4.24571","-0.00308"
"8504","50.98800","4.24918","-0.00347"
"8511","51.03000","4.25271","-0.00314"
"8518","51.07200","4.25618","-0.00293"
"8525","51.11400","4.25971","-0.00282"
"8532","51.15600","4.26323","-0.00276"
"8539","51.19800","4.26670","-0.00258"
"8546","51.24000","4.27023","-0.00311"
"8553","51.28200","4.27370","-0.00296"
"8560","51.32400","4.27722","-0.00345"
"8567","51.36600","4.28075","-0.00332"
"8574","51.40800","4.28422","-0.00324"
"8581","51.45000","4.28775","-0.00357"
"8588","51.49200","4.29121","-0.00288"
"8595","51.53400","4.29468","-0.00324"
"8602","51.57600","4.29815","-0.00336"
"8609","51.61800","4.30162","-0.00313"
"8616","51.66000","4.30521","-0.00305"
"8623","51.70200","4.30873","-0.00336"
"8630","51.74400","4.31220","-0.00288"
"8637","51.78600","4.31573","-0.00304"
"8644","51.82800","4.31926","-0.00300"
"8651","51.87000","4.32266","-0.00259"
"8658","51.91200","4.32619","-0.00227"
"8665","51.95400","4.32978","-0.00315"
"8672","51.99600","4.33325","-0.00307"
"8679","52.03800","4.33671","-0.00284"
"8686","52.08000","4.34024","-0.00280"
"8693","52.12200","4.34371","-0.00326"
"8700","52.16400","4.34712","-0.00314"
"8707","52.20600","4.35065","-0.00328"
"8714","52.24800","4.35423","-0.00316"
"8721","52.29000","4.35776","-0.00343"
"8728","52.33200","4.36123","-0.00384"
"8735","52.37400","4.36476","-0.00329"
"8742","52.41600","4.36822","-0.00291"
"8749","52.45800","4.37169","-0.00265"
"8756","52.50000","4.37522","-0.00296"
"8763","52.54200","4.37875","-0.00254"
"8770","52.58400","4.38221","-0.00257"
"8777","52.62600","4.38568","-0.00338"
"8784","52.66800","4.38921","-0.00310"
"8791","52.71000","4.39268","-0.00307"
"8798","52.75200","4.39614","-0.00367"
"8805","52.79400","4.39967","-0.00382"
"8812","52.83600","4.40320","-0.00386"
"8819","52.87800","4.40673","-0.00381"
"8826","52.92000","4.41020","-0.00329"
"8833","52.96200","4.41372","-0.00365"
"8840","53.00400","4.41719","-0.00336"
"8847","53.04600","4.42066","-0.00329"
"8854","53.08800","4.42419","-0.00343"
"8861","53.13000","4.42765","-0.00302"
"8868","53.17200","4.43118","-0.00290"
"8875","53.21400","4.43465","-0.00329"
"8882","53.25600","4.43818","-0.00264"
"8889","53.29800","4.44165","-0.00303"
"8896","53.34000","4.44517","-0.00283"
"8903","53.38200","4.44876","-0.00325"
"8910","53.42400","4.45223","-0.00298"
"8917","53.46600","4.45570","-0.00373"
"8924","53.50800","4.45922","-0.00307"
"8931","53.55000","4.46269","-0.00330"
"8938","53.59200","4.46616","-0.00354"
"8945","53.63400","4.46969","-0.00333"
"8952","53.67600","4.47321","-0.00318"
"8959","53.71800","4.47668","-0.00298"
"8966","53.76000","4.48015","-0.00273"
"8973","53.80200","4.48368","-0.00270"
"8980","53.84400","4.48720","-0.00257"
"8987","53.88600","4.49073","-0.00296"
"8994","53.92800","4.49420","-0.00347"
"9001","53.97000","4.49773","-0.00355"
"9008","54.01200","4.50119","-0.00330"
"9015","54.05400","4.50472","-0.00383"
"9022","54.09600","4.50819","-0.00403"
"9029","54.13800","4.51172","-0.00363"
"9036","54.18000","4.51519","-0.00375"
"9043","54.22200","4.51865","-0.00338"
"9050","54.26400","4.52218","-0.00358"
"9057","54.30600","4.52565","-0.00356"
"9064","54.34800","4.52912","-0.00328"
"9071","54.39000","4.53270","-0.00291"
"9078","54.43200","4.53617","-0.00356"
"9085","54.47400","4.53970","-0.00243"
"9092","54.51600","4.54323","-0.00335"
"9099","54.55800","4.54669","-0.00298"
"9106","54.60000","4.55022","-0.00283"
"9113","54.64200","4.55375","-0.00327"
"9120","54.68400","4.55722","-0.00307"
"9127","54.72600","4.56069","-0.00313"
"9134","54.76800","4.56421","-0.00329"
"9141","54.81000","4.56762","-0.00342"
"9148","54.85200","4.57115","-0.00302"
"9155","54.89400","4.57468","-0.00328"
"9162","54.93600","4.57820","-0.00317"
"9169","54.97800","4.58173","-0.00295"
"9176","55.02000","4.58526","-0.00334"
"9179","55.03400","4.58645","-0.00345"