File: Trajectories_together/170212_2Specimen_RawData_7.csv
"","V1","V2","V3"
"1","End date","2/12/2017",""
"2","Specimen label","14AG_11",""
"3","Maximum Load","0.17125","N"
"4","Time","Extension","Load"
"5","(s)","(mm)","(N)"
"6","0.00000","0.00000","0.00029"
"49","0.25800","0.02039","0.00058"
"92","0.51600","0.04329","0.00036"
"135","0.77400","0.06475","0.00027"
"178","1.03200","0.08628","0.00097"
"221","1.29000","0.10774","0.00061"
"264","1.54800","0.12926","0.00100"
"307","1.80600","0.15067","0.00140"
"350","2.06400","0.17219","0.00151"
"393","2.32200","0.19372","0.00105"
"436","2.58000","0.21524","0.00108"
"479","2.83800","0.23671","0.00163"
"522","3.09600","0.25823","0.00182"
"565","3.35400","0.27964","0.00136"
"608","3.61200","0.30128","0.00174"
"651","3.87000","0.32268","0.00196"
"694","4.12800","0.34421","0.00149"
"737","4.38600","0.36573","0.00181"
"780","4.64400","0.38726","0.00265"
"823","4.90200","0.40872","0.00212"
"866","5.16000","0.43025","0.00241"
"909","5.41800","0.45165","0.00234"
"952","5.67600","0.47323","0.00177"
"995","5.93400","0.49476","0.00241"
"1038","6.19200","0.51622","0.00187"
"1081","6.45000","0.53769","0.00204"
"1124","6.70800","0.55921","0.00276"
"1167","6.96600","0.58068","0.00224"
"1210","7.22400","0.60214","0.00268"
"1253","7.48200","0.62372","0.00274"
"1296","7.74000","0.64525","0.00220"
"1339","7.99800","0.66677","0.00273"
"1382","8.25600","0.68818","0.00297"
"1425","8.51400","0.70970","0.00231"
"1468","8.77200","0.73123","0.00228"
"1511","9.03000","0.75275","0.00264"
"1554","9.28800","0.77415","0.00270"
"1597","9.54600","0.79568","0.00296"
"1640","9.80400","0.81714","0.00289"
"1683","10.06200","0.83873","0.00243"
"1726","10.32000","0.86019","0.00305"
"1769","10.57800","0.88172","0.00283"
"1812","10.83600","0.90318","0.00328"
"1855","11.09400","0.92476","0.00259"
"1898","11.35200","0.94617","0.00329"
"1941","11.61000","0.96775","0.00340"
"1984","11.86800","0.98922","0.00285"
"2027","12.12600","1.01074","0.00291"
"2070","12.38400","1.03227","0.00297"
"2113","12.64200","1.05373","0.00362"
"2156","12.90000","1.07520","0.00311"
"2199","13.15800","1.09666","0.00306"
"2242","13.41600","1.11824","0.00285"
"2285","13.67400","1.13971","0.00278"
"2328","13.93200","1.16123","0.00264"
"2371","14.19000","1.18270","0.00280"
"2414","14.44800","1.20416","0.00269"
"2457","14.70600","1.22563","0.00310"
"2500","14.96400","1.24727","0.00362"
"2543","15.22200","1.26867","0.00325"
"2586","15.48000","1.29020","0.00245"
"2629","15.73800","1.31166","0.00299"
"2672","15.99600","1.33319","0.00269"
"2715","16.25400","1.35471","0.00246"
"2758","16.51200","1.37630","0.00262"
"2801","16.77000","1.39764","0.00277"
"2844","17.02800","1.41922","0.00247"
"2887","17.28600","1.44069","0.00251"
"2930","17.54400","1.46227","0.00267"
"2973","17.80200","1.48374","0.00253"
"3016","18.06000","1.50526","0.00288"
"3059","18.31800","1.52673","0.00292"
"3102","18.57600","1.54825","0.00301"
"3145","18.83400","1.56971","0.00253"
"3188","19.09200","1.59124","0.00269"
"3231","19.35000","1.61270","0.00276"
"3274","19.60800","1.63423","0.00242"
"3317","19.86600","1.65575","0.00293"
"3360","20.12400","1.67722","0.00336"
"3403","20.38200","1.69880","0.00274"
"3446","20.64000","1.72020","0.00288"
"3489","20.89800","1.74173","0.00290"
"3532","21.15600","1.76313","0.00289"
"3575","21.41400","1.78478","0.00292"
"3618","21.67200","1.80618","0.00307"
"3661","21.93000","1.82771","0.00313"
"3704","22.18800","1.84911","0.00284"
"3747","22.44600","1.87069","0.00325"
"3790","22.70400","1.89222","0.00292"
"3833","22.96200","1.91374","0.00278"
"3876","23.22000","1.93521","0.00297"
"3919","23.47800","1.95673","0.00327"
"3962","23.73600","1.97820","0.00320"
"4005","23.99400","1.99978","0.00288"
"4048","24.25200","2.02125","0.00305"
"4091","24.51000","2.04271","0.00259"
"4134","24.76800","2.06417","0.00293"
"4177","25.02600","2.08576","0.00287"
"4220","25.28400","2.10728","0.00289"
"4263","25.54200","2.12875","0.00300"
"4306","25.80000","2.15021","0.00298"
"4349","26.05800","2.17174","0.00271"
"4392","26.31600","2.19320","0.00310"
"4435","26.57400","2.21472","0.00311"
"4478","26.83200","2.23625","0.00328"
"4521","27.09000","2.25771","0.00324"
"4564","27.34800","2.27930","0.00319"
"4607","27.60600","2.30064","0.00279"
"4650","27.86400","2.32229","0.00357"
"4693","28.12200","2.34369","0.00295"
"4736","28.38000","2.36521","0.00345"
"4779","28.63800","2.38668","0.00300"
"4822","28.89600","2.40820","0.00307"
"4865","29.15400","2.42967","0.00298"
"4908","29.41200","2.45125","0.00341"
"4951","29.67000","2.47266","0.00301"
"4994","29.92800","2.49418","0.00328"
"5037","30.18600","2.51564","0.00308"
"5080","30.44400","2.53723","0.00315"
"5123","30.70200","2.55869","0.00313"
"5166","30.96000","2.58022","0.00341"
"5209","31.21800","2.60174","0.00328"
"5252","31.47600","2.62327","0.00314"
"5295","31.73400","2.64473","0.00391"
"5338","31.99200","2.66619","0.00302"
"5381","32.25000","2.68772","0.00335"
"5424","32.50800","2.70918","0.00354"
"5467","32.76600","2.73071","0.00287"
"5510","33.02400","2.75229","0.00309"
"5553","33.28200","2.77376","0.00311"
"5596","33.54000","2.79516","0.00328"
"5639","33.79800","2.81668","0.00301"
"5682","34.05600","2.83815","0.00323"
"5725","34.31400","2.85973","0.00327"
"5768","34.57200","2.88120","0.00312"
"5811","34.83000","2.90272","0.00327"
"5854","35.08800","2.92419","0.00331"
"5897","35.34600","2.94571","0.00382"
"5940","35.60400","2.96718","0.00360"
"5983","35.86200","2.98876","0.00345"
"6026","36.12000","3.01016","0.00344"
"6069","36.37800","3.03175","0.00355"
"6112","36.63600","3.05321","0.00325"
"6155","36.89400","3.07480","0.00342"
"6198","37.15200","3.09620","0.00311"
"6241","37.41000","3.11773","0.00268"
"6284","37.66800","3.13919","0.00341"
"6327","37.92600","3.16071","0.00294"
"6370","38.18400","3.18224","0.00339"
"6413","38.44200","3.20370","0.00337"
"6456","38.70000","3.22523","0.00337"
"6499","38.95800","3.24675","0.00298"
"6542","39.21600","3.26828","0.00312"
"6585","39.47400","3.28974","0.00303"
"6628","39.73200","3.31120","0.00321"
"6671","39.99000","3.33267","0.00280"
"6714","40.24800","3.35425","0.00312"
"6757","40.50600","3.37566","0.00337"
"6800","40.76400","3.39724","0.00255"
"6843","41.02200","3.41871","0.00326"
"6886","41.28000","3.44017","0.00281"
"6929","41.53800","3.46163","0.00264"
"6972","41.79600","3.48322","0.00264"
"7015","42.05400","3.50474","0.00297"
"7058","42.31200","3.52621","0.00293"
"7101","42.57000","3.54767","0.00338"
"7144","42.82800","3.56926","0.00339"
"7187","43.08600","3.59066","0.00315"
"7230","43.34400","3.61230","0.00341"
"7273","43.60200","3.63365","0.00265"
"7316","43.86000","3.65523","0.00296"
"7359","44.11800","3.67676","0.00343"
"7402","44.37600","3.69822","0.00348"
"7445","44.63400","3.71975","0.00320"
"7488","44.89200","3.74121","0.00390"
"7531","45.15000","3.76268","0.00348"
"7574","45.40800","3.78420","0.00394"
"7617","45.66600","3.80578","0.00301"
"7660","45.92400","3.82725","0.00314"
"7703","46.18200","3.84877","0.00322"
"7746","46.44000","3.87018","0.00335"
"7789","46.69800","3.89170","0.00298"
"7832","46.95600","3.91317","0.00288"
"7875","47.21400","3.93475","0.00353"
"7918","47.47200","3.95615","0.00353"
"7961","47.73000","3.97774","0.00320"
"8004","47.98800","3.99920","0.00369"
"8047","48.24600","4.02073","0.00310"
"8090","48.50400","4.04219","0.00343"
"8133","48.76200","4.06372","0.00309"
"8176","49.02000","4.08518","0.00346"
"8219","49.27800","4.10676","0.00374"
"8262","49.53600","4.12823","0.00316"
"8305","49.79400","4.14975","0.00313"
"8348","50.05200","4.17116","0.00333"
"8391","50.31000","4.19274","0.00372"
"8434","50.56800","4.21415","0.00396"
"8477","50.82600","4.23573","0.00404"
"8520","51.08400","4.25725","0.00348"
"8563","51.34200","4.27872","0.00354"
"8606","51.60000","4.30024","0.00345"
"8649","51.85800","4.32171","0.00429"
"8692","52.11600","4.34323","0.00328"
"8735","52.37400","4.36470","0.00299"
"8778","52.63200","4.38622","0.00322"
"8821","52.89000","4.40762","0.00359"
"8864","53.14800","4.42921","0.00328"
"8907","53.40600","4.45067","0.00334"
"8950","53.66400","4.47226","0.00345"
"8993","53.92200","4.49366","0.00306"
"9036","54.18000","4.51519","0.00309"
"9079","54.43800","4.53665","0.00332"
"9122","54.69600","4.55823","0.00386"
"9165","54.95400","4.57970","0.00364"
"9208","55.21200","4.60122","0.00384"
"9251","55.47000","4.62275","0.00403"
"9294","55.72800","4.64421","0.00328"
"9337","55.98600","4.66574","0.00378"
"9380","56.24400","4.68726","0.00352"
"9423","56.50200","4.70866","0.00370"
"9466","56.76000","4.73019","0.00384"
"9509","57.01800","4.75171","0.00390"
"9552","57.27600","4.77324","0.00376"
"9595","57.53400","4.79470","0.00342"
"9638","57.79200","4.81617","0.00331"
"9681","58.05000","4.83775","0.00330"
"9724","58.30800","4.85916","0.00357"
"9767","58.56600","4.88074","0.00385"
"9810","58.82400","4.90220","0.00403"
"9853","59.08200","4.92373","0.00365"
"9896","59.34000","4.94519","0.00380"
"9939","59.59800","4.96672","0.00386"
"9982","59.85600","4.98818","0.00382"
"10025","60.11400","5.00971","0.00409"
"10068","60.37200","5.03117","0.00443"
"10111","60.63000","5.05275","0.00400"
"10154","60.88800","5.07416","0.00429"
"10197","61.14600","5.09574","0.00403"
"10240","61.40400","5.11721","0.00425"
"10283","61.66200","5.13873","0.00463"
"10326","61.92000","5.16020","0.00374"
"10369","62.17800","5.18178","0.00422"
"10412","62.43600","5.20324","0.00497"
"10455","62.69400","5.22471","0.00472"
"10498","62.95200","5.24623","0.00457"
"10541","63.21000","5.26776","0.00413"
"10584","63.46800","5.28922","0.00454"
"10627","63.72600","5.31069","0.00419"
"10670","63.98400","5.33221","0.00457"
"10713","64.24200","5.35367","0.00426"
"10756","64.50000","5.37526","0.00440"
"10799","64.75800","5.39672","0.00482"
"10842","65.01600","5.41825","0.00428"
"10885","65.27400","5.43965","0.00522"
"10928","65.53200","5.46118","0.00473"
"10971","65.79000","5.48264","0.00531"
"11014","66.04800","5.50422","0.00466"
"11057","66.30600","5.52569","0.00444"
"11100","66.56400","5.54721","0.00510"
"11143","66.82200","5.56868","0.00430"
"11186","67.08000","5.59020","0.00459"
"11229","67.33800","5.61167","0.00471"
"11272","67.59600","5.63325","0.00550"
"11315","67.85400","5.65465","0.00471"
"11358","68.11200","5.67624","0.00500"
"11401","68.37000","5.69770","0.00521"
"11444","68.62800","5.71923","0.00513"
"11487","68.88600","5.74075","0.00513"
"11530","69.14400","5.76222","0.00548"
"11573","69.40200","5.78368","0.00511"
"11616","69.66000","5.80520","0.00490"
"11659","69.91800","5.82679","0.00535"
"11702","70.17600","5.84825","0.00546"
"11745","70.43400","5.86972","0.00555"
"11788","70.69200","5.89118","0.00523"
"11831","70.95000","5.91277","0.00535"
"11874","71.20800","5.93423","0.00562"
"11917","71.46600","5.95575","0.00580"
"11960","71.72400","5.97716","0.00534"
"12003","71.98200","5.99874","0.00599"
"12046","72.24000","6.02015","0.00592"
"12089","72.49800","6.04167","0.00615"
"12132","72.75600","6.06320","0.00556"
"12175","73.01400","6.08472","0.00538"
"12218","73.27200","6.10619","0.00541"
"12261","73.53000","6.12771","0.00616"
"12304","73.78800","6.14917","0.00550"
"12347","74.04600","6.17076","0.00599"
"12390","74.30400","6.19222","0.00615"
"12433","74.56200","6.21375","0.00585"
"12476","74.82000","6.23521","0.00614"
"12519","75.07800","6.25668","0.00607"
"12562","75.33600","6.27820","0.00596"
"12605","75.59400","6.29966","0.00629"
"12648","75.85200","6.32119","0.00597"
"12691","76.11000","6.34271","0.00666"
"12734","76.36800","6.36424","0.00627"
"12777","76.62600","6.38570","0.00664"
"12820","76.88400","6.40723","0.00618"
"12863","77.14200","6.42869","0.00715"
"12906","77.40000","6.45021","0.00740"
"12949","77.65800","6.47174","0.00692"
"12992","77.91600","6.49326","0.00667"
"13035","78.17400","6.51467","0.00703"
"13078","78.43200","6.53619","0.00729"
"13121","78.69000","6.55766","0.00771"
"13164","78.94800","6.57924","0.00722"
"13207","79.20600","6.60070","0.00741"
"13250","79.46400","6.62223","0.00724"
"13293","79.72200","6.64369","0.00760"
"13336","79.98000","6.66528","0.00745"
"13379","80.23800","6.68668","0.00768"
"13422","80.49600","6.70821","0.00793"
"13465","80.75400","6.72967","0.00758"
"13508","81.01200","6.75119","0.00754"
"13551","81.27000","6.77272","0.00805"
"13594","81.52800","6.79424","0.00768"
"13637","81.78600","6.81571","0.00793"
"13680","82.04400","6.83723","0.00834"
"13723","82.30200","6.85870","0.00662"
"13766","82.56000","6.88022","0.00710"
"13809","82.81800","6.90175","0.00704"
"13852","83.07600","6.92321","0.00678"
"13895","83.33400","6.94467","0.00670"
"13938","83.59200","6.96620","0.00672"
"13981","83.85000","6.98778","0.00655"
"14024","84.10800","7.00919","0.00669"
"14067","84.36600","7.03071","0.00706"
"14110","84.62400","7.05212","0.00674"
"14153","84.88200","7.07370","0.00660"
"14196","85.14000","7.09516","0.00677"
"14239","85.39800","7.11675","0.00736"
"14282","85.65600","7.13821","0.00577"
"14325","85.91400","7.15974","0.00736"
"14368","86.17200","7.18114","0.00655"
"14411","86.43000","7.20279","0.00710"
"14454","86.68800","7.22419","0.00728"
"14497","86.94600","7.24577","0.00736"
"14540","87.20400","7.26718","0.00733"
"14583","87.46200","7.28876","0.00755"
"14626","87.72000","7.31023","0.00747"
"14669","87.97800","7.33175","0.00796"
"14712","88.23600","7.35322","0.00780"
"14755","88.49400","7.37468","0.00764"
"14798","88.75200","7.39620","0.00743"
"14841","89.01000","7.41767","0.00790"
"14884","89.26800","7.43925","0.00781"
"14927","89.52600","7.46072","0.00796"
"14970","89.78400","7.48224","0.00855"
"15013","90.04200","7.50365","0.00860"
"15056","90.30000","7.52523","0.00883"
"15099","90.55800","7.54669","0.00844"
"15142","90.81600","7.56822","0.00884"
"15185","91.07400","7.58962","0.00909"
"15228","91.33200","7.61121","0.00891"
"15271","91.59000","7.63267","0.00961"
"15314","91.84800","7.65420","0.00989"
"15357","92.10600","7.67572","0.00969"
"15400","92.36400","7.69725","0.00842"
"15443","92.62200","7.71871","0.00879"
"15486","92.88000","7.74023","0.00895"
"15529","93.13800","7.76170","0.00786"
"15572","93.39600","7.78322","0.00785"
"15615","93.65400","7.80469","0.00757"
"15658","93.91200","7.82621","0.00759"
"15701","94.17000","7.84768","0.00798"
"15744","94.42800","7.86926","0.00799"
"15787","94.68600","7.89072","0.00908"
"15830","94.94400","7.91219","0.00847"
"15873","95.20200","7.93377","0.00807"
"15916","95.46000","7.95524","0.00868"
"15959","95.71800","7.97676","0.00820"
"16002","95.97600","7.99817","0.00864"
"16045","96.23400","8.01969","0.00893"
"16088","96.49200","8.04115","0.00865"
"16131","96.75000","8.06274","0.00885"
"16174","97.00800","8.08420","0.00902"
"16217","97.26600","8.10573","0.00909"
"16260","97.52400","8.12713","0.00931"
"16303","97.78200","8.14872","0.00879"
"16346","98.04000","8.17018","0.00891"
"16389","98.29800","8.19176","0.00935"
"16432","98.55600","8.21323","0.00920"
"16475","98.81400","8.23469","0.00936"
"16518","99.07200","8.25622","0.00886"
"16561","99.33000","8.27774","0.00948"
"16604","99.58800","8.29921","0.00918"
"16647","99.84600","8.32073","0.00997"
"16690","100.10400","8.34219","0.00988"
"16733","100.36200","8.36372","0.01014"
"16776","100.62000","8.38518","0.01009"
"16819","100.87800","8.40671","0.01024"
"16862","101.13600","8.42823","0.00988"
"16905","101.39400","8.44970","0.01032"
"16948","101.65200","8.47116","0.01018"
"16991","101.91000","8.49269","0.01001"
"17034","102.16800","8.51421","0.01057"
"17077","102.42600","8.53567","0.01049"
"17120","102.68400","8.55720","0.01047"
"17163","102.94200","8.57872","0.01029"
"17206","103.20000","8.60025","0.01009"
"17249","103.45800","8.62165","0.01034"
"17292","103.71600","8.64323","0.01049"
"17335","103.97400","8.66464","0.01049"
"17378","104.23200","8.68622","0.01098"
"17421","104.49000","8.70769","0.01097"
"17464","104.74800","8.72927","0.01008"
"17507","105.00600","8.75068","0.01074"
"17550","105.26400","8.77220","0.01048"
"17593","105.52200","8.79366","0.01123"
"17636","105.78000","8.81525","0.01101"
"17679","106.03800","8.83671","0.01099"
"17722","106.29600","8.85818","0.01083"
"17765","106.55400","8.87970","0.01159"
"17808","106.81200","8.90123","0.01100"
"17851","107.07000","8.92275","0.01146"
"17894","107.32800","8.94421","0.01121"
"17937","107.58600","8.96574","0.01115"
"17980","107.84400","8.98720","0.01176"
"18023","108.10200","9.00873","0.01174"
"18066","108.36000","9.03019","0.01110"
"18109","108.61800","9.05172","0.01123"
"18152","108.87600","9.07318","0.01196"
"18195","109.13400","9.09471","0.01192"
"18238","109.39200","9.11617","0.01210"
"18281","109.65000","9.13775","0.01197"
"18324","109.90800","9.15922","0.01247"
"18367","110.16600","9.18068","0.01262"
"18410","110.42400","9.20215","0.01245"
"18453","110.68200","9.22373","0.01291"
"18496","110.94000","9.24520","0.01273"
"18539","111.19800","9.26672","0.01260"
"18582","111.45600","9.28818","0.01347"
"18625","111.71400","9.30971","0.01297"
"18668","111.97200","9.33117","0.01293"
"18711","112.23000","9.35276","0.01291"
"18754","112.48800","9.37422","0.01264"
"18797","112.74600","9.39575","0.01259"
"18840","113.00400","9.41721","0.01204"
"18883","113.26200","9.43873","0.01270"
"18926","113.52000","9.46026","0.01249"
"18969","113.77800","9.48172","0.01283"
"19012","114.03600","9.50319","0.01293"
"19055","114.29400","9.52471","0.01304"
"19098","114.55200","9.54624","0.01346"
"19141","114.81000","9.56770","0.01153"
"19184","115.06800","9.58928","0.01194"
"19227","115.32600","9.61063","0.01176"
"19270","115.58400","9.63227","0.01248"
"19313","115.84200","9.65368","0.01235"
"19356","116.10000","9.67526","0.01246"
"19399","116.35800","9.69667","0.01268"
"19442","116.61600","9.71825","0.01353"
"19485","116.87400","9.73966","0.01323"
"19528","117.13200","9.76124","0.01250"
"19571","117.39000","9.78270","0.01284"
"19614","117.64800","9.80423","0.01293"
"19657","117.90600","9.82569","0.01384"
"19700","118.16400","9.84722","0.01328"
"19743","118.42200","9.86868","0.01362"
"19786","118.68000","9.89026","0.01388"
"19829","118.93800","9.91167","0.01373"
"19872","119.19600","9.93319","0.01469"
"19915","119.45400","9.95472","0.01459"
"19958","119.71200","9.97618","0.01357"
"20001","119.97000","9.99771","0.01463"
"20044","120.22800","10.01923","0.01341"
"20087","120.48600","10.04076","0.01386"
"20130","120.74400","10.06222","0.01508"
"20173","121.00200","10.08374","0.01445"
"20216","121.26000","10.10521","0.01468"
"20259","121.51800","10.12673","0.01533"
"20302","121.77600","10.14814","0.01529"
"20345","122.03400","10.16972","0.01522"
"20388","122.29200","10.19113","0.01517"
"20431","122.55000","10.21277","0.01596"
"20474","122.80800","10.23417","0.01564"
"20517","123.06600","10.25570","0.01580"
"20560","123.32400","10.27710","0.01594"
"20603","123.58200","10.29875","0.01575"
"20646","123.84000","10.32021","0.01605"
"20689","124.09800","10.34174","0.01568"
"20732","124.35600","10.36320","0.01640"
"20775","124.61400","10.38478","0.01622"
"20818","124.87200","10.40619","0.01572"
"20861","125.13000","10.42771","0.01657"
"20904","125.38800","10.44918","0.01643"
"20947","125.64600","10.47070","0.01665"
"20990","125.90400","10.49223","0.01642"
"21033","126.16200","10.51369","0.01712"
"21076","126.42000","10.53522","0.01655"
"21119","126.67800","10.55668","0.01720"
"21162","126.93600","10.57820","0.01748"
"21205","127.19400","10.59973","0.01706"
"21248","127.45200","10.62119","0.01695"
"21291","127.71000","10.64272","0.01787"
"21334","127.96800","10.66424","0.01788"
"21377","128.22600","10.68571","0.01723"
"21420","128.48400","10.70723","0.01709"
"21463","128.74200","10.72869","0.01588"
"21506","129.00000","10.75028","0.01625"
"21549","129.25800","10.77168","0.01646"
"21592","129.51600","10.79321","0.01743"
"21635","129.77400","10.81467","0.01774"
"21678","130.03200","10.83626","0.01737"
"21721","130.29000","10.85772","0.01720"
"21764","130.54800","10.87924","0.01797"
"21807","130.80600","10.90071","0.01721"
"21850","131.06400","10.92229","0.01842"
"21893","131.32200","10.94370","0.01838"
"21936","131.58000","10.96522","0.01757"
"21979","131.83800","10.98669","0.01810"
"22022","132.09600","11.00821","0.01741"
"22065","132.35400","11.02973","0.01810"
"22108","132.61200","11.05126","0.01874"
"22151","132.87000","11.07272","0.01908"
"22194","133.12800","11.09419","0.01896"
"22237","133.38600","11.11577","0.01905"
"22280","133.64400","11.13718","0.01904"
"22323","133.90200","11.15876","0.01900"
"22366","134.16000","11.18016","0.01933"
"22409","134.41800","11.20169","0.01931"
"22452","134.67600","11.22315","0.01987"
"22495","134.93400","11.24474","0.01947"
"22538","135.19200","11.26620","0.01997"
"22581","135.45000","11.28779","0.01977"
"22624","135.70800","11.30919","0.02024"
"22667","135.96600","11.33071","0.02100"
"22710","136.22400","11.35218","0.02075"
"22753","136.48200","11.37376","0.02039"
"22796","136.74000","11.39517","0.02040"
"22839","136.99800","11.41669","0.02120"
"22882","137.25600","11.43822","0.02083"
"22925","137.51400","11.45974","0.02083"
"22968","137.77200","11.48127","0.02130"
"23011","138.03000","11.50273","0.02142"
"23054","138.28800","11.52419","0.02177"
"23097","138.54600","11.54572","0.02170"
"23140","138.80400","11.56724","0.02180"
"23183","139.06200","11.58877","0.02196"
"23226","139.32000","11.61023","0.02192"
"23269","139.57800","11.63170","0.02201"
"23312","139.83600","11.65322","0.02206"
"23355","140.09400","11.67468","0.02179"
"23398","140.35200","11.69621","0.02171"
"23441","140.61000","11.71767","0.02259"
"23484","140.86800","11.73926","0.02244"
"23527","141.12600","11.76066","0.02233"
"23570","141.38400","11.78225","0.02251"
"23613","141.64200","11.80371","0.02338"
"23656","141.90000","11.82523","0.02307"
"23699","142.15800","11.84670","0.02312"
"23742","142.41600","11.86816","0.02306"
"23785","142.67400","11.88969","0.02343"
"23828","142.93200","11.91127","0.02321"
"23871","143.19000","11.93273","0.02383"
"23914","143.44800","11.95426","0.02332"
"23957","143.70600","11.97572","0.02381"
"24000","143.96400","11.99719","0.02402"
"24043","144.22200","12.01871","0.02411"
"24086","144.48000","12.04024","0.02412"
"24129","144.73800","12.06170","0.02443"
"24172","144.99600","12.08323","0.02477"
"24215","145.25400","12.10469","0.02511"
"24258","145.51200","12.12621","0.02543"
"24301","145.77000","12.14768","0.02531"
"24344","146.02800","12.16920","0.02540"
"24387","146.28600","12.19079","0.02518"
"24430","146.54400","12.21219","0.02532"
"24473","146.80200","12.23372","0.02490"
"24516","147.06000","12.25512","0.02369"
"24559","147.31800","12.27676","0.02391"
"24602","147.57600","12.29817","0.02328"
"24645","147.83400","12.31975","0.02356"
"24688","148.09200","12.34122","0.02311"
"24731","148.35000","12.36274","0.02355"
"24774","148.60800","12.38421","0.02378"
"24817","148.86600","12.40573","0.02373"
"24860","149.12400","12.42719","0.02369"
"24903","149.38200","12.44878","0.02235"
"24946","149.64000","12.47018","0.02303"
"24989","149.89800","12.49171","0.02289"
"25032","150.15600","12.51317","0.02366"
"25075","150.41400","12.53476","0.02423"
"25118","150.67200","12.55622","0.02376"
"25161","150.93000","12.57768","0.02393"
"25204","151.18800","12.59921","0.02395"
"25247","151.44600","12.62073","0.02407"
"25290","151.70400","12.64226","0.02451"
"25333","151.96200","12.66366","0.02450"
"25376","152.22000","12.68525","0.02434"
"25419","152.47800","12.70671","0.02449"
"25462","152.73600","12.72824","0.02496"
"25505","152.99400","12.74970","0.02514"
"25548","153.25200","12.77122","0.02517"
"25591","153.51000","12.79269","0.02582"
"25634","153.76800","12.81421","0.02573"
"25677","154.02600","12.83568","0.02608"
"25720","154.28400","12.85726","0.02581"
"25763","154.54200","12.87873","0.02624"
"25806","154.80000","12.90019","0.02611"
"25849","155.05800","12.92171","0.02640"
"25892","155.31600","12.94324","0.02686"
"25935","155.57400","12.96470","0.02721"
"25978","155.83200","12.98629","0.02737"
"26021","156.09000","13.00775","0.02760"
"26064","156.34800","13.02928","0.02725"
"26107","156.60600","13.05068","0.02701"
"26150","156.86400","13.07226","0.02799"
"26193","157.12200","13.09373","0.02763"
"26236","157.38000","13.11519","0.02712"
"26279","157.63800","13.13672","0.02737"
"26322","157.89600","13.15818","0.02726"
"26365","158.15400","13.17976","0.02723"
"26408","158.41200","13.20123","0.02752"
"26451","158.67000","13.22275","0.02814"
"26494","158.92800","13.24422","0.02777"
"26537","159.18600","13.26574","0.02797"
"26580","159.44400","13.28727","0.02769"
"26623","159.70200","13.30873","0.02792"
"26666","159.96000","13.33014","0.02813"
"26709","160.21800","13.35172","0.02787"
"26752","160.47600","13.37319","0.02802"
"26795","160.73400","13.39471","0.02809"
"26838","160.99200","13.41623","0.02815"
"26881","161.25000","13.43770","0.02830"
"26924","161.50800","13.45922","0.02774"
"26967","161.76600","13.48075","0.02729"
"27010","162.02400","13.50221","0.02766"
"27053","162.28200","13.52374","0.02704"
"27096","162.54000","13.54520","0.02751"
"27139","162.79800","13.56672","0.02745"
"27182","163.05600","13.58825","0.02761"
"27225","163.31400","13.60977","0.02822"
"27268","163.57200","13.63124","0.02866"
"27311","163.83000","13.65270","0.02882"
"27354","164.08800","13.67423","0.02814"
"27397","164.34600","13.69569","0.02881"
"27440","164.60400","13.71727","0.02817"
"27483","164.86200","13.73868","0.02837"
"27526","165.12000","13.76020","0.02726"
"27569","165.37800","13.78167","0.02751"
"27612","165.63600","13.80319","0.02755"
"27655","165.89400","13.82472","0.02827"
"27698","166.15200","13.84624","0.02863"
"27741","166.41000","13.86764","0.02813"
"27784","166.66800","13.88917","0.02868"
"27827","166.92600","13.91069","0.02890"
"27870","167.18400","13.93228","0.02895"
"27913","167.44200","13.95368","0.02871"
"27956","167.70000","13.97520","0.02866"
"27999","167.95800","13.99673","0.02933"
"28042","168.21600","14.01825","0.02926"
"28085","168.47400","14.03972","0.02942"
"28128","168.73200","14.06124","0.03028"
"28171","168.99000","14.08271","0.03000"
"28214","169.24800","14.10423","0.03030"
"28257","169.50600","14.12576","0.03026"
"28300","169.76400","14.14722","0.03067"
"28343","170.02200","14.16875","0.03085"
"28386","170.28000","14.19021","0.03092"
"28429","170.53800","14.21167","0.03060"
"28472","170.79600","14.23320","0.03083"
"28515","171.05400","14.25472","0.03078"
"28558","171.31200","14.27619","0.03106"
"28601","171.57000","14.29771","0.03078"
"28644","171.82800","14.31918","0.03070"
"28687","172.08600","14.34076","0.03103"
"28730","172.34400","14.36222","0.03080"
"28773","172.60200","14.38369","0.03122"
"28816","172.86000","14.40515","0.03152"
"28859","173.11800","14.42674","0.03157"
"28902","173.37600","14.44814","0.03172"
"28945","173.63400","14.46972","0.03195"
"28988","173.89200","14.49119","0.03126"
"29031","174.15000","14.51271","0.03146"
"29074","174.40800","14.53418","0.03174"
"29117","174.66600","14.55582","0.03136"
"29160","174.92400","14.57723","0.03183"
"29203","175.18200","14.59869","0.03180"
"29246","175.44000","14.62021","0.03206"
"29289","175.69800","14.64174","0.03213"
"29332","175.95600","14.66320","0.02737"
"29375","176.21400","14.68473","0.02845"
"29418","176.47200","14.70625","0.02839"
"29461","176.73000","14.72772","0.02810"
"29504","176.98800","14.74924","0.02881"
"29547","177.24600","14.77071","0.02884"
"29590","177.50400","14.79223","0.02906"
"29633","177.76200","14.81363","0.02947"
"29676","178.02000","14.83522","0.02966"
"29719","178.27800","14.85668","0.02976"
"29762","178.53600","14.87827","0.03023"
"29805","178.79400","14.89973","0.03014"
"29848","179.05200","14.92120","0.03048"
"29891","179.31000","14.94272","0.03013"
"29934","179.56800","14.96424","0.03086"
"29977","179.82600","14.98571","0.03116"
"30020","180.08400","15.00729","0.03097"
"30063","180.34200","15.02870","0.03107"
"30106","180.60000","15.05022","0.03140"
"30149","180.85800","15.07169","0.03149"
"30192","181.11600","15.09327","0.03172"
"30235","181.37400","15.11473","0.02681"
"30278","181.63200","15.13626","0.01017"
"30321","181.89000","15.15766","0.01199"
"30364","182.14800","15.17925","0.01122"
"30407","182.40600","15.20077","0.00765"
"30450","182.66400","15.22224","0.01130"
"30493","182.92200","15.24370","0.00986"
"30536","183.18000","15.26517","0.01034"
"30579","183.43800","15.28669","0.01229"
"30622","183.69600","15.30821","0.01133"
"30665","183.95400","15.32974","0.01145"
"30708","184.21200","15.35114","0.01312"
"30751","184.47000","15.37279","0.01308"
"30794","184.72800","15.39419","0.01289"
"30837","184.98600","15.41572","0.01460"
"30880","185.24400","15.43718","0.01468"
"30923","185.50200","15.45870","0.01563"
"30966","185.76000","15.48011","0.01564"
"31009","186.01800","15.50175","0.01718"
"31052","186.27600","15.52322","0.01691"
"31095","186.53400","15.54474","0.01816"
"31138","186.79200","15.56621","0.01831"
"31181","187.05000","15.58773","0.01896"
"31224","187.30800","15.60919","0.01910"
"31267","187.56600","15.63078","0.02039"
"31310","187.82400","15.65218","0.01935"
"31353","188.08200","15.67371","0.02165"
"31396","188.34000","15.69517","0.02142"
"31439","188.59800","15.71669","0.02236"
"31482","188.85600","15.73822","0.02184"
"31525","189.11400","15.75974","0.02295"
"31568","189.37200","15.78121","0.02247"
"31611","189.63000","15.80273","0.02334"
"31654","189.88800","15.82420","0.02225"
"31697","190.14600","15.84572","0.02380"
"31740","190.40400","15.86724","0.02321"
"31783","190.66200","15.88865","0.02405"
"31826","190.92000","15.91023","0.02430"
"31869","191.17800","15.93164","0.02510"
"31912","191.43600","15.95328","0.02495"
"31955","191.69400","15.97469","0.02547"
"31998","191.95200","15.99621","0.02635"
"32041","192.21000","16.01768","0.02580"
"32084","192.46800","16.03926","0.02611"
"32127","192.72600","16.06072","0.02714"
"32170","192.98400","16.08225","0.02638"
"32213","193.24200","16.10365","0.02699"
"32256","193.50000","16.12524","0.02698"
"32299","193.75800","16.14670","0.02719"
"32342","194.01600","16.16823","0.02758"
"32385","194.27400","16.18975","0.02808"
"32428","194.53200","16.21121","0.02817"
"32471","194.79000","16.23268","0.02881"
"32514","195.04800","16.25414","0.02884"
"32557","195.30600","16.27573","0.02917"
"32600","195.56400","16.29719","0.02943"
"32643","195.82200","16.31872","0.02974"
"32686","196.08000","16.34024","0.02976"
"32729","196.33800","16.36170","0.03020"
"32772","196.59600","16.38323","0.03027"
"32815","196.85400","16.40469","0.03069"
"32858","197.11200","16.42616","0.03063"
"32901","197.37000","16.44774","0.03116"
"32944","197.62800","16.46921","0.03126"
"32987","197.88600","16.49073","0.03165"
"33030","198.14400","16.51220","0.03186"
"33073","198.40200","16.53372","0.03202"
"33116","198.66000","16.55518","0.03194"
"33159","198.91800","16.57677","0.03226"
"33202","199.17600","16.59823","0.03261"
"33245","199.43400","16.61970","0.03256"
"33288","199.69200","16.64116","0.03241"
"33331","199.95000","16.66280","0.03296"
"33374","200.20800","16.68421","0.03291"
"33417","200.46600","16.70573","0.03327"
"33460","200.72400","16.72720","0.03328"
"33503","200.98200","16.74872","0.03387"
"33546","201.24000","16.77019","0.03405"
"33589","201.49800","16.79171","0.03404"
"33632","201.75600","16.81324","0.03403"
"33675","202.01400","16.83470","0.03443"
"33718","202.27200","16.85622","0.03493"
"33761","202.53000","16.87769","0.03465"
"33804","202.78800","16.89927","0.03512"
"33847","203.04600","16.92074","0.03489"
"33890","203.30400","16.94220","0.03583"
"33933","203.56200","16.96367","0.03542"
"33976","203.82000","16.98519","0.03603"
"34019","204.07800","17.00665","0.03573"
"34062","204.33600","17.02824","0.03681"
"34105","204.59400","17.04964","0.03682"
"34148","204.85200","17.07117","0.03736"
"34191","205.11000","17.09269","0.03780"
"34234","205.36800","17.11422","0.03796"
"34277","205.62600","17.13568","0.03842"
"34320","205.88400","17.15720","0.03864"
"34363","206.14200","17.17867","0.03821"
"34406","206.40000","17.20025","0.03853"
"34449","206.65800","17.22178","0.03914"
"34492","206.91600","17.24330","0.03942"
"34535","207.17400","17.26471","0.04000"
"34578","207.43200","17.28623","0.03994"
"34621","207.69000","17.30775","0.04005"
"34664","207.94800","17.32922","0.03977"
"34707","208.20600","17.35074","0.04009"
"34750","208.46400","17.37221","0.04005"
"34793","208.72200","17.39373","0.04048"
"34836","208.98000","17.41520","0.03880"
"34879","209.23800","17.43672","0.03984"
"34922","209.49600","17.45819","0.03979"
"34965","209.75400","17.47971","0.04034"
"35008","210.01200","17.50117","0.04050"
"35051","210.27000","17.52276","0.03931"
"35094","210.52800","17.54416","0.03903"
"35137","210.78600","17.56575","0.03973"
"35180","211.04400","17.58715","0.03958"
"35223","211.30200","17.60868","0.03955"
"35266","211.56000","17.63020","0.04001"
"35309","211.81800","17.65178","0.04008"
"35352","212.07600","17.67319","0.04005"
"35395","212.33400","17.69471","0.04023"
"35438","212.59200","17.71618","0.04073"
"35481","212.85000","17.73770","0.04159"
"35524","213.10800","17.75922","0.04164"
"35567","213.36600","17.78069","0.04252"
"35610","213.62400","17.80215","0.03040"
"35653","213.88200","17.82374","0.02537"
"35696","214.14000","17.84520","0.02522"
"35739","214.39800","17.86673","0.02903"
"35782","214.65600","17.88819","0.02757"
"35825","214.91400","17.90965","0.02827"
"35868","215.17200","17.93124","0.02884"
"35911","215.43000","17.95271","0.02911"
"35954","215.68800","17.97423","0.02848"
"35997","215.94600","17.99563","0.03066"
"36040","216.20400","18.01722","0.02990"
"36083","216.46200","18.03862","0.03044"
"36126","216.72000","18.06021","0.03068"
"36169","216.97800","18.08167","0.03123"
"36212","217.23600","18.10325","0.03058"
"36255","217.49400","18.12472","0.03211"
"36298","217.75200","18.14624","0.03166"
"36341","218.01000","18.16771","0.03193"
"36384","218.26800","18.18923","0.03197"
"36427","218.52600","18.21070","0.03262"
"36470","218.78400","18.23222","0.03244"
"36513","219.04200","18.25368","0.03255"
"36556","219.30000","18.27521","0.03315"
"36599","219.55800","18.29673","0.03349"
"36642","219.81600","18.31820","0.03319"
"36685","220.07400","18.33966","0.03391"
"36728","220.33200","18.36125","0.03455"
"36771","220.59000","18.38271","0.03412"
"36814","220.84800","18.40417","0.03479"
"36857","221.10600","18.42570","0.03452"
"36900","221.36400","18.44716","0.03547"
"36943","221.62200","18.46869","0.03453"
"36986","221.88000","18.49021","0.03382"
"37029","222.13800","18.51174","0.03359"
"37072","222.39600","18.53320","0.03383"
"37115","222.65400","18.55473","0.03365"
"37158","222.91200","18.57619","0.03432"
"37201","223.17000","18.59777","0.03397"
"37244","223.42800","18.61918","0.03443"
"37287","223.68600","18.64070","0.03428"
"37330","223.94400","18.66217","0.03510"
"37373","224.20200","18.68375","0.03429"
"37416","224.46000","18.70516","0.03492"
"37459","224.71800","18.72674","0.03446"
"37502","224.97600","18.74820","0.03476"
"37545","225.23400","18.76973","0.03492"
"37588","225.49200","18.79119","0.03503"
"37631","225.75000","18.81278","0.03521"
"37674","226.00800","18.83424","0.03512"
"37717","226.26600","18.85571","0.03551"
"37760","226.52400","18.87723","0.03534"
"37803","226.78200","18.89869","0.03608"
"37846","227.04000","18.92028","0.03550"
"37889","227.29800","18.94174","0.03587"
"37932","227.55600","18.96321","0.03605"
"37975","227.81400","18.98467","0.03679"
"38018","228.07200","19.00626","0.03598"
"38061","228.33000","19.02772","0.03672"
"38104","228.58800","19.04924","0.03643"
"38147","228.84600","19.07065","0.03660"
"38190","229.10400","19.09223","0.03676"
"38233","229.36200","19.11370","0.03685"
"38276","229.62000","19.13522","0.03707"
"38319","229.87800","19.15675","0.03716"
"38362","230.13600","19.17827","0.03766"
"38405","230.39400","19.19973","0.03777"
"38448","230.65200","19.22126","0.03760"
"38491","230.91000","19.24266","0.03760"
"38534","231.16800","19.26425","0.03844"
"38577","231.42600","19.28565","0.03790"
"38620","231.68400","19.30718","0.03879"
"38663","231.94200","19.32864","0.03836"
"38706","232.20000","19.35023","0.03858"
"38749","232.45800","19.37175","0.03924"
"38792","232.71600","19.39321","0.03895"
"38835","232.97400","19.41468","0.03905"
"38878","233.23200","19.43620","0.03957"
"38921","233.49000","19.45778","0.03953"
"38964","233.74800","19.47925","0.04002"
"39007","234.00600","19.50072","0.04045"
"39050","234.26400","19.52218","0.03994"
"39093","234.52200","19.54376","0.04103"
"39136","234.78000","19.56523","0.04052"
"39179","235.03800","19.58675","0.04143"
"39222","235.29600","19.60810","0.04054"
"39265","235.55400","19.62968","0.04121"
"39308","235.81200","19.65121","0.04068"
"39351","236.07000","19.67273","0.04179"
"39394","236.32800","19.69419","0.04187"
"39437","236.58600","19.71572","0.04227"
"39480","236.84400","19.73718","0.04257"
"39523","237.10200","19.75871","0.04181"
"39566","237.36000","19.78023","0.04187"
"39609","237.61800","19.80175","0.04210"
"39652","237.87600","19.82322","0.04284"
"39695","238.13400","19.84474","0.04247"
"39738","238.39200","19.86621","0.04291"
"39781","238.65000","19.88779","0.04234"
"39824","238.90800","19.90920","0.04320"
"39867","239.16600","19.93072","0.04316"
"39910","239.42400","19.95218","0.04318"
"39953","239.68200","19.97365","0.04327"
"39996","239.94000","19.99524","0.04369"
"40039","240.19800","20.01670","0.04416"
"40082","240.45600","20.03822","0.04439"
"40125","240.71400","20.05969","0.04346"
"40168","240.97200","20.08121","0.04310"
"40211","241.23000","20.10267","0.04344"
"40254","241.48800","20.12426","0.04324"
"40297","241.74600","20.14566","0.04395"
"40340","242.00400","20.16725","0.04369"
"40383","242.26200","20.18871","0.04455"
"40426","242.52000","20.21030","0.04414"
"40469","242.77800","20.23164","0.04485"
"40512","243.03600","20.25323","0.04431"
"40555","243.29400","20.27469","0.04490"
"40598","243.55200","20.29628","0.04514"
"40641","243.81000","20.31768","0.04451"
"40684","244.06800","20.33920","0.04401"
"40727","244.32600","20.36067","0.04337"
"40770","244.58400","20.38225","0.04402"
"40813","244.84200","20.40372","0.04389"
"40856","245.10000","20.42524","0.04448"
"40899","245.35800","20.44676","0.04405"
"40942","245.61600","20.46823","0.04420"
"40985","245.87400","20.48969","0.04406"
"41028","246.13200","20.51122","0.04410"
"41071","246.39000","20.53274","0.04414"
"41114","246.64800","20.55421","0.04428"
"41157","246.90600","20.57573","0.04542"
"41200","247.16400","20.59719","0.04492"
"41243","247.42200","20.61878","0.04587"
"41286","247.68000","20.64018","0.04621"
"41329","247.93800","20.66171","0.04649"
"41372","248.19600","20.68317","0.04670"
"41415","248.45400","20.70470","0.04729"
"41458","248.71200","20.72622","0.04690"
"41501","248.97000","20.74775","0.04657"
"41544","249.22800","20.76915","0.04638"
"41587","249.48600","20.79079","0.04557"
"41630","249.74400","20.81220","0.04579"
"41673","250.00200","20.83378","0.04527"
"41716","250.26000","20.85518","0.04588"
"41759","250.51800","20.87671","0.04551"
"41802","250.77600","20.89817","0.04592"
"41845","251.03400","20.91976","0.04588"
"41888","251.29200","20.94122","0.04516"
"41931","251.55000","20.96275","0.04367"
"41974","251.80800","20.98421","0.04481"
"42017","252.06600","21.00567","0.04493"
"42060","252.32400","21.02720","0.04572"
"42103","252.58200","21.04873","0.04640"
"42146","252.84000","21.07025","0.04641"
"42189","253.09800","21.09171","0.04712"
"42232","253.35600","21.11324","0.04745"
"42275","253.61400","21.13470","0.04867"
"42318","253.87200","21.15629","0.04842"
"42361","254.13000","21.17769","0.04983"
"42404","254.38800","21.19921","0.04934"
"42447","254.64600","21.22068","0.04865"
"42490","254.90400","21.24220","0.04917"
"42533","255.16200","21.26373","0.04973"
"42576","255.42000","21.28526","0.05110"
"42619","255.67800","21.30672","0.04709"
"42662","255.93600","21.32818","0.04594"
"42705","256.19400","21.34971","0.04413"
"42748","256.45200","21.37129","0.04361"
"42791","256.71000","21.39270","0.04339"
"42834","256.96800","21.41422","0.04427"
"42877","257.22600","21.43568","0.04494"
"42920","257.48400","21.45721","0.04528"
"42963","257.74200","21.47873","0.04607"
"43006","258.00000","21.50025","0.04626"
"43049","258.25800","21.52172","0.04757"
"43092","258.51600","21.54324","0.04653"
"43135","258.77400","21.56465","0.04701"
"43178","259.03200","21.58623","0.04762"
"43221","259.29000","21.60776","0.04735"
"43264","259.54800","21.62916","0.04756"
"43307","259.80600","21.65069","0.04820"
"43350","260.06400","21.67215","0.04832"
"43393","260.32200","21.69374","0.04817"
"43436","260.58000","21.71514","0.04938"
"43479","260.83800","21.73672","0.04911"
"43522","261.09600","21.75819","0.04967"
"43565","261.35400","21.77971","0.05000"
"43608","261.61200","21.80118","0.05128"
"43651","261.87000","21.82276","0.05103"
"43694","262.12800","21.84416","0.05192"
"43737","262.38600","21.86569","0.05218"
"43780","262.64400","21.88721","0.05279"
"43823","262.90200","21.90874","0.05295"
"43866","263.16000","21.93020","0.05314"
"43909","263.41800","21.95167","0.05413"
"43952","263.67600","21.97319","0.05395"
"43995","263.93400","21.99471","0.05445"
"44038","264.19200","22.01624","0.05504"
"44081","264.45000","22.03770","0.05556"
"44124","264.70800","22.05923","0.05545"
"44167","264.96600","22.08075","0.05595"
"44210","265.22400","22.10222","0.05633"
"44253","265.48200","22.12374","0.05670"
"44296","265.74000","22.14527","0.05701"
"44339","265.99800","22.16667","0.05697"
"44382","266.25600","22.18826","0.05766"
"44425","266.51400","22.20972","0.05731"
"44468","266.77200","22.23124","0.05786"
"44511","267.03000","22.25265","0.05876"
"44554","267.28800","22.27417","0.05896"
"44597","267.54600","22.29564","0.05957"
"44640","267.80400","22.31722","0.06060"
"44683","268.06200","22.33868","0.06090"
"44726","268.32000","22.36027","0.06124"
"44769","268.57800","22.38173","0.06148"
"44812","268.83600","22.40326","0.06196"
"44855","269.09400","22.42472","0.06145"
"44898","269.35200","22.44625","0.06253"
"44941","269.61000","22.46771","0.06399"
"44984","269.86800","22.48918","0.06437"
"45027","270.12600","22.51070","0.06565"
"45070","270.38400","22.53222","0.06660"
"45113","270.64200","22.55375","0.06759"
"45156","270.90000","22.57521","0.06845"
"45199","271.15800","22.59668","0.06846"
"45242","271.41600","22.61814","0.06930"
"45285","271.67400","22.63978","0.06981"
"45328","271.93200","22.66119","0.07036"
"45371","272.19000","22.68277","0.07158"
"45414","272.44800","22.70418","0.07216"
"45457","272.70600","22.72570","0.07299"
"45500","272.96400","22.74717","0.07414"
"45543","273.22200","22.76875","0.07493"
"45586","273.48000","22.79015","0.07078"
"45629","273.73800","22.81174","0.07164"
"45672","273.99600","22.83321","0.07136"
"45715","274.25400","22.85473","0.07139"
"45758","274.51200","22.87619","0.07292"
"45801","274.77000","22.89772","0.07397"
"45844","275.02800","22.91912","0.07430"
"45887","275.28600","22.94077","0.07468"
"45930","275.54400","22.96223","0.07525"
"45973","275.80200","22.98381","0.07525"
"46016","276.06000","23.00516","0.07656"
"46059","276.31800","23.02674","0.07661"
"46102","276.57600","23.04820","0.07686"
"46145","276.83400","23.06973","0.07800"
"46188","277.09200","23.09126","0.07865"
"46231","277.35000","23.11272","0.07787"
"46274","277.60800","23.13424","0.07801"
"46317","277.86600","23.15571","0.07860"
"46360","278.12400","23.17723","0.07888"
"46403","278.38200","23.19870","0.07951"
"46446","278.64000","23.22028","0.07995"
"46489","278.89800","23.24163","0.08029"
"46532","279.15600","23.26321","0.08052"
"46575","279.41400","23.28468","0.08079"
"46618","279.67200","23.30626","0.08121"
"46661","279.93000","23.32766","0.08133"
"46704","280.18800","23.34919","0.08142"
"46747","280.44600","23.37065","0.08173"
"46790","280.70400","23.39230","0.08216"
"46833","280.96200","23.41370","0.08230"
"46876","281.22000","23.43523","0.08236"
"46919","281.47800","23.45669","0.08322"
"46962","281.73600","23.47827","0.08299"
"47005","281.99400","23.49974","0.08363"
"47048","282.25200","23.52126","0.08361"
"47091","282.51000","23.54267","0.08337"
"47134","282.76800","23.56419","0.08387"
"47177","283.02600","23.58566","0.08440"
"47220","283.28400","23.60724","0.08434"
"47263","283.54200","23.62876","0.08492"
"47306","283.80000","23.65023","0.08560"
"47349","284.05800","23.67175","0.08625"
"47392","284.31600","23.69322","0.08721"
"47435","284.57400","23.71474","0.08769"
"47478","284.83200","23.73621","0.08748"
"47521","285.09000","23.75773","0.08858"
"47564","285.34800","23.77919","0.08950"
"47607","285.60600","23.80072","0.09093"
"47650","285.86400","23.82218","0.09159"
"47693","286.12200","23.84377","0.09222"
"47736","286.38000","23.86517","0.09375"
"47779","286.63800","23.88676","0.09510"
"47822","286.89600","23.90816","0.09574"
"47865","287.15400","23.92974","0.09738"
"47908","287.41200","23.95121","0.09823"
"47951","287.67000","23.97273","0.09869"
"47994","287.92800","23.99420","0.10008"
"48037","288.18600","24.01572","0.10032"
"48080","288.44400","24.03725","0.10143"
"48123","288.70200","24.05871","0.10235"
"48166","288.96000","24.08017","0.10382"
"48209","289.21800","24.10176","0.10482"
"48252","289.47600","24.12322","0.10566"
"48295","289.73400","24.14469","0.10660"
"48338","289.99200","24.16621","0.10576"
"48381","290.25000","24.18768","0.10690"
"48424","290.50800","24.20926","0.10740"
"48467","290.76600","24.23072","0.10701"
"48510","291.02400","24.25225","0.10798"
"48553","291.28200","24.27365","0.10841"
"48596","291.54000","24.29518","0.10844"
"48639","291.79800","24.31664","0.10908"
"48682","292.05600","24.33822","0.11059"
"48725","292.31400","24.35969","0.11128"
"48768","292.57200","24.38121","0.11201"
"48811","292.83000","24.40268","0.11305"
"48854","293.08800","24.42426","0.11378"
"48897","293.34600","24.44567","0.11429"
"48940","293.60400","24.46725","0.11517"
"48983","293.86200","24.48872","0.11587"
"49026","294.12000","24.51024","0.11660"
"49069","294.37800","24.53171","0.11693"
"49112","294.63600","24.55323","0.11601"
"49155","294.89400","24.57475","0.11661"
"49198","295.15200","24.59622","0.11759"
"49241","295.41000","24.61768","0.11820"
"49284","295.66800","24.63921","0.11898"
"49327","295.92600","24.66073","0.11917"
"49370","296.18400","24.68219","0.11968"
"49413","296.44200","24.70372","0.11951"
"49456","296.70000","24.72518","0.12052"
"49499","296.95800","24.74677","0.12045"
"49542","297.21600","24.76817","0.12115"
"49585","297.47400","24.78976","0.12185"
"49628","297.73200","24.81116","0.12198"
"49671","297.99000","24.83269","0.12294"
"49714","298.24800","24.85421","0.12347"
"49757","298.50600","24.87574","0.12419"
"49800","298.76400","24.89720","0.12410"
"49843","299.02200","24.91866","0.12456"
"49886","299.28000","24.94019","0.12532"
"49929","299.53800","24.96171","0.12573"
"49972","299.79600","24.98318","0.12630"
"50015","300.05400","25.00476","0.12633"
"50058","300.31200","25.02617","0.12680"
"50101","300.57000","25.04775","0.12736"
"50144","300.82800","25.06921","0.12784"
"50187","301.08600","25.09074","0.11777"
"50230","301.34400","25.11226","0.11502"
"50273","301.60200","25.13373","0.10547"
"50316","301.86000","25.15519","0.10957"
"50359","302.11800","25.17671","0.10927"
"50402","302.37600","25.19824","0.11134"
"50445","302.63400","25.21970","0.11357"
"50488","302.89200","25.24123","0.11310"
"50531","303.15000","25.26269","0.11571"
"50574","303.40800","25.28422","0.11421"
"50617","303.66600","25.30568","0.11496"
"50660","303.92400","25.32726","0.11517"
"50703","304.18200","25.34861","0.11490"
"50746","304.44000","25.37025","0.11699"
"50789","304.69800","25.39166","0.11834"
"50832","304.95600","25.41324","0.11608"
"50875","305.21400","25.43471","0.11783"
"50918","305.47200","25.45617","0.11838"
"50961","305.73000","25.47775","0.11966"
"51004","305.98800","25.49922","0.12100"
"51047","306.24600","25.52062","0.12152"
"51090","306.50400","25.54221","0.12103"
"51133","306.76200","25.56367","0.12246"
"51176","307.02000","25.58520","0.12284"
"51219","307.27800","25.60672","0.12408"
"51262","307.53600","25.62825","0.12438"
"51305","307.79400","25.64977","0.12511"
"51348","308.05200","25.67123","0.12644"
"51391","308.31000","25.69270","0.12682"
"51434","308.56800","25.71416","0.12771"
"51477","308.82600","25.73569","0.12837"
"51520","309.08400","25.75721","0.12834"
"51563","309.34200","25.77874","0.12884"
"51606","309.60000","25.80020","0.12973"
"51649","309.85800","25.82172","0.13025"
"51692","310.11600","25.84319","0.13132"
"51735","310.37400","25.86471","0.13242"
"51778","310.63200","25.88618","0.13295"
"51821","310.89000","25.90770","0.13393"
"51864","311.14800","25.92917","0.13431"
"51907","311.40600","25.95075","0.13384"
"51950","311.66400","25.97221","0.13537"
"51993","311.92200","25.99374","0.13580"
"52036","312.18000","26.01520","0.13747"
"52079","312.43800","26.03673","0.13883"
"52122","312.69600","26.05819","0.14043"
"52165","312.95400","26.07972","0.14272"
"52208","313.21200","26.10118","0.14483"
"52251","313.47000","26.12276","0.14616"
"52294","313.72800","26.14423","0.14880"
"52337","313.98600","26.16569","0.15029"
"52380","314.24400","26.18722","0.15291"
"52423","314.50200","26.20868","0.15601"
"52466","314.76000","26.23021","0.15848"
"52509","315.01800","26.25173","0.16104"
"52552","315.27600","26.27325","0.16481"
"52595","315.53400","26.29472","0.16675"
"52638","315.79200","26.31618","0.16903"
"52661","315.92800","26.32754","0.17125"