File: Trajectories_together/170226_3Specimen_RawData_2.csv
"","V1","V2","V3"
"1","End date","2/26/2017",""
"2","Specimen label","7CG_50",""
"3","Maximum Load","0.10801","N"
"4","Time","Extension","Load"
"5","(s)","(mm)","(N)"
"6","0.00000","0.00000","0.00006"
"46","0.24000","0.01853","0.00087"
"86","0.48000","0.04030","0.00217"
"126","0.72000","0.06021","0.00232"
"166","0.96000","0.08024","0.00342"
"206","1.20000","0.10027","0.00320"
"246","1.44000","0.12012","0.00369"
"286","1.68000","0.14027","0.00451"
"326","1.92000","0.16018","0.00529"
"366","2.16000","0.18027","0.00595"
"406","2.40000","0.20024","0.00582"
"446","2.64000","0.22020","0.00613"
"486","2.88000","0.24023","0.00634"
"526","3.12000","0.26020","0.00675"
"566","3.36000","0.28017","0.00702"
"606","3.60000","0.30014","0.00742"
"646","3.84000","0.32023","0.00755"
"686","4.08000","0.34020","0.00756"
"726","4.32000","0.36023","0.00771"
"766","4.56000","0.38020","0.00800"
"806","4.80000","0.40017","0.00850"
"846","5.04000","0.42020","0.00838"
"886","5.28000","0.44023","0.00818"
"926","5.52000","0.46020","0.00872"
"966","5.76000","0.48017","0.00908"
"1006","6.00000","0.50026","0.00924"
"1046","6.24000","0.52017","0.00904"
"1086","6.48000","0.54026","0.00934"
"1126","6.72000","0.56017","0.00977"
"1166","6.96000","0.58026","0.00920"
"1206","7.20000","0.60017","0.00878"
"1246","7.44000","0.62020","0.00994"
"1286","7.68000","0.64023","0.00975"
"1326","7.92000","0.66014","0.01050"
"1366","8.16000","0.68023","0.00969"
"1406","8.40000","0.70014","0.00993"
"1446","8.64000","0.72022","0.00956"
"1486","8.88000","0.74019","0.01021"
"1526","9.12000","0.76022","0.01025"
"1566","9.36000","0.78019","0.01036"
"1606","9.60000","0.80022","0.01066"
"1646","9.84000","0.82025","0.01039"
"1686","10.08000","0.84016","0.01043"
"1726","10.32000","0.86025","0.01048"
"1766","10.56000","0.88016","0.01049"
"1806","10.80000","0.90019","0.01007"
"1846","11.04000","0.92016","0.01072"
"1886","11.28000","0.94019","0.01056"
"1926","11.52000","0.96016","0.01083"
"1966","11.76000","0.98019","0.00990"
"2006","12.00000","1.00022","0.01001"
"2046","12.24000","1.02019","0.01106"
"2086","12.48000","1.04022","0.01080"
"2126","12.72000","1.06025","0.01069"
"2166","12.96000","1.08016","0.01069"
"2206","13.20000","1.10019","0.01096"
"2246","13.44000","1.12028","0.01117"
"2286","13.68000","1.14019","0.01113"
"2326","13.92000","1.16016","0.01120"
"2366","14.16000","1.18025","0.01098"
"2406","14.40000","1.20022","0.01099"
"2446","14.64000","1.22024","0.01128"
"2486","14.88000","1.24021","0.01131"
"2526","15.12000","1.26018","0.01087"
"2566","15.36000","1.28021","0.01121"
"2606","15.60000","1.30024","0.01088"
"2646","15.84000","1.32015","0.01133"
"2686","16.08000","1.34018","0.01101"
"2726","16.32000","1.36027","0.01071"
"2766","16.56000","1.38018","0.01146"
"2806","16.80000","1.40021","0.01133"
"2846","17.04000","1.42018","0.01143"
"2886","17.28000","1.44021","0.01143"
"2926","17.52000","1.46018","0.01133"
"2966","17.76000","1.48027","0.01152"
"3006","18.00000","1.50018","0.01153"
"3046","18.24000","1.52015","0.01139"
"3086","18.48000","1.54024","0.01128"
"3126","18.72000","1.56015","0.01234"
"3166","18.96000","1.58024","0.01136"
"3206","19.20000","1.60015","0.01147"
"3246","19.44000","1.62018","0.01122"
"3286","19.68000","1.64021","0.01126"
"3326","19.92000","1.66024","0.01144"
"3366","20.16000","1.68021","0.01153"
"3406","20.40000","1.70018","0.01194"
"3446","20.64000","1.72026","0.01171"
"3486","20.88000","1.74017","0.01108"
"3526","21.12000","1.76020","0.01168"
"3566","21.36000","1.78017","0.01154"
"3606","21.60000","1.80020","0.01205"
"3646","21.84000","1.82017","0.01241"
"3686","22.08000","1.84026","0.01150"
"3726","22.32000","1.86017","0.01208"
"3766","22.56000","1.88020","0.01126"
"3806","22.80000","1.90023","0.01204"
"3846","23.04000","1.92020","0.01179"
"3886","23.28000","1.94023","0.01175"
"3926","23.52000","1.96014","0.01176"
"3966","23.76000","1.98023","0.01211"
"4006","24.00000","2.00020","0.01252"
"4046","24.24000","2.02029","0.01180"
"4086","24.48000","2.04020","0.01217"
"4126","24.72000","2.06023","0.01175"
"4166","24.96000","2.08026","0.01197"
"4206","25.20000","2.10023","0.01214"
"4246","25.44000","2.12026","0.01198"
"4286","25.68000","2.14011","0.01228"
"4326","25.92000","2.16026","0.01256"
"4366","26.16000","2.18017","0.01196"
"4406","26.40000","2.20020","0.01235"
"4446","26.64000","2.22016","0.01211"
"4486","26.88000","2.24019","0.01250"
"4526","27.12000","2.26022","0.01247"
"4566","27.36000","2.28019","0.01196"
"4606","27.60000","2.30022","0.01211"
"4646","27.84000","2.32013","0.01217"
"4686","28.08000","2.34028","0.01242"
"4726","28.32000","2.36013","0.01226"
"4766","28.56000","2.38022","0.01203"
"4806","28.80000","2.40019","0.01252"
"4846","29.04000","2.42022","0.01240"
"4886","29.28000","2.44019","0.01220"
"4926","29.52000","2.46022","0.01232"
"4966","29.76000","2.48019","0.01225"
"5006","30.00000","2.50016","0.01246"
"5046","30.24000","2.52025","0.01260"
"5086","30.48000","2.54016","0.01246"
"5126","30.72000","2.56025","0.01210"
"5166","30.96000","2.58016","0.01249"
"5206","31.20000","2.60019","0.01261"
"5246","31.44000","2.62016","0.01283"
"5286","31.68000","2.64025","0.01225"
"5326","31.92000","2.66022","0.01269"
"5366","32.16000","2.68013","0.01279"
"5406","32.40000","2.70027","0.01296"
"5446","32.64000","2.72018","0.01228"
"5486","32.88000","2.74021","0.01232"
"5526","33.12000","2.76018","0.01305"
"5566","33.36000","2.78021","0.01269"
"5606","33.60000","2.80024","0.01241"
"5646","33.84000","2.82027","0.01248"
"5686","34.08000","2.84024","0.01317"
"5726","34.32000","2.86015","0.01294"
"5766","34.56000","2.88024","0.01250"
"5806","34.80000","2.90021","0.01286"
"5846","35.04000","2.92030","0.01303"
"5886","35.28000","2.94021","0.01250"
"5926","35.52000","2.96018","0.01311"
"5966","35.76000","2.98015","0.01295"
"6006","36.00000","3.00024","0.01230"
"6046","36.24000","3.02021","0.01303"
"6086","36.48000","3.04018","0.01246"
"6126","36.72000","3.06021","0.01284"
"6166","36.96000","3.08018","0.01233"
"6206","37.20000","3.10015","0.01261"
"6246","37.44000","3.12018","0.01256"
"6286","37.68000","3.14027","0.01334"
"6326","37.92000","3.16018","0.01248"
"6366","38.16000","3.18021","0.01264"
"6406","38.40000","3.20023","0.01255"
"6446","38.64000","3.22014","0.01288"
"6486","38.88000","3.24023","0.01323"
"6526","39.12000","3.26020","0.01350"
"6566","39.36000","3.28017","0.01273"
"6606","39.60000","3.30020","0.01313"
"6646","39.84000","3.32029","0.01211"
"6686","40.08000","3.34020","0.01255"
"6726","40.32000","3.36023","0.01274"
"6766","40.56000","3.38026","0.01270"
"6806","40.80000","3.40023","0.01292"
"6846","41.04000","3.42020","0.01322"
"6886","41.28000","3.44023","0.01276"
"6926","41.52000","3.46020","0.01285"
"6966","41.76000","3.48017","0.01300"
"7006","42.00000","3.50026","0.01273"
"7046","42.24000","3.52017","0.01303"
"7086","42.48000","3.54026","0.01322"
"7126","42.72000","3.56023","0.01289"
"7166","42.96000","3.58020","0.01300"
"7206","43.20000","3.60023","0.01327"
"7246","43.44000","3.62020","0.01296"
"7286","43.68000","3.64017","0.01283"
"7326","43.92000","3.66014","0.01338"
"7366","44.16000","3.68022","0.01325"
"7406","44.40000","3.70019","0.01317"
"7446","44.64000","3.72022","0.01358"
"7486","44.88000","3.74025","0.01306"
"7526","45.12000","3.76016","0.01346"
"7566","45.36000","3.78025","0.01328"
"7606","45.60000","3.80022","0.01344"
"7646","45.84000","3.82019","0.01328"
"7686","46.08000","3.84016","0.01266"
"7726","46.32000","3.86025","0.01351"
"7766","46.56000","3.88022","0.01330"
"7806","46.80000","3.90019","0.01309"
"7846","47.04000","3.92022","0.01328"
"7886","47.28000","3.94019","0.01369"
"7926","47.52000","3.96022","0.01366"
"7966","47.76000","3.98019","0.01347"
"8006","48.00000","4.00022","0.01323"
"8046","48.24000","4.02019","0.01390"
"8086","48.48000","4.04022","0.01379"
"8126","48.72000","4.06019","0.01374"
"8166","48.96000","4.08022","0.01381"
"8206","49.20000","4.10019","0.01413"
"8246","49.44000","4.12022","0.01423"
"8286","49.68000","4.14019","0.01376"
"8326","49.92000","4.16022","0.01424"
"8366","50.16000","4.18024","0.01353"
"8406","50.40000","4.20015","0.01360"
"8446","50.64000","4.22018","0.01385"
"8486","50.88000","4.24021","0.01387"
"8526","51.12000","4.26024","0.01390"
"8566","51.36000","4.28021","0.01448"
"8606","51.60000","4.30018","0.01382"
"8646","51.84000","4.32021","0.01408"
"8686","52.08000","4.34018","0.01442"
"8726","52.32000","4.36027","0.01415"
"8766","52.56000","4.38012","0.01443"
"8806","52.80000","4.40021","0.01406"
"8846","53.04000","4.42018","0.01501"
"8886","53.28000","4.44021","0.01440"
"8926","53.52000","4.46018","0.01446"
"8966","53.76000","4.48021","0.01465"
"9006","54.00000","4.50024","0.01545"
"9046","54.24000","4.52021","0.01562"
"9086","54.48000","4.54024","0.01490"
"9126","54.72000","4.56009","0.01522"
"9166","54.96000","4.58024","0.01524"
"9206","55.20000","4.60021","0.01528"
"9246","55.44000","4.62024","0.01547"
"9286","55.68000","4.64021","0.01525"
"9326","55.92000","4.66018","0.01485"
"9366","56.16000","4.68021","0.01395"
"9406","56.40000","4.70017","0.01520"
"9446","56.64000","4.72020","0.01554"
"9486","56.88000","4.74011","0.01544"
"9526","57.12000","4.76020","0.01453"
"9566","57.36000","4.78023","0.01534"
"9606","57.60000","4.80020","0.01470"
"9646","57.84000","4.82017","0.01504"
"9686","58.08000","4.84026","0.01552"
"9726","58.32000","4.86023","0.01430"
"9766","58.56000","4.88020","0.01557"
"9806","58.80000","4.90023","0.01614"
"9846","59.04000","4.92014","0.01569"
"9886","59.28000","4.94023","0.01549"
"9926","59.52000","4.96014","0.01495"
"9966","59.76000","4.98023","0.01494"
"10006","60.00000","5.00020","0.01554"
"10046","60.24000","5.02029","0.01620"
"10086","60.48000","5.04026","0.01579"
"10126","60.72000","5.06017","0.01624"
"10166","60.96000","5.08026","0.01564"
"10206","61.20000","5.10017","0.01614"
"10246","61.44000","5.12026","0.01558"
"10286","61.68000","5.14017","0.01632"
"10326","61.92000","5.16026","0.01640"
"10366","62.16000","5.18017","0.01635"
"10406","62.40000","5.20019","0.01669"
"10446","62.64000","5.22022","0.01705"
"10486","62.88000","5.24019","0.01666"
"10526","63.12000","5.26022","0.01619"
"10566","63.36000","5.28013","0.01694"
"10606","63.60000","5.30022","0.01602"
"10646","63.84000","5.32019","0.01641"
"10686","64.08000","5.34028","0.01656"
"10726","64.32000","5.36019","0.01618"
"10766","64.56000","5.38022","0.01622"
"10806","64.80000","5.40019","0.01627"
"10846","65.04000","5.42016","0.01688"
"10886","65.28000","5.44019","0.01708"
"10926","65.52000","5.46022","0.01740"
"10966","65.76000","5.48019","0.01658"
"11006","66.00000","5.50016","0.01691"
"11046","66.24000","5.52025","0.01766"
"11086","66.48000","5.54016","0.01715"
"11126","66.72000","5.56025","0.01697"
"11166","66.96000","5.58022","0.01727"
"11206","67.20000","5.60025","0.01708"
"11246","67.44000","5.62022","0.01663"
"11286","67.68000","5.64019","0.01753"
"11326","67.92000","5.66022","0.01757"
"11366","68.16000","5.68013","0.01721"
"11406","68.40000","5.70027","0.01737"
"11446","68.64000","5.72018","0.01795"
"11486","68.88000","5.74027","0.01775"
"11526","69.12000","5.76018","0.01822"
"11566","69.36000","5.78015","0.01817"
"11606","69.60000","5.80024","0.01753"
"11646","69.84000","5.82021","0.01746"
"11686","70.08000","5.84024","0.01705"
"11726","70.32000","5.86015","0.01734"
"11766","70.56000","5.88024","0.01690"
"11806","70.80000","5.90021","0.01732"
"11846","71.04000","5.92024","0.01687"
"11886","71.28000","5.94021","0.01811"
"11926","71.52000","5.96024","0.01763"
"11966","71.76000","5.98021","0.01785"
"12006","72.00000","6.00024","0.01788"
"12046","72.24000","6.02021","0.01838"
"12086","72.48000","6.04018","0.01777"
"12126","72.72000","6.06021","0.01857"
"12166","72.96000","6.08018","0.01879"
"12206","73.20000","6.10021","0.01825"
"12246","73.44000","6.12024","0.01889"
"12286","73.68000","6.14021","0.01898"
"12326","73.92000","6.16017","0.01922"
"12366","74.16000","6.18020","0.01947"
"12406","74.40000","6.20017","0.02008"
"12446","74.64000","6.22020","0.02026"
"12486","74.88000","6.24023","0.01984"
"12526","75.12000","6.26014","0.02044"
"12566","75.36000","6.28023","0.02033"
"12606","75.60000","6.30020","0.02093"
"12646","75.84000","6.32029","0.02123"
"12686","76.08000","6.34020","0.02142"
"12726","76.32000","6.36017","0.02069"
"12766","76.56000","6.38026","0.01968"
"12806","76.80000","6.40017","0.02041"
"12846","77.04000","6.42020","0.02086"
"12886","77.28000","6.44017","0.02065"
"12926","77.52000","6.46026","0.02148"
"12966","77.76000","6.48023","0.02125"
"13006","78.00000","6.50020","0.02174"
"13046","78.24000","6.52017","0.02183"
"13086","78.48000","6.54020","0.02124"
"13126","78.72000","6.56023","0.02231"
"13166","78.96000","6.58014","0.02212"
"13206","79.20000","6.60023","0.02264"
"13246","79.44000","6.62020","0.02281"
"13286","79.68000","6.64017","0.02328"
"13326","79.92000","6.66019","0.02346"
"13366","80.16000","6.68022","0.02381"
"13406","80.40000","6.70019","0.02388"
"13446","80.64000","6.72016","0.02418"
"13486","80.88000","6.74019","0.02439"
"13526","81.12000","6.76010","0.02498"
"13566","81.36000","6.78019","0.02507"
"13606","81.60000","6.80022","0.02550"
"13646","81.84000","6.82019","0.02593"
"13686","82.08000","6.84016","0.02597"
"13726","82.32000","6.86025","0.02591"
"13766","82.56000","6.88016","0.02584"
"13806","82.80000","6.90019","0.02669"
"13846","83.04000","6.92022","0.02661"
"13886","83.28000","6.94013","0.02721"
"13926","83.52000","6.96022","0.02690"
"13966","83.76000","6.98013","0.02630"
"14006","84.00000","7.00022","0.02664"
"14046","84.24000","7.02019","0.02704"
"14086","84.48000","7.04022","0.02724"
"14126","84.72000","7.06019","0.02750"
"14166","84.96000","7.08022","0.02765"
"14206","85.20000","7.10025","0.02805"
"14246","85.44000","7.12016","0.02793"
"14286","85.68000","7.14019","0.02792"
"14326","85.92000","7.16022","0.02793"
"14366","86.16000","7.18024","0.02769"
"14406","86.40000","7.20021","0.02711"
"14446","86.64000","7.22024","0.02800"
"14486","86.88000","7.24015","0.02795"
"14526","87.12000","7.26018","0.02829"
"14566","87.36000","7.28027","0.02851"
"14606","87.60000","7.30018","0.02755"
"14646","87.84000","7.32027","0.02763"
"14686","88.08000","7.34012","0.02742"
"14726","88.32000","7.36021","0.02820"
"14766","88.56000","7.38024","0.02795"
"14806","88.80000","7.40027","0.02867"
"14846","89.04000","7.42018","0.02803"
"14886","89.28000","7.44021","0.02916"
"14926","89.52000","7.46024","0.02870"
"14966","89.76000","7.48021","0.02974"
"15006","90.00000","7.50018","0.02930"
"15046","90.24000","7.52021","0.03033"
"15086","90.48000","7.54024","0.03030"
"15126","90.72000","7.56021","0.02991"
"15166","90.96000","7.58030","0.02869"
"15206","91.20000","7.60021","0.02875"
"15246","91.44000","7.62024","0.02932"
"15286","91.68000","7.64021","0.02918"
"15326","91.92000","7.66018","0.02998"
"15366","92.16000","7.68021","0.02947"
"15406","92.40000","7.70018","0.02975"
"15446","92.64000","7.72020","0.03002"
"15486","92.88000","7.74011","0.03025"
"15526","93.12000","7.76026","0.03017"
"15566","93.36000","7.78017","0.03130"
"15606","93.60000","7.80020","0.03062"
"15646","93.84000","7.82023","0.03111"
"15686","94.08000","7.84020","0.03161"
"15726","94.32000","7.86023","0.03097"
"15766","94.56000","7.88014","0.03137"
"15806","94.80000","7.90023","0.03138"
"15846","95.04000","7.92020","0.03164"
"15886","95.28000","7.94023","0.03139"
"15926","95.52000","7.96020","0.03136"
"15966","95.76000","7.98023","0.03181"
"16006","96.00000","8.00020","0.03130"
"16046","96.24000","8.02023","0.03152"
"16086","96.48000","8.04020","0.03168"
"16126","96.72000","8.06017","0.03186"
"16166","96.96000","8.08026","0.03140"
"16206","97.20000","8.10017","0.03278"
"16246","97.44000","8.12020","0.03252"
"16286","97.68000","8.14023","0.03248"
"16326","97.92000","8.16025","0.03245"
"16366","98.16000","8.18022","0.03237"
"16406","98.40000","8.20019","0.03301"
"16446","98.64000","8.22022","0.03275"
"16486","98.88000","8.24013","0.03307"
"16526","99.12000","8.26022","0.03259"
"16566","99.36000","8.28019","0.03285"
"16606","99.60000","8.30022","0.03266"
"16646","99.84000","8.32019","0.03259"
"16686","100.08000","8.34022","0.03252"
"16726","100.32000","8.36013","0.03264"
"16766","100.56000","8.38022","0.03327"
"16806","100.80000","8.40025","0.03325"
"16846","101.04000","8.42016","0.03285"
"16886","101.28000","8.44025","0.03298"
"16926","101.52000","8.46016","0.03337"
"16966","101.76000","8.48019","0.03366"
"17006","102.00000","8.50022","0.03368"
"17046","102.24000","8.52025","0.03432"
"17086","102.48000","8.54016","0.03390"
"17126","102.72000","8.56019","0.03357"
"17166","102.96000","8.58022","0.03278"
"17206","103.20000","8.60013","0.03338"
"17246","103.44000","8.62022","0.03359"
"17286","103.68000","8.64013","0.03329"
"17326","103.92000","8.66022","0.03303"
"17366","104.16000","8.68018","0.03331"
"17406","104.40000","8.70021","0.03285"
"17446","104.64000","8.72018","0.03368"
"17486","104.88000","8.74015","0.03332"
"17526","105.12000","8.76024","0.03338"
"17566","105.36000","8.78015","0.03355"
"17606","105.60000","8.80024","0.03429"
"17646","105.84000","8.82021","0.03419"
"17686","106.08000","8.84018","0.03382"
"17726","106.32000","8.86015","0.03492"
"17766","106.56000","8.88024","0.03426"
"17806","106.80000","8.90021","0.03474"
"17846","107.04000","8.92024","0.03464"
"17886","107.28000","8.94021","0.03504"
"17926","107.52000","8.96018","0.03536"
"17966","107.76000","8.98021","0.03509"
"18006","108.00000","9.00018","0.03533"
"18046","108.24000","9.02021","0.03528"
"18086","108.48000","9.04018","0.03545"
"18126","108.72000","9.06021","0.03611"
"18166","108.96000","9.08018","0.03640"
"18206","109.20000","9.10021","0.03588"
"18246","109.44000","9.12024","0.03613"
"18286","109.68000","9.14021","0.03677"
"18326","109.92000","9.16023","0.03658"
"18366","110.16000","9.18021","0.03668"
"18406","110.40000","9.20017","0.03700"
"18446","110.64000","9.22014","0.03740"
"18486","110.88000","9.24023","0.03678"
"18526","111.12000","9.26014","0.03776"
"18566","111.36000","9.28023","0.03774"
"18606","111.60000","9.30020","0.03803"
"18646","111.84000","9.32017","0.03807"
"18686","112.08000","9.34020","0.03817"
"18726","112.32000","9.36017","0.03848"
"18766","112.56000","9.38026","0.03854"
"18806","112.80000","9.40017","0.03862"
"18846","113.04000","9.42026","0.03839"
"18886","113.28000","9.44017","0.03857"
"18926","113.52000","9.46020","0.03919"
"18966","113.76000","9.48023","0.03940"
"19006","114.00000","9.50020","0.03998"
"19046","114.24000","9.52023","0.03946"
"19086","114.48000","9.54020","0.03893"
"19126","114.72000","9.56017","0.03923"
"19166","114.96000","9.58020","0.03941"
"19206","115.20000","9.60029","0.03932"
"19246","115.44000","9.62020","0.03966"
"19286","115.68000","9.64023","0.04042"
"19326","115.92000","9.66019","0.04032"
"19366","116.16000","9.68022","0.04087"
"19406","116.40000","9.70025","0.04081"
"19446","116.64000","9.72016","0.04119"
"19486","116.88000","9.74025","0.04110"
"19526","117.12000","9.76010","0.04114"
"19566","117.36000","9.78025","0.04147"
"19606","117.60000","9.80016","0.04213"
"19646","117.84000","9.82019","0.04221"
"19686","118.08000","9.84022","0.04284"
"19726","118.32000","9.86019","0.04252"
"19766","118.56000","9.88022","0.04249"
"19806","118.80000","9.90019","0.04232"
"19846","119.04000","9.92022","0.04275"
"19886","119.28000","9.94013","0.04276"
"19926","119.52000","9.96022","0.04296"
"19966","119.76000","9.98019","0.04277"
"20006","120.00000","10.00028","0.04319"
"20046","120.24000","10.02019","0.04296"
"20086","120.48000","10.04022","0.04351"
"20126","120.72000","10.06025","0.04324"
"20166","120.96000","10.08016","0.04372"
"20206","121.20000","10.10025","0.04350"
"20246","121.44000","10.12010","0.04313"
"20286","121.68000","10.14019","0.04319"
"20326","121.92000","10.16022","0.04414"
"20366","122.16000","10.18018","0.04359"
"20406","122.40000","10.20015","0.04408"
"20446","122.64000","10.22024","0.04453"
"20486","122.88000","10.24021","0.04488"
"20526","123.12000","10.26018","0.04468"
"20566","123.36000","10.28021","0.04525"
"20606","123.60000","10.30012","0.04514"
"20646","123.84000","10.32021","0.04514"
"20686","124.08000","10.34018","0.04567"
"20726","124.32000","10.36021","0.04591"
"20766","124.56000","10.38018","0.04593"
"20806","124.80000","10.40021","0.04570"
"20846","125.04000","10.42018","0.04574"
"20886","125.28000","10.44015","0.04599"
"20926","125.52000","10.46024","0.04604"
"20966","125.76000","10.48015","0.04607"
"21006","126.00000","10.50018","0.04641"
"21046","126.24000","10.52021","0.04637"
"21086","126.48000","10.54018","0.04647"
"21126","126.72000","10.56021","0.04535"
"21166","126.96000","10.58024","0.04539"
"21206","127.20000","10.60021","0.04509"
"21246","127.44000","10.62018","0.04470"
"21286","127.68000","10.64020","0.04375"
"21326","127.92000","10.66011","0.04381"
"21366","128.16000","10.68020","0.04416"
"21406","128.40000","10.70017","0.04432"
"21446","128.64000","10.72020","0.04418"
"21486","128.88000","10.74017","0.04344"
"21526","129.12000","10.76026","0.04357"
"21566","129.36000","10.78023","0.04443"
"21606","129.60000","10.80014","0.04434"
"21646","129.84000","10.82023","0.04402"
"21686","130.08000","10.84014","0.04525"
"21726","130.32000","10.86023","0.04431"
"21766","130.56000","10.88014","0.04461"
"21806","130.80000","10.90029","0.04450"
"21846","131.04000","10.92020","0.04435"
"21886","131.28000","10.94023","0.04470"
"21926","131.52000","10.96020","0.04469"
"21966","131.76000","10.98017","0.04539"
"22006","132.00000","11.00026","0.04525"
"22046","132.24000","11.02017","0.04490"
"22086","132.48000","11.04020","0.03745"
"22126","132.72000","11.06017","0.03762"
"22166","132.96000","11.08026","0.03816"
"22206","133.20000","11.10023","0.03843"
"22246","133.44000","11.12020","0.03844"
"22286","133.68000","11.14023","0.03882"
"22326","133.92000","11.16019","0.03846"
"22366","134.16000","11.18016","0.03887"
"22406","134.40000","11.20019","0.03933"
"22446","134.64000","11.22016","0.03978"
"22486","134.88000","11.24019","0.04017"
"22526","135.12000","11.26028","0.03962"
"22566","135.36000","11.28013","0.04002"
"22606","135.60000","11.30028","0.03995"
"22646","135.84000","11.32019","0.04032"
"22686","136.08000","11.34022","0.04052"
"22726","136.32000","11.36019","0.04013"
"22766","136.56000","11.38022","0.03991"
"22806","136.80000","11.40025","0.03938"
"22846","137.04000","11.42016","0.03981"
"22886","137.28000","11.44025","0.03924"
"22926","137.52000","11.46016","0.03906"
"22966","137.76000","11.48025","0.03904"
"23006","138.00000","11.50022","0.03959"
"23046","138.24000","11.52019","0.03937"
"23086","138.48000","11.54022","0.03938"
"23126","138.72000","11.56019","0.03936"
"23166","138.96000","11.58022","0.03981"
"23206","139.20000","11.60019","0.03936"
"23246","139.44000","11.62022","0.04006"
"23286","139.68000","11.64019","0.04005"
"23326","139.92000","11.66028","0.03996"
"23366","140.16000","11.68024","0.04019"
"23406","140.40000","11.70021","0.03977"
"23446","140.64000","11.72024","0.04052"
"23486","140.88000","11.74015","0.03893"
"23526","141.12000","11.76024","0.03930"
"23566","141.36000","11.78015","0.03932"
"23606","141.60000","11.80024","0.03814"
"23646","141.84000","11.82015","0.03849"
"23686","142.08000","11.84024","0.03822"
"23726","142.32000","11.86021","0.03819"
"23766","142.56000","11.88018","0.03668"
"23806","142.80000","11.90015","0.03663"
"23846","143.04000","11.92018","0.03628"
"23886","143.28000","11.94021","0.03547"
"23926","143.52000","11.96018","0.03454"
"23966","143.76000","11.98021","0.03463"
"24006","144.00000","12.00018","0.03529"
"24046","144.24000","12.02021","0.03463"
"24086","144.48000","12.04024","0.03517"
"24126","144.72000","12.06021","0.03513"
"24166","144.96000","12.08018","0.03536"
"24206","145.20000","12.10020","0.03532"
"24246","145.44000","12.12024","0.03569"
"24286","145.68000","12.14014","0.03505"
"24326","145.92000","12.16023","0.03510"
"24366","146.16000","12.18014","0.03525"
"24406","146.40000","12.20023","0.03527"
"24446","146.64000","12.22020","0.03475"
"24486","146.88000","12.24023","0.03578"
"24526","147.12000","12.26020","0.03530"
"24566","147.36000","12.28017","0.03571"
"24606","147.60000","12.30026","0.03535"
"24646","147.84000","12.32011","0.03615"
"24686","148.08000","12.34020","0.03654"
"24726","148.32000","12.36017","0.03657"
"24766","148.56000","12.38020","0.03650"
"24806","148.80000","12.40017","0.03653"
"24846","149.04000","12.42020","0.03653"
"24886","149.28000","12.44023","0.03665"
"24926","149.52000","12.46020","0.03626"
"24966","149.76000","12.48023","0.03659"
"25006","150.00000","12.50014","0.03714"
"25046","150.24000","12.52023","0.03768"
"25086","150.48000","12.54020","0.03786"
"25126","150.72000","12.56023","0.03727"
"25166","150.96000","12.58020","0.03686"
"25206","151.20000","12.60023","0.03468"
"25246","151.44000","12.62019","0.03485"
"25286","151.68000","12.64017","0.03573"
"25326","151.92000","12.66019","0.03582"
"25366","152.16000","12.68011","0.03634"
"25406","152.40000","12.70025","0.03643"
"25446","152.64000","12.72016","0.03645"
"25486","152.88000","12.74019","0.03596"
"25526","153.12000","12.76016","0.03672"
"25566","153.36000","12.78025","0.03698"
"25606","153.60000","12.80016","0.03706"
"25646","153.84000","12.82019","0.03807"
"25686","154.08000","12.84028","0.03724"
"25726","154.32000","12.86013","0.03773"
"25766","154.56000","12.88022","0.03775"
"25806","154.80000","12.90019","0.03772"
"25846","155.04000","12.92022","0.03790"
"25886","155.28000","12.94019","0.03725"
"25926","155.52000","12.96028","0.03724"
"25966","155.76000","12.98019","0.03710"
"26006","156.00000","13.00022","0.03687"
"26046","156.24000","13.02025","0.03746"
"26086","156.48000","13.04016","0.03700"
"26126","156.72000","13.06025","0.03771"
"26166","156.96000","13.08016","0.03768"
"26206","157.20000","13.10025","0.03667"
"26246","157.44000","13.12016","0.03679"
"26286","157.68000","13.14024","0.03663"
"26326","157.92000","13.16021","0.03677"
"26366","158.16000","13.18018","0.03734"
"26406","158.40000","13.20027","0.03649"
"26446","158.64000","13.22018","0.03696"
"26486","158.88000","13.24021","0.03650"
"26526","159.12000","13.26018","0.03625"
"26566","159.36000","13.28021","0.03611"
"26606","159.60000","13.30018","0.03607"
"26646","159.84000","13.32021","0.03652"
"26686","160.08000","13.34018","0.03707"
"26726","160.32000","13.36027","0.03589"
"26766","160.56000","13.38024","0.03666"
"26806","160.80000","13.40021","0.03629"
"26846","161.04000","13.42018","0.03717"
"26886","161.28000","13.44015","0.03689"
"26926","161.52000","13.46024","0.03646"
"26966","161.76000","13.48015","0.03653"
"27006","162.00000","13.50024","0.03729"
"27046","162.24000","13.52021","0.03709"
"27086","162.48000","13.54024","0.03742"
"27126","162.72000","13.56027","0.03740"
"27166","162.96000","13.58024","0.03704"
"27206","163.20000","13.60021","0.03735"
"27246","163.44000","13.62012","0.03783"
"27286","163.68000","13.64026","0.03712"
"27326","163.92000","13.66017","0.03795"
"27366","164.16000","13.68026","0.03820"
"27406","164.40000","13.70017","0.03865"
"27446","164.64000","13.72020","0.03824"
"27486","164.88000","13.74017","0.03832"
"27526","165.12000","13.76020","0.03855"
"27566","165.36000","13.78023","0.03810"
"27606","165.60000","13.80020","0.03894"
"27646","165.84000","13.82023","0.03936"
"27686","166.08000","13.84014","0.03909"
"27726","166.32000","13.86023","0.03782"
"27766","166.56000","13.88020","0.03825"
"27806","166.80000","13.90023","0.03857"
"27846","167.04000","13.92020","0.03851"
"27886","167.28000","13.94023","0.03907"
"27926","167.52000","13.96026","0.03757"
"27966","167.76000","13.98017","0.03833"
"28006","168.00000","14.00020","0.03759"
"28046","168.24000","14.02017","0.03779"
"28086","168.48000","14.04026","0.03727"
"28126","168.72000","14.06023","0.03826"
"28166","168.96000","14.08020","0.03814"
"28206","169.20000","14.10017","0.03833"
"28246","169.44000","14.12020","0.03824"
"28286","169.68000","14.14022","0.03872"
"28326","169.92000","14.16020","0.03874"
"28366","170.16000","14.18022","0.03890"
"28406","170.40000","14.20013","0.03905"
"28446","170.64000","14.22016","0.03866"
"28486","170.88000","14.24019","0.03917"
"28526","171.12000","14.26022","0.03947"
"28566","171.36000","14.28013","0.03927"
"28606","171.60000","14.30022","0.03927"
"28646","171.84000","14.32025","0.03962"
"28686","172.08000","14.34016","0.03984"
"28726","172.32000","14.36025","0.04042"
"28766","172.56000","14.38016","0.04013"
"28806","172.80000","14.40019","0.03973"
"28846","173.04000","14.42016","0.04077"
"28886","173.28000","14.44019","0.04078"
"28926","173.52000","14.46022","0.04058"
"28966","173.76000","14.48025","0.04006"
"29006","174.00000","14.50022","0.04077"
"29046","174.24000","14.52019","0.04018"
"29086","174.48000","14.54022","0.03590"
"29126","174.72000","14.56019","0.03633"
"29166","174.96000","14.58016","0.03631"
"29206","175.20000","14.60019","0.03730"
"29246","175.44000","14.62027","0.03725"
"29286","175.68000","14.64019","0.03756"
"29326","175.92000","14.66021","0.03713"
"29366","176.16000","14.68024","0.03772"
"29406","176.40000","14.70015","0.03803"
"29446","176.64000","14.72024","0.03818"
"29486","176.88000","14.74021","0.03839"
"29526","177.12000","14.76024","0.03781"
"29566","177.36000","14.78021","0.03795"
"29606","177.60000","14.80024","0.03740"
"29646","177.84000","14.82015","0.03794"
"29686","178.08000","14.84018","0.03782"
"29726","178.32000","14.86021","0.03842"
"29766","178.56000","14.88018","0.03861"
"29806","178.80000","14.90027","0.03904"
"29846","179.04000","14.92018","0.03922"
"29886","179.28000","14.94021","0.03937"
"29926","179.52000","14.96012","0.03986"
"29966","179.76000","14.98027","0.04011"
"30006","180.00000","15.00018","0.03990"
"30046","180.24000","15.02021","0.04000"
"30086","180.48000","15.04024","0.04062"
"30126","180.72000","15.06021","0.04077"
"30166","180.96000","15.08024","0.03995"
"30206","181.20000","15.10015","0.04140"
"30246","181.44000","15.12024","0.04119"
"30286","181.68000","15.14015","0.03895"
"30326","181.92000","15.16029","0.03965"
"30366","182.16000","15.18014","0.03962"
"30406","182.40000","15.20023","0.04031"
"30446","182.64000","15.22026","0.04117"
"30486","182.88000","15.24017","0.04125"
"30526","183.12000","15.26026","0.04175"
"30566","183.36000","15.28017","0.04167"
"30606","183.60000","15.30020","0.04158"
"30646","183.84000","15.32011","0.04202"
"30686","184.08000","15.34026","0.04206"
"30726","184.32000","15.36017","0.04201"
"30766","184.56000","15.38026","0.04204"
"30806","184.80000","15.40017","0.04219"
"30846","185.04000","15.42020","0.04284"
"30886","185.28000","15.44023","0.04253"
"30926","185.52000","15.46020","0.04221"
"30966","185.76000","15.48023","0.04229"
"31006","186.00000","15.50014","0.04177"
"31046","186.24000","15.52023","0.04209"
"31086","186.48000","15.54020","0.04238"
"31126","186.72000","15.56023","0.04205"
"31166","186.96000","15.58026","0.04179"
"31206","187.20000","15.60023","0.04176"
"31246","187.44000","15.62020","0.04256"
"31286","187.68000","15.64016","0.04279"
"31326","187.92000","15.66025","0.04312"
"31366","188.16000","15.68016","0.04302"
"31406","188.40000","15.70025","0.04308"
"31446","188.64000","15.72016","0.04272"
"31486","188.88000","15.74025","0.04263"
"31526","189.12000","15.76022","0.04132"
"31566","189.36000","15.78025","0.04138"
"31606","189.60000","15.80016","0.04225"
"31646","189.84000","15.82019","0.04236"
"31686","190.08000","15.84022","0.04273"
"31726","190.32000","15.86019","0.04289"
"31766","190.56000","15.88022","0.04306"
"31806","190.80000","15.90019","0.04332"
"31846","191.04000","15.92022","0.04358"
"31886","191.28000","15.94019","0.04355"
"31926","191.52000","15.96022","0.04378"
"31966","191.76000","15.98019","0.04409"
"32006","192.00000","16.00016","0.04444"
"32046","192.24000","16.02019","0.04499"
"32086","192.48000","16.04016","0.04488"
"32126","192.72000","16.06019","0.04547"
"32166","192.96000","16.08016","0.04565"
"32206","193.20000","16.10024","0.04502"
"32246","193.44000","16.12021","0.04528"
"32286","193.68000","16.14024","0.04518"
"32326","193.92000","16.16021","0.04549"
"32366","194.16000","16.18012","0.04590"
"32406","194.40000","16.20021","0.04608"
"32446","194.64000","16.22012","0.04555"
"32486","194.88000","16.24015","0.04601"
"32526","195.12000","16.26018","0.04665"
"32566","195.36000","16.28021","0.04688"
"32606","195.60000","16.30018","0.04682"
"32646","195.84000","16.32027","0.04730"
"32686","196.08000","16.34024","0.04763"
"32726","196.32000","16.36021","0.04804"
"32766","196.56000","16.38018","0.04776"
"32806","196.80000","16.40015","0.04888"
"32846","197.04000","16.42018","0.04905"
"32886","197.28000","16.44015","0.04888"
"32926","197.52000","16.46024","0.04921"
"32966","197.76000","16.48021","0.05038"
"33006","198.00000","16.50024","0.05021"
"33046","198.24000","16.52021","0.05068"
"33086","198.48000","16.54017","0.05120"
"33126","198.72000","16.56021","0.05085"
"33166","198.96000","16.58018","0.05101"
"33206","199.20000","16.60020","0.05159"
"33246","199.44000","16.62017","0.05161"
"33286","199.68000","16.64021","0.05151"
"33326","199.92000","16.66017","0.05231"
"33366","200.16000","16.68020","0.05253"
"33406","200.40000","16.70023","0.05241"
"33446","200.64000","16.72020","0.05337"
"33486","200.88000","16.74023","0.05322"
"33526","201.12000","16.76020","0.05378"
"33566","201.36000","16.78023","0.05390"
"33606","201.60000","16.80014","0.05378"
"33646","201.84000","16.82023","0.05430"
"33686","202.08000","16.84020","0.05438"
"33726","202.32000","16.86023","0.05448"
"33766","202.56000","16.88026","0.05468"
"33806","202.80000","16.90017","0.05504"
"33846","203.04000","16.92020","0.05534"
"33886","203.28000","16.94023","0.05557"
"33926","203.52000","16.96020","0.05589"
"33966","203.76000","16.98017","0.05597"
"34006","204.00000","17.00020","0.05575"
"34046","204.24000","17.02017","0.05615"
"34086","204.48000","17.04026","0.05645"
"34126","204.72000","17.06023","0.05670"
"34166","204.96000","17.08019","0.05638"
"34206","205.20000","17.10016","0.05653"
"34246","205.44000","17.12019","0.05695"
"34286","205.68000","17.14022","0.05683"
"34326","205.92000","17.16019","0.05736"
"34366","206.16000","17.18022","0.05753"
"34406","206.40000","17.20019","0.05746"
"34446","206.64000","17.22028","0.05757"
"34486","206.88000","17.24025","0.05781"
"34526","207.12000","17.26016","0.05824"
"34566","207.36000","17.28019","0.05849"
"34606","207.60000","17.30022","0.05837"
"34646","207.84000","17.32025","0.05854"
"34686","208.08000","17.34016","0.05879"
"34726","208.32000","17.36025","0.05893"
"34766","208.56000","17.38016","0.05877"
"34806","208.80000","17.40019","0.05921"
"34846","209.04000","17.42022","0.05962"
"34886","209.28000","17.44019","0.05907"
"34926","209.52000","17.46028","0.05959"
"34966","209.76000","17.48019","0.05989"
"35006","210.00000","17.50022","0.05998"
"35046","210.24000","17.52013","0.06066"
"35086","210.48000","17.54028","0.06065"
"35126","210.72000","17.56019","0.06106"
"35166","210.96000","17.58022","0.06094"
"35206","211.20000","17.60024","0.06141"
"35246","211.44000","17.62021","0.06166"
"35286","211.68000","17.64018","0.06205"
"35326","211.92000","17.66021","0.06202"
"35366","212.16000","17.68024","0.06271"
"35406","212.40000","17.70015","0.06323"
"35446","212.64000","17.72024","0.06330"
"35486","212.88000","17.74015","0.06386"
"35526","213.12000","17.76024","0.06439"
"35566","213.36000","17.78021","0.06470"
"35606","213.60000","17.80024","0.06517"
"35646","213.84000","17.82021","0.06583"
"35686","214.08000","17.84024","0.06623"
"35726","214.32000","17.86021","0.06667"
"35766","214.56000","17.88012","0.06703"
"35806","214.80000","17.90021","0.06741"
"35846","215.04000","17.92018","0.06809"
"35886","215.28000","17.94021","0.06801"
"35926","215.52000","17.96018","0.06764"
"35966","215.76000","17.98021","0.06847"
"36006","216.00000","18.00018","0.06832"
"36046","216.24000","18.02015","0.06952"
"36086","216.48000","18.04024","0.06996"
"36126","216.72000","18.06009","0.07052"
"36166","216.96000","18.08023","0.07076"
"36206","217.20000","18.10021","0.07184"
"36246","217.44000","18.12024","0.07210"
"36286","217.68000","18.14020","0.07282"
"36326","217.92000","18.16023","0.07297"
"36366","218.16000","18.18020","0.07214"
"36406","218.40000","18.20017","0.07355"
"36446","218.64000","18.22026","0.07399"
"36486","218.88000","18.24011","0.07430"
"36526","219.12000","18.26020","0.07462"
"36566","219.36000","18.28023","0.07562"
"36606","219.60000","18.30020","0.07581"
"36646","219.84000","18.32017","0.07702"
"36686","220.08000","18.34026","0.07768"
"36726","220.32000","18.36017","0.07807"
"36766","220.56000","18.38020","0.07784"
"36806","220.80000","18.40017","0.07804"
"36846","221.04000","18.42020","0.07915"
"36886","221.28000","18.44023","0.08010"
"36926","221.52000","18.46014","0.08067"
"36966","221.76000","18.48023","0.08157"
"37006","222.00000","18.50020","0.08212"
"37046","222.24000","18.52029","0.08307"
"37086","222.48000","18.54020","0.08406"
"37126","222.72000","18.56017","0.08476"
"37166","222.96000","18.58026","0.08497"
"37206","223.20000","18.60017","0.08647"
"37246","223.44000","18.62025","0.08655"
"37286","223.68000","18.64016","0.08752"
"37326","223.92000","18.66019","0.08792"
"37366","224.16000","18.68022","0.08826"
"37406","224.40000","18.70025","0.08900"
"37446","224.64000","18.72016","0.08900"
"37486","224.88000","18.74025","0.08981"
"37526","225.12000","18.76022","0.09055"
"37566","225.36000","18.78019","0.09166"
"37606","225.60000","18.80022","0.09155"
"37646","225.84000","18.82019","0.09252"
"37686","226.08000","18.84022","0.09294"
"37726","226.32000","18.86019","0.09364"
"37766","226.56000","18.88022","0.09400"
"37806","226.80000","18.90019","0.09433"
"37846","227.04000","18.92022","0.09536"
"37886","227.28000","18.94025","0.09475"
"37926","227.52000","18.96016","0.09532"
"37966","227.76000","18.98019","0.09613"
"38006","228.00000","19.00016","0.09681"
"38046","228.24000","19.02019","0.09662"
"38086","228.48000","19.04016","0.09783"
"38126","228.72000","19.06025","0.09784"
"38166","228.96000","19.08022","0.09803"
"38206","229.20000","19.10019","0.09841"
"38246","229.44000","19.12016","0.09914"
"38286","229.68000","19.14024","0.09985"
"38326","229.92000","19.16027","0.10068"
"38366","230.16000","19.18018","0.10072"
"38406","230.40000","19.20027","0.10150"
"38446","230.64000","19.22018","0.10244"
"38486","230.88000","19.24027","0.10241"
"38526","231.12000","19.26018","0.10276"
"38566","231.36000","19.28021","0.10339"
"38606","231.60000","19.30018","0.10426"
"38646","231.84000","19.32021","0.10494"
"38686","232.08000","19.34024","0.10523"
"38726","232.32000","19.36015","0.10585"
"38766","232.56000","19.38024","0.10588"
"38806","232.80000","19.40015","0.10740"
"38846","233.04000","19.42024","0.10744"
"38886","233.28000","19.44021","0.10769"
"38926","233.52000","19.46018","0.10743"
"38966","233.76000","19.48021","0.00682"
"39006","234.00000","19.50018","0.01614"
"39046","234.24000","19.52027","0.01334"
"39086","234.48000","19.54024","0.01017"
"39126","234.72000","19.56027","0.00971"
"39166","234.96000","19.58017","0.00900"
"39206","235.20000","19.60015","0.01067"
"39246","235.44000","19.62017","0.01115"
"39286","235.68000","19.64020","0.00939"
"39326","235.92000","19.66023","0.00983"
"39366","236.16000","19.68020","0.01042"
"39406","236.40000","19.70023","0.01030"
"39446","236.64000","19.72020","0.00988"
"39486","236.88000","19.74023","0.00929"
"39526","237.12000","19.76014","0.01022"
"39566","237.36000","19.78023","0.01014"
"39606","237.60000","19.80020","0.01053"
"39646","237.84000","19.82023","0.01085"
"39686","238.08000","19.84020","0.00958"
"39726","238.32000","19.86017","0.00989"
"39766","238.56000","19.88020","0.01000"
"39806","238.80000","19.90017","0.01000"
"39846","239.04000","19.92026","0.01099"
"39886","239.28000","19.94017","0.01080"
"39926","239.52000","19.96020","0.01019"
"39966","239.76000","19.98017","0.01058"
"40006","240.00000","20.00026","0.01027"
"40046","240.24000","20.02022","0.01031"
"40086","240.48000","20.04020","0.01011"
"40126","240.72000","20.06022","0.01042"
"40166","240.96000","20.08014","0.01111"
"40206","241.20000","20.10023","0.01040"
"40246","241.44000","20.12019","0.01080"
"40286","241.68000","20.14022","0.01010"
"40326","241.92000","20.16019","0.01021"
"40366","242.16000","20.18022","0.01017"
"40406","242.40000","20.20019","0.01085"
"40446","242.64000","20.22022","0.01076"
"40486","242.88000","20.24025","0.01122"
"40526","243.12000","20.26016","0.01026"
"40566","243.36000","20.28025","0.01009"
"40606","243.60000","20.30022","0.01102"
"40646","243.84000","20.32019","0.01072"
"40686","244.08000","20.34016","0.01074"
"40726","244.32000","20.36025","0.01046"
"40766","244.56000","20.38022","0.01149"
"40806","244.80000","20.40019","0.01048"
"40846","245.04000","20.42022","0.01086"
"40886","245.28000","20.44019","0.01088"
"40926","245.52000","20.46028","0.01043"
"40966","245.76000","20.48019","0.01065"
"41006","246.00000","20.50022","0.01112"
"41046","246.24000","20.52019","0.01114"
"41086","246.48000","20.54028","0.01078"
"41126","246.72000","20.56013","0.01050"
"41166","246.96000","20.58022","0.01123"
"41206","247.20000","20.60024","0.01094"
"41246","247.44000","20.62015","0.01137"
"41286","247.68000","20.64024","0.01074"
"41326","247.92000","20.66021","0.01075"
"41366","248.16000","20.68018","0.01122"
"41406","248.40000","20.70015","0.01136"
"41446","248.64000","20.72024","0.01102"
"41486","248.88000","20.74015","0.01088"
"41526","249.12000","20.76024","0.01093"
"41566","249.36000","20.78021","0.01097"
"41606","249.60000","20.80018","0.01119"
"41646","249.84000","20.82021","0.01056"
"41686","250.08000","20.84018","0.01073"
"41726","250.32000","20.86021","0.01075"
"41766","250.56000","20.88018","0.01085"
"41806","250.80000","20.90021","0.01032"
"41846","251.04000","20.92018","0.01080"
"41886","251.28000","20.94021","0.01105"
"41926","251.52000","20.96024","0.01126"
"41966","251.76000","20.98021","0.01089"
"42006","252.00000","21.00024","0.01053"
"42046","252.24000","21.02020","0.01099"
"42086","252.48000","21.04024","0.01097"
"42126","252.72000","21.06015","0.01053"
"42166","252.96000","21.08023","0.01043"
"42206","253.20000","21.10020","0.01107"
"42246","253.44000","21.12024","0.01079"
"42286","253.68000","21.14021","0.01063"
"42326","253.92000","21.16017","0.01121"
"42366","254.16000","21.18020","0.01103"
"42406","254.40000","21.20017","0.01051"
"42446","254.64000","21.22020","0.01052"
"42486","254.88000","21.24017","0.01068"
"42526","255.12000","21.26020","0.01045"
"42566","255.36000","21.28023","0.01081"
"42606","255.60000","21.30020","0.01060"
"42646","255.84000","21.32023","0.01069"
"42686","256.08000","21.34026","0.01045"
"42726","256.32000","21.36017","0.01057"
"42766","256.56000","21.38020","0.01025"
"42806","256.80000","21.40023","0.01057"
"42846","257.04000","21.42014","0.01044"
"42886","257.28000","21.44023","0.01072"
"42926","257.52000","21.46020","0.01066"
"42966","257.76000","21.48023","0.01075"
"43006","258.00000","21.50020","0.01098"
"43046","258.24000","21.52023","0.01097"
"43086","258.48000","21.54020","0.01106"
"43126","258.72000","21.56017","0.01075"
"43166","258.96000","21.58026","0.01084"
"43206","259.20000","21.60011","0.01058"
"43246","259.44000","21.62020","0.01118"
"43286","259.68000","21.64022","0.01092"
"43326","259.92000","21.66025","0.01130"
"43366","260.16000","21.68022","0.01111"
"43406","260.40000","21.70019","0.01081"
"43446","260.64000","21.72022","0.01111"
"43486","260.88000","21.74019","0.01124"
"43526","261.12000","21.76022","0.01146"
"43566","261.36000","21.78013","0.01099"
"43606","261.60000","21.80022","0.01093"
"43646","261.84000","21.82019","0.01109"
"43686","262.08000","21.84022","0.01057"
"43726","262.32000","21.86025","0.01050"
"43766","262.56000","21.88022","0.01086"
"43806","262.80000","21.90025","0.01041"
"43846","263.04000","21.92016","0.01113"
"43886","263.28000","21.94025","0.01044"
"43926","263.52000","21.96016","0.01020"
"43966","263.76000","21.98018","0.01080"
"44006","264.00000","22.00022","0.01071"
"44046","264.24000","22.02025","0.01078"
"44086","264.48000","22.04009","0.01099"
"44126","264.72000","22.06018","0.01103"
"44166","264.96000","22.08022","0.01082"
"44206","265.20000","22.10025","0.01131"
"44246","265.44000","22.12021","0.01090"
"44286","265.68000","22.14013","0.01076"
"44326","265.92000","22.16021","0.01075"
"44366","266.16000","22.18018","0.01142"
"44406","266.40000","22.20027","0.01092"
"44446","266.64000","22.22012","0.01118"
"44486","266.88000","22.24027","0.01180"
"44526","267.12000","22.26024","0.01111"
"44566","267.36000","22.28021","0.01087"
"44606","267.60000","22.30030","0.01086"
"44646","267.84000","22.32015","0.01111"
"44686","268.08000","22.34018","0.01103"
"44726","268.32000","22.36015","0.01119"
"44766","268.56000","22.38024","0.01082"
"44806","268.80000","22.40021","0.01141"
"44846","269.04000","22.42024","0.01165"
"44886","269.28000","22.44021","0.01094"
"44926","269.52000","22.46018","0.01252"
"44966","269.76000","22.48021","0.01123"
"45006","270.00000","22.50018","0.01142"
"45046","270.24000","22.52021","0.01110"
"45086","270.48000","22.54018","0.01127"
"45126","270.72000","22.56021","0.01091"
"45166","270.96000","22.58018","0.01145"
"45206","271.20000","22.60027","0.01101"
"45246","271.44000","22.62024","0.01140"
"45286","271.68000","22.64020","0.01165"
"45326","271.92000","22.66017","0.01155"
"45366","272.16000","22.68020","0.01123"
"45406","272.40000","22.70023","0.01126"
"45446","272.64000","22.72014","0.01143"
"45486","272.88000","22.74023","0.01123"
"45526","273.12000","22.76014","0.01180"
"45566","273.36000","22.78023","0.01154"
"45606","273.60000","22.80020","0.01167"
"45646","273.84000","22.82023","0.01143"
"45686","274.08000","22.84026","0.01076"
"45726","274.32000","22.86017","0.01132"
"45766","274.56000","22.88026","0.01148"
"45806","274.80000","22.90017","0.01142"
"45846","275.04000","22.92026","0.01190"
"45886","275.28000","22.94017","0.01149"
"45926","275.52000","22.96026","0.01161"
"45966","275.76000","22.98023","0.01131"
"46006","276.00000","23.00020","0.01134"
"46046","276.24000","23.02023","0.01133"
"46086","276.48000","23.04020","0.01159"
"46126","276.72000","23.06022","0.01157"
"46166","276.96000","23.08013","0.01151"
"46206","277.20000","23.10028","0.01172"
"46246","277.44000","23.12020","0.01165"
"46286","277.68000","23.14022","0.01140"
"46326","277.92000","23.16019","0.01148"
"46366","278.16000","23.18022","0.01123"
"46406","278.40000","23.20019","0.01145"
"46446","278.64000","23.22022","0.01177"
"46486","278.88000","23.24019","0.01215"
"46526","279.12000","23.26010","0.01184"
"46566","279.36000","23.28025","0.01170"
"46606","279.60000","23.30022","0.01153"
"46646","279.84000","23.32019","0.01193"
"46686","280.08000","23.34022","0.01121"
"46726","280.32000","23.36025","0.01188"
"46766","280.56000","23.38022","0.01143"
"46806","280.80000","23.40025","0.01144"
"46846","281.04000","23.42022","0.01140"
"46886","281.28000","23.44019","0.01180"
"46926","281.52000","23.46022","0.01194"
"46966","281.76000","23.48013","0.01178"
"47006","282.00000","23.50028","0.01163"
"47046","282.24000","23.52019","0.01182"
"47086","282.48000","23.54028","0.01197"
"47126","282.72000","23.56018","0.01161"
"47166","282.96000","23.58021","0.01168"
"47206","283.20000","23.60024","0.01185"
"47246","283.44000","23.62016","0.01207"
"47286","283.68000","23.64018","0.01207"
"47326","283.92000","23.66015","0.01125"
"47366","284.16000","23.68024","0.01199"
"47406","284.40000","23.70021","0.01160"
"47446","284.64000","23.72024","0.01167"
"47486","284.88000","23.74015","0.01178"
"47526","285.12000","23.76018","0.01230"
"47566","285.36000","23.78021","0.01184"
"47606","285.60000","23.80018","0.01187"
"47646","285.84000","23.82021","0.01205"
"47686","286.08000","23.84018","0.01194"
"47726","286.32000","23.86015","0.01114"
"47766","286.56000","23.88018","0.01187"
"47806","286.80000","23.90027","0.01179"
"47846","287.04000","23.92018","0.01164"
"47886","287.28000","23.94015","0.01153"
"47926","287.52000","23.96024","0.01149"
"47966","287.76000","23.98015","0.01204"
"48006","288.00000","24.00024","0.01185"
"48046","288.24000","24.02021","0.01184"
"48086","288.48000","24.04017","0.01225"
"48126","288.72000","24.06014","0.01179"
"48166","288.96000","24.08030","0.01157"
"48206","289.20000","24.10014","0.01156"
"48246","289.44000","24.12023","0.01202"
"48286","289.68000","24.14020","0.01208"
"48326","289.92000","24.16018","0.01221"
"48366","290.16000","24.18020","0.01150"
"48406","290.40000","24.20017","0.01202"
"48446","290.64000","24.22020","0.01220"
"48486","290.88000","24.24017","0.01164"
"48526","291.12000","24.26026","0.01204"
"48566","291.36000","24.28023","0.01180"
"48606","291.60000","24.30020","0.01157"
"48646","291.84000","24.32029","0.01178"
"48686","292.08000","24.34014","0.01195"
"48726","292.32000","24.36023","0.01259"
"48766","292.56000","24.38014","0.01195"
"48806","292.80000","24.40023","0.01167"
"48846","293.04000","24.42020","0.01198"
"48886","293.28000","24.44023","0.01208"
"48926","293.52000","24.46020","0.01181"
"48966","293.76000","24.48017","0.01171"
"49006","294.00000","24.50019","0.01214"
"49046","294.24000","24.52017","0.01205"
"49086","294.48000","24.54026","0.01200"
"49126","294.72000","24.56022","0.01209"
"49166","294.96000","24.58026","0.01221"
"49206","295.20000","24.60016","0.01262"
"49246","295.44000","24.62025","0.01224"
"49286","295.68000","24.64017","0.01191"
"49326","295.92000","24.66019","0.01208"
"49366","296.16000","24.68022","0.01183"
"49406","296.40000","24.70019","0.01225"
"49446","296.64000","24.72022","0.01241"
"49486","296.88000","24.74019","0.01205"
"49526","297.12000","24.76022","0.01215"
"49566","297.36000","24.78019","0.01211"
"49606","297.60000","24.80022","0.01172"
"49646","297.84000","24.82019","0.01216"
"49686","298.08000","24.84022","0.01224"
"49726","298.32000","24.86019","0.01152"
"49766","298.56000","24.88022","0.01162"
"49806","298.80000","24.90025","0.01206"
"49846","299.04000","24.92016","0.01243"
"49886","299.28000","24.94019","0.01203"
"49926","299.52000","24.96016","0.01222"
"49966","299.76000","24.98019","0.01170"
"49982","299.85600","24.98826","0.01190"