File: Trajectories_together/170212_1Specimen_RawData_4.csv
"","V1","V2","V3"
"1","End date","2/12/2017",""
"2","Specimen label","9AG_77",""
"3","Maximum Load","1.58650","N"
"4","Time","Extension","Load"
"5","(s)","(mm)","(N)"
"6","0.00000","0.00000","-0.00044"
"83","0.46200","0.03880","0.00142"
"160","0.92400","0.07719","0.00134"
"237","1.38600","0.11569","0.00264"
"314","1.84800","0.15426","0.00337"
"391","2.31000","0.19270","0.00409"
"468","2.77200","0.23121","0.00479"
"545","3.23400","0.26965","0.00513"
"622","3.69600","0.30810","0.00552"
"699","4.15800","0.34672","0.00645"
"776","4.62000","0.38522","0.00680"
"853","5.08200","0.42373","0.00680"
"930","5.54400","0.46217","0.00774"
"1007","6.00600","0.50068","0.00822"
"1084","6.46800","0.53924","0.00919"
"1161","6.93000","0.57763","0.00887"
"1238","7.39200","0.61613","0.00978"
"1315","7.85400","0.65470","0.01030"
"1392","8.31600","0.69326","0.01132"
"1469","8.77800","0.73176","0.01161"
"1546","9.24000","0.77021","0.01248"
"1623","9.70200","0.80865","0.01281"
"1700","10.16400","0.84716","0.01254"
"1777","10.62600","0.88566","0.01282"
"1854","11.08800","0.92423","0.01363"
"1931","11.55000","0.96273","0.01385"
"2008","12.01200","1.00118","0.01452"
"2085","12.47400","1.03974","0.01465"
"2162","12.93600","1.07824","0.01528"
"2239","13.39800","1.11669","0.01599"
"2316","13.86000","1.15519","0.01619"
"2393","14.32200","1.19370","0.01701"
"2470","14.78400","1.23226","0.01678"
"2547","15.24600","1.27065","0.01732"
"2624","15.70800","1.30927","0.01764"
"2701","16.17000","1.34772","0.01831"
"2778","16.63200","1.38616","0.01853"
"2855","17.09400","1.42466","0.01906"
"2932","17.55600","1.46323","0.01882"
"3009","18.01800","1.50167","0.01877"
"3086","18.48000","1.54024","0.01897"
"3163","18.94200","1.57874","0.01990"
"3240","19.40400","1.61719","0.02008"
"3317","19.86600","1.65563","0.02021"
"3394","20.32800","1.69414","0.01991"
"3471","20.79000","1.73270","0.02050"
"3548","21.25200","1.77126","0.02139"
"3625","21.71400","1.80971","0.02168"
"3702","22.17600","1.84815","0.02171"
"3779","22.63800","1.88672","0.02216"
"3856","23.10000","1.92516","0.02246"
"3933","23.56200","1.96367","0.02332"
"4010","24.02400","2.00217","0.02284"
"4087","24.48600","2.04074","0.02410"
"4164","24.94800","2.07918","0.02294"
"4241","25.41000","2.11775","0.02302"
"4318","25.87200","2.15625","0.02351"
"4395","26.33400","2.19463","0.02375"
"4472","26.79600","2.23320","0.02236"
"4549","27.25800","2.27170","0.02101"
"4626","27.72000","2.31027","0.02009"
"4703","28.18200","2.34871","0.02051"
"4780","28.64400","2.38716","0.02117"
"4857","29.10600","2.42572","0.02251"
"4934","29.56800","2.46423","0.02291"
"5011","30.03000","2.50267","0.02250"
"5088","30.49200","2.54123","0.02221"
"5165","30.95400","2.57968","0.02119"
"5242","31.41600","2.61818","0.02188"
"5319","31.87800","2.65675","0.02340"
"5396","32.34000","2.69519","0.02214"
"5473","32.80200","2.73370","0.02303"
"5550","33.26400","2.77214","0.02380"
"5627","33.72600","2.81071","0.02409"
"5704","34.18800","2.84921","0.01608"
"5781","34.65000","2.88771","0.02394"
"5858","35.11200","2.92622","0.02158"
"5935","35.57400","2.96472","0.02168"
"6012","36.03600","3.00317","0.02279"
"6089","36.49800","3.04167","0.02241"
"6166","36.96000","3.08018","0.02331"
"6243","37.42200","3.11874","0.02397"
"6320","37.88400","3.15725","0.02486"
"6397","38.34600","3.19575","0.02527"
"6474","38.80800","3.23419","0.02538"
"6551","39.27000","3.27264","0.02625"
"6628","39.73200","3.31114","0.02707"
"6705","40.19400","3.34971","0.02763"
"6782","40.65600","3.38815","0.02884"
"6859","41.11800","3.42672","0.02829"
"6936","41.58000","3.46516","0.02891"
"7013","42.04200","3.50379","0.02843"
"7090","42.50400","3.54217","0.02928"
"7167","42.96600","3.58062","0.02958"
"7244","43.42800","3.61918","0.03012"
"7321","43.89000","3.65768","0.03030"
"7398","44.35200","3.69619","0.03074"
"7475","44.81400","3.73469","0.03128"
"7552","45.27600","3.77320","0.03165"
"7629","45.73800","3.81164","0.03192"
"7706","46.20000","3.85015","0.03193"
"7783","46.66200","3.88865","0.03259"
"7860","47.12400","3.92722","0.03221"
"7937","47.58600","3.96572","0.03256"
"8014","48.04800","4.00422","0.03303"
"8091","48.51000","4.04279","0.03337"
"8168","48.97200","4.08117","0.03400"
"8245","49.43400","4.11962","0.03439"
"8322","49.89600","4.15812","0.03468"
"8399","50.35800","4.19675","0.03479"
"8476","50.82000","4.23519","0.03534"
"8553","51.28200","4.27370","0.03546"
"8630","51.74400","4.31226","0.03568"
"8707","52.20600","4.35071","0.03610"
"8784","52.66800","4.38921","0.03661"
"8861","53.13000","4.42771","0.03688"
"8938","53.59200","4.46616","0.03707"
"9015","54.05400","4.50472","0.03743"
"9092","54.51600","4.54323","0.03791"
"9169","54.97800","4.58173","0.03858"
"9246","55.44000","4.62018","0.03902"
"9323","55.90200","4.65868","0.03958"
"9400","56.36400","4.69719","0.03994"
"9477","56.82600","4.73569","0.04028"
"9554","57.28800","4.77419","0.04125"
"9631","57.75000","4.81270","0.04233"
"9708","58.21200","4.85120","0.04255"
"9785","58.67400","4.88971","0.04315"
"9862","59.13600","4.92815","0.04397"
"9939","59.59800","4.96666","0.04465"
"10016","60.06000","5.00516","0.04512"
"10093","60.52200","5.04367","0.04602"
"10170","60.98400","5.08223","0.04677"
"10247","61.44600","5.12073","0.04759"
"10324","61.90800","5.15918","0.04876"
"10401","62.37000","5.19762","0.04957"
"10478","62.83200","5.23619","0.05026"
"10555","63.29400","5.27469","0.05098"
"10632","63.75600","5.31320","0.05203"
"10709","64.21800","5.35170","0.05303"
"10786","64.68000","5.39021","0.05436"
"10863","65.14200","5.42871","0.05466"
"10940","65.60400","5.46721","0.05569"
"11017","66.06600","5.50560","0.05631"
"11094","66.52800","5.54416","0.05681"
"11171","66.99000","5.58273","0.05787"
"11248","67.45200","5.62123","0.05874"
"11325","67.91400","5.65974","0.05888"
"11402","68.37600","5.69818","0.06007"
"11479","68.83800","5.73669","0.06075"
"11556","69.30000","5.77513","0.06134"
"11633","69.76200","5.81376","0.06209"
"11710","70.22400","5.85220","0.06211"
"11787","70.68600","5.89070","0.06324"
"11864","71.14800","5.92921","0.06430"
"11941","71.61000","5.96771","0.06425"
"12018","72.07200","6.00616","0.06569"
"12095","72.53400","6.04466","0.06685"
"12172","72.99600","6.08317","0.06744"
"12249","73.45800","6.12173","0.06929"
"12326","73.92000","6.16024","0.07043"
"12403","74.38200","6.19868","0.07145"
"12480","74.84400","6.23718","0.07247"
"12557","75.30600","6.27569","0.07330"
"12634","75.76800","6.31413","0.07514"
"12711","76.23000","6.35270","0.07509"
"12788","76.69200","6.39120","0.07627"
"12865","77.15400","6.42971","0.07671"
"12942","77.61600","6.46821","0.07841"
"13019","78.07800","6.50678","0.07840"
"13096","78.54000","6.54516","0.07929"
"13173","79.00200","6.58360","0.07977"
"13250","79.46400","6.62217","0.08026"
"13327","79.92600","6.66073","0.08103"
"13404","80.38800","6.69924","0.08130"
"13481","80.85000","6.73768","0.08191"
"13558","81.31200","6.77619","0.08240"
"13635","81.77400","6.81469","0.08265"
"13712","82.23600","6.85314","0.08309"
"13789","82.69800","6.89170","0.08360"
"13866","83.16000","6.93015","0.08410"
"13943","83.62200","6.96871","0.08423"
"14020","84.08400","7.00721","0.08473"
"14097","84.54600","7.04572","0.08512"
"14174","85.00800","7.08416","0.08622"
"14251","85.47000","7.12261","0.08740"
"14328","85.93200","7.16117","0.08811"
"14405","86.39400","7.19974","0.08894"
"14482","86.85600","7.23818","0.09050"
"14559","87.31800","7.27668","0.09138"
"14636","87.78000","7.31519","0.09271"
"14713","88.24200","7.35369","0.09410"
"14790","88.70400","7.39220","0.09534"
"14867","89.16600","7.43064","0.09700"
"14944","89.62800","7.46921","0.09902"
"15021","90.09000","7.50771","0.09932"
"15098","90.55200","7.54622","0.09893"
"15175","91.01400","7.58472","0.10002"
"15252","91.47600","7.62323","0.10180"
"15329","91.93800","7.66167","0.10355"
"15406","92.40000","7.70018","0.10445"
"15483","92.86200","7.73874","0.10631"
"15560","93.32400","7.77724","0.10673"
"15637","93.78600","7.81569","0.10802"
"15714","94.24800","7.85419","0.10859"
"15791","94.71000","7.89270","0.09091"
"15868","95.17200","7.93114","0.08979"
"15945","95.63400","7.96971","0.08529"
"16022","96.09600","8.00815","0.08639"
"16099","96.55800","8.04677","0.08755"
"16176","97.02000","8.08522","0.08805"
"16253","97.48200","8.12372","0.08896"
"16330","97.94400","8.16217","0.09080"
"16407","98.40600","8.20061","0.09215"
"16484","98.86800","8.23924","0.09094"
"16561","99.33000","8.27768","0.09253"
"16638","99.79200","8.31619","0.09464"
"16715","100.25400","8.35469","0.09636"
"16792","100.71600","8.39319","0.09815"
"16869","101.17800","8.43170","0.10039"
"16946","101.64000","8.47014","0.10155"
"17023","102.10200","8.50871","0.10323"
"17100","102.56400","8.54715","0.10426"
"17177","103.02600","8.58572","0.10621"
"17254","103.48800","8.62422","0.10782"
"17331","103.95000","8.66273","0.10913"
"17408","104.41200","8.70117","0.11095"
"17485","104.87400","8.73962","0.11256"
"17562","105.33600","8.77818","0.11325"
"17639","105.79800","8.81668","0.11419"
"17716","106.26000","8.85525","0.11560"
"17793","106.72200","8.89369","0.11661"
"17870","107.18400","8.93226","0.11730"
"17947","107.64600","8.97070","0.11857"
"18024","108.10800","9.00915","0.11911"
"18101","108.57000","9.04771","0.11964"
"18178","109.03200","9.08615","0.12078"
"18255","109.49400","9.12472","0.12167"
"18332","109.95600","9.16316","0.12273"
"18409","110.41800","9.20167","0.12344"
"18486","110.88000","9.24023","0.12429"
"18563","111.34200","9.27868","0.12510"
"18640","111.80400","9.31712","0.12533"
"18717","112.26600","9.35569","0.12613"
"18794","112.72800","9.39419","0.12662"
"18871","113.19000","9.43276","0.12730"
"18948","113.65200","9.47120","0.12763"
"19025","114.11400","9.50970","0.12814"
"19102","114.57600","9.54815","0.12854"
"19179","115.03800","9.58665","0.12932"
"19256","115.50000","9.62516","0.12982"
"19333","115.96200","9.66366","0.13059"
"19410","116.42400","9.70223","0.13105"
"19487","116.88600","9.74073","0.13178"
"19564","117.34800","9.77918","0.13274"
"19641","117.81000","9.81768","0.13257"
"19718","118.27200","9.85618","0.13328"
"19795","118.73400","9.89469","0.13405"
"19872","119.19600","9.93319","0.13535"
"19949","119.65800","9.97170","0.13577"
"20026","120.12000","10.01020","0.13757"
"20103","120.58200","10.04871","0.13897"
"20180","121.04400","10.08715","0.14025"
"20257","121.50600","10.12566","0.14235"
"20334","121.96800","10.16422","0.14501"
"20411","122.43000","10.20272","0.14607"
"20488","122.89200","10.24123","0.14900"
"20565","123.35400","10.27967","0.15145"
"20642","123.81600","10.31824","0.15458"
"20719","124.27800","10.35668","0.15731"
"20796","124.74000","10.39519","0.15789"
"20873","125.20200","10.43369","0.15675"
"20950","125.66400","10.47220","0.16005"
"21027","126.12600","10.51070","0.16341"
"21104","126.58800","10.54920","0.16546"
"21181","127.05000","10.58771","0.16908"
"21258","127.51200","10.62621","0.17292"
"21335","127.97400","10.66466","0.17570"
"21412","128.43600","10.70316","0.17745"
"21489","128.89800","10.74173","0.18065"
"21566","129.36000","10.78023","0.18291"
"21643","129.82200","10.81868","0.18389"
"21720","130.28400","10.85718","0.18555"
"21797","130.74600","10.89569","0.18639"
"21874","131.20800","10.93413","0.18737"
"21951","131.67000","10.97269","0.18804"
"22028","132.13200","11.01120","0.18827"
"22105","132.59400","11.04976","0.18984"
"22182","133.05600","11.08821","0.19132"
"22259","133.51800","11.12671","0.18256"
"22336","133.98000","11.16516","0.18403"
"22413","134.44200","11.20366","0.18459"
"22490","134.90400","11.24223","0.18531"
"22567","135.36600","11.28067","0.18650"
"22644","135.82800","11.31923","0.18793"
"22721","136.29000","11.35774","0.18774"
"22798","136.75200","11.39624","0.18840"
"22875","137.21400","11.43469","0.18956"
"22952","137.67600","11.47313","0.19050"
"23029","138.13800","11.51164","0.19108"
"23106","138.60000","11.55020","0.19298"
"23183","139.06200","11.58871","0.19450"
"23260","139.52400","11.62721","0.19461"
"23337","139.98600","11.66572","0.19635"
"23414","140.44800","11.70422","0.19822"
"23491","140.91000","11.74266","0.18671"
"23568","141.37200","11.78117","0.18621"
"23645","141.83400","11.81967","0.18493"
"23722","142.29600","11.85818","0.18548"
"23799","142.75800","11.89668","0.18710"
"23876","143.22000","11.93525","0.18823"
"23953","143.68200","11.97369","0.18846"
"24030","144.14400","12.01219","0.18904"
"24107","144.60600","12.05070","0.19094"
"24184","145.06800","12.08920","0.19115"
"24261","145.53000","12.12771","0.10057"
"24338","145.99200","12.16615","0.09847"
"24415","146.45400","12.20472","0.09871"
"24492","146.91600","12.24322","0.09832"
"24569","147.37800","12.28167","0.09531"
"24646","147.84000","12.32011","0.09638"
"24723","148.30200","12.35868","0.09840"
"24800","148.76400","12.39724","0.10085"
"24877","149.22600","12.43575","0.10466"
"24954","149.68800","12.47425","0.10635"
"25031","150.15000","12.51269","0.10717"
"25108","150.61200","12.55114","0.10802"
"25185","151.07400","12.58970","0.10951"
"25262","151.53600","12.62821","0.11068"
"25339","151.99800","12.66671","0.11184"
"25416","152.46000","12.70522","0.11352"
"25493","152.92200","12.74366","0.11509"
"25570","153.38400","12.78223","0.10894"
"25647","153.84600","12.82067","0.10804"
"25724","154.30800","12.85917","0.10877"
"25801","154.77000","12.89768","0.10955"
"25878","155.23200","12.93618","0.11007"
"25955","155.69400","12.97475","0.11183"
"26032","156.15600","13.01325","0.11319"
"26109","156.61800","13.05170","0.11351"
"26186","157.08000","13.09014","0.11521"
"26263","157.54200","13.12864","0.11602"
"26340","158.00400","13.16721","0.11763"
"26417","158.46600","13.20571","0.11894"
"26494","158.92800","13.24416","0.12066"
"26571","159.39000","13.28272","0.12163"
"26648","159.85200","13.32123","0.12272"
"26725","160.31400","13.35967","0.12391"
"26802","160.77600","13.39818","0.12485"
"26879","161.23800","13.43668","0.12594"
"26956","161.70000","13.47525","0.12697"
"27033","162.16200","13.51369","0.12782"
"27110","162.62400","13.55220","0.12899"
"27187","163.08600","13.59070","0.13001"
"27264","163.54800","13.62914","0.13140"
"27341","164.01000","13.66771","0.13253"
"27418","164.47200","13.70621","0.13379"
"27495","164.93400","13.74466","0.13512"
"27572","165.39600","13.78322","0.13607"
"27649","165.85800","13.82173","0.13254"
"27726","166.32000","13.86023","0.13477"
"27803","166.78200","13.89867","0.13720"
"27880","167.24400","13.93712","0.14136"
"27957","167.70600","13.97568","0.14537"
"28034","168.16800","14.01419","0.15001"
"28111","168.63000","14.05275","0.15531"
"28188","169.09200","14.09120","0.16149"
"28265","169.55400","14.12970","0.16560"
"28342","170.01600","14.16815","0.17133"
"28419","170.47800","14.20671","0.17690"
"28496","170.94000","14.24516","0.18060"
"28573","171.40200","14.28366","0.18464"
"28650","171.86400","14.32222","0.18679"
"28727","172.32600","14.36079","0.18842"
"28804","172.78800","14.39923","0.18989"
"28881","173.25000","14.43768","0.19267"
"28958","173.71200","14.47612","0.19519"
"29035","174.17400","14.51469","0.19796"
"29112","174.63600","14.55325","0.19948"
"29189","175.09800","14.59176","0.20362"
"29266","175.56000","14.63014","0.20489"
"29343","176.02200","14.66870","0.20733"
"29420","176.48400","14.70715","0.20992"
"29497","176.94600","14.74565","0.21211"
"29574","177.40800","14.78422","0.21499"
"29651","177.87000","14.82266","0.21829"
"29728","178.33200","14.86123","0.22119"
"29805","178.79400","14.89973","0.22433"
"29882","179.25600","14.93824","0.22692"
"29959","179.71800","14.97668","0.22927"
"30036","180.18000","15.01513","0.23043"
"30113","180.64200","15.05369","0.23184"
"30190","181.10400","15.09219","0.23289"
"30267","181.56600","15.13070","0.23359"
"30344","182.02800","15.16920","0.23275"
"30421","182.49000","15.20765","0.23420"
"30498","182.95200","15.24621","0.23566"
"30575","183.41400","15.28466","0.23686"
"30652","183.87600","15.32316","0.23884"
"30729","184.33800","15.36166","0.24089"
"30806","184.80000","15.40023","0.24462"
"30883","185.26200","15.43874","0.24863"
"30960","185.72400","15.47718","0.25263"
"31037","186.18600","15.51562","0.25478"
"31114","186.64800","15.55413","0.25865"
"31191","187.11000","15.59269","0.26327"
"31268","187.57200","15.63126","0.26773"
"31345","188.03400","15.66976","0.27183"
"31422","188.49600","15.70820","0.27569"
"31499","188.95800","15.74671","0.27829"
"31576","189.42000","15.78527","0.28083"
"31653","189.88200","15.82366","0.28300"
"31730","190.34400","15.86216","0.28609"
"31807","190.80600","15.90067","0.29071"
"31884","191.26800","15.93923","0.29620"
"31961","191.73000","15.97774","0.30307"
"32038","192.19200","16.01624","0.30803"
"32115","192.65400","16.05468","0.31493"
"32192","193.11600","16.09313","0.32043"
"32269","193.57800","16.13169","0.32626"
"32346","194.04000","16.17020","0.33177"
"32423","194.50200","16.20870","0.33614"
"32500","194.96400","16.24715","0.33945"
"32577","195.42600","16.28577","0.34097"
"32654","195.88800","16.32416","0.34191"
"32731","196.35000","16.36266","0.34266"
"32808","196.81200","16.40117","0.34398"
"32885","197.27400","16.43967","0.34547"
"32962","197.73600","16.47824","0.34742"
"33039","198.19800","16.51668","0.35020"
"33116","198.66000","16.55524","0.35322"
"33193","199.12200","16.59363","0.35609"
"33270","199.58400","16.63213","0.35619"
"33347","200.04600","16.67064","0.36020"
"33424","200.50800","16.70920","0.36802"
"33501","200.97000","16.74771","0.37528"
"33578","201.43200","16.78621","0.38298"
"33655","201.89400","16.82471","0.38835"
"33732","202.35600","16.86322","0.39120"
"33809","202.81800","16.90166","0.39435"
"33886","203.28000","16.94017","0.40022"
"33963","203.74200","16.97867","0.40496"
"34040","204.20400","17.01718","0.40697"
"34117","204.66600","17.05568","0.41152"
"34194","205.12800","17.09425","0.41731"
"34271","205.59000","17.13275","0.42106"
"34348","206.05200","17.17119","0.42508"
"34425","206.51400","17.20964","0.42795"
"34502","206.97600","17.24814","0.43085"
"34579","207.43800","17.28665","0.43412"
"34656","207.90000","17.32521","0.43780"
"34733","208.36200","17.36372","0.44208"
"34810","208.82400","17.40222","0.44688"
"34887","209.28600","17.44073","0.45208"
"34964","209.74800","17.47917","0.45706"
"35041","210.21000","17.51768","0.46263"
"35118","210.67200","17.55624","0.46843"
"35195","211.13400","17.59468","0.47276"
"35272","211.59600","17.63319","0.47813"
"35349","212.05800","17.67169","0.48025"
"35426","212.52000","17.71020","0.48367"
"35503","212.98200","17.74864","0.48768"
"35580","213.44400","17.78715","0.49092"
"35657","213.90600","17.82571","0.49323"
"35734","214.36800","17.86422","0.49752"
"35811","214.83000","17.90272","0.50617"
"35888","215.29200","17.94123","0.51384"
"35965","215.75400","17.97961","0.51932"
"36042","216.21600","18.01817","0.52561"
"36119","216.67800","18.05668","0.52765"
"36196","217.14000","18.09518","0.53429"
"36273","217.60200","18.13369","0.53979"
"36350","218.06400","18.17213","0.54455"
"36427","218.52600","18.21070","0.54887"
"36504","218.98800","18.24920","0.55082"
"36581","219.45000","18.28765","0.55050"
"36658","219.91200","18.32615","0.55274"
"36735","220.37400","18.36471","0.55494"
"36812","220.83600","18.40316","0.55749"
"36889","221.29800","18.44166","0.56117"
"36966","221.76000","18.48023","0.56646"
"37043","222.22200","18.51867","0.57234"
"37120","222.68400","18.55712","0.57840"
"37197","223.14600","18.59568","0.58646"
"37274","223.60800","18.63419","0.59300"
"37351","224.07000","18.67275","0.59865"
"37428","224.53200","18.71125","0.60461"
"37505","224.99400","18.74970","0.61225"
"37582","225.45600","18.78820","0.61809"
"37659","225.91800","18.82665","0.62522"
"37736","226.38000","18.86515","0.63229"
"37813","226.84200","18.90372","0.63519"
"37890","227.30400","18.94222","0.63807"
"37967","227.76600","18.98072","0.63951"
"38044","228.22800","19.01923","0.64003"
"38121","228.69000","19.05767","0.63997"
"38198","229.15200","19.09618","0.62297"
"38275","229.61400","19.13462","0.62708"
"38352","230.07600","19.17319","0.62943"
"38429","230.53800","19.21169","0.63470"
"38506","231.00000","19.25020","0.63780"
"38583","231.46200","19.28876","0.64049"
"38660","231.92400","19.32721","0.64233"
"38737","232.38600","19.36565","0.64365"
"38814","232.84800","19.40415","0.64586"
"38891","233.31000","19.44272","0.64328"
"38968","233.77200","19.48122","0.64402"
"39045","234.23400","19.51967","0.64610"
"39122","234.69600","19.55823","0.64899"
"39199","235.15800","19.59668","0.65199"
"39276","235.62000","19.63518","0.65577"
"39353","236.08200","19.67369","0.66112"
"39430","236.54400","19.71219","0.66831"
"39507","237.00600","19.75070","0.67495"
"39584","237.46800","19.78920","0.68218"
"39661","237.93000","19.82771","0.69217"
"39738","238.39200","19.86621","0.69963"
"39815","238.85400","19.90465","0.70264"
"39892","239.31600","19.94316","0.70654"
"39969","239.77800","19.98172","0.71356"
"40046","240.24000","20.02017","0.72247"
"40123","240.70200","20.05867","0.73167"
"40200","241.16400","20.09723","0.73975"
"40277","241.62600","20.13568","0.74608"
"40354","242.08800","20.17418","0.75086"
"40431","242.55000","20.21269","0.75414"
"40508","243.01200","20.25113","0.75687"
"40585","243.47400","20.28970","0.76076"
"40662","243.93600","20.32826","0.76643"
"40739","244.39800","20.36677","0.77387"
"40816","244.86000","20.40521","0.78227"
"40893","245.32200","20.44366","0.79082"
"40970","245.78400","20.48216","0.79713"
"41047","246.24600","20.52073","0.80438"
"41124","246.70800","20.55917","0.81527"
"41201","247.17000","20.59767","0.82788"
"41278","247.63200","20.63618","0.83803"
"41355","248.09400","20.67474","0.84559"
"41432","248.55600","20.71319","0.85249"
"41509","249.01800","20.75169","0.85527"
"41586","249.48000","20.79020","0.85740"
"41663","249.94200","20.82870","0.86007"
"41740","250.40400","20.86727","0.86335"
"41817","250.86600","20.90577","0.86727"
"41894","251.32800","20.94415","0.87277"
"41971","251.79000","20.98260","0.87852"
"42048","252.25200","21.02116","0.88578"
"42125","252.71400","21.05967","0.89399"
"42202","253.17600","21.09823","0.89860"
"42279","253.63800","21.13674","0.90023"
"42356","254.10000","21.17524","0.90359"
"42433","254.56200","21.21369","0.90734"
"42510","255.02400","21.25219","0.91464"
"42587","255.48600","21.29063","0.91274"
"42664","255.94800","21.32914","0.90640"
"42741","256.41000","21.36770","0.91480"
"42818","256.87200","21.40621","0.92762"
"42895","257.33400","21.44471","0.93596"
"42972","257.79600","21.48322","0.93262"
"43049","258.25800","21.52166","0.94087"
"43126","258.72000","21.56017","0.94677"
"43203","259.18200","21.59867","0.95014"
"43280","259.64400","21.63717","0.95284"
"43357","260.10600","21.67574","0.95649"
"43434","260.56800","21.71424","0.96156"
"43511","261.03000","21.75269","0.96927"
"43588","261.49200","21.79119","0.97866"
"43665","261.95400","21.82964","0.98841"
"43742","262.41600","21.86820","1.00030"
"43819","262.87800","21.90670","1.00970"
"43896","263.34000","21.94521","1.01549"
"43973","263.80200","21.98371","1.02247"
"44050","264.26400","22.02216","1.03178"
"44127","264.72600","22.06067","1.03941"
"44204","265.18800","22.09917","1.04713"
"44281","265.65000","22.13767","1.05265"
"44358","266.11200","22.17618","1.05520"
"44435","266.57400","22.21474","1.05747"
"44512","267.03600","22.25325","1.06045"
"44589","267.49800","22.29175","1.06505"
"44666","267.96000","22.33019","1.07341"
"44743","268.42200","22.36864","1.08256"
"44820","268.88400","22.40714","1.09071"
"44897","269.34600","22.44577","1.10208"
"44974","269.80800","22.48421","1.10480"
"45051","270.27000","22.52272","1.11165"
"45128","270.73200","22.56122","1.11909"
"45205","271.19400","22.59973","1.13042"
"45282","271.65600","22.63817","1.14448"
"45359","272.11800","22.67668","1.15579"
"45436","272.58000","22.71512","1.16423"
"45513","273.04200","22.75368","1.16932"
"45590","273.50400","22.79219","1.17211"
"45667","273.96600","22.83075","1.17447"
"45744","274.42800","22.86920","1.17740"
"45821","274.89000","22.90758","1.18341"
"45898","275.35200","22.94621","1.19591"
"45975","275.81400","22.98471","1.20544"
"46052","276.27600","23.02322","1.21151"
"46129","276.73800","23.06166","1.22135"
"46206","277.20000","23.10016","1.23377"
"46283","277.66200","23.13867","1.24342"
"46360","278.12400","23.17718","1.25314"
"46437","278.58600","23.21562","1.17710"
"46514","279.04800","23.25418","1.17559"
"46591","279.51000","23.29269","1.17793"
"46668","279.97200","23.33125","1.18350"
"46745","280.43400","23.36970","1.19530"
"46822","280.89600","23.40820","1.20593"
"46899","281.35800","23.44664","1.21597"
"46976","281.82000","23.48515","1.22862"
"47053","282.28200","23.52371","1.24243"
"47130","282.74400","23.56222","1.25505"
"47207","283.20600","23.60066","1.26593"
"47284","283.66800","23.63923","1.27084"
"47361","284.13000","23.67773","1.27792"
"47438","284.59200","23.71611","1.29104"
"47515","285.05400","23.75468","1.30488"
"47592","285.51600","23.79318","1.31571"
"47669","285.97800","23.83175","1.32227"
"47746","286.44000","23.87019","1.32562"
"47823","286.90200","23.90870","1.33577"
"47900","287.36400","23.94714","1.34628"
"47977","287.82600","23.98559","1.35352"
"48054","288.28800","24.02415","1.35985"
"48131","288.75000","24.06272","1.36056"
"48208","289.21200","24.10122","1.17961"
"48285","289.67400","24.13972","1.17377"
"48362","290.13600","24.17823","1.17428"
"48439","290.59800","24.21667","1.17500"
"48516","291.06000","24.25518","1.17760"
"48593","291.52200","24.29362","1.17336"
"48670","291.98400","24.33219","1.17451"
"48747","292.44600","24.37075","1.17832"
"48824","292.90800","24.40920","1.18320"
"48901","293.37000","24.44776","1.19542"
"48978","293.83200","24.48615","1.20511"
"49055","294.29400","24.52465","1.21855"
"49132","294.75600","24.56316","1.23082"
"49209","295.21800","24.60172","1.23047"
"49286","295.68000","24.64022","1.23649"
"49363","296.14200","24.67867","1.25369"
"49440","296.60400","24.71723","1.26397"
"49517","297.06600","24.75568","1.27020"
"49594","297.52800","24.79418","1.27077"
"49671","297.99000","24.83269","0.92976"
"49748","298.45200","24.87119","0.93289"
"49825","298.91400","24.90969","0.93903"
"49902","299.37600","24.94820","0.94395"
"49979","299.83800","24.98670","0.94879"
"50056","300.30000","25.02521","0.95465"
"50133","300.76200","25.06365","0.96395"
"50210","301.22400","25.10216","0.97664"
"50287","301.68600","25.14066","0.98617"
"50364","302.14800","25.17923","0.99988"
"50441","302.61000","25.21773","1.01196"
"50518","303.07200","25.25624","1.02036"
"50595","303.53400","25.29468","1.02759"
"50672","303.99600","25.33313","1.03510"
"50749","304.45800","25.37163","1.04518"
"50826","304.92000","25.41019","1.05174"
"50903","305.38200","25.44870","1.05564"
"50980","305.84400","25.48720","1.06062"
"51057","306.30600","25.52571","1.06579"
"51134","306.76800","25.56421","1.07671"
"51211","307.23000","25.60266","1.09142"
"51288","307.69200","25.64122","1.10600"
"51365","308.15400","25.67966","1.11838"
"51442","308.61600","25.71817","1.13050"
"51519","309.07800","25.75673","1.14560"
"51596","309.54000","25.79524","1.15997"
"51673","310.00200","25.83374","1.16651"
"51750","310.46400","25.87213","1.16936"
"51827","310.92600","25.91063","1.15711"
"51904","311.38800","25.94920","1.16259"
"51981","311.85000","25.98770","1.16896"
"52058","312.31200","26.02627","1.17224"
"52135","312.77400","26.06471","1.17610"
"52212","313.23600","26.10321","1.18352"
"52289","313.69800","26.14166","1.19758"
"52366","314.16000","26.18016","1.20970"
"52443","314.62200","26.21867","1.21995"
"52520","315.08400","26.25717","1.23619"
"52597","315.54600","26.29573","1.24744"
"52674","316.00800","26.33418","1.25888"
"52751","316.47000","26.37269","1.26617"
"52828","316.93200","26.41119","1.26839"
"52905","317.39400","26.44964","1.27251"
"52982","317.85600","26.48814","1.28060"
"53059","318.31800","26.52670","1.29389"
"53136","318.78000","26.56521","1.30576"
"53213","319.24200","26.60371","1.31461"
"53290","319.70400","26.64221","1.32151"
"53367","320.16600","26.68072","1.32480"
"53444","320.62800","26.71916","1.33454"
"53521","321.09000","26.75767","1.34409"
"53598","321.55200","26.79617","1.35160"
"53675","322.01400","26.83474","1.35777"
"53752","322.47600","26.87318","1.36460"
"53829","322.93800","26.91169","1.36987"
"53906","323.40000","26.95019","1.37959"
"53983","323.86200","26.98870","1.39202"
"54060","324.32400","27.02720","1.40224"
"54137","324.78600","27.06565","1.41621"
"54214","325.24800","27.10421","1.42625"
"54291","325.71000","27.14272","1.43894"
"54368","326.17200","27.18128","1.43720"
"54445","326.63400","27.21966","1.44521"
"54522","327.09600","27.25811","1.45535"
"54599","327.55800","27.29667","1.46371"
"54676","328.02000","27.33524","1.46758"
"54753","328.48200","27.37374","1.47233"
"54830","328.94400","27.41219","1.47387"
"54907","329.40600","27.45069","1.47417"
"54984","329.86800","27.48920","1.47598"
"55061","330.33000","27.52764","1.48122"
"55138","330.79200","27.56614","1.49033"
"55215","331.25400","27.60465","1.50442"
"55292","331.71600","27.64321","1.51870"
"55369","332.17800","27.68172","1.53011"
"55446","332.64000","27.72028","1.54385"
"55523","333.10200","27.75867","1.50241"
"55600","333.56400","27.79717","1.51683"
"55677","334.02600","27.83568","1.52431"
"55754","334.48800","27.87418","1.53839"
"55831","334.95000","27.91274","1.55138"
"55908","335.41200","27.95119","1.56018"
"55985","335.87400","27.98975","1.56972"
"56062","336.33600","28.02820","1.53803"
"56139","336.79800","28.06670","1.53444"
"56216","337.26000","28.10514","1.53943"
"56293","337.72200","28.14365","1.54857"
"56370","338.18400","28.18221","1.55778"
"56447","338.64600","28.22072","1.56559"
"56524","339.10800","28.25922","1.53184"
"56601","339.57000","28.29767","1.53861"
"56678","340.03200","28.33611","1.54939"
"56755","340.49400","28.37474","1.51287"
"56832","340.95600","28.41324","1.52324"
"56909","341.41800","28.45163","1.53413"
"56986","341.88000","28.49019","1.52330"
"57063","342.34200","28.52869","1.52655"
"57140","342.80400","28.56726","1.52987"
"57217","343.26600","28.60570","1.54318"
"57294","343.72800","28.64415","1.55241"
"57371","344.19000","28.68265","1.56005"
"57448","344.65200","28.72122","1.57062"
"57525","345.11400","28.75972","1.58282"
"57602","345.57600","28.79823","1.34432"
"57679","346.03800","28.83673","1.33187"
"57756","346.50000","28.87524","1.33710"
"57833","346.96200","28.91368","1.34294"
"57910","347.42400","28.95218","1.35097"
"57987","347.88600","28.99069","1.35507"
"58064","348.34800","29.02919","1.34128"
"58141","348.81000","29.06776","1.35033"
"58218","349.27200","29.10620","1.35780"
"58295","349.73400","29.14471","1.36769"
"58372","350.19600","29.18315","1.37905"
"58449","350.65800","29.22160","1.10622"
"58526","351.12000","29.26028","1.10034"
"58603","351.58200","29.29873","1.10258"
"58680","352.04400","29.33723","1.10802"
"58757","352.50600","29.37567","1.11060"
"58834","352.96800","29.41418","1.11502"
"58911","353.43000","29.45268","1.12027"
"58988","353.89200","29.49119","1.10615"
"59065","354.35400","29.52969","1.09238"
"59142","354.81600","29.56820","1.10519"
"59219","355.27800","29.60670","1.11674"
"59296","355.74000","29.64521","1.12357"
"59373","356.20200","29.68371","1.13827"
"59450","356.66400","29.72210","1.14867"
"59527","357.12600","29.76066","1.15985"
"59604","357.58800","29.79922","1.05415"
"59681","358.05000","29.83773","0.85450"
"59758","358.51200","29.87617","0.66578"
"59835","358.97400","29.91474","0.66329"
"59912","359.43600","29.95318","0.64767"
"59989","359.89800","29.99162","0.65049"
"60066","360.36000","30.03019","0.65657"
"60143","360.82200","30.06863","0.66238"
"60220","361.28400","30.10726","0.67447"
"60297","361.74600","30.14570","0.68451"
"60374","362.20800","30.18427","0.69778"
"60451","362.67000","30.22265","0.70220"
"60528","363.13200","30.26110","0.70666"
"60605","363.59400","30.29966","0.71746"
"60682","364.05600","30.33829","0.72952"
"60759","364.51800","30.37673","0.74051"
"60836","364.98000","30.41511","0.56027"
"60913","365.44200","30.45374","0.56839"
"60990","365.90400","30.49224","0.56958"
"61067","366.36600","30.53069","0.57272"
"61144","366.82800","30.56919","0.58502"
"61221","367.29000","30.60770","0.59506"
"61298","367.75200","30.64620","0.59736"
"61375","368.21400","30.68477","0.60323"
"61452","368.67600","30.72327","0.61463"
"61529","369.13800","30.76171","0.62615"
"61606","369.60000","30.80010","0.63101"
"61683","370.06200","30.83867","0.63811"
"61760","370.52400","30.87723","0.63968"
"61837","370.98600","30.91574","0.63936"
"61914","371.44800","30.95418","0.63694"
"61991","371.91000","30.99274","0.63987"
"62068","372.37200","31.03125","0.64267"
"62145","372.83400","31.06969","0.64520"
"62222","373.29600","31.10819","0.65008"
"62299","373.75800","31.14664","0.65713"
"62376","374.22000","31.18521","0.66688"
"62453","374.68200","31.22365","0.67719"
"62530","375.14400","31.26227","0.68977"
"62607","375.60600","31.30066","0.69985"
"62684","376.06800","31.33916","0.70330"
"62761","376.53000","31.37767","0.70966"
"62838","376.99200","31.41617","0.72108"
"62915","377.45400","31.45468","0.73135"
"62992","377.91600","31.49318","0.73948"
"63069","378.37800","31.53174","0.74570"
"63146","378.84000","31.57025","0.75137"
"63223","379.30200","31.60863","0.75573"
"63300","379.76400","31.64714","0.75958"
"63377","380.22600","31.68564","0.76561"
"63454","380.68800","31.72427","0.77383"
"63531","381.15000","31.76271","0.78358"
"63608","381.61200","31.80122","0.79165"
"63685","382.07400","31.83972","0.79660"
"63762","382.53600","31.87810","0.80449"
"63839","382.99800","31.91673","0.81492"
"63916","383.46000","31.95517","0.82344"
"63993","383.92200","31.99368","0.83285"
"64070","384.38400","32.03218","0.84127"
"64147","384.84600","32.07074","0.84110"
"64224","385.30800","32.10919","0.84589"
"64301","385.77000","32.14769","0.76502"
"64378","386.23200","32.18614","0.76899"
"64455","386.69400","32.22464","0.77973"
"64532","387.15600","32.26327","0.79002"
"64609","387.61800","32.30171","0.79645"
"64686","388.08000","32.34022","0.80585"
"64763","388.54200","32.37866","0.82196"
"64840","389.00400","32.41717","0.83916"
"64917","389.46600","32.45567","0.85031"
"64994","389.92800","32.49417","0.85494"
"65071","390.39000","32.53274","0.85761"
"65148","390.85200","32.57119","0.86028"
"65225","391.31400","32.60975","0.86247"
"65302","391.77600","32.64819","0.86602"
"65379","392.23800","32.68664","0.87310"
"65456","392.70000","32.72514","0.88080"
"65533","393.16200","32.76371","0.89056"
"65610","393.62400","32.80221","0.89769"
"65687","394.08600","32.84072","0.90315"
"65764","394.54800","32.87922","0.90781"
"65841","395.01000","32.91772","0.91784"
"65918","395.47200","32.95617","0.93014"
"65995","395.93400","32.99467","0.93801"
"66072","396.39600","33.03318","0.94323"
"66149","396.85800","33.07168","0.94476"
"66226","397.32000","33.11024","0.95008"
"66303","397.78200","33.14869","0.95623"
"66380","398.24400","33.18719","0.96127"
"66457","398.70600","33.22564","0.96701"
"66534","399.16800","33.26414","0.97562"
"66611","399.63000","33.30271","0.98450"
"66688","400.09200","33.34121","0.99316"
"66765","400.55400","33.37972","1.00104"
"66842","401.01600","33.41822","1.00939"
"66919","401.47800","33.45667","1.01564"
"66996","401.94000","33.49523","1.02090"
"67073","402.40200","33.53374","1.02917"
"67150","402.86400","33.57218","1.03676"
"67227","403.32600","33.61069","1.04106"
"67304","403.78800","33.64925","1.02828"
"67381","404.25000","33.68776","1.03401"
"67458","404.71200","33.72626","1.03981"
"67535","405.17400","33.76464","1.04308"
"67612","405.63600","33.80315","0.95675"
"67689","406.09800","33.84165","0.95939"
"67766","406.56000","33.88021","0.96257"
"67843","407.02200","33.91872","0.96519"
"67920","407.48400","33.95716","0.97091"
"67997","407.94600","33.99573","0.97895"
"68074","408.40800","34.03417","0.98576"
"68151","408.87000","34.07268","0.99503"
"68228","409.33200","34.11112","1.00218"
"68305","409.79400","34.14969","1.01063"
"68382","410.25600","34.18819","1.01639"
"68459","410.71800","34.22670","1.02325"
"68536","411.18000","34.26520","1.03094"
"68613","411.64200","34.30371","1.03765"
"68690","412.10400","34.34215","1.04340"
"68767","412.56600","34.38066","1.04923"
"68844","413.02800","34.41922","1.05320"
"68921","413.49000","34.45773","1.05554"
"68998","413.95200","34.49623","1.05736"
"69075","414.41400","34.53468","1.06019"
"69152","414.87600","34.57318","1.06457"
"69229","415.33800","34.61162","1.06954"
"69306","415.80000","34.65019","1.07570"
"69383","416.26200","34.68869","1.08104"
"69460","416.72400","34.72726","1.08829"
"69537","417.18600","34.76570","1.09749"
"69614","417.64800","34.80420","1.10519"
"69691","418.11000","34.84265","1.11322"
"69768","418.57200","34.88115","1.11869"
"69845","419.03400","34.91966","1.12711"
"69922","419.49600","34.95816","1.13829"
"69999","419.95800","34.99673","1.14854"
"70076","420.42000","35.03523","1.15814"
"70153","420.88200","35.07373","1.16394"
"70230","421.34400","35.11224","1.16804"
"70307","421.80600","35.15062","1.17075"
"70384","422.26800","35.18913","1.17269"
"70461","422.73000","35.22775","1.17342"
"70538","423.19200","35.26620","1.17509"
"70615","423.65400","35.30470","1.17820"
"70692","424.11600","35.34321","1.18075"
"70769","424.57800","35.38171","1.18484"
"70846","425.04000","35.42022","1.19257"
"70923","425.50200","35.45866","1.19793"
"71000","425.96400","35.49717","1.20454"
"71077","426.42600","35.53567","1.20727"
"71154","426.88800","35.57423","1.20976"
"71231","427.35000","35.61274","1.21062"
"71308","427.81200","35.65118","1.21346"
"71385","428.27400","35.68962","1.21756"
"71462","428.73600","35.72813","1.22444"
"71539","429.19800","35.76669","1.23298"
"71616","429.66000","35.80520","1.24054"
"71693","430.12200","35.84370","1.24909"
"71770","430.58400","35.88221","1.25679"
"71847","431.04600","35.92071","1.26310"
"71924","431.50800","35.95916","1.26718"
"72001","431.97000","35.99766","1.26950"
"72078","432.43200","36.03617","1.27278"
"72155","432.89400","36.07467","1.27834"
"72232","433.35600","36.11324","1.28630"
"72309","433.81800","36.15168","1.29367"
"72386","434.28000","36.19019","1.30131"
"72463","434.74200","36.22863","1.30850"
"72540","435.20400","36.26720","1.31594"
"72617","435.66600","36.30570","1.32080"
"72694","436.12800","36.34420","1.32288"
"72771","436.59000","36.38265","1.32699"
"72848","437.05200","36.42122","1.30388"
"72925","437.51400","36.45972","1.31169"
"73002","437.97600","36.49822","1.31773"
"73079","438.43800","36.53667","1.32140"
"73156","438.90000","36.57523","1.32409"
"73233","439.36200","36.61368","1.32887"
"73310","439.82400","36.65224","1.33671"
"73387","440.28600","36.69069","1.34222"
"73464","440.74800","36.72919","1.34748"
"73541","441.21000","36.76763","1.25693"
"73618","441.67200","36.80619","1.26050"
"73695","442.13400","36.84470","1.26713"
"73772","442.59600","36.88321","1.27075"
"73849","443.05800","36.92171","1.27917"
"73926","443.52000","36.96021","1.28549"
"74003","443.98200","36.99866","1.29681"
"74080","444.44400","37.03716","1.29500"
"74157","444.90600","37.07561","1.25321"
"74234","445.36800","37.11417","1.25738"
"74311","445.83000","37.15274","1.26428"
"74388","446.29200","37.19124","1.26652"
"74465","446.75400","37.22975","1.27086"
"74542","447.21600","37.26825","1.27370"
"74619","447.67800","37.30670","1.28157"
"74696","448.14000","37.34514","1.28979"
"74773","448.60200","37.38371","1.30025"
"74850","449.06400","37.42215","1.30867"
"74927","449.52600","37.46072","1.31765"
"75004","449.98800","37.49922","1.32124"
"75081","450.45000","37.53766","1.32239"
"75158","450.91200","37.57623","1.32530"
"75235","451.37400","37.61461","1.33094"
"75312","451.83600","37.65318","1.33876"
"75389","452.29800","37.69168","1.34424"
"75466","452.76000","37.73024","1.35042"
"75543","453.22200","37.76869","1.35475"
"75620","453.68400","37.80719","1.35761"
"75697","454.14600","37.84570","1.35853"
"75774","454.60800","37.88414","1.36304"
"75851","455.07000","37.92265","1.36856"
"75928","455.53200","37.96115","1.37286"
"76005","455.99400","37.99971","1.31851"
"76082","456.45600","38.03822","1.32226"
"76159","456.91800","38.07673","1.32360"
"76236","457.38000","38.11511","1.32563"
"76313","457.84200","38.15361","1.33187"
"76390","458.30400","38.19218","1.33780"
"76467","458.76600","38.23074","1.34546"
"76544","459.22800","38.26925","1.34452"
"76621","459.69000","38.30769","1.34902"
"76698","460.15200","38.34620","1.35322"
"76775","460.61400","38.38470","1.35764"
"76852","461.07600","38.42315","1.36168"
"76929","461.53800","38.46171","1.36619"
"77006","462.00000","38.50016","1.37263"
"77083","462.46200","38.53866","1.37898"
"77160","462.92400","38.57729","1.38765"
"77237","463.38600","38.61573","1.39544"
"77314","463.84800","38.65423","1.40409"
"77391","464.31000","38.69262","1.41400"
"77468","464.77200","38.73118","1.42235"
"77545","465.23400","38.76974","1.42955"
"77622","465.69600","38.80819","1.43461"
"77699","466.15800","38.84669","1.44344"
"77776","466.62000","38.88520","1.45086"
"77853","467.08200","38.92370","1.45785"
"77930","467.54400","38.96215","1.46442"
"78007","468.00600","39.00071","1.46981"
"78084","468.46800","39.03916","1.47276"
"78161","468.93000","39.07772","1.47383"
"78238","469.39200","39.11622","1.47410"
"78315","469.85400","39.15467","1.47475"
"78392","470.31600","39.19318","1.47683"
"78469","470.77800","39.23162","1.48044"
"78546","471.24000","39.27018","1.18879"
"78623","471.70200","39.30869","1.18300"
"78700","472.16400","39.34719","1.18252"
"78777","472.62600","39.38570","1.18646"
"78854","473.08800","39.42426","1.19529"
"78931","473.55000","39.46271","1.19879"
"79008","474.01200","39.50115","1.20706"
"79085","474.47400","39.53971","1.21163"
"79162","474.93600","39.57816","1.22008"
"79239","475.39800","39.61672","1.22848"
"79316","475.86000","39.65523","1.23933"
"79393","476.32200","39.69367","1.24868"
"79470","476.78400","39.73218","1.25536"
"79547","477.24600","39.77062","1.26218"
"79624","477.70800","39.80918","1.26327"
"79701","478.17000","39.84763","1.26796"
"79778","478.63200","39.88620","1.27126"
"79855","479.09400","39.92470","1.27570"
"79932","479.55600","39.96326","1.28114"
"80009","480.01800","40.00171","1.28903"
"80086","480.48000","40.04021","1.29528"
"80163","480.94200","40.07866","1.30309"
"80240","481.40400","40.11716","1.30651"
"80317","481.86600","40.15573","1.31142"
"80394","482.32800","40.19423","1.31628"
"80471","482.79000","40.23280","1.32001"
"80548","483.25200","40.27118","1.32245"
"80625","483.71400","40.30968","1.32474"
"80702","484.17600","40.34813","1.32931"
"80779","484.63800","40.38670","1.33668"
"80856","485.10000","40.42520","1.34412"
"80933","485.56200","40.46370","1.34932"
"81010","486.02400","40.50227","1.35444"
"81087","486.48600","40.54071","1.35799"
"81164","486.94800","40.57922","1.36160"
"81241","487.41000","40.61766","1.36521"
"81318","487.87200","40.65617","1.36954"
"81395","488.33400","40.69466","1.37551"
"81472","488.79600","40.73317","1.38085"
"81549","489.25800","40.77168","1.38774"
"81626","489.72000","40.81018","1.39401"
"81703","490.18200","40.84869","1.40158"
"81780","490.64400","40.88713","1.41069"
"81857","491.10600","40.92563","1.41656"
"81934","491.56800","40.96420","1.20832"
"82011","492.03000","41.00270","0.74910"
"82088","492.49200","41.04121","0.73374"
"82165","492.95400","41.07965","0.73368"
"82242","493.41600","41.11816","0.73686"
"82319","493.87800","41.15660","0.73930"
"82396","494.34000","41.19523","0.74461"
"82473","494.80200","41.23367","0.74678"
"82550","495.26400","41.27218","0.74933"
"82627","495.72600","41.31068","0.75190"
"82704","496.18800","41.34919","0.75414"
"82781","496.65000","41.38769","0.75662"
"82858","497.11200","41.42620","0.75844"
"82935","497.57400","41.46464","0.76216"
"83012","498.03600","41.50320","0.76643"
"83089","498.49800","41.54170","0.77090"
"83166","498.96000","41.58021","0.77593"
"83243","499.42200","41.61872","0.78312"
"83320","499.88400","41.65722","0.78523"
"83397","500.34600","41.69561","0.78349"
"83474","500.80800","41.73417","0.78647"
"83551","501.27000","41.77273","0.78635"
"83628","501.73200","41.81124","0.78601"
"83705","502.19400","41.84969","0.78306"
"83782","502.65600","41.88825","0.77739"
"83859","503.11800","41.92669","0.77959"
"83936","503.58000","41.96514","0.78256"
"84013","504.04200","42.00370","0.78546"
"84090","504.50400","42.04221","0.78999"
"84167","504.96600","42.08071","0.79273"
"84244","505.42800","42.11922","0.79460"
"84321","505.89000","42.15772","0.79610"
"84398","506.35200","42.19622","0.79880"
"84475","506.81400","42.23466","0.80229"
"84552","507.27600","42.27317","0.80713"
"84629","507.73800","42.31168","0.81001"
"84706","508.20000","42.35019","0.81634"
"84783","508.66200","42.38868","0.82003"
"84860","509.12400","42.42725","0.82416"
"84937","509.58600","42.46570","0.82772"
"85014","510.04800","42.50414","0.83184"
"85091","510.51000","42.54264","0.83410"
"85168","510.97200","42.58121","0.83297"
"85245","511.43400","42.61971","0.83164"
"85322","511.89600","42.65822","0.83003"
"85399","512.35800","42.69672","0.82745"
"85476","512.82000","42.73517","0.82330"
"85553","513.28200","42.77367","0.82104"
"85630","513.74400","42.81218","0.82005"
"85707","514.20600","42.85068","0.81825"
"85784","514.66800","42.88924","0.82023"
"85861","515.13000","42.92769","0.82268"
"85938","515.59200","42.96626","0.82875"
"86015","516.05400","43.00470","0.83419"
"86092","516.51600","43.04314","0.83884"
"86169","516.97800","43.08165","0.84518"
"86246","517.44000","43.12021","0.85013"
"86323","517.90200","43.15872","0.85308"
"86400","518.36400","43.19716","0.85538"
"86477","518.82600","43.23572","0.85704"
"86554","519.28800","43.27417","0.85878"
"86631","519.75000","43.31268","0.86074"
"86708","520.21200","43.35112","0.86301"
"86785","520.67400","43.38974","0.86644"
"86862","521.13600","43.42818","0.87022"
"86939","521.59800","43.46675","0.87539"
"87016","522.06000","43.50525","0.88030"
"87093","522.52200","43.54364","0.88568"
"87170","522.98400","43.58214","0.89322"
"87247","523.44600","43.62065","0.89977"
"87324","523.90800","43.65921","0.90381"
"87401","524.37000","43.69766","0.90762"
"87478","524.83200","43.73622","0.91251"
"87555","525.29400","43.77473","0.91895"
"87632","525.75600","43.81323","0.92577"
"87709","526.21800","43.85168","0.93252"
"87786","526.68000","43.89012","0.93825"
"87863","527.14200","43.92863","0.94287"
"87940","527.60400","43.96725","0.94637"
"88017","528.06600","44.00570","0.94958"
"88094","528.52800","44.04420","0.95357"
"88171","528.99000","44.08271","0.95753"
"88248","529.45200","44.12115","0.96197"
"88325","529.91400","44.15971","0.96599"
"88402","530.37600","44.19822","0.97114"
"88479","530.83800","44.23666","0.97630"
"88556","531.30000","44.27517","0.98230"
"88633","531.76200","44.31373","0.98685"
"88710","532.22400","44.35217","0.99282"
"88787","532.68600","44.39067","0.79924"
"88864","533.14800","44.42912","0.79919"
"88941","533.61000","44.46763","0.79778"
"89018","534.07200","44.50625","0.79714"
"89095","534.53400","44.54475","0.79825"
"89172","534.99600","44.58320","0.80153"
"89249","535.45800","44.62170","0.80884"
"89326","535.92000","44.66021","0.82028"
"89403","536.38200","44.69865","0.82738"
"89480","536.84400","44.73716","0.83237"
"89557","537.30600","44.77567","0.83899"
"89634","537.76800","44.81423","0.84351"
"89711","538.23000","44.85273","0.55997"
"89788","538.69200","44.89118","0.55914"
"89865","539.15400","44.92968","0.56459"
"89942","539.61600","44.96819","0.55946"
"90019","540.07800","45.00663","0.55986"
"90096","540.54000","45.04520","0.56123"
"90173","541.00200","45.08370","0.56517"
"90250","541.46400","45.12221","0.57359"
"90327","541.92600","45.16071","0.57596"
"90404","542.38800","45.19916","0.57572"
"90481","542.85000","45.23766","0.58029"
"90558","543.31200","45.27617","0.58681"
"90635","543.77400","45.31467","0.59247"
"90712","544.23600","45.35323","0.59732"
"90789","544.69800","45.39174","0.60000"
"90866","545.16000","45.43018","0.60213"
"90943","545.62200","45.46868","0.60445"
"91020","546.08400","45.50713","0.60937"
"91097","546.54600","45.54569","0.61549"
"91174","547.00800","45.58420","0.62190"
"91251","547.47000","45.62270","0.62774"
"91328","547.93200","45.66126","0.63230"
"91405","548.39400","45.69965","0.63467"
"91482","548.85600","45.73822","0.63734"
"91559","549.31800","45.77666","0.63924"
"91636","549.78000","45.81517","0.64101"
"91713","550.24200","45.85367","0.64230"
"91790","550.70400","45.89223","0.64332"
"91867","551.16600","45.93074","0.64465"
"91944","551.62800","45.96925","0.64573"
"92021","552.09000","46.00763","0.64772"
"92098","552.55200","46.04613","0.64981"
"92175","553.01400","46.08469","0.65222"
"92252","553.47600","46.12320","0.65549"
"92329","553.93800","46.16171","0.65861"
"92406","554.40000","46.20015","0.66265"
"92483","554.86200","46.23872","0.66665"
"92560","555.32400","46.27722","0.67158"
"92637","555.78600","46.31566","0.67332"
"92714","556.24800","46.35416","0.67694"
"92791","556.71000","46.39267","0.68215"
"92868","557.17200","46.43118","0.68789"
"92945","557.63400","46.46974","0.69283"
"93022","558.09600","46.50824","0.69636"
"93099","558.55800","46.54669","0.69965"
"93176","559.02000","46.58508","0.70146"
"93253","559.48200","46.62370","0.70224"
"93330","559.94400","46.66220","0.70373"
"93407","560.40600","46.70071","0.70488"
"93484","560.86800","46.73921","0.70690"
"93561","561.33000","46.77772","0.53984"
"93638","561.79200","46.81622","0.05020"
"93715","562.25400","46.85467","0.06500"
"93792","562.71600","46.89317","0.03367"
"93869","563.17800","46.93167","0.07902"
"93946","563.64000","46.97024","0.04012"
"94023","564.10200","47.00869","0.05434"
"94100","564.56400","47.04725","0.04551"
"94127","564.72200","47.06040","0.05111"