File: Trajectories_together/170212_1Specimen_RawData_10.csv
"","V1","V2","V3"
"1","End date","2/12/2017",""
"2","Specimen label","12BT_95",""
"3","Maximum Load","0.39216","N"
"4","Time","Extension","Load"
"5","(s)","(mm)","(N)"
"6","0.00000","0.00000","0.00051"
"41","0.21000","0.01531","0.00073"
"76","0.42000","0.03528","0.00158"
"111","0.63000","0.05273","0.00266"
"146","0.84000","0.07025","0.00311"
"181","1.05000","0.08771","0.00367"
"216","1.26000","0.10523","0.00415"
"251","1.47000","0.12275","0.00471"
"286","1.68000","0.14021","0.00470"
"321","1.89000","0.15772","0.00473"
"356","2.10000","0.17518","0.00540"
"391","2.31000","0.19270","0.00552"
"426","2.52000","0.21022","0.00568"
"461","2.73000","0.22762","0.00627"
"496","2.94200","0.24544","0.00615"
"531","3.15200","0.26283","0.00588"
"566","3.36200","0.28035","0.00662"
"601","3.57200","0.29787","0.00689"
"636","3.78200","0.31539","0.00639"
"671","3.99200","0.33285","0.00731"
"706","4.20200","0.35037","0.00685"
"741","4.41200","0.36783","0.00701"
"776","4.62200","0.38534","0.00720"
"811","4.83200","0.40280","0.00796"
"846","5.04200","0.42038","0.00765"
"881","5.25200","0.43790","0.00745"
"916","5.46200","0.45530","0.00817"
"951","5.67200","0.47288","0.00838"
"986","5.88200","0.49039","0.00783"
"1021","6.09200","0.50785","0.00846"
"1056","6.30200","0.52543","0.00866"
"1091","6.51200","0.54283","0.00899"
"1126","6.72200","0.56041","0.00868"
"1161","6.93200","0.57787","0.00983"
"1196","7.14200","0.59538","0.00877"
"1231","7.35200","0.61284","0.00921"
"1266","7.56200","0.63030","0.00988"
"1301","7.77200","0.64794","0.00937"
"1336","7.98200","0.66540","0.00970"
"1371","8.19200","0.68286","0.01014"
"1406","8.40200","0.70043","0.00929"
"1441","8.61200","0.71783","0.01040"
"1476","8.82200","0.73541","0.00995"
"1511","9.03200","0.75287","0.01004"
"1546","9.24200","0.77039","0.01022"
"1581","9.45200","0.78791","0.01018"
"1616","9.66200","0.80536","0.00994"
"1651","9.87200","0.82288","0.01017"
"1686","10.08200","0.84040","0.01021"
"1721","10.29200","0.85786","0.01066"
"1756","10.50200","0.87532","0.01091"
"1791","10.71200","0.89284","0.01086"
"1826","10.92200","0.91042","0.01144"
"1861","11.13200","0.92793","0.01086"
"1896","11.34200","0.94527","0.01066"
"1931","11.55200","0.96291","0.01190"
"1966","11.76200","0.98037","0.01266"
"2001","11.97200","0.99789","0.01148"
"2036","12.18200","1.01541","0.01141"
"2071","12.39200","1.03286","0.01106"
"2106","12.60200","1.05038","0.01167"
"2141","12.81200","1.06790","0.01194"
"2176","13.02200","1.08536","0.01183"
"2211","13.23200","1.10288","0.01215"
"2246","13.44200","1.12034","0.01202"
"2281","13.65200","1.13791","0.01249"
"2316","13.86200","1.15537","0.01230"
"2351","14.07200","1.17289","0.01315"
"2386","14.28200","1.19041","0.01276"
"2421","14.49200","1.20781","0.01265"
"2456","14.70200","1.22539","0.01366"
"2491","14.91200","1.24290","0.01290"
"2526","15.12200","1.26030","0.01328"
"2561","15.33200","1.27788","0.01361"
"2596","15.54200","1.29534","0.01341"
"2631","15.75200","1.31286","0.01311"
"2666","15.96200","1.33038","0.01345"
"2701","16.17200","1.34784","0.01364"
"2736","16.38200","1.36541","0.01331"
"2771","16.59200","1.38293","0.01379"
"2806","16.80200","1.40033","0.01429"
"2841","17.01200","1.41791","0.01425"
"2876","17.22200","1.43537","0.01386"
"2911","17.43200","1.45289","0.01437"
"2946","17.64200","1.47040","0.01408"
"2981","17.85200","1.48786","0.01431"
"3016","18.06200","1.50538","0.01396"
"3051","18.27200","1.52284","0.01460"
"3086","18.48200","1.54042","0.01418"
"3121","18.69200","1.55788","0.01428"
"3156","18.90200","1.57533","0.01443"
"3191","19.11200","1.59285","0.01489"
"3226","19.32200","1.61037","0.01431"
"3261","19.53200","1.62783","0.01494"
"3296","19.74200","1.64541","0.01466"
"3331","19.95200","1.66281","0.01505"
"3366","20.16200","1.68038","0.01488"
"3401","20.37200","1.69784","0.01520"
"3436","20.58200","1.71536","0.01442"
"3471","20.79200","1.73288","0.01522"
"3506","21.00200","1.75034","0.01543"
"3541","21.21200","1.76792","0.01576"
"3576","21.42200","1.78538","0.01532"
"3611","21.63200","1.80289","0.01464"
"3646","21.84200","1.82041","0.01508"
"3681","22.05200","1.83787","0.01454"
"3716","22.26200","1.85539","0.01568"
"3751","22.47200","1.87285","0.01512"
"3786","22.68200","1.89037","0.01499"
"3821","22.89200","1.90788","0.01590"
"3856","23.10200","1.92534","0.01519"
"3891","23.31200","1.94292","0.01547"
"3926","23.52200","1.96038","0.01547"
"3961","23.73200","1.97790","0.01533"
"3996","23.94200","1.99536","0.01492"
"4031","24.15200","2.01287","0.01537"
"4066","24.36200","2.03039","0.01562"
"4101","24.57200","2.04791","0.01619"
"4136","24.78200","2.06531","0.01605"
"4171","24.99200","2.08289","0.01565"
"4206","25.20200","2.10035","0.01580"
"4241","25.41200","2.11786","0.01628"
"4276","25.62200","2.13544","0.01609"
"4311","25.83200","2.15284","0.01592"
"4346","26.04200","2.17042","0.01613"
"4381","26.25200","2.18788","0.01575"
"4416","26.46200","2.20534","0.01638"
"4451","26.67200","2.22291","0.01587"
"4486","26.88200","2.24037","0.01564"
"4521","27.09200","2.25795","0.01621"
"4556","27.30200","2.27541","0.01642"
"4591","27.51200","2.29281","0.01600"
"4626","27.72200","2.31039","0.01656"
"4661","27.93200","2.32791","0.01600"
"4696","28.14200","2.34536","0.01611"
"4731","28.35200","2.36288","0.01677"
"4766","28.56200","2.38028","0.01640"
"4801","28.77200","2.39792","0.01625"
"4836","28.98200","2.41538","0.01660"
"4871","29.19200","2.43284","0.01613"
"4906","29.40200","2.45035","0.01682"
"4941","29.61200","2.46787","0.01701"
"4976","29.82200","2.48539","0.01637"
"5011","30.03200","2.50291","0.01644"
"5046","30.24200","2.52037","0.01616"
"5081","30.45200","2.53789","0.01591"
"5116","30.66200","2.55534","0.01643"
"5151","30.87200","2.57286","0.01655"
"5186","31.08200","2.59038","0.01641"
"5221","31.29200","2.60784","0.01670"
"5256","31.50200","2.62542","0.01649"
"5291","31.71200","2.64282","0.01679"
"5326","31.92200","2.66040","0.01677"
"5361","32.13200","2.67791","0.01691"
"5396","32.34200","2.69537","0.01665"
"5431","32.55200","2.71289","0.01726"
"5466","32.76200","2.73035","0.01686"
"5501","32.97200","2.74787","0.01716"
"5536","33.18200","2.76539","0.01726"
"5571","33.39200","2.78284","0.01721"
"5606","33.60200","2.80042","0.01710"
"5641","33.81200","2.81788","0.01743"
"5676","34.02200","2.83534","0.01663"
"5711","34.23200","2.85286","0.01710"
"5746","34.44200","2.87038","0.01702"
"5781","34.65200","2.88789","0.01692"
"5816","34.86200","2.90541","0.01722"
"5851","35.07200","2.92287","0.01739"
"5886","35.28200","2.94039","0.01725"
"5921","35.49200","2.95785","0.01713"
"5956","35.70200","2.97537","0.01733"
"5991","35.91200","2.99288","0.01732"
"6026","36.12200","3.01034","0.01720"
"6061","36.33200","3.02786","0.01725"
"6096","36.54200","3.04538","0.01722"
"6131","36.75200","3.06290","0.01672"
"6166","36.96200","3.08042","0.01756"
"6201","37.17200","3.09776","0.01721"
"6236","37.38200","3.11545","0.01745"
"6271","37.59200","3.13285","0.01778"
"6306","37.80200","3.15037","0.01711"
"6341","38.01200","3.16789","0.01736"
"6376","38.22200","3.18535","0.01753"
"6411","38.43200","3.20293","0.01718"
"6446","38.64200","3.22038","0.01751"
"6481","38.85200","3.23784","0.01690"
"6516","39.06200","3.25536","0.01790"
"6551","39.27200","3.27282","0.01732"
"6586","39.48200","3.29034","0.01759"
"6621","39.69200","3.30792","0.01713"
"6656","39.90200","3.32531","0.01736"
"6691","40.11200","3.34289","0.01756"
"6726","40.32200","3.36029","0.01742"
"6761","40.53200","3.37793","0.01792"
"6796","40.74200","3.39539","0.01683"
"6831","40.95200","3.41285","0.01695"
"6866","41.16200","3.43036","0.01739"
"6901","41.37200","3.44782","0.01699"
"6936","41.58200","3.46540","0.01690"
"6971","41.79200","3.48292","0.01745"
"7006","42.00200","3.50038","0.01698"
"7041","42.21200","3.51790","0.01794"
"7076","42.42200","3.53536","0.01710"
"7111","42.63200","3.55281","0.01755"
"7146","42.84200","3.57045","0.01730"
"7181","43.05200","3.58785","0.01720"
"7216","43.26200","3.60543","0.01776"
"7251","43.47200","3.62283","0.01748"
"7286","43.68200","3.64035","0.01752"
"7321","43.89200","3.65786","0.01795"
"7356","44.10200","3.67532","0.01780"
"7391","44.31200","3.69290","0.01742"
"7426","44.52200","3.71042","0.01760"
"7461","44.73200","3.72788","0.01745"
"7496","44.94200","3.74534","0.01755"
"7531","45.15200","3.76285","0.01730"
"7566","45.36200","3.78037","0.01732"
"7601","45.57200","3.79789","0.01751"
"7636","45.78200","3.81529","0.01696"
"7671","45.99200","3.83287","0.01717"
"7706","46.20200","3.85039","0.01789"
"7741","46.41200","3.86790","0.01774"
"7776","46.62200","3.88536","0.01771"
"7811","46.83200","3.90282","0.01749"
"7846","47.04200","3.92034","0.01789"
"7881","47.25200","3.93786","0.01758"
"7916","47.46200","3.95532","0.01817"
"7951","47.67200","3.97289","0.01761"
"7986","47.88200","3.99035","0.01758"
"8021","48.09200","4.00787","0.01755"
"8056","48.30200","4.02539","0.01769"
"8091","48.51200","4.04279","0.01718"
"8126","48.72200","4.06043","0.01742"
"8161","48.93200","4.07783","0.01776"
"8196","49.14200","4.09540","0.01754"
"8231","49.35200","4.11292","0.01759"
"8266","49.56200","4.13032","0.01738"
"8301","49.77200","4.14796","0.01706"
"8336","49.98200","4.16536","0.01713"
"8371","50.19200","4.18288","0.01737"
"8406","50.40200","4.20039","0.01721"
"8441","50.61200","4.21779","0.01716"
"8476","50.82200","4.23537","0.01759"
"8511","51.03200","4.25289","0.01758"
"8546","51.24200","4.27035","0.01736"
"8581","51.45200","4.28793","0.01726"
"8616","51.66200","4.30532","0.01690"
"8651","51.87200","4.32290","0.01743"
"8686","52.08200","4.34036","0.01797"
"8721","52.29200","4.35788","0.01731"
"8756","52.50200","4.37534","0.01795"
"8791","52.71200","4.39286","0.01820"
"8826","52.92200","4.41038","0.01741"
"8861","53.13200","4.42789","0.01815"
"8896","53.34200","4.44529","0.01806"
"8931","53.55200","4.46287","0.01767"
"8966","53.76200","4.48033","0.01756"
"9001","53.97200","4.49785","0.01779"
"9036","54.18200","4.51543","0.01726"
"9071","54.39200","4.53276","0.01758"
"9106","54.60200","4.55040","0.01741"
"9141","54.81200","4.56786","0.01789"
"9176","55.02200","4.58538","0.01776"
"9211","55.23200","4.60290","0.01800"
"9246","55.44200","4.62036","0.01807"
"9281","55.65200","4.63787","0.01703"
"9316","55.86200","4.65539","0.01774"
"9351","56.07200","4.67285","0.01749"
"9386","56.28200","4.69037","0.01731"
"9421","56.49200","4.70783","0.01773"
"9456","56.70200","4.72541","0.01768"
"9491","56.91200","4.74286","0.01775"
"9526","57.12200","4.76032","0.01797"
"9561","57.33200","4.77790","0.01802"
"9596","57.54200","4.79536","0.01769"
"9631","57.75200","4.81288","0.01748"
"9666","57.96200","4.83040","0.01789"
"9701","58.17200","4.84785","0.01807"
"9736","58.38200","4.86537","0.01796"
"9771","58.59200","4.88283","0.01834"
"9806","58.80200","4.90035","0.01732"
"9841","59.01200","4.91793","0.01818"
"9876","59.22200","4.93533","0.01784"
"9911","59.43200","4.95290","0.01845"
"9946","59.64200","4.97042","0.01805"
"9981","59.85200","4.98782","0.01859"
"10016","60.06200","5.00540","0.01793"
"10051","60.27200","5.02286","0.01802"
"10086","60.48200","5.04044","0.01796"
"10121","60.69200","5.05784","0.01833"
"10156","60.90200","5.07535","0.01780"
"10191","61.11200","5.09287","0.01792"
"10226","61.32200","5.11033","0.01826"
"10261","61.53200","5.12791","0.01827"
"10296","61.74200","5.14537","0.01776"
"10331","61.95200","5.16283","0.01838"
"10366","62.16200","5.18034","0.01848"
"10401","62.37200","5.19786","0.01819"
"10436","62.58200","5.21538","0.01812"
"10471","62.79200","5.23290","0.01780"
"10506","63.00200","5.25030","0.01871"
"10541","63.21200","5.26788","0.01779"
"10576","63.42200","5.28534","0.01811"
"10611","63.63200","5.30285","0.01798"
"10646","63.84200","5.32037","0.01820"
"10681","64.05200","5.33789","0.01826"
"10716","64.26200","5.35541","0.01752"
"10751","64.47200","5.37287","0.01840"
"10786","64.68200","5.39033","0.01826"
"10821","64.89200","5.40790","0.01892"
"10856","65.10200","5.42536","0.01791"
"10891","65.31200","5.44288","0.01800"
"10926","65.52200","5.46040","0.01856"
"10961","65.73200","5.47780","0.01833"
"10996","65.94200","5.49544","0.01861"
"11031","66.15200","5.51283","0.01810"
"11066","66.36200","5.53041","0.01811"
"11101","66.57200","5.54793","0.01806"
"11136","66.78200","5.56527","0.01725"
"11171","66.99200","5.58291","0.01787"
"11206","67.20200","5.60037","0.01736"
"11241","67.41200","5.61788","0.01773"
"11276","67.62200","5.63540","0.01765"
"11311","67.83200","5.65280","0.01728"
"11346","68.04200","5.67038","0.01812"
"11381","68.25200","5.68790","0.01762"
"11416","68.46200","5.70530","0.01806"
"11451","68.67200","5.72293","0.01838"
"11486","68.88200","5.74033","0.01737"
"11521","69.09200","5.75791","0.01790"
"11556","69.30200","5.77537","0.01800"
"11591","69.51200","5.79289","0.01836"
"11626","69.72200","5.81035","0.01798"
"11661","69.93200","5.82787","0.01660"
"11696","70.14200","5.84544","0.01685"
"11731","70.35200","5.86284","0.01679"
"11766","70.56200","5.88030","0.01702"
"11801","70.77200","5.89788","0.01716"
"11836","70.98200","5.91540","0.01726"
"11871","71.19200","5.93286","0.01727"
"11906","71.40200","5.95043","0.01757"
"11941","71.61200","5.96777","0.01793"
"11976","71.82200","5.98547","0.01720"
"12011","72.03200","6.00287","0.01693"
"12046","72.24200","6.02039","0.01710"
"12081","72.45200","6.03785","0.01700"
"12116","72.66200","6.05536","0.01725"
"12151","72.87200","6.07288","0.01816"
"12186","73.08200","6.09034","0.01709"
"12221","73.29200","6.10780","0.01607"
"12256","73.50200","6.12538","0.01588"
"12291","73.71200","6.14284","0.01652"
"12326","73.92200","6.16041","0.01619"
"12361","74.13200","6.17781","0.01611"
"12396","74.34200","6.19533","0.01620"
"12431","74.55200","6.21285","0.01600"
"12466","74.76200","6.23031","0.01600"
"12501","74.97200","6.24795","0.01587"
"12536","75.18200","6.26541","0.01535"
"12571","75.39200","6.28286","0.01638"
"12606","75.60200","6.30038","0.01599"
"12641","75.81200","6.31784","0.01564"
"12676","76.02200","6.33536","0.01525"
"12711","76.23200","6.35288","0.01571"
"12746","76.44200","6.37034","0.01555"
"12781","76.65200","6.38791","0.01555"
"12816","76.86200","6.40537","0.01505"
"12851","77.07200","6.42283","0.01535"
"12886","77.28200","6.44041","0.01529"
"12921","77.49200","6.45781","0.01575"
"12956","77.70200","6.47539","0.01546"
"12991","77.91200","6.49290","0.01610"
"13026","78.12200","6.51036","0.01586"
"13061","78.33200","6.52794","0.01589"
"13096","78.54200","6.54534","0.01617"
"13131","78.75200","6.56286","0.01585"
"13166","78.96200","6.58038","0.01495"
"13201","79.17200","6.59783","0.01596"
"13236","79.38200","6.61535","0.01581"
"13271","79.59200","6.63287","0.01564"
"13306","79.80200","6.65039","0.01557"
"13341","80.01200","6.66791","0.01530"
"13376","80.22200","6.68525","0.01591"
"13411","80.43200","6.70295","0.01555"
"13446","80.64200","6.72034","0.01535"
"13481","80.85200","6.73786","0.01584"
"13516","81.06200","6.75538","0.01586"
"13551","81.27200","6.77284","0.01536"
"13586","81.48200","6.79042","0.01530"
"13621","81.69200","6.80788","0.01571"
"13656","81.90200","6.82533","0.01619"
"13691","82.11200","6.84285","0.01631"
"13726","82.32200","6.86037","0.01559"
"13761","82.53200","6.87789","0.01590"
"13796","82.74200","6.89541","0.01570"
"13831","82.95200","6.91281","0.01649"
"13866","83.16200","6.93038","0.01542"
"13901","83.37200","6.94784","0.01605"
"13936","83.58200","6.96536","0.01620"
"13971","83.79200","6.98288","0.01616"
"14006","84.00200","7.00034","0.01605"
"14041","84.21200","7.01786","0.01656"
"14076","84.42200","7.03532","0.01569"
"14111","84.63200","7.05283","0.01631"
"14146","84.84200","7.07041","0.01650"
"14181","85.05200","7.08781","0.01598"
"14216","85.26200","7.10539","0.01573"
"14251","85.47200","7.12285","0.01560"
"14286","85.68200","7.14037","0.01636"
"14321","85.89200","7.15788","0.01609"
"14356","86.10200","7.17534","0.01575"
"14391","86.31200","7.19292","0.01618"
"14426","86.52200","7.21038","0.01606"
"14461","86.73200","7.22790","0.01702"
"14496","86.94200","7.24536","0.01661"
"14531","87.15200","7.26281","0.01614"
"14566","87.36200","7.28039","0.01649"
"14601","87.57200","7.29791","0.01634"
"14636","87.78200","7.31537","0.01686"
"14671","87.99200","7.33289","0.01694"
"14706","88.20200","7.35035","0.01610"
"14741","88.41200","7.36786","0.01625"
"14776","88.62200","7.38544","0.01638"
"14811","88.83200","7.40278","0.01653"
"14846","89.04200","7.42042","0.01685"
"14881","89.25200","7.43788","0.01639"
"14916","89.46200","7.45540","0.01704"
"14951","89.67200","7.47291","0.01729"
"14986","89.88200","7.49031","0.01652"
"15021","90.09200","7.50789","0.01739"
"15056","90.30200","7.52535","0.01758"
"15091","90.51200","7.54281","0.01711"
"15126","90.72200","7.56039","0.01643"
"15161","90.93200","7.57785","0.01714"
"15196","91.14200","7.59536","0.01707"
"15231","91.35200","7.61288","0.01672"
"15266","91.56200","7.63034","0.01688"
"15301","91.77200","7.64786","0.01711"
"15336","91.98200","7.66532","0.01734"
"15371","92.19200","7.68290","0.01714"
"15406","92.40200","7.70035","0.01729"
"15441","92.61200","7.71787","0.01704"
"15476","92.82200","7.73539","0.01738"
"15511","93.03200","7.75285","0.01711"
"15546","93.24200","7.77037","0.01730"
"15581","93.45200","7.78789","0.01728"
"15616","93.66200","7.80534","0.01812"
"15651","93.87200","7.82292","0.01730"
"15686","94.08200","7.84038","0.01781"
"15721","94.29200","7.85784","0.01799"
"15756","94.50200","7.87542","0.01773"
"15791","94.71200","7.89288","0.01825"
"15826","94.92200","7.91039","0.01766"
"15861","95.13200","7.92785","0.01809"
"15896","95.34200","7.94531","0.01842"
"15931","95.55200","7.96289","0.01801"
"15966","95.76200","7.98035","0.01862"
"16001","95.97200","7.99787","0.01846"
"16036","96.18200","8.01538","0.01832"
"16071","96.39200","8.03284","0.01812"
"16106","96.60200","8.05036","0.01787"
"16141","96.81200","8.06782","0.01814"
"16176","97.02200","8.08540","0.01872"
"16211","97.23200","8.10292","0.01898"
"16246","97.44200","8.12032","0.01882"
"16281","97.65200","8.13789","0.01900"
"16316","97.86200","8.15535","0.01964"
"16351","98.07200","8.17287","0.01894"
"16386","98.28200","8.19033","0.01925"
"16421","98.49200","8.20785","0.01899"
"16456","98.70200","8.22537","0.01943"
"16491","98.91200","8.24288","0.01893"
"16526","99.12200","8.26040","0.01921"
"16561","99.33200","8.27786","0.01909"
"16596","99.54200","8.29532","0.01863"
"16631","99.75200","8.31290","0.01925"
"16666","99.96200","8.33036","0.01964"
"16701","100.17200","8.34781","0.01900"
"16736","100.38200","8.36539","0.01966"
"16771","100.59200","8.38279","0.01909"
"16806","100.80200","8.40043","0.01908"
"16841","101.01200","8.41789","0.01854"
"16876","101.22200","8.43535","0.01918"
"16911","101.43200","8.45292","0.01883"
"16946","101.64200","8.47038","0.01842"
"16981","101.85200","8.48790","0.01823"
"17016","102.06200","8.50542","0.01920"
"17051","102.27200","8.52276","0.01891"
"17086","102.48200","8.54040","0.01874"
"17121","102.69200","8.55791","0.01910"
"17156","102.90200","8.57537","0.01920"
"17191","103.11200","8.59289","0.01978"
"17226","103.32200","8.61035","0.01951"
"17261","103.53200","8.62793","0.01985"
"17296","103.74200","8.64533","0.01895"
"17331","103.95200","8.66285","0.01912"
"17366","104.16200","8.68036","0.01957"
"17401","104.37200","8.69782","0.01846"
"17436","104.58200","8.71540","0.01944"
"17471","104.79200","8.73292","0.01899"
"17506","105.00200","8.75032","0.01886"
"17541","105.21200","8.76784","0.01857"
"17576","105.42200","8.78535","0.01795"
"17611","105.63200","8.80281","0.01858"
"17646","105.84200","8.82039","0.01826"
"17681","106.05200","8.83779","0.01933"
"17716","106.26200","8.85537","0.01926"
"17751","106.47200","8.87283","0.01915"
"17786","106.68200","8.89034","0.01910"
"17821","106.89200","8.90792","0.01963"
"17856","107.10200","8.92532","0.01933"
"17891","107.31200","8.94290","0.02031"
"17926","107.52200","8.96036","0.02010"
"17961","107.73200","8.97782","0.01957"
"17996","107.94200","8.99534","0.01999"
"18031","108.15200","9.01285","0.02003"
"18066","108.36200","9.03037","0.02061"
"18101","108.57200","9.04783","0.02020"
"18136","108.78200","9.06535","0.02003"
"18171","108.99200","9.08293","0.01993"
"18206","109.20200","9.10033","0.02056"
"18241","109.41200","9.11790","0.02024"
"18276","109.62200","9.13536","0.02075"
"18311","109.83200","9.15288","0.01932"
"18346","110.04200","9.17040","0.02058"
"18381","110.25200","9.18786","0.01985"
"18416","110.46200","9.20538","0.01970"
"18451","110.67200","9.22289","0.02063"
"18486","110.88200","9.24029","0.01958"
"18521","111.09200","9.25787","0.02042"
"18556","111.30200","9.27539","0.02061"
"18591","111.51200","9.29285","0.02101"
"18626","111.72200","9.31043","0.02113"
"18661","111.93200","9.32783","0.02107"
"18696","112.14200","9.34540","0.02147"
"18731","112.35200","9.36286","0.02092"
"18766","112.56200","9.38038","0.02107"
"18801","112.77200","9.39784","0.02161"
"18836","112.98200","9.41536","0.02181"
"18871","113.19200","9.43288","0.02146"
"18906","113.40200","9.45039","0.02070"
"18941","113.61200","9.46785","0.02120"
"18976","113.82200","9.48537","0.02081"
"19011","114.03200","9.50289","0.02097"
"19046","114.24200","9.52041","0.02161"
"19081","114.45200","9.53792","0.02159"
"19116","114.66200","9.55526","0.02177"
"19151","114.87200","9.57290","0.02132"
"19186","115.08200","9.59036","0.02200"
"19221","115.29200","9.60788","0.02187"
"19256","115.50200","9.62534","0.02168"
"19291","115.71200","9.64286","0.02237"
"19326","115.92200","9.66043","0.02305"
"19361","116.13200","9.67789","0.02245"
"19396","116.34200","9.69535","0.02249"
"19431","116.55200","9.71287","0.02204"
"19466","116.76200","9.73033","0.02278"
"19501","116.97200","9.74791","0.02355"
"19536","117.18200","9.76537","0.02307"
"19571","117.39200","9.78282","0.02346"
"19606","117.60200","9.80040","0.02354"
"19641","117.81200","9.81780","0.02376"
"19676","118.02200","9.83538","0.02413"
"19711","118.23200","9.85296","0.02394"
"19746","118.44200","9.87035","0.02412"
"19781","118.65200","9.88787","0.02394"
"19816","118.86200","9.90533","0.02143"
"19851","119.07200","9.92285","0.02041"
"19886","119.28200","9.94043","0.02095"
"19921","119.49200","9.95783","0.02076"
"19956","119.70200","9.97541","0.02117"
"19991","119.91200","9.99286","0.02096"
"20026","120.12200","10.01032","0.02090"
"20061","120.33200","10.02790","0.02220"
"20096","120.54200","10.04536","0.02128"
"20131","120.75200","10.06288","0.02136"
"20166","120.96200","10.08034","0.02207"
"20201","121.17200","10.09785","0.02281"
"20236","121.38200","10.11537","0.02354"
"20271","121.59200","10.13283","0.02332"
"20306","121.80200","10.15035","0.02233"
"20341","122.01200","10.16787","0.02388"
"20376","122.22200","10.18533","0.02379"
"20411","122.43200","10.20284","0.02369"
"20446","122.64200","10.22030","0.02371"
"20481","122.85200","10.23788","0.02448"
"20516","123.06200","10.25540","0.02463"
"20551","123.27200","10.27280","0.02501"
"20586","123.48200","10.29044","0.02462"
"20621","123.69200","10.30789","0.02531"
"20656","123.90200","10.32535","0.02408"
"20691","124.11200","10.34287","0.02284"
"20726","124.32200","10.36039","0.02350"
"20761","124.53200","10.37791","0.02322"
"20796","124.74200","10.39537","0.02302"
"20831","124.95200","10.41283","0.02403"
"20866","125.16200","10.43034","0.02376"
"20901","125.37200","10.44786","0.02409"
"20936","125.58200","10.46538","0.02469"
"20971","125.79200","10.48284","0.02500"
"21006","126.00200","10.50036","0.02577"
"21041","126.21200","10.51787","0.02610"
"21076","126.42200","10.53533","0.02689"
"21111","126.63200","10.55291","0.02726"
"21146","126.84200","10.57037","0.02772"
"21181","127.05200","10.58783","0.02679"
"21216","127.26200","10.60541","0.02772"
"21251","127.47200","10.62287","0.02742"
"21286","127.68200","10.64038","0.02802"
"21321","127.89200","10.65790","0.02816"
"21356","128.10200","10.67536","0.02876"
"21391","128.31200","10.69288","0.02968"
"21426","128.52200","10.71040","0.03007"
"21461","128.73200","10.72786","0.03023"
"21496","128.94200","10.74543","0.03098"
"21531","129.15200","10.76283","0.03168"
"21566","129.36200","10.78041","0.03233"
"21601","129.57200","10.79787","0.03223"
"21636","129.78200","10.81539","0.03336"
"21671","129.99200","10.83291","0.03375"
"21706","130.20200","10.85037","0.03381"
"21741","130.41200","10.86788","0.03439"
"21776","130.62200","10.88540","0.03517"
"21811","130.83200","10.90286","0.03532"
"21846","131.04200","10.92038","0.03648"
"21881","131.25200","10.93790","0.03609"
"21916","131.46200","10.95536","0.03664"
"21951","131.67200","10.97287","0.03733"
"21986","131.88200","10.99027","0.03752"
"22021","132.09200","11.00791","0.03832"
"22056","132.30200","11.02537","0.03861"
"22091","132.51200","11.04289","0.03909"
"22126","132.72200","11.06035","0.03926"
"22161","132.93200","11.07786","0.03963"
"22196","133.14200","11.09532","0.04045"
"22231","133.35200","11.11284","0.04079"
"22266","133.56200","11.13030","0.04207"
"22301","133.77200","11.14788","0.04215"
"22336","133.98200","11.16534","0.04251"
"22371","134.19200","11.18292","0.04316"
"22406","134.40200","11.20037","0.04290"
"22441","134.61200","11.21783","0.04343"
"22476","134.82200","11.23535","0.04368"
"22511","135.03200","11.25287","0.04385"
"22546","135.24200","11.27039","0.04488"
"22581","135.45200","11.28796","0.04534"
"22616","135.66200","11.30536","0.04525"
"22651","135.87200","11.32288","0.04583"
"22686","136.08200","11.34040","0.04616"
"22721","136.29200","11.35786","0.04646"
"22756","136.50200","11.37538","0.04683"
"22791","136.71200","11.39278","0.04735"
"22826","136.92200","11.41041","0.04774"
"22861","137.13200","11.42793","0.04815"
"22896","137.34200","11.44539","0.04835"
"22931","137.55200","11.46291","0.04864"
"22966","137.76200","11.48031","0.04930"
"23001","137.97200","11.49795","0.04956"
"23036","138.18200","11.51534","0.04982"
"23071","138.39200","11.53286","0.04994"
"23106","138.60200","11.55038","0.04974"
"23141","138.81200","11.56784","0.05013"
"23176","139.02200","11.58542","0.05012"
"23211","139.23200","11.60288","0.05099"
"23246","139.44200","11.62034","0.05122"
"23281","139.65200","11.63791","0.05174"
"23316","139.86200","11.65537","0.05238"
"23351","140.07200","11.67289","0.05284"
"23386","140.28200","11.69041","0.05393"
"23421","140.49200","11.70781","0.05400"
"23456","140.70200","11.72538","0.05446"
"23491","140.91200","11.74284","0.05510"
"23526","141.12200","11.76036","0.05563"
"23561","141.33200","11.77788","0.05571"
"23596","141.54200","11.79540","0.05646"
"23631","141.75200","11.81292","0.05739"
"23666","141.96200","11.83044","0.05812"
"23701","142.17200","11.84789","0.05948"
"23736","142.38200","11.86535","0.05951"
"23771","142.59200","11.88281","0.06058"
"23806","142.80200","11.90039","0.06180"
"23841","143.01200","11.91785","0.06207"
"23876","143.22200","11.93531","0.06267"
"23911","143.43200","11.95288","0.06405"
"23946","143.64200","11.97028","0.06461"
"23981","143.85200","11.98792","0.06577"
"24016","144.06200","12.00538","0.06708"
"24051","144.27200","12.02284","0.06816"
"24086","144.48200","12.04036","0.06903"
"24121","144.69200","12.05781","0.07013"
"24156","144.90200","12.07539","0.07153"
"24191","145.11200","12.09291","0.07147"
"24226","145.32200","12.11031","0.07261"
"24261","145.53200","12.12789","0.07376"
"24296","145.74200","12.14541","0.07453"
"24331","145.95200","12.16280","0.07582"
"24366","146.16200","12.18038","0.07690"
"24401","146.37200","12.19784","0.07772"
"24436","146.58200","12.21536","0.07918"
"24471","146.79200","12.23288","0.07978"
"24506","147.00200","12.25034","0.08054"
"24541","147.21200","12.26786","0.08217"
"24576","147.42200","12.28537","0.08305"
"24611","147.63200","12.30289","0.08400"
"24646","147.84200","12.32041","0.08506"
"24681","148.05200","12.33781","0.07657"
"24716","148.26200","12.35539","0.07828"
"24751","148.47200","12.37291","0.08101"
"24786","148.68200","12.39036","0.08220"
"24821","148.89200","12.40788","0.08334"
"24856","149.10200","12.42528","0.08527"
"24891","149.31200","12.44292","0.08600"
"24926","149.52200","12.46032","0.08789"
"24961","149.73200","12.47790","0.08893"
"24996","149.94200","12.49535","0.09072"
"25031","150.15200","12.51287","0.09115"
"25066","150.36200","12.53045","0.09261"
"25101","150.57200","12.54785","0.09186"
"25136","150.78200","12.56537","0.09373"
"25171","150.99200","12.58289","0.09395"
"25206","151.20200","12.60035","0.09547"
"25241","151.41200","12.61786","0.09518"
"25276","151.62200","12.63538","0.09634"
"25311","151.83200","12.65284","0.09703"
"25346","152.04200","12.67036","0.09757"
"25381","152.25200","12.68782","0.09839"
"25416","152.46200","12.70546","0.09886"
"25451","152.67200","12.72285","0.09929"
"25486","152.88200","12.74037","0.09993"
"25521","153.09200","12.75783","0.10057"
"25556","153.30200","12.77535","0.10104"
"25591","153.51200","12.79287","0.10205"
"25626","153.72200","12.81039","0.10250"
"25661","153.93200","12.82778","0.10360"
"25696","154.14200","12.84542","0.10438"
"25731","154.35200","12.86288","0.10595"
"25766","154.56200","12.88034","0.10665"
"25801","154.77200","12.89792","0.10825"
"25836","154.98200","12.91532","0.10891"
"25871","155.19200","12.93289","0.11069"
"25906","155.40200","12.95035","0.11073"
"25941","155.61200","12.96787","0.11349"
"25976","155.82200","12.98545","0.11238"
"26011","156.03200","13.00285","0.11462"
"26046","156.24200","13.02043","0.11510"
"26081","156.45200","13.03788","0.11651"
"26116","156.66200","13.05534","0.11797"
"26151","156.87200","13.07286","0.11860"
"26186","157.08200","13.09038","0.11925"
"26221","157.29200","13.10784","0.12120"
"26256","157.50200","13.12542","0.12223"
"26291","157.71200","13.14276","0.12372"
"26326","157.92200","13.16045","0.12506"
"26361","158.13200","13.17785","0.12566"
"26396","158.34200","13.19537","0.12633"
"26431","158.55200","13.21283","0.12777"
"26466","158.76200","13.23035","0.12830"
"26501","158.97200","13.24787","0.12570"
"26536","159.18200","13.26538","0.12439"
"26571","159.39200","13.28284","0.12689"
"26606","159.60200","13.30036","0.12692"
"26641","159.81200","13.31782","0.12883"
"26676","160.02200","13.33540","0.12985"
"26711","160.23200","13.35286","0.13071"
"26746","160.44200","13.37031","0.13207"
"26781","160.65200","13.38789","0.13314"
"26816","160.86200","13.40529","0.13314"
"26851","161.07200","13.42293","0.13415"
"26886","161.28200","13.44039","0.13506"
"26921","161.49200","13.45785","0.13522"
"26956","161.70200","13.47537","0.13652"
"26991","161.91200","13.49282","0.13720"
"27026","162.12200","13.51034","0.13755"
"27061","162.33200","13.52792","0.13827"
"27096","162.54200","13.54532","0.13830"
"27131","162.75200","13.56290","0.13928"
"27166","162.96200","13.58035","0.13967"
"27201","163.17200","13.59787","0.14015"
"27236","163.38200","13.61539","0.14087"
"27271","163.59200","13.63285","0.14092"
"27306","163.80200","13.65037","0.14178"
"27341","164.01200","13.66789","0.14225"
"27376","164.22200","13.68541","0.14295"
"27411","164.43200","13.70286","0.14313"
"27446","164.64200","13.72038","0.14402"
"27481","164.85200","13.73790","0.14437"
"27516","165.06200","13.75542","0.14490"
"27551","165.27200","13.77282","0.14533"
"27586","165.48200","13.79040","0.14618"
"27621","165.69200","13.80785","0.14679"
"27656","165.90200","13.82537","0.14747"
"27691","166.11200","13.84289","0.14802"
"27726","166.32200","13.86023","0.14861"
"27761","166.53200","13.87793","0.14925"
"27796","166.74200","13.89533","0.15007"
"27831","166.95200","13.91285","0.15111"
"27866","167.16200","13.93042","0.15196"
"27901","167.37200","13.94782","0.15292"
"27936","167.58200","13.96546","0.15404"
"27971","167.79200","13.98292","0.15489"
"28006","168.00200","14.00038","0.15653"
"28041","168.21200","14.01784","0.15803"
"28076","168.42200","14.03535","0.15949"
"28111","168.63200","14.05287","0.16126"
"28146","168.84200","14.07039","0.16280"
"28181","169.05200","14.08785","0.16384"
"28216","169.26200","14.10543","0.16659"
"28251","169.47200","14.12283","0.16843"
"28286","169.68200","14.14040","0.16836"
"28321","169.89200","14.15786","0.17004"
"28356","170.10200","14.17532","0.17225"
"28391","170.31200","14.19290","0.17442"
"28426","170.52200","14.21036","0.17728"
"28461","170.73200","14.22788","0.17883"
"28496","170.94200","14.24539","0.18180"
"28531","171.15200","14.26285","0.18462"
"28566","171.36200","14.28037","0.18693"
"28601","171.57200","14.29783","0.18974"
"28636","171.78200","14.31535","0.14229"
"28671","171.99200","14.33293","0.13827"
"28706","172.20200","14.35033","0.14040"
"28741","172.41200","14.36790","0.13934"
"28776","172.62200","14.38536","0.14327"
"28811","172.83200","14.40288","0.14122"
"28846","173.04200","14.42040","0.14466"
"28881","173.25200","14.43786","0.14370"
"28916","173.46200","14.45538","0.14602"
"28951","173.67200","14.47289","0.14512"
"28986","173.88200","14.49035","0.14833"
"29021","174.09200","14.50787","0.14664"
"29056","174.30200","14.52539","0.14959"
"29091","174.51200","14.54285","0.14851"
"29126","174.72200","14.56043","0.14501"
"29161","174.93200","14.57782","0.14460"
"29196","175.14200","14.59534","0.14658"
"29231","175.35200","14.61286","0.14668"
"29266","175.56200","14.63038","0.14850"
"29301","175.77200","14.64784","0.14919"
"29336","175.98200","14.66536","0.15104"
"29371","176.19200","14.68287","0.15252"
"29406","176.40200","14.70033","0.15361"
"29441","176.61200","14.71785","0.15614"
"29476","176.82200","14.73537","0.15561"
"29511","177.03200","14.75283","0.16013"
"29546","177.24200","14.77035","0.15784"
"29581","177.45200","14.78793","0.16342"
"29616","177.66200","14.80532","0.16201"
"29651","177.87200","14.82290","0.16596"
"29686","178.08200","14.84036","0.16472"
"29721","178.29200","14.85788","0.16805"
"29756","178.50200","14.87540","0.16916"
"29791","178.71200","14.89280","0.17026"
"29826","178.92200","14.91043","0.17290"
"29861","179.13200","14.92783","0.17283"
"29896","179.34200","14.94541","0.17780"
"29931","179.55200","14.96293","0.17573"
"29966","179.76200","14.98033","0.17889"
"30001","179.97200","14.99791","0.17778"
"30036","180.18200","15.01536","0.18204"
"30071","180.39200","15.03288","0.18120"
"30106","180.60200","15.05040","0.18346"
"30141","180.81200","15.06786","0.18594"
"30176","181.02200","15.08544","0.18634"
"30211","181.23200","15.10284","0.18966"
"30246","181.44200","15.12036","0.18816"
"30281","181.65200","15.13787","0.19085"
"30316","181.86200","15.15539","0.18460"
"30351","182.07200","15.17285","0.18765"
"30386","182.28200","15.19037","0.18748"
"30421","182.49200","15.20783","0.18978"
"30456","182.70200","15.22541","0.19186"
"30491","182.91200","15.24286","0.19404"
"30526","183.12200","15.26038","0.19531"
"30561","183.33200","15.27790","0.19639"
"30596","183.54200","15.29530","0.19837"
"30631","183.75200","15.31294","0.19811"
"30666","183.96200","15.33039","0.20043"
"30701","184.17200","15.34785","0.20053"
"30736","184.38200","15.36543","0.20133"
"30771","184.59200","15.38283","0.20207"
"30806","184.80200","15.40035","0.20250"
"30841","185.01200","15.41787","0.20317"
"30876","185.22200","15.43533","0.20291"
"30911","185.43200","15.45290","0.20338"
"30946","185.64200","15.47030","0.20346"
"30981","185.85200","15.48788","0.20391"
"31016","186.06200","15.50540","0.20449"
"31051","186.27200","15.52280","0.20524"
"31086","186.48200","15.54038","0.20606"
"31121","186.69200","15.55784","0.20389"
"31156","186.90200","15.57541","0.20397"
"31191","187.11200","15.59287","0.20398"
"31226","187.32200","15.61039","0.20462"
"31261","187.53200","15.62785","0.20495"
"31296","187.74200","15.64537","0.20547"
"31331","187.95200","15.66288","0.20558"
"31366","188.16200","15.68040","0.20634"
"31401","188.37200","15.69780","0.20698"
"31436","188.58200","15.71538","0.20698"
"31471","188.79200","15.73290","0.20782"
"31506","189.00200","15.75036","0.20824"
"31541","189.21200","15.76793","0.20815"
"31576","189.42200","15.78533","0.20861"
"31611","189.63200","15.80291","0.20906"
"31646","189.84200","15.82031","0.20987"
"31681","190.05200","15.83789","0.21024"
"31716","190.26200","15.85541","0.21041"
"31751","190.47200","15.87287","0.21234"
"31786","190.68200","15.89038","0.21239"
"31821","190.89200","15.90790","0.21377"
"31856","191.10200","15.92536","0.21433"
"31891","191.31200","15.94288","0.21489"
"31926","191.52200","15.96040","0.21507"
"31961","191.73200","15.97786","0.21696"
"31996","191.94200","15.99537","0.21818"
"32031","192.15200","16.01283","0.21924"
"32066","192.36200","16.03035","0.21831"
"32101","192.57200","16.04781","0.21956"
"32136","192.78200","16.06539","0.21987"
"32171","192.99200","16.08285","0.22099"
"32206","193.20200","16.10036","0.22100"
"32241","193.41200","16.11788","0.22136"
"32276","193.62200","16.13540","0.22191"
"32311","193.83200","16.15286","0.22200"
"32346","194.04200","16.17038","0.22352"
"32381","194.25200","16.18784","0.22422"
"32416","194.46200","16.20535","0.22460"
"32451","194.67200","16.22281","0.22562"
"32486","194.88200","16.24033","0.22516"
"32521","195.09200","16.25791","0.22706"
"32556","195.30200","16.27531","0.22697"
"32591","195.51200","16.29289","0.22734"
"32626","195.72200","16.31041","0.22676"
"32661","195.93200","16.32780","0.22721"
"32696","196.14200","16.34538","0.22854"
"32731","196.35200","16.36284","0.22916"
"32766","196.56200","16.38036","0.22973"
"32801","196.77200","16.39788","0.23026"
"32836","196.98200","16.41528","0.23131"
"32871","197.19200","16.43291","0.23211"
"32906","197.40200","16.45037","0.23191"
"32941","197.61200","16.46783","0.23267"
"32976","197.82200","16.48541","0.23296"
"33011","198.03200","16.50281","0.23439"
"33046","198.24200","16.52045","0.23633"
"33081","198.45200","16.53785","0.23690"
"33116","198.66200","16.55536","0.23823"
"33151","198.87200","16.57282","0.23869"
"33186","199.08200","16.59034","0.23963"
"33221","199.29200","16.60792","0.24100"
"33256","199.50200","16.62538","0.24173"
"33291","199.71200","16.64284","0.24224"
"33326","199.92200","16.66035","0.24318"
"33361","200.13200","16.67787","0.24367"
"33396","200.34200","16.69533","0.24417"
"33431","200.55200","16.71291","0.24471"
"33466","200.76200","16.73025","0.24513"
"33501","200.97200","16.74794","0.24588"
"33536","201.18200","16.76534","0.24619"
"33571","201.39200","16.78292","0.24660"
"33606","201.60200","16.80032","0.24695"
"33641","201.81200","16.81784","0.24714"
"33676","202.02200","16.83536","0.24727"
"33711","202.23200","16.85288","0.24749"
"33746","202.44200","16.87033","0.24782"
"33781","202.65200","16.88785","0.24805"
"33816","202.86200","16.90537","0.24822"
"33851","203.07200","16.92289","0.24849"
"33886","203.28400","16.94053","0.24863"
"33921","203.49400","16.95798","0.24910"
"33956","203.70400","16.97550","0.24950"
"33991","203.91400","16.99296","0.24957"
"34026","204.12400","17.01060","0.24996"
"34061","204.33400","17.02806","0.25020"
"34096","204.54400","17.04552","0.25050"
"34131","204.75400","17.06304","0.25081"
"34166","204.96400","17.08050","0.25114"
"34201","205.17400","17.09801","0.25153"
"34236","205.38400","17.11553","0.25170"
"34271","205.59400","17.13299","0.25183"
"34306","205.80400","17.15057","0.25214"
"34341","206.01400","17.16803","0.25250"
"34376","206.22600","17.18566","0.25273"
"34411","206.43600","17.20324","0.25327"
"34446","206.64600","17.22070","0.25343"
"34481","206.85600","17.23822","0.25372"
"34516","207.06600","17.25574","0.25390"
"34551","207.27600","17.27314","0.25377"
"34586","207.48600","17.29078","0.25417"
"34621","207.69600","17.30817","0.25454"
"34656","207.90600","17.32569","0.25516"
"34691","208.11600","17.34321","0.25519"
"34726","208.32600","17.36067","0.25573"
"34761","208.53600","17.37819","0.25552"
"34796","208.74600","17.39565","0.25634"
"34831","208.95600","17.41322","0.25660"
"34866","209.16600","17.43074","0.25644"
"34901","209.37600","17.44814","0.25682"
"34936","209.58600","17.46572","0.25705"
"34971","209.79600","17.48318","0.25753"
"35006","210.00600","17.50069","0.25832"
"35041","210.21600","17.51821","0.25800"
"35076","210.42600","17.53567","0.25873"
"35111","210.63600","17.55325","0.25943"
"35146","210.84600","17.57071","0.26012"
"35181","211.05600","17.58823","0.26032"
"35216","211.26600","17.60568","0.26044"
"35251","211.47600","17.62321","0.26154"
"35286","211.68600","17.64066","0.26197"
"35321","211.89600","17.65812","0.26304"
"35356","212.10600","17.67564","0.26489"
"35391","212.31600","17.69322","0.26523"
"35426","212.52600","17.71068","0.26585"
"35461","212.73600","17.72825","0.26704"
"35496","212.94600","17.74571","0.26799"
"35531","213.15600","17.76317","0.26910"
"35566","213.36600","17.78069","0.27048"
"35601","213.57600","17.79821","0.27072"
"35636","213.78600","17.81567","0.27150"
"35671","213.99600","17.83324","0.27262"
"35706","214.20600","17.85064","0.27360"
"35741","214.41600","17.86822","0.27486"
"35776","214.62600","17.88568","0.27555"
"35811","214.83600","17.90320","0.27635"
"35846","215.04600","17.92072","0.27756"
"35881","215.25600","17.93811","0.27850"
"35916","215.46600","17.95575","0.28043"
"35951","215.67600","17.97321","0.28086"
"35986","215.88600","17.99073","0.28139"
"36021","216.09600","18.00825","0.28251"
"36056","216.30600","18.02565","0.28353"
"36091","216.51600","18.04323","0.28464"
"36126","216.72600","18.06074","0.28611"
"36161","216.93600","18.07820","0.28697"
"36196","217.14600","18.09572","0.28834"
"36231","217.35600","18.11318","0.28966"
"36266","217.56600","18.13070","0.28999"
"36301","217.77600","18.14828","0.29109"
"36336","217.98600","18.16562","0.29240"
"36371","218.19600","18.18325","0.29335"
"36406","218.40600","18.20071","0.29465"
"36441","218.61600","18.21817","0.29517"
"36476","218.82600","18.23569","0.29575"
"36511","219.03600","18.25315","0.29669"
"36546","219.24600","18.27073","0.29704"
"36581","219.45600","18.28824","0.29732"
"36616","219.66600","18.30570","0.29781"
"36651","219.87600","18.32316","0.29871"
"36686","220.08600","18.34068","0.29896"
"36721","220.29600","18.35826","0.29965"
"36756","220.50600","18.37572","0.30049"
"36791","220.71600","18.39317","0.30135"
"36826","220.92600","18.41069","0.30225"
"36861","221.13600","18.42815","0.30392"
"36896","221.34600","18.44573","0.30469"
"36931","221.55600","18.46319","0.30559"
"36966","221.76600","18.48071","0.30609"
"37001","221.97600","18.49816","0.30864"
"37036","222.18600","18.51568","0.30988"
"37071","222.39600","18.53320","0.31197"
"37106","222.60600","18.55072","0.31351"
"37141","222.81600","18.56818","0.31548"
"37176","223.02600","18.58576","0.31832"
"37211","223.23600","18.60321","0.32037"
"37246","223.44600","18.62073","0.32176"
"37281","223.65600","18.63825","0.32351"
"37316","223.86600","18.65571","0.32598"
"37351","224.07600","18.67323","0.32911"
"37386","224.28600","18.69069","0.32985"
"37421","224.49600","18.70815","0.33226"
"37456","224.70600","18.72572","0.33451"
"37491","224.91600","18.74318","0.33602"
"37526","225.12600","18.76070","0.33699"
"37561","225.33600","18.77828","0.33779"
"37596","225.54600","18.79568","0.33868"
"37631","225.75600","18.81325","0.34012"
"37666","225.96600","18.83065","0.34164"
"37701","226.17600","18.84823","0.34237"
"37736","226.38600","18.86569","0.34278"
"37771","226.59600","18.88315","0.34446"
"37806","226.80600","18.90073","0.34554"
"37841","227.01600","18.91819","0.34641"
"37876","227.22600","18.93571","0.34776"
"37911","227.43600","18.95316","0.34885"
"37946","227.64600","18.97068","0.34977"
"37981","227.85600","18.98820","0.35060"
"38016","228.06600","19.00572","0.35173"
"38051","228.27600","19.02318","0.35247"
"38086","228.48600","19.04075","0.35313"
"38121","228.69600","19.05815","0.35353"
"38156","228.90600","19.07573","0.35387"
"38191","229.11600","19.09319","0.35453"
"38226","229.32600","19.11065","0.35488"
"38261","229.53600","19.12823","0.35530"
"38296","229.74600","19.14569","0.35592"
"38331","229.95600","19.16326","0.35596"
"38366","230.16600","19.18072","0.35665"
"38401","230.37600","19.19818","0.35704"
"38436","230.58600","19.21576","0.35753"
"38471","230.79600","19.23316","0.35761"
"38506","231.00600","19.25074","0.35794"
"38541","231.21600","19.26825","0.35791"
"38576","231.42600","19.28559","0.35824"
"38611","231.63600","19.30323","0.35843"
"38646","231.84600","19.32069","0.35869"
"38681","232.05600","19.33821","0.35881"
"38716","232.26600","19.35573","0.35908"
"38751","232.47600","19.37318","0.35936"
"38786","232.68600","19.39076","0.35932"
"38821","232.89600","19.40816","0.35974"
"38856","233.10600","19.42568","0.35984"
"38891","233.31600","19.44320","0.36034"
"38926","233.52600","19.46066","0.36045"
"38961","233.73600","19.47823","0.36084"
"38996","233.94600","19.49575","0.36096"
"39031","234.15600","19.51315","0.36106"
"39066","234.36600","19.53073","0.36165"
"39101","234.57600","19.54819","0.36216"
"39136","234.78600","19.56571","0.36232"
"39171","234.99600","19.58323","0.36244"
"39206","235.20600","19.60062","0.36287"
"39241","235.41600","19.61820","0.36295"
"39276","235.62600","19.63566","0.36349"
"39311","235.83600","19.65318","0.36369"
"39346","236.04600","19.67070","0.36427"
"39381","236.25600","19.68816","0.36484"
"39416","236.46600","19.70573","0.36549"
"39451","236.67600","19.72325","0.36632"
"39486","236.88600","19.74071","0.36690"
"39521","237.09600","19.75823","0.36761"
"39556","237.30600","19.77563","0.36798"
"39591","237.51600","19.79321","0.36885"
"39626","237.72600","19.81066","0.36935"
"39661","237.93600","19.82818","0.37014"
"39696","238.14600","19.84576","0.37104"
"39731","238.35600","19.86310","0.37182"
"39766","238.56600","19.88074","0.37284"
"39801","238.77600","19.89820","0.37394"
"39836","238.98600","19.91571","0.37397"
"39871","239.19600","19.93317","0.37514"
"39906","239.40600","19.95069","0.37573"
"39941","239.61600","19.96821","0.37653"
"39976","239.82600","19.98573","0.37806"
"40011","240.03600","20.00319","0.37872"
"40046","240.24600","20.02076","0.37933"
"40081","240.45600","20.03816","0.38083"
"40116","240.66600","20.05568","0.38147"
"40151","240.87600","20.07326","0.38266"
"40186","241.08600","20.09066","0.38342"
"40221","241.29600","20.10823","0.38419"
"40256","241.50600","20.12569","0.38524"
"40291","241.71600","20.14321","0.38630"
"40326","241.92600","20.16067","0.38749"
"40361","242.13600","20.17819","0.38754"
"40396","242.34600","20.19571","0.38948"
"40431","242.55600","20.21323","0.39020"
"40466","242.76600","20.23068","0.39084"
"40501","242.97600","20.24820","0.39118"
"40536","243.18600","20.26566","0.39119"
"40571","243.39600","20.28318","0.39095"
"40606","243.60600","20.30070","-0.01846"
"40641","243.81600","20.31810","0.00672"
"40676","244.02600","20.33574","0.02817"
"40711","244.23600","20.35320","0.04321"
"40746","244.44600","20.37071","0.01349"
"40781","244.65600","20.38817","0.01791"
"40816","244.86600","20.40575","0.03610"
"40851","245.07600","20.42327","0.01205"
"40886","245.28600","20.44073","0.01854"
"40921","245.49600","20.45818","0.02551"
"40956","245.70600","20.47570","0.01547"
"40991","245.91600","20.49316","0.02260"
"41026","246.12600","20.51074","0.02270"
"41061","246.33600","20.52814","0.01643"
"41096","246.54600","20.54566","0.02519"
"41131","246.75600","20.56323","0.02092"
"41166","246.96600","20.58064","0.01943"
"41201","247.17600","20.59821","0.02434"
"41236","247.38600","20.61573","0.01955"
"41271","247.59600","20.63319","0.02296"
"41306","247.80600","20.65071","0.02367"
"41341","248.01600","20.66816","0.02063"
"41376","248.22600","20.68568","0.02464"
"41411","248.43600","20.70326","0.02139"
"41446","248.64600","20.72066","0.02302"
"41481","248.85600","20.73824","0.02376"
"41516","249.06600","20.75570","0.02201"
"41551","249.27600","20.77321","0.02475"
"41586","249.48600","20.79073","0.02353"
"41621","249.69600","20.80813","0.02430"
"41656","249.90600","20.82577","0.02536"
"41691","250.11600","20.84317","0.02375"
"41726","250.32600","20.86069","0.02575"
"41761","250.53600","20.87820","0.02494"
"41796","250.74600","20.89567","0.02522"
"41831","250.95600","20.91318","0.02628"
"41866","251.16600","20.93070","0.02537"
"41901","251.37600","20.94816","0.02696"
"41936","251.58600","20.96568","0.02621"
"41971","251.79600","20.98314","0.02592"
"42006","252.00600","21.00071","0.02750"
"42041","252.21600","21.01823","0.02690"
"42076","252.42600","21.03563","0.02734"
"42111","252.63600","21.05321","0.02727"
"42146","252.84600","21.07073","0.02795"
"42181","253.05600","21.08819","0.02834"
"42216","253.26600","21.10571","0.02780"
"42251","253.47600","21.12316","0.02863"
"42286","253.68600","21.14074","0.02860"
"42321","253.89600","21.15820","0.02877"
"42356","254.10600","21.17572","0.02985"
"42391","254.31600","21.19318","0.02914"
"42426","254.52600","21.21064","0.02991"
"42461","254.73600","21.22821","0.02959"
"42496","254.94600","21.24567","0.02986"
"42531","255.15600","21.26319","0.03100"
"42566","255.36600","21.28071","0.02991"
"42601","255.57600","21.29817","0.03111"
"42636","255.78600","21.31575","0.03048"
"42671","255.99600","21.33320","0.03128"
"42706","256.20600","21.35066","0.03164"
"42741","256.41600","21.36824","0.03178"
"42776","256.62600","21.38570","0.03156"
"42811","256.83600","21.40322","0.03194"
"42846","257.04600","21.42074","0.03141"
"42881","257.25600","21.43814","0.03215"
"42916","257.46600","21.45572","0.03265"
"42951","257.67600","21.47317","0.03276"
"42986","257.88600","21.49069","0.03311"
"43021","258.09600","21.50821","0.03345"
"43056","258.30600","21.52561","0.03381"
"43091","258.51600","21.54324","0.03331"
"43111","258.63200","21.55293","0.03305"