File: Trajectories_together/170212_3Specimen_RawData_3.csv
"","V1","V2","V3"
"1","End date","2/12/2017",""
"2","Specimen label","13BG_2",""
"3","Maximum Load","0.49497","N"
"4","Time","Extension","Load"
"5","(s)","(mm)","(N)"
"6","0.00000","0.00000","-0.00020"
"39","0.19800","0.01381","0.00032"
"72","0.39600","0.03324","0.00060"
"105","0.59400","0.04974","0.00067"
"138","0.79200","0.06625","0.00069"
"171","0.99000","0.08275","0.00099"
"204","1.18800","0.09919","0.00060"
"237","1.38600","0.11581","0.00132"
"270","1.58400","0.13219","0.00135"
"303","1.78200","0.14870","0.00123"
"336","1.98000","0.16520","0.00147"
"369","2.17800","0.18170","0.00160"
"402","2.37600","0.19814","0.00179"
"435","2.57400","0.21470","0.00202"
"468","2.77200","0.23121","0.00216"
"501","2.97000","0.24771","0.00193"
"534","3.16800","0.26427","0.00156"
"567","3.36600","0.28065","0.00254"
"600","3.56400","0.29721","0.00249"
"633","3.76200","0.31372","0.00281"
"666","3.96000","0.33016","0.00259"
"699","4.15800","0.34672","0.00286"
"732","4.35600","0.36322","0.00244"
"765","4.55400","0.37972","0.00267"
"798","4.75200","0.39623","0.00292"
"831","4.95000","0.41267","0.00269"
"864","5.14800","0.42923","0.00356"
"897","5.34600","0.44573","0.00298"
"930","5.54400","0.46211","0.00265"
"963","5.74200","0.47873","0.00273"
"996","5.94000","0.49524","0.00327"
"1029","6.13800","0.51168","0.00366"
"1062","6.33600","0.52824","0.00343"
"1095","6.53400","0.54468","0.00319"
"1128","6.73200","0.56118","0.00375"
"1161","6.93000","0.57775","0.00331"
"1194","7.12800","0.59413","0.00338"
"1227","7.32600","0.61069","0.00376"
"1260","7.52400","0.62719","0.00378"
"1293","7.72200","0.64363","0.00367"
"1326","7.92000","0.66026","0.00370"
"1359","8.11800","0.67664","0.00409"
"1392","8.31600","0.69320","0.00385"
"1425","8.51400","0.70970","0.00334"
"1458","8.71200","0.72614","0.00363"
"1491","8.91000","0.74271","0.00419"
"1524","9.10800","0.75921","0.00421"
"1557","9.30600","0.77571","0.00426"
"1590","9.50400","0.79227","0.00375"
"1623","9.70200","0.80871","0.00372"
"1656","9.90000","0.82522","0.00430"
"1689","10.09800","0.84172","0.00473"
"1722","10.29600","0.85816","0.00400"
"1755","10.49400","0.87472","0.00433"
"1788","10.69200","0.89122","0.00455"
"1821","10.89000","0.90761","0.00416"
"1854","11.08800","0.92423","0.00459"
"1887","11.28600","0.94067","0.00448"
"1920","11.48400","0.95717","0.00524"
"1953","11.68200","0.97373","0.00417"
"1986","11.88000","0.99017","0.00434"
"2019","12.07800","1.00674","0.00469"
"2052","12.27600","1.02324","0.00421"
"2085","12.47400","1.03968","0.00499"
"2118","12.67200","1.05624","0.00450"
"2151","12.87000","1.07274","0.00463"
"2184","13.06800","1.08913","0.00511"
"2217","13.26600","1.10575","0.00456"
"2250","13.46400","1.12219","0.00449"
"2283","13.66200","1.13875","0.00452"
"2316","13.86000","1.15519","0.00415"
"2349","14.05800","1.17170","0.00471"
"2382","14.25600","1.18820","0.00488"
"2415","14.45400","1.20470","0.00469"
"2448","14.65200","1.22114","0.00448"
"2481","14.85000","1.23770","0.00486"
"2514","15.04800","1.25415","0.00490"
"2547","15.24600","1.27071","0.00468"
"2580","15.44400","1.28721","0.00537"
"2613","15.64200","1.30365","0.00483"
"2646","15.84000","1.32021","0.00442"
"2679","16.03800","1.33671","0.00424"
"2712","16.23600","1.35322","0.00488"
"2745","16.43400","1.36972","0.00492"
"2778","16.63200","1.38622","0.00432"
"2811","16.83000","1.40266","0.00453"
"2844","17.02800","1.41916","0.00518"
"2877","17.22600","1.43573","0.00505"
"2910","17.42400","1.45223","0.00447"
"2943","17.62200","1.46873","0.00507"
"2976","17.82000","1.48517","0.00477"
"3009","18.01800","1.50167","0.00473"
"3042","18.21600","1.51818","0.00517"
"3075","18.41400","1.53468","0.00465"
"3108","18.61200","1.55118","0.00474"
"3141","18.81000","1.56774","0.00436"
"3174","19.00800","1.58424","0.00543"
"3207","19.20600","1.60069","0.00507"
"3240","19.40400","1.61719","0.00486"
"3273","19.60200","1.63369","0.00452"
"3306","19.80000","1.65019","0.00493"
"3339","19.99800","1.66669","0.00457"
"3372","20.19600","1.68319","0.00504"
"3405","20.39400","1.69970","0.00540"
"3438","20.59200","1.71614","0.00494"
"3471","20.79000","1.73270","0.00539"
"3504","20.98800","1.74920","0.00469"
"3537","21.18600","1.76570","0.00566"
"3570","21.38400","1.78215","0.00552"
"3603","21.58200","1.79865","0.00513"
"3636","21.78000","1.81521","0.00539"
"3669","21.97800","1.83177","0.00458"
"3702","22.17600","1.84815","0.00465"
"3735","22.37400","1.86478","0.00490"
"3768","22.57200","1.88128","0.00441"
"3801","22.77000","1.89760","0.00487"
"3834","22.96800","1.91422","0.00447"
"3867","23.16600","1.93072","0.00455"
"3900","23.36400","1.94717","0.00485"
"3933","23.56200","1.96373","0.00511"
"3966","23.76000","1.98017","0.00461"
"3999","23.95800","1.99673","0.00540"
"4032","24.15600","2.01323","0.00461"
"4065","24.35400","2.02968","0.00531"
"4098","24.55200","2.04618","0.00503"
"4131","24.75000","2.06268","0.00474"
"4164","24.94800","2.07918","0.00482"
"4197","25.14600","2.09574","0.00553"
"4230","25.34400","2.11219","0.00525"
"4263","25.54200","2.12869","0.00515"
"4296","25.74000","2.14525","0.00490"
"4329","25.93800","2.16163","0.00504"
"4362","26.13600","2.17825","0.00477"
"4395","26.33400","2.19469","0.00502"
"4428","26.53200","2.21114","0.00503"
"4461","26.73000","2.22776","0.00484"
"4494","26.92800","2.24420","0.00494"
"4527","27.12600","2.26070","0.00556"
"4560","27.32400","2.27726","0.00531"
"4593","27.52200","2.29371","0.00527"
"4626","27.72000","2.31021","0.00542"
"4659","27.91800","2.32671","0.00482"
"4692","28.11600","2.34315","0.00523"
"4725","28.31400","2.35971","0.00503"
"4758","28.51200","2.37616","0.00483"
"4791","28.71000","2.39272","0.00533"
"4824","28.90800","2.40922","0.00461"
"4857","29.10600","2.42566","0.00505"
"4890","29.30400","2.44222","0.00499"
"4923","29.50200","2.45872","0.00498"
"4956","29.70000","2.47517","0.00490"
"4989","29.89800","2.49173","0.00496"
"5022","30.09600","2.50823","0.00527"
"5055","30.29400","2.52467","0.00526"
"5088","30.49200","2.54123","0.00494"
"5121","30.69000","2.55768","0.00532"
"5154","30.88800","2.57424","0.00530"
"5187","31.08600","2.59068","0.00505"
"5220","31.28400","2.60718","0.00531"
"5253","31.48200","2.62374","0.00469"
"5286","31.68000","2.64019","0.00485"
"5319","31.87800","2.65669","0.00518"
"5352","32.07600","2.67325","0.00488"
"5385","32.27400","2.68969","0.00471"
"5418","32.47200","2.70619","0.00494"
"5451","32.67000","2.72270","0.00572"
"5484","32.86800","2.73914","0.00496"
"5517","33.06600","2.75570","0.00503"
"5550","33.26400","2.77226","0.00475"
"5583","33.46200","2.78864","0.00564"
"5616","33.66000","2.80526","0.00537"
"5649","33.85800","2.82171","0.00511"
"5682","34.05600","2.83821","0.00538"
"5715","34.25400","2.85465","0.00547"
"5748","34.45200","2.87121","0.00533"
"5781","34.65000","2.88771","0.00500"
"5814","34.84800","2.90422","0.00534"
"5847","35.04600","2.92072","0.00567"
"5880","35.24400","2.93722","0.00524"
"5913","35.44200","2.95366","0.00536"
"5946","35.64000","2.97016","0.00494"
"5979","35.83800","2.98667","0.00503"
"6012","36.03600","3.00317","0.00531"
"6045","36.23400","3.01967","0.00555"
"6078","36.43200","3.03617","0.00578"
"6111","36.63000","3.05273","0.00551"
"6144","36.82800","3.06918","0.00571"
"6177","37.02600","3.08568","0.00557"
"6210","37.22400","3.10218","0.00557"
"6243","37.42200","3.11874","0.00572"
"6276","37.62000","3.13518","0.00561"
"6309","37.81800","3.15169","0.00520"
"6342","38.01600","3.16819","0.00558"
"6375","38.21400","3.18475","0.00555"
"6408","38.41200","3.20119","0.00532"
"6441","38.61000","3.21769","0.00556"
"6474","38.80800","3.23419","0.00559"
"6507","39.00600","3.25070","0.00529"
"6540","39.20400","3.26726","0.00571"
"6573","39.40200","3.28364","0.00562"
"6606","39.60000","3.30026","0.00523"
"6639","39.79800","3.31676","0.00591"
"6672","39.99600","3.33315","0.00568"
"6705","40.19400","3.34971","0.00557"
"6738","40.39200","3.36621","0.00494"
"6771","40.59000","3.38271","0.00575"
"6804","40.78800","3.39921","0.00574"
"6837","40.98600","3.41566","0.00554"
"6870","41.18400","3.43216","0.00565"
"6903","41.38200","3.44872","0.00622"
"6936","41.58000","3.46516","0.00524"
"6969","41.77800","3.48172","0.00550"
"7002","41.97600","3.49817","0.00549"
"7035","42.17400","3.51467","0.00561"
"7068","42.37200","3.53123","0.00591"
"7101","42.57000","3.54767","0.00648"
"7134","42.76800","3.56423","0.00564"
"7167","42.96600","3.58074","0.00589"
"7200","43.16400","3.59712","0.00586"
"7233","43.36200","3.61380","0.00511"
"7266","43.56000","3.63018","0.00558"
"7299","43.75800","3.64668","0.00588"
"7332","43.95600","3.66325","0.00610"
"7365","44.15400","3.67969","0.00524"
"7398","44.35200","3.69619","0.00594"
"7431","44.55000","3.71269","0.00579"
"7464","44.74800","3.72919","0.00565"
"7497","44.94600","3.74575","0.00563"
"7530","45.14400","3.76220","0.00613"
"7563","45.34200","3.77864","0.00624"
"7596","45.54000","3.79520","0.00591"
"7629","45.73800","3.81164","0.00593"
"7662","45.93600","3.82820","0.00593"
"7695","46.13400","3.84471","0.00597"
"7728","46.33200","3.86121","0.00530"
"7761","46.53000","3.87771","0.00581"
"7794","46.72800","3.89421","0.00579"
"7827","46.92600","3.91065","0.00580"
"7860","47.12400","3.92728","0.00618"
"7893","47.32200","3.94366","0.00569"
"7926","47.52000","3.96022","0.00596"
"7959","47.71800","3.97672","0.00573"
"7992","47.91600","3.99316","0.00611"
"8025","48.11400","4.00973","0.00553"
"8058","48.31200","4.02623","0.00520"
"8091","48.51000","4.04267","0.00619"
"8124","48.70800","4.05923","0.00613"
"8157","48.90600","4.07573","0.00562"
"8190","49.10400","4.09218","0.00623"
"8223","49.30200","4.10874","0.00597"
"8256","49.50000","4.12518","0.00555"
"8289","49.69800","4.14174","0.00544"
"8322","49.89600","4.15824","0.00605"
"8355","50.09400","4.17468","0.00573"
"8388","50.29200","4.19119","0.00587"
"8421","50.49000","4.20775","0.00573"
"8454","50.68800","4.22419","0.00596"
"8487","50.88600","4.24075","0.00569"
"8520","51.08400","4.25719","0.00607"
"8553","51.28200","4.27370","0.00578"
"8586","51.48000","4.29014","0.00630"
"8619","51.67800","4.30670","0.00604"
"8652","51.87600","4.32320","0.00590"
"8685","52.07400","4.33970","0.00601"
"8718","52.27200","4.35621","0.00559"
"8751","52.47000","4.37271","0.00537"
"8784","52.66800","4.38921","0.00562"
"8817","52.86600","4.40565","0.00541"
"8850","53.06400","4.42221","0.00562"
"8883","53.26200","4.43871","0.00579"
"8916","53.46000","4.45516","0.00586"
"8949","53.65800","4.47166","0.00590"
"8982","53.85600","4.48816","0.00572"
"9015","54.05400","4.50472","0.00539"
"9048","54.25200","4.52116","0.00556"
"9081","54.45000","4.53767","0.00557"
"9114","54.64800","4.55423","0.00559"
"9147","54.84600","4.57073","0.00563"
"9180","55.04400","4.58711","0.00586"
"9213","55.24200","4.60367","0.00611"
"9246","55.44000","4.62024","0.00551"
"9279","55.63800","4.63668","0.00562"
"9312","55.83600","4.65324","0.00570"
"9345","56.03400","4.66962","0.00538"
"9378","56.23200","4.68618","0.00590"
"9411","56.43000","4.70275","0.00593"
"9444","56.62800","4.71913","0.00580"
"9477","56.82600","4.73575","0.00532"
"9510","57.02400","4.75225","0.00561"
"9543","57.22200","4.76863","0.00589"
"9576","57.42000","4.78526","0.00535"
"9609","57.61800","4.80170","0.00627"
"9642","57.81600","4.81820","0.00587"
"9675","58.01400","4.83476","0.00528"
"9708","58.21200","4.85120","0.00612"
"9741","58.41000","4.86770","0.00617"
"9774","58.60800","4.88421","0.00549"
"9807","58.80600","4.90065","0.00561"
"9840","59.00400","4.91727","0.00616"
"9873","59.20200","4.93371","0.00570"
"9906","59.40000","4.95015","0.00625"
"9939","59.59800","4.96678","0.00569"
"9972","59.79600","4.98316","0.00571"
"10005","59.99400","4.99972","0.00601"
"10038","60.19200","5.01622","0.00565"
"10071","60.39000","5.03266","0.00562"
"10104","60.58800","5.04929","0.00552"
"10137","60.78600","5.06573","0.00573"
"10170","60.98400","5.08217","0.00588"
"10203","61.18200","5.09873","0.00549"
"10236","61.38000","5.11517","0.00605"
"10269","61.57800","5.13168","0.00577"
"10302","61.77600","5.14824","0.00571"
"10335","61.97400","5.16468","0.00579"
"10368","62.17200","5.18124","0.00607"
"10401","62.37000","5.19774","0.00591"
"10434","62.56800","5.21413","0.00548"
"10467","62.76600","5.23075","0.00543"
"10500","62.96400","5.24713","0.00538"
"10533","63.16200","5.26369","0.00575"
"10566","63.36000","5.28019","0.00541"
"10599","63.55800","5.29664","0.00548"
"10632","63.75600","5.31326","0.00585"
"10665","63.95400","5.32970","0.00588"
"10698","64.15200","5.34614","0.00532"
"10731","64.35000","5.36276","0.00501"
"10764","64.54800","5.37915","0.00551"
"10797","64.74600","5.39571","0.00585"
"10830","64.94400","5.41221","0.00527"
"10863","65.14200","5.42865","0.00535"
"10896","65.34000","5.44521","0.00532"
"10929","65.53800","5.46177","0.00578"
"10962","65.73600","5.47816","0.00589"
"10995","65.93400","5.49472","0.00556"
"11028","66.13200","5.51122","0.00576"
"11061","66.33000","5.52766","0.00613"
"11094","66.52800","5.54422","0.00544"
"11127","66.72600","5.56067","0.00578"
"11160","66.92400","5.57717","0.00595"
"11193","67.12200","5.59373","0.00557"
"11226","67.32000","5.61017","0.00593"
"11259","67.51800","5.62673","0.00606"
"11292","67.71600","5.64324","0.00588"
"11325","67.91400","5.65968","0.00557"
"11358","68.11200","5.67624","0.00583"
"11391","68.31000","5.69274","0.00595"
"11424","68.50800","5.70918","0.00572"
"11457","68.70600","5.72569","0.00563"
"11490","68.90400","5.74219","0.00545"
"11523","69.10200","5.75869","0.00588"
"11556","69.30000","5.77525","0.00566"
"11589","69.49800","5.79169","0.00528"
"11622","69.69600","5.80825","0.00568"
"11655","69.89400","5.82470","0.00573"
"11688","70.09200","5.84120","0.00590"
"11721","70.29000","5.85776","0.00589"
"11754","70.48800","5.87426","0.00589"
"11787","70.68600","5.89064","0.00586"
"11820","70.88400","5.90721","0.00598"
"11853","71.08200","5.92371","0.00607"
"11886","71.28000","5.94021","0.00588"
"11919","71.47800","5.95671","0.00598"
"11952","71.67600","5.97315","0.00587"
"11985","71.87400","5.98966","0.00547"
"12018","72.07200","6.00622","0.00594"
"12051","72.27000","6.02266","0.00599"
"12084","72.46800","6.03922","0.00575"
"12117","72.66600","6.05572","0.00599"
"12150","72.86400","6.07217","0.00626"
"12183","73.06200","6.08873","0.00544"
"12216","73.26000","6.10517","0.00555"
"12249","73.45800","6.12173","0.00564"
"12282","73.65600","6.13823","0.00594"
"12315","73.85400","6.15468","0.00608"
"12348","74.05200","6.17124","0.00641"
"12381","74.25000","6.18774","0.00635"
"12414","74.44800","6.20412","0.00587"
"12447","74.64600","6.22074","0.00610"
"12480","74.84400","6.23718","0.00623"
"12513","75.04200","6.25369","0.00567"
"12546","75.24000","6.27025","0.00627"
"12579","75.43800","6.28663","0.00623"
"12612","75.63600","6.30319","0.00559"
"12645","75.83400","6.31975","0.00654"
"12678","76.03200","6.33614","0.00588"
"12711","76.23000","6.35276","0.00615"
"12744","76.42800","6.36920","0.00624"
"12777","76.62600","6.38570","0.00605"
"12810","76.82400","6.40226","0.00617"
"12843","77.02200","6.41877","0.00593"
"12876","77.22000","6.43521","0.00595"
"12909","77.41800","6.45177","0.00625"
"12942","77.61600","6.46809","0.00584"
"12975","77.81400","6.48477","0.00600"
"13008","78.01200","6.50121","0.00584"
"13041","78.21000","6.51766","0.00643"
"13074","78.40800","6.53422","0.00637"
"13107","78.60600","6.55072","0.00652"
"13140","78.80400","6.56716","0.00681"
"13173","79.00200","6.58372","0.00626"
"13206","79.20000","6.60017","0.00630"
"13239","79.39800","6.61679","0.00623"
"13272","79.59600","6.63317","0.00637"
"13305","79.79400","6.64967","0.00654"
"13338","79.99200","6.66623","0.00620"
"13371","80.19000","6.68268","0.00633"
"13404","80.38800","6.69924","0.00637"
"13437","80.58600","6.71568","0.00626"
"13470","80.78400","6.73218","0.00638"
"13503","80.98200","6.74874","0.00618"
"13536","81.18000","6.76525","0.00611"
"13569","81.37800","6.78163","0.00668"
"13602","81.57600","6.79825","0.00600"
"13635","81.77400","6.81469","0.00632"
"13668","81.97200","6.83119","0.00639"
"13701","82.17000","6.84770","0.00654"
"13734","82.36800","6.86420","0.00584"
"13767","82.56600","6.88070","0.00668"
"13800","82.76400","6.89726","0.00619"
"13833","82.96200","6.91364","0.00632"
"13866","83.16000","6.93026","0.00629"
"13899","83.35800","6.94665","0.00640"
"13932","83.55600","6.96321","0.00615"
"13965","83.75400","6.97971","0.00655"
"13998","83.95200","6.99615","0.00678"
"14031","84.15000","7.01271","0.00663"
"14064","84.34800","7.02922","0.00613"
"14097","84.54600","7.04566","0.00610"
"14130","84.74400","7.06216","0.00645"
"14163","84.94200","7.07872","0.00669"
"14196","85.14000","7.09516","0.00685"
"14229","85.33800","7.11173","0.00667"
"14262","85.53600","7.12823","0.00647"
"14295","85.73400","7.14467","0.00628"
"14328","85.93200","7.16117","0.00656"
"14361","86.13000","7.17773","0.00642"
"14394","86.32800","7.19418","0.00642"
"14427","86.52600","7.21074","0.00628"
"14460","86.72400","7.22718","0.00709"
"14493","86.92200","7.24374","0.00674"
"14526","87.12000","7.26024","0.00686"
"14559","87.31800","7.27668","0.00698"
"14592","87.51600","7.29319","0.00658"
"14625","87.71400","7.30975","0.00682"
"14658","87.91200","7.32619","0.00672"
"14691","88.11000","7.34269","0.00669"
"14724","88.30800","7.35919","0.00693"
"14757","88.50600","7.37570","0.00724"
"14790","88.70400","7.39220","0.00712"
"14823","88.90200","7.40870","0.00706"
"14856","89.10000","7.42520","0.00698"
"14889","89.29800","7.44176","0.00727"
"14922","89.49600","7.45815","0.00749"
"14955","89.69400","7.47471","0.00699"
"14988","89.89200","7.49121","0.00681"
"15021","90.09000","7.50771","0.00730"
"15054","90.28800","7.52421","0.00717"
"15087","90.48600","7.54072","0.00667"
"15120","90.68400","7.55722","0.00740"
"15153","90.88200","7.57378","0.00682"
"15186","91.08000","7.59016","0.00729"
"15219","91.27800","7.60672","0.00684"
"15252","91.47600","7.62323","0.00674"
"15285","91.67400","7.63967","0.00735"
"15318","91.87200","7.65629","0.00690"
"15351","92.07000","7.67267","0.00711"
"15384","92.26800","7.68917","0.00707"
"15417","92.46600","7.70574","0.00746"
"15450","92.66400","7.72218","0.00784"
"15483","92.86200","7.73874","0.00733"
"15516","93.06000","7.75524","0.00769"
"15549","93.25800","7.77162","0.00737"
"15582","93.45600","7.78824","0.00752"
"15615","93.65400","7.80469","0.00776"
"15648","93.85200","7.82119","0.00751"
"15681","94.05000","7.83775","0.00765"
"15714","94.24800","7.85419","0.00720"
"15747","94.44600","7.87069","0.00775"
"15780","94.64400","7.88726","0.00754"
"15813","94.84200","7.90364","0.00767"
"15846","95.04000","7.92026","0.00794"
"15879","95.23800","7.93670","0.00719"
"15912","95.43600","7.95320","0.00821"
"15945","95.63400","7.96971","0.00770"
"15978","95.83200","7.98615","0.00784"
"16011","96.03000","8.00271","0.00786"
"16044","96.22800","8.01921","0.00739"
"16077","96.42600","8.03565","0.00846"
"16110","96.62400","8.05227","0.00827"
"16143","96.82200","8.06872","0.00760"
"16176","97.02000","8.08516","0.00834"
"16209","97.21800","8.10172","0.00827"
"16242","97.41600","8.11816","0.00821"
"16275","97.61400","8.13466","0.00815"
"16308","97.81200","8.15123","0.00794"
"16341","98.01000","8.16767","0.00862"
"16374","98.20800","8.18423","0.00795"
"16407","98.40600","8.20073","0.00822"
"16440","98.60400","8.21717","0.00790"
"16473","98.80200","8.23374","0.00854"
"16506","99.00000","8.25018","0.00864"
"16539","99.19800","8.26674","0.00849"
"16572","99.39600","8.28318","0.00842"
"16605","99.59400","8.29968","0.00824"
"16638","99.79200","8.31625","0.00866"
"16671","99.99000","8.33269","0.00905"
"16704","100.18800","8.34919","0.00895"
"16737","100.38600","8.36575","0.00846"
"16770","100.58400","8.38219","0.00952"
"16803","100.78200","8.39870","0.00875"
"16836","100.98000","8.41520","0.00863"
"16869","101.17800","8.43170","0.00841"
"16902","101.37600","8.44820","0.00871"
"16935","101.57400","8.46476","0.00813"
"16968","101.77200","8.48120","0.00900"
"17001","101.97000","8.49771","0.00921"
"17034","102.16800","8.51421","0.00869"
"17067","102.36600","8.53065","0.00891"
"17100","102.56400","8.54721","0.00888"
"17133","102.76200","8.56371","0.00898"
"17166","102.96000","8.58022","0.00940"
"17199","103.15800","8.59666","0.00916"
"17232","103.35600","8.61322","0.00890"
"17265","103.55400","8.62972","0.00881"
"17298","103.75200","8.64622","0.00905"
"17331","103.95000","8.66273","0.00891"
"17364","104.14800","8.67923","0.00813"
"17397","104.34600","8.69573","0.00925"
"17430","104.54400","8.71217","0.00869"
"17463","104.74200","8.72867","0.00909"
"17496","104.94000","8.74524","0.00909"
"17529","105.13800","8.76168","0.00932"
"17562","105.33600","8.77818","0.00943"
"17595","105.53400","8.79462","0.00993"
"17628","105.73200","8.81124","0.00969"
"17661","105.93000","8.82769","0.00870"
"17694","106.12800","8.84419","0.00960"
"17727","106.32600","8.86069","0.00893"
"17760","106.52400","8.87725","0.00988"
"17793","106.72200","8.89363","0.01009"
"17826","106.92000","8.91020","0.00929"
"17859","107.11800","8.92664","0.00954"
"17892","107.31600","8.94320","0.00985"
"17925","107.51400","8.95970","0.00910"
"17958","107.71200","8.97614","0.00868"
"17991","107.91000","8.99276","0.00960"
"18024","108.10800","9.00927","0.00988"
"18057","108.30600","9.02559","0.00974"
"18090","108.50400","9.04227","0.00936"
"18123","108.70200","9.05871","0.01014"
"18156","108.90000","9.07515","0.01014"
"18189","109.09800","9.09178","0.01018"
"18222","109.29600","9.10822","0.01013"
"18255","109.49400","9.12472","0.00953"
"18288","109.69200","9.14122","0.00930"
"18321","109.89000","9.15766","0.01038"
"18354","110.08800","9.17423","0.01008"
"18387","110.28600","9.19067","0.01042"
"18420","110.48400","9.20717","0.01038"
"18453","110.68200","9.22373","0.01075"
"18486","110.88000","9.24017","0.01034"
"18519","111.07800","9.25667","0.01035"
"18552","111.27600","9.27324","0.01090"
"18585","111.47400","9.28968","0.01055"
"18618","111.67200","9.30624","0.01007"
"18651","111.87000","9.32274","0.01065"
"18684","112.06800","9.33912","0.01086"
"18717","112.26600","9.35575","0.01101"
"18750","112.46400","9.37219","0.01025"
"18783","112.66200","9.38869","0.01070"
"18816","112.86000","9.40519","0.01124"
"18849","113.05800","9.42169","0.01095"
"18882","113.25600","9.43820","0.01092"
"18915","113.45400","9.45470","0.01125"
"18948","113.65200","9.47120","0.01138"
"18981","113.85000","9.48776","0.01106"
"19014","114.04800","9.50414","0.01131"
"19047","114.24600","9.52071","0.01128"
"19080","114.44400","9.53721","0.01113"
"19113","114.64200","9.55365","0.01154"
"19146","114.84000","9.57021","0.01140"
"19179","115.03800","9.58677","0.01189"
"19212","115.23600","9.60316","0.01140"
"19245","115.43400","9.61978","0.01212"
"19278","115.63200","9.63622","0.01181"
"19311","115.83000","9.65272","0.01197"
"19344","116.02800","9.66922","0.01176"
"19377","116.22600","9.68567","0.01179"
"19410","116.42400","9.70223","0.01163"
"19443","116.62200","9.71873","0.01193"
"19476","116.82000","9.73517","0.01209"
"19509","117.01800","9.75173","0.01206"
"19542","117.21600","9.76823","0.01205"
"19575","117.41400","9.78468","0.01203"
"19608","117.61200","9.80124","0.01223"
"19641","117.81000","9.81768","0.01233"
"19674","118.00800","9.83418","0.01215"
"19707","118.20600","9.85068","0.01215"
"19740","118.40400","9.86719","0.01224"
"19773","118.60200","9.88369","0.01248"
"19806","118.80000","9.90025","0.01262"
"19839","118.99800","9.91669","0.01292"
"19872","119.19600","9.93325","0.01268"
"19905","119.39400","9.94976","0.01245"
"19938","119.59200","9.96620","0.01347"
"19971","119.79000","9.98270","0.01357"
"20004","119.98800","9.99926","0.01195"
"20037","120.18600","10.01564","0.01213"
"20070","120.38400","10.03215","0.01261"
"20103","120.58200","10.04871","0.01217"
"20136","120.78000","10.06521","0.01258"
"20169","120.97800","10.08171","0.01235"
"20202","121.17600","10.09815","0.01268"
"20235","121.37400","10.11471","0.01260"
"20268","121.57200","10.13122","0.01243"
"20301","121.77000","10.14766","0.01301"
"20334","121.96800","10.16422","0.01269"
"20367","122.16600","10.18072","0.01272"
"20400","122.36400","10.19722","0.01374"
"20433","122.56200","10.21373","0.01342"
"20466","122.76000","10.23017","0.01347"
"20499","122.95800","10.24673","0.01353"
"20532","123.15600","10.26323","0.01363"
"20565","123.35400","10.27967","0.01378"
"20598","123.55200","10.29618","0.01376"
"20631","123.75000","10.31268","0.01442"
"20664","123.94800","10.32918","0.01430"
"20697","124.14600","10.34574","0.01401"
"20730","124.34400","10.36218","0.01379"
"20763","124.54200","10.37874","0.01429"
"20796","124.74000","10.39519","0.01418"
"20829","124.93800","10.41163","0.01478"
"20862","125.13600","10.42825","0.01429"
"20895","125.33400","10.44475","0.01423"
"20928","125.53200","10.46114","0.01492"
"20961","125.73000","10.47776","0.01477"
"20994","125.92800","10.49420","0.01503"
"21027","126.12600","10.51070","0.01509"
"21060","126.32400","10.52726","0.01526"
"21093","126.52200","10.54370","0.01520"
"21126","126.72000","10.56021","0.01584"
"21159","126.91800","10.57671","0.01579"
"21192","127.11600","10.59315","0.01534"
"21225","127.31400","10.60977","0.01635"
"21258","127.51200","10.62621","0.01592"
"21291","127.71000","10.64266","0.01642"
"21324","127.90800","10.65928","0.01661"
"21357","128.10600","10.67566","0.01627"
"21390","128.30400","10.69222","0.01688"
"21423","128.50200","10.70872","0.01648"
"21456","128.70000","10.72517","0.01638"
"21489","128.89800","10.74173","0.01736"
"21522","129.09600","10.75823","0.01716"
"21555","129.29400","10.77461","0.01824"
"21588","129.49200","10.79123","0.01766"
"21621","129.69000","10.80774","0.01753"
"21654","129.88800","10.82418","0.01839"
"21687","130.08600","10.84074","0.01837"
"21720","130.28400","10.85718","0.01857"
"21753","130.48200","10.87368","0.01848"
"21786","130.68000","10.89024","0.01838"
"21819","130.87800","10.90663","0.01891"
"21852","131.07600","10.92325","0.01904"
"21885","131.27400","10.93963","0.01916"
"21918","131.47200","10.95619","0.01921"
"21951","131.67000","10.97269","0.01903"
"21984","131.86800","10.98914","0.01967"
"22017","132.06600","11.00576","0.01947"
"22050","132.26400","11.02226","0.02008"
"22083","132.46200","11.03870","0.02090"
"22116","132.66000","11.05526","0.02067"
"22149","132.85800","11.07171","0.02057"
"22182","133.05600","11.08821","0.02119"
"22215","133.25400","11.10471","0.02096"
"22248","133.45200","11.12115","0.02123"
"22281","133.65000","11.13771","0.02192"
"22314","133.84800","11.15427","0.02215"
"22347","134.04600","11.17072","0.02228"
"22380","134.24400","11.18722","0.02228"
"22413","134.44200","11.20372","0.02280"
"22446","134.64000","11.22016","0.02338"
"22479","134.83800","11.23678","0.02366"
"22512","135.03600","11.25323","0.02384"
"22545","135.23400","11.26973","0.02385"
"22578","135.43200","11.28617","0.02441"
"22611","135.63000","11.30267","0.02431"
"22644","135.82800","11.31912","0.02509"
"22677","136.02600","11.33574","0.02540"
"22710","136.22400","11.35218","0.02603"
"22743","136.42200","11.36868","0.02628"
"22776","136.62000","11.38524","0.02705"
"22809","136.81800","11.40168","0.02639"
"22842","137.01600","11.41819","0.02719"
"22875","137.21400","11.43475","0.02695"
"22908","137.41200","11.45119","0.02744"
"22941","137.61000","11.46769","0.02763"
"22974","137.80800","11.48413","0.02842"
"23007","138.00600","11.50070","0.02820"
"23040","138.20400","11.51720","0.02868"
"23073","138.40200","11.53364","0.02924"
"23106","138.60000","11.55020","0.02991"
"23139","138.79800","11.56670","0.02969"
"23172","138.99600","11.58315","0.03044"
"23205","139.19400","11.59971","0.03037"
"23238","139.39200","11.61621","0.03060"
"23271","139.59000","11.63265","0.03107"
"23304","139.78800","11.64921","0.03077"
"23337","139.98600","11.66572","0.03133"
"23370","140.18400","11.68222","0.03137"
"23403","140.38200","11.69878","0.03199"
"23436","140.58000","11.71516","0.03197"
"23469","140.77800","11.73172","0.03241"
"23502","140.97600","11.74822","0.03274"
"23535","141.17400","11.76467","0.03180"
"23568","141.37200","11.78123","0.03191"
"23601","141.57000","11.79767","0.03269"
"23634","141.76800","11.81423","0.03296"
"23667","141.96600","11.83067","0.03361"
"23700","142.16400","11.84712","0.03350"
"23733","142.36200","11.86374","0.03391"
"23766","142.56000","11.88024","0.03429"
"23799","142.75800","11.89662","0.03470"
"23832","142.95600","11.91324","0.03499"
"23865","143.15400","11.92969","0.03529"
"23898","143.35200","11.94619","0.03551"
"23931","143.55000","11.96275","0.03597"
"23964","143.74800","11.97919","0.03598"
"23997","143.94600","11.99569","0.03623"
"24030","144.14400","12.01219","0.03654"
"24063","144.34200","12.02864","0.03690"
"24096","144.54000","12.04526","0.03722"
"24129","144.73800","12.06164","0.03737"
"24162","144.93600","12.07814","0.03789"
"24195","145.13400","12.09476","0.03814"
"24228","145.33200","12.11121","0.03806"
"24261","145.53000","12.12765","0.03869"
"24294","145.72800","12.14421","0.03898"
"24327","145.92600","12.16065","0.03930"
"24360","146.12400","12.17727","0.03955"
"24393","146.32200","12.19372","0.03993"
"24426","146.52000","12.21016","0.04017"
"24459","146.71800","12.22678","0.04084"
"24492","146.91600","12.24322","0.04106"
"24525","147.11400","12.25972","0.04175"
"24558","147.31200","12.27623","0.04232"
"24591","147.51000","12.29267","0.04344"
"24624","147.70800","12.30923","0.04403"
"24657","147.90600","12.32573","0.04445"
"24690","148.10400","12.34217","0.04525"
"24723","148.30200","12.35874","0.04673"
"24756","148.50000","12.37518","0.04728"
"24789","148.69800","12.39168","0.04849"
"24822","148.89600","12.40818","0.04914"
"24855","149.09400","12.42468","0.05041"
"24888","149.29200","12.44118","0.05142"
"24921","149.49000","12.45775","0.05284"
"24954","149.68800","12.47419","0.05467"
"24987","149.88600","12.49075","0.05555"
"25020","150.08400","12.50719","0.05614"
"25053","150.28200","12.52369","0.05757"
"25086","150.48000","12.54020","0.05908"
"25119","150.67800","12.55664","0.06061"
"25152","150.87600","12.57320","0.06184"
"25185","151.07400","12.58976","0.06344"
"25218","151.27200","12.60620","0.06482"
"25251","151.47000","12.62271","0.06577"
"25284","151.66800","12.63921","0.06718"
"25317","151.86600","12.65565","0.06854"
"25350","152.06400","12.67227","0.06962"
"25383","152.26200","12.68871","0.07105"
"25416","152.46000","12.70516","0.07281"
"25449","152.65800","12.72172","0.07332"
"25482","152.85600","12.73822","0.07563"
"25515","153.05400","12.75466","0.07686"
"25548","153.25200","12.77122","0.07862"
"25581","153.45000","12.78767","0.07956"
"25614","153.64800","12.80423","0.08101"
"25647","153.84600","12.82073","0.08197"
"25680","154.04400","12.83717","0.08315"
"25713","154.24200","12.85367","0.08388"
"25746","154.44000","12.87024","0.08477"
"25779","154.63800","12.88668","0.08563"
"25812","154.83600","12.90324","0.08637"
"25845","155.03400","12.91968","0.08680"
"25878","155.23200","12.93624","0.08755"
"25911","155.43000","12.95269","0.08824"
"25944","155.62800","12.96919","0.08890"
"25977","155.82600","12.98569","0.08983"
"26010","156.02400","13.00225","0.09031"
"26043","156.22200","13.01863","0.09091"
"26076","156.42000","13.03520","0.09169"
"26109","156.61800","13.05170","0.09328"
"26142","156.81600","13.06814","0.09616"
"26175","157.01400","13.08470","0.09733"
"26208","157.21200","13.10120","0.09935"
"26241","157.41000","13.11770","0.10227"
"26274","157.60800","13.13421","0.10430"
"26307","157.80600","13.15065","0.10667"
"26340","158.00400","13.16727","0.10808"
"26373","158.20200","13.18371","0.11030"
"26406","158.40000","13.20021","0.11235"
"26439","158.59800","13.21671","0.11463"
"26472","158.79600","13.23316","0.11581"
"26505","158.99400","13.24972","0.11744"
"26538","159.19200","13.26622","0.11892"
"26571","159.39000","13.28266","0.12064"
"26604","159.58800","13.29923","0.12192"
"26637","159.78600","13.31573","0.12306"
"26670","159.98400","13.33217","0.12445"
"26703","160.18200","13.34873","0.12520"
"26736","160.38000","13.36517","0.12652"
"26769","160.57800","13.38168","0.12750"
"26802","160.77600","13.39824","0.12852"
"26835","160.97400","13.41468","0.12931"
"26868","161.17200","13.43124","0.12997"
"26901","161.37000","13.44768","0.13082"
"26934","161.56800","13.46412","0.13188"
"26967","161.76600","13.48075","0.13218"
"27000","161.96400","13.49713","0.13268"
"27033","162.16200","13.51369","0.13386"
"27066","162.36000","13.53025","0.13478"
"27099","162.55800","13.54669","0.13552"
"27132","162.75600","13.56320","0.13723"
"27165","162.95400","13.57976","0.13793"
"27198","163.15200","13.59620","0.13952"
"27231","163.35000","13.61270","0.14103"
"27264","163.54800","13.62920","0.14300"
"27297","163.74600","13.64571","0.14518"
"27330","163.94400","13.66227","0.14904"
"27363","164.14200","13.67871","0.15137"
"27396","164.34000","13.69527","0.15508"
"27429","164.53800","13.71171","0.15815"
"27462","164.73600","13.72822","0.16331"
"27495","164.93400","13.74472","0.16602"
"27528","165.13200","13.76122","0.17152"
"27561","165.33000","13.77766","0.17567"
"27594","165.52800","13.79428","0.17939"
"27627","165.72600","13.81067","0.18445"
"27660","165.92400","13.82723","0.18674"
"27693","166.12200","13.84373","0.18893"
"27726","166.32000","13.86017","0.19079"
"27759","166.51800","13.87667","0.19179"
"27792","166.71600","13.89323","0.19343"
"27825","166.91400","13.90968","0.19339"
"27858","167.11200","13.92624","0.19504"
"27891","167.31000","13.94268","0.19635"
"27924","167.50800","13.95918","0.19820"
"27957","167.70600","13.97568","0.20100"
"27990","167.90400","13.99219","0.20413"
"28023","168.10200","14.00869","0.20692"
"28056","168.30000","14.02519","0.21058"
"28089","168.49800","14.04169","0.21351"
"28122","168.69600","14.05825","0.21529"
"28155","168.89400","14.07470","0.21870"
"28188","169.09200","14.09120","0.22115"
"28221","169.29000","14.10776","0.22404"
"28254","169.48800","14.12426","0.22614"
"28287","169.68600","14.14070","0.22853"
"28320","169.88400","14.15721","0.23054"
"28353","170.08200","14.17371","0.23120"
"28386","170.28000","14.19021","0.23260"
"28419","170.47800","14.20671","0.23433"
"28452","170.67600","14.22315","0.23548"
"28485","170.87400","14.23972","0.23655"
"28518","171.07200","14.25622","0.23761"
"28551","171.27000","14.27266","0.23870"
"28584","171.46800","14.28916","0.23969"
"28617","171.66600","14.30572","0.24063"
"28650","171.86400","14.32216","0.24172"
"28683","172.06200","14.33873","0.24278"
"28716","172.26000","14.35517","0.24354"
"28749","172.45800","14.37173","0.24543"
"28782","172.65600","14.38823","0.24707"
"28815","172.85400","14.40467","0.24975"
"28848","173.05200","14.42118","0.25270"
"28881","173.25000","14.43774","0.25478"
"28914","173.44800","14.45418","0.25751"
"28947","173.64600","14.47068","0.26141"
"28980","173.84400","14.48718","0.26375"
"29013","174.04200","14.50369","0.26679"
"29046","174.24000","14.52019","0.27013"
"29079","174.43800","14.53669","0.27358"
"29112","174.63600","14.55319","0.27639"
"29145","174.83400","14.56969","0.27916"
"29178","175.03200","14.58614","0.28178"
"29211","175.23000","14.60276","0.28372"
"29244","175.42800","14.61920","0.28614"
"29277","175.62600","14.63570","0.28782"
"29310","175.82400","14.65226","0.29035"
"29343","176.02200","14.66870","0.29414"
"29376","176.22000","14.68521","0.29804"
"29409","176.41800","14.70177","0.30264"
"29442","176.61600","14.71815","0.30803"
"29475","176.81400","14.73477","0.31405"
"29508","177.01200","14.75121","0.31866"
"29541","177.21000","14.76766","0.32437"
"29574","177.40800","14.78428","0.32898"
"29607","177.60600","14.80072","0.33238"
"29640","177.80400","14.81722","0.33592"
"29673","178.00200","14.83372","0.33870"
"29706","178.20000","14.85017","0.34103"
"29739","178.39800","14.86673","0.34299"
"29772","178.59600","14.88323","0.34420"
"29805","178.79400","14.89967","0.34539"
"29838","178.99200","14.91623","0.34608"
"29871","179.19000","14.93268","0.34674"
"29904","179.38800","14.94918","0.34745"
"29937","179.58600","14.96568","0.34838"
"29970","179.78400","14.98218","0.34924"
"30003","179.98200","14.99874","0.35086"
"30036","180.18000","15.01524","0.35239"
"30069","180.37800","15.03169","0.35444"
"30102","180.57600","15.04825","0.35702"
"30135","180.77400","15.06469","0.36007"
"30168","180.97200","15.08119","0.36295"
"30201","181.17000","15.09769","0.36644"
"30234","181.36800","15.11420","0.37074"
"30267","181.56600","15.13070","0.37519"
"30300","181.76400","15.14720","0.38012"
"30333","181.96200","15.16370","0.38392"
"30366","182.16000","15.18020","0.38719"
"30399","182.35800","15.19671","0.38867"
"30432","182.55600","15.21321","0.22955"
"30465","182.75400","15.22971","0.21827"
"30498","182.95200","15.24615","0.23318"
"30531","183.15000","15.26271","0.23101"
"30564","183.34800","15.27921","0.23676"
"30597","183.54600","15.29566","0.23389"
"30630","183.74400","15.31222","0.24021"
"30663","183.94200","15.32866","0.23800"
"30696","184.14000","15.34516","0.23948"
"30729","184.33800","15.36172","0.24530"
"30762","184.53600","15.37823","0.24339"
"30795","184.73400","15.39473","0.25307"
"30828","184.93200","15.41117","0.25031"
"30861","185.13000","15.42767","0.26482"
"30894","185.32800","15.44423","0.25890"
"30927","185.52600","15.46074","0.26550"
"30960","185.72400","15.47718","0.27584"
"30993","185.92200","15.49374","0.27353"
"31026","186.12000","15.51024","0.28370"
"31059","186.31800","15.52662","0.28164"
"31092","186.51600","15.54325","0.28897"
"31125","186.71400","15.55975","0.29002"
"31158","186.91200","15.57619","0.29049"
"31191","187.11000","15.59275","0.30831"
"31224","187.30800","15.60919","0.30411"
"31257","187.50600","15.62570","0.31635"
"31290","187.70400","15.64220","0.32058"
"31323","187.90200","15.65870","0.32425"
"31356","188.10000","15.67520","0.33876"
"31389","188.29800","15.69176","0.33550"
"31422","188.49600","15.70815","0.34091"
"31455","188.69400","15.72471","0.34416"
"31488","188.89200","15.74121","0.34478"
"31521","189.09000","15.75771","0.34696"
"31554","189.28800","15.77421","0.34689"
"31587","189.48600","15.79065","0.34781"
"31620","189.68400","15.80722","0.35089"
"31653","189.88200","15.82372","0.35041"
"31686","190.08000","15.84016","0.35363"
"31719","190.27800","15.85672","0.35673"
"31752","190.47600","15.87322","0.35668"
"31785","190.67400","15.88966","0.36521"
"31818","190.87200","15.90623","0.36585"
"31851","191.07000","15.92267","0.36712"
"31884","191.26800","15.93923","0.37861"
"31917","191.46600","15.95573","0.37838"
"31950","191.66400","15.97217","0.38340"
"31983","191.86200","15.98874","0.39167"
"32016","192.06000","16.00518","0.39139"
"32049","192.25800","16.02162","0.39450"
"32082","192.45600","16.03824","0.39916"
"32115","192.65400","16.05468","0.39870"
"32148","192.85200","16.07119","0.40317"
"32181","193.05000","16.08775","0.40889"
"32214","193.24800","16.10413","0.40985"
"32247","193.44600","16.12075","0.41555"
"32280","193.64400","16.13719","0.42019"
"32313","193.84200","16.15364","0.42077"
"32346","194.04000","16.17026","0.42538"
"32379","194.23800","16.18670","0.42799"
"32412","194.43600","16.20314","0.42562"
"32445","194.63400","16.21970","0.42908"
"32478","194.83200","16.23621","0.43121"
"32511","195.03000","16.25271","0.43173"
"32544","195.22800","16.26921","0.43463"
"32577","195.42600","16.28571","0.43677"
"32610","195.62400","16.30227","0.43834"
"32643","195.82200","16.31866","0.44045"
"32676","196.02000","16.33516","0.44424"
"32709","196.21800","16.35172","0.44515"
"32742","196.41600","16.36816","0.44857"
"32775","196.61400","16.38472","0.45333"
"32808","196.81200","16.40123","0.45462"
"32841","197.01000","16.41767","0.45803"
"32874","197.20800","16.43423","0.46369"
"32907","197.40600","16.45073","0.46626"
"32940","197.60400","16.46717","0.46933"
"32973","197.80200","16.48374","0.47483"
"33006","198.00000","16.50018","0.47760"
"33039","198.19800","16.51668","0.47926"
"33072","198.39600","16.53318","0.48480"
"33105","198.59400","16.54968","0.48833"
"33138","198.79200","16.56618","0.48962"
"33171","198.99000","16.58275","0.49298"
"33204","199.18800","16.59913","0.49460"
"33237","199.38600","16.61569","0.48729"
"33270","199.58400","16.63219","0.30326"
"33303","199.78200","16.64869","0.32448"
"33336","199.98000","16.66520","0.30809"
"33369","200.17800","16.68164","0.31929"
"33402","200.37600","16.69820","0.33461"
"33435","200.57400","16.71470","0.33013"
"33468","200.77200","16.73120","0.34607"
"33501","200.97000","16.74771","0.34163"
"33534","201.16800","16.76427","0.34559"
"33567","201.36600","16.78071","0.34675"
"33600","201.56400","16.79727","0.34643"
"33633","201.76200","16.81371","0.35111"
"33666","201.96000","16.83016","0.34815"
"33699","202.15800","16.84672","0.35225"
"33732","202.35600","16.86316","0.35627"
"33765","202.55400","16.87966","0.35396"
"33798","202.75200","16.89622","0.36599"
"33831","202.95000","16.91266","0.36297"
"33864","203.14800","16.92923","0.36606"
"33897","203.34600","16.94573","0.38003"
"33930","203.54400","16.96217","0.37266"
"33963","203.74200","16.97873","0.38568"
"33996","203.94000","16.99523","0.38720"
"34029","204.13800","17.01168","0.38824"
"34062","204.33600","17.02818","0.39601"
"34095","204.53400","17.04468","0.39421"
"34128","204.73200","17.06118","0.39658"
"34161","204.93000","17.07774","0.40443"
"34194","205.12800","17.09413","0.40080"
"34227","205.32600","17.11075","0.40692"
"34260","205.52400","17.12725","0.41220"
"34293","205.72200","17.14369","0.40957"
"34326","205.92000","17.16019","0.41918"
"34359","206.11800","17.17669","0.42028"
"34392","206.31600","17.19320","0.42047"
"34425","206.51400","17.20970","0.42798"
"34458","206.71200","17.22620","0.42730"
"34491","206.91000","17.24270","0.42991"
"34524","207.10800","17.25926","0.43421"
"34557","207.30600","17.27565","0.43334"
"34590","207.50400","17.29227","0.43547"
"34623","207.70200","17.30871","0.43901"
"34656","207.90000","17.32521","0.43782"
"34689","208.09800","17.34177","0.23924"
"34722","208.29600","17.35822","0.21486"
"34755","208.49400","17.37472","0.23805"
"34788","208.69200","17.39122","0.21807"
"34821","208.89000","17.40766","0.24165"
"34854","209.08800","17.42422","0.22368"
"34887","209.28600","17.44067","0.24198"
"34920","209.48400","17.45717","0.22836"
"34953","209.68200","17.47373","0.24312"
"34986","209.88000","17.49011","0.23410"
"35019","210.07800","17.50673","0.24508"
"35052","210.27600","17.52324","0.11029"
"35085","210.47400","17.53968","0.10525"
"35118","210.67200","17.55624","0.08994"
"35151","210.87000","17.57268","0.10080"
"35184","211.06800","17.58912","0.09309"
"35217","211.26600","17.60575","0.09177"
"35250","211.46400","17.62219","0.10553"
"35283","211.66200","17.63869","0.09641"
"35316","211.86000","17.65525","0.11325"
"35349","212.05800","17.67163","0.10695"
"35382","212.25600","17.68826","0.11285"
"35415","212.45400","17.70476","0.11779"
"35448","212.65200","17.72120","0.11123"
"35481","212.85000","17.73776","0.12021"
"35514","213.04800","17.75420","0.11472"
"35547","213.24600","17.77065","0.11509"
"35580","213.44400","17.78721","0.12016"
"35613","213.64200","17.80365","0.11521"
"35646","213.84000","17.82021","0.12269"
"35679","214.03800","17.83671","0.11887"
"35712","214.23600","17.85315","0.12384"
"35745","214.43400","17.86966","0.12356"
"35778","214.63200","17.88622","0.12414"
"35811","214.83000","17.90266","0.12736"
"35844","215.02800","17.91922","0.12476"
"35877","215.22600","17.93566","0.12930"
"35910","215.42400","17.95217","0.12685"
"35943","215.62200","17.96873","0.13020"
"35976","215.82000","17.98523","0.12996"
"36009","216.01800","18.00173","0.13074"
"36042","216.21600","18.01817","0.13232"
"36075","216.41400","18.03468","0.13143"
"36108","216.61200","18.05124","0.13357"
"36141","216.81000","18.06768","0.13279"
"36174","217.00800","18.08424","0.13384"
"36207","217.20600","18.10068","0.13445"
"36240","217.40400","18.11719","0.13429"
"36273","217.60200","18.13369","0.13660"
"36306","217.80000","18.15019","0.13567"
"36339","217.99800","18.16669","0.13880"
"36372","218.19600","18.18319","0.13714"
"36405","218.39400","18.19970","0.14045"
"36438","218.59200","18.21620","0.13881"
"36471","218.79000","18.23270","0.14179"
"36504","218.98800","18.24920","0.14182"
"36537","219.18600","18.26570","0.14378"
"36570","219.38400","18.28221","0.14659"
"36603","219.58200","18.29871","0.14602"
"36636","219.78000","18.31521","0.14953"
"36669","219.97800","18.33171","0.14944"
"36702","220.17600","18.34821","0.15270"
"36735","220.37400","18.36471","0.15312"
"36768","220.57200","18.38128","0.15600"
"36801","220.77000","18.39766","0.15781"
"36834","220.96800","18.41422","0.15996"
"36867","221.16600","18.43072","0.16325"
"36900","221.36400","18.44722","0.16409"
"36933","221.56200","18.46373","0.16882"
"36966","221.76000","18.48017","0.16954"
"36999","221.95800","18.49667","0.17489"
"37032","222.15600","18.51323","0.17576"
"37065","222.35400","18.52961","0.18093"
"37098","222.55200","18.54623","0.18195"
"37131","222.75000","18.56274","0.18398"
"37164","222.94800","18.57918","0.18630"
"37197","223.14600","18.59574","0.18710"
"37230","223.34400","18.61218","0.18896"
"37263","223.54200","18.62874","0.18872"
"37296","223.74000","18.64525","0.19050"
"37329","223.93800","18.66163","0.19115"
"37362","224.13600","18.67819","0.19253"
"37395","224.33400","18.69475","0.19256"
"37428","224.53200","18.71113","0.19399"
"37461","224.73000","18.72775","0.19473"
"37494","224.92800","18.74420","0.19564"
"37527","225.12600","18.76064","0.19676"
"37560","225.32400","18.77726","0.19826"
"37593","225.52200","18.79370","0.19928"
"37626","225.72000","18.81021","0.20036"
"37659","225.91800","18.82671","0.20167"
"37692","226.11600","18.84315","0.20306"
"37725","226.31400","18.85977","0.20513"
"37758","226.51200","18.87621","0.20803"
"37791","226.71000","18.89265","0.20953"
"37824","226.90800","18.90922","0.21110"
"37857","227.10600","18.92566","0.21284"
"37890","227.30400","18.94222","0.21398"
"37923","227.50200","18.95872","0.21569"
"37956","227.70000","18.97516","0.21634"
"37989","227.89800","18.99179","0.21950"
"38022","228.09600","19.00823","0.22021"
"38055","228.29400","19.02461","0.22303"
"38088","228.49200","19.04123","0.22382"
"38121","228.69000","19.05767","0.22518"
"38154","228.88800","19.07418","0.22665"
"38187","229.08600","19.09074","0.22841"
"38220","229.28400","19.10718","0.22880"
"38253","229.48200","19.12374","0.23025"
"38286","229.68000","19.14024","0.23101"
"38319","229.87800","19.15669","0.23179"
"38352","230.07600","19.17325","0.23258"
"38385","230.27400","19.18969","0.23373"
"38418","230.47200","19.20619","0.23429"
"38451","230.67000","19.22269","0.23493"
"38484","230.86800","19.23920","0.23574"
"38517","231.06600","19.25564","0.23655"
"38550","231.26400","19.27220","0.23684"
"38583","231.46200","19.28870","0.23773"
"38616","231.66000","19.30520","0.23835"
"38649","231.85800","19.32171","0.23882"
"38682","232.05600","19.33815","0.23936"
"38715","232.25400","19.35471","0.24001"
"38748","232.45200","19.37115","0.24058"
"38781","232.65000","19.38771","0.24101"
"38814","232.84800","19.40421","0.24175"
"38847","233.04600","19.42072","0.24249"
"38880","233.24400","19.43722","0.24309"
"38913","233.44200","19.45372","0.24366"
"38946","233.64000","19.47022","0.24428"
"38979","233.83800","19.48672","0.24574"
"39012","234.03600","19.50323","0.24645"
"39045","234.23400","19.51973","0.24821"
"39078","234.43200","19.53623","0.24889"
"39111","234.63000","19.55267","0.25052"
"39144","234.82800","19.56917","0.25266"
"39177","235.02600","19.58573","0.25445"
"39210","235.22400","19.60218","0.25649"
"39243","235.42200","19.61868","0.25888"
"39276","235.62000","19.63518","0.26154"
"39309","235.81800","19.65168","0.26288"
"39342","236.01600","19.66818","0.26507"
"39375","236.21400","19.68475","0.26636"
"39408","236.41200","19.70119","0.26737"
"39441","236.61000","19.71769","0.26913"
"39474","236.80800","19.73419","0.27071"
"39507","237.00600","19.75070","0.27258"
"39540","237.20400","19.76719","0.27506"
"39573","237.40200","19.78370","0.27648"
"39606","237.60000","19.80026","0.27831"
"39639","237.79800","19.81676","0.27973"
"39672","237.99600","19.83308","0.28089"
"39705","238.19400","19.84971","0.28257"
"39738","238.39200","19.86621","0.28384"
"39771","238.59000","19.88271","0.28433"
"39804","238.78800","19.89921","0.28557"
"39837","238.98600","19.91571","0.28679"
"39870","239.18400","19.93221","0.28758"
"39903","239.38200","19.94878","0.28941"
"39936","239.58000","19.96516","0.29077"
"39969","239.77800","19.98172","0.29267"
"40002","239.97600","19.99822","0.29471"
"40035","240.17400","20.01466","0.29608"
"40068","240.37200","20.03123","0.29913"
"40101","240.57000","20.04773","0.30208"
"40134","240.76800","20.06417","0.30426"
"40167","240.96600","20.08073","0.30797"
"40200","241.16400","20.09711","0.31160"
"40233","241.36200","20.11368","0.31471"
"40266","241.56000","20.13024","0.31836"
"40299","241.75800","20.14662","0.32107"
"40332","241.95600","20.16324","0.32341"
"40365","242.15400","20.17974","0.32619"
"40398","242.35200","20.19619","0.32815"
"40431","242.55000","20.21275","0.33039"
"40464","242.74800","20.22919","0.33246"
"40497","242.94600","20.24569","0.33391"
"40530","243.14400","20.26219","-0.01150"
"40563","243.34200","20.27864","-0.00105"
"40596","243.54000","20.29526","0.01032"
"40629","243.73800","20.31170","0.00630"
"40662","243.93600","20.32820","0.00197"
"40695","244.13400","20.34470","0.00403"
"40728","244.33200","20.36121","0.00527"
"40761","244.53000","20.37771","0.00423"
"40794","244.72800","20.39421","0.00433"
"40827","244.92600","20.41065","0.00394"
"40860","245.12400","20.42727","0.00402"
"40893","245.32200","20.44372","0.00490"
"40926","245.52000","20.46010","0.00444"
"40959","245.71800","20.47678","0.00385"
"40992","245.91600","20.49316","0.00461"
"41025","246.11400","20.50972","0.00447"
"41058","246.31200","20.52622","0.00460"
"41091","246.51000","20.54273","0.00469"
"41124","246.70800","20.55923","0.00410"
"41157","246.90600","20.57573","0.00445"
"41190","247.10400","20.59217","0.00469"
"41223","247.30200","20.60873","0.00440"
"41256","247.50000","20.62524","0.00449"
"41289","247.69800","20.64168","0.00490"
"41317","247.86200","20.65537","0.00464"