File: Trajectories_together/170212_1Specimen_RawData_7.csv
"","V1","V2","V3"
"1","End date","2/12/2017",""
"2","Specimen label","9DT_73",""
"3","Maximum Load","0.29008","N"
"4","Time","Extension","Load"
"5","(s)","(mm)","(N)"
"6","0.00000","0.00000","-0.00057"
"48","0.25200","0.01967","0.00163"
"90","0.50400","0.04227","0.00065"
"132","0.75600","0.06314","0.00279"
"174","1.00800","0.08424","0.00171"
"216","1.26000","0.10517","0.00324"
"258","1.51200","0.12628","0.00287"
"300","1.76400","0.14720","0.00406"
"342","2.01600","0.16819","0.00372"
"384","2.26800","0.18917","0.00473"
"426","2.52000","0.21022","0.00471"
"468","2.77200","0.23115","0.00484"
"510","3.02400","0.25219","0.00525"
"552","3.27600","0.27324","0.00629"
"594","3.52800","0.29416","0.00653"
"636","3.78000","0.31521","0.00570"
"678","4.03200","0.33614","0.00668"
"720","4.28400","0.35724","0.00653"
"762","4.53600","0.37811","0.00804"
"804","4.78800","0.39921","0.00653"
"846","5.04000","0.42014","0.00876"
"888","5.29200","0.44119","0.00807"
"930","5.54400","0.46217","0.00880"
"972","5.79600","0.48322","0.00842"
"1014","6.04800","0.50415","0.01055"
"1056","6.30000","0.52525","0.00930"
"1098","6.55200","0.54618","0.00996"
"1140","6.80400","0.56716","0.00994"
"1182","7.05600","0.58821","0.00993"
"1224","7.30800","0.60920","0.01025"
"1266","7.56000","0.63024","0.01028"
"1308","7.81200","0.65111","0.01077"
"1350","8.06400","0.67221","0.01071"
"1392","8.31600","0.69320","0.01110"
"1434","8.56800","0.71425","0.01137"
"1476","8.82000","0.73511","0.01135"
"1518","9.07200","0.75622","0.01153"
"1560","9.32400","0.77714","0.01214"
"1602","9.57600","0.79819","0.01213"
"1644","9.82800","0.81918","0.01162"
"1686","10.08000","0.84016","0.01218"
"1728","10.33200","0.86121","0.01228"
"1770","10.58400","0.88219","0.01268"
"1812","10.83600","0.90318","0.01219"
"1854","11.08800","0.92423","0.01256"
"1896","11.34000","0.94521","0.01265"
"1938","11.59200","0.96620","0.01283"
"1980","11.84400","0.98718","0.01284"
"2022","12.09600","1.00817","0.01285"
"2064","12.34800","1.02928","0.01324"
"2106","12.60000","1.05020","0.01230"
"2148","12.85200","1.07119","0.01321"
"2190","13.10400","1.09212","0.01354"
"2232","13.35600","1.11316","0.01318"
"2274","13.60800","1.13421","0.01350"
"2316","13.86000","1.15525","0.01357"
"2358","14.11200","1.17618","0.01364"
"2400","14.36400","1.19723","0.01356"
"2442","14.61600","1.21815","0.01364"
"2484","14.86800","1.23920","0.01396"
"2526","15.12000","1.26024","0.01456"
"2568","15.37200","1.28117","0.01380"
"2610","15.62400","1.30228","0.01474"
"2652","15.87600","1.32320","0.01428"
"2694","16.12800","1.34419","0.01449"
"2736","16.38000","1.36511","0.01399"
"2778","16.63200","1.38622","0.01467"
"2820","16.88400","1.40715","0.01462"
"2862","17.13600","1.42819","0.01471"
"2904","17.38800","1.44912","0.01445"
"2946","17.64000","1.47022","0.01435"
"2988","17.89200","1.49121","0.01442"
"3030","18.14400","1.51226","0.01525"
"3072","18.39600","1.53318","0.01478"
"3114","18.64800","1.55417","0.01522"
"3156","18.90000","1.57522","0.01550"
"3198","19.15200","1.59620","0.01477"
"3240","19.40400","1.61713","0.01499"
"3282","19.65600","1.63817","0.01563"
"3324","19.90800","1.65922","0.01482"
"3366","20.16000","1.68015","0.01539"
"3408","20.41200","1.70119","0.01583"
"3450","20.66400","1.72212","0.01562"
"3492","20.91600","1.74322","0.01500"
"3534","21.16800","1.76415","0.01573"
"3576","21.42000","1.78520","0.01629"
"3618","21.67200","1.80618","0.01607"
"3660","21.92400","1.82723","0.01550"
"3702","22.17600","1.84821","0.01569"
"3744","22.42800","1.86926","0.01521"
"3786","22.68000","1.89019","0.01556"
"3828","22.93200","1.91123","0.01660"
"3870","23.18400","1.93222","0.01610"
"3912","23.43600","1.95320","0.01632"
"3954","23.68800","1.97419","0.01635"
"3996","23.94000","1.99518","0.01590"
"4038","24.19200","2.01622","0.01605"
"4080","24.44400","2.03715","0.01651"
"4122","24.69600","2.05825","0.01632"
"4164","24.94800","2.07918","0.01630"
"4206","25.20000","2.10023","0.01726"
"4248","25.45200","2.12115","0.01655"
"4290","25.70400","2.14220","0.01665"
"4332","25.95600","2.16313","0.01686"
"4374","26.20800","2.18423","0.01614"
"4416","26.46000","2.20522","0.01696"
"4458","26.71200","2.22620","0.01646"
"4500","26.96400","2.24725","0.01703"
"4542","27.21600","2.26818","0.01672"
"4584","27.46800","2.28922","0.01683"
"4626","27.72000","2.31015","0.01743"
"4668","27.97200","2.33119","0.01643"
"4710","28.22400","2.35218","0.01705"
"4752","28.47600","2.37323","0.01744"
"4794","28.72800","2.39415","0.01745"
"4836","28.98000","2.41520","0.01767"
"4878","29.23200","2.43612","0.01785"
"4920","29.48400","2.45723","0.01773"
"4962","29.73600","2.47822","0.01814"
"5004","29.98800","2.49926","0.01794"
"5046","30.24000","2.52019","0.01816"
"5088","30.49200","2.54123","0.01787"
"5130","30.74400","2.56222","0.01789"
"5172","30.99600","2.58321","0.01847"
"5214","31.24800","2.60425","0.01812"
"5256","31.50000","2.62518","0.01819"
"5298","31.75200","2.64622","0.01866"
"5340","32.00400","2.66715","0.01838"
"5382","32.25600","2.68826","0.01821"
"5424","32.50800","2.70912","0.01855"
"5466","32.76000","2.73017","0.01904"
"5508","33.01200","2.75116","0.01868"
"5550","33.26400","2.77226","0.01889"
"5592","33.51600","2.79319","0.01919"
"5634","33.76800","2.81417","0.01896"
"5676","34.02000","2.83516","0.01938"
"5718","34.27200","2.85627","0.01946"
"5760","34.52400","2.87719","0.01968"
"5802","34.77600","2.89818","0.01935"
"5844","35.02800","2.91922","0.02005"
"5886","35.28000","2.94021","0.02007"
"5928","35.53200","2.96120","0.01965"
"5970","35.78400","2.98218","0.02058"
"6012","36.03600","3.00323","0.02008"
"6054","36.28800","3.02421","0.02077"
"6096","36.54000","3.04520","0.02002"
"6138","36.79200","3.06607","0.02044"
"6180","37.04400","3.08723","0.02037"
"6222","37.29600","3.10816","0.02051"
"6264","37.54800","3.12920","0.02036"
"6306","37.80000","3.15019","0.02110"
"6348","38.05200","3.17124","0.02063"
"6390","38.30400","3.19222","0.02108"
"6432","38.55600","3.21327","0.02075"
"6474","38.80800","3.23414","0.02045"
"6516","39.06000","3.25518","0.02070"
"6558","39.31200","3.27623","0.02092"
"6600","39.56400","3.29721","0.02115"
"6642","39.81600","3.31820","0.01963"
"6684","40.06800","3.33913","0.02051"
"6726","40.32000","3.36023","0.02001"
"6768","40.57200","3.38116","0.01952"
"6810","40.82400","3.40220","0.02039"
"6852","41.07600","3.42313","0.02053"
"6894","41.32800","3.44424","0.02069"
"6936","41.58000","3.46516","0.02077"
"6978","41.83200","3.48621","0.02181"
"7020","42.08400","3.50719","0.01988"
"7062","42.33600","3.52824","0.02027"
"7104","42.58800","3.54923","0.02100"
"7146","42.84000","3.57015","0.02057"
"7188","43.09200","3.59126","0.02021"
"7230","43.34400","3.61218","0.02075"
"7272","43.59600","3.63317","0.02111"
"7314","43.84800","3.65416","0.02085"
"7356","44.10000","3.67520","0.02094"
"7398","44.35200","3.69619","0.02044"
"7440","44.60400","3.71723","0.01981"
"7482","44.85600","3.73816","0.01930"
"7524","45.10800","3.75921","0.02027"
"7566","45.36000","3.78019","0.01967"
"7608","45.61200","3.80124","0.02008"
"7650","45.86400","3.82217","0.01977"
"7692","46.11600","3.84321","0.02075"
"7734","46.36800","3.86414","0.02079"
"7776","46.62000","3.88524","0.02113"
"7818","46.87200","3.90617","0.02096"
"7860","47.12400","3.92722","0.02117"
"7902","47.37600","3.94820","0.02108"
"7944","47.62800","3.96919","0.02122"
"7986","47.88000","3.99023","0.02115"
"8028","48.13200","4.01110","0.02187"
"8070","48.38400","4.03221","0.02151"
"8112","48.63600","4.05319","0.02172"
"8154","48.88800","4.07424","0.02215"
"8196","49.14000","4.09516","0.02261"
"8238","49.39200","4.11621","0.02206"
"8280","49.64400","4.13720","0.02255"
"8322","49.89600","4.15824","0.02297"
"8364","50.14800","4.17917","0.02281"
"8406","50.40000","4.20021","0.02310"
"8448","50.65200","4.22120","0.02327"
"8490","50.90400","4.24219","0.02363"
"8532","51.15600","4.26323","0.02323"
"8574","51.40800","4.28416","0.02396"
"8616","51.66000","4.30521","0.02448"
"8658","51.91200","4.32619","0.02386"
"8700","52.16400","4.34718","0.02404"
"8742","52.41600","4.36816","0.02439"
"8784","52.66800","4.38921","0.02454"
"8826","52.92000","4.41020","0.02542"
"8868","53.17200","4.43118","0.02527"
"8910","53.42400","4.45217","0.02537"
"8952","53.67600","4.47327","0.02548"
"8994","53.92800","4.49420","0.02553"
"9036","54.18000","4.51519","0.02601"
"9078","54.43200","4.53617","0.02601"
"9120","54.68400","4.55722","0.02582"
"9162","54.93600","4.57820","0.02688"
"9204","55.18800","4.59919","0.02726"
"9246","55.44000","4.62018","0.02712"
"9288","55.69200","4.64116","0.02733"
"9330","55.94400","4.66221","0.02715"
"9372","56.19600","4.68313","0.02731"
"9414","56.44800","4.70418","0.02750"
"9456","56.70000","4.72511","0.02791"
"9498","56.95200","4.74627","0.02784"
"9540","57.20400","4.76714","0.02812"
"9582","57.45600","4.78819","0.02804"
"9624","57.70800","4.80917","0.02895"
"9666","57.96000","4.83022","0.02840"
"9708","58.21200","4.85114","0.02927"
"9750","58.46400","4.87219","0.02922"
"9792","58.71600","4.89318","0.02957"
"9834","58.96800","4.91416","0.03016"
"9876","59.22000","4.93521","0.02984"
"9918","59.47200","4.95613","0.02990"
"9960","59.72400","4.97724","0.03032"
"10002","59.97600","4.99817","0.03018"
"10044","60.22800","5.01921","0.03067"
"10086","60.48000","5.04008","0.03111"
"10128","60.73200","5.06118","0.03040"
"10170","60.98400","5.08217","0.02836"
"10212","61.23600","5.10322","0.02893"
"10254","61.48800","5.12414","0.02968"
"10296","61.74000","5.14519","0.03063"
"10338","61.99200","5.16617","0.03067"
"10380","62.24400","5.18722","0.03111"
"10422","62.49600","5.20821","0.03116"
"10464","62.74800","5.22919","0.03211"
"10506","63.00000","5.25018","0.03188"
"10548","63.25200","5.27122","0.03187"
"10590","63.50400","5.29221","0.03151"
"10632","63.75600","5.31320","0.03178"
"10674","64.00800","5.33424","0.03220"
"10716","64.26000","5.35517","0.03260"
"10758","64.51200","5.37621","0.03366"
"10800","64.76400","5.39714","0.03353"
"10842","65.01600","5.41825","0.03361"
"10884","65.26800","5.43917","0.03434"
"10926","65.52000","5.46022","0.03477"
"10968","65.77200","5.48115","0.03497"
"11010","66.02400","5.50225","0.03521"
"11052","66.27600","5.52318","0.03586"
"11094","66.52800","5.54416","0.03542"
"11136","66.78000","5.56515","0.03575"
"11178","67.03200","5.58614","0.03688"
"11220","67.28400","5.60724","0.03709"
"11262","67.53600","5.62817","0.03689"
"11304","67.78800","5.64921","0.03716"
"11346","68.04000","5.67020","0.03732"
"11388","68.29200","5.69125","0.03877"
"11430","68.54400","5.71217","0.03880"
"11472","68.79600","5.73316","0.03930"
"11514","69.04800","5.75414","0.03997"
"11556","69.30000","5.77519","0.04009"
"11598","69.55200","5.79618","0.03991"
"11640","69.80400","5.81722","0.04073"
"11682","70.05600","5.83821","0.04070"
"11724","70.30800","5.85920","0.04164"
"11766","70.56000","5.88018","0.04146"
"11808","70.81200","5.90117","0.04168"
"11850","71.06400","5.92215","0.04218"
"11892","71.31600","5.94320","0.04258"
"11934","71.56800","5.96419","0.04269"
"11976","71.82000","5.98517","0.04333"
"12018","72.07200","6.00622","0.04360"
"12060","72.32400","6.02714","0.04396"
"12102","72.57600","6.04825","0.04417"
"12144","72.82800","6.06918","0.04478"
"12186","73.08000","6.09016","0.04497"
"12228","73.33200","6.11115","0.04517"
"12270","73.58400","6.13219","0.04545"
"12312","73.83600","6.15318","0.04599"
"12354","74.08800","6.17429","0.04605"
"12396","74.34000","6.19521","0.04641"
"12438","74.59200","6.21626","0.04669"
"12480","74.84400","6.23718","0.04711"
"12522","75.09600","6.25817","0.04742"
"12564","75.34800","6.27922","0.04777"
"12606","75.60000","6.30020","0.04813"
"12648","75.85200","6.32125","0.04846"
"12690","76.10400","6.34212","0.04900"
"12732","76.35600","6.36322","0.04919"
"12774","76.60800","6.38415","0.05004"
"12816","76.86000","6.40519","0.05056"
"12858","77.11200","6.42612","0.05116"
"12900","77.36400","6.44717","0.05134"
"12942","77.61600","6.46821","0.05178"
"12984","77.86800","6.48926","0.05244"
"13026","78.12000","6.51018","0.05322"
"13068","78.37200","6.53117","0.05449"
"13110","78.62400","6.55222","0.05492"
"13152","78.87600","6.57320","0.05619"
"13194","79.12800","6.59419","0.05751"
"13236","79.38000","6.61517","0.05801"
"13278","79.63200","6.63616","0.05966"
"13320","79.88400","6.65715","0.06032"
"13362","80.13600","6.67819","0.06129"
"13404","80.38800","6.69912","0.06233"
"13446","80.64000","6.72022","0.06304"
"13488","80.89200","6.74121","0.06421"
"13530","81.14400","6.76220","0.06581"
"13572","81.39600","6.78312","0.06409"
"13614","81.64800","6.80429","0.05101"
"13656","81.90000","6.82521","0.05193"
"13698","82.15200","6.84620","0.05230"
"13740","82.40400","6.86719","0.05417"
"13782","82.65600","6.88823","0.05478"
"13824","82.90800","6.90922","0.05505"
"13866","83.16000","6.93020","0.05620"
"13908","83.41200","6.95119","0.05704"
"13950","83.66400","6.97218","0.05793"
"13992","83.91600","6.99322","0.05957"
"14034","84.16800","7.01415","0.06100"
"14076","84.42000","7.03519","0.06134"
"14118","84.67200","7.05612","0.06108"
"14160","84.92400","7.07723","0.06238"
"14202","85.17600","7.09815","0.06462"
"14244","85.42800","7.11920","0.06454"
"14286","85.68000","7.14019","0.06610"
"14328","85.93200","7.16123","0.06668"
"14370","86.18400","7.18216","0.06840"
"14412","86.43600","7.20320","0.06898"
"14454","86.68800","7.22419","0.07032"
"14496","86.94000","7.24518","0.07127"
"14538","87.19200","7.26622","0.07239"
"14580","87.44400","7.28721","0.07356"
"14622","87.69600","7.30819","0.07443"
"14664","87.94800","7.32918","0.07552"
"14706","88.20000","7.35023","0.07728"
"14748","88.45200","7.37115","0.07688"
"14790","88.70400","7.39220","0.01837"
"14832","88.95600","7.41319","0.02767"
"14874","89.20800","7.43423","0.02137"
"14916","89.46000","7.45516","0.02657"
"14958","89.71200","7.47626","0.02526"
"15000","89.96400","7.49719","0.02462"
"15042","90.21600","7.51823","0.02809"
"15084","90.46800","7.53922","0.02676"
"15126","90.72000","7.56021","0.02935"
"15168","90.97200","7.58119","0.02940"
"15210","91.22400","7.60218","0.02946"
"15252","91.47600","7.62317","0.03267"
"15294","91.72800","7.64415","0.03001"
"15336","91.98000","7.66526","0.03402"
"15378","92.23200","7.68618","0.03255"
"15420","92.48400","7.70717","0.03401"
"15462","92.73600","7.72816","0.03133"
"15504","92.98800","7.74920","0.03350"
"15546","93.24000","7.77019","0.03181"
"15588","93.49200","7.79123","0.03579"
"15630","93.74400","7.81216","0.03316"
"15672","93.99600","7.83321","0.03551"
"15714","94.24800","7.85419","0.03552"
"15756","94.50000","7.87524","0.03678"
"15798","94.75200","7.89628","0.03573"
"15840","95.00400","7.91721","0.03557"
"15882","95.25600","7.93826","0.03410"
"15924","95.50800","7.95918","0.03608"
"15966","95.76000","7.98017","0.03601"
"16008","96.01200","8.00115","0.03799"
"16050","96.26400","8.02226","0.03634"
"16092","96.51600","8.04319","0.03875"
"16134","96.76800","8.06417","0.03860"
"16176","97.02000","8.08516","0.03890"
"16218","97.27200","8.10626","0.03830"
"16260","97.52400","8.12719","0.03961"
"16302","97.77600","8.14824","0.03938"
"16344","98.02800","8.16916","0.04080"
"16386","98.28000","8.19021","0.03840"
"16428","98.53200","8.21119","0.04031"
"16470","98.78400","8.23218","0.03999"
"16512","99.03600","8.25317","0.04176"
"16554","99.28800","8.27421","0.04108"
"16596","99.54000","8.29526","0.04222"
"16638","99.79200","8.31613","0.04221"
"16680","100.04400","8.33729","0.04392"
"16722","100.29600","8.35816","0.04320"
"16764","100.54800","8.37920","0.04479"
"16806","100.80000","8.40019","0.04475"
"16848","101.05200","8.42118","0.04612"
"16890","101.30400","8.44216","0.04599"
"16932","101.55600","8.46321","0.04736"
"16974","101.80800","8.48419","0.04703"
"17016","102.06000","8.50518","0.04824"
"17058","102.31200","8.52617","0.04819"
"17100","102.56400","8.54715","0.04962"
"17142","102.81600","8.56820","0.04979"
"17184","103.06800","8.58918","0.05138"
"17226","103.32000","8.61023","0.05191"
"17268","103.57200","8.63116","0.05334"
"17310","103.82400","8.65220","0.05415"
"17352","104.07600","8.67313","0.05562"
"17394","104.32800","8.69418","0.05711"
"17436","104.58000","8.71516","0.05793"
"17478","104.83200","8.73621","0.05904"
"17520","105.08400","8.75719","0.06096"
"17562","105.33600","8.77824","0.06352"
"17604","105.58800","8.79922","0.06451"
"17646","105.84000","8.82015","0.06772"
"17688","106.09200","8.84114","0.06865"
"17730","106.34400","8.86218","0.07153"
"17772","106.59600","8.88323","0.07312"
"17814","106.84800","8.90422","0.07506"
"17856","107.10000","8.92520","0.07742"
"17898","107.35200","8.94619","0.07970"
"17940","107.60400","8.96723","0.08173"
"17982","107.85600","8.98816","0.08355"
"18024","108.10800","9.00921","0.08606"
"18066","108.36000","9.03019","0.08825"
"18108","108.61200","9.05124","0.09036"
"18150","108.86400","9.07216","0.09134"
"18192","109.11600","9.09321","0.09307"
"18234","109.36800","9.11414","0.09450"
"18276","109.62000","9.13524","0.09574"
"18318","109.87200","9.15617","0.09701"
"18360","110.12400","9.17715","0.09823"
"18402","110.37600","9.19820","0.09998"
"18444","110.62800","9.21925","0.10129"
"18486","110.88000","9.24023","0.10372"
"18528","111.13200","9.26116","0.10661"
"18570","111.38400","9.28226","0.10876"
"18612","111.63600","9.30319","0.11263"
"18654","111.88800","9.32418","0.11475"
"18696","112.14000","9.34510","0.11818"
"18738","112.39200","9.36621","0.12057"
"18780","112.64400","9.38720","0.12324"
"18822","112.89600","9.40824","0.12599"
"18864","113.14800","9.42917","0.12779"
"18906","113.40000","9.45015","0.13017"
"18948","113.65200","9.47114","0.13203"
"18990","113.90400","9.49225","0.13350"
"19032","114.15600","9.51317","0.13518"
"19074","114.40800","9.53422","0.13649"
"19116","114.66000","9.55520","0.13815"
"19158","114.91200","9.57619","0.13895"
"19200","115.16400","9.59724","0.14020"
"19242","115.41600","9.61816","0.14145"
"19284","115.66800","9.63921","0.14306"
"19326","115.92000","9.66019","0.14395"
"19368","116.17200","9.68124","0.14535"
"19410","116.42400","9.70211","0.14687"
"19452","116.67600","9.72321","0.14868"
"19494","116.92800","9.74420","0.15070"
"19536","117.18000","9.76525","0.15319"
"19578","117.43200","9.78617","0.15625"
"19620","117.68400","9.80728","0.16048"
"19662","117.93600","9.82820","0.16402"
"19704","118.18800","9.84919","0.16855"
"19746","118.44000","9.87012","0.17310"
"19788","118.69200","9.89116","0.17824"
"19830","118.94400","9.91221","0.18276"
"19872","119.19600","9.93319","0.18700"
"19914","119.44800","9.95424","0.19165"
"19956","119.70000","9.97517","0.19480"
"19998","119.95200","9.99627","0.19781"
"20040","120.20400","10.01714","0.19972"
"20082","120.45600","10.03818","0.20150"
"20124","120.70800","10.05917","0.20263"
"20166","120.96000","10.08022","0.20528"
"20208","121.21200","10.10120","0.20804"
"20250","121.46400","10.12219","0.20993"
"20292","121.71600","10.14318","0.21344"
"20334","121.96800","10.16422","0.21709"
"20376","122.22000","10.18521","0.22056"
"20418","122.47200","10.20619","0.22321"
"20460","122.72400","10.22724","0.22690"
"20502","122.97600","10.24817","0.23039"
"20544","123.22800","10.26921","0.23258"
"20586","123.48000","10.29014","0.23579"
"20628","123.73200","10.31118","0.23826"
"20670","123.98400","10.33217","0.24070"
"20712","124.23600","10.35328","0.24254"
"20754","124.48800","10.37414","0.24384"
"20796","124.74000","10.39519","0.24505"
"20838","124.99200","10.41611","0.24622"
"20880","125.24400","10.43728","0.24489"
"20922","125.49600","10.45821","0.09990"
"20964","125.74800","10.47925","0.09336"
"21006","126.00000","10.50018","0.09964"
"21048","126.25200","10.52122","0.09783"
"21090","126.50400","10.54221","0.10749"
"21132","126.75600","10.56320","0.09967"
"21174","127.00800","10.58418","0.11073"
"21216","127.26000","10.60517","0.10437"
"21258","127.51200","10.62621","0.10690"
"21300","127.76400","10.64714","0.11231"
"21342","128.01600","10.66825","0.11108"
"21384","128.26800","10.68917","0.12389"
"21426","128.52000","10.71016","0.11878"
"21468","128.77200","10.73120","0.12614"
"21510","129.02400","10.75225","0.12310"
"21552","129.27600","10.77318","0.12518"
"21594","129.52800","10.79422","0.13114"
"21636","129.78000","10.81515","0.12941"
"21678","130.03200","10.83619","0.13531"
"21720","130.28400","10.85724","0.13294"
"21762","130.53600","10.87823","0.13535"
"21804","130.78800","10.89921","0.13771"
"21846","131.04000","10.92020","0.13719"
"21888","131.29200","10.94119","0.13960"
"21930","131.54400","10.96217","0.13388"
"21972","131.79600","10.98322","0.13420"
"22014","132.04800","11.00414","0.13566"
"22056","132.30000","11.02519","0.13537"
"22098","132.55200","11.04618","0.13669"
"22140","132.80400","11.06716","0.13470"
"22182","133.05600","11.08815","0.13478"
"22224","133.30800","11.10925","0.13504"
"22266","133.56000","11.13018","0.13574"
"22308","133.81200","11.15117","0.13672"
"22350","134.06400","11.17215","0.13737"
"22392","134.31600","11.19320","0.13879"
"22434","134.56800","11.21418","0.13948"
"22476","134.82000","11.23517","0.14017"
"22518","135.07200","11.25616","0.14131"
"22560","135.32400","11.27714","0.14214"
"22602","135.57600","11.29819","0.14340"
"22644","135.82800","11.31912","0.14454"
"22686","136.08000","11.34028","0.14557"
"22728","136.33200","11.36115","0.14628"
"22770","136.58400","11.38225","0.14763"
"22812","136.83600","11.40318","0.14933"
"22854","137.08800","11.42417","0.15141"
"22896","137.34000","11.44521","0.15275"
"22938","137.59200","11.46620","0.15560"
"22980","137.84400","11.48718","0.15744"
"23022","138.09600","11.50817","0.16047"
"23064","138.34800","11.52922","0.16254"
"23106","138.60000","11.55020","0.16605"
"23148","138.85200","11.57119","0.16880"
"23190","139.10400","11.59217","0.17221"
"23232","139.35600","11.61322","0.17556"
"23274","139.60800","11.63421","0.17877"
"23316","139.86000","11.65519","0.18229"
"23358","140.11200","11.67618","0.18579"
"23400","140.36400","11.69716","0.18842"
"23442","140.61600","11.71821","0.19126"
"23484","140.86800","11.73926","0.19448"
"23526","141.12000","11.76012","0.19628"
"23568","141.37200","11.78123","0.19804"
"23610","141.62400","11.80221","0.19923"
"23652","141.87600","11.82326","0.20068"
"23694","142.12800","11.84413","0.20163"
"23736","142.38000","11.86523","0.20266"
"23778","142.63200","11.88628","0.20454"
"23820","142.88400","11.90721","0.20619"
"23862","143.13600","11.92819","0.20886"
"23904","143.38800","11.94918","0.21018"
"23946","143.64000","11.97022","0.21196"
"23988","143.89200","11.99115","0.21401"
"24030","144.14400","12.01219","0.21597"
"24072","144.39600","12.03318","0.21825"
"24114","144.64800","12.05423","0.22057"
"24156","144.90000","12.07521","0.22381"
"24198","145.15200","12.09620","0.22663"
"24240","145.40400","12.11713","0.22859"
"24282","145.65600","12.13823","0.23164"
"24324","145.90800","12.15922","0.23322"
"24366","146.16000","12.18020","0.23531"
"24408","146.41200","12.20119","0.23713"
"24450","146.66400","12.22218","0.23963"
"24492","146.91600","12.24322","0.24097"
"24534","147.16800","12.26415","0.24244"
"24576","147.42000","12.28525","0.24384"
"24618","147.67200","12.30618","0.24518"
"24660","147.92400","12.32723","0.24588"
"24702","148.17600","12.34815","0.24680"
"24744","148.42800","12.36920","0.24787"
"24786","148.68000","12.39019","0.24871"
"24828","148.93200","12.41123","0.24871"
"24870","149.18400","12.43216","0.24985"
"24912","149.43600","12.45320","0.25109"
"24954","149.68800","12.47419","0.25176"
"24996","149.94000","12.49529","0.25243"
"25038","150.19200","12.51622","0.25115"
"25080","150.44400","12.53721","0.25176"
"25122","150.69600","12.55819","0.25340"
"25164","150.94800","12.57918","0.25467"
"25206","151.20000","12.60023","0.25620"
"25248","151.45200","12.62115","0.25804"
"25290","151.70400","12.64220","0.25902"
"25332","151.95600","12.66312","0.25971"
"25374","152.20800","12.68423","0.26022"
"25416","152.46000","12.70516","0.26273"
"25458","152.71200","12.72620","0.26506"
"25500","152.96400","12.74719","0.26729"
"25542","153.21600","12.76824","0.26939"
"25584","153.46800","12.78916","0.27230"
"25626","153.72000","12.81021","0.27398"
"25668","153.97200","12.83119","0.27614"
"25710","154.22400","12.85224","0.27767"
"25752","154.47600","12.87323","0.27912"
"25794","154.72800","12.89421","0.25336"
"25836","154.98000","12.91520","0.25234"
"25878","155.23200","12.93618","0.25301"
"25920","155.48400","12.95717","0.25270"
"25962","155.73600","12.97816","0.25380"
"26004","155.98800","12.99920","0.25598"
"26046","156.24000","13.02019","0.25658"
"26088","156.49200","13.04123","0.25644"
"26130","156.74400","13.06216","0.25591"
"26172","156.99600","13.08327","0.25554"
"26214","157.24800","13.10419","0.25496"
"26256","157.50000","13.12524","0.25719"
"26298","157.75200","13.14616","0.25836"
"26340","158.00400","13.16721","0.25847"
"26382","158.25600","13.18826","0.25985"
"26424","158.50800","13.20924","0.26257"
"26466","158.76000","13.23023","0.26343"
"26508","159.01200","13.25121","0.26476"
"26550","159.26400","13.27220","0.26713"
"26592","159.51600","13.29313","0.26845"
"26634","159.76800","13.31423","0.26940"
"26676","160.02000","13.33510","0.27229"
"26718","160.27200","13.35620","0.27434"
"26760","160.52400","13.37719","0.27586"
"26802","160.77600","13.39824","0.27811"
"26844","161.02800","13.41916","0.27967"
"26886","161.28000","13.44027","0.27593"
"26928","161.53200","13.46113","0.27464"
"26970","161.78400","13.48218","0.27272"
"27012","162.03600","13.50317","0.27086"
"27054","162.28800","13.52421","0.26675"
"27096","162.54000","13.54526","0.26761"
"27138","162.79200","13.56618","0.26544"
"27180","163.04400","13.58723","0.26545"
"27222","163.29600","13.60816","0.26651"
"27264","163.54800","13.62926","0.26824"
"27306","163.80000","13.65013","0.26940"
"27348","164.05200","13.67124","0.27039"
"27390","164.30400","13.69216","0.26661"
"27432","164.55600","13.71321","0.26749"
"27474","164.80800","13.73419","0.26806"
"27516","165.06000","13.75518","0.26982"
"27558","165.31200","13.77617","0.27116"
"27600","165.56400","13.79721","0.27273"
"27642","165.81600","13.81814","0.27423"
"27684","166.06800","13.83918","0.27556"
"27726","166.32000","13.86017","0.27697"
"27768","166.57200","13.88116","0.27888"
"27810","166.82400","13.90220","0.28076"
"27852","167.07600","13.92319","0.28262"
"27894","167.32800","13.94424","0.28330"
"27936","167.58000","13.96522","0.28501"
"27978","167.83200","13.98621","0.28670"
"28020","168.08400","14.00713","0.28708"
"28062","168.33600","14.02824","0.28869"
"28104","168.58800","14.04916","0.28905"
"28146","168.84000","14.07021","0.29008"
"28188","169.09200","14.09114","0.13428"
"28230","169.34400","14.11224","0.13123"
"28272","169.59600","14.13323","0.13821"
"28314","169.84800","14.15416","0.13507"
"28356","170.10000","14.17514","0.13698"
"28398","170.35200","14.19619","0.13912"
"28440","170.60400","14.21723","0.13765"
"28482","170.85600","14.23816","0.14341"
"28524","171.10800","14.25920","0.13954"
"28566","171.36000","14.28019","0.14168"
"28608","171.61200","14.30124","0.14341"
"28650","171.86400","14.32216","0.14286"
"28692","172.11600","14.34321","0.14689"
"28734","172.36800","14.36414","0.14388"
"28776","172.62000","14.38518","0.14789"
"28818","172.87200","14.40617","0.14934"
"28860","173.12400","14.42721","0.14775"
"28902","173.37600","14.44814","0.15274"
"28944","173.62800","14.46925","0.15099"
"28986","173.88000","14.49023","0.15392"
"29028","174.13200","14.51122","0.15804"
"29070","174.38400","14.53220","0.15477"
"29112","174.63600","14.55313","0.16214"
"29154","174.88800","14.57418","0.16350"
"29196","175.14000","14.59516","0.16265"
"29238","175.39200","14.61621","0.16871"
"29280","175.64400","14.63714","0.16708"
"29322","175.89600","14.65818","0.17094"
"29364","176.14800","14.67917","0.17680"
"29406","176.40000","14.70021","0.17557"
"29448","176.65200","14.72114","0.18058"
"29490","176.90400","14.74224","0.18403"
"29532","177.15600","14.76317","0.18351"
"29574","177.40800","14.78422","0.18895"
"29616","177.66000","14.80520","0.18847"
"29658","177.91200","14.82625","0.19002"
"29700","178.16400","14.84718","0.19273"
"29742","178.41600","14.86816","0.19204"
"29784","178.66800","14.88921","0.19450"
"29826","178.92000","14.91020","0.19704"
"29868","179.17200","14.93124","0.19725"
"29910","179.42400","14.95211","0.19871"
"29952","179.67600","14.97321","0.19967"
"29994","179.92800","14.99414","0.20033"
"30036","180.18000","15.01518","0.20155"
"30078","180.43200","15.03617","0.20222"
"30120","180.68400","15.05716","0.20211"
"30162","180.93600","15.07820","0.20420"
"30204","181.18800","15.09925","0.20417"
"30246","181.44000","15.12018","0.20510"
"30288","181.69200","15.14116","0.20663"
"30330","181.94400","15.16221","0.20810"
"30372","182.19600","15.18319","0.20849"
"30414","182.44800","15.20418","0.21105"
"30456","182.70000","15.22517","0.21144"
"30498","182.95200","15.24615","0.21288"
"30540","183.20400","15.26714","0.21462"
"30582","183.45600","15.28818","0.21556"
"30624","183.70800","15.30917","0.21718"
"30666","183.96000","15.33022","0.21857"
"30708","184.21200","15.35114","0.21934"
"30750","184.46400","15.37219","0.21944"
"30792","184.71600","15.39317","0.19872"
"30834","184.96800","15.41428","0.19671"
"30876","185.22200","15.43533","0.19737"
"30918","185.47400","15.45637","0.19839"
"30960","185.72600","15.47736","0.19833"
"31002","185.97800","15.49840","0.20036"
"31044","186.23000","15.51939","0.20032"
"31086","186.48200","15.54032","0.20032"
"31128","186.73400","15.56136","0.20126"
"31170","186.98600","15.58235","0.20123"
"31212","187.23800","15.60340","0.20178"
"31254","187.49000","15.62432","0.20289"
"31296","187.74200","15.64543","0.20354"
"31338","187.99400","15.66635","0.20466"
"31380","188.24600","15.68740","0.20596"
"31422","188.49800","15.70832","0.20309"
"31464","188.75000","15.72931","0.20319"
"31506","189.00200","15.75030","0.20370"
"31548","189.25400","15.77134","0.20348"
"31590","189.50600","15.79233","0.20336"
"31632","189.75800","15.81337","0.20412"
"31674","190.01000","15.83436","0.20442"
"31716","190.26200","15.85529","0.20567"
"31758","190.51400","15.87633","0.20580"
"31800","190.76600","15.89732","0.20454"
"31842","191.01800","15.91836","0.20522"
"31884","191.27000","15.93935","0.20423"
"31926","191.52200","15.96034","0.20249"
"31968","191.77400","15.98132","0.20169"
"32010","192.02600","16.00231","0.20246"
"32052","192.27800","16.02336","0.20256"
"32094","192.53000","16.04440","0.06704"
"32136","192.78200","16.06533","0.06929"
"32178","193.03400","16.08643","0.06938"
"32220","193.28600","16.10736","0.07017"
"32262","193.53800","16.12841","0.07074"
"32304","193.79000","16.14933","0.07192"
"32346","194.04200","16.17038","0.07169"
"32388","194.29400","16.19136","0.07021"
"32430","194.54600","16.21235","0.06866"
"32472","194.79800","16.23340","0.06968"
"32514","195.05000","16.25432","0.07070"
"32556","195.30200","16.27537","0.07097"
"32598","195.55400","16.29635","0.07245"
"32640","195.80600","16.31740","0.07467"
"32682","196.05800","16.33833","0.07307"
"32724","196.31000","16.35937","0.07350"
"32766","196.56200","16.38030","0.07362"
"32808","196.81400","16.40134","0.07469"
"32850","197.06600","16.42233","0.07540"
"32892","197.31800","16.44338","0.07437"
"32934","197.57000","16.46442","0.04600"
"32976","197.82200","16.48535","0.04650"
"33018","198.07400","16.50633","0.04087"
"33060","198.32600","16.52738","0.03696"
"33102","198.57800","16.54843","0.04382"
"33144","198.83000","16.56935","0.03994"
"33186","199.08200","16.59034","0.04466"
"33228","199.33400","16.61133","0.04198"
"33270","199.58600","16.63237","0.04479"
"33312","199.83800","16.65336","0.04482"
"33354","200.09000","16.67434","0.04597"
"33396","200.34200","16.69533","0.04767"
"33438","200.59400","16.71638","0.04676"
"33480","200.84600","16.73736","0.04933"
"33522","201.09800","16.75835","0.04805"
"33564","201.35000","16.77934","0.05032"
"33606","201.60200","16.80038","0.05025"
"33648","201.85400","16.82142","0.05099"
"33690","202.10600","16.84235","0.05293"
"33732","202.35800","16.86334","0.05058"
"33774","202.61000","16.88438","0.05284"
"33816","202.86200","16.90537","0.05162"
"33858","203.11400","16.92636","0.05177"
"33900","203.36600","16.94734","0.05263"
"33942","203.61800","16.96827","0.05174"
"33984","203.87000","16.98943","0.05319"
"34026","204.12200","17.01036","0.05243"
"34068","204.37400","17.03141","0.05320"
"34110","204.62600","17.05233","0.05397"
"34152","204.87800","17.07338","0.05288"
"34194","205.13000","17.09431","0.05467"
"34236","205.38200","17.11535","0.05517"
"34278","205.63400","17.13640","0.05606"
"34320","205.88600","17.15738","0.05688"
"34362","206.13800","17.17837","0.05721"
"34404","206.39000","17.19936","0.05975"
"34446","206.64200","17.22040","0.05872"
"34488","206.89400","17.24133","0.06013"
"34530","207.14600","17.26237","0.05764"
"34572","207.39800","17.28330","0.05824"
"34614","207.65000","17.30435","0.05972"
"34656","207.90200","17.32533","0.06045"
"34698","208.15400","17.34638","0.06172"
"34740","208.40600","17.36736","0.06178"
"34782","208.65800","17.38841","0.06333"
"34824","208.91000","17.40934","0.06414"
"34866","209.16200","17.43038","0.06317"
"34908","209.41400","17.45131","0.06106"
"34950","209.66600","17.47235","0.06086"
"34992","209.91800","17.49340","0.06011"
"35034","210.17000","17.51439","0.05855"
"35076","210.42200","17.53537","0.05588"
"35118","210.67400","17.55636","0.05470"
"35160","210.92600","17.57734","0.05441"
"35202","211.17800","17.59833","0.05471"
"35244","211.43000","17.61938","0.05455"
"35286","211.68200","17.64024","0.05376"
"35328","211.93400","17.66135","0.05366"
"35370","212.18600","17.68234","0.05388"
"35412","212.43800","17.70338","0.05350"
"35454","212.69000","17.72437","0.05326"
"35496","212.94200","17.74541","0.05362"
"35538","213.19400","17.76634","0.05396"
"35580","213.44600","17.78733","0.05399"
"35622","213.69800","17.80837","0.05073"
"35664","213.95000","17.82942","0.04877"
"35706","214.20200","17.85040","0.04861"
"35748","214.45400","17.87133","0.04864"
"35790","214.70600","17.89238","0.04867"
"35832","214.95800","17.91336","0.04889"
"35874","215.21000","17.93441","0.04900"
"35916","215.46200","17.95527","0.04908"
"35958","215.71400","17.97638","0.04862"
"36000","215.96600","17.99731","0.04861"
"36042","216.21800","18.01835","0.04801"
"36084","216.47000","18.03934","0.04789"
"36126","216.72200","18.06038","0.04799"
"36168","216.97400","18.08137","0.04749"
"36210","217.22600","18.10242","0.04761"
"36252","217.47800","18.12328","0.04739"
"36294","217.73000","18.14433","0.04714"
"36336","217.98200","18.16532","0.03802"
"36378","218.23400","18.18636","0.03612"
"36420","218.48600","18.20741","0.03680"
"36462","218.73800","18.22833","0.03718"
"36504","218.99000","18.24932","0.03653"
"36546","219.24200","18.27037","0.03803"
"36588","219.49400","18.29135","0.03762"
"36630","219.74600","18.31234","0.03858"
"36672","219.99800","18.33339","0.03901"
"36714","220.25000","18.35431","0.03945"
"36756","220.50200","18.37542","0.03949"
"36798","220.75400","18.39634","0.03902"
"36840","221.00600","18.41739","0.03824"
"36882","221.25800","18.43838","0.03910"
"36924","221.51000","18.45936","0.03932"
"36966","221.76200","18.48035","0.03973"
"37008","222.01400","18.50133","0.03918"
"37050","222.26600","18.52238","0.03931"
"37092","222.51800","18.54336","0.03938"
"37134","222.77000","18.56435","0.03926"
"37176","223.02200","18.58534","0.03908"
"37218","223.27400","18.60638","0.03867"
"37260","223.52600","18.62731","0.03795"
"37302","223.77800","18.64836","0.03833"
"37344","224.03000","18.66934","0.03809"
"37386","224.28200","18.69039","0.03809"
"37428","224.53400","18.71137","0.03824"
"37470","224.78600","18.73242","0.03783"
"37512","225.03800","18.75335","0.03747"
"37554","225.29000","18.77439","0.03823"
"37596","225.54200","18.79538","0.03736"
"37638","225.79400","18.81636","0.03674"
"37680","226.04600","18.83729","0.03710"
"37722","226.29800","18.85834","0.03660"
"37764","226.55000","18.87938","0.03743"
"37806","226.80200","18.90031","0.03746"
"37848","227.05400","18.92135","0.03766"
"37890","227.30600","18.94234","0.03782"
"37932","227.55800","18.96339","0.03843"
"37974","227.81000","18.98431","0.03858"
"38016","228.06200","19.00536","0.03894"
"38058","228.31400","19.02629","0.03890"
"38100","228.56600","19.04745","0.03909"
"38142","228.81800","19.06838","0.03967"
"38184","229.07000","19.08942","0.03934"
"38226","229.32200","19.11035","0.03979"
"38268","229.57400","19.13140","0.03997"
"38310","229.82600","19.15232","0.04039"
"38352","230.07800","19.17331","0.04098"
"38394","230.33000","19.19435","0.04123"
"38436","230.58200","19.21540","0.04177"
"38478","230.83400","19.23645","0.04170"
"38520","231.08600","19.25731","0.04185"
"38562","231.33800","19.27836","0.04214"
"38604","231.59000","19.29934","0.04256"
"38646","231.84200","19.32039","0.04229"
"38688","232.09400","19.34132","0.04280"
"38730","232.34600","19.36230","0.04371"
"38772","232.59800","19.38335","0.04338"
"38814","232.85000","19.40439","0.04368"
"38856","233.10200","19.42538","0.04386"
"38898","233.35400","19.44637","0.04433"
"38940","233.60600","19.46735","0.04471"
"38982","233.85800","19.48840","0.04434"
"39024","234.11000","19.50933","0.04494"
"39066","234.36200","19.53037","0.04454"
"39108","234.61400","19.55136","0.04517"
"39150","234.86600","19.57234","0.04487"
"39192","235.11800","19.59339","0.04496"
"39234","235.37000","19.61432","0.01437"
"39276","235.62200","19.63536","0.02108"
"39318","235.87400","19.65635","0.01943"
"39360","236.12600","19.67733","0.02001"
"39402","236.37800","19.69832","0.02012"
"39444","236.63000","19.71937","0.02100"
"39486","236.88200","19.74035","0.02033"
"39528","237.13400","19.76140","0.02004"
"39570","237.38600","19.78232","0.02359"
"39612","237.63800","19.80337","0.01944"
"39654","237.89000","19.82441","0.02148"
"39696","238.14200","19.84534","0.02245"
"39738","238.39400","19.86633","0.02135"
"39780","238.64600","19.88737","0.01997"
"39822","238.89800","19.90836","0.02316"
"39864","239.15000","19.92929","0.02194"
"39906","239.40200","19.95039","0.02196"
"39948","239.65400","19.97126","0.02326"
"39990","239.90600","19.99242","0.02253"
"40032","240.15800","20.01335","0.02235"
"40074","240.41000","20.03440","0.02382"
"40116","240.66200","20.05538","0.02418"
"40158","240.91400","20.07643","0.02331"
"40200","241.16600","20.09735","0.02480"
"40242","241.41800","20.11834","0.02458"
"40284","241.67000","20.13939","0.02440"
"40326","241.92200","20.16043","0.02533"
"40368","242.17400","20.18136","0.02486"
"40410","242.42600","20.20234","0.02518"
"40452","242.67800","20.22339","0.02582"
"40494","242.93000","20.24432","0.02665"
"40536","243.18200","20.26536","0.02547"
"40578","243.43400","20.28629","0.02685"
"40620","243.68600","20.30734","0.02639"
"40662","243.93800","20.32838","0.02678"
"40704","244.19000","20.34937","0.02727"
"40746","244.44200","20.37036","0.02763"
"40788","244.69400","20.39146","0.02777"
"40830","244.94600","20.41233","0.02817"
"40872","245.19800","20.43343","0.02837"
"40914","245.45000","20.45430","0.02869"
"40956","245.70200","20.47534","0.02975"
"40998","245.95400","20.49639","0.02893"
"41040","246.20600","20.51738","0.02921"
"41082","246.45800","20.53836","0.02926"
"41124","246.71000","20.55929","0.03078"
"41166","246.96200","20.58039","0.03032"
"41208","247.21400","20.60138","0.03087"
"41250","247.46600","20.62237","0.03098"
"41292","247.71800","20.64329","0.03154"
"41334","247.97000","20.66434","0.03150"
"41376","248.22200","20.68532","0.03202"
"41418","248.47400","20.70637","0.03236"
"41460","248.72600","20.72736","0.03274"
"41502","248.97800","20.74840","0.03308"
"41544","249.23000","20.76933","0.03314"
"41586","249.48200","20.79038","0.03355"
"41628","249.73400","20.81136","0.03368"
"41670","249.98600","20.83235","0.03406"
"41712","250.23800","20.85340","0.03455"
"41754","250.49000","20.87432","0.03473"
"41796","250.74200","20.89536","0.03517"
"41838","250.99400","20.91629","0.03550"
"41880","251.24600","20.93740","0.03566"
"41922","251.49800","20.95832","0.03616"
"41964","251.75000","20.97937","0.03669"
"42006","252.00200","21.00030","0.03680"
"42048","252.25400","21.02134","0.03705"
"42090","252.50600","21.04233","0.03687"
"42132","252.75800","21.06337","0.03722"
"42174","253.01000","21.08430","0.03782"
"42216","253.26200","21.10541","0.03805"
"42258","253.51400","21.12639","0.03829"
"42300","253.76600","21.14738","0.03864"
"42342","254.01800","21.16830","0.03881"
"42384","254.27000","21.18941","0.03918"
"42426","254.52200","21.21040","0.03996"
"42468","254.77400","21.23132","0.04019"
"42510","255.02600","21.25237","0.04070"
"42552","255.27800","21.27330","0.04105"
"42594","255.53000","21.29440","0.04118"
"42636","255.78200","21.31533","0.04178"
"42678","256.03400","21.33637","0.04246"
"42720","256.28600","21.35730","0.04191"
"42762","256.53800","21.37840","0.04235"
"42804","256.79000","21.39933","0.04248"
"42846","257.04200","21.42038","0.04325"
"42888","257.29400","21.44136","0.04390"
"42930","257.54600","21.46235","0.04390"
"42972","257.79800","21.48339","0.04455"
"43014","258.05000","21.50432","0.04490"
"43056","258.30200","21.52543","0.04516"
"43098","258.55400","21.54635","0.04564"
"43140","258.80600","21.56734","0.04567"
"43182","259.05800","21.58827","0.04620"
"43224","259.31000","21.60937","0.04637"
"43266","259.56200","21.63036","0.04694"
"43308","259.81400","21.65140","0.04732"
"43350","260.06600","21.67239","0.04774"
"43392","260.31800","21.69344","0.04806"
"43434","260.57000","21.71436","0.04852"
"43476","260.82200","21.73541","0.04899"
"43518","261.07400","21.75634","0.04970"
"43560","261.32600","21.77738","0.04976"
"43602","261.57800","21.79837","0.05019"
"43644","261.83000","21.81941","0.05105"
"43686","262.08200","21.84034","0.05137"
"43728","262.33400","21.86133","0.05141"
"43770","262.58600","21.88243","0.05250"
"43812","262.83800","21.90336","0.05285"
"43854","263.09000","21.92434","0.05349"
"43896","263.34200","21.94533","0.05390"
"43938","263.59400","21.96638","0.05487"
"43980","263.84600","21.98736","0.05563"
"44022","264.09800","22.00835","0.05616"
"44064","264.35000","22.02934","0.05712"
"44106","264.60200","22.05044","0.05753"
"44148","264.85400","22.07137","0.05856"
"44190","265.10600","22.09235","0.05922"
"44232","265.35800","22.11334","0.06059"
"44274","265.61000","22.13438","0.06136"
"44316","265.86200","22.15543","0.06260"
"44358","266.11400","22.17636","0.06351"
"44400","266.36600","22.19734","0.06508"
"44442","266.61800","22.21833","0.06556"
"44484","266.87000","22.23938","0.06682"
"44526","267.12200","22.26030","0.06880"
"44568","267.37400","22.28141","0.06953"
"44610","267.62600","22.30233","0.07059"
"44652","267.87800","22.32338","0.07187"
"44694","268.13000","22.34437","0.07299"
"44736","268.38200","22.36535","0.07411"
"44778","268.63400","22.38634","0.07576"
"44820","268.88600","22.40738","0.07564"
"44862","269.13800","22.42831","0.07802"
"44904","269.39000","22.44936","0.07857"
"44946","269.64200","22.47034","0.08033"
"44988","269.89400","22.49139","0.08087"
"45030","270.14600","22.51237","0.08256"
"45072","270.39800","22.53336","0.08300"
"45114","270.65000","22.55441","0.08426"
"45156","270.90200","22.57539","0.08516"
"45198","271.15400","22.59638","0.08681"
"45240","271.40600","22.61730","0.08722"
"45282","271.65800","22.63835","0.08850"
"45324","271.91000","22.65934","0.08950"
"45366","272.16200","22.68044","0.09040"
"45408","272.41400","22.70131","0.09141"
"45450","272.66600","22.72242","0.09270"
"45492","272.91800","22.74334","0.09319"
"45534","273.17000","22.76433","0.09376"
"45576","273.42200","22.78531","0.09431"
"45618","273.67400","22.80636","0.09510"
"45660","273.92600","22.82741","0.09544"
"45702","274.17800","22.84839","0.09558"
"45744","274.43000","22.86938","0.09601"
"45786","274.68200","22.89030","0.09679"
"45828","274.93400","22.91141","0.09768"
"45870","275.18600","22.93233","0.09766"
"45912","275.43800","22.95338","0.09858"
"45954","275.69000","22.97431","0.09885"
"45996","275.94200","22.99541","0.10055"
"46038","276.19400","23.01640","0.10145"
"46080","276.44600","23.03739","0.10282"
"46122","276.69800","23.05837","0.10435"
"46164","276.95000","23.07936","0.10502"
"46206","277.20200","23.10040","0.10602"
"46248","277.45400","23.12139","0.10789"
"46290","277.70600","23.14231","0.10984"
"46332","277.95800","23.16330","0.11166"
"46374","278.21000","23.18441","0.11256"
"46416","278.46200","23.20533","0.11338"
"46458","278.71400","23.22638","0.11501"
"46500","278.96600","23.24730","0.11637"
"46542","279.21800","23.26841","0.11843"
"46584","279.47000","23.28928","0.11964"
"46626","279.72200","23.31033","0.12107"
"46668","279.97400","23.33131","0.12222"
"46710","280.22600","23.35242","0.12323"
"46752","280.47800","23.37334","0.12404"
"46794","280.73000","23.39439","0.12549"
"46836","280.98200","23.41537","0.12699"
"46878","281.23400","23.43642","0.12715"
"46920","281.48600","23.45735","0.12895"
"46962","281.73800","23.47833","0.12999"
"47004","281.99000","23.49938","0.13068"
"47046","282.24200","23.52031","0.13210"
"47088","282.49400","23.54141","0.13297"
"47130","282.74600","23.56228","0.13368"
"47172","282.99800","23.58338","0.13409"
"47214","283.25000","23.60431","0.13474"
"47256","283.50200","23.62542","0.13532"
"47298","283.75400","23.64634","0.13610"
"47340","284.00600","23.66733","0.13678"
"47382","284.25800","23.68831","0.13738"
"47424","284.51000","23.70936","0.13831"
"47466","284.76200","23.73034","0.13849"
"47508","285.01400","23.75139","0.13921"
"47550","285.26600","23.77238","0.13989"
"47592","285.51800","23.79336","0.14064"
"47634","285.77000","23.81435","0.14079"
"47676","286.02200","23.83534","0.14166"
"47718","286.27400","23.85638","0.14254"
"47760","286.52600","23.87737","0.14291"
"47802","286.77800","23.89835","0.14389"
"47844","287.03000","23.91928","0.14456"
"47886","287.28200","23.94039","0.14525"
"47928","287.53400","23.96131","0.14579"
"47970","287.78600","23.98236","0.14628"
"48012","288.03800","24.00340","0.14721"
"48054","288.29000","24.02439","0.14841"
"48096","288.54200","24.04532","0.14951"
"48138","288.79400","24.06642","0.15044"
"48180","289.04600","24.08735","0.15206"
"48222","289.29800","24.10839","0.15261"
"48264","289.55000","24.12944","0.15402"
"48306","289.80200","24.15037","0.15530"
"48348","290.05400","24.17135","0.15743"
"48390","290.30600","24.19234","0.15879"
"48432","290.55800","24.21338","0.16077"
"48474","290.81000","24.23431","0.16205"
"48516","291.06200","24.25536","0.16469"
"48558","291.31400","24.27634","0.16613"
"48600","291.56600","24.29745","0.16871"
"48642","291.81800","24.31832","0.16932"
"48684","292.07000","24.33936","0.17247"
"48726","292.32200","24.36035","0.17466"
"48768","292.57400","24.38139","0.17568"
"48810","292.82600","24.40238","0.17794"
"48852","293.07800","24.42337","0.17887"
"48894","293.33000","24.44441","0.18185"
"48936","293.58200","24.46534","0.18424"
"48978","293.83400","24.48639","0.18552"
"49020","294.08600","24.50737","0.18706"
"49062","294.33800","24.52836","0.18864"
"49104","294.59000","24.54935","0.05720"
"49146","294.84200","24.57039","0.05901"
"49188","295.09400","24.59126","0.07859"
"49230","295.34600","24.61236","0.05241"
"49272","295.59800","24.63335","0.06119"
"49314","295.85000","24.65439","0.07430"
"49356","296.10200","24.67532","0.06482"
"49398","296.35400","24.69642","0.06587"
"49440","296.60600","24.71735","0.06972"
"49482","296.85800","24.73846","0.06548"
"49524","297.11000","24.75932","0.07635"
"49566","297.36200","24.78037","0.06843"
"49608","297.61400","24.80136","0.07291"
"49650","297.86600","24.82240","0.07504"
"49692","298.11800","24.84339","0.07092"
"49734","298.37000","24.86432","0.07853"
"49776","298.62200","24.88536","0.07378"
"49818","298.87400","24.90635","0.08200"
"49860","299.12600","24.92739","0.07606"
"49902","299.37800","24.94826","0.08035"
"49944","299.63000","24.96936","0.07846"
"49986","299.88200","24.99035","0.08146"
"50028","300.13400","25.01140","0.08336"
"50070","300.38600","25.03232","0.08370"
"50112","300.63800","25.05337","0.08488"
"50154","300.89000","25.07442","0.08558"
"50196","301.14200","25.09534","0.08513"
"50238","301.39400","25.11639","0.08736"
"50280","301.64600","25.13737","0.08480"
"50322","301.89800","25.15836","0.08974"
"50364","302.15000","25.17935","0.08655"
"50406","302.40200","25.20033","0.09124"
"50448","302.65400","25.22132","0.08938"
"50490","302.90600","25.24242","0.09077"
"50532","303.15800","25.26335","0.09148"
"50574","303.41000","25.28434","0.09043"
"50616","303.66200","25.30532","0.09340"
"50658","303.91400","25.32637","0.09105"
"50700","304.16600","25.34735","0.09464"
"50742","304.41800","25.36834","0.09240"
"50784","304.67000","25.38927","0.09505"
"50826","304.92200","25.41043","0.09331"
"50868","305.17400","25.43136","0.09487"
"50910","305.42600","25.45240","0.09502"
"50952","305.67800","25.47339","0.09470"
"50994","305.93000","25.49438","0.09642"
"51036","306.18200","25.51542","0.09527"
"51078","306.43400","25.53635","-0.00952"
"51120","306.68600","25.55733","0.00672"
"51162","306.93800","25.57832","0.01033"
"51204","307.19000","25.59943","0.00849"
"51246","307.44200","25.62029","0.00520"
"51288","307.69400","25.64134","0.00586"
"51330","307.94600","25.66232","0.00765"
"51372","308.19800","25.68337","0.00572"
"51414","308.45000","25.70430","0.00591"
"51456","308.70200","25.72540","0.00786"
"51498","308.95400","25.74633","0.00594"
"51540","309.20600","25.76738","0.00620"
"51568","309.37200","25.78119","0.00713"