File: Trajectories_together/170226_2Specimen_RawData_10.csv
"","V1","V2","V3"
"1","End date","2/26/2017",""
"2","Specimen label","7AG_53",""
"3","Maximum Load","0.03320","N"
"4","Time","Extension","Load"
"5","(s)","(mm)","(N)"
"6","0.00000","0.00000","-0.00055"
"69","0.37800","0.03163","0.00146"
"132","0.75600","0.06326","0.00179"
"195","1.13400","0.09477","0.00290"
"258","1.51200","0.12616","0.00407"
"321","1.89000","0.15766","0.00501"
"384","2.26800","0.18917","0.00482"
"447","2.64600","0.22068","0.00555"
"510","3.02400","0.25219","0.00626"
"573","3.40200","0.28370","0.00645"
"636","3.78000","0.31521","0.00751"
"699","4.15800","0.34660","0.00747"
"762","4.53600","0.37817","0.00809"
"825","4.91400","0.40974","0.00692"
"888","5.29200","0.44119","0.00811"
"951","5.67000","0.47270","0.00787"
"1014","6.04800","0.50421","0.00794"
"1077","6.42600","0.53565","0.00862"
"1140","6.80400","0.56716","0.00942"
"1203","7.18200","0.59873","0.00943"
"1266","7.56000","0.63018","0.01043"
"1329","7.93800","0.66169","0.01052"
"1392","8.31600","0.69314","0.01104"
"1455","8.69400","0.72465","0.00962"
"1518","9.07200","0.75616","0.01002"
"1581","9.45000","0.78767","0.01038"
"1644","9.82800","0.81924","0.01081"
"1707","10.20600","0.85075","0.01102"
"1770","10.58400","0.88213","0.01143"
"1833","10.96200","0.91370","0.01145"
"1896","11.34000","0.94521","0.01196"
"1959","11.71800","0.97660","0.01258"
"2022","12.09600","1.00823","0.01308"
"2085","12.47400","1.03968","0.01297"
"2148","12.85200","1.07113","0.01331"
"2211","13.23000","1.10258","0.01352"
"2274","13.60800","1.13427","0.01364"
"2337","13.98600","1.16572","0.01411"
"2400","14.36400","1.19717","0.01402"
"2463","14.74200","1.22867","0.01425"
"2526","15.12000","1.26024","0.01472"
"2589","15.49800","1.29169","0.01453"
"2652","15.87600","1.32314","0.01474"
"2715","16.25400","1.35471","0.01524"
"2778","16.63200","1.38622","0.01561"
"2841","17.01000","1.41773","0.01572"
"2904","17.38800","1.44924","0.01558"
"2967","17.76600","1.48069","0.01551"
"3030","18.14400","1.51214","0.01589"
"3093","18.52200","1.54371","0.01589"
"3156","18.90000","1.57522","0.01601"
"3219","19.27800","1.60666","0.01543"
"3282","19.65600","1.63817","0.01576"
"3345","20.03400","1.66968","0.01568"
"3408","20.41200","1.70119","0.01566"
"3471","20.79000","1.73264","0.01462"
"3534","21.16800","1.76421","0.01347"
"3597","21.54600","1.79572","0.01320"
"3660","21.92400","1.82711","0.01345"
"3723","22.30200","1.85868","0.01327"
"3786","22.68000","1.89025","0.01344"
"3849","23.05800","1.92164","0.01356"
"3912","23.43600","1.95314","0.01412"
"3975","23.81400","1.98471","0.01437"
"4038","24.19200","2.01616","0.01423"
"4101","24.57000","2.04767","0.01376"
"4164","24.94800","2.07924","0.01353"
"4227","25.32600","2.11069","0.01360"
"4290","25.70400","2.14220","0.01371"
"4353","26.08200","2.17365","0.01350"
"4416","26.46000","2.20522","0.01344"
"4479","26.83800","2.23667","0.01348"
"4542","27.21600","2.26818","0.01366"
"4605","27.59400","2.29968","0.01382"
"4668","27.97200","2.33119","0.01372"
"4731","28.35000","2.36264","0.01400"
"4794","28.72800","2.39421","0.01436"
"4857","29.10600","2.42572","0.01446"
"4920","29.48400","2.45717","0.01434"
"4983","29.86200","2.48868","0.01408"
"5046","30.24000","2.52019","0.01467"
"5109","30.61800","2.55170","0.01536"
"5172","30.99600","2.58321","0.01543"
"5235","31.37400","2.61472","0.01518"
"5298","31.75200","2.64622","0.01545"
"5361","32.13000","2.67761","0.01553"
"5424","32.50800","2.70918","0.01588"
"5487","32.88600","2.74069","0.01598"
"5550","33.26400","2.77214","0.01617"
"5613","33.64200","2.80365","0.01586"
"5676","34.02000","2.83516","0.01640"
"5739","34.39800","2.86673","0.01633"
"5802","34.77600","2.89818","0.01684"
"5865","35.15400","2.92969","0.01673"
"5928","35.53200","2.96120","0.01752"
"5991","35.91000","2.99271","0.01719"
"6054","36.28800","3.02415","0.01771"
"6117","36.66600","3.05566","0.01788"
"6180","37.04400","3.08723","0.01833"
"6243","37.42200","3.11862","0.01798"
"6306","37.80000","3.15019","0.01753"
"6369","38.17800","3.18170","0.01807"
"6432","38.55600","3.21315","0.01807"
"6495","38.93400","3.24472","0.01816"
"6558","39.31200","3.27623","0.01793"
"6621","39.69000","3.30762","0.01894"
"6684","40.06800","3.33925","0.01866"
"6747","40.44600","3.37069","0.01876"
"6810","40.82400","3.40214","0.01910"
"6873","41.20200","3.43365","0.01896"
"6936","41.58000","3.46522","0.01917"
"6999","41.95800","3.49667","0.01929"
"7062","42.33600","3.52818","0.01990"
"7125","42.71400","3.55969","0.01977"
"7188","43.09200","3.59126","0.01902"
"7251","43.47000","3.62265","0.01992"
"7314","43.84800","3.65416","0.01981"
"7377","44.22600","3.68573","0.02018"
"7440","44.60400","3.71718","0.02017"
"7503","44.98200","3.74868","0.02011"
"7566","45.36000","3.78019","0.02035"
"7629","45.73800","3.81170","0.02090"
"7692","46.11600","3.84315","0.02081"
"7755","46.49400","3.87472","0.02113"
"7818","46.87200","3.90623","0.02169"
"7881","47.25000","3.93768","0.02201"
"7944","47.62800","3.96919","0.02189"
"8007","48.00600","4.00070","0.02163"
"8070","48.38400","4.03227","0.02059"
"8133","48.76200","4.06366","0.02104"
"8196","49.14000","4.09522","0.02063"
"8259","49.51800","4.12673","0.02086"
"8322","49.89600","4.15812","0.02088"
"8385","50.27400","4.18969","0.02148"
"8448","50.65200","4.22120","0.02131"
"8511","51.03000","4.25265","0.02162"
"8574","51.40800","4.28422","0.02105"
"8637","51.78600","4.31567","0.02098"
"8700","52.16400","4.34718","0.02097"
"8763","52.54200","4.37869","0.02194"
"8826","52.92000","4.41020","0.02142"
"8889","53.29800","4.44170","0.02171"
"8952","53.67600","4.47315","0.02183"
"9015","54.05400","4.50466","0.02237"
"9078","54.43200","4.53623","0.02217"
"9141","54.81000","4.56768","0.02287"
"9204","55.18800","4.59919","0.02301"
"9267","55.56600","4.63070","0.02151"
"9330","55.94400","4.66221","0.02262"
"9393","56.32200","4.69360","0.02257"
"9456","56.70000","4.72529","0.02230"
"9519","57.07800","4.75674","0.02301"
"9582","57.45600","4.78813","0.02306"
"9645","57.83400","4.81975","0.02301"
"9708","58.21200","4.85114","0.02321"
"9771","58.59000","4.88265","0.02282"
"9834","58.96800","4.91416","0.02351"
"9897","59.34600","4.94573","0.02382"
"9960","59.72400","4.97724","0.02365"
"10023","60.10200","5.00863","0.02397"
"10086","60.48000","5.04020","0.02405"
"10149","60.85800","5.07177","0.02451"
"10212","61.23600","5.10316","0.02458"
"10275","61.61400","5.13473","0.02445"
"10338","61.99200","5.16623","0.02475"
"10401","62.37000","5.19774","0.02527"
"10464","62.74800","5.22919","0.02529"
"10527","63.12600","5.26070","0.02512"
"10590","63.50400","5.29215","0.02529"
"10653","63.88200","5.32366","0.02527"
"10716","64.26000","5.35517","0.02559"
"10779","64.63800","5.38674","0.02532"
"10842","65.01600","5.41819","0.02555"
"10905","65.39400","5.44970","0.02584"
"10968","65.77200","5.48127","0.02585"
"11031","66.15000","5.51265","0.02580"
"11094","66.52800","5.54422","0.02583"
"11157","66.90600","5.57573","0.02656"
"11220","67.28400","5.60724","0.02602"
"11283","67.66200","5.63863","0.02704"
"11346","68.04000","5.67026","0.02678"
"11409","68.41800","5.70165","0.02704"
"11472","68.79600","5.73322","0.02753"
"11535","69.17400","5.76473","0.02741"
"11598","69.55200","5.79618","0.02805"
"11661","69.93000","5.82769","0.02826"
"11724","70.30800","5.85920","0.02815"
"11787","70.68600","5.89070","0.02782"
"11850","71.06400","5.92221","0.02805"
"11913","71.44200","5.95360","0.02681"
"11976","71.82000","5.98517","0.02800"
"12039","72.19800","6.01674","0.02830"
"12102","72.57600","6.04813","0.02771"
"12165","72.95400","6.07970","0.02839"
"12228","73.33200","6.11121","0.02793"
"12291","73.71000","6.14266","0.02826"
"12354","74.08800","6.17417","0.02797"
"12417","74.46600","6.20568","0.02867"
"12480","74.84400","6.23724","0.02786"
"12543","75.22200","6.26869","0.02840"
"12606","75.60000","6.30020","0.02822"
"12669","75.97800","6.33165","0.02850"
"12732","76.35600","6.36322","0.02825"
"12795","76.73400","6.39461","0.02864"
"12858","77.11200","6.42624","0.02810"
"12921","77.49000","6.45769","0.02896"
"12984","77.86800","6.48914","0.02868"
"13047","78.24600","6.52071","0.02924"
"13110","78.62400","6.55222","0.02931"
"13173","79.00200","6.58366","0.02974"
"13236","79.38000","6.61517","0.02946"
"13299","79.75800","6.64668","0.02998"
"13362","80.13600","6.67825","0.02964"
"13425","80.51400","6.70970","0.03038"
"13488","80.89200","6.74121","0.03016"
"13551","81.27000","6.77272","0.03089"
"13614","81.64800","6.80417","0.03078"
"13677","82.02600","6.83574","0.03125"
"13740","82.40400","6.86719","0.03163"
"13803","82.78200","6.89864","0.03164"
"13866","83.16000","6.93020","0.03132"
"13929","83.53800","6.96171","0.03190"
"13992","83.91600","6.99316","0.03183"
"14055","84.29400","7.02461","0.03205"
"14118","84.67200","7.05624","0.03229"
"14181","85.05000","7.08769","0.03258"
"14244","85.42800","7.11914","0.03274"
"14307","85.80600","7.15071","0.03318"
"14370","86.18400","7.18216","0.00287"
"14433","86.56200","7.21373","0.00362"
"14496","86.94000","7.24518","0.00348"
"14559","87.31800","7.27668","0.00348"
"14622","87.69600","7.30819","0.00410"
"14685","88.07400","7.33964","0.00245"
"14748","88.45200","7.37121","0.00240"
"14811","88.83000","7.40278","0.00286"
"14874","89.20800","7.43417","0.00235"
"14937","89.58600","7.46568","0.00166"
"15000","89.96400","7.49719","0.00253"
"15063","90.34200","7.52870","0.00232"
"15126","90.72000","7.56015","0.00260"
"15189","91.09800","7.59172","0.00274"
"15252","91.47600","7.62323","0.00252"
"15315","91.85400","7.65468","0.00308"
"15378","92.23200","7.68618","0.00333"
"15441","92.61000","7.71775","0.00337"
"15504","92.98800","7.74914","0.00301"
"15567","93.36600","7.78065","0.00354"
"15630","93.74400","7.81222","0.00359"
"15693","94.12200","7.84367","0.00392"
"15756","94.50000","7.87518","0.00345"
"15819","94.87800","7.90675","0.00390"
"15882","95.25600","7.93820","0.00424"
"15945","95.63400","7.96965","0.00368"
"16008","96.01200","8.00121","0.00405"
"16071","96.39000","8.03272","0.00400"
"16134","96.76800","8.06417","0.00408"
"16197","97.14600","8.09568","0.00387"
"16260","97.52400","8.12719","0.00394"
"16323","97.90200","8.15870","0.00427"
"16386","98.28000","8.19015","0.00451"
"16449","98.65800","8.22172","0.00520"
"16512","99.03600","8.25323","0.00560"
"16575","99.41400","8.28462","0.00506"
"16638","99.79200","8.31619","0.00398"
"16701","100.17000","8.34775","0.00445"
"16764","100.54800","8.37908","0.00414"
"16827","100.92600","8.41065","0.00472"
"16890","101.30400","8.44222","0.00508"
"16953","101.68200","8.47367","0.00453"
"17016","102.06000","8.50518","0.00462"
"17079","102.43800","8.53669","0.00509"
"17142","102.81600","8.56826","0.00445"
"17205","103.19400","8.59971","0.00527"
"17268","103.57200","8.63116","0.00483"
"17331","103.95000","8.66273","0.00451"
"17394","104.32800","8.69423","0.00116"
"17457","104.70600","8.72568","0.00068"
"17520","105.08400","8.75725","0.00115"
"17583","105.46200","8.78870","0.00219"
"17646","105.84000","8.82015","0.00155"
"17709","106.21800","8.85166","0.00140"
"17772","106.59600","8.88323","0.00111"
"17835","106.97400","8.91468","0.00117"
"17898","107.35200","8.94619","0.00170"
"17961","107.73000","8.97764","0.00153"
"18024","108.10800","9.00921","0.00188"
"18087","108.48600","9.04066","0.00173"
"18150","108.86400","9.07222","0.00198"
"18213","109.24200","9.10373","0.00209"
"18276","109.62000","9.13512","0.00271"
"18339","109.99800","9.16669","0.00236"
"18402","110.37600","9.19820","0.00261"
"18465","110.75400","9.22965","0.00162"
"18528","111.13200","9.26116","0.00180"
"18591","111.51000","9.29273","0.00146"
"18654","111.88800","9.32418","0.00124"
"18717","112.26600","9.35563","0.00211"
"18780","112.64400","9.38720","0.00242"
"18843","113.02200","9.41864","0.00206"
"18906","113.40000","9.45015","0.00223"
"18969","113.77800","9.48172","0.00287"
"19032","114.15600","9.51323","0.00236"
"19095","114.53400","9.54468","0.00251"
"19158","114.91200","9.57613","0.00287"
"19221","115.29000","9.60770","0.00301"
"19284","115.66800","9.63921","0.00255"
"19347","116.04600","9.67066","0.00360"
"19410","116.42400","9.70223","0.00366"
"19473","116.80200","9.73374","0.00265"
"19536","117.18000","9.76513","0.00357"
"19599","117.55800","9.79669","0.00299"
"19662","117.93600","9.82820","0.00334"
"19725","118.31400","9.85971","0.00270"
"19788","118.69200","9.89116","0.00326"
"19851","119.07000","9.92273","0.00292"
"19914","119.44800","9.95418","0.00329"
"19977","119.82600","9.98569","0.00316"
"20040","120.20400","10.01720","0.00341"
"20103","120.58200","10.04871","0.00341"
"20166","120.96000","10.08016","0.00356"
"20229","121.33800","10.11172","0.00347"
"20292","121.71600","10.14318","0.00272"
"20355","122.09400","10.17468","0.00342"
"20418","122.47200","10.20613","0.00419"
"20481","122.85000","10.23770","0.00368"
"20544","123.22800","10.26921","0.00356"
"20607","123.60600","10.30066","0.00357"
"20670","123.98400","10.33229","0.00389"
"20733","124.36200","10.36368","0.00316"
"20796","124.74000","10.39519","0.00227"
"20859","125.11800","10.42670","0.00294"
"20922","125.49600","10.45821","0.00287"
"20985","125.87400","10.48972","0.00306"
"21048","126.25200","10.52116","0.00349"
"21111","126.63000","10.55267","0.00412"
"21174","127.00800","10.58418","0.00360"
"21237","127.38600","10.61563","0.00395"
"21300","127.76400","10.64720","0.00393"
"21363","128.14200","10.67871","0.00448"
"21426","128.52000","10.71016","0.00476"
"21489","128.89800","10.74167","0.00446"
"21552","129.27600","10.77318","0.00413"
"21615","129.65400","10.80469","0.00461"
"21678","130.03200","10.83619","0.00463"
"21741","130.41000","10.86765","0.00458"
"21804","130.78800","10.89921","0.00504"
"21867","131.16600","10.93066","0.00497"
"21930","131.54400","10.96217","0.00545"
"21993","131.92200","10.99374","0.00521"
"22056","132.30000","11.02519","0.00528"
"22119","132.67800","11.05664","0.00521"
"22182","133.05600","11.08827","0.00496"
"22245","133.43400","11.11972","0.00565"
"22308","133.81200","11.15111","0.00595"
"22371","134.19000","11.18274","0.00562"
"22434","134.56800","11.21424","0.00584"
"22497","134.94600","11.24563","0.00451"
"22560","135.32400","11.27720","0.00432"
"22623","135.70200","11.30871","0.00466"
"22686","136.08000","11.34016","0.00429"
"22749","136.45800","11.37167","0.00428"
"22812","136.83600","11.40318","0.00392"
"22875","137.21400","11.43469","0.00527"
"22938","137.59200","11.46614","0.00459"
"23001","137.97000","11.49771","0.00531"
"23064","138.34800","11.52922","0.00561"
"23127","138.72600","11.56067","0.00504"
"23190","139.10400","11.59217","0.00532"
"23253","139.48200","11.62374","0.00582"
"23316","139.86000","11.65519","0.00556"
"23379","140.23800","11.68664","0.00534"
"23442","140.61600","11.71821","0.00532"
"23505","140.99400","11.74966","0.00602"
"23568","141.37200","11.78117","0.00482"
"23631","141.75000","11.81268","0.00568"
"23694","142.12800","11.84419","0.00476"
"23757","142.50600","11.87564","0.00462"
"23820","142.88400","11.90715","0.00533"
"23883","143.26200","11.93871","0.00545"
"23946","143.64000","11.97022","0.00503"
"24009","144.01800","12.00167","0.00499"
"24072","144.39600","12.03318","0.00581"
"24135","144.77400","12.06469","0.00562"
"24198","145.15200","12.09608","0.00613"
"24261","145.53000","12.12771","0.00604"
"24324","145.90800","12.15916","0.00601"
"24387","146.28600","12.19067","0.00584"
"24450","146.66400","12.22218","0.00474"
"24513","147.04200","12.25369","0.00452"
"24576","147.42000","12.28520","0.00484"
"24639","147.79800","12.31664","0.00449"
"24702","148.17600","12.34821","0.00450"
"24765","148.55400","12.37978","0.00500"
"24828","148.93200","12.41111","0.00533"
"24891","149.31000","12.44262","0.00477"
"24954","149.68800","12.47425","0.00492"
"25017","150.06600","12.50570","0.00473"
"25080","150.44400","12.53715","0.00487"
"25143","150.82200","12.56872","0.00541"
"25206","151.20000","12.60023","0.00445"
"25269","151.57800","12.63167","0.00568"
"25332","151.95600","12.66318","0.00505"
"25395","152.33400","12.69469","0.00485"
"25458","152.71200","12.72620","0.00463"
"25521","153.09000","12.75765","0.00395"
"25584","153.46800","12.78916","0.00476"
"25647","153.84600","12.82067","0.00458"
"25710","154.22400","12.85218","0.00482"
"25773","154.60200","12.88375","0.00473"
"25836","154.98000","12.91526","0.00458"
"25899","155.35800","12.94659","0.00537"
"25962","155.73600","12.97822","0.00569"
"26025","156.11400","13.00972","0.00528"
"26088","156.49200","13.04111","0.00557"
"26151","156.87000","13.07274","0.00481"
"26214","157.24800","13.10419","0.00496"
"26277","157.62600","13.13564","0.00489"
"26340","158.00400","13.16715","0.00467"
"26403","158.38200","13.19872","0.00412"
"26466","158.76000","13.23023","0.00440"
"26529","159.13800","13.26162","0.00460"
"26592","159.51600","13.29319","0.00496"
"26655","159.89400","13.32469","0.00510"
"26718","160.27200","13.35614","0.00541"
"26781","160.65000","13.38765","0.00465"
"26844","161.02800","13.41928","0.00517"
"26907","161.40600","13.45067","0.00511"
"26970","161.78400","13.48218","0.00532"
"27033","162.16200","13.51375","0.00587"
"27096","162.54000","13.54520","0.00491"
"27159","162.91800","13.57665","0.00563"
"27222","163.29600","13.60822","0.00529"
"27285","163.67400","13.63973","0.00470"
"27348","164.05200","13.67118","0.00416"
"27411","164.43000","13.70268","0.00495"
"27474","164.80800","13.73419","0.00438"
"27537","165.18600","13.76570","0.00491"
"27600","165.56400","13.79715","0.00450"
"27663","165.94200","13.82866","0.00427"
"27726","166.32000","13.86023","0.00491"
"27789","166.69800","13.89162","0.00491"
"27852","167.07600","13.92319","0.00431"
"27915","167.45400","13.95470","0.00498"
"27978","167.83200","13.98621","0.00517"
"28041","168.21000","14.01766","0.00560"
"28104","168.58800","14.04922","0.00554"
"28167","168.96600","14.08074","0.00575"
"28230","169.34400","14.11218","0.00580"
"28293","169.72200","14.14369","0.00608"
"28356","170.10000","14.17520","0.00567"
"28419","170.47800","14.20671","0.00571"
"28482","170.85600","14.23822","0.00619"
"28545","171.23400","14.26967","0.00613"
"28608","171.61200","14.30118","0.00625"
"28671","171.99000","14.33263","0.00731"
"28734","172.36800","14.36420","0.00611"
"28797","172.74600","14.39571","0.00631"
"28860","173.12400","14.42709","0.00599"
"28923","173.50200","14.45872","0.00575"
"28986","173.88000","14.49017","0.00470"
"29049","174.25800","14.52168","0.00522"
"29112","174.63600","14.55319","0.00502"
"29175","175.01400","14.58470","0.00562"
"29238","175.39200","14.61621","0.00534"
"29301","175.77000","14.64766","0.00597"
"29364","176.14800","14.67923","0.00617"
"29427","176.52600","14.71074","0.00615"
"29490","176.90400","14.74213","0.00598"
"29553","177.28200","14.77370","0.00574"
"29616","177.66000","14.80526","0.00564"
"29679","178.03800","14.83665","0.00616"
"29742","178.41600","14.86816","0.00611"
"29805","178.79400","14.89973","0.00579"
"29868","179.17200","14.93118","0.00567"
"29931","179.55000","14.96263","0.00563"
"29994","179.92800","14.99420","0.00546"
"30057","180.30600","15.02571","0.00597"
"30120","180.68400","15.05716","0.00581"
"30183","181.06200","15.08861","0.00557"
"30246","181.44000","15.12018","0.00636"
"30309","181.81800","15.15168","0.00586"
"30372","182.19600","15.18319","0.00548"
"30435","182.57400","15.21470","0.00557"
"30498","182.95200","15.24621","0.00561"
"30561","183.33000","15.27760","0.00586"
"30624","183.70800","15.30917","0.00583"
"30687","184.08600","15.34068","0.00597"
"30750","184.46400","15.37219","0.00618"
"30813","184.84200","15.40376","0.00609"
"30876","185.22000","15.43515","0.00607"
"30939","185.59800","15.46672","0.00653"
"31002","185.97600","15.49811","0.00693"
"31065","186.35400","15.52973","0.00593"
"31128","186.73200","15.56124","0.00625"
"31191","187.11000","15.59263","0.00563"
"31254","187.48800","15.62420","0.00632"
"31317","187.86600","15.65571","0.00629"
"31380","188.24400","15.68710","0.00646"
"31443","188.62200","15.71867","0.00657"
"31506","189.00000","15.75024","0.00633"
"31569","189.37800","15.78163","0.00682"
"31632","189.75600","15.81313","0.00692"
"31695","190.13400","15.84470","0.00685"
"31758","190.51200","15.87621","0.00706"
"31821","190.89000","15.90766","0.00735"
"31884","191.26800","15.93917","0.00721"
"31947","191.64600","15.97068","0.00728"
"32010","192.02400","16.00213","0.00733"
"32073","192.40200","16.03364","0.00757"
"32136","192.78000","16.06521","0.00636"
"32199","193.15800","16.09672","0.00768"
"32262","193.53600","16.12811","0.00716"
"32325","193.91400","16.15968","0.00594"
"32388","194.29200","16.19124","0.00641"
"32451","194.67000","16.22257","0.00652"
"32514","195.04800","16.25420","0.00699"
"32577","195.42600","16.28571","0.00666"
"32640","195.80400","16.31716","0.00643"
"32703","196.18200","16.34867","0.00670"
"32766","196.56000","16.38018","0.00662"
"32829","196.93800","16.41169","0.00661"
"32892","197.31600","16.44320","0.00672"
"32955","197.69400","16.47471","0.00684"
"33018","198.07200","16.50616","0.00647"
"33081","198.45000","16.53761","0.00715"
"33144","198.82800","16.56918","0.00735"
"33207","199.20600","16.60068","0.00696"
"33270","199.58400","16.63219","0.00674"
"33333","199.96200","16.66370","0.00645"
"33396","200.34000","16.69521","0.00741"
"33459","200.71800","16.72666","0.00586"
"33522","201.09600","16.75817","0.00629"
"33585","201.47400","16.78974","0.00683"
"33648","201.85200","16.82119","0.00626"
"33711","202.23000","16.85270","0.00692"
"33774","202.60800","16.88415","0.00686"
"33837","202.98600","16.91571","0.00697"
"33900","203.36400","16.94716","0.00690"
"33963","203.74200","16.97867","0.00699"
"34026","204.12000","17.01018","0.00779"
"34089","204.49800","17.04169","0.00811"
"34152","204.87600","17.07314","0.00759"
"34215","205.25400","17.10471","0.00807"
"34278","205.63200","17.13628","0.00813"
"34341","206.01000","17.16767","0.00745"
"34404","206.38800","17.19918","0.00750"
"34467","206.76600","17.23069","0.00737"
"34530","207.14400","17.26219","0.00758"
"34593","207.52200","17.29364","0.00693"
"34656","207.90000","17.32521","0.00796"
"34719","208.27800","17.35672","0.00849"
"34782","208.65600","17.38817","0.00758"
"34845","209.03400","17.41962","0.00695"
"34908","209.41200","17.45119","0.00678"
"34971","209.79000","17.48270","0.00703"
"35034","210.16800","17.51415","0.00741"
"35097","210.54600","17.54572","0.00727"
"35160","210.92400","17.57717","0.00643"
"35223","211.30200","17.60861","0.00705"
"35286","211.68000","17.64024","0.00674"
"35349","212.05800","17.67169","0.00691"
"35412","212.43600","17.70314","0.00706"
"35475","212.81400","17.73471","0.00713"
"35538","213.19200","17.76622","0.00770"
"35601","213.57000","17.79767","0.00661"
"35664","213.94800","17.82918","0.00513"
"35727","214.32600","17.86069","0.00604"
"35790","214.70400","17.89220","0.00567"
"35853","215.08200","17.92365","0.00626"
"35916","215.46000","17.95522","0.00592"
"35979","215.83800","17.98678","0.00625"
"36042","216.21600","18.01817","0.00654"
"36105","216.59400","18.04968","0.00638"
"36168","216.97200","18.08119","0.00608"
"36231","217.35000","18.11264","0.00677"
"36294","217.72800","18.14415","0.00705"
"36357","218.10600","18.17572","0.00659"
"36420","218.48400","18.20717","0.00712"
"36483","218.86200","18.23868","0.00675"
"36546","219.24000","18.27019","0.00627"
"36609","219.61800","18.30169","0.00661"
"36672","219.99600","18.33315","0.00724"
"36735","220.37400","18.36471","0.00667"
"36798","220.75200","18.39622","0.00687"
"36861","221.13000","18.42773","0.00744"
"36924","221.50800","18.45918","0.00753"
"36987","221.88600","18.49069","0.00789"
"37050","222.26400","18.52220","0.00725"
"37113","222.64200","18.55365","0.00748"
"37176","223.02000","18.58522","0.00741"
"37239","223.39800","18.61667","0.00794"
"37302","223.77600","18.64818","0.00770"
"37365","224.15400","18.67962","0.00758"
"37428","224.53200","18.71119","0.00647"
"37491","224.91000","18.74270","0.00553"
"37554","225.28800","18.77421","0.00597"
"37617","225.66600","18.80572","0.00618"
"37680","226.04400","18.83723","0.00624"
"37743","226.42200","18.86868","0.00608"
"37806","226.80000","18.90013","0.00557"
"37869","227.17800","18.93176","0.00588"
"37932","227.55600","18.96321","0.00581"
"37995","227.93400","18.99466","0.00616"
"38058","228.31200","19.02623","0.00619"
"38121","228.69000","19.05767","0.00639"
"38184","229.06800","19.08912","0.00628"
"38247","229.44600","19.12069","0.00343"
"38310","229.82400","19.15220","0.00313"
"38373","230.20200","19.18365","0.00277"
"38436","230.58000","19.21516","0.00355"
"38499","230.95800","19.24667","0.00357"
"38562","231.33600","19.27818","0.00360"
"38625","231.71400","19.30969","0.00428"
"38688","232.09200","19.34126","0.00362"
"38751","232.47000","19.37271","0.00320"
"38814","232.84800","19.40409","0.00344"
"38877","233.22600","19.43572","0.00374"
"38940","233.60400","19.46723","0.00391"
"39003","233.98200","19.49862","0.00324"
"39066","234.36000","19.53019","0.00296"
"39129","234.73800","19.56170","0.00433"
"39192","235.11600","19.59321","0.00416"
"39255","235.49400","19.62466","0.00441"
"39318","235.87200","19.65623","0.00437"
"39381","236.25000","19.68773","0.00462"
"39444","236.62800","19.71913","0.00445"
"39507","237.00600","19.75064","0.00396"
"39570","237.38400","19.78220","0.00479"
"39633","237.76200","19.81365","0.00470"
"39696","238.14000","19.84516","0.00434"
"39759","238.51800","19.87673","0.00456"
"39822","238.89600","19.90818","0.00493"
"39885","239.27400","19.93969","0.00412"
"39948","239.65200","19.97120","0.00472"
"40011","240.03000","20.00265","0.00446"
"40074","240.40800","20.03416","0.00431"
"40137","240.78600","20.06573","0.00459"
"40200","241.16400","20.09718","0.00491"
"40263","241.54200","20.12868","0.00440"
"40326","241.92000","20.16019","0.00401"
"40389","242.29800","20.19170","0.00485"
"40452","242.67600","20.22321","0.00468"
"40515","243.05400","20.25466","0.00482"
"40578","243.43200","20.28617","0.00478"
"40641","243.81000","20.31774","0.00412"
"40704","244.18800","20.34913","0.00475"
"40767","244.56600","20.38070","0.00559"
"40830","244.94400","20.41221","0.00432"
"40893","245.32200","20.44366","0.00496"
"40956","245.70000","20.47517","0.00477"
"41019","246.07800","20.50667","0.00522"
"41082","246.45600","20.53818","0.00508"
"41145","246.83400","20.56963","0.00540"
"41208","247.21200","20.60120","0.00563"
"41271","247.59000","20.63271","0.00551"
"41334","247.96800","20.66422","0.00558"
"41397","248.34600","20.69567","0.00566"
"41460","248.72400","20.72718","0.00501"
"41523","249.10200","20.75869","0.00542"
"41586","249.48000","20.79020","0.00547"
"41649","249.85800","20.82170","0.00505"
"41712","250.23600","20.85321","0.00568"
"41775","250.61400","20.88460","0.00513"
"41838","250.99200","20.91617","0.00579"
"41901","251.37000","20.94768","0.00552"
"41964","251.74800","20.97919","0.00827"
"42027","252.12600","21.01064","0.00568"
"42090","252.50400","21.04221","0.00701"
"42153","252.88200","21.07366","0.00508"
"42216","253.26000","21.10511","0.00428"
"42279","253.63800","21.13667","0.00384"
"42342","254.01600","21.16830","0.00319"
"42405","254.39400","21.19963","0.00404"
"42468","254.77200","21.23120","0.00409"
"42531","255.15000","21.26271","0.00444"
"42594","255.52800","21.29410","0.00360"
"42657","255.90600","21.32567","0.00408"
"42720","256.28400","21.35724","0.00394"
"42783","256.66200","21.38869","0.00320"
"42846","257.04000","21.42020","-0.00239"
"42909","257.41800","21.45171","-0.00586"
"42972","257.79600","21.48322","-0.00421"
"43035","258.17400","21.51472","-0.00319"
"43098","258.55200","21.54623","-0.00503"
"43161","258.93000","21.57768","-0.00402"
"43224","259.30800","21.60919","-0.00428"
"43287","259.68600","21.64064","-0.00478"
"43350","260.06400","21.67221","-0.00336"
"43413","260.44200","21.70372","-0.00449"
"43476","260.82000","21.73511","-0.00466"
"43539","261.19800","21.76668","-0.00332"
"43602","261.57600","21.79819","-0.00456"
"43665","261.95400","21.82964","-0.00331"
"43728","262.33200","21.86121","-0.00436"
"43791","262.71000","21.89266","-0.00424"
"43854","263.08800","21.92416","-0.00270"
"43917","263.46600","21.95567","-0.00388"
"43980","263.84400","21.98724","-0.00285"
"44043","264.22200","22.01869","-0.00320"
"44106","264.60000","22.05014","-0.00404"
"44169","264.97800","22.08165","-0.00239"
"44232","265.35600","22.11322","-0.00317"
"44295","265.73400","22.14467","-0.00262"
"44358","266.11200","22.17612","-0.00269"
"44421","266.49000","22.20774","-0.00226"
"44484","266.86800","22.23919","-0.00225"
"44547","267.24600","22.27064","-0.00246"
"44610","267.62400","22.30215","-0.00302"
"44673","268.00200","22.33372","-0.00235"
"44736","268.38000","22.36511","-0.00288"
"44799","268.75800","22.39668","-0.00235"
"44862","269.13600","22.42819","-0.00211"
"44925","269.51400","22.45970","-0.00220"
"44988","269.89200","22.49115","-0.00182"
"45051","270.27000","22.52272","-0.00168"
"45114","270.64800","22.55423","-0.00188"
"45177","271.02600","22.58562","-0.00179"
"45240","271.40400","22.61719","-0.00221"
"45303","271.78200","22.64875","-0.00107"
"45366","272.16000","22.68014","-0.00118"
"45429","272.53800","22.71171","-0.00173"
"45492","272.91600","22.74322","-0.00128"
"45555","273.29400","22.77467","-0.00101"
"45618","273.67200","22.80618","-0.00120"
"45681","274.05000","22.83769","-0.00105"
"45744","274.42800","22.86920","-0.00088"
"45807","274.80600","22.90065","-0.00162"
"45870","275.18400","22.93222","-0.00082"
"45933","275.56200","22.96372","-0.00134"
"45996","275.94000","22.99511","-0.00025"
"46059","276.31800","23.02668","-0.00045"
"46122","276.69600","23.05819","-0.00055"
"46185","277.07400","23.08970","-0.00052"
"46248","277.45200","23.12115","-0.00081"
"46311","277.83000","23.15272","-0.00094"
"46374","278.20800","23.18417","-0.00103"
"46437","278.58600","23.21568","-0.00035"
"46500","278.96400","23.24719","-0.00028"
"46563","279.34200","23.27870","-0.00055"
"46626","279.72000","23.31014","-0.00041"
"46689","280.09800","23.34166","0.00019"
"46752","280.47600","23.37316","-0.00015"
"46815","280.85400","23.40467","-0.00022"
"46878","281.23200","23.43612","0.00004"
"46941","281.61000","23.46769","0.00054"
"47004","281.98800","23.49926","-0.00043"
"47067","282.36600","23.53065","-0.00030"
"47130","282.74400","23.56222","-0.00040"
"47193","283.12200","23.59367","-0.00034"
"47256","283.50000","23.62518","0.00006"
"47319","283.87800","23.65668","0.00069"
"47382","284.25600","23.68819","-0.00015"
"47445","284.63400","23.71970","0.00011"
"47508","285.01200","23.75115","0.00014"
"47571","285.39000","23.78266","-0.00021"
"47634","285.76800","23.81423","-0.00058"
"47697","286.14600","23.84568","-0.00101"
"47760","286.52400","23.87713","-0.00096"
"47823","286.90200","23.90870","-0.00168"
"47886","287.28000","23.94020","-0.00150"
"47949","287.65800","23.97166","-0.00159"
"48012","288.03600","24.00323","-0.00108"
"48075","288.41400","24.03473","-0.00119"
"48138","288.79200","24.06618","-0.00155"
"48201","289.17000","24.09775","-0.00099"
"48264","289.54800","24.12920","-0.00160"
"48327","289.92600","24.16065","-0.00092"
"48390","290.30400","24.19222","-0.00124"
"48453","290.68200","24.22367","-0.00064"
"48516","291.06000","24.25518","-0.00100"
"48579","291.43800","24.28663","-0.00122"
"48642","291.81600","24.31820","-0.00129"
"48705","292.19400","24.34971","-0.00097"
"48768","292.57200","24.38116","-0.00106"
"48831","292.95000","24.41267","-0.00202"
"48894","293.32800","24.44423","-0.00148"
"48957","293.70600","24.47562","-0.00178"
"49020","294.08400","24.50713","-0.00069"
"49083","294.46200","24.53876","-0.00134"
"49146","294.84000","24.57021","-0.00121"
"49209","295.21800","24.60166","-0.00093"
"49272","295.59600","24.63317","-0.00063"
"49335","295.97400","24.66474","-0.00060"
"49398","296.35200","24.69613","-0.00109"
"49461","296.73000","24.72770","-0.00150"
"49524","297.10800","24.75920","-0.00121"
"49587","297.48600","24.79071","-0.00218"
"49650","297.86400","24.82216","-0.00173"
"49713","298.24200","24.85367","-0.00151"
"49776","298.62000","24.88524","-0.00158"
"49839","298.99800","24.91663","-0.00126"
"49902","299.37600","24.94820","-0.00191"
"49965","299.75400","24.97971","-0.00190"
"50028","300.13200","25.01116","-0.00196"
"50091","300.51000","25.04267","-0.00165"
"50154","300.88800","25.07417","-0.00168"
"50217","301.26600","25.10568","-0.00223"
"50280","301.64400","25.13720","-0.00146"
"50343","302.02200","25.16864","-0.00131"
"50406","302.40000","25.20021","-0.00131"
"50469","302.77800","25.23166","-0.00108"
"50532","303.15600","25.26317","-0.00082"
"50595","303.53400","25.29474","-0.00160"
"50658","303.91200","25.32613","-0.00127"
"50721","304.29000","25.35764","-0.00076"
"50784","304.66800","25.38921","-0.00121"
"50847","305.04600","25.42065","-0.00161"
"50910","305.42400","25.45217","-0.00126"
"50973","305.80200","25.48368","-0.00297"
"51036","306.18000","25.51518","-0.00411"
"51099","306.55800","25.54663","-0.00415"
"51162","306.93600","25.57826","-0.00426"
"51225","307.31400","25.60971","-0.00386"
"51288","307.69200","25.64116","-0.00467"
"51351","308.07000","25.67267","-0.00344"
"51414","308.44800","25.70418","-0.00424"
"51477","308.82600","25.73575","-0.00425"
"51540","309.20400","25.76720","-0.00398"
"51603","309.58200","25.79871","-0.00395"
"51666","309.96000","25.83021","-0.00467"
"51729","310.33800","25.86160","-0.00420"
"51792","310.71600","25.89317","-0.00466"
"51855","311.09400","25.92474","-0.00382"
"51918","311.47200","25.95613","-0.00442"
"51981","311.85000","25.98770","-0.00435"
"52044","312.22800","26.01921","-0.00430"
"52107","312.60600","26.05066","-0.00401"
"52170","312.98400","26.08217","-0.00396"
"52233","313.36200","26.11374","-0.00431"
"52296","313.74000","26.14524","-0.00462"
"52359","314.11800","26.17664","-0.00454"
"52422","314.49600","26.20814","-0.00465"
"52485","314.87400","26.23971","-0.00451"
"52548","315.25200","26.27116","-0.00463"
"52611","315.63000","26.30273","-0.00416"
"52674","316.00800","26.33424","-0.00408"
"52737","316.38600","26.36569","-0.00434"
"52800","316.76400","26.39714","-0.00412"
"52863","317.14200","26.42871","-0.00421"
"52926","317.52000","26.46021","-0.00443"
"52989","317.89800","26.49167","-0.00386"
"53052","318.27600","26.52324","-0.00469"
"53115","318.65400","26.55469","-0.00446"
"53178","319.03200","26.58619","-0.00417"
"53241","319.41000","26.61770","-0.00439"
"53304","319.78800","26.64915","-0.00356"
"53367","320.16600","26.68066","-0.00442"
"53430","320.54400","26.71217","-0.00456"
"53493","320.92200","26.74368","-0.00455"
"53556","321.30000","26.77525","-0.00434"
"53619","321.67800","26.80664","-0.00357"
"53682","322.05600","26.83815","-0.00380"
"53745","322.43400","26.86972","-0.00466"
"53808","322.81200","26.90122","-0.00403"
"53871","323.19000","26.93268","-0.00430"
"53934","323.56800","26.96424","-0.00384"
"53997","323.94600","26.99575","-0.00411"
"54060","324.32400","27.02714","-0.00416"
"54123","324.70200","27.05871","-0.00446"
"54186","325.08000","27.09022","-0.00425"
"54249","325.45800","27.12167","-0.00454"
"54312","325.83600","27.15318","-0.00424"
"54375","326.21400","27.18469","-0.00392"
"54438","326.59200","27.21620","-0.00410"
"54501","326.97000","27.24765","-0.00369"
"54564","327.34800","27.27921","-0.00448"
"54627","327.72600","27.31072","-0.00401"
"54690","328.10400","27.34211","-0.00420"
"54753","328.48200","27.37368","-0.00411"
"54816","328.86000","27.40519","-0.00344"
"54879","329.23800","27.43670","-0.00399"
"54942","329.61600","27.46815","-0.00387"
"55005","329.99400","27.49966","-0.00398"
"55068","330.37200","27.53123","-0.00427"
"55131","330.75000","27.56268","-0.00394"
"55194","331.12800","27.59425","-0.00382"
"55257","331.50600","27.62576","-0.00422"
"55320","331.88400","27.65708","-0.00384"
"55383","332.26200","27.68871","-0.00424"
"55446","332.64000","27.72022","-0.00351"
"55509","333.01800","27.75167","-0.00392"
"55572","333.39600","27.78318","-0.00419"
"55635","333.77400","27.81475","-0.00420"
"55698","334.15200","27.84614","-0.00390"
"55761","334.53000","27.87765","-0.00401"
"55824","334.90800","27.90922","-0.00389"
"55887","335.28600","27.94066","-0.00399"
"55950","335.66400","27.97218","-0.00418"
"56013","336.04200","28.00368","-0.00355"
"56076","336.42000","28.03519","-0.00394"
"56139","336.79800","28.06670","-0.00322"
"56202","337.17600","28.09815","-0.00387"
"56265","337.55400","28.12972","-0.00425"
"56328","337.93200","28.16123","-0.00331"
"56391","338.31000","28.19262","-0.00339"
"56454","338.68800","28.22419","-0.00352"
"56517","339.06600","28.25570","-0.00370"
"56580","339.44400","28.28714","-0.00274"
"56643","339.82200","28.31872","-0.00346"
"56706","340.20000","28.35016","-0.00345"
"56769","340.57800","28.38173","-0.00345"
"56832","340.95600","28.41318","-0.00391"
"56895","341.33400","28.44469","-0.00318"
"56958","341.71200","28.47620","-0.00339"
"57021","342.09000","28.50765","-0.00373"
"57084","342.46800","28.53916","-0.00328"
"57147","342.84600","28.57073","-0.00330"
"57210","343.22400","28.60212","-0.00409"
"57273","343.60200","28.63369","-0.00335"
"57336","343.98000","28.66520","-0.00341"
"57399","344.35800","28.69670","-0.00413"
"57462","344.73600","28.72815","-0.00314"
"57525","345.11400","28.75972","-0.00345"
"57588","345.49200","28.79117","-0.00327"
"57651","345.87000","28.82268","-0.00311"
"57714","346.24800","28.85419","-0.00388"
"57777","346.62600","28.88570","-0.00372"
"57840","347.00400","28.91721","-0.00383"
"57903","347.38200","28.94866","-0.00305"
"57966","347.76000","28.98022","-0.00381"
"58029","348.13800","29.01173","-0.00375"
"58092","348.51600","29.04313","-0.00344"
"58155","348.89400","29.07470","-0.00290"
"58218","349.27200","29.10620","-0.00334"
"58281","349.65000","29.13765","-0.00266"
"58344","350.02800","29.16922","-0.00290"
"58407","350.40600","29.20073","-0.00323"
"58470","350.78400","29.23212","-0.00273"
"58533","351.16200","29.26369","-0.00376"
"58596","351.54000","29.29520","-0.00327"
"58659","351.91800","29.32671","-0.00297"
"58722","352.29600","29.35816","-0.00272"
"58785","352.67400","29.38966","-0.00231"
"58848","353.05200","29.42123","-0.00321"
"58911","353.43000","29.45262","-0.00306"
"58974","353.80800","29.48413","-0.00285"
"59037","354.18600","29.51570","-0.00347"
"59100","354.56400","29.54721","-0.00284"
"59163","354.94200","29.57866","-0.00326"
"59226","355.32000","29.61017","-0.00277"
"59289","355.69800","29.64168","-0.00333"
"59352","356.07600","29.67319","-0.00299"
"59415","356.45400","29.70476","-0.00315"
"59478","356.83200","29.73621","-0.00334"
"59541","357.21000","29.76765","-0.00318"
"59604","357.58800","29.79917","-0.00253"
"59667","357.96600","29.83067","-0.00299"
"59730","358.34400","29.86224","-0.00250"
"59793","358.72200","29.89369","-0.00291"
"59856","359.10000","29.92520","-0.00261"
"59919","359.47800","29.95671","-0.00247"
"59982","359.85600","29.98810","-0.00305"
"60045","360.23400","30.01967","-0.00307"
"60108","360.61200","30.05124","-0.00231"
"60171","360.99000","30.08269","-0.00267"
"60234","361.36800","30.11419","-0.00273"
"60297","361.74600","30.14570","-0.00262"
"60360","362.12400","30.17721","-0.00252"
"60423","362.50200","30.20866","-0.00279"
"60486","362.88000","30.24017","-0.00283"
"60549","363.25800","30.27174","-0.00256"
"60612","363.63600","30.30319","-0.00233"
"60675","364.01400","30.33464","-0.00220"
"60738","364.39200","30.36621","-0.00252"
"60801","364.77000","30.39766","-0.00253"
"60864","365.14800","30.42911","-0.00273"
"60927","365.52600","30.46073","-0.00246"
"60990","365.90400","30.49224","-0.00282"
"61053","366.28200","30.52363","-0.00226"
"61116","366.66000","30.55526","-0.00205"
"61179","367.03800","30.58671","-0.00281"
"61242","367.41600","30.61810","-0.00263"
"61305","367.79400","30.64967","-0.00320"
"61368","368.17200","30.68118","-0.00273"
"61431","368.55000","30.71269","-0.00281"
"61494","368.92800","30.74414","-0.00301"
"61557","369.30600","30.77571","-0.00268"
"61620","369.68400","30.80722","-0.00330"
"61683","370.06200","30.83861","-0.00269"
"61746","370.44000","30.87017","-0.00237"
"61809","370.81800","30.90174","-0.00259"
"61872","371.19600","30.93313","-0.00193"
"61935","371.57400","30.96464","-0.00302"
"61998","371.95200","30.99621","-0.00270"
"62061","372.33000","31.02772","-0.00200"
"62124","372.70800","31.05911","-0.00283"
"62187","373.08600","31.09074","-0.00267"
"62250","373.46400","31.12218","-0.00280"
"62313","373.84200","31.15370","-0.00234"
"62376","374.22000","31.18521","-0.00206"
"62439","374.59800","31.21666","-0.00196"
"62502","374.97600","31.24822","-0.00195"
"62565","375.35400","31.27967","-0.00240"
"62628","375.73200","31.31124","-0.00205"
"62691","376.11000","31.34275","-0.00228"
"62754","376.48800","31.37414","-0.00189"
"62817","376.86600","31.40571","-0.00231"
"62880","377.24400","31.43721","-0.00189"
"62943","377.62200","31.46867","-0.00159"
"63006","378.00000","31.50018","-0.00216"
"63069","378.37800","31.53168","-0.00162"
"63132","378.75600","31.56319","-0.00194"
"63195","379.13400","31.59470","-0.00188"
"63258","379.51200","31.62615","-0.00149"
"63321","379.89000","31.65766","-0.00186"
"63384","380.26800","31.68917","-0.00180"
"63447","380.64600","31.72074","-0.00183"
"63510","381.02400","31.75225","-0.00195"
"63573","381.40200","31.78364","-0.00158"
"63636","381.78000","31.81520","-0.00140"
"63699","382.15800","31.84671","-0.00171"
"63762","382.53600","31.87816","-0.00178"
"63825","382.91400","31.90961","-0.00207"
"63888","383.29200","31.94118","-0.00149"
"63951","383.67000","31.97269","-0.00138"
"64014","384.04800","32.00414","-0.00100"
"64077","384.42600","32.03571","-0.00077"
"64140","384.80400","32.06722","-0.00124"
"64203","385.18200","32.09867","-0.00226"
"64266","385.56000","32.13012","-0.00166"
"64329","385.93800","32.16169","-0.00123"
"64392","386.31600","32.19320","-0.00167"
"64455","386.69400","32.22464","-0.00110"
"64518","387.07200","32.25621","-0.00093"
"64581","387.45000","32.28772","-0.00160"
"64644","387.82800","32.31911","-0.00051"
"64707","388.20600","32.35068","-0.00162"
"64770","388.58400","32.38225","-0.00129"
"64833","388.96200","32.41364","-0.00144"
"64896","389.34000","32.44515","-0.00124"
"64959","389.71800","32.47666","-0.00134"
"65022","390.09600","32.50816","-0.00090"
"65085","390.47400","32.53968","-0.00112"
"65148","390.85200","32.57119","-0.00139"
"65211","391.23000","32.60270","-0.00131"
"65274","391.60800","32.63414","-0.00113"
"65337","391.98600","32.66565","-0.00092"
"65400","392.36400","32.69722","-0.00113"
"65463","392.74200","32.72867","-0.00112"
"65526","393.12000","32.76018","-0.00087"
"65589","393.49800","32.79169","-0.00019"
"65652","393.87600","32.82314","-0.00075"
"65715","394.25400","32.85464","-0.00061"
"65778","394.63200","32.88627","-0.00020"
"65841","395.01000","32.91772","-0.00027"
"65904","395.38800","32.94918","-0.00063"
"65967","395.76600","32.98074","-0.00038"
"66030","396.14400","33.01213","-0.00048"
"66093","396.52200","33.04370","-0.00073"
"66156","396.90000","33.07515","-0.00076"
"66219","397.27800","33.10672","-0.00071"
"66282","397.65600","33.13823","-0.00047"
"66345","398.03400","33.16962","-0.00045"
"66408","398.41200","33.20119","-0.00129"
"66471","398.79000","33.23276","0.00003"
"66534","399.16800","33.26414","-0.00066"
"66597","399.54600","33.29571","-0.00039"
"66660","399.92400","33.32722","-0.00011"
"66723","400.30200","33.35867","-0.00010"
"66786","400.68000","33.39013","-0.00081"
"66849","401.05800","33.42169","-0.00018"
"66912","401.43600","33.45320","-0.00065"
"66975","401.81400","33.48465","-0.00069"
"67038","402.19200","33.51622","-0.00036"
"67101","402.57000","33.54773","-0.00064"
"67164","402.94800","33.57918","-0.00036"
"67227","403.32600","33.61063","-0.00034"
"67290","403.70400","33.64220","0.00001"
"67353","404.08200","33.67370","0.00033"
"67416","404.46000","33.70521","0.00042"
"67479","404.83800","33.73672","-0.00012"
"67542","405.21600","33.76823","-0.00023"
"67605","405.59400","33.79962","0.00019"
"67668","405.97200","33.83119","0.00000"
"67731","406.35000","33.86276","-0.00024"
"67794","406.72800","33.89415","-0.00013"
"67857","407.10600","33.92566","0.00053"
"67920","407.48400","33.95716","-0.00052"
"67983","407.86200","33.98867","0.00028"
"68046","408.24000","34.02013","0.00015"
"68109","408.61800","34.05175","0.00014"
"68172","408.99600","34.08326","-0.00018"
"68235","409.37400","34.11465","0.00051"
"68298","409.75200","34.14622","-0.00006"
"68361","410.13000","34.17773","-0.00013"
"68424","410.50800","34.20912","0.00058"
"68487","410.88600","34.24063","0.00020"
"68550","411.26400","34.27226","-0.00049"
"68613","411.64200","34.30371","0.00030"
"68676","412.02000","34.33516","0.00026"
"68739","412.39800","34.36672","0.00016"
"68802","412.77600","34.39823","0.00043"
"68865","413.15400","34.42968","0.00065"
"68928","413.53200","34.46113","-0.00022"
"68991","413.91000","34.49270","0.00026"
"69054","414.28800","34.52415","0.00008"
"69117","414.66600","34.55566","0.00036"
"69180","415.04400","34.58717","0.00034"
"69243","415.42200","34.61874","0.00074"
"69306","415.80000","34.65013","0.00052"
"69369","416.17800","34.68164","0.00049"
"69432","416.55600","34.71315","0.00120"
"69495","416.93400","34.74466","0.00109"
"69558","417.31200","34.77622","0.00070"
"69621","417.69000","34.80773","0.00080"
"69684","418.06800","34.83918","0.00063"
"69747","418.44600","34.87069","0.00063"
"69810","418.82400","34.90220","0.00039"
"69873","419.20200","34.93371","-0.00034"
"69936","419.58000","34.96516","0.00093"
"69999","419.95800","34.99667","0.00096"
"70062","420.33600","35.02823","0.00073"
"70125","420.71400","35.05969","0.00106"
"70188","421.09200","35.09114","0.00111"
"70251","421.47000","35.12270","0.00111"
"70314","421.84800","35.15421","0.00072"
"70377","422.22600","35.18566","0.00053"
"70440","422.60400","35.21723","0.00137"
"70503","422.98200","35.24868","0.00074"
"70566","423.36000","35.28019","0.00125"
"70629","423.73800","35.31170","0.00149"
"70692","424.11600","35.34315","0.00070"
"70755","424.49400","35.37472","0.00079"
"70818","424.87200","35.40617","0.00146"
"70881","425.25000","35.43767","0.00129"
"70944","425.62800","35.46925","0.00136"
"71007","426.00600","35.50063","0.00083"
"71070","426.38400","35.53220","0.00132"
"71133","426.76200","35.56377","0.00119"
"71196","427.14000","35.59510","0.00136"
"71259","427.51800","35.62673","0.00168"
"71322","427.89600","35.65824","0.00135"
"71385","428.27400","35.68962","0.00175"
"71448","428.65200","35.72114","0.00171"
"71511","429.03000","35.75277","0.00169"
"71574","429.40800","35.78421","0.00156"
"71637","429.78600","35.81566","0.00170"
"71700","430.16400","35.84717","0.00131"
"71763","430.54200","35.87874","0.00141"
"71826","430.92000","35.91019","0.00146"
"71889","431.29800","35.94164","0.00172"
"71952","431.67600","35.97321","0.00174"
"72015","432.05400","36.00466","0.00180"
"72078","432.43200","36.03617","0.00195"
"72141","432.81000","36.06768","0.00167"
"72204","433.18800","36.09919","0.00143"
"72267","433.56600","36.13070","0.00191"
"72330","433.94400","36.16220","0.00202"
"72393","434.32200","36.19365","0.00191"
"72456","434.70000","36.22516","0.00248"
"72519","435.07800","36.25667","0.00168"
"72582","435.45600","36.28818","0.00186"
"72645","435.83400","36.31975","0.00258"
"72708","436.21200","36.35114","0.00208"
"72771","436.59000","36.38271","0.00254"
"72834","436.96800","36.41416","0.00218"
"72897","437.34600","36.44567","0.00242"
"72960","437.72400","36.47717","0.00259"
"73023","438.10200","36.50874","0.00237"
"73086","438.48000","36.54013","0.00192"
"73149","438.85800","36.57170","0.00173"
"73212","439.23600","36.60321","0.00221"
"73275","439.61400","36.63466","0.00246"
"73338","439.99200","36.66617","0.00212"
"73401","440.37000","36.69768","0.00241"
"73464","440.74800","36.72925","0.00211"
"73527","441.12600","36.76064","0.00255"
"73590","441.50400","36.79215","0.00292"
"73653","441.88200","36.82372","0.00268"
"73716","442.26000","36.85516","0.00242"
"73779","442.63800","36.88667","0.00277"
"73842","443.01600","36.91818","0.00272"
"73905","443.39400","36.94970","0.00244"
"73968","443.77200","36.98108","0.00243"
"74031","444.15000","37.01277","0.00242"
"74094","444.52800","37.04422","0.00325"
"74157","444.90600","37.07561","0.00261"
"74220","445.28400","37.10723","0.00283"
"74283","445.66200","37.13869","0.00241"
"74346","446.04000","37.17020","0.00269"
"74409","446.41800","37.20164","0.00294"
"74472","446.79600","37.23315","0.00334"
"74535","447.17400","37.26472","0.00282"
"74598","447.55200","37.29611","0.00278"
"74661","447.93000","37.32768","0.00324"
"74724","448.30800","37.35925","0.00305"
"74787","448.68600","37.39064","0.00354"
"74850","449.06400","37.42221","0.00336"
"74913","449.44200","37.45372","0.00372"
"74976","449.82000","37.48517","0.00397"
"75039","450.19800","37.51667","0.00357"
"75102","450.57600","37.54818","0.00369"
"75165","450.95400","37.57963","0.00280"
"75228","451.33200","37.61115","0.00388"
"75291","451.71000","37.64272","0.00350"
"75354","452.08800","37.67422","0.00371"
"75417","452.46600","37.70567","0.00334"
"75480","452.84400","37.73718","0.00344"
"75543","453.22200","37.76875","0.00346"
"75606","453.60000","37.80020","0.00382"
"75669","453.97800","37.83165","0.00405"
"75732","454.35600","37.86322","0.00272"
"75795","454.73400","37.89473","0.00347"
"75858","455.11200","37.92612","0.00318"
"75921","455.49000","37.95774","0.00403"
"75984","455.86800","37.98919","0.00410"
"76047","456.24600","38.02065","0.00371"
"76110","456.62400","38.05215","0.00455"
"76173","457.00200","38.08366","0.00469"
"76236","457.38000","38.11517","0.00423"
"76299","457.75800","38.14662","0.00480"
"76362","458.13600","38.17819","0.00432"
"76425","458.51400","38.20976","0.00473"
"76488","458.89200","38.24115","0.00430"
"76551","459.27000","38.27266","0.00517"
"76614","459.64800","38.30423","0.00511"
"76677","460.02600","38.33567","0.00442"
"76740","460.40400","38.36712","0.00400"
"76803","460.78200","38.39875","0.00477"
"76866","461.16000","38.43020","0.00502"
"76929","461.53800","38.46165","0.00480"
"76992","461.91600","38.49322","0.00515"
"77055","462.29400","38.52473","0.00455"
"77107","462.60400","38.55044","0.00462"