File: Trajectories_together/170225_2Specimen_RawData_6.csv
"","V1","V2","V3"
"1","End date","2/25/2017",""
"2","Specimen label","5DT_35",""
"3","Maximum Load","0.17180","N"
"4","Time","Extension","Load"
"5","(s)","(mm)","(N)"
"6","0.00000","0.00000","0.00043"
"79","0.43800","0.03677","0.00221"
"152","0.87600","0.07324","0.00342"
"225","1.31400","0.10971","0.00425"
"298","1.75200","0.14625","0.00516"
"371","2.19000","0.18272","0.00622"
"444","2.62800","0.21919","0.00642"
"517","3.06600","0.25572","0.00718"
"590","3.50400","0.29225","0.00782"
"663","3.94200","0.32872","0.00834"
"736","4.38000","0.36519","0.00894"
"809","4.81800","0.40167","0.00926"
"882","5.25600","0.43820","0.00943"
"955","5.69400","0.47473","0.00963"
"1028","6.13200","0.51120","0.01012"
"1101","6.57000","0.54767","0.01067"
"1174","7.00800","0.58420","0.01210"
"1247","7.44600","0.62068","0.01197"
"1320","7.88400","0.65721","0.01223"
"1393","8.32200","0.69374","0.01253"
"1466","8.76000","0.73027","0.01335"
"1539","9.19800","0.76668","0.01300"
"1612","9.63600","0.80315","0.01341"
"1685","10.07400","0.83968","0.01396"
"1758","10.51200","0.87622","0.01431"
"1831","10.95000","0.91275","0.01438"
"1904","11.38800","0.94922","0.01479"
"1977","11.82600","0.98569","0.01486"
"2050","12.26400","1.02222","0.01531"
"2123","12.70200","1.05875","0.01542"
"2196","13.14000","1.09522","0.01573"
"2269","13.57800","1.13176","0.01601"
"2342","14.01600","1.16823","0.01640"
"2415","14.45400","1.20470","0.01631"
"2488","14.89200","1.24117","0.01621"
"2561","15.33000","1.27776","0.01680"
"2634","15.76800","1.31423","0.01749"
"2707","16.20600","1.35071","0.01748"
"2780","16.64400","1.38718","0.01741"
"2853","17.08200","1.42371","0.01776"
"2926","17.52000","1.46018","0.01822"
"2999","17.95800","1.49671","0.01853"
"3072","18.39600","1.53318","0.01872"
"3145","18.83400","1.56965","0.01910"
"3218","19.27200","1.60619","0.01947"
"3291","19.71000","1.64278","0.01936"
"3364","20.14800","1.67925","0.01994"
"3437","20.58600","1.71578","0.02026"
"3510","21.02400","1.75225","0.01990"
"3583","21.46200","1.78866","0.01991"
"3656","21.90000","1.82525","0.02024"
"3729","22.33800","1.86173","0.02006"
"3802","22.77600","1.89820","0.02107"
"3875","23.21400","1.93467","0.02090"
"3948","23.65200","1.97120","0.02119"
"4021","24.09000","2.00773","0.02175"
"4094","24.52800","2.04420","0.02138"
"4167","24.96600","2.08068","0.02111"
"4240","25.40400","2.11721","0.02137"
"4313","25.84200","2.15362","0.02113"
"4386","26.28000","2.19021","0.02146"
"4459","26.71800","2.22674","0.02169"
"4532","27.15600","2.26321","0.02164"
"4605","27.59400","2.29974","0.02204"
"4678","28.03200","2.33622","0.02214"
"4751","28.47000","2.37269","0.02138"
"4824","28.90800","2.40922","0.02237"
"4897","29.34600","2.44569","0.02177"
"4970","29.78400","2.48222","0.02242"
"5043","30.22200","2.51875","0.02278"
"5116","30.66000","2.55511","0.02215"
"5189","31.09800","2.59170","0.02164"
"5262","31.53600","2.62823","0.02128"
"5335","31.97400","2.66470","0.02191"
"5408","32.41200","2.70123","0.02200"
"5481","32.85000","2.73770","0.02244"
"5554","33.28800","2.77417","0.02218"
"5627","33.72600","2.81065","0.02200"
"5700","34.16400","2.84718","0.02027"
"5773","34.60200","2.88371","0.02043"
"5846","35.04000","2.92018","0.02116"
"5919","35.47800","2.95665","0.02115"
"5992","35.91600","2.99324","0.02150"
"6065","36.35400","3.02971","0.02187"
"6138","36.79200","3.06625","0.02244"
"6211","37.23000","3.10278","0.02210"
"6284","37.66800","3.13925","0.02257"
"6357","38.10600","3.17566","0.02224"
"6430","38.54400","3.21225","0.02294"
"6503","38.98200","3.24872","0.02294"
"6576","39.42000","3.28526","0.02253"
"6649","39.85800","3.32167","0.02346"
"6722","40.29600","3.35814","0.02350"
"6795","40.73400","3.39473","0.02438"
"6868","41.17200","3.43120","0.02429"
"6941","41.61000","3.46767","0.02460"
"7014","42.04800","3.50420","0.02464"
"7087","42.48600","3.54062","0.02480"
"7160","42.92400","3.57721","0.02517"
"7233","43.36200","3.61368","0.02480"
"7306","43.80000","3.65021","0.02555"
"7379","44.23800","3.68674","0.02552"
"7452","44.67600","3.72315","0.02561"
"7525","45.11400","3.75969","0.02617"
"7598","45.55200","3.79622","0.02689"
"7671","45.99000","3.83275","0.02693"
"7744","46.42800","3.86928","0.02766"
"7817","46.86600","3.90569","0.02786"
"7890","47.30400","3.94216","0.02814"
"7963","47.74200","3.97869","0.02825"
"8036","48.18000","4.01523","0.02901"
"8109","48.61800","4.05176","0.02950"
"8182","49.05600","4.08817","0.02888"
"8255","49.49400","4.12464","0.02978"
"8328","49.93200","4.16117","0.03046"
"8401","50.37000","4.19776","0.03048"
"8474","50.80800","4.23418","0.03187"
"8547","51.24600","4.27071","0.03154"
"8620","51.68400","4.30718","0.02341"
"8693","52.12200","4.34371","0.02234"
"8766","52.56000","4.38024","0.02299"
"8839","52.99800","4.41671","0.02396"
"8912","53.43600","4.45324","0.02423"
"8985","53.87400","4.48972","0.02475"
"9058","54.31200","4.52619","0.02524"
"9131","54.75000","4.56272","0.02618"
"9204","55.18800","4.59919","0.02575"
"9277","55.62600","4.63572","0.02588"
"9350","56.06400","4.67219","0.02626"
"9423","56.50200","4.70860","0.02729"
"9496","56.94000","4.74520","0.02800"
"9569","57.37800","4.78167","0.02793"
"9642","57.81600","4.81826","0.02753"
"9715","58.25400","4.85473","0.02327"
"9788","58.69200","4.89114","0.02110"
"9861","59.13000","4.92767","0.02041"
"9934","59.56800","4.96421","0.01924"
"10007","60.00600","5.00074","0.02100"
"10080","60.44400","5.03727","0.02133"
"10153","60.88200","5.07368","0.02180"
"10226","61.32000","5.11021","0.02288"
"10299","61.75800","5.14668","0.02394"
"10372","62.19600","5.18327","0.02519"
"10445","62.63400","5.21975","0.02664"
"10518","63.07200","5.25628","0.02670"
"10591","63.51000","5.29269","0.02507"
"10664","63.94800","5.32916","0.02569"
"10737","64.38600","5.36575","0.02607"
"10810","64.82400","5.40222","0.02706"
"10883","65.26200","5.43875","0.02764"
"10956","65.70000","5.47517","0.02857"
"11029","66.13800","5.51164","0.02943"
"11102","66.57600","5.54817","0.02932"
"11175","67.01400","5.58470","0.03006"
"11248","67.45200","5.62123","0.03098"
"11321","67.89000","5.65770","0.03011"
"11394","68.32800","5.69412","0.03016"
"11467","68.76600","5.73071","0.03061"
"11540","69.20400","5.76718","0.03224"
"11613","69.64200","5.80371","0.03140"
"11686","70.08000","5.84024","0.03008"
"11759","70.51800","5.87671","0.03174"
"11832","70.95600","5.91319","0.03243"
"11905","71.39400","5.94972","0.03324"
"11978","71.83200","5.98625","0.03289"
"12051","72.27000","6.02278","0.03469"
"12124","72.70800","6.05919","0.03467"
"12197","73.14600","6.09566","0.03595"
"12270","73.58400","6.13219","0.03738"
"12343","74.02200","6.16873","0.03801"
"12416","74.46000","6.20520","0.03878"
"12489","74.89800","6.24173","0.04025"
"12562","75.33600","6.27820","0.02433"
"12635","75.77400","6.31467","0.01814"
"12708","76.21200","6.35120","0.01896"
"12781","76.65000","6.38767","0.02003"
"12854","77.08800","6.42421","0.02084"
"12927","77.52600","6.46074","0.02087"
"13000","77.96400","6.49721","0.02403"
"13073","78.40200","6.53374","0.02559"
"13146","78.84000","6.57021","0.02618"
"13219","79.27800","6.60674","0.02677"
"13292","79.71600","6.64321","0.02798"
"13365","80.15400","6.67969","0.02973"
"13438","80.59200","6.71622","0.03088"
"13511","81.03000","6.75275","0.03281"
"13584","81.46800","6.78922","0.03441"
"13657","81.90600","6.82575","0.03662"
"13730","82.34400","6.86216","0.03725"
"13803","82.78200","6.89870","0.03868"
"13876","83.22000","6.93517","0.04003"
"13949","83.65800","6.97170","0.04206"
"14022","84.09600","7.00823","0.04301"
"14095","84.53400","7.04470","0.04416"
"14168","84.97200","7.08117","0.04582"
"14241","85.41000","7.11770","0.04684"
"14314","85.84800","7.15424","0.04557"
"14387","86.28600","7.19077","0.04676"
"14460","86.72400","7.22718","0.04737"
"14533","87.16200","7.26371","0.04867"
"14606","87.60000","7.30024","0.04127"
"14679","88.03800","7.33671","0.04185"
"14752","88.47600","7.37319","0.04365"
"14825","88.91400","7.40972","0.04474"
"14898","89.35200","7.44619","0.04629"
"14971","89.79000","7.48266","0.04704"
"15044","90.22800","7.51919","0.04745"
"15117","90.66600","7.55578","0.03243"
"15190","91.10400","7.59220","0.03262"
"15263","91.54200","7.62867","0.03101"
"15336","91.98000","7.66514","0.03205"
"15409","92.41800","7.70167","0.03549"
"15482","92.85600","7.73820","0.03619"
"15555","93.29400","7.77473","0.03745"
"15628","93.73200","7.81120","0.03763"
"15701","94.17000","7.84768","0.03924"
"15774","94.60800","7.88421","0.04094"
"15847","95.04600","7.92074","0.04163"
"15920","95.48400","7.95727","0.04359"
"15993","95.92200","7.99374","0.04444"
"16066","96.36000","8.03021","0.04571"
"16139","96.79800","8.06668","0.04706"
"16212","97.23600","8.10322","0.04757"
"16285","97.67400","8.13975","0.04888"
"16358","98.11200","8.17622","0.04844"
"16431","98.55000","8.21269","0.04864"
"16504","98.98800","8.24910","0.04982"
"16577","99.42600","8.28569","0.05062"
"16650","99.86400","8.32222","0.05113"
"16723","100.30200","8.35876","0.05208"
"16796","100.74000","8.39517","0.05316"
"16869","101.17800","8.43170","0.05422"
"16942","101.61600","8.46817","0.05506"
"17015","102.05400","8.50470","0.05573"
"17088","102.49200","8.54123","0.05658"
"17161","102.93000","8.57776","0.05755"
"17234","103.36800","8.61418","0.04472"
"17307","103.80600","8.65065","0.04580"
"17380","104.24400","8.68724","0.04507"
"17453","104.68200","8.72371","0.04668"
"17526","105.12000","8.76024","0.04849"
"17599","105.55800","8.79671","0.04955"
"17672","105.99600","8.83319","0.05066"
"17745","106.43400","8.86972","0.05157"
"17818","106.87200","8.90619","0.05280"
"17891","107.31000","8.94272","0.05319"
"17964","107.74800","8.97931","0.05439"
"18037","108.18600","9.01566","0.05476"
"18110","108.62400","9.05219","0.05551"
"18183","109.06200","9.08873","0.05640"
"18256","109.50000","9.12526","0.05714"
"18329","109.93800","9.16173","0.05792"
"18402","110.37600","9.19820","0.05852"
"18475","110.81400","9.23467","0.05982"
"18548","111.25200","9.27126","0.06078"
"18621","111.69000","9.30774","0.06110"
"18694","112.12800","9.34427","0.06196"
"18767","112.56600","9.38074","0.04754"
"18840","113.00400","9.41715","0.02195"
"18913","113.44200","9.45368","0.02143"
"18986","113.88000","9.49021","0.02150"
"19059","114.31800","9.52674","0.01993"
"19132","114.75600","9.56328","0.02055"
"19205","115.19400","9.59975","0.02095"
"19278","115.63200","9.63616","0.02097"
"19351","116.07000","9.67269","0.02287"
"19424","116.50800","9.70928","0.02453"
"19497","116.94600","9.74575","0.02344"
"19570","117.38400","9.78217","0.02377"
"19643","117.82200","9.81864","0.02389"
"19716","118.26000","9.85517","0.02366"
"19789","118.69800","9.89176","0.02465"
"19862","119.13600","9.92823","0.02620"
"19935","119.57400","9.96470","0.02625"
"20008","120.01200","10.00117","0.02751"
"20081","120.45000","10.03771","0.02897"
"20154","120.88800","10.07418","0.02855"
"20227","121.32600","10.11071","0.02876"
"20300","121.76400","10.14724","0.02490"
"20373","122.20200","10.18371","0.02659"
"20446","122.64000","10.22018","0.02685"
"20519","123.07800","10.25671","0.02678"
"20592","123.51600","10.29319","0.02779"
"20665","123.95400","10.32972","0.02892"
"20738","124.39200","10.36625","0.02971"
"20811","124.83000","10.40266","0.03100"
"20884","125.26800","10.43919","0.03195"
"20957","125.70600","10.47572","0.03288"
"21030","126.14400","10.51220","0.03388"
"21103","126.58200","10.54873","0.03533"
"21176","127.02000","10.58520","0.03346"
"21249","127.45800","10.62167","0.03237"
"21322","127.89600","10.65820","0.03307"
"21395","128.33400","10.69473","0.03293"
"21468","128.77200","10.73127","0.03363"
"21541","129.21000","10.76774","0.03478"
"21614","129.64800","10.80421","0.03463"
"21687","130.08600","10.84074","0.03603"
"21760","130.52400","10.87721","0.03737"
"21833","130.96200","10.91374","0.03748"
"21906","131.40000","10.95021","0.03907"
"21979","131.83800","10.98669","0.04054"
"22052","132.27600","11.02316","0.04021"
"22125","132.71400","11.05969","0.04241"
"22198","133.15200","11.09622","0.04336"
"22271","133.59000","11.13275","0.04504"
"22344","134.02800","11.16916","0.04613"
"22417","134.46600","11.20569","0.04675"
"22490","134.90400","11.24217","0.04753"
"22563","135.34200","11.27876","0.04962"
"22636","135.78000","11.31523","0.05048"
"22709","136.21800","11.35170","0.05111"
"22782","136.65600","11.38817","0.05211"
"22855","137.09400","11.42470","0.05264"
"22928","137.53200","11.46124","0.05345"
"23001","137.97000","11.49777","0.05372"
"23074","138.40800","11.53424","0.05427"
"23147","138.84600","11.57071","0.05495"
"23220","139.28400","11.60718","0.05513"
"23293","139.72200","11.64365","0.05532"
"23366","140.16000","11.68024","0.05587"
"23439","140.59800","11.71672","0.05614"
"23512","141.03600","11.75325","0.05678"
"23585","141.47400","11.78966","0.05689"
"23658","141.91200","11.82619","0.05802"
"23731","142.35000","11.86272","0.05836"
"23804","142.78800","11.89919","0.05976"
"23877","143.22600","11.93572","0.06090"
"23950","143.66400","11.97214","0.06181"
"24023","144.10200","12.00867","0.06158"
"24096","144.54000","12.04526","0.06339"
"24169","144.97800","12.08173","0.06561"
"24242","145.41600","12.11820","0.06811"
"24315","145.85400","12.15473","0.07054"
"24388","146.29200","12.19121","0.07372"
"24461","146.73000","12.22774","0.07505"
"24534","147.16800","12.26427","0.07741"
"24607","147.60600","12.30074","0.07572"
"24680","148.04400","12.33721","0.05548"
"24753","148.48200","12.37368","0.05714"
"24826","148.92000","12.41021","0.05863"
"24899","149.35800","12.44674","0.06088"
"24972","149.79600","12.48322","0.05884"
"25045","150.23400","12.51975","0.06115"
"25118","150.67200","12.55616","0.06280"
"25191","151.11000","12.59269","0.06621"
"25264","151.54800","12.62922","0.06976"
"25337","151.98600","12.66575","0.07269"
"25410","152.42400","12.70223","0.07649"
"25483","152.86200","12.73870","0.07847"
"25556","153.30000","12.77517","0.08212"
"25629","153.73800","12.81170","0.08489"
"25702","154.17600","12.84823","0.08847"
"25775","154.61400","12.88476","0.09119"
"25848","155.05200","12.92118","0.09276"
"25921","155.49000","12.95771","0.09051"
"25994","155.92800","12.99418","0.09286"
"26067","156.36600","13.03071","0.09558"
"26140","156.80400","13.06724","0.09808"
"26213","157.24200","13.10371","0.09949"
"26286","157.68000","13.14012","0.10101"
"26359","158.11800","13.17666","0.10302"
"26432","158.55600","13.21319","0.10540"
"26505","158.99400","13.24972","0.10679"
"26578","159.43200","13.28625","0.10788"
"26651","159.87000","13.32266","0.10705"
"26724","160.30800","13.35919","0.10869"
"26797","160.74600","13.39567","0.10961"
"26870","161.18400","13.43226","0.06390"
"26943","161.62200","13.46879","0.06566"
"27016","162.06000","13.50526","0.06811"
"27089","162.49800","13.54167","0.07588"
"27162","162.93600","13.57820","0.07860"
"27235","163.37400","13.61473","0.08154"
"27308","163.81200","13.65121","0.08629"
"27381","164.25000","13.68774","0.08897"
"27454","164.68800","13.72421","0.09356"
"27527","165.12600","13.76068","0.09686"
"27600","165.56400","13.79715","0.09943"
"27673","166.00200","13.83374","0.10140"
"27746","166.44000","13.87022","0.10280"
"27819","166.87800","13.90669","0.10459"
"27892","167.31600","13.94310","0.10581"
"27965","167.75400","13.97963","0.10846"
"28038","168.19200","14.01622","0.11069"
"28111","168.63000","14.05275","0.11553"
"28184","169.06800","14.08922","0.11659"
"28257","169.50600","14.12570","0.11934"
"28330","169.94400","14.16217","0.12329"
"28403","170.38200","14.19876","0.12773"
"28476","170.82000","14.23523","0.13074"
"28549","171.25800","14.27176","0.13375"
"28622","171.69600","14.30823","0.13627"
"28695","172.13400","14.34471","0.13816"
"28768","172.57200","14.38124","0.13942"
"28841","173.01000","14.41771","0.14060"
"28914","173.44800","14.45424","0.14157"
"28987","173.88600","14.49071","0.14309"
"29060","174.32400","14.52718","0.14407"
"29133","174.76200","14.56365","0.14506"
"29206","175.20000","14.60019","0.14581"
"29279","175.63800","14.63666","0.14648"
"29352","176.07600","14.67325","0.13855"
"29425","176.51400","14.70966","0.10784"
"29498","176.95200","14.74613","0.10861"
"29571","177.39000","14.78266","0.11116"
"29644","177.82800","14.81920","0.11685"
"29717","178.26600","14.85573","0.12073"
"29790","178.70400","14.89220","0.12416"
"29863","179.14200","14.92867","0.12549"
"29936","179.58000","14.96520","0.12957"
"30009","180.01800","15.00173","0.13207"
"30082","180.45600","15.03826","0.13574"
"30155","180.89400","15.07468","0.13756"
"30228","181.33200","15.11121","0.13968"
"30301","181.77000","15.14768","0.14103"
"30374","182.20800","15.18421","0.14252"
"30447","182.64600","15.22074","0.14365"
"30520","183.08400","15.25721","0.14436"
"30593","183.52200","15.29368","0.14472"
"30666","183.96000","15.33016","0.14600"
"30739","184.39800","15.36669","0.14659"
"30812","184.83600","15.40322","0.14737"
"30885","185.27400","15.43969","0.14857"
"30958","185.71200","15.47622","0.10544"
"31031","186.15000","15.51263","0.03178"
"31104","186.58800","15.54917","0.03386"
"31177","187.02600","15.58576","0.03389"
"31250","187.46400","15.62229","0.03574"
"31323","187.90200","15.65876","0.03968"
"31396","188.34000","15.69523","0.04262"
"31469","188.77800","15.73164","0.04479"
"31542","189.21600","15.76823","0.04924"
"31615","189.65400","15.80470","0.05097"
"31688","190.09200","15.84124","0.05162"
"31761","190.53000","15.87765","0.05301"
"31834","190.96800","15.91418","0.05453"
"31907","191.40600","15.95065","0.05582"
"31980","191.84400","15.98724","0.05646"
"32053","192.28200","16.02371","0.05747"
"32126","192.72000","16.06025","0.05945"
"32199","193.15800","16.09666","0.06092"
"32272","193.59600","16.13319","0.06237"
"32345","194.03400","16.16972","0.06507"
"32418","194.47200","16.20625","0.06812"
"32491","194.91000","16.24272","0.06981"
"32564","195.34800","16.27925","0.07287"
"32637","195.78600","16.31573","0.07507"
"32710","196.22400","16.35220","0.07790"
"32783","196.66200","16.38873","0.08120"
"32856","197.10000","16.42526","0.08387"
"32929","197.53800","16.46173","0.08565"
"33002","197.97600","16.49814","0.08919"
"33075","198.41400","16.53473","0.09168"
"33148","198.85200","16.57121","0.09452"
"33221","199.29000","16.60768","0.09669"
"33294","199.72800","16.64421","0.09875"
"33367","200.16600","16.68068","0.10039"
"33440","200.60400","16.71721","0.10185"
"33513","201.04200","16.75368","0.10288"
"33586","201.48000","16.79016","0.10501"
"33659","201.91800","16.82675","0.10716"
"33732","202.35600","16.86322","0.11004"
"33805","202.79400","16.89969","0.11316"
"33878","203.23200","16.93622","0.11750"
"33951","203.67000","16.97275","0.12068"
"34024","204.10800","17.00922","0.12442"
"34097","204.54600","17.04570","0.12813"
"34170","204.98400","17.08223","0.13049"
"34243","205.42200","17.11870","0.13289"
"34316","205.86000","17.15523","0.13549"
"34389","206.29800","17.19170","0.13783"
"34462","206.73600","17.22824","0.13950"
"34535","207.17400","17.26464","0.14146"
"34608","207.61200","17.30118","0.14277"
"34681","208.05000","17.33771","0.14418"
"34754","208.48800","17.37424","0.14505"
"34827","208.92600","17.41065","0.14580"
"34900","209.36400","17.44718","0.14682"
"34973","209.80200","17.48366","0.14775"
"35046","210.24000","17.52019","0.14837"
"35119","210.67800","17.55672","0.14960"
"35192","211.11600","17.59325","0.15074"
"35265","211.55400","17.62972","0.15271"
"35338","211.99200","17.66619","0.15515"
"35411","212.43000","17.70266","0.15711"
"35484","212.86800","17.73926","0.15957"
"35557","213.30600","17.77573","0.16257"
"35630","213.74400","17.81220","0.16548"
"35703","214.18200","17.84867","0.16969"
"35776","214.62000","17.88514","0.17088"
"35849","215.05800","17.92173","0.15123"
"35922","215.49600","17.95820","0.14127"
"35995","215.93400","17.99474","0.14381"
"36068","216.37200","18.03121","0.14505"
"36141","216.81000","18.06768","0.14687"
"36214","217.24800","18.10415","0.14817"
"36287","217.68600","18.14074","0.14968"
"36360","218.12400","18.17721","0.15148"
"36433","218.56200","18.21375","0.15233"
"36506","219.00000","18.25010","0.02651"
"36579","219.43800","18.28669","0.02324"
"36652","219.87600","18.32322","0.02444"
"36725","220.31400","18.35975","0.02818"
"36798","220.75200","18.39622","0.03070"
"36871","221.19000","18.43270","0.03745"
"36944","221.62800","18.46917","0.03919"
"37017","222.06600","18.50570","0.04139"
"37090","222.50400","18.54223","0.04318"
"37163","222.94200","18.57870","0.04665"
"37236","223.38000","18.61523","0.04978"
"37309","223.81800","18.65164","0.05059"
"37382","224.25600","18.68818","0.05153"
"37455","224.69400","18.72471","0.05343"
"37528","225.13200","18.76118","0.05408"
"37601","225.57000","18.79771","0.05486"
"37674","226.00800","18.83418","0.05569"
"37747","226.44600","18.87071","0.05689"
"37820","226.88400","18.90718","0.05815"
"37893","227.32200","18.94372","0.05919"
"37966","227.76000","18.98025","0.06052"
"38039","228.19800","19.01672","0.06249"
"38112","228.63600","19.05313","0.06401"
"38185","229.07400","19.08972","0.06643"
"38258","229.51200","19.12625","0.06852"
"38331","229.95000","19.16273","0.07040"
"38404","230.38800","19.19920","0.07309"
"38477","230.82600","19.23567","0.07526"
"38550","231.26400","19.27220","0.07747"
"38623","231.70200","19.30873","0.07922"
"38696","232.14000","19.34520","0.07961"
"38769","232.57800","19.38173","0.08376"
"38842","233.01600","19.41821","0.08656"
"38915","233.45400","19.45468","0.08818"
"38988","233.89200","19.49115","0.09084"
"39061","234.33000","19.52774","0.09323"
"39134","234.76800","19.56421","0.09450"
"39207","235.20600","19.60074","0.09621"
"39280","235.64400","19.63715","0.09775"
"39353","236.08200","19.67369","0.09932"
"39426","236.52000","19.71022","0.10036"
"39499","236.95800","19.74669","0.10091"
"39572","237.39600","19.78328","0.10147"
"39645","237.83400","19.81969","0.10244"
"39718","238.27200","19.85616","0.10328"
"39791","238.71000","19.89275","0.10381"
"39864","239.14800","19.92922","0.10546"
"39937","239.58600","19.96570","0.10607"
"40010","240.02400","20.00217","0.10756"
"40083","240.46200","20.03864","0.10826"
"40156","240.90000","20.07523","0.11016"
"40229","241.33800","20.11170","0.11222"
"40302","241.77600","20.14818","0.11392"
"40375","242.21400","20.18471","0.11531"
"40448","242.65200","20.22112","0.11780"
"40521","243.09000","20.25765","0.11960"
"40594","243.52800","20.29418","0.12148"
"40667","243.96600","20.33071","0.12351"
"40740","244.40400","20.36724","0.12589"
"40813","244.84200","20.40366","0.12718"
"40886","245.28000","20.44019","0.12865"
"40959","245.71800","20.47672","0.12817"
"41032","246.15600","20.51325","0.12932"
"41105","246.59400","20.54978","0.13109"
"41178","247.03200","20.58619","0.13186"
"41251","247.47000","20.62267","0.13376"
"41324","247.90800","20.65919","0.13540"
"41397","248.34600","20.69573","0.13667"
"41470","248.78400","20.73220","0.13751"
"41543","249.22200","20.76873","0.13943"
"41616","249.66000","20.80520","0.14040"
"41689","250.09800","20.84173","0.14172"
"41762","250.53600","20.87820","0.14180"
"41835","250.97400","20.91474","0.14314"
"41908","251.41200","20.95121","0.14362"
"41981","251.85000","20.98774","0.14441"
"42054","252.28800","21.02415","0.14509"
"42127","252.72600","21.06075","0.14585"
"42200","253.16400","21.09722","0.14599"
"42273","253.60200","21.13375","0.14713"
"42346","254.04000","21.17022","0.14739"
"42419","254.47800","21.20669","0.14809"
"42492","254.91600","21.24322","0.14826"
"42565","255.35400","21.27969","0.03080"
"42638","255.79200","21.31623","0.03799"
"42711","256.23000","21.35276","0.04447"
"42784","256.66800","21.38917","0.04773"
"42857","257.10600","21.42570","0.04919"
"42930","257.54400","21.46229","0.04914"
"43003","257.98200","21.49876","0.05042"
"43076","258.42000","21.53523","0.05365"
"43149","258.85800","21.57170","0.05622"
"43222","259.29600","21.60818","0.05726"
"43295","259.73400","21.64465","0.05881"
"43368","260.17200","21.68118","0.06238"
"43441","260.61000","21.71771","0.06522"
"43514","261.04800","21.75424","0.06830"
"43587","261.48600","21.79066","0.07305"
"43660","261.92400","21.82718","0.07701"
"43733","262.36200","21.86378","0.07993"
"43806","262.80000","21.90025","0.08496"
"43879","263.23800","21.93672","0.08911"
"43952","263.67600","21.97319","0.09207"
"44025","264.11400","22.00966","0.09583"
"44098","264.55200","22.04625","0.09840"
"44171","264.99000","22.08273","0.10053"
"44244","265.42800","22.11926","0.10270"
"44317","265.86600","22.15567","0.10463"
"44390","266.30400","22.19214","0.10758"
"44463","266.74200","22.22873","0.11179"
"44536","267.18000","22.26520","0.11622"
"44609","267.61800","22.30173","0.12065"
"44682","268.05600","22.33821","0.12532"
"44755","268.49400","22.37462","0.12898"
"44828","268.93200","22.41115","0.13188"
"44901","269.37000","22.44774","0.13224"
"44974","269.80800","22.48421","0.13333"
"45047","270.24600","22.52074","0.13554"
"45120","270.68400","22.55721","0.13321"
"45193","271.12200","22.59369","0.02259"
"45266","271.56000","22.63022","0.02148"
"45339","271.99800","22.66675","0.02553"
"45412","272.43600","22.70328","0.03069"
"45485","272.87400","22.73969","0.02784"
"45558","273.31200","22.77617","0.03198"
"45631","273.75000","22.81269","0.03231"
"45704","274.18800","22.84923","0.03149"
"45777","274.62600","22.88570","0.03308"
"45850","275.06400","22.92223","0.03336"
"45923","275.50200","22.95864","0.03304"
"45996","275.94000","22.99517","0.03430"
"46069","276.37800","23.03170","0.03358"
"46142","276.81600","23.06818","0.03283"
"46215","277.25400","23.10471","0.03277"
"46288","277.69200","23.14118","0.03426"
"46361","278.13000","23.17765","0.03533"
"46434","278.56800","23.21424","0.03691"
"46507","279.00600","23.25078","0.03845"
"46580","279.44400","23.28730","0.03875"
"46653","279.88200","23.32378","0.04035"
"46726","280.32000","23.36013","0.04038"
"46799","280.75800","23.39672","0.04114"
"46872","281.19600","23.43325","0.04211"
"46945","281.63400","23.46972","0.04302"
"47018","282.07200","23.50620","0.04386"
"47091","282.51000","23.54267","0.04442"
"47164","282.94800","23.57914","0.04501"
"47237","283.38600","23.61573","0.04616"
"47310","283.82400","23.65220","0.04710"
"47383","284.26200","23.68873","0.04622"
"47456","284.70000","23.72520","0.04686"
"47529","285.13800","23.76167","0.04731"
"47602","285.57600","23.79815","0.04645"
"47675","286.01400","23.83468","0.04685"
"47748","286.45200","23.87121","0.04769"
"47821","286.89000","23.90774","0.04804"
"47894","287.32800","23.94415","0.04847"
"47967","287.76600","23.98068","0.04917"
"48040","288.20400","24.01727","0.04985"
"48113","288.64200","24.05375","0.04890"
"48186","289.08000","24.09028","0.04882"
"48259","289.51800","24.12669","0.04789"
"48332","289.95600","24.16316","0.04410"
"48405","290.39400","24.19969","0.04628"
"48478","290.83200","24.23623","0.04477"
"48551","291.27000","24.27270","0.04398"
"48624","291.70800","24.30917","0.04350"
"48697","292.14600","24.34564","0.04107"
"48770","292.58400","24.38217","0.04098"
"48843","293.02200","24.41870","0.04145"
"48916","293.46000","24.45523","0.03796"
"48989","293.89800","24.49171","0.04074"
"49062","294.33600","24.52818","0.04116"
"49135","294.77400","24.56471","0.04026"
"49208","295.21200","24.60124","0.04236"
"49281","295.65000","24.63771","0.04256"
"49354","296.08800","24.67424","0.04194"
"49427","296.52600","24.71072","0.04388"
"49500","296.96400","24.74719","0.04455"
"49573","297.40200","24.78372","0.04398"
"49646","297.84000","24.82025","0.04411"
"49719","298.27800","24.85672","0.04394"
"49792","298.71600","24.89319","0.04517"
"49865","299.15400","24.92966","0.04565"
"49938","299.59200","24.96620","0.04640"
"50011","300.03000","25.00273","0.04745"
"50084","300.46800","25.03920","0.04858"
"50157","300.90600","25.07573","0.04914"
"50230","301.34400","25.11214","0.04846"
"50303","301.78200","25.14867","0.04961"
"50376","302.22000","25.18521","0.05051"
"50449","302.65800","25.22174","0.05055"
"50522","303.09600","25.25827","0.05110"
"50595","303.53400","25.29474","0.05127"
"50668","303.97200","25.33115","0.05189"
"50741","304.41000","25.36774","0.05269"
"50814","304.84800","25.40421","0.05346"
"50887","305.28600","25.44074","0.05391"
"50960","305.72400","25.47721","0.05435"
"51033","306.16200","25.51369","0.05482"
"51106","306.60000","25.55016","0.05496"
"51179","307.03800","25.58669","0.05550"
"51252","307.47600","25.62322","0.05619"
"51325","307.91400","25.65969","0.05584"
"51398","308.35200","25.69617","0.05496"
"51471","308.79000","25.73264","0.05559"
"51544","309.22800","25.76917","0.05606"
"51617","309.66600","25.80570","0.05683"
"51690","310.10400","25.84223","0.05749"
"51763","310.54200","25.87871","0.05758"
"51836","310.98000","25.91518","0.06061"
"51909","311.41800","25.95171","0.05931"
"51982","311.85600","25.98824","0.05987"
"52055","312.29400","26.02477","0.06090"
"52128","312.73200","26.06124","0.06185"
"52201","313.17000","26.09771","0.06379"
"52274","313.60800","26.13419","0.06555"
"52347","314.04600","26.17072","0.06691"
"52420","314.48400","26.20719","0.06790"
"52493","314.92200","26.24378","0.06973"
"52566","315.36000","26.28019","0.07091"
"52639","315.79800","26.31666","0.07214"
"52712","316.23600","26.35320","0.07392"
"52785","316.67400","26.38979","0.07518"
"52858","317.11200","26.42620","0.07648"
"52931","317.55000","26.46267","0.07761"
"53004","317.98800","26.49914","0.07870"
"53077","318.42600","26.53573","0.08047"
"53150","318.86400","26.57220","0.08136"
"53223","319.30200","26.60873","0.08286"
"53296","319.74000","26.64520","0.08357"
"53369","320.17800","26.68174","0.08530"
"53442","320.61600","26.71821","0.08705"
"53515","321.05400","26.75474","0.08735"
"53588","321.49200","26.79121","0.03684"
"53661","321.93000","26.82774","0.03730"
"53734","322.36800","26.86421","0.04019"
"53807","322.80600","26.90069","0.03935"
"53880","323.24400","26.93722","0.04126"
"53953","323.68200","26.97375","0.04432"
"54026","324.12000","27.01022","0.04410"
"54099","324.55800","27.04669","0.04505"
"54172","324.99600","27.08317","0.04530"
"54245","325.43400","27.11969","0.04693"
"54318","325.87200","27.15623","0.04810"
"54391","326.31000","27.19270","0.04847"
"54464","326.74800","27.22923","0.04935"
"54537","327.18600","27.26570","0.04975"
"54610","327.62400","27.30217","0.05033"
"54683","328.06200","27.33870","0.05122"
"54756","328.50000","27.37524","0.05189"
"54829","328.93800","27.41177","0.05200"
"54902","329.37600","27.44824","0.05235"
"54975","329.81400","27.48465","0.05305"
"55048","330.25200","27.52118","0.05336"
"55121","330.69000","27.55771","0.05380"
"55194","331.12800","27.59425","0.05398"
"55267","331.56600","27.63072","0.05412"
"55340","332.00400","27.66713","0.05453"
"55413","332.44200","27.70366","0.05473"
"55486","332.88000","27.74019","0.05520"
"55559","333.31800","27.77672","0.05562"
"55632","333.75600","27.81319","0.05556"
"55705","334.19400","27.84966","0.05582"
"55778","334.63200","27.88620","0.05652"
"55851","335.07000","27.92273","0.05658"
"55924","335.50800","27.95920","0.05657"
"55997","335.94600","27.99573","0.05711"
"56070","336.38400","28.03220","0.05466"
"56143","336.82200","28.06867","0.05402"
"56216","337.26000","28.10514","0.05491"
"56289","337.69800","28.14168","0.05536"
"56362","338.13600","28.17827","0.05527"
"56435","338.57400","28.21474","0.01107"
"56508","339.01200","28.25115","0.00639"
"56581","339.45000","28.28762","0.01018"
"56654","339.88800","28.32422","0.00822"
"56727","340.32600","28.36075","0.00777"
"56800","340.76400","28.39722","0.00935"
"56873","341.20200","28.43369","0.00956"
"56946","341.64000","28.47016","0.00954"
"57019","342.07800","28.50669","0.00943"
"57092","342.51600","28.54329","0.01007"
"57165","342.95400","28.57970","0.01187"
"57238","343.39200","28.61617","0.01199"
"57311","343.83000","28.65264","0.01102"
"57384","344.26800","28.68917","0.01256"
"57457","344.70600","28.72570","0.01341"
"57530","345.14400","28.76223","0.01358"
"57603","345.58200","28.79877","0.01386"
"57676","346.02000","28.83518","0.01385"
"57749","346.45800","28.87165","0.01478"
"57822","346.89600","28.90818","0.01458"
"57895","347.33400","28.94477","0.01479"
"57968","347.77200","28.98130","0.01313"
"58041","348.21000","29.01771","0.01389"
"58114","348.64800","29.05412","0.01424"
"58187","349.08600","29.09066","0.01514"
"58260","349.52400","29.12719","0.01547"
"58333","349.96200","29.16366","0.01632"
"58406","350.40000","29.20025","0.01105"
"58479","350.83800","29.23672","0.01256"
"58552","351.27600","29.27320","0.01397"
"58625","351.71400","29.30973","0.01427"
"58698","352.15200","29.34620","0.01493"
"58771","352.59000","29.38279","0.01629"
"58844","353.02800","29.41920","0.01651"
"58917","353.46600","29.45568","0.01735"
"58990","353.90400","29.49226","0.01771"
"59063","354.34200","29.52874","0.01881"
"59136","354.78000","29.56527","0.01934"
"59209","355.21800","29.60174","0.01942"
"59282","355.65600","29.63821","0.01970"
"59355","356.09400","29.67468","0.02035"
"59428","356.53200","29.71121","0.02043"
"59501","356.97000","29.74775","0.02013"
"59574","357.40800","29.78422","0.02025"
"59647","357.84600","29.82063","0.02120"
"59720","358.28400","29.85722","0.02225"
"59793","358.72200","29.89369","0.02098"
"59866","359.16000","29.93022","0.02086"
"59939","359.59800","29.96669","0.02203"
"60012","360.03600","30.00316","0.02064"
"60085","360.47400","30.03964","0.02142"
"60158","360.91200","30.07617","0.02169"
"60231","361.35000","30.11270","0.02253"
"60304","361.78800","30.14929","0.02270"
"60377","362.22600","30.18570","0.02246"
"60450","362.66400","30.22217","0.02250"
"60523","363.10200","30.25865","0.02277"
"60596","363.54000","30.29524","0.02275"
"60669","363.97800","30.33171","0.02336"
"60742","364.41600","30.36824","0.02325"
"60815","364.85400","30.40471","0.02362"
"60888","365.29200","30.44113","0.02452"
"60961","365.73000","30.47772","0.02312"
"61034","366.16800","30.51419","0.02500"
"61107","366.60600","30.55078","0.02456"
"61180","367.04400","30.58719","0.02374"
"61253","367.48200","30.62366","0.02289"
"61326","367.92000","30.66019","0.02386"
"61399","368.35800","30.69673","0.02347"
"61472","368.79600","30.73320","0.02433"
"61545","369.23400","30.76973","0.02360"
"61618","369.67200","30.80614","0.02333"
"61691","370.11000","30.84267","0.02332"
"61764","370.54800","30.87920","0.02299"
"61837","370.98600","30.91574","0.02300"
"61910","371.42400","30.95221","0.02357"
"61983","371.86200","30.98874","0.02354"
"62056","372.30000","31.02521","0.02423"
"62129","372.73800","31.06174","0.02352"
"62202","373.17600","31.09827","0.02379"
"62275","373.61400","31.13474","0.02369"
"62348","374.05200","31.17122","0.02389"
"62421","374.49000","31.20762","0.02314"
"62494","374.92800","31.24422","0.02427"
"62567","375.36600","31.28075","0.02414"
"62640","375.80400","31.31722","0.02481"
"62713","376.24200","31.35369","0.02494"
"62786","376.68000","31.39016","0.02523"
"62859","377.11800","31.42663","0.02556"
"62932","377.55600","31.46322","0.02593"
"63005","377.99400","31.49969","0.02636"
"63078","378.43200","31.53623","0.02692"
"63151","378.87000","31.57270","0.02759"
"63224","379.30800","31.60917","0.02690"
"63297","379.74600","31.64576","0.02802"
"63370","380.18400","31.68223","0.02796"
"63443","380.62200","31.71877","0.02781"
"63516","381.06000","31.75524","0.02188"
"63589","381.49800","31.79171","0.02269"
"63662","381.93600","31.82818","0.02384"
"63735","382.37400","31.86471","0.02432"
"63808","382.81200","31.90124","0.02426"
"63881","383.25000","31.93772","0.02250"
"63954","383.68800","31.97412","0.02269"
"64027","384.12600","32.01065","0.02334"
"64100","384.56400","32.04713","0.02208"
"64173","385.00200","32.08372","0.02317"
"64246","385.44000","32.12019","0.02362"
"64319","385.87800","32.15667","0.02448"
"64392","386.31600","32.19320","0.02410"
"64465","386.75400","32.22972","0.02323"
"64538","387.19200","32.26626","0.02421"
"64611","387.63000","32.30273","0.02445"
"64684","388.06800","32.33920","0.02356"
"64757","388.50600","32.37567","0.02412"
"64830","388.94400","32.41220","0.02422"
"64903","389.38200","32.44868","0.02328"
"64976","389.82000","32.48521","0.02441"
"65049","390.25800","32.52174","0.02436"
"65122","390.69600","32.55821","0.02427"
"65195","391.13400","32.59462","0.02496"
"65268","391.57200","32.63121","0.02547"
"65341","392.01000","32.66774","0.02463"
"65414","392.44800","32.70422","0.02501"
"65487","392.88600","32.74068","0.02562"
"65560","393.32400","32.77710","0.02444"
"65633","393.76200","32.81369","0.02563"
"65706","394.20000","32.85022","0.02522"
"65779","394.63800","32.88670","0.02541"
"65852","395.07600","32.92323","0.02597"
"65925","395.51400","32.95964","0.02688"
"65998","395.95200","32.99623","0.02673"
"66071","396.39000","33.03276","0.02763"
"66144","396.82800","33.06923","0.02766"
"66217","397.26600","33.10577","0.02753"
"66290","397.70400","33.14217","0.02783"
"66363","398.14200","33.17865","0.02872"
"66436","398.58000","33.21518","0.02967"
"66509","399.01800","33.25171","0.02953"
"66582","399.45600","33.28824","0.03067"
"66655","399.89400","33.32471","0.03007"
"66728","400.33200","33.36113","0.02965"
"66801","400.77000","33.39766","0.03038"
"66874","401.20800","33.43419","0.03037"
"66947","401.64600","33.47072","0.03066"
"67020","402.08400","33.50719","0.02189"
"67093","402.52200","33.54366","0.02266"
"67166","402.96000","33.58019","0.02455"
"67239","403.39800","33.61666","0.02541"
"67312","403.83600","33.65319","0.02752"
"67385","404.27400","33.68979","0.02693"
"67458","404.71200","33.72626","0.02726"
"67531","405.15000","33.76273","0.02684"
"67604","405.58800","33.79920","0.02705"
"67677","406.02600","33.83567","0.02748"
"67750","406.46400","33.87226","0.02690"
"67823","406.90200","33.90874","0.02580"
"67896","407.34000","33.94521","0.02589"
"67969","407.77800","33.98168","0.02516"
"68042","408.21600","34.01821","0.02573"
"68115","408.65400","34.05468","0.02437"
"68188","409.09200","34.09122","0.02339"
"68261","409.53000","34.12769","0.02312"
"68334","409.96800","34.16416","0.02400"
"68407","410.40600","34.20063","0.02492"
"68480","410.84400","34.23722","0.02372"
"68553","411.28200","34.27369","0.02390"
"68626","411.72000","34.31022","0.02464"
"68699","412.15800","34.34669","0.02171"
"68772","412.59600","34.38322","0.02290"
"68845","413.03400","34.41976","0.02197"
"68918","413.47200","34.45629","0.02258"
"68991","413.91000","34.49276","0.02239"
"69064","414.34800","34.52923","0.01950"
"69137","414.78600","34.56570","0.01822"
"69210","415.22400","34.60218","0.01916"
"69283","415.66200","34.63871","0.01846"
"69356","416.10000","34.67524","0.01937"
"69429","416.53800","34.71171","0.02057"
"69502","416.97600","34.74812","0.01977"
"69575","417.41400","34.78471","0.01971"
"69648","417.85200","34.82125","0.01906"
"69721","418.29000","34.85772","0.01926"
"69794","418.72800","34.89419","0.02030"
"69867","419.16600","34.93066","0.01916"
"69940","419.60400","34.96719","0.01905"
"70013","420.04200","35.00372","0.01897"
"70086","420.48000","35.04019","0.01909"
"70159","420.91800","35.07673","0.01927"
"70232","421.35600","35.11320","0.01877"
"70305","421.79400","35.14973","0.01921"
"70378","422.23200","35.18626","0.01877"
"70451","422.67000","35.22273","0.01973"
"70524","423.10800","35.25926","0.01956"
"70597","423.54600","35.29567","0.01974"
"70670","423.98400","35.33215","0.01999"
"70743","424.42200","35.36868","0.02008"
"70816","424.86000","35.40521","0.02047"
"70889","425.29800","35.44168","0.02045"
"70962","425.73600","35.47821","0.02052"
"71035","426.17400","35.51462","0.02042"
"71108","426.61200","35.55122","0.02076"
"71181","427.05000","35.58769","0.02082"
"71254","427.48800","35.62422","0.02114"
"71327","427.92600","35.66069","0.02086"
"71400","428.36400","35.69716","0.02053"
"71473","428.80200","35.73369","0.02122"
"71546","429.24000","35.77022","0.02146"
"71619","429.67800","35.80676","0.02090"
"71692","430.11600","35.84329","0.02149"
"71765","430.55400","35.87976","0.02105"
"71838","430.99200","35.91617","0.02123"
"71911","431.43000","35.95270","0.02080"
"71984","431.86800","35.98917","0.02170"
"72057","432.30600","36.02570","0.02290"
"72130","432.74400","36.06218","0.02349"
"72203","433.18200","36.09871","0.02229"
"72276","433.62000","36.13518","0.02295"
"72349","434.05800","36.17171","0.02316"
"72422","434.49600","36.20818","0.02436"
"72495","434.93400","36.24471","0.02321"
"72568","435.37200","36.28119","0.02384"
"72641","435.81000","36.31772","0.02414"
"72714","436.24800","36.35419","0.02449"
"72787","436.68600","36.39078","0.02516"
"72860","437.12400","36.42725","0.02595"
"72933","437.56200","36.46372","0.02604"
"73006","438.00000","36.50019","0.02671"
"73079","438.43800","36.53667","0.02817"
"73152","438.87600","36.57326","0.02826"
"73225","439.31400","36.60973","0.02986"
"73298","439.75200","36.64620","0.03008"
"73371","440.19000","36.68267","0.03110"
"73444","440.62800","36.71920","0.03181"
"73517","441.06600","36.75567","0.03146"
"73590","441.50400","36.79221","0.03195"
"73663","441.94200","36.82868","0.03101"
"73736","442.38000","36.86521","0.03293"
"73809","442.81800","36.90162","0.03247"
"73882","443.25600","36.93821","0.03279"
"73955","443.69400","36.97474","0.03315"
"74028","444.13200","37.01122","0.03275"
"74101","444.57000","37.04769","0.03249"
"74174","445.00800","37.08416","0.03287"
"74247","445.44600","37.12069","0.03372"
"74320","445.88400","37.15722","0.03392"
"74393","446.32200","37.19375","0.03354"
"74466","446.76000","37.23022","0.03423"
"74539","447.19800","37.26664","0.03472"
"74612","447.63600","37.30317","0.03480"
"74685","448.07400","37.33970","0.03493"
"74758","448.51200","37.37623","0.03512"
"74831","448.95000","37.41276","0.03553"
"74904","449.38800","37.44923","0.03568"
"74977","449.82600","37.48565","0.03575"
"75050","450.26400","37.52218","0.03577"
"75123","450.70200","37.55871","0.03539"
"75196","451.14000","37.59524","0.03565"
"75269","451.57800","37.63177","0.03637"
"75342","452.01600","37.66813","0.03710"
"75415","452.45400","37.70465","0.03741"
"75488","452.89200","37.74119","0.03558"
"75561","453.33000","37.77772","0.03637"
"75634","453.76800","37.81425","0.03598"
"75707","454.20600","37.85072","0.03644"
"75780","454.64400","37.88719","0.03626"
"75853","455.08200","37.92373","0.03729"
"75926","455.52000","37.96025","0.03766"
"75999","455.95800","37.99679","0.03789"
"76072","456.39600","38.03320","0.03886"
"76145","456.83400","38.06967","0.03863"
"76218","457.27200","38.10620","0.03909"
"76291","457.71000","38.14267","0.03971"
"76364","458.14800","38.17920","0.04106"
"76437","458.58600","38.21573","0.04147"
"76510","459.02400","38.25221","0.04114"
"76583","459.46200","38.28862","0.04309"
"76656","459.90000","38.32515","0.04378"
"76729","460.33800","38.36174","0.02615"
"76802","460.77600","38.39821","0.00658"
"76875","461.21400","38.43468","0.00550"
"76948","461.65200","38.47116","0.00695"
"77021","462.09000","38.50769","0.00861"
"77094","462.52800","38.54428","0.00525"
"77167","462.96600","38.58075","0.00659"
"77240","463.40400","38.61728","0.00938"
"77313","463.84200","38.65369","0.00623"
"77386","464.28000","38.69017","0.00671"
"77459","464.71800","38.72670","0.00739"
"77532","465.15600","38.76323","0.00554"
"77605","465.59400","38.79976","0.00745"
"77678","466.03200","38.83617","0.00645"
"77751","466.47000","38.87264","0.00625"
"77824","466.90800","38.90918","0.00850"
"77897","467.34600","38.94571","0.00623"
"77970","467.78400","38.98224","0.00656"
"78043","468.22200","39.01871","0.00690"
"78116","468.66000","39.05512","0.00599"
"78189","469.09800","39.09166","0.00751"
"78262","469.53600","39.12818","0.00650"
"78335","469.97400","39.16471","0.00631"
"78408","470.41200","39.20119","0.00864"
"78481","470.85000","39.23772","0.00638"
"78554","471.28800","39.27419","0.00701"
"78627","471.72600","39.31072","0.00814"
"78700","472.16400","39.34725","0.00628"
"78773","472.60200","39.38372","0.00849"
"78846","473.04000","39.42020","0.00696"
"78919","473.47800","39.45667","0.00914"
"78992","473.91600","39.49320","0.00789"
"79065","474.35400","39.52973","0.00724"
"79138","474.79200","39.56620","0.00857"
"79211","475.23000","39.60267","0.00784"
"79284","475.66800","39.63921","0.00874"
"79357","476.10600","39.67567","0.00741"
"79430","476.54400","39.71221","0.00947"
"79503","476.98200","39.74868","0.00810"
"79576","477.42000","39.78521","0.00804"
"79649","477.85800","39.82168","0.00960"
"79722","478.29600","39.85815","0.00899"
"79795","478.73400","39.89468","0.01027"
"79868","479.17200","39.93122","0.00945"
"79941","479.61000","39.96769","0.00965"
"80014","480.04800","40.00416","0.01115"
"80087","480.48600","40.04069","0.00998"
"80160","480.92400","40.07722","0.01140"
"80233","481.36200","40.11369","0.01035"
"80306","481.80000","40.15023","0.01136"
"80379","482.23800","40.18664","0.01174"
"80452","482.67600","40.22317","0.01122"
"80525","483.11400","40.25970","0.01240"
"80598","483.55200","40.29623","0.01169"
"80671","483.99000","40.33271","0.01257"
"80744","484.42800","40.36917","0.01317"
"80817","484.86600","40.40570","0.01221"
"80890","485.30400","40.44212","0.01314"
"80963","485.74200","40.47865","0.01210"
"81036","486.18000","40.51524","0.01338"
"81109","486.61800","40.55172","0.01298"
"81182","487.05600","40.58818","0.01253"
"81255","487.49400","40.62466","0.01330"
"81328","487.93200","40.66119","0.01246"
"81401","488.37000","40.69778","0.01335"
"81474","488.80800","40.73425","0.01385"
"81547","489.24600","40.77072","0.01372"
"81620","489.68400","40.80719","0.01424"
"81693","490.12200","40.84367","0.01463"
"81766","490.56000","40.88020","0.01454"
"81839","490.99800","40.91673","0.01531"
"81912","491.43600","40.95325","0.01579"
"81985","491.87400","40.98967","0.01584"
"82058","492.31200","41.02614","0.01198"
"82131","492.75000","41.06268","0.01213"
"82204","493.18800","41.09921","0.01166"
"82277","493.62600","41.13568","0.01264"
"82350","494.06400","41.17221","0.01238"
"82423","494.50200","41.20868","0.01259"
"82496","494.94000","41.24521","0.01328"
"82569","495.37800","41.28175","0.00570"
"82642","495.81600","41.31828","0.00578"
"82715","496.25400","41.35469","0.00645"
"82788","496.69200","41.39122","0.00573"
"82861","497.13000","41.42769","0.00584"
"82934","497.56800","41.46428","0.00688"
"83007","498.00600","41.50075","0.00623"
"83080","498.44400","41.53722","0.00590"
"83153","498.88200","41.57370","0.00620"
"83226","499.32000","41.61016","0.00576"
"83299","499.75800","41.64670","0.00663"
"83372","500.19600","41.68323","0.00638"
"83445","500.63400","41.71970","0.00601"
"83518","501.07200","41.75623","0.00674"
"83591","501.51000","41.79264","0.00533"
"83664","501.94800","41.82918","0.00713"
"83737","502.38600","41.86571","0.00563"
"83810","502.82400","41.90218","0.00638"
"83883","503.26200","41.93871","0.00691"
"83956","503.70000","41.97518","0.00655"
"84029","504.13800","42.01166","0.00654"
"84102","504.57600","42.04824","0.00629"
"84175","505.01400","42.08477","0.00640"
"84248","505.45200","42.12125","0.00642"
"84321","505.89000","42.15772","0.00655"
"84394","506.32800","42.19419","0.00661"
"84467","506.76600","42.23072","0.00615"
"84540","507.20400","42.26725","0.00640"
"84613","507.64200","42.30373","0.00622"
"84686","508.08000","42.34020","0.00630"
"84759","508.51800","42.37667","0.00612"
"84832","508.95600","42.41320","0.00578"
"84905","509.39400","42.44967","0.00585"
"84978","509.83200","42.48621","0.00625"
"85051","510.27000","42.52274","0.00534"
"85124","510.70800","42.55921","0.00561"
"85197","511.14600","42.59562","0.00613"
"85270","511.58400","42.63221","0.00630"
"85343","512.02200","42.66874","0.00558"
"85416","512.46000","42.70527","0.00529"
"85489","512.89800","42.74169","0.00613"
"85562","513.33600","42.77816","0.00574"
"85635","513.77400","42.81469","0.00559"
"85708","514.21200","42.85128","0.00594"
"85781","514.65000","42.88775","0.00532"
"85854","515.08800","42.92422","0.00601"
"85927","515.52600","42.96069","0.00591"
"86000","515.96400","42.99717","0.00504"
"86073","516.40200","43.03370","0.00601"
"86146","516.84000","43.07023","0.00530"
"86219","517.27800","43.10670","0.00618"
"86292","517.71600","43.14317","0.00584"
"86365","518.15400","43.17964","0.00533"
"86438","518.59200","43.21611","0.00526"
"86511","519.03000","43.25271","0.00543"
"86584","519.46800","43.28924","0.00622"
"86657","519.90600","43.32576","0.00541"
"86730","520.34400","43.36218","0.00631"
"86803","520.78200","43.39871","0.00615"
"86876","521.22000","43.43524","0.00543"
"86949","521.65800","43.47172","0.00544"
"87022","522.09600","43.50825","0.00549"
"87095","522.53400","43.54472","0.00538"
"87168","522.97200","43.58119","0.00519"
"87241","523.41000","43.61772","0.00540"
"87314","523.84800","43.65419","0.00527"
"87387","524.28600","43.69066","0.00575"
"87460","524.72400","43.72720","0.00554"
"87533","525.16200","43.76373","0.00510"
"87606","525.60000","43.80014","0.00480"
"87679","526.03800","43.83667","0.00514"
"87752","526.47600","43.87320","0.00473"
"87825","526.91400","43.90967","0.00508"
"87898","527.35200","43.94614","0.00619"
"87971","527.79000","43.98268","0.00514"
"88044","528.22800","44.01921","0.00533"
"88117","528.66600","44.05573","0.00543"
"88190","529.10400","44.09221","0.00504"
"88263","529.54200","44.12874","0.00542"
"88336","529.98000","44.16515","0.00529"
"88409","530.41800","44.20175","0.00576"
"88482","530.85600","44.23827","0.00509"
"88555","531.29400","44.27474","0.00526"
"88628","531.73200","44.31122","0.00521"
"88701","532.17000","44.34769","0.00468"
"88774","532.60800","44.38416","0.00517"
"88847","533.04600","44.42075","0.00542"
"88920","533.48400","44.45717","0.00517"
"88993","533.92200","44.49376","0.00531"
"89066","534.36000","44.53017","0.00471"
"89139","534.79800","44.56670","0.00504"
"89212","535.23600","44.60317","0.00519"
"89285","535.67400","44.63970","0.00501"
"89358","536.11200","44.67617","0.00478"
"89431","536.55000","44.71271","0.00491"
"89504","536.98800","44.74918","0.00551"
"89577","537.42600","44.78571","0.00470"
"89650","537.86400","44.82224","0.00486"
"89723","538.30200","44.85877","0.00532"
"89796","538.74000","44.89524","0.00489"
"89869","539.17800","44.93172","0.00500"
"89942","539.61600","44.96813","0.00506"
"90015","540.05400","45.00471","0.00525"
"90088","540.49200","45.04125","0.00499"
"90161","540.93000","45.07766","0.00521"
"90209","541.21400","45.10134","0.00491"