File: Trajectories_together/170226_1Specimen_RawData_9.csv
"","V1","V2","V3"
"1","End date","2/26/2017",""
"2","Specimen label","6AT_47",""
"3","Maximum Load","0.19279","N"
"4","Time","Extension","Load"
"5","(s)","(mm)","(N)"
"6","0.00000","0.00000","0.00008"
"38","0.19200","0.01327","-0.00023"
"70","0.38400","0.03217","0.00009"
"102","0.57600","0.04831","0.00037"
"134","0.76800","0.06421","0.00051"
"166","0.96000","0.08024","0.00063"
"198","1.15200","0.09632","0.00020"
"230","1.34400","0.11217","0.00049"
"262","1.53600","0.12819","0.00025"
"294","1.72800","0.14427","0.00025"
"326","1.92000","0.16018","0.00009"
"358","2.11200","0.17626","-0.00020"
"390","2.30400","0.19228","-0.00011"
"422","2.49600","0.20819","0.00054"
"454","2.68800","0.22427","0.00002"
"486","2.88000","0.24023","0.00026"
"518","3.07200","0.25620","-0.00009"
"550","3.26400","0.27222","0.00070"
"582","3.45600","0.28819","0.00019"
"614","3.64800","0.30421","0.00027"
"646","3.84000","0.32023","0.00048"
"678","4.03200","0.33620","0.00038"
"710","4.22400","0.35222","0.00073"
"742","4.41600","0.36824","0.00038"
"774","4.60800","0.38421","0.00007"
"806","4.80000","0.40023","0.00089"
"838","4.99200","0.41625","0.00079"
"870","5.18400","0.43216","0.00083"
"902","5.37600","0.44824","0.00046"
"934","5.56800","0.46421","0.00048"
"966","5.76000","0.48017","0.00092"
"998","5.95200","0.49625","0.00014"
"1030","6.14400","0.51222","0.00058"
"1062","6.33600","0.52824","0.00068"
"1094","6.52800","0.54426","0.00065"
"1126","6.72000","0.56023","0.00070"
"1158","6.91200","0.57625","0.00047"
"1190","7.10400","0.59228","0.00059"
"1222","7.29600","0.60818","0.00041"
"1254","7.48800","0.62426","0.00053"
"1286","7.68000","0.64023","-0.00009"
"1318","7.87200","0.65619","0.00094"
"1350","8.06400","0.67227","0.00100"
"1382","8.25600","0.68818","0.00092"
"1414","8.44800","0.70420","0.00076"
"1446","8.64000","0.72022","0.00141"
"1478","8.83200","0.73619","0.00048"
"1510","9.02400","0.75227","0.00120"
"1542","9.21600","0.76824","0.00073"
"1574","9.40800","0.78420","0.00070"
"1606","9.60000","0.80028","0.00037"
"1638","9.79200","0.81625","0.00038"
"1670","9.98400","0.83215","0.00066"
"1702","10.17600","0.84823","0.00038"
"1734","10.36800","0.86426","0.00033"
"1766","10.56000","0.88016","0.00097"
"1798","10.75200","0.89625","0.00047"
"1830","10.94400","0.91221","0.00060"
"1862","11.13600","0.92823","0.00035"
"1894","11.32800","0.94426","0.00078"
"1926","11.52000","0.96022","0.00050"
"1958","11.71200","0.97624","0.00067"
"1990","11.90400","0.99233","0.00033"
"2022","12.09600","1.00823","0.00084"
"2054","12.28800","1.02419","0.00045"
"2086","12.48000","1.04028","0.00106"
"2118","12.67200","1.05618","0.00033"
"2150","12.86400","1.07227","0.00097"
"2182","13.05600","1.08829","0.00085"
"2214","13.24800","1.10419","0.00079"
"2246","13.44000","1.12028","0.00113"
"2278","13.63200","1.13624","0.00029"
"2310","13.82400","1.15220","0.00024"
"2342","14.01600","1.16823","0.00049"
"2374","14.20800","1.18425","0.00094"
"2406","14.40000","1.20022","0.00097"
"2438","14.59200","1.21624","0.00041"
"2470","14.78400","1.23220","0.00075"
"2502","14.97600","1.24829","0.00048"
"2534","15.16800","1.26425","0.00070"
"2566","15.36000","1.28021","0.00080"
"2598","15.55200","1.29624","0.00134"
"2630","15.74400","1.31226","0.00106"
"2662","15.93600","1.32816","0.00015"
"2694","16.12800","1.34425","0.00068"
"2726","16.32000","1.36021","0.00057"
"2758","16.51200","1.37618","0.00061"
"2790","16.70400","1.39220","0.00095"
"2822","16.89600","1.40822","0.00106"
"2854","17.08800","1.42425","0.00097"
"2886","17.28000","1.44021","0.00077"
"2918","17.47200","1.45617","0.00089"
"2950","17.66400","1.47226","0.00070"
"2982","17.85600","1.48822","0.00084"
"3014","18.04800","1.50419","0.00088"
"3046","18.24000","1.52027","0.00067"
"3078","18.43200","1.53623","0.00063"
"3110","18.62400","1.55220","0.00101"
"3142","18.81600","1.56822","0.00112"
"3174","19.00800","1.58424","0.00081"
"3206","19.20000","1.60021","0.00055"
"3238","19.39200","1.61623","0.00109"
"3270","19.58400","1.63225","0.00042"
"3302","19.77600","1.64822","0.00020"
"3334","19.96800","1.66430","0.00041"
"3366","20.16000","1.68021","0.00102"
"3398","20.35200","1.69623","0.00082"
"3430","20.54400","1.71225","0.00105"
"3462","20.73600","1.72816","0.00072"
"3494","20.92800","1.74430","0.00127"
"3526","21.12000","1.76020","-0.00015"
"3558","21.31200","1.77617","-0.00004"
"3590","21.50400","1.79225","0.00016"
"3622","21.69600","1.80821","0.00027"
"3654","21.88800","1.82418","0.00048"
"3686","22.08000","1.84026","0.00061"
"3718","22.27200","1.85623","0.00085"
"3750","22.46400","1.87219","0.00051"
"3782","22.65600","1.88827","0.00100"
"3814","22.84800","1.90418","0.00080"
"3846","23.04000","1.92026","0.00091"
"3878","23.23200","1.93622","0.00096"
"3910","23.42400","1.95213","0.00060"
"3942","23.61600","1.96827","0.00056"
"3974","23.80800","1.98424","0.00057"
"4006","24.00000","2.00020","0.00059"
"4038","24.19200","2.01622","0.00064"
"4070","24.38400","2.03231","0.00132"
"4102","24.57600","2.04821","0.00071"
"4134","24.76800","2.06423","0.00128"
"4166","24.96000","2.08026","0.00096"
"4198","25.15200","2.09622","0.00057"
"4230","25.34400","2.11219","0.00103"
"4262","25.53600","2.12821","0.00112"
"4294","25.72800","2.14423","0.00076"
"4326","25.92000","2.16026","0.00038"
"4358","26.11200","2.17622","0.00101"
"4390","26.30400","2.19224","0.00128"
"4422","26.49600","2.20827","0.00105"
"4454","26.68800","2.22417","0.00092"
"4486","26.88000","2.24031","0.00089"
"4518","27.07200","2.25622","0.00095"
"4550","27.26400","2.27218","0.00095"
"4582","27.45600","2.28826","0.00125"
"4614","27.64800","2.30417","0.00062"
"4646","27.84000","2.32025","0.00125"
"4678","28.03200","2.33622","0.00062"
"4710","28.22400","2.35218","0.00075"
"4742","28.41600","2.36826","0.00101"
"4774","28.60800","2.38423","0.00119"
"4806","28.80000","2.40019","0.00086"
"4838","28.99200","2.41621","0.00109"
"4870","29.18400","2.43224","0.00111"
"4902","29.37600","2.44814","0.00121"
"4934","29.56800","2.46429","0.00107"
"4966","29.76000","2.48025","0.00125"
"4998","29.95200","2.49615","0.00152"
"5030","30.14400","2.51224","0.00167"
"5062","30.33600","2.52820","0.00119"
"5094","30.52800","2.54422","0.00140"
"5126","30.72000","2.56025","0.00126"
"5158","30.91200","2.57621","0.00078"
"5190","31.10400","2.59224","0.00119"
"5222","31.29600","2.60826","0.00130"
"5254","31.48800","2.62416","0.00215"
"5286","31.68000","2.64025","0.00160"
"5318","31.87200","2.65621","0.00128"
"5350","32.06400","2.67217","0.00136"
"5382","32.25600","2.68826","0.00127"
"5414","32.44800","2.70422","0.00117"
"5446","32.64000","2.72018","0.00133"
"5478","32.83200","2.73627","0.00133"
"5510","33.02400","2.75223","0.00167"
"5542","33.21600","2.76820","0.00169"
"5574","33.40800","2.78422","0.00204"
"5606","33.60000","2.80024","0.00132"
"5638","33.79200","2.81621","0.00167"
"5670","33.98400","2.83223","0.00114"
"5702","34.17600","2.84819","0.00138"
"5734","34.36800","2.86422","0.00217"
"5766","34.56000","2.88024","0.00180"
"5798","34.75200","2.89615","0.00187"
"5830","34.94400","2.91223","0.00223"
"5862","35.13600","2.92825","0.00182"
"5894","35.32800","2.94416","0.00194"
"5926","35.52000","2.96024","0.00165"
"5958","35.71200","2.97620","0.00130"
"5990","35.90400","2.99223","0.00174"
"6022","36.09600","3.00819","0.00190"
"6054","36.28800","3.02421","0.00221"
"6086","36.48000","3.04024","0.00237"
"6118","36.67200","3.05620","0.00234"
"6150","36.86400","3.07223","0.00228"
"6182","37.05600","3.08825","0.00202"
"6214","37.24800","3.10421","0.00233"
"6246","37.44000","3.12024","0.00267"
"6278","37.63200","3.13626","0.00236"
"6310","37.82400","3.15222","0.00270"
"6342","38.01600","3.16819","0.00287"
"6374","38.20800","3.18421","0.00224"
"6406","38.40000","3.20023","0.00280"
"6438","38.59200","3.21620","0.00244"
"6470","38.78400","3.23228","0.00274"
"6502","38.97600","3.24825","0.00278"
"6534","39.16800","3.26427","0.00272"
"6566","39.36000","3.28023","0.00239"
"6598","39.55200","3.29626","0.00254"
"6630","39.74400","3.31222","0.00287"
"6662","39.93600","3.32824","0.00307"
"6694","40.12800","3.34421","0.00297"
"6726","40.32000","3.36029","0.00271"
"6758","40.51200","3.37620","0.00302"
"6790","40.70400","3.39216","0.00276"
"6822","40.89600","3.40830","0.00250"
"6854","41.08800","3.42421","0.00326"
"6886","41.28000","3.44017","0.00314"
"6918","41.47200","3.45625","0.00327"
"6950","41.66400","3.47216","0.00339"
"6982","41.85600","3.48824","0.00294"
"7014","42.04800","3.50420","0.00277"
"7046","42.24000","3.52023","0.00228"
"7078","42.43200","3.53625","0.00271"
"7110","42.62400","3.55222","0.00326"
"7142","42.81600","3.56818","0.00358"
"7174","43.00800","3.58426","0.00352"
"7206","43.20000","3.60023","0.00350"
"7238","43.39200","3.61619","0.00326"
"7270","43.58400","3.63221","0.00372"
"7302","43.77600","3.64824","0.00395"
"7334","43.96800","3.66420","0.00320"
"7366","44.16000","3.68022","0.00372"
"7398","44.35200","3.69625","0.00388"
"7430","44.54400","3.71221","0.00388"
"7462","44.73600","3.72830","0.00395"
"7494","44.92800","3.74420","0.00354"
"7526","45.12000","3.76022","0.00377"
"7558","45.31200","3.77631","0.00384"
"7590","45.50400","3.79221","0.00361"
"7622","45.69600","3.80823","0.00352"
"7654","45.88800","3.82426","0.00456"
"7686","46.08000","3.84022","0.00408"
"7718","46.27200","3.85625","0.00360"
"7750","46.46400","3.87227","0.00441"
"7782","46.65600","3.88817","0.00421"
"7814","46.84800","3.90420","0.00416"
"7846","47.04000","3.92022","0.00425"
"7878","47.23200","3.93618","0.00431"
"7910","47.42400","3.95227","0.00461"
"7942","47.61600","3.96823","0.00499"
"7974","47.80800","3.98425","0.00477"
"8006","48.00000","4.00028","0.00489"
"8038","48.19200","4.01624","0.00436"
"8070","48.38400","4.03227","0.00488"
"8102","48.57600","4.04823","0.00457"
"8134","48.76800","4.06419","0.00525"
"8166","48.96000","4.08028","0.00473"
"8198","49.15200","4.09618","0.00482"
"8230","49.34400","4.11226","0.00477"
"8262","49.53600","4.12823","0.00460"
"8294","49.72800","4.14419","0.00493"
"8326","49.92000","4.16022","0.00473"
"8358","50.11200","4.17624","0.00485"
"8390","50.30400","4.19220","0.00489"
"8422","50.49600","4.20829","0.00507"
"8454","50.68800","4.22425","0.00513"
"8486","50.88000","4.24015","0.00510"
"8518","51.07200","4.25624","0.00527"
"8550","51.26400","4.27226","0.00468"
"8582","51.45600","4.28817","0.00522"
"8614","51.64800","4.30425","0.00502"
"8646","51.84000","4.32021","0.00514"
"8678","52.03200","4.33618","0.00539"
"8710","52.22400","4.35232","0.00487"
"8742","52.41600","4.36816","0.00487"
"8774","52.60800","4.38419","0.00470"
"8806","52.80000","4.40027","0.00473"
"8838","52.99200","4.41617","0.00549"
"8870","53.18400","4.43220","0.00470"
"8902","53.37600","4.44828","0.00531"
"8934","53.56800","4.46419","0.00528"
"8966","53.76000","4.48021","0.00519"
"8998","53.95200","4.49629","0.00429"
"9030","54.14400","4.51214","0.00499"
"9062","54.33600","4.52822","0.00494"
"9094","54.52800","4.54424","0.00501"
"9126","54.72000","4.56021","0.00484"
"9158","54.91200","4.57623","0.00513"
"9190","55.10400","4.59219","0.00504"
"9222","55.29600","4.60822","0.00449"
"9254","55.48800","4.62424","0.00437"
"9286","55.68000","4.64021","0.00409"
"9318","55.87200","4.65623","0.00422"
"9350","56.06400","4.67219","0.00437"
"9382","56.25600","4.68822","0.00486"
"9414","56.44800","4.70424","0.00475"
"9446","56.64000","4.72026","0.00446"
"9478","56.83200","4.73623","0.00422"
"9510","57.02400","4.75219","0.00437"
"9542","57.21600","4.76822","0.00398"
"9574","57.40800","4.78418","0.00443"
"9606","57.60000","4.80020","0.00403"
"9638","57.79200","4.81623","0.00403"
"9670","57.98400","4.83225","0.00397"
"9702","58.17600","4.84821","0.00402"
"9734","58.36800","4.86418","0.00435"
"9766","58.56000","4.88020","0.00388"
"9798","58.75200","4.89628","0.00393"
"9830","58.94400","4.91219","0.00363"
"9862","59.13600","4.92827","0.00356"
"9894","59.32800","4.94424","0.00422"
"9926","59.52000","4.96014","0.00331"
"9958","59.71200","4.97628","0.00418"
"9990","59.90400","4.99219","0.00412"
"10022","60.09600","5.00821","0.00434"
"10054","60.28800","5.02423","0.00354"
"10086","60.48000","5.04020","0.00426"
"10118","60.67200","5.05622","0.00411"
"10150","60.86400","5.07224","0.00404"
"10182","61.05600","5.08821","0.00423"
"10214","61.24800","5.10423","0.00357"
"10246","61.44000","5.12026","0.00425"
"10278","61.63200","5.13616","0.00419"
"10310","61.82400","5.15224","0.00365"
"10342","62.01600","5.16827","0.00361"
"10374","62.20800","5.18417","0.00381"
"10406","62.40000","5.20025","0.00379"
"10438","62.59200","5.21628","0.00416"
"10470","62.78400","5.23218","0.00383"
"10502","62.97600","5.24827","0.00314"
"10534","63.16800","5.26423","0.00384"
"10566","63.36000","5.28019","0.00364"
"10598","63.55200","5.29628","0.00360"
"10630","63.74400","5.31218","0.00358"
"10662","63.93600","5.32820","0.00377"
"10694","64.12800","5.34429","0.00278"
"10726","64.32000","5.36019","0.00323"
"10758","64.51200","5.37621","0.00348"
"10790","64.70400","5.39224","0.00362"
"10822","64.89600","5.40820","0.00332"
"10854","65.08800","5.42423","0.00324"
"10886","65.28000","5.44025","0.00309"
"10918","65.47200","5.45615","0.00320"
"10950","65.66400","5.47218","0.00337"
"10982","65.85600","5.48826","0.00289"
"11014","66.04800","5.50422","0.00318"
"11046","66.24000","5.52025","0.00366"
"11078","66.43200","5.53615","0.00329"
"11110","66.62400","5.55224","0.00323"
"11142","66.81600","5.56820","0.00335"
"11174","67.00800","5.58422","0.00377"
"11206","67.20000","5.60019","0.00321"
"11238","67.39200","5.61621","0.00359"
"11270","67.58400","5.63217","0.00354"
"11302","67.77600","5.64826","0.00321"
"11334","67.96800","5.66428","0.00350"
"11366","68.16000","5.68019","0.00306"
"11398","68.35200","5.69627","0.00315"
"11430","68.54400","5.71223","0.00321"
"11462","68.73600","5.72826","0.00289"
"11494","68.92800","5.74422","0.00346"
"11526","69.12000","5.76018","0.00297"
"11558","69.31200","5.77627","0.00285"
"11590","69.50400","5.79223","0.00368"
"11622","69.69600","5.80819","0.00326"
"11654","69.88800","5.82428","0.00329"
"11686","70.08000","5.84024","0.00383"
"11718","70.27200","5.85621","0.00366"
"11750","70.46400","5.87229","0.00334"
"11782","70.65600","5.88825","0.00358"
"11814","70.84800","5.90422","0.00363"
"11846","71.04000","5.92024","0.00302"
"11878","71.23200","5.93620","0.00355"
"11910","71.42400","5.95223","0.00359"
"11942","71.61600","5.96825","0.00316"
"11974","71.80800","5.98422","0.00307"
"12006","72.00000","6.00024","0.00276"
"12038","72.19200","6.01626","0.00297"
"12070","72.38400","6.03223","0.00279"
"12102","72.57600","6.04825","0.00315"
"12134","72.76800","6.06427","0.00308"
"12166","72.96000","6.08012","0.00254"
"12198","73.15200","6.09626","0.00338"
"12230","73.34400","6.11222","0.00292"
"12262","73.53600","6.12813","0.00339"
"12294","73.72800","6.14427","0.00365"
"12326","73.92000","6.16024","0.00294"
"12358","74.11200","6.17620","0.00242"
"12390","74.30400","6.19222","0.00315"
"12422","74.49600","6.20825","0.00274"
"12454","74.68800","6.22421","0.00303"
"12486","74.88000","6.24023","0.00329"
"12518","75.07200","6.25620","0.00323"
"12550","75.26400","6.27222","0.00357"
"12582","75.45600","6.28824","0.00302"
"12614","75.64800","6.30421","0.00284"
"12646","75.84000","6.32029","0.00321"
"12678","76.03200","6.33626","0.00280"
"12710","76.22400","6.35216","0.00295"
"12742","76.41600","6.36824","0.00251"
"12774","76.60800","6.38427","0.00256"
"12806","76.80000","6.40023","0.00343"
"12838","76.99200","6.41619","0.00294"
"12870","77.18400","6.43222","0.00353"
"12902","77.37600","6.44824","0.00318"
"12934","77.56800","6.46427","0.00354"
"12966","77.76000","6.48023","0.00206"
"12998","77.95200","6.49625","0.00318"
"13030","78.14400","6.51228","0.00314"
"13062","78.33600","6.52818","0.00245"
"13094","78.52800","6.54426","0.00299"
"13126","78.72000","6.56023","0.00263"
"13158","78.91200","6.57619","0.00260"
"13190","79.10400","6.59222","0.00319"
"13222","79.29600","6.60818","0.00276"
"13254","79.48800","6.62420","0.00296"
"13286","79.68000","6.64029","0.00307"
"13318","79.87200","6.65619","0.00323"
"13350","80.06400","6.67227","0.00321"
"13382","80.25600","6.68824","0.00272"
"13414","80.44800","6.70420","0.00333"
"13446","80.64000","6.72028","0.00323"
"13478","80.83200","6.73625","0.00363"
"13510","81.02400","6.75221","0.00329"
"13542","81.21600","6.76829","0.00332"
"13574","81.40800","6.78426","0.00322"
"13606","81.60000","6.80016","0.00343"
"13638","81.79200","6.81631","0.00260"
"13670","81.98400","6.83221","0.00254"
"13702","82.17600","6.84817","0.00242"
"13734","82.36800","6.86426","0.00221"
"13766","82.56000","6.88022","0.00239"
"13798","82.75200","6.89618","0.00241"
"13830","82.94400","6.91233","0.00295"
"13862","83.13600","6.92823","0.00249"
"13894","83.32800","6.94426","0.00223"
"13926","83.52000","6.96022","0.00257"
"13958","83.71200","6.97618","0.00249"
"13990","83.90400","6.99227","0.00246"
"14022","84.09600","7.00823","0.00247"
"14054","84.28800","7.02419","0.00257"
"14086","84.48000","7.04022","0.00238"
"14118","84.67200","7.05624","0.00244"
"14150","84.86400","7.07221","0.00251"
"14182","85.05600","7.08817","0.00273"
"14214","85.24800","7.10425","0.00280"
"14246","85.44000","7.12022","0.00279"
"14278","85.63200","7.13624","0.00245"
"14310","85.82400","7.15220","0.00221"
"14342","86.01600","7.16823","0.00290"
"14374","86.20800","7.18425","0.00297"
"14406","86.40000","7.20021","0.00216"
"14438","86.59200","7.21630","0.00268"
"14470","86.78400","7.23226","0.00283"
"14502","86.97600","7.24817","0.00310"
"14534","87.16800","7.26425","0.00268"
"14566","87.36000","7.28021","0.00293"
"14598","87.55200","7.29624","0.00350"
"14630","87.74400","7.31226","0.00258"
"14662","87.93600","7.32822","0.00301"
"14694","88.12800","7.34425","0.00254"
"14726","88.32000","7.36027","0.00251"
"14758","88.51200","7.37624","0.00274"
"14790","88.70400","7.39226","0.00239"
"14822","88.89600","7.40822","0.00313"
"14854","89.08800","7.42419","0.00245"
"14886","89.28000","7.44021","0.00323"
"14918","89.47200","7.45623","0.00309"
"14950","89.66400","7.47220","0.00289"
"14982","89.85600","7.48822","0.00251"
"15014","90.04800","7.50424","0.00306"
"15046","90.24000","7.52021","0.00302"
"15078","90.43200","7.53623","0.00304"
"15110","90.62400","7.55220","0.00312"
"15142","90.81600","7.56822","0.00292"
"15174","91.00800","7.58424","0.00316"
"15206","91.20000","7.60021","0.00333"
"15238","91.39200","7.61623","0.00318"
"15270","91.58400","7.63225","0.00290"
"15302","91.77600","7.64822","0.00292"
"15334","91.96800","7.66430","0.00326"
"15366","92.16000","7.68021","0.00297"
"15398","92.35200","7.69617","0.00322"
"15430","92.54400","7.71225","0.00287"
"15462","92.73600","7.72822","0.00318"
"15494","92.92800","7.74418","0.00324"
"15526","93.12000","7.76026","0.00298"
"15558","93.31200","7.77623","0.00417"
"15590","93.50400","7.79219","0.00341"
"15622","93.69600","7.80827","0.00311"
"15654","93.88800","7.82424","0.00293"
"15686","94.08000","7.84026","0.00325"
"15718","94.27200","7.85628","0.00296"
"15750","94.46400","7.87219","0.00366"
"15782","94.65600","7.88821","0.00344"
"15814","94.84800","7.90424","0.00359"
"15846","95.04000","7.92020","0.00365"
"15878","95.23200","7.93622","0.00292"
"15910","95.42400","7.95225","0.00370"
"15942","95.61600","7.96815","0.00405"
"15974","95.80800","7.98423","0.00337"
"16006","96.00000","8.00026","0.00327"
"16038","96.19200","8.01616","0.00329"
"16070","96.38400","8.03225","0.00370"
"16102","96.57600","8.04821","0.00359"
"16134","96.76800","8.06417","0.00426"
"16166","96.96000","8.08026","0.00355"
"16198","97.15200","8.09622","0.00422"
"16230","97.34400","8.11224","0.00334"
"16262","97.53600","8.12827","0.00395"
"16294","97.72800","8.14423","0.00480"
"16326","97.92000","8.16020","0.00431"
"16358","98.11200","8.17622","0.00371"
"16390","98.30400","8.19224","0.00371"
"16422","98.49600","8.20821","0.00332"
"16454","98.68800","8.22423","0.00354"
"16486","98.88000","8.24019","0.00365"
"16518","99.07200","8.25622","0.00412"
"16550","99.26400","8.27224","0.00379"
"16582","99.45600","8.28826","0.00396"
"16614","99.64800","8.30423","0.00408"
"16646","99.84000","8.32019","0.00492"
"16678","100.03200","8.33622","0.00445"
"16710","100.22400","8.35224","0.00373"
"16742","100.41600","8.36820","0.00455"
"16774","100.60800","8.38429","0.00413"
"16806","100.80000","8.40019","0.00415"
"16838","100.99200","8.41621","0.00444"
"16870","101.18400","8.43224","0.00326"
"16902","101.37600","8.44820","0.00333"
"16934","101.56800","8.46422","0.00334"
"16966","101.76000","8.48025","0.00336"
"16998","101.95200","8.49621","0.00363"
"17030","102.14400","8.51230","0.00381"
"17062","102.33600","8.52826","0.00319"
"17094","102.52800","8.54422","0.00313"
"17126","102.72000","8.56025","0.00310"
"17158","102.91200","8.57621","0.00298"
"17190","103.10400","8.59217","0.00364"
"17222","103.29600","8.60826","0.00373"
"17254","103.48800","8.62428","0.00367"
"17286","103.68000","8.64013","0.00398"
"17318","103.87200","8.65627","0.00329"
"17350","104.06400","8.67223","0.00388"
"17382","104.25600","8.68820","0.00373"
"17414","104.44800","8.70428","0.00415"
"17446","104.64000","8.72024","0.00396"
"17478","104.83200","8.73621","0.00377"
"17510","105.02400","8.75229","0.00397"
"17542","105.21600","8.76814","0.00355"
"17574","105.40800","8.78422","0.00361"
"17606","105.60000","8.80030","0.00395"
"17638","105.79200","8.81621","0.00367"
"17670","105.98400","8.83223","0.00399"
"17702","106.17600","8.84825","0.00375"
"17734","106.36800","8.86416","0.00388"
"17766","106.56000","8.88024","0.00351"
"17798","106.75200","8.89626","0.00392"
"17830","106.94400","8.91223","0.00416"
"17862","107.13600","8.92825","0.00436"
"17894","107.32800","8.94427","0.00376"
"17926","107.52000","8.96018","0.00398"
"17958","107.71200","8.97620","0.00360"
"17990","107.90400","8.99217","0.00423"
"18022","108.09600","9.00819","0.00450"
"18054","108.28800","9.02421","0.00399"
"18086","108.48000","9.04018","0.00425"
"18118","108.67200","9.05620","0.00405"
"18150","108.86400","9.07222","0.00442"
"18182","109.05600","9.08825","0.00450"
"18214","109.24800","9.10421","0.00503"
"18246","109.44000","9.12024","0.00389"
"18278","109.63200","9.13626","0.00463"
"18310","109.82400","9.15222","0.00432"
"18342","110.01600","9.16819","0.00403"
"18374","110.20800","9.18421","0.00415"
"18406","110.40000","9.20023","0.00422"
"18438","110.59200","9.21614","0.00436"
"18470","110.78400","9.23222","0.00432"
"18502","110.97600","9.24824","0.00481"
"18534","111.16800","9.26415","0.00489"
"18566","111.36000","9.28035","0.00443"
"18598","111.55200","9.29620","0.00483"
"18630","111.74400","9.31216","0.00486"
"18662","111.93600","9.32824","0.00432"
"18694","112.12800","9.34427","0.00473"
"18726","112.32000","9.36023","0.00476"
"18758","112.51200","9.37626","0.00467"
"18790","112.70400","9.39222","0.00487"
"18822","112.89600","9.40824","0.00430"
"18854","113.08800","9.42427","0.00522"
"18886","113.28000","9.44023","0.00525"
"18918","113.47200","9.45619","0.00510"
"18950","113.66400","9.47228","0.00527"
"18982","113.85600","9.48818","0.00424"
"19014","114.04800","9.50426","0.00393"
"19046","114.24000","9.52023","0.00363"
"19078","114.43200","9.53619","0.00365"
"19110","114.62400","9.55227","0.00373"
"19142","114.81600","9.56824","0.00455"
"19174","115.00800","9.58420","0.00395"
"19206","115.20000","9.60023","0.00421"
"19238","115.39200","9.61625","0.00369"
"19270","115.58400","9.63221","0.00413"
"19302","115.77600","9.64824","0.00414"
"19334","115.96800","9.66420","0.00436"
"19366","116.16000","9.68022","0.00443"
"19398","116.35200","9.69625","0.00444"
"19430","116.54400","9.71221","0.00429"
"19462","116.73600","9.72824","0.00406"
"19494","116.92800","9.74426","0.00454"
"19526","117.12000","9.76016","0.00440"
"19558","117.31200","9.77619","0.00423"
"19590","117.50400","9.79227","0.00484"
"19622","117.69600","9.80817","0.00514"
"19654","117.88800","9.82420","0.00460"
"19686","118.08000","9.84016","0.00481"
"19718","118.27200","9.85618","0.00493"
"19750","118.46400","9.87221","0.00452"
"19782","118.65600","9.88823","0.00449"
"19814","118.84800","9.90426","0.00429"
"19846","119.04000","9.92022","0.00458"
"19878","119.23200","9.93618","0.00473"
"19910","119.42400","9.95227","0.00511"
"19942","119.61600","9.96823","0.00508"
"19974","119.80800","9.98419","0.00457"
"20006","120.00000","10.00028","0.00485"
"20038","120.19200","10.01624","0.00506"
"20070","120.38400","10.03226","0.00502"
"20102","120.57600","10.04823","0.00431"
"20134","120.76800","10.06419","0.00406"
"20166","120.96000","10.08028","0.00464"
"20198","121.15200","10.09624","0.00408"
"20230","121.34400","10.11220","0.00451"
"20262","121.53600","10.12829","0.00359"
"20294","121.72800","10.14425","0.00456"
"20326","121.92000","10.16022","0.00452"
"20358","122.11200","10.17630","0.00468"
"20390","122.30400","10.19220","0.00503"
"20422","122.49600","10.20817","0.00439"
"20454","122.68800","10.22425","0.00437"
"20486","122.88000","10.24021","0.00501"
"20518","123.07200","10.25618","0.00516"
"20550","123.26400","10.27226","0.00526"
"20582","123.45600","10.28822","0.00508"
"20614","123.64800","10.30425","0.00491"
"20646","123.84000","10.32027","0.00529"
"20678","124.03200","10.33624","0.00538"
"20710","124.22400","10.35220","0.00542"
"20742","124.41600","10.36828","0.00472"
"20774","124.60800","10.38413","0.00517"
"20806","124.80000","10.40027","0.00543"
"20838","124.99200","10.41623","0.00480"
"20870","125.18400","10.43220","0.00595"
"20902","125.37600","10.44822","0.00561"
"20934","125.56800","10.46424","0.00544"
"20966","125.76000","10.48015","0.00590"
"20998","125.95200","10.49623","0.00622"
"21030","126.14400","10.51226","0.00609"
"21062","126.33600","10.52816","0.00631"
"21094","126.52800","10.54424","0.00615"
"21126","126.72000","10.56021","0.00654"
"21158","126.91200","10.57623","0.00642"
"21190","127.10400","10.59225","0.00625"
"21222","127.29600","10.60816","0.00646"
"21254","127.48800","10.62424","0.00685"
"21286","127.68000","10.64020","0.00713"
"21318","127.87200","10.65617","0.00716"
"21350","128.06400","10.67225","0.00748"
"21382","128.25600","10.68822","0.00754"
"21414","128.44800","10.70418","0.00744"
"21446","128.64000","10.72020","0.00799"
"21478","128.83200","10.73623","0.00868"
"21510","129.02400","10.75225","0.00778"
"21542","129.21600","10.76821","0.00845"
"21574","129.40800","10.78418","0.00890"
"21606","129.60000","10.80026","0.00926"
"21638","129.79200","10.81623","0.00893"
"21670","129.98400","10.83219","0.00963"
"21702","130.17600","10.84827","0.00909"
"21734","130.36800","10.86424","0.00941"
"21766","130.56000","10.88020","0.00949"
"21798","130.75200","10.89622","0.01006"
"21830","130.94400","10.91219","0.01004"
"21862","131.13600","10.92821","0.01032"
"21894","131.32800","10.94423","0.01085"
"21926","131.52000","10.96020","0.01109"
"21958","131.71200","10.97622","0.01126"
"21990","131.90400","10.99225","0.01165"
"22022","132.09600","11.00821","0.01241"
"22054","132.28800","11.02423","0.01245"
"22086","132.48000","11.04026","0.01239"
"22118","132.67200","11.05622","0.01305"
"22150","132.86400","11.07224","0.01321"
"22182","133.05600","11.08821","0.01356"
"22214","133.24800","11.10411","0.01361"
"22246","133.44000","11.12032","0.01413"
"22278","133.63200","11.13622","0.01522"
"22310","133.82400","11.15218","0.01568"
"22342","134.01600","11.16827","0.01601"
"22374","134.20800","11.18417","0.01581"
"22406","134.40000","11.20019","0.01647"
"22438","134.59200","11.21628","0.01717"
"22470","134.78400","11.23224","0.01792"
"22502","134.97600","11.24826","0.01783"
"22534","135.16800","11.26423","0.01817"
"22566","135.36000","11.28019","0.01837"
"22598","135.55200","11.29622","0.01864"
"22630","135.74400","11.31224","0.01832"
"22662","135.93600","11.32820","0.01951"
"22694","136.12800","11.34423","0.02051"
"22726","136.32000","11.36025","0.02056"
"22758","136.51200","11.37621","0.02114"
"22790","136.70400","11.39224","0.02154"
"22822","136.89600","11.40826","0.02168"
"22854","137.08800","11.42423","0.02194"
"22886","137.28000","11.44019","0.02263"
"22918","137.47200","11.45621","0.02382"
"22950","137.66400","11.47224","0.02385"
"22982","137.85600","11.48826","0.02477"
"23014","138.04800","11.50422","0.02448"
"23046","138.24000","11.52025","0.02462"
"23078","138.43200","11.53621","0.02551"
"23110","138.62400","11.55218","0.02630"
"23142","138.81600","11.56832","0.02595"
"23174","139.00800","11.58422","0.02681"
"23206","139.20000","11.60019","0.02853"
"23238","139.39200","11.61621","0.02805"
"23270","139.58400","11.63217","0.02850"
"23302","139.77600","11.64820","0.02925"
"23334","139.96800","11.66422","0.03033"
"23366","140.16000","11.68018","0.03058"
"23398","140.35200","11.69621","0.03135"
"23430","140.54400","11.71223","0.03179"
"23462","140.73600","11.72820","0.03196"
"23494","140.92800","11.74422","0.03289"
"23526","141.12000","11.76024","0.03388"
"23558","141.31200","11.77621","0.03462"
"23590","141.50400","11.79223","0.03454"
"23622","141.69600","11.80819","0.03538"
"23654","141.88800","11.82422","0.03596"
"23686","142.08000","11.84024","0.03619"
"23718","142.27200","11.85620","0.03699"
"23750","142.46400","11.87223","0.03782"
"23782","142.65600","11.88825","0.03822"
"23814","142.84800","11.90422","0.03895"
"23846","143.04000","11.92024","0.03882"
"23878","143.23200","11.93626","0.03960"
"23910","143.42400","11.95217","0.04014"
"23942","143.61600","11.96825","0.04047"
"23974","143.80800","11.98421","0.04079"
"24006","144.00000","12.00012","0.04125"
"24038","144.19200","12.01626","0.04212"
"24070","144.38400","12.03223","0.04243"
"24102","144.57600","12.04819","0.04297"
"24134","144.76800","12.06427","0.04355"
"24166","144.96000","12.08024","0.04396"
"24198","145.15200","12.09620","0.04420"
"24230","145.34400","12.11228","0.04474"
"24262","145.53600","12.12825","0.04481"
"24294","145.72800","12.14421","0.04558"
"24326","145.92000","12.16029","0.04552"
"24358","146.11200","12.17614","0.04572"
"24390","146.30400","12.19222","0.04618"
"24422","146.49600","12.20825","0.04631"
"24454","146.68800","12.22415","0.04635"
"24486","146.88000","12.24029","0.04664"
"24518","147.07200","12.25632","0.04701"
"24550","147.26400","12.27210","0.04689"
"24582","147.45600","12.28824","0.04544"
"24614","147.64800","12.30427","0.04604"
"24646","147.84000","12.32017","0.04624"
"24678","148.03200","12.33625","0.04666"
"24710","148.22400","12.35216","0.04684"
"24742","148.41600","12.36818","0.04738"
"24774","148.60800","12.38427","0.04754"
"24806","148.80000","12.40023","0.04833"
"24838","148.99200","12.41619","0.04850"
"24870","149.18400","12.43222","0.04868"
"24902","149.37600","12.44818","0.04925"
"24934","149.56800","12.46426","0.04936"
"24966","149.76000","12.48023","0.05026"
"24998","149.95200","12.49625","0.05046"
"25030","150.14400","12.51222","0.05069"
"25062","150.33600","12.52824","0.05128"
"25094","150.52800","12.54426","0.05182"
"25126","150.72000","12.56023","0.05191"
"25158","150.91200","12.57619","0.05240"
"25190","151.10400","12.59221","0.05259"
"25222","151.29600","12.60824","0.05344"
"25254","151.48800","12.62420","0.05387"
"25286","151.68000","12.64023","0.05486"
"25318","151.87200","12.65631","0.05533"
"25350","152.06400","12.67215","0.05585"
"25382","152.25600","12.68824","0.05683"
"25414","152.44800","12.70420","0.05775"
"25446","152.64000","12.72016","0.05827"
"25478","152.83200","12.73631","0.05869"
"25510","153.02400","12.75221","0.05946"
"25542","153.21600","12.76817","0.06017"
"25574","153.40800","12.78426","0.06078"
"25606","153.60000","12.80022","0.06167"
"25638","153.79200","12.81625","0.06262"
"25670","153.98400","12.83227","0.06320"
"25702","154.17600","12.84811","0.06369"
"25734","154.36800","12.86426","0.06357"
"25766","154.56000","12.88022","0.06357"
"25798","154.75200","12.89612","0.06416"
"25830","154.94400","12.91227","0.06494"
"25862","155.13600","12.92829","0.06562"
"25894","155.32800","12.94414","0.01082"
"25926","155.52000","12.96028","0.01125"
"25958","155.71200","12.97624","0.01477"
"25990","155.90400","12.99221","0.01179"
"26022","156.09600","13.00823","0.01311"
"26054","156.28800","13.02419","0.01639"
"26086","156.48000","13.04016","0.01587"
"26118","156.67200","13.05630","0.01432"
"26150","156.86400","13.07220","0.01507"
"26182","157.05600","13.08823","0.01557"
"26214","157.24800","13.10425","0.01894"
"26246","157.44000","13.12016","0.01656"
"26278","157.63200","13.13624","0.01782"
"26310","157.82400","13.15226","0.02015"
"26342","158.01600","13.16823","0.01892"
"26374","158.20800","13.18425","0.02088"
"26406","158.40000","13.20027","0.02073"
"26438","158.59200","13.21618","0.02267"
"26470","158.78400","13.23220","0.02224"
"26502","158.97600","13.24822","0.02157"
"26534","159.16800","13.26425","0.02412"
"26566","159.36000","13.28027","0.02296"
"26598","159.55200","13.29618","0.02328"
"26630","159.74400","13.31226","0.01614"
"26662","159.93600","13.32822","0.01405"
"26694","160.12800","13.34419","0.01477"
"26726","160.32000","13.36027","0.01414"
"26758","160.51200","13.37623","0.01467"
"26790","160.70400","13.39226","0.01599"
"26822","160.89600","13.40822","0.01505"
"26854","161.08800","13.42419","0.01563"
"26886","161.28000","13.44027","0.01468"
"26918","161.47200","13.45623","0.01522"
"26950","161.66400","13.47214","0.01566"
"26982","161.85600","13.48822","0.01531"
"27014","162.04800","13.50424","0.01418"
"27046","162.24000","13.52015","0.01316"
"27078","162.43200","13.53629","0.01435"
"27110","162.62400","13.55220","0.01544"
"27142","162.81600","13.56816","0.01407"
"27174","163.00800","13.58430","0.01552"
"27206","163.20000","13.60027","0.01540"
"27238","163.39200","13.61617","0.01537"
"27270","163.58400","13.63225","0.01608"
"27302","163.77600","13.64822","0.01591"
"27334","163.96800","13.66418","0.01679"
"27366","164.16000","13.68026","0.01588"
"27398","164.35200","13.69623","0.01224"
"27430","164.54400","13.71219","0.01222"
"27462","164.73600","13.72827","0.01205"
"27494","164.92800","13.74418","0.01222"
"27526","165.12000","13.76020","0.01174"
"27558","165.31200","13.77623","0.01153"
"27590","165.50400","13.79213","0.01171"
"27622","165.69600","13.80821","0.01208"
"27654","165.88800","13.82430","0.01231"
"27686","166.08000","13.84014","0.01277"
"27718","166.27200","13.85628","0.01142"
"27750","166.46400","13.87225","0.01221"
"27782","166.65600","13.88815","0.01149"
"27814","166.84800","13.90424","0.01281"
"27846","167.04000","13.92026","0.01271"
"27878","167.23200","13.93622","0.01220"
"27910","167.42400","13.95225","0.01240"
"27942","167.61600","13.96815","0.01041"
"27974","167.80800","13.98423","0.01085"
"28006","168.00000","14.00026","0.01214"
"28038","168.19200","14.01622","0.01158"
"28070","168.38400","14.03225","0.01175"
"28102","168.57600","14.04821","0.01225"
"28134","168.76800","14.06417","0.01247"
"28166","168.96000","14.08026","0.01187"
"28198","169.15200","14.09622","0.01234"
"28230","169.34400","14.11218","0.01238"
"28262","169.53600","14.12821","0.01259"
"28294","169.72800","14.14423","0.01179"
"28326","169.92000","14.16026","0.01265"
"28358","170.11200","14.17622","0.01282"
"28390","170.30400","14.19224","0.01290"
"28422","170.49600","14.20821","0.01277"
"28454","170.68800","14.22423","0.01274"
"28486","170.88000","14.24019","0.01328"
"28518","171.07200","14.25628","0.01275"
"28550","171.26400","14.27230","0.01292"
"28582","171.45600","14.28815","0.01318"
"28614","171.64800","14.30429","0.01326"
"28646","171.84000","14.32019","0.01368"
"28678","172.03200","14.33622","0.01311"
"28710","172.22400","14.35224","0.01345"
"28742","172.41600","14.36820","0.01454"
"28774","172.60800","14.38423","0.01355"
"28806","172.80000","14.40025","0.01446"
"28838","172.99200","14.41621","0.01468"
"28870","173.18400","14.43224","0.01476"
"28902","173.37600","14.44826","0.01555"
"28934","173.56800","14.46416","0.01513"
"28966","173.76000","14.48025","0.01564"
"28998","173.95200","14.49621","0.01577"
"29030","174.14400","14.51212","0.01618"
"29062","174.33600","14.52826","0.01624"
"29094","174.52800","14.54422","0.01588"
"29126","174.72000","14.56019","0.01613"
"29158","174.91200","14.57627","0.01683"
"29190","175.10400","14.59223","0.01670"
"29222","175.29600","14.60820","0.01727"
"29254","175.48800","14.62428","0.01752"
"29286","175.68000","14.64019","0.01790"
"29318","175.87200","14.65627","0.01772"
"29350","176.06400","14.67229","0.01823"
"29382","176.25600","14.68820","0.01788"
"29414","176.44800","14.70422","0.01825"
"29446","176.64000","14.72018","0.01931"
"29478","176.83200","14.73621","0.01922"
"29510","177.02400","14.75223","0.01915"
"29542","177.21600","14.76825","0.01986"
"29574","177.40800","14.78422","0.02045"
"29606","177.60000","14.80024","0.02014"
"29638","177.79200","14.81627","0.01951"
"29670","177.98400","14.83223","0.02021"
"29702","178.17600","14.84819","0.02056"
"29734","178.36800","14.86422","0.02044"
"29766","178.56000","14.88018","0.02089"
"29798","178.75200","14.89626","0.02147"
"29830","178.94400","14.91217","0.02200"
"29862","179.13600","14.92819","0.02218"
"29894","179.32800","14.94422","0.02309"
"29926","179.52000","14.96018","0.02299"
"29958","179.71200","14.97626","0.02300"
"29990","179.90400","14.99223","0.02381"
"30022","180.09600","15.00819","0.02328"
"30054","180.28800","15.02427","0.02002"
"30086","180.48000","15.04018","0.02097"
"30118","180.67200","15.05620","0.02208"
"30150","180.86400","15.07228","0.02270"
"30182","181.05600","15.08825","0.02318"
"30214","181.24800","15.10427","0.02368"
"30246","181.44000","15.12024","0.02424"
"30278","181.63200","15.13620","0.02473"
"30310","181.82400","15.15228","0.02497"
"30342","182.01600","15.16825","0.02565"
"30374","182.20800","15.18421","0.02570"
"30406","182.40000","15.20029","0.02648"
"30438","182.59200","15.21620","0.02659"
"30470","182.78400","15.23222","0.02727"
"30502","182.97600","15.24825","0.02682"
"30534","183.16800","15.26421","0.02593"
"30566","183.36000","15.28023","0.02656"
"30598","183.55200","15.29626","0.02706"
"30630","183.74400","15.31222","0.02785"
"30662","183.93600","15.32824","0.02829"
"30694","184.12800","15.34427","0.02798"
"30726","184.32000","15.36023","0.02894"
"30758","184.51200","15.37619","0.02872"
"30790","184.70400","15.39222","0.02872"
"30822","184.89600","15.40812","0.02929"
"30854","185.08800","15.42427","0.02958"
"30886","185.28000","15.44029","0.02957"
"30918","185.47200","15.45613","0.02735"
"30950","185.66400","15.47228","0.02654"
"30982","185.85600","15.48824","0.02614"
"31014","186.04800","15.50420","0.02727"
"31046","186.24000","15.52029","0.02643"
"31078","186.43200","15.53619","0.02714"
"31110","186.62400","15.55222","0.02772"
"31142","186.81600","15.56824","0.02728"
"31174","187.00800","15.58414","0.02633"
"31206","187.20000","15.60023","0.02777"
"31238","187.39200","15.61625","0.02810"
"31270","187.58400","15.63221","0.02825"
"31302","187.77600","15.64824","0.02857"
"31334","187.96800","15.66426","0.02972"
"31366","188.16000","15.68022","0.02956"
"31398","188.35200","15.69625","0.02994"
"31430","188.54400","15.71221","0.02996"
"31462","188.73600","15.72823","0.02956"
"31494","188.92800","15.74420","0.03007"
"31526","189.12000","15.76022","0.03062"
"31558","189.31200","15.77625","0.03083"
"31590","189.50400","15.79227","0.03116"
"31622","189.69600","15.80823","0.03118"
"31654","189.88800","15.82426","0.03062"
"31686","190.08000","15.84022","0.03069"
"31718","190.27200","15.85618","0.03026"
"31750","190.46400","15.87227","0.02933"
"31782","190.65600","15.88823","0.03037"
"31814","190.84800","15.90420","0.03117"
"31846","191.04000","15.92022","0.03214"
"31878","191.23200","15.93618","0.03039"
"31910","191.42400","15.95226","0.03240"
"31942","191.61600","15.96829","0.03322"
"31974","191.80800","15.98419","0.03449"
"32006","192.00000","16.00016","0.03446"
"32038","192.19200","16.01624","0.03456"
"32070","192.38400","16.03220","0.03539"
"32102","192.57600","16.04823","0.03558"
"32134","192.76800","16.06425","0.03630"
"32166","192.96000","16.08016","0.03655"
"32198","193.15200","16.09630","0.03039"
"32230","193.34400","16.11226","0.03248"
"32262","193.53600","16.12817","0.03343"
"32294","193.72800","16.14431","0.03298"
"32326","193.92000","16.16021","0.03360"
"32358","194.11200","16.17618","0.03510"
"32390","194.30400","16.19226","0.03516"
"32422","194.49600","16.20816","0.03549"
"32454","194.68800","16.22425","0.03754"
"32486","194.88000","16.24027","0.03763"
"32518","195.07200","16.25618","0.03836"
"32550","195.26400","16.27226","0.03933"
"32582","195.45600","16.28822","0.03927"
"32614","195.64800","16.30419","0.04010"
"32646","195.84000","16.32021","0.04116"
"32678","196.03200","16.33624","0.04103"
"32710","196.22400","16.35220","0.04197"
"32742","196.41600","16.36822","0.04275"
"32774","196.60800","16.38424","0.04294"
"32806","196.80000","16.40021","0.04383"
"32838","196.99200","16.41623","0.04466"
"32870","197.18400","16.43220","0.04452"
"32902","197.37600","16.44822","0.04549"
"32934","197.56800","16.46424","0.04584"
"32966","197.76000","16.48015","0.04637"
"32998","197.95200","16.49623","0.04710"
"33030","198.14400","16.51225","0.04752"
"33062","198.33600","16.52816","0.04850"
"33094","198.52800","16.54424","0.04868"
"33126","198.72000","16.56027","0.04933"
"33158","198.91200","16.57611","0.04968"
"33190","199.10400","16.59225","0.05053"
"33222","199.29600","16.60822","0.05120"
"33254","199.48800","16.62418","0.05150"
"33286","199.68000","16.64026","0.05283"
"33318","199.87200","16.65623","0.05370"
"33350","200.06400","16.67219","0.05477"
"33382","200.25600","16.68827","0.05609"
"33414","200.44800","16.70418","0.05702"
"33446","200.64000","16.72026","0.05797"
"33478","200.83200","16.73629","0.05947"
"33510","201.02400","16.75219","0.06078"
"33542","201.21600","16.76827","0.06239"
"33574","201.40800","16.78424","0.06355"
"33606","201.60000","16.80020","0.06486"
"33638","201.79200","16.81628","0.06663"
"33670","201.98400","16.83219","0.06804"
"33702","202.17600","16.84821","0.06998"
"33734","202.36800","16.86423","0.07127"
"33766","202.56000","16.88020","0.07295"
"33798","202.75200","16.89628","0.07509"
"33830","202.94400","16.91225","0.07607"
"33862","203.13600","16.92821","0.07840"
"33894","203.32800","16.94423","0.07975"
"33926","203.52000","16.96026","0.08134"
"33958","203.71200","16.97622","0.08314"
"33990","203.90400","16.99230","0.08458"
"34022","204.09600","17.00821","0.08595"
"34054","204.28800","17.02417","0.08727"
"34086","204.48000","17.04032","0.08927"
"34118","204.67200","17.05622","0.08956"
"34150","204.86400","17.07218","0.09117"
"34182","205.05600","17.08821","0.09234"
"34214","205.24800","17.10417","0.09330"
"34246","205.44000","17.12025","0.09437"
"34278","205.63200","17.13628","0.09524"
"34310","205.82400","17.15218","0.09589"
"34342","206.01600","17.16826","0.09759"
"34374","206.20800","17.18429","0.09887"
"34406","206.40000","17.20013","0.10021"
"34438","206.59200","17.21628","0.10238"
"34470","206.78400","17.23230","0.10403"
"34502","206.97600","17.24814","0.10585"
"34534","207.16800","17.26423","0.10763"
"34566","207.36000","17.28025","0.10991"
"34598","207.55200","17.29616","0.11205"
"34630","207.74400","17.31230","0.11424"
"34662","207.93600","17.32826","0.11608"
"34694","208.12800","17.34417","0.11889"
"34726","208.32000","17.36025","0.12092"
"34758","208.51200","17.37615","0.12175"
"34790","208.70400","17.39224","0.12426"
"34822","208.89600","17.40826","0.12658"
"34854","209.08800","17.42416","0.12484"
"34886","209.28000","17.44025","0.12457"
"34918","209.47200","17.45627","0.12573"
"34950","209.66400","17.47218","0.12835"
"34982","209.85600","17.48820","0.12968"
"35014","210.04800","17.50422","0.13094"
"35046","210.24000","17.52025","0.13217"
"35078","210.43200","17.53621","0.13304"
"35110","210.62400","17.55223","0.13441"
"35142","210.81600","17.56826","0.13474"
"35174","211.00800","17.58428","0.13555"
"35206","211.20000","17.60024","0.13634"
"35238","211.39200","17.61621","0.13717"
"35270","211.58400","17.63217","0.13795"
"35302","211.77600","17.64820","0.13831"
"35334","211.96800","17.66422","0.13864"
"35366","212.16000","17.68024","0.13930"
"35398","212.35200","17.69621","0.13996"
"35430","212.54400","17.71223","0.14069"
"35462","212.73600","17.72820","0.14138"
"35494","212.92800","17.74422","0.14150"
"35526","213.12000","17.76024","0.14260"
"35558","213.31200","17.77621","0.14353"
"35590","213.50400","17.79223","0.14420"
"35622","213.69600","17.80825","0.14550"
"35654","213.88800","17.82416","0.14638"
"35686","214.08000","17.84024","0.14809"
"35718","214.27200","17.85632","0.14910"
"35750","214.46400","17.87217","0.15121"
"35782","214.65600","17.88831","0.15248"
"35814","214.84800","17.90421","0.15501"
"35846","215.04000","17.92012","0.15793"
"35878","215.23200","17.93626","0.15973"
"35910","215.42400","17.95223","0.16139"
"35942","215.61600","17.96813","0.16419"
"35974","215.80800","17.98433","0.16702"
"36006","216.00000","18.00018","0.16971"
"36038","216.19200","18.01620","0.17272"
"36070","216.38400","18.03228","0.17535"
"36102","216.57600","18.04825","0.17847"
"36134","216.76800","18.06421","0.18191"
"36166","216.96000","18.08023","0.18439"
"36198","217.15200","18.09620","0.18691"
"36230","217.34400","18.11222","0.18909"
"36262","217.53600","18.12831","0.18996"
"36294","217.72800","18.14415","0.18899"
"36326","217.92000","18.16023","0.19155"
"36358","218.11200","18.17626","0.19199"
"36390","218.30400","18.19216","0.01528"
"36422","218.49600","18.20824","0.03948"
"36454","218.68800","18.22421","0.02253"
"36486","218.88000","18.24023","0.03239"
"36518","219.07200","18.25626","0.00345"
"36550","219.26400","18.27222","0.02412"
"36582","219.45600","18.28824","0.00575"
"36614","219.64800","18.30421","0.02530"
"36646","219.84000","18.32023","0.01541"
"36678","220.03200","18.33625","0.02732"
"36710","220.22400","18.35222","0.00546"
"36742","220.41600","18.36812","0.02398"
"36774","220.60800","18.38426","0.02040"
"36806","220.80000","18.40023","0.03431"
"36838","220.99200","18.41619","0.00775"
"36870","221.18400","18.43222","0.03822"
"36902","221.37600","18.44824","0.02157"
"36934","221.56800","18.46420","0.03382"
"36966","221.76000","18.48023","0.01769"
"36998","221.95200","18.49619","0.03425"
"37030","222.14400","18.51228","0.02881"
"37062","222.33600","18.52824","0.03163"
"37094","222.52800","18.54420","0.03384"
"37126","222.72000","18.56029","0.01865"
"37158","222.91200","18.57625","0.03468"
"37190","223.10400","18.59221","0.02650"
"37222","223.29600","18.60830","0.03474"
"37254","223.48800","18.62420","0.01416"
"37286","223.68000","18.64016","0.03736"
"37318","223.87200","18.65625","0.02587"
"37350","224.06400","18.67221","0.02832"
"37382","224.25600","18.68818","0.02373"
"37414","224.44800","18.70426","0.04063"
"37446","224.64000","18.72022","0.02549"
"37478","224.83200","18.73625","0.02576"
"37510","225.02400","18.75227","0.03839"
"37542","225.21600","18.76818","0.03491"
"37574","225.40800","18.78426","0.03048"
"37606","225.60000","18.80022","0.02782"
"37638","225.79200","18.81618","0.04271"
"37670","225.98400","18.83221","0.02723"
"37702","226.17600","18.84823","0.03566"
"37734","226.36800","18.86414","0.03691"
"37766","226.56000","18.88028","0.04128"
"37798","226.75200","18.89624","0.03518"
"37830","226.94400","18.91221","0.03318"
"37862","227.13600","18.92829","0.04476"
"37894","227.32800","18.94419","0.03528"
"37926","227.52000","18.96022","0.03994"
"37958","227.71200","18.97624","0.04129"
"37990","227.90400","18.99215","0.04366"
"38022","228.09600","19.00823","0.04143"
"38054","228.28800","19.02419","0.03510"
"38086","228.48000","19.04016","0.04685"
"38118","228.67200","19.05624","0.04089"
"38150","228.86400","19.07226","0.03814"
"38182","229.05600","19.08817","0.04665"
"38214","229.24800","19.10419","0.04448"
"38246","229.44000","19.12021","0.04202"
"38278","229.63200","19.13618","0.04456"
"38310","229.82400","19.15220","0.04870"
"38342","230.01600","19.16823","0.04428"
"38374","230.20800","19.18425","0.04165"
"38406","230.40000","19.20021","0.05044"
"38438","230.59200","19.21624","0.04501"
"38470","230.78400","19.23226","0.04285"
"38502","230.97600","19.24822","0.05107"
"38534","231.16800","19.26419","0.04775"
"38566","231.36000","19.28027","0.04470"
"38598","231.55200","19.29623","0.05032"
"38630","231.74400","19.31220","0.05128"
"38662","231.93600","19.32828","0.04626"
"38694","232.12800","19.34425","0.04968"
"38726","232.32000","19.36021","0.05529"
"38758","232.51200","19.37623","0.04729"
"38790","232.70400","19.39220","0.04952"
"38822","232.89600","19.40828","0.01553"
"38854","233.08800","19.42424","0.00147"
"38886","233.28000","19.44021","0.00283"
"38918","233.47200","19.45623","-0.00073"
"38950","233.66400","19.47225","0.00120"
"38982","233.85600","19.48822","0.00055"
"39014","234.04800","19.50430","0.00090"
"39046","234.24000","19.52027","0.00113"
"39078","234.43200","19.53617","-0.00002"
"39110","234.62400","19.55225","0.00039"
"39142","234.81600","19.56822","0.00066"
"39174","235.00800","19.58418","-0.00022"
"39206","235.20000","19.60026","0.00055"
"39238","235.39200","19.61623","-0.00016"
"39270","235.58400","19.63219","0.00120"
"39302","235.77600","19.64822","0.00004"
"39334","235.96800","19.66418","-0.00024"
"39366","236.16000","19.68026","-0.00017"
"39398","236.35200","19.69628","0.00022"
"39430","236.54400","19.71219","-0.00001"
"39462","236.73600","19.72827","0.00063"
"39483","236.85800","19.73844","0.00094"