File: Trajectories_together/170226_1Specimen_RawData_4.csv
"","V1","V2","V3"
"1","End date","2/26/2017",""
"2","Specimen label","4BG_28",""
"3","Maximum Load","0.04336","N"
"4","Time","Extension","Load"
"5","(s)","(mm)","(N)"
"6","0.00000","0.00000","0.00016"
"32","0.15600","0.00921","0.00006"
"58","0.31200","0.02565","0.00031"
"84","0.46800","0.03934","0.00119"
"110","0.62400","0.05226","0.00153"
"136","0.78000","0.06523","0.00131"
"162","0.93600","0.07820","0.00183"
"188","1.09200","0.09124","0.00196"
"214","1.24800","0.10427","0.00246"
"240","1.40400","0.11713","0.00237"
"266","1.56000","0.13022","0.00292"
"292","1.71600","0.14320","0.00311"
"318","1.87200","0.15617","0.00283"
"344","2.02800","0.16920","0.00375"
"370","2.18400","0.18218","0.00331"
"396","2.34000","0.19521","0.00401"
"422","2.49600","0.20819","0.00446"
"448","2.65200","0.22128","0.00374"
"474","2.80800","0.23426","0.00389"
"500","2.96400","0.24717","0.00406"
"526","3.12000","0.26020","0.00512"
"552","3.27600","0.27324","0.00458"
"578","3.43200","0.28621","0.00473"
"604","3.58800","0.29913","0.00446"
"630","3.74400","0.31222","0.00475"
"656","3.90000","0.32520","0.00484"
"682","4.05600","0.33817","0.00500"
"708","4.21200","0.35120","0.00500"
"734","4.36800","0.36424","0.00520"
"760","4.52400","0.37715","0.00608"
"786","4.68000","0.39019","0.00588"
"812","4.83600","0.40322","0.00602"
"838","4.99200","0.41625","0.00619"
"864","5.14800","0.42917","0.00588"
"890","5.30400","0.44220","0.00621"
"916","5.46000","0.45524","0.00649"
"942","5.61600","0.46815","0.00615"
"968","5.77200","0.48119","0.00614"
"994","5.92800","0.49422","0.00673"
"1020","6.08400","0.50719","0.00637"
"1046","6.24000","0.52017","0.00721"
"1072","6.39600","0.53326","0.00701"
"1098","6.55200","0.54624","0.00667"
"1124","6.70800","0.55915","0.00648"
"1150","6.86400","0.57219","0.00645"
"1176","7.02000","0.58522","0.00705"
"1202","7.17600","0.59819","0.00732"
"1228","7.33200","0.61117","0.00745"
"1254","7.48800","0.62426","0.00744"
"1280","7.64400","0.63724","0.00792"
"1306","7.80000","0.65021","0.00701"
"1332","7.95600","0.66319","0.00787"
"1358","8.11200","0.67622","0.00710"
"1384","8.26800","0.68919","0.00789"
"1410","8.42400","0.70217","0.00789"
"1436","8.58000","0.71526","0.00780"
"1462","8.73600","0.72824","0.00791"
"1488","8.89200","0.74115","0.00776"
"1514","9.04800","0.75419","0.00822"
"1540","9.20400","0.76716","0.00819"
"1566","9.36000","0.78019","0.00831"
"1592","9.51600","0.79317","0.00787"
"1618","9.67200","0.80626","0.00799"
"1644","9.82800","0.81924","0.00831"
"1670","9.98400","0.83221","0.00830"
"1696","10.14000","0.84524","0.00890"
"1722","10.29600","0.85828","0.00857"
"1748","10.45200","0.87119","0.00871"
"1774","10.60800","0.88423","0.00871"
"1800","10.76400","0.89720","0.00949"
"1826","10.92000","0.91018","0.00870"
"1852","11.07600","0.92315","0.00885"
"1878","11.23200","0.93624","0.00854"
"1904","11.38800","0.94928","0.00987"
"1930","11.54400","0.96219","0.00901"
"1956","11.70000","0.97523","0.00883"
"1982","11.85600","0.98820","0.00914"
"2008","12.01200","1.00124","0.00933"
"2034","12.16800","1.01415","0.00914"
"2060","12.32400","1.02730","0.00935"
"2086","12.48000","1.04022","0.00946"
"2112","12.63600","1.05319","0.00972"
"2138","12.79200","1.06617","0.00983"
"2164","12.94800","1.07920","0.00881"
"2190","13.10400","1.09218","0.00939"
"2216","13.26000","1.10521","0.00996"
"2242","13.41600","1.11824","0.00972"
"2268","13.57200","1.13128","0.00937"
"2294","13.72800","1.14419","0.00953"
"2320","13.88400","1.15723","0.00964"
"2346","14.04000","1.17026","0.00964"
"2372","14.19600","1.18318","0.00969"
"2398","14.35200","1.19615","0.01007"
"2424","14.50800","1.20918","0.00978"
"2450","14.66400","1.22222","0.00989"
"2476","14.82000","1.23513","0.01045"
"2502","14.97600","1.24823","0.00997"
"2528","15.13200","1.26126","0.01033"
"2554","15.28800","1.27423","0.00972"
"2580","15.44400","1.28721","0.01055"
"2606","15.60000","1.30024","0.00979"
"2632","15.75600","1.31322","0.00995"
"2658","15.91200","1.32619","0.01022"
"2684","16.06800","1.33929","0.01078"
"2710","16.22400","1.35226","0.01017"
"2736","16.38000","1.36517","0.01045"
"2762","16.53600","1.37821","0.01017"
"2788","16.69200","1.39124","0.01027"
"2814","16.84800","1.40422","0.01068"
"2840","17.00400","1.41719","0.01037"
"2866","17.16000","1.43029","0.01046"
"2892","17.31600","1.44320","0.01060"
"2918","17.47200","1.45617","0.01038"
"2944","17.62800","1.46921","0.01028"
"2970","17.78400","1.48218","0.01142"
"2996","17.94000","1.49516","0.01054"
"3022","18.09600","1.50819","0.01109"
"3048","18.25200","1.52123","0.01068"
"3074","18.40800","1.53426","0.01115"
"3100","18.56400","1.54717","0.01116"
"3126","18.72000","1.56027","0.01073"
"3152","18.87600","1.57324","0.01092"
"3178","19.03200","1.58628","0.01077"
"3204","19.18800","1.59919","0.01140"
"3230","19.34400","1.61222","0.01127"
"3256","19.50000","1.62520","0.01098"
"3282","19.65600","1.63817","0.01140"
"3308","19.81200","1.65127","0.01093"
"3334","19.96800","1.66424","0.01137"
"3360","20.12400","1.67722","0.01151"
"3386","20.28000","1.69019","0.01046"
"3412","20.43600","1.70328","0.01141"
"3438","20.59200","1.71626","0.01135"
"3464","20.74800","1.72917","0.01100"
"3490","20.90400","1.74227","0.01140"
"3516","21.06000","1.75524","0.01113"
"3542","21.21600","1.76816","0.01121"
"3568","21.37200","1.78119","0.01100"
"3594","21.52800","1.79422","0.01191"
"3620","21.68400","1.80720","0.01150"
"3646","21.84000","1.82011","0.01166"
"3672","21.99600","1.83321","0.01132"
"3698","22.15200","1.84624","0.01168"
"3724","22.30800","1.85922","0.01188"
"3750","22.46400","1.87225","0.01186"
"3776","22.62000","1.88528","0.01146"
"3802","22.77600","1.89826","0.01177"
"3828","22.93200","1.91117","0.01157"
"3854","23.08800","1.92427","0.01182"
"3880","23.24400","1.93724","0.01221"
"3906","23.40000","1.95022","0.01163"
"3932","23.55600","1.96319","0.01179"
"3958","23.71200","1.97622","0.01200"
"3984","23.86800","1.98920","0.01210"
"4010","24.02400","2.00217","0.01205"
"4036","24.18000","2.01527","0.01264"
"4062","24.33600","2.02824","0.01193"
"4088","24.49200","2.04121","0.01224"
"4114","24.64800","2.05425","0.01214"
"4140","24.80400","2.06722","0.01220"
"4166","24.96000","2.08020","0.01253"
"4192","25.11600","2.09317","0.01213"
"4218","25.27200","2.10627","0.01295"
"4244","25.42800","2.11924","0.01257"
"4270","25.58400","2.13215","0.01275"
"4296","25.74000","2.14525","0.01254"
"4322","25.89600","2.15822","0.01252"
"4348","26.05200","2.17120","0.01247"
"4374","26.20800","2.18423","0.01244"
"4400","26.36400","2.19727","0.01252"
"4426","26.52000","2.21018","0.01278"
"4452","26.67600","2.22315","0.01268"
"4478","26.83200","2.23619","0.01225"
"4504","26.98800","2.24922","0.01247"
"4530","27.14400","2.26214","0.01287"
"4556","27.30000","2.27523","0.01303"
"4582","27.45600","2.28821","0.01354"
"4608","27.61200","2.30124","0.01293"
"4634","27.76800","2.31415","0.01281"
"4660","27.92400","2.32731","0.01301"
"4686","28.08000","2.34022","0.01226"
"4712","28.23600","2.35320","0.01291"
"4738","28.39200","2.36623","0.01289"
"4764","28.54800","2.37920","0.01266"
"4790","28.70400","2.39218","0.01330"
"4816","28.86000","2.40515","0.01278"
"4842","29.01600","2.41825","0.01354"
"4868","29.17200","2.43122","0.01289"
"4894","29.32800","2.44414","0.01273"
"4920","29.48400","2.45723","0.01288"
"4946","29.64000","2.47026","0.01276"
"4972","29.79600","2.48324","0.01333"
"4998","29.95200","2.49621","0.01275"
"5024","30.10800","2.50925","0.01334"
"5050","30.26400","2.52222","0.01333"
"5076","30.42000","2.53514","0.01326"
"5102","30.57600","2.54823","0.01369"
"5128","30.73200","2.56126","0.01303"
"5154","30.88800","2.57418","0.01296"
"5180","31.04400","2.58721","0.01354"
"5206","31.20000","2.60025","0.01328"
"5232","31.35600","2.61322","0.01358"
"5258","31.51200","2.62620","0.01341"
"5284","31.66800","2.63923","0.01312"
"5310","31.82400","2.65226","0.01291"
"5336","31.98000","2.66518","0.01311"
"5362","32.13600","2.67815","0.01351"
"5388","32.29200","2.69119","0.01357"
"5414","32.44800","2.70422","0.01355"
"5440","32.60400","2.71714","0.01332"
"5466","32.76000","2.73023","0.01379"
"5492","32.91600","2.74320","0.01394"
"5518","33.07200","2.75618","0.01373"
"5544","33.22800","2.76921","0.01344"
"5570","33.38400","2.78225","0.01421"
"5596","33.54000","2.79522","0.01399"
"5622","33.69600","2.80819","0.01419"
"5648","33.85200","2.82129","0.01429"
"5674","34.00800","2.83420","0.01459"
"5700","34.16400","2.84718","0.01385"
"5726","34.32000","2.86021","0.01370"
"5752","34.47600","2.87319","0.01396"
"5778","34.63200","2.88622","0.01372"
"5804","34.78800","2.89919","0.01393"
"5830","34.94400","2.91229","0.01321"
"5856","35.10000","2.92520","0.01432"
"5882","35.25600","2.93818","0.01345"
"5908","35.41200","2.95121","0.01371"
"5934","35.56800","2.96425","0.01420"
"5960","35.72400","2.97716","0.01477"
"5986","35.88000","2.99019","0.01446"
"6012","36.03600","3.00323","0.01391"
"6038","36.19200","3.01620","0.01425"
"6064","36.34800","3.02918","0.01414"
"6090","36.50400","3.04221","0.01436"
"6116","36.66000","3.05525","0.01453"
"6142","36.81600","3.06822","0.01501"
"6168","36.97200","3.08119","0.01498"
"6194","37.12800","3.09423","0.01497"
"6220","37.28400","3.10720","0.01457"
"6246","37.44000","3.12018","0.01477"
"6272","37.59600","3.13321","0.01499"
"6298","37.75200","3.14625","0.01478"
"6324","37.90800","3.15916","0.01473"
"6350","38.06400","3.17219","0.01455"
"6376","38.22000","3.18523","0.01488"
"6402","38.37600","3.19826","0.01502"
"6428","38.53200","3.21118","0.01496"
"6454","38.68800","3.22427","0.01424"
"6480","38.84400","3.23724","0.01537"
"6506","39.00000","3.25016","0.01484"
"6532","39.15600","3.26319","0.01475"
"6558","39.31200","3.27623","0.01472"
"6584","39.46800","3.28920","0.01458"
"6610","39.62400","3.30212","0.01482"
"6636","39.78000","3.31521","0.01466"
"6662","39.93600","3.32824","0.01506"
"6688","40.09200","3.34116","0.01480"
"6714","40.24800","3.35419","0.01494"
"6740","40.40400","3.36723","0.01522"
"6766","40.56000","3.38020","0.01571"
"6792","40.71600","3.39318","0.01529"
"6818","40.87200","3.40621","0.01526"
"6844","41.02800","3.41924","0.01526"
"6870","41.18400","3.43216","0.01507"
"6896","41.34000","3.44525","0.01534"
"6922","41.49600","3.45817","0.01595"
"6948","41.65200","3.47120","0.01585"
"6974","41.80800","3.48418","0.01525"
"7000","41.96400","3.49727","0.01587"
"7026","42.12000","3.51024","0.01615"
"7052","42.27600","3.52322","0.01581"
"7078","42.43200","3.53619","0.01569"
"7104","42.58800","3.54923","0.01552"
"7130","42.74400","3.56220","0.01654"
"7156","42.90000","3.57518","0.01620"
"7182","43.05600","3.58821","0.01559"
"7208","43.21200","3.60118","0.01604"
"7234","43.36800","3.61416","0.01627"
"7260","43.52400","3.62725","0.01655"
"7286","43.68000","3.64023","0.01654"
"7312","43.83600","3.65320","0.01644"
"7338","43.99200","3.66623","0.01696"
"7364","44.14800","3.67921","0.01690"
"7390","44.30400","3.69224","0.01667"
"7416","44.46000","3.70516","0.01681"
"7442","44.61600","3.71831","0.01684"
"7468","44.77200","3.73123","0.01615"
"7494","44.92800","3.74420","0.01680"
"7520","45.08400","3.75723","0.01650"
"7546","45.24000","3.77021","0.01726"
"7572","45.39600","3.78318","0.01683"
"7598","45.55200","3.79622","0.01688"
"7624","45.70800","3.80931","0.01677"
"7650","45.86400","3.82229","0.01678"
"7676","46.02000","3.83520","0.01752"
"7702","46.17600","3.84823","0.01714"
"7728","46.33200","3.86121","0.01694"
"7754","46.48800","3.87418","0.01720"
"7780","46.64400","3.88716","0.01711"
"7806","46.80000","3.90025","0.01711"
"7832","46.95600","3.91317","0.01704"
"7858","47.11200","3.92620","0.01699"
"7884","47.26800","3.93917","0.01667"
"7910","47.42400","3.95227","0.01678"
"7936","47.58000","3.96518","0.01682"
"7962","47.73600","3.97822","0.01687"
"7988","47.89200","3.99125","0.01744"
"8014","48.04800","4.00422","0.01671"
"8040","48.20400","4.01720","0.01735"
"8066","48.36000","4.03023","0.01792"
"8092","48.51600","4.04327","0.01706"
"8118","48.67200","4.05624","0.01757"
"8144","48.82800","4.06916","0.01756"
"8170","48.98400","4.08225","0.01733"
"8196","49.14000","4.09522","0.01710"
"8222","49.29600","4.10820","0.01759"
"8248","49.45200","4.12129","0.01733"
"8274","49.60800","4.13427","0.01788"
"8300","49.76400","4.14718","0.01812"
"8326","49.92000","4.16016","0.01751"
"8352","50.07600","4.17319","0.01778"
"8378","50.23200","4.18622","0.01716"
"8404","50.38800","4.19914","0.01785"
"8430","50.54400","4.21223","0.01746"
"8456","50.70000","4.22521","0.01737"
"8482","50.85600","4.23818","0.01777"
"8508","51.01200","4.25121","0.01788"
"8534","51.16800","4.26425","0.01776"
"8560","51.32400","4.27722","0.01773"
"8586","51.48000","4.29026","0.01743"
"8612","51.63600","4.30323","0.01762"
"8638","51.79200","4.31627","0.01799"
"8664","51.94800","4.32918","0.01804"
"8690","52.10400","4.34227","0.01734"
"8716","52.26000","4.35525","0.01750"
"8742","52.41600","4.36816","0.01844"
"8768","52.57200","4.38120","0.01802"
"8794","52.72800","4.39423","0.01844"
"8820","52.88400","4.40727","0.01803"
"8846","53.04000","4.42018","0.01821"
"8872","53.19600","4.43327","0.01871"
"8898","53.35200","4.44625","0.01889"
"8924","53.50800","4.45922","0.01866"
"8950","53.66400","4.47226","0.01892"
"8976","53.82000","4.48523","0.01890"
"9002","53.97600","4.49821","0.01889"
"9028","54.13200","4.51112","0.01848"
"9054","54.28800","4.52421","0.01840"
"9080","54.44400","4.53725","0.01864"
"9106","54.60000","4.55016","0.01829"
"9132","54.75600","4.56326","0.01901"
"9158","54.91200","4.57629","0.01868"
"9184","55.06800","4.58927","0.01878"
"9210","55.22400","4.60212","0.01861"
"9236","55.38000","4.61527","0.01850"
"9262","55.53600","4.62825","0.01877"
"9288","55.69200","4.64122","0.01943"
"9314","55.84800","4.65426","0.01969"
"9340","56.00400","4.66729","0.01945"
"9366","56.16000","4.68021","0.01913"
"9392","56.31600","4.69318","0.01932"
"9418","56.47200","4.70627","0.01941"
"9444","56.62800","4.71931","0.01947"
"9470","56.78400","4.73216","0.01927"
"9496","56.94000","4.74526","0.01949"
"9522","57.09600","4.75823","0.01986"
"9548","57.25200","4.77120","0.01942"
"9574","57.40800","4.78418","0.02005"
"9600","57.56400","4.79715","0.01960"
"9626","57.72000","4.81019","0.01994"
"9652","57.87600","4.82316","0.01987"
"9678","58.03200","4.83626","0.01984"
"9704","58.18800","4.84923","0.01926"
"9730","58.34400","4.86220","0.02001"
"9756","58.50000","4.87518","0.02067"
"9782","58.65600","4.88827","0.01993"
"9808","58.81200","4.90119","0.01987"
"9834","58.96800","4.91416","0.01960"
"9860","59.12400","4.92726","0.02029"
"9886","59.28000","4.94023","0.01963"
"9912","59.43600","4.95320","0.02018"
"9938","59.59200","4.96618","0.01894"
"9964","59.74800","4.97921","0.01948"
"9990","59.90400","4.99219","0.01962"
"10016","60.06000","5.00522","0.01958"
"10042","60.21600","5.01826","0.01941"
"10068","60.37200","5.03123","0.01962"
"10094","60.52800","5.04420","0.02015"
"10120","60.68400","5.05718","0.02009"
"10146","60.84000","5.07021","0.01971"
"10172","60.99600","5.08319","0.02009"
"10198","61.15200","5.09622","0.02013"
"10224","61.30800","5.10925","0.01980"
"10250","61.46400","5.12223","0.01975"
"10276","61.62000","5.13520","0.02000"
"10302","61.77600","5.14824","0.01994"
"10328","61.93200","5.16127","0.02061"
"10354","62.08800","5.17425","0.02026"
"10380","62.24400","5.18722","0.02010"
"10406","62.40000","5.20025","0.02025"
"10432","62.55600","5.21323","0.02013"
"10458","62.71200","5.22614","0.02049"
"10484","62.86800","5.23924","0.02067"
"10510","63.02400","5.25221","0.02041"
"10536","63.18000","5.26519","0.02058"
"10562","63.33600","5.27822","0.02110"
"10588","63.49200","5.29125","0.02073"
"10614","63.64800","5.30423","0.02086"
"10640","63.80400","5.31720","0.02145"
"10666","63.96000","5.33024","0.02125"
"10692","64.11600","5.34321","0.02125"
"10718","64.27200","5.35619","0.02162"
"10744","64.42800","5.36916","0.02132"
"10770","64.58400","5.38219","0.02110"
"10796","64.74000","5.39517","0.02160"
"10822","64.89600","5.40814","0.02131"
"10848","65.05200","5.42124","0.02160"
"10874","65.20800","5.43421","0.02113"
"10900","65.36400","5.44719","0.02127"
"10926","65.52000","5.46022","0.02176"
"10952","65.67600","5.47325","0.02194"
"10978","65.83200","5.48623","0.02110"
"11004","65.98800","5.49920","0.02174"
"11030","66.14400","5.51224","0.02180"
"11056","66.30000","5.52521","0.02149"
"11082","66.45600","5.53818","0.02223"
"11108","66.61200","5.55122","0.02205"
"11134","66.76800","5.56419","0.02215"
"11160","66.92400","5.57723","0.02274"
"11186","67.08000","5.59020","0.02210"
"11212","67.23600","5.60330","0.02275"
"11238","67.39200","5.61627","0.02188"
"11264","67.54800","5.62918","0.02209"
"11290","67.70400","5.64222","0.02179"
"11316","67.86000","5.65519","0.02249"
"11342","68.01600","5.66823","0.02211"
"11368","68.17200","5.68114","0.02224"
"11394","68.32800","5.69424","0.02198"
"11420","68.48400","5.70721","0.02204"
"11446","68.64000","5.72018","0.02181"
"11472","68.79600","5.73322","0.02206"
"11498","68.95200","5.74625","0.02284"
"11524","69.10800","5.75923","0.02268"
"11550","69.26400","5.77220","0.02222"
"11576","69.42000","5.78524","0.02306"
"11602","69.57600","5.79821","0.02264"
"11628","69.73200","5.81118","0.02261"
"11654","69.88800","5.82422","0.02292"
"11680","70.04400","5.83725","0.02313"
"11706","70.20000","5.85011","0.02278"
"11732","70.35600","5.86320","0.02313"
"11758","70.51200","5.87624","0.02342"
"11784","70.66800","5.88921","0.02316"
"11810","70.82400","5.90218","0.02333"
"11836","70.98000","5.91534","0.02337"
"11862","71.13600","5.92825","0.02365"
"11888","71.29200","5.94117","0.02310"
"11914","71.44800","5.95420","0.02287"
"11940","71.60400","5.96723","0.02318"
"11966","71.76000","5.98021","0.02306"
"11992","71.91600","5.99318","0.02318"
"12018","72.07200","6.00622","0.02353"
"12044","72.22800","6.01925","0.02320"
"12070","72.38400","6.03217","0.02325"
"12096","72.54000","6.04520","0.02340"
"12122","72.69600","6.05823","0.02353"
"12148","72.85200","6.07121","0.02391"
"12174","73.00800","6.08418","0.02363"
"12200","73.16400","6.09722","0.02394"
"12226","73.32000","6.11025","0.02332"
"12252","73.47600","6.12317","0.02329"
"12278","73.63200","6.13620","0.02359"
"12304","73.78800","6.14923","0.02366"
"12330","73.94400","6.16221","0.02298"
"12356","74.10000","6.17524","0.02320"
"12382","74.25600","6.18828","0.02333"
"12408","74.41200","6.20125","0.02339"
"12434","74.56800","6.21422","0.02331"
"12460","74.72400","6.22720","0.02360"
"12486","74.88000","6.24023","0.02317"
"12512","75.03600","6.25321","0.02293"
"12538","75.19200","6.26624","0.02350"
"12564","75.34800","6.27922","0.02442"
"12590","75.50400","6.29219","0.02385"
"12616","75.66000","6.30511","0.02402"
"12642","75.81600","6.31826","0.02401"
"12668","75.97200","6.33123","0.02365"
"12694","76.12800","6.34421","0.02376"
"12720","76.28400","6.35718","0.02330"
"12746","76.44000","6.37022","0.02377"
"12772","76.59600","6.38325","0.02404"
"12798","76.75200","6.39616","0.02318"
"12824","76.90800","6.40926","0.02328"
"12850","77.06400","6.42223","0.02331"
"12876","77.22000","6.43521","0.02325"
"12902","77.37600","6.44818","0.02324"
"12928","77.53200","6.46122","0.02348"
"12954","77.68800","6.47425","0.02343"
"12980","77.84400","6.48722","0.02341"
"13006","78.00000","6.50026","0.02415"
"13032","78.15600","6.51323","0.02421"
"13058","78.31200","6.52621","0.02414"
"13084","78.46800","6.53924","0.02432"
"13110","78.62400","6.55222","0.02419"
"13136","78.78000","6.56519","0.02375"
"13162","78.93600","6.57816","0.02383"
"13188","79.09200","6.59120","0.02442"
"13214","79.24800","6.60423","0.02392"
"13240","79.40400","6.61715","0.02390"
"13266","79.56000","6.63030","0.02349"
"13292","79.71600","6.64328","0.02380"
"13318","79.87200","6.65625","0.02387"
"13344","80.02800","6.66922","0.02393"
"13370","80.18400","6.68226","0.02394"
"13396","80.34000","6.69523","0.02354"
"13422","80.49600","6.70821","0.02383"
"13448","80.65200","6.72124","0.02384"
"13474","80.80800","6.73427","0.02351"
"13500","80.96400","6.74719","0.02357"
"13526","81.12000","6.76022","0.02425"
"13552","81.27600","6.77326","0.02362"
"13578","81.43200","6.78623","0.02404"
"13604","81.58800","6.79921","0.02383"
"13630","81.74400","6.81224","0.02447"
"13656","81.90000","6.82527","0.02485"
"13682","82.05600","6.83819","0.02443"
"13708","82.21200","6.85116","0.02382"
"13734","82.36800","6.86426","0.02416"
"13760","82.52400","6.87717","0.02397"
"13786","82.68000","6.89015","0.02479"
"13812","82.83600","6.90324","0.02433"
"13838","82.99200","6.91627","0.02395"
"13864","83.14800","6.92919","0.02424"
"13890","83.30400","6.94222","0.02437"
"13916","83.46000","6.95526","0.02389"
"13942","83.61600","6.96817","0.02456"
"13968","83.77200","6.98121","0.02499"
"13994","83.92800","6.99424","0.02467"
"14020","84.08400","7.00727","0.02463"
"14046","84.24000","7.02019","0.02490"
"14072","84.39600","7.03322","0.02481"
"14098","84.55200","7.04620","0.02506"
"14124","84.70800","7.05923","0.02520"
"14150","84.86400","7.07221","0.02531"
"14176","85.02000","7.08524","0.02563"
"14202","85.17600","7.09821","0.02542"
"14228","85.33200","7.11119","0.02567"
"14254","85.48800","7.12422","0.02525"
"14280","85.64400","7.13726","0.02563"
"14306","85.80000","7.15023","0.02555"
"14332","85.95600","7.16314","0.02557"
"14358","86.11200","7.17624","0.02562"
"14384","86.26800","7.18915","0.02541"
"14410","86.42400","7.20213","0.02619"
"14436","86.58000","7.21522","0.02588"
"14462","86.73600","7.22826","0.02070"
"14488","86.89200","7.24123","0.01963"
"14514","87.04800","7.25426","0.02060"
"14540","87.20400","7.26724","0.02302"
"14566","87.36000","7.28021","0.02341"
"14592","87.51600","7.29319","0.02231"
"14618","87.67200","7.30628","0.02247"
"14644","87.82800","7.31926","0.02303"
"14670","87.98400","7.33223","0.02286"
"14696","88.14000","7.34526","0.02448"
"14722","88.29600","7.35824","0.02440"
"14748","88.45200","7.37121","0.02435"
"14774","88.60800","7.38419","0.02460"
"14800","88.76400","7.39728","0.02503"
"14826","88.92000","7.41025","0.02463"
"14852","89.07600","7.42317","0.02440"
"14878","89.23200","7.43626","0.02547"
"14904","89.38800","7.44924","0.02541"
"14930","89.54400","7.46221","0.02549"
"14956","89.70000","7.47519","0.02588"
"14982","89.85600","7.48822","0.02640"
"15008","90.01200","7.50119","0.02636"
"15034","90.16800","7.51417","0.02600"
"15060","90.32400","7.52726","0.02703"
"15086","90.48000","7.54024","0.02635"
"15112","90.63600","7.55315","0.02669"
"15138","90.79200","7.56619","0.02738"
"15164","90.94800","7.57922","0.02706"
"15190","91.10400","7.59220","0.02735"
"15216","91.26000","7.60517","0.02737"
"15242","91.41600","7.61820","0.02788"
"15268","91.57200","7.63124","0.02753"
"15294","91.72800","7.64421","0.02781"
"15320","91.88400","7.65719","0.02809"
"15346","92.04000","7.67022","0.02810"
"15372","92.19600","7.68325","0.02798"
"15398","92.35200","7.69617","0.02803"
"15424","92.50800","7.70926","0.02814"
"15450","92.66400","7.72224","0.02825"
"15476","92.82000","7.73521","0.02899"
"15502","92.97600","7.74819","0.02807"
"15528","93.13200","7.76122","0.02904"
"15554","93.28800","7.77419","0.02962"
"15580","93.44400","7.78717","0.02892"
"15606","93.60000","7.80020","0.02970"
"15632","93.75600","7.81318","0.02957"
"15658","93.91200","7.82615","0.02930"
"15684","94.06800","7.83919","0.02928"
"15710","94.22400","7.85228","0.03020"
"15736","94.38000","7.86525","0.03029"
"15762","94.53600","7.87823","0.02939"
"15788","94.69200","7.89120","0.02972"
"15814","94.84800","7.90418","0.03010"
"15840","95.00400","7.91715","0.03013"
"15866","95.16000","7.93024","0.02998"
"15892","95.31600","7.94322","0.03006"
"15918","95.47200","7.95619","0.03001"
"15944","95.62800","7.96923","0.03083"
"15970","95.78400","7.98226","0.03051"
"15996","95.94000","7.99524","0.03020"
"16022","96.09600","8.00815","0.03098"
"16048","96.25200","8.02124","0.02980"
"16074","96.40800","8.03428","0.03069"
"16100","96.56400","8.04719","0.03082"
"16126","96.72000","8.06023","0.03088"
"16152","96.87600","8.07320","0.03097"
"16178","97.03200","8.08618","0.03112"
"16204","97.18800","8.09915","0.03074"
"16230","97.34400","8.11224","0.03088"
"16256","97.50000","8.12528","0.03112"
"16282","97.65600","8.13819","0.03095"
"16308","97.81200","8.15123","0.03137"
"16334","97.96800","8.16420","0.03108"
"16360","98.12400","8.17723","0.03120"
"16386","98.28000","8.19015","0.03103"
"16412","98.43600","8.20324","0.03142"
"16438","98.59200","8.21622","0.03036"
"16464","98.74800","8.22919","0.02978"
"16490","98.90400","8.24217","0.02984"
"16516","99.06000","8.25526","0.02983"
"16542","99.21600","8.26818","0.02960"
"16568","99.37200","8.28121","0.02962"
"16594","99.52800","8.29424","0.02941"
"16620","99.68400","8.30722","0.02926"
"16646","99.84000","8.32013","0.02883"
"16672","99.99600","8.33323","0.02910"
"16698","100.15200","8.34626","0.02879"
"16724","100.30800","8.35917","0.02805"
"16750","100.46400","8.37215","0.02727"
"16776","100.62000","8.38518","0.02739"
"16802","100.77600","8.39822","0.02723"
"16828","100.93200","8.41119","0.02677"
"16854","101.08800","8.42422","0.02189"
"16880","101.24400","8.43726","0.02153"
"16906","101.40000","8.45017","0.02266"
"16932","101.55600","8.46321","0.02305"
"16958","101.71200","8.47618","0.02397"
"16984","101.86800","8.48916","0.02428"
"17010","102.02400","8.50213","0.02445"
"17036","102.18000","8.51522","0.02392"
"17062","102.33600","8.52820","0.02393"
"17088","102.49200","8.54117","0.02176"
"17114","102.64800","8.55421","0.01837"
"17140","102.80400","8.56724","0.01742"
"17166","102.96000","8.58028","0.01598"
"17192","103.11600","8.59325","0.01500"
"17218","103.27200","8.60629","0.01478"
"17244","103.42800","8.61920","0.01508"
"17270","103.58400","8.63217","0.01468"
"17296","103.74000","8.64521","0.01449"
"17322","103.89600","8.65824","0.01433"
"17348","104.05200","8.67116","0.01512"
"17374","104.20800","8.68419","0.01463"
"17400","104.36400","8.69717","0.01532"
"17426","104.52000","8.71026","0.01562"
"17452","104.67600","8.72317","0.01565"
"17478","104.83200","8.73627","0.01479"
"17504","104.98800","8.74924","0.01498"
"17530","105.14400","8.76222","0.01508"
"17556","105.30000","8.77519","0.01453"
"17582","105.45600","8.78828","0.01594"
"17608","105.61200","8.80126","0.01556"
"17634","105.76800","8.81417","0.01593"
"17660","105.92400","8.82721","0.01581"
"17686","106.08000","8.84024","0.01563"
"17712","106.23600","8.85316","0.01499"
"17738","106.39200","8.86619","0.01554"
"17764","106.54800","8.87928","0.01536"
"17790","106.70400","8.89226","0.01541"
"17816","106.86000","8.90517","0.01524"
"17842","107.01600","8.91827","0.01548"
"17868","107.17200","8.93124","0.01565"
"17894","107.32800","8.94421","0.01561"
"17920","107.48400","8.95719","0.01567"
"17946","107.64000","8.97022","0.01604"
"17972","107.79600","8.98320","0.01593"
"17998","107.95200","8.99617","0.01610"
"18024","108.10800","9.00921","0.01665"
"18050","108.26400","9.02224","0.01624"
"18076","108.42000","9.03521","0.01666"
"18102","108.57600","9.04825","0.01643"
"18128","108.73200","9.06122","0.01635"
"18154","108.88800","9.07420","0.01656"
"18180","109.04400","9.08717","0.01632"
"18206","109.20000","9.10027","0.01649"
"18232","109.35600","9.11324","0.01739"
"18258","109.51200","9.12621","0.01685"
"18284","109.66800","9.13919","0.01750"
"18310","109.82400","9.15222","0.01648"
"18336","109.98000","9.16526","0.01672"
"18362","110.13600","9.17823","0.01701"
"18388","110.29200","9.19127","0.01713"
"18414","110.44800","9.20424","0.01734"
"18440","110.60400","9.21715","0.01714"
"18466","110.76000","9.23019","0.01764"
"18492","110.91600","9.24316","0.01770"
"18518","111.07200","9.25620","0.01745"
"18544","111.22800","9.26917","0.01775"
"18570","111.38400","9.28221","0.01802"
"18596","111.54000","9.29518","0.01842"
"18622","111.69600","9.30815","0.01801"
"18648","111.85200","9.32125","0.01800"
"18674","112.00800","9.33422","0.01804"
"18700","112.16400","9.34720","0.01854"
"18726","112.32000","9.36017","0.01837"
"18752","112.47600","9.37327","0.01807"
"18778","112.63200","9.38618","0.01848"
"18804","112.78800","9.39921","0.01827"
"18830","112.94400","9.41225","0.01817"
"18856","113.10000","9.42522","0.01857"
"18882","113.25600","9.43814","0.01891"
"18908","113.41200","9.45123","0.01909"
"18934","113.56800","9.46426","0.01853"
"18960","113.72400","9.47724","0.01877"
"18986","113.88000","9.49021","0.01910"
"19012","114.03600","9.50331","0.01929"
"19038","114.19200","9.51622","0.01871"
"19064","114.34800","9.52920","0.01916"
"19090","114.50400","9.54223","0.01951"
"19116","114.66000","9.55520","0.01931"
"19142","114.81600","9.56818","0.01958"
"19168","114.97200","9.58115","0.02020"
"19194","115.12800","9.59425","0.01936"
"19220","115.28400","9.60722","0.01963"
"19246","115.44000","9.62020","0.01981"
"19272","115.59600","9.63323","0.02020"
"19298","115.75200","9.64626","0.01954"
"19324","115.90800","9.65918","0.01975"
"19350","116.06400","9.67221","0.02023"
"19376","116.22000","9.68519","0.02000"
"19402","116.37600","9.69822","0.01994"
"19428","116.53200","9.71113","0.02024"
"19454","116.68800","9.72423","0.01990"
"19480","116.84400","9.73720","0.02022"
"19506","117.00000","9.75018","0.02047"
"19532","117.15600","9.76321","0.02041"
"19558","117.31200","9.77625","0.02069"
"19584","117.46800","9.78928","0.02055"
"19610","117.62400","9.80219","0.02109"
"19636","117.78000","9.81523","0.02104"
"19662","117.93600","9.82826","0.02066"
"19688","118.09200","9.84118","0.02164"
"19714","118.24800","9.85421","0.02135"
"19740","118.40400","9.86719","0.02028"
"19766","118.56000","9.88022","0.02103"
"19792","118.71600","9.89313","0.02138"
"19818","118.87200","9.90629","0.02160"
"19844","119.02800","9.91926","0.02074"
"19870","119.18400","9.93224","0.02106"
"19896","119.34000","9.94515","0.02161"
"19922","119.49600","9.95825","0.02108"
"19948","119.65200","9.97116","0.02118"
"19974","119.80800","9.98413","0.02155"
"20000","119.96400","9.99723","0.02152"
"20026","120.12000","10.01020","0.02186"
"20052","120.27600","10.02318","0.02143"
"20078","120.43200","10.03621","0.02197"
"20104","120.58800","10.04924","0.02177"
"20130","120.74400","10.06222","0.02206"
"20156","120.90000","10.07519","0.02175"
"20182","121.05600","10.08829","0.02182"
"20208","121.21200","10.10120","0.02193"
"20234","121.36800","10.11418","0.02216"
"20260","121.52400","10.12721","0.02187"
"20286","121.68000","10.14024","0.02210"
"20312","121.83600","10.15322","0.02262"
"20338","121.99200","10.16619","0.02191"
"20364","122.14800","10.17923","0.02262"
"20390","122.30400","10.19226","0.02186"
"20416","122.46000","10.20518","0.02261"
"20442","122.61600","10.21827","0.02272"
"20468","122.77200","10.23125","0.02297"
"20494","122.92800","10.24422","0.02277"
"20520","123.08400","10.25719","0.02304"
"20546","123.24000","10.27023","0.02239"
"20572","123.39600","10.28320","0.02301"
"20598","123.55200","10.29612","0.02281"
"20624","123.70800","10.30921","0.02320"
"20650","123.86400","10.32224","0.02286"
"20676","124.02000","10.33516","0.02332"
"20702","124.17600","10.34819","0.02301"
"20728","124.33200","10.36123","0.02306"
"20754","124.48800","10.37420","0.02304"
"20780","124.64400","10.38724","0.02344"
"20806","124.80000","10.40027","0.02318"
"20832","124.95600","10.41324","0.02335"
"20858","125.11200","10.42616","0.02329"
"20884","125.26800","10.43919","0.02353"
"20910","125.42400","10.45223","0.02386"
"20936","125.58000","10.46520","0.02337"
"20962","125.73600","10.47818","0.02341"
"20988","125.89200","10.49121","0.02348"
"21014","126.04800","10.50424","0.02352"
"21040","126.20400","10.51722","0.02327"
"21066","126.36000","10.53025","0.02376"
"21092","126.51600","10.54329","0.02410"
"21118","126.67200","10.55620","0.02364"
"21144","126.82800","10.56918","0.02381"
"21170","126.98400","10.58221","0.02371"
"21196","127.14000","10.59524","0.02405"
"21222","127.29600","10.60810","0.02423"
"21248","127.45200","10.62125","0.02422"
"21274","127.60800","10.63423","0.02406"
"21300","127.76400","10.64720","0.02374"
"21326","127.92000","10.66018","0.02401"
"21352","128.07600","10.67327","0.02356"
"21378","128.23200","10.68624","0.02368"
"21404","128.38800","10.69916","0.02403"
"21430","128.54400","10.71219","0.02372"
"21456","128.70000","10.72523","0.02371"
"21482","128.85600","10.73820","0.02344"
"21508","129.01200","10.75117","0.02335"
"21534","129.16800","10.76415","0.02348"
"21560","129.32400","10.77712","0.02343"
"21586","129.48000","10.79016","0.02301"
"21612","129.63600","10.80325","0.02353"
"21638","129.79200","10.81623","0.02404"
"21664","129.94800","10.82920","0.02339"
"21690","130.10400","10.84223","0.02349"
"21716","130.26000","10.85527","0.02393"
"21742","130.41600","10.86824","0.02386"
"21768","130.57200","10.88116","0.02384"
"21794","130.72800","10.89425","0.02422"
"21820","130.88400","10.90723","0.02391"
"21846","131.04000","10.92014","0.02394"
"21872","131.19600","10.93323","0.02406"
"21898","131.35200","10.94627","0.02420"
"21924","131.50800","10.95918","0.02396"
"21950","131.66400","10.97222","0.02444"
"21976","131.82000","10.98525","0.02437"
"22002","131.97600","10.99828","0.02440"
"22028","132.13200","11.01114","0.02424"
"22054","132.28800","11.02429","0.02315"
"22080","132.44400","11.03721","0.02295"
"22106","132.60000","11.05018","0.02299"
"22132","132.75600","11.06316","0.02357"
"22158","132.91200","11.07625","0.02308"
"22184","133.06800","11.08922","0.02333"
"22210","133.22400","11.10214","0.02282"
"22236","133.38000","11.11517","0.02284"
"22262","133.53600","11.12827","0.02342"
"22288","133.69200","11.14118","0.02341"
"22314","133.84800","11.15422","0.02322"
"22340","134.00400","11.16719","0.02272"
"22366","134.16000","11.18016","0.02326"
"22392","134.31600","11.19314","0.02317"
"22418","134.47200","11.20617","0.02360"
"22444","134.62800","11.21921","0.02348"
"22470","134.78400","11.23218","0.02381"
"22496","134.94000","11.24522","0.02373"
"22522","135.09600","11.25831","0.02400"
"22548","135.25200","11.27122","0.02345"
"22574","135.40800","11.28420","0.02382"
"22600","135.56400","11.29723","0.02377"
"22626","135.72000","11.31021","0.02394"
"22652","135.87600","11.32318","0.02393"
"22678","136.03200","11.33622","0.02386"
"22704","136.18800","11.34919","0.02418"
"22730","136.34400","11.36216","0.02451"
"22756","136.50000","11.37514","0.02399"
"22782","136.65600","11.38823","0.02452"
"22808","136.81200","11.40121","0.02466"
"22834","136.96800","11.41418","0.02426"
"22860","137.12400","11.42722","0.02425"
"22886","137.28000","11.44025","0.02497"
"22912","137.43600","11.45322","0.02497"
"22938","137.59200","11.46620","0.02464"
"22964","137.74800","11.47923","0.02486"
"22990","137.90400","11.49221","0.02455"
"23016","138.06000","11.50512","0.02485"
"23042","138.21600","11.51822","0.02472"
"23068","138.37200","11.53125","0.02555"
"23094","138.52800","11.54416","0.02506"
"23120","138.68400","11.55726","0.02525"
"23146","138.84000","11.57029","0.02522"
"23172","138.99600","11.58327","0.02539"
"23198","139.15200","11.59618","0.02516"
"23224","139.30800","11.60927","0.02558"
"23250","139.46400","11.62225","0.02545"
"23276","139.62000","11.63516","0.02504"
"23302","139.77600","11.64826","0.02548"
"23328","139.93200","11.66117","0.02532"
"23354","140.08800","11.67415","0.02616"
"23380","140.24400","11.68712","0.02639"
"23406","140.40000","11.70027","0.02592"
"23432","140.55600","11.71325","0.02620"
"23458","140.71200","11.72616","0.02595"
"23484","140.86800","11.73926","0.02619"
"23510","141.02400","11.75223","0.02614"
"23536","141.18000","11.76520","0.02637"
"23562","141.33600","11.77818","0.02663"
"23588","141.49200","11.79127","0.02623"
"23614","141.64800","11.80425","0.02659"
"23640","141.80400","11.81716","0.02669"
"23666","141.96000","11.83014","0.02661"
"23692","142.11600","11.84323","0.02667"
"23718","142.27200","11.85620","0.02667"
"23744","142.42800","11.86924","0.02661"
"23770","142.58400","11.88221","0.02662"
"23796","142.74000","11.89525","0.02696"
"23822","142.89600","11.90816","0.02729"
"23848","143.05200","11.92126","0.02771"
"23874","143.20800","11.93423","0.02762"
"23900","143.36400","11.94720","0.02789"
"23926","143.52000","11.96018","0.02742"
"23952","143.67600","11.97321","0.02707"
"23978","143.83200","11.98625","0.02723"
"24004","143.98800","11.99916","0.02778"
"24030","144.14400","12.01225","0.02769"
"24056","144.30000","12.02523","0.02806"
"24082","144.45600","12.03821","0.02760"
"24108","144.61200","12.05118","0.02785"
"24134","144.76800","12.06421","0.02784"
"24160","144.92400","12.07719","0.02844"
"24186","145.08000","12.09022","0.02808"
"24212","145.23600","12.10326","0.02776"
"24238","145.39200","12.11623","0.02827"
"24264","145.54800","12.12920","0.02856"
"24290","145.70400","12.14224","0.02810"
"24316","145.86000","12.15527","0.02834"
"24342","146.01600","12.16825","0.02955"
"24368","146.17200","12.18122","0.02859"
"24394","146.32800","12.19425","0.02903"
"24420","146.48400","12.20723","0.02892"
"24446","146.64000","12.22014","0.02913"
"24472","146.79600","12.23318","0.02927"
"24498","146.95200","12.24621","0.02855"
"24524","147.10800","12.25913","0.02911"
"24550","147.26400","12.27222","0.02948"
"24576","147.42000","12.28525","0.02896"
"24602","147.57600","12.29823","0.02940"
"24628","147.73200","12.31120","0.02943"
"24654","147.88800","12.32430","0.02952"
"24680","148.04400","12.33721","0.02955"
"24706","148.20000","12.35018","0.02969"
"24732","148.35600","12.36316","0.02970"
"24758","148.51200","12.37619","0.02959"
"24784","148.66800","12.38923","0.02960"
"24810","148.82400","12.40214","0.02992"
"24836","148.98000","12.41524","0.02980"
"24862","149.13600","12.42821","0.03065"
"24888","149.29200","12.44112","0.02985"
"24914","149.44800","12.45422","0.02992"
"24940","149.60400","12.46725","0.02998"
"24966","149.76000","12.48029","0.03058"
"24992","149.91600","12.49320","0.03063"
"25018","150.07200","12.50630","0.03020"
"25044","150.22800","12.51927","0.03033"
"25070","150.38400","12.53218","0.03018"
"25096","150.54000","12.54522","0.03089"
"25122","150.69600","12.55819","0.03046"
"25148","150.85200","12.57117","0.03017"
"25174","151.00800","12.58420","0.03013"
"25200","151.16400","12.59724","0.03104"
"25226","151.32000","12.61027","0.03119"
"25252","151.47600","12.62324","0.03129"
"25278","151.63200","12.63628","0.03037"
"25304","151.78800","12.64925","0.03062"
"25330","151.94400","12.66223","0.03091"
"25356","152.10000","12.67514","0.03108"
"25382","152.25600","12.68824","0.03126"
"25408","152.41200","12.70121","0.03116"
"25434","152.56800","12.71418","0.03115"
"25460","152.72400","12.72722","0.03157"
"25486","152.88000","12.74025","0.03190"
"25512","153.03600","12.75317","0.03169"
"25538","153.19200","12.76620","0.03230"
"25564","153.34800","12.77929","0.03200"
"25590","153.50400","12.79227","0.03204"
"25616","153.66000","12.80518","0.03168"
"25642","153.81600","12.81828","0.03203"
"25668","153.97200","12.83119","0.03120"
"25694","154.12800","12.84423","0.03173"
"25720","154.28400","12.85720","0.03132"
"25746","154.44000","12.87024","0.03176"
"25772","154.59600","12.88321","0.03215"
"25798","154.75200","12.89618","0.03161"
"25824","154.90800","12.90928","0.03207"
"25850","155.06400","12.92225","0.03227"
"25876","155.22000","12.93517","0.03192"
"25902","155.37600","12.94820","0.03189"
"25928","155.53200","12.96124","0.03261"
"25954","155.68800","12.97415","0.03145"
"25980","155.84400","12.98718","0.03202"
"26006","156.00000","13.00022","0.03259"
"26032","156.15600","13.01319","0.03217"
"26058","156.31200","13.02617","0.03252"
"26084","156.46800","13.03926","0.03272"
"26110","156.62400","13.05223","0.03290"
"26136","156.78000","13.06521","0.03253"
"26162","156.93600","13.07818","0.03238"
"26188","157.09200","13.09128","0.03275"
"26214","157.24800","13.10419","0.03196"
"26240","157.40400","13.11717","0.03290"
"26266","157.56000","13.13020","0.03249"
"26292","157.71600","13.14323","0.03317"
"26318","157.87200","13.15621","0.03347"
"26344","158.02800","13.16918","0.03306"
"26370","158.18400","13.18228","0.03346"
"26396","158.34000","13.19525","0.03311"
"26422","158.49600","13.20817","0.03313"
"26448","158.65200","13.22126","0.03371"
"26474","158.80800","13.23423","0.03316"
"26500","158.96400","13.24721","0.03355"
"26526","159.12000","13.26018","0.03359"
"26552","159.27600","13.27322","0.03330"
"26578","159.43200","13.28619","0.03331"
"26604","159.58800","13.29910","0.03407"
"26630","159.74400","13.31220","0.03345"
"26656","159.90000","13.32523","0.03377"
"26682","160.05600","13.33821","0.03365"
"26708","160.21200","13.35124","0.03350"
"26734","160.36800","13.36422","0.03428"
"26760","160.52400","13.37725","0.03435"
"26786","160.68000","13.39023","0.03427"
"26812","160.83600","13.40326","0.03431"
"26838","160.99200","13.41629","0.03450"
"26864","161.14800","13.42915","0.03424"
"26890","161.30400","13.44218","0.03515"
"26916","161.46000","13.45522","0.03334"
"26942","161.61600","13.46819","0.03318"
"26968","161.77200","13.48116","0.03338"
"26994","161.92800","13.49426","0.03355"
"27020","162.08400","13.50723","0.03315"
"27046","162.24000","13.52021","0.03271"
"27072","162.39600","13.53318","0.03313"
"27098","162.55200","13.54622","0.03376"
"27124","162.70800","13.55919","0.03325"
"27150","162.86400","13.57216","0.03361"
"27176","163.02000","13.58526","0.03363"
"27202","163.17600","13.59817","0.03276"
"27228","163.33200","13.61115","0.03318"
"27254","163.48800","13.62424","0.03383"
"27280","163.64400","13.63722","0.03358"
"27306","163.80000","13.65025","0.03316"
"27332","163.95600","13.66322","0.03351"
"27358","164.11200","13.67626","0.03324"
"27384","164.26800","13.68917","0.03362"
"27410","164.42400","13.70215","0.03332"
"27436","164.58000","13.71524","0.03357"
"27462","164.73600","13.72822","0.03335"
"27488","164.89200","13.74119","0.03418"
"27514","165.04800","13.75422","0.03361"
"27540","165.20400","13.76720","0.03408"
"27566","165.36000","13.78023","0.03480"
"27592","165.51600","13.79315","0.03434"
"27618","165.67200","13.80624","0.03413"
"27644","165.82800","13.81928","0.03452"
"27670","165.98400","13.83219","0.03428"
"27696","166.14000","13.84522","0.03489"
"27722","166.29600","13.85826","0.03399"
"27748","166.45200","13.87123","0.03434"
"27774","166.60800","13.88415","0.03487"
"27800","166.76400","13.89718","0.03459"
"27826","166.92000","13.91022","0.03497"
"27852","167.07600","13.92313","0.03445"
"27878","167.23200","13.93622","0.03505"
"27904","167.38800","13.94926","0.03538"
"27930","167.54400","13.96223","0.03540"
"27956","167.70000","13.97520","0.03572"
"27982","167.85600","13.98824","0.03552"
"28008","168.01200","14.00121","0.03505"
"28034","168.16800","14.01419","0.03420"
"28060","168.32400","14.02716","0.03485"
"28086","168.48000","14.04026","0.03576"
"28112","168.63600","14.05317","0.03522"
"28138","168.79200","14.06615","0.03583"
"28164","168.94800","14.07924","0.03597"
"28190","169.10400","14.09227","0.03517"
"28216","169.26000","14.10519","0.03585"
"28242","169.41600","14.11822","0.03621"
"28268","169.57200","14.13126","0.03590"
"28294","169.72800","14.14423","0.03639"
"28320","169.88400","14.15721","0.03578"
"28346","170.04000","14.17018","0.03616"
"28372","170.19600","14.18321","0.03592"
"28398","170.35200","14.19613","0.03627"
"28424","170.50800","14.20922","0.03669"
"28450","170.66400","14.22220","0.03673"
"28476","170.82000","14.23523","0.03609"
"28502","170.97600","14.24827","0.03618"
"28528","171.13200","14.26124","0.03650"
"28554","171.28800","14.27427","0.03690"
"28580","171.44400","14.28719","0.03720"
"28606","171.60000","14.30022","0.03699"
"28632","171.75600","14.31326","0.03743"
"28658","171.91200","14.32623","0.03732"
"28684","172.06800","14.33920","0.03787"
"28710","172.22400","14.35218","0.03814"
"28736","172.38000","14.36515","0.03752"
"28762","172.53600","14.37819","0.03680"
"28788","172.69200","14.39122","0.03647"
"28814","172.84800","14.40425","0.03677"
"28840","173.00400","14.41723","0.03673"
"28866","173.16000","14.43020","0.03721"
"28892","173.31600","14.44324","0.03770"
"28918","173.47200","14.45621","0.03700"
"28944","173.62800","14.46919","0.03671"
"28970","173.78400","14.48228","0.03788"
"28996","173.94000","14.49520","0.03727"
"29022","174.09600","14.50817","0.03711"
"29048","174.25200","14.52126","0.03757"
"29074","174.40800","14.53424","0.03715"
"29100","174.56400","14.54721","0.03606"
"29126","174.72000","14.56025","0.03728"
"29152","174.87600","14.57322","0.03716"
"29178","175.03200","14.58625","0.03699"
"29204","175.18800","14.59917","0.03764"
"29230","175.34400","14.61226","0.03752"
"29256","175.50000","14.62524","0.03830"
"29282","175.65600","14.63821","0.03782"
"29308","175.81200","14.65119","0.03776"
"29334","175.96800","14.66428","0.03750"
"29360","176.12400","14.67725","0.03822"
"29386","176.28000","14.69017","0.03823"
"29412","176.43600","14.70326","0.03819"
"29438","176.59200","14.71624","0.03801"
"29464","176.74800","14.72915","0.03858"
"29490","176.90400","14.74219","0.03829"
"29516","177.06000","14.75522","0.03863"
"29542","177.21600","14.76825","0.03884"
"29568","177.37200","14.78117","0.03850"
"29594","177.52800","14.79420","0.03886"
"29620","177.68400","14.80724","0.03908"
"29646","177.84000","14.82021","0.03900"
"29672","177.99600","14.83325","0.03929"
"29698","178.15200","14.84628","0.03891"
"29724","178.30800","14.85925","0.03924"
"29750","178.46400","14.87223","0.03900"
"29776","178.62000","14.88526","0.03891"
"29802","178.77600","14.89824","0.03897"
"29828","178.93200","14.91121","0.03843"
"29854","179.08800","14.92418","0.03856"
"29880","179.24400","14.93722","0.03831"
"29906","179.40000","14.95019","0.03934"
"29932","179.55600","14.96317","0.03952"
"29958","179.71200","14.97626","0.03913"
"29984","179.86800","14.98924","0.03926"
"30010","180.02400","15.00221","0.03955"
"30036","180.18000","15.01518","0.03891"
"30062","180.33600","15.02822","0.03875"
"30088","180.49200","15.04119","0.03786"
"30114","180.64800","15.05417","0.03829"
"30140","180.80400","15.06720","0.03773"
"30166","180.96000","15.08018","0.03595"
"30192","181.11600","15.09315","0.03598"
"30218","181.27200","15.10624","0.03714"
"30244","181.42800","15.11922","0.03684"
"30270","181.58400","15.13225","0.03721"
"30296","181.74000","15.14523","0.03753"
"30322","181.89600","15.15826","0.03771"
"30348","182.05200","15.17124","0.03536"
"30374","182.20800","15.18415","0.03516"
"30400","182.36400","15.19724","0.03570"
"30426","182.52000","15.21022","0.03599"
"30452","182.67600","15.22319","0.03575"
"30478","182.83200","15.23623","0.03644"
"30504","182.98800","15.24920","0.03666"
"30530","183.14400","15.26218","0.03709"
"30556","183.30000","15.27515","0.03765"
"30582","183.45600","15.28830","0.03794"
"30608","183.61200","15.30128","0.03807"
"30634","183.76800","15.31419","0.03773"
"30660","183.92400","15.32729","0.03829"
"30686","184.08000","15.34020","0.03784"
"30712","184.23600","15.35323","0.03842"
"30738","184.39200","15.36615","0.03913"
"30764","184.54800","15.37924","0.03966"
"30790","184.70400","15.39222","0.03908"
"30816","184.86000","15.40519","0.03948"
"30842","185.01600","15.41823","0.03915"
"30868","185.17200","15.43126","0.03887"
"30894","185.32800","15.44417","0.03970"
"30920","185.48400","15.45721","0.03837"
"30946","185.64000","15.47024","0.03778"
"30972","185.79600","15.48322","0.03772"
"30998","185.95200","15.49613","0.03743"
"31024","186.10800","15.50923","0.03755"
"31050","186.26400","15.52226","0.03873"
"31076","186.42000","15.53517","0.03890"
"31102","186.57600","15.54821","0.03902"
"31128","186.73200","15.56118","0.03899"
"31154","186.88800","15.57428","0.03642"
"31180","187.04400","15.58719","0.03689"
"31206","187.20000","15.60023","0.03768"
"31232","187.35600","15.61326","0.03766"
"31258","187.51200","15.62617","0.03734"
"31284","187.66800","15.63921","0.03734"
"31310","187.82400","15.65224","0.03800"
"31336","187.98000","15.66522","0.03858"
"31362","188.13600","15.67813","0.03834"
"31388","188.29200","15.69122","0.03924"
"31414","188.44800","15.70426","0.03908"
"31440","188.60400","15.71723","0.03921"
"31466","188.76000","15.73021","0.04005"
"31492","188.91600","15.74324","0.03974"
"31518","189.07200","15.75622","0.03969"
"31544","189.22800","15.76919","0.04028"
"31570","189.38400","15.78228","0.04051"
"31596","189.54000","15.79520","0.04081"
"31622","189.69600","15.80817","0.04033"
"31648","189.85200","15.82121","0.04042"
"31674","190.00800","15.83424","0.04125"
"31700","190.16400","15.84716","0.03967"
"31726","190.32000","15.86019","0.04005"
"31752","190.47600","15.87322","0.04089"
"31778","190.63200","15.88626","0.04062"
"31804","190.78800","15.89917","0.04088"
"31830","190.94400","15.91227","0.04167"
"31856","191.10000","15.92524","0.04109"
"31882","191.25600","15.93822","0.04131"
"31908","191.41200","15.95119","0.04175"
"31934","191.56800","15.96422","0.04174"
"31960","191.72400","15.97720","0.04210"
"31986","191.88000","15.99011","0.04165"
"32012","192.03600","16.00321","0.04265"
"32038","192.19200","16.01630","0.04265"
"32064","192.34800","16.02916","0.04299"
"32090","192.50400","16.04225","0.04229"
"32116","192.66000","16.05522","0.04304"
"32142","192.81600","16.06826","0.04302"
"32144","192.82800","16.06921","0.04320"