File: Trajectories_together/170226_1Specimen_RawData_10.csv
"","V1","V2","V3"
"1","End date","2/26/2017",""
"2","Specimen label","2BG_13",""
"3","Maximum Load","0.69358","N"
"4","Time","Extension","Load"
"5","(s)","(mm)","(N)"
"6","0.00000","0.00000","-0.00393"
"69","0.37800","0.03175","-0.00177"
"132","0.75600","0.06314","-0.00088"
"195","1.13400","0.09471","0.00059"
"258","1.51200","0.12622","0.00116"
"321","1.89000","0.15766","0.00210"
"384","2.26800","0.18917","0.00261"
"447","2.64600","0.22074","0.00361"
"510","3.02400","0.25219","0.00448"
"573","3.40200","0.28370","0.00533"
"636","3.78000","0.31521","0.00610"
"699","4.15800","0.34672","0.00667"
"762","4.53600","0.37817","0.00749"
"825","4.91400","0.40968","0.00771"
"888","5.29200","0.44119","0.00906"
"951","5.67000","0.47270","0.00907"
"1014","6.04800","0.50415","0.00984"
"1077","6.42600","0.53571","0.01069"
"1140","6.80400","0.56722","0.01075"
"1203","7.18200","0.59867","0.01272"
"1266","7.56000","0.63024","0.01292"
"1329","7.93800","0.66169","0.01383"
"1392","8.31600","0.69314","0.01348"
"1455","8.69400","0.72465","0.01372"
"1518","9.07200","0.75622","0.01460"
"1581","9.45000","0.78773","0.01544"
"1644","9.82800","0.81918","0.01532"
"1707","10.20600","0.85075","0.01644"
"1770","10.58400","0.88219","0.01651"
"1833","10.96200","0.91364","0.01754"
"1896","11.34000","0.94521","0.01823"
"1959","11.71800","0.97678","0.01769"
"2022","12.09600","1.00817","0.01904"
"2085","12.47400","1.03968","0.01941"
"2148","12.85200","1.07119","0.02041"
"2211","13.23000","1.10270","0.02121"
"2274","13.60800","1.13421","0.02148"
"2337","13.98600","1.16572","0.02102"
"2400","14.36400","1.19723","0.02218"
"2463","14.74200","1.22867","0.02262"
"2526","15.12000","1.26018","0.02235"
"2589","15.49800","1.29169","0.02285"
"2652","15.87600","1.32320","0.02385"
"2715","16.25400","1.35459","0.02413"
"2778","16.63200","1.38622","0.02457"
"2841","17.01000","1.41773","0.02477"
"2904","17.38800","1.44912","0.02468"
"2967","17.76600","1.48075","0.02572"
"3030","18.14400","1.51220","0.02595"
"3093","18.52200","1.54365","0.02642"
"3156","18.90000","1.57522","0.02661"
"3219","19.27800","1.60672","0.02739"
"3282","19.65600","1.63817","0.02726"
"3345","20.03400","1.66968","0.02771"
"3408","20.41200","1.70125","0.02803"
"3471","20.79000","1.73270","0.02859"
"3534","21.16800","1.76415","0.02900"
"3597","21.54600","1.79572","0.02891"
"3660","21.92400","1.82723","0.02881"
"3723","22.30200","1.85868","0.02968"
"3786","22.68000","1.89019","0.02950"
"3849","23.05800","1.92176","0.02990"
"3912","23.43600","1.95314","0.03024"
"3975","23.81400","1.98465","0.03085"
"4038","24.19200","2.01622","0.03107"
"4101","24.57000","2.04773","0.03040"
"4164","24.94800","2.07918","0.03149"
"4227","25.32600","2.11069","0.03198"
"4290","25.70400","2.14220","0.03117"
"4353","26.08200","2.17365","0.03110"
"4416","26.46000","2.20516","0.03198"
"4479","26.83800","2.23673","0.03189"
"4542","27.21600","2.26824","0.03248"
"4605","27.59400","2.29962","0.03212"
"4668","27.97200","2.33125","0.03250"
"4731","28.35000","2.36270","0.03288"
"4794","28.72800","2.39409","0.03280"
"4857","29.10600","2.42572","0.03271"
"4920","29.48400","2.45717","0.03337"
"4983","29.86200","2.48874","0.03341"
"5046","30.24000","2.52019","0.03384"
"5109","30.61800","2.55170","0.03351"
"5172","30.99600","2.58321","0.03267"
"5235","31.37400","2.61472","0.03247"
"5298","31.75200","2.64616","0.03288"
"5361","32.13000","2.67773","0.03286"
"5424","32.50800","2.70918","0.03325"
"5487","32.88600","2.74063","0.03330"
"5550","33.26400","2.77220","0.03367"
"5613","33.64200","2.80371","0.03383"
"5676","34.02000","2.83516","0.03426"
"5739","34.39800","2.86673","0.03418"
"5802","34.77600","2.89818","0.03459"
"5865","35.15400","2.92963","0.03478"
"5928","35.53200","2.96126","0.03490"
"5991","35.91000","2.99271","0.03497"
"6054","36.28800","3.02415","0.03519"
"6117","36.66600","3.05566","0.03564"
"6180","37.04400","3.08723","0.03580"
"6243","37.42200","3.11868","0.03577"
"6306","37.80000","3.15019","0.03577"
"6369","38.17800","3.18170","0.00633"
"6432","38.55600","3.21327","0.00644"
"6495","38.93400","3.24460","0.00716"
"6558","39.31200","3.27623","0.00662"
"6621","39.69000","3.30774","0.00669"
"6684","40.06800","3.33913","0.00660"
"6747","40.44600","3.37069","0.00584"
"6810","40.82400","3.40220","0.00546"
"6873","41.20200","3.43371","0.00666"
"6936","41.58000","3.46516","0.00662"
"6999","41.95800","3.49667","0.00766"
"7062","42.33600","3.52824","0.00841"
"7125","42.71400","3.55963","0.00867"
"7188","43.09200","3.59120","0.00907"
"7251","43.47000","3.62271","0.00969"
"7314","43.84800","3.65416","0.01043"
"7377","44.22600","3.68567","0.01098"
"7440","44.60400","3.71723","0.01133"
"7503","44.98200","3.74868","0.01129"
"7566","45.36000","3.78019","0.01132"
"7629","45.73800","3.81176","0.01131"
"7692","46.11600","3.84321","0.01159"
"7755","46.49400","3.87466","0.01297"
"7818","46.87200","3.90617","0.01281"
"7881","47.25000","3.93768","0.01325"
"7944","47.62800","3.96919","0.01302"
"8007","48.00600","4.00070","0.01450"
"8070","48.38400","4.03221","0.01421"
"8133","48.76200","4.06372","0.01495"
"8196","49.14000","4.09516","0.01505"
"8259","49.51800","4.12667","0.01524"
"8322","49.89600","4.15830","0.01584"
"8385","50.27400","4.18969","0.01623"
"8448","50.65200","4.22120","0.01628"
"8511","51.03000","4.25271","0.01602"
"8574","51.40800","4.28416","0.01640"
"8637","51.78600","4.31567","0.01635"
"8700","52.16400","4.34724","0.01713"
"8763","52.54200","4.37875","0.01712"
"8826","52.92000","4.41014","0.01736"
"8889","53.29800","4.44170","0.01767"
"8952","53.67600","4.47321","0.01803"
"9015","54.05400","4.50466","0.01790"
"9078","54.43200","4.53617","0.01823"
"9141","54.81000","4.56774","0.01851"
"9204","55.18800","4.59919","0.01873"
"9267","55.56600","4.63070","0.01891"
"9330","55.94400","4.66227","0.01852"
"9393","56.32200","4.69372","0.01850"
"9456","56.70000","4.72517","0.01879"
"9519","57.07800","4.75674","0.01848"
"9582","57.45600","4.78819","0.01927"
"9645","57.83400","4.81969","0.01910"
"9708","58.21200","4.85120","0.01969"
"9771","58.59000","4.88271","0.01982"
"9834","58.96800","4.91422","0.01970"
"9897","59.34600","4.94561","0.02028"
"9960","59.72400","4.97718","0.01969"
"10023","60.10200","5.00875","0.01922"
"10086","60.48000","5.04014","0.01989"
"10149","60.85800","5.07171","0.02033"
"10212","61.23600","5.10328","0.02049"
"10275","61.61400","5.13461","0.02051"
"10338","61.99200","5.16617","0.02129"
"10401","62.37000","5.19774","0.02078"
"10464","62.74800","5.22919","0.02033"
"10527","63.12600","5.26070","0.02080"
"10590","63.50400","5.29221","0.02108"
"10653","63.88200","5.32366","0.02141"
"10716","64.26000","5.35517","0.02137"
"10779","64.63800","5.38668","0.02131"
"10842","65.01600","5.41819","0.02165"
"10905","65.39400","5.44970","0.02178"
"10968","65.77200","5.48121","0.02145"
"11031","66.15000","5.51271","0.02195"
"11094","66.52800","5.54422","0.02174"
"11157","66.90600","5.57561","0.02215"
"11220","67.28400","5.60718","0.02269"
"11283","67.66200","5.63869","0.02246"
"11346","68.04000","5.67014","0.02237"
"11409","68.41800","5.70177","0.02267"
"11472","68.79600","5.73316","0.02292"
"11535","69.17400","5.76467","0.02277"
"11598","69.55200","5.79618","0.02337"
"11661","69.93000","5.82775","0.02400"
"11724","70.30800","5.85925","0.02363"
"11787","70.68600","5.89064","0.02387"
"11850","71.06400","5.92221","0.02457"
"11913","71.44200","5.95372","0.02470"
"11976","71.82000","5.98517","0.02440"
"12039","72.19800","6.01662","0.02543"
"12102","72.57600","6.04825","0.02514"
"12165","72.95400","6.07970","0.02447"
"12228","73.33200","6.11115","0.02421"
"12291","73.71000","6.14272","0.02502"
"12354","74.08800","6.17423","0.02488"
"12417","74.46600","6.20568","0.02551"
"12480","74.84400","6.23718","0.02514"
"12543","75.22200","6.26869","0.02552"
"12606","75.60000","6.30020","0.02547"
"12669","75.97800","6.33165","0.02603"
"12732","76.35600","6.36322","0.02580"
"12795","76.73400","6.39473","0.02621"
"12858","77.11200","6.42612","0.02600"
"12921","77.49000","6.45769","0.02642"
"12984","77.86800","6.48926","0.02645"
"13047","78.24600","6.52065","0.02695"
"13110","78.62400","6.55222","0.02636"
"13173","79.00200","6.58372","0.02701"
"13236","79.38000","6.61517","0.02657"
"13299","79.75800","6.64662","0.02679"
"13362","80.13600","6.67819","0.02679"
"13425","80.51400","6.70970","0.02763"
"13488","80.89200","6.74115","0.02769"
"13551","81.27000","6.77272","0.02736"
"13614","81.64800","6.80423","0.02738"
"13677","82.02600","6.83568","0.02752"
"13740","82.40400","6.86719","0.02703"
"13803","82.78200","6.89870","0.02724"
"13866","83.16000","6.93020","0.02726"
"13929","83.53800","6.96165","0.02755"
"13992","83.91600","6.99322","0.02730"
"14055","84.29400","7.02473","0.02775"
"14118","84.67200","7.05618","0.02794"
"14181","85.05000","7.08769","0.02825"
"14244","85.42800","7.11920","0.02740"
"14307","85.80600","7.15071","0.02724"
"14370","86.18400","7.18216","0.02671"
"14433","86.56200","7.21373","0.02590"
"14496","86.94000","7.24524","0.02623"
"14559","87.31800","7.27668","0.02486"
"14622","87.69600","7.30819","0.02540"
"14685","88.07400","7.33976","0.02535"
"14748","88.45200","7.37109","0.02600"
"14811","88.83000","7.40272","0.02590"
"14874","89.20800","7.43423","0.02626"
"14937","89.58600","7.46562","0.02666"
"15000","89.96400","7.49719","0.02649"
"15063","90.34200","7.52870","0.02607"
"15126","90.72000","7.56021","0.02643"
"15189","91.09800","7.59166","0.02627"
"15252","91.47600","7.62323","0.02577"
"15315","91.85400","7.65474","0.02701"
"15378","92.23200","7.68618","0.02710"
"15441","92.61000","7.71769","0.02645"
"15504","92.98800","7.74920","0.02654"
"15567","93.36600","7.78071","0.02537"
"15630","93.74400","7.81216","0.02586"
"15693","94.12200","7.84373","0.02637"
"15756","94.50000","7.87524","0.02645"
"15819","94.87800","7.90663","0.02586"
"15882","95.25600","7.93826","0.02637"
"15945","95.63400","7.96971","0.02659"
"16008","96.01200","8.00109","0.02625"
"16071","96.39000","8.03272","0.02673"
"16134","96.76800","8.06417","0.02686"
"16197","97.14600","8.09568","0.02680"
"16260","97.52400","8.12719","0.02500"
"16323","97.90200","8.15870","0.02566"
"16386","98.28000","8.19021","0.02580"
"16449","98.65800","8.22166","0.02519"
"16512","99.03600","8.25317","0.02554"
"16575","99.41400","8.28480","0.02594"
"16638","99.79200","8.31613","0.02541"
"16701","100.17000","8.34769","0.02539"
"16764","100.54800","8.37920","0.02549"
"16827","100.92600","8.41065","0.02571"
"16890","101.30400","8.44216","0.02644"
"16953","101.68200","8.47367","0.02640"
"17016","102.06000","8.50524","0.02494"
"17079","102.43800","8.53663","0.02486"
"17142","102.81600","8.56820","0.02518"
"17205","103.19400","8.59971","0.02517"
"17268","103.57200","8.63122","0.02550"
"17331","103.95000","8.66267","0.02563"
"17394","104.32800","8.69423","0.02586"
"17457","104.70600","8.72568","0.02615"
"17520","105.08400","8.75713","0.02575"
"17583","105.46200","8.78870","0.02595"
"17646","105.84000","8.82021","0.02673"
"17709","106.21800","8.85166","0.02659"
"17772","106.59600","8.88323","0.02664"
"17835","106.97400","8.91468","0.02656"
"17898","107.35200","8.94619","0.02669"
"17961","107.73000","8.97770","0.02658"
"18024","108.10800","9.00921","0.02697"
"18087","108.48600","9.04066","0.02612"
"18150","108.86400","9.07216","0.02692"
"18213","109.24200","9.10373","0.02674"
"18276","109.62000","9.13524","0.02661"
"18339","109.99800","9.16669","0.02674"
"18402","110.37600","9.19814","0.02698"
"18465","110.75400","9.22971","0.02713"
"18528","111.13200","9.26116","0.02717"
"18591","111.51000","9.29267","0.02781"
"18654","111.88800","9.32424","0.02796"
"18717","112.26600","9.35569","0.02750"
"18780","112.64400","9.38714","0.02773"
"18843","113.02200","9.41870","0.02792"
"18906","113.40000","9.45027","0.02787"
"18969","113.77800","9.48166","0.02814"
"19032","114.15600","9.51317","0.02818"
"19095","114.53400","9.54474","0.02871"
"19158","114.91200","9.57619","0.02872"
"19221","115.29000","9.60764","0.02806"
"19284","115.66800","9.63921","0.02879"
"19347","116.04600","9.67072","0.02923"
"19410","116.42400","9.70211","0.02893"
"19473","116.80200","9.73374","0.02906"
"19536","117.18000","9.76525","0.02928"
"19599","117.55800","9.79669","0.02980"
"19662","117.93600","9.82820","0.02923"
"19725","118.31400","9.85965","0.02946"
"19788","118.69200","9.89122","0.02940"
"19851","119.07000","9.92273","0.02969"
"19914","119.44800","9.95424","0.02886"
"19977","119.82600","9.98575","0.02864"
"20040","120.20400","10.01720","0.02843"
"20103","120.58200","10.04865","0.02860"
"20166","120.96000","10.08022","0.02878"
"20229","121.33800","10.11167","0.02877"
"20292","121.71600","10.14318","0.02885"
"20355","122.09400","10.17474","0.02876"
"20418","122.47200","10.20619","0.02909"
"20481","122.85000","10.23764","0.02928"
"20544","123.22800","10.26927","0.02971"
"20607","123.60600","10.30072","0.02984"
"20670","123.98400","10.33217","0.03040"
"20733","124.36200","10.36374","0.03028"
"20796","124.74000","10.39519","0.03054"
"20859","125.11800","10.42670","0.03055"
"20922","125.49600","10.45815","0.03069"
"20985","125.87400","10.48965","0.03070"
"21048","126.25200","10.52122","0.03111"
"21111","126.63000","10.55267","0.03123"
"21174","127.00800","10.58418","0.01370"
"21237","127.38600","10.61581","0.01365"
"21300","127.76400","10.64714","0.01427"
"21363","128.14200","10.67871","0.01560"
"21426","128.52000","10.71022","0.01659"
"21489","128.89800","10.74173","0.01579"
"21552","129.27600","10.77318","0.01635"
"21615","129.65400","10.80475","0.01725"
"21678","130.03200","10.83626","0.01764"
"21741","130.41000","10.86758","0.01755"
"21804","130.78800","10.89921","0.01794"
"21867","131.16600","10.93072","0.01918"
"21930","131.54400","10.96223","0.01850"
"21993","131.92200","10.99362","0.01944"
"22056","132.30000","11.02525","0.01946"
"22119","132.67800","11.05670","0.02041"
"22182","133.05600","11.08815","0.02007"
"22245","133.43400","11.11972","0.02051"
"22308","133.81200","11.15123","0.02107"
"22371","134.19000","11.18268","0.01919"
"22434","134.56800","11.21418","0.01966"
"22497","134.94600","11.24569","0.02050"
"22560","135.32400","11.27714","0.01957"
"22623","135.70200","11.30871","0.02035"
"22686","136.08000","11.34016","0.02141"
"22749","136.45800","11.37173","0.02203"
"22812","136.83600","11.40318","0.02196"
"22875","137.21400","11.43469","0.02264"
"22938","137.59200","11.46626","0.02235"
"23001","137.97000","11.49765","0.02267"
"23064","138.34800","11.52922","0.02311"
"23127","138.72600","11.56073","0.02334"
"23190","139.10400","11.59217","0.02321"
"23253","139.48200","11.62362","0.02369"
"23316","139.86000","11.65525","0.02212"
"23379","140.23800","11.68664","0.02346"
"23442","140.61600","11.71815","0.02420"
"23505","140.99400","11.74972","0.02420"
"23568","141.37200","11.78117","0.02471"
"23631","141.75000","11.81268","0.02531"
"23694","142.12800","11.84419","0.02514"
"23757","142.50600","11.87576","0.02548"
"23820","142.88400","11.90721","0.02609"
"23883","143.26200","11.93871","0.02656"
"23946","143.64000","11.97022","0.02689"
"24009","144.01800","12.00173","0.02697"
"24072","144.39600","12.03312","0.02699"
"24135","144.77400","12.06469","0.02785"
"24198","145.15200","12.09620","0.02786"
"24261","145.53000","12.12771","0.02839"
"24324","145.90800","12.15916","0.02812"
"24387","146.28600","12.19073","0.02876"
"24450","146.66400","12.22218","0.02872"
"24513","147.04200","12.25369","0.02842"
"24576","147.42000","12.28520","0.02957"
"24639","147.79800","12.31676","0.02974"
"24702","148.17600","12.34815","0.02958"
"24765","148.55400","12.37966","0.03006"
"24828","148.93200","12.41123","0.02967"
"24891","149.31000","12.44268","0.02882"
"24954","149.68800","12.47419","0.03013"
"25017","150.06600","12.50576","0.03010"
"25080","150.44400","12.53721","0.03026"
"25143","150.82200","12.56866","0.03098"
"25206","151.20000","12.60017","0.03028"
"25269","151.57800","12.63173","0.03085"
"25332","151.95600","12.66312","0.03079"
"25395","152.33400","12.69469","0.03132"
"25458","152.71200","12.72620","0.03090"
"25521","153.09000","12.75771","0.03148"
"25584","153.46800","12.78916","0.03210"
"25647","153.84600","12.82073","0.03254"
"25710","154.22400","12.85224","0.03256"
"25773","154.60200","12.88363","0.03274"
"25836","154.98000","12.91520","0.03282"
"25899","155.35800","12.94671","0.03334"
"25962","155.73600","12.97810","0.03310"
"26025","156.11400","13.00972","0.03289"
"26088","156.49200","13.04123","0.03352"
"26151","156.87000","13.07268","0.03321"
"26214","157.24800","13.10419","0.03391"
"26277","157.62600","13.13576","0.03451"
"26340","158.00400","13.16721","0.03458"
"26403","158.38200","13.19866","0.03474"
"26466","158.76000","13.23023","0.03488"
"26529","159.13800","13.26168","0.03538"
"26592","159.51600","13.29319","0.03571"
"26655","159.89400","13.32469","0.03542"
"26718","160.27200","13.35620","0.03524"
"26781","160.65000","13.38771","0.03539"
"26844","161.02800","13.41916","0.03571"
"26907","161.40600","13.45073","0.03611"
"26970","161.78400","13.48224","0.03618"
"27033","162.16200","13.51369","0.03662"
"27096","162.54000","13.54526","0.03654"
"27159","162.91800","13.57671","0.03699"
"27222","163.29600","13.60816","0.03729"
"27285","163.67400","13.63967","0.03813"
"27348","164.05200","13.67118","0.03832"
"27411","164.43000","13.70274","0.03848"
"27474","164.80800","13.73419","0.03868"
"27537","165.18600","13.76570","0.03947"
"27600","165.56400","13.79727","0.03929"
"27663","165.94200","13.82860","0.03441"
"27726","166.32000","13.86017","0.03473"
"27789","166.69800","13.89168","0.03516"
"27852","167.07600","13.92319","0.03536"
"27915","167.45400","13.95470","0.03567"
"27978","167.83200","13.98621","0.03606"
"28041","168.21000","14.01766","0.03608"
"28104","168.58800","14.04916","0.03655"
"28167","168.96600","14.08068","0.03687"
"28230","169.34400","14.11218","0.03723"
"28293","169.72200","14.14369","0.03688"
"28356","170.10000","14.17514","0.03720"
"28419","170.47800","14.20671","0.03741"
"28482","170.85600","14.23822","0.03728"
"28545","171.23400","14.26967","0.03763"
"28608","171.61200","14.30124","0.03816"
"28671","171.99000","14.33275","0.03817"
"28734","172.36800","14.36408","0.03885"
"28797","172.74600","14.39577","0.03898"
"28860","173.12400","14.42721","0.03938"
"28923","173.50200","14.45860","0.03995"
"28986","173.88000","14.49023","0.04051"
"29049","174.25800","14.52174","0.04093"
"29112","174.63600","14.55319","0.04109"
"29175","175.01400","14.58470","0.04134"
"29238","175.39200","14.61621","0.04166"
"29301","175.77000","14.64772","0.04189"
"29364","176.14800","14.67917","0.04225"
"29427","176.52600","14.71068","0.04265"
"29490","176.90400","14.74224","0.04312"
"29553","177.28200","14.77363","0.04379"
"29616","177.66000","14.80526","0.04270"
"29679","178.03800","14.83671","0.04312"
"29742","178.41600","14.86822","0.03354"
"29805","178.79400","14.89967","0.03414"
"29868","179.17200","14.93124","0.03418"
"29931","179.55000","14.96269","0.03432"
"29994","179.92800","14.99414","0.03458"
"30057","180.30600","15.02571","0.03472"
"30120","180.68400","15.05716","0.03484"
"30183","181.06200","15.08873","0.03474"
"30246","181.44000","15.12012","0.03523"
"30309","181.81800","15.15168","0.03510"
"30372","182.19600","15.18325","0.03582"
"30435","182.57400","15.21464","0.03594"
"30498","182.95200","15.24621","0.03636"
"30561","183.33000","15.27772","0.03664"
"30624","183.70800","15.30911","0.03716"
"30687","184.08600","15.34074","0.03703"
"30750","184.46400","15.37225","0.03741"
"30813","184.84200","15.40364","0.03730"
"30876","185.22000","15.43521","0.03785"
"30939","185.59800","15.46672","0.03813"
"31002","185.97600","15.49822","0.03859"
"31065","186.35400","15.52967","0.03905"
"31128","186.73200","15.56118","0.03965"
"31191","187.11000","15.59275","0.03961"
"31254","187.48800","15.62414","0.04022"
"31317","187.86600","15.65565","0.04015"
"31380","188.24400","15.68722","0.04088"
"31443","188.62200","15.71873","0.04150"
"31506","189.00000","15.75012","0.04187"
"31569","189.37800","15.78169","0.04167"
"31632","189.75600","15.81319","0.04146"
"31695","190.13400","15.84464","0.04192"
"31758","190.51200","15.87621","0.04178"
"31821","190.89000","15.90772","0.04232"
"31884","191.26800","15.93917","0.04313"
"31947","191.64600","15.97068","0.04375"
"32010","192.02400","16.00219","0.04475"
"32073","192.40200","16.03370","0.04475"
"32136","192.78000","16.06515","0.04499"
"32199","193.15800","16.09678","0.04466"
"32262","193.53600","16.12823","0.04541"
"32325","193.91400","16.15962","0.04611"
"32388","194.29200","16.19118","0.04570"
"32451","194.67000","16.22275","0.04658"
"32514","195.04800","16.25414","0.04774"
"32577","195.42600","16.28565","0.04825"
"32640","195.80400","16.31722","0.04940"
"32703","196.18200","16.34867","0.05000"
"32766","196.56000","16.38018","0.05126"
"32829","196.93800","16.41175","0.05171"
"32892","197.31600","16.44326","0.05314"
"32955","197.69400","16.47471","0.05387"
"33018","198.07200","16.50616","0.05396"
"33081","198.45000","16.53772","0.05575"
"33144","198.82800","16.56911","0.05684"
"33207","199.20600","16.60062","0.05837"
"33270","199.58400","16.63225","0.05822"
"33333","199.96200","16.66364","0.05897"
"33396","200.34000","16.69515","0.06100"
"33459","200.71800","16.72678","0.06225"
"33522","201.09600","16.75823","0.06332"
"33585","201.47400","16.78974","0.06482"
"33648","201.85200","16.82125","0.06570"
"33711","202.23000","16.85264","0.06603"
"33774","202.60800","16.88415","0.06686"
"33837","202.98600","16.91566","0.06803"
"33900","203.36400","16.94716","0.06997"
"33963","203.74200","16.97873","0.07097"
"34026","204.12000","17.01018","0.07204"
"34089","204.49800","17.04169","0.07342"
"34152","204.87600","17.07326","0.07423"
"34215","205.25400","17.10465","0.07538"
"34278","205.63200","17.13622","0.07640"
"34341","206.01000","17.16773","0.07449"
"34404","206.38800","17.19918","0.07512"
"34467","206.76600","17.23063","0.07661"
"34530","207.14400","17.26225","0.07800"
"34593","207.52200","17.29370","0.07914"
"34656","207.90000","17.32509","0.08019"
"34719","208.27800","17.35666","0.08093"
"34782","208.65600","17.38823","0.08158"
"34845","209.03400","17.41974","0.08246"
"34908","209.41200","17.45113","0.08329"
"34971","209.79000","17.48270","0.08380"
"35034","210.16800","17.51415","0.08515"
"35097","210.54600","17.54566","0.08643"
"35160","210.92400","17.57722","0.08750"
"35223","211.30200","17.60874","0.08920"
"35286","211.68000","17.64018","0.09041"
"35349","212.05800","17.67169","0.09191"
"35412","212.43600","17.70320","0.09359"
"35475","212.81400","17.73465","0.09507"
"35538","213.19200","17.76622","0.09640"
"35601","213.57000","17.79767","0.09818"
"35664","213.94800","17.82918","0.10056"
"35727","214.32600","17.86069","0.10312"
"35790","214.70400","17.89220","0.10436"
"35853","215.08200","17.92377","0.10677"
"35916","215.46000","17.95516","0.10906"
"35979","215.83800","17.98672","0.11059"
"36042","216.21600","18.01823","0.11251"
"36105","216.59400","18.04968","0.11451"
"36168","216.97200","18.08119","0.11565"
"36231","217.35000","18.11276","0.11694"
"36294","217.72800","18.14415","0.11722"
"36357","218.10600","18.17566","0.11932"
"36420","218.48400","18.20723","0.12009"
"36483","218.86200","18.23868","0.12107"
"36546","219.24000","18.27013","0.12093"
"36609","219.61800","18.30164","0.11802"
"36672","219.99600","18.33320","0.11886"
"36735","220.37400","18.36471","0.12017"
"36798","220.75200","18.39616","0.12128"
"36861","221.13000","18.42773","0.12199"
"36924","221.50800","18.45924","0.12278"
"36987","221.88600","18.49069","0.12314"
"37050","222.26400","18.52220","0.12294"
"37113","222.64200","18.55371","0.12370"
"37176","223.02000","18.58522","0.12471"
"37239","223.39800","18.61667","0.12544"
"37302","223.77600","18.64824","0.12655"
"37365","224.15400","18.67969","0.12714"
"37428","224.53200","18.71119","0.12787"
"37491","224.91000","18.74270","0.12863"
"37554","225.28800","18.77421","0.12915"
"37617","225.66600","18.80566","0.13013"
"37680","226.04400","18.83717","0.13128"
"37743","226.42200","18.86874","0.13252"
"37806","226.80000","18.90019","0.13403"
"37869","227.17800","18.93170","0.13543"
"37932","227.55600","18.96321","0.13781"
"37995","227.93400","18.99466","0.13933"
"38058","228.31200","19.02611","0.14224"
"38121","228.69000","19.05773","0.14434"
"38184","229.06800","19.08924","0.14747"
"38247","229.44600","19.12069","0.15188"
"38310","229.82400","19.15220","0.15443"
"38373","230.20200","19.18371","0.15894"
"38436","230.58000","19.21516","0.16280"
"38499","230.95800","19.24667","0.16601"
"38562","231.33600","19.27824","0.17114"
"38625","231.71400","19.30975","0.17603"
"38688","232.09200","19.34114","0.17994"
"38751","232.47000","19.37265","0.18265"
"38814","232.84800","19.40428","0.18584"
"38877","233.22600","19.43560","0.18772"
"38940","233.60400","19.46717","0.18922"
"39003","233.98200","19.49874","0.19090"
"39066","234.36000","19.53019","0.19275"
"39129","234.73800","19.56164","0.19441"
"39192","235.11600","19.59321","0.19666"
"39255","235.49400","19.62466","0.19943"
"39318","235.87200","19.65617","0.20196"
"39381","236.25000","19.68773","0.20529"
"39444","236.62800","19.71918","0.20840"
"39507","237.00600","19.75070","0.21084"
"39570","237.38400","19.78220","0.21430"
"39633","237.76200","19.81371","0.21724"
"39696","238.14000","19.84516","0.21960"
"39759","238.51800","19.87667","0.22261"
"39822","238.89600","19.90818","0.22506"
"39885","239.27400","19.93969","0.22740"
"39948","239.65200","19.97114","0.22974"
"40011","240.03000","20.00277","0.23099"
"40074","240.40800","20.03422","0.23268"
"40137","240.78600","20.06567","0.23372"
"40200","241.16400","20.09718","0.23539"
"40263","241.54200","20.12868","0.23693"
"40326","241.92000","20.16019","0.23844"
"40389","242.29800","20.19164","0.23973"
"40452","242.67600","20.22321","0.24162"
"40515","243.05400","20.25472","0.24373"
"40578","243.43200","20.28611","0.24647"
"40641","243.81000","20.31768","0.24893"
"40704","244.18800","20.34919","0.25160"
"40767","244.56600","20.38070","0.22332"
"40830","244.94400","20.41215","0.22523"
"40893","245.32200","20.44372","0.22703"
"40956","245.70000","20.47517","0.22813"
"41019","246.07800","20.50661","0.22910"
"41082","246.45600","20.53818","0.23050"
"41145","246.83400","20.56969","0.23144"
"41208","247.21200","20.60120","0.23233"
"41271","247.59000","20.63265","0.23312"
"41334","247.96800","20.66416","0.23422"
"41397","248.34600","20.69567","0.23527"
"41460","248.72400","20.72712","0.23635"
"41523","249.10200","20.75869","0.23676"
"41586","249.48000","20.79026","0.23745"
"41649","249.85800","20.82159","0.23876"
"41712","250.23600","20.85321","0.23955"
"41775","250.61400","20.88472","0.24097"
"41838","250.99200","20.91611","0.24215"
"41901","251.37000","20.94774","0.24374"
"41964","251.74800","20.97925","0.24511"
"42027","252.12600","21.01070","0.24622"
"42090","252.50400","21.04215","0.24877"
"42153","252.88200","21.07372","0.25086"
"42216","253.26000","21.10523","0.25303"
"42279","253.63800","21.13662","0.25498"
"42342","254.01600","21.16818","0.25725"
"42405","254.39400","21.19975","0.25938"
"42468","254.77200","21.23114","0.26192"
"42531","255.15000","21.26271","0.26353"
"42594","255.52800","21.29422","0.26595"
"42657","255.90600","21.32567","0.26807"
"42720","256.28400","21.35718","0.26979"
"42783","256.66200","21.38869","0.27239"
"42846","257.04000","21.42020","0.27441"
"42909","257.41800","21.45165","0.26723"
"42972","257.79600","21.48322","0.26956"
"43035","258.17400","21.51472","0.27182"
"43098","258.55200","21.54623","0.27367"
"43161","258.93000","21.57763","0.27570"
"43224","259.30800","21.60925","0.27832"
"43287","259.68600","21.64070","0.28045"
"43350","260.06400","21.67215","0.28243"
"43413","260.44200","21.70372","0.28419"
"43476","260.82000","21.73523","0.28603"
"43539","261.19800","21.76662","0.28843"
"43602","261.57600","21.79819","0.29094"
"43665","261.95400","21.82970","0.29415"
"43728","262.33200","21.86115","0.29799"
"43791","262.71000","21.89271","0.30235"
"43854","263.08800","21.92422","0.30571"
"43917","263.46600","21.95567","0.30959"
"43980","263.84400","21.98712","0.31398"
"44043","264.22200","22.01869","0.31754"
"44106","264.60000","22.05020","0.32145"
"44169","264.97800","22.08165","0.32587"
"44232","265.35600","22.11316","0.32852"
"44295","265.73400","22.14479","0.33125"
"44358","266.11200","22.17624","0.33349"
"44421","266.49000","22.20769","0.33566"
"44484","266.86800","22.23925","0.33813"
"44547","267.24600","22.27071","0.33915"
"44610","267.62400","22.30215","0.34083"
"44673","268.00200","22.33372","0.34156"
"44736","268.38000","22.36517","0.34238"
"44799","268.75800","22.39668","0.34294"
"44862","269.13600","22.42819","0.34329"
"44925","269.51400","22.45970","0.34379"
"44988","269.89200","22.49121","0.34407"
"45051","270.27000","22.52266","0.34474"
"45114","270.64800","22.55423","0.34537"
"45177","271.02600","22.58574","0.34592"
"45240","271.40400","22.61712","0.34741"
"45303","271.78200","22.64869","0.34680"
"45366","272.16000","22.68026","0.34785"
"45429","272.53800","22.71165","0.34922"
"45492","272.91600","22.74316","0.35026"
"45555","273.29400","22.77467","0.35087"
"45618","273.67200","22.80618","0.35347"
"45681","274.05000","22.83769","0.35473"
"45744","274.42800","22.86920","0.35672"
"45807","274.80600","22.90071","0.35945"
"45870","275.18400","22.93216","0.36188"
"45933","275.56200","22.96367","0.36466"
"45996","275.94000","22.99517","0.36809"
"46059","276.31800","23.02668","0.37149"
"46122","276.69600","23.05813","0.37248"
"46185","277.07400","23.08970","0.37596"
"46248","277.45200","23.12121","0.37906"
"46311","277.83000","23.15266","0.38146"
"46374","278.20800","23.18423","0.38429"
"46437","278.58600","23.21568","0.38686"
"46500","278.96400","23.24713","0.38776"
"46563","279.34200","23.27870","0.38962"
"46626","279.72000","23.31021","0.39157"
"46689","280.09800","23.34166","0.39276"
"46752","280.47600","23.37322","0.39428"
"46815","280.85400","23.40467","0.39630"
"46878","281.23200","23.43624","0.39788"
"46941","281.61000","23.46763","0.39941"
"47004","281.98800","23.49914","0.40255"
"47067","282.36600","23.53077","0.40508"
"47130","282.74400","23.56216","0.39983"
"47193","283.12200","23.59367","0.40248"
"47256","283.50000","23.62523","0.40536"
"47319","283.87800","23.65668","0.40812"
"47382","284.25600","23.68813","0.41197"
"47445","284.63400","23.71970","0.41491"
"47508","285.01200","23.75121","0.41800"
"47571","285.39000","23.78266","0.42031"
"47634","285.76800","23.81417","0.42215"
"47697","286.14600","23.84568","0.42425"
"47760","286.52400","23.87719","0.42594"
"47823","286.90200","23.90864","0.42751"
"47886","287.28000","23.94020","0.42917"
"47949","287.65800","23.97172","0.43114"
"48012","288.03600","24.00316","0.43256"
"48075","288.41400","24.03468","0.43457"
"48138","288.79200","24.06618","0.43699"
"48201","289.17000","24.09764","0.43894"
"48264","289.54800","24.12920","0.43995"
"48327","289.92600","24.16071","0.34100"
"48390","290.30400","24.19216","0.34331"
"48453","290.68200","24.22367","0.34392"
"48516","291.06000","24.25518","0.34415"
"48579","291.43800","24.28669","0.34424"
"48642","291.81600","24.31814","0.34496"
"48705","292.19400","24.34971","0.34533"
"48768","292.57200","24.38128","0.34545"
"48831","292.95000","24.41267","0.34649"
"48894","293.32800","24.44417","0.34780"
"48957","293.70600","24.47574","0.34942"
"49020","294.08400","24.50719","0.35117"
"49083","294.46200","24.53870","0.35261"
"49146","294.84000","24.57027","0.35356"
"49209","295.21800","24.60166","0.35531"
"49272","295.59600","24.63317","0.35815"
"49335","295.97400","24.66474","0.36320"
"49398","296.35200","24.69619","0.36689"
"49461","296.73000","24.72770","0.37035"
"49524","297.10800","24.75915","0.37170"
"49587","297.48600","24.79071","0.37230"
"49650","297.86400","24.82222","0.37501"
"49713","298.24200","24.85367","0.37857"
"49776","298.62000","24.88518","0.38052"
"49839","298.99800","24.91675","0.38314"
"49902","299.37600","24.94814","0.38507"
"49965","299.75400","24.97971","0.38764"
"50028","300.13200","25.01122","0.38953"
"50091","300.51000","25.04267","0.39093"
"50154","300.88800","25.07417","0.39172"
"50217","301.26600","25.10568","0.39312"
"50280","301.64400","25.13720","0.39495"
"50343","302.02200","25.16864","0.39606"
"50406","302.40000","25.20021","0.39784"
"50469","302.77800","25.23172","0.39872"
"50532","303.15600","25.26317","0.40068"
"50595","303.53400","25.29468","0.40118"
"50658","303.91200","25.32619","0.40083"
"50721","304.29000","25.35770","0.39580"
"50784","304.66800","25.38915","0.39220"
"50847","305.04600","25.42071","0.39272"
"50910","305.42400","25.45223","0.39440"
"50973","305.80200","25.48361","0.39703"
"51036","306.18000","25.51524","0.40045"
"51099","306.55800","25.54669","0.40426"
"51162","306.93600","25.57820","0.40726"
"51225","307.31400","25.60965","0.41002"
"51288","307.69200","25.64116","0.41281"
"51351","308.07000","25.67267","0.41577"
"51414","308.44800","25.70418","0.41848"
"51477","308.82600","25.73575","0.42029"
"51540","309.20400","25.76720","0.42190"
"51603","309.58200","25.79859","0.42337"
"51666","309.96000","25.83021","0.42466"
"51729","310.33800","25.86178","0.42632"
"51792","310.71600","25.89317","0.42763"
"51855","311.09400","25.92474","0.42861"
"51918","311.47200","25.95625","0.42967"
"51981","311.85000","25.98764","0.43096"
"52044","312.22800","26.01915","0.43215"
"52107","312.60600","26.05072","0.43364"
"52170","312.98400","26.08223","0.43538"
"52233","313.36200","26.11368","0.43674"
"52296","313.74000","26.14519","0.43838"
"52359","314.11800","26.17664","0.44005"
"52422","314.49600","26.20820","0.44143"
"52485","314.87400","26.23965","0.44332"
"52548","315.25200","26.27116","0.44505"
"52611","315.63000","26.30267","0.44737"
"52674","316.00800","26.33418","0.44970"
"52737","316.38600","26.36569","0.45099"
"52800","316.76400","26.39720","0.45316"
"52863","317.14200","26.42865","0.45595"
"52926","317.52000","26.46021","0.45836"
"52989","317.89800","26.49167","0.46137"
"53052","318.27600","26.52317","0.46343"
"53115","318.65400","26.55469","0.46568"
"53178","319.03200","26.58619","0.46870"
"53241","319.41000","26.61770","0.47130"
"53304","319.78800","26.64915","0.47377"
"53367","320.16600","26.68072","0.47662"
"53430","320.54400","26.71217","0.47845"
"53493","320.92200","26.74362","0.48042"
"53556","321.30000","26.77519","0.48304"
"53619","321.67800","26.80676","0.48458"
"53682","322.05600","26.83815","0.48683"
"53745","322.43400","26.86966","0.48758"
"53808","322.81200","26.90122","0.48933"
"53871","323.19000","26.93273","0.49027"
"53934","323.56800","26.96418","0.49125"
"53997","323.94600","26.99569","0.49204"
"54060","324.32400","27.02726","0.49285"
"54123","324.70200","27.05871","0.49360"
"54186","325.08000","27.09016","0.49522"
"54249","325.45800","27.12167","0.49627"
"54312","325.83600","27.15324","0.49794"
"54375","326.21400","27.18463","0.49996"
"54438","326.59200","27.21620","0.50215"
"54501","326.97000","27.24776","0.50522"
"54564","327.34800","27.27916","0.50671"
"54627","327.72600","27.31066","0.50951"
"54690","328.10400","27.34223","0.51098"
"54753","328.48200","27.37362","0.51445"
"54816","328.86000","27.40525","0.51607"
"54879","329.23800","27.43670","0.51875"
"54942","329.61600","27.46815","0.52062"
"55005","329.99400","27.49966","0.52369"
"55068","330.37200","27.53123","0.52571"
"55131","330.75000","27.56274","0.52762"
"55194","331.12800","27.59418","0.53013"
"55257","331.50600","27.62569","0.53186"
"55320","331.88400","27.65721","0.53470"
"55383","332.26200","27.68865","0.53539"
"55446","332.64000","27.72016","0.53856"
"55509","333.01800","27.75173","0.53994"
"55572","333.39600","27.78318","0.54189"
"55635","333.77400","27.81463","0.54345"
"55698","334.15200","27.84626","0.54443"
"55761","334.53000","27.87771","0.54547"
"55824","334.90800","27.90916","0.54623"
"55887","335.28600","27.94066","0.54656"
"55950","335.66400","27.97224","0.54668"
"56013","336.04200","28.00368","0.54647"
"56076","336.42000","28.03519","0.54669"
"56139","336.79800","28.06670","0.54625"
"56202","337.17600","28.09821","0.54595"
"56265","337.55400","28.12966","0.54640"
"56328","337.93200","28.16123","0.54712"
"56391","338.31000","28.19274","0.54836"
"56454","338.68800","28.22413","0.54994"
"56517","339.06600","28.25570","0.55159"
"56580","339.44400","28.28721","0.55197"
"56643","339.82200","28.31872","0.55312"
"56706","340.20000","28.35016","0.55430"
"56769","340.57800","28.38167","0.55488"
"56832","340.95600","28.41318","0.55580"
"56895","341.33400","28.44469","0.55672"
"56958","341.71200","28.47620","0.55768"
"57021","342.09000","28.50771","0.55961"
"57084","342.46800","28.53916","0.56045"
"57147","342.84600","28.57061","0.56323"
"57210","343.22400","28.60224","0.56473"
"57273","343.60200","28.63369","0.56696"
"57336","343.98000","28.66514","0.56908"
"57399","344.35800","28.69670","0.57125"
"57462","344.73600","28.72821","0.57400"
"57525","345.11400","28.75966","0.57532"
"57588","345.49200","28.79123","0.57866"
"57651","345.87000","28.82268","0.58091"
"57714","346.24800","28.85419","0.58350"
"57777","346.62600","28.88570","0.58628"
"57840","347.00400","28.91721","0.58783"
"57903","347.38200","28.94866","0.58955"
"57966","347.76000","28.98017","0.59083"
"58029","348.13800","29.01173","0.59211"
"58092","348.51600","29.04325","0.59362"
"58155","348.89400","29.07463","0.59430"
"58218","349.27200","29.10614","0.59540"
"58281","349.65000","29.13777","0.59630"
"58344","350.02800","29.16916","0.59821"
"58407","350.40600","29.20073","0.59941"
"58470","350.78400","29.23218","0.60092"
"58533","351.16200","29.26363","0.60210"
"58596","351.54000","29.29520","0.60405"
"58659","351.91800","29.32671","0.60511"
"58722","352.29600","29.35828","0.60719"
"58785","352.67400","29.38961","0.60843"
"58848","353.05200","29.42117","0.61026"
"58911","353.43000","29.45268","0.61251"
"58974","353.80800","29.48419","0.61449"
"59037","354.18600","29.51564","0.61596"
"59100","354.56400","29.54721","0.61824"
"59163","354.94200","29.57866","0.61948"
"59226","355.32000","29.61011","0.62166"
"59289","355.69800","29.64174","0.62295"
"59352","356.07600","29.67319","0.62462"
"59415","356.45400","29.70470","0.62627"
"59478","356.83200","29.73621","0.62832"
"59541","357.21000","29.76765","0.62891"
"59604","357.58800","29.79917","0.63003"
"59667","357.96600","29.83067","0.63090"
"59730","358.34400","29.86218","0.63065"
"59793","358.72200","29.89369","0.62836"
"59856","359.10000","29.92514","0.62648"
"59919","359.47800","29.95665","0.62330"
"59982","359.85600","29.98822","0.62014"
"60045","360.23400","30.01967","0.61906"
"60108","360.61200","30.05112","0.62039"
"60171","360.99000","30.08274","0.62286"
"60234","361.36800","30.11419","0.62517"
"60297","361.74600","30.14565","0.62808"
"60360","362.12400","30.17727","0.63059"
"60423","362.50200","30.20872","0.63276"
"60486","362.88000","30.24017","0.63461"
"60549","363.25800","30.27168","0.63648"
"60612","363.63600","30.30319","0.63841"
"60675","364.01400","30.33470","0.63915"
"60738","364.39200","30.36621","0.64003"
"60801","364.77000","30.39772","0.64100"
"60864","365.14800","30.42923","0.64157"
"60927","365.52600","30.46067","0.64193"
"60990","365.90400","30.49218","0.64235"
"61053","366.28200","30.52375","0.64069"
"61116","366.66000","30.55514","0.64119"
"61179","367.03800","30.58671","0.64164"
"61242","367.41600","30.61816","0.64208"
"61305","367.79400","30.64967","0.64249"
"61368","368.17200","30.68112","0.64296"
"61431","368.55000","30.71269","0.64327"
"61494","368.92800","30.74420","0.64357"
"61557","369.30600","30.77571","0.64384"
"61620","369.68400","30.80722","0.64418"
"61683","370.06200","30.83878","0.64464"
"61746","370.44000","30.87017","0.64490"
"61809","370.81800","30.90168","0.64561"
"61872","371.19600","30.93325","0.64575"
"61935","371.57400","30.96470","0.64597"
"61998","371.95200","30.99615","0.64643"
"62061","372.33000","31.02772","0.64690"
"62124","372.70800","31.05917","0.64718"
"62187","373.08600","31.09062","0.64736"
"62250","373.46400","31.12225","0.64764"
"62313","373.84200","31.15370","0.64758"
"62376","374.22000","31.18521","0.64791"
"62439","374.59800","31.21671","0.64973"
"62502","374.97600","31.24816","0.64923"
"62565","375.35400","31.27973","0.64896"
"62628","375.73200","31.31118","0.64943"
"62691","376.11000","31.34275","0.64993"
"62754","376.48800","31.37426","0.65036"
"62817","376.86600","31.40565","0.65096"
"62880","377.24400","31.43721","0.65101"
"62943","377.62200","31.46867","0.65112"
"63006","378.00000","31.50012","0.65129"
"63069","378.37800","31.53168","0.65214"
"63132","378.75600","31.56319","0.65213"
"63195","379.13400","31.59470","0.65315"
"63258","379.51200","31.62615","0.65319"
"63321","379.89000","31.65772","0.65324"
"63384","380.26800","31.68923","0.65320"
"63447","380.64600","31.72068","0.65159"
"63510","381.02400","31.75219","0.64897"
"63573","381.40200","31.78370","0.64564"
"63636","381.78000","31.81520","0.64385"
"63699","382.15800","31.84665","0.64218"
"63762","382.53600","31.87828","0.64149"
"63825","382.91400","31.90967","0.64075"
"63888","383.29200","31.94112","0.64100"
"63951","383.67000","31.97275","0.64104"
"64014","384.04800","32.00420","0.64179"
"64077","384.42600","32.03565","0.64227"
"64140","384.80400","32.06722","0.64292"
"64203","385.18200","32.09867","0.64355"
"64266","385.56000","32.13018","0.64418"
"64329","385.93800","32.16163","0.64487"
"64392","386.31600","32.19320","0.64547"
"64455","386.69400","32.22470","0.64554"
"64518","387.07200","32.25609","0.64428"
"64581","387.45000","32.28766","0.64134"
"64644","387.82800","32.31923","0.61671"
"64707","388.20600","32.35062","0.59384"
"64770","388.58400","32.38219","0.59631"
"64833","388.96200","32.41370","0.60153"
"64896","389.34000","32.44515","0.60945"
"64959","389.71800","32.47672","0.61784"
"65022","390.09600","32.50823","0.62611"
"65085","390.47400","32.53968","0.63208"
"65148","390.85200","32.57119","0.63719"
"65211","391.23000","32.60270","0.64022"
"65274","391.60800","32.63414","0.64231"
"65337","391.98600","32.66565","0.64349"
"65400","392.36400","32.69722","0.64463"
"65463","392.74200","32.72873","0.64588"
"65526","393.12000","32.76024","0.64834"
"65589","393.49800","32.79169","0.64975"
"65652","393.87600","32.82320","0.65162"
"65715","394.25400","32.85471","0.65379"
"65778","394.63200","32.88615","0.65593"
"65841","395.01000","32.91772","0.65878"
"65904","395.38800","32.94918","0.66138"
"65967","395.76600","32.98063","0.66388"
"66030","396.14400","33.01213","0.66535"
"66093","396.52200","33.04370","0.66766"
"66156","396.90000","33.07521","0.66867"
"66219","397.27800","33.10666","0.67085"
"66282","397.65600","33.13817","0.67189"
"66345","398.03400","33.16974","0.67338"
"66408","398.41200","33.20113","0.67482"
"66471","398.79000","33.23270","0.67625"
"66534","399.16800","33.26426","0.67735"
"66597","399.54600","33.29565","0.67855"
"66660","399.92400","33.32722","0.68032"
"66723","400.30200","33.35873","0.68233"
"66786","400.68000","33.39024","0.68331"
"66849","401.05800","33.42169","0.68442"
"66912","401.43600","33.45320","0.68574"
"66975","401.81400","33.48477","0.68677"
"67038","402.19200","33.51616","0.68777"
"67101","402.57000","33.54766","0.68929"
"67164","402.94800","33.57924","0.69073"
"67227","403.32600","33.61074","0.69131"
"67290","403.70400","33.64214","0.69176"
"67353","404.08200","33.67370","0.69193"
"67416","404.46000","33.70521","0.69245"
"67479","404.83800","33.73660","0.69301"
"67542","405.21600","33.76823","0.69325"
"67605","405.59400","33.79974","0.69177"
"67668","405.97200","33.83113","0.69118"
"67731","406.35000","33.86270","0.68842"
"67794","406.72800","33.89421","0.68244"
"67857","407.10600","33.92572","0.67445"
"67920","407.48400","33.95716","0.66614"
"67983","407.86200","33.98874","0.65973"
"68046","408.24000","34.02019","0.65464"
"68109","408.61800","34.05169","0.65044"
"68172","408.99600","34.08320","0.64746"
"68235","409.37400","34.11471","0.64457"
"68298","409.75200","34.14616","0.64289"
"68361","410.13000","34.17767","0.64099"
"68424","410.50800","34.20924","0.63799"
"68487","410.88600","34.24069","0.63534"
"68550","411.26400","34.27214","0.63374"
"68613","411.64200","34.30371","0.63458"
"68676","412.02000","34.33516","0.63351"
"68739","412.39800","34.36666","0.63317"
"68802","412.77600","34.39823","0.63418"
"68865","413.15400","34.42974","0.63593"
"68928","413.53200","34.46119","0.63643"
"68991","413.91000","34.49270","0.63814"
"69054","414.28800","34.52421","0.63957"
"69117","414.66600","34.55572","0.64041"
"69180","415.04400","34.58711","0.64185"
"69243","415.42200","34.61874","0.64223"
"69306","415.80000","34.65025","0.64283"
"69369","416.17800","34.68158","0.64315"
"69432","416.55600","34.71320","0.64351"
"69495","416.93400","34.74466","0.64401"
"69558","417.31200","34.77616","0.64430"
"69621","417.69000","34.80767","0.64542"
"69684","418.06800","34.83918","0.64577"
"69747","418.44600","34.87075","0.64627"
"69810","418.82400","34.90220","0.64703"
"69873","419.20200","34.93365","0.64770"
"69936","419.58000","34.96516","0.64763"
"69999","419.95800","34.99667","0.64841"
"70062","420.33600","35.02811","0.64835"
"70125","420.71400","35.05969","0.64888"
"70188","421.09200","35.09119","0.64932"
"70251","421.47000","35.12264","0.64935"
"70314","421.84800","35.15421","0.64988"
"70377","422.22600","35.18572","0.64939"
"70440","422.60400","35.21711","0.65018"
"70503","422.98200","35.24874","0.65033"
"70566","423.36000","35.28019","0.65094"
"70629","423.73800","35.31164","0.65129"
"70692","424.11600","35.34315","0.65148"
"70755","424.49400","35.37472","0.65243"
"70818","424.87200","35.40617","0.65244"
"70881","425.25000","35.43761","0.65332"
"70944","425.62800","35.46925","0.65452"
"71007","426.00600","35.50076","0.65519"
"71070","426.38400","35.53214","-0.02196"
"71133","426.76200","35.56371","-0.01150"
"71196","427.14000","35.59528","0.00497"
"71259","427.51800","35.62667","-0.00835"
"71322","427.89600","35.65818","-0.00020"
"71385","428.27400","35.68975","-0.00771"
"71448","428.65200","35.72126","-0.00413"
"71511","429.03000","35.75270","-0.00447"
"71574","429.40800","35.78421","-0.00723"
"71637","429.78600","35.81572","-0.00196"
"71700","430.16400","35.84717","-0.00586"
"71763","430.54200","35.87868","-0.00538"
"71826","430.92000","35.91019","-0.00388"
"71889","431.29800","35.94170","-0.00514"
"71952","431.67600","35.97315","-0.00623"
"72015","432.05400","36.00472","-0.00313"
"72078","432.43200","36.03617","-0.00547"
"72141","432.81000","36.06768","-0.00474"
"72204","433.18800","36.09925","-0.00442"
"72267","433.56600","36.13076","-0.00489"
"72330","433.94400","36.16220","-0.00513"
"72393","434.32200","36.19371","-0.00325"
"72456","434.70000","36.22516","-0.00492"
"72519","435.07800","36.25667","-0.00491"
"72582","435.45600","36.28818","-0.00357"
"72645","435.83400","36.31975","-0.00488"
"72708","436.21200","36.35126","-0.00542"
"72771","436.59000","36.38265","-0.00381"
"72834","436.96800","36.41416","-0.00454"
"72897","437.34600","36.44572","-0.00503"
"72960","437.72400","36.47717","-0.00303"
"73023","438.10200","36.50863","-0.00433"
"73086","438.48000","36.54026","-0.00449"
"73149","438.85800","36.57170","-0.00354"
"73212","439.23600","36.60315","-0.00371"
"73275","439.61400","36.63472","-0.00423"
"73338","439.99200","36.66623","-0.00360"
"73401","440.37000","36.69762","-0.00365"
"73464","440.74800","36.72919","-0.00426"
"73527","441.12600","36.76070","-0.00281"
"73590","441.50400","36.79221","-0.00386"
"73653","441.88200","36.82366","-0.00293"
"73716","442.26000","36.85522","-0.00272"
"73779","442.63800","36.88673","-0.00380"
"73842","443.01600","36.91812","-0.00354"
"73905","443.39400","36.94975","-0.00305"
"73968","443.77200","36.98126","-0.00246"
"74031","444.15000","37.01265","-0.00338"
"74094","444.52800","37.04422","-0.00350"
"74157","444.90600","37.07573","-0.00244"
"74220","445.28400","37.10718","-0.00366"
"74283","445.66200","37.13869","-0.00292"
"74346","446.04000","37.17020","-0.00197"
"74409","446.41800","37.20171","-0.00318"
"74472","446.79600","37.23315","-0.00268"
"74535","447.17400","37.26466","-0.00238"
"74598","447.55200","37.29623","-0.00216"
"74661","447.93000","37.32762","-0.00251"
"74724","448.30800","37.35919","-0.00188"
"74787","448.68600","37.39076","-0.00203"
"74850","449.06400","37.42215","-0.00240"
"74913","449.44200","37.45372","-0.00174"
"74976","449.82000","37.48523","-0.00247"
"75039","450.19800","37.51667","-0.00230"
"75102","450.57600","37.54813","-0.00175"
"75165","450.95400","37.57969","-0.00147"
"75228","451.33200","37.61121","-0.00160"
"75291","451.71000","37.64272","-0.00130"
"75354","452.08800","37.67416","-0.00077"
"75417","452.46600","37.70567","-0.00076"
"75480","452.84400","37.73718","-0.00086"
"75543","453.22200","37.76869","-0.00103"
"75606","453.60000","37.80020","-0.00078"
"75669","453.97800","37.83177","-0.00039"
"75732","454.35600","37.86316","-0.00022"
"75795","454.73400","37.89473","-0.00072"
"75858","455.11200","37.92624","0.00000"
"75921","455.49000","37.95762","-0.00054"
"75984","455.86800","37.98919","-0.00044"
"76047","456.24600","38.02070","0.00023"
"76110","456.62400","38.05221","0.00014"
"76173","457.00200","38.08366","0.00003"
"76236","457.38000","38.11523","-0.00009"
"76299","457.75800","38.14674","0.00027"
"76362","458.13600","38.17819","0.00040"
"76425","458.51400","38.20969","0.00086"
"76488","458.89200","38.24121","0.00038"
"76551","459.27000","38.27272","0.00095"
"76614","459.64800","38.30416","0.00109"
"76677","460.02600","38.33573","0.00119"
"76740","460.40400","38.36718","0.00088"
"76803","460.78200","38.39869","0.00158"
"76866","461.16000","38.43020","0.00210"
"76929","461.53800","38.46171","0.00242"
"76992","461.91600","38.49316","0.00248"
"77055","462.29400","38.52473","0.00206"
"77118","462.67200","38.55618","0.00264"
"77181","463.05000","38.58768","0.00281"
"77244","463.42800","38.61913","0.00312"
"77307","463.80600","38.65071","0.00270"
"77337","463.98400","38.66547","0.00341"