File: Trajectories_together/170212_2Specimen_RawData_8.csv
"","V1","V2","V3"
"1","End date","2/12/2017",""
"2","Specimen label","14AG_11",""
"3","Maximum Load","0.25222","N"
"4","Time","Extension","Load"
"5","(s)","(mm)","(N)"
"6","0.00000","23.15978","0.01835"
"28","0.13200","23.16629","0.01919"
"50","0.26400","23.18046","0.01822"
"72","0.39600","23.19290","0.01846"
"94","0.52800","23.20402","0.01835"
"116","0.66000","23.21490","0.01855"
"138","0.79200","23.22590","0.01938"
"160","0.92400","23.23690","0.01869"
"182","1.05600","23.24791","0.01917"
"204","1.18800","23.25896","0.01912"
"226","1.32000","23.26997","0.01945"
"248","1.45200","23.28091","0.01981"
"270","1.58400","23.29191","0.01966"
"292","1.71600","23.30291","0.01963"
"314","1.84800","23.31391","0.02028"
"336","1.98000","23.32485","0.02000"
"358","2.11200","23.33591","0.02014"
"380","2.24400","23.34692","0.02038"
"402","2.37600","23.35792","0.02023"
"424","2.50800","23.36886","0.01970"
"446","2.64000","23.37992","0.02038"
"468","2.77200","23.39098","0.02100"
"490","2.90400","23.40192","0.02083"
"512","3.03600","23.41292","0.02088"
"534","3.16800","23.42386","0.02149"
"556","3.30000","23.43493","0.02104"
"578","3.43200","23.44593","0.02107"
"600","3.56400","23.45693","0.02143"
"622","3.69600","23.46787","0.02142"
"644","3.82800","23.47893","0.02137"
"666","3.96000","23.48993","0.02172"
"688","4.09200","23.50087","0.02157"
"710","4.22400","23.51187","0.02226"
"732","4.35600","23.52294","0.02215"
"754","4.48800","23.53388","0.02263"
"776","4.62000","23.54488","0.02238"
"798","4.75200","23.55582","0.02225"
"820","4.88400","23.56688","0.02205"
"842","5.01600","23.57788","0.02254"
"864","5.14800","23.58883","0.02244"
"886","5.28000","23.59982","0.02291"
"908","5.41200","23.61095","0.02237"
"930","5.54400","23.62189","0.02343"
"952","5.67600","23.63289","0.02292"
"974","5.80800","23.64389","0.02327"
"996","5.94000","23.65495","0.02330"
"1018","6.07200","23.66589","0.02340"
"1040","6.20400","23.67695","0.02325"
"1062","6.33600","23.68784","0.02344"
"1084","6.46800","23.69890","0.02351"
"1106","6.60000","23.70990","0.02360"
"1128","6.73200","23.72084","0.02422"
"1150","6.86400","23.73184","0.02386"
"1172","6.99600","23.74290","0.02385"
"1194","7.12800","23.75390","0.02468"
"1216","7.26000","23.76484","0.02446"
"1238","7.39200","23.77585","0.02477"
"1260","7.52400","23.78685","0.02391"
"1282","7.65600","23.79791","0.02448"
"1304","7.78800","23.80891","0.02492"
"1326","7.92000","23.81985","0.02495"
"1348","8.05200","23.83091","0.02486"
"1370","8.18400","23.84191","0.02487"
"1392","8.31600","23.85286","0.02448"
"1414","8.44800","23.86386","0.02505"
"1436","8.58000","23.87486","0.02591"
"1458","8.71200","23.88586","0.02573"
"1480","8.84400","23.89692","0.02575"
"1502","8.97600","23.90786","0.02589"
"1524","9.10800","23.91886","0.02569"
"1546","9.24000","23.92992","0.02590"
"1568","9.37200","23.94092","0.02627"
"1590","9.50400","23.95187","0.02569"
"1612","9.63600","23.96287","0.02652"
"1634","9.76800","23.97387","0.02635"
"1656","9.90000","23.98493","0.02689"
"1678","10.03200","23.99587","0.02667"
"1700","10.16400","24.00687","0.02692"
"1722","10.29600","24.01787","0.02685"
"1744","10.42800","24.02893","0.02718"
"1766","10.56000","24.03988","0.02750"
"1788","10.69200","24.05088","0.02690"
"1810","10.82400","24.06188","0.02737"
"1832","10.95600","24.07288","0.02736"
"1854","11.08800","24.08382","0.02748"
"1876","11.22000","24.09482","0.02784"
"1898","11.35200","24.10588","0.02783"
"1920","11.48400","24.11689","0.02772"
"1942","11.61600","24.12789","0.02794"
"1964","11.74800","24.13883","0.02853"
"1986","11.88000","24.14989","0.02853"
"2008","12.01200","24.16089","0.02784"
"2030","12.14400","24.17189","0.02804"
"2052","12.27600","24.18289","0.02803"
"2074","12.40800","24.19390","0.00974"
"2096","12.54000","24.20495","0.02098"
"2118","12.67200","24.21590","0.02646"
"2140","12.80400","24.22690","0.01182"
"2162","12.93600","24.23790","0.01827"
"2184","13.06800","24.24884","0.02838"
"2206","13.20000","24.25984","0.02198"
"2228","13.33200","24.27078","0.01757"
"2250","13.46400","24.28191","0.02492"
"2272","13.59600","24.29284","0.02100"
"2294","13.72800","24.30391","0.01839"
"2316","13.86000","24.31485","0.02482"
"2338","13.99200","24.32591","0.02247"
"2360","14.12400","24.33691","0.01792"
"2382","14.25600","24.34797","0.02547"
"2404","14.38800","24.35885","0.02528"
"2426","14.52000","24.36992","0.01826"
"2448","14.65200","24.38092","0.02288"
"2470","14.78400","24.39192","0.02638"
"2492","14.91600","24.40286","0.02209"
"2514","15.04800","24.41392","0.02170"
"2536","15.18000","24.42492","0.02522"
"2558","15.31200","24.43592","0.02385"
"2580","15.44400","24.44686","0.02313"
"2602","15.57600","24.45793","0.02386"
"2624","15.70800","24.46893","0.02272"
"2646","15.84000","24.47993","0.02459"
"2668","15.97200","24.49087","0.02588"
"2690","16.10400","24.50193","0.02307"
"2712","16.23600","24.51293","0.02433"
"2734","16.36800","24.52387","0.02678"
"2756","16.50000","24.53487","0.02462"
"2778","16.63200","24.54587","0.02362"
"2800","16.76400","24.55694","0.02652"
"2822","16.89600","24.56788","0.02616"
"2844","17.02800","24.57888","0.02448"
"2866","17.16000","24.58982","0.02508"
"2888","17.29200","24.60094","0.02649"
"2910","17.42400","24.61194","0.02653"
"2932","17.55600","24.62283","0.02619"
"2954","17.68800","24.63388","0.02526"
"2976","17.82000","24.64495","0.02635"
"2998","17.95200","24.65595","0.02755"
"3020","18.08400","24.66683","0.02636"
"3042","18.21600","24.67783","0.02606"
"3064","18.34800","24.68889","0.02720"
"3086","18.48000","24.69995","0.02782"
"3108","18.61200","24.71089","0.02603"
"3130","18.74400","24.72184","0.02765"
"3152","18.87600","24.73289","0.02844"
"3174","19.00800","24.74390","0.02768"
"3196","19.14000","24.75490","0.02723"
"3218","19.27200","24.76584","0.02808"
"3240","19.40400","24.77690","0.02835"
"3262","19.53600","24.78790","0.02824"
"3284","19.66800","24.79890","0.02788"
"3306","19.80000","24.80985","0.02836"
"3328","19.93200","24.82091","0.02946"
"3350","20.06400","24.83191","0.02880"
"3372","20.19600","24.84291","0.02819"
"3394","20.32800","24.85385","0.02936"
"3416","20.46000","24.86491","0.02977"
"3438","20.59200","24.87592","0.02915"
"3460","20.72400","24.88691","0.02868"
"3482","20.85600","24.89791","0.03004"
"3504","20.98800","24.90892","0.03009"
"3526","21.12000","24.91992","0.02954"
"3548","21.25200","24.93092","0.02974"
"3570","21.38400","24.94186","0.03064"
"3592","21.51600","24.95292","0.03030"
"3614","21.64800","24.96386","0.02981"
"3636","21.78000","24.97486","0.03056"
"3658","21.91200","24.98587","0.03069"
"3680","22.04400","24.99693","0.03050"
"3702","22.17600","25.00793","0.03025"
"3724","22.30800","25.01887","0.03081"
"3746","22.44000","25.02987","0.03123"
"3768","22.57200","25.04087","0.03067"
"3790","22.70400","25.05187","0.03082"
"3812","22.83600","25.06293","0.03133"
"3834","22.96800","25.07382","0.03177"
"3856","23.10000","25.08488","0.03150"
"3878","23.23200","25.09594","0.03128"
"3900","23.36400","25.10694","0.03207"
"3922","23.49600","25.11782","0.03177"
"3944","23.62800","25.12888","0.03170"
"3966","23.76000","25.13994","0.03200"
"3988","23.89200","25.15089","0.03253"
"4010","24.02400","25.16183","0.03239"
"4032","24.15600","25.17289","0.03230"
"4054","24.28800","25.18395","0.03270"
"4076","24.42000","25.19489","0.03306"
"4098","24.55200","25.20589","0.03311"
"4120","24.68400","25.21684","0.03299"
"4142","24.81600","25.22789","0.03299"
"4164","24.94800","25.23890","0.03342"
"4186","25.08000","25.24990","0.03351"
"4208","25.21200","25.26084","0.03355"
"4230","25.34400","25.27196","0.03379"
"4252","25.47600","25.28290","0.03375"
"4274","25.60800","25.29390","0.03380"
"4296","25.74000","25.30484","0.03408"
"4318","25.87200","25.31596","0.03442"
"4340","26.00400","25.32691","0.03455"
"4362","26.13600","25.33785","0.03445"
"4384","26.26800","25.34879","0.03479"
"4406","26.40000","25.35985","0.03529"
"4428","26.53200","25.37091","0.03489"
"4450","26.66400","25.38191","0.03503"
"4472","26.79600","25.39285","0.03562"
"4494","26.92800","25.40392","0.03548"
"4516","27.06000","25.41492","0.03568"
"4538","27.19200","25.42586","0.03542"
"4560","27.32400","25.43686","0.03610"
"4582","27.45600","25.44792","0.03614"
"4604","27.58800","25.45892","0.03629"
"4626","27.72000","25.46992","0.03652"
"4648","27.85200","25.48087","0.03707"
"4670","27.98400","25.49187","0.03698"
"4692","28.11600","25.50293","0.03713"
"4714","28.24800","25.51393","0.03745"
"4736","28.38000","25.52487","0.03783"
"4758","28.51200","25.53587","0.03795"
"4780","28.64400","25.54693","0.03787"
"4802","28.77600","25.55787","0.03843"
"4824","28.90800","25.56887","0.03865"
"4846","29.04000","25.57988","0.03867"
"4868","29.17200","25.59094","0.03889"
"4890","29.30400","25.60194","0.03937"
"4912","29.43600","25.61294","0.03970"
"4934","29.56800","25.62394","0.03964"
"4956","29.70000","25.63488","0.04027"
"4978","29.83200","25.64588","0.04042"
"5000","29.96400","25.65689","0.04094"
"5022","30.09600","25.66788","0.04109"
"5044","30.22800","25.67895","0.04141"
"5066","30.36000","25.68989","0.04232"
"5088","30.49200","25.70083","0.04213"
"5110","30.62400","25.71183","0.04315"
"5132","30.75600","25.72289","0.04416"
"5154","30.88800","25.73389","0.04389"
"5176","31.02000","25.74489","0.04458"
"5198","31.15200","25.75590","0.04547"
"5220","31.28400","25.76690","0.04588"
"5242","31.41600","25.77790","0.04672"
"5264","31.54800","25.78884","0.04729"
"5286","31.68000","25.79990","0.04835"
"5308","31.81200","25.81090","0.04850"
"5330","31.94400","25.82191","0.04798"
"5352","32.07600","25.83285","0.04929"
"5374","32.20800","25.84385","0.04966"
"5396","32.34000","25.85497","0.05060"
"5418","32.47200","25.86591","0.05083"
"5440","32.60400","25.87685","0.05164"
"5462","32.73600","25.88785","0.05239"
"5484","32.86800","25.89891","0.05265"
"5506","33.00000","25.90992","0.05408"
"5528","33.13200","25.92086","0.05540"
"5550","33.26400","25.93180","0.05513"
"5572","33.39600","25.94292","0.05554"
"5594","33.52800","25.95392","0.05621"
"5616","33.66000","25.96492","0.05689"
"5638","33.79200","25.97586","0.05760"
"5660","33.92400","25.98692","0.05828"
"5682","34.05600","25.99792","0.05825"
"5704","34.18800","26.00892","0.05900"
"5726","34.32000","26.01987","0.05979"
"5748","34.45200","26.03087","0.06017"
"5770","34.58400","26.04193","0.06080"
"5792","34.71600","26.05287","0.06145"
"5814","34.84800","26.06381","0.06216"
"5836","34.98000","26.07487","0.06342"
"5858","35.11200","26.08588","0.06341"
"5880","35.24400","26.09688","0.06377"
"5902","35.37600","26.10788","0.06470"
"5924","35.50800","26.11894","0.06533"
"5946","35.64000","26.12988","0.06614"
"5968","35.77200","26.14094","0.06692"
"5990","35.90400","26.15182","0.06798"
"6012","36.03600","26.16288","0.06890"
"6034","36.16800","26.17389","0.06885"
"6056","36.30000","26.18494","0.07048"
"6078","36.43200","26.19589","0.07133"
"6100","36.56400","26.20689","0.07218"
"6122","36.69600","26.21789","0.07257"
"6144","36.82800","26.22889","0.07318"
"6166","36.96000","26.23983","0.07388"
"6188","37.09200","26.25089","0.07501"
"6210","37.22400","26.26196","0.07516"
"6232","37.35600","26.27295","0.07583"
"6254","37.48800","26.28396","0.07643"
"6276","37.62000","26.29490","0.07745"
"6298","37.75200","26.30596","0.07769"
"6320","37.88400","26.31690","0.07798"
"6342","38.01600","26.32790","0.07848"
"6364","38.14800","26.33885","0.07879"
"6386","38.28000","26.34991","0.07908"
"6408","38.41200","26.36091","0.07975"
"6430","38.54400","26.37191","0.07982"
"6452","38.67600","26.38285","0.07952"
"6474","38.80800","26.39397","0.07974"
"6496","38.94000","26.40491","0.08009"
"6518","39.07200","26.41591","0.08041"
"6540","39.20400","26.42686","0.08069"
"6562","39.33600","26.43792","0.08136"
"6584","39.46800","26.44892","0.08173"
"6606","39.60000","26.45986","0.08191"
"6628","39.73200","26.47086","0.08218"
"6650","39.86400","26.48192","0.08218"
"6672","39.99600","26.49292","0.08283"
"6694","40.12800","26.50386","0.08318"
"6716","40.26000","26.51487","0.08307"
"6738","40.39200","26.52593","0.08343"
"6760","40.52400","26.53693","0.08391"
"6782","40.65600","26.54793","0.08404"
"6804","40.78800","26.55887","0.08448"
"6826","40.92000","26.56993","0.08509"
"6848","41.05200","26.58087","0.08511"
"6870","41.18400","26.59188","0.08566"
"6892","41.31600","26.60282","0.08618"
"6914","41.44800","26.61387","0.08708"
"6936","41.58000","26.62488","0.08719"
"6958","41.71200","26.63588","0.08803"
"6980","41.84400","26.64682","0.08936"
"7002","41.97600","26.65794","0.08881"
"7024","42.10800","26.66894","0.08959"
"7046","42.24000","26.67994","0.09097"
"7068","42.37200","26.69089","0.09217"
"7090","42.50400","26.70195","0.09206"
"7112","42.63600","26.71295","0.09259"
"7134","42.76800","26.72389","0.09321"
"7156","42.90000","26.73483","0.09400"
"7178","43.03200","26.74589","0.09563"
"7200","43.16400","26.75689","0.09528"
"7222","43.29600","26.76789","0.09603"
"7244","43.42800","26.77884","0.09720"
"7266","43.56000","26.78990","0.09743"
"7288","43.69200","26.80090","0.09826"
"7310","43.82400","26.81190","0.09851"
"7332","43.95600","26.82290","0.09955"
"7354","44.08800","26.83390","0.10053"
"7376","44.22000","26.84496","0.10127"
"7398","44.35200","26.85591","0.10187"
"7420","44.48400","26.86685","0.10197"
"7442","44.61600","26.87785","0.10279"
"7464","44.74800","26.88891","0.10324"
"7486","44.88000","26.89991","0.10484"
"7508","45.01200","26.91085","0.10471"
"7530","45.14400","26.92185","0.10543"
"7552","45.27600","26.93291","0.10632"
"7574","45.40800","26.94391","0.10714"
"7596","45.54000","26.95486","0.10814"
"7618","45.67200","26.96592","0.10904"
"7640","45.80400","26.97698","0.10965"
"7662","45.93600","26.98792","0.10992"
"7684","46.06800","26.99886","0.11123"
"7706","46.20000","27.00986","0.11157"
"7728","46.33200","27.02086","0.11220"
"7750","46.46400","27.03186","0.11253"
"7772","46.59600","27.04281","0.11344"
"7794","46.72800","27.05381","0.11307"
"7816","46.86000","27.06493","0.11451"
"7838","46.99200","27.07587","0.11437"
"7860","47.12400","27.08693","0.11522"
"7882","47.25600","27.09787","0.11581"
"7904","47.38800","27.10893","0.11598"
"7926","47.52000","27.11994","0.11653"
"7948","47.65200","27.13088","0.11725"
"7970","47.78400","27.14182","0.11723"
"7992","47.91600","27.15288","0.11792"
"8014","48.04800","27.16388","0.11881"
"8036","48.18000","27.17482","0.11949"
"8058","48.31200","27.18588","0.11973"
"8080","48.44400","27.19694","0.12022"
"8102","48.57600","27.20789","0.12048"
"8124","48.70800","27.21894","0.12094"
"8146","48.84000","27.22989","0.12128"
"8168","48.97200","27.24095","0.12205"
"8190","49.10400","27.25195","0.12180"
"8212","49.23600","27.26289","0.12267"
"8234","49.36800","27.27383","0.12260"
"8256","49.50000","27.28489","0.12306"
"8278","49.63200","27.29589","0.12362"
"8300","49.76400","27.30684","0.12400"
"8322","49.89600","27.31784","0.12445"
"8344","50.02800","27.32890","0.12491"
"8366","50.16000","27.33990","0.12472"
"8388","50.29200","27.35090","0.12483"
"8410","50.42400","27.36190","0.12532"
"8432","50.55600","27.37290","0.12549"
"8454","50.68800","27.38397","0.12584"
"8476","50.82000","27.39491","0.12594"
"8498","50.95200","27.40585","0.12643"
"8520","51.08400","27.41685","0.12664"
"8542","51.21600","27.42797","0.12671"
"8564","51.34800","27.43891","0.12686"
"8586","51.48000","27.44985","0.12734"
"8608","51.61200","27.46086","0.12795"
"8630","51.74400","27.47191","0.12814"
"8652","51.87600","27.48292","0.12822"
"8674","52.00800","27.49386","0.12865"
"8696","52.14000","27.50492","0.12848"
"8718","52.27200","27.51592","0.12879"
"8740","52.40400","27.52692","0.12892"
"8762","52.53600","27.53786","0.12964"
"8784","52.66800","27.54887","0.12947"
"8806","52.80000","27.55993","0.12970"
"8828","52.93200","27.57093","0.13030"
"8850","53.06400","27.58187","0.13060"
"8872","53.19600","27.59287","0.13070"
"8894","53.32800","27.60393","0.13073"
"8916","53.46000","27.61493","0.13107"
"8938","53.59200","27.62588","0.13144"
"8960","53.72400","27.63688","0.13133"
"8982","53.85600","27.64793","0.13218"
"9004","53.98800","27.65894","0.13205"
"9026","54.12000","27.66988","0.13254"
"9048","54.25200","27.68082","0.13291"
"9070","54.38400","27.69188","0.13329"
"9092","54.51600","27.70288","0.13340"
"9114","54.64800","27.71389","0.13307"
"9136","54.78000","27.72482","0.13343"
"9158","54.91200","27.73594","0.13300"
"9180","55.04400","27.74689","0.13297"
"9202","55.17600","27.75789","0.13369"
"9224","55.30800","27.76889","0.13427"
"9246","55.44000","27.77995","0.13403"
"9268","55.57200","27.79095","0.13451"
"9290","55.70400","27.80190","0.13495"
"9312","55.83600","27.81284","0.13564"
"9334","55.96800","27.82389","0.13662"
"9356","56.10000","27.83484","0.13711"
"9378","56.23200","27.84584","0.13740"
"9400","56.36400","27.85684","0.13851"
"9422","56.49600","27.86790","0.13909"
"9444","56.62800","27.87890","0.13909"
"9466","56.76000","27.88991","0.14001"
"9488","56.89200","27.90091","0.14011"
"9510","57.02400","27.91191","0.14061"
"9532","57.15600","27.92291","0.14163"
"9554","57.28800","27.93391","0.14285"
"9576","57.42000","27.94485","0.14300"
"9598","57.55200","27.95591","0.14403"
"9620","57.68400","27.96691","0.14513"
"9642","57.81600","27.97791","0.14609"
"9664","57.94800","27.98886","0.14693"
"9686","58.08000","27.99986","0.14843"
"9708","58.21200","28.01092","0.14873"
"9730","58.34400","28.02192","0.15034"
"9752","58.47600","28.03286","0.15140"
"9774","58.60800","28.04392","0.15227"
"9796","58.74000","28.05492","0.15287"
"9818","58.87200","28.06593","0.15475"
"9840","59.00400","28.07686","0.15625"
"9862","59.13600","28.08787","0.15725"
"9884","59.26800","28.09893","0.15547"
"9906","59.40000","28.10987","0.15556"
"9928","59.53200","28.12087","0.15711"
"9950","59.66400","28.13181","0.15653"
"9972","59.79600","28.14293","0.15856"
"9994","59.92800","28.15394","0.16099"
"10016","60.06000","28.16488","0.15982"
"10038","60.19200","28.17588","0.16243"
"10060","60.32400","28.18694","0.16332"
"10082","60.45600","28.19794","0.16324"
"10104","60.58800","28.20882","0.16583"
"10126","60.72000","28.21982","0.16651"
"10148","60.85200","28.23088","0.16764"
"10170","60.98400","28.24188","0.16844"
"10192","61.11600","28.25289","0.17038"
"10214","61.24800","28.26383","0.17000"
"10236","61.38000","28.27489","0.17176"
"10258","61.51200","28.28595","0.17309"
"10280","61.64400","28.29689","0.17250"
"10302","61.77600","28.30789","0.17177"
"10324","61.90800","28.31889","0.17206"
"10346","62.04000","28.32996","0.17458"
"10368","62.17200","28.34090","0.17433"
"10390","62.30400","28.35184","0.17513"
"10412","62.43600","28.36290","0.17664"
"10434","62.56800","28.37390","0.17606"
"10456","62.70000","28.38484","0.17752"
"10478","62.83200","28.39584","0.17866"
"10500","62.96400","28.40690","0.17875"
"10522","63.09600","28.41791","0.17747"
"10544","63.22800","28.42891","0.17832"
"10566","63.36000","28.43991","0.18003"
"10588","63.49200","28.45091","0.18105"
"10610","63.62400","28.46191","0.18085"
"10632","63.75600","28.47291","0.18154"
"10654","63.88800","28.48385","0.18184"
"10676","64.02000","28.49491","0.18281"
"10698","64.15200","28.50586","0.18342"
"10720","64.28400","28.51686","0.18367"
"10742","64.41600","28.52786","0.18507"
"10764","64.54800","28.53892","0.18486"
"10786","64.68000","28.54992","0.18505"
"10808","64.81200","28.56092","0.18592"
"10830","64.94400","28.57186","0.18630"
"10852","65.07600","28.58293","0.18628"
"10874","65.20800","28.59393","0.18681"
"10896","65.34000","28.60493","0.18722"
"10918","65.47200","28.61593","0.18743"
"10940","65.60400","28.62693","0.18766"
"10962","65.73600","28.63793","0.18813"
"10984","65.86800","28.64893","0.18820"
"11006","66.00000","28.65987","0.18849"
"11028","66.13200","28.67088","0.18894"
"11050","66.26400","28.68194","0.18937"
"11072","66.39600","28.69294","0.18932"
"11094","66.52800","28.70388","0.18979"
"11116","66.66000","28.71488","0.19031"
"11138","66.79200","28.72594","0.19094"
"11160","66.92400","28.73688","0.19126"
"11182","67.05600","28.74788","0.19218"
"11204","67.18800","28.75889","0.19243"
"11226","67.32000","28.76995","0.19290"
"11248","67.45200","28.78089","0.19259"
"11270","67.58400","28.79183","0.19316"
"11292","67.71600","28.80283","0.19409"
"11314","67.84800","28.81395","0.19480"
"11336","67.98000","28.82495","0.19555"
"11358","68.11200","28.83590","0.19660"
"11380","68.24400","28.84684","0.19685"
"11402","68.37600","28.85790","0.19731"
"11424","68.50800","28.86890","0.19933"
"11446","68.64000","28.87990","0.19905"
"11468","68.77200","28.89084","0.20043"
"11490","68.90400","28.90184","0.20180"
"11512","69.03600","28.91290","0.20187"
"11534","69.16800","28.92385","0.20353"
"11556","69.30000","28.93485","0.20429"
"11578","69.43200","28.94585","0.20488"
"11600","69.56400","28.95691","0.20570"
"11622","69.69600","28.96791","0.20624"
"11644","69.82800","28.97885","0.20739"
"11666","69.96000","28.98991","0.20924"
"11688","70.09200","29.00091","0.20910"
"11710","70.22400","29.01192","0.20990"
"11732","70.35600","29.02286","0.21095"
"11754","70.48800","29.03386","0.21253"
"11776","70.62000","29.04492","0.21322"
"11798","70.75200","29.05592","0.21461"
"11820","70.88400","29.06686","0.21527"
"11842","71.01600","29.07786","0.21594"
"11864","71.14800","29.08886","0.21648"
"11886","71.28000","29.09993","0.21651"
"11908","71.41200","29.11087","0.21727"
"11930","71.54400","29.12187","0.21835"
"11952","71.67600","29.13287","0.21955"
"11974","71.80800","29.14387","0.21976"
"11996","71.94000","29.15487","0.22100"
"12018","72.07200","29.16587","0.22155"
"12040","72.20400","29.17687","0.22212"
"12062","72.33600","29.18788","0.22320"
"12084","72.46800","29.19888","0.22364"
"12106","72.60000","29.20988","0.22425"
"12128","72.73200","29.22094","0.22496"
"12150","72.86400","29.23188","0.22548"
"12172","72.99600","29.24288","0.22555"
"12194","73.12800","29.25382","0.22649"
"12216","73.26000","29.26488","0.22710"
"12238","73.39200","29.27588","0.22737"
"12260","73.52400","29.28689","0.22804"
"12282","73.65600","29.29789","0.22841"
"12304","73.78800","29.30895","0.22848"
"12326","73.92000","29.31995","0.22929"
"12348","74.05200","29.33089","0.22962"
"12370","74.18400","29.34190","0.23004"
"12392","74.31600","29.35289","0.23065"
"12414","74.44800","29.36390","0.23089"
"12436","74.58000","29.37490","0.23122"
"12458","74.71200","29.38590","0.23135"
"12480","74.84400","29.39696","0.23174"
"12502","74.97600","29.40784","0.23220"
"12524","75.10800","29.41890","0.23181"
"12546","75.24000","29.42985","0.23195"
"12568","75.37200","29.44097","0.23235"
"12590","75.50400","29.45190","0.23233"
"12612","75.63600","29.46285","0.23288"
"12634","75.76800","29.47385","0.23297"
"12656","75.90000","29.48491","0.23324"
"12678","76.03200","29.49597","0.23370"
"12700","76.16400","29.50691","0.23411"
"12722","76.29600","29.51785","0.23447"
"12744","76.42800","29.52891","0.23469"
"12766","76.56000","29.53992","0.23502"
"12788","76.69200","29.55092","0.23524"
"12810","76.82400","29.56186","0.23564"
"12832","76.95600","29.57292","0.23574"
"12854","77.08800","29.58392","0.23636"
"12876","77.22000","29.59492","0.23658"
"12898","77.35200","29.60587","0.23707"
"12920","77.48400","29.61687","0.23733"
"12942","77.61600","29.62787","0.23769"
"12964","77.74800","29.63887","0.23788"
"12986","77.88000","29.64981","0.23852"
"13008","78.01200","29.66087","0.23909"
"13030","78.14400","29.67193","0.23917"
"13052","78.27600","29.68293","0.24013"
"13074","78.40800","29.69388","0.24010"
"13096","78.54000","29.70493","0.24100"
"13118","78.67200","29.71594","0.24069"
"13140","78.80400","29.72694","0.24139"
"13162","78.93600","29.73788","0.24176"
"13184","79.06800","29.74888","0.24198"
"13206","79.20000","29.75988","0.24243"
"13228","79.33200","29.77094","0.24389"
"13250","79.46400","29.78194","0.24462"
"13272","79.59600","29.79289","0.24557"
"13294","79.72800","29.80389","0.24676"
"13316","79.86000","29.81495","0.24777"
"13338","79.99200","29.82583","0.24838"
"13360","80.12400","29.83689","0.24938"
"13382","80.25600","29.84795","0.24960"
"13404","80.38800","29.85889","0.25104"
"13426","80.52000","29.86990","0.25200"
"13448","80.65200","29.88083","0.20812"
"13470","80.78400","29.89190","0.20786"
"13492","80.91600","29.90290","0.19866"
"13514","81.04800","29.91390","0.19833"
"13536","81.18000","29.92484","0.20357"
"13558","81.31200","29.93590","0.20267"
"13580","81.44400","29.94690","0.20448"
"13602","81.57600","29.95790","0.20537"
"13624","81.70800","29.96891","0.20933"
"13646","81.84000","29.97997","0.20541"
"13668","81.97200","29.99091","0.20940"
"13690","82.10400","30.00185","0.21480"
"13712","82.23600","30.01285","0.20873"
"13734","82.36800","30.02391","0.21561"
"13756","82.50000","30.03491","0.21513"
"13778","82.63200","30.04585","0.21273"
"13800","82.76400","30.05686","0.21926"
"13822","82.89600","30.06792","0.21840"
"13844","83.02800","30.07892","0.21978"
"13866","83.16000","30.08986","0.22049"
"13888","83.29200","30.10086","0.22291"
"13910","83.42400","30.11192","0.22173"
"13932","83.55600","30.12292","0.22328"
"13954","83.68800","30.13393","0.22643"
"13976","83.82000","30.14481","0.22338"
"13998","83.95200","30.15593","0.22695"
"14020","84.08400","30.16693","0.22698"
"14042","84.21600","30.17787","0.22658"
"14064","84.34800","30.18881","0.22888"
"14086","84.48000","30.19993","0.22829"
"14108","84.61200","30.21087","0.22942"
"14130","84.74400","30.22188","0.22996"
"14152","84.87600","30.23288","0.23109"
"14174","85.00800","30.24388","0.23083"
"14196","85.14000","30.25494","0.23180"
"14218","85.27200","30.26588","0.23224"
"14240","85.40400","30.27682","0.23190"
"14262","85.53600","30.28788","0.23320"
"14284","85.66800","30.29889","0.23298"
"14306","85.80000","30.30989","0.23367"
"14328","85.93200","30.32083","0.23441"
"14350","86.06400","30.33189","0.23426"
"14372","86.19600","30.34289","0.23499"
"14394","86.32800","30.35389","0.23563"
"14416","86.46000","30.36483","0.23638"
"14438","86.59200","30.37589","0.23601"
"14460","86.72400","30.38696","0.23697"
"14482","86.85600","30.39796","0.23718"
"14504","86.98800","30.40890","0.23759"
"14526","87.12000","30.41990","0.23883"
"14548","87.25200","30.43090","0.23814"
"14570","87.38400","30.44190","0.23929"
"14592","87.51600","30.45290","0.23911"
"14614","87.64800","30.46390","0.23971"
"14636","87.78000","30.47491","0.23935"
"14658","87.91200","30.48591","0.12860"
"14680","88.04400","30.49685","0.14075"
"14702","88.17600","30.50791","0.12191"
"14724","88.30800","30.51891","0.12195"
"14746","88.44000","30.52991","0.13221"
"14768","88.57200","30.54091","0.13700"
"14790","88.70400","30.55185","0.12488"
"14812","88.83600","30.56292","0.12568"
"14834","88.96800","30.57392","0.14819"
"14856","89.10000","30.58492","0.13024"
"14878","89.23200","30.59586","0.12501"
"14900","89.36400","30.60692","0.13523"
"14922","89.49600","30.61792","0.14513"
"14944","89.62800","30.62886","0.12715"
"14966","89.76000","30.63986","0.13005"
"14988","89.89200","30.65092","0.15185"
"15010","90.02400","30.66193","0.13404"
"15032","90.15600","30.67293","0.12922"
"15054","90.28800","30.68387","0.14075"
"15076","90.42000","30.69493","0.15431"
"15098","90.55200","30.70587","0.13109"
"15120","90.68400","30.71681","0.13396"
"15142","90.81600","30.72782","0.16120"
"15164","90.94800","30.73888","0.13793"
"15186","91.08000","30.74988","0.13405"
"15208","91.21200","30.76088","0.15143"
"15230","91.34400","30.77188","0.15490"
"15252","91.47600","30.78288","0.13607"
"15274","91.60800","30.79388","0.14293"
"15296","91.74000","30.80494","0.16977"
"15318","91.87200","30.81588","0.14322"
"15340","92.00400","30.82694","0.14224"
"15362","92.13600","30.83789","0.16682"
"15384","92.26800","30.84889","0.15798"
"15406","92.40000","30.85983","0.14548"
"15428","92.53200","30.87095","0.15989"
"15450","92.66400","30.88189","0.17442"
"15472","92.79600","30.89289","0.15170"
"15494","92.92800","30.90389","0.15728"
"15516","93.06000","30.91490","0.18144"
"15538","93.19200","30.92590","0.16368"
"15560","93.32400","30.93696","0.15922"
"15582","93.45600","30.94790","0.17994"
"15604","93.58800","30.95890","0.17736"
"15626","93.72000","30.96996","0.16446"
"15648","93.85200","30.98090","0.17441"
"15670","93.98400","30.99184","0.18419"
"15692","94.11600","31.00285","0.17055"
"15714","94.24800","31.01391","0.17438"
"15736","94.38000","31.02491","0.18605"
"15758","94.51200","31.03585","0.17820"
"15780","94.64400","31.04691","0.17681"
"15802","94.77600","31.05797","0.18569"
"15824","94.90800","31.06891","0.18485"
"15846","95.04000","31.07985","0.17940"
"15868","95.17200","31.09085","0.18433"
"15890","95.30400","31.10186","0.18725"
"15912","95.43600","31.11292","0.18157"
"15934","95.56800","31.12386","0.18419"
"15956","95.70000","31.13480","0.18912"
"15978","95.83200","31.14592","0.18499"
"16000","95.96400","31.15692","0.18600"
"16022","96.09600","31.16787","0.18900"
"16044","96.22800","31.17887","0.18802"
"16066","96.36000","31.18987","0.18682"
"16088","96.49200","31.20093","0.18949"
"16110","96.62400","31.21187","0.19029"
"16132","96.75600","31.22287","0.18745"
"16154","96.88800","31.23388","0.19026"
"16176","97.02000","31.24487","0.19317"
"16198","97.15200","31.25587","0.18933"
"16220","97.28400","31.26682","0.19106"
"16242","97.41600","31.27788","0.19482"
"16264","97.54800","31.28888","0.19231"
"16286","97.68000","31.29988","0.19136"
"16308","97.81200","31.31082","0.19660"
"16330","97.94400","31.32194","0.19415"
"16352","98.07600","31.33294","0.19176"
"16374","98.20800","31.34394","0.19737"
"16396","98.34000","31.35494","0.18365"
"16418","98.47200","31.36595","0.18503"
"16440","98.60400","31.37695","0.18608"
"16462","98.73600","31.38789","0.18618"
"16484","98.86800","31.39883","0.18567"
"16506","99.00000","31.40989","0.18616"
"16528","99.13200","31.42083","0.18739"
"16550","99.26400","31.43184","0.18640"
"16572","99.39600","31.44284","0.18672"
"16594","99.52800","31.45390","0.18742"
"16616","99.66000","31.46490","0.18720"
"16638","99.79200","31.47590","0.18754"
"16660","99.92400","31.48690","0.18797"
"16682","100.05600","31.49790","0.18836"
"16704","100.18800","31.50890","0.18760"
"16726","100.32000","31.51991","0.18811"
"16748","100.45200","31.53090","0.18912"
"16770","100.58400","31.54185","0.18954"
"16792","100.71600","31.55291","0.18983"
"16814","100.84800","31.56397","0.19045"
"16836","100.98000","31.57485","-0.01456"
"16858","101.11200","31.58585","0.01927"
"16880","101.24400","31.59697","0.01846"
"16902","101.37600","31.60791","0.01523"
"16924","101.50800","31.61886","0.00204"
"16946","101.64000","31.62992","0.00279"
"16968","101.77200","31.64098","0.02954"
"16990","101.90400","31.65192","0.02247"
"17012","102.03600","31.66286","0.00731"
"17034","102.16800","31.67380","0.02603"
"17056","102.30000","31.68492","0.02490"
"17078","102.43200","31.69587","0.01802"
"17100","102.56400","31.70687","0.02662"
"17122","102.69600","31.71781","0.02100"
"17144","102.82800","31.72893","0.00630"
"17166","102.96000","31.73993","0.02142"
"17188","103.09200","31.75087","0.03112"
"17210","103.22400","31.76187","0.01095"
"17232","103.35600","31.77293","0.00673"
"17254","103.48800","31.78394","0.02875"
"17276","103.62000","31.79488","0.02507"
"17298","103.75200","31.80582","0.01281"
"17320","103.88400","31.81688","0.02176"
"17342","104.01600","31.82794","0.02156"
"17364","104.14800","31.83888","0.01219"
"17386","104.28000","31.84988","0.02538"
"17408","104.41200","31.86088","0.02802"
"17430","104.54400","31.87194","0.01321"
"17452","104.67600","31.88295","0.01495"
"17474","104.80800","31.89389","0.02953"
"17496","104.94000","31.90495","0.01737"
"17518","105.07200","31.91595","0.01140"
"17540","105.20400","31.92695","0.02711"
"17562","105.33600","31.93783","0.02590"
"17584","105.46800","31.94889","0.01495"
"17606","105.60000","31.95989","0.02177"
"17628","105.73200","31.97084","0.02517"
"17650","105.86400","31.98184","0.01421"
"17672","105.99600","31.99290","0.02140"
"17694","106.12800","32.00390","0.02801"
"17716","106.26000","32.01490","0.01956"
"17738","106.39200","32.02584","0.01634"
"17760","106.52400","32.03690","0.02644"
"17782","106.65600","32.04797","0.02087"
"17804","106.78800","32.05891","0.01728"
"17826","106.92000","32.06991","0.02688"
"17848","107.05200","32.08085","0.02658"
"17870","107.18400","32.09185","0.01646"
"17892","107.31600","32.10291","0.02199"
"17914","107.44800","32.11385","0.02660"
"17936","107.58000","32.12486","0.01828"
"17958","107.71200","32.13586","0.02164"
"17980","107.84400","32.14692","0.02809"
"18002","107.97600","32.15786","0.02323"
"18024","108.10800","32.16886","0.01958"
"18046","108.24000","32.17992","0.02534"
"18068","108.37200","32.19086","0.02273"
"18090","108.50400","32.20186","0.02203"
"18112","108.63600","32.21286","0.02778"
"18134","108.76800","32.22387","0.02587"
"18156","108.90000","32.23487","0.02008"
"18178","109.03200","32.24587","0.02581"
"18200","109.16400","32.25687","0.02702"
"18222","109.29600","32.26793","0.01994"
"18244","109.42800","32.27893","0.02437"
"18266","109.56000","32.28988","0.02849"
"18288","109.69200","32.30087","0.02388"
"18310","109.82400","32.31200","0.02203"
"18332","109.95600","32.32288","0.02601"
"18354","110.08800","32.33388","0.02491"
"18376","110.22000","32.34482","0.02569"
"18398","110.35200","32.35588","0.02844"
"18420","110.48400","32.36688","0.02553"
"18442","110.61600","32.37788","0.02376"
"18464","110.74800","32.38882","0.02808"
"18486","110.88000","32.39995","0.02600"
"18508","111.01200","32.41089","0.02236"
"18530","111.14400","32.42195","0.02756"
"18552","111.27600","32.43283","0.02869"
"18574","111.40800","32.44395","0.02472"
"18596","111.54000","32.45495","0.02561"
"18618","111.67200","32.46589","0.02765"
"18640","111.80400","32.47683","0.02635"
"18662","111.93600","32.48790","0.02835"
"18684","112.06800","32.49890","0.02846"
"18706","112.20000","32.50990","0.02603"
"18728","112.33200","32.52084","0.02832"
"18750","112.46400","32.53190","0.02881"
"18772","112.59600","32.54290","0.02545"
"18794","112.72800","32.55391","0.02836"
"18816","112.86000","32.56485","0.03021"
"18838","112.99200","32.57591","0.02711"
"18860","113.12400","32.58691","0.02691"
"18882","113.25600","32.59791","0.02924"
"18904","113.38800","32.60885","0.02874"
"18926","113.52000","32.61985","0.02941"
"18948","113.65200","32.63085","0.02999"
"18970","113.78400","32.64185","0.02863"
"18992","113.91600","32.65286","0.02933"
"19014","114.04800","32.66386","0.03012"
"19036","114.18000","32.67486","0.02806"
"19058","114.31200","32.68592","0.02967"
"19080","114.44400","32.69686","0.03086"
"19102","114.57600","32.70786","0.02915"
"19124","114.70800","32.71892","0.02935"
"19146","114.84000","32.72993","0.03064"
"19168","114.97200","32.74087","0.03026"
"19190","115.10400","32.75187","0.03072"
"19212","115.23600","32.76293","0.03121"
"19234","115.36800","32.77387","0.03033"
"19256","115.50000","32.78487","0.03115"
"19278","115.63200","32.79593","0.03103"
"19300","115.76400","32.80700","0.03016"
"19322","115.89600","32.81794","0.03162"
"19344","116.02800","32.82888","0.03207"
"19366","116.16000","32.83988","0.03119"
"19388","116.29200","32.85094","0.03152"
"19410","116.42400","32.86188","0.03193"
"19432","116.55600","32.87288","0.03215"
"19454","116.68800","32.88388","0.03292"
"19476","116.82000","32.89488","0.03191"
"19498","116.95200","32.90589","0.03193"
"19520","117.08400","32.91683","0.03306"
"19542","117.21600","32.92783","0.03235"
"19564","117.34800","32.93889","0.03276"
"19586","117.48000","32.94995","0.03337"
"19608","117.61200","32.96089","0.03299"
"19630","117.74400","32.97189","0.03301"
"19652","117.87600","32.98296","0.03310"
"19674","118.00800","32.99390","0.03394"
"19696","118.14000","33.00490","0.03484"
"19718","118.27200","33.01590","0.03425"
"19740","118.40400","33.02696","0.03437"
"19762","118.53600","33.03790","0.03500"
"19784","118.66800","33.04884","0.03478"
"19806","118.80000","33.05978","0.03583"
"19828","118.93200","33.07091","0.03605"
"19850","119.06400","33.08191","0.03520"
"19872","119.19600","33.09285","0.03599"
"19894","119.32800","33.10385","0.03524"
"19916","119.46000","33.11491","0.03598"
"19938","119.59200","33.12591","0.03721"
"19960","119.72400","33.13691","0.03642"
"19982","119.85600","33.14785","0.03631"
"20004","119.98800","33.15892","0.03707"
"20026","120.12000","33.16992","0.03722"
"20048","120.25200","33.18086","0.03795"
"20070","120.38400","33.19186","0.03811"
"20092","120.51600","33.20286","0.03836"
"20114","120.64800","33.21386","0.03858"
"20136","120.78000","33.22492","0.03819"
"20158","120.91200","33.23587","0.03927"
"20180","121.04400","33.24687","0.04050"
"20202","121.17600","33.25793","0.03972"
"20224","121.30800","33.26893","0.03974"
"20246","121.44000","33.27987","0.04049"
"20268","121.57200","33.29087","0.04141"
"20290","121.70400","33.30193","0.04218"
"20312","121.83600","33.31287","0.04128"
"20334","121.96800","33.32388","0.04188"
"20356","122.10000","33.33482","0.04234"
"20378","122.23200","33.34588","0.04300"
"20400","122.36400","33.35688","0.04408"
"20422","122.49600","33.36788","0.04397"
"20444","122.62800","33.37888","0.04396"
"20466","122.76000","33.38988","0.04437"
"20488","122.89200","33.40094","0.04551"
"20510","123.02400","33.41189","0.04645"
"20532","123.15600","33.42289","0.04621"
"20554","123.28800","33.43395","0.04617"
"20576","123.42000","33.44489","0.04692"
"20598","123.55200","33.45589","0.04840"
"20620","123.68400","33.46689","0.04894"
"20642","123.81600","33.47795","0.04854"
"20664","123.94800","33.48890","0.04909"
"20686","124.08000","33.49990","0.04985"
"20708","124.21200","33.51090","0.05119"
"20730","124.34400","33.52190","0.05161"
"20752","124.47600","33.53290","0.05164"
"20774","124.60800","33.54390","0.05256"
"20796","124.74000","33.55484","0.05264"
"20818","124.87200","33.56591","0.05438"
"20840","125.00400","33.57690","0.05455"
"20862","125.13600","33.58785","0.05417"
"20884","125.26800","33.59885","0.05490"
"20906","125.40000","33.60991","0.05607"
"20928","125.53200","33.62091","0.05702"
"20950","125.66400","33.63185","0.05703"
"20972","125.79600","33.64285","0.05709"
"20994","125.92800","33.65392","0.05792"
"21016","126.06000","33.66492","0.05910"
"21038","126.19200","33.67591","0.06015"
"21060","126.32400","33.68686","0.05955"
"21082","126.45600","33.69792","0.06009"
"21104","126.58800","33.70892","0.06059"
"21126","126.72000","33.71992","0.06133"
"21148","126.85200","33.73080","0.06232"
"21170","126.98400","33.74192","0.06176"
"21192","127.11600","33.75286","0.06216"
"21214","127.24800","33.76387","0.06341"
"21236","127.38000","33.77487","0.06505"
"21258","127.51200","33.78587","0.06470"
"21280","127.64400","33.79687","0.06440"
"21302","127.77600","33.80793","0.06516"
"21324","127.90800","33.81887","0.06647"
"21346","128.04000","33.82993","0.06724"
"21368","128.17200","33.84093","0.06441"
"21390","128.30400","33.85194","0.06401"
"21412","128.43600","33.86282","0.06465"
"21434","128.56800","33.87388","0.06748"
"21456","128.70000","33.88494","0.06729"
"21478","128.83200","33.89594","0.06565"
"21500","128.96400","33.90688","0.06259"
"21522","129.09600","33.91788","0.06239"
"21544","129.22800","33.92889","0.06568"
"21566","129.36000","33.93989","0.06609"
"21588","129.49200","33.95083","0.06474"
"21610","129.62400","33.96189","0.06528"
"21632","129.75600","33.97295","0.06733"
"21654","129.88800","33.98395","0.06925"
"21676","130.02000","33.99490","0.06792"
"21698","130.15200","34.00584","0.06762"
"21720","130.28400","34.01690","0.06874"
"21742","130.41600","34.02790","0.07086"
"21764","130.54800","34.03884","0.07115"
"21786","130.68000","34.04984","0.07011"
"21808","130.81200","34.06090","0.07150"
"21830","130.94400","34.07190","0.07375"
"21852","131.07600","34.08284","0.07412"
"21874","131.20800","34.09385","0.07386"
"21896","131.34000","34.10490","0.07429"
"21918","131.47200","34.11591","0.07527"
"21940","131.60400","34.12685","0.07605"
"21962","131.73600","34.13779","0.07682"
"21984","131.86800","34.14891","0.07666"
"22006","132.00000","34.15985","0.07693"
"22028","132.13200","34.17091","0.07784"
"22050","132.26400","34.18185","0.07848"
"22072","132.39600","34.19292","0.07862"
"22094","132.52800","34.20392","0.07867"
"22116","132.66000","34.21486","0.07925"
"22138","132.79200","34.22586","0.08024"
"22160","132.92400","34.23686","0.08062"
"22182","133.05600","34.24786","0.07982"
"22204","133.18800","34.25887","0.08030"
"22226","133.32000","34.26981","0.08128"
"22248","133.45200","34.28086","0.08107"
"22270","133.58400","34.29187","0.08087"
"22292","133.71600","34.30287","0.08092"
"22314","133.84800","34.31387","0.08151"
"22336","133.98000","34.32487","0.08222"
"22358","134.11200","34.33587","0.08224"
"22380","134.24400","34.34687","0.08212"
"22402","134.37600","34.35788","0.08212"
"22424","134.50800","34.36893","0.08285"
"22446","134.64000","34.37994","0.08286"
"22468","134.77200","34.39094","0.08283"
"22490","134.90400","34.40188","0.08292"
"22512","135.03600","34.41288","0.08361"
"22534","135.16800","34.42389","0.08383"
"22556","135.30000","34.43488","0.08368"
"22578","135.43200","34.44583","0.08383"
"22600","135.56400","34.45689","0.08442"
"22622","135.69600","34.46789","0.08526"
"22644","135.82800","34.47889","0.08502"
"22666","135.96000","34.48989","0.08508"
"22688","136.09200","34.50089","0.08596"
"22710","136.22400","34.51196","0.08723"
"22732","136.35600","34.52290","0.08767"
"22754","136.48800","34.53390","0.08764"
"22776","136.62000","34.54490","0.08826"
"22798","136.75200","34.55596","0.09050"
"22820","136.88400","34.56696","0.09094"
"22842","137.01600","34.57784","0.08949"
"22864","137.14800","34.58878","0.09051"
"22886","137.28000","34.59996","0.09255"
"22908","137.41200","34.61090","0.07026"
"22930","137.54400","34.62191","0.07357"
"22952","137.67600","34.63291","0.07482"
"22974","137.80800","34.64391","0.07303"
"22996","137.94000","34.65497","0.07280"
"23018","138.07200","34.66591","0.07545"
"23040","138.20400","34.67685","0.07461"
"23062","138.33600","34.68792","0.07307"
"23084","138.46800","34.69891","0.07315"
"23106","138.60000","34.70985","0.07380"
"23128","138.73200","34.72080","0.07361"
"23150","138.86400","34.73192","0.04967"
"23172","138.99600","34.74292","0.04749"
"23194","139.12800","34.75386","0.05871"
"23216","139.26000","34.76486","0.04812"
"23238","139.39200","34.77592","0.03884"
"23260","139.52400","34.78693","0.03588"
"23282","139.65600","34.79792","0.04373"
"23304","139.78800","34.80887","0.05576"
"23326","139.92000","34.81993","0.04404"
"23348","140.05200","34.83093","0.03764"
"23370","140.18400","34.84193","0.03835"
"23392","140.31600","34.85287","0.04764"
"23414","140.44800","34.86393","0.05471"
"23436","140.58000","34.87487","0.04241"
"23458","140.71200","34.88594","0.03756"
"23480","140.84400","34.89682","0.04253"
"23502","140.97600","34.90788","0.05095"
"23524","141.10800","34.91894","0.05338"
"23546","141.24000","34.92994","0.04167"
"23568","141.37200","34.94088","0.03878"
"23590","141.50400","34.95189","0.04792"
"23612","141.63600","34.96289","0.05333"
"23634","141.76800","34.97388","0.04996"
"23656","141.90000","34.98483","0.04177"
"23678","142.03200","34.99583","0.04110"
"23700","142.16400","35.00689","0.05250"
"23722","142.29600","35.01783","0.05500"
"23744","142.42800","35.02884","0.04753"
"23766","142.56000","35.03989","0.04285"
"23788","142.69200","35.05095","0.04548"
"23810","142.82400","35.06195","0.05491"
"23832","142.95600","35.07290","0.05566"
"23854","143.08800","35.08390","0.04685"
"23876","143.22000","35.09490","0.04630"
"23898","143.35200","35.10590","0.05105"
"23920","143.48400","35.11684","0.05609"
"23942","143.61600","35.12785","0.05494"
"23964","143.74800","35.13890","0.04808"
"23986","143.88000","35.14991","0.04938"
"24008","144.01200","35.16091","0.05555"
"24030","144.14400","35.17191","0.05641"
"24052","144.27600","35.18291","0.05404"
"24074","144.40800","35.19391","0.05022"
"24096","144.54000","35.20485","0.05278"
"24118","144.67200","35.21585","0.05847"
"24140","144.80400","35.22691","0.05707"
"24162","144.93600","35.23792","0.05319"
"24184","145.06800","35.24886","0.05351"
"24206","145.20000","35.25980","0.05651"
"24228","145.33200","35.27092","0.05831"
"24250","145.46400","35.28192","0.05741"
"24272","145.59600","35.29286","0.05417"
"24294","145.72800","35.30381","0.05675"
"24316","145.86000","35.31493","0.05938"
"24338","145.99200","35.32593","0.05904"
"24360","146.12400","35.33693","0.05716"
"24382","146.25600","35.34787","0.05791"
"24404","146.38800","35.35887","0.05929"
"24426","146.52000","35.36993","0.06120"
"24448","146.65200","35.38087","0.05935"
"24470","146.78400","35.39182","0.05746"
"24492","146.91600","35.40287","0.05934"
"24514","147.04800","35.41388","0.06161"
"24536","147.18000","35.42488","0.06077"
"24558","147.31200","35.43588","0.05931"
"24580","147.44400","35.44688","0.05869"
"24602","147.57600","35.45794","0.06167"
"24624","147.70800","35.46894","0.06341"
"24646","147.84000","35.47989","0.06132"
"24668","147.97200","35.49089","0.05939"
"24690","148.10400","35.50195","0.06157"
"24712","148.23600","35.51289","0.06409"
"24734","148.36800","35.52389","0.06418"
"24756","148.50000","35.53489","0.06190"
"24778","148.63200","35.54583","0.06065"
"24800","148.76400","35.55689","0.06375"
"24822","148.89600","35.56784","0.06594"
"24844","149.02800","35.57890","0.06436"
"24866","149.16000","35.58990","0.06197"
"24888","149.29200","35.60096","0.06333"
"24910","149.42400","35.61190","0.06624"
"24932","149.55600","35.62290","0.06715"
"24954","149.68800","35.63390","0.06413"
"24976","149.82000","35.64491","0.06335"
"24998","149.95200","35.65585","0.06593"
"25020","150.08400","35.66685","0.06917"
"25042","150.21600","35.67785","0.06783"
"25064","150.34800","35.68891","0.06478"
"25086","150.48000","35.69985","0.06591"
"25108","150.61200","35.71085","0.06873"
"25130","150.74400","35.72191","0.07049"
"25152","150.87600","35.73291","0.06807"
"25174","151.00800","35.74392","0.06565"
"25196","151.14000","35.75492","0.06802"
"25218","151.27200","35.76598","0.07067"
"25240","151.40400","35.77692","0.07097"
"25262","151.53600","35.78786","0.06891"
"25284","151.66800","35.79892","0.06815"
"25306","151.80000","35.80992","0.07084"
"25328","151.93200","35.82092","0.07298"
"25350","152.06400","35.83193","0.07170"
"25372","152.19600","35.84287","0.06972"
"25394","152.32800","35.85393","0.07070"
"25416","152.46000","35.86493","0.07329"
"25438","152.59200","35.87587","0.07343"
"25460","152.72400","35.88687","0.07213"
"25482","152.85600","35.89799","0.07135"
"25504","152.98800","35.90887","0.07322"
"25526","153.12000","35.91988","0.07529"
"25548","153.25200","35.93082","0.07474"
"25570","153.38400","35.94188","0.07266"
"25592","153.51600","35.95294","0.07400"
"25614","153.64800","35.96388","0.07625"
"25636","153.78000","35.97482","0.07645"
"25658","153.91200","35.98594","0.07593"
"25680","154.04400","35.99689","0.07524"
"25702","154.17600","36.00795","0.07536"
"25724","154.30800","36.01883","0.07700"
"25746","154.44000","36.02995","0.07760"
"25768","154.57200","36.04095","0.07654"
"25790","154.70400","36.05189","0.07612"
"25812","154.83600","36.06283","0.07807"
"25834","154.96800","36.07383","0.07848"
"25856","155.10000","36.08490","0.07783"
"25878","155.23200","36.09584","0.07712"
"25900","155.36400","36.10684","0.07775"
"25922","155.49600","36.11790","0.07838"
"25944","155.62800","36.12890","0.07851"
"25966","155.76000","36.13990","0.07854"
"25988","155.89200","36.15084","0.07767"
"26010","156.02400","36.16191","0.07759"
"26032","156.15600","36.17297","0.07354"
"26054","156.28800","36.18397","0.07221"
"26076","156.42000","36.19485","-0.00844"
"26098","156.55200","36.20585","-0.00514"
"26120","156.68400","36.21685","-0.00181"
"26142","156.81600","36.22785","0.00094"
"26164","156.94800","36.23891","0.00240"
"26186","157.08000","36.24986","0.00294"
"26208","157.21200","36.26092","0.00317"
"26230","157.34400","36.27192","0.00229"
"26252","157.47600","36.28286","0.00218"
"26274","157.60800","36.29386","0.00098"
"26296","157.74000","36.30492","0.00059"
"26318","157.87200","36.31592","0.00073"
"26340","158.00400","36.32686","0.00159"
"26362","158.13600","36.33787","0.00105"
"26384","158.26800","36.34887","0.00149"
"26406","158.40000","36.35987","0.00156"
"26428","158.53200","36.37087","0.00178"
"26450","158.66400","36.38187","0.00188"
"26472","158.79600","36.39293","0.00194"
"26494","158.92800","36.40393","0.00164"
"26516","159.06000","36.41494","0.00127"
"26538","159.19200","36.42588","0.00166"
"26560","159.32400","36.43694","0.00156"
"26579","159.43400","36.44608","0.00180"