File: Trajectories_together/170225_1Specimen_RawData_4.csv
"","V1","V2","V3"
"1","End date","2/25/2017",""
"2","Specimen label","2AT_15",""
"3","Maximum Load","0.04883","N"
"4","Time","Extension","Load"
"5","(s)","(mm)","(N)"
"6","0.00000","0.00000","-0.00027"
"32","0.15600","0.00909","0.00050"
"58","0.31200","0.02565","0.00062"
"84","0.46800","0.03934","0.00068"
"110","0.62400","0.05220","0.00079"
"136","0.78000","0.06523","0.00043"
"162","0.93600","0.07826","0.00087"
"188","1.09200","0.09124","0.00083"
"214","1.24800","0.10421","0.00083"
"240","1.40400","0.11725","0.00143"
"266","1.56000","0.13016","0.00096"
"292","1.71600","0.14314","0.00122"
"318","1.87200","0.15617","0.00101"
"344","2.02800","0.16920","0.00070"
"370","2.18400","0.18218","0.00114"
"396","2.34000","0.19515","0.00135"
"422","2.49600","0.20825","0.00160"
"448","2.65200","0.22122","0.00202"
"474","2.80800","0.23414","0.00138"
"500","2.96400","0.24723","0.00150"
"526","3.12000","0.26020","0.00189"
"552","3.27600","0.27318","0.00160"
"578","3.43200","0.28615","0.00205"
"604","3.58800","0.29919","0.00145"
"630","3.74400","0.31216","0.00192"
"656","3.90000","0.32508","0.00181"
"682","4.05600","0.33817","0.00170"
"708","4.21200","0.35126","0.00205"
"734","4.36800","0.36412","0.00190"
"760","4.52400","0.37715","0.00182"
"786","4.68000","0.39019","0.00201"
"812","4.83600","0.40322","0.00242"
"838","4.99200","0.41619","0.00191"
"864","5.14800","0.42917","0.00261"
"890","5.30400","0.44220","0.00248"
"916","5.46000","0.45512","0.00242"
"942","5.61600","0.46815","0.00147"
"968","5.77200","0.48113","0.00200"
"994","5.92800","0.49416","0.00199"
"1020","6.08400","0.50713","0.00249"
"1046","6.24000","0.52023","0.00194"
"1072","6.39600","0.53326","0.00252"
"1098","6.55200","0.54618","0.00222"
"1124","6.70800","0.55915","0.00296"
"1150","6.86400","0.57219","0.00276"
"1176","7.02000","0.58516","0.00258"
"1202","7.17600","0.59813","0.00255"
"1228","7.33200","0.61117","0.00287"
"1254","7.48800","0.62420","0.00238"
"1280","7.64400","0.63718","0.00254"
"1306","7.80000","0.65021","0.00245"
"1332","7.95600","0.66319","0.00281"
"1358","8.11200","0.67610","0.00267"
"1384","8.26800","0.68919","0.00275"
"1410","8.42400","0.70217","0.00238"
"1436","8.58000","0.71520","0.00250"
"1462","8.73600","0.72812","0.00254"
"1488","8.89200","0.74121","0.00271"
"1514","9.04800","0.75419","0.00267"
"1540","9.20400","0.76716","0.00296"
"1566","9.36000","0.78019","0.00289"
"1592","9.51600","0.79317","0.00299"
"1618","9.67200","0.80620","0.00257"
"1644","9.82800","0.81918","0.00281"
"1670","9.98400","0.83227","0.00295"
"1696","10.14000","0.84518","0.00299"
"1722","10.29600","0.85816","0.00321"
"1748","10.45200","0.87119","0.00293"
"1774","10.60800","0.88423","0.00325"
"1800","10.76400","0.89720","0.00344"
"1826","10.92000","0.91018","0.00327"
"1852","11.07600","0.92327","0.00336"
"1878","11.23200","0.93618","0.00353"
"1904","11.38800","0.94916","0.00326"
"1930","11.54400","0.96219","0.00304"
"1956","11.70000","0.97529","0.00328"
"1982","11.85600","0.98820","0.00354"
"2008","12.01200","1.00118","0.00338"
"2034","12.16800","1.01421","0.00304"
"2060","12.32400","1.02718","0.00367"
"2086","12.48000","1.04016","0.00355"
"2112","12.63600","1.05319","0.00382"
"2138","12.79200","1.06623","0.00377"
"2164","12.94800","1.07914","0.00288"
"2190","13.10400","1.09212","0.00369"
"2216","13.26000","1.10521","0.00373"
"2242","13.41600","1.11824","0.00371"
"2268","13.57200","1.13116","0.00328"
"2294","13.72800","1.14419","0.00380"
"2320","13.88400","1.15723","0.00334"
"2346","14.04000","1.17014","0.00349"
"2372","14.19600","1.18318","0.00358"
"2398","14.35200","1.19615","0.00319"
"2424","14.50800","1.20918","0.00347"
"2450","14.66400","1.22210","0.00390"
"2476","14.82000","1.23519","0.00399"
"2502","14.97600","1.24823","0.00382"
"2528","15.13200","1.26120","0.00328"
"2554","15.28800","1.27423","0.00343"
"2580","15.44400","1.28727","0.00412"
"2606","15.60000","1.30018","0.00335"
"2632","15.75600","1.31316","0.00282"
"2658","15.91200","1.32619","0.00398"
"2684","16.06800","1.33929","0.00349"
"2710","16.22400","1.35220","0.00447"
"2736","16.38000","1.36523","0.00371"
"2762","16.53600","1.37821","0.00351"
"2788","16.69200","1.39112","0.00376"
"2814","16.84800","1.40416","0.00354"
"2840","17.00400","1.41725","0.00358"
"2866","17.16000","1.43023","0.00358"
"2892","17.31600","1.44320","0.00395"
"2918","17.47200","1.45623","0.00354"
"2944","17.62800","1.46921","0.00383"
"2970","17.78400","1.48218","0.00325"
"2996","17.94000","1.49516","0.00357"
"3022","18.09600","1.50819","0.00437"
"3048","18.25200","1.52117","0.00381"
"3074","18.40800","1.53414","0.00365"
"3100","18.56400","1.54723","0.00340"
"3126","18.72000","1.56021","0.00408"
"3152","18.87600","1.57318","0.00381"
"3178","19.03200","1.58622","0.00396"
"3204","19.18800","1.59925","0.00428"
"3230","19.34400","1.61222","0.00440"
"3256","19.50000","1.62508","0.00384"
"3282","19.65600","1.63823","0.00355"
"3308","19.81200","1.65121","0.00456"
"3334","19.96800","1.66418","0.00390"
"3360","20.12400","1.67716","0.00454"
"3386","20.28000","1.69025","0.00371"
"3412","20.43600","1.70316","0.00354"
"3438","20.59200","1.71620","0.00391"
"3464","20.74800","1.72923","0.00378"
"3490","20.90400","1.74221","0.00365"
"3516","21.06000","1.75518","0.00434"
"3542","21.21600","1.76816","0.00453"
"3568","21.37200","1.78119","0.00371"
"3594","21.52800","1.79416","0.00452"
"3620","21.68400","1.80708","0.00415"
"3646","21.84000","1.82017","0.00407"
"3672","21.99600","1.83321","0.00458"
"3698","22.15200","1.84618","0.00414"
"3724","22.30800","1.85922","0.00451"
"3750","22.46400","1.87225","0.00425"
"3776","22.62000","1.88522","0.00395"
"3802","22.77600","1.89820","0.00405"
"3828","22.93200","1.91117","0.00455"
"3854","23.08800","1.92421","0.00382"
"3880","23.24400","1.93718","0.00390"
"3906","23.40000","1.95022","0.00441"
"3932","23.55600","1.96325","0.00406"
"3958","23.71200","1.97616","0.00383"
"3984","23.86800","1.98914","0.00428"
"4010","24.02400","2.00217","0.00337"
"4036","24.18000","2.01521","0.00358"
"4062","24.33600","2.02818","0.00434"
"4088","24.49200","2.04115","0.00403"
"4114","24.64800","2.05419","0.00476"
"4140","24.80400","2.06716","0.00443"
"4166","24.96000","2.08014","0.00465"
"4192","25.11600","2.09317","0.00490"
"4218","25.27200","2.10615","0.00458"
"4244","25.42800","2.11912","0.00433"
"4270","25.58400","2.13221","0.00367"
"4296","25.74000","2.14519","0.00438"
"4322","25.89600","2.15816","0.00354"
"4348","26.05200","2.17120","0.00451"
"4374","26.20800","2.18423","0.00457"
"4400","26.36400","2.19721","0.00373"
"4426","26.52000","2.21018","0.00375"
"4452","26.67600","2.22321","0.00414"
"4478","26.83200","2.23619","0.00375"
"4504","26.98800","2.24916","0.00392"
"4530","27.14400","2.26220","0.00466"
"4556","27.30000","2.27517","0.00472"
"4582","27.45600","2.28815","0.00419"
"4608","27.61200","2.30112","0.00468"
"4634","27.76800","2.31421","0.00415"
"4660","27.92400","2.32719","0.00441"
"4686","28.08000","2.34016","0.00430"
"4712","28.23600","2.35320","0.00384"
"4738","28.39200","2.36617","0.00391"
"4764","28.54800","2.37914","0.00465"
"4790","28.70400","2.39212","0.00473"
"4816","28.86000","2.40521","0.00445"
"4842","29.01600","2.41819","0.00447"
"4868","29.17200","2.43116","0.00424"
"4894","29.32800","2.44414","0.00391"
"4920","29.48400","2.45717","0.00415"
"4946","29.64000","2.47014","0.00417"
"4972","29.79600","2.48318","0.00443"
"4998","29.95200","2.49621","0.00415"
"5024","30.10800","2.50919","0.00438"
"5050","30.26400","2.52210","0.00454"
"5076","30.42000","2.53526","0.00402"
"5102","30.57600","2.54823","0.00462"
"5128","30.73200","2.56114","0.00505"
"5154","30.88800","2.57418","0.00465"
"5180","31.04400","2.58715","0.00423"
"5206","31.20000","2.60025","0.00484"
"5232","31.35600","2.61316","0.00487"
"5258","31.51200","2.62620","0.00423"
"5284","31.66800","2.63923","0.00426"
"5310","31.82400","2.65214","0.00477"
"5336","31.98000","2.66518","0.00470"
"5362","32.13600","2.67821","0.00441"
"5388","32.29200","2.69119","0.00398"
"5414","32.44800","2.70410","0.00476"
"5440","32.60400","2.71720","0.00405"
"5466","32.76000","2.73017","0.00432"
"5492","32.91600","2.74314","0.00406"
"5518","33.07200","2.75618","0.00465"
"5544","33.22800","2.76921","0.00484"
"5570","33.38400","2.78225","0.00457"
"5596","33.54000","2.79516","0.00470"
"5622","33.69600","2.80825","0.00467"
"5648","33.85200","2.82117","0.00490"
"5674","34.00800","2.83414","0.00455"
"5700","34.16400","2.84718","0.00417"
"5726","34.32000","2.86021","0.00504"
"5752","34.47600","2.87313","0.00479"
"5778","34.63200","2.88616","0.00483"
"5804","34.78800","2.89925","0.00463"
"5830","34.94400","2.91223","0.00486"
"5856","35.10000","2.92514","0.00499"
"5882","35.25600","2.93818","0.00457"
"5908","35.41200","2.95121","0.00451"
"5934","35.56800","2.96419","0.00456"
"5960","35.72400","2.97716","0.00483"
"5986","35.88000","2.99019","0.00464"
"6012","36.03600","3.00317","0.00459"
"6038","36.19200","3.01608","0.00474"
"6064","36.34800","3.02918","0.00465"
"6090","36.50400","3.04221","0.00493"
"6116","36.66000","3.05519","0.00449"
"6142","36.81600","3.06816","0.00470"
"6168","36.97200","3.08119","0.00479"
"6194","37.12800","3.09417","0.00484"
"6220","37.28400","3.10714","0.00532"
"6246","37.44000","3.12024","0.00488"
"6272","37.59600","3.13321","0.00509"
"6298","37.75200","3.14618","0.00528"
"6324","37.90800","3.15916","0.00500"
"6350","38.06400","3.17219","0.00430"
"6376","38.22000","3.18517","0.00472"
"6402","38.37600","3.19820","0.00459"
"6428","38.53200","3.21124","0.00501"
"6454","38.68800","3.22427","0.00557"
"6480","38.84400","3.23712","0.00470"
"6506","39.00000","3.25016","0.00518"
"6532","39.15600","3.26319","0.00467"
"6558","39.31200","3.27617","0.00526"
"6584","39.46800","3.28920","0.00523"
"6610","39.62400","3.30218","0.00485"
"6636","39.78000","3.31521","0.00471"
"6662","39.93600","3.32812","0.00486"
"6688","40.09200","3.34122","0.00512"
"6714","40.24800","3.35419","0.00554"
"6740","40.40400","3.36717","0.00562"
"6766","40.56000","3.38014","0.00591"
"6792","40.71600","3.39324","0.00506"
"6818","40.87200","3.40621","0.00552"
"6844","41.02800","3.41918","0.00523"
"6870","41.18400","3.43222","0.00491"
"6896","41.34000","3.44519","0.00481"
"6922","41.49600","3.45817","0.00463"
"6948","41.65200","3.47114","0.00490"
"6974","41.80800","3.48423","0.00489"
"7000","41.96400","3.49721","0.00461"
"7026","42.12000","3.51018","0.00459"
"7052","42.27600","3.52328","0.00461"
"7078","42.43200","3.53619","0.00511"
"7104","42.58800","3.54917","0.00511"
"7130","42.74400","3.56214","0.00559"
"7156","42.90000","3.57518","0.00538"
"7182","43.05600","3.58815","0.00575"
"7208","43.21200","3.60112","0.00474"
"7234","43.36800","3.61416","0.00510"
"7260","43.52400","3.62719","0.00578"
"7286","43.68000","3.64017","0.00551"
"7312","43.83600","3.65320","0.00565"
"7338","43.99200","3.66623","0.00556"
"7364","44.14800","3.67921","0.00537"
"7390","44.30400","3.69218","0.00606"
"7416","44.46000","3.70522","0.00532"
"7442","44.61600","3.71819","0.00572"
"7468","44.77200","3.73123","0.00567"
"7494","44.92800","3.74420","0.00510"
"7520","45.08400","3.75723","0.00550"
"7546","45.24000","3.77015","0.00532"
"7572","45.39600","3.78318","0.00572"
"7598","45.55200","3.79622","0.00540"
"7624","45.70800","3.80919","0.00514"
"7650","45.86400","3.82217","0.00546"
"7676","46.02000","3.83526","0.00473"
"7702","46.17600","3.84823","0.00551"
"7728","46.33200","3.86115","0.00531"
"7754","46.48800","3.87418","0.00549"
"7780","46.64400","3.88716","0.00604"
"7806","46.80000","3.90019","0.00592"
"7832","46.95600","3.91311","0.00575"
"7858","47.11200","3.92614","0.00565"
"7884","47.26800","3.93923","0.00568"
"7910","47.42400","3.95215","0.00586"
"7936","47.58000","3.96518","0.00497"
"7962","47.73600","3.97828","0.00518"
"7988","47.89200","3.99119","0.00581"
"8014","48.04800","4.00416","0.00552"
"8040","48.20400","4.01720","0.00522"
"8066","48.36000","4.03023","0.00547"
"8092","48.51600","4.04321","0.00536"
"8118","48.67200","4.05618","0.00480"
"8144","48.82800","4.06922","0.00525"
"8170","48.98400","4.08219","0.00533"
"8196","49.14000","4.09516","0.00587"
"8222","49.29600","4.10826","0.00582"
"8248","49.45200","4.12123","0.00535"
"8274","49.60800","4.13415","0.00557"
"8300","49.76400","4.14718","0.00542"
"8326","49.92000","4.16016","0.00653"
"8352","50.07600","4.17313","0.00603"
"8378","50.23200","4.18610","0.00611"
"8404","50.38800","4.19914","0.00594"
"8430","50.54400","4.21217","0.00591"
"8456","50.70000","4.22515","0.00539"
"8482","50.85600","4.23818","0.00593"
"8508","51.01200","4.25121","0.00613"
"8534","51.16800","4.26419","0.00508"
"8560","51.32400","4.27722","0.00517"
"8586","51.48000","4.29020","0.00540"
"8612","51.63600","4.30317","0.00584"
"8638","51.79200","4.31615","0.00591"
"8664","51.94800","4.32924","0.00570"
"8690","52.10400","4.34221","0.00568"
"8716","52.26000","4.35519","0.00547"
"8742","52.41600","4.36816","0.00592"
"8768","52.57200","4.38120","0.00594"
"8794","52.72800","4.39417","0.00590"
"8820","52.88400","4.40715","0.00613"
"8846","53.04000","4.42024","0.00568"
"8872","53.19600","4.43321","0.00640"
"8898","53.35200","4.44613","0.00523"
"8924","53.50800","4.45916","0.00625"
"8950","53.66400","4.47220","0.00608"
"8976","53.82000","4.48517","0.00600"
"9002","53.97600","4.49809","0.00583"
"9028","54.13200","4.51124","0.00609"
"9054","54.28800","4.52421","0.00539"
"9080","54.44400","4.53719","0.00583"
"9106","54.60000","4.55022","0.00546"
"9132","54.75600","4.56320","0.00556"
"9158","54.91200","4.57617","0.00541"
"9184","55.06800","4.58915","0.00555"
"9210","55.22400","4.60218","0.00598"
"9236","55.38000","4.61515","0.00535"
"9262","55.53600","4.62813","0.00661"
"9288","55.69200","4.64116","0.00547"
"9314","55.84800","4.65426","0.00578"
"9340","56.00400","4.66717","0.00595"
"9366","56.16000","4.68015","0.00516"
"9392","56.31600","4.69318","0.00573"
"9418","56.47200","4.70621","0.00575"
"9444","56.62800","4.71919","0.00580"
"9470","56.78400","4.73222","0.00562"
"9496","56.94000","4.74526","0.00528"
"9522","57.09600","4.75817","0.00609"
"9548","57.25200","4.77114","0.00559"
"9574","57.40800","4.78418","0.00608"
"9600","57.56400","4.79721","0.00581"
"9626","57.72000","4.81013","0.00635"
"9652","57.87600","4.82322","0.00626"
"9678","58.03200","4.83620","0.00593"
"9704","58.18800","4.84917","0.00599"
"9730","58.34400","4.86220","0.00595"
"9756","58.50000","4.87524","0.00566"
"9782","58.65600","4.88821","0.00563"
"9808","58.81200","4.90119","0.00618"
"9834","58.96800","4.91422","0.00654"
"9860","59.12400","4.92720","0.00603"
"9886","59.28000","4.94017","0.00614"
"9912","59.43600","4.95320","0.00685"
"9938","59.59200","4.96618","0.00621"
"9964","59.74800","4.97915","0.00607"
"9990","59.90400","4.99213","0.00578"
"10016","60.06000","5.00516","0.00568"
"10042","60.21600","5.01819","0.00565"
"10068","60.37200","5.03117","0.00614"
"10094","60.52800","5.04420","0.00636"
"10120","60.68400","5.05718","0.00592"
"10146","60.84000","5.07015","0.00613"
"10172","60.99600","5.08313","0.00612"
"10198","61.15200","5.09616","0.00639"
"10224","61.30800","5.10919","0.00645"
"10250","61.46400","5.12211","0.00620"
"10276","61.62000","5.13526","0.00686"
"10302","61.77600","5.14824","0.00719"
"10328","61.93200","5.16121","0.00682"
"10354","62.08800","5.17419","0.00595"
"10380","62.24400","5.18722","0.00660"
"10406","62.40000","5.20025","0.00695"
"10432","62.55600","5.21311","0.00656"
"10458","62.71200","5.22620","0.00644"
"10484","62.86800","5.23918","0.00732"
"10510","63.02400","5.25215","0.00685"
"10536","63.18000","5.26513","0.00669"
"10562","63.33600","5.27822","0.00646"
"10588","63.49200","5.29119","0.00671"
"10614","63.64800","5.30417","0.00664"
"10640","63.80400","5.31720","0.00678"
"10666","63.96000","5.33024","0.00670"
"10692","64.11600","5.34315","0.00674"
"10718","64.27200","5.35613","0.00655"
"10744","64.42800","5.36916","0.00606"
"10770","64.58400","5.38213","0.00659"
"10796","64.74000","5.39511","0.00688"
"10822","64.89600","5.40820","0.00694"
"10848","65.05200","5.42124","0.00673"
"10874","65.20800","5.43415","0.00603"
"10900","65.36400","5.44719","0.00622"
"10926","65.52000","5.46016","0.00670"
"10952","65.67600","5.47319","0.00623"
"10978","65.83200","5.48611","0.00652"
"11004","65.98800","5.49920","0.00649"
"11030","66.14400","5.51218","0.00675"
"11056","66.30000","5.52515","0.00650"
"11082","66.45600","5.53818","0.00673"
"11108","66.61200","5.55116","0.00623"
"11134","66.76800","5.56419","0.00692"
"11160","66.92400","5.57717","0.00573"
"11186","67.08000","5.59026","0.00644"
"11212","67.23600","5.60324","0.00646"
"11238","67.39200","5.61615","0.00649"
"11264","67.54800","5.62918","0.00683"
"11290","67.70400","5.64216","0.00640"
"11316","67.86000","5.65519","0.00726"
"11342","68.01600","5.66817","0.00702"
"11368","68.17200","5.68120","0.00634"
"11394","68.32800","5.69412","0.00654"
"11420","68.48400","5.70715","0.00633"
"11446","68.64000","5.72024","0.00735"
"11472","68.79600","5.73328","0.00657"
"11498","68.95200","5.74619","0.00661"
"11524","69.10800","5.75923","0.00724"
"11550","69.26400","5.77220","0.00683"
"11576","69.42000","5.78518","0.00681"
"11602","69.57600","5.79815","0.00643"
"11628","69.73200","5.81118","0.00685"
"11654","69.88800","5.82422","0.00718"
"11680","70.04400","5.83713","0.00666"
"11706","70.20000","5.85023","0.00651"
"11732","70.35600","5.86314","0.00697"
"11758","70.51200","5.87617","0.00686"
"11784","70.66800","5.88915","0.00659"
"11810","70.82400","5.90230","0.00652"
"11836","70.98000","5.91522","0.00677"
"11862","71.13600","5.92813","0.00663"
"11888","71.29200","5.94117","0.00660"
"11914","71.44800","5.95420","0.00693"
"11940","71.60400","5.96717","0.00627"
"11966","71.76000","5.98015","0.00616"
"11992","71.91600","5.99318","0.00654"
"12018","72.07200","6.00616","0.00670"
"12044","72.22800","6.01913","0.00613"
"12070","72.38400","6.03217","0.00649"
"12096","72.54000","6.04514","0.00650"
"12122","72.69600","6.05811","0.00584"
"12148","72.85200","6.07115","0.00609"
"12174","73.00800","6.08424","0.00678"
"12200","73.16400","6.09722","0.00658"
"12226","73.32000","6.11013","0.00672"
"12252","73.47600","6.12323","0.00632"
"12278","73.63200","6.13620","0.00604"
"12304","73.78800","6.14917","0.00712"
"12330","73.94400","6.16215","0.00728"
"12356","74.10000","6.17518","0.00725"
"12382","74.25600","6.18822","0.00736"
"12408","74.41200","6.20119","0.00658"
"12434","74.56800","6.21422","0.00700"
"12460","74.72400","6.22726","0.00681"
"12486","74.88000","6.24017","0.00687"
"12512","75.03600","6.25321","0.00701"
"12538","75.19200","6.26624","0.00714"
"12564","75.34800","6.27922","0.00637"
"12590","75.50400","6.29219","0.00699"
"12616","75.66000","6.30517","0.00636"
"12642","75.81600","6.31814","0.00712"
"12668","75.97200","6.33117","0.00651"
"12694","76.12800","6.34421","0.00719"
"12720","76.28400","6.35724","0.00689"
"12746","76.44000","6.37022","0.00646"
"12772","76.59600","6.38313","0.00711"
"12798","76.75200","6.39622","0.00691"
"12824","76.90800","6.40914","0.00715"
"12850","77.06400","6.42217","0.00698"
"12876","77.22000","6.43515","0.00732"
"12902","77.37600","6.44818","0.00656"
"12928","77.53200","6.46116","0.00714"
"12954","77.68800","6.47419","0.00687"
"12980","77.84400","6.48722","0.00764"
"13006","78.00000","6.50020","0.00705"
"13032","78.15600","6.51317","0.00626"
"13058","78.31200","6.52621","0.00729"
"13084","78.46800","6.53924","0.00704"
"13110","78.62400","6.55216","0.00762"
"13136","78.78000","6.56519","0.00685"
"13162","78.93600","6.57816","0.00718"
"13188","79.09200","6.59114","0.00699"
"13214","79.24800","6.60411","0.00708"
"13240","79.40400","6.61721","0.00734"
"13266","79.56000","6.63024","0.00723"
"13292","79.71600","6.64321","0.00732"
"13318","79.87200","6.65625","0.00727"
"13344","80.02800","6.66922","0.00756"
"13370","80.18400","6.68220","0.00700"
"13396","80.34000","6.69511","0.00778"
"13422","80.49600","6.70827","0.00743"
"13448","80.65200","6.72124","0.00715"
"13474","80.80800","6.73421","0.00823"
"13500","80.96400","6.74719","0.00741"
"13526","81.12000","6.76022","0.00811"
"13552","81.27600","6.77320","0.00743"
"13578","81.43200","6.78617","0.00719"
"13604","81.58800","6.79921","0.00723"
"13630","81.74400","6.81224","0.00742"
"13656","81.90000","6.82516","0.00784"
"13682","82.05600","6.83819","0.00734"
"13708","82.21200","6.85122","0.00735"
"13734","82.36800","6.86414","0.00763"
"13760","82.52400","6.87717","0.00782"
"13786","82.68000","6.89015","0.00711"
"13812","82.83600","6.90318","0.00754"
"13838","82.99200","6.91615","0.00743"
"13864","83.14800","6.92919","0.00728"
"13890","83.30400","6.94216","0.00731"
"13916","83.46000","6.95514","0.00802"
"13942","83.61600","6.96817","0.00750"
"13968","83.77200","6.98121","0.00763"
"13994","83.92800","6.99418","0.00816"
"14020","84.08400","7.00715","0.00760"
"14046","84.24000","7.02019","0.00821"
"14072","84.39600","7.03322","0.00841"
"14098","84.55200","7.04620","0.00853"
"14124","84.70800","7.05917","0.00808"
"14150","84.86400","7.07221","0.00787"
"14176","85.02000","7.08518","0.00818"
"14202","85.17600","7.09821","0.00815"
"14228","85.33200","7.11125","0.00834"
"14254","85.48800","7.12416","0.00747"
"14280","85.64400","7.13720","0.00792"
"14306","85.80000","7.15017","0.00854"
"14332","85.95600","7.16320","0.00859"
"14358","86.11200","7.17612","0.00847"
"14384","86.26800","7.18915","0.00818"
"14410","86.42400","7.20219","0.00869"
"14436","86.58000","7.21522","0.00823"
"14462","86.73600","7.22820","0.00865"
"14488","86.89200","7.24123","0.00876"
"14514","87.04800","7.25420","0.00869"
"14540","87.20400","7.26724","0.00903"
"14566","87.36000","7.28021","0.00865"
"14592","87.51600","7.29319","0.00905"
"14618","87.67200","7.30616","0.00899"
"14644","87.82800","7.31914","0.00918"
"14670","87.98400","7.33217","0.00898"
"14696","88.14000","7.34520","0.00886"
"14722","88.29600","7.35818","0.00911"
"14748","88.45200","7.37115","0.00926"
"14774","88.60800","7.38419","0.00945"
"14800","88.76400","7.39716","0.00933"
"14826","88.92000","7.41014","0.00906"
"14852","89.07600","7.42323","0.00903"
"14878","89.23200","7.43620","0.00915"
"14904","89.38800","7.44918","0.00946"
"14930","89.54400","7.46215","0.00936"
"14956","89.70000","7.47519","0.01025"
"14982","89.85600","7.48816","0.00953"
"15008","90.01200","7.50114","0.00925"
"15034","90.16800","7.51417","0.00946"
"15060","90.32400","7.52726","0.00995"
"15086","90.48000","7.54018","0.00949"
"15112","90.63600","7.55321","0.01001"
"15138","90.79200","7.56625","0.01033"
"15164","90.94800","7.57916","0.01017"
"15190","91.10400","7.59220","0.01047"
"15216","91.26000","7.60517","0.00991"
"15242","91.41600","7.61820","0.01035"
"15268","91.57200","7.63112","0.00993"
"15294","91.72800","7.64415","0.00992"
"15320","91.88400","7.65719","0.01006"
"15346","92.04000","7.67016","0.01019"
"15372","92.19600","7.68313","0.01007"
"15398","92.35200","7.69623","0.01045"
"15424","92.50800","7.70920","0.01002"
"15450","92.66400","7.72218","0.01016"
"15476","92.82000","7.73521","0.01100"
"15502","92.97600","7.74819","0.01030"
"15528","93.13200","7.76116","0.01043"
"15554","93.28800","7.77413","0.00994"
"15580","93.44400","7.78717","0.01037"
"15606","93.60000","7.80014","0.01059"
"15632","93.75600","7.81312","0.01000"
"15658","93.91200","7.82621","0.01008"
"15684","94.06800","7.83919","0.00951"
"15710","94.22400","7.85216","0.00991"
"15736","94.38000","7.86519","0.01002"
"15762","94.53600","7.87817","0.00975"
"15788","94.69200","7.89120","0.01005"
"15814","94.84800","7.90412","0.01027"
"15840","95.00400","7.91715","0.01042"
"15866","95.16000","7.93018","0.01003"
"15892","95.31600","7.94316","0.01028"
"15918","95.47200","7.95619","0.01105"
"15944","95.62800","7.96923","0.01088"
"15970","95.78400","7.98220","0.01056"
"15996","95.94000","7.99512","0.01069"
"16022","96.09600","8.00821","0.01126"
"16048","96.25200","8.02118","0.01052"
"16074","96.40800","8.03416","0.01133"
"16100","96.56400","8.04719","0.01083"
"16126","96.72000","8.06017","0.01106"
"16152","96.87600","8.07314","0.01151"
"16178","97.03200","8.08612","0.01127"
"16204","97.18800","8.09921","0.01171"
"16230","97.34400","8.11218","0.01136"
"16256","97.50000","8.12516","0.01094"
"16282","97.65600","8.13819","0.01174"
"16308","97.81200","8.15123","0.01168"
"16334","97.96800","8.16420","0.01147"
"16360","98.12400","8.17712","0.01155"
"16386","98.28000","8.19015","0.01201"
"16412","98.43600","8.20318","0.01181"
"16438","98.59200","8.21610","0.01211"
"16464","98.74800","8.22919","0.01187"
"16490","98.90400","8.24223","0.01214"
"16516","99.06000","8.25514","0.01237"
"16542","99.21600","8.26818","0.01207"
"16568","99.37200","8.28121","0.01212"
"16594","99.52800","8.29418","0.01292"
"16620","99.68400","8.30716","0.01258"
"16646","99.84000","8.32019","0.01277"
"16672","99.99600","8.33323","0.01283"
"16698","100.15200","8.34614","0.01283"
"16724","100.30800","8.35917","0.01304"
"16750","100.46400","8.37215","0.01256"
"16776","100.62000","8.38518","0.01313"
"16802","100.77600","8.39816","0.01261"
"16828","100.93200","8.41119","0.01310"
"16854","101.08800","8.42417","0.01299"
"16880","101.24400","8.43714","0.01350"
"16906","101.40000","8.45017","0.01340"
"16932","101.55600","8.46321","0.01381"
"16958","101.71200","8.47618","0.01309"
"16984","101.86800","8.48916","0.01384"
"17010","102.02400","8.50219","0.01417"
"17036","102.18000","8.51522","0.01421"
"17062","102.33600","8.52814","0.01416"
"17088","102.49200","8.54117","0.01383"
"17114","102.64800","8.55421","0.01452"
"17140","102.80400","8.56718","0.01459"
"17166","102.96000","8.58016","0.01396"
"17192","103.11600","8.59325","0.01503"
"17218","103.27200","8.60623","0.01517"
"17244","103.42800","8.61920","0.01466"
"17270","103.58400","8.63217","0.01506"
"17296","103.74000","8.64521","0.01484"
"17322","103.89600","8.65818","0.01556"
"17348","104.05200","8.67116","0.01534"
"17374","104.20800","8.68419","0.01535"
"17400","104.36400","8.69717","0.01535"
"17426","104.52000","8.71014","0.01586"
"17452","104.67600","8.72329","0.01578"
"17478","104.83200","8.73621","0.01571"
"17504","104.98800","8.74918","0.01595"
"17530","105.14400","8.76216","0.01597"
"17556","105.30000","8.77519","0.01657"
"17582","105.45600","8.78822","0.01607"
"17608","105.61200","8.80114","0.01617"
"17634","105.76800","8.81423","0.01661"
"17660","105.92400","8.82721","0.01633"
"17686","106.08000","8.84012","0.01705"
"17712","106.23600","8.85316","0.01729"
"17738","106.39200","8.86625","0.01704"
"17764","106.54800","8.87922","0.01754"
"17790","106.70400","8.89214","0.01714"
"17816","106.86000","8.90529","0.01744"
"17842","107.01600","8.91821","0.01785"
"17868","107.17200","8.93118","0.01746"
"17894","107.32800","8.94416","0.01789"
"17920","107.48400","8.95719","0.01814"
"17946","107.64000","8.97016","0.01863"
"17972","107.79600","8.98314","0.01854"
"17998","107.95200","8.99617","0.01890"
"18024","108.10800","9.00921","0.01865"
"18050","108.26400","9.02218","0.01845"
"18076","108.42000","9.03521","0.01936"
"18102","108.57600","9.04825","0.01930"
"18128","108.73200","9.06116","0.01944"
"18154","108.88800","9.07414","0.01989"
"18180","109.04400","9.08717","0.02051"
"18206","109.20000","9.10021","0.02013"
"18232","109.35600","9.11312","0.02018"
"18258","109.51200","9.12621","0.01986"
"18284","109.66800","9.13925","0.02020"
"18310","109.82400","9.15216","0.02079"
"18336","109.98000","9.16520","0.02073"
"18362","110.13600","9.17823","0.02146"
"18388","110.29200","9.19121","0.02130"
"18414","110.44800","9.20418","0.02138"
"18440","110.60400","9.21721","0.02141"
"18466","110.76000","9.23019","0.02197"
"18492","110.91600","9.24316","0.02243"
"18518","111.07200","9.25614","0.02215"
"18544","111.22800","9.26917","0.02258"
"18570","111.38400","9.28215","0.02257"
"18596","111.54000","9.29518","0.02265"
"18622","111.69600","9.30821","0.02292"
"18648","111.85200","9.32119","0.02307"
"18674","112.00800","9.33416","0.02325"
"18700","112.16400","9.34720","0.02326"
"18726","112.32000","9.36023","0.02305"
"18752","112.47600","9.37315","0.02270"
"18778","112.63200","9.38618","0.02244"
"18804","112.78800","9.39921","0.02067"
"18830","112.94400","9.41225","0.02013"
"18856","113.10000","9.42516","0.01957"
"18882","113.25600","9.43820","0.01887"
"18908","113.41200","9.45117","0.01872"
"18934","113.56800","9.46414","0.01882"
"18960","113.72400","9.47718","0.01958"
"18986","113.88000","9.49027","0.01963"
"19012","114.03600","9.50319","0.01894"
"19038","114.19200","9.51616","0.01902"
"19064","114.34800","9.52920","0.01952"
"19090","114.50400","9.54217","0.02005"
"19116","114.66000","9.55515","0.01994"
"19142","114.81600","9.56812","0.02059"
"19168","114.97200","9.58121","0.02053"
"19194","115.12800","9.59413","0.02121"
"19220","115.28400","9.60716","0.02064"
"19246","115.44000","9.62020","0.02129"
"19272","115.59600","9.63323","0.02149"
"19298","115.75200","9.64614","0.02204"
"19324","115.90800","9.65918","0.02166"
"19350","116.06400","9.67221","0.02255"
"19376","116.22000","9.68519","0.02240"
"19402","116.37600","9.69810","0.02214"
"19428","116.53200","9.71120","0.02359"
"19454","116.68800","9.72423","0.02291"
"19480","116.84400","9.73714","0.02299"
"19506","117.00000","9.75018","0.02271"
"19532","117.15600","9.76315","0.02324"
"19558","117.31200","9.77619","0.02380"
"19584","117.46800","9.78916","0.02352"
"19610","117.62400","9.80219","0.02314"
"19636","117.78000","9.81523","0.02419"
"19662","117.93600","9.82814","0.02431"
"19688","118.09200","9.84118","0.02373"
"19714","118.24800","9.85421","0.02399"
"19740","118.40400","9.86719","0.02435"
"19766","118.56000","9.88010","0.02412"
"19792","118.71600","9.89319","0.02430"
"19818","118.87200","9.90617","0.02326"
"19844","119.02800","9.91920","0.02424"
"19870","119.18400","9.93218","0.02415"
"19896","119.34000","9.94521","0.02354"
"19922","119.49600","9.95819","0.02368"
"19948","119.65200","9.97116","0.02349"
"19974","119.80800","9.98425","0.02355"
"20000","119.96400","9.99711","0.02390"
"20026","120.12000","10.01014","0.02329"
"20052","120.27600","10.02318","0.02403"
"20078","120.43200","10.03621","0.02421"
"20104","120.58800","10.04912","0.02477"
"20130","120.74400","10.06216","0.02446"
"20156","120.90000","10.07519","0.02514"
"20182","121.05600","10.08817","0.02489"
"20208","121.21200","10.10114","0.02562"
"20234","121.36800","10.11418","0.02527"
"20260","121.52400","10.12721","0.02624"
"20286","121.68000","10.14012","0.02585"
"20312","121.83600","10.15316","0.02605"
"20338","121.99200","10.16619","0.02637"
"20364","122.14800","10.17917","0.02617"
"20390","122.30400","10.19208","0.02459"
"20416","122.46000","10.20524","0.02518"
"20442","122.61600","10.21827","0.02576"
"20468","122.77200","10.23118","0.02527"
"20494","122.92800","10.24422","0.02613"
"20520","123.08400","10.25725","0.02607"
"20546","123.24000","10.27017","0.02708"
"20572","123.39600","10.28314","0.02698"
"20598","123.55200","10.29618","0.02718"
"20624","123.70800","10.30915","0.02771"
"20650","123.86400","10.32212","0.02845"
"20676","124.02000","10.33516","0.02843"
"20702","124.17600","10.34819","0.02872"
"20728","124.33200","10.36117","0.02981"
"20754","124.48800","10.37414","0.02949"
"20780","124.64400","10.38718","0.02976"
"20806","124.80000","10.40015","0.03034"
"20832","124.95600","10.41312","0.03052"
"20858","125.11200","10.42616","0.03114"
"20884","125.26800","10.43925","0.03089"
"20910","125.42400","10.45211","0.03072"
"20936","125.58000","10.46514","0.03198"
"20962","125.73600","10.47818","0.03237"
"20988","125.89200","10.49121","0.03252"
"21014","126.04800","10.50412","0.03216"
"21040","126.20400","10.51722","0.03291"
"21066","126.36000","10.53025","0.03347"
"21092","126.51600","10.54317","0.03350"
"21118","126.67200","10.55620","0.03298"
"21144","126.82800","10.56918","0.03342"
"21170","126.98400","10.58221","0.03353"
"21196","127.14000","10.59512","0.03423"
"21222","127.29600","10.60816","0.03459"
"21248","127.45200","10.62119","0.03502"
"21274","127.60800","10.63417","0.03524"
"21300","127.76400","10.64720","0.03499"
"21326","127.92000","10.66023","0.03502"
"21352","128.07600","10.67321","0.03568"
"21378","128.23200","10.68618","0.03633"
"21404","128.38800","10.69922","0.03644"
"21430","128.54400","10.71219","0.03638"
"21456","128.70000","10.72517","0.03705"
"21482","128.85600","10.73814","0.03613"
"21508","129.01200","10.75117","0.03671"
"21534","129.16800","10.76415","0.03645"
"21560","129.32400","10.77712","0.03686"
"21586","129.48000","10.79022","0.03711"
"21612","129.63600","10.80319","0.03675"
"21638","129.79200","10.81611","0.03682"
"21664","129.94800","10.82920","0.03665"
"21690","130.10400","10.84223","0.03675"
"21716","130.26000","10.85521","0.03690"
"21742","130.41600","10.86818","0.03669"
"21768","130.57200","10.88122","0.03672"
"21794","130.72800","10.89419","0.03673"
"21820","130.88400","10.90711","0.03657"
"21846","131.04000","10.92020","0.03597"
"21872","131.19600","10.93323","0.03604"
"21898","131.35200","10.94615","0.03611"
"21924","131.50800","10.95918","0.03664"
"21950","131.66400","10.97222","0.03673"
"21976","131.82000","10.98519","0.03720"
"22002","131.97600","10.99811","0.03655"
"22028","132.13200","11.01126","0.03657"
"22054","132.28800","11.02423","0.03712"
"22080","132.44400","11.03721","0.03752"
"22106","132.60000","11.05024","0.03743"
"22132","132.75600","11.06322","0.03716"
"22158","132.91200","11.07619","0.03736"
"22184","133.06800","11.08916","0.03748"
"22210","133.22400","11.10220","0.03684"
"22236","133.38000","11.11523","0.03742"
"22262","133.53600","11.12815","0.03780"
"22288","133.69200","11.14118","0.03828"
"22314","133.84800","11.15422","0.03879"
"22340","134.00400","11.16719","0.03839"
"22366","134.16000","11.18016","0.03940"
"22392","134.31600","11.19320","0.03901"
"22418","134.47200","11.20617","0.03864"
"22444","134.62800","11.21909","0.03960"
"22470","134.78400","11.23218","0.03953"
"22496","134.94000","11.24516","0.03947"
"22522","135.09600","11.25819","0.03990"
"22548","135.25200","11.27122","0.03995"
"22574","135.40800","11.28426","0.04051"
"22600","135.56400","11.29723","0.04094"
"22626","135.72000","11.31015","0.04125"
"22652","135.87600","11.32318","0.04119"
"22678","136.03200","11.33622","0.04123"
"22704","136.18800","11.34919","0.04240"
"22730","136.34400","11.36216","0.04247"
"22756","136.50000","11.37514","0.04241"
"22782","136.65600","11.38817","0.04260"
"22808","136.81200","11.40115","0.04267"
"22834","136.96800","11.41424","0.04328"
"22860","137.12400","11.42722","0.04364"
"22886","137.28000","11.44013","0.04342"
"22912","137.43600","11.45316","0.04337"
"22938","137.59200","11.46620","0.04356"
"22964","137.74800","11.47923","0.04331"
"22990","137.90400","11.49221","0.04444"
"23016","138.06000","11.50524","0.04419"
"23042","138.21600","11.51822","0.04373"
"23068","138.37200","11.53119","0.04400"
"23094","138.52800","11.54422","0.04291"
"23120","138.68400","11.55726","0.03648"
"23146","138.84000","11.57023","0.03385"
"23172","138.99600","11.58321","0.02800"
"23198","139.15200","11.59624","0.02743"
"23224","139.30800","11.60921","0.02772"
"23250","139.46400","11.62213","0.02622"
"23276","139.62000","11.63522","0.02724"
"23302","139.77600","11.64820","0.02783"
"23328","139.93200","11.66117","0.02760"
"23354","140.08800","11.67415","0.02624"
"23380","140.24400","11.68718","0.02806"
"23406","140.40000","11.70021","0.02833"
"23432","140.55600","11.71313","0.02773"
"23458","140.71200","11.72622","0.02826"
"23484","140.86800","11.73926","0.02875"
"23510","141.02400","11.75217","0.02893"
"23536","141.18000","11.76515","0.02877"
"23562","141.33600","11.77818","0.02920"
"23588","141.49200","11.79121","0.02947"
"23614","141.64800","11.80413","0.02991"
"23640","141.80400","11.81716","0.02967"
"23666","141.96000","11.83020","0.03044"
"23692","142.11600","11.84311","0.03012"
"23718","142.27200","11.85620","0.03043"
"23744","142.42800","11.86924","0.03004"
"23770","142.58400","11.88221","0.02967"
"23796","142.74000","11.89513","0.03001"
"23822","142.89600","11.90822","0.03079"
"23848","143.05200","11.92126","0.03097"
"23874","143.20800","11.93411","0.03079"
"23900","143.36400","11.94714","0.03022"
"23926","143.52000","11.96018","0.03033"
"23952","143.67600","11.97321","0.03105"
"23978","143.83200","11.98613","0.03136"
"24004","143.98800","11.99922","0.03101"
"24030","144.14400","12.01225","0.03110"
"24056","144.30000","12.02517","0.03192"
"24082","144.45600","12.03821","0.03128"
"24108","144.61200","12.05118","0.03219"
"24134","144.76800","12.06421","0.03192"
"24160","144.92400","12.07719","0.03180"
"24186","145.08000","12.09022","0.03172"
"24212","145.23600","12.10319","0.03149"
"24238","145.39200","12.11617","0.03193"
"24264","145.54800","12.12920","0.03269"
"24290","145.70400","12.14224","0.03243"
"24316","145.86000","12.15515","0.03310"
"24342","146.01600","12.16819","0.03313"
"24368","146.17200","12.18122","0.03240"
"24394","146.32800","12.19420","0.03143"
"24420","146.48400","12.20717","0.03077"
"24446","146.64000","12.22020","0.02992"
"24472","146.79600","12.23324","0.02947"
"24498","146.95200","12.24615","0.02978"
"24524","147.10800","12.25913","0.02909"
"24550","147.26400","12.27216","0.02988"
"24576","147.42000","12.28520","0.03006"
"24602","147.57600","12.29811","0.02977"
"24628","147.73200","12.31126","0.02976"
"24654","147.88800","12.32418","0.03034"
"24680","148.04400","12.33715","0.02964"
"24706","148.20000","12.35018","0.03007"
"24732","148.35600","12.36322","0.03073"
"24758","148.51200","12.37619","0.03132"
"24784","148.66800","12.38911","0.03099"
"24810","148.82400","12.40226","0.03064"
"24836","148.98000","12.41518","0.03089"
"24862","149.13600","12.42815","0.02991"
"24888","149.29200","12.44118","0.03010"
"24914","149.44800","12.45422","0.03023"
"24940","149.60400","12.46719","0.02888"
"24966","149.76000","12.48017","0.02604"
"24992","149.91600","12.49326","0.02433"
"25018","150.07200","12.50618","0.02353"
"25044","150.22800","12.51915","0.02143"
"25070","150.38400","12.53218","0.02160"
"25096","150.54000","12.54522","0.02022"
"25122","150.69600","12.55813","0.02131"
"25148","150.85200","12.57117","0.02185"
"25174","151.00800","12.58420","0.02128"
"25200","151.16400","12.59724","0.02146"
"25226","151.32000","12.61015","0.02122"
"25252","151.47600","12.62324","0.02137"
"25278","151.63200","12.63622","0.02106"
"25304","151.78800","12.64919","0.02175"
"25330","151.94400","12.66217","0.02160"
"25356","152.10000","12.67514","0.02137"
"25382","152.25600","12.68818","0.02217"
"25408","152.41200","12.70109","0.02196"
"25434","152.56800","12.71418","0.02197"
"25460","152.72400","12.72722","0.02265"
"25486","152.88000","12.74013","0.02255"
"25512","153.03600","12.75317","0.02281"
"25538","153.19200","12.76620","0.02316"
"25564","153.34800","12.77918","0.02309"
"25590","153.50400","12.79215","0.02147"
"25616","153.66000","12.80524","0.02149"
"25642","153.81600","12.81816","0.02220"
"25668","153.97200","12.83113","0.02144"
"25694","154.12800","12.84417","0.02142"
"25720","154.28400","12.85720","0.02243"
"25746","154.44000","12.87017","0.02127"
"25772","154.59600","12.88315","0.02175"
"25798","154.75200","12.89618","0.02210"
"25824","154.90800","12.90922","0.02240"
"25850","155.06400","12.92219","0.02270"
"25876","155.22000","12.93517","0.02204"
"25902","155.37600","12.94820","0.02293"
"25928","155.53200","12.96117","0.02346"
"25954","155.68800","12.97415","0.02284"
"25980","155.84400","12.98724","0.02329"
"26006","156.00000","13.00016","0.02198"
"26032","156.15600","13.01313","0.02178"
"26058","156.31200","13.02623","0.02251"
"26084","156.46800","13.03920","0.02208"
"26110","156.62400","13.05217","0.02209"
"26136","156.78000","13.06515","0.02219"
"26162","156.93600","13.07818","0.02267"
"26188","157.09200","13.09116","0.02219"
"26214","157.24800","13.10413","0.02199"
"26240","157.40400","13.11723","0.02309"
"26266","157.56000","13.13020","0.02182"
"26292","157.71600","13.14317","0.02163"
"26318","157.87200","13.15615","0.02196"
"26344","158.02800","13.16918","0.02201"
"26370","158.18400","13.18222","0.02199"
"26396","158.34000","13.19513","0.02175"
"26422","158.49600","13.20823","0.02266"
"26448","158.65200","13.22120","0.02263"
"26474","158.80800","13.23417","0.02253"
"26500","158.96400","13.24721","0.02213"
"26526","159.12000","13.26018","0.02294"
"26552","159.27600","13.27316","0.02296"
"26578","159.43200","13.28613","0.02214"
"26604","159.58800","13.29923","0.02244"
"26630","159.74400","13.31220","0.02277"
"26656","159.90000","13.32517","0.02340"
"26682","160.05600","13.33815","0.02281"
"26708","160.21200","13.35118","0.02249"
"26734","160.36800","13.36422","0.02165"
"26760","160.52400","13.37713","0.02206"
"26786","160.68000","13.39023","0.02201"
"26812","160.83600","13.40326","0.02138"
"26838","160.99200","13.41617","0.02169"
"26864","161.14800","13.42921","0.02210"
"26890","161.30400","13.44224","0.02241"
"26916","161.46000","13.45516","0.02190"
"26942","161.61600","13.46813","0.02192"
"26968","161.77200","13.48123","0.02270"
"26994","161.92800","13.49420","0.02214"
"27020","162.08400","13.50717","0.02177"
"27046","162.24000","13.52015","0.02170"
"27072","162.39600","13.53324","0.02228"
"27098","162.55200","13.54616","0.02216"
"27124","162.70800","13.55919","0.02240"
"27150","162.86400","13.57222","0.02228"
"27176","163.02000","13.58514","0.02242"
"27202","163.17600","13.59811","0.02226"
"27228","163.33200","13.61121","0.02283"
"27254","163.48800","13.62418","0.02194"
"27280","163.64400","13.63722","0.02252"
"27306","163.80000","13.65019","0.02285"
"27332","163.95600","13.66328","0.02250"
"27358","164.11200","13.67620","0.02254"
"27384","164.26800","13.68917","0.02226"
"27410","164.42400","13.70221","0.02219"
"27436","164.58000","13.71524","0.02188"
"27462","164.73600","13.72816","0.02208"
"27488","164.89200","13.74119","0.02193"
"27514","165.04800","13.75416","0.02114"
"27540","165.20400","13.76714","0.02227"
"27566","165.36000","13.78011","0.02204"
"27592","165.51600","13.79321","0.02188"
"27618","165.67200","13.80624","0.02184"
"27644","165.82800","13.81916","0.02304"
"27670","165.98400","13.83219","0.02241"
"27696","166.14000","13.84522","0.02271"
"27722","166.29600","13.85820","0.02272"
"27748","166.45200","13.87111","0.02306"
"27774","166.60800","13.88421","0.02349"
"27800","166.76400","13.89718","0.02389"
"27826","166.92000","13.91015","0.02437"
"27852","167.07600","13.92313","0.02563"
"27878","167.23200","13.93622","0.02576"
"27904","167.38800","13.94914","0.02607"
"27930","167.54400","13.96217","0.02684"
"27956","167.70000","13.97520","0.02664"
"27982","167.85600","13.98818","0.02845"
"28008","168.01200","14.00115","0.02835"
"28034","168.16800","14.01419","0.02860"
"28060","168.32400","14.02722","0.02922"
"28086","168.48000","14.04014","0.03000"
"28112","168.63600","14.05317","0.02974"
"28138","168.79200","14.06615","0.03088"
"28164","168.94800","14.07924","0.03121"
"28190","169.10400","14.09215","0.03092"
"28216","169.26000","14.10525","0.03130"
"28242","169.41600","14.11822","0.03029"
"28268","169.57200","14.13114","0.03123"
"28294","169.72800","14.14417","0.03179"
"28320","169.88400","14.15721","0.03210"
"28346","170.04000","14.17024","0.03149"
"28372","170.19600","14.18315","0.03189"
"28398","170.35200","14.19619","0.03270"
"28424","170.50800","14.20922","0.03367"
"28450","170.66400","14.22220","0.03401"
"28476","170.82000","14.23523","0.03413"
"28502","170.97600","14.24821","0.03509"
"28528","171.13200","14.26124","0.03473"
"28554","171.28800","14.27421","0.03395"
"28580","171.44400","14.28725","0.03477"
"28606","171.60000","14.30016","0.03639"
"28632","171.75600","14.31314","0.03693"
"28658","171.91200","14.32617","0.03721"
"28684","172.06800","14.33920","0.03804"
"28710","172.22400","14.35212","0.03915"
"28736","172.38000","14.36515","0.03927"
"28762","172.53600","14.37819","0.03802"
"28788","172.69200","14.39122","0.03960"
"28814","172.84800","14.40420","0.04091"
"28840","173.00400","14.41723","0.04052"
"28866","173.16000","14.43020","0.04013"
"28892","173.31600","14.44318","0.04055"
"28918","173.47200","14.45621","0.04063"
"28944","173.62800","14.46925","0.04058"
"28970","173.78400","14.48222","0.04114"
"28996","173.94000","14.49514","0.04216"
"29022","174.09600","14.50823","0.04239"
"29048","174.25200","14.52120","0.04276"
"29074","174.40800","14.53418","0.04269"
"29100","174.56400","14.54721","0.04334"
"29126","174.72000","14.56025","0.04371"
"29152","174.87600","14.57322","0.04340"
"29178","175.03200","14.58614","0.04282"
"29204","175.18800","14.59923","0.04324"
"29230","175.34400","14.61220","0.04223"
"29256","175.50000","14.62518","0.04242"
"29282","175.65600","14.63821","0.04299"
"29308","175.81200","14.65119","0.04292"
"29334","175.96800","14.66422","0.04317"
"29360","176.12400","14.67714","0.04303"
"29386","176.28000","14.69023","0.04329"
"29412","176.43600","14.70326","0.04353"
"29438","176.59200","14.71618","0.04350"
"29464","176.74800","14.72921","0.04429"
"29490","176.90400","14.74219","0.04441"
"29516","177.06000","14.75516","0.04488"
"29542","177.21600","14.76820","0.04525"
"29568","177.37200","14.78117","0.04551"
"29594","177.52800","14.79420","0.04550"
"29620","177.68400","14.80718","0.04606"
"29646","177.84000","14.82015","0.04634"
"29672","177.99600","14.83319","0.04688"
"29698","178.15200","14.84616","0.04658"
"29724","178.30800","14.85919","0.04671"
"29750","178.46400","14.87223","0.04669"
"29776","178.62000","14.88526","0.04734"
"29802","178.77600","14.89812","0.04707"
"29828","178.93200","14.91121","0.04705"
"29854","179.08800","14.92418","0.04755"
"29880","179.24400","14.93716","0.04694"
"29906","179.40000","14.95014","0.04699"
"29932","179.55600","14.96317","0.04715"
"29958","179.71200","14.97614","0.04737"
"29984","179.86800","14.98918","0.04703"
"30010","180.02400","15.00221","0.04695"
"30036","180.18000","15.01524","0.04684"
"30062","180.33600","15.02816","0.04723"
"30088","180.49200","15.04119","0.04722"
"30114","180.64800","15.05417","0.04763"
"30140","180.80400","15.06714","0.04784"
"30166","180.96000","15.08012","0.04746"
"30192","181.11600","15.09321","0.04816"
"30218","181.27200","15.10624","0.04851"
"30244","181.42800","15.11916","0.04812"
"30270","181.58400","15.13219","0.04876"
"30296","181.74000","15.14523","0.04862"
"30322","181.89600","15.15820","0.04764"
"30348","182.05200","15.17118","0.04752"
"30374","182.20800","15.18427","0.04681"
"30400","182.36400","15.19724","0.04398"
"30426","182.52000","15.21010","0.03823"
"30452","182.67600","15.22319","0.03819"
"30478","182.83200","15.23623","0.02794"
"30504","182.98800","15.24914","0.02592"
"30530","183.14400","15.26212","0.02812"
"30556","183.30000","15.27527","0.02669"
"30582","183.45600","15.28824","0.02447"
"30608","183.61200","15.30116","0.02565"
"30634","183.76800","15.31425","0.02712"
"30660","183.92400","15.32723","0.02662"
"30686","184.08000","15.34020","0.02604"
"30712","184.23600","15.35318","0.02622"
"30738","184.39200","15.36621","0.02736"
"30764","184.54800","15.37918","0.02670"
"30790","184.70400","15.39210","0.02727"
"30816","184.86000","15.40519","0.02619"
"30842","185.01600","15.41823","0.02705"
"30868","185.17200","15.43120","0.02787"
"30894","185.32800","15.44417","0.02807"
"30920","185.48400","15.45721","0.02797"
"30946","185.64000","15.47018","0.02835"
"30972","185.79600","15.48316","0.02813"
"30998","185.95200","15.49619","0.02754"
"31024","186.10800","15.50923","0.02810"
"31050","186.26400","15.52214","0.02814"
"31076","186.42000","15.53517","0.02809"
"31102","186.57600","15.54815","0.02880"
"31128","186.73200","15.56118","0.02948"
"31154","186.88800","15.57416","0.02971"
"31180","187.04400","15.58725","0.03028"
"31206","187.20000","15.60023","0.03089"
"31232","187.35600","15.61320","0.03064"
"31258","187.51200","15.62617","0.03159"
"31284","187.66800","15.63921","0.03033"
"31310","187.82400","15.65218","0.03070"
"31336","187.98000","15.66516","0.03073"
"31362","188.13600","15.67819","0.03166"
"31388","188.29200","15.69116","0.03196"
"31414","188.44800","15.70414","0.03362"
"31440","188.60400","15.71717","0.03413"
"31466","188.76000","15.73021","0.03436"
"31492","188.91600","15.74312","0.03510"
"31518","189.07200","15.75616","0.03599"
"31544","189.22800","15.76919","0.03629"
"31570","189.38400","15.78222","0.03630"
"31596","189.54000","15.79514","0.03589"
"31622","189.69600","15.80817","0.03563"
"31648","189.85200","15.82121","0.03700"
"31674","190.00800","15.83412","0.03665"
"31700","190.16400","15.84716","0.03786"
"31726","190.32000","15.86013","0.03900"
"31752","190.47600","15.87316","0.03861"
"31778","190.63200","15.88614","0.03966"
"31804","190.78800","15.89923","0.03893"
"31830","190.94400","15.91221","0.03896"
"31856","191.10000","15.92518","0.03936"
"31882","191.25600","15.93822","0.03829"
"31908","191.41200","15.95119","0.03854"
"31934","191.56800","15.96422","0.03908"
"31960","191.72400","15.97708","0.03961"
"31986","191.88000","15.99023","0.03945"
"32012","192.03600","16.00321","0.03953"
"32038","192.19200","16.01618","0.04031"
"32064","192.34800","16.02921","0.04068"
"32090","192.50400","16.04225","0.04083"
"32116","192.66000","16.05522","0.04150"
"32142","192.81600","16.06814","0.04183"
"32168","192.97200","16.08123","0.04207"
"32194","193.12800","16.09415","0.04251"
"32220","193.28400","16.10712","0.04343"
"32246","193.44000","16.12016","0.04308"
"32272","193.59600","16.13319","0.04354"
"32298","193.75200","16.14610","0.04391"
"32324","193.90800","16.15914","0.04403"
"32350","194.06400","16.17223","0.04428"
"32376","194.22000","16.18521","0.04392"
"32402","194.37600","16.19818","0.04408"
"32428","194.53200","16.21121","0.04449"
"32454","194.68800","16.22425","0.04505"
"32480","194.84400","16.23716","0.04466"
"32506","195.00000","16.25014","0.04518"
"32532","195.15600","16.26317","0.04492"
"32558","195.31200","16.27615","0.04541"
"32584","195.46800","16.28906","0.04592"
"32610","195.62400","16.30221","0.04648"
"32636","195.78000","16.31519","0.04627"
"32662","195.93600","16.32822","0.04649"
"32688","196.09200","16.34120","0.04694"
"32714","196.24800","16.35423","0.04735"
"32740","196.40400","16.36720","0.04721"
"32766","196.56000","16.38018","0.04764"
"32792","196.71600","16.39321","0.04775"
"32818","196.87200","16.40625","0.04820"
"32836","196.97600","16.41480","0.04797"