File: Trajectories_together/170212_1Specimen_RawData_2.csv
"","V1","V2","V3"
"1","End date","2/12/2017",""
"2","Specimen label","10BG_Unk2",""
"3","Maximum Load","0.64592","N"
"4","Time","Extension","Load"
"5","(s)","(mm)","(N)"
"6","0.00000","0.00000","-0.00043"
"45","0.23400","0.01770","0.00059"
"84","0.46800","0.03934","0.00195"
"123","0.70200","0.05871","0.00237"
"162","0.93600","0.07826","0.00273"
"201","1.17000","0.09770","0.00326"
"240","1.40400","0.11725","0.00383"
"279","1.63800","0.13668","0.00448"
"318","1.87200","0.15623","0.00447"
"357","2.10600","0.17572","0.00471"
"396","2.34000","0.19515","0.00517"
"435","2.57400","0.21476","0.00495"
"474","2.80800","0.23414","0.00577"
"513","3.04200","0.25375","0.00636"
"552","3.27600","0.27318","0.00550"
"591","3.51000","0.29273","0.00656"
"630","3.74400","0.31222","0.00688"
"669","3.97800","0.33171","0.00678"
"708","4.21200","0.35126","0.00712"
"747","4.44600","0.37070","0.00792"
"786","4.68000","0.39019","0.00796"
"825","4.91400","0.40968","0.00844"
"864","5.14800","0.42923","0.00787"
"903","5.38200","0.44872","0.00828"
"942","5.61600","0.46821","0.00898"
"981","5.85000","0.48764","0.00857"
"1020","6.08400","0.50713","0.00840"
"1059","6.31800","0.52675","0.00920"
"1098","6.55200","0.54612","0.00929"
"1137","6.78600","0.56573","0.00959"
"1176","7.02000","0.58516","0.00982"
"1215","7.25400","0.60471","0.01024"
"1254","7.48800","0.62420","0.00997"
"1293","7.72200","0.64369","0.01005"
"1332","7.95600","0.66325","0.01092"
"1371","8.19000","0.68268","0.00999"
"1410","8.42400","0.70217","0.01104"
"1449","8.65800","0.72166","0.01040"
"1488","8.89200","0.74127","0.01088"
"1527","9.12600","0.76064","0.01091"
"1566","9.36000","0.78025","0.01154"
"1605","9.59400","0.79974","0.01084"
"1644","9.82800","0.81912","0.01146"
"1683","10.06200","0.83873","0.01175"
"1722","10.29600","0.85816","0.01160"
"1761","10.53000","0.87771","0.01183"
"1800","10.76400","0.89714","0.01181"
"1839","10.99800","0.91669","0.01163"
"1878","11.23200","0.93624","0.01214"
"1917","11.46600","0.95568","0.01268"
"1956","11.70000","0.97523","0.01172"
"1995","11.93400","0.99466","0.01281"
"2034","12.16800","1.01421","0.01270"
"2073","12.40200","1.03364","0.01252"
"2112","12.63600","1.05325","0.01266"
"2151","12.87000","1.07268","0.01340"
"2190","13.10400","1.09218","0.01331"
"2229","13.33800","1.11173","0.01227"
"2268","13.57200","1.13116","0.01321"
"2307","13.80600","1.15077","0.01327"
"2346","14.04000","1.17020","0.01323"
"2385","14.27400","1.18969","0.01329"
"2424","14.50800","1.20924","0.01386"
"2463","14.74200","1.22867","0.01373"
"2502","14.97600","1.24823","0.01380"
"2541","15.21000","1.26766","0.01423"
"2580","15.44400","1.28727","0.01404"
"2619","15.67800","1.30670","0.01398"
"2658","15.91200","1.32625","0.01463"
"2697","16.14600","1.34568","0.01363"
"2736","16.38000","1.36523","0.01411"
"2775","16.61400","1.38473","0.01463"
"2814","16.84800","1.40422","0.01522"
"2853","17.08200","1.42371","0.01416"
"2892","17.31600","1.44314","0.01454"
"2931","17.55000","1.46269","0.01482"
"2970","17.78400","1.48218","0.01457"
"3009","18.01800","1.50173","0.01504"
"3048","18.25200","1.52128","0.01607"
"3087","18.48600","1.54066","0.01481"
"3126","18.72000","1.56021","0.01492"
"3165","18.95400","1.57970","0.01497"
"3204","19.18800","1.59925","0.01545"
"3243","19.42200","1.61868","0.01528"
"3282","19.65600","1.63823","0.01549"
"3321","19.89000","1.65766","0.01602"
"3360","20.12400","1.67722","0.01503"
"3399","20.35800","1.69671","0.01553"
"3438","20.59200","1.71620","0.01567"
"3477","20.82600","1.73569","0.01614"
"3516","21.06000","1.75518","0.01573"
"3555","21.29400","1.77473","0.01642"
"3594","21.52800","1.79422","0.01577"
"3633","21.76200","1.81372","0.01624"
"3672","21.99600","1.83321","0.01648"
"3711","22.23000","1.85270","0.01611"
"3750","22.46400","1.87219","0.01531"
"3789","22.69800","1.89168","0.01614"
"3828","22.93200","1.91123","0.01578"
"3867","23.16600","1.93072","0.01610"
"3906","23.40000","1.95022","0.01612"
"3945","23.63400","1.96965","0.01621"
"3984","23.86800","1.98920","0.01622"
"4023","24.10200","2.00875","0.01585"
"4062","24.33600","2.02818","0.01601"
"4101","24.57000","2.04773","0.01686"
"4140","24.80400","2.06716","0.01662"
"4179","25.03800","2.08671","0.01620"
"4218","25.27200","2.10621","0.01657"
"4257","25.50600","2.12570","0.01609"
"4296","25.74000","2.14519","0.01713"
"4335","25.97400","2.16474","0.01678"
"4374","26.20800","2.18423","0.01694"
"4413","26.44200","2.20366","0.01669"
"4452","26.67600","2.22321","0.01699"
"4491","26.91000","2.24271","0.01702"
"4530","27.14400","2.26226","0.01738"
"4569","27.37800","2.28169","0.01769"
"4608","27.61200","2.30118","0.01653"
"4647","27.84600","2.32073","0.01706"
"4686","28.08000","2.34010","0.01749"
"4725","28.31400","2.35971","0.01658"
"4764","28.54800","2.37920","0.01703"
"4803","28.78200","2.39876","0.01670"
"4842","29.01600","2.41825","0.01675"
"4881","29.25000","2.43768","0.01767"
"4920","29.48400","2.45723","0.01758"
"4959","29.71800","2.47672","0.01705"
"4998","29.95200","2.49615","0.01720"
"5037","30.18600","2.51564","0.01703"
"5076","30.42000","2.53526","0.01672"
"5115","30.65400","2.55469","0.01754"
"5154","30.88800","2.57418","0.01777"
"5193","31.12200","2.59367","0.01770"
"5232","31.35600","2.61310","0.01734"
"5271","31.59000","2.63277","0.01751"
"5310","31.82400","2.65214","0.01812"
"5349","32.05800","2.67176","0.01798"
"5388","32.29200","2.69119","0.01772"
"5427","32.52600","2.71074","0.01750"
"5466","32.76000","2.73017","0.01746"
"5505","32.99400","2.74972","0.01792"
"5544","33.22800","2.76921","0.01742"
"5583","33.46200","2.78870","0.01791"
"5622","33.69600","2.80819","0.01823"
"5661","33.93000","2.82769","0.01791"
"5700","34.16400","2.84730","0.01831"
"5739","34.39800","2.86667","0.01782"
"5778","34.63200","2.88616","0.01804"
"5817","34.86600","2.90571","0.01847"
"5856","35.10000","2.92514","0.01810"
"5895","35.33400","2.94475","0.01782"
"5934","35.56800","2.96419","0.01832"
"5973","35.80200","2.98374","0.01796"
"6012","36.03600","3.00317","0.01861"
"6051","36.27000","3.02272","0.01809"
"6090","36.50400","3.04221","0.01766"
"6129","36.73800","3.06170","0.01835"
"6168","36.97200","3.08125","0.01832"
"6207","37.20600","3.10069","0.01851"
"6246","37.44000","3.12024","0.01892"
"6285","37.67400","3.13967","0.01847"
"6324","37.90800","3.15922","0.01868"
"6363","38.14200","3.17871","0.01868"
"6402","38.37600","3.19820","0.01843"
"6441","38.61000","3.21775","0.01861"
"6480","38.84400","3.23712","0.01930"
"6519","39.07800","3.25668","0.01921"
"6558","39.31200","3.27623","0.01882"
"6597","39.54600","3.29572","0.01861"
"6636","39.78000","3.31521","0.01839"
"6675","40.01400","3.33470","0.01900"
"6714","40.24800","3.35425","0.01865"
"6753","40.48200","3.37368","0.01935"
"6792","40.71600","3.39318","0.01897"
"6831","40.95000","3.41267","0.01882"
"6870","41.18400","3.43222","0.01886"
"6909","41.41800","3.45165","0.01896"
"6948","41.65200","3.47120","0.01971"
"6987","41.88600","3.49075","0.01880"
"7026","42.12000","3.51012","0.01942"
"7065","42.35400","3.52973","0.01925"
"7104","42.58800","3.54917","0.01874"
"7143","42.82200","3.56872","0.01881"
"7182","43.05600","3.58821","0.01923"
"7221","43.29000","3.60770","0.01930"
"7260","43.52400","3.62725","0.01902"
"7299","43.75800","3.64668","0.01954"
"7338","43.99200","3.66623","0.01890"
"7377","44.22600","3.68561","0.01967"
"7416","44.46000","3.70522","0.01923"
"7455","44.69400","3.72465","0.01979"
"7494","44.92800","3.74426","0.01950"
"7533","45.16200","3.76369","0.01905"
"7572","45.39600","3.78312","0.01958"
"7611","45.63000","3.80279","0.01937"
"7650","45.86400","3.82211","0.01946"
"7689","46.09800","3.84178","0.01934"
"7728","46.33200","3.86121","0.01960"
"7767","46.56600","3.88070","0.01955"
"7806","46.80000","3.90025","0.01953"
"7845","47.03400","3.91968","0.01930"
"7884","47.26800","3.93923","0.01985"
"7923","47.50200","3.95866","0.01972"
"7962","47.73600","3.97822","0.01896"
"8001","47.97000","3.99765","0.01967"
"8040","48.20400","4.01726","0.01941"
"8079","48.43800","4.03663","0.01979"
"8118","48.67200","4.05618","0.02027"
"8157","48.90600","4.07567","0.02026"
"8196","49.14000","4.09516","0.01993"
"8235","49.37400","4.11472","0.02040"
"8274","49.60800","4.13415","0.01989"
"8313","49.84200","4.15370","0.02070"
"8352","50.07600","4.17319","0.02023"
"8391","50.31000","4.19268","0.01998"
"8430","50.54400","4.21223","0.01995"
"8469","50.77800","4.23172","0.01975"
"8508","51.01200","4.25127","0.02080"
"8547","51.24600","4.27065","0.02053"
"8586","51.48000","4.29020","0.02016"
"8625","51.71400","4.30963","0.02055"
"8664","51.94800","4.32924","0.02038"
"8703","52.18200","4.34867","0.02013"
"8742","52.41600","4.36822","0.02010"
"8781","52.65000","4.38771","0.02101"
"8820","52.88400","4.40715","0.01938"
"8859","53.11800","4.42676","0.01893"
"8898","53.35200","4.44619","0.01872"
"8937","53.58600","4.46568","0.01866"
"8976","53.82000","4.48517","0.01869"
"9015","54.05400","4.50472","0.01882"
"9054","54.28800","4.52421","0.01892"
"9093","54.52200","4.54371","0.01903"
"9132","54.75600","4.56326","0.01915"
"9171","54.99000","4.58269","0.01882"
"9210","55.22400","4.60224","0.01888"
"9249","55.45800","4.62167","0.01891"
"9288","55.69200","4.64122","0.01876"
"9327","55.92600","4.66071","0.01854"
"9366","56.16000","4.68021","0.01921"
"9405","56.39400","4.69976","0.01923"
"9444","56.62800","4.71919","0.01896"
"9483","56.86200","4.73868","0.01928"
"9522","57.09600","4.75817","0.01788"
"9561","57.33000","4.77772","0.01827"
"9600","57.56400","4.79721","0.01822"
"9639","57.79800","4.81670","0.01819"
"9678","58.03200","4.83620","0.01862"
"9717","58.26600","4.85569","0.01827"
"9756","58.50000","4.87518","0.01874"
"9795","58.73400","4.89467","0.01857"
"9834","58.96800","4.91422","0.01876"
"9873","59.20200","4.93371","0.01845"
"9912","59.43600","4.95320","0.01916"
"9951","59.67000","4.97269","0.01901"
"9990","59.90400","4.99219","0.01857"
"10029","60.13800","5.01168","0.01936"
"10068","60.37200","5.03111","0.01927"
"10107","60.60600","5.05072","0.01892"
"10146","60.84000","5.07021","0.01940"
"10185","61.07400","5.08976","0.01916"
"10224","61.30800","5.10925","0.01874"
"10263","61.54200","5.12869","0.01890"
"10302","61.77600","5.14818","0.01915"
"10341","62.01000","5.16773","0.01952"
"10380","62.24400","5.18722","0.01905"
"10419","62.47800","5.20665","0.01894"
"10458","62.71200","5.22620","0.01967"
"10497","62.94600","5.24569","0.01919"
"10536","63.18000","5.26519","0.01925"
"10575","63.41400","5.28474","0.01919"
"10614","63.64800","5.30417","0.01948"
"10653","63.88200","5.32372","0.01948"
"10692","64.11600","5.34315","0.02011"
"10731","64.35000","5.36270","0.01989"
"10770","64.58400","5.38213","0.01833"
"10809","64.81800","5.40169","0.01883"
"10848","65.05200","5.42118","0.01875"
"10887","65.28600","5.44067","0.01828"
"10926","65.52000","5.46016","0.01923"
"10965","65.75400","5.47971","0.01843"
"11004","65.98800","5.49920","0.01855"
"11043","66.22200","5.51869","0.01790"
"11082","66.45600","5.53824","0.01877"
"11121","66.69000","5.55768","0.01832"
"11160","66.92400","5.57717","0.01886"
"11199","67.15800","5.59672","0.01871"
"11238","67.39200","5.61615","0.01866"
"11277","67.62600","5.63570","0.01871"
"11316","67.86000","5.65513","0.01815"
"11355","68.09400","5.67474","0.01869"
"11394","68.32800","5.69424","0.01892"
"11433","68.56200","5.71373","0.01887"
"11472","68.79600","5.73322","0.01896"
"11511","69.03000","5.75271","0.01886"
"11550","69.26400","5.77220","0.01875"
"11589","69.49800","5.79163","0.01845"
"11628","69.73200","5.81124","0.01969"
"11667","69.96600","5.83068","0.01898"
"11706","70.20000","5.85023","0.01888"
"11745","70.43400","5.86966","0.01848"
"11784","70.66800","5.88915","0.01870"
"11823","70.90200","5.90876","0.01913"
"11862","71.13600","5.92813","0.01935"
"11901","71.37000","5.94768","0.01878"
"11940","71.60400","5.96717","0.01894"
"11979","71.83800","5.98673","0.01873"
"12018","72.07200","6.00622","0.01948"
"12057","72.30600","6.02571","0.01970"
"12096","72.54000","6.04526","0.01935"
"12135","72.77400","6.06469","0.01959"
"12174","73.00800","6.08418","0.01931"
"12213","73.24200","6.10361","0.01864"
"12252","73.47600","6.12329","0.01876"
"12291","73.71000","6.14272","0.01877"
"12330","73.94400","6.16221","0.01858"
"12369","74.17800","6.18170","0.01870"
"12408","74.41200","6.20113","0.01858"
"12447","74.64600","6.22074","0.01907"
"12486","74.88000","6.24017","0.01872"
"12525","75.11400","6.25973","0.01935"
"12564","75.34800","6.27922","0.01912"
"12603","75.58200","6.29871","0.01951"
"12642","75.81600","6.31820","0.01878"
"12681","76.05000","6.33769","0.01952"
"12720","76.28400","6.35724","0.01909"
"12759","76.51800","6.37667","0.01956"
"12798","76.75200","6.39616","0.01922"
"12837","76.98600","6.41566","0.01942"
"12876","77.22000","6.43527","0.01932"
"12915","77.45400","6.45470","0.01955"
"12954","77.68800","6.47419","0.01890"
"12993","77.92200","6.49374","0.01980"
"13032","78.15600","6.51311","0.01920"
"13071","78.39000","6.53278","0.01897"
"13110","78.62400","6.55216","0.01878"
"13149","78.85800","6.57171","0.01870"
"13188","79.09200","6.59120","0.01897"
"13227","79.32600","6.61069","0.01899"
"13266","79.56000","6.63024","0.01932"
"13305","79.79400","6.64967","0.01845"
"13344","80.02800","6.66922","0.01921"
"13383","80.26200","6.68866","0.01883"
"13422","80.49600","6.70821","0.01922"
"13461","80.73000","6.72764","0.01891"
"13500","80.96400","6.74719","0.01972"
"13539","81.19800","6.76668","0.01934"
"13578","81.43200","6.78617","0.01981"
"13617","81.66600","6.80572","0.01936"
"13656","81.90000","6.82510","0.01960"
"13695","82.13400","6.84471","0.01921"
"13734","82.36800","6.86420","0.01957"
"13773","82.60200","6.88369","0.01998"
"13812","82.83600","6.90324","0.01979"
"13851","83.07000","6.92273","0.01993"
"13890","83.30400","6.94222","0.02023"
"13929","83.53800","6.96171","0.01973"
"13968","83.77200","6.98121","0.01975"
"14007","84.00600","7.00070","0.01997"
"14046","84.24000","7.02025","0.02042"
"14085","84.47400","7.03962","0.02049"
"14124","84.70800","7.05923","0.02072"
"14163","84.94200","7.07872","0.02040"
"14202","85.17600","7.09815","0.02007"
"14241","85.41000","7.11770","0.02050"
"14280","85.64400","7.13714","0.02068"
"14319","85.87800","7.15669","0.02065"
"14358","86.11200","7.17618","0.02086"
"14397","86.34600","7.19567","0.02043"
"14436","86.58000","7.21522","0.02135"
"14475","86.81400","7.23471","0.02066"
"14514","87.04800","7.25420","0.02118"
"14553","87.28200","7.27364","0.02127"
"14592","87.51600","7.29325","0.02040"
"14631","87.75000","7.31274","0.01998"
"14670","87.98400","7.33223","0.01976"
"14709","88.21800","7.35166","0.02048"
"14748","88.45200","7.37115","0.02075"
"14787","88.68600","7.39076","0.02108"
"14826","88.92000","7.41014","0.02054"
"14865","89.15400","7.42969","0.02107"
"14904","89.38800","7.44918","0.02095"
"14943","89.62200","7.46873","0.02127"
"14982","89.85600","7.48822","0.02051"
"15021","90.09000","7.50771","0.02061"
"15060","90.32400","7.52720","0.02112"
"15099","90.55800","7.54675","0.02101"
"15138","90.79200","7.56619","0.02161"
"15177","91.02600","7.58562","0.02119"
"15216","91.26000","7.60523","0.02123"
"15255","91.49400","7.62472","0.02098"
"15294","91.72800","7.64421","0.02164"
"15333","91.96200","7.66370","0.02144"
"15372","92.19600","7.68319","0.02204"
"15411","92.43000","7.70275","0.02187"
"15450","92.66400","7.72218","0.02180"
"15489","92.89800","7.74173","0.02276"
"15528","93.13200","7.76116","0.02219"
"15567","93.36600","7.78071","0.02210"
"15606","93.60000","7.80020","0.02238"
"15645","93.83400","7.81975","0.02238"
"15684","94.06800","7.83919","0.02289"
"15723","94.30200","7.85868","0.02258"
"15762","94.53600","7.87823","0.02294"
"15801","94.77000","7.89760","0.02238"
"15840","95.00400","7.91721","0.02298"
"15879","95.23800","7.93670","0.02340"
"15918","95.47200","7.95625","0.02221"
"15957","95.70600","7.97574","0.02196"
"15996","95.94000","7.99518","0.02260"
"16035","96.17400","8.01473","0.02302"
"16074","96.40800","8.03416","0.02327"
"16113","96.64200","8.05371","0.02346"
"16152","96.87600","8.07314","0.02336"
"16191","97.11000","8.09269","0.02404"
"16230","97.34400","8.11218","0.02343"
"16269","97.57800","8.13168","0.02357"
"16308","97.81200","8.15123","0.02439"
"16347","98.04600","8.17066","0.02409"
"16386","98.28000","8.19027","0.02431"
"16425","98.51400","8.20958","0.02423"
"16464","98.74800","8.22925","0.02453"
"16503","98.98200","8.24868","0.02405"
"16542","99.21600","8.26823","0.02432"
"16581","99.45000","8.28773","0.02463"
"16620","99.68400","8.30716","0.02483"
"16659","99.91800","8.32671","0.02496"
"16698","100.15200","8.34620","0.02430"
"16737","100.38600","8.36569","0.02494"
"16776","100.62000","8.38518","0.02544"
"16815","100.85400","8.40473","0.02549"
"16854","101.08800","8.42422","0.02546"
"16893","101.32200","8.44372","0.02633"
"16932","101.55600","8.46321","0.02618"
"16971","101.79000","8.48264","0.02580"
"17010","102.02400","8.50225","0.02615"
"17049","102.25800","8.52168","0.02494"
"17088","102.49200","8.54123","0.02574"
"17127","102.72600","8.56073","0.02600"
"17166","102.96000","8.58022","0.02622"
"17205","103.19400","8.59971","0.02603"
"17244","103.42800","8.61908","0.02668"
"17283","103.66200","8.63869","0.02644"
"17322","103.89600","8.65824","0.02676"
"17361","104.13000","8.67773","0.02685"
"17400","104.36400","8.69722","0.02725"
"17439","104.59800","8.71672","0.02767"
"17478","104.83200","8.73621","0.02672"
"17517","105.06600","8.75570","0.02734"
"17556","105.30000","8.77525","0.02705"
"17595","105.53400","8.79468","0.02794"
"17634","105.76800","8.81423","0.02760"
"17673","106.00200","8.83366","0.02801"
"17712","106.23600","8.85322","0.02830"
"17751","106.47000","8.87277","0.02819"
"17790","106.70400","8.89214","0.02806"
"17829","106.93800","8.91175","0.02853"
"17868","107.17200","8.93112","0.02842"
"17907","107.40600","8.95067","0.02845"
"17946","107.64000","8.97016","0.02880"
"17985","107.87400","8.98971","0.02884"
"18024","108.10800","9.00921","0.02842"
"18063","108.34200","9.02870","0.02875"
"18102","108.57600","9.04825","0.02851"
"18141","108.81000","9.06768","0.02897"
"18180","109.04400","9.08723","0.02896"
"18219","109.27800","9.10666","0.02906"
"18258","109.51200","9.12627","0.02891"
"18297","109.74600","9.14565","0.02906"
"18336","109.98000","9.16520","0.02835"
"18375","110.21400","9.18469","0.02844"
"18414","110.44800","9.20418","0.02804"
"18453","110.68200","9.22373","0.02836"
"18492","110.91600","9.24322","0.02893"
"18531","111.15000","9.26271","0.02927"
"18570","111.38400","9.28221","0.02895"
"18609","111.61800","9.30176","0.02918"
"18648","111.85200","9.32125","0.02863"
"18687","112.08600","9.34068","0.02983"
"18726","112.32000","9.36023","0.02974"
"18765","112.55400","9.37966","0.02984"
"18804","112.78800","9.39927","0.02957"
"18843","113.02200","9.41864","0.03008"
"18882","113.25600","9.43826","0.02963"
"18921","113.49000","9.45769","0.02986"
"18960","113.72400","9.47724","0.02949"
"18999","113.95800","9.49673","0.03062"
"19038","114.19200","9.51616","0.03059"
"19077","114.42600","9.53571","0.03067"
"19116","114.66000","9.55520","0.03055"
"19155","114.89400","9.57476","0.03070"
"19194","115.12800","9.59425","0.03086"
"19233","115.36200","9.61374","0.03132"
"19272","115.59600","9.63323","0.03011"
"19311","115.83000","9.65266","0.03033"
"19350","116.06400","9.67221","0.03115"
"19389","116.29800","9.69164","0.03069"
"19428","116.53200","9.71126","0.03100"
"19467","116.76600","9.73069","0.03166"
"19506","117.00000","9.75018","0.03073"
"19545","117.23400","9.76973","0.03114"
"19584","117.46800","9.78916","0.03105"
"19623","117.70200","9.80871","0.03095"
"19662","117.93600","9.82820","0.03155"
"19701","118.17000","9.84769","0.03244"
"19740","118.40400","9.86719","0.03129"
"19779","118.63800","9.88668","0.03210"
"19818","118.87200","9.90617","0.03190"
"19857","119.10600","9.92572","0.03275"
"19896","119.34000","9.94521","0.03216"
"19935","119.57400","9.96464","0.03242"
"19974","119.80800","9.98425","0.03219"
"20013","120.04200","10.00369","0.03257"
"20052","120.27600","10.02330","0.03284"
"20091","120.51000","10.04267","0.03337"
"20130","120.74400","10.06222","0.03335"
"20169","120.97800","10.08177","0.03381"
"20208","121.21200","10.10114","0.03382"
"20247","121.44600","10.12075","0.03331"
"20286","121.68000","10.14012","0.03422"
"20325","121.91400","10.15968","0.03407"
"20364","122.14800","10.17923","0.03452"
"20403","122.38200","10.19866","0.03478"
"20442","122.61600","10.21821","0.03482"
"20481","122.85000","10.23770","0.03488"
"20520","123.08400","10.25719","0.03499"
"20559","123.31800","10.27668","0.03467"
"20598","123.55200","10.29624","0.03538"
"20637","123.78600","10.31567","0.03544"
"20676","124.02000","10.33516","0.03572"
"20715","124.25400","10.35471","0.03531"
"20754","124.48800","10.37420","0.03556"
"20793","124.72200","10.39375","0.03546"
"20832","124.95600","10.41312","0.03506"
"20871","125.19000","10.43274","0.03507"
"20910","125.42400","10.45217","0.03549"
"20949","125.65800","10.47172","0.03571"
"20988","125.89200","10.49121","0.03578"
"21027","126.12600","10.51070","0.03630"
"21066","126.36000","10.53019","0.03684"
"21105","126.59400","10.54974","0.03593"
"21144","126.82800","10.56918","0.03596"
"21183","127.06200","10.58867","0.03653"
"21222","127.29600","10.60822","0.03640"
"21261","127.53000","10.62765","0.03717"
"21300","127.76400","10.64720","0.03619"
"21339","127.99800","10.66675","0.03690"
"21378","128.23200","10.68618","0.03704"
"21417","128.46600","10.70573","0.03644"
"21456","128.70000","10.72517","0.03718"
"21495","128.93400","10.74472","0.03649"
"21534","129.16800","10.76421","0.03761"
"21573","129.40200","10.78370","0.03704"
"21612","129.63600","10.80319","0.03700"
"21651","129.87000","10.82268","0.03600"
"21690","130.10400","10.84217","0.03657"
"21729","130.33800","10.86161","0.03661"
"21768","130.57200","10.88128","0.03651"
"21807","130.80600","10.90065","0.03651"
"21846","131.04000","10.92026","0.03678"
"21885","131.27400","10.93969","0.03707"
"21924","131.50800","10.95918","0.03732"
"21963","131.74200","10.97873","0.03818"
"22002","131.97600","10.99811","0.03788"
"22041","132.21000","11.01772","0.03804"
"22080","132.44400","11.03721","0.03884"
"22119","132.67800","11.05676","0.03858"
"22158","132.91200","11.07619","0.03928"
"22197","133.14600","11.09568","0.03872"
"22236","133.38000","11.11523","0.03875"
"22275","133.61400","11.13472","0.03902"
"22314","133.84800","11.15422","0.03915"
"22353","134.08200","11.17365","0.03903"
"22392","134.31600","11.19326","0.04009"
"22431","134.55000","11.21269","0.03939"
"22470","134.78400","11.23218","0.03974"
"22509","135.01800","11.25167","0.04046"
"22548","135.25200","11.27116","0.04015"
"22587","135.48600","11.29072","0.04040"
"22626","135.72000","11.31015","0.04083"
"22665","135.95400","11.32970","0.04072"
"22704","136.18800","11.34919","0.04074"
"22743","136.42200","11.36874","0.04069"
"22782","136.65600","11.38823","0.04069"
"22821","136.89000","11.40772","0.04133"
"22860","137.12400","11.42727","0.04130"
"22899","137.35800","11.44670","0.04123"
"22938","137.59200","11.46626","0.04177"
"22977","137.82600","11.48563","0.04171"
"23016","138.06000","11.50524","0.04153"
"23055","138.29400","11.52467","0.04134"
"23094","138.52800","11.54422","0.04152"
"23133","138.76200","11.56377","0.04191"
"23172","138.99600","11.58315","0.04222"
"23211","139.23000","11.60276","0.04216"
"23250","139.46400","11.62219","0.04265"
"23289","139.69800","11.64168","0.04331"
"23328","139.93200","11.66111","0.04333"
"23367","140.16600","11.68072","0.04309"
"23406","140.40000","11.70021","0.04341"
"23445","140.63400","11.71965","0.04334"
"23484","140.86800","11.73926","0.04344"
"23523","141.10200","11.75863","0.04385"
"23562","141.33600","11.77824","0.04410"
"23601","141.57000","11.79767","0.04440"
"23640","141.80400","11.81722","0.04441"
"23679","142.03800","11.83671","0.04487"
"23718","142.27200","11.85620","0.04422"
"23757","142.50600","11.87576","0.04465"
"23796","142.74000","11.89513","0.04473"
"23835","142.97400","11.91474","0.04554"
"23874","143.20800","11.93423","0.04488"
"23913","143.44200","11.95366","0.04580"
"23952","143.67600","11.97321","0.04564"
"23991","143.91000","11.99270","0.04519"
"24030","144.14400","12.01225","0.04502"
"24069","144.37800","12.03169","0.04503"
"24108","144.61200","12.05124","0.04539"
"24147","144.84600","12.07067","0.04558"
"24186","145.08000","12.09022","0.04521"
"24225","145.31400","12.10965","0.04612"
"24264","145.54800","12.12920","0.04554"
"24303","145.78200","12.14869","0.04668"
"24342","146.01600","12.16825","0.04682"
"24381","146.25000","12.18774","0.04615"
"24420","146.48400","12.20711","0.04653"
"24459","146.71800","12.22672","0.04655"
"24498","146.95200","12.24621","0.04657"
"24537","147.18600","12.26576","0.04658"
"24576","147.42000","12.28520","0.04735"
"24615","147.65400","12.30475","0.04725"
"24654","147.88800","12.32424","0.04793"
"24693","148.12200","12.34367","0.04747"
"24732","148.35600","12.36322","0.04751"
"24771","148.59000","12.38265","0.04745"
"24810","148.82400","12.40226","0.04684"
"24849","149.05800","12.42163","0.04768"
"24888","149.29200","12.44125","0.04751"
"24927","149.52600","12.46074","0.04786"
"24966","149.76000","12.48017","0.04748"
"25005","149.99400","12.49972","0.04799"
"25044","150.22800","12.51915","0.04799"
"25083","150.46200","12.53870","0.04794"
"25122","150.69600","12.55819","0.04832"
"25161","150.93000","12.57768","0.04800"
"25200","151.16400","12.59718","0.04841"
"25239","151.39800","12.61673","0.04898"
"25278","151.63200","12.63622","0.04852"
"25317","151.86600","12.65571","0.04854"
"25356","152.10000","12.67526","0.04919"
"25395","152.33400","12.69475","0.04933"
"25434","152.56800","12.71424","0.04947"
"25473","152.80200","12.73368","0.04952"
"25512","153.03600","12.75317","0.04977"
"25551","153.27000","12.77272","0.04967"
"25590","153.50400","12.79215","0.04986"
"25629","153.73800","12.81170","0.04989"
"25668","153.97200","12.83113","0.05026"
"25707","154.20600","12.85068","0.05058"
"25746","154.44000","12.87017","0.05092"
"25785","154.67400","12.88973","0.05079"
"25824","154.90800","12.90922","0.04976"
"25863","155.14200","12.92871","0.05017"
"25902","155.37600","12.94820","0.05015"
"25941","155.61000","12.96763","0.05040"
"25980","155.84400","12.98724","0.04990"
"26019","156.07800","13.00667","0.05022"
"26058","156.31200","13.02623","0.05035"
"26097","156.54600","13.04572","0.05035"
"26136","156.78000","13.06515","0.05048"
"26175","157.01400","13.08470","0.05041"
"26214","157.24800","13.10413","0.05107"
"26253","157.48200","13.12374","0.05108"
"26292","157.71600","13.14317","0.05123"
"26331","157.95000","13.16273","0.05173"
"26370","158.18400","13.18222","0.05184"
"26409","158.41800","13.20177","0.05210"
"26448","158.65200","13.22120","0.05252"
"26487","158.88600","13.24069","0.05300"
"26526","159.12000","13.26018","0.05315"
"26565","159.35400","13.27967","0.05347"
"26604","159.58800","13.29929","0.05343"
"26643","159.82200","13.31872","0.05380"
"26682","160.05600","13.33821","0.05428"
"26721","160.29000","13.35770","0.05458"
"26760","160.52400","13.37713","0.05492"
"26799","160.75800","13.39668","0.05542"
"26838","160.99200","13.41617","0.05613"
"26877","161.22600","13.43573","0.05658"
"26916","161.46000","13.45516","0.05660"
"26955","161.69400","13.47471","0.05751"
"26994","161.92800","13.49420","0.05812"
"27033","162.16200","13.51375","0.05858"
"27072","162.39600","13.53318","0.05865"
"27111","162.63000","13.55273","0.06000"
"27150","162.86400","13.57228","0.06062"
"27189","163.09800","13.59166","0.06090"
"27228","163.33200","13.61127","0.06163"
"27267","163.56600","13.63064","0.06225"
"27306","163.80000","13.65019","0.06324"
"27345","164.03400","13.66974","0.06357"
"27384","164.26800","13.68917","0.05982"
"27423","164.50200","13.70878","0.06019"
"27462","164.73600","13.72816","0.05858"
"27501","164.97000","13.74771","0.05815"
"27540","165.20400","13.76720","0.05682"
"27579","165.43800","13.78669","0.05538"
"27618","165.67200","13.80624","0.05594"
"27657","165.90600","13.82573","0.05650"
"27696","166.14000","13.84528","0.05649"
"27735","166.37400","13.86466","0.05694"
"27774","166.60800","13.88426","0.05745"
"27813","166.84200","13.90364","0.05821"
"27852","167.07600","13.92319","0.05814"
"27891","167.31000","13.94274","0.05865"
"27930","167.54400","13.96217","0.05949"
"27969","167.77800","13.98172","0.06000"
"28008","168.01200","14.00115","0.06095"
"28047","168.24600","14.02071","0.06132"
"28086","168.48000","14.04020","0.06189"
"28125","168.71400","14.05969","0.06304"
"28164","168.94800","14.07918","0.06329"
"28203","169.18200","14.09867","0.06447"
"28242","169.41600","14.11822","0.06436"
"28281","169.65000","14.13771","0.06584"
"28320","169.88400","14.15721","0.06685"
"28359","170.11800","14.17664","0.06755"
"28398","170.35200","14.19625","0.06837"
"28437","170.58600","14.21568","0.06940"
"28476","170.82000","14.23523","0.07081"
"28515","171.05400","14.25478","0.07003"
"28554","171.28800","14.27421","0.07242"
"28593","171.52200","14.29370","0.07249"
"28632","171.75600","14.31320","0.07293"
"28671","171.99000","14.33269","0.07319"
"28710","172.22400","14.35218","0.07417"
"28749","172.45800","14.37173","0.07465"
"28788","172.69200","14.39122","0.07505"
"28827","172.92600","14.41065","0.07530"
"28866","173.16000","14.43020","0.07628"
"28905","173.39400","14.44964","0.07709"
"28944","173.62800","14.46925","0.07725"
"28983","173.86200","14.48868","0.07745"
"29022","174.09600","14.50823","0.07821"
"29061","174.33000","14.52766","0.07897"
"29100","174.56400","14.54715","0.07995"
"29139","174.79800","14.56676","0.08035"
"29178","175.03200","14.58614","0.08166"
"29217","175.26600","14.60575","0.08166"
"29256","175.50000","14.62518","0.08254"
"29295","175.73400","14.64467","0.08305"
"29334","175.96800","14.66416","0.08363"
"29373","176.20200","14.68371","0.08418"
"29412","176.43600","14.70320","0.08487"
"29451","176.67000","14.72264","0.08600"
"29490","176.90400","14.74219","0.08613"
"29529","177.13800","14.76162","0.08752"
"29568","177.37200","14.78123","0.08773"
"29607","177.60600","14.80066","0.08932"
"29646","177.84000","14.82021","0.08946"
"29685","178.07400","14.83970","0.09018"
"29724","178.30800","14.85913","0.09079"
"29763","178.54200","14.87875","0.09104"
"29802","178.77600","14.89818","0.09183"
"29841","179.01000","14.91773","0.09220"
"29880","179.24400","14.93722","0.09340"
"29919","179.47800","14.95671","0.09409"
"29958","179.71200","14.97620","0.09478"
"29997","179.94600","14.99575","0.09523"
"30036","180.18000","15.01524","0.09641"
"30075","180.41400","15.03468","0.09748"
"30114","180.64800","15.05417","0.09827"
"30153","180.88200","15.07366","0.09847"
"30192","181.11600","15.09321","0.09887"
"30231","181.35000","15.11264","0.09917"
"30270","181.58400","15.13225","0.09839"
"30309","181.81800","15.15174","0.09897"
"30348","182.05200","15.17118","0.09975"
"30387","182.28600","15.19073","0.10013"
"30426","182.52000","15.21022","0.10053"
"30465","182.75400","15.22971","0.10118"
"30504","182.98800","15.24914","0.10162"
"30543","183.22200","15.26875","0.10138"
"30582","183.45600","15.28818","0.10210"
"30621","183.69000","15.30773","0.10239"
"30660","183.92400","15.32723","0.10282"
"30699","184.15800","15.34666","0.10351"
"30738","184.39200","15.36621","0.10450"
"30777","184.62600","15.38570","0.10500"
"30816","184.86000","15.40519","0.10557"
"30855","185.09400","15.42468","0.10636"
"30894","185.32800","15.44417","0.10751"
"30933","185.56200","15.46373","0.10698"
"30972","185.79600","15.48316","0.10804"
"31011","186.03000","15.50271","0.10834"
"31050","186.26400","15.52214","0.11016"
"31089","186.49800","15.54169","0.11148"
"31128","186.73200","15.56118","0.11241"
"31167","186.96600","15.58073","0.11323"
"31206","187.20000","15.60017","0.11400"
"31245","187.43400","15.61972","0.11668"
"31284","187.66800","15.63921","0.11730"
"31323","187.90200","15.65870","0.11877"
"31362","188.13600","15.67819","0.12021"
"31401","188.37000","15.69768","0.12129"
"31440","188.60400","15.71723","0.12220"
"31479","188.83800","15.73672","0.12327"
"31518","189.07200","15.75622","0.12466"
"31557","189.30600","15.77571","0.12479"
"31596","189.54000","15.79514","0.12198"
"31635","189.77400","15.81475","0.12234"
"31674","190.00800","15.83418","0.12421"
"31713","190.24200","15.85373","0.12533"
"31752","190.47600","15.87322","0.12692"
"31791","190.71000","15.89272","0.12890"
"31830","190.94400","15.91221","0.12986"
"31869","191.17800","15.93164","0.13126"
"31908","191.41200","15.95125","0.13269"
"31947","191.64600","15.97062","0.13377"
"31986","191.88000","15.99023","0.13413"
"32025","192.11400","16.00966","0.13150"
"32064","192.34800","16.02921","0.13231"
"32103","192.58200","16.04877","0.13382"
"32142","192.81600","16.06814","0.13521"
"32181","193.05000","16.08775","0.13640"
"32220","193.28400","16.10718","0.13708"
"32259","193.51800","16.12667","0.13825"
"32298","193.75200","16.14616","0.13919"
"32337","193.98600","16.16571","0.14000"
"32376","194.22000","16.18515","0.14093"
"32415","194.45400","16.20470","0.14194"
"32454","194.68800","16.22419","0.14271"
"32493","194.92200","16.24368","0.14325"
"32532","195.15600","16.26323","0.14367"
"32571","195.39000","16.28266","0.14484"
"32610","195.62400","16.30227","0.14531"
"32649","195.85800","16.32165","0.14616"
"32688","196.09200","16.34120","0.14694"
"32727","196.32600","16.36069","0.14770"
"32766","196.56000","16.38018","0.14824"
"32805","196.79400","16.39973","0.14907"
"32844","197.02800","16.41916","0.14970"
"32883","197.26200","16.43871","0.15069"
"32922","197.49600","16.45820","0.15195"
"32961","197.73000","16.47776","0.15307"
"33000","197.96400","16.49719","0.15435"
"33039","198.19800","16.51674","0.15624"
"33078","198.43200","16.53623","0.15748"
"33117","198.66600","16.55560","0.15927"
"33156","198.90000","16.57521","0.16092"
"33195","199.13400","16.59464","0.16330"
"33234","199.36800","16.61419","0.16632"
"33273","199.60200","16.63369","0.16842"
"33312","199.83600","16.65318","0.17197"
"33351","200.07000","16.67273","0.17569"
"33390","200.30400","16.69216","0.17895"
"33429","200.53800","16.71171","0.18174"
"33468","200.77200","16.73114","0.18509"
"33507","201.00600","16.75069","0.18983"
"33546","201.24000","16.77024","0.19282"
"33585","201.47400","16.78968","0.19686"
"33624","201.70800","16.80923","0.19998"
"33663","201.94200","16.82866","0.20128"
"33702","202.17600","16.84821","0.20369"
"33741","202.41000","16.86764","0.20524"
"33780","202.64400","16.88725","0.20593"
"33819","202.87800","16.90669","0.20687"
"33858","203.11200","16.92624","0.20720"
"33897","203.34600","16.94573","0.20901"
"33936","203.58000","16.96516","0.20862"
"33975","203.81400","16.98471","0.21058"
"34014","204.04800","17.00414","0.21251"
"34053","204.28200","17.02369","0.21508"
"34092","204.51600","17.04319","0.21817"
"34131","204.75000","17.06274","0.22069"
"34170","204.98400","17.08217","0.22325"
"34209","205.21800","17.10166","0.22613"
"34248","205.45200","17.12121","0.22918"
"34287","205.68600","17.14070","0.23186"
"34326","205.92000","17.16025","0.23510"
"34365","206.15400","17.17962","0.23727"
"34404","206.38800","17.19924","0.24001"
"34443","206.62200","17.21867","0.24242"
"34482","206.85600","17.23822","0.24392"
"34521","207.09000","17.25777","0.24537"
"34560","207.32400","17.27714","0.24721"
"34599","207.55800","17.29675","0.24859"
"34638","207.79200","17.31618","0.24993"
"34677","208.02600","17.33574","0.25099"
"34716","208.26000","17.35517","0.25218"
"34755","208.49400","17.37472","0.25288"
"34794","208.72800","17.39421","0.25344"
"34833","208.96200","17.41370","0.25419"
"34872","209.19600","17.43319","0.25561"
"34911","209.43000","17.45268","0.25654"
"34950","209.66400","17.47223","0.25741"
"34989","209.89800","17.49167","0.25887"
"35028","210.13200","17.51122","0.25993"
"35067","210.36600","17.53077","0.25957"
"35106","210.60000","17.55020","0.26110"
"35145","210.83400","17.56975","0.26370"
"35184","211.06800","17.58912","0.26692"
"35223","211.30200","17.60868","0.26972"
"35262","211.53600","17.62817","0.27211"
"35301","211.77000","17.64772","0.27571"
"35340","212.00400","17.66715","0.27832"
"35379","212.23800","17.68676","0.28127"
"35418","212.47200","17.70619","0.28475"
"35457","212.70600","17.72568","0.28640"
"35496","212.94000","17.74523","0.28959"
"35535","213.17400","17.76467","0.29220"
"35574","213.40800","17.78422","0.29576"
"35613","213.64200","17.80365","0.29769"
"35652","213.87600","17.82326","0.29949"
"35691","214.11000","17.84275","0.30150"
"35730","214.34400","17.86224","0.30307"
"35769","214.57800","17.88173","0.30582"
"35808","214.81200","17.90117","0.30894"
"35847","215.04600","17.92072","0.31385"
"35886","215.28000","17.94021","0.31861"
"35925","215.51400","17.95976","0.32484"
"35964","215.74800","17.97919","0.33001"
"36003","215.98200","17.99868","0.33612"
"36042","216.21600","18.01817","0.33947"
"36081","216.45000","18.03761","0.34308"
"36120","216.68400","18.05722","0.34698"
"36159","216.91800","18.07665","0.35066"
"36198","217.15200","18.09626","0.35363"
"36237","217.38600","18.11569","0.35596"
"36276","217.62000","18.13518","0.35802"
"36315","217.85400","18.15473","0.35919"
"36354","218.08800","18.17416","0.36006"
"36393","218.32200","18.19372","0.36070"
"36432","218.55600","18.21321","0.36148"
"36471","218.79000","18.23270","0.36202"
"36510","219.02400","18.25219","0.36299"
"36549","219.25800","18.27174","0.36384"
"36588","219.49200","18.29117","0.36534"
"36627","219.72600","18.31072","0.36667"
"36666","219.96000","18.33022","0.36888"
"36705","220.19400","18.34965","0.37092"
"36744","220.42800","18.36920","0.37375"
"36783","220.66200","18.38869","0.37606"
"36822","220.89600","18.40818","0.37943"
"36861","221.13000","18.42773","0.38291"
"36900","221.36400","18.44716","0.38772"
"36939","221.59800","18.46671","0.39285"
"36978","221.83200","18.48621","0.39627"
"37017","222.06600","18.50570","0.40052"
"37056","222.30000","18.52519","0.40401"
"37095","222.53400","18.54468","0.40711"
"37134","222.76800","18.56417","0.40876"
"37173","223.00200","18.58372","0.41085"
"37212","223.23600","18.60321","0.41336"
"37251","223.47000","18.62271","0.41625"
"37290","223.70400","18.64226","0.41978"
"37329","223.93800","18.66163","0.42331"
"37368","224.17200","18.68124","0.42710"
"37407","224.40600","18.70067","0.43069"
"37446","224.64000","18.72028","0.43306"
"37485","224.87400","18.73971","0.43430"
"37524","225.10800","18.75921","0.43652"
"37563","225.34200","18.77870","0.43787"
"37602","225.57600","18.79819","0.43914"
"37641","225.81000","18.81774","0.44134"
"37680","226.04400","18.83717","0.44279"
"37719","226.27800","18.85666","0.44464"
"37758","226.51200","18.87615","0.44617"
"37797","226.74600","18.89570","0.44750"
"37836","226.98000","18.91520","0.44831"
"37875","227.21400","18.93469","0.42962"
"37914","227.44800","18.95424","0.41678"
"37953","227.68200","18.97361","0.41730"
"37992","227.91600","18.99322","0.42009"
"38031","228.15000","19.01271","0.42381"
"38070","228.38400","19.03220","0.42678"
"38109","228.61800","19.05175","0.42924"
"38148","228.85200","19.07119","0.43238"
"38187","229.08600","19.09068","0.43386"
"38226","229.32000","19.11017","0.43659"
"38265","229.55400","19.12966","0.43873"
"38304","229.78800","19.14915","0.44124"
"38343","230.02200","19.16870","0.44270"
"38382","230.25600","19.18820","0.44479"
"38421","230.49000","19.20769","0.44610"
"38460","230.72400","19.22724","0.44783"
"38499","230.95800","19.24667","0.44993"
"38538","231.19200","19.26622","0.45114"
"38577","231.42600","19.28565","0.45350"
"38616","231.66000","19.30526","0.45565"
"38655","231.89400","19.32469","0.45775"
"38694","232.12800","19.34425","0.45983"
"38733","232.36200","19.36368","0.46178"
"38772","232.59600","19.38311","0.46486"
"38811","232.83000","19.40272","0.46743"
"38850","233.06400","19.42215","0.47019"
"38889","233.29800","19.44170","0.47121"
"38928","233.53200","19.46119","0.47327"
"38967","233.76600","19.48068","0.47657"
"39006","234.00000","19.50024","0.48029"
"39045","234.23400","19.51967","0.48337"
"39084","234.46800","19.53922","0.48664"
"39123","234.70200","19.55865","0.48940"
"39162","234.93600","19.57820","0.49225"
"39201","235.17000","19.59769","0.49570"
"39240","235.40400","19.61724","0.49792"
"39279","235.63800","19.63674","0.49920"
"39318","235.87200","19.65617","0.49916"
"39357","236.10600","19.67572","0.50220"
"39396","236.34000","19.69521","0.50432"
"39435","236.57400","19.71470","0.50613"
"39474","236.80800","19.73413","0.50773"
"39513","237.04200","19.75368","0.50911"
"39552","237.27600","19.77317","0.51008"
"39591","237.51000","19.79267","0.51083"
"39630","237.74400","19.81222","0.51108"
"39669","237.97800","19.83165","0.51248"
"39708","238.21200","19.85126","0.51538"
"39747","238.44600","19.87069","0.51915"
"39786","238.68000","19.89024","0.51953"
"39825","238.91400","19.90968","0.52109"
"39864","239.14800","19.92917","0.52411"
"39903","239.38200","19.94866","0.52825"
"39942","239.61600","19.96821","0.53406"
"39981","239.85000","19.98770","0.53949"
"40020","240.08400","20.00719","0.54380"
"40059","240.31800","20.02668","0.54893"
"40098","240.55200","20.04618","0.55234"
"40137","240.78600","20.06573","0.55683"
"40176","241.02000","20.08516","0.55994"
"40215","241.25400","20.10471","0.56334"
"40254","241.48800","20.12426","0.56563"
"40293","241.72200","20.14363","0.56751"
"40332","241.95600","20.16324","0.56936"
"40371","242.19000","20.18267","0.57082"
"40410","242.42400","20.20222","0.57208"
"40449","242.65800","20.22172","0.57336"
"40488","242.89200","20.24121","0.57444"
"40527","243.12600","20.26070","0.57593"
"40566","243.36000","20.28019","0.57746"
"40605","243.59400","20.29968","0.57967"
"40644","243.82800","20.31918","0.58366"
"40683","244.06200","20.33873","0.58731"
"40722","244.29600","20.35815","0.59158"
"40761","244.53000","20.37771","0.59652"
"40800","244.76400","20.39720","0.60022"
"40839","244.99800","20.41669","0.60430"
"40878","245.23200","20.43618","0.60813"
"40917","245.46600","20.45561","0.61121"
"40956","245.70000","20.47522","0.61479"
"40995","245.93400","20.49471","0.61618"
"41034","246.16800","20.51421","0.61791"
"41073","246.40200","20.53370","0.62090"
"41112","246.63600","20.55319","0.62408"
"41151","246.87000","20.57274","0.62909"
"41190","247.10400","20.59217","0.63416"
"41229","247.33800","20.61166","0.63611"
"41268","247.57200","20.63116","0.64035"
"41307","247.80600","20.65071","0.64511"
"41346","248.04000","20.67014","0.42109"
"41385","248.27400","20.68969","0.42339"
"41424","248.50800","20.70918","0.43243"
"41463","248.74200","20.72873","0.43463"
"41502","248.97600","20.74822","0.44435"
"41541","249.21000","20.76765","0.44935"
"41580","249.44400","20.78727","0.44811"
"41619","249.67800","20.80664","0.45153"
"41658","249.91200","20.82619","0.45475"
"41697","250.14600","20.84574","0.45670"
"41736","250.38000","20.86517","0.46541"
"41775","250.61400","20.88472","0.47234"
"41814","250.84800","20.90415","0.47321"
"41853","251.08200","20.92371","0.47743"
"41892","251.31600","20.94320","0.47153"
"41931","251.55000","20.96275","0.37525"
"41970","251.78400","20.98212","0.36197"
"42009","252.01800","21.00167","0.36232"
"42048","252.25200","21.02128","0.36148"
"42087","252.48600","21.04065","0.36145"
"42126","252.72000","21.06020","0.25881"
"42165","252.95400","21.07964","0.25807"
"42204","253.18800","21.09925","0.25715"
"42243","253.42200","21.11868","0.25877"
"42282","253.65600","21.13823","0.26554"
"42321","253.89000","21.15772","0.26649"
"42360","254.12400","21.17715","0.27071"
"42399","254.35800","21.19670","0.27704"
"42438","254.59200","21.21620","0.27857"
"42477","254.82600","21.23575","0.28402"
"42516","255.06000","21.25518","0.28977"
"42555","255.29400","21.27473","0.29582"
"42594","255.52800","21.29416","0.29593"
"42633","255.76200","21.31371","0.29873"
"42672","255.99600","21.33320","0.30216"
"42711","256.23000","21.35264","0.30655"
"42750","256.46400","21.37219","0.30893"
"42789","256.69800","21.39168","0.31431"
"42828","256.93200","21.41123","0.32625"
"42867","257.16600","21.43072","0.33182"
"42906","257.40000","21.45021","0.33644"
"42945","257.63400","21.46971","0.34138"
"42984","257.86800","21.48913","0.34782"
"43023","258.10200","21.50869","0.33003"
"43062","258.33600","21.52818","0.32763"
"43101","258.57000","21.54773","0.33211"
"43140","258.80400","21.56716","0.34102"
"43179","259.03800","21.58671","0.34554"
"43218","259.27200","21.60620","0.34896"
"43257","259.50600","21.62564","0.35211"
"43296","259.74000","21.64524","0.35680"
"43335","259.97400","21.66462","0.35825"
"43374","260.20800","21.68423","0.35948"
"43413","260.44200","21.70366","0.36013"
"43452","260.67600","21.72315","0.36156"
"43491","260.91000","21.74270","0.36244"
"43530","261.14400","21.76219","0.36350"
"43569","261.37800","21.78175","0.36574"
"43608","261.61200","21.80124","0.36822"
"43647","261.84600","21.82073","0.37200"
"43686","262.08000","21.84022","0.37455"
"43725","262.31400","21.85971","0.37888"
"43764","262.54800","21.87920","0.38371"
"43803","262.78200","21.89869","0.39079"
"43842","263.01600","21.91825","0.39728"
"43881","263.25000","21.93762","0.40120"
"43920","263.48400","21.95723","0.40551"
"43959","263.71800","21.97672","0.40862"
"43998","263.95200","21.99621","0.41132"
"44037","264.18600","22.01576","0.41466"
"44076","264.42000","22.03519","0.41730"
"44115","264.65400","22.05469","0.42088"
"44154","264.88800","22.07417","0.42593"
"44193","265.12200","22.09367","0.42961"
"44232","265.35600","22.11322","0.43381"
"44271","265.59000","22.13271","0.43638"
"44310","265.82400","22.15220","0.43731"
"44349","266.05800","22.17169","0.44003"
"44388","266.29200","22.19118","0.44197"
"44427","266.52600","22.21068","0.44445"
"44466","266.76000","22.23022","0.44563"
"44505","266.99400","22.24966","0.44725"
"44544","267.22800","22.26921","0.44795"
"44583","267.46200","22.28870","0.44985"
"44622","267.69600","22.30825","0.45181"
"44661","267.93000","22.32774","0.45464"
"44700","268.16400","22.34724","0.45766"
"44739","268.39800","22.36673","0.45901"
"44778","268.63200","22.38622","0.46074"
"44817","268.86600","22.40571","0.46224"
"44856","269.10000","22.42514","0.46490"
"44895","269.33400","22.44469","0.46834"
"44934","269.56800","22.46418","0.47213"
"44973","269.80200","22.48368","0.47553"
"45012","270.03600","22.50323","0.47850"
"45051","270.27000","22.52266","0.48200"
"45090","270.50400","22.54227","0.48558"
"45129","270.73800","22.56164","0.48898"
"45168","270.97200","22.58125","0.49216"
"45207","271.20600","22.60068","0.49579"
"45246","271.44000","22.62017","0.49824"
"45285","271.67400","22.63972","0.50046"
"45324","271.90800","22.65922","0.50271"
"45363","272.14200","22.67871","0.50459"
"45402","272.37600","22.69820","0.50666"
"45441","272.61000","22.71769","0.50802"
"45480","272.84400","22.73718","0.50910"
"45519","273.07800","22.75673","0.51032"
"45558","273.31200","22.77617","0.51147"
"45597","273.54600","22.79566","0.51331"
"45636","273.78000","22.81521","0.51471"
"45675","274.01400","22.83470","0.51750"
"45714","274.24800","22.85425","0.52048"
"45753","274.48200","22.87368","0.52440"
"45792","274.71600","22.89323","0.52782"
"45831","274.95000","22.91273","0.53216"
"45870","275.18400","22.93222","0.53456"
"45909","275.41800","22.95164","0.53663"
"45948","275.65200","22.97114","0.53939"
"45987","275.88600","22.99069","0.54210"
"46026","276.12000","23.01018","0.54481"
"46065","276.35400","23.02973","0.54721"
"46104","276.58800","23.04916","0.54919"
"46143","276.82200","23.06878","0.55166"
"46182","277.05600","23.08821","0.36568"
"46221","277.29000","23.10764","0.18689"
"46260","277.52400","23.12719","0.18703"
"46299","277.75800","23.14668","0.20422"
"46338","277.99200","23.16623","0.19863"
"46377","278.22600","23.18567","0.20500"
"46416","278.46000","23.20522","0.20853"
"46455","278.69400","23.22471","0.20487"
"46494","278.92800","23.24420","0.20918"
"46533","279.16200","23.26375","0.20993"
"46572","279.39600","23.28318","0.20872"
"46611","279.63000","23.30267","0.21695"
"46650","279.86400","23.32216","0.21450"
"46689","280.09800","23.34171","0.21364"
"46728","280.33200","23.36115","0.22380"
"46767","280.56600","23.38070","0.22254"
"46806","280.80000","23.40019","0.22006"
"46845","281.03400","23.41974","0.01714"
"46884","281.26800","23.43923","0.02420"
"46923","281.50200","23.45872","0.01572"
"46962","281.73600","23.47827","0.02299"
"47001","281.97000","23.49771","0.01552"
"47040","282.20400","23.51720","0.02320"
"47079","282.43800","23.53669","0.01521"
"47118","282.67200","23.55618","0.02124"
"47157","282.90600","23.57573","0.01682"
"47196","283.14000","23.59516","0.02099"
"47235","283.37400","23.61471","0.01810"
"47274","283.60800","23.63415","0.01821"
"47313","283.84200","23.65376","0.01997"
"47352","284.07600","23.67319","0.01679"
"47391","284.31000","23.69274","0.02120"
"47430","284.54400","23.71229","0.01844"
"47469","284.77800","23.73166","0.02176"
"47508","285.01200","23.75121","0.01920"
"47547","285.24600","23.77070","0.02030"
"47586","285.48000","23.79025","0.01904"
"47625","285.71400","23.80975","0.01968"
"47664","285.94800","23.82918","0.02033"
"47703","286.18200","23.84873","0.02014"
"47742","286.41600","23.86816","0.02168"
"47781","286.65000","23.88777","0.01968"
"47820","286.88400","23.90714","0.02103"
"47859","287.11800","23.92669","0.01922"
"47861","287.12800","23.92753","0.01936"