File: Trajectories_together/170226_3Specimen_RawData_4.csv
"","V1","V2","V3"
"1","End date","2/26/2017",""
"2","Specimen label","7CG_56",""
"3","Maximum Load","0.48809","N"
"4","Time","Extension","Load"
"5","(s)","(mm)","(N)"
"6","0.00000","0.00000","-0.00069"
"88","0.49200","0.04131","0.00056"
"170","0.98400","0.08227","0.00075"
"252","1.47600","0.12323","0.00181"
"334","1.96800","0.16424","0.00233"
"416","2.46000","0.20532","0.00232"
"498","2.95200","0.24621","0.00293"
"580","3.44400","0.28717","0.00291"
"662","3.93600","0.32818","0.00313"
"744","4.42800","0.36920","0.00351"
"826","4.92000","0.41016","0.00353"
"908","5.41200","0.45117","0.00403"
"990","5.90400","0.49231","0.00400"
"1072","6.39600","0.53320","0.00447"
"1154","6.88800","0.57422","0.00483"
"1236","7.38000","0.61523","0.00539"
"1318","7.87200","0.65625","0.00577"
"1400","8.36400","0.69721","0.00588"
"1482","8.85600","0.73822","0.00622"
"1564","9.34800","0.77924","0.00649"
"1646","9.84000","0.82019","0.00711"
"1728","10.33200","0.86121","0.00693"
"1810","10.82400","0.90222","0.00741"
"1892","11.31600","0.94324","0.00727"
"1974","11.80800","0.98420","0.00749"
"2056","12.30000","1.02527","0.00776"
"2138","12.79200","1.06623","0.00836"
"2220","13.28400","1.10718","0.00853"
"2302","13.77600","1.14826","0.00860"
"2384","14.26800","1.18927","0.00897"
"2466","14.76000","1.23023","0.00904"
"2548","15.25200","1.27119","0.00966"
"2630","15.74400","1.31214","0.01021"
"2712","16.23600","1.35316","0.01005"
"2794","16.72800","1.39417","0.01050"
"2876","17.22000","1.43525","0.01077"
"2958","17.71200","1.47620","0.01035"
"3040","18.20400","1.51722","0.01106"
"3122","18.69600","1.55823","0.01102"
"3204","19.18800","1.59925","0.01068"
"3286","19.68000","1.64027","0.01067"
"3368","20.17200","1.68122","0.01141"
"3450","20.66400","1.72224","0.01210"
"3532","21.15600","1.76319","0.01218"
"3614","21.64800","1.80421","0.01244"
"3696","22.14000","1.84516","0.01310"
"3778","22.63200","1.88618","0.01321"
"3860","23.12400","1.92726","0.01318"
"3942","23.61600","1.96821","0.01406"
"4024","24.10800","2.00923","0.01474"
"4106","24.60000","2.05024","0.01464"
"4188","25.09200","2.09126","0.01528"
"4270","25.58400","2.13227","0.01474"
"4352","26.07600","2.17323","0.01537"
"4434","26.56800","2.21425","0.01534"
"4516","27.06000","2.25514","0.01486"
"4598","27.55200","2.29622","0.01488"
"4680","28.04400","2.33717","0.01572"
"4762","28.53600","2.37819","0.01580"
"4844","29.02800","2.41914","0.01570"
"4926","29.52000","2.46022","0.01576"
"5008","30.01200","2.50124","0.01654"
"5090","30.50400","2.54225","0.01678"
"5172","30.99600","2.58327","0.01687"
"5254","31.48800","2.62422","0.01770"
"5336","31.98000","2.66524","0.01811"
"5418","32.47200","2.70619","0.01848"
"5500","32.96400","2.74715","0.01783"
"5582","33.45600","2.78817","0.01792"
"5664","33.94800","2.82918","0.01771"
"5746","34.44000","2.87026","0.01822"
"5828","34.93200","2.91121","0.01901"
"5910","35.42400","2.95223","0.01840"
"5992","35.91600","2.99324","0.01755"
"6074","36.40800","3.03420","0.01682"
"6156","36.90000","3.07527","0.01665"
"6238","37.39200","3.11623","0.01672"
"6320","37.88400","3.15725","0.01710"
"6402","38.37600","3.19814","0.01043"
"6484","38.86800","3.23916","0.00870"
"6566","39.36000","3.28023","0.00908"
"6648","39.85200","3.32125","0.00957"
"6730","40.34400","3.36220","0.00916"
"6812","40.83600","3.40322","0.01014"
"6894","41.32800","3.44430","0.01060"
"6976","41.82000","3.48525","0.01022"
"7058","42.31200","3.52627","0.01042"
"7140","42.80400","3.56722","0.01003"
"7222","43.29600","3.60818","0.00991"
"7304","43.78800","3.64919","0.00881"
"7386","44.28000","3.69015","0.00877"
"7468","44.77200","3.73123","0.00918"
"7550","45.26400","3.77218","0.00892"
"7632","45.75600","3.81326","0.00940"
"7714","46.24800","3.85421","0.00956"
"7796","46.74000","3.89523","0.01055"
"7878","47.23200","3.93624","0.01038"
"7960","47.72400","3.97720","0.01065"
"8042","48.21600","4.01828","0.01109"
"8124","48.70800","4.05929","0.01196"
"8206","49.20000","4.10025","0.01169"
"8288","49.69200","4.14120","0.00973"
"8370","50.18400","4.18216","0.01013"
"8452","50.67600","4.22317","0.01030"
"8534","51.16800","4.26425","0.01109"
"8616","51.66000","4.30526","0.01131"
"8698","52.15200","4.34622","0.01137"
"8780","52.64400","4.38724","0.01077"
"8862","53.13600","4.42819","0.01137"
"8944","53.62800","4.46921","0.01156"
"9026","54.12000","4.51028","0.01164"
"9108","54.61200","4.55124","0.01224"
"9190","55.10400","4.59219","0.01240"
"9272","55.59600","4.63315","0.01287"
"9354","56.08800","4.67417","0.01290"
"9436","56.58000","4.71518","0.01269"
"9518","57.07200","4.75620","0.01314"
"9600","57.56400","4.79727","0.01383"
"9682","58.05600","4.83823","0.01356"
"9764","58.54800","4.87924","0.01273"
"9846","59.04000","4.92026","0.01403"
"9928","59.53200","4.96128","0.01378"
"10010","60.02400","5.00223","0.01460"
"10092","60.51600","5.04319","0.01435"
"10174","61.00800","5.08420","0.01419"
"10256","61.50000","5.12516","0.01520"
"10338","61.99200","5.16617","0.01530"
"10420","62.48400","5.20725","0.01492"
"10502","62.97600","5.24821","0.01499"
"10584","63.46800","5.28922","0.01562"
"10666","63.96000","5.33024","0.01665"
"10748","64.45200","5.37119","0.01576"
"10830","64.94400","5.41221","0.01605"
"10912","65.43600","5.45328","0.01638"
"10994","65.92800","5.49424","0.01599"
"11076","66.42000","5.53520","0.01684"
"11158","66.91200","5.57621","0.01689"
"11240","67.40400","5.61717","0.01714"
"11322","67.89600","5.65818","0.01766"
"11404","68.38800","5.69920","0.01772"
"11486","68.88000","5.74027","0.01721"
"11568","69.37200","5.78123","0.01814"
"11650","69.86400","5.82225","0.01821"
"11732","70.35600","5.86320","0.01832"
"11814","70.84800","5.90422","0.01865"
"11896","71.34000","5.94529","0.01812"
"11978","71.83200","5.98625","0.01864"
"12060","72.32400","6.02720","0.01809"
"12142","72.81600","6.06816","0.01821"
"12224","73.30800","6.10923","0.01899"
"12306","73.80000","6.15019","0.01930"
"12388","74.29200","6.19121","0.01894"
"12470","74.78400","6.23222","0.01912"
"12552","75.27600","6.27324","0.01939"
"12634","75.76800","6.31425","0.01977"
"12716","76.26000","6.35521","0.01873"
"12798","76.75200","6.39628","0.01957"
"12880","77.24400","6.43724","0.02025"
"12962","77.73600","6.47826","0.02028"
"13044","78.22800","6.51921","0.02028"
"13126","78.72000","6.56017","0.01978"
"13208","79.21200","6.60118","0.01981"
"13290","79.70400","6.64220","0.02045"
"13372","80.19600","6.68321","0.02054"
"13454","80.68800","6.72417","0.02096"
"13536","81.18000","6.76525","0.02143"
"13618","81.67200","6.80626","0.02138"
"13700","82.16400","6.84722","0.02102"
"13782","82.65600","6.88823","0.02212"
"13864","83.14800","6.92925","0.02240"
"13946","83.64000","6.97026","0.02281"
"14028","84.13200","7.01122","0.02262"
"14110","84.62400","7.05218","0.02207"
"14192","85.11600","7.09313","0.02287"
"14274","85.60800","7.13415","0.02283"
"14356","86.10000","7.17522","0.02279"
"14438","86.59200","7.21624","0.02348"
"14520","87.08400","7.25725","0.02385"
"14602","87.57600","7.29821","0.02373"
"14684","88.06800","7.33923","0.02341"
"14766","88.56000","7.38030","0.02407"
"14848","89.05200","7.42120","0.02417"
"14930","89.54400","7.46221","0.02318"
"15012","90.03600","7.50317","0.02419"
"15094","90.52800","7.54418","0.02368"
"15176","91.02000","7.58520","0.02409"
"15258","91.51200","7.62621","0.02454"
"15340","92.00400","7.66723","0.02485"
"15422","92.49600","7.70819","0.02499"
"15504","92.98800","7.74926","0.02512"
"15586","93.48000","7.79022","0.02569"
"15668","93.97200","7.83129","0.02616"
"15750","94.46400","7.87225","0.02604"
"15832","94.95600","7.91320","0.02631"
"15914","95.44800","7.95422","0.02574"
"15996","95.94000","7.99518","0.02596"
"16078","96.43200","8.03613","0.02417"
"16160","96.92400","8.07721","0.02478"
"16242","97.41600","8.11822","0.02484"
"16324","97.90800","8.15918","0.02492"
"16406","98.40000","8.20019","0.02486"
"16488","98.89200","8.24127","0.02509"
"16570","99.38400","8.28223","0.02589"
"16652","99.87600","8.32324","0.02609"
"16734","100.36800","8.36426","0.02568"
"16816","100.86000","8.40527","0.02524"
"16898","101.35200","8.44617","0.02589"
"16980","101.84400","8.48718","0.02631"
"17062","102.33600","8.52820","0.02657"
"17144","102.82800","8.56916","0.02570"
"17226","103.32000","8.61023","0.02658"
"17308","103.81200","8.65125","0.02676"
"17390","104.30400","8.69226","0.02717"
"17472","104.79600","8.73322","0.02754"
"17554","105.28800","8.77423","0.02753"
"17636","105.78000","8.81525","0.02806"
"17718","106.27200","8.85620","0.02801"
"17800","106.76400","8.89722","0.02846"
"17882","107.25600","8.93824","0.02913"
"17964","107.74800","8.97913","0.02842"
"18046","108.24000","9.02015","0.02866"
"18128","108.73200","9.06116","0.02892"
"18210","109.22400","9.10224","0.02935"
"18292","109.71600","9.14325","0.02883"
"18374","110.20800","9.18427","0.02931"
"18456","110.70000","9.22523","0.02947"
"18538","111.19200","9.26624","0.02957"
"18620","111.68400","9.30726","0.03046"
"18702","112.17600","9.34821","0.03084"
"18784","112.66800","9.38917","0.03092"
"18866","113.16000","9.43019","0.03112"
"18948","113.65200","9.47120","0.03135"
"19030","114.14400","9.51222","0.03141"
"19112","114.63600","9.55323","0.03200"
"19194","115.12800","9.59419","0.03177"
"19276","115.62000","9.63520","0.03215"
"19358","116.11200","9.67628","0.03192"
"19440","116.60400","9.71723","0.03291"
"19522","117.09600","9.75825","0.03253"
"19604","117.58800","9.79926","0.03323"
"19686","118.08000","9.84022","0.03384"
"19768","118.57200","9.88118","0.03412"
"19850","119.06400","9.92213","0.03418"
"19932","119.55600","9.96321","0.03486"
"20014","120.04800","10.00416","0.03505"
"20096","120.54000","10.04524","0.03532"
"20178","121.03200","10.08620","0.03580"
"20260","121.52400","10.12727","0.03635"
"20342","122.01600","10.16823","0.03681"
"20424","122.50800","10.20924","0.03738"
"20506","123.00000","10.25026","0.03756"
"20588","123.49200","10.29121","0.03841"
"20670","123.98400","10.33223","0.03921"
"20752","124.47600","10.37318","0.03956"
"20834","124.96800","10.41420","0.03976"
"20916","125.46000","10.45516","0.04018"
"20998","125.95200","10.49623","0.04049"
"21080","126.44400","10.53719","0.04112"
"21162","126.93600","10.57820","0.04202"
"21244","127.42800","10.61928","0.04219"
"21326","127.92000","10.66023","0.04218"
"21408","128.41200","10.70125","0.04332"
"21490","128.90400","10.74227","0.04304"
"21572","129.39600","10.78322","0.04393"
"21654","129.88800","10.82424","0.04405"
"21736","130.38000","10.86519","0.04467"
"21818","130.87200","10.90621","0.04497"
"21900","131.36400","10.94722","0.04596"
"21982","131.85600","10.98818","0.04614"
"22064","132.34800","11.02925","0.04598"
"22146","132.84000","11.07027","0.04698"
"22228","133.33200","11.11123","0.04716"
"22310","133.82400","11.15218","0.04828"
"22392","134.31600","11.19326","0.04841"
"22474","134.80800","11.23427","0.04880"
"22556","135.30000","11.27529","0.04886"
"22638","135.79200","11.31618","0.04957"
"22720","136.28400","11.35714","0.05001"
"22802","136.77600","11.39822","0.05106"
"22884","137.26800","11.43917","0.05142"
"22966","137.76000","11.48025","0.05149"
"23048","138.25200","11.52120","0.05241"
"23130","138.74400","11.56228","0.05280"
"23212","139.23600","11.60324","0.05396"
"23294","139.72800","11.64425","0.05429"
"23376","140.22000","11.68527","0.05419"
"23458","140.71200","11.72622","0.05509"
"23540","141.20400","11.76724","0.05594"
"23622","141.69600","11.80819","0.05670"
"23704","142.18800","11.84921","0.05778"
"23786","142.68000","11.89017","0.05825"
"23868","143.17200","11.93118","0.05743"
"23950","143.66400","11.97220","0.05916"
"24032","144.15600","12.01321","0.05989"
"24114","144.64800","12.05429","0.06054"
"24196","145.14000","12.09524","0.06144"
"24278","145.63200","12.13632","0.06261"
"24360","146.12400","12.17721","0.06345"
"24442","146.61600","12.21823","0.06468"
"24524","147.10800","12.25919","0.06608"
"24606","147.60000","12.30020","0.06689"
"24688","148.09200","12.34122","0.06806"
"24770","148.58400","12.38217","0.06963"
"24852","149.07600","12.42319","0.07013"
"24934","149.56800","12.46415","0.07155"
"25016","150.06000","12.50522","0.07340"
"25098","150.55200","12.54624","0.07391"
"25180","151.04400","12.58725","0.07548"
"25262","151.53600","12.62821","0.07581"
"25344","152.02800","12.66928","0.06134"
"25426","152.52000","12.71024","0.06224"
"25508","153.01200","12.75119","0.06305"
"25590","153.50400","12.79215","0.06410"
"25672","153.99600","12.83317","0.06560"
"25754","154.48800","12.87418","0.06726"
"25836","154.98000","12.91526","0.06809"
"25918","155.47200","12.95627","0.07001"
"26000","155.96400","12.99723","0.07219"
"26082","156.45600","13.03818","0.07282"
"26164","156.94800","13.07926","0.07478"
"26246","157.44000","13.12028","0.07637"
"26328","157.93200","13.16123","0.07835"
"26410","158.42400","13.20225","0.08032"
"26492","158.91600","13.24320","0.08131"
"26574","159.40800","13.28416","0.08277"
"26656","159.90000","13.32517","0.08372"
"26738","160.39200","13.36625","0.08417"
"26820","160.88400","13.40726","0.08577"
"26902","161.37600","13.44822","0.08610"
"26984","161.86800","13.48924","0.08801"
"27066","162.36000","13.53019","0.08932"
"27148","162.85200","13.57127","0.09039"
"27230","163.34400","13.61228","0.09178"
"27312","163.83600","13.65324","0.09378"
"27394","164.32800","13.69419","0.09503"
"27476","164.82000","13.73515","0.09592"
"27558","165.31200","13.77623","0.09682"
"27640","165.80400","13.81718","0.09775"
"27722","166.29600","13.85826","0.09891"
"27804","166.78800","13.89921","0.10048"
"27886","167.28000","13.94023","0.10168"
"27968","167.77200","13.98124","0.10272"
"28050","168.26400","14.02220","0.10389"
"28132","168.75600","14.06328","0.10530"
"28214","169.24800","14.10423","0.10756"
"28296","169.74000","14.14525","0.10894"
"28378","170.23200","14.18620","0.10990"
"28460","170.72400","14.22716","0.11234"
"28542","171.21600","14.26817","0.11501"
"28624","171.70800","14.30919","0.11530"
"28706","172.20000","14.35021","0.11573"
"28788","172.69200","14.39122","0.11790"
"28870","173.18400","14.43230","0.11914"
"28952","173.67600","14.47325","0.12143"
"29034","174.16800","14.51427","0.12335"
"29116","174.66000","14.55522","0.12509"
"29198","175.15200","14.59624","0.12645"
"29280","175.64400","14.63720","0.12334"
"29362","176.13600","14.67821","0.12414"
"29444","176.62800","14.71923","0.12584"
"29526","177.12000","14.76012","0.12783"
"29608","177.61200","14.80120","0.12934"
"29690","178.10400","14.84227","0.13109"
"29772","178.59600","14.88323","0.13220"
"29854","179.08800","14.92424","0.13278"
"29936","179.58000","14.96526","0.13427"
"30018","180.07200","15.00622","0.13498"
"30100","180.56400","15.04723","0.13585"
"30182","181.05600","15.08825","0.13670"
"30264","181.54800","15.12920","0.13734"
"30346","182.04000","15.17016","0.13803"
"30428","182.53200","15.21124","0.13929"
"30510","183.02400","15.25219","0.14051"
"30592","183.51600","15.29321","0.14094"
"30674","184.00800","15.33422","0.14180"
"30756","184.50000","15.37524","0.14355"
"30838","184.99200","15.41625","0.14436"
"30920","185.48400","15.45721","0.14577"
"31002","185.97600","15.49828","0.14799"
"31084","186.46800","15.53924","0.14966"
"31166","186.96000","15.58026","0.15144"
"31248","187.45200","15.62121","0.15400"
"31330","187.94400","15.66217","0.15692"
"31412","188.43600","15.70312","0.15958"
"31494","188.92800","15.74420","0.16162"
"31576","189.42000","15.78527","0.16604"
"31658","189.91200","15.82617","0.17009"
"31740","190.40400","15.86724","0.17427"
"31822","190.89600","15.90826","0.17807"
"31904","191.38800","15.94928","0.18029"
"31986","191.88000","15.99029","0.18309"
"32068","192.37200","16.03125","0.18457"
"32150","192.86400","16.07220","0.18809"
"32232","193.35600","16.11322","0.19029"
"32314","193.84800","16.15424","0.19339"
"32396","194.34000","16.19513","0.19577"
"32478","194.83200","16.23615","0.19859"
"32560","195.32400","16.27722","0.20025"
"32642","195.81600","16.31824","0.20186"
"32724","196.30800","16.35925","0.20186"
"32806","196.80000","16.40027","0.20085"
"32888","197.29200","16.44128","0.20205"
"32970","197.78400","16.48224","0.20392"
"33052","198.27600","16.52320","0.20667"
"33134","198.76800","16.56421","0.20865"
"33216","199.26000","16.60517","0.20956"
"33298","199.75200","16.64618","0.21240"
"33380","200.24400","16.68720","0.21497"
"33462","200.73600","16.72816","0.21728"
"33544","201.22800","16.76917","0.21970"
"33626","201.72000","16.81025","0.22264"
"33708","202.21200","16.85132","0.22487"
"33790","202.70400","16.89222","0.22702"
"33872","203.19600","16.93323","0.22968"
"33954","203.68800","16.97425","0.23214"
"34036","204.18000","17.01526","0.23483"
"34118","204.67200","17.05622","0.23699"
"34200","205.16400","17.09723","0.23923"
"34282","205.65600","17.13819","0.24109"
"34364","206.14800","17.17921","0.24276"
"34446","206.64000","17.22022","0.24493"
"34528","207.13200","17.26118","0.24574"
"34610","207.62400","17.30225","0.24720"
"34692","208.11600","17.34327","0.24829"
"34774","208.60800","17.38423","0.25015"
"34856","209.10000","17.42524","0.25085"
"34938","209.59200","17.46620","0.25246"
"35020","210.08400","17.50721","0.25498"
"35102","210.57600","17.54823","0.25711"
"35184","211.06800","17.58918","0.25936"
"35266","211.56000","17.63020","0.26190"
"35348","212.05200","17.67122","0.26473"
"35430","212.54400","17.71223","0.26732"
"35512","213.03600","17.75319","0.26980"
"35594","213.52800","17.79426","0.27264"
"35676","214.02000","17.83522","0.27561"
"35758","214.51200","17.87629","0.27855"
"35840","215.00400","17.91725","0.28110"
"35922","215.49600","17.95820","0.28413"
"36004","215.98800","17.99922","0.28692"
"36086","216.48000","18.04018","0.28924"
"36168","216.97200","18.08125","0.29329"
"36250","217.46400","18.12221","0.29590"
"36332","217.95600","18.16322","0.29921"
"36414","218.44800","18.20418","0.30210"
"36496","218.94000","18.24525","0.30596"
"36578","219.43200","18.28627","0.31049"
"36660","219.92400","18.32722","0.31459"
"36742","220.41600","18.36824","0.32214"
"36824","220.90800","18.40926","0.32893"
"36906","221.40000","18.45021","0.33336"
"36988","221.89200","18.49117","0.33932"
"37070","222.38400","18.53218","0.34277"
"37152","222.87600","18.57320","0.34620"
"37234","223.36800","18.61422","0.34892"
"37316","223.86000","18.65523","0.35079"
"37398","224.35200","18.69625","0.35299"
"37480","224.84400","18.73726","0.35423"
"37562","225.33600","18.77828","0.35562"
"37644","225.82800","18.81923","0.35610"
"37726","226.32000","18.86025","0.35742"
"37808","226.81200","18.90126","0.35866"
"37890","227.30400","18.94222","0.35986"
"37972","227.79600","18.98318","0.36201"
"38054","228.28800","19.02419","0.36381"
"38136","228.78000","19.06515","0.36685"
"38218","229.27200","19.10622","0.37001"
"38300","229.76400","19.14724","0.37392"
"38382","230.25600","19.18820","0.37766"
"38464","230.74800","19.22927","0.38174"
"38546","231.24000","19.27023","0.38548"
"38628","231.73200","19.31124","0.38903"
"38710","232.22400","19.35220","0.39373"
"38792","232.71600","19.39321","0.39875"
"38874","233.20800","19.43423","0.39162"
"38956","233.70000","19.47518","0.38817"
"39038","234.19200","19.51620","0.38659"
"39120","234.68400","19.55722","0.39034"
"39202","235.17600","19.59823","0.39349"
"39284","235.66800","19.63919","0.39721"
"39366","236.16000","19.68026","0.40138"
"39448","236.65200","19.72122","0.40516"
"39530","237.14400","19.76224","0.40888"
"39612","237.63600","19.80331","0.41248"
"39694","238.12800","19.84426","0.41595"
"39776","238.62000","19.88528","0.41791"
"39858","239.11200","19.92618","0.42115"
"39940","239.60400","19.96719","0.42521"
"40022","240.09600","20.00815","0.42875"
"40104","240.58800","20.04922","0.43204"
"40186","241.08000","20.09024","0.43488"
"40268","241.57200","20.13119","0.43822"
"40350","242.06400","20.17227","0.44027"
"40432","242.55600","20.21323","0.22631"
"40514","243.04800","20.25424","0.22943"
"40596","243.54000","20.29532","0.23780"
"40678","244.03200","20.33621","0.23438"
"40760","244.52400","20.37717","0.23886"
"40842","245.01600","20.41819","0.24389"
"40924","245.50800","20.45920","0.24226"
"41006","246.00000","20.50016","0.24848"
"41088","246.49200","20.54117","0.24641"
"41170","246.98400","20.58219","0.25005"
"41252","247.47600","20.62320","0.25266"
"41334","247.96800","20.66428","0.25268"
"41416","248.46000","20.70530","0.26009"
"41498","248.95200","20.74631","0.25697"
"41580","249.44400","20.78720","0.26421"
"41662","249.93600","20.82822","0.26262"
"41744","250.42800","20.86924","0.26748"
"41826","250.92000","20.91013","0.26763"
"41908","251.41200","20.95121","0.27054"
"41990","251.90400","20.99223","0.27333"
"42072","252.39600","21.03318","0.27495"
"42154","252.88800","21.07419","0.28050"
"42236","253.38000","21.11527","0.28011"
"42318","253.87200","21.15623","0.28528"
"42400","254.36400","21.19718","0.28396"
"42482","254.85600","21.23826","0.28895"
"42564","255.34800","21.27921","0.28802"
"42646","255.84000","21.32023","0.29287"
"42728","256.33200","21.36119","0.29102"
"42810","256.82400","21.40220","0.29530"
"42892","257.31600","21.44316","0.29487"
"42974","257.80800","21.48423","0.29920"
"43056","258.30000","21.52525","0.29801"
"43138","258.79200","21.56620","0.30277"
"43220","259.28400","21.60728","0.30389"
"43302","259.77600","21.64824","0.31132"
"43384","260.26800","21.68925","0.31249"
"43466","260.76000","21.73027","0.32050"
"43548","261.25200","21.77122","0.32293"
"43630","261.74400","21.81218","0.33049"
"43712","262.23600","21.85319","0.33306"
"43794","262.72800","21.89421","0.33741"
"43876","263.22000","21.93517","0.34065"
"43958","263.71200","21.97618","0.34365"
"44040","264.20400","22.01726","0.34649"
"44122","264.69600","22.05821","0.34775"
"44204","265.18800","22.09923","0.35029"
"44286","265.68000","22.14024","0.35138"
"44368","266.17200","22.18132","0.35380"
"44450","266.66400","22.22227","0.35378"
"44532","267.15600","22.26323","0.35466"
"44614","267.64800","22.30419","0.35585"
"44696","268.14000","22.34520","0.35651"
"44778","268.63200","22.38622","0.35823"
"44860","269.12400","22.42723","0.35858"
"44942","269.61600","22.46825","0.36023"
"45024","270.10800","22.50914","0.36165"
"45106","270.60000","22.55022","0.36266"
"45188","271.09200","22.59124","0.36571"
"45270","271.58400","22.63219","0.36792"
"45352","272.07600","22.67327","0.37198"
"45434","272.56800","22.71428","0.37537"
"45516","273.06000","22.75524","0.38012"
"45598","273.55200","22.79619","0.38537"
"45680","274.04400","22.83721","0.38767"
"45762","274.53600","22.87811","0.39110"
"45844","275.02800","22.91918","0.39453"
"45926","275.52000","22.96026","0.39776"
"46008","276.01200","23.00121","0.40220"
"46090","276.50400","23.04223","0.40526"
"46172","276.99600","23.08324","0.15933"
"46254","277.48800","23.12426","0.15562"
"46336","277.98000","23.16527","0.16919"
"46418","278.47200","23.20623","0.19643"
"46500","278.96400","23.24725","0.19179"
"46582","279.45600","23.28820","0.19003"
"46664","279.94800","23.32922","0.19734"
"46746","280.44000","23.37017","0.21224"
"46828","280.93200","23.41119","0.21181"
"46910","281.42400","23.45220","0.21197"
"46992","281.91600","23.49322","0.22456"
"47074","282.40800","23.53424","0.23152"
"47156","282.90000","23.57525","0.22890"
"47238","283.39200","23.61627","0.23665"
"47320","283.88400","23.65722","0.24295"
"47402","284.37600","23.69818","0.24263"
"47484","284.86800","23.73925","0.24680"
"47566","285.36000","23.78015","0.25001"
"47648","285.85200","23.82123","0.25076"
"47730","286.34400","23.86224","0.25633"
"47812","286.83600","23.90320","0.25837"
"47894","287.32800","23.94415","0.26106"
"47976","287.82000","23.98523","0.26566"
"48058","288.31200","24.02624","0.26698"
"48140","288.80400","24.06726","0.27160"
"48222","289.29600","24.10827","0.27490"
"48304","289.78800","24.14929","0.27916"
"48386","290.28000","24.19025","0.28367"
"48468","290.77200","24.23120","0.28537"
"48550","291.26400","24.27222","0.28982"
"48632","291.75600","24.31317","0.29253"
"48714","292.24800","24.35419","0.29633"
"48796","292.74000","24.39520","0.29941"
"48878","293.23200","24.43622","0.30318"
"48960","293.72400","24.47724","0.30752"
"49042","294.21600","24.51825","0.31035"
"49124","294.70800","24.55927","0.31426"
"49206","295.20000","24.60028","0.31874"
"49288","295.69200","24.64118","0.32508"
"49370","296.18400","24.68225","0.32945"
"49452","296.67600","24.72321","0.33521"
"49534","297.16800","24.76417","0.33874"
"49616","297.66000","24.80524","0.34112"
"49698","298.15200","24.84620","0.34373"
"49780","298.64400","24.88721","0.34670"
"49862","299.13600","24.92823","0.34919"
"49944","299.62800","24.96924","0.35094"
"50026","300.12000","25.01026","0.35268"
"50108","300.61200","25.05128","0.35424"
"50190","301.10400","25.09223","0.35516"
"50272","301.59600","25.13319","0.35661"
"50354","302.08800","25.17420","0.35728"
"50436","302.58000","25.21516","0.35897"
"50518","303.07200","25.25624","0.35991"
"50600","303.56400","25.29719","0.36182"
"50682","304.05600","25.33821","0.36461"
"50764","304.54800","25.37922","0.36742"
"50846","305.04000","25.42024","0.37023"
"50928","305.53200","25.46125","0.37533"
"51010","306.02400","25.50221","0.37915"
"51092","306.51600","25.54328","0.38203"
"51174","307.00800","25.58424","0.38442"
"51256","307.50000","25.62526","0.38781"
"51338","307.99200","25.66615","0.39184"
"51420","308.48400","25.70717","0.39553"
"51502","308.97600","25.74818","0.39939"
"51584","309.46800","25.78920","0.40370"
"51666","309.96000","25.83021","0.40719"
"51748","310.45200","25.87123","0.41138"
"51830","310.94400","25.91224","0.41460"
"51912","311.43600","25.95326","0.41683"
"51994","311.92800","25.99422","0.41868"
"52076","312.42000","26.03523","0.42161"
"52158","312.91200","26.07625","0.42434"
"52240","313.40400","26.11721","0.42743"
"52322","313.89600","26.15822","0.43007"
"52404","314.38800","26.19917","0.43314"
"52486","314.88000","26.24019","0.43568"
"52568","315.37200","26.28121","0.43899"
"52650","315.86400","26.32222","0.44134"
"52732","316.35600","26.36324","0.44422"
"52814","316.84800","26.40419","0.44640"
"52896","317.34000","26.44527","0.44852"
"52978","317.83200","26.48628","0.45047"
"53060","318.32400","26.52724","0.45216"
"53142","318.81600","26.56826","0.45510"
"53224","319.30800","26.60921","0.45829"
"53306","319.80000","26.65017","0.46131"
"53388","320.29200","26.69118","0.46594"
"53470","320.78400","26.73226","0.46888"
"53552","321.27600","26.77321","0.47315"
"53634","321.76800","26.81423","0.47715"
"53716","322.26000","26.85525","0.48125"
"53798","322.75200","26.89620","0.48445"
"53880","323.24400","26.93722","0.48809"
"53962","323.73600","26.97829","0.36301"
"54044","324.22800","27.01925","0.36038"
"54126","324.72000","27.06027","0.36067"
"54208","325.21200","27.10116","0.36050"
"54290","325.70400","27.14218","0.36197"
"54372","326.19600","27.18319","0.36286"
"54454","326.68800","27.22421","0.36480"
"54536","327.18000","27.26528","0.36640"
"54618","327.67200","27.30618","0.36909"
"54700","328.16400","27.34725","0.37183"
"54782","328.65600","27.38821","0.37562"
"54864","329.14800","27.42929","0.38005"
"54946","329.64000","27.47024","0.38400"
"55028","330.13200","27.51126","0.38762"
"55110","330.62400","27.55221","0.39036"
"55192","331.11600","27.59323","0.39356"
"55274","331.60800","27.63424","0.39653"
"55356","332.10000","27.67514","0.39954"
"55438","332.59200","27.71622","0.40288"
"55520","333.08400","27.75723","0.40580"
"55602","333.57600","27.79819","0.40932"
"55684","334.06800","27.83926","0.41246"
"55766","334.56000","27.88022","0.41474"
"55848","335.05200","27.92129","0.41766"
"55930","335.54400","27.96225","0.42062"
"56012","336.03600","28.00327","0.42351"
"56094","336.52800","28.04422","0.42669"
"56176","337.02000","28.08518","0.42906"
"56258","337.51200","28.12613","0.43219"
"56340","338.00400","28.16721","0.43348"
"56422","338.49600","28.20822","0.38590"
"56504","338.98800","28.24918","0.39228"
"56586","339.48000","28.29025","0.39278"
"56668","339.97200","28.33121","0.39915"
"56750","340.46400","28.37223","0.40007"
"56832","340.95600","28.41324","0.40250"
"56914","341.44800","28.45426","0.40504"
"56996","341.94000","28.49527","0.40710"
"57078","342.43200","28.53617","0.41177"
"57160","342.92400","28.57719","0.41342"
"57242","343.41600","28.61814","0.41573"
"57324","343.90800","28.65922","0.41721"
"57406","344.40000","28.70023","0.42003"
"57488","344.89200","28.74125","0.42333"
"57570","345.38400","28.78220","0.42549"
"57652","345.87600","28.82322","0.42941"
"57734","346.36800","28.86424","0.43133"
"57816","346.86000","28.90525","0.43348"
"57898","347.35200","28.94621","0.43558"
"57980","347.84400","28.98722","0.43728"
"58062","348.33600","29.02818","0.43897"
"58144","348.82800","29.06919","0.44061"
"58226","349.32000","29.11015","0.44250"
"58308","349.81200","29.15123","0.44499"
"58390","350.30400","29.19224","0.44625"
"58472","350.79600","29.23319","0.44763"
"58554","351.28800","29.27427","0.44920"
"58636","351.78000","29.31523","0.45054"
"58718","352.27200","29.35630","0.45202"
"58800","352.76400","29.39726","0.45403"
"58882","353.25600","29.43822","0.45584"
"58964","353.74800","29.47917","0.45828"
"59046","354.24000","29.52019","0.46104"
"59128","354.73200","29.56120","0.46466"
"59210","355.22400","29.60216","0.46671"
"59292","355.71600","29.64323","0.03399"
"59374","356.20800","29.68419","0.00302"
"59456","356.70000","29.72527","0.00747"
"59538","357.19200","29.76628","0.03254"
"59620","357.68400","29.80717","0.03554"
"59702","358.17600","29.84825","0.01746"
"59784","358.66800","29.88927","0.02747"
"59866","359.16000","29.93028","0.04268"
"59948","359.65200","29.97118","0.02457"
"60030","360.14400","30.01219","0.02323"
"60112","360.63600","30.05315","0.04033"
"60194","361.12800","30.09417","0.02732"
"60276","361.62000","30.13524","0.02525"
"60358","362.11200","30.17620","0.03734"
"60440","362.60400","30.21727","0.02954"
"60522","363.09600","30.25823","0.02948"
"60604","363.58800","30.29924","0.03834"
"60686","364.08000","30.34026","0.03398"
"60768","364.57200","30.38121","0.03595"
"60850","365.06400","30.42223","0.04291"
"60932","365.55600","30.46325","0.04134"
"61014","366.04800","30.50414","0.04235"
"61096","366.54000","30.54516","0.04512"
"61178","367.03200","30.58617","0.04639"
"61260","367.52400","30.62725","0.04498"
"61342","368.01600","30.66821","0.04503"
"61424","368.50800","30.70928","0.04660"
"61506","369.00000","30.75024","0.04620"
"61588","369.49200","30.79125","0.04606"
"61670","369.98400","30.83227","0.04664"
"61752","370.47600","30.87322","0.04902"
"61834","370.96800","30.91418","0.04988"
"61916","371.46000","30.95520","0.05045"
"61998","371.95200","30.99621","0.05158"
"62080","372.44400","31.03716","0.05339"
"62162","372.93600","31.07824","0.05485"
"62244","373.42800","31.11920","0.05489"
"62326","373.92000","31.16021","0.05472"
"62408","374.41200","31.20129","0.05468"
"62490","374.90400","31.24218","0.05664"
"62572","375.39600","31.28326","0.05826"
"62654","375.88800","31.32427","0.06018"
"62736","376.38000","31.36523","0.06109"
"62818","376.87200","31.40619","0.06261"
"62900","377.36400","31.44714","0.06505"
"62982","377.85600","31.48822","0.06685"
"63064","378.34800","31.52917","0.06902"
"63146","378.84000","31.57025","0.07051"
"63228","379.33200","31.61120","0.07188"
"63310","379.82400","31.65228","0.07483"
"63392","380.31600","31.69324","0.07622"
"63474","380.80800","31.73419","0.07847"
"63556","381.30000","31.77527","0.08057"
"63638","381.79200","31.81622","0.08236"
"63720","382.28400","31.85724","0.08435"
"63802","382.77600","31.89819","0.08618"
"63884","383.26800","31.93921","0.08755"
"63966","383.76000","31.98016","0.08834"
"64048","384.25200","32.02124","0.09079"
"64130","384.74400","32.06219","0.09161"
"64212","385.23600","32.10321","0.09291"
"64294","385.72800","32.14423","0.09443"
"64376","386.22000","32.18524","0.09625"
"64458","386.71200","32.22626","0.09725"
"64540","387.20400","32.26721","0.09870"
"64622","387.69600","32.30823","0.09931"
"64704","388.18800","32.34919","0.10129"
"64786","388.68000","32.39020","0.10235"
"64868","389.17200","32.43116","0.10455"
"64950","389.66400","32.47218","0.10611"
"65032","390.15600","32.51319","0.10867"
"65114","390.64800","32.55421","0.11088"
"65196","391.14000","32.59522","0.11313"
"65278","391.63200","32.63624","0.11514"
"65360","392.12400","32.67719","0.11826"
"65442","392.61600","32.71827","0.12081"
"65524","393.10800","32.75928","0.12260"
"65606","393.60000","32.80030","0.12483"
"65688","394.09200","32.84119","0.12641"
"65770","394.58400","32.88215","0.12862"
"65852","395.07600","32.92323","0.13029"
"65934","395.56800","32.96418","0.13150"
"66016","396.06000","33.00520","0.13303"
"66098","396.55200","33.04621","0.13390"
"66180","397.04400","33.08729","0.13466"
"66262","397.53600","33.12824","0.13568"
"66344","398.02800","33.16926","0.13606"
"66426","398.52000","33.21027","0.13676"
"66508","399.01200","33.25123","0.13775"
"66590","399.50400","33.29219","0.13874"
"66672","399.99600","33.33320","0.13955"
"66754","400.48800","33.37422","0.14027"
"66836","400.98000","33.41517","0.14085"
"66918","401.47200","33.45619","0.14195"
"67000","401.96400","33.49726","0.01069"
"67082","402.45600","33.53822","0.02734"
"67164","402.94800","33.57924","0.02358"
"67246","403.44000","33.62025","0.02574"
"67328","403.93200","33.66127","0.03000"
"67410","404.42400","33.70222","0.03126"
"67492","404.91600","33.74324","0.03520"
"67574","405.40800","33.78426","0.03829"
"67656","405.90000","33.82521","0.03873"
"67738","406.39200","33.86617","0.04159"
"67820","406.88400","33.90718","0.04185"
"67902","407.37600","33.94820","0.04101"
"67984","407.86800","33.98921","0.04057"
"68066","408.36000","34.03029","0.03883"
"68148","408.85200","34.07119","0.03624"
"68230","409.34400","34.11220","0.03433"
"68312","409.83600","34.15322","0.03098"
"68394","410.32800","34.19423","0.02891"
"68476","410.82000","34.23524","0.02799"
"68558","411.31200","34.27620","0.02715"
"68640","411.80400","34.31722","0.02736"
"68722","412.29600","34.35817","0.02882"
"68804","412.78800","34.39919","0.03047"
"68886","413.28000","34.44020","0.03272"
"68968","413.77200","34.48122","0.03582"
"69050","414.26400","34.52224","0.03867"
"69132","414.75600","34.56319","0.04030"
"69214","415.24800","34.60427","0.04206"
"69296","415.74000","34.64529","0.04223"
"69378","416.23200","34.68624","0.04251"
"69460","416.72400","34.72720","0.04155"
"69542","417.21600","34.76821","0.04039"
"69624","417.70800","34.80917","0.03976"
"69706","418.20000","34.85012","0.03915"
"69788","418.69200","34.89120","0.03872"
"69870","419.18400","34.93222","0.03913"
"69952","419.67600","34.97317","0.04071"
"70034","420.16800","35.01424","0.04260"
"70116","420.66000","35.05526","0.04417"
"70198","421.15200","35.09628","0.04523"
"70280","421.64400","35.13723","0.04592"
"70362","422.13600","35.17825","0.04613"
"70444","422.62800","35.21920","0.04616"
"70526","423.12000","35.26016","0.04595"
"70608","423.61200","35.30117","0.04570"
"70690","424.10400","35.34219","0.04553"
"70772","424.59600","35.38321","0.04633"
"70854","425.08800","35.42422","0.04679"
"70936","425.58000","35.46524","0.04767"
"71018","426.07200","35.50625","0.04846"
"71100","426.56400","35.54727","0.04890"
"71182","427.05600","35.58828","0.04938"
"71264","427.54800","35.62924","0.04964"
"71346","428.04000","35.67025","0.04957"
"71428","428.53200","35.71121","0.04986"
"71510","429.02400","35.75222","0.04916"
"71592","429.51600","35.79312","0.04971"
"71674","430.00800","35.83420","0.05037"
"71756","430.50000","35.87516","0.05122"
"71838","430.99200","35.91623","0.05107"
"71920","431.48400","35.95731","0.05175"
"72002","431.97600","35.99820","0.05196"
"72084","432.46800","36.03928","0.05182"
"72166","432.96000","36.08023","0.05204"
"72248","433.45200","36.12125","0.05248"
"72330","433.94400","36.16220","0.05313"
"72412","434.43600","36.20322","0.05302"
"72494","434.92800","36.24417","0.05440"
"72576","435.42000","36.28513","0.05472"
"72658","435.91200","36.32621","0.05537"
"72740","436.40400","36.36722","0.05506"
"72822","436.89600","36.40824","0.05588"
"72904","437.38800","36.44925","0.05610"
"72986","437.88000","36.49027","0.05697"
"73068","438.37200","36.53122","0.05750"
"73150","438.86400","36.57224","0.05866"
"73232","439.35600","36.61325","0.05927"
"73314","439.84800","36.65421","0.05759"
"73396","440.34000","36.69517","0.05716"
"73478","440.83200","36.73618","0.05780"
"73560","441.32400","36.77720","0.05847"
"73642","441.81600","36.81821","0.05975"
"73724","442.30800","36.85917","0.06047"
"73806","442.80000","36.90025","0.06127"
"73888","443.29200","36.94120","0.06164"
"73970","443.78400","36.98222","0.06217"
"74052","444.27600","37.02330","0.06298"
"74134","444.76800","37.06425","0.06303"
"74216","445.26000","37.10527","0.06488"
"74298","445.75200","37.14622","0.06570"
"74380","446.24400","37.18718","0.06605"
"74462","446.73600","37.22813","0.06646"
"74544","447.22800","37.26921","0.06535"
"74626","447.72000","37.31022","0.06539"
"74708","448.21200","37.35118","0.06702"
"74790","448.70400","37.39225","0.06500"
"74872","449.19600","37.43327","0.06706"
"74954","449.68800","37.47429","0.06874"
"75036","450.18000","37.51530","0.07043"
"75118","450.67200","37.55620","0.07050"
"75200","451.16400","37.59721","0.07112"
"75282","451.65600","37.63823","0.07333"
"75364","452.14800","37.67924","0.07419"
"75446","452.64000","37.72014","0.07410"
"75528","453.13200","37.76115","0.07564"
"75610","453.62400","37.80223","0.07652"
"75692","454.11600","37.84325","0.07860"
"75774","454.60800","37.88426","0.08056"
"75856","455.10000","37.92528","0.08129"
"75938","455.59200","37.96623","0.08230"
"76020","456.08400","38.00719","0.08338"
"76102","456.57600","38.04820","0.08514"
"76184","457.06800","38.08922","0.08616"
"76266","457.56000","38.13018","0.08625"
"76348","458.05200","38.17120","0.08642"
"76430","458.54400","38.21221","0.08729"
"76512","459.03600","38.25323","0.08869"
"76594","459.52800","38.29418","0.08974"
"76676","460.02000","38.33525","0.09111"
"76758","460.51200","38.37627","0.09233"
"76840","461.00400","38.41723","0.09348"
"76922","461.49600","38.45824","0.09415"
"77004","461.98800","38.49926","0.09578"
"77086","462.48000","38.54021","0.09727"
"77168","462.97200","38.58123","0.09833"
"77250","463.46400","38.62225","0.10002"
"77332","463.95600","38.66320","0.10083"
"77414","464.44800","38.70422","0.10153"
"77496","464.94000","38.74517","0.10363"
"77578","465.43200","38.78619","0.10554"
"77660","465.92400","38.82726","0.10727"
"77742","466.41600","38.86828","0.10966"
"77824","466.90800","38.90923","0.11147"
"77906","467.40000","38.95025","0.11349"
"77988","467.89200","38.99121","0.11603"
"78070","468.38400","39.03222","0.11891"
"78152","468.87600","39.07318","0.12109"
"78234","469.36800","39.11419","0.12233"
"78316","469.86000","39.15515","0.12427"
"78398","470.35200","39.19622","0.12431"
"78480","470.84400","39.23718","0.12558"
"78562","471.33600","39.27819","0.12733"
"78644","471.82800","39.31927","0.12806"
"78726","472.32000","39.36023","0.12970"
"78808","472.81200","39.40130","0.12998"
"78890","473.30400","39.44220","0.13167"
"78972","473.79600","39.48328","0.13296"
"79054","474.28800","39.52423","0.13381"
"79136","474.78000","39.56519","0.13449"
"79218","475.27200","39.60620","0.13535"
"79300","475.76400","39.64716","0.13600"
"79382","476.25600","39.68817","0.13648"
"79464","476.74800","39.72919","0.13755"
"79546","477.24000","39.77026","0.13889"
"79628","477.73200","39.81128","0.13975"
"79710","478.22400","39.85223","0.14093"
"79792","478.71600","39.89325","0.14186"
"79874","479.20800","39.93420","0.14265"
"79956","479.70000","39.97522","0.14426"
"80038","480.19200","40.01618","0.14549"
"80120","480.68400","40.05719","0.14659"
"80202","481.17600","40.09815","0.14791"
"80284","481.66800","40.13923","0.14971"
"80366","482.16000","40.18018","0.15133"
"80448","482.65200","40.22120","0.15267"
"80530","483.14400","40.26227","0.15492"
"80612","483.63600","40.30323","0.15638"
"80694","484.12800","40.34424","0.15851"
"80776","484.62000","40.38526","0.16059"
"80858","485.11200","40.42628","0.16500"
"80940","485.60400","40.46723","0.16882"
"81022","486.09600","40.50819","0.17133"
"81104","486.58800","40.54920","0.17561"
"81186","487.08000","40.59016","0.17887"
"81268","487.57200","40.63123","0.18008"
"81350","488.06400","40.67225","0.18399"
"81432","488.55600","40.71321","0.18596"
"81514","489.04800","40.75422","0.18874"
"81596","489.54000","40.79530","0.19026"
"81678","490.03200","40.83625","0.19181"
"81760","490.52400","40.87720","0.19360"
"81842","491.01600","40.91822","0.19541"
"81924","491.50800","40.95924","0.19731"
"82006","492.00000","41.00019","0.19966"
"82088","492.49200","41.04121","0.20175"
"82170","492.98400","41.08216","0.20400"
"82252","493.47600","41.12318","0.20586"
"82334","493.96800","41.16414","0.20735"
"82416","494.46000","41.20521","0.20857"
"82498","494.95200","41.24623","0.21010"
"82580","495.44400","41.28724","0.21175"
"82662","495.93600","41.32826","0.21284"
"82744","496.42800","41.36921","0.21602"
"82826","496.92000","41.41029","0.21883"
"82908","497.41200","41.45119","0.22063"
"82990","497.90400","41.49220","0.22232"
"83072","498.39600","41.53315","0.22473"
"83154","498.88800","41.57417","0.22700"
"83236","499.38000","41.61525","0.22892"
"83318","499.87200","41.65620","0.23037"
"83400","500.36400","41.69722","0.23231"
"83482","500.85600","41.73817","0.23403"
"83564","501.34800","41.77925","0.23615"
"83646","501.84000","41.82027","0.23762"
"83728","502.33200","41.86122","0.23922"
"83810","502.82400","41.90218","0.24049"
"83892","503.31600","41.94325","0.24140"
"83974","503.80800","41.98421","0.24252"
"84056","504.30000","42.02517","0.24306"
"84138","504.79200","42.06618","0.24404"
"84220","505.28400","42.10720","0.24426"
"84302","505.77600","42.14821","0.24495"
"84384","506.26800","42.18923","0.24511"
"84466","506.76000","42.23024","0.24517"
"84548","507.25200","42.27120","0.24538"
"84630","507.74400","42.31222","0.24505"
"84712","508.23600","42.35323","0.24520"
"84794","508.72800","42.39425","0.24460"
"84876","509.22000","42.43514","0.24522"
"84958","509.71200","42.47615","0.24493"
"85040","510.20400","42.51723","0.24500"
"85122","510.69600","42.55819","0.24511"
"85204","511.18800","42.59914","0.24488"
"85286","511.68000","42.64028","0.24537"
"85368","512.17200","42.68123","0.24587"
"85450","512.66400","42.72219","0.24617"
"85532","513.15600","42.76327","0.24736"
"85614","513.64800","42.80422","0.24777"
"85696","514.14000","42.84524","0.24793"
"85778","514.63200","42.88620","0.24880"
"85860","515.12400","42.92721","0.24950"
"85942","515.61600","42.96817","0.24994"
"86024","516.10800","43.00919","0.25055"
"86106","516.60000","43.05020","0.25125"
"86188","517.09200","43.09122","0.25200"
"86270","517.58400","43.13229","0.25267"
"86352","518.07600","43.17324","0.25348"
"86434","518.56800","43.21426","0.25417"
"86516","519.06000","43.25528","0.25457"
"86598","519.55200","43.29623","0.25494"
"86680","520.04400","43.33719","0.25570"
"86762","520.53600","43.37820","0.25610"
"86844","521.02800","43.41922","0.25639"
"86926","521.52000","43.46017","0.25785"
"87008","522.01200","43.50119","0.25889"
"87090","522.50400","43.54220","0.25979"
"87172","522.99600","43.58322","0.25990"
"87254","523.48800","43.62423","0.26080"
"87336","523.98000","43.66525","0.26154"
"87418","524.47200","43.70626","0.26281"
"87500","524.96400","43.74722","0.26342"
"87582","525.45600","43.78824","0.26427"
"87664","525.94800","43.82920","0.26503"
"87746","526.44000","43.87015","0.26611"
"87828","526.93200","43.91117","0.26760"
"87910","527.42400","43.95218","0.26818"
"87992","527.91600","43.99326","0.26929"
"88074","528.40800","44.03422","0.27078"
"88156","528.90000","44.07523","0.27232"
"88238","529.39200","44.11625","0.27274"
"88320","529.88400","44.15720","0.27381"
"88402","530.37600","44.19822","0.27537"
"88484","530.86800","44.23929","0.27636"
"88566","531.36000","44.28019","0.27809"
"88648","531.85200","44.32120","0.27767"
"88730","532.34400","44.36222","0.27915"
"88812","532.83600","44.40312","0.27969"
"88894","533.32800","44.44419","0.28069"
"88976","533.82000","44.48526","0.28232"
"89058","534.31200","44.52622","0.28263"
"89140","534.80400","44.56718","0.28399"
"89222","535.29600","44.60825","0.28457"
"89304","535.78800","44.64927","0.28585"
"89386","536.28000","44.69028","0.28762"
"89468","536.77200","44.73124","0.28827"
"89550","537.26400","44.77225","0.28981"
"89632","537.75600","44.81321","0.29125"
"89714","538.24800","44.85417","0.29283"
"89796","538.74000","44.89518","0.29411"
"89878","539.23200","44.93620","0.29560"
"89960","539.72400","44.97721","0.29699"
"90042","540.21600","45.01823","0.29830"
"90124","540.70800","45.05925","0.29986"
"90206","541.20000","45.10027","0.30183"
"90288","541.69200","45.14128","0.30223"
"90370","542.18400","45.18224","0.30435"
"90452","542.67600","45.22325","0.30560"
"90534","543.16800","45.26427","0.30600"
"90616","543.66000","45.30516","0.30912"
"90698","544.15200","45.34618","0.31011"
"90780","544.64400","45.38719","0.31157"
"90862","545.13600","45.42820","0.31336"
"90944","545.62800","45.46917","0.31579"
"91026","546.12000","45.51023","0.31887"
"91108","546.61200","45.55125","0.32289"
"91190","547.10400","45.59227","0.32586"
"91272","547.59600","45.63323","0.33058"
"91354","548.08800","45.67424","0.33332"
"91436","548.58000","45.71526","0.33648"
"91518","549.07200","45.75615","0.33861"
"91600","549.56400","45.79723","0.34044"
"91682","550.05600","45.83818","0.34307"
"91764","550.54800","45.87920","0.34478"
"91846","551.04000","45.92022","0.34666"
"91928","551.53200","45.96123","0.34798"
"92010","552.02400","46.00219","0.34938"
"92092","552.51600","46.04320","0.35029"
"92174","553.00800","46.08428","0.35141"
"92256","553.50000","46.12523","0.35260"
"92338","553.99200","46.16618","0.35303"
"92420","554.48400","46.20720","0.35369"
"92502","554.97600","46.24816","0.35469"
"92584","555.46800","46.28923","0.35508"
"92666","555.96000","46.33019","0.35565"
"92748","556.45200","46.37121","0.35624"
"92830","556.94400","46.41217","0.35699"
"92912","557.43600","46.45324","0.35779"
"92994","557.92800","46.49425","0.35851"
"93076","558.42000","46.53521","0.35947"
"93158","558.91200","46.57628","0.36019"
"93240","559.40400","46.61724","0.36034"
"93322","559.89600","46.65820","0.36151"
"93404","560.38800","46.69921","0.36227"
"93486","560.88000","46.74017","0.36346"
"93568","561.37200","46.78125","0.36386"
"93650","561.86400","46.82220","0.36554"
"93732","562.35600","46.86322","0.36699"
"93814","562.84800","46.90417","0.36838"
"93896","563.34000","46.94525","0.36947"
"93978","563.83200","46.98626","0.37087"
"94060","564.32400","47.02721","0.37082"
"94142","564.81600","47.06829","0.37072"
"94224","565.30800","47.10925","0.37329"
"94306","565.80000","47.15026","0.37420"
"94388","566.29200","47.19116","0.37667"
"94470","566.78400","47.23217","0.37831"
"94552","567.27600","47.27319","0.38097"
"94634","567.76800","47.31421","0.38296"
"94716","568.26000","47.35522","0.38430"
"94798","568.75200","47.39618","0.38651"
"94880","569.24400","47.43726","0.38805"
"94962","569.73600","47.47821","0.38911"
"95044","570.22800","47.51923","0.39070"
"95126","570.72000","47.56024","0.39316"
"95208","571.21200","47.60126","0.39425"
"95290","571.70400","47.64227","0.39566"
"95372","572.19600","47.68317","0.39757"
"95454","572.68800","47.72419","0.39983"
"95536","573.18000","47.76514","0.40174"
"95618","573.67200","47.80622","0.40385"
"95700","574.16400","47.84723","0.40520"
"95782","574.65600","47.88825","0.40775"
"95864","575.14800","47.92921","0.40889"
"95946","575.64000","47.97028","0.40989"
"96028","576.13200","48.01123","0.41165"
"96110","576.62400","48.05219","0.41284"
"96192","577.11600","48.09327","0.41471"
"96274","577.60800","48.13422","0.41517"
"96356","578.10000","48.17517","0.41512"
"96438","578.59200","48.21619","0.41546"
"96520","579.08400","48.25727","0.00679"
"96602","579.57600","48.29822","0.00938"
"96684","580.06800","48.33918","0.00916"
"96766","580.56000","48.38025","0.00663"
"96848","581.05200","48.42121","0.00462"
"96930","581.54400","48.46223","0.00431"
"97012","582.03600","48.50330","0.00788"
"97094","582.52800","48.54426","0.00647"
"97176","583.02000","48.58521","0.00556"
"97258","583.51200","48.62617","0.00442"
"97340","584.00400","48.66719","0.00489"
"97422","584.49600","48.70820","0.00715"
"97504","584.98800","48.74922","0.00549"
"97586","585.48000","48.79023","0.00693"
"97668","585.97200","48.83119","0.00465"
"97750","586.46400","48.87226","0.00488"
"97832","586.95600","48.91322","0.00710"
"97914","587.44800","48.95424","0.00548"
"97996","587.94000","48.99525","0.00608"
"98078","588.43200","49.03626","0.00488"
"98160","588.92400","49.07722","0.00475"
"98242","589.41600","49.11818","0.00690"
"98324","589.90800","49.15919","0.00529"
"98406","590.40000","49.20015","0.00576"
"98488","590.89200","49.24117","0.00492"
"98570","591.38400","49.28218","0.00599"
"98652","591.87600","49.32320","0.00663"
"98734","592.36800","49.36427","0.00471"
"98816","592.86000","49.40523","0.00589"
"98898","593.35200","49.44630","0.00506"
"98980","593.84400","49.48720","0.00653"
"99062","594.33600","49.52821","0.00671"
"99144","594.82800","49.56923","0.00530"
"99226","595.32000","49.61018","0.00614"
"99308","595.81200","49.65114","0.00492"
"99390","596.30400","49.69221","0.00677"
"99472","596.79600","49.73323","0.00696"
"99554","597.28800","49.77419","0.00594"
"99636","597.78000","49.81527","0.00635"
"99718","598.27200","49.85622","0.00482"
"99800","598.76400","49.89717","0.00640"
"99882","599.25600","49.93826","0.00637"
"99964","599.74800","49.97927","0.00631"
"100046","600.24000","50.02029","0.00632"
"100128","600.73200","50.06118","0.00584"
"100210","601.22400","50.10219","0.00593"
"100292","601.71600","50.14315","0.00674"
"100359","602.11600","50.17657","0.00611"