File: Trajectories_together/170225_2Specimen_RawData_2.csv
"","V1","V2","V3"
"1","End date","2/25/2017",""
"2","Specimen label","1BG_6",""
"3","Maximum Load","0.15376","N"
"4","Time","Extension","Load"
"5","(s)","(mm)","(N)"
"6","0.00000","0.00000","0.00036"
"65","0.35400","0.02954","0.00063"
"124","0.70800","0.05925","0.00099"
"183","1.06200","0.08867","0.00112"
"242","1.41600","0.11820","0.00191"
"301","1.77000","0.14774","0.00220"
"360","2.12400","0.17722","0.00222"
"419","2.47800","0.20669","0.00248"
"478","2.83200","0.23617","0.00266"
"537","3.18600","0.26564","0.00242"
"596","3.54000","0.29524","0.00317"
"655","3.89400","0.32466","0.00333"
"714","4.24800","0.35419","0.00321"
"773","4.60200","0.38379","0.00343"
"832","4.95600","0.41315","0.00321"
"891","5.31000","0.44268","0.00336"
"950","5.66400","0.47222","0.00368"
"1009","6.01800","0.50163","0.00405"
"1068","6.37200","0.53123","0.00358"
"1127","6.72600","0.56071","0.00364"
"1186","7.08000","0.59018","0.00460"
"1245","7.43400","0.61972","0.00395"
"1304","7.78800","0.64919","0.00424"
"1363","8.14200","0.67867","0.00440"
"1422","8.49600","0.70821","0.00434"
"1481","8.85000","0.73768","0.00435"
"1540","9.20400","0.76716","0.00430"
"1599","9.55800","0.79670","0.00426"
"1658","9.91200","0.82623","0.00425"
"1717","10.26600","0.85571","0.00460"
"1776","10.62000","0.88518","0.00443"
"1835","10.97400","0.91472","0.00495"
"1894","11.32800","0.94414","0.00527"
"1953","11.68200","0.97373","0.00535"
"2012","12.03600","1.00321","0.00511"
"2071","12.39000","1.03268","0.00562"
"2130","12.74400","1.06222","0.00572"
"2189","13.09800","1.09170","0.00561"
"2248","13.45200","1.12117","0.00582"
"2307","13.80600","1.15071","0.00551"
"2366","14.16000","1.18019","0.00541"
"2425","14.51400","1.20966","0.00523"
"2484","14.86800","1.23926","0.00586"
"2543","15.22200","1.26861","0.00573"
"2602","15.57600","1.29821","0.00568"
"2661","15.93000","1.32763","0.00498"
"2720","16.28400","1.35716","0.00582"
"2779","16.63800","1.38670","0.00575"
"2838","16.99200","1.41623","0.00609"
"2897","17.34600","1.44571","0.00562"
"2956","17.70000","1.47519","0.00579"
"3015","18.05400","1.50472","0.00564"
"3074","18.40800","1.53414","0.00583"
"3133","18.76200","1.56368","0.00616"
"3192","19.11600","1.59315","0.00639"
"3251","19.47000","1.62269","0.00637"
"3310","19.82400","1.65222","0.00601"
"3369","20.17800","1.68176","0.00616"
"3428","20.53200","1.71112","0.00643"
"3487","20.88600","1.74077","0.00632"
"3546","21.24000","1.77025","0.00615"
"3605","21.59400","1.79961","0.00661"
"3664","21.94800","1.82920","0.00669"
"3723","22.30200","1.85868","0.00632"
"3782","22.65600","1.88815","0.00672"
"3841","23.01000","1.91769","0.00663"
"3900","23.36400","1.94723","0.00591"
"3959","23.71800","1.97664","0.00679"
"4018","24.07200","2.00618","0.00609"
"4077","24.42600","2.03565","0.00679"
"4136","24.78000","2.06519","0.00764"
"4195","25.13400","2.09473","0.00748"
"4254","25.48800","2.12414","0.00644"
"4313","25.84200","2.15368","0.00683"
"4372","26.19600","2.18321","0.00735"
"4431","26.55000","2.21263","0.00711"
"4490","26.90400","2.24223","0.00656"
"4549","27.25800","2.27170","0.00723"
"4608","27.61200","2.30118","0.00644"
"4667","27.96600","2.33072","0.00561"
"4726","28.32000","2.36019","0.00562"
"4785","28.67400","2.38967","0.00527"
"4844","29.02800","2.41914","0.00517"
"4903","29.38200","2.44868","0.00550"
"4962","29.73600","2.47816","0.00629"
"5021","30.09000","2.50775","0.00552"
"5080","30.44400","2.53717","0.00615"
"5139","30.79800","2.56670","0.00572"
"5198","31.15200","2.59618","0.00576"
"5257","31.50600","2.62578","0.00610"
"5316","31.86000","2.65513","0.00581"
"5375","32.21400","2.68473","0.00595"
"5434","32.56800","2.71421","0.00550"
"5493","32.92200","2.74368","0.00636"
"5552","33.27600","2.77328","0.00622"
"5611","33.63000","2.80275","0.00662"
"5670","33.98400","2.83217","0.00657"
"5729","34.33800","2.86171","0.00648"
"5788","34.69200","2.89118","0.00695"
"5847","35.04600","2.92066","0.00660"
"5906","35.40000","2.95019","0.00648"
"5965","35.75400","2.97967","0.00670"
"6024","36.10800","3.00921","0.00673"
"6083","36.46200","3.03868","0.00671"
"6142","36.81600","3.06822","0.00653"
"6201","37.17000","3.09770","0.00654"
"6260","37.52400","3.12723","0.00715"
"6319","37.87800","3.15671","0.00721"
"6378","38.23200","3.18618","0.00729"
"6437","38.58600","3.21572","0.00659"
"6496","38.94000","3.24520","0.00667"
"6555","39.29400","3.27467","0.00677"
"6614","39.64800","3.30427","0.00691"
"6673","40.00200","3.33369","0.00710"
"6732","40.35600","3.36316","0.00710"
"6791","40.71000","3.39276","0.00808"
"6850","41.06400","3.42217","0.00729"
"6909","41.41800","3.45171","0.00756"
"6968","41.77200","3.48119","0.00784"
"7027","42.12600","3.51066","0.00716"
"7086","42.48000","3.54020","0.00782"
"7145","42.83400","3.56979","0.00731"
"7204","43.18800","3.59915","0.00755"
"7263","43.54200","3.62875","0.00742"
"7322","43.89600","3.65816","0.00730"
"7381","44.25000","3.68764","0.00750"
"7440","44.60400","3.71718","0.00783"
"7499","44.95800","3.74671","0.00798"
"7558","45.31200","3.77613","0.00768"
"7617","45.66600","3.80566","0.00777"
"7676","46.02000","3.83526","0.00765"
"7735","46.37400","3.86462","0.00806"
"7794","46.72800","3.89421","0.00821"
"7853","47.08200","3.92369","0.00791"
"7912","47.43600","3.95316","0.00811"
"7971","47.79000","3.98270","0.00801"
"8030","48.14400","4.01224","0.00808"
"8089","48.49800","4.04165","0.00782"
"8148","48.85200","4.07125","0.00766"
"8207","49.20600","4.10073","0.00812"
"8266","49.56000","4.13014","0.00807"
"8325","49.91400","4.15974","0.00856"
"8384","50.26800","4.18921","0.00842"
"8443","50.62200","4.21863","0.00859"
"8502","50.97600","4.24817","0.00814"
"8561","51.33000","4.27770","0.00861"
"8620","51.68400","4.30718","0.00866"
"8679","52.03800","4.33671","0.00889"
"8738","52.39200","4.36619","0.00862"
"8797","52.74600","4.39573","0.00819"
"8856","53.10000","4.42520","0.00842"
"8915","53.45400","4.45468","0.00884"
"8974","53.80800","4.48421","0.00844"
"9033","54.16200","4.51369","0.00901"
"9092","54.51600","4.54317","0.00912"
"9151","54.87000","4.57264","0.00942"
"9210","55.22400","4.60224","0.00897"
"9269","55.57800","4.63166","0.00884"
"9328","55.93200","4.66125","0.00888"
"9387","56.28600","4.69073","0.00931"
"9446","56.64000","4.72014","0.00934"
"9505","56.99400","4.74962","0.00906"
"9564","57.34800","4.77922","0.00917"
"9623","57.70200","4.80869","0.00923"
"9682","58.05600","4.83823","0.00931"
"9741","58.41000","4.86770","0.00923"
"9800","58.76400","4.89718","0.00840"
"9859","59.11800","4.92672","0.00944"
"9918","59.47200","4.95625","0.00894"
"9977","59.82600","4.98567","0.00905"
"10036","60.18000","5.01521","0.00902"
"10095","60.53400","5.04468","0.00916"
"10154","60.88800","5.07416","0.00936"
"10213","61.24200","5.10369","0.00958"
"10272","61.59600","5.13317","0.00955"
"10331","61.95000","5.16265","0.00966"
"10390","62.30400","5.19218","0.00952"
"10449","62.65800","5.22172","0.00990"
"10508","63.01200","5.25113","0.01008"
"10567","63.36600","5.28073","0.00909"
"10626","63.72000","5.31021","0.00949"
"10685","64.07400","5.33968","0.00954"
"10744","64.42800","5.36922","0.00940"
"10803","64.78200","5.39876","0.00977"
"10862","65.13600","5.42817","0.00963"
"10921","65.49000","5.45771","0.00991"
"10980","65.84400","5.48712","0.01016"
"11039","66.19800","5.51666","0.00983"
"11098","66.55200","5.54626","0.00947"
"11157","66.90600","5.57567","0.01000"
"11216","67.26000","5.60515","0.01017"
"11275","67.61400","5.63463","0.01058"
"11334","67.96800","5.66422","0.01008"
"11393","68.32200","5.69364","0.01002"
"11452","68.67600","5.72323","0.00995"
"11511","69.03000","5.75271","0.01011"
"11570","69.38400","5.78219","0.01006"
"11629","69.73800","5.81172","0.01000"
"11688","70.09200","5.84120","0.01012"
"11747","70.44600","5.87067","0.01008"
"11806","70.80000","5.90021","0.01053"
"11865","71.15400","5.92969","0.01019"
"11924","71.50800","5.95922","0.01021"
"11983","71.86200","5.98870","0.01089"
"12042","72.21600","6.01812","0.01057"
"12101","72.57000","6.04771","0.01058"
"12160","72.92400","6.07725","0.01057"
"12219","73.27800","6.10666","0.01068"
"12278","73.63200","6.13614","0.01022"
"12337","73.98600","6.16574","0.01099"
"12396","74.34000","6.19509","0.01099"
"12455","74.69400","6.22469","0.01147"
"12514","75.04800","6.25422","0.01081"
"12573","75.40200","6.28370","0.01066"
"12632","75.75600","6.31318","0.01104"
"12691","76.11000","6.34271","0.01087"
"12750","76.46400","6.37213","0.01064"
"12809","76.81800","6.40167","0.01054"
"12868","77.17200","6.43120","0.01125"
"12927","77.52600","6.46068","0.01079"
"12986","77.88000","6.49021","0.01083"
"13045","78.23400","6.51969","0.01089"
"13104","78.58800","6.54917","0.01130"
"13163","78.94200","6.57870","0.01151"
"13222","79.29600","6.60818","0.01105"
"13281","79.65000","6.63759","0.01123"
"13340","80.00400","6.66725","0.01138"
"13399","80.35800","6.69667","0.01080"
"13458","80.71200","6.72620","0.01121"
"13517","81.06600","6.75568","0.01153"
"13576","81.42000","6.78522","0.01127"
"13635","81.77400","6.81469","0.01069"
"13694","82.12800","6.84417","0.01105"
"13753","82.48200","6.87364","0.01110"
"13812","82.83600","6.90318","0.01105"
"13871","83.19000","6.93272","0.01176"
"13930","83.54400","6.96213","0.01106"
"13989","83.89800","6.99173","0.01134"
"14048","84.25200","7.02114","0.01127"
"14107","84.60600","7.05068","0.01151"
"14166","84.96000","7.08016","0.01122"
"14225","85.31400","7.10975","0.01106"
"14284","85.66800","7.13917","0.01189"
"14343","86.02200","7.16871","0.01195"
"14402","86.37600","7.19824","0.01151"
"14461","86.73000","7.22766","0.01144"
"14520","87.08400","7.25713","0.01145"
"14579","87.43800","7.28667","0.01201"
"14638","87.79200","7.31615","0.01178"
"14697","88.14600","7.34568","0.01174"
"14756","88.50000","7.37522","0.01193"
"14815","88.85400","7.40463","0.01200"
"14874","89.20800","7.43423","0.01245"
"14933","89.56200","7.46371","0.01253"
"14992","89.91600","7.49318","0.01269"
"15051","90.27000","7.52278","0.01225"
"15110","90.62400","7.55226","0.01275"
"15169","90.97800","7.58167","0.01315"
"15228","91.33200","7.61127","0.01278"
"15287","91.68600","7.64062","0.01259"
"15346","92.04000","7.67016","0.01287"
"15405","92.39400","7.69976","0.01315"
"15464","92.74800","7.72917","0.01295"
"15523","93.10200","7.75865","0.01298"
"15582","93.45600","7.78819","0.01328"
"15641","93.81000","7.81766","0.01298"
"15700","94.16400","7.84720","0.01336"
"15759","94.51800","7.87673","0.01285"
"15818","94.87200","7.90615","0.01374"
"15877","95.22600","7.93569","0.01369"
"15936","95.58000","7.96516","0.01352"
"15995","95.93400","7.99470","0.01389"
"16054","96.28800","8.02417","0.01359"
"16113","96.64200","8.05371","0.01382"
"16172","96.99600","8.08313","0.01405"
"16231","97.35000","8.11272","0.01408"
"16290","97.70400","8.14220","0.01430"
"16349","98.05800","8.17161","0.01424"
"16408","98.41200","8.20121","0.01330"
"16467","98.76600","8.23075","0.01380"
"16526","99.12000","8.26010","0.01400"
"16585","99.47400","8.28964","0.01396"
"16644","99.82800","8.31924","0.01466"
"16703","100.18200","8.34865","0.01408"
"16762","100.53600","8.37825","0.01433"
"16821","100.89000","8.40766","0.01471"
"16880","101.24400","8.43714","0.01467"
"16939","101.59800","8.46674","0.01502"
"16998","101.95200","8.49621","0.01456"
"17057","102.30600","8.52563","0.01377"
"17116","102.66000","8.55522","0.01363"
"17175","103.01400","8.58464","0.01366"
"17234","103.36800","8.61418","0.01373"
"17293","103.72200","8.64371","0.01393"
"17352","104.07600","8.67319","0.01382"
"17411","104.43000","8.70267","0.01373"
"17470","104.78400","8.73220","0.01374"
"17529","105.13800","8.76168","0.01451"
"17588","105.49200","8.79115","0.01368"
"17647","105.84600","8.82069","0.01375"
"17706","106.20000","8.85023","0.01433"
"17765","106.55400","8.87970","0.01356"
"17824","106.90800","8.90924","0.01353"
"17883","107.26200","8.93871","0.01349"
"17942","107.61600","8.96813","0.01371"
"18001","107.97000","8.99773","0.01391"
"18060","108.32400","9.02714","0.01364"
"18119","108.67800","9.05668","0.01369"
"18178","109.03200","9.08622","0.01445"
"18237","109.38600","9.11563","0.01404"
"18296","109.74000","9.14517","0.01394"
"18355","110.09400","9.17470","0.01469"
"18414","110.44800","9.20412","0.01440"
"18473","110.80200","9.23366","0.01447"
"18532","111.15600","9.26319","0.01401"
"18591","111.51000","9.29261","0.01402"
"18650","111.86400","9.32220","0.01428"
"18709","112.21800","9.35168","0.01428"
"18768","112.57200","9.38116","0.01442"
"18827","112.92600","9.41069","0.01422"
"18886","113.28000","9.44023","0.01445"
"18945","113.63400","9.46965","0.01466"
"19004","113.98800","9.49924","0.01473"
"19063","114.34200","9.52872","0.01493"
"19122","114.69600","9.55813","0.01463"
"19181","115.05000","9.58773","0.01501"
"19240","115.40400","9.61721","0.01500"
"19299","115.75800","9.64662","0.01499"
"19358","116.11200","9.67622","0.01489"
"19417","116.46600","9.70576","0.01435"
"19476","116.82000","9.73517","0.01589"
"19535","117.17400","9.76471","0.01516"
"19594","117.52800","9.79418","0.01484"
"19653","117.88200","9.82372","0.01571"
"19712","118.23600","9.85325","0.01550"
"19771","118.59000","9.88273","0.01534"
"19830","118.94400","9.91221","0.01559"
"19889","119.29800","9.94168","0.01564"
"19948","119.65200","9.97116","0.01526"
"20007","120.00600","10.00070","0.01542"
"20066","120.36000","10.03017","0.01539"
"20125","120.71400","10.05965","0.01563"
"20184","121.06800","10.08918","0.01593"
"20243","121.42200","10.11866","0.01526"
"20302","121.77600","10.14820","0.01555"
"20361","122.13000","10.17767","0.01585"
"20420","122.48400","10.20715","0.01559"
"20479","122.83800","10.23669","0.01603"
"20538","123.19200","10.26622","0.01588"
"20597","123.54800","10.29588","0.01615"
"20656","123.90200","10.32535","0.01554"
"20715","124.25600","10.35489","0.01505"
"20774","124.61000","10.38442","0.01597"
"20833","124.96400","10.41378","0.01599"
"20892","125.31800","10.44332","0.01621"
"20951","125.67200","10.47285","0.01556"
"21010","126.02600","10.50227","0.01590"
"21069","126.38000","10.53187","0.01616"
"21128","126.73400","10.56134","0.01587"
"21187","127.08800","10.59088","0.01611"
"21246","127.44200","10.62041","0.01633"
"21305","127.79600","10.64989","0.01621"
"21364","128.15000","10.67925","0.01641"
"21423","128.50400","10.70890","0.01694"
"21482","128.85800","10.73832","0.01659"
"21541","129.21200","10.76785","0.01609"
"21600","129.56600","10.79739","0.01690"
"21659","129.92000","10.82687","0.01636"
"21718","130.27400","10.85634","0.01620"
"21777","130.62800","10.88588","0.01664"
"21836","130.98200","10.91536","0.01625"
"21895","131.33600","10.94483","0.01585"
"21954","131.69000","10.97437","0.01558"
"22013","132.04400","11.00385","0.01663"
"22072","132.39800","11.03338","0.01560"
"22131","132.75200","11.06286","0.01387"
"22190","133.10600","11.09239","0.01279"
"22249","133.46000","11.12181","0.01410"
"22308","133.81400","11.15141","0.01362"
"22367","134.16800","11.18088","0.01343"
"22426","134.52200","11.21036","0.01333"
"22485","134.87600","11.23989","0.01387"
"22544","135.23000","11.26937","0.01352"
"22603","135.58400","11.29885","0.01348"
"22662","135.93800","11.32832","0.01385"
"22721","136.29200","11.35786","0.01394"
"22780","136.64600","11.38733","0.01372"
"22839","137.00000","11.41687","0.01482"
"22898","137.35400","11.44629","0.01403"
"22957","137.70800","11.47582","0.01399"
"23016","138.06200","11.50530","0.01405"
"23075","138.41600","11.53484","0.01360"
"23134","138.77000","11.56431","0.01424"
"23193","139.12400","11.59385","0.01403"
"23252","139.47800","11.62338","0.01429"
"23311","139.83200","11.65292","0.01485"
"23370","140.18600","11.68240","0.01451"
"23429","140.54000","11.71187","0.01470"
"23488","140.89400","11.74135","0.01427"
"23547","141.24800","11.77088","0.01462"
"23606","141.60200","11.80030","0.01452"
"23665","141.95600","11.82990","0.01480"
"23724","142.31000","11.85943","0.01509"
"23783","142.66400","11.88879","0.01534"
"23842","143.01800","11.91839","0.01503"
"23901","143.37200","11.94786","0.01500"
"23960","143.72600","11.97734","0.01449"
"24019","144.08000","12.00688","0.01443"
"24078","144.43400","12.03641","0.01496"
"24137","144.78800","12.06583","0.01499"
"24196","145.14200","12.09542","0.01462"
"24255","145.49600","12.12490","0.01502"
"24314","145.85000","12.15437","0.01468"
"24373","146.20400","12.18385","0.01484"
"24432","146.55800","12.21339","0.01488"
"24491","146.91200","12.24286","0.01526"
"24550","147.26600","12.27240","0.01506"
"24609","147.62000","12.30188","0.01488"
"24668","147.97400","12.33135","0.01459"
"24727","148.32800","12.36089","0.01510"
"24786","148.68200","12.39031","0.01402"
"24845","149.03600","12.41984","0.01341"
"24904","149.39000","12.44932","0.01468"
"24963","149.74400","12.47885","0.01452"
"25022","150.09800","12.50833","0.01433"
"25081","150.45200","12.53786","0.01427"
"25140","150.80600","12.56734","0.01412"
"25199","151.16000","12.59688","0.01463"
"25258","151.51400","12.62641","0.01446"
"25317","151.86800","12.65583","0.01513"
"25376","152.22200","12.68537","0.01447"
"25435","152.57600","12.71490","0.01476"
"25494","152.93000","12.74438","0.01466"
"25553","153.28400","12.77385","0.01510"
"25612","153.63800","12.80339","0.01496"
"25671","153.99200","12.83275","0.01477"
"25730","154.34600","12.86234","0.01524"
"25789","154.70000","12.89188","0.01500"
"25848","155.05400","12.92130","0.01501"
"25907","155.40800","12.95083","0.01495"
"25966","155.76200","12.98043","0.01417"
"26025","156.11600","13.00984","0.01419"
"26084","156.47000","13.03938","0.01336"
"26143","156.82400","13.06886","0.01421"
"26202","157.17800","13.09833","0.01420"
"26261","157.53200","13.12781","0.01407"
"26320","157.88600","13.15740","0.01415"
"26379","158.24000","13.18682","0.01474"
"26438","158.59400","13.21636","0.01437"
"26497","158.94800","13.24589","0.01380"
"26556","159.30200","13.27531","0.01489"
"26615","159.65600","13.30491","0.01496"
"26674","160.01000","13.33438","0.01526"
"26733","160.36400","13.36386","0.01530"
"26792","160.71800","13.39339","0.01497"
"26851","161.07200","13.42287","0.01513"
"26910","161.42600","13.45235","0.01523"
"26969","161.78000","13.48188","0.01536"
"27028","162.13400","13.51136","0.01531"
"27087","162.48800","13.54083","0.01520"
"27146","162.84200","13.57037","0.01520"
"27205","163.19600","13.59979","0.01488"
"27264","163.55000","13.62932","0.01540"
"27323","163.90400","13.65886","0.01506"
"27382","164.25800","13.68834","0.01567"
"27441","164.61200","13.71781","0.01538"
"27500","164.96600","13.74741","0.01556"
"27559","165.32000","13.77682","0.01522"
"27618","165.67400","13.80642","0.01550"
"27677","166.02800","13.83590","0.01561"
"27736","166.38200","13.86531","0.01601"
"27795","166.73600","13.89485","0.01604"
"27854","167.09000","13.92439","0.01615"
"27913","167.44400","13.95386","0.01645"
"27972","167.79800","13.98340","0.01594"
"28031","168.15200","14.01293","0.01638"
"28090","168.50600","14.04229","0.01594"
"28149","168.86000","14.07188","0.01591"
"28208","169.21400","14.10136","0.01571"
"28267","169.56800","14.13084","0.01645"
"28326","169.92200","14.16043","0.01634"
"28385","170.27600","14.18985","0.01668"
"28444","170.63000","14.21933","0.01676"
"28503","170.98400","14.24892","0.01645"
"28562","171.33800","14.27840","0.01678"
"28621","171.69200","14.30788","0.01691"
"28680","172.04600","14.33735","0.01692"
"28739","172.40000","14.36689","0.01622"
"28798","172.75400","14.39636","0.01731"
"28857","173.10800","14.42584","0.01665"
"28916","173.46200","14.45532","0.01688"
"28975","173.81600","14.48479","0.01534"
"29034","174.17000","14.51433","0.01613"
"29093","174.52400","14.54386","0.01628"
"29152","174.87800","14.57334","0.01656"
"29211","175.23200","14.60288","0.01673"
"29270","175.58600","14.63235","0.01700"
"29329","175.94000","14.66183","0.01614"
"29388","176.29400","14.69143","0.01656"
"29447","176.64800","14.72078","0.01659"
"29506","177.00200","14.75038","0.01618"
"29565","177.35600","14.77985","0.01645"
"29624","177.71000","14.80933","0.01648"
"29683","178.06400","14.83887","0.01677"
"29742","178.41800","14.86834","0.01662"
"29801","178.77200","14.89782","0.01719"
"29860","179.12600","14.92735","0.01714"
"29919","179.48000","14.95689","0.01696"
"29978","179.83400","14.98631","0.01698"
"30037","180.18800","15.01590","0.01686"
"30096","180.54200","15.04538","0.01699"
"30155","180.89600","15.07485","0.01705"
"30214","181.25000","15.10433","0.01726"
"30273","181.60400","15.13393","0.01697"
"30332","181.95800","15.16328","0.01770"
"30391","182.31200","15.19288","0.01677"
"30450","182.66600","15.22242","0.01691"
"30509","183.02000","15.25183","0.01693"
"30568","183.37400","15.28143","0.01714"
"30627","183.72800","15.31090","0.01723"
"30686","184.08200","15.34026","0.01738"
"30745","184.43600","15.36986","0.01729"
"30804","184.79000","15.39939","0.01718"
"30863","185.14400","15.42887","0.01706"
"30922","185.49800","15.45840","0.01723"
"30981","185.85200","15.48782","0.01767"
"31040","186.20600","15.51730","0.01797"
"31099","186.56000","15.54689","0.01789"
"31158","186.91400","15.57631","0.01772"
"31217","187.26800","15.60585","0.01779"
"31276","187.62200","15.63544","0.01778"
"31335","187.97600","15.66486","0.01768"
"31394","188.33000","15.69439","0.01778"
"31453","188.68400","15.72387","0.01788"
"31512","189.03800","15.75335","0.01814"
"31571","189.39200","15.78282","0.01783"
"31630","189.74600","15.81236","0.01807"
"31689","190.10000","15.84183","0.01767"
"31748","190.45400","15.87131","0.01765"
"31807","190.80800","15.90085","0.01750"
"31866","191.16200","15.93032","0.01716"
"31925","191.51600","15.95992","0.01794"
"31984","191.87000","15.98934","0.01771"
"32043","192.22400","16.01881","0.01793"
"32102","192.57800","16.04835","0.01782"
"32161","192.93200","16.07794","0.01818"
"32220","193.28600","16.10724","0.01761"
"32279","193.64000","16.13690","0.01859"
"32338","193.99400","16.16637","0.01807"
"32397","194.34800","16.19579","0.01847"
"32456","194.70200","16.22532","0.01833"
"32515","195.05600","16.25486","0.01811"
"32574","195.41000","16.28428","0.01882"
"32633","195.76400","16.31387","0.01829"
"32692","196.11800","16.34341","0.01790"
"32751","196.47200","16.37283","0.01828"
"32810","196.82600","16.40236","0.01851"
"32869","197.18000","16.43184","0.01838"
"32928","197.53400","16.46137","0.01876"
"32987","197.88800","16.49085","0.01953"
"33046","198.24200","16.52039","0.01910"
"33105","198.59600","16.54986","0.01923"
"33164","198.95000","16.57934","0.01919"
"33223","199.30400","16.60881","0.01948"
"33282","199.65800","16.63835","0.01974"
"33341","200.01200","16.66788","0.01939"
"33400","200.36600","16.69736","0.01771"
"33459","200.72000","16.72684","0.01734"
"33518","201.07400","16.75637","0.01747"
"33577","201.42800","16.78591","0.01800"
"33636","201.78200","16.81533","0.01796"
"33695","202.13600","16.84486","0.01848"
"33754","202.49000","16.87434","0.01809"
"33813","202.84400","16.90388","0.01796"
"33872","203.19800","16.93335","0.01809"
"33931","203.55200","16.96283","0.01904"
"33990","203.90600","16.99236","0.01831"
"34049","204.26000","17.02190","0.01934"
"34108","204.61400","17.05132","0.01907"
"34167","204.96800","17.08091","0.01896"
"34226","205.32200","17.11033","0.01920"
"34285","205.67600","17.13980","0.01987"
"34344","206.03000","17.16940","0.01921"
"34403","206.38400","17.19888","0.01935"
"34462","206.73800","17.22835","0.01955"
"34521","207.09200","17.25783","0.01943"
"34580","207.44600","17.28737","0.01984"
"34639","207.80000","17.31684","0.01962"
"34698","208.15400","17.34632","0.02026"
"34757","208.50800","17.37585","0.01988"
"34816","208.86200","17.40533","0.01942"
"34875","209.21600","17.43487","0.01985"
"34934","209.57000","17.46440","0.02002"
"34993","209.92400","17.49376","0.01985"
"35052","210.27800","17.52341","0.02053"
"35111","210.63200","17.55289","0.01999"
"35170","210.98600","17.58231","0.02040"
"35229","211.34000","17.61190","0.02076"
"35288","211.69400","17.64138","0.02067"
"35347","212.04800","17.67086","0.02098"
"35406","212.40200","17.70039","0.02114"
"35465","212.75600","17.72987","0.02081"
"35524","213.11000","17.75935","0.02044"
"35583","213.46400","17.78894","0.02059"
"35642","213.81800","17.81836","0.02105"
"35701","214.17200","17.84783","0.02114"
"35760","214.52600","17.87737","0.02081"
"35819","214.88000","17.90685","0.02086"
"35878","215.23400","17.93638","0.02066"
"35937","215.58800","17.96586","0.02120"
"35996","215.94200","17.99533","0.02175"
"36055","216.29600","18.02487","0.02024"
"36114","216.65000","18.05441","0.02071"
"36173","217.00400","18.08382","0.02138"
"36232","217.35800","18.11342","0.02094"
"36291","217.71200","18.14283","0.02194"
"36350","218.06600","18.17237","0.02125"
"36409","218.42000","18.20179","0.02100"
"36468","218.77400","18.23138","0.02225"
"36527","219.12800","18.26080","0.02233"
"36586","219.48200","18.29033","0.02280"
"36645","219.83600","18.31993","0.02249"
"36704","220.19000","18.34935","0.02242"
"36763","220.54400","18.37882","0.02332"
"36822","220.89800","18.40836","0.02303"
"36881","221.25200","18.43778","0.02433"
"36940","221.60600","18.46737","0.02412"
"36999","221.96000","18.49685","0.02451"
"37058","222.31400","18.52633","0.02431"
"37117","222.66800","18.55586","0.02439"
"37176","223.02200","18.58534","0.02444"
"37235","223.37600","18.61481","0.02524"
"37294","223.73000","18.64435","0.02532"
"37353","224.08400","18.67389","0.02514"
"37412","224.43800","18.70330","0.02575"
"37471","224.79200","18.73290","0.02601"
"37530","225.14600","18.76237","0.02634"
"37589","225.50000","18.79185","0.02711"
"37648","225.85400","18.82133","0.02680"
"37707","226.20800","18.85092","0.02611"
"37766","226.56200","18.88034","0.02582"
"37825","226.91600","18.90988","0.02640"
"37884","227.27000","18.93935","0.02669"
"37943","227.62400","18.96883","0.02785"
"38002","227.97800","18.99836","0.02822"
"38061","228.33200","19.02784","0.02837"
"38120","228.68600","19.05738","0.02875"
"38179","229.04000","19.08685","0.02957"
"38238","229.39400","19.11639","0.02919"
"38297","229.74800","19.14580","0.03000"
"38356","230.10200","19.17540","0.02999"
"38415","230.45600","19.20481","0.03023"
"38474","230.81000","19.23435","0.03155"
"38533","231.16400","19.26383","0.03223"
"38592","231.51800","19.29336","0.03300"
"38651","231.87200","19.32284","0.03300"
"38710","232.22600","19.35238","0.03390"
"38769","232.58000","19.38185","0.03418"
"38828","232.93400","19.41133","0.03537"
"38887","233.28800","19.44086","0.03508"
"38946","233.64200","19.47028","0.03687"
"39005","233.99600","19.49988","0.03733"
"39064","234.35000","19.52935","0.03807"
"39123","234.70400","19.55883","0.03875"
"39182","235.05800","19.58837","0.03940"
"39241","235.41200","19.61796","0.03983"
"39300","235.76600","19.64732","0.04120"
"39359","236.12000","19.67691","0.04131"
"39418","236.47400","19.70639","0.04216"
"39477","236.82800","19.73581","0.04257"
"39536","237.18200","19.76540","0.04319"
"39595","237.53600","19.79482","0.04350"
"39654","237.89000","19.82430","0.04432"
"39713","238.24400","19.85389","0.04519"
"39772","238.59800","19.88337","0.04550"
"39831","238.95200","19.91284","0.04652"
"39890","239.30600","19.94238","0.04742"
"39949","239.66000","19.97180","0.04744"
"40008","240.01400","20.00127","0.04816"
"40067","240.36800","20.03087","0.04875"
"40126","240.72200","20.06034","0.05002"
"40185","241.07600","20.08982","0.05026"
"40244","241.43000","20.11942","0.05082"
"40303","241.78400","20.14883","0.05154"
"40362","242.13800","20.17837","0.05187"
"40421","242.49200","20.20790","0.05272"
"40480","242.84600","20.23738","0.05232"
"40539","243.20000","20.26680","0.05336"
"40598","243.55400","20.29633","0.05378"
"40657","243.90800","20.32587","0.05379"
"40716","244.26200","20.35535","0.05452"
"40775","244.61600","20.38494","0.05480"
"40834","244.97000","20.41430","0.05519"
"40893","245.32400","20.44389","0.05596"
"40952","245.67800","20.47337","0.05597"
"41011","246.03200","20.50285","0.05643"
"41070","246.38600","20.53232","0.05649"
"41129","246.74000","20.56192","0.05700"
"41188","247.09400","20.59134","0.05725"
"41247","247.44800","20.62087","0.05756"
"41306","247.80200","20.65041","0.05779"
"41365","248.15600","20.67982","0.05816"
"41424","248.51000","20.70936","0.05849"
"41483","248.86400","20.73890","0.05766"
"41542","249.21800","20.76831","0.05821"
"41601","249.57200","20.79785","0.05870"
"41660","249.92600","20.82738","0.05890"
"41719","250.28000","20.85680","0.05923"
"41778","250.63400","20.88640","0.05996"
"41837","250.98800","20.91587","0.05962"
"41896","251.34200","20.94529","0.06014"
"41955","251.69600","20.97489","0.06071"
"42014","252.05000","21.00442","0.06088"
"42073","252.40400","21.03378","0.06182"
"42132","252.75800","21.06337","0.06250"
"42191","253.11200","21.09285","0.06287"
"42250","253.46600","21.12233","0.06422"
"42309","253.82000","21.15192","0.06445"
"42368","254.17400","21.18134","0.06565"
"42427","254.52800","21.21087","0.06647"
"42486","254.88200","21.24041","0.06694"
"42545","255.23600","21.26983","0.06787"
"42604","255.59000","21.29930","0.06859"
"42663","255.94400","21.32884","0.06930"
"42722","256.29800","21.35832","0.07041"
"42781","256.65200","21.38785","0.07248"
"42840","257.00600","21.41733","0.07385"
"42899","257.36000","21.44687","0.07506"
"42958","257.71400","21.47634","0.07659"
"43017","258.06800","21.50588","0.07841"
"43076","258.42200","21.53529","0.07968"
"43135","258.77600","21.56483","0.07980"
"43194","259.13000","21.59436","0.08103"
"43253","259.48400","21.62378","0.08209"
"43312","259.83800","21.65332","0.08386"
"43371","260.19200","21.68286","0.08524"
"43430","260.54600","21.71233","0.08567"
"43489","260.90000","21.74187","0.08618"
"43548","261.25400","21.77140","0.08801"
"43607","261.60800","21.80076","0.08920"
"43666","261.96200","21.83042","0.09113"
"43725","262.31600","21.85983","0.09132"
"43784","262.67000","21.88931","0.09372"
"43843","263.02400","21.91890","0.09427"
"43902","263.37800","21.94838","0.09531"
"43961","263.73200","21.97779","0.09672"
"44020","264.08600","22.00739","0.09773"
"44079","264.44000","22.03687","0.09939"
"44138","264.79400","22.06634","0.10004"
"44197","265.14800","22.09594","0.10119"
"44256","265.50200","22.12536","0.10216"
"44315","265.85600","22.15483","0.10281"
"44374","266.21000","22.18431","0.10369"
"44433","266.56400","22.21384","0.10380"
"44492","266.91800","22.24338","0.10404"
"44551","267.27200","22.27292","0.10505"
"44610","267.62600","22.30233","0.10584"
"44669","267.98000","22.33181","0.10597"
"44728","268.33400","22.36140","0.10684"
"44787","268.68800","22.39082","0.10214"
"44846","269.04200","22.42030","0.10372"
"44905","269.39600","22.44989","0.10373"
"44964","269.75000","22.47931","0.10350"
"45023","270.10400","22.50885","0.10434"
"45082","270.45800","22.53838","0.10549"
"45141","270.81200","22.56786","0.10573"
"45200","271.16600","22.59739","0.10663"
"45259","271.52000","22.62687","0.10755"
"45318","271.87400","22.65635","0.10855"
"45377","272.22800","22.68582","0.10910"
"45436","272.58200","22.71542","0.11028"
"45495","272.93600","22.74478","0.11332"
"45554","273.29000","22.77443","0.11507"
"45613","273.64400","22.80385","0.11632"
"45672","273.99800","22.83332","0.11778"
"45731","274.35200","22.86286","0.12099"
"45790","274.70600","22.89240","0.12346"
"45849","275.06000","22.92181","0.12555"
"45908","275.41400","22.95135","0.12589"
"45967","275.76800","22.98089","0.12728"
"46026","276.12200","23.01030","0.12964"
"46085","276.47600","23.03990","0.13060"
"46144","276.83000","23.06937","0.13246"
"46203","277.18400","23.09885","0.13389"
"46262","277.53800","23.12839","0.13530"
"46321","277.89200","23.15792","0.13687"
"46380","278.24600","23.18728","0.13741"
"46439","278.60000","23.21688","0.13886"
"46498","278.95400","23.24635","0.13938"
"46557","279.30800","23.27589","0.13902"
"46616","279.66200","23.30536","0.13983"
"46675","280.01600","23.33490","0.14019"
"46734","280.37000","23.36437","0.03261"
"46793","280.72400","23.39391","0.02925"
"46852","281.07800","23.42332","0.04149"
"46911","281.43200","23.45280","0.02938"
"46970","281.78600","23.48240","0.04285"
"47029","282.14000","23.51182","0.03418"
"47088","282.49400","23.54141","0.04010"
"47147","282.84800","23.57083","0.04284"
"47206","283.20200","23.60036","0.03923"
"47265","283.55600","23.62990","0.04626"
"47324","283.91000","23.65932","0.04384"
"47383","284.26400","23.68879","0.04526"
"47442","284.61800","23.71839","0.04806"
"47501","284.97200","23.74787","0.04739"
"47560","285.32600","23.77734","0.04869"
"47619","285.68000","23.80682","0.05055"
"47678","286.03400","23.83641","0.04955"
"47737","286.38800","23.86583","0.05172"
"47796","286.74200","23.89536","0.05205"
"47855","287.09600","23.92490","0.05196"
"47914","287.45000","23.95432","0.05314"
"47973","287.80400","23.98385","0.05316"
"48032","288.15800","24.01339","0.05387"
"48091","288.51200","24.04281","0.05422"
"48150","288.86600","24.07240","0.05364"
"48209","289.22000","24.10188","0.05449"
"48268","289.57400","24.13129","0.05490"
"48327","289.92800","24.16089","0.05497"
"48386","290.28200","24.19037","0.05573"
"48445","290.63600","24.21984","0.05586"
"48504","290.99000","24.24938","0.05624"
"48563","291.34400","24.27885","0.05662"
"48622","291.69800","24.30833","0.05691"
"48681","292.05200","24.33787","0.05750"
"48740","292.40600","24.36735","0.05734"
"48799","292.76000","24.39688","0.05799"
"48858","293.11400","24.42642","0.05819"
"48917","293.46800","24.45583","0.05881"
"48976","293.82200","24.48531","0.05955"
"49035","294.17600","24.51484","0.06021"
"49094","294.53000","24.54438","0.06037"
"49153","294.88400","24.57380","0.06120"
"49212","295.23800","24.60339","0.06175"
"49271","295.59200","24.63287","0.06222"
"49330","295.94600","24.66234","0.06320"
"49389","296.30000","24.69188","0.06348"
"49448","296.65400","24.72130","0.06425"
"49507","297.00800","24.75083","0.06468"
"49566","297.36200","24.78037","0.06592"
"49625","297.71600","24.80985","0.06596"
"49684","298.07000","24.83932","0.06759"
"49743","298.42400","24.86892","0.06848"
"49802","298.77800","24.89833","0.06889"
"49861","299.13200","24.92787","0.07139"
"49920","299.48600","24.95735","0.07196"
"49979","299.84000","24.98688","0.07386"
"50038","300.19400","25.01636","0.07555"
"50097","300.54800","25.04589","0.07678"
"50156","300.90200","25.07531","0.07800"
"50215","301.25600","25.10485","0.07884"
"50274","301.61000","25.13438","0.08122"
"50333","301.96400","25.16380","0.08169"
"50392","302.31800","25.19334","0.08335"
"50451","302.67200","25.22281","0.08439"
"50510","303.02600","25.25235","0.08581"
"50569","303.38000","25.28189","0.08722"
"50628","303.73400","25.31142","0.08809"
"50687","304.08800","25.34084","0.08943"
"50746","304.44200","25.37037","0.09106"
"50805","304.79600","25.39991","0.09238"
"50864","305.15000","25.42939","0.09385"
"50923","305.50400","25.45886","0.09434"
"50982","305.85800","25.48840","0.09676"
"51041","306.21200","25.51781","0.09757"
"51100","306.56600","25.54741","0.09909"
"51159","306.92000","25.57683","0.10084"
"51218","307.27400","25.60630","0.10154"
"51277","307.62800","25.63590","0.10244"
"51336","307.98200","25.66538","0.10338"
"51395","308.33600","25.69485","0.10395"
"51454","308.69000","25.72433","0.10455"
"51513","309.04400","25.75386","0.10519"
"51572","309.39800","25.78334","0.10540"
"51631","309.75200","25.81288","0.10660"
"51690","310.10600","25.84229","0.10685"
"51749","310.46000","25.87189","0.10748"
"51808","310.81400","25.90136","0.10914"
"51867","311.16800","25.93084","0.11118"
"51926","311.52200","25.96037","0.11239"
"51985","311.87600","25.98985","0.11444"
"52044","312.23000","26.01933","0.11556"
"52103","312.58400","26.04886","0.11062"
"52162","312.93800","26.07840","0.11098"
"52221","313.29200","26.10782","0.11223"
"52280","313.64600","26.13741","0.11488"
"52339","314.00000","26.16689","0.11595"
"52398","314.35400","26.19631","0.11745"
"52457","314.70800","26.22584","0.11898"
"52516","315.06200","26.25544","0.12149"
"52575","315.41600","26.28479","0.12430"
"52634","315.77000","26.31439","0.12706"
"52693","316.12400","26.34386","0.12912"
"52752","316.47800","26.37334","0.13090"
"52811","316.83200","26.40288","0.13241"
"52870","317.18600","26.43235","0.13429"
"52929","317.54000","26.46183","0.13579"
"52988","317.89400","26.49137","0.13652"
"53047","318.24800","26.52085","0.13826"
"53106","318.60200","26.55032","0.13940"
"53165","318.95600","26.57992","0.14049"
"53224","319.31000","26.60939","0.14059"
"53283","319.66400","26.63881","0.14065"
"53342","320.01800","26.66840","0.14067"
"53401","320.37200","26.69782","0.14102"
"53460","320.72600","26.72730","0.14181"
"53519","321.08000","26.75695","0.14271"
"53578","321.43400","26.78637","0.14362"
"53637","321.78800","26.81585","0.14452"
"53696","322.14200","26.84532","0.14530"
"53755","322.49600","26.87486","0.14588"
"53814","322.85000","26.90434","0.14658"
"53873","323.20400","26.93387","0.14683"
"53932","323.55800","26.96335","0.14709"
"53991","323.91200","26.99282","0.14773"
"54050","324.26600","27.02236","0.14809"
"54109","324.62000","27.05184","0.14868"
"54168","324.97400","27.08137","0.14882"
"54227","325.32800","27.11085","0.14928"
"54286","325.68200","27.14032","0.14946"
"54345","326.03600","27.16980","0.14993"
"54404","326.39000","27.19940","0.15047"
"54463","326.74400","27.22881","0.15058"
"54522","327.09800","27.25841","0.15088"
"54581","327.45200","27.28794","0.15124"
"54640","327.80600","27.31730","0.15164"
"54699","328.16000","27.34683","0.15207"
"54758","328.51400","27.37637","0.15262"
"54817","328.86800","27.40585","0.15339"
"54876","329.22200","27.43538","0.02879"
"54935","329.57600","27.46492","0.02519"
"54994","329.93000","27.49428","0.02796"
"55053","330.28400","27.52387","0.02309"
"55112","330.63800","27.55335","0.02779"
"55171","330.99200","27.58282","0.02658"
"55230","331.34600","27.61236","0.02781"
"55289","331.70000","27.64190","0.03060"
"55348","332.05400","27.67137","0.03037"
"55407","332.40800","27.70085","0.03271"
"55466","332.76200","27.73039","0.03285"
"55525","333.11600","27.75980","0.03470"
"55584","333.47000","27.78940","0.03488"
"55643","333.82400","27.81888","0.03525"
"55702","334.17800","27.84835","0.03859"
"55761","334.53200","27.87789","0.03873"
"55820","334.88600","27.90736","0.03966"
"55879","335.24000","27.93684","0.04066"
"55938","335.59400","27.96638","0.04140"
"55997","335.94800","27.99579","0.04152"
"56056","336.30200","28.02533","0.04297"
"56115","336.65600","28.05486","0.04322"
"56174","337.01000","28.08434","0.04443"
"56233","337.36400","28.11382","0.04580"
"56292","337.71800","28.14341","0.04701"
"56351","338.07200","28.17283","0.04805"
"56410","338.42600","28.20237","0.04866"
"56469","338.78000","28.23184","0.04951"
"56528","339.13400","28.26132","0.05047"
"56587","339.48800","28.29085","0.05161"
"56646","339.84200","28.32039","0.05195"
"56705","340.19600","28.34980","0.05286"
"56764","340.55000","28.37934","0.05286"
"56823","340.90400","28.40888","0.05295"
"56882","341.25800","28.43829","0.05323"
"56941","341.61200","28.46789","0.05196"
"57000","341.96600","28.49736","0.05204"
"57059","342.32000","28.52684","0.05305"
"57118","342.67400","28.55638","0.05366"
"57177","343.02800","28.58586","0.05379"
"57236","343.38200","28.61527","0.05470"
"57295","343.73600","28.64493","0.05479"
"57354","344.09000","28.67440","0.05510"
"57413","344.44400","28.70382","0.05535"
"57472","344.79800","28.73335","0.05597"
"57531","345.15200","28.76289","0.05634"
"57590","345.50600","28.79231","0.05670"
"57649","345.86000","28.82184","0.05700"
"57708","346.21400","28.85138","0.05748"
"57767","346.56800","28.88080","0.05795"
"57826","346.92200","28.91039","0.05842"
"57885","347.27600","28.93987","0.05863"
"57944","347.63000","28.96935","0.05913"
"58003","347.98400","28.99888","0.05979"
"58062","348.33800","29.02836","0.06000"
"58121","348.69200","29.05783","0.06021"
"58180","349.04600","29.08743","0.06079"
"58239","349.40000","29.11685","0.06170"
"58298","349.75400","29.14632","0.06179"
"58357","350.10800","29.17586","0.06229"
"58416","350.46200","29.20534","0.06298"
"58475","350.81600","29.23487","0.06422"
"58534","351.17000","29.26435","0.06542"
"58593","351.52400","29.29388","0.06668"
"58652","351.87800","29.32336","0.06806"
"58711","352.23200","29.35289","0.06918"
"58770","352.58600","29.38231","0.07042"
"58829","352.94000","29.41191","0.07268"
"58888","353.29400","29.44132","0.07432"
"58947","353.64800","29.47080","0.07587"
"59006","354.00200","29.50034","0.07714"
"59065","354.35600","29.52987","0.07903"
"59124","354.71000","29.55935","0.07955"
"59183","355.06400","29.58888","0.07984"
"59242","355.41800","29.61842","0.08037"
"59301","355.77200","29.64778","0.08136"
"59360","356.12600","29.67737","0.08186"
"59419","356.48000","29.70691","0.08316"
"59478","356.83400","29.73632","0.08454"
"59537","357.18800","29.76586","0.08486"
"59596","357.54200","29.79540","0.08655"
"59655","357.89600","29.82481","0.08753"
"59714","358.25000","29.85441","0.08952"
"59773","358.60400","29.88389","0.09084"
"59832","358.95800","29.91336","0.09178"
"59891","359.31200","29.94290","0.09441"
"59950","359.66600","29.97237","0.09512"
"60009","360.02000","30.00185","0.09674"
"60068","360.37400","30.03139","0.09887"
"60127","360.72800","30.06086","0.09937"
"60186","361.08200","30.09034","0.10080"
"60245","361.43600","30.11987","0.10219"
"60304","361.79000","30.14935","0.10226"
"60363","362.14400","30.17883","0.10348"
"60422","362.49800","30.20836","0.10372"
"60481","362.85200","30.23784","0.10423"
"60540","363.20600","30.26731","0.10454"
"60599","363.56000","30.29685","0.10497"
"60658","363.91400","30.32633","0.10635"
"60717","364.26800","30.35586","0.10686"
"60776","364.62200","30.38534","0.10764"
"60835","364.97600","30.41482","0.10906"
"60894","365.33000","30.44435","0.10983"
"60953","365.68400","30.47389","0.11118"
"61012","366.03800","30.50324","0.11230"
"61071","366.39200","30.53290","0.11500"
"61130","366.74600","30.56244","0.11695"
"61189","367.10000","30.59179","0.11918"
"61248","367.45400","30.62139","0.12145"
"61307","367.80800","30.65087","0.12472"
"61366","368.16200","30.68034","0.12605"
"61425","368.51600","30.70982","0.12780"
"61484","368.87000","30.73935","0.12935"
"61543","369.22400","30.76883","0.13095"
"61602","369.57800","30.79837","0.13262"
"61661","369.93200","30.82784","0.13467"
"61720","370.28600","30.85738","0.13549"
"61779","370.64000","30.88686","0.13750"
"61838","370.99400","30.91639","0.13881"
"61897","371.34800","30.94581","0.14036"
"61956","371.70200","30.97534","0.14128"
"62015","372.05600","31.00488","0.09615"
"62074","372.41000","31.03429","0.10053"
"62133","372.76400","31.06383","0.10178"
"62192","373.11800","31.09337","0.10205"
"62251","373.47200","31.12279","0.10452"
"62310","373.82600","31.15238","0.10588"
"62369","374.18000","31.18185","0.10555"
"62428","374.53400","31.21133","0.10712"
"62487","374.88800","31.24093","0.11134"
"62546","375.24200","31.27034","0.11341"
"62605","375.59600","31.29982","0.11287"
"62664","375.95000","31.32936","0.02135"
"62723","376.30400","31.35889","0.03110"
"62782","376.65800","31.38837","0.03107"
"62841","377.01200","31.41784","0.03481"
"62900","377.36600","31.44738","0.03169"
"62959","377.72000","31.47686","0.03573"
"63018","378.07400","31.50639","0.03850"
"63077","378.42800","31.53581","0.03366"
"63136","378.78200","31.56540","0.03808"
"63195","379.13600","31.59482","0.03941"
"63254","379.49000","31.62436","0.04031"
"63313","379.84400","31.65377","0.04343"
"63372","380.19800","31.68343","0.04199"
"63431","380.55200","31.71284","0.04389"
"63490","380.90600","31.74232","0.04499"
"63549","381.26000","31.77186","0.04522"
"63608","381.61400","31.80134","0.04690"
"63667","381.96800","31.83081","0.04755"
"63726","382.32200","31.86041","0.04883"
"63785","382.67600","31.88982","0.04916"
"63844","383.03000","31.91936","0.05045"
"63903","383.38400","31.94889","0.05176"
"63962","383.73800","31.97831","0.05203"
"64021","384.09200","32.00785","0.05227"
"64080","384.44600","32.03738","0.05327"
"64139","384.80000","32.06680","0.05379"
"64198","385.15400","32.09640","0.05475"
"64257","385.50800","32.12587","0.05505"
"64316","385.86200","32.15535","0.05537"
"64375","386.21600","32.18488","0.05577"
"64434","386.57000","32.21436","0.05598"
"64493","386.92400","32.24384","0.05633"
"64552","387.27800","32.27337","0.05695"
"64611","387.63200","32.30285","0.05757"
"64670","387.98600","32.33239","0.05751"
"64729","388.34000","32.36186","0.05823"
"64788","388.69400","32.39133","0.05830"
"64847","389.04800","32.42081","0.05871"
"64906","389.40200","32.45035","0.05897"
"64965","389.75600","32.47989","0.05945"
"65024","390.11000","32.50936","0.06012"
"65083","390.46400","32.53884","0.06055"
"65142","390.81800","32.56837","0.06127"
"65201","391.17200","32.59785","0.06174"
"65260","391.52600","32.62738","0.06214"
"65319","391.88000","32.65680","0.06286"
"65378","392.23400","32.68634","0.06364"
"65437","392.58800","32.71588","0.06400"
"65496","392.94200","32.74535","0.06569"
"65555","393.29600","32.77483","0.06621"
"65614","393.65000","32.80436","0.06704"
"65673","394.00400","32.83384","0.06777"
"65732","394.35800","32.86332","0.06893"
"65791","394.71200","32.89291","0.06943"
"65850","395.06600","32.92227","0.07121"
"65909","395.42000","32.95192","0.07256"
"65968","395.77400","32.98140","0.07329"
"66027","396.12800","33.01082","0.05461"
"66086","396.48200","33.04035","0.05676"
"66145","396.83600","33.06989","0.05149"
"66204","397.19000","33.09930","0.05856"
"66263","397.54400","33.12884","0.05631"
"66322","397.89800","33.15838","0.05607"
"66381","398.25200","33.18779","0.06091"
"66440","398.60600","33.21733","0.05687"
"66499","398.96000","33.24687","0.06218"
"66558","399.31400","33.27628","0.06015"
"66617","399.66800","33.30588","0.06168"
"66676","400.02200","33.33535","0.06178"
"66735","400.37600","33.36483","0.06399"
"66794","400.73000","33.39442","0.06112"
"66853","401.08400","33.42384","0.06526"
"66912","401.43800","33.45326","0.06372"
"66971","401.79200","33.48286","0.06370"
"67030","402.14600","33.51239","0.06948"
"67089","402.50000","33.54181","0.06490"
"67148","402.85400","33.57140","0.06953"
"67207","403.20800","33.60082","0.06866"
"67266","403.56200","33.63036","0.06870"
"67325","403.91600","33.65984","0.07194"
"67384","404.27000","33.68931","0.07367"
"67443","404.62400","33.71884","0.07478"
"67502","404.97800","33.74832","0.07398"
"67561","405.33200","33.77785","0.07658"
"67620","405.68600","33.80733","0.07794"
"67679","406.04000","33.83687","0.07836"
"67738","406.39400","33.86629","0.08111"
"67797","406.74800","33.89588","0.08168"
"67856","407.10200","33.92536","0.08232"
"67915","407.45600","33.95483","0.08493"
"67974","407.81000","33.98431","0.08573"
"68033","408.16400","34.01397","0.08662"
"68092","408.51800","34.04326","0.08817"
"68151","408.87200","34.07286","0.09004"
"68210","409.22600","34.10239","0.09168"
"68269","409.58000","34.13181","0.09220"
"68328","409.93400","34.16135","0.09446"
"68387","410.28800","34.19088","0.09670"
"68446","410.64200","34.22030","0.09714"
"68505","410.99600","34.24989","0.09824"
"68564","411.35000","34.27937","0.09989"
"68623","411.70400","34.30879","0.10131"
"68682","412.05800","34.33839","0.10201"
"68741","412.41200","34.36786","0.10262"
"68800","412.76600","34.39734","0.10365"
"68859","413.12000","34.42687","0.10399"
"68918","413.47400","34.45641","0.10478"
"68977","413.82800","34.48589","0.10534"
"69036","414.18200","34.51536","0.10656"
"69095","414.53600","34.54484","0.10772"
"69154","414.89000","34.57438","0.10841"
"69213","415.24400","34.60391","0.05285"
"69272","415.59800","34.63339","0.04769"
"69331","415.95200","34.66286","0.05086"
"69390","416.30600","34.69234","0.05356"
"69449","416.66000","34.72181","0.05072"
"69508","417.01400","34.75135","0.05258"
"69567","417.36800","34.78089","0.05472"
"69626","417.72200","34.81030","0.05469"
"69685","418.07600","34.83984","0.05437"
"69744","418.43000","34.86932","0.05566"
"69803","418.78400","34.89885","0.05604"
"69862","419.13800","34.92833","0.05624"
"69921","419.49200","34.95792","0.05722"
"69980","419.84600","34.98728","0.05661"
"70039","420.20000","35.01688","0.05688"
"70098","420.55400","35.04635","0.05733"
"70157","420.90800","35.07577","0.05766"
"70216","421.26200","35.10536","0.05790"
"70275","421.61600","35.13490","0.05786"
"70334","421.97000","35.16431","0.05842"
"70393","422.32400","35.19385","0.05807"
"70452","422.67800","35.22345","0.05846"
"70511","423.03200","35.25281","0.05887"
"70570","423.38600","35.28234","0.05907"
"70629","423.74000","35.31182","0.05957"
"70688","424.09400","35.34129","0.05941"
"70747","424.44800","35.37095","0.01419"
"70806","424.80200","35.40036","0.01537"
"70865","425.15600","35.42978","0.01026"
"70924","425.51000","35.45938","0.01165"
"70983","425.86400","35.48885","0.01265"
"71042","426.21800","35.51833","0.00999"
"71101","426.57200","35.54787","0.01210"
"71160","426.92600","35.57734","0.01151"
"71219","427.28000","35.60682","0.01072"
"71278","427.63400","35.63635","0.01306"
"71337","427.98800","35.66583","0.01132"
"71396","428.34200","35.69537","0.01184"
"71455","428.69600","35.72490","0.01296"
"71514","429.05000","35.75432","0.01104"
"71573","429.40400","35.78386","0.01221"
"71632","429.75800","35.81339","0.01263"
"71691","430.11200","35.84281","0.01154"
"71750","430.46600","35.87234","0.01231"
"71809","430.82000","35.90188","0.01153"
"71868","431.17400","35.93135","0.01216"
"71927","431.52800","35.96083","0.01239"
"71986","431.88200","35.99037","0.01225"
"72045","432.23600","36.01985","0.01250"
"72104","432.59000","36.04938","0.01172"
"72163","432.94400","36.07886","0.01205"
"72222","433.29800","36.10833","0.01279"
"72281","433.65200","36.13787","0.01274"
"72340","434.00600","36.16740","0.01303"
"72399","434.36000","36.19676","0.01312"
"72442","434.61400","36.21805","0.01248"