File: Trajectories_together/170212_2Specimen_RawData_4.csv
"","V1","V2","V3"
"1","End date","2/12/2017",""
"2","Specimen label","9CG_74",""
"3","Maximum Load","0.06649","N"
"4","Time","Extension","Load"
"5","(s)","(mm)","(N)"
"6","0.00000","7.26742","0.03015"
"75","0.41400","7.30216","0.03024"
"144","0.82800","7.33665","0.02999"
"213","1.24200","7.37115","0.03006"
"282","1.65600","7.40565","0.03066"
"351","2.07000","7.44009","0.03015"
"420","2.48400","7.47459","0.03051"
"489","2.89800","7.50909","0.03070"
"558","3.31200","7.54365","0.03080"
"627","3.72600","7.57802","0.03076"
"696","4.14000","7.61264","0.03050"
"765","4.55400","7.64714","0.03086"
"834","4.96800","7.68164","0.03067"
"903","5.38200","7.71608","0.03127"
"972","5.79600","7.75058","0.03147"
"1041","6.21000","7.78514","0.03091"
"1110","6.62400","7.81957","0.03134"
"1179","7.03800","7.85407","0.03070"
"1248","7.45200","7.88857","0.03188"
"1317","7.86600","7.92313","0.03197"
"1386","8.28000","7.95763","0.03160"
"1455","8.69400","7.99213","0.03128"
"1524","9.10800","8.02657","0.03190"
"1593","9.52200","8.06106","0.03179"
"1662","9.93600","8.09562","0.03152"
"1731","10.35000","8.13012","0.03167"
"1800","10.76400","8.16456","0.03222"
"1869","11.17800","8.19906","0.03141"
"1938","11.59200","8.23362","0.03244"
"2007","12.00600","8.26818","0.03152"
"2076","12.42000","8.30261","0.03276"
"2145","12.83400","8.33705","0.03213"
"2214","13.24800","8.37161","0.03272"
"2283","13.66200","8.40611","0.03231"
"2352","14.07600","8.44061","0.03274"
"2421","14.49000","8.47505","0.03186"
"2490","14.90400","8.50961","0.03234"
"2559","15.31800","8.54416","0.03208"
"2628","15.73200","8.57866","0.03238"
"2697","16.14600","8.61310","0.03252"
"2766","16.56000","8.64754","0.03301"
"2835","16.97400","8.68216","0.03221"
"2904","17.38800","8.71666","0.03261"
"2973","17.80200","8.75109","0.03312"
"3042","18.21600","8.78559","0.03253"
"3111","18.63000","8.82009","0.03285"
"3180","19.04400","8.85465","0.03223"
"3249","19.45800","8.88915","0.03261"
"3318","19.87200","8.92359","0.03268"
"3387","20.28600","8.95809","0.03282"
"3456","20.70000","8.99265","0.03260"
"3525","21.11400","9.02714","0.03274"
"3594","21.52800","9.06158","0.03305"
"3663","21.94200","9.09608","0.03290"
"3732","22.35600","9.13064","0.03349"
"3801","22.77000","9.16514","0.03349"
"3870","23.18400","9.19964","0.03280"
"3939","23.59800","9.23413","0.03306"
"4008","24.01200","9.26863","0.03281"
"4077","24.42600","9.30307","0.03331"
"4146","24.84000","9.33763","0.03312"
"4215","25.25400","9.37207","0.03274"
"4284","25.66800","9.40663","0.03220"
"4353","26.08200","9.44113","0.03290"
"4422","26.49600","9.47569","0.03240"
"4491","26.91000","9.51012","0.03284"
"4560","27.32400","9.54462","0.03303"
"4629","27.73800","9.57912","0.03283"
"4698","28.15200","9.61362","0.03305"
"4767","28.56600","9.64812","0.03301"
"4836","28.98000","9.68256","0.03282"
"4905","29.39400","9.71717","0.03340"
"4974","29.80800","9.75167","0.03291"
"5043","30.22200","9.78617","0.03308"
"5112","30.63600","9.82061","0.03267"
"5181","31.05000","9.85511","0.03349"
"5250","31.46400","9.88961","0.03296"
"5319","31.87800","9.92411","0.03317"
"5388","32.29200","9.95860","0.03319"
"5457","32.70600","9.99304","0.03315"
"5526","33.12000","10.02766","0.03358"
"5595","33.53400","10.06216","0.03323"
"5664","33.94800","10.09660","0.03341"
"5733","34.36200","10.13110","0.03330"
"5802","34.77600","10.16560","0.03369"
"5871","35.19000","10.20009","0.03314"
"5940","35.60400","10.23459","0.03356"
"6009","36.01800","10.26909","0.03349"
"6078","36.43200","10.30359","0.03351"
"6147","36.84600","10.33815","0.03367"
"6216","37.26000","10.37265","0.03309"
"6285","37.67400","10.40708","0.03350"
"6354","38.08800","10.44158","0.03409"
"6423","38.50200","10.47614","0.03382"
"6492","38.91600","10.51064","0.03385"
"6561","39.33000","10.54508","0.03338"
"6630","39.74400","10.57958","0.03323"
"6699","40.15800","10.61414","0.03370"
"6768","40.57200","10.64863","0.03348"
"6837","40.98600","10.68313","0.03333"
"6906","41.40000","10.71757","0.03333"
"6975","41.81400","10.75213","0.03372"
"7044","42.22800","10.78657","0.03319"
"7113","42.64200","10.82113","0.03391"
"7182","43.05600","10.85557","0.03360"
"7251","43.47000","10.89007","0.03351"
"7320","43.88400","10.92456","0.03388"
"7389","44.29800","10.95912","0.03343"
"7458","44.71200","10.99362","0.03363"
"7527","45.12600","11.02806","0.03370"
"7596","45.54000","11.06262","0.03380"
"7665","45.95400","11.09712","0.03346"
"7734","46.36800","11.13162","0.03317"
"7803","46.78200","11.16599","0.03336"
"7872","47.19600","11.20061","0.03402"
"7941","47.61000","11.23517","0.03410"
"8010","48.02400","11.26967","0.03323"
"8079","48.43800","11.30411","0.03358"
"8148","48.85200","11.33861","0.03387"
"8217","49.26600","11.37311","0.03418"
"8286","49.68000","11.40760","0.03352"
"8355","50.09400","11.44210","0.03390"
"8424","50.50800","11.47660","0.03394"
"8493","50.92200","11.51116","0.03394"
"8562","51.33600","11.54566","0.03433"
"8631","51.75000","11.58016","0.03407"
"8700","52.16400","11.61459","0.03380"
"8769","52.57800","11.64909","0.03334"
"8838","52.99200","11.68365","0.03440"
"8907","53.40600","11.71809","0.03434"
"8976","53.82000","11.75259","0.03385"
"9045","54.23400","11.78709","0.03412"
"9114","54.64800","11.82159","0.03362"
"9183","55.06200","11.85614","0.03456"
"9252","55.47600","11.89064","0.03377"
"9321","55.89000","11.92508","0.03414"
"9390","56.30400","11.95964","0.03387"
"9459","56.71800","11.99420","0.03461"
"9528","57.13200","12.02864","0.03420"
"9597","57.54600","12.06308","0.03435"
"9666","57.96000","12.09763","0.03435"
"9735","58.37400","12.13213","0.03390"
"9804","58.78800","12.16669","0.03468"
"9873","59.20200","12.20107","0.03443"
"9942","59.61600","12.23557","0.03448"
"10011","60.03000","12.27013","0.03443"
"10080","60.44400","12.30468","0.03406"
"10149","60.85800","12.33906","0.03414"
"10218","61.27200","12.37356","0.03472"
"10287","61.68600","12.40812","0.03454"
"10356","62.10000","12.44262","0.03461"
"10425","62.51400","12.47718","0.03458"
"10494","62.92800","12.51162","0.03431"
"10563","63.34200","12.54612","0.03409"
"10632","63.75600","12.58061","0.03527"
"10701","64.17000","12.61517","0.03406"
"10770","64.58400","12.64955","0.03453"
"10839","64.99800","12.68411","0.03445"
"10908","65.41200","12.71861","0.03457"
"10977","65.82600","12.75317","0.03511"
"11046","66.24000","12.78761","0.03538"
"11115","66.65400","12.82210","0.03472"
"11184","67.06800","12.85660","0.03425"
"11253","67.48200","12.89110","0.03475"
"11322","67.89600","12.92560","0.03475"
"11391","68.31000","12.96010","0.03459"
"11460","68.72400","12.99460","0.03524"
"11529","69.13800","13.02910","0.03451"
"11598","69.55200","13.06365","0.03488"
"11667","69.96600","13.09809","0.03494"
"11736","70.38000","13.13259","0.03488"
"11805","70.79400","13.16709","0.03515"
"11874","71.20800","13.20159","0.03526"
"11943","71.62200","13.23615","0.03508"
"12012","72.03600","13.27053","0.03492"
"12081","72.45000","13.30514","0.03535"
"12150","72.86400","13.33970","0.03479"
"12219","73.27800","13.37414","0.03552"
"12288","73.69200","13.40858","0.03513"
"12357","74.10600","13.44314","0.03544"
"12426","74.52000","13.47770","0.03509"
"12495","74.93400","13.51208","0.03527"
"12564","75.34800","13.54657","0.03551"
"12633","75.76200","13.58107","0.03570"
"12702","76.17600","13.61563","0.03522"
"12771","76.59000","13.65019","0.03482"
"12840","77.00400","13.68457","0.03558"
"12909","77.41800","13.71907","0.03580"
"12978","77.83200","13.75363","0.03554"
"13047","78.24600","13.78806","0.03579"
"13116","78.66000","13.82262","0.03597"
"13185","79.07400","13.85706","0.03562"
"13254","79.48800","13.89162","0.03516"
"13323","79.90200","13.92612","0.03499"
"13392","80.31600","13.96068","0.03511"
"13461","80.73000","13.99512","0.03566"
"13530","81.14400","14.02961","0.03574"
"13599","81.55800","14.06411","0.03575"
"13668","81.97200","14.09867","0.03530"
"13737","82.38600","14.13305","0.03526"
"13806","82.80000","14.16755","0.03553"
"13875","83.21400","14.20211","0.03525"
"13944","83.62800","14.23667","0.03582"
"14013","84.04200","14.27110","0.03591"
"14082","84.45600","14.30560","0.03599"
"14151","84.87000","14.34010","0.03512"
"14220","85.28400","14.37460","0.03492"
"14289","85.69800","14.40910","0.03502"
"14358","86.11200","14.44354","0.03478"
"14427","86.52600","14.47810","0.03506"
"14496","86.94000","14.51260","0.03529"
"14565","87.35400","14.54715","0.03522"
"14634","87.76800","14.58165","0.03528"
"14703","88.18200","14.61609","0.03570"
"14772","88.59600","14.65065","0.03567"
"14841","89.01000","14.68509","0.03559"
"14910","89.42400","14.71965","0.03579"
"14979","89.83800","14.75402","0.03541"
"15048","90.25200","14.78864","0.03536"
"15117","90.66600","14.82314","0.03551"
"15186","91.08000","14.85770","0.03528"
"15255","91.49400","14.89214","0.03538"
"15324","91.90800","14.92664","0.03563"
"15393","92.32200","14.96113","0.03566"
"15462","92.73600","14.99563","0.03549"
"15531","93.15000","15.03013","0.03569"
"15600","93.56400","15.06457","0.03600"
"15669","93.97800","15.09913","0.03670"
"15738","94.39200","15.13363","0.03573"
"15807","94.80600","15.16813","0.03636"
"15876","95.22000","15.20263","0.03545"
"15945","95.63400","15.23706","0.03589"
"16014","96.04800","15.27162","0.03551"
"16083","96.46200","15.30612","0.03535"
"16152","96.87600","15.34062","0.03555"
"16221","97.29000","15.37506","0.03627"
"16290","97.70400","15.40956","0.03598"
"16359","98.11800","15.44411","0.03597"
"16428","98.53200","15.47867","0.03632"
"16497","98.94600","15.51311","0.03577"
"16566","99.36000","15.54761","0.03597"
"16635","99.77400","15.58211","0.03621"
"16704","100.18800","15.61661","0.03661"
"16773","100.60200","15.65105","0.03597"
"16842","101.01600","15.68561","0.03655"
"16911","101.43000","15.72016","0.03602"
"16980","101.84400","15.75466","0.03634"
"17049","102.25800","15.78910","0.03655"
"17118","102.67200","15.82360","0.03695"
"17187","103.08600","15.85810","0.03670"
"17256","103.50000","15.89260","0.03667"
"17325","103.91400","15.92710","0.03673"
"17394","104.32800","15.96159","0.03656"
"17463","104.74200","15.99603","0.03670"
"17532","105.15600","16.03065","0.03717"
"17601","105.57000","16.06515","0.03678"
"17670","105.98400","16.09953","0.03641"
"17739","106.39800","16.13408","0.03724"
"17808","106.81200","16.16864","0.03708"
"17877","107.22600","16.20314","0.03715"
"17946","107.64000","16.23752","0.03742"
"18015","108.05400","16.27208","0.03727"
"18084","108.46800","16.30664","0.03735"
"18153","108.88200","16.34114","0.03727"
"18222","109.29600","16.37564","0.03748"
"18291","109.71000","16.41007","0.03720"
"18360","110.12400","16.44463","0.03713"
"18429","110.53800","16.47907","0.03706"
"18498","110.95200","16.51363","0.03766"
"18567","111.36600","16.54807","0.03727"
"18636","111.78000","16.58257","0.03806"
"18705","112.19400","16.61712","0.03749"
"18774","112.60800","16.65168","0.03751"
"18843","113.02200","16.68612","0.03751"
"18912","113.43600","16.72056","0.03771"
"18981","113.85000","16.75512","0.03698"
"19050","114.26400","16.78962","0.03777"
"19119","114.67800","16.82412","0.03710"
"19188","115.09200","16.85855","0.03778"
"19257","115.50600","16.89311","0.03723"
"19326","115.92000","16.92767","0.03768"
"19395","116.33400","16.96217","0.03726"
"19464","116.74800","16.99661","0.03779"
"19533","117.16200","17.03111","0.03813"
"19602","117.57600","17.06561","0.03732"
"19671","117.99000","17.10011","0.03761"
"19740","118.40400","17.13454","0.03772"
"19809","118.81800","17.16910","0.03776"
"19878","119.23200","17.20360","0.03743"
"19947","119.64600","17.23816","0.03799"
"20016","120.06000","17.27260","0.03751"
"20085","120.47400","17.30710","0.03708"
"20154","120.88800","17.34165","0.03755"
"20223","121.30200","17.37609","0.03645"
"20292","121.71600","17.41059","0.03678"
"20361","122.13000","17.44509","0.03710"
"20430","122.54400","17.47965","0.03759"
"20499","122.95800","17.51415","0.03742"
"20568","123.37200","17.54871","0.03704"
"20637","123.78600","17.58315","0.03745"
"20706","124.20000","17.61758","0.03758"
"20775","124.61400","17.65214","0.03765"
"20844","125.02800","17.68664","0.03728"
"20913","125.44200","17.72114","0.03792"
"20982","125.85600","17.75558","0.03775"
"21051","126.27000","17.79008","0.03785"
"21120","126.68400","17.82463","0.03705"
"21189","127.09800","17.85913","0.03669"
"21258","127.51200","17.89363","0.03729"
"21327","127.92600","17.92813","0.03663"
"21396","128.34000","17.96263","0.03749"
"21465","128.75400","17.99713","0.03652"
"21534","129.16800","18.03157","0.03710"
"21603","129.58200","18.06606","0.03745"
"21672","129.99600","18.10062","0.03717"
"21741","130.41000","18.13512","0.03762"
"21810","130.82400","18.16962","0.03759"
"21879","131.23800","18.20406","0.03733"
"21948","131.65200","18.23868","0.03789"
"22017","132.06600","18.27312","0.03711"
"22086","132.48000","18.30762","0.03719"
"22155","132.89400","18.34205","0.03726"
"22224","133.30800","18.37661","0.03780"
"22293","133.72200","18.41111","0.03787"
"22362","134.13600","18.44567","0.03782"
"22431","134.55000","18.48011","0.03830"
"22500","134.96400","18.51461","0.03791"
"22569","135.37800","18.54916","0.03820"
"22638","135.79200","18.58360","0.03791"
"22707","136.20600","18.61810","0.03844"
"22776","136.62000","18.65254","0.03794"
"22845","137.03400","18.68710","0.03809"
"22914","137.44800","18.72160","0.03844"
"22983","137.86200","18.75610","0.03860"
"23052","138.27600","18.79053","0.03850"
"23121","138.69000","18.82509","0.03884"
"23190","139.10400","18.85959","0.03858"
"23259","139.51800","18.89409","0.03796"
"23328","139.93200","18.92859","0.03824"
"23397","140.34600","18.96309","0.03798"
"23466","140.76000","18.99759","0.03899"
"23535","141.17400","19.03214","0.03824"
"23604","141.58800","19.06664","0.03883"
"23673","142.00200","19.10102","0.03857"
"23742","142.41600","19.13564","0.03852"
"23811","142.83000","19.17014","0.03845"
"23880","143.24400","19.20464","0.03861"
"23949","143.65800","19.23902","0.03881"
"24018","144.07200","19.27357","0.03871"
"24087","144.48600","19.30813","0.03940"
"24156","144.90000","19.34269","0.03913"
"24225","145.31400","19.37707","0.03929"
"24294","145.72800","19.41157","0.03985"
"24363","146.14200","19.44613","0.03902"
"24432","146.55600","19.48063","0.03950"
"24501","146.97000","19.51513","0.03942"
"24570","147.38400","19.54956","0.03914"
"24639","147.79800","19.58406","0.03929"
"24708","148.21200","19.61862","0.03956"
"24777","148.62600","19.65318","0.03935"
"24846","149.04000","19.68762","0.03969"
"24915","149.45400","19.72211","0.03907"
"24984","149.86800","19.75661","0.04012"
"25053","150.28200","19.79117","0.04037"
"25122","150.69600","19.82555","0.04020"
"25191","151.11000","19.86005","0.04027"
"25260","151.52400","19.89461","0.04053"
"25329","151.93800","19.92917","0.04031"
"25398","152.35200","19.96367","0.03958"
"25467","152.76600","19.99811","0.04022"
"25536","153.18000","20.03266","0.03993"
"25605","153.59400","20.06710","0.04012"
"25674","154.00800","20.10160","0.04017"
"25743","154.42200","20.13604","0.04046"
"25812","154.83600","20.17060","0.04058"
"25881","155.25000","20.20515","0.04070"
"25950","155.66400","20.23965","0.04091"
"26019","156.07800","20.27409","0.04083"
"26088","156.49200","20.30859","0.04104"
"26157","156.90600","20.34315","0.04061"
"26226","157.32000","20.37765","0.04063"
"26295","157.73400","20.41215","0.04069"
"26364","158.14800","20.44653","0.04132"
"26433","158.56200","20.48114","0.04143"
"26502","158.97600","20.51564","0.04070"
"26571","159.39000","20.55020","0.04090"
"26640","159.80400","20.58464","0.04019"
"26709","160.21800","20.61908","0.04029"
"26778","160.63200","20.65370","0.04096"
"26847","161.04600","20.68814","0.04137"
"26916","161.46000","20.72263","0.04056"
"26985","161.87400","20.75707","0.04116"
"27054","162.28800","20.79163","0.04123"
"27123","162.70200","20.82613","0.04122"
"27192","163.11600","20.86057","0.04108"
"27261","163.53000","20.89513","0.04193"
"27330","163.94400","20.92962","0.04205"
"27399","164.35800","20.96406","0.04191"
"27468","164.77200","20.99862","0.04167"
"27537","165.18600","21.03306","0.04174"
"27606","165.60000","21.06756","0.04165"
"27675","166.01400","21.10212","0.04201"
"27744","166.42800","21.13667","0.04233"
"27813","166.84200","21.17112","0.04188"
"27882","167.25600","21.20561","0.04193"
"27951","167.67000","21.24017","0.04185"
"28020","168.08400","21.27461","0.04213"
"28089","168.49800","21.30911","0.04196"
"28158","168.91200","21.34355","0.04277"
"28227","169.32600","21.37811","0.04232"
"28296","169.74000","21.41266","0.04259"
"28365","170.15400","21.44710","0.04287"
"28434","170.56800","21.48160","0.04247"
"28503","170.98200","21.51610","0.04225"
"28572","171.39600","21.55060","0.04154"
"28641","171.81000","21.58510","0.04252"
"28710","172.22400","21.61960","0.04203"
"28779","172.63800","21.65409","0.04198"
"28848","173.05200","21.68859","0.04290"
"28917","173.46600","21.72315","0.04294"
"28986","173.88000","21.75759","0.04287"
"29055","174.29400","21.79203","0.04237"
"29124","174.70800","21.82664","0.04293"
"29193","175.12200","21.86115","0.04273"
"29262","175.53600","21.89558","0.04178"
"29331","175.95000","21.93002","0.04246"
"29400","176.36400","21.96458","0.04287"
"29469","176.77800","21.99914","0.04264"
"29538","177.19200","22.03364","0.04311"
"29607","177.60600","22.06814","0.04316"
"29676","178.02000","22.10258","0.04326"
"29745","178.43400","22.13713","0.04354"
"29814","178.84800","22.17163","0.04371"
"29883","179.26200","22.20613","0.04362"
"29952","179.67600","22.24057","0.04371"
"30021","180.09000","22.27513","0.04399"
"30090","180.50400","22.30963","0.04349"
"30159","180.91800","22.34413","0.04393"
"30228","181.33200","22.37862","0.04390"
"30297","181.74600","22.41306","0.04381"
"30366","182.16000","22.44762","0.04438"
"30435","182.57400","22.48212","0.04411"
"30504","182.98800","22.51662","0.04411"
"30573","183.40200","22.55106","0.04492"
"30642","183.81600","22.58562","0.04398"
"30711","184.23000","22.62011","0.04480"
"30780","184.64400","22.65461","0.04413"
"30849","185.05800","22.68905","0.04480"
"30918","185.47200","22.72367","0.04503"
"30987","185.88600","22.75817","0.04478"
"31056","186.30000","22.79261","0.04470"
"31125","186.71400","22.82704","0.04425"
"31194","187.12800","22.86160","0.04455"
"31263","187.54200","22.89616","0.04498"
"31332","187.95600","22.93066","0.04516"
"31401","188.37000","22.96510","0.04471"
"31470","188.78400","22.99960","0.04377"
"31539","189.19800","23.03416","0.04361"
"31608","189.61200","23.06866","0.04354"
"31677","190.02600","23.10310","0.04446"
"31746","190.44000","23.13753","0.04430"
"31815","190.85400","23.17209","0.04441"
"31884","191.26800","23.20665","0.04464"
"31953","191.68200","23.24115","0.04500"
"32022","192.09600","23.27559","0.04511"
"32091","192.51000","23.31008","0.04546"
"32160","192.92400","23.34464","0.04489"
"32229","193.33800","23.37914","0.04511"
"32298","193.75200","23.41358","0.04449"
"32367","194.16600","23.44808","0.04534"
"32436","194.58000","23.48264","0.04571"
"32505","194.99400","23.51714","0.04574"
"32574","195.40800","23.55164","0.04571"
"32643","195.82200","23.58614","0.04508"
"32712","196.23600","23.62063","0.04536"
"32781","196.65000","23.65513","0.04519"
"32850","197.06400","23.68963","0.04545"
"32919","197.47800","23.72407","0.04499"
"32988","197.89200","23.75863","0.04372"
"33057","198.30600","23.79312","0.04250"
"33126","198.72000","23.82763","0.04305"
"33195","199.13400","23.86206","0.04223"
"33264","199.54800","23.89662","0.04169"
"33333","199.96200","23.93112","0.04182"
"33402","200.37600","23.96562","0.04276"
"33471","200.79000","24.00012","0.04275"
"33540","201.20400","24.03456","0.04396"
"33609","201.61800","24.06911","0.04405"
"33678","202.03200","24.10367","0.04342"
"33747","202.44600","24.13817","0.04367"
"33816","202.86000","24.17261","0.04357"
"33885","203.27400","24.20705","0.04451"
"33954","203.68800","24.24166","0.04303"
"34023","204.10200","24.27611","0.04205"
"34092","204.51600","24.31060","0.04185"
"34161","204.93000","24.34510","0.04230"
"34230","205.34400","24.37966","0.04209"
"34299","205.75800","24.41416","0.04208"
"34368","206.17200","24.44860","0.04257"
"34437","206.58600","24.48304","0.04226"
"34506","207.00000","24.51765","0.04243"
"34575","207.41400","24.55209","0.04240"
"34644","207.82800","24.58659","0.04313"
"34713","208.24200","24.62109","0.04396"
"34782","208.65600","24.65559","0.04363"
"34851","209.07000","24.69015","0.04403"
"34920","209.48400","24.72465","0.04421"
"34989","209.89800","24.75908","0.04420"
"35058","210.31200","24.79358","0.04428"
"35127","210.72600","24.82814","0.04483"
"35196","211.14000","24.86264","0.04511"
"35265","211.55400","24.89708","0.04514"
"35334","211.96800","24.93158","0.04412"
"35403","212.38200","24.96608","0.04467"
"35472","212.79600","25.00069","0.04485"
"35541","213.21000","25.03513","0.04513"
"35610","213.62400","25.06963","0.04530"
"35679","214.03800","25.10407","0.04632"
"35748","214.45200","25.13863","0.04596"
"35817","214.86600","25.17313","0.04654"
"35886","215.28000","25.20763","0.04724"
"35955","215.69400","25.24212","0.04655"
"36024","216.10800","25.27662","0.04814"
"36093","216.52200","25.31112","0.04744"
"36162","216.93600","25.34562","0.04787"
"36231","217.35000","25.38006","0.04818"
"36300","217.76400","25.41462","0.04875"
"36369","218.17800","25.44912","0.04868"
"36438","218.59200","25.48368","0.04636"
"36507","219.00600","25.51805","0.04733"
"36576","219.42000","25.55261","0.04784"
"36645","219.83400","25.58711","0.04753"
"36714","220.24800","25.62161","0.04720"
"36783","220.66200","25.65611","0.04805"
"36852","221.07600","25.69061","0.04848"
"36921","221.49000","25.72516","0.04823"
"36990","221.90400","25.75966","0.04872"
"37059","222.31800","25.79416","0.04869"
"37128","222.73200","25.82854","0.04909"
"37197","223.14600","25.86310","0.04901"
"37266","223.56000","25.89766","0.04905"
"37335","223.97400","25.93216","0.04895"
"37404","224.38800","25.96665","0.04962"
"37473","224.80200","26.00109","0.04947"
"37542","225.21600","26.03565","0.04956"
"37611","225.63000","26.07015","0.04938"
"37680","226.04400","26.10459","0.05035"
"37749","226.45800","26.13903","0.05037"
"37818","226.87200","26.17358","0.05103"
"37887","227.28600","26.20814","0.05098"
"37956","227.70000","26.24264","0.05058"
"38025","228.11400","26.27708","0.05126"
"38094","228.52800","26.31164","0.05148"
"38163","228.94200","26.34614","0.05092"
"38232","229.35600","26.38058","0.05187"
"38301","229.77000","26.41507","0.05229"
"38370","230.18400","26.44958","0.05290"
"38439","230.59800","26.48413","0.05236"
"38508","231.01200","26.51863","0.05266"
"38577","231.42600","26.55313","0.05369"
"38646","231.84000","26.58757","0.05393"
"38715","232.25400","26.62213","0.05437"
"38784","232.66800","26.65662","0.05422"
"38853","233.08200","26.69113","0.05405"
"38922","233.49600","26.72556","0.05485"
"38991","233.91000","26.76006","0.05404"
"39060","234.32400","26.79462","0.05472"
"39129","234.73800","26.82912","0.05520"
"39198","235.15200","26.86356","0.05530"
"39267","235.56600","26.89811","0.05551"
"39336","235.98000","26.93268","0.05610"
"39405","236.39400","26.96717","0.05561"
"39474","236.80800","27.00155","0.05615"
"39543","237.22200","27.03605","0.05645"
"39612","237.63600","27.07061","0.05492"
"39681","238.05000","27.10511","0.05607"
"39750","238.46400","27.13966","0.05625"
"39819","238.87800","27.17404","0.05588"
"39888","239.29200","27.20860","0.05672"
"39957","239.70600","27.24316","0.05672"
"40026","240.12000","27.27760","0.05718"
"40095","240.53400","27.31204","0.05613"
"40164","240.94800","27.34660","0.05613"
"40233","241.36200","27.38115","0.05690"
"40302","241.77600","27.41566","0.05655"
"40371","242.19000","27.45009","0.05740"
"40440","242.60400","27.48459","0.05680"
"40509","243.01800","27.51909","0.05722"
"40578","243.43200","27.55365","0.05743"
"40647","243.84600","27.58815","0.05582"
"40716","244.26000","27.62252","0.05566"
"40785","244.67400","27.65708","0.05658"
"40854","245.08800","27.69164","0.05621"
"40923","245.50200","27.72620","0.05641"
"40992","245.91600","27.76058","0.05701"
"41061","246.33000","27.79508","0.05713"
"41130","246.74400","27.82964","0.05748"
"41199","247.15800","27.86414","0.05610"
"41268","247.57200","27.89857","0.05628"
"41337","247.98600","27.93307","0.05644"
"41406","248.40000","27.96763","0.05719"
"41475","248.81400","28.00213","0.05718"
"41544","249.22800","28.03657","0.05759"
"41613","249.64200","28.07107","0.05650"
"41682","250.05600","28.10569","0.05684"
"41751","250.47000","28.14012","0.05672"
"41820","250.88400","28.17462","0.05714"
"41889","251.29800","28.20906","0.05735"
"41958","251.71200","28.24362","0.05688"
"42027","252.12600","28.27812","0.05696"
"42096","252.54000","28.31262","0.05796"
"42165","252.95400","28.34711","0.05658"
"42234","253.36800","28.38161","0.05680"
"42303","253.78200","28.41617","0.05756"
"42372","254.19600","28.45067","0.05788"
"42441","254.61000","28.48511","0.05757"
"42510","255.02400","28.51955","0.05822"
"42579","255.43800","28.55411","0.05786"
"42648","255.85200","28.58866","0.05849"
"42717","256.26600","28.62310","0.05668"
"42786","256.68000","28.65760","0.05727"
"42855","257.09400","28.69210","0.05735"
"42924","257.50800","28.72666","0.05714"
"42993","257.92200","28.76116","0.05787"
"43062","258.33600","28.79566","0.05792"
"43131","258.75000","28.83010","0.05882"
"43200","259.16400","28.86459","0.05854"
"43269","259.57800","28.89909","0.05834"
"43338","259.99200","28.93359","0.05831"
"43407","260.40600","28.96809","0.05849"
"43476","260.82000","29.00265","0.05902"
"43545","261.23400","29.03715","0.05928"
"43614","261.64800","29.07164","0.05883"
"43683","262.06200","29.10608","0.05907"
"43752","262.47600","29.14058","0.05943"
"43821","262.89000","29.17514","0.05920"
"43890","263.30400","29.20964","0.05938"
"43959","263.71800","29.24408","0.05932"
"44028","264.13200","29.27864","0.05951"
"44097","264.54600","29.31319","0.06010"
"44166","264.96000","29.34763","0.06034"
"44235","265.37400","29.38213","0.06061"
"44304","265.78800","29.41657","0.06080"
"44373","266.20200","29.45113","0.06080"
"44442","266.61600","29.48563","0.06060"
"44511","267.03000","29.52013","0.06068"
"44580","267.44400","29.55457","0.06048"
"44649","267.85800","29.58906","0.06014"
"44718","268.27200","29.62362","0.06082"
"44787","268.68600","29.65812","0.06043"
"44856","269.10000","29.69262","0.06053"
"44925","269.51400","29.72706","0.06118"
"44994","269.92800","29.76156","0.06029"
"45063","270.34200","29.79612","0.06108"
"45132","270.75600","29.83061","0.06069"
"45201","271.17000","29.86505","0.06054"
"45270","271.58400","29.89961","0.06070"
"45339","271.99800","29.93417","0.06044"
"45408","272.41200","29.96861","0.06036"
"45477","272.82600","30.00311","0.06079"
"45546","273.24000","30.03760","0.06075"
"45615","273.65400","30.07216","0.06082"
"45684","274.06800","30.10660","0.06077"
"45753","274.48200","30.14110","0.05984"
"45822","274.89600","30.17560","0.06053"
"45891","275.31000","30.21010","0.06010"
"45960","275.72400","30.24465","0.05946"
"46029","276.13800","30.27909","0.05957"
"46098","276.55200","30.31353","0.05973"
"46167","276.96600","30.34803","0.05958"
"46236","277.38000","30.38265","0.05949"
"46305","277.79400","30.41715","0.06002"
"46374","278.20800","30.45159","0.05969"
"46443","278.62200","30.48602","0.05926"
"46512","279.03600","30.52064","0.05989"
"46581","279.45000","30.55514","0.06013"
"46650","279.86400","30.58958","0.05578"
"46719","280.27800","30.62408","0.05758"
"46788","280.69200","30.65858","0.05861"
"46857","281.10600","30.69308","0.05877"
"46926","281.52000","30.72764","0.05910"
"46995","281.93400","30.76207","0.05970"
"47064","282.34800","30.79663","0.05977"
"47133","282.76200","30.83113","0.06010"
"47202","283.17600","30.86563","0.05999"
"47271","283.59000","30.90007","0.06018"
"47340","284.00400","30.93463","0.06087"
"47409","284.41800","30.96912","0.06096"
"47478","284.83200","31.00363","0.06077"
"47547","285.24600","31.03812","0.06038"
"47616","285.66000","31.07262","0.06020"
"47685","286.07400","31.10712","0.06038"
"47754","286.48800","31.14162","0.05933"
"47823","286.90200","31.17612","0.05964"
"47892","287.31600","31.21056","0.05987"
"47961","287.73000","31.24511","0.06058"
"48030","288.14400","31.27967","0.06119"
"48099","288.55800","31.31417","0.06133"
"48168","288.97200","31.34861","0.06098"
"48237","289.38600","31.38311","0.06129"
"48306","289.80000","31.41766","0.06145"
"48375","290.21400","31.45216","0.06187"
"48444","290.62800","31.48660","0.06094"
"48513","291.04200","31.52104","0.06183"
"48582","291.45600","31.55560","0.06150"
"48651","291.87000","31.59016","0.06147"
"48720","292.28400","31.62466","0.06113"
"48789","292.69800","31.65910","0.06129"
"48858","293.11200","31.69365","0.06136"
"48927","293.52600","31.72815","0.06133"
"48996","293.94000","31.76259","0.06142"
"49065","294.35400","31.79709","0.06164"
"49134","294.76800","31.83153","0.06179"
"49203","295.18200","31.86615","0.06141"
"49272","295.59600","31.90064","0.06112"
"49341","296.01000","31.93509","0.06110"
"49410","296.42400","31.96958","0.06115"
"49479","296.83800","32.00414","0.06134"
"49548","297.25200","32.03864","0.06134"
"49617","297.66600","32.07314","0.06133"
"49686","298.08000","32.10758","0.06136"
"49755","298.49400","32.14208","0.06086"
"49824","298.90800","32.17663","0.06081"
"49893","299.32200","32.21113","0.06166"
"49962","299.73600","32.24563","0.06122"
"50031","300.15000","32.28007","0.06172"
"50100","300.56400","32.31463","0.06119"
"50169","300.97800","32.34912","0.06131"
"50238","301.39200","32.38363","0.06105"
"50307","301.80600","32.41806","0.06152"
"50376","302.22000","32.45256","0.06139"
"50445","302.63400","32.48712","0.06058"
"50514","303.04800","32.52162","0.06065"
"50583","303.46200","32.55606","0.06054"
"50652","303.87600","32.59062","0.05946"
"50721","304.29000","32.62518","0.05916"
"50790","304.70400","32.65967","0.05896"
"50859","305.11800","32.69405","0.05898"
"50928","305.53200","32.72855","0.05953"
"50997","305.94600","32.76311","0.05960"
"51066","306.36000","32.79761","0.05949"
"51135","306.77400","32.83210","0.05949"
"51204","307.18800","32.86655","0.06029"
"51273","307.60200","32.90110","0.05961"
"51342","308.01600","32.93566","0.05988"
"51411","308.43000","32.97016","0.05946"
"51480","308.84400","33.00454","0.05998"
"51549","309.25800","33.03910","0.06005"
"51618","309.67200","33.07366","0.05944"
"51687","310.08600","33.10809","0.05976"
"51756","310.50000","33.14259","0.05940"
"51825","310.91400","33.17709","0.05942"
"51894","311.32800","33.21159","0.05906"
"51963","311.74200","33.24615","0.05877"
"52032","312.15600","33.28065","0.05988"
"52101","312.57000","33.31503","0.05922"
"52170","312.98400","33.34959","0.05927"
"52239","313.39800","33.38409","0.06034"
"52308","313.81200","33.41864","0.05895"
"52377","314.22600","33.45308","0.05912"
"52446","314.64000","33.48758","0.05926"
"52515","315.05400","33.52214","0.05961"
"52584","315.46800","33.55664","0.06015"
"52653","315.88200","33.59107","0.05963"
"52722","316.29600","33.62557","0.05945"
"52791","316.71000","33.66007","0.05945"
"52860","317.12400","33.69457","0.06003"
"52929","317.53800","33.72907","0.06029"
"52998","317.95200","33.76357","0.06000"
"53067","318.36600","33.79813","0.06056"
"53136","318.78000","33.83263","0.06050"
"53205","319.19400","33.86712","0.06039"
"53274","319.60800","33.90156","0.06107"
"53343","320.02200","33.93606","0.06028"
"53412","320.43600","33.97068","0.06028"
"53481","320.85000","34.00518","0.06043"
"53550","321.26400","34.03956","0.06043"
"53619","321.67800","34.07405","0.06094"
"53688","322.09200","34.10867","0.06057"
"53757","322.50600","34.14317","0.06092"
"53826","322.92000","34.17761","0.06105"
"53895","323.33400","34.21205","0.06134"
"53964","323.74800","34.24661","0.06108"
"54033","324.16200","34.28117","0.06164"
"54102","324.57600","34.31567","0.06147"
"54171","324.99000","34.35011","0.06153"
"54240","325.40400","34.38466","0.06177"
"54309","325.81800","34.41916","0.06200"
"54378","326.23200","34.45366","0.06237"
"54447","326.64600","34.48810","0.06128"
"54516","327.06000","34.52260","0.06194"
"54585","327.47400","34.55709","0.06180"
"54654","327.88800","34.59165","0.06113"
"54723","328.30200","34.62609","0.06171"
"54792","328.71600","34.66065","0.06272"
"54861","329.13000","34.69515","0.06238"
"54930","329.54400","34.72965","0.06218"
"54999","329.95800","34.76414","0.06220"
"55068","330.37200","34.79853","0.06233"
"55137","330.78600","34.83308","0.06203"
"55206","331.20000","34.86764","0.06255"
"55275","331.61400","34.90214","0.06184"
"55344","332.02800","34.93658","0.06232"
"55413","332.44200","34.97108","0.06297"
"55482","332.85600","35.00570","0.06197"
"55551","333.27000","35.04019","0.06287"
"55620","333.68400","35.07463","0.06334"
"55689","334.09800","35.10907","0.06296"
"55758","334.51200","35.14363","0.06283"
"55827","334.92600","35.17813","0.06276"
"55896","335.34000","35.21263","0.05968"
"55965","335.75400","35.24707","0.05944"
"56034","336.16800","35.28162","0.06031"
"56103","336.58200","35.31612","0.05978"
"56172","336.99600","35.35062","0.05983"
"56241","337.41000","35.38512","0.06059"
"56310","337.82400","35.41956","0.05982"
"56379","338.23800","35.45412","0.06062"
"56448","338.65200","35.48862","0.06130"
"56517","339.06600","35.52311","0.06033"
"56586","339.48000","35.55761","0.06050"
"56655","339.89400","35.59211","0.06007"
"56724","340.30800","35.62667","0.06056"
"56793","340.72200","35.66117","0.06083"
"56862","341.13600","35.69555","0.06052"
"56931","341.55000","35.73005","0.06091"
"57000","341.96400","35.76466","0.05776"
"57069","342.37800","35.79910","0.05870"
"57138","342.79200","35.83360","0.05944"
"57207","343.20600","35.86810","0.05991"
"57276","343.62000","35.90260","0.05992"
"57345","344.03400","35.93716","0.06034"
"57414","344.44800","35.97160","0.06065"
"57483","344.86200","36.00603","0.06035"
"57552","345.27600","36.04059","0.06053"
"57621","345.69000","36.07509","0.06075"
"57690","346.10400","36.10965","0.06102"
"57759","346.51800","36.14409","0.06023"
"57828","346.93200","36.17859","0.06060"
"57897","347.34600","36.21315","0.06118"
"57966","347.76000","36.24765","0.06087"
"58035","348.17400","36.28208","0.06127"
"58104","348.58800","36.31658","0.06158"
"58173","349.00200","36.35114","0.06178"
"58242","349.41600","36.38558","0.06155"
"58311","349.83000","36.42014","0.06186"
"58380","350.24400","36.45458","0.06194"
"58449","350.65800","36.48913","0.06213"
"58518","351.07200","36.52363","0.06199"
"58587","351.48600","36.55813","0.06234"
"58656","351.90000","36.59251","0.06200"
"58725","352.31400","36.62713","0.06236"
"58794","352.72800","36.66162","0.06210"
"58863","353.14200","36.69613","0.06191"
"58932","353.55600","36.73063","0.06250"
"59001","353.97000","36.76506","0.06232"
"59070","354.38400","36.79968","0.06216"
"59139","354.79800","36.83412","0.06137"
"59208","355.21200","36.86862","0.06174"
"59277","355.62600","36.90306","0.06205"
"59346","356.04000","36.93755","0.06199"
"59415","356.45400","36.97211","0.06190"
"59484","356.86800","37.00667","0.06246"
"59553","357.28200","37.04105","0.06211"
"59622","357.69600","37.07561","0.06237"
"59691","358.11000","37.11017","0.06188"
"59760","358.52400","37.14466","0.06146"
"59829","358.93800","37.17910","0.06134"
"59898","359.35200","37.21360","0.06131"
"59967","359.76600","37.24810","0.06164"
"60036","360.18000","37.28260","0.06157"
"60105","360.59400","37.31710","0.06122"
"60174","361.00800","37.35160","0.06145"
"60243","361.42200","37.38616","0.06170"
"60312","361.83600","37.42065","0.06140"
"60381","362.25000","37.45515","0.06212"
"60450","362.66400","37.48959","0.06182"
"60519","363.07800","37.52409","0.06223"
"60588","363.49200","37.55865","0.06201"
"60657","363.90600","37.59315","0.06233"
"60726","364.32000","37.62759","0.06277"
"60795","364.73400","37.66209","0.06280"
"60864","365.14800","37.69664","0.06301"
"60933","365.56200","37.73114","0.06328"
"61002","365.97600","37.76564","0.06345"
"61071","366.39000","37.80008","0.06324"
"61140","366.80400","37.83458","0.06329"
"61209","367.21800","37.86914","0.06279"
"61278","367.63200","37.90369","0.06264"
"61347","368.04600","37.93807","0.06255"
"61416","368.46000","37.97263","0.06349"
"61485","368.87400","38.00719","0.06280"
"61554","369.28800","38.04169","0.06341"
"61623","369.70200","38.07607","0.06326"
"61692","370.11600","38.11063","0.06324"
"61761","370.53000","38.14513","0.06383"
"61830","370.94400","38.17963","0.06410"
"61899","371.35800","38.21412","0.06367"
"61968","371.77200","38.24862","0.06402"
"62037","372.18600","38.28312","0.06239"
"62106","372.60000","38.31768","0.06263"
"62175","373.01400","38.35218","0.06353"
"62244","373.42800","38.38655","0.06332"
"62313","373.84200","38.42105","0.06382"
"62382","374.25600","38.45561","0.06368"
"62451","374.67000","38.49017","0.06367"
"62520","375.08400","38.52455","0.06381"
"62589","375.49800","38.55911","0.06406"
"62658","375.91200","38.59361","0.06418"
"62727","376.32600","38.62817","0.06431"
"62796","376.74000","38.66260","0.06376"
"62865","377.15400","38.69704","0.06420"
"62934","377.56800","38.73160","0.06469"
"63003","377.98200","38.76610","0.06440"
"63072","378.39600","38.80060","0.06494"
"63141","378.81000","38.83504","0.06488"
"63210","379.22400","38.86959","0.06476"
"63279","379.63800","38.90409","0.06508"
"63348","380.05200","38.93865","0.06472"
"63417","380.46600","38.97309","0.06453"
"63486","380.88000","39.00759","0.06453"
"63555","381.29400","39.04215","0.06487"
"63624","381.70800","39.07658","0.06491"
"63693","382.12200","39.11108","0.06506"
"63762","382.53600","39.14558","0.06524"
"63831","382.95000","39.18014","0.06530"
"63900","383.36400","39.21464","0.05394"
"63969","383.77800","39.24914","0.05305"
"64038","384.19200","39.28358","0.05565"
"64107","384.60600","39.31808","0.05650"
"64176","385.02000","39.35263","0.05446"
"64245","385.43400","39.38707","0.05570"
"64314","385.84800","39.42163","0.05632"
"64383","386.26200","39.45607","0.05721"
"64452","386.67600","39.49069","0.05735"
"64521","387.09000","39.52512","0.05750"
"64590","387.50400","39.55962","0.05797"
"64659","387.91800","39.59407","0.05812"
"64728","388.33200","39.62856","0.05839"
"64797","388.74600","39.66312","0.05844"
"64866","389.16000","39.69762","0.05877"
"64935","389.57400","39.73206","0.05772"
"65004","389.98800","39.76662","0.05430"
"65073","390.40200","39.80112","0.05423"
"65142","390.81600","39.83567","0.05359"
"65211","391.23000","39.87005","0.05182"
"65280","391.64400","39.90455","0.05159"
"65349","392.05800","39.93911","0.05137"
"65418","392.47200","39.97367","0.05263"
"65487","392.88600","40.00811","0.05259"
"65556","393.30000","40.04255","0.05055"
"65625","393.71400","40.07716","0.04937"
"65694","394.12800","40.11166","0.04882"
"65763","394.54200","40.14622","0.05000"
"65832","394.95600","40.18054","0.04992"
"65901","395.37000","40.21510","0.04975"
"65970","395.78400","40.24960","0.05007"
"66039","396.19800","40.28409","0.05073"
"66108","396.61200","40.31859","0.05034"
"66177","397.02600","40.35309","0.05058"
"66246","397.44000","40.38765","0.05048"
"66315","397.85400","40.42215","0.05130"
"66384","398.26800","40.45665","0.05116"
"66453","398.68200","40.49102","0.05203"
"66522","399.09600","40.52559","0.05145"
"66591","399.51000","40.56009","0.05210"
"66660","399.92400","40.59464","0.05234"
"66729","400.33800","40.62908","0.05245"
"66798","400.75200","40.66364","0.05276"
"66867","401.16600","40.69813","0.05235"
"66936","401.58000","40.73264","0.05266"
"67005","401.99400","40.76713","0.05308"
"67074","402.40800","40.80157","0.05412"
"67143","402.82200","40.83613","0.05319"
"67212","403.23600","40.87057","0.05370"
"67281","403.65000","40.90512","0.05396"
"67350","404.06400","40.93957","0.05400"
"67419","404.47800","40.97412","0.05463"
"67488","404.89200","41.00869","0.05455"
"67557","405.30600","41.04319","0.05455"
"67626","405.72000","41.07756","0.05450"
"67695","406.13400","41.11206","0.05437"
"67764","406.54800","41.14662","0.05477"
"67833","406.96200","41.18111","0.05495"
"67902","407.37600","41.21555","0.05489"
"67971","407.79000","41.25005","0.05482"
"68040","408.20400","41.28461","0.05517"
"68109","408.61800","41.31917","0.05478"
"68178","409.03200","41.35361","0.05534"
"68247","409.44600","41.38805","0.05572"
"68316","409.86000","41.42255","0.05569"
"68385","410.27400","41.45710","0.05617"
"68454","410.68800","41.49166","0.05575"
"68523","411.10200","41.52604","0.05622"
"68592","411.51600","41.56060","0.05636"
"68661","411.93000","41.59516","0.05641"
"68730","412.34400","41.62966","0.05650"
"68799","412.75800","41.66410","0.05651"
"68868","413.17200","41.69859","0.05716"
"68937","413.58600","41.73309","0.05652"
"69006","414.00000","41.76759","0.05671"
"69075","414.41400","41.80209","0.05777"
"69144","414.82800","41.83659","0.05728"
"69213","415.24200","41.87109","0.05703"
"69282","415.65600","41.90559","0.05727"
"69351","416.07000","41.94014","0.05755"
"69420","416.48400","41.97458","0.05749"
"69489","416.89800","42.00908","0.05779"
"69558","417.31200","42.04364","0.05747"
"69627","417.72600","42.07814","0.05750"
"69696","418.14000","42.11264","0.05744"
"69765","418.55400","42.14708","0.05855"
"69834","418.96800","42.18163","0.05782"
"69903","419.38200","42.21613","0.05842"
"69972","419.79600","42.25057","0.05868"
"70041","420.21000","42.28507","0.05844"
"70110","420.62400","42.31956","0.05860"
"70179","421.03800","42.35413","0.05874"
"70248","421.45200","42.38863","0.05944"
"70317","421.86600","42.42307","0.05886"
"70386","422.28000","42.45762","0.05907"
"70455","422.69400","42.49212","0.05908"
"70524","423.10800","42.52668","0.05980"
"70593","423.52200","42.56112","0.05976"
"70662","423.93600","42.59556","0.05994"
"70731","424.35000","42.63012","0.05968"
"70800","424.76400","42.66462","0.05986"
"70869","425.17800","42.69911","0.06035"
"70938","425.59200","42.73361","0.06021"
"71007","426.00600","42.76811","0.06073"
"71076","426.42000","42.80267","0.06065"
"71145","426.83400","42.83711","0.06049"
"71214","427.24800","42.87154","0.06069"
"71283","427.66200","42.90611","0.06082"
"71352","428.07600","42.94066","0.06080"
"71421","428.49000","42.97510","0.06105"
"71490","428.90400","43.00960","0.06084"
"71559","429.31800","43.04410","0.06115"
"71628","429.73200","43.07866","0.06124"
"71697","430.14600","43.11316","0.06057"
"71766","430.56000","43.14766","0.06167"
"71835","430.97400","43.18209","0.06103"
"71904","431.38800","43.21659","0.06096"
"71973","431.80200","43.25109","0.05970"
"72042","432.21600","43.28564","0.05939"
"72111","432.63000","43.32009","0.06006"
"72180","433.04400","43.35459","0.05949"
"72249","433.45800","43.38914","0.06023"
"72318","433.87200","43.42370","0.05988"
"72387","434.28600","43.45814","0.05995"
"72456","434.70000","43.49258","0.05937"
"72525","435.11400","43.52714","0.06094"
"72594","435.52800","43.56164","0.06026"
"72663","435.94200","43.59614","0.06002"
"72732","436.35600","43.63058","0.06062"
"72801","436.77000","43.66513","0.06027"
"72870","437.18400","43.69969","0.06042"
"72939","437.59800","43.73413","0.06006"
"73008","438.01200","43.76857","0.06048"
"73077","438.42600","43.80313","0.06064"
"73146","438.84000","43.83762","0.06063"
"73215","439.25400","43.87212","0.06066"
"73284","439.66800","43.90662","0.06062"
"73353","440.08200","43.94106","0.06132"
"73422","440.49600","43.97562","0.06066"
"73491","440.91000","44.01018","0.06108"
"73560","441.32400","44.04467","0.06165"
"73629","441.73800","44.07906","0.06059"
"73698","442.15200","44.11355","0.06080"
"73767","442.56600","44.14811","0.06095"
"73836","442.98000","44.18267","0.06099"
"73905","443.39400","44.21705","0.06181"
"73974","443.80800","44.25155","0.06118"
"74043","444.22200","44.28611","0.06194"
"74112","444.63600","44.32066","0.06206"
"74181","445.05000","44.35516","0.06194"
"74250","445.46400","44.38961","0.06161"
"74319","445.87800","44.42410","0.06149"
"74388","446.29200","44.45860","0.06196"
"74457","446.70600","44.49310","0.06205"
"74526","447.12000","44.52754","0.06201"
"74595","447.53400","44.56210","0.06226"
"74664","447.94800","44.59659","0.06194"
"74733","448.36200","44.63115","0.06237"
"74802","448.77600","44.66559","0.06256"
"74871","449.19000","44.70009","0.06186"
"74940","449.60400","44.73465","0.06252"
"75009","450.01800","44.76915","0.06231"
"75078","450.43200","44.80359","0.06182"
"75147","450.84600","44.83803","0.06191"
"75216","451.26000","44.87265","0.06234"
"75285","451.67400","44.90714","0.06196"
"75354","452.08800","44.94164","0.06259"
"75423","452.50200","44.97608","0.06252"
"75492","452.91600","45.01058","0.06283"
"75561","453.33000","45.04514","0.06291"
"75630","453.74400","45.07963","0.06330"
"75699","454.15800","45.11407","0.06322"
"75768","454.57200","45.14863","0.06323"
"75837","454.98600","45.18313","0.06355"
"75906","455.40000","45.21769","0.06323"
"75975","455.81400","45.25213","0.06276"
"76044","456.22800","45.28662","0.06346"
"76113","456.64200","45.32112","0.06369"
"76182","457.05600","45.35563","0.06350"
"76251","457.47000","45.39012","0.06378"
"76320","457.88400","45.42462","0.06412"
"76389","458.29800","45.45912","0.06404"
"76458","458.71200","45.49368","0.06424"
"76527","459.12600","45.52818","0.06425"
"76596","459.54000","45.56255","0.06422"
"76665","459.95400","45.59705","0.06471"
"76734","460.36800","45.63161","0.06453"
"76803","460.78200","45.66617","0.06486"
"76872","461.19600","45.70061","0.06477"
"76941","461.61000","45.73511","0.06495"
"77010","462.02400","45.76966","0.06496"
"77079","462.43800","45.80416","0.06502"
"77148","462.85200","45.83866","0.06487"
"77217","463.26600","45.87304","0.06502"
"77286","463.68000","45.90760","0.06555"
"77355","464.09400","45.94210","0.06566"
"77424","464.50800","45.97666","0.06550"
"77493","464.92200","46.01110","0.06524"
"77562","465.33600","46.04559","0.06532"
"77631","465.75000","46.08015","0.06526"
"77700","466.16400","46.11465","0.06523"
"77769","466.57800","46.14909","0.06527"
"77838","466.99200","46.18353","0.06552"
"77907","467.40600","46.21815","0.06572"
"77976","467.82000","46.25259","0.06530"
"78045","468.23400","46.28709","0.06548"
"78114","468.64800","46.32158","0.06518"
"78183","469.06200","46.35608","0.06542"
"78252","469.47600","46.39064","0.06567"
"78321","469.89000","46.42513","0.06570"
"78390","470.30400","46.45964","0.06561"
"78459","470.71800","46.49408","0.06498"
"78528","471.13200","46.52863","0.06577"
"78597","471.54600","46.56307","0.06590"
"78666","471.96000","46.59757","0.06606"
"78735","472.37400","46.63207","0.06649"
"78804","472.78800","46.66663","0.06627"
"78873","473.20200","46.70113","0.06628"
"78942","473.61600","46.73563","0.06553"
"79011","474.03000","46.77007","0.06618"
"79080","474.44400","46.80456","0.06298"
"79149","474.85800","46.83912","0.06396"
"79218","475.27200","46.87362","0.06357"
"79287","475.68600","46.90805","0.06359"
"79356","476.10000","46.94255","0.06389"
"79425","476.51400","46.97712","0.06300"
"79494","476.92800","47.01167","0.06438"
"79563","477.34200","47.04617","0.06416"
"79632","477.75600","47.08055","0.06447"
"79701","478.17000","47.11510","0.06494"
"79770","478.58400","47.14960","0.06422"
"79839","478.99800","47.18410","0.06537"
"79908","479.41200","47.21854","0.06497"
"79977","479.82600","47.25311","0.06520"
"80046","480.24000","47.28766","0.06533"
"80115","480.65400","47.32216","0.06484"
"80184","481.06800","47.35660","0.06435"
"80253","481.48200","47.39109","0.06421"
"80322","481.89600","47.42559","0.06367"
"80391","482.31000","47.46009","0.06414"
"80460","482.72400","47.49459","0.06361"
"80529","483.13800","47.52903","0.06405"
"80598","483.55200","47.56359","0.06219"
"80667","483.96600","47.59809","0.06220"
"80736","484.38000","47.63264","0.06295"
"80805","484.79400","47.66708","0.06350"
"80874","485.20800","47.70158","0.06334"
"80943","485.62200","47.73615","0.06373"
"81012","486.03600","47.77064","0.06278"
"81081","486.45000","47.80502","0.06353"
"81150","486.86400","47.83964","0.06318"
"81219","487.27800","47.87413","0.06286"
"81288","487.69200","47.90863","0.06191"
"81357","488.10600","47.94313","0.06002"
"81426","488.52000","47.97757","0.05994"
"81495","488.93400","48.01213","0.06079"
"81564","489.34800","48.04663","0.06071"
"81633","489.76200","48.08113","0.06125"
"81702","490.17600","48.11557","0.06106"
"81771","490.59000","48.15007","0.06010"
"81840","491.00400","48.18462","0.06041"
"81909","491.41800","48.21918","0.06057"
"81978","491.83200","48.25362","0.06126"
"82047","492.24600","48.28806","0.06072"
"82116","492.66000","48.32262","0.06024"
"82185","493.07400","48.35712","0.05916"
"82254","493.48800","48.39161","0.06000"
"82323","493.90200","48.42606","0.06026"
"82392","494.31600","48.46061","0.06057"
"82461","494.73000","48.49511","0.06073"
"82530","495.14400","48.52967","0.06016"
"82599","495.55800","48.56404","0.06087"
"82668","495.97200","48.59861","0.06021"
"82737","496.38600","48.63311","0.06043"
"82806","496.80000","48.66766","0.06087"
"82875","497.21400","48.70210","0.06122"
"82944","497.62800","48.73660","0.06155"
"83013","498.04200","48.77116","0.06124"
"83082","498.45600","48.80566","0.06160"
"83151","498.87000","48.84016","0.06212"
"83220","499.28400","48.87460","0.06179"
"83289","499.69800","48.90910","0.06249"
"83358","500.11200","48.94359","0.06201"
"83427","500.52600","48.97809","0.06205"
"83496","500.94000","49.01258","0.06253"
"83565","501.35400","49.04709","0.06289"
"83634","501.76800","49.08171","0.06296"
"83703","502.18200","49.11620","0.06253"
"83772","502.59600","49.15059","0.06317"
"83841","503.01000","49.18508","0.06304"
"83910","503.42400","49.21958","0.06275"
"83979","503.83800","49.25414","0.06288"
"84048","504.25200","49.28864","0.06329"
"84101","504.57000","49.31512","0.06317"