File: Trajectories_together/170226_3Specimen_RawData_7.csv
"","V1","V2","V3"
"1","End date","2/26/2017",""
"2","Specimen label","8CG_71",""
"3","Maximum Load","0.03895","N"
"4","Time","Extension","Load"
"5","(s)","(mm)","(N)"
"6","0.00000","0.00000","-0.00025"
"88","0.49200","0.04137","0.00105"
"170","0.98400","0.08233","0.00286"
"252","1.47600","0.12323","0.00259"
"334","1.96800","0.16418","0.00316"
"416","2.46000","0.20514","0.00336"
"498","2.95200","0.24621","0.00389"
"580","3.44400","0.28717","0.00349"
"662","3.93600","0.32824","0.00334"
"744","4.42800","0.36920","0.00417"
"826","4.92000","0.41022","0.00393"
"908","5.41200","0.45123","0.00407"
"990","5.90400","0.49219","0.00420"
"1072","6.39600","0.53332","0.00458"
"1154","6.88800","0.57422","0.00456"
"1236","7.38000","0.61523","0.00462"
"1318","7.87200","0.65625","0.00454"
"1400","8.36400","0.69715","0.00490"
"1482","8.85600","0.73816","0.00565"
"1564","9.34800","0.77918","0.00580"
"1646","9.84000","0.82019","0.00557"
"1728","10.33200","0.86121","0.00516"
"1810","10.82400","0.90228","0.00511"
"1892","11.31600","0.94324","0.00545"
"1974","11.80800","0.98420","0.00575"
"2056","12.30000","1.02527","0.00602"
"2138","12.79200","1.06623","0.00563"
"2220","13.28400","1.10718","0.00560"
"2302","13.77600","1.14820","0.00546"
"2384","14.26800","1.18921","0.00549"
"2466","14.76000","1.23017","0.00557"
"2548","15.25200","1.27119","0.00590"
"2630","15.74400","1.31226","0.00589"
"2712","16.23600","1.35322","0.00549"
"2794","16.72800","1.39423","0.00575"
"2876","17.22000","1.43525","0.00575"
"2958","17.71200","1.47626","0.00577"
"3040","18.20400","1.51728","0.00566"
"3122","18.69600","1.55817","0.00648"
"3204","19.18800","1.59925","0.00633"
"3286","19.68000","1.64015","0.00584"
"3368","20.17200","1.68122","0.00594"
"3450","20.66400","1.72224","0.00625"
"3532","21.15600","1.76319","0.00650"
"3614","21.64800","1.80421","0.00673"
"3696","22.14000","1.84522","0.00625"
"3778","22.63200","1.88624","0.00599"
"3860","23.12400","1.92720","0.00651"
"3942","23.61600","1.96827","0.00650"
"4024","24.10800","2.00923","0.00698"
"4106","24.60000","2.05024","0.00686"
"4188","25.09200","2.09120","0.00674"
"4270","25.58400","2.13215","0.00703"
"4352","26.07600","2.17317","0.00719"
"4434","26.56800","2.21419","0.00709"
"4516","27.06000","2.25526","0.00678"
"4598","27.55200","2.29622","0.00726"
"4680","28.04400","2.33729","0.00697"
"4762","28.53600","2.37825","0.00709"
"4844","29.02800","2.41920","0.00691"
"4926","29.52000","2.46022","0.00616"
"5008","30.01200","2.50124","0.00647"
"5090","30.50400","2.54219","0.00688"
"5172","30.99600","2.58315","0.00707"
"5254","31.48800","2.62422","0.00715"
"5336","31.98000","2.66518","0.00741"
"5418","32.47200","2.70619","0.00707"
"5500","32.96400","2.74721","0.00674"
"5582","33.45600","2.78823","0.00637"
"5664","33.94800","2.82924","0.00645"
"5746","34.44000","2.87026","0.00629"
"5828","34.93200","2.91127","0.00701"
"5910","35.42400","2.95229","0.00710"
"5992","35.91600","2.99324","0.00710"
"6074","36.40800","3.03420","0.00655"
"6156","36.90000","3.07516","0.00774"
"6238","37.39200","3.11623","0.00696"
"6320","37.88400","3.15719","0.00700"
"6402","38.37600","3.19826","0.00777"
"6484","38.86800","3.23922","0.00728"
"6566","39.36000","3.28023","0.00732"
"6648","39.85200","3.32125","0.00759"
"6730","40.34400","3.36220","0.00678"
"6812","40.83600","3.40328","0.00663"
"6894","41.32800","3.44424","0.00621"
"6976","41.82000","3.48525","0.00644"
"7058","42.31200","3.52621","0.00689"
"7140","42.80400","3.56716","0.00702"
"7222","43.29600","3.60818","0.00691"
"7304","43.78800","3.64919","0.00697"
"7386","44.28000","3.69027","0.00640"
"7468","44.77200","3.73123","0.00703"
"7550","45.26400","3.77224","0.00706"
"7632","45.75600","3.81326","0.00675"
"7714","46.24800","3.85421","0.00695"
"7796","46.74000","3.89529","0.00720"
"7878","47.23200","3.93624","0.00698"
"7960","47.72400","3.97726","0.00719"
"8042","48.21600","4.01816","0.00685"
"8124","48.70800","4.05923","0.00705"
"8206","49.20000","4.10019","0.00765"
"8288","49.69200","4.14120","0.00797"
"8370","50.18400","4.18228","0.00750"
"8452","50.67600","4.22323","0.00737"
"8534","51.16800","4.26425","0.00753"
"8616","51.66000","4.30521","0.00758"
"8698","52.15200","4.34628","0.00732"
"8780","52.64400","4.38724","0.00754"
"8862","53.13600","4.42825","0.00792"
"8944","53.62800","4.46921","0.00730"
"9026","54.12000","4.51016","0.00823"
"9108","54.61200","4.55118","0.00800"
"9190","55.10400","4.59219","0.00813"
"9272","55.59600","4.63321","0.00817"
"9354","56.08800","4.67423","0.00819"
"9436","56.58000","4.71524","0.00828"
"9518","57.07200","4.75626","0.00846"
"9600","57.56400","4.79721","0.00845"
"9682","58.05600","4.83829","0.00858"
"9764","58.54800","4.87924","0.00917"
"9846","59.04000","4.92026","0.00879"
"9928","59.53200","4.96116","0.00909"
"10010","60.02400","5.00217","0.00789"
"10092","60.51600","5.04313","0.00884"
"10174","61.00800","5.08420","0.00920"
"10256","61.50000","5.12522","0.00872"
"10338","61.99200","5.16617","0.00831"
"10420","62.48400","5.20725","0.00860"
"10502","62.97600","5.24827","0.00885"
"10584","63.46800","5.28922","0.00906"
"10666","63.96000","5.33024","0.00869"
"10748","64.45200","5.37119","0.00960"
"10830","64.94400","5.41221","0.00951"
"10912","65.43600","5.45316","0.00900"
"10994","65.92800","5.49418","0.01045"
"11076","66.42000","5.53520","0.00999"
"11158","66.91200","5.57615","0.00988"
"11240","67.40400","5.61717","0.01021"
"11322","67.89600","5.65818","0.01023"
"11404","68.38800","5.69926","0.01077"
"11486","68.88000","5.74027","0.01078"
"11568","69.37200","5.78129","0.01059"
"11650","69.86400","5.82225","0.01062"
"11732","70.35600","5.86320","0.01134"
"11814","70.84800","5.90422","0.01170"
"11896","71.34000","5.94517","0.01183"
"11978","71.83200","5.98619","0.01111"
"12060","72.32400","6.02720","0.01221"
"12142","72.81600","6.06822","0.01210"
"12224","73.30800","6.10923","0.01122"
"12306","73.80000","6.15025","0.01221"
"12388","74.29200","6.19121","0.01233"
"12470","74.78400","6.23216","0.01174"
"12552","75.27600","6.27324","0.01288"
"12634","75.76800","6.31425","0.01310"
"12716","76.26000","6.35527","0.01321"
"12798","76.75200","6.39616","0.01315"
"12880","77.24400","6.43718","0.01362"
"12962","77.73600","6.47820","0.01415"
"13044","78.22800","6.51921","0.01413"
"13126","78.72000","6.56023","0.01364"
"13208","79.21200","6.60124","0.01403"
"13290","79.70400","6.64232","0.01400"
"13372","80.19600","6.68327","0.01509"
"13454","80.68800","6.72423","0.01430"
"13536","81.18000","6.76525","0.01487"
"13618","81.67200","6.80626","0.01415"
"13700","82.16400","6.84722","0.01551"
"13782","82.65600","6.88817","0.01557"
"13864","83.14800","6.92919","0.01601"
"13946","83.64000","6.97014","0.01527"
"14028","84.13200","7.01116","0.01607"
"14110","84.62400","7.05224","0.01680"
"14192","85.11600","7.09319","0.01613"
"14274","85.60800","7.13421","0.01688"
"14356","86.10000","7.17522","0.01638"
"14438","86.59200","7.21630","0.01609"
"14520","87.08400","7.25725","0.01603"
"14602","87.57600","7.29821","0.01675"
"14684","88.06800","7.33923","0.01645"
"14766","88.56000","7.38012","0.01749"
"14848","89.05200","7.42120","0.01698"
"14930","89.54400","7.46221","0.01774"
"15012","90.03600","7.50323","0.01711"
"15094","90.52800","7.54424","0.01731"
"15176","91.02000","7.58520","0.01775"
"15258","91.51200","7.62627","0.01718"
"15340","92.00400","7.66723","0.01748"
"15422","92.49600","7.70831","0.01753"
"15504","92.98800","7.74920","0.01766"
"15586","93.48000","7.79022","0.01783"
"15668","93.97200","7.83123","0.01795"
"15750","94.46400","7.87213","0.01814"
"15832","94.95600","7.91314","0.01914"
"15914","95.44800","7.95416","0.01892"
"15996","95.94000","7.99524","0.01825"
"16078","96.43200","8.03619","0.01884"
"16160","96.92400","8.07727","0.01852"
"16242","97.41600","8.11822","0.01938"
"16324","97.90800","8.15924","0.01901"
"16406","98.40000","8.20019","0.01947"
"16488","98.89200","8.24121","0.01967"
"16570","99.38400","8.28223","0.01866"
"16652","99.87600","8.32318","0.01890"
"16734","100.36800","8.36420","0.01876"
"16816","100.86000","8.40521","0.01902"
"16898","101.35200","8.44617","0.02003"
"16980","101.84400","8.48718","0.01938"
"17062","102.33600","8.52826","0.01966"
"17144","102.82800","8.56927","0.02004"
"17226","103.32000","8.61023","0.02060"
"17308","103.81200","8.65125","0.02051"
"17390","104.30400","8.69226","0.02044"
"17472","104.79600","8.73322","0.02016"
"17554","105.28800","8.77423","0.02071"
"17636","105.78000","8.81513","0.02112"
"17718","106.27200","8.85614","0.02090"
"17800","106.76400","8.89722","0.02100"
"17882","107.25600","8.93824","0.02123"
"17964","107.74800","8.97925","0.02174"
"18046","108.24000","9.02021","0.02220"
"18128","108.73200","9.06128","0.02206"
"18210","109.22400","9.10218","0.02238"
"18292","109.71600","9.14325","0.02251"
"18374","110.20800","9.18421","0.02246"
"18456","110.70000","9.22523","0.02302"
"18538","111.19200","9.26618","0.02291"
"18620","111.68400","9.30714","0.02304"
"18702","112.17600","9.34815","0.02367"
"18784","112.66800","9.38917","0.02350"
"18866","113.16000","9.43024","0.02383"
"18948","113.65200","9.47120","0.02364"
"19030","114.14400","9.51222","0.02421"
"19112","114.63600","9.55323","0.02372"
"19194","115.12800","9.59425","0.02353"
"19276","115.62000","9.63526","0.02387"
"19358","116.11200","9.67628","0.02427"
"19440","116.60400","9.71717","0.02454"
"19522","117.09600","9.75819","0.02414"
"19604","117.58800","9.79920","0.02465"
"19686","118.08000","9.84016","0.02470"
"19768","118.57200","9.88118","0.02463"
"19850","119.06400","9.92219","0.02488"
"19932","119.55600","9.96321","0.02508"
"20014","120.04800","10.00428","0.02513"
"20096","120.54000","10.04524","0.02440"
"20178","121.03200","10.08626","0.02459"
"20260","121.52400","10.12733","0.02438"
"20342","122.01600","10.16823","0.02392"
"20424","122.50800","10.20918","0.02465"
"20506","123.00000","10.25014","0.02443"
"20588","123.49200","10.29121","0.02358"
"20670","123.98400","10.33217","0.02277"
"20752","124.47600","10.37324","0.02248"
"20834","124.96800","10.41420","0.02335"
"20916","125.46000","10.45522","0.02335"
"20998","125.95200","10.49623","0.02314"
"21080","126.44400","10.53719","0.02327"
"21162","126.93600","10.57820","0.02262"
"21244","127.42800","10.61922","0.02254"
"21326","127.92000","10.66029","0.02310"
"21408","128.41200","10.70119","0.02244"
"21490","128.90400","10.74215","0.02284"
"21572","129.39600","10.78316","0.02367"
"21654","129.88800","10.82418","0.02426"
"21736","130.38000","10.86525","0.02345"
"21818","130.87200","10.90621","0.02349"
"21900","131.36400","10.94728","0.02360"
"21982","131.85600","10.98824","0.02380"
"22064","132.34800","11.02925","0.02353"
"22146","132.84000","11.07021","0.02361"
"22228","133.33200","11.11123","0.02368"
"22310","133.82400","11.15224","0.02353"
"22392","134.31600","11.19320","0.02291"
"22474","134.80800","11.23421","0.02270"
"22556","135.30000","11.27517","0.02144"
"22638","135.79200","11.31618","0.02202"
"22720","136.28400","11.35720","0.02194"
"22802","136.77600","11.39822","0.02218"
"22884","137.26800","11.43923","0.02282"
"22966","137.76000","11.48019","0.02270"
"23048","138.25200","11.52120","0.02254"
"23130","138.74400","11.56228","0.02307"
"23212","139.23600","11.60324","0.02286"
"23294","139.72800","11.64419","0.02262"
"23376","140.22000","11.68515","0.02293"
"23458","140.71200","11.72622","0.02280"
"23540","141.20400","11.76718","0.02263"
"23622","141.69600","11.80819","0.02324"
"23704","142.18800","11.84921","0.02300"
"23786","142.68000","11.89022","0.02176"
"23868","143.17200","11.93124","0.02184"
"23950","143.66400","11.97220","0.02163"
"24032","144.15600","12.01327","0.02259"
"24114","144.64800","12.05423","0.02237"
"24196","145.14000","12.09530","0.02286"
"24278","145.63200","12.13620","0.02252"
"24360","146.12400","12.17715","0.02256"
"24442","146.61600","12.21817","0.02298"
"24524","147.10800","12.25919","0.02337"
"24606","147.60000","12.30020","0.02267"
"24688","148.09200","12.34122","0.02268"
"24770","148.58400","12.38229","0.02257"
"24852","149.07600","12.42325","0.02259"
"24934","149.56800","12.46426","0.02251"
"25016","150.06000","12.50522","0.02241"
"25098","150.55200","12.54618","0.02242"
"25180","151.04400","12.58725","0.02236"
"25262","151.53600","12.62821","0.02315"
"25344","152.02800","12.66922","0.02331"
"25426","152.52000","12.71018","0.02325"
"25508","153.01200","12.75119","0.02385"
"25590","153.50400","12.79215","0.02367"
"25672","153.99600","12.83322","0.02410"
"25754","154.48800","12.87424","0.02440"
"25836","154.98000","12.91520","0.02435"
"25918","155.47200","12.95627","0.02411"
"26000","155.96400","12.99729","0.02533"
"26082","156.45600","13.03818","0.02447"
"26164","156.94800","13.07920","0.02482"
"26246","157.44000","13.12016","0.02259"
"26328","157.93200","13.16123","0.02130"
"26410","158.42400","13.20219","0.01845"
"26492","158.91600","13.24326","0.01791"
"26574","159.40800","13.28428","0.01864"
"26656","159.90000","13.32523","0.01897"
"26738","160.39200","13.36625","0.01880"
"26820","160.88400","13.40720","0.01872"
"26902","161.37600","13.44822","0.01845"
"26984","161.86800","13.48924","0.01764"
"27066","162.36000","13.53025","0.01841"
"27148","162.85200","13.57121","0.01896"
"27230","163.34400","13.61216","0.01883"
"27312","163.83600","13.65318","0.01931"
"27394","164.32800","13.69413","0.01969"
"27476","164.82000","13.73527","0.01968"
"27558","165.31200","13.77617","0.01941"
"27640","165.80400","13.81730","0.02051"
"27722","166.29600","13.85826","0.01993"
"27804","166.78800","13.89927","0.02044"
"27886","167.28000","13.94023","0.02053"
"27968","167.77200","13.98118","0.02057"
"28050","168.26400","14.02226","0.02120"
"28132","168.75600","14.06316","0.02096"
"28214","169.24800","14.10423","0.02135"
"28296","169.74000","14.14513","0.02129"
"28378","170.23200","14.18620","0.02190"
"28460","170.72400","14.22722","0.02195"
"28542","171.21600","14.26823","0.02213"
"28624","171.70800","14.30925","0.02162"
"28706","172.20000","14.35021","0.02196"
"28788","172.69200","14.39128","0.02248"
"28870","173.18400","14.43224","0.02287"
"28952","173.67600","14.47319","0.02241"
"29034","174.16800","14.51421","0.02262"
"29116","174.66000","14.55516","0.02265"
"29198","175.15200","14.59618","0.02312"
"29280","175.64400","14.63714","0.02301"
"29362","176.13600","14.67821","0.02355"
"29444","176.62800","14.71923","0.02320"
"29526","177.12000","14.76024","0.02417"
"29608","177.61200","14.80126","0.02395"
"29690","178.10400","14.84221","0.02473"
"29772","178.59600","14.88323","0.02423"
"29854","179.08800","14.92418","0.02434"
"29936","179.58000","14.96526","0.02504"
"30018","180.07200","15.00622","0.02491"
"30100","180.56400","15.04711","0.02514"
"30182","181.05600","15.08813","0.02584"
"30264","181.54800","15.12920","0.02557"
"30346","182.04000","15.17022","0.02523"
"30428","182.53200","15.21124","0.02564"
"30510","183.02400","15.25225","0.02568"
"30592","183.51600","15.29327","0.02611"
"30674","184.00800","15.33422","0.02631"
"30756","184.50000","15.37524","0.02660"
"30838","184.99200","15.41619","0.02667"
"30920","185.48400","15.45727","0.02692"
"31002","185.97600","15.49822","0.02689"
"31084","186.46800","15.53918","0.02748"
"31166","186.96000","15.58014","0.02728"
"31248","187.45200","15.62121","0.02745"
"31330","187.94400","15.66223","0.02769"
"31412","188.43600","15.70324","0.02766"
"31494","188.92800","15.74426","0.02761"
"31576","189.42000","15.78521","0.02776"
"31658","189.91200","15.82623","0.02795"
"31740","190.40400","15.86724","0.02785"
"31822","190.89600","15.90820","0.02801"
"31904","191.38800","15.94922","0.02827"
"31986","191.88000","15.99017","0.02806"
"32068","192.37200","16.03119","0.02787"
"32150","192.86400","16.07220","0.02868"
"32232","193.35600","16.11322","0.02862"
"32314","193.84800","16.15424","0.02862"
"32396","194.34000","16.19519","0.02889"
"32478","194.83200","16.23621","0.02936"
"32560","195.32400","16.27722","0.02935"
"32642","195.81600","16.31824","0.02901"
"32724","196.30800","16.35919","0.02963"
"32806","196.80000","16.40027","0.02949"
"32888","197.29200","16.44123","0.02960"
"32970","197.78400","16.48212","0.02961"
"33052","198.27600","16.52320","0.02974"
"33134","198.76800","16.56415","0.02927"
"33216","199.26000","16.60517","0.02961"
"33298","199.75200","16.64618","0.03004"
"33380","200.24400","16.68732","0.02986"
"33462","200.73600","16.72821","0.02969"
"33544","201.22800","16.76923","0.02942"
"33626","201.72000","16.81019","0.02966"
"33708","202.21200","16.85126","0.03003"
"33790","202.70400","16.89222","0.02975"
"33872","203.19600","16.93323","0.02950"
"33954","203.68800","16.97419","0.02962"
"34036","204.18000","17.01520","0.02996"
"34118","204.67200","17.05616","0.03006"
"34200","205.16400","17.09723","0.03017"
"34282","205.65600","17.13819","0.03012"
"34364","206.14800","17.17927","0.03035"
"34446","206.64000","17.22028","0.03007"
"34528","207.13200","17.26124","0.03007"
"34610","207.62400","17.30231","0.03068"
"34692","208.11600","17.34321","0.03077"
"34774","208.60800","17.38417","0.03061"
"34856","209.10000","17.42518","0.03009"
"34938","209.59200","17.46626","0.03049"
"35020","210.08400","17.50715","0.03009"
"35102","210.57600","17.54817","0.03021"
"35184","211.06800","17.58924","0.03044"
"35266","211.56000","17.63026","0.03080"
"35348","212.05200","17.67122","0.03109"
"35430","212.54400","17.71217","0.03130"
"35512","213.03600","17.75324","0.03046"
"35594","213.52800","17.79420","0.03104"
"35676","214.02000","17.83528","0.03058"
"35758","214.51200","17.87623","0.03074"
"35840","215.00400","17.91719","0.03123"
"35922","215.49600","17.95815","0.03126"
"36004","215.98800","17.99922","0.03123"
"36086","216.48000","18.04024","0.03104"
"36168","216.97200","18.08119","0.03023"
"36250","217.46400","18.12227","0.03073"
"36332","217.95600","18.16322","0.03101"
"36414","218.44800","18.20424","0.03132"
"36496","218.94000","18.24525","0.03123"
"36578","219.43200","18.28621","0.03091"
"36660","219.92400","18.32722","0.03107"
"36742","220.41600","18.36818","0.03078"
"36824","220.90800","18.40920","0.03106"
"36906","221.40000","18.45015","0.03121"
"36988","221.89200","18.49123","0.03103"
"37070","222.38400","18.53224","0.03104"
"37152","222.87600","18.57320","0.03169"
"37234","223.36800","18.61422","0.03174"
"37316","223.86000","18.65529","0.03194"
"37398","224.35200","18.69625","0.03234"
"37480","224.84400","18.73726","0.03151"
"37562","225.33600","18.77822","0.03142"
"37644","225.82800","18.81917","0.03139"
"37726","226.32000","18.86019","0.03170"
"37808","226.81200","18.90121","0.03158"
"37890","227.30400","18.94222","0.03184"
"37972","227.79600","18.98318","0.03164"
"38054","228.28800","19.02419","0.03195"
"38136","228.78000","19.06527","0.03201"
"38218","229.27200","19.10622","0.03133"
"38300","229.76400","19.14724","0.03136"
"38382","230.25600","19.18826","0.03158"
"38464","230.74800","19.22921","0.03095"
"38546","231.24000","19.27023","0.03125"
"38628","231.73200","19.31124","0.03169"
"38710","232.22400","19.35214","0.03174"
"38792","232.71600","19.39315","0.03136"
"38874","233.20800","19.43417","0.03167"
"38956","233.70000","19.47518","0.03148"
"39038","234.19200","19.51620","0.03179"
"39120","234.68400","19.55728","0.03179"
"39202","235.17600","19.59829","0.03168"
"39284","235.66800","19.63925","0.03190"
"39366","236.16000","19.68020","0.03213"
"39448","236.65200","19.72122","0.03178"
"39530","237.14400","19.76224","0.03269"
"39612","237.63600","19.80313","0.03047"
"39694","238.12800","19.84420","0.03077"
"39776","238.62000","19.88516","0.03110"
"39858","239.11200","19.92618","0.03092"
"39940","239.60400","19.96719","0.03025"
"40022","240.09600","20.00821","0.02999"
"40104","240.58800","20.04922","0.03083"
"40186","241.08000","20.09018","0.03038"
"40268","241.57200","20.13132","0.03070"
"40350","242.06400","20.17227","0.03053"
"40432","242.55600","20.21323","0.03098"
"40514","243.04800","20.25418","0.02996"
"40596","243.54000","20.29520","0.02955"
"40678","244.03200","20.33621","0.02959"
"40760","244.52400","20.37717","0.02984"
"40842","245.01600","20.41824","0.03003"
"40924","245.50800","20.45920","0.02944"
"41006","246.00000","20.50022","0.02973"
"41088","246.49200","20.54123","0.02992"
"41170","246.98400","20.58219","0.03011"
"41252","247.47600","20.62326","0.03039"
"41334","247.96800","20.66422","0.03036"
"41416","248.46000","20.70524","0.02952"
"41498","248.95200","20.74619","0.02941"
"41580","249.44400","20.78720","0.02963"
"41662","249.93600","20.82816","0.02977"
"41744","250.42800","20.86918","0.03049"
"41826","250.92000","20.91019","0.03022"
"41908","251.41200","20.95121","0.02997"
"41990","251.90400","20.99228","0.03062"
"42072","252.39600","21.03324","0.03058"
"42154","252.88800","21.07425","0.03020"
"42236","253.38000","21.11521","0.03047"
"42318","253.87200","21.15623","0.03082"
"42400","254.36400","21.19724","0.03110"
"42482","254.85600","21.23820","0.03084"
"42564","255.34800","21.27921","0.03063"
"42646","255.84000","21.32017","0.03068"
"42728","256.33200","21.36119","0.03070"
"42810","256.82400","21.40220","0.03098"
"42892","257.31600","21.44322","0.03118"
"42974","257.80800","21.48429","0.03225"
"43056","258.30000","21.52525","0.03191"
"43138","258.79200","21.56627","0.03208"
"43220","259.28400","21.60728","0.03220"
"43302","259.77600","21.64818","0.03204"
"43384","260.26800","21.68919","0.03251"
"43466","260.76000","21.73015","0.03275"
"43548","261.25200","21.77122","0.03333"
"43630","261.74400","21.81218","0.03293"
"43712","262.23600","21.85325","0.03238"
"43794","262.72800","21.89421","0.03274"
"43876","263.22000","21.93528","0.03292"
"43958","263.71200","21.97624","0.03281"
"44040","264.20400","22.01720","0.03268"
"44122","264.69600","22.05827","0.03226"
"44204","265.18800","22.09923","0.03254"
"44286","265.68000","22.14024","0.03350"
"44368","266.17200","22.18120","0.01888"
"44450","266.66400","22.22216","0.01845"
"44532","267.15600","22.26311","0.01802"
"44614","267.64800","22.30419","0.01861"
"44696","268.14000","22.34520","0.01914"
"44778","268.63200","22.38616","0.01848"
"44860","269.12400","22.42729","0.01916"
"44942","269.61600","22.46825","0.01921"
"45024","270.10800","22.50927","0.02033"
"45106","270.60000","22.55022","0.02120"
"45188","271.09200","22.59124","0.02111"
"45270","271.58400","22.63219","0.02161"
"45352","272.07600","22.67315","0.02199"
"45434","272.56800","22.71422","0.02179"
"45516","273.06000","22.75518","0.02173"
"45598","273.55200","22.79626","0.02279"
"45680","274.04400","22.83721","0.02314"
"45762","274.53600","22.87823","0.02344"
"45844","275.02800","22.91924","0.02343"
"45926","275.52000","22.96026","0.02406"
"46008","276.01200","23.00127","0.02418"
"46090","276.50400","23.04223","0.02395"
"46172","276.99600","23.08324","0.02421"
"46254","277.48800","23.12420","0.02523"
"46336","277.98000","23.16516","0.02547"
"46418","278.47200","23.20617","0.02421"
"46500","278.96400","23.24719","0.02503"
"46582","279.45600","23.28820","0.02460"
"46664","279.94800","23.32922","0.02461"
"46746","280.44000","23.37023","0.02418"
"46828","280.93200","23.41125","0.02372"
"46910","281.42400","23.45220","0.02484"
"46992","281.91600","23.49328","0.02469"
"47074","282.40800","23.53424","0.02476"
"47156","282.90000","23.57525","0.02468"
"47238","283.39200","23.61627","0.02492"
"47320","283.88400","23.65716","0.02529"
"47402","284.37600","23.69818","0.02558"
"47484","284.86800","23.73914","0.02531"
"47566","285.36000","23.78027","0.02650"
"47648","285.85200","23.82117","0.02642"
"47730","286.34400","23.86230","0.02729"
"47812","286.83600","23.90320","0.02715"
"47894","287.32800","23.94421","0.02731"
"47976","287.82000","23.98523","0.02815"
"48058","288.31200","24.02624","0.02731"
"48140","288.80400","24.06720","0.02641"
"48222","289.29600","24.10816","0.02721"
"48304","289.78800","24.14923","0.02676"
"48386","290.28000","24.19019","0.02771"
"48468","290.77200","24.23114","0.02764"
"48550","291.26400","24.27222","0.02817"
"48632","291.75600","24.31324","0.02637"
"48714","292.24800","24.35419","0.02686"
"48796","292.74000","24.39527","0.02771"
"48878","293.23200","24.43628","0.02791"
"48960","293.72400","24.47724","0.02781"
"49042","294.21600","24.51825","0.02854"
"49124","294.70800","24.55921","0.02854"
"49206","295.20000","24.60016","0.02880"
"49288","295.69200","24.64118","0.02906"
"49370","296.18400","24.68219","0.02989"
"49452","296.67600","24.72321","0.02983"
"49534","297.16800","24.76423","0.02998"
"49616","297.66000","24.80524","0.03062"
"49698","298.15200","24.84626","0.03056"
"49780","298.64400","24.88721","0.03021"
"49862","299.13600","24.92823","0.03106"
"49944","299.62800","24.96924","0.03040"
"50026","300.12000","25.01026","0.03093"
"50108","300.61200","25.05122","0.03078"
"50190","301.10400","25.09217","0.03161"
"50272","301.59600","25.13313","0.03159"
"50354","302.08800","25.17420","0.03172"
"50436","302.58000","25.21528","0.03247"
"50518","303.07200","25.25617","0.03190"
"50600","303.56400","25.29725","0.03202"
"50682","304.05600","25.33827","0.03214"
"50764","304.54800","25.37922","0.03245"
"50846","305.04000","25.42024","0.03212"
"50928","305.53200","25.46119","0.03273"
"51010","306.02400","25.50221","0.03265"
"51092","306.51600","25.54323","0.03272"
"51174","307.00800","25.58424","0.03291"
"51256","307.50000","25.62519","0.03312"
"51338","307.99200","25.66621","0.03309"
"51420","308.48400","25.70723","0.03299"
"51502","308.97600","25.74824","0.03305"
"51584","309.46800","25.78920","0.03273"
"51666","309.96000","25.83021","0.03314"
"51748","310.45200","25.87123","0.03327"
"51830","310.94400","25.91224","0.03358"
"51912","311.43600","25.95320","0.03347"
"51994","311.92800","25.99422","0.03383"
"52076","312.42000","26.03518","0.03362"
"52158","312.91200","26.07619","0.03383"
"52240","313.40400","26.11721","0.03325"
"52322","313.89600","26.15822","0.03452"
"52404","314.38800","26.19917","0.03473"
"52486","314.88000","26.24025","0.03434"
"52568","315.37200","26.28121","0.03516"
"52650","315.86400","26.32222","0.03463"
"52732","316.35600","26.36324","0.03547"
"52814","316.84800","26.40425","0.03522"
"52896","317.34000","26.44527","0.03541"
"52978","317.83200","26.48616","0.03559"
"53060","318.32400","26.52718","0.03580"
"53142","318.81600","26.56814","0.03651"
"53224","319.30800","26.60921","0.03655"
"53306","319.80000","26.65023","0.03662"
"53388","320.29200","26.69118","0.03631"
"53470","320.78400","26.73226","0.03597"
"53552","321.27600","26.77321","0.03592"
"53634","321.76800","26.81423","0.03586"
"53716","322.26000","26.85525","0.03634"
"53798","322.75200","26.89620","0.03682"
"53880","323.24400","26.93722","0.03689"
"53962","323.73600","26.97817","0.03693"
"54044","324.22800","27.01919","0.03723"
"54126","324.72000","27.06020","0.03720"
"54208","325.21200","27.10122","0.03675"
"54290","325.70400","27.14218","0.03708"
"54372","326.19600","27.18319","0.03724"
"54454","326.68800","27.22421","0.03625"
"54536","327.18000","27.26522","0.03715"
"54618","327.67200","27.30630","0.03721"
"54700","328.16400","27.34731","0.03580"
"54782","328.65600","27.38821","0.03551"
"54864","329.14800","27.42923","0.03616"
"54946","329.64000","27.47018","0.03669"
"55028","330.13200","27.51120","0.03665"
"55110","330.62400","27.55215","0.03661"
"55192","331.11600","27.59317","0.03616"
"55274","331.60800","27.63424","0.03646"
"55356","332.10000","27.67520","0.03729"
"55438","332.59200","27.71622","0.03749"
"55520","333.08400","27.75717","0.03759"
"55602","333.57600","27.79825","0.03774"
"55684","334.06800","27.83920","0.03816"
"55766","334.56000","27.88028","0.03816"
"55848","335.05200","27.92124","0.03865"
"55930","335.54400","27.96219","0.03838"
"56012","336.03600","28.00320","0.03814"
"56094","336.52800","28.04416","0.03786"
"56176","337.02000","28.08524","0.03779"
"56258","337.51200","28.12619","0.03773"
"56340","338.00400","28.16727","0.03776"
"56422","338.49600","28.20829","0.03769"
"56504","338.98800","28.24930","0.03769"
"56586","339.48000","28.29020","0.03676"
"56668","339.97200","28.33121","0.03375"
"56750","340.46400","28.37223","0.03414"
"56832","340.95600","28.41318","0.03220"
"56914","341.44800","28.45420","0.03058"
"56996","341.94000","28.49516","0.02931"
"57078","342.43200","28.53623","0.02952"
"57160","342.92400","28.57719","0.02869"
"57242","343.41600","28.61820","0.02806"
"57324","343.90800","28.65922","0.02880"
"57406","344.40000","28.70023","0.02929"
"57488","344.89200","28.74125","0.02947"
"57570","345.38400","28.78226","0.02999"
"57652","345.87600","28.82322","0.03059"
"57734","346.36800","28.86424","0.03059"
"57816","346.86000","28.90519","0.03021"
"57898","347.35200","28.94615","0.03030"
"57980","347.84400","28.98722","0.02998"
"58062","348.33600","29.02824","0.03008"
"58144","348.82800","29.06919","0.03049"
"58226","349.32000","29.11027","0.03116"
"58308","349.81200","29.15123","0.03095"
"58390","350.30400","29.19224","0.02961"
"58472","350.79600","29.23326","0.02794"
"58554","351.28800","29.27421","0.02808"
"58636","351.78000","29.31529","0.02855"
"58718","352.27200","29.35624","0.02776"
"58800","352.76400","29.39714","0.02747"
"58882","353.25600","29.43815","0.02731"
"58964","353.74800","29.47917","0.02805"
"59046","354.24000","29.52024","0.02808"
"59128","354.73200","29.56120","0.02823"
"59210","355.22400","29.60228","0.02838"
"59292","355.71600","29.64323","0.02781"
"59374","356.20800","29.68425","0.02900"
"59456","356.70000","29.72520","0.02924"
"59538","357.19200","29.76622","0.02915"
"59620","357.68400","29.80724","0.03003"
"59702","358.17600","29.84819","0.02953"
"59784","358.66800","29.88921","0.02990"
"59866","359.16000","29.93016","0.03017"
"59948","359.65200","29.97124","0.02953"
"60030","360.14400","30.01219","0.03016"
"60112","360.63600","30.05321","0.03038"
"60194","361.12800","30.09423","0.03012"
"60276","361.62000","30.13524","0.03078"
"60358","362.11200","30.17632","0.03065"
"60440","362.60400","30.21721","0.03078"
"60522","363.09600","30.25823","0.03119"
"60604","363.58800","30.29918","0.03159"
"60686","364.08000","30.34014","0.03134"
"60768","364.57200","30.38121","0.03131"
"60850","365.06400","30.42217","0.03078"
"60932","365.55600","30.46319","0.03031"
"61014","366.04800","30.50426","0.03059"
"61096","366.54000","30.54522","0.03092"
"61178","367.03200","30.58629","0.03033"
"61260","367.52400","30.62719","0.03129"
"61342","368.01600","30.66827","0.03105"
"61424","368.50800","30.70922","0.03196"
"61506","369.00000","30.75024","0.03219"
"61588","369.49200","30.79119","0.03191"
"61670","369.98400","30.83221","0.03164"
"61752","370.47600","30.87317","0.03146"
"61834","370.96800","30.91418","0.03178"
"61916","371.46000","30.95520","0.03198"
"61998","371.95200","30.99621","0.03189"
"62080","372.44400","31.03723","0.03216"
"62162","372.93600","31.07824","0.03206"
"62244","373.42800","31.11926","0.03135"
"62326","373.92000","31.16021","0.03167"
"62408","374.41200","31.20129","0.03109"
"62490","374.90400","31.24218","0.03090"
"62572","375.39600","31.28320","0.03099"
"62654","375.88800","31.32421","0.03037"
"62736","376.38000","31.36517","0.03026"
"62818","376.87200","31.40619","0.03019"
"62900","377.36400","31.44726","0.03067"
"62982","377.85600","31.48822","0.03134"
"63064","378.34800","31.52923","0.03101"
"63146","378.84000","31.57025","0.03128"
"63228","379.33200","31.61126","0.03096"
"63310","379.82400","31.65228","0.03155"
"63392","380.31600","31.69324","0.03114"
"63474","380.80800","31.73419","0.03087"
"63556","381.30000","31.77521","0.02951"
"63638","381.79200","31.81622","0.03029"
"63720","382.28400","31.85718","0.03017"
"63802","382.77600","31.89819","0.02998"
"63884","383.26800","31.93921","0.03010"
"63966","383.76000","31.98022","0.03025"
"64048","384.25200","32.02124","0.03073"
"64130","384.74400","32.06219","0.03043"
"64212","385.23600","32.10321","0.03100"
"64294","385.72800","32.14423","0.03053"
"64376","386.22000","32.18524","0.03039"
"64458","386.71200","32.22620","0.03097"
"64540","387.20400","32.26721","0.03153"
"64622","387.69600","32.30817","0.03076"
"64704","388.18800","32.34919","0.03052"
"64786","388.68000","32.39020","0.03095"
"64868","389.17200","32.43122","0.03092"
"64950","389.66400","32.47229","0.03062"
"65032","390.15600","32.51325","0.03090"
"65114","390.64800","32.55426","0.03073"
"65196","391.14000","32.59522","0.03080"
"65278","391.63200","32.63624","0.03144"
"65360","392.12400","32.67725","0.03146"
"65442","392.61600","32.71821","0.03153"
"65524","393.10800","32.75916","0.03134"
"65606","393.60000","32.80012","0.03127"
"65688","394.09200","32.84119","0.03140"
"65770","394.58400","32.88221","0.03143"
"65852","395.07600","32.92323","0.03165"
"65934","395.56800","32.96424","0.03139"
"66016","396.06000","33.00520","0.03220"
"66098","396.55200","33.04621","0.03179"
"66180","397.04400","33.08729","0.03208"
"66262","397.53600","33.12818","0.03209"
"66344","398.02800","33.16920","0.03230"
"66426","398.52000","33.21021","0.03210"
"66508","399.01200","33.25123","0.03232"
"66590","399.50400","33.29219","0.03262"
"66672","399.99600","33.33320","0.03279"
"66754","400.48800","33.37422","0.03284"
"66836","400.98000","33.41523","0.03315"
"66918","401.47200","33.45625","0.03214"
"67000","401.96400","33.49721","0.03237"
"67082","402.45600","33.53828","0.03246"
"67164","402.94800","33.57924","0.03214"
"67246","403.44000","33.62025","0.03182"
"67328","403.93200","33.66115","0.03168"
"67410","404.42400","33.70216","0.03139"
"67492","404.91600","33.74318","0.03138"
"67574","405.40800","33.78419","0.03152"
"67656","405.90000","33.82521","0.03152"
"67738","406.39200","33.86617","0.03130"
"67820","406.88400","33.90724","0.02933"
"67902","407.37600","33.94820","0.02967"
"67984","407.86800","33.98927","0.02895"
"68066","408.36000","34.03023","0.02919"
"68148","408.85200","34.07124","0.02925"
"68230","409.34400","34.11226","0.02985"
"68312","409.83600","34.15322","0.02960"
"68394","410.32800","34.19423","0.02928"
"68476","410.82000","34.23519","0.02910"
"68558","411.31200","34.27620","0.02909"
"68640","411.80400","34.31716","0.02914"
"68722","412.29600","34.35823","0.02844"
"68804","412.78800","34.39925","0.02740"
"68886","413.28000","34.44020","0.02738"
"68968","413.77200","34.48128","0.02814"
"69050","414.26400","34.52224","0.02822"
"69132","414.75600","34.56319","0.02840"
"69214","415.24800","34.60421","0.02786"
"69296","415.74000","34.64523","0.02738"
"69378","416.23200","34.68618","0.02792"
"69460","416.72400","34.72714","0.02782"
"69542","417.21600","34.76821","0.02784"
"69624","417.70800","34.80923","0.02753"
"69706","418.20000","34.85024","0.02791"
"69788","418.69200","34.89120","0.02843"
"69870","419.18400","34.93216","0.02806"
"69952","419.67600","34.97323","0.02785"
"70034","420.16800","35.01419","0.02805"
"70116","420.66000","35.05526","0.02786"
"70198","421.15200","35.09622","0.02721"
"70280","421.64400","35.13717","0.02791"
"70362","422.13600","35.17819","0.02761"
"70444","422.62800","35.21914","0.02800"
"70526","423.12000","35.26022","0.02781"
"70608","423.61200","35.30117","0.02799"
"70690","424.10400","35.34225","0.02799"
"70772","424.59600","35.38327","0.02832"
"70854","425.08800","35.42422","0.02845"
"70936","425.58000","35.46524","0.02846"
"71018","426.07200","35.50625","0.02830"
"71100","426.56400","35.54727","0.02740"
"71182","427.05600","35.58817","0.02779"
"71264","427.54800","35.62918","0.02745"
"71346","428.04000","35.67014","0.02726"
"71428","428.53200","35.71121","0.02657"
"71510","429.02400","35.75222","0.02708"
"71592","429.51600","35.79318","0.02713"
"71674","430.00800","35.83426","0.02731"
"71756","430.50000","35.87522","0.02621"
"71838","430.99200","35.91629","0.02718"
"71920","431.48400","35.95725","0.02710"
"72002","431.97600","35.99820","0.02639"
"72084","432.46800","36.03922","0.02665"
"72166","432.96000","36.08017","0.02630"
"72248","433.45200","36.12119","0.02621"
"72330","433.94400","36.16214","0.02642"
"72412","434.43600","36.20322","0.02618"
"72494","434.92800","36.24417","0.02629"
"72576","435.42000","36.28525","0.02643"
"72658","435.91200","36.32621","0.02690"
"72740","436.40400","36.36722","0.02702"
"72822","436.89600","36.40824","0.02698"
"72904","437.38800","36.44920","0.02740"
"72986","437.88000","36.49027","0.02792"
"73068","438.37200","36.53122","0.02740"
"73150","438.86400","36.57218","0.02572"
"73232","439.35600","36.61314","0.02684"
"73314","439.84800","36.65415","0.02594"
"73396","440.34000","36.69517","0.02576"
"73478","440.83200","36.73618","0.02642"
"73560","441.32400","36.77726","0.02623"
"73642","441.81600","36.81821","0.02642"
"73724","442.30800","36.85923","0.02689"
"73806","442.80000","36.90025","0.02657"
"73888","443.29200","36.94120","0.02743"
"73970","443.78400","36.98222","0.02754"
"74052","444.27600","37.02324","0.02691"
"74134","444.76800","37.06419","0.02637"
"74216","445.26000","37.10515","0.02541"
"74298","445.75200","37.14616","0.02587"
"74380","446.24400","37.18718","0.02656"
"74462","446.73600","37.22819","0.02625"
"74544","447.22800","37.26927","0.02536"
"74626","447.72000","37.31022","0.02630"
"74708","448.21200","37.35124","0.02634"
"74790","448.70400","37.39225","0.02623"
"74872","449.19600","37.43321","0.02647"
"74954","449.68800","37.47423","0.02570"
"75036","450.18000","37.51518","0.02639"
"75118","450.67200","37.55620","0.02590"
"75200","451.16400","37.59721","0.02617"
"75282","451.65600","37.63823","0.02647"
"75364","452.14800","37.67918","0.02677"
"75446","452.64000","37.72026","0.02687"
"75528","453.13200","37.76122","0.02682"
"75610","453.62400","37.80223","0.02643"
"75692","454.11600","37.84325","0.02688"
"75774","454.60800","37.88420","0.02623"
"75856","455.10000","37.92522","0.02697"
"75938","455.59200","37.96617","0.02688"
"76020","456.08400","38.00719","0.02687"
"76102","456.57600","38.04815","0.02683"
"76184","457.06800","38.08916","0.02650"
"76266","457.56000","38.13018","0.02617"
"76348","458.05200","38.17120","0.02615"
"76430","458.54400","38.21227","0.02656"
"76512","459.03600","38.25323","0.02624"
"76594","459.52800","38.29424","0.02659"
"76676","460.02000","38.33520","0.02651"
"76758","460.51200","38.37627","0.02663"
"76840","461.00400","38.41723","0.02631"
"76922","461.49600","38.45818","0.02712"
"77004","461.98800","38.49920","0.02667"
"77086","462.48000","38.54015","0.02682"
"77168","462.97200","38.58123","0.02656"
"77250","463.46400","38.62218","0.02596"
"77332","463.95600","38.66320","0.02658"
"77414","464.44800","38.70422","0.02636"
"77496","464.94000","38.74523","0.02646"
"77578","465.43200","38.78625","0.02552"
"77660","465.92400","38.82726","0.02568"
"77742","466.41600","38.86828","0.02414"
"77824","466.90800","38.90918","0.02340"
"77906","467.40000","38.95019","0.02305"
"77988","467.89200","38.99121","0.02300"
"78070","468.38400","39.03216","0.02314"
"78152","468.87600","39.07318","0.02281"
"78234","469.36800","39.11425","0.02286"
"78316","469.86000","39.15526","0.02324"
"78398","470.35200","39.19622","0.02304"
"78480","470.84400","39.23718","0.02280"
"78562","471.33600","39.27819","0.02191"
"78644","471.82800","39.31921","0.02217"
"78726","472.32000","39.36028","0.02260"
"78808","472.81200","39.40125","0.02225"
"78890","473.30400","39.44220","0.02246"
"78972","473.79600","39.48315","0.02247"
"79054","474.28800","39.52417","0.02270"
"79136","474.78000","39.56519","0.02249"
"79218","475.27200","39.60620","0.02256"
"79300","475.76400","39.64728","0.02282"
"79382","476.25600","39.68823","0.02271"
"79464","476.74800","39.72925","0.02314"
"79546","477.24000","39.77020","0.02310"
"79628","477.73200","39.81121","0.02337"
"79710","478.22400","39.85223","0.02359"
"79792","478.71600","39.89319","0.02280"
"79874","479.20800","39.93420","0.02299"
"79956","479.70000","39.97516","0.02346"
"80038","480.19200","40.01618","0.02365"
"80120","480.68400","40.05719","0.02384"
"80202","481.17600","40.09821","0.02383"
"80284","481.66800","40.13923","0.02218"
"80366","482.16000","40.18024","0.02185"
"80448","482.65200","40.22126","0.02195"
"80530","483.14400","40.26227","0.02248"
"80612","483.63600","40.30323","0.02295"
"80694","484.12800","40.34418","0.02274"
"80776","484.62000","40.38520","0.02293"
"80858","485.11200","40.42621","0.02165"
"80940","485.60400","40.46723","0.02203"
"81022","486.09600","40.50819","0.02133"
"81104","486.58800","40.54920","0.02226"
"81186","487.08000","40.59028","0.02173"
"81268","487.57200","40.63123","0.02194"
"81350","488.06400","40.67225","0.02202"
"81432","488.55600","40.71326","0.02222"
"81514","489.04800","40.75422","0.02179"
"81596","489.54000","40.79524","0.02216"
"81678","490.03200","40.83625","0.02276"
"81760","490.52400","40.87720","0.02253"
"81842","491.01600","40.91816","0.02201"
"81924","491.50800","40.95918","0.02252"
"82006","492.00000","41.00019","0.02212"
"82088","492.49200","41.04121","0.02247"
"82170","492.98400","41.08228","0.02168"
"82252","493.47600","41.12324","0.02262"
"82334","493.96800","41.16426","0.02236"
"82416","494.46000","41.20521","0.02257"
"82498","494.95200","41.24623","0.02316"
"82580","495.44400","41.28724","0.02280"
"82662","495.93600","41.32814","0.02310"
"82744","496.42800","41.36921","0.02278"
"82826","496.92000","41.41017","0.02377"
"82908","497.41200","41.45119","0.02272"
"82990","497.90400","41.49220","0.02296"
"83072","498.39600","41.53322","0.02293"
"83154","498.88800","41.57417","0.02292"
"83236","499.38000","41.61518","0.02378"
"83318","499.87200","41.65633","0.02255"
"83400","500.36400","41.69722","0.02281"
"83482","500.85600","41.73817","0.02282"
"83564","501.34800","41.77919","0.02244"
"83646","501.84000","41.82021","0.02219"
"83728","502.33200","41.86122","0.02250"
"83810","502.82400","41.90218","0.02193"
"83892","503.31600","41.94325","0.02192"
"83974","503.80800","41.98421","0.02260"
"84056","504.30000","42.02523","0.02213"
"84138","504.79200","42.06624","0.02295"
"84220","505.28400","42.10726","0.02213"
"84302","505.77600","42.14821","0.02216"
"84384","506.26800","42.18923","0.02181"
"84466","506.76000","42.23024","0.02172"
"84548","507.25200","42.27120","0.02254"
"84630","507.74400","42.31222","0.02176"
"84712","508.23600","42.35317","0.02217"
"84794","508.72800","42.39412","0.02194"
"84876","509.22000","42.43520","0.02183"
"84958","509.71200","42.47615","0.02122"
"85040","510.20400","42.51729","0.02239"
"85122","510.69600","42.55825","0.02213"
"85204","511.18800","42.59926","0.02210"
"85286","511.68000","42.64022","0.02212"
"85368","512.17200","42.68123","0.02232"
"85450","512.66400","42.72225","0.02209"
"85532","513.15600","42.76327","0.02298"
"85614","513.64800","42.80422","0.02278"
"85696","514.14000","42.84518","0.02254"
"85778","514.63200","42.88620","0.02275"
"85860","515.12400","42.92721","0.02262"
"85942","515.61600","42.96823","0.02232"
"86024","516.10800","43.00924","0.02219"
"86106","516.60000","43.05026","0.02274"
"86188","517.09200","43.09122","0.02300"
"86270","517.58400","43.13223","0.02334"
"86352","518.07600","43.17324","0.02329"
"86434","518.56800","43.21420","0.02324"
"86516","519.06000","43.25516","0.02281"
"86598","519.55200","43.29617","0.02309"
"86680","520.04400","43.33712","0.02298"
"86762","520.53600","43.37820","0.02308"
"86844","521.02800","43.41922","0.02331"
"86926","521.52000","43.46024","0.02334"
"87008","522.01200","43.50125","0.02235"
"87090","522.50400","43.54220","0.02292"
"87172","522.99600","43.58328","0.02254"
"87254","523.48800","43.62423","0.02255"
"87336","523.98000","43.66525","0.02206"
"87418","524.47200","43.70621","0.02277"
"87500","524.96400","43.74717","0.02267"
"87582","525.45600","43.78812","0.02283"
"87664","525.94800","43.82920","0.02229"
"87746","526.44000","43.87021","0.02307"
"87828","526.93200","43.91117","0.02316"
"87910","527.42400","43.95224","0.02283"
"87992","527.91600","43.99326","0.02285"
"88074","528.40800","44.03428","0.02310"
"88156","528.90000","44.07523","0.02327"
"88238","529.39200","44.11625","0.02278"
"88320","529.88400","44.15720","0.02230"
"88402","530.37600","44.19822","0.02246"
"88484","530.86800","44.23923","0.02223"
"88566","531.36000","44.28019","0.02250"
"88648","531.85200","44.32120","0.02210"
"88730","532.34400","44.36222","0.02144"
"88812","532.83600","44.40323","0.02190"
"88894","533.32800","44.44425","0.02124"
"88976","533.82000","44.48520","0.02150"
"89058","534.31200","44.52628","0.02154"
"89140","534.80400","44.56723","0.02196"
"89222","535.29600","44.60825","0.02215"
"89304","535.78800","44.64921","0.02201"
"89386","536.28000","44.69017","0.02179"
"89468","536.77200","44.73118","0.02208"
"89550","537.26400","44.77220","0.02168"
"89632","537.75600","44.81315","0.02179"
"89714","538.24800","44.85417","0.02154"
"89796","538.74000","44.89524","0.02162"
"89878","539.23200","44.93620","0.02196"
"89960","539.72400","44.97721","0.02157"
"90042","540.21600","45.01823","0.02180"
"90124","540.70800","45.05918","0.01968"
"90206","541.20000","45.10027","0.01991"
"90288","541.69200","45.14122","0.02033"
"90370","542.18400","45.18224","0.02113"
"90452","542.67600","45.22319","0.02091"
"90534","543.16800","45.26414","0.02114"
"90616","543.66000","45.30522","0.02162"
"90698","544.15200","45.34618","0.02148"
"90780","544.64400","45.38725","0.02079"
"90862","545.13600","45.42827","0.02125"
"90944","545.62800","45.46928","0.02144"
"91026","546.12000","45.51018","0.02174"
"91108","546.61200","45.55125","0.02146"
"91190","547.10400","45.59221","0.02150"
"91272","547.59600","45.63317","0.02184"
"91354","548.08800","45.67424","0.02088"
"91436","548.58000","45.71514","0.02038"
"91518","549.07200","45.75615","0.02024"
"91600","549.56400","45.79717","0.02055"
"91682","550.05600","45.83825","0.02040"
"91764","550.54800","45.87920","0.01972"
"91846","551.04000","45.92028","0.01980"
"91928","551.53200","45.96129","0.01974"
"92010","552.02400","46.00225","0.02025"
"92092","552.51600","46.04326","0.01975"
"92174","553.00800","46.08416","0.01987"
"92256","553.50000","46.12517","0.02053"
"92338","553.99200","46.16618","0.02010"
"92420","554.48400","46.20720","0.02024"
"92502","554.97600","46.24821","0.02020"
"92584","555.46800","46.28923","0.02057"
"92666","555.96000","46.33025","0.02000"
"92748","556.45200","46.37121","0.02063"
"92830","556.94400","46.41217","0.01981"
"92912","557.43600","46.45324","0.01918"
"92994","557.92800","46.49425","0.01952"
"93076","558.42000","46.53521","0.01972"
"93158","558.91200","46.57617","0.01976"
"93240","559.40400","46.61724","0.01974"
"93322","559.89600","46.65814","0.02005"
"93404","560.38800","46.69915","0.01997"
"93486","560.88000","46.74023","0.01951"
"93568","561.37200","46.78119","0.01932"
"93650","561.86400","46.82226","0.01984"
"93732","562.35600","46.86328","0.01952"
"93814","562.84800","46.90429","0.01960"
"93896","563.34000","46.94518","0.01955"
"93978","563.83200","46.98620","0.02026"
"94060","564.32400","47.02721","0.01969"
"94142","564.81600","47.06817","0.01991"
"94224","565.30800","47.10925","0.01984"
"94306","565.80000","47.15014","0.02025"
"94388","566.29200","47.19122","0.01958"
"94470","566.78400","47.23217","0.01991"
"94552","567.27600","47.27325","0.02013"
"94634","567.76800","47.31421","0.02022"
"94716","568.26000","47.35522","0.02009"
"94798","568.75200","47.39630","0.02015"
"94880","569.24400","47.43726","0.02008"
"94962","569.73600","47.47821","0.01958"
"95044","570.22800","47.51917","0.01901"
"95126","570.72000","47.56018","0.01924"
"95208","571.21200","47.60114","0.01887"
"95290","571.70400","47.64215","0.01972"
"95372","572.19600","47.68317","0.01953"
"95454","572.68800","47.72419","0.01929"
"95536","573.18000","47.76526","0.01981"
"95618","573.67200","47.80622","0.01877"
"95700","574.16400","47.84723","0.01990"
"95782","574.65600","47.88825","0.01970"
"95864","575.14800","47.92926","0.01884"
"95946","575.64000","47.97028","0.01892"
"96028","576.13200","48.01117","0.01887"
"96110","576.62400","48.05219","0.01906"
"96192","577.11600","48.09314","0.01902"
"96274","577.60800","48.13416","0.01803"
"96356","578.10000","48.17517","0.01847"
"96438","578.59200","48.21619","0.01762"
"96520","579.08400","48.25721","0.01790"
"96602","579.57600","48.29822","0.01808"
"96684","580.06800","48.33929","0.01865"
"96766","580.56000","48.38020","0.01833"
"96848","581.05200","48.42121","0.01828"
"96930","581.54400","48.46223","0.01838"
"97012","582.03600","48.50318","0.01829"
"97094","582.52800","48.54420","0.01800"
"97176","583.02000","48.58516","0.01830"
"97258","583.51200","48.62623","0.01805"
"97340","584.00400","48.66712","0.01807"
"97422","584.49600","48.70820","0.01797"
"97504","584.98800","48.74922","0.01772"
"97586","585.48000","48.79023","0.01810"
"97668","585.97200","48.83131","0.01737"
"97750","586.46400","48.87226","0.01825"
"97832","586.95600","48.91322","0.01777"
"97914","587.44800","48.95424","0.01857"
"97996","587.94000","48.99519","0.01847"
"98078","588.43200","49.03621","0.01799"
"98160","588.92400","49.07716","0.01852"
"98242","589.41600","49.11818","0.01767"
"98324","589.90800","49.15919","0.01739"
"98406","590.40000","49.20021","0.01769"
"98488","590.89200","49.24122","0.01784"
"98570","591.38400","49.28218","0.01749"
"98652","591.87600","49.32325","0.01758"
"98734","592.36800","49.36421","0.01752"
"98816","592.86000","49.40528","0.01789"
"98898","593.35200","49.44619","0.01781"
"98980","593.84400","49.48720","0.01788"
"99062","594.33600","49.52821","0.01770"
"99144","594.82800","49.56917","0.01732"
"99226","595.32000","49.61018","0.01793"
"99308","595.81200","49.65120","0.01732"
"99390","596.30400","49.69228","0.01664"
"99472","596.79600","49.73323","0.01745"
"99554","597.28800","49.77425","0.01775"
"99636","597.78000","49.81521","0.01714"
"99718","598.27200","49.85622","0.01762"
"99800","598.76400","49.89724","0.01755"
"99882","599.25600","49.93819","0.01829"
"99964","599.74800","49.97921","0.01793"
"100046","600.24000","50.02016","0.01786"
"100128","600.73200","50.06124","0.01811"
"100210","601.22400","50.10219","0.01853"
"100292","601.71600","50.14321","0.01871"
"100374","602.20800","50.18422","0.01861"
"100456","602.70000","50.22524","0.01928"
"100538","603.19200","50.26625","0.01808"
"100620","603.68400","50.30727","0.01824"
"100702","604.17600","50.34823","0.01868"
"100784","604.66800","50.38924","0.01834"
"100866","605.16000","50.43014","0.01831"
"100948","605.65200","50.47116","0.01830"
"100967","605.76600","50.48072","0.01885"