File: Trajectories_together/170226_1Specimen_RawData_2.csv
"","V1","V2","V3"
"1","End date","2/26/2017",""
"2","Specimen label","1AT_2.2",""
"3","Maximum Load","0.00830","N"
"4","Time","Extension","Load"
"5","(s)","(mm)","(N)"
"6","0.00000","0.00000","-0.00010"
"21","0.09000","0.00293","0.00005"
"36","0.18000","0.01160","0.00012"
"51","0.27000","0.02146","-0.00073"
"66","0.36000","0.03013","0.00027"
"81","0.45000","0.03779","0.00013"
"96","0.54000","0.04526","0.00007"
"111","0.63000","0.05279","0.00008"
"126","0.72000","0.06027","0.00028"
"141","0.81000","0.06774","0.00036"
"156","0.90000","0.07528","0.00051"
"171","0.99000","0.08269","0.00006"
"186","1.08000","0.09022","0.00044"
"201","1.17000","0.09770","0.00008"
"216","1.26000","0.10523","0.00020"
"231","1.35000","0.11276","0.00060"
"246","1.44000","0.12024","0.00059"
"261","1.53000","0.12771","0.00028"
"276","1.62000","0.13518","0.00080"
"291","1.71000","0.14272","0.00029"
"306","1.80000","0.15025","0.00014"
"321","1.89000","0.15772","0.00019"
"336","1.98000","0.16520","0.00038"
"351","2.07000","0.17273","0.00042"
"366","2.16000","0.18021","0.00006"
"381","2.25000","0.18774","0.00047"
"396","2.34000","0.19521","0.00035"
"411","2.43000","0.20269","0.00046"
"426","2.52000","0.21022","0.00037"
"441","2.61000","0.21769","0.00033"
"456","2.70000","0.22517","0.00065"
"471","2.79000","0.23270","0.00109"
"486","2.88000","0.24023","0.00070"
"501","2.97000","0.24777","0.00019"
"516","3.06000","0.25518","0.00023"
"531","3.15000","0.26272","0.00072"
"546","3.24000","0.27019","0.00062"
"561","3.33000","0.27772","-0.00001"
"576","3.42000","0.28520","0.00029"
"591","3.51000","0.29267","0.00074"
"606","3.60000","0.30014","0.00066"
"621","3.69000","0.30768","0.00067"
"636","3.78000","0.31515","0.00034"
"651","3.87000","0.32274","0.00089"
"666","3.96000","0.33022","0.00074"
"681","4.05000","0.33769","0.00041"
"696","4.14000","0.34522","0.00043"
"711","4.23000","0.35270","0.00036"
"726","4.32000","0.36017","0.00029"
"741","4.41000","0.36771","0.00062"
"756","4.50000","0.37524","0.00075"
"771","4.59000","0.38271","0.00031"
"786","4.68000","0.39019","0.00060"
"801","4.77000","0.39760","0.00044"
"816","4.86000","0.40519","0.00100"
"831","4.95000","0.41273","0.00052"
"846","5.04000","0.42020","0.00039"
"861","5.13000","0.42779","0.00063"
"876","5.22000","0.43521","0.00044"
"891","5.31000","0.44268","0.00064"
"906","5.40000","0.45022","0.00087"
"921","5.49000","0.45769","0.00014"
"936","5.58000","0.46522","0.00062"
"951","5.67000","0.47270","0.00075"
"966","5.76000","0.48017","0.00058"
"981","5.85000","0.48764","0.00056"
"996","5.94000","0.49518","0.00072"
"1011","6.03000","0.50271","0.00022"
"1026","6.12000","0.51024","0.00061"
"1041","6.21000","0.51772","0.00035"
"1056","6.30000","0.52519","0.00080"
"1071","6.39000","0.53266","0.00075"
"1086","6.48000","0.54014","0.00025"
"1101","6.57000","0.54773","0.00098"
"1116","6.66000","0.55527","0.00059"
"1131","6.75000","0.56274","0.00053"
"1146","6.84000","0.57021","0.00077"
"1161","6.93000","0.57769","0.00070"
"1176","7.02000","0.58522","0.00039"
"1191","7.11000","0.59275","0.00107"
"1206","7.20000","0.60023","0.00068"
"1221","7.29000","0.60776","0.00057"
"1236","7.38000","0.61523","0.00071"
"1251","7.47000","0.62271","0.00024"
"1266","7.56000","0.63018","0.00100"
"1281","7.65000","0.63772","0.00125"
"1296","7.74000","0.64519","0.00053"
"1311","7.83000","0.65272","0.00124"
"1326","7.92000","0.66020","0.00037"
"1341","8.01000","0.66767","0.00102"
"1356","8.10000","0.67520","0.00103"
"1371","8.19000","0.68268","0.00047"
"1386","8.28000","0.69021","0.00167"
"1401","8.37000","0.69774","0.00083"
"1416","8.46000","0.70516","0.00032"
"1431","8.55000","0.71269","-0.00028"
"1446","8.64000","0.72016","0.00009"
"1461","8.73000","0.72770","0.00040"
"1476","8.82000","0.73529","0.00016"
"1491","8.91000","0.74271","0.00061"
"1506","9.00000","0.75018","0.00033"
"1521","9.09000","0.75771","0.00019"
"1536","9.18000","0.76519","0.00033"
"1551","9.27000","0.77272","0.00024"
"1566","9.36000","0.78019","0.00048"
"1581","9.45000","0.78779","0.00044"
"1596","9.54000","0.79526","-0.00010"
"1611","9.63000","0.80267","0.00001"
"1626","9.72000","0.81021","0.00038"
"1641","9.81000","0.81774","0.00006"
"1656","9.90000","0.82516","-0.00007"
"1671","9.99000","0.83275","0.00036"
"1686","10.08000","0.84022","0.00006"
"1701","10.17000","0.84764","0.00019"
"1716","10.26000","0.85523","0.00040"
"1731","10.35000","0.86276","-0.00001"
"1746","10.44000","0.87024","-0.00036"
"1761","10.53000","0.87771","0.00004"
"1776","10.62000","0.88518","0.00002"
"1791","10.71000","0.89272","-0.00014"
"1806","10.80000","0.90013","0.00040"
"1821","10.89000","0.90772","0.00031"
"1836","10.98000","0.91526","0.00056"
"1851","11.07000","0.92273","0.00037"
"1866","11.16000","0.93015","0.00033"
"1881","11.25000","0.93762","0.00055"
"1896","11.34000","0.94521","-0.00009"
"1911","11.43000","0.95275","0.00060"
"1926","11.52000","0.96022","0.00012"
"1941","11.61000","0.96769","0.00002"
"1956","11.70000","0.97523","0.00077"
"1971","11.79000","0.98264","-0.00023"
"1986","11.88000","0.99023","0.00039"
"2001","11.97000","0.99777","-0.00039"
"2016","12.06000","1.00518","0.00058"
"2031","12.15000","1.01272","0.00080"
"2046","12.24000","1.02019","-0.00005"
"2061","12.33000","1.02766","0.00034"
"2076","12.42000","1.03520","0.00017"
"2091","12.51000","1.04273","0.00062"
"2106","12.60000","1.05020","0.00081"
"2121","12.69000","1.05774","0.00076"
"2136","12.78000","1.06515","0.00037"
"2151","12.87000","1.07268","0.00009"
"2166","12.96000","1.08022","0.00030"
"2181","13.05000","1.08775","-0.00001"
"2196","13.14000","1.09522","0.00046"
"2211","13.23000","1.10270","0.00027"
"2226","13.32000","1.11017","0.00048"
"2241","13.41000","1.11771","0.00043"
"2256","13.50000","1.12518","0.00044"
"2271","13.59000","1.13277","0.00037"
"2286","13.68000","1.14025","0.00017"
"2301","13.77000","1.14772","0.00040"
"2316","13.86000","1.15525","0.00035"
"2331","13.95000","1.16267","0.00044"
"2346","14.04000","1.17020","0.00013"
"2361","14.13000","1.17779","0.00042"
"2376","14.22000","1.18521","0.00049"
"2391","14.31000","1.19268","0.00026"
"2406","14.40000","1.20016","0.00029"
"2421","14.49000","1.20763","0.00025"
"2436","14.58000","1.21522","0.00038"
"2451","14.67000","1.22276","0.00002"
"2466","14.76000","1.23023","0.00039"
"2481","14.85000","1.23776","0.00029"
"2496","14.94000","1.24524","0.00092"
"2511","15.03000","1.25271","0.00037"
"2526","15.12000","1.26018","0.00057"
"2541","15.21000","1.26778","0.00073"
"2556","15.30000","1.27525","0.00003"
"2571","15.39000","1.28272","0.00050"
"2586","15.48000","1.29020","0.00029"
"2601","15.57000","1.29767","0.00038"
"2616","15.66000","1.30515","0.00042"
"2631","15.75000","1.31280","0.00040"
"2646","15.84000","1.32027","0.00010"
"2661","15.93000","1.32769","0.00051"
"2676","16.02000","1.33522","0.00093"
"2691","16.11000","1.34263","-0.00019"
"2706","16.20000","1.35017","0.00066"
"2721","16.29000","1.35776","0.00061"
"2736","16.38000","1.36523","0.00054"
"2751","16.47000","1.37271","0.00045"
"2766","16.56000","1.38018","0.00007"
"2781","16.65000","1.38766","0.00096"
"2796","16.74000","1.39519","0.00045"
"2811","16.83000","1.40272","0.00044"
"2826","16.92000","1.41026","0.00057"
"2841","17.01000","1.41779","0.00087"
"2856","17.10000","1.42520","0.00048"
"2871","17.19000","1.43268","0.00101"
"2886","17.28000","1.44021","0.00056"
"2901","17.37000","1.44768","0.00060"
"2916","17.46000","1.45528","0.00064"
"2931","17.55000","1.46275","0.00064"
"2946","17.64000","1.47016","0.00035"
"2961","17.73000","1.47770","0.00046"
"2976","17.82000","1.48523","0.00078"
"2991","17.91000","1.49277","0.00031"
"3006","18.00000","1.50030","0.00060"
"3021","18.09000","1.50771","0.00034"
"3036","18.18000","1.51519","0.00057"
"3051","18.27000","1.52266","0.00007"
"3066","18.36000","1.53019","0.00021"
"3081","18.45000","1.53773","0.00042"
"3096","18.54000","1.54520","0.00057"
"3111","18.63000","1.55273","0.00040"
"3126","18.72000","1.56015","0.00068"
"3141","18.81000","1.56762","0.00073"
"3156","18.90000","1.57522","0.00069"
"3171","18.99000","1.58275","0.00106"
"3186","19.08000","1.59022","0.00035"
"3201","19.17000","1.59770","0.00064"
"3216","19.26000","1.60517","0.00000"
"3231","19.35000","1.61264","0.00085"
"3246","19.44000","1.62024","0.00096"
"3261","19.53000","1.62771","0.00094"
"3276","19.62000","1.63524","0.00086"
"3291","19.71000","1.64278","0.00059"
"3306","19.80000","1.65019","0.00026"
"3321","19.89000","1.65772","0.00005"
"3336","19.98000","1.66520","0.00067"
"3351","20.07000","1.67273","0.00023"
"3366","20.16000","1.68027","0.00043"
"3381","20.25000","1.68768","0.00015"
"3396","20.34000","1.69521","0.00022"
"3411","20.43000","1.70269","0.00084"
"3426","20.52000","1.71016","0.00064"
"3441","20.61000","1.71775","0.00049"
"3456","20.70000","1.72517","0.00109"
"3471","20.79000","1.73270","0.00028"
"3486","20.88000","1.74023","0.00032"
"3501","20.97000","1.74765","0.00065"
"3516","21.06000","1.75524","0.00019"
"3531","21.15000","1.76271","-0.00003"
"3546","21.24000","1.77019","0.00062"
"3561","21.33000","1.77772","0.00053"
"3576","21.42000","1.78520","0.00043"
"3591","21.51000","1.79267","0.00068"
"3606","21.60000","1.80020","0.00081"
"3621","21.69000","1.80768","0.00079"
"3636","21.78000","1.81521","0.00013"
"3651","21.87000","1.82274","0.00006"
"3666","21.96000","1.83016","0.00021"
"3681","22.05000","1.83769","0.00085"
"3696","22.14000","1.84522","0.00054"
"3711","22.23000","1.85276","0.00048"
"3726","22.32000","1.86023","0.00052"
"3741","22.41000","1.86771","0.00062"
"3756","22.50000","1.87518","0.00059"
"3771","22.59000","1.88265","0.00056"
"3786","22.68000","1.89025","0.00032"
"3801","22.77000","1.89778","0.00030"
"3816","22.86000","1.90525","0.00014"
"3831","22.95000","1.91273","0.00070"
"3846","23.04000","1.92020","0.00012"
"3861","23.13000","1.92767","0.00104"
"3876","23.22000","1.93521","0.00065"
"3891","23.31000","1.94274","0.00050"
"3906","23.40000","1.95022","0.00082"
"3921","23.49000","1.95775","0.00041"
"3936","23.58000","1.96516","0.00079"
"3951","23.67000","1.97264","0.00106"
"3966","23.76000","1.98023","0.00041"
"3981","23.85000","1.98770","0.00028"
"3996","23.94000","1.99518","0.00047"
"4011","24.03000","2.00271","0.00077"
"4026","24.12000","2.01018","0.00062"
"4041","24.21000","2.01766","0.00091"
"4056","24.30000","2.02519","0.00113"
"4071","24.39000","2.03272","0.00082"
"4086","24.48000","2.04026","0.00017"
"4101","24.57000","2.04767","0.00018"
"4116","24.66000","2.05521","0.00090"
"4131","24.75000","2.06268","0.00049"
"4146","24.84000","2.07015","0.00044"
"4161","24.93000","2.07775","0.00020"
"4176","25.02000","2.08528","0.00108"
"4191","25.11000","2.09269","0.00075"
"4206","25.20000","2.10017","0.00049"
"4221","25.29000","2.10770","0.00062"
"4236","25.38000","2.11517","0.00059"
"4251","25.47000","2.12277","0.00049"
"4266","25.56000","2.13024","0.00056"
"4281","25.65000","2.13772","0.00033"
"4296","25.74000","2.14519","0.00040"
"4311","25.83000","2.15266","0.00058"
"4326","25.92000","2.16020","0.00094"
"4341","26.01000","2.16773","0.00003"
"4356","26.10000","2.17520","0.00059"
"4371","26.19000","2.18274","0.00059"
"4386","26.28000","2.19015","0.00055"
"4401","26.37000","2.19762","0.00078"
"4416","26.46000","2.20516","0.00079"
"4431","26.55000","2.21275","0.00071"
"4446","26.64000","2.22022","0.00048"
"4461","26.73000","2.22770","0.00077"
"4476","26.82000","2.23517","0.00009"
"4491","26.91000","2.24265","0.00057"
"4506","27.00000","2.25024","0.00072"
"4521","27.09000","2.25771","0.00011"
"4536","27.18000","2.26525","0.00041"
"4551","27.27000","2.27272","0.00073"
"4566","27.36000","2.28025","0.00038"
"4581","27.45000","2.28767","0.00095"
"4596","27.54000","2.29520","0.00065"
"4611","27.63000","2.30279","0.00086"
"4626","27.72000","2.31021","0.00028"
"4641","27.81000","2.31774","0.00049"
"4656","27.90000","2.32521","0.00082"
"4671","27.99000","2.33269","0.00058"
"4686","28.08000","2.34022","0.00038"
"4701","28.17000","2.34776","0.00066"
"4716","28.26000","2.35523","0.00040"
"4731","28.35000","2.36276","0.00044"
"4746","28.44000","2.37024","0.00085"
"4761","28.53000","2.37771","0.00023"
"4776","28.62000","2.38524","0.00072"
"4791","28.71000","2.39272","-0.00002"
"4806","28.80000","2.40025","0.00090"
"4821","28.89000","2.40772","0.00036"
"4836","28.98000","2.41514","0.00035"
"4851","29.07000","2.42273","0.00034"
"4866","29.16000","2.43021","0.00108"
"4881","29.25000","2.43768","0.00068"
"4896","29.34000","2.44521","0.00058"
"4911","29.43000","2.45269","0.00018"
"4926","29.52000","2.46016","0.00081"
"4941","29.61000","2.46769","0.00062"
"4956","29.70000","2.47523","0.00040"
"4971","29.79000","2.48276","0.00091"
"4986","29.88000","2.49023","0.00032"
"5001","29.97000","2.49771","0.00042"
"5016","30.06000","2.50524","0.00149"
"5031","30.15000","2.51272","0.00036"
"5046","30.24000","2.52019","0.00052"
"5061","30.33000","2.52772","0.00056"
"5076","30.42000","2.53526","0.00063"
"5091","30.51000","2.54273","0.00060"
"5106","30.60000","2.55014","0.00070"
"5121","30.69000","2.55768","0.00022"
"5136","30.78000","2.56527","0.00055"
"5151","30.87000","2.57274","0.00090"
"5166","30.96000","2.58028","0.00039"
"5181","31.05000","2.58775","0.00049"
"5196","31.14000","2.59516","0.00043"
"5211","31.23000","2.60270","0.00030"
"5226","31.32000","2.61023","0.00039"
"5241","31.41000","2.61771","0.00090"
"5256","31.50000","2.62518","0.00059"
"5271","31.59000","2.63271","0.00068"
"5286","31.68000","2.64013","0.00009"
"5301","31.77000","2.64766","0.00072"
"5316","31.86000","2.65519","0.00027"
"5331","31.95000","2.66273","0.00057"
"5346","32.04000","2.67026","0.00043"
"5361","32.13000","2.67773","0.00052"
"5376","32.22000","2.68521","0.00044"
"5391","32.31000","2.69268","0.00103"
"5406","32.40000","2.70021","0.00049"
"5421","32.49000","2.70775","0.00055"
"5436","32.58000","2.71522","0.00032"
"5451","32.67000","2.72276","0.00032"
"5466","32.76000","2.73017","0.00089"
"5481","32.85000","2.73764","0.00078"
"5496","32.94000","2.74524","0.00063"
"5511","33.03000","2.75271","-0.00004"
"5526","33.12000","2.76024","0.00080"
"5541","33.21000","2.76778","0.00061"
"5556","33.30000","2.77519","0.00030"
"5571","33.39000","2.78266","0.00018"
"5586","33.48000","2.79020","0.00049"
"5601","33.57000","2.79767","0.00034"
"5616","33.66000","2.80526","0.00048"
"5631","33.75000","2.81268","0.00062"
"5646","33.84000","2.82015","0.00026"
"5661","33.93000","2.82769","0.00035"
"5676","34.02000","2.83522","0.00045"
"5691","34.11000","2.84269","0.00090"
"5706","34.20000","2.85023","0.00064"
"5721","34.29000","2.85770","0.00049"
"5736","34.38000","2.86517","0.00027"
"5751","34.47000","2.87265","0.00076"
"5766","34.56000","2.88024","0.00067"
"5781","34.65000","2.88777","0.00032"
"5796","34.74000","2.89525","0.00095"
"5811","34.83000","2.90272","0.00052"
"5826","34.92000","2.91020","0.00046"
"5841","35.01000","2.91767","0.00122"
"5856","35.10000","2.92526","0.00087"
"5871","35.19000","2.93274","0.00034"
"5886","35.28000","2.94027","0.00020"
"5901","35.37000","2.94774","0.00024"
"5916","35.46000","2.95516","0.00059"
"5931","35.55000","2.96269","0.00022"
"5946","35.64000","2.97022","0.00036"
"5961","35.73000","2.97770","-0.00010"
"5976","35.82000","2.98523","0.00074"
"5991","35.91000","2.99271","0.00066"
"6006","36.00000","3.00018","0.00008"
"6021","36.09000","3.00765","0.00109"
"6036","36.18000","3.01525","0.00007"
"6051","36.27000","3.02272","0.00013"
"6066","36.36000","3.03025","-0.00020"
"6081","36.45000","3.03767","0.00059"
"6096","36.54000","3.04520","0.00039"
"6111","36.63000","3.05267","0.00048"
"6126","36.72000","3.06021","0.00081"
"6141","36.81000","3.06774","0.00037"
"6156","36.90000","3.07516","0.00066"
"6171","36.99000","3.08269","0.00031"
"6186","37.08000","3.09022","-0.00007"
"6201","37.17000","3.09764","0.00018"
"6216","37.26000","3.10523","0.00081"
"6231","37.35000","3.11270","0.00121"
"6246","37.44000","3.12024","0.00051"
"6261","37.53000","3.12777","0.00102"
"6276","37.62000","3.13518","0.00003"
"6291","37.71000","3.14272","0.00000"
"6306","37.80000","3.15031","0.00063"
"6321","37.89000","3.15772","0.00050"
"6336","37.98000","3.16520","0.00101"
"6351","38.07000","3.17267","0.00045"
"6366","38.16000","3.18021","0.00052"
"6381","38.25000","3.18774","0.00073"
"6396","38.34000","3.19521","0.00017"
"6411","38.43000","3.20275","0.00062"
"6426","38.52000","3.21022","0.00107"
"6441","38.61000","3.21769","0.00130"
"6456","38.70000","3.22523","0.00084"
"6471","38.79000","3.23270","0.00070"
"6486","38.88000","3.24017","0.00051"
"6501","38.97000","3.24777","0.00078"
"6516","39.06000","3.25524","0.00026"
"6531","39.15000","3.26265","0.00075"
"6546","39.24000","3.27019","0.00044"
"6561","39.33000","3.27772","0.00037"
"6576","39.42000","3.28526","0.00031"
"6591","39.51000","3.29273","-0.00015"
"6606","39.60000","3.30026","0.00037"
"6621","39.69000","3.30768","0.00112"
"6636","39.78000","3.31515","0.00034"
"6651","39.87000","3.32274","0.00011"
"6666","39.96000","3.33022","0.00019"
"6681","40.05000","3.33775","0.00025"
"6696","40.14000","3.34522","0.00043"
"6711","40.23000","3.35270","0.00078"
"6726","40.32000","3.36017","0.00106"
"6741","40.41000","3.36771","0.00088"
"6756","40.50000","3.37524","0.00084"
"6771","40.59000","3.38271","-0.00042"
"6786","40.68000","3.39025","0.00107"
"6801","40.77000","3.39766","0.00108"
"6816","40.86000","3.40513","0.00107"
"6831","40.95000","3.41273","-0.00001"
"6846","41.04000","3.42026","0.00082"
"6861","41.13000","3.42773","-0.00019"
"6876","41.22000","3.43521","0.00075"
"6891","41.31000","3.44268","0.00053"
"6906","41.40000","3.45021","0.00048"
"6921","41.49000","3.45763","0.00060"
"6936","41.58000","3.46528","0.00037"
"6951","41.67000","3.47276","0.00030"
"6966","41.76000","3.48017","0.00029"
"6981","41.85000","3.48770","0.00083"
"6996","41.94000","3.49512","0.00042"
"7011","42.03000","3.50265","0.00060"
"7026","42.12000","3.51024","0.00070"
"7041","42.21000","3.51772","0.00032"
"7056","42.30000","3.52519","0.00055"
"7071","42.39000","3.53266","0.00073"
"7086","42.48000","3.54014","0.00039"
"7101","42.57000","3.54773","0.00046"
"7116","42.66000","3.55527","0.00064"
"7131","42.75000","3.56274","0.00053"
"7146","42.84000","3.57027","0.00035"
"7161","42.93000","3.57769","0.00050"
"7176","43.02000","3.58516","0.00067"
"7191","43.11000","3.59275","0.00043"
"7206","43.20000","3.60023","0.00043"
"7221","43.29000","3.60776","0.00036"
"7236","43.38000","3.61523","0.00076"
"7251","43.47000","3.62277","0.00019"
"7266","43.56000","3.63018","0.00050"
"7281","43.65000","3.63771","0.00043"
"7296","43.74000","3.64525","0.00082"
"7311","43.83000","3.65272","0.00030"
"7326","43.92000","3.66026","-0.00020"
"7341","44.01000","3.66773","0.00094"
"7356","44.10000","3.67514","0.00077"
"7371","44.19000","3.68268","0.00073"
"7386","44.28000","3.69021","0.00038"
"7401","44.37000","3.69768","0.00002"
"7416","44.46000","3.70522","0.00045"
"7431","44.55000","3.71269","0.00011"
"7446","44.64000","3.72010","0.00046"
"7461","44.73000","3.72770","0.00117"
"7476","44.82000","3.73523","0.00052"
"7491","44.91000","3.74271","0.00034"
"7506","45.00000","3.75024","0.00061"
"7521","45.09000","3.75771","0.00065"
"7536","45.18000","3.76513","0.00032"
"7551","45.27000","3.77272","0.00029"
"7566","45.36000","3.78025","0.00124"
"7581","45.45000","3.78773","0.00041"
"7596","45.54000","3.79526","0.00092"
"7611","45.63000","3.80273","0.00013"
"7626","45.72000","3.81021","0.00052"
"7641","45.81000","3.81768","0.00072"
"7656","45.90000","3.82521","0.00060"
"7671","45.99000","3.83275","0.00071"
"7686","46.08000","3.84022","0.00001"
"7701","46.17000","3.84770","0.00036"
"7716","46.26000","3.85517","0.00041"
"7731","46.35000","3.86270","0.00054"
"7746","46.44000","3.87030","0.00048"
"7761","46.53000","3.87771","0.00057"
"7776","46.62000","3.88518","0.00077"
"7791","46.71000","3.89272","0.00041"
"7806","46.80000","3.90013","0.00012"
"7821","46.89000","3.90766","0.00030"
"7836","46.98000","3.91526","0.00058"
"7851","47.07000","3.92273","0.00032"
"7866","47.16000","3.93021","0.00112"
"7881","47.25000","3.93768","0.00038"
"7896","47.34000","3.94515","0.00036"
"7911","47.43000","3.95269","0.00038"
"7926","47.52000","3.96022","0.00061"
"7941","47.61000","3.96769","0.00072"
"7956","47.70000","3.97523","0.00037"
"7971","47.79000","3.98264","0.00046"
"7986","47.88000","3.99017","0.00054"
"8001","47.97000","3.99771","0.00027"
"8016","48.06000","4.00524","0.00009"
"8031","48.15000","4.01277","0.00034"
"8046","48.24000","4.02025","0.00059"
"8061","48.33000","4.02766","0.00034"
"8076","48.42000","4.03520","0.00048"
"8091","48.51000","4.04273","0.00068"
"8106","48.60000","4.05026","0.00061"
"8121","48.69000","4.05774","0.00089"
"8136","48.78000","4.06521","0.00015"
"8151","48.87000","4.07268","0.00042"
"8166","48.96000","4.08016","0.00041"
"8181","49.05000","4.08769","0.00072"
"8196","49.14000","4.09528","0.00046"
"8211","49.23000","4.10270","0.00058"
"8226","49.32000","4.11023","0.00058"
"8241","49.41000","4.11765","0.00064"
"8256","49.50000","4.12512","0.00004"
"8271","49.59000","4.13271","0.00087"
"8286","49.68000","4.14025","0.00037"
"8301","49.77000","4.14772","0.00058"
"8316","49.86000","4.15525","0.00069"
"8331","49.95000","4.16267","0.00057"
"8346","50.04000","4.17014","0.00012"
"8361","50.13000","4.17773","0.00067"
"8376","50.22000","4.18527","0.00019"
"8391","50.31000","4.19274","0.00050"
"8406","50.40000","4.20021","0.00045"
"8421","50.49000","4.20769","0.00001"
"8436","50.58000","4.21522","0.00003"
"8451","50.67000","4.22270","0.00017"
"8466","50.76000","4.23023","0.00043"
"8481","50.85000","4.23776","0.00000"
"8496","50.94000","4.24524","0.00006"
"8511","51.03000","4.25265","0.00046"
"8526","51.12000","4.26018","-0.00019"
"8541","51.21000","4.26772","-0.00006"
"8556","51.30000","4.27519","0.00045"
"8571","51.39000","4.28272","0.00040"
"8586","51.48000","4.29020","0.00011"
"8601","51.57000","4.29767","0.00017"
"8616","51.66000","4.30515","0.00053"
"8631","51.75000","4.31268","0.00049"
"8646","51.84000","4.32021","0.00023"
"8661","51.93000","4.32775","-0.00025"
"8676","52.02000","4.33528","0.00067"
"8691","52.11000","4.34263","0.00077"
"8706","52.20000","4.35017","-0.00033"
"8721","52.29000","4.35776","0.00018"
"8736","52.38000","4.36523","0.00062"
"8751","52.47000","4.37277","0.00015"
"8766","52.56000","4.38024","0.00020"
"8781","52.65000","4.38771","0.00031"
"8796","52.74000","4.39525","-0.00049"
"8811","52.83000","4.40272","0.00042"
"8826","52.92000","4.41020","0.00044"
"8841","53.01000","4.41779","0.00040"
"8856","53.10000","4.42520","0.00054"
"8871","53.19000","4.43268","0.00032"
"8886","53.28000","4.44015","-0.00019"
"8901","53.37000","4.44774","0.00001"
"8916","53.46000","4.45528","0.00044"
"8931","53.55000","4.46269","0.00026"
"8946","53.64000","4.47022","0.00038"
"8961","53.73000","4.47770","0.00052"
"8976","53.82000","4.48517","0.00046"
"8991","53.91000","4.49265","-0.00024"
"9006","54.00000","4.50024","-0.00034"
"9021","54.09000","4.50771","0.00036"
"9036","54.18000","4.51525","0.00065"
"9051","54.27000","4.52266","0.00031"
"9066","54.36000","4.53013","0.00053"
"9081","54.45000","4.53773","0.00013"
"9096","54.54000","4.54520","0.00000"
"9111","54.63000","4.55267","0.00042"
"9126","54.72000","4.56021","-0.00001"
"9141","54.81000","4.56768","0.00087"
"9156","54.90000","4.57515","0.00061"
"9171","54.99000","4.58269","0.00009"
"9186","55.08000","4.59022","0.00009"
"9201","55.17000","4.59770","0.00021"
"9216","55.26000","4.60517","0.00009"
"9231","55.35000","4.61264","-0.00011"
"9246","55.44000","4.62018","0.00049"
"9261","55.53000","4.62771","0.00022"
"9276","55.62000","4.63524","0.00055"
"9291","55.71000","4.64272","0.00046"
"9306","55.80000","4.65019","0.00069"
"9321","55.89000","4.65772","0.00007"
"9336","55.98000","4.66520","-0.00037"
"9351","56.07000","4.67273","0.00018"
"9366","56.16000","4.68026","0.00001"
"9381","56.25000","4.68774","0.00103"
"9396","56.34000","4.69521","0.00045"
"9411","56.43000","4.70269","0.00039"
"9426","56.52000","4.71022","0.00033"
"9441","56.61000","4.71769","0.00054"
"9456","56.70000","4.72523","0.00078"
"9471","56.79000","4.73276","0.00065"
"9486","56.88000","4.74023","0.00064"
"9501","56.97000","4.74765","0.00037"
"9516","57.06000","4.75518","0.00039"
"9531","57.15000","4.76277","0.00053"
"9546","57.24000","4.77019","0.00001"
"9561","57.33000","4.77772","0.00120"
"9576","57.42000","4.78514","0.00086"
"9591","57.51000","4.79267","0.00018"
"9606","57.60000","4.80020","0.00056"
"9621","57.69000","4.80768","-0.00002"
"9636","57.78000","4.81527","0.00057"
"9651","57.87000","4.82274","0.00041"
"9666","57.96000","4.83022","0.00026"
"9681","58.05000","4.83769","0.00021"
"9696","58.14000","4.84516","0.00052"
"9711","58.23000","4.85270","0.00064"
"9726","58.32000","4.86029","0.00036"
"9741","58.41000","4.86776","0.00028"
"9756","58.50000","4.87524","0.00060"
"9771","58.59000","4.88265","0.00057"
"9786","58.68000","4.89013","0.00054"
"9801","58.77000","4.89772","0.00043"
"9816","58.86000","4.90525","0.00056"
"9831","58.95000","4.91273","0.00084"
"9846","59.04000","4.92020","0.00061"
"9861","59.13000","4.92767","0.00004"
"9876","59.22000","4.93521","0.00034"
"9891","59.31000","4.94274","0.00050"
"9906","59.40000","4.95021","-0.00012"
"9921","59.49000","4.95775","0.00008"
"9936","59.58000","4.96516","0.00051"
"9951","59.67000","4.97264","0.00018"
"9966","59.76000","4.98023","0.00074"
"9981","59.85000","4.98764","0.00069"
"9996","59.94000","4.99524","0.00031"
"10011","60.03000","5.00277","0.00054"
"10026","60.12000","5.01018","0.00003"
"10041","60.21000","5.01766","0.00012"
"10056","60.30000","5.02519","0.00015"
"10071","60.39000","5.03272","0.00036"
"10086","60.48000","5.04026","0.00063"
"10101","60.57000","5.04773","0.00054"
"10116","60.66000","5.05520","0.00046"
"10131","60.75000","5.06268","0.00049"
"10146","60.84000","5.07021","0.00034"
"10161","60.93000","5.07775","0.00047"
"10176","61.02000","5.08522","0.00020"
"10191","61.11000","5.09275","0.00053"
"10206","61.20000","5.10023","0.00052"
"10221","61.29000","5.10770","0.00011"
"10236","61.38000","5.11523","-0.00022"
"10251","61.47000","5.12277","0.00046"
"10266","61.56000","5.13018","0.00012"
"10281","61.65000","5.13777","0.00012"
"10296","61.74000","5.14519","0.00035"
"10311","61.83000","5.15260","0.00004"
"10326","61.92000","5.16026","0.00038"
"10341","62.01000","5.16773","0.00001"
"10356","62.10000","5.17520","0.00040"
"10371","62.19000","5.18274","0.00030"
"10386","62.28000","5.19015","-0.00024"
"10401","62.37000","5.19762","0.00022"
"10416","62.46000","5.20516","0.00008"
"10431","62.55000","5.21275","0.00031"
"10446","62.64000","5.22022","0.00016"
"10461","62.73000","5.22770","0.00068"
"10476","62.82000","5.23523","0.00057"
"10491","62.91000","5.24270","0.00022"
"10506","63.00000","5.25018","0.00089"
"10521","63.09000","5.25771","-0.00037"
"10536","63.18000","5.26525","0.00038"
"10551","63.27000","5.27272","0.00031"
"10566","63.36000","5.28025","0.00017"
"10581","63.45000","5.28767","0.00066"
"10596","63.54000","5.29520","0.00008"
"10611","63.63000","5.30279","0.00065"
"10626","63.72000","5.31021","0.00001"
"10641","63.81000","5.31768","0.00027"
"10656","63.90000","5.32515","0.00025"
"10671","63.99000","5.33263","0.00007"
"10686","64.08000","5.34022","0.00042"
"10701","64.17000","5.34775","0.00069"
"10716","64.26000","5.35523","0.00043"
"10731","64.35000","5.36270","0.00013"
"10746","64.44000","5.37018","-0.00009"
"10761","64.53000","5.37771","0.00078"
"10776","64.62000","5.38518","0.00011"
"10791","64.71000","5.39272","0.00065"
"10806","64.80000","5.40019","-0.00004"
"10821","64.89000","5.40772","0.00030"
"10836","64.98000","5.41520","0.00021"
"10851","65.07000","5.42261","0.00018"
"10866","65.16000","5.43020","0.00048"
"10881","65.25000","5.43774","-0.00016"
"10896","65.34000","5.44527","0.00062"
"10911","65.43000","5.45274","0.00036"
"10926","65.52000","5.46022","-0.00004"
"10941","65.61000","5.46769","-0.00002"
"10956","65.70000","5.47517","0.00051"
"10971","65.79000","5.48282","0.00060"
"10986","65.88000","5.49023","0.00004"
"11001","65.97000","5.49771","-0.00012"
"11016","66.06000","5.50524","0.00027"
"11031","66.15000","5.51265","0.00010"
"11046","66.24000","5.52025","0.00000"
"11061","66.33000","5.52772","0.00023"
"11076","66.42000","5.53520","0.00014"
"11091","66.51000","5.54273","-0.00016"
"11106","66.60000","5.55020","0.00038"
"11121","66.69000","5.55768","-0.00038"
"11136","66.78000","5.56521","0.00040"
"11151","66.87000","5.57274","0.00017"
"11166","66.96000","5.58022","-0.00022"
"11181","67.05000","5.58769","0.00013"
"11196","67.14000","5.59516","0.00012"
"11211","67.23000","5.60264","0.00022"
"11226","67.32000","5.61017","0.00071"
"11241","67.41000","5.61776","-0.00017"
"11256","67.50000","5.62530","0.00021"
"11271","67.59000","5.63271","0.00036"
"11286","67.68000","5.64019","0.00029"
"11301","67.77000","5.64766","0.00013"
"11316","67.86000","5.65519","-0.00010"
"11331","67.95000","5.66267","-0.00013"
"11346","68.04000","5.67020","0.00107"
"11361","68.13000","5.67773","0.00017"
"11376","68.22000","5.68515","0.00051"
"11391","68.31000","5.69268","0.00002"
"11406","68.40000","5.70021","0.00016"
"11421","68.49000","5.70775","0.00016"
"11436","68.58000","5.71522","0.00044"
"11451","68.67000","5.72276","0.00000"
"11466","68.76000","5.73017","0.00032"
"11481","68.85000","5.73764","-0.00041"
"11496","68.94000","5.74524","0.00041"
"11511","69.03000","5.75271","0.00036"
"11526","69.12000","5.76024","0.00077"
"11541","69.21000","5.76772","0.00058"
"11556","69.30000","5.77519","0.00014"
"11571","69.39000","5.78266","0.00028"
"11586","69.48000","5.79020","0.00031"
"11601","69.57000","5.79773","0.00043"
"11616","69.66000","5.80526","0.00011"
"11631","69.75000","5.81268","0.00010"
"11646","69.84000","5.82015","0.00039"
"11661","69.93000","5.82769","-0.00028"
"11676","70.02000","5.83516","0.00046"
"11691","70.11000","5.84275","0.00058"
"11706","70.20000","5.85017","0.00009"
"11721","70.29000","5.85770","0.00017"
"11736","70.38000","5.86523","0.00021"
"11751","70.47000","5.87265","-0.00013"
"11766","70.56000","5.88024","0.00001"
"11781","70.65000","5.88777","0.00009"
"11796","70.74000","5.89519","0.00001"
"11811","70.83000","5.90272","0.00023"
"11826","70.92000","5.91020","0.00003"
"11841","71.01000","5.91767","0.00018"
"11856","71.10000","5.92526","0.00015"
"11871","71.19000","5.93274","0.00032"
"11886","71.28000","5.94021","0.00009"
"11901","71.37000","5.94774","-0.00005"
"11916","71.46000","5.95522","0.00024"
"11931","71.55000","5.96269","0.00010"
"11946","71.64000","5.97022","-0.00059"
"11961","71.73000","5.97770","0.00045"
"11976","71.82000","5.98523","0.00083"
"11991","71.91000","5.99270","0.00008"
"12006","72.00000","6.00018","0.00025"
"12021","72.09000","6.00765","0.00068"
"12036","72.18000","6.01525","0.00016"
"12051","72.27000","6.02272","0.00048"
"12066","72.36000","6.03025","-0.00049"
"12081","72.45000","6.03773","0.00055"
"12096","72.54000","6.04520","0.00010"
"12111","72.63000","6.05261","-0.00011"
"12126","72.72000","6.06021","0.00004"
"12141","72.81000","6.06774","0.00017"
"12156","72.90000","6.07521","0.00011"
"12171","72.99000","6.08269","0.00051"
"12186","73.08000","6.09022","0.00036"
"12201","73.17000","6.09764","0.00072"
"12216","73.26000","6.10523","0.00080"
"12231","73.35000","6.11270","0.00023"
"12246","73.44000","6.12018","0.00037"
"12261","73.53000","6.12777","0.00030"
"12276","73.62000","6.13518","0.00098"
"12291","73.71000","6.14266","0.00026"
"12306","73.80000","6.15025","0.00062"
"12321","73.89000","6.15772","0.00091"
"12336","73.98000","6.16526","0.00068"
"12351","74.07000","6.17273","0.00041"
"12366","74.16000","6.18020","0.00079"
"12381","74.25000","6.18768","-0.00003"
"12396","74.34000","6.19521","0.00047"
"12411","74.43000","6.20275","0.00077"
"12426","74.52000","6.21022","0.00043"
"12441","74.61000","6.21763","0.00058"
"12456","74.70000","6.22517","0.00058"
"12471","74.79000","6.23258","0.00049"
"12486","74.88000","6.24023","0.00020"
"12501","74.97000","6.24777","0.00003"
"12516","75.06000","6.25518","0.00023"
"12531","75.15000","6.26277","0.00020"
"12546","75.24000","6.27019","0.00105"
"12561","75.33000","6.27760","0.00044"
"12576","75.42000","6.28525","0.00078"
"12591","75.51000","6.29273","0.00083"
"12606","75.60000","6.30026","0.00003"
"12621","75.69000","6.30774","0.00070"
"12636","75.78000","6.31521","0.00038"
"12651","75.87000","6.32268","0.00017"
"12666","75.96000","6.33022","0.00055"
"12681","76.05000","6.33781","0.00061"
"12696","76.14000","6.34522","0.00033"
"12711","76.23000","6.35270","0.00065"
"12726","76.32000","6.36023","0.00055"
"12741","76.41000","6.36770","0.00106"
"12756","76.50000","6.37518","0.00064"
"12771","76.59000","6.38277","0.00031"
"12786","76.68000","6.39025","0.00073"
"12801","76.77000","6.39766","0.00114"
"12816","76.86000","6.40519","0.00085"
"12831","76.95000","6.41267","0.00056"
"12846","77.04000","6.42020","0.00083"
"12861","77.13000","6.42773","0.00050"
"12876","77.22000","6.43521","0.00123"
"12891","77.31000","6.44268","0.00043"
"12906","77.40000","6.45015","0.00068"
"12921","77.49000","6.45763","0.00038"
"12936","77.58000","6.46522","0.00054"
"12951","77.67000","6.47275","0.00038"
"12966","77.76000","6.48023","0.00043"
"12981","77.85000","6.48776","0.00051"
"12996","77.94000","6.49518","-0.00005"
"13011","78.03000","6.50271","0.00062"
"13026","78.12000","6.51024","0.00127"
"13041","78.21000","6.51772","0.00090"
"13056","78.30000","6.52525","0.00134"
"13071","78.39000","6.53272","0.00036"
"13086","78.48000","6.54020","0.00048"
"13101","78.57000","6.54773","0.00070"
"13116","78.66000","6.55520","0.00021"
"13131","78.75000","6.56274","0.00054"
"13146","78.84000","6.57027","0.00103"
"13161","78.93000","6.57769","0.00041"
"13176","79.02000","6.58522","0.00126"
"13191","79.11000","6.59269","0.00098"
"13206","79.20000","6.60023","0.00059"
"13221","79.29000","6.60776","0.00057"
"13236","79.38000","6.61523","0.00057"
"13251","79.47000","6.62271","0.00046"
"13266","79.56000","6.63018","0.00098"
"13281","79.65000","6.63771","0.00057"
"13296","79.74000","6.64519","0.00083"
"13311","79.83000","6.65272","0.00059"
"13326","79.92000","6.66025","0.00096"
"13341","80.01000","6.66773","0.00133"
"13356","80.10000","6.67514","0.00088"
"13371","80.19000","6.68268","0.00083"
"13386","80.28000","6.69021","0.00086"
"13401","80.37000","6.69768","0.00138"
"13416","80.46000","6.70522","0.00111"
"13431","80.55000","6.71275","0.00110"
"13446","80.64000","6.72022","0.00098"
"13461","80.73000","6.72770","0.00132"
"13476","80.82000","6.73523","0.00101"
"13491","80.91000","6.74271","0.00125"
"13506","81.00000","6.75024","0.00162"
"13521","81.09000","6.75765","0.00110"
"13536","81.18000","6.76519","0.00130"
"13551","81.27000","6.77272","0.00109"
"13566","81.36000","6.78019","0.00131"
"13581","81.45000","6.78779","0.00160"
"13596","81.54000","6.79526","0.00095"
"13611","81.63000","6.80267","0.00123"
"13626","81.72000","6.81021","0.00122"
"13641","81.81000","6.81768","0.00106"
"13656","81.90000","6.82521","0.00168"
"13671","81.99000","6.83275","0.00161"
"13686","82.08000","6.84028","0.00125"
"13701","82.17000","6.84770","0.00137"
"13716","82.26000","6.85517","0.00165"
"13731","82.35000","6.86264","0.00130"
"13746","82.44000","6.87024","0.00145"
"13761","82.53000","6.87771","0.00195"
"13776","82.62000","6.88518","0.00135"
"13791","82.71000","6.89278","0.00139"
"13806","82.80000","6.90013","0.00168"
"13821","82.89000","6.90766","0.00170"
"13836","82.98000","6.91520","0.00178"
"13851","83.07000","6.92273","0.00170"
"13866","83.16000","6.93026","0.00118"
"13881","83.25000","6.93768","0.00133"
"13896","83.34000","6.94515","0.00198"
"13911","83.43000","6.95269","0.00186"
"13926","83.52000","6.96022","0.00184"
"13941","83.61000","6.96769","0.00159"
"13956","83.70000","6.97523","0.00200"
"13971","83.79000","6.98270","0.00166"
"13986","83.88000","6.99017","0.00189"
"14001","83.97000","6.99765","0.00163"
"14016","84.06000","7.00524","0.00174"
"14031","84.15000","7.01277","0.00198"
"14046","84.24000","7.02019","0.00207"
"14061","84.33000","7.02772","0.00231"
"14076","84.42000","7.03519","0.00203"
"14091","84.51000","7.04267","0.00166"
"14106","84.60000","7.05026","0.00147"
"14121","84.69000","7.05774","0.00159"
"14136","84.78000","7.06527","0.00212"
"14151","84.87000","7.07274","0.00172"
"14166","84.96000","7.08016","0.00188"
"14181","85.05000","7.08769","0.00183"
"14196","85.14000","7.09522","0.00201"
"14211","85.23000","7.10270","0.00232"
"14226","85.32000","7.11023","0.00157"
"14241","85.41000","7.11770","0.00205"
"14256","85.50000","7.12512","0.00214"
"14271","85.59000","7.13271","0.00183"
"14286","85.68000","7.14019","0.00182"
"14301","85.77000","7.14772","0.00069"
"14316","85.86000","7.15525","0.00060"
"14331","85.95000","7.16267","0.00102"
"14346","86.04000","7.17014","0.00148"
"14361","86.13000","7.17767","0.00108"
"14376","86.22000","7.18521","0.00095"
"14391","86.31000","7.19274","0.00111"
"14406","86.40000","7.20021","0.00134"
"14421","86.49000","7.20769","0.00059"
"14436","86.58000","7.21522","0.00109"
"14451","86.67000","7.22264","0.00085"
"14466","86.76000","7.23023","0.00128"
"14481","86.85000","7.23770","0.00148"
"14496","86.94000","7.24524","0.00147"
"14511","87.03000","7.25277","0.00148"
"14526","87.12000","7.26018","0.00194"
"14541","87.21000","7.26772","0.00103"
"14556","87.30000","7.27525","0.00124"
"14571","87.39000","7.28266","0.00130"
"14586","87.48000","7.29026","0.00161"
"14601","87.57000","7.29773","0.00165"
"14616","87.66000","7.30515","0.00224"
"14631","87.75000","7.31268","0.00172"
"14646","87.84000","7.32015","0.00179"
"14661","87.93000","7.32775","0.00134"
"14676","88.02000","7.33522","0.00181"
"14691","88.11000","7.34269","0.00139"
"14706","88.20000","7.35017","0.00181"
"14721","88.29000","7.35770","0.00205"
"14736","88.38000","7.36523","0.00195"
"14751","88.47000","7.37277","0.00178"
"14766","88.56000","7.38024","0.00198"
"14781","88.65000","7.38777","0.00166"
"14796","88.74000","7.39525","0.00222"
"14811","88.83000","7.40272","0.00192"
"14826","88.92000","7.41025","0.00188"
"14841","89.01000","7.41779","0.00171"
"14856","89.10000","7.42526","0.00193"
"14871","89.19000","7.43274","0.00243"
"14886","89.28000","7.44015","0.00194"
"14901","89.37000","7.44768","0.00210"
"14916","89.46000","7.45528","0.00185"
"14931","89.55000","7.46269","0.00159"
"14946","89.64000","7.47022","0.00212"
"14961","89.73000","7.47770","0.00257"
"14976","89.82000","7.48517","0.00223"
"14991","89.91000","7.49270","0.00226"
"15006","90.00000","7.50024","0.00177"
"15021","90.09000","7.50771","0.00227"
"15036","90.18000","7.51524","0.00219"
"15051","90.27000","7.52266","0.00263"
"15066","90.36000","7.53019","0.00199"
"15081","90.45000","7.53773","0.00183"
"15096","90.54000","7.54520","0.00201"
"15111","90.63000","7.55273","0.00236"
"15126","90.72000","7.56021","0.00285"
"15141","90.81000","7.56762","0.00260"
"15156","90.90000","7.57515","0.00231"
"15171","90.99000","7.58275","0.00252"
"15186","91.08000","7.59022","0.00223"
"15201","91.17000","7.59775","0.00239"
"15216","91.26000","7.60529","0.00235"
"15231","91.35000","7.61270","0.00276"
"15246","91.44000","7.62018","0.00234"
"15261","91.53000","7.62771","0.00178"
"15276","91.62000","7.63530","0.00245"
"15291","91.71000","7.64272","0.00188"
"15306","91.80000","7.65019","0.00236"
"15321","91.89000","7.65766","0.00237"
"15336","91.98000","7.66514","0.00232"
"15351","92.07000","7.67273","0.00195"
"15366","92.16000","7.68026","0.00249"
"15381","92.25000","7.68774","0.00185"
"15396","92.34000","7.69527","0.00239"
"15411","92.43000","7.70269","0.00278"
"15426","92.52000","7.71016","0.00241"
"15441","92.61000","7.71769","0.00245"
"15456","92.70000","7.72523","0.00266"
"15471","92.79000","7.73276","0.00276"
"15486","92.88000","7.74023","0.00252"
"15501","92.97000","7.74771","0.00268"
"15516","93.06000","7.75512","0.00247"
"15531","93.15000","7.76266","0.00256"
"15546","93.24000","7.77031","0.00245"
"15561","93.33000","7.77778","0.00260"
"15576","93.42000","7.78520","0.00302"
"15591","93.51000","7.79273","0.00257"
"15606","93.60000","7.80020","0.00280"
"15621","93.69000","7.80768","0.00199"
"15636","93.78000","7.81527","0.00209"
"15651","93.87000","7.82274","0.00284"
"15666","93.96000","7.83022","0.00200"
"15681","94.05000","7.83769","0.00273"
"15696","94.14000","7.84516","0.00260"
"15711","94.23000","7.85270","0.00254"
"15726","94.32000","7.86023","0.00257"
"15741","94.41000","7.86770","0.00232"
"15756","94.50000","7.87530","0.00227"
"15771","94.59000","7.88271","0.00253"
"15786","94.68000","7.89019","0.00303"
"15801","94.77000","7.89772","0.00293"
"15816","94.86000","7.90525","0.00284"
"15831","94.95000","7.91273","0.00231"
"15846","95.04000","7.92020","0.00308"
"15861","95.13000","7.92767","0.00305"
"15876","95.22000","7.93515","0.00309"
"15891","95.31000","7.94268","0.00277"
"15906","95.40000","7.95021","0.00310"
"15921","95.49000","7.95775","0.00266"
"15936","95.58000","7.96522","0.00292"
"15951","95.67000","7.97269","0.00311"
"15966","95.76000","7.98017","0.00305"
"15981","95.85000","7.98770","0.00305"
"15996","95.94000","7.99524","0.00356"
"16011","96.03000","8.00271","0.00310"
"16026","96.12000","8.01018","0.00318"
"16041","96.21000","8.01772","0.00305"
"16056","96.30000","8.02513","0.00332"
"16071","96.39000","8.03272","0.00330"
"16086","96.48000","8.04026","0.00262"
"16101","96.57000","8.04773","0.00315"
"16116","96.66000","8.05520","0.00310"
"16131","96.75000","8.06274","0.00292"
"16146","96.84000","8.07015","0.00283"
"16161","96.93000","8.07769","0.00251"
"16176","97.02000","8.08522","0.00347"
"16191","97.11000","8.09269","0.00270"
"16206","97.20000","8.10023","0.00292"
"16221","97.29000","8.10764","0.00286"
"16236","97.38000","8.11517","0.00289"
"16251","97.47000","8.12271","0.00378"
"16266","97.56000","8.13024","0.00340"
"16281","97.65000","8.13777","0.00353"
"16296","97.74000","8.14519","0.00342"
"16311","97.83000","8.15272","0.00365"
"16326","97.92000","8.16020","0.00325"
"16341","98.01000","8.16767","0.00280"
"16356","98.10000","8.17526","0.00310"
"16371","98.19000","8.18268","0.00337"
"16386","98.28000","8.19015","0.00286"
"16401","98.37000","8.19774","0.00323"
"16416","98.46000","8.20516","0.00328"
"16431","98.55000","8.21269","0.00349"
"16446","98.64000","8.22022","0.00310"
"16461","98.73000","8.22776","0.00348"
"16476","98.82000","8.23517","0.00324"
"16491","98.91000","8.24264","0.00349"
"16506","99.00000","8.25018","0.00323"
"16521","99.09000","8.25771","0.00327"
"16536","99.18000","8.26524","0.00352"
"16551","99.27000","8.27272","0.00305"
"16566","99.36000","8.28025","0.00348"
"16581","99.45000","8.28767","0.00327"
"16596","99.54000","8.29520","0.00336"
"16611","99.63000","8.30273","0.00311"
"16626","99.72000","8.31027","0.00424"
"16641","99.81000","8.31774","0.00334"
"16656","99.90000","8.32521","0.00377"
"16671","99.99000","8.33269","0.00362"
"16686","100.08000","8.34016","0.00405"
"16701","100.17000","8.34769","0.00389"
"16716","100.26000","8.35523","0.00369"
"16731","100.35000","8.36270","0.00383"
"16746","100.44000","8.37018","0.00435"
"16761","100.53000","8.37765","0.00369"
"16776","100.62000","8.38512","0.00371"
"16791","100.71000","8.39272","0.00386"
"16806","100.80000","8.40025","0.00446"
"16821","100.89000","8.40772","0.00397"
"16836","100.98000","8.41526","0.00474"
"16851","101.07000","8.42273","0.00356"
"16866","101.16000","8.43014","0.00404"
"16881","101.25000","8.43774","0.00427"
"16896","101.34000","8.44521","0.00412"
"16911","101.43000","8.45275","0.00397"
"16926","101.52000","8.46028","0.00397"
"16941","101.61000","8.46769","0.00434"
"16956","101.70000","8.47517","0.00420"
"16971","101.79000","8.48276","0.00405"
"16986","101.88000","8.49023","0.00370"
"17001","101.97000","8.49777","0.00386"
"17016","102.06000","8.50518","0.00424"
"17031","102.15000","8.51265","0.00393"
"17046","102.24000","8.52019","0.00432"
"17061","102.33000","8.52766","0.00418"
"17076","102.42000","8.53525","0.00395"
"17091","102.51000","8.54273","0.00436"
"17106","102.60000","8.55020","0.00458"
"17121","102.69000","8.55768","0.00474"
"17136","102.78000","8.56515","0.00458"
"17151","102.87000","8.57268","0.00458"
"17166","102.96000","8.58022","0.00475"
"17181","103.05000","8.58775","0.00437"
"17196","103.14000","8.59522","0.00427"
"17211","103.23000","8.60270","0.00460"
"17226","103.32000","8.61011","0.00483"
"17241","103.41000","8.61776","0.00429"
"17256","103.50000","8.62524","0.00478"
"17271","103.59000","8.63277","0.00439"
"17286","103.68000","8.64025","0.00451"
"17301","103.77000","8.64772","0.00447"
"17316","103.86000","8.65519","0.00424"
"17331","103.95000","8.66273","0.00434"
"17346","104.04000","8.67020","0.00461"
"17361","104.13000","8.67773","0.00443"
"17376","104.22000","8.68521","0.00460"
"17391","104.31000","8.69274","0.00548"
"17406","104.40000","8.70021","0.00428"
"17421","104.49000","8.70769","0.00462"
"17436","104.58000","8.71522","0.00481"
"17451","104.67000","8.72276","0.00495"
"17466","104.76000","8.73023","0.00501"
"17481","104.85000","8.73770","0.00520"
"17496","104.94000","8.74518","0.00480"
"17511","105.03000","8.75271","0.00430"
"17526","105.12000","8.76024","0.00478"
"17541","105.21000","8.76766","0.00481"
"17556","105.30000","8.77519","0.00529"
"17571","105.39000","8.78272","0.00522"
"17586","105.48000","8.79014","0.00525"
"17601","105.57000","8.79773","0.00549"
"17616","105.66000","8.80520","0.00490"
"17631","105.75000","8.81268","0.00536"
"17646","105.84000","8.82021","0.00548"
"17661","105.93000","8.82769","0.00527"
"17676","106.02000","8.83516","0.00532"
"17691","106.11000","8.84275","0.00547"
"17706","106.20000","8.85023","0.00537"
"17721","106.29000","8.85776","0.00501"
"17736","106.38000","8.86523","0.00498"
"17751","106.47000","8.87271","0.00516"
"17766","106.56000","8.88024","0.00483"
"17781","106.65000","8.88771","0.00530"
"17796","106.74000","8.89525","0.00542"
"17811","106.83000","8.90272","0.00520"
"17826","106.92000","8.91020","0.00576"
"17841","107.01000","8.91767","0.00552"
"17856","107.10000","8.92520","0.00536"
"17871","107.19000","8.93274","0.00576"
"17886","107.28000","8.94027","0.00538"
"17901","107.37000","8.94774","0.00566"
"17916","107.46000","8.95522","0.00545"
"17931","107.55000","8.96269","0.00594"
"17946","107.64000","8.97016","0.00574"
"17961","107.73000","8.97770","0.00610"
"17976","107.82000","8.98523","0.00597"
"17991","107.91000","8.99270","0.00598"
"18006","108.00000","9.00018","0.00573"
"18021","108.09000","9.00765","0.00598"
"18036","108.18000","9.01519","0.00556"
"18051","108.27000","9.02278","0.00586"
"18066","108.36000","9.03019","0.00598"
"18081","108.45000","9.03773","0.00578"
"18096","108.54000","9.04520","0.00595"
"18111","108.63000","9.05267","0.00615"
"18126","108.72000","9.06021","0.00656"
"18141","108.81000","9.06774","0.00641"
"18156","108.90000","9.07521","0.00654"
"18171","108.99000","9.08275","0.00583"
"18186","109.08000","9.09016","0.00654"
"18201","109.17000","9.09764","0.00617"
"18216","109.26000","9.10523","0.00656"
"18231","109.35000","9.11276","0.00657"
"18246","109.44000","9.12024","0.00667"
"18261","109.53000","9.12777","0.00612"
"18276","109.62000","9.13518","0.00660"
"18291","109.71000","9.14272","0.00687"
"18306","109.80000","9.15013","0.00652"
"18321","109.89000","9.15772","0.00640"
"18336","109.98000","9.16526","0.00598"
"18351","110.07000","9.17273","0.00669"
"18366","110.16000","9.18026","0.00658"
"18381","110.25000","9.18768","0.00711"
"18396","110.34000","9.19515","0.00695"
"18411","110.43000","9.20274","0.00800"
"18426","110.52000","9.21022","0.00745"
"18441","110.61000","9.21775","0.00787"
"18456","110.70000","9.22523","0.00787"
"18471","110.79000","9.23270","0.00714"
"18486","110.88000","9.24017","0.00730"
"18501","110.97000","9.24771","0.00712"
"18516","111.06000","9.25518","0.00753"
"18531","111.15000","9.26277","0.00768"
"18546","111.24000","9.27019","0.00767"
"18561","111.33000","9.27760","0.00672"
"18576","111.42000","9.28525","0.00251"
"18591","111.51000","9.29273","0.00051"
"18606","111.60000","9.30020","0.00061"
"18621","111.69000","9.30774","0.00026"
"18636","111.78000","9.31521","0.00090"
"18651","111.87000","9.32268","0.00112"
"18666","111.96000","9.33022","0.00169"
"18681","112.05000","9.33775","0.00170"
"18696","112.14000","9.34522","0.00047"
"18711","112.23000","9.35276","0.00071"
"18726","112.32000","9.36023","0.00094"
"18741","112.41000","9.36770","0.00135"
"18756","112.50000","9.37518","0.00254"
"18771","112.59000","9.38271","0.00196"
"18786","112.68000","9.39025","0.00179"
"18801","112.77000","9.39772","0.00057"
"18816","112.86000","9.40525","0.00140"
"18831","112.95000","9.41267","0.00175"
"18846","113.04000","9.42020","0.00282"
"18861","113.13000","9.42773","0.00266"
"18876","113.22000","9.43521","0.00301"
"18891","113.31000","9.44274","0.00165"
"18906","113.40000","9.45015","0.00171"
"18921","113.49000","9.45763","0.00129"
"18936","113.58000","9.46522","0.00235"
"18951","113.67000","9.47270","0.00317"
"18966","113.76000","9.48023","0.00266"
"18981","113.85000","9.48776","0.00252"
"18996","113.94000","9.49518","0.00176"
"19011","114.03000","9.50271","0.00170"
"19026","114.12000","9.51018","0.00322"
"19041","114.21000","9.51772","0.00368"
"19056","114.30000","9.52525","0.00396"
"19071","114.39000","9.53272","0.00315"
"19077","114.42600","9.53577","0.00259"